File: Experimental Raw Data/TC04-12-01K VRMac VRMde/TC04-12-01K_VRMac_55K_12000s.dc.dat
[Header]
TITLE,MPMS DC Measurement
BYAPP,MPMS Measurement,2.1,Summary
FILEOPENTIME, 1524351393.766000 4/21/2018, 4:56:33 PM

INFO, APPNAME, MPMS MultiVu Application, Revision 1.61,  Build 082

INFO, NAME, TC04-12-01K
INFO, WEIGHT, 1.000
INFO, AREA, 1.000
INFO, LENGTH, 1.000
INFO, SHAPE, 0
INFO, COMMENT,
INFO, SEQUENCE FILE: VRMac_55K_12000s_VRMde_55Klinear.seq


INFO, BACKGROUND DATA FILE:, None


STARTUPAXIS,X,4,LINEAR,AUTO,0.000000,0.000000
STARTUPAXIS,Y1,5,LINEAR,AUTO,0.000000,0.000000


STARTUPGROUP,Longitudinal
FIELDGROUP,Longitudinal,1,2,3,4,5,6,7,8,9,15,16,17,18,27,28
FIELDGROUP,Transverse,1,2,3,4,10,11,12,13,14,19,20,21,22,27,28

PLOT_APPEARANCE,ALL,HORZ_GRID_ON,VERT_GRID_ON,MARKERS_AND_LINES

[Data]
Time,Comment,Field (Oe),Temperature (K),Long Moment (emu),Long Scan Std Dev,Long Algorithm,Long Reg Fit,Long Percent Error (%),Trans Moment (emu),Trans Scan Std Dev,Trans Algorithm,Trans Reg Fit,Trans Percent Error (%),Long Moment [w/o ABS] (emu),Long Scan Std Dev [w/o ABS],Long Reg Fit [w/o ABS],Long Percent Error [w/o ABS] (%),Trans Moment [w/o ABS] (emu),Trans Scan Std Dev [w/o ABS],Trans Reg Fit [w/o ABS],Trans Percent Error [w/o ABS] (%),Points per Scan,Scans per Measurement,Scan Length (cm),Delta Temp (K),Rot Position (deg),Error,EC Comp. Running,Using ABS,
1524351393.766,,0.000000e+000,5.505107e+001,-4.964513e-005,0.000000e+000,2,6.809652e-001,0.000000e+000,,,,,,,,,,,,,,32,1,4.000000e+000,2.635956e-002,0.000000e+000,0,,0,
1524351432.146,,0.000000e+000,5.501682e+001,-5.456954e-005,0.000000e+000,2,6.858298e-001,0.000000e+000,,,,,,,,,,,,,,32,1,4.000000e+000,2.370071e-002,0.000000e+000,0,,0,
1524351469.906,,0.000000e+000,5.501156e+001,-5.656380e-005,0.000000e+000,2,6.903055e-001,0.000000e+000,,,,,,,,,,,,,,32,1,4.000000e+000,1.578140e-002,0.000000e+000,0,,0,
1524351507.246,,0.000000e+000,5.500367e+001,-5.782556e-005,0.000000e+000,2,6.886956e-001,0.000000e+000,,,,,,,,,,,,,,32,1,4.000000e+000,0.000000e+000,0.000000e+000,0,,0,
1524351545.326,,0.000000e+000,5.500169e+001,-5.891226e-005,0.000000e+000,2,6.912277e-001,0.000000e+000,,,,,,,,,,,,,,32,1,4.000000e+000,1.709747e-002,0.000000e+000,0,,0,
1524351583.366,,0.000000e+000,5.500103e+001,-5.961431e-005,0.000000e+000,2,6.904540e-001,0.000000e+000,,,,,,,,,,,,,,32,1,4.000000e+000,2.639771e-003,0.000000e+000,0,,0,
1524351621.796,,0.000000e+000,5.499445e+001,-6.034146e-005,0.000000e+000,2,6.911312e-001,0.000000e+000,,,,,,,,,,,,,,32,1,4.000000e+000,0.000000e+000,0.000000e+000,0,,0,
1524351659.516,,0.000000e+000,5.500366e+001,-6.092088e-005,0.000000e+000,2,6.925679e-001,0.000000e+000,,,,,,,,,,,,,,32,1,4.000000e+000,2.620697e-003,0.000000e+000,0,,0,
1524351697.286,,0.000000e+000,5.500563e+001,-6.135234e-005,0.000000e+000,2,6.911637e-001,0.000000e+000,,,,,,,,,,,,,,32,1,4.000000e+000,1.319885e-003,0.000000e+000,0,,0,
1524351735.616,,0.000000e+000,5.499972e+001,-6.181623e-005,0.000000e+000,2,6.931069e-001,0.000000e+000,,,,,,,,,,,,,,32,1,4.000000e+000,5.268097e-003,0.000000e+000,0,,0,
1524351773.676,,0.000000e+000,5.499773e+001,-6.226735e-005,0.000000e+000,2,6.934935e-001,0.000000e+000,,,,,,,,,,,,,,32,1,4.000000e+000,1.308441e-003,0.000000e+000,0,,0,
1524351811.416,,0.000000e+000,5.500168e+001,-6.255809e-005,0.000000e+000,2,6.925530e-001,0.000000e+000,,,,,,,,,,,,,,32,1,4.000000e+000,6.580353e-003,0.000000e+000,0,,0,
1524351849.026,,0.000000e+000,5.499839e+001,-6.281193e-005,0.000000e+000,2,6.933759e-001,0.000000e+000,,,,,,,,,,,,,,32,1,4.000000e+000,0.000000e+000,0.000000e+000,0,,0,
1524351887.276,,0.000000e+000,5.499511e+001,-6.318562e-005,0.000000e+000,2,6.945034e-001,0.000000e+000,,,,,,,,,,,,,,32,1,4.000000e+000,1.319885e-003,0.000000e+000,0,,0,
1524351924.376,,0.000000e+000,5.499577e+001,-6.342450e-005,0.000000e+000,2,6.940286e-001,0.000000e+000,,,,,,,,,,,,,,32,1,4.000000e+000,2.632141e-003,0.000000e+000,0,,0,
1524351962.287,,0.000000e+000,5.499972e+001,-6.369937e-005,0.000000e+000,2,6.945647e-001,0.000000e+000,,,,,,,,,,,,,,32,1,4.000000e+000,5.268097e-003,0.000000e+000,0,,0,
1524352000.567,,0.000000e+000,5.499511e+001,-6.400114e-005,0.000000e+000,2,6.953556e-001,0.000000e+000,,,,,,,,,,,,,,32,1,4.000000e+000,9.201050e-003,0.000000e+000,0,,0,
1524352037.827,,0.000000e+000,5.500366e+001,-6.418412e-005,0.000000e+000,2,6.941663e-001,0.000000e+000,,,,,,,,,,,,,,32,1,4.000000e+000,5.260468e-003,0.000000e+000,0,,0,
1524352075.767,,0.000000e+000,5.500037e+001,-6.435985e-005,0.000000e+000,2,6.953069e-001,0.000000e+000,,,,,,,,,,,,,,32,1,4.000000e+000,3.959656e-003,0.000000e+000,0,,0,
1524352113.837,,0.000000e+000,5.499313e+001,-6.459955e-005,0.000000e+000,2,6.949754e-001,0.000000e+000,,,,,,,,,,,,,,32,1,4.000000e+000,1.050949e-002,0.000000e+000,0,,0,
1524352150.797,,0.000000e+000,5.499905e+001,-6.473312e-005,0.000000e+000,2,6.961954e-001,0.000000e+000,,,,,,,,,,,,,,32,1,4.000000e+000,1.319885e-003,0.000000e+000,0,,0,
1524352187.917,,0.000000e+000,5.500037e+001,-6.489448e-005,0.000000e+000,2,6.953927e-001,0.000000e+000,,,,,,,,,,,,,,32,1,4.000000e+000,1.319885e-003,0.000000e+000,0,,0,
1524352225.847,,0.000000e+000,5.499577e+001,-6.510214e-005,0.000000e+000,2,6.974160e-001,0.000000e+000,,,,,,,,,,,,,,32,1,4.000000e+000,2.632141e-003,0.000000e+000,0,,0,
1524352263.917,,0.000000e+000,5.500037e+001,-6.534737e-005,0.000000e+000,2,6.961954e-001,0.000000e+000,,,,,,,,,,,,,,32,1,4.000000e+000,1.319885e-003,0.000000e+000,0,,0,
1524352301.607,,0.000000e+000,5.499445e+001,-6.550800e-005,0.000000e+000,2,6.974285e-001,0.000000e+000,,,,,,,,,,,,,,32,1,4.000000e+000,5.260468e-003,0.000000e+000,0,,0,
1524352339.447,,0.000000e+000,5.499840e+001,-6.575933e-005,0.000000e+000,2,6.984617e-001,0.000000e+000,,,,,,,,,,,,,,32,1,4.000000e+000,5.260468e-003,0.000000e+000,0,,0,
1524352376.837,,0.000000e+000,5.499905e+001,-6.577455e-005,0.000000e+000,2,6.965840e-001,0.000000e+000,,,,,,,,,,,,,,32,1,4.000000e+000,3.948212e-003,0.000000e+000,0,,0,
1524352414.297,,0.000000e+000,5.499708e+001,-6.590205e-005,0.000000e+000,2,6.986868e-001,0.000000e+000,,,,,,,,,,,,,,32,1,4.000000e+000,2.620697e-003,0.000000e+000,0,,0,
1524352451.937,,0.000000e+000,5.499379e+001,-6.608019e-005,0.000000e+000,2,6.971954e-001,0.000000e+000,,,,,,,,,,,,,,32,1,4.000000e+000,9.201050e-003,0.000000e+000,0,,0,
1524352489.147,,0.000000e+000,5.500037e+001,-6.628795e-005,0.000000e+000,2,7.000514e-001,0.000000e+000,,,,,,,,,,,,,,32,1,4.000000e+000,3.959656e-003,0.000000e+000,0,,0,
1524352527.017,,0.000000e+000,5.499577e+001,-6.634289e-005,0.000000e+000,2,6.984861e-001,0.000000e+000,,,,,,,,,,,,,,32,1,4.000000e+000,2.632141e-003,0.000000e+000,0,,0,
1524352564.417,,0.000000e+000,5.499905e+001,-6.641503e-005,0.000000e+000,2,7.001724e-001,0.000000e+000,,,,,,,,,,,,,,32,1,4.000000e+000,3.948212e-003,0.000000e+000,0,,0,
1524352602.117,,0.000000e+000,5.499445e+001,-6.660566e-005,0.000000e+000,2,6.994899e-001,0.000000e+000,,,,,,,,,,,,,,32,1,4.000000e+000,7.881165e-003,0.000000e+000,0,,0,
1524352640.027,,0.000000e+000,5.500103e+001,-6.669563e-005,0.000000e+000,2,6.997511e-001,0.000000e+000,,,,,,,,,,,,,,32,1,4.000000e+000,0.000000e+000,0.000000e+000,0,,0,
1524352678.668,,0.000000e+000,5.499971e+001,-6.685450e-005,0.000000e+000,2,6.997674e-001,0.000000e+000,,,,,,,,,,,,,,32,1,4.000000e+000,0.000000e+000,0.000000e+000,0,,0,
1524352717.038,,0.000000e+000,5.499577e+001,-6.692395e-005,0.000000e+000,2,6.998414e-001,0.000000e+000,,,,,,,,,,,,,,32,1,4.000000e+000,2.632141e-003,0.000000e+000,0,,0,
1524352754.698,,0.000000e+000,5.500037e+001,-6.700811e-005,0.000000e+000,2,7.007990e-001,0.000000e+000,,,,,,,,,,,,,,32,1,4.000000e+000,1.319885e-003,0.000000e+000,0,,0,
1524352793.038,,0.000000e+000,5.499642e+001,-6.716963e-005,0.000000e+000,2,7.012915e-001,0.000000e+000,,,,,,,,,,,,,,32,1,4.000000e+000,3.940582e-003,0.000000e+000,0,,0,
1524352830.528,,0.000000e+000,5.499708e+001,-6.725963e-005,0.000000e+000,2,7.001731e-001,0.000000e+000,,,,,,,,,,,,,,32,1,4.000000e+000,2.620697e-003,0.000000e+000,0,,0,
1524352867.938,,0.000000e+000,5.499971e+001,-6.736485e-005,0.000000e+000,2,7.020857e-001,0.000000e+000,,,,,,,,,,,,,,32,1,4.000000e+000,2.639771e-003,0.000000e+000,0,,0,
1524352905.828,,0.000000e+000,5.498985e+001,-6.744950e-005,0.000000e+000,2,7.004347e-001,0.000000e+000,,,,,,,,,,,,,,32,1,4.000000e+000,1.319885e-003,0.000000e+000,0,,0,
1524352943.488,,0.000000e+000,5.500169e+001,-6.756887e-005,0.000000e+000,2,7.023030e-001,0.000000e+000,,,,,,,,,,,,,,32,1,4.000000e+000,3.959656e-003,0.000000e+000,0,,0,
1524352981.408,,0.000000e+000,5.499182e+001,-6.770560e-005,0.000000e+000,2,7.024410e-001,0.000000e+000,,,,,,,,,,,,,,32,1,4.000000e+000,1.052094e-002,0.000000e+000,0,,0,
1524353018.678,,0.000000e+000,5.499905e+001,-6.777018e-005,0.000000e+000,2,7.013370e-001,0.000000e+000,,,,,,,,,,,,,,32,1,4.000000e+000,1.182938e-002,0.000000e+000,0,,0,
1524353056.978,,0.000000e+000,5.500169e+001,-6.785373e-005,0.000000e+000,2,7.030560e-001,0.000000e+000,,,,,,,,,,,,,,32,1,4.000000e+000,1.446915e-002,0.000000e+000,0,,0,
1524353095.008,,0.000000e+000,5.499445e+001,-6.794272e-005,0.000000e+000,2,7.032684e-001,0.000000e+000,,,,,,,,,,,,,,32,1,4.000000e+000,5.260468e-003,0.000000e+000,0,,0,
1524353132.178,,0.000000e+000,5.500168e+001,-6.801577e-005,0.000000e+000,2,7.022802e-001,0.000000e+000,,,,,,,,,,,,,,32,1,4.000000e+000,6.580353e-003,0.000000e+000,0,,0,
1524353169.758,,0.000000e+000,5.499775e+001,-6.810406e-005,0.000000e+000,2,7.040344e-001,0.000000e+000,,,,,,,,,,,,,,32,1,4.000000e+000,1.184845e-002,0.000000e+000,0,,0,
1524353206.958,,0.000000e+000,5.499971e+001,-6.821896e-005,0.000000e+000,2,7.031261e-001,0.000000e+000,,,,,,,,,,,,,,32,1,4.000000e+000,0.000000e+000,0.000000e+000,0,,0,
1524353244.968,,0.000000e+000,5.499380e+001,-6.825551e-005,0.000000e+000,2,7.039428e-001,0.000000e+000,,,,,,,,,,,,,,32,1,4.000000e+000,1.308441e-003,0.000000e+000,0,,0,
1524353282.238,,0.000000e+000,5.499972e+001,-6.838156e-005,0.000000e+000,2,7.027811e-001,0.000000e+000,,,,,,,,,,,,,,32,1,4.000000e+000,7.900238e-003,0.000000e+000,0,,0,
1524353319.828,,0.000000e+000,5.500301e+001,-6.844795e-005,0.000000e+000,2,7.043193e-001,0.000000e+000,,,,,,,,,,,,,,32,1,4.000000e+000,1.319885e-003,0.000000e+000,0,,0,
1524353358.048,,0.000000e+000,5.499905e+001,-6.849104e-005,0.000000e+000,2,7.033854e-001,0.000000e+000,,,,,,,,,,,,,,32,1,4.000000e+000,3.948212e-003,0.000000e+000,0,,0,
1524353395.759,,0.000000e+000,5.499971e+001,-6.861854e-005,0.000000e+000,2,7.049145e-001,0.000000e+000,,,,,,,,,,,,,,32,1,4.000000e+000,1.052094e-002,0.000000e+000,0,,0,
1524353434.049,,0.000000e+000,5.500366e+001,-6.869945e-005,0.000000e+000,2,7.053019e-001,0.000000e+000,,,,,,,,,,,,,,32,1,4.000000e+000,2.620697e-003,0.000000e+000,0,,0,
1524353472.269,,0.000000e+000,5.499906e+001,-6.876470e-005,0.000000e+000,2,7.042711e-001,0.000000e+000,,,,,,,,,,,,,,32,1,4.000000e+000,6.580353e-003,0.000000e+000,0,,0,
1524353510.139,,0.000000e+000,5.499971e+001,-6.885095e-005,0.000000e+000,2,7.057046e-001,0.000000e+000,,,,,,,,,,,,,,32,1,4.000000e+000,0.000000e+000,0.000000e+000,0,,0,
1524353547.239,,0.000000e+000,5.499708e+001,-6.889934e-005,0.000000e+000,2,7.045953e-001,0.000000e+000,,,,,,,,,,,,,,32,1,4.000000e+000,2.620697e-003,0.000000e+000,0,,0,
1524353585.179,,0.000000e+000,5.499709e+001,-6.889800e-005,0.000000e+000,2,7.052968e-001,0.000000e+000,,,,,,,,,,,,,,32,1,4.000000e+000,1.052856e-002,0.000000e+000,0,,0,
1524353623.289,,0.000000e+000,5.499774e+001,-6.903202e-005,0.000000e+000,2,7.059232e-001,0.000000e+000,,,,,,,,,,,,,,32,1,4.000000e+000,3.940582e-003,0.000000e+000,0,,0,
1524353661.229,,0.000000e+000,5.499773e+001,-6.909299e-005,0.000000e+000,2,7.054536e-001,0.000000e+000,,,,,,,,,,,,,,32,1,4.000000e+000,1.308441e-003,0.000000e+000,0,,0,
1524353699.149,,0.000000e+000,5.500169e+001,-6.913891e-005,0.000000e+000,2,7.063994e-001,0.000000e+000,,,,,,,,,,,,,,32,1,4.000000e+000,3.959656e-003,0.000000e+000,0,,0,
1524353736.809,,0.000000e+000,5.499708e+001,-6.921295e-005,0.000000e+000,2,7.058007e-001,0.000000e+000,,,,,,,,,,,,,,32,1,4.000000e+000,2.620697e-003,0.000000e+000,0,,0,
1524353774.729,,0.000000e+000,5.499577e+001,-6.926597e-005,0.000000e+000,2,7.077452e-001,0.000000e+000,,,,,,,,,,,,,,32,1,4.000000e+000,5.249023e-003,0.000000e+000,0,,0,
1524353813.319,,0.000000e+000,5.499511e+001,-6.940650e-005,0.000000e+000,2,7.072625e-001,0.000000e+000,,,,,,,,,,,,,,32,1,4.000000e+000,6.568909e-003,0.000000e+000,0,,0,
1524353851.169,,0.000000e+000,5.500300e+001,-6.936736e-005,0.000000e+000,2,7.054834e-001,0.000000e+000,,,,,,,,,,,,,,32,1,4.000000e+000,6.580353e-003,0.000000e+000,0,,0,
1524353889.249,,0.000000e+000,5.499905e+001,-6.948530e-005,0.000000e+000,2,7.072081e-001,0.000000e+000,,,,,,,,,,,,,,32,1,4.000000e+000,1.319885e-003,0.000000e+000,0,,0,
1524353926.109,,0.000000e+000,5.499183e+001,-6.960802e-005,0.000000e+000,2,7.074374e-001,0.000000e+000,,,,,,,,,,,,,,32,1,4.000000e+000,2.632141e-003,0.000000e+000,0,,0,
1524353963.519,,0.000000e+000,5.499905e+001,-6.959158e-005,0.000000e+000,2,7.081122e-001,0.000000e+000,,,,,,,,,,,,,,32,1,4.000000e+000,3.948212e-003,0.000000e+000,0,,0,
1524354001.029,,0.000000e+000,5.499774e+001,-6.973519e-005,0.000000e+000,2,7.080422e-001,0.000000e+000,,,,,,,,,,,,,,32,1,4.000000e+000,3.940582e-003,0.000000e+000,0,,0,
1524354038.249,,0.000000e+000,5.499972e+001,-6.976508e-005,0.000000e+000,2,7.085470e-001,0.000000e+000,,,,,,,,,,,,,,32,1,4.000000e+000,1.314926e-002,0.000000e+000,0,,0,
1524354075.809,,0.000000e+000,5.500498e+001,-6.983737e-005,0.000000e+000,2,7.085633e-001,0.000000e+000,,,,,,,,,,,,,,32,1,4.000000e+000,2.620697e-003,0.000000e+000,0,,0,
1524354113.820,,0.000000e+000,5.499971e+001,-6.986607e-005,0.000000e+000,2,7.088438e-001,0.000000e+000,,,,,,,,,,,,,,32,1,4.000000e+000,0.000000e+000,0.000000e+000,0,,0,
1524354151.440,,0.000000e+000,5.500563e+001,-6.985557e-005,0.000000e+000,2,7.086577e-001,0.000000e+000,,,,,,,,,,,,,,32,1,4.000000e+000,1.319885e-003,0.000000e+000,0,,0,
1524354189.450,,0.000000e+000,5.499971e+001,-6.999946e-005,0.000000e+000,2,7.095773e-001,0.000000e+000,,,,,,,,,,,,,,32,1,4.000000e+000,2.639771e-003,0.000000e+000,0,,0,
1524354227.010,,0.000000e+000,5.499840e+001,-7.001314e-005,0.000000e+000,2,7.089438e-001,0.000000e+000,,,,,,,,,,,,,,32,1,4.000000e+000,1.314926e-002,0.000000e+000,0,,0,
1524354265.020,,0.000000e+000,5.499971e+001,-7.001914e-005,0.000000e+000,2,7.089497e-001,0.000000e+000,,,,,,,,,,,,,,32,1,4.000000e+000,0.000000e+000,0.000000e+000,0,,0,
1524354302.630,,0.000000e+000,5.499445e+001,-7.009220e-005,0.000000e+000,2,7.090195e-001,0.000000e+000,,,,,,,,,,,,,,32,1,4.000000e+000,2.628326e-003,0.000000e+000,0,,0,
1524354340.620,,0.000000e+000,5.499905e+001,-7.020773e-005,0.000000e+000,2,7.104294e-001,0.000000e+000,,,,,,,,,,,,,,32,1,4.000000e+000,3.948212e-003,0.000000e+000,0,,0,
1524354378.190,,0.000000e+000,5.499774e+001,-7.015746e-005,0.000000e+000,2,7.090482e-001,0.000000e+000,,,,,,,,,,,,,,32,1,4.000000e+000,1.446152e-002,0.000000e+000,0,,0,
1524354416.160,,0.000000e+000,5.499906e+001,-7.020690e-005,0.000000e+000,2,7.091457e-001,0.000000e+000,,,,,,,,,,,,,,32,1,4.000000e+000,9.220123e-003,0.000000e+000,0,,0,
1524354453.650,,0.000000e+000,5.499445e+001,-7.024591e-005,0.000000e+000,2,7.089565e-001,0.000000e+000,,,,,,,,,,,,,,32,1,4.000000e+000,7.881165e-003,0.000000e+000,0,,0,
1524354491.800,,0.000000e+000,5.500103e+001,-7.032583e-005,0.000000e+000,2,7.101167e-001,0.000000e+000,,,,,,,,,,,,,,32,1,4.000000e+000,2.639771e-003,0.000000e+000,0,,0,
1524354529.460,,0.000000e+000,5.500235e+001,-7.038152e-005,0.000000e+000,2,7.092116e-001,0.000000e+000,,,,,,,,,,,,,,32,1,4.000000e+000,2.639771e-003,0.000000e+000,0,,0,
1524354566.840,,0.000000e+000,5.499183e+001,-7.042348e-005,0.000000e+000,2,7.108539e-001,0.000000e+000,,,,,,,,,,,,,,32,1,4.000000e+000,7.888794e-003,0.000000e+000,0,,0,
1524354604.410,,0.000000e+000,5.500037e+001,-7.045918e-005,0.000000e+000,2,7.092952e-001,0.000000e+000,,,,,,,,,,,,,,32,1,4.000000e+000,1.446915e-002,0.000000e+000,0,,0,
1524354642.470,,0.000000e+000,5.499841e+001,-7.045123e-005,0.000000e+000,2,7.097552e-001,0.000000e+000,,,,,,,,,,,,,,32,1,4.000000e+000,1.052856e-002,0.000000e+000,0,,0,
1524354680.770,,0.000000e+000,5.499774e+001,-7.058282e-005,0.000000e+000,2,7.112979e-001,0.000000e+000,,,,,,,,,,,,,,32,1,4.000000e+000,1.710129e-002,0.000000e+000,0,,0,
1524354719.040,,0.000000e+000,5.499445e+001,-7.067408e-005,0.000000e+000,2,7.109033e-001,0.000000e+000,,,,,,,,,,,,,,32,1,4.000000e+000,5.260468e-003,0.000000e+000,0,,0,
1524354756.700,,0.000000e+000,5.499445e+001,-7.063698e-005,0.000000e+000,2,7.115086e-001,0.000000e+000,,,,,,,,,,,,,,32,1,4.000000e+000,7.881165e-003,0.000000e+000,0,,0,
1524354794.730,,0.000000e+000,5.499313e+001,-7.070299e-005,0.000000e+000,2,7.120806e-001,0.000000e+000,,,,,,,,,,,,,,32,1,4.000000e+000,1.314926e-002,0.000000e+000,0,,0,
1524354832.001,,0.000000e+000,5.499511e+001,-7.071545e-005,0.000000e+000,2,7.103695e-001,0.000000e+000,,,,,,,,,,,,,,32,1,4.000000e+000,3.940582e-003,0.000000e+000,0,,0,
1524354869.201,,0.000000e+000,5.499840e+001,-7.087276e-005,0.000000e+000,2,7.125803e-001,0.000000e+000,,,,,,,,,,,,,,32,1,4.000000e+000,5.260468e-003,0.000000e+000,0,,0,
1524354906.831,,0.000000e+000,5.499773e+001,-7.088242e-005,0.000000e+000,2,7.121277e-001,0.000000e+000,,,,,,,,,,,,,,32,1,4.000000e+000,1.308441e-003,0.000000e+000,0,,0,
1524354944.741,,0.000000e+000,5.500037e+001,-7.093455e-005,0.000000e+000,2,7.131643e-001,0.000000e+000,,,,,,,,,,,,,,32,1,4.000000e+000,1.319885e-003,0.000000e+000,0,,0,
1524354982.601,,0.000000e+000,5.500037e+001,-7.092142e-005,0.000000e+000,2,7.114001e-001,0.000000e+000,,,,,,,,,,,,,,32,1,4.000000e+000,1.184082e-002,0.000000e+000,0,,0,
1524355019.861,,0.000000e+000,5.499840e+001,-7.098507e-005,0.000000e+000,2,7.135498e-001,0.000000e+000,,,,,,,,,,,,,,32,1,4.000000e+000,7.900238e-003,0.000000e+000,0,,0,
1524355057.481,,0.000000e+000,5.499313e+001,-7.104314e-005,0.000000e+000,2,7.126719e-001,0.000000e+000,,,,,,,,,,,,,,32,1,4.000000e+000,1.050949e-002,0.000000e+000,0,,0,
1524355095.501,,0.000000e+000,5.500169e+001,-7.109701e-005,0.000000e+000,2,7.133231e-001,0.000000e+000,,,,,,,,,,,,,,32,1,4.000000e+000,1.319885e-003,0.000000e+000,0,,0,
1524355133.211,,0.000000e+000,5.500629e+001,-7.108010e-005,0.000000e+000,2,7.123004e-001,0.000000e+000,,,,,,,,,,,,,,32,1,4.000000e+000,1.580048e-002,0.000000e+000,0,,0,
1524355171.091,,0.000000e+000,5.500037e+001,-7.128479e-005,0.000000e+000,2,7.149568e-001,0.000000e+000,,,,,,,,,,,,,,32,1,4.000000e+000,1.319885e-003,0.000000e+000,0,,0,
1524355208.481,,0.000000e+000,5.499380e+001,-7.121317e-005,0.000000e+000,2,7.127681e-001,0.000000e+000,,,,,,,,,,,,,,32,1,4.000000e+000,3.948212e-003,0.000000e+000,0,,0,
1524355246.831,,0.000000e+000,5.499773e+001,-7.119936e-005,0.000000e+000,2,7.139601e-001,0.000000e+000,,,,,,,,,,,,,,32,1,4.000000e+000,1.308441e-003,0.000000e+000,0,,0,
1524355284.491,,0.000000e+000,5.499905e+001,-7.127089e-005,0.000000e+000,2,7.134909e-001,0.000000e+000,,,,,,,,,,,,,,32,1,4.000000e+000,3.948212e-003,0.000000e+000,0,,0,
1524355322.671,,0.000000e+000,5.499577e+001,-7.131211e-005,0.000000e+000,2,7.133288e-001,0.000000e+000,,,,,,,,,,,,,,32,1,4.000000e+000,7.888794e-003,0.000000e+000,0,,0,
1524355360.371,,0.000000e+000,5.499708e+001,-7.139408e-005,0.000000e+000,2,7.152177e-001,0.000000e+000,,,,,,,,,,,,,,32,1,4.000000e+000,0.000000e+000,0.000000e+000,0,,0,
1524355398.111,,0.000000e+000,5.500169e+001,-7.139141e-005,0.000000e+000,2,7.144799e-001,0.000000e+000,,,,,,,,,,,,,,32,1,4.000000e+000,3.959656e-003,0.000000e+000,0,,0,
1524355435.981,,0.000000e+000,5.499577e+001,-7.147834e-005,0.000000e+000,2,7.145146e-001,0.000000e+000,,,,,,,,,,,,,,32,1,4.000000e+000,5.249023e-003,0.000000e+000,0,,0,
1524355473.701,,0.000000e+000,5.499577e+001,-7.147680e-005,0.000000e+000,2,7.146129e-001,0.000000e+000,,,,,,,,,,,,,,32,1,4.000000e+000,2.632141e-003,0.000000e+000,0,,0,
1524355511.571,,0.000000e+000,5.499840e+001,-7.152191e-005,0.000000e+000,2,7.153057e-001,0.000000e+000,,,,,,,,,,,,,,32,1,4.000000e+000,5.260468e-003,0.000000e+000,0,,0,
1524355548.672,,0.000000e+000,5.499643e+001,-7.153531e-005,0.000000e+000,2,7.150617e-001,0.000000e+000,,,,,,,,,,,,,,32,1,4.000000e+000,1.312256e-003,0.000000e+000,0,,0,
1524355586.482,,0.000000e+000,5.499839e+001,-7.165455e-005,0.000000e+000,2,7.152623e-001,0.000000e+000,,,,,,,,,,,,,,32,1,4.000000e+000,0.000000e+000,0.000000e+000,0,,0,
1524355624.272,,0.000000e+000,5.499445e+001,-7.161935e-005,0.000000e+000,2,7.155730e-001,0.000000e+000,,,,,,,,,,,,,,32,1,4.000000e+000,5.260468e-003,0.000000e+000,0,,0,
1524355662.642,,0.000000e+000,5.500103e+001,-7.170123e-005,0.000000e+000,2,7.164864e-001,0.000000e+000,,,,,,,,,,,,,,32,1,4.000000e+000,2.639771e-003,0.000000e+000,0,,0,
1524355699.922,,0.000000e+000,5.499643e+001,-7.170469e-005,0.000000e+000,2,7.149532e-001,0.000000e+000,,,,,,,,,,,,,,32,1,4.000000e+000,1.312256e-003,0.000000e+000,0,,0,
1524355737.952,,0.000000e+000,5.499183e+001,-7.173255e-005,0.000000e+000,2,7.159902e-001,0.000000e+000,,,,,,,,,,,,,,32,1,4.000000e+000,2.632141e-003,0.000000e+000,0,,0,
1524355775.712,,0.000000e+000,5.499577e+001,-7.176168e-005,0.000000e+000,2,7.147209e-001,0.000000e+000,,,,,,,,,,,,,,32,1,4.000000e+000,2.632141e-003,0.000000e+000,0,,0,
1524355813.602,,0.000000e+000,5.499774e+001,-7.185157e-005,0.000000e+000,2,7.160112e-001,0.000000e+000,,,,,,,,,,,,,,32,1,4.000000e+000,3.940582e-003,0.000000e+000,0,,0,
1524355851.352,,0.000000e+000,5.500103e+001,-7.186900e-005,0.000000e+000,2,7.158916e-001,0.000000e+000,,,,,,,,,,,,,,32,1,4.000000e+000,0.000000e+000,0.000000e+000,0,,0,
1524355889.142,,0.000000e+000,5.499577e+001,-7.192936e-005,0.000000e+000,2,7.174486e-001,0.000000e+000,,,,,,,,,,,,,,32,1,4.000000e+000,5.249023e-003,0.000000e+000,0,,0,
1524355926.552,,0.000000e+000,5.500892e+001,-7.192049e-005,0.000000e+000,2,7.162021e-001,0.000000e+000,,,,,,,,,,,,,,32,1,4.000000e+000,5.260468e-003,0.000000e+000,0,,0,
1524355964.862,,0.000000e+000,5.500234e+001,-7.189127e-005,0.000000e+000,2,7.171203e-001,0.000000e+000,,,,,,,,,,,,,,32,1,4.000000e+000,7.900238e-003,0.000000e+000,0,,0,
1524356002.182,,0.000000e+000,5.499840e+001,-7.201850e-005,0.000000e+000,2,7.155061e-001,0.000000e+000,,,,,,,,,,,,,,32,1,4.000000e+000,2.628326e-003,0.000000e+000,0,,0,
1524356039.942,,0.000000e+000,5.499840e+001,-7.200949e-005,0.000000e+000,2,7.177040e-001,0.000000e+000,,,,,,,,,,,,,,32,1,4.000000e+000,5.260468e-003,0.000000e+000,0,,0,
1524356077.282,,0.000000e+000,5.500564e+001,-7.204400e-005,0.000000e+000,2,7.158648e-001,0.000000e+000,,,,,,,,,,,,,,32,1,4.000000e+000,3.940582e-003,0.000000e+000,0,,0,
1524356115.042,,0.000000e+000,5.499972e+001,-7.206640e-005,0.000000e+000,2,7.172345e-001,0.000000e+000,,,,,,,,,,,,,,32,1,4.000000e+000,5.268097e-003,0.000000e+000,0,,0,
1524356152.552,,0.000000e+000,5.500168e+001,-7.211399e-005,0.000000e+000,2,7.161000e-001,0.000000e+000,,,,,,,,,,,,,,32,1,4.000000e+000,6.580353e-003,0.000000e+000,0,,0,
1524356190.872,,0.000000e+000,5.499577e+001,-7.213421e-005,0.000000e+000,2,7.169840e-001,0.000000e+000,,,,,,,,,,,,,,32,1,4.000000e+000,0.000000e+000,0.000000e+000,0,,0,
1524356228.952,,0.000000e+000,5.499313e+001,-7.221136e-005,0.000000e+000,2,7.177728e-001,0.000000e+000,,,,,,,,,,,,,,32,1,4.000000e+000,2.628326e-003,0.000000e+000,0,,0,
1524356266.543,,0.000000e+000,5.500235e+001,-7.222126e-005,0.000000e+000,2,7.172920e-001,0.000000e+000,,,,,,,,,,,,,,32,1,4.000000e+000,2.639771e-003,0.000000e+000,0,,0,
1524356304.583,,0.000000e+000,5.500103e+001,-7.226507e-005,0.000000e+000,2,7.177342e-001,0.000000e+000,,,,,,,,,,,,,,32,1,4.000000e+000,5.279541e-003,0.000000e+000,0,,0,
1524356342.193,,0.000000e+000,5.499774e+001,-7.228089e-005,0.000000e+000,2,7.171662e-001,0.000000e+000,,,,,,,,,,,,,,32,1,4.000000e+000,6.580353e-003,0.000000e+000,0,,0,
1524356380.213,,0.000000e+000,5.500235e+001,-7.232372e-005,0.000000e+000,2,7.187053e-001,0.000000e+000,,,,,,,,,,,,,,32,1,4.000000e+000,2.639771e-003,0.000000e+000,0,,0,
1524356417.803,,0.000000e+000,5.500037e+001,-7.233243e-005,0.000000e+000,2,7.176093e-001,0.000000e+000,,,,,,,,,,,,,,32,1,4.000000e+000,1.319885e-003,0.000000e+000,0,,0,
1524356455.403,,0.000000e+000,5.499971e+001,-7.238877e-005,0.000000e+000,2,7.192047e-001,0.000000e+000,,,,,,,,,,,,,,32,1,4.000000e+000,2.639771e-003,0.000000e+000,0,,0,
1524356492.833,,0.000000e+000,5.499643e+001,-7.244581e-005,0.000000e+000,2,7.188740e-001,0.000000e+000,,,,,,,,,,,,,,32,1,4.000000e+000,1.184082e-002,0.000000e+000,0,,0,
1524356530.473,,0.000000e+000,5.499773e+001,-7.240069e-005,0.000000e+000,2,7.187228e-001,0.000000e+000,,,,,,,,,,,,,,32,1,4.000000e+000,1.308441e-003,0.000000e+000,0,,0,
1524356569.373,,0.000000e+000,5.499445e+001,-7.253740e-005,0.000000e+000,2,7.202898e-001,0.000000e+000,,,,,,,,,,,,,,32,1,4.000000e+000,2.628326e-003,0.000000e+000,0,,0,
1524356607.713,,0.000000e+000,5.499445e+001,-7.256852e-005,0.000000e+000,2,7.195301e-001,0.000000e+000,,,,,,,,,,,,,,32,1,4.000000e+000,5.260468e-003,0.000000e+000,0,,0,
1524356645.113,,0.000000e+000,5.499840e+001,-7.249010e-005,0.000000e+000,2,7.187448e-001,0.000000e+000,,,,,,,,,,,,,,32,1,4.000000e+000,1.314926e-002,0.000000e+000,0,,0,
1524356683.303,,0.000000e+000,5.499709e+001,-7.258033e-005,0.000000e+000,2,7.203234e-001,0.000000e+000,,,,,,,,,,,,,,32,1,4.000000e+000,7.888794e-003,0.000000e+000,0,,0,
1524356720.803,,0.000000e+000,5.499511e+001,-7.257230e-005,0.000000e+000,2,7.185507e-001,0.000000e+000,,,,,,,,,,,,,,32,1,4.000000e+000,6.568909e-003,0.000000e+000,0,,0,
1524356758.733,,0.000000e+000,5.499380e+001,-7.262450e-005,0.000000e+000,2,7.199203e-001,0.000000e+000,,,,,,,,,,,,,,32,1,4.000000e+000,1.308441e-003,0.000000e+000,0,,0,
1524356796.403,,0.000000e+000,5.499971e+001,-7.263554e-005,0.000000e+000,2,7.190346e-001,0.000000e+000,,,,,,,,,,,,,,32,1,4.000000e+000,2.639771e-003,0.000000e+000,0,,0,
1524356834.393,,0.000000e+000,5.499906e+001,-7.265528e-005,0.000000e+000,2,7.195399e-001,0.000000e+000,,,,,,,,,,,,,,32,1,4.000000e+000,9.220123e-003,0.000000e+000,0,,0,
1524356872.153,,0.000000e+000,5.500300e+001,-7.278073e-005,0.000000e+000,2,7.192169e-001,0.000000e+000,,,,,,,,,,,,,,32,1,4.000000e+000,3.940582e-003,0.000000e+000,0,,0,
1524356910.343,,0.000000e+000,5.500037e+001,-7.273448e-005,0.000000e+000,2,7.195851e-001,0.000000e+000,,,,,,,,,,,,,,32,1,4.000000e+000,1.319885e-003,0.000000e+000,0,,0,
1524356948.453,,0.000000e+000,5.500103e+001,-7.275485e-005,0.000000e+000,2,7.204669e-001,0.000000e+000,,,,,,,,,,,,,,32,1,4.000000e+000,7.888794e-003,0.000000e+000,0,,0,
1524356986.424,,0.000000e+000,5.499839e+001,-7.282392e-005,0.000000e+000,2,7.202690e-001,0.000000e+000,,,,,,,,,,,,,,32,1,4.000000e+000,0.000000e+000,0.000000e+000,0,,0,
1524357024.414,,0.000000e+000,5.499380e+001,-7.283206e-005,0.000000e+000,2,7.197580e-001,0.000000e+000,,,,,,,,,,,,,,32,1,4.000000e+000,1.308441e-003,0.000000e+000,0,,0,
1524357062.424,,0.000000e+000,5.499774e+001,-7.289202e-005,0.000000e+000,2,7.205415e-001,0.000000e+000,,,,,,,,,,,,,,32,1,4.000000e+000,3.940582e-003,0.000000e+000,0,,0,
1524357100.604,,0.000000e+000,5.499511e+001,-7.289034e-005,0.000000e+000,2,7.210194e-001,0.000000e+000,,,,,,,,,,,,,,32,1,4.000000e+000,3.940582e-003,0.000000e+000,0,,0,
1524357138.284,,0.000000e+000,5.499971e+001,-7.293167e-005,0.000000e+000,2,7.204167e-001,0.000000e+000,,,,,,,,,,,,,,32,1,4.000000e+000,0.000000e+000,0.000000e+000,0,,0,
1524357176.214,,0.000000e+000,5.499840e+001,-7.290232e-005,0.000000e+000,2,7.220017e-001,0.000000e+000,,,,,,,,,,,,,,32,1,4.000000e+000,2.628326e-003,0.000000e+000,0,,0,
1524357213.854,,0.000000e+000,5.500234e+001,-7.296460e-005,0.000000e+000,2,7.200031e-001,0.000000e+000,,,,,,,,,,,,,,32,1,4.000000e+000,7.900238e-003,0.000000e+000,0,,0,
1524357251.804,,0.000000e+000,5.500234e+001,-7.299315e-005,0.000000e+000,2,7.223537e-001,0.000000e+000,,,,,,,,,,,,,,32,1,4.000000e+000,7.900238e-003,0.000000e+000,0,,0,
1524357289.704,,0.000000e+000,5.499840e+001,-7.302508e-005,0.000000e+000,2,7.207667e-001,0.000000e+000,,,,,,,,,,,,,,32,1,4.000000e+000,7.900238e-003,0.000000e+000,0,,0,
1524357326.944,,0.000000e+000,5.499445e+001,-7.305951e-005,0.000000e+000,2,7.212202e-001,0.000000e+000,,,,,,,,,,,,,,32,1,4.000000e+000,0.000000e+000,0.000000e+000,0,,0,
1524357365.024,,0.000000e+000,5.500169e+001,-7.315370e-005,0.000000e+000,2,7.215670e-001,0.000000e+000,,,,,,,,,,,,,,32,1,4.000000e+000,1.319885e-003,0.000000e+000,0,,0,
1524357403.284,,0.000000e+000,5.499380e+001,-7.312997e-005,0.000000e+000,2,7.210214e-001,0.000000e+000,,,,,,,,,,,,,,32,1,4.000000e+000,1.308441e-003,0.000000e+000,0,,0,
1524357440.764,,0.000000e+000,5.500366e+001,-7.314394e-005,0.000000e+000,2,7.221788e-001,0.000000e+000,,,,,,,,,,,,,,32,1,4.000000e+000,2.620697e-003,0.000000e+000,0,,0,
1524357478.754,,0.000000e+000,5.500168e+001,-7.320210e-005,0.000000e+000,2,7.217542e-001,0.000000e+000,,,,,,,,,,,,,,32,1,4.000000e+000,6.580353e-003,0.000000e+000,0,,0,
1524357516.564,,0.000000e+000,5.499577e+001,-7.319848e-005,0.000000e+000,2,7.216088e-001,0.000000e+000,,,,,,,,,,,,,,32,1,4.000000e+000,2.632141e-003,0.000000e+000,0,,0,
1524357554.814,,0.000000e+000,5.499643e+001,-7.324006e-005,0.000000e+000,2,7.222083e-001,0.000000e+000,,,,,,,,,,,,,,32,1,4.000000e+000,1.312256e-003,0.000000e+000,0,,0,
1524357593.304,,0.000000e+000,5.500103e+001,-7.323630e-005,0.000000e+000,2,7.231333e-001,0.000000e+000,,,,,,,,,,,,,,32,1,4.000000e+000,5.279541e-003,0.000000e+000,0,,0,
1524357631.534,,0.000000e+000,5.499642e+001,-7.326520e-005,0.000000e+000,2,7.228563e-001,0.000000e+000,,,,,,,,,,,,,,32,1,4.000000e+000,3.940582e-003,0.000000e+000,0,,0,
1524357669.124,,0.000000e+000,5.499971e+001,-7.327860e-005,0.000000e+000,2,7.212986e-001,0.000000e+000,,,,,,,,,,,,,,32,1,4.000000e+000,2.639771e-003,0.000000e+000,0,,0,
1524357707.095,,0.000000e+000,5.499577e+001,-7.332501e-005,0.000000e+000,2,7.234982e-001,0.000000e+000,,,,,,,,,,,,,,32,1,4.000000e+000,5.249023e-003,0.000000e+000,0,,0,
1524357744.735,,0.000000e+000,5.499511e+001,-7.333075e-005,0.000000e+000,2,7.226014e-001,0.000000e+000,,,,,,,,,,,,,,32,1,4.000000e+000,1.319885e-003,0.000000e+000,0,,0,
1524357782.705,,0.000000e+000,5.499840e+001,-7.334373e-005,0.000000e+000,2,7.234617e-001,0.000000e+000,,,,,,,,,,,,,,32,1,4.000000e+000,5.260468e-003,0.000000e+000,0,,0,
1524357819.845,,0.000000e+000,5.500103e+001,-7.341162e-005,0.000000e+000,2,7.222345e-001,0.000000e+000,,,,,,,,,,,,,,32,1,4.000000e+000,2.639771e-003,0.000000e+000,0,,0,
1524357858.295,,0.000000e+000,5.499840e+001,-7.346978e-005,0.000000e+000,2,7.229291e-001,0.000000e+000,,,,,,,,,,,,,,32,1,4.000000e+000,1.842117e-002,0.000000e+000,0,,0,
1524357895.905,,0.000000e+000,5.500300e+001,-7.344833e-005,0.000000e+000,2,7.232475e-001,0.000000e+000,,,,,,,,,,,,,,32,1,4.000000e+000,1.183701e-002,0.000000e+000,0,,0,
1524357933.765,,0.000000e+000,5.499773e+001,-7.345069e-005,0.000000e+000,2,7.222436e-001,0.000000e+000,,,,,,,,,,,,,,32,1,4.000000e+000,1.308441e-003,0.000000e+000,0,,0,
1524357971.775,,0.000000e+000,5.499971e+001,-7.345858e-005,0.000000e+000,2,7.240880e-001,0.000000e+000,,,,,,,,,,,,,,32,1,4.000000e+000,2.639771e-003,0.000000e+000,0,,0,
1524358008.635,,0.000000e+000,5.499511e+001,-7.350177e-005,0.000000e+000,2,7.229038e-001,0.000000e+000,,,,,,,,,,,,,,32,1,4.000000e+000,6.568909e-003,0.000000e+000,0,,0,
1524358046.615,,0.000000e+000,5.499642e+001,-7.354752e-005,0.000000e+000,2,7.239892e-001,0.000000e+000,,,,,,,,,,,,,,32,1,4.000000e+000,3.940582e-003,0.000000e+000,0,,0,
1524358084.515,,0.000000e+000,5.500365e+001,-7.355028e-005,0.000000e+000,2,7.243545e-001,0.000000e+000,,,,,,,,,,,,,,32,1,4.000000e+000,1.052856e-002,0.000000e+000,0,,0,
1524358122.235,,0.000000e+000,5.499708e+001,-7.358747e-005,0.000000e+000,2,7.230657e-001,0.000000e+000,,,,,,,,,,,,,,32,1,4.000000e+000,0.000000e+000,0.000000e+000,0,,0,
1524358159.655,,0.000000e+000,5.500169e+001,-7.363137e-005,0.000000e+000,2,7.252039e-001,0.000000e+000,,,,,,,,,,,,,,32,1,4.000000e+000,1.184082e-002,0.000000e+000,0,,0,
1524358197.285,,0.000000e+000,5.499577e+001,-7.368447e-005,0.000000e+000,2,7.245458e-001,0.000000e+000,,,,,,,,,,,,,,32,1,4.000000e+000,1.052094e-002,0.000000e+000,0,,0,
1524358235.155,,0.000000e+000,5.499774e+001,-7.362119e-005,0.000000e+000,2,7.237094e-001,0.000000e+000,,,,,,,,,,,,,,32,1,4.000000e+000,3.940582e-003,0.000000e+000,0,,0,
1524358273.645,,0.000000e+000,5.500103e+001,-7.370848e-005,0.000000e+000,2,7.247981e-001,0.000000e+000,,,,,,,,,,,,,,32,1,4.000000e+000,2.639771e-003,0.000000e+000,0,,0,
1524358311.305,,0.000000e+000,5.500037e+001,-7.365570e-005,0.000000e+000,2,7.238621e-001,0.000000e+000,,,,,,,,,,,,,,32,1,4.000000e+000,3.959656e-003,0.000000e+000,0,,0,
1524358348.745,,0.000000e+000,5.499708e+001,-7.373137e-005,0.000000e+000,2,7.256665e-001,0.000000e+000,,,,,,,,,,,,,,32,1,4.000000e+000,0.000000e+000,0.000000e+000,0,,0,
1524358386.375,,0.000000e+000,5.500037e+001,-7.373789e-005,0.000000e+000,2,7.245048e-001,0.000000e+000,,,,,,,,,,,,,,32,1,4.000000e+000,1.184082e-002,0.000000e+000,0,,0,
1524358423.916,,0.000000e+000,5.500169e+001,-7.380883e-005,0.000000e+000,2,7.250581e-001,0.000000e+000,,,,,,,,,,,,,,32,1,4.000000e+000,1.319885e-003,0.000000e+000,0,,0,
1524358461.256,,0.000000e+000,5.499905e+001,-7.376113e-005,0.000000e+000,2,7.243025e-001,0.000000e+000,,,,,,,,,,,,,,32,1,4.000000e+000,1.319885e-003,0.000000e+000,0,,0,
1524358499.986,,0.000000e+000,5.499511e+001,-7.380188e-005,0.000000e+000,2,7.250304e-001,0.000000e+000,,,,,,,,,,,,,,32,1,4.000000e+000,1.319885e-003,0.000000e+000,0,,0,
1524358537.526,,0.000000e+000,5.500366e+001,-7.383180e-005,0.000000e+000,2,7.239450e-001,0.000000e+000,,,,,,,,,,,,,,32,1,4.000000e+000,2.620697e-003,0.000000e+000,0,,0,
1524358574.916,,0.000000e+000,5.500234e+001,-7.385058e-005,0.000000e+000,2,7.253549e-001,0.000000e+000,,,,,,,,,,,,,,32,1,4.000000e+000,5.260468e-003,0.000000e+000,0,,0,
1524358613.426,,0.000000e+000,5.499445e+001,-7.384561e-005,0.000000e+000,2,7.256762e-001,0.000000e+000,,,,,,,,,,,,,,32,1,4.000000e+000,1.052094e-002,0.000000e+000,0,,0,
1524358651.086,,0.000000e+000,5.500235e+001,-7.384898e-005,0.000000e+000,2,7.245778e-001,0.000000e+000,,,,,,,,,,,,,,32,1,4.000000e+000,2.639771e-003,0.000000e+000,0,,0,
1524358689.036,,0.000000e+000,5.499774e+001,-7.396194e-005,0.000000e+000,2,7.253577e-001,0.000000e+000,,,,,,,,,,,,,,32,1,4.000000e+000,3.940582e-003,0.000000e+000,0,,0,
1524358726.546,,0.000000e+000,5.500103e+001,-7.394206e-005,0.000000e+000,2,7.247623e-001,0.000000e+000,,,,,,,,,,,,,,32,1,4.000000e+000,0.000000e+000,0.000000e+000,0,,0,
1524358765.196,,0.000000e+000,5.500037e+001,-7.395713e-005,0.000000e+000,2,7.247590e-001,0.000000e+000,,,,,,,,,,,,,,32,1,4.000000e+000,1.319885e-003,0.000000e+000,0,,0,
1524358803.436,,0.000000e+000,5.499708e+001,-7.399297e-005,0.000000e+000,2,7.263095e-001,0.000000e+000,,,,,,,,,,,,,,32,1,4.000000e+000,0.000000e+000,0.000000e+000,0,,0,
1524358841.136,,0.000000e+000,5.499773e+001,-7.407351e-005,0.000000e+000,2,7.261965e-001,0.000000e+000,,,,,,,,,,,,,,32,1,4.000000e+000,1.308441e-003,0.000000e+000,0,,0,
1524358878.476,,0.000000e+000,5.500300e+001,-7.403560e-005,0.000000e+000,2,7.265208e-001,0.000000e+000,,,,,,,,,,,,,,32,1,4.000000e+000,9.220123e-003,0.000000e+000,0,,0,
1524358916.216,,0.000000e+000,5.499380e+001,-7.404578e-005,0.000000e+000,2,7.250823e-001,0.000000e+000,,,,,,,,,,,,,,32,1,4.000000e+000,6.572723e-003,0.000000e+000,0,,0,
1524358954.126,,0.000000e+000,5.500103e+001,-7.405744e-005,0.000000e+000,2,7.257153e-001,0.000000e+000,,,,,,,,,,,,,,32,1,4.000000e+000,2.639771e-003,0.000000e+000,0,,0,
1524358992.066,,0.000000e+000,5.499840e+001,-7.405378e-005,0.000000e+000,2,7.265765e-001,0.000000e+000,,,,,,,,,,,,,,32,1,4.000000e+000,7.900238e-003,0.000000e+000,0,,0,
1524359029.616,,0.000000e+000,5.499577e+001,-7.413089e-005,0.000000e+000,2,7.239646e-001,0.000000e+000,,,,,,,,,,,,,,32,1,4.000000e+000,5.249023e-003,0.000000e+000,0,,0,
1524359067.126,,0.000000e+000,5.499511e+001,-7.406568e-005,0.000000e+000,2,7.259988e-001,0.000000e+000,,,,,,,,,,,,,,32,1,4.000000e+000,3.940582e-003,0.000000e+000,0,,0,
1524359105.197,,0.000000e+000,5.499906e+001,-7.416853e-005,0.000000e+000,2,7.255921e-001,0.000000e+000,,,,,,,,,,,,,,32,1,4.000000e+000,9.220123e-003,0.000000e+000,0,,0,
1524359142.787,,0.000000e+000,5.499773e+001,-7.424656e-005,0.000000e+000,2,7.269340e-001,0.000000e+000,,,,,,,,,,,,,,32,1,4.000000e+000,1.308441e-003,0.000000e+000,0,,0,
1524359179.777,,0.000000e+000,5.500432e+001,-7.418489e-005,0.000000e+000,2,7.258114e-001,0.000000e+000,,,,,,,,,,,,,,32,1,4.000000e+000,6.580353e-003,0.000000e+000,0,,0,
1524359218.347,,0.000000e+000,5.499972e+001,-7.426509e-005,0.000000e+000,2,7.270528e-001,0.000000e+000,,,,,,,,,,,,,,32,1,4.000000e+000,5.268097e-003,0.000000e+000,0,,0,
1524359256.067,,0.000000e+000,5.500169e+001,-7.422669e-005,0.000000e+000,2,7.268129e-001,0.000000e+000,,,,,,,,,,,,,,32,1,4.000000e+000,1.319885e-003,0.000000e+000,0,,0,
1524359294.077,,0.000000e+000,5.500301e+001,-7.432223e-005,0.000000e+000,2,7.265043e-001,0.000000e+000,,,,,,,,,,,,,,32,1,4.000000e+000,1.446915e-002,0.000000e+000,0,,0,
1524359331.197,,0.000000e+000,5.499577e+001,-7.429731e-005,0.000000e+000,2,7.269780e-001,0.000000e+000,,,,,,,,,,,,,,32,1,4.000000e+000,0.000000e+000,0.000000e+000,0,,0,
1524359369.447,,0.000000e+000,5.499117e+001,-7.435340e-005,0.000000e+000,2,7.274716e-001,0.000000e+000,,,,,,,,,,,,,,32,1,4.000000e+000,1.312256e-003,0.000000e+000,0,,0,
1524359407.227,,0.000000e+000,5.499643e+001,-7.428852e-005,0.000000e+000,2,7.265779e-001,0.000000e+000,,,,,,,,,,,,,,32,1,4.000000e+000,6.568909e-003,0.000000e+000,0,,0,
1524359445.247,,0.000000e+000,5.500168e+001,-7.436109e-005,0.000000e+000,2,7.271659e-001,0.000000e+000,,,,,,,,,,,,,,32,1,4.000000e+000,6.580353e-003,0.000000e+000,0,,0,
1524359482.907,,0.000000e+000,5.499905e+001,-7.436135e-005,0.000000e+000,2,7.262058e-001,0.000000e+000,,,,,,,,,,,,,,32,1,4.000000e+000,3.948212e-003,0.000000e+000,0,,0,
1524359520.847,,0.000000e+000,5.499840e+001,-7.438826e-005,0.000000e+000,2,7.279192e-001,0.000000e+000,,,,,,,,,,,,,,32,1,4.000000e+000,2.628326e-003,0.000000e+000,0,,0,
1524359558.507,,0.000000e+000,5.499839e+001,-7.438874e-005,0.000000e+000,2,7.265550e-001,0.000000e+000,,,,,,,,,,,,,,32,1,4.000000e+000,0.000000e+000,0.000000e+000,0,,0,
1524359596.467,,0.000000e+000,5.499971e+001,-7.440083e-005,0.000000e+000,2,7.278450e-001,0.000000e+000,,,,,,,,,,,,,,32,1,4.000000e+000,2.639771e-003,0.000000e+000,0,,0,
1524359634.167,,0.000000e+000,5.499708e+001,-7.444626e-005,0.000000e+000,2,7.269456e-001,0.000000e+000,,,,,,,,,,,,,,32,1,4.000000e+000,0.000000e+000,0.000000e+000,0,,0,
1524359672.107,,0.000000e+000,5.500037e+001,-7.456844e-005,0.000000e+000,2,7.290401e-001,0.000000e+000,,,,,,,,,,,,,,32,1,4.000000e+000,3.959656e-003,0.000000e+000,0,,0,
1524359709.787,,0.000000e+000,5.499643e+001,-7.450152e-005,0.000000e+000,2,7.273431e-001,0.000000e+000,,,,,,,,,,,,,,32,1,4.000000e+000,6.568909e-003,0.000000e+000,0,,0,
1524359747.727,,0.000000e+000,5.499839e+001,-7.449230e-005,0.000000e+000,2,7.279456e-001,0.000000e+000,,,,,,,,,,,,,,32,1,4.000000e+000,0.000000e+000,0.000000e+000,0,,0,
1524359785.397,,0.000000e+000,5.499905e+001,-7.451022e-005,0.000000e+000,2,7.268313e-001,0.000000e+000,,,,,,,,,,,,,,32,1,4.000000e+000,1.319885e-003,0.000000e+000,0,,0,
1524359823.348,,0.000000e+000,5.499511e+001,-7.446600e-005,0.000000e+000,2,7.282481e-001,0.000000e+000,,,,,,,,,,,,,,32,1,4.000000e+000,1.319885e-003,0.000000e+000,0,,0,
1524359861.028,,0.000000e+000,5.499708e+001,-7.455602e-005,0.000000e+000,2,7.274911e-001,0.000000e+000,,,,,,,,,,,,,,32,1,4.000000e+000,2.620697e-003,0.000000e+000,0,,0,
1524359898.968,,0.000000e+000,5.500169e+001,-7.454013e-005,0.000000e+000,2,7.286788e-001,0.000000e+000,,,,,,,,,,,,,,32,1,4.000000e+000,1.319885e-003,0.000000e+000,0,,0,
1524359936.368,,0.000000e+000,5.499643e+001,-7.457640e-005,0.000000e+000,2,7.276449e-001,0.000000e+000,,,,,,,,,,,,,,32,1,4.000000e+000,1.312256e-003,0.000000e+000,0,,0,
1524359974.028,,0.000000e+000,5.499642e+001,-7.458034e-005,0.000000e+000,2,7.282233e-001,0.000000e+000,,,,,,,,,,,,,,32,1,4.000000e+000,3.940582e-003,0.000000e+000,0,,0,
1524360011.698,,0.000000e+000,5.500103e+001,-7.454857e-005,0.000000e+000,2,7.278698e-001,0.000000e+000,,,,,,,,,,,,,,32,1,4.000000e+000,7.888794e-003,0.000000e+000,0,,0,
1524360049.788,,0.000000e+000,5.500431e+001,-7.458827e-005,0.000000e+000,2,7.279119e-001,0.000000e+000,,,,,,,,,,,,,,32,1,4.000000e+000,9.208679e-003,0.000000e+000,0,,0,
1524360087.538,,0.000000e+000,5.499708e+001,-7.470401e-005,0.000000e+000,2,7.282831e-001,0.000000e+000,,,,,,,,,,,,,,32,1,4.000000e+000,5.260468e-003,0.000000e+000,0,,0,
1524360125.708,,0.000000e+000,5.499708e+001,-7.469268e-005,0.000000e+000,2,7.283360e-001,0.000000e+000,,,,,,,,,,,,,,32,1,4.000000e+000,5.260468e-003,0.000000e+000,0,,0,
1524360163.588,,0.000000e+000,5.500300e+001,-7.476865e-005,0.000000e+000,2,7.291083e-001,0.000000e+000,,,,,,,,,,,,,,32,1,4.000000e+000,1.183701e-002,0.000000e+000,0,,0,
1524360201.018,,0.000000e+000,5.499906e+001,-7.470966e-005,0.000000e+000,2,7.278591e-001,0.000000e+000,,,,,,,,,,,,,,32,1,4.000000e+000,1.710129e-002,0.000000e+000,0,,0,
1524360238.188,,0.000000e+000,5.499643e+001,-7.477566e-005,0.000000e+000,2,7.300158e-001,0.000000e+000,,,,,,,,,,,,,,32,1,4.000000e+000,1.448059e-002,0.000000e+000,0,,0,
1524360275.898,,0.000000e+000,5.498788e+001,-7.477332e-005,0.000000e+000,2,7.295936e-001,0.000000e+000,,,,,,,,,,,,,,32,1,4.000000e+000,0.000000e+000,0.000000e+000,0,,0,
1524360313.598,,0.000000e+000,5.499971e+001,-7.484757e-005,0.000000e+000,2,7.296456e-001,0.000000e+000,,,,,,,,,,,,,,32,1,4.000000e+000,0.000000e+000,0.000000e+000,0,,0,
1524360351.458,,0.000000e+000,5.499708e+001,-7.476276e-005,0.000000e+000,2,7.283652e-001,0.000000e+000,,,,,,,,,,,,,,32,1,4.000000e+000,2.620697e-003,0.000000e+000,0,,0,
1524360389.438,,0.000000e+000,5.499839e+001,-7.479420e-005,0.000000e+000,2,7.299907e-001,0.000000e+000,,,,,,,,,,,,,,32,1,4.000000e+000,0.000000e+000,0.000000e+000,0,,0,
1524360427.188,,0.000000e+000,5.500103e+001,-7.483078e-005,0.000000e+000,2,7.285210e-001,0.000000e+000,,,,,,,,,,,,,,32,1,4.000000e+000,0.000000e+000,0.000000e+000,0,,0,
1524360465.248,,0.000000e+000,5.498853e+001,-7.481493e-005,0.000000e+000,2,7.280198e-001,0.000000e+000,,,,,,,,,,,,,,32,1,4.000000e+000,9.212494e-003,0.000000e+000,0,,0,
1524360502.318,,0.000000e+000,5.499905e+001,-7.485003e-005,0.000000e+000,2,7.295761e-001,0.000000e+000,,,,,,,,,,,,,,32,1,4.000000e+000,1.319885e-003,0.000000e+000,0,,0,
1524360539.619,,0.000000e+000,5.500301e+001,-7.481749e-005,0.000000e+000,2,7.285267e-001,0.000000e+000,,,,,,,,,,,,,,32,1,4.000000e+000,1.319885e-003,0.000000e+000,0,,0,
1524360576.859,,0.000000e+000,5.499905e+001,-7.488379e-005,0.000000e+000,2,7.304099e-001,0.000000e+000,,,,,,,,,,,,,,32,1,4.000000e+000,1.319885e-003,0.000000e+000,0,,0,
1524360614.539,,0.000000e+000,5.498985e+001,-7.492039e-005,0.000000e+000,2,7.292753e-001,0.000000e+000,,,,,,,,,,,,,,32,1,4.000000e+000,1.708984e-002,0.000000e+000,0,,0,
1524360652.639,,0.000000e+000,5.499840e+001,-7.488029e-005,0.000000e+000,2,7.299953e-001,0.000000e+000,,,,,,,,,,,,,,32,1,4.000000e+000,7.900238e-003,0.000000e+000,0,,0,
1524360690.399,,0.000000e+000,5.500169e+001,-7.494889e-005,0.000000e+000,2,7.308325e-001,0.000000e+000,,,,,,,,,,,,,,32,1,4.000000e+000,3.959656e-003,0.000000e+000,0,,0,
1524360727.519,,0.000000e+000,5.499708e+001,-7.495799e-005,0.000000e+000,2,7.298352e-001,0.000000e+000,,,,,,,,,,,,,,32,1,4.000000e+000,2.620697e-003,0.000000e+000,0,,0,
1524360764.869,,0.000000e+000,5.499708e+001,-7.498541e-005,0.000000e+000,2,7.294623e-001,0.000000e+000,,,,,,,,,,,,,,32,1,4.000000e+000,2.620697e-003,0.000000e+000,0,,0,
1524360802.259,,0.000000e+000,5.499709e+001,-7.494948e-005,0.000000e+000,2,7.297899e-001,0.000000e+000,,,,,,,,,,,,,,32,1,4.000000e+000,1.316071e-002,0.000000e+000,0,,0,
1524360839.879,,0.000000e+000,5.500037e+001,-7.496624e-005,0.000000e+000,2,7.289069e-001,0.000000e+000,,,,,,,,,,,,,,32,1,4.000000e+000,1.319885e-003,0.000000e+000,0,,0,
1524360877.549,,0.000000e+000,5.499577e+001,-7.497506e-005,0.000000e+000,2,7.305962e-001,0.000000e+000,,,,,,,,,,,,,,32,1,4.000000e+000,2.632141e-003,0.000000e+000,0,,0,
1524360915.389,,0.000000e+000,5.499905e+001,-7.505611e-005,0.000000e+000,2,7.296252e-001,0.000000e+000,,,,,,,,,,,,,,32,1,4.000000e+000,3.948212e-003,0.000000e+000,0,,0,
1524360952.969,,0.000000e+000,5.500432e+001,-7.499563e-005,0.000000e+000,2,7.299724e-001,0.000000e+000,,,,,,,,,,,,,,32,1,4.000000e+000,6.580353e-003,0.000000e+000,0,,0,
1524360991.149,,0.000000e+000,5.500037e+001,-7.510896e-005,0.000000e+000,2,7.303696e-001,0.000000e+000,,,,,,,,,,,,,,32,1,4.000000e+000,3.959656e-003,0.000000e+000,0,,0,
1524361029.219,,0.000000e+000,5.499773e+001,-7.503268e-005,0.000000e+000,2,7.296665e-001,0.000000e+000,,,,,,,,,,,,,,32,1,4.000000e+000,1.308441e-003,0.000000e+000,0,,0,
1524361067.369,,0.000000e+000,5.500103e+001,-7.510655e-005,0.000000e+000,2,7.306081e-001,0.000000e+000,,,,,,,,,,,,,,32,1,4.000000e+000,0.000000e+000,0.000000e+000,0,,0,
1524361105.029,,0.000000e+000,5.499708e+001,-7.510083e-005,0.000000e+000,2,7.298684e-001,0.000000e+000,,,,,,,,,,,,,,32,1,4.000000e+000,5.260468e-003,0.000000e+000,0,,0,
1524361143.029,,0.000000e+000,5.499839e+001,-7.516803e-005,0.000000e+000,2,7.312291e-001,0.000000e+000,,,,,,,,,,,,,,32,1,4.000000e+000,0.000000e+000,0.000000e+000,0,,0,
1524361180.739,,0.000000e+000,5.499643e+001,-7.508901e-005,0.000000e+000,2,7.297311e-001,0.000000e+000,,,,,,,,,,,,,,32,1,4.000000e+000,1.312256e-003,0.000000e+000,0,,0,
1524361218.399,,0.000000e+000,5.500037e+001,-7.516684e-005,0.000000e+000,2,7.308359e-001,0.000000e+000,,,,,,,,,,,,,,32,1,4.000000e+000,9.201050e-003,0.000000e+000,0,,0,
1524361255.770,,0.000000e+000,5.500103e+001,-7.517145e-005,0.000000e+000,2,7.300004e-001,0.000000e+000,,,,,,,,,,,,,,32,1,4.000000e+000,5.279541e-003,0.000000e+000,0,,0,
1524361293.690,,0.000000e+000,5.499971e+001,-7.517341e-005,0.000000e+000,2,7.313322e-001,0.000000e+000,,,,,,,,,,,,,,32,1,4.000000e+000,2.639771e-003,0.000000e+000,0,,0,
1524361331.080,,0.000000e+000,5.499773e+001,-7.520078e-005,0.000000e+000,2,7.300994e-001,0.000000e+000,,,,,,,,,,,,,,32,1,4.000000e+000,1.308441e-003,0.000000e+000,0,,0,
1524361368.350,,0.000000e+000,5.500168e+001,-7.525666e-005,0.000000e+000,2,7.313872e-001,0.000000e+000,,,,,,,,,,,,,,32,1,4.000000e+000,6.580353e-003,0.000000e+000,0,,0,
1524361406.690,,0.000000e+000,5.499906e+001,-7.529113e-005,0.000000e+000,2,7.309746e-001,0.000000e+000,,,,,,,,,,,,,,32,1,4.000000e+000,9.220123e-003,0.000000e+000,0,,0,
1524361445.100,,0.000000e+000,5.499840e+001,-7.528979e-005,0.000000e+000,2,7.299727e-001,0.000000e+000,,,,,,,,,,,,,,32,1,4.000000e+000,2.628326e-003,0.000000e+000,0,,0,
1524361482.400,,0.000000e+000,5.500037e+001,-7.532690e-005,0.000000e+000,2,7.314921e-001,0.000000e+000,,,,,,,,,,,,,,32,1,4.000000e+000,1.319885e-003,0.000000e+000,0,,0,
1524361520.720,,0.000000e+000,5.500037e+001,-7.532871e-005,0.000000e+000,2,7.313461e-001,0.000000e+000,,,,,,,,,,,,,,32,1,4.000000e+000,2.236176e-002,0.000000e+000,0,,0,
1524361557.810,,0.000000e+000,5.500103e+001,-7.528574e-005,0.000000e+000,2,7.317857e-001,0.000000e+000,,,,,,,,,,,,,,32,1,4.000000e+000,7.888794e-003,0.000000e+000,0,,0,
1524361595.140,,0.000000e+000,5.500037e+001,-7.529854e-005,0.000000e+000,2,7.310930e-001,0.000000e+000,,,,,,,,,,,,,,32,1,4.000000e+000,6.587982e-003,0.000000e+000,0,,0,
1524361633.170,,0.000000e+000,5.499445e+001,-7.529885e-005,0.000000e+000,2,7.313984e-001,0.000000e+000,,,,,,,,,,,,,,32,1,4.000000e+000,0.000000e+000,0.000000e+000,0,,0,
1524361671.270,,0.000000e+000,5.499774e+001,-7.531009e-005,0.000000e+000,2,7.311992e-001,0.000000e+000,,,,,,,,,,,,,,32,1,4.000000e+000,3.940582e-003,0.000000e+000,0,,0,
1524361708.600,,0.000000e+000,5.499511e+001,-7.536893e-005,0.000000e+000,2,7.313174e-001,0.000000e+000,,,,,,,,,,,,,,32,1,4.000000e+000,6.568909e-003,0.000000e+000,0,,0,
1524361746.480,,0.000000e+000,5.499971e+001,-7.534407e-005,0.000000e+000,2,7.320743e-001,0.000000e+000,,,,,,,,,,,,,,32,1,4.000000e+000,2.639771e-003,0.000000e+000,0,,0,
1524361783.650,,0.000000e+000,5.499972e+001,-7.537082e-005,0.000000e+000,2,7.309312e-001,0.000000e+000,,,,,,,,,,,,,,32,1,4.000000e+000,5.268097e-003,0.000000e+000,0,,0,
1524361821.460,,0.000000e+000,5.499380e+001,-7.534368e-005,0.000000e+000,2,7.314436e-001,0.000000e+000,,,,,,,,,,,,,,32,1,4.000000e+000,6.572723e-003,0.000000e+000,0,,0,
1524361859.510,,0.000000e+000,5.499972e+001,-7.543866e-005,0.000000e+000,2,7.321190e-001,0.000000e+000,,,,,,,,,,,,,,32,1,4.000000e+000,5.268097e-003,0.000000e+000,0,,0,
1524361897.310,,0.000000e+000,5.499971e+001,-7.540671e-005,0.000000e+000,2,7.320758e-001,0.000000e+000,,,,,,,,,,,,,,32,1,4.000000e+000,2.639771e-003,0.000000e+000,0,,0,
1524361934.660,,0.000000e+000,5.500367e+001,-7.543467e-005,0.000000e+000,2,7.324144e-001,0.000000e+000,,,,,,,,,,,,,,32,1,4.000000e+000,0.000000e+000,0.000000e+000,0,,0,
1524361972.441,,0.000000e+000,5.500103e+001,-7.544452e-005,0.000000e+000,2,7.320977e-001,0.000000e+000,,,,,,,,,,,,,,32,1,4.000000e+000,0.000000e+000,0.000000e+000,0,,0,
1524362010.291,,0.000000e+000,5.500234e+001,-7.541478e-005,0.000000e+000,2,7.324327e-001,0.000000e+000,,,,,,,,,,,,,,32,1,4.000000e+000,7.900238e-003,0.000000e+000,0,,0,
1524362048.071,,0.000000e+000,5.499775e+001,-7.547808e-005,0.000000e+000,2,7.317926e-001,0.000000e+000,,,,,,,,,,,,,,32,1,4.000000e+000,9.208679e-003,0.000000e+000,0,,0,
1524362060.711,,0.000000e+000,5.499643e+001,-7.552488e-005,0.000000e+000,2,7.324244e-001,0.000000e+000,,,,,,,,,,,,,,32,1,4.000000e+000,1.312256e-003,0.000000e+000,0,,0,