File: Experimental Raw Data/TC04-12-01K VRMac VRMde/TC04-12-01K_VRMac_54K_3000s_VRMde_55K.dc.dat
[Header]
TITLE,MPMS DC Measurement
BYAPP,MPMS Measurement,2.1,Summary
FILEOPENTIME, 1524301677.964000 4/21/2018, 3:07:57 AM

INFO, APPNAME, MPMS MultiVu Application, Revision 1.61,  Build 082

INFO, NAME, TC04-12-01K
INFO, WEIGHT, 1.000
INFO, AREA, 1.000
INFO, LENGTH, 1.000
INFO, SHAPE, 0
INFO, COMMENT,
INFO, SEQUENCE FILE: VRMac_54K_3000s_VRMde_55K.seq


INFO, BACKGROUND DATA FILE:, None


STARTUPAXIS,X,4,LINEAR,AUTO,0.000000,0.000000
STARTUPAXIS,Y1,5,LINEAR,AUTO,0.000000,0.000000


STARTUPGROUP,Longitudinal
FIELDGROUP,Longitudinal,1,2,3,4,5,6,7,8,9,15,16,17,18,27,28
FIELDGROUP,Transverse,1,2,3,4,10,11,12,13,14,19,20,21,22,27,28

PLOT_APPEARANCE,ALL,HORZ_GRID_ON,VERT_GRID_ON,MARKERS_AND_LINES

[Data]
Time,Comment,Field (Oe),Temperature (K),Long Moment (emu),Long Scan Std Dev,Long Algorithm,Long Reg Fit,Long Percent Error (%),Trans Moment (emu),Trans Scan Std Dev,Trans Algorithm,Trans Reg Fit,Trans Percent Error (%),Long Moment [w/o ABS] (emu),Long Scan Std Dev [w/o ABS],Long Reg Fit [w/o ABS],Long Percent Error [w/o ABS] (%),Trans Moment [w/o ABS] (emu),Trans Scan Std Dev [w/o ABS],Trans Reg Fit [w/o ABS],Trans Percent Error [w/o ABS] (%),Points per Scan,Scans per Measurement,Scan Length (cm),Delta Temp (K),Rot Position (deg),Error,EC Comp. Running,Using ABS,
1524301677.964,,0.000000e+000,5.413065e+001,-1.399533e-005,0.000000e+000,2,9.119149e-001,0.000000e+000,,,,,,,,,,,,,,32,1,4.000000e+000,2.493477e-001,0.000000e+000,0,,0,
1524301718.264,,0.000000e+000,5.501355e+001,-9.598627e-006,0.000000e+000,2,8.448578e-001,0.000000e+000,,,,,,,,,,,,,,32,1,4.000000e+000,6.449127e-002,0.000000e+000,0,,0,
1524301756.924,,0.000000e+000,5.505238e+001,-7.202552e-006,0.000000e+000,2,7.965863e-001,0.000000e+000,,,,,,,,,,,,,,32,1,4.000000e+000,7.907867e-003,0.000000e+000,0,,0,
1524301794.414,,0.000000e+000,5.501814e+001,-5.986975e-006,0.000000e+000,2,7.511311e-001,0.000000e+000,,,,,,,,,,,,,,32,1,4.000000e+000,2.632141e-003,0.000000e+000,0,,0,
1524301832.034,,0.000000e+000,5.500893e+001,-4.923241e-006,0.000000e+000,2,6.728645e-001,0.000000e+000,,,,,,,,,,,,,,32,1,4.000000e+000,2.628326e-003,0.000000e+000,0,,0,
1524301869.484,,0.000000e+000,5.499511e+001,-4.142963e-006,0.000000e+000,2,6.381999e-001,0.000000e+000,,,,,,,,,,,,,,32,1,4.000000e+000,6.568909e-003,0.000000e+000,0,,0,
1524301907.554,,0.000000e+000,5.500103e+001,-3.668078e-006,0.000000e+000,2,5.828945e-001,0.000000e+000,,,,,,,,,,,,,,32,1,4.000000e+000,0.000000e+000,0.000000e+000,0,,0,
1524301944.824,,0.000000e+000,5.499577e+001,-3.110803e-006,0.000000e+000,2,5.000885e-001,0.000000e+000,,,,,,,,,,,,,,32,1,4.000000e+000,7.888794e-003,0.000000e+000,0,,0,
1524301983.335,,0.000000e+000,5.499905e+001,-2.616008e-006,0.000000e+000,2,4.014444e-001,0.000000e+000,,,,,,,,,,,,,,32,1,4.000000e+000,1.182938e-002,0.000000e+000,0,,0,
1524302021.085,,0.000000e+000,5.499774e+001,-2.257890e-006,0.000000e+000,2,3.089615e-001,0.000000e+000,,,,,,,,,,,,,,32,1,4.000000e+000,3.940582e-003,0.000000e+000,0,,0,
1524302059.895,,0.000000e+000,5.499906e+001,-1.942281e-006,0.000000e+000,2,2.385681e-001,0.000000e+000,,,,,,,,,,,,,,32,1,4.000000e+000,1.710129e-002,0.000000e+000,0,,0,
1524302097.445,,0.000000e+000,5.500037e+001,-1.616932e-006,0.000000e+000,2,0.000000e+000,0.000000e+000,,,,,,,,,,,,,,32,1,4.000000e+000,1.446915e-002,0.000000e+000,0,,0,
1524302135.965,,0.000000e+000,5.499511e+001,-1.306812e-006,0.000000e+000,2,0.000000e+000,0.000000e+000,,,,,,,,,,,,,,32,1,4.000000e+000,9.201050e-003,0.000000e+000,0,,0,
1524302174.235,,0.000000e+000,5.499774e+001,-1.133257e-006,0.000000e+000,2,0.000000e+000,0.000000e+000,,,,,,,,,,,,,,32,1,4.000000e+000,3.940582e-003,0.000000e+000,0,,0,
1524302211.895,,0.000000e+000,5.499905e+001,-9.568447e-007,0.000000e+000,2,0.000000e+000,0.000000e+000,,,,,,,,,,,,,,32,1,4.000000e+000,3.948212e-003,0.000000e+000,0,,0,
1524302249.855,,0.000000e+000,5.499905e+001,-7.210469e-007,0.000000e+000,2,0.000000e+000,0.000000e+000,,,,,,,,,,,,,,32,1,4.000000e+000,3.948212e-003,0.000000e+000,0,,0,
1524302287.445,,0.000000e+000,5.499905e+001,-5.824010e-007,0.000000e+000,2,0.000000e+000,0.000000e+000,,,,,,,,,,,,,,32,1,4.000000e+000,3.948212e-003,0.000000e+000,0,,0,
1524302325.405,,0.000000e+000,5.499445e+001,-4.137251e-007,0.000000e+000,2,0.000000e+000,0.000000e+000,,,,,,,,,,,,,,32,1,4.000000e+000,0.000000e+000,0.000000e+000,0,,0,
1524302363.555,,0.000000e+000,5.499577e+001,-3.329321e-007,0.000000e+000,2,0.000000e+000,0.000000e+000,,,,,,,,,,,,,,32,1,4.000000e+000,0.000000e+000,0.000000e+000,0,,0,
1524302401.355,,0.000000e+000,5.499577e+001,-9.906782e-008,0.000000e+000,2,0.000000e+000,0.000000e+000,,,,,,,,,,,,,,32,1,4.000000e+000,1.052094e-002,0.000000e+000,0,,0,
1524302439.565,,0.000000e+000,5.500432e+001,1.981687e-010,0.000000e+000,2,0.000000e+000,0.000000e+000,,,,,,,,,,,,,,32,1,4.000000e+000,3.940582e-003,0.000000e+000,0,,0,
1524302476.965,,0.000000e+000,5.500695e+001,8.242367e-008,0.000000e+000,2,0.000000e+000,0.000000e+000,,,,,,,,,,,,,,32,1,4.000000e+000,1.448059e-002,0.000000e+000,0,,0,
1524302514.635,,0.000000e+000,5.499511e+001,2.312145e-007,0.000000e+000,2,0.000000e+000,0.000000e+000,,,,,,,,,,,,,,32,1,4.000000e+000,6.568909e-003,0.000000e+000,0,,0,
1524302553.205,,0.000000e+000,5.500366e+001,3.010508e-007,0.000000e+000,2,0.000000e+000,0.000000e+000,,,,,,,,,,,,,,32,1,4.000000e+000,1.315689e-002,0.000000e+000,0,,0,
1524302591.035,,0.000000e+000,5.500169e+001,5.115527e-007,0.000000e+000,2,0.000000e+000,0.000000e+000,,,,,,,,,,,,,,32,1,4.000000e+000,9.208679e-003,0.000000e+000,0,,0,
1524302628.975,,0.000000e+000,5.500103e+001,5.051085e-007,0.000000e+000,2,0.000000e+000,0.000000e+000,,,,,,,,,,,,,,32,1,4.000000e+000,0.000000e+000,0.000000e+000,0,,0,
1524302666.695,,0.000000e+000,5.499971e+001,6.868811e-007,0.000000e+000,2,0.000000e+000,0.000000e+000,,,,,,,,,,,,,,32,1,4.000000e+000,2.639771e-003,0.000000e+000,0,,0,
1524302704.606,,0.000000e+000,5.500037e+001,7.227226e-007,0.000000e+000,2,0.000000e+000,0.000000e+000,,,,,,,,,,,,,,32,1,4.000000e+000,3.959656e-003,0.000000e+000,0,,0,
1524302742.196,,0.000000e+000,5.499708e+001,7.888620e-007,0.000000e+000,2,0.000000e+000,0.000000e+000,,,,,,,,,,,,,,32,1,4.000000e+000,0.000000e+000,0.000000e+000,0,,0,
1524302780.236,,0.000000e+000,5.500103e+001,8.736783e-007,0.000000e+000,2,0.000000e+000,0.000000e+000,,,,,,,,,,,,,,32,1,4.000000e+000,2.639771e-003,0.000000e+000,0,,0,
1524302817.806,,0.000000e+000,5.499445e+001,9.080954e-007,0.000000e+000,2,0.000000e+000,0.000000e+000,,,,,,,,,,,,,,32,1,4.000000e+000,5.260468e-003,0.000000e+000,0,,0,
1524302855.806,,0.000000e+000,5.499775e+001,1.016683e-006,0.000000e+000,2,0.000000e+000,0.000000e+000,,,,,,,,,,,,,,32,1,4.000000e+000,9.208679e-003,0.000000e+000,0,,0,
1524302893.396,,0.000000e+000,5.500432e+001,1.002475e-006,0.000000e+000,2,0.000000e+000,0.000000e+000,,,,,,,,,,,,,,32,1,4.000000e+000,6.580353e-003,0.000000e+000,0,,0,
1524302931.236,,0.000000e+000,5.499643e+001,1.156226e-006,0.000000e+000,2,0.000000e+000,0.000000e+000,,,,,,,,,,,,,,32,1,4.000000e+000,1.312256e-003,0.000000e+000,0,,0,
1524302968.686,,0.000000e+000,5.499708e+001,1.162537e-006,0.000000e+000,2,0.000000e+000,0.000000e+000,,,,,,,,,,,,,,32,1,4.000000e+000,2.620697e-003,0.000000e+000,0,,0,
1524303006.356,,0.000000e+000,5.499972e+001,1.249738e-006,0.000000e+000,2,0.000000e+000,0.000000e+000,,,,,,,,,,,,,,32,1,4.000000e+000,5.268097e-003,0.000000e+000,0,,0,
1524303044.306,,0.000000e+000,5.499708e+001,1.375898e-006,0.000000e+000,2,0.000000e+000,0.000000e+000,,,,,,,,,,,,,,32,1,4.000000e+000,5.260468e-003,0.000000e+000,0,,0,
1524303081.886,,0.000000e+000,5.500168e+001,1.447997e-006,0.000000e+000,2,0.000000e+000,0.000000e+000,,,,,,,,,,,,,,32,1,4.000000e+000,6.580353e-003,0.000000e+000,0,,0,
1524303119.396,,0.000000e+000,5.499905e+001,1.502893e-006,0.000000e+000,2,0.000000e+000,0.000000e+000,,,,,,,,,,,,,,32,1,4.000000e+000,1.319885e-003,0.000000e+000,0,,0,
1524303157.196,,0.000000e+000,5.499445e+001,1.552367e-006,0.000000e+000,2,0.000000e+000,0.000000e+000,,,,,,,,,,,,,,32,1,4.000000e+000,7.881165e-003,0.000000e+000,0,,0,
1524303195.006,,0.000000e+000,5.499905e+001,1.572969e-006,0.000000e+000,2,0.000000e+000,0.000000e+000,,,,,,,,,,,,,,32,1,4.000000e+000,3.948212e-003,0.000000e+000,0,,0,
1524303232.376,,0.000000e+000,5.499380e+001,1.615927e-006,0.000000e+000,2,0.000000e+000,0.000000e+000,,,,,,,,,,,,,,32,1,4.000000e+000,3.948212e-003,0.000000e+000,0,,0,
1524303270.116,,0.000000e+000,5.499972e+001,1.654531e-006,0.000000e+000,2,1.849035e-002,0.000000e+000,,,,,,,,,,,,,,32,1,4.000000e+000,5.268097e-003,0.000000e+000,0,,0,
1524303307.476,,0.000000e+000,5.499643e+001,1.678062e-006,0.000000e+000,2,1.987328e-002,0.000000e+000,,,,,,,,,,,,,,32,1,4.000000e+000,1.312256e-003,0.000000e+000,0,,0,
1524303344.946,,0.000000e+000,5.499972e+001,1.766646e-006,0.000000e+000,2,9.912767e-002,0.000000e+000,,,,,,,,,,,,,,32,1,4.000000e+000,5.268097e-003,0.000000e+000,0,,0,
1524303382.866,,0.000000e+000,5.499445e+001,1.739245e-006,0.000000e+000,2,0.000000e+000,0.000000e+000,,,,,,,,,,,,,,32,1,4.000000e+000,1.314926e-002,0.000000e+000,0,,0,
1524303420.977,,0.000000e+000,5.499511e+001,1.753137e-006,0.000000e+000,2,6.360929e-002,0.000000e+000,,,,,,,,,,,,,,32,1,4.000000e+000,1.319885e-003,0.000000e+000,0,,0,
1524303459.607,,0.000000e+000,5.500103e+001,1.884014e-006,0.000000e+000,2,1.607931e-001,0.000000e+000,,,,,,,,,,,,,,32,1,4.000000e+000,2.639771e-003,0.000000e+000,0,,0,
1524303497.307,,0.000000e+000,5.499643e+001,1.908859e-006,0.000000e+000,2,1.082442e-001,0.000000e+000,,,,,,,,,,,,,,32,1,4.000000e+000,9.208679e-003,0.000000e+000,0,,0,
1524303535.117,,0.000000e+000,5.499577e+001,1.954166e-006,0.000000e+000,2,1.914108e-001,0.000000e+000,,,,,,,,,,,,,,32,1,4.000000e+000,5.249023e-003,0.000000e+000,0,,0,
1524303572.457,,0.000000e+000,5.500103e+001,1.925714e-006,0.000000e+000,2,1.293710e-001,0.000000e+000,,,,,,,,,,,,,,32,1,4.000000e+000,7.888794e-003,0.000000e+000,0,,0,
1524303610.917,,0.000000e+000,5.499642e+001,1.966276e-006,0.000000e+000,2,1.753922e-001,0.000000e+000,,,,,,,,,,,,,,32,1,4.000000e+000,3.940582e-003,0.000000e+000,0,,0,
1524303648.267,,0.000000e+000,5.499577e+001,1.984887e-006,0.000000e+000,2,1.340107e-001,0.000000e+000,,,,,,,,,,,,,,32,1,4.000000e+000,1.316071e-002,0.000000e+000,0,,0,
1524303685.497,,0.000000e+000,5.499708e+001,2.014568e-006,0.000000e+000,2,2.024750e-001,0.000000e+000,,,,,,,,,,,,,,32,1,4.000000e+000,2.620697e-003,0.000000e+000,0,,0,
1524303723.077,,0.000000e+000,5.500103e+001,2.063360e-006,0.000000e+000,2,2.002952e-001,0.000000e+000,,,,,,,,,,,,,,32,1,4.000000e+000,7.888794e-003,0.000000e+000,0,,0,
1524303761.127,,0.000000e+000,5.499971e+001,2.103477e-006,0.000000e+000,2,2.375115e-001,0.000000e+000,,,,,,,,,,,,,,32,1,4.000000e+000,0.000000e+000,0.000000e+000,0,,0,
1524303798.627,,0.000000e+000,5.499774e+001,2.152035e-006,0.000000e+000,2,2.086817e-001,0.000000e+000,,,,,,,,,,,,,,32,1,4.000000e+000,3.940582e-003,0.000000e+000,0,,0,
1524303836.437,,0.000000e+000,5.499248e+001,2.095421e-006,0.000000e+000,2,2.130641e-001,0.000000e+000,,,,,,,,,,,,,,32,1,4.000000e+000,1.319885e-003,0.000000e+000,0,,0,
1524303873.737,,0.000000e+000,5.500037e+001,2.067513e-006,0.000000e+000,2,1.764503e-001,0.000000e+000,,,,,,,,,,,,,,32,1,4.000000e+000,1.319885e-003,0.000000e+000,0,,0,
1524303911.507,,0.000000e+000,5.499511e+001,2.198762e-006,0.000000e+000,2,2.391810e-001,0.000000e+000,,,,,,,,,,,,,,32,1,4.000000e+000,1.319885e-003,0.000000e+000,0,,0,
1524303949.127,,0.000000e+000,5.500301e+001,2.184588e-006,0.000000e+000,2,2.451914e-001,0.000000e+000,,,,,,,,,,,,,,32,1,4.000000e+000,1.319885e-003,0.000000e+000,0,,0,
1524303987.127,,0.000000e+000,5.500169e+001,2.210239e-006,0.000000e+000,2,2.424462e-001,0.000000e+000,,,,,,,,,,,,,,32,1,4.000000e+000,1.184082e-002,0.000000e+000,0,,0,
1524304024.607,,0.000000e+000,5.499314e+001,2.255641e-006,0.000000e+000,2,2.797689e-001,0.000000e+000,,,,,,,,,,,,,,32,1,4.000000e+000,0.000000e+000,0.000000e+000,0,,0,
1524304062.787,,0.000000e+000,5.500498e+001,2.110387e-006,0.000000e+000,2,2.177039e-001,0.000000e+000,,,,,,,,,,,,,,32,1,4.000000e+000,5.260468e-003,0.000000e+000,0,,0,
1524304100.747,,0.000000e+000,5.500169e+001,2.305666e-006,0.000000e+000,2,2.621374e-001,0.000000e+000,,,,,,,,,,,,,,32,1,4.000000e+000,3.959656e-003,0.000000e+000,0,,0,
1524304138.638,,0.000000e+000,5.499313e+001,2.333306e-006,0.000000e+000,2,3.007883e-001,0.000000e+000,,,,,,,,,,,,,,32,1,4.000000e+000,7.892609e-003,0.000000e+000,0,,0,
1524304176.258,,0.000000e+000,5.499379e+001,2.438197e-006,0.000000e+000,2,2.927747e-001,0.000000e+000,,,,,,,,,,,,,,32,1,4.000000e+000,9.201050e-003,0.000000e+000,0,,0,
1524304214.248,,0.000000e+000,5.499773e+001,2.373935e-006,0.000000e+000,2,2.973683e-001,0.000000e+000,,,,,,,,,,,,,,32,1,4.000000e+000,1.308441e-003,0.000000e+000,0,,0,
1524304251.828,,0.000000e+000,5.500235e+001,2.397905e-006,0.000000e+000,2,2.964122e-001,0.000000e+000,,,,,,,,,,,,,,32,1,4.000000e+000,2.639771e-003,0.000000e+000,0,,0,
1524304289.888,,0.000000e+000,5.499708e+001,2.432696e-006,0.000000e+000,2,3.329156e-001,0.000000e+000,,,,,,,,,,,,,,32,1,4.000000e+000,2.620697e-003,0.000000e+000,0,,0,
1524304327.458,,0.000000e+000,5.499774e+001,2.459227e-006,0.000000e+000,2,3.258341e-001,0.000000e+000,,,,,,,,,,,,,,32,1,4.000000e+000,1.710129e-002,0.000000e+000,0,,0,
1524304365.538,,0.000000e+000,5.499971e+001,2.464237e-006,0.000000e+000,2,3.354546e-001,0.000000e+000,,,,,,,,,,,,,,32,1,4.000000e+000,0.000000e+000,0.000000e+000,0,,0,
1524304403.168,,0.000000e+000,5.499971e+001,2.490513e-006,0.000000e+000,2,3.278887e-001,0.000000e+000,,,,,,,,,,,,,,32,1,4.000000e+000,2.639771e-003,0.000000e+000,0,,0,
1524304440.678,,0.000000e+000,5.500234e+001,2.476151e-006,0.000000e+000,2,3.411922e-001,0.000000e+000,,,,,,,,,,,,,,32,1,4.000000e+000,7.900238e-003,0.000000e+000,0,,0,
1524304478.758,,0.000000e+000,5.499511e+001,2.436100e-006,0.000000e+000,2,3.175240e-001,0.000000e+000,,,,,,,,,,,,,,32,1,4.000000e+000,6.568909e-003,0.000000e+000,0,,0,
1524304516.098,,0.000000e+000,5.500168e+001,2.449674e-006,0.000000e+000,2,3.441941e-001,0.000000e+000,,,,,,,,,,,,,,32,1,4.000000e+000,6.580353e-003,0.000000e+000,0,,0,
1524304553.618,,0.000000e+000,5.500103e+001,2.384619e-006,0.000000e+000,2,3.066207e-001,0.000000e+000,,,,,,,,,,,,,,32,1,4.000000e+000,7.888794e-003,0.000000e+000,0,,0,
1524304591.438,,0.000000e+000,5.500037e+001,2.473893e-006,0.000000e+000,2,3.431143e-001,0.000000e+000,,,,,,,,,,,,,,32,1,4.000000e+000,3.959656e-003,0.000000e+000,0,,0,
1524304629.758,,0.000000e+000,5.499773e+001,2.542591e-006,0.000000e+000,2,3.577327e-001,0.000000e+000,,,,,,,,,,,,,,32,1,4.000000e+000,1.308441e-003,0.000000e+000,0,,0,
1524304667.068,,0.000000e+000,5.499972e+001,2.474355e-006,0.000000e+000,2,3.565099e-001,0.000000e+000,,,,,,,,,,,,,,32,1,4.000000e+000,7.900238e-003,0.000000e+000,0,,0,
1524304704.908,,0.000000e+000,5.499971e+001,2.521861e-006,0.000000e+000,2,3.192116e-001,0.000000e+000,,,,,,,,,,,,,,32,1,4.000000e+000,2.639771e-003,0.000000e+000,0,,0,
1524304742.698,,0.000000e+000,5.499709e+001,2.459610e-006,0.000000e+000,2,3.726418e-001,0.000000e+000,,,,,,,,,,,,,,32,1,4.000000e+000,7.888794e-003,0.000000e+000,0,,0,
1524304781.018,,0.000000e+000,5.499643e+001,2.596300e-006,0.000000e+000,2,3.444685e-001,0.000000e+000,,,,,,,,,,,,,,32,1,4.000000e+000,1.312256e-003,0.000000e+000,0,,0,
1524304818.378,,0.000000e+000,5.499642e+001,2.390582e-006,0.000000e+000,2,3.452834e-001,0.000000e+000,,,,,,,,,,,,,,32,1,4.000000e+000,3.940582e-003,0.000000e+000,0,,0,
1524304856.129,,0.000000e+000,5.499643e+001,2.574719e-006,0.000000e+000,2,3.514258e-001,0.000000e+000,,,,,,,,,,,,,,32,1,4.000000e+000,6.568909e-003,0.000000e+000,0,,0,
1524304893.989,,0.000000e+000,5.500103e+001,2.410321e-006,0.000000e+000,2,3.545895e-001,0.000000e+000,,,,,,,,,,,,,,32,1,4.000000e+000,0.000000e+000,0.000000e+000,0,,0,
1524304931.749,,0.000000e+000,5.499972e+001,2.395211e-006,0.000000e+000,2,3.319101e-001,0.000000e+000,,,,,,,,,,,,,,32,1,4.000000e+000,7.900238e-003,0.000000e+000,0,,0,
1524304969.389,,0.000000e+000,5.499971e+001,2.477962e-006,0.000000e+000,2,3.801926e-001,0.000000e+000,,,,,,,,,,,,,,32,1,4.000000e+000,0.000000e+000,0.000000e+000,0,,0,
1524305007.159,,0.000000e+000,5.500037e+001,2.486530e-006,0.000000e+000,2,3.572707e-001,0.000000e+000,,,,,,,,,,,,,,32,1,4.000000e+000,1.319885e-003,0.000000e+000,0,,0,
1524305044.569,,0.000000e+000,5.499445e+001,2.514874e-006,0.000000e+000,2,3.753486e-001,0.000000e+000,,,,,,,,,,,,,,32,1,4.000000e+000,2.628326e-003,0.000000e+000,0,,0,
1524305082.109,,0.000000e+000,5.500103e+001,2.520543e-006,0.000000e+000,2,3.600246e-001,0.000000e+000,,,,,,,,,,,,,,32,1,4.000000e+000,5.279541e-003,0.000000e+000,0,,0,
1524305120.119,,0.000000e+000,5.499972e+001,2.577723e-006,0.000000e+000,2,3.970194e-001,0.000000e+000,,,,,,,,,,,,,,32,1,4.000000e+000,1.314926e-002,0.000000e+000,0,,0,
1524305157.759,,0.000000e+000,5.499511e+001,2.606097e-006,0.000000e+000,2,3.606077e-001,0.000000e+000,,,,,,,,,,,,,,32,1,4.000000e+000,3.940582e-003,0.000000e+000,0,,0,
1524305195.769,,0.000000e+000,5.499117e+001,2.648409e-006,0.000000e+000,2,3.921682e-001,0.000000e+000,,,,,,,,,,,,,,32,1,4.000000e+000,6.568909e-003,0.000000e+000,0,,0,
1524305232.759,,0.000000e+000,5.499708e+001,2.658275e-006,0.000000e+000,2,3.653811e-001,0.000000e+000,,,,,,,,,,,,,,32,1,4.000000e+000,5.260468e-003,0.000000e+000,0,,0,
1524305270.269,,0.000000e+000,5.500234e+001,2.492325e-006,0.000000e+000,2,3.887942e-001,0.000000e+000,,,,,,,,,,,,,,32,1,4.000000e+000,5.260468e-003,0.000000e+000,0,,0,
1524305307.949,,0.000000e+000,5.499708e+001,2.795304e-006,0.000000e+000,2,3.954037e-001,0.000000e+000,,,,,,,,,,,,,,32,1,4.000000e+000,0.000000e+000,0.000000e+000,0,,0,
1524305345.839,,0.000000e+000,5.499643e+001,2.760437e-006,0.000000e+000,2,3.912052e-001,0.000000e+000,,,,,,,,,,,,,,32,1,4.000000e+000,1.312256e-003,0.000000e+000,0,,0,
1524305383.199,,0.000000e+000,5.500169e+001,2.804526e-006,0.000000e+000,2,3.902483e-001,0.000000e+000,,,,,,,,,,,,,,32,1,4.000000e+000,1.319885e-003,0.000000e+000,0,,0,
1524305420.939,,0.000000e+000,5.499313e+001,2.781942e-006,0.000000e+000,2,4.097931e-001,0.000000e+000,,,,,,,,,,,,,,32,1,4.000000e+000,2.628326e-003,0.000000e+000,0,,0,
1524305458.609,,0.000000e+000,5.499708e+001,2.825036e-006,0.000000e+000,2,3.773826e-001,0.000000e+000,,,,,,,,,,,,,,32,1,4.000000e+000,0.000000e+000,0.000000e+000,0,,0,
1524305495.989,,0.000000e+000,5.499773e+001,2.825860e-006,0.000000e+000,2,4.189384e-001,0.000000e+000,,,,,,,,,,,,,,32,1,4.000000e+000,1.308441e-003,0.000000e+000,0,,0,
1524305533.459,,0.000000e+000,5.499773e+001,2.772619e-006,0.000000e+000,2,3.613751e-001,0.000000e+000,,,,,,,,,,,,,,32,1,4.000000e+000,1.308441e-003,0.000000e+000,0,,0,
1524305571.830,,0.000000e+000,5.499643e+001,2.872109e-006,0.000000e+000,2,4.200071e-001,0.000000e+000,,,,,,,,,,,,,,32,1,4.000000e+000,1.312256e-003,0.000000e+000,0,,0,
1524305609.870,,0.000000e+000,5.499380e+001,2.810107e-006,0.000000e+000,2,4.046472e-001,0.000000e+000,,,,,,,,,,,,,,32,1,4.000000e+000,1.446915e-002,0.000000e+000,0,,0,
1524305647.640,,0.000000e+000,5.499773e+001,2.876353e-006,0.000000e+000,2,4.011832e-001,0.000000e+000,,,,,,,,,,,,,,32,1,4.000000e+000,1.308441e-003,0.000000e+000,0,,0,
1524305685.360,,0.000000e+000,5.499840e+001,2.792379e-006,0.000000e+000,2,4.208785e-001,0.000000e+000,,,,,,,,,,,,,,32,1,4.000000e+000,5.260468e-003,0.000000e+000,0,,0,
1524305723.040,,0.000000e+000,5.499905e+001,2.955667e-006,0.000000e+000,2,4.350202e-001,0.000000e+000,,,,,,,,,,,,,,32,1,4.000000e+000,1.319885e-003,0.000000e+000,0,,0,
1524305760.570,,0.000000e+000,5.499708e+001,2.945740e-006,0.000000e+000,2,4.547460e-001,0.000000e+000,,,,,,,,,,,,,,32,1,4.000000e+000,5.260468e-003,0.000000e+000,0,,0,
1524305798.200,,0.000000e+000,5.499643e+001,2.849570e-006,0.000000e+000,2,4.111776e-001,0.000000e+000,,,,,,,,,,,,,,32,1,4.000000e+000,1.312256e-003,0.000000e+000,0,,0,
1524305836.130,,0.000000e+000,5.499577e+001,2.901804e-006,0.000000e+000,2,4.053764e-001,0.000000e+000,,,,,,,,,,,,,,32,1,4.000000e+000,5.249023e-003,0.000000e+000,0,,0,
1524305873.480,,0.000000e+000,5.500037e+001,2.867574e-006,0.000000e+000,2,4.291081e-001,0.000000e+000,,,,,,,,,,,,,,32,1,4.000000e+000,1.319885e-003,0.000000e+000,0,,0,
1524305910.820,,0.000000e+000,5.499182e+001,2.887922e-006,0.000000e+000,2,3.977585e-001,0.000000e+000,,,,,,,,,,,,,,32,1,4.000000e+000,1.314163e-002,0.000000e+000,0,,0,
1524305948.400,,0.000000e+000,5.499840e+001,2.949409e-006,0.000000e+000,2,4.497631e-001,0.000000e+000,,,,,,,,,,,,,,32,1,4.000000e+000,2.628326e-003,0.000000e+000,0,,0,
1524305986.970,,0.000000e+000,5.499840e+001,2.894857e-006,0.000000e+000,2,4.353758e-001,0.000000e+000,,,,,,,,,,,,,,32,1,4.000000e+000,5.260468e-003,0.000000e+000,0,,0,
1524306025.020,,0.000000e+000,5.499643e+001,2.950504e-006,0.000000e+000,2,4.160520e-001,0.000000e+000,,,,,,,,,,,,,,32,1,4.000000e+000,6.568909e-003,0.000000e+000,0,,0,
1524306063.040,,0.000000e+000,5.499577e+001,2.958950e-006,0.000000e+000,2,4.393189e-001,0.000000e+000,,,,,,,,,,,,,,32,1,4.000000e+000,7.888794e-003,0.000000e+000,0,,0,
1524306100.600,,0.000000e+000,5.499313e+001,2.940670e-006,0.000000e+000,2,4.268601e-001,0.000000e+000,,,,,,,,,,,,,,32,1,4.000000e+000,7.892609e-003,0.000000e+000,0,,0,
1524306138.650,,0.000000e+000,5.499708e+001,2.968605e-006,0.000000e+000,2,4.440382e-001,0.000000e+000,,,,,,,,,,,,,,32,1,4.000000e+000,5.260468e-003,0.000000e+000,0,,0,
1524306176.310,,0.000000e+000,5.499511e+001,3.032129e-006,0.000000e+000,2,4.250177e-001,0.000000e+000,,,,,,,,,,,,,,32,1,4.000000e+000,3.940582e-003,0.000000e+000,0,,0,
1524306214.250,,0.000000e+000,5.499839e+001,2.975553e-006,0.000000e+000,2,4.468363e-001,0.000000e+000,,,,,,,,,,,,,,32,1,4.000000e+000,0.000000e+000,0.000000e+000,0,,0,
1524306252.000,,0.000000e+000,5.499051e+001,2.963699e-006,0.000000e+000,2,4.291642e-001,0.000000e+000,,,,,,,,,,,,,,32,1,4.000000e+000,7.888794e-003,0.000000e+000,0,,0,
1524306289.891,,0.000000e+000,5.499905e+001,2.986414e-006,0.000000e+000,2,4.473716e-001,0.000000e+000,,,,,,,,,,,,,,32,1,4.000000e+000,3.948212e-003,0.000000e+000,0,,0,
1524306327.481,,0.000000e+000,5.499183e+001,3.050881e-006,0.000000e+000,2,4.498859e-001,0.000000e+000,,,,,,,,,,,,,,32,1,4.000000e+000,1.840973e-002,0.000000e+000,0,,0,
1524306365.451,,0.000000e+000,5.499643e+001,3.008071e-006,0.000000e+000,2,4.535000e-001,0.000000e+000,,,,,,,,,,,,,,32,1,4.000000e+000,1.312256e-003,0.000000e+000,0,,0,
1524306403.061,,0.000000e+000,5.499905e+001,3.028996e-006,0.000000e+000,2,4.410298e-001,0.000000e+000,,,,,,,,,,,,,,32,1,4.000000e+000,3.948212e-003,0.000000e+000,0,,0,
1524306440.521,,0.000000e+000,5.499840e+001,3.012954e-006,0.000000e+000,2,4.592367e-001,0.000000e+000,,,,,,,,,,,,,,32,1,4.000000e+000,2.628326e-003,0.000000e+000,0,,0,
1524306478.181,,0.000000e+000,5.499773e+001,3.074186e-006,0.000000e+000,2,4.483491e-001,0.000000e+000,,,,,,,,,,,,,,32,1,4.000000e+000,1.308441e-003,0.000000e+000,0,,0,
1524306516.031,,0.000000e+000,5.499248e+001,2.986550e-006,0.000000e+000,2,4.439445e-001,0.000000e+000,,,,,,,,,,,,,,32,1,4.000000e+000,3.940582e-003,0.000000e+000,0,,0,
1524306553.811,,0.000000e+000,5.499905e+001,3.045905e-006,0.000000e+000,2,4.396829e-001,0.000000e+000,,,,,,,,,,,,,,32,1,4.000000e+000,1.319885e-003,0.000000e+000,0,,0,
1524306591.881,,0.000000e+000,5.500169e+001,3.039595e-006,0.000000e+000,2,4.456127e-001,0.000000e+000,,,,,,,,,,,,,,32,1,4.000000e+000,1.319885e-003,0.000000e+000,0,,0,
1524306629.581,,0.000000e+000,5.500301e+001,3.003461e-006,0.000000e+000,2,4.383281e-001,0.000000e+000,,,,,,,,,,,,,,32,1,4.000000e+000,1.319885e-003,0.000000e+000,0,,0,
1524306667.781,,0.000000e+000,5.499971e+001,3.122173e-006,0.000000e+000,2,4.607624e-001,0.000000e+000,,,,,,,,,,,,,,32,1,4.000000e+000,0.000000e+000,0.000000e+000,0,,0,
1524306705.771,,0.000000e+000,5.499577e+001,3.058403e-006,0.000000e+000,2,4.602017e-001,0.000000e+000,,,,,,,,,,,,,,32,1,4.000000e+000,5.249023e-003,0.000000e+000,0,,0,
1524306743.801,,0.000000e+000,5.499643e+001,3.008403e-006,0.000000e+000,2,4.587926e-001,0.000000e+000,,,,,,,,,,,,,,32,1,4.000000e+000,1.312256e-003,0.000000e+000,0,,0,
1524306781.671,,0.000000e+000,5.499577e+001,3.079185e-006,0.000000e+000,2,4.474870e-001,0.000000e+000,,,,,,,,,,,,,,32,1,4.000000e+000,2.632141e-003,0.000000e+000,0,,0,
1524306820.101,,0.000000e+000,5.499708e+001,3.073760e-006,0.000000e+000,2,4.603096e-001,0.000000e+000,,,,,,,,,,,,,,32,1,4.000000e+000,2.620697e-003,0.000000e+000,0,,0,
1524306858.221,,0.000000e+000,5.499840e+001,3.111556e-006,0.000000e+000,2,4.474378e-001,0.000000e+000,,,,,,,,,,,,,,32,1,4.000000e+000,2.628326e-003,0.000000e+000,0,,0,
1524306896.321,,0.000000e+000,5.500037e+001,3.029253e-006,0.000000e+000,2,4.497425e-001,0.000000e+000,,,,,,,,,,,,,,32,1,4.000000e+000,3.959656e-003,0.000000e+000,0,,0,
1524306933.911,,0.000000e+000,5.499445e+001,3.062359e-006,0.000000e+000,2,4.485756e-001,0.000000e+000,,,,,,,,,,,,,,32,1,4.000000e+000,2.628326e-003,0.000000e+000,0,,0,
1524306971.942,,0.000000e+000,5.500037e+001,3.109001e-006,0.000000e+000,2,4.740192e-001,0.000000e+000,,,,,,,,,,,,,,32,1,4.000000e+000,1.184082e-002,0.000000e+000,0,,0,
1524307009.622,,0.000000e+000,5.499445e+001,3.131949e-006,0.000000e+000,2,4.634241e-001,0.000000e+000,,,,,,,,,,,,,,32,1,4.000000e+000,5.260468e-003,0.000000e+000,0,,0,
1524307048.022,,0.000000e+000,5.500169e+001,3.077318e-006,0.000000e+000,2,4.556771e-001,0.000000e+000,,,,,,,,,,,,,,32,1,4.000000e+000,3.959656e-003,0.000000e+000,0,,0,
1524307085.602,,0.000000e+000,5.500234e+001,3.094292e-006,0.000000e+000,2,4.375283e-001,0.000000e+000,,,,,,,,,,,,,,32,1,4.000000e+000,5.260468e-003,0.000000e+000,0,,0,
1524307123.312,,0.000000e+000,5.500497e+001,3.071910e-006,0.000000e+000,2,4.586711e-001,0.000000e+000,,,,,,,,,,,,,,32,1,4.000000e+000,0.000000e+000,0.000000e+000,0,,0,
1524307162.212,,0.000000e+000,5.499775e+001,3.111953e-006,0.000000e+000,2,4.731608e-001,0.000000e+000,,,,,,,,,,,,,,32,1,4.000000e+000,1.184845e-002,0.000000e+000,0,,0,
1524307199.692,,0.000000e+000,5.499445e+001,3.112841e-006,0.000000e+000,2,4.350740e-001,0.000000e+000,,,,,,,,,,,,,,32,1,4.000000e+000,7.881165e-003,0.000000e+000,0,,0,
1524307237.662,,0.000000e+000,5.499314e+001,3.175732e-006,0.000000e+000,2,4.935599e-001,0.000000e+000,,,,,,,,,,,,,,32,1,4.000000e+000,0.000000e+000,0.000000e+000,0,,0,
1524307275.022,,0.000000e+000,5.499971e+001,3.106895e-006,0.000000e+000,2,4.291130e-001,0.000000e+000,,,,,,,,,,,,,,32,1,4.000000e+000,2.639771e-003,0.000000e+000,0,,0,
1524307312.942,,0.000000e+000,5.500037e+001,3.128536e-006,0.000000e+000,2,4.709899e-001,0.000000e+000,,,,,,,,,,,,,,32,1,4.000000e+000,1.319885e-003,0.000000e+000,0,,0,
1524307350.372,,0.000000e+000,5.499773e+001,3.137803e-006,0.000000e+000,2,4.556205e-001,0.000000e+000,,,,,,,,,,,,,,32,1,4.000000e+000,1.308441e-003,0.000000e+000,0,,0,
1524307388.222,,0.000000e+000,5.499708e+001,3.133661e-006,0.000000e+000,2,4.639685e-001,0.000000e+000,,,,,,,,,,,,,,32,1,4.000000e+000,5.260468e-003,0.000000e+000,0,,0,
1524307425.982,,0.000000e+000,5.499708e+001,3.153036e-006,0.000000e+000,2,4.472520e-001,0.000000e+000,,,,,,,,,,,,,,32,1,4.000000e+000,0.000000e+000,0.000000e+000,0,,0,
1524307463.942,,0.000000e+000,5.499511e+001,3.114669e-006,0.000000e+000,2,4.589012e-001,0.000000e+000,,,,,,,,,,,,,,32,1,4.000000e+000,3.940582e-003,0.000000e+000,0,,0,
1524307501.602,,0.000000e+000,5.499445e+001,3.113204e-006,0.000000e+000,2,4.400754e-001,0.000000e+000,,,,,,,,,,,,,,32,1,4.000000e+000,7.881165e-003,0.000000e+000,0,,0,
1524307538.972,,0.000000e+000,5.499905e+001,3.223215e-006,0.000000e+000,2,4.963952e-001,0.000000e+000,,,,,,,,,,,,,,32,1,4.000000e+000,3.948212e-003,0.000000e+000,0,,0,
1524307576.562,,0.000000e+000,5.499314e+001,3.178683e-006,0.000000e+000,2,4.697637e-001,0.000000e+000,,,,,,,,,,,,,,32,1,4.000000e+000,1.578140e-002,0.000000e+000,0,,0,
1524307614.002,,0.000000e+000,5.500234e+001,3.195200e-006,0.000000e+000,2,4.616373e-001,0.000000e+000,,,,,,,,,,,,,,32,1,4.000000e+000,5.260468e-003,0.000000e+000,0,,0,
1524307651.602,,0.000000e+000,5.499839e+001,3.149765e-006,0.000000e+000,2,4.417421e-001,0.000000e+000,,,,,,,,,,,,,,32,1,4.000000e+000,0.000000e+000,0.000000e+000,0,,0,
1524307689.033,,0.000000e+000,5.500037e+001,3.193312e-006,0.000000e+000,2,4.705073e-001,0.000000e+000,,,,,,,,,,,,,,32,1,4.000000e+000,1.319885e-003,0.000000e+000,0,,0,
1524307726.443,,0.000000e+000,5.499905e+001,3.191945e-006,0.000000e+000,2,4.587472e-001,0.000000e+000,,,,,,,,,,,,,,32,1,4.000000e+000,1.182938e-002,0.000000e+000,0,,0,
1524307764.033,,0.000000e+000,5.499774e+001,3.174912e-006,0.000000e+000,2,4.782733e-001,0.000000e+000,,,,,,,,,,,,,,32,1,4.000000e+000,3.940582e-003,0.000000e+000,0,,0,
1524307801.203,,0.000000e+000,5.499445e+001,3.209034e-006,0.000000e+000,2,4.681993e-001,0.000000e+000,,,,,,,,,,,,,,32,1,4.000000e+000,7.881165e-003,0.000000e+000,0,,0,
1524307839.173,,0.000000e+000,5.500103e+001,3.208068e-006,0.000000e+000,2,4.853748e-001,0.000000e+000,,,,,,,,,,,,,,32,1,4.000000e+000,1.052094e-002,0.000000e+000,0,,0,
1524307876.793,,0.000000e+000,5.499380e+001,3.208757e-006,0.000000e+000,2,4.620174e-001,0.000000e+000,,,,,,,,,,,,,,32,1,4.000000e+000,1.308441e-003,0.000000e+000,0,,0,
1524307914.573,,0.000000e+000,5.499577e+001,3.204171e-006,0.000000e+000,2,4.728235e-001,0.000000e+000,,,,,,,,,,,,,,32,1,4.000000e+000,5.249023e-003,0.000000e+000,0,,0,
1524307951.883,,0.000000e+000,5.499840e+001,3.224588e-006,0.000000e+000,2,4.722624e-001,0.000000e+000,,,,,,,,,,,,,,32,1,4.000000e+000,2.628326e-003,0.000000e+000,0,,0,
1524307989.843,,0.000000e+000,5.499773e+001,3.236603e-006,0.000000e+000,2,4.820189e-001,0.000000e+000,,,,,,,,,,,,,,32,1,4.000000e+000,1.308441e-003,0.000000e+000,0,,0,
1524308027.523,,0.000000e+000,5.499774e+001,3.194593e-006,0.000000e+000,2,4.559865e-001,0.000000e+000,,,,,,,,,,,,,,32,1,4.000000e+000,3.940582e-003,0.000000e+000,0,,0,
1524308065.463,,0.000000e+000,5.499774e+001,3.244357e-006,0.000000e+000,2,4.888559e-001,0.000000e+000,,,,,,,,,,,,,,32,1,4.000000e+000,3.940582e-003,0.000000e+000,0,,0,
1524308103.043,,0.000000e+000,5.500037e+001,3.237762e-006,0.000000e+000,2,4.646279e-001,0.000000e+000,,,,,,,,,,,,,,32,1,4.000000e+000,9.201050e-003,0.000000e+000,0,,0,
1524308140.913,,0.000000e+000,5.499577e+001,3.227239e-006,0.000000e+000,2,4.798814e-001,0.000000e+000,,,,,,,,,,,,,,32,1,4.000000e+000,2.632141e-003,0.000000e+000,0,,0,
1524308178.853,,0.000000e+000,5.499643e+001,3.274450e-006,0.000000e+000,2,4.923861e-001,0.000000e+000,,,,,,,,,,,,,,32,1,4.000000e+000,1.312256e-003,0.000000e+000,0,,0,
1524308216.543,,0.000000e+000,5.500629e+001,3.235897e-006,0.000000e+000,2,4.619615e-001,0.000000e+000,,,,,,,,,,,,,,32,1,4.000000e+000,1.316071e-002,0.000000e+000,0,,0,
1524308254.473,,0.000000e+000,5.500103e+001,3.245924e-006,0.000000e+000,2,4.964926e-001,0.000000e+000,,,,,,,,,,,,,,32,1,4.000000e+000,2.639771e-003,0.000000e+000,0,,0,
1524308292.073,,0.000000e+000,5.499708e+001,3.212735e-006,0.000000e+000,2,4.650032e-001,0.000000e+000,,,,,,,,,,,,,,32,1,4.000000e+000,2.620697e-003,0.000000e+000,0,,0,
1524308330.493,,0.000000e+000,5.499708e+001,3.285261e-006,0.000000e+000,2,4.780409e-001,0.000000e+000,,,,,,,,,,,,,,32,1,4.000000e+000,5.260468e-003,0.000000e+000,0,,0,
1524308368.433,,0.000000e+000,5.499511e+001,3.267657e-006,0.000000e+000,2,4.898197e-001,0.000000e+000,,,,,,,,,,,,,,32,1,4.000000e+000,1.319885e-003,0.000000e+000,0,,0,
1524308406.544,,0.000000e+000,5.499708e+001,3.217312e-006,0.000000e+000,2,4.622993e-001,0.000000e+000,,,,,,,,,,,,,,32,1,4.000000e+000,2.620697e-003,0.000000e+000,0,,0,
1524308444.074,,0.000000e+000,5.498985e+001,3.236419e-006,0.000000e+000,2,4.585027e-001,0.000000e+000,,,,,,,,,,,,,,32,1,4.000000e+000,1.184082e-002,0.000000e+000,0,,0,
1524308481.884,,0.000000e+000,5.499643e+001,3.242058e-006,0.000000e+000,2,4.945575e-001,0.000000e+000,,,,,,,,,,,,,,32,1,4.000000e+000,1.184082e-002,0.000000e+000,0,,0,
1524308519.444,,0.000000e+000,5.500301e+001,3.248750e-006,0.000000e+000,2,4.830308e-001,0.000000e+000,,,,,,,,,,,,,,32,1,4.000000e+000,1.319885e-003,0.000000e+000,0,,0,
1524308557.464,,0.000000e+000,5.500235e+001,3.264484e-006,0.000000e+000,2,4.876851e-001,0.000000e+000,,,,,,,,,,,,,,32,1,4.000000e+000,2.639771e-003,0.000000e+000,0,,0,
1524308595.054,,0.000000e+000,5.500037e+001,3.315417e-006,0.000000e+000,2,4.787040e-001,0.000000e+000,,,,,,,,,,,,,,32,1,4.000000e+000,9.201050e-003,0.000000e+000,0,,0,
1524308632.804,,0.000000e+000,5.500300e+001,3.231312e-006,0.000000e+000,2,4.849150e-001,0.000000e+000,,,,,,,,,,,,,,32,1,4.000000e+000,6.580353e-003,0.000000e+000,0,,0,
1524308669.954,,0.000000e+000,5.499445e+001,3.302863e-006,0.000000e+000,2,4.801804e-001,0.000000e+000,,,,,,,,,,,,,,32,1,4.000000e+000,7.881165e-003,0.000000e+000,0,,0,
1524308707.684,,0.000000e+000,5.500563e+001,3.252229e-006,0.000000e+000,2,4.848868e-001,0.000000e+000,,,,,,,,,,,,,,32,1,4.000000e+000,6.568909e-003,0.000000e+000,0,,0,
1524308744.834,,0.000000e+000,5.500103e+001,3.283413e-006,0.000000e+000,2,4.675688e-001,0.000000e+000,,,,,,,,,,,,,,32,1,4.000000e+000,5.279541e-003,0.000000e+000,0,,0,
1524308782.414,,0.000000e+000,5.499051e+001,3.265080e-006,0.000000e+000,2,4.824339e-001,0.000000e+000,,,,,,,,,,,,,,32,1,4.000000e+000,0.000000e+000,0.000000e+000,0,,0,
1524308820.154,,0.000000e+000,5.499511e+001,3.289001e-006,0.000000e+000,2,4.850567e-001,0.000000e+000,,,,,,,,,,,,,,32,1,4.000000e+000,3.940582e-003,0.000000e+000,0,,0,
1524308858.034,,0.000000e+000,5.499773e+001,3.250372e-006,0.000000e+000,2,4.831768e-001,0.000000e+000,,,,,,,,,,,,,,32,1,4.000000e+000,1.308441e-003,0.000000e+000,0,,0,
1524308895.764,,0.000000e+000,5.499905e+001,3.291249e-006,0.000000e+000,2,4.837387e-001,0.000000e+000,,,,,,,,,,,,,,32,1,4.000000e+000,3.948212e-003,0.000000e+000,0,,0,
1524308933.634,,0.000000e+000,5.499708e+001,3.280035e-006,0.000000e+000,2,4.927603e-001,0.000000e+000,,,,,,,,,,,,,,32,1,4.000000e+000,2.620697e-003,0.000000e+000,0,,0,
1524308971.384,,0.000000e+000,5.500431e+001,3.309182e-006,0.000000e+000,2,4.900740e-001,0.000000e+000,,,,,,,,,,,,,,32,1,4.000000e+000,9.208679e-003,0.000000e+000,0,,0,
1524309009.244,,0.000000e+000,5.500497e+001,3.184579e-006,0.000000e+000,2,4.596552e-001,0.000000e+000,,,,,,,,,,,,,,32,1,4.000000e+000,1.052856e-002,0.000000e+000,0,,0,
1524309046.984,,0.000000e+000,5.499906e+001,3.309526e-006,0.000000e+000,2,4.831331e-001,0.000000e+000,,,,,,,,,,,,,,32,1,4.000000e+000,9.220123e-003,0.000000e+000,0,,0,
1524309084.854,,0.000000e+000,5.500234e+001,3.208981e-006,0.000000e+000,2,4.802164e-001,0.000000e+000,,,,,,,,,,,,,,32,1,4.000000e+000,5.260468e-003,0.000000e+000,0,,0,
1524309122.615,,0.000000e+000,5.499971e+001,3.315079e-006,0.000000e+000,2,4.911131e-001,0.000000e+000,,,,,,,,,,,,,,32,1,4.000000e+000,0.000000e+000,0.000000e+000,0,,0,
1524309160.465,,0.000000e+000,5.498985e+001,3.268214e-006,0.000000e+000,2,4.990032e-001,0.000000e+000,,,,,,,,,,,,,,32,1,4.000000e+000,9.201050e-003,0.000000e+000,0,,0,
1524309198.205,,0.000000e+000,5.499972e+001,3.307879e-006,0.000000e+000,2,4.982890e-001,0.000000e+000,,,,,,,,,,,,,,32,1,4.000000e+000,1.314926e-002,0.000000e+000,0,,0,
1524309236.075,,0.000000e+000,5.500037e+001,3.259193e-006,0.000000e+000,2,4.942880e-001,0.000000e+000,,,,,,,,,,,,,,32,1,4.000000e+000,6.587982e-003,0.000000e+000,0,,0,
1524309273.805,,0.000000e+000,5.499248e+001,3.308022e-006,0.000000e+000,2,4.939264e-001,0.000000e+000,,,,,,,,,,,,,,32,1,4.000000e+000,6.580353e-003,0.000000e+000,0,,0,
1524309311.675,,0.000000e+000,5.500235e+001,3.268282e-006,0.000000e+000,2,4.961690e-001,0.000000e+000,,,,,,,,,,,,,,32,1,4.000000e+000,0.000000e+000,0.000000e+000,0,,0,
1524309349.425,,0.000000e+000,5.499577e+001,3.314740e-006,0.000000e+000,2,4.767332e-001,0.000000e+000,,,,,,,,,,,,,,32,1,4.000000e+000,2.632141e-003,0.000000e+000,0,,0,
1524309387.295,,0.000000e+000,5.499445e+001,3.302441e-006,0.000000e+000,2,4.974240e-001,0.000000e+000,,,,,,,,,,,,,,32,1,4.000000e+000,0.000000e+000,0.000000e+000,0,,0,
1524309425.055,,0.000000e+000,5.499709e+001,3.342049e-006,0.000000e+000,2,4.888619e-001,0.000000e+000,,,,,,,,,,,,,,32,1,4.000000e+000,7.888794e-003,0.000000e+000,0,,0,
1524309462.895,,0.000000e+000,5.500103e+001,3.267142e-006,0.000000e+000,2,4.935046e-001,0.000000e+000,,,,,,,,,,,,,,32,1,4.000000e+000,7.888794e-003,0.000000e+000,0,,0,
1524309500.635,,0.000000e+000,5.500366e+001,3.335026e-006,0.000000e+000,2,4.834545e-001,0.000000e+000,,,,,,,,,,,,,,32,1,4.000000e+000,7.900238e-003,0.000000e+000,0,,0,
1524309538.505,,0.000000e+000,5.499774e+001,3.278935e-006,0.000000e+000,2,4.958744e-001,0.000000e+000,,,,,,,,,,,,,,32,1,4.000000e+000,6.580353e-003,0.000000e+000,0,,0,
1524309576.235,,0.000000e+000,5.499839e+001,3.345888e-006,0.000000e+000,2,5.050782e-001,0.000000e+000,,,,,,,,,,,,,,32,1,4.000000e+000,0.000000e+000,0.000000e+000,0,,0,
1524309614.125,,0.000000e+000,5.499642e+001,3.254953e-006,0.000000e+000,2,4.904543e-001,0.000000e+000,,,,,,,,,,,,,,32,1,4.000000e+000,3.940582e-003,0.000000e+000,0,,0,
1524309651.465,,0.000000e+000,5.500103e+001,3.381842e-006,0.000000e+000,2,4.922770e-001,0.000000e+000,,,,,,,,,,,,,,32,1,4.000000e+000,2.639771e-003,0.000000e+000,0,,0,
1524309689.735,,0.000000e+000,5.499905e+001,3.304835e-006,0.000000e+000,2,4.984002e-001,0.000000e+000,,,,,,,,,,,,,,32,1,4.000000e+000,1.319885e-003,0.000000e+000,0,,0,
1524309727.475,,0.000000e+000,5.499051e+001,3.358705e-006,0.000000e+000,2,4.887302e-001,0.000000e+000,,,,,,,,,,,,,,32,1,4.000000e+000,1.052094e-002,0.000000e+000,0,,0,
1524309765.345,,0.000000e+000,5.500169e+001,3.343265e-006,0.000000e+000,2,5.040483e-001,0.000000e+000,,,,,,,,,,,,,,32,1,4.000000e+000,1.319885e-003,0.000000e+000,0,,0,
1524309803.245,,0.000000e+000,5.500037e+001,3.339511e-006,0.000000e+000,2,4.766399e-001,0.000000e+000,,,,,,,,,,,,,,32,1,4.000000e+000,1.319885e-003,0.000000e+000,0,,0,
1524309841.206,,0.000000e+000,5.499839e+001,3.361826e-006,0.000000e+000,2,5.028945e-001,0.000000e+000,,,,,,,,,,,,,,32,1,4.000000e+000,0.000000e+000,0.000000e+000,0,,0,
1524309879.016,,0.000000e+000,5.499445e+001,3.315937e-006,0.000000e+000,2,4.700543e-001,0.000000e+000,,,,,,,,,,,,,,32,1,4.000000e+000,2.628326e-003,0.000000e+000,0,,0,
1524309916.246,,0.000000e+000,5.499642e+001,3.286064e-006,0.000000e+000,2,4.905362e-001,0.000000e+000,,,,,,,,,,,,,,32,1,4.000000e+000,3.940582e-003,0.000000e+000,0,,0,
1524309954.156,,0.000000e+000,5.500169e+001,3.300097e-006,0.000000e+000,2,4.715117e-001,0.000000e+000,,,,,,,,,,,,,,32,1,4.000000e+000,1.319885e-003,0.000000e+000,0,,0,
1524309991.466,,0.000000e+000,5.499708e+001,3.322692e-006,0.000000e+000,2,5.096989e-001,0.000000e+000,,,,,,,,,,,,,,32,1,4.000000e+000,2.620697e-003,0.000000e+000,0,,0,
1524310028.646,,0.000000e+000,5.499972e+001,3.370876e-006,0.000000e+000,2,4.739831e-001,0.000000e+000,,,,,,,,,,,,,,32,1,4.000000e+000,5.268097e-003,0.000000e+000,0,,0,
1524310066.816,,0.000000e+000,5.499839e+001,3.353195e-006,0.000000e+000,2,4.996517e-001,0.000000e+000,,,,,,,,,,,,,,32,1,4.000000e+000,0.000000e+000,0.000000e+000,0,,0,
1524310104.496,,0.000000e+000,5.499643e+001,3.326146e-006,0.000000e+000,2,4.985355e-001,0.000000e+000,,,,,,,,,,,,,,32,1,4.000000e+000,1.312256e-003,0.000000e+000,0,,0,
1524310142.226,,0.000000e+000,5.500235e+001,3.375348e-006,0.000000e+000,2,4.984127e-001,0.000000e+000,,,,,,,,,,,,,,32,1,4.000000e+000,2.639771e-003,0.000000e+000,0,,0,
1524310180.106,,0.000000e+000,5.499905e+001,3.336484e-006,0.000000e+000,2,5.034072e-001,0.000000e+000,,,,,,,,,,,,,,32,1,4.000000e+000,1.319885e-003,0.000000e+000,0,,0,
1524310217.856,,0.000000e+000,5.499577e+001,3.366643e-006,0.000000e+000,2,4.947622e-001,0.000000e+000,,,,,,,,,,,,,,32,1,4.000000e+000,7.888794e-003,0.000000e+000,0,,0,
1524310255.716,,0.000000e+000,5.499839e+001,3.300123e-006,0.000000e+000,2,4.944400e-001,0.000000e+000,,,,,,,,,,,,,,32,1,4.000000e+000,0.000000e+000,0.000000e+000,0,,0,
1524310293.496,,0.000000e+000,5.499840e+001,3.361672e-006,0.000000e+000,2,4.984328e-001,0.000000e+000,,,,,,,,,,,,,,32,1,4.000000e+000,5.260468e-003,0.000000e+000,0,,0,
1524310331.346,,0.000000e+000,5.499905e+001,3.367536e-006,0.000000e+000,2,5.110011e-001,0.000000e+000,,,,,,,,,,,,,,32,1,4.000000e+000,1.319885e-003,0.000000e+000,0,,0,
1524310369.086,,0.000000e+000,5.500169e+001,3.391529e-006,0.000000e+000,2,5.009263e-001,0.000000e+000,,,,,,,,,,,,,,32,1,4.000000e+000,3.959656e-003,0.000000e+000,0,,0,
1524310406.956,,0.000000e+000,5.499840e+001,3.366564e-006,0.000000e+000,2,5.046349e-001,0.000000e+000,,,,,,,,,,,,,,32,1,4.000000e+000,2.628326e-003,0.000000e+000,0,,0,
1524310444.706,,0.000000e+000,5.500235e+001,3.375984e-006,0.000000e+000,2,4.982892e-001,0.000000e+000,,,,,,,,,,,,,,32,1,4.000000e+000,2.639771e-003,0.000000e+000,0,,0,
1524310482.576,,0.000000e+000,5.499445e+001,3.308262e-006,0.000000e+000,2,5.000678e-001,0.000000e+000,,,,,,,,,,,,,,32,1,4.000000e+000,0.000000e+000,0.000000e+000,0,,0,
1524310520.016,,0.000000e+000,5.499906e+001,3.416267e-006,0.000000e+000,2,5.127596e-001,0.000000e+000,,,,,,,,,,,,,,32,1,4.000000e+000,9.220123e-003,0.000000e+000,0,,0,
1524310558.197,,0.000000e+000,5.499905e+001,3.336366e-006,0.000000e+000,2,5.053238e-001,0.000000e+000,,,,,,,,,,,,,,32,1,4.000000e+000,3.948212e-003,0.000000e+000,0,,0,
1524310595.927,,0.000000e+000,5.499577e+001,3.400159e-006,0.000000e+000,2,4.987068e-001,0.000000e+000,,,,,,,,,,,,,,32,1,4.000000e+000,5.249023e-003,0.000000e+000,0,,0,
1524310633.807,,0.000000e+000,5.500037e+001,3.337833e-006,0.000000e+000,2,5.012693e-001,0.000000e+000,,,,,,,,,,,,,,32,1,4.000000e+000,1.319885e-003,0.000000e+000,0,,0,
1524310671.527,,0.000000e+000,5.499577e+001,3.378084e-006,0.000000e+000,2,4.982864e-001,0.000000e+000,,,,,,,,,,,,,,32,1,4.000000e+000,2.632141e-003,0.000000e+000,0,,0,
1524310709.417,,0.000000e+000,5.499839e+001,3.362368e-006,0.000000e+000,2,5.057235e-001,0.000000e+000,,,,,,,,,,,,,,32,1,4.000000e+000,0.000000e+000,0.000000e+000,0,,0,
1524310747.157,,0.000000e+000,5.499643e+001,3.360485e-006,0.000000e+000,2,4.977085e-001,0.000000e+000,,,,,,,,,,,,,,32,1,4.000000e+000,1.312256e-003,0.000000e+000,0,,0,
1524310785.047,,0.000000e+000,5.500169e+001,3.385576e-006,0.000000e+000,2,5.101386e-001,0.000000e+000,,,,,,,,,,,,,,32,1,4.000000e+000,9.208679e-003,0.000000e+000,0,,0,
1524310822.757,,0.000000e+000,5.499905e+001,3.367777e-006,0.000000e+000,2,4.880911e-001,0.000000e+000,,,,,,,,,,,,,,32,1,4.000000e+000,1.319885e-003,0.000000e+000,0,,0,
1524310860.417,,0.000000e+000,5.499971e+001,3.302974e-006,0.000000e+000,2,4.954017e-001,0.000000e+000,,,,,,,,,,,,,,32,1,4.000000e+000,0.000000e+000,0.000000e+000,0,,0,
1524310897.737,,0.000000e+000,5.499971e+001,3.389922e-006,0.000000e+000,2,4.982277e-001,0.000000e+000,,,,,,,,,,,,,,32,1,4.000000e+000,2.639771e-003,0.000000e+000,0,,0,
1524310935.557,,0.000000e+000,5.499840e+001,3.316145e-006,0.000000e+000,2,4.762847e-001,0.000000e+000,,,,,,,,,,,,,,32,1,4.000000e+000,2.628326e-003,0.000000e+000,0,,0,
1524310973.337,,0.000000e+000,5.499643e+001,3.380777e-006,0.000000e+000,2,5.067139e-001,0.000000e+000,,,,,,,,,,,,,,32,1,4.000000e+000,1.312256e-003,0.000000e+000,0,,0,
1524311011.367,,0.000000e+000,5.500366e+001,3.321602e-006,0.000000e+000,2,4.761508e-001,0.000000e+000,,,,,,,,,,,,,,32,1,4.000000e+000,2.620697e-003,0.000000e+000,0,,0,
1524311048.957,,0.000000e+000,5.499708e+001,3.386906e-006,0.000000e+000,2,4.969333e-001,0.000000e+000,,,,,,,,,,,,,,32,1,4.000000e+000,2.620697e-003,0.000000e+000,0,,0,
1524311087.257,,0.000000e+000,5.499248e+001,3.394134e-006,0.000000e+000,2,5.152066e-001,0.000000e+000,,,,,,,,,,,,,,32,1,4.000000e+000,1.319885e-003,0.000000e+000,0,,0,
1524311125.377,,0.000000e+000,5.499840e+001,3.357597e-006,0.000000e+000,2,4.821432e-001,0.000000e+000,,,,,,,,,,,,,,32,1,4.000000e+000,2.628326e-003,0.000000e+000,0,,0,
1524311163.177,,0.000000e+000,5.499643e+001,3.414477e-006,0.000000e+000,2,5.101390e-001,0.000000e+000,,,,,,,,,,,,,,32,1,4.000000e+000,1.312256e-003,0.000000e+000,0,,0,
1524311200.967,,0.000000e+000,5.499643e+001,3.392160e-006,0.000000e+000,2,5.253482e-001,0.000000e+000,,,,,,,,,,,,,,32,1,4.000000e+000,1.312256e-003,0.000000e+000,0,,0,
1524311238.517,,0.000000e+000,5.499511e+001,3.371463e-006,0.000000e+000,2,4.722030e-001,0.000000e+000,,,,,,,,,,,,,,32,1,4.000000e+000,6.568909e-003,0.000000e+000,0,,0,
1524311276.448,,0.000000e+000,5.499577e+001,3.465475e-006,0.000000e+000,2,5.061781e-001,0.000000e+000,,,,,,,,,,,,,,32,1,4.000000e+000,7.888794e-003,0.000000e+000,0,,0,
1524311314.648,,0.000000e+000,5.499840e+001,3.404791e-006,0.000000e+000,2,5.144147e-001,0.000000e+000,,,,,,,,,,,,,,32,1,4.000000e+000,7.900238e-003,0.000000e+000,0,,0,
1524311351.958,,0.000000e+000,5.500037e+001,3.393069e-006,0.000000e+000,2,4.842629e-001,0.000000e+000,,,,,,,,,,,,,,32,1,4.000000e+000,1.319885e-003,0.000000e+000,0,,0,
1524311390.008,,0.000000e+000,5.499708e+001,3.473370e-006,0.000000e+000,2,4.983563e-001,0.000000e+000,,,,,,,,,,,,,,32,1,4.000000e+000,0.000000e+000,0.000000e+000,0,,0,
1524311428.268,,0.000000e+000,5.500037e+001,3.428368e-006,0.000000e+000,2,5.090987e-001,0.000000e+000,,,,,,,,,,,,,,32,1,4.000000e+000,1.319885e-003,0.000000e+000,0,,0,
1524311465.618,,0.000000e+000,5.500301e+001,3.434807e-006,0.000000e+000,2,4.970568e-001,0.000000e+000,,,,,,,,,,,,,,32,1,4.000000e+000,1.446915e-002,0.000000e+000,0,,0,
1524311503.078,,0.000000e+000,5.500037e+001,3.492525e-006,0.000000e+000,2,5.262635e-001,0.000000e+000,,,,,,,,,,,,,,32,1,4.000000e+000,3.959656e-003,0.000000e+000,0,,0,
1524311540.898,,0.000000e+000,5.499380e+001,3.403773e-006,0.000000e+000,2,4.859695e-001,0.000000e+000,,,,,,,,,,,,,,32,1,4.000000e+000,6.572723e-003,0.000000e+000,0,,0,
1524311578.588,,0.000000e+000,5.500037e+001,3.438775e-006,0.000000e+000,2,5.151608e-001,0.000000e+000,,,,,,,,,,,,,,32,1,4.000000e+000,3.959656e-003,0.000000e+000,0,,0,
1524311617.678,,0.000000e+000,5.500103e+001,3.390525e-006,0.000000e+000,2,5.117571e-001,0.000000e+000,,,,,,,,,,,,,,32,1,4.000000e+000,1.316071e-002,0.000000e+000,0,,0,
1524311655.428,,0.000000e+000,5.499972e+001,3.357407e-006,0.000000e+000,2,4.776476e-001,0.000000e+000,,,,,,,,,,,,,,32,1,4.000000e+000,7.900238e-003,0.000000e+000,0,,0,
1524311693.228,,0.000000e+000,5.500103e+001,3.478458e-006,0.000000e+000,2,5.230677e-001,0.000000e+000,,,,,,,,,,,,,,32,1,4.000000e+000,2.639771e-003,0.000000e+000,0,,0,
1524311731.048,,0.000000e+000,5.499774e+001,3.379879e-006,0.000000e+000,2,4.903560e-001,0.000000e+000,,,,,,,,,,,,,,32,1,4.000000e+000,6.580353e-003,0.000000e+000,0,,0,
1524311769.208,,0.000000e+000,5.499577e+001,3.420705e-006,0.000000e+000,2,4.922222e-001,0.000000e+000,,,,,,,,,,,,,,32,1,4.000000e+000,5.249023e-003,0.000000e+000,0,,0,
1524311807.078,,0.000000e+000,5.500366e+001,3.496111e-006,0.000000e+000,2,5.157753e-001,0.000000e+000,,,,,,,,,,,,,,32,1,4.000000e+000,7.900238e-003,0.000000e+000,0,,0,
1524311844.738,,0.000000e+000,5.499774e+001,3.438951e-006,0.000000e+000,2,4.894043e-001,0.000000e+000,,,,,,,,,,,,,,32,1,4.000000e+000,3.940582e-003,0.000000e+000,0,,0,
1524311882.708,,0.000000e+000,5.499971e+001,3.439759e-006,0.000000e+000,2,5.082502e-001,0.000000e+000,,,,,,,,,,,,,,32,1,4.000000e+000,2.639771e-003,0.000000e+000,0,,0,
1524311920.348,,0.000000e+000,5.500103e+001,3.442824e-006,0.000000e+000,2,4.899867e-001,0.000000e+000,,,,,,,,,,,,,,32,1,4.000000e+000,7.888794e-003,0.000000e+000,0,,0,
1524311958.318,,0.000000e+000,5.499905e+001,3.435286e-006,0.000000e+000,2,5.084538e-001,0.000000e+000,,,,,,,,,,,,,,32,1,4.000000e+000,1.319885e-003,0.000000e+000,0,,0,
1524311995.669,,0.000000e+000,5.499906e+001,3.468823e-006,0.000000e+000,2,5.040193e-001,0.000000e+000,,,,,,,,,,,,,,32,1,4.000000e+000,6.580353e-003,0.000000e+000,0,,0,
1524312033.259,,0.000000e+000,5.499577e+001,3.460065e-006,0.000000e+000,2,5.041294e-001,0.000000e+000,,,,,,,,,,,,,,32,1,4.000000e+000,0.000000e+000,0.000000e+000,0,,0,
1524312071.909,,0.000000e+000,5.500235e+001,3.439277e-006,0.000000e+000,2,5.120255e-001,0.000000e+000,,,,,,,,,,,,,,32,1,4.000000e+000,2.639771e-003,0.000000e+000,0,,0,
1524312110.349,,0.000000e+000,5.498853e+001,3.399265e-006,0.000000e+000,2,4.782980e-001,0.000000e+000,,,,,,,,,,,,,,32,1,4.000000e+000,1.710129e-002,0.000000e+000,0,,0,
1524312147.699,,0.000000e+000,5.500037e+001,3.472861e-006,0.000000e+000,2,5.095073e-001,0.000000e+000,,,,,,,,,,,,,,32,1,4.000000e+000,6.587982e-003,0.000000e+000,0,,0,
1524312185.579,,0.000000e+000,5.499577e+001,3.405137e-006,0.000000e+000,2,4.831989e-001,0.000000e+000,,,,,,,,,,,,,,32,1,4.000000e+000,5.249023e-003,0.000000e+000,0,,0,
1524312221.909,,0.000000e+000,5.499708e+001,3.417915e-006,0.000000e+000,2,4.986954e-001,0.000000e+000,,,,,,,,,,,,,,32,1,4.000000e+000,5.260468e-003,0.000000e+000,0,,0,
1524312259.729,,0.000000e+000,5.499971e+001,3.378764e-006,0.000000e+000,2,5.131614e-001,0.000000e+000,,,,,,,,,,,,,,32,1,4.000000e+000,2.639771e-003,0.000000e+000,0,,0,
1524312296.729,,0.000000e+000,5.499774e+001,3.450925e-006,0.000000e+000,2,5.033796e-001,0.000000e+000,,,,,,,,,,,,,,32,1,4.000000e+000,6.580353e-003,0.000000e+000,0,,0,
1524312334.699,,0.000000e+000,5.499709e+001,3.414349e-006,0.000000e+000,2,5.045502e-001,0.000000e+000,,,,,,,,,,,,,,32,1,4.000000e+000,7.888794e-003,0.000000e+000,0,,0,
1524312372.259,,0.000000e+000,5.499577e+001,3.459428e-006,0.000000e+000,2,5.163949e-001,0.000000e+000,,,,,,,,,,,,,,32,1,4.000000e+000,5.249023e-003,0.000000e+000,0,,0,
1524312410.409,,0.000000e+000,5.500103e+001,3.474272e-006,0.000000e+000,2,5.104033e-001,0.000000e+000,,,,,,,,,,,,,,32,1,4.000000e+000,5.279541e-003,0.000000e+000,0,,0,
1524312448.069,,0.000000e+000,5.500168e+001,3.472719e-006,0.000000e+000,2,4.944127e-001,0.000000e+000,,,,,,,,,,,,,,32,1,4.000000e+000,6.580353e-003,0.000000e+000,0,,0,
1524312485.939,,0.000000e+000,5.499972e+001,3.417528e-006,0.000000e+000,2,5.117562e-001,0.000000e+000,,,,,,,,,,,,,,32,1,4.000000e+000,7.900238e-003,0.000000e+000,0,,0,
1524312498.329,,0.000000e+000,5.500037e+001,3.402418e-006,0.000000e+000,2,4.895602e-001,0.000000e+000,,,,,,,,,,,,,,32,1,4.000000e+000,9.201050e-003,0.000000e+000,0,,0,