File: Experimental Raw Data/TC04-12-01K VRMac VRMde/TC04-12-01K_VRMac_56K_3000s.dc.dat
[Header]
TITLE,MPMS DC Measurement
BYAPP,MPMS Measurement,2.1,Summary
FILEOPENTIME, 1524279112.863000 4/20/2018, 8:51:52 PM

INFO, APPNAME, MPMS MultiVu Application, Revision 1.61,  Build 082

INFO, NAME, TC04-12-01K
INFO, WEIGHT, 1.000
INFO, AREA, 1.000
INFO, LENGTH, 1.000
INFO, SHAPE, 0
INFO, COMMENT,
INFO, SEQUENCE FILE: VRMac_56K_3000s_VRMde_55K.seq


INFO, BACKGROUND DATA FILE:, None


STARTUPAXIS,X,4,LINEAR,AUTO,0.000000,0.000000
STARTUPAXIS,Y1,5,LINEAR,AUTO,0.000000,0.000000


STARTUPGROUP,Longitudinal
FIELDGROUP,Longitudinal,1,2,3,4,5,6,7,8,9,15,16,17,18,27,28
FIELDGROUP,Transverse,1,2,3,4,10,11,12,13,14,19,20,21,22,27,28

PLOT_APPEARANCE,ALL,HORZ_GRID_ON,VERT_GRID_ON,MARKERS_AND_LINES

[Data]
Time,Comment,Field (Oe),Temperature (K),Long Moment (emu),Long Scan Std Dev,Long Algorithm,Long Reg Fit,Long Percent Error (%),Trans Moment (emu),Trans Scan Std Dev,Trans Algorithm,Trans Reg Fit,Trans Percent Error (%),Long Moment [w/o ABS] (emu),Long Scan Std Dev [w/o ABS],Long Reg Fit [w/o ABS],Long Percent Error [w/o ABS] (%),Trans Moment [w/o ABS] (emu),Trans Scan Std Dev [w/o ABS],Trans Reg Fit [w/o ABS],Trans Percent Error [w/o ABS] (%),Points per Scan,Scans per Measurement,Scan Length (cm),Delta Temp (K),Rot Position (deg),Error,EC Comp. Running,Using ABS,
1524279112.863,,0.000000e+000,5.605338e+001,-4.929999e-005,0.000000e+000,2,6.520866e-001,0.000000e+000,,,,,,,,,,,,,,32,1,4.000000e+000,2.313995e-002,0.000000e+000,0,,0,
1524279125.873,,0.000000e+000,5.604113e+001,-5.181283e-005,0.000000e+000,2,6.550028e-001,0.000000e+000,,,,,,,,,,,,,,32,1,4.000000e+000,1.358032e-003,0.000000e+000,0,,0,
1524279138.913,,0.000000e+000,5.603909e+001,-5.325459e-005,0.000000e+000,2,6.561354e-001,0.000000e+000,,,,,,,,,,,,,,32,1,4.000000e+000,2.719879e-003,0.000000e+000,0,,0,
1524279151.453,,0.000000e+000,5.602889e+001,-5.434400e-005,0.000000e+000,2,6.580434e-001,0.000000e+000,,,,,,,,,,,,,,32,1,4.000000e+000,1.768112e-002,0.000000e+000,0,,0,
1524279164.113,,0.000000e+000,5.602005e+001,-5.517099e-005,0.000000e+000,2,6.565148e-001,0.000000e+000,,,,,,,,,,,,,,32,1,4.000000e+000,0.000000e+000,0.000000e+000,0,,0,
1524279176.563,,0.000000e+000,5.601869e+001,-5.581679e-005,0.000000e+000,2,6.595482e-001,0.000000e+000,,,,,,,,,,,,,,32,1,4.000000e+000,2.719879e-003,0.000000e+000,0,,0,
1524279189.553,,0.000000e+000,5.601394e+001,-5.639481e-005,0.000000e+000,2,6.587816e-001,0.000000e+000,,,,,,,,,,,,,,32,1,4.000000e+000,1.361847e-003,0.000000e+000,0,,0,
1524279201.713,,0.000000e+000,5.600851e+001,-5.682991e-005,0.000000e+000,2,6.595579e-001,0.000000e+000,,,,,,,,,,,,,,32,1,4.000000e+000,9.510040e-003,0.000000e+000,0,,0,
1524279214.323,,0.000000e+000,5.600307e+001,-5.734510e-005,0.000000e+000,2,6.605445e-001,0.000000e+000,,,,,,,,,,,,,,32,1,4.000000e+000,1.369476e-003,0.000000e+000,0,,0,
1524279226.593,,0.000000e+000,5.600442e+001,-5.762984e-005,0.000000e+000,2,6.601610e-001,0.000000e+000,,,,,,,,,,,,,,32,1,4.000000e+000,4.077911e-003,0.000000e+000,0,,0,
1524279239.703,,0.000000e+000,5.599899e+001,-5.805152e-005,0.000000e+000,2,6.598780e-001,0.000000e+000,,,,,,,,,,,,,,32,1,4.000000e+000,1.493835e-002,0.000000e+000,0,,0,
1524279252.303,,0.000000e+000,5.599423e+001,-5.831539e-005,0.000000e+000,2,6.591507e-001,0.000000e+000,,,,,,,,,,,,,,32,1,4.000000e+000,5.428314e-003,0.000000e+000,0,,0,
1524279264.993,,0.000000e+000,5.600102e+001,-5.865607e-005,0.000000e+000,2,6.610634e-001,0.000000e+000,,,,,,,,,,,,,,32,1,4.000000e+000,2.712250e-003,0.000000e+000,0,,0,
1524279277.463,,0.000000e+000,5.599966e+001,-5.893166e-005,0.000000e+000,2,6.600364e-001,0.000000e+000,,,,,,,,,,,,,,32,1,4.000000e+000,5.432129e-003,0.000000e+000,0,,0,
1524279290.693,,0.000000e+000,5.600442e+001,-5.920073e-005,0.000000e+000,2,6.617269e-001,0.000000e+000,,,,,,,,,,,,,,32,1,4.000000e+000,4.077911e-003,0.000000e+000,0,,0,
1524279303.273,,0.000000e+000,5.599560e+001,-5.944218e-005,0.000000e+000,2,6.607036e-001,0.000000e+000,,,,,,,,,,,,,,32,1,4.000000e+000,5.428314e-003,0.000000e+000,0,,0,
1524279315.773,,0.000000e+000,5.600034e+001,-5.971689e-005,0.000000e+000,2,6.630213e-001,0.000000e+000,,,,,,,,,,,,,,32,1,4.000000e+000,4.070282e-003,0.000000e+000,0,,0,
1524279328.443,,0.000000e+000,5.600510e+001,-5.982052e-005,0.000000e+000,2,6.608994e-001,0.000000e+000,,,,,,,,,,,,,,32,1,4.000000e+000,5.439758e-003,0.000000e+000,0,,0,
1524279341.043,,0.000000e+000,5.599831e+001,-6.009876e-005,0.000000e+000,2,6.638641e-001,0.000000e+000,,,,,,,,,,,,,,32,1,4.000000e+000,2.719879e-003,0.000000e+000,0,,0,
1524279353.593,,0.000000e+000,5.599831e+001,-6.022358e-005,0.000000e+000,2,6.615836e-001,0.000000e+000,,,,,,,,,,,,,,32,1,4.000000e+000,2.719879e-003,0.000000e+000,0,,0,
1524279366.303,,0.000000e+000,5.599423e+001,-6.049165e-005,0.000000e+000,2,6.635107e-001,0.000000e+000,,,,,,,,,,,,,,32,1,4.000000e+000,1.086807e-002,0.000000e+000,0,,0,
1524279379.013,,0.000000e+000,5.599492e+001,-6.060916e-005,0.000000e+000,2,6.628047e-001,0.000000e+000,,,,,,,,,,,,,,32,1,4.000000e+000,1.222992e-002,0.000000e+000,0,,0,
1524279391.953,,0.000000e+000,5.599831e+001,-6.079306e-005,0.000000e+000,2,6.636051e-001,0.000000e+000,,,,,,,,,,,,,,32,1,4.000000e+000,8.140564e-003,0.000000e+000,0,,0,
1524279404.093,,0.000000e+000,5.599831e+001,-6.088773e-005,0.000000e+000,2,6.632853e-001,0.000000e+000,,,,,,,,,,,,,,32,1,4.000000e+000,2.719879e-003,0.000000e+000,0,,0,
1524279416.673,,0.000000e+000,5.599899e+001,-6.100845e-005,0.000000e+000,2,6.642957e-001,0.000000e+000,,,,,,,,,,,,,,32,1,4.000000e+000,1.358032e-003,0.000000e+000,0,,0,
1524279429.143,,0.000000e+000,5.599831e+001,-6.121649e-005,0.000000e+000,2,6.631102e-001,0.000000e+000,,,,,,,,,,,,,,32,1,4.000000e+000,0.000000e+000,0.000000e+000,0,,0,
1524279441.783,,0.000000e+000,5.599695e+001,-6.137523e-005,0.000000e+000,2,6.642934e-001,0.000000e+000,,,,,,,,,,,,,,32,1,4.000000e+000,2.719879e-003,0.000000e+000,0,,0,
1524279454.233,,0.000000e+000,5.599627e+001,-6.159147e-005,0.000000e+000,2,6.640801e-001,0.000000e+000,,,,,,,,,,,,,,32,1,4.000000e+000,1.358032e-003,0.000000e+000,0,,0,
1524279466.603,,0.000000e+000,5.599628e+001,-6.158889e-005,0.000000e+000,2,6.629969e-001,0.000000e+000,,,,,,,,,,,,,,32,1,4.000000e+000,4.070282e-003,0.000000e+000,0,,0,
1524279479.023,,0.000000e+000,5.599967e+001,-6.177946e-005,0.000000e+000,2,6.626403e-001,0.000000e+000,,,,,,,,,,,,,,32,1,4.000000e+000,2.719879e-003,0.000000e+000,0,,0,
1524279491.283,,0.000000e+000,5.600171e+001,-6.185722e-005,0.000000e+000,2,6.643113e-001,0.000000e+000,,,,,,,,,,,,,,32,1,4.000000e+000,1.493835e-002,0.000000e+000,0,,0,
1524279503.563,,0.000000e+000,5.599831e+001,-6.203439e-005,0.000000e+000,2,6.636651e-001,0.000000e+000,,,,,,,,,,,,,,32,1,4.000000e+000,1.086807e-002,0.000000e+000,0,,0,
1524279516.543,,0.000000e+000,5.600103e+001,-6.208142e-005,0.000000e+000,2,6.642334e-001,0.000000e+000,,,,,,,,,,,,,,32,1,4.000000e+000,5.439758e-003,0.000000e+000,0,,0,
1524279528.863,,0.000000e+000,5.600034e+001,-6.230990e-005,0.000000e+000,2,6.650107e-001,0.000000e+000,,,,,,,,,,,,,,32,1,4.000000e+000,4.070282e-003,0.000000e+000,0,,0,
1524279541.593,,0.000000e+000,5.599423e+001,-6.229561e-005,0.000000e+000,2,6.638962e-001,0.000000e+000,,,,,,,,,,,,,,32,1,4.000000e+000,1.086807e-002,0.000000e+000,0,,0,
1524279554.043,,0.000000e+000,5.599899e+001,-6.245810e-005,0.000000e+000,2,6.655036e-001,0.000000e+000,,,,,,,,,,,,,,32,1,4.000000e+000,1.358032e-003,0.000000e+000,0,,0,
1524279566.613,,0.000000e+000,5.599559e+001,-6.249910e-005,0.000000e+000,2,6.637204e-001,0.000000e+000,,,,,,,,,,,,,,32,1,4.000000e+000,0.000000e+000,0.000000e+000,0,,0,
1524279579.103,,0.000000e+000,5.599627e+001,-6.267968e-005,0.000000e+000,2,6.657526e-001,0.000000e+000,,,,,,,,,,,,,,32,1,4.000000e+000,1.358032e-003,0.000000e+000,0,,0,
1524279591.513,,0.000000e+000,5.599967e+001,-6.273515e-005,0.000000e+000,2,6.644501e-001,0.000000e+000,,,,,,,,,,,,,,32,1,4.000000e+000,8.159637e-003,0.000000e+000,0,,0,
1524279604.353,,0.000000e+000,5.600103e+001,-6.279341e-005,0.000000e+000,2,6.648809e-001,0.000000e+000,,,,,,,,,,,,,,32,1,4.000000e+000,5.439758e-003,0.000000e+000,0,,0,
1524279617.163,,0.000000e+000,5.599967e+001,-6.294956e-005,0.000000e+000,2,6.657315e-001,0.000000e+000,,,,,,,,,,,,,,32,1,4.000000e+000,2.719879e-003,0.000000e+000,0,,0,
1524279629.833,,0.000000e+000,5.599220e+001,-6.298262e-005,0.000000e+000,2,6.648467e-001,0.000000e+000,,,,,,,,,,,,,,32,1,4.000000e+000,4.077911e-003,0.000000e+000,0,,0,
1524279642.613,,0.000000e+000,5.599763e+001,-6.308986e-005,0.000000e+000,2,6.662764e-001,0.000000e+000,,,,,,,,,,,,,,32,1,4.000000e+000,1.361847e-003,0.000000e+000,0,,0,
1524279654.753,,0.000000e+000,5.599423e+001,-6.315910e-005,0.000000e+000,2,6.643714e-001,0.000000e+000,,,,,,,,,,,,,,32,1,4.000000e+000,5.428314e-003,0.000000e+000,0,,0,
1524279667.613,,0.000000e+000,5.599763e+001,-6.322563e-005,0.000000e+000,2,6.651413e-001,0.000000e+000,,,,,,,,,,,,,,32,1,4.000000e+000,4.077911e-003,0.000000e+000,0,,0,
1524279679.913,,0.000000e+000,5.599899e+001,-6.333566e-005,0.000000e+000,2,6.655627e-001,0.000000e+000,,,,,,,,,,,,,,32,1,4.000000e+000,4.081726e-003,0.000000e+000,0,,0,
1524279692.443,,0.000000e+000,5.600035e+001,-6.350760e-005,0.000000e+000,2,6.664867e-001,0.000000e+000,,,,,,,,,,,,,,32,1,4.000000e+000,1.361847e-003,0.000000e+000,0,,0,
1524279704.923,,0.000000e+000,5.599899e+001,-6.347143e-005,0.000000e+000,2,6.656194e-001,0.000000e+000,,,,,,,,,,,,,,32,1,4.000000e+000,1.358032e-003,0.000000e+000,0,,0,
1524279718.123,,0.000000e+000,5.599831e+001,-6.361582e-005,0.000000e+000,2,6.667667e-001,0.000000e+000,,,,,,,,,,,,,,32,1,4.000000e+000,0.000000e+000,0.000000e+000,0,,0,
1524279730.563,,0.000000e+000,5.600238e+001,-6.365630e-005,0.000000e+000,2,6.666207e-001,0.000000e+000,,,,,,,,,,,,,,32,1,4.000000e+000,0.000000e+000,0.000000e+000,0,,0,
1524279743.173,,0.000000e+000,5.600034e+001,-6.381737e-005,0.000000e+000,2,6.668242e-001,0.000000e+000,,,,,,,,,,,,,,32,1,4.000000e+000,4.070282e-003,0.000000e+000,0,,0,
1524279756.413,,0.000000e+000,5.600034e+001,-6.381245e-005,0.000000e+000,2,6.665815e-001,0.000000e+000,,,,,,,,,,,,,,32,1,4.000000e+000,4.070282e-003,0.000000e+000,0,,0,
1524279769.023,,0.000000e+000,5.599627e+001,-6.391175e-005,0.000000e+000,2,6.668512e-001,0.000000e+000,,,,,,,,,,,,,,32,1,4.000000e+000,1.358032e-003,0.000000e+000,0,,0,
1524279781.333,,0.000000e+000,5.599627e+001,-6.393147e-005,0.000000e+000,2,6.662763e-001,0.000000e+000,,,,,,,,,,,,,,32,1,4.000000e+000,1.358032e-003,0.000000e+000,0,,0,
1524279793.883,,0.000000e+000,5.599831e+001,-6.405748e-005,0.000000e+000,2,6.685579e-001,0.000000e+000,,,,,,,,,,,,,,32,1,4.000000e+000,5.439758e-003,0.000000e+000,0,,0,
1524279806.353,,0.000000e+000,5.599559e+001,-6.411943e-005,0.000000e+000,2,6.670685e-001,0.000000e+000,,,,,,,,,,,,,,32,1,4.000000e+000,2.708435e-003,0.000000e+000,0,,0,
1524279819.523,,0.000000e+000,5.599627e+001,-6.419073e-005,0.000000e+000,2,6.676788e-001,0.000000e+000,,,,,,,,,,,,,,32,1,4.000000e+000,1.358032e-003,0.000000e+000,0,,0,
1524279831.954,,0.000000e+000,5.599899e+001,-6.421425e-005,0.000000e+000,2,6.677429e-001,0.000000e+000,,,,,,,,,,,,,,32,1,4.000000e+000,6.790161e-003,0.000000e+000,0,,0,
1524279844.354,,0.000000e+000,5.599627e+001,-6.434066e-005,0.000000e+000,2,6.690359e-001,0.000000e+000,,,,,,,,,,,,,,32,1,4.000000e+000,1.358032e-003,0.000000e+000,0,,0,
1524279857.404,,0.000000e+000,5.599695e+001,-6.434353e-005,0.000000e+000,2,6.671857e-001,0.000000e+000,,,,,,,,,,,,,,32,1,4.000000e+000,0.000000e+000,0.000000e+000,0,,0,
1524279869.964,,0.000000e+000,5.599627e+001,-6.446001e-005,0.000000e+000,2,6.671582e-001,0.000000e+000,,,,,,,,,,,,,,32,1,4.000000e+000,1.358032e-003,0.000000e+000,0,,0,
1524279882.614,,0.000000e+000,5.599967e+001,-6.453977e-005,0.000000e+000,2,6.678239e-001,0.000000e+000,,,,,,,,,,,,,,32,1,4.000000e+000,8.159637e-003,0.000000e+000,0,,0,
1524279894.964,,0.000000e+000,5.600035e+001,-6.453609e-005,0.000000e+000,2,6.681548e-001,0.000000e+000,,,,,,,,,,,,,,32,1,4.000000e+000,6.801605e-003,0.000000e+000,0,,0,
1524279907.424,,0.000000e+000,5.599831e+001,-6.459213e-005,0.000000e+000,2,6.678563e-001,0.000000e+000,,,,,,,,,,,,,,32,1,4.000000e+000,5.439758e-003,0.000000e+000,0,,0,
1524279920.324,,0.000000e+000,5.600307e+001,-6.472427e-005,0.000000e+000,2,6.688948e-001,0.000000e+000,,,,,,,,,,,,,,32,1,4.000000e+000,9.510040e-003,0.000000e+000,0,,0,
1524279932.704,,0.000000e+000,5.600307e+001,-6.484806e-005,0.000000e+000,2,6.685007e-001,0.000000e+000,,,,,,,,,,,,,,32,1,4.000000e+000,9.510040e-003,0.000000e+000,0,,0,
1524279945.224,,0.000000e+000,5.599695e+001,-6.476960e-005,0.000000e+000,2,6.684983e-001,0.000000e+000,,,,,,,,,,,,,,32,1,4.000000e+000,0.000000e+000,0.000000e+000,0,,0,
1524279957.574,,0.000000e+000,5.599560e+001,-6.484070e-005,0.000000e+000,2,6.691871e-001,0.000000e+000,,,,,,,,,,,,,,32,1,4.000000e+000,5.428314e-003,0.000000e+000,0,,0,
1524279970.314,,0.000000e+000,5.599763e+001,-6.488397e-005,0.000000e+000,2,6.688199e-001,0.000000e+000,,,,,,,,,,,,,,32,1,4.000000e+000,1.222992e-002,0.000000e+000,0,,0,
1524279983.604,,0.000000e+000,5.599492e+001,-6.494842e-005,0.000000e+000,2,6.690268e-001,0.000000e+000,,,,,,,,,,,,,,32,1,4.000000e+000,1.350403e-003,0.000000e+000,0,,0,
1524279995.484,,0.000000e+000,5.599424e+001,-6.500817e-005,0.000000e+000,2,6.690609e-001,0.000000e+000,,,,,,,,,,,,,,32,1,4.000000e+000,0.000000e+000,0.000000e+000,0,,0,
1524280007.834,,0.000000e+000,5.599696e+001,-6.512256e-005,0.000000e+000,2,6.682923e-001,0.000000e+000,,,,,,,,,,,,,,32,1,4.000000e+000,5.428314e-003,0.000000e+000,0,,0,
1524280020.254,,0.000000e+000,5.599695e+001,-6.511805e-005,0.000000e+000,2,6.688536e-001,0.000000e+000,,,,,,,,,,,,,,32,1,4.000000e+000,1.086044e-002,0.000000e+000,0,,0,
1524280032.814,,0.000000e+000,5.599695e+001,-6.520297e-005,0.000000e+000,2,6.682616e-001,0.000000e+000,,,,,,,,,,,,,,32,1,4.000000e+000,2.719879e-003,0.000000e+000,0,,0,
1524280045.094,,0.000000e+000,5.599628e+001,-6.515384e-005,0.000000e+000,2,6.692227e-001,0.000000e+000,,,,,,,,,,,,,,32,1,4.000000e+000,4.070282e-003,0.000000e+000,0,,0,
1524280057.644,,0.000000e+000,5.599899e+001,-6.527157e-005,0.000000e+000,2,6.693554e-001,0.000000e+000,,,,,,,,,,,,,,32,1,4.000000e+000,1.221848e-002,0.000000e+000,0,,0,
1524280070.184,,0.000000e+000,5.599763e+001,-6.525881e-005,0.000000e+000,2,6.686923e-001,0.000000e+000,,,,,,,,,,,,,,32,1,4.000000e+000,9.498596e-003,0.000000e+000,0,,0,
1524280082.784,,0.000000e+000,5.600034e+001,-6.537980e-005,0.000000e+000,2,6.696571e-001,0.000000e+000,,,,,,,,,,,,,,32,1,4.000000e+000,4.070282e-003,0.000000e+000,0,,0,
1524280095.364,,0.000000e+000,5.599763e+001,-6.536086e-005,0.000000e+000,2,6.692388e-001,0.000000e+000,,,,,,,,,,,,,,32,1,4.000000e+000,1.361847e-003,0.000000e+000,0,,0,
1524280107.744,,0.000000e+000,5.599831e+001,-6.552709e-005,0.000000e+000,2,6.705837e-001,0.000000e+000,,,,,,,,,,,,,,32,1,4.000000e+000,2.719879e-003,0.000000e+000,0,,0,
1524280120.184,,0.000000e+000,5.599763e+001,-6.556139e-005,0.000000e+000,2,6.707196e-001,0.000000e+000,,,,,,,,,,,,,,32,1,4.000000e+000,1.361847e-003,0.000000e+000,0,,0,
1524280133.384,,0.000000e+000,5.600375e+001,-6.561217e-005,0.000000e+000,2,6.710165e-001,0.000000e+000,,,,,,,,,,,,,,32,1,4.000000e+000,5.428314e-003,0.000000e+000,0,,0,
1524280145.774,,0.000000e+000,5.599967e+001,-6.560500e-005,0.000000e+000,2,6.697960e-001,0.000000e+000,,,,,,,,,,,,,,32,1,4.000000e+000,8.159637e-003,0.000000e+000,0,,0,
1524280158.384,,0.000000e+000,5.599628e+001,-6.565282e-005,0.000000e+000,2,6.708988e-001,0.000000e+000,,,,,,,,,,,,,,32,1,4.000000e+000,6.786346e-003,0.000000e+000,0,,0,
1524280171.324,,0.000000e+000,5.599424e+001,-6.571184e-005,0.000000e+000,2,6.693449e-001,0.000000e+000,,,,,,,,,,,,,,32,1,4.000000e+000,8.148193e-003,0.000000e+000,0,,0,
1524280184.104,,0.000000e+000,5.599763e+001,-6.573793e-005,0.000000e+000,2,6.705579e-001,0.000000e+000,,,,,,,,,,,,,,32,1,4.000000e+000,1.361847e-003,0.000000e+000,0,,0,
1524280196.534,,0.000000e+000,5.599831e+001,-6.580893e-005,0.000000e+000,2,6.705015e-001,0.000000e+000,,,,,,,,,,,,,,32,1,4.000000e+000,2.719879e-003,0.000000e+000,0,,0,
1524280209.064,,0.000000e+000,5.600238e+001,-6.581087e-005,0.000000e+000,2,6.701134e-001,0.000000e+000,,,,,,,,,,,,,,32,1,4.000000e+000,0.000000e+000,0.000000e+000,0,,0,
1524280221.594,,0.000000e+000,5.599627e+001,-6.590099e-005,0.000000e+000,2,6.699726e-001,0.000000e+000,,,,,,,,,,,,,,32,1,4.000000e+000,1.358032e-003,0.000000e+000,0,,0,
1524280234.094,,0.000000e+000,5.599017e+001,-6.596935e-005,0.000000e+000,2,6.714955e-001,0.000000e+000,,,,,,,,,,,,,,32,1,4.000000e+000,5.432129e-003,0.000000e+000,0,,0,
1524280246.224,,0.000000e+000,5.599355e+001,-6.597638e-005,0.000000e+000,2,6.698502e-001,0.000000e+000,,,,,,,,,,,,,,32,1,4.000000e+000,4.070282e-003,0.000000e+000,0,,0,
1524280259.034,,0.000000e+000,5.600035e+001,-6.599604e-005,0.000000e+000,2,6.725228e-001,0.000000e+000,,,,,,,,,,,,,,32,1,4.000000e+000,6.801605e-003,0.000000e+000,0,,0,
1524280271.554,,0.000000e+000,5.599355e+001,-6.607455e-005,0.000000e+000,2,6.710589e-001,0.000000e+000,,,,,,,,,,,,,,32,1,4.000000e+000,6.786346e-003,0.000000e+000,0,,0,
1524280284.114,,0.000000e+000,5.599559e+001,-6.611292e-005,0.000000e+000,2,6.717716e-001,0.000000e+000,,,,,,,,,,,,,,32,1,4.000000e+000,2.708435e-003,0.000000e+000,0,,0,
1524280297.164,,0.000000e+000,5.599696e+001,-6.613145e-005,0.000000e+000,2,6.719909e-001,0.000000e+000,,,,,,,,,,,,,,32,1,4.000000e+000,5.428314e-003,0.000000e+000,0,,0,
1524280309.694,,0.000000e+000,5.599424e+001,-6.616084e-005,0.000000e+000,2,6.705049e-001,0.000000e+000,,,,,,,,,,,,,,32,1,4.000000e+000,2.708435e-003,0.000000e+000,0,,0,
1524280322.324,,0.000000e+000,5.599492e+001,-6.626576e-005,0.000000e+000,2,6.725327e-001,0.000000e+000,,,,,,,,,,,,,,32,1,4.000000e+000,9.506226e-003,0.000000e+000,0,,0,
1524280334.954,,0.000000e+000,5.599627e+001,-6.634948e-005,0.000000e+000,2,6.719896e-001,0.000000e+000,,,,,,,,,,,,,,32,1,4.000000e+000,1.358032e-003,0.000000e+000,0,,0,
1524280347.604,,0.000000e+000,5.599763e+001,-6.632220e-005,0.000000e+000,2,6.714889e-001,0.000000e+000,,,,,,,,,,,,,,32,1,4.000000e+000,4.077911e-003,0.000000e+000,0,,0,
1524280359.994,,0.000000e+000,5.600035e+001,-6.635787e-005,0.000000e+000,2,6.715503e-001,0.000000e+000,,,,,,,,,,,,,,32,1,4.000000e+000,1.361847e-003,0.000000e+000,0,,0,
1524280372.644,,0.000000e+000,5.599423e+001,-6.637541e-005,0.000000e+000,2,6.723782e-001,0.000000e+000,,,,,,,,,,,,,,32,1,4.000000e+000,5.428314e-003,0.000000e+000,0,,0,
1524280384.944,,0.000000e+000,5.599831e+001,-6.640830e-005,0.000000e+000,2,6.716201e-001,0.000000e+000,,,,,,,,,,,,,,32,1,4.000000e+000,5.439758e-003,0.000000e+000,0,,0,
1524280397.654,,0.000000e+000,5.599695e+001,-6.649432e-005,0.000000e+000,2,6.734470e-001,0.000000e+000,,,,,,,,,,,,,,32,1,4.000000e+000,2.719879e-003,0.000000e+000,0,,0,
1524280410.254,,0.000000e+000,5.599492e+001,-6.653226e-005,0.000000e+000,2,6.726242e-001,0.000000e+000,,,,,,,,,,,,,,32,1,4.000000e+000,6.790161e-003,0.000000e+000,0,,0,
1524280423.014,,0.000000e+000,5.599220e+001,-6.657641e-005,0.000000e+000,2,6.733969e-001,0.000000e+000,,,,,,,,,,,,,,32,1,4.000000e+000,1.361847e-003,0.000000e+000,0,,0,
1524280435.634,,0.000000e+000,5.599763e+001,-6.659592e-005,0.000000e+000,2,6.737829e-001,0.000000e+000,,,,,,,,,,,,,,32,1,4.000000e+000,9.498596e-003,0.000000e+000,0,,0,
1524280448.324,,0.000000e+000,5.599831e+001,-6.662197e-005,0.000000e+000,2,6.718090e-001,0.000000e+000,,,,,,,,,,,,,,32,1,4.000000e+000,0.000000e+000,0.000000e+000,0,,0,
1524280460.934,,0.000000e+000,5.599899e+001,-6.668676e-005,0.000000e+000,2,6.736278e-001,0.000000e+000,,,,,,,,,,,,,,32,1,4.000000e+000,1.358032e-003,0.000000e+000,0,,0,
1524280473.564,,0.000000e+000,5.599967e+001,-6.666063e-005,0.000000e+000,2,6.719021e-001,0.000000e+000,,,,,,,,,,,,,,32,1,4.000000e+000,1.357651e-002,0.000000e+000,0,,0,
1524280486.184,,0.000000e+000,5.600171e+001,-6.673300e-005,0.000000e+000,2,6.737999e-001,0.000000e+000,,,,,,,,,,,,,,32,1,4.000000e+000,4.081726e-003,0.000000e+000,0,,0,
1524280498.664,,0.000000e+000,5.599763e+001,-6.688467e-005,0.000000e+000,2,6.730408e-001,0.000000e+000,,,,,,,,,,,,,,32,1,4.000000e+000,4.077911e-003,0.000000e+000,0,,0,
1524280510.794,,0.000000e+000,5.599355e+001,-6.683984e-005,0.000000e+000,2,6.739342e-001,0.000000e+000,,,,,,,,,,,,,,32,1,4.000000e+000,4.070282e-003,0.000000e+000,0,,0,
1524280523.714,,0.000000e+000,5.599492e+001,-6.692906e-005,0.000000e+000,2,6.730357e-001,0.000000e+000,,,,,,,,,,,,,,32,1,4.000000e+000,6.790161e-003,0.000000e+000,0,,0,
1524280535.784,,0.000000e+000,5.599763e+001,-6.688564e-005,0.000000e+000,2,6.739138e-001,0.000000e+000,,,,,,,,,,,,,,32,1,4.000000e+000,1.361847e-003,0.000000e+000,0,,0,
1524280548.425,,0.000000e+000,5.599695e+001,-6.687889e-005,0.000000e+000,2,6.727987e-001,0.000000e+000,,,,,,,,,,,,,,32,1,4.000000e+000,0.000000e+000,0.000000e+000,0,,0,
1524280560.815,,0.000000e+000,5.599424e+001,-6.692007e-005,0.000000e+000,2,6.738003e-001,0.000000e+000,,,,,,,,,,,,,,32,1,4.000000e+000,1.628113e-002,0.000000e+000,0,,0,
1524280573.245,,0.000000e+000,5.600102e+001,-6.704092e-005,0.000000e+000,2,6.732023e-001,0.000000e+000,,,,,,,,,,,,,,32,1,4.000000e+000,2.712250e-003,0.000000e+000,0,,0,
1524280585.845,,0.000000e+000,5.599831e+001,-6.698738e-005,0.000000e+000,2,6.738181e-001,0.000000e+000,,,,,,,,,,,,,,32,1,4.000000e+000,2.719879e-003,0.000000e+000,0,,0,
1524280598.235,,0.000000e+000,5.599695e+001,-6.704606e-005,0.000000e+000,2,6.734318e-001,0.000000e+000,,,,,,,,,,,,,,32,1,4.000000e+000,0.000000e+000,0.000000e+000,0,,0,
1524280611.055,,0.000000e+000,5.600238e+001,-6.706264e-005,0.000000e+000,2,6.743935e-001,0.000000e+000,,,,,,,,,,,,,,32,1,4.000000e+000,1.087189e-002,0.000000e+000,0,,0,
1524280623.395,,0.000000e+000,5.599288e+001,-6.709649e-005,0.000000e+000,2,6.728169e-001,0.000000e+000,,,,,,,,,,,,,,32,1,4.000000e+000,0.000000e+000,0.000000e+000,0,,0,
1524280636.715,,0.000000e+000,5.599559e+001,-6.714197e-005,0.000000e+000,2,6.751859e-001,0.000000e+000,,,,,,,,,,,,,,32,1,4.000000e+000,1.358032e-002,0.000000e+000,0,,0,
1524280649.875,,0.000000e+000,5.599763e+001,-6.723377e-005,0.000000e+000,2,6.742885e-001,0.000000e+000,,,,,,,,,,,,,,32,1,4.000000e+000,4.077911e-003,0.000000e+000,0,,0,
1524280662.595,,0.000000e+000,5.599899e+001,-6.722544e-005,0.000000e+000,2,6.739509e-001,0.000000e+000,,,,,,,,,,,,,,32,1,4.000000e+000,6.790161e-003,0.000000e+000,0,,0,
1524280675.235,,0.000000e+000,5.599967e+001,-6.723095e-005,0.000000e+000,2,6.752166e-001,0.000000e+000,,,,,,,,,,,,,,32,1,4.000000e+000,0.000000e+000,0.000000e+000,0,,0,
1524280687.585,,0.000000e+000,5.599899e+001,-6.727077e-005,0.000000e+000,2,6.739324e-001,0.000000e+000,,,,,,,,,,,,,,32,1,4.000000e+000,1.358032e-003,0.000000e+000,0,,0,
1524280700.495,,0.000000e+000,5.599967e+001,-6.727489e-005,0.000000e+000,2,6.755934e-001,0.000000e+000,,,,,,,,,,,,,,32,1,4.000000e+000,1.086044e-002,0.000000e+000,0,,0,
1524280712.685,,0.000000e+000,5.599695e+001,-6.734882e-005,0.000000e+000,2,6.756395e-001,0.000000e+000,,,,,,,,,,,,,,32,1,4.000000e+000,1.086044e-002,0.000000e+000,0,,0,
1524280725.235,,0.000000e+000,5.599220e+001,-6.738140e-005,0.000000e+000,2,6.759229e-001,0.000000e+000,,,,,,,,,,,,,,32,1,4.000000e+000,1.221085e-002,0.000000e+000,0,,0,
1524280738.145,,0.000000e+000,5.599763e+001,-6.741751e-005,0.000000e+000,2,6.742316e-001,0.000000e+000,,,,,,,,,,,,,,32,1,4.000000e+000,1.361847e-003,0.000000e+000,0,,0,
1524280750.605,,0.000000e+000,5.599831e+001,-6.741340e-005,0.000000e+000,2,6.748070e-001,0.000000e+000,,,,,,,,,,,,,,32,1,4.000000e+000,2.719879e-003,0.000000e+000,0,,0,
1524280763.345,,0.000000e+000,5.600238e+001,-6.758045e-005,0.000000e+000,2,6.758590e-001,0.000000e+000,,,,,,,,,,,,,,32,1,4.000000e+000,5.432129e-003,0.000000e+000,0,,0,
1524280775.455,,0.000000e+000,5.599627e+001,-6.750655e-005,0.000000e+000,2,6.752120e-001,0.000000e+000,,,,,,,,,,,,,,32,1,4.000000e+000,1.358032e-003,0.000000e+000,0,,0,
1524280788.675,,0.000000e+000,5.599627e+001,-6.753288e-005,0.000000e+000,2,6.739910e-001,0.000000e+000,,,,,,,,,,,,,,32,1,4.000000e+000,1.358032e-003,0.000000e+000,0,,0,
1524280800.605,,0.000000e+000,5.599695e+001,-6.751345e-005,0.000000e+000,2,6.753924e-001,0.000000e+000,,,,,,,,,,,,,,32,1,4.000000e+000,0.000000e+000,0.000000e+000,0,,0,
1524280813.115,,0.000000e+000,5.599831e+001,-6.759620e-005,0.000000e+000,2,6.754185e-001,0.000000e+000,,,,,,,,,,,,,,32,1,4.000000e+000,5.439758e-003,0.000000e+000,0,,0,
1524280825.775,,0.000000e+000,5.599355e+001,-6.757241e-005,0.000000e+000,2,6.755064e-001,0.000000e+000,,,,,,,,,,,,,,32,1,4.000000e+000,9.510040e-003,0.000000e+000,0,,0,
1524280837.935,,0.000000e+000,5.599967e+001,-6.762995e-005,0.000000e+000,2,6.755945e-001,0.000000e+000,,,,,,,,,,,,,,32,1,4.000000e+000,2.719879e-003,0.000000e+000,0,,0,
1524280850.335,,0.000000e+000,5.600171e+001,-6.763505e-005,0.000000e+000,2,6.761348e-001,0.000000e+000,,,,,,,,,,,,,,32,1,4.000000e+000,4.081726e-003,0.000000e+000,0,,0,
1524280862.715,,0.000000e+000,5.599899e+001,-6.772688e-005,0.000000e+000,2,6.760750e-001,0.000000e+000,,,,,,,,,,,,,,32,1,4.000000e+000,1.358032e-003,0.000000e+000,0,,0,
1524280875.055,,0.000000e+000,5.600103e+001,-6.768174e-005,0.000000e+000,2,6.762218e-001,0.000000e+000,,,,,,,,,,,,,,32,1,4.000000e+000,5.439758e-003,0.000000e+000,0,,0,
1524280887.415,,0.000000e+000,5.599696e+001,-6.773778e-005,0.000000e+000,2,6.757283e-001,0.000000e+000,,,,,,,,,,,,,,32,1,4.000000e+000,8.148193e-003,0.000000e+000,0,,0,
1524280899.825,,0.000000e+000,5.599967e+001,-6.783124e-005,0.000000e+000,2,6.754151e-001,0.000000e+000,,,,,,,,,,,,,,32,1,4.000000e+000,2.719879e-003,0.000000e+000,0,,0,
1524280912.735,,0.000000e+000,5.600578e+001,-6.783141e-005,0.000000e+000,2,6.752870e-001,0.000000e+000,,,,,,,,,,,,,,32,1,4.000000e+000,1.494980e-002,0.000000e+000,0,,0,
1524280924.865,,0.000000e+000,5.599424e+001,-6.786904e-005,0.000000e+000,2,6.768847e-001,0.000000e+000,,,,,,,,,,,,,,32,1,4.000000e+000,2.708435e-003,0.000000e+000,0,,0,
1524280937.515,,0.000000e+000,5.599560e+001,-6.791324e-005,0.000000e+000,2,6.763715e-001,0.000000e+000,,,,,,,,,,,,,,32,1,4.000000e+000,5.428314e-003,0.000000e+000,0,,0,
1524280949.975,,0.000000e+000,5.599831e+001,-6.786692e-005,0.000000e+000,2,6.766317e-001,0.000000e+000,,,,,,,,,,,,,,32,1,4.000000e+000,1.358032e-002,0.000000e+000,0,,0,
1524280962.365,,0.000000e+000,5.599356e+001,-6.792058e-005,0.000000e+000,2,6.754088e-001,0.000000e+000,,,,,,,,,,,,,,32,1,4.000000e+000,1.358032e-003,0.000000e+000,0,,0,
1524280975.125,,0.000000e+000,5.599288e+001,-6.796994e-005,0.000000e+000,2,6.769277e-001,0.000000e+000,,,,,,,,,,,,,,32,1,4.000000e+000,0.000000e+000,0.000000e+000,0,,0,
1524280987.335,,0.000000e+000,5.599967e+001,-6.794248e-005,0.000000e+000,2,6.756530e-001,0.000000e+000,,,,,,,,,,,,,,32,1,4.000000e+000,8.159637e-003,0.000000e+000,0,,0,
1524280999.875,,0.000000e+000,5.599559e+001,-6.805764e-005,0.000000e+000,2,6.773178e-001,0.000000e+000,,,,,,,,,,,,,,32,1,4.000000e+000,2.172852e-002,0.000000e+000,0,,0,
1524281013.005,,0.000000e+000,5.599288e+001,-6.802690e-005,0.000000e+000,2,6.772358e-001,0.000000e+000,,,,,,,,,,,,,,32,1,4.000000e+000,1.630020e-002,0.000000e+000,0,,0,
1524281025.325,,0.000000e+000,5.600307e+001,-6.801225e-005,0.000000e+000,2,6.770598e-001,0.000000e+000,,,,,,,,,,,,,,32,1,4.000000e+000,4.070282e-003,0.000000e+000,0,,0,
1524281038.275,,0.000000e+000,5.600307e+001,-6.810600e-005,0.000000e+000,2,6.782410e-001,0.000000e+000,,,,,,,,,,,,,,32,1,4.000000e+000,4.070282e-003,0.000000e+000,0,,0,
1524281051.365,,0.000000e+000,5.600035e+001,-6.805939e-005,0.000000e+000,2,6.763891e-001,0.000000e+000,,,,,,,,,,,,,,32,1,4.000000e+000,1.361847e-003,0.000000e+000,0,,0,
1524281063.845,,0.000000e+000,5.600102e+001,-6.815328e-005,0.000000e+000,2,6.772451e-001,0.000000e+000,,,,,,,,,,,,,,32,1,4.000000e+000,2.712250e-003,0.000000e+000,0,,0,
1524281076.295,,0.000000e+000,5.599559e+001,-6.812442e-005,0.000000e+000,2,6.769608e-001,0.000000e+000,,,,,,,,,,,,,,32,1,4.000000e+000,1.358032e-002,0.000000e+000,0,,0,
1524281088.905,,0.000000e+000,5.599016e+001,-6.813177e-005,0.000000e+000,2,6.771652e-001,0.000000e+000,,,,,,,,,,,,,,32,1,4.000000e+000,2.719879e-003,0.000000e+000,0,,0,
1524281101.425,,0.000000e+000,5.599763e+001,-6.822927e-005,0.000000e+000,2,6.772003e-001,0.000000e+000,,,,,,,,,,,,,,32,1,4.000000e+000,1.222992e-002,0.000000e+000,0,,0,
1524281114.025,,0.000000e+000,5.599831e+001,-6.816332e-005,0.000000e+000,2,6.773637e-001,0.000000e+000,,,,,,,,,,,,,,32,1,4.000000e+000,2.719879e-003,0.000000e+000,0,,0,
1524281126.965,,0.000000e+000,5.600035e+001,-6.831365e-005,0.000000e+000,2,6.781934e-001,0.000000e+000,,,,,,,,,,,,,,32,1,4.000000e+000,1.361847e-003,0.000000e+000,0,,0,
1524281140.155,,0.000000e+000,5.599424e+001,-6.823702e-005,0.000000e+000,2,6.776192e-001,0.000000e+000,,,,,,,,,,,,,,32,1,4.000000e+000,1.358032e-002,0.000000e+000,0,,0,
1524281153.045,,0.000000e+000,5.599424e+001,-6.828361e-005,0.000000e+000,2,6.786785e-001,0.000000e+000,,,,,,,,,,,,,,32,1,4.000000e+000,1.358032e-002,0.000000e+000,0,,0,
1524281166.235,,0.000000e+000,5.599967e+001,-6.826984e-005,0.000000e+000,2,6.773357e-001,0.000000e+000,,,,,,,,,,,,,,32,1,4.000000e+000,2.719879e-003,0.000000e+000,0,,0,
1524281178.865,,0.000000e+000,5.598949e+001,-6.831926e-005,0.000000e+000,2,6.769007e-001,0.000000e+000,,,,,,,,,,,,,,32,1,4.000000e+000,1.765060e-002,0.000000e+000,0,,0,
1524281191.455,,0.000000e+000,5.599695e+001,-6.843564e-005,0.000000e+000,2,6.786129e-001,0.000000e+000,,,,,,,,,,,,,,32,1,4.000000e+000,0.000000e+000,0.000000e+000,0,,0,
1524281203.975,,0.000000e+000,5.599560e+001,-6.839607e-005,0.000000e+000,2,6.782290e-001,0.000000e+000,,,,,,,,,,,,,,32,1,4.000000e+000,1.086807e-002,0.000000e+000,0,,0,
1524281217.175,,0.000000e+000,5.599831e+001,-6.841922e-005,0.000000e+000,2,6.784991e-001,0.000000e+000,,,,,,,,,,,,,,32,1,4.000000e+000,8.140564e-003,0.000000e+000,0,,0,
1524281229.415,,0.000000e+000,5.599899e+001,-6.842771e-005,0.000000e+000,2,6.777135e-001,0.000000e+000,,,,,,,,,,,,,,32,1,4.000000e+000,1.358032e-003,0.000000e+000,0,,0,
1524281242.135,,0.000000e+000,5.599696e+001,-6.839186e-005,0.000000e+000,2,6.786699e-001,0.000000e+000,,,,,,,,,,,,,,32,1,4.000000e+000,5.428314e-003,0.000000e+000,0,,0,
1524281255.586,,0.000000e+000,5.599763e+001,-6.851381e-005,0.000000e+000,2,6.779109e-001,0.000000e+000,,,,,,,,,,,,,,32,1,4.000000e+000,4.077911e-003,0.000000e+000,0,,0,
1524281268.116,,0.000000e+000,5.599966e+001,-6.845523e-005,0.000000e+000,2,6.768278e-001,0.000000e+000,,,,,,,,,,,,,,32,1,4.000000e+000,5.432129e-003,0.000000e+000,0,,0,
1524281281.026,,0.000000e+000,5.599763e+001,-6.850358e-005,0.000000e+000,2,6.784876e-001,0.000000e+000,,,,,,,,,,,,,,32,1,4.000000e+000,4.077911e-003,0.000000e+000,0,,0,
1524281293.296,,0.000000e+000,5.599628e+001,-6.853444e-005,0.000000e+000,2,6.780577e-001,0.000000e+000,,,,,,,,,,,,,,32,1,4.000000e+000,6.786346e-003,0.000000e+000,0,,0,
1524281305.676,,0.000000e+000,5.599560e+001,-6.863494e-005,0.000000e+000,2,6.801665e-001,0.000000e+000,,,,,,,,,,,,,,32,1,4.000000e+000,5.428314e-003,0.000000e+000,0,,0,
1524281318.276,,0.000000e+000,5.600034e+001,-6.852606e-005,0.000000e+000,2,6.775451e-001,0.000000e+000,,,,,,,,,,,,,,32,1,4.000000e+000,4.070282e-003,0.000000e+000,0,,0,
1524281331.286,,0.000000e+000,5.600239e+001,-6.861942e-005,0.000000e+000,2,6.786481e-001,0.000000e+000,,,,,,,,,,,,,,32,1,4.000000e+000,2.719879e-003,0.000000e+000,0,,0,
1524281343.956,,0.000000e+000,5.600171e+001,-6.871387e-005,0.000000e+000,2,6.791053e-001,0.000000e+000,,,,,,,,,,,,,,32,1,4.000000e+000,1.350403e-003,0.000000e+000,0,,0,
1524281356.416,,0.000000e+000,5.599763e+001,-6.869858e-005,0.000000e+000,2,6.795920e-001,0.000000e+000,,,,,,,,,,,,,,32,1,4.000000e+000,9.498596e-003,0.000000e+000,0,,0,
1524281368.896,,0.000000e+000,5.599899e+001,-6.873090e-005,0.000000e+000,2,6.786112e-001,0.000000e+000,,,,,,,,,,,,,,32,1,4.000000e+000,9.510040e-003,0.000000e+000,0,,0,
1524281381.506,,0.000000e+000,5.599696e+001,-6.870894e-005,0.000000e+000,2,6.793123e-001,0.000000e+000,,,,,,,,,,,,,,32,1,4.000000e+000,5.428314e-003,0.000000e+000,0,,0,
1524281394.026,,0.000000e+000,5.600171e+001,-6.882683e-005,0.000000e+000,2,6.794527e-001,0.000000e+000,,,,,,,,,,,,,,32,1,4.000000e+000,4.081726e-003,0.000000e+000,0,,0,
1524281406.586,,0.000000e+000,5.599763e+001,-6.878223e-005,0.000000e+000,2,6.797150e-001,0.000000e+000,,,,,,,,,,,,,,32,1,4.000000e+000,1.361847e-003,0.000000e+000,0,,0,
1524281418.996,,0.000000e+000,5.599831e+001,-6.884206e-005,0.000000e+000,2,6.791238e-001,0.000000e+000,,,,,,,,,,,,,,32,1,4.000000e+000,0.000000e+000,0.000000e+000,0,,0,
1524281431.526,,0.000000e+000,5.599424e+001,-6.876611e-005,0.000000e+000,2,6.799784e-001,0.000000e+000,,,,,,,,,,,,,,32,1,4.000000e+000,8.148193e-003,0.000000e+000,0,,0,
1524281444.036,,0.000000e+000,5.599899e+001,-6.884591e-005,0.000000e+000,2,6.794998e-001,0.000000e+000,,,,,,,,,,,,,,32,1,4.000000e+000,4.081726e-003,0.000000e+000,0,,0,
1524281456.426,,0.000000e+000,5.599899e+001,-6.882406e-005,0.000000e+000,2,6.797476e-001,0.000000e+000,,,,,,,,,,,,,,32,1,4.000000e+000,4.081726e-003,0.000000e+000,0,,0,
1524281468.776,,0.000000e+000,5.599560e+001,-6.885997e-005,0.000000e+000,2,6.783604e-001,0.000000e+000,,,,,,,,,,,,,,32,1,4.000000e+000,5.428314e-003,0.000000e+000,0,,0,
1524281481.286,,0.000000e+000,5.599899e+001,-6.890163e-005,0.000000e+000,2,6.801445e-001,0.000000e+000,,,,,,,,,,,,,,32,1,4.000000e+000,1.358032e-003,0.000000e+000,0,,0,
1524281494.416,,0.000000e+000,5.599628e+001,-6.895245e-005,0.000000e+000,2,6.805090e-001,0.000000e+000,,,,,,,,,,,,,,32,1,4.000000e+000,6.786346e-003,0.000000e+000,0,,0,
1524281507.006,,0.000000e+000,5.599763e+001,-6.889582e-005,0.000000e+000,2,6.793745e-001,0.000000e+000,,,,,,,,,,,,,,32,1,4.000000e+000,6.790161e-003,0.000000e+000,0,,0,
1524281519.686,,0.000000e+000,5.599966e+001,-6.898656e-005,0.000000e+000,2,6.811803e-001,0.000000e+000,,,,,,,,,,,,,,32,1,4.000000e+000,5.432129e-003,0.000000e+000,0,,0,
1524281532.266,,0.000000e+000,5.599492e+001,-6.897846e-005,0.000000e+000,2,6.791206e-001,0.000000e+000,,,,,,,,,,,,,,32,1,4.000000e+000,1.350403e-003,0.000000e+000,0,,0,
1524281544.956,,0.000000e+000,5.599696e+001,-6.901204e-005,0.000000e+000,2,6.804326e-001,0.000000e+000,,,,,,,,,,,,,,32,1,4.000000e+000,5.428314e-003,0.000000e+000,0,,0,
1524281557.266,,0.000000e+000,5.600035e+001,-6.902054e-005,0.000000e+000,2,6.794589e-001,0.000000e+000,,,,,,,,,,,,,,32,1,4.000000e+000,1.361847e-003,0.000000e+000,0,,0,
1524281569.576,,0.000000e+000,5.600307e+001,-6.911483e-005,0.000000e+000,2,6.810590e-001,0.000000e+000,,,,,,,,,,,,,,32,1,4.000000e+000,4.070282e-003,0.000000e+000,0,,0,
1524281582.056,,0.000000e+000,5.600034e+001,-6.909086e-005,0.000000e+000,2,6.794827e-001,0.000000e+000,,,,,,,,,,,,,,32,1,4.000000e+000,4.070282e-003,0.000000e+000,0,,0,
1524281594.716,,0.000000e+000,5.599424e+001,-6.911535e-005,0.000000e+000,2,6.811601e-001,0.000000e+000,,,,,,,,,,,,,,32,1,4.000000e+000,0.000000e+000,0.000000e+000,0,,0,
1524281607.106,,0.000000e+000,5.599831e+001,-6.906676e-005,0.000000e+000,2,6.788479e-001,0.000000e+000,,,,,,,,,,,,,,32,1,4.000000e+000,8.140564e-003,0.000000e+000,0,,0,
1524281620.096,,0.000000e+000,5.600102e+001,-6.914207e-005,0.000000e+000,2,6.815205e-001,0.000000e+000,,,,,,,,,,,,,,32,1,4.000000e+000,8.152008e-003,0.000000e+000,0,,0,
1524281632.256,,0.000000e+000,5.599695e+001,-6.914242e-005,0.000000e+000,2,6.796061e-001,0.000000e+000,,,,,,,,,,,,,,32,1,4.000000e+000,0.000000e+000,0.000000e+000,0,,0,
1524281644.556,,0.000000e+000,5.600103e+001,-6.914423e-005,0.000000e+000,2,6.810377e-001,0.000000e+000,,,,,,,,,,,,,,32,1,4.000000e+000,5.439758e-003,0.000000e+000,0,,0,
1524281657.096,,0.000000e+000,5.599831e+001,-6.914521e-005,0.000000e+000,2,6.800246e-001,0.000000e+000,,,,,,,,,,,,,,32,1,4.000000e+000,0.000000e+000,0.000000e+000,0,,0,
1524281669.636,,0.000000e+000,5.599763e+001,-6.918490e-005,0.000000e+000,2,6.808220e-001,0.000000e+000,,,,,,,,,,,,,,32,1,4.000000e+000,1.361847e-003,0.000000e+000,0,,0,
1524281682.156,,0.000000e+000,5.599627e+001,-6.924819e-005,0.000000e+000,2,6.807180e-001,0.000000e+000,,,,,,,,,,,,,,32,1,4.000000e+000,1.358032e-003,0.000000e+000,0,,0,
1524281694.756,,0.000000e+000,5.599695e+001,-6.926156e-005,0.000000e+000,2,6.807830e-001,0.000000e+000,,,,,,,,,,,,,,32,1,4.000000e+000,2.719879e-003,0.000000e+000,0,,0,
1524281707.726,,0.000000e+000,5.599831e+001,-6.927776e-005,0.000000e+000,2,6.809384e-001,0.000000e+000,,,,,,,,,,,,,,32,1,4.000000e+000,0.000000e+000,0.000000e+000,0,,0,
1524281720.126,,0.000000e+000,5.599967e+001,-6.929699e-005,0.000000e+000,2,6.813816e-001,0.000000e+000,,,,,,,,,,,,,,32,1,4.000000e+000,2.719879e-003,0.000000e+000,0,,0,
1524281733.516,,0.000000e+000,5.599831e+001,-6.937741e-005,0.000000e+000,2,6.813177e-001,0.000000e+000,,,,,,,,,,,,,,32,1,4.000000e+000,5.439758e-003,0.000000e+000,0,,0,
1524281746.266,,0.000000e+000,5.599695e+001,-6.932757e-005,0.000000e+000,2,6.802406e-001,0.000000e+000,,,,,,,,,,,,,,32,1,4.000000e+000,1.086044e-002,0.000000e+000,0,,0,
1524281758.846,,0.000000e+000,5.600238e+001,-6.935640e-005,0.000000e+000,2,6.817429e-001,0.000000e+000,,,,,,,,,,,,,,32,1,4.000000e+000,0.000000e+000,0.000000e+000,0,,0,
1524281771.336,,0.000000e+000,5.599696e+001,-6.940751e-005,0.000000e+000,2,6.808411e-001,0.000000e+000,,,,,,,,,,,,,,32,1,4.000000e+000,8.148193e-003,0.000000e+000,0,,0,