File: Experimental Raw Data/TC04-12-01K VRMac VRMde/TC04-12-01K_VRMac_55K_12000s_VRMde_55Klinear.dc.dat
[Header]
TITLE,MPMS DC Measurement
BYAPP,MPMS Measurement,2.1,Summary
FILEOPENTIME, 1524362099.791000 4/21/2018, 7:54:59 PM

INFO, APPNAME, MPMS MultiVu Application, Revision 1.61,  Build 082

INFO, NAME, TC04-12-01K
INFO, WEIGHT, 1.000
INFO, AREA, 1.000
INFO, LENGTH, 1.000
INFO, SHAPE, 0
INFO, COMMENT,
INFO, SEQUENCE FILE: VRMac_55K_12000s_VRMde_55Klinear.seq


INFO, BACKGROUND DATA FILE:, None


STARTUPAXIS,X,4,LINEAR,AUTO,0.000000,0.000000
STARTUPAXIS,Y1,5,LINEAR,AUTO,0.000000,0.000000


STARTUPGROUP,Longitudinal
FIELDGROUP,Longitudinal,1,2,3,4,5,6,7,8,9,15,16,17,18,27,28
FIELDGROUP,Transverse,1,2,3,4,10,11,12,13,14,19,20,21,22,27,28

PLOT_APPEARANCE,ALL,HORZ_GRID_ON,VERT_GRID_ON,MARKERS_AND_LINES

[Data]
Time,Comment,Field (Oe),Temperature (K),Long Moment (emu),Long Scan Std Dev,Long Algorithm,Long Reg Fit,Long Percent Error (%),Trans Moment (emu),Trans Scan Std Dev,Trans Algorithm,Trans Reg Fit,Trans Percent Error (%),Long Moment [w/o ABS] (emu),Long Scan Std Dev [w/o ABS],Long Reg Fit [w/o ABS],Long Percent Error [w/o ABS] (%),Trans Moment [w/o ABS] (emu),Trans Scan Std Dev [w/o ABS],Trans Reg Fit [w/o ABS],Trans Percent Error [w/o ABS] (%),Points per Scan,Scans per Measurement,Scan Length (cm),Delta Temp (K),Rot Position (deg),Error,EC Comp. Running,Using ABS,
1524362099.791,,0.000000e+000,5.500037e+001,-2.028751e-005,0.000000e+000,2,9.405857e-001,0.000000e+000,,,,,,,,,,,,,,32,1,4.000000e+000,6.587982e-003,0.000000e+000,0,,0,
1524362137.621,,0.000000e+000,5.499577e+001,-1.628055e-005,0.000000e+000,2,9.199158e-001,0.000000e+000,,,,,,,,,,,,,,32,1,4.000000e+000,2.632141e-003,0.000000e+000,0,,0,
1524362175.011,,0.000000e+000,5.499774e+001,-1.433618e-005,0.000000e+000,2,9.041174e-001,0.000000e+000,,,,,,,,,,,,,,32,1,4.000000e+000,6.580353e-003,0.000000e+000,0,,0,
1524362212.911,,0.000000e+000,5.499905e+001,-1.307394e-005,0.000000e+000,2,8.989527e-001,0.000000e+000,,,,,,,,,,,,,,32,1,4.000000e+000,3.948212e-003,0.000000e+000,0,,0,
1524362251.421,,0.000000e+000,5.500168e+001,-1.210285e-005,0.000000e+000,2,8.909172e-001,0.000000e+000,,,,,,,,,,,,,,32,1,4.000000e+000,6.580353e-003,0.000000e+000,0,,0,
1524362289.211,,0.000000e+000,5.500103e+001,-1.133776e-005,0.000000e+000,2,8.764110e-001,0.000000e+000,,,,,,,,,,,,,,32,1,4.000000e+000,0.000000e+000,0.000000e+000,0,,0,
1524362327.191,,0.000000e+000,5.500235e+001,-1.072540e-005,0.000000e+000,2,8.797411e-001,0.000000e+000,,,,,,,,,,,,,,32,1,4.000000e+000,0.000000e+000,0.000000e+000,0,,0,
1524362364.761,,0.000000e+000,5.500564e+001,-1.019370e-005,0.000000e+000,2,8.642729e-001,0.000000e+000,,,,,,,,,,,,,,32,1,4.000000e+000,3.940582e-003,0.000000e+000,0,,0,
1524362402.401,,0.000000e+000,5.499840e+001,-9.704365e-006,0.000000e+000,2,8.594096e-001,0.000000e+000,,,,,,,,,,,,,,32,1,4.000000e+000,7.900238e-003,0.000000e+000,0,,0,
1524362440.901,,0.000000e+000,5.500168e+001,-9.279306e-006,0.000000e+000,2,8.537163e-001,0.000000e+000,,,,,,,,,,,,,,32,1,4.000000e+000,6.580353e-003,0.000000e+000,0,,0,
1524362478.861,,0.000000e+000,5.500366e+001,-9.006008e-006,0.000000e+000,2,8.440250e-001,0.000000e+000,,,,,,,,,,,,,,32,1,4.000000e+000,2.620697e-003,0.000000e+000,0,,0,
1524362517.011,,0.000000e+000,5.499709e+001,-8.564197e-006,0.000000e+000,2,8.325512e-001,0.000000e+000,,,,,,,,,,,,,,32,1,4.000000e+000,1.052856e-002,0.000000e+000,0,,0,
1524362554.961,,0.000000e+000,5.499971e+001,-8.266030e-006,0.000000e+000,2,8.337974e-001,0.000000e+000,,,,,,,,,,,,,,32,1,4.000000e+000,2.639771e-003,0.000000e+000,0,,0,
1524362592.561,,0.000000e+000,5.499708e+001,-7.987430e-006,0.000000e+000,2,8.208469e-001,0.000000e+000,,,,,,,,,,,,,,32,1,4.000000e+000,5.260468e-003,0.000000e+000,0,,0,
1524362630.511,,0.000000e+000,5.499905e+001,-7.704025e-006,0.000000e+000,2,8.176078e-001,0.000000e+000,,,,,,,,,,,,,,32,1,4.000000e+000,1.319885e-003,0.000000e+000,0,,0,
1524362668.481,,0.000000e+000,5.499906e+001,-7.516803e-006,0.000000e+000,2,8.096998e-001,0.000000e+000,,,,,,,,,,,,,,32,1,4.000000e+000,6.580353e-003,0.000000e+000,0,,0,
1524362706.362,,0.000000e+000,5.499709e+001,-7.212123e-006,0.000000e+000,2,7.993718e-001,0.000000e+000,,,,,,,,,,,,,,32,1,4.000000e+000,1.316071e-002,0.000000e+000,0,,0,
1524362743.872,,0.000000e+000,5.500234e+001,-7.093719e-006,0.000000e+000,2,7.995238e-001,0.000000e+000,,,,,,,,,,,,,,32,1,4.000000e+000,7.900238e-003,0.000000e+000,0,,0,
1524362782.622,,0.000000e+000,5.499773e+001,-6.809857e-006,0.000000e+000,2,7.788740e-001,0.000000e+000,,,,,,,,,,,,,,32,1,4.000000e+000,1.308441e-003,0.000000e+000,0,,0,
1524362821.302,,0.000000e+000,5.500103e+001,-6.608155e-006,0.000000e+000,2,7.886401e-001,0.000000e+000,,,,,,,,,,,,,,32,1,4.000000e+000,7.888794e-003,0.000000e+000,0,,0,
1524362859.372,,0.000000e+000,5.500103e+001,-6.417871e-006,0.000000e+000,2,7.842487e-001,0.000000e+000,,,,,,,,,,,,,,32,1,4.000000e+000,5.279541e-003,0.000000e+000,0,,0,
1524362896.792,,0.000000e+000,5.499643e+001,-6.267836e-006,0.000000e+000,2,7.652979e-001,0.000000e+000,,,,,,,,,,,,,,32,1,4.000000e+000,1.312256e-003,0.000000e+000,0,,0,
1524362935.622,,0.000000e+000,5.500037e+001,-6.081719e-006,0.000000e+000,2,7.626307e-001,0.000000e+000,,,,,,,,,,,,,,32,1,4.000000e+000,3.959656e-003,0.000000e+000,0,,0,
1524362974.112,,0.000000e+000,5.500037e+001,-5.956503e-006,0.000000e+000,2,7.686802e-001,0.000000e+000,,,,,,,,,,,,,,32,1,4.000000e+000,1.319885e-003,0.000000e+000,0,,0,
1524363013.012,,0.000000e+000,5.500037e+001,-5.749349e-006,0.000000e+000,2,7.609718e-001,0.000000e+000,,,,,,,,,,,,,,32,1,4.000000e+000,1.319885e-003,0.000000e+000,0,,0,
1524363050.512,,0.000000e+000,5.499642e+001,-5.563923e-006,0.000000e+000,2,7.405970e-001,0.000000e+000,,,,,,,,,,,,,,32,1,4.000000e+000,3.940582e-003,0.000000e+000,0,,0,
1524363088.502,,0.000000e+000,5.499511e+001,-5.513235e-006,0.000000e+000,2,7.440239e-001,0.000000e+000,,,,,,,,,,,,,,32,1,4.000000e+000,1.319885e-003,0.000000e+000,0,,0,
1524363126.082,,0.000000e+000,5.499840e+001,-5.353719e-006,0.000000e+000,2,7.231495e-001,0.000000e+000,,,,,,,,,,,,,,32,1,4.000000e+000,5.260468e-003,0.000000e+000,0,,0,
1524363164.132,,0.000000e+000,5.499577e+001,-5.269162e-006,0.000000e+000,2,7.337247e-001,0.000000e+000,,,,,,,,,,,,,,32,1,4.000000e+000,2.632141e-003,0.000000e+000,0,,0,
1524363201.742,,0.000000e+000,5.500037e+001,-5.156923e-006,0.000000e+000,2,7.180049e-001,0.000000e+000,,,,,,,,,,,,,,32,1,4.000000e+000,3.959656e-003,0.000000e+000,0,,0,
1524363239.772,,0.000000e+000,5.499775e+001,-4.994759e-006,0.000000e+000,2,7.188612e-001,0.000000e+000,,,,,,,,,,,,,,32,1,4.000000e+000,9.208679e-003,0.000000e+000,0,,0,
1524363276.992,,0.000000e+000,5.499773e+001,-4.875878e-006,0.000000e+000,2,6.988239e-001,0.000000e+000,,,,,,,,,,,,,,32,1,4.000000e+000,1.308441e-003,0.000000e+000,0,,0,
1524363314.442,,0.000000e+000,5.499380e+001,-4.809641e-006,0.000000e+000,2,7.154447e-001,0.000000e+000,,,,,,,,,,,,,,32,1,4.000000e+000,6.572723e-003,0.000000e+000,0,,0,
1524363351.672,,0.000000e+000,5.499577e+001,-4.764557e-006,0.000000e+000,2,6.875861e-001,0.000000e+000,,,,,,,,,,,,,,32,1,4.000000e+000,0.000000e+000,0.000000e+000,0,,0,
1524363389.872,,0.000000e+000,5.499773e+001,-4.559847e-006,0.000000e+000,2,6.793876e-001,0.000000e+000,,,,,,,,,,,,,,32,1,4.000000e+000,1.308441e-003,0.000000e+000,0,,0,
1524363427.883,,0.000000e+000,5.499708e+001,-4.477870e-006,0.000000e+000,2,6.873150e-001,0.000000e+000,,,,,,,,,,,,,,32,1,4.000000e+000,1.578140e-002,0.000000e+000,0,,0,
1524363465.433,,0.000000e+000,5.499773e+001,-4.408134e-006,0.000000e+000,2,6.722063e-001,0.000000e+000,,,,,,,,,,,,,,32,1,4.000000e+000,1.308441e-003,0.000000e+000,0,,0,
1524363502.643,,0.000000e+000,5.499774e+001,-4.289856e-006,0.000000e+000,2,6.847944e-001,0.000000e+000,,,,,,,,,,,,,,32,1,4.000000e+000,3.940582e-003,0.000000e+000,0,,0,
1524363540.353,,0.000000e+000,5.499445e+001,-4.232753e-006,0.000000e+000,2,6.558461e-001,0.000000e+000,,,,,,,,,,,,,,32,1,4.000000e+000,0.000000e+000,0.000000e+000,0,,0,
1524363578.253,,0.000000e+000,5.499708e+001,-4.103509e-006,0.000000e+000,2,6.432749e-001,0.000000e+000,,,,,,,,,,,,,,32,1,4.000000e+000,5.260468e-003,0.000000e+000,0,,0,
1524363615.653,,0.000000e+000,5.499708e+001,-4.001204e-006,0.000000e+000,2,6.583562e-001,0.000000e+000,,,,,,,,,,,,,,32,1,4.000000e+000,2.620697e-003,0.000000e+000,0,,0,
1524363653.103,,0.000000e+000,5.499840e+001,-3.952496e-006,0.000000e+000,2,6.322197e-001,0.000000e+000,,,,,,,,,,,,,,32,1,4.000000e+000,5.260468e-003,0.000000e+000,0,,0,
1524363691.043,,0.000000e+000,5.499642e+001,-3.858435e-006,0.000000e+000,2,6.262599e-001,0.000000e+000,,,,,,,,,,,,,,32,1,4.000000e+000,3.940582e-003,0.000000e+000,0,,0,
1524363728.923,,0.000000e+000,5.500169e+001,-3.856459e-006,0.000000e+000,2,6.447510e-001,0.000000e+000,,,,,,,,,,,,,,32,1,4.000000e+000,9.208679e-003,0.000000e+000,0,,0,
1524363766.523,,0.000000e+000,5.499773e+001,-3.721803e-006,0.000000e+000,2,5.919253e-001,0.000000e+000,,,,,,,,,,,,,,32,1,4.000000e+000,1.308441e-003,0.000000e+000,0,,0,
1524363804.593,,0.000000e+000,5.500037e+001,-3.652030e-006,0.000000e+000,2,6.245804e-001,0.000000e+000,,,,,,,,,,,,,,32,1,4.000000e+000,9.201050e-003,0.000000e+000,0,,0,
1524363842.373,,0.000000e+000,5.499971e+001,-3.592969e-006,0.000000e+000,2,5.905013e-001,0.000000e+000,,,,,,,,,,,,,,32,1,4.000000e+000,0.000000e+000,0.000000e+000,0,,0,
1524363880.343,,0.000000e+000,5.499182e+001,-3.501875e-006,0.000000e+000,2,5.981165e-001,0.000000e+000,,,,,,,,,,,,,,32,1,4.000000e+000,5.260468e-003,0.000000e+000,0,,0,
1524363917.933,,0.000000e+000,5.499577e+001,-3.407380e-006,0.000000e+000,2,5.772040e-001,0.000000e+000,,,,,,,,,,,,,,32,1,4.000000e+000,5.249023e-003,0.000000e+000,0,,0,
1524363955.943,,0.000000e+000,5.499708e+001,-3.387860e-006,0.000000e+000,2,6.045154e-001,0.000000e+000,,,,,,,,,,,,,,32,1,4.000000e+000,2.620697e-003,0.000000e+000,0,,0,
1524363993.553,,0.000000e+000,5.499511e+001,-3.329082e-006,0.000000e+000,2,5.659428e-001,0.000000e+000,,,,,,,,,,,,,,32,1,4.000000e+000,1.184082e-002,0.000000e+000,0,,0,
1524364031.543,,0.000000e+000,5.499577e+001,-3.258689e-006,0.000000e+000,2,5.729148e-001,0.000000e+000,,,,,,,,,,,,,,32,1,4.000000e+000,2.632141e-003,0.000000e+000,0,,0,
1524364069.173,,0.000000e+000,5.499643e+001,-3.148131e-006,0.000000e+000,2,5.355159e-001,0.000000e+000,,,,,,,,,,,,,,32,1,4.000000e+000,1.312256e-003,0.000000e+000,0,,0,
1524364107.104,,0.000000e+000,5.499840e+001,-3.072357e-006,0.000000e+000,2,5.424209e-001,0.000000e+000,,,,,,,,,,,,,,32,1,4.000000e+000,7.900238e-003,0.000000e+000,0,,0,
1524364145.034,,0.000000e+000,5.499773e+001,-3.082460e-006,0.000000e+000,2,5.243589e-001,0.000000e+000,,,,,,,,,,,,,,32,1,4.000000e+000,1.308441e-003,0.000000e+000,0,,0,
1524364182.214,,0.000000e+000,5.500037e+001,-3.045069e-006,0.000000e+000,2,5.293605e-001,0.000000e+000,,,,,,,,,,,,,,32,1,4.000000e+000,1.319885e-003,0.000000e+000,0,,0,
1524364220.124,,0.000000e+000,5.499708e+001,-2.921085e-006,0.000000e+000,2,4.880542e-001,0.000000e+000,,,,,,,,,,,,,,32,1,4.000000e+000,5.260468e-003,0.000000e+000,0,,0,
1524364258.374,,0.000000e+000,5.500037e+001,-2.852967e-006,0.000000e+000,2,5.046076e-001,0.000000e+000,,,,,,,,,,,,,,32,1,4.000000e+000,3.959656e-003,0.000000e+000,0,,0,
1524364295.234,,0.000000e+000,5.499906e+001,-2.855014e-006,0.000000e+000,2,4.656980e-001,0.000000e+000,,,,,,,,,,,,,,32,1,4.000000e+000,9.220123e-003,0.000000e+000,0,,0,
1524364332.914,,0.000000e+000,5.500234e+001,-2.788484e-006,0.000000e+000,2,4.928019e-001,0.000000e+000,,,,,,,,,,,,,,32,1,4.000000e+000,5.260468e-003,0.000000e+000,0,,0,
1524364370.274,,0.000000e+000,5.500037e+001,-2.741366e-006,0.000000e+000,2,4.538628e-001,0.000000e+000,,,,,,,,,,,,,,32,1,4.000000e+000,1.319885e-003,0.000000e+000,0,,0,
1524364408.574,,0.000000e+000,5.499971e+001,-2.656783e-006,0.000000e+000,2,4.703644e-001,0.000000e+000,,,,,,,,,,,,,,32,1,4.000000e+000,2.639771e-003,0.000000e+000,0,,0,
1524364446.884,,0.000000e+000,5.500234e+001,-2.611560e-006,0.000000e+000,2,4.602825e-001,0.000000e+000,,,,,,,,,,,,,,32,1,4.000000e+000,5.260468e-003,0.000000e+000,0,,0,
1524364484.004,,0.000000e+000,5.499774e+001,-2.526544e-006,0.000000e+000,2,4.167839e-001,0.000000e+000,,,,,,,,,,,,,,32,1,4.000000e+000,3.940582e-003,0.000000e+000,0,,0,
1524364521.964,,0.000000e+000,5.499971e+001,-2.535767e-006,0.000000e+000,2,4.483113e-001,0.000000e+000,,,,,,,,,,,,,,32,1,4.000000e+000,2.639771e-003,0.000000e+000,0,,0,
1524364559.564,,0.000000e+000,5.499905e+001,-2.484230e-006,0.000000e+000,2,4.102554e-001,0.000000e+000,,,,,,,,,,,,,,32,1,4.000000e+000,1.319885e-003,0.000000e+000,0,,0,
1524364597.564,,0.000000e+000,5.499906e+001,-2.421388e-006,0.000000e+000,2,4.232009e-001,0.000000e+000,,,,,,,,,,,,,,32,1,4.000000e+000,6.580353e-003,0.000000e+000,0,,0,
1524364634.664,,0.000000e+000,5.500431e+001,-2.327433e-006,0.000000e+000,2,3.778728e-001,0.000000e+000,,,,,,,,,,,,,,32,1,4.000000e+000,9.208679e-003,0.000000e+000,0,,0,
1524364672.664,,0.000000e+000,5.499511e+001,-2.288757e-006,0.000000e+000,2,3.828250e-001,0.000000e+000,,,,,,,,,,,,,,32,1,4.000000e+000,1.319885e-003,0.000000e+000,0,,0,
1524364710.294,,0.000000e+000,5.499972e+001,-2.284606e-006,0.000000e+000,2,3.654759e-001,0.000000e+000,,,,,,,,,,,,,,32,1,4.000000e+000,5.268097e-003,0.000000e+000,0,,0,
1524364748.244,,0.000000e+000,5.499971e+001,-2.209892e-006,0.000000e+000,2,3.755991e-001,0.000000e+000,,,,,,,,,,,,,,32,1,4.000000e+000,2.639771e-003,0.000000e+000,0,,0,
1524364785.584,,0.000000e+000,5.500301e+001,-2.212895e-006,0.000000e+000,2,3.214004e-001,0.000000e+000,,,,,,,,,,,,,,32,1,4.000000e+000,1.319885e-003,0.000000e+000,0,,0,
1524364823.315,,0.000000e+000,5.500037e+001,-2.154520e-006,0.000000e+000,2,3.535094e-001,0.000000e+000,,,,,,,,,,,,,,32,1,4.000000e+000,1.319885e-003,0.000000e+000,0,,0,
1524364860.465,,0.000000e+000,5.499774e+001,-2.092541e-006,0.000000e+000,2,2.940085e-001,0.000000e+000,,,,,,,,,,,,,,32,1,4.000000e+000,3.940582e-003,0.000000e+000,0,,0,
1524364898.375,,0.000000e+000,5.500300e+001,-2.065810e-006,0.000000e+000,2,3.043266e-001,0.000000e+000,,,,,,,,,,,,,,32,1,4.000000e+000,9.220123e-003,0.000000e+000,0,,0,
1524364936.215,,0.000000e+000,5.499511e+001,-2.075528e-006,0.000000e+000,2,2.749749e-001,0.000000e+000,,,,,,,,,,,,,,32,1,4.000000e+000,1.319885e-003,0.000000e+000,0,,0,
1524364974.365,,0.000000e+000,5.499642e+001,-1.977716e-006,0.000000e+000,2,2.744498e-001,0.000000e+000,,,,,,,,,,,,,,32,1,4.000000e+000,3.940582e-003,0.000000e+000,0,,0,
1524365012.295,,0.000000e+000,5.499445e+001,-1.966570e-006,0.000000e+000,2,2.786323e-001,0.000000e+000,,,,,,,,,,,,,,32,1,4.000000e+000,0.000000e+000,0.000000e+000,0,,0,
1524365050.115,,0.000000e+000,5.499840e+001,-1.931344e-006,0.000000e+000,2,2.484039e-001,0.000000e+000,,,,,,,,,,,,,,32,1,4.000000e+000,2.628326e-003,0.000000e+000,0,,0,
1524365087.965,,0.000000e+000,5.499445e+001,-1.894882e-006,0.000000e+000,2,2.448507e-001,0.000000e+000,,,,,,,,,,,,,,32,1,4.000000e+000,2.628326e-003,0.000000e+000,0,,0,
1524365125.775,,0.000000e+000,5.500037e+001,-1.862290e-006,0.000000e+000,2,1.838231e-001,0.000000e+000,,,,,,,,,,,,,,32,1,4.000000e+000,1.319885e-003,0.000000e+000,0,,0,
1524365163.675,,0.000000e+000,5.499971e+001,-1.816542e-006,0.000000e+000,2,2.174825e-001,0.000000e+000,,,,,,,,,,,,,,32,1,4.000000e+000,0.000000e+000,0.000000e+000,0,,0,
1524365201.635,,0.000000e+000,5.499773e+001,-1.906774e-006,0.000000e+000,2,2.711994e-001,0.000000e+000,,,,,,,,,,,,,,32,1,4.000000e+000,1.308441e-003,0.000000e+000,0,,0,
1524365240.155,,0.000000e+000,5.499905e+001,-1.678480e-006,0.000000e+000,2,8.969016e-002,0.000000e+000,,,,,,,,,,,,,,32,1,4.000000e+000,3.948212e-003,0.000000e+000,0,,0,
1524365277.465,,0.000000e+000,5.499511e+001,-1.704150e-006,0.000000e+000,2,1.902552e-001,0.000000e+000,,,,,,,,,,,,,,32,1,4.000000e+000,3.940582e-003,0.000000e+000,0,,0,
1524365315.115,,0.000000e+000,5.499840e+001,-1.663432e-006,0.000000e+000,2,1.245356e-001,0.000000e+000,,,,,,,,,,,,,,32,1,4.000000e+000,2.628326e-003,0.000000e+000,0,,0,
1524365352.885,,0.000000e+000,5.500234e+001,-1.632544e-006,0.000000e+000,2,1.182794e-001,0.000000e+000,,,,,,,,,,,,,,32,1,4.000000e+000,5.260468e-003,0.000000e+000,0,,0,
1524365390.625,,0.000000e+000,5.500169e+001,-1.597142e-006,0.000000e+000,2,9.866150e-002,0.000000e+000,,,,,,,,,,,,,,32,1,4.000000e+000,9.208679e-003,0.000000e+000,0,,0,
1524365428.845,,0.000000e+000,5.500037e+001,-1.582634e-006,0.000000e+000,2,1.160298e-001,0.000000e+000,,,,,,,,,,,,,,32,1,4.000000e+000,3.959656e-003,0.000000e+000,0,,0,
1524365466.275,,0.000000e+000,5.499972e+001,-1.529085e-006,0.000000e+000,2,1.152934e-003,0.000000e+000,,,,,,,,,,,,,,32,1,4.000000e+000,5.268097e-003,0.000000e+000,0,,0,
1524365503.905,,0.000000e+000,5.499905e+001,-1.499480e-006,0.000000e+000,2,5.269077e-002,0.000000e+000,,,,,,,,,,,,,,32,1,4.000000e+000,3.948212e-003,0.000000e+000,0,,0,
1524365541.856,,0.000000e+000,5.499708e+001,-1.504486e-006,0.000000e+000,2,4.115614e-002,0.000000e+000,,,,,,,,,,,,,,32,1,4.000000e+000,0.000000e+000,0.000000e+000,0,,0,
1524365580.296,,0.000000e+000,5.499840e+001,-1.449654e-006,0.000000e+000,2,0.000000e+000,0.000000e+000,,,,,,,,,,,,,,32,1,4.000000e+000,2.628326e-003,0.000000e+000,0,,0,
1524365617.686,,0.000000e+000,5.499971e+001,-1.411325e-006,0.000000e+000,2,2.452224e-002,0.000000e+000,,,,,,,,,,,,,,32,1,4.000000e+000,0.000000e+000,0.000000e+000,0,,0,
1524365655.596,,0.000000e+000,5.499643e+001,-1.324563e-006,0.000000e+000,2,0.000000e+000,0.000000e+000,,,,,,,,,,,,,,32,1,4.000000e+000,6.568909e-003,0.000000e+000,0,,0,
1524365693.296,,0.000000e+000,5.499906e+001,-1.320291e-006,0.000000e+000,2,0.000000e+000,0.000000e+000,,,,,,,,,,,,,,32,1,4.000000e+000,6.580353e-003,0.000000e+000,0,,0,
1524365731.406,,0.000000e+000,5.499905e+001,-1.381822e-006,0.000000e+000,2,0.000000e+000,0.000000e+000,,,,,,,,,,,,,,32,1,4.000000e+000,1.319885e-003,0.000000e+000,0,,0,
1524365769.756,,0.000000e+000,5.500037e+001,-1.314068e-006,0.000000e+000,2,0.000000e+000,0.000000e+000,,,,,,,,,,,,,,32,1,4.000000e+000,1.709747e-002,0.000000e+000,0,,0,
1524365808.106,,0.000000e+000,5.500564e+001,-1.237298e-006,0.000000e+000,2,0.000000e+000,0.000000e+000,,,,,,,,,,,,,,32,1,4.000000e+000,3.940582e-003,0.000000e+000,0,,0,
1524365846.166,,0.000000e+000,5.499708e+001,-1.231595e-006,0.000000e+000,2,0.000000e+000,0.000000e+000,,,,,,,,,,,,,,32,1,4.000000e+000,2.620697e-003,0.000000e+000,0,,0,
1524365883.606,,0.000000e+000,5.499971e+001,-1.155660e-006,0.000000e+000,2,0.000000e+000,0.000000e+000,,,,,,,,,,,,,,32,1,4.000000e+000,2.639771e-003,0.000000e+000,0,,0,
1524365920.976,,0.000000e+000,5.500103e+001,-1.171827e-006,0.000000e+000,2,0.000000e+000,0.000000e+000,,,,,,,,,,,,,,32,1,4.000000e+000,5.279541e-003,0.000000e+000,0,,0,
1524365959.486,,0.000000e+000,5.500037e+001,-1.154807e-006,0.000000e+000,2,0.000000e+000,0.000000e+000,,,,,,,,,,,,,,32,1,4.000000e+000,9.201050e-003,0.000000e+000,0,,0,
1524365997.116,,0.000000e+000,5.499709e+001,-1.075706e-006,0.000000e+000,2,0.000000e+000,0.000000e+000,,,,,,,,,,,,,,32,1,4.000000e+000,1.052856e-002,0.000000e+000,0,,0,
1524366035.136,,0.000000e+000,5.499905e+001,-1.071520e-006,0.000000e+000,2,0.000000e+000,0.000000e+000,,,,,,,,,,,,,,32,1,4.000000e+000,1.319885e-003,0.000000e+000,0,,0,
1524366072.876,,0.000000e+000,5.499642e+001,-1.038752e-006,0.000000e+000,2,0.000000e+000,0.000000e+000,,,,,,,,,,,,,,32,1,4.000000e+000,3.940582e-003,0.000000e+000,0,,0,
1524366110.766,,0.000000e+000,5.499905e+001,-1.004570e-006,0.000000e+000,2,0.000000e+000,0.000000e+000,,,,,,,,,,,,,,32,1,4.000000e+000,3.948212e-003,0.000000e+000,0,,0,
1524366147.916,,0.000000e+000,5.500629e+001,-9.593157e-007,0.000000e+000,2,0.000000e+000,0.000000e+000,,,,,,,,,,,,,,32,1,4.000000e+000,1.052094e-002,0.000000e+000,0,,0,
1524366185.826,,0.000000e+000,5.500563e+001,-9.620105e-007,0.000000e+000,2,0.000000e+000,0.000000e+000,,,,,,,,,,,,,,32,1,4.000000e+000,1.319885e-003,0.000000e+000,0,,0,
1524366224.166,,0.000000e+000,5.499709e+001,-9.731813e-007,0.000000e+000,2,0.000000e+000,0.000000e+000,,,,,,,,,,,,,,32,1,4.000000e+000,1.316071e-002,0.000000e+000,0,,0,
1524366261.767,,0.000000e+000,5.499117e+001,-8.777175e-007,0.000000e+000,2,0.000000e+000,0.000000e+000,,,,,,,,,,,,,,32,1,4.000000e+000,1.312256e-003,0.000000e+000,0,,0,
1524366299.647,,0.000000e+000,5.499971e+001,-8.219624e-007,0.000000e+000,2,0.000000e+000,0.000000e+000,,,,,,,,,,,,,,32,1,4.000000e+000,2.639771e-003,0.000000e+000,0,,0,
1524366337.707,,0.000000e+000,5.499313e+001,-8.932246e-007,0.000000e+000,2,0.000000e+000,0.000000e+000,,,,,,,,,,,,,,32,1,4.000000e+000,7.892609e-003,0.000000e+000,0,,0,
1524366374.967,,0.000000e+000,5.499905e+001,-8.314631e-007,0.000000e+000,2,0.000000e+000,0.000000e+000,,,,,,,,,,,,,,32,1,4.000000e+000,3.948212e-003,0.000000e+000,0,,0,
1524366413.257,,0.000000e+000,5.499577e+001,-9.080592e-007,0.000000e+000,2,0.000000e+000,0.000000e+000,,,,,,,,,,,,,,32,1,4.000000e+000,2.632141e-003,0.000000e+000,0,,0,
1524366450.367,,0.000000e+000,5.499643e+001,-7.956321e-007,0.000000e+000,2,0.000000e+000,0.000000e+000,,,,,,,,,,,,,,32,1,4.000000e+000,1.312256e-003,0.000000e+000,0,,0,
1524366487.207,,0.000000e+000,5.500629e+001,-7.397940e-007,0.000000e+000,2,0.000000e+000,0.000000e+000,,,,,,,,,,,,,,32,1,4.000000e+000,1.052094e-002,0.000000e+000,0,,0,
1524366525.617,,0.000000e+000,5.499905e+001,-7.560109e-007,0.000000e+000,2,0.000000e+000,0.000000e+000,,,,,,,,,,,,,,32,1,4.000000e+000,1.182938e-002,0.000000e+000,0,,0,
1524366563.577,,0.000000e+000,5.500365e+001,-7.670250e-007,0.000000e+000,2,0.000000e+000,0.000000e+000,,,,,,,,,,,,,,32,1,4.000000e+000,1.052856e-002,0.000000e+000,0,,0,
1524366601.557,,0.000000e+000,5.499708e+001,-7.083290e-007,0.000000e+000,2,0.000000e+000,0.000000e+000,,,,,,,,,,,,,,32,1,4.000000e+000,2.620697e-003,0.000000e+000,0,,0,
1524366639.417,,0.000000e+000,5.499972e+001,-6.380727e-007,0.000000e+000,2,0.000000e+000,0.000000e+000,,,,,,,,,,,,,,32,1,4.000000e+000,7.900238e-003,0.000000e+000,0,,0,
1524366676.497,,0.000000e+000,5.499643e+001,-6.913913e-007,0.000000e+000,2,0.000000e+000,0.000000e+000,,,,,,,,,,,,,,32,1,4.000000e+000,1.312256e-003,0.000000e+000,0,,0,
1524366714.697,,0.000000e+000,5.499840e+001,-6.421128e-007,0.000000e+000,2,0.000000e+000,0.000000e+000,,,,,,,,,,,,,,32,1,4.000000e+000,7.900238e-003,0.000000e+000,0,,0,
1524366753.507,,0.000000e+000,5.500168e+001,-6.577700e-007,0.000000e+000,2,0.000000e+000,0.000000e+000,,,,,,,,,,,,,,32,1,4.000000e+000,6.580353e-003,0.000000e+000,0,,0,
1524366791.027,,0.000000e+000,5.499708e+001,-6.003564e-007,0.000000e+000,2,0.000000e+000,0.000000e+000,,,,,,,,,,,,,,32,1,4.000000e+000,2.620697e-003,0.000000e+000,0,,0,
1524366829.007,,0.000000e+000,5.499840e+001,-5.940180e-007,0.000000e+000,2,0.000000e+000,0.000000e+000,,,,,,,,,,,,,,32,1,4.000000e+000,7.900238e-003,0.000000e+000,0,,0,
1524366866.647,,0.000000e+000,5.499577e+001,-5.406877e-007,0.000000e+000,2,0.000000e+000,0.000000e+000,,,,,,,,,,,,,,32,1,4.000000e+000,2.632141e-003,0.000000e+000,0,,0,
1524366904.487,,0.000000e+000,5.499839e+001,-5.863121e-007,0.000000e+000,2,0.000000e+000,0.000000e+000,,,,,,,,,,,,,,32,1,4.000000e+000,0.000000e+000,0.000000e+000,0,,0,
1524366942.247,,0.000000e+000,5.499577e+001,-5.275393e-007,0.000000e+000,2,0.000000e+000,0.000000e+000,,,,,,,,,,,,,,32,1,4.000000e+000,1.052094e-002,0.000000e+000,0,,0,
1524366980.228,,0.000000e+000,5.499905e+001,-5.013604e-007,0.000000e+000,2,0.000000e+000,0.000000e+000,,,,,,,,,,,,,,32,1,4.000000e+000,1.319885e-003,0.000000e+000,0,,0,
1524367018.178,,0.000000e+000,5.499971e+001,-5.232850e-007,0.000000e+000,2,0.000000e+000,0.000000e+000,,,,,,,,,,,,,,32,1,4.000000e+000,2.639771e-003,0.000000e+000,0,,0,
1524367056.198,,0.000000e+000,5.499774e+001,-4.379271e-007,0.000000e+000,2,0.000000e+000,0.000000e+000,,,,,,,,,,,,,,32,1,4.000000e+000,3.940582e-003,0.000000e+000,0,,0,
1524367094.198,,0.000000e+000,5.499905e+001,-4.445104e-007,0.000000e+000,2,0.000000e+000,0.000000e+000,,,,,,,,,,,,,,32,1,4.000000e+000,1.319885e-003,0.000000e+000,0,,0,
1524367131.258,,0.000000e+000,5.499773e+001,-4.112395e-007,0.000000e+000,2,0.000000e+000,0.000000e+000,,,,,,,,,,,,,,32,1,4.000000e+000,1.308441e-003,0.000000e+000,0,,0,
1524367168.668,,0.000000e+000,5.499839e+001,-4.123943e-007,0.000000e+000,2,0.000000e+000,0.000000e+000,,,,,,,,,,,,,,32,1,4.000000e+000,0.000000e+000,0.000000e+000,0,,0,
1524367206.318,,0.000000e+000,5.500103e+001,-3.830401e-007,0.000000e+000,2,0.000000e+000,0.000000e+000,,,,,,,,,,,,,,32,1,4.000000e+000,7.888794e-003,0.000000e+000,0,,0,
1524367243.728,,0.000000e+000,5.500300e+001,-3.555101e-007,0.000000e+000,2,0.000000e+000,0.000000e+000,,,,,,,,,,,,,,32,1,4.000000e+000,1.183701e-002,0.000000e+000,0,,0,
1524367281.328,,0.000000e+000,5.500103e+001,-3.284971e-007,0.000000e+000,2,0.000000e+000,0.000000e+000,,,,,,,,,,,,,,32,1,4.000000e+000,2.639771e-003,0.000000e+000,0,,0,
1524367319.328,,0.000000e+000,5.499971e+001,-3.497383e-007,0.000000e+000,2,0.000000e+000,0.000000e+000,,,,,,,,,,,,,,32,1,4.000000e+000,2.639771e-003,0.000000e+000,0,,0,
1524367357.058,,0.000000e+000,5.499642e+001,-3.086312e-007,0.000000e+000,2,0.000000e+000,0.000000e+000,,,,,,,,,,,,,,32,1,4.000000e+000,3.940582e-003,0.000000e+000,0,,0,
1524367394.988,,0.000000e+000,5.499511e+001,-3.128897e-007,0.000000e+000,2,0.000000e+000,0.000000e+000,,,,,,,,,,,,,,32,1,4.000000e+000,3.940582e-003,0.000000e+000,0,,0,
1524367432.518,,0.000000e+000,5.500037e+001,-3.142202e-007,0.000000e+000,2,0.000000e+000,0.000000e+000,,,,,,,,,,,,,,32,1,4.000000e+000,9.201050e-003,0.000000e+000,0,,0,
1524367470.528,,0.000000e+000,5.499971e+001,-2.566690e-007,0.000000e+000,2,0.000000e+000,0.000000e+000,,,,,,,,,,,,,,32,1,4.000000e+000,0.000000e+000,0.000000e+000,0,,0,
1524367508.218,,0.000000e+000,5.500037e+001,-2.065520e-007,0.000000e+000,2,0.000000e+000,0.000000e+000,,,,,,,,,,,,,,32,1,4.000000e+000,6.587982e-003,0.000000e+000,0,,0,
1524367546.118,,0.000000e+000,5.500169e+001,-3.376910e-007,0.000000e+000,2,0.000000e+000,0.000000e+000,,,,,,,,,,,,,,32,1,4.000000e+000,1.184082e-002,0.000000e+000,0,,0,
1524367583.448,,0.000000e+000,5.499708e+001,-2.267147e-007,0.000000e+000,2,0.000000e+000,0.000000e+000,,,,,,,,,,,,,,32,1,4.000000e+000,0.000000e+000,0.000000e+000,0,,0,
1524367621.798,,0.000000e+000,5.499840e+001,-1.950386e-007,0.000000e+000,2,0.000000e+000,0.000000e+000,,,,,,,,,,,,,,32,1,4.000000e+000,2.628326e-003,0.000000e+000,0,,0,
1524367658.648,,0.000000e+000,5.499971e+001,-1.518996e-007,0.000000e+000,2,0.000000e+000,0.000000e+000,,,,,,,,,,,,,,32,1,4.000000e+000,2.639771e-003,0.000000e+000,0,,0,
1524367696.309,,0.000000e+000,5.499445e+001,-1.607152e-007,0.000000e+000,2,0.000000e+000,0.000000e+000,,,,,,,,,,,,,,32,1,4.000000e+000,7.881165e-003,0.000000e+000,0,,0,
1524367734.209,,0.000000e+000,5.499840e+001,-1.957826e-007,0.000000e+000,2,0.000000e+000,0.000000e+000,,,,,,,,,,,,,,32,1,4.000000e+000,5.260468e-003,0.000000e+000,0,,0,
1524367772.359,,0.000000e+000,5.499839e+001,-1.728342e-007,0.000000e+000,2,0.000000e+000,0.000000e+000,,,,,,,,,,,,,,32,1,4.000000e+000,0.000000e+000,0.000000e+000,0,,0,
1524367810.249,,0.000000e+000,5.499905e+001,-1.187881e-007,0.000000e+000,2,0.000000e+000,0.000000e+000,,,,,,,,,,,,,,32,1,4.000000e+000,1.319885e-003,0.000000e+000,0,,0,
1524367847.579,,0.000000e+000,5.499511e+001,-1.889294e-007,0.000000e+000,2,0.000000e+000,0.000000e+000,,,,,,,,,,,,,,32,1,4.000000e+000,9.201050e-003,0.000000e+000,0,,0,
1524367886.629,,0.000000e+000,5.499708e+001,-1.111484e-007,0.000000e+000,2,0.000000e+000,0.000000e+000,,,,,,,,,,,,,,32,1,4.000000e+000,0.000000e+000,0.000000e+000,0,,0,
1524367924.489,,0.000000e+000,5.500234e+001,-8.538741e-008,0.000000e+000,2,0.000000e+000,0.000000e+000,,,,,,,,,,,,,,32,1,4.000000e+000,1.314926e-002,0.000000e+000,0,,0,
1524367963.019,,0.000000e+000,5.500300e+001,-6.458279e-008,0.000000e+000,2,0.000000e+000,0.000000e+000,,,,,,,,,,,,,,32,1,4.000000e+000,3.940582e-003,0.000000e+000,0,,0,
1524368000.829,,0.000000e+000,5.499577e+001,-1.478476e-007,0.000000e+000,2,0.000000e+000,0.000000e+000,,,,,,,,,,,,,,32,1,4.000000e+000,5.249023e-003,0.000000e+000,0,,0,
1524368038.689,,0.000000e+000,5.499643e+001,-2.084042e-008,0.000000e+000,2,0.000000e+000,0.000000e+000,,,,,,,,,,,,,,32,1,4.000000e+000,1.312256e-003,0.000000e+000,0,,0,
1524368076.309,,0.000000e+000,5.500037e+001,4.708808e-009,0.000000e+000,2,0.000000e+000,0.000000e+000,,,,,,,,,,,,,,32,1,4.000000e+000,3.959656e-003,0.000000e+000,0,,0,
1524368114.269,,0.000000e+000,5.500300e+001,9.567771e-009,0.000000e+000,2,0.000000e+000,0.000000e+000,,,,,,,,,,,,,,32,1,4.000000e+000,6.580353e-003,0.000000e+000,0,,0,
1524368151.899,,0.000000e+000,5.500103e+001,3.137705e-008,0.000000e+000,2,0.000000e+000,0.000000e+000,,,,,,,,,,,,,,32,1,4.000000e+000,5.279541e-003,0.000000e+000,0,,0,
1524368189.899,,0.000000e+000,5.500103e+001,-3.381465e-009,0.000000e+000,2,0.000000e+000,0.000000e+000,,,,,,,,,,,,,,32,1,4.000000e+000,5.279541e-003,0.000000e+000,0,,0,
1524368227.139,,0.000000e+000,5.499775e+001,5.701852e-008,0.000000e+000,2,0.000000e+000,0.000000e+000,,,,,,,,,,,,,,32,1,4.000000e+000,1.972961e-002,0.000000e+000,0,,0,
1524368264.959,,0.000000e+000,5.499577e+001,5.948404e-008,0.000000e+000,2,0.000000e+000,0.000000e+000,,,,,,,,,,,,,,32,1,4.000000e+000,2.632141e-003,0.000000e+000,0,,0,
1524368302.569,,0.000000e+000,5.500037e+001,8.717556e-008,0.000000e+000,2,0.000000e+000,0.000000e+000,,,,,,,,,,,,,,32,1,4.000000e+000,1.319885e-003,0.000000e+000,0,,0,
1524368340.699,,0.000000e+000,5.499906e+001,3.267794e-008,0.000000e+000,2,0.000000e+000,0.000000e+000,,,,,,,,,,,,,,32,1,4.000000e+000,6.580353e-003,0.000000e+000,0,,0,
1524368378.509,,0.000000e+000,5.499709e+001,6.505687e-008,0.000000e+000,2,0.000000e+000,0.000000e+000,,,,,,,,,,,,,,32,1,4.000000e+000,1.316071e-002,0.000000e+000,0,,0,
1524368416.480,,0.000000e+000,5.499313e+001,9.732976e-008,0.000000e+000,2,0.000000e+000,0.000000e+000,,,,,,,,,,,,,,32,1,4.000000e+000,1.050949e-002,0.000000e+000,0,,0,
1524368454.300,,0.000000e+000,5.500037e+001,4.589071e-008,0.000000e+000,2,0.000000e+000,0.000000e+000,,,,,,,,,,,,,,32,1,4.000000e+000,1.319885e-003,0.000000e+000,0,,0,
1524368492.470,,0.000000e+000,5.499577e+001,1.088409e-007,0.000000e+000,2,0.000000e+000,0.000000e+000,,,,,,,,,,,,,,32,1,4.000000e+000,5.249023e-003,0.000000e+000,0,,0,
1524368530.170,,0.000000e+000,5.499905e+001,1.394392e-007,0.000000e+000,2,0.000000e+000,0.000000e+000,,,,,,,,,,,,,,32,1,4.000000e+000,1.319885e-003,0.000000e+000,0,,0,
1524368568.400,,0.000000e+000,5.500103e+001,1.319526e-007,0.000000e+000,2,0.000000e+000,0.000000e+000,,,,,,,,,,,,,,32,1,4.000000e+000,2.639771e-003,0.000000e+000,0,,0,
1524368606.310,,0.000000e+000,5.500037e+001,1.635942e-007,0.000000e+000,2,0.000000e+000,0.000000e+000,,,,,,,,,,,,,,32,1,4.000000e+000,3.959656e-003,0.000000e+000,0,,0,
1524368643.160,,0.000000e+000,5.499839e+001,1.961756e-007,0.000000e+000,2,0.000000e+000,0.000000e+000,,,,,,,,,,,,,,32,1,4.000000e+000,0.000000e+000,0.000000e+000,0,,0,
1524368680.430,,0.000000e+000,5.500037e+001,1.529048e-007,0.000000e+000,2,0.000000e+000,0.000000e+000,,,,,,,,,,,,,,32,1,4.000000e+000,6.587982e-003,0.000000e+000,0,,0,
1524368718.460,,0.000000e+000,5.499971e+001,1.895638e-007,0.000000e+000,2,0.000000e+000,0.000000e+000,,,,,,,,,,,,,,32,1,4.000000e+000,0.000000e+000,0.000000e+000,0,,0,
1524368755.820,,0.000000e+000,5.499511e+001,2.339536e-007,0.000000e+000,2,0.000000e+000,0.000000e+000,,,,,,,,,,,,,,32,1,4.000000e+000,6.568909e-003,0.000000e+000,0,,0,
1524368793.680,,0.000000e+000,5.499577e+001,2.288651e-007,0.000000e+000,2,0.000000e+000,0.000000e+000,,,,,,,,,,,,,,32,1,4.000000e+000,1.052094e-002,0.000000e+000,0,,0,
1524368831.870,,0.000000e+000,5.499905e+001,2.982174e-007,0.000000e+000,2,0.000000e+000,0.000000e+000,,,,,,,,,,,,,,32,1,4.000000e+000,3.948212e-003,0.000000e+000,0,,0,
1524368869.970,,0.000000e+000,5.500629e+001,2.777448e-007,0.000000e+000,2,0.000000e+000,0.000000e+000,,,,,,,,,,,,,,32,1,4.000000e+000,1.580048e-002,0.000000e+000,0,,0,
1524368908.260,,0.000000e+000,5.500629e+001,2.894033e-007,0.000000e+000,2,0.000000e+000,0.000000e+000,,,,,,,,,,,,,,32,1,4.000000e+000,2.639771e-003,0.000000e+000,0,,0,
1524368945.730,,0.000000e+000,5.499708e+001,2.745071e-007,0.000000e+000,2,0.000000e+000,0.000000e+000,,,,,,,,,,,,,,32,1,4.000000e+000,0.000000e+000,0.000000e+000,0,,0,
1524368983.390,,0.000000e+000,5.499840e+001,2.912687e-007,0.000000e+000,2,0.000000e+000,0.000000e+000,,,,,,,,,,,,,,32,1,4.000000e+000,2.628326e-003,0.000000e+000,0,,0,
1524369021.310,,0.000000e+000,5.499511e+001,2.739101e-007,0.000000e+000,2,0.000000e+000,0.000000e+000,,,,,,,,,,,,,,32,1,4.000000e+000,3.940582e-003,0.000000e+000,0,,0,
1524369059.430,,0.000000e+000,5.499380e+001,3.469132e-007,0.000000e+000,2,0.000000e+000,0.000000e+000,,,,,,,,,,,,,,32,1,4.000000e+000,1.308441e-003,0.000000e+000,0,,0,
1524369097.650,,0.000000e+000,5.499971e+001,4.059699e-007,0.000000e+000,2,0.000000e+000,0.000000e+000,,,,,,,,,,,,,,32,1,4.000000e+000,2.639771e-003,0.000000e+000,0,,0,
1524369135.581,,0.000000e+000,5.499775e+001,3.935505e-007,0.000000e+000,2,0.000000e+000,0.000000e+000,,,,,,,,,,,,,,32,1,4.000000e+000,9.208679e-003,0.000000e+000,0,,0,
1524369173.621,,0.000000e+000,5.499840e+001,3.334257e-007,0.000000e+000,2,0.000000e+000,0.000000e+000,,,,,,,,,,,,,,32,1,4.000000e+000,5.260468e-003,0.000000e+000,0,,0,
1524369211.831,,0.000000e+000,5.499248e+001,3.261857e-007,0.000000e+000,2,0.000000e+000,0.000000e+000,,,,,,,,,,,,,,32,1,4.000000e+000,3.940582e-003,0.000000e+000,0,,0,
1524369249.861,,0.000000e+000,5.499708e+001,3.473573e-007,0.000000e+000,2,0.000000e+000,0.000000e+000,,,,,,,,,,,,,,32,1,4.000000e+000,5.260468e-003,0.000000e+000,0,,0,
1524369287.131,,0.000000e+000,5.500234e+001,4.026252e-007,0.000000e+000,2,0.000000e+000,0.000000e+000,,,,,,,,,,,,,,32,1,4.000000e+000,7.900238e-003,0.000000e+000,0,,0,
1524369324.841,,0.000000e+000,5.499313e+001,3.647898e-007,0.000000e+000,2,0.000000e+000,0.000000e+000,,,,,,,,,,,,,,32,1,4.000000e+000,1.314926e-002,0.000000e+000,0,,0,
1524369363.361,,0.000000e+000,5.499905e+001,4.220682e-007,0.000000e+000,2,0.000000e+000,0.000000e+000,,,,,,,,,,,,,,32,1,4.000000e+000,3.948212e-003,0.000000e+000,0,,0,
1524369401.201,,0.000000e+000,5.500366e+001,4.800674e-007,0.000000e+000,2,0.000000e+000,0.000000e+000,,,,,,,,,,,,,,32,1,4.000000e+000,5.260468e-003,0.000000e+000,0,,0,
1524369438.321,,0.000000e+000,5.499905e+001,4.835546e-007,0.000000e+000,2,0.000000e+000,0.000000e+000,,,,,,,,,,,,,,32,1,4.000000e+000,3.948212e-003,0.000000e+000,0,,0,
1524369476.291,,0.000000e+000,5.499643e+001,4.684563e-007,0.000000e+000,2,0.000000e+000,0.000000e+000,,,,,,,,,,,,,,32,1,4.000000e+000,1.312256e-003,0.000000e+000,0,,0,
1524369513.931,,0.000000e+000,5.499642e+001,5.049910e-007,0.000000e+000,2,0.000000e+000,0.000000e+000,,,,,,,,,,,,,,32,1,4.000000e+000,3.940582e-003,0.000000e+000,0,,0,
1524369551.881,,0.000000e+000,5.499577e+001,5.095122e-007,0.000000e+000,2,0.000000e+000,0.000000e+000,,,,,,,,,,,,,,32,1,4.000000e+000,2.632141e-003,0.000000e+000,0,,0,
1524369589.531,,0.000000e+000,5.499905e+001,4.582464e-007,0.000000e+000,2,0.000000e+000,0.000000e+000,,,,,,,,,,,,,,32,1,4.000000e+000,3.948212e-003,0.000000e+000,0,,0,
1524369626.761,,0.000000e+000,5.499643e+001,5.574178e-007,0.000000e+000,2,0.000000e+000,0.000000e+000,,,,,,,,,,,,,,32,1,4.000000e+000,6.568909e-003,0.000000e+000,0,,0,
1524369664.831,,0.000000e+000,5.499708e+001,4.761819e-007,0.000000e+000,2,0.000000e+000,0.000000e+000,,,,,,,,,,,,,,32,1,4.000000e+000,2.620697e-003,0.000000e+000,0,,0,
1524369701.521,,0.000000e+000,5.500037e+001,5.827678e-007,0.000000e+000,2,0.000000e+000,0.000000e+000,,,,,,,,,,,,,,32,1,4.000000e+000,6.587982e-003,0.000000e+000,0,,0,
1524369739.281,,0.000000e+000,5.499577e+001,5.537224e-007,0.000000e+000,2,0.000000e+000,0.000000e+000,,,,,,,,,,,,,,32,1,4.000000e+000,2.632141e-003,0.000000e+000,0,,0,
1524369776.231,,0.000000e+000,5.500235e+001,5.465051e-007,0.000000e+000,2,0.000000e+000,0.000000e+000,,,,,,,,,,,,,,32,1,4.000000e+000,2.639771e-003,0.000000e+000,0,,0,
1524369814.411,,0.000000e+000,5.499445e+001,4.815393e-007,0.000000e+000,2,0.000000e+000,0.000000e+000,,,,,,,,,,,,,,32,1,4.000000e+000,2.628326e-003,0.000000e+000,0,,0,
1524369851.702,,0.000000e+000,5.500103e+001,5.799272e-007,0.000000e+000,2,0.000000e+000,0.000000e+000,,,,,,,,,,,,,,32,1,4.000000e+000,7.888794e-003,0.000000e+000,0,,0,
1524369889.492,,0.000000e+000,5.499773e+001,5.361230e-007,0.000000e+000,2,0.000000e+000,0.000000e+000,,,,,,,,,,,,,,32,1,4.000000e+000,1.308441e-003,0.000000e+000,0,,0,
1524369927.312,,0.000000e+000,5.499840e+001,5.839981e-007,0.000000e+000,2,0.000000e+000,0.000000e+000,,,,,,,,,,,,,,32,1,4.000000e+000,2.628326e-003,0.000000e+000,0,,0,
1524369964.452,,0.000000e+000,5.500168e+001,5.424107e-007,0.000000e+000,2,0.000000e+000,0.000000e+000,,,,,,,,,,,,,,32,1,4.000000e+000,6.580353e-003,0.000000e+000,0,,0,
1524370002.252,,0.000000e+000,5.500234e+001,6.145813e-007,0.000000e+000,2,0.000000e+000,0.000000e+000,,,,,,,,,,,,,,32,1,4.000000e+000,5.260468e-003,0.000000e+000,0,,0,
1524370040.082,,0.000000e+000,5.499445e+001,5.840579e-007,0.000000e+000,2,0.000000e+000,0.000000e+000,,,,,,,,,,,,,,32,1,4.000000e+000,2.628326e-003,0.000000e+000,0,,0,
1524370077.992,,0.000000e+000,5.499577e+001,6.585670e-007,0.000000e+000,2,0.000000e+000,0.000000e+000,,,,,,,,,,,,,,32,1,4.000000e+000,7.888794e-003,0.000000e+000,0,,0,
1524370115.172,,0.000000e+000,5.500103e+001,5.932435e-007,0.000000e+000,2,0.000000e+000,0.000000e+000,,,,,,,,,,,,,,32,1,4.000000e+000,1.316071e-002,0.000000e+000,0,,0,
1524370153.792,,0.000000e+000,5.499380e+001,6.998000e-007,0.000000e+000,2,0.000000e+000,0.000000e+000,,,,,,,,,,,,,,32,1,4.000000e+000,3.948212e-003,0.000000e+000,0,,0,
1524370191.812,,0.000000e+000,5.499643e+001,6.317287e-007,0.000000e+000,2,0.000000e+000,0.000000e+000,,,,,,,,,,,,,,32,1,4.000000e+000,1.312256e-003,0.000000e+000,0,,0,
1524370229.402,,0.000000e+000,5.499774e+001,7.097004e-007,0.000000e+000,2,0.000000e+000,0.000000e+000,,,,,,,,,,,,,,32,1,4.000000e+000,6.580353e-003,0.000000e+000,0,,0,
1524370267.362,,0.000000e+000,5.499511e+001,7.071181e-007,0.000000e+000,2,0.000000e+000,0.000000e+000,,,,,,,,,,,,,,32,1,4.000000e+000,1.319885e-003,0.000000e+000,0,,0,
1524370304.952,,0.000000e+000,5.500103e+001,7.326693e-007,0.000000e+000,2,0.000000e+000,0.000000e+000,,,,,,,,,,,,,,32,1,4.000000e+000,2.639771e-003,0.000000e+000,0,,0,
1524370343.002,,0.000000e+000,5.499445e+001,6.354593e-007,0.000000e+000,2,0.000000e+000,0.000000e+000,,,,,,,,,,,,,,32,1,4.000000e+000,7.881165e-003,0.000000e+000,0,,0,
1524370380.582,,0.000000e+000,5.499709e+001,7.160290e-007,0.000000e+000,2,0.000000e+000,0.000000e+000,,,,,,,,,,,,,,32,1,4.000000e+000,7.888794e-003,0.000000e+000,0,,0,
1524370418.562,,0.000000e+000,5.499905e+001,6.953119e-007,0.000000e+000,2,0.000000e+000,0.000000e+000,,,,,,,,,,,,,,32,1,4.000000e+000,1.319885e-003,0.000000e+000,0,,0,
1524370456.182,,0.000000e+000,5.499905e+001,7.486000e-007,0.000000e+000,2,0.000000e+000,0.000000e+000,,,,,,,,,,,,,,32,1,4.000000e+000,1.319885e-003,0.000000e+000,0,,0,
1524370494.192,,0.000000e+000,5.499643e+001,7.397521e-007,0.000000e+000,2,0.000000e+000,0.000000e+000,,,,,,,,,,,,,,32,1,4.000000e+000,1.312256e-003,0.000000e+000,0,,0,
1524370531.712,,0.000000e+000,5.499313e+001,7.285301e-007,0.000000e+000,2,0.000000e+000,0.000000e+000,,,,,,,,,,,,,,32,1,4.000000e+000,7.892609e-003,0.000000e+000,0,,0,
1524370569.373,,0.000000e+000,5.499971e+001,7.291013e-007,0.000000e+000,2,0.000000e+000,0.000000e+000,,,,,,,,,,,,,,32,1,4.000000e+000,2.639771e-003,0.000000e+000,0,,0,
1524370607.353,,0.000000e+000,5.499971e+001,7.621899e-007,0.000000e+000,2,0.000000e+000,0.000000e+000,,,,,,,,,,,,,,32,1,4.000000e+000,2.639771e-003,0.000000e+000,0,,0,
1524370645.743,,0.000000e+000,5.499840e+001,7.567979e-007,0.000000e+000,2,0.000000e+000,0.000000e+000,,,,,,,,,,,,,,32,1,4.000000e+000,2.628326e-003,0.000000e+000,0,,0,
1524370683.673,,0.000000e+000,5.499840e+001,8.224554e-007,0.000000e+000,2,0.000000e+000,0.000000e+000,,,,,,,,,,,,,,32,1,4.000000e+000,2.628326e-003,0.000000e+000,0,,0,
1524370721.293,,0.000000e+000,5.499839e+001,8.126035e-007,0.000000e+000,2,0.000000e+000,0.000000e+000,,,,,,,,,,,,,,32,1,4.000000e+000,0.000000e+000,0.000000e+000,0,,0,
1524370759.203,,0.000000e+000,5.499577e+001,7.687651e-007,0.000000e+000,2,0.000000e+000,0.000000e+000,,,,,,,,,,,,,,32,1,4.000000e+000,2.632141e-003,0.000000e+000,0,,0,
1524370796.643,,0.000000e+000,5.500958e+001,8.546904e-007,0.000000e+000,2,0.000000e+000,0.000000e+000,,,,,,,,,,,,,,32,1,4.000000e+000,9.220123e-003,0.000000e+000,0,,0,
1524370834.403,,0.000000e+000,5.499773e+001,9.348618e-007,0.000000e+000,2,0.000000e+000,0.000000e+000,,,,,,,,,,,,,,32,1,4.000000e+000,1.308441e-003,0.000000e+000,0,,0,
1524370872.653,,0.000000e+000,5.499905e+001,8.670570e-007,0.000000e+000,2,0.000000e+000,0.000000e+000,,,,,,,,,,,,,,32,1,4.000000e+000,1.319885e-003,0.000000e+000,0,,0,
1524370910.293,,0.000000e+000,5.500103e+001,8.628400e-007,0.000000e+000,2,0.000000e+000,0.000000e+000,,,,,,,,,,,,,,32,1,4.000000e+000,0.000000e+000,0.000000e+000,0,,0,
1524370948.203,,0.000000e+000,5.499577e+001,8.455463e-007,0.000000e+000,2,0.000000e+000,0.000000e+000,,,,,,,,,,,,,,32,1,4.000000e+000,5.249023e-003,0.000000e+000,0,,0,
1524370985.913,,0.000000e+000,5.500037e+001,8.711340e-007,0.000000e+000,2,0.000000e+000,0.000000e+000,,,,,,,,,,,,,,32,1,4.000000e+000,6.587982e-003,0.000000e+000,0,,0,
1524371024.023,,0.000000e+000,5.499643e+001,8.637209e-007,0.000000e+000,2,0.000000e+000,0.000000e+000,,,,,,,,,,,,,,32,1,4.000000e+000,6.568909e-003,0.000000e+000,0,,0,
1524371062.163,,0.000000e+000,5.500103e+001,9.090509e-007,0.000000e+000,2,0.000000e+000,0.000000e+000,,,,,,,,,,,,,,32,1,4.000000e+000,0.000000e+000,0.000000e+000,0,,0,
1524371099.753,,0.000000e+000,5.499774e+001,8.893198e-007,0.000000e+000,2,0.000000e+000,0.000000e+000,,,,,,,,,,,,,,32,1,4.000000e+000,6.580353e-003,0.000000e+000,0,,0,
1524371137.963,,0.000000e+000,5.500169e+001,8.039042e-007,0.000000e+000,2,0.000000e+000,0.000000e+000,,,,,,,,,,,,,,32,1,4.000000e+000,3.959656e-003,0.000000e+000,0,,0,
1524371175.043,,0.000000e+000,5.500037e+001,8.011854e-007,0.000000e+000,2,0.000000e+000,0.000000e+000,,,,,,,,,,,,,,32,1,4.000000e+000,3.959656e-003,0.000000e+000,0,,0,
1524371212.263,,0.000000e+000,5.499971e+001,9.095768e-007,0.000000e+000,2,0.000000e+000,0.000000e+000,,,,,,,,,,,,,,32,1,4.000000e+000,0.000000e+000,0.000000e+000,0,,0,
1524371249.624,,0.000000e+000,5.499774e+001,8.550228e-007,0.000000e+000,2,0.000000e+000,0.000000e+000,,,,,,,,,,,,,,32,1,4.000000e+000,3.940582e-003,0.000000e+000,0,,0,
1524371287.994,,0.000000e+000,5.499905e+001,8.950061e-007,0.000000e+000,2,0.000000e+000,0.000000e+000,,,,,,,,,,,,,,32,1,4.000000e+000,1.319885e-003,0.000000e+000,0,,0,
1524371325.944,,0.000000e+000,5.500563e+001,8.757284e-007,0.000000e+000,2,0.000000e+000,0.000000e+000,,,,,,,,,,,,,,32,1,4.000000e+000,1.319885e-003,0.000000e+000,0,,0,
1524371363.284,,0.000000e+000,5.499577e+001,9.033539e-007,0.000000e+000,2,0.000000e+000,0.000000e+000,,,,,,,,,,,,,,32,1,4.000000e+000,7.888794e-003,0.000000e+000,0,,0,
1524371401.324,,0.000000e+000,5.500300e+001,8.503610e-007,0.000000e+000,2,0.000000e+000,0.000000e+000,,,,,,,,,,,,,,32,1,4.000000e+000,3.940582e-003,0.000000e+000,0,,0,
1524371438.764,,0.000000e+000,5.500432e+001,9.612639e-007,0.000000e+000,2,0.000000e+000,0.000000e+000,,,,,,,,,,,,,,32,1,4.000000e+000,1.300812e-003,0.000000e+000,0,,0,
1524371477.354,,0.000000e+000,5.499971e+001,9.503821e-007,0.000000e+000,2,0.000000e+000,0.000000e+000,,,,,,,,,,,,,,32,1,4.000000e+000,2.639771e-003,0.000000e+000,0,,0,
1524371514.954,,0.000000e+000,5.500103e+001,9.374746e-007,0.000000e+000,2,0.000000e+000,0.000000e+000,,,,,,,,,,,,,,32,1,4.000000e+000,0.000000e+000,0.000000e+000,0,,0,
1524371552.424,,0.000000e+000,5.500366e+001,9.092241e-007,0.000000e+000,2,0.000000e+000,0.000000e+000,,,,,,,,,,,,,,32,1,4.000000e+000,2.620697e-003,0.000000e+000,0,,0,
1524371590.134,,0.000000e+000,5.499840e+001,9.711255e-007,0.000000e+000,2,0.000000e+000,0.000000e+000,,,,,,,,,,,,,,32,1,4.000000e+000,5.260468e-003,0.000000e+000,0,,0,
1524371628.784,,0.000000e+000,5.499773e+001,9.850838e-007,0.000000e+000,2,0.000000e+000,0.000000e+000,,,,,,,,,,,,,,32,1,4.000000e+000,1.308441e-003,0.000000e+000,0,,0,
1524371666.574,,0.000000e+000,5.499511e+001,9.480142e-007,0.000000e+000,2,0.000000e+000,0.000000e+000,,,,,,,,,,,,,,32,1,4.000000e+000,1.319885e-003,0.000000e+000,0,,0,
1524371704.354,,0.000000e+000,5.499708e+001,9.723540e-007,0.000000e+000,2,0.000000e+000,0.000000e+000,,,,,,,,,,,,,,32,1,4.000000e+000,2.620697e-003,0.000000e+000,0,,0,
1524371741.944,,0.000000e+000,5.499708e+001,1.031142e-006,0.000000e+000,2,0.000000e+000,0.000000e+000,,,,,,,,,,,,,,32,1,4.000000e+000,0.000000e+000,0.000000e+000,0,,0,
1524371779.224,,0.000000e+000,5.499971e+001,1.004921e-006,0.000000e+000,2,0.000000e+000,0.000000e+000,,,,,,,,,,,,,,32,1,4.000000e+000,0.000000e+000,0.000000e+000,0,,0,
1524371816.994,,0.000000e+000,5.500103e+001,1.070373e-006,0.000000e+000,2,0.000000e+000,0.000000e+000,,,,,,,,,,,,,,32,1,4.000000e+000,2.639771e-003,0.000000e+000,0,,0,
1524371854.624,,0.000000e+000,5.500169e+001,1.042442e-006,0.000000e+000,2,0.000000e+000,0.000000e+000,,,,,,,,,,,,,,32,1,4.000000e+000,1.319885e-003,0.000000e+000,0,,0,
1524371892.574,,0.000000e+000,5.500037e+001,1.050336e-006,0.000000e+000,2,0.000000e+000,0.000000e+000,,,,,,,,,,,,,,32,1,4.000000e+000,3.959656e-003,0.000000e+000,0,,0,
1524371930.224,,0.000000e+000,5.499972e+001,1.063066e-006,0.000000e+000,2,0.000000e+000,0.000000e+000,,,,,,,,,,,,,,32,1,4.000000e+000,5.268097e-003,0.000000e+000,0,,0,
1524371968.145,,0.000000e+000,5.500301e+001,1.079751e-006,0.000000e+000,2,0.000000e+000,0.000000e+000,,,,,,,,,,,,,,32,1,4.000000e+000,1.319885e-003,0.000000e+000,0,,0,
1524372005.845,,0.000000e+000,5.499839e+001,1.030289e-006,0.000000e+000,2,0.000000e+000,0.000000e+000,,,,,,,,,,,,,,32,1,4.000000e+000,0.000000e+000,0.000000e+000,0,,0,
1524372043.555,,0.000000e+000,5.499445e+001,1.081397e-006,0.000000e+000,2,0.000000e+000,0.000000e+000,,,,,,,,,,,,,,32,1,4.000000e+000,2.628326e-003,0.000000e+000,0,,0,
1524372080.665,,0.000000e+000,5.499840e+001,1.045274e-006,0.000000e+000,2,0.000000e+000,0.000000e+000,,,,,,,,,,,,,,32,1,4.000000e+000,5.260468e-003,0.000000e+000,0,,0,
1524372118.275,,0.000000e+000,5.499905e+001,1.097416e-006,0.000000e+000,2,0.000000e+000,0.000000e+000,,,,,,,,,,,,,,32,1,4.000000e+000,3.948212e-003,0.000000e+000,0,,0,
1524372155.895,,0.000000e+000,5.499841e+001,1.095364e-006,0.000000e+000,2,0.000000e+000,0.000000e+000,,,,,,,,,,,,,,32,1,4.000000e+000,1.052856e-002,0.000000e+000,0,,0,
1524372193.865,,0.000000e+000,5.499577e+001,1.074769e-006,0.000000e+000,2,0.000000e+000,0.000000e+000,,,,,,,,,,,,,,32,1,4.000000e+000,0.000000e+000,0.000000e+000,0,,0,
1524372231.565,,0.000000e+000,5.499773e+001,1.093415e-006,0.000000e+000,2,0.000000e+000,0.000000e+000,,,,,,,,,,,,,,32,1,4.000000e+000,1.308441e-003,0.000000e+000,0,,0,
1524372269.395,,0.000000e+000,5.499773e+001,1.114160e-006,0.000000e+000,2,0.000000e+000,0.000000e+000,,,,,,,,,,,,,,32,1,4.000000e+000,1.308441e-003,0.000000e+000,0,,0,
1524372307.645,,0.000000e+000,5.500037e+001,1.155343e-006,0.000000e+000,2,0.000000e+000,0.000000e+000,,,,,,,,,,,,,,32,1,4.000000e+000,1.319885e-003,0.000000e+000,0,,0,
1524372345.395,,0.000000e+000,5.499577e+001,1.140236e-006,0.000000e+000,2,0.000000e+000,0.000000e+000,,,,,,,,,,,,,,32,1,4.000000e+000,0.000000e+000,0.000000e+000,0,,0,
1524372383.355,,0.000000e+000,5.499971e+001,1.164597e-006,0.000000e+000,2,0.000000e+000,0.000000e+000,,,,,,,,,,,,,,32,1,4.000000e+000,0.000000e+000,0.000000e+000,0,,0,
1524372421.015,,0.000000e+000,5.499905e+001,1.135784e-006,0.000000e+000,2,0.000000e+000,0.000000e+000,,,,,,,,,,,,,,32,1,4.000000e+000,1.319885e-003,0.000000e+000,0,,0,
1524372458.965,,0.000000e+000,5.500103e+001,1.079099e-006,0.000000e+000,2,0.000000e+000,0.000000e+000,,,,,,,,,,,,,,32,1,4.000000e+000,2.639771e-003,0.000000e+000,0,,0,
1524372496.575,,0.000000e+000,5.499905e+001,1.210683e-006,0.000000e+000,2,0.000000e+000,0.000000e+000,,,,,,,,,,,,,,32,1,4.000000e+000,1.319885e-003,0.000000e+000,0,,0,
1524372534.585,,0.000000e+000,5.499905e+001,1.163719e-006,0.000000e+000,2,0.000000e+000,0.000000e+000,,,,,,,,,,,,,,32,1,4.000000e+000,1.319885e-003,0.000000e+000,0,,0,
1524372572.205,,0.000000e+000,5.499905e+001,1.125907e-006,0.000000e+000,2,0.000000e+000,0.000000e+000,,,,,,,,,,,,,,32,1,4.000000e+000,3.948212e-003,0.000000e+000,0,,0,
1524372610.235,,0.000000e+000,5.499511e+001,1.166259e-006,0.000000e+000,2,0.000000e+000,0.000000e+000,,,,,,,,,,,,,,32,1,4.000000e+000,1.319885e-003,0.000000e+000,0,,0,
1524372648.495,,0.000000e+000,5.500366e+001,1.160534e-006,0.000000e+000,2,0.000000e+000,0.000000e+000,,,,,,,,,,,,,,32,1,4.000000e+000,5.260468e-003,0.000000e+000,0,,0,
1524372686.046,,0.000000e+000,5.499380e+001,1.202121e-006,0.000000e+000,2,0.000000e+000,0.000000e+000,,,,,,,,,,,,,,32,1,4.000000e+000,1.308441e-003,0.000000e+000,0,,0,
1524372724.066,,0.000000e+000,5.500301e+001,1.230022e-006,0.000000e+000,2,0.000000e+000,0.000000e+000,,,,,,,,,,,,,,32,1,4.000000e+000,1.319885e-003,0.000000e+000,0,,0,
1524372762.376,,0.000000e+000,5.499577e+001,1.178229e-006,0.000000e+000,2,0.000000e+000,0.000000e+000,,,,,,,,,,,,,,32,1,4.000000e+000,5.249023e-003,0.000000e+000,0,,0,
1524372800.116,,0.000000e+000,5.499051e+001,1.204446e-006,0.000000e+000,2,0.000000e+000,0.000000e+000,,,,,,,,,,,,,,32,1,4.000000e+000,1.052094e-002,0.000000e+000,0,,0,
1524372812.986,,0.000000e+000,5.499511e+001,1.172659e-006,0.000000e+000,2,0.000000e+000,0.000000e+000,,,,,,,,,,,,,,32,1,4.000000e+000,1.319885e-003,0.000000e+000,0,,0,