File: Experimental Raw Data/TC04-12-01K VRMac VRMde/TC04-12-01K_VRMac_55K_750s_VRMde_55Klinear.dc.dat
[Header]
TITLE,MPMS DC Measurement
BYAPP,MPMS Measurement,2.1,Summary
FILEOPENTIME, 1524341592.168000 4/21/2018, 2:13:12 PM

INFO, APPNAME, MPMS MultiVu Application, Revision 1.61,  Build 082

INFO, NAME, TC04-12-01K
INFO, WEIGHT, 1.000
INFO, AREA, 1.000
INFO, LENGTH, 1.000
INFO, SHAPE, 0
INFO, COMMENT,
INFO, SEQUENCE FILE: VRMac_55K_750s_VRMde_55Klinear.seq


INFO, BACKGROUND DATA FILE:, None


STARTUPAXIS,X,4,LINEAR,AUTO,0.000000,0.000000
STARTUPAXIS,Y1,5,LINEAR,AUTO,0.000000,0.000000


STARTUPGROUP,Longitudinal
FIELDGROUP,Longitudinal,1,2,3,4,5,6,7,8,9,15,16,17,18,27,28
FIELDGROUP,Transverse,1,2,3,4,10,11,12,13,14,19,20,21,22,27,28

PLOT_APPEARANCE,ALL,HORZ_GRID_ON,VERT_GRID_ON,MARKERS_AND_LINES

[Data]
Time,Comment,Field (Oe),Temperature (K),Long Moment (emu),Long Scan Std Dev,Long Algorithm,Long Reg Fit,Long Percent Error (%),Trans Moment (emu),Trans Scan Std Dev,Trans Algorithm,Trans Reg Fit,Trans Percent Error (%),Long Moment [w/o ABS] (emu),Long Scan Std Dev [w/o ABS],Long Reg Fit [w/o ABS],Long Percent Error [w/o ABS] (%),Trans Moment [w/o ABS] (emu),Trans Scan Std Dev [w/o ABS],Trans Reg Fit [w/o ABS],Trans Percent Error [w/o ABS] (%),Points per Scan,Scans per Measurement,Scan Length (cm),Delta Temp (K),Rot Position (deg),Error,EC Comp. Running,Using ABS,
1524341592.168,,0.000000e+000,5.500037e+001,-1.319114e-005,0.000000e+000,2,9.073421e-001,0.000000e+000,,,,,,,,,,,,,,32,1,4.000000e+000,9.201050e-003,0.000000e+000,0,,0,
1524341604.538,,0.000000e+000,5.499840e+001,-1.130881e-005,0.000000e+000,2,8.678635e-001,0.000000e+000,,,,,,,,,,,,,,32,1,4.000000e+000,7.900238e-003,0.000000e+000,0,,0,
1524341617.228,,0.000000e+000,5.499577e+001,-1.005633e-005,0.000000e+000,2,8.604081e-001,0.000000e+000,,,,,,,,,,,,,,32,1,4.000000e+000,7.888794e-003,0.000000e+000,0,,0,
1524341629.728,,0.000000e+000,5.499511e+001,-9.131824e-006,0.000000e+000,2,8.353930e-001,0.000000e+000,,,,,,,,,,,,,,32,1,4.000000e+000,9.201050e-003,0.000000e+000,0,,0,
1524341642.478,,0.000000e+000,5.499840e+001,-8.384440e-006,0.000000e+000,2,8.241059e-001,0.000000e+000,,,,,,,,,,,,,,32,1,4.000000e+000,5.260468e-003,0.000000e+000,0,,0,
1524341654.828,,0.000000e+000,5.499577e+001,-7.788967e-006,0.000000e+000,2,8.025956e-001,0.000000e+000,,,,,,,,,,,,,,32,1,4.000000e+000,5.249023e-003,0.000000e+000,0,,0,
1524341667.298,,0.000000e+000,5.499577e+001,-7.315640e-006,0.000000e+000,2,7.942679e-001,0.000000e+000,,,,,,,,,,,,,,32,1,4.000000e+000,0.000000e+000,0.000000e+000,0,,0,
1524341679.958,,0.000000e+000,5.499905e+001,-6.850939e-006,0.000000e+000,2,7.821400e-001,0.000000e+000,,,,,,,,,,,,,,32,1,4.000000e+000,1.319885e-003,0.000000e+000,0,,0,
1524341692.678,,0.000000e+000,5.500366e+001,-6.428406e-006,0.000000e+000,2,7.613282e-001,0.000000e+000,,,,,,,,,,,,,,32,1,4.000000e+000,7.900238e-003,0.000000e+000,0,,0,
1524341705.308,,0.000000e+000,5.500498e+001,-6.072810e-006,0.000000e+000,2,7.561260e-001,0.000000e+000,,,,,,,,,,,,,,32,1,4.000000e+000,5.260468e-003,0.000000e+000,0,,0,
1524341717.548,,0.000000e+000,5.500366e+001,-5.755177e-006,0.000000e+000,2,7.441726e-001,0.000000e+000,,,,,,,,,,,,,,32,1,4.000000e+000,5.260468e-003,0.000000e+000,0,,0,
1524341729.958,,0.000000e+000,5.500169e+001,-5.491915e-006,0.000000e+000,2,7.218348e-001,0.000000e+000,,,,,,,,,,,,,,32,1,4.000000e+000,1.319885e-003,0.000000e+000,0,,0,
1524341742.698,,0.000000e+000,5.498919e+001,-5.169162e-006,0.000000e+000,2,6.980491e-001,0.000000e+000,,,,,,,,,,,,,,32,1,4.000000e+000,1.840973e-002,0.000000e+000,0,,0,
1524341755.298,,0.000000e+000,5.500037e+001,-4.945462e-006,0.000000e+000,2,7.045528e-001,0.000000e+000,,,,,,,,,,,,,,32,1,4.000000e+000,3.959656e-003,0.000000e+000,0,,0,
1524341767.498,,0.000000e+000,5.499577e+001,-4.728595e-006,0.000000e+000,2,6.642333e-001,0.000000e+000,,,,,,,,,,,,,,32,1,4.000000e+000,0.000000e+000,0.000000e+000,0,,0,
1524341779.918,,0.000000e+000,5.499972e+001,-4.525672e-006,0.000000e+000,2,6.597821e-001,0.000000e+000,,,,,,,,,,,,,,32,1,4.000000e+000,2.367020e-002,0.000000e+000,0,,0,
1524341792.518,,0.000000e+000,5.499380e+001,-4.307362e-006,0.000000e+000,2,6.415137e-001,0.000000e+000,,,,,,,,,,,,,,32,1,4.000000e+000,1.182938e-002,0.000000e+000,0,,0,
1524341805.298,,0.000000e+000,5.499708e+001,-4.030642e-006,0.000000e+000,2,6.280823e-001,0.000000e+000,,,,,,,,,,,,,,32,1,4.000000e+000,5.260468e-003,0.000000e+000,0,,0,
1524341817.798,,0.000000e+000,5.499445e+001,-3.937685e-006,0.000000e+000,2,6.039450e-001,0.000000e+000,,,,,,,,,,,,,,32,1,4.000000e+000,2.628326e-003,0.000000e+000,0,,0,
1524341830.548,,0.000000e+000,5.499577e+001,-3.773861e-006,0.000000e+000,2,5.984784e-001,0.000000e+000,,,,,,,,,,,,,,32,1,4.000000e+000,5.249023e-003,0.000000e+000,0,,0,
1524341843.168,,0.000000e+000,5.500234e+001,-3.593841e-006,0.000000e+000,2,5.456640e-001,0.000000e+000,,,,,,,,,,,,,,32,1,4.000000e+000,1.314926e-002,0.000000e+000,0,,0,
1524341855.908,,0.000000e+000,5.499905e+001,-3.406585e-006,0.000000e+000,2,5.521655e-001,0.000000e+000,,,,,,,,,,,,,,32,1,4.000000e+000,1.182938e-002,0.000000e+000,0,,0,
1524341868.958,,0.000000e+000,5.500234e+001,-3.308987e-006,0.000000e+000,2,5.270185e-001,0.000000e+000,,,,,,,,,,,,,,32,1,4.000000e+000,7.900238e-003,0.000000e+000,0,,0,
1524341880.928,,0.000000e+000,5.499839e+001,-3.119296e-006,0.000000e+000,2,5.181941e-001,0.000000e+000,,,,,,,,,,,,,,32,1,4.000000e+000,0.000000e+000,0.000000e+000,0,,0,
1524341894.198,,0.000000e+000,5.499708e+001,-3.016438e-006,0.000000e+000,2,5.015129e-001,0.000000e+000,,,,,,,,,,,,,,32,1,4.000000e+000,2.620697e-003,0.000000e+000,0,,0,
1524341906.158,,0.000000e+000,5.499380e+001,-2.862122e-006,0.000000e+000,2,4.610013e-001,0.000000e+000,,,,,,,,,,,,,,32,1,4.000000e+000,3.948212e-003,0.000000e+000,0,,0,
1524341919.088,,0.000000e+000,5.499380e+001,-2.824379e-006,0.000000e+000,2,4.427437e-001,0.000000e+000,,,,,,,,,,,,,,32,1,4.000000e+000,3.948212e-003,0.000000e+000,0,,0,
1524341931.748,,0.000000e+000,5.499708e+001,-2.667646e-006,0.000000e+000,2,3.978826e-001,0.000000e+000,,,,,,,,,,,,,,32,1,4.000000e+000,2.620697e-003,0.000000e+000,0,,0,
1524341944.318,,0.000000e+000,5.500103e+001,-2.643364e-006,0.000000e+000,2,4.109308e-001,0.000000e+000,,,,,,,,,,,,,,32,1,4.000000e+000,5.279541e-003,0.000000e+000,0,,0,
1524341957.038,,0.000000e+000,5.499775e+001,-2.503888e-006,0.000000e+000,2,3.698344e-001,0.000000e+000,,,,,,,,,,,,,,32,1,4.000000e+000,1.184845e-002,0.000000e+000,0,,0,
1524341969.769,,0.000000e+000,5.499708e+001,-2.374321e-006,0.000000e+000,2,3.529844e-001,0.000000e+000,,,,,,,,,,,,,,32,1,4.000000e+000,2.620697e-003,0.000000e+000,0,,0,
1524341982.249,,0.000000e+000,5.499708e+001,-2.235445e-006,0.000000e+000,2,2.813277e-001,0.000000e+000,,,,,,,,,,,,,,32,1,4.000000e+000,2.620697e-003,0.000000e+000,0,,0,
1524341994.769,,0.000000e+000,5.499971e+001,-2.197066e-006,0.000000e+000,2,3.096559e-001,0.000000e+000,,,,,,,,,,,,,,32,1,4.000000e+000,2.639771e-003,0.000000e+000,0,,0,
1524342007.459,,0.000000e+000,5.499708e+001,-2.059325e-006,0.000000e+000,2,2.161095e-001,0.000000e+000,,,,,,,,,,,,,,32,1,4.000000e+000,5.260468e-003,0.000000e+000,0,,0,
1524342020.099,,0.000000e+000,5.500497e+001,-1.976968e-006,0.000000e+000,2,2.208664e-001,0.000000e+000,,,,,,,,,,,,,,32,1,4.000000e+000,7.888794e-003,0.000000e+000,0,,0,
1524342032.659,,0.000000e+000,5.499708e+001,-1.926029e-006,0.000000e+000,2,1.576577e-001,0.000000e+000,,,,,,,,,,,,,,32,1,4.000000e+000,0.000000e+000,0.000000e+000,0,,0,
1524342045.419,,0.000000e+000,5.499906e+001,-1.826741e-006,0.000000e+000,2,1.849768e-001,0.000000e+000,,,,,,,,,,,,,,32,1,4.000000e+000,6.580353e-003,0.000000e+000,0,,0,
1524342057.849,,0.000000e+000,5.499379e+001,-1.745029e-006,0.000000e+000,2,7.458708e-002,0.000000e+000,,,,,,,,,,,,,,32,1,4.000000e+000,9.201050e-003,0.000000e+000,0,,0,
1524342070.439,,0.000000e+000,5.499577e+001,-1.632970e-006,0.000000e+000,2,8.223015e-002,0.000000e+000,,,,,,,,,,,,,,32,1,4.000000e+000,1.578903e-002,0.000000e+000,0,,0,
1524342083.079,,0.000000e+000,5.499839e+001,-1.532933e-006,0.000000e+000,2,0.000000e+000,0.000000e+000,,,,,,,,,,,,,,32,1,4.000000e+000,0.000000e+000,0.000000e+000,0,,0,
1524342095.849,,0.000000e+000,5.499708e+001,-1.448752e-006,0.000000e+000,2,0.000000e+000,0.000000e+000,,,,,,,,,,,,,,32,1,4.000000e+000,5.260468e-003,0.000000e+000,0,,0,
1524342108.279,,0.000000e+000,5.499643e+001,-1.470112e-006,0.000000e+000,2,0.000000e+000,0.000000e+000,,,,,,,,,,,,,,32,1,4.000000e+000,6.568909e-003,0.000000e+000,0,,0,
1524342121.059,,0.000000e+000,5.499643e+001,-1.361474e-006,0.000000e+000,2,0.000000e+000,0.000000e+000,,,,,,,,,,,,,,32,1,4.000000e+000,6.568909e-003,0.000000e+000,0,,0,
1524342133.509,,0.000000e+000,5.499840e+001,-1.353109e-006,0.000000e+000,2,0.000000e+000,0.000000e+000,,,,,,,,,,,,,,32,1,4.000000e+000,5.260468e-003,0.000000e+000,0,,0,
1524342146.279,,0.000000e+000,5.499511e+001,-1.204180e-006,0.000000e+000,2,0.000000e+000,0.000000e+000,,,,,,,,,,,,,,32,1,4.000000e+000,9.201050e-003,0.000000e+000,0,,0,
1524342158.739,,0.000000e+000,5.500037e+001,-1.143030e-006,0.000000e+000,2,0.000000e+000,0.000000e+000,,,,,,,,,,,,,,32,1,4.000000e+000,1.319885e-003,0.000000e+000,0,,0,
1524342171.539,,0.000000e+000,5.499775e+001,-1.063256e-006,0.000000e+000,2,0.000000e+000,0.000000e+000,,,,,,,,,,,,,,32,1,4.000000e+000,9.208679e-003,0.000000e+000,0,,0,
1524342183.989,,0.000000e+000,5.499839e+001,-1.082670e-006,0.000000e+000,2,0.000000e+000,0.000000e+000,,,,,,,,,,,,,,32,1,4.000000e+000,0.000000e+000,0.000000e+000,0,,0,
1524342196.199,,0.000000e+000,5.499840e+001,-9.559305e-007,0.000000e+000,2,0.000000e+000,0.000000e+000,,,,,,,,,,,,,,32,1,4.000000e+000,5.260468e-003,0.000000e+000,0,,0,
1524342208.659,,0.000000e+000,5.500037e+001,-8.744541e-007,0.000000e+000,2,0.000000e+000,0.000000e+000,,,,,,,,,,,,,,32,1,4.000000e+000,3.959656e-003,0.000000e+000,0,,0,
1524342221.429,,0.000000e+000,5.499708e+001,-8.612166e-007,0.000000e+000,2,0.000000e+000,0.000000e+000,,,,,,,,,,,,,,32,1,4.000000e+000,0.000000e+000,0.000000e+000,0,,0,
1524342233.809,,0.000000e+000,5.500234e+001,-8.114661e-007,0.000000e+000,2,0.000000e+000,0.000000e+000,,,,,,,,,,,,,,32,1,4.000000e+000,5.260468e-003,0.000000e+000,0,,0,
1524342246.689,,0.000000e+000,5.499840e+001,-8.260602e-007,0.000000e+000,2,0.000000e+000,0.000000e+000,,,,,,,,,,,,,,32,1,4.000000e+000,2.628326e-003,0.000000e+000,0,,0,
1524342259.099,,0.000000e+000,5.499708e+001,-7.205537e-007,0.000000e+000,2,0.000000e+000,0.000000e+000,,,,,,,,,,,,,,32,1,4.000000e+000,2.620697e-003,0.000000e+000,0,,0,
1524342271.859,,0.000000e+000,5.499840e+001,-6.673478e-007,0.000000e+000,2,0.000000e+000,0.000000e+000,,,,,,,,,,,,,,32,1,4.000000e+000,2.628326e-003,0.000000e+000,0,,0,
1524342284.899,,0.000000e+000,5.500037e+001,-6.164349e-007,0.000000e+000,2,0.000000e+000,0.000000e+000,,,,,,,,,,,,,,32,1,4.000000e+000,1.319885e-003,0.000000e+000,0,,0,
1524342296.949,,0.000000e+000,5.499774e+001,-5.764201e-007,0.000000e+000,2,0.000000e+000,0.000000e+000,,,,,,,,,,,,,,32,1,4.000000e+000,6.580353e-003,0.000000e+000,0,,0,
1524342309.539,,0.000000e+000,5.499839e+001,-5.984998e-007,0.000000e+000,2,0.000000e+000,0.000000e+000,,,,,,,,,,,,,,32,1,4.000000e+000,0.000000e+000,0.000000e+000,0,,0,
1524342322.159,,0.000000e+000,5.499708e+001,-4.394334e-007,0.000000e+000,2,0.000000e+000,0.000000e+000,,,,,,,,,,,,,,32,1,4.000000e+000,2.620697e-003,0.000000e+000,0,,0,
1524342334.959,,0.000000e+000,5.500169e+001,-4.486188e-007,0.000000e+000,2,0.000000e+000,0.000000e+000,,,,,,,,,,,,,,32,1,4.000000e+000,1.184082e-002,0.000000e+000,0,,0,
1524342347.369,,0.000000e+000,5.500037e+001,-3.642113e-007,0.000000e+000,2,0.000000e+000,0.000000e+000,,,,,,,,,,,,,,32,1,4.000000e+000,1.319885e-003,0.000000e+000,0,,0,
1524342360.139,,0.000000e+000,5.499905e+001,-4.167787e-007,0.000000e+000,2,0.000000e+000,0.000000e+000,,,,,,,,,,,,,,32,1,4.000000e+000,1.182938e-002,0.000000e+000,0,,0,
1524342372.579,,0.000000e+000,5.500168e+001,-3.492566e-007,0.000000e+000,2,0.000000e+000,0.000000e+000,,,,,,,,,,,,,,32,1,4.000000e+000,6.580353e-003,0.000000e+000,0,,0,
1524342385.359,,0.000000e+000,5.499708e+001,-2.885527e-007,0.000000e+000,2,0.000000e+000,0.000000e+000,,,,,,,,,,,,,,32,1,4.000000e+000,2.620697e-003,0.000000e+000,0,,0,
1524342397.739,,0.000000e+000,5.499380e+001,-2.618805e-007,0.000000e+000,2,0.000000e+000,0.000000e+000,,,,,,,,,,,,,,32,1,4.000000e+000,6.572723e-003,0.000000e+000,0,,0,
1524342410.569,,0.000000e+000,5.499380e+001,-1.747877e-007,0.000000e+000,2,0.000000e+000,0.000000e+000,,,,,,,,,,,,,,32,1,4.000000e+000,1.446915e-002,0.000000e+000,0,,0,
1524342423.069,,0.000000e+000,5.499972e+001,-1.610425e-007,0.000000e+000,2,0.000000e+000,0.000000e+000,,,,,,,,,,,,,,32,1,4.000000e+000,5.268097e-003,0.000000e+000,0,,0,
1524342435.849,,0.000000e+000,5.499840e+001,-1.805281e-007,0.000000e+000,2,0.000000e+000,0.000000e+000,,,,,,,,,,,,,,32,1,4.000000e+000,2.628326e-003,0.000000e+000,0,,0,
1524342448.109,,0.000000e+000,5.500103e+001,-7.194841e-008,0.000000e+000,2,0.000000e+000,0.000000e+000,,,,,,,,,,,,,,32,1,4.000000e+000,7.888794e-003,0.000000e+000,0,,0,
1524342460.999,,0.000000e+000,5.500169e+001,-1.284909e-008,0.000000e+000,2,0.000000e+000,0.000000e+000,,,,,,,,,,,,,,32,1,4.000000e+000,1.319885e-003,0.000000e+000,0,,0,
1524342473.189,,0.000000e+000,5.499774e+001,-5.937299e-009,0.000000e+000,2,0.000000e+000,0.000000e+000,,,,,,,,,,,,,,32,1,4.000000e+000,3.940582e-003,0.000000e+000,0,,0,
1524342485.739,,0.000000e+000,5.500103e+001,2.026413e-008,0.000000e+000,2,0.000000e+000,0.000000e+000,,,,,,,,,,,,,,32,1,4.000000e+000,2.639771e-003,0.000000e+000,0,,0,
1524342498.219,,0.000000e+000,5.499774e+001,3.251198e-008,0.000000e+000,2,0.000000e+000,0.000000e+000,,,,,,,,,,,,,,32,1,4.000000e+000,3.940582e-003,0.000000e+000,0,,0,
1524342510.939,,0.000000e+000,5.499708e+001,7.186981e-008,0.000000e+000,2,0.000000e+000,0.000000e+000,,,,,,,,,,,,,,32,1,4.000000e+000,0.000000e+000,0.000000e+000,0,,0,
1524342523.419,,0.000000e+000,5.499905e+001,1.890949e-007,0.000000e+000,2,0.000000e+000,0.000000e+000,,,,,,,,,,,,,,32,1,4.000000e+000,1.319885e-003,0.000000e+000,0,,0,
1524342536.199,,0.000000e+000,5.499906e+001,1.751575e-007,0.000000e+000,2,0.000000e+000,0.000000e+000,,,,,,,,,,,,,,32,1,4.000000e+000,6.580353e-003,0.000000e+000,0,,0,
1524342548.639,,0.000000e+000,5.500103e+001,1.625068e-007,0.000000e+000,2,0.000000e+000,0.000000e+000,,,,,,,,,,,,,,32,1,4.000000e+000,2.639771e-003,0.000000e+000,0,,0,
1524342561.419,,0.000000e+000,5.500037e+001,1.735421e-007,0.000000e+000,2,0.000000e+000,0.000000e+000,,,,,,,,,,,,,,32,1,4.000000e+000,3.959656e-003,0.000000e+000,0,,0,
1524342573.849,,0.000000e+000,5.499839e+001,2.276568e-007,0.000000e+000,2,0.000000e+000,0.000000e+000,,,,,,,,,,,,,,32,1,4.000000e+000,0.000000e+000,0.000000e+000,0,,0,
1524342586.629,,0.000000e+000,5.500103e+001,2.633313e-007,0.000000e+000,2,0.000000e+000,0.000000e+000,,,,,,,,,,,,,,32,1,4.000000e+000,2.639771e-003,0.000000e+000,0,,0,
1524342599.049,,0.000000e+000,5.499840e+001,3.153892e-007,0.000000e+000,2,0.000000e+000,0.000000e+000,,,,,,,,,,,,,,32,1,4.000000e+000,7.900238e-003,0.000000e+000,0,,0,
1524342611.849,,0.000000e+000,5.499445e+001,3.153141e-007,0.000000e+000,2,0.000000e+000,0.000000e+000,,,,,,,,,,,,,,32,1,4.000000e+000,2.628326e-003,0.000000e+000,0,,0,
1524342624.239,,0.000000e+000,5.500761e+001,3.629191e-007,0.000000e+000,2,0.000000e+000,0.000000e+000,,,,,,,,,,,,,,32,1,4.000000e+000,7.881165e-003,0.000000e+000,0,,0,
1524342637.059,,0.000000e+000,5.499511e+001,3.939400e-007,0.000000e+000,2,0.000000e+000,0.000000e+000,,,,,,,,,,,,,,32,1,4.000000e+000,3.940582e-003,0.000000e+000,0,,0,
1524342649.449,,0.000000e+000,5.499972e+001,4.135684e-007,0.000000e+000,2,0.000000e+000,0.000000e+000,,,,,,,,,,,,,,32,1,4.000000e+000,1.314926e-002,0.000000e+000,0,,0,
1524342662.329,,0.000000e+000,5.500168e+001,4.710228e-007,0.000000e+000,2,0.000000e+000,0.000000e+000,,,,,,,,,,,,,,32,1,4.000000e+000,6.580353e-003,0.000000e+000,0,,0,
1524342674.719,,0.000000e+000,5.499906e+001,5.085636e-007,0.000000e+000,2,0.000000e+000,0.000000e+000,,,,,,,,,,,,,,32,1,4.000000e+000,9.220123e-003,0.000000e+000,0,,0,
1524342687.540,,0.000000e+000,5.499708e+001,4.883932e-007,0.000000e+000,2,0.000000e+000,0.000000e+000,,,,,,,,,,,,,,32,1,4.000000e+000,0.000000e+000,0.000000e+000,0,,0,
1524342699.970,,0.000000e+000,5.500300e+001,5.419294e-007,0.000000e+000,2,0.000000e+000,0.000000e+000,,,,,,,,,,,,,,32,1,4.000000e+000,3.940582e-003,0.000000e+000,0,,0,
1524342712.760,,0.000000e+000,5.499511e+001,5.124678e-007,0.000000e+000,2,0.000000e+000,0.000000e+000,,,,,,,,,,,,,,32,1,4.000000e+000,3.940582e-003,0.000000e+000,0,,0,
1524342725.160,,0.000000e+000,5.499643e+001,6.090158e-007,0.000000e+000,2,0.000000e+000,0.000000e+000,,,,,,,,,,,,,,32,1,4.000000e+000,6.568909e-003,0.000000e+000,0,,0,
1524342737.950,,0.000000e+000,5.499906e+001,6.044826e-007,0.000000e+000,2,0.000000e+000,0.000000e+000,,,,,,,,,,,,,,32,1,4.000000e+000,9.220123e-003,0.000000e+000,0,,0,
1524342750.340,,0.000000e+000,5.499905e+001,6.086286e-007,0.000000e+000,2,0.000000e+000,0.000000e+000,,,,,,,,,,,,,,32,1,4.000000e+000,1.182938e-002,0.000000e+000,0,,0,
1524342763.200,,0.000000e+000,5.500103e+001,6.391180e-007,0.000000e+000,2,0.000000e+000,0.000000e+000,,,,,,,,,,,,,,32,1,4.000000e+000,5.279541e-003,0.000000e+000,0,,0,
1524342775.410,,0.000000e+000,5.500037e+001,6.965106e-007,0.000000e+000,2,0.000000e+000,0.000000e+000,,,,,,,,,,,,,,32,1,4.000000e+000,6.587982e-003,0.000000e+000,0,,0,
1524342788.110,,0.000000e+000,5.499643e+001,7.025649e-007,0.000000e+000,2,0.000000e+000,0.000000e+000,,,,,,,,,,,,,,32,1,4.000000e+000,1.312256e-003,0.000000e+000,0,,0,
1524342800.480,,0.000000e+000,5.500432e+001,7.174837e-007,0.000000e+000,2,0.000000e+000,0.000000e+000,,,,,,,,,,,,,,32,1,4.000000e+000,6.580353e-003,0.000000e+000,0,,0,
1524342813.060,,0.000000e+000,5.499906e+001,7.131528e-007,0.000000e+000,2,0.000000e+000,0.000000e+000,,,,,,,,,,,,,,32,1,4.000000e+000,6.580353e-003,0.000000e+000,0,,0,
1524342825.550,,0.000000e+000,5.499709e+001,7.246382e-007,0.000000e+000,2,0.000000e+000,0.000000e+000,,,,,,,,,,,,,,32,1,4.000000e+000,7.888794e-003,0.000000e+000,0,,0,
1524342838.330,,0.000000e+000,5.499643e+001,7.747248e-007,0.000000e+000,2,0.000000e+000,0.000000e+000,,,,,,,,,,,,,,32,1,4.000000e+000,9.208679e-003,0.000000e+000,0,,0,
1524342850.890,,0.000000e+000,5.499905e+001,7.309696e-007,0.000000e+000,2,0.000000e+000,0.000000e+000,,,,,,,,,,,,,,32,1,4.000000e+000,1.319885e-003,0.000000e+000,0,,0,
1524342863.580,,0.000000e+000,5.499379e+001,8.455714e-007,0.000000e+000,2,0.000000e+000,0.000000e+000,,,,,,,,,,,,,,32,1,4.000000e+000,9.201050e-003,0.000000e+000,0,,0,
1524342876.210,,0.000000e+000,5.499971e+001,7.812924e-007,0.000000e+000,2,0.000000e+000,0.000000e+000,,,,,,,,,,,,,,32,1,4.000000e+000,0.000000e+000,0.000000e+000,0,,0,
1524342889.000,,0.000000e+000,5.500169e+001,8.261362e-007,0.000000e+000,2,0.000000e+000,0.000000e+000,,,,,,,,,,,,,,32,1,4.000000e+000,3.959656e-003,0.000000e+000,0,,0,
1524342901.630,,0.000000e+000,5.499577e+001,9.104965e-007,0.000000e+000,2,0.000000e+000,0.000000e+000,,,,,,,,,,,,,,32,1,4.000000e+000,0.000000e+000,0.000000e+000,0,,0,
1524342913.910,,0.000000e+000,5.499773e+001,8.700802e-007,0.000000e+000,2,0.000000e+000,0.000000e+000,,,,,,,,,,,,,,32,1,4.000000e+000,1.308441e-003,0.000000e+000,0,,0,
1524342926.560,,0.000000e+000,5.499773e+001,9.172850e-007,0.000000e+000,2,0.000000e+000,0.000000e+000,,,,,,,,,,,,,,32,1,4.000000e+000,1.308441e-003,0.000000e+000,0,,0,
1524342938.980,,0.000000e+000,5.499905e+001,9.196094e-007,0.000000e+000,2,0.000000e+000,0.000000e+000,,,,,,,,,,,,,,32,1,4.000000e+000,1.319885e-003,0.000000e+000,0,,0,
1524342951.830,,0.000000e+000,5.499511e+001,8.886090e-007,0.000000e+000,2,0.000000e+000,0.000000e+000,,,,,,,,,,,,,,32,1,4.000000e+000,1.319885e-003,0.000000e+000,0,,0,
1524342963.970,,0.000000e+000,5.499314e+001,9.125121e-007,0.000000e+000,2,0.000000e+000,0.000000e+000,,,,,,,,,,,,,,32,1,4.000000e+000,5.260468e-003,0.000000e+000,0,,0,
1524342976.470,,0.000000e+000,5.499773e+001,9.724846e-007,0.000000e+000,2,0.000000e+000,0.000000e+000,,,,,,,,,,,,,,32,1,4.000000e+000,1.308441e-003,0.000000e+000,0,,0,
1524342988.860,,0.000000e+000,5.500103e+001,1.047035e-006,0.000000e+000,2,0.000000e+000,0.000000e+000,,,,,,,,,,,,,,32,1,4.000000e+000,5.279541e-003,0.000000e+000,0,,0,
1524343001.720,,0.000000e+000,5.499643e+001,1.034730e-006,0.000000e+000,2,0.000000e+000,0.000000e+000,,,,,,,,,,,,,,32,1,4.000000e+000,6.568909e-003,0.000000e+000,0,,0,
1524343014.380,,0.000000e+000,5.499839e+001,1.040489e-006,0.000000e+000,2,0.000000e+000,0.000000e+000,,,,,,,,,,,,,,32,1,4.000000e+000,0.000000e+000,0.000000e+000,0,,0,
1524343027.080,,0.000000e+000,5.499642e+001,1.069051e-006,0.000000e+000,2,0.000000e+000,0.000000e+000,,,,,,,,,,,,,,32,1,4.000000e+000,3.940582e-003,0.000000e+000,0,,0,
1524343040.180,,0.000000e+000,5.499643e+001,9.572877e-007,0.000000e+000,2,0.000000e+000,0.000000e+000,,,,,,,,,,,,,,32,1,4.000000e+000,6.568909e-003,0.000000e+000,0,,0,
1524343052.100,,0.000000e+000,5.499905e+001,1.124687e-006,0.000000e+000,2,0.000000e+000,0.000000e+000,,,,,,,,,,,,,,32,1,4.000000e+000,1.319885e-003,0.000000e+000,0,,0,
1524343065.060,,0.000000e+000,5.499511e+001,1.094944e-006,0.000000e+000,2,0.000000e+000,0.000000e+000,,,,,,,,,,,,,,32,1,4.000000e+000,6.568909e-003,0.000000e+000,0,,0,
1524343077.640,,0.000000e+000,5.499182e+001,1.146885e-006,0.000000e+000,2,0.000000e+000,0.000000e+000,,,,,,,,,,,,,,32,1,4.000000e+000,0.000000e+000,0.000000e+000,0,,0,
1524343090.080,,0.000000e+000,5.499511e+001,1.161691e-006,0.000000e+000,2,0.000000e+000,0.000000e+000,,,,,,,,,,,,,,32,1,4.000000e+000,6.568909e-003,0.000000e+000,0,,0,
1524343102.430,,0.000000e+000,5.499905e+001,1.189652e-006,0.000000e+000,2,0.000000e+000,0.000000e+000,,,,,,,,,,,,,,32,1,4.000000e+000,1.319885e-003,0.000000e+000,0,,0,
1524343115.270,,0.000000e+000,5.500103e+001,1.162942e-006,0.000000e+000,2,0.000000e+000,0.000000e+000,,,,,,,,,,,,,,32,1,4.000000e+000,2.639771e-003,0.000000e+000,0,,0,
1524343127.420,,0.000000e+000,5.499906e+001,1.186669e-006,0.000000e+000,2,0.000000e+000,0.000000e+000,,,,,,,,,,,,,,32,1,4.000000e+000,6.580353e-003,0.000000e+000,0,,0,
1524343139.850,,0.000000e+000,5.499774e+001,1.166127e-006,0.000000e+000,2,0.000000e+000,0.000000e+000,,,,,,,,,,,,,,32,1,4.000000e+000,3.940582e-003,0.000000e+000,0,,0,
1524343152.650,,0.000000e+000,5.499775e+001,1.220097e-006,0.000000e+000,2,0.000000e+000,0.000000e+000,,,,,,,,,,,,,,32,1,4.000000e+000,9.208679e-003,0.000000e+000,0,,0,
1524343165.120,,0.000000e+000,5.499643e+001,1.227231e-006,0.000000e+000,2,0.000000e+000,0.000000e+000,,,,,,,,,,,,,,32,1,4.000000e+000,1.312256e-003,0.000000e+000,0,,0,
1524343177.850,,0.000000e+000,5.500169e+001,1.287268e-006,0.000000e+000,2,0.000000e+000,0.000000e+000,,,,,,,,,,,,,,32,1,4.000000e+000,1.319885e-003,0.000000e+000,0,,0,
1524343190.980,,0.000000e+000,5.499709e+001,1.225960e-006,0.000000e+000,2,0.000000e+000,0.000000e+000,,,,,,,,,,,,,,32,1,4.000000e+000,1.052856e-002,0.000000e+000,0,,0,
1524343203.290,,0.000000e+000,5.499511e+001,1.350570e-006,0.000000e+000,2,0.000000e+000,0.000000e+000,,,,,,,,,,,,,,32,1,4.000000e+000,6.568909e-003,0.000000e+000,0,,0,
1524343215.880,,0.000000e+000,5.499971e+001,1.171688e-006,0.000000e+000,2,0.000000e+000,0.000000e+000,,,,,,,,,,,,,,32,1,4.000000e+000,2.639771e-003,0.000000e+000,0,,0,
1524343228.080,,0.000000e+000,5.499905e+001,1.250922e-006,0.000000e+000,2,0.000000e+000,0.000000e+000,,,,,,,,,,,,,,32,1,4.000000e+000,3.948212e-003,0.000000e+000,0,,0,
1524343240.220,,0.000000e+000,5.499643e+001,1.243837e-006,0.000000e+000,2,0.000000e+000,0.000000e+000,,,,,,,,,,,,,,32,1,4.000000e+000,1.312256e-003,0.000000e+000,0,,0,
1524343252.800,,0.000000e+000,5.500235e+001,1.349427e-006,0.000000e+000,2,0.000000e+000,0.000000e+000,,,,,,,,,,,,,,32,1,4.000000e+000,2.639771e-003,0.000000e+000,0,,0,
1524343265.470,,0.000000e+000,5.499380e+001,1.365706e-006,0.000000e+000,2,0.000000e+000,0.000000e+000,,,,,,,,,,,,,,32,1,4.000000e+000,1.308441e-003,0.000000e+000,0,,0,
1524343278.200,,0.000000e+000,5.499643e+001,1.285339e-006,0.000000e+000,2,0.000000e+000,0.000000e+000,,,,,,,,,,,,,,32,1,4.000000e+000,9.208679e-003,0.000000e+000,0,,0,
1524343291.260,,0.000000e+000,5.499972e+001,1.292956e-006,0.000000e+000,2,0.000000e+000,0.000000e+000,,,,,,,,,,,,,,32,1,4.000000e+000,1.578903e-002,0.000000e+000,0,,0,
1524343303.360,,0.000000e+000,5.499445e+001,1.382095e-006,0.000000e+000,2,0.000000e+000,0.000000e+000,,,,,,,,,,,,,,32,1,4.000000e+000,5.260468e-003,0.000000e+000,0,,0,
1524343316.060,,0.000000e+000,5.499708e+001,1.311691e-006,0.000000e+000,2,0.000000e+000,0.000000e+000,,,,,,,,,,,,,,32,1,4.000000e+000,0.000000e+000,0.000000e+000,0,,0,
1524343328.600,,0.000000e+000,5.499840e+001,1.422984e-006,0.000000e+000,2,0.000000e+000,0.000000e+000,,,,,,,,,,,,,,32,1,4.000000e+000,2.628326e-003,0.000000e+000,0,,0,
1524343341.200,,0.000000e+000,5.499905e+001,1.395033e-006,0.000000e+000,2,0.000000e+000,0.000000e+000,,,,,,,,,,,,,,32,1,4.000000e+000,3.948212e-003,0.000000e+000,0,,0,
1524343353.570,,0.000000e+000,5.499313e+001,1.385674e-006,0.000000e+000,2,0.000000e+000,0.000000e+000,,,,,,,,,,,,,,32,1,4.000000e+000,7.892609e-003,0.000000e+000,0,,0,
1524343365.880,,0.000000e+000,5.500103e+001,1.423566e-006,0.000000e+000,2,0.000000e+000,0.000000e+000,,,,,,,,,,,,,,32,1,4.000000e+000,2.639771e-003,0.000000e+000,0,,0,
1524343378.480,,0.000000e+000,5.499709e+001,1.500680e-006,0.000000e+000,2,0.000000e+000,0.000000e+000,,,,,,,,,,,,,,32,1,4.000000e+000,1.052856e-002,0.000000e+000,0,,0,
1524343391.090,,0.000000e+000,5.499511e+001,1.404631e-006,0.000000e+000,2,0.000000e+000,0.000000e+000,,,,,,,,,,,,,,32,1,4.000000e+000,6.568909e-003,0.000000e+000,0,,0,
1524343403.851,,0.000000e+000,5.499511e+001,1.426838e-006,0.000000e+000,2,0.000000e+000,0.000000e+000,,,,,,,,,,,,,,32,1,4.000000e+000,1.319885e-003,0.000000e+000,0,,0,
1524343416.781,,0.000000e+000,5.499445e+001,1.427431e-006,0.000000e+000,2,0.000000e+000,0.000000e+000,,,,,,,,,,,,,,32,1,4.000000e+000,7.881165e-003,0.000000e+000,0,,0,
1524343428.881,,0.000000e+000,5.499839e+001,1.432928e-006,0.000000e+000,2,0.000000e+000,0.000000e+000,,,,,,,,,,,,,,32,1,4.000000e+000,0.000000e+000,0.000000e+000,0,,0,
1524343441.511,,0.000000e+000,5.499839e+001,1.449322e-006,0.000000e+000,2,0.000000e+000,0.000000e+000,,,,,,,,,,,,,,32,1,4.000000e+000,0.000000e+000,0.000000e+000,0,,0,
1524343454.261,,0.000000e+000,5.499840e+001,1.516671e-006,0.000000e+000,2,0.000000e+000,0.000000e+000,,,,,,,,,,,,,,32,1,4.000000e+000,5.260468e-003,0.000000e+000,0,,0,
1524343466.681,,0.000000e+000,5.499577e+001,1.516595e-006,0.000000e+000,2,0.000000e+000,0.000000e+000,,,,,,,,,,,,,,32,1,4.000000e+000,7.888794e-003,0.000000e+000,0,,0,
1524343479.311,,0.000000e+000,5.499643e+001,1.592201e-006,0.000000e+000,2,2.460861e-003,0.000000e+000,,,,,,,,,,,,,,32,1,4.000000e+000,1.312256e-003,0.000000e+000,0,,0,
1524343492.421,,0.000000e+000,5.499905e+001,1.548103e-006,0.000000e+000,2,0.000000e+000,0.000000e+000,,,,,,,,,,,,,,32,1,4.000000e+000,3.948212e-003,0.000000e+000,0,,0,
1524343504.531,,0.000000e+000,5.499643e+001,1.574505e-006,0.000000e+000,2,0.000000e+000,0.000000e+000,,,,,,,,,,,,,,32,1,4.000000e+000,9.208679e-003,0.000000e+000,0,,0,
1524343517.621,,0.000000e+000,5.499840e+001,1.578082e-006,0.000000e+000,2,0.000000e+000,0.000000e+000,,,,,,,,,,,,,,32,1,4.000000e+000,2.628326e-003,0.000000e+000,0,,0,
1524343529.741,,0.000000e+000,5.500037e+001,1.558217e-006,0.000000e+000,2,0.000000e+000,0.000000e+000,,,,,,,,,,,,,,32,1,4.000000e+000,1.319885e-003,0.000000e+000,0,,0,
1524343542.331,,0.000000e+000,5.499905e+001,1.543542e-006,0.000000e+000,2,0.000000e+000,0.000000e+000,,,,,,,,,,,,,,32,1,4.000000e+000,3.948212e-003,0.000000e+000,0,,0,
1524343554.951,,0.000000e+000,5.499577e+001,1.592706e-006,0.000000e+000,2,0.000000e+000,0.000000e+000,,,,,,,,,,,,,,32,1,4.000000e+000,5.249023e-003,0.000000e+000,0,,0,
1524343568.041,,0.000000e+000,5.499971e+001,1.504389e-006,0.000000e+000,2,0.000000e+000,0.000000e+000,,,,,,,,,,,,,,32,1,4.000000e+000,2.639771e-003,0.000000e+000,0,,0,
1524343580.291,,0.000000e+000,5.499709e+001,1.571848e-006,0.000000e+000,2,0.000000e+000,0.000000e+000,,,,,,,,,,,,,,32,1,4.000000e+000,7.888794e-003,0.000000e+000,0,,0,
1524343592.951,,0.000000e+000,5.499577e+001,1.458299e-006,0.000000e+000,2,0.000000e+000,0.000000e+000,,,,,,,,,,,,,,32,1,4.000000e+000,5.249023e-003,0.000000e+000,0,,0,
1524343605.541,,0.000000e+000,5.499708e+001,1.569039e-006,0.000000e+000,2,7.595166e-003,0.000000e+000,,,,,,,,,,,,,,32,1,4.000000e+000,2.620697e-003,0.000000e+000,0,,0,
1524343618.781,,0.000000e+000,5.499708e+001,1.555416e-006,0.000000e+000,2,2.959000e-002,0.000000e+000,,,,,,,,,,,,,,32,1,4.000000e+000,2.620697e-003,0.000000e+000,0,,0,
1524343631.421,,0.000000e+000,5.500037e+001,1.567312e-006,0.000000e+000,2,0.000000e+000,0.000000e+000,,,,,,,,,,,,,,32,1,4.000000e+000,6.587982e-003,0.000000e+000,0,,0,
1524343644.151,,0.000000e+000,5.499511e+001,1.704322e-006,0.000000e+000,2,9.331477e-002,0.000000e+000,,,,,,,,,,,,,,32,1,4.000000e+000,3.940582e-003,0.000000e+000,0,,0,
1524343656.611,,0.000000e+000,5.499840e+001,1.617005e-006,0.000000e+000,2,3.973799e-002,0.000000e+000,,,,,,,,,,,,,,32,1,4.000000e+000,2.628326e-003,0.000000e+000,0,,0,
1524343669.541,,0.000000e+000,5.499773e+001,1.742885e-006,0.000000e+000,2,9.482437e-002,0.000000e+000,,,,,,,,,,,,,,32,1,4.000000e+000,1.308441e-003,0.000000e+000,0,,0,
1524343682.151,,0.000000e+000,5.499709e+001,1.596524e-006,0.000000e+000,2,3.307533e-002,0.000000e+000,,,,,,,,,,,,,,32,1,4.000000e+000,7.888794e-003,0.000000e+000,0,,0,
1524343694.761,,0.000000e+000,5.499839e+001,1.669851e-006,0.000000e+000,2,9.757958e-002,0.000000e+000,,,,,,,,,,,,,,32,1,4.000000e+000,0.000000e+000,0.000000e+000,0,,0,
1524343707.501,,0.000000e+000,5.500366e+001,1.668308e-006,0.000000e+000,2,6.558006e-002,0.000000e+000,,,,,,,,,,,,,,32,1,4.000000e+000,1.315689e-002,0.000000e+000,0,,0,
1524343720.161,,0.000000e+000,5.499643e+001,1.735157e-006,0.000000e+000,2,7.338648e-002,0.000000e+000,,,,,,,,,,,,,,32,1,4.000000e+000,1.312256e-003,0.000000e+000,0,,0,
1524343732.711,,0.000000e+000,5.499314e+001,1.670224e-006,0.000000e+000,2,2.455969e-002,0.000000e+000,,,,,,,,,,,,,,32,1,4.000000e+000,5.260468e-003,0.000000e+000,0,,0,
1524343745.371,,0.000000e+000,5.499906e+001,1.782842e-006,0.000000e+000,2,9.589264e-002,0.000000e+000,,,,,,,,,,,,,,32,1,4.000000e+000,6.580353e-003,0.000000e+000,0,,0,
1524343757.931,,0.000000e+000,5.500169e+001,1.764620e-006,0.000000e+000,2,1.042617e-001,0.000000e+000,,,,,,,,,,,,,,32,1,4.000000e+000,1.319885e-003,0.000000e+000,0,,0,
1524343770.611,,0.000000e+000,5.499774e+001,1.770149e-006,0.000000e+000,2,7.992145e-002,0.000000e+000,,,,,,,,,,,,,,32,1,4.000000e+000,6.580353e-003,0.000000e+000,0,,0,
1524343783.141,,0.000000e+000,5.499117e+001,1.784851e-006,0.000000e+000,2,9.035138e-002,0.000000e+000,,,,,,,,,,,,,,32,1,4.000000e+000,9.208679e-003,0.000000e+000,0,,0,
1524343795.711,,0.000000e+000,5.499314e+001,1.807633e-006,0.000000e+000,2,1.130580e-001,0.000000e+000,,,,,,,,,,,,,,32,1,4.000000e+000,5.260468e-003,0.000000e+000,0,,0,
1524343808.151,,0.000000e+000,5.499248e+001,1.788182e-006,0.000000e+000,2,1.242544e-001,0.000000e+000,,,,,,,,,,,,,,32,1,4.000000e+000,3.940582e-003,0.000000e+000,0,,0,
1524343820.501,,0.000000e+000,5.499511e+001,1.850411e-006,0.000000e+000,2,1.200115e-001,0.000000e+000,,,,,,,,,,,,,,32,1,4.000000e+000,3.940582e-003,0.000000e+000,0,,0,
1524343833.341,,0.000000e+000,5.500103e+001,1.824575e-006,0.000000e+000,2,1.472167e-001,0.000000e+000,,,,,,,,,,,,,,32,1,4.000000e+000,7.888794e-003,0.000000e+000,0,,0,
1524343845.471,,0.000000e+000,5.500432e+001,1.867567e-006,0.000000e+000,2,1.547510e-001,0.000000e+000,,,,,,,,,,,,,,32,1,4.000000e+000,1.300812e-003,0.000000e+000,0,,0,
1524343858.231,,0.000000e+000,5.499708e+001,1.839266e-006,0.000000e+000,2,1.318571e-001,0.000000e+000,,,,,,,,,,,,,,32,1,4.000000e+000,5.260468e-003,0.000000e+000,0,,0,
1524343871.431,,0.000000e+000,5.499380e+001,1.887842e-006,0.000000e+000,2,1.334730e-001,0.000000e+000,,,,,,,,,,,,,,32,1,4.000000e+000,1.308441e-003,0.000000e+000,0,,0,
1524343884.571,,0.000000e+000,5.499117e+001,1.946207e-006,0.000000e+000,2,1.979803e-001,0.000000e+000,,,,,,,,,,,,,,32,1,4.000000e+000,3.952026e-003,0.000000e+000,0,,0,
1524343896.931,,0.000000e+000,5.499840e+001,1.936326e-006,0.000000e+000,2,1.490006e-001,0.000000e+000,,,,,,,,,,,,,,32,1,4.000000e+000,2.628326e-003,0.000000e+000,0,,0,
1524343909.271,,0.000000e+000,5.500169e+001,1.870361e-006,0.000000e+000,2,1.446306e-001,0.000000e+000,,,,,,,,,,,,,,32,1,4.000000e+000,1.184082e-002,0.000000e+000,0,,0,
1524343922.171,,0.000000e+000,5.500629e+001,1.834892e-006,0.000000e+000,2,1.023508e-001,0.000000e+000,,,,,,,,,,,,,,32,1,4.000000e+000,2.639771e-003,0.000000e+000,0,,0,
1524343934.261,,0.000000e+000,5.500103e+001,1.928974e-006,0.000000e+000,2,1.604035e-001,0.000000e+000,,,,,,,,,,,,,,32,1,4.000000e+000,7.888794e-003,0.000000e+000,0,,0,
1524343946.891,,0.000000e+000,5.500366e+001,1.848572e-006,0.000000e+000,2,1.101280e-001,0.000000e+000,,,,,,,,,,,,,,32,1,4.000000e+000,7.900238e-003,0.000000e+000,0,,0,
1524343959.631,,0.000000e+000,5.499380e+001,1.915543e-006,0.000000e+000,2,1.373249e-001,0.000000e+000,,,,,,,,,,,,,,32,1,4.000000e+000,6.572723e-003,0.000000e+000,0,,0,
1524343972.571,,0.000000e+000,5.499380e+001,1.861708e-006,0.000000e+000,2,1.317338e-001,0.000000e+000,,,,,,,,,,,,,,32,1,4.000000e+000,6.572723e-003,0.000000e+000,0,,0,
1524343984.691,,0.000000e+000,5.499511e+001,1.857862e-006,0.000000e+000,2,1.306283e-001,0.000000e+000,,,,,,,,,,,,,,32,1,4.000000e+000,3.940582e-003,0.000000e+000,0,,0,
1524343997.811,,0.000000e+000,5.500037e+001,1.871885e-006,0.000000e+000,2,1.443943e-001,0.000000e+000,,,,,,,,,,,,,,32,1,4.000000e+000,3.959656e-003,0.000000e+000,0,,0,
1524344009.911,,0.000000e+000,5.500366e+001,1.914926e-006,0.000000e+000,2,1.614181e-001,0.000000e+000,,,,,,,,,,,,,,32,1,4.000000e+000,2.620697e-003,0.000000e+000,0,,0,
1524344022.541,,0.000000e+000,5.499839e+001,1.894420e-006,0.000000e+000,2,1.291940e-001,0.000000e+000,,,,,,,,,,,,,,32,1,4.000000e+000,0.000000e+000,0.000000e+000,0,,0,
1524344034.911,,0.000000e+000,5.499971e+001,1.963388e-006,0.000000e+000,2,1.946769e-001,0.000000e+000,,,,,,,,,,,,,,32,1,4.000000e+000,2.639771e-003,0.000000e+000,0,,0,
1524344046.921,,0.000000e+000,5.499511e+001,1.932344e-006,0.000000e+000,2,1.342693e-001,0.000000e+000,,,,,,,,,,,,,,32,1,4.000000e+000,3.940582e-003,0.000000e+000,0,,0,
1524344059.801,,0.000000e+000,5.500300e+001,1.967378e-006,0.000000e+000,2,1.894341e-001,0.000000e+000,,,,,,,,,,,,,,32,1,4.000000e+000,3.940582e-003,0.000000e+000,0,,0,
1524344072.411,,0.000000e+000,5.499709e+001,1.890112e-006,0.000000e+000,2,1.580117e-001,0.000000e+000,,,,,,,,,,,,,,32,1,4.000000e+000,7.888794e-003,0.000000e+000,0,,0,
1524344085.161,,0.000000e+000,5.499577e+001,1.949922e-006,0.000000e+000,2,1.930142e-001,0.000000e+000,,,,,,,,,,,,,,32,1,4.000000e+000,2.632141e-003,0.000000e+000,0,,0,
1524344098.101,,0.000000e+000,5.499774e+001,1.919887e-006,0.000000e+000,2,2.181231e-001,0.000000e+000,,,,,,,,,,,,,,32,1,4.000000e+000,6.580353e-003,0.000000e+000,0,,0,
1524344110.662,,0.000000e+000,5.499774e+001,2.071786e-006,0.000000e+000,2,1.904582e-001,0.000000e+000,,,,,,,,,,,,,,32,1,4.000000e+000,6.580353e-003,0.000000e+000,0,,0,
1524344123.932,,0.000000e+000,5.499840e+001,2.065794e-006,0.000000e+000,2,2.356776e-001,0.000000e+000,,,,,,,,,,,,,,32,1,4.000000e+000,7.900238e-003,0.000000e+000,0,,0,
1524344136.512,,0.000000e+000,5.499906e+001,2.019046e-006,0.000000e+000,2,1.473299e-001,0.000000e+000,,,,,,,,,,,,,,32,1,4.000000e+000,6.580353e-003,0.000000e+000,0,,0,
1524344149.132,,0.000000e+000,5.499380e+001,2.062424e-006,0.000000e+000,2,2.360189e-001,0.000000e+000,,,,,,,,,,,,,,32,1,4.000000e+000,3.948212e-003,0.000000e+000,0,,0,
1524344161.792,,0.000000e+000,5.499577e+001,2.059797e-006,0.000000e+000,2,1.843060e-001,0.000000e+000,,,,,,,,,,,,,,32,1,4.000000e+000,7.888794e-003,0.000000e+000,0,,0,
1524344174.492,,0.000000e+000,5.500234e+001,2.042408e-006,0.000000e+000,2,2.073695e-001,0.000000e+000,,,,,,,,,,,,,,32,1,4.000000e+000,5.260468e-003,0.000000e+000,0,,0,
1524344187.112,,0.000000e+000,5.499708e+001,2.000793e-006,0.000000e+000,2,1.871246e-001,0.000000e+000,,,,,,,,,,,,,,32,1,4.000000e+000,5.260468e-003,0.000000e+000,0,,0,
1524344199.352,,0.000000e+000,5.500037e+001,2.045969e-006,0.000000e+000,2,2.145385e-001,0.000000e+000,,,,,,,,,,,,,,32,1,4.000000e+000,3.959656e-003,0.000000e+000,0,,0,
1524344211.772,,0.000000e+000,5.500365e+001,2.039647e-006,0.000000e+000,2,2.298116e-001,0.000000e+000,,,,,,,,,,,,,,32,1,4.000000e+000,1.052856e-002,0.000000e+000,0,,0,
1524344224.492,,0.000000e+000,5.499642e+001,2.075954e-006,0.000000e+000,2,2.065252e-001,0.000000e+000,,,,,,,,,,,,,,32,1,4.000000e+000,3.940582e-003,0.000000e+000,0,,0,
1524344237.132,,0.000000e+000,5.499511e+001,2.058217e-006,0.000000e+000,2,2.534940e-001,0.000000e+000,,,,,,,,,,,,,,32,1,4.000000e+000,1.319885e-003,0.000000e+000,0,,0,
1524344249.642,,0.000000e+000,5.499840e+001,2.061271e-006,0.000000e+000,2,1.946998e-001,0.000000e+000,,,,,,,,,,,,,,32,1,4.000000e+000,2.628326e-003,0.000000e+000,0,,0,
1524344262.412,,0.000000e+000,5.499840e+001,2.061451e-006,0.000000e+000,2,2.560930e-001,0.000000e+000,,,,,,,,,,,,,,32,1,4.000000e+000,2.628326e-003,0.000000e+000,0,,0,
1524344274.832,,0.000000e+000,5.500037e+001,2.099378e-006,0.000000e+000,2,2.201352e-001,0.000000e+000,,,,,,,,,,,,,,32,1,4.000000e+000,1.319885e-003,0.000000e+000,0,,0,