File: Experimental Raw Data/TC04-12-01K VRMac VRMde/TC04-12-01K_VRMac_57K_6000s_VRMde_55K.dc.dat
[Header]
TITLE,MPMS DC Measurement
BYAPP,MPMS Measurement,2.1,Summary
FILEOPENTIME, 1524324206.426000 4/21/2018, 9:23:26 AM

INFO, APPNAME, MPMS MultiVu Application, Revision 1.61,  Build 082

INFO, NAME, TC04-12-01K
INFO, WEIGHT, 1.000
INFO, AREA, 1.000
INFO, LENGTH, 1.000
INFO, SHAPE, 0
INFO, COMMENT,
INFO, SEQUENCE FILE: VRMac_57K_6000s_VRMde_55K.seq


INFO, BACKGROUND DATA FILE:, None


STARTUPAXIS,X,4,LINEAR,AUTO,0.000000,0.000000
STARTUPAXIS,Y1,5,LINEAR,AUTO,0.000000,0.000000


STARTUPGROUP,Longitudinal
FIELDGROUP,Longitudinal,1,2,3,4,5,6,7,8,9,15,16,17,18,27,28
FIELDGROUP,Transverse,1,2,3,4,10,11,12,13,14,19,20,21,22,27,28

PLOT_APPEARANCE,ALL,HORZ_GRID_ON,VERT_GRID_ON,MARKERS_AND_LINES

[Data]
Time,Comment,Field (Oe),Temperature (K),Long Moment (emu),Long Scan Std Dev,Long Algorithm,Long Reg Fit,Long Percent Error (%),Trans Moment (emu),Trans Scan Std Dev,Trans Algorithm,Trans Reg Fit,Trans Percent Error (%),Long Moment [w/o ABS] (emu),Long Scan Std Dev [w/o ABS],Long Reg Fit [w/o ABS],Long Percent Error [w/o ABS] (%),Trans Moment [w/o ABS] (emu),Trans Scan Std Dev [w/o ABS],Trans Reg Fit [w/o ABS],Trans Percent Error [w/o ABS] (%),Points per Scan,Scans per Measurement,Scan Length (cm),Delta Temp (K),Rot Position (deg),Error,EC Comp. Running,Using ABS,
1524324206.426,,0.000000e+000,5.698555e+001,-1.696613e-005,0.000000e+000,2,9.247385e-001,0.000000e+000,,,,,,,,,,,,,,32,1,4.000000e+000,4.064178e-002,0.000000e+000,0,,0,
1524324245.466,,0.000000e+000,5.681224e+001,-1.328151e-005,0.000000e+000,2,8.866209e-001,0.000000e+000,,,,,,,,,,,,,,32,1,4.000000e+000,4.042053e-002,0.000000e+000,0,,0,
1524324284.006,,0.000000e+000,5.661009e+001,-1.156989e-005,0.000000e+000,2,8.774949e-001,0.000000e+000,,,,,,,,,,,,,,32,1,4.000000e+000,7.201767e-002,0.000000e+000,0,,0,
1524324322.526,,0.000000e+000,5.633431e+001,-1.060707e-005,0.000000e+000,2,8.585153e-001,0.000000e+000,,,,,,,,,,,,,,32,1,4.000000e+000,9.336090e-002,0.000000e+000,0,,0,
1524324360.286,,0.000000e+000,5.600311e+001,-9.808477e-006,0.000000e+000,2,8.380614e-001,0.000000e+000,,,,,,,,,,,,,,32,1,4.000000e+000,9.103012e-002,0.000000e+000,0,,0,
1524324398.978,,0.000000e+000,5.564848e+001,-9.304230e-006,0.000000e+000,2,8.333743e-001,0.000000e+000,,,,,,,,,,,,,,32,1,4.000000e+000,1.047707e-001,0.000000e+000,0,,0,
1524324437.454,,0.000000e+000,5.528126e+001,-8.329554e-006,0.000000e+000,2,8.549927e-001,0.000000e+000,,,,,,,,,,,,,,32,1,4.000000e+000,1.141701e-001,0.000000e+000,0,,0,
1524324478.994,,0.000000e+000,5.495305e+001,-8.729971e-006,0.000000e+000,2,8.177685e-001,0.000000e+000,,,,,,,,,,,,,,32,1,4.000000e+000,3.284073e-002,0.000000e+000,0,,0,
1524324516.824,,0.000000e+000,5.497079e+001,-8.546400e-006,0.000000e+000,2,8.208812e-001,0.000000e+000,,,,,,,,,,,,,,32,1,4.000000e+000,2.365875e-002,0.000000e+000,0,,0,
1524324555.574,,0.000000e+000,5.499445e+001,-8.281208e-006,0.000000e+000,2,8.230006e-001,0.000000e+000,,,,,,,,,,,,,,32,1,4.000000e+000,1.052094e-002,0.000000e+000,0,,0,
1524324592.816,,0.000000e+000,5.500103e+001,-8.068690e-006,0.000000e+000,2,8.044814e-001,0.000000e+000,,,,,,,,,,,,,,32,1,4.000000e+000,1.052094e-002,0.000000e+000,0,,0,
1524324630.696,,0.000000e+000,5.500103e+001,-7.927082e-006,0.000000e+000,2,8.130084e-001,0.000000e+000,,,,,,,,,,,,,,32,1,4.000000e+000,7.888794e-003,0.000000e+000,0,,0,
1524324668.336,,0.000000e+000,5.499051e+001,-7.732455e-006,0.000000e+000,2,8.030347e-001,0.000000e+000,,,,,,,,,,,,,,32,1,4.000000e+000,5.260468e-003,0.000000e+000,0,,0,
1524324706.306,,0.000000e+000,5.500037e+001,-7.612902e-006,0.000000e+000,2,8.052217e-001,0.000000e+000,,,,,,,,,,,,,,32,1,4.000000e+000,1.319885e-003,0.000000e+000,0,,0,
1524324743.946,,0.000000e+000,5.499380e+001,-7.336024e-006,0.000000e+000,2,7.911624e-001,0.000000e+000,,,,,,,,,,,,,,32,1,4.000000e+000,3.948212e-003,0.000000e+000,0,,0,
1524324781.366,,0.000000e+000,5.499642e+001,-7.218859e-006,0.000000e+000,2,7.931476e-001,0.000000e+000,,,,,,,,,,,,,,32,1,4.000000e+000,3.940582e-003,0.000000e+000,0,,0,
1524324818.996,,0.000000e+000,5.499445e+001,-7.059524e-006,0.000000e+000,2,7.822398e-001,0.000000e+000,,,,,,,,,,,,,,32,1,4.000000e+000,0.000000e+000,0.000000e+000,0,,0,
1524324857.007,,0.000000e+000,5.499511e+001,-6.991036e-006,0.000000e+000,2,7.897308e-001,0.000000e+000,,,,,,,,,,,,,,32,1,4.000000e+000,6.568909e-003,0.000000e+000,0,,0,
1524324894.697,,0.000000e+000,5.499708e+001,-6.811535e-006,0.000000e+000,2,7.758424e-001,0.000000e+000,,,,,,,,,,,,,,32,1,4.000000e+000,2.620697e-003,0.000000e+000,0,,0,
1524324932.597,,0.000000e+000,5.499643e+001,-6.685879e-006,0.000000e+000,2,7.779933e-001,0.000000e+000,,,,,,,,,,,,,,32,1,4.000000e+000,9.208679e-003,0.000000e+000,0,,0,
1524324971.147,,0.000000e+000,5.500103e+001,-6.577040e-006,0.000000e+000,2,7.658353e-001,0.000000e+000,,,,,,,,,,,,,,32,1,4.000000e+000,5.279541e-003,0.000000e+000,0,,0,
1524325009.087,,0.000000e+000,5.499839e+001,-6.404923e-006,0.000000e+000,2,7.581410e-001,0.000000e+000,,,,,,,,,,,,,,32,1,4.000000e+000,0.000000e+000,0.000000e+000,0,,0,
1524325046.937,,0.000000e+000,5.499773e+001,-6.338378e-006,0.000000e+000,2,7.648281e-001,0.000000e+000,,,,,,,,,,,,,,32,1,4.000000e+000,1.308441e-003,0.000000e+000,0,,0,
1524325084.667,,0.000000e+000,5.499117e+001,-6.197300e-006,0.000000e+000,2,7.531065e-001,0.000000e+000,,,,,,,,,,,,,,32,1,4.000000e+000,3.952026e-003,0.000000e+000,0,,0,
1524325122.557,,0.000000e+000,5.500563e+001,-6.134253e-006,0.000000e+000,2,7.604811e-001,0.000000e+000,,,,,,,,,,,,,,32,1,4.000000e+000,6.568909e-003,0.000000e+000,0,,0,
1524325159.977,,0.000000e+000,5.499774e+001,-5.973987e-006,0.000000e+000,2,7.475628e-001,0.000000e+000,,,,,,,,,,,,,,32,1,4.000000e+000,3.940582e-003,0.000000e+000,0,,0,
1524325199.117,,0.000000e+000,5.499577e+001,-5.920981e-006,0.000000e+000,2,7.488778e-001,0.000000e+000,,,,,,,,,,,,,,32,1,4.000000e+000,5.249023e-003,0.000000e+000,0,,0,
1524325236.667,,0.000000e+000,5.499905e+001,-5.786472e-006,0.000000e+000,2,7.258019e-001,0.000000e+000,,,,,,,,,,,,,,32,1,4.000000e+000,1.182938e-002,0.000000e+000,0,,0,
1524325274.577,,0.000000e+000,5.499511e+001,-5.724432e-006,0.000000e+000,2,7.397620e-001,0.000000e+000,,,,,,,,,,,,,,32,1,4.000000e+000,1.319885e-003,0.000000e+000,0,,0,
1524325312.107,,0.000000e+000,5.499709e+001,-5.633198e-006,0.000000e+000,2,7.186114e-001,0.000000e+000,,,,,,,,,,,,,,32,1,4.000000e+000,1.052856e-002,0.000000e+000,0,,0,
1524325349.357,,0.000000e+000,5.499314e+001,-5.502764e-006,0.000000e+000,2,7.355506e-001,0.000000e+000,,,,,,,,,,,,,,32,1,4.000000e+000,1.578140e-002,0.000000e+000,0,,0,
1524325388.397,,0.000000e+000,5.500300e+001,-5.354292e-006,0.000000e+000,2,7.209418e-001,0.000000e+000,,,,,,,,,,,,,,32,1,4.000000e+000,1.710129e-002,0.000000e+000,0,,0,
1524325426.097,,0.000000e+000,5.499774e+001,-5.343559e-006,0.000000e+000,2,7.179574e-001,0.000000e+000,,,,,,,,,,,,,,32,1,4.000000e+000,1.710129e-002,0.000000e+000,0,,0,
1524325463.837,,0.000000e+000,5.500431e+001,-5.262311e-006,0.000000e+000,2,7.056807e-001,0.000000e+000,,,,,,,,,,,,,,32,1,4.000000e+000,1.184845e-002,0.000000e+000,0,,0,
1524325501.437,,0.000000e+000,5.500037e+001,-5.193641e-006,0.000000e+000,2,7.116809e-001,0.000000e+000,,,,,,,,,,,,,,32,1,4.000000e+000,6.587982e-003,0.000000e+000,0,,0,
1524325539.117,,0.000000e+000,5.499971e+001,-5.111745e-006,0.000000e+000,2,6.911672e-001,0.000000e+000,,,,,,,,,,,,,,32,1,4.000000e+000,0.000000e+000,0.000000e+000,0,,0,
1524325577.238,,0.000000e+000,5.500168e+001,-5.036049e-006,0.000000e+000,2,7.041281e-001,0.000000e+000,,,,,,,,,,,,,,32,1,4.000000e+000,6.580353e-003,0.000000e+000,0,,0,
1524325616.368,,0.000000e+000,5.499117e+001,-4.935302e-006,0.000000e+000,2,7.018487e-001,0.000000e+000,,,,,,,,,,,,,,32,1,4.000000e+000,6.568909e-003,0.000000e+000,0,,0,
1524325654.118,,0.000000e+000,5.500695e+001,-4.878594e-006,0.000000e+000,2,6.919460e-001,0.000000e+000,,,,,,,,,,,,,,32,1,4.000000e+000,1.184082e-002,0.000000e+000,0,,0,
1524325691.548,,0.000000e+000,5.499577e+001,-4.828856e-006,0.000000e+000,2,6.657094e-001,0.000000e+000,,,,,,,,,,,,,,32,1,4.000000e+000,2.632141e-003,0.000000e+000,0,,0,
1524325728.858,,0.000000e+000,5.499380e+001,-4.721208e-006,0.000000e+000,2,6.822833e-001,0.000000e+000,,,,,,,,,,,,,,32,1,4.000000e+000,3.948212e-003,0.000000e+000,0,,0,
1524325766.278,,0.000000e+000,5.500300e+001,-4.699131e-006,0.000000e+000,2,6.559029e-001,0.000000e+000,,,,,,,,,,,,,,32,1,4.000000e+000,3.940582e-003,0.000000e+000,0,,0,
1524325803.928,,0.000000e+000,5.499840e+001,-4.587912e-006,0.000000e+000,2,6.810666e-001,0.000000e+000,,,,,,,,,,,,,,32,1,4.000000e+000,2.628326e-003,0.000000e+000,0,,0,
1524325841.378,,0.000000e+000,5.500037e+001,-4.575751e-006,0.000000e+000,2,6.607949e-001,0.000000e+000,,,,,,,,,,,,,,32,1,4.000000e+000,1.319885e-003,0.000000e+000,0,,0,
1524325878.438,,0.000000e+000,5.499643e+001,-4.434188e-006,0.000000e+000,2,6.593544e-001,0.000000e+000,,,,,,,,,,,,,,32,1,4.000000e+000,1.312256e-003,0.000000e+000,0,,0,
1524325915.718,,0.000000e+000,5.499708e+001,-4.411569e-006,0.000000e+000,2,6.472958e-001,0.000000e+000,,,,,,,,,,,,,,32,1,4.000000e+000,5.260468e-003,0.000000e+000,0,,0,
1524325953.508,,0.000000e+000,5.498919e+001,-4.401510e-006,0.000000e+000,2,6.668240e-001,0.000000e+000,,,,,,,,,,,,,,32,1,4.000000e+000,5.260468e-003,0.000000e+000,0,,0,
1524325991.188,,0.000000e+000,5.499643e+001,-4.271438e-006,0.000000e+000,2,6.314332e-001,0.000000e+000,,,,,,,,,,,,,,32,1,4.000000e+000,6.568909e-003,0.000000e+000,0,,0,
1524326028.588,,0.000000e+000,5.499643e+001,-4.248224e-006,0.000000e+000,2,6.507003e-001,0.000000e+000,,,,,,,,,,,,,,32,1,4.000000e+000,1.312256e-003,0.000000e+000,0,,0,
1524326065.638,,0.000000e+000,5.499511e+001,-4.150499e-006,0.000000e+000,2,6.208580e-001,0.000000e+000,,,,,,,,,,,,,,32,1,4.000000e+000,1.319885e-003,0.000000e+000,0,,0,
1524326103.258,,0.000000e+000,5.500497e+001,-4.146030e-006,0.000000e+000,2,6.305545e-001,0.000000e+000,,,,,,,,,,,,,,32,1,4.000000e+000,7.888794e-003,0.000000e+000,0,,0,
1524326141.638,,0.000000e+000,5.499313e+001,-4.079654e-006,0.000000e+000,2,6.432924e-001,0.000000e+000,,,,,,,,,,,,,,32,1,4.000000e+000,2.628326e-003,0.000000e+000,0,,0,
1524326179.128,,0.000000e+000,5.499708e+001,-4.018109e-006,0.000000e+000,2,6.083767e-001,0.000000e+000,,,,,,,,,,,,,,32,1,4.000000e+000,0.000000e+000,0.000000e+000,0,,0,
1524326217.048,,0.000000e+000,5.500037e+001,-3.983972e-006,0.000000e+000,2,6.261532e-001,0.000000e+000,,,,,,,,,,,,,,32,1,4.000000e+000,6.587982e-003,0.000000e+000,0,,0,
1524326254.389,,0.000000e+000,5.499445e+001,-3.982027e-006,0.000000e+000,2,5.952197e-001,0.000000e+000,,,,,,,,,,,,,,32,1,4.000000e+000,7.881165e-003,0.000000e+000,0,,0,
1524326292.139,,0.000000e+000,5.499708e+001,-3.892667e-006,0.000000e+000,2,6.174367e-001,0.000000e+000,,,,,,,,,,,,,,32,1,4.000000e+000,5.260468e-003,0.000000e+000,0,,0,
1524326329.759,,0.000000e+000,5.499313e+001,-3.788188e-006,0.000000e+000,2,5.927618e-001,0.000000e+000,,,,,,,,,,,,,,32,1,4.000000e+000,1.314926e-002,0.000000e+000,0,,0,
1524326367.419,,0.000000e+000,5.500037e+001,-3.745457e-006,0.000000e+000,2,6.037687e-001,0.000000e+000,,,,,,,,,,,,,,32,1,4.000000e+000,1.319885e-003,0.000000e+000,0,,0,
1524326405.599,,0.000000e+000,5.499643e+001,-3.753676e-006,0.000000e+000,2,5.953397e-001,0.000000e+000,,,,,,,,,,,,,,32,1,4.000000e+000,1.312256e-003,0.000000e+000,0,,0,
1524326443.779,,0.000000e+000,5.500103e+001,-3.684159e-006,0.000000e+000,2,5.706252e-001,0.000000e+000,,,,,,,,,,,,,,32,1,4.000000e+000,2.639771e-003,0.000000e+000,0,,0,
1524326481.719,,0.000000e+000,5.499511e+001,-3.585149e-006,0.000000e+000,2,5.894645e-001,0.000000e+000,,,,,,,,,,,,,,32,1,4.000000e+000,1.319885e-003,0.000000e+000,0,,0,
1524326519.369,,0.000000e+000,5.499445e+001,-3.599022e-006,0.000000e+000,2,5.606642e-001,0.000000e+000,,,,,,,,,,,,,,32,1,4.000000e+000,5.260468e-003,0.000000e+000,0,,0,
1524326556.759,,0.000000e+000,5.499774e+001,-3.543829e-006,0.000000e+000,2,5.747995e-001,0.000000e+000,,,,,,,,,,,,,,32,1,4.000000e+000,3.940582e-003,0.000000e+000,0,,0,
1524326594.039,,0.000000e+000,5.499445e+001,-3.471016e-006,0.000000e+000,2,5.463191e-001,0.000000e+000,,,,,,,,,,,,,,32,1,4.000000e+000,0.000000e+000,0.000000e+000,0,,0,
1524326631.979,,0.000000e+000,5.500300e+001,-3.456430e-006,0.000000e+000,2,5.725739e-001,0.000000e+000,,,,,,,,,,,,,,32,1,4.000000e+000,6.580353e-003,0.000000e+000,0,,0,
1524326670.869,,0.000000e+000,5.499972e+001,-3.454305e-006,0.000000e+000,2,5.721967e-001,0.000000e+000,,,,,,,,,,,,,,32,1,4.000000e+000,1.314926e-002,0.000000e+000,0,,0,
1524326708.289,,0.000000e+000,5.499445e+001,-3.394278e-006,0.000000e+000,2,5.439012e-001,0.000000e+000,,,,,,,,,,,,,,32,1,4.000000e+000,5.260468e-003,0.000000e+000,0,,0,
1524326745.659,,0.000000e+000,5.499775e+001,-3.274665e-006,0.000000e+000,2,5.413164e-001,0.000000e+000,,,,,,,,,,,,,,32,1,4.000000e+000,1.184845e-002,0.000000e+000,0,,0,
1524326783.559,,0.000000e+000,5.499445e+001,-3.322646e-006,0.000000e+000,2,5.485969e-001,0.000000e+000,,,,,,,,,,,,,,32,1,4.000000e+000,5.260468e-003,0.000000e+000,0,,0,
1524326821.129,,0.000000e+000,5.499511e+001,-3.223465e-006,0.000000e+000,2,5.132468e-001,0.000000e+000,,,,,,,,,,,,,,32,1,4.000000e+000,9.201050e-003,0.000000e+000,0,,0,
1524326859.209,,0.000000e+000,5.499643e+001,-3.212180e-006,0.000000e+000,2,5.264723e-001,0.000000e+000,,,,,,,,,,,,,,32,1,4.000000e+000,1.312256e-003,0.000000e+000,0,,0,
1524326897.219,,0.000000e+000,5.499511e+001,-3.154737e-006,0.000000e+000,2,5.008468e-001,0.000000e+000,,,,,,,,,,,,,,32,1,4.000000e+000,1.319885e-003,0.000000e+000,0,,0,
1524326935.149,,0.000000e+000,5.499971e+001,-3.121874e-006,0.000000e+000,2,5.052586e-001,0.000000e+000,,,,,,,,,,,,,,32,1,4.000000e+000,1.052094e-002,0.000000e+000,0,,0,
1524326972.910,,0.000000e+000,5.499905e+001,-3.110559e-006,0.000000e+000,2,5.101810e-001,0.000000e+000,,,,,,,,,,,,,,32,1,4.000000e+000,3.948212e-003,0.000000e+000,0,,0,
1524327010.760,,0.000000e+000,5.500169e+001,-3.020548e-006,0.000000e+000,2,4.904108e-001,0.000000e+000,,,,,,,,,,,,,,32,1,4.000000e+000,1.184082e-002,0.000000e+000,0,,0,
1524327049.410,,0.000000e+000,5.499642e+001,-2.963661e-006,0.000000e+000,2,4.933423e-001,0.000000e+000,,,,,,,,,,,,,,32,1,4.000000e+000,3.940582e-003,0.000000e+000,0,,0,
1524327087.340,,0.000000e+000,5.499773e+001,-2.943912e-006,0.000000e+000,2,4.912277e-001,0.000000e+000,,,,,,,,,,,,,,32,1,4.000000e+000,1.308441e-003,0.000000e+000,0,,0,
1524327125.240,,0.000000e+000,5.499971e+001,-2.969517e-006,0.000000e+000,2,4.839228e-001,0.000000e+000,,,,,,,,,,,,,,32,1,4.000000e+000,2.639771e-003,0.000000e+000,0,,0,
1524327162.680,,0.000000e+000,5.500103e+001,-2.891536e-006,0.000000e+000,2,4.885212e-001,0.000000e+000,,,,,,,,,,,,,,32,1,4.000000e+000,0.000000e+000,0.000000e+000,0,,0,
1524327200.030,,0.000000e+000,5.500037e+001,-2.807619e-006,0.000000e+000,2,4.231076e-001,0.000000e+000,,,,,,,,,,,,,,32,1,4.000000e+000,3.959656e-003,0.000000e+000,0,,0,
1524327237.190,,0.000000e+000,5.499643e+001,-2.771079e-006,0.000000e+000,2,4.585774e-001,0.000000e+000,,,,,,,,,,,,,,32,1,4.000000e+000,1.312256e-003,0.000000e+000,0,,0,
1524327274.290,,0.000000e+000,5.499117e+001,-2.785749e-006,0.000000e+000,2,4.443052e-001,0.000000e+000,,,,,,,,,,,,,,32,1,4.000000e+000,1.708984e-002,0.000000e+000,0,,0,
1524327311.830,,0.000000e+000,5.500103e+001,-2.810869e-006,0.000000e+000,2,4.643512e-001,0.000000e+000,,,,,,,,,,,,,,32,1,4.000000e+000,7.888794e-003,0.000000e+000,0,,0,
1524327349.140,,0.000000e+000,5.499972e+001,-2.734721e-006,0.000000e+000,2,4.489836e-001,0.000000e+000,,,,,,,,,,,,,,32,1,4.000000e+000,5.268097e-003,0.000000e+000,0,,0,
1524327387.470,,0.000000e+000,5.499774e+001,-2.715572e-006,0.000000e+000,2,4.263212e-001,0.000000e+000,,,,,,,,,,,,,,32,1,4.000000e+000,6.580353e-003,0.000000e+000,0,,0,
1524327424.720,,0.000000e+000,5.500037e+001,-2.649699e-006,0.000000e+000,2,4.266080e-001,0.000000e+000,,,,,,,,,,,,,,32,1,4.000000e+000,3.959656e-003,0.000000e+000,0,,0,
1524327462.530,,0.000000e+000,5.500103e+001,-2.630847e-006,0.000000e+000,2,3.944720e-001,0.000000e+000,,,,,,,,,,,,,,32,1,4.000000e+000,2.639771e-003,0.000000e+000,0,,0,
1524327500.100,,0.000000e+000,5.499708e+001,-2.632230e-006,0.000000e+000,2,4.208482e-001,0.000000e+000,,,,,,,,,,,,,,32,1,4.000000e+000,2.620697e-003,0.000000e+000,0,,0,
1524327537.490,,0.000000e+000,5.499445e+001,-2.560304e-006,0.000000e+000,2,3.785478e-001,0.000000e+000,,,,,,,,,,,,,,32,1,4.000000e+000,1.578903e-002,0.000000e+000,0,,0,
1524327576.270,,0.000000e+000,5.500301e+001,-2.539851e-006,0.000000e+000,2,3.727182e-001,0.000000e+000,,,,,,,,,,,,,,32,1,4.000000e+000,1.319885e-003,0.000000e+000,0,,0,
1524327614.510,,0.000000e+000,5.499905e+001,-2.472826e-006,0.000000e+000,2,3.682667e-001,0.000000e+000,,,,,,,,,,,,,,32,1,4.000000e+000,3.948212e-003,0.000000e+000,0,,0,
1524327652.260,,0.000000e+000,5.499709e+001,-2.463203e-006,0.000000e+000,2,3.888149e-001,0.000000e+000,,,,,,,,,,,,,,32,1,4.000000e+000,7.888794e-003,0.000000e+000,0,,0,
1524327690.081,,0.000000e+000,5.499709e+001,-2.486778e-006,0.000000e+000,2,3.569692e-001,0.000000e+000,,,,,,,,,,,,,,32,1,4.000000e+000,7.888794e-003,0.000000e+000,0,,0,
1524327727.521,,0.000000e+000,5.499577e+001,-2.451648e-006,0.000000e+000,2,3.931663e-001,0.000000e+000,,,,,,,,,,,,,,32,1,4.000000e+000,7.888794e-003,0.000000e+000,0,,0,
1524327765.151,,0.000000e+000,5.499643e+001,-2.378970e-006,0.000000e+000,2,3.311045e-001,0.000000e+000,,,,,,,,,,,,,,32,1,4.000000e+000,9.208679e-003,0.000000e+000,0,,0,
1524327803.661,,0.000000e+000,5.499840e+001,-2.368100e-006,0.000000e+000,2,3.510924e-001,0.000000e+000,,,,,,,,,,,,,,32,1,4.000000e+000,2.628326e-003,0.000000e+000,0,,0,
1524327840.481,,0.000000e+000,5.499709e+001,-2.373010e-006,0.000000e+000,2,3.222554e-001,0.000000e+000,,,,,,,,,,,,,,32,1,4.000000e+000,1.840973e-002,0.000000e+000,0,,0,
1524327877.631,,0.000000e+000,5.499511e+001,-2.294441e-006,0.000000e+000,2,3.437148e-001,0.000000e+000,,,,,,,,,,,,,,32,1,4.000000e+000,3.940582e-003,0.000000e+000,0,,0,
1524327915.071,,0.000000e+000,5.500234e+001,-2.320424e-006,0.000000e+000,2,3.256346e-001,0.000000e+000,,,,,,,,,,,,,,32,1,4.000000e+000,7.900238e-003,0.000000e+000,0,,0,
1524327952.231,,0.000000e+000,5.499773e+001,-2.221088e-006,0.000000e+000,2,3.284669e-001,0.000000e+000,,,,,,,,,,,,,,32,1,4.000000e+000,1.308441e-003,0.000000e+000,0,,0,
1524327990.441,,0.000000e+000,5.499905e+001,-2.186393e-006,0.000000e+000,2,2.519405e-001,0.000000e+000,,,,,,,,,,,,,,32,1,4.000000e+000,3.948212e-003,0.000000e+000,0,,0,
1524328027.741,,0.000000e+000,5.500301e+001,-2.226227e-006,0.000000e+000,2,3.438931e-001,0.000000e+000,,,,,,,,,,,,,,32,1,4.000000e+000,1.972961e-002,0.000000e+000,0,,0,
1524328065.381,,0.000000e+000,5.501024e+001,-2.126131e-006,0.000000e+000,2,2.742072e-001,0.000000e+000,,,,,,,,,,,,,,32,1,4.000000e+000,0.000000e+000,0.000000e+000,0,,0,
1524328103.141,,0.000000e+000,5.500301e+001,-2.189613e-006,0.000000e+000,2,3.072726e-001,0.000000e+000,,,,,,,,,,,,,,32,1,4.000000e+000,1.319885e-003,0.000000e+000,0,,0,
1524328141.511,,0.000000e+000,5.499972e+001,-2.057678e-006,0.000000e+000,2,2.380997e-001,0.000000e+000,,,,,,,,,,,,,,32,1,4.000000e+000,5.268097e-003,0.000000e+000,0,,0,
1524328179.531,,0.000000e+000,5.499971e+001,-2.075117e-006,0.000000e+000,2,2.706161e-001,0.000000e+000,,,,,,,,,,,,,,32,1,4.000000e+000,2.639771e-003,0.000000e+000,0,,0,
1524328217.101,,0.000000e+000,5.499773e+001,-2.050770e-006,0.000000e+000,2,2.235966e-001,0.000000e+000,,,,,,,,,,,,,,32,1,4.000000e+000,1.308441e-003,0.000000e+000,0,,0,
1524328255.141,,0.000000e+000,5.499445e+001,-2.062262e-006,0.000000e+000,2,2.637211e-001,0.000000e+000,,,,,,,,,,,,,,32,1,4.000000e+000,2.628326e-003,0.000000e+000,0,,0,
1524328293.161,,0.000000e+000,5.500037e+001,-1.999357e-006,0.000000e+000,2,2.006994e-001,0.000000e+000,,,,,,,,,,,,,,32,1,4.000000e+000,6.587982e-003,0.000000e+000,0,,0,
1524328330.651,,0.000000e+000,5.499643e+001,-2.016774e-006,0.000000e+000,2,2.391714e-001,0.000000e+000,,,,,,,,,,,,,,32,1,4.000000e+000,1.312256e-003,0.000000e+000,0,,0,
1524328367.521,,0.000000e+000,5.500432e+001,-1.957759e-006,0.000000e+000,2,2.009300e-001,0.000000e+000,,,,,,,,,,,,,,32,1,4.000000e+000,1.300812e-003,0.000000e+000,0,,0,
1524328405.222,,0.000000e+000,5.499182e+001,-1.939110e-006,0.000000e+000,2,1.986724e-001,0.000000e+000,,,,,,,,,,,,,,32,1,4.000000e+000,5.260468e-003,0.000000e+000,0,,0,
1524328443.282,,0.000000e+000,5.499905e+001,-1.875347e-006,0.000000e+000,2,1.442266e-001,0.000000e+000,,,,,,,,,,,,,,32,1,4.000000e+000,1.319885e-003,0.000000e+000,0,,0,
1524328480.812,,0.000000e+000,5.499774e+001,-1.874533e-006,0.000000e+000,2,1.945527e-001,0.000000e+000,,,,,,,,,,,,,,32,1,4.000000e+000,3.940582e-003,0.000000e+000,0,,0,
1524328519.252,,0.000000e+000,5.499577e+001,-1.899191e-006,0.000000e+000,2,1.832341e-001,0.000000e+000,,,,,,,,,,,,,,32,1,4.000000e+000,0.000000e+000,0.000000e+000,0,,0,
1524328557.212,,0.000000e+000,5.500432e+001,-1.826580e-006,0.000000e+000,2,1.381516e-001,0.000000e+000,,,,,,,,,,,,,,32,1,4.000000e+000,1.300812e-003,0.000000e+000,0,,0,
1524328594.942,,0.000000e+000,5.499840e+001,-1.854217e-006,0.000000e+000,2,1.822416e-001,0.000000e+000,,,,,,,,,,,,,,32,1,4.000000e+000,7.900238e-003,0.000000e+000,0,,0,
1524328632.792,,0.000000e+000,5.499642e+001,-1.814428e-006,0.000000e+000,2,1.654273e-001,0.000000e+000,,,,,,,,,,,,,,32,1,4.000000e+000,3.940582e-003,0.000000e+000,0,,0,
1524328671.152,,0.000000e+000,5.500366e+001,-1.743376e-006,0.000000e+000,2,7.667129e-002,0.000000e+000,,,,,,,,,,,,,,32,1,4.000000e+000,1.315689e-002,0.000000e+000,0,,0,
1524328708.872,,0.000000e+000,5.499906e+001,-1.803852e-006,0.000000e+000,2,1.278878e-001,0.000000e+000,,,,,,,,,,,,,,32,1,4.000000e+000,6.580353e-003,0.000000e+000,0,,0,
1524328747.072,,0.000000e+000,5.499905e+001,-1.736565e-006,0.000000e+000,2,1.205563e-001,0.000000e+000,,,,,,,,,,,,,,32,1,4.000000e+000,1.319885e-003,0.000000e+000,0,,0,
1524328784.642,,0.000000e+000,5.499380e+001,-1.703540e-006,0.000000e+000,2,4.673116e-002,0.000000e+000,,,,,,,,,,,,,,32,1,4.000000e+000,3.948212e-003,0.000000e+000,0,,0,
1524328822.602,,0.000000e+000,5.499643e+001,-1.620486e-006,0.000000e+000,2,4.455589e-002,0.000000e+000,,,,,,,,,,,,,,32,1,4.000000e+000,9.208679e-003,0.000000e+000,0,,0,
1524328861.032,,0.000000e+000,5.500037e+001,-1.780225e-006,0.000000e+000,2,1.563348e-001,0.000000e+000,,,,,,,,,,,,,,32,1,4.000000e+000,1.184082e-002,0.000000e+000,0,,0,
1524328898.652,,0.000000e+000,5.500432e+001,-1.600437e-006,0.000000e+000,2,1.936547e-003,0.000000e+000,,,,,,,,,,,,,,32,1,4.000000e+000,1.300812e-003,0.000000e+000,0,,0,
1524328936.102,,0.000000e+000,5.499642e+001,-1.620507e-006,0.000000e+000,2,7.431620e-002,0.000000e+000,,,,,,,,,,,,,,32,1,4.000000e+000,3.940582e-003,0.000000e+000,0,,0,
1524328973.672,,0.000000e+000,5.499840e+001,-1.599274e-006,0.000000e+000,2,1.932354e-002,0.000000e+000,,,,,,,,,,,,,,32,1,4.000000e+000,5.260468e-003,0.000000e+000,0,,0,
1524329011.422,,0.000000e+000,5.500366e+001,-1.548601e-006,0.000000e+000,2,1.043607e-002,0.000000e+000,,,,,,,,,,,,,,32,1,4.000000e+000,5.260468e-003,0.000000e+000,0,,0,
1524329050.462,,0.000000e+000,5.499905e+001,-1.540303e-006,0.000000e+000,2,7.623907e-003,0.000000e+000,,,,,,,,,,,,,,32,1,4.000000e+000,3.948212e-003,0.000000e+000,0,,0,
1524329088.642,,0.000000e+000,5.499773e+001,-1.543036e-006,0.000000e+000,2,4.246792e-002,0.000000e+000,,,,,,,,,,,,,,32,1,4.000000e+000,1.308441e-003,0.000000e+000,0,,0,
1524329126.943,,0.000000e+000,5.500037e+001,-1.558655e-006,0.000000e+000,2,0.000000e+000,0.000000e+000,,,,,,,,,,,,,,32,1,4.000000e+000,3.959656e-003,0.000000e+000,0,,0,
1524329164.733,,0.000000e+000,5.499971e+001,-1.479293e-006,0.000000e+000,2,0.000000e+000,0.000000e+000,,,,,,,,,,,,,,32,1,4.000000e+000,2.639771e-003,0.000000e+000,0,,0,
1524329203.033,,0.000000e+000,5.499773e+001,-1.562707e-006,0.000000e+000,2,1.316493e-003,0.000000e+000,,,,,,,,,,,,,,32,1,4.000000e+000,1.308441e-003,0.000000e+000,0,,0,
1524329240.503,,0.000000e+000,5.499773e+001,-1.519104e-006,0.000000e+000,2,0.000000e+000,0.000000e+000,,,,,,,,,,,,,,32,1,4.000000e+000,1.308441e-003,0.000000e+000,0,,0,
1524329278.143,,0.000000e+000,5.499643e+001,-1.535798e-006,0.000000e+000,2,0.000000e+000,0.000000e+000,,,,,,,,,,,,,,32,1,4.000000e+000,1.312256e-003,0.000000e+000,0,,0,
1524329315.743,,0.000000e+000,5.499839e+001,-1.445279e-006,0.000000e+000,2,0.000000e+000,0.000000e+000,,,,,,,,,,,,,,32,1,4.000000e+000,0.000000e+000,0.000000e+000,0,,0,
1524329352.833,,0.000000e+000,5.500366e+001,-1.395225e-006,0.000000e+000,2,0.000000e+000,0.000000e+000,,,,,,,,,,,,,,32,1,4.000000e+000,7.900238e-003,0.000000e+000,0,,0,
1524329390.303,,0.000000e+000,5.500367e+001,-1.341145e-006,0.000000e+000,2,0.000000e+000,0.000000e+000,,,,,,,,,,,,,,32,1,4.000000e+000,0.000000e+000,0.000000e+000,0,,0,
1524329427.843,,0.000000e+000,5.500037e+001,-1.361683e-006,0.000000e+000,2,0.000000e+000,0.000000e+000,,,,,,,,,,,,,,32,1,4.000000e+000,3.959656e-003,0.000000e+000,0,,0,
1524329465.933,,0.000000e+000,5.500037e+001,-1.356437e-006,0.000000e+000,2,0.000000e+000,0.000000e+000,,,,,,,,,,,,,,32,1,4.000000e+000,1.319885e-003,0.000000e+000,0,,0,
1524329503.233,,0.000000e+000,5.500301e+001,-1.317296e-006,0.000000e+000,2,0.000000e+000,0.000000e+000,,,,,,,,,,,,,,32,1,4.000000e+000,1.319885e-003,0.000000e+000,0,,0,
1524329540.973,,0.000000e+000,5.499972e+001,-1.317262e-006,0.000000e+000,2,0.000000e+000,0.000000e+000,,,,,,,,,,,,,,32,1,4.000000e+000,7.900238e-003,0.000000e+000,0,,0,
1524329578.663,,0.000000e+000,5.499445e+001,-1.285138e-006,0.000000e+000,2,0.000000e+000,0.000000e+000,,,,,,,,,,,,,,32,1,4.000000e+000,5.260468e-003,0.000000e+000,0,,0,
1524329616.583,,0.000000e+000,5.499905e+001,-1.257879e-006,0.000000e+000,2,0.000000e+000,0.000000e+000,,,,,,,,,,,,,,32,1,4.000000e+000,3.948212e-003,0.000000e+000,0,,0,
1524329654.193,,0.000000e+000,5.499643e+001,-1.223079e-006,0.000000e+000,2,0.000000e+000,0.000000e+000,,,,,,,,,,,,,,32,1,4.000000e+000,9.208679e-003,0.000000e+000,0,,0,
1524329691.643,,0.000000e+000,5.499773e+001,-1.248448e-006,0.000000e+000,2,0.000000e+000,0.000000e+000,,,,,,,,,,,,,,32,1,4.000000e+000,1.308441e-003,0.000000e+000,0,,0,
1524329729.313,,0.000000e+000,5.499577e+001,-1.239895e-006,0.000000e+000,2,0.000000e+000,0.000000e+000,,,,,,,,,,,,,,32,1,4.000000e+000,0.000000e+000,0.000000e+000,0,,0,
1524329767.233,,0.000000e+000,5.499511e+001,-1.192250e-006,0.000000e+000,2,0.000000e+000,0.000000e+000,,,,,,,,,,,,,,32,1,4.000000e+000,1.184082e-002,0.000000e+000,0,,0,
1524329804.893,,0.000000e+000,5.499774e+001,-1.165719e-006,0.000000e+000,2,0.000000e+000,0.000000e+000,,,,,,,,,,,,,,32,1,4.000000e+000,6.580353e-003,0.000000e+000,0,,0,
1524329842.874,,0.000000e+000,5.500235e+001,-1.169883e-006,0.000000e+000,2,0.000000e+000,0.000000e+000,,,,,,,,,,,,,,32,1,4.000000e+000,2.639771e-003,0.000000e+000,0,,0,
1524329880.504,,0.000000e+000,5.499905e+001,-1.153609e-006,0.000000e+000,2,0.000000e+000,0.000000e+000,,,,,,,,,,,,,,32,1,4.000000e+000,3.948212e-003,0.000000e+000,0,,0,
1524329918.434,,0.000000e+000,5.499774e+001,-1.118735e-006,0.000000e+000,2,0.000000e+000,0.000000e+000,,,,,,,,,,,,,,32,1,4.000000e+000,3.940582e-003,0.000000e+000,0,,0,
1524329956.144,,0.000000e+000,5.500037e+001,-1.120007e-006,0.000000e+000,2,0.000000e+000,0.000000e+000,,,,,,,,,,,,,,32,1,4.000000e+000,1.319885e-003,0.000000e+000,0,,0,
1524329994.474,,0.000000e+000,5.500103e+001,-1.044262e-006,0.000000e+000,2,0.000000e+000,0.000000e+000,,,,,,,,,,,,,,32,1,4.000000e+000,0.000000e+000,0.000000e+000,0,,0,
1524330032.164,,0.000000e+000,5.499182e+001,-1.113504e-006,0.000000e+000,2,0.000000e+000,0.000000e+000,,,,,,,,,,,,,,32,1,4.000000e+000,0.000000e+000,0.000000e+000,0,,0,
1524330070.114,,0.000000e+000,5.500103e+001,-1.058129e-006,0.000000e+000,2,0.000000e+000,0.000000e+000,,,,,,,,,,,,,,32,1,4.000000e+000,0.000000e+000,0.000000e+000,0,,0,
1524330108.014,,0.000000e+000,5.499840e+001,-9.972321e-007,0.000000e+000,2,0.000000e+000,0.000000e+000,,,,,,,,,,,,,,32,1,4.000000e+000,2.628326e-003,0.000000e+000,0,,0,
1524330145.654,,0.000000e+000,5.500300e+001,-9.787760e-007,0.000000e+000,2,0.000000e+000,0.000000e+000,,,,,,,,,,,,,,32,1,4.000000e+000,6.580353e-003,0.000000e+000,0,,0,
1524330183.824,,0.000000e+000,5.499183e+001,-9.938775e-007,0.000000e+000,2,0.000000e+000,0.000000e+000,,,,,,,,,,,,,,32,1,4.000000e+000,2.632141e-003,0.000000e+000,0,,0,
1524330221.784,,0.000000e+000,5.500432e+001,-1.067908e-006,0.000000e+000,2,0.000000e+000,0.000000e+000,,,,,,,,,,,,,,32,1,4.000000e+000,6.580353e-003,0.000000e+000,0,,0,
1524330259.464,,0.000000e+000,5.499577e+001,-9.762848e-007,0.000000e+000,2,0.000000e+000,0.000000e+000,,,,,,,,,,,,,,32,1,4.000000e+000,5.249023e-003,0.000000e+000,0,,0,
1524330296.924,,0.000000e+000,5.499577e+001,-9.712918e-007,0.000000e+000,2,0.000000e+000,0.000000e+000,,,,,,,,,,,,,,32,1,4.000000e+000,0.000000e+000,0.000000e+000,0,,0,
1524330334.514,,0.000000e+000,5.499906e+001,-9.829853e-007,0.000000e+000,2,0.000000e+000,0.000000e+000,,,,,,,,,,,,,,32,1,4.000000e+000,6.580353e-003,0.000000e+000,0,,0,
1524330372.424,,0.000000e+000,5.499643e+001,-9.673360e-007,0.000000e+000,2,0.000000e+000,0.000000e+000,,,,,,,,,,,,,,32,1,4.000000e+000,6.568909e-003,0.000000e+000,0,,0,
1524330410.664,,0.000000e+000,5.499906e+001,-1.002361e-006,0.000000e+000,2,0.000000e+000,0.000000e+000,,,,,,,,,,,,,,32,1,4.000000e+000,9.220123e-003,0.000000e+000,0,,0,
1524330448.154,,0.000000e+000,5.499971e+001,-9.078322e-007,0.000000e+000,2,0.000000e+000,0.000000e+000,,,,,,,,,,,,,,32,1,4.000000e+000,0.000000e+000,0.000000e+000,0,,0,
1524330485.564,,0.000000e+000,5.499773e+001,-9.049904e-007,0.000000e+000,2,0.000000e+000,0.000000e+000,,,,,,,,,,,,,,32,1,4.000000e+000,1.308441e-003,0.000000e+000,0,,0,
1524330523.224,,0.000000e+000,5.499313e+001,-8.943028e-007,0.000000e+000,2,0.000000e+000,0.000000e+000,,,,,,,,,,,,,,32,1,4.000000e+000,7.892609e-003,0.000000e+000,0,,0,
1524330561.775,,0.000000e+000,5.499840e+001,-8.438776e-007,0.000000e+000,2,0.000000e+000,0.000000e+000,,,,,,,,,,,,,,32,1,4.000000e+000,2.628326e-003,0.000000e+000,0,,0,
1524330599.595,,0.000000e+000,5.500300e+001,-8.636467e-007,0.000000e+000,2,0.000000e+000,0.000000e+000,,,,,,,,,,,,,,32,1,4.000000e+000,9.220123e-003,0.000000e+000,0,,0,
1524330636.565,,0.000000e+000,5.499906e+001,-8.246822e-007,0.000000e+000,2,0.000000e+000,0.000000e+000,,,,,,,,,,,,,,32,1,4.000000e+000,6.580353e-003,0.000000e+000,0,,0,
1524330674.575,,0.000000e+000,5.500103e+001,-8.034174e-007,0.000000e+000,2,0.000000e+000,0.000000e+000,,,,,,,,,,,,,,32,1,4.000000e+000,5.279541e-003,0.000000e+000,0,,0,
1524330712.745,,0.000000e+000,5.500103e+001,-8.674692e-007,0.000000e+000,2,0.000000e+000,0.000000e+000,,,,,,,,,,,,,,32,1,4.000000e+000,2.639771e-003,0.000000e+000,0,,0,
1524330751.375,,0.000000e+000,5.499577e+001,-8.073602e-007,0.000000e+000,2,0.000000e+000,0.000000e+000,,,,,,,,,,,,,,32,1,4.000000e+000,2.632141e-003,0.000000e+000,0,,0,
1524330788.735,,0.000000e+000,5.499774e+001,-7.989841e-007,0.000000e+000,2,0.000000e+000,0.000000e+000,,,,,,,,,,,,,,32,1,4.000000e+000,6.580353e-003,0.000000e+000,0,,0,
1524330826.765,,0.000000e+000,5.500234e+001,-7.487383e-007,0.000000e+000,2,0.000000e+000,0.000000e+000,,,,,,,,,,,,,,32,1,4.000000e+000,5.260468e-003,0.000000e+000,0,,0,
1524330864.605,,0.000000e+000,5.499971e+001,-7.374330e-007,0.000000e+000,2,0.000000e+000,0.000000e+000,,,,,,,,,,,,,,32,1,4.000000e+000,2.639771e-003,0.000000e+000,0,,0,
1524330902.435,,0.000000e+000,5.499380e+001,-8.317778e-007,0.000000e+000,2,0.000000e+000,0.000000e+000,,,,,,,,,,,,,,32,1,4.000000e+000,1.308441e-003,0.000000e+000,0,,0,
1524330940.175,,0.000000e+000,5.499971e+001,-7.141041e-007,0.000000e+000,2,0.000000e+000,0.000000e+000,,,,,,,,,,,,,,32,1,4.000000e+000,2.639771e-003,0.000000e+000,0,,0,
1524330978.165,,0.000000e+000,5.500301e+001,-7.605973e-007,0.000000e+000,2,0.000000e+000,0.000000e+000,,,,,,,,,,,,,,32,1,4.000000e+000,1.319885e-003,0.000000e+000,0,,0,
1524331015.745,,0.000000e+000,5.499773e+001,-7.186363e-007,0.000000e+000,2,0.000000e+000,0.000000e+000,,,,,,,,,,,,,,32,1,4.000000e+000,1.308441e-003,0.000000e+000,0,,0,
1524331053.775,,0.000000e+000,5.499774e+001,-6.993968e-007,0.000000e+000,2,0.000000e+000,0.000000e+000,,,,,,,,,,,,,,32,1,4.000000e+000,1.446152e-002,0.000000e+000,0,,0,
1524331091.315,,0.000000e+000,5.499445e+001,-6.848501e-007,0.000000e+000,2,0.000000e+000,0.000000e+000,,,,,,,,,,,,,,32,1,4.000000e+000,1.052094e-002,0.000000e+000,0,,0,
1524331129.405,,0.000000e+000,5.500169e+001,-6.835574e-007,0.000000e+000,2,0.000000e+000,0.000000e+000,,,,,,,,,,,,,,32,1,4.000000e+000,3.959656e-003,0.000000e+000,0,,0,
1524331166.975,,0.000000e+000,5.499905e+001,-6.686565e-007,0.000000e+000,2,0.000000e+000,0.000000e+000,,,,,,,,,,,,,,32,1,4.000000e+000,1.319885e-003,0.000000e+000,0,,0,
1524331205.015,,0.000000e+000,5.499709e+001,-6.397963e-007,0.000000e+000,2,0.000000e+000,0.000000e+000,,,,,,,,,,,,,,32,1,4.000000e+000,1.052856e-002,0.000000e+000,0,,0,
1524331242.635,,0.000000e+000,5.499972e+001,-5.539864e-007,0.000000e+000,2,0.000000e+000,0.000000e+000,,,,,,,,,,,,,,32,1,4.000000e+000,5.268097e-003,0.000000e+000,0,,0,
1524331305.906,,0.000000e+000,5.500103e+001,-6.390305e-007,0.000000e+000,2,0.000000e+000,0.000000e+000,,,,,,,,,,,,,,32,1,4.000000e+000,1.316071e-002,0.000000e+000,0,,0,
1524331343.416,,0.000000e+000,5.499577e+001,-6.549280e-007,0.000000e+000,2,0.000000e+000,0.000000e+000,,,,,,,,,,,,,,32,1,4.000000e+000,0.000000e+000,0.000000e+000,0,,0,
1524331381.446,,0.000000e+000,5.499972e+001,-6.104858e-007,0.000000e+000,2,0.000000e+000,0.000000e+000,,,,,,,,,,,,,,32,1,4.000000e+000,5.268097e-003,0.000000e+000,0,,0,
1524331418.876,,0.000000e+000,5.499445e+001,-5.161339e-007,0.000000e+000,2,0.000000e+000,0.000000e+000,,,,,,,,,,,,,,32,1,4.000000e+000,1.578903e-002,0.000000e+000,0,,0,
1524331456.646,,0.000000e+000,5.499643e+001,-5.695878e-007,0.000000e+000,2,0.000000e+000,0.000000e+000,,,,,,,,,,,,,,32,1,4.000000e+000,1.312256e-003,0.000000e+000,0,,0,
1524331494.236,,0.000000e+000,5.499906e+001,-5.691358e-007,0.000000e+000,2,0.000000e+000,0.000000e+000,,,,,,,,,,,,,,32,1,4.000000e+000,9.220123e-003,0.000000e+000,0,,0,
1524331531.686,,0.000000e+000,5.500235e+001,-5.262276e-007,0.000000e+000,2,0.000000e+000,0.000000e+000,,,,,,,,,,,,,,32,1,4.000000e+000,0.000000e+000,0.000000e+000,0,,0,
1524331569.866,,0.000000e+000,5.499512e+001,-4.499579e-007,0.000000e+000,2,0.000000e+000,0.000000e+000,,,,,,,,,,,,,,32,1,4.000000e+000,1.710892e-002,0.000000e+000,0,,0,
1524331607.006,,0.000000e+000,5.499577e+001,-4.170583e-007,0.000000e+000,2,0.000000e+000,0.000000e+000,,,,,,,,,,,,,,32,1,4.000000e+000,7.888794e-003,0.000000e+000,0,,0,
1524331644.516,,0.000000e+000,5.500300e+001,-5.779143e-007,0.000000e+000,2,0.000000e+000,0.000000e+000,,,,,,,,,,,,,,32,1,4.000000e+000,3.940582e-003,0.000000e+000,0,,0,
1524331682.396,,0.000000e+000,5.499774e+001,-5.015179e-007,0.000000e+000,2,0.000000e+000,0.000000e+000,,,,,,,,,,,,,,32,1,4.000000e+000,6.580353e-003,0.000000e+000,0,,0,
1524331720.366,,0.000000e+000,5.499708e+001,-5.355100e-007,0.000000e+000,2,0.000000e+000,0.000000e+000,,,,,,,,,,,,,,32,1,4.000000e+000,2.620697e-003,0.000000e+000,0,,0,
1524331757.966,,0.000000e+000,5.499774e+001,-4.558334e-007,0.000000e+000,2,0.000000e+000,0.000000e+000,,,,,,,,,,,,,,32,1,4.000000e+000,6.580353e-003,0.000000e+000,0,,0,
1524331795.956,,0.000000e+000,5.499445e+001,-5.261272e-007,0.000000e+000,2,0.000000e+000,0.000000e+000,,,,,,,,,,,,,,32,1,4.000000e+000,1.052094e-002,0.000000e+000,0,,0,
1524331833.566,,0.000000e+000,5.500037e+001,-4.210324e-007,0.000000e+000,2,0.000000e+000,0.000000e+000,,,,,,,,,,,,,,32,1,4.000000e+000,1.319885e-003,0.000000e+000,0,,0,
1524331871.536,,0.000000e+000,5.500037e+001,-4.788089e-007,0.000000e+000,2,0.000000e+000,0.000000e+000,,,,,,,,,,,,,,32,1,4.000000e+000,1.319885e-003,0.000000e+000,0,,0,
1524331909.416,,0.000000e+000,5.499642e+001,-4.127055e-007,0.000000e+000,2,0.000000e+000,0.000000e+000,,,,,,,,,,,,,,32,1,4.000000e+000,3.940582e-003,0.000000e+000,0,,0,
1524331947.156,,0.000000e+000,5.499708e+001,-3.988343e-007,0.000000e+000,2,0.000000e+000,0.000000e+000,,,,,,,,,,,,,,32,1,4.000000e+000,2.620697e-003,0.000000e+000,0,,0,
1524331984.737,,0.000000e+000,5.499577e+001,-3.974886e-007,0.000000e+000,2,0.000000e+000,0.000000e+000,,,,,,,,,,,,,,32,1,4.000000e+000,2.632141e-003,0.000000e+000,0,,0,
1524332022.427,,0.000000e+000,5.500037e+001,-3.595646e-007,0.000000e+000,2,0.000000e+000,0.000000e+000,,,,,,,,,,,,,,32,1,4.000000e+000,1.184082e-002,0.000000e+000,0,,0,
1524332060.737,,0.000000e+000,5.499643e+001,-4.403612e-007,0.000000e+000,2,0.000000e+000,0.000000e+000,,,,,,,,,,,,,,32,1,4.000000e+000,1.708984e-002,0.000000e+000,0,,0,
1524332097.827,,0.000000e+000,5.500235e+001,-3.066307e-007,0.000000e+000,2,0.000000e+000,0.000000e+000,,,,,,,,,,,,,,32,1,4.000000e+000,2.639771e-003,0.000000e+000,0,,0,
1524332135.887,,0.000000e+000,5.500498e+001,-3.389733e-007,0.000000e+000,2,0.000000e+000,0.000000e+000,,,,,,,,,,,,,,32,1,4.000000e+000,2.620697e-003,0.000000e+000,0,,0,
1524332173.427,,0.000000e+000,5.499905e+001,-3.319210e-007,0.000000e+000,2,0.000000e+000,0.000000e+000,,,,,,,,,,,,,,32,1,4.000000e+000,1.319885e-003,0.000000e+000,0,,0,
1524332211.497,,0.000000e+000,5.499577e+001,-3.578397e-007,0.000000e+000,2,0.000000e+000,0.000000e+000,,,,,,,,,,,,,,32,1,4.000000e+000,2.632141e-003,0.000000e+000,0,,0,
1524332249.067,,0.000000e+000,5.499511e+001,-2.638604e-007,0.000000e+000,2,0.000000e+000,0.000000e+000,,,,,,,,,,,,,,32,1,4.000000e+000,1.319885e-003,0.000000e+000,0,,0,
1524332286.557,,0.000000e+000,5.499380e+001,-3.348647e-007,0.000000e+000,2,0.000000e+000,0.000000e+000,,,,,,,,,,,,,,32,1,4.000000e+000,1.308441e-003,0.000000e+000,0,,0,
1524332323.787,,0.000000e+000,5.499577e+001,-2.757266e-007,0.000000e+000,2,0.000000e+000,0.000000e+000,,,,,,,,,,,,,,32,1,4.000000e+000,2.632141e-003,0.000000e+000,0,,0,
1524332361.617,,0.000000e+000,5.499905e+001,-3.617133e-007,0.000000e+000,2,0.000000e+000,0.000000e+000,,,,,,,,,,,,,,32,1,4.000000e+000,1.319885e-003,0.000000e+000,0,,0,
1524332398.587,,0.000000e+000,5.499971e+001,-2.490815e-007,0.000000e+000,2,0.000000e+000,0.000000e+000,,,,,,,,,,,,,,32,1,4.000000e+000,0.000000e+000,0.000000e+000,0,,0,
1524332436.627,,0.000000e+000,5.499708e+001,-2.472049e-007,0.000000e+000,2,0.000000e+000,0.000000e+000,,,,,,,,,,,,,,32,1,4.000000e+000,2.620697e-003,0.000000e+000,0,,0,
1524332474.097,,0.000000e+000,5.499972e+001,-2.153084e-007,0.000000e+000,2,0.000000e+000,0.000000e+000,,,,,,,,,,,,,,32,1,4.000000e+000,7.900238e-003,0.000000e+000,0,,0,
1524332511.497,,0.000000e+000,5.499905e+001,-2.223735e-007,0.000000e+000,2,0.000000e+000,0.000000e+000,,,,,,,,,,,,,,32,1,4.000000e+000,1.319885e-003,0.000000e+000,0,,0,
1524332548.857,,0.000000e+000,5.499773e+001,-2.401171e-007,0.000000e+000,2,0.000000e+000,0.000000e+000,,,,,,,,,,,,,,32,1,4.000000e+000,1.308441e-003,0.000000e+000,0,,0,
1524332586.807,,0.000000e+000,5.500300e+001,-1.956792e-007,0.000000e+000,2,0.000000e+000,0.000000e+000,,,,,,,,,,,,,,32,1,4.000000e+000,3.940582e-003,0.000000e+000,0,,0,
1524332624.637,,0.000000e+000,5.499577e+001,-1.634559e-007,0.000000e+000,2,0.000000e+000,0.000000e+000,,,,,,,,,,,,,,32,1,4.000000e+000,2.632141e-003,0.000000e+000,0,,0,
1524332662.907,,0.000000e+000,5.499840e+001,-2.067655e-007,0.000000e+000,2,0.000000e+000,0.000000e+000,,,,,,,,,,,,,,32,1,4.000000e+000,5.260468e-003,0.000000e+000,0,,0,
1524332700.458,,0.000000e+000,5.499906e+001,-1.699003e-007,0.000000e+000,2,0.000000e+000,0.000000e+000,,,,,,,,,,,,,,32,1,4.000000e+000,9.220123e-003,0.000000e+000,0,,0,
1524332763.948,,0.000000e+000,5.500169e+001,-2.140923e-007,0.000000e+000,2,0.000000e+000,0.000000e+000,,,,,,,,,,,,,,32,1,4.000000e+000,1.319885e-003,0.000000e+000,0,,0,
1524332801.518,,0.000000e+000,5.500365e+001,-1.497156e-007,0.000000e+000,2,0.000000e+000,0.000000e+000,,,,,,,,,,,,,,32,1,4.000000e+000,1.052856e-002,0.000000e+000,0,,0,
1524332838.908,,0.000000e+000,5.499840e+001,-1.676365e-007,0.000000e+000,2,0.000000e+000,0.000000e+000,,,,,,,,,,,,,,32,1,4.000000e+000,1.578140e-002,0.000000e+000,0,,0,
1524332876.128,,0.000000e+000,5.499445e+001,-1.668529e-007,0.000000e+000,2,0.000000e+000,0.000000e+000,,,,,,,,,,,,,,32,1,4.000000e+000,0.000000e+000,0.000000e+000,0,,0,
1524332913.408,,0.000000e+000,5.499708e+001,-1.345836e-007,0.000000e+000,2,0.000000e+000,0.000000e+000,,,,,,,,,,,,,,32,1,4.000000e+000,0.000000e+000,0.000000e+000,0,,0,
1524332950.758,,0.000000e+000,5.499248e+001,-1.453547e-007,0.000000e+000,2,0.000000e+000,0.000000e+000,,,,,,,,,,,,,,32,1,4.000000e+000,9.201050e-003,0.000000e+000,0,,0,
1524332989.128,,0.000000e+000,5.499972e+001,-1.533780e-007,0.000000e+000,2,0.000000e+000,0.000000e+000,,,,,,,,,,,,,,32,1,4.000000e+000,5.268097e-003,0.000000e+000,0,,0,
1524333026.578,,0.000000e+000,5.500103e+001,-4.064792e-008,0.000000e+000,2,0.000000e+000,0.000000e+000,,,,,,,,,,,,,,32,1,4.000000e+000,0.000000e+000,0.000000e+000,0,,0,
1524333064.558,,0.000000e+000,5.500037e+001,-8.337321e-008,0.000000e+000,2,0.000000e+000,0.000000e+000,,,,,,,,,,,,,,32,1,4.000000e+000,3.959656e-003,0.000000e+000,0,,0,
1524333101.918,,0.000000e+000,5.499971e+001,-1.239124e-007,0.000000e+000,2,0.000000e+000,0.000000e+000,,,,,,,,,,,,,,32,1,4.000000e+000,2.639771e-003,0.000000e+000,0,,0,
1524333139.618,,0.000000e+000,5.499708e+001,-7.735578e-008,0.000000e+000,2,0.000000e+000,0.000000e+000,,,,,,,,,,,,,,32,1,4.000000e+000,2.620697e-003,0.000000e+000,0,,0,
1524333178.318,,0.000000e+000,5.499643e+001,-5.280016e-008,0.000000e+000,2,0.000000e+000,0.000000e+000,,,,,,,,,,,,,,32,1,4.000000e+000,1.448059e-002,0.000000e+000,0,,0,
1524333216.068,,0.000000e+000,5.499905e+001,-5.144421e-008,0.000000e+000,2,0.000000e+000,0.000000e+000,,,,,,,,,,,,,,32,1,4.000000e+000,3.948212e-003,0.000000e+000,0,,0,
1524333253.928,,0.000000e+000,5.500235e+001,-6.128148e-008,0.000000e+000,2,0.000000e+000,0.000000e+000,,,,,,,,,,,,,,32,1,4.000000e+000,1.052856e-002,0.000000e+000,0,,0,
1524333291.658,,0.000000e+000,5.499773e+001,-5.073986e-008,0.000000e+000,2,0.000000e+000,0.000000e+000,,,,,,,,,,,,,,32,1,4.000000e+000,1.308441e-003,0.000000e+000,0,,0,
1524333329.538,,0.000000e+000,5.499577e+001,-6.553894e-008,0.000000e+000,2,0.000000e+000,0.000000e+000,,,,,,,,,,,,,,32,1,4.000000e+000,5.249023e-003,0.000000e+000,0,,0,
1524333367.308,,0.000000e+000,5.500235e+001,-2.330144e-008,0.000000e+000,2,0.000000e+000,0.000000e+000,,,,,,,,,,,,,,32,1,4.000000e+000,0.000000e+000,0.000000e+000,0,,0,
1524333405.159,,0.000000e+000,5.499445e+001,-5.147184e-008,0.000000e+000,2,0.000000e+000,0.000000e+000,,,,,,,,,,,,,,32,1,4.000000e+000,2.628326e-003,0.000000e+000,0,,0,
1524333442.909,,0.000000e+000,5.499708e+001,5.929139e-008,0.000000e+000,2,0.000000e+000,0.000000e+000,,,,,,,,,,,,,,32,1,4.000000e+000,5.260468e-003,0.000000e+000,0,,0,
1524333480.789,,0.000000e+000,5.499577e+001,-4.935973e-008,0.000000e+000,2,0.000000e+000,0.000000e+000,,,,,,,,,,,,,,32,1,4.000000e+000,5.249023e-003,0.000000e+000,0,,0,
1524333518.529,,0.000000e+000,5.499972e+001,2.363114e-008,0.000000e+000,2,0.000000e+000,0.000000e+000,,,,,,,,,,,,,,32,1,4.000000e+000,5.268097e-003,0.000000e+000,0,,0,
1524333556.409,,0.000000e+000,5.499971e+001,1.519767e-008,0.000000e+000,2,0.000000e+000,0.000000e+000,,,,,,,,,,,,,,32,1,4.000000e+000,2.639771e-003,0.000000e+000,0,,0,
1524333594.159,,0.000000e+000,5.499643e+001,2.398092e-008,0.000000e+000,2,0.000000e+000,0.000000e+000,,,,,,,,,,,,,,32,1,4.000000e+000,6.568909e-003,0.000000e+000,0,,0,
1524333632.019,,0.000000e+000,5.500103e+001,4.062817e-008,0.000000e+000,2,0.000000e+000,0.000000e+000,,,,,,,,,,,,,,32,1,4.000000e+000,7.888794e-003,0.000000e+000,0,,0,
1524333669.749,,0.000000e+000,5.500169e+001,7.717505e-008,0.000000e+000,2,0.000000e+000,0.000000e+000,,,,,,,,,,,,,,32,1,4.000000e+000,1.319885e-003,0.000000e+000,0,,0,
1524333707.639,,0.000000e+000,5.499905e+001,1.024695e-008,0.000000e+000,2,0.000000e+000,0.000000e+000,,,,,,,,,,,,,,32,1,4.000000e+000,3.948212e-003,0.000000e+000,0,,0,
1524333745.379,,0.000000e+000,5.499511e+001,5.814030e-008,0.000000e+000,2,0.000000e+000,0.000000e+000,,,,,,,,,,,,,,32,1,4.000000e+000,3.940582e-003,0.000000e+000,0,,0,
1524333783.249,,0.000000e+000,5.499972e+001,1.550081e-008,0.000000e+000,2,0.000000e+000,0.000000e+000,,,,,,,,,,,,,,32,1,4.000000e+000,1.314926e-002,0.000000e+000,0,,0,
1524333820.989,,0.000000e+000,5.500037e+001,1.056918e-007,0.000000e+000,2,0.000000e+000,0.000000e+000,,,,,,,,,,,,,,32,1,4.000000e+000,1.319885e-003,0.000000e+000,0,,0,
1524333858.879,,0.000000e+000,5.499774e+001,9.759342e-008,0.000000e+000,2,0.000000e+000,0.000000e+000,,,,,,,,,,,,,,32,1,4.000000e+000,6.580353e-003,0.000000e+000,0,,0,
1524333896.609,,0.000000e+000,5.499313e+001,1.093722e-007,0.000000e+000,2,0.000000e+000,0.000000e+000,,,,,,,,,,,,,,32,1,4.000000e+000,7.892609e-003,0.000000e+000,0,,0,
1524333934.479,,0.000000e+000,5.499905e+001,4.062394e-008,0.000000e+000,2,0.000000e+000,0.000000e+000,,,,,,,,,,,,,,32,1,4.000000e+000,1.182938e-002,0.000000e+000,0,,0,
1524333972.259,,0.000000e+000,5.500103e+001,1.308597e-007,0.000000e+000,2,0.000000e+000,0.000000e+000,,,,,,,,,,,,,,32,1,4.000000e+000,0.000000e+000,0.000000e+000,0,,0,
1524334010.109,,0.000000e+000,5.499511e+001,1.199882e-007,0.000000e+000,2,0.000000e+000,0.000000e+000,,,,,,,,,,,,,,32,1,4.000000e+000,1.319885e-003,0.000000e+000,0,,0,
1524334047.839,,0.000000e+000,5.499840e+001,1.505899e-007,0.000000e+000,2,0.000000e+000,0.000000e+000,,,,,,,,,,,,,,32,1,4.000000e+000,5.260468e-003,0.000000e+000,0,,0,
1524334085.719,,0.000000e+000,5.500103e+001,9.858784e-008,0.000000e+000,2,0.000000e+000,0.000000e+000,,,,,,,,,,,,,,32,1,4.000000e+000,5.279541e-003,0.000000e+000,0,,0,
1524334123.440,,0.000000e+000,5.499577e+001,9.779339e-008,0.000000e+000,2,0.000000e+000,0.000000e+000,,,,,,,,,,,,,,32,1,4.000000e+000,2.632141e-003,0.000000e+000,0,,0,
1524334161.330,,0.000000e+000,5.499906e+001,8.186430e-008,0.000000e+000,2,0.000000e+000,0.000000e+000,,,,,,,,,,,,,,32,1,4.000000e+000,9.220123e-003,0.000000e+000,0,,0,
1524334199.080,,0.000000e+000,5.500103e+001,1.934404e-007,0.000000e+000,2,0.000000e+000,0.000000e+000,,,,,,,,,,,,,,32,1,4.000000e+000,2.639771e-003,0.000000e+000,0,,0,
1524334236.960,,0.000000e+000,5.499840e+001,2.024396e-007,0.000000e+000,2,0.000000e+000,0.000000e+000,,,,,,,,,,,,,,32,1,4.000000e+000,2.628326e-003,0.000000e+000,0,,0,
1524334274.700,,0.000000e+000,5.499643e+001,2.254693e-007,0.000000e+000,2,0.000000e+000,0.000000e+000,,,,,,,,,,,,,,32,1,4.000000e+000,1.312256e-003,0.000000e+000,0,,0,
1524334312.570,,0.000000e+000,5.499708e+001,1.458506e-007,0.000000e+000,2,0.000000e+000,0.000000e+000,,,,,,,,,,,,,,32,1,4.000000e+000,2.620697e-003,0.000000e+000,0,,0,
1524334350.300,,0.000000e+000,5.499906e+001,2.742574e-007,0.000000e+000,2,0.000000e+000,0.000000e+000,,,,,,,,,,,,,,32,1,4.000000e+000,6.580353e-003,0.000000e+000,0,,0,
1524334388.190,,0.000000e+000,5.499840e+001,1.453628e-007,0.000000e+000,2,0.000000e+000,0.000000e+000,,,,,,,,,,,,,,32,1,4.000000e+000,2.628326e-003,0.000000e+000,0,,0,
1524334425.920,,0.000000e+000,5.499380e+001,1.989282e-007,0.000000e+000,2,0.000000e+000,0.000000e+000,,,,,,,,,,,,,,32,1,4.000000e+000,1.710129e-002,0.000000e+000,0,,0,
1524334463.810,,0.000000e+000,5.500300e+001,1.756139e-007,0.000000e+000,2,0.000000e+000,0.000000e+000,,,,,,,,,,,,,,32,1,4.000000e+000,3.940582e-003,0.000000e+000,0,,0,
1524334501.550,,0.000000e+000,5.499840e+001,2.408708e-007,0.000000e+000,2,0.000000e+000,0.000000e+000,,,,,,,,,,,,,,32,1,4.000000e+000,5.260468e-003,0.000000e+000,0,,0,
1524334539.430,,0.000000e+000,5.499840e+001,1.760980e-007,0.000000e+000,2,0.000000e+000,0.000000e+000,,,,,,,,,,,,,,32,1,4.000000e+000,2.628326e-003,0.000000e+000,0,,0,
1524334577.320,,0.000000e+000,5.499971e+001,2.384470e-007,0.000000e+000,2,0.000000e+000,0.000000e+000,,,,,,,,,,,,,,32,1,4.000000e+000,0.000000e+000,0.000000e+000,0,,0,
1524334615.330,,0.000000e+000,5.500037e+001,2.913592e-007,0.000000e+000,2,0.000000e+000,0.000000e+000,,,,,,,,,,,,,,32,1,4.000000e+000,1.319885e-003,0.000000e+000,0,,0,
1524334652.960,,0.000000e+000,5.500037e+001,2.376631e-007,0.000000e+000,2,0.000000e+000,0.000000e+000,,,,,,,,,,,,,,32,1,4.000000e+000,1.319885e-003,0.000000e+000,0,,0,
1524334690.880,,0.000000e+000,5.499117e+001,2.675139e-007,0.000000e+000,2,0.000000e+000,0.000000e+000,,,,,,,,,,,,,,32,1,4.000000e+000,6.568909e-003,0.000000e+000,0,,0,
1524334728.750,,0.000000e+000,5.499972e+001,2.598652e-007,0.000000e+000,2,0.000000e+000,0.000000e+000,,,,,,,,,,,,,,32,1,4.000000e+000,5.268097e-003,0.000000e+000,0,,0,
1524334766.710,,0.000000e+000,5.499839e+001,2.719035e-007,0.000000e+000,2,0.000000e+000,0.000000e+000,,,,,,,,,,,,,,32,1,4.000000e+000,0.000000e+000,0.000000e+000,0,,0,
1524334804.690,,0.000000e+000,5.500037e+001,3.366564e-007,0.000000e+000,2,0.000000e+000,0.000000e+000,,,,,,,,,,,,,,32,1,4.000000e+000,3.959656e-003,0.000000e+000,0,,0,
1524334842.011,,0.000000e+000,5.499708e+001,3.323212e-007,0.000000e+000,2,0.000000e+000,0.000000e+000,,,,,,,,,,,,,,32,1,4.000000e+000,2.620697e-003,0.000000e+000,0,,0,
1524334880.121,,0.000000e+000,5.499643e+001,2.691623e-007,0.000000e+000,2,0.000000e+000,0.000000e+000,,,,,,,,,,,,,,32,1,4.000000e+000,1.312256e-003,0.000000e+000,0,,0,
1524334919.031,,0.000000e+000,5.499773e+001,2.597966e-007,0.000000e+000,2,0.000000e+000,0.000000e+000,,,,,,,,,,,,,,32,1,4.000000e+000,1.308441e-003,0.000000e+000,0,,0,
1524334957.321,,0.000000e+000,5.500103e+001,2.931872e-007,0.000000e+000,2,0.000000e+000,0.000000e+000,,,,,,,,,,,,,,32,1,4.000000e+000,2.639771e-003,0.000000e+000,0,,0,
1524334995.041,,0.000000e+000,5.499840e+001,3.710074e-007,0.000000e+000,2,0.000000e+000,0.000000e+000,,,,,,,,,,,,,,32,1,4.000000e+000,2.628326e-003,0.000000e+000,0,,0,
1524335008.351,,0.000000e+000,5.500103e+001,3.223004e-007,0.000000e+000,2,0.000000e+000,0.000000e+000,,,,,,,,,,,,,,32,1,4.000000e+000,2.639771e-003,0.000000e+000,0,,0,