File: Experimental Raw Data/TC04-12-01K VRMac VRMde/TC04-12-01K_VRMac_56K_6000s.dc.dat
[Header]
TITLE,MPMS DC Measurement
BYAPP,MPMS Measurement,2.1,Summary
FILEOPENTIME, 1524256549.561000 4/20/2018, 2:35:49 PM

INFO, APPNAME, MPMS MultiVu Application, Revision 1.61,  Build 082

INFO, NAME, TC04-12-01K
INFO, WEIGHT, 1.000
INFO, AREA, 1.000
INFO, LENGTH, 1.000
INFO, SHAPE, 0
INFO, COMMENT,
INFO, SEQUENCE FILE: VRMac_56K_6000s_VRMde_55K.seq


INFO, BACKGROUND DATA FILE:, None


STARTUPAXIS,X,4,LINEAR,AUTO,0.000000,0.000000
STARTUPAXIS,Y1,5,LINEAR,AUTO,0.000000,0.000000


STARTUPGROUP,Longitudinal
FIELDGROUP,Longitudinal,1,2,3,4,5,6,7,8,9,15,16,17,18,27,28
FIELDGROUP,Transverse,1,2,3,4,10,11,12,13,14,19,20,21,22,27,28

PLOT_APPEARANCE,ALL,HORZ_GRID_ON,VERT_GRID_ON,MARKERS_AND_LINES

[Data]
Time,Comment,Field (Oe),Temperature (K),Long Moment (emu),Long Scan Std Dev,Long Algorithm,Long Reg Fit,Long Percent Error (%),Trans Moment (emu),Trans Scan Std Dev,Trans Algorithm,Trans Reg Fit,Trans Percent Error (%),Long Moment [w/o ABS] (emu),Long Scan Std Dev [w/o ABS],Long Reg Fit [w/o ABS],Long Percent Error [w/o ABS] (%),Trans Moment [w/o ABS] (emu),Trans Scan Std Dev [w/o ABS],Trans Reg Fit [w/o ABS],Trans Percent Error [w/o ABS] (%),Points per Scan,Scans per Measurement,Scan Length (cm),Delta Temp (K),Rot Position (deg),Error,EC Comp. Running,Using ABS,
1524256549.561,,0.000000e+000,5.605066e+001,-4.998547e-005,0.000000e+000,2,6.403229e-001,0.000000e+000,,,,,,,,,,,,,,32,1,4.000000e+000,1.224136e-002,0.000000e+000,0,,0,
1524256575.211,,0.000000e+000,5.603093e+001,-5.371758e-005,0.000000e+000,2,6.433545e-001,0.000000e+000,,,,,,,,,,,,,,32,1,4.000000e+000,2.719879e-003,0.000000e+000,0,,0,
1524256600.231,,0.000000e+000,5.602141e+001,-5.559582e-005,0.000000e+000,2,6.440093e-001,0.000000e+000,,,,,,,,,,,,,,32,1,4.000000e+000,2.719879e-003,0.000000e+000,0,,0,
1524256650.331,,0.000000e+000,5.600171e+001,-5.772306e-005,0.000000e+000,2,6.469617e-001,0.000000e+000,,,,,,,,,,,,,,32,1,4.000000e+000,1.350403e-003,0.000000e+000,0,,0,
1524256675.561,,0.000000e+000,5.600646e+001,-5.851170e-005,0.000000e+000,2,6.482280e-001,0.000000e+000,,,,,,,,,,,,,,32,1,4.000000e+000,5.428314e-003,0.000000e+000,0,,0,
1524256700.841,,0.000000e+000,5.599831e+001,-5.910698e-005,0.000000e+000,2,6.490508e-001,0.000000e+000,,,,,,,,,,,,,,32,1,4.000000e+000,1.358032e-002,0.000000e+000,0,,0,
1524256726.191,,0.000000e+000,5.599899e+001,-5.969618e-005,0.000000e+000,2,6.495929e-001,0.000000e+000,,,,,,,,,,,,,,32,1,4.000000e+000,6.790161e-003,0.000000e+000,0,,0,
1524256751.341,,0.000000e+000,5.600171e+001,-6.011509e-005,0.000000e+000,2,6.505243e-001,0.000000e+000,,,,,,,,,,,,,,32,1,4.000000e+000,1.350403e-003,0.000000e+000,0,,0,
1524256775.881,,0.000000e+000,5.599967e+001,-6.053396e-005,0.000000e+000,2,6.508420e-001,0.000000e+000,,,,,,,,,,,,,,32,1,4.000000e+000,0.000000e+000,0.000000e+000,0,,0,
1524256800.901,,0.000000e+000,5.599831e+001,-6.098443e-005,0.000000e+000,2,6.515416e-001,0.000000e+000,,,,,,,,,,,,,,32,1,4.000000e+000,1.086807e-002,0.000000e+000,0,,0,
1524256826.041,,0.000000e+000,5.599492e+001,-6.129577e-005,0.000000e+000,2,6.524816e-001,0.000000e+000,,,,,,,,,,,,,,32,1,4.000000e+000,4.066467e-003,0.000000e+000,0,,0,
1524256851.341,,0.000000e+000,5.600238e+001,-6.150128e-005,0.000000e+000,2,6.516532e-001,0.000000e+000,,,,,,,,,,,,,,32,1,4.000000e+000,0.000000e+000,0.000000e+000,0,,0,
1524256876.761,,0.000000e+000,5.599560e+001,-6.186235e-005,0.000000e+000,2,6.515928e-001,0.000000e+000,,,,,,,,,,,,,,32,1,4.000000e+000,1.086807e-002,0.000000e+000,0,,0,
1524256902.101,,0.000000e+000,5.600646e+001,-6.211198e-005,0.000000e+000,2,6.513615e-001,0.000000e+000,,,,,,,,,,,,,,32,1,4.000000e+000,1.902008e-002,0.000000e+000,0,,0,
1524256927.341,,0.000000e+000,5.599696e+001,-6.245929e-005,0.000000e+000,2,6.520792e-001,0.000000e+000,,,,,,,,,,,,,,32,1,4.000000e+000,5.428314e-003,0.000000e+000,0,,0,
1524256952.511,,0.000000e+000,5.599695e+001,-6.255742e-005,0.000000e+000,2,6.517783e-001,0.000000e+000,,,,,,,,,,,,,,32,1,4.000000e+000,0.000000e+000,0.000000e+000,0,,0,
1524256977.662,,0.000000e+000,5.599831e+001,-6.287536e-005,0.000000e+000,2,6.531174e-001,0.000000e+000,,,,,,,,,,,,,,32,1,4.000000e+000,2.719879e-003,0.000000e+000,0,,0,
1524257003.422,,0.000000e+000,5.599084e+001,-6.306716e-005,0.000000e+000,2,6.532854e-001,0.000000e+000,,,,,,,,,,,,,,32,1,4.000000e+000,9.490967e-003,0.000000e+000,0,,0,
1524257028.142,,0.000000e+000,5.599899e+001,-6.327342e-005,0.000000e+000,2,6.527977e-001,0.000000e+000,,,,,,,,,,,,,,32,1,4.000000e+000,1.221848e-002,0.000000e+000,0,,0,
1524257053.072,,0.000000e+000,5.599831e+001,-6.349717e-005,0.000000e+000,2,6.528769e-001,0.000000e+000,,,,,,,,,,,,,,32,1,4.000000e+000,8.140564e-003,0.000000e+000,0,,0,
1524257078.342,,0.000000e+000,5.600375e+001,-6.365863e-005,0.000000e+000,2,6.548608e-001,0.000000e+000,,,,,,,,,,,,,,32,1,4.000000e+000,5.428314e-003,0.000000e+000,0,,0,
1524257103.682,,0.000000e+000,5.600102e+001,-6.376388e-005,0.000000e+000,2,6.555305e-001,0.000000e+000,,,,,,,,,,,,,,32,1,4.000000e+000,8.152008e-003,0.000000e+000,0,,0,
1524257128.972,,0.000000e+000,5.600171e+001,-6.398161e-005,0.000000e+000,2,6.550891e-001,0.000000e+000,,,,,,,,,,,,,,32,1,4.000000e+000,1.350403e-003,0.000000e+000,0,,0,
1524257154.192,,0.000000e+000,5.599696e+001,-6.403311e-005,0.000000e+000,2,6.544830e-001,0.000000e+000,,,,,,,,,,,,,,32,1,4.000000e+000,5.428314e-003,0.000000e+000,0,,0,
1524257179.272,,0.000000e+000,5.600103e+001,-6.428321e-005,0.000000e+000,2,6.556998e-001,0.000000e+000,,,,,,,,,,,,,,32,1,4.000000e+000,5.439758e-003,0.000000e+000,0,,0,
1524257204.902,,0.000000e+000,5.599695e+001,-6.441841e-005,0.000000e+000,2,6.536202e-001,0.000000e+000,,,,,,,,,,,,,,32,1,4.000000e+000,2.719879e-003,0.000000e+000,0,,0,
1524257230.372,,0.000000e+000,5.599967e+001,-6.457862e-005,0.000000e+000,2,6.551499e-001,0.000000e+000,,,,,,,,,,,,,,32,1,4.000000e+000,0.000000e+000,0.000000e+000,0,,0,
1524257255.512,,0.000000e+000,5.599899e+001,-6.467984e-005,0.000000e+000,2,6.553178e-001,0.000000e+000,,,,,,,,,,,,,,32,1,4.000000e+000,4.081726e-003,0.000000e+000,0,,0,
1524257280.642,,0.000000e+000,5.600034e+001,-6.479620e-005,0.000000e+000,2,6.556129e-001,0.000000e+000,,,,,,,,,,,,,,32,1,4.000000e+000,4.070282e-003,0.000000e+000,0,,0,
1524257306.072,,0.000000e+000,5.599492e+001,-6.500533e-005,0.000000e+000,2,6.559991e-001,0.000000e+000,,,,,,,,,,,,,,32,1,4.000000e+000,9.506226e-003,0.000000e+000,0,,0,
1524257331.262,,0.000000e+000,5.600102e+001,-6.514569e-005,0.000000e+000,2,6.571365e-001,0.000000e+000,,,,,,,,,,,,,,32,1,4.000000e+000,8.152008e-003,0.000000e+000,0,,0,
1524257356.512,,0.000000e+000,5.599695e+001,-6.525636e-005,0.000000e+000,2,6.570364e-001,0.000000e+000,,,,,,,,,,,,,,32,1,4.000000e+000,2.719879e-003,0.000000e+000,0,,0,
1524257381.672,,0.000000e+000,5.600103e+001,-6.539797e-005,0.000000e+000,2,6.572448e-001,0.000000e+000,,,,,,,,,,,,,,32,1,4.000000e+000,5.439758e-003,0.000000e+000,0,,0,
1524257406.952,,0.000000e+000,5.599967e+001,-6.537668e-005,0.000000e+000,2,6.577490e-001,0.000000e+000,,,,,,,,,,,,,,32,1,4.000000e+000,2.719879e-003,0.000000e+000,0,,0,
1524257431.722,,0.000000e+000,5.599899e+001,-6.558819e-005,0.000000e+000,2,6.588469e-001,0.000000e+000,,,,,,,,,,,,,,32,1,4.000000e+000,4.081726e-003,0.000000e+000,0,,0,
1524257456.852,,0.000000e+000,5.599831e+001,-6.572207e-005,0.000000e+000,2,6.587127e-001,0.000000e+000,,,,,,,,,,,,,,32,1,4.000000e+000,5.439758e-003,0.000000e+000,0,,0,
1524257481.572,,0.000000e+000,5.599831e+001,-6.580506e-005,0.000000e+000,2,6.588885e-001,0.000000e+000,,,,,,,,,,,,,,32,1,4.000000e+000,5.439758e-003,0.000000e+000,0,,0,
1524257507.112,,0.000000e+000,5.600102e+001,-6.587775e-005,0.000000e+000,2,6.584187e-001,0.000000e+000,,,,,,,,,,,,,,32,1,4.000000e+000,2.712250e-003,0.000000e+000,0,,0,
1524257532.022,,0.000000e+000,5.599560e+001,-6.603565e-005,0.000000e+000,2,6.593243e-001,0.000000e+000,,,,,,,,,,,,,,32,1,4.000000e+000,5.428314e-003,0.000000e+000,0,,0,
1524257556.942,,0.000000e+000,5.599559e+001,-6.606342e-005,0.000000e+000,2,6.582473e-001,0.000000e+000,,,,,,,,,,,,,,32,1,4.000000e+000,2.708435e-003,0.000000e+000,0,,0,
1524257581.892,,0.000000e+000,5.599763e+001,-6.613349e-005,0.000000e+000,2,6.583183e-001,0.000000e+000,,,,,,,,,,,,,,32,1,4.000000e+000,9.498596e-003,0.000000e+000,0,,0,
1524257608.052,,0.000000e+000,5.599695e+001,-6.627589e-005,0.000000e+000,2,6.586727e-001,0.000000e+000,,,,,,,,,,,,,,32,1,4.000000e+000,2.719879e-003,0.000000e+000,0,,0,
1524257633.362,,0.000000e+000,5.599899e+001,-6.642126e-005,0.000000e+000,2,6.599153e-001,0.000000e+000,,,,,,,,,,,,,,32,1,4.000000e+000,1.358032e-003,0.000000e+000,0,,0,
1524257658.662,,0.000000e+000,5.599356e+001,-6.649308e-005,0.000000e+000,2,6.608211e-001,0.000000e+000,,,,,,,,,,,,,,32,1,4.000000e+000,1.493073e-002,0.000000e+000,0,,0,
1524257683.672,,0.000000e+000,5.599152e+001,-6.654526e-005,0.000000e+000,2,6.607130e-001,0.000000e+000,,,,,,,,,,,,,,32,1,4.000000e+000,5.439758e-003,0.000000e+000,0,,0,
1524257708.533,,0.000000e+000,5.599763e+001,-6.668745e-005,0.000000e+000,2,6.594546e-001,0.000000e+000,,,,,,,,,,,,,,32,1,4.000000e+000,4.077911e-003,0.000000e+000,0,,0,
1524257733.243,,0.000000e+000,5.599967e+001,-6.673173e-005,0.000000e+000,2,6.602510e-001,0.000000e+000,,,,,,,,,,,,,,32,1,4.000000e+000,1.630020e-002,0.000000e+000,0,,0,
1524257758.143,,0.000000e+000,5.599287e+001,-6.683227e-005,0.000000e+000,2,6.608970e-001,0.000000e+000,,,,,,,,,,,,,,32,1,4.000000e+000,5.428314e-003,0.000000e+000,0,,0,
1524257783.653,,0.000000e+000,5.599288e+001,-6.685153e-005,0.000000e+000,2,6.610597e-001,0.000000e+000,,,,,,,,,,,,,,32,1,4.000000e+000,2.719879e-003,0.000000e+000,0,,0,
1524257808.923,,0.000000e+000,5.599831e+001,-6.694409e-005,0.000000e+000,2,6.607277e-001,0.000000e+000,,,,,,,,,,,,,,32,1,4.000000e+000,8.140564e-003,0.000000e+000,0,,0,
1524257834.443,,0.000000e+000,5.599696e+001,-6.700776e-005,0.000000e+000,2,6.604335e-001,0.000000e+000,,,,,,,,,,,,,,32,1,4.000000e+000,5.428314e-003,0.000000e+000,0,,0,
1524257859.733,,0.000000e+000,5.599899e+001,-6.719294e-005,0.000000e+000,2,6.614358e-001,0.000000e+000,,,,,,,,,,,,,,32,1,4.000000e+000,1.493835e-002,0.000000e+000,0,,0,
1524257884.633,,0.000000e+000,5.600035e+001,-6.723544e-005,0.000000e+000,2,6.613966e-001,0.000000e+000,,,,,,,,,,,,,,32,1,4.000000e+000,1.361847e-003,0.000000e+000,0,,0,
1524257909.853,,0.000000e+000,5.599627e+001,-6.735934e-005,0.000000e+000,2,6.628553e-001,0.000000e+000,,,,,,,,,,,,,,32,1,4.000000e+000,1.358032e-003,0.000000e+000,0,,0,
1524257935.053,,0.000000e+000,5.599899e+001,-6.737354e-005,0.000000e+000,2,6.623046e-001,0.000000e+000,,,,,,,,,,,,,,32,1,4.000000e+000,4.081726e-003,0.000000e+000,0,,0,
1524257960.253,,0.000000e+000,5.599763e+001,-6.741511e-005,0.000000e+000,2,6.627091e-001,0.000000e+000,,,,,,,,,,,,,,32,1,4.000000e+000,1.361847e-003,0.000000e+000,0,,0,
1524257985.193,,0.000000e+000,5.599220e+001,-6.750681e-005,0.000000e+000,2,6.626465e-001,0.000000e+000,,,,,,,,,,,,,,32,1,4.000000e+000,4.077911e-003,0.000000e+000,0,,0,
1524258010.453,,0.000000e+000,5.599763e+001,-6.753927e-005,0.000000e+000,2,6.631593e-001,0.000000e+000,,,,,,,,,,,,,,32,1,4.000000e+000,6.790161e-003,0.000000e+000,0,,0,
1524258035.723,,0.000000e+000,5.599763e+001,-6.760799e-005,0.000000e+000,2,6.639851e-001,0.000000e+000,,,,,,,,,,,,,,32,1,4.000000e+000,9.498596e-003,0.000000e+000,0,,0,
1524258060.903,,0.000000e+000,5.599696e+001,-6.772012e-005,0.000000e+000,2,6.634507e-001,0.000000e+000,,,,,,,,,,,,,,32,1,4.000000e+000,8.148193e-003,0.000000e+000,0,,0,
1524258085.963,,0.000000e+000,5.599424e+001,-6.778927e-005,0.000000e+000,2,6.639321e-001,0.000000e+000,,,,,,,,,,,,,,32,1,4.000000e+000,0.000000e+000,0.000000e+000,0,,0,
1524258111.503,,0.000000e+000,5.600035e+001,-6.786102e-005,0.000000e+000,2,6.647353e-001,0.000000e+000,,,,,,,,,,,,,,32,1,4.000000e+000,1.361847e-003,0.000000e+000,0,,0,
1524258136.323,,0.000000e+000,5.600035e+001,-6.790100e-005,0.000000e+000,2,6.632648e-001,0.000000e+000,,,,,,,,,,,,,,32,1,4.000000e+000,1.361847e-003,0.000000e+000,0,,0,
1524258161.513,,0.000000e+000,5.600102e+001,-6.798135e-005,0.000000e+000,2,6.634248e-001,0.000000e+000,,,,,,,,,,,,,,32,1,4.000000e+000,2.712250e-003,0.000000e+000,0,,0,
1524258186.553,,0.000000e+000,5.599966e+001,-6.805461e-005,0.000000e+000,2,6.637328e-001,0.000000e+000,,,,,,,,,,,,,,32,1,4.000000e+000,5.432129e-003,0.000000e+000,0,,0,
1524258211.653,,0.000000e+000,5.599152e+001,-6.809647e-005,0.000000e+000,2,6.650120e-001,0.000000e+000,,,,,,,,,,,,,,32,1,4.000000e+000,5.439758e-003,0.000000e+000,0,,0,
1524258236.743,,0.000000e+000,5.599967e+001,-6.813370e-005,0.000000e+000,2,6.644065e-001,0.000000e+000,,,,,,,,,,,,,,32,1,4.000000e+000,8.159637e-003,0.000000e+000,0,,0,
1524258261.873,,0.000000e+000,5.599628e+001,-6.823108e-005,0.000000e+000,2,6.644540e-001,0.000000e+000,,,,,,,,,,,,,,32,1,4.000000e+000,4.070282e-003,0.000000e+000,0,,0,
1524258286.923,,0.000000e+000,5.599696e+001,-6.829474e-005,0.000000e+000,2,6.644759e-001,0.000000e+000,,,,,,,,,,,,,,32,1,4.000000e+000,8.148193e-003,0.000000e+000,0,,0,
1524258312.033,,0.000000e+000,5.599763e+001,-6.827997e-005,0.000000e+000,2,6.652727e-001,0.000000e+000,,,,,,,,,,,,,,32,1,4.000000e+000,4.077911e-003,0.000000e+000,0,,0,
1524258337.063,,0.000000e+000,5.599492e+001,-6.837348e-005,0.000000e+000,2,6.660206e-001,0.000000e+000,,,,,,,,,,,,,,32,1,4.000000e+000,9.506226e-003,0.000000e+000,0,,0,
1524258362.403,,0.000000e+000,5.599831e+001,-6.841808e-005,0.000000e+000,2,6.657605e-001,0.000000e+000,,,,,,,,,,,,,,32,1,4.000000e+000,8.140564e-003,0.000000e+000,0,,0,
1524258387.693,,0.000000e+000,5.599560e+001,-6.841079e-005,0.000000e+000,2,6.636431e-001,0.000000e+000,,,,,,,,,,,,,,32,1,4.000000e+000,1.086807e-002,0.000000e+000,0,,0,
1524258412.694,,0.000000e+000,5.599424e+001,-6.852631e-005,0.000000e+000,2,6.643080e-001,0.000000e+000,,,,,,,,,,,,,,32,1,4.000000e+000,8.148193e-003,0.000000e+000,0,,0,
1524258437.884,,0.000000e+000,5.599899e+001,-6.858459e-005,0.000000e+000,2,6.644735e-001,0.000000e+000,,,,,,,,,,,,,,32,1,4.000000e+000,4.081726e-003,0.000000e+000,0,,0,
1524258463.004,,0.000000e+000,5.599763e+001,-6.865309e-005,0.000000e+000,2,6.651337e-001,0.000000e+000,,,,,,,,,,,,,,32,1,4.000000e+000,1.361847e-003,0.000000e+000,0,,0,
1524258487.984,,0.000000e+000,5.599831e+001,-6.868390e-005,0.000000e+000,2,6.651658e-001,0.000000e+000,,,,,,,,,,,,,,32,1,4.000000e+000,2.719879e-003,0.000000e+000,0,,0,
1524258513.044,,0.000000e+000,5.600307e+001,-6.876980e-005,0.000000e+000,2,6.667938e-001,0.000000e+000,,,,,,,,,,,,,,32,1,4.000000e+000,9.510040e-003,0.000000e+000,0,,0,
1524258538.554,,0.000000e+000,5.600034e+001,-6.877883e-005,0.000000e+000,2,6.650653e-001,0.000000e+000,,,,,,,,,,,,,,32,1,4.000000e+000,4.070282e-003,0.000000e+000,0,,0,
1524258564.064,,0.000000e+000,5.599763e+001,-6.884678e-005,0.000000e+000,2,6.660084e-001,0.000000e+000,,,,,,,,,,,,,,32,1,4.000000e+000,9.498596e-003,0.000000e+000,0,,0,
1524258589.424,,0.000000e+000,5.599899e+001,-6.891866e-005,0.000000e+000,2,6.673241e-001,0.000000e+000,,,,,,,,,,,,,,32,1,4.000000e+000,1.358032e-003,0.000000e+000,0,,0,
1524258614.924,,0.000000e+000,5.599424e+001,-6.906445e-005,0.000000e+000,2,6.680809e-001,0.000000e+000,,,,,,,,,,,,,,32,1,4.000000e+000,8.148193e-003,0.000000e+000,0,,0,
1524258640.534,,0.000000e+000,5.600443e+001,-6.900098e-005,0.000000e+000,2,6.671690e-001,0.000000e+000,,,,,,,,,,,,,,32,1,4.000000e+000,1.350403e-003,0.000000e+000,0,,0,
1524258666.104,,0.000000e+000,5.599831e+001,-6.903747e-005,0.000000e+000,2,6.684781e-001,0.000000e+000,,,,,,,,,,,,,,32,1,4.000000e+000,1.086807e-002,0.000000e+000,0,,0,
1524258691.364,,0.000000e+000,5.599967e+001,-6.904535e-005,0.000000e+000,2,6.674021e-001,0.000000e+000,,,,,,,,,,,,,,32,1,4.000000e+000,2.719879e-003,0.000000e+000,0,,0,
1524258716.514,,0.000000e+000,5.599831e+001,-6.914620e-005,0.000000e+000,2,6.666380e-001,0.000000e+000,,,,,,,,,,,,,,32,1,4.000000e+000,2.719879e-003,0.000000e+000,0,,0,
1524258741.284,,0.000000e+000,5.599220e+001,-6.920750e-005,0.000000e+000,2,6.682084e-001,0.000000e+000,,,,,,,,,,,,,,32,1,4.000000e+000,6.790161e-003,0.000000e+000,0,,0,
1524258766.224,,0.000000e+000,5.599627e+001,-6.923093e-005,0.000000e+000,2,6.688281e-001,0.000000e+000,,,,,,,,,,,,,,32,1,4.000000e+000,1.358032e-003,0.000000e+000,0,,0,
1524258791.334,,0.000000e+000,5.599696e+001,-6.932877e-005,0.000000e+000,2,6.690367e-001,0.000000e+000,,,,,,,,,,,,,,32,1,4.000000e+000,5.428314e-003,0.000000e+000,0,,0,
1524258815.964,,0.000000e+000,5.599424e+001,-6.933540e-005,0.000000e+000,2,6.681905e-001,0.000000e+000,,,,,,,,,,,,,,32,1,4.000000e+000,2.708435e-003,0.000000e+000,0,,0,
1524258840.864,,0.000000e+000,5.600238e+001,-6.939228e-005,0.000000e+000,2,6.687174e-001,0.000000e+000,,,,,,,,,,,,,,32,1,4.000000e+000,0.000000e+000,0.000000e+000,0,,0,
1524258865.984,,0.000000e+000,5.599899e+001,-6.943064e-005,0.000000e+000,2,6.686978e-001,0.000000e+000,,,,,,,,,,,,,,32,1,4.000000e+000,4.081726e-003,0.000000e+000,0,,0,
1524258890.624,,0.000000e+000,5.600375e+001,-6.945137e-005,0.000000e+000,2,6.689702e-001,0.000000e+000,,,,,,,,,,,,,,32,1,4.000000e+000,0.000000e+000,0.000000e+000,0,,0,
1524258915.954,,0.000000e+000,5.599355e+001,-6.955509e-005,0.000000e+000,2,6.682418e-001,0.000000e+000,,,,,,,,,,,,,,32,1,4.000000e+000,4.070282e-003,0.000000e+000,0,,0,
1524258941.624,,0.000000e+000,5.599695e+001,-6.955866e-005,0.000000e+000,2,6.682277e-001,0.000000e+000,,,,,,,,,,,,,,32,1,4.000000e+000,0.000000e+000,0.000000e+000,0,,0,
1524258967.084,,0.000000e+000,5.599967e+001,-6.956449e-005,0.000000e+000,2,6.705666e-001,0.000000e+000,,,,,,,,,,,,,,32,1,4.000000e+000,0.000000e+000,0.000000e+000,0,,0,
1524258992.334,,0.000000e+000,5.599696e+001,-6.956992e-005,0.000000e+000,2,6.708819e-001,0.000000e+000,,,,,,,,,,,,,,32,1,4.000000e+000,5.428314e-003,0.000000e+000,0,,0,
1524259017.314,,0.000000e+000,5.600443e+001,-6.964648e-005,0.000000e+000,2,6.708258e-001,0.000000e+000,,,,,,,,,,,,,,32,1,4.000000e+000,9.510040e-003,0.000000e+000,0,,0,
1524259042.184,,0.000000e+000,5.599763e+001,-6.965717e-005,0.000000e+000,2,6.699455e-001,0.000000e+000,,,,,,,,,,,,,,32,1,4.000000e+000,1.361847e-003,0.000000e+000,0,,0,
1524259067.264,,0.000000e+000,5.599967e+001,-6.973394e-005,0.000000e+000,2,6.711160e-001,0.000000e+000,,,,,,,,,,,,,,32,1,4.000000e+000,8.159637e-003,0.000000e+000,0,,0,
1524259092.404,,0.000000e+000,5.599152e+001,-6.976761e-005,0.000000e+000,2,6.702346e-001,0.000000e+000,,,,,,,,,,,,,,32,1,4.000000e+000,0.000000e+000,0.000000e+000,0,,0,
1524259117.745,,0.000000e+000,5.600171e+001,-6.977544e-005,0.000000e+000,2,6.701704e-001,0.000000e+000,,,,,,,,,,,,,,32,1,4.000000e+000,4.081726e-003,0.000000e+000,0,,0,
1524259142.495,,0.000000e+000,5.599831e+001,-6.983502e-005,0.000000e+000,2,6.696531e-001,0.000000e+000,,,,,,,,,,,,,,32,1,4.000000e+000,0.000000e+000,0.000000e+000,0,,0,
1524259167.715,,0.000000e+000,5.599356e+001,-6.979300e-005,0.000000e+000,2,6.698987e-001,0.000000e+000,,,,,,,,,,,,,,32,1,4.000000e+000,2.037048e-002,0.000000e+000,0,,0,
1524259192.875,,0.000000e+000,5.599967e+001,-6.983835e-005,0.000000e+000,2,6.695299e-001,0.000000e+000,,,,,,,,,,,,,,32,1,4.000000e+000,1.086044e-002,0.000000e+000,0,,0,
1524259217.775,,0.000000e+000,5.599899e+001,-6.994617e-005,0.000000e+000,2,6.703305e-001,0.000000e+000,,,,,,,,,,,,,,32,1,4.000000e+000,4.081726e-003,0.000000e+000,0,,0,
1524259243.095,,0.000000e+000,5.599831e+001,-7.000438e-005,0.000000e+000,2,6.710544e-001,0.000000e+000,,,,,,,,,,,,,,32,1,4.000000e+000,2.719879e-003,0.000000e+000,0,,0,
1524259268.055,,0.000000e+000,5.599152e+001,-7.002373e-005,0.000000e+000,2,6.714302e-001,0.000000e+000,,,,,,,,,,,,,,32,1,4.000000e+000,5.439758e-003,0.000000e+000,0,,0,
1524259293.055,,0.000000e+000,5.599695e+001,-7.004703e-005,0.000000e+000,2,6.711638e-001,0.000000e+000,,,,,,,,,,,,,,32,1,4.000000e+000,2.719879e-003,0.000000e+000,0,,0,
1524259318.665,,0.000000e+000,5.600103e+001,-7.007557e-005,0.000000e+000,2,6.720695e-001,0.000000e+000,,,,,,,,,,,,,,32,1,4.000000e+000,0.000000e+000,0.000000e+000,0,,0,
1524259344.125,,0.000000e+000,5.600103e+001,-7.012642e-005,0.000000e+000,2,6.716308e-001,0.000000e+000,,,,,,,,,,,,,,32,1,4.000000e+000,0.000000e+000,0.000000e+000,0,,0,
1524259369.315,,0.000000e+000,5.599967e+001,-7.016062e-005,0.000000e+000,2,6.716116e-001,0.000000e+000,,,,,,,,,,,,,,32,1,4.000000e+000,1.357651e-002,0.000000e+000,0,,0,
1524259394.305,,0.000000e+000,5.600171e+001,-7.022401e-005,0.000000e+000,2,6.719981e-001,0.000000e+000,,,,,,,,,,,,,,32,1,4.000000e+000,1.350403e-003,0.000000e+000,0,,0,
1524259419.325,,0.000000e+000,5.600375e+001,-7.021945e-005,0.000000e+000,2,6.719297e-001,0.000000e+000,,,,,,,,,,,,,,32,1,4.000000e+000,1.359177e-002,0.000000e+000,0,,0,
1524259443.825,,0.000000e+000,5.599763e+001,-7.022881e-005,0.000000e+000,2,6.719860e-001,0.000000e+000,,,,,,,,,,,,,,32,1,4.000000e+000,1.361847e-003,0.000000e+000,0,,0,
1524259468.965,,0.000000e+000,5.600035e+001,-7.031297e-005,0.000000e+000,2,6.725314e-001,0.000000e+000,,,,,,,,,,,,,,32,1,4.000000e+000,1.361847e-003,0.000000e+000,0,,0,
1524259494.195,,0.000000e+000,5.599967e+001,-7.039763e-005,0.000000e+000,2,6.742776e-001,0.000000e+000,,,,,,,,,,,,,,32,1,4.000000e+000,1.086044e-002,0.000000e+000,0,,0,
1524259519.765,,0.000000e+000,5.599628e+001,-7.032847e-005,0.000000e+000,2,6.735439e-001,0.000000e+000,,,,,,,,,,,,,,32,1,4.000000e+000,6.786346e-003,0.000000e+000,0,,0,
1524259557.085,,0.000000e+000,5.599695e+001,-7.049629e-005,0.000000e+000,2,6.731036e-001,0.000000e+000,,,,,,,,,,,,,,32,1,4.000000e+000,0.000000e+000,0.000000e+000,0,,0,
1524259582.855,,0.000000e+000,5.599763e+001,-7.048971e-005,0.000000e+000,2,6.739603e-001,0.000000e+000,,,,,,,,,,,,,,32,1,4.000000e+000,6.790161e-003,0.000000e+000,0,,0,
1524259607.705,,0.000000e+000,5.599763e+001,-7.050271e-005,0.000000e+000,2,6.732216e-001,0.000000e+000,,,,,,,,,,,,,,32,1,4.000000e+000,6.790161e-003,0.000000e+000,0,,0,
1524259633.615,,0.000000e+000,5.600170e+001,-7.046884e-005,0.000000e+000,2,6.741260e-001,0.000000e+000,,,,,,,,,,,,,,32,1,4.000000e+000,9.510040e-003,0.000000e+000,0,,0,
1524259659.025,,0.000000e+000,5.599899e+001,-7.059317e-005,0.000000e+000,2,6.754730e-001,0.000000e+000,,,,,,,,,,,,,,32,1,4.000000e+000,1.221848e-002,0.000000e+000,0,,0,
1524259684.105,,0.000000e+000,5.600103e+001,-7.061401e-005,0.000000e+000,2,6.732528e-001,0.000000e+000,,,,,,,,,,,,,,32,1,4.000000e+000,5.439758e-003,0.000000e+000,0,,0,
1524259709.575,,0.000000e+000,5.599899e+001,-7.071452e-005,0.000000e+000,2,6.756968e-001,0.000000e+000,,,,,,,,,,,,,,32,1,4.000000e+000,1.358032e-003,0.000000e+000,0,,0,
1524259734.535,,0.000000e+000,5.599967e+001,-7.063842e-005,0.000000e+000,2,6.748617e-001,0.000000e+000,,,,,,,,,,,,,,32,1,4.000000e+000,2.719879e-003,0.000000e+000,0,,0,
1524259759.655,,0.000000e+000,5.599763e+001,-7.065218e-005,0.000000e+000,2,6.741749e-001,0.000000e+000,,,,,,,,,,,,,,32,1,4.000000e+000,4.077911e-003,0.000000e+000,0,,0,
1524259785.195,,0.000000e+000,5.599763e+001,-7.077939e-005,0.000000e+000,2,6.745200e-001,0.000000e+000,,,,,,,,,,,,,,32,1,4.000000e+000,6.790161e-003,0.000000e+000,0,,0,
1524259810.145,,0.000000e+000,5.599763e+001,-7.075125e-005,0.000000e+000,2,6.751165e-001,0.000000e+000,,,,,,,,,,,,,,32,1,4.000000e+000,1.361847e-003,0.000000e+000,0,,0,
1524259835.306,,0.000000e+000,5.599424e+001,-7.087707e-005,0.000000e+000,2,6.747774e-001,0.000000e+000,,,,,,,,,,,,,,32,1,4.000000e+000,8.148193e-003,0.000000e+000,0,,0,
1524259860.886,,0.000000e+000,5.600103e+001,-7.074274e-005,0.000000e+000,2,6.737271e-001,0.000000e+000,,,,,,,,,,,,,,32,1,4.000000e+000,5.439758e-003,0.000000e+000,0,,0,
1524259885.896,,0.000000e+000,5.599628e+001,-7.089720e-005,0.000000e+000,2,6.748382e-001,0.000000e+000,,,,,,,,,,,,,,32,1,4.000000e+000,6.786346e-003,0.000000e+000,0,,0,
1524259911.366,,0.000000e+000,5.600171e+001,-7.084574e-005,0.000000e+000,2,6.743982e-001,0.000000e+000,,,,,,,,,,,,,,32,1,4.000000e+000,1.222992e-002,0.000000e+000,0,,0,
1524259936.486,,0.000000e+000,5.600238e+001,-7.089850e-005,0.000000e+000,2,6.736388e-001,0.000000e+000,,,,,,,,,,,,,,32,1,4.000000e+000,8.148193e-003,0.000000e+000,0,,0,
1524259961.376,,0.000000e+000,5.600171e+001,-7.094209e-005,0.000000e+000,2,6.751639e-001,0.000000e+000,,,,,,,,,,,,,,32,1,4.000000e+000,4.081726e-003,0.000000e+000,0,,0,
1524259986.176,,0.000000e+000,5.600306e+001,-7.101899e-005,0.000000e+000,2,6.759132e-001,0.000000e+000,,,,,,,,,,,,,,32,1,4.000000e+000,6.790161e-003,0.000000e+000,0,,0,
1524260011.236,,0.000000e+000,5.599424e+001,-7.094105e-005,0.000000e+000,2,6.767190e-001,0.000000e+000,,,,,,,,,,,,,,32,1,4.000000e+000,2.708435e-003,0.000000e+000,0,,0,
1524260037.216,,0.000000e+000,5.599492e+001,-7.090103e-005,0.000000e+000,2,6.758169e-001,0.000000e+000,,,,,,,,,,,,,,32,1,4.000000e+000,1.350403e-003,0.000000e+000,0,,0,
1524260062.886,,0.000000e+000,5.600103e+001,-7.097785e-005,0.000000e+000,2,6.765087e-001,0.000000e+000,,,,,,,,,,,,,,32,1,4.000000e+000,0.000000e+000,0.000000e+000,0,,0,
1524260088.596,,0.000000e+000,5.599831e+001,-7.104735e-005,0.000000e+000,2,6.760324e-001,0.000000e+000,,,,,,,,,,,,,,32,1,4.000000e+000,2.719879e-003,0.000000e+000,0,,0,
1524260113.786,,0.000000e+000,5.599423e+001,-7.107140e-005,0.000000e+000,2,6.759999e-001,0.000000e+000,,,,,,,,,,,,,,32,1,4.000000e+000,5.428314e-003,0.000000e+000,0,,0,
1524260138.816,,0.000000e+000,5.599084e+001,-7.113776e-005,0.000000e+000,2,6.773860e-001,0.000000e+000,,,,,,,,,,,,,,32,1,4.000000e+000,1.358032e-003,0.000000e+000,0,,0,
1524260164.196,,0.000000e+000,5.600238e+001,-7.115219e-005,0.000000e+000,2,6.760536e-001,0.000000e+000,,,,,,,,,,,,,,32,1,4.000000e+000,5.432129e-003,0.000000e+000,0,,0,
1524260189.536,,0.000000e+000,5.599831e+001,-7.119728e-005,0.000000e+000,2,6.756629e-001,0.000000e+000,,,,,,,,,,,,,,32,1,4.000000e+000,0.000000e+000,0.000000e+000,0,,0,
1524260214.316,,0.000000e+000,5.599967e+001,-7.125930e-005,0.000000e+000,2,6.758631e-001,0.000000e+000,,,,,,,,,,,,,,32,1,4.000000e+000,2.719879e-003,0.000000e+000,0,,0,
1524260239.546,,0.000000e+000,5.600374e+001,-7.128913e-005,0.000000e+000,2,6.770424e-001,0.000000e+000,,,,,,,,,,,,,,32,1,4.000000e+000,2.719879e-003,0.000000e+000,0,,0,
1524260264.646,,0.000000e+000,5.600102e+001,-7.129711e-005,0.000000e+000,2,6.784748e-001,0.000000e+000,,,,,,,,,,,,,,32,1,4.000000e+000,1.086807e-002,0.000000e+000,0,,0,
1524260290.226,,0.000000e+000,5.599899e+001,-7.124905e-005,0.000000e+000,2,6.770594e-001,0.000000e+000,,,,,,,,,,,,,,32,1,4.000000e+000,9.510040e-003,0.000000e+000,0,,0,
1524260315.566,,0.000000e+000,5.599763e+001,-7.133192e-005,0.000000e+000,2,6.788167e-001,0.000000e+000,,,,,,,,,,,,,,32,1,4.000000e+000,9.498596e-003,0.000000e+000,0,,0,
1524260340.466,,0.000000e+000,5.599831e+001,-7.136970e-005,0.000000e+000,2,6.786464e-001,0.000000e+000,,,,,,,,,,,,,,32,1,4.000000e+000,0.000000e+000,0.000000e+000,0,,0,
1524260365.646,,0.000000e+000,5.599492e+001,-7.136922e-005,0.000000e+000,2,6.774995e-001,0.000000e+000,,,,,,,,,,,,,,32,1,4.000000e+000,4.066467e-003,0.000000e+000,0,,0,
1524260390.626,,0.000000e+000,5.600238e+001,-7.138665e-005,0.000000e+000,2,6.770475e-001,0.000000e+000,,,,,,,,,,,,,,32,1,4.000000e+000,1.087189e-002,0.000000e+000,0,,0,
1524260415.286,,0.000000e+000,5.599695e+001,-7.135938e-005,0.000000e+000,2,6.773439e-001,0.000000e+000,,,,,,,,,,,,,,32,1,4.000000e+000,2.719879e-003,0.000000e+000,0,,0,
1524260440.716,,0.000000e+000,5.599559e+001,-7.136999e-005,0.000000e+000,2,6.766503e-001,0.000000e+000,,,,,,,,,,,,,,32,1,4.000000e+000,2.708435e-003,0.000000e+000,0,,0,
1524260465.876,,0.000000e+000,5.599899e+001,-7.147624e-005,0.000000e+000,2,6.781574e-001,0.000000e+000,,,,,,,,,,,,,,32,1,4.000000e+000,1.358032e-003,0.000000e+000,0,,0,
1524260490.896,,0.000000e+000,5.599831e+001,-7.146101e-005,0.000000e+000,2,6.790416e-001,0.000000e+000,,,,,,,,,,,,,,32,1,4.000000e+000,1.086807e-002,0.000000e+000,0,,0,
1524260516.586,,0.000000e+000,5.599899e+001,-7.157194e-005,0.000000e+000,2,6.786821e-001,0.000000e+000,,,,,,,,,,,,,,32,1,4.000000e+000,6.790161e-003,0.000000e+000,0,,0,
1524260541.237,,0.000000e+000,5.599492e+001,-7.158013e-005,0.000000e+000,2,6.802197e-001,0.000000e+000,,,,,,,,,,,,,,32,1,4.000000e+000,4.066467e-003,0.000000e+000,0,,0,
1524260566.447,,0.000000e+000,5.599627e+001,-7.160925e-005,0.000000e+000,2,6.808452e-001,0.000000e+000,,,,,,,,,,,,,,32,1,4.000000e+000,1.358032e-003,0.000000e+000,0,,0,
1524260590.967,,0.000000e+000,5.600034e+001,-7.152952e-005,0.000000e+000,2,6.785197e-001,0.000000e+000,,,,,,,,,,,,,,32,1,4.000000e+000,4.070282e-003,0.000000e+000,0,,0,
1524260616.157,,0.000000e+000,5.599355e+001,-7.159472e-005,0.000000e+000,2,6.786560e-001,0.000000e+000,,,,,,,,,,,,,,32,1,4.000000e+000,4.070282e-003,0.000000e+000,0,,0,
1524260641.337,,0.000000e+000,5.600510e+001,-7.165747e-005,0.000000e+000,2,6.799033e-001,0.000000e+000,,,,,,,,,,,,,,32,1,4.000000e+000,2.708435e-003,0.000000e+000,0,,0,
1524260666.537,,0.000000e+000,5.600103e+001,-7.172884e-005,0.000000e+000,2,6.794648e-001,0.000000e+000,,,,,,,,,,,,,,32,1,4.000000e+000,5.439758e-003,0.000000e+000,0,,0,
1524260692.217,,0.000000e+000,5.599899e+001,-7.158408e-005,0.000000e+000,2,6.788908e-001,0.000000e+000,,,,,,,,,,,,,,32,1,4.000000e+000,1.358032e-003,0.000000e+000,0,,0,
1524260717.817,,0.000000e+000,5.599966e+001,-7.174396e-005,0.000000e+000,2,6.789184e-001,0.000000e+000,,,,,,,,,,,,,,32,1,4.000000e+000,5.432129e-003,0.000000e+000,0,,0,
1524260742.857,,0.000000e+000,5.599560e+001,-7.176119e-005,0.000000e+000,2,6.791693e-001,0.000000e+000,,,,,,,,,,,,,,32,1,4.000000e+000,5.428314e-003,0.000000e+000,0,,0,
1524260768.087,,0.000000e+000,5.599763e+001,-7.173557e-005,0.000000e+000,2,6.803088e-001,0.000000e+000,,,,,,,,,,,,,,32,1,4.000000e+000,1.361847e-003,0.000000e+000,0,,0,
1524260792.697,,0.000000e+000,5.600034e+001,-7.176473e-005,0.000000e+000,2,6.782466e-001,0.000000e+000,,,,,,,,,,,,,,32,1,4.000000e+000,4.070282e-003,0.000000e+000,0,,0,
1524260817.847,,0.000000e+000,5.599967e+001,-7.183681e-005,0.000000e+000,2,6.798227e-001,0.000000e+000,,,,,,,,,,,,,,32,1,4.000000e+000,2.719879e-003,0.000000e+000,0,,0,
1524260842.957,,0.000000e+000,5.599695e+001,-7.189110e-005,0.000000e+000,2,6.793136e-001,0.000000e+000,,,,,,,,,,,,,,32,1,4.000000e+000,0.000000e+000,0.000000e+000,0,,0,
1524260868.037,,0.000000e+000,5.599831e+001,-7.189456e-005,0.000000e+000,2,6.802618e-001,0.000000e+000,,,,,,,,,,,,,,32,1,4.000000e+000,2.719879e-003,0.000000e+000,0,,0,
1524260892.607,,0.000000e+000,5.599966e+001,-7.191749e-005,0.000000e+000,2,6.797002e-001,0.000000e+000,,,,,,,,,,,,,,32,1,4.000000e+000,5.432129e-003,0.000000e+000,0,,0,
1524260917.907,,0.000000e+000,5.599492e+001,-7.196806e-005,0.000000e+000,2,6.792970e-001,0.000000e+000,,,,,,,,,,,,,,32,1,4.000000e+000,1.222992e-002,0.000000e+000,0,,0,
1524260943.087,,0.000000e+000,5.599763e+001,-7.198007e-005,0.000000e+000,2,6.791039e-001,0.000000e+000,,,,,,,,,,,,,,32,1,4.000000e+000,1.222992e-002,0.000000e+000,0,,0,
1524260967.747,,0.000000e+000,5.599899e+001,-7.179035e-005,0.000000e+000,2,6.788483e-001,0.000000e+000,,,,,,,,,,,,,,32,1,4.000000e+000,9.510040e-003,0.000000e+000,0,,0,
1524260992.557,,0.000000e+000,5.599355e+001,-7.197158e-005,0.000000e+000,2,6.805580e-001,0.000000e+000,,,,,,,,,,,,,,32,1,4.000000e+000,6.786346e-003,0.000000e+000,0,,0,
1524261017.717,,0.000000e+000,5.599763e+001,-7.196963e-005,0.000000e+000,2,6.800045e-001,0.000000e+000,,,,,,,,,,,,,,32,1,4.000000e+000,1.361847e-003,0.000000e+000,0,,0,
1524261043.437,,0.000000e+000,5.600239e+001,-7.204005e-005,0.000000e+000,2,6.802805e-001,0.000000e+000,,,,,,,,,,,,,,32,1,4.000000e+000,2.719879e-003,0.000000e+000,0,,0,
1524261068.397,,0.000000e+000,5.599559e+001,-7.196161e-005,0.000000e+000,2,6.801860e-001,0.000000e+000,,,,,,,,,,,,,,32,1,4.000000e+000,0.000000e+000,0.000000e+000,0,,0,
1524261093.977,,0.000000e+000,5.599492e+001,-7.199698e-005,0.000000e+000,2,6.814024e-001,0.000000e+000,,,,,,,,,,,,,,32,1,4.000000e+000,1.350403e-003,0.000000e+000,0,,0,
1524261119.177,,0.000000e+000,5.599628e+001,-7.214074e-005,0.000000e+000,2,6.813692e-001,0.000000e+000,,,,,,,,,,,,,,32,1,4.000000e+000,4.070282e-003,0.000000e+000,0,,0,
1524261144.867,,0.000000e+000,5.599424e+001,-7.193643e-005,0.000000e+000,2,6.794475e-001,0.000000e+000,,,,,,,,,,,,,,32,1,4.000000e+000,1.358032e-002,0.000000e+000,0,,0,
1524261169.767,,0.000000e+000,5.600034e+001,-7.218585e-005,0.000000e+000,2,6.805934e-001,0.000000e+000,,,,,,,,,,,,,,32,1,4.000000e+000,4.070282e-003,0.000000e+000,0,,0,
1524261195.167,,0.000000e+000,5.600171e+001,-7.214066e-005,0.000000e+000,2,6.810805e-001,0.000000e+000,,,,,,,,,,,,,,32,1,4.000000e+000,4.081726e-003,0.000000e+000,0,,0,
1524261220.897,,0.000000e+000,5.599967e+001,-7.218398e-005,0.000000e+000,2,6.830188e-001,0.000000e+000,,,,,,,,,,,,,,32,1,4.000000e+000,1.086044e-002,0.000000e+000,0,,0,
1524261246.457,,0.000000e+000,5.599899e+001,-7.227873e-005,0.000000e+000,2,6.827749e-001,0.000000e+000,,,,,,,,,,,,,,32,1,4.000000e+000,1.221848e-002,0.000000e+000,0,,0,
1524261271.288,,0.000000e+000,5.599424e+001,-7.223187e-005,0.000000e+000,2,6.815437e-001,0.000000e+000,,,,,,,,,,,,,,32,1,4.000000e+000,8.148193e-003,0.000000e+000,0,,0,
1524261296.998,,0.000000e+000,5.600103e+001,-7.218284e-005,0.000000e+000,2,6.831230e-001,0.000000e+000,,,,,,,,,,,,,,32,1,4.000000e+000,0.000000e+000,0.000000e+000,0,,0,
1524261346.908,,0.000000e+000,5.599763e+001,-7.228630e-005,0.000000e+000,2,6.827334e-001,0.000000e+000,,,,,,,,,,,,,,32,1,4.000000e+000,6.790161e-003,0.000000e+000,0,,0,
1524261372.008,,0.000000e+000,5.599696e+001,-7.244118e-005,0.000000e+000,2,6.836764e-001,0.000000e+000,,,,,,,,,,,,,,32,1,4.000000e+000,8.148193e-003,0.000000e+000,0,,0,
1524261396.808,,0.000000e+000,5.599831e+001,-7.234373e-005,0.000000e+000,2,6.819213e-001,0.000000e+000,,,,,,,,,,,,,,32,1,4.000000e+000,5.439758e-003,0.000000e+000,0,,0,
1524261422.068,,0.000000e+000,5.599831e+001,-7.226790e-005,0.000000e+000,2,6.843820e-001,0.000000e+000,,,,,,,,,,,,,,32,1,4.000000e+000,1.086807e-002,0.000000e+000,0,,0,
1524261447.098,,0.000000e+000,5.599967e+001,-7.228574e-005,0.000000e+000,2,6.832252e-001,0.000000e+000,,,,,,,,,,,,,,32,1,4.000000e+000,1.086044e-002,0.000000e+000,0,,0,
1524261471.988,,0.000000e+000,5.599831e+001,-7.227005e-005,0.000000e+000,2,6.829419e-001,0.000000e+000,,,,,,,,,,,,,,32,1,4.000000e+000,2.719879e-003,0.000000e+000,0,,0,
1524261497.668,,0.000000e+000,5.599492e+001,-7.245119e-005,0.000000e+000,2,6.853138e-001,0.000000e+000,,,,,,,,,,,,,,32,1,4.000000e+000,4.066467e-003,0.000000e+000,0,,0,
1524261522.958,,0.000000e+000,5.599424e+001,-7.248473e-005,0.000000e+000,2,6.840926e-001,0.000000e+000,,,,,,,,,,,,,,32,1,4.000000e+000,2.708435e-003,0.000000e+000,0,,0,
1524261548.248,,0.000000e+000,5.600306e+001,-7.248289e-005,0.000000e+000,2,6.832693e-001,0.000000e+000,,,,,,,,,,,,,,32,1,4.000000e+000,6.790161e-003,0.000000e+000,0,,0,
1524261573.238,,0.000000e+000,5.599763e+001,-7.236122e-005,0.000000e+000,2,6.837056e-001,0.000000e+000,,,,,,,,,,,,,,32,1,4.000000e+000,1.361847e-003,0.000000e+000,0,,0,
1524261598.398,,0.000000e+000,5.599627e+001,-7.253529e-005,0.000000e+000,2,6.846163e-001,0.000000e+000,,,,,,,,,,,,,,32,1,4.000000e+000,1.358032e-003,0.000000e+000,0,,0,
1524261623.318,,0.000000e+000,5.599695e+001,-7.247773e-005,0.000000e+000,2,6.828551e-001,0.000000e+000,,,,,,,,,,,,,,32,1,4.000000e+000,1.086044e-002,0.000000e+000,0,,0,
1524261649.378,,0.000000e+000,5.599899e+001,-7.240481e-005,0.000000e+000,2,6.833754e-001,0.000000e+000,,,,,,,,,,,,,,32,1,4.000000e+000,1.358032e-003,0.000000e+000,0,,0,
1524261674.318,,0.000000e+000,5.599899e+001,-7.262104e-005,0.000000e+000,2,6.831591e-001,0.000000e+000,,,,,,,,,,,,,,32,1,4.000000e+000,1.358032e-003,0.000000e+000,0,,0,
1524261699.768,,0.000000e+000,5.599899e+001,-7.250242e-005,0.000000e+000,2,6.826611e-001,0.000000e+000,,,,,,,,,,,,,,32,1,4.000000e+000,9.510040e-003,0.000000e+000,0,,0,
1524261724.978,,0.000000e+000,5.599559e+001,-7.266959e-005,0.000000e+000,2,6.855406e-001,0.000000e+000,,,,,,,,,,,,,,32,1,4.000000e+000,2.708435e-003,0.000000e+000,0,,0,
1524261749.928,,0.000000e+000,5.599967e+001,-7.258664e-005,0.000000e+000,2,6.838799e-001,0.000000e+000,,,,,,,,,,,,,,32,1,4.000000e+000,1.357651e-002,0.000000e+000,0,,0,
1524261774.888,,0.000000e+000,5.599967e+001,-7.276455e-005,0.000000e+000,2,6.864802e-001,0.000000e+000,,,,,,,,,,,,,,32,1,4.000000e+000,2.719879e-003,0.000000e+000,0,,0,
1524261800.008,,0.000000e+000,5.599355e+001,-7.257843e-005,0.000000e+000,2,6.835868e-001,0.000000e+000,,,,,,,,,,,,,,32,1,4.000000e+000,4.070282e-003,0.000000e+000,0,,0,
1524261824.548,,0.000000e+000,5.599695e+001,-7.282513e-005,0.000000e+000,2,6.846783e-001,0.000000e+000,,,,,,,,,,,,,,32,1,4.000000e+000,2.719879e-003,0.000000e+000,0,,0,
1524261849.218,,0.000000e+000,5.599628e+001,-7.262071e-005,0.000000e+000,2,6.827350e-001,0.000000e+000,,,,,,,,,,,,,,32,1,4.000000e+000,6.786346e-003,0.000000e+000,0,,0,
1524261874.738,,0.000000e+000,5.599287e+001,-7.283537e-005,0.000000e+000,2,6.849354e-001,0.000000e+000,,,,,,,,,,,,,,32,1,4.000000e+000,5.428314e-003,0.000000e+000,0,,0,
1524261899.488,,0.000000e+000,5.600171e+001,-7.285098e-005,0.000000e+000,2,6.852074e-001,0.000000e+000,,,,,,,,,,,,,,32,1,4.000000e+000,1.350403e-003,0.000000e+000,0,,0,
1524261912.018,,0.000000e+000,5.599423e+001,-7.279978e-005,0.000000e+000,2,6.847740e-001,0.000000e+000,,,,,,,,,,,,,,32,1,4.000000e+000,5.428314e-003,0.000000e+000,0,,0,