File: Input/MFn1_VRMac_37K_3000s_VRMde_35K.dc.dat
[Header]
TITLE,MPMS DC Measurement
BYAPP,MPMS Measurement,2.1,Summary
FILEOPENTIME, 1524193325.372000 4/19/2018, 9:02:05 PM

INFO, APPNAME, MPMS MultiVu Application, Revision 1.61,  Build 082

INFO, NAME, MFn1
INFO, WEIGHT, 1.000
INFO, AREA, 1.000
INFO, LENGTH, 1.000
INFO, SHAPE, 0
INFO, COMMENT,
INFO, SEQUENCE FILE: VRMac_37K_3000s_VRMde_35K.seq


INFO, BACKGROUND DATA FILE:, None


STARTUPAXIS,X,4,LINEAR,AUTO,0.000000,0.000000
STARTUPAXIS,Y1,5,LINEAR,AUTO,0.000000,0.000000


STARTUPGROUP,Longitudinal
FIELDGROUP,Longitudinal,1,2,3,4,5,6,7,8,9,15,16,17,18,27,28
FIELDGROUP,Transverse,1,2,3,4,10,11,12,13,14,19,20,21,22,27,28

PLOT_APPEARANCE,ALL,HORZ_GRID_ON,VERT_GRID_ON,MARKERS_AND_LINES

[Data]
Time,Comment,Field (Oe),Temperature (K),Long Moment (emu),Long Scan Std Dev,Long Algorithm,Long Reg Fit,Long Percent Error (%),Trans Moment (emu),Trans Scan Std Dev,Trans Algorithm,Trans Reg Fit,Trans Percent Error (%),Long Moment [w/o ABS] (emu),Long Scan Std Dev [w/o ABS],Long Reg Fit [w/o ABS],Long Percent Error [w/o ABS] (%),Trans Moment [w/o ABS] (emu),Trans Scan Std Dev [w/o ABS],Trans Reg Fit [w/o ABS],Trans Percent Error [w/o ABS] (%),Points per Scan,Scans per Measurement,Scan Length (cm),Delta Temp (K),Rot Position (deg),Error,EC Comp. Running,Using ABS,
1524193325.370,,0.000000e+000,3.499833e+001,-1.808858e-005,0.000000e+000,3,9.471307e-001,0.000000e+000,,,,,,,,,,,,,,32,1,4.000000e+000,2.349854e-003,0.000000e+000,0,,0,
1524193362.950,,0.000000e+000,3.500145e+001,-1.783621e-005,0.000000e+000,3,9.479607e-001,0.000000e+000,,,,,,,,,,,,,,32,1,4.000000e+000,2.349854e-003,0.000000e+000,0,,0,
1524193400.728,,0.000000e+000,3.500028e+001,-1.740055e-005,0.000000e+000,3,9.475861e-001,0.000000e+000,,,,,,,,,,,,,,32,1,4.000000e+000,1.560211e-003,0.000000e+000,0,,0,
1524193438.869,,0.000000e+000,3.499989e+001,-1.698711e-005,0.000000e+000,3,9.451966e-001,0.000000e+000,,,,,,,,,,,,,,32,1,4.000000e+000,2.342224e-003,0.000000e+000,0,,0,
1524193476.810,,0.000000e+000,3.499872e+001,-1.656380e-005,0.000000e+000,3,9.437060e-001,0.000000e+000,,,,,,,,,,,,,,32,1,4.000000e+000,0.000000e+000,0.000000e+000,0,,0,
1524193515.008,,0.000000e+000,3.499754e+001,-1.621485e-005,0.000000e+000,3,9.455908e-001,0.000000e+000,,,,,,,,,,,,,,32,1,4.000000e+000,2.349854e-003,0.000000e+000,0,,0,
1524193552.923,,0.000000e+000,3.499950e+001,-1.589943e-005,0.000000e+000,3,9.425440e-001,0.000000e+000,,,,,,,,,,,,,,32,1,4.000000e+000,0.000000e+000,0.000000e+000,0,,0,
1524193590.949,,0.000000e+000,3.499833e+001,-1.552302e-005,0.000000e+000,3,9.418185e-001,0.000000e+000,,,,,,,,,,,,,,32,1,4.000000e+000,7.781982e-004,0.000000e+000,0,,0,
1524193628.642,,0.000000e+000,3.499872e+001,-1.528471e-005,0.000000e+000,3,9.393880e-001,0.000000e+000,,,,,,,,,,,,,,32,1,4.000000e+000,0.000000e+000,0.000000e+000,0,,0,
1524193666.745,,0.000000e+000,3.499989e+001,-1.501908e-005,0.000000e+000,3,9.389309e-001,0.000000e+000,,,,,,,,,,,,,,32,1,4.000000e+000,7.781982e-004,0.000000e+000,0,,0,
1524193705.688,,0.000000e+000,3.499911e+001,-1.475027e-005,0.000000e+000,3,9.375760e-001,0.000000e+000,,,,,,,,,,,,,,32,1,4.000000e+000,7.820129e-004,0.000000e+000,0,,0,
1524193743.829,,0.000000e+000,3.499872e+001,-1.446911e-005,0.000000e+000,3,9.361444e-001,0.000000e+000,,,,,,,,,,,,,,32,1,4.000000e+000,0.000000e+000,0.000000e+000,0,,0,
1524193781.942,,0.000000e+000,3.499950e+001,-1.427465e-005,0.000000e+000,3,9.365073e-001,0.000000e+000,,,,,,,,,,,,,,32,1,4.000000e+000,0.000000e+000,0.000000e+000,0,,0,
1524193820.057,,0.000000e+000,3.499872e+001,-1.412661e-005,0.000000e+000,3,9.356617e-001,0.000000e+000,,,,,,,,,,,,,,32,1,4.000000e+000,0.000000e+000,0.000000e+000,0,,0,
1524193858.205,,0.000000e+000,3.499911e+001,-1.386391e-005,0.000000e+000,3,9.336278e-001,0.000000e+000,,,,,,,,,,,,,,32,1,4.000000e+000,7.820129e-004,0.000000e+000,0,,0,
1524193896.333,,0.000000e+000,3.499911e+001,-1.363722e-005,0.000000e+000,3,9.332069e-001,0.000000e+000,,,,,,,,,,,,,,32,1,4.000000e+000,7.820129e-004,0.000000e+000,0,,0,
1524193933.946,,0.000000e+000,3.499871e+001,-1.345009e-005,0.000000e+000,3,9.325181e-001,0.000000e+000,,,,,,,,,,,,,,32,1,4.000000e+000,3.128052e-003,0.000000e+000,0,,0,
1524193972.549,,0.000000e+000,3.499911e+001,-1.329353e-005,0.000000e+000,3,9.330959e-001,0.000000e+000,,,,,,,,,,,,,,32,1,4.000000e+000,7.820129e-004,0.000000e+000,0,,0,
1524194010.660,,0.000000e+000,3.499794e+001,-1.305958e-005,0.000000e+000,3,9.304403e-001,0.000000e+000,,,,,,,,,,,,,,32,1,4.000000e+000,0.000000e+000,0.000000e+000,0,,0,
1524194048.350,,0.000000e+000,3.499872e+001,-1.296146e-005,0.000000e+000,3,9.284708e-001,0.000000e+000,,,,,,,,,,,,,,32,1,4.000000e+000,1.560211e-003,0.000000e+000,0,,0,
1524194085.673,,0.000000e+000,3.499989e+001,-1.273915e-005,0.000000e+000,3,9.286224e-001,0.000000e+000,,,,,,,,,,,,,,32,1,4.000000e+000,7.781982e-004,0.000000e+000,0,,0,
1524194123.329,,0.000000e+000,3.499989e+001,-1.258722e-005,0.000000e+000,3,9.257051e-001,0.000000e+000,,,,,,,,,,,,,,32,1,4.000000e+000,2.342224e-003,0.000000e+000,0,,0,
1524194161.447,,0.000000e+000,3.499872e+001,-1.242329e-005,0.000000e+000,3,9.232374e-001,0.000000e+000,,,,,,,,,,,,,,32,1,4.000000e+000,1.560211e-003,0.000000e+000,0,,0,
1524194199.388,,0.000000e+000,3.499911e+001,-1.234541e-005,0.000000e+000,3,9.287542e-001,0.000000e+000,,,,,,,,,,,,,,32,1,4.000000e+000,7.820129e-004,0.000000e+000,0,,0,
1524194237.333,,0.000000e+000,3.499950e+001,-1.215081e-005,0.000000e+000,3,9.221244e-001,0.000000e+000,,,,,,,,,,,,,,32,1,4.000000e+000,0.000000e+000,0.000000e+000,0,,0,
1524194275.564,,0.000000e+000,3.499950e+001,-1.200744e-005,0.000000e+000,3,9.227375e-001,0.000000e+000,,,,,,,,,,,,,,32,1,4.000000e+000,0.000000e+000,0.000000e+000,0,,0,
1524194313.327,,0.000000e+000,3.499911e+001,-1.189662e-005,0.000000e+000,3,9.235506e-001,0.000000e+000,,,,,,,,,,,,,,32,1,4.000000e+000,7.820129e-004,0.000000e+000,0,,0,
1524194350.732,,0.000000e+000,3.499950e+001,-1.178243e-005,0.000000e+000,3,9.209834e-001,0.000000e+000,,,,,,,,,,,,,,32,1,4.000000e+000,1.560211e-003,0.000000e+000,0,,0,
1524194388.868,,0.000000e+000,3.499872e+001,-1.167977e-005,0.000000e+000,3,9.235129e-001,0.000000e+000,,,,,,,,,,,,,,32,1,4.000000e+000,1.560211e-003,0.000000e+000,0,,0,
1524194426.199,,0.000000e+000,3.499872e+001,-1.153779e-005,0.000000e+000,3,9.212667e-001,0.000000e+000,,,,,,,,,,,,,,32,1,4.000000e+000,1.560211e-003,0.000000e+000,0,,0,
1524194464.319,,0.000000e+000,3.499911e+001,-1.140583e-005,0.000000e+000,3,9.183589e-001,0.000000e+000,,,,,,,,,,,,,,32,1,4.000000e+000,2.338409e-003,0.000000e+000,0,,0,
1524194502.465,,0.000000e+000,3.499911e+001,-1.127377e-005,0.000000e+000,3,9.180382e-001,0.000000e+000,,,,,,,,,,,,,,32,1,4.000000e+000,7.820129e-004,0.000000e+000,0,,0,
1524194540.580,,0.000000e+000,3.499989e+001,-1.119184e-005,0.000000e+000,3,9.172814e-001,0.000000e+000,,,,,,,,,,,,,,32,1,4.000000e+000,7.781982e-004,0.000000e+000,0,,0,
1524194578.753,,0.000000e+000,3.499872e+001,-1.107409e-005,0.000000e+000,3,9.174424e-001,0.000000e+000,,,,,,,,,,,,,,32,1,4.000000e+000,1.560211e-003,0.000000e+000,0,,0,
1524194616.896,,0.000000e+000,3.499950e+001,-1.102608e-005,0.000000e+000,3,9.189405e-001,0.000000e+000,,,,,,,,,,,,,,32,1,4.000000e+000,1.560211e-003,0.000000e+000,0,,0,
1524194654.984,,0.000000e+000,3.499911e+001,-1.089239e-005,0.000000e+000,3,9.141676e-001,0.000000e+000,,,,,,,,,,,,,,32,1,4.000000e+000,7.820129e-004,0.000000e+000,0,,0,
1524194693.130,,0.000000e+000,3.499911e+001,-1.077471e-005,0.000000e+000,3,9.159369e-001,0.000000e+000,,,,,,,,,,,,,,32,1,4.000000e+000,7.820129e-004,0.000000e+000,0,,0,
1524194730.768,,0.000000e+000,3.499950e+001,-1.062129e-005,0.000000e+000,3,9.112720e-001,0.000000e+000,,,,,,,,,,,,,,32,1,4.000000e+000,0.000000e+000,0.000000e+000,0,,0,
1524194768.886,,0.000000e+000,3.499989e+001,-1.054521e-005,0.000000e+000,3,9.107158e-001,0.000000e+000,,,,,,,,,,,,,,32,1,4.000000e+000,7.781982e-004,0.000000e+000,0,,0,
1524194806.266,,0.000000e+000,3.499911e+001,-1.050427e-005,0.000000e+000,3,9.140280e-001,0.000000e+000,,,,,,,,,,,,,,32,1,4.000000e+000,7.820129e-004,0.000000e+000,0,,0,
1524194844.790,,0.000000e+000,3.499950e+001,-1.041007e-005,0.000000e+000,3,9.120129e-001,0.000000e+000,,,,,,,,,,,,,,32,1,4.000000e+000,0.000000e+000,0.000000e+000,0,,0,
1524194882.908,,0.000000e+000,3.499911e+001,-1.032988e-005,0.000000e+000,3,9.115273e-001,0.000000e+000,,,,,,,,,,,,,,32,1,4.000000e+000,7.820129e-004,0.000000e+000,0,,0,
1524194920.608,,0.000000e+000,3.499950e+001,-1.023080e-005,0.000000e+000,3,9.114949e-001,0.000000e+000,,,,,,,,,,,,,,32,1,4.000000e+000,1.560211e-003,0.000000e+000,0,,0,
1524194958.756,,0.000000e+000,3.499989e+001,-1.014649e-005,0.000000e+000,3,9.093434e-001,0.000000e+000,,,,,,,,,,,,,,32,1,4.000000e+000,7.781982e-004,0.000000e+000,0,,0,
1524194996.874,,0.000000e+000,3.499872e+001,-1.009057e-005,0.000000e+000,3,9.109437e-001,0.000000e+000,,,,,,,,,,,,,,32,1,4.000000e+000,0.000000e+000,0.000000e+000,0,,0,
1524195034.997,,0.000000e+000,3.499911e+001,-1.000057e-005,0.000000e+000,3,9.105902e-001,0.000000e+000,,,,,,,,,,,,,,32,1,4.000000e+000,7.820129e-004,0.000000e+000,0,,0,
1524195073.041,,0.000000e+000,3.499989e+001,-9.932052e-006,0.000000e+000,3,9.085364e-001,0.000000e+000,,,,,,,,,,,,,,32,1,4.000000e+000,7.781982e-004,0.000000e+000,0,,0,
1524195111.229,,0.000000e+000,3.499872e+001,-9.822758e-006,0.000000e+000,3,9.076695e-001,0.000000e+000,,,,,,,,,,,,,,32,1,4.000000e+000,0.000000e+000,0.000000e+000,0,,0,
1524195149.307,,0.000000e+000,3.499989e+001,-9.759862e-006,0.000000e+000,3,9.054930e-001,0.000000e+000,,,,,,,,,,,,,,32,1,4.000000e+000,7.781982e-004,0.000000e+000,0,,0,
1524195186.997,,0.000000e+000,3.499832e+001,-9.681383e-006,0.000000e+000,3,9.036067e-001,0.000000e+000,,,,,,,,,,,,,,32,1,4.000000e+000,3.910065e-003,0.000000e+000,0,,0,
1524195225.050,,0.000000e+000,3.499872e+001,-9.610620e-006,0.000000e+000,3,9.054012e-001,0.000000e+000,,,,,,,,,,,,,,32,1,4.000000e+000,0.000000e+000,0.000000e+000,0,,0,
1524195263.188,,0.000000e+000,3.499950e+001,-9.524018e-006,0.000000e+000,3,9.022910e-001,0.000000e+000,,,,,,,,,,,,,,32,1,4.000000e+000,0.000000e+000,0.000000e+000,0,,0,
1524195300.649,,0.000000e+000,3.499989e+001,-9.462464e-006,0.000000e+000,3,9.048851e-001,0.000000e+000,,,,,,,,,,,,,,32,1,4.000000e+000,7.781982e-004,0.000000e+000,0,,0,
1524195337.864,,0.000000e+000,3.499872e+001,-9.393244e-006,0.000000e+000,3,9.014689e-001,0.000000e+000,,,,,,,,,,,,,,32,1,4.000000e+000,1.560211e-003,0.000000e+000,0,,0,
1524195375.665,,0.000000e+000,3.500106e+001,-9.326127e-006,0.000000e+000,3,9.055465e-001,0.000000e+000,,,,,,,,,,,,,,32,1,4.000000e+000,3.128052e-003,0.000000e+000,0,,0,
1524195413.700,,0.000000e+000,3.499911e+001,-9.255053e-006,0.000000e+000,3,9.009030e-001,0.000000e+000,,,,,,,,,,,,,,32,1,4.000000e+000,7.820129e-004,0.000000e+000,0,,0,
1524195451.833,,0.000000e+000,3.499833e+001,-9.201583e-006,0.000000e+000,3,8.953723e-001,0.000000e+000,,,,,,,,,,,,,,32,1,4.000000e+000,7.781982e-004,0.000000e+000,0,,0,
1524195490.229,,0.000000e+000,3.499754e+001,-9.108320e-006,0.000000e+000,3,8.959489e-001,0.000000e+000,,,,,,,,,,,,,,32,1,4.000000e+000,7.896423e-004,0.000000e+000,0,,0,
1524195528.062,,0.000000e+000,3.499872e+001,-9.000250e-006,0.000000e+000,3,9.002972e-001,0.000000e+000,,,,,,,,,,,,,,32,1,4.000000e+000,0.000000e+000,0.000000e+000,0,,0,
1524195566.203,,0.000000e+000,3.499911e+001,-8.978689e-006,0.000000e+000,3,8.997496e-001,0.000000e+000,,,,,,,,,,,,,,32,1,4.000000e+000,7.820129e-004,0.000000e+000,0,,0,
1524195604.353,,0.000000e+000,3.499872e+001,-8.987585e-006,0.000000e+000,3,8.966344e-001,0.000000e+000,,,,,,,,,,,,,,32,1,4.000000e+000,1.560211e-003,0.000000e+000,0,,0,
1524195642.836,,0.000000e+000,3.499911e+001,-8.894896e-006,0.000000e+000,3,8.960148e-001,0.000000e+000,,,,,,,,,,,,,,32,1,4.000000e+000,7.820129e-004,0.000000e+000,0,,0,
1524195680.549,,0.000000e+000,3.499950e+001,-8.777902e-006,0.000000e+000,3,8.939930e-001,0.000000e+000,,,,,,,,,,,,,,32,1,4.000000e+000,1.560211e-003,0.000000e+000,0,,0,
1524195718.252,,0.000000e+000,3.499911e+001,-8.780509e-006,0.000000e+000,3,8.985180e-001,0.000000e+000,,,,,,,,,,,,,,32,1,4.000000e+000,7.820129e-004,0.000000e+000,0,,0,
1524195756.796,,0.000000e+000,3.499911e+001,-8.644657e-006,0.000000e+000,3,8.970835e-001,0.000000e+000,,,,,,,,,,,,,,32,1,4.000000e+000,7.820129e-004,0.000000e+000,0,,0,
1524195794.831,,0.000000e+000,3.499833e+001,-8.645839e-006,0.000000e+000,3,8.961073e-001,0.000000e+000,,,,,,,,,,,,,,32,1,4.000000e+000,7.781982e-004,0.000000e+000,0,,0,
1524195832.564,,0.000000e+000,3.499872e+001,-8.513854e-006,0.000000e+000,3,8.949822e-001,0.000000e+000,,,,,,,,,,,,,,32,1,4.000000e+000,0.000000e+000,0.000000e+000,0,,0,
1524195870.225,,0.000000e+000,3.499911e+001,-8.489578e-006,0.000000e+000,3,8.933307e-001,0.000000e+000,,,,,,,,,,,,,,32,1,4.000000e+000,7.820129e-004,0.000000e+000,0,,0,
1524195908.360,,0.000000e+000,3.499989e+001,-8.431137e-006,0.000000e+000,3,8.954247e-001,0.000000e+000,,,,,,,,,,,,,,32,1,4.000000e+000,7.781982e-004,0.000000e+000,0,,0,
1524195946.488,,0.000000e+000,3.499872e+001,-8.442809e-006,0.000000e+000,3,8.898716e-001,0.000000e+000,,,,,,,,,,,,,,32,1,4.000000e+000,1.560211e-003,0.000000e+000,0,,0,
1524195983.829,,0.000000e+000,3.499911e+001,-8.344381e-006,0.000000e+000,3,8.851227e-001,0.000000e+000,,,,,,,,,,,,,,32,1,4.000000e+000,7.820129e-004,0.000000e+000,0,,0,
1524196021.587,,0.000000e+000,3.499989e+001,-8.367098e-006,0.000000e+000,3,8.939752e-001,0.000000e+000,,,,,,,,,,,,,,32,1,4.000000e+000,7.781982e-004,0.000000e+000,0,,0,
1524196059.555,,0.000000e+000,3.499833e+001,-8.261086e-006,0.000000e+000,3,8.863333e-001,0.000000e+000,,,,,,,,,,,,,,32,1,4.000000e+000,7.781982e-004,0.000000e+000,0,,0,
1524196097.700,,0.000000e+000,3.499911e+001,-8.189543e-006,0.000000e+000,3,8.874368e-001,0.000000e+000,,,,,,,,,,,,,,32,1,4.000000e+000,7.820129e-004,0.000000e+000,0,,0,
1524196135.951,,0.000000e+000,3.499911e+001,-8.180148e-006,0.000000e+000,3,8.877288e-001,0.000000e+000,,,,,,,,,,,,,,32,1,4.000000e+000,7.820129e-004,0.000000e+000,0,,0,
1524196173.967,,0.000000e+000,3.499872e+001,-8.141545e-006,0.000000e+000,3,8.880207e-001,0.000000e+000,,,,,,,,,,,,,,32,1,4.000000e+000,0.000000e+000,0.000000e+000,0,,0,
1524196212.095,,0.000000e+000,3.499911e+001,-8.041487e-006,0.000000e+000,3,8.879231e-001,0.000000e+000,,,,,,,,,,,,,,32,1,4.000000e+000,7.820129e-004,0.000000e+000,0,,0,
1524196250.250,,0.000000e+000,3.499833e+001,-8.021678e-006,0.000000e+000,3,8.859270e-001,0.000000e+000,,,,,,,,,,,,,,32,1,4.000000e+000,7.781982e-004,0.000000e+000,0,,0,
1524196288.358,,0.000000e+000,3.499989e+001,-7.942675e-006,0.000000e+000,3,8.883298e-001,0.000000e+000,,,,,,,,,,,,,,32,1,4.000000e+000,7.781982e-004,0.000000e+000,0,,0,
1524196326.234,,0.000000e+000,3.499989e+001,-7.891102e-006,0.000000e+000,3,8.781278e-001,0.000000e+000,,,,,,,,,,,,,,32,1,4.000000e+000,7.781982e-004,0.000000e+000,0,,0,
1524196364.152,,0.000000e+000,3.499872e+001,-7.847503e-006,0.000000e+000,3,8.825857e-001,0.000000e+000,,,,,,,,,,,,,,32,1,4.000000e+000,1.560211e-003,0.000000e+000,0,,0,
1524196402.128,,0.000000e+000,3.499911e+001,-7.832588e-006,0.000000e+000,3,8.840335e-001,0.000000e+000,,,,,,,,,,,,,,32,1,4.000000e+000,7.820129e-004,0.000000e+000,0,,0,
1524196439.711,,0.000000e+000,3.499950e+001,-7.745750e-006,0.000000e+000,3,8.881972e-001,0.000000e+000,,,,,,,,,,,,,,32,1,4.000000e+000,0.000000e+000,0.000000e+000,0,,0,
1524196477.964,,0.000000e+000,3.499833e+001,-7.665890e-006,0.000000e+000,3,8.759930e-001,0.000000e+000,,,,,,,,,,,,,,32,1,4.000000e+000,2.349854e-003,0.000000e+000,0,,0,
1524196516.277,,0.000000e+000,3.499872e+001,-7.704523e-006,0.000000e+000,3,8.824312e-001,0.000000e+000,,,,,,,,,,,,,,32,1,4.000000e+000,1.560211e-003,0.000000e+000,0,,0,
1524196554.422,,0.000000e+000,3.499872e+001,-7.652131e-006,0.000000e+000,3,8.783598e-001,0.000000e+000,,,,,,,,,,,,,,32,1,4.000000e+000,0.000000e+000,0.000000e+000,0,,0,
1524196593.625,,0.000000e+000,3.499950e+001,-7.594426e-006,0.000000e+000,3,8.765975e-001,0.000000e+000,,,,,,,,,,,,,,32,1,4.000000e+000,0.000000e+000,0.000000e+000,0,,0,
1524196631.711,,0.000000e+000,3.499989e+001,-7.582977e-006,0.000000e+000,3,8.793850e-001,0.000000e+000,,,,,,,,,,,,,,32,1,4.000000e+000,7.781982e-004,0.000000e+000,0,,0,
1524196669.894,,0.000000e+000,3.499911e+001,-7.563953e-006,0.000000e+000,3,8.820888e-001,0.000000e+000,,,,,,,,,,,,,,32,1,4.000000e+000,7.820129e-004,0.000000e+000,0,,0,
1524196708.424,,0.000000e+000,3.499833e+001,-7.507844e-006,0.000000e+000,3,8.782594e-001,0.000000e+000,,,,,,,,,,,,,,32,1,4.000000e+000,7.781982e-004,0.000000e+000,0,,0,
1524196744.810,,0.000000e+000,3.499911e+001,-7.315326e-006,0.000000e+000,3,8.722569e-001,0.000000e+000,,,,,,,,,,,,,,32,1,4.000000e+000,7.820129e-004,0.000000e+000,0,,0,
1524196783.063,,0.000000e+000,3.499989e+001,-7.432593e-006,0.000000e+000,3,8.844696e-001,0.000000e+000,,,,,,,,,,,,,,32,1,4.000000e+000,7.781982e-004,0.000000e+000,0,,0,
1524196821.094,,0.000000e+000,3.499989e+001,-7.387849e-006,0.000000e+000,3,8.807092e-001,0.000000e+000,,,,,,,,,,,,,,32,1,4.000000e+000,7.781982e-004,0.000000e+000,0,,0,
1524196858.639,,0.000000e+000,3.500106e+001,-7.299333e-006,0.000000e+000,3,8.757977e-001,0.000000e+000,,,,,,,,,,,,,,32,1,4.000000e+000,1.560211e-003,0.000000e+000,0,,0,
1524196896.785,,0.000000e+000,3.499833e+001,-7.360597e-006,0.000000e+000,3,8.768637e-001,0.000000e+000,,,,,,,,,,,,,,32,1,4.000000e+000,7.781982e-004,0.000000e+000,0,,0,
1524196934.855,,0.000000e+000,3.499989e+001,-7.317917e-006,0.000000e+000,3,8.697561e-001,0.000000e+000,,,,,,,,,,,,,,32,1,4.000000e+000,2.342224e-003,0.000000e+000,0,,0,
1524196972.748,,0.000000e+000,3.499794e+001,-7.206770e-006,0.000000e+000,3,8.661131e-001,0.000000e+000,,,,,,,,,,,,,,32,1,4.000000e+000,0.000000e+000,0.000000e+000,0,,0,
1524197010.574,,0.000000e+000,3.499950e+001,-7.129607e-006,0.000000e+000,3,8.698406e-001,0.000000e+000,,,,,,,,,,,,,,32,1,4.000000e+000,0.000000e+000,0.000000e+000,0,,0,
1524197048.339,,0.000000e+000,3.499793e+001,-7.147553e-006,0.000000e+000,3,8.776438e-001,0.000000e+000,,,,,,,,,,,,,,32,1,4.000000e+000,1.567841e-003,0.000000e+000,0,,0,
1524197085.913,,0.000000e+000,3.499833e+001,-7.180470e-006,0.000000e+000,3,8.742226e-001,0.000000e+000,,,,,,,,,,,,,,32,1,4.000000e+000,7.781982e-004,0.000000e+000,0,,0,
1524197124.131,,0.000000e+000,3.499911e+001,-7.082048e-006,0.000000e+000,3,8.682858e-001,0.000000e+000,,,,,,,,,,,,,,32,1,4.000000e+000,7.820129e-004,0.000000e+000,0,,0,
1524197162.234,,0.000000e+000,3.499911e+001,-7.016917e-006,0.000000e+000,3,8.747246e-001,0.000000e+000,,,,,,,,,,,,,,32,1,4.000000e+000,7.820129e-004,0.000000e+000,0,,0,
1524197200.272,,0.000000e+000,3.499911e+001,-6.985244e-006,0.000000e+000,3,8.692870e-001,0.000000e+000,,,,,,,,,,,,,,32,1,4.000000e+000,2.338409e-003,0.000000e+000,0,,0,
1524197238.382,,0.000000e+000,3.499911e+001,-6.982466e-006,0.000000e+000,3,8.724056e-001,0.000000e+000,,,,,,,,,,,,,,32,1,4.000000e+000,7.820129e-004,0.000000e+000,0,,0,
1524197276.065,,0.000000e+000,3.499871e+001,-6.960963e-006,0.000000e+000,3,8.661075e-001,0.000000e+000,,,,,,,,,,,,,,32,1,4.000000e+000,3.128052e-003,0.000000e+000,0,,0,
1524197314.198,,0.000000e+000,3.499911e+001,-6.893024e-006,0.000000e+000,3,8.723785e-001,0.000000e+000,,,,,,,,,,,,,,32,1,4.000000e+000,7.820129e-004,0.000000e+000,0,,0,
1524197352.954,,0.000000e+000,3.499911e+001,-6.866293e-006,0.000000e+000,3,8.701726e-001,0.000000e+000,,,,,,,,,,,,,,32,1,4.000000e+000,7.820129e-004,0.000000e+000,0,,0,
1524197391.237,,0.000000e+000,3.499872e+001,-6.800046e-006,0.000000e+000,3,8.594249e-001,0.000000e+000,,,,,,,,,,,,,,32,1,4.000000e+000,1.560211e-003,0.000000e+000,0,,0,
1524197429.205,,0.000000e+000,3.499754e+001,-6.801376e-006,0.000000e+000,3,8.666583e-001,0.000000e+000,,,,,,,,,,,,,,32,1,4.000000e+000,2.349854e-003,0.000000e+000,0,,0,
1524197466.841,,0.000000e+000,3.499794e+001,-6.735823e-006,0.000000e+000,3,8.613409e-001,0.000000e+000,,,,,,,,,,,,,,32,1,4.000000e+000,0.000000e+000,0.000000e+000,0,,0,
1524197504.934,,0.000000e+000,3.500067e+001,-6.674535e-006,0.000000e+000,3,8.616381e-001,0.000000e+000,,,,,,,,,,,,,,32,1,4.000000e+000,2.338409e-003,0.000000e+000,0,,0,
1524197542.309,,0.000000e+000,3.499911e+001,-6.668108e-006,0.000000e+000,3,8.628478e-001,0.000000e+000,,,,,,,,,,,,,,32,1,4.000000e+000,7.820129e-004,0.000000e+000,0,,0,
1524197580.467,,0.000000e+000,3.499950e+001,-6.683541e-006,0.000000e+000,3,8.667060e-001,0.000000e+000,,,,,,,,,,,,,,32,1,4.000000e+000,0.000000e+000,0.000000e+000,0,,0,
1524197618.023,,0.000000e+000,3.499950e+001,-6.606037e-006,0.000000e+000,3,8.603722e-001,0.000000e+000,,,,,,,,,,,,,,32,1,4.000000e+000,0.000000e+000,0.000000e+000,0,,0,
1524197656.666,,0.000000e+000,3.499872e+001,-6.575648e-006,0.000000e+000,3,8.639418e-001,0.000000e+000,,,,,,,,,,,,,,32,1,4.000000e+000,0.000000e+000,0.000000e+000,0,,0,
1524197695.164,,0.000000e+000,3.499950e+001,-6.550278e-006,0.000000e+000,3,8.573987e-001,0.000000e+000,,,,,,,,,,,,,,32,1,4.000000e+000,0.000000e+000,0.000000e+000,0,,0,
1524197732.757,,0.000000e+000,3.499911e+001,-6.493670e-006,0.000000e+000,3,8.583553e-001,0.000000e+000,,,,,,,,,,,,,,32,1,4.000000e+000,7.820129e-004,0.000000e+000,0,,0,
1524197770.400,,0.000000e+000,3.500028e+001,-6.468247e-006,0.000000e+000,3,8.655908e-001,0.000000e+000,,,,,,,,,,,,,,32,1,4.000000e+000,0.000000e+000,0.000000e+000,0,,0,
1524197808.513,,0.000000e+000,3.499989e+001,-6.462804e-006,0.000000e+000,3,8.620507e-001,0.000000e+000,,,,,,,,,,,,,,32,1,4.000000e+000,7.781982e-004,0.000000e+000,0,,0,
1524197847.674,,0.000000e+000,3.499911e+001,-6.415214e-006,0.000000e+000,3,8.587363e-001,0.000000e+000,,,,,,,,,,,,,,32,1,4.000000e+000,7.820129e-004,0.000000e+000,0,,0,
1524197884.597,,0.000000e+000,3.499989e+001,-6.411039e-006,0.000000e+000,3,8.553193e-001,0.000000e+000,,,,,,,,,,,,,,32,1,4.000000e+000,7.781982e-004,0.000000e+000,0,,0,
1524197921.967,,0.000000e+000,3.499950e+001,-6.346990e-006,0.000000e+000,3,8.531296e-001,0.000000e+000,,,,,,,,,,,,,,32,1,4.000000e+000,0.000000e+000,0.000000e+000,0,,0,
1524197959.635,,0.000000e+000,3.499950e+001,-6.332846e-006,0.000000e+000,3,8.571134e-001,0.000000e+000,,,,,,,,,,,,,,32,1,4.000000e+000,0.000000e+000,0.000000e+000,0,,0,
1524197998.213,,0.000000e+000,3.499911e+001,-6.313076e-006,0.000000e+000,3,8.540092e-001,0.000000e+000,,,,,,,,,,,,,,32,1,4.000000e+000,7.820129e-004,0.000000e+000,0,,0,
1524198035.866,,0.000000e+000,3.499872e+001,-6.318581e-006,0.000000e+000,3,8.545272e-001,0.000000e+000,,,,,,,,,,,,,,32,1,4.000000e+000,0.000000e+000,0.000000e+000,0,,0,
1524198073.995,,0.000000e+000,3.499872e+001,-6.283097e-006,0.000000e+000,3,8.572225e-001,0.000000e+000,,,,,,,,,,,,,,32,1,4.000000e+000,0.000000e+000,0.000000e+000,0,,0,
1524198112.115,,0.000000e+000,3.499911e+001,-6.252888e-006,0.000000e+000,3,8.542528e-001,0.000000e+000,,,,,,,,,,,,,,32,1,4.000000e+000,7.820129e-004,0.000000e+000,0,,0,
1524198150.146,,0.000000e+000,3.499833e+001,-6.163776e-006,0.000000e+000,3,8.527490e-001,0.000000e+000,,,,,,,,,,,,,,32,1,4.000000e+000,2.349854e-003,0.000000e+000,0,,0,
1524198187.856,,0.000000e+000,3.499872e+001,-6.149307e-006,0.000000e+000,3,8.498262e-001,0.000000e+000,,,,,,,,,,,,,,32,1,4.000000e+000,1.560211e-003,0.000000e+000,0,,0,
1524198225.737,,0.000000e+000,3.499950e+001,-6.174103e-006,0.000000e+000,3,8.561059e-001,0.000000e+000,,,,,,,,,,,,,,32,1,4.000000e+000,1.560211e-003,0.000000e+000,0,,0,
1524198263.275,,0.000000e+000,3.499911e+001,-6.142217e-006,0.000000e+000,3,8.494213e-001,0.000000e+000,,,,,,,,,,,,,,32,1,4.000000e+000,7.820129e-004,0.000000e+000,0,,0,
1524198301.393,,0.000000e+000,3.499872e+001,-6.088007e-006,0.000000e+000,3,8.498681e-001,0.000000e+000,,,,,,,,,,,,,,32,1,4.000000e+000,0.000000e+000,0.000000e+000,0,,0,
1524198339.316,,0.000000e+000,3.499989e+001,-6.063729e-006,0.000000e+000,3,8.489586e-001,0.000000e+000,,,,,,,,,,,,,,32,1,4.000000e+000,7.781982e-004,0.000000e+000,0,,0,
1524198377.311,,0.000000e+000,3.499911e+001,-6.013247e-006,0.000000e+000,3,8.450978e-001,0.000000e+000,,,,,,,,,,,,,,32,1,4.000000e+000,7.820129e-004,0.000000e+000,0,,0,
1524198415.235,,0.000000e+000,3.499872e+001,-6.032818e-006,0.000000e+000,3,8.501465e-001,0.000000e+000,,,,,,,,,,,,,,32,1,4.000000e+000,0.000000e+000,0.000000e+000,0,,0,
1524198453.353,,0.000000e+000,3.499872e+001,-5.972232e-006,0.000000e+000,3,8.484362e-001,0.000000e+000,,,,,,,,,,,,,,32,1,4.000000e+000,1.560211e-003,0.000000e+000,0,,0,
1524198491.478,,0.000000e+000,3.499989e+001,-6.018350e-006,0.000000e+000,3,8.454220e-001,0.000000e+000,,,,,,,,,,,,,,32,1,4.000000e+000,7.781982e-004,0.000000e+000,0,,0,
1524198529.394,,0.000000e+000,3.499833e+001,-5.842842e-006,0.000000e+000,3,8.406003e-001,0.000000e+000,,,,,,,,,,,,,,32,1,4.000000e+000,2.349854e-003,0.000000e+000,0,,0,
1524198568.337,,0.000000e+000,3.499911e+001,-5.920769e-006,0.000000e+000,3,8.481824e-001,0.000000e+000,,,,,,,,,,,,,,32,1,4.000000e+000,7.820129e-004,0.000000e+000,0,,0,
1524198605.622,,0.000000e+000,3.499911e+001,-5.936794e-006,0.000000e+000,3,8.453892e-001,0.000000e+000,,,,,,,,,,,,,,32,1,4.000000e+000,7.820129e-004,0.000000e+000,0,,0,
1524198643.473,,0.000000e+000,3.499911e+001,-5.898989e-006,0.000000e+000,3,8.499193e-001,0.000000e+000,,,,,,,,,,,,,,32,1,4.000000e+000,7.820129e-004,0.000000e+000,0,,0,
1524198682.303,,0.000000e+000,3.499872e+001,-5.839244e-006,0.000000e+000,3,8.410515e-001,0.000000e+000,,,,,,,,,,,,,,32,1,4.000000e+000,0.000000e+000,0.000000e+000,0,,0,
1524198719.964,,0.000000e+000,3.499911e+001,-5.797881e-006,0.000000e+000,3,8.380964e-001,0.000000e+000,,,,,,,,,,,,,,32,1,4.000000e+000,7.820129e-004,0.000000e+000,0,,0,
1524198757.295,,0.000000e+000,3.499911e+001,-5.809613e-006,0.000000e+000,3,8.477127e-001,0.000000e+000,,,,,,,,,,,,,,32,1,4.000000e+000,7.820129e-004,0.000000e+000,0,,0,
1524198795.378,,0.000000e+000,3.499950e+001,-5.743106e-006,0.000000e+000,3,8.447365e-001,0.000000e+000,,,,,,,,,,,,,,32,1,4.000000e+000,1.560211e-003,0.000000e+000,0,,0,
1524198833.531,,0.000000e+000,3.499950e+001,-5.751388e-006,0.000000e+000,3,8.417060e-001,0.000000e+000,,,,,,,,,,,,,,32,1,4.000000e+000,0.000000e+000,0.000000e+000,0,,0,
1524198871.604,,0.000000e+000,3.499833e+001,-5.694852e-006,0.000000e+000,3,8.420378e-001,0.000000e+000,,,,,,,,,,,,,,32,1,4.000000e+000,2.349854e-003,0.000000e+000,0,,0,
1524198909.809,,0.000000e+000,3.499950e+001,-5.708890e-006,0.000000e+000,3,8.381249e-001,0.000000e+000,,,,,,,,,,,,,,32,1,4.000000e+000,1.560211e-003,0.000000e+000,0,,0,
1524198947.885,,0.000000e+000,3.499911e+001,-5.671178e-006,0.000000e+000,3,8.430254e-001,0.000000e+000,,,,,,,,,,,,,,32,1,4.000000e+000,7.820129e-004,0.000000e+000,0,,0,
1524198986.015,,0.000000e+000,3.499754e+001,-5.633192e-006,0.000000e+000,3,8.403148e-001,0.000000e+000,,,,,,,,,,,,,,32,1,4.000000e+000,7.896423e-004,0.000000e+000,0,,0,
1524199024.128,,0.000000e+000,3.500067e+001,-5.592611e-006,0.000000e+000,3,8.343313e-001,0.000000e+000,,,,,,,,,,,,,,32,1,4.000000e+000,7.820129e-004,0.000000e+000,0,,0,
1524199062.837,,0.000000e+000,3.499950e+001,-5.598852e-006,0.000000e+000,3,8.360239e-001,0.000000e+000,,,,,,,,,,,,,,32,1,4.000000e+000,3.120422e-003,0.000000e+000,0,,0,
1524199101.007,,0.000000e+000,3.500028e+001,-5.579565e-006,0.000000e+000,3,8.330135e-001,0.000000e+000,,,,,,,,,,,,,,32,1,4.000000e+000,0.000000e+000,0.000000e+000,0,,0,
1524199138.523,,0.000000e+000,3.500028e+001,-5.569502e-006,0.000000e+000,3,8.359590e-001,0.000000e+000,,,,,,,,,,,,,,32,1,4.000000e+000,1.560211e-003,0.000000e+000,0,,0,
1524199176.648,,0.000000e+000,3.500028e+001,-5.503655e-006,0.000000e+000,3,8.408075e-001,0.000000e+000,,,,,,,,,,,,,,32,1,4.000000e+000,0.000000e+000,0.000000e+000,0,,0,
1524199214.761,,0.000000e+000,3.499833e+001,-5.499617e-006,0.000000e+000,3,8.292400e-001,0.000000e+000,,,,,,,,,,,,,,32,1,4.000000e+000,7.781982e-004,0.000000e+000,0,,0,
1524199252.384,,0.000000e+000,3.499950e+001,-5.465522e-006,0.000000e+000,3,8.292478e-001,0.000000e+000,,,,,,,,,,,,,,32,1,4.000000e+000,1.560211e-003,0.000000e+000,0,,0,
1524199291.000,,0.000000e+000,3.499833e+001,-5.467825e-006,0.000000e+000,3,8.333893e-001,0.000000e+000,,,,,,,,,,,,,,32,1,4.000000e+000,7.781982e-004,0.000000e+000,0,,0,
1524199328.660,,0.000000e+000,3.499950e+001,-5.435773e-006,0.000000e+000,3,8.377983e-001,0.000000e+000,,,,,,,,,,,,,,32,1,4.000000e+000,1.560211e-003,0.000000e+000,0,,0,
1524199366.766,,0.000000e+000,3.499911e+001,-5.406870e-006,0.000000e+000,3,8.167604e-001,0.000000e+000,,,,,,,,,,,,,,32,1,4.000000e+000,2.338409e-003,0.000000e+000,0,,0,
1524199404.907,,0.000000e+000,3.499950e+001,-5.404956e-006,0.000000e+000,3,8.268105e-001,0.000000e+000,,,,,,,,,,,,,,32,1,4.000000e+000,1.560211e-003,0.000000e+000,0,,0,
1524199443.000,,0.000000e+000,3.499989e+001,-5.348250e-006,0.000000e+000,3,8.302320e-001,0.000000e+000,,,,,,,,,,,,,,32,1,4.000000e+000,7.781982e-004,0.000000e+000,0,,0,
1524199482.363,,0.000000e+000,3.499872e+001,-5.339127e-006,0.000000e+000,3,8.289901e-001,0.000000e+000,,,,,,,,,,,,,,32,1,4.000000e+000,1.560211e-003,0.000000e+000,0,,0,
1524199520.201,,0.000000e+000,3.499911e+001,-5.346774e-006,0.000000e+000,3,8.290173e-001,0.000000e+000,,,,,,,,,,,,,,32,1,4.000000e+000,2.338409e-003,0.000000e+000,0,,0,
1524199558.429,,0.000000e+000,3.499911e+001,-5.250873e-006,0.000000e+000,3,8.202366e-001,0.000000e+000,,,,,,,,,,,,,,32,1,4.000000e+000,7.820129e-004,0.000000e+000,0,,0,
1524199596.449,,0.000000e+000,3.499911e+001,-5.255823e-006,0.000000e+000,3,8.257811e-001,0.000000e+000,,,,,,,,,,,,,,32,1,4.000000e+000,7.820129e-004,0.000000e+000,0,,0,
1524199634.440,,0.000000e+000,3.499833e+001,-5.242224e-006,0.000000e+000,3,8.163124e-001,0.000000e+000,,,,,,,,,,,,,,32,1,4.000000e+000,7.781982e-004,0.000000e+000,0,,0,
1524199671.498,,0.000000e+000,3.499989e+001,-5.256915e-006,0.000000e+000,3,8.302422e-001,0.000000e+000,,,,,,,,,,,,,,32,1,4.000000e+000,7.781982e-004,0.000000e+000,0,,0,
1524199709.521,,0.000000e+000,3.499911e+001,-5.259132e-006,0.000000e+000,3,8.307139e-001,0.000000e+000,,,,,,,,,,,,,,32,1,4.000000e+000,7.820129e-004,0.000000e+000,0,,0,
1524199747.222,,0.000000e+000,3.499872e+001,-5.221515e-006,0.000000e+000,3,8.214809e-001,0.000000e+000,,,,,,,,,,,,,,32,1,4.000000e+000,0.000000e+000,0.000000e+000,0,,0,
1524199785.537,,0.000000e+000,3.499911e+001,-5.191126e-006,0.000000e+000,3,8.261998e-001,0.000000e+000,,,,,,,,,,,,,,32,1,4.000000e+000,2.338409e-003,0.000000e+000,0,,0,
1524199822.740,,0.000000e+000,3.499872e+001,-5.193714e-006,0.000000e+000,3,8.240110e-001,0.000000e+000,,,,,,,,,,,,,,32,1,4.000000e+000,1.560211e-003,0.000000e+000,0,,0,
1524199860.301,,0.000000e+000,3.499950e+001,-5.125175e-006,0.000000e+000,3,8.192231e-001,0.000000e+000,,,,,,,,,,,,,,32,1,4.000000e+000,0.000000e+000,0.000000e+000,0,,0,
1524199898.416,,0.000000e+000,3.499872e+001,-5.148071e-006,0.000000e+000,3,8.209920e-001,0.000000e+000,,,,,,,,,,,,,,32,1,4.000000e+000,0.000000e+000,0.000000e+000,0,,0,
1524199936.677,,0.000000e+000,3.499950e+001,-5.131455e-006,0.000000e+000,3,8.190849e-001,0.000000e+000,,,,,,,,,,,,,,32,1,4.000000e+000,0.000000e+000,0.000000e+000,0,,0,
1524199974.700,,0.000000e+000,3.499950e+001,-5.081395e-006,0.000000e+000,3,8.188247e-001,0.000000e+000,,,,,,,,,,,,,,32,1,4.000000e+000,0.000000e+000,0.000000e+000,0,,0,
1524200012.193,,0.000000e+000,3.499950e+001,-5.050342e-006,0.000000e+000,3,8.145200e-001,0.000000e+000,,,,,,,,,,,,,,32,1,4.000000e+000,0.000000e+000,0.000000e+000,0,,0,
1524200049.618,,0.000000e+000,3.499950e+001,-5.065285e-006,0.000000e+000,3,8.225239e-001,0.000000e+000,,,,,,,,,,,,,,32,1,4.000000e+000,0.000000e+000,0.000000e+000,0,,0,
1524200088.217,,0.000000e+000,3.499950e+001,-5.036243e-006,0.000000e+000,3,8.154505e-001,0.000000e+000,,,,,,,,,,,,,,32,1,4.000000e+000,0.000000e+000,0.000000e+000,0,,0,
1524200125.785,,0.000000e+000,3.499833e+001,-5.033754e-006,0.000000e+000,3,8.181004e-001,0.000000e+000,,,,,,,,,,,,,,32,1,4.000000e+000,7.781982e-004,0.000000e+000,0,,0,
1524200163.960,,0.000000e+000,3.500028e+001,-5.011618e-006,0.000000e+000,3,8.205498e-001,0.000000e+000,,,,,,,,,,,,,,32,1,4.000000e+000,0.000000e+000,0.000000e+000,0,,0,
1524200201.163,,0.000000e+000,3.499911e+001,-4.972362e-006,0.000000e+000,3,8.164319e-001,0.000000e+000,,,,,,,,,,,,,,32,1,4.000000e+000,7.820129e-004,0.000000e+000,0,,0,
1524200239.624,,0.000000e+000,3.499872e+001,-4.982740e-006,0.000000e+000,3,8.163497e-001,0.000000e+000,,,,,,,,,,,,,,32,1,4.000000e+000,0.000000e+000,0.000000e+000,0,,0,
1524200277.894,,0.000000e+000,3.499950e+001,-4.946266e-006,0.000000e+000,3,8.175481e-001,0.000000e+000,,,,,,,,,,,,,,32,1,4.000000e+000,0.000000e+000,0.000000e+000,0,,0,
1524200316.470,,0.000000e+000,3.499872e+001,-4.896393e-006,0.000000e+000,3,8.131284e-001,0.000000e+000,,,,,,,,,,,,,,32,1,4.000000e+000,0.000000e+000,0.000000e+000,0,,0,
1524200354.075,,0.000000e+000,3.499911e+001,-4.897114e-006,0.000000e+000,3,8.110729e-001,0.000000e+000,,,,,,,,,,,,,,32,1,4.000000e+000,7.820129e-004,0.000000e+000,0,,0,
1524200392.239,,0.000000e+000,3.499872e+001,-4.873682e-006,0.000000e+000,3,8.127055e-001,0.000000e+000,,,,,,,,,,,,,,32,1,4.000000e+000,0.000000e+000,0.000000e+000,0,,0,
1524200430.347,,0.000000e+000,3.499911e+001,-4.855509e-006,0.000000e+000,3,8.086079e-001,0.000000e+000,,,,,,,,,,,,,,32,1,4.000000e+000,7.820129e-004,0.000000e+000,0,,0,
1524200468.482,,0.000000e+000,3.499911e+001,-4.853406e-006,0.000000e+000,3,8.152971e-001,0.000000e+000,,,,,,,,,,,,,,32,1,4.000000e+000,2.338409e-003,0.000000e+000,0,,0,
1524200505.960,,0.000000e+000,3.500028e+001,-4.903423e-006,0.000000e+000,3,8.243334e-001,0.000000e+000,,,,,,,,,,,,,,32,1,4.000000e+000,1.560211e-003,0.000000e+000,0,,0,
1524200543.763,,0.000000e+000,3.499950e+001,-4.825486e-006,0.000000e+000,3,8.109511e-001,0.000000e+000,,,,,,,,,,,,,,32,1,4.000000e+000,0.000000e+000,0.000000e+000,0,,0,
1524200581.916,,0.000000e+000,3.499950e+001,-4.795820e-006,0.000000e+000,3,8.147117e-001,0.000000e+000,,,,,,,,,,,,,,32,1,4.000000e+000,1.560211e-003,0.000000e+000,0,,0,
1524200620.049,,0.000000e+000,3.499950e+001,-4.792427e-006,0.000000e+000,3,8.096958e-001,0.000000e+000,,,,,,,,,,,,,,32,1,4.000000e+000,1.560211e-003,0.000000e+000,0,,0,
1524200658.165,,0.000000e+000,3.499911e+001,-4.774625e-006,0.000000e+000,3,8.103448e-001,0.000000e+000,,,,,,,,,,,,,,32,1,4.000000e+000,7.820129e-004,0.000000e+000,0,,0,
1524200696.220,,0.000000e+000,3.499794e+001,-4.790726e-006,0.000000e+000,3,8.135713e-001,0.000000e+000,,,,,,,,,,,,,,32,1,4.000000e+000,0.000000e+000,0.000000e+000,0,,0,
1524200734.361,,0.000000e+000,3.499911e+001,-4.769249e-006,0.000000e+000,3,8.119066e-001,0.000000e+000,,,,,,,,,,,,,,32,1,4.000000e+000,7.820129e-004,0.000000e+000,0,,0,
1524200772.497,,0.000000e+000,3.499872e+001,-4.724473e-006,0.000000e+000,3,8.080683e-001,0.000000e+000,,,,,,,,,,,,,,32,1,4.000000e+000,0.000000e+000,0.000000e+000,0,,0,
1524200810.727,,0.000000e+000,3.499911e+001,-4.657561e-006,0.000000e+000,3,8.027244e-001,0.000000e+000,,,,,,,,,,,,,,32,1,4.000000e+000,7.820129e-004,0.000000e+000,0,,0,
1524200848.760,,0.000000e+000,3.499872e+001,-4.714830e-006,0.000000e+000,3,8.059464e-001,0.000000e+000,,,,,,,,,,,,,,32,1,4.000000e+000,0.000000e+000,0.000000e+000,0,,0,
1524200886.893,,0.000000e+000,3.499950e+001,-4.659122e-006,0.000000e+000,3,8.108975e-001,0.000000e+000,,,,,,,,,,,,,,32,1,4.000000e+000,0.000000e+000,0.000000e+000,0,,0,
1524200925.014,,0.000000e+000,3.499911e+001,-4.659541e-006,0.000000e+000,3,8.033488e-001,0.000000e+000,,,,,,,,,,,,,,32,1,4.000000e+000,7.820129e-004,0.000000e+000,0,,0,
1524200963.419,,0.000000e+000,3.499911e+001,-4.622527e-006,0.000000e+000,3,8.006456e-001,0.000000e+000,,,,,,,,,,,,,,32,1,4.000000e+000,7.820129e-004,0.000000e+000,0,,0,
1524201001.085,,0.000000e+000,3.499950e+001,-4.633944e-006,0.000000e+000,3,8.060749e-001,0.000000e+000,,,,,,,,,,,,,,32,1,4.000000e+000,0.000000e+000,0.000000e+000,0,,0,
1524201038.431,,0.000000e+000,3.500028e+001,-4.659905e-006,0.000000e+000,3,8.061172e-001,0.000000e+000,,,,,,,,,,,,,,32,1,4.000000e+000,0.000000e+000,0.000000e+000,0,,0,
1524201075.764,,0.000000e+000,3.499989e+001,-4.704279e-006,0.000000e+000,3,8.127117e-001,0.000000e+000,,,,,,,,,,,,,,32,1,4.000000e+000,7.781982e-004,0.000000e+000,0,,0,
1524201113.837,,0.000000e+000,3.499911e+001,-4.553559e-006,0.000000e+000,3,7.949171e-001,0.000000e+000,,,,,,,,,,,,,,32,1,4.000000e+000,2.338409e-003,0.000000e+000,0,,0,
1524201151.995,,0.000000e+000,3.499950e+001,-4.548195e-006,0.000000e+000,3,7.905083e-001,0.000000e+000,,,,,,,,,,,,,,32,1,4.000000e+000,0.000000e+000,0.000000e+000,0,,0,
1524201190.643,,0.000000e+000,3.499872e+001,-4.523351e-006,0.000000e+000,3,8.056967e-001,0.000000e+000,,,,,,,,,,,,,,32,1,4.000000e+000,0.000000e+000,0.000000e+000,0,,0,
1524201227.956,,0.000000e+000,3.499950e+001,-4.541133e-006,0.000000e+000,3,7.667156e-001,0.000000e+000,,,,,,,,,,,,,,32,1,4.000000e+000,0.000000e+000,0.000000e+000,0,,0,
1524201266.304,,0.000000e+000,3.499950e+001,-4.471195e-006,0.000000e+000,3,7.911292e-001,0.000000e+000,,,,,,,,,,,,,,32,1,4.000000e+000,1.560211e-003,0.000000e+000,0,,0,
1524201303.964,,0.000000e+000,3.499989e+001,-4.425197e-006,0.000000e+000,3,7.806345e-001,0.000000e+000,,,,,,,,,,,,,,32,1,4.000000e+000,7.781982e-004,0.000000e+000,0,,0,
1524201341.825,,0.000000e+000,3.499911e+001,-4.410452e-006,0.000000e+000,3,7.867895e-001,0.000000e+000,,,,,,,,,,,,,,32,1,4.000000e+000,2.338409e-003,0.000000e+000,0,,0,
1524201380.728,,0.000000e+000,3.499989e+001,-4.543382e-006,0.000000e+000,3,8.021865e-001,0.000000e+000,,,,,,,,,,,,,,32,1,4.000000e+000,7.781982e-004,0.000000e+000,0,,0,
1524201418.294,,0.000000e+000,3.499833e+001,-4.425880e-006,0.000000e+000,3,7.915508e-001,0.000000e+000,,,,,,,,,,,,,,32,1,4.000000e+000,7.781982e-004,0.000000e+000,0,,0,
1524201456.959,,0.000000e+000,3.499911e+001,-4.467322e-006,0.000000e+000,3,7.857855e-001,0.000000e+000,,,,,,,,,,,,,,32,1,4.000000e+000,7.820129e-004,0.000000e+000,0,,0,
1524201495.232,,0.000000e+000,3.499950e+001,-4.421325e-006,0.000000e+000,3,7.860440e-001,0.000000e+000,,,,,,,,,,,,,,32,1,4.000000e+000,0.000000e+000,0.000000e+000,0,,0,
1524201532.900,,0.000000e+000,3.499950e+001,-4.371463e-006,0.000000e+000,3,8.107412e-001,0.000000e+000,,,,,,,,,,,,,,32,1,4.000000e+000,0.000000e+000,0.000000e+000,0,,0,
1524201570.361,,0.000000e+000,3.499950e+001,-4.392677e-006,0.000000e+000,3,7.856247e-001,0.000000e+000,,,,,,,,,,,,,,32,1,4.000000e+000,0.000000e+000,0.000000e+000,0,,0,
1524201608.314,,0.000000e+000,3.500028e+001,-4.376920e-006,0.000000e+000,3,7.970282e-001,0.000000e+000,,,,,,,,,,,,,,32,1,4.000000e+000,1.560211e-003,0.000000e+000,0,,0,
1524201646.427,,0.000000e+000,3.499833e+001,-4.424927e-006,0.000000e+000,3,7.867184e-001,0.000000e+000,,,,,,,,,,,,,,32,1,4.000000e+000,7.781982e-004,0.000000e+000,0,,0,
1524201684.577,,0.000000e+000,3.499911e+001,-4.212864e-006,0.000000e+000,3,7.874829e-001,0.000000e+000,,,,,,,,,,,,,,32,1,4.000000e+000,7.820129e-004,0.000000e+000,0,,0,
1524201722.678,,0.000000e+000,3.499989e+001,-4.363241e-006,0.000000e+000,3,7.721499e-001,0.000000e+000,,,,,,,,,,,,,,32,1,4.000000e+000,2.342224e-003,0.000000e+000,0,,0,
1524201760.774,,0.000000e+000,3.499872e+001,-4.405963e-006,0.000000e+000,3,7.906257e-001,0.000000e+000,,,,,,,,,,,,,,32,1,4.000000e+000,0.000000e+000,0.000000e+000,0,,0,
1524201799.034,,0.000000e+000,3.500106e+001,-4.343236e-006,0.000000e+000,3,7.961793e-001,0.000000e+000,,,,,,,,,,,,,,32,1,4.000000e+000,3.128052e-003,0.000000e+000,0,,0,
1524201837.127,,0.000000e+000,3.499950e+001,-4.267438e-006,0.000000e+000,3,7.933565e-001,0.000000e+000,,,,,,,,,,,,,,32,1,4.000000e+000,3.120422e-003,0.000000e+000,0,,0,
1524201875.130,,0.000000e+000,3.499989e+001,-4.227857e-006,0.000000e+000,3,7.735152e-001,0.000000e+000,,,,,,,,,,,,,,32,1,4.000000e+000,7.781982e-004,0.000000e+000,0,,0,
1524201913.273,,0.000000e+000,3.499872e+001,-4.291501e-006,0.000000e+000,3,7.757279e-001,0.000000e+000,,,,,,,,,,,,,,32,1,4.000000e+000,1.560211e-003,0.000000e+000,0,,0,
1524201951.384,,0.000000e+000,3.499911e+001,-4.299020e-006,0.000000e+000,3,7.904901e-001,0.000000e+000,,,,,,,,,,,,,,32,1,4.000000e+000,7.820129e-004,0.000000e+000,0,,0,
1524201989.524,,0.000000e+000,3.499911e+001,-4.262377e-006,0.000000e+000,3,7.840643e-001,0.000000e+000,,,,,,,,,,,,,,32,1,4.000000e+000,7.820129e-004,0.000000e+000,0,,0,
1524202027.595,,0.000000e+000,3.499989e+001,-4.202275e-006,0.000000e+000,3,7.802203e-001,0.000000e+000,,,,,,,,,,,,,,32,1,4.000000e+000,7.781982e-004,0.000000e+000,0,,0,
1524202065.726,,0.000000e+000,3.499989e+001,-4.211460e-006,0.000000e+000,3,7.761471e-001,0.000000e+000,,,,,,,,,,,,,,32,1,4.000000e+000,2.342224e-003,0.000000e+000,0,,0,
1524202103.856,,0.000000e+000,3.499950e+001,-4.169776e-006,0.000000e+000,3,7.722583e-001,0.000000e+000,,,,,,,,,,,,,,32,1,4.000000e+000,0.000000e+000,0.000000e+000,0,,0,
1524202141.947,,0.000000e+000,3.499911e+001,-4.237537e-006,0.000000e+000,3,7.767186e-001,0.000000e+000,,,,,,,,,,,,,,32,1,4.000000e+000,7.820129e-004,0.000000e+000,0,,0,
1524202179.807,,0.000000e+000,3.499989e+001,-4.219336e-006,0.000000e+000,3,7.692692e-001,0.000000e+000,,,,,,,,,,,,,,32,1,4.000000e+000,7.781982e-004,0.000000e+000,0,,0,
1524202217.843,,0.000000e+000,3.499950e+001,-4.161879e-006,0.000000e+000,3,7.726846e-001,0.000000e+000,,,,,,,,,,,,,,32,1,4.000000e+000,0.000000e+000,0.000000e+000,0,,0,
1524202255.586,,0.000000e+000,3.499950e+001,-4.232979e-006,0.000000e+000,3,7.901197e-001,0.000000e+000,,,,,,,,,,,,,,32,1,4.000000e+000,0.000000e+000,0.000000e+000,0,,0,
1524202292.996,,0.000000e+000,3.499911e+001,-4.186502e-006,0.000000e+000,3,8.054585e-001,0.000000e+000,,,,,,,,,,,,,,32,1,4.000000e+000,7.820129e-004,0.000000e+000,0,,0,
1524202331.064,,0.000000e+000,3.499989e+001,-4.167806e-006,0.000000e+000,3,7.768014e-001,0.000000e+000,,,,,,,,,,,,,,32,1,4.000000e+000,7.781982e-004,0.000000e+000,0,,0,
1524202368.803,,0.000000e+000,3.499911e+001,-4.045367e-006,0.000000e+000,3,7.701718e-001,0.000000e+000,,,,,,,,,,,,,,32,1,4.000000e+000,7.820129e-004,0.000000e+000,0,,0,
1524202406.866,,0.000000e+000,3.499950e+001,-4.174692e-006,0.000000e+000,3,7.685554e-001,0.000000e+000,,,,,,,,,,,,,,32,1,4.000000e+000,1.560211e-003,0.000000e+000,0,,0,
1524202445.034,,0.000000e+000,3.499989e+001,-4.082882e-006,0.000000e+000,3,7.790951e-001,0.000000e+000,,,,,,,,,,,,,,32,1,4.000000e+000,7.781982e-004,0.000000e+000,0,,0,
1524202482.889,,0.000000e+000,3.500028e+001,-4.078884e-006,0.000000e+000,3,7.705300e-001,0.000000e+000,,,,,,,,,,,,,,32,1,4.000000e+000,1.560211e-003,0.000000e+000,0,,0,
1524202521.042,,0.000000e+000,3.499989e+001,-4.060495e-006,0.000000e+000,3,7.707860e-001,0.000000e+000,,,,,,,,,,,,,,32,1,4.000000e+000,7.781982e-004,0.000000e+000,0,,0,
1524202558.898,,0.000000e+000,3.499793e+001,-4.040374e-006,0.000000e+000,3,7.791603e-001,0.000000e+000,,,,,,,,,,,,,,32,1,4.000000e+000,1.567841e-003,0.000000e+000,0,,0,
1524202596.393,,0.000000e+000,3.499950e+001,-4.070926e-006,0.000000e+000,3,7.694731e-001,0.000000e+000,,,,,,,,,,,,,,32,1,4.000000e+000,1.560211e-003,0.000000e+000,0,,0,
1524202634.034,,0.000000e+000,3.499911e+001,-3.965706e-006,0.000000e+000,3,7.726463e-001,0.000000e+000,,,,,,,,,,,,,,32,1,4.000000e+000,7.820129e-004,0.000000e+000,0,,0,
1524202671.364,,0.000000e+000,3.499950e+001,-4.015197e-006,0.000000e+000,3,7.756523e-001,0.000000e+000,,,,,,,,,,,,,,32,1,4.000000e+000,1.560211e-003,0.000000e+000,0,,0,
1524202709.462,,0.000000e+000,3.499989e+001,-3.959034e-006,0.000000e+000,3,7.744798e-001,0.000000e+000,,,,,,,,,,,,,,32,1,4.000000e+000,7.781982e-004,0.000000e+000,0,,0,
1524202747.601,,0.000000e+000,3.499793e+001,-3.989670e-006,0.000000e+000,3,7.707098e-001,0.000000e+000,,,,,,,,,,,,,,32,1,4.000000e+000,1.567841e-003,0.000000e+000,0,,0,
1524202785.266,,0.000000e+000,3.499911e+001,-3.953238e-006,0.000000e+000,3,7.708461e-001,0.000000e+000,,,,,,,,,,,,,,32,1,4.000000e+000,7.820129e-004,0.000000e+000,0,,0,
1524202822.642,,0.000000e+000,3.499559e+001,-3.994855e-006,0.000000e+000,3,7.777470e-001,0.000000e+000,,,,,,,,,,,,,,32,1,4.000000e+000,4.699707e-003,0.000000e+000,0,,0,
1524202860.775,,0.000000e+000,3.499872e+001,-3.907075e-006,0.000000e+000,3,7.648036e-001,0.000000e+000,,,,,,,,,,,,,,32,1,4.000000e+000,0.000000e+000,0.000000e+000,0,,0,
1524202898.113,,0.000000e+000,3.499833e+001,-3.942061e-006,0.000000e+000,3,7.674466e-001,0.000000e+000,,,,,,,,,,,,,,32,1,4.000000e+000,2.349854e-003,0.000000e+000,0,,0,
1524202935.601,,0.000000e+000,3.499989e+001,-3.971096e-006,0.000000e+000,3,7.728090e-001,0.000000e+000,,,,,,,,,,,,,,32,1,4.000000e+000,2.342224e-003,0.000000e+000,0,,0,
1524202973.244,,0.000000e+000,3.499833e+001,-3.927383e-006,0.000000e+000,3,7.687781e-001,0.000000e+000,,,,,,,,,,,,,,32,1,4.000000e+000,7.781982e-004,0.000000e+000,0,,0,
1524203011.259,,0.000000e+000,3.499833e+001,-3.933762e-006,0.000000e+000,3,7.720253e-001,0.000000e+000,,,,,,,,,,,,,,32,1,4.000000e+000,7.781982e-004,0.000000e+000,0,,0,
1524203049.030,,0.000000e+000,3.499950e+001,-3.904639e-006,0.000000e+000,3,7.636180e-001,0.000000e+000,,,,,,,,,,,,,,32,1,4.000000e+000,0.000000e+000,0.000000e+000,0,,0,
1524203087.031,,0.000000e+000,3.499989e+001,-3.863649e-006,0.000000e+000,3,7.589430e-001,0.000000e+000,,,,,,,,,,,,,,32,1,4.000000e+000,7.781982e-004,0.000000e+000,0,,0,
1524203124.161,,0.000000e+000,3.499911e+001,-3.820955e-006,0.000000e+000,3,7.537991e-001,0.000000e+000,,,,,,,,,,,,,,32,1,4.000000e+000,7.820129e-004,0.000000e+000,0,,0,
1524203161.672,,0.000000e+000,3.499872e+001,-3.835631e-006,0.000000e+000,3,7.552018e-001,0.000000e+000,,,,,,,,,,,,,,32,1,4.000000e+000,1.560211e-003,0.000000e+000,0,,0,
1524203199.497,,0.000000e+000,3.499872e+001,-3.866106e-006,0.000000e+000,3,7.645785e-001,0.000000e+000,,,,,,,,,,,,,,32,1,4.000000e+000,0.000000e+000,0.000000e+000,0,,0,
1524203236.835,,0.000000e+000,3.499833e+001,-3.804409e-006,0.000000e+000,3,7.588278e-001,0.000000e+000,,,,,,,,,,,,,,32,1,4.000000e+000,2.349854e-003,0.000000e+000,0,,0,
1524203274.918,,0.000000e+000,3.499833e+001,-3.851856e-006,0.000000e+000,3,7.633734e-001,0.000000e+000,,,,,,,,,,,,,,32,1,4.000000e+000,7.781982e-004,0.000000e+000,0,,0,
1524203312.761,,0.000000e+000,3.499950e+001,-3.785168e-006,0.000000e+000,3,7.654532e-001,0.000000e+000,,,,,,,,,,,,,,32,1,4.000000e+000,0.000000e+000,0.000000e+000,0,,0,
1524203350.639,,0.000000e+000,3.499989e+001,-3.798984e-006,0.000000e+000,3,7.644349e-001,0.000000e+000,,,,,,,,,,,,,,32,1,4.000000e+000,7.781982e-004,0.000000e+000,0,,0,
1524203388.755,,0.000000e+000,3.499950e+001,-3.756634e-006,0.000000e+000,3,7.587512e-001,0.000000e+000,,,,,,,,,,,,,,32,1,4.000000e+000,0.000000e+000,0.000000e+000,0,,0,
1524203426.633,,0.000000e+000,3.499950e+001,-3.753239e-006,0.000000e+000,3,7.510504e-001,0.000000e+000,,,,,,,,,,,,,,32,1,4.000000e+000,0.000000e+000,0.000000e+000,0,,0,
1524203465.749,,0.000000e+000,3.499872e+001,-3.800829e-006,0.000000e+000,3,7.689803e-001,0.000000e+000,,,,,,,,,,,,,,32,1,4.000000e+000,0.000000e+000,0.000000e+000,0,,0,
1524203503.892,,0.000000e+000,3.499911e+001,-3.770828e-006,0.000000e+000,3,7.678298e-001,0.000000e+000,,,,,,,,,,,,,,32,1,4.000000e+000,7.820129e-004,0.000000e+000,0,,0,
1524203541.495,,0.000000e+000,3.499950e+001,-3.787727e-006,0.000000e+000,3,7.567017e-001,0.000000e+000,,,,,,,,,,,,,,32,1,4.000000e+000,0.000000e+000,0.000000e+000,0,,0,
1524203579.598,,0.000000e+000,3.499989e+001,-3.758043e-006,0.000000e+000,3,7.581123e-001,0.000000e+000,,,,,,,,,,,,,,32,1,4.000000e+000,2.342224e-003,0.000000e+000,0,,0,
1524203618.196,,0.000000e+000,3.499989e+001,-3.705050e-006,0.000000e+000,3,7.516654e-001,0.000000e+000,,,,,,,,,,,,,,32,1,4.000000e+000,7.781982e-004,0.000000e+000,0,,0,
1524203655.859,,0.000000e+000,3.499911e+001,-3.737306e-006,0.000000e+000,3,7.575127e-001,0.000000e+000,,,,,,,,,,,,,,32,1,4.000000e+000,7.820129e-004,0.000000e+000,0,,0,
1524203693.847,,0.000000e+000,3.499911e+001,-3.725741e-006,0.000000e+000,3,7.557868e-001,0.000000e+000,,,,,,,,,,,,,,32,1,4.000000e+000,7.820129e-004,0.000000e+000,0,,0,
1524203732.013,,0.000000e+000,3.499911e+001,-3.696264e-006,0.000000e+000,3,7.574491e-001,0.000000e+000,,,,,,,,,,,,,,32,1,4.000000e+000,7.820129e-004,0.000000e+000,0,,0,
1524203770.206,,0.000000e+000,3.499872e+001,-3.665809e-006,0.000000e+000,3,7.540517e-001,0.000000e+000,,,,,,,,,,,,,,32,1,4.000000e+000,1.560211e-003,0.000000e+000,0,,0,
1524203808.716,,0.000000e+000,3.499911e+001,-3.709985e-006,0.000000e+000,3,7.550322e-001,0.000000e+000,,,,,,,,,,,,,,32,1,4.000000e+000,7.820129e-004,0.000000e+000,0,,0,
1524203846.427,,0.000000e+000,3.499833e+001,-3.550908e-006,0.000000e+000,3,7.365416e-001,0.000000e+000,,,,,,,,,,,,,,32,1,4.000000e+000,2.349854e-003,0.000000e+000,0,,0,
1524203885.027,,0.000000e+000,3.499989e+001,-3.566651e-006,0.000000e+000,3,7.451757e-001,0.000000e+000,,,,,,,,,,,,,,32,1,4.000000e+000,2.342224e-003,0.000000e+000,0,,0,
1524203922.925,,0.000000e+000,3.499989e+001,-3.608595e-006,0.000000e+000,3,7.533314e-001,0.000000e+000,,,,,,,,,,,,,,32,1,4.000000e+000,7.781982e-004,0.000000e+000,0,,0,
1524203961.041,,0.000000e+000,3.500028e+001,-3.632349e-006,0.000000e+000,3,7.433110e-001,0.000000e+000,,,,,,,,,,,,,,32,1,4.000000e+000,0.000000e+000,0.000000e+000,0,,0,
1524203999.261,,0.000000e+000,3.499872e+001,-3.627476e-006,0.000000e+000,3,7.483432e-001,0.000000e+000,,,,,,,,,,,,,,32,1,4.000000e+000,1.560211e-003,0.000000e+000,0,,0,
1524204036.649,,0.000000e+000,3.499872e+001,-3.574907e-006,0.000000e+000,3,7.433408e-001,0.000000e+000,,,,,,,,,,,,,,32,1,4.000000e+000,0.000000e+000,0.000000e+000,0,,0,