File: Input/MFn1_TRMac_38K_0.32Kmin_VRMde_35K.dc.dat
[Header]
TITLE,MPMS DC Measurement
BYAPP,MPMS Measurement,2.1,Summary
FILEOPENTIME, 1524603007.874000 4/24/2018, 2:50:07 PM

INFO, APPNAME, MPMS MultiVu Application, Revision 1.61,  Build 082

INFO, NAME, MFn1
INFO, WEIGHT, 1.000
INFO, AREA, 1.000
INFO, LENGTH, 1.000
INFO, SHAPE, 0
INFO, COMMENT,
INFO, SEQUENCE FILE: TRMac_38K_0.32Kmin_VRMde_35K.seq


INFO, BACKGROUND DATA FILE:, None


STARTUPAXIS,X,4,LINEAR,AUTO,0.000000,0.000000
STARTUPAXIS,Y1,5,LINEAR,AUTO,0.000000,0.000000


STARTUPGROUP,Longitudinal
FIELDGROUP,Longitudinal,1,2,3,4,5,6,7,8,9,15,16,17,18,27,28
FIELDGROUP,Transverse,1,2,3,4,10,11,12,13,14,19,20,21,22,27,28

PLOT_APPEARANCE,ALL,HORZ_GRID_ON,VERT_GRID_ON,MARKERS_AND_LINES

[Data]
Time,Comment,Field (Oe),Temperature (K),Long Moment (emu),Long Scan Std Dev,Long Algorithm,Long Reg Fit,Long Percent Error (%),Trans Moment (emu),Trans Scan Std Dev,Trans Algorithm,Trans Reg Fit,Trans Percent Error (%),Long Moment [w/o ABS] (emu),Long Scan Std Dev [w/o ABS],Long Reg Fit [w/o ABS],Long Percent Error [w/o ABS] (%),Trans Moment [w/o ABS] (emu),Trans Scan Std Dev [w/o ABS],Trans Reg Fit [w/o ABS],Trans Percent Error [w/o ABS] (%),Points per Scan,Scans per Measurement,Scan Length (cm),Delta Temp (K),Rot Position (deg),Error,EC Comp. Running,Using ABS,
1524603007.872,,0.000000e+000,3.500028e+001,-1.159274e-005,0.000000e+000,3,9.398925e-001,0.000000e+000,,,,,,,,,,,,,,32,1,4.000000e+000,9.387970e-003,0.000000e+000,0,,0,
1524603032.890,,0.000000e+000,3.499754e+001,-9.675058e-006,0.000000e+000,3,9.287683e-001,0.000000e+000,,,,,,,,,,,,,,32,1,4.000000e+000,7.896423e-004,0.000000e+000,0,,0,
1524603057.968,,0.000000e+000,3.499833e+001,-8.278328e-006,0.000000e+000,3,9.173789e-001,0.000000e+000,,,,,,,,,,,,,,32,1,4.000000e+000,7.781982e-004,0.000000e+000,0,,0,
1524603083.348,,0.000000e+000,3.499715e+001,-7.130132e-006,0.000000e+000,3,8.985875e-001,0.000000e+000,,,,,,,,,,,,,,32,1,4.000000e+000,1.571655e-003,0.000000e+000,0,,0,
1524603109.781,,0.000000e+000,3.499911e+001,-6.252830e-006,0.000000e+000,3,8.882467e-001,0.000000e+000,,,,,,,,,,,,,,32,1,4.000000e+000,7.820129e-004,0.000000e+000,0,,0,
1524603134.554,,0.000000e+000,3.499715e+001,-5.532324e-006,0.000000e+000,3,8.691726e-001,0.000000e+000,,,,,,,,,,,,,,32,1,4.000000e+000,1.571655e-003,0.000000e+000,0,,0,
1524603159.742,,0.000000e+000,3.499872e+001,-4.956578e-006,0.000000e+000,3,8.654723e-001,0.000000e+000,,,,,,,,,,,,,,32,1,4.000000e+000,0.000000e+000,0.000000e+000,0,,0,
1524603185.102,,0.000000e+000,3.499950e+001,-4.415713e-006,0.000000e+000,3,8.353418e-001,0.000000e+000,,,,,,,,,,,,,,32,1,4.000000e+000,1.560211e-003,0.000000e+000,0,,0,
1524603210.245,,0.000000e+000,3.500145e+001,-3.979239e-006,0.000000e+000,3,8.136978e-001,0.000000e+000,,,,,,,,,,,,,,32,1,4.000000e+000,7.781982e-004,0.000000e+000,0,,0,
1524603236.380,,0.000000e+000,3.499833e+001,-3.581019e-006,0.000000e+000,3,8.020805e-001,0.000000e+000,,,,,,,,,,,,,,32,1,4.000000e+000,7.781982e-004,0.000000e+000,0,,0,
1524603261.586,,0.000000e+000,3.499793e+001,-3.136493e-006,0.000000e+000,3,7.637811e-001,0.000000e+000,,,,,,,,,,,,,,32,1,4.000000e+000,1.567841e-003,0.000000e+000,0,,0,
1524603287.136,,0.000000e+000,3.499833e+001,-2.820736e-006,0.000000e+000,3,7.444173e-001,0.000000e+000,,,,,,,,,,,,,,32,1,4.000000e+000,7.781982e-004,0.000000e+000,0,,0,
1524603312.519,,0.000000e+000,3.499754e+001,-2.579087e-006,0.000000e+000,3,7.311996e-001,0.000000e+000,,,,,,,,,,,,,,32,1,4.000000e+000,7.896423e-004,0.000000e+000,0,,0,
1524603337.679,,0.000000e+000,3.499677e+001,-2.209788e-006,0.000000e+000,3,6.531770e-001,0.000000e+000,,,,,,,,,,,,,,32,1,4.000000e+000,2.349854e-003,0.000000e+000,0,,0,
1524603363.317,,0.000000e+000,3.499754e+001,-1.992826e-006,0.000000e+000,3,6.339600e-001,0.000000e+000,,,,,,,,,,,,,,32,1,4.000000e+000,7.896423e-004,0.000000e+000,0,,0,
1524603388.490,,0.000000e+000,3.499794e+001,-1.793405e-006,0.000000e+000,3,5.889576e-001,0.000000e+000,,,,,,,,,,,,,,32,1,4.000000e+000,0.000000e+000,0.000000e+000,0,,0,
1524603413.898,,0.000000e+000,3.499677e+001,-1.496872e-006,0.000000e+000,3,4.926365e-001,0.000000e+000,,,,,,,,,,,,,,32,1,4.000000e+000,3.910065e-003,0.000000e+000,0,,0,
1524603439.536,,0.000000e+000,3.499793e+001,-1.361496e-006,0.000000e+000,3,4.618320e-001,0.000000e+000,,,,,,,,,,,,,,32,1,4.000000e+000,6.252289e-003,0.000000e+000,0,,0,
1524603464.676,,0.000000e+000,3.499872e+001,-1.266557e-006,0.000000e+000,3,4.184393e-001,0.000000e+000,,,,,,,,,,,,,,32,1,4.000000e+000,0.000000e+000,0.000000e+000,0,,0,
1524603490.329,,0.000000e+000,3.499637e+001,-1.021177e-006,0.000000e+000,3,2.479992e-001,0.000000e+000,,,,,,,,,,,,,,32,1,4.000000e+000,0.000000e+000,0.000000e+000,0,,0,
1524603515.769,,0.000000e+000,3.499911e+001,-8.806111e-007,0.000000e+000,3,9.129965e-002,0.000000e+000,,,,,,,,,,,,,,32,1,4.000000e+000,2.338409e-003,0.000000e+000,0,,0,
1524603541.137,,0.000000e+000,3.499950e+001,-7.058711e-007,0.000000e+000,3,0.000000e+000,0.000000e+000,,,,,,,,,,,,,,32,1,4.000000e+000,1.560211e-003,0.000000e+000,0,,0,
1524603568.331,,0.000000e+000,3.499950e+001,-2.501370e-007,0.000000e+000,2,0.000000e+000,0.000000e+000,,,,,,,,,,,,,,32,1,4.000000e+000,3.120422e-003,0.000000e+000,0,,0,
1524603593.369,,0.000000e+000,3.500067e+001,1.009076e-006,0.000000e+000,3,2.893546e-001,0.000000e+000,,,,,,,,,,,,,,32,1,4.000000e+000,7.820129e-004,0.000000e+000,0,,0,
1524603621.948,,0.000000e+000,3.500028e+001,9.249436e-008,0.000000e+000,2,0.000000e+000,0.000000e+000,,,,,,,,,,,,,,32,1,4.000000e+000,0.000000e+000,0.000000e+000,0,,0,
1524603649.219,,0.000000e+000,3.499754e+001,7.037016e-008,0.000000e+000,2,0.000000e+000,0.000000e+000,,,,,,,,,,,,,,32,1,4.000000e+000,7.896423e-004,0.000000e+000,0,,0,
1524603675.082,,0.000000e+000,3.499911e+001,1.136710e-006,0.000000e+000,3,4.051499e-001,0.000000e+000,,,,,,,,,,,,,,32,1,4.000000e+000,2.338409e-003,0.000000e+000,0,,0,
1524603700.255,,0.000000e+000,3.499950e+001,1.028112e-006,0.000000e+000,3,3.470961e-001,0.000000e+000,,,,,,,,,,,,,,32,1,4.000000e+000,1.560211e-003,0.000000e+000,0,,0,
1524603725.446,,0.000000e+000,3.499677e+001,1.085524e-006,0.000000e+000,3,4.144131e-001,0.000000e+000,,,,,,,,,,,,,,32,1,4.000000e+000,5.470276e-003,0.000000e+000,0,,0,
1524603750.758,,0.000000e+000,3.499872e+001,1.175741e-006,0.000000e+000,3,4.714925e-001,0.000000e+000,,,,,,,,,,,,,,32,1,4.000000e+000,0.000000e+000,0.000000e+000,0,,0,
1524603776.161,,0.000000e+000,3.499793e+001,1.188664e-006,0.000000e+000,3,4.399124e-001,0.000000e+000,,,,,,,,,,,,,,32,1,4.000000e+000,1.567841e-003,0.000000e+000,0,,0,
1524603801.172,,0.000000e+000,3.499950e+001,1.178606e-006,0.000000e+000,3,4.415648e-001,0.000000e+000,,,,,,,,,,,,,,32,1,4.000000e+000,1.560211e-003,0.000000e+000,0,,0,
1524603826.447,,0.000000e+000,3.499871e+001,1.306354e-006,0.000000e+000,3,4.865265e-001,0.000000e+000,,,,,,,,,,,,,,32,1,4.000000e+000,4.692078e-003,0.000000e+000,0,,0,
1524603851.607,,0.000000e+000,3.499520e+001,1.235045e-006,0.000000e+000,3,4.562584e-001,0.000000e+000,,,,,,,,,,,,,,32,1,4.000000e+000,7.820129e-004,0.000000e+000,0,,0,
1524603877.285,,0.000000e+000,3.499793e+001,1.481032e-006,0.000000e+000,3,5.408034e-001,0.000000e+000,,,,,,,,,,,,,,32,1,4.000000e+000,3.131866e-003,0.000000e+000,0,,0,
1524603902.563,,0.000000e+000,3.499676e+001,1.516535e-006,0.000000e+000,3,5.508460e-001,0.000000e+000,,,,,,,,,,,,,,32,1,4.000000e+000,7.820129e-004,0.000000e+000,0,,0,
1524603927.461,,0.000000e+000,3.499754e+001,1.526508e-006,0.000000e+000,3,5.723810e-001,0.000000e+000,,,,,,,,,,,,,,32,1,4.000000e+000,7.896423e-004,0.000000e+000,0,,0,
1524603952.656,,0.000000e+000,3.499911e+001,1.765832e-006,0.000000e+000,3,5.876027e-001,0.000000e+000,,,,,,,,,,,,,,32,1,4.000000e+000,7.820129e-004,0.000000e+000,0,,0,
1524603978.077,,0.000000e+000,3.499794e+001,1.830856e-006,0.000000e+000,3,6.274876e-001,0.000000e+000,,,,,,,,,,,,,,32,1,4.000000e+000,0.000000e+000,0.000000e+000,0,,0,
1524604003.504,,0.000000e+000,3.499833e+001,1.840810e-006,0.000000e+000,3,6.164912e-001,0.000000e+000,,,,,,,,,,,,,,32,1,4.000000e+000,7.781982e-004,0.000000e+000,0,,0,
1524604028.885,,0.000000e+000,3.499911e+001,1.976466e-006,0.000000e+000,3,6.530796e-001,0.000000e+000,,,,,,,,,,,,,,32,1,4.000000e+000,7.820129e-004,0.000000e+000,0,,0,
1524604055.113,,0.000000e+000,3.499950e+001,1.985052e-006,0.000000e+000,3,6.641406e-001,0.000000e+000,,,,,,,,,,,,,,32,1,4.000000e+000,3.120422e-003,0.000000e+000,0,,0,
1524604079.951,,0.000000e+000,3.499715e+001,1.938105e-006,0.000000e+000,3,6.576579e-001,0.000000e+000,,,,,,,,,,,,,,32,1,4.000000e+000,1.571655e-003,0.000000e+000,0,,0,
1524604105.086,,0.000000e+000,3.499754e+001,2.092388e-006,0.000000e+000,3,6.700771e-001,0.000000e+000,,,,,,,,,,,,,,32,1,4.000000e+000,5.470276e-003,0.000000e+000,0,,0,
1524604130.494,,0.000000e+000,3.499911e+001,2.124674e-006,0.000000e+000,3,6.747605e-001,0.000000e+000,,,,,,,,,,,,,,32,1,4.000000e+000,2.338409e-003,0.000000e+000,0,,0,
1524604155.604,,0.000000e+000,3.499872e+001,2.180475e-006,0.000000e+000,3,6.816918e-001,0.000000e+000,,,,,,,,,,,,,,32,1,4.000000e+000,0.000000e+000,0.000000e+000,0,,0,
1524604180.780,,0.000000e+000,3.499715e+001,2.282587e-006,0.000000e+000,3,7.031442e-001,0.000000e+000,,,,,,,,,,,,,,32,1,4.000000e+000,3.128052e-003,0.000000e+000,0,,0,
1524604205.793,,0.000000e+000,3.499676e+001,2.305886e-006,0.000000e+000,3,6.859711e-001,0.000000e+000,,,,,,,,,,,,,,32,1,4.000000e+000,7.820129e-004,0.000000e+000,0,,0,
1524604231.018,,0.000000e+000,3.499833e+001,2.382293e-006,0.000000e+000,3,7.024692e-001,0.000000e+000,,,,,,,,,,,,,,32,1,4.000000e+000,7.781982e-004,0.000000e+000,0,,0,
1524604256.453,,0.000000e+000,3.499911e+001,2.436446e-006,0.000000e+000,3,7.122324e-001,0.000000e+000,,,,,,,,,,,,,,32,1,4.000000e+000,7.820129e-004,0.000000e+000,0,,0,
1524604281.479,,0.000000e+000,3.499872e+001,2.512387e-006,0.000000e+000,3,7.341244e-001,0.000000e+000,,,,,,,,,,,,,,32,1,4.000000e+000,1.560211e-003,0.000000e+000,0,,0,
1524604307.382,,0.000000e+000,3.499872e+001,2.515614e-006,0.000000e+000,3,7.188060e-001,0.000000e+000,,,,,,,,,,,,,,32,1,4.000000e+000,0.000000e+000,0.000000e+000,0,,0,
1524604332.652,,0.000000e+000,3.499833e+001,2.505046e-006,0.000000e+000,3,7.315187e-001,0.000000e+000,,,,,,,,,,,,,,32,1,4.000000e+000,2.349854e-003,0.000000e+000,0,,0,
1524604357.877,,0.000000e+000,3.499677e+001,2.585439e-006,0.000000e+000,3,7.135872e-001,0.000000e+000,,,,,,,,,,,,,,32,1,4.000000e+000,3.910065e-003,0.000000e+000,0,,0,
1524604383.118,,0.000000e+000,3.499911e+001,2.831531e-006,0.000000e+000,3,7.503347e-001,0.000000e+000,,,,,,,,,,,,,,32,1,4.000000e+000,7.820129e-004,0.000000e+000,0,,0,
1524604408.328,,0.000000e+000,3.499872e+001,2.757310e-006,0.000000e+000,3,7.515683e-001,0.000000e+000,,,,,,,,,,,,,,32,1,4.000000e+000,1.560211e-003,0.000000e+000,0,,0,
1524604432.851,,0.000000e+000,3.499833e+001,2.668211e-006,0.000000e+000,3,7.252730e-001,0.000000e+000,,,,,,,,,,,,,,32,1,4.000000e+000,7.781982e-004,0.000000e+000,0,,0,
1524604458.119,,0.000000e+000,3.499911e+001,2.796169e-006,0.000000e+000,3,7.504117e-001,0.000000e+000,,,,,,,,,,,,,,32,1,4.000000e+000,7.820129e-004,0.000000e+000,0,,0,
1524604483.512,,0.000000e+000,3.499754e+001,2.873696e-006,0.000000e+000,3,7.492792e-001,0.000000e+000,,,,,,,,,,,,,,32,1,4.000000e+000,7.896423e-004,0.000000e+000,0,,0,
1524604508.524,,0.000000e+000,3.499637e+001,2.945713e-006,0.000000e+000,3,7.645765e-001,0.000000e+000,,,,,,,,,,,,,,32,1,4.000000e+000,1.560211e-003,0.000000e+000,0,,0,
1524604533.947,,0.000000e+000,3.499637e+001,2.964827e-006,0.000000e+000,3,7.683405e-001,0.000000e+000,,,,,,,,,,,,,,32,1,4.000000e+000,1.560211e-003,0.000000e+000,0,,0,
1524604559.893,,0.000000e+000,3.499871e+001,2.993932e-006,0.000000e+000,3,7.719935e-001,0.000000e+000,,,,,,,,,,,,,,32,1,4.000000e+000,3.128052e-003,0.000000e+000,0,,0,
1524604585.116,,0.000000e+000,3.499598e+001,3.087427e-006,0.000000e+000,3,7.807491e-001,0.000000e+000,,,,,,,,,,,,,,32,1,4.000000e+000,7.041931e-003,0.000000e+000,0,,0,
1524604610.518,,0.000000e+000,3.499989e+001,3.121054e-006,0.000000e+000,3,7.767752e-001,0.000000e+000,,,,,,,,,,,,,,32,1,4.000000e+000,2.342224e-003,0.000000e+000,0,,0,
1524604635.926,,0.000000e+000,3.499793e+001,3.126649e-006,0.000000e+000,3,7.774159e-001,0.000000e+000,,,,,,,,,,,,,,32,1,4.000000e+000,3.131866e-003,0.000000e+000,0,,0,
1524604661.497,,0.000000e+000,3.499637e+001,3.221633e-006,0.000000e+000,3,7.830333e-001,0.000000e+000,,,,,,,,,,,,,,32,1,4.000000e+000,6.259918e-003,0.000000e+000,0,,0,
1524604686.885,,0.000000e+000,3.499754e+001,3.191125e-006,0.000000e+000,3,7.837327e-001,0.000000e+000,,,,,,,,,,,,,,32,1,4.000000e+000,7.896423e-004,0.000000e+000,0,,0,
1524604712.282,,0.000000e+000,3.499715e+001,3.176468e-006,0.000000e+000,3,7.789014e-001,0.000000e+000,,,,,,,,,,,,,,32,1,4.000000e+000,3.128052e-003,0.000000e+000,0,,0,
1524604737.670,,0.000000e+000,3.499833e+001,3.257567e-006,0.000000e+000,3,7.856115e-001,0.000000e+000,,,,,,,,,,,,,,32,1,4.000000e+000,7.781982e-004,0.000000e+000,0,,0,
1524604763.206,,0.000000e+000,3.499872e+001,3.320747e-006,0.000000e+000,3,7.914532e-001,0.000000e+000,,,,,,,,,,,,,,32,1,4.000000e+000,1.560211e-003,0.000000e+000,0,,0,
1524604788.501,,0.000000e+000,3.499872e+001,3.366730e-006,0.000000e+000,3,8.007348e-001,0.000000e+000,,,,,,,,,,,,,,32,1,4.000000e+000,1.560211e-003,0.000000e+000,0,,0,
1524604813.914,,0.000000e+000,3.499872e+001,3.399114e-006,0.000000e+000,3,7.899426e-001,0.000000e+000,,,,,,,,,,,,,,32,1,4.000000e+000,0.000000e+000,0.000000e+000,0,,0,
1524604839.314,,0.000000e+000,3.499872e+001,3.410736e-006,0.000000e+000,3,7.933025e-001,0.000000e+000,,,,,,,,,,,,,,32,1,4.000000e+000,0.000000e+000,0.000000e+000,0,,0,
1524604864.465,,0.000000e+000,3.499793e+001,3.469531e-006,0.000000e+000,3,7.956334e-001,0.000000e+000,,,,,,,,,,,,,,32,1,4.000000e+000,4.688263e-003,0.000000e+000,0,,0,
1524604889.628,,0.000000e+000,3.499911e+001,3.509166e-006,0.000000e+000,3,8.005821e-001,0.000000e+000,,,,,,,,,,,,,,32,1,4.000000e+000,7.820129e-004,0.000000e+000,0,,0,
1524604915.048,,0.000000e+000,3.499754e+001,3.584513e-006,0.000000e+000,3,7.982264e-001,0.000000e+000,,,,,,,,,,,,,,32,1,4.000000e+000,7.896423e-004,0.000000e+000,0,,0,
1524604940.308,,0.000000e+000,3.499794e+001,3.536312e-006,0.000000e+000,3,8.110239e-001,0.000000e+000,,,,,,,,,,,,,,32,1,4.000000e+000,0.000000e+000,0.000000e+000,0,,0,
1524604965.826,,0.000000e+000,3.499911e+001,3.563598e-006,0.000000e+000,3,8.049965e-001,0.000000e+000,,,,,,,,,,,,,,32,1,4.000000e+000,7.820129e-004,0.000000e+000,0,,0,
1524604991.117,,0.000000e+000,3.499911e+001,3.651286e-006,0.000000e+000,3,7.982603e-001,0.000000e+000,,,,,,,,,,,,,,32,1,4.000000e+000,7.820129e-004,0.000000e+000,0,,0,
1524605016.312,,0.000000e+000,3.499793e+001,3.634352e-006,0.000000e+000,3,8.133857e-001,0.000000e+000,,,,,,,,,,,,,,32,1,4.000000e+000,1.567841e-003,0.000000e+000,0,,0,
1524605041.717,,0.000000e+000,3.499794e+001,3.668286e-006,0.000000e+000,3,8.222609e-001,0.000000e+000,,,,,,,,,,,,,,32,1,4.000000e+000,0.000000e+000,0.000000e+000,0,,0,
1524605066.565,,0.000000e+000,3.499637e+001,3.686806e-006,0.000000e+000,3,8.123336e-001,0.000000e+000,,,,,,,,,,,,,,32,1,4.000000e+000,1.560211e-003,0.000000e+000,0,,0,
1524605092.026,,0.000000e+000,3.499754e+001,3.722460e-006,0.000000e+000,3,8.160381e-001,0.000000e+000,,,,,,,,,,,,,,32,1,4.000000e+000,7.896423e-004,0.000000e+000,0,,0,
1524605117.383,,0.000000e+000,3.499793e+001,3.754944e-006,0.000000e+000,3,8.148195e-001,0.000000e+000,,,,,,,,,,,,,,32,1,4.000000e+000,3.131866e-003,0.000000e+000,0,,0,
1524605142.846,,0.000000e+000,3.499911e+001,3.741736e-006,0.000000e+000,3,8.216399e-001,0.000000e+000,,,,,,,,,,,,,,32,1,4.000000e+000,2.338409e-003,0.000000e+000,0,,0,
1524605168.267,,0.000000e+000,3.499950e+001,3.793244e-006,0.000000e+000,3,8.215249e-001,0.000000e+000,,,,,,,,,,,,,,32,1,4.000000e+000,3.120422e-003,0.000000e+000,0,,0,
1524605193.679,,0.000000e+000,3.499950e+001,3.865265e-006,0.000000e+000,3,8.193747e-001,0.000000e+000,,,,,,,,,,,,,,32,1,4.000000e+000,1.560211e-003,0.000000e+000,0,,0,
1524605218.992,,0.000000e+000,3.499910e+001,3.883833e-006,0.000000e+000,3,8.182402e-001,0.000000e+000,,,,,,,,,,,,,,32,1,4.000000e+000,5.470276e-003,0.000000e+000,0,,0,
1524605244.223,,0.000000e+000,3.499715e+001,3.880803e-006,0.000000e+000,3,8.238485e-001,0.000000e+000,,,,,,,,,,,,,,32,1,4.000000e+000,1.571655e-003,0.000000e+000,0,,0,
1524605269.821,,0.000000e+000,3.499950e+001,3.906999e-006,0.000000e+000,3,8.235732e-001,0.000000e+000,,,,,,,,,,,,,,32,1,4.000000e+000,1.560211e-003,0.000000e+000,0,,0,
1524605295.321,,0.000000e+000,3.499754e+001,3.995992e-006,0.000000e+000,3,8.270732e-001,0.000000e+000,,,,,,,,,,,,,,32,1,4.000000e+000,7.896423e-004,0.000000e+000,0,,0,
1524605320.734,,0.000000e+000,3.499715e+001,3.992403e-006,0.000000e+000,3,8.160095e-001,0.000000e+000,,,,,,,,,,,,,,32,1,4.000000e+000,1.571655e-003,0.000000e+000,0,,0,
1524605346.342,,0.000000e+000,3.499754e+001,3.942530e-006,0.000000e+000,3,8.236402e-001,0.000000e+000,,,,,,,,,,,,,,32,1,4.000000e+000,7.896423e-004,0.000000e+000,0,,0,
1524605372.447,,0.000000e+000,3.500067e+001,4.040527e-006,0.000000e+000,3,8.285679e-001,0.000000e+000,,,,,,,,,,,,,,32,1,4.000000e+000,2.338409e-003,0.000000e+000,0,,0,
1524605397.882,,0.000000e+000,3.499715e+001,4.064002e-006,0.000000e+000,3,8.324300e-001,0.000000e+000,,,,,,,,,,,,,,32,1,4.000000e+000,1.571655e-003,0.000000e+000,0,,0,
1524605423.540,,0.000000e+000,3.499833e+001,4.088473e-006,0.000000e+000,3,8.278721e-001,0.000000e+000,,,,,,,,,,,,,,32,1,4.000000e+000,7.781982e-004,0.000000e+000,0,,0,
1524605448.571,,0.000000e+000,3.499794e+001,4.167448e-006,0.000000e+000,3,8.361083e-001,0.000000e+000,,,,,,,,,,,,,,32,1,4.000000e+000,0.000000e+000,0.000000e+000,0,,0,
1524605473.971,,0.000000e+000,3.499754e+001,4.109653e-006,0.000000e+000,3,8.319268e-001,0.000000e+000,,,,,,,,,,,,,,32,1,4.000000e+000,2.349854e-003,0.000000e+000,0,,0,
1524605499.817,,0.000000e+000,3.499754e+001,4.146746e-006,0.000000e+000,3,8.337983e-001,0.000000e+000,,,,,,,,,,,,,,32,1,4.000000e+000,7.896423e-004,0.000000e+000,0,,0,
1524605525.164,,0.000000e+000,3.499793e+001,4.138412e-006,0.000000e+000,3,8.341412e-001,0.000000e+000,,,,,,,,,,,,,,32,1,4.000000e+000,3.131866e-003,0.000000e+000,0,,0,
1524605550.032,,0.000000e+000,3.499833e+001,4.212960e-006,0.000000e+000,3,8.344173e-001,0.000000e+000,,,,,,,,,,,,,,32,1,4.000000e+000,2.349854e-003,0.000000e+000,0,,0,
1524605575.475,,0.000000e+000,3.499872e+001,4.216096e-006,0.000000e+000,3,8.403350e-001,0.000000e+000,,,,,,,,,,,,,,32,1,4.000000e+000,0.000000e+000,0.000000e+000,0,,0,
1524605600.151,,0.000000e+000,3.499911e+001,4.204909e-006,0.000000e+000,3,8.391979e-001,0.000000e+000,,,,,,,,,,,,,,32,1,4.000000e+000,7.820129e-004,0.000000e+000,0,,0,
1524605625.551,,0.000000e+000,3.499871e+001,4.245183e-006,0.000000e+000,3,8.367252e-001,0.000000e+000,,,,,,,,,,,,,,32,1,4.000000e+000,3.128052e-003,0.000000e+000,0,,0,
1524605650.966,,0.000000e+000,3.499833e+001,4.264611e-006,0.000000e+000,3,8.417056e-001,0.000000e+000,,,,,,,,,,,,,,32,1,4.000000e+000,7.781982e-004,0.000000e+000,0,,0,
1524605676.364,,0.000000e+000,3.499872e+001,4.280598e-006,0.000000e+000,3,8.409443e-001,0.000000e+000,,,,,,,,,,,,,,32,1,4.000000e+000,1.560211e-003,0.000000e+000,0,,0,
1524605701.777,,0.000000e+000,3.499911e+001,4.287231e-006,0.000000e+000,3,8.367517e-001,0.000000e+000,,,,,,,,,,,,,,32,1,4.000000e+000,7.820129e-004,0.000000e+000,0,,0,
1524605727.162,,0.000000e+000,3.499872e+001,4.288322e-006,0.000000e+000,3,8.390458e-001,0.000000e+000,,,,,,,,,,,,,,32,1,4.000000e+000,0.000000e+000,0.000000e+000,0,,0,
1524605753.018,,0.000000e+000,3.499794e+001,4.328213e-006,0.000000e+000,3,8.424932e-001,0.000000e+000,,,,,,,,,,,,,,32,1,4.000000e+000,0.000000e+000,0.000000e+000,0,,0,
1524605777.981,,0.000000e+000,3.499794e+001,4.321020e-006,0.000000e+000,3,8.395591e-001,0.000000e+000,,,,,,,,,,,,,,32,1,4.000000e+000,0.000000e+000,0.000000e+000,0,,0,
1524605803.384,,0.000000e+000,3.499911e+001,4.346509e-006,0.000000e+000,3,8.347372e-001,0.000000e+000,,,,,,,,,,,,,,32,1,4.000000e+000,7.820129e-004,0.000000e+000,0,,0,
1524605828.764,,0.000000e+000,3.499793e+001,4.382672e-006,0.000000e+000,3,8.409227e-001,0.000000e+000,,,,,,,,,,,,,,32,1,4.000000e+000,3.131866e-003,0.000000e+000,0,,0,
1524605854.442,,0.000000e+000,3.499872e+001,4.414539e-006,0.000000e+000,3,8.415275e-001,0.000000e+000,,,,,,,,,,,,,,32,1,4.000000e+000,0.000000e+000,0.000000e+000,0,,0,
1524605879.880,,0.000000e+000,3.499872e+001,4.444545e-006,0.000000e+000,3,8.424969e-001,0.000000e+000,,,,,,,,,,,,,,32,1,4.000000e+000,1.560211e-003,0.000000e+000,0,,0,
1524605905.337,,0.000000e+000,3.499911e+001,4.488493e-006,0.000000e+000,3,8.498205e-001,0.000000e+000,,,,,,,,,,,,,,32,1,4.000000e+000,7.820129e-004,0.000000e+000,0,,0,
1524605930.690,,0.000000e+000,3.499833e+001,4.463664e-006,0.000000e+000,3,8.403959e-001,0.000000e+000,,,,,,,,,,,,,,32,1,4.000000e+000,7.781982e-004,0.000000e+000,0,,0,
1524605956.096,,0.000000e+000,3.500067e+001,4.491531e-006,0.000000e+000,3,8.416679e-001,0.000000e+000,,,,,,,,,,,,,,32,1,4.000000e+000,3.910065e-003,0.000000e+000,0,,0,
1524605981.354,,0.000000e+000,3.499833e+001,4.533287e-006,0.000000e+000,3,8.481366e-001,0.000000e+000,,,,,,,,,,,,,,32,1,4.000000e+000,7.781982e-004,0.000000e+000,0,,0,
1524606006.374,,0.000000e+000,3.499715e+001,4.520229e-006,0.000000e+000,3,8.412581e-001,0.000000e+000,,,,,,,,,,,,,,32,1,4.000000e+000,0.000000e+000,0.000000e+000,0,,0,
1524606031.724,,0.000000e+000,3.499794e+001,4.529927e-006,0.000000e+000,3,8.428339e-001,0.000000e+000,,,,,,,,,,,,,,32,1,4.000000e+000,0.000000e+000,0.000000e+000,0,,0,
1524606056.692,,0.000000e+000,3.499911e+001,4.568819e-006,0.000000e+000,3,8.480898e-001,0.000000e+000,,,,,,,,,,,,,,32,1,4.000000e+000,7.820129e-004,0.000000e+000,0,,0,
1524606081.743,,0.000000e+000,3.500028e+001,4.569948e-006,0.000000e+000,3,8.451452e-001,0.000000e+000,,,,,,,,,,,,,,32,1,4.000000e+000,3.120422e-003,0.000000e+000,0,,0,
1524606106.680,,0.000000e+000,3.499833e+001,4.547368e-006,0.000000e+000,3,8.425090e-001,0.000000e+000,,,,,,,,,,,,,,32,1,4.000000e+000,7.781982e-004,0.000000e+000,0,,0,
1524606131.418,,0.000000e+000,3.499872e+001,4.600478e-006,0.000000e+000,3,8.497994e-001,0.000000e+000,,,,,,,,,,,,,,32,1,4.000000e+000,1.560211e-003,0.000000e+000,0,,0,
1524606156.691,,0.000000e+000,3.499872e+001,4.601930e-006,0.000000e+000,3,8.440298e-001,0.000000e+000,,,,,,,,,,,,,,32,1,4.000000e+000,1.560211e-003,0.000000e+000,0,,0,
1524606182.127,,0.000000e+000,3.499989e+001,4.614842e-006,0.000000e+000,3,8.477795e-001,0.000000e+000,,,,,,,,,,,,,,32,1,4.000000e+000,7.781982e-004,0.000000e+000,0,,0,
1524606207.507,,0.000000e+000,3.499793e+001,4.621890e-006,0.000000e+000,3,8.461660e-001,0.000000e+000,,,,,,,,,,,,,,32,1,4.000000e+000,1.567841e-003,0.000000e+000,0,,0,
1524606232.950,,0.000000e+000,3.499833e+001,4.748747e-006,0.000000e+000,3,8.496028e-001,0.000000e+000,,,,,,,,,,,,,,32,1,4.000000e+000,7.781982e-004,0.000000e+000,0,,0,
1524606258.333,,0.000000e+000,3.499872e+001,4.694633e-006,0.000000e+000,3,8.509533e-001,0.000000e+000,,,,,,,,,,,,,,32,1,4.000000e+000,1.560211e-003,0.000000e+000,0,,0,
1524606283.733,,0.000000e+000,3.499872e+001,4.693404e-006,0.000000e+000,3,8.511499e-001,0.000000e+000,,,,,,,,,,,,,,32,1,4.000000e+000,0.000000e+000,0.000000e+000,0,,0,
1524606309.693,,0.000000e+000,3.499833e+001,4.717007e-006,0.000000e+000,3,8.508166e-001,0.000000e+000,,,,,,,,,,,,,,32,1,4.000000e+000,7.781982e-004,0.000000e+000,0,,0,
1524606334.261,,0.000000e+000,3.499950e+001,4.673293e-006,0.000000e+000,3,8.524433e-001,0.000000e+000,,,,,,,,,,,,,,32,1,4.000000e+000,3.120422e-003,0.000000e+000,0,,0,
1524606359.459,,0.000000e+000,3.499872e+001,4.710575e-006,0.000000e+000,3,8.568950e-001,0.000000e+000,,,,,,,,,,,,,,32,1,4.000000e+000,1.560211e-003,0.000000e+000,0,,0,
1524606384.832,,0.000000e+000,3.499793e+001,4.727778e-006,0.000000e+000,3,8.492670e-001,0.000000e+000,,,,,,,,,,,,,,32,1,4.000000e+000,1.567841e-003,0.000000e+000,0,,0,
1524606410.245,,0.000000e+000,3.499793e+001,4.798592e-006,0.000000e+000,3,8.509479e-001,0.000000e+000,,,,,,,,,,,,,,32,1,4.000000e+000,3.131866e-003,0.000000e+000,0,,0,
1524606435.028,,0.000000e+000,3.499754e+001,4.788456e-006,0.000000e+000,3,8.556754e-001,0.000000e+000,,,,,,,,,,,,,,32,1,4.000000e+000,2.349854e-003,0.000000e+000,0,,0,
1524606460.236,,0.000000e+000,3.499872e+001,4.771439e-006,0.000000e+000,3,8.536094e-001,0.000000e+000,,,,,,,,,,,,,,32,1,4.000000e+000,1.560211e-003,0.000000e+000,0,,0,
1524606485.181,,0.000000e+000,3.499754e+001,4.722223e-006,0.000000e+000,3,8.624321e-001,0.000000e+000,,,,,,,,,,,,,,32,1,4.000000e+000,7.896423e-004,0.000000e+000,0,,0,
1524606510.344,,0.000000e+000,3.499911e+001,4.809351e-006,0.000000e+000,3,8.614597e-001,0.000000e+000,,,,,,,,,,,,,,32,1,4.000000e+000,7.820129e-004,0.000000e+000,0,,0,
1524606535.199,,0.000000e+000,3.500106e+001,4.786967e-006,0.000000e+000,3,8.461359e-001,0.000000e+000,,,,,,,,,,,,,,32,1,4.000000e+000,1.560211e-003,0.000000e+000,0,,0,
1524606560.655,,0.000000e+000,3.500106e+001,4.796308e-006,0.000000e+000,3,8.549571e-001,0.000000e+000,,,,,,,,,,,,,,32,1,4.000000e+000,3.128052e-003,0.000000e+000,0,,0,
1524606586.052,,0.000000e+000,3.499793e+001,4.868964e-006,0.000000e+000,3,8.591697e-001,0.000000e+000,,,,,,,,,,,,,,32,1,4.000000e+000,1.567841e-003,0.000000e+000,0,,0,
1524606610.368,,0.000000e+000,3.499872e+001,4.805535e-006,0.000000e+000,3,8.597454e-001,0.000000e+000,,,,,,,,,,,,,,32,1,4.000000e+000,1.560211e-003,0.000000e+000,0,,0,
1524606635.296,,0.000000e+000,3.499793e+001,4.874003e-006,0.000000e+000,3,8.598422e-001,0.000000e+000,,,,,,,,,,,,,,32,1,4.000000e+000,3.131866e-003,0.000000e+000,0,,0,
1524606660.669,,0.000000e+000,3.499872e+001,4.891215e-006,0.000000e+000,3,8.582035e-001,0.000000e+000,,,,,,,,,,,,,,32,1,4.000000e+000,0.000000e+000,0.000000e+000,0,,0,
1524606686.574,,0.000000e+000,3.500028e+001,4.891554e-006,0.000000e+000,3,8.623332e-001,0.000000e+000,,,,,,,,,,,,,,32,1,4.000000e+000,1.560211e-003,0.000000e+000,0,,0,
1524606712.762,,0.000000e+000,3.499871e+001,4.893549e-006,0.000000e+000,3,8.573461e-001,0.000000e+000,,,,,,,,,,,,,,32,1,4.000000e+000,3.128052e-003,0.000000e+000,0,,0,
1524606738.790,,0.000000e+000,3.499871e+001,4.844836e-006,0.000000e+000,3,8.509649e-001,0.000000e+000,,,,,,,,,,,,,,32,1,4.000000e+000,3.128052e-003,0.000000e+000,0,,0,
1524606764.185,,0.000000e+000,3.499911e+001,4.920297e-006,0.000000e+000,3,8.594754e-001,0.000000e+000,,,,,,,,,,,,,,32,1,4.000000e+000,3.910065e-003,0.000000e+000,0,,0,
1524606789.603,,0.000000e+000,3.500067e+001,4.928429e-006,0.000000e+000,3,8.525158e-001,0.000000e+000,,,,,,,,,,,,,,32,1,4.000000e+000,7.820129e-004,0.000000e+000,0,,0,
1524606815.378,,0.000000e+000,3.499754e+001,4.950786e-006,0.000000e+000,3,8.622993e-001,0.000000e+000,,,,,,,,,,,,,,32,1,4.000000e+000,2.349854e-003,0.000000e+000,0,,0,
1524606840.916,,0.000000e+000,3.499832e+001,4.994355e-006,0.000000e+000,3,8.564684e-001,0.000000e+000,,,,,,,,,,,,,,32,1,4.000000e+000,3.910065e-003,0.000000e+000,0,,0,
1524606866.057,,0.000000e+000,3.499833e+001,4.927663e-006,0.000000e+000,3,8.648944e-001,0.000000e+000,,,,,,,,,,,,,,32,1,4.000000e+000,7.781982e-004,0.000000e+000,0,,0,
1524606891.112,,0.000000e+000,3.499833e+001,4.943576e-006,0.000000e+000,3,8.574467e-001,0.000000e+000,,,,,,,,,,,,,,32,1,4.000000e+000,5.470276e-003,0.000000e+000,0,,0,
1524606915.855,,0.000000e+000,3.499911e+001,4.965544e-006,0.000000e+000,3,8.593698e-001,0.000000e+000,,,,,,,,,,,,,,32,1,4.000000e+000,7.820129e-004,0.000000e+000,0,,0,
1524606941.218,,0.000000e+000,3.499950e+001,4.967695e-006,0.000000e+000,3,8.561777e-001,0.000000e+000,,,,,,,,,,,,,,32,1,4.000000e+000,1.560211e-003,0.000000e+000,0,,0,
1524606966.323,,0.000000e+000,3.499989e+001,5.032037e-006,0.000000e+000,3,8.612048e-001,0.000000e+000,,,,,,,,,,,,,,32,1,4.000000e+000,2.342224e-003,0.000000e+000,0,,0,
1524606991.528,,0.000000e+000,3.499833e+001,5.089354e-006,0.000000e+000,3,8.546730e-001,0.000000e+000,,,,,,,,,,,,,,32,1,4.000000e+000,7.781982e-004,0.000000e+000,0,,0,
1524607016.826,,0.000000e+000,3.499833e+001,5.060364e-006,0.000000e+000,3,8.608603e-001,0.000000e+000,,,,,,,,,,,,,,32,1,4.000000e+000,7.781982e-004,0.000000e+000,0,,0,
1524607042.244,,0.000000e+000,3.500185e+001,5.060825e-006,0.000000e+000,3,8.611522e-001,0.000000e+000,,,,,,,,,,,,,,32,1,4.000000e+000,4.688263e-003,0.000000e+000,0,,0,
1524607067.745,,0.000000e+000,3.499950e+001,5.023278e-006,0.000000e+000,3,8.608565e-001,0.000000e+000,,,,,,,,,,,,,,32,1,4.000000e+000,1.560211e-003,0.000000e+000,0,,0,
1524607092.907,,0.000000e+000,3.499950e+001,5.072763e-006,0.000000e+000,3,8.567422e-001,0.000000e+000,,,,,,,,,,,,,,32,1,4.000000e+000,0.000000e+000,0.000000e+000,0,,0,
1524607117.675,,0.000000e+000,3.499911e+001,5.146880e-006,0.000000e+000,3,8.700773e-001,0.000000e+000,,,,,,,,,,,,,,32,1,4.000000e+000,7.820129e-004,0.000000e+000,0,,0,
1524607142.658,,0.000000e+000,3.499911e+001,5.095708e-006,0.000000e+000,3,8.598958e-001,0.000000e+000,,,,,,,,,,,,,,32,1,4.000000e+000,7.820129e-004,0.000000e+000,0,,0,
1524607168.504,,0.000000e+000,3.499833e+001,5.120163e-006,0.000000e+000,3,8.653287e-001,0.000000e+000,,,,,,,,,,,,,,32,1,4.000000e+000,7.781982e-004,0.000000e+000,0,,0,
1524607193.441,,0.000000e+000,3.499911e+001,5.112339e-006,0.000000e+000,3,8.667547e-001,0.000000e+000,,,,,,,,,,,,,,32,1,4.000000e+000,7.820129e-004,0.000000e+000,0,,0,
1524607219.597,,0.000000e+000,3.499911e+001,5.125366e-006,0.000000e+000,3,8.663895e-001,0.000000e+000,,,,,,,,,,,,,,32,1,4.000000e+000,7.820129e-004,0.000000e+000,0,,0,
1524607244.695,,0.000000e+000,3.500028e+001,5.190934e-006,0.000000e+000,3,8.675224e-001,0.000000e+000,,,,,,,,,,,,,,32,1,4.000000e+000,1.560211e-003,0.000000e+000,0,,0,
1524607270.105,,0.000000e+000,3.499676e+001,5.177797e-006,0.000000e+000,3,8.630927e-001,0.000000e+000,,,,,,,,,,,,,,32,1,4.000000e+000,7.820129e-004,0.000000e+000,0,,0,
1524607295.920,,0.000000e+000,3.499793e+001,5.161684e-006,0.000000e+000,3,8.673462e-001,0.000000e+000,,,,,,,,,,,,,,32,1,4.000000e+000,1.567841e-003,0.000000e+000,0,,0,
1524607321.128,,0.000000e+000,3.499989e+001,5.147254e-006,0.000000e+000,3,8.664976e-001,0.000000e+000,,,,,,,,,,,,,,32,1,4.000000e+000,7.781982e-004,0.000000e+000,0,,0,
1524607346.584,,0.000000e+000,3.500067e+001,5.202069e-006,0.000000e+000,3,8.629119e-001,0.000000e+000,,,,,,,,,,,,,,32,1,4.000000e+000,7.820129e-004,0.000000e+000,0,,0,
1524607371.944,,0.000000e+000,3.499989e+001,5.212364e-006,0.000000e+000,3,8.700612e-001,0.000000e+000,,,,,,,,,,,,,,32,1,4.000000e+000,3.898621e-003,0.000000e+000,0,,0,
1524607397.349,,0.000000e+000,3.499793e+001,5.220204e-006,0.000000e+000,3,8.661875e-001,0.000000e+000,,,,,,,,,,,,,,32,1,4.000000e+000,1.567841e-003,0.000000e+000,0,,0,
1524607422.745,,0.000000e+000,3.500028e+001,5.246023e-006,0.000000e+000,3,8.687780e-001,0.000000e+000,,,,,,,,,,,,,,32,1,4.000000e+000,0.000000e+000,0.000000e+000,0,,0,
1524607447.960,,0.000000e+000,3.499754e+001,5.212545e-006,0.000000e+000,3,8.602768e-001,0.000000e+000,,,,,,,,,,,,,,32,1,4.000000e+000,2.349854e-003,0.000000e+000,0,,0,
1524607473.648,,0.000000e+000,3.499950e+001,5.242961e-006,0.000000e+000,3,8.638268e-001,0.000000e+000,,,,,,,,,,,,,,32,1,4.000000e+000,1.560211e-003,0.000000e+000,0,,0,
1524607499.033,,0.000000e+000,3.499950e+001,5.187886e-006,0.000000e+000,3,8.588034e-001,0.000000e+000,,,,,,,,,,,,,,32,1,4.000000e+000,0.000000e+000,0.000000e+000,0,,0,
1524607524.424,,0.000000e+000,3.499833e+001,5.221017e-006,0.000000e+000,3,8.693229e-001,0.000000e+000,,,,,,,,,,,,,,32,1,4.000000e+000,2.349854e-003,0.000000e+000,0,,0,
1524607549.577,,0.000000e+000,3.499911e+001,5.244122e-006,0.000000e+000,3,8.585824e-001,0.000000e+000,,,,,,,,,,,,,,32,1,4.000000e+000,7.820129e-004,0.000000e+000,0,,0,
1524607575.752,,0.000000e+000,3.499871e+001,5.206257e-006,0.000000e+000,3,8.615165e-001,0.000000e+000,,,,,,,,,,,,,,32,1,4.000000e+000,3.128052e-003,0.000000e+000,0,,0,
1524607601.152,,0.000000e+000,3.499794e+001,5.239364e-006,0.000000e+000,3,8.662936e-001,0.000000e+000,,,,,,,,,,,,,,32,1,4.000000e+000,0.000000e+000,0.000000e+000,0,,0,
1524607625.620,,0.000000e+000,3.499833e+001,5.241340e-006,0.000000e+000,3,8.626254e-001,0.000000e+000,,,,,,,,,,,,,,32,1,4.000000e+000,2.349854e-003,0.000000e+000,0,,0,
1524607650.831,,0.000000e+000,3.499872e+001,5.264846e-006,0.000000e+000,3,8.626794e-001,0.000000e+000,,,,,,,,,,,,,,32,1,4.000000e+000,0.000000e+000,0.000000e+000,0,,0,
1524607676.236,,0.000000e+000,3.499911e+001,5.293634e-006,0.000000e+000,3,8.664209e-001,0.000000e+000,,,,,,,,,,,,,,32,1,4.000000e+000,7.820129e-004,0.000000e+000,0,,0,
1524607701.656,,0.000000e+000,3.499833e+001,5.249847e-006,0.000000e+000,3,8.646066e-001,0.000000e+000,,,,,,,,,,,,,,32,1,4.000000e+000,2.349854e-003,0.000000e+000,0,,0,
1524607727.029,,0.000000e+000,3.499911e+001,5.308700e-006,0.000000e+000,3,8.656493e-001,0.000000e+000,,,,,,,,,,,,,,32,1,4.000000e+000,2.338409e-003,0.000000e+000,0,,0,
1524607752.427,,0.000000e+000,3.499989e+001,5.301785e-006,0.000000e+000,3,8.688573e-001,0.000000e+000,,,,,,,,,,,,,,32,1,4.000000e+000,7.781982e-004,0.000000e+000,0,,0,
1524607778.002,,0.000000e+000,3.499911e+001,5.317744e-006,0.000000e+000,3,8.705984e-001,0.000000e+000,,,,,,,,,,,,,,32,1,4.000000e+000,7.820129e-004,0.000000e+000,0,,0,
1524607802.965,,0.000000e+000,3.499832e+001,5.328952e-006,0.000000e+000,3,8.627750e-001,0.000000e+000,,,,,,,,,,,,,,32,1,4.000000e+000,3.910065e-003,0.000000e+000,0,,0,
1524607827.978,,0.000000e+000,3.499793e+001,5.338120e-006,0.000000e+000,3,8.679954e-001,0.000000e+000,,,,,,,,,,,,,,32,1,4.000000e+000,1.567841e-003,0.000000e+000,0,,0,
1524607853.036,,0.000000e+000,3.499833e+001,5.404099e-006,0.000000e+000,3,8.678178e-001,0.000000e+000,,,,,,,,,,,,,,32,1,4.000000e+000,2.349854e-003,0.000000e+000,0,,0,
1524607878.624,,0.000000e+000,3.499793e+001,5.392038e-006,0.000000e+000,3,8.656190e-001,0.000000e+000,,,,,,,,,,,,,,32,1,4.000000e+000,4.688263e-003,0.000000e+000,0,,0,
1524607903.797,,0.000000e+000,3.499911e+001,5.401871e-006,0.000000e+000,3,8.688179e-001,0.000000e+000,,,,,,,,,,,,,,32,1,4.000000e+000,2.338409e-003,0.000000e+000,0,,0,
1524607929.202,,0.000000e+000,3.499950e+001,5.421557e-006,0.000000e+000,3,8.701788e-001,0.000000e+000,,,,,,,,,,,,,,32,1,4.000000e+000,1.560211e-003,0.000000e+000,0,,0,
1524607954.578,,0.000000e+000,3.499950e+001,5.379867e-006,0.000000e+000,3,8.666542e-001,0.000000e+000,,,,,,,,,,,,,,32,1,4.000000e+000,1.560211e-003,0.000000e+000,0,,0,
1524607979.893,,0.000000e+000,3.499950e+001,5.408479e-006,0.000000e+000,3,8.744539e-001,0.000000e+000,,,,,,,,,,,,,,32,1,4.000000e+000,0.000000e+000,0.000000e+000,0,,0,
1524608005.403,,0.000000e+000,3.499950e+001,5.441539e-006,0.000000e+000,3,8.701684e-001,0.000000e+000,,,,,,,,,,,,,,32,1,4.000000e+000,1.560211e-003,0.000000e+000,0,,0,
1524608030.791,,0.000000e+000,3.499872e+001,5.461889e-006,0.000000e+000,3,8.744363e-001,0.000000e+000,,,,,,,,,,,,,,32,1,4.000000e+000,1.560211e-003,0.000000e+000,0,,0,
1524608056.209,,0.000000e+000,3.499872e+001,5.471055e-006,0.000000e+000,3,8.692693e-001,0.000000e+000,,,,,,,,,,,,,,32,1,4.000000e+000,0.000000e+000,0.000000e+000,0,,0,
1524608082.634,,0.000000e+000,3.499872e+001,5.392636e-006,0.000000e+000,3,8.688446e-001,0.000000e+000,,,,,,,,,,,,,,32,1,4.000000e+000,0.000000e+000,0.000000e+000,0,,0,
1524608107.125,,0.000000e+000,3.499833e+001,5.412787e-006,0.000000e+000,3,8.685552e-001,0.000000e+000,,,,,,,,,,,,,,32,1,4.000000e+000,2.349854e-003,0.000000e+000,0,,0,
1524608132.515,,0.000000e+000,3.499989e+001,5.434446e-006,0.000000e+000,3,8.717080e-001,0.000000e+000,,,,,,,,,,,,,,32,1,4.000000e+000,2.342224e-003,0.000000e+000,0,,0,
1524608157.480,,0.000000e+000,3.499871e+001,5.468814e-006,0.000000e+000,3,8.628244e-001,0.000000e+000,,,,,,,,,,,,,,32,1,4.000000e+000,3.128052e-003,0.000000e+000,0,,0,
1524608182.253,,0.000000e+000,3.499911e+001,5.470094e-006,0.000000e+000,3,8.696866e-001,0.000000e+000,,,,,,,,,,,,,,32,1,4.000000e+000,2.338409e-003,0.000000e+000,0,,0,
1524608207.976,,0.000000e+000,3.499989e+001,5.398736e-006,0.000000e+000,3,8.719407e-001,0.000000e+000,,,,,,,,,,,,,,32,1,4.000000e+000,7.781982e-004,0.000000e+000,0,,0,
1524608233.414,,0.000000e+000,3.499872e+001,5.516380e-006,0.000000e+000,3,8.740540e-001,0.000000e+000,,,,,,,,,,,,,,32,1,4.000000e+000,0.000000e+000,0.000000e+000,0,,0,
1524608258.932,,0.000000e+000,3.499833e+001,5.524767e-006,0.000000e+000,3,8.693077e-001,0.000000e+000,,,,,,,,,,,,,,32,1,4.000000e+000,7.781982e-004,0.000000e+000,0,,0,
1524608284.085,,0.000000e+000,3.499950e+001,5.490178e-006,0.000000e+000,3,8.749038e-001,0.000000e+000,,,,,,,,,,,,,,32,1,4.000000e+000,1.560211e-003,0.000000e+000,0,,0,
1524608309.590,,0.000000e+000,3.499833e+001,5.482539e-006,0.000000e+000,3,8.721203e-001,0.000000e+000,,,,,,,,,,,,,,32,1,4.000000e+000,7.781982e-004,0.000000e+000,0,,0,
1524608334.708,,0.000000e+000,3.499833e+001,5.428195e-006,0.000000e+000,3,8.643539e-001,0.000000e+000,,,,,,,,,,,,,,32,1,4.000000e+000,7.781982e-004,0.000000e+000,0,,0,
1524608359.726,,0.000000e+000,3.499637e+001,5.504807e-006,0.000000e+000,3,8.736424e-001,0.000000e+000,,,,,,,,,,,,,,32,1,4.000000e+000,6.259918e-003,0.000000e+000,0,,0,
1524608385.131,,0.000000e+000,3.500145e+001,5.529299e-006,0.000000e+000,3,8.726000e-001,0.000000e+000,,,,,,,,,,,,,,32,1,4.000000e+000,2.349854e-003,0.000000e+000,0,,0,
1524608410.489,,0.000000e+000,3.499872e+001,5.531824e-006,0.000000e+000,3,8.751141e-001,0.000000e+000,,,,,,,,,,,,,,32,1,4.000000e+000,0.000000e+000,0.000000e+000,0,,0,
1524608435.790,,0.000000e+000,3.500106e+001,5.528012e-006,0.000000e+000,3,8.692908e-001,0.000000e+000,,,,,,,,,,,,,,32,1,4.000000e+000,3.128052e-003,0.000000e+000,0,,0,
1524608460.523,,0.000000e+000,3.499833e+001,5.566012e-006,0.000000e+000,3,8.726095e-001,0.000000e+000,,,,,,,,,,,,,,32,1,4.000000e+000,7.781982e-004,0.000000e+000,0,,0,
1524608486.255,,0.000000e+000,3.499950e+001,5.565683e-006,0.000000e+000,3,8.691643e-001,0.000000e+000,,,,,,,,,,,,,,32,1,4.000000e+000,1.560211e-003,0.000000e+000,0,,0,
1524608511.631,,0.000000e+000,3.499950e+001,5.583316e-006,0.000000e+000,3,8.730047e-001,0.000000e+000,,,,,,,,,,,,,,32,1,4.000000e+000,1.560211e-003,0.000000e+000,0,,0,
1524608537.084,,0.000000e+000,3.499872e+001,5.580182e-006,0.000000e+000,3,8.745975e-001,0.000000e+000,,,,,,,,,,,,,,32,1,4.000000e+000,0.000000e+000,0.000000e+000,0,,0,
1524608562.336,,0.000000e+000,3.499911e+001,5.581979e-006,0.000000e+000,3,8.680160e-001,0.000000e+000,,,,,,,,,,,,,,32,1,4.000000e+000,2.338409e-003,0.000000e+000,0,,0,
1524608587.527,,0.000000e+000,3.499794e+001,5.651899e-006,0.000000e+000,3,8.814876e-001,0.000000e+000,,,,,,,,,,,,,,32,1,4.000000e+000,0.000000e+000,0.000000e+000,0,,0,
1524608612.517,,0.000000e+000,3.499872e+001,5.602719e-006,0.000000e+000,3,8.717802e-001,0.000000e+000,,,,,,,,,,,,,,32,1,4.000000e+000,0.000000e+000,0.000000e+000,0,,0,
1524608637.208,,0.000000e+000,3.499950e+001,5.560029e-006,0.000000e+000,3,8.741756e-001,0.000000e+000,,,,,,,,,,,,,,32,1,4.000000e+000,1.560211e-003,0.000000e+000,0,,0,
1524608662.495,,0.000000e+000,3.500106e+001,5.657285e-006,0.000000e+000,3,8.707859e-001,0.000000e+000,,,,,,,,,,,,,,32,1,4.000000e+000,0.000000e+000,0.000000e+000,0,,0,
1524608687.218,,0.000000e+000,3.499442e+001,5.538238e-006,0.000000e+000,3,8.672176e-001,0.000000e+000,,,,,,,,,,,,,,32,1,4.000000e+000,7.041931e-003,0.000000e+000,0,,0,
1524608712.404,,0.000000e+000,3.500028e+001,5.595123e-006,0.000000e+000,3,8.635476e-001,0.000000e+000,,,,,,,,,,,,,,32,1,4.000000e+000,1.560211e-003,0.000000e+000,0,,0,
1524608737.361,,0.000000e+000,3.499754e+001,5.566977e-006,0.000000e+000,3,8.781710e-001,0.000000e+000,,,,,,,,,,,,,,32,1,4.000000e+000,7.896423e-004,0.000000e+000,0,,0,
1524608763.197,,0.000000e+000,3.499872e+001,5.635195e-006,0.000000e+000,3,8.674170e-001,0.000000e+000,,,,,,,,,,,,,,32,1,4.000000e+000,0.000000e+000,0.000000e+000,0,,0,
1524608788.037,,0.000000e+000,3.499989e+001,5.544916e-006,0.000000e+000,3,8.727633e-001,0.000000e+000,,,,,,,,,,,,,,32,1,4.000000e+000,2.342224e-003,0.000000e+000,0,,0,
1524608813.920,,0.000000e+000,3.499793e+001,5.593880e-006,0.000000e+000,3,8.753365e-001,0.000000e+000,,,,,,,,,,,,,,32,1,4.000000e+000,1.567841e-003,0.000000e+000,0,,0,
1524608839.105,,0.000000e+000,3.499989e+001,5.591949e-006,0.000000e+000,3,8.807308e-001,0.000000e+000,,,,,,,,,,,,,,32,1,4.000000e+000,7.781982e-004,0.000000e+000,0,,0,
1524608863.816,,0.000000e+000,3.499950e+001,5.631594e-006,0.000000e+000,3,8.685148e-001,0.000000e+000,,,,,,,,,,,,,,32,1,4.000000e+000,1.560211e-003,0.000000e+000,0,,0,
1524608889.184,,0.000000e+000,3.499833e+001,5.602524e-006,0.000000e+000,3,8.724967e-001,0.000000e+000,,,,,,,,,,,,,,32,1,4.000000e+000,2.349854e-003,0.000000e+000,0,,0,
1524608914.594,,0.000000e+000,3.499911e+001,5.598235e-006,0.000000e+000,3,8.705992e-001,0.000000e+000,,,,,,,,,,,,,,32,1,4.000000e+000,7.820129e-004,0.000000e+000,0,,0,
1524608939.952,,0.000000e+000,3.499911e+001,5.630724e-006,0.000000e+000,3,8.744394e-001,0.000000e+000,,,,,,,,,,,,,,32,1,4.000000e+000,7.820129e-004,0.000000e+000,0,,0,
1524608965.300,,0.000000e+000,3.499833e+001,5.648770e-006,0.000000e+000,3,8.673216e-001,0.000000e+000,,,,,,,,,,,,,,32,1,4.000000e+000,7.781982e-004,0.000000e+000,0,,0,
1524608990.248,,0.000000e+000,3.499911e+001,5.643035e-006,0.000000e+000,3,8.718798e-001,0.000000e+000,,,,,,,,,,,,,,32,1,4.000000e+000,7.820129e-004,0.000000e+000,0,,0,
1524609016.111,,0.000000e+000,3.499911e+001,5.649135e-006,0.000000e+000,3,8.786467e-001,0.000000e+000,,,,,,,,,,,,,,32,1,4.000000e+000,7.820129e-004,0.000000e+000,0,,0,
1524609041.514,,0.000000e+000,3.499911e+001,5.664918e-006,0.000000e+000,3,8.818656e-001,0.000000e+000,,,,,,,,,,,,,,32,1,4.000000e+000,7.820129e-004,0.000000e+000,0,,0,
1524609066.439,,0.000000e+000,3.499911e+001,5.677012e-006,0.000000e+000,3,8.767182e-001,0.000000e+000,,,,,,,,,,,,,,32,1,4.000000e+000,7.820129e-004,0.000000e+000,0,,0,
1524609092.287,,0.000000e+000,3.499793e+001,5.695067e-006,0.000000e+000,3,8.751522e-001,0.000000e+000,,,,,,,,,,,,,,32,1,4.000000e+000,1.567841e-003,0.000000e+000,0,,0,
1524609117.222,,0.000000e+000,3.499911e+001,5.660019e-006,0.000000e+000,3,8.752892e-001,0.000000e+000,,,,,,,,,,,,,,32,1,4.000000e+000,7.820129e-004,0.000000e+000,0,,0,
1524609142.563,,0.000000e+000,3.499911e+001,5.689288e-006,0.000000e+000,3,8.702987e-001,0.000000e+000,,,,,,,,,,,,,,32,1,4.000000e+000,3.910065e-003,0.000000e+000,0,,0,
1524609167.535,,0.000000e+000,3.499950e+001,5.688962e-006,0.000000e+000,3,8.679383e-001,0.000000e+000,,,,,,,,,,,,,,32,1,4.000000e+000,4.688263e-003,0.000000e+000,0,,0,
1524609192.921,,0.000000e+000,3.499950e+001,5.698494e-006,0.000000e+000,3,8.769249e-001,0.000000e+000,,,,,,,,,,,,,,32,1,4.000000e+000,0.000000e+000,0.000000e+000,0,,0,
1524609218.304,,0.000000e+000,3.499911e+001,5.684019e-006,0.000000e+000,3,8.748488e-001,0.000000e+000,,,,,,,,,,,,,,32,1,4.000000e+000,7.820129e-004,0.000000e+000,0,,0,
1524609243.679,,0.000000e+000,3.499989e+001,5.694837e-006,0.000000e+000,3,8.750725e-001,0.000000e+000,,,,,,,,,,,,,,32,1,4.000000e+000,2.342224e-003,0.000000e+000,0,,0,
1524609269.537,,0.000000e+000,3.500028e+001,5.699312e-006,0.000000e+000,3,8.823758e-001,0.000000e+000,,,,,,,,,,,,,,32,1,4.000000e+000,0.000000e+000,0.000000e+000,0,,0,
1524609294.490,,0.000000e+000,3.499872e+001,5.585205e-006,0.000000e+000,3,8.783600e-001,0.000000e+000,,,,,,,,,,,,,,32,1,4.000000e+000,0.000000e+000,0.000000e+000,0,,0,
1524609319.885,,0.000000e+000,3.499950e+001,5.685762e-006,0.000000e+000,3,8.771389e-001,0.000000e+000,,,,,,,,,,,,,,32,1,4.000000e+000,0.000000e+000,0.000000e+000,0,,0,
1524609345.723,,0.000000e+000,3.499911e+001,5.653656e-006,0.000000e+000,3,8.762801e-001,0.000000e+000,,,,,,,,,,,,,,32,1,4.000000e+000,7.820129e-004,0.000000e+000,0,,0,
1524609370.703,,0.000000e+000,3.499911e+001,5.660680e-006,0.000000e+000,3,8.631088e-001,0.000000e+000,,,,,,,,,,,,,,32,1,4.000000e+000,7.820129e-004,0.000000e+000,0,,0,
1524609396.084,,0.000000e+000,3.499911e+001,5.721650e-006,0.000000e+000,3,8.731723e-001,0.000000e+000,,,,,,,,,,,,,,32,1,4.000000e+000,7.820129e-004,0.000000e+000,0,,0,
1524609421.481,,0.000000e+000,3.499911e+001,5.686060e-006,0.000000e+000,3,8.743354e-001,0.000000e+000,,,,,,,,,,,,,,32,1,4.000000e+000,7.820129e-004,0.000000e+000,0,,0,
1524609446.877,,0.000000e+000,3.499872e+001,5.716935e-006,0.000000e+000,3,8.797258e-001,0.000000e+000,,,,,,,,,,,,,,32,1,4.000000e+000,1.560211e-003,0.000000e+000,0,,0,
1524609472.190,,0.000000e+000,3.499950e+001,5.728259e-006,0.000000e+000,3,8.775219e-001,0.000000e+000,,,,,,,,,,,,,,32,1,4.000000e+000,0.000000e+000,0.000000e+000,0,,0,
1524609497.648,,0.000000e+000,3.499950e+001,5.720359e-006,0.000000e+000,3,8.773282e-001,0.000000e+000,,,,,,,,,,,,,,32,1,4.000000e+000,1.560211e-003,0.000000e+000,0,,0,
1524609523.033,,0.000000e+000,3.499872e+001,5.730614e-006,0.000000e+000,3,8.825149e-001,0.000000e+000,,,,,,,,,,,,,,32,1,4.000000e+000,0.000000e+000,0.000000e+000,0,,0,
1524609548.441,,0.000000e+000,3.499911e+001,5.743232e-006,0.000000e+000,3,8.707485e-001,0.000000e+000,,,,,,,,,,,,,,32,1,4.000000e+000,7.820129e-004,0.000000e+000,0,,0,
1524609573.831,,0.000000e+000,3.499950e+001,5.757042e-006,0.000000e+000,3,8.684051e-001,0.000000e+000,,,,,,,,,,,,,,32,1,4.000000e+000,1.560211e-003,0.000000e+000,0,,0,
1524609599.179,,0.000000e+000,3.499989e+001,5.768958e-006,0.000000e+000,3,8.788030e-001,0.000000e+000,,,,,,,,,,,,,,32,1,4.000000e+000,2.342224e-003,0.000000e+000,0,,0,
1524609625.210,,0.000000e+000,3.499989e+001,5.793949e-006,0.000000e+000,3,8.763573e-001,0.000000e+000,,,,,,,,,,,,,,32,1,4.000000e+000,2.342224e-003,0.000000e+000,0,,0,
1524609651.390,,0.000000e+000,3.499872e+001,5.772150e-006,0.000000e+000,3,8.760052e-001,0.000000e+000,,,,,,,,,,,,,,32,1,4.000000e+000,1.560211e-003,0.000000e+000,0,,0,
1524609675.970,,0.000000e+000,3.499793e+001,5.784359e-006,0.000000e+000,3,8.700379e-001,0.000000e+000,,,,,,,,,,,,,,32,1,4.000000e+000,1.567841e-003,0.000000e+000,0,,0,
1524609701.053,,0.000000e+000,3.499793e+001,5.707419e-006,0.000000e+000,3,8.802516e-001,0.000000e+000,,,,,,,,,,,,,,32,1,4.000000e+000,1.567841e-003,0.000000e+000,0,,0,
1524609726.524,,0.000000e+000,3.499950e+001,5.811887e-006,0.000000e+000,3,8.911235e-001,0.000000e+000,,,,,,,,,,,,,,32,1,4.000000e+000,1.560211e-003,0.000000e+000,0,,0,
1524609752.401,,0.000000e+000,3.499950e+001,5.758291e-006,0.000000e+000,3,8.770835e-001,0.000000e+000,,,,,,,,,,,,,,32,1,4.000000e+000,3.120422e-003,0.000000e+000,0,,0,
1524609778.622,,0.000000e+000,3.499950e+001,5.826037e-006,0.000000e+000,3,8.692857e-001,0.000000e+000,,,,,,,,,,,,,,32,1,4.000000e+000,1.560211e-003,0.000000e+000,0,,0,
1524609804.407,,0.000000e+000,3.499989e+001,5.840303e-006,0.000000e+000,3,8.737622e-001,0.000000e+000,,,,,,,,,,,,,,32,1,4.000000e+000,7.781982e-004,0.000000e+000,0,,0,
1524609829.325,,0.000000e+000,3.500106e+001,5.827082e-006,0.000000e+000,3,8.830817e-001,0.000000e+000,,,,,,,,,,,,,,32,1,4.000000e+000,6.248474e-003,0.000000e+000,0,,0,
1524609854.300,,0.000000e+000,3.499911e+001,5.793343e-006,0.000000e+000,3,8.794154e-001,0.000000e+000,,,,,,,,,,,,,,32,1,4.000000e+000,7.820129e-004,0.000000e+000,0,,0,
1524609879.668,,0.000000e+000,3.499872e+001,5.793697e-006,0.000000e+000,3,8.793691e-001,0.000000e+000,,,,,,,,,,,,,,32,1,4.000000e+000,0.000000e+000,0.000000e+000,0,,0,
1524609905.101,,0.000000e+000,3.499911e+001,5.792617e-006,0.000000e+000,3,8.802898e-001,0.000000e+000,,,,,,,,,,,,,,32,1,4.000000e+000,7.820129e-004,0.000000e+000,0,,0,
1524609930.381,,0.000000e+000,3.499872e+001,5.864589e-006,0.000000e+000,3,8.842096e-001,0.000000e+000,,,,,,,,,,,,,,32,1,4.000000e+000,0.000000e+000,0.000000e+000,0,,0,
1524609955.862,,0.000000e+000,3.499833e+001,5.787860e-006,0.000000e+000,3,8.789063e-001,0.000000e+000,,,,,,,,,,,,,,32,1,4.000000e+000,7.781982e-004,0.000000e+000,0,,0,
1524609980.777,,0.000000e+000,3.499911e+001,5.773953e-006,0.000000e+000,3,8.835332e-001,0.000000e+000,,,,,,,,,,,,,,32,1,4.000000e+000,7.820129e-004,0.000000e+000,0,,0,
1524610005.898,,0.000000e+000,3.499911e+001,5.780862e-006,0.000000e+000,3,8.797154e-001,0.000000e+000,,,,,,,,,,,,,,32,1,4.000000e+000,7.820129e-004,0.000000e+000,0,,0,
1524610031.401,,0.000000e+000,3.499833e+001,5.788118e-006,0.000000e+000,3,8.812220e-001,0.000000e+000,,,,,,,,,,,,,,32,1,4.000000e+000,2.349854e-003,0.000000e+000,0,,0,
1524610056.868,,0.000000e+000,3.499872e+001,5.838981e-006,0.000000e+000,3,8.862231e-001,0.000000e+000,,,,,,,,,,,,,,32,1,4.000000e+000,1.560211e-003,0.000000e+000,0,,0,
1524610082.231,,0.000000e+000,3.499989e+001,5.821474e-006,0.000000e+000,3,8.818381e-001,0.000000e+000,,,,,,,,,,,,,,32,1,4.000000e+000,7.781982e-004,0.000000e+000,0,,0,
1524610107.889,,0.000000e+000,3.499911e+001,5.825265e-006,0.000000e+000,3,8.773314e-001,0.000000e+000,,,,,,,,,,,,,,32,1,4.000000e+000,7.820129e-004,0.000000e+000,0,,0,
1524610133.877,,0.000000e+000,3.499989e+001,5.811058e-006,0.000000e+000,3,8.769370e-001,0.000000e+000,,,,,,,,,,,,,,32,1,4.000000e+000,3.898621e-003,0.000000e+000,0,,0,
1524610158.795,,0.000000e+000,3.499833e+001,5.818312e-006,0.000000e+000,3,8.812351e-001,0.000000e+000,,,,,,,,,,,,,,32,1,4.000000e+000,2.349854e-003,0.000000e+000,0,,0,
1524610184.205,,0.000000e+000,3.499950e+001,5.813106e-006,0.000000e+000,3,8.739339e-001,0.000000e+000,,,,,,,,,,,,,,32,1,4.000000e+000,0.000000e+000,0.000000e+000,0,,0,
1524610209.708,,0.000000e+000,3.499950e+001,5.845065e-006,0.000000e+000,3,8.797532e-001,0.000000e+000,,,,,,,,,,,,,,32,1,4.000000e+000,1.560211e-003,0.000000e+000,0,,0,
1524610235.004,,0.000000e+000,3.499911e+001,5.843049e-006,0.000000e+000,3,8.746778e-001,0.000000e+000,,,,,,,,,,,,,,32,1,4.000000e+000,2.338409e-003,0.000000e+000,0,,0,
1524610260.366,,0.000000e+000,3.500067e+001,5.822939e-006,0.000000e+000,3,8.730366e-001,0.000000e+000,,,,,,,,,,,,,,32,1,4.000000e+000,3.910065e-003,0.000000e+000,0,,0,
1524610285.754,,0.000000e+000,3.499950e+001,5.856290e-006,0.000000e+000,3,8.831448e-001,0.000000e+000,,,,,,,,,,,,,,32,1,4.000000e+000,1.560211e-003,0.000000e+000,0,,0,
1524610311.162,,0.000000e+000,3.499950e+001,5.825732e-006,0.000000e+000,3,8.770331e-001,0.000000e+000,,,,,,,,,,,,,,32,1,4.000000e+000,0.000000e+000,0.000000e+000,0,,0,
1524610336.700,,0.000000e+000,3.499793e+001,5.882032e-006,0.000000e+000,3,8.830161e-001,0.000000e+000,,,,,,,,,,,,,,32,1,4.000000e+000,3.131866e-003,0.000000e+000,0,,0,
1524610362.540,,0.000000e+000,3.499911e+001,5.858874e-006,0.000000e+000,3,8.740507e-001,0.000000e+000,,,,,,,,,,,,,,32,1,4.000000e+000,7.820129e-004,0.000000e+000,0,,0,
1524610387.381,,0.000000e+000,3.499950e+001,5.832031e-006,0.000000e+000,3,8.728405e-001,0.000000e+000,,,,,,,,,,,,,,32,1,4.000000e+000,1.560211e-003,0.000000e+000,0,,0,
1524610412.131,,0.000000e+000,3.499950e+001,5.825616e-006,0.000000e+000,3,8.725391e-001,0.000000e+000,,,,,,,,,,,,,,32,1,4.000000e+000,0.000000e+000,0.000000e+000,0,,0,
1524610437.292,,0.000000e+000,3.499911e+001,5.897133e-006,0.000000e+000,3,8.803096e-001,0.000000e+000,,,,,,,,,,,,,,32,1,4.000000e+000,7.820129e-004,0.000000e+000,0,,0,