File: Input/MFn1_VRMac_34K_6000s_VRMde_35K.dc.dat
[Header]
TITLE,MPMS DC Measurement
BYAPP,MPMS Measurement,2.1,Summary
FILEOPENTIME, 1524263121.777000 4/20/2018, 4:25:21 PM

INFO, APPNAME, MPMS MultiVu Application, Revision 1.61,  Build 082

INFO, NAME, MFn1
INFO, WEIGHT, 1.000
INFO, AREA, 1.000
INFO, LENGTH, 1.000
INFO, SHAPE, 0
INFO, COMMENT,
INFO, SEQUENCE FILE: VRMac_34K_6000s_VRMde_35K.seq


INFO, BACKGROUND DATA FILE:, None


STARTUPAXIS,X,4,LINEAR,AUTO,0.000000,0.000000
STARTUPAXIS,Y1,5,LINEAR,AUTO,0.000000,0.000000


STARTUPGROUP,Longitudinal
FIELDGROUP,Longitudinal,1,2,3,4,5,6,7,8,9,15,16,17,18,27,28
FIELDGROUP,Transverse,1,2,3,4,10,11,12,13,14,19,20,21,22,27,28

PLOT_APPEARANCE,ALL,HORZ_GRID_ON,VERT_GRID_ON,MARKERS_AND_LINES

[Data]
Time,Comment,Field (Oe),Temperature (K),Long Moment (emu),Long Scan Std Dev,Long Algorithm,Long Reg Fit,Long Percent Error (%),Trans Moment (emu),Trans Scan Std Dev,Trans Algorithm,Trans Reg Fit,Trans Percent Error (%),Long Moment [w/o ABS] (emu),Long Scan Std Dev [w/o ABS],Long Reg Fit [w/o ABS],Long Percent Error [w/o ABS] (%),Trans Moment [w/o ABS] (emu),Trans Scan Std Dev [w/o ABS],Trans Reg Fit [w/o ABS],Trans Percent Error [w/o ABS] (%),Points per Scan,Scans per Measurement,Scan Length (cm),Delta Temp (K),Rot Position (deg),Error,EC Comp. Running,Using ABS,
1524263121.775,,0.000000e+000,3.500341e+001,-1.369346e-005,0.000000e+000,2,9.347021e-001,0.000000e+000,,,,,,,,,,,,,,32,1,4.000000e+000,3.139496e-003,0.000000e+000,0,,0,
1524263159.898,,0.000000e+000,3.500067e+001,-1.260288e-005,0.000000e+000,2,9.303678e-001,0.000000e+000,,,,,,,,,,,,,,32,1,4.000000e+000,7.820129e-004,0.000000e+000,0,,0,
1524263210.606,,0.000000e+000,3.500067e+001,-1.113230e-005,0.000000e+000,2,9.147830e-001,0.000000e+000,,,,,,,,,,,,,,32,1,4.000000e+000,7.820129e-004,0.000000e+000,0,,0,
1524263248.744,,0.000000e+000,3.499950e+001,-1.031731e-005,0.000000e+000,2,9.138272e-001,0.000000e+000,,,,,,,,,,,,,,32,1,4.000000e+000,1.560211e-003,0.000000e+000,0,,0,
1524263287.050,,0.000000e+000,3.500067e+001,-9.590704e-006,0.000000e+000,2,9.049163e-001,0.000000e+000,,,,,,,,,,,,,,32,1,4.000000e+000,2.338409e-003,0.000000e+000,0,,0,
1524263325.208,,0.000000e+000,3.499911e+001,-8.979812e-006,0.000000e+000,2,8.960100e-001,0.000000e+000,,,,,,,,,,,,,,32,1,4.000000e+000,7.820129e-004,0.000000e+000,0,,0,
1524263363.071,,0.000000e+000,3.499989e+001,-8.452321e-006,0.000000e+000,2,8.883585e-001,0.000000e+000,,,,,,,,,,,,,,32,1,4.000000e+000,7.781982e-004,0.000000e+000,0,,0,
1524263401.232,,0.000000e+000,3.499872e+001,-8.016966e-006,0.000000e+000,2,8.872395e-001,0.000000e+000,,,,,,,,,,,,,,32,1,4.000000e+000,0.000000e+000,0.000000e+000,0,,0,
1524263439.200,,0.000000e+000,3.499950e+001,-7.640017e-006,0.000000e+000,2,8.796048e-001,0.000000e+000,,,,,,,,,,,,,,32,1,4.000000e+000,0.000000e+000,0.000000e+000,0,,0,
1524263477.243,,0.000000e+000,3.499911e+001,-7.216750e-006,0.000000e+000,2,8.726131e-001,0.000000e+000,,,,,,,,,,,,,,32,1,4.000000e+000,7.820129e-004,0.000000e+000,0,,0,
1524263514.661,,0.000000e+000,3.500106e+001,-6.835572e-006,0.000000e+000,2,8.723711e-001,0.000000e+000,,,,,,,,,,,,,,32,1,4.000000e+000,3.128052e-003,0.000000e+000,0,,0,
1524263552.796,,0.000000e+000,3.499872e+001,-6.584591e-006,0.000000e+000,2,8.617243e-001,0.000000e+000,,,,,,,,,,,,,,32,1,4.000000e+000,1.560211e-003,0.000000e+000,0,,0,
1524263591.084,,0.000000e+000,3.499833e+001,-6.335221e-006,0.000000e+000,2,8.472252e-001,0.000000e+000,,,,,,,,,,,,,,32,1,4.000000e+000,7.781982e-004,0.000000e+000,0,,0,
1524263628.962,,0.000000e+000,3.499794e+001,-6.096266e-006,0.000000e+000,2,8.430262e-001,0.000000e+000,,,,,,,,,,,,,,32,1,4.000000e+000,0.000000e+000,0.000000e+000,0,,0,
1524263667.173,,0.000000e+000,3.499911e+001,-5.846680e-006,0.000000e+000,2,8.380606e-001,0.000000e+000,,,,,,,,,,,,,,32,1,4.000000e+000,7.820129e-004,0.000000e+000,0,,0,
1524263704.953,,0.000000e+000,3.499911e+001,-5.575142e-006,0.000000e+000,2,8.217355e-001,0.000000e+000,,,,,,,,,,,,,,32,1,4.000000e+000,7.820129e-004,0.000000e+000,0,,0,
1524263742.959,,0.000000e+000,3.499950e+001,-5.314830e-006,0.000000e+000,2,8.183522e-001,0.000000e+000,,,,,,,,,,,,,,32,1,4.000000e+000,1.560211e-003,0.000000e+000,0,,0,
1524263781.127,,0.000000e+000,3.499950e+001,-5.123611e-006,0.000000e+000,2,8.277372e-001,0.000000e+000,,,,,,,,,,,,,,32,1,4.000000e+000,1.560211e-003,0.000000e+000,0,,0,
1524263819.258,,0.000000e+000,3.499911e+001,-4.986700e-006,0.000000e+000,2,8.096392e-001,0.000000e+000,,,,,,,,,,,,,,32,1,4.000000e+000,7.820129e-004,0.000000e+000,0,,0,
1524263856.858,,0.000000e+000,3.499950e+001,-4.833318e-006,0.000000e+000,2,8.117475e-001,0.000000e+000,,,,,,,,,,,,,,32,1,4.000000e+000,0.000000e+000,0.000000e+000,0,,0,
1524263894.329,,0.000000e+000,3.500028e+001,-4.640870e-006,0.000000e+000,2,8.037030e-001,0.000000e+000,,,,,,,,,,,,,,32,1,4.000000e+000,1.560211e-003,0.000000e+000,0,,0,
1524263932.732,,0.000000e+000,3.499950e+001,-4.499665e-006,0.000000e+000,2,7.920294e-001,0.000000e+000,,,,,,,,,,,,,,32,1,4.000000e+000,0.000000e+000,0.000000e+000,0,,0,
1524263970.727,,0.000000e+000,3.499872e+001,-4.344146e-006,0.000000e+000,2,7.854161e-001,0.000000e+000,,,,,,,,,,,,,,32,1,4.000000e+000,1.560211e-003,0.000000e+000,0,,0,
1524264008.876,,0.000000e+000,3.499754e+001,-4.198829e-006,0.000000e+000,2,7.781698e-001,0.000000e+000,,,,,,,,,,,,,,32,1,4.000000e+000,2.349854e-003,0.000000e+000,0,,0,
1524264046.629,,0.000000e+000,3.499989e+001,-4.091396e-006,0.000000e+000,2,7.681264e-001,0.000000e+000,,,,,,,,,,,,,,32,1,4.000000e+000,7.781982e-004,0.000000e+000,0,,0,
1524264084.627,,0.000000e+000,3.499950e+001,-3.939249e-006,0.000000e+000,2,7.689803e-001,0.000000e+000,,,,,,,,,,,,,,32,1,4.000000e+000,0.000000e+000,0.000000e+000,0,,0,
1524264122.267,,0.000000e+000,3.499911e+001,-3.798943e-006,0.000000e+000,2,7.483824e-001,0.000000e+000,,,,,,,,,,,,,,32,1,4.000000e+000,7.820129e-004,0.000000e+000,0,,0,
1524264159.735,,0.000000e+000,3.499911e+001,-3.662990e-006,0.000000e+000,2,7.508628e-001,0.000000e+000,,,,,,,,,,,,,,32,1,4.000000e+000,7.820129e-004,0.000000e+000,0,,0,
1524264197.841,,0.000000e+000,3.499872e+001,-3.599691e-006,0.000000e+000,2,7.415739e-001,0.000000e+000,,,,,,,,,,,,,,32,1,4.000000e+000,0.000000e+000,0.000000e+000,0,,0,
1524264236.771,,0.000000e+000,3.499911e+001,-3.479845e-006,0.000000e+000,2,7.253193e-001,0.000000e+000,,,,,,,,,,,,,,32,1,4.000000e+000,7.820129e-004,0.000000e+000,0,,0,
1524264274.602,,0.000000e+000,3.499911e+001,-3.361575e-006,0.000000e+000,2,7.251348e-001,0.000000e+000,,,,,,,,,,,,,,32,1,4.000000e+000,7.820129e-004,0.000000e+000,0,,0,
1524264312.525,,0.000000e+000,3.499950e+001,-3.270524e-006,0.000000e+000,2,7.139910e-001,0.000000e+000,,,,,,,,,,,,,,32,1,4.000000e+000,0.000000e+000,0.000000e+000,0,,0,
1524264350.165,,0.000000e+000,3.499989e+001,-3.194489e-006,0.000000e+000,2,7.116831e-001,0.000000e+000,,,,,,,,,,,,,,32,1,4.000000e+000,7.781982e-004,0.000000e+000,0,,0,
1524264388.313,,0.000000e+000,3.499950e+001,-3.094621e-006,0.000000e+000,2,7.016053e-001,0.000000e+000,,,,,,,,,,,,,,32,1,4.000000e+000,0.000000e+000,0.000000e+000,0,,0,
1524264426.317,,0.000000e+000,3.499677e+001,-3.005277e-006,0.000000e+000,2,6.947945e-001,0.000000e+000,,,,,,,,,,,,,,32,1,4.000000e+000,3.910065e-003,0.000000e+000,0,,0,
1524264464.070,,0.000000e+000,3.500028e+001,-2.890656e-006,0.000000e+000,2,6.667090e-001,0.000000e+000,,,,,,,,,,,,,,32,1,4.000000e+000,3.120422e-003,0.000000e+000,0,,0,
1524264502.153,,0.000000e+000,3.499911e+001,-2.795984e-006,0.000000e+000,2,6.698598e-001,0.000000e+000,,,,,,,,,,,,,,32,1,4.000000e+000,7.820129e-004,0.000000e+000,0,,0,
1524264540.486,,0.000000e+000,3.499989e+001,-2.709728e-006,0.000000e+000,2,6.509371e-001,0.000000e+000,,,,,,,,,,,,,,32,1,4.000000e+000,7.781982e-004,0.000000e+000,0,,0,
1524264578.631,,0.000000e+000,3.499989e+001,-2.619545e-006,0.000000e+000,2,6.461973e-001,0.000000e+000,,,,,,,,,,,,,,32,1,4.000000e+000,7.781982e-004,0.000000e+000,0,,0,
1524264616.539,,0.000000e+000,3.499872e+001,-2.577034e-006,0.000000e+000,2,6.364335e-001,0.000000e+000,,,,,,,,,,,,,,32,1,4.000000e+000,0.000000e+000,0.000000e+000,0,,0,
1524264654.695,,0.000000e+000,3.499911e+001,-2.509674e-006,0.000000e+000,2,6.234455e-001,0.000000e+000,,,,,,,,,,,,,,32,1,4.000000e+000,7.820129e-004,0.000000e+000,0,,0,
1524264692.326,,0.000000e+000,3.499950e+001,-2.386609e-006,0.000000e+000,2,6.041109e-001,0.000000e+000,,,,,,,,,,,,,,32,1,4.000000e+000,0.000000e+000,0.000000e+000,0,,0,
1524264730.476,,0.000000e+000,3.499911e+001,-2.262049e-006,0.000000e+000,2,5.805281e-001,0.000000e+000,,,,,,,,,,,,,,32,1,4.000000e+000,7.820129e-004,0.000000e+000,0,,0,
1524264769.099,,0.000000e+000,3.499872e+001,-2.286898e-006,0.000000e+000,2,5.886216e-001,0.000000e+000,,,,,,,,,,,,,,32,1,4.000000e+000,0.000000e+000,0.000000e+000,0,,0,
1524264806.780,,0.000000e+000,3.499911e+001,-2.246523e-006,0.000000e+000,2,5.969502e-001,0.000000e+000,,,,,,,,,,,,,,32,1,4.000000e+000,7.820129e-004,0.000000e+000,0,,0,
1524264844.800,,0.000000e+000,3.499911e+001,-2.317306e-006,0.000000e+000,2,6.021235e-001,0.000000e+000,,,,,,,,,,,,,,32,1,4.000000e+000,7.820129e-004,0.000000e+000,0,,0,
1524264882.583,,0.000000e+000,3.499872e+001,-2.116392e-006,0.000000e+000,2,5.707861e-001,0.000000e+000,,,,,,,,,,,,,,32,1,4.000000e+000,0.000000e+000,0.000000e+000,0,,0,
1524264920.584,,0.000000e+000,3.499833e+001,-2.051577e-006,0.000000e+000,2,5.455793e-001,0.000000e+000,,,,,,,,,,,,,,32,1,4.000000e+000,7.781982e-004,0.000000e+000,0,,0,
1524264958.082,,0.000000e+000,3.500028e+001,-2.012959e-006,0.000000e+000,2,5.261126e-001,0.000000e+000,,,,,,,,,,,,,,32,1,4.000000e+000,3.120422e-003,0.000000e+000,0,,0,
1524264995.660,,0.000000e+000,3.499832e+001,-1.948373e-006,0.000000e+000,2,4.955447e-001,0.000000e+000,,,,,,,,,,,,,,32,1,4.000000e+000,3.910065e-003,0.000000e+000,0,,0,
1524265033.593,,0.000000e+000,3.499911e+001,-1.895507e-006,0.000000e+000,2,5.144186e-001,0.000000e+000,,,,,,,,,,,,,,32,1,4.000000e+000,7.820129e-004,0.000000e+000,0,,0,
1524265071.644,,0.000000e+000,3.500028e+001,-1.811609e-006,0.000000e+000,2,4.705029e-001,0.000000e+000,,,,,,,,,,,,,,32,1,4.000000e+000,0.000000e+000,0.000000e+000,0,,0,
1524265109.662,,0.000000e+000,3.499872e+001,-1.750842e-006,0.000000e+000,2,4.682087e-001,0.000000e+000,,,,,,,,,,,,,,32,1,4.000000e+000,0.000000e+000,0.000000e+000,0,,0,
1524265147.442,,0.000000e+000,3.499950e+001,-1.717211e-006,0.000000e+000,2,4.455512e-001,0.000000e+000,,,,,,,,,,,,,,32,1,4.000000e+000,0.000000e+000,0.000000e+000,0,,0,
1524265185.145,,0.000000e+000,3.499911e+001,-1.692357e-006,0.000000e+000,2,4.673101e-001,0.000000e+000,,,,,,,,,,,,,,32,1,4.000000e+000,7.820129e-004,0.000000e+000,0,,0,
1524265223.671,,0.000000e+000,3.499911e+001,-1.651954e-006,0.000000e+000,2,4.421540e-001,0.000000e+000,,,,,,,,,,,,,,32,1,4.000000e+000,2.338409e-003,0.000000e+000,0,,0,
1524265260.886,,0.000000e+000,3.499950e+001,-1.610355e-006,0.000000e+000,2,3.999138e-001,0.000000e+000,,,,,,,,,,,,,,32,1,4.000000e+000,0.000000e+000,0.000000e+000,0,,0,
1524265298.932,,0.000000e+000,3.499950e+001,-1.542985e-006,0.000000e+000,2,3.974292e-001,0.000000e+000,,,,,,,,,,,,,,32,1,4.000000e+000,1.560211e-003,0.000000e+000,0,,0,
1524265337.083,,0.000000e+000,3.499911e+001,-1.507641e-006,0.000000e+000,2,3.891711e-001,0.000000e+000,,,,,,,,,,,,,,32,1,4.000000e+000,7.820129e-004,0.000000e+000,0,,0,
1524265375.571,,0.000000e+000,3.499911e+001,-1.414382e-006,0.000000e+000,2,3.282744e-001,0.000000e+000,,,,,,,,,,,,,,32,1,4.000000e+000,7.820129e-004,0.000000e+000,0,,0,
1524265413.831,,0.000000e+000,3.499872e+001,-1.407761e-006,0.000000e+000,2,3.408401e-001,0.000000e+000,,,,,,,,,,,,,,32,1,4.000000e+000,0.000000e+000,0.000000e+000,0,,0,
1524265452.017,,0.000000e+000,3.499911e+001,-1.348281e-006,0.000000e+000,2,2.995633e-001,0.000000e+000,,,,,,,,,,,,,,32,1,4.000000e+000,7.820129e-004,0.000000e+000,0,,0,
1524265489.775,,0.000000e+000,3.500067e+001,-1.326894e-006,0.000000e+000,2,2.919818e-001,0.000000e+000,,,,,,,,,,,,,,32,1,4.000000e+000,3.910065e-003,0.000000e+000,0,,0,
1524265527.543,,0.000000e+000,3.499911e+001,-1.252460e-006,0.000000e+000,2,2.585771e-001,0.000000e+000,,,,,,,,,,,,,,32,1,4.000000e+000,7.820129e-004,0.000000e+000,0,,0,
1524265565.713,,0.000000e+000,3.499911e+001,-1.144595e-006,0.000000e+000,2,2.099309e-001,0.000000e+000,,,,,,,,,,,,,,32,1,4.000000e+000,7.820129e-004,0.000000e+000,0,,0,
1524265603.611,,0.000000e+000,3.499833e+001,-1.207417e-006,0.000000e+000,2,2.437328e-001,0.000000e+000,,,,,,,,,,,,,,32,1,4.000000e+000,7.781982e-004,0.000000e+000,0,,0,
1524265641.744,,0.000000e+000,3.499833e+001,-1.152615e-006,0.000000e+000,2,1.740141e-001,0.000000e+000,,,,,,,,,,,,,,32,1,4.000000e+000,2.349854e-003,0.000000e+000,0,,0,
1524265679.892,,0.000000e+000,3.499872e+001,-1.120417e-006,0.000000e+000,2,1.611868e-001,0.000000e+000,,,,,,,,,,,,,,32,1,4.000000e+000,0.000000e+000,0.000000e+000,0,,0,
1524265718.070,,0.000000e+000,3.499872e+001,-1.080604e-006,0.000000e+000,2,1.279430e-001,0.000000e+000,,,,,,,,,,,,,,32,1,4.000000e+000,1.560211e-003,0.000000e+000,0,,0,
1524265756.131,,0.000000e+000,3.499794e+001,-1.034683e-006,0.000000e+000,2,8.195826e-002,0.000000e+000,,,,,,,,,,,,,,32,1,4.000000e+000,0.000000e+000,0.000000e+000,0,,0,
1524265794.169,,0.000000e+000,3.500028e+001,-1.006534e-006,0.000000e+000,2,5.542771e-002,0.000000e+000,,,,,,,,,,,,,,32,1,4.000000e+000,1.560211e-003,0.000000e+000,0,,0,
1524265832.132,,0.000000e+000,3.499950e+001,-9.197254e-007,0.000000e+000,2,0.000000e+000,0.000000e+000,,,,,,,,,,,,,,32,1,4.000000e+000,1.560211e-003,0.000000e+000,0,,0,
1524265870.385,,0.000000e+000,3.499637e+001,-9.623385e-007,0.000000e+000,2,0.000000e+000,0.000000e+000,,,,,,,,,,,,,,32,1,4.000000e+000,1.560211e-003,0.000000e+000,0,,0,
1524265908.221,,0.000000e+000,3.500146e+001,-9.492901e-007,0.000000e+000,2,1.560326e-002,0.000000e+000,,,,,,,,,,,,,,32,1,4.000000e+000,3.910065e-003,0.000000e+000,0,,0,
1524265946.784,,0.000000e+000,3.499872e+001,-8.986503e-007,0.000000e+000,2,0.000000e+000,0.000000e+000,,,,,,,,,,,,,,32,1,4.000000e+000,0.000000e+000,0.000000e+000,0,,0,
1524265984.897,,0.000000e+000,3.499989e+001,-8.823260e-007,0.000000e+000,2,0.000000e+000,0.000000e+000,,,,,,,,,,,,,,32,1,4.000000e+000,7.781982e-004,0.000000e+000,0,,0,
1524266022.805,,0.000000e+000,3.499989e+001,-8.123387e-007,0.000000e+000,2,0.000000e+000,0.000000e+000,,,,,,,,,,,,,,32,1,4.000000e+000,7.781982e-004,0.000000e+000,0,,0,
1524266061.618,,0.000000e+000,3.499871e+001,-8.056421e-007,0.000000e+000,2,0.000000e+000,0.000000e+000,,,,,,,,,,,,,,32,1,4.000000e+000,3.128052e-003,0.000000e+000,0,,0,
1524266099.604,,0.000000e+000,3.499872e+001,-8.001363e-007,0.000000e+000,2,0.000000e+000,0.000000e+000,,,,,,,,,,,,,,32,1,4.000000e+000,0.000000e+000,0.000000e+000,0,,0,
1524266137.644,,0.000000e+000,3.499715e+001,-7.649338e-007,0.000000e+000,2,0.000000e+000,0.000000e+000,,,,,,,,,,,,,,32,1,4.000000e+000,3.128052e-003,0.000000e+000,0,,0,
1524266175.327,,0.000000e+000,3.499872e+001,-6.607410e-007,0.000000e+000,2,0.000000e+000,0.000000e+000,,,,,,,,,,,,,,32,1,4.000000e+000,1.560211e-003,0.000000e+000,0,,0,
1524266213.713,,0.000000e+000,3.499911e+001,-6.492619e-007,0.000000e+000,2,0.000000e+000,0.000000e+000,,,,,,,,,,,,,,32,1,4.000000e+000,7.820129e-004,0.000000e+000,0,,0,
1524266251.083,,0.000000e+000,3.499911e+001,-6.450117e-007,0.000000e+000,2,0.000000e+000,0.000000e+000,,,,,,,,,,,,,,32,1,4.000000e+000,7.820129e-004,0.000000e+000,0,,0,
1524266289.169,,0.000000e+000,3.499911e+001,-6.558166e-007,0.000000e+000,2,0.000000e+000,0.000000e+000,,,,,,,,,,,,,,32,1,4.000000e+000,7.820129e-004,0.000000e+000,0,,0,
1524266327.287,,0.000000e+000,3.499911e+001,-6.120101e-007,0.000000e+000,2,0.000000e+000,0.000000e+000,,,,,,,,,,,,,,32,1,4.000000e+000,7.820129e-004,0.000000e+000,0,,0,
1524266365.442,,0.000000e+000,3.499911e+001,-6.050877e-007,0.000000e+000,2,0.000000e+000,0.000000e+000,,,,,,,,,,,,,,32,1,4.000000e+000,7.820129e-004,0.000000e+000,0,,0,
1524266402.698,,0.000000e+000,3.499950e+001,-5.909007e-007,0.000000e+000,2,0.000000e+000,0.000000e+000,,,,,,,,,,,,,,32,1,4.000000e+000,1.560211e-003,0.000000e+000,0,,0,
1524266441.086,,0.000000e+000,3.499911e+001,-5.138801e-007,0.000000e+000,2,0.000000e+000,0.000000e+000,,,,,,,,,,,,,,32,1,4.000000e+000,7.820129e-004,0.000000e+000,0,,0,
1524266478.997,,0.000000e+000,3.499871e+001,-4.974100e-007,0.000000e+000,2,0.000000e+000,0.000000e+000,,,,,,,,,,,,,,32,1,4.000000e+000,3.128052e-003,0.000000e+000,0,,0,
1524266516.790,,0.000000e+000,3.499950e+001,-4.441586e-007,0.000000e+000,2,0.000000e+000,0.000000e+000,,,,,,,,,,,,,,32,1,4.000000e+000,3.120422e-003,0.000000e+000,0,,0,
1524266554.263,,0.000000e+000,3.500028e+001,-4.567625e-007,0.000000e+000,2,0.000000e+000,0.000000e+000,,,,,,,,,,,,,,32,1,4.000000e+000,1.560211e-003,0.000000e+000,0,,0,
1524266592.851,,0.000000e+000,3.499989e+001,-4.326928e-007,0.000000e+000,2,0.000000e+000,0.000000e+000,,,,,,,,,,,,,,32,1,4.000000e+000,7.781982e-004,0.000000e+000,0,,0,
1524266630.289,,0.000000e+000,3.499793e+001,-4.246454e-007,0.000000e+000,2,0.000000e+000,0.000000e+000,,,,,,,,,,,,,,32,1,4.000000e+000,1.567841e-003,0.000000e+000,0,,0,
1524266668.122,,0.000000e+000,3.499911e+001,-3.794842e-007,0.000000e+000,2,0.000000e+000,0.000000e+000,,,,,,,,,,,,,,32,1,4.000000e+000,7.820129e-004,0.000000e+000,0,,0,
1524266706.663,,0.000000e+000,3.499911e+001,-3.471526e-007,0.000000e+000,2,0.000000e+000,0.000000e+000,,,,,,,,,,,,,,32,1,4.000000e+000,7.820129e-004,0.000000e+000,0,,0,
1524266744.268,,0.000000e+000,3.499911e+001,-3.418370e-007,0.000000e+000,2,0.000000e+000,0.000000e+000,,,,,,,,,,,,,,32,1,4.000000e+000,7.820129e-004,0.000000e+000,0,,0,
1524266782.124,,0.000000e+000,3.499950e+001,-3.074597e-007,0.000000e+000,2,0.000000e+000,0.000000e+000,,,,,,,,,,,,,,32,1,4.000000e+000,0.000000e+000,0.000000e+000,0,,0,
1524266820.569,,0.000000e+000,3.499950e+001,-2.889552e-007,0.000000e+000,2,0.000000e+000,0.000000e+000,,,,,,,,,,,,,,32,1,4.000000e+000,0.000000e+000,0.000000e+000,0,,0,
1524266858.227,,0.000000e+000,3.499911e+001,-2.968393e-007,0.000000e+000,2,0.000000e+000,0.000000e+000,,,,,,,,,,,,,,32,1,4.000000e+000,7.820129e-004,0.000000e+000,0,,0,
1524266896.833,,0.000000e+000,3.499911e+001,-2.551640e-007,0.000000e+000,2,0.000000e+000,0.000000e+000,,,,,,,,,,,,,,32,1,4.000000e+000,7.820129e-004,0.000000e+000,0,,0,
1524266934.963,,0.000000e+000,3.499950e+001,-2.403801e-007,0.000000e+000,2,0.000000e+000,0.000000e+000,,,,,,,,,,,,,,32,1,4.000000e+000,0.000000e+000,0.000000e+000,0,,0,
1524266972.641,,0.000000e+000,3.499950e+001,-2.088940e-007,0.000000e+000,2,0.000000e+000,0.000000e+000,,,,,,,,,,,,,,32,1,4.000000e+000,0.000000e+000,0.000000e+000,0,,0,
1524267010.754,,0.000000e+000,3.499950e+001,-2.075181e-007,0.000000e+000,2,0.000000e+000,0.000000e+000,,,,,,,,,,,,,,32,1,4.000000e+000,0.000000e+000,0.000000e+000,0,,0,
1524267048.882,,0.000000e+000,3.499793e+001,-2.614107e-007,0.000000e+000,2,0.000000e+000,0.000000e+000,,,,,,,,,,,,,,32,1,4.000000e+000,1.567841e-003,0.000000e+000,0,,0,
1524267087.038,,0.000000e+000,3.499911e+001,-1.695973e-007,0.000000e+000,2,0.000000e+000,0.000000e+000,,,,,,,,,,,,,,32,1,4.000000e+000,7.820129e-004,0.000000e+000,0,,0,
1524267125.084,,0.000000e+000,3.499989e+001,-1.995273e-007,0.000000e+000,2,0.000000e+000,0.000000e+000,,,,,,,,,,,,,,32,1,4.000000e+000,7.781982e-004,0.000000e+000,0,,0,
1524267163.302,,0.000000e+000,3.499911e+001,-1.262735e-007,0.000000e+000,2,0.000000e+000,0.000000e+000,,,,,,,,,,,,,,32,1,4.000000e+000,7.820129e-004,0.000000e+000,0,,0,
1524267201.435,,0.000000e+000,3.499872e+001,-1.200225e-007,0.000000e+000,2,0.000000e+000,0.000000e+000,,,,,,,,,,,,,,32,1,4.000000e+000,0.000000e+000,0.000000e+000,0,,0,
1524267239.573,,0.000000e+000,3.499911e+001,-7.625372e-008,0.000000e+000,2,0.000000e+000,0.000000e+000,,,,,,,,,,,,,,32,1,4.000000e+000,7.820129e-004,0.000000e+000,0,,0,
1524267278.106,,0.000000e+000,3.499950e+001,-8.282502e-008,0.000000e+000,2,0.000000e+000,0.000000e+000,,,,,,,,,,,,,,32,1,4.000000e+000,1.560211e-003,0.000000e+000,0,,0,
1524267316.154,,0.000000e+000,3.500028e+001,-2.121689e-008,0.000000e+000,2,0.000000e+000,0.000000e+000,,,,,,,,,,,,,,32,1,4.000000e+000,0.000000e+000,0.000000e+000,0,,0,
1524267353.627,,0.000000e+000,3.499872e+001,7.902795e-010,0.000000e+000,2,0.000000e+000,0.000000e+000,,,,,,,,,,,,,,32,1,4.000000e+000,1.560211e-003,0.000000e+000,0,,0,
1524267391.588,,0.000000e+000,3.499950e+001,-2.161014e-008,0.000000e+000,2,0.000000e+000,0.000000e+000,,,,,,,,,,,,,,32,1,4.000000e+000,1.560211e-003,0.000000e+000,0,,0,
1524267430.198,,0.000000e+000,3.499872e+001,-5.930834e-010,0.000000e+000,2,0.000000e+000,0.000000e+000,,,,,,,,,,,,,,32,1,4.000000e+000,1.560211e-003,0.000000e+000,0,,0,
1524267468.334,,0.000000e+000,3.499872e+001,3.852399e-008,0.000000e+000,2,0.000000e+000,0.000000e+000,,,,,,,,,,,,,,32,1,4.000000e+000,0.000000e+000,0.000000e+000,0,,0,
1524267506.444,,0.000000e+000,3.499950e+001,4.274752e-008,0.000000e+000,2,0.000000e+000,0.000000e+000,,,,,,,,,,,,,,32,1,4.000000e+000,0.000000e+000,0.000000e+000,0,,0,
1524267544.610,,0.000000e+000,3.499950e+001,7.365756e-008,0.000000e+000,2,0.000000e+000,0.000000e+000,,,,,,,,,,,,,,32,1,4.000000e+000,0.000000e+000,0.000000e+000,0,,0,
1524267582.745,,0.000000e+000,3.499833e+001,8.157456e-008,0.000000e+000,2,0.000000e+000,0.000000e+000,,,,,,,,,,,,,,32,1,4.000000e+000,7.781982e-004,0.000000e+000,0,,0,
1524267620.958,,0.000000e+000,3.499950e+001,1.319141e-007,0.000000e+000,2,0.000000e+000,0.000000e+000,,,,,,,,,,,,,,32,1,4.000000e+000,0.000000e+000,0.000000e+000,0,,0,
1524267658.754,,0.000000e+000,3.499872e+001,1.144527e-007,0.000000e+000,2,0.000000e+000,0.000000e+000,,,,,,,,,,,,,,32,1,4.000000e+000,1.560211e-003,0.000000e+000,0,,0,
1524267696.672,,0.000000e+000,3.499872e+001,1.214610e-007,0.000000e+000,2,0.000000e+000,0.000000e+000,,,,,,,,,,,,,,32,1,4.000000e+000,1.560211e-003,0.000000e+000,0,,0,
1524267734.473,,0.000000e+000,3.499950e+001,1.584414e-007,0.000000e+000,2,0.000000e+000,0.000000e+000,,,,,,,,,,,,,,32,1,4.000000e+000,0.000000e+000,0.000000e+000,0,,0,
1524267771.898,,0.000000e+000,3.499950e+001,1.604908e-007,0.000000e+000,2,0.000000e+000,0.000000e+000,,,,,,,,,,,,,,32,1,4.000000e+000,0.000000e+000,0.000000e+000,0,,0,
1524267810.476,,0.000000e+000,3.500028e+001,1.231794e-007,0.000000e+000,2,0.000000e+000,0.000000e+000,,,,,,,,,,,,,,32,1,4.000000e+000,0.000000e+000,0.000000e+000,0,,0,
1524267848.054,,0.000000e+000,3.499950e+001,1.985565e-007,0.000000e+000,2,0.000000e+000,0.000000e+000,,,,,,,,,,,,,,32,1,4.000000e+000,0.000000e+000,0.000000e+000,0,,0,
1524267886.247,,0.000000e+000,3.499911e+001,1.665621e-007,0.000000e+000,2,0.000000e+000,0.000000e+000,,,,,,,,,,,,,,32,1,4.000000e+000,7.820129e-004,0.000000e+000,0,,0,
1524267924.838,,0.000000e+000,3.499911e+001,2.268584e-007,0.000000e+000,2,0.000000e+000,0.000000e+000,,,,,,,,,,,,,,32,1,4.000000e+000,7.820129e-004,0.000000e+000,0,,0,
1524267962.784,,0.000000e+000,3.499950e+001,2.639405e-007,0.000000e+000,2,0.000000e+000,0.000000e+000,,,,,,,,,,,,,,32,1,4.000000e+000,0.000000e+000,0.000000e+000,0,,0,
1524268000.814,,0.000000e+000,3.499989e+001,2.487571e-007,0.000000e+000,2,0.000000e+000,0.000000e+000,,,,,,,,,,,,,,32,1,4.000000e+000,7.781982e-004,0.000000e+000,0,,0,
1524268038.275,,0.000000e+000,3.499833e+001,2.391382e-007,0.000000e+000,2,0.000000e+000,0.000000e+000,,,,,,,,,,,,,,32,1,4.000000e+000,7.781982e-004,0.000000e+000,0,,0,
1524268076.865,,0.000000e+000,3.500145e+001,2.661654e-007,0.000000e+000,2,0.000000e+000,0.000000e+000,,,,,,,,,,,,,,32,1,4.000000e+000,2.349854e-003,0.000000e+000,0,,0,
1524268114.521,,0.000000e+000,3.499911e+001,2.665754e-007,0.000000e+000,2,0.000000e+000,0.000000e+000,,,,,,,,,,,,,,32,1,4.000000e+000,7.820129e-004,0.000000e+000,0,,0,
1524268152.404,,0.000000e+000,3.499950e+001,2.656407e-007,0.000000e+000,2,0.000000e+000,0.000000e+000,,,,,,,,,,,,,,32,1,4.000000e+000,0.000000e+000,0.000000e+000,0,,0,
1524268190.557,,0.000000e+000,3.499872e+001,2.943341e-007,0.000000e+000,2,0.000000e+000,0.000000e+000,,,,,,,,,,,,,,32,1,4.000000e+000,0.000000e+000,0.000000e+000,0,,0,
1524268227.797,,0.000000e+000,3.499872e+001,2.753538e-007,0.000000e+000,2,0.000000e+000,0.000000e+000,,,,,,,,,,,,,,32,1,4.000000e+000,1.560211e-003,0.000000e+000,0,,0,
1524268265.245,,0.000000e+000,3.499950e+001,3.339973e-007,0.000000e+000,2,0.000000e+000,0.000000e+000,,,,,,,,,,,,,,32,1,4.000000e+000,0.000000e+000,0.000000e+000,0,,0,
1524268303.183,,0.000000e+000,3.499950e+001,3.371814e-007,0.000000e+000,2,0.000000e+000,0.000000e+000,,,,,,,,,,,,,,32,1,4.000000e+000,0.000000e+000,0.000000e+000,0,,0,
1524268341.349,,0.000000e+000,3.499950e+001,3.724463e-007,0.000000e+000,2,0.000000e+000,0.000000e+000,,,,,,,,,,,,,,32,1,4.000000e+000,0.000000e+000,0.000000e+000,0,,0,
1524268379.577,,0.000000e+000,3.499793e+001,3.965845e-007,0.000000e+000,2,0.000000e+000,0.000000e+000,,,,,,,,,,,,,,32,1,4.000000e+000,1.567841e-003,0.000000e+000,0,,0,
1524268416.945,,0.000000e+000,3.499872e+001,3.930928e-007,0.000000e+000,2,0.000000e+000,0.000000e+000,,,,,,,,,,,,,,32,1,4.000000e+000,0.000000e+000,0.000000e+000,0,,0,
1524268454.706,,0.000000e+000,3.499833e+001,3.848210e-007,0.000000e+000,2,0.000000e+000,0.000000e+000,,,,,,,,,,,,,,32,1,4.000000e+000,2.349854e-003,0.000000e+000,0,,0,
1524268492.824,,0.000000e+000,3.500185e+001,3.997509e-007,0.000000e+000,2,0.000000e+000,0.000000e+000,,,,,,,,,,,,,,32,1,4.000000e+000,4.688263e-003,0.000000e+000,0,,0,
1524268530.899,,0.000000e+000,3.499911e+001,4.118834e-007,0.000000e+000,2,0.000000e+000,0.000000e+000,,,,,,,,,,,,,,32,1,4.000000e+000,7.820129e-004,0.000000e+000,0,,0,
1524268569.040,,0.000000e+000,3.499950e+001,4.466578e-007,0.000000e+000,2,0.000000e+000,0.000000e+000,,,,,,,,,,,,,,32,1,4.000000e+000,1.560211e-003,0.000000e+000,0,,0,
1524268606.820,,0.000000e+000,3.499911e+001,4.481511e-007,0.000000e+000,2,0.000000e+000,0.000000e+000,,,,,,,,,,,,,,32,1,4.000000e+000,7.820129e-004,0.000000e+000,0,,0,
1524268644.984,,0.000000e+000,3.499911e+001,4.612286e-007,0.000000e+000,2,0.000000e+000,0.000000e+000,,,,,,,,,,,,,,32,1,4.000000e+000,7.820129e-004,0.000000e+000,0,,0,
1524268682.887,,0.000000e+000,3.499989e+001,4.294401e-007,0.000000e+000,2,0.000000e+000,0.000000e+000,,,,,,,,,,,,,,32,1,4.000000e+000,7.781982e-004,0.000000e+000,0,,0,
1524268719.977,,0.000000e+000,3.499872e+001,4.347110e-007,0.000000e+000,2,0.000000e+000,0.000000e+000,,,,,,,,,,,,,,32,1,4.000000e+000,1.560211e-003,0.000000e+000,0,,0,
1524268758.118,,0.000000e+000,3.499950e+001,4.732310e-007,0.000000e+000,2,0.000000e+000,0.000000e+000,,,,,,,,,,,,,,32,1,4.000000e+000,0.000000e+000,0.000000e+000,0,,0,
1524268796.283,,0.000000e+000,3.499989e+001,5.387492e-007,0.000000e+000,2,0.000000e+000,0.000000e+000,,,,,,,,,,,,,,32,1,4.000000e+000,7.781982e-004,0.000000e+000,0,,0,
1524268834.394,,0.000000e+000,3.499950e+001,5.004189e-007,0.000000e+000,2,0.000000e+000,0.000000e+000,,,,,,,,,,,,,,32,1,4.000000e+000,0.000000e+000,0.000000e+000,0,,0,
1524268872.349,,0.000000e+000,3.499950e+001,5.387543e-007,0.000000e+000,2,0.000000e+000,0.000000e+000,,,,,,,,,,,,,,32,1,4.000000e+000,1.560211e-003,0.000000e+000,0,,0,
1524268909.685,,0.000000e+000,3.499950e+001,5.075645e-007,0.000000e+000,2,0.000000e+000,0.000000e+000,,,,,,,,,,,,,,32,1,4.000000e+000,0.000000e+000,0.000000e+000,0,,0,
1524268946.610,,0.000000e+000,3.499715e+001,5.719615e-007,0.000000e+000,2,0.000000e+000,0.000000e+000,,,,,,,,,,,,,,32,1,4.000000e+000,4.692078e-003,0.000000e+000,0,,0,
1524268984.406,,0.000000e+000,3.499833e+001,5.852275e-007,0.000000e+000,2,0.000000e+000,0.000000e+000,,,,,,,,,,,,,,32,1,4.000000e+000,7.781982e-004,0.000000e+000,0,,0,
1524269022.952,,0.000000e+000,3.499833e+001,5.633971e-007,0.000000e+000,2,0.000000e+000,0.000000e+000,,,,,,,,,,,,,,32,1,4.000000e+000,2.349854e-003,0.000000e+000,0,,0,
1524269060.307,,0.000000e+000,3.499989e+001,5.590423e-007,0.000000e+000,2,0.000000e+000,0.000000e+000,,,,,,,,,,,,,,32,1,4.000000e+000,7.781982e-004,0.000000e+000,0,,0,
1524269098.168,,0.000000e+000,3.499950e+001,5.543930e-007,0.000000e+000,2,0.000000e+000,0.000000e+000,,,,,,,,,,,,,,32,1,4.000000e+000,0.000000e+000,0.000000e+000,0,,0,
1524269135.888,,0.000000e+000,3.499950e+001,6.000319e-007,0.000000e+000,2,0.000000e+000,0.000000e+000,,,,,,,,,,,,,,32,1,4.000000e+000,0.000000e+000,0.000000e+000,0,,0,
1524269173.879,,0.000000e+000,3.499989e+001,5.815879e-007,0.000000e+000,2,0.000000e+000,0.000000e+000,,,,,,,,,,,,,,32,1,4.000000e+000,2.342224e-003,0.000000e+000,0,,0,
1524269212.027,,0.000000e+000,3.499911e+001,5.925813e-007,0.000000e+000,2,0.000000e+000,0.000000e+000,,,,,,,,,,,,,,32,1,4.000000e+000,7.820129e-004,0.000000e+000,0,,0,
1524269250.715,,0.000000e+000,3.499950e+001,5.977550e-007,0.000000e+000,2,0.000000e+000,0.000000e+000,,,,,,,,,,,,,,32,1,4.000000e+000,0.000000e+000,0.000000e+000,0,,0,
1524269287.765,,0.000000e+000,3.499989e+001,6.084249e-007,0.000000e+000,2,0.000000e+000,0.000000e+000,,,,,,,,,,,,,,32,1,4.000000e+000,7.781982e-004,0.000000e+000,0,,0,
1524269325.871,,0.000000e+000,3.499950e+001,6.244078e-007,0.000000e+000,2,0.000000e+000,0.000000e+000,,,,,,,,,,,,,,32,1,4.000000e+000,0.000000e+000,0.000000e+000,0,,0,
1524269364.024,,0.000000e+000,3.499872e+001,6.430034e-007,0.000000e+000,2,0.000000e+000,0.000000e+000,,,,,,,,,,,,,,32,1,4.000000e+000,0.000000e+000,0.000000e+000,0,,0,
1524269402.127,,0.000000e+000,3.499950e+001,6.198555e-007,0.000000e+000,2,0.000000e+000,0.000000e+000,,,,,,,,,,,,,,32,1,4.000000e+000,0.000000e+000,0.000000e+000,0,,0,
1524269440.285,,0.000000e+000,3.499911e+001,6.632638e-007,0.000000e+000,2,0.000000e+000,0.000000e+000,,,,,,,,,,,,,,32,1,4.000000e+000,7.820129e-004,0.000000e+000,0,,0,
1524269478.421,,0.000000e+000,3.499950e+001,6.583346e-007,0.000000e+000,2,0.000000e+000,0.000000e+000,,,,,,,,,,,,,,32,1,4.000000e+000,0.000000e+000,0.000000e+000,0,,0,
1524269516.551,,0.000000e+000,3.499872e+001,6.665688e-007,0.000000e+000,2,0.000000e+000,0.000000e+000,,,,,,,,,,,,,,32,1,4.000000e+000,1.560211e-003,0.000000e+000,0,,0,
1524269554.664,,0.000000e+000,3.499872e+001,6.973199e-007,0.000000e+000,2,0.000000e+000,0.000000e+000,,,,,,,,,,,,,,32,1,4.000000e+000,0.000000e+000,0.000000e+000,0,,0,
1524269592.805,,0.000000e+000,3.499911e+001,6.995782e-007,0.000000e+000,2,0.000000e+000,0.000000e+000,,,,,,,,,,,,,,32,1,4.000000e+000,7.820129e-004,0.000000e+000,0,,0,
1524269630.913,,0.000000e+000,3.499911e+001,6.703650e-007,0.000000e+000,2,0.000000e+000,0.000000e+000,,,,,,,,,,,,,,32,1,4.000000e+000,7.820129e-004,0.000000e+000,0,,0,
1524269669.066,,0.000000e+000,3.499950e+001,6.993015e-007,0.000000e+000,2,0.000000e+000,0.000000e+000,,,,,,,,,,,,,,32,1,4.000000e+000,0.000000e+000,0.000000e+000,0,,0,
1524269707.404,,0.000000e+000,3.499989e+001,7.151455e-007,0.000000e+000,2,0.000000e+000,0.000000e+000,,,,,,,,,,,,,,32,1,4.000000e+000,7.781982e-004,0.000000e+000,0,,0,
1524269745.335,,0.000000e+000,3.499950e+001,7.257368e-007,0.000000e+000,2,0.000000e+000,0.000000e+000,,,,,,,,,,,,,,32,1,4.000000e+000,0.000000e+000,0.000000e+000,0,,0,
1524269783.468,,0.000000e+000,3.499911e+001,7.614142e-007,0.000000e+000,2,0.000000e+000,0.000000e+000,,,,,,,,,,,,,,32,1,4.000000e+000,7.820129e-004,0.000000e+000,0,,0,
1524269821.596,,0.000000e+000,3.499950e+001,7.471539e-007,0.000000e+000,2,0.000000e+000,0.000000e+000,,,,,,,,,,,,,,32,1,4.000000e+000,0.000000e+000,0.000000e+000,0,,0,
1524269859.726,,0.000000e+000,3.499950e+001,7.400153e-007,0.000000e+000,2,0.000000e+000,0.000000e+000,,,,,,,,,,,,,,32,1,4.000000e+000,0.000000e+000,0.000000e+000,0,,0,
1524269897.872,,0.000000e+000,3.499989e+001,7.361483e-007,0.000000e+000,2,0.000000e+000,0.000000e+000,,,,,,,,,,,,,,32,1,4.000000e+000,7.781982e-004,0.000000e+000,0,,0,
1524269935.980,,0.000000e+000,3.499950e+001,7.573618e-007,0.000000e+000,2,0.000000e+000,0.000000e+000,,,,,,,,,,,,,,32,1,4.000000e+000,1.560211e-003,0.000000e+000,0,,0,
1524269974.086,,0.000000e+000,3.499872e+001,7.661052e-007,0.000000e+000,2,0.000000e+000,0.000000e+000,,,,,,,,,,,,,,32,1,4.000000e+000,0.000000e+000,0.000000e+000,0,,0,
1524270011.356,,0.000000e+000,3.499598e+001,7.676466e-007,0.000000e+000,2,0.000000e+000,0.000000e+000,,,,,,,,,,,,,,32,1,4.000000e+000,7.041931e-003,0.000000e+000,0,,0,
1524270049.689,,0.000000e+000,3.499872e+001,7.662690e-007,0.000000e+000,2,0.000000e+000,0.000000e+000,,,,,,,,,,,,,,32,1,4.000000e+000,0.000000e+000,0.000000e+000,0,,0,
1524270087.982,,0.000000e+000,3.500067e+001,7.905662e-007,0.000000e+000,2,0.000000e+000,0.000000e+000,,,,,,,,,,,,,,32,1,4.000000e+000,2.338409e-003,0.000000e+000,0,,0,
1524270125.828,,0.000000e+000,3.499793e+001,8.046599e-007,0.000000e+000,2,0.000000e+000,0.000000e+000,,,,,,,,,,,,,,32,1,4.000000e+000,1.567841e-003,0.000000e+000,0,,0,
1524270164.038,,0.000000e+000,3.499911e+001,8.245236e-007,0.000000e+000,2,0.000000e+000,0.000000e+000,,,,,,,,,,,,,,32,1,4.000000e+000,7.820129e-004,0.000000e+000,0,,0,
1524270202.114,,0.000000e+000,3.499911e+001,8.583978e-007,0.000000e+000,2,0.000000e+000,0.000000e+000,,,,,,,,,,,,,,32,1,4.000000e+000,7.820129e-004,0.000000e+000,0,,0,
1524270239.969,,0.000000e+000,3.499950e+001,8.594956e-007,0.000000e+000,2,0.000000e+000,0.000000e+000,,,,,,,,,,,,,,32,1,4.000000e+000,3.120422e-003,0.000000e+000,0,,0,
1524270278.125,,0.000000e+000,3.499872e+001,8.335566e-007,0.000000e+000,2,0.000000e+000,0.000000e+000,,,,,,,,,,,,,,32,1,4.000000e+000,0.000000e+000,0.000000e+000,0,,0,
1524270315.720,,0.000000e+000,3.499950e+001,8.252786e-007,0.000000e+000,2,0.000000e+000,0.000000e+000,,,,,,,,,,,,,,32,1,4.000000e+000,0.000000e+000,0.000000e+000,0,,0,
1524270353.786,,0.000000e+000,3.499872e+001,8.527542e-007,0.000000e+000,2,0.000000e+000,0.000000e+000,,,,,,,,,,,,,,32,1,4.000000e+000,1.560211e-003,0.000000e+000,0,,0,
1524270391.914,,0.000000e+000,3.499872e+001,8.662463e-007,0.000000e+000,2,0.000000e+000,0.000000e+000,,,,,,,,,,,,,,32,1,4.000000e+000,1.560211e-003,0.000000e+000,0,,0,
1524270430.047,,0.000000e+000,3.500106e+001,8.562635e-007,0.000000e+000,2,0.000000e+000,0.000000e+000,,,,,,,,,,,,,,32,1,4.000000e+000,3.128052e-003,0.000000e+000,0,,0,
1524270468.168,,0.000000e+000,3.499911e+001,8.814791e-007,0.000000e+000,2,0.000000e+000,0.000000e+000,,,,,,,,,,,,,,32,1,4.000000e+000,2.338409e-003,0.000000e+000,0,,0,
1524270506.313,,0.000000e+000,3.499911e+001,8.708890e-007,0.000000e+000,2,0.000000e+000,0.000000e+000,,,,,,,,,,,,,,32,1,4.000000e+000,7.820129e-004,0.000000e+000,0,,0,
1524270544.446,,0.000000e+000,3.499989e+001,8.987718e-007,0.000000e+000,2,0.000000e+000,0.000000e+000,,,,,,,,,,,,,,32,1,4.000000e+000,7.781982e-004,0.000000e+000,0,,0,
1524270582.562,,0.000000e+000,3.499911e+001,9.077610e-007,0.000000e+000,2,0.000000e+000,0.000000e+000,,,,,,,,,,,,,,32,1,4.000000e+000,7.820129e-004,0.000000e+000,0,,0,
1524270620.650,,0.000000e+000,3.499950e+001,9.101136e-007,0.000000e+000,2,0.000000e+000,0.000000e+000,,,,,,,,,,,,,,32,1,4.000000e+000,1.560211e-003,0.000000e+000,0,,0,
1524270658.483,,0.000000e+000,3.499911e+001,9.062180e-007,0.000000e+000,2,0.000000e+000,0.000000e+000,,,,,,,,,,,,,,32,1,4.000000e+000,7.820129e-004,0.000000e+000,0,,0,
1524270697.599,,0.000000e+000,3.499911e+001,8.846072e-007,0.000000e+000,2,0.000000e+000,0.000000e+000,,,,,,,,,,,,,,32,1,4.000000e+000,7.820129e-004,0.000000e+000,0,,0,
1524270736.267,,0.000000e+000,3.499794e+001,9.148087e-007,0.000000e+000,2,0.000000e+000,0.000000e+000,,,,,,,,,,,,,,32,1,4.000000e+000,0.000000e+000,0.000000e+000,0,,0,
1524270773.465,,0.000000e+000,3.499872e+001,9.038009e-007,0.000000e+000,2,0.000000e+000,0.000000e+000,,,,,,,,,,,,,,32,1,4.000000e+000,0.000000e+000,0.000000e+000,0,,0,
1524270812.050,,0.000000e+000,3.499872e+001,9.209807e-007,0.000000e+000,2,0.000000e+000,0.000000e+000,,,,,,,,,,,,,,32,1,4.000000e+000,0.000000e+000,0.000000e+000,0,,0,
1524270850.036,,0.000000e+000,3.499911e+001,9.204435e-007,0.000000e+000,2,0.000000e+000,0.000000e+000,,,,,,,,,,,,,,32,1,4.000000e+000,7.820129e-004,0.000000e+000,0,,0,
1524270888.286,,0.000000e+000,3.499911e+001,9.476591e-007,0.000000e+000,2,1.113066e-002,0.000000e+000,,,,,,,,,,,,,,32,1,4.000000e+000,7.820129e-004,0.000000e+000,0,,0,
1524270926.697,,0.000000e+000,3.500145e+001,9.672957e-007,0.000000e+000,2,0.000000e+000,0.000000e+000,,,,,,,,,,,,,,32,1,4.000000e+000,5.470276e-003,0.000000e+000,0,,0,
1524270964.875,,0.000000e+000,3.499911e+001,9.592382e-007,0.000000e+000,2,4.726388e-003,0.000000e+000,,,,,,,,,,,,,,32,1,4.000000e+000,7.820129e-004,0.000000e+000,0,,0,
1524271003.036,,0.000000e+000,3.499872e+001,1.016311e-006,0.000000e+000,2,6.361201e-002,0.000000e+000,,,,,,,,,,,,,,32,1,4.000000e+000,1.560211e-003,0.000000e+000,0,,0,
1524271041.149,,0.000000e+000,3.499872e+001,9.371275e-007,0.000000e+000,2,0.000000e+000,0.000000e+000,,,,,,,,,,,,,,32,1,4.000000e+000,1.560211e-003,0.000000e+000,0,,0,
1524271079.247,,0.000000e+000,3.499950e+001,9.750942e-007,0.000000e+000,2,1.951186e-002,0.000000e+000,,,,,,,,,,,,,,32,1,4.000000e+000,0.000000e+000,0.000000e+000,0,,0,
1524271117.392,,0.000000e+000,3.499911e+001,9.645516e-007,0.000000e+000,2,9.273676e-004,0.000000e+000,,,,,,,,,,,,,,32,1,4.000000e+000,2.338409e-003,0.000000e+000,0,,0,
1524271155.498,,0.000000e+000,3.499950e+001,9.841511e-007,0.000000e+000,2,2.540314e-002,0.000000e+000,,,,,,,,,,,,,,32,1,4.000000e+000,0.000000e+000,0.000000e+000,0,,0,
1524271193.683,,0.000000e+000,3.499911e+001,1.016487e-006,0.000000e+000,2,7.344055e-002,0.000000e+000,,,,,,,,,,,,,,32,1,4.000000e+000,7.820129e-004,0.000000e+000,0,,0,
1524271231.761,,0.000000e+000,3.499872e+001,1.016975e-006,0.000000e+000,2,5.926987e-002,0.000000e+000,,,,,,,,,,,,,,32,1,4.000000e+000,1.560211e-003,0.000000e+000,0,,0,
1524271269.890,,0.000000e+000,3.499911e+001,9.883914e-007,0.000000e+000,2,2.989081e-002,0.000000e+000,,,,,,,,,,,,,,32,1,4.000000e+000,7.820129e-004,0.000000e+000,0,,0,
1524271308.050,,0.000000e+000,3.499793e+001,1.006081e-006,0.000000e+000,2,5.510025e-002,0.000000e+000,,,,,,,,,,,,,,32,1,4.000000e+000,3.131866e-003,0.000000e+000,0,,0,
1524271345.623,,0.000000e+000,3.500106e+001,1.027027e-006,0.000000e+000,2,5.264788e-002,0.000000e+000,,,,,,,,,,,,,,32,1,4.000000e+000,1.560211e-003,0.000000e+000,0,,0,
1524271383.674,,0.000000e+000,3.499872e+001,1.037046e-006,0.000000e+000,2,6.455235e-002,0.000000e+000,,,,,,,,,,,,,,32,1,4.000000e+000,0.000000e+000,0.000000e+000,0,,0,
1524271421.582,,0.000000e+000,3.499833e+001,1.057289e-006,0.000000e+000,2,7.670327e-002,0.000000e+000,,,,,,,,,,,,,,32,1,4.000000e+000,7.781982e-004,0.000000e+000,0,,0,
1524271459.837,,0.000000e+000,3.499872e+001,1.024923e-006,0.000000e+000,2,5.826213e-002,0.000000e+000,,,,,,,,,,,,,,32,1,4.000000e+000,1.560211e-003,0.000000e+000,0,,0,
1524271497.883,,0.000000e+000,3.499989e+001,1.057374e-006,0.000000e+000,2,1.120564e-001,0.000000e+000,,,,,,,,,,,,,,32,1,4.000000e+000,7.781982e-004,0.000000e+000,0,,0,
1524271536.271,,0.000000e+000,3.499872e+001,1.053656e-006,0.000000e+000,2,8.099354e-002,0.000000e+000,,,,,,,,,,,,,,32,1,4.000000e+000,1.560211e-003,0.000000e+000,0,,0,
1524271573.609,,0.000000e+000,3.499833e+001,1.043877e-006,0.000000e+000,2,7.672608e-002,0.000000e+000,,,,,,,,,,,,,,32,1,4.000000e+000,7.781982e-004,0.000000e+000,0,,0,
1524271611.474,,0.000000e+000,3.499872e+001,1.116986e-006,0.000000e+000,2,1.277708e-001,0.000000e+000,,,,,,,,,,,,,,32,1,4.000000e+000,0.000000e+000,0.000000e+000,0,,0,
1524271649.068,,0.000000e+000,3.499793e+001,1.077054e-006,0.000000e+000,2,9.666176e-002,0.000000e+000,,,,,,,,,,,,,,32,1,4.000000e+000,1.567841e-003,0.000000e+000,0,,0,
1524271687.706,,0.000000e+000,3.499872e+001,1.063994e-006,0.000000e+000,2,9.919982e-002,0.000000e+000,,,,,,,,,,,,,,32,1,4.000000e+000,0.000000e+000,0.000000e+000,0,,0,
1524271725.801,,0.000000e+000,3.499911e+001,1.056596e-006,0.000000e+000,2,9.411281e-002,0.000000e+000,,,,,,,,,,,,,,32,1,4.000000e+000,7.820129e-004,0.000000e+000,0,,0,
1524271763.357,,0.000000e+000,3.499911e+001,1.086360e-006,0.000000e+000,2,1.180591e-001,0.000000e+000,,,,,,,,,,,,,,32,1,4.000000e+000,7.820129e-004,0.000000e+000,0,,0,
1524271801.120,,0.000000e+000,3.499833e+001,1.056625e-006,0.000000e+000,2,9.697426e-002,0.000000e+000,,,,,,,,,,,,,,32,1,4.000000e+000,7.781982e-004,0.000000e+000,0,,0,
1524271839.083,,0.000000e+000,3.499911e+001,1.091454e-006,0.000000e+000,2,1.137379e-001,0.000000e+000,,,,,,,,,,,,,,32,1,4.000000e+000,7.820129e-004,0.000000e+000,0,,0,
1524271877.191,,0.000000e+000,3.499950e+001,1.064380e-006,0.000000e+000,2,9.872986e-002,0.000000e+000,,,,,,,,,,,,,,32,1,4.000000e+000,1.560211e-003,0.000000e+000,0,,0,
1524271915.326,,0.000000e+000,3.499950e+001,1.048542e-006,0.000000e+000,2,7.872038e-002,0.000000e+000,,,,,,,,,,,,,,32,1,4.000000e+000,0.000000e+000,0.000000e+000,0,,0,
1524271952.965,,0.000000e+000,3.499950e+001,1.101395e-006,0.000000e+000,2,1.232869e-001,0.000000e+000,,,,,,,,,,,,,,32,1,4.000000e+000,0.000000e+000,0.000000e+000,0,,0,
1524271991.068,,0.000000e+000,3.499833e+001,1.131245e-006,0.000000e+000,2,1.584408e-001,0.000000e+000,,,,,,,,,,,,,,32,1,4.000000e+000,2.349854e-003,0.000000e+000,0,,0,
1524272028.811,,0.000000e+000,3.499911e+001,1.141059e-006,0.000000e+000,2,1.566547e-001,0.000000e+000,,,,,,,,,,,,,,32,1,4.000000e+000,7.820129e-004,0.000000e+000,0,,0,
1524272066.774,,0.000000e+000,3.499833e+001,1.132104e-006,0.000000e+000,2,1.504380e-001,0.000000e+000,,,,,,,,,,,,,,32,1,4.000000e+000,2.349854e-003,0.000000e+000,0,,0,
1524272105.172,,0.000000e+000,3.499715e+001,1.179065e-006,0.000000e+000,2,1.995470e-001,0.000000e+000,,,,,,,,,,,,,,32,1,4.000000e+000,1.571655e-003,0.000000e+000,0,,0,
1524272143.320,,0.000000e+000,3.499911e+001,1.153888e-006,0.000000e+000,2,1.556952e-001,0.000000e+000,,,,,,,,,,,,,,32,1,4.000000e+000,2.338409e-003,0.000000e+000,0,,0,
1524272181.423,,0.000000e+000,3.499989e+001,1.164398e-006,0.000000e+000,2,1.585143e-001,0.000000e+000,,,,,,,,,,,,,,32,1,4.000000e+000,3.898621e-003,0.000000e+000,0,,0,
1524272219.411,,0.000000e+000,3.499833e+001,1.131168e-006,0.000000e+000,2,1.518593e-001,0.000000e+000,,,,,,,,,,,,,,32,1,4.000000e+000,7.781982e-004,0.000000e+000,0,,0,
1524272257.389,,0.000000e+000,3.499950e+001,1.156301e-006,0.000000e+000,2,1.682473e-001,0.000000e+000,,,,,,,,,,,,,,32,1,4.000000e+000,1.560211e-003,0.000000e+000,0,,0,
1524272295.635,,0.000000e+000,3.499911e+001,1.204933e-006,0.000000e+000,2,1.944186e-001,0.000000e+000,,,,,,,,,,,,,,32,1,4.000000e+000,7.820129e-004,0.000000e+000,0,,0,
1524272334.203,,0.000000e+000,3.500028e+001,1.163190e-006,0.000000e+000,2,1.978074e-001,0.000000e+000,,,,,,,,,,,,,,32,1,4.000000e+000,1.560211e-003,0.000000e+000,0,,0,
1524272372.496,,0.000000e+000,3.499911e+001,1.165057e-006,0.000000e+000,2,1.798917e-001,0.000000e+000,,,,,,,,,,,,,,32,1,4.000000e+000,7.820129e-004,0.000000e+000,0,,0,
1524272411.189,,0.000000e+000,3.499950e+001,1.191881e-006,0.000000e+000,2,1.958548e-001,0.000000e+000,,,,,,,,,,,,,,32,1,4.000000e+000,0.000000e+000,0.000000e+000,0,,0,
1524272448.904,,0.000000e+000,3.499989e+001,1.183464e-006,0.000000e+000,2,1.753607e-001,0.000000e+000,,,,,,,,,,,,,,32,1,4.000000e+000,2.342224e-003,0.000000e+000,0,,0,
1524272486.652,,0.000000e+000,3.499911e+001,1.143558e-006,0.000000e+000,2,1.845093e-001,0.000000e+000,,,,,,,,,,,,,,32,1,4.000000e+000,7.820129e-004,0.000000e+000,0,,0,
1524272525.268,,0.000000e+000,3.499950e+001,1.188232e-006,0.000000e+000,2,1.882491e-001,0.000000e+000,,,,,,,,,,,,,,32,1,4.000000e+000,0.000000e+000,0.000000e+000,0,,0,
1524272563.401,,0.000000e+000,3.499950e+001,1.190452e-006,0.000000e+000,2,1.798721e-001,0.000000e+000,,,,,,,,,,,,,,32,1,4.000000e+000,1.560211e-003,0.000000e+000,0,,0,
1524272601.524,,0.000000e+000,3.499950e+001,1.187775e-006,0.000000e+000,2,1.905068e-001,0.000000e+000,,,,,,,,,,,,,,32,1,4.000000e+000,0.000000e+000,0.000000e+000,0,,0,
1524272639.655,,0.000000e+000,3.499950e+001,1.223723e-006,0.000000e+000,2,2.056032e-001,0.000000e+000,,,,,,,,,,,,,,32,1,4.000000e+000,1.560211e-003,0.000000e+000,0,,0,
1524272678.445,,0.000000e+000,3.499989e+001,1.197585e-006,0.000000e+000,2,1.999399e-001,0.000000e+000,,,,,,,,,,,,,,32,1,4.000000e+000,7.781982e-004,0.000000e+000,0,,0,
1524272716.708,,0.000000e+000,3.499989e+001,1.196013e-006,0.000000e+000,2,2.079266e-001,0.000000e+000,,,,,,,,,,,,,,32,1,4.000000e+000,7.781982e-004,0.000000e+000,0,,0,
1524272754.834,,0.000000e+000,3.499911e+001,1.189615e-006,0.000000e+000,2,1.833362e-001,0.000000e+000,,,,,,,,,,,,,,32,1,4.000000e+000,7.820129e-004,0.000000e+000,0,,0,
1524272792.954,,0.000000e+000,3.499989e+001,1.240542e-006,0.000000e+000,2,2.368349e-001,0.000000e+000,,,,,,,,,,,,,,32,1,4.000000e+000,7.781982e-004,0.000000e+000,0,,0,
1524272831.100,,0.000000e+000,3.499911e+001,1.225125e-006,0.000000e+000,2,2.160427e-001,0.000000e+000,,,,,,,,,,,,,,32,1,4.000000e+000,7.820129e-004,0.000000e+000,0,,0,
1524272869.698,,0.000000e+000,3.499872e+001,1.229905e-006,0.000000e+000,2,2.233564e-001,0.000000e+000,,,,,,,,,,,,,,32,1,4.000000e+000,0.000000e+000,0.000000e+000,0,,0,
1524272907.839,,0.000000e+000,3.499989e+001,1.232049e-006,0.000000e+000,2,2.264172e-001,0.000000e+000,,,,,,,,,,,,,,32,1,4.000000e+000,7.781982e-004,0.000000e+000,0,,0,
1524272946.019,,0.000000e+000,3.500106e+001,1.265567e-006,0.000000e+000,2,2.316189e-001,0.000000e+000,,,,,,,,,,,,,,32,1,4.000000e+000,3.128052e-003,0.000000e+000,0,,0,
1524272983.837,,0.000000e+000,3.499950e+001,1.263955e-006,0.000000e+000,2,2.361506e-001,0.000000e+000,,,,,,,,,,,,,,32,1,4.000000e+000,0.000000e+000,0.000000e+000,0,,0,
1524273021.678,,0.000000e+000,3.499872e+001,1.245946e-006,0.000000e+000,2,2.294442e-001,0.000000e+000,,,,,,,,,,,,,,32,1,4.000000e+000,0.000000e+000,0.000000e+000,0,,0,
1524273059.373,,0.000000e+000,3.499793e+001,1.232412e-006,0.000000e+000,2,2.402418e-001,0.000000e+000,,,,,,,,,,,,,,32,1,4.000000e+000,3.131866e-003,0.000000e+000,0,,0,
1524273097.394,,0.000000e+000,3.499872e+001,1.213188e-006,0.000000e+000,2,2.202731e-001,0.000000e+000,,,,,,,,,,,,,,32,1,4.000000e+000,1.560211e-003,0.000000e+000,0,,0,
1524273135.612,,0.000000e+000,3.499872e+001,1.236377e-006,0.000000e+000,2,2.198614e-001,0.000000e+000,,,,,,,,,,,,,,32,1,4.000000e+000,0.000000e+000,0.000000e+000,0,,0,
1524273173.742,,0.000000e+000,3.499911e+001,1.257831e-006,0.000000e+000,2,2.246522e-001,0.000000e+000,,,,,,,,,,,,,,32,1,4.000000e+000,7.820129e-004,0.000000e+000,0,,0,
1524273212.143,,0.000000e+000,3.499950e+001,1.300669e-006,0.000000e+000,2,2.534754e-001,0.000000e+000,,,,,,,,,,,,,,32,1,4.000000e+000,1.560211e-003,0.000000e+000,0,,0,
1524273250.189,,0.000000e+000,3.499754e+001,1.279644e-006,0.000000e+000,2,2.509061e-001,0.000000e+000,,,,,,,,,,,,,,32,1,4.000000e+000,3.910065e-003,0.000000e+000,0,,0,
1524273288.119,,0.000000e+000,3.499950e+001,1.279931e-006,0.000000e+000,2,2.325153e-001,0.000000e+000,,,,,,,,,,,,,,32,1,4.000000e+000,0.000000e+000,0.000000e+000,0,,0,
1524273325.662,,0.000000e+000,3.499872e+001,1.282047e-006,0.000000e+000,2,2.535614e-001,0.000000e+000,,,,,,,,,,,,,,32,1,4.000000e+000,1.560211e-003,0.000000e+000,0,,0,
1524273363.778,,0.000000e+000,3.499911e+001,1.298614e-006,0.000000e+000,2,2.441477e-001,0.000000e+000,,,,,,,,,,,,,,32,1,4.000000e+000,7.820129e-004,0.000000e+000,0,,0,
1524273401.376,,0.000000e+000,3.500028e+001,1.272046e-006,0.000000e+000,2,2.608761e-001,0.000000e+000,,,,,,,,,,,,,,32,1,4.000000e+000,1.560211e-003,0.000000e+000,0,,0,
1524273439.754,,0.000000e+000,3.499950e+001,1.295090e-006,0.000000e+000,2,2.612724e-001,0.000000e+000,,,,,,,,,,,,,,32,1,4.000000e+000,0.000000e+000,0.000000e+000,0,,0,
1524273477.117,,0.000000e+000,3.500028e+001,1.299176e-006,0.000000e+000,2,2.706105e-001,0.000000e+000,,,,,,,,,,,,,,32,1,4.000000e+000,1.560211e-003,0.000000e+000,0,,0,
1524273515.295,,0.000000e+000,3.499911e+001,1.279076e-006,0.000000e+000,2,2.553854e-001,0.000000e+000,,,,,,,,,,,,,,32,1,4.000000e+000,7.820129e-004,0.000000e+000,0,,0,
1524273553.703,,0.000000e+000,3.499950e+001,1.304493e-006,0.000000e+000,2,2.419125e-001,0.000000e+000,,,,,,,,,,,,,,32,1,4.000000e+000,1.560211e-003,0.000000e+000,0,,0,
1524273591.854,,0.000000e+000,3.499911e+001,1.333574e-006,0.000000e+000,2,2.747115e-001,0.000000e+000,,,,,,,,,,,,,,32,1,4.000000e+000,7.820129e-004,0.000000e+000,0,,0,
1524273629.267,,0.000000e+000,3.499871e+001,1.313076e-006,0.000000e+000,2,2.507871e-001,0.000000e+000,,,,,,,,,,,,,,32,1,4.000000e+000,3.128052e-003,0.000000e+000,0,,0,
1524273667.280,,0.000000e+000,3.500067e+001,1.316971e-006,0.000000e+000,2,2.739117e-001,0.000000e+000,,,,,,,,,,,,,,32,1,4.000000e+000,3.910065e-003,0.000000e+000,0,,0,
1524273705.400,,0.000000e+000,3.499911e+001,1.341878e-006,0.000000e+000,2,3.057469e-001,0.000000e+000,,,,,,,,,,,,,,32,1,4.000000e+000,7.820129e-004,0.000000e+000,0,,0,
1524273743.538,,0.000000e+000,3.499911e+001,1.288485e-006,0.000000e+000,2,2.740106e-001,0.000000e+000,,,,,,,,,,,,,,32,1,4.000000e+000,7.820129e-004,0.000000e+000,0,,0,
1524273781.571,,0.000000e+000,3.499911e+001,1.272183e-006,0.000000e+000,2,2.458577e-001,0.000000e+000,,,,,,,,,,,,,,32,1,4.000000e+000,2.338409e-003,0.000000e+000,0,,0,
1524273820.022,,0.000000e+000,3.500028e+001,1.291544e-006,0.000000e+000,2,2.612244e-001,0.000000e+000,,,,,,,,,,,,,,32,1,4.000000e+000,3.120422e-003,0.000000e+000,0,,0,
1524273858.192,,0.000000e+000,3.500106e+001,1.353184e-006,0.000000e+000,2,2.857760e-001,0.000000e+000,,,,,,,,,,,,,,32,1,4.000000e+000,1.560211e-003,0.000000e+000,0,,0,
1524273896.218,,0.000000e+000,3.499872e+001,1.319545e-006,0.000000e+000,2,2.728613e-001,0.000000e+000,,,,,,,,,,,,,,32,1,4.000000e+000,1.560211e-003,0.000000e+000,0,,0,
1524273934.349,,0.000000e+000,3.499793e+001,1.328764e-006,0.000000e+000,2,2.751714e-001,0.000000e+000,,,,,,,,,,,,,,32,1,4.000000e+000,3.131866e-003,0.000000e+000,0,,0,
1524273959.751,,0.000000e+000,3.499833e+001,1.350581e-006,0.000000e+000,2,2.801284e-001,0.000000e+000,,,,,,,,,,,,,,32,1,4.000000e+000,7.781982e-004,0.000000e+000,0,,0,