File: Input/MFn1_VRMac_35K_6000s_VRMde_35K.dc.dat
[Header]
TITLE,MPMS DC Measurement
BYAPP,MPMS Measurement,2.1,Summary
FILEOPENTIME, 1524023750.372000 4/17/2018, 9:55:50 PM

INFO, APPNAME, MPMS MultiVu Application, Revision 1.61,  Build 082

INFO, NAME, MFn1
INFO, WEIGHT, 1.000
INFO, AREA, 1.000
INFO, LENGTH, 1.000
INFO, SHAPE, 0
INFO, COMMENT,
INFO, SEQUENCE FILE: VRMac_35K_6000s_VRMde_35K.seq


INFO, BACKGROUND DATA FILE:, None


STARTUPAXIS,X,4,LINEAR,AUTO,0.000000,0.000000
STARTUPAXIS,Y1,5,LINEAR,AUTO,0.000000,0.000000


STARTUPGROUP,Longitudinal
FIELDGROUP,Longitudinal,1,2,3,4,5,6,7,8,9,15,16,17,18,27,28
FIELDGROUP,Transverse,1,2,3,4,10,11,12,13,14,19,20,21,22,27,28

PLOT_APPEARANCE,ALL,HORZ_GRID_ON,VERT_GRID_ON,MARKERS_AND_LINES

[Data]
Time,Comment,Field (Oe),Temperature (K),Long Moment (emu),Long Scan Std Dev,Long Algorithm,Long Reg Fit,Long Percent Error (%),Trans Moment (emu),Trans Scan Std Dev,Trans Algorithm,Trans Reg Fit,Trans Percent Error (%),Long Moment [w/o ABS] (emu),Long Scan Std Dev [w/o ABS],Long Reg Fit [w/o ABS],Long Percent Error [w/o ABS] (%),Trans Moment [w/o ABS] (emu),Trans Scan Std Dev [w/o ABS],Trans Reg Fit [w/o ABS],Trans Percent Error [w/o ABS] (%),Points per Scan,Scans per Measurement,Scan Length (cm),Delta Temp (K),Rot Position (deg),Error,EC Comp. Running,Using ABS,
1524023750.355,,0.000000e+000,3.499911e+001,-2.347682e-005,0.000000e+000,3,9.628077e-001,0.000000e+000,,,,,,,,,,,,,,32,1,4.000000e+000,7.820129e-004,0.000000e+000,0,,0,
1524023788.408,,0.000000e+000,3.499950e+001,-2.011695e-005,0.000000e+000,3,9.538566e-001,0.000000e+000,,,,,,,,,,,,,,32,1,4.000000e+000,0.000000e+000,0.000000e+000,0,,0,
1524023826.459,,0.000000e+000,3.500028e+001,-1.822899e-005,0.000000e+000,3,9.489046e-001,0.000000e+000,,,,,,,,,,,,,,32,1,4.000000e+000,0.000000e+000,0.000000e+000,0,,0,
1524023864.404,,0.000000e+000,3.500067e+001,-1.685607e-005,0.000000e+000,3,9.459652e-001,0.000000e+000,,,,,,,,,,,,,,32,1,4.000000e+000,7.820129e-004,0.000000e+000,0,,0,
1524023902.525,,0.000000e+000,3.500028e+001,-1.583997e-005,0.000000e+000,3,9.424992e-001,0.000000e+000,,,,,,,,,,,,,,32,1,4.000000e+000,1.560211e-003,0.000000e+000,0,,0,
1524023940.560,,0.000000e+000,3.499911e+001,-1.505106e-005,0.000000e+000,3,9.408463e-001,0.000000e+000,,,,,,,,,,,,,,32,1,4.000000e+000,7.820129e-004,0.000000e+000,0,,0,
1524023979.313,,0.000000e+000,3.499872e+001,-1.421155e-005,0.000000e+000,3,9.346473e-001,0.000000e+000,,,,,,,,,,,,,,32,1,4.000000e+000,0.000000e+000,0.000000e+000,0,,0,
1524024017.481,,0.000000e+000,3.499950e+001,-1.370178e-005,0.000000e+000,3,9.342487e-001,0.000000e+000,,,,,,,,,,,,,,32,1,4.000000e+000,1.560211e-003,0.000000e+000,0,,0,
1524024055.477,,0.000000e+000,3.499989e+001,-1.314930e-005,0.000000e+000,3,9.311346e-001,0.000000e+000,,,,,,,,,,,,,,32,1,4.000000e+000,7.781982e-004,0.000000e+000,0,,0,
1524024093.525,,0.000000e+000,3.499911e+001,-1.268142e-005,0.000000e+000,3,9.286267e-001,0.000000e+000,,,,,,,,,,,,,,32,1,4.000000e+000,7.820129e-004,0.000000e+000,0,,0,
1524024131.586,,0.000000e+000,3.499911e+001,-1.227634e-005,0.000000e+000,3,9.275006e-001,0.000000e+000,,,,,,,,,,,,,,32,1,4.000000e+000,7.820129e-004,0.000000e+000,0,,0,
1524024169.661,,0.000000e+000,3.499911e+001,-1.189460e-005,0.000000e+000,3,9.229772e-001,0.000000e+000,,,,,,,,,,,,,,32,1,4.000000e+000,7.820129e-004,0.000000e+000,0,,0,
1524024207.782,,0.000000e+000,3.499989e+001,-1.160124e-005,0.000000e+000,3,9.203452e-001,0.000000e+000,,,,,,,,,,,,,,32,1,4.000000e+000,7.781982e-004,0.000000e+000,0,,0,
1524024245.760,,0.000000e+000,3.499911e+001,-1.118188e-005,0.000000e+000,3,9.185295e-001,0.000000e+000,,,,,,,,,,,,,,32,1,4.000000e+000,7.820129e-004,0.000000e+000,0,,0,
1524024283.905,,0.000000e+000,3.499950e+001,-1.088934e-005,0.000000e+000,3,9.157095e-001,0.000000e+000,,,,,,,,,,,,,,32,1,4.000000e+000,1.560211e-003,0.000000e+000,0,,0,
1524024321.896,,0.000000e+000,3.499950e+001,-1.059102e-005,0.000000e+000,3,9.163120e-001,0.000000e+000,,,,,,,,,,,,,,32,1,4.000000e+000,1.560211e-003,0.000000e+000,0,,0,
1524024360.239,,0.000000e+000,3.499911e+001,-1.031672e-005,0.000000e+000,3,9.137064e-001,0.000000e+000,,,,,,,,,,,,,,32,1,4.000000e+000,7.820129e-004,0.000000e+000,0,,0,
1524024397.569,,0.000000e+000,3.500028e+001,-1.015216e-005,0.000000e+000,3,9.111194e-001,0.000000e+000,,,,,,,,,,,,,,32,1,4.000000e+000,1.560211e-003,0.000000e+000,0,,0,
1524024435.622,,0.000000e+000,3.499911e+001,-9.918160e-006,0.000000e+000,3,9.087514e-001,0.000000e+000,,,,,,,,,,,,,,32,1,4.000000e+000,7.820129e-004,0.000000e+000,0,,0,
1524024473.868,,0.000000e+000,3.499872e+001,-9.609962e-006,0.000000e+000,3,9.069250e-001,0.000000e+000,,,,,,,,,,,,,,32,1,4.000000e+000,1.560211e-003,0.000000e+000,0,,0,
1524024511.661,,0.000000e+000,3.499911e+001,-9.432928e-006,0.000000e+000,3,9.039355e-001,0.000000e+000,,,,,,,,,,,,,,32,1,4.000000e+000,7.820129e-004,0.000000e+000,0,,0,
1524024549.989,,0.000000e+000,3.500067e+001,-9.211111e-006,0.000000e+000,3,9.033369e-001,0.000000e+000,,,,,,,,,,,,,,32,1,4.000000e+000,2.338409e-003,0.000000e+000,0,,0,
1524024588.055,,0.000000e+000,3.499872e+001,-9.019680e-006,0.000000e+000,3,8.987353e-001,0.000000e+000,,,,,,,,,,,,,,32,1,4.000000e+000,1.560211e-003,0.000000e+000,0,,0,
1524024625.708,,0.000000e+000,3.499911e+001,-8.842065e-006,0.000000e+000,3,8.969482e-001,0.000000e+000,,,,,,,,,,,,,,32,1,4.000000e+000,7.820129e-004,0.000000e+000,0,,0,
1524024664.223,,0.000000e+000,3.499872e+001,-8.763243e-006,0.000000e+000,3,9.013550e-001,0.000000e+000,,,,,,,,,,,,,,32,1,4.000000e+000,0.000000e+000,0.000000e+000,0,,0,
1524024702.886,,0.000000e+000,3.499950e+001,-8.513335e-006,0.000000e+000,3,8.931527e-001,0.000000e+000,,,,,,,,,,,,,,32,1,4.000000e+000,1.560211e-003,0.000000e+000,0,,0,
1524024740.944,,0.000000e+000,3.499872e+001,-8.339184e-006,0.000000e+000,3,8.921608e-001,0.000000e+000,,,,,,,,,,,,,,32,1,4.000000e+000,0.000000e+000,0.000000e+000,0,,0,
1524024778.108,,0.000000e+000,3.499872e+001,-8.238600e-006,0.000000e+000,3,8.896486e-001,0.000000e+000,,,,,,,,,,,,,,32,1,4.000000e+000,1.560211e-003,0.000000e+000,0,,0,
1524024816.083,,0.000000e+000,3.499989e+001,-8.032700e-006,0.000000e+000,3,8.879609e-001,0.000000e+000,,,,,,,,,,,,,,32,1,4.000000e+000,7.781982e-004,0.000000e+000,0,,0,
1524024854.066,,0.000000e+000,3.499911e+001,-7.918571e-006,0.000000e+000,3,8.864119e-001,0.000000e+000,,,,,,,,,,,,,,32,1,4.000000e+000,7.820129e-004,0.000000e+000,0,,0,
1524024892.052,,0.000000e+000,3.499989e+001,-7.890575e-006,0.000000e+000,3,8.901334e-001,0.000000e+000,,,,,,,,,,,,,,32,1,4.000000e+000,7.781982e-004,0.000000e+000,0,,0,
1524024930.117,,0.000000e+000,3.499950e+001,-7.674211e-006,0.000000e+000,3,8.838467e-001,0.000000e+000,,,,,,,,,,,,,,32,1,4.000000e+000,0.000000e+000,0.000000e+000,0,,0,
1524024968.918,,0.000000e+000,3.499950e+001,-7.547882e-006,0.000000e+000,3,8.823019e-001,0.000000e+000,,,,,,,,,,,,,,32,1,4.000000e+000,0.000000e+000,0.000000e+000,0,,0,
1524025007.056,,0.000000e+000,3.499911e+001,-7.391171e-006,0.000000e+000,3,8.772839e-001,0.000000e+000,,,,,,,,,,,,,,32,1,4.000000e+000,7.820129e-004,0.000000e+000,0,,0,
1524025045.049,,0.000000e+000,3.499911e+001,-7.262527e-006,0.000000e+000,3,8.769835e-001,0.000000e+000,,,,,,,,,,,,,,32,1,4.000000e+000,7.820129e-004,0.000000e+000,0,,0,
1524025082.679,,0.000000e+000,3.499872e+001,-7.173899e-006,0.000000e+000,3,8.756405e-001,0.000000e+000,,,,,,,,,,,,,,32,1,4.000000e+000,0.000000e+000,0.000000e+000,0,,0,
1524025119.943,,0.000000e+000,3.499872e+001,-7.163457e-006,0.000000e+000,3,8.760436e-001,0.000000e+000,,,,,,,,,,,,,,32,1,4.000000e+000,0.000000e+000,0.000000e+000,0,,0,
1524025158.586,,0.000000e+000,3.499911e+001,-6.964944e-006,0.000000e+000,3,8.711398e-001,0.000000e+000,,,,,,,,,,,,,,32,1,4.000000e+000,7.820129e-004,0.000000e+000,0,,0,
1524025195.719,,0.000000e+000,3.499950e+001,-6.889440e-006,0.000000e+000,3,8.684405e-001,0.000000e+000,,,,,,,,,,,,,,32,1,4.000000e+000,0.000000e+000,0.000000e+000,0,,0,
1524025233.627,,0.000000e+000,3.499833e+001,-6.731668e-006,0.000000e+000,3,8.658862e-001,0.000000e+000,,,,,,,,,,,,,,32,1,4.000000e+000,7.781982e-004,0.000000e+000,0,,0,
1524025271.700,,0.000000e+000,3.499989e+001,-6.631170e-006,0.000000e+000,3,8.632109e-001,0.000000e+000,,,,,,,,,,,,,,32,1,4.000000e+000,7.781982e-004,0.000000e+000,0,,0,
1524025309.070,,0.000000e+000,3.499989e+001,-6.559942e-006,0.000000e+000,3,8.599704e-001,0.000000e+000,,,,,,,,,,,,,,32,1,4.000000e+000,7.781982e-004,0.000000e+000,0,,0,
1524025347.253,,0.000000e+000,3.499950e+001,-6.387757e-006,0.000000e+000,3,8.498661e-001,0.000000e+000,,,,,,,,,,,,,,32,1,4.000000e+000,1.560211e-003,0.000000e+000,0,,0,
1524025385.874,,0.000000e+000,3.499950e+001,-6.391854e-006,0.000000e+000,3,8.574123e-001,0.000000e+000,,,,,,,,,,,,,,32,1,4.000000e+000,1.560211e-003,0.000000e+000,0,,0,
1524025423.122,,0.000000e+000,3.499793e+001,-6.302570e-006,0.000000e+000,3,8.556615e-001,0.000000e+000,,,,,,,,,,,,,,32,1,4.000000e+000,3.131866e-003,0.000000e+000,0,,0,
1524025460.975,,0.000000e+000,3.499833e+001,-6.166584e-006,0.000000e+000,3,8.504526e-001,0.000000e+000,,,,,,,,,,,,,,32,1,4.000000e+000,7.781982e-004,0.000000e+000,0,,0,
1524025499.486,,0.000000e+000,3.499950e+001,-6.141232e-006,0.000000e+000,3,8.520876e-001,0.000000e+000,,,,,,,,,,,,,,32,1,4.000000e+000,0.000000e+000,0.000000e+000,0,,0,
1524025538.111,,0.000000e+000,3.499950e+001,-6.044881e-006,0.000000e+000,3,8.513544e-001,0.000000e+000,,,,,,,,,,,,,,32,1,4.000000e+000,1.560211e-003,0.000000e+000,0,,0,
1524025576.227,,0.000000e+000,3.499911e+001,-5.900055e-006,0.000000e+000,3,8.384967e-001,0.000000e+000,,,,,,,,,,,,,,32,1,4.000000e+000,7.820129e-004,0.000000e+000,0,,0,
1524025613.622,,0.000000e+000,3.499872e+001,-5.879516e-006,0.000000e+000,3,8.449913e-001,0.000000e+000,,,,,,,,,,,,,,32,1,4.000000e+000,1.560211e-003,0.000000e+000,0,,0,
1524025652.470,,0.000000e+000,3.499833e+001,-5.795062e-006,0.000000e+000,3,8.437057e-001,0.000000e+000,,,,,,,,,,,,,,32,1,4.000000e+000,7.781982e-004,0.000000e+000,0,,0,
1524025689.958,,0.000000e+000,3.499872e+001,-5.690685e-006,0.000000e+000,3,8.405461e-001,0.000000e+000,,,,,,,,,,,,,,32,1,4.000000e+000,0.000000e+000,0.000000e+000,0,,0,
1524025727.814,,0.000000e+000,3.499871e+001,-5.678805e-006,0.000000e+000,3,8.420101e-001,0.000000e+000,,,,,,,,,,,,,,32,1,4.000000e+000,4.692078e-003,0.000000e+000,0,,0,
1524025766.129,,0.000000e+000,3.499911e+001,-5.605557e-006,0.000000e+000,3,8.391714e-001,0.000000e+000,,,,,,,,,,,,,,32,1,4.000000e+000,2.338409e-003,0.000000e+000,0,,0,
1524025804.828,,0.000000e+000,3.499989e+001,-5.375457e-006,0.000000e+000,3,8.279030e-001,0.000000e+000,,,,,,,,,,,,,,32,1,4.000000e+000,2.342224e-003,0.000000e+000,0,,0,
1524025841.943,,0.000000e+000,3.499872e+001,-5.449383e-006,0.000000e+000,3,8.345755e-001,0.000000e+000,,,,,,,,,,,,,,32,1,4.000000e+000,0.000000e+000,0.000000e+000,0,,0,
1524025879.784,,0.000000e+000,3.499911e+001,-5.362593e-006,0.000000e+000,3,8.321890e-001,0.000000e+000,,,,,,,,,,,,,,32,1,4.000000e+000,7.820129e-004,0.000000e+000,0,,0,
1524025917.567,,0.000000e+000,3.499794e+001,-5.313808e-006,0.000000e+000,3,8.263893e-001,0.000000e+000,,,,,,,,,,,,,,32,1,4.000000e+000,0.000000e+000,0.000000e+000,0,,0,
1524025955.627,,0.000000e+000,3.499911e+001,-5.213677e-006,0.000000e+000,3,8.241606e-001,0.000000e+000,,,,,,,,,,,,,,32,1,4.000000e+000,7.820129e-004,0.000000e+000,0,,0,
1524025993.695,,0.000000e+000,3.499911e+001,-5.198174e-006,0.000000e+000,3,8.228992e-001,0.000000e+000,,,,,,,,,,,,,,32,1,4.000000e+000,2.338409e-003,0.000000e+000,0,,0,
1524026031.516,,0.000000e+000,3.499911e+001,-5.086795e-006,0.000000e+000,3,8.097742e-001,0.000000e+000,,,,,,,,,,,,,,32,1,4.000000e+000,7.820129e-004,0.000000e+000,0,,0,
1524026069.789,,0.000000e+000,3.499950e+001,-5.102799e-006,0.000000e+000,3,8.228655e-001,0.000000e+000,,,,,,,,,,,,,,32,1,4.000000e+000,1.560211e-003,0.000000e+000,0,,0,
1524026107.550,,0.000000e+000,3.499677e+001,-5.028160e-006,0.000000e+000,3,8.176758e-001,0.000000e+000,,,,,,,,,,,,,,32,1,4.000000e+000,2.349854e-003,0.000000e+000,0,,0,
1524026145.595,,0.000000e+000,3.499950e+001,-5.003360e-006,0.000000e+000,3,8.143298e-001,0.000000e+000,,,,,,,,,,,,,,32,1,4.000000e+000,0.000000e+000,0.000000e+000,0,,0,
1524026183.621,,0.000000e+000,3.500106e+001,-4.910798e-006,0.000000e+000,3,8.098233e-001,0.000000e+000,,,,,,,,,,,,,,32,1,4.000000e+000,6.248474e-003,0.000000e+000,0,,0,
1524026222.091,,0.000000e+000,3.499950e+001,-4.845010e-006,0.000000e+000,3,8.234808e-001,0.000000e+000,,,,,,,,,,,,,,32,1,4.000000e+000,1.560211e-003,0.000000e+000,0,,0,
1524026260.172,,0.000000e+000,3.499911e+001,-4.819916e-006,0.000000e+000,3,7.950819e-001,0.000000e+000,,,,,,,,,,,,,,32,1,4.000000e+000,7.820129e-004,0.000000e+000,0,,0,
1524026298.242,,0.000000e+000,3.500028e+001,-4.752144e-006,0.000000e+000,3,8.069479e-001,0.000000e+000,,,,,,,,,,,,,,32,1,4.000000e+000,1.560211e-003,0.000000e+000,0,,0,
1524026336.293,,0.000000e+000,3.499911e+001,-4.705370e-006,0.000000e+000,3,8.053393e-001,0.000000e+000,,,,,,,,,,,,,,32,1,4.000000e+000,7.820129e-004,0.000000e+000,0,,0,
1524026374.048,,0.000000e+000,3.499950e+001,-4.608272e-006,0.000000e+000,3,8.076875e-001,0.000000e+000,,,,,,,,,,,,,,32,1,4.000000e+000,0.000000e+000,0.000000e+000,0,,0,
1524026413.014,,0.000000e+000,3.499872e+001,-4.604577e-006,0.000000e+000,3,8.033363e-001,0.000000e+000,,,,,,,,,,,,,,32,1,4.000000e+000,0.000000e+000,0.000000e+000,0,,0,
1524026451.082,,0.000000e+000,3.499833e+001,-4.529906e-006,0.000000e+000,3,8.030000e-001,0.000000e+000,,,,,,,,,,,,,,32,1,4.000000e+000,7.781982e-004,0.000000e+000,0,,0,
1524026489.273,,0.000000e+000,3.499872e+001,-4.550845e-006,0.000000e+000,3,7.972196e-001,0.000000e+000,,,,,,,,,,,,,,32,1,4.000000e+000,0.000000e+000,0.000000e+000,0,,0,
1524026526.861,,0.000000e+000,3.499989e+001,-4.455153e-006,0.000000e+000,3,7.990855e-001,0.000000e+000,,,,,,,,,,,,,,32,1,4.000000e+000,7.781982e-004,0.000000e+000,0,,0,
1524026564.811,,0.000000e+000,3.499989e+001,-4.436218e-006,0.000000e+000,3,7.994644e-001,0.000000e+000,,,,,,,,,,,,,,32,1,4.000000e+000,7.781982e-004,0.000000e+000,0,,0,
1524026602.864,,0.000000e+000,3.499950e+001,-4.368953e-006,0.000000e+000,3,7.919638e-001,0.000000e+000,,,,,,,,,,,,,,32,1,4.000000e+000,0.000000e+000,0.000000e+000,0,,0,
1524026640.942,,0.000000e+000,3.499911e+001,-4.313669e-006,0.000000e+000,3,7.932594e-001,0.000000e+000,,,,,,,,,,,,,,32,1,4.000000e+000,7.820129e-004,0.000000e+000,0,,0,
1524026679.030,,0.000000e+000,3.499950e+001,-4.237009e-006,0.000000e+000,3,7.874519e-001,0.000000e+000,,,,,,,,,,,,,,32,1,4.000000e+000,0.000000e+000,0.000000e+000,0,,0,
1524026716.763,,0.000000e+000,3.499833e+001,-4.240848e-006,0.000000e+000,3,7.914057e-001,0.000000e+000,,,,,,,,,,,,,,32,1,4.000000e+000,7.781982e-004,0.000000e+000,0,,0,
1524026755.137,,0.000000e+000,3.499989e+001,-4.184445e-006,0.000000e+000,3,7.918198e-001,0.000000e+000,,,,,,,,,,,,,,32,1,4.000000e+000,2.342224e-003,0.000000e+000,0,,0,
1524026793.252,,0.000000e+000,3.499833e+001,-4.160908e-006,0.000000e+000,3,7.844908e-001,0.000000e+000,,,,,,,,,,,,,,32,1,4.000000e+000,2.349854e-003,0.000000e+000,0,,0,
1524026831.378,,0.000000e+000,3.499989e+001,-4.117859e-006,0.000000e+000,3,7.792096e-001,0.000000e+000,,,,,,,,,,,,,,32,1,4.000000e+000,2.342224e-003,0.000000e+000,0,,0,
1524026869.033,,0.000000e+000,3.499911e+001,-4.100909e-006,0.000000e+000,3,7.815451e-001,0.000000e+000,,,,,,,,,,,,,,32,1,4.000000e+000,7.820129e-004,0.000000e+000,0,,0,
1524026907.529,,0.000000e+000,3.499950e+001,-4.047404e-006,0.000000e+000,3,7.803204e-001,0.000000e+000,,,,,,,,,,,,,,32,1,4.000000e+000,1.560211e-003,0.000000e+000,0,,0,
1524026945.149,,0.000000e+000,3.499950e+001,-3.998256e-006,0.000000e+000,3,7.791679e-001,0.000000e+000,,,,,,,,,,,,,,32,1,4.000000e+000,1.560211e-003,0.000000e+000,0,,0,
1524026982.977,,0.000000e+000,3.499950e+001,-3.960187e-006,0.000000e+000,3,7.775906e-001,0.000000e+000,,,,,,,,,,,,,,32,1,4.000000e+000,0.000000e+000,0.000000e+000,0,,0,
1524027020.503,,0.000000e+000,3.499989e+001,-3.899499e-006,0.000000e+000,3,7.690701e-001,0.000000e+000,,,,,,,,,,,,,,32,1,4.000000e+000,7.781982e-004,0.000000e+000,0,,0,
1524027057.986,,0.000000e+000,3.499911e+001,-3.883304e-006,0.000000e+000,3,7.720715e-001,0.000000e+000,,,,,,,,,,,,,,32,1,4.000000e+000,7.820129e-004,0.000000e+000,0,,0,
1524027096.086,,0.000000e+000,3.500067e+001,-3.829418e-006,0.000000e+000,3,7.605835e-001,0.000000e+000,,,,,,,,,,,,,,32,1,4.000000e+000,2.338409e-003,0.000000e+000,0,,0,
1524027133.627,,0.000000e+000,3.499950e+001,-3.814956e-006,0.000000e+000,3,7.639437e-001,0.000000e+000,,,,,,,,,,,,,,32,1,4.000000e+000,0.000000e+000,0.000000e+000,0,,0,
1524027171.685,,0.000000e+000,3.499911e+001,-3.755011e-006,0.000000e+000,3,7.575265e-001,0.000000e+000,,,,,,,,,,,,,,32,1,4.000000e+000,7.820129e-004,0.000000e+000,0,,0,
1524027209.383,,0.000000e+000,3.499989e+001,-3.745528e-006,0.000000e+000,3,7.568584e-001,0.000000e+000,,,,,,,,,,,,,,32,1,4.000000e+000,7.781982e-004,0.000000e+000,0,,0,
1524027247.691,,0.000000e+000,3.499950e+001,-3.749881e-006,0.000000e+000,3,7.565079e-001,0.000000e+000,,,,,,,,,,,,,,32,1,4.000000e+000,0.000000e+000,0.000000e+000,0,,0,
1524027285.472,,0.000000e+000,3.499989e+001,-3.664095e-006,0.000000e+000,3,7.521882e-001,0.000000e+000,,,,,,,,,,,,,,32,1,4.000000e+000,7.781982e-004,0.000000e+000,0,,0,
1524027324.035,,0.000000e+000,3.499872e+001,-3.621063e-006,0.000000e+000,3,7.527056e-001,0.000000e+000,,,,,,,,,,,,,,32,1,4.000000e+000,0.000000e+000,0.000000e+000,0,,0,
1524027362.208,,0.000000e+000,3.499911e+001,-3.614231e-006,0.000000e+000,3,7.535360e-001,0.000000e+000,,,,,,,,,,,,,,32,1,4.000000e+000,2.338409e-003,0.000000e+000,0,,0,
1524027400.866,,0.000000e+000,3.499950e+001,-3.551054e-006,0.000000e+000,3,7.401727e-001,0.000000e+000,,,,,,,,,,,,,,32,1,4.000000e+000,1.560211e-003,0.000000e+000,0,,0,
1524027439.194,,0.000000e+000,3.499833e+001,-3.551869e-006,0.000000e+000,3,7.458760e-001,0.000000e+000,,,,,,,,,,,,,,32,1,4.000000e+000,7.781982e-004,0.000000e+000,0,,0,
1524027477.230,,0.000000e+000,3.499833e+001,-3.483053e-006,0.000000e+000,3,7.428222e-001,0.000000e+000,,,,,,,,,,,,,,32,1,4.000000e+000,2.349854e-003,0.000000e+000,0,,0,
1524027515.283,,0.000000e+000,3.499950e+001,-3.461517e-006,0.000000e+000,3,7.411172e-001,0.000000e+000,,,,,,,,,,,,,,32,1,4.000000e+000,0.000000e+000,0.000000e+000,0,,0,
1524027553.353,,0.000000e+000,3.499950e+001,-3.469571e-006,0.000000e+000,3,7.381047e-001,0.000000e+000,,,,,,,,,,,,,,32,1,4.000000e+000,0.000000e+000,0.000000e+000,0,,0,
1524027591.351,,0.000000e+000,3.499872e+001,-3.420387e-006,0.000000e+000,3,7.360989e-001,0.000000e+000,,,,,,,,,,,,,,32,1,4.000000e+000,0.000000e+000,0.000000e+000,0,,0,
1524027629.202,,0.000000e+000,3.499872e+001,-3.397732e-006,0.000000e+000,3,7.255288e-001,0.000000e+000,,,,,,,,,,,,,,32,1,4.000000e+000,0.000000e+000,0.000000e+000,0,,0,
1524027666.857,,0.000000e+000,3.500028e+001,-3.330797e-006,0.000000e+000,3,7.296066e-001,0.000000e+000,,,,,,,,,,,,,,32,1,4.000000e+000,0.000000e+000,0.000000e+000,0,,0,
1524027704.890,,0.000000e+000,3.499950e+001,-3.287988e-006,0.000000e+000,3,7.201946e-001,0.000000e+000,,,,,,,,,,,,,,32,1,4.000000e+000,0.000000e+000,0.000000e+000,0,,0,
1524027742.981,,0.000000e+000,3.499911e+001,-3.301094e-006,0.000000e+000,3,7.302003e-001,0.000000e+000,,,,,,,,,,,,,,32,1,4.000000e+000,2.338409e-003,0.000000e+000,0,,0,
1524027781.014,,0.000000e+000,3.499911e+001,-3.252772e-006,0.000000e+000,3,7.197680e-001,0.000000e+000,,,,,,,,,,,,,,32,1,4.000000e+000,7.820129e-004,0.000000e+000,0,,0,
1524027819.057,,0.000000e+000,3.499989e+001,-3.152108e-006,0.000000e+000,3,7.210240e-001,0.000000e+000,,,,,,,,,,,,,,32,1,4.000000e+000,2.342224e-003,0.000000e+000,0,,0,
1524027856.983,,0.000000e+000,3.500106e+001,-3.195115e-006,0.000000e+000,3,7.101489e-001,0.000000e+000,,,,,,,,,,,,,,32,1,4.000000e+000,3.128052e-003,0.000000e+000,0,,0,
1524027895.346,,0.000000e+000,3.500028e+001,-3.172529e-006,0.000000e+000,3,7.148778e-001,0.000000e+000,,,,,,,,,,,,,,32,1,4.000000e+000,0.000000e+000,0.000000e+000,0,,0,
1524027933.411,,0.000000e+000,3.499950e+001,-3.141118e-006,0.000000e+000,3,7.101477e-001,0.000000e+000,,,,,,,,,,,,,,32,1,4.000000e+000,0.000000e+000,0.000000e+000,0,,0,
1524027970.894,,0.000000e+000,3.499911e+001,-3.135867e-006,0.000000e+000,3,7.128337e-001,0.000000e+000,,,,,,,,,,,,,,32,1,4.000000e+000,7.820129e-004,0.000000e+000,0,,0,
1524028008.945,,0.000000e+000,3.499911e+001,-3.122806e-006,0.000000e+000,3,7.124770e-001,0.000000e+000,,,,,,,,,,,,,,32,1,4.000000e+000,7.820129e-004,0.000000e+000,0,,0,
1524028047.063,,0.000000e+000,3.499950e+001,-3.078501e-006,0.000000e+000,3,7.047330e-001,0.000000e+000,,,,,,,,,,,,,,32,1,4.000000e+000,0.000000e+000,0.000000e+000,0,,0,
1524028085.114,,0.000000e+000,3.499911e+001,-3.028758e-006,0.000000e+000,3,7.012832e-001,0.000000e+000,,,,,,,,,,,,,,32,1,4.000000e+000,7.820129e-004,0.000000e+000,0,,0,
1524028123.177,,0.000000e+000,3.499950e+001,-3.040665e-006,0.000000e+000,3,7.020992e-001,0.000000e+000,,,,,,,,,,,,,,32,1,4.000000e+000,1.560211e-003,0.000000e+000,0,,0,
1524028160.997,,0.000000e+000,3.499950e+001,-3.001291e-006,0.000000e+000,3,6.911654e-001,0.000000e+000,,,,,,,,,,,,,,32,1,4.000000e+000,0.000000e+000,0.000000e+000,0,,0,
1524028198.803,,0.000000e+000,3.499911e+001,-2.985891e-006,0.000000e+000,3,6.984251e-001,0.000000e+000,,,,,,,,,,,,,,32,1,4.000000e+000,2.338409e-003,0.000000e+000,0,,0,
1524028236.323,,0.000000e+000,3.499833e+001,-2.942483e-006,0.000000e+000,3,6.915916e-001,0.000000e+000,,,,,,,,,,,,,,32,1,4.000000e+000,7.781982e-004,0.000000e+000,0,,0,
1524028274.346,,0.000000e+000,3.500067e+001,-2.941855e-006,0.000000e+000,3,6.928797e-001,0.000000e+000,,,,,,,,,,,,,,32,1,4.000000e+000,2.338409e-003,0.000000e+000,0,,0,
1524028312.364,,0.000000e+000,3.499950e+001,-2.874706e-006,0.000000e+000,3,6.903989e-001,0.000000e+000,,,,,,,,,,,,,,32,1,4.000000e+000,0.000000e+000,0.000000e+000,0,,0,
1524028350.482,,0.000000e+000,3.499950e+001,-2.890429e-006,0.000000e+000,3,6.914256e-001,0.000000e+000,,,,,,,,,,,,,,32,1,4.000000e+000,0.000000e+000,0.000000e+000,0,,0,
1524028388.516,,0.000000e+000,3.499950e+001,-2.839969e-006,0.000000e+000,3,6.847577e-001,0.000000e+000,,,,,,,,,,,,,,32,1,4.000000e+000,1.560211e-003,0.000000e+000,0,,0,
1524028426.561,,0.000000e+000,3.499872e+001,-2.841189e-006,0.000000e+000,3,6.809660e-001,0.000000e+000,,,,,,,,,,,,,,32,1,4.000000e+000,0.000000e+000,0.000000e+000,0,,0,
1524028464.657,,0.000000e+000,3.499989e+001,-2.808970e-006,0.000000e+000,3,6.775618e-001,0.000000e+000,,,,,,,,,,,,,,32,1,4.000000e+000,7.781982e-004,0.000000e+000,0,,0,
1524028502.690,,0.000000e+000,3.499950e+001,-2.773778e-006,0.000000e+000,3,6.784596e-001,0.000000e+000,,,,,,,,,,,,,,32,1,4.000000e+000,0.000000e+000,0.000000e+000,0,,0,
1524028540.533,,0.000000e+000,3.499872e+001,-2.775909e-006,0.000000e+000,3,6.676251e-001,0.000000e+000,,,,,,,,,,,,,,32,1,4.000000e+000,0.000000e+000,0.000000e+000,0,,0,
1524028578.456,,0.000000e+000,3.499872e+001,-2.738600e-006,0.000000e+000,3,6.723194e-001,0.000000e+000,,,,,,,,,,,,,,32,1,4.000000e+000,0.000000e+000,0.000000e+000,0,,0,
1524028616.506,,0.000000e+000,3.499833e+001,-2.741651e-006,0.000000e+000,3,6.747807e-001,0.000000e+000,,,,,,,,,,,,,,32,1,4.000000e+000,2.349854e-003,0.000000e+000,0,,0,
1524028653.747,,0.000000e+000,3.499872e+001,-2.707500e-006,0.000000e+000,3,6.590982e-001,0.000000e+000,,,,,,,,,,,,,,32,1,4.000000e+000,1.560211e-003,0.000000e+000,0,,0,
1524028691.812,,0.000000e+000,3.499794e+001,-2.630701e-006,0.000000e+000,3,6.526948e-001,0.000000e+000,,,,,,,,,,,,,,32,1,4.000000e+000,0.000000e+000,0.000000e+000,0,,0,
1524028730.016,,0.000000e+000,3.499871e+001,-2.650720e-006,0.000000e+000,3,6.621326e-001,0.000000e+000,,,,,,,,,,,,,,32,1,4.000000e+000,3.128052e-003,0.000000e+000,0,,0,
1524028768.064,,0.000000e+000,3.499950e+001,-2.641743e-006,0.000000e+000,3,6.630931e-001,0.000000e+000,,,,,,,,,,,,,,32,1,4.000000e+000,1.560211e-003,0.000000e+000,0,,0,
1524028806.134,,0.000000e+000,3.499950e+001,-2.485371e-006,0.000000e+000,3,6.429534e-001,0.000000e+000,,,,,,,,,,,,,,32,1,4.000000e+000,0.000000e+000,0.000000e+000,0,,0,
1524028844.730,,0.000000e+000,3.499989e+001,-2.611011e-006,0.000000e+000,3,6.457911e-001,0.000000e+000,,,,,,,,,,,,,,32,1,4.000000e+000,7.781982e-004,0.000000e+000,0,,0,
1524028882.245,,0.000000e+000,3.499950e+001,-2.572928e-006,0.000000e+000,3,6.518851e-001,0.000000e+000,,,,,,,,,,,,,,32,1,4.000000e+000,0.000000e+000,0.000000e+000,0,,0,
1524028920.316,,0.000000e+000,3.499950e+001,-2.547943e-006,0.000000e+000,3,6.479315e-001,0.000000e+000,,,,,,,,,,,,,,32,1,4.000000e+000,0.000000e+000,0.000000e+000,0,,0,
1524028957.704,,0.000000e+000,3.499872e+001,-2.531119e-006,0.000000e+000,3,6.369425e-001,0.000000e+000,,,,,,,,,,,,,,32,1,4.000000e+000,1.560211e-003,0.000000e+000,0,,0,
1524028995.772,,0.000000e+000,3.500067e+001,-2.481661e-006,0.000000e+000,3,6.420782e-001,0.000000e+000,,,,,,,,,,,,,,32,1,4.000000e+000,3.910065e-003,0.000000e+000,0,,0,
1524029033.793,,0.000000e+000,3.499911e+001,-2.499763e-006,0.000000e+000,3,6.516213e-001,0.000000e+000,,,,,,,,,,,,,,32,1,4.000000e+000,7.820129e-004,0.000000e+000,0,,0,
1524029071.978,,0.000000e+000,3.499989e+001,-2.476814e-006,0.000000e+000,3,6.357974e-001,0.000000e+000,,,,,,,,,,,,,,32,1,4.000000e+000,2.342224e-003,0.000000e+000,0,,0,
1524029110.039,,0.000000e+000,3.499911e+001,-2.494891e-006,0.000000e+000,3,6.409488e-001,0.000000e+000,,,,,,,,,,,,,,32,1,4.000000e+000,2.338409e-003,0.000000e+000,0,,0,
1524029148.079,,0.000000e+000,3.499833e+001,-2.414164e-006,0.000000e+000,3,6.226386e-001,0.000000e+000,,,,,,,,,,,,,,32,1,4.000000e+000,7.781982e-004,0.000000e+000,0,,0,
1524029186.150,,0.000000e+000,3.499872e+001,-2.461866e-006,0.000000e+000,3,6.437134e-001,0.000000e+000,,,,,,,,,,,,,,32,1,4.000000e+000,0.000000e+000,0.000000e+000,0,,0,
1524029223.758,,0.000000e+000,3.499950e+001,-2.392096e-006,0.000000e+000,3,6.223047e-001,0.000000e+000,,,,,,,,,,,,,,32,1,4.000000e+000,0.000000e+000,0.000000e+000,0,,0,
1524029261.768,,0.000000e+000,3.499950e+001,-2.395508e-006,0.000000e+000,3,6.216273e-001,0.000000e+000,,,,,,,,,,,,,,32,1,4.000000e+000,1.560211e-003,0.000000e+000,0,,0,
1524029300.281,,0.000000e+000,3.499950e+001,-2.333255e-006,0.000000e+000,3,6.143752e-001,0.000000e+000,,,,,,,,,,,,,,32,1,4.000000e+000,1.560211e-003,0.000000e+000,0,,0,
1524029338.337,,0.000000e+000,3.499872e+001,-2.337320e-006,0.000000e+000,3,6.111071e-001,0.000000e+000,,,,,,,,,,,,,,32,1,4.000000e+000,0.000000e+000,0.000000e+000,0,,0,
1524029376.467,,0.000000e+000,3.499950e+001,-2.324871e-006,0.000000e+000,3,6.042687e-001,0.000000e+000,,,,,,,,,,,,,,32,1,4.000000e+000,0.000000e+000,0.000000e+000,0,,0,
1524029413.976,,0.000000e+000,3.499950e+001,-2.319841e-006,0.000000e+000,3,6.133621e-001,0.000000e+000,,,,,,,,,,,,,,32,1,4.000000e+000,0.000000e+000,0.000000e+000,0,,0,
1524029452.046,,0.000000e+000,3.499911e+001,-2.338372e-006,0.000000e+000,3,6.101005e-001,0.000000e+000,,,,,,,,,,,,,,32,1,4.000000e+000,7.820129e-004,0.000000e+000,0,,0,
1524029490.062,,0.000000e+000,3.499872e+001,-2.282244e-006,0.000000e+000,3,6.062484e-001,0.000000e+000,,,,,,,,,,,,,,32,1,4.000000e+000,1.560211e-003,0.000000e+000,0,,0,
1524029528.145,,0.000000e+000,3.499911e+001,-2.247196e-006,0.000000e+000,3,6.012143e-001,0.000000e+000,,,,,,,,,,,,,,32,1,4.000000e+000,7.820129e-004,0.000000e+000,0,,0,
1524029566.193,,0.000000e+000,3.499872e+001,-2.238961e-006,0.000000e+000,3,5.930434e-001,0.000000e+000,,,,,,,,,,,,,,32,1,4.000000e+000,1.560211e-003,0.000000e+000,0,,0,
1524029604.051,,0.000000e+000,3.499872e+001,-2.214665e-006,0.000000e+000,3,5.861944e-001,0.000000e+000,,,,,,,,,,,,,,32,1,4.000000e+000,0.000000e+000,0.000000e+000,0,,0,
1524029641.834,,0.000000e+000,3.499872e+001,-2.196022e-006,0.000000e+000,3,5.844430e-001,0.000000e+000,,,,,,,,,,,,,,32,1,4.000000e+000,0.000000e+000,0.000000e+000,0,,0,
1524029679.719,,0.000000e+000,3.499950e+001,-2.147546e-006,0.000000e+000,3,5.640009e-001,0.000000e+000,,,,,,,,,,,,,,32,1,4.000000e+000,0.000000e+000,0.000000e+000,0,,0,
1524029717.025,,0.000000e+000,3.499950e+001,-2.153262e-006,0.000000e+000,3,5.910275e-001,0.000000e+000,,,,,,,,,,,,,,32,1,4.000000e+000,0.000000e+000,0.000000e+000,0,,0,
1524029755.076,,0.000000e+000,3.499989e+001,-2.157302e-006,0.000000e+000,3,5.804890e-001,0.000000e+000,,,,,,,,,,,,,,32,1,4.000000e+000,7.781982e-004,0.000000e+000,0,,0,
1524029793.214,,0.000000e+000,3.499989e+001,-2.152383e-006,0.000000e+000,3,5.852243e-001,0.000000e+000,,,,,,,,,,,,,,32,1,4.000000e+000,7.781982e-004,0.000000e+000,0,,0,
1524029831.749,,0.000000e+000,3.499833e+001,-2.118924e-006,0.000000e+000,3,5.666304e-001,0.000000e+000,,,,,,,,,,,,,,32,1,4.000000e+000,7.781982e-004,0.000000e+000,0,,0,
1524029869.935,,0.000000e+000,3.500067e+001,-2.113392e-006,0.000000e+000,3,5.623925e-001,0.000000e+000,,,,,,,,,,,,,,32,1,4.000000e+000,7.820129e-004,0.000000e+000,0,,0,
1524029908.495,,0.000000e+000,3.499950e+001,-2.105350e-006,0.000000e+000,3,5.776831e-001,0.000000e+000,,,,,,,,,,,,,,32,1,4.000000e+000,0.000000e+000,0.000000e+000,0,,0,
1524029945.936,,0.000000e+000,3.499911e+001,-2.102833e-006,0.000000e+000,3,5.737233e-001,0.000000e+000,,,,,,,,,,,,,,32,1,4.000000e+000,7.820129e-004,0.000000e+000,0,,0,
1524029983.871,,0.000000e+000,3.499950e+001,-2.058950e-006,0.000000e+000,3,5.587789e-001,0.000000e+000,,,,,,,,,,,,,,32,1,4.000000e+000,1.560211e-003,0.000000e+000,0,,0,
1524030021.629,,0.000000e+000,3.499911e+001,-2.067734e-006,0.000000e+000,3,5.632845e-001,0.000000e+000,,,,,,,,,,,,,,32,1,4.000000e+000,7.820129e-004,0.000000e+000,0,,0,
1524030059.940,,0.000000e+000,3.499950e+001,-2.098940e-006,0.000000e+000,3,5.641194e-001,0.000000e+000,,,,,,,,,,,,,,32,1,4.000000e+000,0.000000e+000,0.000000e+000,0,,0,
1524030097.471,,0.000000e+000,3.499872e+001,-2.026973e-006,0.000000e+000,3,5.627473e-001,0.000000e+000,,,,,,,,,,,,,,32,1,4.000000e+000,1.560211e-003,0.000000e+000,0,,0,
1524030135.484,,0.000000e+000,3.499989e+001,-1.974128e-006,0.000000e+000,3,5.414125e-001,0.000000e+000,,,,,,,,,,,,,,32,1,4.000000e+000,7.781982e-004,0.000000e+000,0,,0,
1524030173.549,,0.000000e+000,3.499911e+001,-1.995954e-006,0.000000e+000,3,5.429906e-001,0.000000e+000,,,,,,,,,,,,,,32,1,4.000000e+000,2.338409e-003,0.000000e+000,0,,0,
1524030211.637,,0.000000e+000,3.499950e+001,-1.973515e-006,0.000000e+000,3,5.416562e-001,0.000000e+000,,,,,,,,,,,,,,32,1,4.000000e+000,1.560211e-003,0.000000e+000,0,,0,
1524030249.045,,0.000000e+000,3.499872e+001,-1.956141e-006,0.000000e+000,3,5.180123e-001,0.000000e+000,,,,,,,,,,,,,,32,1,4.000000e+000,1.560211e-003,0.000000e+000,0,,0,
1524030287.126,,0.000000e+000,3.499872e+001,-1.951517e-006,0.000000e+000,3,5.300386e-001,0.000000e+000,,,,,,,,,,,,,,32,1,4.000000e+000,0.000000e+000,0.000000e+000,0,,0,
1524030325.281,,0.000000e+000,3.500028e+001,-1.940131e-006,0.000000e+000,3,5.424466e-001,0.000000e+000,,,,,,,,,,,,,,32,1,4.000000e+000,1.560211e-003,0.000000e+000,0,,0,
1524030363.105,,0.000000e+000,3.499911e+001,-1.931993e-006,0.000000e+000,3,5.389011e-001,0.000000e+000,,,,,,,,,,,,,,32,1,4.000000e+000,7.820129e-004,0.000000e+000,0,,0,
1524030400.990,,0.000000e+000,3.499950e+001,-1.913625e-006,0.000000e+000,3,5.355579e-001,0.000000e+000,,,,,,,,,,,,,,32,1,4.000000e+000,0.000000e+000,0.000000e+000,0,,0,
1524030438.568,,0.000000e+000,3.499794e+001,-1.755874e-006,0.000000e+000,3,5.041116e-001,0.000000e+000,,,,,,,,,,,,,,32,1,4.000000e+000,0.000000e+000,0.000000e+000,0,,0,
1524030477.684,,0.000000e+000,3.499872e+001,-1.881150e-006,0.000000e+000,3,5.182869e-001,0.000000e+000,,,,,,,,,,,,,,32,1,4.000000e+000,0.000000e+000,0.000000e+000,0,,0,
1524030515.719,,0.000000e+000,3.499911e+001,-1.899861e-006,0.000000e+000,3,5.305333e-001,0.000000e+000,,,,,,,,,,,,,,32,1,4.000000e+000,7.820129e-004,0.000000e+000,0,,0,
1524030553.847,,0.000000e+000,3.499911e+001,-1.849079e-006,0.000000e+000,3,5.127513e-001,0.000000e+000,,,,,,,,,,,,,,32,1,4.000000e+000,7.820129e-004,0.000000e+000,0,,0,
1524030591.940,,0.000000e+000,3.500028e+001,-1.841646e-006,0.000000e+000,3,5.130976e-001,0.000000e+000,,,,,,,,,,,,,,32,1,4.000000e+000,0.000000e+000,0.000000e+000,0,,0,
1524030629.903,,0.000000e+000,3.499989e+001,-1.838599e-006,0.000000e+000,3,5.272781e-001,0.000000e+000,,,,,,,,,,,,,,32,1,4.000000e+000,7.781982e-004,0.000000e+000,0,,0,
1524030668.036,,0.000000e+000,3.499911e+001,-1.825665e-006,0.000000e+000,3,5.181720e-001,0.000000e+000,,,,,,,,,,,,,,32,1,4.000000e+000,7.820129e-004,0.000000e+000,0,,0,
1524030706.427,,0.000000e+000,3.499833e+001,-1.801191e-006,0.000000e+000,3,5.061948e-001,0.000000e+000,,,,,,,,,,,,,,32,1,4.000000e+000,7.781982e-004,0.000000e+000,0,,0,
1524030744.958,,0.000000e+000,3.500028e+001,-1.708620e-006,0.000000e+000,3,4.383212e-001,0.000000e+000,,,,,,,,,,,,,,32,1,4.000000e+000,0.000000e+000,0.000000e+000,0,,0,
1524030783.286,,0.000000e+000,3.499950e+001,-1.800925e-006,0.000000e+000,3,5.082654e-001,0.000000e+000,,,,,,,,,,,,,,32,1,4.000000e+000,0.000000e+000,0.000000e+000,0,,0,
1524030821.654,,0.000000e+000,3.499911e+001,-1.739014e-006,0.000000e+000,3,4.709322e-001,0.000000e+000,,,,,,,,,,,,,,32,1,4.000000e+000,7.820129e-004,0.000000e+000,0,,0,
1524030859.102,,0.000000e+000,3.499950e+001,-1.785146e-006,0.000000e+000,3,4.747131e-001,0.000000e+000,,,,,,,,,,,,,,32,1,4.000000e+000,1.560211e-003,0.000000e+000,0,,0,
1524030897.220,,0.000000e+000,3.499950e+001,-1.712800e-006,0.000000e+000,3,4.654160e-001,0.000000e+000,,,,,,,,,,,,,,32,1,4.000000e+000,1.560211e-003,0.000000e+000,0,,0,
1524030935.155,,0.000000e+000,3.499989e+001,-1.689424e-006,0.000000e+000,3,4.445412e-001,0.000000e+000,,,,,,,,,,,,,,32,1,4.000000e+000,7.781982e-004,0.000000e+000,0,,0,
1524030972.796,,0.000000e+000,3.500028e+001,-1.710587e-006,0.000000e+000,3,4.593003e-001,0.000000e+000,,,,,,,,,,,,,,32,1,4.000000e+000,1.560211e-003,0.000000e+000,0,,0,
1524031010.867,,0.000000e+000,3.499872e+001,-1.714201e-006,0.000000e+000,3,4.793713e-001,0.000000e+000,,,,,,,,,,,,,,32,1,4.000000e+000,0.000000e+000,0.000000e+000,0,,0,
1524031048.927,,0.000000e+000,3.499950e+001,-1.689228e-006,0.000000e+000,3,4.656138e-001,0.000000e+000,,,,,,,,,,,,,,32,1,4.000000e+000,0.000000e+000,0.000000e+000,0,,0,
1524031086.955,,0.000000e+000,3.500028e+001,-1.688581e-006,0.000000e+000,3,4.615302e-001,0.000000e+000,,,,,,,,,,,,,,32,1,4.000000e+000,0.000000e+000,0.000000e+000,0,,0,
1524031124.756,,0.000000e+000,3.499911e+001,-1.645294e-006,0.000000e+000,3,4.404149e-001,0.000000e+000,,,,,,,,,,,,,,32,1,4.000000e+000,7.820129e-004,0.000000e+000,0,,0,
1524031162.591,,0.000000e+000,3.499950e+001,-1.638249e-006,0.000000e+000,3,4.348194e-001,0.000000e+000,,,,,,,,,,,,,,32,1,4.000000e+000,1.560211e-003,0.000000e+000,0,,0,
1524031200.489,,0.000000e+000,3.499911e+001,-1.647224e-006,0.000000e+000,3,4.471319e-001,0.000000e+000,,,,,,,,,,,,,,32,1,4.000000e+000,7.820129e-004,0.000000e+000,0,,0,
1524031238.665,,0.000000e+000,3.499871e+001,-1.625972e-006,0.000000e+000,3,4.532329e-001,0.000000e+000,,,,,,,,,,,,,,32,1,4.000000e+000,3.128052e-003,0.000000e+000,0,,0,
1524031276.758,,0.000000e+000,3.499833e+001,-1.622085e-006,0.000000e+000,3,4.361244e-001,0.000000e+000,,,,,,,,,,,,,,32,1,4.000000e+000,7.781982e-004,0.000000e+000,0,,0,
1524031314.786,,0.000000e+000,3.499911e+001,-1.599056e-006,0.000000e+000,3,4.320591e-001,0.000000e+000,,,,,,,,,,,,,,32,1,4.000000e+000,7.820129e-004,0.000000e+000,0,,0,
1524031352.864,,0.000000e+000,3.499989e+001,-1.586578e-006,0.000000e+000,3,4.307716e-001,0.000000e+000,,,,,,,,,,,,,,32,1,4.000000e+000,7.781982e-004,0.000000e+000,0,,0,
1524031390.667,,0.000000e+000,3.499911e+001,-1.595291e-006,0.000000e+000,3,4.234953e-001,0.000000e+000,,,,,,,,,,,,,,32,1,4.000000e+000,7.820129e-004,0.000000e+000,0,,0,
1524031428.438,,0.000000e+000,3.499950e+001,-1.548019e-006,0.000000e+000,3,4.083150e-001,0.000000e+000,,,,,,,,,,,,,,32,1,4.000000e+000,0.000000e+000,0.000000e+000,0,,0,
1524031466.993,,0.000000e+000,3.499911e+001,-1.546191e-006,0.000000e+000,3,4.154591e-001,0.000000e+000,,,,,,,,,,,,,,32,1,4.000000e+000,7.820129e-004,0.000000e+000,0,,0,
1524031505.641,,0.000000e+000,3.499911e+001,-1.547683e-006,0.000000e+000,3,4.108137e-001,0.000000e+000,,,,,,,,,,,,,,32,1,4.000000e+000,2.338409e-003,0.000000e+000,0,,0,
1524031542.637,,0.000000e+000,3.499950e+001,-1.536634e-006,0.000000e+000,3,4.071760e-001,0.000000e+000,,,,,,,,,,,,,,32,1,4.000000e+000,0.000000e+000,0.000000e+000,0,,0,
1524031580.690,,0.000000e+000,3.499872e+001,-1.536610e-006,0.000000e+000,3,4.048924e-001,0.000000e+000,,,,,,,,,,,,,,32,1,4.000000e+000,0.000000e+000,0.000000e+000,0,,0,
1524031619.280,,0.000000e+000,3.499950e+001,-1.574256e-006,0.000000e+000,3,4.467502e-001,0.000000e+000,,,,,,,,,,,,,,32,1,4.000000e+000,0.000000e+000,0.000000e+000,0,,0,
1524031656.816,,0.000000e+000,3.499872e+001,-1.519991e-006,0.000000e+000,3,4.161246e-001,0.000000e+000,,,,,,,,,,,,,,32,1,4.000000e+000,1.560211e-003,0.000000e+000,0,,0,
1524031694.952,,0.000000e+000,3.499911e+001,-1.466843e-006,0.000000e+000,3,3.743710e-001,0.000000e+000,,,,,,,,,,,,,,32,1,4.000000e+000,7.820129e-004,0.000000e+000,0,,0,
1524031733.370,,0.000000e+000,3.500028e+001,-1.465366e-006,0.000000e+000,3,3.796390e-001,0.000000e+000,,,,,,,,,,,,,,32,1,4.000000e+000,1.560211e-003,0.000000e+000,0,,0,
1524031771.450,,0.000000e+000,3.499950e+001,-1.484620e-006,0.000000e+000,3,3.858853e-001,0.000000e+000,,,,,,,,,,,,,,32,1,4.000000e+000,0.000000e+000,0.000000e+000,0,,0,
1524031809.713,,0.000000e+000,3.500028e+001,-1.459279e-006,0.000000e+000,3,3.884240e-001,0.000000e+000,,,,,,,,,,,,,,32,1,4.000000e+000,1.560211e-003,0.000000e+000,0,,0,
1524031848.201,,0.000000e+000,3.499989e+001,-1.392928e-006,0.000000e+000,3,3.478482e-001,0.000000e+000,,,,,,,,,,,,,,32,1,4.000000e+000,7.781982e-004,0.000000e+000,0,,0,
1524031886.887,,0.000000e+000,3.499911e+001,-1.472069e-006,0.000000e+000,3,3.929844e-001,0.000000e+000,,,,,,,,,,,,,,32,1,4.000000e+000,7.820129e-004,0.000000e+000,0,,0,
1524031923.672,,0.000000e+000,3.499950e+001,-1.443732e-006,0.000000e+000,3,3.436537e-001,0.000000e+000,,,,,,,,,,,,,,32,1,4.000000e+000,1.560211e-003,0.000000e+000,0,,0,
1524031962.295,,0.000000e+000,3.500145e+001,-1.437667e-006,0.000000e+000,3,3.596145e-001,0.000000e+000,,,,,,,,,,,,,,32,1,4.000000e+000,2.349854e-003,0.000000e+000,0,,0,
1524032000.383,,0.000000e+000,3.499833e+001,-1.426596e-006,0.000000e+000,3,3.610184e-001,0.000000e+000,,,,,,,,,,,,,,32,1,4.000000e+000,7.781982e-004,0.000000e+000,0,,0,
1524032038.419,,0.000000e+000,3.499872e+001,-1.389950e-006,0.000000e+000,3,3.427770e-001,0.000000e+000,,,,,,,,,,,,,,32,1,4.000000e+000,1.560211e-003,0.000000e+000,0,,0,
1524032075.972,,0.000000e+000,3.499911e+001,-1.413305e-006,0.000000e+000,3,3.571114e-001,0.000000e+000,,,,,,,,,,,,,,32,1,4.000000e+000,2.338409e-003,0.000000e+000,0,,0,
1524032114.033,,0.000000e+000,3.499989e+001,-1.385356e-006,0.000000e+000,3,3.462655e-001,0.000000e+000,,,,,,,,,,,,,,32,1,4.000000e+000,7.781982e-004,0.000000e+000,0,,0,
1524032152.111,,0.000000e+000,3.499950e+001,-1.365034e-006,0.000000e+000,3,3.406575e-001,0.000000e+000,,,,,,,,,,,,,,32,1,4.000000e+000,0.000000e+000,0.000000e+000,0,,0,
1524032190.179,,0.000000e+000,3.499911e+001,-1.360674e-006,0.000000e+000,3,3.395523e-001,0.000000e+000,,,,,,,,,,,,,,32,1,4.000000e+000,7.820129e-004,0.000000e+000,0,,0,
1524032228.199,,0.000000e+000,3.499950e+001,-1.374719e-006,0.000000e+000,3,3.538161e-001,0.000000e+000,,,,,,,,,,,,,,32,1,4.000000e+000,0.000000e+000,0.000000e+000,0,,0,
1524032266.210,,0.000000e+000,3.499911e+001,-1.357877e-006,0.000000e+000,3,3.377027e-001,0.000000e+000,,,,,,,,,,,,,,32,1,4.000000e+000,7.820129e-004,0.000000e+000,0,,0,
1524032303.775,,0.000000e+000,3.499911e+001,-1.373856e-006,0.000000e+000,3,3.302843e-001,0.000000e+000,,,,,,,,,,,,,,32,1,4.000000e+000,7.820129e-004,0.000000e+000,0,,0,
1524032341.829,,0.000000e+000,3.500067e+001,-1.326212e-006,0.000000e+000,3,3.293314e-001,0.000000e+000,,,,,,,,,,,,,,32,1,4.000000e+000,7.820129e-004,0.000000e+000,0,,0,
1524032379.909,,0.000000e+000,3.499989e+001,-1.314267e-006,0.000000e+000,3,3.081822e-001,0.000000e+000,,,,,,,,,,,,,,32,1,4.000000e+000,7.781982e-004,0.000000e+000,0,,0,
1524032417.335,,0.000000e+000,3.499911e+001,-1.308930e-006,0.000000e+000,3,3.029457e-001,0.000000e+000,,,,,,,,,,,,,,32,1,4.000000e+000,7.820129e-004,0.000000e+000,0,,0,
1524032455.505,,0.000000e+000,3.499872e+001,-1.301781e-006,0.000000e+000,3,3.109690e-001,0.000000e+000,,,,,,,,,,,,,,32,1,4.000000e+000,0.000000e+000,0.000000e+000,0,,0,
1524032493.523,,0.000000e+000,3.499911e+001,-1.299490e-006,0.000000e+000,3,3.050613e-001,0.000000e+000,,,,,,,,,,,,,,32,1,4.000000e+000,7.820129e-004,0.000000e+000,0,,0,
1524032531.374,,0.000000e+000,3.499911e+001,-1.286183e-006,0.000000e+000,3,2.812214e-001,0.000000e+000,,,,,,,,,,,,,,32,1,4.000000e+000,7.820129e-004,0.000000e+000,0,,0,
1524032569.312,,0.000000e+000,3.499950e+001,-1.273221e-006,0.000000e+000,3,2.855455e-001,0.000000e+000,,,,,,,,,,,,,,32,1,4.000000e+000,0.000000e+000,0.000000e+000,0,,0,
1524032608.867,,0.000000e+000,3.499989e+001,-1.259548e-006,0.000000e+000,3,2.633443e-001,0.000000e+000,,,,,,,,,,,,,,32,1,4.000000e+000,7.781982e-004,0.000000e+000,0,,0,
1524032646.765,,0.000000e+000,3.499872e+001,-1.249649e-006,0.000000e+000,3,2.790052e-001,0.000000e+000,,,,,,,,,,,,,,32,1,4.000000e+000,1.560211e-003,0.000000e+000,0,,0,
1524032684.666,,0.000000e+000,3.499872e+001,-1.245574e-006,0.000000e+000,3,2.496801e-001,0.000000e+000,,,,,,,,,,,,,,32,1,4.000000e+000,0.000000e+000,0.000000e+000,0,,0,
1524032723.022,,0.000000e+000,3.499950e+001,-1.233633e-006,0.000000e+000,3,2.548178e-001,0.000000e+000,,,,,,,,,,,,,,32,1,4.000000e+000,1.560211e-003,0.000000e+000,0,,0,
1524032760.992,,0.000000e+000,3.499989e+001,-1.210191e-006,0.000000e+000,3,2.529953e-001,0.000000e+000,,,,,,,,,,,,,,32,1,4.000000e+000,7.781982e-004,0.000000e+000,0,,0,
1524032799.090,,0.000000e+000,3.499950e+001,-1.277842e-006,0.000000e+000,3,3.217666e-001,0.000000e+000,,,,,,,,,,,,,,32,1,4.000000e+000,0.000000e+000,0.000000e+000,0,,0,
1524032837.161,,0.000000e+000,3.499989e+001,-1.223335e-006,0.000000e+000,3,2.709814e-001,0.000000e+000,,,,,,,,,,,,,,32,1,4.000000e+000,7.781982e-004,0.000000e+000,0,,0,
1524032875.739,,0.000000e+000,3.499950e+001,-1.197879e-006,0.000000e+000,3,2.724776e-001,0.000000e+000,,,,,,,,,,,,,,32,1,4.000000e+000,0.000000e+000,0.000000e+000,0,,0,
1524032913.792,,0.000000e+000,3.499950e+001,-1.189407e-006,0.000000e+000,3,2.370831e-001,0.000000e+000,,,,,,,,,,,,,,32,1,4.000000e+000,0.000000e+000,0.000000e+000,0,,0,
1524032950.755,,0.000000e+000,3.499950e+001,-1.193552e-006,0.000000e+000,3,2.489370e-001,0.000000e+000,,,,,,,,,,,,,,32,1,4.000000e+000,0.000000e+000,0.000000e+000,0,,0,
1524032988.973,,0.000000e+000,3.499989e+001,-1.162518e-006,0.000000e+000,3,2.184307e-001,0.000000e+000,,,,,,,,,,,,,,32,1,4.000000e+000,7.781982e-004,0.000000e+000,0,,0,
1524033026.874,,0.000000e+000,3.499950e+001,-1.220514e-006,0.000000e+000,3,2.919929e-001,0.000000e+000,,,,,,,,,,,,,,32,1,4.000000e+000,1.560211e-003,0.000000e+000,0,,0,
1524033064.407,,0.000000e+000,3.499950e+001,-1.172533e-006,0.000000e+000,3,2.425782e-001,0.000000e+000,,,,,,,,,,,,,,32,1,4.000000e+000,0.000000e+000,0.000000e+000,0,,0,
1524033102.482,,0.000000e+000,3.499950e+001,-1.160225e-006,0.000000e+000,3,2.018846e-001,0.000000e+000,,,,,,,,,,,,,,32,1,4.000000e+000,1.560211e-003,0.000000e+000,0,,0,
1524033140.545,,0.000000e+000,3.499911e+001,-1.152788e-006,0.000000e+000,3,2.043907e-001,0.000000e+000,,,,,,,,,,,,,,32,1,4.000000e+000,7.820129e-004,0.000000e+000,0,,0,
1524033178.338,,0.000000e+000,3.499950e+001,-1.132218e-006,0.000000e+000,3,1.749217e-001,0.000000e+000,,,,,,,,,,,,,,32,1,4.000000e+000,0.000000e+000,0.000000e+000,0,,0,
1524033216.144,,0.000000e+000,3.499950e+001,-1.134778e-006,0.000000e+000,3,1.658178e-001,0.000000e+000,,,,,,,,,,,,,,32,1,4.000000e+000,0.000000e+000,0.000000e+000,0,,0,
1524033254.027,,0.000000e+000,3.499754e+001,-1.110148e-006,0.000000e+000,3,1.949052e-001,0.000000e+000,,,,,,,,,,,,,,32,1,4.000000e+000,2.349854e-003,0.000000e+000,0,,0,
1524033292.247,,0.000000e+000,3.499989e+001,-1.123174e-006,0.000000e+000,3,1.839046e-001,0.000000e+000,,,,,,,,,,,,,,32,1,4.000000e+000,7.781982e-004,0.000000e+000,0,,0,
1524033330.310,,0.000000e+000,3.499911e+001,-1.102629e-006,0.000000e+000,3,1.833431e-001,0.000000e+000,,,,,,,,,,,,,,32,1,4.000000e+000,7.820129e-004,0.000000e+000,0,,0,
1524033368.354,,0.000000e+000,3.499950e+001,-1.072871e-006,0.000000e+000,3,1.502104e-001,0.000000e+000,,,,,,,,,,,,,,32,1,4.000000e+000,0.000000e+000,0.000000e+000,0,,0,
1524033406.382,,0.000000e+000,3.499950e+001,-1.083390e-006,0.000000e+000,3,1.521498e-001,0.000000e+000,,,,,,,,,,,,,,32,1,4.000000e+000,0.000000e+000,0.000000e+000,0,,0,
1524033444.480,,0.000000e+000,3.499833e+001,-1.090260e-006,0.000000e+000,3,1.768639e-001,0.000000e+000,,,,,,,,,,,,,,32,1,4.000000e+000,2.349854e-003,0.000000e+000,0,,0,
1524033482.535,,0.000000e+000,3.499833e+001,-1.090953e-006,0.000000e+000,3,1.767350e-001,0.000000e+000,,,,,,,,,,,,,,32,1,4.000000e+000,7.781982e-004,0.000000e+000,0,,0,
1524033520.208,,0.000000e+000,3.499872e+001,-1.110273e-006,0.000000e+000,3,1.875489e-001,0.000000e+000,,,,,,,,,,,,,,32,1,4.000000e+000,1.560211e-003,0.000000e+000,0,,0,
1524033558.096,,0.000000e+000,3.499911e+001,-1.046450e-006,0.000000e+000,3,1.362931e-001,0.000000e+000,,,,,,,,,,,,,,32,1,4.000000e+000,7.820129e-004,0.000000e+000,0,,0,
1524033596.179,,0.000000e+000,3.500028e+001,-1.055473e-006,0.000000e+000,3,1.382887e-001,0.000000e+000,,,,,,,,,,,,,,32,1,4.000000e+000,1.560211e-003,0.000000e+000,0,,0,
1524033634.238,,0.000000e+000,3.499950e+001,-1.049130e-006,0.000000e+000,3,1.176347e-001,0.000000e+000,,,,,,,,,,,,,,32,1,4.000000e+000,0.000000e+000,0.000000e+000,0,,0,
1524033672.303,,0.000000e+000,3.499872e+001,-1.038613e-006,0.000000e+000,3,1.369800e-001,0.000000e+000,,,,,,,,,,,,,,32,1,4.000000e+000,1.560211e-003,0.000000e+000,0,,0,
1524033710.869,,0.000000e+000,3.499872e+001,-1.052604e-006,0.000000e+000,3,1.281898e-001,0.000000e+000,,,,,,,,,,,,,,32,1,4.000000e+000,0.000000e+000,0.000000e+000,0,,0,
1524033747.844,,0.000000e+000,3.499989e+001,-1.104362e-006,0.000000e+000,3,2.231841e-001,0.000000e+000,,,,,,,,,,,,,,32,1,4.000000e+000,7.781982e-004,0.000000e+000,0,,0,
1524033785.527,,0.000000e+000,3.499833e+001,-1.036832e-006,0.000000e+000,3,1.283992e-001,0.000000e+000,,,,,,,,,,,,,,32,1,4.000000e+000,7.781982e-004,0.000000e+000,0,,0,
1524033823.413,,0.000000e+000,3.499911e+001,-1.006485e-006,0.000000e+000,3,8.166436e-002,0.000000e+000,,,,,,,,,,,,,,32,1,4.000000e+000,2.338409e-003,0.000000e+000,0,,0,
1524033861.513,,0.000000e+000,3.500028e+001,-9.945732e-007,0.000000e+000,3,8.262441e-002,0.000000e+000,,,,,,,,,,,,,,32,1,4.000000e+000,0.000000e+000,0.000000e+000,0,,0,
1524033899.541,,0.000000e+000,3.499872e+001,-1.021469e-006,0.000000e+000,3,9.682594e-002,0.000000e+000,,,,,,,,,,,,,,32,1,4.000000e+000,0.000000e+000,0.000000e+000,0,,0,
1524033937.637,,0.000000e+000,3.499872e+001,-9.828199e-007,0.000000e+000,3,9.189398e-002,0.000000e+000,,,,,,,,,,,,,,32,1,4.000000e+000,1.560211e-003,0.000000e+000,0,,0,
1524033975.695,,0.000000e+000,3.499872e+001,-1.017462e-006,0.000000e+000,3,1.322422e-001,0.000000e+000,,,,,,,,,,,,,,32,1,4.000000e+000,0.000000e+000,0.000000e+000,0,,0,
1524034013.758,,0.000000e+000,3.499911e+001,-9.976599e-007,0.000000e+000,3,7.518227e-002,0.000000e+000,,,,,,,,,,,,,,32,1,4.000000e+000,2.338409e-003,0.000000e+000,0,,0,
1524034051.314,,0.000000e+000,3.499950e+001,-9.805525e-007,0.000000e+000,3,8.162399e-002,0.000000e+000,,,,,,,,,,,,,,32,1,4.000000e+000,0.000000e+000,0.000000e+000,0,,0,
1524034088.942,,0.000000e+000,3.499911e+001,-9.613624e-007,0.000000e+000,3,7.125065e-002,0.000000e+000,,,,,,,,,,,,,,32,1,4.000000e+000,7.820129e-004,0.000000e+000,0,,0,
1524034127.075,,0.000000e+000,3.499950e+001,-9.709976e-007,0.000000e+000,3,2.322966e-002,0.000000e+000,,,,,,,,,,,,,,32,1,4.000000e+000,0.000000e+000,0.000000e+000,0,,0,
1524034164.978,,0.000000e+000,3.499911e+001,-9.242904e-007,0.000000e+000,3,1.441622e-002,0.000000e+000,,,,,,,,,,,,,,32,1,4.000000e+000,7.820129e-004,0.000000e+000,0,,0,
1524034202.583,,0.000000e+000,3.499911e+001,-9.405261e-007,0.000000e+000,3,2.929389e-002,0.000000e+000,,,,,,,,,,,,,,32,1,4.000000e+000,7.820129e-004,0.000000e+000,0,,0,
1524034240.641,,0.000000e+000,3.499911e+001,-9.427669e-007,0.000000e+000,3,2.320405e-002,0.000000e+000,,,,,,,,,,,,,,32,1,4.000000e+000,7.820129e-004,0.000000e+000,0,,0,
1524034278.702,,0.000000e+000,3.499872e+001,-9.351555e-007,0.000000e+000,3,3.129488e-002,0.000000e+000,,,,,,,,,,,,,,32,1,4.000000e+000,0.000000e+000,0.000000e+000,0,,0,
1524034316.620,,0.000000e+000,3.499911e+001,-9.361891e-007,0.000000e+000,3,2.224919e-004,0.000000e+000,,,,,,,,,,,,,,32,1,4.000000e+000,7.820129e-004,0.000000e+000,0,,0,
1524034354.948,,0.000000e+000,3.499950e+001,-9.009689e-007,0.000000e+000,3,5.871524e-003,0.000000e+000,,,,,,,,,,,,,,32,1,4.000000e+000,0.000000e+000,0.000000e+000,0,,0,
1524034393.286,,0.000000e+000,3.499911e+001,-9.019493e-007,0.000000e+000,3,0.000000e+000,0.000000e+000,,,,,,,,,,,,,,32,1,4.000000e+000,7.820129e-004,0.000000e+000,0,,0,
1524034431.064,,0.000000e+000,3.499833e+001,-9.059560e-007,0.000000e+000,3,0.000000e+000,0.000000e+000,,,,,,,,,,,,,,32,1,4.000000e+000,7.781982e-004,0.000000e+000,0,,0,
1524034468.855,,0.000000e+000,3.499833e+001,-9.141525e-007,0.000000e+000,3,1.251323e-002,0.000000e+000,,,,,,,,,,,,,,32,1,4.000000e+000,7.781982e-004,0.000000e+000,0,,0,
1524034506.403,,0.000000e+000,3.499989e+001,-9.082236e-007,0.000000e+000,3,0.000000e+000,0.000000e+000,,,,,,,,,,,,,,32,1,4.000000e+000,2.342224e-003,0.000000e+000,0,,0,
1524034519.053,,0.000000e+000,3.499911e+001,-8.840360e-007,0.000000e+000,3,0.000000e+000,0.000000e+000,,,,,,,,,,,,,,32,1,4.000000e+000,7.820129e-004,0.000000e+000,0,,0,