File: Input/MFn1_VRMac_33K_6000s_VRMde_35K.dc.dat
[Header]
TITLE,MPMS DC Measurement
BYAPP,MPMS Measurement,2.1,Summary
FILEOPENTIME, 1524133252.427000 4/19/2018, 4:20:52 AM

INFO, APPNAME, MPMS MultiVu Application, Revision 1.61,  Build 082

INFO, NAME, MFn1
INFO, WEIGHT, 1.000
INFO, AREA, 1.000
INFO, LENGTH, 1.000
INFO, SHAPE, 0
INFO, COMMENT,
INFO, SEQUENCE FILE: VRMac_33K_6000s_VRMde_35K.seq


INFO, BACKGROUND DATA FILE:, None


STARTUPAXIS,X,4,LINEAR,AUTO,0.000000,0.000000
STARTUPAXIS,Y1,5,LINEAR,AUTO,0.000000,0.000000


STARTUPGROUP,Longitudinal
FIELDGROUP,Longitudinal,1,2,3,4,5,6,7,8,9,15,16,17,18,27,28
FIELDGROUP,Transverse,1,2,3,4,10,11,12,13,14,19,20,21,22,27,28

PLOT_APPEARANCE,ALL,HORZ_GRID_ON,VERT_GRID_ON,MARKERS_AND_LINES

[Data]
Time,Comment,Field (Oe),Temperature (K),Long Moment (emu),Long Scan Std Dev,Long Algorithm,Long Reg Fit,Long Percent Error (%),Trans Moment (emu),Trans Scan Std Dev,Trans Algorithm,Trans Reg Fit,Trans Percent Error (%),Long Moment [w/o ABS] (emu),Long Scan Std Dev [w/o ABS],Long Reg Fit [w/o ABS],Long Percent Error [w/o ABS] (%),Trans Moment [w/o ABS] (emu),Trans Scan Std Dev [w/o ABS],Trans Reg Fit [w/o ABS],Trans Percent Error [w/o ABS] (%),Points per Scan,Scans per Measurement,Scan Length (cm),Delta Temp (K),Rot Position (deg),Error,EC Comp. Running,Using ABS,
1524133252.427,,0.000000e+000,3.500224e+001,-9.364212e-006,0.000000e+000,3,8.988621e-001,0.000000e+000,,,,,,,,,,,,,,32,1,4.000000e+000,2.349854e-003,0.000000e+000,0,,0,
1524133290.802,,0.000000e+000,3.499911e+001,-8.199976e-006,0.000000e+000,3,8.887144e-001,0.000000e+000,,,,,,,,,,,,,,32,1,4.000000e+000,2.338409e-003,0.000000e+000,0,,0,
1524133328.890,,0.000000e+000,3.499950e+001,-7.262965e-006,0.000000e+000,3,8.724038e-001,0.000000e+000,,,,,,,,,,,,,,32,1,4.000000e+000,1.560211e-003,0.000000e+000,0,,0,
1524133367.128,,0.000000e+000,3.499911e+001,-6.534382e-006,0.000000e+000,3,8.637678e-001,0.000000e+000,,,,,,,,,,,,,,32,1,4.000000e+000,7.820129e-004,0.000000e+000,0,,0,
1524133404.917,,0.000000e+000,3.499833e+001,-5.867873e-006,0.000000e+000,3,8.527668e-001,0.000000e+000,,,,,,,,,,,,,,32,1,4.000000e+000,7.781982e-004,0.000000e+000,0,,0,
1524133443.002,,0.000000e+000,3.499950e+001,-5.344077e-006,0.000000e+000,3,8.343263e-001,0.000000e+000,,,,,,,,,,,,,,32,1,4.000000e+000,1.560211e-003,0.000000e+000,0,,0,
1524133481.023,,0.000000e+000,3.499911e+001,-4.925878e-006,0.000000e+000,3,8.157909e-001,0.000000e+000,,,,,,,,,,,,,,32,1,4.000000e+000,7.820129e-004,0.000000e+000,0,,0,
1524133518.708,,0.000000e+000,3.499950e+001,-4.547964e-006,0.000000e+000,3,8.015316e-001,0.000000e+000,,,,,,,,,,,,,,32,1,4.000000e+000,0.000000e+000,0.000000e+000,0,,0,
1524133556.481,,0.000000e+000,3.499871e+001,-4.170658e-006,0.000000e+000,3,7.863583e-001,0.000000e+000,,,,,,,,,,,,,,32,1,4.000000e+000,6.248474e-003,0.000000e+000,0,,0,
1524133619.230,,0.000000e+000,3.499911e+001,-3.635507e-006,0.000000e+000,3,7.527283e-001,0.000000e+000,,,,,,,,,,,,,,32,1,4.000000e+000,7.820129e-004,0.000000e+000,0,,0,
1524133657.763,,0.000000e+000,3.499950e+001,-3.405672e-006,0.000000e+000,3,7.505717e-001,0.000000e+000,,,,,,,,,,,,,,32,1,4.000000e+000,1.560211e-003,0.000000e+000,0,,0,
1524133695.761,,0.000000e+000,3.499833e+001,-3.158056e-006,0.000000e+000,3,7.182385e-001,0.000000e+000,,,,,,,,,,,,,,32,1,4.000000e+000,7.781982e-004,0.000000e+000,0,,0,
1524133733.616,,0.000000e+000,3.499911e+001,-2.928542e-006,0.000000e+000,3,6.793428e-001,0.000000e+000,,,,,,,,,,,,,,32,1,4.000000e+000,7.820129e-004,0.000000e+000,0,,0,
1524133771.707,,0.000000e+000,3.499989e+001,-2.775037e-006,0.000000e+000,3,6.621265e-001,0.000000e+000,,,,,,,,,,,,,,32,1,4.000000e+000,7.781982e-004,0.000000e+000,0,,0,
1524133810.440,,0.000000e+000,3.499911e+001,-2.582140e-006,0.000000e+000,3,6.582442e-001,0.000000e+000,,,,,,,,,,,,,,32,1,4.000000e+000,7.820129e-004,0.000000e+000,0,,0,
1524133847.456,,0.000000e+000,3.499911e+001,-2.397772e-006,0.000000e+000,3,5.976357e-001,0.000000e+000,,,,,,,,,,,,,,32,1,4.000000e+000,7.820129e-004,0.000000e+000,0,,0,
1524133886.091,,0.000000e+000,3.500028e+001,-2.274501e-006,0.000000e+000,3,6.083120e-001,0.000000e+000,,,,,,,,,,,,,,32,1,4.000000e+000,0.000000e+000,0.000000e+000,0,,0,
1524133923.294,,0.000000e+000,3.499911e+001,-2.176665e-006,0.000000e+000,3,5.820858e-001,0.000000e+000,,,,,,,,,,,,,,32,1,4.000000e+000,7.820129e-004,0.000000e+000,0,,0,
1524133961.362,,0.000000e+000,3.499872e+001,-2.052619e-006,0.000000e+000,3,5.483510e-001,0.000000e+000,,,,,,,,,,,,,,32,1,4.000000e+000,0.000000e+000,0.000000e+000,0,,0,
1524134000.928,,0.000000e+000,3.499872e+001,-1.797235e-006,0.000000e+000,3,4.939836e-001,0.000000e+000,,,,,,,,,,,,,,32,1,4.000000e+000,1.560211e-003,0.000000e+000,0,,0,
1524134038.953,,0.000000e+000,3.499950e+001,-1.751547e-006,0.000000e+000,3,4.447606e-001,0.000000e+000,,,,,,,,,,,,,,32,1,4.000000e+000,0.000000e+000,0.000000e+000,0,,0,
1524134076.636,,0.000000e+000,3.499872e+001,-1.653374e-006,0.000000e+000,3,4.481302e-001,0.000000e+000,,,,,,,,,,,,,,32,1,4.000000e+000,1.560211e-003,0.000000e+000,0,,0,
1524134114.777,,0.000000e+000,3.499911e+001,-1.570406e-006,0.000000e+000,3,4.152275e-001,0.000000e+000,,,,,,,,,,,,,,32,1,4.000000e+000,7.820129e-004,0.000000e+000,0,,0,
1524134153.028,,0.000000e+000,3.499911e+001,-1.476259e-006,0.000000e+000,3,3.948417e-001,0.000000e+000,,,,,,,,,,,,,,32,1,4.000000e+000,7.820129e-004,0.000000e+000,0,,0,
1524134190.886,,0.000000e+000,3.499989e+001,-1.344162e-006,0.000000e+000,3,3.153638e-001,0.000000e+000,,,,,,,,,,,,,,32,1,4.000000e+000,7.781982e-004,0.000000e+000,0,,0,
1524134229.261,,0.000000e+000,3.499872e+001,-1.263567e-006,0.000000e+000,3,3.012383e-001,0.000000e+000,,,,,,,,,,,,,,32,1,4.000000e+000,0.000000e+000,0.000000e+000,0,,0,
1524134266.637,,0.000000e+000,3.499989e+001,-1.282447e-006,0.000000e+000,3,2.563726e-001,0.000000e+000,,,,,,,,,,,,,,32,1,4.000000e+000,7.781982e-004,0.000000e+000,0,,0,
1524134305.155,,0.000000e+000,3.499911e+001,-1.195301e-006,0.000000e+000,3,2.377735e-001,0.000000e+000,,,,,,,,,,,,,,32,1,4.000000e+000,7.820129e-004,0.000000e+000,0,,0,
1524134343.438,,0.000000e+000,3.500028e+001,-1.091836e-006,0.000000e+000,3,1.234102e-001,0.000000e+000,,,,,,,,,,,,,,32,1,4.000000e+000,1.560211e-003,0.000000e+000,0,,0,
1524134381.551,,0.000000e+000,3.499638e+001,-1.026858e-006,0.000000e+000,3,1.008916e-001,0.000000e+000,,,,,,,,,,,,,,32,1,4.000000e+000,4.688263e-003,0.000000e+000,0,,0,
1524134419.086,,0.000000e+000,3.499911e+001,-9.650669e-007,0.000000e+000,3,6.583898e-002,0.000000e+000,,,,,,,,,,,,,,32,1,4.000000e+000,7.820129e-004,0.000000e+000,0,,0,
1524134457.210,,0.000000e+000,3.499950e+001,-8.921706e-007,0.000000e+000,3,0.000000e+000,0.000000e+000,,,,,,,,,,,,,,32,1,4.000000e+000,0.000000e+000,0.000000e+000,0,,0,
1524134495.395,,0.000000e+000,3.499911e+001,-8.590909e-007,0.000000e+000,3,0.000000e+000,0.000000e+000,,,,,,,,,,,,,,32,1,4.000000e+000,7.820129e-004,0.000000e+000,0,,0,
1524134534.021,,0.000000e+000,3.499950e+001,-7.457259e-007,0.000000e+000,3,0.000000e+000,0.000000e+000,,,,,,,,,,,,,,32,1,4.000000e+000,1.560211e-003,0.000000e+000,0,,0,
1524134571.514,,0.000000e+000,3.499872e+001,-7.225369e-007,0.000000e+000,3,0.000000e+000,0.000000e+000,,,,,,,,,,,,,,32,1,4.000000e+000,0.000000e+000,0.000000e+000,0,,0,
1524134609.107,,0.000000e+000,3.499911e+001,-7.079567e-007,0.000000e+000,3,0.000000e+000,0.000000e+000,,,,,,,,,,,,,,32,1,4.000000e+000,7.820129e-004,0.000000e+000,0,,0,
1524134647.192,,0.000000e+000,3.499872e+001,-6.760339e-007,0.000000e+000,3,0.000000e+000,0.000000e+000,,,,,,,,,,,,,,32,1,4.000000e+000,0.000000e+000,0.000000e+000,0,,0,
1524134685.275,,0.000000e+000,3.499911e+001,-6.617792e-007,0.000000e+000,3,0.000000e+000,0.000000e+000,,,,,,,,,,,,,,32,1,4.000000e+000,7.820129e-004,0.000000e+000,0,,0,
1524134723.326,,0.000000e+000,3.499872e+001,-6.194871e-007,0.000000e+000,3,0.000000e+000,0.000000e+000,,,,,,,,,,,,,,32,1,4.000000e+000,1.560211e-003,0.000000e+000,0,,0,
1524134761.481,,0.000000e+000,3.499950e+001,-5.248867e-007,0.000000e+000,3,0.000000e+000,0.000000e+000,,,,,,,,,,,,,,32,1,4.000000e+000,0.000000e+000,0.000000e+000,0,,0,
1524134800.060,,0.000000e+000,3.499911e+001,-4.636148e-007,0.000000e+000,3,0.000000e+000,0.000000e+000,,,,,,,,,,,,,,32,1,4.000000e+000,7.820129e-004,0.000000e+000,0,,0,
1524134837.608,,0.000000e+000,3.499950e+001,-4.691562e-007,0.000000e+000,3,0.000000e+000,0.000000e+000,,,,,,,,,,,,,,32,1,4.000000e+000,1.560211e-003,0.000000e+000,0,,0,
1524134875.683,,0.000000e+000,3.499872e+001,-2.969321e-007,0.000000e+000,3,0.000000e+000,0.000000e+000,,,,,,,,,,,,,,32,1,4.000000e+000,1.560211e-003,0.000000e+000,0,,0,
1524134913.761,,0.000000e+000,3.499950e+001,9.056386e-007,0.000000e+000,3,2.620013e-002,0.000000e+000,,,,,,,,,,,,,,32,1,4.000000e+000,1.560211e-003,0.000000e+000,0,,0,
1524134953.358,,0.000000e+000,3.499989e+001,4.316443e-007,0.000000e+000,3,0.000000e+000,0.000000e+000,,,,,,,,,,,,,,32,1,4.000000e+000,7.781982e-004,0.000000e+000,0,,0,
1524134990.708,,0.000000e+000,3.499911e+001,7.218588e-007,0.000000e+000,3,0.000000e+000,0.000000e+000,,,,,,,,,,,,,,32,1,4.000000e+000,7.820129e-004,0.000000e+000,0,,0,
1524135030.659,,0.000000e+000,3.499950e+001,6.304128e-007,0.000000e+000,3,0.000000e+000,0.000000e+000,,,,,,,,,,,,,,32,1,4.000000e+000,1.560211e-003,0.000000e+000,0,,0,
1524135067.852,,0.000000e+000,3.499911e+001,7.246711e-007,0.000000e+000,3,0.000000e+000,0.000000e+000,,,,,,,,,,,,,,32,1,4.000000e+000,7.820129e-004,0.000000e+000,0,,0,
1524135107.039,,0.000000e+000,3.500028e+001,8.807792e-007,0.000000e+000,3,6.029299e-003,0.000000e+000,,,,,,,,,,,,,,32,1,4.000000e+000,1.560211e-003,0.000000e+000,0,,0,
1524135144.907,,0.000000e+000,3.499833e+001,6.161620e-007,0.000000e+000,3,0.000000e+000,0.000000e+000,,,,,,,,,,,,,,32,1,4.000000e+000,7.781982e-004,0.000000e+000,0,,0,
1524135186.143,,0.000000e+000,3.499989e+001,-1.387758e-007,0.000000e+000,2,0.000000e+000,0.000000e+000,,,,,,,,,,,,,,32,1,4.000000e+000,7.781982e-004,0.000000e+000,0,,0,
1524135227.230,,0.000000e+000,3.500028e+001,-8.267347e-008,0.000000e+000,2,0.000000e+000,0.000000e+000,,,,,,,,,,,,,,32,1,4.000000e+000,3.120422e-003,0.000000e+000,0,,0,
1524135267.589,,0.000000e+000,3.499872e+001,-9.006017e-008,0.000000e+000,2,0.000000e+000,0.000000e+000,,,,,,,,,,,,,,32,1,4.000000e+000,0.000000e+000,0.000000e+000,0,,0,
1524135308.575,,0.000000e+000,3.499872e+001,8.049550e-007,0.000000e+000,3,0.000000e+000,0.000000e+000,,,,,,,,,,,,,,32,1,4.000000e+000,0.000000e+000,0.000000e+000,0,,0,
1524135348.879,,0.000000e+000,3.499950e+001,-5.041442e-008,0.000000e+000,2,0.000000e+000,0.000000e+000,,,,,,,,,,,,,,32,1,4.000000e+000,0.000000e+000,0.000000e+000,0,,0,
1524135388.978,,0.000000e+000,3.499911e+001,1.358634e-007,0.000000e+000,3,0.000000e+000,0.000000e+000,,,,,,,,,,,,,,32,1,4.000000e+000,7.820129e-004,0.000000e+000,0,,0,
1524135427.273,,0.000000e+000,3.499911e+001,1.012442e-007,0.000000e+000,3,0.000000e+000,0.000000e+000,,,,,,,,,,,,,,32,1,4.000000e+000,7.820129e-004,0.000000e+000,0,,0,
1524135465.006,,0.000000e+000,3.499793e+001,7.668378e-007,0.000000e+000,3,0.000000e+000,0.000000e+000,,,,,,,,,,,,,,32,1,4.000000e+000,1.567841e-003,0.000000e+000,0,,0,
1524135504.803,,0.000000e+000,3.499793e+001,9.462721e-007,0.000000e+000,3,2.776343e-002,0.000000e+000,,,,,,,,,,,,,,32,1,4.000000e+000,3.131866e-003,0.000000e+000,0,,0,
1524135545.024,,0.000000e+000,3.499911e+001,3.693794e-008,0.000000e+000,2,0.000000e+000,0.000000e+000,,,,,,,,,,,,,,32,1,4.000000e+000,7.820129e-004,0.000000e+000,0,,0,
1524135583.102,,0.000000e+000,3.499950e+001,9.243810e-007,0.000000e+000,3,7.877632e-002,0.000000e+000,,,,,,,,,,,,,,32,1,4.000000e+000,0.000000e+000,0.000000e+000,0,,0,
1524135624.661,,0.000000e+000,3.500067e+001,-9.713849e-007,0.000000e+000,3,6.198679e-002,0.000000e+000,,,,,,,,,,,,,,32,1,4.000000e+000,2.338409e-003,0.000000e+000,0,,0,
1524135665.684,,0.000000e+000,3.499911e+001,1.239916e-007,0.000000e+000,2,0.000000e+000,0.000000e+000,,,,,,,,,,,,,,32,1,4.000000e+000,7.820129e-004,0.000000e+000,0,,0,
1524135703.200,,0.000000e+000,3.499872e+001,8.369530e-008,0.000000e+000,3,0.000000e+000,0.000000e+000,,,,,,,,,,,,,,32,1,4.000000e+000,1.560211e-003,0.000000e+000,0,,0,
1524135741.285,,0.000000e+000,3.499911e+001,9.085330e-007,0.000000e+000,3,3.432810e-002,0.000000e+000,,,,,,,,,,,,,,32,1,4.000000e+000,7.820129e-004,0.000000e+000,0,,0,
1524135778.433,,0.000000e+000,3.499950e+001,8.378548e-007,0.000000e+000,3,0.000000e+000,0.000000e+000,,,,,,,,,,,,,,32,1,4.000000e+000,0.000000e+000,0.000000e+000,0,,0,
1524135818.827,,0.000000e+000,3.499950e+001,8.626910e-007,0.000000e+000,3,0.000000e+000,0.000000e+000,,,,,,,,,,,,,,32,1,4.000000e+000,1.560211e-003,0.000000e+000,0,,0,
1524135859.972,,0.000000e+000,3.499833e+001,2.336006e-007,0.000000e+000,2,0.000000e+000,0.000000e+000,,,,,,,,,,,,,,32,1,4.000000e+000,7.781982e-004,0.000000e+000,0,,0,
1524135898.923,,0.000000e+000,3.499833e+001,-2.230382e-007,0.000000e+000,3,0.000000e+000,0.000000e+000,,,,,,,,,,,,,,32,1,4.000000e+000,7.781982e-004,0.000000e+000,0,,0,
1524135941.184,,0.000000e+000,3.499989e+001,2.264490e-007,0.000000e+000,2,0.000000e+000,0.000000e+000,,,,,,,,,,,,,,32,1,4.000000e+000,7.781982e-004,0.000000e+000,0,,0,
1524135981.445,,0.000000e+000,3.500067e+001,-2.866384e-007,0.000000e+000,3,0.000000e+000,0.000000e+000,,,,,,,,,,,,,,32,1,4.000000e+000,3.910065e-003,0.000000e+000,0,,0,
1524136021.666,,0.000000e+000,3.500028e+001,-3.071353e-007,0.000000e+000,3,0.000000e+000,0.000000e+000,,,,,,,,,,,,,,32,1,4.000000e+000,3.120422e-003,0.000000e+000,0,,0,
1524136061.043,,0.000000e+000,3.499911e+001,-3.775547e-007,0.000000e+000,3,0.000000e+000,0.000000e+000,,,,,,,,,,,,,,32,1,4.000000e+000,2.338409e-003,0.000000e+000,0,,0,
1524136098.901,,0.000000e+000,3.499833e+001,-3.072249e-007,0.000000e+000,3,0.000000e+000,0.000000e+000,,,,,,,,,,,,,,32,1,4.000000e+000,7.781982e-004,0.000000e+000,0,,0,
1524136138.289,,0.000000e+000,3.499872e+001,-3.484875e-007,0.000000e+000,3,0.000000e+000,0.000000e+000,,,,,,,,,,,,,,32,1,4.000000e+000,0.000000e+000,0.000000e+000,0,,0,
1524136178.353,,0.000000e+000,3.499950e+001,3.593848e-007,0.000000e+000,2,0.000000e+000,0.000000e+000,,,,,,,,,,,,,,32,1,4.000000e+000,0.000000e+000,0.000000e+000,0,,0,
1524136215.868,,0.000000e+000,3.499911e+001,-3.520705e-007,0.000000e+000,3,0.000000e+000,0.000000e+000,,,,,,,,,,,,,,32,1,4.000000e+000,7.820129e-004,0.000000e+000,0,,0,
1524136253.576,,0.000000e+000,3.500028e+001,-3.607734e-007,0.000000e+000,3,0.000000e+000,0.000000e+000,,,,,,,,,,,,,,32,1,4.000000e+000,3.120422e-003,0.000000e+000,0,,0,
1524136295.259,,0.000000e+000,3.499950e+001,4.195198e-007,0.000000e+000,2,0.000000e+000,0.000000e+000,,,,,,,,,,,,,,32,1,4.000000e+000,0.000000e+000,0.000000e+000,0,,0,
1524136336.619,,0.000000e+000,3.500067e+001,4.342422e-007,0.000000e+000,2,0.000000e+000,0.000000e+000,,,,,,,,,,,,,,32,1,4.000000e+000,3.910065e-003,0.000000e+000,0,,0,
1524136378.780,,0.000000e+000,3.500106e+001,4.365625e-007,0.000000e+000,2,0.000000e+000,0.000000e+000,,,,,,,,,,,,,,32,1,4.000000e+000,1.560211e-003,0.000000e+000,0,,0,
1524136421.422,,0.000000e+000,3.499950e+001,4.610909e-007,0.000000e+000,2,0.000000e+000,0.000000e+000,,,,,,,,,,,,,,32,1,4.000000e+000,3.120422e-003,0.000000e+000,0,,0,
1524136464.926,,0.000000e+000,3.500067e+001,4.519249e-007,0.000000e+000,2,0.000000e+000,0.000000e+000,,,,,,,,,,,,,,32,1,4.000000e+000,7.820129e-004,0.000000e+000,0,,0,
1524136508.048,,0.000000e+000,3.499911e+001,5.232066e-007,0.000000e+000,2,0.000000e+000,0.000000e+000,,,,,,,,,,,,,,32,1,4.000000e+000,2.338409e-003,0.000000e+000,0,,0,
1524136549.340,,0.000000e+000,3.499911e+001,5.545447e-007,0.000000e+000,2,0.000000e+000,0.000000e+000,,,,,,,,,,,,,,32,1,4.000000e+000,7.820129e-004,0.000000e+000,0,,0,
1524136590.539,,0.000000e+000,3.499989e+001,5.122800e-007,0.000000e+000,2,0.000000e+000,0.000000e+000,,,,,,,,,,,,,,32,1,4.000000e+000,2.342224e-003,0.000000e+000,0,,0,
1524136633.436,,0.000000e+000,3.500067e+001,5.383453e-007,0.000000e+000,2,0.000000e+000,0.000000e+000,,,,,,,,,,,,,,32,1,4.000000e+000,8.609772e-003,0.000000e+000,0,,0,
1524136674.297,,0.000000e+000,3.500028e+001,5.188468e-007,0.000000e+000,2,0.000000e+000,0.000000e+000,,,,,,,,,,,,,,32,1,4.000000e+000,3.120422e-003,0.000000e+000,0,,0,
1524136715.651,,0.000000e+000,3.499989e+001,5.452444e-007,0.000000e+000,2,0.000000e+000,0.000000e+000,,,,,,,,,,,,,,32,1,4.000000e+000,7.781982e-004,0.000000e+000,0,,0,
1524136756.383,,0.000000e+000,3.500067e+001,4.987634e-007,0.000000e+000,2,0.000000e+000,0.000000e+000,,,,,,,,,,,,,,32,1,4.000000e+000,2.338409e-003,0.000000e+000,0,,0,
1524136796.524,,0.000000e+000,3.500028e+001,1.312404e-006,0.000000e+000,3,3.081432e-001,0.000000e+000,,,,,,,,,,,,,,32,1,4.000000e+000,3.120422e-003,0.000000e+000,0,,0,
1524136838.880,,0.000000e+000,3.499911e+001,5.589591e-007,0.000000e+000,2,0.000000e+000,0.000000e+000,,,,,,,,,,,,,,32,1,4.000000e+000,7.820129e-004,0.000000e+000,0,,0,
1524136879.049,,0.000000e+000,3.500067e+001,1.336359e-006,0.000000e+000,3,3.094489e-001,0.000000e+000,,,,,,,,,,,,,,32,1,4.000000e+000,2.338409e-003,0.000000e+000,0,,0,
1524136919.415,,0.000000e+000,3.499872e+001,1.251533e-006,0.000000e+000,3,2.507992e-001,0.000000e+000,,,,,,,,,,,,,,32,1,4.000000e+000,0.000000e+000,0.000000e+000,0,,0,
1524136957.226,,0.000000e+000,3.499833e+001,1.289305e-006,0.000000e+000,3,2.920599e-001,0.000000e+000,,,,,,,,,,,,,,32,1,4.000000e+000,7.781982e-004,0.000000e+000,0,,0,
1524136998.887,,0.000000e+000,3.499872e+001,5.768576e-007,0.000000e+000,2,0.000000e+000,0.000000e+000,,,,,,,,,,,,,,32,1,4.000000e+000,1.560211e-003,0.000000e+000,0,,0,
1524137035.948,,0.000000e+000,3.499911e+001,1.293314e-006,0.000000e+000,3,2.734580e-001,0.000000e+000,,,,,,,,,,,,,,32,1,4.000000e+000,7.820129e-004,0.000000e+000,0,,0,
1524137075.559,,0.000000e+000,3.499950e+001,1.412416e-006,0.000000e+000,3,3.276411e-001,0.000000e+000,,,,,,,,,,,,,,32,1,4.000000e+000,1.560211e-003,0.000000e+000,0,,0,
1524137113.642,,0.000000e+000,3.499950e+001,1.332606e-006,0.000000e+000,3,3.064795e-001,0.000000e+000,,,,,,,,,,,,,,32,1,4.000000e+000,1.560211e-003,0.000000e+000,0,,0,
1524137151.348,,0.000000e+000,3.499950e+001,1.384483e-006,0.000000e+000,3,3.692178e-001,0.000000e+000,,,,,,,,,,,,,,32,1,4.000000e+000,1.560211e-003,0.000000e+000,0,,0,
1524137189.313,,0.000000e+000,3.499911e+001,1.355318e-006,0.000000e+000,3,3.358129e-001,0.000000e+000,,,,,,,,,,,,,,32,1,4.000000e+000,2.338409e-003,0.000000e+000,0,,0,
1524137229.117,,0.000000e+000,3.499950e+001,1.407979e-006,0.000000e+000,3,3.557940e-001,0.000000e+000,,,,,,,,,,,,,,32,1,4.000000e+000,0.000000e+000,0.000000e+000,0,,0,
1524137268.375,,0.000000e+000,3.499989e+001,1.383620e-006,0.000000e+000,3,3.704996e-001,0.000000e+000,,,,,,,,,,,,,,32,1,4.000000e+000,7.781982e-004,0.000000e+000,0,,0,
1524137305.988,,0.000000e+000,3.499950e+001,1.373632e-006,0.000000e+000,3,3.463961e-001,0.000000e+000,,,,,,,,,,,,,,32,1,4.000000e+000,0.000000e+000,0.000000e+000,0,,0,
1524137344.021,,0.000000e+000,3.499911e+001,1.386839e-006,0.000000e+000,3,3.505053e-001,0.000000e+000,,,,,,,,,,,,,,32,1,4.000000e+000,7.820129e-004,0.000000e+000,0,,0,
1524137382.529,,0.000000e+000,3.499911e+001,1.326319e-006,0.000000e+000,3,3.086901e-001,0.000000e+000,,,,,,,,,,,,,,32,1,4.000000e+000,7.820129e-004,0.000000e+000,0,,0,
1524137420.637,,0.000000e+000,3.499911e+001,1.366118e-006,0.000000e+000,3,3.500969e-001,0.000000e+000,,,,,,,,,,,,,,32,1,4.000000e+000,7.820129e-004,0.000000e+000,0,,0,
1524137458.280,,0.000000e+000,3.499950e+001,1.423080e-006,0.000000e+000,3,3.715931e-001,0.000000e+000,,,,,,,,,,,,,,32,1,4.000000e+000,0.000000e+000,0.000000e+000,0,,0,
1524137496.368,,0.000000e+000,3.499950e+001,1.397626e-006,0.000000e+000,3,3.576881e-001,0.000000e+000,,,,,,,,,,,,,,32,1,4.000000e+000,0.000000e+000,0.000000e+000,0,,0,
1524137534.876,,0.000000e+000,3.499872e+001,1.398705e-006,0.000000e+000,3,3.594260e-001,0.000000e+000,,,,,,,,,,,,,,32,1,4.000000e+000,0.000000e+000,0.000000e+000,0,,0,
1524137572.987,,0.000000e+000,3.499911e+001,1.432975e-006,0.000000e+000,3,3.576180e-001,0.000000e+000,,,,,,,,,,,,,,32,1,4.000000e+000,7.820129e-004,0.000000e+000,0,,0,
1524137611.327,,0.000000e+000,3.499794e+001,1.455282e-006,0.000000e+000,3,3.716919e-001,0.000000e+000,,,,,,,,,,,,,,32,1,4.000000e+000,0.000000e+000,0.000000e+000,0,,0,
1524137649.350,,0.000000e+000,3.499754e+001,1.472297e-006,0.000000e+000,3,4.056484e-001,0.000000e+000,,,,,,,,,,,,,,32,1,4.000000e+000,3.910065e-003,0.000000e+000,0,,0,
1524137687.476,,0.000000e+000,3.499950e+001,1.473426e-006,0.000000e+000,3,3.824358e-001,0.000000e+000,,,,,,,,,,,,,,32,1,4.000000e+000,0.000000e+000,0.000000e+000,0,,0,
1524137725.509,,0.000000e+000,3.499638e+001,1.445563e-006,0.000000e+000,3,3.762724e-001,0.000000e+000,,,,,,,,,,,,,,32,1,4.000000e+000,4.688263e-003,0.000000e+000,0,,0,
1524137763.587,,0.000000e+000,3.499793e+001,1.484499e-006,0.000000e+000,3,3.832272e-001,0.000000e+000,,,,,,,,,,,,,,32,1,4.000000e+000,4.688263e-003,0.000000e+000,0,,0,
1524137800.930,,0.000000e+000,3.499950e+001,1.483470e-006,0.000000e+000,3,3.838626e-001,0.000000e+000,,,,,,,,,,,,,,32,1,4.000000e+000,0.000000e+000,0.000000e+000,0,,0,
1524137838.323,,0.000000e+000,3.499872e+001,1.473953e-006,0.000000e+000,3,4.063257e-001,0.000000e+000,,,,,,,,,,,,,,32,1,4.000000e+000,0.000000e+000,0.000000e+000,0,,0,
1524137875.656,,0.000000e+000,3.499950e+001,1.486001e-006,0.000000e+000,3,4.164836e-001,0.000000e+000,,,,,,,,,,,,,,32,1,4.000000e+000,1.560211e-003,0.000000e+000,0,,0,
1524137913.987,,0.000000e+000,3.499911e+001,1.491707e-006,0.000000e+000,3,3.880910e-001,0.000000e+000,,,,,,,,,,,,,,32,1,4.000000e+000,7.820129e-004,0.000000e+000,0,,0,
1524137951.532,,0.000000e+000,3.499989e+001,1.456690e-006,0.000000e+000,3,3.905048e-001,0.000000e+000,,,,,,,,,,,,,,32,1,4.000000e+000,7.781982e-004,0.000000e+000,0,,0,
1524137989.615,,0.000000e+000,3.499911e+001,1.457185e-006,0.000000e+000,3,3.841262e-001,0.000000e+000,,,,,,,,,,,,,,32,1,4.000000e+000,7.820129e-004,0.000000e+000,0,,0,
1524138027.761,,0.000000e+000,3.499872e+001,1.551981e-006,0.000000e+000,3,4.498557e-001,0.000000e+000,,,,,,,,,,,,,,32,1,4.000000e+000,1.560211e-003,0.000000e+000,0,,0,
1524138065.784,,0.000000e+000,3.499989e+001,1.486675e-006,0.000000e+000,3,4.002625e-001,0.000000e+000,,,,,,,,,,,,,,32,1,4.000000e+000,7.781982e-004,0.000000e+000,0,,0,
1524138103.847,,0.000000e+000,3.499872e+001,1.494589e-006,0.000000e+000,3,4.092819e-001,0.000000e+000,,,,,,,,,,,,,,32,1,4.000000e+000,0.000000e+000,0.000000e+000,0,,0,
1524138141.943,,0.000000e+000,3.500028e+001,1.500792e-006,0.000000e+000,3,3.899065e-001,0.000000e+000,,,,,,,,,,,,,,32,1,4.000000e+000,0.000000e+000,0.000000e+000,0,,0,
1524138180.013,,0.000000e+000,3.499911e+001,1.553350e-006,0.000000e+000,3,4.099766e-001,0.000000e+000,,,,,,,,,,,,,,32,1,4.000000e+000,7.820129e-004,0.000000e+000,0,,0,
1524138218.131,,0.000000e+000,3.499911e+001,1.531990e-006,0.000000e+000,3,3.992664e-001,0.000000e+000,,,,,,,,,,,,,,32,1,4.000000e+000,7.820129e-004,0.000000e+000,0,,0,
1524138256.232,,0.000000e+000,3.499911e+001,1.528879e-006,0.000000e+000,3,4.122837e-001,0.000000e+000,,,,,,,,,,,,,,32,1,4.000000e+000,7.820129e-004,0.000000e+000,0,,0,
1524138294.067,,0.000000e+000,3.499989e+001,1.533065e-006,0.000000e+000,3,4.174276e-001,0.000000e+000,,,,,,,,,,,,,,32,1,4.000000e+000,7.781982e-004,0.000000e+000,0,,0,
1524138331.778,,0.000000e+000,3.499950e+001,1.581104e-006,0.000000e+000,3,4.203270e-001,0.000000e+000,,,,,,,,,,,,,,32,1,4.000000e+000,0.000000e+000,0.000000e+000,0,,0,
1524138369.148,,0.000000e+000,3.499911e+001,1.548032e-006,0.000000e+000,3,4.315848e-001,0.000000e+000,,,,,,,,,,,,,,32,1,4.000000e+000,7.820129e-004,0.000000e+000,0,,0,
1524138407.627,,0.000000e+000,3.499950e+001,1.599224e-006,0.000000e+000,3,4.496761e-001,0.000000e+000,,,,,,,,,,,,,,32,1,4.000000e+000,0.000000e+000,0.000000e+000,0,,0,
1524138444.795,,0.000000e+000,3.499793e+001,1.538439e-006,0.000000e+000,3,4.396836e-001,0.000000e+000,,,,,,,,,,,,,,32,1,4.000000e+000,3.131866e-003,0.000000e+000,0,,0,
1524138482.798,,0.000000e+000,3.499911e+001,1.519301e-006,0.000000e+000,3,4.284972e-001,0.000000e+000,,,,,,,,,,,,,,32,1,4.000000e+000,7.820129e-004,0.000000e+000,0,,0,
1524138521.271,,0.000000e+000,3.499950e+001,1.564801e-006,0.000000e+000,3,4.163225e-001,0.000000e+000,,,,,,,,,,,,,,32,1,4.000000e+000,1.560211e-003,0.000000e+000,0,,0,
1524138560.499,,0.000000e+000,3.499872e+001,1.550121e-006,0.000000e+000,3,4.215324e-001,0.000000e+000,,,,,,,,,,,,,,32,1,4.000000e+000,1.560211e-003,0.000000e+000,0,,0,
1524138598.714,,0.000000e+000,3.499950e+001,1.571598e-006,0.000000e+000,3,4.225798e-001,0.000000e+000,,,,,,,,,,,,,,32,1,4.000000e+000,0.000000e+000,0.000000e+000,0,,0,
1524138636.285,,0.000000e+000,3.499872e+001,1.546061e-006,0.000000e+000,3,4.313578e-001,0.000000e+000,,,,,,,,,,,,,,32,1,4.000000e+000,1.560211e-003,0.000000e+000,0,,0,
1524138674.303,,0.000000e+000,3.499872e+001,1.572331e-006,0.000000e+000,3,4.483477e-001,0.000000e+000,,,,,,,,,,,,,,32,1,4.000000e+000,0.000000e+000,0.000000e+000,0,,0,
1524138711.943,,0.000000e+000,3.499950e+001,1.558843e-006,0.000000e+000,3,4.335571e-001,0.000000e+000,,,,,,,,,,,,,,32,1,4.000000e+000,0.000000e+000,0.000000e+000,0,,0,
1524138750.481,,0.000000e+000,3.499911e+001,1.541174e-006,0.000000e+000,3,4.285486e-001,0.000000e+000,,,,,,,,,,,,,,32,1,4.000000e+000,7.820129e-004,0.000000e+000,0,,0,
1524138788.122,,0.000000e+000,3.499989e+001,1.581222e-006,0.000000e+000,3,4.247065e-001,0.000000e+000,,,,,,,,,,,,,,32,1,4.000000e+000,7.781982e-004,0.000000e+000,0,,0,
1524138826.673,,0.000000e+000,3.499872e+001,1.616483e-006,0.000000e+000,3,4.288966e-001,0.000000e+000,,,,,,,,,,,,,,32,1,4.000000e+000,1.560211e-003,0.000000e+000,0,,0,
1524138864.188,,0.000000e+000,3.499950e+001,1.571841e-006,0.000000e+000,3,4.494855e-001,0.000000e+000,,,,,,,,,,,,,,32,1,4.000000e+000,1.560211e-003,0.000000e+000,0,,0,
1524138902.264,,0.000000e+000,3.499911e+001,1.600953e-006,0.000000e+000,3,4.358965e-001,0.000000e+000,,,,,,,,,,,,,,32,1,4.000000e+000,7.820129e-004,0.000000e+000,0,,0,
1524138940.382,,0.000000e+000,3.499950e+001,1.612610e-006,0.000000e+000,3,4.394037e-001,0.000000e+000,,,,,,,,,,,,,,32,1,4.000000e+000,1.560211e-003,0.000000e+000,0,,0,
1524138979.327,,0.000000e+000,3.499989e+001,1.635258e-006,0.000000e+000,3,4.612321e-001,0.000000e+000,,,,,,,,,,,,,,32,1,4.000000e+000,7.781982e-004,0.000000e+000,0,,0,
1524139017.018,,0.000000e+000,3.499989e+001,1.533699e-006,0.000000e+000,3,4.345358e-001,0.000000e+000,,,,,,,,,,,,,,32,1,4.000000e+000,7.781982e-004,0.000000e+000,0,,0,
1524139055.046,,0.000000e+000,3.499911e+001,1.577821e-006,0.000000e+000,3,4.191178e-001,0.000000e+000,,,,,,,,,,,,,,32,1,4.000000e+000,2.338409e-003,0.000000e+000,0,,0,
1524139093.564,,0.000000e+000,3.499872e+001,1.663175e-006,0.000000e+000,3,4.765210e-001,0.000000e+000,,,,,,,,,,,,,,32,1,4.000000e+000,1.560211e-003,0.000000e+000,0,,0,
1524139131.442,,0.000000e+000,3.499950e+001,1.568515e-006,0.000000e+000,3,4.445769e-001,0.000000e+000,,,,,,,,,,,,,,32,1,4.000000e+000,1.560211e-003,0.000000e+000,0,,0,
1524139169.788,,0.000000e+000,3.499989e+001,1.578924e-006,0.000000e+000,3,4.351865e-001,0.000000e+000,,,,,,,,,,,,,,32,1,4.000000e+000,7.781982e-004,0.000000e+000,0,,0,
1524139207.096,,0.000000e+000,3.499911e+001,1.618551e-006,0.000000e+000,3,4.424518e-001,0.000000e+000,,,,,,,,,,,,,,32,1,4.000000e+000,7.820129e-004,0.000000e+000,0,,0,
1524139245.094,,0.000000e+000,3.499950e+001,1.613536e-006,0.000000e+000,3,4.487160e-001,0.000000e+000,,,,,,,,,,,,,,32,1,4.000000e+000,0.000000e+000,0.000000e+000,0,,0,
1524139283.237,,0.000000e+000,3.499989e+001,1.698489e-006,0.000000e+000,3,4.886294e-001,0.000000e+000,,,,,,,,,,,,,,32,1,4.000000e+000,7.781982e-004,0.000000e+000,0,,0,
1524139321.327,,0.000000e+000,3.499911e+001,1.596226e-006,0.000000e+000,3,4.364380e-001,0.000000e+000,,,,,,,,,,,,,,32,1,4.000000e+000,7.820129e-004,0.000000e+000,0,,0,
1524139359.378,,0.000000e+000,3.500067e+001,1.643003e-006,0.000000e+000,3,4.646984e-001,0.000000e+000,,,,,,,,,,,,,,32,1,4.000000e+000,2.338409e-003,0.000000e+000,0,,0,
1524139396.916,,0.000000e+000,3.499911e+001,1.642250e-006,0.000000e+000,3,4.411693e-001,0.000000e+000,,,,,,,,,,,,,,32,1,4.000000e+000,7.820129e-004,0.000000e+000,0,,0,
1524139434.552,,0.000000e+000,3.499950e+001,1.675895e-006,0.000000e+000,3,4.637606e-001,0.000000e+000,,,,,,,,,,,,,,32,1,4.000000e+000,1.560211e-003,0.000000e+000,0,,0,
1524139473.110,,0.000000e+000,3.499911e+001,1.604104e-006,0.000000e+000,3,4.462875e-001,0.000000e+000,,,,,,,,,,,,,,32,1,4.000000e+000,7.820129e-004,0.000000e+000,0,,0,
1524139510.725,,0.000000e+000,3.499950e+001,1.668460e-006,0.000000e+000,3,4.487091e-001,0.000000e+000,,,,,,,,,,,,,,32,1,4.000000e+000,0.000000e+000,0.000000e+000,0,,0,
1524139548.823,,0.000000e+000,3.499950e+001,1.618839e-006,0.000000e+000,3,4.421727e-001,0.000000e+000,,,,,,,,,,,,,,32,1,4.000000e+000,0.000000e+000,0.000000e+000,0,,0,
1524139586.814,,0.000000e+000,3.499950e+001,1.655345e-006,0.000000e+000,3,4.842271e-001,0.000000e+000,,,,,,,,,,,,,,32,1,4.000000e+000,0.000000e+000,0.000000e+000,0,,0,
1524139625.294,,0.000000e+000,3.499989e+001,1.713454e-006,0.000000e+000,3,4.582917e-001,0.000000e+000,,,,,,,,,,,,,,32,1,4.000000e+000,2.342224e-003,0.000000e+000,0,,0,
1524139663.372,,0.000000e+000,3.499911e+001,1.724702e-006,0.000000e+000,3,4.567662e-001,0.000000e+000,,,,,,,,,,,,,,32,1,4.000000e+000,7.820129e-004,0.000000e+000,0,,0,
1524139701.951,,0.000000e+000,3.499911e+001,1.657044e-006,0.000000e+000,3,4.553988e-001,0.000000e+000,,,,,,,,,,,,,,32,1,4.000000e+000,7.820129e-004,0.000000e+000,0,,0,
1524139740.096,,0.000000e+000,3.499911e+001,1.714350e-006,0.000000e+000,3,4.817411e-001,0.000000e+000,,,,,,,,,,,,,,32,1,4.000000e+000,7.820129e-004,0.000000e+000,0,,0,
1524139777.579,,0.000000e+000,3.499911e+001,1.650556e-006,0.000000e+000,3,4.751920e-001,0.000000e+000,,,,,,,,,,,,,,32,1,4.000000e+000,7.820129e-004,0.000000e+000,0,,0,
1524139816.257,,0.000000e+000,3.499872e+001,1.676110e-006,0.000000e+000,3,4.707351e-001,0.000000e+000,,,,,,,,,,,,,,32,1,4.000000e+000,0.000000e+000,0.000000e+000,0,,0,
1524139853.268,,0.000000e+000,3.499872e+001,1.695911e-006,0.000000e+000,3,4.464718e-001,0.000000e+000,,,,,,,,,,,,,,32,1,4.000000e+000,1.560211e-003,0.000000e+000,0,,0,
1524139891.321,,0.000000e+000,3.499950e+001,1.717195e-006,0.000000e+000,3,4.761866e-001,0.000000e+000,,,,,,,,,,,,,,32,1,4.000000e+000,1.560211e-003,0.000000e+000,0,,0,
1524139930.634,,0.000000e+000,3.499911e+001,1.706694e-006,0.000000e+000,3,4.747136e-001,0.000000e+000,,,,,,,,,,,,,,32,1,4.000000e+000,7.820129e-004,0.000000e+000,0,,0,
1524139967.792,,0.000000e+000,3.499950e+001,1.644617e-006,0.000000e+000,3,4.578773e-001,0.000000e+000,,,,,,,,,,,,,,32,1,4.000000e+000,0.000000e+000,0.000000e+000,0,,0,
1524140005.782,,0.000000e+000,3.499911e+001,1.678328e-006,0.000000e+000,3,4.821024e-001,0.000000e+000,,,,,,,,,,,,,,32,1,4.000000e+000,7.820129e-004,0.000000e+000,0,,0,
1524140043.865,,0.000000e+000,3.499911e+001,1.697368e-006,0.000000e+000,3,4.633961e-001,0.000000e+000,,,,,,,,,,,,,,32,1,4.000000e+000,7.820129e-004,0.000000e+000,0,,0,
1524140081.946,,0.000000e+000,3.499911e+001,1.759240e-006,0.000000e+000,3,5.117311e-001,0.000000e+000,,,,,,,,,,,,,,32,1,4.000000e+000,7.820129e-004,0.000000e+000,0,,0,
1524140119.992,,0.000000e+000,3.499989e+001,1.685899e-006,0.000000e+000,3,4.994914e-001,0.000000e+000,,,,,,,,,,,,,,32,1,4.000000e+000,7.781982e-004,0.000000e+000,0,,0,
1524140159.675,,0.000000e+000,3.499989e+001,1.642102e-006,0.000000e+000,3,4.556818e-001,0.000000e+000,,,,,,,,,,,,,,32,1,4.000000e+000,7.781982e-004,0.000000e+000,0,,0,
1524140197.808,,0.000000e+000,3.499950e+001,1.705102e-006,0.000000e+000,3,4.897788e-001,0.000000e+000,,,,,,,,,,,,,,32,1,4.000000e+000,0.000000e+000,0.000000e+000,0,,0,
1524140235.903,,0.000000e+000,3.499911e+001,1.718933e-006,0.000000e+000,3,4.828046e-001,0.000000e+000,,,,,,,,,,,,,,32,1,4.000000e+000,7.820129e-004,0.000000e+000,0,,0,
1524140274.314,,0.000000e+000,3.499794e+001,1.734938e-006,0.000000e+000,3,4.793090e-001,0.000000e+000,,,,,,,,,,,,,,32,1,4.000000e+000,0.000000e+000,0.000000e+000,0,,0,
1524140312.599,,0.000000e+000,3.500028e+001,1.752821e-006,0.000000e+000,3,4.959613e-001,0.000000e+000,,,,,,,,,,,,,,32,1,4.000000e+000,0.000000e+000,0.000000e+000,0,,0,
1524140351.548,,0.000000e+000,3.499950e+001,1.737933e-006,0.000000e+000,3,4.737943e-001,0.000000e+000,,,,,,,,,,,,,,32,1,4.000000e+000,1.560211e-003,0.000000e+000,0,,0,
1524140388.588,,0.000000e+000,3.499794e+001,1.708586e-006,0.000000e+000,3,4.684128e-001,0.000000e+000,,,,,,,,,,,,,,32,1,4.000000e+000,0.000000e+000,0.000000e+000,0,,0,
1524140426.639,,0.000000e+000,3.499950e+001,1.783100e-006,0.000000e+000,3,4.830083e-001,0.000000e+000,,,,,,,,,,,,,,32,1,4.000000e+000,1.560211e-003,0.000000e+000,0,,0,
1524140464.714,,0.000000e+000,3.499950e+001,1.720859e-006,0.000000e+000,3,4.647510e-001,0.000000e+000,,,,,,,,,,,,,,32,1,4.000000e+000,0.000000e+000,0.000000e+000,0,,0,
1524140502.640,,0.000000e+000,3.499989e+001,1.740585e-006,0.000000e+000,3,5.153707e-001,0.000000e+000,,,,,,,,,,,,,,32,1,4.000000e+000,3.898621e-003,0.000000e+000,0,,0,
1524140540.413,,0.000000e+000,3.499911e+001,1.718020e-006,0.000000e+000,3,4.596576e-001,0.000000e+000,,,,,,,,,,,,,,32,1,4.000000e+000,7.820129e-004,0.000000e+000,0,,0,
1524140578.513,,0.000000e+000,3.499950e+001,1.755480e-006,0.000000e+000,3,4.937776e-001,0.000000e+000,,,,,,,,,,,,,,32,1,4.000000e+000,1.560211e-003,0.000000e+000,0,,0,
1524140616.549,,0.000000e+000,3.499950e+001,1.823940e-006,0.000000e+000,3,4.910991e-001,0.000000e+000,,,,,,,,,,,,,,32,1,4.000000e+000,0.000000e+000,0.000000e+000,0,,0,
1524140654.659,,0.000000e+000,3.499911e+001,1.770246e-006,0.000000e+000,3,4.955809e-001,0.000000e+000,,,,,,,,,,,,,,32,1,4.000000e+000,7.820129e-004,0.000000e+000,0,,0,
1524140692.765,,0.000000e+000,3.499989e+001,1.757858e-006,0.000000e+000,3,4.907996e-001,0.000000e+000,,,,,,,,,,,,,,32,1,4.000000e+000,7.781982e-004,0.000000e+000,0,,0,
1524140730.956,,0.000000e+000,3.499872e+001,1.789420e-006,0.000000e+000,3,5.070502e-001,0.000000e+000,,,,,,,,,,,,,,32,1,4.000000e+000,0.000000e+000,0.000000e+000,0,,0,
1524140768.699,,0.000000e+000,3.499950e+001,1.740548e-006,0.000000e+000,3,4.724586e-001,0.000000e+000,,,,,,,,,,,,,,32,1,4.000000e+000,0.000000e+000,0.000000e+000,0,,0,
1524140807.769,,0.000000e+000,3.499950e+001,1.734637e-006,0.000000e+000,3,4.865179e-001,0.000000e+000,,,,,,,,,,,,,,32,1,4.000000e+000,0.000000e+000,0.000000e+000,0,,0,
1524140845.855,,0.000000e+000,3.499793e+001,1.792981e-006,0.000000e+000,3,5.107067e-001,0.000000e+000,,,,,,,,,,,,,,32,1,4.000000e+000,1.567841e-003,0.000000e+000,0,,0,
1524140883.935,,0.000000e+000,3.499911e+001,1.775659e-006,0.000000e+000,3,4.955524e-001,0.000000e+000,,,,,,,,,,,,,,32,1,4.000000e+000,7.820129e-004,0.000000e+000,0,,0,
1524140921.528,,0.000000e+000,3.500028e+001,1.724303e-006,0.000000e+000,3,4.901823e-001,0.000000e+000,,,,,,,,,,,,,,32,1,4.000000e+000,0.000000e+000,0.000000e+000,0,,0,
1524140959.524,,0.000000e+000,3.499950e+001,1.775575e-006,0.000000e+000,3,4.952824e-001,0.000000e+000,,,,,,,,,,,,,,32,1,4.000000e+000,0.000000e+000,0.000000e+000,0,,0,
1524140997.832,,0.000000e+000,3.499989e+001,1.807850e-006,0.000000e+000,3,4.856060e-001,0.000000e+000,,,,,,,,,,,,,,32,1,4.000000e+000,7.781982e-004,0.000000e+000,0,,0,
1524141035.960,,0.000000e+000,3.499950e+001,1.797237e-006,0.000000e+000,3,5.099875e-001,0.000000e+000,,,,,,,,,,,,,,32,1,4.000000e+000,0.000000e+000,0.000000e+000,0,,0,
1524141073.353,,0.000000e+000,3.499950e+001,1.758096e-006,0.000000e+000,3,4.979177e-001,0.000000e+000,,,,,,,,,,,,,,32,1,4.000000e+000,1.560211e-003,0.000000e+000,0,,0,
1524141111.901,,0.000000e+000,3.499950e+001,1.750720e-006,0.000000e+000,3,5.001943e-001,0.000000e+000,,,,,,,,,,,,,,32,1,4.000000e+000,0.000000e+000,0.000000e+000,0,,0,
1524141149.949,,0.000000e+000,3.499950e+001,1.869488e-006,0.000000e+000,3,5.247015e-001,0.000000e+000,,,,,,,,,,,,,,32,1,4.000000e+000,0.000000e+000,0.000000e+000,0,,0,
1524141187.595,,0.000000e+000,3.499872e+001,1.768866e-006,0.000000e+000,3,4.948029e-001,0.000000e+000,,,,,,,,,,,,,,32,1,4.000000e+000,0.000000e+000,0.000000e+000,0,,0,
1524141225.740,,0.000000e+000,3.499872e+001,1.780354e-006,0.000000e+000,3,5.062079e-001,0.000000e+000,,,,,,,,,,,,,,32,1,4.000000e+000,0.000000e+000,0.000000e+000,0,,0,
1524141263.763,,0.000000e+000,3.499911e+001,1.791499e-006,0.000000e+000,3,4.985406e-001,0.000000e+000,,,,,,,,,,,,,,32,1,4.000000e+000,7.820129e-004,0.000000e+000,0,,0,
1524141302.316,,0.000000e+000,3.499911e+001,1.774849e-006,0.000000e+000,3,5.090802e-001,0.000000e+000,,,,,,,,,,,,,,32,1,4.000000e+000,7.820129e-004,0.000000e+000,0,,0,
1524141339.920,,0.000000e+000,3.499872e+001,1.796614e-006,0.000000e+000,3,5.106432e-001,0.000000e+000,,,,,,,,,,,,,,32,1,4.000000e+000,0.000000e+000,0.000000e+000,0,,0,
1524141378.483,,0.000000e+000,3.499911e+001,1.789998e-006,0.000000e+000,3,5.014513e-001,0.000000e+000,,,,,,,,,,,,,,32,1,4.000000e+000,7.820129e-004,0.000000e+000,0,,0,
1524141416.536,,0.000000e+000,3.499911e+001,1.811000e-006,0.000000e+000,3,5.173345e-001,0.000000e+000,,,,,,,,,,,,,,32,1,4.000000e+000,7.820129e-004,0.000000e+000,0,,0,
1524141454.164,,0.000000e+000,3.499950e+001,1.824157e-006,0.000000e+000,3,5.110410e-001,0.000000e+000,,,,,,,,,,,,,,32,1,4.000000e+000,0.000000e+000,0.000000e+000,0,,0,
1524141492.242,,0.000000e+000,3.499950e+001,1.775700e-006,0.000000e+000,3,5.063478e-001,0.000000e+000,,,,,,,,,,,,,,32,1,4.000000e+000,0.000000e+000,0.000000e+000,0,,0,
1524141530.760,,0.000000e+000,3.499950e+001,1.785999e-006,0.000000e+000,3,5.088198e-001,0.000000e+000,,,,,,,,,,,,,,32,1,4.000000e+000,0.000000e+000,0.000000e+000,0,,0,
1524141569.110,,0.000000e+000,3.499872e+001,1.823674e-006,0.000000e+000,3,5.088524e-001,0.000000e+000,,,,,,,,,,,,,,32,1,4.000000e+000,0.000000e+000,0.000000e+000,0,,0,
1524141606.766,,0.000000e+000,3.499872e+001,1.819790e-006,0.000000e+000,3,5.019483e-001,0.000000e+000,,,,,,,,,,,,,,32,1,4.000000e+000,0.000000e+000,0.000000e+000,0,,0,
1524141644.849,,0.000000e+000,3.499911e+001,1.892713e-006,0.000000e+000,3,5.187668e-001,0.000000e+000,,,,,,,,,,,,,,32,1,4.000000e+000,2.338409e-003,0.000000e+000,0,,0,
1524141683.430,,0.000000e+000,3.499950e+001,1.824425e-006,0.000000e+000,3,5.106255e-001,0.000000e+000,,,,,,,,,,,,,,32,1,4.000000e+000,1.560211e-003,0.000000e+000,0,,0,
1524141721.485,,0.000000e+000,3.499911e+001,1.880740e-006,0.000000e+000,3,5.361031e-001,0.000000e+000,,,,,,,,,,,,,,32,1,4.000000e+000,2.338409e-003,0.000000e+000,0,,0,
1524141759.116,,0.000000e+000,3.499872e+001,1.782177e-006,0.000000e+000,3,4.972232e-001,0.000000e+000,,,,,,,,,,,,,,32,1,4.000000e+000,1.560211e-003,0.000000e+000,0,,0,
1524141796.479,,0.000000e+000,3.499911e+001,1.823383e-006,0.000000e+000,3,5.041534e-001,0.000000e+000,,,,,,,,,,,,,,32,1,4.000000e+000,7.820129e-004,0.000000e+000,0,,0,
1524141834.049,,0.000000e+000,3.499989e+001,1.850686e-006,0.000000e+000,3,5.139905e-001,0.000000e+000,,,,,,,,,,,,,,32,1,4.000000e+000,7.781982e-004,0.000000e+000,0,,0,
1524141871.582,,0.000000e+000,3.499911e+001,1.847234e-006,0.000000e+000,3,4.792210e-001,0.000000e+000,,,,,,,,,,,,,,32,1,4.000000e+000,7.820129e-004,0.000000e+000,0,,0,
1524141909.688,,0.000000e+000,3.499638e+001,1.803461e-006,0.000000e+000,3,5.137466e-001,0.000000e+000,,,,,,,,,,,,,,32,1,4.000000e+000,4.688263e-003,0.000000e+000,0,,0,
1524141947.883,,0.000000e+000,3.499950e+001,1.899167e-006,0.000000e+000,3,5.281220e-001,0.000000e+000,,,,,,,,,,,,,,32,1,4.000000e+000,6.259918e-003,0.000000e+000,0,,0,
1524141985.599,,0.000000e+000,3.499677e+001,1.823258e-006,0.000000e+000,3,4.950227e-001,0.000000e+000,,,,,,,,,,,,,,32,1,4.000000e+000,5.470276e-003,0.000000e+000,0,,0,
1524142023.865,,0.000000e+000,3.500185e+001,1.827475e-006,0.000000e+000,3,5.173362e-001,0.000000e+000,,,,,,,,,,,,,,32,1,4.000000e+000,4.688263e-003,0.000000e+000,0,,0,
1524142061.878,,0.000000e+000,3.499911e+001,1.873155e-006,0.000000e+000,3,5.180676e-001,0.000000e+000,,,,,,,,,,,,,,32,1,4.000000e+000,7.820129e-004,0.000000e+000,0,,0,
1524142099.971,,0.000000e+000,3.499793e+001,1.829582e-006,0.000000e+000,3,5.038648e-001,0.000000e+000,,,,,,,,,,,,,,32,1,4.000000e+000,1.567841e-003,0.000000e+000,0,,0,
1524142137.416,,0.000000e+000,3.499911e+001,1.884991e-006,0.000000e+000,3,5.289317e-001,0.000000e+000,,,,,,,,,,,,,,32,1,4.000000e+000,7.820129e-004,0.000000e+000,0,,0,
1524142175.009,,0.000000e+000,3.499833e+001,1.839310e-006,0.000000e+000,3,5.147181e-001,0.000000e+000,,,,,,,,,,,,,,32,1,4.000000e+000,7.781982e-004,0.000000e+000,0,,0,
1524142213.087,,0.000000e+000,3.499950e+001,1.794486e-006,0.000000e+000,3,4.712444e-001,0.000000e+000,,,,,,,,,,,,,,32,1,4.000000e+000,3.120422e-003,0.000000e+000,0,,0,
1524142250.945,,0.000000e+000,3.499911e+001,1.870152e-006,0.000000e+000,3,5.370377e-001,0.000000e+000,,,,,,,,,,,,,,32,1,4.000000e+000,7.820129e-004,0.000000e+000,0,,0,
1524142288.448,,0.000000e+000,3.500028e+001,1.873979e-006,0.000000e+000,3,5.172800e-001,0.000000e+000,,,,,,,,,,,,,,32,1,4.000000e+000,1.560211e-003,0.000000e+000,0,,0,
1524142326.547,,0.000000e+000,3.500028e+001,1.851247e-006,0.000000e+000,3,5.268040e-001,0.000000e+000,,,,,,,,,,,,,,32,1,4.000000e+000,0.000000e+000,0.000000e+000,0,,0,
1524142364.657,,0.000000e+000,3.499872e+001,1.858093e-006,0.000000e+000,3,5.089968e-001,0.000000e+000,,,,,,,,,,,,,,32,1,4.000000e+000,0.000000e+000,0.000000e+000,0,,0,
1524142402.713,,0.000000e+000,3.499872e+001,1.843387e-006,0.000000e+000,3,5.161732e-001,0.000000e+000,,,,,,,,,,,,,,32,1,4.000000e+000,0.000000e+000,0.000000e+000,0,,0,
1524142440.798,,0.000000e+000,3.499989e+001,1.883037e-006,0.000000e+000,3,5.237837e-001,0.000000e+000,,,,,,,,,,,,,,32,1,4.000000e+000,7.781982e-004,0.000000e+000,0,,0,
1524142477.996,,0.000000e+000,3.499950e+001,1.840405e-006,0.000000e+000,3,5.083425e-001,0.000000e+000,,,,,,,,,,,,,,32,1,4.000000e+000,0.000000e+000,0.000000e+000,0,,0,
1524142516.089,,0.000000e+000,3.499872e+001,1.851000e-006,0.000000e+000,3,5.249565e-001,0.000000e+000,,,,,,,,,,,,,,32,1,4.000000e+000,0.000000e+000,0.000000e+000,0,,0,
1524142554.152,,0.000000e+000,3.499911e+001,1.853805e-006,0.000000e+000,3,5.171664e-001,0.000000e+000,,,,,,,,,,,,,,32,1,4.000000e+000,7.820129e-004,0.000000e+000,0,,0,
1524142591.788,,0.000000e+000,3.499950e+001,1.842204e-006,0.000000e+000,3,5.202585e-001,0.000000e+000,,,,,,,,,,,,,,32,1,4.000000e+000,1.560211e-003,0.000000e+000,0,,0,
1524142629.858,,0.000000e+000,3.499950e+001,1.864547e-006,0.000000e+000,3,5.195168e-001,0.000000e+000,,,,,,,,,,,,,,32,1,4.000000e+000,1.560211e-003,0.000000e+000,0,,0,
1524142667.857,,0.000000e+000,3.499950e+001,1.838486e-006,0.000000e+000,3,5.298252e-001,0.000000e+000,,,,,,,,,,,,,,32,1,4.000000e+000,0.000000e+000,0.000000e+000,0,,0,
1524142705.602,,0.000000e+000,3.499911e+001,1.822290e-006,0.000000e+000,3,5.079539e-001,0.000000e+000,,,,,,,,,,,,,,32,1,4.000000e+000,7.820129e-004,0.000000e+000,0,,0,
1524142743.485,,0.000000e+000,3.499950e+001,1.821400e-006,0.000000e+000,3,5.339335e-001,0.000000e+000,,,,,,,,,,,,,,32,1,4.000000e+000,0.000000e+000,0.000000e+000,0,,0,
1524142781.198,,0.000000e+000,3.500067e+001,1.851467e-006,0.000000e+000,3,5.087799e-001,0.000000e+000,,,,,,,,,,,,,,32,1,4.000000e+000,2.338409e-003,0.000000e+000,0,,0,
1524142819.676,,0.000000e+000,3.499872e+001,1.843451e-006,0.000000e+000,3,5.120157e-001,0.000000e+000,,,,,,,,,,,,,,32,1,4.000000e+000,0.000000e+000,0.000000e+000,0,,0,
1524142857.299,,0.000000e+000,3.499950e+001,1.959979e-006,0.000000e+000,3,5.472725e-001,0.000000e+000,,,,,,,,,,,,,,32,1,4.000000e+000,0.000000e+000,0.000000e+000,0,,0,
1524142895.815,,0.000000e+000,3.499911e+001,1.867528e-006,0.000000e+000,3,5.219740e-001,0.000000e+000,,,,,,,,,,,,,,32,1,4.000000e+000,2.338409e-003,0.000000e+000,0,,0,
1524142933.443,,0.000000e+000,3.499872e+001,1.873983e-006,0.000000e+000,3,5.342548e-001,0.000000e+000,,,,,,,,,,,,,,32,1,4.000000e+000,0.000000e+000,0.000000e+000,0,,0,
1524142971.453,,0.000000e+000,3.499911e+001,1.855768e-006,0.000000e+000,3,5.145081e-001,0.000000e+000,,,,,,,,,,,,,,32,1,4.000000e+000,7.820129e-004,0.000000e+000,0,,0,
1524143009.542,,0.000000e+000,3.499911e+001,1.884525e-006,0.000000e+000,3,5.359363e-001,0.000000e+000,,,,,,,,,,,,,,32,1,4.000000e+000,7.820129e-004,0.000000e+000,0,,0,
1524143047.697,,0.000000e+000,3.499989e+001,1.891797e-006,0.000000e+000,3,5.321884e-001,0.000000e+000,,,,,,,,,,,,,,32,1,4.000000e+000,7.781982e-004,0.000000e+000,0,,0,
1524143085.730,,0.000000e+000,3.499911e+001,1.914992e-006,0.000000e+000,3,5.354699e-001,0.000000e+000,,,,,,,,,,,,,,32,1,4.000000e+000,7.820129e-004,0.000000e+000,0,,0,
1524143124.146,,0.000000e+000,3.499872e+001,1.958941e-006,0.000000e+000,3,5.370193e-001,0.000000e+000,,,,,,,,,,,,,,32,1,4.000000e+000,1.560211e-003,0.000000e+000,0,,0,
1524143162.576,,0.000000e+000,3.499872e+001,1.883407e-006,0.000000e+000,3,5.205539e-001,0.000000e+000,,,,,,,,,,,,,,32,1,4.000000e+000,1.560211e-003,0.000000e+000,0,,0,
1524143200.659,,0.000000e+000,3.499794e+001,1.906827e-006,0.000000e+000,3,5.233586e-001,0.000000e+000,,,,,,,,,,,,,,32,1,4.000000e+000,0.000000e+000,0.000000e+000,0,,0,
1524143238.727,,0.000000e+000,3.499989e+001,1.896547e-006,0.000000e+000,3,5.411022e-001,0.000000e+000,,,,,,,,,,,,,,32,1,4.000000e+000,7.781982e-004,0.000000e+000,0,,0,
1524143276.465,,0.000000e+000,3.500028e+001,1.918419e-006,0.000000e+000,3,5.394312e-001,0.000000e+000,,,,,,,,,,,,,,32,1,4.000000e+000,1.560211e-003,0.000000e+000,0,,0,
1524143314.581,,0.000000e+000,3.500028e+001,1.845498e-006,0.000000e+000,3,5.203630e-001,0.000000e+000,,,,,,,,,,,,,,32,1,4.000000e+000,1.560211e-003,0.000000e+000,0,,0,
1524143352.662,,0.000000e+000,3.499911e+001,1.895276e-006,0.000000e+000,3,5.251508e-001,0.000000e+000,,,,,,,,,,,,,,32,1,4.000000e+000,7.820129e-004,0.000000e+000,0,,0,
1524143390.710,,0.000000e+000,3.500067e+001,1.901127e-006,0.000000e+000,3,5.312353e-001,0.000000e+000,,,,,,,,,,,,,,32,1,4.000000e+000,7.820129e-004,0.000000e+000,0,,0,
1524143428.793,,0.000000e+000,3.500067e+001,1.890806e-006,0.000000e+000,3,5.302168e-001,0.000000e+000,,,,,,,,,,,,,,32,1,4.000000e+000,7.820129e-004,0.000000e+000,0,,0,
1524143466.923,,0.000000e+000,3.499872e+001,1.954325e-006,0.000000e+000,3,5.371892e-001,0.000000e+000,,,,,,,,,,,,,,32,1,4.000000e+000,0.000000e+000,0.000000e+000,0,,0,
1524143504.689,,0.000000e+000,3.499950e+001,1.870206e-006,0.000000e+000,3,5.328021e-001,0.000000e+000,,,,,,,,,,,,,,32,1,4.000000e+000,0.000000e+000,0.000000e+000,0,,0,
1524143542.584,,0.000000e+000,3.499950e+001,1.903948e-006,0.000000e+000,3,5.361812e-001,0.000000e+000,,,,,,,,,,,,,,32,1,4.000000e+000,0.000000e+000,0.000000e+000,0,,0,
1524143580.660,,0.000000e+000,3.499872e+001,1.904701e-006,0.000000e+000,3,5.312836e-001,0.000000e+000,,,,,,,,,,,,,,32,1,4.000000e+000,0.000000e+000,0.000000e+000,0,,0,
1524143618.740,,0.000000e+000,3.499872e+001,1.911230e-006,0.000000e+000,3,5.483637e-001,0.000000e+000,,,,,,,,,,,,,,32,1,4.000000e+000,0.000000e+000,0.000000e+000,0,,0,
1524143656.839,,0.000000e+000,3.499911e+001,1.935661e-006,0.000000e+000,3,5.275444e-001,0.000000e+000,,,,,,,,,,,,,,32,1,4.000000e+000,7.820129e-004,0.000000e+000,0,,0,
1524143694.892,,0.000000e+000,3.499989e+001,1.927129e-006,0.000000e+000,3,5.440382e-001,0.000000e+000,,,,,,,,,,,,,,32,1,4.000000e+000,7.781982e-004,0.000000e+000,0,,0,
1524143732.777,,0.000000e+000,3.499911e+001,1.887879e-006,0.000000e+000,3,5.171202e-001,0.000000e+000,,,,,,,,,,,,,,32,1,4.000000e+000,7.820129e-004,0.000000e+000,0,,0,
1524143772.280,,0.000000e+000,3.499911e+001,1.940324e-006,0.000000e+000,3,5.337797e-001,0.000000e+000,,,,,,,,,,,,,,32,1,4.000000e+000,7.820129e-004,0.000000e+000,0,,0,
1524143810.111,,0.000000e+000,3.499833e+001,1.963228e-006,0.000000e+000,3,5.427678e-001,0.000000e+000,,,,,,,,,,,,,,32,1,4.000000e+000,7.781982e-004,0.000000e+000,0,,0,
1524143848.314,,0.000000e+000,3.499872e+001,1.915244e-006,0.000000e+000,3,5.283864e-001,0.000000e+000,,,,,,,,,,,,,,32,1,4.000000e+000,1.560211e-003,0.000000e+000,0,,0,
1524143887.047,,0.000000e+000,3.499950e+001,1.937710e-006,0.000000e+000,3,5.481088e-001,0.000000e+000,,,,,,,,,,,,,,32,1,4.000000e+000,1.560211e-003,0.000000e+000,0,,0,
1524143925.205,,0.000000e+000,3.499911e+001,1.969107e-006,0.000000e+000,3,5.386975e-001,0.000000e+000,,,,,,,,,,,,,,32,1,4.000000e+000,7.820129e-004,0.000000e+000,0,,0,
1524143963.353,,0.000000e+000,3.499950e+001,1.905019e-006,0.000000e+000,3,5.286294e-001,0.000000e+000,,,,,,,,,,,,,,32,1,4.000000e+000,0.000000e+000,0.000000e+000,0,,0,
1524144001.444,,0.000000e+000,3.499950e+001,1.873842e-006,0.000000e+000,3,5.228290e-001,0.000000e+000,,,,,,,,,,,,,,32,1,4.000000e+000,0.000000e+000,0.000000e+000,0,,0,
1524144039.539,,0.000000e+000,3.499950e+001,1.893283e-006,0.000000e+000,3,5.285437e-001,0.000000e+000,,,,,,,,,,,,,,32,1,4.000000e+000,0.000000e+000,0.000000e+000,0,,0,
1524144077.630,,0.000000e+000,3.499911e+001,1.920923e-006,0.000000e+000,3,5.279496e-001,0.000000e+000,,,,,,,,,,,,,,32,1,4.000000e+000,7.820129e-004,0.000000e+000,0,,0,
1524144115.738,,0.000000e+000,3.499911e+001,1.905230e-006,0.000000e+000,3,5.411064e-001,0.000000e+000,,,,,,,,,,,,,,32,1,4.000000e+000,7.820129e-004,0.000000e+000,0,,0,
1524144154.176,,0.000000e+000,3.499950e+001,1.939715e-006,0.000000e+000,3,5.449338e-001,0.000000e+000,,,,,,,,,,,,,,32,1,4.000000e+000,0.000000e+000,0.000000e+000,0,,0,
1524144192.074,,0.000000e+000,3.499989e+001,1.969861e-006,0.000000e+000,3,5.348567e-001,0.000000e+000,,,,,,,,,,,,,,32,1,4.000000e+000,7.781982e-004,0.000000e+000,0,,0,
1524144229.832,,0.000000e+000,3.500028e+001,1.939775e-006,0.000000e+000,3,5.369548e-001,0.000000e+000,,,,,,,,,,,,,,32,1,4.000000e+000,1.560211e-003,0.000000e+000,0,,0,
1524144267.560,,0.000000e+000,3.500067e+001,2.010627e-006,0.000000e+000,3,5.698360e-001,0.000000e+000,,,,,,,,,,,,,,32,1,4.000000e+000,2.338409e-003,0.000000e+000,0,,0,
1524144293.433,,0.000000e+000,3.499950e+001,1.798478e-006,0.000000e+000,3,4.975896e-001,0.000000e+000,,,,,,,,,,,,,,32,1,4.000000e+000,1.560211e-003,0.000000e+000,0,,0,