File: Input/MFn1_VRMac_36K_1500s_VRMde_35K.dc.dat
[Header]
TITLE,MPMS DC Measurement
BYAPP,MPMS Measurement,2.1,Summary
FILEOPENTIME, 1524568873.650000 4/24/2018, 5:21:13 AM

INFO, APPNAME, MPMS MultiVu Application, Revision 1.61,  Build 082

INFO, NAME, MFn1
INFO, WEIGHT, 1.000
INFO, AREA, 1.000
INFO, LENGTH, 1.000
INFO, SHAPE, 0
INFO, COMMENT,
INFO, SEQUENCE FILE: VRMac_36K_1500s_VRMde_35K.seq


INFO, BACKGROUND DATA FILE:, None


STARTUPAXIS,X,4,LINEAR,AUTO,0.000000,0.000000
STARTUPAXIS,Y1,5,LINEAR,AUTO,0.000000,0.000000


STARTUPGROUP,Longitudinal
FIELDGROUP,Longitudinal,1,2,3,4,5,6,7,8,9,15,16,17,18,27,28
FIELDGROUP,Transverse,1,2,3,4,10,11,12,13,14,19,20,21,22,27,28

PLOT_APPEARANCE,ALL,HORZ_GRID_ON,VERT_GRID_ON,MARKERS_AND_LINES

[Data]
Time,Comment,Field (Oe),Temperature (K),Long Moment (emu),Long Scan Std Dev,Long Algorithm,Long Reg Fit,Long Percent Error (%),Trans Moment (emu),Trans Scan Std Dev,Trans Algorithm,Trans Reg Fit,Trans Percent Error (%),Long Moment [w/o ABS] (emu),Long Scan Std Dev [w/o ABS],Long Reg Fit [w/o ABS],Long Percent Error [w/o ABS] (%),Trans Moment [w/o ABS] (emu),Trans Scan Std Dev [w/o ABS],Trans Reg Fit [w/o ABS],Trans Percent Error [w/o ABS] (%),Points per Scan,Scans per Measurement,Scan Length (cm),Delta Temp (K),Rot Position (deg),Error,EC Comp. Running,Using ABS,
1524568873.648,,0.000000e+000,3.500106e+001,-6.313132e-006,0.000000e+000,3,8.913514e-001,0.000000e+000,,,,,,,,,,,,,,32,1,4.000000e+000,0.000000e+000,0.000000e+000,0,,0,
1524568911.761,,0.000000e+000,3.500028e+001,-5.894844e-006,0.000000e+000,3,8.806449e-001,0.000000e+000,,,,,,,,,,,,,,32,1,4.000000e+000,3.120422e-003,0.000000e+000,0,,0,
1524568949.804,,0.000000e+000,3.500145e+001,-5.337660e-006,0.000000e+000,3,8.696534e-001,0.000000e+000,,,,,,,,,,,,,,32,1,4.000000e+000,7.781982e-004,0.000000e+000,0,,0,
1524568988.324,,0.000000e+000,3.500106e+001,-4.843461e-006,0.000000e+000,3,8.562583e-001,0.000000e+000,,,,,,,,,,,,,,32,1,4.000000e+000,3.128052e-003,0.000000e+000,0,,0,
1524569026.415,,0.000000e+000,3.499715e+001,-4.411822e-006,0.000000e+000,3,8.395550e-001,0.000000e+000,,,,,,,,,,,,,,32,1,4.000000e+000,1.571655e-003,0.000000e+000,0,,0,
1524569064.183,,0.000000e+000,3.499911e+001,-4.018518e-006,0.000000e+000,3,8.205088e-001,0.000000e+000,,,,,,,,,,,,,,32,1,4.000000e+000,7.820129e-004,0.000000e+000,0,,0,
1524569102.161,,0.000000e+000,3.499989e+001,-3.610683e-006,0.000000e+000,3,7.971769e-001,0.000000e+000,,,,,,,,,,,,,,32,1,4.000000e+000,7.781982e-004,0.000000e+000,0,,0,
1524569140.012,,0.000000e+000,3.499833e+001,-3.259122e-006,0.000000e+000,3,7.831873e-001,0.000000e+000,,,,,,,,,,,,,,32,1,4.000000e+000,7.781982e-004,0.000000e+000,0,,0,
1524569178.825,,0.000000e+000,3.499833e+001,-3.009225e-006,0.000000e+000,3,7.477111e-001,0.000000e+000,,,,,,,,,,,,,,32,1,4.000000e+000,7.781982e-004,0.000000e+000,0,,0,
1524569216.805,,0.000000e+000,3.499989e+001,-2.721921e-006,0.000000e+000,3,7.408158e-001,0.000000e+000,,,,,,,,,,,,,,32,1,4.000000e+000,7.781982e-004,0.000000e+000,0,,0,
1524569255.781,,0.000000e+000,3.499872e+001,-2.444342e-006,0.000000e+000,3,7.010814e-001,0.000000e+000,,,,,,,,,,,,,,32,1,4.000000e+000,0.000000e+000,0.000000e+000,0,,0,
1524569293.691,,0.000000e+000,3.499833e+001,-2.255380e-006,0.000000e+000,3,6.862611e-001,0.000000e+000,,,,,,,,,,,,,,32,1,4.000000e+000,7.781982e-004,0.000000e+000,0,,0,
1524569331.794,,0.000000e+000,3.499911e+001,-2.067740e-006,0.000000e+000,3,6.613880e-001,0.000000e+000,,,,,,,,,,,,,,32,1,4.000000e+000,2.338409e-003,0.000000e+000,0,,0,
1524569369.827,,0.000000e+000,3.499989e+001,-1.822862e-006,0.000000e+000,3,6.169693e-001,0.000000e+000,,,,,,,,,,,,,,32,1,4.000000e+000,2.342224e-003,0.000000e+000,0,,0,
1524569407.953,,0.000000e+000,3.499950e+001,-1.663165e-006,0.000000e+000,3,5.866359e-001,0.000000e+000,,,,,,,,,,,,,,32,1,4.000000e+000,0.000000e+000,0.000000e+000,0,,0,
1524569716.009,,0.000000e+000,3.499950e+001,-1.650898e-007,0.000000e+000,2,0.000000e+000,0.000000e+000,,,,,,,,,,,,,,32,1,4.000000e+000,0.000000e+000,0.000000e+000,0,,0,
1524569755.334,,0.000000e+000,3.499793e+001,-2.971262e-007,0.000000e+000,3,0.000000e+000,0.000000e+000,,,,,,,,,,,,,,32,1,4.000000e+000,3.131866e-003,0.000000e+000,0,,0,
1524569795.005,,0.000000e+000,3.499950e+001,6.528981e-008,0.000000e+000,2,0.000000e+000,0.000000e+000,,,,,,,,,,,,,,32,1,4.000000e+000,0.000000e+000,0.000000e+000,0,,0,
1524569832.431,,0.000000e+000,3.499872e+001,-4.414405e-007,0.000000e+000,3,0.000000e+000,0.000000e+000,,,,,,,,,,,,,,32,1,4.000000e+000,1.560211e-003,0.000000e+000,0,,0,
1524569875.640,,0.000000e+000,3.499871e+001,3.824036e-007,0.000000e+000,2,0.000000e+000,0.000000e+000,,,,,,,,,,,,,,32,1,4.000000e+000,3.128052e-003,0.000000e+000,0,,0,
1524570547.488,,0.000000e+000,3.499833e+001,1.975467e-006,0.000000e+000,3,6.670181e-001,0.000000e+000,,,,,,,,,,,,,,32,1,4.000000e+000,7.781982e-004,0.000000e+000,0,,0,
1524570586.051,,0.000000e+000,3.499794e+001,2.013079e-006,0.000000e+000,3,6.768711e-001,0.000000e+000,,,,,,,,,,,,,,32,1,4.000000e+000,0.000000e+000,0.000000e+000,0,,0,
1524570623.729,,0.000000e+000,3.499911e+001,2.160136e-006,0.000000e+000,3,6.687924e-001,0.000000e+000,,,,,,,,,,,,,,32,1,4.000000e+000,7.820129e-004,0.000000e+000,0,,0,
1524570662.297,,0.000000e+000,3.499872e+001,2.111897e-006,0.000000e+000,3,6.888655e-001,0.000000e+000,,,,,,,,,,,,,,32,1,4.000000e+000,0.000000e+000,0.000000e+000,0,,0,
1524570699.958,,0.000000e+000,3.499872e+001,2.193626e-006,0.000000e+000,3,6.986326e-001,0.000000e+000,,,,,,,,,,,,,,32,1,4.000000e+000,0.000000e+000,0.000000e+000,0,,0,
1524570738.006,,0.000000e+000,3.499911e+001,2.257405e-006,0.000000e+000,3,7.091309e-001,0.000000e+000,,,,,,,,,,,,,,32,1,4.000000e+000,2.338409e-003,0.000000e+000,0,,0,
1524570776.199,,0.000000e+000,3.499911e+001,2.272324e-006,0.000000e+000,3,7.240225e-001,0.000000e+000,,,,,,,,,,,,,,32,1,4.000000e+000,7.820129e-004,0.000000e+000,0,,0,
1524570813.797,,0.000000e+000,3.499872e+001,2.356276e-006,0.000000e+000,3,7.188121e-001,0.000000e+000,,,,,,,,,,,,,,32,1,4.000000e+000,0.000000e+000,0.000000e+000,0,,0,
1524570851.825,,0.000000e+000,3.499911e+001,2.375923e-006,0.000000e+000,3,7.334139e-001,0.000000e+000,,,,,,,,,,,,,,32,1,4.000000e+000,7.820129e-004,0.000000e+000,0,,0,
1524570889.996,,0.000000e+000,3.499872e+001,2.414352e-006,0.000000e+000,3,7.189070e-001,0.000000e+000,,,,,,,,,,,,,,32,1,4.000000e+000,0.000000e+000,0.000000e+000,0,,0,
1524570928.116,,0.000000e+000,3.499872e+001,2.462808e-006,0.000000e+000,3,7.257410e-001,0.000000e+000,,,,,,,,,,,,,,32,1,4.000000e+000,0.000000e+000,0.000000e+000,0,,0,
1524570966.152,,0.000000e+000,3.499989e+001,2.521693e-006,0.000000e+000,3,7.230864e-001,0.000000e+000,,,,,,,,,,,,,,32,1,4.000000e+000,7.781982e-004,0.000000e+000,0,,0,
1524571004.267,,0.000000e+000,3.499950e+001,2.552211e-006,0.000000e+000,3,7.483147e-001,0.000000e+000,,,,,,,,,,,,,,32,1,4.000000e+000,0.000000e+000,0.000000e+000,0,,0,
1524571042.380,,0.000000e+000,3.499872e+001,2.598611e-006,0.000000e+000,3,7.527207e-001,0.000000e+000,,,,,,,,,,,,,,32,1,4.000000e+000,0.000000e+000,0.000000e+000,0,,0,
1524571080.843,,0.000000e+000,3.499872e+001,2.691886e-006,0.000000e+000,3,7.560878e-001,0.000000e+000,,,,,,,,,,,,,,32,1,4.000000e+000,0.000000e+000,0.000000e+000,0,,0,
1524571118.974,,0.000000e+000,3.499872e+001,2.737303e-006,0.000000e+000,3,7.477698e-001,0.000000e+000,,,,,,,,,,,,,,32,1,4.000000e+000,0.000000e+000,0.000000e+000,0,,0,
1524571156.922,,0.000000e+000,3.499872e+001,2.822496e-006,0.000000e+000,3,7.656670e-001,0.000000e+000,,,,,,,,,,,,,,32,1,4.000000e+000,0.000000e+000,0.000000e+000,0,,0,
1524571194.833,,0.000000e+000,3.499833e+001,2.819479e-006,0.000000e+000,3,7.537838e-001,0.000000e+000,,,,,,,,,,,,,,32,1,4.000000e+000,7.781982e-004,0.000000e+000,0,,0,
1524571232.408,,0.000000e+000,3.499911e+001,2.803357e-006,0.000000e+000,3,7.691560e-001,0.000000e+000,,,,,,,,,,,,,,32,1,4.000000e+000,7.820129e-004,0.000000e+000,0,,0,
1524571270.134,,0.000000e+000,3.500106e+001,2.829684e-006,0.000000e+000,3,7.565327e-001,0.000000e+000,,,,,,,,,,,,,,32,1,4.000000e+000,3.128052e-003,0.000000e+000,0,,0,
1524571308.649,,0.000000e+000,3.499950e+001,2.869309e-006,0.000000e+000,3,7.594652e-001,0.000000e+000,,,,,,,,,,,,,,32,1,4.000000e+000,1.560211e-003,0.000000e+000,0,,0,
1524571346.322,,0.000000e+000,3.499950e+001,2.935823e-006,0.000000e+000,3,7.733983e-001,0.000000e+000,,,,,,,,,,,,,,32,1,4.000000e+000,1.560211e-003,0.000000e+000,0,,0,
1524571384.893,,0.000000e+000,3.499911e+001,2.995212e-006,0.000000e+000,3,7.764881e-001,0.000000e+000,,,,,,,,,,,,,,32,1,4.000000e+000,7.820129e-004,0.000000e+000,0,,0,
1524571422.561,,0.000000e+000,3.499950e+001,2.996768e-006,0.000000e+000,3,7.711949e-001,0.000000e+000,,,,,,,,,,,,,,32,1,4.000000e+000,0.000000e+000,0.000000e+000,0,,0,
1524571461.124,,0.000000e+000,3.499872e+001,3.035573e-006,0.000000e+000,3,7.779088e-001,0.000000e+000,,,,,,,,,,,,,,32,1,4.000000e+000,0.000000e+000,0.000000e+000,0,,0,
1524571499.450,,0.000000e+000,3.499872e+001,3.061278e-006,0.000000e+000,3,7.851731e-001,0.000000e+000,,,,,,,,,,,,,,32,1,4.000000e+000,0.000000e+000,0.000000e+000,0,,0,
1524571536.925,,0.000000e+000,3.499989e+001,3.130970e-006,0.000000e+000,3,7.801447e-001,0.000000e+000,,,,,,,,,,,,,,32,1,4.000000e+000,2.342224e-003,0.000000e+000,0,,0,
1524571575.738,,0.000000e+000,3.499638e+001,3.175612e-006,0.000000e+000,3,7.921010e-001,0.000000e+000,,,,,,,,,,,,,,32,1,4.000000e+000,4.688263e-003,0.000000e+000,0,,0,
1524571613.651,,0.000000e+000,3.499872e+001,3.212397e-006,0.000000e+000,3,7.820910e-001,0.000000e+000,,,,,,,,,,,,,,32,1,4.000000e+000,0.000000e+000,0.000000e+000,0,,0,
1524571651.654,,0.000000e+000,3.499950e+001,3.256383e-006,0.000000e+000,3,7.896098e-001,0.000000e+000,,,,,,,,,,,,,,32,1,4.000000e+000,0.000000e+000,0.000000e+000,0,,0,
1524571689.622,,0.000000e+000,3.499833e+001,3.256151e-006,0.000000e+000,3,7.936785e-001,0.000000e+000,,,,,,,,,,,,,,32,1,4.000000e+000,7.781982e-004,0.000000e+000,0,,0,
1524571727.495,,0.000000e+000,3.499911e+001,3.247452e-006,0.000000e+000,3,7.854737e-001,0.000000e+000,,,,,,,,,,,,,,32,1,4.000000e+000,7.820129e-004,0.000000e+000,0,,0,
1524571765.454,,0.000000e+000,3.499833e+001,3.227150e-006,0.000000e+000,3,7.930076e-001,0.000000e+000,,,,,,,,,,,,,,32,1,4.000000e+000,7.781982e-004,0.000000e+000,0,,0,
1524571803.392,,0.000000e+000,3.499833e+001,3.306124e-006,0.000000e+000,3,7.969185e-001,0.000000e+000,,,,,,,,,,,,,,32,1,4.000000e+000,7.781982e-004,0.000000e+000,0,,0,
1524571841.505,,0.000000e+000,3.499989e+001,3.386894e-006,0.000000e+000,3,7.776316e-001,0.000000e+000,,,,,,,,,,,,,,32,1,4.000000e+000,2.342224e-003,0.000000e+000,0,,0,
1524571880.160,,0.000000e+000,3.499793e+001,3.389059e-006,0.000000e+000,3,8.001372e-001,0.000000e+000,,,,,,,,,,,,,,32,1,4.000000e+000,1.567841e-003,0.000000e+000,0,,0,
1524571917.373,,0.000000e+000,3.499989e+001,3.404459e-006,0.000000e+000,3,7.921705e-001,0.000000e+000,,,,,,,,,,,,,,32,1,4.000000e+000,2.342224e-003,0.000000e+000,0,,0,
1524571955.504,,0.000000e+000,3.499950e+001,3.516193e-006,0.000000e+000,3,7.991964e-001,0.000000e+000,,,,,,,,,,,,,,32,1,4.000000e+000,0.000000e+000,0.000000e+000,0,,0,
1524571993.579,,0.000000e+000,3.499950e+001,3.529092e-006,0.000000e+000,3,8.081721e-001,0.000000e+000,,,,,,,,,,,,,,32,1,4.000000e+000,0.000000e+000,0.000000e+000,0,,0,
1524572032.002,,0.000000e+000,3.499911e+001,3.516127e-006,0.000000e+000,3,7.943708e-001,0.000000e+000,,,,,,,,,,,,,,32,1,4.000000e+000,7.820129e-004,0.000000e+000,0,,0,
1524572069.675,,0.000000e+000,3.499950e+001,3.529429e-006,0.000000e+000,3,8.054149e-001,0.000000e+000,,,,,,,,,,,,,,32,1,4.000000e+000,0.000000e+000,0.000000e+000,0,,0,
1524572107.513,,0.000000e+000,3.499754e+001,3.517185e-006,0.000000e+000,3,7.910051e-001,0.000000e+000,,,,,,,,,,,,,,32,1,4.000000e+000,2.349854e-003,0.000000e+000,0,,0,
1524572146.369,,0.000000e+000,3.499872e+001,3.614043e-006,0.000000e+000,3,8.104698e-001,0.000000e+000,,,,,,,,,,,,,,32,1,4.000000e+000,1.560211e-003,0.000000e+000,0,,0,
1524572184.627,,0.000000e+000,3.499872e+001,3.636861e-006,0.000000e+000,3,8.123146e-001,0.000000e+000,,,,,,,,,,,,,,32,1,4.000000e+000,1.560211e-003,0.000000e+000,0,,0,
1524572222.828,,0.000000e+000,3.499833e+001,3.668315e-006,0.000000e+000,3,8.140300e-001,0.000000e+000,,,,,,,,,,,,,,32,1,4.000000e+000,7.781982e-004,0.000000e+000,0,,0,
1524572261.411,,0.000000e+000,3.499950e+001,3.685395e-006,0.000000e+000,3,8.229771e-001,0.000000e+000,,,,,,,,,,,,,,32,1,4.000000e+000,1.560211e-003,0.000000e+000,0,,0,
1524572299.491,,0.000000e+000,3.499911e+001,3.740938e-006,0.000000e+000,3,8.282480e-001,0.000000e+000,,,,,,,,,,,,,,32,1,4.000000e+000,7.820129e-004,0.000000e+000,0,,0,
1524572337.649,,0.000000e+000,3.499833e+001,3.771426e-006,0.000000e+000,3,8.175648e-001,0.000000e+000,,,,,,,,,,,,,,32,1,4.000000e+000,7.781982e-004,0.000000e+000,0,,0,
1524572375.555,,0.000000e+000,3.499911e+001,3.805814e-006,0.000000e+000,3,8.142011e-001,0.000000e+000,,,,,,,,,,,,,,32,1,4.000000e+000,2.338409e-003,0.000000e+000,0,,0,
1524572412.948,,0.000000e+000,3.499911e+001,3.799142e-006,0.000000e+000,3,8.052219e-001,0.000000e+000,,,,,,,,,,,,,,32,1,4.000000e+000,7.820129e-004,0.000000e+000,0,,0,
1524572451.421,,0.000000e+000,3.499950e+001,3.803807e-006,0.000000e+000,3,8.186797e-001,0.000000e+000,,,,,,,,,,,,,,32,1,4.000000e+000,1.560211e-003,0.000000e+000,0,,0,
1524572488.952,,0.000000e+000,3.499989e+001,3.792251e-006,0.000000e+000,3,8.251247e-001,0.000000e+000,,,,,,,,,,,,,,32,1,4.000000e+000,7.781982e-004,0.000000e+000,0,,0,
1524572527.062,,0.000000e+000,3.499950e+001,3.828446e-006,0.000000e+000,3,8.257949e-001,0.000000e+000,,,,,,,,,,,,,,32,1,4.000000e+000,1.560211e-003,0.000000e+000,0,,0,
1524572565.163,,0.000000e+000,3.499833e+001,3.885238e-006,0.000000e+000,3,8.251316e-001,0.000000e+000,,,,,,,,,,,,,,32,1,4.000000e+000,7.781982e-004,0.000000e+000,0,,0,
1524572603.608,,0.000000e+000,3.499872e+001,3.869509e-006,0.000000e+000,3,8.343301e-001,0.000000e+000,,,,,,,,,,,,,,32,1,4.000000e+000,0.000000e+000,0.000000e+000,0,,0,
1524572641.391,,0.000000e+000,3.499872e+001,3.891931e-006,0.000000e+000,3,8.213939e-001,0.000000e+000,,,,,,,,,,,,,,32,1,4.000000e+000,0.000000e+000,0.000000e+000,0,,0,
1524572679.452,,0.000000e+000,3.499872e+001,4.001043e-006,0.000000e+000,3,8.376578e-001,0.000000e+000,,,,,,,,,,,,,,32,1,4.000000e+000,0.000000e+000,0.000000e+000,0,,0,
1524572717.127,,0.000000e+000,3.499833e+001,3.963109e-006,0.000000e+000,3,8.188299e-001,0.000000e+000,,,,,,,,,,,,,,32,1,4.000000e+000,7.781982e-004,0.000000e+000,0,,0,
1524572756.206,,0.000000e+000,3.499911e+001,3.951039e-006,0.000000e+000,3,8.284483e-001,0.000000e+000,,,,,,,,,,,,,,32,1,4.000000e+000,7.820129e-004,0.000000e+000,0,,0,
1524572794.181,,0.000000e+000,3.499833e+001,4.008275e-006,0.000000e+000,3,8.268102e-001,0.000000e+000,,,,,,,,,,,,,,32,1,4.000000e+000,7.781982e-004,0.000000e+000,0,,0,
1524572832.429,,0.000000e+000,3.499911e+001,4.008200e-006,0.000000e+000,3,8.226520e-001,0.000000e+000,,,,,,,,,,,,,,32,1,4.000000e+000,7.820129e-004,0.000000e+000,0,,0,
1524572870.527,,0.000000e+000,3.499950e+001,3.950089e-006,0.000000e+000,3,8.219700e-001,0.000000e+000,,,,,,,,,,,,,,32,1,4.000000e+000,0.000000e+000,0.000000e+000,0,,0,
1524572908.645,,0.000000e+000,3.499793e+001,4.018868e-006,0.000000e+000,3,8.355064e-001,0.000000e+000,,,,,,,,,,,,,,32,1,4.000000e+000,3.131866e-003,0.000000e+000,0,,0,
1524572948.246,,0.000000e+000,3.499989e+001,4.092241e-006,0.000000e+000,3,8.294965e-001,0.000000e+000,,,,,,,,,,,,,,32,1,4.000000e+000,7.781982e-004,0.000000e+000,0,,0,
1524572986.161,,0.000000e+000,3.499833e+001,4.102804e-006,0.000000e+000,3,8.343794e-001,0.000000e+000,,,,,,,,,,,,,,32,1,4.000000e+000,2.349854e-003,0.000000e+000,0,,0,
1524573024.369,,0.000000e+000,3.500067e+001,4.180803e-006,0.000000e+000,3,8.456950e-001,0.000000e+000,,,,,,,,,,,,,,32,1,4.000000e+000,2.338409e-003,0.000000e+000,0,,0,
1524573062.453,,0.000000e+000,3.499833e+001,4.116512e-006,0.000000e+000,3,8.395190e-001,0.000000e+000,,,,,,,,,,,,,,32,1,4.000000e+000,7.781982e-004,0.000000e+000,0,,0,
1524573100.583,,0.000000e+000,3.500106e+001,4.202670e-006,0.000000e+000,3,8.328722e-001,0.000000e+000,,,,,,,,,,,,,,32,1,4.000000e+000,1.560211e-003,0.000000e+000,0,,0,
1524573138.601,,0.000000e+000,3.500028e+001,4.186546e-006,0.000000e+000,3,8.347168e-001,0.000000e+000,,,,,,,,,,,,,,32,1,4.000000e+000,3.120422e-003,0.000000e+000,0,,0,
1524573176.649,,0.000000e+000,3.499872e+001,4.209244e-006,0.000000e+000,3,8.421548e-001,0.000000e+000,,,,,,,,,,,,,,32,1,4.000000e+000,1.560211e-003,0.000000e+000,0,,0,
1524573214.805,,0.000000e+000,3.499950e+001,4.230003e-006,0.000000e+000,3,8.536111e-001,0.000000e+000,,,,,,,,,,,,,,32,1,4.000000e+000,0.000000e+000,0.000000e+000,0,,0,
1524573252.990,,0.000000e+000,3.499793e+001,4.203426e-006,0.000000e+000,3,8.329939e-001,0.000000e+000,,,,,,,,,,,,,,32,1,4.000000e+000,1.567841e-003,0.000000e+000,0,,0,
1524573291.091,,0.000000e+000,3.499911e+001,4.198218e-006,0.000000e+000,3,8.428915e-001,0.000000e+000,,,,,,,,,,,,,,32,1,4.000000e+000,7.820129e-004,0.000000e+000,0,,0,
1524573329.156,,0.000000e+000,3.499872e+001,4.262815e-006,0.000000e+000,3,8.432019e-001,0.000000e+000,,,,,,,,,,,,,,32,1,4.000000e+000,0.000000e+000,0.000000e+000,0,,0,
1524573367.290,,0.000000e+000,3.499911e+001,4.208722e-006,0.000000e+000,3,8.308056e-001,0.000000e+000,,,,,,,,,,,,,,32,1,4.000000e+000,7.820129e-004,0.000000e+000,0,,0,
1524573405.443,,0.000000e+000,3.499872e+001,4.315523e-006,0.000000e+000,3,8.422621e-001,0.000000e+000,,,,,,,,,,,,,,32,1,4.000000e+000,0.000000e+000,0.000000e+000,0,,0,
1524573443.538,,0.000000e+000,3.499989e+001,4.299141e-006,0.000000e+000,3,8.398904e-001,0.000000e+000,,,,,,,,,,,,,,32,1,4.000000e+000,7.781982e-004,0.000000e+000,0,,0,
1524573482.169,,0.000000e+000,3.499872e+001,4.339777e-006,0.000000e+000,3,8.422582e-001,0.000000e+000,,,,,,,,,,,,,,32,1,4.000000e+000,1.560211e-003,0.000000e+000,0,,0,
1524573518.569,,0.000000e+000,3.500262e+001,4.268014e-006,0.000000e+000,3,8.454350e-001,0.000000e+000,,,,,,,,,,,,,,32,1,4.000000e+000,1.571655e-003,0.000000e+000,0,,0,
1524573556.707,,0.000000e+000,3.499911e+001,4.297315e-006,0.000000e+000,3,8.403387e-001,0.000000e+000,,,,,,,,,,,,,,32,1,4.000000e+000,3.910065e-003,0.000000e+000,0,,0,
1524573594.903,,0.000000e+000,3.499911e+001,4.456987e-006,0.000000e+000,3,8.390915e-001,0.000000e+000,,,,,,,,,,,,,,32,1,4.000000e+000,7.820129e-004,0.000000e+000,0,,0,
1524573632.498,,0.000000e+000,3.499950e+001,4.435627e-006,0.000000e+000,3,8.406652e-001,0.000000e+000,,,,,,,,,,,,,,32,1,4.000000e+000,0.000000e+000,0.000000e+000,0,,0,
1524573670.446,,0.000000e+000,3.499950e+001,4.401966e-006,0.000000e+000,3,8.450984e-001,0.000000e+000,,,,,,,,,,,,,,32,1,4.000000e+000,0.000000e+000,0.000000e+000,0,,0,
1524573708.367,,0.000000e+000,3.499833e+001,4.457817e-006,0.000000e+000,3,8.456659e-001,0.000000e+000,,,,,,,,,,,,,,32,1,4.000000e+000,2.349854e-003,0.000000e+000,0,,0,
1524573746.253,,0.000000e+000,3.499872e+001,4.473807e-006,0.000000e+000,3,8.452424e-001,0.000000e+000,,,,,,,,,,,,,,32,1,4.000000e+000,0.000000e+000,0.000000e+000,0,,0,
1524573784.321,,0.000000e+000,3.499911e+001,4.426816e-006,0.000000e+000,3,8.529893e-001,0.000000e+000,,,,,,,,,,,,,,32,1,4.000000e+000,7.820129e-004,0.000000e+000,0,,0,
1524573822.461,,0.000000e+000,3.499872e+001,4.491542e-006,0.000000e+000,3,8.435662e-001,0.000000e+000,,,,,,,,,,,,,,32,1,4.000000e+000,0.000000e+000,0.000000e+000,0,,0,
1524573860.577,,0.000000e+000,3.499911e+001,4.429053e-006,0.000000e+000,3,8.302467e-001,0.000000e+000,,,,,,,,,,,,,,32,1,4.000000e+000,7.820129e-004,0.000000e+000,0,,0,
1524573898.662,,0.000000e+000,3.499833e+001,4.468646e-006,0.000000e+000,3,8.370445e-001,0.000000e+000,,,,,,,,,,,,,,32,1,4.000000e+000,7.781982e-004,0.000000e+000,0,,0,
1524573936.775,,0.000000e+000,3.499872e+001,4.506739e-006,0.000000e+000,3,8.526807e-001,0.000000e+000,,,,,,,,,,,,,,32,1,4.000000e+000,1.560211e-003,0.000000e+000,0,,0,
1524573974.886,,0.000000e+000,3.499872e+001,4.496398e-006,0.000000e+000,3,8.449074e-001,0.000000e+000,,,,,,,,,,,,,,32,1,4.000000e+000,0.000000e+000,0.000000e+000,0,,0,
1524574012.932,,0.000000e+000,3.499833e+001,4.500096e-006,0.000000e+000,3,8.483451e-001,0.000000e+000,,,,,,,,,,,,,,32,1,4.000000e+000,2.349854e-003,0.000000e+000,0,,0,
1524574051.642,,0.000000e+000,3.499911e+001,4.498492e-006,0.000000e+000,3,8.418939e-001,0.000000e+000,,,,,,,,,,,,,,32,1,4.000000e+000,7.820129e-004,0.000000e+000,0,,0,
1524574088.738,,0.000000e+000,3.499950e+001,4.568364e-006,0.000000e+000,3,8.571641e-001,0.000000e+000,,,,,,,,,,,,,,32,1,4.000000e+000,1.560211e-003,0.000000e+000,0,,0,
1524574128.648,,0.000000e+000,3.499950e+001,4.582533e-006,0.000000e+000,3,8.601229e-001,0.000000e+000,,,,,,,,,,,,,,32,1,4.000000e+000,3.120422e-003,0.000000e+000,0,,0,
1524574166.746,,0.000000e+000,3.499911e+001,4.546710e-006,0.000000e+000,3,8.405187e-001,0.000000e+000,,,,,,,,,,,,,,32,1,4.000000e+000,7.820129e-004,0.000000e+000,0,,0,
1524574204.864,,0.000000e+000,3.500028e+001,4.463908e-006,0.000000e+000,3,8.408463e-001,0.000000e+000,,,,,,,,,,,,,,32,1,4.000000e+000,0.000000e+000,0.000000e+000,0,,0,
1524574242.962,,0.000000e+000,3.499911e+001,4.538581e-006,0.000000e+000,3,8.453777e-001,0.000000e+000,,,,,,,,,,,,,,32,1,4.000000e+000,7.820129e-004,0.000000e+000,0,,0,
1524574280.650,,0.000000e+000,3.499872e+001,4.690186e-006,0.000000e+000,3,8.588357e-001,0.000000e+000,,,,,,,,,,,,,,32,1,4.000000e+000,1.560211e-003,0.000000e+000,0,,0,
1524574318.938,,0.000000e+000,3.499950e+001,4.607339e-006,0.000000e+000,3,8.506275e-001,0.000000e+000,,,,,,,,,,,,,,32,1,4.000000e+000,0.000000e+000,0.000000e+000,0,,0,
1524574356.869,,0.000000e+000,3.499950e+001,4.692370e-006,0.000000e+000,3,8.458457e-001,0.000000e+000,,,,,,,,,,,,,,32,1,4.000000e+000,0.000000e+000,0.000000e+000,0,,0,
1524574394.090,,0.000000e+000,3.499872e+001,4.621058e-006,0.000000e+000,3,8.449615e-001,0.000000e+000,,,,,,,,,,,,,,32,1,4.000000e+000,0.000000e+000,0.000000e+000,0,,0,
1524574432.585,,0.000000e+000,3.499481e+001,4.665077e-006,0.000000e+000,3,8.583850e-001,0.000000e+000,,,,,,,,,,,,,,32,1,4.000000e+000,9.380341e-003,0.000000e+000,0,,0,
1524574470.991,,0.000000e+000,3.500106e+001,4.643891e-006,0.000000e+000,3,8.524024e-001,0.000000e+000,,,,,,,,,,,,,,32,1,4.000000e+000,7.827759e-003,0.000000e+000,0,,0,
1524574509.439,,0.000000e+000,3.499872e+001,4.700407e-006,0.000000e+000,3,8.554576e-001,0.000000e+000,,,,,,,,,,,,,,32,1,4.000000e+000,0.000000e+000,0.000000e+000,0,,0,
1524574547.047,,0.000000e+000,3.500106e+001,4.644415e-006,0.000000e+000,3,8.477598e-001,0.000000e+000,,,,,,,,,,,,,,32,1,4.000000e+000,3.128052e-003,0.000000e+000,0,,0,
1524574584.442,,0.000000e+000,3.499833e+001,4.633666e-006,0.000000e+000,3,8.445675e-001,0.000000e+000,,,,,,,,,,,,,,32,1,4.000000e+000,7.781982e-004,0.000000e+000,0,,0,
1524574622.353,,0.000000e+000,3.499911e+001,4.730871e-006,0.000000e+000,3,8.540196e-001,0.000000e+000,,,,,,,,,,,,,,32,1,4.000000e+000,7.820129e-004,0.000000e+000,0,,0,
1524574660.844,,0.000000e+000,3.499833e+001,4.708919e-006,0.000000e+000,3,8.620108e-001,0.000000e+000,,,,,,,,,,,,,,32,1,4.000000e+000,7.781982e-004,0.000000e+000,0,,0,
1524574698.794,,0.000000e+000,3.499989e+001,4.757285e-006,0.000000e+000,3,8.549104e-001,0.000000e+000,,,,,,,,,,,,,,32,1,4.000000e+000,7.781982e-004,0.000000e+000,0,,0,
1524574736.132,,0.000000e+000,3.499950e+001,4.758934e-006,0.000000e+000,3,8.521906e-001,0.000000e+000,,,,,,,,,,,,,,32,1,4.000000e+000,0.000000e+000,0.000000e+000,0,,0,
1524574773.793,,0.000000e+000,3.499950e+001,4.776837e-006,0.000000e+000,3,8.450097e-001,0.000000e+000,,,,,,,,,,,,,,32,1,4.000000e+000,0.000000e+000,0.000000e+000,0,,0,
1524574811.818,,0.000000e+000,3.499911e+001,4.759512e-006,0.000000e+000,3,8.590939e-001,0.000000e+000,,,,,,,,,,,,,,32,1,4.000000e+000,7.820129e-004,0.000000e+000,0,,0,
1524574849.754,,0.000000e+000,3.499989e+001,4.805675e-006,0.000000e+000,3,8.695284e-001,0.000000e+000,,,,,,,,,,,,,,32,1,4.000000e+000,7.781982e-004,0.000000e+000,0,,0,
1524574888.497,,0.000000e+000,3.499950e+001,4.808785e-006,0.000000e+000,3,8.586721e-001,0.000000e+000,,,,,,,,,,,,,,32,1,4.000000e+000,0.000000e+000,0.000000e+000,0,,0,
1524574926.410,,0.000000e+000,3.499950e+001,4.819086e-006,0.000000e+000,3,8.606361e-001,0.000000e+000,,,,,,,,,,,,,,32,1,4.000000e+000,1.560211e-003,0.000000e+000,0,,0,
1524574965.113,,0.000000e+000,3.499872e+001,4.878833e-006,0.000000e+000,3,8.528472e-001,0.000000e+000,,,,,,,,,,,,,,32,1,4.000000e+000,0.000000e+000,0.000000e+000,0,,0,
1524575003.308,,0.000000e+000,3.499793e+001,4.858892e-006,0.000000e+000,3,8.548548e-001,0.000000e+000,,,,,,,,,,,,,,32,1,4.000000e+000,1.567841e-003,0.000000e+000,0,,0,
1524575040.837,,0.000000e+000,3.499872e+001,4.801336e-006,0.000000e+000,3,8.634056e-001,0.000000e+000,,,,,,,,,,,,,,32,1,4.000000e+000,0.000000e+000,0.000000e+000,0,,0,
1524575078.972,,0.000000e+000,3.499872e+001,4.837137e-006,0.000000e+000,3,8.547857e-001,0.000000e+000,,,,,,,,,,,,,,32,1,4.000000e+000,0.000000e+000,0.000000e+000,0,,0,
1524575116.560,,0.000000e+000,3.499871e+001,4.902423e-006,0.000000e+000,3,8.570207e-001,0.000000e+000,,,,,,,,,,,,,,32,1,4.000000e+000,3.128052e-003,0.000000e+000,0,,0,
1524575154.908,,0.000000e+000,3.499950e+001,4.871609e-006,0.000000e+000,3,8.598419e-001,0.000000e+000,,,,,,,,,,,,,,32,1,4.000000e+000,0.000000e+000,0.000000e+000,0,,0,
1524575192.749,,0.000000e+000,3.500028e+001,4.863194e-006,0.000000e+000,3,8.569512e-001,0.000000e+000,,,,,,,,,,,,,,32,1,4.000000e+000,0.000000e+000,0.000000e+000,0,,0,
1524575230.517,,0.000000e+000,3.499911e+001,4.878611e-006,0.000000e+000,3,8.621132e-001,0.000000e+000,,,,,,,,,,,,,,32,1,4.000000e+000,7.820129e-004,0.000000e+000,0,,0,
1524575268.617,,0.000000e+000,3.499911e+001,4.942855e-006,0.000000e+000,3,8.630335e-001,0.000000e+000,,,,,,,,,,,,,,32,1,4.000000e+000,7.820129e-004,0.000000e+000,0,,0,
1524575306.426,,0.000000e+000,3.499911e+001,4.942590e-006,0.000000e+000,3,8.640335e-001,0.000000e+000,,,,,,,,,,,,,,32,1,4.000000e+000,7.820129e-004,0.000000e+000,0,,0,
1524575344.519,,0.000000e+000,3.499911e+001,4.901915e-006,0.000000e+000,3,8.581421e-001,0.000000e+000,,,,,,,,,,,,,,32,1,4.000000e+000,7.820129e-004,0.000000e+000,0,,0,
1524575382.544,,0.000000e+000,3.499911e+001,4.952820e-006,0.000000e+000,3,8.473963e-001,0.000000e+000,,,,,,,,,,,,,,32,1,4.000000e+000,2.338409e-003,0.000000e+000,0,,0,
1524575420.785,,0.000000e+000,3.499989e+001,4.915213e-006,0.000000e+000,3,8.524148e-001,0.000000e+000,,,,,,,,,,,,,,32,1,4.000000e+000,7.781982e-004,0.000000e+000,0,,0,
1524575458.145,,0.000000e+000,3.499950e+001,5.004116e-006,0.000000e+000,3,8.624346e-001,0.000000e+000,,,,,,,,,,,,,,32,1,4.000000e+000,0.000000e+000,0.000000e+000,0,,0,
1524575496.113,,0.000000e+000,3.499911e+001,4.946339e-006,0.000000e+000,3,8.651454e-001,0.000000e+000,,,,,,,,,,,,,,32,1,4.000000e+000,7.820129e-004,0.000000e+000,0,,0,
1524575533.791,,0.000000e+000,3.499872e+001,4.929599e-006,0.000000e+000,3,8.700413e-001,0.000000e+000,,,,,,,,,,,,,,32,1,4.000000e+000,1.560211e-003,0.000000e+000,0,,0,
1524575571.897,,0.000000e+000,3.499911e+001,4.988917e-006,0.000000e+000,3,8.628539e-001,0.000000e+000,,,,,,,,,,,,,,32,1,4.000000e+000,7.820129e-004,0.000000e+000,0,,0,
1524575610.075,,0.000000e+000,3.499872e+001,5.006957e-006,0.000000e+000,3,8.563489e-001,0.000000e+000,,,,,,,,,,,,,,32,1,4.000000e+000,0.000000e+000,0.000000e+000,0,,0,
1524575647.678,,0.000000e+000,3.499833e+001,4.842811e-006,0.000000e+000,3,8.659432e-001,0.000000e+000,,,,,,,,,,,,,,32,1,4.000000e+000,2.349854e-003,0.000000e+000,0,,0,
1524575686.523,,0.000000e+000,3.499872e+001,5.045792e-006,0.000000e+000,3,8.608231e-001,0.000000e+000,,,,,,,,,,,,,,32,1,4.000000e+000,0.000000e+000,0.000000e+000,0,,0,
1524575724.454,,0.000000e+000,3.499833e+001,5.001357e-006,0.000000e+000,3,8.556788e-001,0.000000e+000,,,,,,,,,,,,,,32,1,4.000000e+000,7.781982e-004,0.000000e+000,0,,0,
1524575762.540,,0.000000e+000,3.499833e+001,5.060284e-006,0.000000e+000,3,8.528141e-001,0.000000e+000,,,,,,,,,,,,,,32,1,4.000000e+000,7.781982e-004,0.000000e+000,0,,0,
1524575800.393,,0.000000e+000,3.499911e+001,5.045710e-006,0.000000e+000,3,8.578730e-001,0.000000e+000,,,,,,,,,,,,,,32,1,4.000000e+000,7.820129e-004,0.000000e+000,0,,0,
1524575839.656,,0.000000e+000,3.499911e+001,5.012515e-006,0.000000e+000,3,8.599876e-001,0.000000e+000,,,,,,,,,,,,,,32,1,4.000000e+000,7.820129e-004,0.000000e+000,0,,0,
1524575877.849,,0.000000e+000,3.499833e+001,5.067205e-006,0.000000e+000,3,8.609309e-001,0.000000e+000,,,,,,,,,,,,,,32,1,4.000000e+000,7.781982e-004,0.000000e+000,0,,0,
1524575916.032,,0.000000e+000,3.499911e+001,5.076977e-006,0.000000e+000,3,8.717195e-001,0.000000e+000,,,,,,,,,,,,,,32,1,4.000000e+000,7.820129e-004,0.000000e+000,0,,0,
1524575954.538,,0.000000e+000,3.499872e+001,5.042011e-006,0.000000e+000,3,8.682228e-001,0.000000e+000,,,,,,,,,,,,,,32,1,4.000000e+000,0.000000e+000,0.000000e+000,0,,0,
1524575991.718,,0.000000e+000,3.499911e+001,5.024438e-006,0.000000e+000,3,8.603811e-001,0.000000e+000,,,,,,,,,,,,,,32,1,4.000000e+000,7.820129e-004,0.000000e+000,0,,0,
1524576030.271,,0.000000e+000,3.499872e+001,5.134737e-006,0.000000e+000,3,8.702664e-001,0.000000e+000,,,,,,,,,,,,,,32,1,4.000000e+000,0.000000e+000,0.000000e+000,0,,0,
1524576067.857,,0.000000e+000,3.499989e+001,5.077281e-006,0.000000e+000,3,8.738765e-001,0.000000e+000,,,,,,,,,,,,,,32,1,4.000000e+000,7.781982e-004,0.000000e+000,0,,0,
1524576105.965,,0.000000e+000,3.499950e+001,5.113494e-006,0.000000e+000,3,8.645392e-001,0.000000e+000,,,,,,,,,,,,,,32,1,4.000000e+000,1.560211e-003,0.000000e+000,0,,0,
1524576144.410,,0.000000e+000,3.499833e+001,5.104163e-006,0.000000e+000,3,8.643624e-001,0.000000e+000,,,,,,,,,,,,,,32,1,4.000000e+000,7.781982e-004,0.000000e+000,0,,0,
1524576182.388,,0.000000e+000,3.499833e+001,5.042099e-006,0.000000e+000,3,8.627393e-001,0.000000e+000,,,,,,,,,,,,,,32,1,4.000000e+000,7.781982e-004,0.000000e+000,0,,0,
1524576220.304,,0.000000e+000,3.499950e+001,5.146022e-006,0.000000e+000,3,8.692517e-001,0.000000e+000,,,,,,,,,,,,,,32,1,4.000000e+000,0.000000e+000,0.000000e+000,0,,0,
1524576258.382,,0.000000e+000,3.499911e+001,5.141573e-006,0.000000e+000,3,8.650024e-001,0.000000e+000,,,,,,,,,,,,,,32,1,4.000000e+000,7.820129e-004,0.000000e+000,0,,0,
1524576296.052,,0.000000e+000,3.499911e+001,5.123361e-006,0.000000e+000,3,8.645358e-001,0.000000e+000,,,,,,,,,,,,,,32,1,4.000000e+000,7.820129e-004,0.000000e+000,0,,0,
1524576334.063,,0.000000e+000,3.499950e+001,5.082997e-006,0.000000e+000,3,8.683838e-001,0.000000e+000,,,,,,,,,,,,,,32,1,4.000000e+000,1.560211e-003,0.000000e+000,0,,0,
1524576371.781,,0.000000e+000,3.499715e+001,5.104139e-006,0.000000e+000,3,8.618569e-001,0.000000e+000,,,,,,,,,,,,,,32,1,4.000000e+000,3.128052e-003,0.000000e+000,0,,0,
1524576409.847,,0.000000e+000,3.499989e+001,5.149599e-006,0.000000e+000,3,8.632833e-001,0.000000e+000,,,,,,,,,,,,,,32,1,4.000000e+000,7.781982e-004,0.000000e+000,0,,0,
1524576447.700,,0.000000e+000,3.499833e+001,5.142553e-006,0.000000e+000,3,8.689552e-001,0.000000e+000,,,,,,,,,,,,,,32,1,4.000000e+000,7.781982e-004,0.000000e+000,0,,0,
1524576485.260,,0.000000e+000,3.499950e+001,5.170451e-006,0.000000e+000,3,8.639768e-001,0.000000e+000,,,,,,,,,,,,,,32,1,4.000000e+000,0.000000e+000,0.000000e+000,0,,0,
1524576523.911,,0.000000e+000,3.499911e+001,5.166817e-006,0.000000e+000,3,8.658637e-001,0.000000e+000,,,,,,,,,,,,,,32,1,4.000000e+000,2.338409e-003,0.000000e+000,0,,0,
1524576561.611,,0.000000e+000,3.500028e+001,5.149673e-006,0.000000e+000,3,8.718981e-001,0.000000e+000,,,,,,,,,,,,,,32,1,4.000000e+000,1.560211e-003,0.000000e+000,0,,0,
1524576599.724,,0.000000e+000,3.499911e+001,5.142816e-006,0.000000e+000,3,8.638325e-001,0.000000e+000,,,,,,,,,,,,,,32,1,4.000000e+000,2.338409e-003,0.000000e+000,0,,0,
1524576637.663,,0.000000e+000,3.500028e+001,5.187940e-006,0.000000e+000,3,8.674979e-001,0.000000e+000,,,,,,,,,,,,,,32,1,4.000000e+000,1.560211e-003,0.000000e+000,0,,0,
1524576675.793,,0.000000e+000,3.500067e+001,5.207226e-006,0.000000e+000,3,8.594494e-001,0.000000e+000,,,,,,,,,,,,,,32,1,4.000000e+000,7.820129e-004,0.000000e+000,0,,0,
1524576713.861,,0.000000e+000,3.499794e+001,5.193672e-006,0.000000e+000,3,8.664809e-001,0.000000e+000,,,,,,,,,,,,,,32,1,4.000000e+000,0.000000e+000,0.000000e+000,0,,0,
1524576752.022,,0.000000e+000,3.500067e+001,5.193031e-006,0.000000e+000,3,8.646508e-001,0.000000e+000,,,,,,,,,,,,,,32,1,4.000000e+000,2.338409e-003,0.000000e+000,0,,0,
1524576790.080,,0.000000e+000,3.499911e+001,5.231542e-006,0.000000e+000,3,8.669045e-001,0.000000e+000,,,,,,,,,,,,,,32,1,4.000000e+000,7.820129e-004,0.000000e+000,0,,0,
1524576828.218,,0.000000e+000,3.499793e+001,5.210147e-006,0.000000e+000,3,8.623981e-001,0.000000e+000,,,,,,,,,,,,,,32,1,4.000000e+000,3.131866e-003,0.000000e+000,0,,0,
1524576866.301,,0.000000e+000,3.499911e+001,5.202016e-006,0.000000e+000,3,8.669322e-001,0.000000e+000,,,,,,,,,,,,,,32,1,4.000000e+000,7.820129e-004,0.000000e+000,0,,0,
1524576904.399,,0.000000e+000,3.499950e+001,5.240443e-006,0.000000e+000,3,8.649032e-001,0.000000e+000,,,,,,,,,,,,,,32,1,4.000000e+000,1.560211e-003,0.000000e+000,0,,0,
1524576942.662,,0.000000e+000,3.499911e+001,5.277870e-006,0.000000e+000,3,8.740470e-001,0.000000e+000,,,,,,,,,,,,,,32,1,4.000000e+000,2.338409e-003,0.000000e+000,0,,0,
1524576980.662,,0.000000e+000,3.499872e+001,5.209317e-006,0.000000e+000,3,8.667384e-001,0.000000e+000,,,,,,,,,,,,,,32,1,4.000000e+000,1.560211e-003,0.000000e+000,0,,0,
1524577018.783,,0.000000e+000,3.499989e+001,5.267594e-006,0.000000e+000,3,8.679875e-001,0.000000e+000,,,,,,,,,,,,,,32,1,4.000000e+000,7.781982e-004,0.000000e+000,0,,0,
1524577056.829,,0.000000e+000,3.499793e+001,5.300905e-006,0.000000e+000,3,8.654034e-001,0.000000e+000,,,,,,,,,,,,,,32,1,4.000000e+000,1.567841e-003,0.000000e+000,0,,0,
1524577094.432,,0.000000e+000,3.499872e+001,5.301893e-006,0.000000e+000,3,8.645627e-001,0.000000e+000,,,,,,,,,,,,,,32,1,4.000000e+000,0.000000e+000,0.000000e+000,0,,0,
1524577132.712,,0.000000e+000,3.499911e+001,5.302451e-006,0.000000e+000,3,8.699943e-001,0.000000e+000,,,,,,,,,,,,,,32,1,4.000000e+000,7.820129e-004,0.000000e+000,0,,0,
1524577170.848,,0.000000e+000,3.499872e+001,5.318153e-006,0.000000e+000,3,8.729498e-001,0.000000e+000,,,,,,,,,,,,,,32,1,4.000000e+000,1.560211e-003,0.000000e+000,0,,0,
1524577208.903,,0.000000e+000,3.499911e+001,5.287491e-006,0.000000e+000,3,8.662453e-001,0.000000e+000,,,,,,,,,,,,,,32,1,4.000000e+000,7.820129e-004,0.000000e+000,0,,0,
1524577246.889,,0.000000e+000,3.499911e+001,5.313246e-006,0.000000e+000,3,8.677443e-001,0.000000e+000,,,,,,,,,,,,,,32,1,4.000000e+000,7.820129e-004,0.000000e+000,0,,0,
1524577284.997,,0.000000e+000,3.499950e+001,5.351470e-006,0.000000e+000,3,8.696309e-001,0.000000e+000,,,,,,,,,,,,,,32,1,4.000000e+000,0.000000e+000,0.000000e+000,0,,0,
1524577323.100,,0.000000e+000,3.499911e+001,5.319182e-006,0.000000e+000,3,8.666330e-001,0.000000e+000,,,,,,,,,,,,,,32,1,4.000000e+000,2.338409e-003,0.000000e+000,0,,0,
1524577361.188,,0.000000e+000,3.499911e+001,5.289151e-006,0.000000e+000,3,8.688439e-001,0.000000e+000,,,,,,,,,,,,,,32,1,4.000000e+000,7.820129e-004,0.000000e+000,0,,0,
1524577399.301,,0.000000e+000,3.499950e+001,5.268502e-006,0.000000e+000,3,8.667310e-001,0.000000e+000,,,,,,,,,,,,,,32,1,4.000000e+000,0.000000e+000,0.000000e+000,0,,0,
1524577437.402,,0.000000e+000,3.499911e+001,5.344076e-006,0.000000e+000,3,8.720893e-001,0.000000e+000,,,,,,,,,,,,,,32,1,4.000000e+000,7.820129e-004,0.000000e+000,0,,0,
1524577475.510,,0.000000e+000,3.499872e+001,5.334628e-006,0.000000e+000,3,8.667742e-001,0.000000e+000,,,,,,,,,,,,,,32,1,4.000000e+000,0.000000e+000,0.000000e+000,0,,0,
1524577513.640,,0.000000e+000,3.499872e+001,5.306514e-006,0.000000e+000,3,8.640026e-001,0.000000e+000,,,,,,,,,,,,,,32,1,4.000000e+000,0.000000e+000,0.000000e+000,0,,0,
1524577551.753,,0.000000e+000,3.499911e+001,5.314931e-006,0.000000e+000,3,8.698395e-001,0.000000e+000,,,,,,,,,,,,,,32,1,4.000000e+000,7.820129e-004,0.000000e+000,0,,0,
1524577589.589,,0.000000e+000,3.499911e+001,5.351059e-006,0.000000e+000,3,8.679050e-001,0.000000e+000,,,,,,,,,,,,,,32,1,4.000000e+000,7.820129e-004,0.000000e+000,0,,0,
1524577627.100,,0.000000e+000,3.499950e+001,5.391742e-006,0.000000e+000,3,8.693557e-001,0.000000e+000,,,,,,,,,,,,,,32,1,4.000000e+000,0.000000e+000,0.000000e+000,0,,0,
1524577665.177,,0.000000e+000,3.499872e+001,5.367179e-006,0.000000e+000,3,8.704787e-001,0.000000e+000,,,,,,,,,,,,,,32,1,4.000000e+000,0.000000e+000,0.000000e+000,0,,0,
1524577702.846,,0.000000e+000,3.499989e+001,5.341524e-006,0.000000e+000,3,8.701670e-001,0.000000e+000,,,,,,,,,,,,,,32,1,4.000000e+000,7.781982e-004,0.000000e+000,0,,0,
1524577740.964,,0.000000e+000,3.499911e+001,5.319464e-006,0.000000e+000,3,8.777905e-001,0.000000e+000,,,,,,,,,,,,,,32,1,4.000000e+000,7.820129e-004,0.000000e+000,0,,0,
1524577778.967,,0.000000e+000,3.499950e+001,5.347024e-006,0.000000e+000,3,8.709325e-001,0.000000e+000,,,,,,,,,,,,,,32,1,4.000000e+000,0.000000e+000,0.000000e+000,0,,0,
1524577817.310,,0.000000e+000,3.499950e+001,5.402881e-006,0.000000e+000,3,8.690451e-001,0.000000e+000,,,,,,,,,,,,,,32,1,4.000000e+000,0.000000e+000,0.000000e+000,0,,0,
1524577855.440,,0.000000e+000,3.499911e+001,5.373297e-006,0.000000e+000,3,8.730341e-001,0.000000e+000,,,,,,,,,,,,,,32,1,4.000000e+000,7.820129e-004,0.000000e+000,0,,0,
1524577893.411,,0.000000e+000,3.500028e+001,5.415513e-006,0.000000e+000,3,8.645818e-001,0.000000e+000,,,,,,,,,,,,,,32,1,4.000000e+000,1.560211e-003,0.000000e+000,0,,0,
1524577931.764,,0.000000e+000,3.499911e+001,5.483440e-006,0.000000e+000,3,8.741733e-001,0.000000e+000,,,,,,,,,,,,,,32,1,4.000000e+000,7.820129e-004,0.000000e+000,0,,0,
1524577969.820,,0.000000e+000,3.499872e+001,5.411321e-006,0.000000e+000,3,8.735071e-001,0.000000e+000,,,,,,,,,,,,,,32,1,4.000000e+000,0.000000e+000,0.000000e+000,0,,0,
1524578007.493,,0.000000e+000,3.499833e+001,5.433150e-006,0.000000e+000,3,8.612035e-001,0.000000e+000,,,,,,,,,,,,,,32,1,4.000000e+000,2.349854e-003,0.000000e+000,0,,0,
1524578045.526,,0.000000e+000,3.499950e+001,5.368881e-006,0.000000e+000,3,8.624266e-001,0.000000e+000,,,,,,,,,,,,,,32,1,4.000000e+000,1.560211e-003,0.000000e+000,0,,0,
1524578083.509,,0.000000e+000,3.499872e+001,5.462192e-006,0.000000e+000,3,8.728275e-001,0.000000e+000,,,,,,,,,,,,,,32,1,4.000000e+000,0.000000e+000,0.000000e+000,0,,0,
1524578121.432,,0.000000e+000,3.499911e+001,5.442698e-006,0.000000e+000,3,8.713151e-001,0.000000e+000,,,,,,,,,,,,,,32,1,4.000000e+000,7.820129e-004,0.000000e+000,0,,0,
1524578158.822,,0.000000e+000,3.499950e+001,5.420956e-006,0.000000e+000,3,8.693572e-001,0.000000e+000,,,,,,,,,,,,,,32,1,4.000000e+000,3.120422e-003,0.000000e+000,0,,0,
1524578197.075,,0.000000e+000,3.499989e+001,5.541082e-006,0.000000e+000,3,8.732917e-001,0.000000e+000,,,,,,,,,,,,,,32,1,4.000000e+000,7.781982e-004,0.000000e+000,0,,0,
1524578234.638,,0.000000e+000,3.499989e+001,5.423973e-006,0.000000e+000,3,8.782489e-001,0.000000e+000,,,,,,,,,,,,,,32,1,4.000000e+000,7.781982e-004,0.000000e+000,0,,0,
1524578272.744,,0.000000e+000,3.499794e+001,5.437565e-006,0.000000e+000,3,8.734276e-001,0.000000e+000,,,,,,,,,,,,,,32,1,4.000000e+000,0.000000e+000,0.000000e+000,0,,0,
1524578310.925,,0.000000e+000,3.499911e+001,5.455682e-006,0.000000e+000,3,8.710012e-001,0.000000e+000,,,,,,,,,,,,,,32,1,4.000000e+000,7.820129e-004,0.000000e+000,0,,0,
1524578348.790,,0.000000e+000,3.499989e+001,5.350636e-006,0.000000e+000,3,8.793414e-001,0.000000e+000,,,,,,,,,,,,,,32,1,4.000000e+000,7.781982e-004,0.000000e+000,0,,0,
1524578387.298,,0.000000e+000,3.499950e+001,5.376075e-006,0.000000e+000,3,8.805121e-001,0.000000e+000,,,,,,,,,,,,,,32,1,4.000000e+000,1.560211e-003,0.000000e+000,0,,0,
1524578424.889,,0.000000e+000,3.499872e+001,5.463709e-006,0.000000e+000,3,8.668477e-001,0.000000e+000,,,,,,,,,,,,,,32,1,4.000000e+000,0.000000e+000,0.000000e+000,0,,0,
1524578462.892,,0.000000e+000,3.499911e+001,5.456541e-006,0.000000e+000,3,8.689739e-001,0.000000e+000,,,,,,,,,,,,,,32,1,4.000000e+000,7.820129e-004,0.000000e+000,0,,0,
1524578500.877,,0.000000e+000,3.499989e+001,5.402312e-006,0.000000e+000,3,8.691576e-001,0.000000e+000,,,,,,,,,,,,,,32,1,4.000000e+000,7.781982e-004,0.000000e+000,0,,0,
1524578538.973,,0.000000e+000,3.499833e+001,5.466846e-006,0.000000e+000,3,8.703830e-001,0.000000e+000,,,,,,,,,,,,,,32,1,4.000000e+000,7.781982e-004,0.000000e+000,0,,0,
1524578578.136,,0.000000e+000,3.499989e+001,5.523240e-006,0.000000e+000,3,8.701129e-001,0.000000e+000,,,,,,,,,,,,,,32,1,4.000000e+000,7.781982e-004,0.000000e+000,0,,0,
1524578616.887,,0.000000e+000,3.499911e+001,5.510400e-006,0.000000e+000,3,8.717449e-001,0.000000e+000,,,,,,,,,,,,,,32,1,4.000000e+000,7.820129e-004,0.000000e+000,0,,0,
1524578655.080,,0.000000e+000,3.499872e+001,5.457030e-006,0.000000e+000,3,8.664618e-001,0.000000e+000,,,,,,,,,,,,,,32,1,4.000000e+000,0.000000e+000,0.000000e+000,0,,0,
1524578693.348,,0.000000e+000,3.499754e+001,5.544214e-006,0.000000e+000,3,8.726237e-001,0.000000e+000,,,,,,,,,,,,,,32,1,4.000000e+000,3.910065e-003,0.000000e+000,0,,0,
1524578731.398,,0.000000e+000,3.499989e+001,5.561042e-006,0.000000e+000,3,8.754008e-001,0.000000e+000,,,,,,,,,,,,,,32,1,4.000000e+000,7.781982e-004,0.000000e+000,0,,0,
1524578770.004,,0.000000e+000,3.499911e+001,5.462467e-006,0.000000e+000,3,8.717493e-001,0.000000e+000,,,,,,,,,,,,,,32,1,4.000000e+000,7.820129e-004,0.000000e+000,0,,0,
1524578807.599,,0.000000e+000,3.499833e+001,5.526841e-006,0.000000e+000,3,8.814892e-001,0.000000e+000,,,,,,,,,,,,,,32,1,4.000000e+000,7.781982e-004,0.000000e+000,0,,0,
1524578846.287,,0.000000e+000,3.499872e+001,5.549196e-006,0.000000e+000,3,8.771546e-001,0.000000e+000,,,,,,,,,,,,,,32,1,4.000000e+000,0.000000e+000,0.000000e+000,0,,0,
1524578883.813,,0.000000e+000,3.499950e+001,5.548359e-006,0.000000e+000,3,8.731031e-001,0.000000e+000,,,,,,,,,,,,,,32,1,4.000000e+000,1.560211e-003,0.000000e+000,0,,0,
1524578921.609,,0.000000e+000,3.499911e+001,5.454616e-006,0.000000e+000,3,8.716131e-001,0.000000e+000,,,,,,,,,,,,,,32,1,4.000000e+000,7.820129e-004,0.000000e+000,0,,0,
1524578959.407,,0.000000e+000,3.499950e+001,5.558132e-006,0.000000e+000,3,8.766382e-001,0.000000e+000,,,,,,,,,,,,,,32,1,4.000000e+000,0.000000e+000,0.000000e+000,0,,0,
1524578997.282,,0.000000e+000,3.499989e+001,5.543893e-006,0.000000e+000,3,8.676870e-001,0.000000e+000,,,,,,,,,,,,,,32,1,4.000000e+000,7.781982e-004,0.000000e+000,0,,0,
1524579034.620,,0.000000e+000,3.499989e+001,5.591062e-006,0.000000e+000,3,8.666455e-001,0.000000e+000,,,,,,,,,,,,,,32,1,4.000000e+000,7.781982e-004,0.000000e+000,0,,0,
1524579072.701,,0.000000e+000,3.499950e+001,5.644278e-006,0.000000e+000,3,8.670837e-001,0.000000e+000,,,,,,,,,,,,,,32,1,4.000000e+000,0.000000e+000,0.000000e+000,0,,0,
1524579111.244,,0.000000e+000,3.499833e+001,5.606514e-006,0.000000e+000,3,8.766319e-001,0.000000e+000,,,,,,,,,,,,,,32,1,4.000000e+000,2.349854e-003,0.000000e+000,0,,0,
1524579149.294,,0.000000e+000,3.499793e+001,5.587854e-006,0.000000e+000,3,8.706791e-001,0.000000e+000,,,,,,,,,,,,,,32,1,4.000000e+000,1.567841e-003,0.000000e+000,0,,0,
1524579186.767,,0.000000e+000,3.500067e+001,5.551951e-006,0.000000e+000,3,8.819795e-001,0.000000e+000,,,,,,,,,,,,,,32,1,4.000000e+000,2.338409e-003,0.000000e+000,0,,0,
1524579224.430,,0.000000e+000,3.499950e+001,5.562920e-006,0.000000e+000,3,8.717242e-001,0.000000e+000,,,,,,,,,,,,,,32,1,4.000000e+000,1.560211e-003,0.000000e+000,0,,0,
1524579262.516,,0.000000e+000,3.500028e+001,5.573640e-006,0.000000e+000,3,8.692670e-001,0.000000e+000,,,,,,,,,,,,,,32,1,4.000000e+000,3.120422e-003,0.000000e+000,0,,0,
1524579300.389,,0.000000e+000,3.499989e+001,5.526109e-006,0.000000e+000,3,8.665113e-001,0.000000e+000,,,,,,,,,,,,,,32,1,4.000000e+000,7.781982e-004,0.000000e+000,0,,0,
1524579338.597,,0.000000e+000,3.499911e+001,5.582733e-006,0.000000e+000,3,8.742326e-001,0.000000e+000,,,,,,,,,,,,,,32,1,4.000000e+000,7.820129e-004,0.000000e+000,0,,0,
1524579376.755,,0.000000e+000,3.499989e+001,5.496368e-006,0.000000e+000,3,8.750282e-001,0.000000e+000,,,,,,,,,,,,,,32,1,4.000000e+000,7.781982e-004,0.000000e+000,0,,0,
1524579414.866,,0.000000e+000,3.499989e+001,5.570426e-006,0.000000e+000,3,8.742461e-001,0.000000e+000,,,,,,,,,,,,,,32,1,4.000000e+000,7.781982e-004,0.000000e+000,0,,0,
1524579453.299,,0.000000e+000,3.499911e+001,5.621213e-006,0.000000e+000,3,8.884863e-001,0.000000e+000,,,,,,,,,,,,,,32,1,4.000000e+000,7.820129e-004,0.000000e+000,0,,0,
1524579491.287,,0.000000e+000,3.499950e+001,5.642124e-006,0.000000e+000,3,8.734853e-001,0.000000e+000,,,,,,,,,,,,,,32,1,4.000000e+000,1.560211e-003,0.000000e+000,0,,0,
1524579528.745,,0.000000e+000,3.499911e+001,5.693493e-006,0.000000e+000,3,8.685126e-001,0.000000e+000,,,,,,,,,,,,,,32,1,4.000000e+000,7.820129e-004,0.000000e+000,0,,0,
1524579567.313,,0.000000e+000,3.499872e+001,5.629463e-006,0.000000e+000,3,8.872636e-001,0.000000e+000,,,,,,,,,,,,,,32,1,4.000000e+000,0.000000e+000,0.000000e+000,0,,0,
1524579605.374,,0.000000e+000,3.499911e+001,5.529052e-006,0.000000e+000,3,8.750817e-001,0.000000e+000,,,,,,,,,,,,,,32,1,4.000000e+000,7.820129e-004,0.000000e+000,0,,0,
1524579643.054,,0.000000e+000,3.499950e+001,5.546982e-006,0.000000e+000,3,8.722707e-001,0.000000e+000,,,,,,,,,,,,,,32,1,4.000000e+000,0.000000e+000,0.000000e+000,0,,0,
1524579681.166,,0.000000e+000,3.499872e+001,5.495544e-006,0.000000e+000,3,8.763528e-001,0.000000e+000,,,,,,,,,,,,,,32,1,4.000000e+000,0.000000e+000,0.000000e+000,0,,0,
1524579719.269,,0.000000e+000,3.499793e+001,5.625050e-006,0.000000e+000,3,8.813781e-001,0.000000e+000,,,,,,,,,,,,,,32,1,4.000000e+000,3.131866e-003,0.000000e+000,0,,0,
1524579731.981,,0.000000e+000,3.499911e+001,5.635047e-006,0.000000e+000,3,8.856823e-001,0.000000e+000,,,,,,,,,,,,,,32,1,4.000000e+000,7.820129e-004,0.000000e+000,0,,0,