File: Input/MFn1_TRMac_37.5K_0.04Kmin_VRMde_35K.dc.dat
[Header]
TITLE,MPMS DC Measurement
BYAPP,MPMS Measurement,2.1,Summary
FILEOPENTIME, 1524677481.007000 4/25/2018, 11:31:21 AM

INFO, APPNAME, MPMS MultiVu Application, Revision 1.61,  Build 082

INFO, NAME, MFn1
INFO, WEIGHT, 1.000
INFO, AREA, 1.000
INFO, LENGTH, 1.000
INFO, SHAPE, 0
INFO, COMMENT,
INFO, SEQUENCE FILE: TRMac_37.5K_0.04Kmin_VRMde_35K.seq


INFO, BACKGROUND DATA FILE:, None


STARTUPAXIS,X,4,LINEAR,AUTO,0.000000,0.000000
STARTUPAXIS,Y1,5,LINEAR,AUTO,0.000000,0.000000


STARTUPGROUP,Longitudinal
FIELDGROUP,Longitudinal,1,2,3,4,5,6,7,8,9,15,16,17,18,27,28
FIELDGROUP,Transverse,1,2,3,4,10,11,12,13,14,19,20,21,22,27,28

PLOT_APPEARANCE,ALL,HORZ_GRID_ON,VERT_GRID_ON,MARKERS_AND_LINES

[Data]
Time,Comment,Field (Oe),Temperature (K),Long Moment (emu),Long Scan Std Dev,Long Algorithm,Long Reg Fit,Long Percent Error (%),Trans Moment (emu),Trans Scan Std Dev,Trans Algorithm,Trans Reg Fit,Trans Percent Error (%),Long Moment [w/o ABS] (emu),Long Scan Std Dev [w/o ABS],Long Reg Fit [w/o ABS],Long Percent Error [w/o ABS] (%),Trans Moment [w/o ABS] (emu),Trans Scan Std Dev [w/o ABS],Trans Reg Fit [w/o ABS],Trans Percent Error [w/o ABS] (%),Points per Scan,Scans per Measurement,Scan Length (cm),Delta Temp (K),Rot Position (deg),Error,EC Comp. Running,Using ABS,
1524677481.007,,0.000000e+000,3.499364e+001,-2.386414e-005,0.000000e+000,3,9.743761e-001,0.000000e+000,,,,,,,,,,,,,,32,1,4.000000e+000,7.896423e-004,0.000000e+000,0,,0,
1524677518.775,,0.000000e+000,3.499363e+001,-1.921320e-005,0.000000e+000,3,9.620818e-001,0.000000e+000,,,,,,,,,,,,,,32,1,4.000000e+000,2.349854e-003,0.000000e+000,0,,0,
1524677557.176,,0.000000e+000,3.499754e+001,-1.695775e-005,0.000000e+000,3,9.585713e-001,0.000000e+000,,,,,,,,,,,,,,32,1,4.000000e+000,7.896423e-004,0.000000e+000,0,,0,
1524677594.649,,0.000000e+000,3.500849e+001,-1.549098e-005,0.000000e+000,3,9.544840e-001,0.000000e+000,,,,,,,,,,,,,,32,1,4.000000e+000,7.896423e-004,0.000000e+000,0,,0,
1524677632.964,,0.000000e+000,3.500224e+001,-1.436273e-005,0.000000e+000,3,9.545677e-001,0.000000e+000,,,,,,,,,,,,,,32,1,4.000000e+000,7.896423e-004,0.000000e+000,0,,0,
1524677683.590,,0.000000e+000,3.499715e+001,-1.320097e-005,0.000000e+000,3,9.452304e-001,0.000000e+000,,,,,,,,,,,,,,32,1,4.000000e+000,0.000000e+000,0.000000e+000,0,,0,
1524677721.548,,0.000000e+000,3.499833e+001,-1.248317e-005,0.000000e+000,3,9.422002e-001,0.000000e+000,,,,,,,,,,,,,,32,1,4.000000e+000,2.349854e-003,0.000000e+000,0,,0,
1524677760.084,,0.000000e+000,3.499950e+001,-1.184341e-005,0.000000e+000,3,9.404864e-001,0.000000e+000,,,,,,,,,,,,,,32,1,4.000000e+000,4.688263e-003,0.000000e+000,0,,0,
1524677798.139,,0.000000e+000,3.499832e+001,-1.133825e-005,0.000000e+000,3,9.364420e-001,0.000000e+000,,,,,,,,,,,,,,32,1,4.000000e+000,3.910065e-003,0.000000e+000,0,,0,
1524677836.470,,0.000000e+000,3.499911e+001,-1.083130e-005,0.000000e+000,3,9.367962e-001,0.000000e+000,,,,,,,,,,,,,,32,1,4.000000e+000,7.820129e-004,0.000000e+000,0,,0,
1524677874.251,,0.000000e+000,3.499833e+001,-1.038433e-005,0.000000e+000,3,9.252105e-001,0.000000e+000,,,,,,,,,,,,,,32,1,4.000000e+000,2.349854e-003,0.000000e+000,0,,0,
1524677912.186,,0.000000e+000,3.499872e+001,-1.000103e-005,0.000000e+000,3,9.262695e-001,0.000000e+000,,,,,,,,,,,,,,32,1,4.000000e+000,0.000000e+000,0.000000e+000,0,,0,
1524677950.249,,0.000000e+000,3.500224e+001,-9.615683e-006,0.000000e+000,3,9.221383e-001,0.000000e+000,,,,,,,,,,,,,,32,1,4.000000e+000,5.477905e-003,0.000000e+000,0,,0,
1524677987.655,,0.000000e+000,3.499950e+001,-9.337143e-006,0.000000e+000,3,9.253230e-001,0.000000e+000,,,,,,,,,,,,,,32,1,4.000000e+000,1.560211e-003,0.000000e+000,0,,0,
1524678025.250,,0.000000e+000,3.499911e+001,-8.990509e-006,0.000000e+000,3,9.230838e-001,0.000000e+000,,,,,,,,,,,,,,32,1,4.000000e+000,7.820129e-004,0.000000e+000,0,,0,
1524678063.303,,0.000000e+000,3.499911e+001,-8.711855e-006,0.000000e+000,3,9.180135e-001,0.000000e+000,,,,,,,,,,,,,,32,1,4.000000e+000,7.820129e-004,0.000000e+000,0,,0,
1524678100.756,,0.000000e+000,3.499950e+001,-8.419603e-006,0.000000e+000,3,9.150720e-001,0.000000e+000,,,,,,,,,,,,,,32,1,4.000000e+000,1.560211e-003,0.000000e+000,0,,0,
1524678137.757,,0.000000e+000,3.499793e+001,-8.205606e-006,0.000000e+000,3,9.133199e-001,0.000000e+000,,,,,,,,,,,,,,32,1,4.000000e+000,3.131866e-003,0.000000e+000,0,,0,
1524678175.817,,0.000000e+000,3.499911e+001,-7.913941e-006,0.000000e+000,3,9.099938e-001,0.000000e+000,,,,,,,,,,,,,,32,1,4.000000e+000,7.820129e-004,0.000000e+000,0,,0,
1524678214.155,,0.000000e+000,3.500028e+001,-7.684369e-006,0.000000e+000,3,9.086290e-001,0.000000e+000,,,,,,,,,,,,,,32,1,4.000000e+000,0.000000e+000,0.000000e+000,0,,0,
1524678252.076,,0.000000e+000,3.499833e+001,-7.477704e-006,0.000000e+000,3,9.017330e-001,0.000000e+000,,,,,,,,,,,,,,32,1,4.000000e+000,2.349854e-003,0.000000e+000,0,,0,
1524678290.386,,0.000000e+000,3.499950e+001,-7.265695e-006,0.000000e+000,3,8.950529e-001,0.000000e+000,,,,,,,,,,,,,,32,1,4.000000e+000,1.560211e-003,0.000000e+000,0,,0,
1524678328.432,,0.000000e+000,3.499950e+001,-7.045612e-006,0.000000e+000,3,8.981684e-001,0.000000e+000,,,,,,,,,,,,,,32,1,4.000000e+000,0.000000e+000,0.000000e+000,0,,0,
1524678366.475,,0.000000e+000,3.499911e+001,-6.908676e-006,0.000000e+000,3,8.954547e-001,0.000000e+000,,,,,,,,,,,,,,32,1,4.000000e+000,7.820129e-004,0.000000e+000,0,,0,
1524678404.576,,0.000000e+000,3.499833e+001,-6.695225e-006,0.000000e+000,3,8.932517e-001,0.000000e+000,,,,,,,,,,,,,,32,1,4.000000e+000,7.781982e-004,0.000000e+000,0,,0,
1524678443.146,,0.000000e+000,3.499989e+001,-6.535189e-006,0.000000e+000,3,8.924516e-001,0.000000e+000,,,,,,,,,,,,,,32,1,4.000000e+000,7.781982e-004,0.000000e+000,0,,0,
1524678481.847,,0.000000e+000,3.499950e+001,-6.362985e-006,0.000000e+000,3,8.891581e-001,0.000000e+000,,,,,,,,,,,,,,32,1,4.000000e+000,1.560211e-003,0.000000e+000,0,,0,
1524678521.005,,0.000000e+000,3.499950e+001,-6.175093e-006,0.000000e+000,3,8.886327e-001,0.000000e+000,,,,,,,,,,,,,,32,1,4.000000e+000,1.560211e-003,0.000000e+000,0,,0,
1524678559.061,,0.000000e+000,3.499911e+001,-6.026556e-006,0.000000e+000,3,8.887250e-001,0.000000e+000,,,,,,,,,,,,,,32,1,4.000000e+000,7.820129e-004,0.000000e+000,0,,0,
1524678597.514,,0.000000e+000,3.500028e+001,-5.870602e-006,0.000000e+000,3,8.779843e-001,0.000000e+000,,,,,,,,,,,,,,32,1,4.000000e+000,0.000000e+000,0.000000e+000,0,,0,
1524678636.049,,0.000000e+000,3.499833e+001,-5.682473e-006,0.000000e+000,3,8.768705e-001,0.000000e+000,,,,,,,,,,,,,,32,1,4.000000e+000,2.349854e-003,0.000000e+000,0,,0,
1524678673.892,,0.000000e+000,3.499950e+001,-5.606189e-006,0.000000e+000,3,8.679273e-001,0.000000e+000,,,,,,,,,,,,,,32,1,4.000000e+000,1.560211e-003,0.000000e+000,0,,0,
1524678711.430,,0.000000e+000,3.499989e+001,-5.423708e-006,0.000000e+000,3,8.649148e-001,0.000000e+000,,,,,,,,,,,,,,32,1,4.000000e+000,7.781982e-004,0.000000e+000,0,,0,
1524678749.921,,0.000000e+000,3.500028e+001,-5.307881e-006,0.000000e+000,3,8.663155e-001,0.000000e+000,,,,,,,,,,,,,,32,1,4.000000e+000,0.000000e+000,0.000000e+000,0,,0,
1524678787.784,,0.000000e+000,3.499950e+001,-5.223257e-006,0.000000e+000,3,8.609518e-001,0.000000e+000,,,,,,,,,,,,,,32,1,4.000000e+000,0.000000e+000,0.000000e+000,0,,0,
1524678825.349,,0.000000e+000,3.499950e+001,-5.049431e-006,0.000000e+000,3,8.573491e-001,0.000000e+000,,,,,,,,,,,,,,32,1,4.000000e+000,0.000000e+000,0.000000e+000,0,,0,
1524678864.627,,0.000000e+000,3.499794e+001,-4.975633e-006,0.000000e+000,3,8.559491e-001,0.000000e+000,,,,,,,,,,,,,,32,1,4.000000e+000,0.000000e+000,0.000000e+000,0,,0,
1524678902.186,,0.000000e+000,3.499911e+001,-4.827610e-006,0.000000e+000,3,8.542183e-001,0.000000e+000,,,,,,,,,,,,,,32,1,4.000000e+000,7.820129e-004,0.000000e+000,0,,0,
1524678940.174,,0.000000e+000,3.499950e+001,-4.709869e-006,0.000000e+000,3,8.484449e-001,0.000000e+000,,,,,,,,,,,,,,32,1,4.000000e+000,0.000000e+000,0.000000e+000,0,,0,
1524678977.754,,0.000000e+000,3.500067e+001,-4.668243e-006,0.000000e+000,3,8.490753e-001,0.000000e+000,,,,,,,,,,,,,,32,1,4.000000e+000,7.820129e-004,0.000000e+000,0,,0,
1524679016.292,,0.000000e+000,3.499950e+001,-4.470317e-006,0.000000e+000,3,8.511805e-001,0.000000e+000,,,,,,,,,,,,,,32,1,4.000000e+000,0.000000e+000,0.000000e+000,0,,0,
1524679053.868,,0.000000e+000,3.499833e+001,-4.504260e-006,0.000000e+000,3,8.473278e-001,0.000000e+000,,,,,,,,,,,,,,32,1,4.000000e+000,2.349854e-003,0.000000e+000,0,,0,
1524679091.713,,0.000000e+000,3.499872e+001,-4.363484e-006,0.000000e+000,3,8.228828e-001,0.000000e+000,,,,,,,,,,,,,,32,1,4.000000e+000,0.000000e+000,0.000000e+000,0,,0,
1524679129.191,,0.000000e+000,3.499950e+001,-4.201651e-006,0.000000e+000,3,8.183431e-001,0.000000e+000,,,,,,,,,,,,,,32,1,4.000000e+000,0.000000e+000,0.000000e+000,0,,0,
1524679167.242,,0.000000e+000,3.500028e+001,-4.108296e-006,0.000000e+000,3,8.280817e-001,0.000000e+000,,,,,,,,,,,,,,32,1,4.000000e+000,1.560211e-003,0.000000e+000,0,,0,
1524679205.345,,0.000000e+000,3.499793e+001,-4.023958e-006,0.000000e+000,3,8.148230e-001,0.000000e+000,,,,,,,,,,,,,,32,1,4.000000e+000,1.567841e-003,0.000000e+000,0,,0,
1524679244.136,,0.000000e+000,3.499950e+001,-3.966887e-006,0.000000e+000,3,8.230581e-001,0.000000e+000,,,,,,,,,,,,,,32,1,4.000000e+000,1.560211e-003,0.000000e+000,0,,0,
1524679282.136,,0.000000e+000,3.499911e+001,-3.871431e-006,0.000000e+000,3,8.149921e-001,0.000000e+000,,,,,,,,,,,,,,32,1,4.000000e+000,7.820129e-004,0.000000e+000,0,,0,
1524679320.199,,0.000000e+000,3.499872e+001,-3.754680e-006,0.000000e+000,3,8.155398e-001,0.000000e+000,,,,,,,,,,,,,,32,1,4.000000e+000,0.000000e+000,0.000000e+000,0,,0,
1524679358.600,,0.000000e+000,3.499872e+001,-3.641409e-006,0.000000e+000,3,8.081568e-001,0.000000e+000,,,,,,,,,,,,,,32,1,4.000000e+000,0.000000e+000,0.000000e+000,0,,0,
1524679396.713,,0.000000e+000,3.499950e+001,-3.581661e-006,0.000000e+000,3,7.934552e-001,0.000000e+000,,,,,,,,,,,,,,32,1,4.000000e+000,0.000000e+000,0.000000e+000,0,,0,
1524679435.208,,0.000000e+000,3.499989e+001,-3.512465e-006,0.000000e+000,3,7.981411e-001,0.000000e+000,,,,,,,,,,,,,,32,1,4.000000e+000,7.781982e-004,0.000000e+000,0,,0,
1524679473.259,,0.000000e+000,3.499911e+001,-3.410725e-006,0.000000e+000,3,7.875571e-001,0.000000e+000,,,,,,,,,,,,,,32,1,4.000000e+000,7.820129e-004,0.000000e+000,0,,0,
1524679510.814,,0.000000e+000,3.499911e+001,-3.362361e-006,0.000000e+000,3,7.831897e-001,0.000000e+000,,,,,,,,,,,,,,32,1,4.000000e+000,2.338409e-003,0.000000e+000,0,,0,
1524679548.908,,0.000000e+000,3.499793e+001,-3.277169e-006,0.000000e+000,3,7.748528e-001,0.000000e+000,,,,,,,,,,,,,,32,1,4.000000e+000,1.567841e-003,0.000000e+000,0,,0,
1524679586.968,,0.000000e+000,3.499872e+001,-3.215298e-006,0.000000e+000,3,7.733988e-001,0.000000e+000,,,,,,,,,,,,,,32,1,4.000000e+000,1.560211e-003,0.000000e+000,0,,0,
1524679625.019,,0.000000e+000,3.499598e+001,-3.110349e-006,0.000000e+000,3,7.702817e-001,0.000000e+000,,,,,,,,,,,,,,32,1,4.000000e+000,7.041931e-003,0.000000e+000,0,,0,
1524679663.069,,0.000000e+000,3.499950e+001,-3.061454e-006,0.000000e+000,3,7.757701e-001,0.000000e+000,,,,,,,,,,,,,,32,1,4.000000e+000,1.560211e-003,0.000000e+000,0,,0,
1524679701.120,,0.000000e+000,3.499872e+001,-3.030943e-006,0.000000e+000,3,7.544603e-001,0.000000e+000,,,,,,,,,,,,,,32,1,4.000000e+000,0.000000e+000,0.000000e+000,0,,0,
1524679738.858,,0.000000e+000,3.499715e+001,-2.953694e-006,0.000000e+000,3,7.668704e-001,0.000000e+000,,,,,,,,,,,,,,32,1,4.000000e+000,1.571655e-003,0.000000e+000,0,,0,
1524679776.763,,0.000000e+000,3.499950e+001,-2.841437e-006,0.000000e+000,3,7.405885e-001,0.000000e+000,,,,,,,,,,,,,,32,1,4.000000e+000,1.560211e-003,0.000000e+000,0,,0,
1524679814.534,,0.000000e+000,3.499950e+001,-2.789634e-006,0.000000e+000,3,7.305748e-001,0.000000e+000,,,,,,,,,,,,,,32,1,4.000000e+000,0.000000e+000,0.000000e+000,0,,0,
1524679852.810,,0.000000e+000,3.499833e+001,-2.736290e-006,0.000000e+000,3,7.420048e-001,0.000000e+000,,,,,,,,,,,,,,32,1,4.000000e+000,7.781982e-004,0.000000e+000,0,,0,
1524679891.600,,0.000000e+000,3.499911e+001,-2.679370e-006,0.000000e+000,3,7.316908e-001,0.000000e+000,,,,,,,,,,,,,,32,1,4.000000e+000,7.820129e-004,0.000000e+000,0,,0,
1524679929.723,,0.000000e+000,3.499833e+001,-2.595425e-006,0.000000e+000,3,7.230186e-001,0.000000e+000,,,,,,,,,,,,,,32,1,4.000000e+000,7.781982e-004,0.000000e+000,0,,0,
1524679967.791,,0.000000e+000,3.499872e+001,-2.516736e-006,0.000000e+000,3,7.115995e-001,0.000000e+000,,,,,,,,,,,,,,32,1,4.000000e+000,0.000000e+000,0.000000e+000,0,,0,
1524680005.784,,0.000000e+000,3.499989e+001,-2.491335e-006,0.000000e+000,3,7.130342e-001,0.000000e+000,,,,,,,,,,,,,,32,1,4.000000e+000,7.781982e-004,0.000000e+000,0,,0,
1524680044.090,,0.000000e+000,3.499872e+001,-2.433806e-006,0.000000e+000,3,7.127557e-001,0.000000e+000,,,,,,,,,,,,,,32,1,4.000000e+000,0.000000e+000,0.000000e+000,0,,0,
1524680082.135,,0.000000e+000,3.499989e+001,-2.361514e-006,0.000000e+000,3,6.749346e-001,0.000000e+000,,,,,,,,,,,,,,32,1,4.000000e+000,7.781982e-004,0.000000e+000,0,,0,
1524680119.961,,0.000000e+000,3.500067e+001,-2.328048e-006,0.000000e+000,3,6.886767e-001,0.000000e+000,,,,,,,,,,,,,,32,1,4.000000e+000,3.910065e-003,0.000000e+000,0,,0,
1524680158.049,,0.000000e+000,3.500067e+001,-2.199079e-006,0.000000e+000,3,6.783057e-001,0.000000e+000,,,,,,,,,,,,,,32,1,4.000000e+000,2.338409e-003,0.000000e+000,0,,0,
1524680195.640,,0.000000e+000,3.499950e+001,-2.218455e-006,0.000000e+000,3,6.815987e-001,0.000000e+000,,,,,,,,,,,,,,32,1,4.000000e+000,0.000000e+000,0.000000e+000,0,,0,
1524680234.158,,0.000000e+000,3.499872e+001,-2.166684e-006,0.000000e+000,3,6.733347e-001,0.000000e+000,,,,,,,,,,,,,,32,1,4.000000e+000,0.000000e+000,0.000000e+000,0,,0,
1524680271.756,,0.000000e+000,3.499911e+001,-2.132618e-006,0.000000e+000,3,6.744043e-001,0.000000e+000,,,,,,,,,,,,,,32,1,4.000000e+000,7.820129e-004,0.000000e+000,0,,0,
1524680308.996,,0.000000e+000,3.499950e+001,-2.035385e-006,0.000000e+000,3,6.343806e-001,0.000000e+000,,,,,,,,,,,,,,32,1,4.000000e+000,0.000000e+000,0.000000e+000,0,,0,
1524680347.057,,0.000000e+000,3.499872e+001,-2.015232e-006,0.000000e+000,3,6.379245e-001,0.000000e+000,,,,,,,,,,,,,,32,1,4.000000e+000,1.560211e-003,0.000000e+000,0,,0,
1524680385.152,,0.000000e+000,3.499833e+001,-1.956801e-006,0.000000e+000,3,6.181186e-001,0.000000e+000,,,,,,,,,,,,,,32,1,4.000000e+000,7.781982e-004,0.000000e+000,0,,0,
1524680423.748,,0.000000e+000,3.499872e+001,-1.886599e-006,0.000000e+000,3,6.025118e-001,0.000000e+000,,,,,,,,,,,,,,32,1,4.000000e+000,0.000000e+000,0.000000e+000,0,,0,
1524680461.461,,0.000000e+000,3.499989e+001,-1.844037e-006,0.000000e+000,3,6.075252e-001,0.000000e+000,,,,,,,,,,,,,,32,1,4.000000e+000,7.781982e-004,0.000000e+000,0,,0,
1524680499.419,,0.000000e+000,3.500067e+001,-1.823839e-006,0.000000e+000,3,6.035078e-001,0.000000e+000,,,,,,,,,,,,,,32,1,4.000000e+000,2.338409e-003,0.000000e+000,0,,0,
1524680537.057,,0.000000e+000,3.499833e+001,-1.738212e-006,0.000000e+000,3,5.866636e-001,0.000000e+000,,,,,,,,,,,,,,32,1,4.000000e+000,7.781982e-004,0.000000e+000,0,,0,
1524680576.178,,0.000000e+000,3.499872e+001,-1.706836e-006,0.000000e+000,3,5.819736e-001,0.000000e+000,,,,,,,,,,,,,,32,1,4.000000e+000,0.000000e+000,0.000000e+000,0,,0,
1524680613.558,,0.000000e+000,3.500028e+001,-1.678231e-006,0.000000e+000,3,5.693808e-001,0.000000e+000,,,,,,,,,,,,,,32,1,4.000000e+000,1.560211e-003,0.000000e+000,0,,0,
1524680651.066,,0.000000e+000,3.499911e+001,-1.630258e-006,0.000000e+000,3,5.490478e-001,0.000000e+000,,,,,,,,,,,,,,32,1,4.000000e+000,7.820129e-004,0.000000e+000,0,,0,
1524680689.097,,0.000000e+000,3.499872e+001,-1.629881e-006,0.000000e+000,3,5.298913e-001,0.000000e+000,,,,,,,,,,,,,,32,1,4.000000e+000,1.560211e-003,0.000000e+000,0,,0,
1524680726.937,,0.000000e+000,3.499911e+001,-1.539885e-006,0.000000e+000,3,5.070044e-001,0.000000e+000,,,,,,,,,,,,,,32,1,4.000000e+000,7.820129e-004,0.000000e+000,0,,0,
1524680765.200,,0.000000e+000,3.499911e+001,-1.491862e-006,0.000000e+000,3,5.074410e-001,0.000000e+000,,,,,,,,,,,,,,32,1,4.000000e+000,7.820129e-004,0.000000e+000,0,,0,
1524680803.853,,0.000000e+000,3.499950e+001,-1.458271e-006,0.000000e+000,3,4.980777e-001,0.000000e+000,,,,,,,,,,,,,,32,1,4.000000e+000,0.000000e+000,0.000000e+000,0,,0,
1524680841.621,,0.000000e+000,3.500028e+001,-1.433558e-006,0.000000e+000,3,5.031828e-001,0.000000e+000,,,,,,,,,,,,,,32,1,4.000000e+000,1.560211e-003,0.000000e+000,0,,0,
1524680879.937,,0.000000e+000,3.499911e+001,-1.413008e-006,0.000000e+000,3,5.051498e-001,0.000000e+000,,,,,,,,,,,,,,32,1,4.000000e+000,7.820129e-004,0.000000e+000,0,,0,
1524680919.098,,0.000000e+000,3.499872e+001,-1.346253e-006,0.000000e+000,3,4.506636e-001,0.000000e+000,,,,,,,,,,,,,,32,1,4.000000e+000,1.560211e-003,0.000000e+000,0,,0,
1524680957.166,,0.000000e+000,3.499911e+001,-1.271661e-006,0.000000e+000,3,4.106996e-001,0.000000e+000,,,,,,,,,,,,,,32,1,4.000000e+000,7.820129e-004,0.000000e+000,0,,0,
1524680994.134,,0.000000e+000,3.499872e+001,-1.277240e-006,0.000000e+000,3,4.105895e-001,0.000000e+000,,,,,,,,,,,,,,32,1,4.000000e+000,0.000000e+000,0.000000e+000,0,,0,
1524681032.199,,0.000000e+000,3.499872e+001,-1.233625e-006,0.000000e+000,3,3.814244e-001,0.000000e+000,,,,,,,,,,,,,,32,1,4.000000e+000,0.000000e+000,0.000000e+000,0,,0,
1524681070.220,,0.000000e+000,3.499950e+001,-1.203023e-006,0.000000e+000,3,3.751611e-001,0.000000e+000,,,,,,,,,,,,,,32,1,4.000000e+000,0.000000e+000,0.000000e+000,0,,0,
1524681108.048,,0.000000e+000,3.499872e+001,-1.135940e-006,0.000000e+000,3,3.061820e-001,0.000000e+000,,,,,,,,,,,,,,32,1,4.000000e+000,0.000000e+000,0.000000e+000,0,,0,
1524681145.513,,0.000000e+000,3.499911e+001,-1.096603e-006,0.000000e+000,3,3.354416e-001,0.000000e+000,,,,,,,,,,,,,,32,1,4.000000e+000,7.820129e-004,0.000000e+000,0,,0,
1524681183.099,,0.000000e+000,3.499950e+001,-1.077686e-006,0.000000e+000,3,3.337893e-001,0.000000e+000,,,,,,,,,,,,,,32,1,4.000000e+000,1.560211e-003,0.000000e+000,0,,0,
1524681221.642,,0.000000e+000,3.499950e+001,-1.078913e-006,0.000000e+000,3,3.254055e-001,0.000000e+000,,,,,,,,,,,,,,32,1,4.000000e+000,0.000000e+000,0.000000e+000,0,,0,
1524681259.210,,0.000000e+000,3.499872e+001,-1.025371e-006,0.000000e+000,3,2.953845e-001,0.000000e+000,,,,,,,,,,,,,,32,1,4.000000e+000,0.000000e+000,0.000000e+000,0,,0,
1524681298.011,,0.000000e+000,3.499872e+001,-1.030425e-006,0.000000e+000,3,2.759644e-001,0.000000e+000,,,,,,,,,,,,,,32,1,4.000000e+000,1.560211e-003,0.000000e+000,0,,0,
1524681335.906,,0.000000e+000,3.499911e+001,-9.683816e-007,0.000000e+000,3,2.314498e-001,0.000000e+000,,,,,,,,,,,,,,32,1,4.000000e+000,2.338409e-003,0.000000e+000,0,,0,
1524681374.099,,0.000000e+000,3.499950e+001,-9.205366e-007,0.000000e+000,3,1.822803e-001,0.000000e+000,,,,,,,,,,,,,,32,1,4.000000e+000,0.000000e+000,0.000000e+000,0,,0,
1524681412.167,,0.000000e+000,3.499989e+001,-9.348745e-007,0.000000e+000,3,1.861506e-001,0.000000e+000,,,,,,,,,,,,,,32,1,4.000000e+000,7.781982e-004,0.000000e+000,0,,0,
1524681450.185,,0.000000e+000,3.499833e+001,-9.010283e-007,0.000000e+000,3,1.353998e-001,0.000000e+000,,,,,,,,,,,,,,32,1,4.000000e+000,7.781982e-004,0.000000e+000,0,,0,
1524681487.708,,0.000000e+000,3.499950e+001,-8.996600e-007,0.000000e+000,3,1.596710e-001,0.000000e+000,,,,,,,,,,,,,,32,1,4.000000e+000,1.560211e-003,0.000000e+000,0,,0,
1524681525.189,,0.000000e+000,3.499793e+001,-9.796970e-007,0.000000e+000,3,2.371471e-001,0.000000e+000,,,,,,,,,,,,,,32,1,4.000000e+000,1.567841e-003,0.000000e+000,0,,0,
1524681563.505,,0.000000e+000,3.499950e+001,-8.029282e-007,0.000000e+000,3,1.061537e-003,0.000000e+000,,,,,,,,,,,,,,32,1,4.000000e+000,1.560211e-003,0.000000e+000,0,,0,
1524681601.235,,0.000000e+000,3.499872e+001,-7.812596e-007,0.000000e+000,3,0.000000e+000,0.000000e+000,,,,,,,,,,,,,,32,1,4.000000e+000,0.000000e+000,0.000000e+000,0,,0,
1524681639.281,,0.000000e+000,3.499911e+001,-7.520632e-007,0.000000e+000,3,0.000000e+000,0.000000e+000,,,,,,,,,,,,,,32,1,4.000000e+000,7.820129e-004,0.000000e+000,0,,0,
1524681677.814,,0.000000e+000,3.499950e+001,-5.400316e-007,0.000000e+000,3,0.000000e+000,0.000000e+000,,,,,,,,,,,,,,32,1,4.000000e+000,0.000000e+000,0.000000e+000,0,,0,
1524681715.444,,0.000000e+000,3.499911e+001,-6.129030e-007,0.000000e+000,3,0.000000e+000,0.000000e+000,,,,,,,,,,,,,,32,1,4.000000e+000,7.820129e-004,0.000000e+000,0,,0,
1524681753.945,,0.000000e+000,3.499872e+001,-5.749846e-007,0.000000e+000,3,0.000000e+000,0.000000e+000,,,,,,,,,,,,,,32,1,4.000000e+000,0.000000e+000,0.000000e+000,0,,0,
1524681791.570,,0.000000e+000,3.500028e+001,5.677690e-007,0.000000e+000,3,0.000000e+000,0.000000e+000,,,,,,,,,,,,,,32,1,4.000000e+000,1.560211e-003,0.000000e+000,0,,0,
1524681833.054,,0.000000e+000,3.499872e+001,-2.278247e-007,0.000000e+000,2,0.000000e+000,0.000000e+000,,,,,,,,,,,,,,32,1,4.000000e+000,0.000000e+000,0.000000e+000,0,,0,
1524681876.041,,0.000000e+000,3.499715e+001,-2.059498e-007,0.000000e+000,2,0.000000e+000,0.000000e+000,,,,,,,,,,,,,,32,1,4.000000e+000,3.128052e-003,0.000000e+000,0,,0,
1524681915.522,,0.000000e+000,3.499989e+001,9.765918e-007,0.000000e+000,3,2.882372e-001,0.000000e+000,,,,,,,,,,,,,,32,1,4.000000e+000,2.342224e-003,0.000000e+000,0,,0,
1524681954.388,,0.000000e+000,3.499950e+001,9.201643e-007,0.000000e+000,3,2.657186e-001,0.000000e+000,,,,,,,,,,,,,,32,1,4.000000e+000,0.000000e+000,0.000000e+000,0,,0,
1524681991.689,,0.000000e+000,3.499872e+001,8.518355e-007,0.000000e+000,3,1.207862e-001,0.000000e+000,,,,,,,,,,,,,,32,1,4.000000e+000,0.000000e+000,0.000000e+000,0,,0,
1524682033.048,,0.000000e+000,3.500146e+001,9.224381e-007,0.000000e+000,3,2.622630e-001,0.000000e+000,,,,,,,,,,,,,,32,1,4.000000e+000,3.910065e-003,0.000000e+000,0,,0,
1524682074.217,,0.000000e+000,3.499911e+001,-1.064767e-007,0.000000e+000,3,0.000000e+000,0.000000e+000,,,,,,,,,,,,,,32,1,4.000000e+000,7.820129e-004,0.000000e+000,0,,0,
1524682112.188,,0.000000e+000,3.499872e+001,-4.433599e-007,0.000000e+000,3,0.000000e+000,0.000000e+000,,,,,,,,,,,,,,32,1,4.000000e+000,1.560211e-003,0.000000e+000,0,,0,
1524682152.354,,0.000000e+000,3.500028e+001,9.209709e-007,0.000000e+000,3,2.383906e-001,0.000000e+000,,,,,,,,,,,,,,32,1,4.000000e+000,0.000000e+000,0.000000e+000,0,,0,
1524682192.432,,0.000000e+000,3.499872e+001,5.838403e-008,0.000000e+000,2,0.000000e+000,0.000000e+000,,,,,,,,,,,,,,32,1,4.000000e+000,0.000000e+000,0.000000e+000,0,,0,
1524682230.608,,0.000000e+000,3.499911e+001,-3.297388e-007,0.000000e+000,3,0.000000e+000,0.000000e+000,,,,,,,,,,,,,,32,1,4.000000e+000,7.820129e-004,0.000000e+000,0,,0,
1524682270.164,,0.000000e+000,3.499950e+001,-4.006822e-007,0.000000e+000,3,0.000000e+000,0.000000e+000,,,,,,,,,,,,,,32,1,4.000000e+000,0.000000e+000,0.000000e+000,0,,0,
1524682307.800,,0.000000e+000,3.499989e+001,-2.886850e-007,0.000000e+000,3,0.000000e+000,0.000000e+000,,,,,,,,,,,,,,32,1,4.000000e+000,3.898621e-003,0.000000e+000,0,,0,
1524682346.868,,0.000000e+000,3.499911e+001,-4.642487e-007,0.000000e+000,3,0.000000e+000,0.000000e+000,,,,,,,,,,,,,,32,1,4.000000e+000,7.820129e-004,0.000000e+000,0,,0,
1524682385.666,,0.000000e+000,3.499950e+001,-3.868471e-007,0.000000e+000,3,0.000000e+000,0.000000e+000,,,,,,,,,,,,,,32,1,4.000000e+000,0.000000e+000,0.000000e+000,0,,0,
1524682423.709,,0.000000e+000,3.500028e+001,-4.181904e-007,0.000000e+000,3,0.000000e+000,0.000000e+000,,,,,,,,,,,,,,32,1,4.000000e+000,0.000000e+000,0.000000e+000,0,,0,
1524682465.856,,0.000000e+000,3.500067e+001,2.691059e-007,0.000000e+000,2,0.000000e+000,0.000000e+000,,,,,,,,,,,,,,32,1,4.000000e+000,7.820129e-004,0.000000e+000,0,,0,
1524682510.175,,0.000000e+000,3.500028e+001,3.304667e-007,0.000000e+000,2,0.000000e+000,0.000000e+000,,,,,,,,,,,,,,32,1,4.000000e+000,1.560211e-003,0.000000e+000,0,,0,
1524682552.480,,0.000000e+000,3.499833e+001,3.031932e-007,0.000000e+000,2,0.000000e+000,0.000000e+000,,,,,,,,,,,,,,32,1,4.000000e+000,7.781982e-004,0.000000e+000,0,,0,
1524682593.961,,0.000000e+000,3.500028e+001,4.150087e-007,0.000000e+000,3,0.000000e+000,0.000000e+000,,,,,,,,,,,,,,32,1,4.000000e+000,1.560211e-003,0.000000e+000,0,,0,
1524682636.018,,0.000000e+000,3.499950e+001,3.796958e-007,0.000000e+000,2,0.000000e+000,0.000000e+000,,,,,,,,,,,,,,32,1,4.000000e+000,0.000000e+000,0.000000e+000,0,,0,
1524682675.812,,0.000000e+000,3.499911e+001,3.694624e-007,0.000000e+000,2,0.000000e+000,0.000000e+000,,,,,,,,,,,,,,32,1,4.000000e+000,7.820129e-004,0.000000e+000,0,,0,
1524682713.740,,0.000000e+000,3.499950e+001,8.371542e-007,0.000000e+000,3,6.709348e-002,0.000000e+000,,,,,,,,,,,,,,32,1,4.000000e+000,0.000000e+000,0.000000e+000,0,,0,
1524682751.868,,0.000000e+000,3.499911e+001,1.018804e-006,0.000000e+000,3,3.604763e-001,0.000000e+000,,,,,,,,,,,,,,32,1,4.000000e+000,7.820129e-004,0.000000e+000,0,,0,
1524682791.686,,0.000000e+000,3.500028e+001,1.070935e-006,0.000000e+000,3,3.935039e-001,0.000000e+000,,,,,,,,,,,,,,32,1,4.000000e+000,1.560211e-003,0.000000e+000,0,,0,
1524682830.625,,0.000000e+000,3.499989e+001,1.068165e-006,0.000000e+000,3,3.644913e-001,0.000000e+000,,,,,,,,,,,,,,32,1,4.000000e+000,2.342224e-003,0.000000e+000,0,,0,
1524682868.055,,0.000000e+000,3.500028e+001,1.109426e-006,0.000000e+000,3,4.391979e-001,0.000000e+000,,,,,,,,,,,,,,32,1,4.000000e+000,0.000000e+000,0.000000e+000,0,,0,
1524682908.399,,0.000000e+000,3.500185e+001,1.094726e-006,0.000000e+000,3,4.168376e-001,0.000000e+000,,,,,,,,,,,,,,32,1,4.000000e+000,4.688263e-003,0.000000e+000,0,,0,
1524682946.367,,0.000000e+000,3.499911e+001,1.031696e-006,0.000000e+000,3,3.563978e-001,0.000000e+000,,,,,,,,,,,,,,32,1,4.000000e+000,7.820129e-004,0.000000e+000,0,,0,
1524682984.452,,0.000000e+000,3.499872e+001,1.161148e-006,0.000000e+000,3,4.384983e-001,0.000000e+000,,,,,,,,,,,,,,32,1,4.000000e+000,0.000000e+000,0.000000e+000,0,,0,
1524683022.450,,0.000000e+000,3.499872e+001,1.067438e-006,0.000000e+000,3,3.820370e-001,0.000000e+000,,,,,,,,,,,,,,32,1,4.000000e+000,0.000000e+000,0.000000e+000,0,,0,
1524683060.569,,0.000000e+000,3.499911e+001,1.073870e-006,0.000000e+000,3,3.906343e-001,0.000000e+000,,,,,,,,,,,,,,32,1,4.000000e+000,7.820129e-004,0.000000e+000,0,,0,
1524683098.644,,0.000000e+000,3.499911e+001,1.215818e-006,0.000000e+000,3,4.448290e-001,0.000000e+000,,,,,,,,,,,,,,32,1,4.000000e+000,7.820129e-004,0.000000e+000,0,,0,
1524683136.642,,0.000000e+000,3.499950e+001,1.141012e-006,0.000000e+000,3,4.179067e-001,0.000000e+000,,,,,,,,,,,,,,32,1,4.000000e+000,0.000000e+000,0.000000e+000,0,,0,
1524683174.725,,0.000000e+000,3.499989e+001,1.100643e-006,0.000000e+000,3,4.062542e-001,0.000000e+000,,,,,,,,,,,,,,32,1,4.000000e+000,7.781982e-004,0.000000e+000,0,,0,
1524683212.811,,0.000000e+000,3.499911e+001,1.145889e-006,0.000000e+000,3,4.017550e-001,0.000000e+000,,,,,,,,,,,,,,32,1,4.000000e+000,7.820129e-004,0.000000e+000,0,,0,
1524683250.864,,0.000000e+000,3.499911e+001,1.150055e-006,0.000000e+000,3,4.152178e-001,0.000000e+000,,,,,,,,,,,,,,32,1,4.000000e+000,7.820129e-004,0.000000e+000,0,,0,
1524683288.659,,0.000000e+000,3.499872e+001,1.197818e-006,0.000000e+000,3,4.089478e-001,0.000000e+000,,,,,,,,,,,,,,32,1,4.000000e+000,0.000000e+000,0.000000e+000,0,,0,
1524683326.433,,0.000000e+000,3.499833e+001,1.272853e-006,0.000000e+000,3,4.686837e-001,0.000000e+000,,,,,,,,,,,,,,32,1,4.000000e+000,7.781982e-004,0.000000e+000,0,,0,
1524683364.346,,0.000000e+000,3.499989e+001,1.308658e-006,0.000000e+000,3,5.285470e-001,0.000000e+000,,,,,,,,,,,,,,32,1,4.000000e+000,7.781982e-004,0.000000e+000,0,,0,
1524683402.539,,0.000000e+000,3.499989e+001,1.219185e-006,0.000000e+000,3,4.427830e-001,0.000000e+000,,,,,,,,,,,,,,32,1,4.000000e+000,7.781982e-004,0.000000e+000,0,,0,
1524683440.124,,0.000000e+000,3.500028e+001,1.192818e-006,0.000000e+000,3,4.689154e-001,0.000000e+000,,,,,,,,,,,,,,32,1,4.000000e+000,0.000000e+000,0.000000e+000,0,,0,
1524683477.490,,0.000000e+000,3.499872e+001,1.249749e-006,0.000000e+000,3,4.462593e-001,0.000000e+000,,,,,,,,,,,,,,32,1,4.000000e+000,0.000000e+000,0.000000e+000,0,,0,
1524683514.875,,0.000000e+000,3.499950e+001,1.236945e-006,0.000000e+000,3,4.584437e-001,0.000000e+000,,,,,,,,,,,,,,32,1,4.000000e+000,0.000000e+000,0.000000e+000,0,,0,
1524683553.198,,0.000000e+000,3.499911e+001,1.229928e-006,0.000000e+000,3,4.730948e-001,0.000000e+000,,,,,,,,,,,,,,32,1,4.000000e+000,7.820129e-004,0.000000e+000,0,,0,
1524683590.974,,0.000000e+000,3.500028e+001,1.248496e-006,0.000000e+000,3,4.757964e-001,0.000000e+000,,,,,,,,,,,,,,32,1,4.000000e+000,0.000000e+000,0.000000e+000,0,,0,
1524683629.044,,0.000000e+000,3.499950e+001,1.238816e-006,0.000000e+000,3,4.702611e-001,0.000000e+000,,,,,,,,,,,,,,32,1,4.000000e+000,0.000000e+000,0.000000e+000,0,,0,
1524683666.460,,0.000000e+000,3.499950e+001,1.316899e-006,0.000000e+000,3,4.972591e-001,0.000000e+000,,,,,,,,,,,,,,32,1,4.000000e+000,1.560211e-003,0.000000e+000,0,,0,
1524683704.108,,0.000000e+000,3.499911e+001,1.328814e-006,0.000000e+000,3,4.733146e-001,0.000000e+000,,,,,,,,,,,,,,32,1,4.000000e+000,7.820129e-004,0.000000e+000,0,,0,
1524683741.916,,0.000000e+000,3.499872e+001,1.372966e-006,0.000000e+000,3,5.169416e-001,0.000000e+000,,,,,,,,,,,,,,32,1,4.000000e+000,0.000000e+000,0.000000e+000,0,,0,
1524683779.817,,0.000000e+000,3.499911e+001,1.384079e-006,0.000000e+000,3,5.326694e-001,0.000000e+000,,,,,,,,,,,,,,32,1,4.000000e+000,7.820129e-004,0.000000e+000,0,,0,
1524683817.392,,0.000000e+000,3.500028e+001,1.262539e-006,0.000000e+000,3,4.620549e-001,0.000000e+000,,,,,,,,,,,,,,32,1,4.000000e+000,3.120422e-003,0.000000e+000,0,,0,
1524683855.693,,0.000000e+000,3.499950e+001,1.386469e-006,0.000000e+000,3,5.185083e-001,0.000000e+000,,,,,,,,,,,,,,32,1,4.000000e+000,1.560211e-003,0.000000e+000,0,,0,
1524683893.581,,0.000000e+000,3.499950e+001,1.369987e-006,0.000000e+000,3,4.891730e-001,0.000000e+000,,,,,,,,,,,,,,32,1,4.000000e+000,0.000000e+000,0.000000e+000,0,,0,
1524683931.199,,0.000000e+000,3.499989e+001,1.379180e-006,0.000000e+000,3,5.393900e-001,0.000000e+000,,,,,,,,,,,,,,32,1,4.000000e+000,2.342224e-003,0.000000e+000,0,,0,
1524683969.104,,0.000000e+000,3.499833e+001,1.519213e-006,0.000000e+000,3,5.811210e-001,0.000000e+000,,,,,,,,,,,,,,32,1,4.000000e+000,2.349854e-003,0.000000e+000,0,,0,
1524684007.140,,0.000000e+000,3.499872e+001,1.379993e-006,0.000000e+000,3,4.808495e-001,0.000000e+000,,,,,,,,,,,,,,32,1,4.000000e+000,0.000000e+000,0.000000e+000,0,,0,
1524684045.366,,0.000000e+000,3.499950e+001,1.453342e-006,0.000000e+000,3,5.646013e-001,0.000000e+000,,,,,,,,,,,,,,32,1,4.000000e+000,0.000000e+000,0.000000e+000,0,,0,
1524684083.584,,0.000000e+000,3.499871e+001,1.458451e-006,0.000000e+000,3,5.349721e-001,0.000000e+000,,,,,,,,,,,,,,32,1,4.000000e+000,3.128052e-003,0.000000e+000,0,,0,
1524684121.094,,0.000000e+000,3.500028e+001,1.507813e-006,0.000000e+000,3,5.567780e-001,0.000000e+000,,,,,,,,,,,,,,32,1,4.000000e+000,3.120422e-003,0.000000e+000,0,,0,
1524684160.035,,0.000000e+000,3.499872e+001,1.529261e-006,0.000000e+000,3,5.659725e-001,0.000000e+000,,,,,,,,,,,,,,32,1,4.000000e+000,0.000000e+000,0.000000e+000,0,,0,
1524684197.035,,0.000000e+000,3.499950e+001,1.459170e-006,0.000000e+000,3,5.398798e-001,0.000000e+000,,,,,,,,,,,,,,32,1,4.000000e+000,0.000000e+000,0.000000e+000,0,,0,
1524684235.053,,0.000000e+000,3.500028e+001,1.560793e-006,0.000000e+000,3,5.810779e-001,0.000000e+000,,,,,,,,,,,,,,32,1,4.000000e+000,0.000000e+000,0.000000e+000,0,,0,
1524684273.159,,0.000000e+000,3.499950e+001,1.547592e-006,0.000000e+000,3,5.465273e-001,0.000000e+000,,,,,,,,,,,,,,32,1,4.000000e+000,0.000000e+000,0.000000e+000,0,,0,
1524684311.354,,0.000000e+000,3.499911e+001,1.556643e-006,0.000000e+000,3,5.567820e-001,0.000000e+000,,,,,,,,,,,,,,32,1,4.000000e+000,7.820129e-004,0.000000e+000,0,,0,
1524684349.252,,0.000000e+000,3.499950e+001,1.504005e-006,0.000000e+000,3,5.731738e-001,0.000000e+000,,,,,,,,,,,,,,32,1,4.000000e+000,0.000000e+000,0.000000e+000,0,,0,
1524684387.320,,0.000000e+000,3.499989e+001,1.582963e-006,0.000000e+000,3,5.721013e-001,0.000000e+000,,,,,,,,,,,,,,32,1,4.000000e+000,7.781982e-004,0.000000e+000,0,,0,
1524684425.359,,0.000000e+000,3.499911e+001,1.558921e-006,0.000000e+000,3,5.579431e-001,0.000000e+000,,,,,,,,,,,,,,32,1,4.000000e+000,7.820129e-004,0.000000e+000,0,,0,
1524684463.447,,0.000000e+000,3.499950e+001,1.592133e-006,0.000000e+000,3,5.626870e-001,0.000000e+000,,,,,,,,,,,,,,32,1,4.000000e+000,1.560211e-003,0.000000e+000,0,,0,
1524684501.640,,0.000000e+000,3.499950e+001,1.615114e-006,0.000000e+000,3,5.768150e-001,0.000000e+000,,,,,,,,,,,,,,32,1,4.000000e+000,1.560211e-003,0.000000e+000,0,,0,
1524684539.570,,0.000000e+000,3.499911e+001,1.660529e-006,0.000000e+000,3,6.041007e-001,0.000000e+000,,,,,,,,,,,,,,32,1,4.000000e+000,7.820129e-004,0.000000e+000,0,,0,
1524684577.646,,0.000000e+000,3.499872e+001,1.652378e-006,0.000000e+000,3,6.340924e-001,0.000000e+000,,,,,,,,,,,,,,32,1,4.000000e+000,0.000000e+000,0.000000e+000,0,,0,
1524684615.161,,0.000000e+000,3.499950e+001,1.667141e-006,0.000000e+000,3,5.717620e-001,0.000000e+000,,,,,,,,,,,,,,32,1,4.000000e+000,1.560211e-003,0.000000e+000,0,,0,
1524684653.204,,0.000000e+000,3.499911e+001,1.656480e-006,0.000000e+000,3,5.956042e-001,0.000000e+000,,,,,,,,,,,,,,32,1,4.000000e+000,7.820129e-004,0.000000e+000,0,,0,
1524684691.468,,0.000000e+000,3.500028e+001,1.714745e-006,0.000000e+000,3,5.923838e-001,0.000000e+000,,,,,,,,,,,,,,32,1,4.000000e+000,0.000000e+000,0.000000e+000,0,,0,
1524684729.323,,0.000000e+000,3.499872e+001,1.702278e-006,0.000000e+000,3,5.852498e-001,0.000000e+000,,,,,,,,,,,,,,32,1,4.000000e+000,1.560211e-003,0.000000e+000,0,,0,
1524684767.324,,0.000000e+000,3.499950e+001,1.702806e-006,0.000000e+000,3,5.935705e-001,0.000000e+000,,,,,,,,,,,,,,32,1,4.000000e+000,3.120422e-003,0.000000e+000,0,,0,
1524684806.192,,0.000000e+000,3.499911e+001,1.706233e-006,0.000000e+000,3,5.959969e-001,0.000000e+000,,,,,,,,,,,,,,32,1,4.000000e+000,7.820129e-004,0.000000e+000,0,,0,
1524684844.175,,0.000000e+000,3.499950e+001,1.716623e-006,0.000000e+000,3,6.238528e-001,0.000000e+000,,,,,,,,,,,,,,32,1,4.000000e+000,1.560211e-003,0.000000e+000,0,,0,
1524684882.718,,0.000000e+000,3.499872e+001,1.790671e-006,0.000000e+000,3,6.239928e-001,0.000000e+000,,,,,,,,,,,,,,32,1,4.000000e+000,0.000000e+000,0.000000e+000,0,,0,
1524684920.671,,0.000000e+000,3.499911e+001,1.799132e-006,0.000000e+000,3,6.308506e-001,0.000000e+000,,,,,,,,,,,,,,32,1,4.000000e+000,7.820129e-004,0.000000e+000,0,,0,
1524684959.199,,0.000000e+000,3.499950e+001,1.804192e-006,0.000000e+000,3,6.318860e-001,0.000000e+000,,,,,,,,,,,,,,32,1,4.000000e+000,1.560211e-003,0.000000e+000,0,,0,
1524684998.035,,0.000000e+000,3.499911e+001,1.802852e-006,0.000000e+000,3,6.155719e-001,0.000000e+000,,,,,,,,,,,,,,32,1,4.000000e+000,7.820129e-004,0.000000e+000,0,,0,
1524685036.018,,0.000000e+000,3.499911e+001,1.804905e-006,0.000000e+000,3,6.309520e-001,0.000000e+000,,,,,,,,,,,,,,32,1,4.000000e+000,7.820129e-004,0.000000e+000,0,,0,
1524685074.173,,0.000000e+000,3.499989e+001,1.833093e-006,0.000000e+000,3,6.360183e-001,0.000000e+000,,,,,,,,,,,,,,32,1,4.000000e+000,7.781982e-004,0.000000e+000,0,,0,
1524685112.159,,0.000000e+000,3.499911e+001,1.828973e-006,0.000000e+000,3,6.315934e-001,0.000000e+000,,,,,,,,,,,,,,32,1,4.000000e+000,7.820129e-004,0.000000e+000,0,,0,
1524685150.279,,0.000000e+000,3.499872e+001,1.833380e-006,0.000000e+000,3,6.362004e-001,0.000000e+000,,,,,,,,,,,,,,32,1,4.000000e+000,1.560211e-003,0.000000e+000,0,,0,
1524685188.280,,0.000000e+000,3.499989e+001,1.850075e-006,0.000000e+000,3,6.452774e-001,0.000000e+000,,,,,,,,,,,,,,32,1,4.000000e+000,7.781982e-004,0.000000e+000,0,,0,
1524685226.675,,0.000000e+000,3.499950e+001,1.867837e-006,0.000000e+000,3,6.393522e-001,0.000000e+000,,,,,,,,,,,,,,32,1,4.000000e+000,0.000000e+000,0.000000e+000,0,,0,
1524685265.066,,0.000000e+000,3.499833e+001,1.888641e-006,0.000000e+000,3,6.451554e-001,0.000000e+000,,,,,,,,,,,,,,32,1,4.000000e+000,2.349854e-003,0.000000e+000,0,,0,
1524685302.649,,0.000000e+000,3.499872e+001,1.905361e-006,0.000000e+000,3,6.620024e-001,0.000000e+000,,,,,,,,,,,,,,32,1,4.000000e+000,1.560211e-003,0.000000e+000,0,,0,
1524685340.332,,0.000000e+000,3.499950e+001,1.911565e-006,0.000000e+000,3,6.470944e-001,0.000000e+000,,,,,,,,,,,,,,32,1,4.000000e+000,0.000000e+000,0.000000e+000,0,,0,
1524685377.890,,0.000000e+000,3.499872e+001,2.004783e-006,0.000000e+000,3,6.452007e-001,0.000000e+000,,,,,,,,,,,,,,32,1,4.000000e+000,0.000000e+000,0.000000e+000,0,,0,
1524685415.956,,0.000000e+000,3.499793e+001,1.945183e-006,0.000000e+000,3,6.419656e-001,0.000000e+000,,,,,,,,,,,,,,32,1,4.000000e+000,1.567841e-003,0.000000e+000,0,,0,
1524685454.009,,0.000000e+000,3.499989e+001,1.961737e-006,0.000000e+000,3,6.474789e-001,0.000000e+000,,,,,,,,,,,,,,32,1,4.000000e+000,7.781982e-004,0.000000e+000,0,,0,
1524685492.624,,0.000000e+000,3.499911e+001,2.004563e-006,0.000000e+000,3,6.555800e-001,0.000000e+000,,,,,,,,,,,,,,32,1,4.000000e+000,7.820129e-004,0.000000e+000,0,,0,
1524685529.887,,0.000000e+000,3.499950e+001,1.986999e-006,0.000000e+000,3,6.360334e-001,0.000000e+000,,,,,,,,,,,,,,32,1,4.000000e+000,0.000000e+000,0.000000e+000,0,,0,
1524685568.943,,0.000000e+000,3.499911e+001,1.976270e-006,0.000000e+000,3,6.539401e-001,0.000000e+000,,,,,,,,,,,,,,32,1,4.000000e+000,7.820129e-004,0.000000e+000,0,,0,
1524685606.518,,0.000000e+000,3.500028e+001,1.968333e-006,0.000000e+000,3,6.349701e-001,0.000000e+000,,,,,,,,,,,,,,32,1,4.000000e+000,3.120422e-003,0.000000e+000,0,,0,
1524685643.787,,0.000000e+000,3.499950e+001,2.008887e-006,0.000000e+000,3,6.464626e-001,0.000000e+000,,,,,,,,,,,,,,32,1,4.000000e+000,0.000000e+000,0.000000e+000,0,,0,
1524685656.487,,0.000000e+000,3.500028e+001,1.992847e-006,0.000000e+000,3,6.603397e-001,0.000000e+000,,,,,,,,,,,,,,32,1,4.000000e+000,1.560211e-003,0.000000e+000,0,,0,