File: Input/MFn1_TRMac_37K_0.32Kmin_VRMde_35K.dc.dat
[Header]
TITLE,MPMS DC Measurement
BYAPP,MPMS Measurement,2.1,Summary
FILEOPENTIME, 1524583698.413000 4/24/2018, 9:28:18 AM

INFO, APPNAME, MPMS MultiVu Application, Revision 1.61,  Build 082

INFO, NAME, MFn1
INFO, WEIGHT, 1.000
INFO, AREA, 1.000
INFO, LENGTH, 1.000
INFO, SHAPE, 0
INFO, COMMENT,
INFO, SEQUENCE FILE: TRMac_37K_0.32Kmin_VRMde_35K.seq


INFO, BACKGROUND DATA FILE:, None


STARTUPAXIS,X,4,LINEAR,AUTO,0.000000,0.000000
STARTUPAXIS,Y1,5,LINEAR,AUTO,0.000000,0.000000


STARTUPGROUP,Longitudinal
FIELDGROUP,Longitudinal,1,2,3,4,5,6,7,8,9,15,16,17,18,27,28
FIELDGROUP,Transverse,1,2,3,4,10,11,12,13,14,19,20,21,22,27,28

PLOT_APPEARANCE,ALL,HORZ_GRID_ON,VERT_GRID_ON,MARKERS_AND_LINES

[Data]
Time,Comment,Field (Oe),Temperature (K),Long Moment (emu),Long Scan Std Dev,Long Algorithm,Long Reg Fit,Long Percent Error (%),Trans Moment (emu),Trans Scan Std Dev,Trans Algorithm,Trans Reg Fit,Trans Percent Error (%),Long Moment [w/o ABS] (emu),Long Scan Std Dev [w/o ABS],Long Reg Fit [w/o ABS],Long Percent Error [w/o ABS] (%),Trans Moment [w/o ABS] (emu),Trans Scan Std Dev [w/o ABS],Trans Reg Fit [w/o ABS],Trans Percent Error [w/o ABS] (%),Points per Scan,Scans per Measurement,Scan Length (cm),Delta Temp (K),Rot Position (deg),Error,EC Comp. Running,Using ABS,
1524583698.410,,0.000000e+000,3.504767e+001,-5.952278e-006,0.000000e+000,3,8.864698e-001,0.000000e+000,,,,,,,,,,,,,,32,1,4.000000e+000,2.361298e-003,0.000000e+000,0,,0,
1524583736.293,,0.000000e+000,3.503944e+001,-3.671919e-006,0.000000e+000,3,8.005955e-001,0.000000e+000,,,,,,,,,,,,,,32,1,4.000000e+000,1.567841e-003,0.000000e+000,0,,0,
1524583773.541,,0.000000e+000,3.503551e+001,-2.130271e-006,0.000000e+000,3,6.637304e-001,0.000000e+000,,,,,,,,,,,,,,32,1,4.000000e+000,1.571655e-003,0.000000e+000,0,,0,
1524583811.317,,0.000000e+000,3.503120e+001,-1.438267e-006,0.000000e+000,3,4.660461e-001,0.000000e+000,,,,,,,,,,,,,,32,1,4.000000e+000,7.896423e-004,0.000000e+000,0,,0,
1524583849.187,,0.000000e+000,3.502376e+001,-7.393486e-007,0.000000e+000,3,0.000000e+000,0.000000e+000,,,,,,,,,,,,,,32,1,4.000000e+000,0.000000e+000,0.000000e+000,0,,0,
1524583891.362,,0.000000e+000,3.501437e+001,3.329050e-007,0.000000e+000,2,0.000000e+000,0.000000e+000,,,,,,,,,,,,,,32,1,4.000000e+000,0.000000e+000,0.000000e+000,0,,0,
1524584182.294,,0.000000e+000,3.500185e+001,2.942089e-006,0.000000e+000,3,7.552449e-001,0.000000e+000,,,,,,,,,,,,,,32,1,4.000000e+000,3.131866e-003,0.000000e+000,0,,0,
1524584220.354,,0.000000e+000,3.499989e+001,3.206578e-006,0.000000e+000,3,7.750461e-001,0.000000e+000,,,,,,,,,,,,,,32,1,4.000000e+000,2.342224e-003,0.000000e+000,0,,0,
1524584258.425,,0.000000e+000,3.499950e+001,3.281182e-006,0.000000e+000,3,7.943736e-001,0.000000e+000,,,,,,,,,,,,,,32,1,4.000000e+000,0.000000e+000,0.000000e+000,0,,0,
1524584296.463,,0.000000e+000,3.499833e+001,3.347701e-006,0.000000e+000,3,7.975690e-001,0.000000e+000,,,,,,,,,,,,,,32,1,4.000000e+000,7.781982e-004,0.000000e+000,0,,0,
1524584334.578,,0.000000e+000,3.499638e+001,3.638573e-006,0.000000e+000,3,8.155745e-001,0.000000e+000,,,,,,,,,,,,,,32,1,4.000000e+000,4.688263e-003,0.000000e+000,0,,0,
1524584372.652,,0.000000e+000,3.499715e+001,3.687330e-006,0.000000e+000,3,8.042415e-001,0.000000e+000,,,,,,,,,,,,,,32,1,4.000000e+000,3.128052e-003,0.000000e+000,0,,0,
1524584410.452,,0.000000e+000,3.499911e+001,3.691302e-006,0.000000e+000,3,8.015268e-001,0.000000e+000,,,,,,,,,,,,,,32,1,4.000000e+000,7.820129e-004,0.000000e+000,0,,0,
1524584449.565,,0.000000e+000,3.499794e+001,4.062141e-006,0.000000e+000,3,8.281242e-001,0.000000e+000,,,,,,,,,,,,,,32,1,4.000000e+000,0.000000e+000,0.000000e+000,0,,0,
1524584487.186,,0.000000e+000,3.499754e+001,4.037251e-006,0.000000e+000,3,8.321158e-001,0.000000e+000,,,,,,,,,,,,,,32,1,4.000000e+000,7.896423e-004,0.000000e+000,0,,0,
1524584525.211,,0.000000e+000,3.499833e+001,4.268058e-006,0.000000e+000,3,8.482075e-001,0.000000e+000,,,,,,,,,,,,,,32,1,4.000000e+000,2.349854e-003,0.000000e+000,0,,0,
1524584563.297,,0.000000e+000,3.499833e+001,4.187133e-006,0.000000e+000,3,8.345017e-001,0.000000e+000,,,,,,,,,,,,,,32,1,4.000000e+000,7.781982e-004,0.000000e+000,0,,0,
1524584601.390,,0.000000e+000,3.499793e+001,4.187176e-006,0.000000e+000,3,8.438541e-001,0.000000e+000,,,,,,,,,,,,,,32,1,4.000000e+000,1.567841e-003,0.000000e+000,0,,0,
1524584639.473,,0.000000e+000,3.499676e+001,4.428067e-006,0.000000e+000,3,8.439506e-001,0.000000e+000,,,,,,,,,,,,,,32,1,4.000000e+000,7.820129e-004,0.000000e+000,0,,0,
1524584677.449,,0.000000e+000,3.499950e+001,4.459901e-006,0.000000e+000,3,8.543909e-001,0.000000e+000,,,,,,,,,,,,,,32,1,4.000000e+000,1.560211e-003,0.000000e+000,0,,0,
1524584715.774,,0.000000e+000,3.499754e+001,4.582738e-006,0.000000e+000,3,8.516158e-001,0.000000e+000,,,,,,,,,,,,,,32,1,4.000000e+000,7.896423e-004,0.000000e+000,0,,0,
1524584753.637,,0.000000e+000,3.499754e+001,4.681800e-006,0.000000e+000,3,8.540860e-001,0.000000e+000,,,,,,,,,,,,,,32,1,4.000000e+000,7.896423e-004,0.000000e+000,0,,0,
1524584791.190,,0.000000e+000,3.499872e+001,4.639076e-006,0.000000e+000,3,8.541668e-001,0.000000e+000,,,,,,,,,,,,,,32,1,4.000000e+000,1.560211e-003,0.000000e+000,0,,0,
1524584829.286,,0.000000e+000,3.499950e+001,4.767438e-006,0.000000e+000,3,8.585515e-001,0.000000e+000,,,,,,,,,,,,,,32,1,4.000000e+000,0.000000e+000,0.000000e+000,0,,0,
1524584868.241,,0.000000e+000,3.499872e+001,4.819769e-006,0.000000e+000,3,8.513426e-001,0.000000e+000,,,,,,,,,,,,,,32,1,4.000000e+000,0.000000e+000,0.000000e+000,0,,0,
1524584907.099,,0.000000e+000,3.499872e+001,4.820017e-006,0.000000e+000,3,8.561645e-001,0.000000e+000,,,,,,,,,,,,,,32,1,4.000000e+000,1.560211e-003,0.000000e+000,0,,0,
1524584945.127,,0.000000e+000,3.499754e+001,4.915982e-006,0.000000e+000,3,8.532358e-001,0.000000e+000,,,,,,,,,,,,,,32,1,4.000000e+000,7.896423e-004,0.000000e+000,0,,0,
1524584983.305,,0.000000e+000,3.499794e+001,4.968205e-006,0.000000e+000,3,8.627750e-001,0.000000e+000,,,,,,,,,,,,,,32,1,4.000000e+000,0.000000e+000,0.000000e+000,0,,0,
1524585021.399,,0.000000e+000,3.499833e+001,5.129060e-006,0.000000e+000,3,8.672141e-001,0.000000e+000,,,,,,,,,,,,,,32,1,4.000000e+000,2.349854e-003,0.000000e+000,0,,0,
1524585059.487,,0.000000e+000,3.499793e+001,5.159467e-006,0.000000e+000,3,8.670799e-001,0.000000e+000,,,,,,,,,,,,,,32,1,4.000000e+000,1.567841e-003,0.000000e+000,0,,0,
1524585097.585,,0.000000e+000,3.499911e+001,5.164465e-006,0.000000e+000,3,8.623557e-001,0.000000e+000,,,,,,,,,,,,,,32,1,4.000000e+000,2.338409e-003,0.000000e+000,0,,0,
1524585135.683,,0.000000e+000,3.499911e+001,5.132827e-006,0.000000e+000,3,8.637217e-001,0.000000e+000,,,,,,,,,,,,,,32,1,4.000000e+000,3.910065e-003,0.000000e+000,0,,0,
1524585173.783,,0.000000e+000,3.499872e+001,5.210925e-006,0.000000e+000,3,8.603418e-001,0.000000e+000,,,,,,,,,,,,,,32,1,4.000000e+000,0.000000e+000,0.000000e+000,0,,0,
1524585211.896,,0.000000e+000,3.499911e+001,5.254963e-006,0.000000e+000,3,8.680222e-001,0.000000e+000,,,,,,,,,,,,,,32,1,4.000000e+000,2.338409e-003,0.000000e+000,0,,0,
1524585249.914,,0.000000e+000,3.499872e+001,5.396964e-006,0.000000e+000,3,8.724257e-001,0.000000e+000,,,,,,,,,,,,,,32,1,4.000000e+000,0.000000e+000,0.000000e+000,0,,0,
1524585288.257,,0.000000e+000,3.499794e+001,5.474890e-006,0.000000e+000,3,8.760707e-001,0.000000e+000,,,,,,,,,,,,,,32,1,4.000000e+000,0.000000e+000,0.000000e+000,0,,0,
1524585325.713,,0.000000e+000,3.499793e+001,5.403381e-006,0.000000e+000,3,8.736988e-001,0.000000e+000,,,,,,,,,,,,,,32,1,4.000000e+000,1.567841e-003,0.000000e+000,0,,0,
1524585363.804,,0.000000e+000,3.499911e+001,5.350425e-006,0.000000e+000,3,8.602636e-001,0.000000e+000,,,,,,,,,,,,,,32,1,4.000000e+000,7.820129e-004,0.000000e+000,0,,0,
1524585401.904,,0.000000e+000,3.499793e+001,5.432524e-006,0.000000e+000,3,8.789203e-001,0.000000e+000,,,,,,,,,,,,,,32,1,4.000000e+000,1.567841e-003,0.000000e+000,0,,0,
1524585440.017,,0.000000e+000,3.499833e+001,5.420819e-006,0.000000e+000,3,8.724073e-001,0.000000e+000,,,,,,,,,,,,,,32,1,4.000000e+000,7.781982e-004,0.000000e+000,0,,0,
1524585477.333,,0.000000e+000,3.499793e+001,5.499737e-006,0.000000e+000,3,8.719030e-001,0.000000e+000,,,,,,,,,,,,,,32,1,4.000000e+000,3.131866e-003,0.000000e+000,0,,0,
1524585514.796,,0.000000e+000,3.499715e+001,5.508980e-006,0.000000e+000,3,8.745657e-001,0.000000e+000,,,,,,,,,,,,,,32,1,4.000000e+000,1.571655e-003,0.000000e+000,0,,0,
1524585552.226,,0.000000e+000,3.499794e+001,5.548451e-006,0.000000e+000,3,8.722999e-001,0.000000e+000,,,,,,,,,,,,,,32,1,4.000000e+000,0.000000e+000,0.000000e+000,0,,0,
1524585590.319,,0.000000e+000,3.499911e+001,5.569203e-006,0.000000e+000,3,8.772947e-001,0.000000e+000,,,,,,,,,,,,,,32,1,4.000000e+000,7.820129e-004,0.000000e+000,0,,0,
1524585628.432,,0.000000e+000,3.499793e+001,5.615384e-006,0.000000e+000,3,8.769850e-001,0.000000e+000,,,,,,,,,,,,,,32,1,4.000000e+000,1.567841e-003,0.000000e+000,0,,0,
1524585666.528,,0.000000e+000,3.499833e+001,5.542301e-006,0.000000e+000,3,8.760651e-001,0.000000e+000,,,,,,,,,,,,,,32,1,4.000000e+000,7.781982e-004,0.000000e+000,0,,0,
1524585704.544,,0.000000e+000,3.499950e+001,5.647450e-006,0.000000e+000,3,8.796695e-001,0.000000e+000,,,,,,,,,,,,,,32,1,4.000000e+000,4.688263e-003,0.000000e+000,0,,0,
1524585742.732,,0.000000e+000,3.499989e+001,5.671453e-006,0.000000e+000,3,8.790393e-001,0.000000e+000,,,,,,,,,,,,,,32,1,4.000000e+000,7.781982e-004,0.000000e+000,0,,0,
1524585781.117,,0.000000e+000,3.499833e+001,5.714332e-006,0.000000e+000,3,8.745728e-001,0.000000e+000,,,,,,,,,,,,,,32,1,4.000000e+000,7.781982e-004,0.000000e+000,0,,0,
1524585819.245,,0.000000e+000,3.499950e+001,5.689687e-006,0.000000e+000,3,8.830850e-001,0.000000e+000,,,,,,,,,,,,,,32,1,4.000000e+000,1.560211e-003,0.000000e+000,0,,0,
1524585858.503,,0.000000e+000,3.499715e+001,5.861432e-006,0.000000e+000,3,8.810457e-001,0.000000e+000,,,,,,,,,,,,,,32,1,4.000000e+000,1.571655e-003,0.000000e+000,0,,0,
1524585896.716,,0.000000e+000,3.499989e+001,5.728052e-006,0.000000e+000,3,8.803190e-001,0.000000e+000,,,,,,,,,,,,,,32,1,4.000000e+000,2.342224e-003,0.000000e+000,0,,0,
1524585934.852,,0.000000e+000,3.499911e+001,5.795509e-006,0.000000e+000,3,8.815073e-001,0.000000e+000,,,,,,,,,,,,,,32,1,4.000000e+000,7.820129e-004,0.000000e+000,0,,0,
1524585973.210,,0.000000e+000,3.499793e+001,5.844400e-006,0.000000e+000,3,8.771843e-001,0.000000e+000,,,,,,,,,,,,,,32,1,4.000000e+000,1.567841e-003,0.000000e+000,0,,0,
1524586011.321,,0.000000e+000,3.499872e+001,5.889323e-006,0.000000e+000,3,8.817418e-001,0.000000e+000,,,,,,,,,,,,,,32,1,4.000000e+000,0.000000e+000,0.000000e+000,0,,0,
1524586049.651,,0.000000e+000,3.499833e+001,5.861796e-006,0.000000e+000,3,8.819413e-001,0.000000e+000,,,,,,,,,,,,,,32,1,4.000000e+000,2.349854e-003,0.000000e+000,0,,0,
1524586087.782,,0.000000e+000,3.499950e+001,5.868545e-006,0.000000e+000,3,8.794329e-001,0.000000e+000,,,,,,,,,,,,,,32,1,4.000000e+000,3.120422e-003,0.000000e+000,0,,0,
1524586125.637,,0.000000e+000,3.499911e+001,5.895349e-006,0.000000e+000,3,8.799734e-001,0.000000e+000,,,,,,,,,,,,,,32,1,4.000000e+000,7.820129e-004,0.000000e+000,0,,0,
1524586163.798,,0.000000e+000,3.499754e+001,5.906380e-006,0.000000e+000,3,8.806755e-001,0.000000e+000,,,,,,,,,,,,,,32,1,4.000000e+000,2.349854e-003,0.000000e+000,0,,0,
1524586201.856,,0.000000e+000,3.499911e+001,5.927396e-006,0.000000e+000,3,8.815976e-001,0.000000e+000,,,,,,,,,,,,,,32,1,4.000000e+000,7.820129e-004,0.000000e+000,0,,0,
1524586239.956,,0.000000e+000,3.499872e+001,5.993854e-006,0.000000e+000,3,8.828936e-001,0.000000e+000,,,,,,,,,,,,,,32,1,4.000000e+000,1.560211e-003,0.000000e+000,0,,0,
1524586278.072,,0.000000e+000,3.499872e+001,5.959167e-006,0.000000e+000,3,8.737667e-001,0.000000e+000,,,,,,,,,,,,,,32,1,4.000000e+000,1.560211e-003,0.000000e+000,0,,0,
1524586316.190,,0.000000e+000,3.499872e+001,5.981765e-006,0.000000e+000,3,8.856918e-001,0.000000e+000,,,,,,,,,,,,,,32,1,4.000000e+000,1.560211e-003,0.000000e+000,0,,0,
1524586354.286,,0.000000e+000,3.499872e+001,5.997586e-006,0.000000e+000,3,8.856990e-001,0.000000e+000,,,,,,,,,,,,,,32,1,4.000000e+000,1.560211e-003,0.000000e+000,0,,0,
1524586392.421,,0.000000e+000,3.499794e+001,6.006171e-006,0.000000e+000,3,8.820022e-001,0.000000e+000,,,,,,,,,,,,,,32,1,4.000000e+000,0.000000e+000,0.000000e+000,0,,0,
1524586429.977,,0.000000e+000,3.499950e+001,6.079067e-006,0.000000e+000,3,8.868344e-001,0.000000e+000,,,,,,,,,,,,,,32,1,4.000000e+000,0.000000e+000,0.000000e+000,0,,0,
1524586468.097,,0.000000e+000,3.499872e+001,6.087595e-006,0.000000e+000,3,8.844228e-001,0.000000e+000,,,,,,,,,,,,,,32,1,4.000000e+000,1.560211e-003,0.000000e+000,0,,0,
1524586505.808,,0.000000e+000,3.500146e+001,6.067696e-006,0.000000e+000,3,8.893057e-001,0.000000e+000,,,,,,,,,,,,,,32,1,4.000000e+000,7.038116e-003,0.000000e+000,0,,0,
1524586544.308,,0.000000e+000,3.499872e+001,6.109969e-006,0.000000e+000,3,8.841335e-001,0.000000e+000,,,,,,,,,,,,,,32,1,4.000000e+000,0.000000e+000,0.000000e+000,0,,0,
1524586581.736,,0.000000e+000,3.499793e+001,6.099947e-006,0.000000e+000,3,8.845001e-001,0.000000e+000,,,,,,,,,,,,,,32,1,4.000000e+000,3.131866e-003,0.000000e+000,0,,0,
1524586619.444,,0.000000e+000,3.499911e+001,6.210998e-006,0.000000e+000,3,8.841381e-001,0.000000e+000,,,,,,,,,,,,,,32,1,4.000000e+000,2.338409e-003,0.000000e+000,0,,0,
1524586658.343,,0.000000e+000,3.499911e+001,6.129238e-006,0.000000e+000,3,8.830044e-001,0.000000e+000,,,,,,,,,,,,,,32,1,4.000000e+000,7.820129e-004,0.000000e+000,0,,0,
1524586696.153,,0.000000e+000,3.499872e+001,6.163501e-006,0.000000e+000,3,8.848891e-001,0.000000e+000,,,,,,,,,,,,,,32,1,4.000000e+000,1.560211e-003,0.000000e+000,0,,0,
1524586734.254,,0.000000e+000,3.499833e+001,6.171892e-006,0.000000e+000,3,8.853051e-001,0.000000e+000,,,,,,,,,,,,,,32,1,4.000000e+000,7.781982e-004,0.000000e+000,0,,0,
1524586772.047,,0.000000e+000,3.499950e+001,6.137505e-006,0.000000e+000,3,8.860408e-001,0.000000e+000,,,,,,,,,,,,,,32,1,4.000000e+000,0.000000e+000,0.000000e+000,0,,0,
1524586809.670,,0.000000e+000,3.499833e+001,6.180427e-006,0.000000e+000,3,8.894158e-001,0.000000e+000,,,,,,,,,,,,,,32,1,4.000000e+000,7.781982e-004,0.000000e+000,0,,0,
1524586846.988,,0.000000e+000,3.499754e+001,6.173779e-006,0.000000e+000,3,8.848839e-001,0.000000e+000,,,,,,,,,,,,,,32,1,4.000000e+000,2.349854e-003,0.000000e+000,0,,0,
1524586885.091,,0.000000e+000,3.499950e+001,6.190235e-006,0.000000e+000,3,8.858342e-001,0.000000e+000,,,,,,,,,,,,,,32,1,4.000000e+000,1.560211e-003,0.000000e+000,0,,0,
1524586923.166,,0.000000e+000,3.499950e+001,6.178734e-006,0.000000e+000,3,8.872985e-001,0.000000e+000,,,,,,,,,,,,,,32,1,4.000000e+000,0.000000e+000,0.000000e+000,0,,0,
1524586961.274,,0.000000e+000,3.499637e+001,6.181810e-006,0.000000e+000,3,8.919287e-001,0.000000e+000,,,,,,,,,,,,,,32,1,4.000000e+000,1.560211e-003,0.000000e+000,0,,0,
1524586999.500,,0.000000e+000,3.500106e+001,6.293213e-006,0.000000e+000,3,8.891311e-001,0.000000e+000,,,,,,,,,,,,,,32,1,4.000000e+000,1.560211e-003,0.000000e+000,0,,0,
1524587037.513,,0.000000e+000,3.499989e+001,6.239306e-006,0.000000e+000,3,8.878111e-001,0.000000e+000,,,,,,,,,,,,,,32,1,4.000000e+000,2.342224e-003,0.000000e+000,0,,0,
1524587074.849,,0.000000e+000,3.499637e+001,6.265829e-006,0.000000e+000,3,8.880174e-001,0.000000e+000,,,,,,,,,,,,,,32,1,4.000000e+000,0.000000e+000,0.000000e+000,0,,0,
1524587112.959,,0.000000e+000,3.499754e+001,6.296805e-006,0.000000e+000,3,8.930483e-001,0.000000e+000,,,,,,,,,,,,,,32,1,4.000000e+000,3.910065e-003,0.000000e+000,0,,0,
1524587150.817,,0.000000e+000,3.499754e+001,6.274496e-006,0.000000e+000,3,8.884920e-001,0.000000e+000,,,,,,,,,,,,,,32,1,4.000000e+000,7.896423e-004,0.000000e+000,0,,0,
1524587188.443,,0.000000e+000,3.500067e+001,6.283932e-006,0.000000e+000,3,8.893471e-001,0.000000e+000,,,,,,,,,,,,,,32,1,4.000000e+000,7.820129e-004,0.000000e+000,0,,0,
1524587226.241,,0.000000e+000,3.499833e+001,6.289517e-006,0.000000e+000,3,8.916147e-001,0.000000e+000,,,,,,,,,,,,,,32,1,4.000000e+000,5.470276e-003,0.000000e+000,0,,0,
1524587264.416,,0.000000e+000,3.499676e+001,6.292029e-006,0.000000e+000,3,8.894094e-001,0.000000e+000,,,,,,,,,,,,,,32,1,4.000000e+000,7.820129e-004,0.000000e+000,0,,0,
1524587302.462,,0.000000e+000,3.499950e+001,6.332857e-006,0.000000e+000,3,8.849756e-001,0.000000e+000,,,,,,,,,,,,,,32,1,4.000000e+000,3.120422e-003,0.000000e+000,0,,0,
1524587340.420,,0.000000e+000,3.499871e+001,6.334128e-006,0.000000e+000,3,8.832727e-001,0.000000e+000,,,,,,,,,,,,,,32,1,4.000000e+000,4.692078e-003,0.000000e+000,0,,0,
1524587378.386,,0.000000e+000,3.499793e+001,6.311863e-006,0.000000e+000,3,8.802078e-001,0.000000e+000,,,,,,,,,,,,,,32,1,4.000000e+000,1.567841e-003,0.000000e+000,0,,0,
1524587416.504,,0.000000e+000,3.499989e+001,6.329856e-006,0.000000e+000,3,8.890418e-001,0.000000e+000,,,,,,,,,,,,,,32,1,4.000000e+000,7.781982e-004,0.000000e+000,0,,0,
1524587454.347,,0.000000e+000,3.499793e+001,6.356503e-006,0.000000e+000,3,8.852549e-001,0.000000e+000,,,,,,,,,,,,,,32,1,4.000000e+000,3.131866e-003,0.000000e+000,0,,0,
1524587492.202,,0.000000e+000,3.499989e+001,6.373672e-006,0.000000e+000,3,8.873146e-001,0.000000e+000,,,,,,,,,,,,,,32,1,4.000000e+000,7.781982e-004,0.000000e+000,0,,0,
1524587530.818,,0.000000e+000,3.499989e+001,6.365682e-006,0.000000e+000,3,8.871704e-001,0.000000e+000,,,,,,,,,,,,,,32,1,4.000000e+000,2.342224e-003,0.000000e+000,0,,0,
1524587568.911,,0.000000e+000,3.499911e+001,6.344179e-006,0.000000e+000,3,8.920708e-001,0.000000e+000,,,,,,,,,,,,,,32,1,4.000000e+000,7.820129e-004,0.000000e+000,0,,0,
1524587606.529,,0.000000e+000,3.499911e+001,6.366801e-006,0.000000e+000,3,8.882838e-001,0.000000e+000,,,,,,,,,,,,,,32,1,4.000000e+000,7.820129e-004,0.000000e+000,0,,0,
1524587644.742,,0.000000e+000,3.499950e+001,6.378511e-006,0.000000e+000,3,8.879235e-001,0.000000e+000,,,,,,,,,,,,,,32,1,4.000000e+000,0.000000e+000,0.000000e+000,0,,0,
1524587682.708,,0.000000e+000,3.499793e+001,6.395695e-006,0.000000e+000,3,8.897581e-001,0.000000e+000,,,,,,,,,,,,,,32,1,4.000000e+000,1.567841e-003,0.000000e+000,0,,0,
1524587721.641,,0.000000e+000,3.499911e+001,6.403989e-006,0.000000e+000,3,8.890015e-001,0.000000e+000,,,,,,,,,,,,,,32,1,4.000000e+000,7.820129e-004,0.000000e+000,0,,0,
1524587759.669,,0.000000e+000,3.499911e+001,6.370973e-006,0.000000e+000,3,8.856809e-001,0.000000e+000,,,,,,,,,,,,,,32,1,4.000000e+000,7.820129e-004,0.000000e+000,0,,0,
1524587797.784,,0.000000e+000,3.499833e+001,6.392112e-006,0.000000e+000,3,8.916904e-001,0.000000e+000,,,,,,,,,,,,,,32,1,4.000000e+000,7.781982e-004,0.000000e+000,0,,0,
1524587835.915,,0.000000e+000,3.499911e+001,6.433043e-006,0.000000e+000,3,8.938115e-001,0.000000e+000,,,,,,,,,,,,,,32,1,4.000000e+000,2.338409e-003,0.000000e+000,0,,0,
1524587874.665,,0.000000e+000,3.499715e+001,6.437599e-006,0.000000e+000,3,8.894171e-001,0.000000e+000,,,,,,,,,,,,,,32,1,4.000000e+000,3.128052e-003,0.000000e+000,0,,0,
1524587913.016,,0.000000e+000,3.500067e+001,6.473845e-006,0.000000e+000,3,8.907232e-001,0.000000e+000,,,,,,,,,,,,,,32,1,4.000000e+000,7.820129e-004,0.000000e+000,0,,0,
1524587951.917,,0.000000e+000,3.499793e+001,6.419105e-006,0.000000e+000,3,8.933592e-001,0.000000e+000,,,,,,,,,,,,,,32,1,4.000000e+000,3.131866e-003,0.000000e+000,0,,0,
1524587990.315,,0.000000e+000,3.499911e+001,6.469229e-006,0.000000e+000,3,8.934681e-001,0.000000e+000,,,,,,,,,,,,,,32,1,4.000000e+000,7.820129e-004,0.000000e+000,0,,0,
1524588028.935,,0.000000e+000,3.500067e+001,6.484570e-006,0.000000e+000,3,8.885356e-001,0.000000e+000,,,,,,,,,,,,,,32,1,4.000000e+000,3.910065e-003,0.000000e+000,0,,0,
1524588066.713,,0.000000e+000,3.499872e+001,6.489280e-006,0.000000e+000,3,8.951681e-001,0.000000e+000,,,,,,,,,,,,,,32,1,4.000000e+000,0.000000e+000,0.000000e+000,0,,0,
1524588104.969,,0.000000e+000,3.499911e+001,6.393268e-006,0.000000e+000,3,8.958806e-001,0.000000e+000,,,,,,,,,,,,,,32,1,4.000000e+000,7.820129e-004,0.000000e+000,0,,0,
1524588142.747,,0.000000e+000,3.499754e+001,6.491759e-006,0.000000e+000,3,8.922927e-001,0.000000e+000,,,,,,,,,,,,,,32,1,4.000000e+000,7.896423e-004,0.000000e+000,0,,0,
1524588180.332,,0.000000e+000,3.499872e+001,6.494654e-006,0.000000e+000,3,8.934818e-001,0.000000e+000,,,,,,,,,,,,,,32,1,4.000000e+000,0.000000e+000,0.000000e+000,0,,0,
1524588218.448,,0.000000e+000,3.499833e+001,6.540838e-006,0.000000e+000,3,8.906629e-001,0.000000e+000,,,,,,,,,,,,,,32,1,4.000000e+000,7.781982e-004,0.000000e+000,0,,0,
1524588256.233,,0.000000e+000,3.499911e+001,6.524278e-006,0.000000e+000,3,8.972970e-001,0.000000e+000,,,,,,,,,,,,,,32,1,4.000000e+000,7.820129e-004,0.000000e+000,0,,0,
1524588293.872,,0.000000e+000,3.499833e+001,6.484760e-006,0.000000e+000,3,8.948361e-001,0.000000e+000,,,,,,,,,,,,,,32,1,4.000000e+000,7.781982e-004,0.000000e+000,0,,0,
1524588331.182,,0.000000e+000,3.499950e+001,6.517797e-006,0.000000e+000,3,8.907264e-001,0.000000e+000,,,,,,,,,,,,,,32,1,4.000000e+000,1.560211e-003,0.000000e+000,0,,0,
1524588369.285,,0.000000e+000,3.500028e+001,6.497002e-006,0.000000e+000,3,8.917127e-001,0.000000e+000,,,,,,,,,,,,,,32,1,4.000000e+000,1.560211e-003,0.000000e+000,0,,0,
1524588407.463,,0.000000e+000,3.500106e+001,6.490872e-006,0.000000e+000,3,8.895736e-001,0.000000e+000,,,,,,,,,,,,,,32,1,4.000000e+000,1.560211e-003,0.000000e+000,0,,0,
1524588445.499,,0.000000e+000,3.499833e+001,6.484441e-006,0.000000e+000,3,8.906469e-001,0.000000e+000,,,,,,,,,,,,,,32,1,4.000000e+000,2.349854e-003,0.000000e+000,0,,0,
1524588483.744,,0.000000e+000,3.499871e+001,6.609238e-006,0.000000e+000,3,8.954995e-001,0.000000e+000,,,,,,,,,,,,,,32,1,4.000000e+000,3.128052e-003,0.000000e+000,0,,0,
1524588521.730,,0.000000e+000,3.499872e+001,6.524610e-006,0.000000e+000,3,8.943630e-001,0.000000e+000,,,,,,,,,,,,,,32,1,4.000000e+000,1.560211e-003,0.000000e+000,0,,0,
1524588559.405,,0.000000e+000,3.499794e+001,6.545588e-006,0.000000e+000,3,8.951601e-001,0.000000e+000,,,,,,,,,,,,,,32,1,4.000000e+000,0.000000e+000,0.000000e+000,0,,0,
1524588597.366,,0.000000e+000,3.499754e+001,6.545604e-006,0.000000e+000,3,8.947296e-001,0.000000e+000,,,,,,,,,,,,,,32,1,4.000000e+000,7.896423e-004,0.000000e+000,0,,0,
1524588635.419,,0.000000e+000,3.499754e+001,6.574697e-006,0.000000e+000,3,8.920676e-001,0.000000e+000,,,,,,,,,,,,,,32,1,4.000000e+000,7.896423e-004,0.000000e+000,0,,0,
1524588673.680,,0.000000e+000,3.499911e+001,6.584615e-006,0.000000e+000,3,8.932479e-001,0.000000e+000,,,,,,,,,,,,,,32,1,4.000000e+000,7.820129e-004,0.000000e+000,0,,0,
1524588710.903,,0.000000e+000,3.500380e+001,6.578749e-006,0.000000e+000,3,8.946611e-001,0.000000e+000,,,,,,,,,,,,,,32,1,4.000000e+000,8.598328e-003,0.000000e+000,0,,0,
1524588749.271,,0.000000e+000,3.499911e+001,6.607060e-006,0.000000e+000,3,8.943086e-001,0.000000e+000,,,,,,,,,,,,,,32,1,4.000000e+000,7.820129e-004,0.000000e+000,0,,0,
1524588786.649,,0.000000e+000,3.499950e+001,6.520087e-006,0.000000e+000,3,8.955272e-001,0.000000e+000,,,,,,,,,,,,,,32,1,4.000000e+000,0.000000e+000,0.000000e+000,0,,0,
1524588824.754,,0.000000e+000,3.499989e+001,6.565128e-006,0.000000e+000,3,8.938934e-001,0.000000e+000,,,,,,,,,,,,,,32,1,4.000000e+000,7.781982e-004,0.000000e+000,0,,0,
1524588862.070,,0.000000e+000,3.499833e+001,6.572386e-006,0.000000e+000,3,8.926985e-001,0.000000e+000,,,,,,,,,,,,,,32,1,4.000000e+000,7.781982e-004,0.000000e+000,0,,0,
1524588899.793,,0.000000e+000,3.500106e+001,6.596919e-006,0.000000e+000,3,8.937546e-001,0.000000e+000,,,,,,,,,,,,,,32,1,4.000000e+000,3.128052e-003,0.000000e+000,0,,0,
1524588937.768,,0.000000e+000,3.499950e+001,6.567099e-006,0.000000e+000,3,8.922365e-001,0.000000e+000,,,,,,,,,,,,,,32,1,4.000000e+000,3.120422e-003,0.000000e+000,0,,0,
1524588975.292,,0.000000e+000,3.499950e+001,6.573461e-006,0.000000e+000,3,8.933653e-001,0.000000e+000,,,,,,,,,,,,,,32,1,4.000000e+000,0.000000e+000,0.000000e+000,0,,0,
1524589013.412,,0.000000e+000,3.499833e+001,6.580419e-006,0.000000e+000,3,8.891715e-001,0.000000e+000,,,,,,,,,,,,,,32,1,4.000000e+000,2.349854e-003,0.000000e+000,0,,0,
1524589051.000,,0.000000e+000,3.499872e+001,6.603334e-006,0.000000e+000,3,8.947942e-001,0.000000e+000,,,,,,,,,,,,,,32,1,4.000000e+000,1.560211e-003,0.000000e+000,0,,0,
1524589089.071,,0.000000e+000,3.499833e+001,6.589054e-006,0.000000e+000,3,8.914047e-001,0.000000e+000,,,,,,,,,,,,,,32,1,4.000000e+000,2.349854e-003,0.000000e+000,0,,0,
1524589127.174,,0.000000e+000,3.499793e+001,6.586596e-006,0.000000e+000,3,8.925146e-001,0.000000e+000,,,,,,,,,,,,,,32,1,4.000000e+000,3.131866e-003,0.000000e+000,0,,0,
1524589165.857,,0.000000e+000,3.499871e+001,6.616931e-006,0.000000e+000,3,8.943188e-001,0.000000e+000,,,,,,,,,,,,,,32,1,4.000000e+000,3.128052e-003,0.000000e+000,0,,0,
1524589203.355,,0.000000e+000,3.499911e+001,6.611185e-006,0.000000e+000,3,8.975623e-001,0.000000e+000,,,,,,,,,,,,,,32,1,4.000000e+000,7.820129e-004,0.000000e+000,0,,0,
1524589240.958,,0.000000e+000,3.499989e+001,6.633753e-006,0.000000e+000,3,8.952996e-001,0.000000e+000,,,,,,,,,,,,,,32,1,4.000000e+000,7.781982e-004,0.000000e+000,0,,0,
1524589279.011,,0.000000e+000,3.499715e+001,6.727603e-006,0.000000e+000,3,8.982458e-001,0.000000e+000,,,,,,,,,,,,,,32,1,4.000000e+000,1.571655e-003,0.000000e+000,0,,0,
1524589317.107,,0.000000e+000,3.499911e+001,6.570980e-006,0.000000e+000,3,8.860150e-001,0.000000e+000,,,,,,,,,,,,,,32,1,4.000000e+000,7.820129e-004,0.000000e+000,0,,0,
1524589355.195,,0.000000e+000,3.499872e+001,6.607766e-006,0.000000e+000,3,8.878129e-001,0.000000e+000,,,,,,,,,,,,,,32,1,4.000000e+000,1.560211e-003,0.000000e+000,0,,0,
1524589393.905,,0.000000e+000,3.499950e+001,6.633202e-006,0.000000e+000,3,8.957838e-001,0.000000e+000,,,,,,,,,,,,,,32,1,4.000000e+000,0.000000e+000,0.000000e+000,0,,0,
1524589432.548,,0.000000e+000,3.499833e+001,6.607720e-006,0.000000e+000,3,8.942133e-001,0.000000e+000,,,,,,,,,,,,,,32,1,4.000000e+000,7.781982e-004,0.000000e+000,0,,0,
1524589470.541,,0.000000e+000,3.499911e+001,6.647122e-006,0.000000e+000,3,8.947214e-001,0.000000e+000,,,,,,,,,,,,,,32,1,4.000000e+000,7.820129e-004,0.000000e+000,0,,0,
1524589509.132,,0.000000e+000,3.500067e+001,6.632242e-006,0.000000e+000,3,8.920543e-001,0.000000e+000,,,,,,,,,,,,,,32,1,4.000000e+000,2.338409e-003,0.000000e+000,0,,0,
1524589548.037,,0.000000e+000,3.499794e+001,6.607486e-006,0.000000e+000,3,8.947504e-001,0.000000e+000,,,,,,,,,,,,,,32,1,4.000000e+000,0.000000e+000,0.000000e+000,0,,0,
1524589586.146,,0.000000e+000,3.499833e+001,6.642309e-006,0.000000e+000,3,8.922914e-001,0.000000e+000,,,,,,,,,,,,,,32,1,4.000000e+000,7.781982e-004,0.000000e+000,0,,0,
1524589624.636,,0.000000e+000,3.500067e+001,6.620355e-006,0.000000e+000,3,8.957794e-001,0.000000e+000,,,,,,,,,,,,,,32,1,4.000000e+000,7.820129e-004,0.000000e+000,0,,0,
1524589661.794,,0.000000e+000,3.499911e+001,6.647418e-006,0.000000e+000,3,8.962045e-001,0.000000e+000,,,,,,,,,,,,,,32,1,4.000000e+000,7.820129e-004,0.000000e+000,0,,0,
1524589699.890,,0.000000e+000,3.500028e+001,6.645969e-006,0.000000e+000,3,8.947282e-001,0.000000e+000,,,,,,,,,,,,,,32,1,4.000000e+000,0.000000e+000,0.000000e+000,0,,0,
1524589738.455,,0.000000e+000,3.499911e+001,6.648395e-006,0.000000e+000,3,8.920192e-001,0.000000e+000,,,,,,,,,,,,,,32,1,4.000000e+000,7.820129e-004,0.000000e+000,0,,0,
1524589776.086,,0.000000e+000,3.499911e+001,6.612830e-006,0.000000e+000,3,8.963586e-001,0.000000e+000,,,,,,,,,,,,,,32,1,4.000000e+000,7.820129e-004,0.000000e+000,0,,0,
1524589814.134,,0.000000e+000,3.499989e+001,6.645039e-006,0.000000e+000,3,8.949733e-001,0.000000e+000,,,,,,,,,,,,,,32,1,4.000000e+000,7.781982e-004,0.000000e+000,0,,0,
1524589852.232,,0.000000e+000,3.499911e+001,6.649969e-006,0.000000e+000,3,8.955942e-001,0.000000e+000,,,,,,,,,,,,,,32,1,4.000000e+000,7.820129e-004,0.000000e+000,0,,0,
1524589890.317,,0.000000e+000,3.499911e+001,6.639945e-006,0.000000e+000,3,8.962955e-001,0.000000e+000,,,,,,,,,,,,,,32,1,4.000000e+000,2.338409e-003,0.000000e+000,0,,0,
1524589928.418,,0.000000e+000,3.500028e+001,6.664851e-006,0.000000e+000,3,8.936011e-001,0.000000e+000,,,,,,,,,,,,,,32,1,4.000000e+000,1.560211e-003,0.000000e+000,0,,0,
1524589966.431,,0.000000e+000,3.499989e+001,6.638291e-006,0.000000e+000,3,8.951194e-001,0.000000e+000,,,,,,,,,,,,,,32,1,4.000000e+000,7.781982e-004,0.000000e+000,0,,0,
1524590004.609,,0.000000e+000,3.499950e+001,6.660620e-006,0.000000e+000,3,8.949853e-001,0.000000e+000,,,,,,,,,,,,,,32,1,4.000000e+000,0.000000e+000,0.000000e+000,0,,0,
1524590043.040,,0.000000e+000,3.500028e+001,6.680878e-006,0.000000e+000,3,8.922254e-001,0.000000e+000,,,,,,,,,,,,,,32,1,4.000000e+000,1.560211e-003,0.000000e+000,0,,0,
1524590081.090,,0.000000e+000,3.499950e+001,6.753225e-006,0.000000e+000,3,8.925740e-001,0.000000e+000,,,,,,,,,,,,,,32,1,4.000000e+000,0.000000e+000,0.000000e+000,0,,0,
1524590118.861,,0.000000e+000,3.500028e+001,6.713719e-006,0.000000e+000,3,8.946310e-001,0.000000e+000,,,,,,,,,,,,,,32,1,4.000000e+000,0.000000e+000,0.000000e+000,0,,0,
1524590156.936,,0.000000e+000,3.499754e+001,6.690569e-006,0.000000e+000,3,8.949910e-001,0.000000e+000,,,,,,,,,,,,,,32,1,4.000000e+000,7.896423e-004,0.000000e+000,0,,0,
1524590195.424,,0.000000e+000,3.499833e+001,6.705222e-006,0.000000e+000,3,8.926970e-001,0.000000e+000,,,,,,,,,,,,,,32,1,4.000000e+000,7.781982e-004,0.000000e+000,0,,0,
1524590233.355,,0.000000e+000,3.499871e+001,6.707323e-006,0.000000e+000,3,8.942924e-001,0.000000e+000,,,,,,,,,,,,,,32,1,4.000000e+000,3.128052e-003,0.000000e+000,0,,0,
1524590271.516,,0.000000e+000,3.499911e+001,6.716742e-006,0.000000e+000,3,8.907987e-001,0.000000e+000,,,,,,,,,,,,,,32,1,4.000000e+000,7.820129e-004,0.000000e+000,0,,0,
1524590309.634,,0.000000e+000,3.499950e+001,6.731155e-006,0.000000e+000,3,8.994022e-001,0.000000e+000,,,,,,,,,,,,,,32,1,4.000000e+000,0.000000e+000,0.000000e+000,0,,0,
1524590347.479,,0.000000e+000,3.499911e+001,6.667654e-006,0.000000e+000,3,8.898364e-001,0.000000e+000,,,,,,,,,,,,,,32,1,4.000000e+000,7.820129e-004,0.000000e+000,0,,0,
1524590385.080,,0.000000e+000,3.499911e+001,6.722283e-006,0.000000e+000,3,8.961794e-001,0.000000e+000,,,,,,,,,,,,,,32,1,4.000000e+000,7.820129e-004,0.000000e+000,0,,0,
1524590423.010,,0.000000e+000,3.499911e+001,6.649723e-006,0.000000e+000,3,8.937737e-001,0.000000e+000,,,,,,,,,,,,,,32,1,4.000000e+000,7.820129e-004,0.000000e+000,0,,0,
1524590460.733,,0.000000e+000,3.499989e+001,6.748907e-006,0.000000e+000,3,8.952121e-001,0.000000e+000,,,,,,,,,,,,,,32,1,4.000000e+000,7.781982e-004,0.000000e+000,0,,0,
1524590499.079,,0.000000e+000,3.499911e+001,6.777148e-006,0.000000e+000,3,8.925315e-001,0.000000e+000,,,,,,,,,,,,,,32,1,4.000000e+000,7.820129e-004,0.000000e+000,0,,0,
1524590536.532,,0.000000e+000,3.499950e+001,6.626845e-006,0.000000e+000,3,8.921339e-001,0.000000e+000,,,,,,,,,,,,,,32,1,4.000000e+000,0.000000e+000,0.000000e+000,0,,0,
1524590574.637,,0.000000e+000,3.499911e+001,6.723611e-006,0.000000e+000,3,8.944879e-001,0.000000e+000,,,,,,,,,,,,,,32,1,4.000000e+000,7.820129e-004,0.000000e+000,0,,0,
1524590612.726,,0.000000e+000,3.499638e+001,6.743129e-006,0.000000e+000,3,8.978608e-001,0.000000e+000,,,,,,,,,,,,,,32,1,4.000000e+000,4.688263e-003,0.000000e+000,0,,0,
1524590650.811,,0.000000e+000,3.499871e+001,6.759226e-006,0.000000e+000,3,8.968039e-001,0.000000e+000,,,,,,,,,,,,,,32,1,4.000000e+000,3.128052e-003,0.000000e+000,0,,0,
1524590687.972,,0.000000e+000,3.499676e+001,6.695650e-006,0.000000e+000,3,8.937984e-001,0.000000e+000,,,,,,,,,,,,,,32,1,4.000000e+000,7.820129e-004,0.000000e+000,0,,0,
1524590726.485,,0.000000e+000,3.499911e+001,6.782675e-006,0.000000e+000,3,8.966307e-001,0.000000e+000,,,,,,,,,,,,,,32,1,4.000000e+000,2.338409e-003,0.000000e+000,0,,0,
1524590764.525,,0.000000e+000,3.499872e+001,6.723161e-006,0.000000e+000,3,8.935053e-001,0.000000e+000,,,,,,,,,,,,,,32,1,4.000000e+000,1.560211e-003,0.000000e+000,0,,0,
1524590802.526,,0.000000e+000,3.499950e+001,6.714070e-006,0.000000e+000,3,8.957940e-001,0.000000e+000,,,,,,,,,,,,,,32,1,4.000000e+000,3.120422e-003,0.000000e+000,0,,0,
1524590840.799,,0.000000e+000,3.499793e+001,6.762739e-006,0.000000e+000,3,8.891166e-001,0.000000e+000,,,,,,,,,,,,,,32,1,4.000000e+000,1.567841e-003,0.000000e+000,0,,0,
1524590878.890,,0.000000e+000,3.499872e+001,6.694985e-006,0.000000e+000,3,8.933499e-001,0.000000e+000,,,,,,,,,,,,,,32,1,4.000000e+000,0.000000e+000,0.000000e+000,0,,0,
1524590916.520,,0.000000e+000,3.500067e+001,6.687311e-006,0.000000e+000,3,8.928474e-001,0.000000e+000,,,,,,,,,,,,,,32,1,4.000000e+000,2.338409e-003,0.000000e+000,0,,0,
1524590954.378,,0.000000e+000,3.499872e+001,6.729957e-006,0.000000e+000,3,8.854007e-001,0.000000e+000,,,,,,,,,,,,,,32,1,4.000000e+000,0.000000e+000,0.000000e+000,0,,0,
1524590992.676,,0.000000e+000,3.499989e+001,6.690756e-006,0.000000e+000,3,8.800852e-001,0.000000e+000,,,,,,,,,,,,,,32,1,4.000000e+000,2.342224e-003,0.000000e+000,0,,0,
1524591031.577,,0.000000e+000,3.499911e+001,6.827041e-006,0.000000e+000,3,8.846601e-001,0.000000e+000,,,,,,,,,,,,,,32,1,4.000000e+000,2.338409e-003,0.000000e+000,0,,0,
1524591069.150,,0.000000e+000,3.500067e+001,6.666154e-006,0.000000e+000,3,8.995106e-001,0.000000e+000,,,,,,,,,,,,,,32,1,4.000000e+000,7.820129e-004,0.000000e+000,0,,0,
1524591107.703,,0.000000e+000,3.499872e+001,6.773163e-006,0.000000e+000,3,8.973548e-001,0.000000e+000,,,,,,,,,,,,,,32,1,4.000000e+000,1.560211e-003,0.000000e+000,0,,0,
1524591145.783,,0.000000e+000,3.499872e+001,6.798998e-006,0.000000e+000,3,8.918118e-001,0.000000e+000,,,,,,,,,,,,,,32,1,4.000000e+000,0.000000e+000,0.000000e+000,0,,0,
1524591183.881,,0.000000e+000,3.499911e+001,6.677478e-006,0.000000e+000,3,8.935183e-001,0.000000e+000,,,,,,,,,,,,,,32,1,4.000000e+000,2.338409e-003,0.000000e+000,0,,0,
1524591222.004,,0.000000e+000,3.500224e+001,6.745789e-006,0.000000e+000,3,8.959119e-001,0.000000e+000,,,,,,,,,,,,,,32,1,4.000000e+000,2.349854e-003,0.000000e+000,0,,0,
1524591259.640,,0.000000e+000,3.499950e+001,6.719657e-006,0.000000e+000,3,8.920900e-001,0.000000e+000,,,,,,,,,,,,,,32,1,4.000000e+000,0.000000e+000,0.000000e+000,0,,0,
1524591298.153,,0.000000e+000,3.499872e+001,6.785877e-006,0.000000e+000,3,8.981582e-001,0.000000e+000,,,,,,,,,,,,,,32,1,4.000000e+000,0.000000e+000,0.000000e+000,0,,0,
1524591336.491,,0.000000e+000,3.499989e+001,6.747415e-006,0.000000e+000,3,9.035629e-001,0.000000e+000,,,,,,,,,,,,,,32,1,4.000000e+000,2.342224e-003,0.000000e+000,0,,0,
1524591374.552,,0.000000e+000,3.500106e+001,6.668158e-006,0.000000e+000,3,8.974466e-001,0.000000e+000,,,,,,,,,,,,,,32,1,4.000000e+000,4.692078e-003,0.000000e+000,0,,0,
1524591412.677,,0.000000e+000,3.500106e+001,6.754552e-006,0.000000e+000,3,8.925949e-001,0.000000e+000,,,,,,,,,,,,,,32,1,4.000000e+000,4.692078e-003,0.000000e+000,0,,0,
1524591450.940,,0.000000e+000,3.499520e+001,6.803431e-006,0.000000e+000,3,8.877640e-001,0.000000e+000,,,,,,,,,,,,,,32,1,4.000000e+000,7.038116e-003,0.000000e+000,0,,0,
1524591488.518,,0.000000e+000,3.499989e+001,6.736412e-006,0.000000e+000,3,8.941125e-001,0.000000e+000,,,,,,,,,,,,,,32,1,4.000000e+000,7.781982e-004,0.000000e+000,0,,0,
1524591526.309,,0.000000e+000,3.499793e+001,6.743364e-006,0.000000e+000,3,8.931558e-001,0.000000e+000,,,,,,,,,,,,,,32,1,4.000000e+000,3.131866e-003,0.000000e+000,0,,0,
1524591564.687,,0.000000e+000,3.499950e+001,6.793748e-006,0.000000e+000,3,8.977803e-001,0.000000e+000,,,,,,,,,,,,,,32,1,4.000000e+000,0.000000e+000,0.000000e+000,0,,0,
1524591602.838,,0.000000e+000,3.499950e+001,6.778290e-006,0.000000e+000,3,8.896233e-001,0.000000e+000,,,,,,,,,,,,,,32,1,4.000000e+000,1.560211e-003,0.000000e+000,0,,0,
1524591640.853,,0.000000e+000,3.499989e+001,6.723992e-006,0.000000e+000,3,8.973114e-001,0.000000e+000,,,,,,,,,,,,,,32,1,4.000000e+000,7.781982e-004,0.000000e+000,0,,0,
1524591678.941,,0.000000e+000,3.499833e+001,6.783489e-006,0.000000e+000,3,8.939208e-001,0.000000e+000,,,,,,,,,,,,,,32,1,4.000000e+000,7.781982e-004,0.000000e+000,0,,0,
1524591717.007,,0.000000e+000,3.499950e+001,6.784610e-006,0.000000e+000,3,8.905064e-001,0.000000e+000,,,,,,,,,,,,,,32,1,4.000000e+000,0.000000e+000,0.000000e+000,0,,0,
1524591755.380,,0.000000e+000,3.499950e+001,6.746933e-006,0.000000e+000,3,8.926257e-001,0.000000e+000,,,,,,,,,,,,,,32,1,4.000000e+000,0.000000e+000,0.000000e+000,0,,0,
1524591793.605,,0.000000e+000,3.499911e+001,6.809128e-006,0.000000e+000,3,8.979988e-001,0.000000e+000,,,,,,,,,,,,,,32,1,4.000000e+000,7.820129e-004,0.000000e+000,0,,0,
1524591831.578,,0.000000e+000,3.499872e+001,6.727129e-006,0.000000e+000,3,8.968341e-001,0.000000e+000,,,,,,,,,,,,,,32,1,4.000000e+000,0.000000e+000,0.000000e+000,0,,0,
1524591869.676,,0.000000e+000,3.499950e+001,6.776263e-006,0.000000e+000,3,8.953282e-001,0.000000e+000,,,,,,,,,,,,,,32,1,4.000000e+000,0.000000e+000,0.000000e+000,0,,0,
1524591908.157,,0.000000e+000,3.499950e+001,6.773203e-006,0.000000e+000,3,8.995700e-001,0.000000e+000,,,,,,,,,,,,,,32,1,4.000000e+000,4.688263e-003,0.000000e+000,0,,0,
1524591946.060,,0.000000e+000,3.499793e+001,6.790047e-006,0.000000e+000,3,8.954478e-001,0.000000e+000,,,,,,,,,,,,,,32,1,4.000000e+000,1.567841e-003,0.000000e+000,0,,0,
1524591985.008,,0.000000e+000,3.499910e+001,6.716099e-006,0.000000e+000,3,8.930067e-001,0.000000e+000,,,,,,,,,,,,,,32,1,4.000000e+000,5.470276e-003,0.000000e+000,0,,0,
1524592023.419,,0.000000e+000,3.499950e+001,6.764676e-006,0.000000e+000,3,8.904235e-001,0.000000e+000,,,,,,,,,,,,,,32,1,4.000000e+000,6.259918e-003,0.000000e+000,0,,0,
1524592061.512,,0.000000e+000,3.499911e+001,6.756709e-006,0.000000e+000,3,8.862577e-001,0.000000e+000,,,,,,,,,,,,,,32,1,4.000000e+000,7.820129e-004,0.000000e+000,0,,0,
1524592099.650,,0.000000e+000,3.499910e+001,6.827775e-006,0.000000e+000,3,8.980629e-001,0.000000e+000,,,,,,,,,,,,,,32,1,4.000000e+000,5.470276e-003,0.000000e+000,0,,0,
1524592138.078,,0.000000e+000,3.499989e+001,6.760973e-006,0.000000e+000,3,8.889452e-001,0.000000e+000,,,,,,,,,,,,,,32,1,4.000000e+000,7.781982e-004,0.000000e+000,0,,0,
1524592176.196,,0.000000e+000,3.499833e+001,6.801770e-006,0.000000e+000,3,8.913463e-001,0.000000e+000,,,,,,,,,,,,,,32,1,4.000000e+000,7.781982e-004,0.000000e+000,0,,0,
1524592214.799,,0.000000e+000,3.499872e+001,6.830119e-006,0.000000e+000,3,8.968831e-001,0.000000e+000,,,,,,,,,,,,,,32,1,4.000000e+000,0.000000e+000,0.000000e+000,0,,0,
1524592253.002,,0.000000e+000,3.499911e+001,6.920998e-006,0.000000e+000,3,9.012883e-001,0.000000e+000,,,,,,,,,,,,,,32,1,4.000000e+000,2.338409e-003,0.000000e+000,0,,0,
1524592291.925,,0.000000e+000,3.499676e+001,6.733703e-006,0.000000e+000,3,8.968577e-001,0.000000e+000,,,,,,,,,,,,,,32,1,4.000000e+000,7.820129e-004,0.000000e+000,0,,0,
1524592330.023,,0.000000e+000,3.499793e+001,6.828748e-006,0.000000e+000,3,8.949618e-001,0.000000e+000,,,,,,,,,,,,,,32,1,4.000000e+000,1.567841e-003,0.000000e+000,0,,0,
1524592368.101,,0.000000e+000,3.499911e+001,6.898560e-006,0.000000e+000,3,8.922207e-001,0.000000e+000,,,,,,,,,,,,,,32,1,4.000000e+000,7.820129e-004,0.000000e+000,0,,0,
1524592406.174,,0.000000e+000,3.499989e+001,6.771783e-006,0.000000e+000,3,8.951465e-001,0.000000e+000,,,,,,,,,,,,,,32,1,4.000000e+000,7.781982e-004,0.000000e+000,0,,0,
1524592444.592,,0.000000e+000,3.499911e+001,6.785347e-006,0.000000e+000,3,8.999912e-001,0.000000e+000,,,,,,,,,,,,,,32,1,4.000000e+000,7.820129e-004,0.000000e+000,0,,0,
1524592482.736,,0.000000e+000,3.499911e+001,6.837502e-006,0.000000e+000,3,8.991519e-001,0.000000e+000,,,,,,,,,,,,,,32,1,4.000000e+000,7.820129e-004,0.000000e+000,0,,0,
1524592520.691,,0.000000e+000,3.499989e+001,6.800272e-006,0.000000e+000,3,9.015516e-001,0.000000e+000,,,,,,,,,,,,,,32,1,4.000000e+000,7.781982e-004,0.000000e+000,0,,0,
1524592558.782,,0.000000e+000,3.499638e+001,6.842087e-006,0.000000e+000,3,8.995934e-001,0.000000e+000,,,,,,,,,,,,,,32,1,4.000000e+000,4.688263e-003,0.000000e+000,0,,0,
1524592596.687,,0.000000e+000,3.499676e+001,6.809574e-006,0.000000e+000,3,8.973665e-001,0.000000e+000,,,,,,,,,,,,,,32,1,4.000000e+000,7.038116e-003,0.000000e+000,0,,0,
1524592634.828,,0.000000e+000,3.499872e+001,6.799971e-006,0.000000e+000,3,8.924763e-001,0.000000e+000,,,,,,,,,,,,,,32,1,4.000000e+000,1.560211e-003,0.000000e+000,0,,0,
1524592672.678,,0.000000e+000,3.499911e+001,6.832225e-006,0.000000e+000,3,8.927544e-001,0.000000e+000,,,,,,,,,,,,,,32,1,4.000000e+000,2.338409e-003,0.000000e+000,0,,0,
1524592711.226,,0.000000e+000,3.499793e+001,6.835166e-006,0.000000e+000,3,9.024016e-001,0.000000e+000,,,,,,,,,,,,,,32,1,4.000000e+000,1.567841e-003,0.000000e+000,0,,0,
1524592749.327,,0.000000e+000,3.499872e+001,6.844327e-006,0.000000e+000,3,8.975801e-001,0.000000e+000,,,,,,,,,,,,,,32,1,4.000000e+000,1.560211e-003,0.000000e+000,0,,0,
1524592787.730,,0.000000e+000,3.499950e+001,6.829800e-006,0.000000e+000,3,8.956960e-001,0.000000e+000,,,,,,,,,,,,,,32,1,4.000000e+000,1.560211e-003,0.000000e+000,0,,0,
1524592825.828,,0.000000e+000,3.499989e+001,6.757866e-006,0.000000e+000,3,8.940088e-001,0.000000e+000,,,,,,,,,,,,,,32,1,4.000000e+000,7.781982e-004,0.000000e+000,0,,0,
1524592863.784,,0.000000e+000,3.499872e+001,6.769487e-006,0.000000e+000,3,9.027693e-001,0.000000e+000,,,,,,,,,,,,,,32,1,4.000000e+000,0.000000e+000,0.000000e+000,0,,0,
1524592902.602,,0.000000e+000,3.499911e+001,6.813400e-006,0.000000e+000,3,8.953466e-001,0.000000e+000,,,,,,,,,,,,,,32,1,4.000000e+000,2.338409e-003,0.000000e+000,0,,0,
1524592940.170,,0.000000e+000,3.499950e+001,6.782004e-006,0.000000e+000,3,8.953690e-001,0.000000e+000,,,,,,,,,,,,,,32,1,4.000000e+000,3.120422e-003,0.000000e+000,0,,0,
1524592978.145,,0.000000e+000,3.499950e+001,6.807831e-006,0.000000e+000,3,8.880110e-001,0.000000e+000,,,,,,,,,,,,,,32,1,4.000000e+000,0.000000e+000,0.000000e+000,0,,0,
1524593016.108,,0.000000e+000,3.499950e+001,6.844981e-006,0.000000e+000,3,8.937611e-001,0.000000e+000,,,,,,,,,,,,,,32,1,4.000000e+000,1.560211e-003,0.000000e+000,0,,0,
1524593053.806,,0.000000e+000,3.500067e+001,6.800065e-006,0.000000e+000,3,9.001944e-001,0.000000e+000,,,,,,,,,,,,,,32,1,4.000000e+000,7.820129e-004,0.000000e+000,0,,0,
1524593091.777,,0.000000e+000,3.499911e+001,6.834794e-006,0.000000e+000,3,8.999174e-001,0.000000e+000,,,,,,,,,,,,,,32,1,4.000000e+000,2.338409e-003,0.000000e+000,0,,0,
1524593129.530,,0.000000e+000,3.500028e+001,6.843508e-006,0.000000e+000,3,8.937898e-001,0.000000e+000,,,,,,,,,,,,,,32,1,4.000000e+000,1.560211e-003,0.000000e+000,0,,0,
1524593167.476,,0.000000e+000,3.499911e+001,6.907328e-006,0.000000e+000,3,8.979414e-001,0.000000e+000,,,,,,,,,,,,,,32,1,4.000000e+000,7.820129e-004,0.000000e+000,0,,0,
1524593205.136,,0.000000e+000,3.499833e+001,6.746399e-006,0.000000e+000,3,9.038126e-001,0.000000e+000,,,,,,,,,,,,,,32,1,4.000000e+000,7.781982e-004,0.000000e+000,0,,0,
1524593242.452,,0.000000e+000,3.499950e+001,6.842947e-006,0.000000e+000,3,8.937297e-001,0.000000e+000,,,,,,,,,,,,,,32,1,4.000000e+000,0.000000e+000,0.000000e+000,0,,0,
1524593279.997,,0.000000e+000,3.499950e+001,6.818307e-006,0.000000e+000,3,8.945427e-001,0.000000e+000,,,,,,,,,,,,,,32,1,4.000000e+000,1.560211e-003,0.000000e+000,0,,0,
1524593316.953,,0.000000e+000,3.499833e+001,6.811350e-006,0.000000e+000,3,8.894376e-001,0.000000e+000,,,,,,,,,,,,,,32,1,4.000000e+000,2.349854e-003,0.000000e+000,0,,0,
1524593354.371,,0.000000e+000,3.499911e+001,6.848716e-006,0.000000e+000,3,8.954290e-001,0.000000e+000,,,,,,,,,,,,,,32,1,4.000000e+000,7.820129e-004,0.000000e+000,0,,0,
1524593392.036,,0.000000e+000,3.499950e+001,6.788351e-006,0.000000e+000,3,8.973352e-001,0.000000e+000,,,,,,,,,,,,,,32,1,4.000000e+000,1.560211e-003,0.000000e+000,0,,0,
1524593430.357,,0.000000e+000,3.499950e+001,6.824896e-006,0.000000e+000,3,8.978677e-001,0.000000e+000,,,,,,,,,,,,,,32,1,4.000000e+000,0.000000e+000,0.000000e+000,0,,0,
1524593468.137,,0.000000e+000,3.499872e+001,6.798938e-006,0.000000e+000,3,8.948060e-001,0.000000e+000,,,,,,,,,,,,,,32,1,4.000000e+000,1.560211e-003,0.000000e+000,0,,0,
1524593505.836,,0.000000e+000,3.499989e+001,6.855860e-006,0.000000e+000,3,9.004893e-001,0.000000e+000,,,,,,,,,,,,,,32,1,4.000000e+000,2.342224e-003,0.000000e+000,0,,0,
1524593543.861,,0.000000e+000,3.499950e+001,6.873425e-006,0.000000e+000,3,9.034553e-001,0.000000e+000,,,,,,,,,,,,,,32,1,4.000000e+000,1.560211e-003,0.000000e+000,0,,0,
1524593581.149,,0.000000e+000,3.499911e+001,6.833553e-006,0.000000e+000,3,8.868436e-001,0.000000e+000,,,,,,,,,,,,,,32,1,4.000000e+000,7.820129e-004,0.000000e+000,0,,0,
1524593619.335,,0.000000e+000,3.499872e+001,6.836043e-006,0.000000e+000,3,8.896708e-001,0.000000e+000,,,,,,,,,,,,,,32,1,4.000000e+000,0.000000e+000,0.000000e+000,0,,0,
1524593657.350,,0.000000e+000,3.499833e+001,6.825936e-006,0.000000e+000,3,8.920490e-001,0.000000e+000,,,,,,,,,,,,,,32,1,4.000000e+000,7.781982e-004,0.000000e+000,0,,0,
1524593695.436,,0.000000e+000,3.499833e+001,6.899117e-006,0.000000e+000,3,8.949383e-001,0.000000e+000,,,,,,,,,,,,,,32,1,4.000000e+000,7.781982e-004,0.000000e+000,0,,0,
1524593733.286,,0.000000e+000,3.499950e+001,6.775783e-006,0.000000e+000,3,8.981394e-001,0.000000e+000,,,,,,,,,,,,,,32,1,4.000000e+000,1.560211e-003,0.000000e+000,0,,0,
1524593771.107,,0.000000e+000,3.499872e+001,6.924560e-006,0.000000e+000,3,9.015433e-001,0.000000e+000,,,,,,,,,,,,,,32,1,4.000000e+000,1.560211e-003,0.000000e+000,0,,0,
1524593809.797,,0.000000e+000,3.499715e+001,6.855164e-006,0.000000e+000,3,8.985565e-001,0.000000e+000,,,,,,,,,,,,,,32,1,4.000000e+000,0.000000e+000,0.000000e+000,0,,0,
1524593847.926,,0.000000e+000,3.499833e+001,6.802349e-006,0.000000e+000,3,8.984905e-001,0.000000e+000,,,,,,,,,,,,,,32,1,4.000000e+000,7.781982e-004,0.000000e+000,0,,0,
1524593886.371,,0.000000e+000,3.500028e+001,6.858576e-006,0.000000e+000,3,8.938755e-001,0.000000e+000,,,,,,,,,,,,,,32,1,4.000000e+000,3.120422e-003,0.000000e+000,0,,0,
1524593924.424,,0.000000e+000,3.499989e+001,6.853471e-006,0.000000e+000,3,8.917394e-001,0.000000e+000,,,,,,,,,,,,,,32,1,4.000000e+000,2.342224e-003,0.000000e+000,0,,0,
1524593962.215,,0.000000e+000,3.499872e+001,6.875845e-006,0.000000e+000,3,8.955469e-001,0.000000e+000,,,,,,,,,,,,,,32,1,4.000000e+000,1.560211e-003,0.000000e+000,0,,0,
1524593999.200,,0.000000e+000,3.499950e+001,6.856287e-006,0.000000e+000,3,8.951078e-001,0.000000e+000,,,,,,,,,,,,,,32,1,4.000000e+000,0.000000e+000,0.000000e+000,0,,0,
1524594036.796,,0.000000e+000,3.500067e+001,6.861701e-006,0.000000e+000,3,9.004505e-001,0.000000e+000,,,,,,,,,,,,,,32,1,4.000000e+000,7.820129e-004,0.000000e+000,0,,0,
1524594074.674,,0.000000e+000,3.499871e+001,6.863229e-006,0.000000e+000,3,8.882399e-001,0.000000e+000,,,,,,,,,,,,,,32,1,4.000000e+000,3.128052e-003,0.000000e+000,0,,0,
1524594112.537,,0.000000e+000,3.499950e+001,6.860177e-006,0.000000e+000,3,9.006519e-001,0.000000e+000,,,,,,,,,,,,,,32,1,4.000000e+000,0.000000e+000,0.000000e+000,0,,0,
1524594150.763,,0.000000e+000,3.499872e+001,6.799218e-006,0.000000e+000,3,8.896594e-001,0.000000e+000,,,,,,,,,,,,,,32,1,4.000000e+000,0.000000e+000,0.000000e+000,0,,0,
1524594188.191,,0.000000e+000,3.499715e+001,6.835656e-006,0.000000e+000,3,8.908450e-001,0.000000e+000,,,,,,,,,,,,,,32,1,4.000000e+000,3.128052e-003,0.000000e+000,0,,0,
1524594226.289,,0.000000e+000,3.499520e+001,6.856887e-006,0.000000e+000,3,8.959346e-001,0.000000e+000,,,,,,,,,,,,,,32,1,4.000000e+000,8.602142e-003,0.000000e+000,0,,0,
1524594264.209,,0.000000e+000,3.499911e+001,6.824340e-006,0.000000e+000,3,8.939009e-001,0.000000e+000,,,,,,,,,,,,,,32,1,4.000000e+000,7.820129e-004,0.000000e+000,0,,0,
1524594302.162,,0.000000e+000,3.499911e+001,6.890677e-006,0.000000e+000,3,9.027767e-001,0.000000e+000,,,,,,,,,,,,,,32,1,4.000000e+000,7.820129e-004,0.000000e+000,0,,0,
1524594339.853,,0.000000e+000,3.499833e+001,6.902201e-006,0.000000e+000,3,9.005161e-001,0.000000e+000,,,,,,,,,,,,,,32,1,4.000000e+000,2.349854e-003,0.000000e+000,0,,0,
1524594378.568,,0.000000e+000,3.499677e+001,6.931455e-006,0.000000e+000,3,9.030897e-001,0.000000e+000,,,,,,,,,,,,,,32,1,4.000000e+000,2.349854e-003,0.000000e+000,0,,0,
1524594416.521,,0.000000e+000,3.499989e+001,6.828846e-006,0.000000e+000,3,8.940605e-001,0.000000e+000,,,,,,,,,,,,,,32,1,4.000000e+000,7.781982e-004,0.000000e+000,0,,0,
1524594454.062,,0.000000e+000,3.499989e+001,6.895236e-006,0.000000e+000,3,8.923752e-001,0.000000e+000,,,,,,,,,,,,,,32,1,4.000000e+000,7.781982e-004,0.000000e+000,0,,0,
1524594491.465,,0.000000e+000,3.499911e+001,6.831994e-006,0.000000e+000,3,8.953245e-001,0.000000e+000,,,,,,,,,,,,,,32,1,4.000000e+000,7.820129e-004,0.000000e+000,0,,0,
1524594529.468,,0.000000e+000,3.499950e+001,6.814697e-006,0.000000e+000,3,9.007137e-001,0.000000e+000,,,,,,,,,,,,,,32,1,4.000000e+000,0.000000e+000,0.000000e+000,0,,0,
1524594542.161,,0.000000e+000,3.499950e+001,6.840288e-006,0.000000e+000,3,8.995792e-001,0.000000e+000,,,,,,,,,,,,,,32,1,4.000000e+000,0.000000e+000,0.000000e+000,0,,0,