File: Input/MFn1_TRMac_37K_0.16Kmin_VRMde_35K.dc.dat
[Header]
TITLE,MPMS DC Measurement
BYAPP,MPMS Measurement,2.1,Summary
FILEOPENTIME, 1524550410.503000 4/24/2018, 12:13:30 AM

INFO, APPNAME, MPMS MultiVu Application, Revision 1.61,  Build 082

INFO, NAME, MFn1
INFO, WEIGHT, 1.000
INFO, AREA, 1.000
INFO, LENGTH, 1.000
INFO, SHAPE, 0
INFO, COMMENT,
INFO, SEQUENCE FILE: TRMac_37K_0.16Kmin_VRMde_35K.seq


INFO, BACKGROUND DATA FILE:, None


STARTUPAXIS,X,4,LINEAR,AUTO,0.000000,0.000000
STARTUPAXIS,Y1,5,LINEAR,AUTO,0.000000,0.000000


STARTUPGROUP,Longitudinal
FIELDGROUP,Longitudinal,1,2,3,4,5,6,7,8,9,15,16,17,18,27,28
FIELDGROUP,Transverse,1,2,3,4,10,11,12,13,14,19,20,21,22,27,28

PLOT_APPEARANCE,ALL,HORZ_GRID_ON,VERT_GRID_ON,MARKERS_AND_LINES

[Data]
Time,Comment,Field (Oe),Temperature (K),Long Moment (emu),Long Scan Std Dev,Long Algorithm,Long Reg Fit,Long Percent Error (%),Trans Moment (emu),Trans Scan Std Dev,Trans Algorithm,Trans Reg Fit,Trans Percent Error (%),Long Moment [w/o ABS] (emu),Long Scan Std Dev [w/o ABS],Long Reg Fit [w/o ABS],Long Percent Error [w/o ABS] (%),Trans Moment [w/o ABS] (emu),Trans Scan Std Dev [w/o ABS],Trans Reg Fit [w/o ABS],Trans Percent Error [w/o ABS] (%),Points per Scan,Scans per Measurement,Scan Length (cm),Delta Temp (K),Rot Position (deg),Error,EC Comp. Running,Using ABS,
1524550410.500,,0.000000e+000,3.499754e+001,-5.539344e-006,0.000000e+000,3,8.710757e-001,0.000000e+000,,,,,,,,,,,,,,32,1,4.000000e+000,7.030487e-003,0.000000e+000,0,,0,
1524550448.868,,0.000000e+000,3.500106e+001,-3.505432e-006,0.000000e+000,3,8.035514e-001,0.000000e+000,,,,,,,,,,,,,,32,1,4.000000e+000,0.000000e+000,0.000000e+000,0,,0,
1524550486.621,,0.000000e+000,3.499794e+001,-2.213841e-006,0.000000e+000,3,6.616613e-001,0.000000e+000,,,,,,,,,,,,,,32,1,4.000000e+000,0.000000e+000,0.000000e+000,0,,0,
1524550524.739,,0.000000e+000,3.500302e+001,-1.334717e-006,0.000000e+000,3,4.526671e-001,0.000000e+000,,,,,,,,,,,,,,32,1,4.000000e+000,7.820129e-004,0.000000e+000,0,,0,
1524550562.390,,0.000000e+000,3.500380e+001,-6.591362e-007,0.000000e+000,3,0.000000e+000,0.000000e+000,,,,,,,,,,,,,,32,1,4.000000e+000,7.781982e-004,0.000000e+000,0,,0,
1524550603.667,,0.000000e+000,3.499638e+001,2.776702e-007,0.000000e+000,2,0.000000e+000,0.000000e+000,,,,,,,,,,,,,,32,1,4.000000e+000,3.131866e-003,0.000000e+000,0,,0,
1524550895.319,,0.000000e+000,3.499872e+001,2.923285e-006,0.000000e+000,3,7.708774e-001,0.000000e+000,,,,,,,,,,,,,,32,1,4.000000e+000,0.000000e+000,0.000000e+000,0,,0,
1524550932.357,,0.000000e+000,3.499911e+001,3.086606e-006,0.000000e+000,3,7.809002e-001,0.000000e+000,,,,,,,,,,,,,,32,1,4.000000e+000,7.820129e-004,0.000000e+000,0,,0,
1524550970.320,,0.000000e+000,3.499872e+001,3.314072e-006,0.000000e+000,3,7.883737e-001,0.000000e+000,,,,,,,,,,,,,,32,1,4.000000e+000,0.000000e+000,0.000000e+000,0,,0,
1524551008.386,,0.000000e+000,3.499872e+001,3.415307e-006,0.000000e+000,3,7.927618e-001,0.000000e+000,,,,,,,,,,,,,,32,1,4.000000e+000,0.000000e+000,0.000000e+000,0,,0,
1524551046.511,,0.000000e+000,3.499911e+001,3.563849e-006,0.000000e+000,3,8.033026e-001,0.000000e+000,,,,,,,,,,,,,,32,1,4.000000e+000,2.338409e-003,0.000000e+000,0,,0,
1524551084.657,,0.000000e+000,3.499872e+001,3.699736e-006,0.000000e+000,3,8.102394e-001,0.000000e+000,,,,,,,,,,,,,,32,1,4.000000e+000,1.560211e-003,0.000000e+000,0,,0,
1524551122.762,,0.000000e+000,3.499794e+001,3.809463e-006,0.000000e+000,3,8.159465e-001,0.000000e+000,,,,,,,,,,,,,,32,1,4.000000e+000,0.000000e+000,0.000000e+000,0,,0,
1524551160.888,,0.000000e+000,3.499833e+001,3.956240e-006,0.000000e+000,3,8.241445e-001,0.000000e+000,,,,,,,,,,,,,,32,1,4.000000e+000,7.781982e-004,0.000000e+000,0,,0,
1524551198.991,,0.000000e+000,3.499833e+001,4.036624e-006,0.000000e+000,3,8.217450e-001,0.000000e+000,,,,,,,,,,,,,,32,1,4.000000e+000,2.349854e-003,0.000000e+000,0,,0,
1524551236.741,,0.000000e+000,3.499833e+001,4.172490e-006,0.000000e+000,3,8.333460e-001,0.000000e+000,,,,,,,,,,,,,,32,1,4.000000e+000,7.781982e-004,0.000000e+000,0,,0,
1524551274.704,,0.000000e+000,3.499481e+001,4.260650e-006,0.000000e+000,3,8.348650e-001,0.000000e+000,,,,,,,,,,,,,,32,1,4.000000e+000,7.820129e-003,0.000000e+000,0,,0,
1524551312.130,,0.000000e+000,3.499833e+001,4.365790e-006,0.000000e+000,3,8.426896e-001,0.000000e+000,,,,,,,,,,,,,,32,1,4.000000e+000,7.781982e-004,0.000000e+000,0,,0,
1524551350.298,,0.000000e+000,3.499911e+001,4.412713e-006,0.000000e+000,3,8.436050e-001,0.000000e+000,,,,,,,,,,,,,,32,1,4.000000e+000,7.820129e-004,0.000000e+000,0,,0,
1524551388.228,,0.000000e+000,3.499871e+001,4.505077e-006,0.000000e+000,3,8.404970e-001,0.000000e+000,,,,,,,,,,,,,,32,1,4.000000e+000,3.128052e-003,0.000000e+000,0,,0,
1524551426.007,,0.000000e+000,3.499872e+001,4.605844e-006,0.000000e+000,3,8.543442e-001,0.000000e+000,,,,,,,,,,,,,,32,1,4.000000e+000,0.000000e+000,0.000000e+000,0,,0,
1524551464.012,,0.000000e+000,3.500067e+001,4.664568e-006,0.000000e+000,3,8.555037e-001,0.000000e+000,,,,,,,,,,,,,,32,1,4.000000e+000,3.910065e-003,0.000000e+000,0,,0,
1524551502.158,,0.000000e+000,3.499872e+001,4.747426e-006,0.000000e+000,3,8.498031e-001,0.000000e+000,,,,,,,,,,,,,,32,1,4.000000e+000,1.560211e-003,0.000000e+000,0,,0,
1524551540.261,,0.000000e+000,3.499793e+001,4.783325e-006,0.000000e+000,3,8.605602e-001,0.000000e+000,,,,,,,,,,,,,,32,1,4.000000e+000,3.131866e-003,0.000000e+000,0,,0,
1524551578.356,,0.000000e+000,3.499833e+001,4.840197e-006,0.000000e+000,3,8.573179e-001,0.000000e+000,,,,,,,,,,,,,,32,1,4.000000e+000,7.781982e-004,0.000000e+000,0,,0,
1524551615.982,,0.000000e+000,3.499715e+001,4.915012e-006,0.000000e+000,3,8.602007e-001,0.000000e+000,,,,,,,,,,,,,,32,1,4.000000e+000,1.571655e-003,0.000000e+000,0,,0,
1524551652.705,,0.000000e+000,3.499911e+001,4.983509e-006,0.000000e+000,3,8.616170e-001,0.000000e+000,,,,,,,,,,,,,,32,1,4.000000e+000,2.338409e-003,0.000000e+000,0,,0,
1524551690.658,,0.000000e+000,3.499911e+001,5.029392e-006,0.000000e+000,3,8.595518e-001,0.000000e+000,,,,,,,,,,,,,,32,1,4.000000e+000,7.820129e-004,0.000000e+000,0,,0,
1524551728.421,,0.000000e+000,3.500067e+001,5.055901e-006,0.000000e+000,3,8.616300e-001,0.000000e+000,,,,,,,,,,,,,,32,1,4.000000e+000,7.820129e-004,0.000000e+000,0,,0,
1524551766.604,,0.000000e+000,3.499911e+001,5.103260e-006,0.000000e+000,3,8.668806e-001,0.000000e+000,,,,,,,,,,,,,,32,1,4.000000e+000,2.338409e-003,0.000000e+000,0,,0,
1524551804.472,,0.000000e+000,3.499833e+001,5.149568e-006,0.000000e+000,3,8.586720e-001,0.000000e+000,,,,,,,,,,,,,,32,1,4.000000e+000,2.349854e-003,0.000000e+000,0,,0,
1524551842.563,,0.000000e+000,3.499833e+001,5.199965e-006,0.000000e+000,3,8.652576e-001,0.000000e+000,,,,,,,,,,,,,,32,1,4.000000e+000,7.781982e-004,0.000000e+000,0,,0,
1524551880.696,,0.000000e+000,3.499911e+001,5.251183e-006,0.000000e+000,3,8.672544e-001,0.000000e+000,,,,,,,,,,,,,,32,1,4.000000e+000,2.338409e-003,0.000000e+000,0,,0,
1524551918.946,,0.000000e+000,3.499872e+001,5.276519e-006,0.000000e+000,3,8.696619e-001,0.000000e+000,,,,,,,,,,,,,,32,1,4.000000e+000,1.560211e-003,0.000000e+000,0,,0,
1524551956.897,,0.000000e+000,3.499833e+001,5.345282e-006,0.000000e+000,3,8.690249e-001,0.000000e+000,,,,,,,,,,,,,,32,1,4.000000e+000,2.349854e-003,0.000000e+000,0,,0,
1524551994.995,,0.000000e+000,3.499872e+001,5.369973e-006,0.000000e+000,3,8.654951e-001,0.000000e+000,,,,,,,,,,,,,,32,1,4.000000e+000,1.560211e-003,0.000000e+000,0,,0,
1524552033.140,,0.000000e+000,3.499872e+001,5.392253e-006,0.000000e+000,3,8.701227e-001,0.000000e+000,,,,,,,,,,,,,,32,1,4.000000e+000,1.560211e-003,0.000000e+000,0,,0,
1524552071.309,,0.000000e+000,3.499872e+001,5.486393e-006,0.000000e+000,3,8.744194e-001,0.000000e+000,,,,,,,,,,,,,,32,1,4.000000e+000,1.560211e-003,0.000000e+000,0,,0,
1524552109.374,,0.000000e+000,3.499872e+001,5.500570e-006,0.000000e+000,3,8.714834e-001,0.000000e+000,,,,,,,,,,,,,,32,1,4.000000e+000,1.560211e-003,0.000000e+000,0,,0,
1524552148.117,,0.000000e+000,3.499715e+001,5.512651e-006,0.000000e+000,3,8.742657e-001,0.000000e+000,,,,,,,,,,,,,,32,1,4.000000e+000,3.128052e-003,0.000000e+000,0,,0,
1524552186.835,,0.000000e+000,3.499833e+001,5.549154e-006,0.000000e+000,3,8.743494e-001,0.000000e+000,,,,,,,,,,,,,,32,1,4.000000e+000,7.781982e-004,0.000000e+000,0,,0,
1524552224.388,,0.000000e+000,3.499911e+001,5.572819e-006,0.000000e+000,3,8.748585e-001,0.000000e+000,,,,,,,,,,,,,,32,1,4.000000e+000,7.820129e-004,0.000000e+000,0,,0,
1524552262.499,,0.000000e+000,3.499794e+001,5.627154e-006,0.000000e+000,3,8.778972e-001,0.000000e+000,,,,,,,,,,,,,,32,1,4.000000e+000,0.000000e+000,0.000000e+000,0,,0,
1524552300.684,,0.000000e+000,3.499950e+001,5.677657e-006,0.000000e+000,3,8.774289e-001,0.000000e+000,,,,,,,,,,,,,,32,1,4.000000e+000,1.560211e-003,0.000000e+000,0,,0,
1524552339.060,,0.000000e+000,3.499833e+001,5.691661e-006,0.000000e+000,3,8.801069e-001,0.000000e+000,,,,,,,,,,,,,,32,1,4.000000e+000,7.781982e-004,0.000000e+000,0,,0,
1524552377.171,,0.000000e+000,3.499911e+001,5.709398e-006,0.000000e+000,3,8.792155e-001,0.000000e+000,,,,,,,,,,,,,,32,1,4.000000e+000,7.820129e-004,0.000000e+000,0,,0,
1524552415.336,,0.000000e+000,3.499715e+001,5.781647e-006,0.000000e+000,3,8.746037e-001,0.000000e+000,,,,,,,,,,,,,,32,1,4.000000e+000,3.128052e-003,0.000000e+000,0,,0,
1524552453.357,,0.000000e+000,3.499794e+001,5.797280e-006,0.000000e+000,3,8.748572e-001,0.000000e+000,,,,,,,,,,,,,,32,1,4.000000e+000,0.000000e+000,0.000000e+000,0,,0,
1524552491.295,,0.000000e+000,3.499872e+001,5.817629e-006,0.000000e+000,3,8.762928e-001,0.000000e+000,,,,,,,,,,,,,,32,1,4.000000e+000,1.560211e-003,0.000000e+000,0,,0,
1524552529.215,,0.000000e+000,3.499989e+001,5.807908e-006,0.000000e+000,3,8.813037e-001,0.000000e+000,,,,,,,,,,,,,,32,1,4.000000e+000,7.781982e-004,0.000000e+000,0,,0,
1524552566.621,,0.000000e+000,3.499754e+001,5.806014e-006,0.000000e+000,3,8.804544e-001,0.000000e+000,,,,,,,,,,,,,,32,1,4.000000e+000,3.910065e-003,0.000000e+000,0,,0,
1524552604.529,,0.000000e+000,3.499833e+001,5.873107e-006,0.000000e+000,3,8.819463e-001,0.000000e+000,,,,,,,,,,,,,,32,1,4.000000e+000,7.781982e-004,0.000000e+000,0,,0,
1524552642.642,,0.000000e+000,3.499832e+001,5.885044e-006,0.000000e+000,3,8.850976e-001,0.000000e+000,,,,,,,,,,,,,,32,1,4.000000e+000,3.910065e-003,0.000000e+000,0,,0,
1524552680.770,,0.000000e+000,3.499754e+001,5.933446e-006,0.000000e+000,3,8.826554e-001,0.000000e+000,,,,,,,,,,,,,,32,1,4.000000e+000,2.349854e-003,0.000000e+000,0,,0,
1524552718.540,,0.000000e+000,3.499833e+001,5.956729e-006,0.000000e+000,3,8.825306e-001,0.000000e+000,,,,,,,,,,,,,,32,1,4.000000e+000,7.781982e-004,0.000000e+000,0,,0,
1524552756.641,,0.000000e+000,3.499794e+001,5.960076e-006,0.000000e+000,3,8.841318e-001,0.000000e+000,,,,,,,,,,,,,,32,1,4.000000e+000,0.000000e+000,0.000000e+000,0,,0,
1524552795.994,,0.000000e+000,3.499911e+001,5.951500e-006,0.000000e+000,3,8.802304e-001,0.000000e+000,,,,,,,,,,,,,,32,1,4.000000e+000,7.820129e-004,0.000000e+000,0,,0,
1524552833.207,,0.000000e+000,3.499911e+001,5.978467e-006,0.000000e+000,3,8.813235e-001,0.000000e+000,,,,,,,,,,,,,,32,1,4.000000e+000,7.820129e-004,0.000000e+000,0,,0,
1524552872.223,,0.000000e+000,3.499872e+001,5.997372e-006,0.000000e+000,3,8.823684e-001,0.000000e+000,,,,,,,,,,,,,,32,1,4.000000e+000,1.560211e-003,0.000000e+000,0,,0,
1524552909.386,,0.000000e+000,3.499872e+001,6.012580e-006,0.000000e+000,3,8.805739e-001,0.000000e+000,,,,,,,,,,,,,,32,1,4.000000e+000,1.560211e-003,0.000000e+000,0,,0,
1524552947.381,,0.000000e+000,3.499793e+001,6.014394e-006,0.000000e+000,3,8.863488e-001,0.000000e+000,,,,,,,,,,,,,,32,1,4.000000e+000,1.567841e-003,0.000000e+000,0,,0,
1524552984.987,,0.000000e+000,3.499754e+001,6.072896e-006,0.000000e+000,3,8.859776e-001,0.000000e+000,,,,,,,,,,,,,,32,1,4.000000e+000,7.896423e-004,0.000000e+000,0,,0,
1524553022.993,,0.000000e+000,3.499950e+001,6.059494e-006,0.000000e+000,3,8.840755e-001,0.000000e+000,,,,,,,,,,,,,,32,1,4.000000e+000,1.560211e-003,0.000000e+000,0,,0,
1524553061.078,,0.000000e+000,3.499911e+001,6.111389e-006,0.000000e+000,3,8.874645e-001,0.000000e+000,,,,,,,,,,,,,,32,1,4.000000e+000,2.338409e-003,0.000000e+000,0,,0,
1524553099.166,,0.000000e+000,3.500028e+001,6.136635e-006,0.000000e+000,3,8.875102e-001,0.000000e+000,,,,,,,,,,,,,,32,1,4.000000e+000,0.000000e+000,0.000000e+000,0,,0,
1524553137.504,,0.000000e+000,3.499989e+001,6.125664e-006,0.000000e+000,3,8.805243e-001,0.000000e+000,,,,,,,,,,,,,,32,1,4.000000e+000,7.781982e-004,0.000000e+000,0,,0,
1524553175.522,,0.000000e+000,3.499871e+001,6.118967e-006,0.000000e+000,3,8.870891e-001,0.000000e+000,,,,,,,,,,,,,,32,1,4.000000e+000,3.128052e-003,0.000000e+000,0,,0,
1524553213.643,,0.000000e+000,3.499872e+001,6.155954e-006,0.000000e+000,3,8.816916e-001,0.000000e+000,,,,,,,,,,,,,,32,1,4.000000e+000,0.000000e+000,0.000000e+000,0,,0,
1524553251.766,,0.000000e+000,3.499950e+001,6.150161e-006,0.000000e+000,3,8.858638e-001,0.000000e+000,,,,,,,,,,,,,,32,1,4.000000e+000,0.000000e+000,0.000000e+000,0,,0,
1524553290.484,,0.000000e+000,3.499950e+001,6.200903e-006,0.000000e+000,3,8.844081e-001,0.000000e+000,,,,,,,,,,,,,,32,1,4.000000e+000,0.000000e+000,0.000000e+000,0,,0,
1524553327.972,,0.000000e+000,3.499950e+001,6.169194e-006,0.000000e+000,3,8.841767e-001,0.000000e+000,,,,,,,,,,,,,,32,1,4.000000e+000,1.560211e-003,0.000000e+000,0,,0,
1524553365.462,,0.000000e+000,3.499872e+001,6.203745e-006,0.000000e+000,3,8.890027e-001,0.000000e+000,,,,,,,,,,,,,,32,1,4.000000e+000,1.560211e-003,0.000000e+000,0,,0,
1524553403.323,,0.000000e+000,3.499911e+001,6.226116e-006,0.000000e+000,3,8.882717e-001,0.000000e+000,,,,,,,,,,,,,,32,1,4.000000e+000,7.820129e-004,0.000000e+000,0,,0,
1524553441.459,,0.000000e+000,3.499872e+001,6.265977e-006,0.000000e+000,3,8.885596e-001,0.000000e+000,,,,,,,,,,,,,,32,1,4.000000e+000,1.560211e-003,0.000000e+000,0,,0,
1524553479.829,,0.000000e+000,3.499793e+001,6.256766e-006,0.000000e+000,3,8.908597e-001,0.000000e+000,,,,,,,,,,,,,,32,1,4.000000e+000,1.567841e-003,0.000000e+000,0,,0,
1524553517.747,,0.000000e+000,3.499754e+001,6.290807e-006,0.000000e+000,3,8.831714e-001,0.000000e+000,,,,,,,,,,,,,,32,1,4.000000e+000,7.896423e-004,0.000000e+000,0,,0,
1524553555.255,,0.000000e+000,3.499677e+001,6.263714e-006,0.000000e+000,3,8.886750e-001,0.000000e+000,,,,,,,,,,,,,,32,1,4.000000e+000,2.349854e-003,0.000000e+000,0,,0,
1524553592.918,,0.000000e+000,3.499911e+001,6.269674e-006,0.000000e+000,3,8.917672e-001,0.000000e+000,,,,,,,,,,,,,,32,1,4.000000e+000,7.820129e-004,0.000000e+000,0,,0,
1524553630.959,,0.000000e+000,3.499911e+001,6.255870e-006,0.000000e+000,3,8.895460e-001,0.000000e+000,,,,,,,,,,,,,,32,1,4.000000e+000,2.338409e-003,0.000000e+000,0,,0,
1524553669.107,,0.000000e+000,3.500028e+001,6.312805e-006,0.000000e+000,3,8.899450e-001,0.000000e+000,,,,,,,,,,,,,,32,1,4.000000e+000,1.560211e-003,0.000000e+000,0,,0,
1524553706.855,,0.000000e+000,3.499911e+001,6.289104e-006,0.000000e+000,3,8.875828e-001,0.000000e+000,,,,,,,,,,,,,,32,1,4.000000e+000,2.338409e-003,0.000000e+000,0,,0,
1524553745.288,,0.000000e+000,3.499872e+001,6.344869e-006,0.000000e+000,3,8.891252e-001,0.000000e+000,,,,,,,,,,,,,,32,1,4.000000e+000,0.000000e+000,0.000000e+000,0,,0,
1524553783.279,,0.000000e+000,3.499872e+001,6.333884e-006,0.000000e+000,3,8.917866e-001,0.000000e+000,,,,,,,,,,,,,,32,1,4.000000e+000,1.560211e-003,0.000000e+000,0,,0,
1524553821.637,,0.000000e+000,3.499833e+001,6.344186e-006,0.000000e+000,3,8.844786e-001,0.000000e+000,,,,,,,,,,,,,,32,1,4.000000e+000,2.349854e-003,0.000000e+000,0,,0,
1524553859.955,,0.000000e+000,3.499989e+001,6.333102e-006,0.000000e+000,3,8.892438e-001,0.000000e+000,,,,,,,,,,,,,,32,1,4.000000e+000,2.342224e-003,0.000000e+000,0,,0,
1524553898.910,,0.000000e+000,3.499989e+001,6.363109e-006,0.000000e+000,3,8.908254e-001,0.000000e+000,,,,,,,,,,,,,,32,1,4.000000e+000,7.781982e-004,0.000000e+000,0,,0,
1524553936.381,,0.000000e+000,3.499950e+001,6.353802e-006,0.000000e+000,3,8.915140e-001,0.000000e+000,,,,,,,,,,,,,,32,1,4.000000e+000,1.560211e-003,0.000000e+000,0,,0,
1524553974.846,,0.000000e+000,3.499754e+001,6.471322e-006,0.000000e+000,3,8.880878e-001,0.000000e+000,,,,,,,,,,,,,,32,1,4.000000e+000,2.349854e-003,0.000000e+000,0,,0,
1524554012.859,,0.000000e+000,3.499989e+001,6.450274e-006,0.000000e+000,3,8.878813e-001,0.000000e+000,,,,,,,,,,,,,,32,1,4.000000e+000,7.781982e-004,0.000000e+000,0,,0,
1524554050.733,,0.000000e+000,3.500028e+001,6.376352e-006,0.000000e+000,3,8.901090e-001,0.000000e+000,,,,,,,,,,,,,,32,1,4.000000e+000,1.560211e-003,0.000000e+000,0,,0,
1524554088.848,,0.000000e+000,3.499833e+001,6.441550e-006,0.000000e+000,3,8.919202e-001,0.000000e+000,,,,,,,,,,,,,,32,1,4.000000e+000,7.781982e-004,0.000000e+000,0,,0,
1524554127.809,,0.000000e+000,3.500067e+001,6.468360e-006,0.000000e+000,3,8.879737e-001,0.000000e+000,,,,,,,,,,,,,,32,1,4.000000e+000,7.820129e-004,0.000000e+000,0,,0,
1524554165.429,,0.000000e+000,3.499872e+001,6.419697e-006,0.000000e+000,3,8.908269e-001,0.000000e+000,,,,,,,,,,,,,,32,1,4.000000e+000,1.560211e-003,0.000000e+000,0,,0,
1524554203.567,,0.000000e+000,3.499911e+001,6.443985e-006,0.000000e+000,3,8.911812e-001,0.000000e+000,,,,,,,,,,,,,,32,1,4.000000e+000,7.820129e-004,0.000000e+000,0,,0,
1524554241.648,,0.000000e+000,3.499833e+001,6.418418e-006,0.000000e+000,3,8.876435e-001,0.000000e+000,,,,,,,,,,,,,,32,1,4.000000e+000,7.781982e-004,0.000000e+000,0,,0,
1524554280.388,,0.000000e+000,3.499715e+001,6.466612e-006,0.000000e+000,3,8.930973e-001,0.000000e+000,,,,,,,,,,,,,,32,1,4.000000e+000,0.000000e+000,0.000000e+000,0,,0,
1524554318.452,,0.000000e+000,3.499872e+001,6.409161e-006,0.000000e+000,3,8.925122e-001,0.000000e+000,,,,,,,,,,,,,,32,1,4.000000e+000,0.000000e+000,0.000000e+000,0,,0,
1524554355.222,,0.000000e+000,3.499911e+001,6.461683e-006,0.000000e+000,3,8.884750e-001,0.000000e+000,,,,,,,,,,,,,,32,1,4.000000e+000,7.820129e-004,0.000000e+000,0,,0,
1524554393.640,,0.000000e+000,3.499872e+001,6.459797e-006,0.000000e+000,3,8.917127e-001,0.000000e+000,,,,,,,,,,,,,,32,1,4.000000e+000,1.560211e-003,0.000000e+000,0,,0,
1524554431.973,,0.000000e+000,3.499911e+001,6.442507e-006,0.000000e+000,3,8.920925e-001,0.000000e+000,,,,,,,,,,,,,,32,1,4.000000e+000,2.338409e-003,0.000000e+000,0,,0,
1524554470.079,,0.000000e+000,3.500028e+001,6.478100e-006,0.000000e+000,3,8.933522e-001,0.000000e+000,,,,,,,,,,,,,,32,1,4.000000e+000,1.560211e-003,0.000000e+000,0,,0,
1524554508.349,,0.000000e+000,3.499676e+001,6.497408e-006,0.000000e+000,3,8.878117e-001,0.000000e+000,,,,,,,,,,,,,,32,1,4.000000e+000,7.820129e-004,0.000000e+000,0,,0,
1524554546.642,,0.000000e+000,3.499911e+001,6.489377e-006,0.000000e+000,3,8.842857e-001,0.000000e+000,,,,,,,,,,,,,,32,1,4.000000e+000,7.820129e-004,0.000000e+000,0,,0,
1524554584.948,,0.000000e+000,3.500028e+001,6.549789e-006,0.000000e+000,3,8.952261e-001,0.000000e+000,,,,,,,,,,,,,,32,1,4.000000e+000,1.560211e-003,0.000000e+000,0,,0,
1524554623.358,,0.000000e+000,3.499677e+001,6.502859e-006,0.000000e+000,3,8.937237e-001,0.000000e+000,,,,,,,,,,,,,,32,1,4.000000e+000,2.349854e-003,0.000000e+000,0,,0,
1524554660.852,,0.000000e+000,3.499989e+001,6.506426e-006,0.000000e+000,3,8.912439e-001,0.000000e+000,,,,,,,,,,,,,,32,1,4.000000e+000,7.781982e-004,0.000000e+000,0,,0,
1524554698.717,,0.000000e+000,3.499911e+001,6.542418e-006,0.000000e+000,3,8.847497e-001,0.000000e+000,,,,,,,,,,,,,,32,1,4.000000e+000,7.820129e-004,0.000000e+000,0,,0,
1524554735.995,,0.000000e+000,3.499911e+001,6.524102e-006,0.000000e+000,3,8.930632e-001,0.000000e+000,,,,,,,,,,,,,,32,1,4.000000e+000,7.820129e-004,0.000000e+000,0,,0,
1524554774.078,,0.000000e+000,3.499950e+001,6.536384e-006,0.000000e+000,3,8.951793e-001,0.000000e+000,,,,,,,,,,,,,,32,1,4.000000e+000,0.000000e+000,0.000000e+000,0,,0,
1524554811.966,,0.000000e+000,3.499911e+001,6.569034e-006,0.000000e+000,3,8.924106e-001,0.000000e+000,,,,,,,,,,,,,,32,1,4.000000e+000,3.910065e-003,0.000000e+000,0,,0,
1524554850.087,,0.000000e+000,3.499911e+001,6.557867e-006,0.000000e+000,3,8.876868e-001,0.000000e+000,,,,,,,,,,,,,,32,1,4.000000e+000,7.820129e-004,0.000000e+000,0,,0,
1524554888.055,,0.000000e+000,3.499911e+001,6.586439e-006,0.000000e+000,3,8.922957e-001,0.000000e+000,,,,,,,,,,,,,,32,1,4.000000e+000,7.820129e-004,0.000000e+000,0,,0,
1524554926.203,,0.000000e+000,3.499754e+001,6.528124e-006,0.000000e+000,3,8.936732e-001,0.000000e+000,,,,,,,,,,,,,,32,1,4.000000e+000,7.896423e-004,0.000000e+000,0,,0,
1524554964.111,,0.000000e+000,3.499793e+001,6.551487e-006,0.000000e+000,3,8.924995e-001,0.000000e+000,,,,,,,,,,,,,,32,1,4.000000e+000,4.688263e-003,0.000000e+000,0,,0,
1524555002.177,,0.000000e+000,3.499833e+001,6.540832e-006,0.000000e+000,3,8.907905e-001,0.000000e+000,,,,,,,,,,,,,,32,1,4.000000e+000,2.349854e-003,0.000000e+000,0,,0,
1524555040.832,,0.000000e+000,3.499833e+001,6.488119e-006,0.000000e+000,3,8.950823e-001,0.000000e+000,,,,,,,,,,,,,,32,1,4.000000e+000,2.349854e-003,0.000000e+000,0,,0,
1524555078.378,,0.000000e+000,3.499950e+001,6.583726e-006,0.000000e+000,3,8.881360e-001,0.000000e+000,,,,,,,,,,,,,,32,1,4.000000e+000,0.000000e+000,0.000000e+000,0,,0,
1524555117.528,,0.000000e+000,3.499833e+001,6.590702e-006,0.000000e+000,3,8.954753e-001,0.000000e+000,,,,,,,,,,,,,,32,1,4.000000e+000,2.349854e-003,0.000000e+000,0,,0,
1524555155.541,,0.000000e+000,3.499872e+001,6.610406e-006,0.000000e+000,3,8.934332e-001,0.000000e+000,,,,,,,,,,,,,,32,1,4.000000e+000,1.560211e-003,0.000000e+000,0,,0,
1524555193.442,,0.000000e+000,3.499989e+001,6.588839e-006,0.000000e+000,3,8.938004e-001,0.000000e+000,,,,,,,,,,,,,,32,1,4.000000e+000,7.781982e-004,0.000000e+000,0,,0,
1524555231.412,,0.000000e+000,3.499989e+001,6.608537e-006,0.000000e+000,3,8.960783e-001,0.000000e+000,,,,,,,,,,,,,,32,1,4.000000e+000,7.781982e-004,0.000000e+000,0,,0,
1524555269.380,,0.000000e+000,3.499950e+001,6.625244e-006,0.000000e+000,3,8.921900e-001,0.000000e+000,,,,,,,,,,,,,,32,1,4.000000e+000,0.000000e+000,0.000000e+000,0,,0,
1524555307.354,,0.000000e+000,3.499911e+001,6.639345e-006,0.000000e+000,3,8.934158e-001,0.000000e+000,,,,,,,,,,,,,,32,1,4.000000e+000,3.910065e-003,0.000000e+000,0,,0,
1524555344.782,,0.000000e+000,3.499871e+001,6.611843e-006,0.000000e+000,3,8.925191e-001,0.000000e+000,,,,,,,,,,,,,,32,1,4.000000e+000,4.692078e-003,0.000000e+000,0,,0,
1524555382.867,,0.000000e+000,3.499872e+001,6.609122e-006,0.000000e+000,3,8.959532e-001,0.000000e+000,,,,,,,,,,,,,,32,1,4.000000e+000,0.000000e+000,0.000000e+000,0,,0,
1524555420.985,,0.000000e+000,3.499793e+001,6.591205e-006,0.000000e+000,3,8.970178e-001,0.000000e+000,,,,,,,,,,,,,,32,1,4.000000e+000,3.131866e-003,0.000000e+000,0,,0,
1524555459.136,,0.000000e+000,3.499950e+001,6.598315e-006,0.000000e+000,3,8.921594e-001,0.000000e+000,,,,,,,,,,,,,,32,1,4.000000e+000,0.000000e+000,0.000000e+000,0,,0,
1524555497.169,,0.000000e+000,3.499911e+001,6.590930e-006,0.000000e+000,3,8.968595e-001,0.000000e+000,,,,,,,,,,,,,,32,1,4.000000e+000,7.820129e-004,0.000000e+000,0,,0,
1524555534.492,,0.000000e+000,3.499911e+001,6.594978e-006,0.000000e+000,3,8.923192e-001,0.000000e+000,,,,,,,,,,,,,,32,1,4.000000e+000,7.820129e-004,0.000000e+000,0,,0,
1524555572.547,,0.000000e+000,3.499872e+001,6.600055e-006,0.000000e+000,3,8.914902e-001,0.000000e+000,,,,,,,,,,,,,,32,1,4.000000e+000,1.560211e-003,0.000000e+000,0,,0,
1524555609.798,,0.000000e+000,3.499911e+001,6.593863e-006,0.000000e+000,3,8.955714e-001,0.000000e+000,,,,,,,,,,,,,,32,1,4.000000e+000,2.338409e-003,0.000000e+000,0,,0,
1524555647.899,,0.000000e+000,3.499833e+001,6.615040e-006,0.000000e+000,3,8.929477e-001,0.000000e+000,,,,,,,,,,,,,,32,1,4.000000e+000,7.781982e-004,0.000000e+000,0,,0,
1524555686.282,,0.000000e+000,3.499950e+001,6.653111e-006,0.000000e+000,3,8.988116e-001,0.000000e+000,,,,,,,,,,,,,,32,1,4.000000e+000,0.000000e+000,0.000000e+000,0,,0,
1524555724.097,,0.000000e+000,3.499833e+001,6.667826e-006,0.000000e+000,3,8.937164e-001,0.000000e+000,,,,,,,,,,,,,,32,1,4.000000e+000,7.781982e-004,0.000000e+000,0,,0,
1524555762.405,,0.000000e+000,3.500067e+001,6.656080e-006,0.000000e+000,3,8.932469e-001,0.000000e+000,,,,,,,,,,,,,,32,1,4.000000e+000,2.338409e-003,0.000000e+000,0,,0,
1524555800.473,,0.000000e+000,3.499911e+001,6.663807e-006,0.000000e+000,3,8.990356e-001,0.000000e+000,,,,,,,,,,,,,,32,1,4.000000e+000,7.820129e-004,0.000000e+000,0,,0,
1524555838.366,,0.000000e+000,3.499833e+001,6.635431e-006,0.000000e+000,3,8.952166e-001,0.000000e+000,,,,,,,,,,,,,,32,1,4.000000e+000,7.781982e-004,0.000000e+000,0,,0,
1524555876.482,,0.000000e+000,3.499872e+001,6.643432e-006,0.000000e+000,3,8.940564e-001,0.000000e+000,,,,,,,,,,,,,,32,1,4.000000e+000,0.000000e+000,0.000000e+000,0,,0,
1524555913.452,,0.000000e+000,3.499911e+001,6.669833e-006,0.000000e+000,3,8.962677e-001,0.000000e+000,,,,,,,,,,,,,,32,1,4.000000e+000,7.820129e-004,0.000000e+000,0,,0,
1524555951.430,,0.000000e+000,3.499871e+001,6.664630e-006,0.000000e+000,3,8.953233e-001,0.000000e+000,,,,,,,,,,,,,,32,1,4.000000e+000,3.128052e-003,0.000000e+000,0,,0,
1524555989.516,,0.000000e+000,3.499950e+001,6.651153e-006,0.000000e+000,3,8.951758e-001,0.000000e+000,,,,,,,,,,,,,,32,1,4.000000e+000,1.560211e-003,0.000000e+000,0,,0,
1524556027.604,,0.000000e+000,3.499833e+001,6.666431e-006,0.000000e+000,3,8.954883e-001,0.000000e+000,,,,,,,,,,,,,,32,1,4.000000e+000,7.781982e-004,0.000000e+000,0,,0,
1524556065.682,,0.000000e+000,3.499989e+001,6.651937e-006,0.000000e+000,3,8.913001e-001,0.000000e+000,,,,,,,,,,,,,,32,1,4.000000e+000,2.342224e-003,0.000000e+000,0,,0,
1524556103.800,,0.000000e+000,3.500067e+001,6.680903e-006,0.000000e+000,3,8.934969e-001,0.000000e+000,,,,,,,,,,,,,,32,1,4.000000e+000,7.820129e-004,0.000000e+000,0,,0,
1524556141.858,,0.000000e+000,3.499989e+001,6.696853e-006,0.000000e+000,3,8.943831e-001,0.000000e+000,,,,,,,,,,,,,,32,1,4.000000e+000,2.342224e-003,0.000000e+000,0,,0,
1524556179.454,,0.000000e+000,3.499911e+001,6.680802e-006,0.000000e+000,3,8.919650e-001,0.000000e+000,,,,,,,,,,,,,,32,1,4.000000e+000,7.820129e-004,0.000000e+000,0,,0,
1524556217.554,,0.000000e+000,3.499833e+001,6.671029e-006,0.000000e+000,3,8.946856e-001,0.000000e+000,,,,,,,,,,,,,,32,1,4.000000e+000,7.781982e-004,0.000000e+000,0,,0,
1524556255.677,,0.000000e+000,3.499950e+001,6.699273e-006,0.000000e+000,3,8.955278e-001,0.000000e+000,,,,,,,,,,,,,,32,1,4.000000e+000,0.000000e+000,0.000000e+000,0,,0,
1524556292.875,,0.000000e+000,3.499872e+001,6.689364e-006,0.000000e+000,3,8.948759e-001,0.000000e+000,,,,,,,,,,,,,,32,1,4.000000e+000,0.000000e+000,0.000000e+000,0,,0,
1524556330.536,,0.000000e+000,3.499989e+001,6.710047e-006,0.000000e+000,3,8.944425e-001,0.000000e+000,,,,,,,,,,,,,,32,1,4.000000e+000,7.781982e-004,0.000000e+000,0,,0,
1524556368.619,,0.000000e+000,3.499872e+001,6.689673e-006,0.000000e+000,3,8.937124e-001,0.000000e+000,,,,,,,,,,,,,,32,1,4.000000e+000,0.000000e+000,0.000000e+000,0,,0,
1524556406.720,,0.000000e+000,3.499950e+001,6.662294e-006,0.000000e+000,3,8.973494e-001,0.000000e+000,,,,,,,,,,,,,,32,1,4.000000e+000,0.000000e+000,0.000000e+000,0,,0,
1524556444.713,,0.000000e+000,3.499911e+001,6.658577e-006,0.000000e+000,3,8.990831e-001,0.000000e+000,,,,,,,,,,,,,,32,1,4.000000e+000,7.820129e-004,0.000000e+000,0,,0,
1524556483.191,,0.000000e+000,3.499872e+001,6.734176e-006,0.000000e+000,3,8.953645e-001,0.000000e+000,,,,,,,,,,,,,,32,1,4.000000e+000,1.560211e-003,0.000000e+000,0,,0,
1524556521.276,,0.000000e+000,3.499911e+001,6.718441e-006,0.000000e+000,3,8.952596e-001,0.000000e+000,,,,,,,,,,,,,,32,1,4.000000e+000,7.820129e-004,0.000000e+000,0,,0,
1524556560.522,,0.000000e+000,3.499911e+001,6.734024e-006,0.000000e+000,3,8.939666e-001,0.000000e+000,,,,,,,,,,,,,,32,1,4.000000e+000,7.820129e-004,0.000000e+000,0,,0,
1524556598.770,,0.000000e+000,3.499989e+001,6.695100e-006,0.000000e+000,3,8.988485e-001,0.000000e+000,,,,,,,,,,,,,,32,1,4.000000e+000,2.342224e-003,0.000000e+000,0,,0,
1524556636.793,,0.000000e+000,3.499950e+001,6.697233e-006,0.000000e+000,3,8.991308e-001,0.000000e+000,,,,,,,,,,,,,,32,1,4.000000e+000,1.560211e-003,0.000000e+000,0,,0,
1524556675.234,,0.000000e+000,3.499793e+001,6.717429e-006,0.000000e+000,3,8.921085e-001,0.000000e+000,,,,,,,,,,,,,,32,1,4.000000e+000,1.567841e-003,0.000000e+000,0,,0,
1524556713.317,,0.000000e+000,3.499911e+001,6.751572e-006,0.000000e+000,3,8.944513e-001,0.000000e+000,,,,,,,,,,,,,,32,1,4.000000e+000,7.820129e-004,0.000000e+000,0,,0,
1524556751.075,,0.000000e+000,3.499950e+001,6.763847e-006,0.000000e+000,3,8.977542e-001,0.000000e+000,,,,,,,,,,,,,,32,1,4.000000e+000,0.000000e+000,0.000000e+000,0,,0,
1524556788.630,,0.000000e+000,3.499911e+001,6.738221e-006,0.000000e+000,3,8.966459e-001,0.000000e+000,,,,,,,,,,,,,,32,1,4.000000e+000,7.820129e-004,0.000000e+000,0,,0,
1524556826.276,,0.000000e+000,3.499833e+001,6.695966e-006,0.000000e+000,3,8.940008e-001,0.000000e+000,,,,,,,,,,,,,,32,1,4.000000e+000,7.781982e-004,0.000000e+000,0,,0,
1524556864.394,,0.000000e+000,3.499754e+001,6.725980e-006,0.000000e+000,3,8.941801e-001,0.000000e+000,,,,,,,,,,,,,,32,1,4.000000e+000,7.896423e-004,0.000000e+000,0,,0,
1524556901.979,,0.000000e+000,3.500028e+001,6.720126e-006,0.000000e+000,3,8.972401e-001,0.000000e+000,,,,,,,,,,,,,,32,1,4.000000e+000,1.560211e-003,0.000000e+000,0,,0,
1524556940.502,,0.000000e+000,3.499872e+001,6.734372e-006,0.000000e+000,3,8.965442e-001,0.000000e+000,,,,,,,,,,,,,,32,1,4.000000e+000,0.000000e+000,0.000000e+000,0,,0,
1524556978.173,,0.000000e+000,3.499833e+001,6.793827e-006,0.000000e+000,3,9.004257e-001,0.000000e+000,,,,,,,,,,,,,,32,1,4.000000e+000,7.781982e-004,0.000000e+000,0,,0,
1524557016.251,,0.000000e+000,3.499911e+001,6.743933e-006,0.000000e+000,3,8.976291e-001,0.000000e+000,,,,,,,,,,,,,,32,1,4.000000e+000,7.820129e-004,0.000000e+000,0,,0,
1524557054.797,,0.000000e+000,3.499911e+001,6.752833e-006,0.000000e+000,3,8.967432e-001,0.000000e+000,,,,,,,,,,,,,,32,1,4.000000e+000,7.820129e-004,0.000000e+000,0,,0,
1524557092.352,,0.000000e+000,3.499833e+001,6.740182e-006,0.000000e+000,3,8.994564e-001,0.000000e+000,,,,,,,,,,,,,,32,1,4.000000e+000,7.781982e-004,0.000000e+000,0,,0,
1524557130.455,,0.000000e+000,3.499950e+001,6.767478e-006,0.000000e+000,3,8.973817e-001,0.000000e+000,,,,,,,,,,,,,,32,1,4.000000e+000,1.560211e-003,0.000000e+000,0,,0,
1524557168.128,,0.000000e+000,3.499950e+001,6.750210e-006,0.000000e+000,3,8.952736e-001,0.000000e+000,,,,,,,,,,,,,,32,1,4.000000e+000,0.000000e+000,0.000000e+000,0,,0,
1524557206.219,,0.000000e+000,3.499872e+001,6.734514e-006,0.000000e+000,3,8.968083e-001,0.000000e+000,,,,,,,,,,,,,,32,1,4.000000e+000,1.560211e-003,0.000000e+000,0,,0,
1524557244.257,,0.000000e+000,3.499950e+001,6.738691e-006,0.000000e+000,3,8.966992e-001,0.000000e+000,,,,,,,,,,,,,,32,1,4.000000e+000,1.560211e-003,0.000000e+000,0,,0,
1524557282.337,,0.000000e+000,3.499637e+001,6.748088e-006,0.000000e+000,3,8.963420e-001,0.000000e+000,,,,,,,,,,,,,,32,1,4.000000e+000,0.000000e+000,0.000000e+000,0,,0,
1524557320.933,,0.000000e+000,3.499833e+001,6.786119e-006,0.000000e+000,3,8.956299e-001,0.000000e+000,,,,,,,,,,,,,,32,1,4.000000e+000,7.781982e-004,0.000000e+000,0,,0,
1524557358.126,,0.000000e+000,3.499872e+001,6.687376e-006,0.000000e+000,3,8.992043e-001,0.000000e+000,,,,,,,,,,,,,,32,1,4.000000e+000,0.000000e+000,0.000000e+000,0,,0,
1524557396.202,,0.000000e+000,3.499911e+001,6.744099e-006,0.000000e+000,3,8.975469e-001,0.000000e+000,,,,,,,,,,,,,,32,1,4.000000e+000,7.820129e-004,0.000000e+000,0,,0,
1524557434.305,,0.000000e+000,3.499911e+001,6.719123e-006,0.000000e+000,3,8.954048e-001,0.000000e+000,,,,,,,,,,,,,,32,1,4.000000e+000,7.820129e-004,0.000000e+000,0,,0,
1524557472.160,,0.000000e+000,3.499911e+001,6.733563e-006,0.000000e+000,3,8.958338e-001,0.000000e+000,,,,,,,,,,,,,,32,1,4.000000e+000,7.820129e-004,0.000000e+000,0,,0,
1524557509.721,,0.000000e+000,3.500028e+001,6.763062e-006,0.000000e+000,3,8.960309e-001,0.000000e+000,,,,,,,,,,,,,,32,1,4.000000e+000,1.560211e-003,0.000000e+000,0,,0,
1524557547.566,,0.000000e+000,3.499833e+001,6.789368e-006,0.000000e+000,3,8.958105e-001,0.000000e+000,,,,,,,,,,,,,,32,1,4.000000e+000,7.781982e-004,0.000000e+000,0,,0,
1524557585.674,,0.000000e+000,3.499950e+001,6.774603e-006,0.000000e+000,3,8.901044e-001,0.000000e+000,,,,,,,,,,,,,,32,1,4.000000e+000,1.560211e-003,0.000000e+000,0,,0,
1524557623.700,,0.000000e+000,3.500067e+001,6.715744e-006,0.000000e+000,3,8.983306e-001,0.000000e+000,,,,,,,,,,,,,,32,1,4.000000e+000,2.338409e-003,0.000000e+000,0,,0,
1524557661.243,,0.000000e+000,3.499950e+001,6.765486e-006,0.000000e+000,3,8.954271e-001,0.000000e+000,,,,,,,,,,,,,,32,1,4.000000e+000,1.560211e-003,0.000000e+000,0,,0,
1524557700.381,,0.000000e+000,3.499872e+001,6.726004e-006,0.000000e+000,3,8.939919e-001,0.000000e+000,,,,,,,,,,,,,,32,1,4.000000e+000,1.560211e-003,0.000000e+000,0,,0,
1524557738.799,,0.000000e+000,3.499872e+001,6.762618e-006,0.000000e+000,3,8.994025e-001,0.000000e+000,,,,,,,,,,,,,,32,1,4.000000e+000,1.560211e-003,0.000000e+000,0,,0,
1524557776.862,,0.000000e+000,3.499989e+001,6.789619e-006,0.000000e+000,3,8.983323e-001,0.000000e+000,,,,,,,,,,,,,,32,1,4.000000e+000,7.781982e-004,0.000000e+000,0,,0,
1524557814.805,,0.000000e+000,3.499832e+001,6.778570e-006,0.000000e+000,3,8.964536e-001,0.000000e+000,,,,,,,,,,,,,,32,1,4.000000e+000,3.910065e-003,0.000000e+000,0,,0,
1524557853.256,,0.000000e+000,3.500106e+001,6.808099e-006,0.000000e+000,3,8.990080e-001,0.000000e+000,,,,,,,,,,,,,,32,1,4.000000e+000,1.560211e-003,0.000000e+000,0,,0,
1524557891.224,,0.000000e+000,3.499872e+001,6.750332e-006,0.000000e+000,3,8.932596e-001,0.000000e+000,,,,,,,,,,,,,,32,1,4.000000e+000,0.000000e+000,0.000000e+000,0,,0,
1524557929.322,,0.000000e+000,3.500106e+001,6.798538e-006,0.000000e+000,3,8.954663e-001,0.000000e+000,,,,,,,,,,,,,,32,1,4.000000e+000,4.692078e-003,0.000000e+000,0,,0,
1524557967.745,,0.000000e+000,3.499950e+001,6.786678e-006,0.000000e+000,3,8.961986e-001,0.000000e+000,,,,,,,,,,,,,,32,1,4.000000e+000,0.000000e+000,0.000000e+000,0,,0,
1524558004.978,,0.000000e+000,3.499950e+001,6.812199e-006,0.000000e+000,3,8.956794e-001,0.000000e+000,,,,,,,,,,,,,,32,1,4.000000e+000,0.000000e+000,0.000000e+000,0,,0,
1524558043.004,,0.000000e+000,3.499833e+001,6.808033e-006,0.000000e+000,3,8.959706e-001,0.000000e+000,,,,,,,,,,,,,,32,1,4.000000e+000,7.781982e-004,0.000000e+000,0,,0,
1524558080.952,,0.000000e+000,3.500028e+001,6.814935e-006,0.000000e+000,3,8.932788e-001,0.000000e+000,,,,,,,,,,,,,,32,1,4.000000e+000,1.560211e-003,0.000000e+000,0,,0,
1524558118.730,,0.000000e+000,3.499911e+001,6.835035e-006,0.000000e+000,3,8.987213e-001,0.000000e+000,,,,,,,,,,,,,,32,1,4.000000e+000,7.820129e-004,0.000000e+000,0,,0,
1524558156.070,,0.000000e+000,3.499872e+001,6.819971e-006,0.000000e+000,3,8.991948e-001,0.000000e+000,,,,,,,,,,,,,,32,1,4.000000e+000,1.560211e-003,0.000000e+000,0,,0,
1524558194.643,,0.000000e+000,3.499989e+001,6.824242e-006,0.000000e+000,3,8.937297e-001,0.000000e+000,,,,,,,,,,,,,,32,1,4.000000e+000,7.781982e-004,0.000000e+000,0,,0,
1524558232.701,,0.000000e+000,3.499833e+001,6.775725e-006,0.000000e+000,3,8.977296e-001,0.000000e+000,,,,,,,,,,,,,,32,1,4.000000e+000,7.781982e-004,0.000000e+000,0,,0,
1524558270.502,,0.000000e+000,3.499989e+001,6.835447e-006,0.000000e+000,3,8.970383e-001,0.000000e+000,,,,,,,,,,,,,,32,1,4.000000e+000,2.342224e-003,0.000000e+000,0,,0,
1524558308.368,,0.000000e+000,3.499950e+001,6.786589e-006,0.000000e+000,3,8.938877e-001,0.000000e+000,,,,,,,,,,,,,,32,1,4.000000e+000,3.120422e-003,0.000000e+000,0,,0,
1524558346.808,,0.000000e+000,3.499911e+001,6.853653e-006,0.000000e+000,3,8.953087e-001,0.000000e+000,,,,,,,,,,,,,,32,1,4.000000e+000,7.820129e-004,0.000000e+000,0,,0,
1524558385.444,,0.000000e+000,3.499989e+001,6.875704e-006,0.000000e+000,3,8.958692e-001,0.000000e+000,,,,,,,,,,,,,,32,1,4.000000e+000,3.898621e-003,0.000000e+000,0,,0,
1524558424.124,,0.000000e+000,3.499911e+001,6.819896e-006,0.000000e+000,3,8.980445e-001,0.000000e+000,,,,,,,,,,,,,,32,1,4.000000e+000,7.820129e-004,0.000000e+000,0,,0,
1524558461.312,,0.000000e+000,3.499950e+001,6.809940e-006,0.000000e+000,3,9.001242e-001,0.000000e+000,,,,,,,,,,,,,,32,1,4.000000e+000,1.560211e-003,0.000000e+000,0,,0,
1524558499.760,,0.000000e+000,3.499754e+001,6.807971e-006,0.000000e+000,3,8.974437e-001,0.000000e+000,,,,,,,,,,,,,,32,1,4.000000e+000,2.349854e-003,0.000000e+000,0,,0,
1524558537.326,,0.000000e+000,3.499911e+001,6.795901e-006,0.000000e+000,3,8.969838e-001,0.000000e+000,,,,,,,,,,,,,,32,1,4.000000e+000,2.338409e-003,0.000000e+000,0,,0,
1524558575.524,,0.000000e+000,3.499833e+001,6.845076e-006,0.000000e+000,3,8.946632e-001,0.000000e+000,,,,,,,,,,,,,,32,1,4.000000e+000,7.781982e-004,0.000000e+000,0,,0,
1524558613.679,,0.000000e+000,3.499872e+001,6.807569e-006,0.000000e+000,3,8.990030e-001,0.000000e+000,,,,,,,,,,,,,,32,1,4.000000e+000,1.560211e-003,0.000000e+000,0,,0,
1524558652.310,,0.000000e+000,3.500067e+001,6.854641e-006,0.000000e+000,3,8.972829e-001,0.000000e+000,,,,,,,,,,,,,,32,1,4.000000e+000,7.820129e-004,0.000000e+000,0,,0,
1524558690.483,,0.000000e+000,3.499715e+001,6.870400e-006,0.000000e+000,3,8.935381e-001,0.000000e+000,,,,,,,,,,,,,,32,1,4.000000e+000,3.128052e-003,0.000000e+000,0,,0,
1524558728.434,,0.000000e+000,3.499872e+001,6.869762e-006,0.000000e+000,3,8.982273e-001,0.000000e+000,,,,,,,,,,,,,,32,1,4.000000e+000,1.560211e-003,0.000000e+000,0,,0,
1524558766.424,,0.000000e+000,3.499950e+001,6.880980e-006,0.000000e+000,3,8.960063e-001,0.000000e+000,,,,,,,,,,,,,,32,1,4.000000e+000,0.000000e+000,0.000000e+000,0,,0,
1524558804.975,,0.000000e+000,3.499793e+001,6.858369e-006,0.000000e+000,3,8.947586e-001,0.000000e+000,,,,,,,,,,,,,,32,1,4.000000e+000,1.567841e-003,0.000000e+000,0,,0,
1524558843.065,,0.000000e+000,3.500028e+001,6.865054e-006,0.000000e+000,3,8.967000e-001,0.000000e+000,,,,,,,,,,,,,,32,1,4.000000e+000,3.120422e-003,0.000000e+000,0,,0,
1524558880.851,,0.000000e+000,3.500028e+001,6.848262e-006,0.000000e+000,3,8.944609e-001,0.000000e+000,,,,,,,,,,,,,,32,1,4.000000e+000,0.000000e+000,0.000000e+000,0,,0,
1524558918.602,,0.000000e+000,3.499911e+001,6.867427e-006,0.000000e+000,3,8.971153e-001,0.000000e+000,,,,,,,,,,,,,,32,1,4.000000e+000,3.910065e-003,0.000000e+000,0,,0,
1524558956.897,,0.000000e+000,3.499794e+001,6.850609e-006,0.000000e+000,3,8.964680e-001,0.000000e+000,,,,,,,,,,,,,,32,1,4.000000e+000,0.000000e+000,0.000000e+000,0,,0,
1524558994.388,,0.000000e+000,3.499950e+001,6.860002e-006,0.000000e+000,3,8.931056e-001,0.000000e+000,,,,,,,,,,,,,,32,1,4.000000e+000,0.000000e+000,0.000000e+000,0,,0,
1524559032.536,,0.000000e+000,3.499911e+001,6.866980e-006,0.000000e+000,3,8.975710e-001,0.000000e+000,,,,,,,,,,,,,,32,1,4.000000e+000,7.820129e-004,0.000000e+000,0,,0,
1524559070.631,,0.000000e+000,3.499989e+001,6.961082e-006,0.000000e+000,3,8.996240e-001,0.000000e+000,,,,,,,,,,,,,,32,1,4.000000e+000,2.342224e-003,0.000000e+000,0,,0,
1524559107.944,,0.000000e+000,3.499793e+001,6.854555e-006,0.000000e+000,3,8.886013e-001,0.000000e+000,,,,,,,,,,,,,,32,1,4.000000e+000,3.131866e-003,0.000000e+000,0,,0,
1524559146.932,,0.000000e+000,3.499871e+001,6.876938e-006,0.000000e+000,3,8.964427e-001,0.000000e+000,,,,,,,,,,,,,,32,1,4.000000e+000,3.128052e-003,0.000000e+000,0,,0,
1524559185.150,,0.000000e+000,3.499872e+001,6.888587e-006,0.000000e+000,3,8.974293e-001,0.000000e+000,,,,,,,,,,,,,,32,1,4.000000e+000,0.000000e+000,0.000000e+000,0,,0,
1524559223.393,,0.000000e+000,3.499950e+001,6.843233e-006,0.000000e+000,3,8.965116e-001,0.000000e+000,,,,,,,,,,,,,,32,1,4.000000e+000,1.560211e-003,0.000000e+000,0,,0,
1524559261.539,,0.000000e+000,3.499677e+001,6.878754e-006,0.000000e+000,3,8.987294e-001,0.000000e+000,,,,,,,,,,,,,,32,1,4.000000e+000,5.470276e-003,0.000000e+000,0,,0,
1524559299.287,,0.000000e+000,3.499793e+001,6.877657e-006,0.000000e+000,3,8.976006e-001,0.000000e+000,,,,,,,,,,,,,,32,1,4.000000e+000,1.567841e-003,0.000000e+000,0,,0,
1524559337.588,,0.000000e+000,3.499911e+001,6.907037e-006,0.000000e+000,3,8.986750e-001,0.000000e+000,,,,,,,,,,,,,,32,1,4.000000e+000,7.820129e-004,0.000000e+000,0,,0,
1524559375.271,,0.000000e+000,3.499950e+001,6.878751e-006,0.000000e+000,3,8.982370e-001,0.000000e+000,,,,,,,,,,,,,,32,1,4.000000e+000,0.000000e+000,0.000000e+000,0,,0,
1524559413.519,,0.000000e+000,3.499911e+001,6.910305e-006,0.000000e+000,3,8.969112e-001,0.000000e+000,,,,,,,,,,,,,,32,1,4.000000e+000,7.820129e-004,0.000000e+000,0,,0,
1524559451.652,,0.000000e+000,3.499989e+001,6.877504e-006,0.000000e+000,3,8.936383e-001,0.000000e+000,,,,,,,,,,,,,,32,1,4.000000e+000,2.342224e-003,0.000000e+000,0,,0,
1524559489.422,,0.000000e+000,3.499833e+001,6.900189e-006,0.000000e+000,3,8.953959e-001,0.000000e+000,,,,,,,,,,,,,,32,1,4.000000e+000,7.781982e-004,0.000000e+000,0,,0,
1524559527.273,,0.000000e+000,3.499598e+001,6.925365e-006,0.000000e+000,3,8.961809e-001,0.000000e+000,,,,,,,,,,,,,,32,1,4.000000e+000,7.041931e-003,0.000000e+000,0,,0,
1524559565.098,,0.000000e+000,3.500146e+001,6.912459e-006,0.000000e+000,3,8.983906e-001,0.000000e+000,,,,,,,,,,,,,,32,1,4.000000e+000,3.910065e-003,0.000000e+000,0,,0,
1524559602.779,,0.000000e+000,3.499950e+001,6.898552e-006,0.000000e+000,3,8.970993e-001,0.000000e+000,,,,,,,,,,,,,,32,1,4.000000e+000,1.560211e-003,0.000000e+000,0,,0,
1524559640.867,,0.000000e+000,3.499833e+001,6.926585e-006,0.000000e+000,3,8.976079e-001,0.000000e+000,,,,,,,,,,,,,,32,1,4.000000e+000,2.349854e-003,0.000000e+000,0,,0,
1524559679.188,,0.000000e+000,3.500028e+001,6.916784e-006,0.000000e+000,3,9.008177e-001,0.000000e+000,,,,,,,,,,,,,,32,1,4.000000e+000,0.000000e+000,0.000000e+000,0,,0,
1524559716.838,,0.000000e+000,3.499715e+001,6.912502e-006,0.000000e+000,3,8.985004e-001,0.000000e+000,,,,,,,,,,,,,,32,1,4.000000e+000,1.571655e-003,0.000000e+000,0,,0,
1524559754.256,,0.000000e+000,3.499872e+001,6.914353e-006,0.000000e+000,3,8.990351e-001,0.000000e+000,,,,,,,,,,,,,,32,1,4.000000e+000,0.000000e+000,0.000000e+000,0,,0,
1524559792.382,,0.000000e+000,3.499989e+001,6.951165e-006,0.000000e+000,3,8.987987e-001,0.000000e+000,,,,,,,,,,,,,,32,1,4.000000e+000,3.898621e-003,0.000000e+000,0,,0,
1524559830.595,,0.000000e+000,3.499871e+001,6.903375e-006,0.000000e+000,3,8.989403e-001,0.000000e+000,,,,,,,,,,,,,,32,1,4.000000e+000,3.128052e-003,0.000000e+000,0,,0,
1524559869.036,,0.000000e+000,3.499833e+001,6.941618e-006,0.000000e+000,3,8.959329e-001,0.000000e+000,,,,,,,,,,,,,,32,1,4.000000e+000,2.349854e-003,0.000000e+000,0,,0,
1524559907.159,,0.000000e+000,3.499872e+001,6.908943e-006,0.000000e+000,3,8.949542e-001,0.000000e+000,,,,,,,,,,,,,,32,1,4.000000e+000,1.560211e-003,0.000000e+000,0,,0,
1524559945.249,,0.000000e+000,3.499871e+001,6.921854e-006,0.000000e+000,3,8.976296e-001,0.000000e+000,,,,,,,,,,,,,,32,1,4.000000e+000,3.128052e-003,0.000000e+000,0,,0,
1524559983.317,,0.000000e+000,3.499794e+001,6.987416e-006,0.000000e+000,3,9.011664e-001,0.000000e+000,,,,,,,,,,,,,,32,1,4.000000e+000,0.000000e+000,0.000000e+000,0,,0,
1524560021.185,,0.000000e+000,3.500028e+001,6.928234e-006,0.000000e+000,3,8.923109e-001,0.000000e+000,,,,,,,,,,,,,,32,1,4.000000e+000,1.560211e-003,0.000000e+000,0,,0,
1524560058.991,,0.000000e+000,3.499950e+001,6.891247e-006,0.000000e+000,3,8.974999e-001,0.000000e+000,,,,,,,,,,,,,,32,1,4.000000e+000,1.560211e-003,0.000000e+000,0,,0,
1524560097.066,,0.000000e+000,3.499793e+001,6.921658e-006,0.000000e+000,3,8.979358e-001,0.000000e+000,,,,,,,,,,,,,,32,1,4.000000e+000,3.131866e-003,0.000000e+000,0,,0,
1524560135.772,,0.000000e+000,3.499911e+001,6.927040e-006,0.000000e+000,3,8.998367e-001,0.000000e+000,,,,,,,,,,,,,,32,1,4.000000e+000,7.820129e-004,0.000000e+000,0,,0,
1524560173.537,,0.000000e+000,3.499833e+001,6.915358e-006,0.000000e+000,3,8.993095e-001,0.000000e+000,,,,,,,,,,,,,,32,1,4.000000e+000,7.781982e-004,0.000000e+000,0,,0,
1524560211.648,,0.000000e+000,3.499872e+001,6.918377e-006,0.000000e+000,3,8.972940e-001,0.000000e+000,,,,,,,,,,,,,,32,1,4.000000e+000,1.560211e-003,0.000000e+000,0,,0,
1524560249.726,,0.000000e+000,3.499950e+001,6.903604e-006,0.000000e+000,3,9.010707e-001,0.000000e+000,,,,,,,,,,,,,,32,1,4.000000e+000,0.000000e+000,0.000000e+000,0,,0,
1524560288.222,,0.000000e+000,3.499833e+001,6.918573e-006,0.000000e+000,3,8.997831e-001,0.000000e+000,,,,,,,,,,,,,,32,1,4.000000e+000,7.781982e-004,0.000000e+000,0,,0,
1524560326.085,,0.000000e+000,3.499989e+001,6.900870e-006,0.000000e+000,3,8.982175e-001,0.000000e+000,,,,,,,,,,,,,,32,1,4.000000e+000,7.781982e-004,0.000000e+000,0,,0,
1524560364.208,,0.000000e+000,3.500106e+001,6.918393e-006,0.000000e+000,3,8.976579e-001,0.000000e+000,,,,,,,,,,,,,,32,1,4.000000e+000,3.128052e-003,0.000000e+000,0,,0,
1524560402.381,,0.000000e+000,3.499950e+001,6.940326e-006,0.000000e+000,3,8.987826e-001,0.000000e+000,,,,,,,,,,,,,,32,1,4.000000e+000,0.000000e+000,0.000000e+000,0,,0,
1524560441.029,,0.000000e+000,3.499872e+001,6.936346e-006,0.000000e+000,3,8.969042e-001,0.000000e+000,,,,,,,,,,,,,,32,1,4.000000e+000,0.000000e+000,0.000000e+000,0,,0,
1524560478.607,,0.000000e+000,3.500028e+001,6.925134e-006,0.000000e+000,3,8.964846e-001,0.000000e+000,,,,,,,,,,,,,,32,1,4.000000e+000,3.120422e-003,0.000000e+000,0,,0,
1524560516.030,,0.000000e+000,3.499794e+001,6.934086e-006,0.000000e+000,3,8.911591e-001,0.000000e+000,,,,,,,,,,,,,,32,1,4.000000e+000,0.000000e+000,0.000000e+000,0,,0,
1524560554.151,,0.000000e+000,3.499754e+001,6.958979e-006,0.000000e+000,3,9.013724e-001,0.000000e+000,,,,,,,,,,,,,,32,1,4.000000e+000,7.896423e-004,0.000000e+000,0,,0,
1524560592.354,,0.000000e+000,3.499754e+001,6.935080e-006,0.000000e+000,3,8.975422e-001,0.000000e+000,,,,,,,,,,,,,,32,1,4.000000e+000,3.910065e-003,0.000000e+000,0,,0,
1524560630.454,,0.000000e+000,3.499989e+001,6.949626e-006,0.000000e+000,3,8.941332e-001,0.000000e+000,,,,,,,,,,,,,,32,1,4.000000e+000,7.781982e-004,0.000000e+000,0,,0,
1524560668.592,,0.000000e+000,3.499989e+001,6.953905e-006,0.000000e+000,3,8.972338e-001,0.000000e+000,,,,,,,,,,,,,,32,1,4.000000e+000,7.781982e-004,0.000000e+000,0,,0,
1524560706.633,,0.000000e+000,3.499872e+001,6.949971e-006,0.000000e+000,3,8.985136e-001,0.000000e+000,,,,,,,,,,,,,,32,1,4.000000e+000,0.000000e+000,0.000000e+000,0,,0,
1524560744.791,,0.000000e+000,3.499950e+001,6.934000e-006,0.000000e+000,3,8.962742e-001,0.000000e+000,,,,,,,,,,,,,,32,1,4.000000e+000,1.560211e-003,0.000000e+000,0,,0,
1524560782.879,,0.000000e+000,3.499950e+001,6.962556e-006,0.000000e+000,3,8.974211e-001,0.000000e+000,,,,,,,,,,,,,,32,1,4.000000e+000,0.000000e+000,0.000000e+000,0,,0,
1524560820.957,,0.000000e+000,3.499911e+001,6.960459e-006,0.000000e+000,3,8.976820e-001,0.000000e+000,,,,,,,,,,,,,,32,1,4.000000e+000,7.820129e-004,0.000000e+000,0,,0,
1524560859.055,,0.000000e+000,3.499950e+001,6.949354e-006,0.000000e+000,3,8.969568e-001,0.000000e+000,,,,,,,,,,,,,,32,1,4.000000e+000,0.000000e+000,0.000000e+000,0,,0,
1524560897.128,,0.000000e+000,3.499793e+001,6.936873e-006,0.000000e+000,3,8.991265e-001,0.000000e+000,,,,,,,,,,,,,,32,1,4.000000e+000,3.131866e-003,0.000000e+000,0,,0,
1524560935.231,,0.000000e+000,3.499950e+001,6.947238e-006,0.000000e+000,3,8.949457e-001,0.000000e+000,,,,,,,,,,,,,,32,1,4.000000e+000,0.000000e+000,0.000000e+000,0,,0,
1524560972.809,,0.000000e+000,3.499872e+001,6.961833e-006,0.000000e+000,3,8.968780e-001,0.000000e+000,,,,,,,,,,,,,,32,1,4.000000e+000,1.560211e-003,0.000000e+000,0,,0,
1524561010.692,,0.000000e+000,3.499950e+001,6.983497e-006,0.000000e+000,3,8.967760e-001,0.000000e+000,,,,,,,,,,,,,,32,1,4.000000e+000,1.560211e-003,0.000000e+000,0,,0,
1524561049.828,,0.000000e+000,3.499989e+001,6.935958e-006,0.000000e+000,3,8.989285e-001,0.000000e+000,,,,,,,,,,,,,,32,1,4.000000e+000,7.781982e-004,0.000000e+000,0,,0,
1524561087.828,,0.000000e+000,3.499871e+001,6.943075e-006,0.000000e+000,3,8.998705e-001,0.000000e+000,,,,,,,,,,,,,,32,1,4.000000e+000,3.128052e-003,0.000000e+000,0,,0,
1524561125.991,,0.000000e+000,3.499911e+001,6.964670e-006,0.000000e+000,3,8.975335e-001,0.000000e+000,,,,,,,,,,,,,,32,1,4.000000e+000,7.820129e-004,0.000000e+000,0,,0,
1524561164.024,,0.000000e+000,3.500106e+001,6.970314e-006,0.000000e+000,3,9.018291e-001,0.000000e+000,,,,,,,,,,,,,,32,1,4.000000e+000,0.000000e+000,0.000000e+000,0,,0,
1524561202.600,,0.000000e+000,3.500028e+001,6.973108e-006,0.000000e+000,3,8.987946e-001,0.000000e+000,,,,,,,,,,,,,,32,1,4.000000e+000,1.560211e-003,0.000000e+000,0,,0,
1524561241.058,,0.000000e+000,3.499950e+001,6.987859e-006,0.000000e+000,3,8.950077e-001,0.000000e+000,,,,,,,,,,,,,,32,1,4.000000e+000,0.000000e+000,0.000000e+000,0,,0,
1524561278.941,,0.000000e+000,3.499989e+001,6.970008e-006,0.000000e+000,3,9.023083e-001,0.000000e+000,,,,,,,,,,,,,,32,1,4.000000e+000,7.781982e-004,0.000000e+000,0,,0,
1524561316.789,,0.000000e+000,3.499989e+001,6.987843e-006,0.000000e+000,3,8.987526e-001,0.000000e+000,,,,,,,,,,,,,,32,1,4.000000e+000,7.781982e-004,0.000000e+000,0,,0,
1524561329.229,,0.000000e+000,3.499872e+001,6.959234e-006,0.000000e+000,3,8.910382e-001,0.000000e+000,,,,,,,,,,,,,,32,1,4.000000e+000,0.000000e+000,0.000000e+000,0,,0,