File: Input/TC04-12-01K-01_Hysteresis.dat
[Header]
TITLE,MPMS DC Measurement
BYAPP,MPMS Measurement,2.1,Summary
FILEOPENTIME, 1455897616.221000 2/19/2016, 10:00:16 AM

INFO, APPNAME, MPMS MultiVu Application, Revision 1.61,  Build 082

INFO, NAME, TC04-12-01K-01
INFO, WEIGHT, 0.000
INFO, AREA, 0.000
INFO, LENGTH, 0.000
INFO, SHAPE,
INFO, COMMENT,
INFO, SEQUENCE FILE: Hysteresis_30K_250K.seq


INFO, BACKGROUND DATA FILE:, None


STARTUPAXIS,X,4,LINEAR,AUTO,0.000000,0.000000
STARTUPAXIS,Y1,5,LINEAR,AUTO,0.000000,0.000000


STARTUPGROUP,Longitudinal
FIELDGROUP,Longitudinal,1,2,3,4,5,6,7,8,9,15,16,17,18,27,28
FIELDGROUP,Transverse,1,2,3,4,10,11,12,13,14,19,20,21,22,27,28

PLOT_APPEARANCE,ALL,HORZ_GRID_ON,VERT_GRID_ON,MARKERS_AND_LINES

[Data]
Time,Comment,Field (Oe),Temperature (K),Long Moment (emu),Long Scan Std Dev,Long Algorithm,Long Reg Fit,Long Percent Error (%),Trans Moment (emu),Trans Scan Std Dev,Trans Algorithm,Trans Reg Fit,Trans Percent Error (%),Long Moment [w/o ABS] (emu),Long Scan Std Dev [w/o ABS],Long Reg Fit [w/o ABS],Long Percent Error [w/o ABS] (%),Trans Moment [w/o ABS] (emu),Trans Scan Std Dev [w/o ABS],Trans Reg Fit [w/o ABS],Trans Percent Error [w/o ABS] (%),Points per Scan,Scans per Measurement,Scan Length (cm),Delta Temp (K),Rot Position (deg),Error,EC Comp. Running,Using ABS,
1455897616.221,,-2.509862e+004,3.000128e+001,-4.678014e-002,0.000000e+000,3,9.504421e-001,0.000000e+000,,,,,,,,,,,,,,32,1,4.000000e+000,0.000000e+000,0.000000e+000,0,,0,
1455897706.411,,-2.108293e+004,2.999958e+001,-4.358893e-002,0.000000e+000,3,9.485506e-001,0.000000e+000,,,,,,,,,,,,,,32,1,4.000000e+000,4.529953e-003,0.000000e+000,0,,0,
1455897796.311,,-1.706778e+004,2.999873e+001,-4.021100e-002,0.000000e+000,3,9.482760e-001,0.000000e+000,,,,,,,,,,,,,,32,1,4.000000e+000,5.090714e-003,0.000000e+000,0,,0,
1455897886.571,,-1.305265e+004,2.999902e+001,-3.679235e-002,0.000000e+000,3,9.481585e-001,0.000000e+000,,,,,,,,,,,,,,32,1,4.000000e+000,5.661011e-003,0.000000e+000,0,,0,
1455897976.641,,-9.039819e+003,2.999987e+001,-3.327968e-002,0.000000e+000,3,9.475006e-001,0.000000e+000,,,,,,,,,,,,,,32,1,4.000000e+000,3.959656e-003,0.000000e+000,0,,0,
1455898066.101,,-5.027213e+003,2.999902e+001,-2.943434e-002,0.000000e+000,3,9.464334e-001,0.000000e+000,,,,,,,,,,,,,,32,1,4.000000e+000,4.520416e-003,0.000000e+000,0,,0,
1455898166.892,,-1.011302e+003,3.000015e+001,-2.085239e-002,0.000000e+000,3,9.451776e-001,0.000000e+000,,,,,,,,,,,,,,32,1,4.000000e+000,2.260208e-003,0.000000e+000,0,,0,
1455898275.612,,3.019368e+003,2.999987e+001,2.654609e-002,0.000000e+000,3,9.523864e-001,0.000000e+000,,,,,,,,,,,,,,32,1,4.000000e+000,2.819061e-003,0.000000e+000,0,,0,
1455898365.582,,7.036160e+003,2.999902e+001,3.111641e-002,0.000000e+000,3,9.515848e-001,0.000000e+000,,,,,,,,,,,,,,32,1,4.000000e+000,2.260208e-003,0.000000e+000,0,,0,
1455898455.682,,1.105009e+004,2.999902e+001,3.482928e-002,0.000000e+000,3,9.507801e-001,0.000000e+000,,,,,,,,,,,,,,32,1,4.000000e+000,3.398895e-003,0.000000e+000,0,,0,
1455898545.782,,1.506490e+004,2.999874e+001,3.835535e-002,0.000000e+000,3,9.502342e-001,0.000000e+000,,,,,,,,,,,,,,32,1,4.000000e+000,3.959656e-003,0.000000e+000,0,,0,
1455898635.892,,1.907894e+004,2.999902e+001,4.177382e-002,0.000000e+000,3,9.500568e-001,0.000000e+000,,,,,,,,,,,,,,32,1,4.000000e+000,3.398895e-003,0.000000e+000,0,,0,
1455898726.152,,2.309297e+004,2.999931e+001,4.516421e-002,0.000000e+000,3,9.497990e-001,0.000000e+000,,,,,,,,,,,,,,32,1,4.000000e+000,1.689911e-003,0.000000e+000,0,,0,
1455899302.575,,-2.409855e+004,3.999856e+001,-4.097947e-002,0.000000e+000,3,9.473894e-001,0.000000e+000,,,,,,,,,,,,,,32,1,4.000000e+000,3.101349e-003,0.000000e+000,0,,0,
1455899392.445,,-2.008286e+004,3.999805e+001,-3.858241e-002,0.000000e+000,3,9.483884e-001,0.000000e+000,,,,,,,,,,,,,,32,1,4.000000e+000,6.191254e-003,0.000000e+000,0,,0,
1455899480.955,,-1.606717e+004,3.999908e+001,-3.602909e-002,0.000000e+000,3,9.481890e-001,0.000000e+000,,,,,,,,,,,,,,32,1,4.000000e+000,4.131317e-003,0.000000e+000,0,,0,
1455899569.976,,-1.205214e+004,3.999960e+001,-3.336241e-002,0.000000e+000,3,9.475569e-001,0.000000e+000,,,,,,,,,,,,,,32,1,4.000000e+000,1.029968e-003,0.000000e+000,0,,0,
1455899659.456,,-8.036891e+003,4.000011e+001,-3.068335e-002,0.000000e+000,3,9.474714e-001,0.000000e+000,,,,,,,,,,,,,,32,1,4.000000e+000,0.000000e+000,0.000000e+000,0,,0,
1455899747.046,,-4.020647e+003,3.999908e+001,-2.742057e-002,0.000000e+000,3,9.461242e-001,0.000000e+000,,,,,,,,,,,,,,32,1,4.000000e+000,2.059937e-003,0.000000e+000,0,,0,
1455899847.016,,-3.083909e+000,3.999701e+001,-7.115867e-003,0.000000e+000,3,9.597103e-001,0.000000e+000,,,,,,,,,,,,,,32,1,4.000000e+000,0.000000e+000,0.000000e+000,0,,0,
1455899967.986,,4.021198e+003,3.999805e+001,2.713199e-002,0.000000e+000,3,9.516439e-001,0.000000e+000,,,,,,,,,,,,,,32,1,4.000000e+000,4.131317e-003,0.000000e+000,0,,0,
1455900059.076,,8.037547e+003,3.999805e+001,3.041816e-002,0.000000e+000,3,9.511982e-001,0.000000e+000,,,,,,,,,,,,,,32,1,4.000000e+000,2.071381e-003,0.000000e+000,0,,0,
1455900148.196,,1.205258e+004,3.999805e+001,3.317318e-002,0.000000e+000,3,9.504409e-001,0.000000e+000,,,,,,,,,,,,,,32,1,4.000000e+000,0.000000e+000,0.000000e+000,0,,0,
1455900236.376,,1.606662e+004,3.999960e+001,3.586748e-002,0.000000e+000,3,9.501383e-001,0.000000e+000,,,,,,,,,,,,,,32,1,4.000000e+000,1.029968e-003,0.000000e+000,0,,0,
1455900327.547,,2.008286e+004,3.999908e+001,3.850484e-002,0.000000e+000,3,9.498824e-001,0.000000e+000,,,,,,,,,,,,,,32,1,4.000000e+000,2.059937e-003,0.000000e+000,0,,0,
1455900417.027,,2.409855e+004,3.999857e+001,4.104935e-002,0.000000e+000,3,9.496862e-001,0.000000e+000,,,,,,,,,,,,,,32,1,4.000000e+000,1.029968e-003,0.000000e+000,0,,0,
1455900943.429,,-2.309188e+004,4.999769e+001,-3.713562e-002,0.000000e+000,3,9.525297e-001,0.000000e+000,,,,,,,,,,,,,,32,1,4.000000e+000,6.580353e-003,0.000000e+000,0,,0,
1455901032.410,,-1.907839e+004,5.000098e+001,-3.547785e-002,0.000000e+000,3,9.476002e-001,0.000000e+000,,,,,,,,,,,,,,32,1,4.000000e+000,3.292084e-003,0.000000e+000,0,,0,
1455901123.370,,-1.506380e+004,4.999934e+001,-3.340400e-002,0.000000e+000,3,9.479937e-001,0.000000e+000,,,,,,,,,,,,,,32,1,4.000000e+000,3.292084e-003,0.000000e+000,0,,0,
1455901213.930,,-1.104964e+004,4.999686e+001,-3.128192e-002,0.000000e+000,3,9.474809e-001,0.000000e+000,,,,,,,,,,,,,,32,1,4.000000e+000,4.928589e-003,0.000000e+000,0,,0,
1455901304.820,,-7.035499e+003,5.000015e+001,-2.898554e-002,0.000000e+000,3,9.470562e-001,0.000000e+000,,,,,,,,,,,,,,32,1,4.000000e+000,4.932404e-003,0.000000e+000,0,,0,
1455901395.260,,-3.018817e+003,4.999769e+001,-2.583702e-002,0.000000e+000,3,9.461688e-001,0.000000e+000,,,,,,,,,,,,,,32,1,4.000000e+000,6.580353e-003,0.000000e+000,0,,0,
1455901492.960,,1.011633e+003,5.000098e+001,1.927054e-002,0.000000e+000,3,9.521767e-001,0.000000e+000,,,,,,,,,,,,,,32,1,4.000000e+000,3.292084e-003,0.000000e+000,0,,0,
1455901581.870,,5.027653e+003,4.999686e+001,2.739421e-002,0.000000e+000,3,9.515034e-001,0.000000e+000,,,,,,,,,,,,,,32,1,4.000000e+000,8.232117e-003,0.000000e+000,0,,0,
1455901671.010,,9.040038e+003,4.999768e+001,2.994921e-002,0.000000e+000,3,9.504222e-001,0.000000e+000,,,,,,,,,,,,,,32,1,4.000000e+000,3.288269e-003,0.000000e+000,0,,0,
1455901760.951,,1.305154e+004,5.000180e+001,3.215577e-002,0.000000e+000,3,9.500744e-001,0.000000e+000,,,,,,,,,,,,,,32,1,4.000000e+000,1.640320e-003,0.000000e+000,0,,0,
1455901849.431,,1.706724e+004,4.999851e+001,3.429518e-002,0.000000e+000,3,9.491597e-001,0.000000e+000,,,,,,,,,,,,,,32,1,4.000000e+000,4.940033e-003,0.000000e+000,0,,0,
1455901938.871,,2.108348e+004,4.999686e+001,3.640768e-002,0.000000e+000,3,9.496459e-001,0.000000e+000,,,,,,,,,,,,,,32,1,4.000000e+000,4.928589e-003,0.000000e+000,0,,0,
1455902027.611,,2.510082e+004,4.999686e+001,3.843153e-002,0.000000e+000,3,9.492537e-001,0.000000e+000,,,,,,,,,,,,,,32,1,4.000000e+000,8.232117e-003,0.000000e+000,0,,0,
1455902551.894,,-2.208685e+004,6.000010e+001,-3.508727e-002,0.000000e+000,3,9.473302e-001,0.000000e+000,,,,,,,,,,,,,,32,1,4.000000e+000,4.821777e-003,0.000000e+000,0,,0,
1455902640.374,,-1.807171e+004,5.999529e+001,-3.330410e-002,0.000000e+000,3,9.474090e-001,0.000000e+000,,,,,,,,,,,,,,32,1,4.000000e+000,9.628296e-003,0.000000e+000,0,,0,
1455902729.734,,-1.405932e+004,5.999769e+001,-3.156689e-002,0.000000e+000,3,9.471697e-001,0.000000e+000,,,,,,,,,,,,,,32,1,4.000000e+000,1.443863e-002,0.000000e+000,0,,0,
1455902820.074,,-1.004649e+004,6.000130e+001,-2.974386e-002,0.000000e+000,3,9.474581e-001,0.000000e+000,,,,,,,,,,,,,,32,1,4.000000e+000,2.410889e-003,0.000000e+000,0,,0,
1455902909.884,,-6.032788e+003,5.999649e+001,-2.772986e-002,0.000000e+000,3,9.479494e-001,0.000000e+000,,,,,,,,,,,,,,32,1,4.000000e+000,7.217407e-003,0.000000e+000,0,,0,
1455903000.804,,-2.017978e+003,6.000010e+001,-2.387098e-002,0.000000e+000,3,9.454048e-001,0.000000e+000,,,,,,,,,,,,,,32,1,4.000000e+000,4.821777e-003,0.000000e+000,0,,0,
1455903136.575,,2.018309e+003,6.000250e+001,2.360369e-002,0.000000e+000,3,9.510776e-001,0.000000e+000,,,,,,,,,,,,,,32,1,4.000000e+000,9.632111e-003,0.000000e+000,0,,0,
1455903228.165,,6.033008e+003,6.000010e+001,2.754451e-002,0.000000e+000,3,9.496970e-001,0.000000e+000,,,,,,,,,,,,,,32,1,4.000000e+000,0.000000e+000,0.000000e+000,0,,0,
1455903318.875,,1.004672e+004,5.999889e+001,2.958094e-002,0.000000e+000,3,9.508199e-001,0.000000e+000,,,,,,,,,,,,,,32,1,4.000000e+000,1.202774e-002,0.000000e+000,0,,0,
1455903407.855,,1.405932e+004,5.999770e+001,3.142215e-002,0.000000e+000,3,9.499005e-001,0.000000e+000,,,,,,,,,,,,,,32,1,4.000000e+000,4.810333e-003,0.000000e+000,0,,0,
1455903498.365,,1.807171e+004,5.999770e+001,3.321340e-002,0.000000e+000,3,9.497416e-001,0.000000e+000,,,,,,,,,,,,,,32,1,4.000000e+000,9.628296e-003,0.000000e+000,0,,0,
1455903589.365,,2.208685e+004,5.999890e+001,3.489485e-002,0.000000e+000,3,9.486015e-001,0.000000e+000,,,,,,,,,,,,,,32,1,4.000000e+000,7.221222e-003,0.000000e+000,0,,0,
1455904123.238,,-2.510137e+004,6.999191e+001,-3.454247e-002,0.000000e+000,3,9.487504e-001,0.000000e+000,,,,,,,,,,,,,,32,1,4.000000e+000,1.194000e-002,0.000000e+000,0,,0,
1455904213.048,,-2.108403e+004,6.999590e+001,-3.323732e-002,0.000000e+000,3,9.466060e-001,0.000000e+000,,,,,,,,,,,,,,32,1,4.000000e+000,1.327515e-003,0.000000e+000,0,,0,
1455904303.218,,-1.706834e+004,6.999855e+001,-3.170041e-002,0.000000e+000,3,9.472182e-001,0.000000e+000,,,,,,,,,,,,,,32,1,4.000000e+000,1.319885e-003,0.000000e+000,0,,0,
1455904393.498,,-1.305265e+004,7.000385e+001,-3.017719e-002,0.000000e+000,3,9.474429e-001,0.000000e+000,,,,,,,,,,,,,,32,1,4.000000e+000,1.319885e-003,0.000000e+000,0,,0,
1455904483.788,,-9.039821e+003,6.998927e+001,-2.858130e-002,0.000000e+000,3,9.470500e-001,0.000000e+000,,,,,,,,,,,,,,32,1,4.000000e+000,1.457977e-002,0.000000e+000,0,,0,
1455904574.089,,-5.027543e+003,6.999457e+001,-2.668120e-002,0.000000e+000,3,9.466403e-001,0.000000e+000,,,,,,,,,,,,,,32,1,4.000000e+000,6.629944e-003,0.000000e+000,0,,0,
1455904664.509,,-1.011632e+003,6.999987e+001,-1.998577e-002,0.000000e+000,3,9.469112e-001,0.000000e+000,,,,,,,,,,,,,,32,1,4.000000e+000,9.277344e-003,0.000000e+000,0,,0,
1455904787.069,,3.019808e+003,6.999722e+001,2.460826e-002,0.000000e+000,3,9.575543e-001,0.000000e+000,,,,,,,,,,,,,,32,1,4.000000e+000,3.974915e-003,0.000000e+000,0,,0,
1455904877.419,,7.036160e+003,7.000119e+001,2.771915e-002,0.000000e+000,3,9.484573e-001,0.000000e+000,,,,,,,,,,,,,,32,1,4.000000e+000,1.192474e-002,0.000000e+000,0,,0,
1455904967.849,,1.105008e+004,7.000385e+001,2.930006e-002,0.000000e+000,3,9.503969e-001,0.000000e+000,,,,,,,,,,,,,,32,1,4.000000e+000,6.629944e-003,0.000000e+000,0,,0,
1455905059.019,,1.506545e+004,6.999524e+001,3.084686e-002,0.000000e+000,3,9.504046e-001,0.000000e+000,,,,,,,,,,,,,,32,1,4.000000e+000,1.590729e-002,0.000000e+000,0,,0,
1455905150.929,,1.907949e+004,7.000186e+001,3.232333e-002,0.000000e+000,3,9.487668e-001,0.000000e+000,,,,,,,,,,,,,,32,1,4.000000e+000,7.949829e-003,0.000000e+000,0,,0,
1455905241.249,,2.309352e+004,6.999590e+001,3.379957e-002,0.000000e+000,3,9.487930e-001,0.000000e+000,,,,,,,,,,,,,,32,1,4.000000e+000,1.457977e-002,0.000000e+000,0,,0,
1455905786.812,,-2.409965e+004,7.999400e+001,-3.297399e-002,0.000000e+000,3,9.495493e-001,0.000000e+000,,,,,,,,,,,,,,32,1,4.000000e+000,3.494263e-003,0.000000e+000,0,,0,
1455905877.202,,-2.008341e+004,7.999138e+001,-3.174167e-002,0.000000e+000,3,9.492675e-001,0.000000e+000,,,,,,,,,,,,,,32,1,4.000000e+000,8.735657e-003,0.000000e+000,0,,0,
1455905966.962,,-1.606772e+004,7.999138e+001,-3.046328e-002,0.000000e+000,3,9.489227e-001,0.000000e+000,,,,,,,,,,,,,,32,1,4.000000e+000,2.272797e-002,0.000000e+000,0,,0,
1455906056.733,,-1.205280e+004,7.999575e+001,-2.914668e-002,0.000000e+000,3,9.485486e-001,0.000000e+000,,,,,,,,,,,,,,32,1,4.000000e+000,1.748657e-002,0.000000e+000,0,,0,
1455906144.113,,-8.037547e+003,8.000798e+001,-2.773432e-002,0.000000e+000,3,9.484323e-001,0.000000e+000,,,,,,,,,,,,,,32,1,4.000000e+000,1.049042e-002,0.000000e+000,0,,0,
1455906233.313,,-4.021087e+003,7.999312e+001,-2.577050e-002,0.000000e+000,3,9.470240e-001,0.000000e+000,,,,,,,,,,,,,,32,1,4.000000e+000,1.222992e-002,0.000000e+000,0,,0,
1455906332.913,,-3.524468e+000,7.998351e+001,-4.503216e-003,0.000000e+000,3,9.586084e-001,0.000000e+000,,,,,,,,,,,,,,32,1,4.000000e+000,2.445984e-002,0.000000e+000,0,,0,
1455906455.513,,4.021309e+003,7.999574e+001,2.553112e-002,0.000000e+000,3,9.503842e-001,0.000000e+000,,,,,,,,,,,,,,32,1,4.000000e+000,1.399231e-002,0.000000e+000,0,,0,
1455906545.553,,8.037988e+003,7.999662e+001,2.751303e-002,0.000000e+000,3,9.520602e-001,0.000000e+000,,,,,,,,,,,,,,32,1,4.000000e+000,1.574707e-002,0.000000e+000,0,,0,
1455906636.693,,1.205324e+004,7.999750e+001,2.901315e-002,0.000000e+000,3,9.513592e-001,0.000000e+000,,,,,,,,,,,,,,32,1,4.000000e+000,1.399994e-002,0.000000e+000,0,,0,
1455906726.394,,1.606717e+004,7.999312e+001,3.038524e-002,0.000000e+000,3,9.505397e-001,0.000000e+000,,,,,,,,,,,,,,32,1,4.000000e+000,1.572418e-002,0.000000e+000,0,,0,
1455906815.084,,2.008341e+004,8.000012e+001,3.154269e-002,0.000000e+000,3,9.514829e-001,0.000000e+000,,,,,,,,,,,,,,32,1,4.000000e+000,1.573944e-002,0.000000e+000,0,,0,
1455906906.154,,2.409910e+004,7.999574e+001,3.297831e-002,0.000000e+000,3,9.495142e-001,0.000000e+000,,,,,,,,,,,,,,32,1,4.000000e+000,2.449036e-002,0.000000e+000,0,,0,
1455907452.007,,-2.309297e+004,8.999387e+001,-3.171435e-002,0.000000e+000,3,9.491854e-001,0.000000e+000,,,,,,,,,,,,,,32,1,4.000000e+000,8.911133e-003,0.000000e+000,0,,0,
1455907541.407,,-1.907894e+004,8.999276e+001,-3.083136e-002,0.000000e+000,3,9.465725e-001,0.000000e+000,,,,,,,,,,,,,,32,1,4.000000e+000,2.006531e-002,0.000000e+000,0,,0,
1455907631.287,,-1.506490e+004,8.999387e+001,-2.949001e-002,0.000000e+000,3,9.489042e-001,0.000000e+000,,,,,,,,,,,,,,32,1,4.000000e+000,1.337433e-002,0.000000e+000,0,,0,
1455907721.407,,-1.105008e+004,8.999276e+001,-2.829386e-002,0.000000e+000,3,9.476482e-001,0.000000e+000,,,,,,,,,,,,,,32,1,4.000000e+000,1.559448e-002,0.000000e+000,0,,0,
1455907811.397,,-7.035939e+003,8.999611e+001,-2.695737e-002,0.000000e+000,3,9.484900e-001,0.000000e+000,,,,,,,,,,,,,,32,1,4.000000e+000,2.230072e-002,0.000000e+000,0,,0,
1455907898.777,,-3.019257e+003,8.999946e+001,-2.483901e-002,0.000000e+000,3,9.458355e-001,0.000000e+000,,,,,,,,,,,,,,32,1,4.000000e+000,1.560974e-002,0.000000e+000,0,,0,
1455908021.657,,1.011742e+003,8.998830e+001,1.899831e-002,0.000000e+000,3,9.518098e-001,0.000000e+000,,,,,,,,,,,,,,32,1,4.000000e+000,1.560211e-002,0.000000e+000,0,,0,
1455908112.267,,5.027984e+003,8.999722e+001,2.580127e-002,0.000000e+000,3,9.531623e-001,0.000000e+000,,,,,,,,,,,,,,32,1,4.000000e+000,1.560974e-002,0.000000e+000,0,,0,
1455908202.078,,9.040701e+003,8.999611e+001,2.745889e-002,0.000000e+000,3,9.514421e-001,0.000000e+000,,,,,,,,,,,,,,32,1,4.000000e+000,1.784515e-002,0.000000e+000,0,,0,
1455908292.398,,1.305265e+004,8.999500e+001,2.872341e-002,0.000000e+000,3,9.504958e-001,0.000000e+000,,,,,,,,,,,,,,32,1,4.000000e+000,2.453613e-002,0.000000e+000,0,,0,
1455908380.208,,1.706834e+004,9.000169e+001,2.992806e-002,0.000000e+000,3,9.507784e-001,0.000000e+000,,,,,,,,,,,,,,32,1,4.000000e+000,2.006531e-002,0.000000e+000,0,,0,
1455908470.028,,2.108403e+004,9.000056e+001,3.110701e-002,0.000000e+000,3,9.494432e-001,0.000000e+000,,,,,,,,,,,,,,32,1,4.000000e+000,8.926392e-003,0.000000e+000,0,,0,
1455908559.218,,2.510082e+004,8.999722e+001,3.221533e-002,0.000000e+000,3,9.504776e-001,0.000000e+000,,,,,,,,,,,,,,32,1,4.000000e+000,2.008057e-002,0.000000e+000,0,,0,
1455909106.941,,-2.208740e+004,9.999389e+001,-3.067516e-002,0.000000e+000,3,9.486241e-001,0.000000e+000,,,,,,,,,,,,,,32,1,4.000000e+000,1.382446e-002,0.000000e+000,0,,0,
1455909197.101,,-1.807281e+004,9.999251e+001,-2.974393e-002,0.000000e+000,3,9.482012e-001,0.000000e+000,,,,,,,,,,,,,,32,1,4.000000e+000,1.107025e-002,0.000000e+000,0,,0,
1455909287.571,,-1.405987e+004,9.999805e+001,-2.874992e-002,0.000000e+000,3,9.471433e-001,0.000000e+000,,,,,,,,,,,,,,32,1,4.000000e+000,1.109314e-002,0.000000e+000,0,,0,
1455909378.851,,-1.004605e+004,9.999945e+001,-2.761021e-002,0.000000e+000,3,9.462203e-001,0.000000e+000,,,,,,,,,,,,,,32,1,4.000000e+000,1.389313e-002,0.000000e+000,0,,0,
1455909469.561,,-6.032788e+003,9.999805e+001,-2.628233e-002,0.000000e+000,3,9.473717e-001,0.000000e+000,,,,,,,,,,,,,,32,1,4.000000e+000,1.109314e-002,0.000000e+000,0,,0,
1455909559.152,,-2.017978e+003,1.000022e+002,-2.319951e-002,0.000000e+000,3,9.463989e-001,0.000000e+000,,,,,,,,,,,,,,32,1,4.000000e+000,1.939392e-002,0.000000e+000,0,,0,
1455909679.902,,2.018419e+003,9.999113e+001,2.281468e-002,0.000000e+000,3,9.525133e-001,0.000000e+000,,,,,,,,,,,,,,32,1,4.000000e+000,2.493286e-002,0.000000e+000,0,,0,
1455909770.792,,6.033008e+003,9.999945e+001,2.605672e-002,0.000000e+000,3,9.507749e-001,0.000000e+000,,,,,,,,,,,,,,32,1,4.000000e+000,3.049469e-002,0.000000e+000,0,,0,
1455909862.532,,1.004672e+004,9.999667e+001,2.743585e-002,0.000000e+000,3,9.507549e-001,0.000000e+000,,,,,,,,,,,,,,32,1,4.000000e+000,1.384735e-002,0.000000e+000,0,,0,
1455909951.842,,1.406042e+004,9.999389e+001,2.856907e-002,0.000000e+000,3,9.504558e-001,0.000000e+000,,,,,,,,,,,,,,32,1,4.000000e+000,1.382446e-002,0.000000e+000,0,,0,
1455910041.712,,1.807226e+004,1.000022e+002,2.962521e-002,0.000000e+000,3,9.500850e-001,0.000000e+000,,,,,,,,,,,,,,32,1,4.000000e+000,2.799988e-003,0.000000e+000,0,,0,
1455910131.542,,2.208685e+004,9.998839e+001,3.067758e-002,0.000000e+000,3,9.497597e-001,0.000000e+000,,,,,,,,,,,,,,32,1,4.000000e+000,3.601837e-002,0.000000e+000,0,,0,
1455910676.065,,-2.510248e+004,1.099904e+002,-3.059054e-002,0.000000e+000,3,9.499320e-001,0.000000e+000,,,,,,,,,,,,,,32,1,4.000000e+000,0.000000e+000,0.000000e+000,0,,0,
1455910766.375,,-2.108458e+004,1.099971e+002,-2.976627e-002,0.000000e+000,3,9.479122e-001,0.000000e+000,,,,,,,,,,,,,,32,1,4.000000e+000,6.706238e-003,0.000000e+000,0,,0,
1455910856.165,,-1.706889e+004,1.099904e+002,-2.887411e-002,0.000000e+000,3,9.476106e-001,0.000000e+000,,,,,,,,,,,,,,32,1,4.000000e+000,6.698608e-003,0.000000e+000,0,,0,
1455910946.555,,-1.305320e+004,1.099921e+002,-2.796961e-002,0.000000e+000,3,9.484167e-001,0.000000e+000,,,,,,,,,,,,,,32,1,4.000000e+000,1.679993e-002,0.000000e+000,0,,0,
1455911038.166,,-9.040481e+003,1.099921e+002,-2.693656e-002,0.000000e+000,3,9.484262e-001,0.000000e+000,,,,,,,,,,,,,,32,1,4.000000e+000,3.709412e-002,0.000000e+000,0,,0,
1455911129.306,,-5.028204e+003,1.099921e+002,-2.561286e-002,0.000000e+000,3,9.481436e-001,0.000000e+000,,,,,,,,,,,,,,32,1,4.000000e+000,3.030396e-002,0.000000e+000,0,,0,
1455911218.946,,-1.012183e+003,1.099938e+002,-1.964497e-002,0.000000e+000,3,9.471030e-001,0.000000e+000,,,,,,,,,,,,,,32,1,4.000000e+000,2.700043e-002,0.000000e+000,0,,0,
1455911342.096,,3.020359e+003,1.099989e+002,2.403044e-002,0.000000e+000,3,9.524246e-001,0.000000e+000,,,,,,,,,,,,,,32,1,4.000000e+000,1.689911e-002,0.000000e+000,0,,0,
1455911430.376,,7.037041e+003,1.099921e+002,2.613352e-002,0.000000e+000,3,9.510127e-001,0.000000e+000,,,,,,,,,,,,,,32,1,4.000000e+000,1.679993e-002,0.000000e+000,0,,0,
1455911519.436,,1.105119e+004,1.099938e+002,2.732853e-002,0.000000e+000,3,9.502457e-001,0.000000e+000,,,,,,,,,,,,,,32,1,4.000000e+000,2.700043e-002,0.000000e+000,0,,0,
1455911607.536,,1.506600e+004,1.099938e+002,2.836132e-002,0.000000e+000,3,9.497336e-001,0.000000e+000,,,,,,,,,,,,,,32,1,4.000000e+000,6.797791e-003,0.000000e+000,0,,0,
1455911696.716,,1.908004e+004,1.099971e+002,2.930556e-002,0.000000e+000,3,9.492569e-001,0.000000e+000,,,,,,,,,,,,,,32,1,4.000000e+000,3.369904e-002,0.000000e+000,0,,0,
1455911784.827,,2.309407e+004,1.099921e+002,3.019359e-002,0.000000e+000,3,9.493199e-001,0.000000e+000,,,,,,,,,,,,,,32,1,4.000000e+000,3.030396e-002,0.000000e+000,0,,0,
1455912329.899,,-2.409855e+004,1.199874e+002,-2.977678e-002,0.000000e+000,3,9.489963e-001,0.000000e+000,,,,,,,,,,,,,,32,1,4.000000e+000,3.230286e-002,0.000000e+000,0,,0,
1455912418.030,,-2.008286e+004,1.199914e+002,-2.903766e-002,0.000000e+000,3,9.491464e-001,0.000000e+000,,,,,,,,,,,,,,32,1,4.000000e+000,8.102417e-003,0.000000e+000,0,,0,
1455912507.670,,-1.606717e+004,1.200076e+002,-2.822126e-002,0.000000e+000,3,9.490485e-001,0.000000e+000,,,,,,,,,,,,,,32,1,4.000000e+000,4.840088e-002,0.000000e+000,0,,0,
1455912596.550,,-1.205192e+004,1.199955e+002,-2.735488e-002,0.000000e+000,3,9.480495e-001,0.000000e+000,,,,,,,,,,,,,,32,1,4.000000e+000,2.420044e-002,0.000000e+000,0,,0,
1455912686.020,,-8.036887e+003,1.199894e+002,-2.638707e-002,0.000000e+000,3,9.484566e-001,0.000000e+000,,,,,,,,,,,,,,32,1,4.000000e+000,1.210022e-002,0.000000e+000,0,,0,
1455912776.720,,-4.020647e+003,1.199955e+002,-2.493989e-002,0.000000e+000,3,9.473887e-001,0.000000e+000,,,,,,,,,,,,,,32,1,4.000000e+000,3.229523e-002,0.000000e+000,0,,0,
1455912879.410,,-2.753490e+000,1.199834e+002,-3.774486e-003,0.000000e+000,3,9.725899e-001,0.000000e+000,,,,,,,,,,,,,,32,1,4.000000e+000,1.609802e-002,0.000000e+000,0,,0,
1455912987.540,,4.021088e+003,1.199895e+002,2.465012e-002,0.000000e+000,3,9.525862e-001,0.000000e+000,,,,,,,,,,,,,,32,1,4.000000e+000,2.829742e-002,0.000000e+000,0,,0,
1455913078.400,,8.037328e+003,1.199975e+002,2.621122e-002,0.000000e+000,3,9.512063e-001,0.000000e+000,,,,,,,,,,,,,,32,1,4.000000e+000,2.020264e-002,0.000000e+000,0,,0,
1455913168.181,,1.205258e+004,1.199915e+002,2.726149e-002,0.000000e+000,3,9.503143e-001,0.000000e+000,,,,,,,,,,,,,,32,1,4.000000e+000,3.229523e-002,0.000000e+000,0,,0,
1455913258.171,,1.606717e+004,1.199975e+002,2.815595e-002,0.000000e+000,3,9.500054e-001,0.000000e+000,,,,,,,,,,,,,,32,1,4.000000e+000,3.639984e-002,0.000000e+000,0,,0,
1455913347.701,,2.008286e+004,1.199995e+002,2.899021e-002,0.000000e+000,3,9.488018e-001,0.000000e+000,,,,,,,,,,,,,,32,1,4.000000e+000,1.619720e-002,0.000000e+000,0,,0,
1455913438.561,,2.409910e+004,1.199975e+002,2.981512e-002,0.000000e+000,3,9.484696e-001,0.000000e+000,,,,,,,,,,,,,,32,1,4.000000e+000,3.639984e-002,0.000000e+000,0,,0,
1455913980.794,,-2.309407e+004,1.300011e+002,-2.906834e-002,0.000000e+000,3,9.483254e-001,0.000000e+000,,,,,,,,,,,,,,32,1,4.000000e+000,4.699707e-003,0.000000e+000,0,,0,
1455914071.314,,-1.908004e+004,1.299892e+002,-2.836073e-002,0.000000e+000,3,9.487526e-001,0.000000e+000,,,,,,,,,,,,,,32,1,4.000000e+000,1.910400e-002,0.000000e+000,0,,0,
1455914161.094,,-1.506600e+004,1.299962e+002,-2.761711e-002,0.000000e+000,3,9.492589e-001,0.000000e+000,,,,,,,,,,,,,,32,1,4.000000e+000,1.429749e-002,0.000000e+000,0,,0,
1455914249.894,,-1.105097e+004,1.299892e+002,-2.681147e-002,0.000000e+000,3,9.482790e-001,0.000000e+000,,,,,,,,,,,,,,32,1,4.000000e+000,9.490967e-003,0.000000e+000,0,,0,
1455914340.854,,-7.037041e+003,1.299987e+002,-2.585593e-002,0.000000e+000,3,9.479051e-001,0.000000e+000,,,,,,,,,,,,,,32,1,4.000000e+000,3.810120e-002,0.000000e+000,0,,0,
1455914428.824,,-3.020249e+003,1.300010e+002,-2.407675e-002,0.000000e+000,3,9.473150e-001,0.000000e+000,,,,,,,,,,,,,,32,1,4.000000e+000,1.420593e-002,0.000000e+000,0,,0,
1455914550.774,,1.012734e+003,1.299843e+002,1.859318e-002,0.000000e+000,3,9.531832e-001,0.000000e+000,,,,,,,,,,,,,,32,1,4.000000e+000,9.506226e-003,0.000000e+000,0,,0,
1455914640.855,,5.028975e+003,1.299939e+002,2.495073e-002,0.000000e+000,3,9.519392e-001,0.000000e+000,,,,,,,,,,,,,,32,1,4.000000e+000,1.899719e-002,0.000000e+000,0,,0,
1455914731.015,,9.041362e+003,1.299867e+002,2.619121e-002,0.000000e+000,3,9.504325e-001,0.000000e+000,,,,,,,,,,,,,,32,1,4.000000e+000,4.280090e-002,0.000000e+000,0,,0,
1455914820.365,,1.305430e+004,1.299939e+002,2.712013e-002,0.000000e+000,3,9.500706e-001,0.000000e+000,,,,,,,,,,,,,,32,1,4.000000e+000,2.850342e-002,0.000000e+000,0,,0,
1455914909.015,,1.706944e+004,1.299915e+002,2.792549e-002,0.000000e+000,3,9.496890e-001,0.000000e+000,,,,,,,,,,,,,,32,1,4.000000e+000,3.320313e-002,0.000000e+000,0,,0,
1455915000.085,,2.108513e+004,1.299939e+002,2.868599e-002,0.000000e+000,3,9.490249e-001,0.000000e+000,,,,,,,,,,,,,,32,1,4.000000e+000,3.799438e-002,0.000000e+000,0,,0,
1455915090.795,,2.510248e+004,1.299939e+002,2.941562e-002,0.000000e+000,3,9.493586e-001,0.000000e+000,,,,,,,,,,,,,,32,1,4.000000e+000,0.000000e+000,0.000000e+000,0,,0,
1455915629.368,,-2.208685e+004,1.399990e+002,-2.845011e-002,0.000000e+000,3,9.489329e-001,0.000000e+000,,,,,,,,,,,,,,32,1,4.000000e+000,1.100159e-002,0.000000e+000,0,,0,
1455915717.978,,-1.807226e+004,1.399907e+002,-2.776811e-002,0.000000e+000,3,9.472505e-001,0.000000e+000,,,,,,,,,,,,,,32,1,4.000000e+000,2.760315e-002,0.000000e+000,0,,0,
1455915808.108,,-1.405987e+004,1.400045e+002,-2.706303e-002,0.000000e+000,3,9.472188e-001,0.000000e+000,,,,,,,,,,,,,,32,1,4.000000e+000,2.209473e-002,0.000000e+000,0,,0,
1455915898.618,,-1.004605e+004,1.399907e+002,-2.631463e-002,0.000000e+000,3,9.475449e-001,0.000000e+000,,,,,,,,,,,,,,32,1,4.000000e+000,4.978943e-002,0.000000e+000,0,,0,
1455915988.689,,-6.032678e+003,1.399934e+002,-2.536158e-002,0.000000e+000,3,9.470165e-001,0.000000e+000,,,,,,,,,,,,,,32,1,4.000000e+000,1.109314e-002,0.000000e+000,0,,0,
1455916081.649,,-2.017648e+003,1.399796e+002,-2.258915e-002,0.000000e+000,3,9.454328e-001,0.000000e+000,,,,,,,,,,,,,,32,1,4.000000e+000,5.508423e-003,0.000000e+000,0,,0,
1455916202.209,,2.018198e+003,1.400073e+002,2.222730e-002,0.000000e+000,3,9.510023e-001,0.000000e+000,,,,,,,,,,,,,,32,1,4.000000e+000,1.660156e-002,0.000000e+000,0,,0,
1455916290.999,,6.032898e+003,1.399935e+002,2.511971e-002,0.000000e+000,3,9.494913e-001,0.000000e+000,,,,,,,,,,,,,,32,1,4.000000e+000,3.320313e-002,0.000000e+000,0,,0,
1455916380.319,,1.004649e+004,1.399962e+002,2.616552e-002,0.000000e+000,3,9.489129e-001,0.000000e+000,,,,,,,,,,,,,,32,1,4.000000e+000,2.769470e-002,0.000000e+000,0,,0,
1455916469.409,,1.405987e+004,1.400017e+002,2.698139e-002,0.000000e+000,3,9.483547e-001,0.000000e+000,,,,,,,,,,,,,,32,1,4.000000e+000,2.769470e-002,0.000000e+000,0,,0,
1455916559.389,,1.807281e+004,1.399796e+002,2.771108e-002,0.000000e+000,3,9.483440e-001,0.000000e+000,,,,,,,,,,,,,,32,1,4.000000e+000,3.869629e-002,0.000000e+000,0,,0,
1455916649.119,,2.208740e+004,1.399907e+002,2.839674e-002,0.000000e+000,3,9.478050e-001,0.000000e+000,,,,,,,,,,,,,,32,1,4.000000e+000,5.599976e-003,0.000000e+000,0,,0,
1455917187.262,,-2.510248e+004,1.499771e+002,-2.833085e-002,0.000000e+000,3,9.494771e-001,0.000000e+000,,,,,,,,,,,,,,32,1,4.000000e+000,1.910400e-002,0.000000e+000,0,,0,
1455917278.392,,-2.108568e+004,1.500281e+002,-2.787085e-002,0.000000e+000,3,9.493262e-001,0.000000e+000,,,,,,,,,,,,,,32,1,4.000000e+000,6.393433e-003,0.000000e+000,0,,0,
1455917367.482,,-1.706944e+004,1.499866e+002,-2.725072e-002,0.000000e+000,3,9.491109e-001,0.000000e+000,,,,,,,,,,,,,,32,1,4.000000e+000,0.000000e+000,0.000000e+000,0,,0,
1455917459.193,,-1.305430e+004,1.500089e+002,-2.656258e-002,0.000000e+000,3,9.480440e-001,0.000000e+000,,,,,,,,,,,,,,32,1,4.000000e+000,3.190613e-002,0.000000e+000,0,,0,
1455917548.583,,-9.041362e+003,1.499931e+002,-2.583956e-002,0.000000e+000,3,9.487705e-001,0.000000e+000,,,,,,,,,,,,,,32,1,4.000000e+000,3.829956e-002,0.000000e+000,0,,0,
1455917637.993,,-5.028645e+003,1.499483e+002,-2.480972e-002,0.000000e+000,3,9.478847e-001,0.000000e+000,,,,,,,,,,,,,,32,1,4.000000e+000,3.829956e-002,0.000000e+000,0,,0,
1455917726.803,,-1.012624e+003,1.500058e+002,-1.904935e-002,0.000000e+000,3,9.480770e-001,0.000000e+000,,,,,,,,,,,,,,32,1,4.000000e+000,0.000000e+000,0.000000e+000,0,,0,
1455917846.153,,3.020689e+003,1.500090e+002,2.336572e-002,0.000000e+000,3,9.529919e-001,0.000000e+000,,,,,,,,,,,,,,32,1,4.000000e+000,8.300781e-002,0.000000e+000,0,,0,
1455917934.263,,7.037481e+003,1.499803e+002,2.522304e-002,0.000000e+000,3,9.513941e-001,0.000000e+000,,,,,,,,,,,,,,32,1,4.000000e+000,1.269531e-002,0.000000e+000,0,,0,
1455918025.523,,1.105163e+004,1.499931e+002,2.606013e-002,0.000000e+000,3,9.491087e-001,0.000000e+000,,,,,,,,,,,,,,32,1,4.000000e+000,3.829956e-002,0.000000e+000,0,,0,
1455918115.723,,1.506655e+004,1.499962e+002,2.682542e-002,0.000000e+000,3,9.495793e-001,0.000000e+000,,,,,,,,,,,,,,32,1,4.000000e+000,1.919556e-002,0.000000e+000,0,,0,
1455918205.124,,1.908058e+004,1.499771e+002,2.750795e-002,0.000000e+000,3,9.499884e-001,0.000000e+000,,,,,,,,,,,,,,32,1,4.000000e+000,4.460144e-002,0.000000e+000,0,,0,
1455918293.184,,2.309463e+004,1.499962e+002,2.812279e-002,0.000000e+000,3,9.485486e-001,0.000000e+000,,,,,,,,,,,,,,32,1,4.000000e+000,1.919556e-002,0.000000e+000,0,,0,
1455918828.144,,-2.410020e+004,1.599926e+002,-2.783344e-002,0.000000e+000,3,9.495276e-001,0.000000e+000,,,,,,,,,,,,,,32,1,4.000000e+000,2.920532e-002,0.000000e+000,0,,0,
1455918916.945,,-2.008396e+004,1.599962e+002,-2.731607e-002,0.000000e+000,3,9.493093e-001,0.000000e+000,,,,,,,,,,,,,,32,1,4.000000e+000,2.189636e-002,0.000000e+000,0,,0,
1455919008.425,,-1.606827e+004,1.599926e+002,-2.673542e-002,0.000000e+000,3,9.490870e-001,0.000000e+000,,,,,,,,,,,,,,32,1,4.000000e+000,2.920532e-002,0.000000e+000,0,,0,
1455919098.615,,-1.205390e+004,1.599926e+002,-2.611515e-002,0.000000e+000,3,9.489332e-001,0.000000e+000,,,,,,,,,,,,,,32,1,4.000000e+000,2.920532e-002,0.000000e+000,0,,0,
1455919186.665,,-8.038428e+003,1.599944e+002,-2.534623e-002,0.000000e+000,3,9.479576e-001,0.000000e+000,,,,,,,,,,,,,,32,1,4.000000e+000,3.280640e-002,0.000000e+000,0,,0,
1455919277.785,,-4.021638e+003,1.599926e+002,-2.414770e-002,0.000000e+000,3,9.471890e-001,0.000000e+000,,,,,,,,,,,,,,32,1,4.000000e+000,3.649902e-002,0.000000e+000,0,,0,
1455919379.605,,-3.634611e+000,1.599780e+002,-3.685458e-003,0.000000e+000,3,9.684511e-001,0.000000e+000,,,,,,,,,,,,,,32,1,4.000000e+000,7.293701e-003,0.000000e+000,0,,0,
1455919488.595,,4.022079e+003,1.599926e+002,2.388075e-002,0.000000e+000,3,9.521543e-001,0.000000e+000,,,,,,,,,,,,,,32,1,4.000000e+000,2.920532e-002,0.000000e+000,0,,0,
1455919579.286,,8.038869e+003,1.599926e+002,2.519966e-002,0.000000e+000,3,9.504668e-001,0.000000e+000,,,,,,,,,,,,,,32,1,4.000000e+000,3.649902e-002,0.000000e+000,0,,0,
1455919668.096,,1.205412e+004,1.599980e+002,2.600787e-002,0.000000e+000,3,9.506207e-001,0.000000e+000,,,,,,,,,,,,,,32,1,4.000000e+000,3.289795e-002,0.000000e+000,0,,0,
1455919758.146,,1.606882e+004,1.599926e+002,2.664908e-002,0.000000e+000,3,9.494353e-001,0.000000e+000,,,,,,,,,,,,,,32,1,4.000000e+000,3.649902e-002,0.000000e+000,0,,0,
1455919850.186,,2.008451e+004,1.599926e+002,2.728068e-002,0.000000e+000,3,9.496840e-001,0.000000e+000,,,,,,,,,,,,,,32,1,4.000000e+000,3.649902e-002,0.000000e+000,0,,0,
1455919940.386,,2.410075e+004,1.599926e+002,2.780166e-002,0.000000e+000,3,9.491639e-001,0.000000e+000,,,,,,,,,,,,,,32,1,4.000000e+000,3.649902e-002,0.000000e+000,0,,0,
1455920474.459,,-2.309352e+004,1.699951e+002,-2.731309e-002,0.000000e+000,3,9.492345e-001,0.000000e+000,,,,,,,,,,,,,,32,1,4.000000e+000,2.909851e-002,0.000000e+000,0,,0,
1455920564.489,,-1.908003e+004,1.699908e+002,-2.682304e-002,0.000000e+000,3,9.488319e-001,0.000000e+000,,,,,,,,,,,,,,32,1,4.000000e+000,2.909851e-002,0.000000e+000,0,,0,
1455920654.479,,-1.506545e+004,1.699951e+002,-2.626824e-002,0.000000e+000,3,9.484299e-001,0.000000e+000,,,,,,,,,,,,,,32,1,4.000000e+000,2.909851e-002,0.000000e+000,0,,0,
1455920744.839,,-1.105075e+004,1.699951e+002,-2.566863e-002,0.000000e+000,3,9.482360e-001,0.000000e+000,,,,,,,,,,,,,,32,1,4.000000e+000,2.909851e-002,0.000000e+000,0,,0,
1455920835.889,,-7.036600e+003,1.699930e+002,-2.493411e-002,0.000000e+000,3,9.479209e-001,0.000000e+000,,,,,,,,,,,,,,32,1,4.000000e+000,3.329468e-002,0.000000e+000,0,,0,
1455920925.199,,-3.020029e+003,1.699909e+002,-2.332861e-002,0.000000e+000,3,9.470261e-001,0.000000e+000,,,,,,,,,,,,,,32,1,4.000000e+000,3.739929e-002,0.000000e+000,0,,0,
1455921047.630,,1.012403e+003,1.699763e+002,1.808735e-002,0.000000e+000,3,9.534095e-001,0.000000e+000,,,,,,,,,,,,,,32,1,4.000000e+000,8.300781e-003,0.000000e+000,0,,0,
1455921138.070,,5.028424e+003,1.699950e+002,2.411570e-002,0.000000e+000,3,9.517909e-001,0.000000e+000,,,,,,,,,,,,,,32,1,4.000000e+000,3.739929e-002,0.000000e+000,0,,0,
1455921229.240,,9.041143e+003,1.699930e+002,2.514720e-002,0.000000e+000,3,9.492774e-001,0.000000e+000,,,,,,,,,,,,,,32,1,4.000000e+000,3.329468e-002,0.000000e+000,0,,0,
1455921320.190,,1.305320e+004,1.699909e+002,2.585199e-002,0.000000e+000,3,9.488999e-001,0.000000e+000,,,,,,,,,,,,,,32,1,4.000000e+000,3.739929e-002,0.000000e+000,0,,0,
1455921409.620,,1.706889e+004,1.699908e+002,2.644997e-002,0.000000e+000,3,9.487064e-001,0.000000e+000,,,,,,,,,,,,,,32,1,4.000000e+000,4.570007e-002,0.000000e+000,0,,0,
1455921499.780,,2.108568e+004,1.699930e+002,2.704538e-002,0.000000e+000,3,9.495643e-001,0.000000e+000,,,,,,,,,,,,,,32,1,4.000000e+000,4.989624e-002,0.000000e+000,0,,0,
1455921589.100,,2.510193e+004,1.699930e+002,2.755078e-002,0.000000e+000,3,9.502866e-001,0.000000e+000,,,,,,,,,,,,,,32,1,4.000000e+000,4.150391e-002,0.000000e+000,0,,0,
1455922120.233,,-2.208685e+004,1.800009e+002,-2.680399e-002,0.000000e+000,3,9.488258e-001,0.000000e+000,,,,,,,,,,,,,,32,1,4.000000e+000,2.819824e-002,0.000000e+000,0,,0,
1455922211.423,,-1.807226e+004,1.799939e+002,-2.633914e-002,0.000000e+000,3,9.481148e-001,0.000000e+000,,,,,,,,,,,,,,32,1,4.000000e+000,3.280640e-002,0.000000e+000,0,,0,
1455922302.843,,-1.405987e+004,1.799915e+002,-2.583853e-002,0.000000e+000,3,9.483643e-001,0.000000e+000,,,,,,,,,,,,,,32,1,4.000000e+000,2.810669e-002,0.000000e+000,0,,0,
1455922394.403,,-1.004672e+004,1.799892e+002,-2.523791e-002,0.000000e+000,3,9.477671e-001,0.000000e+000,,,,,,,,,,,,,,32,1,4.000000e+000,4.220581e-002,0.000000e+000,0,,0,
1455922484.654,,-6.032788e+003,1.799915e+002,-2.443426e-002,0.000000e+000,3,9.472731e-001,0.000000e+000,,,,,,,,,,,,,,32,1,4.000000e+000,3.750610e-002,0.000000e+000,0,,0,
1455922575.914,,-2.017978e+003,1.799962e+002,-2.186605e-002,0.000000e+000,3,9.469835e-001,0.000000e+000,,,,,,,,,,,,,,32,1,4.000000e+000,3.750610e-002,0.000000e+000,0,,0,
1455922696.734,,2.018419e+003,1.799939e+002,2.149309e-002,0.000000e+000,3,9.539197e-001,0.000000e+000,,,,,,,,,,,,,,32,1,4.000000e+000,4.220581e-002,0.000000e+000,0,,0,
1455922787.034,,6.033339e+003,1.799915e+002,2.422915e-002,0.000000e+000,3,9.503374e-001,0.000000e+000,,,,,,,,,,,,,,32,1,4.000000e+000,3.750610e-002,0.000000e+000,0,,0,
1455922877.944,,1.004693e+004,1.799939e+002,2.509439e-002,0.000000e+000,3,9.498172e-001,0.000000e+000,,,,,,,,,,,,,,32,1,4.000000e+000,3.280640e-002,0.000000e+000,0,,0,
1455922967.754,,1.405987e+004,1.799915e+002,2.572336e-002,0.000000e+000,3,9.496529e-001,0.000000e+000,,,,,,,,,,,,,,32,1,4.000000e+000,4.690552e-002,0.000000e+000,0,,0,
1455923057.334,,1.807336e+004,1.799915e+002,2.631173e-002,0.000000e+000,3,9.498167e-001,0.000000e+000,,,,,,,,,,,,,,32,1,4.000000e+000,4.690552e-002,0.000000e+000,0,,0,
1455923146.575,,2.208740e+004,1.799939e+002,2.679957e-002,0.000000e+000,3,9.486685e-001,0.000000e+000,,,,,,,,,,,,,,32,1,4.000000e+000,4.220581e-002,0.000000e+000,0,,0,
1455923676.097,,-2.510192e+004,1.899868e+002,-2.672080e-002,0.000000e+000,3,9.512934e-001,0.000000e+000,,,,,,,,,,,,,,32,1,4.000000e+000,3.680420e-002,0.000000e+000,0,,0,
1455923767.447,,-2.108458e+004,1.899947e+002,-2.636071e-002,0.000000e+000,3,9.493284e-001,0.000000e+000,,,,,,,,,,,,,,32,1,4.000000e+000,3.150940e-002,0.000000e+000,0,,0,
1455923857.258,,-1.706889e+004,1.899868e+002,-2.590476e-002,0.000000e+000,3,9.488418e-001,0.000000e+000,,,,,,,,,,,,,,32,1,4.000000e+000,3.680420e-002,0.000000e+000,0,,0,
1455923946.958,,-1.305320e+004,1.899894e+002,-2.537821e-002,0.000000e+000,3,9.478958e-001,0.000000e+000,,,,,,,,,,,,,,32,1,4.000000e+000,4.200745e-002,0.000000e+000,0,,0,
1455924037.688,,-9.040698e+003,1.899894e+002,-2.482150e-002,0.000000e+000,3,9.480424e-001,0.000000e+000,,,,,,,,,,,,,,32,1,4.000000e+000,4.200745e-002,0.000000e+000,0,,0,
1455924126.328,,-5.028094e+003,1.899894e+002,-2.397709e-002,0.000000e+000,3,9.474717e-001,0.000000e+000,,,,,,,,,,,,,,32,1,4.000000e+000,4.200745e-002,0.000000e+000,0,,0,
1455924216.838,,-1.012183e+003,1.899947e+002,-1.840499e-002,0.000000e+000,3,9.478163e-001,0.000000e+000,,,,,,,,,,,,,,32,1,4.000000e+000,4.209900e-002,0.000000e+000,0,,0,
1455924338.738,,3.020249e+003,1.899947e+002,2.255500e-002,0.000000e+000,3,9.533436e-001,0.000000e+000,,,,,,,,,,,,,,32,1,4.000000e+000,4.209900e-002,0.000000e+000,0,,0,
1455924429.858,,7.037041e+003,1.899921e+002,2.425098e-002,0.000000e+000,3,9.505981e-001,0.000000e+000,,,,,,,,,,,,,,32,1,4.000000e+000,4.730225e-002,0.000000e+000,0,,0,
1455924519.968,,1.105097e+004,1.899947e+002,2.499183e-002,0.000000e+000,3,9.492013e-001,0.000000e+000,,,,,,,,,,,,,,32,1,4.000000e+000,5.250549e-002,0.000000e+000,0,,0,
1455924610.419,,1.506600e+004,1.899894e+002,2.558025e-002,0.000000e+000,3,9.503731e-001,0.000000e+000,,,,,,,,,,,,,,32,1,4.000000e+000,4.200745e-002,0.000000e+000,0,,0,
1455924702.479,,1.908004e+004,1.899921e+002,2.607026e-002,0.000000e+000,3,9.494305e-001,0.000000e+000,,,,,,,,,,,,,,32,1,4.000000e+000,4.730225e-002,0.000000e+000,0,,0,
1455924792.399,,2.309407e+004,1.899921e+002,2.656857e-002,0.000000e+000,3,9.501448e-001,0.000000e+000,,,,,,,,,,,,,,32,1,4.000000e+000,4.730225e-002,0.000000e+000,0,,0,
1455925322.442,,-2.409910e+004,1.999928e+002,-2.627698e-002,0.000000e+000,3,9.486449e-001,0.000000e+000,,,,,,,,,,,,,,32,1,4.000000e+000,3.509521e-002,0.000000e+000,0,,0,
1455925412.792,,-2.008286e+004,1.999957e+002,-2.590103e-002,0.000000e+000,3,9.483311e-001,0.000000e+000,,,,,,,,,,,,,,32,1,4.000000e+000,4.100037e-002,0.000000e+000,0,,0,
1455925502.362,,-1.606717e+004,1.999869e+002,-2.548028e-002,0.000000e+000,3,9.476030e-001,0.000000e+000,,,,,,,,,,,,,,32,1,4.000000e+000,3.520203e-002,0.000000e+000,0,,0,
1455925592.382,,-1.205280e+004,1.999928e+002,-2.498448e-002,0.000000e+000,3,9.481578e-001,0.000000e+000,,,,,,,,,,,,,,32,1,4.000000e+000,4.690552e-002,0.000000e+000,0,,0,
1455925682.972,,-8.037112e+003,1.999898e+002,-2.440671e-002,0.000000e+000,3,9.470569e-001,0.000000e+000,,,,,,,,,,,,,,32,1,4.000000e+000,4.100037e-002,0.000000e+000,0,,0,
1455925773.392,,-4.020867e+003,1.999899e+002,-2.332564e-002,0.000000e+000,3,9.464026e-001,0.000000e+000,,,,,,,,,,,,,,32,1,4.000000e+000,5.270386e-002,0.000000e+000,0,,0,
1455925874.442,,-2.973770e+000,1.999752e+002,-3.527006e-003,0.000000e+000,3,9.664240e-001,0.000000e+000,,,,,,,,,,,,,,32,1,4.000000e+000,1.170349e-002,0.000000e+000,0,,0,
1455925984.573,,4.021308e+003,1.999899e+002,2.306219e-002,0.000000e+000,3,9.523140e-001,0.000000e+000,,,,,,,,,,,,,,32,1,4.000000e+000,5.270386e-002,0.000000e+000,0,,0,
1455926076.353,,8.037551e+003,1.999928e+002,2.422949e-002,0.000000e+000,3,9.493350e-001,0.000000e+000,,,,,,,,,,,,,,32,1,4.000000e+000,4.690552e-002,0.000000e+000,0,,0,
1455926166.453,,1.205258e+004,1.999898e+002,2.484112e-002,0.000000e+000,3,9.492503e-001,0.000000e+000,,,,,,,,,,,,,,32,1,4.000000e+000,4.100037e-002,0.000000e+000,0,,0,
1455926256.093,,1.606772e+004,1.999899e+002,2.538836e-002,0.000000e+000,3,9.497202e-001,0.000000e+000,,,,,,,,,,,,,,32,1,4.000000e+000,5.270386e-002,0.000000e+000,0,,0,
1455926345.603,,2.008341e+004,1.999899e+002,2.584399e-002,0.000000e+000,3,9.484668e-001,0.000000e+000,,,,,,,,,,,,,,32,1,4.000000e+000,5.270386e-002,0.000000e+000,0,,0,
1455926435.623,,2.409910e+004,1.999898e+002,2.626716e-002,0.000000e+000,3,9.496786e-001,0.000000e+000,,,,,,,,,,,,,,32,1,4.000000e+000,4.100037e-002,0.000000e+000,0,,0,
1455926963.206,,-2.309298e+004,2.099946e+002,-2.586342e-002,0.000000e+000,3,9.492571e-001,0.000000e+000,,,,,,,,,,,,,,32,1,4.000000e+000,3.259277e-002,0.000000e+000,0,,0,
1455927054.836,,-1.907894e+004,2.099881e+002,-2.549375e-002,0.000000e+000,3,9.479226e-001,0.000000e+000,,,,,,,,,,,,,,32,1,4.000000e+000,4.550171e-002,0.000000e+000,0,,0,
1455927145.036,,-1.506490e+004,2.099914e+002,-2.509425e-002,0.000000e+000,3,9.482259e-001,0.000000e+000,,,,,,,,,,,,,,32,1,4.000000e+000,3.900146e-002,0.000000e+000,0,,0,
1455927235.226,,-1.104964e+004,2.099881e+002,-2.461409e-002,0.000000e+000,3,9.480850e-001,0.000000e+000,,,,,,,,,,,,,,32,1,4.000000e+000,4.550171e-002,0.000000e+000,0,,0,
1455927324.926,,-7.035719e+003,2.099914e+002,-2.398984e-002,0.000000e+000,3,9.471303e-001,0.000000e+000,,,,,,,,,,,,,,32,1,4.000000e+000,3.900146e-002,0.000000e+000,0,,0,
1455927416.047,,-3.019257e+003,2.099881e+002,-2.253026e-002,0.000000e+000,3,9.462754e-001,0.000000e+000,,,,,,,,,,,,,,32,1,4.000000e+000,5.859375e-002,0.000000e+000,0,,0,
1455927537.997,,1.011632e+003,2.099588e+002,1.752444e-002,0.000000e+000,3,9.532943e-001,0.000000e+000,,,,,,,,,,,,,,32,1,4.000000e+000,1.309204e-002,0.000000e+000,0,,0,
1455927629.907,,5.027763e+003,2.099914e+002,2.323746e-002,0.000000e+000,3,9.506755e-001,0.000000e+000,,,,,,,,,,,,,,32,1,4.000000e+000,5.200195e-002,0.000000e+000,0,,0,
1455927720.617,,9.040038e+003,2.099946e+002,2.416535e-002,0.000000e+000,3,9.507892e-001,0.000000e+000,,,,,,,,,,,,,,32,1,4.000000e+000,3.259277e-002,0.000000e+000,0,,0,
1455927809.527,,1.305265e+004,2.099881e+002,2.475193e-002,0.000000e+000,3,9.500355e-001,0.000000e+000,,,,,,,,,,,,,,32,1,4.000000e+000,5.859375e-002,0.000000e+000,0,,0,
1455927899.347,,1.706834e+004,2.099914e+002,2.524230e-002,0.000000e+000,3,9.496986e-001,0.000000e+000,,,,,,,,,,,,,,32,1,4.000000e+000,5.200195e-002,0.000000e+000,0,,0,
1455927989.887,,2.108458e+004,2.099881e+002,2.565984e-002,0.000000e+000,3,9.493143e-001,0.000000e+000,,,,,,,,,,,,,,32,1,4.000000e+000,5.859375e-002,0.000000e+000,0,,0,
1455928079.447,,2.510137e+004,2.099914e+002,2.600183e-002,0.000000e+000,3,9.496304e-001,0.000000e+000,,,,,,,,,,,,,,32,1,4.000000e+000,5.200195e-002,0.000000e+000,0,,0,