File: Input/TC04-12-01K_VRMac_55K_3000s_VRMde_55K.dc.dat
[Header]
TITLE,MPMS DC Measurement
BYAPP,MPMS Measurement,2.1,Summary
FILEOPENTIME, 1524070827.461000 4/18/2018, 11:00:27 AM

INFO, APPNAME, MPMS MultiVu Application, Revision 1.61,  Build 082

INFO, NAME, TC04-12-01K
INFO, WEIGHT, 1.000
INFO, AREA, 1.000
INFO, LENGTH, 1.000
INFO, SHAPE, 0
INFO, COMMENT,
INFO, SEQUENCE FILE: VRMac_55K_3000s_VRMde_55K.seq


INFO, BACKGROUND DATA FILE:, None


STARTUPAXIS,X,4,LINEAR,AUTO,0.000000,0.000000
STARTUPAXIS,Y1,5,LINEAR,AUTO,0.000000,0.000000


STARTUPGROUP,Longitudinal
FIELDGROUP,Longitudinal,1,2,3,4,5,6,7,8,9,15,16,17,18,27,28
FIELDGROUP,Transverse,1,2,3,4,10,11,12,13,14,19,20,21,22,27,28

PLOT_APPEARANCE,ALL,HORZ_GRID_ON,VERT_GRID_ON,MARKERS_AND_LINES

[Data]
Time,Comment,Field (Oe),Temperature (K),Long Moment (emu),Long Scan Std Dev,Long Algorithm,Long Reg Fit,Long Percent Error (%),Trans Moment (emu),Trans Scan Std Dev,Trans Algorithm,Trans Reg Fit,Trans Percent Error (%),Long Moment [w/o ABS] (emu),Long Scan Std Dev [w/o ABS],Long Reg Fit [w/o ABS],Long Percent Error [w/o ABS] (%),Trans Moment [w/o ABS] (emu),Trans Scan Std Dev [w/o ABS],Trans Reg Fit [w/o ABS],Trans Percent Error [w/o ABS] (%),Points per Scan,Scans per Measurement,Scan Length (cm),Delta Temp (K),Rot Position (deg),Error,EC Comp. Running,Using ABS,
1524070827.461,,0.000000e+000,5.500432e+001,-1.343129e-005,0.000000e+000,3,9.752554e-001,0.000000e+000,,,,,,,,,,,,,,32,1,4.000000e+000,3.940582e-003,0.000000e+000,0,,0,
1524070864.721,,0.000000e+000,5.500103e+001,-1.059965e-005,0.000000e+000,3,9.623805e-001,0.000000e+000,,,,,,,,,,,,,,32,1,4.000000e+000,5.279541e-003,0.000000e+000,0,,0,
1524070903.581,,0.000000e+000,5.500037e+001,-8.995757e-006,0.000000e+000,3,9.578571e-001,0.000000e+000,,,,,,,,,,,,,,32,1,4.000000e+000,3.959656e-003,0.000000e+000,0,,0,
1524070942.081,,0.000000e+000,5.500103e+001,-7.824561e-006,0.000000e+000,3,9.584028e-001,0.000000e+000,,,,,,,,,,,,,,32,1,4.000000e+000,7.888794e-003,0.000000e+000,0,,0,
1524070980.651,,0.000000e+000,5.499971e+001,-7.073909e-006,0.000000e+000,3,9.505401e-001,0.000000e+000,,,,,,,,,,,,,,32,1,4.000000e+000,1.052094e-002,0.000000e+000,0,,0,
1524071018.381,,0.000000e+000,5.499840e+001,-6.463441e-006,0.000000e+000,3,9.424528e-001,0.000000e+000,,,,,,,,,,,,,,32,1,4.000000e+000,2.628326e-003,0.000000e+000,0,,0,
1524071055.871,,0.000000e+000,5.499840e+001,-5.894095e-006,0.000000e+000,3,9.443781e-001,0.000000e+000,,,,,,,,,,,,,,32,1,4.000000e+000,5.260468e-003,0.000000e+000,0,,0,
1524071093.501,,0.000000e+000,5.499840e+001,-5.505321e-006,0.000000e+000,3,9.468476e-001,0.000000e+000,,,,,,,,,,,,,,32,1,4.000000e+000,2.628326e-003,0.000000e+000,0,,0,
1524071131.131,,0.000000e+000,5.499511e+001,-5.077828e-006,0.000000e+000,3,9.332070e-001,0.000000e+000,,,,,,,,,,,,,,32,1,4.000000e+000,1.319885e-003,0.000000e+000,0,,0,
1524071169.061,,0.000000e+000,5.499972e+001,-4.830510e-006,0.000000e+000,3,9.240068e-001,0.000000e+000,,,,,,,,,,,,,,32,1,4.000000e+000,5.268097e-003,0.000000e+000,0,,0,
1524071206.831,,0.000000e+000,5.499905e+001,-4.566999e-006,0.000000e+000,3,9.135116e-001,0.000000e+000,,,,,,,,,,,,,,32,1,4.000000e+000,1.319885e-003,0.000000e+000,0,,0,
1524071244.361,,0.000000e+000,5.499905e+001,-4.292811e-006,0.000000e+000,3,9.314196e-001,0.000000e+000,,,,,,,,,,,,,,32,1,4.000000e+000,3.948212e-003,0.000000e+000,0,,0,
1524071281.791,,0.000000e+000,5.499774e+001,-4.093755e-006,0.000000e+000,3,9.127071e-001,0.000000e+000,,,,,,,,,,,,,,32,1,4.000000e+000,3.940582e-003,0.000000e+000,0,,0,
1524071319.962,,0.000000e+000,5.499971e+001,-3.841157e-006,0.000000e+000,3,9.184598e-001,0.000000e+000,,,,,,,,,,,,,,32,1,4.000000e+000,0.000000e+000,0.000000e+000,0,,0,
1524071357.832,,0.000000e+000,5.499445e+001,-3.734834e-006,0.000000e+000,3,8.839473e-001,0.000000e+000,,,,,,,,,,,,,,32,1,4.000000e+000,1.314926e-002,0.000000e+000,0,,0,
1524071395.052,,0.000000e+000,5.499840e+001,-3.492776e-006,0.000000e+000,3,8.990012e-001,0.000000e+000,,,,,,,,,,,,,,32,1,4.000000e+000,2.628326e-003,0.000000e+000,0,,0,
1524071432.632,,0.000000e+000,5.499905e+001,-3.392027e-006,0.000000e+000,3,8.748249e-001,0.000000e+000,,,,,,,,,,,,,,32,1,4.000000e+000,1.319885e-003,0.000000e+000,0,,0,
1524071470.672,,0.000000e+000,5.499708e+001,-3.218145e-006,0.000000e+000,3,8.752330e-001,0.000000e+000,,,,,,,,,,,,,,32,1,4.000000e+000,2.620697e-003,0.000000e+000,0,,0,
1524071533.462,,0.000000e+000,5.499708e+001,-3.087938e-006,0.000000e+000,3,8.564832e-001,0.000000e+000,,,,,,,,,,,,,,32,1,4.000000e+000,2.620697e-003,0.000000e+000,0,,0,
1524071571.432,,0.000000e+000,5.499773e+001,-2.882920e-006,0.000000e+000,3,8.559250e-001,0.000000e+000,,,,,,,,,,,,,,32,1,4.000000e+000,1.308441e-003,0.000000e+000,0,,0,
1524071609.082,,0.000000e+000,5.499774e+001,-2.851462e-006,0.000000e+000,3,8.418641e-001,0.000000e+000,,,,,,,,,,,,,,32,1,4.000000e+000,3.940582e-003,0.000000e+000,0,,0,
1524071647.022,,0.000000e+000,5.500301e+001,-2.760337e-006,0.000000e+000,3,8.327464e-001,0.000000e+000,,,,,,,,,,,,,,32,1,4.000000e+000,1.319885e-003,0.000000e+000,0,,0,
1524071684.782,,0.000000e+000,5.499773e+001,-2.763717e-006,0.000000e+000,3,8.110650e-001,0.000000e+000,,,,,,,,,,,,,,32,1,4.000000e+000,1.308441e-003,0.000000e+000,0,,0,
1524071722.652,,0.000000e+000,5.499972e+001,-2.728157e-006,0.000000e+000,3,8.038133e-001,0.000000e+000,,,,,,,,,,,,,,32,1,4.000000e+000,5.268097e-003,0.000000e+000,0,,0,
1524071760.242,,0.000000e+000,5.500234e+001,-2.816743e-006,0.000000e+000,3,6.486411e-001,0.000000e+000,,,,,,,,,,,,,,32,1,4.000000e+000,7.900238e-003,0.000000e+000,0,,0,
1524071801.724,,0.000000e+000,5.499380e+001,-7.580510e-007,0.000000e+000,2,0.000000e+000,0.000000e+000,,,,,,,,,,,,,,32,1,4.000000e+000,3.948212e-003,0.000000e+000,0,,0,
1524071844.180,,0.000000e+000,5.499380e+001,-6.572668e-007,0.000000e+000,2,0.000000e+000,0.000000e+000,,,,,,,,,,,,,,32,1,4.000000e+000,1.308441e-003,0.000000e+000,0,,0,
1524071886.826,,0.000000e+000,5.499905e+001,-4.500974e-007,0.000000e+000,2,0.000000e+000,0.000000e+000,,,,,,,,,,,,,,32,1,4.000000e+000,3.948212e-003,0.000000e+000,0,,0,
1524071929.072,,0.000000e+000,5.499840e+001,-4.214648e-007,0.000000e+000,2,0.000000e+000,0.000000e+000,,,,,,,,,,,,,,32,1,4.000000e+000,5.260468e-003,0.000000e+000,0,,0,
1524071969.596,,0.000000e+000,5.499971e+001,-3.668187e-007,0.000000e+000,2,0.000000e+000,0.000000e+000,,,,,,,,,,,,,,32,1,4.000000e+000,2.639771e-003,0.000000e+000,0,,0,
1524072007.237,,0.000000e+000,5.499445e+001,2.507481e-006,0.000000e+000,3,6.493482e-001,0.000000e+000,,,,,,,,,,,,,,32,1,4.000000e+000,2.628326e-003,0.000000e+000,0,,0,
1524072044.897,,0.000000e+000,5.499773e+001,2.415550e-006,0.000000e+000,3,6.168742e-001,0.000000e+000,,,,,,,,,,,,,,32,1,4.000000e+000,1.308441e-003,0.000000e+000,0,,0,
1524072083.197,,0.000000e+000,5.499643e+001,2.519384e-006,0.000000e+000,3,6.569571e-001,0.000000e+000,,,,,,,,,,,,,,32,1,4.000000e+000,9.208679e-003,0.000000e+000,0,,0,
1524072120.507,,0.000000e+000,5.499577e+001,-2.622606e-006,0.000000e+000,3,7.722554e-001,0.000000e+000,,,,,,,,,,,,,,32,1,4.000000e+000,2.632141e-003,0.000000e+000,0,,0,
1524072161.801,,0.000000e+000,5.500103e+001,-2.721539e-006,0.000000e+000,3,7.263289e-001,0.000000e+000,,,,,,,,,,,,,,32,1,4.000000e+000,2.639771e-003,0.000000e+000,0,,0,
1524072199.821,,0.000000e+000,5.499972e+001,-2.624251e-006,0.000000e+000,3,7.484150e-001,0.000000e+000,,,,,,,,,,,,,,32,1,4.000000e+000,5.268097e-003,0.000000e+000,0,,0,
1524072262.121,,0.000000e+000,5.499971e+001,-2.695116e-006,0.000000e+000,3,7.309280e-001,0.000000e+000,,,,,,,,,,,,,,32,1,4.000000e+000,0.000000e+000,0.000000e+000,0,,0,
1524072301.543,,0.000000e+000,5.500037e+001,2.892733e-007,0.000000e+000,2,0.000000e+000,0.000000e+000,,,,,,,,,,,,,,32,1,4.000000e+000,1.319885e-003,0.000000e+000,0,,0,
1524072367.357,,0.000000e+000,5.500629e+001,4.235779e-007,0.000000e+000,2,0.000000e+000,0.000000e+000,,,,,,,,,,,,,,32,1,4.000000e+000,7.888794e-003,0.000000e+000,0,,0,
1524072409.833,,0.000000e+000,5.500103e+001,4.970701e-007,0.000000e+000,2,0.000000e+000,0.000000e+000,,,,,,,,,,,,,,32,1,4.000000e+000,1.052094e-002,0.000000e+000,0,,0,
1524072452.179,,0.000000e+000,5.500037e+001,6.148468e-007,0.000000e+000,2,0.000000e+000,0.000000e+000,,,,,,,,,,,,,,32,1,4.000000e+000,1.319885e-003,0.000000e+000,0,,0,
1524072494.435,,0.000000e+000,5.500432e+001,6.364061e-007,0.000000e+000,2,0.000000e+000,0.000000e+000,,,,,,,,,,,,,,32,1,4.000000e+000,1.300812e-003,0.000000e+000,0,,0,
1524072534.619,,0.000000e+000,5.499248e+001,2.073102e-006,0.000000e+000,3,7.426900e-001,0.000000e+000,,,,,,,,,,,,,,32,1,4.000000e+000,6.580353e-003,0.000000e+000,0,,0,
1524072575.793,,0.000000e+000,5.499313e+001,6.081410e-007,0.000000e+000,2,0.000000e+000,0.000000e+000,,,,,,,,,,,,,,32,1,4.000000e+000,1.314926e-002,0.000000e+000,0,,0,
1524072614.995,,0.000000e+000,5.499708e+001,7.012818e-007,0.000000e+000,2,0.000000e+000,0.000000e+000,,,,,,,,,,,,,,32,1,4.000000e+000,2.620697e-003,0.000000e+000,0,,0,
1524072652.005,,0.000000e+000,5.500037e+001,2.222344e-006,0.000000e+000,3,7.100492e-001,0.000000e+000,,,,,,,,,,,,,,32,1,4.000000e+000,1.319885e-003,0.000000e+000,0,,0,
1524072689.615,,0.000000e+000,5.500103e+001,2.160004e-006,0.000000e+000,3,7.340943e-001,0.000000e+000,,,,,,,,,,,,,,32,1,4.000000e+000,7.888794e-003,0.000000e+000,0,,0,
1524072728.086,,0.000000e+000,5.500037e+001,2.183137e-006,0.000000e+000,3,7.466180e-001,0.000000e+000,,,,,,,,,,,,,,32,1,4.000000e+000,3.959656e-003,0.000000e+000,0,,0,
1524072765.966,,0.000000e+000,5.499577e+001,2.287347e-006,0.000000e+000,3,7.271104e-001,0.000000e+000,,,,,,,,,,,,,,32,1,4.000000e+000,1.578903e-002,0.000000e+000,0,,0,
1524072804.616,,0.000000e+000,5.499708e+001,2.325696e-006,0.000000e+000,3,7.239758e-001,0.000000e+000,,,,,,,,,,,,,,32,1,4.000000e+000,0.000000e+000,0.000000e+000,0,,0,
1524072841.896,,0.000000e+000,5.499774e+001,2.181012e-006,0.000000e+000,3,7.743640e-001,0.000000e+000,,,,,,,,,,,,,,32,1,4.000000e+000,3.940582e-003,0.000000e+000,0,,0,
1524072879.456,,0.000000e+000,5.499643e+001,2.266149e-006,0.000000e+000,3,7.371439e-001,0.000000e+000,,,,,,,,,,,,,,32,1,4.000000e+000,1.312256e-003,0.000000e+000,0,,0,
1524073030.866,,0.000000e+000,5.499577e+001,2.397930e-006,0.000000e+000,3,7.492426e-001,0.000000e+000,,,,,,,,,,,,,,32,1,4.000000e+000,7.888794e-003,0.000000e+000,0,,0,
1524073068.436,,0.000000e+000,5.499380e+001,2.363886e-006,0.000000e+000,3,7.489547e-001,0.000000e+000,,,,,,,,,,,,,,32,1,4.000000e+000,3.948212e-003,0.000000e+000,0,,0,
1524073107.306,,0.000000e+000,5.500169e+001,2.433158e-006,0.000000e+000,3,7.674653e-001,0.000000e+000,,,,,,,,,,,,,,32,1,4.000000e+000,1.319885e-003,0.000000e+000,0,,0,
1524073145.036,,0.000000e+000,5.499708e+001,2.515883e-006,0.000000e+000,3,7.803403e-001,0.000000e+000,,,,,,,,,,,,,,32,1,4.000000e+000,0.000000e+000,0.000000e+000,0,,0,
1524073182.186,,0.000000e+000,5.500037e+001,2.510636e-006,0.000000e+000,3,7.624120e-001,0.000000e+000,,,,,,,,,,,,,,32,1,4.000000e+000,6.587982e-003,0.000000e+000,0,,0,
1524073220.406,,0.000000e+000,5.499972e+001,2.537694e-006,0.000000e+000,3,7.839358e-001,0.000000e+000,,,,,,,,,,,,,,32,1,4.000000e+000,7.900238e-003,0.000000e+000,0,,0,
1524073270.956,,0.000000e+000,5.499643e+001,2.513701e-006,0.000000e+000,3,7.775705e-001,0.000000e+000,,,,,,,,,,,,,,32,1,4.000000e+000,1.312256e-003,0.000000e+000,0,,0,
1524073308.656,,0.000000e+000,5.499642e+001,2.704525e-006,0.000000e+000,3,7.677669e-001,0.000000e+000,,,,,,,,,,,,,,32,1,4.000000e+000,3.940582e-003,0.000000e+000,0,,0,
1524073422.296,,0.000000e+000,5.499971e+001,2.651725e-006,0.000000e+000,3,7.711589e-001,0.000000e+000,,,,,,,,,,,,,,32,1,4.000000e+000,2.639771e-003,0.000000e+000,0,,0,
1524073459.917,,0.000000e+000,5.500235e+001,2.661037e-006,0.000000e+000,3,8.021341e-001,0.000000e+000,,,,,,,,,,,,,,32,1,4.000000e+000,2.639771e-003,0.000000e+000,0,,0,
1524073522.827,,0.000000e+000,5.499774e+001,2.709162e-006,0.000000e+000,3,7.649423e-001,0.000000e+000,,,,,,,,,,,,,,32,1,4.000000e+000,3.940582e-003,0.000000e+000,0,,0,
1524073585.817,,0.000000e+000,5.499905e+001,2.631773e-006,0.000000e+000,3,7.916461e-001,0.000000e+000,,,,,,,,,,,,,,32,1,4.000000e+000,3.948212e-003,0.000000e+000,0,,0,
1524073623.127,,0.000000e+000,5.499708e+001,2.764576e-006,0.000000e+000,3,8.003426e-001,0.000000e+000,,,,,,,,,,,,,,32,1,4.000000e+000,0.000000e+000,0.000000e+000,0,,0,
1524073660.477,,0.000000e+000,5.500235e+001,2.669887e-006,0.000000e+000,3,8.250660e-001,0.000000e+000,,,,,,,,,,,,,,32,1,4.000000e+000,2.639771e-003,0.000000e+000,0,,0,
1524073698.987,,0.000000e+000,5.500234e+001,2.792810e-006,0.000000e+000,3,7.921138e-001,0.000000e+000,,,,,,,,,,,,,,32,1,4.000000e+000,5.260468e-003,0.000000e+000,0,,0,
1524073736.237,,0.000000e+000,5.500169e+001,2.682207e-006,0.000000e+000,3,8.036987e-001,0.000000e+000,,,,,,,,,,,,,,32,1,4.000000e+000,3.959656e-003,0.000000e+000,0,,0,
1524073799.557,,0.000000e+000,5.500037e+001,2.695291e-006,0.000000e+000,3,8.156821e-001,0.000000e+000,,,,,,,,,,,,,,32,1,4.000000e+000,9.201050e-003,0.000000e+000,0,,0,
1524073837.247,,0.000000e+000,5.500497e+001,2.742014e-006,0.000000e+000,3,8.168547e-001,0.000000e+000,,,,,,,,,,,,,,32,1,4.000000e+000,7.888794e-003,0.000000e+000,0,,0,
1524073950.517,,0.000000e+000,5.499708e+001,2.858666e-006,0.000000e+000,3,8.113447e-001,0.000000e+000,,,,,,,,,,,,,,32,1,4.000000e+000,2.620697e-003,0.000000e+000,0,,0,
1524074013.337,,0.000000e+000,5.500366e+001,2.758941e-006,0.000000e+000,3,8.208201e-001,0.000000e+000,,,,,,,,,,,,,,32,1,4.000000e+000,2.620697e-003,0.000000e+000,0,,0,
1524074050.777,,0.000000e+000,5.499577e+001,2.891964e-006,0.000000e+000,3,8.158349e-001,0.000000e+000,,,,,,,,,,,,,,32,1,4.000000e+000,1.052094e-002,0.000000e+000,0,,0,
1524074088.227,,0.000000e+000,5.499643e+001,2.808426e-006,0.000000e+000,3,8.267723e-001,0.000000e+000,,,,,,,,,,,,,,32,1,4.000000e+000,1.312256e-003,0.000000e+000,0,,0,
1524074126.737,,0.000000e+000,5.500103e+001,2.809403e-006,0.000000e+000,3,8.270531e-001,0.000000e+000,,,,,,,,,,,,,,32,1,4.000000e+000,2.639771e-003,0.000000e+000,0,,0,
1524074163.838,,0.000000e+000,5.500037e+001,2.889941e-006,0.000000e+000,3,8.174124e-001,0.000000e+000,,,,,,,,,,,,,,32,1,4.000000e+000,1.319885e-003,0.000000e+000,0,,0,
1524074201.838,,0.000000e+000,5.499773e+001,2.900707e-006,0.000000e+000,3,8.472375e-001,0.000000e+000,,,,,,,,,,,,,,32,1,4.000000e+000,1.308441e-003,0.000000e+000,0,,0,
1524074238.868,,0.000000e+000,5.500037e+001,2.963636e-006,0.000000e+000,3,8.246823e-001,0.000000e+000,,,,,,,,,,,,,,32,1,4.000000e+000,1.319885e-003,0.000000e+000,0,,0,
1524074276.888,,0.000000e+000,5.499840e+001,2.900430e-006,0.000000e+000,3,8.168288e-001,0.000000e+000,,,,,,,,,,,,,,32,1,4.000000e+000,2.628326e-003,0.000000e+000,0,,0,
1524074315.318,,0.000000e+000,5.500103e+001,2.890868e-006,0.000000e+000,3,8.295693e-001,0.000000e+000,,,,,,,,,,,,,,32,1,4.000000e+000,5.279541e-003,0.000000e+000,0,,0,
1524074353.338,,0.000000e+000,5.499773e+001,2.941991e-006,0.000000e+000,3,8.367265e-001,0.000000e+000,,,,,,,,,,,,,,32,1,4.000000e+000,1.308441e-003,0.000000e+000,0,,0,
1524074391.398,,0.000000e+000,5.500301e+001,2.920533e-006,0.000000e+000,3,8.216445e-001,0.000000e+000,,,,,,,,,,,,,,32,1,4.000000e+000,1.319885e-003,0.000000e+000,0,,0,
1524074428.968,,0.000000e+000,5.499643e+001,2.970116e-006,0.000000e+000,3,8.185208e-001,0.000000e+000,,,,,,,,,,,,,,32,1,4.000000e+000,6.568909e-003,0.000000e+000,0,,0,
1524074466.848,,0.000000e+000,5.499840e+001,2.987748e-006,0.000000e+000,3,8.353775e-001,0.000000e+000,,,,,,,,,,,,,,32,1,4.000000e+000,2.628326e-003,0.000000e+000,0,,0,
1524074504.288,,0.000000e+000,5.499379e+001,3.046545e-006,0.000000e+000,3,8.320447e-001,0.000000e+000,,,,,,,,,,,,,,32,1,4.000000e+000,9.201050e-003,0.000000e+000,0,,0,
1524074541.468,,0.000000e+000,5.499117e+001,2.891645e-006,0.000000e+000,3,8.560364e-001,0.000000e+000,,,,,,,,,,,,,,32,1,4.000000e+000,6.568909e-003,0.000000e+000,0,,0,
1524074579.138,,0.000000e+000,5.500235e+001,3.007684e-006,0.000000e+000,3,8.272254e-001,0.000000e+000,,,,,,,,,,,,,,32,1,4.000000e+000,2.639771e-003,0.000000e+000,0,,0,
1524074616.538,,0.000000e+000,5.499445e+001,3.020419e-006,0.000000e+000,3,8.288214e-001,0.000000e+000,,,,,,,,,,,,,,32,1,4.000000e+000,5.260468e-003,0.000000e+000,0,,0,
1524074654.378,,0.000000e+000,5.499643e+001,3.031422e-006,0.000000e+000,3,8.612018e-001,0.000000e+000,,,,,,,,,,,,,,32,1,4.000000e+000,6.568909e-003,0.000000e+000,0,,0,
1524074692.248,,0.000000e+000,5.500169e+001,2.994838e-006,0.000000e+000,3,8.288959e-001,0.000000e+000,,,,,,,,,,,,,,32,1,4.000000e+000,1.319885e-003,0.000000e+000,0,,0,
1524074729.718,,0.000000e+000,5.499905e+001,2.987252e-006,0.000000e+000,3,8.524622e-001,0.000000e+000,,,,,,,,,,,,,,32,1,4.000000e+000,3.948212e-003,0.000000e+000,0,,0,
1524074767.458,,0.000000e+000,5.499775e+001,3.019686e-006,0.000000e+000,3,8.413262e-001,0.000000e+000,,,,,,,,,,,,,,32,1,4.000000e+000,9.208679e-003,0.000000e+000,0,,0,
1524074805.328,,0.000000e+000,5.500037e+001,2.971997e-006,0.000000e+000,3,8.593571e-001,0.000000e+000,,,,,,,,,,,,,,32,1,4.000000e+000,3.959656e-003,0.000000e+000,0,,0,
1524074843.078,,0.000000e+000,5.499840e+001,3.002662e-006,0.000000e+000,3,8.378980e-001,0.000000e+000,,,,,,,,,,,,,,32,1,4.000000e+000,2.628326e-003,0.000000e+000,0,,0,
1524074880.939,,0.000000e+000,5.499906e+001,3.064002e-006,0.000000e+000,3,8.516803e-001,0.000000e+000,,,,,,,,,,,,,,32,1,4.000000e+000,9.220123e-003,0.000000e+000,0,,0,
1524074918.259,,0.000000e+000,5.500103e+001,3.081424e-006,0.000000e+000,3,8.351682e-001,0.000000e+000,,,,,,,,,,,,,,32,1,4.000000e+000,7.888794e-003,0.000000e+000,0,,0,
1524074955.999,,0.000000e+000,5.499248e+001,3.029653e-006,0.000000e+000,3,8.532369e-001,0.000000e+000,,,,,,,,,,,,,,32,1,4.000000e+000,1.182938e-002,0.000000e+000,0,,0,
1524074993.409,,0.000000e+000,5.499775e+001,3.035575e-006,0.000000e+000,3,8.354442e-001,0.000000e+000,,,,,,,,,,,,,,32,1,4.000000e+000,9.208679e-003,0.000000e+000,0,,0,
1524075031.609,,0.000000e+000,5.499840e+001,3.099428e-006,0.000000e+000,3,8.518159e-001,0.000000e+000,,,,,,,,,,,,,,32,1,4.000000e+000,2.628326e-003,0.000000e+000,0,,0,
1524075069.359,,0.000000e+000,5.499643e+001,3.154124e-006,0.000000e+000,3,8.465225e-001,0.000000e+000,,,,,,,,,,,,,,32,1,4.000000e+000,9.208679e-003,0.000000e+000,0,,0,
1524075107.219,,0.000000e+000,5.499577e+001,3.113568e-006,0.000000e+000,3,8.590726e-001,0.000000e+000,,,,,,,,,,,,,,32,1,4.000000e+000,0.000000e+000,0.000000e+000,0,,0,
1524075145.129,,0.000000e+000,5.499642e+001,3.146942e-006,0.000000e+000,3,8.415453e-001,0.000000e+000,,,,,,,,,,,,,,32,1,4.000000e+000,3.940582e-003,0.000000e+000,0,,0,
1524075182.499,,0.000000e+000,5.500103e+001,3.087222e-006,0.000000e+000,3,8.584203e-001,0.000000e+000,,,,,,,,,,,,,,32,1,4.000000e+000,2.639771e-003,0.000000e+000,0,,0,
1524075219.409,,0.000000e+000,5.499839e+001,3.180557e-006,0.000000e+000,3,8.420102e-001,0.000000e+000,,,,,,,,,,,,,,32,1,4.000000e+000,0.000000e+000,0.000000e+000,0,,0,
1524075256.819,,0.000000e+000,5.499840e+001,3.078685e-006,0.000000e+000,3,8.501684e-001,0.000000e+000,,,,,,,,,,,,,,32,1,4.000000e+000,5.260468e-003,0.000000e+000,0,,0,
1524075294.399,,0.000000e+000,5.499642e+001,3.172848e-006,0.000000e+000,3,8.361933e-001,0.000000e+000,,,,,,,,,,,,,,32,1,4.000000e+000,3.940582e-003,0.000000e+000,0,,0,
1524075332.119,,0.000000e+000,5.500103e+001,3.106795e-006,0.000000e+000,3,8.561422e-001,0.000000e+000,,,,,,,,,,,,,,32,1,4.000000e+000,7.888794e-003,0.000000e+000,0,,0,
1524075370.549,,0.000000e+000,5.500037e+001,3.155546e-006,0.000000e+000,3,8.789809e-001,0.000000e+000,,,,,,,,,,,,,,32,1,4.000000e+000,1.319885e-003,0.000000e+000,0,,0,
1524075408.109,,0.000000e+000,5.500300e+001,3.183904e-006,0.000000e+000,3,8.552190e-001,0.000000e+000,,,,,,,,,,,,,,32,1,4.000000e+000,3.940582e-003,0.000000e+000,0,,0,
1524075445.509,,0.000000e+000,5.499117e+001,3.015609e-006,0.000000e+000,3,8.665373e-001,0.000000e+000,,,,,,,,,,,,,,32,1,4.000000e+000,1.183319e-002,0.000000e+000,0,,0,
1524075483.189,,0.000000e+000,5.500169e+001,3.233970e-006,0.000000e+000,3,8.493020e-001,0.000000e+000,,,,,,,,,,,,,,32,1,4.000000e+000,9.208679e-003,0.000000e+000,0,,0,
1524075521.119,,0.000000e+000,5.500037e+001,3.140189e-006,0.000000e+000,3,8.737966e-001,0.000000e+000,,,,,,,,,,,,,,32,1,4.000000e+000,6.587982e-003,0.000000e+000,0,,0,
1524075558.779,,0.000000e+000,5.499840e+001,3.197153e-006,0.000000e+000,3,8.448952e-001,0.000000e+000,,,,,,,,,,,,,,32,1,4.000000e+000,2.628326e-003,0.000000e+000,0,,0,
1524075596.720,,0.000000e+000,5.499511e+001,3.190375e-006,0.000000e+000,3,8.697234e-001,0.000000e+000,,,,,,,,,,,,,,32,1,4.000000e+000,6.568909e-003,0.000000e+000,0,,0,
1524075634.040,,0.000000e+000,5.499841e+001,3.218973e-006,0.000000e+000,3,8.440422e-001,0.000000e+000,,,,,,,,,,,,,,32,1,4.000000e+000,1.052856e-002,0.000000e+000,0,,0,
1524075671.800,,0.000000e+000,5.499840e+001,3.215805e-006,0.000000e+000,3,8.698200e-001,0.000000e+000,,,,,,,,,,,,,,32,1,4.000000e+000,2.628326e-003,0.000000e+000,0,,0,
1524075709.440,,0.000000e+000,5.499972e+001,3.282387e-006,0.000000e+000,3,8.557441e-001,0.000000e+000,,,,,,,,,,,,,,32,1,4.000000e+000,7.900238e-003,0.000000e+000,0,,0,
1524075747.940,,0.000000e+000,5.499773e+001,3.191710e-006,0.000000e+000,3,8.674839e-001,0.000000e+000,,,,,,,,,,,,,,32,1,4.000000e+000,1.308441e-003,0.000000e+000,0,,0,
1524075786.270,,0.000000e+000,5.499445e+001,3.149980e-006,0.000000e+000,3,8.726398e-001,0.000000e+000,,,,,,,,,,,,,,32,1,4.000000e+000,0.000000e+000,0.000000e+000,0,,0,
1524075823.750,,0.000000e+000,5.499642e+001,3.306583e-006,0.000000e+000,3,8.791844e-001,0.000000e+000,,,,,,,,,,,,,,32,1,4.000000e+000,3.940582e-003,0.000000e+000,0,,0,
1524075861.580,,0.000000e+000,5.500037e+001,3.247666e-006,0.000000e+000,3,8.602073e-001,0.000000e+000,,,,,,,,,,,,,,32,1,4.000000e+000,3.959656e-003,0.000000e+000,0,,0,
1524075899.500,,0.000000e+000,5.499840e+001,3.275439e-006,0.000000e+000,3,8.755073e-001,0.000000e+000,,,,,,,,,,,,,,32,1,4.000000e+000,5.260468e-003,0.000000e+000,0,,0,
1524075937.460,,0.000000e+000,5.500103e+001,3.378112e-006,0.000000e+000,3,8.607540e-001,0.000000e+000,,,,,,,,,,,,,,32,1,4.000000e+000,2.639771e-003,0.000000e+000,0,,0,
1524075975.340,,0.000000e+000,5.499643e+001,3.264364e-006,0.000000e+000,3,8.637342e-001,0.000000e+000,,,,,,,,,,,,,,32,1,4.000000e+000,1.312256e-003,0.000000e+000,0,,0,
1524076012.950,,0.000000e+000,5.500103e+001,3.288331e-006,0.000000e+000,3,8.497612e-001,0.000000e+000,,,,,,,,,,,,,,32,1,4.000000e+000,7.888794e-003,0.000000e+000,0,,0,
1524076050.950,,0.000000e+000,5.499577e+001,3.296863e-006,0.000000e+000,3,8.744144e-001,0.000000e+000,,,,,,,,,,,,,,32,1,4.000000e+000,1.052094e-002,0.000000e+000,0,,0,
1524076088.560,,0.000000e+000,5.499840e+001,3.333656e-006,0.000000e+000,3,8.610103e-001,0.000000e+000,,,,,,,,,,,,,,32,1,4.000000e+000,2.628326e-003,0.000000e+000,0,,0,
1524076126.560,,0.000000e+000,5.499773e+001,3.329926e-006,0.000000e+000,3,8.691254e-001,0.000000e+000,,,,,,,,,,,,,,32,1,4.000000e+000,1.308441e-003,0.000000e+000,0,,0,
1524076164.190,,0.000000e+000,5.499905e+001,3.319598e-006,0.000000e+000,3,8.537566e-001,0.000000e+000,,,,,,,,,,,,,,32,1,4.000000e+000,3.948212e-003,0.000000e+000,0,,0,
1524076202.170,,0.000000e+000,5.500695e+001,3.295413e-006,0.000000e+000,3,8.657282e-001,0.000000e+000,,,,,,,,,,,,,,32,1,4.000000e+000,1.184082e-002,0.000000e+000,0,,0,
1524076239.860,,0.000000e+000,5.499708e+001,3.362211e-006,0.000000e+000,3,8.540754e-001,0.000000e+000,,,,,,,,,,,,,,32,1,4.000000e+000,0.000000e+000,0.000000e+000,0,,0,
1524076277.870,,0.000000e+000,5.499445e+001,3.365814e-006,0.000000e+000,3,8.870191e-001,0.000000e+000,,,,,,,,,,,,,,32,1,4.000000e+000,5.260468e-003,0.000000e+000,0,,0,
1524076315.551,,0.000000e+000,5.500169e+001,3.415873e-006,0.000000e+000,3,8.572474e-001,0.000000e+000,,,,,,,,,,,,,,32,1,4.000000e+000,9.208679e-003,0.000000e+000,0,,0,
1524076353.411,,0.000000e+000,5.500432e+001,3.283223e-006,0.000000e+000,3,8.801397e-001,0.000000e+000,,,,,,,,,,,,,,32,1,4.000000e+000,3.940582e-003,0.000000e+000,0,,0,
1524076391.061,,0.000000e+000,5.499773e+001,3.361436e-006,0.000000e+000,3,8.572432e-001,0.000000e+000,,,,,,,,,,,,,,32,1,4.000000e+000,1.308441e-003,0.000000e+000,0,,0,
1524076429.041,,0.000000e+000,5.500235e+001,3.337163e-006,0.000000e+000,3,8.779714e-001,0.000000e+000,,,,,,,,,,,,,,32,1,4.000000e+000,0.000000e+000,0.000000e+000,0,,0,
1524076466.651,,0.000000e+000,5.499906e+001,3.362051e-006,0.000000e+000,3,8.551932e-001,0.000000e+000,,,,,,,,,,,,,,32,1,4.000000e+000,6.580353e-003,0.000000e+000,0,,0,
1524076504.661,,0.000000e+000,5.499643e+001,3.350820e-006,0.000000e+000,3,8.753700e-001,0.000000e+000,,,,,,,,,,,,,,32,1,4.000000e+000,6.568909e-003,0.000000e+000,0,,0,
1524076541.961,,0.000000e+000,5.499248e+001,3.385965e-006,0.000000e+000,3,8.600821e-001,0.000000e+000,,,,,,,,,,,,,,32,1,4.000000e+000,9.201050e-003,0.000000e+000,0,,0,
1524076579.701,,0.000000e+000,5.499511e+001,3.367431e-006,0.000000e+000,3,8.772472e-001,0.000000e+000,,,,,,,,,,,,,,32,1,4.000000e+000,1.319885e-003,0.000000e+000,0,,0,
1524076617.081,,0.000000e+000,5.499905e+001,3.398267e-006,0.000000e+000,3,8.648801e-001,0.000000e+000,,,,,,,,,,,,,,32,1,4.000000e+000,3.948212e-003,0.000000e+000,0,,0,
1524076654.461,,0.000000e+000,5.500103e+001,3.274540e-006,0.000000e+000,3,8.953363e-001,0.000000e+000,,,,,,,,,,,,,,32,1,4.000000e+000,2.639771e-003,0.000000e+000,0,,0,
1524076691.811,,0.000000e+000,5.499708e+001,3.369545e-006,0.000000e+000,3,8.715003e-001,0.000000e+000,,,,,,,,,,,,,,32,1,4.000000e+000,5.260468e-003,0.000000e+000,0,,0,
1524076729.471,,0.000000e+000,5.499774e+001,3.312598e-006,0.000000e+000,3,8.711432e-001,0.000000e+000,,,,,,,,,,,,,,32,1,4.000000e+000,3.940582e-003,0.000000e+000,0,,0,
1524076767.761,,0.000000e+000,5.499708e+001,3.272940e-006,0.000000e+000,3,8.848684e-001,0.000000e+000,,,,,,,,,,,,,,32,1,4.000000e+000,2.620697e-003,0.000000e+000,0,,0,
1524076804.381,,0.000000e+000,5.498985e+001,3.302955e-006,0.000000e+000,3,8.610475e-001,0.000000e+000,,,,,,,,,,,,,,32,1,4.000000e+000,6.580353e-003,0.000000e+000,0,,0,
1524076841.701,,0.000000e+000,5.499577e+001,3.346033e-006,0.000000e+000,3,8.675355e-001,0.000000e+000,,,,,,,,,,,,,,32,1,4.000000e+000,5.249023e-003,0.000000e+000,0,,0,
1524076904.871,,0.000000e+000,5.500300e+001,3.400069e-006,0.000000e+000,3,8.910537e-001,0.000000e+000,,,,,,,,,,,,,,32,1,4.000000e+000,3.940582e-003,0.000000e+000,0,,0,
1524076941.991,,0.000000e+000,5.499906e+001,3.331063e-006,0.000000e+000,3,8.798981e-001,0.000000e+000,,,,,,,,,,,,,,32,1,4.000000e+000,6.580353e-003,0.000000e+000,0,,0,
1524076979.581,,0.000000e+000,5.500497e+001,3.363242e-006,0.000000e+000,3,8.712152e-001,0.000000e+000,,,,,,,,,,,,,,32,1,4.000000e+000,1.316071e-002,0.000000e+000,0,,0,
1524077042.092,,0.000000e+000,5.499775e+001,3.359720e-006,0.000000e+000,3,8.891552e-001,0.000000e+000,,,,,,,,,,,,,,32,1,4.000000e+000,9.208679e-003,0.000000e+000,0,,0,
1524077080.012,,0.000000e+000,5.499971e+001,3.372030e-006,0.000000e+000,3,9.024563e-001,0.000000e+000,,,,,,,,,,,,,,32,1,4.000000e+000,1.052094e-002,0.000000e+000,0,,0,
1524077117.612,,0.000000e+000,5.499511e+001,3.426211e-006,0.000000e+000,3,8.767408e-001,0.000000e+000,,,,,,,,,,,,,,32,1,4.000000e+000,1.184082e-002,0.000000e+000,0,,0,
1524077155.592,,0.000000e+000,5.499643e+001,3.392431e-006,0.000000e+000,3,8.804247e-001,0.000000e+000,,,,,,,,,,,,,,32,1,4.000000e+000,1.312256e-003,0.000000e+000,0,,0,
1524077193.162,,0.000000e+000,5.500169e+001,3.417805e-006,0.000000e+000,3,8.704830e-001,0.000000e+000,,,,,,,,,,,,,,32,1,4.000000e+000,3.959656e-003,0.000000e+000,0,,0,
1524077231.202,,0.000000e+000,5.500169e+001,3.373890e-006,0.000000e+000,3,8.880191e-001,0.000000e+000,,,,,,,,,,,,,,32,1,4.000000e+000,1.319885e-003,0.000000e+000,0,,0,
1524077268.812,,0.000000e+000,5.500103e+001,3.407260e-006,0.000000e+000,3,8.713639e-001,0.000000e+000,,,,,,,,,,,,,,32,1,4.000000e+000,2.639771e-003,0.000000e+000,0,,0,
1524077306.832,,0.000000e+000,5.500695e+001,3.409683e-006,0.000000e+000,3,8.903566e-001,0.000000e+000,,,,,,,,,,,,,,32,1,4.000000e+000,6.568909e-003,0.000000e+000,0,,0,
1524077344.432,,0.000000e+000,5.499972e+001,3.454119e-006,0.000000e+000,3,8.677674e-001,0.000000e+000,,,,,,,,,,,,,,32,1,4.000000e+000,7.900238e-003,0.000000e+000,0,,0,
1524077382.452,,0.000000e+000,5.499445e+001,3.385931e-006,0.000000e+000,3,8.863118e-001,0.000000e+000,,,,,,,,,,,,,,32,1,4.000000e+000,5.260468e-003,0.000000e+000,0,,0,
1524077420.122,,0.000000e+000,5.499511e+001,3.418007e-006,0.000000e+000,3,8.878424e-001,0.000000e+000,,,,,,,,,,,,,,32,1,4.000000e+000,1.319885e-003,0.000000e+000,0,,0,
1524077508.512,,0.000000e+000,5.500169e+001,3.500574e-006,0.000000e+000,3,8.800343e-001,0.000000e+000,,,,,,,,,,,,,,32,1,4.000000e+000,1.319885e-003,0.000000e+000,0,,0,
1524077546.102,,0.000000e+000,5.499774e+001,3.536535e-006,0.000000e+000,3,8.712425e-001,0.000000e+000,,,,,,,,,,,,,,32,1,4.000000e+000,3.940582e-003,0.000000e+000,0,,0,
1524077584.152,,0.000000e+000,5.500037e+001,3.522298e-006,0.000000e+000,3,8.867946e-001,0.000000e+000,,,,,,,,,,,,,,32,1,4.000000e+000,1.319885e-003,0.000000e+000,0,,0,
1524077621.682,,0.000000e+000,5.499971e+001,3.552727e-006,0.000000e+000,3,8.723638e-001,0.000000e+000,,,,,,,,,,,,,,32,1,4.000000e+000,2.639771e-003,0.000000e+000,0,,0,
1524077684.182,,0.000000e+000,5.499774e+001,3.518167e-006,0.000000e+000,3,8.874493e-001,0.000000e+000,,,,,,,,,,,,,,32,1,4.000000e+000,6.580353e-003,0.000000e+000,0,,0,
1524077721.543,,0.000000e+000,5.499971e+001,3.550274e-006,0.000000e+000,3,8.690013e-001,0.000000e+000,,,,,,,,,,,,,,32,1,4.000000e+000,0.000000e+000,0.000000e+000,0,,0,
1524077784.653,,0.000000e+000,5.500629e+001,3.592039e-006,0.000000e+000,3,8.931762e-001,0.000000e+000,,,,,,,,,,,,,,32,1,4.000000e+000,7.888794e-003,0.000000e+000,0,,0,
1524077861.603,,0.000000e+000,5.500103e+001,3.554731e-006,0.000000e+000,3,8.967583e-001,0.000000e+000,,,,,,,,,,,,,,32,1,4.000000e+000,5.279541e-003,0.000000e+000,0,,0,
1524077898.863,,0.000000e+000,5.499905e+001,3.576672e-006,0.000000e+000,3,8.801805e-001,0.000000e+000,,,,,,,,,,,,,,32,1,4.000000e+000,1.319885e-003,0.000000e+000,0,,0,
1524077936.603,,0.000000e+000,5.499773e+001,3.512810e-006,0.000000e+000,3,8.848605e-001,0.000000e+000,,,,,,,,,,,,,,32,1,4.000000e+000,1.308441e-003,0.000000e+000,0,,0,
1524077974.583,,0.000000e+000,5.499445e+001,3.472885e-006,0.000000e+000,3,8.849432e-001,0.000000e+000,,,,,,,,,,,,,,32,1,4.000000e+000,2.628326e-003,0.000000e+000,0,,0,
1524078012.423,,0.000000e+000,5.499313e+001,3.480664e-006,0.000000e+000,3,8.823777e-001,0.000000e+000,,,,,,,,,,,,,,32,1,4.000000e+000,2.628326e-003,0.000000e+000,0,,0,
1524078050.453,,0.000000e+000,5.500300e+001,3.487011e-006,0.000000e+000,3,8.873867e-001,0.000000e+000,,,,,,,,,,,,,,32,1,4.000000e+000,9.220123e-003,0.000000e+000,0,,0,
1524078088.543,,0.000000e+000,5.499708e+001,3.529262e-006,0.000000e+000,3,8.887599e-001,0.000000e+000,,,,,,,,,,,,,,32,1,4.000000e+000,5.260468e-003,0.000000e+000,0,,0,
1524078126.133,,0.000000e+000,5.500301e+001,3.560720e-006,0.000000e+000,3,8.760728e-001,0.000000e+000,,,,,,,,,,,,,,32,1,4.000000e+000,1.319885e-003,0.000000e+000,0,,0,
1524078165.013,,0.000000e+000,5.499577e+001,3.523385e-006,0.000000e+000,3,9.039550e-001,0.000000e+000,,,,,,,,,,,,,,32,1,4.000000e+000,1.052094e-002,0.000000e+000,0,,0,
1524078202.873,,0.000000e+000,5.499972e+001,3.493950e-006,0.000000e+000,3,9.057642e-001,0.000000e+000,,,,,,,,,,,,,,32,1,4.000000e+000,5.268097e-003,0.000000e+000,0,,0,
1524078240.423,,0.000000e+000,5.499642e+001,3.493920e-006,0.000000e+000,3,8.821234e-001,0.000000e+000,,,,,,,,,,,,,,32,1,4.000000e+000,3.940582e-003,0.000000e+000,0,,0,
1524078278.373,,0.000000e+000,5.499643e+001,3.488698e-006,0.000000e+000,3,8.938466e-001,0.000000e+000,,,,,,,,,,,,,,32,1,4.000000e+000,1.312256e-003,0.000000e+000,0,,0,
1524078315.973,,0.000000e+000,5.499117e+001,3.584584e-006,0.000000e+000,3,8.830463e-001,0.000000e+000,,,,,,,,,,,,,,32,1,4.000000e+000,6.568909e-003,0.000000e+000,0,,0,
1524078378.583,,0.000000e+000,5.499709e+001,3.516917e-006,0.000000e+000,3,8.812389e-001,0.000000e+000,,,,,,,,,,,,,,32,1,4.000000e+000,1.052856e-002,0.000000e+000,0,,0,
1524078416.083,,0.000000e+000,5.499708e+001,3.498056e-006,0.000000e+000,3,8.905040e-001,0.000000e+000,,,,,,,,,,,,,,32,1,4.000000e+000,5.260468e-003,0.000000e+000,0,,0,
1524078453.864,,0.000000e+000,5.499773e+001,3.540720e-006,0.000000e+000,3,8.923571e-001,0.000000e+000,,,,,,,,,,,,,,32,1,4.000000e+000,1.308441e-003,0.000000e+000,0,,0,
1524078490.854,,0.000000e+000,5.499774e+001,3.618930e-006,0.000000e+000,3,8.901812e-001,0.000000e+000,,,,,,,,,,,,,,32,1,4.000000e+000,6.580353e-003,0.000000e+000,0,,0,
1524078528.784,,0.000000e+000,5.499577e+001,3.513097e-006,0.000000e+000,3,8.826805e-001,0.000000e+000,,,,,,,,,,,,,,32,1,4.000000e+000,1.578903e-002,0.000000e+000,0,,0,
1524078565.944,,0.000000e+000,5.499905e+001,3.538014e-006,0.000000e+000,3,8.798174e-001,0.000000e+000,,,,,,,,,,,,,,32,1,4.000000e+000,3.948212e-003,0.000000e+000,0,,0,
1524078603.294,,0.000000e+000,5.499379e+001,3.479100e-006,0.000000e+000,3,8.868382e-001,0.000000e+000,,,,,,,,,,,,,,32,1,4.000000e+000,9.201050e-003,0.000000e+000,0,,0,
1524078640.954,,0.000000e+000,5.499972e+001,3.551640e-006,0.000000e+000,3,8.752604e-001,0.000000e+000,,,,,,,,,,,,,,32,1,4.000000e+000,5.268097e-003,0.000000e+000,0,,0,
1524078678.504,,0.000000e+000,5.499773e+001,3.538480e-006,0.000000e+000,3,9.015569e-001,0.000000e+000,,,,,,,,,,,,,,32,1,4.000000e+000,1.308441e-003,0.000000e+000,0,,0,
1524078715.904,,0.000000e+000,5.499774e+001,3.629698e-006,0.000000e+000,3,8.911622e-001,0.000000e+000,,,,,,,,,,,,,,32,1,4.000000e+000,3.940582e-003,0.000000e+000,0,,0,
1524078753.044,,0.000000e+000,5.499774e+001,3.547347e-006,0.000000e+000,3,8.906417e-001,0.000000e+000,,,,,,,,,,,,,,32,1,4.000000e+000,6.580353e-003,0.000000e+000,0,,0,
1524078791.344,,0.000000e+000,5.500103e+001,3.521268e-006,0.000000e+000,3,8.966949e-001,0.000000e+000,,,,,,,,,,,,,,32,1,4.000000e+000,0.000000e+000,0.000000e+000,0,,0,
1524078828.914,,0.000000e+000,5.499840e+001,3.515715e-006,0.000000e+000,3,8.953678e-001,0.000000e+000,,,,,,,,,,,,,,32,1,4.000000e+000,2.628326e-003,0.000000e+000,0,,0,
1524078866.634,,0.000000e+000,5.500037e+001,3.586925e-006,0.000000e+000,3,8.948051e-001,0.000000e+000,,,,,,,,,,,,,,32,1,4.000000e+000,1.319885e-003,0.000000e+000,0,,0,
1524078904.664,,0.000000e+000,5.500037e+001,3.604962e-006,0.000000e+000,3,8.918438e-001,0.000000e+000,,,,,,,,,,,,,,32,1,4.000000e+000,6.587982e-003,0.000000e+000,0,,0,
1524078942.454,,0.000000e+000,5.500103e+001,3.537407e-006,0.000000e+000,3,8.898582e-001,0.000000e+000,,,,,,,,,,,,,,32,1,4.000000e+000,5.279541e-003,0.000000e+000,0,,0,
1524078980.364,,0.000000e+000,5.499840e+001,3.676479e-006,0.000000e+000,3,8.952841e-001,0.000000e+000,,,,,,,,,,,,,,32,1,4.000000e+000,2.628326e-003,0.000000e+000,0,,0,
1524079018.664,,0.000000e+000,5.499182e+001,3.578446e-006,0.000000e+000,3,8.866819e-001,0.000000e+000,,,,,,,,,,,,,,32,1,4.000000e+000,5.260468e-003,0.000000e+000,0,,0,
1524079057.154,,0.000000e+000,5.500037e+001,3.532473e-006,0.000000e+000,3,8.967550e-001,0.000000e+000,,,,,,,,,,,,,,32,1,4.000000e+000,1.319885e-003,0.000000e+000,0,,0,
1524079095.304,,0.000000e+000,5.500235e+001,3.596236e-006,0.000000e+000,3,8.856558e-001,0.000000e+000,,,,,,,,,,,,,,32,1,4.000000e+000,2.639771e-003,0.000000e+000,0,,0,
1524079132.914,,0.000000e+000,5.500498e+001,3.664098e-006,0.000000e+000,3,8.780469e-001,0.000000e+000,,,,,,,,,,,,,,32,1,4.000000e+000,2.620697e-003,0.000000e+000,0,,0,
1524079171.105,,0.000000e+000,5.499577e+001,3.583670e-006,0.000000e+000,3,8.963587e-001,0.000000e+000,,,,,,,,,,,,,,32,1,4.000000e+000,1.578903e-002,0.000000e+000,0,,0,
1524079209.425,,0.000000e+000,5.499971e+001,3.567068e-006,0.000000e+000,3,9.018726e-001,0.000000e+000,,,,,,,,,,,,,,32,1,4.000000e+000,0.000000e+000,0.000000e+000,0,,0,
1524079246.745,,0.000000e+000,5.499971e+001,3.556242e-006,0.000000e+000,3,8.846291e-001,0.000000e+000,,,,,,,,,,,,,,32,1,4.000000e+000,0.000000e+000,0.000000e+000,0,,0,
1524079284.685,,0.000000e+000,5.499773e+001,3.577602e-006,0.000000e+000,3,8.905116e-001,0.000000e+000,,,,,,,,,,,,,,32,1,4.000000e+000,1.308441e-003,0.000000e+000,0,,0,
1524079322.475,,0.000000e+000,5.499840e+001,3.668751e-006,0.000000e+000,3,8.806906e-001,0.000000e+000,,,,,,,,,,,,,,32,1,4.000000e+000,5.260468e-003,0.000000e+000,0,,0,
1524079360.715,,0.000000e+000,5.499840e+001,3.578253e-006,0.000000e+000,3,8.949414e-001,0.000000e+000,,,,,,,,,,,,,,32,1,4.000000e+000,1.314926e-002,0.000000e+000,0,,0,
1524079398.205,,0.000000e+000,5.499774e+001,3.664377e-006,0.000000e+000,3,8.790618e-001,0.000000e+000,,,,,,,,,,,,,,32,1,4.000000e+000,3.940582e-003,0.000000e+000,0,,0,
1524079435.615,,0.000000e+000,5.499577e+001,3.611129e-006,0.000000e+000,3,8.918514e-001,0.000000e+000,,,,,,,,,,,,,,32,1,4.000000e+000,2.632141e-003,0.000000e+000,0,,0,
1524079472.965,,0.000000e+000,5.499313e+001,3.662288e-006,0.000000e+000,3,8.809318e-001,0.000000e+000,,,,,,,,,,,,,,32,1,4.000000e+000,7.892609e-003,0.000000e+000,0,,0,
1524079510.715,,0.000000e+000,5.499577e+001,3.628490e-006,0.000000e+000,3,8.917599e-001,0.000000e+000,,,,,,,,,,,,,,32,1,4.000000e+000,2.632141e-003,0.000000e+000,0,,0,
1524079548.575,,0.000000e+000,5.500169e+001,3.565547e-006,0.000000e+000,3,8.909999e-001,0.000000e+000,,,,,,,,,,,,,,32,1,4.000000e+000,1.319885e-003,0.000000e+000,0,,0,
1524079611.975,,0.000000e+000,5.499971e+001,3.702167e-006,0.000000e+000,3,8.755922e-001,0.000000e+000,,,,,,,,,,,,,,32,1,4.000000e+000,2.639771e-003,0.000000e+000,0,,0,
1524079649.875,,0.000000e+000,5.499643e+001,3.616142e-006,0.000000e+000,3,8.943024e-001,0.000000e+000,,,,,,,,,,,,,,32,1,4.000000e+000,1.708984e-002,0.000000e+000,0,,0,
1524079687.485,,0.000000e+000,5.499971e+001,3.669058e-006,0.000000e+000,3,8.899381e-001,0.000000e+000,,,,,,,,,,,,,,32,1,4.000000e+000,2.639771e-003,0.000000e+000,0,,0,
1524079725.525,,0.000000e+000,5.499314e+001,3.691252e-006,0.000000e+000,3,8.976535e-001,0.000000e+000,,,,,,,,,,,,,,32,1,4.000000e+000,2.104950e-002,0.000000e+000,0,,0,
1524079763.125,,0.000000e+000,5.499708e+001,3.705876e-006,0.000000e+000,3,8.923749e-001,0.000000e+000,,,,,,,,,,,,,,32,1,4.000000e+000,2.620697e-003,0.000000e+000,0,,0,
1524079801.155,,0.000000e+000,5.500103e+001,3.659215e-006,0.000000e+000,3,8.897446e-001,0.000000e+000,,,,,,,,,,,,,,32,1,4.000000e+000,1.052094e-002,0.000000e+000,0,,0,
1524079863.456,,0.000000e+000,5.500432e+001,3.669345e-006,0.000000e+000,3,8.799871e-001,0.000000e+000,,,,,,,,,,,,,,32,1,4.000000e+000,1.300812e-003,0.000000e+000,0,,0,
1524079900.936,,0.000000e+000,5.500367e+001,3.580032e-006,0.000000e+000,3,8.805676e-001,0.000000e+000,,,,,,,,,,,,,,32,1,4.000000e+000,0.000000e+000,0.000000e+000,0,,0,
1524079938.576,,0.000000e+000,5.499511e+001,3.663945e-006,0.000000e+000,3,8.950972e-001,0.000000e+000,,,,,,,,,,,,,,32,1,4.000000e+000,3.940582e-003,0.000000e+000,0,,0,
1524080001.436,,0.000000e+000,5.499708e+001,3.700574e-006,0.000000e+000,3,9.009280e-001,0.000000e+000,,,,,,,,,,,,,,32,1,4.000000e+000,2.620697e-003,0.000000e+000,0,,0,
1524080038.606,,0.000000e+000,5.499906e+001,3.675493e-006,0.000000e+000,3,9.009022e-001,0.000000e+000,,,,,,,,,,,,,,32,1,4.000000e+000,6.580353e-003,0.000000e+000,0,,0,
1524080075.596,,0.000000e+000,5.499972e+001,3.696797e-006,0.000000e+000,3,9.178047e-001,0.000000e+000,,,,,,,,,,,,,,32,1,4.000000e+000,7.900238e-003,0.000000e+000,0,,0,
1524080113.496,,0.000000e+000,5.499708e+001,3.691087e-006,0.000000e+000,3,8.979729e-001,0.000000e+000,,,,,,,,,,,,,,32,1,4.000000e+000,2.620697e-003,0.000000e+000,0,,0,
1524080151.646,,0.000000e+000,5.499774e+001,3.712731e-006,0.000000e+000,3,8.918170e-001,0.000000e+000,,,,,,,,,,,,,,32,1,4.000000e+000,3.940582e-003,0.000000e+000,0,,0,
1524080189.566,,0.000000e+000,5.499313e+001,3.650771e-006,0.000000e+000,3,9.039311e-001,0.000000e+000,,,,,,,,,,,,,,32,1,4.000000e+000,7.892609e-003,0.000000e+000,0,,0,
1524080227.286,,0.000000e+000,5.499643e+001,3.745681e-006,0.000000e+000,3,8.959031e-001,0.000000e+000,,,,,,,,,,,,,,32,1,4.000000e+000,1.448059e-002,0.000000e+000,0,,0,
1524080264.786,,0.000000e+000,5.500432e+001,3.750461e-006,0.000000e+000,3,8.988771e-001,0.000000e+000,,,,,,,,,,,,,,32,1,4.000000e+000,6.580353e-003,0.000000e+000,0,,0,
1524080302.986,,0.000000e+000,5.499248e+001,3.674665e-006,0.000000e+000,3,9.071775e-001,0.000000e+000,,,,,,,,,,,,,,32,1,4.000000e+000,6.580353e-003,0.000000e+000,0,,0,
1524080340.996,,0.000000e+000,5.499445e+001,3.733122e-006,0.000000e+000,3,8.901842e-001,0.000000e+000,,,,,,,,,,,,,,32,1,4.000000e+000,2.628326e-003,0.000000e+000,0,,0,
1524080378.156,,0.000000e+000,5.499972e+001,3.653809e-006,0.000000e+000,3,8.983794e-001,0.000000e+000,,,,,,,,,,,,,,32,1,4.000000e+000,1.314926e-002,0.000000e+000,0,,0,
1524080416.346,,0.000000e+000,5.499773e+001,3.773358e-006,0.000000e+000,3,8.869844e-001,0.000000e+000,,,,,,,,,,,,,,32,1,4.000000e+000,1.308441e-003,0.000000e+000,0,,0,
1524080454.256,,0.000000e+000,5.499314e+001,3.705402e-006,0.000000e+000,3,8.998275e-001,0.000000e+000,,,,,,,,,,,,,,32,1,4.000000e+000,0.000000e+000,0.000000e+000,0,,0,
1524080492.336,,0.000000e+000,5.500103e+001,3.726128e-006,0.000000e+000,3,9.049297e-001,0.000000e+000,,,,,,,,,,,,,,32,1,4.000000e+000,5.279541e-003,0.000000e+000,0,,0,
1524080530.796,,0.000000e+000,5.500103e+001,3.729427e-006,0.000000e+000,3,8.905348e-001,0.000000e+000,,,,,,,,,,,,,,32,1,4.000000e+000,7.888794e-003,0.000000e+000,0,,0,
1524080569.047,,0.000000e+000,5.500366e+001,3.805776e-006,0.000000e+000,3,8.838906e-001,0.000000e+000,,,,,,,,,,,,,,32,1,4.000000e+000,7.900238e-003,0.000000e+000,0,,0,
1524080607.097,,0.000000e+000,5.499708e+001,3.786946e-006,0.000000e+000,3,9.120743e-001,0.000000e+000,,,,,,,,,,,,,,32,1,4.000000e+000,5.260468e-003,0.000000e+000,0,,0,
1524080644.757,,0.000000e+000,5.500629e+001,3.821755e-006,0.000000e+000,3,8.877234e-001,0.000000e+000,,,,,,,,,,,,,,32,1,4.000000e+000,1.580048e-002,0.000000e+000,0,,0,
1524080682.697,,0.000000e+000,5.499972e+001,3.772812e-006,0.000000e+000,3,9.075359e-001,0.000000e+000,,,,,,,,,,,,,,32,1,4.000000e+000,7.900238e-003,0.000000e+000,0,,0,
1524080720.377,,0.000000e+000,5.499840e+001,3.797992e-006,0.000000e+000,3,8.906366e-001,0.000000e+000,,,,,,,,,,,,,,32,1,4.000000e+000,2.628326e-003,0.000000e+000,0,,0,
1524080758.477,,0.000000e+000,5.500037e+001,3.819526e-006,0.000000e+000,3,9.016444e-001,0.000000e+000,,,,,,,,,,,,,,32,1,4.000000e+000,1.446915e-002,0.000000e+000,0,,0,
1524080797.057,,0.000000e+000,5.499314e+001,3.824514e-006,0.000000e+000,3,9.242041e-001,0.000000e+000,,,,,,,,,,,,,,32,1,4.000000e+000,0.000000e+000,0.000000e+000,0,,0,
1524080834.767,,0.000000e+000,5.500037e+001,3.772482e-006,0.000000e+000,3,8.931720e-001,0.000000e+000,,,,,,,,,,,,,,32,1,4.000000e+000,1.319885e-003,0.000000e+000,0,,0,
1524080873.367,,0.000000e+000,5.499840e+001,3.785026e-006,0.000000e+000,3,9.152223e-001,0.000000e+000,,,,,,,,,,,,,,32,1,4.000000e+000,2.628326e-003,0.000000e+000,0,,0,
1524080910.617,,0.000000e+000,5.500169e+001,3.820232e-006,0.000000e+000,3,9.077529e-001,0.000000e+000,,,,,,,,,,,,,,32,1,4.000000e+000,1.446915e-002,0.000000e+000,0,,0,
1524080948.457,,0.000000e+000,5.499643e+001,3.774120e-006,0.000000e+000,3,9.001402e-001,0.000000e+000,,,,,,,,,,,,,,32,1,4.000000e+000,1.184082e-002,0.000000e+000,0,,0,
1524080986.127,,0.000000e+000,5.499840e+001,3.805658e-006,0.000000e+000,3,8.928162e-001,0.000000e+000,,,,,,,,,,,,,,32,1,4.000000e+000,5.260468e-003,0.000000e+000,0,,0,
1524081024.077,,0.000000e+000,5.499380e+001,3.775019e-006,0.000000e+000,3,9.006090e-001,0.000000e+000,,,,,,,,,,,,,,32,1,4.000000e+000,1.308441e-003,0.000000e+000,0,,0,
1524081061.937,,0.000000e+000,5.499643e+001,3.779950e-006,0.000000e+000,3,9.005321e-001,0.000000e+000,,,,,,,,,,,,,,32,1,4.000000e+000,1.312256e-003,0.000000e+000,0,,0,
1524081099.787,,0.000000e+000,5.499905e+001,3.868474e-006,0.000000e+000,3,8.968720e-001,0.000000e+000,,,,,,,,,,,,,,32,1,4.000000e+000,3.948212e-003,0.000000e+000,0,,0,
1524081137.507,,0.000000e+000,5.499905e+001,3.830351e-006,0.000000e+000,3,8.997996e-001,0.000000e+000,,,,,,,,,,,,,,32,1,4.000000e+000,3.948212e-003,0.000000e+000,0,,0,
1524081175.067,,0.000000e+000,5.500366e+001,3.800865e-006,0.000000e+000,3,8.961185e-001,0.000000e+000,,,,,,,,,,,,,,32,1,4.000000e+000,2.620697e-003,0.000000e+000,0,,0,
1524081212.447,,0.000000e+000,5.500037e+001,3.767114e-006,0.000000e+000,3,8.927673e-001,0.000000e+000,,,,,,,,,,,,,,32,1,4.000000e+000,1.184082e-002,0.000000e+000,0,,0,
1524081250.987,,0.000000e+000,5.500234e+001,3.720274e-006,0.000000e+000,3,9.041604e-001,0.000000e+000,,,,,,,,,,,,,,32,1,4.000000e+000,5.260468e-003,0.000000e+000,0,,0,
1524081289.028,,0.000000e+000,5.500169e+001,3.841101e-006,0.000000e+000,3,8.971791e-001,0.000000e+000,,,,,,,,,,,,,,32,1,4.000000e+000,3.959656e-003,0.000000e+000,0,,0,
1524081327.338,,0.000000e+000,5.499906e+001,3.776883e-006,0.000000e+000,3,9.006209e-001,0.000000e+000,,,,,,,,,,,,,,32,1,4.000000e+000,9.220123e-003,0.000000e+000,0,,0,
1524081365.688,,0.000000e+000,5.499905e+001,3.744096e-006,0.000000e+000,3,9.034265e-001,0.000000e+000,,,,,,,,,,,,,,32,1,4.000000e+000,3.948212e-003,0.000000e+000,0,,0,
1524081403.708,,0.000000e+000,5.499643e+001,3.827423e-006,0.000000e+000,3,8.901610e-001,0.000000e+000,,,,,,,,,,,,,,32,1,4.000000e+000,1.312256e-003,0.000000e+000,0,,0,
1524081441.648,,0.000000e+000,5.499708e+001,3.838740e-006,0.000000e+000,3,9.051948e-001,0.000000e+000,,,,,,,,,,,,,,32,1,4.000000e+000,2.620697e-003,0.000000e+000,0,,0,
1524081479.268,,0.000000e+000,5.499773e+001,3.861143e-006,0.000000e+000,3,8.956236e-001,0.000000e+000,,,,,,,,,,,,,,32,1,4.000000e+000,1.308441e-003,0.000000e+000,0,,0,
1524081516.748,,0.000000e+000,5.500497e+001,3.839806e-006,0.000000e+000,3,8.992064e-001,0.000000e+000,,,,,,,,,,,,,,32,1,4.000000e+000,1.578903e-002,0.000000e+000,0,,0,
1524081554.838,,0.000000e+000,5.500037e+001,3.793737e-006,0.000000e+000,3,8.982198e-001,0.000000e+000,,,,,,,,,,,,,,32,1,4.000000e+000,9.201050e-003,0.000000e+000,0,,0,
1524081592.758,,0.000000e+000,5.500301e+001,3.866296e-006,0.000000e+000,3,8.878736e-001,0.000000e+000,,,,,,,,,,,,,,32,1,4.000000e+000,1.319885e-003,0.000000e+000,0,,0,
1524081631.268,,0.000000e+000,5.499445e+001,3.803105e-006,0.000000e+000,3,8.904651e-001,0.000000e+000,,,,,,,,,,,,,,32,1,4.000000e+000,5.260468e-003,0.000000e+000,0,,0,
1524081669.618,,0.000000e+000,5.499906e+001,3.787352e-006,0.000000e+000,3,9.144369e-001,0.000000e+000,,,,,,,,,,,,,,32,1,4.000000e+000,6.580353e-003,0.000000e+000,0,,0,
1524081707.238,,0.000000e+000,5.499774e+001,3.840671e-006,0.000000e+000,3,8.909988e-001,0.000000e+000,,,,,,,,,,,,,,32,1,4.000000e+000,3.940582e-003,0.000000e+000,0,,0,
1524081745.228,,0.000000e+000,5.499971e+001,3.814249e-006,0.000000e+000,3,9.023203e-001,0.000000e+000,,,,,,,,,,,,,,32,1,4.000000e+000,0.000000e+000,0.000000e+000,0,,0,
1524081782.798,,0.000000e+000,5.499773e+001,3.847715e-006,0.000000e+000,3,8.883282e-001,0.000000e+000,,,,,,,,,,,,,,32,1,4.000000e+000,1.308441e-003,0.000000e+000,0,,0,
1524081820.878,,0.000000e+000,5.500300e+001,3.812131e-006,0.000000e+000,3,9.049307e-001,0.000000e+000,,,,,,,,,,,,,,32,1,4.000000e+000,1.710129e-002,0.000000e+000,0,,0,
1524081858.138,,0.000000e+000,5.499511e+001,3.875398e-006,0.000000e+000,3,8.968418e-001,0.000000e+000,,,,,,,,,,,,,,32,1,4.000000e+000,6.568909e-003,0.000000e+000,0,,0,
1524081920.918,,0.000000e+000,5.499905e+001,3.825136e-006,0.000000e+000,3,9.086141e-001,0.000000e+000,,,,,,,,,,,,,,32,1,4.000000e+000,1.319885e-003,0.000000e+000,0,,0,
1524081959.148,,0.000000e+000,5.500103e+001,3.859517e-006,0.000000e+000,3,9.057236e-001,0.000000e+000,,,,,,,,,,,,,,32,1,4.000000e+000,1.841736e-002,0.000000e+000,0,,0,
1524081997.449,,0.000000e+000,5.499971e+001,3.827767e-006,0.000000e+000,3,9.022638e-001,0.000000e+000,,,,,,,,,,,,,,32,1,4.000000e+000,0.000000e+000,0.000000e+000,0,,0,
1524082034.659,,0.000000e+000,5.500431e+001,3.787069e-006,0.000000e+000,3,8.967420e-001,0.000000e+000,,,,,,,,,,,,,,32,1,4.000000e+000,9.208679e-003,0.000000e+000,0,,0,
1524082072.299,,0.000000e+000,5.499511e+001,3.867962e-006,0.000000e+000,3,8.924814e-001,0.000000e+000,,,,,,,,,,,,,,32,1,4.000000e+000,1.319885e-003,0.000000e+000,0,,0,
1524082110.199,,0.000000e+000,5.499905e+001,3.830565e-006,0.000000e+000,3,9.010573e-001,0.000000e+000,,,,,,,,,,,,,,32,1,4.000000e+000,3.948212e-003,0.000000e+000,0,,0,
1524082147.759,,0.000000e+000,5.499905e+001,3.885072e-006,0.000000e+000,3,8.940175e-001,0.000000e+000,,,,,,,,,,,,,,32,1,4.000000e+000,1.319885e-003,0.000000e+000,0,,0,
1524082185.779,,0.000000e+000,5.499839e+001,3.842417e-006,0.000000e+000,3,9.041892e-001,0.000000e+000,,,,,,,,,,,,,,32,1,4.000000e+000,0.000000e+000,0.000000e+000,0,,0,
1524082223.389,,0.000000e+000,5.499905e+001,3.907233e-006,0.000000e+000,3,8.932648e-001,0.000000e+000,,,,,,,,,,,,,,32,1,4.000000e+000,1.319885e-003,0.000000e+000,0,,0,
1524082261.409,,0.000000e+000,5.500366e+001,3.840753e-006,0.000000e+000,3,9.035130e-001,0.000000e+000,,,,,,,,,,,,,,32,1,4.000000e+000,1.315689e-002,0.000000e+000,0,,0,
1524082298.899,,0.000000e+000,5.499972e+001,3.892795e-006,0.000000e+000,3,9.008295e-001,0.000000e+000,,,,,,,,,,,,,,32,1,4.000000e+000,5.268097e-003,0.000000e+000,0,,0,
1524082337.019,,0.000000e+000,5.500037e+001,3.867412e-006,0.000000e+000,3,9.055124e-001,0.000000e+000,,,,,,,,,,,,,,32,1,4.000000e+000,1.184082e-002,0.000000e+000,0,,0,
1524082374.659,,0.000000e+000,5.499643e+001,3.874396e-006,0.000000e+000,3,8.962201e-001,0.000000e+000,,,,,,,,,,,,,,32,1,4.000000e+000,1.312256e-003,0.000000e+000,0,,0,
1524082387.469,,0.000000e+000,5.500234e+001,3.854409e-006,0.000000e+000,3,9.057089e-001,0.000000e+000,,,,,,,,,,,,,,32,1,4.000000e+000,7.900238e-003,0.000000e+000,0,,0,