File: Input/TC04-12-01K_VRMac_53K_12000s_VRMde_55K.dc.dat
[Header]
TITLE,MPMS DC Measurement
BYAPP,MPMS Measurement,2.1,Summary
FILEOPENTIME, 1524132280.785000 4/19/2018, 4:04:40 AM

INFO, APPNAME, MPMS MultiVu Application, Revision 1.61,  Build 082

INFO, NAME, TC04-12-01K
INFO, WEIGHT, 1.000
INFO, AREA, 1.000
INFO, LENGTH, 1.000
INFO, SHAPE, 0
INFO, COMMENT,
INFO, SEQUENCE FILE: VRMac_53K_12000s_VRMde_55K.seq


INFO, BACKGROUND DATA FILE:, None


STARTUPAXIS,X,4,LINEAR,AUTO,0.000000,0.000000
STARTUPAXIS,Y1,5,LINEAR,AUTO,0.000000,0.000000


STARTUPGROUP,Longitudinal
FIELDGROUP,Longitudinal,1,2,3,4,5,6,7,8,9,15,16,17,18,27,28
FIELDGROUP,Transverse,1,2,3,4,10,11,12,13,14,19,20,21,22,27,28

PLOT_APPEARANCE,ALL,HORZ_GRID_ON,VERT_GRID_ON,MARKERS_AND_LINES

[Data]
Time,Comment,Field (Oe),Temperature (K),Long Moment (emu),Long Scan Std Dev,Long Algorithm,Long Reg Fit,Long Percent Error (%),Trans Moment (emu),Trans Scan Std Dev,Trans Algorithm,Trans Reg Fit,Trans Percent Error (%),Long Moment [w/o ABS] (emu),Long Scan Std Dev [w/o ABS],Long Reg Fit [w/o ABS],Long Percent Error [w/o ABS] (%),Trans Moment [w/o ABS] (emu),Trans Scan Std Dev [w/o ABS],Trans Reg Fit [w/o ABS],Trans Percent Error [w/o ABS] (%),Points per Scan,Scans per Measurement,Scan Length (cm),Delta Temp (K),Rot Position (deg),Error,EC Comp. Running,Using ABS,
1524132280.785,,0.000000e+000,5.316882e+001,-1.963558e-005,0.000000e+000,3,9.649549e-001,0.000000e+000,,,,,,,,,,,,,,32,1,4.000000e+000,3.368492e-001,0.000000e+000,0,,0,
1524132305.945,,0.000000e+000,5.446838e+001,-1.611238e-005,0.000000e+000,3,9.620131e-001,0.000000e+000,,,,,,,,,,,,,,32,1,4.000000e+000,3.901596e-001,0.000000e+000,0,,0,
1524132331.075,,0.000000e+000,5.499845e+001,-1.336294e-005,0.000000e+000,3,9.603029e-001,0.000000e+000,,,,,,,,,,,,,,32,1,4.000000e+000,1.105003e-001,0.000000e+000,0,,0,
1524132356.315,,0.000000e+000,5.507611e+001,-1.151038e-005,0.000000e+000,3,9.648667e-001,0.000000e+000,,,,,,,,,,,,,,32,1,4.000000e+000,0.000000e+000,0.000000e+000,0,,0,
1524132382.335,,0.000000e+000,5.505634e+001,-1.009955e-005,0.000000e+000,3,9.531373e-001,0.000000e+000,,,,,,,,,,,,,,32,1,4.000000e+000,0.000000e+000,0.000000e+000,0,,0,
1524132407.725,,0.000000e+000,5.503657e+001,-9.216485e-006,0.000000e+000,3,9.523674e-001,0.000000e+000,,,,,,,,,,,,,,32,1,4.000000e+000,1.054001e-002,0.000000e+000,0,,0,
1524132433.575,,0.000000e+000,5.502209e+001,-8.595737e-006,0.000000e+000,3,9.543855e-001,0.000000e+000,,,,,,,,,,,,,,32,1,4.000000e+000,2.628326e-003,0.000000e+000,0,,0,
1524132458.705,,0.000000e+000,5.500629e+001,-7.971581e-006,0.000000e+000,3,9.532138e-001,0.000000e+000,,,,,,,,,,,,,,32,1,4.000000e+000,2.639771e-003,0.000000e+000,0,,0,
1524132483.365,,0.000000e+000,5.500432e+001,-7.472126e-006,0.000000e+000,3,9.490163e-001,0.000000e+000,,,,,,,,,,,,,,32,1,4.000000e+000,3.940582e-003,0.000000e+000,0,,0,
1524132508.695,,0.000000e+000,5.499906e+001,-6.910825e-006,0.000000e+000,3,9.423209e-001,0.000000e+000,,,,,,,,,,,,,,32,1,4.000000e+000,6.580353e-003,0.000000e+000,0,,0,
1524132533.895,,0.000000e+000,5.500497e+001,-6.614441e-006,0.000000e+000,3,9.422500e-001,0.000000e+000,,,,,,,,,,,,,,32,1,4.000000e+000,1.316071e-002,0.000000e+000,0,,0,
1524132559.365,,0.000000e+000,5.499117e+001,-6.224021e-006,0.000000e+000,3,9.421849e-001,0.000000e+000,,,,,,,,,,,,,,32,1,4.000000e+000,1.312256e-003,0.000000e+000,0,,0,
1524132584.395,,0.000000e+000,5.499511e+001,-5.893589e-006,0.000000e+000,3,9.325560e-001,0.000000e+000,,,,,,,,,,,,,,32,1,4.000000e+000,6.568909e-003,0.000000e+000,0,,0,
1524132609.285,,0.000000e+000,5.499643e+001,-5.649169e-006,0.000000e+000,3,9.336317e-001,0.000000e+000,,,,,,,,,,,,,,32,1,4.000000e+000,1.184082e-002,0.000000e+000,0,,0,
1524132634.215,,0.000000e+000,5.499773e+001,-5.396715e-006,0.000000e+000,3,9.359509e-001,0.000000e+000,,,,,,,,,,,,,,32,1,4.000000e+000,1.308441e-003,0.000000e+000,0,,0,
1524132658.915,,0.000000e+000,5.499643e+001,-5.204394e-006,0.000000e+000,3,9.296610e-001,0.000000e+000,,,,,,,,,,,,,,32,1,4.000000e+000,9.208679e-003,0.000000e+000,0,,0,
1524132684.155,,0.000000e+000,5.499905e+001,-4.978197e-006,0.000000e+000,3,9.379180e-001,0.000000e+000,,,,,,,,,,,,,,32,1,4.000000e+000,1.319885e-003,0.000000e+000,0,,0,
1524132709.386,,0.000000e+000,5.499773e+001,-4.831777e-006,0.000000e+000,3,9.221546e-001,0.000000e+000,,,,,,,,,,,,,,32,1,4.000000e+000,1.308441e-003,0.000000e+000,0,,0,
1524132734.846,,0.000000e+000,5.500300e+001,-4.577383e-006,0.000000e+000,3,9.279228e-001,0.000000e+000,,,,,,,,,,,,,,32,1,4.000000e+000,3.940582e-003,0.000000e+000,0,,0,
1524132760.336,,0.000000e+000,5.500103e+001,-4.339060e-006,0.000000e+000,3,9.313425e-001,0.000000e+000,,,,,,,,,,,,,,32,1,4.000000e+000,1.052094e-002,0.000000e+000,0,,0,
1524132785.496,,0.000000e+000,5.499511e+001,-4.207504e-006,0.000000e+000,3,9.242392e-001,0.000000e+000,,,,,,,,,,,,,,32,1,4.000000e+000,6.568909e-003,0.000000e+000,0,,0,
1524132810.756,,0.000000e+000,5.499708e+001,-4.084501e-006,0.000000e+000,3,9.342408e-001,0.000000e+000,,,,,,,,,,,,,,32,1,4.000000e+000,2.620697e-003,0.000000e+000,0,,0,
1524132835.916,,0.000000e+000,5.499708e+001,-3.956591e-006,0.000000e+000,3,9.186496e-001,0.000000e+000,,,,,,,,,,,,,,32,1,4.000000e+000,5.260468e-003,0.000000e+000,0,,0,
1524132861.236,,0.000000e+000,5.499840e+001,-3.785972e-006,0.000000e+000,3,9.275859e-001,0.000000e+000,,,,,,,,,,,,,,32,1,4.000000e+000,2.628326e-003,0.000000e+000,0,,0,
1524132886.476,,0.000000e+000,5.500037e+001,-3.673151e-006,0.000000e+000,3,9.123262e-001,0.000000e+000,,,,,,,,,,,,,,32,1,4.000000e+000,9.201050e-003,0.000000e+000,0,,0,
1524132911.506,,0.000000e+000,5.499905e+001,-3.473735e-006,0.000000e+000,3,9.271889e-001,0.000000e+000,,,,,,,,,,,,,,32,1,4.000000e+000,1.319885e-003,0.000000e+000,0,,0,
1524132936.396,,0.000000e+000,5.500169e+001,-3.447886e-006,0.000000e+000,3,9.050081e-001,0.000000e+000,,,,,,,,,,,,,,32,1,4.000000e+000,1.319885e-003,0.000000e+000,0,,0,
1524132961.626,,0.000000e+000,5.500103e+001,-3.309422e-006,0.000000e+000,3,9.005563e-001,0.000000e+000,,,,,,,,,,,,,,32,1,4.000000e+000,7.888794e-003,0.000000e+000,0,,0,
1524132986.896,,0.000000e+000,5.499445e+001,-3.213549e-006,0.000000e+000,3,9.015660e-001,0.000000e+000,,,,,,,,,,,,,,32,1,4.000000e+000,2.628326e-003,0.000000e+000,0,,0,
1524133012.116,,0.000000e+000,5.499709e+001,-3.127891e-006,0.000000e+000,3,8.891931e-001,0.000000e+000,,,,,,,,,,,,,,32,1,4.000000e+000,7.888794e-003,0.000000e+000,0,,0,
1524133037.326,,0.000000e+000,5.499577e+001,-3.082753e-006,0.000000e+000,3,8.903399e-001,0.000000e+000,,,,,,,,,,,,,,32,1,4.000000e+000,0.000000e+000,0.000000e+000,0,,0,
1524133062.566,,0.000000e+000,5.499840e+001,-2.987102e-006,0.000000e+000,3,8.832183e-001,0.000000e+000,,,,,,,,,,,,,,32,1,4.000000e+000,2.628326e-003,0.000000e+000,0,,0,
1524133087.796,,0.000000e+000,5.499577e+001,-2.936742e-006,0.000000e+000,3,8.815503e-001,0.000000e+000,,,,,,,,,,,,,,32,1,4.000000e+000,1.578903e-002,0.000000e+000,0,,0,
1524133113.766,,0.000000e+000,5.499708e+001,-2.854435e-006,0.000000e+000,3,8.865626e-001,0.000000e+000,,,,,,,,,,,,,,32,1,4.000000e+000,2.620697e-003,0.000000e+000,0,,0,
1524133138.576,,0.000000e+000,5.499314e+001,-2.760326e-006,0.000000e+000,3,8.796915e-001,0.000000e+000,,,,,,,,,,,,,,32,1,4.000000e+000,0.000000e+000,0.000000e+000,0,,0,
1524133163.536,,0.000000e+000,5.499972e+001,-2.678865e-006,0.000000e+000,3,8.672331e-001,0.000000e+000,,,,,,,,,,,,,,32,1,4.000000e+000,1.314926e-002,0.000000e+000,0,,0,
1524133188.186,,0.000000e+000,5.499313e+001,-2.638552e-006,0.000000e+000,3,8.690842e-001,0.000000e+000,,,,,,,,,,,,,,32,1,4.000000e+000,2.628326e-003,0.000000e+000,0,,0,
1524133213.726,,0.000000e+000,5.499642e+001,-2.586827e-006,0.000000e+000,3,8.560423e-001,0.000000e+000,,,,,,,,,,,,,,32,1,4.000000e+000,3.940582e-003,0.000000e+000,0,,0,
1524133239.136,,0.000000e+000,5.499708e+001,-2.649502e-006,0.000000e+000,3,8.493350e-001,0.000000e+000,,,,,,,,,,,,,,32,1,4.000000e+000,0.000000e+000,0.000000e+000,0,,0,
1524133519.469,,0.000000e+000,5.499972e+001,-5.869763e-007,0.000000e+000,2,0.000000e+000,0.000000e+000,,,,,,,,,,,,,,32,1,4.000000e+000,5.268097e-003,0.000000e+000,0,,0,
1524133547.953,,0.000000e+000,5.499775e+001,-5.851335e-007,0.000000e+000,2,0.000000e+000,0.000000e+000,,,,,,,,,,,,,,32,1,4.000000e+000,1.972961e-002,0.000000e+000,0,,0,
1524133576.467,,0.000000e+000,5.500169e+001,-4.765406e-007,0.000000e+000,2,0.000000e+000,0.000000e+000,,,,,,,,,,,,,,32,1,4.000000e+000,1.184082e-002,0.000000e+000,0,,0,
1524133604.661,,0.000000e+000,5.500366e+001,-3.462626e-007,0.000000e+000,2,0.000000e+000,0.000000e+000,,,,,,,,,,,,,,32,1,4.000000e+000,1.315689e-002,0.000000e+000,0,,0,
1524133633.145,,0.000000e+000,5.499512e+001,-2.713989e-007,0.000000e+000,2,0.000000e+000,0.000000e+000,,,,,,,,,,,,,,32,1,4.000000e+000,1.446915e-002,0.000000e+000,0,,0,
1524133659.447,,0.000000e+000,5.499445e+001,2.244670e-006,0.000000e+000,3,6.266807e-001,0.000000e+000,,,,,,,,,,,,,,32,1,4.000000e+000,7.881165e-003,0.000000e+000,0,,0,
1524133686.989,,0.000000e+000,5.499972e+001,2.058571e-006,0.000000e+000,3,5.847564e-001,0.000000e+000,,,,,,,,,,,,,,32,1,4.000000e+000,1.578903e-002,0.000000e+000,0,,0,
1524133713.811,,0.000000e+000,5.500497e+001,2.242938e-006,0.000000e+000,3,6.294730e-001,0.000000e+000,,,,,,,,,,,,,,32,1,4.000000e+000,7.888794e-003,0.000000e+000,0,,0,
1524133738.881,,0.000000e+000,5.500103e+001,2.200699e-006,0.000000e+000,3,6.300049e-001,0.000000e+000,,,,,,,,,,,,,,32,1,4.000000e+000,7.888794e-003,0.000000e+000,0,,0,
1524133764.111,,0.000000e+000,5.500037e+001,2.169811e-006,0.000000e+000,3,6.302273e-001,0.000000e+000,,,,,,,,,,,,,,32,1,4.000000e+000,6.587982e-003,0.000000e+000,0,,0,
1524133789.161,,0.000000e+000,5.499511e+001,2.144807e-006,0.000000e+000,3,6.258264e-001,0.000000e+000,,,,,,,,,,,,,,32,1,4.000000e+000,1.319885e-003,0.000000e+000,0,,0,
1524133814.401,,0.000000e+000,5.499708e+001,-2.209276e-006,0.000000e+000,3,7.433679e-001,0.000000e+000,,,,,,,,,,,,,,32,1,4.000000e+000,0.000000e+000,0.000000e+000,0,,0,
1524133841.273,,0.000000e+000,5.499445e+001,1.966271e-006,0.000000e+000,3,5.043740e-001,0.000000e+000,,,,,,,,,,,,,,32,1,4.000000e+000,5.260468e-003,0.000000e+000,0,,0,
1524133868.315,,0.000000e+000,5.500563e+001,3.336517e-008,0.000000e+000,2,0.000000e+000,0.000000e+000,,,,,,,,,,,,,,32,1,4.000000e+000,9.208679e-003,0.000000e+000,0,,0,
1524133894.717,,0.000000e+000,5.499313e+001,3.518267e-008,0.000000e+000,2,0.000000e+000,0.000000e+000,,,,,,,,,,,,,,32,1,4.000000e+000,2.628326e-003,0.000000e+000,0,,0,
1524133920.087,,0.000000e+000,5.500432e+001,-2.160689e-006,0.000000e+000,3,7.354997e-001,0.000000e+000,,,,,,,,,,,,,,32,1,4.000000e+000,3.940582e-003,0.000000e+000,0,,0,
1524133945.247,,0.000000e+000,5.499183e+001,-2.142598e-006,0.000000e+000,3,7.300165e-001,0.000000e+000,,,,,,,,,,,,,,32,1,4.000000e+000,7.888794e-003,0.000000e+000,0,,0,
1524133970.357,,0.000000e+000,5.500169e+001,-2.077715e-006,0.000000e+000,3,7.321714e-001,0.000000e+000,,,,,,,,,,,,,,32,1,4.000000e+000,1.319885e-003,0.000000e+000,0,,0,
1524133996.067,,0.000000e+000,5.499773e+001,-2.291971e-006,0.000000e+000,3,7.606216e-001,0.000000e+000,,,,,,,,,,,,,,32,1,4.000000e+000,1.308441e-003,0.000000e+000,0,,0,
1524134021.507,,0.000000e+000,5.499971e+001,-2.242867e-006,0.000000e+000,3,7.072205e-001,0.000000e+000,,,,,,,,,,,,,,32,1,4.000000e+000,2.639771e-003,0.000000e+000,0,,0,
1524134049.871,,0.000000e+000,5.499774e+001,3.351383e-007,0.000000e+000,2,0.000000e+000,0.000000e+000,,,,,,,,,,,,,,32,1,4.000000e+000,6.580353e-003,0.000000e+000,0,,0,
1524134078.155,,0.000000e+000,5.500037e+001,4.105028e-007,0.000000e+000,2,0.000000e+000,0.000000e+000,,,,,,,,,,,,,,32,1,4.000000e+000,6.587982e-003,0.000000e+000,0,,0,
1524134105.739,,0.000000e+000,5.499971e+001,4.620242e-007,0.000000e+000,2,0.000000e+000,0.000000e+000,,,,,,,,,,,,,,32,1,4.000000e+000,2.639771e-003,0.000000e+000,0,,0,
1524134133.364,,0.000000e+000,5.500235e+001,4.328355e-007,0.000000e+000,2,0.000000e+000,0.000000e+000,,,,,,,,,,,,,,32,1,4.000000e+000,2.639771e-003,0.000000e+000,0,,0,
1524134161.868,,0.000000e+000,5.499840e+001,5.395513e-007,0.000000e+000,2,0.000000e+000,0.000000e+000,,,,,,,,,,,,,,32,1,4.000000e+000,7.900238e-003,0.000000e+000,0,,0,
1524134190.152,,0.000000e+000,5.500037e+001,5.891893e-007,0.000000e+000,2,0.000000e+000,0.000000e+000,,,,,,,,,,,,,,32,1,4.000000e+000,6.587982e-003,0.000000e+000,0,,0,
1524134217.294,,0.000000e+000,5.499511e+001,5.291253e-007,0.000000e+000,2,0.000000e+000,0.000000e+000,,,,,,,,,,,,,,32,1,4.000000e+000,1.319885e-003,0.000000e+000,0,,0,
1524134243.496,,0.000000e+000,5.499905e+001,2.058623e-006,0.000000e+000,3,6.683355e-001,0.000000e+000,,,,,,,,,,,,,,32,1,4.000000e+000,1.319885e-003,0.000000e+000,0,,0,
1524134268.476,,0.000000e+000,5.499905e+001,2.125201e-006,0.000000e+000,3,6.478578e-001,0.000000e+000,,,,,,,,,,,,,,32,1,4.000000e+000,1.319885e-003,0.000000e+000,0,,0,
1524134295.398,,0.000000e+000,5.500235e+001,6.571433e-007,0.000000e+000,2,0.000000e+000,0.000000e+000,,,,,,,,,,,,,,32,1,4.000000e+000,0.000000e+000,0.000000e+000,0,,0,
1524134320.248,,0.000000e+000,5.499643e+001,2.090727e-006,0.000000e+000,3,7.326867e-001,0.000000e+000,,,,,,,,,,,,,,32,1,4.000000e+000,1.312256e-003,0.000000e+000,0,,0,
1524134973.921,,0.000000e+000,5.500366e+001,2.250724e-006,0.000000e+000,3,7.722916e-001,0.000000e+000,,,,,,,,,,,,,,32,1,4.000000e+000,1.315689e-002,0.000000e+000,0,,0,
1524134999.321,,0.000000e+000,5.499971e+001,2.219945e-006,0.000000e+000,3,7.851409e-001,0.000000e+000,,,,,,,,,,,,,,32,1,4.000000e+000,1.052094e-002,0.000000e+000,0,,0,
1524135024.561,,0.000000e+000,5.499906e+001,2.236543e-006,0.000000e+000,3,7.841487e-001,0.000000e+000,,,,,,,,,,,,,,32,1,4.000000e+000,6.580353e-003,0.000000e+000,0,,0,
1524135049.781,,0.000000e+000,5.500037e+001,2.244190e-006,0.000000e+000,3,7.818231e-001,0.000000e+000,,,,,,,,,,,,,,32,1,4.000000e+000,1.319885e-003,0.000000e+000,0,,0,
1524135075.021,,0.000000e+000,5.499577e+001,2.245548e-006,0.000000e+000,3,7.767764e-001,0.000000e+000,,,,,,,,,,,,,,32,1,4.000000e+000,1.578903e-002,0.000000e+000,0,,0,
1524135100.251,,0.000000e+000,5.499709e+001,2.281118e-006,0.000000e+000,3,7.921345e-001,0.000000e+000,,,,,,,,,,,,,,32,1,4.000000e+000,7.888794e-003,0.000000e+000,0,,0,
1524135125.491,,0.000000e+000,5.500103e+001,2.245972e-006,0.000000e+000,3,7.959219e-001,0.000000e+000,,,,,,,,,,,,,,32,1,4.000000e+000,0.000000e+000,0.000000e+000,0,,0,
1524135150.721,,0.000000e+000,5.500235e+001,2.256014e-006,0.000000e+000,3,7.911921e-001,0.000000e+000,,,,,,,,,,,,,,32,1,4.000000e+000,0.000000e+000,0.000000e+000,0,,0,
1524135175.961,,0.000000e+000,5.499577e+001,2.264844e-006,0.000000e+000,3,7.876770e-001,0.000000e+000,,,,,,,,,,,,,,32,1,4.000000e+000,2.632141e-003,0.000000e+000,0,,0,
1524135201.191,,0.000000e+000,5.500037e+001,2.269370e-006,0.000000e+000,3,7.887807e-001,0.000000e+000,,,,,,,,,,,,,,32,1,4.000000e+000,6.587982e-003,0.000000e+000,0,,0,
1524135226.421,,0.000000e+000,5.499708e+001,2.263364e-006,0.000000e+000,3,7.966202e-001,0.000000e+000,,,,,,,,,,,,,,32,1,4.000000e+000,2.620697e-003,0.000000e+000,0,,0,
1524135251.431,,0.000000e+000,5.500235e+001,2.303698e-006,0.000000e+000,3,7.886738e-001,0.000000e+000,,,,,,,,,,,,,,32,1,4.000000e+000,0.000000e+000,0.000000e+000,0,,0,
1524135276.941,,0.000000e+000,5.499905e+001,2.287515e-006,0.000000e+000,3,7.822077e-001,0.000000e+000,,,,,,,,,,,,,,32,1,4.000000e+000,1.319885e-003,0.000000e+000,0,,0,
1524135301.991,,0.000000e+000,5.499709e+001,2.328343e-006,0.000000e+000,3,7.784255e-001,0.000000e+000,,,,,,,,,,,,,,32,1,4.000000e+000,7.888794e-003,0.000000e+000,0,,0,
1524135327.141,,0.000000e+000,5.500037e+001,2.305962e-006,0.000000e+000,3,7.652019e-001,0.000000e+000,,,,,,,,,,,,,,32,1,4.000000e+000,1.319885e-003,0.000000e+000,0,,0,
1524135352.171,,0.000000e+000,5.499841e+001,2.362529e-006,0.000000e+000,3,7.620018e-001,0.000000e+000,,,,,,,,,,,,,,32,1,4.000000e+000,1.052856e-002,0.000000e+000,0,,0,
1524135377.121,,0.000000e+000,5.499511e+001,2.327744e-006,0.000000e+000,3,7.647673e-001,0.000000e+000,,,,,,,,,,,,,,32,1,4.000000e+000,1.319885e-003,0.000000e+000,0,,0,
1524135402.361,,0.000000e+000,5.499314e+001,2.384876e-006,0.000000e+000,3,7.849470e-001,0.000000e+000,,,,,,,,,,,,,,32,1,4.000000e+000,0.000000e+000,0.000000e+000,0,,0,
1524135427.721,,0.000000e+000,5.499643e+001,2.354122e-006,0.000000e+000,3,7.863963e-001,0.000000e+000,,,,,,,,,,,,,,32,1,4.000000e+000,1.312256e-003,0.000000e+000,0,,0,
1524135452.771,,0.000000e+000,5.500037e+001,2.456606e-006,0.000000e+000,3,7.890193e-001,0.000000e+000,,,,,,,,,,,,,,32,1,4.000000e+000,1.319885e-003,0.000000e+000,0,,0,
1524135477.741,,0.000000e+000,5.499905e+001,2.387378e-006,0.000000e+000,3,7.966160e-001,0.000000e+000,,,,,,,,,,,,,,32,1,4.000000e+000,3.948212e-003,0.000000e+000,0,,0,
1524135503.371,,0.000000e+000,5.499248e+001,2.450405e-006,0.000000e+000,3,8.034313e-001,0.000000e+000,,,,,,,,,,,,,,32,1,4.000000e+000,6.580353e-003,0.000000e+000,0,,0,
1524135528.401,,0.000000e+000,5.500103e+001,2.468090e-006,0.000000e+000,3,7.955436e-001,0.000000e+000,,,,,,,,,,,,,,32,1,4.000000e+000,1.052094e-002,0.000000e+000,0,,0,
1524135553.821,,0.000000e+000,5.500169e+001,2.488128e-006,0.000000e+000,3,8.411714e-001,0.000000e+000,,,,,,,,,,,,,,32,1,4.000000e+000,3.959656e-003,0.000000e+000,0,,0,
1524135578.462,,0.000000e+000,5.499840e+001,2.510150e-006,0.000000e+000,3,8.352422e-001,0.000000e+000,,,,,,,,,,,,,,32,1,4.000000e+000,5.260468e-003,0.000000e+000,0,,0,
1524135603.822,,0.000000e+000,5.500037e+001,2.362876e-006,0.000000e+000,3,8.333088e-001,0.000000e+000,,,,,,,,,,,,,,32,1,4.000000e+000,1.319885e-003,0.000000e+000,0,,0,
1524135628.832,,0.000000e+000,5.499117e+001,2.374662e-006,0.000000e+000,3,8.227803e-001,0.000000e+000,,,,,,,,,,,,,,32,1,4.000000e+000,6.568909e-003,0.000000e+000,0,,0,
1524135654.552,,0.000000e+000,5.499840e+001,2.427259e-006,0.000000e+000,3,8.105346e-001,0.000000e+000,,,,,,,,,,,,,,32,1,4.000000e+000,2.628326e-003,0.000000e+000,0,,0,
1524135679.932,,0.000000e+000,5.499248e+001,2.424208e-006,0.000000e+000,3,8.138226e-001,0.000000e+000,,,,,,,,,,,,,,32,1,4.000000e+000,6.580353e-003,0.000000e+000,0,,0,
1524135704.982,,0.000000e+000,5.499840e+001,2.457666e-006,0.000000e+000,3,8.039661e-001,0.000000e+000,,,,,,,,,,,,,,32,1,4.000000e+000,2.628326e-003,0.000000e+000,0,,0,
1524135730.592,,0.000000e+000,5.499708e+001,2.529601e-006,0.000000e+000,3,8.151199e-001,0.000000e+000,,,,,,,,,,,,,,32,1,4.000000e+000,5.260468e-003,0.000000e+000,0,,0,
1524135755.952,,0.000000e+000,5.499905e+001,2.474375e-006,0.000000e+000,3,8.014607e-001,0.000000e+000,,,,,,,,,,,,,,32,1,4.000000e+000,3.948212e-003,0.000000e+000,0,,0,
1524135781.032,,0.000000e+000,5.499906e+001,2.523114e-006,0.000000e+000,3,8.055983e-001,0.000000e+000,,,,,,,,,,,,,,32,1,4.000000e+000,6.580353e-003,0.000000e+000,0,,0,
1524135806.292,,0.000000e+000,5.499708e+001,2.498666e-006,0.000000e+000,3,8.059387e-001,0.000000e+000,,,,,,,,,,,,,,32,1,4.000000e+000,5.260468e-003,0.000000e+000,0,,0,
1524135831.032,,0.000000e+000,5.499839e+001,2.517701e-006,0.000000e+000,3,8.118992e-001,0.000000e+000,,,,,,,,,,,,,,32,1,4.000000e+000,0.000000e+000,0.000000e+000,0,,0,
1524135856.162,,0.000000e+000,5.499117e+001,2.531815e-006,0.000000e+000,3,8.115562e-001,0.000000e+000,,,,,,,,,,,,,,32,1,4.000000e+000,3.952026e-003,0.000000e+000,0,,0,
1524135881.702,,0.000000e+000,5.499839e+001,2.614131e-006,0.000000e+000,3,8.354768e-001,0.000000e+000,,,,,,,,,,,,,,32,1,4.000000e+000,0.000000e+000,0.000000e+000,0,,0,
1524135906.902,,0.000000e+000,5.499840e+001,2.626493e-006,0.000000e+000,3,8.330412e-001,0.000000e+000,,,,,,,,,,,,,,32,1,4.000000e+000,2.628326e-003,0.000000e+000,0,,0,
1524135931.862,,0.000000e+000,5.499642e+001,2.569640e-006,0.000000e+000,3,8.207503e-001,0.000000e+000,,,,,,,,,,,,,,32,1,4.000000e+000,3.940582e-003,0.000000e+000,0,,0,
1524135956.752,,0.000000e+000,5.499905e+001,2.435743e-006,0.000000e+000,3,8.588504e-001,0.000000e+000,,,,,,,,,,,,,,32,1,4.000000e+000,3.948212e-003,0.000000e+000,0,,0,
1524135981.792,,0.000000e+000,5.499643e+001,2.518204e-006,0.000000e+000,3,8.416559e-001,0.000000e+000,,,,,,,,,,,,,,32,1,4.000000e+000,1.184082e-002,0.000000e+000,0,,0,
1524136007.022,,0.000000e+000,5.500432e+001,2.540675e-006,0.000000e+000,3,8.352598e-001,0.000000e+000,,,,,,,,,,,,,,32,1,4.000000e+000,1.300812e-003,0.000000e+000,0,,0,
1524136032.492,,0.000000e+000,5.500169e+001,2.577412e-006,0.000000e+000,3,8.370502e-001,0.000000e+000,,,,,,,,,,,,,,32,1,4.000000e+000,3.959656e-003,0.000000e+000,0,,0,
1524136057.152,,0.000000e+000,5.500103e+001,2.568481e-006,0.000000e+000,3,8.278738e-001,0.000000e+000,,,,,,,,,,,,,,32,1,4.000000e+000,2.639771e-003,0.000000e+000,0,,0,
1524136082.402,,0.000000e+000,5.500103e+001,2.568204e-006,0.000000e+000,3,8.195271e-001,0.000000e+000,,,,,,,,,,,,,,32,1,4.000000e+000,7.888794e-003,0.000000e+000,0,,0,
1524136107.672,,0.000000e+000,5.499708e+001,2.609565e-006,0.000000e+000,3,8.520952e-001,0.000000e+000,,,,,,,,,,,,,,32,1,4.000000e+000,0.000000e+000,0.000000e+000,0,,0,
1524136132.462,,0.000000e+000,5.499839e+001,2.649619e-006,0.000000e+000,3,8.574298e-001,0.000000e+000,,,,,,,,,,,,,,32,1,4.000000e+000,0.000000e+000,0.000000e+000,0,,0,
1524136157.772,,0.000000e+000,5.499971e+001,2.568923e-006,0.000000e+000,3,8.289025e-001,0.000000e+000,,,,,,,,,,,,,,32,1,4.000000e+000,2.639771e-003,0.000000e+000,0,,0,
1524136182.782,,0.000000e+000,5.499643e+001,2.623729e-006,0.000000e+000,3,8.222086e-001,0.000000e+000,,,,,,,,,,,,,,32,1,4.000000e+000,9.208679e-003,0.000000e+000,0,,0,
1524136208.412,,0.000000e+000,5.499708e+001,2.634161e-006,0.000000e+000,3,8.270322e-001,0.000000e+000,,,,,,,,,,,,,,32,1,4.000000e+000,5.260468e-003,0.000000e+000,0,,0,
1524136234.252,,0.000000e+000,5.499773e+001,2.688676e-006,0.000000e+000,3,8.325385e-001,0.000000e+000,,,,,,,,,,,,,,32,1,4.000000e+000,1.308441e-003,0.000000e+000,0,,0,
1524136259.682,,0.000000e+000,5.499511e+001,2.660025e-006,0.000000e+000,3,8.602311e-001,0.000000e+000,,,,,,,,,,,,,,32,1,4.000000e+000,1.972198e-002,0.000000e+000,0,,0,
1524136285.563,,0.000000e+000,5.499511e+001,2.622535e-006,0.000000e+000,3,8.422671e-001,0.000000e+000,,,,,,,,,,,,,,32,1,4.000000e+000,3.940582e-003,0.000000e+000,0,,0,
1524136310.623,,0.000000e+000,5.499248e+001,2.637698e-006,0.000000e+000,3,8.512357e-001,0.000000e+000,,,,,,,,,,,,,,32,1,4.000000e+000,1.319885e-003,0.000000e+000,0,,0,
1524136335.833,,0.000000e+000,5.500037e+001,2.647233e-006,0.000000e+000,3,8.403920e-001,0.000000e+000,,,,,,,,,,,,,,32,1,4.000000e+000,1.319885e-003,0.000000e+000,0,,0,
1524136361.103,,0.000000e+000,5.500300e+001,2.628746e-006,0.000000e+000,3,8.442411e-001,0.000000e+000,,,,,,,,,,,,,,32,1,4.000000e+000,9.220123e-003,0.000000e+000,0,,0,
1524136386.313,,0.000000e+000,5.499775e+001,2.650281e-006,0.000000e+000,3,8.353540e-001,0.000000e+000,,,,,,,,,,,,,,32,1,4.000000e+000,9.208679e-003,0.000000e+000,0,,0,
1524136411.573,,0.000000e+000,5.499905e+001,2.636685e-006,0.000000e+000,3,8.434047e-001,0.000000e+000,,,,,,,,,,,,,,32,1,4.000000e+000,3.948212e-003,0.000000e+000,0,,0,
1524136436.793,,0.000000e+000,5.499775e+001,2.659868e-006,0.000000e+000,3,8.590892e-001,0.000000e+000,,,,,,,,,,,,,,32,1,4.000000e+000,9.208679e-003,0.000000e+000,0,,0,
1524136462.053,,0.000000e+000,5.500169e+001,2.682575e-006,0.000000e+000,3,8.416609e-001,0.000000e+000,,,,,,,,,,,,,,32,1,4.000000e+000,1.319885e-003,0.000000e+000,0,,0,
1524136487.253,,0.000000e+000,5.499773e+001,2.715893e-006,0.000000e+000,3,8.459851e-001,0.000000e+000,,,,,,,,,,,,,,32,1,4.000000e+000,1.308441e-003,0.000000e+000,0,,0,
1524136511.903,,0.000000e+000,5.499380e+001,2.668826e-006,0.000000e+000,3,8.541896e-001,0.000000e+000,,,,,,,,,,,,,,32,1,4.000000e+000,3.948212e-003,0.000000e+000,0,,0,
1524136537.193,,0.000000e+000,5.499906e+001,2.691107e-006,0.000000e+000,3,8.377177e-001,0.000000e+000,,,,,,,,,,,,,,32,1,4.000000e+000,9.220123e-003,0.000000e+000,0,,0,
1524136562.373,,0.000000e+000,5.499183e+001,2.703807e-006,0.000000e+000,3,8.414032e-001,0.000000e+000,,,,,,,,,,,,,,32,1,4.000000e+000,2.632141e-003,0.000000e+000,0,,0,
1524136587.683,,0.000000e+000,5.499709e+001,2.740968e-006,0.000000e+000,3,8.437186e-001,0.000000e+000,,,,,,,,,,,,,,32,1,4.000000e+000,7.888794e-003,0.000000e+000,0,,0,
1524136612.343,,0.000000e+000,5.499248e+001,2.717662e-006,0.000000e+000,3,8.491161e-001,0.000000e+000,,,,,,,,,,,,,,32,1,4.000000e+000,6.580353e-003,0.000000e+000,0,,0,
1524136637.573,,0.000000e+000,5.499511e+001,2.732943e-006,0.000000e+000,3,8.500130e-001,0.000000e+000,,,,,,,,,,,,,,32,1,4.000000e+000,9.201050e-003,0.000000e+000,0,,0,
1524136662.803,,0.000000e+000,5.499708e+001,2.784934e-006,0.000000e+000,3,8.751661e-001,0.000000e+000,,,,,,,,,,,,,,32,1,4.000000e+000,5.260468e-003,0.000000e+000,0,,0,
1524136688.003,,0.000000e+000,5.499643e+001,2.702904e-006,0.000000e+000,3,8.497393e-001,0.000000e+000,,,,,,,,,,,,,,32,1,4.000000e+000,1.312256e-003,0.000000e+000,0,,0,
1524136713.433,,0.000000e+000,5.500169e+001,2.766609e-006,0.000000e+000,3,8.570207e-001,0.000000e+000,,,,,,,,,,,,,,32,1,4.000000e+000,1.319885e-003,0.000000e+000,0,,0,
1524136739.513,,0.000000e+000,5.499708e+001,2.805682e-006,0.000000e+000,3,8.470120e-001,0.000000e+000,,,,,,,,,,,,,,32,1,4.000000e+000,5.260468e-003,0.000000e+000,0,,0,
1524136764.713,,0.000000e+000,5.500037e+001,2.785686e-006,0.000000e+000,3,8.359917e-001,0.000000e+000,,,,,,,,,,,,,,32,1,4.000000e+000,1.319885e-003,0.000000e+000,0,,0,
1524136789.983,,0.000000e+000,5.500169e+001,2.826042e-006,0.000000e+000,3,8.421718e-001,0.000000e+000,,,,,,,,,,,,,,32,1,4.000000e+000,1.319885e-003,0.000000e+000,0,,0,
1524136815.133,,0.000000e+000,5.500037e+001,2.807603e-006,0.000000e+000,3,8.393281e-001,0.000000e+000,,,,,,,,,,,,,,32,1,4.000000e+000,1.319885e-003,0.000000e+000,0,,0,
1524136840.413,,0.000000e+000,5.499643e+001,2.823675e-006,0.000000e+000,3,8.442675e-001,0.000000e+000,,,,,,,,,,,,,,32,1,4.000000e+000,1.312256e-003,0.000000e+000,0,,0,
1524136865.563,,0.000000e+000,5.499840e+001,2.863356e-006,0.000000e+000,3,8.522676e-001,0.000000e+000,,,,,,,,,,,,,,32,1,4.000000e+000,2.628326e-003,0.000000e+000,0,,0,
1524136890.853,,0.000000e+000,5.499773e+001,2.872701e-006,0.000000e+000,3,8.356501e-001,0.000000e+000,,,,,,,,,,,,,,32,1,4.000000e+000,1.308441e-003,0.000000e+000,0,,0,
1524136916.123,,0.000000e+000,5.499905e+001,2.868700e-006,0.000000e+000,3,8.528823e-001,0.000000e+000,,,,,,,,,,,,,,32,1,4.000000e+000,3.948212e-003,0.000000e+000,0,,0,
1524136941.523,,0.000000e+000,5.499643e+001,2.899770e-006,0.000000e+000,3,8.728136e-001,0.000000e+000,,,,,,,,,,,,,,32,1,4.000000e+000,9.208679e-003,0.000000e+000,0,,0,
1524136966.793,,0.000000e+000,5.499511e+001,2.887695e-006,0.000000e+000,3,8.680767e-001,0.000000e+000,,,,,,,,,,,,,,32,1,4.000000e+000,1.319885e-003,0.000000e+000,0,,0,
1524136991.604,,0.000000e+000,5.499708e+001,2.873007e-006,0.000000e+000,3,8.474850e-001,0.000000e+000,,,,,,,,,,,,,,32,1,4.000000e+000,5.260468e-003,0.000000e+000,0,,0,
1524137016.904,,0.000000e+000,5.499511e+001,2.854051e-006,0.000000e+000,3,8.461230e-001,0.000000e+000,,,,,,,,,,,,,,32,1,4.000000e+000,9.201050e-003,0.000000e+000,0,,0,
1524137042.184,,0.000000e+000,5.499117e+001,2.819821e-006,0.000000e+000,3,8.711790e-001,0.000000e+000,,,,,,,,,,,,,,32,1,4.000000e+000,1.312256e-003,0.000000e+000,0,,0,
1524137067.814,,0.000000e+000,5.499905e+001,2.856124e-006,0.000000e+000,3,8.623022e-001,0.000000e+000,,,,,,,,,,,,,,32,1,4.000000e+000,1.319885e-003,0.000000e+000,0,,0,
1524137092.874,,0.000000e+000,5.500103e+001,2.886658e-006,0.000000e+000,3,8.554180e-001,0.000000e+000,,,,,,,,,,,,,,32,1,4.000000e+000,7.888794e-003,0.000000e+000,0,,0,
1524137117.664,,0.000000e+000,5.499577e+001,2.909135e-006,0.000000e+000,3,8.808926e-001,0.000000e+000,,,,,,,,,,,,,,32,1,4.000000e+000,2.632141e-003,0.000000e+000,0,,0,
1524137143.004,,0.000000e+000,5.500037e+001,2.841758e-006,0.000000e+000,3,8.634790e-001,0.000000e+000,,,,,,,,,,,,,,32,1,4.000000e+000,1.319885e-003,0.000000e+000,0,,0,
1524137168.004,,0.000000e+000,5.499906e+001,2.879917e-006,0.000000e+000,3,8.585907e-001,0.000000e+000,,,,,,,,,,,,,,32,1,4.000000e+000,6.580353e-003,0.000000e+000,0,,0,
1524137193.014,,0.000000e+000,5.499906e+001,2.834736e-006,0.000000e+000,3,8.557720e-001,0.000000e+000,,,,,,,,,,,,,,32,1,4.000000e+000,6.580353e-003,0.000000e+000,0,,0,
1524137219.084,,0.000000e+000,5.499577e+001,2.863180e-006,0.000000e+000,3,8.550532e-001,0.000000e+000,,,,,,,,,,,,,,32,1,4.000000e+000,1.052094e-002,0.000000e+000,0,,0,
1524137244.784,,0.000000e+000,5.500037e+001,2.985717e-006,0.000000e+000,3,8.593912e-001,0.000000e+000,,,,,,,,,,,,,,32,1,4.000000e+000,6.587982e-003,0.000000e+000,0,,0,
1524137269.774,,0.000000e+000,5.499905e+001,3.013346e-006,0.000000e+000,3,8.427330e-001,0.000000e+000,,,,,,,,,,,,,,32,1,4.000000e+000,1.319885e-003,0.000000e+000,0,,0,
1524137295.104,,0.000000e+000,5.499248e+001,2.928974e-006,0.000000e+000,3,8.407946e-001,0.000000e+000,,,,,,,,,,,,,,32,1,4.000000e+000,1.319885e-003,0.000000e+000,0,,0,
1524137320.314,,0.000000e+000,5.500300e+001,2.963878e-006,0.000000e+000,3,8.509098e-001,0.000000e+000,,,,,,,,,,,,,,32,1,4.000000e+000,1.183701e-002,0.000000e+000,0,,0,
1524137345.614,,0.000000e+000,5.499511e+001,2.946074e-006,0.000000e+000,3,8.507792e-001,0.000000e+000,,,,,,,,,,,,,,32,1,4.000000e+000,6.568909e-003,0.000000e+000,0,,0,
1524137370.794,,0.000000e+000,5.500761e+001,2.922124e-006,0.000000e+000,3,8.590211e-001,0.000000e+000,,,,,,,,,,,,,,32,1,4.000000e+000,1.052094e-002,0.000000e+000,0,,0,
1524137396.194,,0.000000e+000,5.499512e+001,2.951845e-006,0.000000e+000,3,8.425189e-001,0.000000e+000,,,,,,,,,,,,,,32,1,4.000000e+000,1.446915e-002,0.000000e+000,0,,0,
1524137421.284,,0.000000e+000,5.499380e+001,3.004924e-006,0.000000e+000,3,8.475324e-001,0.000000e+000,,,,,,,,,,,,,,32,1,4.000000e+000,1.446915e-002,0.000000e+000,0,,0,
1524137446.534,,0.000000e+000,5.499972e+001,2.996210e-006,0.000000e+000,3,8.635606e-001,0.000000e+000,,,,,,,,,,,,,,32,1,4.000000e+000,7.900238e-003,0.000000e+000,0,,0,
1524137471.754,,0.000000e+000,5.499379e+001,2.977650e-006,0.000000e+000,3,8.492823e-001,0.000000e+000,,,,,,,,,,,,,,32,1,4.000000e+000,9.201050e-003,0.000000e+000,0,,0,
1524137496.964,,0.000000e+000,5.499906e+001,3.001946e-006,0.000000e+000,3,8.463004e-001,0.000000e+000,,,,,,,,,,,,,,32,1,4.000000e+000,6.580353e-003,0.000000e+000,0,,0,
1524137522.234,,0.000000e+000,5.499314e+001,3.030738e-006,0.000000e+000,3,8.572974e-001,0.000000e+000,,,,,,,,,,,,,,32,1,4.000000e+000,5.260468e-003,0.000000e+000,0,,0,
1524137547.434,,0.000000e+000,5.499708e+001,2.985456e-006,0.000000e+000,3,8.455959e-001,0.000000e+000,,,,,,,,,,,,,,32,1,4.000000e+000,5.260468e-003,0.000000e+000,0,,0,
1524137572.694,,0.000000e+000,5.499445e+001,3.007231e-006,0.000000e+000,3,8.430828e-001,0.000000e+000,,,,,,,,,,,,,,32,1,4.000000e+000,2.628326e-003,0.000000e+000,0,,0,
1524137597.924,,0.000000e+000,5.499841e+001,3.006472e-006,0.000000e+000,3,8.441234e-001,0.000000e+000,,,,,,,,,,,,,,32,1,4.000000e+000,1.052856e-002,0.000000e+000,0,,0,
1524137623.174,,0.000000e+000,5.499774e+001,3.016056e-006,0.000000e+000,3,8.529601e-001,0.000000e+000,,,,,,,,,,,,,,32,1,4.000000e+000,3.940582e-003,0.000000e+000,0,,0,
1524137648.424,,0.000000e+000,5.500564e+001,3.030721e-006,0.000000e+000,3,8.583140e-001,0.000000e+000,,,,,,,,,,,,,,32,1,4.000000e+000,1.710892e-002,0.000000e+000,0,,0,
1524137673.634,,0.000000e+000,5.500169e+001,2.997849e-006,0.000000e+000,3,8.508028e-001,0.000000e+000,,,,,,,,,,,,,,32,1,4.000000e+000,1.319885e-003,0.000000e+000,0,,0,
1524137698.404,,0.000000e+000,5.499773e+001,3.048583e-006,0.000000e+000,3,8.555014e-001,0.000000e+000,,,,,,,,,,,,,,32,1,4.000000e+000,1.308441e-003,0.000000e+000,0,,0,
1524137723.585,,0.000000e+000,5.499905e+001,3.047703e-006,0.000000e+000,3,8.529658e-001,0.000000e+000,,,,,,,,,,,,,,32,1,4.000000e+000,3.948212e-003,0.000000e+000,0,,0,
1524137748.625,,0.000000e+000,5.499445e+001,3.092817e-006,0.000000e+000,3,8.607768e-001,0.000000e+000,,,,,,,,,,,,,,32,1,4.000000e+000,5.260468e-003,0.000000e+000,0,,0,
1524137774.025,,0.000000e+000,5.500168e+001,3.085780e-006,0.000000e+000,3,8.577218e-001,0.000000e+000,,,,,,,,,,,,,,32,1,4.000000e+000,6.580353e-003,0.000000e+000,0,,0,
1524137799.535,,0.000000e+000,5.499972e+001,3.043696e-006,0.000000e+000,3,8.803811e-001,0.000000e+000,,,,,,,,,,,,,,32,1,4.000000e+000,5.268097e-003,0.000000e+000,0,,0,
1524137824.195,,0.000000e+000,5.499839e+001,3.057164e-006,0.000000e+000,3,8.823266e-001,0.000000e+000,,,,,,,,,,,,,,32,1,4.000000e+000,0.000000e+000,0.000000e+000,0,,0,
1524137849.275,,0.000000e+000,5.500103e+001,3.107737e-006,0.000000e+000,3,8.565838e-001,0.000000e+000,,,,,,,,,,,,,,32,1,4.000000e+000,5.279541e-003,0.000000e+000,0,,0,
1524137874.145,,0.000000e+000,5.499445e+001,3.111237e-006,0.000000e+000,3,8.611271e-001,0.000000e+000,,,,,,,,,,,,,,32,1,4.000000e+000,0.000000e+000,0.000000e+000,0,,0,
1524137899.135,,0.000000e+000,5.499905e+001,3.111244e-006,0.000000e+000,3,8.462854e-001,0.000000e+000,,,,,,,,,,,,,,32,1,4.000000e+000,1.319885e-003,0.000000e+000,0,,0,
1524137924.635,,0.000000e+000,5.499773e+001,3.146615e-006,0.000000e+000,3,8.637626e-001,0.000000e+000,,,,,,,,,,,,,,32,1,4.000000e+000,1.308441e-003,0.000000e+000,0,,0,
1524137949.575,,0.000000e+000,5.499972e+001,3.118647e-006,0.000000e+000,3,8.847347e-001,0.000000e+000,,,,,,,,,,,,,,32,1,4.000000e+000,7.900238e-003,0.000000e+000,0,,0,
1524137975.085,,0.000000e+000,5.499642e+001,3.151516e-006,0.000000e+000,3,8.979926e-001,0.000000e+000,,,,,,,,,,,,,,32,1,4.000000e+000,3.940582e-003,0.000000e+000,0,,0,
1524138000.275,,0.000000e+000,5.499839e+001,3.124672e-006,0.000000e+000,3,8.861359e-001,0.000000e+000,,,,,,,,,,,,,,32,1,4.000000e+000,0.000000e+000,0.000000e+000,0,,0,
1524138025.035,,0.000000e+000,5.499774e+001,3.127552e-006,0.000000e+000,3,8.930191e-001,0.000000e+000,,,,,,,,,,,,,,32,1,4.000000e+000,6.580353e-003,0.000000e+000,0,,0,
1524138049.805,,0.000000e+000,5.500169e+001,3.083660e-006,0.000000e+000,3,8.684026e-001,0.000000e+000,,,,,,,,,,,,,,32,1,4.000000e+000,1.184082e-002,0.000000e+000,0,,0,
1524138074.655,,0.000000e+000,5.499905e+001,3.095314e-006,0.000000e+000,3,8.632493e-001,0.000000e+000,,,,,,,,,,,,,,32,1,4.000000e+000,3.948212e-003,0.000000e+000,0,,0,
1524138099.375,,0.000000e+000,5.499380e+001,3.146131e-006,0.000000e+000,3,8.660651e-001,0.000000e+000,,,,,,,,,,,,,,32,1,4.000000e+000,1.710129e-002,0.000000e+000,0,,0,
1524138124.415,,0.000000e+000,5.499511e+001,3.118823e-006,0.000000e+000,3,8.650940e-001,0.000000e+000,,,,,,,,,,,,,,32,1,4.000000e+000,1.319885e-003,0.000000e+000,0,,0,
1524138149.895,,0.000000e+000,5.499577e+001,3.164460e-006,0.000000e+000,3,8.586049e-001,0.000000e+000,,,,,,,,,,,,,,32,1,4.000000e+000,0.000000e+000,0.000000e+000,0,,0,
1524138175.305,,0.000000e+000,5.499577e+001,3.137231e-006,0.000000e+000,3,8.953678e-001,0.000000e+000,,,,,,,,,,,,,,32,1,4.000000e+000,1.052094e-002,0.000000e+000,0,,0,
1524138201.135,,0.000000e+000,5.500169e+001,3.057395e-006,0.000000e+000,3,8.678436e-001,0.000000e+000,,,,,,,,,,,,,,32,1,4.000000e+000,9.208679e-003,0.000000e+000,0,,0,
1524138226.365,,0.000000e+000,5.499971e+001,3.059136e-006,0.000000e+000,3,8.764319e-001,0.000000e+000,,,,,,,,,,,,,,32,1,4.000000e+000,0.000000e+000,0.000000e+000,0,,0,
1524138251.285,,0.000000e+000,5.500234e+001,3.067223e-006,0.000000e+000,3,8.861108e-001,0.000000e+000,,,,,,,,,,,,,,32,1,4.000000e+000,7.900238e-003,0.000000e+000,0,,0,
1524138276.505,,0.000000e+000,5.500234e+001,3.105107e-006,0.000000e+000,3,8.763943e-001,0.000000e+000,,,,,,,,,,,,,,32,1,4.000000e+000,5.260468e-003,0.000000e+000,0,,0,
1524138301.735,,0.000000e+000,5.499643e+001,3.090657e-006,0.000000e+000,3,8.791165e-001,0.000000e+000,,,,,,,,,,,,,,32,1,4.000000e+000,1.312256e-003,0.000000e+000,0,,0,
1524138326.975,,0.000000e+000,5.499445e+001,3.102246e-006,0.000000e+000,3,8.735269e-001,0.000000e+000,,,,,,,,,,,,,,32,1,4.000000e+000,0.000000e+000,0.000000e+000,0,,0,
1524138352.205,,0.000000e+000,5.499840e+001,3.104982e-006,0.000000e+000,3,8.756180e-001,0.000000e+000,,,,,,,,,,,,,,32,1,4.000000e+000,5.260468e-003,0.000000e+000,0,,0,
1524138377.445,,0.000000e+000,5.499905e+001,3.083925e-006,0.000000e+000,3,8.702520e-001,0.000000e+000,,,,,,,,,,,,,,32,1,4.000000e+000,3.948212e-003,0.000000e+000,0,,0,
1524138402.685,,0.000000e+000,5.499577e+001,3.112352e-006,0.000000e+000,3,8.770083e-001,0.000000e+000,,,,,,,,,,,,,,32,1,4.000000e+000,0.000000e+000,0.000000e+000,0,,0,
1524138427.906,,0.000000e+000,5.499971e+001,3.103369e-006,0.000000e+000,3,8.766223e-001,0.000000e+000,,,,,,,,,,,,,,32,1,4.000000e+000,1.052094e-002,0.000000e+000,0,,0,
1524138453.136,,0.000000e+000,5.499577e+001,3.092280e-006,0.000000e+000,3,8.782014e-001,0.000000e+000,,,,,,,,,,,,,,32,1,4.000000e+000,5.249023e-003,0.000000e+000,0,,0,
1524138478.376,,0.000000e+000,5.499248e+001,3.100284e-006,0.000000e+000,3,8.779813e-001,0.000000e+000,,,,,,,,,,,,,,32,1,4.000000e+000,1.319885e-003,0.000000e+000,0,,0,
1524138503.606,,0.000000e+000,5.499313e+001,3.173281e-006,0.000000e+000,3,8.759134e-001,0.000000e+000,,,,,,,,,,,,,,32,1,4.000000e+000,1.050949e-002,0.000000e+000,0,,0,
1524138528.836,,0.000000e+000,5.499577e+001,3.100746e-006,0.000000e+000,3,8.767834e-001,0.000000e+000,,,,,,,,,,,,,,32,1,4.000000e+000,0.000000e+000,0.000000e+000,0,,0,
1524138554.076,,0.000000e+000,5.498985e+001,3.112523e-006,0.000000e+000,3,8.779508e-001,0.000000e+000,,,,,,,,,,,,,,32,1,4.000000e+000,1.319885e-003,0.000000e+000,0,,0,
1524138579.316,,0.000000e+000,5.499774e+001,3.114145e-006,0.000000e+000,3,8.825398e-001,0.000000e+000,,,,,,,,,,,,,,32,1,4.000000e+000,3.940582e-003,0.000000e+000,0,,0,
1524138604.546,,0.000000e+000,5.500235e+001,3.156513e-006,0.000000e+000,3,8.758101e-001,0.000000e+000,,,,,,,,,,,,,,32,1,4.000000e+000,0.000000e+000,0.000000e+000,0,,0,
1524138629.776,,0.000000e+000,5.499972e+001,3.146246e-006,0.000000e+000,3,8.834703e-001,0.000000e+000,,,,,,,,,,,,,,32,1,4.000000e+000,7.900238e-003,0.000000e+000,0,,0,