File: Experimental Raw Data/TC04-12-01K TRMac VRMde/Ndat/TC04-12-01K_TRMac_56K_0.32Kmin_VRMde_55K.dc.dat
[Header]
TITLE,MPMS DC Measurement
BYAPP,MPMS Measurement,2.1,Summary
FILEOPENTIME, 1524545944.477000 4/23/2018, 10:59:04 PM

INFO, APPNAME, MPMS MultiVu Application, Revision 1.61,  Build 082

INFO, NAME, TC04-12-01K
INFO, WEIGHT, 1.000
INFO, AREA, 1.000
INFO, LENGTH, 1.000
INFO, SHAPE, 0
INFO, COMMENT,
INFO, SEQUENCE FILE: TRMac_56K_0.32Kmin_VRMde_55K.seq


INFO, BACKGROUND DATA FILE:, None


STARTUPAXIS,X,4,LINEAR,AUTO,0.000000,0.000000
STARTUPAXIS,Y1,5,LINEAR,AUTO,0.000000,0.000000


STARTUPGROUP,Longitudinal
FIELDGROUP,Longitudinal,1,2,3,4,5,6,7,8,9,15,16,17,18,27,28
FIELDGROUP,Transverse,1,2,3,4,10,11,12,13,14,19,20,21,22,27,28

PLOT_APPEARANCE,ALL,HORZ_GRID_ON,VERT_GRID_ON,MARKERS_AND_LINES

[Data]
Time,Comment,Field (Oe),Temperature (K),Long Moment (emu),Long Scan Std Dev,Long Algorithm,Long Reg Fit,Long Percent Error (%),Trans Moment (emu),Trans Scan Std Dev,Trans Algorithm,Trans Reg Fit,Trans Percent Error (%),Long Moment [w/o ABS] (emu),Long Scan Std Dev [w/o ABS],Long Reg Fit [w/o ABS],Long Percent Error [w/o ABS] (%),Trans Moment [w/o ABS] (emu),Trans Scan Std Dev [w/o ABS],Trans Reg Fit [w/o ABS],Trans Percent Error [w/o ABS] (%),Points per Scan,Scans per Measurement,Scan Length (cm),Delta Temp (K),Rot Position (deg),Error,EC Comp. Running,Using ABS,
1524545944.477,,0.000000e+000,5.499051e+001,4.301352e-006,0.000000e+000,3,7.542512e-001,0.000000e+000,,,,,,,,,,,,,,32,1,4.000000e+000,2.632141e-003,0.000000e+000,0,,0,
1524545982.267,,0.000000e+000,5.501024e+001,2.693475e-006,0.000000e+000,3,6.723386e-001,0.000000e+000,,,,,,,,,,,,,,32,1,4.000000e+000,1.578140e-002,0.000000e+000,0,,0,
1524546020.097,,0.000000e+000,5.501155e+001,1.838059e-006,0.000000e+000,3,5.154390e-001,0.000000e+000,,,,,,,,,,,,,,32,1,4.000000e+000,1.052856e-002,0.000000e+000,0,,0,
1524546057.047,,0.000000e+000,5.501287e+001,1.626141e-006,0.000000e+000,3,4.834737e-001,0.000000e+000,,,,,,,,,,,,,,32,1,4.000000e+000,2.639771e-003,0.000000e+000,0,,0,
1524546094.927,,0.000000e+000,5.500300e+001,1.475889e-006,0.000000e+000,3,4.234312e-001,0.000000e+000,,,,,,,,,,,,,,32,1,4.000000e+000,3.940582e-003,0.000000e+000,0,,0,
1524546132.228,,0.000000e+000,5.501418e+001,1.348495e-006,0.000000e+000,3,3.749848e-001,0.000000e+000,,,,,,,,,,,,,,32,1,4.000000e+000,7.892609e-003,0.000000e+000,0,,0,
1524546169.878,,0.000000e+000,5.501551e+001,1.314130e-006,0.000000e+000,3,3.584024e-001,0.000000e+000,,,,,,,,,,,,,,32,1,4.000000e+000,0.000000e+000,0.000000e+000,0,,0,
1524546207.348,,0.000000e+000,5.501353e+001,3.540671e-007,0.000000e+000,3,0.000000e+000,0.000000e+000,,,,,,,,,,,,,,32,1,4.000000e+000,3.959656e-003,0.000000e+000,0,,0,
1524546250.422,,0.000000e+000,5.501748e+001,2.274104e-007,0.000000e+000,2,0.000000e+000,0.000000e+000,,,,,,,,,,,,,,32,1,4.000000e+000,1.312256e-003,0.000000e+000,0,,0,
1524546290.254,,0.000000e+000,5.501484e+001,-1.947884e-006,0.000000e+000,3,8.058950e-001,0.000000e+000,,,,,,,,,,,,,,32,1,4.000000e+000,6.580353e-003,0.000000e+000,0,,0,
1524546331.308,,0.000000e+000,5.502077e+001,4.319219e-008,0.000000e+000,2,0.000000e+000,0.000000e+000,,,,,,,,,,,,,,32,1,4.000000e+000,1.316833e-002,0.000000e+000,0,,0,
1524546373.364,,0.000000e+000,5.501353e+001,-8.366337e-008,0.000000e+000,2,0.000000e+000,0.000000e+000,,,,,,,,,,,,,,32,1,4.000000e+000,1.319885e-003,0.000000e+000,0,,0,
1524546412.246,,0.000000e+000,5.501353e+001,9.226194e-007,0.000000e+000,3,0.000000e+000,0.000000e+000,,,,,,,,,,,,,,32,1,4.000000e+000,1.319885e-003,0.000000e+000,0,,0,
1524546453.360,,0.000000e+000,5.501089e+001,1.200007e-006,0.000000e+000,3,1.567332e-001,0.000000e+000,,,,,,,,,,,,,,32,1,4.000000e+000,3.952026e-003,0.000000e+000,0,,0,
1524546493.272,,0.000000e+000,5.501287e+001,1.179038e-006,0.000000e+000,3,1.432422e-001,0.000000e+000,,,,,,,,,,,,,,32,1,4.000000e+000,1.052094e-002,0.000000e+000,0,,0,
1524546530.972,,0.000000e+000,5.500300e+001,1.039724e-006,0.000000e+000,3,6.335144e-002,0.000000e+000,,,,,,,,,,,,,,32,1,4.000000e+000,6.580353e-003,0.000000e+000,0,,0,
1524546568.682,,0.000000e+000,5.500103e+001,1.278078e-006,0.000000e+000,3,2.353667e-001,0.000000e+000,,,,,,,,,,,,,,32,1,4.000000e+000,2.639771e-003,0.000000e+000,0,,0,
1524546608.934,,0.000000e+000,5.500169e+001,-2.853035e-007,0.000000e+000,2,0.000000e+000,0.000000e+000,,,,,,,,,,,,,,32,1,4.000000e+000,1.319885e-003,0.000000e+000,0,,0,
1524546647.616,,0.000000e+000,5.500300e+001,1.159006e-006,0.000000e+000,3,9.519499e-002,0.000000e+000,,,,,,,,,,,,,,32,1,4.000000e+000,6.580353e-003,0.000000e+000,0,,0,
1524546684.536,,0.000000e+000,5.500169e+001,1.090585e-006,0.000000e+000,3,1.622846e-001,0.000000e+000,,,,,,,,,,,,,,32,1,4.000000e+000,3.959656e-003,0.000000e+000,0,,0,
1524546722.716,,0.000000e+000,5.499708e+001,1.256645e-006,0.000000e+000,3,1.701205e-001,0.000000e+000,,,,,,,,,,,,,,32,1,4.000000e+000,0.000000e+000,0.000000e+000,0,,0,
1524546763.660,,0.000000e+000,5.499972e+001,1.123987e-006,0.000000e+000,3,5.185289e-002,0.000000e+000,,,,,,,,,,,,,,32,1,4.000000e+000,7.900238e-003,0.000000e+000,0,,0,
1524546801.150,,0.000000e+000,5.500695e+001,1.166526e-006,0.000000e+000,3,4.114549e-002,0.000000e+000,,,,,,,,,,,,,,32,1,4.000000e+000,1.319885e-003,0.000000e+000,0,,0,
1524546841.195,,0.000000e+000,5.500366e+001,1.210952e-006,0.000000e+000,3,1.219521e-001,0.000000e+000,,,,,,,,,,,,,,32,1,4.000000e+000,2.620697e-003,0.000000e+000,0,,0,
1524546882.419,,0.000000e+000,5.500234e+001,-3.541478e-007,0.000000e+000,2,0.000000e+000,0.000000e+000,,,,,,,,,,,,,,32,1,4.000000e+000,7.900238e-003,0.000000e+000,0,,0,
1524546924.555,,0.000000e+000,5.500300e+001,-3.851579e-007,0.000000e+000,2,0.000000e+000,0.000000e+000,,,,,,,,,,,,,,32,1,4.000000e+000,3.940582e-003,0.000000e+000,0,,0,
1524546968.041,,0.000000e+000,5.500497e+001,-4.022328e-007,0.000000e+000,2,0.000000e+000,0.000000e+000,,,,,,,,,,,,,,32,1,4.000000e+000,7.888794e-003,0.000000e+000,0,,0,
1524547010.427,,0.000000e+000,5.500300e+001,-3.952484e-007,0.000000e+000,2,0.000000e+000,0.000000e+000,,,,,,,,,,,,,,32,1,4.000000e+000,3.940582e-003,0.000000e+000,0,,0,
1524547053.253,,0.000000e+000,5.500037e+001,-4.464080e-007,0.000000e+000,2,0.000000e+000,0.000000e+000,,,,,,,,,,,,,,32,1,4.000000e+000,1.319885e-003,0.000000e+000,0,,0,
1524547095.789,,0.000000e+000,5.499380e+001,-5.066752e-007,0.000000e+000,2,0.000000e+000,0.000000e+000,,,,,,,,,,,,,,32,1,4.000000e+000,6.572723e-003,0.000000e+000,0,,0,
1524547138.605,,0.000000e+000,5.499840e+001,-4.913152e-007,0.000000e+000,2,0.000000e+000,0.000000e+000,,,,,,,,,,,,,,32,1,4.000000e+000,2.628326e-003,0.000000e+000,0,,0,
1524547181.341,,0.000000e+000,5.500037e+001,-5.258693e-007,0.000000e+000,2,0.000000e+000,0.000000e+000,,,,,,,,,,,,,,32,1,4.000000e+000,1.319885e-003,0.000000e+000,0,,0,
1524547223.507,,0.000000e+000,5.499840e+001,-4.161398e-007,0.000000e+000,2,0.000000e+000,0.000000e+000,,,,,,,,,,,,,,32,1,4.000000e+000,5.260468e-003,0.000000e+000,0,,0,
1524547265.783,,0.000000e+000,5.499708e+001,-4.925685e-007,0.000000e+000,2,0.000000e+000,0.000000e+000,,,,,,,,,,,,,,32,1,4.000000e+000,0.000000e+000,0.000000e+000,0,,0,
1524547308.719,,0.000000e+000,5.499380e+001,-5.790537e-007,0.000000e+000,2,0.000000e+000,0.000000e+000,,,,,,,,,,,,,,32,1,4.000000e+000,3.948212e-003,0.000000e+000,0,,0,
1524547350.855,,0.000000e+000,5.499248e+001,-5.598687e-007,0.000000e+000,2,0.000000e+000,0.000000e+000,,,,,,,,,,,,,,32,1,4.000000e+000,9.201050e-003,0.000000e+000,0,,0,
1524547393.941,,0.000000e+000,5.500169e+001,-4.851310e-007,0.000000e+000,2,0.000000e+000,0.000000e+000,,,,,,,,,,,,,,32,1,4.000000e+000,9.208679e-003,0.000000e+000,0,,0,
1524547437.357,,0.000000e+000,5.500037e+001,-5.107225e-007,0.000000e+000,2,0.000000e+000,0.000000e+000,,,,,,,,,,,,,,32,1,4.000000e+000,3.959656e-003,0.000000e+000,0,,0,
1524547479.381,,0.000000e+000,5.500432e+001,-4.790878e-007,0.000000e+000,2,0.000000e+000,0.000000e+000,,,,,,,,,,,,,,32,1,4.000000e+000,1.446915e-002,0.000000e+000,0,,0,
1524547521.597,,0.000000e+000,5.500037e+001,-6.070097e-007,0.000000e+000,2,0.000000e+000,0.000000e+000,,,,,,,,,,,,,,32,1,4.000000e+000,1.446915e-002,0.000000e+000,0,,0,
1524547563.624,,0.000000e+000,5.499182e+001,-5.754179e-007,0.000000e+000,2,0.000000e+000,0.000000e+000,,,,,,,,,,,,,,32,1,4.000000e+000,5.260468e-003,0.000000e+000,0,,0,
1524547607.740,,0.000000e+000,5.499643e+001,-5.988297e-007,0.000000e+000,2,0.000000e+000,0.000000e+000,,,,,,,,,,,,,,32,1,4.000000e+000,1.312256e-003,0.000000e+000,0,,0,
1524547651.096,,0.000000e+000,5.500366e+001,-5.271768e-007,0.000000e+000,2,0.000000e+000,0.000000e+000,,,,,,,,,,,,,,32,1,4.000000e+000,1.842117e-002,0.000000e+000,0,,0,
1524547692.892,,0.000000e+000,5.500432e+001,-5.448258e-007,0.000000e+000,2,0.000000e+000,0.000000e+000,,,,,,,,,,,,,,32,1,4.000000e+000,6.580353e-003,0.000000e+000,0,,0,
1524547737.008,,0.000000e+000,5.499380e+001,-6.244969e-007,0.000000e+000,2,0.000000e+000,0.000000e+000,,,,,,,,,,,,,,32,1,4.000000e+000,1.308441e-003,0.000000e+000,0,,0,
1524547780.544,,0.000000e+000,5.499709e+001,-6.166832e-007,0.000000e+000,2,0.000000e+000,0.000000e+000,,,,,,,,,,,,,,32,1,4.000000e+000,1.052856e-002,0.000000e+000,0,,0,
1524547821.938,,0.000000e+000,5.499906e+001,-1.689962e-006,0.000000e+000,3,6.869639e-001,0.000000e+000,,,,,,,,,,,,,,32,1,4.000000e+000,9.220123e-003,0.000000e+000,0,,0,
1524547864.644,,0.000000e+000,5.499971e+001,-5.329874e-007,0.000000e+000,2,0.000000e+000,0.000000e+000,,,,,,,,,,,,,,32,1,4.000000e+000,2.639771e-003,0.000000e+000,0,,0,
1524547905.468,,0.000000e+000,5.499972e+001,-5.453708e-007,0.000000e+000,2,0.000000e+000,0.000000e+000,,,,,,,,,,,,,,32,1,4.000000e+000,1.314926e-002,0.000000e+000,0,,0,
1524547948.132,,0.000000e+000,5.499775e+001,-5.498678e-007,0.000000e+000,2,0.000000e+000,0.000000e+000,,,,,,,,,,,,,,32,1,4.000000e+000,1.184845e-002,0.000000e+000,0,,0,
1524547989.256,,0.000000e+000,5.500037e+001,-5.836535e-007,0.000000e+000,2,0.000000e+000,0.000000e+000,,,,,,,,,,,,,,32,1,4.000000e+000,9.201050e-003,0.000000e+000,0,,0,
1524548032.372,,0.000000e+000,5.500103e+001,-6.023204e-007,0.000000e+000,2,0.000000e+000,0.000000e+000,,,,,,,,,,,,,,32,1,4.000000e+000,0.000000e+000,0.000000e+000,0,,0,
1524548073.746,,0.000000e+000,5.499577e+001,-4.777378e-007,0.000000e+000,2,0.000000e+000,0.000000e+000,,,,,,,,,,,,,,32,1,4.000000e+000,7.888794e-003,0.000000e+000,0,,0,
1524548116.372,,0.000000e+000,5.499840e+001,-6.361371e-007,0.000000e+000,2,0.000000e+000,0.000000e+000,,,,,,,,,,,,,,32,1,4.000000e+000,5.260468e-003,0.000000e+000,0,,0,
1524548157.206,,0.000000e+000,5.499380e+001,-1.819346e-006,0.000000e+000,3,7.087816e-001,0.000000e+000,,,,,,,,,,,,,,32,1,4.000000e+000,6.572723e-003,0.000000e+000,0,,0,
1524548200.292,,0.000000e+000,5.500432e+001,-6.127852e-007,0.000000e+000,2,0.000000e+000,0.000000e+000,,,,,,,,,,,,,,32,1,4.000000e+000,3.940582e-003,0.000000e+000,0,,0,
1524548240.575,,0.000000e+000,5.500037e+001,-5.364150e-007,0.000000e+000,2,0.000000e+000,0.000000e+000,,,,,,,,,,,,,,32,1,4.000000e+000,3.959656e-003,0.000000e+000,0,,0,
1524548281.577,,0.000000e+000,5.499511e+001,-5.260326e-007,0.000000e+000,2,0.000000e+000,0.000000e+000,,,,,,,,,,,,,,32,1,4.000000e+000,6.568909e-003,0.000000e+000,0,,0,
1524548322.241,,0.000000e+000,5.500103e+001,-1.543603e-006,0.000000e+000,3,7.444504e-001,0.000000e+000,,,,,,,,,,,,,,32,1,4.000000e+000,5.279541e-003,0.000000e+000,0,,0,
1524548363.395,,0.000000e+000,5.499380e+001,-1.681024e-006,0.000000e+000,3,7.412927e-001,0.000000e+000,,,,,,,,,,,,,,32,1,4.000000e+000,3.948212e-003,0.000000e+000,0,,0,
1524548402.827,,0.000000e+000,5.499445e+001,-1.661678e-006,0.000000e+000,3,7.177953e-001,0.000000e+000,,,,,,,,,,,,,,32,1,4.000000e+000,0.000000e+000,0.000000e+000,0,,0,
1524548444.081,,0.000000e+000,5.499380e+001,-1.706849e-006,0.000000e+000,3,6.910590e-001,0.000000e+000,,,,,,,,,,,,,,32,1,4.000000e+000,3.948212e-003,0.000000e+000,0,,0,
1524548485.345,,0.000000e+000,5.499445e+001,-5.046975e-007,0.000000e+000,2,0.000000e+000,0.000000e+000,,,,,,,,,,,,,,32,1,4.000000e+000,2.628326e-003,0.000000e+000,0,,0,
1524548527.339,,0.000000e+000,5.499643e+001,-1.712531e-006,0.000000e+000,3,7.499533e-001,0.000000e+000,,,,,,,,,,,,,,32,1,4.000000e+000,1.312256e-003,0.000000e+000,0,,0,
1524548568.613,,0.000000e+000,5.499248e+001,-5.997381e-007,0.000000e+000,2,0.000000e+000,0.000000e+000,,,,,,,,,,,,,,32,1,4.000000e+000,3.940582e-003,0.000000e+000,0,,0,
1524548609.627,,0.000000e+000,5.499774e+001,-5.365558e-007,0.000000e+000,2,0.000000e+000,0.000000e+000,,,,,,,,,,,,,,32,1,4.000000e+000,3.940582e-003,0.000000e+000,0,,0,
1524548650.601,,0.000000e+000,5.499773e+001,-1.809928e-006,0.000000e+000,3,7.399937e-001,0.000000e+000,,,,,,,,,,,,,,32,1,4.000000e+000,1.308441e-003,0.000000e+000,0,,0,
1524548692.605,,0.000000e+000,5.499314e+001,-5.835448e-007,0.000000e+000,2,0.000000e+000,0.000000e+000,,,,,,,,,,,,,,32,1,4.000000e+000,1.578140e-002,0.000000e+000,0,,0,
1524548736.721,,0.000000e+000,5.500234e+001,-6.301598e-007,0.000000e+000,2,0.000000e+000,0.000000e+000,,,,,,,,,,,,,,32,1,4.000000e+000,5.260468e-003,0.000000e+000,0,,0,
1524548778.075,,0.000000e+000,5.499709e+001,-5.837244e-007,0.000000e+000,2,0.000000e+000,0.000000e+000,,,,,,,,,,,,,,32,1,4.000000e+000,7.888794e-003,0.000000e+000,0,,0,
1524548818.049,,0.000000e+000,5.500103e+001,-1.772316e-006,0.000000e+000,3,7.711758e-001,0.000000e+000,,,,,,,,,,,,,,32,1,4.000000e+000,2.639771e-003,0.000000e+000,0,,0,
1524548857.351,,0.000000e+000,5.499314e+001,-1.773523e-006,0.000000e+000,3,7.374265e-001,0.000000e+000,,,,,,,,,,,,,,32,1,4.000000e+000,0.000000e+000,0.000000e+000,0,,0,
1524548900.057,,0.000000e+000,5.500169e+001,-5.747705e-007,0.000000e+000,2,0.000000e+000,0.000000e+000,,,,,,,,,,,,,,32,1,4.000000e+000,3.959656e-003,0.000000e+000,0,,0,
1524548943.513,,0.000000e+000,5.499775e+001,-5.946486e-007,0.000000e+000,2,0.000000e+000,0.000000e+000,,,,,,,,,,,,,,32,1,4.000000e+000,9.208679e-003,0.000000e+000,0,,0,
1524548984.588,,0.000000e+000,5.499972e+001,-5.891125e-007,0.000000e+000,2,0.000000e+000,0.000000e+000,,,,,,,,,,,,,,32,1,4.000000e+000,5.268097e-003,0.000000e+000,0,,0,
1524549023.250,,0.000000e+000,5.499380e+001,-5.481743e-007,0.000000e+000,2,0.000000e+000,0.000000e+000,,,,,,,,,,,,,,32,1,4.000000e+000,6.572723e-003,0.000000e+000,0,,0,
1524549064.214,,0.000000e+000,5.499972e+001,-5.860745e-007,0.000000e+000,2,0.000000e+000,0.000000e+000,,,,,,,,,,,,,,32,1,4.000000e+000,7.900238e-003,0.000000e+000,0,,0,
1524549103.466,,0.000000e+000,5.499905e+001,-5.663938e-007,0.000000e+000,2,0.000000e+000,0.000000e+000,,,,,,,,,,,,,,32,1,4.000000e+000,1.319885e-003,0.000000e+000,0,,0,
1524549143.840,,0.000000e+000,5.499577e+001,-6.039155e-007,0.000000e+000,2,0.000000e+000,0.000000e+000,,,,,,,,,,,,,,32,1,4.000000e+000,5.249023e-003,0.000000e+000,0,,0,
1524549184.644,,0.000000e+000,5.499248e+001,-1.771188e-006,0.000000e+000,3,7.039677e-001,0.000000e+000,,,,,,,,,,,,,,32,1,4.000000e+000,1.319885e-003,0.000000e+000,0,,0,
1524549226.578,,0.000000e+000,5.499906e+001,-5.642807e-007,0.000000e+000,2,0.000000e+000,0.000000e+000,,,,,,,,,,,,,,32,1,4.000000e+000,6.580353e-003,0.000000e+000,0,,0,
1524549267.262,,0.000000e+000,5.498788e+001,-5.826876e-007,0.000000e+000,2,0.000000e+000,0.000000e+000,,,,,,,,,,,,,,32,1,4.000000e+000,2.628326e-003,0.000000e+000,0,,0,
1524549309.576,,0.000000e+000,5.499972e+001,-1.754745e-006,0.000000e+000,3,7.459652e-001,0.000000e+000,,,,,,,,,,,,,,32,1,4.000000e+000,5.268097e-003,0.000000e+000,0,,0,
1524549348.428,,0.000000e+000,5.499511e+001,-1.763765e-006,0.000000e+000,3,7.480053e-001,0.000000e+000,,,,,,,,,,,,,,32,1,4.000000e+000,3.940582e-003,0.000000e+000,0,,0,
1524549392.144,,0.000000e+000,5.499511e+001,-5.966485e-007,0.000000e+000,2,0.000000e+000,0.000000e+000,,,,,,,,,,,,,,32,1,4.000000e+000,6.568909e-003,0.000000e+000,0,,0,
1524549430.166,,0.000000e+000,5.500234e+001,-1.672162e-006,0.000000e+000,3,6.753531e-001,0.000000e+000,,,,,,,,,,,,,,32,1,4.000000e+000,7.900238e-003,0.000000e+000,0,,0,
1524549471.550,,0.000000e+000,5.499380e+001,-5.923433e-007,0.000000e+000,2,0.000000e+000,0.000000e+000,,,,,,,,,,,,,,32,1,4.000000e+000,2.499008e-002,0.000000e+000,0,,0,
1524549512.924,,0.000000e+000,5.499840e+001,-5.984203e-007,0.000000e+000,2,0.000000e+000,0.000000e+000,,,,,,,,,,,,,,32,1,4.000000e+000,7.900238e-003,0.000000e+000,0,,0,
1524549556.440,,0.000000e+000,5.499577e+001,-6.061715e-007,0.000000e+000,2,0.000000e+000,0.000000e+000,,,,,,,,,,,,,,32,1,4.000000e+000,2.632141e-003,0.000000e+000,0,,0,
1524549593.590,,0.000000e+000,5.499906e+001,-1.710881e-006,0.000000e+000,3,7.374805e-001,0.000000e+000,,,,,,,,,,,,,,32,1,4.000000e+000,9.220123e-003,0.000000e+000,0,,0,
1524549635.986,,0.000000e+000,5.500103e+001,-5.639201e-007,0.000000e+000,2,0.000000e+000,0.000000e+000,,,,,,,,,,,,,,32,1,4.000000e+000,7.888794e-003,0.000000e+000,0,,0,
1524549675.149,,0.000000e+000,5.499313e+001,-5.759357e-007,0.000000e+000,2,0.000000e+000,0.000000e+000,,,,,,,,,,,,,,32,1,4.000000e+000,1.314926e-002,0.000000e+000,0,,0,
1524549715.183,,0.000000e+000,5.499709e+001,-1.746959e-006,0.000000e+000,3,7.397630e-001,0.000000e+000,,,,,,,,,,,,,,32,1,4.000000e+000,7.888794e-003,0.000000e+000,0,,0,
1524549758.419,,0.000000e+000,5.499774e+001,-6.179064e-007,0.000000e+000,2,0.000000e+000,0.000000e+000,,,,,,,,,,,,,,32,1,4.000000e+000,6.580353e-003,0.000000e+000,0,,0,
1524549798.883,,0.000000e+000,5.499183e+001,-6.000363e-007,0.000000e+000,2,0.000000e+000,0.000000e+000,,,,,,,,,,,,,,32,1,4.000000e+000,2.632141e-003,0.000000e+000,0,,0,
1524549837.435,,0.000000e+000,5.499840e+001,-1.670651e-006,0.000000e+000,3,7.192121e-001,0.000000e+000,,,,,,,,,,,,,,32,1,4.000000e+000,5.260468e-003,0.000000e+000,0,,0,
1524549879.449,,0.000000e+000,5.499840e+001,-5.794953e-007,0.000000e+000,2,0.000000e+000,0.000000e+000,,,,,,,,,,,,,,32,1,4.000000e+000,5.260468e-003,0.000000e+000,0,,0,
1524549922.825,,0.000000e+000,5.499774e+001,-5.966771e-007,0.000000e+000,2,0.000000e+000,0.000000e+000,,,,,,,,,,,,,,32,1,4.000000e+000,3.940582e-003,0.000000e+000,0,,0,
1524549963.259,,0.000000e+000,5.499511e+001,-5.690266e-007,0.000000e+000,2,0.000000e+000,0.000000e+000,,,,,,,,,,,,,,32,1,4.000000e+000,1.319885e-003,0.000000e+000,0,,0,
1524550005.525,,0.000000e+000,5.500168e+001,-6.211600e-007,0.000000e+000,2,0.000000e+000,0.000000e+000,,,,,,,,,,,,,,32,1,4.000000e+000,6.580353e-003,0.000000e+000,0,,0,
1524550045.899,,0.000000e+000,5.499643e+001,-6.365730e-007,0.000000e+000,2,0.000000e+000,0.000000e+000,,,,,,,,,,,,,,32,1,4.000000e+000,6.568909e-003,0.000000e+000,0,,0,
1524550087.083,,0.000000e+000,5.499906e+001,-5.971406e-007,0.000000e+000,2,0.000000e+000,0.000000e+000,,,,,,,,,,,,,,32,1,4.000000e+000,9.220123e-003,0.000000e+000,0,,0,
1524550129.979,,0.000000e+000,5.500103e+001,-6.443137e-007,0.000000e+000,2,0.000000e+000,0.000000e+000,,,,,,,,,,,,,,32,1,4.000000e+000,2.639771e-003,0.000000e+000,0,,0,
1524550168.971,,0.000000e+000,5.499511e+001,-1.719803e-006,0.000000e+000,3,7.078916e-001,0.000000e+000,,,,,,,,,,,,,,32,1,4.000000e+000,1.319885e-003,0.000000e+000,0,,0,
1524550210.865,,0.000000e+000,5.499971e+001,-1.860697e-006,0.000000e+000,3,7.677860e-001,0.000000e+000,,,,,,,,,,,,,,32,1,4.000000e+000,2.639771e-003,0.000000e+000,0,,0,
1524550252.129,,0.000000e+000,5.499774e+001,-1.823333e-006,0.000000e+000,3,7.240095e-001,0.000000e+000,,,,,,,,,,,,,,32,1,4.000000e+000,6.580353e-003,0.000000e+000,0,,0,
1524550293.643,,0.000000e+000,5.499117e+001,-6.110095e-007,0.000000e+000,2,0.000000e+000,0.000000e+000,,,,,,,,,,,,,,32,1,4.000000e+000,3.952026e-003,0.000000e+000,0,,0,
1524550333.095,,0.000000e+000,5.499905e+001,-5.862743e-007,0.000000e+000,2,0.000000e+000,0.000000e+000,,,,,,,,,,,,,,32,1,4.000000e+000,3.948212e-003,0.000000e+000,0,,0,
1524550375.060,,0.000000e+000,5.500300e+001,-5.615068e-007,0.000000e+000,2,0.000000e+000,0.000000e+000,,,,,,,,,,,,,,32,1,4.000000e+000,1.710129e-002,0.000000e+000,0,,0,
1524550413.602,,0.000000e+000,5.500037e+001,-1.627937e-006,0.000000e+000,3,7.467573e-001,0.000000e+000,,,,,,,,,,,,,,32,1,4.000000e+000,9.201050e-003,0.000000e+000,0,,0,
1524550456.678,,0.000000e+000,5.500037e+001,-5.840800e-007,0.000000e+000,2,0.000000e+000,0.000000e+000,,,,,,,,,,,,,,32,1,4.000000e+000,3.959656e-003,0.000000e+000,0,,0,
1524550497.672,,0.000000e+000,5.499445e+001,-6.074278e-007,0.000000e+000,2,0.000000e+000,0.000000e+000,,,,,,,,,,,,,,32,1,4.000000e+000,7.881165e-003,0.000000e+000,0,,0,
1524550537.134,,0.000000e+000,5.499248e+001,-5.682506e-007,0.000000e+000,2,0.000000e+000,0.000000e+000,,,,,,,,,,,,,,32,1,4.000000e+000,6.580353e-003,0.000000e+000,0,,0,
1524550577.998,,0.000000e+000,5.499840e+001,-1.822283e-006,0.000000e+000,3,7.682568e-001,0.000000e+000,,,,,,,,,,,,,,32,1,4.000000e+000,1.578140e-002,0.000000e+000,0,,0,
1524550618.702,,0.000000e+000,5.499248e+001,-1.796735e-006,0.000000e+000,3,7.455488e-001,0.000000e+000,,,,,,,,,,,,,,32,1,4.000000e+000,6.580353e-003,0.000000e+000,0,,0,
1524550660.415,,0.000000e+000,5.500037e+001,-5.860722e-007,0.000000e+000,2,0.000000e+000,0.000000e+000,,,,,,,,,,,,,,32,1,4.000000e+000,1.184082e-002,0.000000e+000,0,,0,
1524550701.479,,0.000000e+000,5.500235e+001,-1.773983e-006,0.000000e+000,3,7.440011e-001,0.000000e+000,,,,,,,,,,,,,,32,1,4.000000e+000,1.052856e-002,0.000000e+000,0,,0,
1524550742.563,,0.000000e+000,5.500301e+001,-1.803518e-006,0.000000e+000,3,7.687427e-001,0.000000e+000,,,,,,,,,,,,,,32,1,4.000000e+000,1.319885e-003,0.000000e+000,0,,0,
1524550782.285,,0.000000e+000,5.499708e+001,-1.892780e-006,0.000000e+000,3,7.282231e-001,0.000000e+000,,,,,,,,,,,,,,32,1,4.000000e+000,0.000000e+000,0.000000e+000,0,,0,
1524550823.389,,0.000000e+000,5.499840e+001,-5.763322e-007,0.000000e+000,2,0.000000e+000,0.000000e+000,,,,,,,,,,,,,,32,1,4.000000e+000,2.628326e-003,0.000000e+000,0,,0,
1524550862.841,,0.000000e+000,5.499182e+001,-1.546533e-008,0.000000e+000,3,0.000000e+000,0.000000e+000,,,,,,,,,,,,,,32,1,4.000000e+000,1.314163e-002,0.000000e+000,0,,0,
1524550904.355,,0.000000e+000,5.499511e+001,-5.662349e-007,0.000000e+000,2,0.000000e+000,0.000000e+000,,,,,,,,,,,,,,32,1,4.000000e+000,3.940582e-003,0.000000e+000,0,,0,
1524550947.321,,0.000000e+000,5.500037e+001,-5.987653e-007,0.000000e+000,2,0.000000e+000,0.000000e+000,,,,,,,,,,,,,,32,1,4.000000e+000,1.319885e-003,0.000000e+000,0,,0,
1524550986.723,,0.000000e+000,5.499577e+001,-5.539699e-007,0.000000e+000,2,0.000000e+000,0.000000e+000,,,,,,,,,,,,,,32,1,4.000000e+000,7.888794e-003,0.000000e+000,0,,0,
1524551027.507,,0.000000e+000,5.499773e+001,-6.085240e-007,0.000000e+000,2,0.000000e+000,0.000000e+000,,,,,,,,,,,,,,32,1,4.000000e+000,1.308441e-003,0.000000e+000,0,,0,
1524551067.421,,0.000000e+000,5.499905e+001,-5.886391e-007,0.000000e+000,2,0.000000e+000,0.000000e+000,,,,,,,,,,,,,,32,1,4.000000e+000,1.319885e-003,0.000000e+000,0,,0,
1524551109.948,,0.000000e+000,5.499905e+001,-6.330215e-007,0.000000e+000,2,0.000000e+000,0.000000e+000,,,,,,,,,,,,,,32,1,4.000000e+000,3.948212e-003,0.000000e+000,0,,0,
1524551151.102,,0.000000e+000,5.499839e+001,-5.578603e-007,0.000000e+000,2,0.000000e+000,0.000000e+000,,,,,,,,,,,,,,32,1,4.000000e+000,0.000000e+000,0.000000e+000,0,,0,
1524551195.268,,0.000000e+000,5.500037e+001,-6.176872e-007,0.000000e+000,2,0.000000e+000,0.000000e+000,,,,,,,,,,,,,,32,1,4.000000e+000,1.319885e-003,0.000000e+000,0,,0,
1524551234.220,,0.000000e+000,5.499708e+001,-1.732444e-006,0.000000e+000,3,7.267752e-001,0.000000e+000,,,,,,,,,,,,,,32,1,4.000000e+000,1.578140e-002,0.000000e+000,0,,0,
1524551275.674,,0.000000e+000,5.499905e+001,-5.705099e-007,0.000000e+000,2,0.000000e+000,0.000000e+000,,,,,,,,,,,,,,32,1,4.000000e+000,1.319885e-003,0.000000e+000,0,,0,
1524551315.668,,0.000000e+000,5.499841e+001,-5.983052e-007,0.000000e+000,2,0.000000e+000,0.000000e+000,,,,,,,,,,,,,,32,1,4.000000e+000,1.052856e-002,0.000000e+000,0,,0,
1524551358.454,,0.000000e+000,5.499840e+001,-5.906016e-007,0.000000e+000,2,0.000000e+000,0.000000e+000,,,,,,,,,,,,,,32,1,4.000000e+000,2.630234e-002,0.000000e+000,0,,0,
1524551396.684,,0.000000e+000,5.499445e+001,-1.754331e-006,0.000000e+000,3,7.119031e-001,0.000000e+000,,,,,,,,,,,,,,32,1,4.000000e+000,1.052094e-002,0.000000e+000,0,,0,
1524551438.688,,0.000000e+000,5.499445e+001,-6.439636e-007,0.000000e+000,2,0.000000e+000,0.000000e+000,,,,,,,,,,,,,,32,1,4.000000e+000,7.881165e-003,0.000000e+000,0,,0,
1524551479.732,,0.000000e+000,5.499643e+001,-6.080615e-007,0.000000e+000,2,0.000000e+000,0.000000e+000,,,,,,,,,,,,,,32,1,4.000000e+000,1.312256e-003,0.000000e+000,0,,0,
1524551521.968,,0.000000e+000,5.499972e+001,-6.252228e-007,0.000000e+000,2,0.000000e+000,0.000000e+000,,,,,,,,,,,,,,32,1,4.000000e+000,5.268097e-003,0.000000e+000,0,,0,
1524551562.692,,0.000000e+000,5.499774e+001,-5.816984e-007,0.000000e+000,2,0.000000e+000,0.000000e+000,,,,,,,,,,,,,,32,1,4.000000e+000,6.580353e-003,0.000000e+000,0,,0,
1524551600.904,,0.000000e+000,5.499445e+001,-1.715483e-006,0.000000e+000,3,7.238709e-001,0.000000e+000,,,,,,,,,,,,,,32,1,4.000000e+000,5.260468e-003,0.000000e+000,0,,0,
1524551642.158,,0.000000e+000,5.499906e+001,-5.654496e-007,0.000000e+000,2,0.000000e+000,0.000000e+000,,,,,,,,,,,,,,32,1,4.000000e+000,6.580353e-003,0.000000e+000,0,,0,
1524551681.170,,0.000000e+000,5.500366e+001,-1.775602e-006,0.000000e+000,3,7.344604e-001,0.000000e+000,,,,,,,,,,,,,,32,1,4.000000e+000,2.620697e-003,0.000000e+000,0,,0,
1524551722.624,,0.000000e+000,5.500498e+001,-1.803952e-006,0.000000e+000,3,7.297936e-001,0.000000e+000,,,,,,,,,,,,,,32,1,4.000000e+000,5.260468e-003,0.000000e+000,0,,0,
1524551764.638,,0.000000e+000,5.499445e+001,-6.141134e-007,0.000000e+000,2,0.000000e+000,0.000000e+000,,,,,,,,,,,,,,32,1,4.000000e+000,7.881165e-003,0.000000e+000,0,,0,
1524551808.035,,0.000000e+000,5.499905e+001,-5.883326e-007,0.000000e+000,2,0.000000e+000,0.000000e+000,,,,,,,,,,,,,,32,1,4.000000e+000,1.319885e-003,0.000000e+000,0,,0,
1524551848.579,,0.000000e+000,5.499709e+001,-6.046773e-007,0.000000e+000,2,0.000000e+000,0.000000e+000,,,,,,,,,,,,,,32,1,4.000000e+000,7.888794e-003,0.000000e+000,0,,0,
1524551888.671,,0.000000e+000,5.500037e+001,-5.939830e-007,0.000000e+000,2,0.000000e+000,0.000000e+000,,,,,,,,,,,,,,32,1,4.000000e+000,1.184082e-002,0.000000e+000,0,,0,
1524551927.883,,0.000000e+000,5.499643e+001,-5.720936e-007,0.000000e+000,2,0.000000e+000,0.000000e+000,,,,,,,,,,,,,,32,1,4.000000e+000,1.184082e-002,0.000000e+000,0,,0,
1524551968.217,,0.000000e+000,5.500366e+001,-5.730064e-007,0.000000e+000,2,0.000000e+000,0.000000e+000,,,,,,,,,,,,,,32,1,4.000000e+000,7.900238e-003,0.000000e+000,0,,0,
1524552009.061,,0.000000e+000,5.499773e+001,-5.652287e-007,0.000000e+000,2,0.000000e+000,0.000000e+000,,,,,,,,,,,,,,32,1,4.000000e+000,1.308441e-003,0.000000e+000,0,,0,
1524552049.695,,0.000000e+000,5.500103e+001,-1.814580e-006,0.000000e+000,3,7.564029e-001,0.000000e+000,,,,,,,,,,,,,,32,1,4.000000e+000,2.639771e-003,0.000000e+000,0,,0,
1524552091.709,,0.000000e+000,5.500234e+001,-6.380167e-007,0.000000e+000,2,0.000000e+000,0.000000e+000,,,,,,,,,,,,,,32,1,4.000000e+000,7.900238e-003,0.000000e+000,0,,0,
1524552131.831,,0.000000e+000,5.499708e+001,-1.723606e-006,0.000000e+000,3,7.146930e-001,0.000000e+000,,,,,,,,,,,,,,32,1,4.000000e+000,2.620697e-003,0.000000e+000,0,,0,
1524552172.745,,0.000000e+000,5.499774e+001,-1.851083e-006,0.000000e+000,3,7.421498e-001,0.000000e+000,,,,,,,,,,,,,,32,1,4.000000e+000,3.940582e-003,0.000000e+000,0,,0,
1524552214.419,,0.000000e+000,5.500300e+001,-5.898168e-007,0.000000e+000,2,0.000000e+000,0.000000e+000,,,,,,,,,,,,,,32,1,4.000000e+000,6.580353e-003,0.000000e+000,0,,0,
1524552255.553,,0.000000e+000,5.500037e+001,-6.071016e-007,0.000000e+000,2,0.000000e+000,0.000000e+000,,,,,,,,,,,,,,32,1,4.000000e+000,1.319885e-003,0.000000e+000,0,,0,
1524552295.065,,0.000000e+000,5.499182e+001,-1.724686e-006,0.000000e+000,3,7.256087e-001,0.000000e+000,,,,,,,,,,,,,,32,1,4.000000e+000,5.260468e-003,0.000000e+000,0,,0,
1524552336.499,,0.000000e+000,5.499906e+001,-1.925813e-006,0.000000e+000,3,7.869087e-001,0.000000e+000,,,,,,,,,,,,,,32,1,4.000000e+000,6.580353e-003,0.000000e+000,0,,0,
1524552379.895,,0.000000e+000,5.499577e+001,-6.272389e-007,0.000000e+000,2,0.000000e+000,0.000000e+000,,,,,,,,,,,,,,32,1,4.000000e+000,1.578903e-002,0.000000e+000,0,,0,
1524552417.075,,0.000000e+000,5.499774e+001,1.247254e-006,0.000000e+000,3,9.352406e-002,0.000000e+000,,,,,,,,,,,,,,32,1,4.000000e+000,3.940582e-003,0.000000e+000,0,,0,
1524552460.451,,0.000000e+000,5.499906e+001,-5.881788e-007,0.000000e+000,2,0.000000e+000,0.000000e+000,,,,,,,,,,,,,,32,1,4.000000e+000,9.220123e-003,0.000000e+000,0,,0,
1524552503.557,,0.000000e+000,5.499774e+001,-6.249721e-007,0.000000e+000,2,0.000000e+000,0.000000e+000,,,,,,,,,,,,,,32,1,4.000000e+000,1.710129e-002,0.000000e+000,0,,0,
1524552544.802,,0.000000e+000,5.499774e+001,-6.327258e-007,0.000000e+000,2,0.000000e+000,0.000000e+000,,,,,,,,,,,,,,32,1,4.000000e+000,3.940582e-003,0.000000e+000,0,,0,
1524552586.176,,0.000000e+000,5.499577e+001,-1.831167e-006,0.000000e+000,3,7.612607e-001,0.000000e+000,,,,,,,,,,,,,,32,1,4.000000e+000,7.888794e-003,0.000000e+000,0,,0,
1524552628.100,,0.000000e+000,5.499708e+001,-5.683671e-007,0.000000e+000,2,0.000000e+000,0.000000e+000,,,,,,,,,,,,,,32,1,4.000000e+000,2.620697e-003,0.000000e+000,0,,0,
1524552667.342,,0.000000e+000,5.499314e+001,-5.602465e-007,0.000000e+000,2,0.000000e+000,0.000000e+000,,,,,,,,,,,,,,32,1,4.000000e+000,5.260468e-003,0.000000e+000,0,,0,
1524552708.066,,0.000000e+000,5.499380e+001,-6.402052e-007,0.000000e+000,2,0.000000e+000,0.000000e+000,,,,,,,,,,,,,,32,1,4.000000e+000,3.948212e-003,0.000000e+000,0,,0,
1524552748.820,,0.000000e+000,5.499840e+001,-5.862106e-007,0.000000e+000,2,0.000000e+000,0.000000e+000,,,,,,,,,,,,,,32,1,4.000000e+000,2.628326e-003,0.000000e+000,0,,0,
1524552788.032,,0.000000e+000,5.500301e+001,-5.832013e-007,0.000000e+000,2,0.000000e+000,0.000000e+000,,,,,,,,,,,,,,32,1,4.000000e+000,1.319885e-003,0.000000e+000,0,,0,
1524552827.314,,0.000000e+000,5.499445e+001,-5.405885e-007,0.000000e+000,2,0.000000e+000,0.000000e+000,,,,,,,,,,,,,,32,1,4.000000e+000,5.260468e-003,0.000000e+000,0,,0,
1524552868.178,,0.000000e+000,5.499840e+001,-4.894921e-007,0.000000e+000,2,0.000000e+000,0.000000e+000,,,,,,,,,,,,,,32,1,4.000000e+000,2.628326e-003,0.000000e+000,0,,0,
1524552907.270,,0.000000e+000,5.499313e+001,-1.650798e-006,0.000000e+000,3,7.289442e-001,0.000000e+000,,,,,,,,,,,,,,32,1,4.000000e+000,2.628326e-003,0.000000e+000,0,,0,
1524552951.146,,0.000000e+000,5.499248e+001,-6.361348e-007,0.000000e+000,2,0.000000e+000,0.000000e+000,,,,,,,,,,,,,,32,1,4.000000e+000,3.940582e-003,0.000000e+000,0,,0,
1524552991.870,,0.000000e+000,5.499643e+001,-6.016052e-007,0.000000e+000,2,0.000000e+000,0.000000e+000,,,,,,,,,,,,,,32,1,4.000000e+000,1.312256e-003,0.000000e+000,0,,0,
1524553031.952,,0.000000e+000,5.499511e+001,-1.638235e-006,0.000000e+000,3,7.238309e-001,0.000000e+000,,,,,,,,,,,,,,32,1,4.000000e+000,6.568909e-003,0.000000e+000,0,,0,
1524553070.714,,0.000000e+000,5.499182e+001,-1.569267e-006,0.000000e+000,3,6.945380e-001,0.000000e+000,,,,,,,,,,,,,,32,1,4.000000e+000,1.052094e-002,0.000000e+000,0,,0,
1524553111.376,,0.000000e+000,5.499380e+001,-1.565815e-006,0.000000e+000,3,6.981386e-001,0.000000e+000,,,,,,,,,,,,,,32,1,4.000000e+000,1.182938e-002,0.000000e+000,0,,0,
1524553151.598,,0.000000e+000,5.499445e+001,-1.680818e-006,0.000000e+000,3,7.125676e-001,0.000000e+000,,,,,,,,,,,,,,32,1,4.000000e+000,1.578903e-002,0.000000e+000,0,,0,
1524553191.560,,0.000000e+000,5.500103e+001,-1.681648e-006,0.000000e+000,3,6.988525e-001,0.000000e+000,,,,,,,,,,,,,,32,1,4.000000e+000,5.279541e-003,0.000000e+000,0,,0,
1524553232.215,,0.000000e+000,5.500103e+001,-5.174625e-007,0.000000e+000,2,0.000000e+000,0.000000e+000,,,,,,,,,,,,,,32,1,4.000000e+000,7.888794e-003,0.000000e+000,0,,0,
1524553275.181,,0.000000e+000,5.499511e+001,-5.460890e-007,0.000000e+000,2,0.000000e+000,0.000000e+000,,,,,,,,,,,,,,32,1,4.000000e+000,1.184082e-002,0.000000e+000,0,,0,
1524553316.765,,0.000000e+000,5.499971e+001,-1.609018e-006,0.000000e+000,3,7.268615e-001,0.000000e+000,,,,,,,,,,,,,,32,1,4.000000e+000,1.052094e-002,0.000000e+000,0,,0,
1524553359.441,,0.000000e+000,5.499051e+001,-6.047737e-007,0.000000e+000,2,0.000000e+000,0.000000e+000,,,,,,,,,,,,,,32,1,4.000000e+000,2.632141e-003,0.000000e+000,0,,0,
1524553402.197,,0.000000e+000,5.499643e+001,-5.534017e-007,0.000000e+000,2,0.000000e+000,0.000000e+000,,,,,,,,,,,,,,32,1,4.000000e+000,1.312256e-003,0.000000e+000,0,,0,
1524553443.041,,0.000000e+000,5.500432e+001,-5.970437e-007,0.000000e+000,2,0.000000e+000,0.000000e+000,,,,,,,,,,,,,,32,1,4.000000e+000,1.710129e-002,0.000000e+000,0,,0,
1524553484.725,,0.000000e+000,5.499708e+001,-1.708457e-006,0.000000e+000,3,7.752540e-001,0.000000e+000,,,,,,,,,,,,,,32,1,4.000000e+000,0.000000e+000,0.000000e+000,0,,0,
1524553525.559,,0.000000e+000,5.499708e+001,-5.608599e-007,0.000000e+000,2,0.000000e+000,0.000000e+000,,,,,,,,,,,,,,32,1,4.000000e+000,0.000000e+000,0.000000e+000,0,,0,
1524553566.343,,0.000000e+000,5.499905e+001,-5.874705e-007,0.000000e+000,2,0.000000e+000,0.000000e+000,,,,,,,,,,,,,,32,1,4.000000e+000,1.319885e-003,0.000000e+000,0,,0,
1524553603.803,,0.000000e+000,5.499577e+001,-1.699125e-006,0.000000e+000,3,7.543048e-001,0.000000e+000,,,,,,,,,,,,,,32,1,4.000000e+000,7.888794e-003,0.000000e+000,0,,0,
1524553646.869,,0.000000e+000,5.499708e+001,-6.034578e-007,0.000000e+000,2,0.000000e+000,0.000000e+000,,,,,,,,,,,,,,32,1,4.000000e+000,1.578140e-002,0.000000e+000,0,,0,
1524553688.523,,0.000000e+000,5.500497e+001,-5.727571e-007,0.000000e+000,2,0.000000e+000,0.000000e+000,,,,,,,,,,,,,,32,1,4.000000e+000,1.578903e-002,0.000000e+000,0,,0,
1524553730.739,,0.000000e+000,5.499117e+001,-5.471362e-007,0.000000e+000,2,0.000000e+000,0.000000e+000,,,,,,,,,,,,,,32,1,4.000000e+000,1.183319e-002,0.000000e+000,0,,0,
1524553770.701,,0.000000e+000,5.499248e+001,-5.817907e-007,0.000000e+000,2,0.000000e+000,0.000000e+000,,,,,,,,,,,,,,32,1,4.000000e+000,6.580353e-003,0.000000e+000,0,,0,
1524553812.025,,0.000000e+000,5.500301e+001,-5.548558e-007,0.000000e+000,2,0.000000e+000,0.000000e+000,,,,,,,,,,,,,,32,1,4.000000e+000,1.319885e-003,0.000000e+000,0,,0,
1524553855.881,,0.000000e+000,5.499773e+001,-6.215724e-007,0.000000e+000,2,0.000000e+000,0.000000e+000,,,,,,,,,,,,,,32,1,4.000000e+000,1.308441e-003,0.000000e+000,0,,0,
1524553896.045,,0.000000e+000,5.500497e+001,-5.952622e-007,0.000000e+000,2,0.000000e+000,0.000000e+000,,,,,,,,,,,,,,32,1,4.000000e+000,1.052856e-002,0.000000e+000,0,,0,
1524553937.020,,0.000000e+000,5.499577e+001,-5.671242e-007,0.000000e+000,2,0.000000e+000,0.000000e+000,,,,,,,,,,,,,,32,1,4.000000e+000,5.249023e-003,0.000000e+000,0,,0,
1524553980.416,,0.000000e+000,5.499840e+001,-5.764114e-007,0.000000e+000,2,0.000000e+000,0.000000e+000,,,,,,,,,,,,,,32,1,4.000000e+000,7.900238e-003,0.000000e+000,0,,0,
1524554018.798,,0.000000e+000,5.500366e+001,-1.619257e-006,0.000000e+000,3,7.193637e-001,0.000000e+000,,,,,,,,,,,,,,32,1,4.000000e+000,7.900238e-003,0.000000e+000,0,,0,
1524554060.202,,0.000000e+000,5.499840e+001,-1.791648e-006,0.000000e+000,3,7.457707e-001,0.000000e+000,,,,,,,,,,,,,,32,1,4.000000e+000,1.314926e-002,0.000000e+000,0,,0,
1524554101.176,,0.000000e+000,5.500169e+001,-1.770981e-006,0.000000e+000,3,7.390815e-001,0.000000e+000,,,,,,,,,,,,,,32,1,4.000000e+000,1.319885e-003,0.000000e+000,0,,0,
1524554140.238,,0.000000e+000,5.500103e+001,-1.739443e-006,0.000000e+000,3,7.262223e-001,0.000000e+000,,,,,,,,,,,,,,32,1,4.000000e+000,2.639771e-003,0.000000e+000,0,,0,
1524554184.104,,0.000000e+000,5.499972e+001,-5.447001e-007,0.000000e+000,2,0.000000e+000,0.000000e+000,,,,,,,,,,,,,,32,1,4.000000e+000,5.268097e-003,0.000000e+000,0,,0,
1524554227.040,,0.000000e+000,5.500103e+001,-5.527599e-007,0.000000e+000,2,0.000000e+000,0.000000e+000,,,,,,,,,,,,,,32,1,4.000000e+000,2.639771e-003,0.000000e+000,0,,0,
1524554267.734,,0.000000e+000,5.500365e+001,-6.113884e-007,0.000000e+000,2,0.000000e+000,0.000000e+000,,,,,,,,,,,,,,32,1,4.000000e+000,1.052856e-002,0.000000e+000,0,,0,
1524554306.846,,0.000000e+000,5.499905e+001,-5.724318e-007,0.000000e+000,2,0.000000e+000,0.000000e+000,,,,,,,,,,,,,,32,1,4.000000e+000,1.182938e-002,0.000000e+000,0,,0,
1524554348.450,,0.000000e+000,5.500629e+001,-1.762223e-006,0.000000e+000,3,7.431698e-001,0.000000e+000,,,,,,,,,,,,,,32,1,4.000000e+000,0.000000e+000,0.000000e+000,0,,0,
1524554391.336,,0.000000e+000,5.499708e+001,-6.063419e-007,0.000000e+000,2,0.000000e+000,0.000000e+000,,,,,,,,,,,,,,32,1,4.000000e+000,2.620697e-003,0.000000e+000,0,,0,
1524554432.520,,0.000000e+000,5.499380e+001,-5.781381e-007,0.000000e+000,2,0.000000e+000,0.000000e+000,,,,,,,,,,,,,,32,1,4.000000e+000,1.308441e-003,0.000000e+000,0,,0,
1524554472.422,,0.000000e+000,5.500365e+001,-1.714591e-006,0.000000e+000,3,7.182159e-001,0.000000e+000,,,,,,,,,,,,,,32,1,4.000000e+000,1.052856e-002,0.000000e+000,0,,0,
1524554515.968,,0.000000e+000,5.500103e+001,-5.976659e-007,0.000000e+000,2,0.000000e+000,0.000000e+000,,,,,,,,,,,,,,32,1,4.000000e+000,5.279541e-003,0.000000e+000,0,,0,
1524554557.082,,0.000000e+000,5.499708e+001,1.550665e-006,0.000000e+000,3,3.813955e-001,0.000000e+000,,,,,,,,,,,,,,32,1,4.000000e+000,2.620697e-003,0.000000e+000,0,,0,
1524554600.178,,0.000000e+000,5.499709e+001,-5.960208e-007,0.000000e+000,2,0.000000e+000,0.000000e+000,,,,,,,,,,,,,,32,1,4.000000e+000,1.052856e-002,0.000000e+000,0,,0,
1524554640.872,,0.000000e+000,5.499117e+001,-5.723644e-007,0.000000e+000,2,0.000000e+000,0.000000e+000,,,,,,,,,,,,,,32,1,4.000000e+000,6.568909e-003,0.000000e+000,0,,0,
1524554681.697,,0.000000e+000,5.500103e+001,-5.141666e-007,0.000000e+000,2,0.000000e+000,0.000000e+000,,,,,,,,,,,,,,32,1,4.000000e+000,5.279541e-003,0.000000e+000,0,,0,
1524554722.141,,0.000000e+000,5.499971e+001,-1.794364e-006,0.000000e+000,3,7.446280e-001,0.000000e+000,,,,,,,,,,,,,,32,1,4.000000e+000,0.000000e+000,0.000000e+000,0,,0,
1524554759.951,,0.000000e+000,5.499313e+001,-1.732515e-006,0.000000e+000,3,7.214730e-001,0.000000e+000,,,,,,,,,,,,,,32,1,4.000000e+000,2.628326e-003,0.000000e+000,0,,0,
1524554803.367,,0.000000e+000,5.499773e+001,-5.608767e-007,0.000000e+000,2,0.000000e+000,0.000000e+000,,,,,,,,,,,,,,32,1,4.000000e+000,1.308441e-003,0.000000e+000,0,,0,
1524554844.181,,0.000000e+000,5.499117e+001,-6.035914e-007,0.000000e+000,2,0.000000e+000,0.000000e+000,,,,,,,,,,,,,,32,1,4.000000e+000,1.312256e-003,0.000000e+000,0,,0,
1524554885.435,,0.000000e+000,5.499511e+001,-1.735317e-006,0.000000e+000,3,7.633131e-001,0.000000e+000,,,,,,,,,,,,,,32,1,4.000000e+000,3.940582e-003,0.000000e+000,0,,0,
1524554928.531,,0.000000e+000,5.500301e+001,-6.228841e-007,0.000000e+000,2,0.000000e+000,0.000000e+000,,,,,,,,,,,,,,32,1,4.000000e+000,1.319885e-003,0.000000e+000,0,,0,
1524554970.725,,0.000000e+000,5.500037e+001,-1.807689e-006,0.000000e+000,3,7.355391e-001,0.000000e+000,,,,,,,,,,,,,,32,1,4.000000e+000,9.201050e-003,0.000000e+000,0,,0,
1524555012.279,,0.000000e+000,5.499905e+001,-5.854584e-007,0.000000e+000,2,0.000000e+000,0.000000e+000,,,,,,,,,,,,,,32,1,4.000000e+000,1.319885e-003,0.000000e+000,0,,0,
1524555053.183,,0.000000e+000,5.499380e+001,-5.531367e-007,0.000000e+000,2,0.000000e+000,0.000000e+000,,,,,,,,,,,,,,32,1,4.000000e+000,1.308441e-003,0.000000e+000,0,,0,
1524555093.887,,0.000000e+000,5.499643e+001,-1.798953e-006,0.000000e+000,3,7.330211e-001,0.000000e+000,,,,,,,,,,,,,,32,1,4.000000e+000,6.568909e-003,0.000000e+000,0,,0,
1524555136.963,,0.000000e+000,5.499773e+001,-5.680654e-007,0.000000e+000,2,0.000000e+000,0.000000e+000,,,,,,,,,,,,,,32,1,4.000000e+000,1.308441e-003,0.000000e+000,0,,0,
1524555177.627,,0.000000e+000,5.500037e+001,-1.776187e-006,0.000000e+000,3,7.521175e-001,0.000000e+000,,,,,,,,,,,,,,32,1,4.000000e+000,1.319885e-003,0.000000e+000,0,,0,
1524555216.799,,0.000000e+000,5.499314e+001,-1.680005e-006,0.000000e+000,3,7.248305e-001,0.000000e+000,,,,,,,,,,,,,,32,1,4.000000e+000,0.000000e+000,0.000000e+000,0,,0,
1524555260.295,,0.000000e+000,5.499182e+001,-5.316354e-007,0.000000e+000,2,0.000000e+000,0.000000e+000,,,,,,,,,,,,,,32,1,4.000000e+000,0.000000e+000,0.000000e+000,0,,0,
1524555300.569,,0.000000e+000,5.499709e+001,-5.834374e-007,0.000000e+000,2,0.000000e+000,0.000000e+000,,,,,,,,,,,,,,32,1,4.000000e+000,7.888794e-003,0.000000e+000,0,,0,
1524555344.755,,0.000000e+000,5.499972e+001,-5.956069e-007,0.000000e+000,2,0.000000e+000,0.000000e+000,,,,,,,,,,,,,,32,1,4.000000e+000,1.314926e-002,0.000000e+000,0,,0,
1524555384.428,,0.000000e+000,5.499774e+001,-5.542198e-007,0.000000e+000,2,0.000000e+000,0.000000e+000,,,,,,,,,,,,,,32,1,4.000000e+000,3.940582e-003,0.000000e+000,0,,0,
1524555424.050,,0.000000e+000,5.499577e+001,-1.586915e-006,0.000000e+000,3,7.113796e-001,0.000000e+000,,,,,,,,,,,,,,32,1,4.000000e+000,2.632141e-003,0.000000e+000,0,,0,
1524555465.514,,0.000000e+000,5.500103e+001,-1.733473e-006,0.000000e+000,3,7.393202e-001,0.000000e+000,,,,,,,,,,,,,,32,1,4.000000e+000,5.279541e-003,0.000000e+000,0,,0,
1524555508.270,,0.000000e+000,5.499972e+001,-5.860869e-007,0.000000e+000,2,0.000000e+000,0.000000e+000,,,,,,,,,,,,,,32,1,4.000000e+000,5.268097e-003,0.000000e+000,0,,0,
1524555548.644,,0.000000e+000,5.499709e+001,-5.530966e-007,0.000000e+000,2,0.000000e+000,0.000000e+000,,,,,,,,,,,,,,32,1,4.000000e+000,1.052856e-002,0.000000e+000,0,,0,
1524555588.196,,0.000000e+000,5.499972e+001,-1.695936e-006,0.000000e+000,3,7.241505e-001,0.000000e+000,,,,,,,,,,,,,,32,1,4.000000e+000,1.314926e-002,0.000000e+000,0,,0,
1524555629.530,,0.000000e+000,5.499643e+001,-5.962635e-007,0.000000e+000,2,0.000000e+000,0.000000e+000,,,,,,,,,,,,,,32,1,4.000000e+000,9.208679e-003,0.000000e+000,0,,0,
1524555672.966,,0.000000e+000,5.499840e+001,-5.971704e-007,0.000000e+000,2,0.000000e+000,0.000000e+000,,,,,,,,,,,,,,32,1,4.000000e+000,2.628326e-003,0.000000e+000,0,,0,
1524555716.892,,0.000000e+000,5.499445e+001,-5.893194e-007,0.000000e+000,2,0.000000e+000,0.000000e+000,,,,,,,,,,,,,,32,1,4.000000e+000,1.052094e-002,0.000000e+000,0,,0,
1524555757.496,,0.000000e+000,5.500497e+001,-5.508870e-007,0.000000e+000,2,0.000000e+000,0.000000e+000,,,,,,,,,,,,,,32,1,4.000000e+000,1.316071e-002,0.000000e+000,0,,0,
1524555797.478,,0.000000e+000,5.500037e+001,-5.898747e-007,0.000000e+000,2,0.000000e+000,0.000000e+000,,,,,,,,,,,,,,32,1,4.000000e+000,6.587982e-003,0.000000e+000,0,,0,
1524555838.011,,0.000000e+000,5.499708e+001,-5.527037e-007,0.000000e+000,2,0.000000e+000,0.000000e+000,,,,,,,,,,,,,,32,1,4.000000e+000,5.260468e-003,0.000000e+000,0,,0,
1524555878.695,,0.000000e+000,5.499183e+001,-5.894000e-007,0.000000e+000,2,0.000000e+000,0.000000e+000,,,,,,,,,,,,,,32,1,4.000000e+000,2.632141e-003,0.000000e+000,0,,0,
1524555919.769,,0.000000e+000,5.499512e+001,-5.884273e-007,0.000000e+000,2,0.000000e+000,0.000000e+000,,,,,,,,,,,,,,32,1,4.000000e+000,1.446915e-002,0.000000e+000,0,,0,
1524555962.065,,0.000000e+000,5.499972e+001,-5.511567e-007,0.000000e+000,2,0.000000e+000,0.000000e+000,,,,,,,,,,,,,,32,1,4.000000e+000,5.268097e-003,0.000000e+000,0,,0,
1524556002.839,,0.000000e+000,5.499708e+001,-5.470985e-007,0.000000e+000,2,0.000000e+000,0.000000e+000,,,,,,,,,,,,,,32,1,4.000000e+000,2.620697e-003,0.000000e+000,0,,0,
1524556043.553,,0.000000e+000,5.499971e+001,-1.848686e-006,0.000000e+000,3,7.287089e-001,0.000000e+000,,,,,,,,,,,,,,32,1,4.000000e+000,1.052094e-002,0.000000e+000,0,,0,
1524556082.756,,0.000000e+000,5.500103e+001,-1.729048e-006,0.000000e+000,3,7.450677e-001,0.000000e+000,,,,,,,,,,,,,,32,1,4.000000e+000,2.639771e-003,0.000000e+000,0,,0,
1524556125.882,,0.000000e+000,5.500629e+001,-5.997932e-007,0.000000e+000,2,0.000000e+000,0.000000e+000,,,,,,,,,,,,,,32,1,4.000000e+000,7.888794e-003,0.000000e+000,0,,0,
1524556167.036,,0.000000e+000,5.500695e+001,-1.868359e-006,0.000000e+000,3,7.037137e-001,0.000000e+000,,,,,,,,,,,,,,32,1,4.000000e+000,1.319885e-003,0.000000e+000,0,,0,
1524556209.322,,0.000000e+000,5.500169e+001,-5.833134e-007,0.000000e+000,2,0.000000e+000,0.000000e+000,,,,,,,,,,,,,,32,1,4.000000e+000,3.959656e-003,0.000000e+000,0,,0,
1524556250.006,,0.000000e+000,5.500301e+001,-5.285612e-007,0.000000e+000,2,0.000000e+000,0.000000e+000,,,,,,,,,,,,,,32,1,4.000000e+000,1.319885e-003,0.000000e+000,0,,0,
1524556291.560,,0.000000e+000,5.499643e+001,-1.778893e-006,0.000000e+000,3,6.929615e-001,0.000000e+000,,,,,,,,,,,,,,32,1,4.000000e+000,1.312256e-003,0.000000e+000,0,,0,
1524556333.364,,0.000000e+000,5.499840e+001,-5.637472e-007,0.000000e+000,2,0.000000e+000,0.000000e+000,,,,,,,,,,,,,,32,1,4.000000e+000,5.260468e-003,0.000000e+000,0,,0,
1524556374.560,,0.000000e+000,5.500103e+001,-5.463298e-007,0.000000e+000,2,0.000000e+000,0.000000e+000,,,,,,,,,,,,,,32,1,4.000000e+000,7.888794e-003,0.000000e+000,0,,0,
1524556415.194,,0.000000e+000,5.500367e+001,-1.735159e-006,0.000000e+000,3,7.566447e-001,0.000000e+000,,,,,,,,,,,,,,32,1,4.000000e+000,0.000000e+000,0.000000e+000,0,,0,
1524556455.178,,0.000000e+000,5.499906e+001,-1.730131e-006,0.000000e+000,3,7.653531e-001,0.000000e+000,,,,,,,,,,,,,,32,1,4.000000e+000,6.580353e-003,0.000000e+000,0,,0,
1524556495.992,,0.000000e+000,5.500103e+001,-1.778289e-006,0.000000e+000,3,7.119897e-001,0.000000e+000,,,,,,,,,,,,,,32,1,4.000000e+000,1.316071e-002,0.000000e+000,0,,0,
1524556537.336,,0.000000e+000,5.499445e+001,-5.859675e-007,0.000000e+000,2,0.000000e+000,0.000000e+000,,,,,,,,,,,,,,32,1,4.000000e+000,2.628326e-003,0.000000e+000,0,,0,
1524556578.270,,0.000000e+000,5.499708e+001,-5.497427e-007,0.000000e+000,2,0.000000e+000,0.000000e+000,,,,,,,,,,,,,,32,1,4.000000e+000,2.620697e-003,0.000000e+000,0,,0,
1524556621.666,,0.000000e+000,5.500037e+001,-5.819650e-007,0.000000e+000,2,0.000000e+000,0.000000e+000,,,,,,,,,,,,,,32,1,4.000000e+000,1.446915e-002,0.000000e+000,0,,0,
1524556663.100,,0.000000e+000,5.500037e+001,-5.343780e-007,0.000000e+000,2,0.000000e+000,0.000000e+000,,,,,,,,,,,,,,32,1,4.000000e+000,6.587982e-003,0.000000e+000,0,,0,
1524556705.566,,0.000000e+000,5.500300e+001,-5.775685e-007,0.000000e+000,2,0.000000e+000,0.000000e+000,,,,,,,,,,,,,,32,1,4.000000e+000,1.183701e-002,0.000000e+000,0,,0,
1524556745.608,,0.000000e+000,5.500037e+001,-5.887328e-007,0.000000e+000,2,0.000000e+000,0.000000e+000,,,,,,,,,,,,,,32,1,4.000000e+000,1.184082e-002,0.000000e+000,0,,0,
1524556786.233,,0.000000e+000,5.500300e+001,-5.776163e-007,0.000000e+000,2,0.000000e+000,0.000000e+000,,,,,,,,,,,,,,32,1,4.000000e+000,3.940582e-003,0.000000e+000,0,,0,
1524556826.867,,0.000000e+000,5.500037e+001,-1.649211e-006,0.000000e+000,3,7.233458e-001,0.000000e+000,,,,,,,,,,,,,,32,1,4.000000e+000,6.587982e-003,0.000000e+000,0,,0,
1524556870.283,,0.000000e+000,5.499445e+001,-5.487435e-007,0.000000e+000,2,0.000000e+000,0.000000e+000,,,,,,,,,,,,,,32,1,4.000000e+000,2.628326e-003,0.000000e+000,0,,0,
1524556912.217,,0.000000e+000,5.499708e+001,-5.539812e-007,0.000000e+000,2,0.000000e+000,0.000000e+000,,,,,,,,,,,,,,32,1,4.000000e+000,2.620697e-003,0.000000e+000,0,,0,
1524556951.229,,0.000000e+000,5.499248e+001,-1.803080e-006,0.000000e+000,3,7.589043e-001,0.000000e+000,,,,,,,,,,,,,,32,1,4.000000e+000,1.182938e-002,0.000000e+000,0,,0,
1524556992.503,,0.000000e+000,5.500235e+001,-1.800473e-006,0.000000e+000,3,7.315403e-001,0.000000e+000,,,,,,,,,,,,,,32,1,4.000000e+000,2.639771e-003,0.000000e+000,0,,0,
1524557034.899,,0.000000e+000,5.499971e+001,-5.342299e-007,0.000000e+000,2,0.000000e+000,0.000000e+000,,,,,,,,,,,,,,32,1,4.000000e+000,2.639771e-003,0.000000e+000,0,,0,
1524557074.783,,0.000000e+000,5.499905e+001,-1.711328e-006,0.000000e+000,3,7.093295e-001,0.000000e+000,,,,,,,,,,,,,,32,1,4.000000e+000,3.948212e-003,0.000000e+000,0,,0,
1524557116.047,,0.000000e+000,5.499840e+001,-5.036118e-007,0.000000e+000,2,0.000000e+000,0.000000e+000,,,,,,,,,,,,,,32,1,4.000000e+000,5.260468e-003,0.000000e+000,0,,0,
1524557158.953,,0.000000e+000,5.499511e+001,-6.195772e-007,0.000000e+000,2,0.000000e+000,0.000000e+000,,,,,,,,,,,,,,32,1,4.000000e+000,6.568909e-003,0.000000e+000,0,,0,
1524557201.027,,0.000000e+000,5.500366e+001,-1.859414e-006,0.000000e+000,3,7.425095e-001,0.000000e+000,,,,,,,,,,,,,,32,1,4.000000e+000,2.620697e-003,0.000000e+000,0,,0,
1524557242.563,,0.000000e+000,5.499313e+001,-5.816862e-007,0.000000e+000,2,0.000000e+000,0.000000e+000,,,,,,,,,,,,,,32,1,4.000000e+000,1.314926e-002,0.000000e+000,0,,0,
1524557286.049,,0.000000e+000,5.499183e+001,-6.075664e-007,0.000000e+000,2,0.000000e+000,0.000000e+000,,,,,,,,,,,,,,32,1,4.000000e+000,7.888794e-003,0.000000e+000,0,,0,
1524557326.603,,0.000000e+000,5.499577e+001,-5.908971e-007,0.000000e+000,2,0.000000e+000,0.000000e+000,,,,,,,,,,,,,,32,1,4.000000e+000,2.632141e-003,0.000000e+000,0,,0,
1524557367.847,,0.000000e+000,5.500103e+001,-5.762367e-007,0.000000e+000,2,0.000000e+000,0.000000e+000,,,,,,,,,,,,,,32,1,4.000000e+000,7.888794e-003,0.000000e+000,0,,0,
1524557408.401,,0.000000e+000,5.499182e+001,-1.786793e-006,0.000000e+000,3,7.387242e-001,0.000000e+000,,,,,,,,,,,,,,32,1,4.000000e+000,1.578140e-002,0.000000e+000,0,,0,
1524557448.735,,0.000000e+000,5.499708e+001,-5.497793e-007,0.000000e+000,2,0.000000e+000,0.000000e+000,,,,,,,,,,,,,,32,1,4.000000e+000,5.260468e-003,0.000000e+000,0,,0,
1524557490.130,,0.000000e+000,5.499972e+001,-1.717711e-006,0.000000e+000,3,7.336124e-001,0.000000e+000,,,,,,,,,,,,,,32,1,4.000000e+000,5.268097e-003,0.000000e+000,0,,0,
1524557529.732,,0.000000e+000,5.499971e+001,1.107874e-006,0.000000e+000,3,0.000000e+000,0.000000e+000,,,,,,,,,,,,,,32,1,4.000000e+000,2.639771e-003,0.000000e+000,0,,0,
1524557572.648,,0.000000e+000,5.499313e+001,-5.275025e-007,0.000000e+000,2,0.000000e+000,0.000000e+000,,,,,,,,,,,,,,32,1,4.000000e+000,2.628326e-003,0.000000e+000,0,,0,
1524557613.682,,0.000000e+000,5.499445e+001,-1.779127e-006,0.000000e+000,3,7.557675e-001,0.000000e+000,,,,,,,,,,,,,,32,1,4.000000e+000,1.052094e-002,0.000000e+000,0,,0,