File: Experimental Raw Data/TC04-12-01K TRMac VRMde/Ndat/TC04-12-01K_TRMac_57K_0.16Kmin_VRMde_55K.dc.dat
[Header]
TITLE,MPMS DC Measurement
BYAPP,MPMS Measurement,2.1,Summary
FILEOPENTIME, 1524587089.145000 4/24/2018, 10:24:49 AM

INFO, APPNAME, MPMS MultiVu Application, Revision 1.61,  Build 082

INFO, NAME, TC04-12-01K
INFO, WEIGHT, 1.000
INFO, AREA, 1.000
INFO, LENGTH, 1.000
INFO, SHAPE, 0
INFO, COMMENT,
INFO, SEQUENCE FILE: TRMac_57K_0.16Kmin_VRMde_55K.seq


INFO, BACKGROUND DATA FILE:, None


STARTUPAXIS,X,4,LINEAR,AUTO,0.000000,0.000000
STARTUPAXIS,Y1,5,LINEAR,AUTO,0.000000,0.000000


STARTUPGROUP,Longitudinal
FIELDGROUP,Longitudinal,1,2,3,4,5,6,7,8,9,15,16,17,18,27,28
FIELDGROUP,Transverse,1,2,3,4,10,11,12,13,14,19,20,21,22,27,28

PLOT_APPEARANCE,ALL,HORZ_GRID_ON,VERT_GRID_ON,MARKERS_AND_LINES

[Data]
Time,Comment,Field (Oe),Temperature (K),Long Moment (emu),Long Scan Std Dev,Long Algorithm,Long Reg Fit,Long Percent Error (%),Trans Moment (emu),Trans Scan Std Dev,Trans Algorithm,Trans Reg Fit,Trans Percent Error (%),Long Moment [w/o ABS] (emu),Long Scan Std Dev [w/o ABS],Long Reg Fit [w/o ABS],Long Percent Error [w/o ABS] (%),Trans Moment [w/o ABS] (emu),Trans Scan Std Dev [w/o ABS],Trans Reg Fit [w/o ABS],Trans Percent Error [w/o ABS] (%),Points per Scan,Scans per Measurement,Scan Length (cm),Delta Temp (K),Rot Position (deg),Error,EC Comp. Running,Using ABS,
1524587089.145,,0.000000e+000,5.499314e+001,8.379825e-006,0.000000e+000,3,8.035753e-001,0.000000e+000,,,,,,,,,,,,,,32,1,4.000000e+000,0.000000e+000,0.000000e+000,0,,0,
1524587126.755,,0.000000e+000,5.498524e+001,6.240672e-006,0.000000e+000,3,7.821513e-001,0.000000e+000,,,,,,,,,,,,,,32,1,4.000000e+000,2.632141e-003,0.000000e+000,0,,0,
1524587164.815,,0.000000e+000,5.499577e+001,5.238277e-006,0.000000e+000,3,7.699425e-001,0.000000e+000,,,,,,,,,,,,,,32,1,4.000000e+000,2.632141e-003,0.000000e+000,0,,0,
1524587202.745,,0.000000e+000,5.499445e+001,4.640403e-006,0.000000e+000,3,7.745563e-001,0.000000e+000,,,,,,,,,,,,,,32,1,4.000000e+000,2.628326e-003,0.000000e+000,0,,0,
1524587240.355,,0.000000e+000,5.499445e+001,4.215206e-006,0.000000e+000,3,7.545292e-001,0.000000e+000,,,,,,,,,,,,,,32,1,4.000000e+000,2.628326e-003,0.000000e+000,0,,0,
1524587278.385,,0.000000e+000,5.499577e+001,3.706707e-006,0.000000e+000,3,7.697578e-001,0.000000e+000,,,,,,,,,,,,,,32,1,4.000000e+000,1.052094e-002,0.000000e+000,0,,0,
1524587316.065,,0.000000e+000,5.500103e+001,3.502814e-006,0.000000e+000,3,7.336198e-001,0.000000e+000,,,,,,,,,,,,,,32,1,4.000000e+000,1.316071e-002,0.000000e+000,0,,0,
1524587354.065,,0.000000e+000,5.499840e+001,3.165756e-006,0.000000e+000,3,7.357048e-001,0.000000e+000,,,,,,,,,,,,,,32,1,4.000000e+000,5.260468e-003,0.000000e+000,0,,0,
1524587391.765,,0.000000e+000,5.499774e+001,2.949098e-006,0.000000e+000,3,6.993256e-001,0.000000e+000,,,,,,,,,,,,,,32,1,4.000000e+000,3.940582e-003,0.000000e+000,0,,0,
1524587429.735,,0.000000e+000,5.499577e+001,2.740285e-006,0.000000e+000,3,7.133287e-001,0.000000e+000,,,,,,,,,,,,,,32,1,4.000000e+000,2.632141e-003,0.000000e+000,0,,0,
1524587467.396,,0.000000e+000,5.499511e+001,2.581427e-006,0.000000e+000,3,6.671460e-001,0.000000e+000,,,,,,,,,,,,,,32,1,4.000000e+000,1.319885e-003,0.000000e+000,0,,0,
1524587505.186,,0.000000e+000,5.499773e+001,2.427189e-006,0.000000e+000,3,6.847866e-001,0.000000e+000,,,,,,,,,,,,,,32,1,4.000000e+000,1.308441e-003,0.000000e+000,0,,0,
1524587542.506,,0.000000e+000,5.500169e+001,2.278133e-006,0.000000e+000,3,6.304767e-001,0.000000e+000,,,,,,,,,,,,,,32,1,4.000000e+000,1.319885e-003,0.000000e+000,0,,0,
1524587580.466,,0.000000e+000,5.499840e+001,2.208842e-006,0.000000e+000,3,6.845514e-001,0.000000e+000,,,,,,,,,,,,,,32,1,4.000000e+000,5.260468e-003,0.000000e+000,0,,0,
1524587618.346,,0.000000e+000,5.500168e+001,2.191821e-006,0.000000e+000,3,7.141805e-001,0.000000e+000,,,,,,,,,,,,,,32,1,4.000000e+000,6.580353e-003,0.000000e+000,0,,0,
1524587655.436,,0.000000e+000,5.499708e+001,2.042559e-006,0.000000e+000,3,6.059045e-001,0.000000e+000,,,,,,,,,,,,,,32,1,4.000000e+000,0.000000e+000,0.000000e+000,0,,0,
1524587693.216,,0.000000e+000,5.499773e+001,1.953297e-006,0.000000e+000,3,6.022719e-001,0.000000e+000,,,,,,,,,,,,,,32,1,4.000000e+000,1.308441e-003,0.000000e+000,0,,0,
1524587731.146,,0.000000e+000,5.499971e+001,1.836296e-006,0.000000e+000,3,5.686517e-001,0.000000e+000,,,,,,,,,,,,,,32,1,4.000000e+000,2.639771e-003,0.000000e+000,0,,0,
1524587769.136,,0.000000e+000,5.499248e+001,1.813066e-006,0.000000e+000,3,5.915077e-001,0.000000e+000,,,,,,,,,,,,,,32,1,4.000000e+000,1.319885e-003,0.000000e+000,0,,0,
1524587807.276,,0.000000e+000,5.499971e+001,1.771188e-006,0.000000e+000,3,6.091281e-001,0.000000e+000,,,,,,,,,,,,,,32,1,4.000000e+000,2.639771e-003,0.000000e+000,0,,0,
1524587845.726,,0.000000e+000,5.499971e+001,1.640522e-006,0.000000e+000,3,5.969933e-001,0.000000e+000,,,,,,,,,,,,,,32,1,4.000000e+000,1.052094e-002,0.000000e+000,0,,0,
1524587883.156,,0.000000e+000,5.499643e+001,1.672182e-006,0.000000e+000,3,5.764761e-001,0.000000e+000,,,,,,,,,,,,,,32,1,4.000000e+000,6.568909e-003,0.000000e+000,0,,0,
1524587920.856,,0.000000e+000,5.499182e+001,1.525018e-006,0.000000e+000,3,5.062419e-001,0.000000e+000,,,,,,,,,,,,,,32,1,4.000000e+000,5.260468e-003,0.000000e+000,0,,0,
1524587958.856,,0.000000e+000,5.499840e+001,1.517679e-006,0.000000e+000,3,5.178261e-001,0.000000e+000,,,,,,,,,,,,,,32,1,4.000000e+000,2.628326e-003,0.000000e+000,0,,0,
1524587997.296,,0.000000e+000,5.499708e+001,1.406822e-006,0.000000e+000,3,4.494026e-001,0.000000e+000,,,,,,,,,,,,,,32,1,4.000000e+000,2.620697e-003,0.000000e+000,0,,0,
1524588033.946,,0.000000e+000,5.500037e+001,1.414578e-006,0.000000e+000,3,4.611505e-001,0.000000e+000,,,,,,,,,,,,,,32,1,4.000000e+000,3.959656e-003,0.000000e+000,0,,0,
1524588071.836,,0.000000e+000,5.500037e+001,1.352372e-006,0.000000e+000,3,4.989462e-001,0.000000e+000,,,,,,,,,,,,,,32,1,4.000000e+000,3.959656e-003,0.000000e+000,0,,0,
1524588110.546,,0.000000e+000,5.499708e+001,1.331099e-006,0.000000e+000,3,4.187611e-001,0.000000e+000,,,,,,,,,,,,,,32,1,4.000000e+000,0.000000e+000,0.000000e+000,0,,0,
1524588147.966,,0.000000e+000,5.499906e+001,1.422051e-006,0.000000e+000,3,4.352885e-001,0.000000e+000,,,,,,,,,,,,,,32,1,4.000000e+000,6.580353e-003,0.000000e+000,0,,0,
1524588186.497,,0.000000e+000,5.500103e+001,1.241480e-006,0.000000e+000,3,3.567210e-001,0.000000e+000,,,,,,,,,,,,,,32,1,4.000000e+000,5.279541e-003,0.000000e+000,0,,0,
1524588224.617,,0.000000e+000,5.499445e+001,1.304337e-006,0.000000e+000,3,4.075248e-001,0.000000e+000,,,,,,,,,,,,,,32,1,4.000000e+000,1.314926e-002,0.000000e+000,0,,0,
1524588262.537,,0.000000e+000,5.499972e+001,1.355662e-006,0.000000e+000,3,4.771485e-001,0.000000e+000,,,,,,,,,,,,,,32,1,4.000000e+000,5.268097e-003,0.000000e+000,0,,0,
1524588299.947,,0.000000e+000,5.500367e+001,1.240404e-006,0.000000e+000,3,4.287507e-001,0.000000e+000,,,,,,,,,,,,,,32,1,4.000000e+000,0.000000e+000,0.000000e+000,0,,0,
1524588337.687,,0.000000e+000,5.499840e+001,1.282726e-006,0.000000e+000,3,4.111592e-001,0.000000e+000,,,,,,,,,,,,,,32,1,4.000000e+000,7.900238e-003,0.000000e+000,0,,0,
1524588375.837,,0.000000e+000,5.499182e+001,1.195102e-006,0.000000e+000,3,3.332604e-001,0.000000e+000,,,,,,,,,,,,,,32,1,4.000000e+000,5.260468e-003,0.000000e+000,0,,0,
1524588414.037,,0.000000e+000,5.499511e+001,1.129345e-006,0.000000e+000,3,3.075388e-001,0.000000e+000,,,,,,,,,,,,,,32,1,4.000000e+000,3.940582e-003,0.000000e+000,0,,0,
1524588452.067,,0.000000e+000,5.500497e+001,1.198447e-006,0.000000e+000,3,3.202311e-001,0.000000e+000,,,,,,,,,,,,,,32,1,4.000000e+000,7.888794e-003,0.000000e+000,0,,0,
1524588489.647,,0.000000e+000,5.499380e+001,1.211021e-006,0.000000e+000,3,3.939330e-001,0.000000e+000,,,,,,,,,,,,,,32,1,4.000000e+000,1.308441e-003,0.000000e+000,0,,0,
1524588527.487,,0.000000e+000,5.499248e+001,1.132693e-006,0.000000e+000,3,3.287609e-001,0.000000e+000,,,,,,,,,,,,,,32,1,4.000000e+000,9.201050e-003,0.000000e+000,0,,0,
1524588565.417,,0.000000e+000,5.499577e+001,1.111861e-006,0.000000e+000,3,2.006825e-001,0.000000e+000,,,,,,,,,,,,,,32,1,4.000000e+000,1.052094e-002,0.000000e+000,0,,0,
1524588603.997,,0.000000e+000,5.499445e+001,1.229783e-006,0.000000e+000,3,3.331180e-001,0.000000e+000,,,,,,,,,,,,,,32,1,4.000000e+000,0.000000e+000,0.000000e+000,0,,0,
1524588641.307,,0.000000e+000,5.499643e+001,1.108363e-006,0.000000e+000,3,2.770931e-001,0.000000e+000,,,,,,,,,,,,,,32,1,4.000000e+000,1.184082e-002,0.000000e+000,0,,0,
1524588679.247,,0.000000e+000,5.499577e+001,1.157989e-006,0.000000e+000,3,3.277166e-001,0.000000e+000,,,,,,,,,,,,,,32,1,4.000000e+000,0.000000e+000,0.000000e+000,0,,0,
1524588716.957,,0.000000e+000,5.499840e+001,1.077020e-006,0.000000e+000,3,2.605190e-001,0.000000e+000,,,,,,,,,,,,,,32,1,4.000000e+000,2.628326e-003,0.000000e+000,0,,0,
1524588756.247,,0.000000e+000,5.499446e+001,3.267750e-007,0.000000e+000,2,0.000000e+000,0.000000e+000,,,,,,,,,,,,,,32,1,4.000000e+000,1.842117e-002,0.000000e+000,0,,0,
1524588798.623,,0.000000e+000,5.499906e+001,2.855447e-007,0.000000e+000,2,0.000000e+000,0.000000e+000,,,,,,,,,,,,,,32,1,4.000000e+000,6.580353e-003,0.000000e+000,0,,0,
1524588840.839,,0.000000e+000,5.500629e+001,2.809963e-007,0.000000e+000,2,0.000000e+000,0.000000e+000,,,,,,,,,,,,,,32,1,4.000000e+000,5.249023e-003,0.000000e+000,0,,0,
1524588883.436,,0.000000e+000,5.500037e+001,1.990142e-007,0.000000e+000,2,0.000000e+000,0.000000e+000,,,,,,,,,,,,,,32,1,4.000000e+000,3.959656e-003,0.000000e+000,0,,0,
1524588926.352,,0.000000e+000,5.499971e+001,2.436289e-007,0.000000e+000,2,0.000000e+000,0.000000e+000,,,,,,,,,,,,,,32,1,4.000000e+000,0.000000e+000,0.000000e+000,0,,0,
1524588967.806,,0.000000e+000,5.499905e+001,-1.822884e-006,0.000000e+000,3,8.441761e-001,0.000000e+000,,,,,,,,,,,,,,32,1,4.000000e+000,1.319885e-003,0.000000e+000,0,,0,
1524589010.662,,0.000000e+000,5.499905e+001,2.105152e-007,0.000000e+000,2,0.000000e+000,0.000000e+000,,,,,,,,,,,,,,32,1,4.000000e+000,3.948212e-003,0.000000e+000,0,,0,
1524589050.856,,0.000000e+000,5.500234e+001,2.229631e-007,0.000000e+000,2,0.000000e+000,0.000000e+000,,,,,,,,,,,,,,32,1,4.000000e+000,7.900238e-003,0.000000e+000,0,,0,
1524589089.658,,0.000000e+000,5.499577e+001,-1.662864e-006,0.000000e+000,3,8.176385e-001,0.000000e+000,,,,,,,,,,,,,,32,1,4.000000e+000,5.249023e-003,0.000000e+000,0,,0,
1524589129.510,,0.000000e+000,5.499445e+001,-1.672776e-006,0.000000e+000,3,8.141516e-001,0.000000e+000,,,,,,,,,,,,,,32,1,4.000000e+000,0.000000e+000,0.000000e+000,0,,0,
1524589170.794,,0.000000e+000,5.499642e+001,1.688339e-007,0.000000e+000,2,0.000000e+000,0.000000e+000,,,,,,,,,,,,,,32,1,4.000000e+000,3.940582e-003,0.000000e+000,0,,0,
1524589207.604,,0.000000e+000,5.500103e+001,-1.719138e-006,0.000000e+000,3,7.739716e-001,0.000000e+000,,,,,,,,,,,,,,32,1,4.000000e+000,2.639771e-003,0.000000e+000,0,,0,
1524589246.646,,0.000000e+000,5.499708e+001,-1.825233e-006,0.000000e+000,3,8.466910e-001,0.000000e+000,,,,,,,,,,,,,,32,1,4.000000e+000,2.620697e-003,0.000000e+000,0,,0,
1524589288.040,,0.000000e+000,5.499577e+001,4.996915e-008,0.000000e+000,2,0.000000e+000,0.000000e+000,,,,,,,,,,,,,,32,1,4.000000e+000,2.632141e-003,0.000000e+000,0,,0,
1524589325.250,,0.000000e+000,5.499774e+001,9.686476e-007,0.000000e+000,3,2.925961e-002,0.000000e+000,,,,,,,,,,,,,,32,1,4.000000e+000,3.940582e-003,0.000000e+000,0,,0,
1524589365.352,,0.000000e+000,5.500169e+001,-1.642740e-006,0.000000e+000,3,8.334104e-001,0.000000e+000,,,,,,,,,,,,,,32,1,4.000000e+000,9.208679e-003,0.000000e+000,0,,0,
1524589404.644,,0.000000e+000,5.500432e+001,-1.638718e-006,0.000000e+000,3,8.464085e-001,0.000000e+000,,,,,,,,,,,,,,32,1,4.000000e+000,6.580353e-003,0.000000e+000,0,,0,
1524589444.836,,0.000000e+000,5.499775e+001,-1.595484e-006,0.000000e+000,3,8.620666e-001,0.000000e+000,,,,,,,,,,,,,,32,1,4.000000e+000,9.208679e-003,0.000000e+000,0,,0,
1524589482.736,,0.000000e+000,5.499840e+001,-1.690050e-006,0.000000e+000,3,7.977473e-001,0.000000e+000,,,,,,,,,,,,,,32,1,4.000000e+000,7.900238e-003,0.000000e+000,0,,0,
1524589522.928,,0.000000e+000,5.500103e+001,9.785081e-007,0.000000e+000,3,1.091084e-001,0.000000e+000,,,,,,,,,,,,,,32,1,4.000000e+000,7.888794e-003,0.000000e+000,0,,0,
1524589562.850,,0.000000e+000,5.499445e+001,3.371144e-008,0.000000e+000,2,0.000000e+000,0.000000e+000,,,,,,,,,,,,,,32,1,4.000000e+000,2.628326e-003,0.000000e+000,0,,0,
1524589602.322,,0.000000e+000,5.499773e+001,6.811559e-009,0.000000e+000,2,0.000000e+000,0.000000e+000,,,,,,,,,,,,,,32,1,4.000000e+000,1.308441e-003,0.000000e+000,0,,0,
1524589639.682,,0.000000e+000,5.499445e+001,-1.676112e-006,0.000000e+000,3,8.206421e-001,0.000000e+000,,,,,,,,,,,,,,32,1,4.000000e+000,2.628326e-003,0.000000e+000,0,,0,
1524589680.346,,0.000000e+000,5.500037e+001,1.129501e-006,0.000000e+000,3,1.728739e-001,0.000000e+000,,,,,,,,,,,,,,32,1,4.000000e+000,1.319885e-003,0.000000e+000,0,,0,
1524589719.958,,0.000000e+000,5.499643e+001,4.268430e-008,0.000000e+000,2,0.000000e+000,0.000000e+000,,,,,,,,,,,,,,32,1,4.000000e+000,9.208679e-003,0.000000e+000,0,,0,
1524589758.870,,0.000000e+000,5.499840e+001,1.036236e-006,0.000000e+000,3,9.343556e-002,0.000000e+000,,,,,,,,,,,,,,32,1,4.000000e+000,2.628326e-003,0.000000e+000,0,,0,
1524589800.314,,0.000000e+000,5.500366e+001,-4.271775e-008,0.000000e+000,2,0.000000e+000,0.000000e+000,,,,,,,,,,,,,,32,1,4.000000e+000,5.260468e-003,0.000000e+000,0,,0,
1524589840.626,,0.000000e+000,5.499840e+001,-3.056699e-008,0.000000e+000,2,0.000000e+000,0.000000e+000,,,,,,,,,,,,,,32,1,4.000000e+000,7.900238e-003,0.000000e+000,0,,0,
1524589883.572,,0.000000e+000,5.499577e+001,-5.345876e-008,0.000000e+000,2,0.000000e+000,0.000000e+000,,,,,,,,,,,,,,32,1,4.000000e+000,2.632141e-003,0.000000e+000,0,,0,
1524589925.056,,0.000000e+000,5.500169e+001,-7.053741e-008,0.000000e+000,2,0.000000e+000,0.000000e+000,,,,,,,,,,,,,,32,1,4.000000e+000,1.319885e-003,0.000000e+000,0,,0,
1524589962.116,,0.000000e+000,5.499643e+001,-1.631521e-006,0.000000e+000,3,7.492595e-001,0.000000e+000,,,,,,,,,,,,,,32,1,4.000000e+000,9.208679e-003,0.000000e+000,0,,0,
1524589999.876,,0.000000e+000,5.499774e+001,1.123712e-006,0.000000e+000,3,2.070811e-001,0.000000e+000,,,,,,,,,,,,,,32,1,4.000000e+000,6.580353e-003,0.000000e+000,0,,0,
1524590062.436,,0.000000e+000,5.500432e+001,9.898259e-007,0.000000e+000,3,3.189697e-002,0.000000e+000,,,,,,,,,,,,,,32,1,4.000000e+000,1.446915e-002,0.000000e+000,0,,0,
1524590100.276,,0.000000e+000,5.499906e+001,1.239987e-006,0.000000e+000,3,3.324048e-001,0.000000e+000,,,,,,,,,,,,,,32,1,4.000000e+000,9.220123e-003,0.000000e+000,0,,0,
1524590139.148,,0.000000e+000,5.499840e+001,9.891303e-007,0.000000e+000,3,1.428595e-001,0.000000e+000,,,,,,,,,,,,,,32,1,4.000000e+000,5.260468e-003,0.000000e+000,0,,0,
1524590177.098,,0.000000e+000,5.499313e+001,1.111634e-006,0.000000e+000,3,2.016852e-001,0.000000e+000,,,,,,,,,,,,,,32,1,4.000000e+000,1.050949e-002,0.000000e+000,0,,0,
1524590215.158,,0.000000e+000,5.499642e+001,1.113812e-006,0.000000e+000,3,3.065832e-001,0.000000e+000,,,,,,,,,,,,,,32,1,4.000000e+000,3.940582e-003,0.000000e+000,0,,0,
1524590252.948,,0.000000e+000,5.499840e+001,8.704471e-007,0.000000e+000,3,3.296150e-002,0.000000e+000,,,,,,,,,,,,,,32,1,4.000000e+000,7.900238e-003,0.000000e+000,0,,0,
1524590290.568,,0.000000e+000,5.499773e+001,1.131377e-006,0.000000e+000,3,2.617168e-001,0.000000e+000,,,,,,,,,,,,,,32,1,4.000000e+000,1.308441e-003,0.000000e+000,0,,0,
1524590352.439,,0.000000e+000,5.500169e+001,9.202299e-007,0.000000e+000,3,7.022659e-002,0.000000e+000,,,,,,,,,,,,,,32,1,4.000000e+000,1.319885e-003,0.000000e+000,0,,0,
1524590390.349,,0.000000e+000,5.499840e+001,1.066178e-006,0.000000e+000,3,2.179614e-001,0.000000e+000,,,,,,,,,,,,,,32,1,4.000000e+000,5.260468e-003,0.000000e+000,0,,0,
1524590428.049,,0.000000e+000,5.499773e+001,1.072438e-006,0.000000e+000,3,1.536379e-001,0.000000e+000,,,,,,,,,,,,,,32,1,4.000000e+000,1.308441e-003,0.000000e+000,0,,0,
1524590466.039,,0.000000e+000,5.500103e+001,1.122920e-006,0.000000e+000,3,2.033109e-001,0.000000e+000,,,,,,,,,,,,,,32,1,4.000000e+000,0.000000e+000,0.000000e+000,0,,0,
1524590503.679,,0.000000e+000,5.499511e+001,1.001552e-006,0.000000e+000,3,9.702677e-002,0.000000e+000,,,,,,,,,,,,,,32,1,4.000000e+000,3.940582e-003,0.000000e+000,0,,0,
1524590541.719,,0.000000e+000,5.499905e+001,1.088531e-006,0.000000e+000,3,1.638310e-001,0.000000e+000,,,,,,,,,,,,,,32,1,4.000000e+000,1.446915e-002,0.000000e+000,0,,0,
1524590579.429,,0.000000e+000,5.499511e+001,1.075746e-006,0.000000e+000,3,1.785943e-001,0.000000e+000,,,,,,,,,,,,,,32,1,4.000000e+000,3.940582e-003,0.000000e+000,0,,0,
1524590617.359,,0.000000e+000,5.500432e+001,1.191254e-006,0.000000e+000,3,2.314001e-001,0.000000e+000,,,,,,,,,,,,,,32,1,4.000000e+000,1.300812e-003,0.000000e+000,0,,0,
1524590654.989,,0.000000e+000,5.499906e+001,1.143260e-006,0.000000e+000,3,1.855765e-001,0.000000e+000,,,,,,,,,,,,,,32,1,4.000000e+000,6.580353e-003,0.000000e+000,0,,0,
1524590692.939,,0.000000e+000,5.499971e+001,1.109557e-006,0.000000e+000,3,1.830748e-001,0.000000e+000,,,,,,,,,,,,,,32,1,4.000000e+000,2.639771e-003,0.000000e+000,0,,0,
1524590733.471,,0.000000e+000,5.499775e+001,1.041429e-006,0.000000e+000,3,6.336617e-002,0.000000e+000,,,,,,,,,,,,,,32,1,4.000000e+000,9.208679e-003,0.000000e+000,0,,0,
1524590771.211,,0.000000e+000,5.499380e+001,1.251644e-006,0.000000e+000,3,3.008744e-001,0.000000e+000,,,,,,,,,,,,,,32,1,4.000000e+000,3.948212e-003,0.000000e+000,0,,0,
1524590808.411,,0.000000e+000,5.499708e+001,1.132136e-006,0.000000e+000,3,2.008805e-001,0.000000e+000,,,,,,,,,,,,,,32,1,4.000000e+000,2.620697e-003,0.000000e+000,0,,0,
1524590847.833,,0.000000e+000,5.499182e+001,1.087662e-006,0.000000e+000,3,1.070217e-001,0.000000e+000,,,,,,,,,,,,,,32,1,4.000000e+000,5.260468e-003,0.000000e+000,0,,0,
1524590890.529,,0.000000e+000,5.499577e+001,-2.864435e-007,0.000000e+000,2,0.000000e+000,0.000000e+000,,,,,,,,,,,,,,32,1,4.000000e+000,0.000000e+000,0.000000e+000,0,,0,
1524590930.643,,0.000000e+000,5.499643e+001,-3.028066e-007,0.000000e+000,2,0.000000e+000,0.000000e+000,,,,,,,,,,,,,,32,1,4.000000e+000,6.568909e-003,0.000000e+000,0,,0,
1524590971.727,,0.000000e+000,5.499905e+001,-3.141314e-007,0.000000e+000,2,0.000000e+000,0.000000e+000,,,,,,,,,,,,,,32,1,4.000000e+000,1.319885e-003,0.000000e+000,0,,0,
1524591013.934,,0.000000e+000,5.499971e+001,-3.092298e-007,0.000000e+000,2,0.000000e+000,0.000000e+000,,,,,,,,,,,,,,32,1,4.000000e+000,0.000000e+000,0.000000e+000,0,,0,
1524591057.640,,0.000000e+000,5.499709e+001,-3.599042e-007,0.000000e+000,2,0.000000e+000,0.000000e+000,,,,,,,,,,,,,,32,1,4.000000e+000,7.888794e-003,0.000000e+000,0,,0,
1524591098.954,,0.000000e+000,5.499577e+001,1.284655e-006,0.000000e+000,3,2.281821e-001,0.000000e+000,,,,,,,,,,,,,,32,1,4.000000e+000,5.249023e-003,0.000000e+000,0,,0,
1524591141.270,,0.000000e+000,5.499774e+001,-3.198668e-007,0.000000e+000,2,0.000000e+000,0.000000e+000,,,,,,,,,,,,,,32,1,4.000000e+000,3.940582e-003,0.000000e+000,0,,0,
1524591181.844,,0.000000e+000,5.499840e+001,-3.597892e-007,0.000000e+000,2,0.000000e+000,0.000000e+000,,,,,,,,,,,,,,32,1,4.000000e+000,5.260468e-003,0.000000e+000,0,,0,
1524591222.828,,0.000000e+000,5.499051e+001,-3.942015e-007,0.000000e+000,2,0.000000e+000,0.000000e+000,,,,,,,,,,,,,,32,1,4.000000e+000,2.632141e-003,0.000000e+000,0,,0,
1524591264.884,,0.000000e+000,5.499116e+001,-3.393334e-007,0.000000e+000,2,0.000000e+000,0.000000e+000,,,,,,,,,,,,,,32,1,4.000000e+000,1.446152e-002,0.000000e+000,0,,0,
1524591308.070,,0.000000e+000,5.498985e+001,-3.502157e-007,0.000000e+000,2,0.000000e+000,0.000000e+000,,,,,,,,,,,,,,32,1,4.000000e+000,1.319885e-003,0.000000e+000,0,,0,
1524591349.716,,0.000000e+000,5.499905e+001,-3.205794e-007,0.000000e+000,2,0.000000e+000,0.000000e+000,,,,,,,,,,,,,,32,1,4.000000e+000,3.948212e-003,0.000000e+000,0,,0,
1524591392.852,,0.000000e+000,5.500037e+001,-3.379162e-007,0.000000e+000,2,0.000000e+000,0.000000e+000,,,,,,,,,,,,,,32,1,4.000000e+000,1.446915e-002,0.000000e+000,0,,0,
1524591436.488,,0.000000e+000,5.500037e+001,-3.689265e-007,0.000000e+000,2,0.000000e+000,0.000000e+000,,,,,,,,,,,,,,32,1,4.000000e+000,3.959656e-003,0.000000e+000,0,,0,
1524591478.894,,0.000000e+000,5.499577e+001,-3.286663e-007,0.000000e+000,2,0.000000e+000,0.000000e+000,,,,,,,,,,,,,,32,1,4.000000e+000,1.316071e-002,0.000000e+000,0,,0,
1524591520.820,,0.000000e+000,5.500169e+001,-3.745162e-007,0.000000e+000,2,0.000000e+000,0.000000e+000,,,,,,,,,,,,,,32,1,4.000000e+000,3.959656e-003,0.000000e+000,0,,0,
1524591562.956,,0.000000e+000,5.499972e+001,-3.784739e-007,0.000000e+000,2,0.000000e+000,0.000000e+000,,,,,,,,,,,,,,32,1,4.000000e+000,7.900238e-003,0.000000e+000,0,,0,
1524591606.792,,0.000000e+000,5.499445e+001,-3.157967e-007,0.000000e+000,2,0.000000e+000,0.000000e+000,,,,,,,,,,,,,,32,1,4.000000e+000,0.000000e+000,0.000000e+000,0,,0,
1524591650.738,,0.000000e+000,5.499577e+001,-4.151537e-007,0.000000e+000,2,0.000000e+000,0.000000e+000,,,,,,,,,,,,,,32,1,4.000000e+000,2.632141e-003,0.000000e+000,0,,0,
1524591694.144,,0.000000e+000,5.499708e+001,-4.309499e-007,0.000000e+000,2,0.000000e+000,0.000000e+000,,,,,,,,,,,,,,32,1,4.000000e+000,2.620697e-003,0.000000e+000,0,,0,
1524591735.781,,0.000000e+000,5.500497e+001,-3.861119e-007,0.000000e+000,2,0.000000e+000,0.000000e+000,,,,,,,,,,,,,,32,1,4.000000e+000,0.000000e+000,0.000000e+000,0,,0,
1524591779.157,,0.000000e+000,5.500037e+001,-4.658913e-007,0.000000e+000,2,0.000000e+000,0.000000e+000,,,,,,,,,,,,,,32,1,4.000000e+000,9.201050e-003,0.000000e+000,0,,0,
1524591821.513,,0.000000e+000,5.500234e+001,-3.615888e-007,0.000000e+000,2,0.000000e+000,0.000000e+000,,,,,,,,,,,,,,32,1,4.000000e+000,5.260468e-003,0.000000e+000,0,,0,
1524591864.509,,0.000000e+000,5.500629e+001,-3.733820e-007,0.000000e+000,2,0.000000e+000,0.000000e+000,,,,,,,,,,,,,,32,1,4.000000e+000,5.249023e-003,0.000000e+000,0,,0,
1524591907.315,,0.000000e+000,5.500037e+001,-4.387984e-007,0.000000e+000,2,0.000000e+000,0.000000e+000,,,,,,,,,,,,,,32,1,4.000000e+000,3.959656e-003,0.000000e+000,0,,0,
1524591950.211,,0.000000e+000,5.500169e+001,-4.408044e-007,0.000000e+000,2,0.000000e+000,0.000000e+000,,,,,,,,,,,,,,32,1,4.000000e+000,9.208679e-003,0.000000e+000,0,,0,
1524591993.489,,0.000000e+000,5.500103e+001,-4.991884e-007,0.000000e+000,2,0.000000e+000,0.000000e+000,,,,,,,,,,,,,,32,1,4.000000e+000,0.000000e+000,0.000000e+000,0,,0,
1524592036.815,,0.000000e+000,5.499773e+001,-4.589997e-007,0.000000e+000,2,0.000000e+000,0.000000e+000,,,,,,,,,,,,,,32,1,4.000000e+000,1.308441e-003,0.000000e+000,0,,0,
1524592079.701,,0.000000e+000,5.499511e+001,-3.924791e-007,0.000000e+000,2,0.000000e+000,0.000000e+000,,,,,,,,,,,,,,32,1,4.000000e+000,6.568909e-003,0.000000e+000,0,,0,
1524592122.147,,0.000000e+000,5.500300e+001,-4.164081e-007,0.000000e+000,2,0.000000e+000,0.000000e+000,,,,,,,,,,,,,,32,1,4.000000e+000,3.940582e-003,0.000000e+000,0,,0,
1524592165.433,,0.000000e+000,5.499775e+001,-4.359994e-007,0.000000e+000,2,0.000000e+000,0.000000e+000,,,,,,,,,,,,,,32,1,4.000000e+000,9.208679e-003,0.000000e+000,0,,0,
1524592208.409,,0.000000e+000,5.499773e+001,-4.631147e-007,0.000000e+000,2,0.000000e+000,0.000000e+000,,,,,,,,,,,,,,32,1,4.000000e+000,1.308441e-003,0.000000e+000,0,,0,
1524592249.383,,0.000000e+000,5.500037e+001,-4.593705e-007,0.000000e+000,2,0.000000e+000,0.000000e+000,,,,,,,,,,,,,,32,1,4.000000e+000,9.201050e-003,0.000000e+000,0,,0,
1524592292.009,,0.000000e+000,5.500367e+001,-4.552230e-007,0.000000e+000,2,0.000000e+000,0.000000e+000,,,,,,,,,,,,,,32,1,4.000000e+000,0.000000e+000,0.000000e+000,0,,0,
1524592334.855,,0.000000e+000,5.500103e+001,-4.457412e-007,0.000000e+000,2,0.000000e+000,0.000000e+000,,,,,,,,,,,,,,32,1,4.000000e+000,0.000000e+000,0.000000e+000,0,,0,
1524592376.971,,0.000000e+000,5.499905e+001,-4.632949e-007,0.000000e+000,2,0.000000e+000,0.000000e+000,,,,,,,,,,,,,,32,1,4.000000e+000,3.948212e-003,0.000000e+000,0,,0,
1524592420.637,,0.000000e+000,5.500037e+001,-5.245016e-007,0.000000e+000,2,0.000000e+000,0.000000e+000,,,,,,,,,,,,,,32,1,4.000000e+000,6.587982e-003,0.000000e+000,0,,0,
1524592464.174,,0.000000e+000,5.500366e+001,-4.243800e-007,0.000000e+000,2,0.000000e+000,0.000000e+000,,,,,,,,,,,,,,32,1,4.000000e+000,1.315689e-002,0.000000e+000,0,,0,
1524592507.390,,0.000000e+000,5.499643e+001,-4.561383e-007,0.000000e+000,2,0.000000e+000,0.000000e+000,,,,,,,,,,,,,,32,1,4.000000e+000,6.568909e-003,0.000000e+000,0,,0,
1524592549.466,,0.000000e+000,5.499182e+001,-4.232560e-007,0.000000e+000,2,0.000000e+000,0.000000e+000,,,,,,,,,,,,,,32,1,4.000000e+000,5.260468e-003,0.000000e+000,0,,0,
1524592592.654,,0.000000e+000,5.499709e+001,-4.952357e-007,0.000000e+000,2,0.000000e+000,0.000000e+000,,,,,,,,,,,,,,32,1,4.000000e+000,7.888794e-003,0.000000e+000,0,,0,
1524592635.430,,0.000000e+000,5.500366e+001,-4.812607e-007,0.000000e+000,2,0.000000e+000,0.000000e+000,,,,,,,,,,,,,,32,1,4.000000e+000,1.578140e-002,0.000000e+000,0,,0,
1524592678.316,,0.000000e+000,5.500103e+001,-4.430946e-007,0.000000e+000,2,0.000000e+000,0.000000e+000,,,,,,,,,,,,,,32,1,4.000000e+000,5.279541e-003,0.000000e+000,0,,0,
1524592721.232,,0.000000e+000,5.499511e+001,-5.059268e-007,0.000000e+000,2,0.000000e+000,0.000000e+000,,,,,,,,,,,,,,32,1,4.000000e+000,1.319885e-003,0.000000e+000,0,,0,
1524592763.198,,0.000000e+000,5.499642e+001,-4.212775e-007,0.000000e+000,2,0.000000e+000,0.000000e+000,,,,,,,,,,,,,,32,1,4.000000e+000,3.940582e-003,0.000000e+000,0,,0,
1524592805.464,,0.000000e+000,5.500498e+001,-5.028037e-007,0.000000e+000,2,0.000000e+000,0.000000e+000,,,,,,,,,,,,,,32,1,4.000000e+000,5.260468e-003,0.000000e+000,0,,0,
1524592848.870,,0.000000e+000,5.499906e+001,-5.233832e-007,0.000000e+000,2,0.000000e+000,0.000000e+000,,,,,,,,,,,,,,32,1,4.000000e+000,9.220123e-003,0.000000e+000,0,,0,
1524592892.496,,0.000000e+000,5.499774e+001,-4.813771e-007,0.000000e+000,2,0.000000e+000,0.000000e+000,,,,,,,,,,,,,,32,1,4.000000e+000,3.940582e-003,0.000000e+000,0,,0,
1524592936.002,,0.000000e+000,5.499577e+001,-5.157102e-007,0.000000e+000,2,0.000000e+000,0.000000e+000,,,,,,,,,,,,,,32,1,4.000000e+000,7.888794e-003,0.000000e+000,0,,0,
1524592977.626,,0.000000e+000,5.500498e+001,-4.090770e-007,0.000000e+000,2,0.000000e+000,0.000000e+000,,,,,,,,,,,,,,32,1,4.000000e+000,5.260468e-003,0.000000e+000,0,,0,
1524593020.992,,0.000000e+000,5.499577e+001,-4.807903e-007,0.000000e+000,2,0.000000e+000,0.000000e+000,,,,,,,,,,,,,,32,1,4.000000e+000,7.888794e-003,0.000000e+000,0,,0,
1524593061.938,,0.000000e+000,5.499511e+001,-4.402348e-007,0.000000e+000,2,0.000000e+000,0.000000e+000,,,,,,,,,,,,,,32,1,4.000000e+000,1.319885e-003,0.000000e+000,0,,0,
1524593102.852,,0.000000e+000,5.500037e+001,-1.641074e-006,0.000000e+000,3,6.570424e-001,0.000000e+000,,,,,,,,,,,,,,32,1,4.000000e+000,9.201050e-003,0.000000e+000,0,,0,
1524593145.279,,0.000000e+000,5.499840e+001,-5.276841e-007,0.000000e+000,2,0.000000e+000,0.000000e+000,,,,,,,,,,,,,,32,1,4.000000e+000,2.628326e-003,0.000000e+000,0,,0,
1524593186.553,,0.000000e+000,5.499905e+001,-4.967757e-007,0.000000e+000,2,0.000000e+000,0.000000e+000,,,,,,,,,,,,,,32,1,4.000000e+000,1.319885e-003,0.000000e+000,0,,0,
1524593229.999,,0.000000e+000,5.500366e+001,-4.868821e-007,0.000000e+000,2,0.000000e+000,0.000000e+000,,,,,,,,,,,,,,32,1,4.000000e+000,1.315689e-002,0.000000e+000,0,,0,
1524593272.385,,0.000000e+000,5.499905e+001,-4.932643e-007,0.000000e+000,2,0.000000e+000,0.000000e+000,,,,,,,,,,,,,,32,1,4.000000e+000,3.948212e-003,0.000000e+000,0,,0,
1524593315.191,,0.000000e+000,5.500037e+001,-5.289908e-007,0.000000e+000,2,0.000000e+000,0.000000e+000,,,,,,,,,,,,,,32,1,4.000000e+000,6.587982e-003,0.000000e+000,0,,0,
1524593355.565,,0.000000e+000,5.499445e+001,-5.372013e-007,0.000000e+000,2,0.000000e+000,0.000000e+000,,,,,,,,,,,,,,32,1,4.000000e+000,0.000000e+000,0.000000e+000,0,,0,
1524593399.121,,0.000000e+000,5.499182e+001,-5.538869e-007,0.000000e+000,2,0.000000e+000,0.000000e+000,,,,,,,,,,,,,,32,1,4.000000e+000,1.578140e-002,0.000000e+000,0,,0,
1524593440.805,,0.000000e+000,5.499248e+001,-5.150491e-007,0.000000e+000,2,0.000000e+000,0.000000e+000,,,,,,,,,,,,,,32,1,4.000000e+000,6.580353e-003,0.000000e+000,0,,0,
1524593483.671,,0.000000e+000,5.499775e+001,-5.130760e-007,0.000000e+000,2,0.000000e+000,0.000000e+000,,,,,,,,,,,,,,32,1,4.000000e+000,1.184845e-002,0.000000e+000,0,,0,
1524593527.367,,0.000000e+000,5.499840e+001,-4.965071e-007,0.000000e+000,2,0.000000e+000,0.000000e+000,,,,,,,,,,,,,,32,1,4.000000e+000,2.628326e-003,0.000000e+000,0,,0,
1524593568.191,,0.000000e+000,5.500103e+001,-5.428328e-007,0.000000e+000,2,0.000000e+000,0.000000e+000,,,,,,,,,,,,,,32,1,4.000000e+000,0.000000e+000,0.000000e+000,0,,0,
1524593609.235,,0.000000e+000,5.499708e+001,-5.516274e-007,0.000000e+000,2,0.000000e+000,0.000000e+000,,,,,,,,,,,,,,32,1,4.000000e+000,2.620697e-003,0.000000e+000,0,,0,
1524593650.089,,0.000000e+000,5.499642e+001,-1.617992e-006,0.000000e+000,3,7.302094e-001,0.000000e+000,,,,,,,,,,,,,,32,1,4.000000e+000,3.940582e-003,0.000000e+000,0,,0,
1524593693.805,,0.000000e+000,5.500037e+001,-4.824860e-007,0.000000e+000,2,0.000000e+000,0.000000e+000,,,,,,,,,,,,,,32,1,4.000000e+000,6.587982e-003,0.000000e+000,0,,0,
1524593735.479,,0.000000e+000,5.500169e+001,-1.591303e-006,0.000000e+000,3,7.388973e-001,0.000000e+000,,,,,,,,,,,,,,32,1,4.000000e+000,9.208679e-003,0.000000e+000,0,,0,
1524593776.243,,0.000000e+000,5.500037e+001,-1.680199e-006,0.000000e+000,3,7.486804e-001,0.000000e+000,,,,,,,,,,,,,,32,1,4.000000e+000,1.184082e-002,0.000000e+000,0,,0,
1524593818.949,,0.000000e+000,5.499643e+001,-5.370437e-007,0.000000e+000,2,0.000000e+000,0.000000e+000,,,,,,,,,,,,,,32,1,4.000000e+000,6.568909e-003,0.000000e+000,0,,0,
1524593860.694,,0.000000e+000,5.500037e+001,-1.758163e-006,0.000000e+000,3,6.100414e-001,0.000000e+000,,,,,,,,,,,,,,32,1,4.000000e+000,1.319885e-003,0.000000e+000,0,,0,
1524593904.000,,0.000000e+000,5.499709e+001,-4.895064e-007,0.000000e+000,2,0.000000e+000,0.000000e+000,,,,,,,,,,,,,,32,1,4.000000e+000,1.052856e-002,0.000000e+000,0,,0,
1524593945.174,,0.000000e+000,5.500103e+001,-1.546469e-006,0.000000e+000,3,7.512702e-001,0.000000e+000,,,,,,,,,,,,,,32,1,4.000000e+000,0.000000e+000,0.000000e+000,0,,0,
1524593988.210,,0.000000e+000,5.499774e+001,-5.431274e-007,0.000000e+000,2,0.000000e+000,0.000000e+000,,,,,,,,,,,,,,32,1,4.000000e+000,6.580353e-003,0.000000e+000,0,,0,
1524594031.756,,0.000000e+000,5.499905e+001,-5.478788e-007,0.000000e+000,2,0.000000e+000,0.000000e+000,,,,,,,,,,,,,,32,1,4.000000e+000,3.948212e-003,0.000000e+000,0,,0,
1524594072.890,,0.000000e+000,5.499577e+001,-5.446120e-007,0.000000e+000,2,0.000000e+000,0.000000e+000,,,,,,,,,,,,,,32,1,4.000000e+000,1.316071e-002,0.000000e+000,0,,0,
1524594114.754,,0.000000e+000,5.499445e+001,-1.669496e-006,0.000000e+000,3,7.193469e-001,0.000000e+000,,,,,,,,,,,,,,32,1,4.000000e+000,0.000000e+000,0.000000e+000,0,,0,
1524594157.360,,0.000000e+000,5.499840e+001,-4.787703e-007,0.000000e+000,2,0.000000e+000,0.000000e+000,,,,,,,,,,,,,,32,1,4.000000e+000,2.628326e-003,0.000000e+000,0,,0,
1524594201.796,,0.000000e+000,5.500103e+001,-5.864482e-007,0.000000e+000,2,0.000000e+000,0.000000e+000,,,,,,,,,,,,,,32,1,4.000000e+000,0.000000e+000,0.000000e+000,0,,0,
1524594243.020,,0.000000e+000,5.498722e+001,-5.128027e-007,0.000000e+000,2,0.000000e+000,0.000000e+000,,,,,,,,,,,,,,32,1,4.000000e+000,1.184082e-002,0.000000e+000,0,,0,
1524594284.364,,0.000000e+000,5.500301e+001,-5.429138e-007,0.000000e+000,2,0.000000e+000,0.000000e+000,,,,,,,,,,,,,,32,1,4.000000e+000,1.319885e-003,0.000000e+000,0,,0,
1524594325.198,,0.000000e+000,5.500169e+001,-1.550508e-006,0.000000e+000,3,7.618679e-001,0.000000e+000,,,,,,,,,,,,,,32,1,4.000000e+000,3.959656e-003,0.000000e+000,0,,0,
1524594368.854,,0.000000e+000,5.500234e+001,-5.215305e-007,0.000000e+000,2,0.000000e+000,0.000000e+000,,,,,,,,,,,,,,32,1,4.000000e+000,1.578903e-002,0.000000e+000,0,,0,
1524594407.356,,0.000000e+000,5.500300e+001,-1.507328e-006,0.000000e+000,3,7.502316e-001,0.000000e+000,,,,,,,,,,,,,,32,1,4.000000e+000,9.220123e-003,0.000000e+000,0,,0,
1524594450.192,,0.000000e+000,5.500169e+001,-5.234082e-007,0.000000e+000,2,0.000000e+000,0.000000e+000,,,,,,,,,,,,,,32,1,4.000000e+000,1.319885e-003,0.000000e+000,0,,0,
1524594493.348,,0.000000e+000,5.500563e+001,-5.455479e-007,0.000000e+000,2,0.000000e+000,0.000000e+000,,,,,,,,,,,,,,32,1,4.000000e+000,1.319885e-003,0.000000e+000,0,,0,
1524594532.050,,0.000000e+000,5.500103e+001,-1.622970e-006,0.000000e+000,3,6.920550e-001,0.000000e+000,,,,,,,,,,,,,,32,1,4.000000e+000,2.639771e-003,0.000000e+000,0,,0,
1524594573.935,,0.000000e+000,5.499840e+001,-5.699118e-007,0.000000e+000,2,0.000000e+000,0.000000e+000,,,,,,,,,,,,,,32,1,4.000000e+000,2.628326e-003,0.000000e+000,0,,0,
1524594614.899,,0.000000e+000,5.499248e+001,-5.021691e-007,0.000000e+000,2,0.000000e+000,0.000000e+000,,,,,,,,,,,,,,32,1,4.000000e+000,3.940582e-003,0.000000e+000,0,,0,
1524594654.431,,0.000000e+000,5.499773e+001,-4.982940e-007,0.000000e+000,2,0.000000e+000,0.000000e+000,,,,,,,,,,,,,,32,1,4.000000e+000,1.308441e-003,0.000000e+000,0,,0,
1524594692.411,,0.000000e+000,5.499905e+001,-1.588963e-006,0.000000e+000,3,7.023907e-001,0.000000e+000,,,,,,,,,,,,,,32,1,4.000000e+000,1.319885e-003,0.000000e+000,0,,0,
1524594732.243,,0.000000e+000,5.500037e+001,-5.546979e-007,0.000000e+000,2,0.000000e+000,0.000000e+000,,,,,,,,,,,,,,32,1,4.000000e+000,1.184082e-002,0.000000e+000,0,,0,
1524594772.525,,0.000000e+000,5.499577e+001,-4.559934e-007,0.000000e+000,2,0.000000e+000,0.000000e+000,,,,,,,,,,,,,,32,1,4.000000e+000,7.888794e-003,0.000000e+000,0,,0,
1524594815.921,,0.000000e+000,5.499840e+001,-5.155995e-007,0.000000e+000,2,0.000000e+000,0.000000e+000,,,,,,,,,,,,,,32,1,4.000000e+000,2.628326e-003,0.000000e+000,0,,0,
1524594855.413,,0.000000e+000,5.499708e+001,-1.540041e-006,0.000000e+000,3,7.275827e-001,0.000000e+000,,,,,,,,,,,,,,32,1,4.000000e+000,0.000000e+000,0.000000e+000,0,,0,
1524594896.677,,0.000000e+000,5.499905e+001,-1.598205e-006,0.000000e+000,3,7.338528e-001,0.000000e+000,,,,,,,,,,,,,,32,1,4.000000e+000,1.319885e-003,0.000000e+000,0,,0,
1524594935.059,,0.000000e+000,5.499511e+001,-1.525150e-006,0.000000e+000,3,7.465955e-001,0.000000e+000,,,,,,,,,,,,,,32,1,4.000000e+000,3.940582e-003,0.000000e+000,0,,0,
1524594976.823,,0.000000e+000,5.499380e+001,-5.091431e-007,0.000000e+000,2,0.000000e+000,0.000000e+000,,,,,,,,,,,,,,32,1,4.000000e+000,3.948212e-003,0.000000e+000,0,,0,
1524595019.469,,0.000000e+000,5.499709e+001,-5.577195e-007,0.000000e+000,2,0.000000e+000,0.000000e+000,,,,,,,,,,,,,,32,1,4.000000e+000,7.888794e-003,0.000000e+000,0,,0,
1524595061.043,,0.000000e+000,5.499840e+001,-4.944185e-007,0.000000e+000,2,0.000000e+000,0.000000e+000,,,,,,,,,,,,,,32,1,4.000000e+000,2.628326e-003,0.000000e+000,0,,0,
1524595098.503,,0.000000e+000,5.499972e+001,-1.555746e-006,0.000000e+000,3,7.253540e-001,0.000000e+000,,,,,,,,,,,,,,32,1,4.000000e+000,7.900238e-003,0.000000e+000,0,,0,
1524595140.107,,0.000000e+000,5.499643e+001,-1.679334e-006,0.000000e+000,3,7.608814e-001,0.000000e+000,,,,,,,,,,,,,,32,1,4.000000e+000,1.448059e-002,0.000000e+000,0,,0,
1524595181.431,,0.000000e+000,5.499577e+001,-5.484310e-007,0.000000e+000,2,0.000000e+000,0.000000e+000,,,,,,,,,,,,,,32,1,4.000000e+000,2.632141e-003,0.000000e+000,0,,0,
1524595220.303,,0.000000e+000,5.499642e+001,-1.600629e-006,0.000000e+000,3,7.341759e-001,0.000000e+000,,,,,,,,,,,,,,32,1,4.000000e+000,3.940582e-003,0.000000e+000,0,,0,
1524595261.697,,0.000000e+000,5.500959e+001,-5.026943e-007,0.000000e+000,2,0.000000e+000,0.000000e+000,,,,,,,,,,,,,,32,1,4.000000e+000,1.184082e-002,0.000000e+000,0,,0,
1524595301.710,,0.000000e+000,5.499314e+001,-4.811897e-007,0.000000e+000,2,0.000000e+000,0.000000e+000,,,,,,,,,,,,,,32,1,4.000000e+000,5.260468e-003,0.000000e+000,0,,0,
1524595343.204,,0.000000e+000,5.500037e+001,-5.250006e-007,0.000000e+000,2,0.000000e+000,0.000000e+000,,,,,,,,,,,,,,32,1,4.000000e+000,1.446915e-002,0.000000e+000,0,,0,
1524595383.006,,0.000000e+000,5.499905e+001,-5.133389e-007,0.000000e+000,2,0.000000e+000,0.000000e+000,,,,,,,,,,,,,,32,1,4.000000e+000,1.319885e-003,0.000000e+000,0,,0,
1524595424.390,,0.000000e+000,5.499511e+001,-1.667321e-006,0.000000e+000,3,7.192163e-001,0.000000e+000,,,,,,,,,,,,,,32,1,4.000000e+000,3.940582e-003,0.000000e+000,0,,0,
1524595466.926,,0.000000e+000,5.499314e+001,-5.540119e-007,0.000000e+000,2,0.000000e+000,0.000000e+000,,,,,,,,,,,,,,32,1,4.000000e+000,0.000000e+000,0.000000e+000,0,,0,
1524595504.576,,0.000000e+000,5.499775e+001,-1.514027e-006,0.000000e+000,3,6.826702e-001,0.000000e+000,,,,,,,,,,,,,,32,1,4.000000e+000,9.208679e-003,0.000000e+000,0,,0,
1524595544.118,,0.000000e+000,5.499774e+001,-1.559666e-006,0.000000e+000,3,6.906387e-001,0.000000e+000,,,,,,,,,,,,,,32,1,4.000000e+000,3.940582e-003,0.000000e+000,0,,0,
1524595584.430,,0.000000e+000,5.499380e+001,-4.859708e-007,0.000000e+000,2,0.000000e+000,0.000000e+000,,,,,,,,,,,,,,32,1,4.000000e+000,3.948212e-003,0.000000e+000,0,,0,
1524595624.834,,0.000000e+000,5.499972e+001,-5.514182e-007,0.000000e+000,2,0.000000e+000,0.000000e+000,,,,,,,,,,,,,,32,1,4.000000e+000,5.268097e-003,0.000000e+000,0,,0,
1524595664.536,,0.000000e+000,5.499841e+001,-4.908210e-007,0.000000e+000,2,0.000000e+000,0.000000e+000,,,,,,,,,,,,,,32,1,4.000000e+000,1.052856e-002,0.000000e+000,0,,0,
1524595705.080,,0.000000e+000,5.499445e+001,-4.671382e-007,0.000000e+000,2,0.000000e+000,0.000000e+000,,,,,,,,,,,,,,32,1,4.000000e+000,5.260468e-003,0.000000e+000,0,,0,
1524595742.370,,0.000000e+000,5.499840e+001,-1.427837e-006,0.000000e+000,3,3.728672e-001,0.000000e+000,,,,,,,,,,,,,,32,1,4.000000e+000,2.628326e-003,0.000000e+000,0,,0,
1524595784.204,,0.000000e+000,5.500169e+001,-5.983270e-007,0.000000e+000,2,0.000000e+000,0.000000e+000,,,,,,,,,,,,,,32,1,4.000000e+000,1.319885e-003,0.000000e+000,0,,0,
1524595823.516,,0.000000e+000,5.500431e+001,-4.302369e-007,0.000000e+000,2,0.000000e+000,0.000000e+000,,,,,,,,,,,,,,32,1,4.000000e+000,9.208679e-003,0.000000e+000,0,,0,
1524595863.168,,0.000000e+000,5.499313e+001,-1.646851e-006,0.000000e+000,3,6.718200e-001,0.000000e+000,,,,,,,,,,,,,,32,1,4.000000e+000,7.892609e-003,0.000000e+000,0,,0,
1524595904.652,,0.000000e+000,5.500037e+001,-1.775707e-006,0.000000e+000,3,7.703836e-001,0.000000e+000,,,,,,,,,,,,,,32,1,4.000000e+000,9.201050e-003,0.000000e+000,0,,0,
1524595945.426,,0.000000e+000,5.500629e+001,-1.588900e-006,0.000000e+000,3,7.419547e-001,0.000000e+000,,,,,,,,,,,,,,32,1,4.000000e+000,2.639771e-003,0.000000e+000,0,,0,
1524595986.460,,0.000000e+000,5.499379e+001,-5.694826e-007,0.000000e+000,2,0.000000e+000,0.000000e+000,,,,,,,,,,,,,,32,1,4.000000e+000,9.201050e-003,0.000000e+000,0,,0,
1524596051.513,,0.000000e+000,5.499511e+001,-4.947590e-007,0.000000e+000,2,0.000000e+000,0.000000e+000,,,,,,,,,,,,,,32,1,4.000000e+000,3.940582e-003,0.000000e+000,0,,0,
1524596091.867,,0.000000e+000,5.499577e+001,-5.835839e-007,0.000000e+000,2,0.000000e+000,0.000000e+000,,,,,,,,,,,,,,32,1,4.000000e+000,5.249023e-003,0.000000e+000,0,,0,
1524596130.557,,0.000000e+000,5.499511e+001,-1.460677e-006,0.000000e+000,3,7.380309e-001,0.000000e+000,,,,,,,,,,,,,,32,1,4.000000e+000,6.568909e-003,0.000000e+000,0,,0,
1524596172.091,,0.000000e+000,5.499905e+001,-4.977854e-007,0.000000e+000,2,0.000000e+000,0.000000e+000,,,,,,,,,,,,,,32,1,4.000000e+000,1.182938e-002,0.000000e+000,0,,0,
1524596214.237,,0.000000e+000,5.500564e+001,-5.533896e-007,0.000000e+000,2,0.000000e+000,0.000000e+000,,,,,,,,,,,,,,32,1,4.000000e+000,1.710892e-002,0.000000e+000,0,,0,
1524596254.239,,0.000000e+000,5.500037e+001,-5.493889e-007,0.000000e+000,2,0.000000e+000,0.000000e+000,,,,,,,,,,,,,,32,1,4.000000e+000,1.319885e-003,0.000000e+000,0,,0,
1524596292.661,,0.000000e+000,5.499840e+001,-1.682493e-006,0.000000e+000,3,7.705259e-001,0.000000e+000,,,,,,,,,,,,,,32,1,4.000000e+000,2.628326e-003,0.000000e+000,0,,0,
1524596334.085,,0.000000e+000,5.499906e+001,-1.739810e-006,0.000000e+000,3,7.238154e-001,0.000000e+000,,,,,,,,,,,,,,32,1,4.000000e+000,9.220123e-003,0.000000e+000,0,,0,
1524596372.155,,0.000000e+000,5.499708e+001,-1.609976e-006,0.000000e+000,3,7.798183e-001,0.000000e+000,,,,,,,,,,,,,,32,1,4.000000e+000,2.620697e-003,0.000000e+000,0,,0,
1524596411.567,,0.000000e+000,5.499642e+001,-1.493871e-006,0.000000e+000,3,7.381710e-001,0.000000e+000,,,,,,,,,,,,,,32,1,4.000000e+000,3.940582e-003,0.000000e+000,0,,0,
1524596455.243,,0.000000e+000,5.500037e+001,-5.121958e-007,0.000000e+000,2,0.000000e+000,0.000000e+000,,,,,,,,,,,,,,32,1,4.000000e+000,9.201050e-003,0.000000e+000,0,,0,
1524596494.755,,0.000000e+000,5.499248e+001,-1.510217e-006,0.000000e+000,3,6.970144e-001,0.000000e+000,,,,,,,,,,,,,,32,1,4.000000e+000,3.940582e-003,0.000000e+000,0,,0,
1524596536.219,,0.000000e+000,5.498788e+001,-5.394026e-007,0.000000e+000,2,0.000000e+000,0.000000e+000,,,,,,,,,,,,,,32,1,4.000000e+000,2.628326e-003,0.000000e+000,0,,0,
1524596578.425,,0.000000e+000,5.499774e+001,-5.435339e-007,0.000000e+000,2,0.000000e+000,0.000000e+000,,,,,,,,,,,,,,32,1,4.000000e+000,6.580353e-003,0.000000e+000,0,,0,
1524596617.777,,0.000000e+000,5.499773e+001,-5.312468e-007,0.000000e+000,2,0.000000e+000,0.000000e+000,,,,,,,,,,,,,,32,1,4.000000e+000,1.308441e-003,0.000000e+000,0,,0,
1524596657.139,,0.000000e+000,5.500367e+001,-5.623900e-007,0.000000e+000,2,0.000000e+000,0.000000e+000,,,,,,,,,,,,,,32,1,4.000000e+000,0.000000e+000,0.000000e+000,0,,0,
1524596694.299,,0.000000e+000,5.499905e+001,-1.699079e-006,0.000000e+000,3,7.442978e-001,0.000000e+000,,,,,,,,,,,,,,32,1,4.000000e+000,3.948212e-003,0.000000e+000,0,,0,
1524596735.544,,0.000000e+000,5.499708e+001,-5.439495e-007,0.000000e+000,2,0.000000e+000,0.000000e+000,,,,,,,,,,,,,,32,1,4.000000e+000,2.620697e-003,0.000000e+000,0,,0,
1524596774.676,,0.000000e+000,5.499840e+001,-1.467482e-006,0.000000e+000,3,7.231243e-001,0.000000e+000,,,,,,,,,,,,,,32,1,4.000000e+000,2.628326e-003,0.000000e+000,0,,0,
1524596814.108,,0.000000e+000,5.500103e+001,-5.607745e-007,0.000000e+000,2,0.000000e+000,0.000000e+000,,,,,,,,,,,,,,32,1,4.000000e+000,0.000000e+000,0.000000e+000,0,,0,
1524596851.348,,0.000000e+000,5.500037e+001,-1.585971e-006,0.000000e+000,3,7.146288e-001,0.000000e+000,,,,,,,,,,,,,,32,1,4.000000e+000,1.319885e-003,0.000000e+000,0,,0,
1524596890.090,,0.000000e+000,5.499445e+001,-1.534883e-006,0.000000e+000,3,7.500779e-001,0.000000e+000,,,,,,,,,,,,,,32,1,4.000000e+000,7.881165e-003,0.000000e+000,0,,0,
1524596929.902,,0.000000e+000,5.499972e+001,-1.561422e-006,0.000000e+000,3,7.356348e-001,0.000000e+000,,,,,,,,,,,,,,32,1,4.000000e+000,7.900238e-003,0.000000e+000,0,,0,
1524596971.206,,0.000000e+000,5.499577e+001,-5.619285e-007,0.000000e+000,2,0.000000e+000,0.000000e+000,,,,,,,,,,,,,,32,1,4.000000e+000,0.000000e+000,0.000000e+000,0,,0,
1524597010.828,,0.000000e+000,5.500432e+001,-5.587515e-007,0.000000e+000,2,0.000000e+000,0.000000e+000,,,,,,,,,,,,,,32,1,4.000000e+000,1.446915e-002,0.000000e+000,0,,0,
1524597050.200,,0.000000e+000,5.499051e+001,-5.593508e-007,0.000000e+000,2,0.000000e+000,0.000000e+000,,,,,,,,,,,,,,32,1,4.000000e+000,5.260468e-003,0.000000e+000,0,,0,
1524597089.352,,0.000000e+000,5.499905e+001,-5.621811e-007,0.000000e+000,2,0.000000e+000,0.000000e+000,,,,,,,,,,,,,,32,1,4.000000e+000,1.319885e-003,0.000000e+000,0,,0,
1524597129.134,,0.000000e+000,5.500235e+001,-5.512177e-007,0.000000e+000,2,0.000000e+000,0.000000e+000,,,,,,,,,,,,,,32,1,4.000000e+000,2.639771e-003,0.000000e+000,0,,0,
1524597168.386,,0.000000e+000,5.499709e+001,-5.582843e-007,0.000000e+000,2,0.000000e+000,0.000000e+000,,,,,,,,,,,,,,32,1,4.000000e+000,7.888794e-003,0.000000e+000,0,,0,
1524597205.436,,0.000000e+000,5.499117e+001,-1.658981e-006,0.000000e+000,3,7.580874e-001,0.000000e+000,,,,,,,,,,,,,,32,1,4.000000e+000,3.952026e-003,0.000000e+000,0,,0,
1524597244.788,,0.000000e+000,5.499905e+001,-1.662984e-006,0.000000e+000,3,7.680321e-001,0.000000e+000,,,,,,,,,,,,,,32,1,4.000000e+000,1.182938e-002,0.000000e+000,0,,0,
1524597284.220,,0.000000e+000,5.499774e+001,-1.660136e-006,0.000000e+000,3,7.629398e-001,0.000000e+000,,,,,,,,,,,,,,32,1,4.000000e+000,6.580353e-003,0.000000e+000,0,,0,
1524597323.962,,0.000000e+000,5.499905e+001,-5.063631e-007,0.000000e+000,2,0.000000e+000,0.000000e+000,,,,,,,,,,,,,,32,1,4.000000e+000,1.319885e-003,0.000000e+000,0,,0,
1524597361.382,,0.000000e+000,5.499905e+001,-1.603029e-006,0.000000e+000,3,7.188554e-001,0.000000e+000,,,,,,,,,,,,,,32,1,4.000000e+000,1.319885e-003,0.000000e+000,0,,0,
1524597401.454,,0.000000e+000,5.499841e+001,-5.414557e-007,0.000000e+000,2,0.000000e+000,0.000000e+000,,,,,,,,,,,,,,32,1,4.000000e+000,1.052856e-002,0.000000e+000,0,,0,
1524597439.385,,0.000000e+000,5.499511e+001,-1.598726e-006,0.000000e+000,3,7.722409e-001,0.000000e+000,,,,,,,,,,,,,,32,1,4.000000e+000,3.940582e-003,0.000000e+000,0,,0,
1524597476.745,,0.000000e+000,5.499577e+001,-1.527751e-006,0.000000e+000,3,7.144194e-001,0.000000e+000,,,,,,,,,,,,,,32,1,4.000000e+000,5.249023e-003,0.000000e+000,0,,0,
1524597516.767,,0.000000e+000,5.499248e+001,-5.738382e-007,0.000000e+000,2,0.000000e+000,0.000000e+000,,,,,,,,,,,,,,32,1,4.000000e+000,1.319885e-003,0.000000e+000,0,,0,
1524597557.111,,0.000000e+000,5.500563e+001,-5.787326e-007,0.000000e+000,2,0.000000e+000,0.000000e+000,,,,,,,,,,,,,,32,1,4.000000e+000,6.568909e-003,0.000000e+000,0,,0,
1524597595.873,,0.000000e+000,5.499905e+001,-5.405824e-007,0.000000e+000,2,0.000000e+000,0.000000e+000,,,,,,,,,,,,,,32,1,4.000000e+000,1.319885e-003,0.000000e+000,0,,0,
1524597635.707,,0.000000e+000,5.499905e+001,-6.123574e-007,0.000000e+000,2,0.000000e+000,0.000000e+000,,,,,,,,,,,,,,32,1,4.000000e+000,3.948212e-003,0.000000e+000,0,,0,
1524597673.627,,0.000000e+000,5.499971e+001,-1.703614e-006,0.000000e+000,3,7.722552e-001,0.000000e+000,,,,,,,,,,,,,,32,1,4.000000e+000,2.639771e-003,0.000000e+000,0,,0,
1524597710.967,,0.000000e+000,5.499643e+001,-1.546812e-006,0.000000e+000,3,7.483197e-001,0.000000e+000,,,,,,,,,,,,,,32,1,4.000000e+000,1.312256e-003,0.000000e+000,0,,0,
1524597749.829,,0.000000e+000,5.500235e+001,-1.663076e-006,0.000000e+000,3,7.389501e-001,0.000000e+000,,,,,,,,,,,,,,32,1,4.000000e+000,1.052856e-002,0.000000e+000,0,,0,
1524597791.793,,0.000000e+000,5.499839e+001,-5.242752e-007,0.000000e+000,2,0.000000e+000,0.000000e+000,,,,,,,,,,,,,,32,1,4.000000e+000,0.000000e+000,0.000000e+000,0,,0,
1524597829.143,,0.000000e+000,5.499642e+001,-1.651421e-006,0.000000e+000,3,7.200847e-001,0.000000e+000,,,,,,,,,,,,,,32,1,4.000000e+000,3.940582e-003,0.000000e+000,0,,0,
1524597868.265,,0.000000e+000,5.499577e+001,-1.645396e-006,0.000000e+000,3,7.449203e-001,0.000000e+000,,,,,,,,,,,,,,32,1,4.000000e+000,5.249023e-003,0.000000e+000,0,,0,
1524597906.015,,0.000000e+000,5.499445e+001,-1.473505e-006,0.000000e+000,3,7.288768e-001,0.000000e+000,,,,,,,,,,,,,,32,1,4.000000e+000,1.578903e-002,0.000000e+000,0,,0,
1524597945.957,,0.000000e+000,5.499643e+001,-5.128641e-007,0.000000e+000,2,0.000000e+000,0.000000e+000,,,,,,,,,,,,,,32,1,4.000000e+000,1.312256e-003,0.000000e+000,0,,0,
1524597986.709,,0.000000e+000,5.499972e+001,-5.492443e-007,0.000000e+000,2,0.000000e+000,0.000000e+000,,,,,,,,,,,,,,32,1,4.000000e+000,7.900238e-003,0.000000e+000,0,,0,
1524598026.811,,0.000000e+000,5.499774e+001,-5.627088e-007,0.000000e+000,2,0.000000e+000,0.000000e+000,,,,,,,,,,,,,,32,1,4.000000e+000,6.580353e-003,0.000000e+000,0,,0,
1524598090.733,,0.000000e+000,5.499511e+001,-1.606948e-006,0.000000e+000,3,7.537101e-001,0.000000e+000,,,,,,,,,,,,,,32,1,4.000000e+000,6.568909e-003,0.000000e+000,0,,0,
1524598129.856,,0.000000e+000,5.499972e+001,-1.502104e-006,0.000000e+000,3,7.753317e-001,0.000000e+000,,,,,,,,,,,,,,32,1,4.000000e+000,5.268097e-003,0.000000e+000,0,,0,
1524598170.110,,0.000000e+000,5.499709e+001,-1.583752e-006,0.000000e+000,3,7.526660e-001,0.000000e+000,,,,,,,,,,,,,,32,1,4.000000e+000,1.316071e-002,0.000000e+000,0,,0,
1524598211.074,,0.000000e+000,5.499840e+001,-1.557179e-006,0.000000e+000,3,7.428226e-001,0.000000e+000,,,,,,,,,,,,,,32,1,4.000000e+000,2.628326e-003,0.000000e+000,0,,0,
1524598248.654,,0.000000e+000,5.499577e+001,-1.616266e-006,0.000000e+000,3,7.401906e-001,0.000000e+000,,,,,,,,,,,,,,32,1,4.000000e+000,0.000000e+000,0.000000e+000,0,,0,
1524598289.968,,0.000000e+000,5.500234e+001,-1.645220e-006,0.000000e+000,3,7.932646e-001,0.000000e+000,,,,,,,,,,,,,,32,1,4.000000e+000,1.578903e-002,0.000000e+000,0,,0,
1524598327.858,,0.000000e+000,5.499511e+001,-1.667593e-006,0.000000e+000,3,7.679671e-001,0.000000e+000,,,,,,,,,,,,,,32,1,4.000000e+000,6.568909e-003,0.000000e+000,0,,0,
1524598367.690,,0.000000e+000,5.499972e+001,-5.458335e-007,0.000000e+000,2,0.000000e+000,0.000000e+000,,,,,,,,,,,,,,32,1,4.000000e+000,5.268097e-003,0.000000e+000,0,,0,
1524598404.760,,0.000000e+000,5.499182e+001,-1.671738e-006,0.000000e+000,3,7.674530e-001,0.000000e+000,,,,,,,,,,,,,,32,1,4.000000e+000,1.314163e-002,0.000000e+000,0,,0,
1524598444.072,,0.000000e+000,5.499446e+001,-1.639123e-006,0.000000e+000,3,7.341220e-001,0.000000e+000,,,,,,,,,,,,,,32,1,4.000000e+000,1.842117e-002,0.000000e+000,0,,0,
1524598481.602,,0.000000e+000,5.499511e+001,-1.529544e-006,0.000000e+000,3,7.077327e-001,0.000000e+000,,,,,,,,,,,,,,32,1,4.000000e+000,1.319885e-003,0.000000e+000,0,,0,
1524598520.494,,0.000000e+000,5.499709e+001,-1.563621e-006,0.000000e+000,3,6.883205e-001,0.000000e+000,,,,,,,,,,,,,,32,1,4.000000e+000,1.052856e-002,0.000000e+000,0,,0,
1524598560.286,,0.000000e+000,5.500234e+001,-1.741663e-006,0.000000e+000,3,7.394786e-001,0.000000e+000,,,,,,,,,,,,,,32,1,4.000000e+000,7.900238e-003,0.000000e+000,0,,0,
1524598599.628,,0.000000e+000,5.499313e+001,-1.689602e-006,0.000000e+000,3,7.652686e-001,0.000000e+000,,,,,,,,,,,,,,32,1,4.000000e+000,2.628326e-003,0.000000e+000,0,,0,
1524598614.170,,0.000000e+000,5.499971e+001,-5.764958e-007,0.000000e+000,2,0.000000e+000,0.000000e+000,,,,,,,,,,,,,,32,1,4.000000e+000,0.000000e+000,0.000000e+000,0,,0,