File: Experimental Raw Data/TC04-12-01K TRMac VRMde/Ndat/TC04-12-01K_TRMac_56K_0.06Kmin_VRMde_55K.dc.dat
[Header]
TITLE,MPMS DC Measurement
BYAPP,MPMS Measurement,2.1,Summary
FILEOPENTIME, 1524673686.719000 4/25/2018, 10:28:06 AM

INFO, APPNAME, MPMS MultiVu Application, Revision 1.61,  Build 082

INFO, NAME, TC04-12-01K
INFO, WEIGHT, 1.000
INFO, AREA, 1.000
INFO, LENGTH, 1.000
INFO, SHAPE, 0
INFO, COMMENT,
INFO, SEQUENCE FILE: TRMac_56K_0.06Kmin_VRMde_55K.seq


INFO, BACKGROUND DATA FILE:, None


STARTUPAXIS,X,4,LINEAR,AUTO,0.000000,0.000000
STARTUPAXIS,Y1,5,LINEAR,AUTO,0.000000,0.000000


STARTUPGROUP,Longitudinal
FIELDGROUP,Longitudinal,1,2,3,4,5,6,7,8,9,15,16,17,18,27,28
FIELDGROUP,Transverse,1,2,3,4,10,11,12,13,14,19,20,21,22,27,28

PLOT_APPEARANCE,ALL,HORZ_GRID_ON,VERT_GRID_ON,MARKERS_AND_LINES

[Data]
Time,Comment,Field (Oe),Temperature (K),Long Moment (emu),Long Scan Std Dev,Long Algorithm,Long Reg Fit,Long Percent Error (%),Trans Moment (emu),Trans Scan Std Dev,Trans Algorithm,Trans Reg Fit,Trans Percent Error (%),Long Moment [w/o ABS] (emu),Long Scan Std Dev [w/o ABS],Long Reg Fit [w/o ABS],Long Percent Error [w/o ABS] (%),Trans Moment [w/o ABS] (emu),Trans Scan Std Dev [w/o ABS],Trans Reg Fit [w/o ABS],Trans Percent Error [w/o ABS] (%),Points per Scan,Scans per Measurement,Scan Length (cm),Delta Temp (K),Rot Position (deg),Error,EC Comp. Running,Using ABS,
1524673686.719,,0.000000e+000,5.499577e+001,5.944658e-006,0.000000e+000,3,7.892975e-001,0.000000e+000,,,,,,,,,,,,,,32,1,4.000000e+000,1.578903e-002,0.000000e+000,0,,0,
1524673712.059,,0.000000e+000,5.499643e+001,4.451541e-006,0.000000e+000,3,7.510706e-001,0.000000e+000,,,,,,,,,,,,,,32,1,4.000000e+000,1.312256e-003,0.000000e+000,0,,0,
1524673737.199,,0.000000e+000,5.499905e+001,3.713004e-006,0.000000e+000,3,7.399458e-001,0.000000e+000,,,,,,,,,,,,,,32,1,4.000000e+000,1.319885e-003,0.000000e+000,0,,0,
1524673761.879,,0.000000e+000,5.499380e+001,3.159361e-006,0.000000e+000,3,7.283615e-001,0.000000e+000,,,,,,,,,,,,,,32,1,4.000000e+000,1.308441e-003,0.000000e+000,0,,0,
1524673786.689,,0.000000e+000,5.499511e+001,2.758640e-006,0.000000e+000,3,7.185616e-001,0.000000e+000,,,,,,,,,,,,,,32,1,4.000000e+000,3.940582e-003,0.000000e+000,0,,0,
1524673811.770,,0.000000e+000,5.499051e+001,2.487438e-006,0.000000e+000,3,6.934558e-001,0.000000e+000,,,,,,,,,,,,,,32,1,4.000000e+000,7.888794e-003,0.000000e+000,0,,0,
1524673837.180,,0.000000e+000,5.499972e+001,2.324944e-006,0.000000e+000,3,7.100927e-001,0.000000e+000,,,,,,,,,,,,,,32,1,4.000000e+000,7.900238e-003,0.000000e+000,0,,0,
1524673862.730,,0.000000e+000,5.499708e+001,2.062087e-006,0.000000e+000,3,6.393687e-001,0.000000e+000,,,,,,,,,,,,,,32,1,4.000000e+000,2.620697e-003,0.000000e+000,0,,0,
1524673888.540,,0.000000e+000,5.500235e+001,1.812168e-006,0.000000e+000,3,6.164876e-001,0.000000e+000,,,,,,,,,,,,,,32,1,4.000000e+000,2.639771e-003,0.000000e+000,0,,0,
1524673913.750,,0.000000e+000,5.499840e+001,1.627638e-006,0.000000e+000,3,5.558146e-001,0.000000e+000,,,,,,,,,,,,,,32,1,4.000000e+000,2.628326e-003,0.000000e+000,0,,0,
1524673939.150,,0.000000e+000,5.499380e+001,1.585884e-006,0.000000e+000,3,5.458149e-001,0.000000e+000,,,,,,,,,,,,,,32,1,4.000000e+000,1.308441e-003,0.000000e+000,0,,0,
1524673964.180,,0.000000e+000,5.499577e+001,1.460658e-006,0.000000e+000,3,5.030328e-001,0.000000e+000,,,,,,,,,,,,,,32,1,4.000000e+000,2.632141e-003,0.000000e+000,0,,0,
1524673989.350,,0.000000e+000,5.499905e+001,1.451123e-006,0.000000e+000,3,4.995048e-001,0.000000e+000,,,,,,,,,,,,,,32,1,4.000000e+000,1.319885e-003,0.000000e+000,0,,0,
1524674014.550,,0.000000e+000,5.499380e+001,1.376734e-006,0.000000e+000,3,4.754111e-001,0.000000e+000,,,,,,,,,,,,,,32,1,4.000000e+000,3.948212e-003,0.000000e+000,0,,0,
1524674039.270,,0.000000e+000,5.499708e+001,1.287680e-006,0.000000e+000,3,4.097529e-001,0.000000e+000,,,,,,,,,,,,,,32,1,4.000000e+000,5.260468e-003,0.000000e+000,0,,0,
1524674064.950,,0.000000e+000,5.499972e+001,1.251451e-006,0.000000e+000,3,4.029372e-001,0.000000e+000,,,,,,,,,,,,,,32,1,4.000000e+000,7.900238e-003,0.000000e+000,0,,0,
1524674090.150,,0.000000e+000,5.499577e+001,1.238929e-006,0.000000e+000,3,4.068762e-001,0.000000e+000,,,,,,,,,,,,,,32,1,4.000000e+000,2.632141e-003,0.000000e+000,0,,0,
1524674114.860,,0.000000e+000,5.499708e+001,1.088044e-006,0.000000e+000,3,3.275179e-001,0.000000e+000,,,,,,,,,,,,,,32,1,4.000000e+000,2.620697e-003,0.000000e+000,0,,0,
1524674140.560,,0.000000e+000,5.500234e+001,1.185676e-006,0.000000e+000,3,3.695681e-001,0.000000e+000,,,,,,,,,,,,,,32,1,4.000000e+000,5.260468e-003,0.000000e+000,0,,0,
1524674165.750,,0.000000e+000,5.499972e+001,1.066023e-006,0.000000e+000,3,2.337013e-001,0.000000e+000,,,,,,,,,,,,,,32,1,4.000000e+000,5.268097e-003,0.000000e+000,0,,0,
1524674192.490,,0.000000e+000,5.499708e+001,3.211370e-007,0.000000e+000,2,0.000000e+000,0.000000e+000,,,,,,,,,,,,,,32,1,4.000000e+000,2.620697e-003,0.000000e+000,0,,0,
1524674219.062,,0.000000e+000,5.499643e+001,3.067015e-007,0.000000e+000,2,0.000000e+000,0.000000e+000,,,,,,,,,,,,,,32,1,4.000000e+000,1.312256e-003,0.000000e+000,0,,0,
1524674246.666,,0.000000e+000,5.499445e+001,2.397009e-007,0.000000e+000,2,0.000000e+000,0.000000e+000,,,,,,,,,,,,,,32,1,4.000000e+000,5.260468e-003,0.000000e+000,0,,0,
1524674273.408,,0.000000e+000,5.499906e+001,1.771101e-007,0.000000e+000,2,0.000000e+000,0.000000e+000,,,,,,,,,,,,,,32,1,4.000000e+000,6.580353e-003,0.000000e+000,0,,0,
1524674300.070,,0.000000e+000,5.499774e+001,1.621762e-007,0.000000e+000,2,0.000000e+000,0.000000e+000,,,,,,,,,,,,,,32,1,4.000000e+000,3.940582e-003,0.000000e+000,0,,0,
1524674325.180,,0.000000e+000,5.500301e+001,-1.552598e-006,0.000000e+000,3,8.108392e-001,0.000000e+000,,,,,,,,,,,,,,32,1,4.000000e+000,1.319885e-003,0.000000e+000,0,,0,
1524674352.092,,0.000000e+000,5.499511e+001,5.474556e-008,0.000000e+000,2,0.000000e+000,0.000000e+000,,,,,,,,,,,,,,32,1,4.000000e+000,1.319885e-003,0.000000e+000,0,,0,
1524674376.512,,0.000000e+000,5.499971e+001,-1.628809e-006,0.000000e+000,3,8.131439e-001,0.000000e+000,,,,,,,,,,,,,,32,1,4.000000e+000,2.639771e-003,0.000000e+000,0,,0,
1524674401.772,,0.000000e+000,5.499906e+001,-1.552778e-006,0.000000e+000,3,8.257987e-001,0.000000e+000,,,,,,,,,,,,,,32,1,4.000000e+000,6.580353e-003,0.000000e+000,0,,0,
1524674426.392,,0.000000e+000,5.499708e+001,-1.564850e-006,0.000000e+000,3,7.923233e-001,0.000000e+000,,,,,,,,,,,,,,32,1,4.000000e+000,2.620697e-003,0.000000e+000,0,,0,
1524674451.382,,0.000000e+000,5.499643e+001,-1.550294e-006,0.000000e+000,3,8.129632e-001,0.000000e+000,,,,,,,,,,,,,,32,1,4.000000e+000,6.568909e-003,0.000000e+000,0,,0,
1524674476.242,,0.000000e+000,5.500103e+001,1.222545e-007,0.000000e+000,3,0.000000e+000,0.000000e+000,,,,,,,,,,,,,,32,1,4.000000e+000,5.279541e-003,0.000000e+000,0,,0,
1524674501.422,,0.000000e+000,5.500169e+001,-1.654180e-006,0.000000e+000,3,8.117265e-001,0.000000e+000,,,,,,,,,,,,,,32,1,4.000000e+000,9.208679e-003,0.000000e+000,0,,0,
1524674528.015,,0.000000e+000,5.499511e+001,1.076816e-006,0.000000e+000,3,1.636827e-001,0.000000e+000,,,,,,,,,,,,,,32,1,4.000000e+000,3.940582e-003,0.000000e+000,0,,0,
1524674553.945,,0.000000e+000,5.499643e+001,8.704234e-007,0.000000e+000,3,2.991042e-002,0.000000e+000,,,,,,,,,,,,,,32,1,4.000000e+000,1.312256e-003,0.000000e+000,0,,0,
1524674579.135,,0.000000e+000,5.499445e+001,8.763245e-007,0.000000e+000,3,1.740629e-002,0.000000e+000,,,,,,,,,,,,,,32,1,4.000000e+000,0.000000e+000,0.000000e+000,0,,0,
1524674604.045,,0.000000e+000,5.499511e+001,9.648102e-007,0.000000e+000,3,1.004012e-001,0.000000e+000,,,,,,,,,,,,,,32,1,4.000000e+000,3.940582e-003,0.000000e+000,0,,0,
1524674628.805,,0.000000e+000,5.499313e+001,9.474552e-007,0.000000e+000,3,7.739294e-002,0.000000e+000,,,,,,,,,,,,,,32,1,4.000000e+000,2.628326e-003,0.000000e+000,0,,0,
1524674653.695,,0.000000e+000,5.499905e+001,9.106412e-007,0.000000e+000,3,8.588724e-002,0.000000e+000,,,,,,,,,,,,,,32,1,4.000000e+000,1.319885e-003,0.000000e+000,0,,0,
1524674682.179,,0.000000e+000,5.499971e+001,-2.444233e-007,0.000000e+000,2,0.000000e+000,0.000000e+000,,,,,,,,,,,,,,32,1,4.000000e+000,0.000000e+000,0.000000e+000,0,,0,
1524674709.261,,0.000000e+000,5.499445e+001,-2.808913e-007,0.000000e+000,2,0.000000e+000,0.000000e+000,,,,,,,,,,,,,,32,1,4.000000e+000,0.000000e+000,0.000000e+000,0,,0,
1524674737.945,,0.000000e+000,5.499971e+001,-3.281753e-007,0.000000e+000,2,0.000000e+000,0.000000e+000,,,,,,,,,,,,,,32,1,4.000000e+000,2.639771e-003,0.000000e+000,0,,0,
1524674766.759,,0.000000e+000,5.500169e+001,-2.999681e-007,0.000000e+000,2,0.000000e+000,0.000000e+000,,,,,,,,,,,,,,32,1,4.000000e+000,1.319885e-003,0.000000e+000,0,,0,
1524674795.073,,0.000000e+000,5.499182e+001,-3.354379e-007,0.000000e+000,2,0.000000e+000,0.000000e+000,,,,,,,,,,,,,,32,1,4.000000e+000,5.260468e-003,0.000000e+000,0,,0,
1524674823.207,,0.000000e+000,5.499708e+001,-3.534364e-007,0.000000e+000,2,0.000000e+000,0.000000e+000,,,,,,,,,,,,,,32,1,4.000000e+000,2.620697e-003,0.000000e+000,0,,0,
1524674851.561,,0.000000e+000,5.499972e+001,-3.759975e-007,0.000000e+000,2,0.000000e+000,0.000000e+000,,,,,,,,,,,,,,32,1,4.000000e+000,5.268097e-003,0.000000e+000,0,,0,
1524674879.445,,0.000000e+000,5.499840e+001,-3.404482e-007,0.000000e+000,2,0.000000e+000,0.000000e+000,,,,,,,,,,,,,,32,1,4.000000e+000,5.260468e-003,0.000000e+000,0,,0,
1524674907.879,,0.000000e+000,5.499841e+001,-3.924255e-007,0.000000e+000,2,0.000000e+000,0.000000e+000,,,,,,,,,,,,,,32,1,4.000000e+000,1.052856e-002,0.000000e+000,0,,0,
1524674936.363,,0.000000e+000,5.499380e+001,-4.266095e-007,0.000000e+000,2,0.000000e+000,0.000000e+000,,,,,,,,,,,,,,32,1,4.000000e+000,1.308441e-003,0.000000e+000,0,,0,
1524674964.197,,0.000000e+000,5.499182e+001,-3.701546e-007,0.000000e+000,2,0.000000e+000,0.000000e+000,,,,,,,,,,,,,,32,1,4.000000e+000,1.578140e-002,0.000000e+000,0,,0,
1524674992.251,,0.000000e+000,5.499379e+001,-3.993315e-007,0.000000e+000,2,0.000000e+000,0.000000e+000,,,,,,,,,,,,,,32,1,4.000000e+000,9.201050e-003,0.000000e+000,0,,0,
1524675021.275,,0.000000e+000,5.499577e+001,-4.221674e-007,0.000000e+000,2,0.000000e+000,0.000000e+000,,,,,,,,,,,,,,32,1,4.000000e+000,5.249023e-003,0.000000e+000,0,,0,
1524675049.919,,0.000000e+000,5.499445e+001,-4.298321e-007,0.000000e+000,2,0.000000e+000,0.000000e+000,,,,,,,,,,,,,,32,1,4.000000e+000,0.000000e+000,0.000000e+000,0,,0,
1524675077.903,,0.000000e+000,5.499709e+001,-4.207220e-007,0.000000e+000,2,0.000000e+000,0.000000e+000,,,,,,,,,,,,,,32,1,4.000000e+000,7.888794e-003,0.000000e+000,0,,0,
1524675106.077,,0.000000e+000,5.499774e+001,-3.993804e-007,0.000000e+000,2,0.000000e+000,0.000000e+000,,,,,,,,,,,,,,32,1,4.000000e+000,3.940582e-003,0.000000e+000,0,,0,
1524675134.721,,0.000000e+000,5.500301e+001,-4.038655e-007,0.000000e+000,2,0.000000e+000,0.000000e+000,,,,,,,,,,,,,,32,1,4.000000e+000,1.972961e-002,0.000000e+000,0,,0,
1524675162.875,,0.000000e+000,5.499380e+001,-5.007282e-007,0.000000e+000,2,0.000000e+000,0.000000e+000,,,,,,,,,,,,,,32,1,4.000000e+000,1.308441e-003,0.000000e+000,0,,0,
1524675190.879,,0.000000e+000,5.499773e+001,-4.646682e-007,0.000000e+000,2,0.000000e+000,0.000000e+000,,,,,,,,,,,,,,32,1,4.000000e+000,1.308441e-003,0.000000e+000,0,,0,
1524675217.651,,0.000000e+000,5.500103e+001,-4.585995e-007,0.000000e+000,2,0.000000e+000,0.000000e+000,,,,,,,,,,,,,,32,1,4.000000e+000,5.279541e-003,0.000000e+000,0,,0,
1524675243.874,,0.000000e+000,5.499708e+001,-1.559892e-006,0.000000e+000,3,7.391790e-001,0.000000e+000,,,,,,,,,,,,,,32,1,4.000000e+000,2.620697e-003,0.000000e+000,0,,0,
1524675270.406,,0.000000e+000,5.500037e+001,-1.437862e-006,0.000000e+000,3,7.265910e-001,0.000000e+000,,,,,,,,,,,,,,32,1,4.000000e+000,9.201050e-003,0.000000e+000,0,,0,
1524675299.240,,0.000000e+000,5.499773e+001,-4.936020e-007,0.000000e+000,2,0.000000e+000,0.000000e+000,,,,,,,,,,,,,,32,1,4.000000e+000,1.308441e-003,0.000000e+000,0,,0,
1524675326.182,,0.000000e+000,5.499708e+001,-4.859841e-007,0.000000e+000,2,0.000000e+000,0.000000e+000,,,,,,,,,,,,,,32,1,4.000000e+000,5.260468e-003,0.000000e+000,0,,0,
1524675352.554,,0.000000e+000,5.499577e+001,-1.568179e-006,0.000000e+000,3,7.487686e-001,0.000000e+000,,,,,,,,,,,,,,32,1,4.000000e+000,5.249023e-003,0.000000e+000,0,,0,
1524675381.078,,0.000000e+000,5.499708e+001,-5.608781e-007,0.000000e+000,2,0.000000e+000,0.000000e+000,,,,,,,,,,,,,,32,1,4.000000e+000,2.620697e-003,0.000000e+000,0,,0,
1524675407.880,,0.000000e+000,5.499773e+001,-1.609598e-006,0.000000e+000,3,7.356783e-001,0.000000e+000,,,,,,,,,,,,,,32,1,4.000000e+000,1.308441e-003,0.000000e+000,0,,0,
1524675434.592,,0.000000e+000,5.499577e+001,-5.003370e-007,0.000000e+000,2,0.000000e+000,0.000000e+000,,,,,,,,,,,,,,32,1,4.000000e+000,2.632141e-003,0.000000e+000,0,,0,
1524675458.972,,0.000000e+000,5.500234e+001,-1.347134e-006,0.000000e+000,3,7.145796e-001,0.000000e+000,,,,,,,,,,,,,,32,1,4.000000e+000,7.900238e-003,0.000000e+000,0,,0,
1524675485.974,,0.000000e+000,5.500037e+001,-4.956021e-007,0.000000e+000,2,0.000000e+000,0.000000e+000,,,,,,,,,,,,,,32,1,4.000000e+000,3.959656e-003,0.000000e+000,0,,0,
1524675512.086,,0.000000e+000,5.499773e+001,-1.597573e-006,0.000000e+000,3,7.446912e-001,0.000000e+000,,,,,,,,,,,,,,32,1,4.000000e+000,1.308441e-003,0.000000e+000,0,,0,
1524675539.438,,0.000000e+000,5.499643e+001,-5.200324e-007,0.000000e+000,2,0.000000e+000,0.000000e+000,,,,,,,,,,,,,,32,1,4.000000e+000,6.568909e-003,0.000000e+000,0,,0,
1524675564.048,,0.000000e+000,5.499708e+001,-1.449813e-006,0.000000e+000,3,7.309000e-001,0.000000e+000,,,,,,,,,,,,,,32,1,4.000000e+000,2.620697e-003,0.000000e+000,0,,0,
1524675591.000,,0.000000e+000,5.500037e+001,-1.528805e-006,0.000000e+000,3,7.612156e-001,0.000000e+000,,,,,,,,,,,,,,32,1,4.000000e+000,6.587982e-003,0.000000e+000,0,,0,
1524675616.190,,0.000000e+000,5.499643e+001,1.428684e-006,0.000000e+000,3,5.158666e-001,0.000000e+000,,,,,,,,,,,,,,32,1,4.000000e+000,1.184082e-002,0.000000e+000,0,,0,
1524675641.910,,0.000000e+000,5.499709e+001,-1.617481e-006,0.000000e+000,3,7.494013e-001,0.000000e+000,,,,,,,,,,,,,,32,1,4.000000e+000,1.052856e-002,0.000000e+000,0,,0,
1524675668.812,,0.000000e+000,5.499708e+001,-5.405558e-007,0.000000e+000,2,0.000000e+000,0.000000e+000,,,,,,,,,,,,,,32,1,4.000000e+000,2.620697e-003,0.000000e+000,0,,0,
1524675694.072,,0.000000e+000,5.499905e+001,-1.281070e-006,0.000000e+000,3,7.216678e-001,0.000000e+000,,,,,,,,,,,,,,32,1,4.000000e+000,3.948212e-003,0.000000e+000,0,,0,
1524675719.162,,0.000000e+000,5.500037e+001,-1.363203e-006,0.000000e+000,3,7.276524e-001,0.000000e+000,,,,,,,,,,,,,,32,1,4.000000e+000,1.319885e-003,0.000000e+000,0,,0,
1524675744.702,,0.000000e+000,5.499511e+001,-1.564129e-006,0.000000e+000,3,7.236637e-001,0.000000e+000,,,,,,,,,,,,,,32,1,4.000000e+000,1.319885e-003,0.000000e+000,0,,0,
1524675771.874,,0.000000e+000,5.499840e+001,-1.524359e-006,0.000000e+000,3,7.665026e-001,0.000000e+000,,,,,,,,,,,,,,32,1,4.000000e+000,2.628326e-003,0.000000e+000,0,,0,
1524675796.904,,0.000000e+000,5.499905e+001,-1.585088e-006,0.000000e+000,3,7.195500e-001,0.000000e+000,,,,,,,,,,,,,,32,1,4.000000e+000,3.948212e-003,0.000000e+000,0,,0,
1524675821.944,,0.000000e+000,5.499774e+001,-1.496569e-006,0.000000e+000,3,7.041510e-001,0.000000e+000,,,,,,,,,,,,,,32,1,4.000000e+000,6.580353e-003,0.000000e+000,0,,0,
1524675847.234,,0.000000e+000,5.499839e+001,-1.458319e-006,0.000000e+000,3,6.823245e-001,0.000000e+000,,,,,,,,,,,,,,32,1,4.000000e+000,0.000000e+000,0.000000e+000,0,,0,
1524675872.334,,0.000000e+000,5.499380e+001,-1.376374e-006,0.000000e+000,3,7.220318e-001,0.000000e+000,,,,,,,,,,,,,,32,1,4.000000e+000,3.948212e-003,0.000000e+000,0,,0,
1524675898.024,,0.000000e+000,5.500037e+001,-1.414266e-006,0.000000e+000,3,7.226439e-001,0.000000e+000,,,,,,,,,,,,,,32,1,4.000000e+000,9.201050e-003,0.000000e+000,0,,0,
1524675922.934,,0.000000e+000,5.499445e+001,-1.401537e-006,0.000000e+000,3,7.191754e-001,0.000000e+000,,,,,,,,,,,,,,32,1,4.000000e+000,5.260468e-003,0.000000e+000,0,,0,
1524675947.655,,0.000000e+000,5.500037e+001,-1.464651e-006,0.000000e+000,3,7.496907e-001,0.000000e+000,,,,,,,,,,,,,,32,1,4.000000e+000,6.587982e-003,0.000000e+000,0,,0,
1524675972.325,,0.000000e+000,5.499905e+001,-1.442627e-006,0.000000e+000,3,7.317231e-001,0.000000e+000,,,,,,,,,,,,,,32,1,4.000000e+000,1.446915e-002,0.000000e+000,0,,0,
1524676022.435,,0.000000e+000,5.499840e+001,-1.467699e-006,0.000000e+000,3,7.032741e-001,0.000000e+000,,,,,,,,,,,,,,32,1,4.000000e+000,1.314926e-002,0.000000e+000,0,,0,
1524676047.915,,0.000000e+000,5.499709e+001,-1.468480e-006,0.000000e+000,3,7.351064e-001,0.000000e+000,,,,,,,,,,,,,,32,1,4.000000e+000,7.888794e-003,0.000000e+000,0,,0,
1524676074.145,,0.000000e+000,5.500103e+001,-1.609068e-006,0.000000e+000,3,7.360898e-001,0.000000e+000,,,,,,,,,,,,,,32,1,4.000000e+000,2.639771e-003,0.000000e+000,0,,0,
1524676099.345,,0.000000e+000,5.499708e+001,-1.559369e-006,0.000000e+000,3,7.230017e-001,0.000000e+000,,,,,,,,,,,,,,32,1,4.000000e+000,0.000000e+000,0.000000e+000,0,,0,
1524676124.155,,0.000000e+000,5.499905e+001,-1.501905e-006,0.000000e+000,3,7.683145e-001,0.000000e+000,,,,,,,,,,,,,,32,1,4.000000e+000,1.319885e-003,0.000000e+000,0,,0,
1524676149.125,,0.000000e+000,5.499182e+001,-1.549067e-006,0.000000e+000,3,7.592761e-001,0.000000e+000,,,,,,,,,,,,,,32,1,4.000000e+000,1.052094e-002,0.000000e+000,0,,0,
1524676174.425,,0.000000e+000,5.499445e+001,-1.515411e-006,0.000000e+000,3,7.528672e-001,0.000000e+000,,,,,,,,,,,,,,32,1,4.000000e+000,2.628326e-003,0.000000e+000,0,,0,
1524676199.625,,0.000000e+000,5.499708e+001,-1.558876e-006,0.000000e+000,3,7.562879e-001,0.000000e+000,,,,,,,,,,,,,,32,1,4.000000e+000,2.620697e-003,0.000000e+000,0,,0,
1524676224.845,,0.000000e+000,5.499445e+001,-1.559114e-006,0.000000e+000,3,7.657501e-001,0.000000e+000,,,,,,,,,,,,,,32,1,4.000000e+000,7.881165e-003,0.000000e+000,0,,0,
1524676249.625,,0.000000e+000,5.499577e+001,-1.527561e-006,0.000000e+000,3,7.489677e-001,0.000000e+000,,,,,,,,,,,,,,32,1,4.000000e+000,1.052094e-002,0.000000e+000,0,,0,
1524676274.525,,0.000000e+000,5.499314e+001,-1.494849e-006,0.000000e+000,3,7.263854e-001,0.000000e+000,,,,,,,,,,,,,,32,1,4.000000e+000,5.260468e-003,0.000000e+000,0,,0,
1524676299.475,,0.000000e+000,5.499708e+001,-1.634810e-006,0.000000e+000,3,7.339490e-001,0.000000e+000,,,,,,,,,,,,,,32,1,4.000000e+000,2.620697e-003,0.000000e+000,0,,0,
1524676324.905,,0.000000e+000,5.499971e+001,-1.497199e-006,0.000000e+000,3,6.679488e-001,0.000000e+000,,,,,,,,,,,,,,32,1,4.000000e+000,2.639771e-003,0.000000e+000,0,,0,
1524676375.385,,0.000000e+000,5.499577e+001,-1.368125e-006,0.000000e+000,3,6.923000e-001,0.000000e+000,,,,,,,,,,,,,,32,1,4.000000e+000,0.000000e+000,0.000000e+000,0,,0,
1524676425.405,,0.000000e+000,5.499445e+001,-1.416973e-006,0.000000e+000,3,7.128074e-001,0.000000e+000,,,,,,,,,,,,,,32,1,4.000000e+000,2.628326e-003,0.000000e+000,0,,0,
1524676450.315,,0.000000e+000,5.499577e+001,-1.429340e-006,0.000000e+000,3,6.784174e-001,0.000000e+000,,,,,,,,,,,,,,32,1,4.000000e+000,2.632141e-003,0.000000e+000,0,,0,
1524676475.575,,0.000000e+000,5.499840e+001,-1.441997e-006,0.000000e+000,3,7.020909e-001,0.000000e+000,,,,,,,,,,,,,,32,1,4.000000e+000,2.628326e-003,0.000000e+000,0,,0,
1524676500.625,,0.000000e+000,5.499380e+001,-1.444473e-006,0.000000e+000,3,6.905518e-001,0.000000e+000,,,,,,,,,,,,,,32,1,4.000000e+000,3.948212e-003,0.000000e+000,0,,0,
1524676525.755,,0.000000e+000,5.500037e+001,-1.459034e-006,0.000000e+000,3,7.513079e-001,0.000000e+000,,,,,,,,,,,,,,32,1,4.000000e+000,3.959656e-003,0.000000e+000,0,,0,
1524676551.065,,0.000000e+000,5.499906e+001,-1.479125e-006,0.000000e+000,3,7.507269e-001,0.000000e+000,,,,,,,,,,,,,,32,1,4.000000e+000,1.710129e-002,0.000000e+000,0,,0,
1524676576.995,,0.000000e+000,5.499840e+001,-1.522548e-006,0.000000e+000,3,7.510031e-001,0.000000e+000,,,,,,,,,,,,,,32,1,4.000000e+000,1.578140e-002,0.000000e+000,0,,0,
1524676602.425,,0.000000e+000,5.499511e+001,-1.518533e-006,0.000000e+000,3,6.983119e-001,0.000000e+000,,,,,,,,,,,,,,32,1,4.000000e+000,1.319885e-003,0.000000e+000,0,,0,
1524676627.675,,0.000000e+000,5.499708e+001,-1.586449e-006,0.000000e+000,3,7.241424e-001,0.000000e+000,,,,,,,,,,,,,,32,1,4.000000e+000,2.620697e-003,0.000000e+000,0,,0,
1524676653.015,,0.000000e+000,5.499708e+001,-1.529823e-006,0.000000e+000,3,7.291470e-001,0.000000e+000,,,,,,,,,,,,,,32,1,4.000000e+000,2.620697e-003,0.000000e+000,0,,0,
1524676678.266,,0.000000e+000,5.499642e+001,-1.502464e-006,0.000000e+000,3,7.108499e-001,0.000000e+000,,,,,,,,,,,,,,32,1,4.000000e+000,3.940582e-003,0.000000e+000,0,,0,
1524676703.306,,0.000000e+000,5.499840e+001,-1.377394e-006,0.000000e+000,3,7.366363e-001,0.000000e+000,,,,,,,,,,,,,,32,1,4.000000e+000,5.260468e-003,0.000000e+000,0,,0,
1524676729.056,,0.000000e+000,5.499511e+001,-1.600637e-006,0.000000e+000,3,7.666391e-001,0.000000e+000,,,,,,,,,,,,,,32,1,4.000000e+000,1.184082e-002,0.000000e+000,0,,0,
1524676754.526,,0.000000e+000,5.499708e+001,-1.604444e-006,0.000000e+000,3,7.631313e-001,0.000000e+000,,,,,,,,,,,,,,32,1,4.000000e+000,2.620697e-003,0.000000e+000,0,,0,
1524676779.716,,0.000000e+000,5.498920e+001,-1.558070e-006,0.000000e+000,3,7.639616e-001,0.000000e+000,,,,,,,,,,,,,,32,1,4.000000e+000,1.314926e-002,0.000000e+000,0,,0,
1524676804.896,,0.000000e+000,5.499708e+001,-1.638047e-006,0.000000e+000,3,7.358831e-001,0.000000e+000,,,,,,,,,,,,,,32,1,4.000000e+000,0.000000e+000,0.000000e+000,0,,0,
1524676830.346,,0.000000e+000,5.499840e+001,-1.554350e-006,0.000000e+000,3,6.821290e-001,0.000000e+000,,,,,,,,,,,,,,32,1,4.000000e+000,5.260468e-003,0.000000e+000,0,,0,
1524676855.696,,0.000000e+000,5.499905e+001,-1.569404e-006,0.000000e+000,3,7.218453e-001,0.000000e+000,,,,,,,,,,,,,,32,1,4.000000e+000,1.319885e-003,0.000000e+000,0,,0,
1524676881.166,,0.000000e+000,5.499905e+001,-1.523346e-006,0.000000e+000,3,7.860801e-001,0.000000e+000,,,,,,,,,,,,,,32,1,4.000000e+000,1.182938e-002,0.000000e+000,0,,0,
1524676905.926,,0.000000e+000,5.499971e+001,-1.467957e-006,0.000000e+000,3,7.585571e-001,0.000000e+000,,,,,,,,,,,,,,32,1,4.000000e+000,1.052094e-002,0.000000e+000,0,,0,
1524676931.416,,0.000000e+000,5.499905e+001,-1.589069e-006,0.000000e+000,3,7.439720e-001,0.000000e+000,,,,,,,,,,,,,,32,1,4.000000e+000,1.319885e-003,0.000000e+000,0,,0,
1524676955.986,,0.000000e+000,5.499445e+001,-1.591240e-006,0.000000e+000,3,7.491757e-001,0.000000e+000,,,,,,,,,,,,,,32,1,4.000000e+000,5.260468e-003,0.000000e+000,0,,0,
1524676981.436,,0.000000e+000,5.499709e+001,-1.621862e-006,0.000000e+000,3,7.446491e-001,0.000000e+000,,,,,,,,,,,,,,32,1,4.000000e+000,7.888794e-003,0.000000e+000,0,,0,
1524677006.486,,0.000000e+000,5.499313e+001,-1.675852e-006,0.000000e+000,3,7.521598e-001,0.000000e+000,,,,,,,,,,,,,,32,1,4.000000e+000,2.628326e-003,0.000000e+000,0,,0,
1524677031.586,,0.000000e+000,5.499905e+001,-1.656681e-006,0.000000e+000,3,7.207763e-001,0.000000e+000,,,,,,,,,,,,,,32,1,4.000000e+000,1.319885e-003,0.000000e+000,0,,0,
1524677056.756,,0.000000e+000,5.499445e+001,-1.684528e-006,0.000000e+000,3,7.247216e-001,0.000000e+000,,,,,,,,,,,,,,32,1,4.000000e+000,2.628326e-003,0.000000e+000,0,,0,
1524677081.486,,0.000000e+000,5.500103e+001,-1.545227e-006,0.000000e+000,3,7.669894e-001,0.000000e+000,,,,,,,,,,,,,,32,1,4.000000e+000,5.279541e-003,0.000000e+000,0,,0,
1524677106.196,,0.000000e+000,5.499380e+001,-1.512891e-006,0.000000e+000,3,7.390113e-001,0.000000e+000,,,,,,,,,,,,,,32,1,4.000000e+000,1.446915e-002,0.000000e+000,0,,0,
1524677131.596,,0.000000e+000,5.500103e+001,-1.620789e-006,0.000000e+000,3,7.424163e-001,0.000000e+000,,,,,,,,,,,,,,32,1,4.000000e+000,5.279541e-003,0.000000e+000,0,,0,
1524677156.596,,0.000000e+000,5.499643e+001,-1.583804e-006,0.000000e+000,3,7.360425e-001,0.000000e+000,,,,,,,,,,,,,,32,1,4.000000e+000,9.208679e-003,0.000000e+000,0,,0,
1524677181.296,,0.000000e+000,5.499708e+001,-1.601741e-006,0.000000e+000,3,7.260731e-001,0.000000e+000,,,,,,,,,,,,,,32,1,4.000000e+000,5.260468e-003,0.000000e+000,0,,0,
1524677206.706,,0.000000e+000,5.499577e+001,-1.490510e-006,0.000000e+000,3,7.301406e-001,0.000000e+000,,,,,,,,,,,,,,32,1,4.000000e+000,5.249023e-003,0.000000e+000,0,,0,
1524677231.656,,0.000000e+000,5.499840e+001,-1.575180e-006,0.000000e+000,3,7.044716e-001,0.000000e+000,,,,,,,,,,,,,,32,1,4.000000e+000,2.628326e-003,0.000000e+000,0,,0,
1524677257.176,,0.000000e+000,5.500037e+001,-1.573174e-006,0.000000e+000,3,7.221382e-001,0.000000e+000,,,,,,,,,,,,,,32,1,4.000000e+000,1.319885e-003,0.000000e+000,0,,0,
1524677282.056,,0.000000e+000,5.499511e+001,-1.636668e-006,0.000000e+000,3,7.150023e-001,0.000000e+000,,,,,,,,,,,,,,32,1,4.000000e+000,3.940582e-003,0.000000e+000,0,,0,
1524677307.956,,0.000000e+000,5.499445e+001,-1.500117e-006,0.000000e+000,3,7.143319e-001,0.000000e+000,,,,,,,,,,,,,,32,1,4.000000e+000,7.881165e-003,0.000000e+000,0,,0,
1524677332.696,,0.000000e+000,5.499708e+001,-1.451485e-006,0.000000e+000,3,7.358924e-001,0.000000e+000,,,,,,,,,,,,,,32,1,4.000000e+000,0.000000e+000,0.000000e+000,0,,0,
1524677357.846,,0.000000e+000,5.499840e+001,-1.506083e-006,0.000000e+000,3,7.069538e-001,0.000000e+000,,,,,,,,,,,,,,32,1,4.000000e+000,5.260468e-003,0.000000e+000,0,,0,
1524677383.177,,0.000000e+000,5.499840e+001,-1.481367e-006,0.000000e+000,3,7.356011e-001,0.000000e+000,,,,,,,,,,,,,,32,1,4.000000e+000,2.628326e-003,0.000000e+000,0,,0,
1524677408.537,,0.000000e+000,5.499709e+001,-1.562290e-006,0.000000e+000,3,7.532164e-001,0.000000e+000,,,,,,,,,,,,,,32,1,4.000000e+000,1.052856e-002,0.000000e+000,0,,0,
1524677433.937,,0.000000e+000,5.499643e+001,-1.604130e-006,0.000000e+000,3,7.518112e-001,0.000000e+000,,,,,,,,,,,,,,32,1,4.000000e+000,6.568909e-003,0.000000e+000,0,,0,
1524677459.377,,0.000000e+000,5.499445e+001,-1.542789e-006,0.000000e+000,3,6.839728e-001,0.000000e+000,,,,,,,,,,,,,,32,1,4.000000e+000,5.260468e-003,0.000000e+000,0,,0,
1524677484.707,,0.000000e+000,5.499577e+001,-1.487990e-006,0.000000e+000,3,7.174078e-001,0.000000e+000,,,,,,,,,,,,,,32,1,4.000000e+000,7.888794e-003,0.000000e+000,0,,0,
1524677509.777,,0.000000e+000,5.499839e+001,-1.539028e-006,0.000000e+000,3,7.221333e-001,0.000000e+000,,,,,,,,,,,,,,32,1,4.000000e+000,0.000000e+000,0.000000e+000,0,,0,
1524677535.027,,0.000000e+000,5.499709e+001,-1.510525e-006,0.000000e+000,3,6.764752e-001,0.000000e+000,,,,,,,,,,,,,,32,1,4.000000e+000,1.052856e-002,0.000000e+000,0,,0,
1524677559.927,,0.000000e+000,5.499773e+001,-1.508748e-006,0.000000e+000,3,7.215269e-001,0.000000e+000,,,,,,,,,,,,,,32,1,4.000000e+000,1.308441e-003,0.000000e+000,0,,0,
1524677610.307,,0.000000e+000,5.499577e+001,-1.443620e-006,0.000000e+000,3,7.214603e-001,0.000000e+000,,,,,,,,,,,,,,32,1,4.000000e+000,1.316071e-002,0.000000e+000,0,,0,
1524677635.747,,0.000000e+000,5.499906e+001,-1.515700e-006,0.000000e+000,3,7.434476e-001,0.000000e+000,,,,,,,,,,,,,,32,1,4.000000e+000,9.220123e-003,0.000000e+000,0,,0,
1524677661.357,,0.000000e+000,5.500300e+001,-1.565042e-006,0.000000e+000,3,7.691992e-001,0.000000e+000,,,,,,,,,,,,,,32,1,4.000000e+000,1.183701e-002,0.000000e+000,0,,0,
1524677686.197,,0.000000e+000,5.500366e+001,-1.642928e-006,0.000000e+000,3,7.702493e-001,0.000000e+000,,,,,,,,,,,,,,32,1,4.000000e+000,7.900238e-003,0.000000e+000,0,,0,
1524677710.927,,0.000000e+000,5.499445e+001,-1.632690e-006,0.000000e+000,3,7.613334e-001,0.000000e+000,,,,,,,,,,,,,,32,1,4.000000e+000,7.881165e-003,0.000000e+000,0,,0,
1524677735.847,,0.000000e+000,5.499379e+001,-1.628222e-006,0.000000e+000,3,7.165963e-001,0.000000e+000,,,,,,,,,,,,,,32,1,4.000000e+000,9.201050e-003,0.000000e+000,0,,0,
1524677761.227,,0.000000e+000,5.499643e+001,-1.617522e-006,0.000000e+000,3,6.951585e-001,0.000000e+000,,,,,,,,,,,,,,32,1,4.000000e+000,1.312256e-003,0.000000e+000,0,,0,
1524677786.887,,0.000000e+000,5.499839e+001,-1.590580e-006,0.000000e+000,3,6.951798e-001,0.000000e+000,,,,,,,,,,,,,,32,1,4.000000e+000,0.000000e+000,0.000000e+000,0,,0,
1524677812.087,,0.000000e+000,5.499511e+001,-1.555026e-006,0.000000e+000,3,7.054625e-001,0.000000e+000,,,,,,,,,,,,,,32,1,4.000000e+000,9.201050e-003,0.000000e+000,0,,0,
1524677837.297,,0.000000e+000,5.499971e+001,-1.534345e-006,0.000000e+000,3,6.929963e-001,0.000000e+000,,,,,,,,,,,,,,32,1,4.000000e+000,2.639771e-003,0.000000e+000,0,,0,
1524677862.497,,0.000000e+000,5.500432e+001,-1.533798e-006,0.000000e+000,3,6.884683e-001,0.000000e+000,,,,,,,,,,,,,,32,1,4.000000e+000,3.940582e-003,0.000000e+000,0,,0,
1524677887.687,,0.000000e+000,5.499577e+001,-1.507358e-006,0.000000e+000,3,6.991015e-001,0.000000e+000,,,,,,,,,,,,,,32,1,4.000000e+000,2.632141e-003,0.000000e+000,0,,0,
1524677912.899,,0.000000e+000,5.500037e+001,-1.509757e-006,0.000000e+000,3,7.264401e-001,0.000000e+000,,,,,,,,,,,,,,32,1,4.000000e+000,6.587982e-003,0.000000e+000,0,,0,
1524677938.131,,0.000000e+000,5.499905e+001,-1.523566e-006,0.000000e+000,3,6.974259e-001,0.000000e+000,,,,,,,,,,,,,,32,1,4.000000e+000,3.948212e-003,0.000000e+000,0,,0,
1524677963.321,,0.000000e+000,5.499709e+001,-1.489835e-006,0.000000e+000,3,7.011186e-001,0.000000e+000,,,,,,,,,,,,,,32,1,4.000000e+000,7.888794e-003,0.000000e+000,0,,0,
1524677988.501,,0.000000e+000,5.499642e+001,-1.501682e-006,0.000000e+000,3,7.087062e-001,0.000000e+000,,,,,,,,,,,,,,32,1,4.000000e+000,3.940582e-003,0.000000e+000,0,,0,
1524678013.711,,0.000000e+000,5.499774e+001,-1.556417e-006,0.000000e+000,3,7.141333e-001,0.000000e+000,,,,,,,,,,,,,,32,1,4.000000e+000,6.580353e-003,0.000000e+000,0,,0,
1524678038.911,,0.000000e+000,5.499708e+001,-1.504081e-006,0.000000e+000,3,6.972131e-001,0.000000e+000,,,,,,,,,,,,,,32,1,4.000000e+000,0.000000e+000,0.000000e+000,0,,0,
1524678064.111,,0.000000e+000,5.500235e+001,-1.485080e-006,0.000000e+000,3,7.127773e-001,0.000000e+000,,,,,,,,,,,,,,32,1,4.000000e+000,0.000000e+000,0.000000e+000,0,,0,
1524678089.002,,0.000000e+000,5.499313e+001,-1.556296e-006,0.000000e+000,3,7.491845e-001,0.000000e+000,,,,,,,,,,,,,,32,1,4.000000e+000,1.050949e-002,0.000000e+000,0,,0,
1524678113.862,,0.000000e+000,5.500037e+001,-1.555070e-006,0.000000e+000,3,6.941287e-001,0.000000e+000,,,,,,,,,,,,,,32,1,4.000000e+000,1.184082e-002,0.000000e+000,0,,0,
1524678139.062,,0.000000e+000,5.500234e+001,-1.574052e-006,0.000000e+000,3,7.151239e-001,0.000000e+000,,,,,,,,,,,,,,32,1,4.000000e+000,7.900238e-003,0.000000e+000,0,,0,
1524678164.272,,0.000000e+000,5.500037e+001,-1.537220e-006,0.000000e+000,3,6.893626e-001,0.000000e+000,,,,,,,,,,,,,,32,1,4.000000e+000,6.587982e-003,0.000000e+000,0,,0,
1524678176.882,,0.000000e+000,5.500169e+001,-1.478890e-006,0.000000e+000,3,7.063047e-001,0.000000e+000,,,,,,,,,,,,,,32,1,4.000000e+000,3.959656e-003,0.000000e+000,0,,0,