File: Experimental Raw Data/TC04-12-01K TRMac VRMde/Ndat/TC04-12-01K_TRMac_56K_0.08Kmin_VRMde_55K.dc.dat
[Header]
TITLE,MPMS DC Measurement
BYAPP,MPMS Measurement,2.1,Summary
FILEOPENTIME, 1524449785.475000 4/22/2018, 8:16:25 PM

INFO, APPNAME, MPMS MultiVu Application, Revision 1.61,  Build 082

INFO, NAME, TC04-12-01K
INFO, WEIGHT, 1.000
INFO, AREA, 1.000
INFO, LENGTH, 1.000
INFO, SHAPE, 0
INFO, COMMENT,
INFO, SEQUENCE FILE: TRMac_56K_0.08Kmin_VRMde_55K.seq


INFO, BACKGROUND DATA FILE:, None


STARTUPAXIS,X,4,LINEAR,AUTO,0.000000,0.000000
STARTUPAXIS,Y1,5,LINEAR,AUTO,0.000000,0.000000


STARTUPGROUP,Longitudinal
FIELDGROUP,Longitudinal,1,2,3,4,5,6,7,8,9,15,16,17,18,27,28
FIELDGROUP,Transverse,1,2,3,4,10,11,12,13,14,19,20,21,22,27,28

PLOT_APPEARANCE,ALL,HORZ_GRID_ON,VERT_GRID_ON,MARKERS_AND_LINES

[Data]
Time,Comment,Field (Oe),Temperature (K),Long Moment (emu),Long Scan Std Dev,Long Algorithm,Long Reg Fit,Long Percent Error (%),Trans Moment (emu),Trans Scan Std Dev,Trans Algorithm,Trans Reg Fit,Trans Percent Error (%),Long Moment [w/o ABS] (emu),Long Scan Std Dev [w/o ABS],Long Reg Fit [w/o ABS],Long Percent Error [w/o ABS] (%),Trans Moment [w/o ABS] (emu),Trans Scan Std Dev [w/o ABS],Trans Reg Fit [w/o ABS],Trans Percent Error [w/o ABS] (%),Points per Scan,Scans per Measurement,Scan Length (cm),Delta Temp (K),Rot Position (deg),Error,EC Comp. Running,Using ABS,
1524449785.475,,0.000000e+000,5.499380e+001,-5.978318e-006,0.000000e+000,3,9.584913e-001,0.000000e+000,,,,,,,,,,,,,,32,1,4.000000e+000,1.182938e-002,0.000000e+000,0,,0,
1524449823.605,,0.000000e+000,5.500497e+001,-3.489102e-006,0.000000e+000,3,8.875543e-001,0.000000e+000,,,,,,,,,,,,,,32,1,4.000000e+000,1.052856e-002,0.000000e+000,0,,0,
1524449861.545,,0.000000e+000,5.499774e+001,-2.282970e-006,0.000000e+000,3,8.405893e-001,0.000000e+000,,,,,,,,,,,,,,32,1,4.000000e+000,6.580353e-003,0.000000e+000,0,,0,
1524449901.585,,0.000000e+000,5.499709e+001,-6.618545e-007,0.000000e+000,2,0.000000e+000,0.000000e+000,,,,,,,,,,,,,,32,1,4.000000e+000,1.316071e-002,0.000000e+000,0,,0,
1524449938.515,,0.000000e+000,5.499840e+001,-2.090608e-006,0.000000e+000,3,6.846135e-001,0.000000e+000,,,,,,,,,,,,,,32,1,4.000000e+000,2.628326e-003,0.000000e+000,0,,0,
1524449979.349,,0.000000e+000,5.500037e+001,2.117700e-006,0.000000e+000,3,7.158145e-001,0.000000e+000,,,,,,,,,,,,,,32,1,4.000000e+000,3.959656e-003,0.000000e+000,0,,0,
1524450017.049,,0.000000e+000,5.500497e+001,2.058390e-006,0.000000e+000,3,7.572027e-001,0.000000e+000,,,,,,,,,,,,,,32,1,4.000000e+000,1.578903e-002,0.000000e+000,0,,0,
1524450055.609,,0.000000e+000,5.499249e+001,2.304132e-006,0.000000e+000,3,7.872118e-001,0.000000e+000,,,,,,,,,,,,,,32,1,4.000000e+000,1.972961e-002,0.000000e+000,0,,0,
1524450093.669,,0.000000e+000,5.499840e+001,2.463994e-006,0.000000e+000,3,7.878837e-001,0.000000e+000,,,,,,,,,,,,,,32,1,4.000000e+000,5.260468e-003,0.000000e+000,0,,0,
1524450131.679,,0.000000e+000,5.499577e+001,2.591259e-006,0.000000e+000,3,8.517722e-001,0.000000e+000,,,,,,,,,,,,,,32,1,4.000000e+000,1.052094e-002,0.000000e+000,0,,0,
1524450169.249,,0.000000e+000,5.499840e+001,2.814532e-006,0.000000e+000,3,8.464318e-001,0.000000e+000,,,,,,,,,,,,,,32,1,4.000000e+000,5.260468e-003,0.000000e+000,0,,0,
1524450207.309,,0.000000e+000,5.500169e+001,2.795972e-006,0.000000e+000,3,8.651544e-001,0.000000e+000,,,,,,,,,,,,,,32,1,4.000000e+000,1.184082e-002,0.000000e+000,0,,0,
1524450245.819,,0.000000e+000,5.499577e+001,2.968785e-006,0.000000e+000,3,8.809077e-001,0.000000e+000,,,,,,,,,,,,,,32,1,4.000000e+000,1.316071e-002,0.000000e+000,0,,0,
1524450283.139,,0.000000e+000,5.499905e+001,3.098242e-006,0.000000e+000,3,8.760832e-001,0.000000e+000,,,,,,,,,,,,,,32,1,4.000000e+000,3.948212e-003,0.000000e+000,0,,0,
1524450321.469,,0.000000e+000,5.499314e+001,3.125831e-006,0.000000e+000,3,8.830447e-001,0.000000e+000,,,,,,,,,,,,,,32,1,4.000000e+000,5.260468e-003,0.000000e+000,0,,0,
1524450358.949,,0.000000e+000,5.499511e+001,3.205893e-006,0.000000e+000,3,8.826764e-001,0.000000e+000,,,,,,,,,,,,,,32,1,4.000000e+000,1.319885e-003,0.000000e+000,0,,0,
1524450395.969,,0.000000e+000,5.499971e+001,3.317851e-006,0.000000e+000,3,8.846464e-001,0.000000e+000,,,,,,,,,,,,,,32,1,4.000000e+000,1.052094e-002,0.000000e+000,0,,0,
1524450433.190,,0.000000e+000,5.499774e+001,3.410216e-006,0.000000e+000,3,9.133087e-001,0.000000e+000,,,,,,,,,,,,,,32,1,4.000000e+000,1.446152e-002,0.000000e+000,0,,0,
1524450471.220,,0.000000e+000,5.500168e+001,3.515127e-006,0.000000e+000,3,9.122076e-001,0.000000e+000,,,,,,,,,,,,,,32,1,4.000000e+000,6.580353e-003,0.000000e+000,0,,0,
1524450509.720,,0.000000e+000,5.500563e+001,3.553464e-006,0.000000e+000,3,8.855443e-001,0.000000e+000,,,,,,,,,,,,,,32,1,4.000000e+000,1.319885e-003,0.000000e+000,0,,0,
1524450547.580,,0.000000e+000,5.499708e+001,3.557786e-006,0.000000e+000,3,8.879682e-001,0.000000e+000,,,,,,,,,,,,,,32,1,4.000000e+000,5.260468e-003,0.000000e+000,0,,0,
1524450585.240,,0.000000e+000,5.500235e+001,3.645956e-006,0.000000e+000,3,8.967395e-001,0.000000e+000,,,,,,,,,,,,,,32,1,4.000000e+000,2.639771e-003,0.000000e+000,0,,0,
1524450623.520,,0.000000e+000,5.499773e+001,3.694896e-006,0.000000e+000,3,8.981537e-001,0.000000e+000,,,,,,,,,,,,,,32,1,4.000000e+000,1.308441e-003,0.000000e+000,0,,0,
1524450661.620,,0.000000e+000,5.500300e+001,3.723558e-006,0.000000e+000,3,9.071614e-001,0.000000e+000,,,,,,,,,,,,,,32,1,4.000000e+000,9.220123e-003,0.000000e+000,0,,0,
1524450713.280,,0.000000e+000,5.499446e+001,3.918433e-006,0.000000e+000,3,9.277487e-001,0.000000e+000,,,,,,,,,,,,,,32,1,4.000000e+000,1.842117e-002,0.000000e+000,0,,0,
1524450751.180,,0.000000e+000,5.499182e+001,3.838971e-006,0.000000e+000,3,8.853699e-001,0.000000e+000,,,,,,,,,,,,,,32,1,4.000000e+000,5.260468e-003,0.000000e+000,0,,0,
1524450788.760,,0.000000e+000,5.499708e+001,3.946733e-006,0.000000e+000,3,8.787315e-001,0.000000e+000,,,,,,,,,,,,,,32,1,4.000000e+000,2.620697e-003,0.000000e+000,0,,0,
1524450826.830,,0.000000e+000,5.499708e+001,3.990303e-006,0.000000e+000,3,8.940625e-001,0.000000e+000,,,,,,,,,,,,,,32,1,4.000000e+000,2.620697e-003,0.000000e+000,0,,0,
1524450864.440,,0.000000e+000,5.500168e+001,4.055187e-006,0.000000e+000,3,8.895084e-001,0.000000e+000,,,,,,,,,,,,,,32,1,4.000000e+000,6.580353e-003,0.000000e+000,0,,0,
1524450902.490,,0.000000e+000,5.500103e+001,4.015718e-006,0.000000e+000,3,9.034993e-001,0.000000e+000,,,,,,,,,,,,,,32,1,4.000000e+000,0.000000e+000,0.000000e+000,0,,0,
1524450940.070,,0.000000e+000,5.499643e+001,4.154718e-006,0.000000e+000,3,8.926938e-001,0.000000e+000,,,,,,,,,,,,,,32,1,4.000000e+000,6.568909e-003,0.000000e+000,0,,0,
1524450978.150,,0.000000e+000,5.499445e+001,4.102582e-006,0.000000e+000,3,9.005672e-001,0.000000e+000,,,,,,,,,,,,,,32,1,4.000000e+000,0.000000e+000,0.000000e+000,0,,0,
1524451015.800,,0.000000e+000,5.499445e+001,4.085156e-006,0.000000e+000,3,9.058648e-001,0.000000e+000,,,,,,,,,,,,,,32,1,4.000000e+000,7.881165e-003,0.000000e+000,0,,0,
1524451053.260,,0.000000e+000,5.499577e+001,4.007778e-006,0.000000e+000,3,9.030190e-001,0.000000e+000,,,,,,,,,,,,,,32,1,4.000000e+000,1.052094e-002,0.000000e+000,0,,0,
1524451090.900,,0.000000e+000,5.499839e+001,4.141674e-006,0.000000e+000,3,9.063749e-001,0.000000e+000,,,,,,,,,,,,,,32,1,4.000000e+000,0.000000e+000,0.000000e+000,0,,0,
1524451128.911,,0.000000e+000,5.499774e+001,4.175584e-006,0.000000e+000,3,9.056808e-001,0.000000e+000,,,,,,,,,,,,,,32,1,4.000000e+000,6.580353e-003,0.000000e+000,0,,0,
1524451166.361,,0.000000e+000,5.499906e+001,4.162061e-006,0.000000e+000,3,9.024910e-001,0.000000e+000,,,,,,,,,,,,,,32,1,4.000000e+000,6.580353e-003,0.000000e+000,0,,0,
1524451204.731,,0.000000e+000,5.499248e+001,4.219646e-006,0.000000e+000,3,9.043400e-001,0.000000e+000,,,,,,,,,,,,,,32,1,4.000000e+000,1.710129e-002,0.000000e+000,0,,0,
1524451242.721,,0.000000e+000,5.499840e+001,4.240077e-006,0.000000e+000,3,9.128599e-001,0.000000e+000,,,,,,,,,,,,,,32,1,4.000000e+000,2.628326e-003,0.000000e+000,0,,0,
1524451280.031,,0.000000e+000,5.499445e+001,4.243753e-006,0.000000e+000,3,9.009010e-001,0.000000e+000,,,,,,,,,,,,,,32,1,4.000000e+000,5.260468e-003,0.000000e+000,0,,0,
1524451318.021,,0.000000e+000,5.500103e+001,4.253828e-006,0.000000e+000,3,9.151555e-001,0.000000e+000,,,,,,,,,,,,,,32,1,4.000000e+000,7.888794e-003,0.000000e+000,0,,0,
1524451356.651,,0.000000e+000,5.499577e+001,4.305665e-006,0.000000e+000,3,9.228682e-001,0.000000e+000,,,,,,,,,,,,,,32,1,4.000000e+000,0.000000e+000,0.000000e+000,0,,0,
1524451394.831,,0.000000e+000,5.500037e+001,4.233128e-006,0.000000e+000,3,9.124479e-001,0.000000e+000,,,,,,,,,,,,,,32,1,4.000000e+000,1.184082e-002,0.000000e+000,0,,0,
1524451433.011,,0.000000e+000,5.499511e+001,4.346601e-006,0.000000e+000,3,9.030402e-001,0.000000e+000,,,,,,,,,,,,,,32,1,4.000000e+000,3.940582e-003,0.000000e+000,0,,0,
1524451470.981,,0.000000e+000,5.499839e+001,4.379133e-006,0.000000e+000,3,9.122639e-001,0.000000e+000,,,,,,,,,,,,,,32,1,4.000000e+000,0.000000e+000,0.000000e+000,0,,0,
1524451508.331,,0.000000e+000,5.499708e+001,4.346753e-006,0.000000e+000,3,9.167030e-001,0.000000e+000,,,,,,,,,,,,,,32,1,4.000000e+000,2.620697e-003,0.000000e+000,0,,0,
1524451546.041,,0.000000e+000,5.500497e+001,4.466031e-006,0.000000e+000,3,9.025255e-001,0.000000e+000,,,,,,,,,,,,,,32,1,4.000000e+000,1.052856e-002,0.000000e+000,0,,0,
1524451583.421,,0.000000e+000,5.499708e+001,4.417833e-006,0.000000e+000,3,9.122236e-001,0.000000e+000,,,,,,,,,,,,,,32,1,4.000000e+000,2.620697e-003,0.000000e+000,0,,0,
1524451635.951,,0.000000e+000,5.500103e+001,4.517328e-006,0.000000e+000,3,9.348109e-001,0.000000e+000,,,,,,,,,,,,,,32,1,4.000000e+000,5.279541e-003,0.000000e+000,0,,0,
1524451673.601,,0.000000e+000,5.499840e+001,4.396363e-006,0.000000e+000,3,9.220836e-001,0.000000e+000,,,,,,,,,,,,,,32,1,4.000000e+000,5.260468e-003,0.000000e+000,0,,0,
1524451711.681,,0.000000e+000,5.500037e+001,4.508163e-006,0.000000e+000,3,8.934249e-001,0.000000e+000,,,,,,,,,,,,,,32,1,4.000000e+000,6.587982e-003,0.000000e+000,0,,0,
1524451749.521,,0.000000e+000,5.499248e+001,4.527409e-006,0.000000e+000,3,9.144397e-001,0.000000e+000,,,,,,,,,,,,,,32,1,4.000000e+000,1.319885e-003,0.000000e+000,0,,0,
1524451787.641,,0.000000e+000,5.500103e+001,4.425675e-006,0.000000e+000,3,9.144635e-001,0.000000e+000,,,,,,,,,,,,,,32,1,4.000000e+000,5.279541e-003,0.000000e+000,0,,0,
1524451825.451,,0.000000e+000,5.499905e+001,4.541898e-006,0.000000e+000,3,9.050054e-001,0.000000e+000,,,,,,,,,,,,,,32,1,4.000000e+000,1.319885e-003,0.000000e+000,0,,0,
1524451864.042,,0.000000e+000,5.499708e+001,4.506809e-006,0.000000e+000,3,9.167861e-001,0.000000e+000,,,,,,,,,,,,,,32,1,4.000000e+000,5.260468e-003,0.000000e+000,0,,0,
1524451901.082,,0.000000e+000,5.499511e+001,4.498952e-006,0.000000e+000,3,8.970465e-001,0.000000e+000,,,,,,,,,,,,,,32,1,4.000000e+000,1.319885e-003,0.000000e+000,0,,0,
1524451938.452,,0.000000e+000,5.499709e+001,4.517651e-006,0.000000e+000,3,9.132993e-001,0.000000e+000,,,,,,,,,,,,,,32,1,4.000000e+000,1.316071e-002,0.000000e+000,0,,0,
1524451976.432,,0.000000e+000,5.499708e+001,4.501199e-006,0.000000e+000,3,9.160869e-001,0.000000e+000,,,,,,,,,,,,,,32,1,4.000000e+000,5.260468e-003,0.000000e+000,0,,0,
1524452014.282,,0.000000e+000,5.500234e+001,4.491015e-006,0.000000e+000,3,9.148578e-001,0.000000e+000,,,,,,,,,,,,,,32,1,4.000000e+000,1.578903e-002,0.000000e+000,0,,0,
1524452051.902,,0.000000e+000,5.499511e+001,4.513397e-006,0.000000e+000,3,9.108604e-001,0.000000e+000,,,,,,,,,,,,,,32,1,4.000000e+000,3.940582e-003,0.000000e+000,0,,0,
1524452089.972,,0.000000e+000,5.499839e+001,4.547138e-006,0.000000e+000,3,9.195263e-001,0.000000e+000,,,,,,,,,,,,,,32,1,4.000000e+000,0.000000e+000,0.000000e+000,0,,0,
1524452127.722,,0.000000e+000,5.500300e+001,4.543145e-006,0.000000e+000,3,9.049838e-001,0.000000e+000,,,,,,,,,,,,,,32,1,4.000000e+000,1.710129e-002,0.000000e+000,0,,0,
1524452165.632,,0.000000e+000,5.499774e+001,4.492150e-006,0.000000e+000,3,9.199422e-001,0.000000e+000,,,,,,,,,,,,,,32,1,4.000000e+000,1.446152e-002,0.000000e+000,0,,0,
1524452203.192,,0.000000e+000,5.500234e+001,4.512367e-006,0.000000e+000,3,9.107174e-001,0.000000e+000,,,,,,,,,,,,,,32,1,4.000000e+000,5.260468e-003,0.000000e+000,0,,0,
1524452241.262,,0.000000e+000,5.499314e+001,4.523221e-006,0.000000e+000,3,9.187321e-001,0.000000e+000,,,,,,,,,,,,,,32,1,4.000000e+000,0.000000e+000,0.000000e+000,0,,0,
1524452278.882,,0.000000e+000,5.499708e+001,4.539597e-006,0.000000e+000,3,9.116546e-001,0.000000e+000,,,,,,,,,,,,,,32,1,4.000000e+000,2.620697e-003,0.000000e+000,0,,0,
1524452316.942,,0.000000e+000,5.499577e+001,4.514680e-006,0.000000e+000,3,9.204798e-001,0.000000e+000,,,,,,,,,,,,,,32,1,4.000000e+000,2.632141e-003,0.000000e+000,0,,0,
1524452354.622,,0.000000e+000,5.499905e+001,4.596059e-006,0.000000e+000,3,9.095300e-001,0.000000e+000,,,,,,,,,,,,,,32,1,4.000000e+000,3.948212e-003,0.000000e+000,0,,0,
1524452392.462,,0.000000e+000,5.499117e+001,4.553912e-006,0.000000e+000,3,9.204187e-001,0.000000e+000,,,,,,,,,,,,,,32,1,4.000000e+000,3.952026e-003,0.000000e+000,0,,0,
1524452430.742,,0.000000e+000,5.500365e+001,4.581448e-006,0.000000e+000,3,9.203045e-001,0.000000e+000,,,,,,,,,,,,,,32,1,4.000000e+000,1.052856e-002,0.000000e+000,0,,0,
1524452468.322,,0.000000e+000,5.499643e+001,4.530625e-006,0.000000e+000,3,9.094473e-001,0.000000e+000,,,,,,,,,,,,,,32,1,4.000000e+000,6.568909e-003,0.000000e+000,0,,0,
1524452505.912,,0.000000e+000,5.499840e+001,4.571157e-006,0.000000e+000,3,9.009448e-001,0.000000e+000,,,,,,,,,,,,,,32,1,4.000000e+000,5.260468e-003,0.000000e+000,0,,0,
1524452556.973,,0.000000e+000,5.499774e+001,4.648678e-006,0.000000e+000,3,9.344176e-001,0.000000e+000,,,,,,,,,,,,,,32,1,4.000000e+000,1.710129e-002,0.000000e+000,0,,0,
1524452595.433,,0.000000e+000,5.500761e+001,4.592219e-006,0.000000e+000,3,9.169917e-001,0.000000e+000,,,,,,,,,,,,,,32,1,4.000000e+000,1.052094e-002,0.000000e+000,0,,0,
1524452633.063,,0.000000e+000,5.499642e+001,4.587461e-006,0.000000e+000,3,9.090005e-001,0.000000e+000,,,,,,,,,,,,,,32,1,4.000000e+000,3.940582e-003,0.000000e+000,0,,0,
1524452671.073,,0.000000e+000,5.499314e+001,4.589345e-006,0.000000e+000,3,9.148391e-001,0.000000e+000,,,,,,,,,,,,,,32,1,4.000000e+000,0.000000e+000,0.000000e+000,0,,0,
1524452708.663,,0.000000e+000,5.500563e+001,4.632558e-006,0.000000e+000,3,9.094512e-001,0.000000e+000,,,,,,,,,,,,,,32,1,4.000000e+000,1.319885e-003,0.000000e+000,0,,0,
1524452746.713,,0.000000e+000,5.500366e+001,4.608613e-006,0.000000e+000,3,9.253342e-001,0.000000e+000,,,,,,,,,,,,,,32,1,4.000000e+000,5.260468e-003,0.000000e+000,0,,0,
1524452784.383,,0.000000e+000,5.499972e+001,4.638321e-006,0.000000e+000,3,9.109702e-001,0.000000e+000,,,,,,,,,,,,,,32,1,4.000000e+000,7.900238e-003,0.000000e+000,0,,0,
1524452822.383,,0.000000e+000,5.499708e+001,4.626127e-006,0.000000e+000,3,9.237068e-001,0.000000e+000,,,,,,,,,,,,,,32,1,4.000000e+000,2.620697e-003,0.000000e+000,0,,0,
1524452860.003,,0.000000e+000,5.499972e+001,4.683618e-006,0.000000e+000,3,9.172719e-001,0.000000e+000,,,,,,,,,,,,,,32,1,4.000000e+000,1.314926e-002,0.000000e+000,0,,0,
1524452898.083,,0.000000e+000,5.499708e+001,4.733300e-006,0.000000e+000,3,9.129757e-001,0.000000e+000,,,,,,,,,,,,,,32,1,4.000000e+000,5.260468e-003,0.000000e+000,0,,0,
1524452936.183,,0.000000e+000,5.499445e+001,4.669456e-006,0.000000e+000,3,9.084035e-001,0.000000e+000,,,,,,,,,,,,,,32,1,4.000000e+000,5.260468e-003,0.000000e+000,0,,0,
1524452974.683,,0.000000e+000,5.500037e+001,4.665869e-006,0.000000e+000,3,9.164189e-001,0.000000e+000,,,,,,,,,,,,,,32,1,4.000000e+000,6.587982e-003,0.000000e+000,0,,0,
1524453012.093,,0.000000e+000,5.499577e+001,4.640749e-006,0.000000e+000,3,9.294658e-001,0.000000e+000,,,,,,,,,,,,,,32,1,4.000000e+000,2.632141e-003,0.000000e+000,0,,0,
1524453049.783,,0.000000e+000,5.499380e+001,4.594357e-006,0.000000e+000,3,9.228443e-001,0.000000e+000,,,,,,,,,,,,,,32,1,4.000000e+000,1.308441e-003,0.000000e+000,0,,0,
1524453088.553,,0.000000e+000,5.499905e+001,4.600081e-006,0.000000e+000,3,9.132819e-001,0.000000e+000,,,,,,,,,,,,,,32,1,4.000000e+000,1.319885e-003,0.000000e+000,0,,0,
1524453126.953,,0.000000e+000,5.499445e+001,4.619232e-006,0.000000e+000,3,9.153388e-001,0.000000e+000,,,,,,,,,,,,,,32,1,4.000000e+000,2.628326e-003,0.000000e+000,0,,0,
1524453165.193,,0.000000e+000,5.500037e+001,4.601941e-006,0.000000e+000,3,9.283195e-001,0.000000e+000,,,,,,,,,,,,,,32,1,4.000000e+000,3.959656e-003,0.000000e+000,0,,0,
1524453202.483,,0.000000e+000,5.499906e+001,4.629959e-006,0.000000e+000,3,9.216676e-001,0.000000e+000,,,,,,,,,,,,,,32,1,4.000000e+000,6.580353e-003,0.000000e+000,0,,0,
1524453240.173,,0.000000e+000,5.499971e+001,4.579925e-006,0.000000e+000,3,9.229250e-001,0.000000e+000,,,,,,,,,,,,,,32,1,4.000000e+000,0.000000e+000,0.000000e+000,0,,0,
1524453276.954,,0.000000e+000,5.499905e+001,4.544437e-006,0.000000e+000,3,9.145637e-001,0.000000e+000,,,,,,,,,,,,,,32,1,4.000000e+000,1.446915e-002,0.000000e+000,0,,0,
1524453315.494,,0.000000e+000,5.499905e+001,4.625681e-006,0.000000e+000,3,9.111148e-001,0.000000e+000,,,,,,,,,,,,,,32,1,4.000000e+000,1.319885e-003,0.000000e+000,0,,0,
1524453353.074,,0.000000e+000,5.499775e+001,4.616863e-006,0.000000e+000,3,9.301199e-001,0.000000e+000,,,,,,,,,,,,,,32,1,4.000000e+000,9.208679e-003,0.000000e+000,0,,0,
1524453391.604,,0.000000e+000,5.499511e+001,4.547191e-006,0.000000e+000,3,9.270987e-001,0.000000e+000,,,,,,,,,,,,,,32,1,4.000000e+000,1.184082e-002,0.000000e+000,0,,0,
1524453429.184,,0.000000e+000,5.499840e+001,4.631330e-006,0.000000e+000,3,9.196923e-001,0.000000e+000,,,,,,,,,,,,,,32,1,4.000000e+000,7.900238e-003,0.000000e+000,0,,0,
1524453480.084,,0.000000e+000,5.500300e+001,4.708205e-006,0.000000e+000,3,9.232049e-001,0.000000e+000,,,,,,,,,,,,,,32,1,4.000000e+000,6.580353e-003,0.000000e+000,0,,0,
1524453518.814,,0.000000e+000,5.500432e+001,4.626048e-006,0.000000e+000,3,9.071870e-001,0.000000e+000,,,,,,,,,,,,,,32,1,4.000000e+000,1.300812e-003,0.000000e+000,0,,0,
1524453556.784,,0.000000e+000,5.499577e+001,4.563733e-006,0.000000e+000,3,9.255396e-001,0.000000e+000,,,,,,,,,,,,,,32,1,4.000000e+000,2.632141e-003,0.000000e+000,0,,0,
1524453594.154,,0.000000e+000,5.500169e+001,4.598170e-006,0.000000e+000,3,9.166170e-001,0.000000e+000,,,,,,,,,,,,,,32,1,4.000000e+000,1.184082e-002,0.000000e+000,0,,0,
1524453632.524,,0.000000e+000,5.499774e+001,4.642028e-006,0.000000e+000,3,9.211899e-001,0.000000e+000,,,,,,,,,,,,,,32,1,4.000000e+000,1.446152e-002,0.000000e+000,0,,0,
1524453670.604,,0.000000e+000,5.499248e+001,4.617165e-006,0.000000e+000,3,9.318852e-001,0.000000e+000,,,,,,,,,,,,,,32,1,4.000000e+000,1.319885e-003,0.000000e+000,0,,0,
1524453707.954,,0.000000e+000,5.499577e+001,4.632811e-006,0.000000e+000,3,9.234520e-001,0.000000e+000,,,,,,,,,,,,,,32,1,4.000000e+000,5.249023e-003,0.000000e+000,0,,0,
1524453746.284,,0.000000e+000,5.499840e+001,4.612852e-006,0.000000e+000,3,9.274305e-001,0.000000e+000,,,,,,,,,,,,,,32,1,4.000000e+000,5.260468e-003,0.000000e+000,0,,0,
1524453783.604,,0.000000e+000,5.500301e+001,4.651738e-006,0.000000e+000,3,9.181020e-001,0.000000e+000,,,,,,,,,,,,,,32,1,4.000000e+000,1.446915e-002,0.000000e+000,0,,0,
1524453821.484,,0.000000e+000,5.499380e+001,4.605903e-006,0.000000e+000,3,9.303641e-001,0.000000e+000,,,,,,,,,,,,,,32,1,4.000000e+000,3.948212e-003,0.000000e+000,0,,0,
1524453858.794,,0.000000e+000,5.499183e+001,4.656715e-006,0.000000e+000,3,9.205182e-001,0.000000e+000,,,,,,,,,,,,,,32,1,4.000000e+000,7.888794e-003,0.000000e+000,0,,0,
1524453896.674,,0.000000e+000,5.499313e+001,4.604229e-006,0.000000e+000,3,9.181244e-001,0.000000e+000,,,,,,,,,,,,,,32,1,4.000000e+000,2.628326e-003,0.000000e+000,0,,0,
1524453934.734,,0.000000e+000,5.499577e+001,4.671074e-006,0.000000e+000,3,9.167606e-001,0.000000e+000,,,,,,,,,,,,,,32,1,4.000000e+000,0.000000e+000,0.000000e+000,0,,0,
1524453972.354,,0.000000e+000,5.499445e+001,4.650977e-006,0.000000e+000,3,9.299781e-001,0.000000e+000,,,,,,,,,,,,,,32,1,4.000000e+000,5.260468e-003,0.000000e+000,0,,0,
1524454009.595,,0.000000e+000,5.498920e+001,4.663261e-006,0.000000e+000,3,9.179000e-001,0.000000e+000,,,,,,,,,,,,,,32,1,4.000000e+000,2.628326e-003,0.000000e+000,0,,0,
1524454047.475,,0.000000e+000,5.499971e+001,4.713840e-006,0.000000e+000,3,9.389338e-001,0.000000e+000,,,,,,,,,,,,,,32,1,4.000000e+000,0.000000e+000,0.000000e+000,0,,0,
1524454085.335,,0.000000e+000,5.500168e+001,4.731369e-006,0.000000e+000,3,9.274079e-001,0.000000e+000,,,,,,,,,,,,,,32,1,4.000000e+000,6.580353e-003,0.000000e+000,0,,0,
1524454122.915,,0.000000e+000,5.499380e+001,4.739328e-006,0.000000e+000,3,9.424069e-001,0.000000e+000,,,,,,,,,,,,,,32,1,4.000000e+000,1.308441e-003,0.000000e+000,0,,0,
1524454160.705,,0.000000e+000,5.500366e+001,4.700666e-006,0.000000e+000,3,9.223548e-001,0.000000e+000,,,,,,,,,,,,,,32,1,4.000000e+000,5.260468e-003,0.000000e+000,0,,0,
1524454198.795,,0.000000e+000,5.499972e+001,4.814274e-006,0.000000e+000,3,9.183277e-001,0.000000e+000,,,,,,,,,,,,,,32,1,4.000000e+000,5.268097e-003,0.000000e+000,0,,0,
1524454237.315,,0.000000e+000,5.499971e+001,4.805421e-006,0.000000e+000,3,9.137008e-001,0.000000e+000,,,,,,,,,,,,,,32,1,4.000000e+000,2.639771e-003,0.000000e+000,0,,0,
1524454275.585,,0.000000e+000,5.499774e+001,4.814875e-006,0.000000e+000,3,9.304990e-001,0.000000e+000,,,,,,,,,,,,,,32,1,4.000000e+000,3.940582e-003,0.000000e+000,0,,0,
1524454313.055,,0.000000e+000,5.499313e+001,4.787260e-006,0.000000e+000,3,9.190043e-001,0.000000e+000,,,,,,,,,,,,,,32,1,4.000000e+000,7.892609e-003,0.000000e+000,0,,0,
1524454350.985,,0.000000e+000,5.500695e+001,4.798409e-006,0.000000e+000,3,9.219580e-001,0.000000e+000,,,,,,,,,,,,,,32,1,4.000000e+000,1.973724e-002,0.000000e+000,0,,0,
1524454401.655,,0.000000e+000,5.499905e+001,4.831433e-006,0.000000e+000,3,9.086826e-001,0.000000e+000,,,,,,,,,,,,,,32,1,4.000000e+000,3.948212e-003,0.000000e+000,0,,0,
1524454439.045,,0.000000e+000,5.499840e+001,4.777448e-006,0.000000e+000,3,9.292432e-001,0.000000e+000,,,,,,,,,,,,,,32,1,4.000000e+000,2.628326e-003,0.000000e+000,0,,0,
1524454476.635,,0.000000e+000,5.499840e+001,4.787085e-006,0.000000e+000,3,9.155865e-001,0.000000e+000,,,,,,,,,,,,,,32,1,4.000000e+000,7.900238e-003,0.000000e+000,0,,0,
1524454513.595,,0.000000e+000,5.500169e+001,4.774447e-006,0.000000e+000,3,9.267057e-001,0.000000e+000,,,,,,,,,,,,,,32,1,4.000000e+000,9.208679e-003,0.000000e+000,0,,0,
1524454550.785,,0.000000e+000,5.499643e+001,4.794273e-006,0.000000e+000,3,9.186391e-001,0.000000e+000,,,,,,,,,,,,,,32,1,4.000000e+000,6.568909e-003,0.000000e+000,0,,0,
1524454588.695,,0.000000e+000,5.500037e+001,4.833335e-006,0.000000e+000,3,9.308767e-001,0.000000e+000,,,,,,,,,,,,,,32,1,4.000000e+000,1.319885e-003,0.000000e+000,0,,0,
1524454626.045,,0.000000e+000,5.499905e+001,4.781263e-006,0.000000e+000,3,9.234107e-001,0.000000e+000,,,,,,,,,,,,,,32,1,4.000000e+000,3.948212e-003,0.000000e+000,0,,0,
1524454663.805,,0.000000e+000,5.499773e+001,4.763605e-006,0.000000e+000,3,9.269125e-001,0.000000e+000,,,,,,,,,,,,,,32,1,4.000000e+000,1.308441e-003,0.000000e+000,0,,0,
1524454701.006,,0.000000e+000,5.500169e+001,4.737355e-006,0.000000e+000,3,9.338698e-001,0.000000e+000,,,,,,,,,,,,,,32,1,4.000000e+000,3.959656e-003,0.000000e+000,0,,0,
1524454738.866,,0.000000e+000,5.499248e+001,4.819975e-006,0.000000e+000,3,9.158483e-001,0.000000e+000,,,,,,,,,,,,,,32,1,4.000000e+000,1.319885e-003,0.000000e+000,0,,0,
1524454776.736,,0.000000e+000,5.499642e+001,4.758859e-006,0.000000e+000,3,9.270145e-001,0.000000e+000,,,,,,,,,,,,,,32,1,4.000000e+000,3.940582e-003,0.000000e+000,0,,0,
1524454814.356,,0.000000e+000,5.500695e+001,4.782882e-006,0.000000e+000,3,9.185911e-001,0.000000e+000,,,,,,,,,,,,,,32,1,4.000000e+000,6.568909e-003,0.000000e+000,0,,0,
1524454852.406,,0.000000e+000,5.499905e+001,4.753249e-006,0.000000e+000,3,9.278592e-001,0.000000e+000,,,,,,,,,,,,,,32,1,4.000000e+000,3.948212e-003,0.000000e+000,0,,0,
1524454890.046,,0.000000e+000,5.499445e+001,4.791895e-006,0.000000e+000,3,9.213355e-001,0.000000e+000,,,,,,,,,,,,,,32,1,4.000000e+000,1.052094e-002,0.000000e+000,0,,0,
1524454927.526,,0.000000e+000,5.499905e+001,4.846552e-006,0.000000e+000,3,9.234641e-001,0.000000e+000,,,,,,,,,,,,,,32,1,4.000000e+000,1.319885e-003,0.000000e+000,0,,0,
1524454965.196,,0.000000e+000,5.499511e+001,4.789366e-006,0.000000e+000,3,9.211316e-001,0.000000e+000,,,,,,,,,,,,,,32,1,4.000000e+000,3.940582e-003,0.000000e+000,0,,0,
1524455002.626,,0.000000e+000,5.499511e+001,4.767524e-006,0.000000e+000,3,9.365311e-001,0.000000e+000,,,,,,,,,,,,,,32,1,4.000000e+000,3.940582e-003,0.000000e+000,0,,0,
1524455040.526,,0.000000e+000,5.499577e+001,4.805065e-006,0.000000e+000,3,9.383256e-001,0.000000e+000,,,,,,,,,,,,,,32,1,4.000000e+000,1.316071e-002,0.000000e+000,0,,0,
1524455079.126,,0.000000e+000,5.498853e+001,4.840914e-006,0.000000e+000,3,9.145551e-001,0.000000e+000,,,,,,,,,,,,,,32,1,4.000000e+000,3.948212e-003,0.000000e+000,0,,0,
1524455117.176,,0.000000e+000,5.499445e+001,4.848167e-006,0.000000e+000,3,9.208745e-001,0.000000e+000,,,,,,,,,,,,,,32,1,4.000000e+000,1.314926e-002,0.000000e+000,0,,0,
1524455154.276,,0.000000e+000,5.499905e+001,4.806137e-006,0.000000e+000,3,9.198664e-001,0.000000e+000,,,,,,,,,,,,,,32,1,4.000000e+000,3.948212e-003,0.000000e+000,0,,0,
1524455192.366,,0.000000e+000,5.499839e+001,4.828837e-006,0.000000e+000,3,9.225100e-001,0.000000e+000,,,,,,,,,,,,,,32,1,4.000000e+000,0.000000e+000,0.000000e+000,0,,0,
1524455230.406,,0.000000e+000,5.500103e+001,4.701420e-006,0.000000e+000,3,9.275301e-001,0.000000e+000,,,,,,,,,,,,,,32,1,4.000000e+000,0.000000e+000,0.000000e+000,0,,0,
1524455268.196,,0.000000e+000,5.500563e+001,4.815087e-006,0.000000e+000,3,9.201096e-001,0.000000e+000,,,,,,,,,,,,,,32,1,4.000000e+000,9.208679e-003,0.000000e+000,0,,0,
1524455319.546,,0.000000e+000,5.499445e+001,4.742471e-006,0.000000e+000,3,9.306853e-001,0.000000e+000,,,,,,,,,,,,,,32,1,4.000000e+000,2.628326e-003,0.000000e+000,0,,0,
1524455357.276,,0.000000e+000,5.499511e+001,4.707854e-006,0.000000e+000,3,9.247619e-001,0.000000e+000,,,,,,,,,,,,,,32,1,4.000000e+000,1.319885e-003,0.000000e+000,0,,0,
1524455394.616,,0.000000e+000,5.499906e+001,4.676971e-006,0.000000e+000,3,9.239647e-001,0.000000e+000,,,,,,,,,,,,,,32,1,4.000000e+000,6.580353e-003,0.000000e+000,0,,0,
1524455432.377,,0.000000e+000,5.499775e+001,4.664525e-006,0.000000e+000,3,9.129460e-001,0.000000e+000,,,,,,,,,,,,,,32,1,4.000000e+000,9.208679e-003,0.000000e+000,0,,0,
1524455469.787,,0.000000e+000,5.499379e+001,4.559371e-006,0.000000e+000,3,9.189094e-001,0.000000e+000,,,,,,,,,,,,,,32,1,4.000000e+000,9.201050e-003,0.000000e+000,0,,0,
1524455507.227,,0.000000e+000,5.498919e+001,4.552881e-006,0.000000e+000,3,8.995432e-001,0.000000e+000,,,,,,,,,,,,,,32,1,4.000000e+000,5.260468e-003,0.000000e+000,0,,0,
1524455545.447,,0.000000e+000,5.499643e+001,4.546684e-006,0.000000e+000,3,9.226744e-001,0.000000e+000,,,,,,,,,,,,,,32,1,4.000000e+000,6.568909e-003,0.000000e+000,0,,0,
1524455582.377,,0.000000e+000,5.499773e+001,4.555834e-006,0.000000e+000,3,8.972793e-001,0.000000e+000,,,,,,,,,,,,,,32,1,4.000000e+000,1.308441e-003,0.000000e+000,0,,0,
1524455620.667,,0.000000e+000,5.499643e+001,4.522286e-006,0.000000e+000,3,9.074960e-001,0.000000e+000,,,,,,,,,,,,,,32,1,4.000000e+000,1.184082e-002,0.000000e+000,0,,0,
1524455658.847,,0.000000e+000,5.499774e+001,4.522210e-006,0.000000e+000,3,9.090448e-001,0.000000e+000,,,,,,,,,,,,,,32,1,4.000000e+000,3.940582e-003,0.000000e+000,0,,0,
1524455697.047,,0.000000e+000,5.499774e+001,4.596951e-006,0.000000e+000,3,9.095698e-001,0.000000e+000,,,,,,,,,,,,,,32,1,4.000000e+000,6.580353e-003,0.000000e+000,0,,0,
1524455734.777,,0.000000e+000,5.500497e+001,4.520072e-006,0.000000e+000,3,9.089417e-001,0.000000e+000,,,,,,,,,,,,,,32,1,4.000000e+000,0.000000e+000,0.000000e+000,0,,0,
1524455773.177,,0.000000e+000,5.500234e+001,4.526099e-006,0.000000e+000,3,9.135763e-001,0.000000e+000,,,,,,,,,,,,,,32,1,4.000000e+000,1.314926e-002,0.000000e+000,0,,0,
1524455810.677,,0.000000e+000,5.499445e+001,4.568691e-006,0.000000e+000,3,9.040594e-001,0.000000e+000,,,,,,,,,,,,,,32,1,4.000000e+000,2.628326e-003,0.000000e+000,0,,0,
1524455848.277,,0.000000e+000,5.500169e+001,4.565125e-006,0.000000e+000,3,9.330844e-001,0.000000e+000,,,,,,,,,,,,,,32,1,4.000000e+000,1.319885e-003,0.000000e+000,0,,0,
1524455886.817,,0.000000e+000,5.499380e+001,4.504665e-006,0.000000e+000,3,9.065171e-001,0.000000e+000,,,,,,,,,,,,,,32,1,4.000000e+000,1.446915e-002,0.000000e+000,0,,0,
1524455924.657,,0.000000e+000,5.499380e+001,4.578782e-006,0.000000e+000,3,9.027419e-001,0.000000e+000,,,,,,,,,,,,,,32,1,4.000000e+000,6.572723e-003,0.000000e+000,0,,0,
1524455962.727,,0.000000e+000,5.500300e+001,4.549950e-006,0.000000e+000,3,9.106133e-001,0.000000e+000,,,,,,,,,,,,,,32,1,4.000000e+000,9.220123e-003,0.000000e+000,0,,0,
1524456000.447,,0.000000e+000,5.500761e+001,4.566912e-006,0.000000e+000,3,9.036841e-001,0.000000e+000,,,,,,,,,,,,,,32,1,4.000000e+000,2.628326e-003,0.000000e+000,0,,0,
1524456038.217,,0.000000e+000,5.500037e+001,4.575880e-006,0.000000e+000,3,8.975798e-001,0.000000e+000,,,,,,,,,,,,,,32,1,4.000000e+000,3.959656e-003,0.000000e+000,0,,0,
1524456075.177,,0.000000e+000,5.499313e+001,4.480408e-006,0.000000e+000,3,9.024314e-001,0.000000e+000,,,,,,,,,,,,,,32,1,4.000000e+000,7.892609e-003,0.000000e+000,0,,0,
1524456113.147,,0.000000e+000,5.499906e+001,4.521169e-006,0.000000e+000,3,9.073810e-001,0.000000e+000,,,,,,,,,,,,,,32,1,4.000000e+000,6.580353e-003,0.000000e+000,0,,0,
1524456151.138,,0.000000e+000,5.499775e+001,4.447717e-006,0.000000e+000,3,9.254696e-001,0.000000e+000,,,,,,,,,,,,,,32,1,4.000000e+000,1.184845e-002,0.000000e+000,0,,0,
1524456189.358,,0.000000e+000,5.499774e+001,4.487112e-006,0.000000e+000,3,8.993036e-001,0.000000e+000,,,,,,,,,,,,,,32,1,4.000000e+000,6.580353e-003,0.000000e+000,0,,0,
1524456240.448,,0.000000e+000,5.500103e+001,4.477844e-006,0.000000e+000,3,9.131705e-001,0.000000e+000,,,,,,,,,,,,,,32,1,4.000000e+000,7.888794e-003,0.000000e+000,0,,0,
1524456278.668,,0.000000e+000,5.499511e+001,4.496756e-006,0.000000e+000,3,9.206321e-001,0.000000e+000,,,,,,,,,,,,,,32,1,4.000000e+000,1.319885e-003,0.000000e+000,0,,0,
1524456316.568,,0.000000e+000,5.500366e+001,4.510885e-006,0.000000e+000,3,9.114427e-001,0.000000e+000,,,,,,,,,,,,,,32,1,4.000000e+000,2.620697e-003,0.000000e+000,0,,0,
1524456354.228,,0.000000e+000,5.500300e+001,4.479109e-006,0.000000e+000,3,9.095367e-001,0.000000e+000,,,,,,,,,,,,,,32,1,4.000000e+000,1.183701e-002,0.000000e+000,0,,0,
1524456391.828,,0.000000e+000,5.499971e+001,4.517892e-006,0.000000e+000,3,8.980045e-001,0.000000e+000,,,,,,,,,,,,,,32,1,4.000000e+000,1.052094e-002,0.000000e+000,0,,0,
1524456429.898,,0.000000e+000,5.499709e+001,4.493270e-006,0.000000e+000,3,9.112300e-001,0.000000e+000,,,,,,,,,,,,,,32,1,4.000000e+000,7.888794e-003,0.000000e+000,0,,0,
1524456467.608,,0.000000e+000,5.500301e+001,4.571361e-006,0.000000e+000,3,9.040146e-001,0.000000e+000,,,,,,,,,,,,,,32,1,4.000000e+000,1.319885e-003,0.000000e+000,0,,0,
1524456505.588,,0.000000e+000,5.499972e+001,4.472875e-006,0.000000e+000,3,9.163509e-001,0.000000e+000,,,,,,,,,,,,,,32,1,4.000000e+000,7.900238e-003,0.000000e+000,0,,0,
1524456543.208,,0.000000e+000,5.499709e+001,4.530109e-006,0.000000e+000,3,9.000580e-001,0.000000e+000,,,,,,,,,,,,,,32,1,4.000000e+000,7.888794e-003,0.000000e+000,0,,0,
1524456580.688,,0.000000e+000,5.500103e+001,4.521263e-006,0.000000e+000,3,9.129757e-001,0.000000e+000,,,,,,,,,,,,,,32,1,4.000000e+000,2.639771e-003,0.000000e+000,0,,0,
1524456618.308,,0.000000e+000,5.500826e+001,4.493926e-006,0.000000e+000,3,8.997393e-001,0.000000e+000,,,,,,,,,,,,,,32,1,4.000000e+000,1.308441e-003,0.000000e+000,0,,0,
1524456656.368,,0.000000e+000,5.500037e+001,4.505765e-006,0.000000e+000,3,9.062375e-001,0.000000e+000,,,,,,,,,,,,,,32,1,4.000000e+000,9.201050e-003,0.000000e+000,0,,0,
1524456693.988,,0.000000e+000,5.499248e+001,4.562489e-006,0.000000e+000,3,9.000124e-001,0.000000e+000,,,,,,,,,,,,,,32,1,4.000000e+000,1.319885e-003,0.000000e+000,0,,0,
1524456732.048,,0.000000e+000,5.499511e+001,4.499719e-006,0.000000e+000,3,9.150095e-001,0.000000e+000,,,,,,,,,,,,,,32,1,4.000000e+000,1.319885e-003,0.000000e+000,0,,0,
1524456769.658,,0.000000e+000,5.499840e+001,4.531048e-006,0.000000e+000,3,9.011836e-001,0.000000e+000,,,,,,,,,,,,,,32,1,4.000000e+000,2.628326e-003,0.000000e+000,0,,0,
1524456807.708,,0.000000e+000,5.499971e+001,4.531622e-006,0.000000e+000,3,9.139169e-001,0.000000e+000,,,,,,,,,,,,,,32,1,4.000000e+000,2.639771e-003,0.000000e+000,0,,0,
1524456844.629,,0.000000e+000,5.499972e+001,4.558187e-006,0.000000e+000,3,9.016197e-001,0.000000e+000,,,,,,,,,,,,,,32,1,4.000000e+000,7.900238e-003,0.000000e+000,0,,0,
1524456882.289,,0.000000e+000,5.500235e+001,4.534520e-006,0.000000e+000,3,9.145062e-001,0.000000e+000,,,,,,,,,,,,,,32,1,4.000000e+000,1.840973e-002,0.000000e+000,0,,0,
1524456919.949,,0.000000e+000,5.499905e+001,4.552785e-006,0.000000e+000,3,9.025205e-001,0.000000e+000,,,,,,,,,,,,,,32,1,4.000000e+000,3.948212e-003,0.000000e+000,0,,0,
1524456957.969,,0.000000e+000,5.499051e+001,4.529120e-006,0.000000e+000,3,9.174361e-001,0.000000e+000,,,,,,,,,,,,,,32,1,4.000000e+000,5.260468e-003,0.000000e+000,0,,0,
1524456995.599,,0.000000e+000,5.500037e+001,4.478812e-006,0.000000e+000,3,8.972458e-001,0.000000e+000,,,,,,,,,,,,,,32,1,4.000000e+000,1.184082e-002,0.000000e+000,0,,0,
1524457033.669,,0.000000e+000,5.499313e+001,4.524917e-006,0.000000e+000,3,9.069023e-001,0.000000e+000,,,,,,,,,,,,,,32,1,4.000000e+000,2.628326e-003,0.000000e+000,0,,0,
1524457071.119,,0.000000e+000,5.499380e+001,4.563596e-006,0.000000e+000,3,9.187915e-001,0.000000e+000,,,,,,,,,,,,,,32,1,4.000000e+000,1.308441e-003,0.000000e+000,0,,0,
1524457109.009,,0.000000e+000,5.499906e+001,4.538928e-006,0.000000e+000,3,8.974578e-001,0.000000e+000,,,,,,,,,,,,,,32,1,4.000000e+000,9.220123e-003,0.000000e+000,0,,0,
1524457159.729,,0.000000e+000,5.500037e+001,4.518836e-006,0.000000e+000,3,9.088894e-001,0.000000e+000,,,,,,,,,,,,,,32,1,4.000000e+000,1.184082e-002,0.000000e+000,0,,0,
1524457197.589,,0.000000e+000,5.499445e+001,4.581657e-006,0.000000e+000,3,9.176252e-001,0.000000e+000,,,,,,,,,,,,,,32,1,4.000000e+000,7.881165e-003,0.000000e+000,0,,0,
1524457235.309,,0.000000e+000,5.500366e+001,4.559803e-006,0.000000e+000,3,9.116596e-001,0.000000e+000,,,,,,,,,,,,,,32,1,4.000000e+000,2.620697e-003,0.000000e+000,0,,0,
1524457273.299,,0.000000e+000,5.499445e+001,4.566457e-006,0.000000e+000,3,9.270613e-001,0.000000e+000,,,,,,,,,,,,,,32,1,4.000000e+000,1.052094e-002,0.000000e+000,0,,0,
1524457310.629,,0.000000e+000,5.499117e+001,4.579945e-006,0.000000e+000,3,9.135386e-001,0.000000e+000,,,,,,,,,,,,,,32,1,4.000000e+000,1.312256e-003,0.000000e+000,0,,0,
1524457347.919,,0.000000e+000,5.500103e+001,4.539632e-006,0.000000e+000,3,9.121935e-001,0.000000e+000,,,,,,,,,,,,,,32,1,4.000000e+000,0.000000e+000,0.000000e+000,0,,0,
1524457385.199,,0.000000e+000,5.499708e+001,4.598843e-006,0.000000e+000,3,9.041379e-001,0.000000e+000,,,,,,,,,,,,,,32,1,4.000000e+000,5.260468e-003,0.000000e+000,0,,0,
1524457423.159,,0.000000e+000,5.499511e+001,4.546707e-006,0.000000e+000,3,9.055485e-001,0.000000e+000,,,,,,,,,,,,,,32,1,4.000000e+000,3.940582e-003,0.000000e+000,0,,0,
1524457461.129,,0.000000e+000,5.499577e+001,4.517422e-006,0.000000e+000,3,9.130439e-001,0.000000e+000,,,,,,,,,,,,,,32,1,4.000000e+000,2.632141e-003,0.000000e+000,0,,0,
1524457498.859,,0.000000e+000,5.500169e+001,4.601827e-006,0.000000e+000,3,9.009142e-001,0.000000e+000,,,,,,,,,,,,,,32,1,4.000000e+000,1.319885e-003,0.000000e+000,0,,0,
1524457537.029,,0.000000e+000,5.499577e+001,4.907901e-006,0.000000e+000,3,9.261058e-001,0.000000e+000,,,,,,,,,,,,,,32,1,4.000000e+000,7.888794e-003,0.000000e+000,0,,0,
1524457574.700,,0.000000e+000,5.499709e+001,4.557799e-006,0.000000e+000,3,9.006317e-001,0.000000e+000,,,,,,,,,,,,,,32,1,4.000000e+000,7.888794e-003,0.000000e+000,0,,0,
1524457612.720,,0.000000e+000,5.499972e+001,4.578658e-006,0.000000e+000,3,9.117894e-001,0.000000e+000,,,,,,,,,,,,,,32,1,4.000000e+000,5.268097e-003,0.000000e+000,0,,0,
1524457650.340,,0.000000e+000,5.499643e+001,4.530189e-006,0.000000e+000,3,9.007239e-001,0.000000e+000,,,,,,,,,,,,,,32,1,4.000000e+000,6.568909e-003,0.000000e+000,0,,0,
1524457688.400,,0.000000e+000,5.499971e+001,4.560064e-006,0.000000e+000,3,9.138148e-001,0.000000e+000,,,,,,,,,,,,,,32,1,4.000000e+000,1.052094e-002,0.000000e+000,0,,0,
1524457726.070,,0.000000e+000,5.500432e+001,4.559688e-006,0.000000e+000,3,9.078833e-001,0.000000e+000,,,,,,,,,,,,,,32,1,4.000000e+000,1.710129e-002,0.000000e+000,0,,0,
1524457763.520,,0.000000e+000,5.499971e+001,4.553795e-006,0.000000e+000,3,9.110665e-001,0.000000e+000,,,,,,,,,,,,,,32,1,4.000000e+000,2.639771e-003,0.000000e+000,0,,0,
1524457800.780,,0.000000e+000,5.499313e+001,4.544084e-006,0.000000e+000,3,9.293886e-001,0.000000e+000,,,,,,,,,,,,,,32,1,4.000000e+000,7.892609e-003,0.000000e+000,0,,0,
1524457838.330,,0.000000e+000,5.499840e+001,4.594820e-006,0.000000e+000,3,9.014888e-001,0.000000e+000,,,,,,,,,,,,,,32,1,4.000000e+000,7.900238e-003,0.000000e+000,0,,0,
1524457876.470,,0.000000e+000,5.499512e+001,4.597850e-006,0.000000e+000,3,9.189336e-001,0.000000e+000,,,,,,,,,,,,,,32,1,4.000000e+000,1.710892e-002,0.000000e+000,0,,0,
1524457913.630,,0.000000e+000,5.500432e+001,4.599818e-006,0.000000e+000,3,9.043264e-001,0.000000e+000,,,,,,,,,,,,,,32,1,4.000000e+000,6.580353e-003,0.000000e+000,0,,0,
1524457951.380,,0.000000e+000,5.500432e+001,4.476906e-006,0.000000e+000,3,9.075655e-001,0.000000e+000,,,,,,,,,,,,,,32,1,4.000000e+000,3.940582e-003,0.000000e+000,0,,0,
1524457989.880,,0.000000e+000,5.499643e+001,4.507303e-006,0.000000e+000,3,9.146821e-001,0.000000e+000,,,,,,,,,,,,,,32,1,4.000000e+000,1.448059e-002,0.000000e+000,0,,0,
1524458027.760,,0.000000e+000,5.499840e+001,4.547222e-006,0.000000e+000,3,9.060471e-001,0.000000e+000,,,,,,,,,,,,,,32,1,4.000000e+000,5.260468e-003,0.000000e+000,0,,0,
1524458079.540,,0.000000e+000,5.499445e+001,4.504619e-006,0.000000e+000,3,9.162087e-001,0.000000e+000,,,,,,,,,,,,,,32,1,4.000000e+000,1.052094e-002,0.000000e+000,0,,0,
1524458117.240,,0.000000e+000,5.499577e+001,4.599795e-006,0.000000e+000,3,9.023608e-001,0.000000e+000,,,,,,,,,,,,,,32,1,4.000000e+000,7.888794e-003,0.000000e+000,0,,0,
1524458155.070,,0.000000e+000,5.500234e+001,4.505993e-006,0.000000e+000,3,9.182371e-001,0.000000e+000,,,,,,,,,,,,,,32,1,4.000000e+000,5.260468e-003,0.000000e+000,0,,0,
1524458192.330,,0.000000e+000,5.500234e+001,4.546982e-006,0.000000e+000,3,9.162059e-001,0.000000e+000,,,,,,,,,,,,,,32,1,4.000000e+000,5.260468e-003,0.000000e+000,0,,0,
1524458230.170,,0.000000e+000,5.500498e+001,4.502306e-006,0.000000e+000,3,9.123689e-001,0.000000e+000,,,,,,,,,,,,,,32,1,4.000000e+000,2.620697e-003,0.000000e+000,0,,0,
1524458267.661,,0.000000e+000,5.500300e+001,4.553953e-006,0.000000e+000,3,9.062600e-001,0.000000e+000,,,,,,,,,,,,,,32,1,4.000000e+000,6.580353e-003,0.000000e+000,0,,0,
1524458305.071,,0.000000e+000,5.499709e+001,4.506916e-006,0.000000e+000,3,9.106041e-001,0.000000e+000,,,,,,,,,,,,,,32,1,4.000000e+000,7.888794e-003,0.000000e+000,0,,0,
1524458342.981,,0.000000e+000,5.499117e+001,4.542257e-006,0.000000e+000,3,9.027212e-001,0.000000e+000,,,,,,,,,,,,,,32,1,4.000000e+000,1.708984e-002,0.000000e+000,0,,0,
1524458380.771,,0.000000e+000,5.499905e+001,4.519843e-006,0.000000e+000,3,9.108216e-001,0.000000e+000,,,,,,,,,,,,,,32,1,4.000000e+000,1.319885e-003,0.000000e+000,0,,0,
1524458418.241,,0.000000e+000,5.500103e+001,4.589849e-006,0.000000e+000,3,9.047190e-001,0.000000e+000,,,,,,,,,,,,,,32,1,4.000000e+000,0.000000e+000,0.000000e+000,0,,0,
1524458455.931,,0.000000e+000,5.499643e+001,4.507474e-006,0.000000e+000,3,9.068833e-001,0.000000e+000,,,,,,,,,,,,,,32,1,4.000000e+000,6.568909e-003,0.000000e+000,0,,0,
1524458493.251,,0.000000e+000,5.499709e+001,4.517151e-006,0.000000e+000,3,9.118491e-001,0.000000e+000,,,,,,,,,,,,,,32,1,4.000000e+000,7.888794e-003,0.000000e+000,0,,0,
1524458531.091,,0.000000e+000,5.499577e+001,4.557473e-006,0.000000e+000,3,9.123410e-001,0.000000e+000,,,,,,,,,,,,,,32,1,4.000000e+000,5.249023e-003,0.000000e+000,0,,0,
1524458568.501,,0.000000e+000,5.499643e+001,4.535028e-006,0.000000e+000,3,9.310126e-001,0.000000e+000,,,,,,,,,,,,,,32,1,4.000000e+000,1.312256e-003,0.000000e+000,0,,0,
1524458605.971,,0.000000e+000,5.500103e+001,4.548366e-006,0.000000e+000,3,9.147384e-001,0.000000e+000,,,,,,,,,,,,,,32,1,4.000000e+000,1.052094e-002,0.000000e+000,0,,0,
1524458644.371,,0.000000e+000,5.499709e+001,4.535751e-006,0.000000e+000,3,9.206816e-001,0.000000e+000,,,,,,,,,,,,,,32,1,4.000000e+000,7.888794e-003,0.000000e+000,0,,0,
1524458681.701,,0.000000e+000,5.500365e+001,4.610448e-006,0.000000e+000,3,9.005341e-001,0.000000e+000,,,,,,,,,,,,,,32,1,4.000000e+000,1.052856e-002,0.000000e+000,0,,0,
1524458719.341,,0.000000e+000,5.499182e+001,4.544968e-006,0.000000e+000,3,9.192671e-001,0.000000e+000,,,,,,,,,,,,,,32,1,4.000000e+000,1.052094e-002,0.000000e+000,0,,0,
1524458756.511,,0.000000e+000,5.500037e+001,4.506934e-006,0.000000e+000,3,9.142605e-001,0.000000e+000,,,,,,,,,,,,,,32,1,4.000000e+000,3.959656e-003,0.000000e+000,0,,0,
1524458794.431,,0.000000e+000,5.499773e+001,4.545203e-006,0.000000e+000,3,9.109671e-001,0.000000e+000,,,,,,,,,,,,,,32,1,4.000000e+000,1.308441e-003,0.000000e+000,0,,0,
1524458832.621,,0.000000e+000,5.499380e+001,4.489732e-006,0.000000e+000,3,9.160497e-001,0.000000e+000,,,,,,,,,,,,,,32,1,4.000000e+000,3.948212e-003,0.000000e+000,0,,0,
1524458870.571,,0.000000e+000,5.500103e+001,4.573043e-006,0.000000e+000,3,9.049765e-001,0.000000e+000,,,,,,,,,,,,,,32,1,4.000000e+000,0.000000e+000,0.000000e+000,0,,0,
1524458908.521,,0.000000e+000,5.499642e+001,4.573480e-006,0.000000e+000,3,9.150953e-001,0.000000e+000,,,,,,,,,,,,,,32,1,4.000000e+000,3.940582e-003,0.000000e+000,0,,0,
1524458946.371,,0.000000e+000,5.499773e+001,4.531842e-006,0.000000e+000,3,9.242861e-001,0.000000e+000,,,,,,,,,,,,,,32,1,4.000000e+000,1.308441e-003,0.000000e+000,0,,0,
1524458998.222,,0.000000e+000,5.499511e+001,4.513498e-006,0.000000e+000,3,9.104974e-001,0.000000e+000,,,,,,,,,,,,,,32,1,4.000000e+000,1.319885e-003,0.000000e+000,0,,0,
1524459035.992,,0.000000e+000,5.499445e+001,4.531840e-006,0.000000e+000,3,9.013516e-001,0.000000e+000,,,,,,,,,,,,,,32,1,4.000000e+000,5.260468e-003,0.000000e+000,0,,0,
1524459073.902,,0.000000e+000,5.500497e+001,4.536580e-006,0.000000e+000,3,9.177008e-001,0.000000e+000,,,,,,,,,,,,,,32,1,4.000000e+000,1.052856e-002,0.000000e+000,0,,0,
1524459111.652,,0.000000e+000,5.499642e+001,4.487273e-006,0.000000e+000,3,8.984569e-001,0.000000e+000,,,,,,,,,,,,,,32,1,4.000000e+000,3.940582e-003,0.000000e+000,0,,0,
1524459149.562,,0.000000e+000,5.499117e+001,4.493367e-006,0.000000e+000,3,9.049781e-001,0.000000e+000,,,,,,,,,,,,,,32,1,4.000000e+000,3.952026e-003,0.000000e+000,0,,0,
1524459187.322,,0.000000e+000,5.499380e+001,4.569512e-006,0.000000e+000,3,9.002025e-001,0.000000e+000,,,,,,,,,,,,,,32,1,4.000000e+000,3.948212e-003,0.000000e+000,0,,0,
1524459225.242,,0.000000e+000,5.499972e+001,4.543713e-006,0.000000e+000,3,9.144800e-001,0.000000e+000,,,,,,,,,,,,,,32,1,4.000000e+000,1.578903e-002,0.000000e+000,0,,0,
1524459262.672,,0.000000e+000,5.500037e+001,4.590304e-006,0.000000e+000,3,9.038177e-001,0.000000e+000,,,,,,,,,,,,,,32,1,4.000000e+000,9.201050e-003,0.000000e+000,0,,0,
1524459300.352,,0.000000e+000,5.499906e+001,4.538178e-006,0.000000e+000,3,9.144937e-001,0.000000e+000,,,,,,,,,,,,,,32,1,4.000000e+000,1.710129e-002,0.000000e+000,0,,0,
1524459338.102,,0.000000e+000,5.499577e+001,4.630349e-006,0.000000e+000,3,9.089913e-001,0.000000e+000,,,,,,,,,,,,,,32,1,4.000000e+000,5.249023e-003,0.000000e+000,0,,0,
1524459376.012,,0.000000e+000,5.499773e+001,4.689147e-006,0.000000e+000,3,9.244923e-001,0.000000e+000,,,,,,,,,,,,,,32,1,4.000000e+000,1.308441e-003,0.000000e+000,0,,0,
1524459413.782,,0.000000e+000,5.499643e+001,4.733893e-006,0.000000e+000,3,9.162068e-001,0.000000e+000,,,,,,,,,,,,,,32,1,4.000000e+000,9.208679e-003,0.000000e+000,0,,0,
1524459451.452,,0.000000e+000,5.500169e+001,4.626548e-006,0.000000e+000,3,9.269328e-001,0.000000e+000,,,,,,,,,,,,,,32,1,4.000000e+000,3.959656e-003,0.000000e+000,0,,0,
1524459489.872,,0.000000e+000,5.499511e+001,4.740426e-006,0.000000e+000,3,9.219069e-001,0.000000e+000,,,,,,,,,,,,,,32,1,4.000000e+000,3.940582e-003,0.000000e+000,0,,0,
1524459527.542,,0.000000e+000,5.499971e+001,4.697045e-006,0.000000e+000,3,9.077334e-001,0.000000e+000,,,,,,,,,,,,,,32,1,4.000000e+000,0.000000e+000,0.000000e+000,0,,0,
1524459565.532,,0.000000e+000,5.500234e+001,4.642146e-006,0.000000e+000,3,9.328524e-001,0.000000e+000,,,,,,,,,,,,,,32,1,4.000000e+000,7.900238e-003,0.000000e+000,0,,0,
1524459603.092,,0.000000e+000,5.500234e+001,4.756868e-006,0.000000e+000,3,9.220681e-001,0.000000e+000,,,,,,,,,,,,,,32,1,4.000000e+000,5.260468e-003,0.000000e+000,0,,0,
1524459641.262,,0.000000e+000,5.499642e+001,4.727726e-006,0.000000e+000,3,9.323469e-001,0.000000e+000,,,,,,,,,,,,,,32,1,4.000000e+000,3.940582e-003,0.000000e+000,0,,0,
1524459678.802,,0.000000e+000,5.500235e+001,4.832302e-006,0.000000e+000,3,9.291081e-001,0.000000e+000,,,,,,,,,,,,,,32,1,4.000000e+000,2.639771e-003,0.000000e+000,0,,0,
1524459716.773,,0.000000e+000,5.500037e+001,4.899934e-006,0.000000e+000,3,9.294034e-001,0.000000e+000,,,,,,,,,,,,,,32,1,4.000000e+000,6.587982e-003,0.000000e+000,0,,0,
1524459754.453,,0.000000e+000,5.500234e+001,4.765308e-006,0.000000e+000,3,9.280270e-001,0.000000e+000,,,,,,,,,,,,,,32,1,4.000000e+000,1.314926e-002,0.000000e+000,0,,0,
1524459792.433,,0.000000e+000,5.499708e+001,4.840234e-006,0.000000e+000,3,9.266750e-001,0.000000e+000,,,,,,,,,,,,,,32,1,4.000000e+000,5.260468e-003,0.000000e+000,0,,0,
1524459830.143,,0.000000e+000,5.500103e+001,4.785785e-006,0.000000e+000,3,9.233425e-001,0.000000e+000,,,,,,,,,,,,,,32,1,4.000000e+000,2.639771e-003,0.000000e+000,0,,0,
1524459881.583,,0.000000e+000,5.499840e+001,4.791099e-006,0.000000e+000,3,9.416724e-001,0.000000e+000,,,,,,,,,,,,,,32,1,4.000000e+000,5.260468e-003,0.000000e+000,0,,0,
1524459919.493,,0.000000e+000,5.499840e+001,4.865329e-006,0.000000e+000,3,9.177846e-001,0.000000e+000,,,,,,,,,,,,,,32,1,4.000000e+000,7.900238e-003,0.000000e+000,0,,0,
1524459957.463,,0.000000e+000,5.500037e+001,4.854308e-006,0.000000e+000,3,9.349820e-001,0.000000e+000,,,,,,,,,,,,,,32,1,4.000000e+000,1.184082e-002,0.000000e+000,0,,0,
1524459994.823,,0.000000e+000,5.500037e+001,4.870944e-006,0.000000e+000,3,9.198245e-001,0.000000e+000,,,,,,,,,,,,,,32,1,4.000000e+000,1.184082e-002,0.000000e+000,0,,0,
1524460032.143,,0.000000e+000,5.499445e+001,4.859141e-006,0.000000e+000,3,9.419197e-001,0.000000e+000,,,,,,,,,,,,,,32,1,4.000000e+000,1.052094e-002,0.000000e+000,0,,0,
1524460069.963,,0.000000e+000,5.499445e+001,4.789690e-006,0.000000e+000,3,9.168328e-001,0.000000e+000,,,,,,,,,,,,,,32,1,4.000000e+000,1.314926e-002,0.000000e+000,0,,0,
1524460107.663,,0.000000e+000,5.499841e+001,4.876320e-006,0.000000e+000,3,9.159874e-001,0.000000e+000,,,,,,,,,,,,,,32,1,4.000000e+000,1.052856e-002,0.000000e+000,0,,0,
1524460145.313,,0.000000e+000,5.499709e+001,4.821948e-006,0.000000e+000,3,9.223483e-001,0.000000e+000,,,,,,,,,,,,,,32,1,4.000000e+000,7.888794e-003,0.000000e+000,0,,0,
1524460182.883,,0.000000e+000,5.499577e+001,4.906342e-006,0.000000e+000,3,9.198561e-001,0.000000e+000,,,,,,,,,,,,,,32,1,4.000000e+000,1.052094e-002,0.000000e+000,0,,0,
1524460220.843,,0.000000e+000,5.499643e+001,4.861644e-006,0.000000e+000,3,9.228830e-001,0.000000e+000,,,,,,,,,,,,,,32,1,4.000000e+000,6.568909e-003,0.000000e+000,0,,0,
1524460258.453,,0.000000e+000,5.499051e+001,4.850539e-006,0.000000e+000,3,9.294313e-001,0.000000e+000,,,,,,,,,,,,,,32,1,4.000000e+000,1.315308e-002,0.000000e+000,0,,0,
1524460295.803,,0.000000e+000,5.499971e+001,4.849739e-006,0.000000e+000,3,9.360169e-001,0.000000e+000,,,,,,,,,,,,,,32,1,4.000000e+000,1.840973e-002,0.000000e+000,0,,0,
1524460333.743,,0.000000e+000,5.499906e+001,4.787596e-006,0.000000e+000,3,9.145480e-001,0.000000e+000,,,,,,,,,,,,,,32,1,4.000000e+000,9.220123e-003,0.000000e+000,0,,0,
1524460371.583,,0.000000e+000,5.499905e+001,4.849205e-006,0.000000e+000,3,9.166244e-001,0.000000e+000,,,,,,,,,,,,,,32,1,4.000000e+000,1.972961e-002,0.000000e+000,0,,0,
1524460409.434,,0.000000e+000,5.499577e+001,4.793332e-006,0.000000e+000,3,9.278140e-001,0.000000e+000,,,,,,,,,,,,,,32,1,4.000000e+000,5.249023e-003,0.000000e+000,0,,0,
1524460447.154,,0.000000e+000,5.499905e+001,4.806171e-006,0.000000e+000,3,9.191625e-001,0.000000e+000,,,,,,,,,,,,,,32,1,4.000000e+000,1.182938e-002,0.000000e+000,0,,0,
1524460484.704,,0.000000e+000,5.500169e+001,4.825988e-006,0.000000e+000,3,9.223197e-001,0.000000e+000,,,,,,,,,,,,,,32,1,4.000000e+000,1.709747e-002,0.000000e+000,0,,0,
1524460521.784,,0.000000e+000,5.499972e+001,4.788592e-006,0.000000e+000,3,9.402110e-001,0.000000e+000,,,,,,,,,,,,,,32,1,4.000000e+000,5.268097e-003,0.000000e+000,0,,0,
1524460559.004,,0.000000e+000,5.500498e+001,4.799174e-006,0.000000e+000,3,9.211653e-001,0.000000e+000,,,,,,,,,,,,,,32,1,4.000000e+000,2.620697e-003,0.000000e+000,0,,0,
1524460597.204,,0.000000e+000,5.499380e+001,4.791219e-006,0.000000e+000,3,9.128627e-001,0.000000e+000,,,,,,,,,,,,,,32,1,4.000000e+000,1.182938e-002,0.000000e+000,0,,0,
1524460635.034,,0.000000e+000,5.499314e+001,4.799529e-006,0.000000e+000,3,9.326192e-001,0.000000e+000,,,,,,,,,,,,,,32,1,4.000000e+000,0.000000e+000,0.000000e+000,0,,0,
1524460672.734,,0.000000e+000,5.499840e+001,4.771580e-006,0.000000e+000,3,9.165094e-001,0.000000e+000,,,,,,,,,,,,,,32,1,4.000000e+000,5.260468e-003,0.000000e+000,0,,0,
1524460710.764,,0.000000e+000,5.499971e+001,4.764526e-006,0.000000e+000,3,9.266046e-001,0.000000e+000,,,,,,,,,,,,,,32,1,4.000000e+000,0.000000e+000,0.000000e+000,0,,0,
1524460748.474,,0.000000e+000,5.499905e+001,4.824235e-006,0.000000e+000,3,9.252816e-001,0.000000e+000,,,,,,,,,,,,,,32,1,4.000000e+000,1.182938e-002,0.000000e+000,0,,0,
1524460773.834,,0.000000e+000,5.499841e+001,4.847311e-006,0.000000e+000,3,9.360018e-001,0.000000e+000,,,,,,,,,,,,,,32,1,4.000000e+000,1.052856e-002,0.000000e+000,0,,0,