File: Experimental Raw Data/TC04-12-01K TRMac VRMde/Ndat/TC04-12-01K_TRMac_58K_0.08Kmin_VRMde_55K.dc.dat
[Header]
TITLE,MPMS DC Measurement
BYAPP,MPMS Measurement,2.1,Summary
FILEOPENTIME, 1524469973.107000 4/23/2018, 1:52:53 AM

INFO, APPNAME, MPMS MultiVu Application, Revision 1.61,  Build 082

INFO, NAME, TC04-12-01K
INFO, WEIGHT, 1.000
INFO, AREA, 1.000
INFO, LENGTH, 1.000
INFO, SHAPE, 0
INFO, COMMENT,
INFO, SEQUENCE FILE: TRMac_58K_0.08Kmin_VRMde_55K.seq


INFO, BACKGROUND DATA FILE:, None


STARTUPAXIS,X,4,LINEAR,AUTO,0.000000,0.000000
STARTUPAXIS,Y1,5,LINEAR,AUTO,0.000000,0.000000


STARTUPGROUP,Longitudinal
FIELDGROUP,Longitudinal,1,2,3,4,5,6,7,8,9,15,16,17,18,27,28
FIELDGROUP,Transverse,1,2,3,4,10,11,12,13,14,19,20,21,22,27,28

PLOT_APPEARANCE,ALL,HORZ_GRID_ON,VERT_GRID_ON,MARKERS_AND_LINES

[Data]
Time,Comment,Field (Oe),Temperature (K),Long Moment (emu),Long Scan Std Dev,Long Algorithm,Long Reg Fit,Long Percent Error (%),Trans Moment (emu),Trans Scan Std Dev,Trans Algorithm,Trans Reg Fit,Trans Percent Error (%),Long Moment [w/o ABS] (emu),Long Scan Std Dev [w/o ABS],Long Reg Fit [w/o ABS],Long Percent Error [w/o ABS] (%),Trans Moment [w/o ABS] (emu),Trans Scan Std Dev [w/o ABS],Trans Reg Fit [w/o ABS],Trans Percent Error [w/o ABS] (%),Points per Scan,Scans per Measurement,Scan Length (cm),Delta Temp (K),Rot Position (deg),Error,EC Comp. Running,Using ABS,
1524469973.107,,0.000000e+000,5.498853e+001,-1.203085e-005,0.000000e+000,3,9.706129e-001,0.000000e+000,,,,,,,,,,,,,,32,1,4.000000e+000,6.572723e-003,0.000000e+000,0,,0,
1524470013.077,,0.000000e+000,5.499248e+001,-9.073531e-006,0.000000e+000,3,9.609459e-001,0.000000e+000,,,,,,,,,,,,,,32,1,4.000000e+000,3.940582e-003,0.000000e+000,0,,0,
1524470051.317,,0.000000e+000,5.499905e+001,-7.497855e-006,0.000000e+000,3,9.457945e-001,0.000000e+000,,,,,,,,,,,,,,32,1,4.000000e+000,1.319885e-003,0.000000e+000,0,,0,
1524470089.197,,0.000000e+000,5.499314e+001,-6.344632e-006,0.000000e+000,3,9.344508e-001,0.000000e+000,,,,,,,,,,,,,,32,1,4.000000e+000,0.000000e+000,0.000000e+000,0,,0,
1524470127.217,,0.000000e+000,5.500037e+001,-5.632998e-006,0.000000e+000,3,9.425196e-001,0.000000e+000,,,,,,,,,,,,,,32,1,4.000000e+000,1.319885e-003,0.000000e+000,0,,0,
1524470164.317,,0.000000e+000,5.500037e+001,-5.063430e-006,0.000000e+000,3,9.171523e-001,0.000000e+000,,,,,,,,,,,,,,32,1,4.000000e+000,3.959656e-003,0.000000e+000,0,,0,
1524470202.227,,0.000000e+000,5.500300e+001,-4.543530e-006,0.000000e+000,3,9.245812e-001,0.000000e+000,,,,,,,,,,,,,,32,1,4.000000e+000,6.580353e-003,0.000000e+000,0,,0,
1524470239.777,,0.000000e+000,5.499577e+001,-4.287339e-006,0.000000e+000,3,9.125407e-001,0.000000e+000,,,,,,,,,,,,,,32,1,4.000000e+000,7.888794e-003,0.000000e+000,0,,0,
1524470277.637,,0.000000e+000,5.500366e+001,-3.874342e-006,0.000000e+000,3,9.058437e-001,0.000000e+000,,,,,,,,,,,,,,32,1,4.000000e+000,2.620697e-003,0.000000e+000,0,,0,
1524470315.897,,0.000000e+000,5.500761e+001,-3.473241e-006,0.000000e+000,3,8.924438e-001,0.000000e+000,,,,,,,,,,,,,,32,1,4.000000e+000,0.000000e+000,0.000000e+000,0,,0,
1524470353.397,,0.000000e+000,5.500235e+001,-3.272500e-006,0.000000e+000,3,8.831025e-001,0.000000e+000,,,,,,,,,,,,,,32,1,4.000000e+000,1.052856e-002,0.000000e+000,0,,0,
1524470391.587,,0.000000e+000,5.500103e+001,-3.004409e-006,0.000000e+000,3,8.820870e-001,0.000000e+000,,,,,,,,,,,,,,32,1,4.000000e+000,0.000000e+000,0.000000e+000,0,,0,
1524470428.728,,0.000000e+000,5.500103e+001,-2.760076e-006,0.000000e+000,3,8.857108e-001,0.000000e+000,,,,,,,,,,,,,,32,1,4.000000e+000,0.000000e+000,0.000000e+000,0,,0,
1524470465.788,,0.000000e+000,5.500300e+001,-2.697833e-006,0.000000e+000,3,8.458008e-001,0.000000e+000,,,,,,,,,,,,,,32,1,4.000000e+000,3.940582e-003,0.000000e+000,0,,0,
1524470503.858,,0.000000e+000,5.499512e+001,-2.553211e-006,0.000000e+000,3,8.621204e-001,0.000000e+000,,,,,,,,,,,,,,32,1,4.000000e+000,1.710892e-002,0.000000e+000,0,,0,
1524470541.478,,0.000000e+000,5.499774e+001,-2.409851e-006,0.000000e+000,3,8.302162e-001,0.000000e+000,,,,,,,,,,,,,,32,1,4.000000e+000,6.580353e-003,0.000000e+000,0,,0,
1524470579.368,,0.000000e+000,5.499905e+001,-2.303688e-006,0.000000e+000,3,8.349184e-001,0.000000e+000,,,,,,,,,,,,,,32,1,4.000000e+000,1.319885e-003,0.000000e+000,0,,0,
1524470617.148,,0.000000e+000,5.499708e+001,-2.204347e-006,0.000000e+000,3,8.112200e-001,0.000000e+000,,,,,,,,,,,,,,32,1,4.000000e+000,2.620697e-003,0.000000e+000,0,,0,
1524470654.268,,0.000000e+000,5.499775e+001,-2.143265e-006,0.000000e+000,3,8.114368e-001,0.000000e+000,,,,,,,,,,,,,,32,1,4.000000e+000,9.208679e-003,0.000000e+000,0,,0,
1524470692.268,,0.000000e+000,5.500037e+001,-2.040557e-006,0.000000e+000,3,7.716713e-001,0.000000e+000,,,,,,,,,,,,,,32,1,4.000000e+000,9.201050e-003,0.000000e+000,0,,0,
1524470730.118,,0.000000e+000,5.499511e+001,-2.006313e-006,0.000000e+000,3,7.837616e-001,0.000000e+000,,,,,,,,,,,,,,32,1,4.000000e+000,3.940582e-003,0.000000e+000,0,,0,
1524470768.128,,0.000000e+000,5.499972e+001,-1.930395e-006,0.000000e+000,3,7.673502e-001,0.000000e+000,,,,,,,,,,,,,,32,1,4.000000e+000,5.268097e-003,0.000000e+000,0,,0,
1524470811.442,,0.000000e+000,5.500037e+001,-4.665864e-007,0.000000e+000,2,0.000000e+000,0.000000e+000,,,,,,,,,,,,,,32,1,4.000000e+000,9.201050e-003,0.000000e+000,0,,0,
1524470855.058,,0.000000e+000,5.499380e+001,-3.133877e-007,0.000000e+000,2,0.000000e+000,0.000000e+000,,,,,,,,,,,,,,32,1,4.000000e+000,1.182938e-002,0.000000e+000,0,,0,
1524470908.102,,0.000000e+000,5.500037e+001,1.932827e-006,0.000000e+000,3,6.069722e-001,0.000000e+000,,,,,,,,,,,,,,32,1,4.000000e+000,1.319885e-003,0.000000e+000,0,,0,
1524470945.932,,0.000000e+000,5.500300e+001,1.969836e-006,0.000000e+000,3,6.075655e-001,0.000000e+000,,,,,,,,,,,,,,32,1,4.000000e+000,6.580353e-003,0.000000e+000,0,,0,
1524470985.094,,0.000000e+000,5.499709e+001,-3.387875e-008,0.000000e+000,2,0.000000e+000,0.000000e+000,,,,,,,,,,,,,,32,1,4.000000e+000,1.052856e-002,0.000000e+000,0,,0,
1524471022.314,,0.000000e+000,5.499313e+001,1.839113e-006,0.000000e+000,3,6.545454e-001,0.000000e+000,,,,,,,,,,,,,,32,1,4.000000e+000,2.628326e-003,0.000000e+000,0,,0,
1524471062.126,,0.000000e+000,5.499577e+001,-1.993214e-006,0.000000e+000,3,7.117770e-001,0.000000e+000,,,,,,,,,,,,,,32,1,4.000000e+000,7.888794e-003,0.000000e+000,0,,0,
1524471099.666,,0.000000e+000,5.499642e+001,-2.049060e-006,0.000000e+000,3,6.930246e-001,0.000000e+000,,,,,,,,,,,,,,32,1,4.000000e+000,3.940582e-003,0.000000e+000,0,,0,
1524471141.091,,0.000000e+000,5.499643e+001,3.619863e-007,0.000000e+000,2,0.000000e+000,0.000000e+000,,,,,,,,,,,,,,32,1,4.000000e+000,9.208679e-003,0.000000e+000,0,,0,
1524471184.517,,0.000000e+000,5.499445e+001,4.641037e-007,0.000000e+000,2,0.000000e+000,0.000000e+000,,,,,,,,,,,,,,32,1,4.000000e+000,5.260468e-003,0.000000e+000,0,,0,
1524471227.203,,0.000000e+000,5.499511e+001,4.727602e-007,0.000000e+000,2,0.000000e+000,0.000000e+000,,,,,,,,,,,,,,32,1,4.000000e+000,6.568909e-003,0.000000e+000,0,,0,
1524471269.649,,0.000000e+000,5.499840e+001,5.400698e-007,0.000000e+000,2,0.000000e+000,0.000000e+000,,,,,,,,,,,,,,32,1,4.000000e+000,5.260468e-003,0.000000e+000,0,,0,
1524471310.603,,0.000000e+000,5.500037e+001,6.080996e-007,0.000000e+000,2,0.000000e+000,0.000000e+000,,,,,,,,,,,,,,32,1,4.000000e+000,1.319885e-003,0.000000e+000,0,,0,
1524471347.173,,0.000000e+000,5.499774e+001,1.951726e-006,0.000000e+000,3,7.072966e-001,0.000000e+000,,,,,,,,,,,,,,32,1,4.000000e+000,6.580353e-003,0.000000e+000,0,,0,
1524471384.923,,0.000000e+000,5.499643e+001,1.874627e-006,0.000000e+000,3,6.948407e-001,0.000000e+000,,,,,,,,,,,,,,32,1,4.000000e+000,1.312256e-003,0.000000e+000,0,,0,
1524471423.073,,0.000000e+000,5.499775e+001,1.879718e-006,0.000000e+000,3,7.261611e-001,0.000000e+000,,,,,,,,,,,,,,32,1,4.000000e+000,9.208679e-003,0.000000e+000,0,,0,
1524471461.563,,0.000000e+000,5.499511e+001,1.914449e-006,0.000000e+000,3,6.837418e-001,0.000000e+000,,,,,,,,,,,,,,32,1,4.000000e+000,1.319885e-003,0.000000e+000,0,,0,
1524471498.953,,0.000000e+000,5.499248e+001,1.895585e-006,0.000000e+000,3,7.148478e-001,0.000000e+000,,,,,,,,,,,,,,32,1,4.000000e+000,1.319885e-003,0.000000e+000,0,,0,
1524471536.293,,0.000000e+000,5.499314e+001,1.981700e-006,0.000000e+000,3,7.134012e-001,0.000000e+000,,,,,,,,,,,,,,32,1,4.000000e+000,0.000000e+000,0.000000e+000,0,,0,
1524471574.243,,0.000000e+000,5.499643e+001,1.976594e-006,0.000000e+000,3,7.182767e-001,0.000000e+000,,,,,,,,,,,,,,32,1,4.000000e+000,9.208679e-003,0.000000e+000,0,,0,
1524471611.533,,0.000000e+000,5.499840e+001,2.110023e-006,0.000000e+000,3,7.891743e-001,0.000000e+000,,,,,,,,,,,,,,32,1,4.000000e+000,7.900238e-003,0.000000e+000,0,,0,
1524471649.323,,0.000000e+000,5.499577e+001,1.927158e-006,0.000000e+000,3,7.377024e-001,0.000000e+000,,,,,,,,,,,,,,32,1,4.000000e+000,5.249023e-003,0.000000e+000,0,,0,
1524471688.103,,0.000000e+000,5.500037e+001,1.960809e-006,0.000000e+000,3,7.436039e-001,0.000000e+000,,,,,,,,,,,,,,32,1,4.000000e+000,6.587982e-003,0.000000e+000,0,,0,
1524471725.413,,0.000000e+000,5.499905e+001,2.048958e-006,0.000000e+000,3,7.564742e-001,0.000000e+000,,,,,,,,,,,,,,32,1,4.000000e+000,1.446915e-002,0.000000e+000,0,,0,
1524471763.183,,0.000000e+000,5.499709e+001,2.043282e-006,0.000000e+000,3,7.779738e-001,0.000000e+000,,,,,,,,,,,,,,32,1,4.000000e+000,1.052856e-002,0.000000e+000,0,,0,
1524471801.683,,0.000000e+000,5.500235e+001,2.036379e-006,0.000000e+000,3,7.959129e-001,0.000000e+000,,,,,,,,,,,,,,32,1,4.000000e+000,0.000000e+000,0.000000e+000,0,,0,
1524471853.294,,0.000000e+000,5.499840e+001,2.090757e-006,0.000000e+000,3,7.420572e-001,0.000000e+000,,,,,,,,,,,,,,32,1,4.000000e+000,5.260468e-003,0.000000e+000,0,,0,
1524471891.434,,0.000000e+000,5.500103e+001,2.198861e-006,0.000000e+000,3,7.715235e-001,0.000000e+000,,,,,,,,,,,,,,32,1,4.000000e+000,2.639771e-003,0.000000e+000,0,,0,
1524471929.114,,0.000000e+000,5.499840e+001,2.226473e-006,0.000000e+000,3,7.480723e-001,0.000000e+000,,,,,,,,,,,,,,32,1,4.000000e+000,2.628326e-003,0.000000e+000,0,,0,
1524471967.114,,0.000000e+000,5.499445e+001,2.218088e-006,0.000000e+000,3,7.759888e-001,0.000000e+000,,,,,,,,,,,,,,32,1,4.000000e+000,5.260468e-003,0.000000e+000,0,,0,
1524472004.434,,0.000000e+000,5.499643e+001,2.302030e-006,0.000000e+000,3,7.601144e-001,0.000000e+000,,,,,,,,,,,,,,32,1,4.000000e+000,1.312256e-003,0.000000e+000,0,,0,
1524472042.794,,0.000000e+000,5.500431e+001,2.474552e-006,0.000000e+000,3,7.963529e-001,0.000000e+000,,,,,,,,,,,,,,32,1,4.000000e+000,1.184845e-002,0.000000e+000,0,,0,
1524472080.424,,0.000000e+000,5.499773e+001,2.463284e-006,0.000000e+000,3,8.082256e-001,0.000000e+000,,,,,,,,,,,,,,32,1,4.000000e+000,1.308441e-003,0.000000e+000,0,,0,
1524472118.554,,0.000000e+000,5.499577e+001,2.454397e-006,0.000000e+000,3,7.843376e-001,0.000000e+000,,,,,,,,,,,,,,32,1,4.000000e+000,1.052094e-002,0.000000e+000,0,,0,
1524472155.754,,0.000000e+000,5.500103e+001,2.462079e-006,0.000000e+000,3,8.138057e-001,0.000000e+000,,,,,,,,,,,,,,32,1,4.000000e+000,2.639771e-003,0.000000e+000,0,,0,
1524472193.564,,0.000000e+000,5.499643e+001,2.526328e-006,0.000000e+000,3,8.026731e-001,0.000000e+000,,,,,,,,,,,,,,32,1,4.000000e+000,1.184082e-002,0.000000e+000,0,,0,
1524472231.174,,0.000000e+000,5.499577e+001,2.553182e-006,0.000000e+000,3,7.960039e-001,0.000000e+000,,,,,,,,,,,,,,32,1,4.000000e+000,2.632141e-003,0.000000e+000,0,,0,
1524472269.244,,0.000000e+000,5.499643e+001,2.583216e-006,0.000000e+000,3,8.096378e-001,0.000000e+000,,,,,,,,,,,,,,32,1,4.000000e+000,6.568909e-003,0.000000e+000,0,,0,
1524472306.974,,0.000000e+000,5.500366e+001,2.556032e-006,0.000000e+000,3,8.098460e-001,0.000000e+000,,,,,,,,,,,,,,32,1,4.000000e+000,2.620697e-003,0.000000e+000,0,,0,
1524472344.884,,0.000000e+000,5.500037e+001,2.656269e-006,0.000000e+000,3,8.202219e-001,0.000000e+000,,,,,,,,,,,,,,32,1,4.000000e+000,1.319885e-003,0.000000e+000,0,,0,
1524472382.534,,0.000000e+000,5.499774e+001,2.629394e-006,0.000000e+000,3,8.183438e-001,0.000000e+000,,,,,,,,,,,,,,32,1,4.000000e+000,1.446152e-002,0.000000e+000,0,,0,
1524472420.524,,0.000000e+000,5.499774e+001,2.673888e-006,0.000000e+000,3,8.223073e-001,0.000000e+000,,,,,,,,,,,,,,32,1,4.000000e+000,6.580353e-003,0.000000e+000,0,,0,
1524472458.164,,0.000000e+000,5.499511e+001,2.760760e-006,0.000000e+000,3,8.201824e-001,0.000000e+000,,,,,,,,,,,,,,32,1,4.000000e+000,3.940582e-003,0.000000e+000,0,,0,
1524472496.184,,0.000000e+000,5.499313e+001,2.660621e-006,0.000000e+000,3,8.185027e-001,0.000000e+000,,,,,,,,,,,,,,32,1,4.000000e+000,1.050949e-002,0.000000e+000,0,,0,
1524472533.764,,0.000000e+000,5.500629e+001,2.747000e-006,0.000000e+000,3,8.228242e-001,0.000000e+000,,,,,,,,,,,,,,32,1,4.000000e+000,5.249023e-003,0.000000e+000,0,,0,
1524472571.865,,0.000000e+000,5.499511e+001,2.711162e-006,0.000000e+000,3,8.208841e-001,0.000000e+000,,,,,,,,,,,,,,32,1,4.000000e+000,9.201050e-003,0.000000e+000,0,,0,
1524472609.525,,0.000000e+000,5.499248e+001,2.827961e-006,0.000000e+000,3,8.248243e-001,0.000000e+000,,,,,,,,,,,,,,32,1,4.000000e+000,3.940582e-003,0.000000e+000,0,,0,
1524472647.525,,0.000000e+000,5.500103e+001,2.856554e-006,0.000000e+000,3,8.323904e-001,0.000000e+000,,,,,,,,,,,,,,32,1,4.000000e+000,2.639771e-003,0.000000e+000,0,,0,
1524472685.105,,0.000000e+000,5.500432e+001,2.866144e-006,0.000000e+000,3,8.227589e-001,0.000000e+000,,,,,,,,,,,,,,32,1,4.000000e+000,6.580353e-003,0.000000e+000,0,,0,
1524472723.155,,0.000000e+000,5.499314e+001,2.870318e-006,0.000000e+000,3,8.476291e-001,0.000000e+000,,,,,,,,,,,,,,32,1,4.000000e+000,5.260468e-003,0.000000e+000,0,,0,
1524472774.255,,0.000000e+000,5.500037e+001,2.951717e-006,0.000000e+000,3,8.522473e-001,0.000000e+000,,,,,,,,,,,,,,32,1,4.000000e+000,1.184082e-002,0.000000e+000,0,,0,
1524472811.535,,0.000000e+000,5.499971e+001,2.702953e-006,0.000000e+000,3,8.274743e-001,0.000000e+000,,,,,,,,,,,,,,32,1,4.000000e+000,1.052094e-002,0.000000e+000,0,,0,
1524472849.285,,0.000000e+000,5.499708e+001,2.875587e-006,0.000000e+000,3,8.530843e-001,0.000000e+000,,,,,,,,,,,,,,32,1,4.000000e+000,2.620697e-003,0.000000e+000,0,,0,
1524472886.495,,0.000000e+000,5.499051e+001,2.883436e-006,0.000000e+000,3,8.265581e-001,0.000000e+000,,,,,,,,,,,,,,32,1,4.000000e+000,5.260468e-003,0.000000e+000,0,,0,
1524472923.675,,0.000000e+000,5.500366e+001,2.985223e-006,0.000000e+000,3,8.386117e-001,0.000000e+000,,,,,,,,,,,,,,32,1,4.000000e+000,5.260468e-003,0.000000e+000,0,,0,
1524472961.795,,0.000000e+000,5.499840e+001,2.861862e-006,0.000000e+000,3,8.158343e-001,0.000000e+000,,,,,,,,,,,,,,32,1,4.000000e+000,7.900238e-003,0.000000e+000,0,,0,
1524472999.295,,0.000000e+000,5.499051e+001,2.928962e-006,0.000000e+000,3,8.229663e-001,0.000000e+000,,,,,,,,,,,,,,32,1,4.000000e+000,2.632141e-003,0.000000e+000,0,,0,
1524473037.275,,0.000000e+000,5.499840e+001,2.957972e-006,0.000000e+000,3,8.387501e-001,0.000000e+000,,,,,,,,,,,,,,32,1,4.000000e+000,2.628326e-003,0.000000e+000,0,,0,
1524473075.445,,0.000000e+000,5.499971e+001,2.910795e-006,0.000000e+000,3,8.335007e-001,0.000000e+000,,,,,,,,,,,,,,32,1,4.000000e+000,0.000000e+000,0.000000e+000,0,,0,
1524473112.985,,0.000000e+000,5.499314e+001,3.012213e-006,0.000000e+000,3,8.035129e-001,0.000000e+000,,,,,,,,,,,,,,32,1,4.000000e+000,1.842117e-002,0.000000e+000,0,,0,
1524473151.335,,0.000000e+000,5.500037e+001,2.986545e-006,0.000000e+000,3,8.520588e-001,0.000000e+000,,,,,,,,,,,,,,32,1,4.000000e+000,9.201050e-003,0.000000e+000,0,,0,
1524473188.615,,0.000000e+000,5.499906e+001,2.997024e-006,0.000000e+000,3,8.311632e-001,0.000000e+000,,,,,,,,,,,,,,32,1,4.000000e+000,2.235794e-002,0.000000e+000,0,,0,
1524473226.495,,0.000000e+000,5.500169e+001,2.992436e-006,0.000000e+000,3,8.608308e-001,0.000000e+000,,,,,,,,,,,,,,32,1,4.000000e+000,1.319885e-003,0.000000e+000,0,,0,
1524473264.166,,0.000000e+000,5.500037e+001,3.015403e-006,0.000000e+000,3,8.430262e-001,0.000000e+000,,,,,,,,,,,,,,32,1,4.000000e+000,1.446915e-002,0.000000e+000,0,,0,
1524473302.166,,0.000000e+000,5.500563e+001,2.966297e-006,0.000000e+000,3,8.542656e-001,0.000000e+000,,,,,,,,,,,,,,32,1,4.000000e+000,1.319885e-003,0.000000e+000,0,,0,
1524473339.786,,0.000000e+000,5.500169e+001,3.032198e-006,0.000000e+000,3,8.493139e-001,0.000000e+000,,,,,,,,,,,,,,32,1,4.000000e+000,1.446915e-002,0.000000e+000,0,,0,
1524473377.796,,0.000000e+000,5.499445e+001,3.029847e-006,0.000000e+000,3,8.571910e-001,0.000000e+000,,,,,,,,,,,,,,32,1,4.000000e+000,1.052094e-002,0.000000e+000,0,,0,
1524473415.556,,0.000000e+000,5.499577e+001,3.041688e-006,0.000000e+000,3,8.456196e-001,0.000000e+000,,,,,,,,,,,,,,32,1,4.000000e+000,2.104187e-002,0.000000e+000,0,,0,
1524473453.476,,0.000000e+000,5.499577e+001,3.061427e-006,0.000000e+000,3,8.611313e-001,0.000000e+000,,,,,,,,,,,,,,32,1,4.000000e+000,1.052094e-002,0.000000e+000,0,,0,
1524473491.056,,0.000000e+000,5.499905e+001,3.138496e-006,0.000000e+000,3,8.517159e-001,0.000000e+000,,,,,,,,,,,,,,32,1,4.000000e+000,3.948212e-003,0.000000e+000,0,,0,
1524473529.116,,0.000000e+000,5.500366e+001,3.108437e-006,0.000000e+000,3,8.547446e-001,0.000000e+000,,,,,,,,,,,,,,32,1,4.000000e+000,5.260468e-003,0.000000e+000,0,,0,
1524473566.476,,0.000000e+000,5.500497e+001,3.105627e-006,0.000000e+000,3,8.634771e-001,0.000000e+000,,,,,,,,,,,,,,32,1,4.000000e+000,1.052856e-002,0.000000e+000,0,,0,
1524473604.036,,0.000000e+000,5.500169e+001,3.189115e-006,0.000000e+000,3,8.563473e-001,0.000000e+000,,,,,,,,,,,,,,32,1,4.000000e+000,3.959656e-003,0.000000e+000,0,,0,
1524473641.856,,0.000000e+000,5.499051e+001,3.076117e-006,0.000000e+000,3,8.443873e-001,0.000000e+000,,,,,,,,,,,,,,32,1,4.000000e+000,1.052094e-002,0.000000e+000,0,,0,
1524473693.146,,0.000000e+000,5.499577e+001,3.310191e-006,0.000000e+000,3,8.853326e-001,0.000000e+000,,,,,,,,,,,,,,32,1,4.000000e+000,2.632141e-003,0.000000e+000,0,,0,
1524473731.126,,0.000000e+000,5.500103e+001,3.158454e-006,0.000000e+000,3,8.678810e-001,0.000000e+000,,,,,,,,,,,,,,32,1,4.000000e+000,0.000000e+000,0.000000e+000,0,,0,
1524473768.736,,0.000000e+000,5.499905e+001,3.191669e-006,0.000000e+000,3,8.531173e-001,0.000000e+000,,,,,,,,,,,,,,32,1,4.000000e+000,3.948212e-003,0.000000e+000,0,,0,
1524473806.566,,0.000000e+000,5.499314e+001,3.226900e-006,0.000000e+000,3,8.649316e-001,0.000000e+000,,,,,,,,,,,,,,32,1,4.000000e+000,5.260468e-003,0.000000e+000,0,,0,
1524473844.476,,0.000000e+000,5.499248e+001,3.204416e-006,0.000000e+000,3,8.742779e-001,0.000000e+000,,,,,,,,,,,,,,32,1,4.000000e+000,3.940582e-003,0.000000e+000,0,,0,
1524473882.086,,0.000000e+000,5.499708e+001,3.273961e-006,0.000000e+000,3,8.523290e-001,0.000000e+000,,,,,,,,,,,,,,32,1,4.000000e+000,5.260468e-003,0.000000e+000,0,,0,
1524473919.546,,0.000000e+000,5.499709e+001,3.259820e-006,0.000000e+000,3,8.772511e-001,0.000000e+000,,,,,,,,,,,,,,32,1,4.000000e+000,1.316071e-002,0.000000e+000,0,,0,
1524473957.256,,0.000000e+000,5.500103e+001,3.359694e-006,0.000000e+000,3,8.625487e-001,0.000000e+000,,,,,,,,,,,,,,32,1,4.000000e+000,5.279541e-003,0.000000e+000,0,,0,
1524473995.737,,0.000000e+000,5.499774e+001,3.227115e-006,0.000000e+000,3,8.761958e-001,0.000000e+000,,,,,,,,,,,,,,32,1,4.000000e+000,1.710129e-002,0.000000e+000,0,,0,
1524474033.207,,0.000000e+000,5.499971e+001,3.245807e-006,0.000000e+000,3,8.455431e-001,0.000000e+000,,,,,,,,,,,,,,32,1,4.000000e+000,0.000000e+000,0.000000e+000,0,,0,
1524474071.377,,0.000000e+000,5.500498e+001,3.204060e-006,0.000000e+000,3,8.711755e-001,0.000000e+000,,,,,,,,,,,,,,32,1,4.000000e+000,2.620697e-003,0.000000e+000,0,,0,
1524474109.047,,0.000000e+000,5.499708e+001,3.270294e-006,0.000000e+000,3,8.550918e-001,0.000000e+000,,,,,,,,,,,,,,32,1,4.000000e+000,2.620697e-003,0.000000e+000,0,,0,
1524474146.587,,0.000000e+000,5.499051e+001,3.207049e-006,0.000000e+000,3,8.698442e-001,0.000000e+000,,,,,,,,,,,,,,32,1,4.000000e+000,2.632141e-003,0.000000e+000,0,,0,
1524474184.197,,0.000000e+000,5.499708e+001,3.245872e-006,0.000000e+000,3,8.649566e-001,0.000000e+000,,,,,,,,,,,,,,32,1,4.000000e+000,1.578140e-002,0.000000e+000,0,,0,
1524474222.197,,0.000000e+000,5.499840e+001,3.258528e-006,0.000000e+000,3,8.644859e-001,0.000000e+000,,,,,,,,,,,,,,32,1,4.000000e+000,2.628326e-003,0.000000e+000,0,,0,
1524474259.827,,0.000000e+000,5.499577e+001,3.294643e-006,0.000000e+000,3,8.622697e-001,0.000000e+000,,,,,,,,,,,,,,32,1,4.000000e+000,2.104187e-002,0.000000e+000,0,,0,
1524474297.827,,0.000000e+000,5.499051e+001,3.270962e-006,0.000000e+000,3,8.707033e-001,0.000000e+000,,,,,,,,,,,,,,32,1,4.000000e+000,7.888794e-003,0.000000e+000,0,,0,
1524474335.367,,0.000000e+000,5.500103e+001,3.368454e-006,0.000000e+000,3,8.641915e-001,0.000000e+000,,,,,,,,,,,,,,32,1,4.000000e+000,0.000000e+000,0.000000e+000,0,,0,
1524474373.967,,0.000000e+000,5.500037e+001,3.307494e-006,0.000000e+000,3,8.736296e-001,0.000000e+000,,,,,,,,,,,,,,32,1,4.000000e+000,1.319885e-003,0.000000e+000,0,,0,
1524474411.207,,0.000000e+000,5.500235e+001,3.341754e-006,0.000000e+000,3,8.553436e-001,0.000000e+000,,,,,,,,,,,,,,32,1,4.000000e+000,2.639771e-003,0.000000e+000,0,,0,
1524474449.177,,0.000000e+000,5.499709e+001,3.284445e-006,0.000000e+000,3,8.746877e-001,0.000000e+000,,,,,,,,,,,,,,32,1,4.000000e+000,7.888794e-003,0.000000e+000,0,,0,
1524474487.277,,0.000000e+000,5.499773e+001,3.317040e-006,0.000000e+000,3,8.658468e-001,0.000000e+000,,,,,,,,,,,,,,32,1,4.000000e+000,1.308441e-003,0.000000e+000,0,,0,
1524474525.007,,0.000000e+000,5.500235e+001,3.346486e-006,0.000000e+000,3,8.705454e-001,0.000000e+000,,,,,,,,,,,,,,32,1,4.000000e+000,2.639771e-003,0.000000e+000,0,,0,
1524474562.447,,0.000000e+000,5.499445e+001,3.302422e-006,0.000000e+000,3,8.598306e-001,0.000000e+000,,,,,,,,,,,,,,32,1,4.000000e+000,0.000000e+000,0.000000e+000,0,,0,
1524474613.867,,0.000000e+000,5.499971e+001,3.356875e-006,0.000000e+000,3,8.909869e-001,0.000000e+000,,,,,,,,,,,,,,32,1,4.000000e+000,1.052094e-002,0.000000e+000,0,,0,
1524474651.367,,0.000000e+000,5.499445e+001,3.380160e-006,0.000000e+000,3,8.567069e-001,0.000000e+000,,,,,,,,,,,,,,32,1,4.000000e+000,0.000000e+000,0.000000e+000,0,,0,
1524474689.418,,0.000000e+000,5.499906e+001,3.348415e-006,0.000000e+000,3,8.633671e-001,0.000000e+000,,,,,,,,,,,,,,32,1,4.000000e+000,6.580353e-003,0.000000e+000,0,,0,
1524474727.448,,0.000000e+000,5.499972e+001,3.411918e-006,0.000000e+000,3,8.898135e-001,0.000000e+000,,,,,,,,,,,,,,32,1,4.000000e+000,7.900238e-003,0.000000e+000,0,,0,
1524474765.448,,0.000000e+000,5.499906e+001,3.462506e-006,0.000000e+000,3,8.700110e-001,0.000000e+000,,,,,,,,,,,,,,32,1,4.000000e+000,6.580353e-003,0.000000e+000,0,,0,
1524474803.598,,0.000000e+000,5.499248e+001,3.350534e-006,0.000000e+000,3,8.699211e-001,0.000000e+000,,,,,,,,,,,,,,32,1,4.000000e+000,3.940582e-003,0.000000e+000,0,,0,
1524474841.938,,0.000000e+000,5.499905e+001,3.353741e-006,0.000000e+000,3,8.773697e-001,0.000000e+000,,,,,,,,,,,,,,32,1,4.000000e+000,3.948212e-003,0.000000e+000,0,,0,
1524474879.268,,0.000000e+000,5.500037e+001,3.439362e-006,0.000000e+000,3,8.750112e-001,0.000000e+000,,,,,,,,,,,,,,32,1,4.000000e+000,6.587982e-003,0.000000e+000,0,,0,
1524474917.128,,0.000000e+000,5.499445e+001,3.399851e-006,0.000000e+000,3,8.844636e-001,0.000000e+000,,,,,,,,,,,,,,32,1,4.000000e+000,7.881165e-003,0.000000e+000,0,,0,
1524474954.938,,0.000000e+000,5.499117e+001,3.434540e-006,0.000000e+000,3,8.702611e-001,0.000000e+000,,,,,,,,,,,,,,32,1,4.000000e+000,1.312256e-003,0.000000e+000,0,,0,
1524474993.288,,0.000000e+000,5.499840e+001,3.403134e-006,0.000000e+000,3,8.860311e-001,0.000000e+000,,,,,,,,,,,,,,32,1,4.000000e+000,5.260468e-003,0.000000e+000,0,,0,
1524475030.628,,0.000000e+000,5.499511e+001,3.459990e-006,0.000000e+000,3,8.703124e-001,0.000000e+000,,,,,,,,,,,,,,32,1,4.000000e+000,1.319885e-003,0.000000e+000,0,,0,
1524475068.968,,0.000000e+000,5.499708e+001,3.422274e-006,0.000000e+000,3,8.825295e-001,0.000000e+000,,,,,,,,,,,,,,32,1,4.000000e+000,2.620697e-003,0.000000e+000,0,,0,
1524475106.518,,0.000000e+000,5.500037e+001,3.511466e-006,0.000000e+000,3,8.772699e-001,0.000000e+000,,,,,,,,,,,,,,32,1,4.000000e+000,1.319885e-003,0.000000e+000,0,,0,
1524475143.328,,0.000000e+000,5.499248e+001,3.545661e-006,0.000000e+000,3,8.934302e-001,0.000000e+000,,,,,,,,,,,,,,32,1,4.000000e+000,3.940582e-003,0.000000e+000,0,,0,
1524475180.768,,0.000000e+000,5.499577e+001,3.556897e-006,0.000000e+000,3,8.842800e-001,0.000000e+000,,,,,,,,,,,,,,32,1,4.000000e+000,2.632141e-003,0.000000e+000,0,,0,
1524475217.938,,0.000000e+000,5.499709e+001,3.560685e-006,0.000000e+000,3,8.780237e-001,0.000000e+000,,,,,,,,,,,,,,32,1,4.000000e+000,1.052856e-002,0.000000e+000,0,,0,
1524475256.438,,0.000000e+000,5.499972e+001,3.529365e-006,0.000000e+000,3,8.691053e-001,0.000000e+000,,,,,,,,,,,,,,32,1,4.000000e+000,1.578903e-002,0.000000e+000,0,,0,
1524475293.708,,0.000000e+000,5.499577e+001,3.580391e-006,0.000000e+000,3,8.828865e-001,0.000000e+000,,,,,,,,,,,,,,32,1,4.000000e+000,0.000000e+000,0.000000e+000,0,,0,
1524475330.978,,0.000000e+000,5.500103e+001,3.637169e-006,0.000000e+000,3,8.782877e-001,0.000000e+000,,,,,,,,,,,,,,32,1,4.000000e+000,0.000000e+000,0.000000e+000,0,,0,
1524475368.158,,0.000000e+000,5.500169e+001,3.629832e-006,0.000000e+000,3,8.716989e-001,0.000000e+000,,,,,,,,,,,,,,32,1,4.000000e+000,3.959656e-003,0.000000e+000,0,,0,
1524475406.119,,0.000000e+000,5.500037e+001,3.546317e-006,0.000000e+000,3,8.766572e-001,0.000000e+000,,,,,,,,,,,,,,32,1,4.000000e+000,1.184082e-002,0.000000e+000,0,,0,
1524475443.759,,0.000000e+000,5.499445e+001,3.587554e-006,0.000000e+000,3,8.801809e-001,0.000000e+000,,,,,,,,,,,,,,32,1,4.000000e+000,5.260468e-003,0.000000e+000,0,,0,
1524475482.329,,0.000000e+000,5.500037e+001,3.564115e-006,0.000000e+000,3,8.764073e-001,0.000000e+000,,,,,,,,,,,,,,32,1,4.000000e+000,3.959656e-003,0.000000e+000,0,,0,
1524475532.729,,0.000000e+000,5.500168e+001,3.557487e-006,0.000000e+000,3,8.784149e-001,0.000000e+000,,,,,,,,,,,,,,32,1,4.000000e+000,6.580353e-003,0.000000e+000,0,,0,
1524475571.159,,0.000000e+000,5.499380e+001,3.628833e-006,0.000000e+000,3,8.996312e-001,0.000000e+000,,,,,,,,,,,,,,32,1,4.000000e+000,3.948212e-003,0.000000e+000,0,,0,
1524475608.439,,0.000000e+000,5.499511e+001,3.665257e-006,0.000000e+000,3,8.784459e-001,0.000000e+000,,,,,,,,,,,,,,32,1,4.000000e+000,1.319885e-003,0.000000e+000,0,,0,
1524475645.789,,0.000000e+000,5.499183e+001,3.675737e-006,0.000000e+000,3,8.880309e-001,0.000000e+000,,,,,,,,,,,,,,32,1,4.000000e+000,2.632141e-003,0.000000e+000,0,,0,
1524475683.429,,0.000000e+000,5.500103e+001,3.646427e-006,0.000000e+000,3,8.617122e-001,0.000000e+000,,,,,,,,,,,,,,32,1,4.000000e+000,5.279541e-003,0.000000e+000,0,,0,
1524475721.309,,0.000000e+000,5.500300e+001,3.686879e-006,0.000000e+000,3,8.898481e-001,0.000000e+000,,,,,,,,,,,,,,32,1,4.000000e+000,3.940582e-003,0.000000e+000,0,,0,
1524475758.989,,0.000000e+000,5.499905e+001,3.632751e-006,0.000000e+000,3,8.908246e-001,0.000000e+000,,,,,,,,,,,,,,32,1,4.000000e+000,3.948212e-003,0.000000e+000,0,,0,
1524475797.079,,0.000000e+000,5.499314e+001,3.605208e-006,0.000000e+000,3,8.760149e-001,0.000000e+000,,,,,,,,,,,,,,32,1,4.000000e+000,2.104950e-002,0.000000e+000,0,,0,
1524475834.489,,0.000000e+000,5.499972e+001,3.657318e-006,0.000000e+000,3,8.792303e-001,0.000000e+000,,,,,,,,,,,,,,32,1,4.000000e+000,2.367020e-002,0.000000e+000,0,,0,
1524475871.909,,0.000000e+000,5.498985e+001,3.612826e-006,0.000000e+000,3,8.786296e-001,0.000000e+000,,,,,,,,,,,,,,32,1,4.000000e+000,6.580353e-003,0.000000e+000,0,,0,
1524475909.929,,0.000000e+000,5.500432e+001,3.685721e-006,0.000000e+000,3,8.700241e-001,0.000000e+000,,,,,,,,,,,,,,32,1,4.000000e+000,1.300812e-003,0.000000e+000,0,,0,
1524475947.189,,0.000000e+000,5.500300e+001,3.646334e-006,0.000000e+000,3,8.825098e-001,0.000000e+000,,,,,,,,,,,,,,32,1,4.000000e+000,3.940582e-003,0.000000e+000,0,,0,
1524475985.639,,0.000000e+000,5.499643e+001,3.692098e-006,0.000000e+000,3,8.760906e-001,0.000000e+000,,,,,,,,,,,,,,32,1,4.000000e+000,1.184082e-002,0.000000e+000,0,,0,
1524476023.659,,0.000000e+000,5.500103e+001,3.707522e-006,0.000000e+000,3,9.031733e-001,0.000000e+000,,,,,,,,,,,,,,32,1,4.000000e+000,5.279541e-003,0.000000e+000,0,,0,
1524476061.009,,0.000000e+000,5.500103e+001,3.732455e-006,0.000000e+000,3,8.827472e-001,0.000000e+000,,,,,,,,,,,,,,32,1,4.000000e+000,1.577759e-002,0.000000e+000,0,,0,
1524476097.829,,0.000000e+000,5.500037e+001,3.706429e-006,0.000000e+000,3,8.984107e-001,0.000000e+000,,,,,,,,,,,,,,32,1,4.000000e+000,1.709747e-002,0.000000e+000,0,,0,
1524476135.920,,0.000000e+000,5.500169e+001,3.686308e-006,0.000000e+000,3,8.844990e-001,0.000000e+000,,,,,,,,,,,,,,32,1,4.000000e+000,3.959656e-003,0.000000e+000,0,,0,
1524476173.940,,0.000000e+000,5.499905e+001,3.651327e-006,0.000000e+000,3,8.893472e-001,0.000000e+000,,,,,,,,,,,,,,32,1,4.000000e+000,1.182938e-002,0.000000e+000,0,,0,
1524476211.610,,0.000000e+000,5.500037e+001,3.718212e-006,0.000000e+000,3,8.851662e-001,0.000000e+000,,,,,,,,,,,,,,32,1,4.000000e+000,1.319885e-003,0.000000e+000,0,,0,
1524476249.730,,0.000000e+000,5.500169e+001,3.667777e-006,0.000000e+000,3,8.919708e-001,0.000000e+000,,,,,,,,,,,,,,32,1,4.000000e+000,3.959656e-003,0.000000e+000,0,,0,
1524476287.240,,0.000000e+000,5.500037e+001,3.713915e-006,0.000000e+000,3,8.803483e-001,0.000000e+000,,,,,,,,,,,,,,32,1,4.000000e+000,9.201050e-003,0.000000e+000,0,,0,
1524476325.290,,0.000000e+000,5.499643e+001,3.645586e-006,0.000000e+000,3,8.950722e-001,0.000000e+000,,,,,,,,,,,,,,32,1,4.000000e+000,1.312256e-003,0.000000e+000,0,,0,
1524476362.980,,0.000000e+000,5.500037e+001,3.724547e-006,0.000000e+000,3,8.857801e-001,0.000000e+000,,,,,,,,,,,,,,32,1,4.000000e+000,1.319885e-003,0.000000e+000,0,,0,
1524476400.830,,0.000000e+000,5.499708e+001,3.678092e-006,0.000000e+000,3,8.770747e-001,0.000000e+000,,,,,,,,,,,,,,32,1,4.000000e+000,5.260468e-003,0.000000e+000,0,,0,
1524476452.310,,0.000000e+000,5.499774e+001,3.694547e-006,0.000000e+000,3,9.016786e-001,0.000000e+000,,,,,,,,,,,,,,32,1,4.000000e+000,1.446152e-002,0.000000e+000,0,,0,
1524476490.410,,0.000000e+000,5.499905e+001,3.661456e-006,0.000000e+000,3,9.034145e-001,0.000000e+000,,,,,,,,,,,,,,32,1,4.000000e+000,3.948212e-003,0.000000e+000,0,,0,
1524476528.890,,0.000000e+000,5.499840e+001,3.623826e-006,0.000000e+000,3,8.825143e-001,0.000000e+000,,,,,,,,,,,,,,32,1,4.000000e+000,5.260468e-003,0.000000e+000,0,,0,
1524476565.930,,0.000000e+000,5.499775e+001,3.647502e-006,0.000000e+000,3,8.780348e-001,0.000000e+000,,,,,,,,,,,,,,32,1,4.000000e+000,9.208679e-003,0.000000e+000,0,,0,
1524476602.870,,0.000000e+000,5.500037e+001,3.661829e-006,0.000000e+000,3,8.809248e-001,0.000000e+000,,,,,,,,,,,,,,32,1,4.000000e+000,1.184082e-002,0.000000e+000,0,,0,
1524476640.650,,0.000000e+000,5.500432e+001,3.684514e-006,0.000000e+000,3,8.819094e-001,0.000000e+000,,,,,,,,,,,,,,32,1,4.000000e+000,1.300812e-003,0.000000e+000,0,,0,
1524476678.200,,0.000000e+000,5.500103e+001,3.701203e-006,0.000000e+000,3,8.752107e-001,0.000000e+000,,,,,,,,,,,,,,32,1,4.000000e+000,5.279541e-003,0.000000e+000,0,,0,
1524476715.630,,0.000000e+000,5.499380e+001,3.712258e-006,0.000000e+000,3,8.682364e-001,0.000000e+000,,,,,,,,,,,,,,32,1,4.000000e+000,3.948212e-003,0.000000e+000,0,,0,
1524476752.520,,0.000000e+000,5.500037e+001,3.696670e-006,0.000000e+000,3,8.854162e-001,0.000000e+000,,,,,,,,,,,,,,32,1,4.000000e+000,6.587982e-003,0.000000e+000,0,,0,
1524476790.310,,0.000000e+000,5.499117e+001,3.639096e-006,0.000000e+000,3,8.860805e-001,0.000000e+000,,,,,,,,,,,,,,32,1,4.000000e+000,6.568909e-003,0.000000e+000,0,,0,
1524476827.500,,0.000000e+000,5.499643e+001,3.711647e-006,0.000000e+000,3,8.776203e-001,0.000000e+000,,,,,,,,,,,,,,32,1,4.000000e+000,9.208679e-003,0.000000e+000,0,,0,
1524476864.951,,0.000000e+000,5.499775e+001,3.697669e-006,0.000000e+000,3,8.913567e-001,0.000000e+000,,,,,,,,,,,,,,32,1,4.000000e+000,9.208679e-003,0.000000e+000,0,,0,
1524476902.251,,0.000000e+000,5.499577e+001,3.679877e-006,0.000000e+000,3,8.862888e-001,0.000000e+000,,,,,,,,,,,,,,32,1,4.000000e+000,2.632141e-003,0.000000e+000,0,,0,
1524476939.541,,0.000000e+000,5.500432e+001,3.732006e-006,0.000000e+000,3,9.124426e-001,0.000000e+000,,,,,,,,,,,,,,32,1,4.000000e+000,1.300812e-003,0.000000e+000,0,,0,
1524476976.941,,0.000000e+000,5.499380e+001,3.732910e-006,0.000000e+000,3,8.981299e-001,0.000000e+000,,,,,,,,,,,,,,32,1,4.000000e+000,6.572723e-003,0.000000e+000,0,,0,
1524477014.651,,0.000000e+000,5.499511e+001,3.707599e-006,0.000000e+000,3,8.809624e-001,0.000000e+000,,,,,,,,,,,,,,32,1,4.000000e+000,1.184082e-002,0.000000e+000,0,,0,
1524477053.251,,0.000000e+000,5.499708e+001,3.708159e-006,0.000000e+000,3,8.815326e-001,0.000000e+000,,,,,,,,,,,,,,32,1,4.000000e+000,0.000000e+000,0.000000e+000,0,,0,
1524477090.731,,0.000000e+000,5.499708e+001,3.759825e-006,0.000000e+000,3,8.773618e-001,0.000000e+000,,,,,,,,,,,,,,32,1,4.000000e+000,2.620697e-003,0.000000e+000,0,,0,
1524477128.381,,0.000000e+000,5.499380e+001,3.711658e-006,0.000000e+000,3,8.807032e-001,0.000000e+000,,,,,,,,,,,,,,32,1,4.000000e+000,1.308441e-003,0.000000e+000,0,,0,
1524477166.321,,0.000000e+000,5.500037e+001,3.733511e-006,0.000000e+000,3,8.899452e-001,0.000000e+000,,,,,,,,,,,,,,32,1,4.000000e+000,3.959656e-003,0.000000e+000,0,,0,
1524477204.131,,0.000000e+000,5.499905e+001,3.688603e-006,0.000000e+000,3,8.769025e-001,0.000000e+000,,,,,,,,,,,,,,32,1,4.000000e+000,1.319885e-003,0.000000e+000,0,,0,
1524477242.291,,0.000000e+000,5.500037e+001,3.793162e-006,0.000000e+000,3,8.973638e-001,0.000000e+000,,,,,,,,,,,,,,32,1,4.000000e+000,1.446915e-002,0.000000e+000,0,,0,
1524477279.661,,0.000000e+000,5.499773e+001,3.732529e-006,0.000000e+000,3,8.862941e-001,0.000000e+000,,,,,,,,,,,,,,32,1,4.000000e+000,1.308441e-003,0.000000e+000,0,,0,
1524477317.631,,0.000000e+000,5.500103e+001,3.717004e-006,0.000000e+000,3,8.852290e-001,0.000000e+000,,,,,,,,,,,,,,32,1,4.000000e+000,0.000000e+000,0.000000e+000,0,,0,
1524477368.871,,0.000000e+000,5.499971e+001,3.794201e-006,0.000000e+000,3,8.724786e-001,0.000000e+000,,,,,,,,,,,,,,32,1,4.000000e+000,2.639771e-003,0.000000e+000,0,,0,
1524477406.631,,0.000000e+000,5.500431e+001,3.789643e-006,0.000000e+000,3,8.936309e-001,0.000000e+000,,,,,,,,,,,,,,32,1,4.000000e+000,9.208679e-003,0.000000e+000,0,,0,
1524477443.771,,0.000000e+000,5.500235e+001,3.782577e-006,0.000000e+000,3,8.797858e-001,0.000000e+000,,,,,,,,,,,,,,32,1,4.000000e+000,2.639771e-003,0.000000e+000,0,,0,
1524477481.291,,0.000000e+000,5.499774e+001,3.795545e-006,0.000000e+000,3,8.862479e-001,0.000000e+000,,,,,,,,,,,,,,32,1,4.000000e+000,6.580353e-003,0.000000e+000,0,,0,
1524477519.261,,0.000000e+000,5.500037e+001,3.748497e-006,0.000000e+000,3,8.996809e-001,0.000000e+000,,,,,,,,,,,,,,32,1,4.000000e+000,1.709747e-002,0.000000e+000,0,,0,
1524477556.972,,0.000000e+000,5.500169e+001,3.818159e-006,0.000000e+000,3,8.891751e-001,0.000000e+000,,,,,,,,,,,,,,32,1,4.000000e+000,1.319885e-003,0.000000e+000,0,,0,
1524477594.272,,0.000000e+000,5.499774e+001,3.793855e-006,0.000000e+000,3,8.814930e-001,0.000000e+000,,,,,,,,,,,,,,32,1,4.000000e+000,3.940582e-003,0.000000e+000,0,,0,
1524477632.082,,0.000000e+000,5.500103e+001,3.719494e-006,0.000000e+000,3,8.973660e-001,0.000000e+000,,,,,,,,,,,,,,32,1,4.000000e+000,2.639771e-003,0.000000e+000,0,,0,
1524477670.042,,0.000000e+000,5.499775e+001,3.737987e-006,0.000000e+000,3,8.905727e-001,0.000000e+000,,,,,,,,,,,,,,32,1,4.000000e+000,9.208679e-003,0.000000e+000,0,,0,
1524477707.942,,0.000000e+000,5.500695e+001,3.812178e-006,0.000000e+000,3,8.995263e-001,0.000000e+000,,,,,,,,,,,,,,32,1,4.000000e+000,6.568909e-003,0.000000e+000,0,,0,
1524477744.762,,0.000000e+000,5.499905e+001,3.783197e-006,0.000000e+000,3,8.812010e-001,0.000000e+000,,,,,,,,,,,,,,32,1,4.000000e+000,3.948212e-003,0.000000e+000,0,,0,
1524477781.982,,0.000000e+000,5.500432e+001,3.774788e-006,0.000000e+000,3,9.175729e-001,0.000000e+000,,,,,,,,,,,,,,32,1,4.000000e+000,6.580353e-003,0.000000e+000,0,,0,
1524477819.072,,0.000000e+000,5.499905e+001,3.757815e-006,0.000000e+000,3,8.842491e-001,0.000000e+000,,,,,,,,,,,,,,32,1,4.000000e+000,1.446915e-002,0.000000e+000,0,,0,
1524477856.542,,0.000000e+000,5.499708e+001,3.771253e-006,0.000000e+000,3,9.001242e-001,0.000000e+000,,,,,,,,,,,,,,32,1,4.000000e+000,2.620697e-003,0.000000e+000,0,,0,
1524477893.672,,0.000000e+000,5.499905e+001,3.795278e-006,0.000000e+000,3,8.903471e-001,0.000000e+000,,,,,,,,,,,,,,32,1,4.000000e+000,1.319885e-003,0.000000e+000,0,,0,
1524477931.172,,0.000000e+000,5.499905e+001,3.845747e-006,0.000000e+000,3,8.970802e-001,0.000000e+000,,,,,,,,,,,,,,32,1,4.000000e+000,3.948212e-003,0.000000e+000,0,,0,
1524477968.562,,0.000000e+000,5.499774e+001,3.826950e-006,0.000000e+000,3,8.889945e-001,0.000000e+000,,,,,,,,,,,,,,32,1,4.000000e+000,6.580353e-003,0.000000e+000,0,,0,
1524478006.502,,0.000000e+000,5.499774e+001,3.815855e-006,0.000000e+000,3,8.861931e-001,0.000000e+000,,,,,,,,,,,,,,32,1,4.000000e+000,6.580353e-003,0.000000e+000,0,,0,
1524478044.502,,0.000000e+000,5.499775e+001,3.758874e-006,0.000000e+000,3,8.924472e-001,0.000000e+000,,,,,,,,,,,,,,32,1,4.000000e+000,9.208679e-003,0.000000e+000,0,,0,
1524478082.382,,0.000000e+000,5.499445e+001,3.874703e-006,0.000000e+000,3,8.854797e-001,0.000000e+000,,,,,,,,,,,,,,32,1,4.000000e+000,5.260468e-003,0.000000e+000,0,,0,
1524478120.422,,0.000000e+000,5.500366e+001,3.838401e-006,0.000000e+000,3,9.119128e-001,0.000000e+000,,,,,,,,,,,,,,32,1,4.000000e+000,1.315689e-002,0.000000e+000,0,,0,
1524478158.072,,0.000000e+000,5.498656e+001,3.906030e-006,0.000000e+000,3,8.942775e-001,0.000000e+000,,,,,,,,,,,,,,32,1,4.000000e+000,0.000000e+000,0.000000e+000,0,,0,
1524478196.132,,0.000000e+000,5.500103e+001,3.849771e-006,0.000000e+000,3,8.978919e-001,0.000000e+000,,,,,,,,,,,,,,32,1,4.000000e+000,7.888794e-003,0.000000e+000,0,,0,
1524478233.752,,0.000000e+000,5.500300e+001,3.910752e-006,0.000000e+000,3,8.944785e-001,0.000000e+000,,,,,,,,,,,,,,32,1,4.000000e+000,1.183701e-002,0.000000e+000,0,,0,
1524478285.633,,0.000000e+000,5.500169e+001,3.903448e-006,0.000000e+000,3,8.995655e-001,0.000000e+000,,,,,,,,,,,,,,32,1,4.000000e+000,9.208679e-003,0.000000e+000,0,,0,
1524478323.753,,0.000000e+000,5.499709e+001,3.959371e-006,0.000000e+000,3,8.820382e-001,0.000000e+000,,,,,,,,,,,,,,32,1,4.000000e+000,7.888794e-003,0.000000e+000,0,,0,
1524478361.723,,0.000000e+000,5.500103e+001,3.926802e-006,0.000000e+000,3,9.042214e-001,0.000000e+000,,,,,,,,,,,,,,32,1,4.000000e+000,2.639771e-003,0.000000e+000,0,,0,
1524478399.303,,0.000000e+000,5.499182e+001,3.904698e-006,0.000000e+000,3,8.868982e-001,0.000000e+000,,,,,,,,,,,,,,32,1,4.000000e+000,1.314163e-002,0.000000e+000,0,,0,
1524478437.363,,0.000000e+000,5.499905e+001,3.900848e-006,0.000000e+000,3,9.182681e-001,0.000000e+000,,,,,,,,,,,,,,32,1,4.000000e+000,3.948212e-003,0.000000e+000,0,,0,
1524478474.733,,0.000000e+000,5.499971e+001,3.916526e-006,0.000000e+000,3,9.040141e-001,0.000000e+000,,,,,,,,,,,,,,32,1,4.000000e+000,2.639771e-003,0.000000e+000,0,,0,
1524478512.563,,0.000000e+000,5.499905e+001,3.887522e-006,0.000000e+000,3,9.012173e-001,0.000000e+000,,,,,,,,,,,,,,32,1,4.000000e+000,1.319885e-003,0.000000e+000,0,,0,
1524478550.213,,0.000000e+000,5.499643e+001,3.842823e-006,0.000000e+000,3,8.904179e-001,0.000000e+000,,,,,,,,,,,,,,32,1,4.000000e+000,9.208679e-003,0.000000e+000,0,,0,
1524478588.353,,0.000000e+000,5.500564e+001,3.922440e-006,0.000000e+000,3,9.007124e-001,0.000000e+000,,,,,,,,,,,,,,32,1,4.000000e+000,1.710892e-002,0.000000e+000,0,,0,
1524478626.593,,0.000000e+000,5.499708e+001,3.892363e-006,0.000000e+000,3,8.997715e-001,0.000000e+000,,,,,,,,,,,,,,32,1,4.000000e+000,5.260468e-003,0.000000e+000,0,,0,
1524478664.013,,0.000000e+000,5.499445e+001,3.892602e-006,0.000000e+000,3,9.139664e-001,0.000000e+000,,,,,,,,,,,,,,32,1,4.000000e+000,0.000000e+000,0.000000e+000,0,,0,
1524478701.483,,0.000000e+000,5.500103e+001,3.857557e-006,0.000000e+000,3,8.916770e-001,0.000000e+000,,,,,,,,,,,,,,32,1,4.000000e+000,5.279541e-003,0.000000e+000,0,,0,
1524478739.193,,0.000000e+000,5.500037e+001,3.881306e-006,0.000000e+000,3,9.223741e-001,0.000000e+000,,,,,,,,,,,,,,32,1,4.000000e+000,6.587982e-003,0.000000e+000,0,,0,
1524478777.023,,0.000000e+000,5.500037e+001,3.845610e-006,0.000000e+000,3,8.994755e-001,0.000000e+000,,,,,,,,,,,,,,32,1,4.000000e+000,3.959656e-003,0.000000e+000,0,,0,
1524478814.403,,0.000000e+000,5.499445e+001,3.892589e-006,0.000000e+000,3,8.919061e-001,0.000000e+000,,,,,,,,,,,,,,32,1,4.000000e+000,5.260468e-003,0.000000e+000,0,,0,
1524478852.383,,0.000000e+000,5.500366e+001,3.776994e-006,0.000000e+000,3,9.005406e-001,0.000000e+000,,,,,,,,,,,,,,32,1,4.000000e+000,7.900238e-003,0.000000e+000,0,,0,
1524478890.203,,0.000000e+000,5.499773e+001,3.862030e-006,0.000000e+000,3,8.904995e-001,0.000000e+000,,,,,,,,,,,,,,32,1,4.000000e+000,1.308441e-003,0.000000e+000,0,,0,
1524478927.573,,0.000000e+000,5.499577e+001,3.828536e-006,0.000000e+000,3,8.933346e-001,0.000000e+000,,,,,,,,,,,,,,32,1,4.000000e+000,5.249023e-003,0.000000e+000,0,,0,
1524478965.483,,0.000000e+000,5.498853e+001,3.847831e-006,0.000000e+000,3,9.005145e-001,0.000000e+000,,,,,,,,,,,,,,32,1,4.000000e+000,1.182938e-002,0.000000e+000,0,,0,
1524479003.464,,0.000000e+000,5.500103e+001,3.884068e-006,0.000000e+000,3,9.092287e-001,0.000000e+000,,,,,,,,,,,,,,32,1,4.000000e+000,2.639771e-003,0.000000e+000,0,,0,
1524479040.784,,0.000000e+000,5.500300e+001,3.917346e-006,0.000000e+000,3,8.978155e-001,0.000000e+000,,,,,,,,,,,,,,32,1,4.000000e+000,3.940582e-003,0.000000e+000,0,,0,
1524479078.814,,0.000000e+000,5.499380e+001,3.909447e-006,0.000000e+000,3,8.919549e-001,0.000000e+000,,,,,,,,,,,,,,32,1,4.000000e+000,6.572723e-003,0.000000e+000,0,,0,
1524479116.734,,0.000000e+000,5.500103e+001,3.887588e-006,0.000000e+000,3,8.933486e-001,0.000000e+000,,,,,,,,,,,,,,32,1,4.000000e+000,2.639771e-003,0.000000e+000,0,,0,
1524479154.504,,0.000000e+000,5.499708e+001,3.936589e-006,0.000000e+000,3,8.842002e-001,0.000000e+000,,,,,,,,,,,,,,32,1,4.000000e+000,2.620697e-003,0.000000e+000,0,,0,
1524479205.684,,0.000000e+000,5.499971e+001,3.932684e-006,0.000000e+000,3,8.799848e-001,0.000000e+000,,,,,,,,,,,,,,32,1,4.000000e+000,2.639771e-003,0.000000e+000,0,,0,
1524479243.864,,0.000000e+000,5.500169e+001,3.907618e-006,0.000000e+000,3,8.952619e-001,0.000000e+000,,,,,,,,,,,,,,32,1,4.000000e+000,3.959656e-003,0.000000e+000,0,,0,
1524479282.154,,0.000000e+000,5.499906e+001,3.868859e-006,0.000000e+000,3,8.940934e-001,0.000000e+000,,,,,,,,,,,,,,32,1,4.000000e+000,1.710129e-002,0.000000e+000,0,,0,
1524479320.264,,0.000000e+000,5.499708e+001,3.952238e-006,0.000000e+000,3,8.773311e-001,0.000000e+000,,,,,,,,,,,,,,32,1,4.000000e+000,5.260468e-003,0.000000e+000,0,,0,
1524479358.164,,0.000000e+000,5.500169e+001,3.928021e-006,0.000000e+000,3,8.893799e-001,0.000000e+000,,,,,,,,,,,,,,32,1,4.000000e+000,3.959656e-003,0.000000e+000,0,,0,
1524479395.784,,0.000000e+000,5.499708e+001,3.922386e-006,0.000000e+000,3,8.992674e-001,0.000000e+000,,,,,,,,,,,,,,32,1,4.000000e+000,2.620697e-003,0.000000e+000,0,,0,
1524479433.594,,0.000000e+000,5.499906e+001,3.978182e-006,0.000000e+000,3,8.904108e-001,0.000000e+000,,,,,,,,,,,,,,32,1,4.000000e+000,6.580353e-003,0.000000e+000,0,,0,
1524479471.464,,0.000000e+000,5.499971e+001,3.891810e-006,0.000000e+000,3,8.966643e-001,0.000000e+000,,,,,,,,,,,,,,32,1,4.000000e+000,1.052094e-002,0.000000e+000,0,,0,
1524479509.044,,0.000000e+000,5.500037e+001,3.908528e-006,0.000000e+000,3,8.920591e-001,0.000000e+000,,,,,,,,,,,,,,32,1,4.000000e+000,3.959656e-003,0.000000e+000,0,,0,
1524479546.494,,0.000000e+000,5.500366e+001,3.973968e-006,0.000000e+000,3,9.147102e-001,0.000000e+000,,,,,,,,,,,,,,32,1,4.000000e+000,2.620697e-003,0.000000e+000,0,,0,
1524479584.414,,0.000000e+000,5.500169e+001,3.952789e-006,0.000000e+000,3,8.954490e-001,0.000000e+000,,,,,,,,,,,,,,32,1,4.000000e+000,1.709747e-002,0.000000e+000,0,,0,
1524479622.284,,0.000000e+000,5.499709e+001,3.897916e-006,0.000000e+000,3,8.983108e-001,0.000000e+000,,,,,,,,,,,,,,32,1,4.000000e+000,1.316071e-002,0.000000e+000,0,,0,
1524479659.814,,0.000000e+000,5.500037e+001,3.969118e-006,0.000000e+000,3,8.938062e-001,0.000000e+000,,,,,,,,,,,,,,32,1,4.000000e+000,1.319885e-003,0.000000e+000,0,,0,
1524479696.815,,0.000000e+000,5.499708e+001,3.984996e-006,0.000000e+000,3,9.027209e-001,0.000000e+000,,,,,,,,,,,,,,32,1,4.000000e+000,5.260468e-003,0.000000e+000,0,,0,
1524479734.545,,0.000000e+000,5.499511e+001,3.946893e-006,0.000000e+000,3,9.042628e-001,0.000000e+000,,,,,,,,,,,,,,32,1,4.000000e+000,1.319885e-003,0.000000e+000,0,,0,
1524479772.685,,0.000000e+000,5.499971e+001,3.938393e-006,0.000000e+000,3,9.060202e-001,0.000000e+000,,,,,,,,,,,,,,32,1,4.000000e+000,2.639771e-003,0.000000e+000,0,,0,
1524479810.635,,0.000000e+000,5.499445e+001,4.029863e-006,0.000000e+000,3,8.965879e-001,0.000000e+000,,,,,,,,,,,,,,32,1,4.000000e+000,5.260468e-003,0.000000e+000,0,,0,
1524479848.535,,0.000000e+000,5.500037e+001,3.992479e-006,0.000000e+000,3,9.065747e-001,0.000000e+000,,,,,,,,,,,,,,32,1,4.000000e+000,3.959656e-003,0.000000e+000,0,,0,
1524479886.275,,0.000000e+000,5.499971e+001,4.024155e-006,0.000000e+000,3,9.031396e-001,0.000000e+000,,,,,,,,,,,,,,32,1,4.000000e+000,0.000000e+000,0.000000e+000,0,,0,
1524479924.275,,0.000000e+000,5.499972e+001,3.944743e-006,0.000000e+000,3,9.074616e-001,0.000000e+000,,,,,,,,,,,,,,32,1,4.000000e+000,7.900238e-003,0.000000e+000,0,,0,
1524479961.755,,0.000000e+000,5.499577e+001,4.009368e-006,0.000000e+000,3,8.972467e-001,0.000000e+000,,,,,,,,,,,,,,32,1,4.000000e+000,2.632141e-003,0.000000e+000,0,,0,
1524479999.525,,0.000000e+000,5.499643e+001,4.030058e-006,0.000000e+000,3,8.896039e-001,0.000000e+000,,,,,,,,,,,,,,32,1,4.000000e+000,6.568909e-003,0.000000e+000,0,,0,
1524480037.675,,0.000000e+000,5.500037e+001,4.019082e-006,0.000000e+000,3,9.104882e-001,0.000000e+000,,,,,,,,,,,,,,32,1,4.000000e+000,3.959656e-003,0.000000e+000,0,,0,
1524480075.075,,0.000000e+000,5.500103e+001,4.019829e-006,0.000000e+000,3,8.976846e-001,0.000000e+000,,,,,,,,,,,,,,32,1,4.000000e+000,5.279541e-003,0.000000e+000,0,,0,
1524480126.175,,0.000000e+000,5.499906e+001,4.001467e-006,0.000000e+000,3,9.148603e-001,0.000000e+000,,,,,,,,,,,,,,32,1,4.000000e+000,6.580353e-003,0.000000e+000,0,,0,
1524480164.785,,0.000000e+000,5.500103e+001,3.991929e-006,0.000000e+000,3,8.886777e-001,0.000000e+000,,,,,,,,,,,,,,32,1,4.000000e+000,5.279541e-003,0.000000e+000,0,,0,
1524480202.585,,0.000000e+000,5.499051e+001,4.012269e-006,0.000000e+000,3,8.946496e-001,0.000000e+000,,,,,,,,,,,,,,32,1,4.000000e+000,5.260468e-003,0.000000e+000,0,,0,
1524480240.745,,0.000000e+000,5.499971e+001,4.012595e-006,0.000000e+000,3,9.045405e-001,0.000000e+000,,,,,,,,,,,,,,32,1,4.000000e+000,2.639771e-003,0.000000e+000,0,,0,
1524480278.645,,0.000000e+000,5.500432e+001,3.935499e-006,0.000000e+000,3,9.023234e-001,0.000000e+000,,,,,,,,,,,,,,32,1,4.000000e+000,6.580353e-003,0.000000e+000,0,,0,
1524480316.825,,0.000000e+000,5.499708e+001,3.997826e-006,0.000000e+000,3,8.945204e-001,0.000000e+000,,,,,,,,,,,,,,32,1,4.000000e+000,2.620697e-003,0.000000e+000,0,,0,
1524480354.735,,0.000000e+000,5.499577e+001,4.021309e-006,0.000000e+000,3,9.117323e-001,0.000000e+000,,,,,,,,,,,,,,32,1,4.000000e+000,7.888794e-003,0.000000e+000,0,,0,
1524480391.935,,0.000000e+000,5.499971e+001,4.059629e-006,0.000000e+000,3,9.021534e-001,0.000000e+000,,,,,,,,,,,,,,32,1,4.000000e+000,0.000000e+000,0.000000e+000,0,,0,
1524480429.926,,0.000000e+000,5.499380e+001,3.997118e-006,0.000000e+000,3,9.077614e-001,0.000000e+000,,,,,,,,,,,,,,32,1,4.000000e+000,1.308441e-003,0.000000e+000,0,,0,
1524480467.116,,0.000000e+000,5.499511e+001,4.069499e-006,0.000000e+000,3,8.964563e-001,0.000000e+000,,,,,,,,,,,,,,32,1,4.000000e+000,1.319885e-003,0.000000e+000,0,,0,
1524480504.276,,0.000000e+000,5.499905e+001,4.092755e-006,0.000000e+000,3,8.971062e-001,0.000000e+000,,,,,,,,,,,,,,32,1,4.000000e+000,3.948212e-003,0.000000e+000,0,,0,
1524480541.936,,0.000000e+000,5.500103e+001,3.950315e-006,0.000000e+000,3,8.998191e-001,0.000000e+000,,,,,,,,,,,,,,32,1,4.000000e+000,7.888794e-003,0.000000e+000,0,,0,
1524480580.596,,0.000000e+000,5.499511e+001,4.030709e-006,0.000000e+000,3,8.940043e-001,0.000000e+000,,,,,,,,,,,,,,32,1,4.000000e+000,1.319885e-003,0.000000e+000,0,,0,
1524480618.526,,0.000000e+000,5.500169e+001,4.063496e-006,0.000000e+000,3,9.117001e-001,0.000000e+000,,,,,,,,,,,,,,32,1,4.000000e+000,3.959656e-003,0.000000e+000,0,,0,
1524480655.626,,0.000000e+000,5.500827e+001,4.056674e-006,0.000000e+000,3,9.014828e-001,0.000000e+000,,,,,,,,,,,,,,32,1,4.000000e+000,9.201050e-003,0.000000e+000,0,,0,
1524480693.676,,0.000000e+000,5.499248e+001,3.999115e-006,0.000000e+000,3,9.083713e-001,0.000000e+000,,,,,,,,,,,,,,32,1,4.000000e+000,6.580353e-003,0.000000e+000,0,,0,
1524480731.716,,0.000000e+000,5.499708e+001,4.018104e-006,0.000000e+000,3,9.148630e-001,0.000000e+000,,,,,,,,,,,,,,32,1,4.000000e+000,2.620697e-003,0.000000e+000,0,,0,
1524480768.976,,0.000000e+000,5.499906e+001,4.038536e-006,0.000000e+000,3,8.922573e-001,0.000000e+000,,,,,,,,,,,,,,32,1,4.000000e+000,6.580353e-003,0.000000e+000,0,,0,
1524480806.606,,0.000000e+000,5.500103e+001,4.052026e-006,0.000000e+000,3,9.074268e-001,0.000000e+000,,,,,,,,,,,,,,32,1,4.000000e+000,5.279541e-003,0.000000e+000,0,,0,
1524480843.736,,0.000000e+000,5.499840e+001,4.132750e-006,0.000000e+000,3,8.980175e-001,0.000000e+000,,,,,,,,,,,,,,32,1,4.000000e+000,2.628326e-003,0.000000e+000,0,,0,
1524480882.436,,0.000000e+000,5.500169e+001,4.074369e-006,0.000000e+000,3,9.076112e-001,0.000000e+000,,,,,,,,,,,,,,32,1,4.000000e+000,1.184082e-002,0.000000e+000,0,,0,
1524480919.976,,0.000000e+000,5.499839e+001,4.089067e-006,0.000000e+000,3,8.974532e-001,0.000000e+000,,,,,,,,,,,,,,32,1,4.000000e+000,0.000000e+000,0.000000e+000,0,,0,
1524480957.386,,0.000000e+000,5.499314e+001,4.136877e-006,0.000000e+000,3,9.094753e-001,0.000000e+000,,,,,,,,,,,,,,32,1,4.000000e+000,5.260468e-003,0.000000e+000,0,,0,
1524480995.086,,0.000000e+000,5.500431e+001,4.065039e-006,0.000000e+000,3,9.039306e-001,0.000000e+000,,,,,,,,,,,,,,32,1,4.000000e+000,9.208679e-003,0.000000e+000,0,,0,