File: Experimental Raw Data/TC04-12-01K TRMac VRMde/Ndat/TC04-12-01K_TRMac_56K_0.02Kmin_VRMde_55K.dc.dat
[Header]
TITLE,MPMS DC Measurement
BYAPP,MPMS Measurement,2.1,Summary
FILEOPENTIME, 1524512899.231000 4/23/2018, 1:48:19 PM

INFO, APPNAME, MPMS MultiVu Application, Revision 1.61,  Build 082

INFO, NAME, TC04-12-01K
INFO, WEIGHT, 1.000
INFO, AREA, 1.000
INFO, LENGTH, 1.000
INFO, SHAPE, 0
INFO, COMMENT,
INFO, SEQUENCE FILE: TRMac_56K_0.02Kmin_VRMde_55K.seq


INFO, BACKGROUND DATA FILE:, None


STARTUPAXIS,X,4,LINEAR,AUTO,0.000000,0.000000
STARTUPAXIS,Y1,5,LINEAR,AUTO,0.000000,0.000000


STARTUPGROUP,Longitudinal
FIELDGROUP,Longitudinal,1,2,3,4,5,6,7,8,9,15,16,17,18,27,28
FIELDGROUP,Transverse,1,2,3,4,10,11,12,13,14,19,20,21,22,27,28

PLOT_APPEARANCE,ALL,HORZ_GRID_ON,VERT_GRID_ON,MARKERS_AND_LINES

[Data]
Time,Comment,Field (Oe),Temperature (K),Long Moment (emu),Long Scan Std Dev,Long Algorithm,Long Reg Fit,Long Percent Error (%),Trans Moment (emu),Trans Scan Std Dev,Trans Algorithm,Trans Reg Fit,Trans Percent Error (%),Long Moment [w/o ABS] (emu),Long Scan Std Dev [w/o ABS],Long Reg Fit [w/o ABS],Long Percent Error [w/o ABS] (%),Trans Moment [w/o ABS] (emu),Trans Scan Std Dev [w/o ABS],Trans Reg Fit [w/o ABS],Trans Percent Error [w/o ABS] (%),Points per Scan,Scans per Measurement,Scan Length (cm),Delta Temp (K),Rot Position (deg),Error,EC Comp. Running,Using ABS,
1524512899.231,,0.000000e+000,5.500563e+001,-1.481182e-005,0.000000e+000,3,9.716192e-001,0.000000e+000,,,,,,,,,,,,,,32,1,4.000000e+000,1.319885e-003,0.000000e+000,0,,0,
1524512951.761,,0.000000e+000,5.499840e+001,-1.025208e-005,0.000000e+000,3,9.610826e-001,0.000000e+000,,,,,,,,,,,,,,32,1,4.000000e+000,7.900238e-003,0.000000e+000,0,,0,
1524513003.501,,0.000000e+000,5.499051e+001,-8.532807e-006,0.000000e+000,3,9.525027e-001,0.000000e+000,,,,,,,,,,,,,,32,1,4.000000e+000,7.888794e-003,0.000000e+000,0,,0,
1524513053.491,,0.000000e+000,5.499117e+001,-7.299091e-006,0.000000e+000,3,9.451177e-001,0.000000e+000,,,,,,,,,,,,,,32,1,4.000000e+000,1.312256e-003,0.000000e+000,0,,0,
1524513103.961,,0.000000e+000,5.500235e+001,-6.454456e-006,0.000000e+000,3,9.436367e-001,0.000000e+000,,,,,,,,,,,,,,32,1,4.000000e+000,2.639771e-003,0.000000e+000,0,,0,
1524513154.741,,0.000000e+000,5.499643e+001,-5.699427e-006,0.000000e+000,3,9.332379e-001,0.000000e+000,,,,,,,,,,,,,,32,1,4.000000e+000,1.972961e-002,0.000000e+000,0,,0,
1524513206.051,,0.000000e+000,5.499773e+001,-5.130818e-006,0.000000e+000,3,9.357426e-001,0.000000e+000,,,,,,,,,,,,,,32,1,4.000000e+000,1.308441e-003,0.000000e+000,0,,0,
1524513256.852,,0.000000e+000,5.500695e+001,-4.756919e-006,0.000000e+000,3,9.270512e-001,0.000000e+000,,,,,,,,,,,,,,32,1,4.000000e+000,6.568909e-003,0.000000e+000,0,,0,
1524513306.872,,0.000000e+000,5.499773e+001,-4.422673e-006,0.000000e+000,3,9.246206e-001,0.000000e+000,,,,,,,,,,,,,,32,1,4.000000e+000,1.308441e-003,0.000000e+000,0,,0,
1524513357.232,,0.000000e+000,5.499773e+001,-4.105889e-006,0.000000e+000,3,9.144690e-001,0.000000e+000,,,,,,,,,,,,,,32,1,4.000000e+000,1.308441e-003,0.000000e+000,0,,0,
1524513407.432,,0.000000e+000,5.499971e+001,-3.771535e-006,0.000000e+000,3,9.025573e-001,0.000000e+000,,,,,,,,,,,,,,32,1,4.000000e+000,2.639771e-003,0.000000e+000,0,,0,
1524513458.082,,0.000000e+000,5.499905e+001,-3.536436e-006,0.000000e+000,3,9.052565e-001,0.000000e+000,,,,,,,,,,,,,,32,1,4.000000e+000,1.319885e-003,0.000000e+000,0,,0,
1524513508.522,,0.000000e+000,5.499708e+001,-3.363545e-006,0.000000e+000,3,8.871751e-001,0.000000e+000,,,,,,,,,,,,,,32,1,4.000000e+000,2.620697e-003,0.000000e+000,0,,0,
1524513559.092,,0.000000e+000,5.499709e+001,-3.291360e-006,0.000000e+000,3,8.841777e-001,0.000000e+000,,,,,,,,,,,,,,32,1,4.000000e+000,1.840973e-002,0.000000e+000,0,,0,
1524513609.912,,0.000000e+000,5.499380e+001,-3.061941e-006,0.000000e+000,3,8.503926e-001,0.000000e+000,,,,,,,,,,,,,,32,1,4.000000e+000,6.572723e-003,0.000000e+000,0,,0,
1524513660.392,,0.000000e+000,5.499380e+001,-2.929175e-006,0.000000e+000,3,8.741338e-001,0.000000e+000,,,,,,,,,,,,,,32,1,4.000000e+000,1.182938e-002,0.000000e+000,0,,0,
1524513711.262,,0.000000e+000,5.499511e+001,-2.774232e-006,0.000000e+000,3,8.637668e-001,0.000000e+000,,,,,,,,,,,,,,32,1,4.000000e+000,1.184082e-002,0.000000e+000,0,,0,
1524513762.452,,0.000000e+000,5.499840e+001,-2.769399e-006,0.000000e+000,3,8.330983e-001,0.000000e+000,,,,,,,,,,,,,,32,1,4.000000e+000,5.260468e-003,0.000000e+000,0,,0,
1524513826.652,,0.000000e+000,5.499380e+001,-2.369623e-006,0.000000e+000,3,8.082517e-001,0.000000e+000,,,,,,,,,,,,,,32,1,4.000000e+000,1.308441e-003,0.000000e+000,0,,0,
1524513877.452,,0.000000e+000,5.499971e+001,-2.389074e-006,0.000000e+000,3,7.978417e-001,0.000000e+000,,,,,,,,,,,,,,32,1,4.000000e+000,2.639771e-003,0.000000e+000,0,,0,
1524513929.062,,0.000000e+000,5.499971e+001,-2.266457e-006,0.000000e+000,3,7.512368e-001,0.000000e+000,,,,,,,,,,,,,,32,1,4.000000e+000,0.000000e+000,0.000000e+000,0,,0,
1524513979.203,,0.000000e+000,5.500103e+001,-2.224852e-006,0.000000e+000,3,7.385783e-001,0.000000e+000,,,,,,,,,,,,,,32,1,4.000000e+000,2.639771e-003,0.000000e+000,0,,0,
1524514029.743,,0.000000e+000,5.500103e+001,-2.206510e-006,0.000000e+000,3,7.774063e-001,0.000000e+000,,,,,,,,,,,,,,32,1,4.000000e+000,7.888794e-003,0.000000e+000,0,,0,
1524514079.683,,0.000000e+000,5.499840e+001,-2.077664e-006,0.000000e+000,3,7.450791e-001,0.000000e+000,,,,,,,,,,,,,,32,1,4.000000e+000,5.260468e-003,0.000000e+000,0,,0,
1524514130.243,,0.000000e+000,5.499248e+001,-2.019497e-006,0.000000e+000,3,7.742276e-001,0.000000e+000,,,,,,,,,,,,,,32,1,4.000000e+000,6.580353e-003,0.000000e+000,0,,0,
1524514180.793,,0.000000e+000,5.499512e+001,-1.939808e-006,0.000000e+000,3,7.318724e-001,0.000000e+000,,,,,,,,,,,,,,32,1,4.000000e+000,1.446915e-002,0.000000e+000,0,,0,
1524514231.593,,0.000000e+000,5.499183e+001,-1.906049e-006,0.000000e+000,3,7.252805e-001,0.000000e+000,,,,,,,,,,,,,,32,1,4.000000e+000,2.632141e-003,0.000000e+000,0,,0,
1524514282.063,,0.000000e+000,5.499511e+001,-1.884894e-006,0.000000e+000,3,7.038953e-001,0.000000e+000,,,,,,,,,,,,,,32,1,4.000000e+000,3.940582e-003,0.000000e+000,0,,0,
1524514332.203,,0.000000e+000,5.500103e+001,-1.807741e-006,0.000000e+000,3,6.482669e-001,0.000000e+000,,,,,,,,,,,,,,32,1,4.000000e+000,1.316071e-002,0.000000e+000,0,,0,
1524514382.663,,0.000000e+000,5.499971e+001,-1.761749e-006,0.000000e+000,3,6.567920e-001,0.000000e+000,,,,,,,,,,,,,,32,1,4.000000e+000,2.639771e-003,0.000000e+000,0,,0,
1524514433.123,,0.000000e+000,5.499643e+001,-1.721316e-006,0.000000e+000,3,6.534291e-001,0.000000e+000,,,,,,,,,,,,,,32,1,4.000000e+000,1.312256e-003,0.000000e+000,0,,0,
1524514483.573,,0.000000e+000,5.499380e+001,-1.697438e-006,0.000000e+000,3,6.324490e-001,0.000000e+000,,,,,,,,,,,,,,32,1,4.000000e+000,1.182938e-002,0.000000e+000,0,,0,
1524514534.053,,0.000000e+000,5.500169e+001,-1.650052e-006,0.000000e+000,3,6.146514e-001,0.000000e+000,,,,,,,,,,,,,,32,1,4.000000e+000,1.319885e-003,0.000000e+000,0,,0,
1524514584.503,,0.000000e+000,5.499511e+001,-1.636137e-006,0.000000e+000,3,5.941465e-001,0.000000e+000,,,,,,,,,,,,,,32,1,4.000000e+000,1.319885e-003,0.000000e+000,0,,0,
1524514634.963,,0.000000e+000,5.500037e+001,-1.588327e-006,0.000000e+000,3,5.761313e-001,0.000000e+000,,,,,,,,,,,,,,32,1,4.000000e+000,3.959656e-003,0.000000e+000,0,,0,
1524514685.404,,0.000000e+000,5.500103e+001,-1.546491e-006,0.000000e+000,3,5.567393e-001,0.000000e+000,,,,,,,,,,,,,,32,1,4.000000e+000,5.279541e-003,0.000000e+000,0,,0,
1524514749.204,,0.000000e+000,5.500169e+001,-1.575779e-006,0.000000e+000,3,5.968277e-001,0.000000e+000,,,,,,,,,,,,,,32,1,4.000000e+000,1.446915e-002,0.000000e+000,0,,0,
1524514799.224,,0.000000e+000,5.499445e+001,-1.615047e-006,0.000000e+000,3,6.420732e-001,0.000000e+000,,,,,,,,,,,,,,32,1,4.000000e+000,5.260468e-003,0.000000e+000,0,,0,
1524514848.934,,0.000000e+000,5.499445e+001,-1.582149e-006,0.000000e+000,3,6.447182e-001,0.000000e+000,,,,,,,,,,,,,,32,1,4.000000e+000,5.260468e-003,0.000000e+000,0,,0,
1524514898.844,,0.000000e+000,5.499577e+001,-1.530209e-006,0.000000e+000,3,6.175148e-001,0.000000e+000,,,,,,,,,,,,,,32,1,4.000000e+000,7.888794e-003,0.000000e+000,0,,0,
1524514949.364,,0.000000e+000,5.499577e+001,-1.586647e-006,0.000000e+000,3,6.085669e-001,0.000000e+000,,,,,,,,,,,,,,32,1,4.000000e+000,7.888794e-003,0.000000e+000,0,,0,
1524514999.644,,0.000000e+000,5.500695e+001,-1.590323e-006,0.000000e+000,3,6.205161e-001,0.000000e+000,,,,,,,,,,,,,,32,1,4.000000e+000,1.319885e-003,0.000000e+000,0,,0,
1524515049.894,,0.000000e+000,5.500498e+001,-1.596974e-006,0.000000e+000,3,6.262443e-001,0.000000e+000,,,,,,,,,,,,,,32,1,4.000000e+000,2.620697e-003,0.000000e+000,0,,0,
1524515100.774,,0.000000e+000,5.499248e+001,-1.499862e-006,0.000000e+000,3,5.613992e-001,0.000000e+000,,,,,,,,,,,,,,32,1,4.000000e+000,1.319885e-003,0.000000e+000,0,,0,
1524515151.204,,0.000000e+000,5.499511e+001,-1.481521e-006,0.000000e+000,3,5.479734e-001,0.000000e+000,,,,,,,,,,,,,,32,1,4.000000e+000,1.319885e-003,0.000000e+000,0,,0,
1524515201.714,,0.000000e+000,5.499775e+001,-1.593498e-006,0.000000e+000,3,6.494842e-001,0.000000e+000,,,,,,,,,,,,,,32,1,4.000000e+000,1.184845e-002,0.000000e+000,0,,0,
1524515252.234,,0.000000e+000,5.500169e+001,-1.499541e-006,0.000000e+000,3,6.254201e-001,0.000000e+000,,,,,,,,,,,,,,32,1,4.000000e+000,1.319885e-003,0.000000e+000,0,,0,
1524515302.964,,0.000000e+000,5.500694e+001,-1.520852e-006,0.000000e+000,3,5.731208e-001,0.000000e+000,,,,,,,,,,,,,,32,1,4.000000e+000,3.948212e-003,0.000000e+000,0,,0,
1524515353.114,,0.000000e+000,5.499840e+001,-1.466111e-006,0.000000e+000,3,5.576645e-001,0.000000e+000,,,,,,,,,,,,,,32,1,4.000000e+000,7.900238e-003,0.000000e+000,0,,0,
1524515403.625,,0.000000e+000,5.500103e+001,-1.567425e-006,0.000000e+000,3,5.832255e-001,0.000000e+000,,,,,,,,,,,,,,32,1,4.000000e+000,2.639771e-003,0.000000e+000,0,,0,
1524515453.465,,0.000000e+000,5.499314e+001,-1.510252e-006,0.000000e+000,3,5.844914e-001,0.000000e+000,,,,,,,,,,,,,,32,1,4.000000e+000,5.260468e-003,0.000000e+000,0,,0,
1524515503.365,,0.000000e+000,5.500695e+001,-1.479195e-006,0.000000e+000,3,5.440160e-001,0.000000e+000,,,,,,,,,,,,,,32,1,4.000000e+000,1.319885e-003,0.000000e+000,0,,0,
1524515553.965,,0.000000e+000,5.499511e+001,-1.493541e-006,0.000000e+000,3,5.822430e-001,0.000000e+000,,,,,,,,,,,,,,32,1,4.000000e+000,9.201050e-003,0.000000e+000,0,,0,
1524515604.425,,0.000000e+000,5.500103e+001,-1.517506e-006,0.000000e+000,3,5.557146e-001,0.000000e+000,,,,,,,,,,,,,,32,1,4.000000e+000,2.639771e-003,0.000000e+000,0,,0,
1524515668.275,,0.000000e+000,5.499511e+001,-1.485416e-006,0.000000e+000,3,6.111133e-001,0.000000e+000,,,,,,,,,,,,,,32,1,4.000000e+000,6.568909e-003,0.000000e+000,0,,0,
1524515718.405,,0.000000e+000,5.499182e+001,-1.531760e-006,0.000000e+000,3,5.725411e-001,0.000000e+000,,,,,,,,,,,,,,32,1,4.000000e+000,1.314163e-002,0.000000e+000,0,,0,
1524515768.295,,0.000000e+000,5.499445e+001,-1.518291e-006,0.000000e+000,3,6.081654e-001,0.000000e+000,,,,,,,,,,,,,,32,1,4.000000e+000,5.260468e-003,0.000000e+000,0,,0,
1524515818.585,,0.000000e+000,5.499774e+001,-1.555567e-006,0.000000e+000,3,6.148106e-001,0.000000e+000,,,,,,,,,,,,,,32,1,4.000000e+000,6.580353e-003,0.000000e+000,0,,0,
1524515868.545,,0.000000e+000,5.500366e+001,-1.531776e-006,0.000000e+000,3,5.879931e-001,0.000000e+000,,,,,,,,,,,,,,32,1,4.000000e+000,2.620697e-003,0.000000e+000,0,,0,
1524515919.695,,0.000000e+000,5.499905e+001,-1.580037e-006,0.000000e+000,3,6.068738e-001,0.000000e+000,,,,,,,,,,,,,,32,1,4.000000e+000,3.948212e-003,0.000000e+000,0,,0,
1524529498.314,,0.000000e+000,5.499117e+001,1.060743e-005,0.000000e+000,3,7.909513e-001,0.000000e+000,,,,,,,,,,,,,,32,1,4.000000e+000,1.312256e-003,0.000000e+000,0,,0,
1524529549.094,,0.000000e+000,5.500300e+001,8.318839e-006,0.000000e+000,3,7.989451e-001,0.000000e+000,,,,,,,,,,,,,,32,1,4.000000e+000,3.940582e-003,0.000000e+000,0,,0,
1524529599.034,,0.000000e+000,5.499445e+001,7.218538e-006,0.000000e+000,3,7.979565e-001,0.000000e+000,,,,,,,,,,,,,,32,1,4.000000e+000,1.052094e-002,0.000000e+000,0,,0,
1524529649.874,,0.000000e+000,5.499709e+001,6.399290e-006,0.000000e+000,3,7.965975e-001,0.000000e+000,,,,,,,,,,,,,,32,1,4.000000e+000,1.840973e-002,0.000000e+000,0,,0,
1524529700.825,,0.000000e+000,5.499708e+001,5.811298e-006,0.000000e+000,3,8.009071e-001,0.000000e+000,,,,,,,,,,,,,,32,1,4.000000e+000,2.620697e-003,0.000000e+000,0,,0,
1524529751.205,,0.000000e+000,5.499577e+001,5.470118e-006,0.000000e+000,3,8.101443e-001,0.000000e+000,,,,,,,,,,,,,,32,1,4.000000e+000,0.000000e+000,0.000000e+000,0,,0,
1524529801.155,,0.000000e+000,5.499774e+001,5.124070e-006,0.000000e+000,3,8.116685e-001,0.000000e+000,,,,,,,,,,,,,,32,1,4.000000e+000,3.940582e-003,0.000000e+000,0,,0,
1524529851.715,,0.000000e+000,5.499773e+001,4.808863e-006,0.000000e+000,3,8.185893e-001,0.000000e+000,,,,,,,,,,,,,,32,1,4.000000e+000,1.308441e-003,0.000000e+000,0,,0,
1524529902.365,,0.000000e+000,5.499971e+001,4.569731e-006,0.000000e+000,3,7.913539e-001,0.000000e+000,,,,,,,,,,,,,,32,1,4.000000e+000,0.000000e+000,0.000000e+000,0,,0,
1524529953.465,,0.000000e+000,5.499511e+001,4.331006e-006,0.000000e+000,3,7.939479e-001,0.000000e+000,,,,,,,,,,,,,,32,1,4.000000e+000,9.201050e-003,0.000000e+000,0,,0,
1524530003.835,,0.000000e+000,5.499905e+001,4.095719e-006,0.000000e+000,3,7.892242e-001,0.000000e+000,,,,,,,,,,,,,,32,1,4.000000e+000,3.948212e-003,0.000000e+000,0,,0,
1524530054.665,,0.000000e+000,5.499708e+001,3.935739e-006,0.000000e+000,3,7.843425e-001,0.000000e+000,,,,,,,,,,,,,,32,1,4.000000e+000,5.260468e-003,0.000000e+000,0,,0,
1524530104.815,,0.000000e+000,5.499708e+001,3.736952e-006,0.000000e+000,3,8.047199e-001,0.000000e+000,,,,,,,,,,,,,,32,1,4.000000e+000,2.620697e-003,0.000000e+000,0,,0,
1524530154.825,,0.000000e+000,5.499577e+001,3.545202e-006,0.000000e+000,3,7.955465e-001,0.000000e+000,,,,,,,,,,,,,,32,1,4.000000e+000,5.249023e-003,0.000000e+000,0,,0,
1524530205.195,,0.000000e+000,5.500629e+001,3.387089e-006,0.000000e+000,3,7.866888e-001,0.000000e+000,,,,,,,,,,,,,,32,1,4.000000e+000,1.842880e-002,0.000000e+000,0,,0,
1524530255.755,,0.000000e+000,5.500037e+001,3.338489e-006,0.000000e+000,3,7.989619e-001,0.000000e+000,,,,,,,,,,,,,,32,1,4.000000e+000,1.319885e-003,0.000000e+000,0,,0,
1524530306.295,,0.000000e+000,5.499577e+001,3.140095e-006,0.000000e+000,3,7.568703e-001,0.000000e+000,,,,,,,,,,,,,,32,1,4.000000e+000,2.632141e-003,0.000000e+000,0,,0,
1524530356.515,,0.000000e+000,5.499313e+001,3.056912e-006,0.000000e+000,3,7.485498e-001,0.000000e+000,,,,,,,,,,,,,,32,1,4.000000e+000,2.628326e-003,0.000000e+000,0,,0,
1524530406.516,,0.000000e+000,5.499840e+001,3.027183e-006,0.000000e+000,3,7.447932e-001,0.000000e+000,,,,,,,,,,,,,,32,1,4.000000e+000,7.900238e-003,0.000000e+000,0,,0,
1524530456.366,,0.000000e+000,5.499643e+001,3.072144e-006,0.000000e+000,3,7.629216e-001,0.000000e+000,,,,,,,,,,,,,,32,1,4.000000e+000,6.568909e-003,0.000000e+000,0,,0,
1524530506.786,,0.000000e+000,5.499773e+001,2.948397e-006,0.000000e+000,3,7.511038e-001,0.000000e+000,,,,,,,,,,,,,,32,1,4.000000e+000,1.308441e-003,0.000000e+000,0,,0,
1524530557.376,,0.000000e+000,5.499774e+001,2.815188e-006,0.000000e+000,3,7.558340e-001,0.000000e+000,,,,,,,,,,,,,,32,1,4.000000e+000,3.940582e-003,0.000000e+000,0,,0,
1524530607.536,,0.000000e+000,5.499971e+001,2.703051e-006,0.000000e+000,3,7.514436e-001,0.000000e+000,,,,,,,,,,,,,,32,1,4.000000e+000,2.639771e-003,0.000000e+000,0,,0,
1524530657.736,,0.000000e+000,5.499971e+001,2.658611e-006,0.000000e+000,3,7.731078e-001,0.000000e+000,,,,,,,,,,,,,,32,1,4.000000e+000,2.639771e-003,0.000000e+000,0,,0,
1524530708.616,,0.000000e+000,5.500037e+001,2.614915e-006,0.000000e+000,3,7.231408e-001,0.000000e+000,,,,,,,,,,,,,,32,1,4.000000e+000,1.319885e-003,0.000000e+000,0,,0,
1524530758.976,,0.000000e+000,5.500169e+001,2.618999e-006,0.000000e+000,3,7.469644e-001,0.000000e+000,,,,,,,,,,,,,,32,1,4.000000e+000,1.319885e-003,0.000000e+000,0,,0,
1524530810.236,,0.000000e+000,5.499445e+001,2.438360e-006,0.000000e+000,3,7.317467e-001,0.000000e+000,,,,,,,,,,,,,,32,1,4.000000e+000,5.260468e-003,0.000000e+000,0,,0,
1524530860.706,,0.000000e+000,5.499642e+001,2.425068e-006,0.000000e+000,3,7.472814e-001,0.000000e+000,,,,,,,,,,,,,,32,1,4.000000e+000,3.940582e-003,0.000000e+000,0,,0,
1524530911.306,,0.000000e+000,5.499445e+001,2.314054e-006,0.000000e+000,3,7.098392e-001,0.000000e+000,,,,,,,,,,,,,,32,1,4.000000e+000,2.628326e-003,0.000000e+000,0,,0,
1524530961.576,,0.000000e+000,5.499773e+001,2.278421e-006,0.000000e+000,3,7.459424e-001,0.000000e+000,,,,,,,,,,,,,,32,1,4.000000e+000,1.308441e-003,0.000000e+000,0,,0,
1524531011.946,,0.000000e+000,5.500103e+001,2.233295e-006,0.000000e+000,3,7.046278e-001,0.000000e+000,,,,,,,,,,,,,,32,1,4.000000e+000,1.052094e-002,0.000000e+000,0,,0,
1524531062.156,,0.000000e+000,5.499709e+001,2.166474e-006,0.000000e+000,3,7.019475e-001,0.000000e+000,,,,,,,,,,,,,,32,1,4.000000e+000,1.052856e-002,0.000000e+000,0,,0,
1524531112.807,,0.000000e+000,5.500103e+001,2.116126e-006,0.000000e+000,3,6.949667e-001,0.000000e+000,,,,,,,,,,,,,,32,1,4.000000e+000,2.639771e-003,0.000000e+000,0,,0,
1524531163.067,,0.000000e+000,5.500169e+001,2.101181e-006,0.000000e+000,3,6.928928e-001,0.000000e+000,,,,,,,,,,,,,,32,1,4.000000e+000,1.709747e-002,0.000000e+000,0,,0,
1524531213.567,,0.000000e+000,5.499248e+001,2.076815e-006,0.000000e+000,3,6.876618e-001,0.000000e+000,,,,,,,,,,,,,,32,1,4.000000e+000,9.201050e-003,0.000000e+000,0,,0,
1524531264.017,,0.000000e+000,5.499643e+001,1.998412e-006,0.000000e+000,3,6.772591e-001,0.000000e+000,,,,,,,,,,,,,,32,1,4.000000e+000,1.312256e-003,0.000000e+000,0,,0,
1524531314.417,,0.000000e+000,5.499972e+001,1.962392e-006,0.000000e+000,3,6.820157e-001,0.000000e+000,,,,,,,,,,,,,,32,1,4.000000e+000,5.268097e-003,0.000000e+000,0,,0,
1524531364.237,,0.000000e+000,5.499709e+001,1.955397e-006,0.000000e+000,3,7.121143e-001,0.000000e+000,,,,,,,,,,,,,,32,1,4.000000e+000,1.052856e-002,0.000000e+000,0,,0,
1524531414.807,,0.000000e+000,5.499905e+001,1.914227e-006,0.000000e+000,3,6.380670e-001,0.000000e+000,,,,,,,,,,,,,,32,1,4.000000e+000,1.319885e-003,0.000000e+000,0,,0,
1524531466.027,,0.000000e+000,5.499248e+001,1.894896e-006,0.000000e+000,3,6.430048e-001,0.000000e+000,,,,,,,,,,,,,,32,1,4.000000e+000,1.446152e-002,0.000000e+000,0,,0,
1524531517.297,,0.000000e+000,5.500301e+001,1.790293e-006,0.000000e+000,3,6.492742e-001,0.000000e+000,,,,,,,,,,,,,,32,1,4.000000e+000,1.319885e-003,0.000000e+000,0,,0,
1524531567.417,,0.000000e+000,5.499445e+001,1.740707e-006,0.000000e+000,3,6.245860e-001,0.000000e+000,,,,,,,,,,,,,,32,1,4.000000e+000,5.260468e-003,0.000000e+000,0,,0,
1524531618.657,,0.000000e+000,5.500103e+001,1.797303e-006,0.000000e+000,3,6.415144e-001,0.000000e+000,,,,,,,,,,,,,,32,1,4.000000e+000,2.639771e-003,0.000000e+000,0,,0,
1524531669.087,,0.000000e+000,5.499708e+001,1.803644e-006,0.000000e+000,3,6.575539e-001,0.000000e+000,,,,,,,,,,,,,,32,1,4.000000e+000,2.620697e-003,0.000000e+000,0,,0,
1524531719.587,,0.000000e+000,5.499840e+001,1.759881e-006,0.000000e+000,3,6.552614e-001,0.000000e+000,,,,,,,,,,,,,,32,1,4.000000e+000,7.900238e-003,0.000000e+000,0,,0,
1524531770.037,,0.000000e+000,5.499839e+001,1.790366e-006,0.000000e+000,3,6.597459e-001,0.000000e+000,,,,,,,,,,,,,,32,1,4.000000e+000,0.000000e+000,0.000000e+000,0,,0,
1524531820.457,,0.000000e+000,5.499643e+001,1.729032e-006,0.000000e+000,3,6.254323e-001,0.000000e+000,,,,,,,,,,,,,,32,1,4.000000e+000,1.312256e-003,0.000000e+000,0,,0,
1524531870.958,,0.000000e+000,5.499577e+001,1.704521e-006,0.000000e+000,3,6.195847e-001,0.000000e+000,,,,,,,,,,,,,,32,1,4.000000e+000,2.632141e-003,0.000000e+000,0,,0,
1524531921.368,,0.000000e+000,5.500235e+001,1.668365e-006,0.000000e+000,3,6.068093e-001,0.000000e+000,,,,,,,,,,,,,,32,1,4.000000e+000,2.639771e-003,0.000000e+000,0,,0,
1524531971.288,,0.000000e+000,5.499905e+001,1.696492e-006,0.000000e+000,3,6.084037e-001,0.000000e+000,,,,,,,,,,,,,,32,1,4.000000e+000,1.319885e-003,0.000000e+000,0,,0,
1524532021.738,,0.000000e+000,5.500103e+001,1.603118e-006,0.000000e+000,3,6.008303e-001,0.000000e+000,,,,,,,,,,,,,,32,1,4.000000e+000,2.639771e-003,0.000000e+000,0,,0,
1524532072.308,,0.000000e+000,5.499708e+001,1.610706e-006,0.000000e+000,3,6.001841e-001,0.000000e+000,,,,,,,,,,,,,,32,1,4.000000e+000,2.620697e-003,0.000000e+000,0,,0,
1524532122.568,,0.000000e+000,5.499905e+001,1.465538e-006,0.000000e+000,3,5.072590e-001,0.000000e+000,,,,,,,,,,,,,,32,1,4.000000e+000,1.319885e-003,0.000000e+000,0,,0,
1524532172.968,,0.000000e+000,5.500037e+001,1.344769e-006,0.000000e+000,3,4.728732e-001,0.000000e+000,,,,,,,,,,,,,,32,1,4.000000e+000,9.201050e-003,0.000000e+000,0,,0,
1524532223.378,,0.000000e+000,5.499577e+001,1.412084e-006,0.000000e+000,3,5.193921e-001,0.000000e+000,,,,,,,,,,,,,,32,1,4.000000e+000,1.316071e-002,0.000000e+000,0,,0,
1524532273.718,,0.000000e+000,5.499905e+001,1.471832e-006,0.000000e+000,3,5.777819e-001,0.000000e+000,,,,,,,,,,,,,,32,1,4.000000e+000,3.948212e-003,0.000000e+000,0,,0,
1524532323.748,,0.000000e+000,5.500103e+001,1.352008e-006,0.000000e+000,3,5.007883e-001,0.000000e+000,,,,,,,,,,,,,,32,1,4.000000e+000,5.279541e-003,0.000000e+000,0,,0,
1524532374.418,,0.000000e+000,5.499708e+001,1.327874e-006,0.000000e+000,3,4.902920e-001,0.000000e+000,,,,,,,,,,,,,,32,1,4.000000e+000,0.000000e+000,0.000000e+000,0,,0,
1524532424.468,,0.000000e+000,5.499840e+001,1.278847e-006,0.000000e+000,3,4.864309e-001,0.000000e+000,,,,,,,,,,,,,,32,1,4.000000e+000,7.900238e-003,0.000000e+000,0,,0,
1524532475.018,,0.000000e+000,5.499380e+001,1.378751e-006,0.000000e+000,3,4.925233e-001,0.000000e+000,,,,,,,,,,,,,,32,1,4.000000e+000,1.308441e-003,0.000000e+000,0,,0,
1524532525.598,,0.000000e+000,5.499511e+001,1.353929e-006,0.000000e+000,3,5.019048e-001,0.000000e+000,,,,,,,,,,,,,,32,1,4.000000e+000,1.319885e-003,0.000000e+000,0,,0,
1524532576.049,,0.000000e+000,5.499708e+001,1.303999e-006,0.000000e+000,3,5.177585e-001,0.000000e+000,,,,,,,,,,,,,,32,1,4.000000e+000,0.000000e+000,0.000000e+000,0,,0,
1524532626.199,,0.000000e+000,5.500103e+001,1.294869e-006,0.000000e+000,3,5.447822e-001,0.000000e+000,,,,,,,,,,,,,,32,1,4.000000e+000,2.639771e-003,0.000000e+000,0,,0,
1524532676.449,,0.000000e+000,5.499577e+001,1.275154e-006,0.000000e+000,3,5.134343e-001,0.000000e+000,,,,,,,,,,,,,,32,1,4.000000e+000,1.316071e-002,0.000000e+000,0,,0,
1524532726.339,,0.000000e+000,5.499708e+001,1.250796e-006,0.000000e+000,3,4.896232e-001,0.000000e+000,,,,,,,,,,,,,,32,1,4.000000e+000,0.000000e+000,0.000000e+000,0,,0,
1524532776.969,,0.000000e+000,5.500103e+001,1.180817e-006,0.000000e+000,3,4.716214e-001,0.000000e+000,,,,,,,,,,,,,,32,1,4.000000e+000,5.279541e-003,0.000000e+000,0,,0,
1524532828.099,,0.000000e+000,5.499117e+001,1.250519e-006,0.000000e+000,3,4.800363e-001,0.000000e+000,,,,,,,,,,,,,,32,1,4.000000e+000,1.183319e-002,0.000000e+000,0,,0,
1524532877.829,,0.000000e+000,5.499380e+001,1.289591e-006,0.000000e+000,3,5.136161e-001,0.000000e+000,,,,,,,,,,,,,,32,1,4.000000e+000,1.182938e-002,0.000000e+000,0,,0,
1524532928.259,,0.000000e+000,5.499971e+001,1.280786e-006,0.000000e+000,3,4.949174e-001,0.000000e+000,,,,,,,,,,,,,,32,1,4.000000e+000,2.639771e-003,0.000000e+000,0,,0,
1524532978.499,,0.000000e+000,5.500432e+001,1.230487e-006,0.000000e+000,3,4.368029e-001,0.000000e+000,,,,,,,,,,,,,,32,1,4.000000e+000,1.300812e-003,0.000000e+000,0,,0,
1524533028.949,,0.000000e+000,5.499773e+001,1.211882e-006,0.000000e+000,3,4.004241e-001,0.000000e+000,,,,,,,,,,,,,,32,1,4.000000e+000,1.308441e-003,0.000000e+000,0,,0,
1524533079.799,,0.000000e+000,5.499642e+001,1.322946e-006,0.000000e+000,3,4.712473e-001,0.000000e+000,,,,,,,,,,,,,,32,1,4.000000e+000,3.940582e-003,0.000000e+000,0,,0,
1524533130.089,,0.000000e+000,5.499643e+001,1.282643e-006,0.000000e+000,3,4.499520e-001,0.000000e+000,,,,,,,,,,,,,,32,1,4.000000e+000,1.312256e-003,0.000000e+000,0,,0,
1524533180.539,,0.000000e+000,5.499708e+001,1.243053e-006,0.000000e+000,3,4.363601e-001,0.000000e+000,,,,,,,,,,,,,,32,1,4.000000e+000,2.620697e-003,0.000000e+000,0,,0,
1524533230.979,,0.000000e+000,5.500366e+001,1.159651e-006,0.000000e+000,3,4.549172e-001,0.000000e+000,,,,,,,,,,,,,,32,1,4.000000e+000,5.260468e-003,0.000000e+000,0,,0,
1524533281.430,,0.000000e+000,5.499511e+001,1.176758e-006,0.000000e+000,3,4.805433e-001,0.000000e+000,,,,,,,,,,,,,,32,1,4.000000e+000,6.568909e-003,0.000000e+000,0,,0,
1524533331.920,,0.000000e+000,5.499905e+001,1.267715e-006,0.000000e+000,3,4.107543e-001,0.000000e+000,,,,,,,,,,,,,,32,1,4.000000e+000,3.948212e-003,0.000000e+000,0,,0,
1524533382.350,,0.000000e+000,5.499511e+001,1.248240e-006,0.000000e+000,3,4.075106e-001,0.000000e+000,,,,,,,,,,,,,,32,1,4.000000e+000,1.319885e-003,0.000000e+000,0,,0,
1524533432.800,,0.000000e+000,5.499905e+001,1.264508e-006,0.000000e+000,3,4.113541e-001,0.000000e+000,,,,,,,,,,,,,,32,1,4.000000e+000,3.948212e-003,0.000000e+000,0,,0,
1524533482.620,,0.000000e+000,5.500564e+001,1.235347e-006,0.000000e+000,3,4.762979e-001,0.000000e+000,,,,,,,,,,,,,,32,1,4.000000e+000,3.940582e-003,0.000000e+000,0,,0,
1524533533.180,,0.000000e+000,5.500366e+001,1.279516e-006,0.000000e+000,3,4.797632e-001,0.000000e+000,,,,,,,,,,,,,,32,1,4.000000e+000,2.620697e-003,0.000000e+000,0,,0,
1524533583.570,,0.000000e+000,5.499905e+001,1.088452e-006,0.000000e+000,3,3.572556e-001,0.000000e+000,,,,,,,,,,,,,,32,1,4.000000e+000,3.948212e-003,0.000000e+000,0,,0,
1524533633.150,,0.000000e+000,5.499840e+001,1.245767e-006,0.000000e+000,3,3.829808e-001,0.000000e+000,,,,,,,,,,,,,,32,1,4.000000e+000,5.260468e-003,0.000000e+000,0,,0,
1524533683.880,,0.000000e+000,5.500103e+001,1.230352e-006,0.000000e+000,3,3.310529e-001,0.000000e+000,,,,,,,,,,,,,,32,1,4.000000e+000,5.279541e-003,0.000000e+000,0,,0,
1524533734.250,,0.000000e+000,5.500498e+001,1.232911e-006,0.000000e+000,3,3.825206e-001,0.000000e+000,,,,,,,,,,,,,,32,1,4.000000e+000,5.260468e-003,0.000000e+000,0,,0,
1524533784.190,,0.000000e+000,5.499577e+001,1.164889e-006,0.000000e+000,3,3.319173e-001,0.000000e+000,,,,,,,,,,,,,,32,1,4.000000e+000,2.632141e-003,0.000000e+000,0,,0,
1524533834.790,,0.000000e+000,5.500169e+001,1.177233e-006,0.000000e+000,3,4.090254e-001,0.000000e+000,,,,,,,,,,,,,,32,1,4.000000e+000,1.319885e-003,0.000000e+000,0,,0,
1524533884.540,,0.000000e+000,5.499971e+001,1.137648e-006,0.000000e+000,3,3.132071e-001,0.000000e+000,,,,,,,,,,,,,,32,1,4.000000e+000,2.639771e-003,0.000000e+000,0,,0,
1524533934.670,,0.000000e+000,5.499577e+001,1.077810e-006,0.000000e+000,3,3.003370e-001,0.000000e+000,,,,,,,,,,,,,,32,1,4.000000e+000,5.249023e-003,0.000000e+000,0,,0,
1524533985.021,,0.000000e+000,5.499708e+001,9.506514e-007,0.000000e+000,3,1.912178e-001,0.000000e+000,,,,,,,,,,,,,,32,1,4.000000e+000,5.260468e-003,0.000000e+000,0,,0,
1524534035.811,,0.000000e+000,5.500168e+001,9.664851e-007,0.000000e+000,3,2.015258e-001,0.000000e+000,,,,,,,,,,,,,,32,1,4.000000e+000,6.580353e-003,0.000000e+000,0,,0,
1524534086.361,,0.000000e+000,5.500300e+001,9.860153e-007,0.000000e+000,3,2.894260e-001,0.000000e+000,,,,,,,,,,,,,,32,1,4.000000e+000,3.940582e-003,0.000000e+000,0,,0,
1524534136.361,,0.000000e+000,5.499840e+001,1.001077e-006,0.000000e+000,3,2.964811e-001,0.000000e+000,,,,,,,,,,,,,,32,1,4.000000e+000,2.628326e-003,0.000000e+000,0,,0,
1524534186.411,,0.000000e+000,5.499643e+001,1.017782e-006,0.000000e+000,3,3.441164e-001,0.000000e+000,,,,,,,,,,,,,,32,1,4.000000e+000,1.184082e-002,0.000000e+000,0,,0,
1524534236.361,,0.000000e+000,5.499248e+001,1.049513e-006,0.000000e+000,3,3.425691e-001,0.000000e+000,,,,,,,,,,,,,,32,1,4.000000e+000,6.580353e-003,0.000000e+000,0,,0,
1524534287.041,,0.000000e+000,5.500103e+001,1.018239e-006,0.000000e+000,3,2.515130e-001,0.000000e+000,,,,,,,,,,,,,,32,1,4.000000e+000,0.000000e+000,0.000000e+000,0,,0,
1524534337.291,,0.000000e+000,5.499642e+001,1.005211e-006,0.000000e+000,3,2.964098e-001,0.000000e+000,,,,,,,,,,,,,,32,1,4.000000e+000,3.940582e-003,0.000000e+000,0,,0,
1524534387.871,,0.000000e+000,5.500037e+001,1.002660e-006,0.000000e+000,3,2.555939e-001,0.000000e+000,,,,,,,,,,,,,,32,1,4.000000e+000,6.587982e-003,0.000000e+000,0,,0,
1524534437.901,,0.000000e+000,5.499906e+001,1.002821e-006,0.000000e+000,3,3.920793e-001,0.000000e+000,,,,,,,,,,,,,,32,1,4.000000e+000,6.580353e-003,0.000000e+000,0,,0,
1524534488.931,,0.000000e+000,5.499709e+001,1.011508e-006,0.000000e+000,3,2.898104e-001,0.000000e+000,,,,,,,,,,,,,,32,1,4.000000e+000,7.888794e-003,0.000000e+000,0,,0,
1524534538.801,,0.000000e+000,5.499971e+001,1.041903e-006,0.000000e+000,3,3.253811e-001,0.000000e+000,,,,,,,,,,,,,,32,1,4.000000e+000,0.000000e+000,0.000000e+000,0,,0,
1524534589.291,,0.000000e+000,5.499971e+001,1.092859e-006,0.000000e+000,3,3.233722e-001,0.000000e+000,,,,,,,,,,,,,,32,1,4.000000e+000,2.639771e-003,0.000000e+000,0,,0,
1524534639.531,,0.000000e+000,5.499775e+001,1.018963e-006,0.000000e+000,3,2.170881e-001,0.000000e+000,,,,,,,,,,,,,,32,1,4.000000e+000,9.208679e-003,0.000000e+000,0,,0,
1524534690.062,,0.000000e+000,5.499840e+001,1.037156e-006,0.000000e+000,3,2.118472e-001,0.000000e+000,,,,,,,,,,,,,,32,1,4.000000e+000,2.628326e-003,0.000000e+000,0,,0,
1524534740.182,,0.000000e+000,5.498788e+001,1.035887e-006,0.000000e+000,3,1.792669e-001,0.000000e+000,,,,,,,,,,,,,,32,1,4.000000e+000,5.260468e-003,0.000000e+000,0,,0,
1524534790.972,,0.000000e+000,5.499971e+001,1.045089e-006,0.000000e+000,3,1.767016e-001,0.000000e+000,,,,,,,,,,,,,,32,1,4.000000e+000,1.052094e-002,0.000000e+000,0,,0,
1524534841.222,,0.000000e+000,5.499972e+001,1.037847e-006,0.000000e+000,3,1.842777e-001,0.000000e+000,,,,,,,,,,,,,,32,1,4.000000e+000,1.578903e-002,0.000000e+000,0,,0,
1524534891.742,,0.000000e+000,5.500235e+001,1.060435e-006,0.000000e+000,3,2.077025e-001,0.000000e+000,,,,,,,,,,,,,,32,1,4.000000e+000,2.639771e-003,0.000000e+000,0,,0,
1524534941.922,,0.000000e+000,5.500103e+001,1.007681e-006,0.000000e+000,3,2.241033e-001,0.000000e+000,,,,,,,,,,,,,,32,1,4.000000e+000,7.888794e-003,0.000000e+000,0,,0,
1524534992.672,,0.000000e+000,5.500103e+001,1.019298e-006,0.000000e+000,3,2.096391e-001,0.000000e+000,,,,,,,,,,,,,,32,1,4.000000e+000,2.639771e-003,0.000000e+000,0,,0,
1524535042.122,,0.000000e+000,5.499708e+001,1.045993e-006,0.000000e+000,3,2.349786e-001,0.000000e+000,,,,,,,,,,,,,,32,1,4.000000e+000,5.260468e-003,0.000000e+000,0,,0,
1524535092.022,,0.000000e+000,5.500037e+001,1.027113e-006,0.000000e+000,3,2.852711e-001,0.000000e+000,,,,,,,,,,,,,,32,1,4.000000e+000,1.319885e-003,0.000000e+000,0,,0,
1524535142.382,,0.000000e+000,5.499774e+001,9.890980e-007,0.000000e+000,3,2.421198e-001,0.000000e+000,,,,,,,,,,,,,,32,1,4.000000e+000,3.940582e-003,0.000000e+000,0,,0,
1524535193.332,,0.000000e+000,5.499248e+001,8.678856e-007,0.000000e+000,3,1.104803e-001,0.000000e+000,,,,,,,,,,,,,,32,1,4.000000e+000,3.940582e-003,0.000000e+000,0,,0,
1524535243.532,,0.000000e+000,5.500498e+001,8.679394e-007,0.000000e+000,3,1.157277e-001,0.000000e+000,,,,,,,,,,,,,,32,1,4.000000e+000,1.842117e-002,0.000000e+000,0,,0,
1524535293.342,,0.000000e+000,5.499577e+001,8.749767e-007,0.000000e+000,3,1.014045e-001,0.000000e+000,,,,,,,,,,,,,,32,1,4.000000e+000,5.249023e-003,0.000000e+000,0,,0,
1524535344.342,,0.000000e+000,5.499972e+001,8.470509e-007,0.000000e+000,3,2.624323e-001,0.000000e+000,,,,,,,,,,,,,,32,1,4.000000e+000,7.900238e-003,0.000000e+000,0,,0,
1524535393.642,,0.000000e+000,5.500169e+001,8.579687e-007,0.000000e+000,3,1.449466e-001,0.000000e+000,,,,,,,,,,,,,,32,1,4.000000e+000,1.184082e-002,0.000000e+000,0,,0,
1524535444.583,,0.000000e+000,5.500103e+001,9.404805e-007,0.000000e+000,3,2.409125e-001,0.000000e+000,,,,,,,,,,,,,,32,1,4.000000e+000,2.639771e-003,0.000000e+000,0,,0,
1524535495.003,,0.000000e+000,5.499775e+001,9.247345e-007,0.000000e+000,3,2.035097e-001,0.000000e+000,,,,,,,,,,,,,,32,1,4.000000e+000,1.184845e-002,0.000000e+000,0,,0,
1524535545.063,,0.000000e+000,5.499905e+001,9.533387e-007,0.000000e+000,3,2.641977e-001,0.000000e+000,,,,,,,,,,,,,,32,1,4.000000e+000,1.319885e-003,0.000000e+000,0,,0,
1524535595.443,,0.000000e+000,5.500235e+001,8.992669e-007,0.000000e+000,3,1.407412e-001,0.000000e+000,,,,,,,,,,,,,,32,1,4.000000e+000,2.639771e-003,0.000000e+000,0,,0,
1524535645.933,,0.000000e+000,5.499577e+001,8.549130e-007,0.000000e+000,3,1.338704e-001,0.000000e+000,,,,,,,,,,,,,,32,1,4.000000e+000,7.888794e-003,0.000000e+000,0,,0,
1524535697.103,,0.000000e+000,5.499839e+001,8.990748e-007,0.000000e+000,3,1.989166e-001,0.000000e+000,,,,,,,,,,,,,,32,1,4.000000e+000,0.000000e+000,0.000000e+000,0,,0,
1524535747.273,,0.000000e+000,5.500103e+001,7.836873e-007,0.000000e+000,3,0.000000e+000,0.000000e+000,,,,,,,,,,,,,,32,1,4.000000e+000,5.279541e-003,0.000000e+000,0,,0,
1524535797.723,,0.000000e+000,5.499577e+001,8.290559e-007,0.000000e+000,3,0.000000e+000,0.000000e+000,,,,,,,,,,,,,,32,1,4.000000e+000,1.052094e-002,0.000000e+000,0,,0,
1524535848.453,,0.000000e+000,5.499773e+001,7.463311e-007,0.000000e+000,3,0.000000e+000,0.000000e+000,,,,,,,,,,,,,,32,1,4.000000e+000,1.308441e-003,0.000000e+000,0,,0,
1524535898.723,,0.000000e+000,5.499840e+001,7.842883e-007,0.000000e+000,3,0.000000e+000,0.000000e+000,,,,,,,,,,,,,,32,1,4.000000e+000,2.628326e-003,0.000000e+000,0,,0,
1524535949.163,,0.000000e+000,5.499577e+001,8.979496e-007,0.000000e+000,3,1.591862e-002,0.000000e+000,,,,,,,,,,,,,,32,1,4.000000e+000,2.632141e-003,0.000000e+000,0,,0,
1524535999.513,,0.000000e+000,5.499708e+001,8.927212e-007,0.000000e+000,3,7.875804e-003,0.000000e+000,,,,,,,,,,,,,,32,1,4.000000e+000,2.620697e-003,0.000000e+000,0,,0,
1524536050.273,,0.000000e+000,5.499577e+001,7.762221e-007,0.000000e+000,3,0.000000e+000,0.000000e+000,,,,,,,,,,,,,,32,1,4.000000e+000,2.632141e-003,0.000000e+000,0,,0,
1524536100.433,,0.000000e+000,5.499248e+001,8.589363e-007,0.000000e+000,3,0.000000e+000,0.000000e+000,,,,,,,,,,,,,,32,1,4.000000e+000,3.940582e-003,0.000000e+000,0,,0,
1524536150.874,,0.000000e+000,5.499905e+001,7.214483e-007,0.000000e+000,3,0.000000e+000,0.000000e+000,,,,,,,,,,,,,,32,1,4.000000e+000,1.319885e-003,0.000000e+000,0,,0,
1524536202.444,,0.000000e+000,5.499708e+001,8.726134e-007,0.000000e+000,3,0.000000e+000,0.000000e+000,,,,,,,,,,,,,,32,1,4.000000e+000,5.260468e-003,0.000000e+000,0,,0,
1524536253.174,,0.000000e+000,5.499840e+001,5.072132e-007,0.000000e+000,3,0.000000e+000,0.000000e+000,,,,,,,,,,,,,,32,1,4.000000e+000,2.628326e-003,0.000000e+000,0,,0,
1524536303.354,,0.000000e+000,5.500301e+001,7.770381e-007,0.000000e+000,3,0.000000e+000,0.000000e+000,,,,,,,,,,,,,,32,1,4.000000e+000,1.319885e-003,0.000000e+000,0,,0,
1524536353.414,,0.000000e+000,5.499840e+001,7.309781e-007,0.000000e+000,3,0.000000e+000,0.000000e+000,,,,,,,,,,,,,,32,1,4.000000e+000,5.260468e-003,0.000000e+000,0,,0,
1524536403.444,,0.000000e+000,5.499841e+001,5.703094e-007,0.000000e+000,3,0.000000e+000,0.000000e+000,,,,,,,,,,,,,,32,1,4.000000e+000,1.052856e-002,0.000000e+000,0,,0,
1524536453.304,,0.000000e+000,5.499511e+001,6.742825e-007,0.000000e+000,3,0.000000e+000,0.000000e+000,,,,,,,,,,,,,,32,1,4.000000e+000,1.319885e-003,0.000000e+000,0,,0,
1524536502.944,,0.000000e+000,5.500300e+001,6.592924e-007,0.000000e+000,3,0.000000e+000,0.000000e+000,,,,,,,,,,,,,,32,1,4.000000e+000,6.580353e-003,0.000000e+000,0,,0,
1524536553.284,,0.000000e+000,5.499577e+001,7.618097e-007,0.000000e+000,3,3.913065e-002,0.000000e+000,,,,,,,,,,,,,,32,1,4.000000e+000,5.249023e-003,0.000000e+000,0,,0,
1524536603.614,,0.000000e+000,5.500103e+001,8.553042e-007,0.000000e+000,3,8.524392e-002,0.000000e+000,,,,,,,,,,,,,,32,1,4.000000e+000,7.888794e-003,0.000000e+000,0,,0,
1524536654.044,,0.000000e+000,5.499972e+001,8.876714e-007,0.000000e+000,3,1.155348e-001,0.000000e+000,,,,,,,,,,,,,,32,1,4.000000e+000,5.268097e-003,0.000000e+000,0,,0,
1524536704.514,,0.000000e+000,5.499840e+001,8.305282e-007,0.000000e+000,3,1.381392e-001,0.000000e+000,,,,,,,,,,,,,,32,1,4.000000e+000,5.260468e-003,0.000000e+000,0,,0,
1524536754.374,,0.000000e+000,5.500103e+001,8.363498e-007,0.000000e+000,3,7.609235e-002,0.000000e+000,,,,,,,,,,,,,,32,1,4.000000e+000,7.888794e-003,0.000000e+000,0,,0,
1524536804.494,,0.000000e+000,5.500103e+001,8.470547e-007,0.000000e+000,3,0.000000e+000,0.000000e+000,,,,,,,,,,,,,,32,1,4.000000e+000,2.639771e-003,0.000000e+000,0,,0,
1524536855.175,,0.000000e+000,5.500169e+001,7.155691e-007,0.000000e+000,3,0.000000e+000,0.000000e+000,,,,,,,,,,,,,,32,1,4.000000e+000,3.959656e-003,0.000000e+000,0,,0,
1524536904.865,,0.000000e+000,5.500235e+001,7.529673e-007,0.000000e+000,3,0.000000e+000,0.000000e+000,,,,,,,,,,,,,,32,1,4.000000e+000,2.639771e-003,0.000000e+000,0,,0,
1524536955.365,,0.000000e+000,5.498853e+001,6.290691e-007,0.000000e+000,3,0.000000e+000,0.000000e+000,,,,,,,,,,,,,,32,1,4.000000e+000,6.572723e-003,0.000000e+000,0,,0,
1524537006.095,,0.000000e+000,5.499380e+001,8.058748e-007,0.000000e+000,3,0.000000e+000,0.000000e+000,,,,,,,,,,,,,,32,1,4.000000e+000,1.308441e-003,0.000000e+000,0,,0,
1524537056.285,,0.000000e+000,5.499314e+001,6.466184e-007,0.000000e+000,3,0.000000e+000,0.000000e+000,,,,,,,,,,,,,,32,1,4.000000e+000,1.578140e-002,0.000000e+000,0,,0,
1524537106.825,,0.000000e+000,5.500300e+001,5.906475e-007,0.000000e+000,3,0.000000e+000,0.000000e+000,,,,,,,,,,,,,,32,1,4.000000e+000,6.580353e-003,0.000000e+000,0,,0,
1524537157.765,,0.000000e+000,5.499839e+001,5.585039e-007,0.000000e+000,3,0.000000e+000,0.000000e+000,,,,,,,,,,,,,,32,1,4.000000e+000,0.000000e+000,0.000000e+000,0,,0,
1524537207.815,,0.000000e+000,5.499709e+001,5.285117e-007,0.000000e+000,3,0.000000e+000,0.000000e+000,,,,,,,,,,,,,,32,1,4.000000e+000,1.052856e-002,0.000000e+000,0,,0,
1524537257.605,,0.000000e+000,5.499577e+001,2.363219e-007,0.000000e+000,3,0.000000e+000,0.000000e+000,,,,,,,,,,,,,,32,1,4.000000e+000,2.632141e-003,0.000000e+000,0,,0,
1524537308.545,,0.000000e+000,5.500695e+001,5.733898e-007,0.000000e+000,3,0.000000e+000,0.000000e+000,,,,,,,,,,,,,,32,1,4.000000e+000,1.184082e-002,0.000000e+000,0,,0,
1524537359.035,,0.000000e+000,5.500301e+001,4.806996e-007,0.000000e+000,3,0.000000e+000,0.000000e+000,,,,,,,,,,,,,,32,1,4.000000e+000,1.319885e-003,0.000000e+000,0,,0,
1524537409.925,,0.000000e+000,5.500168e+001,4.320227e-007,0.000000e+000,3,0.000000e+000,0.000000e+000,,,,,,,,,,,,,,32,1,4.000000e+000,6.580353e-003,0.000000e+000,0,,0,
1524537460.625,,0.000000e+000,5.499905e+001,4.407458e-007,0.000000e+000,3,0.000000e+000,0.000000e+000,,,,,,,,,,,,,,32,1,4.000000e+000,1.319885e-003,0.000000e+000,0,,0,
1524537510.835,,0.000000e+000,5.499577e+001,6.068543e-007,0.000000e+000,3,0.000000e+000,0.000000e+000,,,,,,,,,,,,,,32,1,4.000000e+000,0.000000e+000,0.000000e+000,0,,0,
1524537560.936,,0.000000e+000,5.499905e+001,4.573833e-007,0.000000e+000,3,0.000000e+000,0.000000e+000,,,,,,,,,,,,,,32,1,4.000000e+000,3.948212e-003,0.000000e+000,0,,0,
1524537610.616,,0.000000e+000,5.500037e+001,7.400289e-007,0.000000e+000,3,0.000000e+000,0.000000e+000,,,,,,,,,,,,,,32,1,4.000000e+000,1.319885e-003,0.000000e+000,0,,0,
1524537661.496,,0.000000e+000,5.498853e+001,4.051428e-007,0.000000e+000,3,0.000000e+000,0.000000e+000,,,,,,,,,,,,,,32,1,4.000000e+000,3.948212e-003,0.000000e+000,0,,0,
1524537711.746,,0.000000e+000,5.498722e+001,5.745581e-007,0.000000e+000,3,0.000000e+000,0.000000e+000,,,,,,,,,,,,,,32,1,4.000000e+000,1.319885e-003,0.000000e+000,0,,0,
1524537761.646,,0.000000e+000,5.499708e+001,5.757411e-007,0.000000e+000,3,0.000000e+000,0.000000e+000,,,,,,,,,,,,,,32,1,4.000000e+000,5.260468e-003,0.000000e+000,0,,0,
1524537811.806,,0.000000e+000,5.500037e+001,3.666019e-007,0.000000e+000,3,0.000000e+000,0.000000e+000,,,,,,,,,,,,,,32,1,4.000000e+000,1.319885e-003,0.000000e+000,0,,0,
1524537862.356,,0.000000e+000,5.499117e+001,5.685534e-007,0.000000e+000,3,0.000000e+000,0.000000e+000,,,,,,,,,,,,,,32,1,4.000000e+000,1.183319e-002,0.000000e+000,0,,0,
1524537912.756,,0.000000e+000,5.499445e+001,4.809105e-007,0.000000e+000,3,0.000000e+000,0.000000e+000,,,,,,,,,,,,,,32,1,4.000000e+000,5.260468e-003,0.000000e+000,0,,0,
1524537963.196,,0.000000e+000,5.500300e+001,5.255620e-007,0.000000e+000,3,0.000000e+000,0.000000e+000,,,,,,,,,,,,,,32,1,4.000000e+000,3.940582e-003,0.000000e+000,0,,0,
1524538013.876,,0.000000e+000,5.499445e+001,4.956066e-007,0.000000e+000,3,0.000000e+000,0.000000e+000,,,,,,,,,,,,,,32,1,4.000000e+000,1.052094e-002,0.000000e+000,0,,0,
1524538063.946,,0.000000e+000,5.499643e+001,3.992661e-007,0.000000e+000,3,0.000000e+000,0.000000e+000,,,,,,,,,,,,,,32,1,4.000000e+000,2.236176e-002,0.000000e+000,0,,0,
1524538114.246,,0.000000e+000,5.499905e+001,1.636773e-007,0.000000e+000,3,0.000000e+000,0.000000e+000,,,,,,,,,,,,,,32,1,4.000000e+000,1.319885e-003,0.000000e+000,0,,0,
1524538164.216,,0.000000e+000,5.499709e+001,2.234743e-007,0.000000e+000,3,0.000000e+000,0.000000e+000,,,,,,,,,,,,,,32,1,4.000000e+000,7.888794e-003,0.000000e+000,0,,0,
1524538214.656,,0.000000e+000,5.499445e+001,1.406017e-007,0.000000e+000,3,0.000000e+000,0.000000e+000,,,,,,,,,,,,,,32,1,4.000000e+000,0.000000e+000,0.000000e+000,0,,0,
1524538265.097,,0.000000e+000,5.499183e+001,1.343502e-007,0.000000e+000,3,0.000000e+000,0.000000e+000,,,,,,,,,,,,,,32,1,4.000000e+000,2.632141e-003,0.000000e+000,0,,0,
1524538316.017,,0.000000e+000,5.499840e+001,3.821461e-007,0.000000e+000,3,0.000000e+000,0.000000e+000,,,,,,,,,,,,,,32,1,4.000000e+000,2.628326e-003,0.000000e+000,0,,0,
1524538365.977,,0.000000e+000,5.499313e+001,1.640637e-007,0.000000e+000,3,0.000000e+000,0.000000e+000,,,,,,,,,,,,,,32,1,4.000000e+000,1.050949e-002,0.000000e+000,0,,0,
1524538417.947,,0.000000e+000,5.499775e+001,5.079228e-008,0.000000e+000,3,0.000000e+000,0.000000e+000,,,,,,,,,,,,,,32,1,4.000000e+000,1.184845e-002,0.000000e+000,0,,0,
1524538468.727,,0.000000e+000,5.499972e+001,2.464793e-007,0.000000e+000,3,0.000000e+000,0.000000e+000,,,,,,,,,,,,,,32,1,4.000000e+000,5.268097e-003,0.000000e+000,0,,0,
1524538522.041,,0.000000e+000,5.499774e+001,2.400135e-007,0.000000e+000,3,0.000000e+000,0.000000e+000,,,,,,,,,,,,,,32,1,4.000000e+000,6.580353e-003,0.000000e+000,0,,0,
1524538571.941,,0.000000e+000,5.499643e+001,4.373513e-007,0.000000e+000,3,0.000000e+000,0.000000e+000,,,,,,,,,,,,,,32,1,4.000000e+000,9.208679e-003,0.000000e+000,0,,0,
1524538622.411,,0.000000e+000,5.499971e+001,1.102372e-007,0.000000e+000,3,0.000000e+000,0.000000e+000,,,,,,,,,,,,,,32,1,4.000000e+000,0.000000e+000,0.000000e+000,0,,0,
1524538672.851,,0.000000e+000,5.500234e+001,2.190167e-007,0.000000e+000,3,0.000000e+000,0.000000e+000,,,,,,,,,,,,,,32,1,4.000000e+000,7.900238e-003,0.000000e+000,0,,0,
1524538723.271,,0.000000e+000,5.499905e+001,3.854118e-007,0.000000e+000,3,0.000000e+000,0.000000e+000,,,,,,,,,,,,,,32,1,4.000000e+000,1.319885e-003,0.000000e+000,0,,0,
1524538773.741,,0.000000e+000,5.499511e+001,1.870694e-007,0.000000e+000,3,0.000000e+000,0.000000e+000,,,,,,,,,,,,,,32,1,4.000000e+000,1.184082e-002,0.000000e+000,0,,0,
1524538824.191,,0.000000e+000,5.499709e+001,6.929142e-007,0.000000e+000,3,0.000000e+000,0.000000e+000,,,,,,,,,,,,,,32,1,4.000000e+000,7.888794e-003,0.000000e+000,0,,0,
1524538874.631,,0.000000e+000,5.499839e+001,7.112093e-007,0.000000e+000,3,0.000000e+000,0.000000e+000,,,,,,,,,,,,,,32,1,4.000000e+000,0.000000e+000,0.000000e+000,0,,0,
1524538925.041,,0.000000e+000,5.499905e+001,6.476886e-007,0.000000e+000,3,0.000000e+000,0.000000e+000,,,,,,,,,,,,,,32,1,4.000000e+000,1.319885e-003,0.000000e+000,0,,0,
1524538975.472,,0.000000e+000,5.499511e+001,2.548299e-007,0.000000e+000,3,0.000000e+000,0.000000e+000,,,,,,,,,,,,,,32,1,4.000000e+000,9.201050e-003,0.000000e+000,0,,0,
1524539027.942,,0.000000e+000,5.499117e+001,3.153241e-007,0.000000e+000,2,0.000000e+000,0.000000e+000,,,,,,,,,,,,,,32,1,4.000000e+000,6.568909e-003,0.000000e+000,0,,0,
1524539084.020,,0.000000e+000,5.499182e+001,2.796559e-007,0.000000e+000,2,0.000000e+000,0.000000e+000,,,,,,,,,,,,,,32,1,4.000000e+000,5.260468e-003,0.000000e+000,0,,0,
1524539139.576,,0.000000e+000,5.499906e+001,2.764539e-007,0.000000e+000,2,0.000000e+000,0.000000e+000,,,,,,,,,,,,,,32,1,4.000000e+000,9.220123e-003,0.000000e+000,0,,0,
1524539188.776,,0.000000e+000,5.499577e+001,4.655465e-007,0.000000e+000,3,0.000000e+000,0.000000e+000,,,,,,,,,,,,,,32,1,4.000000e+000,7.888794e-003,0.000000e+000,0,,0,
1524539239.326,,0.000000e+000,5.499182e+001,8.413672e-008,0.000000e+000,3,0.000000e+000,0.000000e+000,,,,,,,,,,,,,,32,1,4.000000e+000,5.260468e-003,0.000000e+000,0,,0,
1524539290.286,,0.000000e+000,5.499773e+001,1.811678e-007,0.000000e+000,3,0.000000e+000,0.000000e+000,,,,,,,,,,,,,,32,1,4.000000e+000,1.308441e-003,0.000000e+000,0,,0,
1524539339.946,,0.000000e+000,5.499643e+001,1.429934e-007,0.000000e+000,3,0.000000e+000,0.000000e+000,,,,,,,,,,,,,,32,1,4.000000e+000,9.208679e-003,0.000000e+000,0,,0,
1524539390.216,,0.000000e+000,5.500168e+001,4.170132e-007,0.000000e+000,3,0.000000e+000,0.000000e+000,,,,,,,,,,,,,,32,1,4.000000e+000,6.580353e-003,0.000000e+000,0,,0,
1524539445.672,,0.000000e+000,5.499511e+001,2.573944e-007,0.000000e+000,2,0.000000e+000,0.000000e+000,,,,,,,,,,,,,,32,1,4.000000e+000,6.568909e-003,0.000000e+000,0,,0,
1524539502.990,,0.000000e+000,5.499841e+001,2.824173e-007,0.000000e+000,2,0.000000e+000,0.000000e+000,,,,,,,,,,,,,,32,1,4.000000e+000,1.052856e-002,0.000000e+000,0,,0,
1524539559.808,,0.000000e+000,5.499906e+001,2.601497e-007,0.000000e+000,2,0.000000e+000,0.000000e+000,,,,,,,,,,,,,,32,1,4.000000e+000,6.580353e-003,0.000000e+000,0,,0,
1524539616.946,,0.000000e+000,5.500234e+001,2.455275e-007,0.000000e+000,2,0.000000e+000,0.000000e+000,,,,,,,,,,,,,,32,1,4.000000e+000,5.260468e-003,0.000000e+000,0,,0,
1524539674.744,,0.000000e+000,5.499512e+001,2.342126e-007,0.000000e+000,2,0.000000e+000,0.000000e+000,,,,,,,,,,,,,,32,1,4.000000e+000,1.446915e-002,0.000000e+000,0,,0,
1524539730.733,,0.000000e+000,5.499182e+001,2.138262e-007,0.000000e+000,2,0.000000e+000,0.000000e+000,,,,,,,,,,,,,,32,1,4.000000e+000,1.052094e-002,0.000000e+000,0,,0,
1524539786.771,,0.000000e+000,5.499971e+001,3.081606e-007,0.000000e+000,2,0.000000e+000,0.000000e+000,,,,,,,,,,,,,,32,1,4.000000e+000,0.000000e+000,0.000000e+000,0,,0,
1524539843.289,,0.000000e+000,5.499380e+001,2.564965e-007,0.000000e+000,2,0.000000e+000,0.000000e+000,,,,,,,,,,,,,,32,1,4.000000e+000,3.948212e-003,0.000000e+000,0,,0,
1524539900.467,,0.000000e+000,5.499905e+001,2.655789e-007,0.000000e+000,2,0.000000e+000,0.000000e+000,,,,,,,,,,,,,,32,1,4.000000e+000,1.319885e-003,0.000000e+000,0,,0,
1524539956.535,,0.000000e+000,5.500037e+001,2.957117e-007,0.000000e+000,2,0.000000e+000,0.000000e+000,,,,,,,,,,,,,,32,1,4.000000e+000,1.319885e-003,0.000000e+000,0,,0,
1524540014.033,,0.000000e+000,5.500168e+001,2.000408e-007,0.000000e+000,2,0.000000e+000,0.000000e+000,,,,,,,,,,,,,,32,1,4.000000e+000,6.580353e-003,0.000000e+000,0,,0,
1524540070.191,,0.000000e+000,5.499775e+001,1.893080e-007,0.000000e+000,2,0.000000e+000,0.000000e+000,,,,,,,,,,,,,,32,1,4.000000e+000,9.208679e-003,0.000000e+000,0,,0,
1524540126.617,,0.000000e+000,5.499577e+001,3.133824e-007,0.000000e+000,2,0.000000e+000,0.000000e+000,,,,,,,,,,,,,,32,1,4.000000e+000,1.052094e-002,0.000000e+000,0,,0,
1524540209.035,,0.000000e+000,5.500037e+001,2.262483e-007,0.000000e+000,2,0.000000e+000,0.000000e+000,,,,,,,,,,,,,,32,1,4.000000e+000,9.201050e-003,0.000000e+000,0,,0,
1524540263.619,,0.000000e+000,5.499839e+001,1.722195e-007,0.000000e+000,2,0.000000e+000,0.000000e+000,,,,,,,,,,,,,,32,1,4.000000e+000,0.000000e+000,0.000000e+000,0,,0,
1524540319.497,,0.000000e+000,5.499971e+001,2.291969e-007,0.000000e+000,2,0.000000e+000,0.000000e+000,,,,,,,,,,,,,,32,1,4.000000e+000,0.000000e+000,0.000000e+000,0,,0,
1524540377.185,,0.000000e+000,5.499445e+001,2.215820e-007,0.000000e+000,2,0.000000e+000,0.000000e+000,,,,,,,,,,,,,,32,1,4.000000e+000,5.260468e-003,0.000000e+000,0,,0,
1524540432.412,,0.000000e+000,5.499774e+001,2.483558e-007,0.000000e+000,2,0.000000e+000,0.000000e+000,,,,,,,,,,,,,,32,1,4.000000e+000,6.580353e-003,0.000000e+000,0,,0,
1524540489.070,,0.000000e+000,5.499313e+001,1.839221e-007,0.000000e+000,2,0.000000e+000,0.000000e+000,,,,,,,,,,,,,,32,1,4.000000e+000,2.628326e-003,0.000000e+000,0,,0,