File: Experimental Raw Data/MFn1 VRM/Linear Regression/MFn1_VRMac_36K_6000s.dc.dat
[Header]
TITLE,MPMS DC Measurement
BYAPP,MPMS Measurement,2.1,Summary
FILEOPENTIME, 1524317037.563000 4/21/2018, 7:23:57 AM

INFO, APPNAME, MPMS MultiVu Application, Revision 1.61,  Build 082

INFO, NAME, MFn1
INFO, WEIGHT, 1.000
INFO, AREA, 1.000
INFO, LENGTH, 1.000
INFO, SHAPE, 0
INFO, COMMENT,
INFO, SEQUENCE FILE: VRMac_36K_6000s_VRMde_35K.seq


INFO, BACKGROUND DATA FILE:, None


STARTUPAXIS,X,4,LINEAR,AUTO,0.000000,0.000000
STARTUPAXIS,Y1,5,LINEAR,AUTO,0.000000,0.000000


STARTUPGROUP,Longitudinal
FIELDGROUP,Longitudinal,1,2,3,4,5,6,7,8,9,15,16,17,18,27,28
FIELDGROUP,Transverse,1,2,3,4,10,11,12,13,14,19,20,21,22,27,28

PLOT_APPEARANCE,ALL,HORZ_GRID_ON,VERT_GRID_ON,MARKERS_AND_LINES

[Data]
Time,Comment,Field (Oe),Temperature (K),Long Moment (emu),Long Scan Std Dev,Long Algorithm,Long Reg Fit,Long Percent Error (%),Trans Moment (emu),Trans Scan Std Dev,Trans Algorithm,Trans Reg Fit,Trans Percent Error (%),Long Moment [w/o ABS] (emu),Long Scan Std Dev [w/o ABS],Long Reg Fit [w/o ABS],Long Percent Error [w/o ABS] (%),Trans Moment [w/o ABS] (emu),Trans Scan Std Dev [w/o ABS],Trans Reg Fit [w/o ABS],Trans Percent Error [w/o ABS] (%),Points per Scan,Scans per Measurement,Scan Length (cm),Delta Temp (K),Rot Position (deg),Error,EC Comp. Running,Using ABS,
1524317037.561,,0.000000e+000,3.599860e+001,-1.770450e-004,0.000000e+000,2,9.349947e-001,0.000000e+000,,,,,,,,,,,,,,32,1,4.000000e+000,4.150391e-003,0.000000e+000,0,,0,
1524317063.501,,0.000000e+000,3.599902e+001,-1.794559e-004,0.000000e+000,2,9.352874e-001,0.000000e+000,,,,,,,,,,,,,,32,1,4.000000e+000,4.970551e-003,0.000000e+000,0,,0,
1524317088.664,,0.000000e+000,3.599984e+001,-1.810426e-004,0.000000e+000,2,9.352711e-001,0.000000e+000,,,,,,,,,,,,,,32,1,4.000000e+000,0.000000e+000,0.000000e+000,0,,0,
1524317113.760,,0.000000e+000,3.599860e+001,-1.823197e-004,0.000000e+000,2,9.352921e-001,0.000000e+000,,,,,,,,,,,,,,32,1,4.000000e+000,8.277893e-004,0.000000e+000,0,,0,
1524317139.005,,0.000000e+000,3.599902e+001,-1.832539e-004,0.000000e+000,2,9.356893e-001,0.000000e+000,,,,,,,,,,,,,,32,1,4.000000e+000,3.318787e-003,0.000000e+000,0,,0,
1524317164.145,,0.000000e+000,3.599819e+001,-1.841153e-004,0.000000e+000,2,9.356602e-001,0.000000e+000,,,,,,,,,,,,,,32,1,4.000000e+000,0.000000e+000,0.000000e+000,0,,0,
1524317189.336,,0.000000e+000,3.599860e+001,-1.848780e-004,0.000000e+000,2,9.359927e-001,0.000000e+000,,,,,,,,,,,,,,32,1,4.000000e+000,8.277893e-004,0.000000e+000,0,,0,
1524317214.464,,0.000000e+000,3.599902e+001,-1.854763e-004,0.000000e+000,2,9.360151e-001,0.000000e+000,,,,,,,,,,,,,,32,1,4.000000e+000,3.318787e-003,0.000000e+000,0,,0,
1524317239.419,,0.000000e+000,3.599819e+001,-1.860487e-004,0.000000e+000,2,9.362494e-001,0.000000e+000,,,,,,,,,,,,,,32,1,4.000000e+000,1.659393e-003,0.000000e+000,0,,0,
1524317264.582,,0.000000e+000,3.599778e+001,-1.865825e-004,0.000000e+000,2,9.363239e-001,0.000000e+000,,,,,,,,,,,,,,32,1,4.000000e+000,8.316040e-004,0.000000e+000,0,,0,
1524317289.760,,0.000000e+000,3.599943e+001,-1.870503e-004,0.000000e+000,2,9.366700e-001,0.000000e+000,,,,,,,,,,,,,,32,1,4.000000e+000,4.138947e-003,0.000000e+000,0,,0,
1524317314.938,,0.000000e+000,3.599736e+001,-1.874969e-004,0.000000e+000,2,9.366734e-001,0.000000e+000,,,,,,,,,,,,,,32,1,4.000000e+000,0.000000e+000,0.000000e+000,0,,0,
1524317340.103,,0.000000e+000,3.599819e+001,-1.879042e-004,0.000000e+000,2,9.371335e-001,0.000000e+000,,,,,,,,,,,,,,32,1,4.000000e+000,0.000000e+000,0.000000e+000,0,,0,
1524317365.171,,0.000000e+000,3.599819e+001,-1.883294e-004,0.000000e+000,2,9.370687e-001,0.000000e+000,,,,,,,,,,,,,,32,1,4.000000e+000,0.000000e+000,0.000000e+000,0,,0,
1524317390.431,,0.000000e+000,3.599819e+001,-1.886344e-004,0.000000e+000,2,9.373519e-001,0.000000e+000,,,,,,,,,,,,,,32,1,4.000000e+000,0.000000e+000,0.000000e+000,0,,0,
1524317415.607,,0.000000e+000,3.599778e+001,-1.889853e-004,0.000000e+000,2,9.373580e-001,0.000000e+000,,,,,,,,,,,,,,32,1,4.000000e+000,8.316040e-004,0.000000e+000,0,,0,
1524317440.787,,0.000000e+000,3.599819e+001,-1.892738e-004,0.000000e+000,2,9.376190e-001,0.000000e+000,,,,,,,,,,,,,,32,1,4.000000e+000,1.659393e-003,0.000000e+000,0,,0,
1524317465.927,,0.000000e+000,3.599819e+001,-1.896833e-004,0.000000e+000,2,9.377980e-001,0.000000e+000,,,,,,,,,,,,,,32,1,4.000000e+000,1.659393e-003,0.000000e+000,0,,0,
1524317491.115,,0.000000e+000,3.599694e+001,-1.899209e-004,0.000000e+000,2,9.378564e-001,0.000000e+000,,,,,,,,,,,,,,32,1,4.000000e+000,8.316040e-004,0.000000e+000,0,,0,
1524317516.281,,0.000000e+000,3.599985e+001,-1.902800e-004,0.000000e+000,2,9.382545e-001,0.000000e+000,,,,,,,,,,,,,,32,1,4.000000e+000,1.659393e-003,0.000000e+000,0,,0,
1524317541.436,,0.000000e+000,3.599778e+001,-1.904746e-004,0.000000e+000,2,9.381910e-001,0.000000e+000,,,,,,,,,,,,,,32,1,4.000000e+000,8.316040e-004,0.000000e+000,0,,0,
1524317566.631,,0.000000e+000,3.600110e+001,-1.907132e-004,0.000000e+000,2,9.380623e-001,0.000000e+000,,,,,,,,,,,,,,32,1,4.000000e+000,5.809784e-003,0.000000e+000,0,,0,
1524317591.792,,0.000000e+000,3.599736e+001,-1.909567e-004,0.000000e+000,2,9.383364e-001,0.000000e+000,,,,,,,,,,,,,,32,1,4.000000e+000,0.000000e+000,0.000000e+000,0,,0,
1524317616.980,,0.000000e+000,3.599819e+001,-1.912320e-004,0.000000e+000,2,9.385309e-001,0.000000e+000,,,,,,,,,,,,,,32,1,4.000000e+000,0.000000e+000,0.000000e+000,0,,0,
1524317642.092,,0.000000e+000,3.599819e+001,-1.914350e-004,0.000000e+000,2,9.385579e-001,0.000000e+000,,,,,,,,,,,,,,32,1,4.000000e+000,0.000000e+000,0.000000e+000,0,,0,
1524317667.290,,0.000000e+000,3.599778e+001,-1.916008e-004,0.000000e+000,2,9.386273e-001,0.000000e+000,,,,,,,,,,,,,,32,1,4.000000e+000,8.316040e-004,0.000000e+000,0,,0,
1524317692.496,,0.000000e+000,3.599819e+001,-1.918524e-004,0.000000e+000,2,9.385895e-001,0.000000e+000,,,,,,,,,,,,,,32,1,4.000000e+000,0.000000e+000,0.000000e+000,0,,0,
1524317717.608,,0.000000e+000,3.599778e+001,-1.921551e-004,0.000000e+000,2,9.387530e-001,0.000000e+000,,,,,,,,,,,,,,32,1,4.000000e+000,8.316040e-004,0.000000e+000,0,,0,
1524317742.811,,0.000000e+000,3.599819e+001,-1.922272e-004,0.000000e+000,2,9.388877e-001,0.000000e+000,,,,,,,,,,,,,,32,1,4.000000e+000,1.659393e-003,0.000000e+000,0,,0,
1524317767.959,,0.000000e+000,3.599819e+001,-1.925094e-004,0.000000e+000,2,9.390840e-001,0.000000e+000,,,,,,,,,,,,,,32,1,4.000000e+000,0.000000e+000,0.000000e+000,0,,0,
1524317793.155,,0.000000e+000,3.599860e+001,-1.926313e-004,0.000000e+000,2,9.391525e-001,0.000000e+000,,,,,,,,,,,,,,32,1,4.000000e+000,2.479553e-003,0.000000e+000,0,,0,
1524317818.805,,0.000000e+000,3.599736e+001,-1.927633e-004,0.000000e+000,2,9.393520e-001,0.000000e+000,,,,,,,,,,,,,,32,1,4.000000e+000,0.000000e+000,0.000000e+000,0,,0,
1524317844.465,,0.000000e+000,3.599694e+001,-1.929952e-004,0.000000e+000,2,9.393161e-001,0.000000e+000,,,,,,,,,,,,,,32,1,4.000000e+000,8.316040e-004,0.000000e+000,0,,0,
1524317869.581,,0.000000e+000,3.599695e+001,-1.932076e-004,0.000000e+000,2,9.392819e-001,0.000000e+000,,,,,,,,,,,,,,32,1,4.000000e+000,2.490997e-003,0.000000e+000,0,,0,
1524317894.789,,0.000000e+000,3.599860e+001,-1.933246e-004,0.000000e+000,2,9.393820e-001,0.000000e+000,,,,,,,,,,,,,,32,1,4.000000e+000,2.479553e-003,0.000000e+000,0,,0,
1524317919.627,,0.000000e+000,3.599985e+001,-1.935302e-004,0.000000e+000,2,9.397596e-001,0.000000e+000,,,,,,,,,,,,,,32,1,4.000000e+000,1.659393e-003,0.000000e+000,0,,0,
1524317945.127,,0.000000e+000,3.599944e+001,-1.936719e-004,0.000000e+000,2,9.397441e-001,0.000000e+000,,,,,,,,,,,,,,32,1,4.000000e+000,2.487183e-003,0.000000e+000,0,,0,
1524317969.795,,0.000000e+000,3.599902e+001,-1.937432e-004,0.000000e+000,2,9.397275e-001,0.000000e+000,,,,,,,,,,,,,,32,1,4.000000e+000,3.318787e-003,0.000000e+000,0,,0,
1524317995.445,,0.000000e+000,3.599902e+001,-1.939399e-004,0.000000e+000,2,9.401280e-001,0.000000e+000,,,,,,,,,,,,,,32,1,4.000000e+000,1.647949e-003,0.000000e+000,0,,0,
1524318020.611,,0.000000e+000,3.599943e+001,-1.941149e-004,0.000000e+000,2,9.403887e-001,0.000000e+000,,,,,,,,,,,,,,32,1,4.000000e+000,8.201599e-004,0.000000e+000,0,,0,
1524318045.803,,0.000000e+000,3.599943e+001,-1.942610e-004,0.000000e+000,2,9.403400e-001,0.000000e+000,,,,,,,,,,,,,,32,1,4.000000e+000,8.201599e-004,0.000000e+000,0,,0,
1524318070.944,,0.000000e+000,3.599860e+001,-1.943683e-004,0.000000e+000,2,9.402370e-001,0.000000e+000,,,,,,,,,,,,,,32,1,4.000000e+000,2.479553e-003,0.000000e+000,0,,0,
1524318096.122,,0.000000e+000,3.599943e+001,-1.945411e-004,0.000000e+000,2,9.405679e-001,0.000000e+000,,,,,,,,,,,,,,32,1,4.000000e+000,8.201599e-004,0.000000e+000,0,,0,
1524318121.237,,0.000000e+000,3.599819e+001,-1.946393e-004,0.000000e+000,2,9.405628e-001,0.000000e+000,,,,,,,,,,,,,,32,1,4.000000e+000,1.659393e-003,0.000000e+000,0,,0,
1524318146.092,,0.000000e+000,3.599818e+001,-1.947788e-004,0.000000e+000,2,9.408612e-001,0.000000e+000,,,,,,,,,,,,,,32,1,4.000000e+000,3.311157e-003,0.000000e+000,0,,0,
1524318171.593,,0.000000e+000,3.599778e+001,-1.949187e-004,0.000000e+000,2,9.408502e-001,0.000000e+000,,,,,,,,,,,,,,32,1,4.000000e+000,8.316040e-004,0.000000e+000,0,,0,
1524318196.776,,0.000000e+000,3.599944e+001,-1.950307e-004,0.000000e+000,2,9.410397e-001,0.000000e+000,,,,,,,,,,,,,,32,1,4.000000e+000,2.487183e-003,0.000000e+000,0,,0,
1524318221.938,,0.000000e+000,3.599819e+001,-1.951580e-004,0.000000e+000,2,9.411072e-001,0.000000e+000,,,,,,,,,,,,,,32,1,4.000000e+000,1.659393e-003,0.000000e+000,0,,0,
1524318247.064,,0.000000e+000,3.599902e+001,-1.952523e-004,0.000000e+000,2,9.414573e-001,0.000000e+000,,,,,,,,,,,,,,32,1,4.000000e+000,0.000000e+000,0.000000e+000,0,,0,
1524318271.767,,0.000000e+000,3.599943e+001,-1.953589e-004,0.000000e+000,2,9.412272e-001,0.000000e+000,,,,,,,,,,,,,,32,1,4.000000e+000,8.201599e-004,0.000000e+000,0,,0,
1524318296.527,,0.000000e+000,3.599860e+001,-1.956286e-004,0.000000e+000,2,9.417042e-001,0.000000e+000,,,,,,,,,,,,,,32,1,4.000000e+000,8.277893e-004,0.000000e+000,0,,0,
1524318321.425,,0.000000e+000,3.599736e+001,-1.956637e-004,0.000000e+000,2,9.415341e-001,0.000000e+000,,,,,,,,,,,,,,32,1,4.000000e+000,1.663208e-003,0.000000e+000,0,,0,
1524318346.765,,0.000000e+000,3.599860e+001,-1.957240e-004,0.000000e+000,2,9.421496e-001,0.000000e+000,,,,,,,,,,,,,,32,1,4.000000e+000,8.277893e-004,0.000000e+000,0,,0,
1524318371.886,,0.000000e+000,3.599778e+001,-1.957891e-004,0.000000e+000,2,9.420948e-001,0.000000e+000,,,,,,,,,,,,,,32,1,4.000000e+000,8.316040e-004,0.000000e+000,0,,0,
1524318397.081,,0.000000e+000,3.599860e+001,-1.960241e-004,0.000000e+000,2,9.421439e-001,0.000000e+000,,,,,,,,,,,,,,32,1,4.000000e+000,8.277893e-004,0.000000e+000,0,,0,
1524318422.224,,0.000000e+000,3.599819e+001,-1.960126e-004,0.000000e+000,2,9.424050e-001,0.000000e+000,,,,,,,,,,,,,,32,1,4.000000e+000,0.000000e+000,0.000000e+000,0,,0,
1524318447.404,,0.000000e+000,3.599778e+001,-1.960554e-004,0.000000e+000,2,9.424530e-001,0.000000e+000,,,,,,,,,,,,,,32,1,4.000000e+000,8.316040e-004,0.000000e+000,0,,0,
1524318472.565,,0.000000e+000,3.599860e+001,-1.962224e-004,0.000000e+000,2,9.426029e-001,0.000000e+000,,,,,,,,,,,,,,32,1,4.000000e+000,8.277893e-004,0.000000e+000,0,,0,
1524318497.785,,0.000000e+000,3.599819e+001,-1.963411e-004,0.000000e+000,2,9.427516e-001,0.000000e+000,,,,,,,,,,,,,,32,1,4.000000e+000,0.000000e+000,0.000000e+000,0,,0,
1524318522.948,,0.000000e+000,3.599819e+001,-1.964986e-004,0.000000e+000,2,9.426050e-001,0.000000e+000,,,,,,,,,,,,,,32,1,4.000000e+000,0.000000e+000,0.000000e+000,0,,0,
1524318548.091,,0.000000e+000,3.599778e+001,-1.965054e-004,0.000000e+000,2,9.433801e-001,0.000000e+000,,,,,,,,,,,,,,32,1,4.000000e+000,8.316040e-004,0.000000e+000,0,,0,
1524318573.281,,0.000000e+000,3.599778e+001,-1.966480e-004,0.000000e+000,2,9.433956e-001,0.000000e+000,,,,,,,,,,,,,,32,1,4.000000e+000,8.316040e-004,0.000000e+000,0,,0,
1524318598.476,,0.000000e+000,3.599778e+001,-1.967676e-004,0.000000e+000,2,9.433376e-001,0.000000e+000,,,,,,,,,,,,,,32,1,4.000000e+000,8.316040e-004,0.000000e+000,0,,0,
1524318623.634,,0.000000e+000,3.599860e+001,-1.968466e-004,0.000000e+000,2,9.433162e-001,0.000000e+000,,,,,,,,,,,,,,32,1,4.000000e+000,8.277893e-004,0.000000e+000,0,,0,
1524318648.810,,0.000000e+000,3.599819e+001,-1.968702e-004,0.000000e+000,2,9.435424e-001,0.000000e+000,,,,,,,,,,,,,,32,1,4.000000e+000,0.000000e+000,0.000000e+000,0,,0,
1524318673.958,,0.000000e+000,3.599860e+001,-1.969306e-004,0.000000e+000,2,9.437655e-001,0.000000e+000,,,,,,,,,,,,,,32,1,4.000000e+000,8.277893e-004,0.000000e+000,0,,0,
1524318699.145,,0.000000e+000,3.599778e+001,-1.971297e-004,0.000000e+000,2,9.436354e-001,0.000000e+000,,,,,,,,,,,,,,32,1,4.000000e+000,8.316040e-004,0.000000e+000,0,,0,
1524318724.293,,0.000000e+000,3.599777e+001,-1.971727e-004,0.000000e+000,2,9.439597e-001,0.000000e+000,,,,,,,,,,,,,,32,1,4.000000e+000,2.490997e-003,0.000000e+000,0,,0,
1524318749.481,,0.000000e+000,3.599819e+001,-1.972386e-004,0.000000e+000,2,9.439489e-001,0.000000e+000,,,,,,,,,,,,,,32,1,4.000000e+000,0.000000e+000,0.000000e+000,0,,0,
1524318774.624,,0.000000e+000,3.599860e+001,-1.974053e-004,0.000000e+000,2,9.436475e-001,0.000000e+000,,,,,,,,,,,,,,32,1,4.000000e+000,8.277893e-004,0.000000e+000,0,,0,
1524318799.819,,0.000000e+000,3.599819e+001,-1.974138e-004,0.000000e+000,2,9.440729e-001,0.000000e+000,,,,,,,,,,,,,,32,1,4.000000e+000,1.659393e-003,0.000000e+000,0,,0,
1524318824.745,,0.000000e+000,3.599819e+001,-1.975931e-004,0.000000e+000,2,9.443164e-001,0.000000e+000,,,,,,,,,,,,,,32,1,4.000000e+000,0.000000e+000,0.000000e+000,0,,0,
1524318849.913,,0.000000e+000,3.599943e+001,-1.976819e-004,0.000000e+000,2,9.443261e-001,0.000000e+000,,,,,,,,,,,,,,32,1,4.000000e+000,8.201599e-004,0.000000e+000,0,,0,
1524318875.115,,0.000000e+000,3.599819e+001,-1.977146e-004,0.000000e+000,2,9.441700e-001,0.000000e+000,,,,,,,,,,,,,,32,1,4.000000e+000,0.000000e+000,0.000000e+000,0,,0,
1524318900.283,,0.000000e+000,3.599902e+001,-1.978896e-004,0.000000e+000,2,9.442070e-001,0.000000e+000,,,,,,,,,,,,,,32,1,4.000000e+000,0.000000e+000,0.000000e+000,0,,0,
1524318925.359,,0.000000e+000,3.599902e+001,-1.977324e-004,0.000000e+000,2,9.447475e-001,0.000000e+000,,,,,,,,,,,,,,32,1,4.000000e+000,0.000000e+000,0.000000e+000,0,,0,
1524318950.634,,0.000000e+000,3.599819e+001,-1.979773e-004,0.000000e+000,2,9.448794e-001,0.000000e+000,,,,,,,,,,,,,,32,1,4.000000e+000,0.000000e+000,0.000000e+000,0,,0,
1524318975.804,,0.000000e+000,3.599819e+001,-1.980062e-004,0.000000e+000,2,9.447514e-001,0.000000e+000,,,,,,,,,,,,,,32,1,4.000000e+000,1.659393e-003,0.000000e+000,0,,0,
1524319000.992,,0.000000e+000,3.599819e+001,-1.981945e-004,0.000000e+000,2,9.455542e-001,0.000000e+000,,,,,,,,,,,,,,32,1,4.000000e+000,0.000000e+000,0.000000e+000,0,,0,
1524319026.155,,0.000000e+000,3.599860e+001,-1.982486e-004,0.000000e+000,2,9.449388e-001,0.000000e+000,,,,,,,,,,,,,,32,1,4.000000e+000,8.277893e-004,0.000000e+000,0,,0,
1524319051.336,,0.000000e+000,3.599819e+001,-1.982641e-004,0.000000e+000,2,9.453354e-001,0.000000e+000,,,,,,,,,,,,,,32,1,4.000000e+000,0.000000e+000,0.000000e+000,0,,0,
1524319076.513,,0.000000e+000,3.599860e+001,-1.983641e-004,0.000000e+000,2,9.451849e-001,0.000000e+000,,,,,,,,,,,,,,32,1,4.000000e+000,8.277893e-004,0.000000e+000,0,,0,
1524319101.689,,0.000000e+000,3.599860e+001,-1.984256e-004,0.000000e+000,2,9.454119e-001,0.000000e+000,,,,,,,,,,,,,,32,1,4.000000e+000,8.277893e-004,0.000000e+000,0,,0,
1524319127.169,,0.000000e+000,3.599902e+001,-1.984955e-004,0.000000e+000,2,9.457149e-001,0.000000e+000,,,,,,,,,,,,,,32,1,4.000000e+000,0.000000e+000,0.000000e+000,0,,0,
1524319152.505,,0.000000e+000,3.599694e+001,-1.985668e-004,0.000000e+000,2,9.462372e-001,0.000000e+000,,,,,,,,,,,,,,32,1,4.000000e+000,8.316040e-004,0.000000e+000,0,,0,
1524319177.727,,0.000000e+000,3.599902e+001,-1.987084e-004,0.000000e+000,2,9.462348e-001,0.000000e+000,,,,,,,,,,,,,,32,1,4.000000e+000,1.647949e-003,0.000000e+000,0,,0,
1524319202.868,,0.000000e+000,3.599944e+001,-1.987412e-004,0.000000e+000,2,9.463495e-001,0.000000e+000,,,,,,,,,,,,,,32,1,4.000000e+000,2.487183e-003,0.000000e+000,0,,0,
1524319228.031,,0.000000e+000,3.599736e+001,-1.987317e-004,0.000000e+000,2,9.463833e-001,0.000000e+000,,,,,,,,,,,,,,32,1,4.000000e+000,1.663208e-003,0.000000e+000,0,,0,
1524319253.274,,0.000000e+000,3.599902e+001,-1.988806e-004,0.000000e+000,2,9.466448e-001,0.000000e+000,,,,,,,,,,,,,,32,1,4.000000e+000,0.000000e+000,0.000000e+000,0,,0,
1524319278.431,,0.000000e+000,3.600026e+001,-1.988851e-004,0.000000e+000,2,9.468326e-001,0.000000e+000,,,,,,,,,,,,,,32,1,4.000000e+000,2.479553e-003,0.000000e+000,0,,0,
1524319303.574,,0.000000e+000,3.599818e+001,-1.989585e-004,0.000000e+000,2,9.468222e-001,0.000000e+000,,,,,,,,,,,,,,32,1,4.000000e+000,3.311157e-003,0.000000e+000,0,,0,
1524319329.015,,0.000000e+000,3.599860e+001,-1.990481e-004,0.000000e+000,2,9.470416e-001,0.000000e+000,,,,,,,,,,,,,,32,1,4.000000e+000,8.277893e-004,0.000000e+000,0,,0,
1524319354.218,,0.000000e+000,3.599653e+001,-1.991061e-004,0.000000e+000,2,9.470601e-001,0.000000e+000,,,,,,,,,,,,,,32,1,4.000000e+000,0.000000e+000,0.000000e+000,0,,0,
1524319379.388,,0.000000e+000,3.599860e+001,-1.992299e-004,0.000000e+000,2,9.471602e-001,0.000000e+000,,,,,,,,,,,,,,32,1,4.000000e+000,8.277893e-004,0.000000e+000,0,,0,
1524319404.563,,0.000000e+000,3.599985e+001,-1.992384e-004,0.000000e+000,2,9.473864e-001,0.000000e+000,,,,,,,,,,,,,,32,1,4.000000e+000,1.659393e-003,0.000000e+000,0,,0,
1524319429.074,,0.000000e+000,3.599778e+001,-1.993147e-004,0.000000e+000,2,9.473681e-001,0.000000e+000,,,,,,,,,,,,,,32,1,4.000000e+000,8.316040e-004,0.000000e+000,0,,0,
1524319454.127,,0.000000e+000,3.599778e+001,-1.993592e-004,0.000000e+000,2,9.476706e-001,0.000000e+000,,,,,,,,,,,,,,32,1,4.000000e+000,8.316040e-004,0.000000e+000,0,,0,
1524319479.179,,0.000000e+000,3.599943e+001,-1.994191e-004,0.000000e+000,2,9.476056e-001,0.000000e+000,,,,,,,,,,,,,,32,1,4.000000e+000,8.201599e-004,0.000000e+000,0,,0,
1524319504.345,,0.000000e+000,3.599777e+001,-1.994943e-004,0.000000e+000,2,9.479493e-001,0.000000e+000,,,,,,,,,,,,,,32,1,4.000000e+000,2.490997e-003,0.000000e+000,0,,0,
1524319529.620,,0.000000e+000,3.599902e+001,-1.995516e-004,0.000000e+000,2,9.480935e-001,0.000000e+000,,,,,,,,,,,,,,32,1,4.000000e+000,0.000000e+000,0.000000e+000,0,,0,
1524319554.810,,0.000000e+000,3.599902e+001,-1.996130e-004,0.000000e+000,2,9.481394e-001,0.000000e+000,,,,,,,,,,,,,,32,1,4.000000e+000,1.647949e-003,0.000000e+000,0,,0,
1524319580.018,,0.000000e+000,3.599943e+001,-1.996900e-004,0.000000e+000,2,9.482943e-001,0.000000e+000,,,,,,,,,,,,,,32,1,4.000000e+000,8.201599e-004,0.000000e+000,0,,0,
1524319605.654,,0.000000e+000,3.599944e+001,-1.997235e-004,0.000000e+000,2,9.485896e-001,0.000000e+000,,,,,,,,,,,,,,32,1,4.000000e+000,2.487183e-003,0.000000e+000,0,,0,
1524319630.929,,0.000000e+000,3.599695e+001,-1.997829e-004,0.000000e+000,2,9.487348e-001,0.000000e+000,,,,,,,,,,,,,,32,1,4.000000e+000,2.490997e-003,0.000000e+000,0,,0,
1524319656.742,,0.000000e+000,3.599694e+001,-1.998421e-004,0.000000e+000,2,9.487775e-001,0.000000e+000,,,,,,,,,,,,,,32,1,4.000000e+000,8.316040e-004,0.000000e+000,0,,0,
1524319681.957,,0.000000e+000,3.599819e+001,-1.998732e-004,0.000000e+000,2,9.486300e-001,0.000000e+000,,,,,,,,,,,,,,32,1,4.000000e+000,0.000000e+000,0.000000e+000,0,,0,
1524319707.065,,0.000000e+000,3.599777e+001,-1.999458e-004,0.000000e+000,2,9.488390e-001,0.000000e+000,,,,,,,,,,,,,,32,1,4.000000e+000,2.490997e-003,0.000000e+000,0,,0,
1524319732.276,,0.000000e+000,3.599943e+001,-2.000199e-004,0.000000e+000,2,9.490276e-001,0.000000e+000,,,,,,,,,,,,,,32,1,4.000000e+000,8.201599e-004,0.000000e+000,0,,0,
1524319757.441,,0.000000e+000,3.599860e+001,-2.000650e-004,0.000000e+000,2,9.491874e-001,0.000000e+000,,,,,,,,,,,,,,32,1,4.000000e+000,2.479553e-003,0.000000e+000,0,,0,
1524319782.596,,0.000000e+000,3.599902e+001,-2.001469e-004,0.000000e+000,2,9.492379e-001,0.000000e+000,,,,,,,,,,,,,,32,1,4.000000e+000,1.647949e-003,0.000000e+000,0,,0,
1524319807.789,,0.000000e+000,3.599860e+001,-2.001849e-004,0.000000e+000,2,9.493315e-001,0.000000e+000,,,,,,,,,,,,,,32,1,4.000000e+000,8.277893e-004,0.000000e+000,0,,0,
1524319832.965,,0.000000e+000,3.599943e+001,-2.002353e-004,0.000000e+000,2,9.496262e-001,0.000000e+000,,,,,,,,,,,,,,32,1,4.000000e+000,8.201599e-004,0.000000e+000,0,,0,
1524319858.107,,0.000000e+000,3.599984e+001,-2.002718e-004,0.000000e+000,2,9.495474e-001,0.000000e+000,,,,,,,,,,,,,,32,1,4.000000e+000,0.000000e+000,0.000000e+000,0,,0,
1524319883.300,,0.000000e+000,3.599985e+001,-2.003434e-004,0.000000e+000,2,9.496972e-001,0.000000e+000,,,,,,,,,,,,,,32,1,4.000000e+000,1.659393e-003,0.000000e+000,0,,0,
1524319908.441,,0.000000e+000,3.599944e+001,-2.004141e-004,0.000000e+000,2,9.499580e-001,0.000000e+000,,,,,,,,,,,,,,32,1,4.000000e+000,2.487183e-003,0.000000e+000,0,,0,
1524319933.644,,0.000000e+000,3.599902e+001,-2.004552e-004,0.000000e+000,2,9.499545e-001,0.000000e+000,,,,,,,,,,,,,,32,1,4.000000e+000,1.647949e-003,0.000000e+000,0,,0,
1524319958.821,,0.000000e+000,3.599985e+001,-2.005174e-004,0.000000e+000,2,9.500257e-001,0.000000e+000,,,,,,,,,,,,,,32,1,4.000000e+000,1.659393e-003,0.000000e+000,0,,0,
1524319983.987,,0.000000e+000,3.599819e+001,-2.005694e-004,0.000000e+000,2,9.500636e-001,0.000000e+000,,,,,,,,,,,,,,32,1,4.000000e+000,0.000000e+000,0.000000e+000,0,,0,
1524320009.132,,0.000000e+000,3.599819e+001,-2.006346e-004,0.000000e+000,2,9.504009e-001,0.000000e+000,,,,,,,,,,,,,,32,1,4.000000e+000,1.659393e-003,0.000000e+000,0,,0,
1524320034.323,,0.000000e+000,3.599736e+001,-2.006494e-004,0.000000e+000,2,9.504012e-001,0.000000e+000,,,,,,,,,,,,,,32,1,4.000000e+000,0.000000e+000,0.000000e+000,0,,0,
1524320059.500,,0.000000e+000,3.599984e+001,-2.007009e-004,0.000000e+000,2,9.505516e-001,0.000000e+000,,,,,,,,,,,,,,32,1,4.000000e+000,0.000000e+000,0.000000e+000,0,,0,
1524320084.736,,0.000000e+000,3.599653e+001,-2.007681e-004,0.000000e+000,2,9.507585e-001,0.000000e+000,,,,,,,,,,,,,,32,1,4.000000e+000,1.659393e-003,0.000000e+000,0,,0,
1524320109.869,,0.000000e+000,3.599695e+001,-2.008386e-004,0.000000e+000,2,9.507641e-001,0.000000e+000,,,,,,,,,,,,,,32,1,4.000000e+000,2.490997e-003,0.000000e+000,0,,0,
1524320135.017,,0.000000e+000,3.599902e+001,-2.008975e-004,0.000000e+000,2,9.508986e-001,0.000000e+000,,,,,,,,,,,,,,32,1,4.000000e+000,0.000000e+000,0.000000e+000,0,,0,
1524320160.199,,0.000000e+000,3.599902e+001,-2.009397e-004,0.000000e+000,2,9.509989e-001,0.000000e+000,,,,,,,,,,,,,,32,1,4.000000e+000,1.647949e-003,0.000000e+000,0,,0,
1524320185.365,,0.000000e+000,3.599902e+001,-2.009818e-004,0.000000e+000,2,9.509557e-001,0.000000e+000,,,,,,,,,,,,,,32,1,4.000000e+000,0.000000e+000,0.000000e+000,0,,0,
1524320210.530,,0.000000e+000,3.599860e+001,-2.010217e-004,0.000000e+000,2,9.513280e-001,0.000000e+000,,,,,,,,,,,,,,32,1,4.000000e+000,8.277893e-004,0.000000e+000,0,,0,
1524320235.728,,0.000000e+000,3.599860e+001,-2.010460e-004,0.000000e+000,2,9.515702e-001,0.000000e+000,,,,,,,,,,,,,,32,1,4.000000e+000,2.479553e-003,0.000000e+000,0,,0,
1524320260.908,,0.000000e+000,3.599777e+001,-2.011019e-004,0.000000e+000,2,9.515373e-001,0.000000e+000,,,,,,,,,,,,,,32,1,4.000000e+000,2.490997e-003,0.000000e+000,0,,0,
1524320286.059,,0.000000e+000,3.600026e+001,-2.011430e-004,0.000000e+000,2,9.515638e-001,0.000000e+000,,,,,,,,,,,,,,32,1,4.000000e+000,8.392334e-004,0.000000e+000,0,,0,
1524320311.244,,0.000000e+000,3.599819e+001,-2.012218e-004,0.000000e+000,2,9.516675e-001,0.000000e+000,,,,,,,,,,,,,,32,1,4.000000e+000,1.659393e-003,0.000000e+000,0,,0,
1524320336.427,,0.000000e+000,3.599902e+001,-2.012869e-004,0.000000e+000,2,9.518093e-001,0.000000e+000,,,,,,,,,,,,,,32,1,4.000000e+000,1.647949e-003,0.000000e+000,0,,0,
1524320361.525,,0.000000e+000,3.599818e+001,-2.013244e-004,0.000000e+000,2,9.519188e-001,0.000000e+000,,,,,,,,,,,,,,32,1,4.000000e+000,3.311157e-003,0.000000e+000,0,,0,
1524320386.773,,0.000000e+000,3.600067e+001,-2.013596e-004,0.000000e+000,2,9.520202e-001,0.000000e+000,,,,,,,,,,,,,,32,1,4.000000e+000,1.659393e-003,0.000000e+000,0,,0,
1524320411.940,,0.000000e+000,3.599778e+001,-2.014193e-004,0.000000e+000,2,9.522281e-001,0.000000e+000,,,,,,,,,,,,,,32,1,4.000000e+000,8.316040e-004,0.000000e+000,0,,0,
1524320437.098,,0.000000e+000,3.599902e+001,-2.014619e-004,0.000000e+000,2,9.522985e-001,0.000000e+000,,,,,,,,,,,,,,32,1,4.000000e+000,3.318787e-003,0.000000e+000,0,,0,
1524320462.251,,0.000000e+000,3.599985e+001,-2.015410e-004,0.000000e+000,2,9.525520e-001,0.000000e+000,,,,,,,,,,,,,,32,1,4.000000e+000,1.659393e-003,0.000000e+000,0,,0,
1524320487.464,,0.000000e+000,3.599819e+001,-2.015268e-004,0.000000e+000,2,9.525706e-001,0.000000e+000,,,,,,,,,,,,,,32,1,4.000000e+000,1.659393e-003,0.000000e+000,0,,0,
1524320512.635,,0.000000e+000,3.599985e+001,-2.016113e-004,0.000000e+000,2,9.526360e-001,0.000000e+000,,,,,,,,,,,,,,32,1,4.000000e+000,1.659393e-003,0.000000e+000,0,,0,
1524320537.815,,0.000000e+000,3.599902e+001,-2.016487e-004,0.000000e+000,2,9.527830e-001,0.000000e+000,,,,,,,,,,,,,,32,1,4.000000e+000,1.647949e-003,0.000000e+000,0,,0,
1524320563.008,,0.000000e+000,3.599736e+001,-2.016799e-004,0.000000e+000,2,9.528720e-001,0.000000e+000,,,,,,,,,,,,,,32,1,4.000000e+000,1.663208e-003,0.000000e+000,0,,0,
1524320588.191,,0.000000e+000,3.599860e+001,-2.017317e-004,0.000000e+000,2,9.530395e-001,0.000000e+000,,,,,,,,,,,,,,32,1,4.000000e+000,8.277893e-004,0.000000e+000,0,,0,
1524320613.329,,0.000000e+000,3.599778e+001,-2.017761e-004,0.000000e+000,2,9.530007e-001,0.000000e+000,,,,,,,,,,,,,,32,1,4.000000e+000,8.316040e-004,0.000000e+000,0,,0,
1524320638.501,,0.000000e+000,3.599778e+001,-2.018240e-004,0.000000e+000,2,9.532315e-001,0.000000e+000,,,,,,,,,,,,,,32,1,4.000000e+000,8.316040e-004,0.000000e+000,0,,0,
1524320663.679,,0.000000e+000,3.599860e+001,-2.018456e-004,0.000000e+000,2,9.534550e-001,0.000000e+000,,,,,,,,,,,,,,32,1,4.000000e+000,8.277893e-004,0.000000e+000,0,,0,
1524320688.870,,0.000000e+000,3.599819e+001,-2.019009e-004,0.000000e+000,2,9.533324e-001,0.000000e+000,,,,,,,,,,,,,,32,1,4.000000e+000,1.659393e-003,0.000000e+000,0,,0,
1524320714.063,,0.000000e+000,3.599985e+001,-2.019667e-004,0.000000e+000,2,9.535444e-001,0.000000e+000,,,,,,,,,,,,,,32,1,4.000000e+000,3.307343e-003,0.000000e+000,0,,0,
1524320739.193,,0.000000e+000,3.599694e+001,-2.019687e-004,0.000000e+000,2,9.535497e-001,0.000000e+000,,,,,,,,,,,,,,32,1,4.000000e+000,8.316040e-004,0.000000e+000,0,,0,
1524320764.386,,0.000000e+000,3.599818e+001,-2.020278e-004,0.000000e+000,2,9.536784e-001,0.000000e+000,,,,,,,,,,,,,,32,1,4.000000e+000,3.311157e-003,0.000000e+000,0,,0,
1524320789.574,,0.000000e+000,3.599902e+001,-2.020797e-004,0.000000e+000,2,9.537958e-001,0.000000e+000,,,,,,,,,,,,,,32,1,4.000000e+000,1.647949e-003,0.000000e+000,0,,0,
1524320814.737,,0.000000e+000,3.599860e+001,-2.021149e-004,0.000000e+000,2,9.539939e-001,0.000000e+000,,,,,,,,,,,,,,32,1,4.000000e+000,4.150391e-003,0.000000e+000,0,,0,
1524320839.922,,0.000000e+000,3.599736e+001,-2.021358e-004,0.000000e+000,2,9.541001e-001,0.000000e+000,,,,,,,,,,,,,,32,1,4.000000e+000,3.318787e-003,0.000000e+000,0,,0,
1524320865.072,,0.000000e+000,3.599778e+001,-2.022135e-004,0.000000e+000,2,9.541633e-001,0.000000e+000,,,,,,,,,,,,,,32,1,4.000000e+000,8.316040e-004,0.000000e+000,0,,0,
1524320890.263,,0.000000e+000,3.599943e+001,-2.022320e-004,0.000000e+000,2,9.542078e-001,0.000000e+000,,,,,,,,,,,,,,32,1,4.000000e+000,8.201599e-004,0.000000e+000,0,,0,
1524320915.425,,0.000000e+000,3.599985e+001,-2.022747e-004,0.000000e+000,2,9.542829e-001,0.000000e+000,,,,,,,,,,,,,,32,1,4.000000e+000,3.307343e-003,0.000000e+000,0,,0,
1524320940.593,,0.000000e+000,3.599985e+001,-2.023178e-004,0.000000e+000,2,9.544835e-001,0.000000e+000,,,,,,,,,,,,,,32,1,4.000000e+000,3.307343e-003,0.000000e+000,0,,0,
1524320965.726,,0.000000e+000,3.599778e+001,-2.023835e-004,0.000000e+000,2,9.546586e-001,0.000000e+000,,,,,,,,,,,,,,32,1,4.000000e+000,8.316040e-004,0.000000e+000,0,,0,
1524320990.964,,0.000000e+000,3.599943e+001,-2.024323e-004,0.000000e+000,2,9.546516e-001,0.000000e+000,,,,,,,,,,,,,,32,1,4.000000e+000,4.138947e-003,0.000000e+000,0,,0,
1524321016.134,,0.000000e+000,3.599860e+001,-2.024383e-004,0.000000e+000,2,9.548022e-001,0.000000e+000,,,,,,,,,,,,,,32,1,4.000000e+000,8.277893e-004,0.000000e+000,0,,0,
1524321041.320,,0.000000e+000,3.599902e+001,-2.024869e-004,0.000000e+000,2,9.549111e-001,0.000000e+000,,,,,,,,,,,,,,32,1,4.000000e+000,1.647949e-003,0.000000e+000,0,,0,
1524321066.493,,0.000000e+000,3.599985e+001,-2.024894e-004,0.000000e+000,2,9.551980e-001,0.000000e+000,,,,,,,,,,,,,,32,1,4.000000e+000,1.659393e-003,0.000000e+000,0,,0,
1524321091.653,,0.000000e+000,3.599694e+001,-2.025408e-004,0.000000e+000,2,9.551762e-001,0.000000e+000,,,,,,,,,,,,,,32,1,4.000000e+000,8.316040e-004,0.000000e+000,0,,0,
1524321116.816,,0.000000e+000,3.599860e+001,-2.025608e-004,0.000000e+000,2,9.553632e-001,0.000000e+000,,,,,,,,,,,,,,32,1,4.000000e+000,2.479553e-003,0.000000e+000,0,,0,
1524321142.009,,0.000000e+000,3.600026e+001,-2.026322e-004,0.000000e+000,2,9.554743e-001,0.000000e+000,,,,,,,,,,,,,,32,1,4.000000e+000,8.392334e-004,0.000000e+000,0,,0,
1524321167.167,,0.000000e+000,3.599985e+001,-2.026563e-004,0.000000e+000,2,9.554881e-001,0.000000e+000,,,,,,,,,,,,,,32,1,4.000000e+000,3.307343e-003,0.000000e+000,0,,0,
1524321192.340,,0.000000e+000,3.599860e+001,-2.027112e-004,0.000000e+000,2,9.556348e-001,0.000000e+000,,,,,,,,,,,,,,32,1,4.000000e+000,8.277893e-004,0.000000e+000,0,,0,
1524321217.502,,0.000000e+000,3.599819e+001,-2.027093e-004,0.000000e+000,2,9.558448e-001,0.000000e+000,,,,,,,,,,,,,,32,1,4.000000e+000,0.000000e+000,0.000000e+000,0,,0,
1524321242.683,,0.000000e+000,3.599902e+001,-2.027835e-004,0.000000e+000,2,9.558521e-001,0.000000e+000,,,,,,,,,,,,,,32,1,4.000000e+000,1.647949e-003,0.000000e+000,0,,0,
1524321267.866,,0.000000e+000,3.599736e+001,-2.028111e-004,0.000000e+000,2,9.558643e-001,0.000000e+000,,,,,,,,,,,,,,32,1,4.000000e+000,0.000000e+000,0.000000e+000,0,,0,
1524321293.048,,0.000000e+000,3.599902e+001,-2.028453e-004,0.000000e+000,2,9.560222e-001,0.000000e+000,,,,,,,,,,,,,,32,1,4.000000e+000,1.647949e-003,0.000000e+000,0,,0,
1524321318.251,,0.000000e+000,3.599984e+001,-2.028896e-004,0.000000e+000,2,9.559855e-001,0.000000e+000,,,,,,,,,,,,,,32,1,4.000000e+000,0.000000e+000,0.000000e+000,0,,0,
1524321343.402,,0.000000e+000,3.599902e+001,-2.029312e-004,0.000000e+000,2,9.561450e-001,0.000000e+000,,,,,,,,,,,,,,32,1,4.000000e+000,3.318787e-003,0.000000e+000,0,,0,
1524321368.612,,0.000000e+000,3.599902e+001,-2.029698e-004,0.000000e+000,2,9.562033e-001,0.000000e+000,,,,,,,,,,,,,,32,1,4.000000e+000,3.318787e-003,0.000000e+000,0,,0,
1524321393.755,,0.000000e+000,3.599984e+001,-2.030326e-004,0.000000e+000,2,9.561929e-001,0.000000e+000,,,,,,,,,,,,,,32,1,4.000000e+000,0.000000e+000,0.000000e+000,0,,0,
1524321418.935,,0.000000e+000,3.599819e+001,-2.030516e-004,0.000000e+000,2,9.563075e-001,0.000000e+000,,,,,,,,,,,,,,32,1,4.000000e+000,1.659393e-003,0.000000e+000,0,,0,
1524321444.111,,0.000000e+000,3.599902e+001,-2.030766e-004,0.000000e+000,2,9.564247e-001,0.000000e+000,,,,,,,,,,,,,,32,1,4.000000e+000,3.318787e-003,0.000000e+000,0,,0,
1524321469.286,,0.000000e+000,3.600026e+001,-2.031100e-004,0.000000e+000,2,9.565609e-001,0.000000e+000,,,,,,,,,,,,,,32,1,4.000000e+000,8.392334e-004,0.000000e+000,0,,0,
1524321494.476,,0.000000e+000,3.599736e+001,-2.031317e-004,0.000000e+000,2,9.564889e-001,0.000000e+000,,,,,,,,,,,,,,32,1,4.000000e+000,1.663208e-003,0.000000e+000,0,,0,
1524321519.652,,0.000000e+000,3.599778e+001,-2.032064e-004,0.000000e+000,2,9.567096e-001,0.000000e+000,,,,,,,,,,,,,,32,1,4.000000e+000,8.316040e-004,0.000000e+000,0,,0,
1524321544.827,,0.000000e+000,3.599943e+001,-2.032234e-004,0.000000e+000,2,9.568066e-001,0.000000e+000,,,,,,,,,,,,,,32,1,4.000000e+000,8.201599e-004,0.000000e+000,0,,0,
1524321569.970,,0.000000e+000,3.599860e+001,-2.032562e-004,0.000000e+000,2,9.568522e-001,0.000000e+000,,,,,,,,,,,,,,32,1,4.000000e+000,8.277893e-004,0.000000e+000,0,,0,
1524321595.170,,0.000000e+000,3.599902e+001,-2.032875e-004,0.000000e+000,2,9.569781e-001,0.000000e+000,,,,,,,,,,,,,,32,1,4.000000e+000,1.647949e-003,0.000000e+000,0,,0,
1524321620.358,,0.000000e+000,3.600026e+001,-2.033370e-004,0.000000e+000,2,9.570101e-001,0.000000e+000,,,,,,,,,,,,,,32,1,4.000000e+000,8.392334e-004,0.000000e+000,0,,0,
1524321645.516,,0.000000e+000,3.599819e+001,-2.033813e-004,0.000000e+000,2,9.571828e-001,0.000000e+000,,,,,,,,,,,,,,32,1,4.000000e+000,1.659393e-003,0.000000e+000,0,,0,
1524321670.674,,0.000000e+000,3.599778e+001,-2.033569e-004,0.000000e+000,2,9.572533e-001,0.000000e+000,,,,,,,,,,,,,,32,1,4.000000e+000,8.316040e-004,0.000000e+000,0,,0,
1524321695.869,,0.000000e+000,3.600026e+001,-2.034093e-004,0.000000e+000,2,9.572722e-001,0.000000e+000,,,,,,,,,,,,,,32,1,4.000000e+000,8.392334e-004,0.000000e+000,0,,0,
1524321721.065,,0.000000e+000,3.599902e+001,-2.034847e-004,0.000000e+000,2,9.574114e-001,0.000000e+000,,,,,,,,,,,,,,32,1,4.000000e+000,1.647949e-003,0.000000e+000,0,,0,
1524321746.270,,0.000000e+000,3.600026e+001,-2.034940e-004,0.000000e+000,2,9.576074e-001,0.000000e+000,,,,,,,,,,,,,,32,1,4.000000e+000,8.392334e-004,0.000000e+000,0,,0,
1524321771.430,,0.000000e+000,3.599902e+001,-2.035458e-004,0.000000e+000,2,9.577299e-001,0.000000e+000,,,,,,,,,,,,,,32,1,4.000000e+000,1.647949e-003,0.000000e+000,0,,0,
1524321796.591,,0.000000e+000,3.599902e+001,-2.035620e-004,0.000000e+000,2,9.577051e-001,0.000000e+000,,,,,,,,,,,,,,32,1,4.000000e+000,1.647949e-003,0.000000e+000,0,,0,
1524321821.766,,0.000000e+000,3.599819e+001,-2.035929e-004,0.000000e+000,2,9.578079e-001,0.000000e+000,,,,,,,,,,,,,,32,1,4.000000e+000,0.000000e+000,0.000000e+000,0,,0,
1524321846.962,,0.000000e+000,3.599985e+001,-2.036192e-004,0.000000e+000,2,9.579655e-001,0.000000e+000,,,,,,,,,,,,,,32,1,4.000000e+000,3.307343e-003,0.000000e+000,0,,0,
1524321872.117,,0.000000e+000,3.599944e+001,-2.036451e-004,0.000000e+000,2,9.579593e-001,0.000000e+000,,,,,,,,,,,,,,32,1,4.000000e+000,2.487183e-003,0.000000e+000,0,,0,
1524321897.300,,0.000000e+000,3.599984e+001,-2.037055e-004,0.000000e+000,2,9.581337e-001,0.000000e+000,,,,,,,,,,,,,,32,1,4.000000e+000,0.000000e+000,0.000000e+000,0,,0,
1524321922.485,,0.000000e+000,3.599778e+001,-2.037055e-004,0.000000e+000,2,9.580882e-001,0.000000e+000,,,,,,,,,,,,,,32,1,4.000000e+000,8.316040e-004,0.000000e+000,0,,0,
1524321947.671,,0.000000e+000,3.599944e+001,-2.037443e-004,0.000000e+000,2,9.583226e-001,0.000000e+000,,,,,,,,,,,,,,32,1,4.000000e+000,2.487183e-003,0.000000e+000,0,,0,
1524321972.853,,0.000000e+000,3.599819e+001,-2.038049e-004,0.000000e+000,2,9.584306e-001,0.000000e+000,,,,,,,,,,,,,,32,1,4.000000e+000,0.000000e+000,0.000000e+000,0,,0,
1524321998.044,,0.000000e+000,3.599902e+001,-2.038173e-004,0.000000e+000,2,9.583609e-001,0.000000e+000,,,,,,,,,,,,,,32,1,4.000000e+000,1.647949e-003,0.000000e+000,0,,0,
1524322023.204,,0.000000e+000,3.599902e+001,-2.038558e-004,0.000000e+000,2,9.585330e-001,0.000000e+000,,,,,,,,,,,,,,32,1,4.000000e+000,1.647949e-003,0.000000e+000,0,,0,
1524322048.365,,0.000000e+000,3.599778e+001,-2.038599e-004,0.000000e+000,2,9.585747e-001,0.000000e+000,,,,,,,,,,,,,,32,1,4.000000e+000,8.316040e-004,0.000000e+000,0,,0,
1524322073.570,,0.000000e+000,3.599944e+001,-2.038932e-004,0.000000e+000,2,9.586296e-001,0.000000e+000,,,,,,,,,,,,,,32,1,4.000000e+000,2.487183e-003,0.000000e+000,0,,0,
1524322098.768,,0.000000e+000,3.599778e+001,-2.039557e-004,0.000000e+000,2,9.587013e-001,0.000000e+000,,,,,,,,,,,,,,32,1,4.000000e+000,8.316040e-004,0.000000e+000,0,,0,
1524322123.911,,0.000000e+000,3.599943e+001,-2.039798e-004,0.000000e+000,2,9.586839e-001,0.000000e+000,,,,,,,,,,,,,,32,1,4.000000e+000,8.201599e-004,0.000000e+000,0,,0,
1524322149.106,,0.000000e+000,3.599902e+001,-2.040207e-004,0.000000e+000,2,9.589065e-001,0.000000e+000,,,,,,,,,,,,,,32,1,4.000000e+000,0.000000e+000,0.000000e+000,0,,0,
1524322174.261,,0.000000e+000,3.599902e+001,-2.040390e-004,0.000000e+000,2,9.590372e-001,0.000000e+000,,,,,,,,,,,,,,32,1,4.000000e+000,1.647949e-003,0.000000e+000,0,,0,
1524322199.447,,0.000000e+000,3.599943e+001,-2.040775e-004,0.000000e+000,2,9.590322e-001,0.000000e+000,,,,,,,,,,,,,,32,1,4.000000e+000,8.201599e-004,0.000000e+000,0,,0,
1524322224.637,,0.000000e+000,3.599819e+001,-2.041193e-004,0.000000e+000,2,9.591804e-001,0.000000e+000,,,,,,,,,,,,,,32,1,4.000000e+000,1.659393e-003,0.000000e+000,0,,0,
1524322249.807,,0.000000e+000,3.599818e+001,-2.041246e-004,0.000000e+000,2,9.592530e-001,0.000000e+000,,,,,,,,,,,,,,32,1,4.000000e+000,3.311157e-003,0.000000e+000,0,,0,
1524322275.018,,0.000000e+000,3.600026e+001,-2.041385e-004,0.000000e+000,2,9.593019e-001,0.000000e+000,,,,,,,,,,,,,,32,1,4.000000e+000,2.479553e-003,0.000000e+000,0,,0,
1524322300.126,,0.000000e+000,3.599819e+001,-2.041107e-004,0.000000e+000,2,9.593942e-001,0.000000e+000,,,,,,,,,,,,,,32,1,4.000000e+000,1.659393e-003,0.000000e+000,0,,0,
1524322325.351,,0.000000e+000,3.600026e+001,-2.042279e-004,0.000000e+000,2,9.595676e-001,0.000000e+000,,,,,,,,,,,,,,32,1,4.000000e+000,8.392334e-004,0.000000e+000,0,,0,
1524322337.946,,0.000000e+000,3.599778e+001,-2.042285e-004,0.000000e+000,2,9.596875e-001,0.000000e+000,,,,,,,,,,,,,,32,1,4.000000e+000,8.316040e-004,0.000000e+000,0,,0,