File: Experimental Raw Data/MFn1 VRM/Linear Regression/MFn1_VRMac_34K_6000s.dc.dat
[Header]
TITLE,MPMS DC Measurement
BYAPP,MPMS Measurement,2.1,Summary
FILEOPENTIME, 1524257604.734000 4/20/2018, 2:53:24 PM

INFO, APPNAME, MPMS MultiVu Application, Revision 1.61,  Build 082

INFO, NAME, MFn1
INFO, WEIGHT, 1.000
INFO, AREA, 1.000
INFO, LENGTH, 1.000
INFO, SHAPE, 0
INFO, COMMENT,
INFO, SEQUENCE FILE: VRMac_34K_6000s_VRMde_35K.seq


INFO, BACKGROUND DATA FILE:, None


STARTUPAXIS,X,4,LINEAR,AUTO,0.000000,0.000000
STARTUPAXIS,Y1,5,LINEAR,AUTO,0.000000,0.000000


STARTUPGROUP,Longitudinal
FIELDGROUP,Longitudinal,1,2,3,4,5,6,7,8,9,15,16,17,18,27,28
FIELDGROUP,Transverse,1,2,3,4,10,11,12,13,14,19,20,21,22,27,28

PLOT_APPEARANCE,ALL,HORZ_GRID_ON,VERT_GRID_ON,MARKERS_AND_LINES

[Data]
Time,Comment,Field (Oe),Temperature (K),Long Moment (emu),Long Scan Std Dev,Long Algorithm,Long Reg Fit,Long Percent Error (%),Trans Moment (emu),Trans Scan Std Dev,Trans Algorithm,Trans Reg Fit,Trans Percent Error (%),Long Moment [w/o ABS] (emu),Long Scan Std Dev [w/o ABS],Long Reg Fit [w/o ABS],Long Percent Error [w/o ABS] (%),Trans Moment [w/o ABS] (emu),Trans Scan Std Dev [w/o ABS],Trans Reg Fit [w/o ABS],Trans Percent Error [w/o ABS] (%),Points per Scan,Scans per Measurement,Scan Length (cm),Delta Temp (K),Rot Position (deg),Error,EC Comp. Running,Using ABS,
1524257604.731,,0.000000e+000,3.400156e+001,-1.676716e-004,0.000000e+000,2,8.649969e-001,0.000000e+000,,,,,,,,,,,,,,32,1,4.000000e+000,5.889893e-003,0.000000e+000,0,,0,
1524257629.924,,0.000000e+000,3.399825e+001,-1.718078e-004,0.000000e+000,2,8.635885e-001,0.000000e+000,,,,,,,,,,,,,,32,1,4.000000e+000,3.681183e-003,0.000000e+000,0,,0,
1524257655.210,,0.000000e+000,3.400119e+001,-1.740162e-004,0.000000e+000,2,8.638286e-001,0.000000e+000,,,,,,,,,,,,,,32,1,4.000000e+000,5.149841e-003,0.000000e+000,0,,0,
1524257680.113,,0.000000e+000,3.400046e+001,-1.753925e-004,0.000000e+000,2,8.640823e-001,0.000000e+000,,,,,,,,,,,,,,32,1,4.000000e+000,7.286072e-004,0.000000e+000,0,,0,
1524257705.448,,0.000000e+000,3.399973e+001,-1.765435e-004,0.000000e+000,2,8.643389e-001,0.000000e+000,,,,,,,,,,,,,,32,1,4.000000e+000,7.324219e-004,0.000000e+000,0,,0,
1524257731.091,,0.000000e+000,3.399862e+001,-1.774697e-004,0.000000e+000,2,8.643318e-001,0.000000e+000,,,,,,,,,,,,,,32,1,4.000000e+000,1.480103e-003,0.000000e+000,0,,0,
1524257756.456,,0.000000e+000,3.399825e+001,-1.782488e-004,0.000000e+000,2,8.644722e-001,0.000000e+000,,,,,,,,,,,,,,32,1,4.000000e+000,7.400513e-004,0.000000e+000,0,,0,
1524257781.844,,0.000000e+000,3.399825e+001,-1.789345e-004,0.000000e+000,2,8.647400e-001,0.000000e+000,,,,,,,,,,,,,,32,1,4.000000e+000,7.400513e-004,0.000000e+000,0,,0,
1524257806.567,,0.000000e+000,3.399825e+001,-1.795240e-004,0.000000e+000,2,8.647565e-001,0.000000e+000,,,,,,,,,,,,,,32,1,4.000000e+000,2.220154e-003,0.000000e+000,0,,0,
1524257831.315,,0.000000e+000,3.399751e+001,-1.800402e-004,0.000000e+000,2,8.650661e-001,0.000000e+000,,,,,,,,,,,,,,32,1,4.000000e+000,2.208710e-003,0.000000e+000,0,,0,
1524257855.960,,0.000000e+000,3.399825e+001,-1.804649e-004,0.000000e+000,2,8.652574e-001,0.000000e+000,,,,,,,,,,,,,,32,1,4.000000e+000,7.400513e-004,0.000000e+000,0,,0,
1524257881.441,,0.000000e+000,3.399788e+001,-1.809127e-004,0.000000e+000,2,8.655363e-001,0.000000e+000,,,,,,,,,,,,,,32,1,4.000000e+000,0.000000e+000,0.000000e+000,0,,0,
1524257906.696,,0.000000e+000,3.399899e+001,-1.812558e-004,0.000000e+000,2,8.655072e-001,0.000000e+000,,,,,,,,,,,,,,32,1,4.000000e+000,2.212524e-003,0.000000e+000,0,,0,
1524257931.656,,0.000000e+000,3.399715e+001,-1.816748e-004,0.000000e+000,2,8.654059e-001,0.000000e+000,,,,,,,,,,,,,,32,1,4.000000e+000,1.468658e-003,0.000000e+000,0,,0,
1524257956.477,,0.000000e+000,3.399788e+001,-1.820228e-004,0.000000e+000,2,8.656239e-001,0.000000e+000,,,,,,,,,,,,,,32,1,4.000000e+000,1.480103e-003,0.000000e+000,0,,0,
1524257981.830,,0.000000e+000,3.399899e+001,-1.823429e-004,0.000000e+000,2,8.661345e-001,0.000000e+000,,,,,,,,,,,,,,32,1,4.000000e+000,7.400513e-004,0.000000e+000,0,,0,
1524258007.677,,0.000000e+000,3.399788e+001,-1.826762e-004,0.000000e+000,2,8.663788e-001,0.000000e+000,,,,,,,,,,,,,,32,1,4.000000e+000,0.000000e+000,0.000000e+000,0,,0,
1524258033.135,,0.000000e+000,3.399973e+001,-1.830078e-004,0.000000e+000,2,8.661699e-001,0.000000e+000,,,,,,,,,,,,,,32,1,4.000000e+000,7.324219e-004,0.000000e+000,0,,0,
1524258058.796,,0.000000e+000,3.399788e+001,-1.832559e-004,0.000000e+000,2,8.663812e-001,0.000000e+000,,,,,,,,,,,,,,32,1,4.000000e+000,1.480103e-003,0.000000e+000,0,,0,
1524258084.428,,0.000000e+000,3.399715e+001,-1.834888e-004,0.000000e+000,2,8.664989e-001,0.000000e+000,,,,,,,,,,,,,,32,1,4.000000e+000,1.468658e-003,0.000000e+000,0,,0,
1524258109.531,,0.000000e+000,3.399825e+001,-1.838040e-004,0.000000e+000,2,8.665605e-001,0.000000e+000,,,,,,,,,,,,,,32,1,4.000000e+000,2.220154e-003,0.000000e+000,0,,0,
1524258134.707,,0.000000e+000,3.399788e+001,-1.840317e-004,0.000000e+000,2,8.666849e-001,0.000000e+000,,,,,,,,,,,,,,32,1,4.000000e+000,1.480103e-003,0.000000e+000,0,,0,
1524258159.982,,0.000000e+000,3.399935e+001,-1.842713e-004,0.000000e+000,2,8.670033e-001,0.000000e+000,,,,,,,,,,,,,,32,1,4.000000e+000,2.941132e-003,0.000000e+000,0,,0,
1524258184.715,,0.000000e+000,3.399862e+001,-1.844912e-004,0.000000e+000,2,8.674103e-001,0.000000e+000,,,,,,,,,,,,,,32,1,4.000000e+000,0.000000e+000,0.000000e+000,0,,0,
1524258210.123,,0.000000e+000,3.400452e+001,-1.847208e-004,0.000000e+000,2,8.673935e-001,0.000000e+000,,,,,,,,,,,,,,32,1,4.000000e+000,1.031113e-002,0.000000e+000,0,,0,
1524258236.193,,0.000000e+000,3.399751e+001,-1.849238e-004,0.000000e+000,2,8.674904e-001,0.000000e+000,,,,,,,,,,,,,,32,1,4.000000e+000,2.208710e-003,0.000000e+000,0,,0,
1524258261.224,,0.000000e+000,3.399677e+001,-1.851176e-004,0.000000e+000,2,8.673818e-001,0.000000e+000,,,,,,,,,,,,,,32,1,4.000000e+000,7.286072e-004,0.000000e+000,0,,0,
1524258288.224,,0.000000e+000,3.399825e+001,-1.853173e-004,0.000000e+000,2,8.678657e-001,0.000000e+000,,,,,,,,,,,,,,32,1,4.000000e+000,7.400513e-004,0.000000e+000,0,,0,
1524258313.819,,0.000000e+000,3.399751e+001,-1.855026e-004,0.000000e+000,2,8.680987e-001,0.000000e+000,,,,,,,,,,,,,,32,1,4.000000e+000,7.400513e-004,0.000000e+000,0,,0,
1524258339.587,,0.000000e+000,3.399788e+001,-1.856903e-004,0.000000e+000,2,8.681026e-001,0.000000e+000,,,,,,,,,,,,,,32,1,4.000000e+000,0.000000e+000,0.000000e+000,0,,0,
1524258364.620,,0.000000e+000,3.399751e+001,-1.858565e-004,0.000000e+000,2,8.682894e-001,0.000000e+000,,,,,,,,,,,,,,32,1,4.000000e+000,7.400513e-004,0.000000e+000,0,,0,
1524258403.208,,0.000000e+000,3.399862e+001,-1.860854e-004,0.000000e+000,2,8.688794e-001,0.000000e+000,,,,,,,,,,,,,,32,1,4.000000e+000,1.480103e-003,0.000000e+000,0,,0,
1524258428.276,,0.000000e+000,3.399862e+001,-1.862320e-004,0.000000e+000,2,8.687139e-001,0.000000e+000,,,,,,,,,,,,,,32,1,4.000000e+000,0.000000e+000,0.000000e+000,0,,0,
1524258454.124,,0.000000e+000,3.399862e+001,-1.864054e-004,0.000000e+000,2,8.692653e-001,0.000000e+000,,,,,,,,,,,,,,32,1,4.000000e+000,1.480103e-003,0.000000e+000,0,,0,
1524258479.259,,0.000000e+000,3.399751e+001,-1.865681e-004,0.000000e+000,2,8.692029e-001,0.000000e+000,,,,,,,,,,,,,,32,1,4.000000e+000,2.208710e-003,0.000000e+000,0,,0,
1524258504.637,,0.000000e+000,3.399825e+001,-1.866761e-004,0.000000e+000,2,8.693960e-001,0.000000e+000,,,,,,,,,,,,,,32,1,4.000000e+000,7.400513e-004,0.000000e+000,0,,0,
1524258530.415,,0.000000e+000,3.399862e+001,-1.868145e-004,0.000000e+000,2,8.695178e-001,0.000000e+000,,,,,,,,,,,,,,32,1,4.000000e+000,2.952576e-003,0.000000e+000,0,,0,
1524258555.688,,0.000000e+000,3.399973e+001,-1.869814e-004,0.000000e+000,2,8.696544e-001,0.000000e+000,,,,,,,,,,,,,,32,1,4.000000e+000,7.324219e-004,0.000000e+000,0,,0,
1524258581.273,,0.000000e+000,3.399862e+001,-1.871089e-004,0.000000e+000,2,8.699584e-001,0.000000e+000,,,,,,,,,,,,,,32,1,4.000000e+000,1.480103e-003,0.000000e+000,0,,0,
1524258606.911,,0.000000e+000,3.399751e+001,-1.872851e-004,0.000000e+000,2,8.701219e-001,0.000000e+000,,,,,,,,,,,,,,32,1,4.000000e+000,2.208710e-003,0.000000e+000,0,,0,
1524258632.757,,0.000000e+000,3.399862e+001,-1.874561e-004,0.000000e+000,2,8.698321e-001,0.000000e+000,,,,,,,,,,,,,,32,1,4.000000e+000,1.480103e-003,0.000000e+000,0,,0,
1524258658.420,,0.000000e+000,3.399973e+001,-1.875412e-004,0.000000e+000,2,8.699446e-001,0.000000e+000,,,,,,,,,,,,,,32,1,4.000000e+000,7.324219e-004,0.000000e+000,0,,0,
1524258683.435,,0.000000e+000,3.399825e+001,-1.876727e-004,0.000000e+000,2,8.702479e-001,0.000000e+000,,,,,,,,,,,,,,32,1,4.000000e+000,7.400513e-004,0.000000e+000,0,,0,
1524258708.583,,0.000000e+000,3.399899e+001,-1.877725e-004,0.000000e+000,2,8.705471e-001,0.000000e+000,,,,,,,,,,,,,,32,1,4.000000e+000,7.400513e-004,0.000000e+000,0,,0,
1524258735.176,,0.000000e+000,3.399825e+001,-1.878677e-004,0.000000e+000,2,8.707715e-001,0.000000e+000,,,,,,,,,,,,,,32,1,4.000000e+000,7.400513e-004,0.000000e+000,0,,0,
1524258760.896,,0.000000e+000,3.399862e+001,-1.880170e-004,0.000000e+000,2,8.706479e-001,0.000000e+000,,,,,,,,,,,,,,32,1,4.000000e+000,2.952576e-003,0.000000e+000,0,,0,
1524258786.549,,0.000000e+000,3.399899e+001,-1.881636e-004,0.000000e+000,2,8.708115e-001,0.000000e+000,,,,,,,,,,,,,,32,1,4.000000e+000,7.400513e-004,0.000000e+000,0,,0,
1524258812.204,,0.000000e+000,3.399825e+001,-1.882911e-004,0.000000e+000,2,8.710197e-001,0.000000e+000,,,,,,,,,,,,,,32,1,4.000000e+000,7.400513e-004,0.000000e+000,0,,0,
1524258837.860,,0.000000e+000,3.399825e+001,-1.884121e-004,0.000000e+000,2,8.709975e-001,0.000000e+000,,,,,,,,,,,,,,32,1,4.000000e+000,2.220154e-003,0.000000e+000,0,,0,
1524258863.497,,0.000000e+000,3.399899e+001,-1.884917e-004,0.000000e+000,2,8.710268e-001,0.000000e+000,,,,,,,,,,,,,,32,1,4.000000e+000,7.400513e-004,0.000000e+000,0,,0,
1524258889.173,,0.000000e+000,3.399788e+001,-1.886281e-004,0.000000e+000,2,8.714638e-001,0.000000e+000,,,,,,,,,,,,,,32,1,4.000000e+000,1.480103e-003,0.000000e+000,0,,0,
1524258914.851,,0.000000e+000,3.399751e+001,-1.886994e-004,0.000000e+000,2,8.715767e-001,0.000000e+000,,,,,,,,,,,,,,32,1,4.000000e+000,7.400513e-004,0.000000e+000,0,,0,
1524258940.519,,0.000000e+000,3.399788e+001,-1.888182e-004,0.000000e+000,2,8.716841e-001,0.000000e+000,,,,,,,,,,,,,,32,1,4.000000e+000,1.480103e-003,0.000000e+000,0,,0,
1524258965.811,,0.000000e+000,3.399899e+001,-1.889059e-004,0.000000e+000,2,8.720887e-001,0.000000e+000,,,,,,,,,,,,,,32,1,4.000000e+000,7.400513e-004,0.000000e+000,0,,0,
1524258991.347,,0.000000e+000,3.399825e+001,-1.890273e-004,0.000000e+000,2,8.719181e-001,0.000000e+000,,,,,,,,,,,,,,32,1,4.000000e+000,7.400513e-004,0.000000e+000,0,,0,
1524259017.462,,0.000000e+000,3.399862e+001,-1.891396e-004,0.000000e+000,2,8.722343e-001,0.000000e+000,,,,,,,,,,,,,,32,1,4.000000e+000,1.480103e-003,0.000000e+000,0,,0,
1524259042.768,,0.000000e+000,3.399825e+001,-1.892236e-004,0.000000e+000,2,8.723105e-001,0.000000e+000,,,,,,,,,,,,,,32,1,4.000000e+000,2.220154e-003,0.000000e+000,0,,0,
1524259068.513,,0.000000e+000,3.399789e+001,-1.893294e-004,0.000000e+000,2,8.727179e-001,0.000000e+000,,,,,,,,,,,,,,32,1,4.000000e+000,2.948761e-003,0.000000e+000,0,,0,
1524259094.323,,0.000000e+000,3.399862e+001,-1.894356e-004,0.000000e+000,2,8.726395e-001,0.000000e+000,,,,,,,,,,,,,,32,1,4.000000e+000,2.952576e-003,0.000000e+000,0,,0,
1524259119.571,,0.000000e+000,3.399825e+001,-1.895103e-004,0.000000e+000,2,8.727342e-001,0.000000e+000,,,,,,,,,,,,,,32,1,4.000000e+000,7.400513e-004,0.000000e+000,0,,0,
1524259144.982,,0.000000e+000,3.399899e+001,-1.895738e-004,0.000000e+000,2,8.728677e-001,0.000000e+000,,,,,,,,,,,,,,32,1,4.000000e+000,7.400513e-004,0.000000e+000,0,,0,
1524259170.577,,0.000000e+000,3.399862e+001,-1.896247e-004,0.000000e+000,2,8.728612e-001,0.000000e+000,,,,,,,,,,,,,,32,1,4.000000e+000,1.480103e-003,0.000000e+000,0,,0,
1524259195.692,,0.000000e+000,3.399862e+001,-1.897859e-004,0.000000e+000,2,8.730087e-001,0.000000e+000,,,,,,,,,,,,,,32,1,4.000000e+000,0.000000e+000,0.000000e+000,0,,0,
1524259220.670,,0.000000e+000,3.399862e+001,-1.898862e-004,0.000000e+000,2,8.732643e-001,0.000000e+000,,,,,,,,,,,,,,32,1,4.000000e+000,0.000000e+000,0.000000e+000,0,,0,
1524259246.331,,0.000000e+000,3.399862e+001,-1.899593e-004,0.000000e+000,2,8.733222e-001,0.000000e+000,,,,,,,,,,,,,,32,1,4.000000e+000,0.000000e+000,0.000000e+000,0,,0,
1524259272.434,,0.000000e+000,3.399788e+001,-1.900608e-004,0.000000e+000,2,8.735722e-001,0.000000e+000,,,,,,,,,,,,,,32,1,4.000000e+000,0.000000e+000,0.000000e+000,0,,0,
1524259297.636,,0.000000e+000,3.399936e+001,-1.901269e-004,0.000000e+000,2,8.738801e-001,0.000000e+000,,,,,,,,,,,,,,32,1,4.000000e+000,0.000000e+000,0.000000e+000,0,,0,
1524259323.182,,0.000000e+000,3.399899e+001,-1.902240e-004,0.000000e+000,2,8.739199e-001,0.000000e+000,,,,,,,,,,,,,,32,1,4.000000e+000,2.212524e-003,0.000000e+000,0,,0,
1524259348.837,,0.000000e+000,3.399936e+001,-1.903143e-004,0.000000e+000,2,8.739755e-001,0.000000e+000,,,,,,,,,,,,,,32,1,4.000000e+000,1.472473e-003,0.000000e+000,0,,0,
1524259374.793,,0.000000e+000,3.399862e+001,-1.903678e-004,0.000000e+000,2,8.739560e-001,0.000000e+000,,,,,,,,,,,,,,32,1,4.000000e+000,0.000000e+000,0.000000e+000,0,,0,
1524259399.725,,0.000000e+000,3.399825e+001,-1.904708e-004,0.000000e+000,2,8.743301e-001,0.000000e+000,,,,,,,,,,,,,,32,1,4.000000e+000,7.400513e-004,0.000000e+000,0,,0,
1524259425.483,,0.000000e+000,3.399862e+001,-1.905702e-004,0.000000e+000,2,8.743595e-001,0.000000e+000,,,,,,,,,,,,,,32,1,4.000000e+000,0.000000e+000,0.000000e+000,0,,0,
1524259451.374,,0.000000e+000,3.399825e+001,-1.906609e-004,0.000000e+000,2,8.747498e-001,0.000000e+000,,,,,,,,,,,,,,32,1,4.000000e+000,2.220154e-003,0.000000e+000,0,,0,
1524259476.931,,0.000000e+000,3.399825e+001,-1.905646e-004,0.000000e+000,2,8.746595e-001,0.000000e+000,,,,,,,,,,,,,,32,1,4.000000e+000,7.400513e-004,0.000000e+000,0,,0,
1524259502.264,,0.000000e+000,3.399825e+001,-1.907721e-004,0.000000e+000,2,8.744407e-001,0.000000e+000,,,,,,,,,,,,,,32,1,4.000000e+000,2.220154e-003,0.000000e+000,0,,0,
1524259527.912,,0.000000e+000,3.399862e+001,-1.908755e-004,0.000000e+000,2,8.752614e-001,0.000000e+000,,,,,,,,,,,,,,32,1,4.000000e+000,0.000000e+000,0.000000e+000,0,,0,
1524259553.670,,0.000000e+000,3.399751e+001,-1.909375e-004,0.000000e+000,2,8.752605e-001,0.000000e+000,,,,,,,,,,,,,,32,1,4.000000e+000,7.400513e-004,0.000000e+000,0,,0,
1524259578.405,,0.000000e+000,3.399899e+001,-1.909929e-004,0.000000e+000,2,8.752817e-001,0.000000e+000,,,,,,,,,,,,,,32,1,4.000000e+000,7.400513e-004,0.000000e+000,0,,0,
1524259604.248,,0.000000e+000,3.399825e+001,-1.910625e-004,0.000000e+000,2,8.757212e-001,0.000000e+000,,,,,,,,,,,,,,32,1,4.000000e+000,7.400513e-004,0.000000e+000,0,,0,
1524259629.169,,0.000000e+000,3.399936e+001,-1.911513e-004,0.000000e+000,2,8.755618e-001,0.000000e+000,,,,,,,,,,,,,,32,1,4.000000e+000,1.472473e-003,0.000000e+000,0,,0,
1524259654.587,,0.000000e+000,3.399862e+001,-1.912115e-004,0.000000e+000,2,8.758228e-001,0.000000e+000,,,,,,,,,,,,,,32,1,4.000000e+000,0.000000e+000,0.000000e+000,0,,0,
1524259680.212,,0.000000e+000,3.399862e+001,-1.912922e-004,0.000000e+000,2,8.760499e-001,0.000000e+000,,,,,,,,,,,,,,32,1,4.000000e+000,1.480103e-003,0.000000e+000,0,,0,
1524259705.752,,0.000000e+000,3.399751e+001,-1.913526e-004,0.000000e+000,2,8.761619e-001,0.000000e+000,,,,,,,,,,,,,,32,1,4.000000e+000,7.400513e-004,0.000000e+000,0,,0,
1524259732.843,,0.000000e+000,3.399751e+001,-1.914162e-004,0.000000e+000,2,8.762287e-001,0.000000e+000,,,,,,,,,,,,,,32,1,4.000000e+000,3.688812e-003,0.000000e+000,0,,0,
1524259758.706,,0.000000e+000,3.399825e+001,-1.914757e-004,0.000000e+000,2,8.765193e-001,0.000000e+000,,,,,,,,,,,,,,32,1,4.000000e+000,7.400513e-004,0.000000e+000,0,,0,
1524259785.228,,0.000000e+000,3.399862e+001,-1.915524e-004,0.000000e+000,2,8.766826e-001,0.000000e+000,,,,,,,,,,,,,,32,1,4.000000e+000,1.480103e-003,0.000000e+000,0,,0,
1524259809.549,,0.000000e+000,3.399972e+001,-1.916415e-004,0.000000e+000,2,8.766323e-001,0.000000e+000,,,,,,,,,,,,,,32,1,4.000000e+000,2.201080e-003,0.000000e+000,0,,0,
1524259835.187,,0.000000e+000,3.399715e+001,-1.915914e-004,0.000000e+000,2,8.764700e-001,0.000000e+000,,,,,,,,,,,,,,32,1,4.000000e+000,4.428864e-003,0.000000e+000,0,,0,
1524259860.952,,0.000000e+000,3.399862e+001,-1.917947e-004,0.000000e+000,2,8.769870e-001,0.000000e+000,,,,,,,,,,,,,,32,1,4.000000e+000,1.480103e-003,0.000000e+000,0,,0,
1524259886.608,,0.000000e+000,3.399862e+001,-1.918648e-004,0.000000e+000,2,8.767760e-001,0.000000e+000,,,,,,,,,,,,,,32,1,4.000000e+000,1.480103e-003,0.000000e+000,0,,0,
1524259911.598,,0.000000e+000,3.399935e+001,-1.918798e-004,0.000000e+000,2,8.770506e-001,0.000000e+000,,,,,,,,,,,,,,32,1,4.000000e+000,4.421234e-003,0.000000e+000,0,,0,
1524259936.706,,0.000000e+000,3.399825e+001,-1.919491e-004,0.000000e+000,2,8.773254e-001,0.000000e+000,,,,,,,,,,,,,,32,1,4.000000e+000,7.400513e-004,0.000000e+000,0,,0,
1524259962.136,,0.000000e+000,3.399825e+001,-1.919688e-004,0.000000e+000,2,8.773599e-001,0.000000e+000,,,,,,,,,,,,,,32,1,4.000000e+000,7.400513e-004,0.000000e+000,0,,0,
1524259987.799,,0.000000e+000,3.399825e+001,-1.920386e-004,0.000000e+000,2,8.777484e-001,0.000000e+000,,,,,,,,,,,,,,32,1,4.000000e+000,7.400513e-004,0.000000e+000,0,,0,
1524260014.072,,0.000000e+000,3.399714e+001,-1.921555e-004,0.000000e+000,2,8.777063e-001,0.000000e+000,,,,,,,,,,,,,,32,1,4.000000e+000,0.000000e+000,0.000000e+000,0,,0,
1524260039.425,,0.000000e+000,3.399936e+001,-1.922155e-004,0.000000e+000,2,8.776919e-001,0.000000e+000,,,,,,,,,,,,,,32,1,4.000000e+000,1.472473e-003,0.000000e+000,0,,0,
1524260064.958,,0.000000e+000,3.399899e+001,-1.922516e-004,0.000000e+000,2,8.779566e-001,0.000000e+000,,,,,,,,,,,,,,32,1,4.000000e+000,7.400513e-004,0.000000e+000,0,,0,
1524260091.168,,0.000000e+000,3.399899e+001,-1.924379e-004,0.000000e+000,2,8.782594e-001,0.000000e+000,,,,,,,,,,,,,,32,1,4.000000e+000,7.400513e-004,0.000000e+000,0,,0,
1524260116.811,,0.000000e+000,3.399936e+001,-1.923919e-004,0.000000e+000,2,8.783709e-001,0.000000e+000,,,,,,,,,,,,,,32,1,4.000000e+000,1.472473e-003,0.000000e+000,0,,0,
1524260142.441,,0.000000e+000,3.399788e+001,-1.924636e-004,0.000000e+000,2,8.787239e-001,0.000000e+000,,,,,,,,,,,,,,32,1,4.000000e+000,1.480103e-003,0.000000e+000,0,,0,
1524260167.504,,0.000000e+000,3.399936e+001,-1.924927e-004,0.000000e+000,2,8.787102e-001,0.000000e+000,,,,,,,,,,,,,,32,1,4.000000e+000,0.000000e+000,0.000000e+000,0,,0,
1524260192.994,,0.000000e+000,3.399825e+001,-1.925387e-004,0.000000e+000,2,8.785605e-001,0.000000e+000,,,,,,,,,,,,,,32,1,4.000000e+000,7.400513e-004,0.000000e+000,0,,0,
1524260218.312,,0.000000e+000,3.399641e+001,-1.927029e-004,0.000000e+000,2,8.786444e-001,0.000000e+000,,,,,,,,,,,,,,32,1,4.000000e+000,4.417419e-003,0.000000e+000,0,,0,
1524260243.818,,0.000000e+000,3.399936e+001,-1.927586e-004,0.000000e+000,2,8.790391e-001,0.000000e+000,,,,,,,,,,,,,,32,1,4.000000e+000,1.472473e-003,0.000000e+000,0,,0,
1524260269.376,,0.000000e+000,3.399825e+001,-1.927667e-004,0.000000e+000,2,8.789235e-001,0.000000e+000,,,,,,,,,,,,,,32,1,4.000000e+000,7.400513e-004,0.000000e+000,0,,0,
1524260295.418,,0.000000e+000,3.399825e+001,-1.928153e-004,0.000000e+000,2,8.789650e-001,0.000000e+000,,,,,,,,,,,,,,32,1,4.000000e+000,2.220154e-003,0.000000e+000,0,,0,
1524260320.559,,0.000000e+000,3.399936e+001,-1.928921e-004,0.000000e+000,2,8.788414e-001,0.000000e+000,,,,,,,,,,,,,,32,1,4.000000e+000,0.000000e+000,0.000000e+000,0,,0,
1524260345.292,,0.000000e+000,3.399899e+001,-1.928836e-004,0.000000e+000,2,8.795567e-001,0.000000e+000,,,,,,,,,,,,,,32,1,4.000000e+000,2.212524e-003,0.000000e+000,0,,0,
1524260370.797,,0.000000e+000,3.399936e+001,-1.929656e-004,0.000000e+000,2,8.795425e-001,0.000000e+000,,,,,,,,,,,,,,32,1,4.000000e+000,0.000000e+000,0.000000e+000,0,,0,
1524260396.450,,0.000000e+000,3.399899e+001,-1.930505e-004,0.000000e+000,2,8.798180e-001,0.000000e+000,,,,,,,,,,,,,,32,1,4.000000e+000,7.400513e-004,0.000000e+000,0,,0,
1524260421.938,,0.000000e+000,3.399936e+001,-1.930526e-004,0.000000e+000,2,8.797572e-001,0.000000e+000,,,,,,,,,,,,,,32,1,4.000000e+000,1.472473e-003,0.000000e+000,0,,0,
1524260446.878,,0.000000e+000,3.399788e+001,-1.931726e-004,0.000000e+000,2,8.798918e-001,0.000000e+000,,,,,,,,,,,,,,32,1,4.000000e+000,1.480103e-003,0.000000e+000,0,,0,
1524260472.661,,0.000000e+000,3.399936e+001,-1.932033e-004,0.000000e+000,2,8.802137e-001,0.000000e+000,,,,,,,,,,,,,,32,1,4.000000e+000,0.000000e+000,0.000000e+000,0,,0,
1524260498.519,,0.000000e+000,3.399862e+001,-1.932448e-004,0.000000e+000,2,8.799679e-001,0.000000e+000,,,,,,,,,,,,,,32,1,4.000000e+000,0.000000e+000,0.000000e+000,0,,0,
1524260523.537,,0.000000e+000,3.399825e+001,-1.932685e-004,0.000000e+000,2,8.802791e-001,0.000000e+000,,,,,,,,,,,,,,32,1,4.000000e+000,7.400513e-004,0.000000e+000,0,,0,
1524260548.685,,0.000000e+000,3.399899e+001,-1.933453e-004,0.000000e+000,2,8.807474e-001,0.000000e+000,,,,,,,,,,,,,,32,1,4.000000e+000,2.212524e-003,0.000000e+000,0,,0,
1524260573.778,,0.000000e+000,3.399899e+001,-1.933974e-004,0.000000e+000,2,8.806419e-001,0.000000e+000,,,,,,,,,,,,,,32,1,4.000000e+000,2.212524e-003,0.000000e+000,0,,0,
1524260599.310,,0.000000e+000,3.399862e+001,-1.934528e-004,0.000000e+000,2,8.807577e-001,0.000000e+000,,,,,,,,,,,,,,32,1,4.000000e+000,0.000000e+000,0.000000e+000,0,,0,
1524260624.528,,0.000000e+000,3.399678e+001,-1.935125e-004,0.000000e+000,2,8.807811e-001,0.000000e+000,,,,,,,,,,,,,,32,1,4.000000e+000,5.157471e-003,0.000000e+000,0,,0,
1524260650.189,,0.000000e+000,3.399899e+001,-1.935472e-004,0.000000e+000,2,8.811312e-001,0.000000e+000,,,,,,,,,,,,,,32,1,4.000000e+000,7.400513e-004,0.000000e+000,0,,0,
1524260675.554,,0.000000e+000,3.399899e+001,-1.936054e-004,0.000000e+000,2,8.809192e-001,0.000000e+000,,,,,,,,,,,,,,32,1,4.000000e+000,7.400513e-004,0.000000e+000,0,,0,
1524260700.689,,0.000000e+000,3.399973e+001,-1.936424e-004,0.000000e+000,2,8.812037e-001,0.000000e+000,,,,,,,,,,,,,,32,1,4.000000e+000,7.324219e-004,0.000000e+000,0,,0,
1524260726.045,,0.000000e+000,3.399899e+001,-1.937013e-004,0.000000e+000,2,8.811555e-001,0.000000e+000,,,,,,,,,,,,,,32,1,4.000000e+000,7.400513e-004,0.000000e+000,0,,0,
1524260751.768,,0.000000e+000,3.399936e+001,-1.937693e-004,0.000000e+000,2,8.812197e-001,0.000000e+000,,,,,,,,,,,,,,32,1,4.000000e+000,1.472473e-003,0.000000e+000,0,,0,
1524260777.428,,0.000000e+000,3.399936e+001,-1.938024e-004,0.000000e+000,2,8.813825e-001,0.000000e+000,,,,,,,,,,,,,,32,1,4.000000e+000,1.472473e-003,0.000000e+000,0,,0,
1524260802.721,,0.000000e+000,3.399899e+001,-1.938425e-004,0.000000e+000,2,8.811969e-001,0.000000e+000,,,,,,,,,,,,,,32,1,4.000000e+000,7.400513e-004,0.000000e+000,0,,0,
1524260828.721,,0.000000e+000,3.399936e+001,-1.938645e-004,0.000000e+000,2,8.814121e-001,0.000000e+000,,,,,,,,,,,,,,32,1,4.000000e+000,0.000000e+000,0.000000e+000,0,,0,
1524260854.379,,0.000000e+000,3.399825e+001,-1.939087e-004,0.000000e+000,2,8.818602e-001,0.000000e+000,,,,,,,,,,,,,,32,1,4.000000e+000,7.400513e-004,0.000000e+000,0,,0,
1524260879.612,,0.000000e+000,3.399936e+001,-1.940057e-004,0.000000e+000,2,8.816668e-001,0.000000e+000,,,,,,,,,,,,,,32,1,4.000000e+000,0.000000e+000,0.000000e+000,0,,0,
1524260905.280,,0.000000e+000,3.399899e+001,-1.940491e-004,0.000000e+000,2,8.818411e-001,0.000000e+000,,,,,,,,,,,,,,32,1,4.000000e+000,7.400513e-004,0.000000e+000,0,,0,
1524260931.058,,0.000000e+000,3.399862e+001,-1.940782e-004,0.000000e+000,2,8.819350e-001,0.000000e+000,,,,,,,,,,,,,,32,1,4.000000e+000,1.480103e-003,0.000000e+000,0,,0,
1524260956.896,,0.000000e+000,3.399862e+001,-1.941211e-004,0.000000e+000,2,8.825202e-001,0.000000e+000,,,,,,,,,,,,,,32,1,4.000000e+000,1.480103e-003,0.000000e+000,0,,0,
1524260982.573,,0.000000e+000,3.399899e+001,-1.941392e-004,0.000000e+000,2,8.826337e-001,0.000000e+000,,,,,,,,,,,,,,32,1,4.000000e+000,7.400513e-004,0.000000e+000,0,,0,
1524261008.424,,0.000000e+000,3.399899e+001,-1.942396e-004,0.000000e+000,2,8.824806e-001,0.000000e+000,,,,,,,,,,,,,,32,1,4.000000e+000,7.400513e-004,0.000000e+000,0,,0,
1524261034.082,,0.000000e+000,3.399973e+001,-1.942805e-004,0.000000e+000,2,8.823707e-001,0.000000e+000,,,,,,,,,,,,,,32,1,4.000000e+000,7.324219e-004,0.000000e+000,0,,0,
1524261059.750,,0.000000e+000,3.399936e+001,-1.943415e-004,0.000000e+000,2,8.827510e-001,0.000000e+000,,,,,,,,,,,,,,32,1,4.000000e+000,0.000000e+000,0.000000e+000,0,,0,
1524261085.080,,0.000000e+000,3.399936e+001,-1.943826e-004,0.000000e+000,2,8.825905e-001,0.000000e+000,,,,,,,,,,,,,,32,1,4.000000e+000,0.000000e+000,0.000000e+000,0,,0,
1524261110.720,,0.000000e+000,3.399973e+001,-1.943956e-004,0.000000e+000,2,8.827226e-001,0.000000e+000,,,,,,,,,,,,,,32,1,4.000000e+000,7.324219e-004,0.000000e+000,0,,0,
1524261135.848,,0.000000e+000,3.399825e+001,-1.944637e-004,0.000000e+000,2,8.830943e-001,0.000000e+000,,,,,,,,,,,,,,32,1,4.000000e+000,7.400513e-004,0.000000e+000,0,,0,
1524261161.409,,0.000000e+000,3.399899e+001,-1.945242e-004,0.000000e+000,2,8.835036e-001,0.000000e+000,,,,,,,,,,,,,,32,1,4.000000e+000,7.400513e-004,0.000000e+000,0,,0,
1524261186.852,,0.000000e+000,3.400009e+001,-1.945908e-004,0.000000e+000,2,8.835571e-001,0.000000e+000,,,,,,,,,,,,,,32,1,4.000000e+000,2.941132e-003,0.000000e+000,0,,0,
1524261212.274,,0.000000e+000,3.399973e+001,-1.944928e-004,0.000000e+000,2,8.832928e-001,0.000000e+000,,,,,,,,,,,,,,32,1,4.000000e+000,7.324219e-004,0.000000e+000,0,,0,
1524261238.017,,0.000000e+000,3.399862e+001,-1.946613e-004,0.000000e+000,2,8.837057e-001,0.000000e+000,,,,,,,,,,,,,,32,1,4.000000e+000,1.480103e-003,0.000000e+000,0,,0,
1524261263.920,,0.000000e+000,3.399862e+001,-1.946759e-004,0.000000e+000,2,8.836908e-001,0.000000e+000,,,,,,,,,,,,,,32,1,4.000000e+000,0.000000e+000,0.000000e+000,0,,0,
1524261288.946,,0.000000e+000,3.399862e+001,-1.947332e-004,0.000000e+000,2,8.838390e-001,0.000000e+000,,,,,,,,,,,,,,32,1,4.000000e+000,0.000000e+000,0.000000e+000,0,,0,
1524261313.711,,0.000000e+000,3.399972e+001,-1.693297e-004,0.000000e+000,2,2.632095e-001,0.000000e+000,,,,,,,,,,,,,,32,1,4.000000e+000,2.201080e-003,0.000000e+000,0,,0,
1524261339.139,,0.000000e+000,3.399899e+001,-1.948578e-004,0.000000e+000,2,8.839662e-001,0.000000e+000,,,,,,,,,,,,,,32,1,4.000000e+000,7.400513e-004,0.000000e+000,0,,0,
1524261364.789,,0.000000e+000,3.399899e+001,-1.947507e-004,0.000000e+000,2,8.837017e-001,0.000000e+000,,,,,,,,,,,,,,32,1,4.000000e+000,2.212524e-003,0.000000e+000,0,,0,
1524261390.022,,0.000000e+000,3.399825e+001,-1.948592e-004,0.000000e+000,2,8.840619e-001,0.000000e+000,,,,,,,,,,,,,,32,1,4.000000e+000,7.400513e-004,0.000000e+000,0,,0,
1524261416.170,,0.000000e+000,3.399973e+001,-1.949025e-004,0.000000e+000,2,8.841128e-001,0.000000e+000,,,,,,,,,,,,,,32,1,4.000000e+000,7.324219e-004,0.000000e+000,0,,0,
1524261441.330,,0.000000e+000,3.399788e+001,-1.950070e-004,0.000000e+000,2,8.840861e-001,0.000000e+000,,,,,,,,,,,,,,32,1,4.000000e+000,1.480103e-003,0.000000e+000,0,,0,
1524261465.853,,0.000000e+000,3.399899e+001,-1.949348e-004,0.000000e+000,2,8.846338e-001,0.000000e+000,,,,,,,,,,,,,,32,1,4.000000e+000,7.400513e-004,0.000000e+000,0,,0,
1524261491.391,,0.000000e+000,3.399862e+001,-1.950677e-004,0.000000e+000,2,8.848372e-001,0.000000e+000,,,,,,,,,,,,,,32,1,4.000000e+000,0.000000e+000,0.000000e+000,0,,0,
1524261516.379,,0.000000e+000,3.399825e+001,-1.950530e-004,0.000000e+000,2,8.847961e-001,0.000000e+000,,,,,,,,,,,,,,32,1,4.000000e+000,7.400513e-004,0.000000e+000,0,,0,
1524261541.934,,0.000000e+000,3.399899e+001,-1.950785e-004,0.000000e+000,2,8.849477e-001,0.000000e+000,,,,,,,,,,,,,,32,1,4.000000e+000,7.400513e-004,0.000000e+000,0,,0,
1524261567.600,,0.000000e+000,3.399641e+001,-1.951500e-004,0.000000e+000,2,8.850561e-001,0.000000e+000,,,,,,,,,,,,,,32,1,4.000000e+000,5.889893e-003,0.000000e+000,0,,0,
1524261592.995,,0.000000e+000,3.399825e+001,-1.951822e-004,0.000000e+000,2,8.851269e-001,0.000000e+000,,,,,,,,,,,,,,32,1,4.000000e+000,7.400513e-004,0.000000e+000,0,,0,
1524261618.428,,0.000000e+000,3.399936e+001,-1.952118e-004,0.000000e+000,2,8.852965e-001,0.000000e+000,,,,,,,,,,,,,,32,1,4.000000e+000,1.472473e-003,0.000000e+000,0,,0,
1524261644.106,,0.000000e+000,3.399973e+001,-1.952459e-004,0.000000e+000,2,8.853019e-001,0.000000e+000,,,,,,,,,,,,,,32,1,4.000000e+000,7.324219e-004,0.000000e+000,0,,0,
1524261669.771,,0.000000e+000,3.399973e+001,-1.953250e-004,0.000000e+000,2,8.856096e-001,0.000000e+000,,,,,,,,,,,,,,32,1,4.000000e+000,7.324219e-004,0.000000e+000,0,,0,
1524261695.514,,0.000000e+000,3.399936e+001,-1.953003e-004,0.000000e+000,2,8.856264e-001,0.000000e+000,,,,,,,,,,,,,,32,1,4.000000e+000,1.472473e-003,0.000000e+000,0,,0,
1524261720.772,,0.000000e+000,3.399936e+001,-1.953860e-004,0.000000e+000,2,8.858721e-001,0.000000e+000,,,,,,,,,,,,,,32,1,4.000000e+000,1.472473e-003,0.000000e+000,0,,0,
1524261746.095,,0.000000e+000,3.399788e+001,-1.954295e-004,0.000000e+000,2,8.859056e-001,0.000000e+000,,,,,,,,,,,,,,32,1,4.000000e+000,1.480103e-003,0.000000e+000,0,,0,
1524261771.758,,0.000000e+000,3.399936e+001,-1.954373e-004,0.000000e+000,2,8.858464e-001,0.000000e+000,,,,,,,,,,,,,,32,1,4.000000e+000,1.472473e-003,0.000000e+000,0,,0,
1524261796.888,,0.000000e+000,3.399715e+001,-1.954574e-004,0.000000e+000,2,8.862273e-001,0.000000e+000,,,,,,,,,,,,,,32,1,4.000000e+000,1.468658e-003,0.000000e+000,0,,0,
1524261822.533,,0.000000e+000,3.399862e+001,-1.955410e-004,0.000000e+000,2,8.858615e-001,0.000000e+000,,,,,,,,,,,,,,32,1,4.000000e+000,0.000000e+000,0.000000e+000,0,,0,
1524261848.304,,0.000000e+000,3.399936e+001,-1.955802e-004,0.000000e+000,2,8.864397e-001,0.000000e+000,,,,,,,,,,,,,,32,1,4.000000e+000,1.472473e-003,0.000000e+000,0,,0,
1524261873.437,,0.000000e+000,3.399862e+001,-1.956607e-004,0.000000e+000,2,8.864505e-001,0.000000e+000,,,,,,,,,,,,,,32,1,4.000000e+000,1.480103e-003,0.000000e+000,0,,0,
1524261898.987,,0.000000e+000,3.399899e+001,-1.956037e-004,0.000000e+000,2,8.865651e-001,0.000000e+000,,,,,,,,,,,,,,32,1,4.000000e+000,7.400513e-004,0.000000e+000,0,,0,
1524261924.587,,0.000000e+000,3.399715e+001,-1.956894e-004,0.000000e+000,2,8.864929e-001,0.000000e+000,,,,,,,,,,,,,,32,1,4.000000e+000,4.428864e-003,0.000000e+000,0,,0,
1524261950.343,,0.000000e+000,3.399531e+001,-1.956830e-004,0.000000e+000,2,8.867400e-001,0.000000e+000,,,,,,,,,,,,,,32,1,4.000000e+000,8.098602e-003,0.000000e+000,0,,0,
1524261975.676,,0.000000e+000,3.399899e+001,-1.957467e-004,0.000000e+000,2,8.865915e-001,0.000000e+000,,,,,,,,,,,,,,32,1,4.000000e+000,7.400513e-004,0.000000e+000,0,,0,
1524262001.316,,0.000000e+000,3.399936e+001,-1.957065e-004,0.000000e+000,2,8.870106e-001,0.000000e+000,,,,,,,,,,,,,,32,1,4.000000e+000,0.000000e+000,0.000000e+000,0,,0,
1524262027.081,,0.000000e+000,3.399936e+001,-1.957777e-004,0.000000e+000,2,8.868846e-001,0.000000e+000,,,,,,,,,,,,,,32,1,4.000000e+000,0.000000e+000,0.000000e+000,0,,0,
1524262052.109,,0.000000e+000,3.399899e+001,-1.957983e-004,0.000000e+000,2,8.866035e-001,0.000000e+000,,,,,,,,,,,,,,32,1,4.000000e+000,7.400513e-004,0.000000e+000,0,,0,
1524262077.655,,0.000000e+000,3.399862e+001,-1.958473e-004,0.000000e+000,2,8.871980e-001,0.000000e+000,,,,,,,,,,,,,,32,1,4.000000e+000,0.000000e+000,0.000000e+000,0,,0,
1524262102.868,,0.000000e+000,3.400009e+001,-1.959776e-004,0.000000e+000,2,8.875456e-001,0.000000e+000,,,,,,,,,,,,,,32,1,4.000000e+000,1.461029e-003,0.000000e+000,0,,0,
1524262128.198,,0.000000e+000,3.399862e+001,-1.959378e-004,0.000000e+000,2,8.871529e-001,0.000000e+000,,,,,,,,,,,,,,32,1,4.000000e+000,1.480103e-003,0.000000e+000,0,,0,
1524262153.648,,0.000000e+000,3.399825e+001,-1.959753e-004,0.000000e+000,2,8.873439e-001,0.000000e+000,,,,,,,,,,,,,,32,1,4.000000e+000,7.400513e-004,0.000000e+000,0,,0,
1524262179.039,,0.000000e+000,3.399899e+001,-1.959963e-004,0.000000e+000,2,8.876169e-001,0.000000e+000,,,,,,,,,,,,,,32,1,4.000000e+000,7.400513e-004,0.000000e+000,0,,0,
1524262204.829,,0.000000e+000,3.399899e+001,-1.960729e-004,0.000000e+000,2,8.878640e-001,0.000000e+000,,,,,,,,,,,,,,32,1,4.000000e+000,7.400513e-004,0.000000e+000,0,,0,
1524262229.837,,0.000000e+000,3.399936e+001,-1.960382e-004,0.000000e+000,2,8.875948e-001,0.000000e+000,,,,,,,,,,,,,,32,1,4.000000e+000,1.472473e-003,0.000000e+000,0,,0,
1524262255.190,,0.000000e+000,3.399862e+001,-1.961329e-004,0.000000e+000,2,8.872584e-001,0.000000e+000,,,,,,,,,,,,,,32,1,4.000000e+000,1.480103e-003,0.000000e+000,0,,0,
1524262279.603,,0.000000e+000,3.399899e+001,-1.961397e-004,0.000000e+000,2,8.876694e-001,0.000000e+000,,,,,,,,,,,,,,32,1,4.000000e+000,7.400513e-004,0.000000e+000,0,,0,
1524262304.490,,0.000000e+000,3.399936e+001,-1.962004e-004,0.000000e+000,2,8.878919e-001,0.000000e+000,,,,,,,,,,,,,,32,1,4.000000e+000,1.472473e-003,0.000000e+000,0,,0,
1524262330.123,,0.000000e+000,3.399899e+001,-1.962204e-004,0.000000e+000,2,8.882688e-001,0.000000e+000,,,,,,,,,,,,,,32,1,4.000000e+000,2.212524e-003,0.000000e+000,0,,0,
1524262355.564,,0.000000e+000,3.399936e+001,-1.962764e-004,0.000000e+000,2,8.883030e-001,0.000000e+000,,,,,,,,,,,,,,32,1,4.000000e+000,0.000000e+000,0.000000e+000,0,,0,
1524262381.382,,0.000000e+000,3.399788e+001,-1.963402e-004,0.000000e+000,2,8.886114e-001,0.000000e+000,,,,,,,,,,,,,,32,1,4.000000e+000,1.480103e-003,0.000000e+000,0,,0,
1524262406.407,,0.000000e+000,3.399862e+001,-1.962630e-004,0.000000e+000,2,8.881094e-001,0.000000e+000,,,,,,,,,,,,,,32,1,4.000000e+000,0.000000e+000,0.000000e+000,0,,0,
1524262431.637,,0.000000e+000,3.399862e+001,-1.963746e-004,0.000000e+000,2,8.886049e-001,0.000000e+000,,,,,,,,,,,,,,32,1,4.000000e+000,0.000000e+000,0.000000e+000,0,,0,
1524262457.300,,0.000000e+000,3.399899e+001,-1.964022e-004,0.000000e+000,2,8.887091e-001,0.000000e+000,,,,,,,,,,,,,,32,1,4.000000e+000,7.400513e-004,0.000000e+000,0,,0,
1524262482.381,,0.000000e+000,3.399862e+001,-1.963334e-004,0.000000e+000,2,8.884578e-001,0.000000e+000,,,,,,,,,,,,,,32,1,4.000000e+000,1.480103e-003,0.000000e+000,0,,0,
1524262507.726,,0.000000e+000,3.399973e+001,-1.964719e-004,0.000000e+000,2,8.887098e-001,0.000000e+000,,,,,,,,,,,,,,32,1,4.000000e+000,7.324219e-004,0.000000e+000,0,,0,
1524262533.514,,0.000000e+000,3.399899e+001,-1.964396e-004,0.000000e+000,2,8.892905e-001,0.000000e+000,,,,,,,,,,,,,,32,1,4.000000e+000,7.400513e-004,0.000000e+000,0,,0,
1524262559.372,,0.000000e+000,3.399788e+001,-1.965215e-004,0.000000e+000,2,8.888161e-001,0.000000e+000,,,,,,,,,,,,,,32,1,4.000000e+000,1.480103e-003,0.000000e+000,0,,0,
1524262584.820,,0.000000e+000,3.400009e+001,-1.965398e-004,0.000000e+000,2,8.888322e-001,0.000000e+000,,,,,,,,,,,,,,32,1,4.000000e+000,1.461029e-003,0.000000e+000,0,,0,
1524262610.365,,0.000000e+000,3.399899e+001,-1.965257e-004,0.000000e+000,2,8.892354e-001,0.000000e+000,,,,,,,,,,,,,,32,1,4.000000e+000,7.400513e-004,0.000000e+000,0,,0,
1524262635.490,,0.000000e+000,3.399899e+001,-1.966657e-004,0.000000e+000,2,8.894272e-001,0.000000e+000,,,,,,,,,,,,,,32,1,4.000000e+000,7.400513e-004,0.000000e+000,0,,0,
1524262661.168,,0.000000e+000,3.399862e+001,-1.967298e-004,0.000000e+000,2,8.897099e-001,0.000000e+000,,,,,,,,,,,,,,32,1,4.000000e+000,1.480103e-003,0.000000e+000,0,,0,
1524262686.201,,0.000000e+000,3.399936e+001,-1.967146e-004,0.000000e+000,2,8.895624e-001,0.000000e+000,,,,,,,,,,,,,,32,1,4.000000e+000,1.472473e-003,0.000000e+000,0,,0,
1524262711.864,,0.000000e+000,3.399936e+001,-1.967235e-004,0.000000e+000,2,8.894188e-001,0.000000e+000,,,,,,,,,,,,,,32,1,4.000000e+000,1.472473e-003,0.000000e+000,0,,0,
1524262737.499,,0.000000e+000,3.399862e+001,-1.967761e-004,0.000000e+000,2,8.895336e-001,0.000000e+000,,,,,,,,,,,,,,32,1,4.000000e+000,0.000000e+000,0.000000e+000,0,,0,
1524262762.642,,0.000000e+000,3.399936e+001,-1.967693e-004,0.000000e+000,2,8.901187e-001,0.000000e+000,,,,,,,,,,,,,,32,1,4.000000e+000,0.000000e+000,0.000000e+000,0,,0,
1524262788.348,,0.000000e+000,3.399899e+001,-1.967159e-004,0.000000e+000,2,8.900194e-001,0.000000e+000,,,,,,,,,,,,,,32,1,4.000000e+000,2.212524e-003,0.000000e+000,0,,0,
1524262813.998,,0.000000e+000,3.399862e+001,-1.967570e-004,0.000000e+000,2,8.896888e-001,0.000000e+000,,,,,,,,,,,,,,32,1,4.000000e+000,1.480103e-003,0.000000e+000,0,,0,
1524262840.801,,0.000000e+000,3.399677e+001,-1.969058e-004,0.000000e+000,2,8.900226e-001,0.000000e+000,,,,,,,,,,,,,,32,1,4.000000e+000,2.208710e-003,0.000000e+000,0,,0,
1524262866.314,,0.000000e+000,3.399825e+001,-1.969107e-004,0.000000e+000,2,8.898054e-001,0.000000e+000,,,,,,,,,,,,,,32,1,4.000000e+000,7.400513e-004,0.000000e+000,0,,0,
1524262892.099,,0.000000e+000,3.399899e+001,-1.969828e-004,0.000000e+000,2,8.901264e-001,0.000000e+000,,,,,,,,,,,,,,32,1,4.000000e+000,7.400513e-004,0.000000e+000,0,,0,
1524262917.714,,0.000000e+000,3.399899e+001,-1.969191e-004,0.000000e+000,2,8.900694e-001,0.000000e+000,,,,,,,,,,,,,,32,1,4.000000e+000,7.400513e-004,0.000000e+000,0,,0,
1524262942.922,,0.000000e+000,3.399899e+001,-1.969109e-004,0.000000e+000,2,8.904578e-001,0.000000e+000,,,,,,,,,,,,,,32,1,4.000000e+000,7.400513e-004,0.000000e+000,0,,0,
1524262968.275,,0.000000e+000,3.399973e+001,-1.970210e-004,0.000000e+000,2,8.907669e-001,0.000000e+000,,,,,,,,,,,,,,32,1,4.000000e+000,7.324219e-004,0.000000e+000,0,,0,
1524262993.953,,0.000000e+000,3.399936e+001,-1.970562e-004,0.000000e+000,2,8.907062e-001,0.000000e+000,,,,,,,,,,,,,,32,1,4.000000e+000,1.472473e-003,0.000000e+000,0,,0,