File: Experimental Raw Data/MFn1 VRM/Linear Regression/MFn1_VRMac_35K_750s.dc.dat
[Header]
TITLE,MPMS DC Measurement
BYAPP,MPMS Measurement,2.1,Summary
FILEOPENTIME, 1524344008.832000 4/21/2018, 2:53:28 PM

INFO, APPNAME, MPMS MultiVu Application, Revision 1.61,  Build 082

INFO, NAME, MFn1
INFO, WEIGHT, 1.000
INFO, AREA, 1.000
INFO, LENGTH, 1.000
INFO, SHAPE, 0
INFO, COMMENT,
INFO, SEQUENCE FILE: VRMac_35K_750s_VRMde_35Klinear.seq


INFO, BACKGROUND DATA FILE:, None


STARTUPAXIS,X,4,LINEAR,AUTO,0.000000,0.000000
STARTUPAXIS,Y1,5,LINEAR,AUTO,0.000000,0.000000


STARTUPGROUP,Longitudinal
FIELDGROUP,Longitudinal,1,2,3,4,5,6,7,8,9,15,16,17,18,27,28
FIELDGROUP,Transverse,1,2,3,4,10,11,12,13,14,19,20,21,22,27,28

PLOT_APPEARANCE,ALL,HORZ_GRID_ON,VERT_GRID_ON,MARKERS_AND_LINES

[Data]
Time,Comment,Field (Oe),Temperature (K),Long Moment (emu),Long Scan Std Dev,Long Algorithm,Long Reg Fit,Long Percent Error (%),Trans Moment (emu),Trans Scan Std Dev,Trans Algorithm,Trans Reg Fit,Trans Percent Error (%),Long Moment [w/o ABS] (emu),Long Scan Std Dev [w/o ABS],Long Reg Fit [w/o ABS],Long Percent Error [w/o ABS] (%),Trans Moment [w/o ABS] (emu),Trans Scan Std Dev [w/o ABS],Trans Reg Fit [w/o ABS],Trans Percent Error [w/o ABS] (%),Points per Scan,Scans per Measurement,Scan Length (cm),Delta Temp (K),Rot Position (deg),Error,EC Comp. Running,Using ABS,
1524344008.830,,0.000000e+000,3.499793e+001,-1.741186e-004,0.000000e+000,2,9.323913e-001,0.000000e+000,,,,,,,,,,,,,,32,1,4.000000e+000,6.252289e-003,0.000000e+000,0,,0,
1524344021.582,,0.000000e+000,3.500028e+001,-1.754233e-004,0.000000e+000,2,9.320393e-001,0.000000e+000,,,,,,,,,,,,,,32,1,4.000000e+000,1.560211e-003,0.000000e+000,0,,0,
1524344034.278,,0.000000e+000,3.500028e+001,-1.764142e-004,0.000000e+000,2,9.325179e-001,0.000000e+000,,,,,,,,,,,,,,32,1,4.000000e+000,1.560211e-003,0.000000e+000,0,,0,
1524344046.983,,0.000000e+000,3.500067e+001,-1.771783e-004,0.000000e+000,2,9.319734e-001,0.000000e+000,,,,,,,,,,,,,,32,1,4.000000e+000,7.820129e-004,0.000000e+000,0,,0,
1524344060.638,,0.000000e+000,3.500145e+001,-1.778764e-004,0.000000e+000,2,9.328682e-001,0.000000e+000,,,,,,,,,,,,,,32,1,4.000000e+000,7.781982e-004,0.000000e+000,0,,0,
1524344072.753,,0.000000e+000,3.500028e+001,-1.785041e-004,0.000000e+000,2,9.326423e-001,0.000000e+000,,,,,,,,,,,,,,32,1,4.000000e+000,3.120422e-003,0.000000e+000,0,,0,
1524344085.418,,0.000000e+000,3.499832e+001,-1.792196e-004,0.000000e+000,2,9.326163e-001,0.000000e+000,,,,,,,,,,,,,,32,1,4.000000e+000,7.030487e-003,0.000000e+000,0,,0,
1524344098.116,,0.000000e+000,3.499989e+001,-1.796625e-004,0.000000e+000,2,9.324915e-001,0.000000e+000,,,,,,,,,,,,,,32,1,4.000000e+000,1.016998e-002,0.000000e+000,0,,0,
1524344110.841,,0.000000e+000,3.500185e+001,-1.801356e-004,0.000000e+000,2,9.331328e-001,0.000000e+000,,,,,,,,,,,,,,32,1,4.000000e+000,6.259918e-003,0.000000e+000,0,,0,
1524344123.501,,0.000000e+000,3.499911e+001,-1.806817e-004,0.000000e+000,2,9.333348e-001,0.000000e+000,,,,,,,,,,,,,,32,1,4.000000e+000,7.820129e-004,0.000000e+000,0,,0,
1524344135.994,,0.000000e+000,3.500067e+001,-1.809352e-004,0.000000e+000,2,9.327869e-001,0.000000e+000,,,,,,,,,,,,,,32,1,4.000000e+000,7.820129e-004,0.000000e+000,0,,0,
1524344148.627,,0.000000e+000,3.499911e+001,-1.812489e-004,0.000000e+000,2,9.329867e-001,0.000000e+000,,,,,,,,,,,,,,32,1,4.000000e+000,7.820129e-004,0.000000e+000,0,,0,
1524344161.372,,0.000000e+000,3.499833e+001,-1.816365e-004,0.000000e+000,2,9.329797e-001,0.000000e+000,,,,,,,,,,,,,,32,1,4.000000e+000,7.781982e-004,0.000000e+000,0,,0,
1524344173.952,,0.000000e+000,3.499989e+001,-1.819501e-004,0.000000e+000,2,9.324788e-001,0.000000e+000,,,,,,,,,,,,,,32,1,4.000000e+000,7.781982e-004,0.000000e+000,0,,0,
1524344186.970,,0.000000e+000,3.499794e+001,-1.822256e-004,0.000000e+000,2,9.331934e-001,0.000000e+000,,,,,,,,,,,,,,32,1,4.000000e+000,0.000000e+000,0.000000e+000,0,,0,
1524344199.110,,0.000000e+000,3.500028e+001,-1.825369e-004,0.000000e+000,2,9.335355e-001,0.000000e+000,,,,,,,,,,,,,,32,1,4.000000e+000,1.560211e-003,0.000000e+000,0,,0,
1524344211.780,,0.000000e+000,3.499911e+001,-1.827453e-004,0.000000e+000,2,9.331379e-001,0.000000e+000,,,,,,,,,,,,,,32,1,4.000000e+000,7.820129e-004,0.000000e+000,0,,0,
1524344224.483,,0.000000e+000,3.499793e+001,-1.830563e-004,0.000000e+000,2,9.329793e-001,0.000000e+000,,,,,,,,,,,,,,32,1,4.000000e+000,1.567841e-003,0.000000e+000,0,,0,
1524344237.163,,0.000000e+000,3.499754e+001,-1.833112e-004,0.000000e+000,2,9.338561e-001,0.000000e+000,,,,,,,,,,,,,,32,1,4.000000e+000,7.896423e-004,0.000000e+000,0,,0,
1524344250.113,,0.000000e+000,3.499754e+001,-1.835760e-004,0.000000e+000,2,9.337806e-001,0.000000e+000,,,,,,,,,,,,,,32,1,4.000000e+000,2.349854e-003,0.000000e+000,0,,0,
1524344262.821,,0.000000e+000,3.499989e+001,-1.837478e-004,0.000000e+000,2,9.335628e-001,0.000000e+000,,,,,,,,,,,,,,32,1,4.000000e+000,2.342224e-003,0.000000e+000,0,,0,
1524344275.719,,0.000000e+000,3.499833e+001,-1.841081e-004,0.000000e+000,2,9.336585e-001,0.000000e+000,,,,,,,,,,,,,,32,1,4.000000e+000,7.781982e-004,0.000000e+000,0,,0,
1524344288.179,,0.000000e+000,3.499638e+001,-1.841917e-004,0.000000e+000,2,9.334032e-001,0.000000e+000,,,,,,,,,,,,,,32,1,4.000000e+000,4.688263e-003,0.000000e+000,0,,0,
1524344300.892,,0.000000e+000,3.499833e+001,-1.844848e-004,0.000000e+000,2,9.340901e-001,0.000000e+000,,,,,,,,,,,,,,32,1,4.000000e+000,7.781982e-004,0.000000e+000,0,,0,
1524344313.789,,0.000000e+000,3.499872e+001,-1.846380e-004,0.000000e+000,2,9.338981e-001,0.000000e+000,,,,,,,,,,,,,,32,1,4.000000e+000,1.560211e-003,0.000000e+000,0,,0,
1524344326.250,,0.000000e+000,3.499872e+001,-1.847885e-004,0.000000e+000,2,9.332758e-001,0.000000e+000,,,,,,,,,,,,,,32,1,4.000000e+000,1.560211e-003,0.000000e+000,0,,0,
1524344339.277,,0.000000e+000,3.499989e+001,-1.849370e-004,0.000000e+000,2,9.338354e-001,0.000000e+000,,,,,,,,,,,,,,32,1,4.000000e+000,3.898621e-003,0.000000e+000,0,,0,
1524344351.642,,0.000000e+000,3.499950e+001,-1.852048e-004,0.000000e+000,2,9.344550e-001,0.000000e+000,,,,,,,,,,,,,,32,1,4.000000e+000,4.688263e-003,0.000000e+000,0,,0,
1524344364.223,,0.000000e+000,3.499481e+001,-1.852581e-004,0.000000e+000,2,9.342867e-001,0.000000e+000,,,,,,,,,,,,,,32,1,4.000000e+000,0.000000e+000,0.000000e+000,0,,0,
1524344376.888,,0.000000e+000,3.499833e+001,-1.854700e-004,0.000000e+000,2,9.342774e-001,0.000000e+000,,,,,,,,,,,,,,32,1,4.000000e+000,7.781982e-004,0.000000e+000,0,,0,
1524344389.628,,0.000000e+000,3.499871e+001,-1.855765e-004,0.000000e+000,2,9.345117e-001,0.000000e+000,,,,,,,,,,,,,,32,1,4.000000e+000,3.128052e-003,0.000000e+000,0,,0,
1524344402.488,,0.000000e+000,3.499676e+001,-1.857990e-004,0.000000e+000,2,9.346466e-001,0.000000e+000,,,,,,,,,,,,,,32,1,4.000000e+000,7.820129e-004,0.000000e+000,0,,0,
1524344415.233,,0.000000e+000,3.499832e+001,-1.858956e-004,0.000000e+000,2,9.344118e-001,0.000000e+000,,,,,,,,,,,,,,32,1,4.000000e+000,3.910065e-003,0.000000e+000,0,,0,
1524344427.931,,0.000000e+000,3.499911e+001,-1.861307e-004,0.000000e+000,2,9.343302e-001,0.000000e+000,,,,,,,,,,,,,,32,1,4.000000e+000,2.338409e-003,0.000000e+000,0,,0,
1524344440.714,,0.000000e+000,3.499872e+001,-1.861938e-004,0.000000e+000,2,9.350564e-001,0.000000e+000,,,,,,,,,,,,,,32,1,4.000000e+000,1.560211e-003,0.000000e+000,0,,0,
1524344453.364,,0.000000e+000,3.500067e+001,-1.863083e-004,0.000000e+000,2,9.349695e-001,0.000000e+000,,,,,,,,,,,,,,32,1,4.000000e+000,3.910065e-003,0.000000e+000,0,,0,
1524344466.107,,0.000000e+000,3.499833e+001,-1.865102e-004,0.000000e+000,2,9.350189e-001,0.000000e+000,,,,,,,,,,,,,,32,1,4.000000e+000,2.349854e-003,0.000000e+000,0,,0,
1524344478.777,,0.000000e+000,3.499793e+001,-1.865907e-004,0.000000e+000,2,9.350226e-001,0.000000e+000,,,,,,,,,,,,,,32,1,4.000000e+000,1.567841e-003,0.000000e+000,0,,0,
1524344491.412,,0.000000e+000,3.499872e+001,-1.867365e-004,0.000000e+000,2,9.350263e-001,0.000000e+000,,,,,,,,,,,,,,32,1,4.000000e+000,0.000000e+000,0.000000e+000,0,,0,
1524344504.137,,0.000000e+000,3.499833e+001,-1.868596e-004,0.000000e+000,2,9.351630e-001,0.000000e+000,,,,,,,,,,,,,,32,1,4.000000e+000,7.781982e-004,0.000000e+000,0,,0,
1524344516.817,,0.000000e+000,3.499794e+001,-1.869713e-004,0.000000e+000,2,9.355012e-001,0.000000e+000,,,,,,,,,,,,,,32,1,4.000000e+000,0.000000e+000,0.000000e+000,0,,0,
1524344529.497,,0.000000e+000,3.499872e+001,-1.871491e-004,0.000000e+000,2,9.354827e-001,0.000000e+000,,,,,,,,,,,,,,32,1,4.000000e+000,1.560211e-003,0.000000e+000,0,,0,
1524344542.185,,0.000000e+000,3.499833e+001,-1.872348e-004,0.000000e+000,2,9.356445e-001,0.000000e+000,,,,,,,,,,,,,,32,1,4.000000e+000,2.349854e-003,0.000000e+000,0,,0,
1524344554.848,,0.000000e+000,3.499793e+001,-1.873578e-004,0.000000e+000,2,9.353665e-001,0.000000e+000,,,,,,,,,,,,,,32,1,4.000000e+000,1.567841e-003,0.000000e+000,0,,0,
1524344567.560,,0.000000e+000,3.499793e+001,-1.875914e-004,0.000000e+000,2,9.352561e-001,0.000000e+000,,,,,,,,,,,,,,32,1,4.000000e+000,1.567841e-003,0.000000e+000,0,,0,
1524344580.256,,0.000000e+000,3.499872e+001,-1.877025e-004,0.000000e+000,2,9.352368e-001,0.000000e+000,,,,,,,,,,,,,,32,1,4.000000e+000,0.000000e+000,0.000000e+000,0,,0,
1524344592.776,,0.000000e+000,3.499793e+001,-1.877205e-004,0.000000e+000,2,9.354166e-001,0.000000e+000,,,,,,,,,,,,,,32,1,4.000000e+000,1.567841e-003,0.000000e+000,0,,0,
1524344605.471,,0.000000e+000,3.499833e+001,-1.877663e-004,0.000000e+000,2,9.360629e-001,0.000000e+000,,,,,,,,,,,,,,32,1,4.000000e+000,2.349854e-003,0.000000e+000,0,,0,
1524344618.291,,0.000000e+000,3.499872e+001,-1.880026e-004,0.000000e+000,2,9.358579e-001,0.000000e+000,,,,,,,,,,,,,,32,1,4.000000e+000,1.560211e-003,0.000000e+000,0,,0,
1524344630.839,,0.000000e+000,3.499833e+001,-1.880393e-004,0.000000e+000,2,9.353540e-001,0.000000e+000,,,,,,,,,,,,,,32,1,4.000000e+000,7.781982e-004,0.000000e+000,0,,0,
1524344643.682,,0.000000e+000,3.499833e+001,-1.881068e-004,0.000000e+000,2,9.355692e-001,0.000000e+000,,,,,,,,,,,,,,32,1,4.000000e+000,2.349854e-003,0.000000e+000,0,,0,
1524344656.339,,0.000000e+000,3.499793e+001,-1.882021e-004,0.000000e+000,2,9.358892e-001,0.000000e+000,,,,,,,,,,,,,,32,1,4.000000e+000,1.567841e-003,0.000000e+000,0,,0,
1524344668.919,,0.000000e+000,3.499793e+001,-1.882506e-004,0.000000e+000,2,9.358035e-001,0.000000e+000,,,,,,,,,,,,,,32,1,4.000000e+000,1.567841e-003,0.000000e+000,0,,0,
1524344681.615,,0.000000e+000,3.499833e+001,-1.884403e-004,0.000000e+000,2,9.358373e-001,0.000000e+000,,,,,,,,,,,,,,32,1,4.000000e+000,7.781982e-004,0.000000e+000,0,,0,