File: Experimental Raw Data/MFn1 VRM/Linear Regression/MFn1_VRMac_35K_750s_VRMde_35Klinear.dc.dat
[Header]
TITLE,MPMS DC Measurement
BYAPP,MPMS Measurement,2.1,Summary
FILEOPENTIME, 1524344734.480000 4/21/2018, 3:05:34 PM

INFO, APPNAME, MPMS MultiVu Application, Revision 1.61,  Build 082

INFO, NAME, MFn1
INFO, WEIGHT, 1.000
INFO, AREA, 1.000
INFO, LENGTH, 1.000
INFO, SHAPE, 0
INFO, COMMENT,
INFO, SEQUENCE FILE: VRMac_35K_750s_VRMde_35Klinear.seq


INFO, BACKGROUND DATA FILE:, None


STARTUPAXIS,X,4,LINEAR,AUTO,0.000000,0.000000
STARTUPAXIS,Y1,5,LINEAR,AUTO,0.000000,0.000000


STARTUPGROUP,Longitudinal
FIELDGROUP,Longitudinal,1,2,3,4,5,6,7,8,9,15,16,17,18,27,28
FIELDGROUP,Transverse,1,2,3,4,10,11,12,13,14,19,20,21,22,27,28

PLOT_APPEARANCE,ALL,HORZ_GRID_ON,VERT_GRID_ON,MARKERS_AND_LINES

[Data]
Time,Comment,Field (Oe),Temperature (K),Long Moment (emu),Long Scan Std Dev,Long Algorithm,Long Reg Fit,Long Percent Error (%),Trans Moment (emu),Trans Scan Std Dev,Trans Algorithm,Trans Reg Fit,Trans Percent Error (%),Long Moment [w/o ABS] (emu),Long Scan Std Dev [w/o ABS],Long Reg Fit [w/o ABS],Long Percent Error [w/o ABS] (%),Trans Moment [w/o ABS] (emu),Trans Scan Std Dev [w/o ABS],Trans Reg Fit [w/o ABS],Trans Percent Error [w/o ABS] (%),Points per Scan,Scans per Measurement,Scan Length (cm),Delta Temp (K),Rot Position (deg),Error,EC Comp. Running,Using ABS,
1524344734.478,,0.000000e+000,3.499676e+001,-7.558127e-006,0.000000e+000,2,9.001343e-001,0.000000e+000,,,,,,,,,,,,,,32,1,4.000000e+000,7.820129e-004,0.000000e+000,0,,0,
1524344760.023,,0.000000e+000,3.499754e+001,-5.105929e-006,0.000000e+000,2,8.383102e-001,0.000000e+000,,,,,,,,,,,,,,32,1,4.000000e+000,7.896423e-004,0.000000e+000,0,,0,
1524344785.399,,0.000000e+000,3.500067e+001,-3.661224e-006,0.000000e+000,2,7.792572e-001,0.000000e+000,,,,,,,,,,,,,,32,1,4.000000e+000,2.338409e-003,0.000000e+000,0,,0,
1524344810.824,,0.000000e+000,3.499872e+001,-2.571218e-006,0.000000e+000,2,6.825923e-001,0.000000e+000,,,,,,,,,,,,,,32,1,4.000000e+000,0.000000e+000,0.000000e+000,0,,0,
1524344836.149,,0.000000e+000,3.499754e+001,-1.734545e-006,0.000000e+000,2,5.184007e-001,0.000000e+000,,,,,,,,,,,,,,32,1,4.000000e+000,2.349854e-003,0.000000e+000,0,,0,
1524344861.787,,0.000000e+000,3.499871e+001,-1.089713e-006,0.000000e+000,2,2.601427e-001,0.000000e+000,,,,,,,,,,,,,,32,1,4.000000e+000,3.128052e-003,0.000000e+000,0,,0,
1524344887.165,,0.000000e+000,3.499872e+001,-7.080309e-007,0.000000e+000,2,0.000000e+000,0.000000e+000,,,,,,,,,,,,,,32,1,4.000000e+000,1.560211e-003,0.000000e+000,0,,0,
1524344912.266,,0.000000e+000,3.499793e+001,-2.011031e-008,0.000000e+000,2,0.000000e+000,0.000000e+000,,,,,,,,,,,,,,32,1,4.000000e+000,1.567841e-003,0.000000e+000,0,,0,
1524344937.556,,0.000000e+000,3.499833e+001,3.129427e-007,0.000000e+000,2,0.000000e+000,0.000000e+000,,,,,,,,,,,,,,32,1,4.000000e+000,7.781982e-004,0.000000e+000,0,,0,
1524344962.879,,0.000000e+000,3.499754e+001,6.758609e-007,0.000000e+000,2,0.000000e+000,0.000000e+000,,,,,,,,,,,,,,32,1,4.000000e+000,2.349854e-003,0.000000e+000,0,,0,
1524344988.252,,0.000000e+000,3.499715e+001,9.647672e-007,0.000000e+000,2,1.256599e-001,0.000000e+000,,,,,,,,,,,,,,32,1,4.000000e+000,3.128052e-003,0.000000e+000,0,,0,
1524345013.625,,0.000000e+000,3.500067e+001,1.325760e-006,0.000000e+000,2,3.689259e-001,0.000000e+000,,,,,,,,,,,,,,32,1,4.000000e+000,3.910065e-003,0.000000e+000,0,,0,
1524345039.002,,0.000000e+000,3.499715e+001,1.564800e-006,0.000000e+000,2,4.629676e-001,0.000000e+000,,,,,,,,,,,,,,32,1,4.000000e+000,3.128052e-003,0.000000e+000,0,,0,
1524345064.403,,0.000000e+000,3.499911e+001,1.838519e-006,0.000000e+000,2,5.454975e-001,0.000000e+000,,,,,,,,,,,,,,32,1,4.000000e+000,2.338409e-003,0.000000e+000,0,,0,
1524345090.568,,0.000000e+000,3.499833e+001,1.983765e-006,0.000000e+000,2,5.682726e-001,0.000000e+000,,,,,,,,,,,,,,32,1,4.000000e+000,2.349854e-003,0.000000e+000,0,,0,
1524345115.346,,0.000000e+000,3.499833e+001,2.056010e-006,0.000000e+000,2,5.885973e-001,0.000000e+000,,,,,,,,,,,,,,32,1,4.000000e+000,2.349854e-003,0.000000e+000,0,,0,
1524345140.924,,0.000000e+000,3.499911e+001,2.341812e-006,0.000000e+000,2,6.518623e-001,0.000000e+000,,,,,,,,,,,,,,32,1,4.000000e+000,7.820129e-004,0.000000e+000,0,,0,
1524345166.167,,0.000000e+000,3.499872e+001,2.471071e-006,0.000000e+000,2,6.695001e-001,0.000000e+000,,,,,,,,,,,,,,32,1,4.000000e+000,0.000000e+000,0.000000e+000,0,,0,
1524345191.167,,0.000000e+000,3.499872e+001,2.672407e-006,0.000000e+000,2,6.924449e-001,0.000000e+000,,,,,,,,,,,,,,32,1,4.000000e+000,0.000000e+000,0.000000e+000,0,,0,
1524345216.380,,0.000000e+000,3.499911e+001,2.782945e-006,0.000000e+000,2,6.927752e-001,0.000000e+000,,,,,,,,,,,,,,32,1,4.000000e+000,7.820129e-004,0.000000e+000,0,,0,
1524345241.758,,0.000000e+000,3.499872e+001,2.944124e-006,0.000000e+000,2,7.238556e-001,0.000000e+000,,,,,,,,,,,,,,32,1,4.000000e+000,1.560211e-003,0.000000e+000,0,,0,
1524345267.751,,0.000000e+000,3.499911e+001,3.081552e-006,0.000000e+000,2,7.256830e-001,0.000000e+000,,,,,,,,,,,,,,32,1,4.000000e+000,7.820129e-004,0.000000e+000,0,,0,
1524345293.254,,0.000000e+000,3.499872e+001,3.208297e-006,0.000000e+000,2,7.369524e-001,0.000000e+000,,,,,,,,,,,,,,32,1,4.000000e+000,1.560211e-003,0.000000e+000,0,,0,
1524345318.659,,0.000000e+000,3.499833e+001,3.306134e-006,0.000000e+000,2,7.405017e-001,0.000000e+000,,,,,,,,,,,,,,32,1,4.000000e+000,7.781982e-004,0.000000e+000,0,,0,
1524345344.019,,0.000000e+000,3.499872e+001,3.372064e-006,0.000000e+000,2,7.562280e-001,0.000000e+000,,,,,,,,,,,,,,32,1,4.000000e+000,1.560211e-003,0.000000e+000,0,,0,
1524345369.402,,0.000000e+000,3.499989e+001,3.485212e-006,0.000000e+000,2,7.624829e-001,0.000000e+000,,,,,,,,,,,,,,32,1,4.000000e+000,2.342224e-003,0.000000e+000,0,,0,
1524345394.773,,0.000000e+000,3.499833e+001,3.579115e-006,0.000000e+000,2,7.624708e-001,0.000000e+000,,,,,,,,,,,,,,32,1,4.000000e+000,7.781982e-004,0.000000e+000,0,,0,
1524345420.075,,0.000000e+000,3.499833e+001,3.693230e-006,0.000000e+000,2,7.704920e-001,0.000000e+000,,,,,,,,,,,,,,32,1,4.000000e+000,7.781982e-004,0.000000e+000,0,,0,
1524345445.536,,0.000000e+000,3.499911e+001,3.768187e-006,0.000000e+000,2,7.774642e-001,0.000000e+000,,,,,,,,,,,,,,32,1,4.000000e+000,7.820129e-004,0.000000e+000,0,,0,
1524345470.911,,0.000000e+000,3.499872e+001,3.862953e-006,0.000000e+000,2,7.786646e-001,0.000000e+000,,,,,,,,,,,,,,32,1,4.000000e+000,1.560211e-003,0.000000e+000,0,,0,
1524345496.237,,0.000000e+000,3.499833e+001,3.929738e-006,0.000000e+000,2,7.784022e-001,0.000000e+000,,,,,,,,,,,,,,32,1,4.000000e+000,7.781982e-004,0.000000e+000,0,,0,
1524345521.664,,0.000000e+000,3.499833e+001,3.985694e-006,0.000000e+000,2,7.803100e-001,0.000000e+000,,,,,,,,,,,,,,32,1,4.000000e+000,7.781982e-004,0.000000e+000,0,,0,
1524345547.045,,0.000000e+000,3.499911e+001,4.043925e-006,0.000000e+000,2,7.944162e-001,0.000000e+000,,,,,,,,,,,,,,32,1,4.000000e+000,2.338409e-003,0.000000e+000,0,,0,
1524345572.843,,0.000000e+000,3.499833e+001,4.113322e-006,0.000000e+000,2,7.929220e-001,0.000000e+000,,,,,,,,,,,,,,32,1,4.000000e+000,7.781982e-004,0.000000e+000,0,,0,
1524345597.296,,0.000000e+000,3.500028e+001,4.158950e-006,0.000000e+000,2,8.010073e-001,0.000000e+000,,,,,,,,,,,,,,32,1,4.000000e+000,1.560211e-003,0.000000e+000,0,,0,
1524345622.579,,0.000000e+000,3.499793e+001,4.173438e-006,0.000000e+000,2,7.980021e-001,0.000000e+000,,,,,,,,,,,,,,32,1,4.000000e+000,1.567841e-003,0.000000e+000,0,,0,
1524345648.456,,0.000000e+000,3.499833e+001,4.313647e-006,0.000000e+000,2,8.003930e-001,0.000000e+000,,,,,,,,,,,,,,32,1,4.000000e+000,2.349854e-003,0.000000e+000,0,,0,
1524345673.364,,0.000000e+000,3.499872e+001,4.354846e-006,0.000000e+000,2,8.062147e-001,0.000000e+000,,,,,,,,,,,,,,32,1,4.000000e+000,1.560211e-003,0.000000e+000,0,,0,
1524345698.300,,0.000000e+000,3.499911e+001,4.408694e-006,0.000000e+000,2,8.011905e-001,0.000000e+000,,,,,,,,,,,,,,32,1,4.000000e+000,7.820129e-004,0.000000e+000,0,,0,
1524345723.685,,0.000000e+000,3.499833e+001,4.442459e-006,0.000000e+000,2,8.042805e-001,0.000000e+000,,,,,,,,,,,,,,32,1,4.000000e+000,7.781982e-004,0.000000e+000,0,,0,
1524345749.070,,0.000000e+000,3.499833e+001,4.482505e-006,0.000000e+000,2,8.119556e-001,0.000000e+000,,,,,,,,,,,,,,32,1,4.000000e+000,7.781982e-004,0.000000e+000,0,,0,
1524345774.343,,0.000000e+000,3.499793e+001,4.507714e-006,0.000000e+000,2,8.152539e-001,0.000000e+000,,,,,,,,,,,,,,32,1,4.000000e+000,1.567841e-003,0.000000e+000,0,,0,
1524345799.704,,0.000000e+000,3.499872e+001,4.570604e-006,0.000000e+000,2,8.078830e-001,0.000000e+000,,,,,,,,,,,,,,32,1,4.000000e+000,0.000000e+000,0.000000e+000,0,,0,
1524345824.646,,0.000000e+000,3.499794e+001,4.601108e-006,0.000000e+000,2,8.082830e-001,0.000000e+000,,,,,,,,,,,,,,32,1,4.000000e+000,0.000000e+000,0.000000e+000,0,,0,
1524345850.047,,0.000000e+000,3.499950e+001,4.680524e-006,0.000000e+000,2,8.223569e-001,0.000000e+000,,,,,,,,,,,,,,32,1,4.000000e+000,1.560211e-003,0.000000e+000,0,,0,
1524345875.427,,0.000000e+000,3.499911e+001,4.700802e-006,0.000000e+000,2,8.201197e-001,0.000000e+000,,,,,,,,,,,,,,32,1,4.000000e+000,7.820129e-004,0.000000e+000,0,,0,
1524345900.818,,0.000000e+000,3.499950e+001,4.755771e-006,0.000000e+000,2,8.109842e-001,0.000000e+000,,,,,,,,,,,,,,32,1,4.000000e+000,3.120422e-003,0.000000e+000,0,,0,
1524345926.198,,0.000000e+000,3.499911e+001,4.801213e-006,0.000000e+000,2,8.139991e-001,0.000000e+000,,,,,,,,,,,,,,32,1,4.000000e+000,2.338409e-003,0.000000e+000,0,,0,
1524345951.763,,0.000000e+000,3.499833e+001,4.807529e-006,0.000000e+000,2,8.224688e-001,0.000000e+000,,,,,,,,,,,,,,32,1,4.000000e+000,2.349854e-003,0.000000e+000,0,,0,
1524345977.756,,0.000000e+000,3.499950e+001,4.885363e-006,0.000000e+000,2,8.225800e-001,0.000000e+000,,,,,,,,,,,,,,32,1,4.000000e+000,0.000000e+000,0.000000e+000,0,,0,
1524346003.887,,0.000000e+000,3.499793e+001,4.915355e-006,0.000000e+000,2,8.187582e-001,0.000000e+000,,,,,,,,,,,,,,32,1,4.000000e+000,1.567841e-003,0.000000e+000,0,,0,
1524346029.217,,0.000000e+000,3.499950e+001,4.917334e-006,0.000000e+000,2,8.206671e-001,0.000000e+000,,,,,,,,,,,,,,32,1,4.000000e+000,1.560211e-003,0.000000e+000,0,,0,
1524346054.595,,0.000000e+000,3.499911e+001,4.976616e-006,0.000000e+000,2,8.252637e-001,0.000000e+000,,,,,,,,,,,,,,32,1,4.000000e+000,7.820129e-004,0.000000e+000,0,,0,
1524346079.788,,0.000000e+000,3.499872e+001,4.990814e-006,0.000000e+000,2,8.251896e-001,0.000000e+000,,,,,,,,,,,,,,32,1,4.000000e+000,0.000000e+000,0.000000e+000,0,,0,
1524346105.111,,0.000000e+000,3.499793e+001,5.053458e-006,0.000000e+000,2,8.292378e-001,0.000000e+000,,,,,,,,,,,,,,32,1,4.000000e+000,1.567841e-003,0.000000e+000,0,,0,
1524346130.551,,0.000000e+000,3.499989e+001,5.111413e-006,0.000000e+000,2,8.355476e-001,0.000000e+000,,,,,,,,,,,,,,32,1,4.000000e+000,7.781982e-004,0.000000e+000,0,,0,
1524346155.639,,0.000000e+000,3.499950e+001,5.062707e-006,0.000000e+000,2,8.306800e-001,0.000000e+000,,,,,,,,,,,,,,32,1,4.000000e+000,1.560211e-003,0.000000e+000,0,,0,
1524346180.949,,0.000000e+000,3.499833e+001,5.111420e-006,0.000000e+000,2,8.282610e-001,0.000000e+000,,,,,,,,,,,,,,32,1,4.000000e+000,2.349854e-003,0.000000e+000,0,,0,
1524346206.092,,0.000000e+000,3.499833e+001,5.153224e-006,0.000000e+000,2,8.284377e-001,0.000000e+000,,,,,,,,,,,,,,32,1,4.000000e+000,7.781982e-004,0.000000e+000,0,,0,
1524346231.165,,0.000000e+000,3.500028e+001,5.169829e-006,0.000000e+000,2,8.297330e-001,0.000000e+000,,,,,,,,,,,,,,32,1,4.000000e+000,0.000000e+000,0.000000e+000,0,,0,
1524346256.545,,0.000000e+000,3.499677e+001,5.214810e-006,0.000000e+000,2,8.324079e-001,0.000000e+000,,,,,,,,,,,,,,32,1,4.000000e+000,5.470276e-003,0.000000e+000,0,,0,
1524346281.691,,0.000000e+000,3.499872e+001,5.237422e-006,0.000000e+000,2,8.321350e-001,0.000000e+000,,,,,,,,,,,,,,32,1,4.000000e+000,0.000000e+000,0.000000e+000,0,,0,
1524346307.594,,0.000000e+000,3.500106e+001,5.245473e-006,0.000000e+000,2,8.327050e-001,0.000000e+000,,,,,,,,,,,,,,32,1,4.000000e+000,3.128052e-003,0.000000e+000,0,,0,
1524346332.984,,0.000000e+000,3.499872e+001,5.272092e-006,0.000000e+000,2,8.329421e-001,0.000000e+000,,,,,,,,,,,,,,32,1,4.000000e+000,0.000000e+000,0.000000e+000,0,,0,
1524346358.132,,0.000000e+000,3.499911e+001,5.285329e-006,0.000000e+000,2,8.303617e-001,0.000000e+000,,,,,,,,,,,,,,32,1,4.000000e+000,2.338409e-003,0.000000e+000,0,,0,
1524346382.732,,0.000000e+000,3.499911e+001,5.329610e-006,0.000000e+000,2,8.325075e-001,0.000000e+000,,,,,,,,,,,,,,32,1,4.000000e+000,7.820129e-004,0.000000e+000,0,,0,
1524346408.103,,0.000000e+000,3.499911e+001,5.344530e-006,0.000000e+000,2,8.315126e-001,0.000000e+000,,,,,,,,,,,,,,32,1,4.000000e+000,2.338409e-003,0.000000e+000,0,,0,
1524346433.463,,0.000000e+000,3.499950e+001,5.378995e-006,0.000000e+000,2,8.315207e-001,0.000000e+000,,,,,,,,,,,,,,32,1,4.000000e+000,0.000000e+000,0.000000e+000,0,,0,
1524346458.886,,0.000000e+000,3.499833e+001,5.428979e-006,0.000000e+000,2,8.347639e-001,0.000000e+000,,,,,,,,,,,,,,32,1,4.000000e+000,7.781982e-004,0.000000e+000,0,,0,
1524346484.319,,0.000000e+000,3.499911e+001,5.453904e-006,0.000000e+000,2,8.351800e-001,0.000000e+000,,,,,,,,,,,,,,32,1,4.000000e+000,7.820129e-004,0.000000e+000,0,,0,
1524346509.632,,0.000000e+000,3.499911e+001,5.451453e-006,0.000000e+000,2,8.379524e-001,0.000000e+000,,,,,,,,,,,,,,32,1,4.000000e+000,7.820129e-004,0.000000e+000,0,,0,
1524346534.727,,0.000000e+000,3.499833e+001,5.441124e-006,0.000000e+000,2,8.343760e-001,0.000000e+000,,,,,,,,,,,,,,32,1,4.000000e+000,2.349854e-003,0.000000e+000,0,,0,
1524346559.892,,0.000000e+000,3.499599e+001,5.473431e-006,0.000000e+000,2,8.388735e-001,0.000000e+000,,,,,,,,,,,,,,32,1,4.000000e+000,3.910065e-003,0.000000e+000,0,,0,
1524346585.753,,0.000000e+000,3.499872e+001,5.468642e-006,0.000000e+000,2,8.418690e-001,0.000000e+000,,,,,,,,,,,,,,32,1,4.000000e+000,1.560211e-003,0.000000e+000,0,,0,
1524346610.918,,0.000000e+000,3.499911e+001,5.477481e-006,0.000000e+000,2,8.400980e-001,0.000000e+000,,,,,,,,,,,,,,32,1,4.000000e+000,7.820129e-004,0.000000e+000,0,,0,
1524346636.428,,0.000000e+000,3.499872e+001,5.473267e-006,0.000000e+000,2,8.356909e-001,0.000000e+000,,,,,,,,,,,,,,32,1,4.000000e+000,1.560211e-003,0.000000e+000,0,,0,
1524346662.079,,0.000000e+000,3.500028e+001,5.559629e-006,0.000000e+000,2,8.375258e-001,0.000000e+000,,,,,,,,,,,,,,32,1,4.000000e+000,1.560211e-003,0.000000e+000,0,,0,
1524346686.717,,0.000000e+000,3.499872e+001,5.551640e-006,0.000000e+000,2,8.344649e-001,0.000000e+000,,,,,,,,,,,,,,32,1,4.000000e+000,1.560211e-003,0.000000e+000,0,,0,
1524346712.029,,0.000000e+000,3.499638e+001,5.586942e-006,0.000000e+000,2,8.406879e-001,0.000000e+000,,,,,,,,,,,,,,32,1,4.000000e+000,4.688263e-003,0.000000e+000,0,,0,
1524346737.412,,0.000000e+000,3.499911e+001,5.548480e-006,0.000000e+000,2,8.343745e-001,0.000000e+000,,,,,,,,,,,,,,32,1,4.000000e+000,7.820129e-004,0.000000e+000,0,,0,
1524346762.885,,0.000000e+000,3.499833e+001,5.593661e-006,0.000000e+000,2,8.406669e-001,0.000000e+000,,,,,,,,,,,,,,32,1,4.000000e+000,7.781982e-004,0.000000e+000,0,,0,
1524346788.451,,0.000000e+000,3.499872e+001,5.640792e-006,0.000000e+000,2,8.417545e-001,0.000000e+000,,,,,,,,,,,,,,32,1,4.000000e+000,0.000000e+000,0.000000e+000,0,,0,
1524346813.463,,0.000000e+000,3.499793e+001,5.671015e-006,0.000000e+000,2,8.459368e-001,0.000000e+000,,,,,,,,,,,,,,32,1,4.000000e+000,3.131866e-003,0.000000e+000,0,,0,
1524346838.539,,0.000000e+000,3.499794e+001,5.622758e-006,0.000000e+000,2,8.418862e-001,0.000000e+000,,,,,,,,,,,,,,32,1,4.000000e+000,0.000000e+000,0.000000e+000,0,,0,
1524346863.537,,0.000000e+000,3.499950e+001,5.680149e-006,0.000000e+000,2,8.425341e-001,0.000000e+000,,,,,,,,,,,,,,32,1,4.000000e+000,0.000000e+000,0.000000e+000,0,,0,
1524346889.402,,0.000000e+000,3.499872e+001,5.739340e-006,0.000000e+000,2,8.449267e-001,0.000000e+000,,,,,,,,,,,,,,32,1,4.000000e+000,1.560211e-003,0.000000e+000,0,,0,
1524346914.760,,0.000000e+000,3.499911e+001,5.705892e-006,0.000000e+000,2,8.426072e-001,0.000000e+000,,,,,,,,,,,,,,32,1,4.000000e+000,7.820129e-004,0.000000e+000,0,,0,
1524346940.243,,0.000000e+000,3.499872e+001,5.739042e-006,0.000000e+000,2,8.415188e-001,0.000000e+000,,,,,,,,,,,,,,32,1,4.000000e+000,0.000000e+000,0.000000e+000,0,,0,
1524346965.361,,0.000000e+000,3.499833e+001,5.773392e-006,0.000000e+000,2,8.445776e-001,0.000000e+000,,,,,,,,,,,,,,32,1,4.000000e+000,7.781982e-004,0.000000e+000,0,,0,
1524346990.749,,0.000000e+000,3.499519e+001,5.748616e-006,0.000000e+000,2,8.414515e-001,0.000000e+000,,,,,,,,,,,,,,32,1,4.000000e+000,3.910065e-003,0.000000e+000,0,,0,
1524347016.156,,0.000000e+000,3.499950e+001,5.756151e-006,0.000000e+000,2,8.444403e-001,0.000000e+000,,,,,,,,,,,,,,32,1,4.000000e+000,4.688263e-003,0.000000e+000,0,,0,
1524347041.849,,0.000000e+000,3.499872e+001,5.755352e-006,0.000000e+000,2,8.394729e-001,0.000000e+000,,,,,,,,,,,,,,32,1,4.000000e+000,0.000000e+000,0.000000e+000,0,,0,
1524347066.750,,0.000000e+000,3.499715e+001,5.790767e-006,0.000000e+000,2,8.471490e-001,0.000000e+000,,,,,,,,,,,,,,32,1,4.000000e+000,1.571655e-003,0.000000e+000,0,,0,
1524347092.043,,0.000000e+000,3.500028e+001,5.830473e-006,0.000000e+000,2,8.445907e-001,0.000000e+000,,,,,,,,,,,,,,32,1,4.000000e+000,1.560211e-003,0.000000e+000,0,,0,
1524347117.248,,0.000000e+000,3.500067e+001,5.819798e-006,0.000000e+000,2,8.476324e-001,0.000000e+000,,,,,,,,,,,,,,32,1,4.000000e+000,2.338409e-003,0.000000e+000,0,,0,
1524347142.891,,0.000000e+000,3.499833e+001,5.837476e-006,0.000000e+000,2,8.411472e-001,0.000000e+000,,,,,,,,,,,,,,32,1,4.000000e+000,7.781982e-004,0.000000e+000,0,,0,
1524347168.264,,0.000000e+000,3.499833e+001,5.824978e-006,0.000000e+000,2,8.468379e-001,0.000000e+000,,,,,,,,,,,,,,32,1,4.000000e+000,7.781982e-004,0.000000e+000,0,,0,
1524347193.556,,0.000000e+000,3.499989e+001,5.847540e-006,0.000000e+000,2,8.482119e-001,0.000000e+000,,,,,,,,,,,,,,32,1,4.000000e+000,2.342224e-003,0.000000e+000,0,,0,
1524347218.609,,0.000000e+000,3.500106e+001,5.850042e-006,0.000000e+000,2,8.452476e-001,0.000000e+000,,,,,,,,,,,,,,32,1,4.000000e+000,4.692078e-003,0.000000e+000,0,,0,
1524347244.005,,0.000000e+000,3.499833e+001,5.864508e-006,0.000000e+000,2,8.441871e-001,0.000000e+000,,,,,,,,,,,,,,32,1,4.000000e+000,2.349854e-003,0.000000e+000,0,,0,
1524347269.465,,0.000000e+000,3.499950e+001,5.884299e-006,0.000000e+000,2,8.466176e-001,0.000000e+000,,,,,,,,,,,,,,32,1,4.000000e+000,0.000000e+000,0.000000e+000,0,,0,
1524347294.778,,0.000000e+000,3.499872e+001,5.923569e-006,0.000000e+000,2,8.470576e-001,0.000000e+000,,,,,,,,,,,,,,32,1,4.000000e+000,1.560211e-003,0.000000e+000,0,,0,
1524347320.481,,0.000000e+000,3.499833e+001,5.946613e-006,0.000000e+000,2,8.440017e-001,0.000000e+000,,,,,,,,,,,,,,32,1,4.000000e+000,7.781982e-004,0.000000e+000,0,,0,
1524347345.946,,0.000000e+000,3.499950e+001,5.859330e-006,0.000000e+000,2,8.491638e-001,0.000000e+000,,,,,,,,,,,,,,32,1,4.000000e+000,1.560211e-003,0.000000e+000,0,,0,
1524347371.361,,0.000000e+000,3.499872e+001,5.935211e-006,0.000000e+000,2,8.438565e-001,0.000000e+000,,,,,,,,,,,,,,32,1,4.000000e+000,0.000000e+000,0.000000e+000,0,,0,
1524347396.278,,0.000000e+000,3.499833e+001,5.910238e-006,0.000000e+000,2,8.498362e-001,0.000000e+000,,,,,,,,,,,,,,32,1,4.000000e+000,7.781982e-004,0.000000e+000,0,,0,
1524347421.666,,0.000000e+000,3.499872e+001,5.914253e-006,0.000000e+000,2,8.497922e-001,0.000000e+000,,,,,,,,,,,,,,32,1,4.000000e+000,1.560211e-003,0.000000e+000,0,,0,
1524347447.497,,0.000000e+000,3.499872e+001,5.927207e-006,0.000000e+000,2,8.486606e-001,0.000000e+000,,,,,,,,,,,,,,32,1,4.000000e+000,0.000000e+000,0.000000e+000,0,,0,
1524347472.860,,0.000000e+000,3.499872e+001,5.939694e-006,0.000000e+000,2,8.517477e-001,0.000000e+000,,,,,,,,,,,,,,32,1,4.000000e+000,1.560211e-003,0.000000e+000,0,,0,
1524347498.095,,0.000000e+000,3.499872e+001,5.948071e-006,0.000000e+000,2,8.476213e-001,0.000000e+000,,,,,,,,,,,,,,32,1,4.000000e+000,0.000000e+000,0.000000e+000,0,,0,
1524347523.900,,0.000000e+000,3.499950e+001,6.036556e-006,0.000000e+000,2,8.397295e-001,0.000000e+000,,,,,,,,,,,,,,32,1,4.000000e+000,1.560211e-003,0.000000e+000,0,,0,
1524347549.263,,0.000000e+000,3.499833e+001,6.006728e-006,0.000000e+000,2,8.444089e-001,0.000000e+000,,,,,,,,,,,,,,32,1,4.000000e+000,7.781982e-004,0.000000e+000,0,,0,
1524347574.731,,0.000000e+000,3.499911e+001,6.007491e-006,0.000000e+000,2,8.491060e-001,0.000000e+000,,,,,,,,,,,,,,32,1,4.000000e+000,7.820129e-004,0.000000e+000,0,,0,
1524347600.184,,0.000000e+000,3.499872e+001,6.016998e-006,0.000000e+000,2,8.497861e-001,0.000000e+000,,,,,,,,,,,,,,32,1,4.000000e+000,0.000000e+000,0.000000e+000,0,,0,
1524347625.477,,0.000000e+000,3.499911e+001,6.010578e-006,0.000000e+000,2,8.451602e-001,0.000000e+000,,,,,,,,,,,,,,32,1,4.000000e+000,7.820129e-004,0.000000e+000,0,,0,
1524347650.912,,0.000000e+000,3.499911e+001,6.030578e-006,0.000000e+000,2,8.480328e-001,0.000000e+000,,,,,,,,,,,,,,32,1,4.000000e+000,7.820129e-004,0.000000e+000,0,,0,
1524347676.215,,0.000000e+000,3.499911e+001,6.043392e-006,0.000000e+000,2,8.506919e-001,0.000000e+000,,,,,,,,,,,,,,32,1,4.000000e+000,7.820129e-004,0.000000e+000,0,,0,
1524347701.598,,0.000000e+000,3.499950e+001,6.027763e-006,0.000000e+000,2,8.496594e-001,0.000000e+000,,,,,,,,,,,,,,32,1,4.000000e+000,1.560211e-003,0.000000e+000,0,,0,
1524347726.683,,0.000000e+000,3.499911e+001,6.013895e-006,0.000000e+000,2,8.495490e-001,0.000000e+000,,,,,,,,,,,,,,32,1,4.000000e+000,7.820129e-004,0.000000e+000,0,,0,
1524347751.846,,0.000000e+000,3.499872e+001,6.038207e-006,0.000000e+000,2,8.457915e-001,0.000000e+000,,,,,,,,,,,,,,32,1,4.000000e+000,0.000000e+000,0.000000e+000,0,,0,
1524347776.624,,0.000000e+000,3.500028e+001,6.068700e-006,0.000000e+000,2,8.434193e-001,0.000000e+000,,,,,,,,,,,,,,32,1,4.000000e+000,1.560211e-003,0.000000e+000,0,,0,
1524347802.037,,0.000000e+000,3.499911e+001,6.072823e-006,0.000000e+000,2,8.498176e-001,0.000000e+000,,,,,,,,,,,,,,32,1,4.000000e+000,7.820129e-004,0.000000e+000,0,,0,
1524347827.410,,0.000000e+000,3.499872e+001,6.085270e-006,0.000000e+000,2,8.497046e-001,0.000000e+000,,,,,,,,,,,,,,32,1,4.000000e+000,0.000000e+000,0.000000e+000,0,,0,
1524347852.228,,0.000000e+000,3.499911e+001,6.079723e-006,0.000000e+000,2,8.446808e-001,0.000000e+000,,,,,,,,,,,,,,32,1,4.000000e+000,7.820129e-004,0.000000e+000,0,,0,
1524347878.016,,0.000000e+000,3.499872e+001,6.128932e-006,0.000000e+000,2,8.519962e-001,0.000000e+000,,,,,,,,,,,,,,32,1,4.000000e+000,1.560211e-003,0.000000e+000,0,,0,
1524347903.086,,0.000000e+000,3.499911e+001,6.129573e-006,0.000000e+000,2,8.493875e-001,0.000000e+000,,,,,,,,,,,,,,32,1,4.000000e+000,7.820129e-004,0.000000e+000,0,,0,
1524347928.474,,0.000000e+000,3.499754e+001,6.121188e-006,0.000000e+000,2,8.483384e-001,0.000000e+000,,,,,,,,,,,,,,32,1,4.000000e+000,7.896423e-004,0.000000e+000,0,,0,
1524347953.634,,0.000000e+000,3.499911e+001,6.139384e-006,0.000000e+000,2,8.474684e-001,0.000000e+000,,,,,,,,,,,,,,32,1,4.000000e+000,7.820129e-004,0.000000e+000,0,,0,
1524347978.742,,0.000000e+000,3.499989e+001,6.129404e-006,0.000000e+000,2,8.516448e-001,0.000000e+000,,,,,,,,,,,,,,32,1,4.000000e+000,7.781982e-004,0.000000e+000,0,,0,
1524348004.127,,0.000000e+000,3.499911e+001,6.140774e-006,0.000000e+000,2,8.512093e-001,0.000000e+000,,,,,,,,,,,,,,32,1,4.000000e+000,7.820129e-004,0.000000e+000,0,,0,
1524348029.528,,0.000000e+000,3.500067e+001,6.168306e-006,0.000000e+000,2,8.464994e-001,0.000000e+000,,,,,,,,,,,,,,32,1,4.000000e+000,7.820129e-004,0.000000e+000,0,,0,
1524348054.858,,0.000000e+000,3.499950e+001,6.173119e-006,0.000000e+000,2,8.456843e-001,0.000000e+000,,,,,,,,,,,,,,32,1,4.000000e+000,1.560211e-003,0.000000e+000,0,,0,
1524348080.298,,0.000000e+000,3.499872e+001,6.208948e-006,0.000000e+000,2,8.505193e-001,0.000000e+000,,,,,,,,,,,,,,32,1,4.000000e+000,0.000000e+000,0.000000e+000,0,,0,
1524348105.619,,0.000000e+000,3.499911e+001,6.204687e-006,0.000000e+000,2,8.477222e-001,0.000000e+000,,,,,,,,,,,,,,32,1,4.000000e+000,7.820129e-004,0.000000e+000,0,,0,
1524348130.992,,0.000000e+000,3.499872e+001,6.193125e-006,0.000000e+000,2,8.527346e-001,0.000000e+000,,,,,,,,,,,,,,32,1,4.000000e+000,0.000000e+000,0.000000e+000,0,,0,
1524348156.550,,0.000000e+000,3.499989e+001,6.196942e-006,0.000000e+000,2,8.517784e-001,0.000000e+000,,,,,,,,,,,,,,32,1,4.000000e+000,7.781982e-004,0.000000e+000,0,,0,
1524348181.760,,0.000000e+000,3.499911e+001,6.176457e-006,0.000000e+000,2,8.509939e-001,0.000000e+000,,,,,,,,,,,,,,32,1,4.000000e+000,7.820129e-004,0.000000e+000,0,,0,
1524348207.160,,0.000000e+000,3.499911e+001,6.207566e-006,0.000000e+000,2,8.507413e-001,0.000000e+000,,,,,,,,,,,,,,32,1,4.000000e+000,7.820129e-004,0.000000e+000,0,,0,
1524348232.493,,0.000000e+000,3.500028e+001,6.263767e-006,0.000000e+000,2,8.471892e-001,0.000000e+000,,,,,,,,,,,,,,32,1,4.000000e+000,1.560211e-003,0.000000e+000,0,,0,
1524348257.556,,0.000000e+000,3.499911e+001,6.187606e-006,0.000000e+000,2,8.472478e-001,0.000000e+000,,,,,,,,,,,,,,32,1,4.000000e+000,7.820129e-004,0.000000e+000,0,,0,
1524348284.474,,0.000000e+000,3.499911e+001,6.201063e-006,0.000000e+000,2,8.509226e-001,0.000000e+000,,,,,,,,,,,,,,32,1,4.000000e+000,7.820129e-004,0.000000e+000,0,,0,
1524348309.672,,0.000000e+000,3.500106e+001,6.238369e-006,0.000000e+000,2,8.510069e-001,0.000000e+000,,,,,,,,,,,,,,32,1,4.000000e+000,3.128052e-003,0.000000e+000,0,,0,
1524348334.460,,0.000000e+000,3.499872e+001,6.240262e-006,0.000000e+000,2,8.474612e-001,0.000000e+000,,,,,,,,,,,,,,32,1,4.000000e+000,1.560211e-003,0.000000e+000,0,,0,
1524348359.670,,0.000000e+000,3.499872e+001,6.252306e-006,0.000000e+000,2,8.481809e-001,0.000000e+000,,,,,,,,,,,,,,32,1,4.000000e+000,1.560211e-003,0.000000e+000,0,,0,
1524348385.233,,0.000000e+000,3.499715e+001,6.276134e-006,0.000000e+000,2,8.519566e-001,0.000000e+000,,,,,,,,,,,,,,32,1,4.000000e+000,3.128052e-003,0.000000e+000,0,,0,
1524348410.653,,0.000000e+000,3.499950e+001,6.244812e-006,0.000000e+000,2,8.538482e-001,0.000000e+000,,,,,,,,,,,,,,32,1,4.000000e+000,1.560211e-003,0.000000e+000,0,,0,
1524348435.989,,0.000000e+000,3.499911e+001,6.243165e-006,0.000000e+000,2,8.496198e-001,0.000000e+000,,,,,,,,,,,,,,32,1,4.000000e+000,7.820129e-004,0.000000e+000,0,,0,
1524348461.244,,0.000000e+000,3.499559e+001,6.250811e-006,0.000000e+000,2,8.478910e-001,0.000000e+000,,,,,,,,,,,,,,32,1,4.000000e+000,6.259918e-003,0.000000e+000,0,,0,
1524348486.685,,0.000000e+000,3.500067e+001,6.271501e-006,0.000000e+000,2,8.519995e-001,0.000000e+000,,,,,,,,,,,,,,32,1,4.000000e+000,2.338409e-003,0.000000e+000,0,,0,
1524348511.940,,0.000000e+000,3.499872e+001,6.282693e-006,0.000000e+000,2,8.519626e-001,0.000000e+000,,,,,,,,,,,,,,32,1,4.000000e+000,0.000000e+000,0.000000e+000,0,,0,
1524348538.450,,0.000000e+000,3.499833e+001,6.287477e-006,0.000000e+000,2,8.507230e-001,0.000000e+000,,,,,,,,,,,,,,32,1,4.000000e+000,2.349854e-003,0.000000e+000,0,,0,
1524348563.806,,0.000000e+000,3.499950e+001,6.261643e-006,0.000000e+000,2,8.485981e-001,0.000000e+000,,,,,,,,,,,,,,32,1,4.000000e+000,0.000000e+000,0.000000e+000,0,,0,
1524348589.121,,0.000000e+000,3.499911e+001,6.249214e-006,0.000000e+000,2,8.526770e-001,0.000000e+000,,,,,,,,,,,,,,32,1,4.000000e+000,7.820129e-004,0.000000e+000,0,,0,
1524348614.981,,0.000000e+000,3.499872e+001,6.290989e-006,0.000000e+000,2,8.534813e-001,0.000000e+000,,,,,,,,,,,,,,32,1,4.000000e+000,1.560211e-003,0.000000e+000,0,,0,
1524348640.294,,0.000000e+000,3.499950e+001,6.322011e-006,0.000000e+000,2,8.483984e-001,0.000000e+000,,,,,,,,,,,,,,32,1,4.000000e+000,0.000000e+000,0.000000e+000,0,,0,
1524348665.637,,0.000000e+000,3.499989e+001,6.298627e-006,0.000000e+000,2,8.504028e-001,0.000000e+000,,,,,,,,,,,,,,32,1,4.000000e+000,7.781982e-004,0.000000e+000,0,,0,
1524348691.335,,0.000000e+000,3.499833e+001,6.308803e-006,0.000000e+000,2,8.543770e-001,0.000000e+000,,,,,,,,,,,,,,32,1,4.000000e+000,7.781982e-004,0.000000e+000,0,,0,
1524348716.370,,0.000000e+000,3.499911e+001,6.324093e-006,0.000000e+000,2,8.533864e-001,0.000000e+000,,,,,,,,,,,,,,32,1,4.000000e+000,7.820129e-004,0.000000e+000,0,,0,
1524348741.793,,0.000000e+000,3.499911e+001,6.332616e-006,0.000000e+000,2,8.503360e-001,0.000000e+000,,,,,,,,,,,,,,32,1,4.000000e+000,7.820129e-004,0.000000e+000,0,,0,
1524348767.159,,0.000000e+000,3.499833e+001,6.301052e-006,0.000000e+000,2,8.482264e-001,0.000000e+000,,,,,,,,,,,,,,32,1,4.000000e+000,7.781982e-004,0.000000e+000,0,,0,
1524348792.686,,0.000000e+000,3.499833e+001,6.315548e-006,0.000000e+000,2,8.509576e-001,0.000000e+000,,,,,,,,,,,,,,32,1,4.000000e+000,7.781982e-004,0.000000e+000,0,,0,
1524348817.974,,0.000000e+000,3.499872e+001,6.313517e-006,0.000000e+000,2,8.511486e-001,0.000000e+000,,,,,,,,,,,,,,32,1,4.000000e+000,1.560211e-003,0.000000e+000,0,,0,
1524348843.282,,0.000000e+000,3.499950e+001,6.326452e-006,0.000000e+000,2,8.501276e-001,0.000000e+000,,,,,,,,,,,,,,32,1,4.000000e+000,0.000000e+000,0.000000e+000,0,,0,
1524348868.695,,0.000000e+000,3.499754e+001,6.330984e-006,0.000000e+000,2,8.493458e-001,0.000000e+000,,,,,,,,,,,,,,32,1,4.000000e+000,2.349854e-003,0.000000e+000,0,,0,
1524348894.081,,0.000000e+000,3.499872e+001,6.337676e-006,0.000000e+000,2,8.501603e-001,0.000000e+000,,,,,,,,,,,,,,32,1,4.000000e+000,1.560211e-003,0.000000e+000,0,,0,
1524348919.583,,0.000000e+000,3.499872e+001,6.355413e-006,0.000000e+000,2,8.519686e-001,0.000000e+000,,,,,,,,,,,,,,32,1,4.000000e+000,0.000000e+000,0.000000e+000,0,,0,
1524348944.869,,0.000000e+000,3.499911e+001,6.336774e-006,0.000000e+000,2,8.508680e-001,0.000000e+000,,,,,,,,,,,,,,32,1,4.000000e+000,7.820129e-004,0.000000e+000,0,,0,
1524348970.187,,0.000000e+000,3.499793e+001,6.346460e-006,0.000000e+000,2,8.509327e-001,0.000000e+000,,,,,,,,,,,,,,32,1,4.000000e+000,1.567841e-003,0.000000e+000,0,,0,
1524348995.585,,0.000000e+000,3.500028e+001,6.358708e-006,0.000000e+000,2,8.510076e-001,0.000000e+000,,,,,,,,,,,,,,32,1,4.000000e+000,1.560211e-003,0.000000e+000,0,,0,
1524349020.510,,0.000000e+000,3.499833e+001,6.371075e-006,0.000000e+000,2,8.526941e-001,0.000000e+000,,,,,,,,,,,,,,32,1,4.000000e+000,2.349854e-003,0.000000e+000,0,,0,
1524349045.818,,0.000000e+000,3.499872e+001,6.391743e-006,0.000000e+000,2,8.483058e-001,0.000000e+000,,,,,,,,,,,,,,32,1,4.000000e+000,0.000000e+000,0.000000e+000,0,,0,
1524349071.221,,0.000000e+000,3.499911e+001,6.419625e-006,0.000000e+000,2,8.482025e-001,0.000000e+000,,,,,,,,,,,,,,32,1,4.000000e+000,7.820129e-004,0.000000e+000,0,,0,
1524349096.566,,0.000000e+000,3.499911e+001,6.408239e-006,0.000000e+000,2,8.487645e-001,0.000000e+000,,,,,,,,,,,,,,32,1,4.000000e+000,7.820129e-004,0.000000e+000,0,,0,
1524349121.934,,0.000000e+000,3.499950e+001,6.402897e-006,0.000000e+000,2,8.497562e-001,0.000000e+000,,,,,,,,,,,,,,32,1,4.000000e+000,3.120422e-003,0.000000e+000,0,,0,
1524349147.357,,0.000000e+000,3.499872e+001,6.382296e-006,0.000000e+000,2,8.500262e-001,0.000000e+000,,,,,,,,,,,,,,32,1,4.000000e+000,1.560211e-003,0.000000e+000,0,,0,
1524349172.697,,0.000000e+000,3.499950e+001,6.412329e-006,0.000000e+000,2,8.484178e-001,0.000000e+000,,,,,,,,,,,,,,32,1,4.000000e+000,0.000000e+000,0.000000e+000,0,,0,
1524349198.067,,0.000000e+000,3.499911e+001,6.442011e-006,0.000000e+000,2,8.520216e-001,0.000000e+000,,,,,,,,,,,,,,32,1,4.000000e+000,7.820129e-004,0.000000e+000,0,,0,
1524349223.428,,0.000000e+000,3.499911e+001,6.436994e-006,0.000000e+000,2,8.519629e-001,0.000000e+000,,,,,,,,,,,,,,32,1,4.000000e+000,7.820129e-004,0.000000e+000,0,,0,
1524349248.801,,0.000000e+000,3.499911e+001,6.407345e-006,0.000000e+000,2,8.546898e-001,0.000000e+000,,,,,,,,,,,,,,32,1,4.000000e+000,7.820129e-004,0.000000e+000,0,,0,
1524349274.036,,0.000000e+000,3.499950e+001,6.427712e-006,0.000000e+000,2,8.503812e-001,0.000000e+000,,,,,,,,,,,,,,32,1,4.000000e+000,1.560211e-003,0.000000e+000,0,,0,
1524349299.191,,0.000000e+000,3.499950e+001,6.451357e-006,0.000000e+000,2,8.497635e-001,0.000000e+000,,,,,,,,,,,,,,32,1,4.000000e+000,0.000000e+000,0.000000e+000,0,,0,
1524349324.812,,0.000000e+000,3.499950e+001,6.449312e-006,0.000000e+000,2,8.502510e-001,0.000000e+000,,,,,,,,,,,,,,32,1,4.000000e+000,0.000000e+000,0.000000e+000,0,,0,
1524349348.820,,0.000000e+000,3.499872e+001,6.442453e-006,0.000000e+000,2,8.547311e-001,0.000000e+000,,,,,,,,,,,,,,32,1,4.000000e+000,0.000000e+000,0.000000e+000,0,,0,
1524349373.418,,0.000000e+000,3.499950e+001,6.436191e-006,0.000000e+000,2,8.457966e-001,0.000000e+000,,,,,,,,,,,,,,32,1,4.000000e+000,1.560211e-003,0.000000e+000,0,,0,
1524349398.828,,0.000000e+000,3.500028e+001,6.443071e-006,0.000000e+000,2,8.503749e-001,0.000000e+000,,,,,,,,,,,,,,32,1,4.000000e+000,1.560211e-003,0.000000e+000,0,,0,
1524349424.136,,0.000000e+000,3.499950e+001,6.415346e-006,0.000000e+000,2,8.514503e-001,0.000000e+000,,,,,,,,,,,,,,32,1,4.000000e+000,1.560211e-003,0.000000e+000,0,,0,
1524349449.561,,0.000000e+000,3.500028e+001,6.419910e-006,0.000000e+000,2,8.540764e-001,0.000000e+000,,,,,,,,,,,,,,32,1,4.000000e+000,1.560211e-003,0.000000e+000,0,,0,
1524349474.874,,0.000000e+000,3.499872e+001,6.432404e-006,0.000000e+000,2,8.513985e-001,0.000000e+000,,,,,,,,,,,,,,32,1,4.000000e+000,0.000000e+000,0.000000e+000,0,,0,
1524349500.119,,0.000000e+000,3.499989e+001,6.463163e-006,0.000000e+000,2,8.509169e-001,0.000000e+000,,,,,,,,,,,,,,32,1,4.000000e+000,7.781982e-004,0.000000e+000,0,,0,
1524349525.745,,0.000000e+000,3.499911e+001,6.445050e-006,0.000000e+000,2,8.500616e-001,0.000000e+000,,,,,,,,,,,,,,32,1,4.000000e+000,7.820129e-004,0.000000e+000,0,,0,
1524349551.130,,0.000000e+000,3.499833e+001,6.396479e-006,0.000000e+000,2,8.522655e-001,0.000000e+000,,,,,,,,,,,,,,32,1,4.000000e+000,7.781982e-004,0.000000e+000,0,,0,
1524349576.485,,0.000000e+000,3.499911e+001,6.435156e-006,0.000000e+000,2,8.487876e-001,0.000000e+000,,,,,,,,,,,,,,32,1,4.000000e+000,7.820129e-004,0.000000e+000,0,,0,
1524349601.973,,0.000000e+000,3.500028e+001,6.449943e-006,0.000000e+000,2,8.528798e-001,0.000000e+000,,,,,,,,,,,,,,32,1,4.000000e+000,0.000000e+000,0.000000e+000,0,,0,
1524349627.809,,0.000000e+000,3.499833e+001,6.435881e-006,0.000000e+000,2,8.501112e-001,0.000000e+000,,,,,,,,,,,,,,32,1,4.000000e+000,7.781982e-004,0.000000e+000,0,,0,
1524349652.642,,0.000000e+000,3.499950e+001,6.446566e-006,0.000000e+000,2,8.498957e-001,0.000000e+000,,,,,,,,,,,,,,32,1,4.000000e+000,1.560211e-003,0.000000e+000,0,,0,
1524349677.995,,0.000000e+000,3.499911e+001,6.434412e-006,0.000000e+000,2,8.484254e-001,0.000000e+000,,,,,,,,,,,,,,32,1,4.000000e+000,7.820129e-004,0.000000e+000,0,,0,
1524349703.340,,0.000000e+000,3.499911e+001,6.448080e-006,0.000000e+000,2,8.498175e-001,0.000000e+000,,,,,,,,,,,,,,32,1,4.000000e+000,7.820129e-004,0.000000e+000,0,,0,
1524349728.488,,0.000000e+000,3.499833e+001,6.463382e-006,0.000000e+000,2,8.509363e-001,0.000000e+000,,,,,,,,,,,,,,32,1,4.000000e+000,7.781982e-004,0.000000e+000,0,,0,
1524349753.581,,0.000000e+000,3.499911e+001,6.494779e-006,0.000000e+000,2,8.494605e-001,0.000000e+000,,,,,,,,,,,,,,32,1,4.000000e+000,7.820129e-004,0.000000e+000,0,,0,
1524349779.016,,0.000000e+000,3.499872e+001,6.453815e-006,0.000000e+000,2,8.493501e-001,0.000000e+000,,,,,,,,,,,,,,32,1,4.000000e+000,0.000000e+000,0.000000e+000,0,,0,
1524349804.189,,0.000000e+000,3.499911e+001,6.480341e-006,0.000000e+000,2,8.532621e-001,0.000000e+000,,,,,,,,,,,,,,32,1,4.000000e+000,7.820129e-004,0.000000e+000,0,,0,
1524349829.564,,0.000000e+000,3.500145e+001,6.460820e-006,0.000000e+000,2,8.527015e-001,0.000000e+000,,,,,,,,,,,,,,32,1,4.000000e+000,5.470276e-003,0.000000e+000,0,,0,
1524349854.985,,0.000000e+000,3.500145e+001,6.482128e-006,0.000000e+000,2,8.500972e-001,0.000000e+000,,,,,,,,,,,,,,32,1,4.000000e+000,5.470276e-003,0.000000e+000,0,,0,
1524349880.355,,0.000000e+000,3.499989e+001,6.482795e-006,0.000000e+000,2,8.528438e-001,0.000000e+000,,,,,,,,,,,,,,32,1,4.000000e+000,7.781982e-004,0.000000e+000,0,,0,
1524349905.680,,0.000000e+000,3.499950e+001,6.456829e-006,0.000000e+000,2,8.562860e-001,0.000000e+000,,,,,,,,,,,,,,32,1,4.000000e+000,0.000000e+000,0.000000e+000,0,,0,
1524349931.753,,0.000000e+000,3.499911e+001,6.485628e-006,0.000000e+000,2,8.553194e-001,0.000000e+000,,,,,,,,,,,,,,32,1,4.000000e+000,7.820129e-004,0.000000e+000,0,,0,
1524349956.631,,0.000000e+000,3.499950e+001,6.494836e-006,0.000000e+000,2,8.506895e-001,0.000000e+000,,,,,,,,,,,,,,32,1,4.000000e+000,1.560211e-003,0.000000e+000,0,,0,
1524349982.006,,0.000000e+000,3.499911e+001,6.462437e-006,0.000000e+000,2,8.484729e-001,0.000000e+000,,,,,,,,,,,,,,32,1,4.000000e+000,2.338409e-003,0.000000e+000,0,,0,
1524350007.897,,0.000000e+000,3.499872e+001,6.495242e-006,0.000000e+000,2,8.536450e-001,0.000000e+000,,,,,,,,,,,,,,32,1,4.000000e+000,0.000000e+000,0.000000e+000,0,,0,
1524350032.712,,0.000000e+000,3.499911e+001,6.487552e-006,0.000000e+000,2,8.534169e-001,0.000000e+000,,,,,,,,,,,,,,32,1,4.000000e+000,7.820129e-004,0.000000e+000,0,,0,
1524350058.628,,0.000000e+000,3.499911e+001,6.454517e-006,0.000000e+000,2,8.557650e-001,0.000000e+000,,,,,,,,,,,,,,32,1,4.000000e+000,7.820129e-004,0.000000e+000,0,,0,
1524350083.858,,0.000000e+000,3.499833e+001,6.550903e-006,0.000000e+000,2,8.524806e-001,0.000000e+000,,,,,,,,,,,,,,32,1,4.000000e+000,7.781982e-004,0.000000e+000,0,,0,
1524350109.556,,0.000000e+000,3.499911e+001,6.504670e-006,0.000000e+000,2,8.526230e-001,0.000000e+000,,,,,,,,,,,,,,32,1,4.000000e+000,2.338409e-003,0.000000e+000,0,,0,
1524350134.704,,0.000000e+000,3.499911e+001,6.467741e-006,0.000000e+000,2,8.502045e-001,0.000000e+000,,,,,,,,,,,,,,32,1,4.000000e+000,7.820129e-004,0.000000e+000,0,,0,
1524350147.374,,0.000000e+000,3.499833e+001,6.515612e-006,0.000000e+000,2,8.537614e-001,0.000000e+000,,,,,,,,,,,,,,32,1,4.000000e+000,2.349854e-003,0.000000e+000,0,,0,