File: Experimental Raw Data/MFn1 VRM/Linear Regression/MFn1_VRMac_36K_3000s_VRMde_35K.dc.dat
[Header]
TITLE,MPMS DC Measurement
BYAPP,MPMS Measurement,2.1,Summary
FILEOPENTIME, 1524301131.885000 4/21/2018, 2:58:51 AM

INFO, APPNAME, MPMS MultiVu Application, Revision 1.61,  Build 082

INFO, NAME, MFn1
INFO, WEIGHT, 1.000
INFO, AREA, 1.000
INFO, LENGTH, 1.000
INFO, SHAPE, 0
INFO, COMMENT,
INFO, SEQUENCE FILE: VRMac_36K_3000s_VRMde_35K.seq


INFO, BACKGROUND DATA FILE:, None


STARTUPAXIS,X,4,LINEAR,AUTO,0.000000,0.000000
STARTUPAXIS,Y1,5,LINEAR,AUTO,0.000000,0.000000


STARTUPGROUP,Longitudinal
FIELDGROUP,Longitudinal,1,2,3,4,5,6,7,8,9,15,16,17,18,27,28
FIELDGROUP,Transverse,1,2,3,4,10,11,12,13,14,19,20,21,22,27,28

PLOT_APPEARANCE,ALL,HORZ_GRID_ON,VERT_GRID_ON,MARKERS_AND_LINES

[Data]
Time,Comment,Field (Oe),Temperature (K),Long Moment (emu),Long Scan Std Dev,Long Algorithm,Long Reg Fit,Long Percent Error (%),Trans Moment (emu),Trans Scan Std Dev,Trans Algorithm,Trans Reg Fit,Trans Percent Error (%),Long Moment [w/o ABS] (emu),Long Scan Std Dev [w/o ABS],Long Reg Fit [w/o ABS],Long Percent Error [w/o ABS] (%),Trans Moment [w/o ABS] (emu),Trans Scan Std Dev [w/o ABS],Trans Reg Fit [w/o ABS],Trans Percent Error [w/o ABS] (%),Points per Scan,Scans per Measurement,Scan Length (cm),Delta Temp (K),Rot Position (deg),Error,EC Comp. Running,Using ABS,
1524301131.883,,0.000000e+000,3.500067e+001,-1.195576e-005,0.000000e+000,2,9.335669e-001,0.000000e+000,,,,,,,,,,,,,,32,1,4.000000e+000,7.820129e-004,0.000000e+000,0,,0,
1524301169.788,,0.000000e+000,3.500145e+001,-1.120386e-005,0.000000e+000,2,9.287032e-001,0.000000e+000,,,,,,,,,,,,,,32,1,4.000000e+000,7.781982e-004,0.000000e+000,0,,0,
1524301207.826,,0.000000e+000,3.500185e+001,-1.050574e-005,0.000000e+000,2,9.186062e-001,0.000000e+000,,,,,,,,,,,,,,32,1,4.000000e+000,4.688263e-003,0.000000e+000,0,,0,
1524301246.477,,0.000000e+000,3.500106e+001,-9.850687e-006,0.000000e+000,2,9.154186e-001,0.000000e+000,,,,,,,,,,,,,,32,1,4.000000e+000,3.128052e-003,0.000000e+000,0,,0,
1524301284.580,,0.000000e+000,3.499911e+001,-9.291289e-006,0.000000e+000,2,9.081786e-001,0.000000e+000,,,,,,,,,,,,,,32,1,4.000000e+000,7.820129e-004,0.000000e+000,0,,0,
1524301322.553,,0.000000e+000,3.499950e+001,-8.741701e-006,0.000000e+000,2,9.035356e-001,0.000000e+000,,,,,,,,,,,,,,32,1,4.000000e+000,0.000000e+000,0.000000e+000,0,,0,
1524301360.566,,0.000000e+000,3.499989e+001,-8.271899e-006,0.000000e+000,2,8.986005e-001,0.000000e+000,,,,,,,,,,,,,,32,1,4.000000e+000,7.781982e-004,0.000000e+000,0,,0,
1524301398.492,,0.000000e+000,3.499989e+001,-7.876282e-006,0.000000e+000,2,8.898094e-001,0.000000e+000,,,,,,,,,,,,,,32,1,4.000000e+000,7.781982e-004,0.000000e+000,0,,0,
1524301436.332,,0.000000e+000,3.499794e+001,-7.529982e-006,0.000000e+000,2,8.856296e-001,0.000000e+000,,,,,,,,,,,,,,32,1,4.000000e+000,0.000000e+000,0.000000e+000,0,,0,
1524301474.185,,0.000000e+000,3.499950e+001,-7.165493e-006,0.000000e+000,2,8.830596e-001,0.000000e+000,,,,,,,,,,,,,,32,1,4.000000e+000,0.000000e+000,0.000000e+000,0,,0,
1524301512.163,,0.000000e+000,3.499911e+001,-6.845585e-006,0.000000e+000,2,8.744087e-001,0.000000e+000,,,,,,,,,,,,,,32,1,4.000000e+000,7.820129e-004,0.000000e+000,0,,0,
1524301550.351,,0.000000e+000,3.499989e+001,-6.499274e-006,0.000000e+000,2,8.695617e-001,0.000000e+000,,,,,,,,,,,,,,32,1,4.000000e+000,7.781982e-004,0.000000e+000,0,,0,
1524301589.009,,0.000000e+000,3.499950e+001,-6.268113e-006,0.000000e+000,2,8.624400e-001,0.000000e+000,,,,,,,,,,,,,,32,1,4.000000e+000,0.000000e+000,0.000000e+000,0,,0,
1524301625.990,,0.000000e+000,3.499911e+001,-6.004361e-006,0.000000e+000,2,8.549823e-001,0.000000e+000,,,,,,,,,,,,,,32,1,4.000000e+000,2.338409e-003,0.000000e+000,0,,0,
1524301664.175,,0.000000e+000,3.499950e+001,-5.769763e-006,0.000000e+000,2,8.539084e-001,0.000000e+000,,,,,,,,,,,,,,32,1,4.000000e+000,0.000000e+000,0.000000e+000,0,,0,
1524301702.309,,0.000000e+000,3.499872e+001,-5.539601e-006,0.000000e+000,2,8.460549e-001,0.000000e+000,,,,,,,,,,,,,,32,1,4.000000e+000,0.000000e+000,0.000000e+000,0,,0,
1524301739.589,,0.000000e+000,3.499950e+001,-5.300760e-006,0.000000e+000,2,8.379866e-001,0.000000e+000,,,,,,,,,,,,,,32,1,4.000000e+000,0.000000e+000,0.000000e+000,0,,0,
1524301776.987,,0.000000e+000,3.499911e+001,-5.129780e-006,0.000000e+000,2,8.307304e-001,0.000000e+000,,,,,,,,,,,,,,32,1,4.000000e+000,7.820129e-004,0.000000e+000,0,,0,
1524301815.535,,0.000000e+000,3.499872e+001,-4.908531e-006,0.000000e+000,2,8.238832e-001,0.000000e+000,,,,,,,,,,,,,,32,1,4.000000e+000,0.000000e+000,0.000000e+000,0,,0,
1524301853.583,,0.000000e+000,3.499911e+001,-4.714074e-006,0.000000e+000,2,8.205569e-001,0.000000e+000,,,,,,,,,,,,,,32,1,4.000000e+000,7.820129e-004,0.000000e+000,0,,0,
1524301891.211,,0.000000e+000,3.499911e+001,-4.551483e-006,0.000000e+000,2,8.135432e-001,0.000000e+000,,,,,,,,,,,,,,32,1,4.000000e+000,7.820129e-004,0.000000e+000,0,,0,
1524301929.742,,0.000000e+000,3.499989e+001,-4.336755e-006,0.000000e+000,2,8.035791e-001,0.000000e+000,,,,,,,,,,,,,,32,1,4.000000e+000,7.781982e-004,0.000000e+000,0,,0,
1524301968.137,,0.000000e+000,3.499950e+001,-4.161870e-006,0.000000e+000,2,7.934909e-001,0.000000e+000,,,,,,,,,,,,,,32,1,4.000000e+000,0.000000e+000,0.000000e+000,0,,0,
1524302005.775,,0.000000e+000,3.499676e+001,-4.016824e-006,0.000000e+000,2,7.829204e-001,0.000000e+000,,,,,,,,,,,,,,32,1,4.000000e+000,7.820129e-004,0.000000e+000,0,,0,
1524302043.829,,0.000000e+000,3.499911e+001,-3.882808e-006,0.000000e+000,2,7.769901e-001,0.000000e+000,,,,,,,,,,,,,,32,1,4.000000e+000,7.820129e-004,0.000000e+000,0,,0,
1524302081.499,,0.000000e+000,3.499950e+001,-3.739151e-006,0.000000e+000,2,7.749366e-001,0.000000e+000,,,,,,,,,,,,,,32,1,4.000000e+000,1.560211e-003,0.000000e+000,0,,0,
1524302119.865,,0.000000e+000,3.499793e+001,-3.572152e-006,0.000000e+000,2,7.606720e-001,0.000000e+000,,,,,,,,,,,,,,32,1,4.000000e+000,1.567841e-003,0.000000e+000,0,,0,
1524302156.545,,0.000000e+000,3.499989e+001,-3.437281e-006,0.000000e+000,2,7.480151e-001,0.000000e+000,,,,,,,,,,,,,,32,1,4.000000e+000,2.342224e-003,0.000000e+000,0,,0,
1524302194.501,,0.000000e+000,3.499911e+001,-3.321446e-006,0.000000e+000,2,7.335098e-001,0.000000e+000,,,,,,,,,,,,,,32,1,4.000000e+000,7.820129e-004,0.000000e+000,0,,0,
1524302232.566,,0.000000e+000,3.499794e+001,-3.177100e-006,0.000000e+000,2,7.210226e-001,0.000000e+000,,,,,,,,,,,,,,32,1,4.000000e+000,0.000000e+000,0.000000e+000,0,,0,
1524302270.612,,0.000000e+000,3.499833e+001,-3.097595e-006,0.000000e+000,2,7.156236e-001,0.000000e+000,,,,,,,,,,,,,,32,1,4.000000e+000,7.781982e-004,0.000000e+000,0,,0,
1524302308.680,,0.000000e+000,3.499872e+001,-2.950144e-006,0.000000e+000,2,7.058873e-001,0.000000e+000,,,,,,,,,,,,,,32,1,4.000000e+000,1.560211e-003,0.000000e+000,0,,0,
1524302346.768,,0.000000e+000,3.500028e+001,-2.832326e-006,0.000000e+000,2,6.963073e-001,0.000000e+000,,,,,,,,,,,,,,32,1,4.000000e+000,0.000000e+000,0.000000e+000,0,,0,
1524302384.874,,0.000000e+000,3.499833e+001,-2.734819e-006,0.000000e+000,2,6.874908e-001,0.000000e+000,,,,,,,,,,,,,,32,1,4.000000e+000,2.349854e-003,0.000000e+000,0,,0,
1524302422.949,,0.000000e+000,3.499833e+001,-2.634419e-006,0.000000e+000,2,6.721094e-001,0.000000e+000,,,,,,,,,,,,,,32,1,4.000000e+000,7.781982e-004,0.000000e+000,0,,0,
1524302460.715,,0.000000e+000,3.499911e+001,-2.549293e-006,0.000000e+000,2,6.706048e-001,0.000000e+000,,,,,,,,,,,,,,32,1,4.000000e+000,7.820129e-004,0.000000e+000,0,,0,
1524302498.570,,0.000000e+000,3.499911e+001,-2.433607e-006,0.000000e+000,2,6.422798e-001,0.000000e+000,,,,,,,,,,,,,,32,1,4.000000e+000,7.820129e-004,0.000000e+000,0,,0,
1524302535.626,,0.000000e+000,3.499989e+001,-2.299377e-006,0.000000e+000,2,6.232093e-001,0.000000e+000,,,,,,,,,,,,,,32,1,4.000000e+000,7.781982e-004,0.000000e+000,0,,0,
1524302574.089,,0.000000e+000,3.499637e+001,-2.214311e-006,0.000000e+000,2,6.267912e-001,0.000000e+000,,,,,,,,,,,,,,32,1,4.000000e+000,6.259918e-003,0.000000e+000,0,,0,
1524302612.152,,0.000000e+000,3.500028e+001,-2.112111e-006,0.000000e+000,2,5.894871e-001,0.000000e+000,,,,,,,,,,,,,,32,1,4.000000e+000,3.120422e-003,0.000000e+000,0,,0,
1524302650.467,,0.000000e+000,3.499950e+001,-1.994735e-006,0.000000e+000,2,5.690149e-001,0.000000e+000,,,,,,,,,,,,,,32,1,4.000000e+000,0.000000e+000,0.000000e+000,0,,0,
1524302688.368,,0.000000e+000,3.499833e+001,-1.918563e-006,0.000000e+000,2,5.469772e-001,0.000000e+000,,,,,,,,,,,,,,32,1,4.000000e+000,2.349854e-003,0.000000e+000,0,,0,
1524302726.021,,0.000000e+000,3.499872e+001,-1.843370e-006,0.000000e+000,2,5.232748e-001,0.000000e+000,,,,,,,,,,,,,,32,1,4.000000e+000,1.560211e-003,0.000000e+000,0,,0,
1524302763.794,,0.000000e+000,3.499793e+001,-1.761211e-006,0.000000e+000,2,5.036131e-001,0.000000e+000,,,,,,,,,,,,,,32,1,4.000000e+000,1.567841e-003,0.000000e+000,0,,0,
1524302802.087,,0.000000e+000,3.499872e+001,-1.670710e-006,0.000000e+000,2,4.953796e-001,0.000000e+000,,,,,,,,,,,,,,32,1,4.000000e+000,0.000000e+000,0.000000e+000,0,,0,
1524302839.908,,0.000000e+000,3.499950e+001,-1.584001e-006,0.000000e+000,2,4.585505e-001,0.000000e+000,,,,,,,,,,,,,,32,1,4.000000e+000,0.000000e+000,0.000000e+000,0,,0,
1524302878.283,,0.000000e+000,3.499911e+001,-1.509298e-006,0.000000e+000,2,4.181352e-001,0.000000e+000,,,,,,,,,,,,,,32,1,4.000000e+000,2.338409e-003,0.000000e+000,0,,0,
1524302915.919,,0.000000e+000,3.499872e+001,-1.455963e-006,0.000000e+000,2,3.796723e-001,0.000000e+000,,,,,,,,,,,,,,32,1,4.000000e+000,0.000000e+000,0.000000e+000,0,,0,
1524302954.769,,0.000000e+000,3.499911e+001,-1.340544e-006,0.000000e+000,2,3.565781e-001,0.000000e+000,,,,,,,,,,,,,,32,1,4.000000e+000,7.820129e-004,0.000000e+000,0,,0,
1524302992.730,,0.000000e+000,3.500067e+001,-1.258638e-006,0.000000e+000,2,2.976631e-001,0.000000e+000,,,,,,,,,,,,,,32,1,4.000000e+000,3.910065e-003,0.000000e+000,0,,0,
1524303030.413,,0.000000e+000,3.499911e+001,-1.216075e-006,0.000000e+000,2,2.812249e-001,0.000000e+000,,,,,,,,,,,,,,32,1,4.000000e+000,2.338409e-003,0.000000e+000,0,,0,
1524303069.026,,0.000000e+000,3.499989e+001,-1.072237e-006,0.000000e+000,2,1.680267e-001,0.000000e+000,,,,,,,,,,,,,,32,1,4.000000e+000,7.781982e-004,0.000000e+000,0,,0,
1524303107.009,,0.000000e+000,3.499950e+001,-1.091330e-006,0.000000e+000,2,2.009427e-001,0.000000e+000,,,,,,,,,,,,,,32,1,4.000000e+000,1.560211e-003,0.000000e+000,0,,0,
1524303145.037,,0.000000e+000,3.499911e+001,-1.055061e-006,0.000000e+000,2,1.729907e-001,0.000000e+000,,,,,,,,,,,,,,32,1,4.000000e+000,2.338409e-003,0.000000e+000,0,,0,
1524303182.058,,0.000000e+000,3.499715e+001,-9.268041e-007,0.000000e+000,2,3.349251e-002,0.000000e+000,,,,,,,,,,,,,,32,1,4.000000e+000,3.128052e-003,0.000000e+000,0,,0,
1524303220.966,,0.000000e+000,3.499871e+001,-8.974966e-007,0.000000e+000,2,2.201984e-003,0.000000e+000,,,,,,,,,,,,,,32,1,4.000000e+000,6.248474e-003,0.000000e+000,0,,0,
1524303259.004,,0.000000e+000,3.499872e+001,-8.100338e-007,0.000000e+000,2,0.000000e+000,0.000000e+000,,,,,,,,,,,,,,32,1,4.000000e+000,1.560211e-003,0.000000e+000,0,,0,
1524303297.619,,0.000000e+000,3.499833e+001,-7.059559e-007,0.000000e+000,2,0.000000e+000,0.000000e+000,,,,,,,,,,,,,,32,1,4.000000e+000,7.781982e-004,0.000000e+000,0,,0,
1524303335.300,,0.000000e+000,3.499872e+001,-7.076405e-007,0.000000e+000,2,0.000000e+000,0.000000e+000,,,,,,,,,,,,,,32,1,4.000000e+000,0.000000e+000,0.000000e+000,0,,0,
1524303372.421,,0.000000e+000,3.499872e+001,-6.464525e-007,0.000000e+000,2,0.000000e+000,0.000000e+000,,,,,,,,,,,,,,32,1,4.000000e+000,0.000000e+000,0.000000e+000,0,,0,
1524303410.489,,0.000000e+000,3.499872e+001,-5.777642e-007,0.000000e+000,2,0.000000e+000,0.000000e+000,,,,,,,,,,,,,,32,1,4.000000e+000,1.560211e-003,0.000000e+000,0,,0,
1524303447.607,,0.000000e+000,3.500224e+001,-4.649179e-007,0.000000e+000,2,0.000000e+000,0.000000e+000,,,,,,,,,,,,,,32,1,4.000000e+000,7.041931e-003,0.000000e+000,0,,0,
1524303485.695,,0.000000e+000,3.500028e+001,-4.928625e-007,0.000000e+000,2,0.000000e+000,0.000000e+000,,,,,,,,,,,,,,32,1,4.000000e+000,3.120422e-003,0.000000e+000,0,,0,
1524303523.440,,0.000000e+000,3.499872e+001,-4.140376e-007,0.000000e+000,2,0.000000e+000,0.000000e+000,,,,,,,,,,,,,,32,1,4.000000e+000,0.000000e+000,0.000000e+000,0,,0,
1524303561.588,,0.000000e+000,3.499911e+001,-3.278638e-007,0.000000e+000,2,0.000000e+000,0.000000e+000,,,,,,,,,,,,,,32,1,4.000000e+000,7.820129e-004,0.000000e+000,0,,0,
1524303599.574,,0.000000e+000,3.499872e+001,-2.940213e-007,0.000000e+000,2,0.000000e+000,0.000000e+000,,,,,,,,,,,,,,32,1,4.000000e+000,0.000000e+000,0.000000e+000,0,,0,
1524303637.469,,0.000000e+000,3.499911e+001,-2.420843e-007,0.000000e+000,2,0.000000e+000,0.000000e+000,,,,,,,,,,,,,,32,1,4.000000e+000,7.820129e-004,0.000000e+000,0,,0,
1524303675.680,,0.000000e+000,3.499794e+001,-2.603547e-007,0.000000e+000,2,0.000000e+000,0.000000e+000,,,,,,,,,,,,,,32,1,4.000000e+000,0.000000e+000,0.000000e+000,0,,0,
1524303713.756,,0.000000e+000,3.499872e+001,-1.303334e-007,0.000000e+000,2,0.000000e+000,0.000000e+000,,,,,,,,,,,,,,32,1,4.000000e+000,1.560211e-003,0.000000e+000,0,,0,
1524303751.859,,0.000000e+000,3.499833e+001,-6.739691e-008,0.000000e+000,2,0.000000e+000,0.000000e+000,,,,,,,,,,,,,,32,1,4.000000e+000,7.781982e-004,0.000000e+000,0,,0,
1524303790.534,,0.000000e+000,3.499950e+001,-5.722605e-009,0.000000e+000,2,0.000000e+000,0.000000e+000,,,,,,,,,,,,,,32,1,4.000000e+000,1.560211e-003,0.000000e+000,0,,0,
1524303828.782,,0.000000e+000,3.499989e+001,-1.410024e-008,0.000000e+000,2,0.000000e+000,0.000000e+000,,,,,,,,,,,,,,32,1,4.000000e+000,7.781982e-004,0.000000e+000,0,,0,
1524303866.630,,0.000000e+000,3.499872e+001,3.945924e-008,0.000000e+000,2,0.000000e+000,0.000000e+000,,,,,,,,,,,,,,32,1,4.000000e+000,1.560211e-003,0.000000e+000,0,,0,
1524303904.483,,0.000000e+000,3.500145e+001,3.006239e-008,0.000000e+000,2,0.000000e+000,0.000000e+000,,,,,,,,,,,,,,32,1,4.000000e+000,5.470276e-003,0.000000e+000,0,,0,
1524303942.771,,0.000000e+000,3.499950e+001,1.635940e-007,0.000000e+000,2,0.000000e+000,0.000000e+000,,,,,,,,,,,,,,32,1,4.000000e+000,3.120422e-003,0.000000e+000,0,,0,
1524303981.094,,0.000000e+000,3.499950e+001,1.964500e-007,0.000000e+000,2,0.000000e+000,0.000000e+000,,,,,,,,,,,,,,32,1,4.000000e+000,1.560211e-003,0.000000e+000,0,,0,
1524304018.877,,0.000000e+000,3.499872e+001,2.257244e-007,0.000000e+000,2,0.000000e+000,0.000000e+000,,,,,,,,,,,,,,32,1,4.000000e+000,1.560211e-003,0.000000e+000,0,,0,
1524304056.066,,0.000000e+000,3.499911e+001,2.385694e-007,0.000000e+000,2,0.000000e+000,0.000000e+000,,,,,,,,,,,,,,32,1,4.000000e+000,7.820129e-004,0.000000e+000,0,,0,
1524304093.954,,0.000000e+000,3.499911e+001,2.887828e-007,0.000000e+000,2,0.000000e+000,0.000000e+000,,,,,,,,,,,,,,32,1,4.000000e+000,7.820129e-004,0.000000e+000,0,,0,
1524304132.029,,0.000000e+000,3.500028e+001,3.517486e-007,0.000000e+000,2,0.000000e+000,0.000000e+000,,,,,,,,,,,,,,32,1,4.000000e+000,0.000000e+000,0.000000e+000,0,,0,
1524304170.057,,0.000000e+000,3.499911e+001,3.884700e-007,0.000000e+000,2,0.000000e+000,0.000000e+000,,,,,,,,,,,,,,32,1,4.000000e+000,7.820129e-004,0.000000e+000,0,,0,
1524304209.360,,0.000000e+000,3.499872e+001,4.563108e-007,0.000000e+000,2,0.000000e+000,0.000000e+000,,,,,,,,,,,,,,32,1,4.000000e+000,0.000000e+000,0.000000e+000,0,,0,
1524304246.516,,0.000000e+000,3.499911e+001,4.588830e-007,0.000000e+000,2,0.000000e+000,0.000000e+000,,,,,,,,,,,,,,32,1,4.000000e+000,7.820129e-004,0.000000e+000,0,,0,
1524304284.604,,0.000000e+000,3.499950e+001,4.760478e-007,0.000000e+000,2,0.000000e+000,0.000000e+000,,,,,,,,,,,,,,32,1,4.000000e+000,0.000000e+000,0.000000e+000,0,,0,
1524304321.907,,0.000000e+000,3.499911e+001,5.361458e-007,0.000000e+000,2,0.000000e+000,0.000000e+000,,,,,,,,,,,,,,32,1,4.000000e+000,7.820129e-004,0.000000e+000,0,,0,
1524304359.925,,0.000000e+000,3.500028e+001,6.126459e-007,0.000000e+000,2,0.000000e+000,0.000000e+000,,,,,,,,,,,,,,32,1,4.000000e+000,1.560211e-003,0.000000e+000,0,,0,
1524304397.573,,0.000000e+000,3.500067e+001,6.143586e-007,0.000000e+000,2,0.000000e+000,0.000000e+000,,,,,,,,,,,,,,32,1,4.000000e+000,2.338409e-003,0.000000e+000,0,,0,
1524304435.359,,0.000000e+000,3.499677e+001,6.643177e-007,0.000000e+000,2,0.000000e+000,0.000000e+000,,,,,,,,,,,,,,32,1,4.000000e+000,3.910065e-003,0.000000e+000,0,,0,
1524304473.449,,0.000000e+000,3.499950e+001,7.056387e-007,0.000000e+000,2,0.000000e+000,0.000000e+000,,,,,,,,,,,,,,32,1,4.000000e+000,0.000000e+000,0.000000e+000,0,,0,
1524304511.727,,0.000000e+000,3.499911e+001,7.303715e-007,0.000000e+000,2,0.000000e+000,0.000000e+000,,,,,,,,,,,,,,32,1,4.000000e+000,7.820129e-004,0.000000e+000,0,,0,
1524304549.790,,0.000000e+000,3.499950e+001,8.150591e-007,0.000000e+000,2,0.000000e+000,0.000000e+000,,,,,,,,,,,,,,32,1,4.000000e+000,0.000000e+000,0.000000e+000,0,,0,
1524304587.836,,0.000000e+000,3.500106e+001,8.300785e-007,0.000000e+000,2,0.000000e+000,0.000000e+000,,,,,,,,,,,,,,32,1,4.000000e+000,3.128052e-003,0.000000e+000,0,,0,
1524304625.114,,0.000000e+000,3.499872e+001,8.403571e-007,0.000000e+000,2,0.000000e+000,0.000000e+000,,,,,,,,,,,,,,32,1,4.000000e+000,0.000000e+000,0.000000e+000,0,,0,
1524304662.737,,0.000000e+000,3.499950e+001,8.922839e-007,0.000000e+000,2,0.000000e+000,0.000000e+000,,,,,,,,,,,,,,32,1,4.000000e+000,1.560211e-003,0.000000e+000,0,,0,
1524304701.057,,0.000000e+000,3.499793e+001,9.100244e-007,0.000000e+000,2,2.004510e-002,0.000000e+000,,,,,,,,,,,,,,32,1,4.000000e+000,1.567841e-003,0.000000e+000,0,,0,
1524304738.651,,0.000000e+000,3.499911e+001,9.536758e-007,0.000000e+000,2,3.405372e-002,0.000000e+000,,,,,,,,,,,,,,32,1,4.000000e+000,7.820129e-004,0.000000e+000,0,,0,
1524304776.736,,0.000000e+000,3.499911e+001,9.780945e-007,0.000000e+000,2,7.632927e-002,0.000000e+000,,,,,,,,,,,,,,32,1,4.000000e+000,7.820129e-004,0.000000e+000,0,,0,
1524304814.844,,0.000000e+000,3.499911e+001,1.034995e-006,0.000000e+000,2,1.376906e-001,0.000000e+000,,,,,,,,,,,,,,32,1,4.000000e+000,7.820129e-004,0.000000e+000,0,,0,
1524304853.460,,0.000000e+000,3.499950e+001,1.039892e-006,0.000000e+000,2,1.083941e-001,0.000000e+000,,,,,,,,,,,,,,32,1,4.000000e+000,0.000000e+000,0.000000e+000,0,,0,
1524304891.013,,0.000000e+000,3.499950e+001,1.079314e-006,0.000000e+000,2,1.712881e-001,0.000000e+000,,,,,,,,,,,,,,32,1,4.000000e+000,0.000000e+000,0.000000e+000,0,,0,
1524304928.401,,0.000000e+000,3.499911e+001,1.111121e-006,0.000000e+000,2,1.686540e-001,0.000000e+000,,,,,,,,,,,,,,32,1,4.000000e+000,7.820129e-004,0.000000e+000,0,,0,
1524304966.511,,0.000000e+000,3.499911e+001,1.149011e-006,0.000000e+000,2,2.395249e-001,0.000000e+000,,,,,,,,,,,,,,32,1,4.000000e+000,7.820129e-004,0.000000e+000,0,,0,
1524305004.047,,0.000000e+000,3.499715e+001,1.178387e-006,0.000000e+000,2,2.266655e-001,0.000000e+000,,,,,,,,,,,,,,32,1,4.000000e+000,1.571655e-003,0.000000e+000,0,,0,
1524305041.893,,0.000000e+000,3.499872e+001,1.216398e-006,0.000000e+000,2,2.678228e-001,0.000000e+000,,,,,,,,,,,,,,32,1,4.000000e+000,1.560211e-003,0.000000e+000,0,,0,
1524305079.971,,0.000000e+000,3.499911e+001,1.236563e-006,0.000000e+000,2,2.870337e-001,0.000000e+000,,,,,,,,,,,,,,32,1,4.000000e+000,7.820129e-004,0.000000e+000,0,,0,
1524305118.269,,0.000000e+000,3.499950e+001,1.281053e-006,0.000000e+000,2,3.014434e-001,0.000000e+000,,,,,,,,,,,,,,32,1,4.000000e+000,0.000000e+000,0.000000e+000,0,,0,
1524305156.414,,0.000000e+000,3.499833e+001,1.303590e-006,0.000000e+000,2,3.080383e-001,0.000000e+000,,,,,,,,,,,,,,32,1,4.000000e+000,2.349854e-003,0.000000e+000,0,,0,
1524305194.357,,0.000000e+000,3.499911e+001,1.347184e-006,0.000000e+000,2,3.287587e-001,0.000000e+000,,,,,,,,,,,,,,32,1,4.000000e+000,7.820129e-004,0.000000e+000,0,,0,
1524305232.693,,0.000000e+000,3.499911e+001,1.363710e-006,0.000000e+000,2,3.494528e-001,0.000000e+000,,,,,,,,,,,,,,32,1,4.000000e+000,7.820129e-004,0.000000e+000,0,,0,
1524305270.756,,0.000000e+000,3.499872e+001,1.361703e-006,0.000000e+000,2,3.336828e-001,0.000000e+000,,,,,,,,,,,,,,32,1,4.000000e+000,0.000000e+000,0.000000e+000,0,,0,
1524305308.824,,0.000000e+000,3.499950e+001,1.397868e-006,0.000000e+000,2,3.538170e-001,0.000000e+000,,,,,,,,,,,,,,32,1,4.000000e+000,0.000000e+000,0.000000e+000,0,,0,
1524305346.892,,0.000000e+000,3.499989e+001,1.428941e-006,0.000000e+000,2,3.707133e-001,0.000000e+000,,,,,,,,,,,,,,32,1,4.000000e+000,7.781982e-004,0.000000e+000,0,,0,
1524305383.970,,0.000000e+000,3.499950e+001,1.456086e-006,0.000000e+000,2,3.764304e-001,0.000000e+000,,,,,,,,,,,,,,32,1,4.000000e+000,1.560211e-003,0.000000e+000,0,,0,
1524305422.458,,0.000000e+000,3.499950e+001,1.504882e-006,0.000000e+000,2,3.938543e-001,0.000000e+000,,,,,,,,,,,,,,32,1,4.000000e+000,0.000000e+000,0.000000e+000,0,,0,
1524305459.804,,0.000000e+000,3.499911e+001,1.525845e-006,0.000000e+000,2,3.972936e-001,0.000000e+000,,,,,,,,,,,,,,32,1,4.000000e+000,7.820129e-004,0.000000e+000,0,,0,
1524305497.799,,0.000000e+000,3.499911e+001,1.524959e-006,0.000000e+000,2,4.320552e-001,0.000000e+000,,,,,,,,,,,,,,32,1,4.000000e+000,7.820129e-004,0.000000e+000,0,,0,
1524305535.890,,0.000000e+000,3.499872e+001,1.530944e-006,0.000000e+000,2,4.259961e-001,0.000000e+000,,,,,,,,,,,,,,32,1,4.000000e+000,0.000000e+000,0.000000e+000,0,,0,
1524305573.973,,0.000000e+000,3.499950e+001,1.587412e-006,0.000000e+000,2,4.430242e-001,0.000000e+000,,,,,,,,,,,,,,32,1,4.000000e+000,0.000000e+000,0.000000e+000,0,,0,
1524305612.416,,0.000000e+000,3.499950e+001,1.594401e-006,0.000000e+000,2,4.241442e-001,0.000000e+000,,,,,,,,,,,,,,32,1,4.000000e+000,0.000000e+000,0.000000e+000,0,,0,
1524305649.999,,0.000000e+000,3.499911e+001,1.667912e-006,0.000000e+000,2,4.528108e-001,0.000000e+000,,,,,,,,,,,,,,32,1,4.000000e+000,2.338409e-003,0.000000e+000,0,,0,
1524305688.520,,0.000000e+000,3.499950e+001,1.684619e-006,0.000000e+000,2,4.674419e-001,0.000000e+000,,,,,,,,,,,,,,32,1,4.000000e+000,0.000000e+000,0.000000e+000,0,,0,
1524305726.328,,0.000000e+000,3.499872e+001,1.670256e-006,0.000000e+000,2,4.634877e-001,0.000000e+000,,,,,,,,,,,,,,32,1,4.000000e+000,1.560211e-003,0.000000e+000,0,,0,
1524305763.928,,0.000000e+000,3.499872e+001,1.745857e-006,0.000000e+000,2,4.823556e-001,0.000000e+000,,,,,,,,,,,,,,32,1,4.000000e+000,0.000000e+000,0.000000e+000,0,,0,
1524305801.931,,0.000000e+000,3.499911e+001,1.736871e-006,0.000000e+000,2,4.960683e-001,0.000000e+000,,,,,,,,,,,,,,32,1,4.000000e+000,7.820129e-004,0.000000e+000,0,,0,
1524305840.077,,0.000000e+000,3.499833e+001,1.769273e-006,0.000000e+000,2,4.884908e-001,0.000000e+000,,,,,,,,,,,,,,32,1,4.000000e+000,2.349854e-003,0.000000e+000,0,,0,
1524305878.097,,0.000000e+000,3.499872e+001,1.782295e-006,0.000000e+000,2,4.870118e-001,0.000000e+000,,,,,,,,,,,,,,32,1,4.000000e+000,0.000000e+000,0.000000e+000,0,,0,
1524305916.185,,0.000000e+000,3.499911e+001,1.851612e-006,0.000000e+000,2,4.970344e-001,0.000000e+000,,,,,,,,,,,,,,32,1,4.000000e+000,7.820129e-004,0.000000e+000,0,,0,
1524305953.833,,0.000000e+000,3.499911e+001,1.836285e-006,0.000000e+000,2,5.017256e-001,0.000000e+000,,,,,,,,,,,,,,32,1,4.000000e+000,7.820129e-004,0.000000e+000,0,,0,
1524305991.901,,0.000000e+000,3.499950e+001,1.874751e-006,0.000000e+000,2,5.271997e-001,0.000000e+000,,,,,,,,,,,,,,32,1,4.000000e+000,0.000000e+000,0.000000e+000,0,,0,
1524306029.867,,0.000000e+000,3.499911e+001,1.894851e-006,0.000000e+000,2,5.259051e-001,0.000000e+000,,,,,,,,,,,,,,32,1,4.000000e+000,2.338409e-003,0.000000e+000,0,,0,
1524306068.210,,0.000000e+000,3.499911e+001,1.930978e-006,0.000000e+000,2,5.194207e-001,0.000000e+000,,,,,,,,,,,,,,32,1,4.000000e+000,2.338409e-003,0.000000e+000,0,,0,
1524306106.291,,0.000000e+000,3.499950e+001,1.909837e-006,0.000000e+000,2,5.228981e-001,0.000000e+000,,,,,,,,,,,,,,32,1,4.000000e+000,0.000000e+000,0.000000e+000,0,,0,
1524306144.081,,0.000000e+000,3.499872e+001,1.966606e-006,0.000000e+000,2,5.303829e-001,0.000000e+000,,,,,,,,,,,,,,32,1,4.000000e+000,0.000000e+000,0.000000e+000,0,,0,
1524306181.967,,0.000000e+000,3.499872e+001,1.996818e-006,0.000000e+000,2,5.382248e-001,0.000000e+000,,,,,,,,,,,,,,32,1,4.000000e+000,1.560211e-003,0.000000e+000,0,,0,
1524306220.670,,0.000000e+000,3.499911e+001,2.014228e-006,0.000000e+000,2,5.444540e-001,0.000000e+000,,,,,,,,,,,,,,32,1,4.000000e+000,7.820129e-004,0.000000e+000,0,,0,
1524306259.363,,0.000000e+000,3.499989e+001,2.014302e-006,0.000000e+000,2,5.116879e-001,0.000000e+000,,,,,,,,,,,,,,32,1,4.000000e+000,7.781982e-004,0.000000e+000,0,,0,
1524306297.588,,0.000000e+000,3.499911e+001,2.045202e-006,0.000000e+000,2,5.583634e-001,0.000000e+000,,,,,,,,,,,,,,32,1,4.000000e+000,7.820129e-004,0.000000e+000,0,,0,
1524306335.694,,0.000000e+000,3.499950e+001,2.057977e-006,0.000000e+000,2,5.574136e-001,0.000000e+000,,,,,,,,,,,,,,32,1,4.000000e+000,0.000000e+000,0.000000e+000,0,,0,
1524306374.550,,0.000000e+000,3.499950e+001,2.066023e-006,0.000000e+000,2,5.512070e-001,0.000000e+000,,,,,,,,,,,,,,32,1,4.000000e+000,1.560211e-003,0.000000e+000,0,,0,
1524306412.613,,0.000000e+000,3.499872e+001,2.129358e-006,0.000000e+000,2,5.694860e-001,0.000000e+000,,,,,,,,,,,,,,32,1,4.000000e+000,0.000000e+000,0.000000e+000,0,,0,
1524306450.218,,0.000000e+000,3.499989e+001,2.153109e-006,0.000000e+000,2,5.682005e-001,0.000000e+000,,,,,,,,,,,,,,32,1,4.000000e+000,7.781982e-004,0.000000e+000,0,,0,
1524306488.396,,0.000000e+000,3.499950e+001,2.165198e-006,0.000000e+000,2,5.727108e-001,0.000000e+000,,,,,,,,,,,,,,32,1,4.000000e+000,0.000000e+000,0.000000e+000,0,,0,
1524306526.377,,0.000000e+000,3.499950e+001,2.133846e-006,0.000000e+000,2,5.795361e-001,0.000000e+000,,,,,,,,,,,,,,32,1,4.000000e+000,0.000000e+000,0.000000e+000,0,,0,
1524306564.437,,0.000000e+000,3.499911e+001,2.172574e-006,0.000000e+000,2,5.687759e-001,0.000000e+000,,,,,,,,,,,,,,32,1,4.000000e+000,7.820129e-004,0.000000e+000,0,,0,
1524306602.538,,0.000000e+000,3.499911e+001,2.198672e-006,0.000000e+000,2,5.810531e-001,0.000000e+000,,,,,,,,,,,,,,32,1,4.000000e+000,7.820129e-004,0.000000e+000,0,,0,
1524306640.224,,0.000000e+000,3.499793e+001,2.261324e-006,0.000000e+000,2,5.905178e-001,0.000000e+000,,,,,,,,,,,,,,32,1,4.000000e+000,1.567841e-003,0.000000e+000,0,,0,
1524306678.137,,0.000000e+000,3.499950e+001,2.236861e-006,0.000000e+000,2,5.889136e-001,0.000000e+000,,,,,,,,,,,,,,32,1,4.000000e+000,1.560211e-003,0.000000e+000,0,,0,
1524306716.187,,0.000000e+000,3.499833e+001,2.274838e-006,0.000000e+000,2,6.031108e-001,0.000000e+000,,,,,,,,,,,,,,32,1,4.000000e+000,7.781982e-004,0.000000e+000,0,,0,
1524306754.300,,0.000000e+000,3.499911e+001,2.291302e-006,0.000000e+000,2,6.023301e-001,0.000000e+000,,,,,,,,,,,,,,32,1,4.000000e+000,7.820129e-004,0.000000e+000,0,,0,
1524306792.338,,0.000000e+000,3.499911e+001,2.302154e-006,0.000000e+000,2,6.047608e-001,0.000000e+000,,,,,,,,,,,,,,32,1,4.000000e+000,7.820129e-004,0.000000e+000,0,,0,
1524306830.991,,0.000000e+000,3.500028e+001,2.347383e-006,0.000000e+000,2,6.080667e-001,0.000000e+000,,,,,,,,,,,,,,32,1,4.000000e+000,1.560211e-003,0.000000e+000,0,,0,
1524306868.482,,0.000000e+000,3.499911e+001,2.329959e-006,0.000000e+000,2,6.033244e-001,0.000000e+000,,,,,,,,,,,,,,32,1,4.000000e+000,7.820129e-004,0.000000e+000,0,,0,
1524306906.087,,0.000000e+000,3.499911e+001,2.368910e-006,0.000000e+000,2,6.121243e-001,0.000000e+000,,,,,,,,,,,,,,32,1,4.000000e+000,7.820129e-004,0.000000e+000,0,,0,
1524306944.150,,0.000000e+000,3.499911e+001,2.370391e-006,0.000000e+000,2,6.071112e-001,0.000000e+000,,,,,,,,,,,,,,32,1,4.000000e+000,7.820129e-004,0.000000e+000,0,,0,
1524306981.363,,0.000000e+000,3.499989e+001,2.414951e-006,0.000000e+000,2,6.166160e-001,0.000000e+000,,,,,,,,,,,,,,32,1,4.000000e+000,7.781982e-004,0.000000e+000,0,,0,
1524307018.999,,0.000000e+000,3.499872e+001,2.409436e-006,0.000000e+000,2,6.228566e-001,0.000000e+000,,,,,,,,,,,,,,32,1,4.000000e+000,0.000000e+000,0.000000e+000,0,,0,
1524307057.067,,0.000000e+000,3.499911e+001,2.396474e-006,0.000000e+000,2,6.179615e-001,0.000000e+000,,,,,,,,,,,,,,32,1,4.000000e+000,7.820129e-004,0.000000e+000,0,,0,
1524307095.525,,0.000000e+000,3.499911e+001,2.442166e-006,0.000000e+000,2,6.236442e-001,0.000000e+000,,,,,,,,,,,,,,32,1,4.000000e+000,7.820129e-004,0.000000e+000,0,,0,
1524307132.366,,0.000000e+000,3.499911e+001,2.461428e-006,0.000000e+000,2,6.189941e-001,0.000000e+000,,,,,,,,,,,,,,32,1,4.000000e+000,7.820129e-004,0.000000e+000,0,,0,
1524307169.681,,0.000000e+000,3.500067e+001,2.447102e-006,0.000000e+000,2,6.274449e-001,0.000000e+000,,,,,,,,,,,,,,32,1,4.000000e+000,2.338409e-003,0.000000e+000,0,,0,
1524307207.504,,0.000000e+000,3.499911e+001,2.492852e-006,0.000000e+000,2,6.292080e-001,0.000000e+000,,,,,,,,,,,,,,32,1,4.000000e+000,7.820129e-004,0.000000e+000,0,,0,
1524307245.690,,0.000000e+000,3.499950e+001,2.530270e-006,0.000000e+000,2,6.325583e-001,0.000000e+000,,,,,,,,,,,,,,32,1,4.000000e+000,0.000000e+000,0.000000e+000,0,,0,
1524307283.695,,0.000000e+000,3.499911e+001,2.534876e-006,0.000000e+000,2,6.285792e-001,0.000000e+000,,,,,,,,,,,,,,32,1,4.000000e+000,7.820129e-004,0.000000e+000,0,,0,
1524307321.501,,0.000000e+000,3.499793e+001,2.585373e-006,0.000000e+000,2,6.339405e-001,0.000000e+000,,,,,,,,,,,,,,32,1,4.000000e+000,1.567841e-003,0.000000e+000,0,,0,
1524307359.404,,0.000000e+000,3.499872e+001,2.561839e-006,0.000000e+000,2,6.408883e-001,0.000000e+000,,,,,,,,,,,,,,32,1,4.000000e+000,1.560211e-003,0.000000e+000,0,,0,
1524307397.385,,0.000000e+000,3.499911e+001,2.587135e-006,0.000000e+000,2,6.361196e-001,0.000000e+000,,,,,,,,,,,,,,32,1,4.000000e+000,7.820129e-004,0.000000e+000,0,,0,
1524307435.205,,0.000000e+000,3.500067e+001,2.644961e-006,0.000000e+000,2,6.506033e-001,0.000000e+000,,,,,,,,,,,,,,32,1,4.000000e+000,2.338409e-003,0.000000e+000,0,,0,
1524307474.093,,0.000000e+000,3.499872e+001,2.598610e-006,0.000000e+000,2,6.381429e-001,0.000000e+000,,,,,,,,,,,,,,32,1,4.000000e+000,0.000000e+000,0.000000e+000,0,,0,
1524307511.069,,0.000000e+000,3.499911e+001,2.595281e-006,0.000000e+000,2,6.462466e-001,0.000000e+000,,,,,,,,,,,,,,32,1,4.000000e+000,7.820129e-004,0.000000e+000,0,,0,
1524307549.152,,0.000000e+000,3.500028e+001,2.637696e-006,0.000000e+000,2,6.527586e-001,0.000000e+000,,,,,,,,,,,,,,32,1,4.000000e+000,0.000000e+000,0.000000e+000,0,,0,
1524307586.572,,0.000000e+000,3.499950e+001,2.688747e-006,0.000000e+000,2,6.556823e-001,0.000000e+000,,,,,,,,,,,,,,32,1,4.000000e+000,0.000000e+000,0.000000e+000,0,,0,
1524307624.410,,0.000000e+000,3.500028e+001,2.735614e-006,0.000000e+000,2,6.633857e-001,0.000000e+000,,,,,,,,,,,,,,32,1,4.000000e+000,0.000000e+000,0.000000e+000,0,,0,
1524307661.981,,0.000000e+000,3.499950e+001,2.704967e-006,0.000000e+000,2,6.606253e-001,0.000000e+000,,,,,,,,,,,,,,32,1,4.000000e+000,1.560211e-003,0.000000e+000,0,,0,
1524307699.694,,0.000000e+000,3.499911e+001,2.685652e-006,0.000000e+000,2,6.538029e-001,0.000000e+000,,,,,,,,,,,,,,32,1,4.000000e+000,7.820129e-004,0.000000e+000,0,,0,
1524307737.687,,0.000000e+000,3.499833e+001,2.681343e-006,0.000000e+000,2,6.630169e-001,0.000000e+000,,,,,,,,,,,,,,32,1,4.000000e+000,7.781982e-004,0.000000e+000,0,,0,
1524307775.763,,0.000000e+000,3.499911e+001,2.733914e-006,0.000000e+000,2,6.646874e-001,0.000000e+000,,,,,,,,,,,,,,32,1,4.000000e+000,7.820129e-004,0.000000e+000,0,,0,
1524307813.928,,0.000000e+000,3.499911e+001,2.752481e-006,0.000000e+000,2,6.623802e-001,0.000000e+000,,,,,,,,,,,,,,32,1,4.000000e+000,7.820129e-004,0.000000e+000,0,,0,
1524307851.901,,0.000000e+000,3.499872e+001,2.757607e-006,0.000000e+000,2,6.626713e-001,0.000000e+000,,,,,,,,,,,,,,32,1,4.000000e+000,1.560211e-003,0.000000e+000,0,,0,
1524307889.972,,0.000000e+000,3.499872e+001,2.785605e-006,0.000000e+000,2,6.619386e-001,0.000000e+000,,,,,,,,,,,,,,32,1,4.000000e+000,1.560211e-003,0.000000e+000,0,,0,
1524307927.975,,0.000000e+000,3.499911e+001,2.771931e-006,0.000000e+000,2,6.779855e-001,0.000000e+000,,,,,,,,,,,,,,32,1,4.000000e+000,7.820129e-004,0.000000e+000,0,,0,
1524307966.135,,0.000000e+000,3.499989e+001,2.803702e-006,0.000000e+000,2,6.477259e-001,0.000000e+000,,,,,,,,,,,,,,32,1,4.000000e+000,7.781982e-004,0.000000e+000,0,,0,
1524308004.149,,0.000000e+000,3.499872e+001,2.841034e-006,0.000000e+000,2,6.744692e-001,0.000000e+000,,,,,,,,,,,,,,32,1,4.000000e+000,0.000000e+000,0.000000e+000,0,,0,
1524308042.592,,0.000000e+000,3.500028e+001,2.864211e-006,0.000000e+000,2,6.685567e-001,0.000000e+000,,,,,,,,,,,,,,32,1,4.000000e+000,1.560211e-003,0.000000e+000,0,,0,
1524308080.515,,0.000000e+000,3.499872e+001,2.901175e-006,0.000000e+000,2,6.714232e-001,0.000000e+000,,,,,,,,,,,,,,32,1,4.000000e+000,1.560211e-003,0.000000e+000,0,,0,
1524308118.393,,0.000000e+000,3.499989e+001,2.868677e-006,0.000000e+000,2,6.784981e-001,0.000000e+000,,,,,,,,,,,,,,32,1,4.000000e+000,7.781982e-004,0.000000e+000,0,,0,
1524308156.023,,0.000000e+000,3.499989e+001,2.902535e-006,0.000000e+000,2,6.873107e-001,0.000000e+000,,,,,,,,,,,,,,32,1,4.000000e+000,7.781982e-004,0.000000e+000,0,,0,
1524308194.036,,0.000000e+000,3.499950e+001,2.908542e-006,0.000000e+000,2,6.617589e-001,0.000000e+000,,,,,,,,,,,,,,32,1,4.000000e+000,0.000000e+000,0.000000e+000,0,,0,
1524308232.082,,0.000000e+000,3.499911e+001,2.905952e-006,0.000000e+000,2,6.882919e-001,0.000000e+000,,,,,,,,,,,,,,32,1,4.000000e+000,7.820129e-004,0.000000e+000,0,,0,
1524308270.165,,0.000000e+000,3.499989e+001,2.906229e-006,0.000000e+000,2,6.757666e-001,0.000000e+000,,,,,,,,,,,,,,32,1,4.000000e+000,7.781982e-004,0.000000e+000,0,,0,
1524308307.780,,0.000000e+000,3.499872e+001,2.933302e-006,0.000000e+000,2,6.804613e-001,0.000000e+000,,,,,,,,,,,,,,32,1,4.000000e+000,0.000000e+000,0.000000e+000,0,,0,
1524308346.336,,0.000000e+000,3.499911e+001,2.975532e-006,0.000000e+000,2,6.860442e-001,0.000000e+000,,,,,,,,,,,,,,32,1,4.000000e+000,7.820129e-004,0.000000e+000,0,,0,
1524308383.884,,0.000000e+000,3.499911e+001,2.957751e-006,0.000000e+000,2,6.839517e-001,0.000000e+000,,,,,,,,,,,,,,32,1,4.000000e+000,7.820129e-004,0.000000e+000,0,,0,
1524308422.005,,0.000000e+000,3.500028e+001,2.970809e-006,0.000000e+000,2,6.862285e-001,0.000000e+000,,,,,,,,,,,,,,32,1,4.000000e+000,0.000000e+000,0.000000e+000,0,,0,
1524308460.550,,0.000000e+000,3.499911e+001,3.012388e-006,0.000000e+000,2,6.914576e-001,0.000000e+000,,,,,,,,,,,,,,32,1,4.000000e+000,7.820129e-004,0.000000e+000,0,,0,
1524308498.451,,0.000000e+000,3.499793e+001,3.028027e-006,0.000000e+000,2,6.896912e-001,0.000000e+000,,,,,,,,,,,,,,32,1,4.000000e+000,1.567841e-003,0.000000e+000,0,,0,
1524308536.434,,0.000000e+000,3.499833e+001,3.028540e-006,0.000000e+000,2,6.889054e-001,0.000000e+000,,,,,,,,,,,,,,32,1,4.000000e+000,7.781982e-004,0.000000e+000,0,,0,
1524308574.234,,0.000000e+000,3.499950e+001,3.018237e-006,0.000000e+000,2,6.953138e-001,0.000000e+000,,,,,,,,,,,,,,32,1,4.000000e+000,0.000000e+000,0.000000e+000,0,,0,
1524308612.162,,0.000000e+000,3.499911e+001,3.082704e-006,0.000000e+000,2,6.890464e-001,0.000000e+000,,,,,,,,,,,,,,32,1,4.000000e+000,7.820129e-004,0.000000e+000,0,,0,
1524308650.261,,0.000000e+000,3.499989e+001,3.094895e-006,0.000000e+000,2,6.896085e-001,0.000000e+000,,,,,,,,,,,,,,32,1,4.000000e+000,7.781982e-004,0.000000e+000,0,,0,
1524308688.311,,0.000000e+000,3.499793e+001,3.087228e-006,0.000000e+000,2,6.893964e-001,0.000000e+000,,,,,,,,,,,,,,32,1,4.000000e+000,3.131866e-003,0.000000e+000,0,,0,
1524308725.577,,0.000000e+000,3.499872e+001,3.079626e-006,0.000000e+000,2,7.036961e-001,0.000000e+000,,,,,,,,,,,,,,32,1,4.000000e+000,0.000000e+000,0.000000e+000,0,,0,
1524308762.892,,0.000000e+000,3.499911e+001,3.082498e-006,0.000000e+000,2,6.964331e-001,0.000000e+000,,,,,,,,,,,,,,32,1,4.000000e+000,7.820129e-004,0.000000e+000,0,,0,
1524308800.955,,0.000000e+000,3.499950e+001,3.078288e-006,0.000000e+000,2,6.879740e-001,0.000000e+000,,,,,,,,,,,,,,32,1,4.000000e+000,0.000000e+000,0.000000e+000,0,,0,
1524308839.031,,0.000000e+000,3.499911e+001,3.130374e-006,0.000000e+000,2,6.954303e-001,0.000000e+000,,,,,,,,,,,,,,32,1,4.000000e+000,7.820129e-004,0.000000e+000,0,,0,
1524308877.059,,0.000000e+000,3.499872e+001,3.144491e-006,0.000000e+000,2,6.975277e-001,0.000000e+000,,,,,,,,,,,,,,32,1,4.000000e+000,0.000000e+000,0.000000e+000,0,,0,
1524308915.312,,0.000000e+000,3.499950e+001,3.144800e-006,0.000000e+000,2,6.985415e-001,0.000000e+000,,,,,,,,,,,,,,32,1,4.000000e+000,0.000000e+000,0.000000e+000,0,,0,
1524308953.202,,0.000000e+000,3.499872e+001,3.139158e-006,0.000000e+000,2,7.032611e-001,0.000000e+000,,,,,,,,,,,,,,32,1,4.000000e+000,1.560211e-003,0.000000e+000,0,,0,
1524308991.323,,0.000000e+000,3.499989e+001,3.162953e-006,0.000000e+000,2,7.036723e-001,0.000000e+000,,,,,,,,,,,,,,32,1,4.000000e+000,2.342224e-003,0.000000e+000,0,,0,
1524309029.411,,0.000000e+000,3.499833e+001,3.182191e-006,0.000000e+000,2,6.988449e-001,0.000000e+000,,,,,,,,,,,,,,32,1,4.000000e+000,7.781982e-004,0.000000e+000,0,,0,
1524309067.482,,0.000000e+000,3.499950e+001,3.203212e-006,0.000000e+000,2,7.064161e-001,0.000000e+000,,,,,,,,,,,,,,32,1,4.000000e+000,0.000000e+000,0.000000e+000,0,,0,
1524309105.657,,0.000000e+000,3.499871e+001,3.229467e-006,0.000000e+000,2,7.013682e-001,0.000000e+000,,,,,,,,,,,,,,32,1,4.000000e+000,3.128052e-003,0.000000e+000,0,,0,
1524309143.585,,0.000000e+000,3.499872e+001,3.213711e-006,0.000000e+000,2,7.083609e-001,0.000000e+000,,,,,,,,,,,,,,32,1,4.000000e+000,0.000000e+000,0.000000e+000,0,,0,
1524309181.206,,0.000000e+000,3.499793e+001,3.241439e-006,0.000000e+000,2,7.106718e-001,0.000000e+000,,,,,,,,,,,,,,32,1,4.000000e+000,1.567841e-003,0.000000e+000,0,,0,
1524309218.799,,0.000000e+000,3.499950e+001,3.245805e-006,0.000000e+000,2,7.077941e-001,0.000000e+000,,,,,,,,,,,,,,32,1,4.000000e+000,1.560211e-003,0.000000e+000,0,,0,
1524309257.109,,0.000000e+000,3.499793e+001,3.253487e-006,0.000000e+000,2,7.096241e-001,0.000000e+000,,,,,,,,,,,,,,32,1,4.000000e+000,1.567841e-003,0.000000e+000,0,,0,
1524309294.880,,0.000000e+000,3.499911e+001,3.273153e-006,0.000000e+000,2,7.095308e-001,0.000000e+000,,,,,,,,,,,,,,32,1,4.000000e+000,7.820129e-004,0.000000e+000,0,,0,
1524309332.921,,0.000000e+000,3.499872e+001,3.252904e-006,0.000000e+000,2,7.086297e-001,0.000000e+000,,,,,,,,,,,,,,32,1,4.000000e+000,1.560211e-003,0.000000e+000,0,,0,
1524309370.771,,0.000000e+000,3.499989e+001,3.249328e-006,0.000000e+000,2,7.139185e-001,0.000000e+000,,,,,,,,,,,,,,32,1,4.000000e+000,7.781982e-004,0.000000e+000,0,,0,
1524309408.579,,0.000000e+000,3.499872e+001,3.272021e-006,0.000000e+000,2,7.111970e-001,0.000000e+000,,,,,,,,,,,,,,32,1,4.000000e+000,0.000000e+000,0.000000e+000,0,,0,
1524309447.225,,0.000000e+000,3.499872e+001,3.321214e-006,0.000000e+000,2,7.146178e-001,0.000000e+000,,,,,,,,,,,,,,32,1,4.000000e+000,1.560211e-003,0.000000e+000,0,,0,
1524309484.758,,0.000000e+000,3.499989e+001,3.304237e-006,0.000000e+000,2,7.081413e-001,0.000000e+000,,,,,,,,,,,,,,32,1,4.000000e+000,7.781982e-004,0.000000e+000,0,,0,
1524309523.383,,0.000000e+000,3.499911e+001,3.319248e-006,0.000000e+000,2,7.127148e-001,0.000000e+000,,,,,,,,,,,,,,32,1,4.000000e+000,7.820129e-004,0.000000e+000,0,,0,
1524309560.376,,0.000000e+000,3.499872e+001,3.310663e-006,0.000000e+000,2,7.192224e-001,0.000000e+000,,,,,,,,,,,,,,32,1,4.000000e+000,1.560211e-003,0.000000e+000,0,,0,
1524309598.474,,0.000000e+000,3.499911e+001,3.325045e-006,0.000000e+000,2,7.148942e-001,0.000000e+000,,,,,,,,,,,,,,32,1,4.000000e+000,7.820129e-004,0.000000e+000,0,,0,
1524309636.535,,0.000000e+000,3.500028e+001,3.352855e-006,0.000000e+000,2,7.162768e-001,0.000000e+000,,,,,,,,,,,,,,32,1,4.000000e+000,0.000000e+000,0.000000e+000,0,,0,
1524309674.503,,0.000000e+000,3.500028e+001,3.376923e-006,0.000000e+000,2,7.040536e-001,0.000000e+000,,,,,,,,,,,,,,32,1,4.000000e+000,0.000000e+000,0.000000e+000,0,,0,
1524309712.644,,0.000000e+000,3.499950e+001,3.392783e-006,0.000000e+000,2,7.156181e-001,0.000000e+000,,,,,,,,,,,,,,32,1,4.000000e+000,1.560211e-003,0.000000e+000,0,,0,
1524309750.709,,0.000000e+000,3.499872e+001,3.382635e-006,0.000000e+000,2,7.206789e-001,0.000000e+000,,,,,,,,,,,,,,32,1,4.000000e+000,0.000000e+000,0.000000e+000,0,,0,
1524309788.792,,0.000000e+000,3.500106e+001,3.389800e-006,0.000000e+000,2,7.197299e-001,0.000000e+000,,,,,,,,,,,,,,32,1,4.000000e+000,1.560211e-003,0.000000e+000,0,,0,
1524309826.870,,0.000000e+000,3.500067e+001,3.401419e-006,0.000000e+000,2,7.215150e-001,0.000000e+000,,,,,,,,,,,,,,32,1,4.000000e+000,2.338409e-003,0.000000e+000,0,,0,
1524309864.738,,0.000000e+000,3.499872e+001,3.435772e-006,0.000000e+000,2,7.200734e-001,0.000000e+000,,,,,,,,,,,,,,32,1,4.000000e+000,0.000000e+000,0.000000e+000,0,,0,
1524309902.421,,0.000000e+000,3.499950e+001,3.451608e-006,0.000000e+000,2,7.221944e-001,0.000000e+000,,,,,,,,,,,,,,32,1,4.000000e+000,1.560211e-003,0.000000e+000,0,,0,
1524309940.467,,0.000000e+000,3.499989e+001,3.460902e-006,0.000000e+000,2,7.304853e-001,0.000000e+000,,,,,,,,,,,,,,32,1,4.000000e+000,2.342224e-003,0.000000e+000,0,,0,
1524309978.243,,0.000000e+000,3.499872e+001,3.473569e-006,0.000000e+000,2,7.297500e-001,0.000000e+000,,,,,,,,,,,,,,32,1,4.000000e+000,1.560211e-003,0.000000e+000,0,,0,
1524310016.623,,0.000000e+000,3.499911e+001,3.431330e-006,0.000000e+000,2,7.259073e-001,0.000000e+000,,,,,,,,,,,,,,32,1,4.000000e+000,7.820129e-004,0.000000e+000,0,,0,
1524310054.634,,0.000000e+000,3.499989e+001,3.473809e-006,0.000000e+000,2,7.241856e-001,0.000000e+000,,,,,,,,,,,,,,32,1,4.000000e+000,7.781982e-004,0.000000e+000,0,,0,
1524310092.412,,0.000000e+000,3.500028e+001,3.528252e-006,0.000000e+000,2,7.268768e-001,0.000000e+000,,,,,,,,,,,,,,32,1,4.000000e+000,0.000000e+000,0.000000e+000,0,,0,
1524310130.775,,0.000000e+000,3.499872e+001,3.496440e-006,0.000000e+000,2,7.325501e-001,0.000000e+000,,,,,,,,,,,,,,32,1,4.000000e+000,0.000000e+000,0.000000e+000,0,,0,
1524310168.515,,0.000000e+000,3.500106e+001,3.483468e-006,0.000000e+000,2,7.319247e-001,0.000000e+000,,,,,,,,,,,,,,32,1,4.000000e+000,3.128052e-003,0.000000e+000,0,,0,
1524310206.636,,0.000000e+000,3.499950e+001,3.477033e-006,0.000000e+000,2,7.231811e-001,0.000000e+000,,,,,,,,,,,,,,32,1,4.000000e+000,0.000000e+000,0.000000e+000,0,,0,
1524310244.721,,0.000000e+000,3.499950e+001,3.536459e-006,0.000000e+000,2,7.292553e-001,0.000000e+000,,,,,,,,,,,,,,32,1,4.000000e+000,1.560211e-003,0.000000e+000,0,,0,
1524310282.762,,0.000000e+000,3.500067e+001,3.548415e-006,0.000000e+000,2,7.316255e-001,0.000000e+000,,,,,,,,,,,,,,32,1,4.000000e+000,7.820129e-004,0.000000e+000,0,,0,
1524310320.537,,0.000000e+000,3.499911e+001,3.549062e-006,0.000000e+000,2,7.274226e-001,0.000000e+000,,,,,,,,,,,,,,32,1,4.000000e+000,7.820129e-004,0.000000e+000,0,,0,
1524310358.603,,0.000000e+000,3.499911e+001,3.511688e-006,0.000000e+000,2,7.339189e-001,0.000000e+000,,,,,,,,,,,,,,32,1,4.000000e+000,7.820129e-004,0.000000e+000,0,,0,
1524310397.679,,0.000000e+000,3.499911e+001,3.526740e-006,0.000000e+000,2,7.311826e-001,0.000000e+000,,,,,,,,,,,,,,32,1,4.000000e+000,7.820129e-004,0.000000e+000,0,,0,
1524310435.884,,0.000000e+000,3.499872e+001,3.568678e-006,0.000000e+000,2,7.320545e-001,0.000000e+000,,,,,,,,,,,,,,32,1,4.000000e+000,0.000000e+000,0.000000e+000,0,,0,
1524310473.987,,0.000000e+000,3.499911e+001,3.577620e-006,0.000000e+000,2,7.337739e-001,0.000000e+000,,,,,,,,,,,,,,32,1,4.000000e+000,7.820129e-004,0.000000e+000,0,,0,
1524310511.963,,0.000000e+000,3.499950e+001,3.576026e-006,0.000000e+000,2,7.321623e-001,0.000000e+000,,,,,,,,,,,,,,32,1,4.000000e+000,0.000000e+000,0.000000e+000,0,,0,
1524310550.151,,0.000000e+000,3.499911e+001,3.581901e-006,0.000000e+000,2,7.350423e-001,0.000000e+000,,,,,,,,,,,,,,32,1,4.000000e+000,2.338409e-003,0.000000e+000,0,,0,
1524310588.209,,0.000000e+000,3.499950e+001,3.613404e-006,0.000000e+000,2,7.332228e-001,0.000000e+000,,,,,,,,,,,,,,32,1,4.000000e+000,1.560211e-003,0.000000e+000,0,,0,
1524310626.242,,0.000000e+000,3.499872e+001,3.593077e-006,0.000000e+000,2,7.338493e-001,0.000000e+000,,,,,,,,,,,,,,32,1,4.000000e+000,0.000000e+000,0.000000e+000,0,,0,
1524310664.380,,0.000000e+000,3.499989e+001,3.637084e-006,0.000000e+000,2,7.390754e-001,0.000000e+000,,,,,,,,,,,,,,32,1,4.000000e+000,7.781982e-004,0.000000e+000,0,,0,
1524310702.863,,0.000000e+000,3.499950e+001,3.658827e-006,0.000000e+000,2,7.392814e-001,0.000000e+000,,,,,,,,,,,,,,32,1,4.000000e+000,0.000000e+000,0.000000e+000,0,,0,
1524310740.034,,0.000000e+000,3.499950e+001,3.633621e-006,0.000000e+000,2,7.368333e-001,0.000000e+000,,,,,,,,,,,,,,32,1,4.000000e+000,0.000000e+000,0.000000e+000,0,,0,
1524310778.494,,0.000000e+000,3.499911e+001,3.617193e-006,0.000000e+000,2,7.392992e-001,0.000000e+000,,,,,,,,,,,,,,32,1,4.000000e+000,7.820129e-004,0.000000e+000,0,,0,
1524310816.442,,0.000000e+000,3.499989e+001,3.665975e-006,0.000000e+000,2,7.262468e-001,0.000000e+000,,,,,,,,,,,,,,32,1,4.000000e+000,7.781982e-004,0.000000e+000,0,,0,
1524310855.035,,0.000000e+000,3.500028e+001,3.687160e-006,0.000000e+000,2,7.423123e-001,0.000000e+000,,,,,,,,,,,,,,32,1,4.000000e+000,0.000000e+000,0.000000e+000,0,,0,
1524310893.121,,0.000000e+000,3.499911e+001,3.693146e-006,0.000000e+000,2,7.418906e-001,0.000000e+000,,,,,,,,,,,,,,32,1,4.000000e+000,7.820129e-004,0.000000e+000,0,,0,
1524310931.204,,0.000000e+000,3.499911e+001,3.700371e-006,0.000000e+000,2,7.364941e-001,0.000000e+000,,,,,,,,,,,,,,32,1,4.000000e+000,2.338409e-003,0.000000e+000,0,,0,
1524310968.989,,0.000000e+000,3.499950e+001,3.684361e-006,0.000000e+000,2,7.419412e-001,0.000000e+000,,,,,,,,,,,,,,32,1,4.000000e+000,0.000000e+000,0.000000e+000,0,,0,
1524311007.370,,0.000000e+000,3.499872e+001,3.681796e-006,0.000000e+000,2,7.399443e-001,0.000000e+000,,,,,,,,,,,,,,32,1,4.000000e+000,1.560211e-003,0.000000e+000,0,,0,
1524311045.173,,0.000000e+000,3.499911e+001,3.700569e-006,0.000000e+000,2,7.459461e-001,0.000000e+000,,,,,,,,,,,,,,32,1,4.000000e+000,7.820129e-004,0.000000e+000,0,,0,
1524311083.066,,0.000000e+000,3.499950e+001,3.722245e-006,0.000000e+000,2,7.468229e-001,0.000000e+000,,,,,,,,,,,,,,32,1,4.000000e+000,0.000000e+000,0.000000e+000,0,,0,
1524311121.754,,0.000000e+000,3.499911e+001,3.713578e-006,0.000000e+000,2,7.397509e-001,0.000000e+000,,,,,,,,,,,,,,32,1,4.000000e+000,7.820129e-004,0.000000e+000,0,,0,
1524311159.967,,0.000000e+000,3.499989e+001,3.745611e-006,0.000000e+000,2,7.457737e-001,0.000000e+000,,,,,,,,,,,,,,32,1,4.000000e+000,7.781982e-004,0.000000e+000,0,,0,
1524311198.053,,0.000000e+000,3.499950e+001,3.764896e-006,0.000000e+000,2,7.473220e-001,0.000000e+000,,,,,,,,,,,,,,32,1,4.000000e+000,1.560211e-003,0.000000e+000,0,,0,
1524311236.413,,0.000000e+000,3.499911e+001,3.752846e-006,0.000000e+000,2,7.448403e-001,0.000000e+000,,,,,,,,,,,,,,32,1,4.000000e+000,7.820129e-004,0.000000e+000,0,,0,
1524311273.954,,0.000000e+000,3.499872e+001,3.788017e-006,0.000000e+000,2,7.478331e-001,0.000000e+000,,,,,,,,,,,,,,32,1,4.000000e+000,1.560211e-003,0.000000e+000,0,,0,
1524311312.562,,0.000000e+000,3.499989e+001,3.778660e-006,0.000000e+000,2,7.451269e-001,0.000000e+000,,,,,,,,,,,,,,32,1,4.000000e+000,7.781982e-004,0.000000e+000,0,,0,
1524311351.473,,0.000000e+000,3.499950e+001,3.778248e-006,0.000000e+000,2,7.475964e-001,0.000000e+000,,,,,,,,,,,,,,32,1,4.000000e+000,1.560211e-003,0.000000e+000,0,,0,
1524311390.118,,0.000000e+000,3.499911e+001,3.805491e-006,0.000000e+000,2,7.399317e-001,0.000000e+000,,,,,,,,,,,,,,32,1,4.000000e+000,7.820129e-004,0.000000e+000,0,,0,
1524311427.846,,0.000000e+000,3.499911e+001,3.800295e-006,0.000000e+000,2,7.474485e-001,0.000000e+000,,,,,,,,,,,,,,32,1,4.000000e+000,7.820129e-004,0.000000e+000,0,,0,
1524311465.684,,0.000000e+000,3.499872e+001,3.826005e-006,0.000000e+000,2,7.506223e-001,0.000000e+000,,,,,,,,,,,,,,32,1,4.000000e+000,1.560211e-003,0.000000e+000,0,,0,
1524311503.340,,0.000000e+000,3.499911e+001,3.807602e-006,0.000000e+000,2,7.518702e-001,0.000000e+000,,,,,,,,,,,,,,32,1,4.000000e+000,7.820129e-004,0.000000e+000,0,,0,
1524311541.290,,0.000000e+000,3.499794e+001,3.783363e-006,0.000000e+000,2,7.436181e-001,0.000000e+000,,,,,,,,,,,,,,32,1,4.000000e+000,0.000000e+000,0.000000e+000,0,,0,
1524311578.981,,0.000000e+000,3.500106e+001,3.803426e-006,0.000000e+000,2,7.431496e-001,0.000000e+000,,,,,,,,,,,,,,32,1,4.000000e+000,1.560211e-003,0.000000e+000,0,,0,
1524311616.934,,0.000000e+000,3.499911e+001,3.784074e-006,0.000000e+000,2,7.513664e-001,0.000000e+000,,,,,,,,,,,,,,32,1,4.000000e+000,7.820129e-004,0.000000e+000,0,,0,
1524311655.012,,0.000000e+000,3.499911e+001,3.838232e-006,0.000000e+000,2,7.505346e-001,0.000000e+000,,,,,,,,,,,,,,32,1,4.000000e+000,7.820129e-004,0.000000e+000,0,,0,
1524311693.118,,0.000000e+000,3.499989e+001,3.876146e-006,0.000000e+000,2,7.495555e-001,0.000000e+000,,,,,,,,,,,,,,32,1,4.000000e+000,2.342224e-003,0.000000e+000,0,,0,
1524311731.251,,0.000000e+000,3.499872e+001,3.859344e-006,0.000000e+000,2,7.481015e-001,0.000000e+000,,,,,,,,,,,,,,32,1,4.000000e+000,0.000000e+000,0.000000e+000,0,,0,
1524311769.331,,0.000000e+000,3.499950e+001,3.881771e-006,0.000000e+000,2,7.512454e-001,0.000000e+000,,,,,,,,,,,,,,32,1,4.000000e+000,0.000000e+000,0.000000e+000,0,,0,
1524311807.382,,0.000000e+000,3.499989e+001,3.881329e-006,0.000000e+000,2,7.545109e-001,0.000000e+000,,,,,,,,,,,,,,32,1,4.000000e+000,7.781982e-004,0.000000e+000,0,,0,
1524311820.112,,0.000000e+000,3.499989e+001,3.889647e-006,0.000000e+000,2,7.567996e-001,0.000000e+000,,,,,,,,,,,,,,32,1,4.000000e+000,7.781982e-004,0.000000e+000,0,,0,