File: Experimental Raw Data/MFn1 VRM/raw/MFn1_VRMac_34K_3000s.dc.raw
[Header]
TITLE,MPMS DC Measurement
BYAPP,MPMS Measurement,2.1,Raw with ABS
FILEOPENTIME, 1524279388.471000 4/20/2018, 8:56:28 PM

INFO, APPNAME, MPMS MultiVu Application, Revision 1.61,  Build 082

INFO, NAME, MFn1
INFO, WEIGHT, 1.000
INFO, AREA, 1.000
INFO, LENGTH, 1.000
INFO, SHAPE, 0
INFO, COMMENT,
INFO, SEQUENCE FILE: VRMac_34K_3000s_VRMde_35K.seq


INFO, BACKGROUND DATA FILE:, None


STARTUPAXIS,X,8,LINEAR,AUTO,0.000000,0.000000
STARTUPAXIS,Y1,10,LINEAR,AUTO,0.000000,0.000000


STARTUPGROUP,Longitudinal
FIELDGROUP,Longitudinal,1,3,4,5,6,8,9,10,11,12,13,14,15,16,17,18,19,20,21,22,23
FIELDGROUP,Transverse,1,3,4,5,6,8,9,24,25,26,27,28,29,30,31,32,33,34,35,36,37

PLOT_APPEARANCE,ALL,HORZ_GRID_ON,VERT_GRID_ON,MARKERS_ONLY

[Data]
Time,Comment,Field (Oe),Start Temperature (K),End Temperature (K),Scan,Rejected,Position (cm),Rot Position (deg),Long Voltage,Long Average Voltage,Long Detrended Voltage,Long Demeaned Voltage,Long Regression Fit,Long Detrended Fit,Long Demeaned Fit,Long Scaled Response,Long Avg. Scaled Response,Long Background Response,Long Response [w/ABS],Long Detrended Resp. [w/ABS],Long Fit [w/ABS],Long Detrended Fit [w/ABS],Trans Voltage,Trans Average Voltage,Trans Detrended Voltage,Trans Demeaned Voltage,Trans Regression Fit,Trans Detrended Fit,Trans Demeaned Fit,Trans Scaled Response,Trans Avg Scaled Response,Trans Background Response,Trans Response [w/ABS],Trans Detrended Resp. [w/ABS],Trans Fit [w/ABS],Trans Detrended Fit [w/ABS],
1524279388.451,,0.000000e+000,3.400009e+001,3.399936e+001,1,0,0.000000e+000,0.000000e+000,1.922942e+000,1.922942e+000,7.865415e-001,7.865415e-001,2.013204e+000,8.768039e-001,8.768039e-001,1.164746e-004,1.164746e-004,,,,,,,,,,,,,,,,,,,,
1524279401.139,,0.000000e+000,3.399936e+001,3.400082e+001,1,0,1.290323e-001,0.000000e+000,2.008850e+000,2.008850e+000,9.127437e-001,9.112324e-001,2.110151e+000,1.014045e+000,1.012533e+000,1.306804e-004,1.306804e-004,,,,,,,,,,,,,,,,,,,,
1524279413.669,,0.000000e+000,3.399936e+001,3.400009e+001,1,0,2.580645e-001,0.000000e+000,2.183871e+000,2.183871e+000,1.034951e+000,1.031775e+000,2.265120e+000,1.116200e+000,1.113024e+000,1.442877e-004,1.442877e-004,,,,,,,,,,,,,,,,,,,,
1524279426.429,,0.000000e+000,3.400009e+001,3.400009e+001,1,0,3.870968e-001,0.000000e+000,2.254063e+000,2.254063e+000,1.101455e+000,1.096578e+000,2.304679e+000,1.152072e+000,1.147195e+000,1.516768e-004,1.516768e-004,,,,,,,,,,,,,,,,,,,,
1524279438.549,,0.000000e+000,3.399862e+001,3.400082e+001,1,0,5.161290e-001,0.000000e+000,2.232853e+000,2.232853e+000,1.076767e+000,1.069897e+000,2.252185e+000,1.096099e+000,1.089229e+000,1.490293e-004,1.490293e-004,,,,,,,,,,,,,,,,,,,,
1524279450.610,,0.000000e+000,3.399788e+001,3.400009e+001,1,0,6.451613e-001,0.000000e+000,2.108492e+000,2.108492e+000,9.527431e-001,9.442258e-001,2.093967e+000,9.382189e-001,9.297016e-001,1.353058e-004,1.353058e-004,,,,,,,,,,,,,,,,,,,,
1524279463.822,,0.000000e+000,3.399788e+001,3.400082e+001,1,0,7.741935e-001,0.000000e+000,1.888762e+000,1.888762e+000,7.325360e-001,7.221624e-001,1.844121e+000,6.878950e-001,6.775213e-001,1.109872e-004,1.109872e-004,,,,,,,,,,,,,,,,,,,,
1524279475.782,,0.000000e+000,3.399936e+001,3.400009e+001,1,0,9.032258e-001,0.000000e+000,1.547265e+000,1.547265e+000,4.394273e-001,4.265847e-001,1.473826e+000,3.659884e-001,3.531458e-001,7.867636e-005,7.867636e-005,,,,,,,,,,,,,,,,,,,,
1524279488.545,,0.000000e+000,3.399862e+001,3.399862e+001,1,0,1.032258e+000,0.000000e+000,1.241321e+000,1.241321e+000,8.743481e-002,7.329118e-002,1.146869e+000,-7.017689e-003,-2.116132e-002,3.973652e-005,3.973652e-005,,,,,,,,,,,,,,,,,,,,
1524279501.188,,0.000000e+000,3.399788e+001,3.399936e+001,1,0,1.161290e+000,0.000000e+000,8.531319e-001,8.531319e-001,-2.998217e-001,-3.156452e-001,7.367861e-001,-4.161676e-001,-4.319910e-001,-3.053530e-006,-3.053530e-006,,,,,,,,,,,,,,,,,,,,
1524279513.991,,0.000000e+000,3.399862e+001,3.400082e+001,1,0,1.290323e+000,0.000000e+000,4.303044e-001,4.303044e-001,-7.211708e-001,-7.385973e-001,2.992306e-001,-8.522447e-001,-8.696711e-001,-4.962010e-005,-4.962010e-005,,,,,,,,,,,,,,,,,,,,
1524279526.808,,0.000000e+000,3.399788e+001,3.399788e+001,1,0,1.419355e+000,0.000000e+000,-1.541161e-002,-1.541161e-002,-1.165588e+000,-1.185164e+000,-1.557671e-001,-1.305944e+000,-1.325519e+000,-9.871027e-005,-9.871027e-005,,,,,,,,,,,,,,,,,,,,
1524279539.651,,0.000000e+000,3.399788e+001,3.399936e+001,1,0,1.548387e+000,0.000000e+000,-4.727245e-001,-4.727245e-001,-1.621523e+000,-1.642847e+000,-6.096159e-001,-1.758415e+000,-1.779738e+000,-1.490922e-004,-1.490922e-004,,,,,,,,,,,,,,,,,,,,
1524279552.199,,0.000000e+000,3.399862e+001,3.400082e+001,1,0,1.677419e+000,0.000000e+000,-9.111162e-001,-9.111162e-001,-2.057879e+000,-2.081555e+000,-1.027753e+000,-2.174515e+000,-2.198191e+000,-1.973115e-004,-1.973115e-004,,,,,,,,,,,,,,,,,,,,
1524279564.776,,0.000000e+000,3.400082e+001,3.399936e+001,1,0,1.806452e+000,0.000000e+000,-1.287404e+000,-1.287404e+000,-2.432146e+000,-2.457143e+000,-1.359138e+000,-2.503880e+000,-2.528878e+000,-2.386878e-004,-2.386878e-004,,,,,,,,,,,,,,,,,,,,
1524279578.864,,0.000000e+000,3.399936e+001,3.399936e+001,1,0,1.935484e+000,0.000000e+000,-1.527428e+000,-1.527428e+000,-2.669679e+000,-2.697362e+000,-1.546206e+000,-2.688457e+000,-2.716140e+000,-2.649875e-004,-2.649875e-004,,,,,,,,,,,,,,,,,,,,
1524279591.999,,0.000000e+000,3.399788e+001,3.399936e+001,1,0,2.064516e+000,0.000000e+000,-1.586938e+000,-1.586938e+000,-2.727659e+000,-2.756437e+000,-1.552537e+000,-2.693257e+000,-2.722036e+000,-2.714659e-004,-2.714659e-004,,,,,,,,,,,,,,,,,,,,
1524279604.822,,0.000000e+000,3.399936e+001,3.399862e+001,1,0,2.193548e+000,0.000000e+000,-1.456931e+000,-1.456931e+000,-2.595224e+000,-2.626139e+000,-1.377270e+000,-2.515563e+000,-2.546478e+000,-2.569410e-004,-2.569410e-004,,,,,,,,,,,,,,,,,,,,
1524279617.445,,0.000000e+000,3.399862e+001,3.400009e+001,1,0,2.322581e+000,0.000000e+000,-1.168078e+000,-1.168078e+000,-2.304321e+000,-2.337312e+000,-1.055413e+000,-2.191656e+000,-2.224647e+000,-2.249423e-004,-2.249423e-004,,,,,,,,,,,,,,,,,,,,
1524279630.247,,0.000000e+000,3.400009e+001,3.399936e+001,1,0,2.451613e+000,0.000000e+000,-7.679866e-001,-7.679866e-001,-1.902580e+000,-1.936796e+000,-6.429503e-001,-1.777543e+000,-1.811760e+000,-1.807036e-004,-1.807036e-004,,,,,,,,,,,,,,,,,,,,
1524279642.870,,0.000000e+000,3.399936e+001,3.399862e+001,1,0,2.580645e+000,0.000000e+000,-3.192187e-001,-3.192187e-001,-1.450900e+000,-1.488050e+000,-1.923769e-001,-1.324058e+000,-1.361208e+000,-1.309869e-004,-1.309869e-004,,,,,,,,,,,,,,,,,,,,
1524279655.913,,0.000000e+000,3.399862e+001,3.399936e+001,1,0,2.709677e+000,0.000000e+000,1.377890e-001,1.377890e-001,-9.916580e-001,-1.029749e+000,2.625970e-001,-8.668500e-001,-9.049408e-001,-8.040137e-005,-8.040137e-005,,,,,,,,,,,,,,,,,,,,
1524279668.213,,0.000000e+000,3.399862e+001,3.399862e+001,1,0,2.838710e+000,0.000000e+000,5.889983e-001,5.889983e-001,-5.378926e-001,-5.790457e-001,7.022548e-001,-4.246361e-001,-4.657891e-001,-3.046160e-005,-3.046160e-005,,,,,,,,,,,,,,,,,,,,
1524279680.768,,0.000000e+000,3.399641e+001,3.399862e+001,1,0,2.967742e+000,0.000000e+000,1.016403e+000,1.016403e+000,-1.083534e-001,-1.512259e-001,1.117571e+000,-7.185846e-003,-5.005836e-002,1.682795e-005,1.682795e-005,,,,,,,,,,,,,,,,,,,,
1524279693.611,,0.000000e+000,3.399936e+001,3.399936e+001,1,0,3.096774e+000,0.000000e+000,1.414816e+000,1.414816e+000,2.920695e-001,2.479961e-001,1.498815e+000,3.760681e-001,3.319947e-001,6.092271e-005,6.092271e-005,,,,,,,,,,,,,,,,,,,,
1524279706.303,,0.000000e+000,3.399936e+001,3.399936e+001,1,0,3.225806e+000,0.000000e+000,1.777066e+000,1.777066e+000,6.574495e-001,6.102169e-001,1.829346e+000,7.097298e-001,6.624972e-001,1.010935e-004,1.010935e-004,,,,,,,,,,,,,,,,,,,,
1524279719.271,,0.000000e+000,3.399641e+001,3.399936e+001,1,0,3.354839e+000,0.000000e+000,2.074464e+000,2.074464e+000,9.570040e-001,9.091343e-001,2.089130e+000,9.716701e-001,9.238003e-001,1.340677e-004,1.340677e-004,,,,,,,,,,,,,,,,,,,,
1524279731.771,,0.000000e+000,3.399788e+001,3.399862e+001,1,0,3.483871e+000,0.000000e+000,2.283665e+000,2.283665e+000,1.167409e+000,1.118215e+000,2.256436e+000,1.140180e+000,1.090985e+000,1.571933e-004,1.571933e-004,,,,,,,,,,,,,,,,,,,,
1524279744.361,,0.000000e+000,3.399788e+001,3.399862e+001,1,0,3.612903e+000,0.000000e+000,2.378881e+000,2.378881e+000,1.265847e+000,1.214324e+000,2.317607e+000,1.204572e+000,1.153049e+000,1.679335e-004,1.679335e-004,,,,,,,,,,,,,,,,,,,,
1524279757.164,,0.000000e+000,3.399714e+001,3.399862e+001,1,0,3.741935e+000,0.000000e+000,2.365301e+000,2.365301e+000,1.254815e+000,1.200861e+000,2.283942e+000,1.173457e+000,1.119503e+000,1.665850e-004,1.665850e-004,,,,,,,,,,,,,,,,,,,,
1524279770.262,,0.000000e+000,3.399862e+001,3.399641e+001,1,0,3.870968e+000,0.000000e+000,2.273442e+000,2.273442e+000,1.165516e+000,1.110490e+000,2.180920e+000,1.072994e+000,1.017969e+000,1.566501e-004,1.566501e-004,,,,,,,,,,,,,,,,,,,,
1524279782.914,,0.000000e+000,3.400009e+001,3.399862e+001,1,0,4.000000e+000,0.000000e+000,2.084230e+000,2.084230e+000,1.028348e+000,9.695624e-001,1.990990e+000,9.351083e-001,8.763223e-001,1.413346e-004,1.413346e-004,,,,,,,,,,,,,,,,,,,,
1524279808.777,,0.000000e+000,3.399788e+001,3.399714e+001,1,0,0.000000e+000,0.000000e+000,2.001984e+000,2.001984e+000,8.412334e-001,8.412334e-001,2.097422e+000,9.366714e-001,9.366714e-001,1.250361e-004,1.250361e-004,,,,,,,,,,,,,,,,,,,,
1524279820.957,,0.000000e+000,3.399788e+001,3.400082e+001,1,0,1.290323e-001,0.000000e+000,2.128633e+000,2.128633e+000,9.693723e-001,9.674834e-001,2.235670e+000,1.076409e+000,1.074520e+000,1.390753e-004,1.390753e-004,,,,,,,,,,,,,,,,,,,,
1524279833.510,,0.000000e+000,3.399862e+001,3.399936e+001,1,0,2.580645e-001,0.000000e+000,2.250553e+000,2.250553e+000,1.094438e+000,1.090782e+000,2.335057e+000,1.178943e+000,1.175286e+000,1.526934e-004,1.526934e-004,,,,,,,,,,,,,,,,,,,,
1524279846.075,,0.000000e+000,3.399788e+001,3.399788e+001,1,0,3.870968e-001,0.000000e+000,2.312352e+000,2.312352e+000,1.158626e+000,1.153075e+000,2.366173e+000,1.212447e+000,1.206896e+000,1.596926e-004,1.596926e-004,,,,,,,,,,,,,,,,,,,,
1524279858.683,,0.000000e+000,3.399788e+001,3.399862e+001,1,0,5.161290e-001,0.000000e+000,2.281529e+000,2.281529e+000,1.130466e+000,1.123338e+000,2.300397e+000,1.149334e+000,1.142206e+000,1.564061e-004,1.564061e-004,,,,,,,,,,,,,,,,,,,,
1524279871.703,,0.000000e+000,3.399862e+001,3.399936e+001,1,0,6.451613e-001,0.000000e+000,2.143893e+000,2.143893e+000,9.968804e-001,9.879563e-001,2.127831e+000,9.808193e-001,9.718952e-001,1.415494e-004,1.415494e-004,,,,,,,,,,,,,,,,,,,,
1524279884.448,,0.000000e+000,3.399862e+001,3.399788e+001,1,0,7.741935e-001,0.000000e+000,1.908141e+000,1.908141e+000,7.612149e-001,7.501717e-001,1.864735e+000,7.178088e-001,7.067657e-001,1.154886e-004,1.154886e-004,,,,,,,,,,,,,,,,,,,,
1524279897.294,,0.000000e+000,3.399862e+001,3.399862e+001,1,0,9.032258e-001,0.000000e+000,1.598535e+000,1.598535e+000,4.539568e-001,4.409723e-001,1.525535e+000,3.809563e-001,3.679718e-001,8.148004e-005,8.148004e-005,,,,,,,,,,,,,,,,,,,,
1524279910.116,,0.000000e+000,3.399641e+001,3.399936e+001,1,0,1.032258e+000,0.000000e+000,1.227283e+000,1.227283e+000,8.556694e-002,7.082236e-002,1.134423e+000,-7.292688e-003,-2.203727e-002,4.071229e-005,4.071229e-005,,,,,,,,,,,,,,,,,,,,
1524279922.886,,0.000000e+000,3.399936e+001,3.399788e+001,1,0,1.161290e+000,0.000000e+000,8.200198e-001,8.200198e-001,-3.193901e-001,-3.356603e-001,7.077504e-001,-4.316595e-001,-4.479298e-001,-4.102360e-006,-4.102360e-006,,,,,,,,,,,,,,,,,,,,
1524279935.497,,0.000000e+000,3.399788e+001,3.399788e+001,1,0,1.290323e+000,0.000000e+000,3.851377e-001,3.851377e-001,-7.521257e-001,-7.699801e-001,2.545645e-001,-8.826990e-001,-9.005533e-001,-5.197313e-005,-5.197313e-005,,,,,,,,,,,,,,,,,,,,
1524279948.137,,0.000000e+000,3.399788e+001,3.399788e+001,1,0,1.419355e+000,0.000000e+000,-7.736324e-002,-7.736324e-002,-1.211609e+000,-1.231830e+000,-2.164512e-001,-1.350697e+000,-1.370918e+000,-1.027643e-004,-1.027643e-004,,,,,,,,,,,,,,,,,,,,
1524279960.702,,0.000000e+000,3.399567e+001,3.399862e+001,1,0,1.548387e+000,0.000000e+000,-5.491722e-001,-5.491722e-001,-1.681631e+000,-1.703349e+000,-6.846398e-001,-1.817099e+000,-1.838817e+000,-1.547359e-004,-1.547359e-004,,,,,,,,,,,,,,,,,,,,
1524279974.660,,0.000000e+000,3.399788e+001,3.399936e+001,1,0,1.677419e+000,0.000000e+000,-1.001602e+000,-1.001602e+000,-2.131636e+000,-2.155462e+000,-1.114271e+000,-2.244305e+000,-2.268131e+000,-2.045035e-004,-2.045035e-004,,,,,,,,,,,,,,,,,,,,
1524279986.482,,0.000000e+000,3.399862e+001,3.399862e+001,1,0,1.806452e+000,0.000000e+000,-1.382467e+000,-1.382467e+000,-2.510074e+000,-2.535419e+000,-1.453799e+000,-2.581406e+000,-2.606751e+000,-2.463711e-004,-2.463711e-004,,,,,,,,,,,,,,,,,,,,
1524279999.495,,0.000000e+000,3.399714e+001,3.399862e+001,1,0,1.935484e+000,0.000000e+000,-1.624018e+000,-1.624018e+000,-2.749521e+000,-2.777024e+000,-1.643897e+000,-2.769400e+000,-2.796903e+000,-2.729090e-004,-2.729090e-004,,,,,,,,,,,,,,,,,,,,
1524280011.993,,0.000000e+000,3.399788e+001,3.399936e+001,1,0,2.064516e+000,0.000000e+000,-1.684443e+000,-1.684443e+000,-2.807481e+000,-2.837157e+000,-1.647259e+000,-2.770296e+000,-2.799973e+000,-2.794298e-004,-2.794298e-004,,,,,,,,,,,,,,,,,,,,
1524280024.815,,0.000000e+000,3.399862e+001,3.399862e+001,1,0,2.193548e+000,0.000000e+000,-1.542382e+000,-1.542382e+000,-2.663228e+000,-2.694176e+000,-1.464019e+000,-2.584865e+000,-2.615812e+000,-2.636289e-004,-2.636289e-004,,,,,,,,,,,,,,,,,,,,
1524280037.343,,0.000000e+000,3.399714e+001,3.400009e+001,1,0,2.322581e+000,0.000000e+000,-1.240864e+000,-1.240864e+000,-2.359144e+000,-2.392126e+000,-1.132233e+000,-2.250513e+000,-2.283495e+000,-2.301951e-004,-2.301951e-004,,,,,,,,,,,,,,,,,,,,
1524280049.926,,0.000000e+000,3.399788e+001,3.399862e+001,1,0,2.451613e+000,0.000000e+000,-8.281071e-001,-8.281071e-001,-1.943749e+000,-1.977419e+000,-7.080861e-001,-1.823728e+000,-1.857398e+000,-1.844675e-004,-1.844675e-004,,,,,,,,,,,,,,,,,,,,
1524280062.929,,0.000000e+000,3.399862e+001,3.399788e+001,1,0,2.580645e+000,0.000000e+000,-3.714046e-001,-3.714046e-001,-1.484285e+000,-1.520561e+000,-2.447534e-001,-1.357634e+000,-1.393909e+000,-1.339025e-004,-1.339025e-004,,,,,,,,,,,,,,,,,,,,
1524280075.684,,0.000000e+000,3.399714e+001,3.399862e+001,1,0,2.709677e+000,0.000000e+000,9.979400e-002,9.979400e-002,-1.010391e+000,-1.048207e+000,2.220013e-001,-8.881835e-001,-9.259994e-001,-8.173086e-005,-8.173086e-005,,,,,,,,,,,,,,,,,,,,
1524280088.529,,0.000000e+000,3.399862e+001,3.399862e+001,1,0,2.838710e+000,0.000000e+000,5.622950e-001,5.622950e-001,-5.455762e-001,-5.846828e-001,6.730584e-001,-4.348128e-001,-4.739194e-001,-3.055119e-005,-3.055119e-005,,,,,,,,,,,,,,,,,,,,
1524280101.342,,0.000000e+000,3.399862e+001,3.399862e+001,1,0,2.967742e+000,0.000000e+000,9.965667e-001,9.965667e-001,-1.092802e-001,-1.492568e-001,1.098492e+000,-7.354523e-003,-4.733109e-002,1.749507e-005,1.749507e-005,,,,,,,,,,,,,,,,,,,,
1524280114.529,,0.000000e+000,3.399714e+001,3.399862e+001,1,0,3.096774e+000,0.000000e+000,1.407950e+000,1.407950e+000,3.055196e-001,2.624000e-001,1.487074e+000,3.846432e-001,3.415236e-001,6.311211e-005,6.311211e-005,,,,,,,,,,,,,,,,,,,,
1524280127.424,,0.000000e+000,3.399788e+001,3.399862e+001,1,0,3.225806e+000,0.000000e+000,1.778286e+000,1.778286e+000,6.777539e-001,6.336062e-001,1.826087e+000,7.255541e-001,6.814064e-001,1.040861e-004,1.040861e-004,,,,,,,,,,,,,,,,,,,,
1524280139.275,,0.000000e+000,3.399714e+001,3.399936e+001,1,0,3.354839e+000,0.000000e+000,2.074769e+000,2.074769e+000,9.764779e-001,9.306283e-001,2.091452e+000,9.931608e-001,9.473112e-001,1.369377e-004,1.369377e-004,,,,,,,,,,,,,,,,,,,,
1524280151.922,,0.000000e+000,3.399788e+001,3.399788e+001,1,0,3.483871e+000,0.000000e+000,2.289006e+000,2.289006e+000,1.193791e+000,1.145227e+000,2.259687e+000,1.164473e+000,1.115909e+000,1.607615e-004,1.607615e-004,,,,,,,,,,,,,,,,,,,,
1524280164.740,,0.000000e+000,3.399714e+001,3.399936e+001,1,0,3.612903e+000,0.000000e+000,2.380255e+000,2.380255e+000,1.287687e+000,1.237578e+000,2.322217e+000,1.229648e+000,1.179540e+000,1.710134e-004,1.710134e-004,,,,,,,,,,,,,,,,,,,,
1524280177.560,,0.000000e+000,3.399788e+001,3.399862e+001,1,0,3.741935e+000,0.000000e+000,2.367895e+000,2.367895e+000,1.277596e+000,1.226059e+000,2.287715e+000,1.197416e+000,1.145879e+000,1.697935e-004,1.697935e-004,,,,,,,,,,,,,,,,,,,,
1524280190.718,,0.000000e+000,3.399788e+001,3.399936e+001,1,0,3.870968e+000,0.000000e+000,2.267948e+000,2.267948e+000,1.180248e+000,1.127043e+000,2.182061e+000,1.094361e+000,1.041156e+000,1.589379e-004,1.589379e-004,,,,,,,,,,,,,,,,,,,,
1524280203.216,,0.000000e+000,3.399788e+001,3.399862e+001,1,0,4.000000e+000,0.000000e+000,2.128939e+000,2.128939e+000,1.043910e+000,9.883621e-001,2.038384e+000,9.533556e-001,8.978078e-001,1.437567e-004,1.437567e-004,,,,,,,,,,,,,,,,,,,,
1524280228.574,,0.000000e+000,3.399714e+001,3.399862e+001,1,0,0.000000e+000,0.000000e+000,2.002136e+000,2.002136e+000,8.632593e-001,8.632593e-001,2.092720e+000,9.538429e-001,9.538429e-001,1.279061e-004,1.279061e-004,,,,,,,,,,,,,,,,,,,,
1524280241.146,,0.000000e+000,3.399714e+001,3.399862e+001,1,0,1.290323e-001,0.000000e+000,2.128023e+000,2.128023e+000,9.925413e-001,9.907962e-001,2.231705e+000,1.096223e+000,1.094478e+000,1.420324e-004,1.420324e-004,,,,,,,,,,,,,,,,,,,,
1524280254.164,,0.000000e+000,3.399862e+001,3.399788e+001,1,0,2.580645e-001,0.000000e+000,2.252842e+000,2.252842e+000,1.120483e+000,1.117036e+000,2.332640e+000,1.200282e+000,1.196835e+000,1.560079e-004,1.560079e-004,,,,,,,,,,,,,,,,,,,,
1524280266.742,,0.000000e+000,3.399714e+001,3.399936e+001,1,0,3.870968e-001,0.000000e+000,2.313420e+000,2.313420e+000,1.183713e+000,1.178391e+000,2.363458e+000,1.233751e+000,1.228429e+000,1.629202e-004,1.629202e-004,,,,,,,,,,,,,,,,,,,,
1524280279.342,,0.000000e+000,3.399788e+001,3.399936e+001,1,0,5.161290e-001,0.000000e+000,2.280156e+000,2.280156e+000,1.153371e+000,1.146473e+000,2.296310e+000,1.169526e+000,1.162628e+000,1.594146e-004,1.594146e-004,,,,,,,,,,,,,,,,,,,,
1524280291.884,,0.000000e+000,3.399936e+001,3.399936e+001,1,0,6.451613e-001,0.000000e+000,2.137484e+000,2.137484e+000,1.013166e+000,1.004375e+000,2.122393e+000,9.980752e-001,9.892839e-001,1.438566e-004,1.438566e-004,,,,,,,,,,,,,,,,,,,,
1524280304.717,,0.000000e+000,3.399788e+001,3.399862e+001,1,0,7.741935e-001,0.000000e+000,1.893645e+000,1.893645e+000,7.722018e-001,7.618842e-001,1.851286e+000,7.298428e-001,7.195252e-001,1.171229e-004,1.171229e-004,,,,,,,,,,,,,,,,,,,,
1524280317.522,,0.000000e+000,3.399714e+001,3.399936e+001,1,0,9.032258e-001,0.000000e+000,1.576715e+000,1.576715e+000,4.578791e-001,4.457431e-001,1.506086e+000,3.872506e-001,3.751146e-001,8.233655e-005,8.233655e-005,,,,,,,,,,,,,,,,,,,,
1524280330.747,,0.000000e+000,3.399788e+001,3.399788e+001,1,0,1.032258e+000,0.000000e+000,1.150225e+000,1.150225e+000,8.285651e-002,6.885898e-002,1.059957e+000,-7.411746e-003,-2.140927e-002,4.085536e-005,4.085536e-005,,,,,,,,,,,,,,,,,,,,
1524280343.455,,0.000000e+000,3.399788e+001,3.399862e+001,1,0,1.161290e+000,0.000000e+000,7.864500e-001,7.864500e-001,-3.254134e-001,-3.404669e-001,6.730812e-001,-4.387822e-001,-4.538357e-001,-4.332062e-006,-4.332062e-006,,,,,,,,,,,,,,,,,,,,
1524280356.253,,0.000000e+000,3.399641e+001,3.399936e+001,1,0,1.290323e+000,0.000000e+000,3.424124e-001,3.424124e-001,-7.679790e-001,-7.850348e-001,2.136525e-001,-8.967389e-001,-9.137948e-001,-5.327277e-005,-5.327277e-005,,,,,,,,,,,,,,,,,,,,
1524280369.065,,0.000000e+000,3.399936e+001,3.399936e+001,1,0,1.419355e+000,0.000000e+000,-1.319905e-001,-1.319905e-001,-1.240186e+000,-1.258958e+000,-2.635855e-001,-1.371781e+000,-1.390553e+000,-1.054877e-004,-1.054877e-004,,,,,,,,,,,,,,,,,,,,
1524280381.323,,0.000000e+000,3.399788e+001,3.400009e+001,1,0,1.548387e+000,0.000000e+000,-6.076143e-001,-6.076143e-001,-1.713105e+000,-1.733584e+000,-7.392797e-001,-1.844770e+000,-1.865250e+000,-1.577730e-004,-1.577730e-004,,,,,,,,,,,,,,,,,,,,
1524280394.761,,0.000000e+000,3.399714e+001,3.399936e+001,1,0,1.677419e+000,0.000000e+000,-1.063554e+000,-1.063554e+000,-2.166885e+000,-2.189030e+000,-1.174704e+000,-2.278035e+000,-2.300179e+000,-2.079603e-004,-2.079603e-004,,,,,,,,,,,,,,,,,,,,
1524280407.536,,0.000000e+000,3.399936e+001,3.399862e+001,1,0,1.806452e+000,0.000000e+000,-1.448234e+000,-1.448234e+000,-2.548761e+000,-2.572916e+000,-1.518838e+000,-2.619366e+000,-2.643520e+000,-2.502023e-004,-2.502023e-004,,,,,,,,,,,,,,,,,,,,
1524280420.411,,0.000000e+000,3.399862e+001,3.399714e+001,1,0,1.935484e+000,0.000000e+000,-1.693751e+000,-1.693751e+000,-2.791603e+000,-2.817237e+000,-1.712171e+000,-2.810023e+000,-2.835657e+000,-2.771109e-004,-2.771109e-004,,,,,,,,,,,,,,,,,,,,
1524280433.069,,0.000000e+000,3.399714e+001,3.399936e+001,1,0,2.064516e+000,0.000000e+000,-1.751431e+000,-1.751431e+000,-2.846905e+000,-2.875419e+000,-1.715773e+000,-2.811247e+000,-2.839762e+000,-2.833275e-004,-2.833275e-004,,,,,,,,,,,,,,,,,,,,
1524280445.787,,0.000000e+000,3.399862e+001,3.399936e+001,1,0,2.193548e+000,0.000000e+000,-1.607843e+000,-1.607843e+000,-2.699849e+000,-2.729293e+000,-1.529791e+000,-2.621797e+000,-2.651241e+000,-2.672250e-004,-2.672250e-004,,,,,,,,,,,,,,,,,,,,
1524280458.044,,0.000000e+000,3.399936e+001,3.400082e+001,1,0,2.322581e+000,0.000000e+000,-1.300526e+000,-1.300526e+000,-2.389605e+000,-2.420693e+000,-1.192868e+000,-2.281947e+000,-2.313034e+000,-2.331115e-004,-2.331115e-004,,,,,,,,,,,,,,,,,,,,
1524280470.605,,0.000000e+000,3.399862e+001,3.399862e+001,1,0,2.451613e+000,0.000000e+000,-8.776990e-001,-8.776990e-001,-1.965176e+000,-1.996703e+000,-7.612334e-001,-1.848711e+000,-1.880237e+000,-1.863855e-004,-1.863855e-004,,,,,,,,,,,,,,,,,,,,
1524280482.695,,0.000000e+000,3.399788e+001,3.399862e+001,1,0,2.580645e+000,0.000000e+000,-4.145876e-001,-4.145876e-001,-1.498986e+000,-1.533162e+000,-2.918739e-001,-1.376272e+000,-1.410449e+000,-1.350716e-004,-1.350716e-004,,,,,,,,,,,,,,,,,,,,
1524280495.380,,0.000000e+000,3.399936e+001,3.399862e+001,1,0,2.709677e+000,0.000000e+000,6.332494e-002,6.332494e-002,-1.017833e+000,-1.053700e+000,1.809746e-001,-9.001828e-001,-9.360507e-001,-8.210263e-005,-8.210263e-005,,,,,,,,,,,,,,,,,,,,
1524280508.070,,0.000000e+000,3.399862e+001,3.399862e+001,1,0,2.838710e+000,0.000000e+000,5.302510e-001,5.302510e-001,-5.477981e-001,-5.851629e-001,6.375271e-001,-4.405220e-001,-4.778868e-001,-3.035809e-005,-3.035809e-005,,,,,,,,,,,,,,,,,,,,
1524280520.680,,0.000000e+000,3.400156e+001,3.399862e+001,1,0,2.967742e+000,0.000000e+000,9.726101e-001,9.726101e-001,-1.033301e-001,-1.421012e-001,1.068490e+000,-7.450579e-003,-4.622173e-002,1.857916e-005,1.857916e-005,,,,,,,,,,,,,,,,,,,,
1524280532.695,,0.000000e+000,3.399862e+001,3.399788e+001,1,0,3.096774e+000,0.000000e+000,1.384756e+000,1.384756e+000,3.113714e-001,2.712193e-001,1.462929e+000,3.895446e-001,3.493925e-001,6.422406e-005,6.422406e-005,,,,,,,,,,,,,,,,,,,,
1524280545.428,,0.000000e+000,3.399788e+001,3.399714e+001,1,0,3.225806e+000,0.000000e+000,1.760128e+000,1.760128e+000,6.891361e-001,6.478312e-001,1.805751e+000,7.347588e-001,6.934539e-001,1.058089e-004,1.058089e-004,,,,,,,,,,,,,,,,,,,,
1524280558.108,,0.000000e+000,3.399714e+001,3.399862e+001,1,0,3.354839e+000,0.000000e+000,2.057374e+000,2.057374e+000,9.892143e-001,9.460573e-001,2.073357e+000,1.005197e+000,9.620402e-001,1.387932e-004,1.387932e-004,,,,,,,,,,,,,,,,,,,,
1524280570.743,,0.000000e+000,3.399862e+001,3.399936e+001,1,0,3.483871e+000,0.000000e+000,2.270085e+000,2.270085e+000,1.204468e+000,1.159712e+000,2.244396e+000,1.178779e+000,1.134024e+000,1.624344e-004,1.624344e-004,,,,,,,,,,,,,,,,,,,,
1524280583.256,,0.000000e+000,3.399862e+001,3.400156e+001,1,0,3.612903e+000,0.000000e+000,2.365759e+000,2.365759e+000,1.303473e+000,1.256874e+000,2.307012e+000,1.244726e+000,1.198127e+000,1.732453e-004,1.732453e-004,,,,,,,,,,,,,,,,,,,,
1524280595.949,,0.000000e+000,3.399788e+001,3.400009e+001,1,0,3.741935e+000,0.000000e+000,2.350805e+000,2.350805e+000,1.290470e+000,1.243181e+000,2.272215e+000,1.211880e+000,1.164590e+000,1.717289e-004,1.717289e-004,,,,,,,,,,,,,,,,,,,,
1524280608.789,,0.000000e+000,3.399788e+001,3.399936e+001,1,0,3.870968e+000,0.000000e+000,2.250401e+000,2.250401e+000,1.193086e+000,1.143050e+000,2.164720e+000,1.107406e+000,1.057370e+000,1.608318e-004,1.608318e-004,,,,,,,,,,,,,,,,,,,,
1524280621.599,,0.000000e+000,3.399714e+001,3.400009e+001,1,0,4.000000e+000,0.000000e+000,2.106661e+000,2.106661e+000,1.051408e+000,1.000823e+000,2.019833e+000,9.645799e-001,9.139947e-001,1.451270e-004,1.451270e-004,,,,,,,,,,,,,,,,,,,,
1524280647.227,,0.000000e+000,3.399862e+001,3.399862e+001,1,0,0.000000e+000,0.000000e+000,1.980468e+000,1.980468e+000,8.784890e-001,8.784890e-001,2.067156e+000,9.651769e-001,9.651769e-001,1.297913e-004,1.297913e-004,,,,,,,,,,,,,,,,,,,,
1524280660.045,,0.000000e+000,3.399714e+001,3.399936e+001,1,0,1.290323e-001,0.000000e+000,2.109102e+000,2.109102e+000,1.009717e+000,1.008066e+000,2.208082e+000,1.108696e+000,1.107046e+000,1.441750e-004,1.441750e-004,,,,,,,,,,,,,,,,,,,,
1524280672.880,,0.000000e+000,3.399862e+001,3.399862e+001,1,0,2.580645e-001,0.000000e+000,2.233310e+000,2.233310e+000,1.136322e+000,1.133017e+000,2.311007e+000,1.214019e+000,1.210714e+000,1.580365e-004,1.580365e-004,,,,,,,,,,,,,,,,,,,,
1524280685.673,,0.000000e+000,3.399788e+001,3.400082e+001,1,0,3.870968e-001,0.000000e+000,2.289616e+000,2.289616e+000,1.195594e+000,1.190696e+000,2.341611e+000,1.247589e+000,1.242691e+000,1.644452e-004,1.644452e-004,,,,,,,,,,,,,,,,,,,,
1524280698.500,,0.000000e+000,3.399862e+001,3.399862e+001,1,0,5.161290e-001,0.000000e+000,2.257572e+000,2.257572e+000,1.166211e+000,1.159672e+000,2.273776e+000,1.182415e+000,1.175876e+000,1.610939e-004,1.610939e-004,,,,,,,,,,,,,,,,,,,,
1524280711.888,,0.000000e+000,3.399714e+001,3.399936e+001,1,0,6.451613e-001,0.000000e+000,2.113374e+000,2.113374e+000,1.024602e+000,1.016463e+000,2.097774e+000,1.009001e+000,1.000862e+000,1.453539e-004,1.453539e-004,,,,,,,,,,,,,,,,,,,,
1524280724.683,,0.000000e+000,3.399936e+001,3.399788e+001,1,0,7.741935e-001,0.000000e+000,1.866484e+000,1.866484e+000,7.809765e-001,7.712038e-001,1.823171e+000,7.376640e-001,7.278913e-001,1.183568e-004,1.183568e-004,,,,,,,,,,,,,,,,,,,,
1524280737.358,,0.000000e+000,3.399788e+001,3.400009e+001,1,0,9.032258e-001,0.000000e+000,1.542534e+000,1.542534e+000,4.604877e-001,4.495593e-001,1.473457e+000,3.914105e-001,3.804822e-001,8.284659e-005,8.284659e-005,,,,,,,,,,,,,,,,,,,,
1524280750.069,,0.000000e+000,3.399641e+001,3.399862e+001,1,0,1.032258e+000,0.000000e+000,1.161822e+000,1.161822e+000,8.214580e-002,6.957507e-002,1.072188e+000,-7.488021e-003,-2.005875e-002,4.099557e-005,4.099557e-005,,,,,,,,,,,,,,,,,,,,
1524280762.934,,0.000000e+000,3.400082e+001,3.399788e+001,1,0,1.161290e+000,0.000000e+000,7.391470e-001,7.391470e-001,-3.375583e-001,-3.515101e-001,6.335059e-001,-4.431994e-001,-4.571512e-001,-5.420763e-006,-5.420763e-006,,,,,,,,,,,,,,,,,,,,
1524280775.756,,0.000000e+000,3.399862e+001,3.399714e+001,1,0,1.290323e+000,0.000000e+000,2.908370e-001,2.908370e-001,-7.833389e-001,-7.991978e-001,1.682183e-001,-9.059576e-001,-9.218165e-001,-5.469960e-005,-5.469960e-005,,,,,,,,,,,,,,,,,,,,
1524280788.534,,0.000000e+000,3.399862e+001,3.399788e+001,1,0,1.419355e+000,0.000000e+000,-1.843290e-001,-1.843290e-001,-1.255804e+000,-1.273052e+000,-3.143519e-001,-1.385827e+000,-1.403075e+000,-1.069416e-004,-1.069416e-004,,,,,,,,,,,,,,,,,,,,
1524280801.599,,0.000000e+000,3.399788e+001,3.399862e+001,1,0,1.548387e+000,0.000000e+000,-6.654459e-001,-6.654459e-001,-1.734102e+000,-1.753159e+000,-7.942473e-001,-1.862903e+000,-1.881960e+000,-1.598175e-004,-1.598175e-004,,,,,,,,,,,,,,,,,,,,
1524280814.347,,0.000000e+000,3.399788e+001,3.399936e+001,1,0,1.677419e+000,0.000000e+000,-1.130541e+000,-1.130541e+000,-2.196427e+000,-2.216686e+000,-1.234957e+000,-2.300843e+000,-2.321102e+000,-2.109380e-004,-2.109380e-004,,,,,,,,,,,,,,,,,,,,
1524280827.350,,0.000000e+000,3.399788e+001,3.399936e+001,1,0,1.806452e+000,0.000000e+000,-1.512932e+000,-1.512932e+000,-2.576354e+000,-2.598569e+000,-1.580179e+000,-2.643600e+000,-2.665816e+000,-2.529768e-004,-2.529768e-004,,,,,,,,,,,,,,,,,,,,
1524280840.160,,0.000000e+000,3.399788e+001,3.399788e+001,1,0,1.935484e+000,0.000000e+000,-1.756008e+000,-1.756008e+000,-2.816697e+000,-2.840315e+000,-1.776165e+000,-2.836854e+000,-2.860472e+000,-2.795902e-004,-2.795902e-004,,,,,,,,,,,,,,,,,,,,
1524280852.983,,0.000000e+000,3.399862e+001,3.399936e+001,1,0,2.064516e+000,0.000000e+000,-1.815518e+000,-1.815518e+000,-2.873463e+000,-2.899148e+000,-1.780110e+000,-2.838055e+000,-2.863739e+000,-2.859571e-004,-2.859571e-004,,,,,,,,,,,,,,,,,,,,
1524280865.585,,0.000000e+000,3.399714e+001,3.399936e+001,1,0,2.193548e+000,0.000000e+000,-1.665827e+000,-1.665827e+000,-2.720864e+000,-2.747843e+000,-1.592224e+000,-2.647260e+000,-2.674240e+000,-2.692280e-004,-2.692280e-004,,,,,,,,,,,,,,,,,,,,
1524280878.081,,0.000000e+000,3.399714e+001,3.399936e+001,1,0,2.322581e+000,0.000000e+000,-1.351949e+000,-1.351949e+000,-2.404356e+000,-2.432745e+000,-1.251670e+000,-2.304076e+000,-2.332465e+000,-2.344122e-004,-2.344122e-004,,,,,,,,,,,,,,,,,,,,
1524280890.568,,0.000000e+000,3.399788e+001,3.399862e+001,1,0,2.451613e+000,0.000000e+000,-9.291219e-001,-9.291219e-001,-1.979336e+000,-2.010176e+000,-8.162996e-001,-1.866514e+000,-1.897354e+000,-1.876413e-004,-1.876413e-004,,,,,,,,,,,,,,,,,,,,
1524280903.091,,0.000000e+000,3.399936e+001,3.399862e+001,1,0,2.580645e+000,0.000000e+000,-4.586862e-001,-4.586862e-001,-1.505602e+000,-1.537577e+000,-3.422207e-001,-1.389137e+000,-1.421111e+000,-1.354765e-004,-1.354765e-004,,,,,,,,,,,,,,,,,,,,
1524280915.659,,0.000000e+000,3.399788e+001,3.399862e+001,1,0,2.709677e+000,0.000000e+000,2.090486e-002,2.090486e-002,-1.023355e+000,-1.056246e+000,1.356348e-001,-9.086247e-001,-9.415160e-001,-8.236493e-005,-8.236493e-005,,,,,,,,,,,,,,,,,,,,
1524280928.499,,0.000000e+000,3.399862e+001,3.399862e+001,1,0,2.838710e+000,0.000000e+000,4.899672e-001,4.899672e-001,-5.508765e-001,-5.846634e-001,5.961889e-001,-4.446548e-001,-4.784417e-001,-3.033013e-005,-3.033013e-005,,,,,,,,,,,,,,,,,,,,
1524280941.411,,0.000000e+000,3.399936e+001,3.399862e+001,1,0,2.967742e+000,0.000000e+000,9.373617e-001,9.373617e-001,-1.005952e-001,-1.351633e-001,1.030439e+000,-7.517739e-003,-4.208589e-002,1.926006e-005,1.926006e-005,,,,,,,,,,,,,,,,,,,,
1524280954.042,,0.000000e+000,3.399862e+001,3.399788e+001,1,0,3.096774e+000,0.000000e+000,1.351949e+000,1.351949e+000,3.164974e-001,2.801672e-001,1.428571e+000,3.931188e-001,3.567886e-001,6.517287e-005,6.517287e-005,,,,,,,,,,,,,,,,,,,,
1524280966.884,,0.000000e+000,3.399788e+001,3.399936e+001,1,0,3.225806e+000,0.000000e+000,1.726253e+000,1.726253e+000,6.936742e-001,6.554534e-001,1.773881e+000,7.413024e-001,7.030816e-001,1.066712e-004,1.066712e-004,,,,,,,,,,,,,,,,,,,,
1524280979.707,,0.000000e+000,3.399936e+001,3.400009e+001,1,0,3.354839e+000,0.000000e+000,2.032349e+000,2.032349e+000,1.002160e+000,9.627376e-001,2.044427e+000,1.014238e+000,9.748158e-001,1.406108e-004,1.406108e-004,,,,,,,,,,,,,,,,,,,,
1524280992.510,,0.000000e+000,3.399788e+001,3.399788e+001,1,0,3.483871e+000,0.000000e+000,2.244602e+000,2.244602e+000,1.217001e+000,1.176508e+000,2.216720e+000,1.189119e+000,1.148626e+000,1.642222e-004,1.642222e-004,,,,,,,,,,,,,,,,,,,,
1524281005.107,,0.000000e+000,3.399714e+001,3.399641e+001,1,0,3.612903e+000,0.000000e+000,2.334630e+000,2.334630e+000,1.309649e+000,1.267609e+000,2.280326e+000,1.255345e+000,1.213305e+000,1.743406e-004,1.743406e-004,,,,,,,,,,,,,,,,,,,,
1524281018.823,,0.000000e+000,3.399862e+001,3.399862e+001,1,0,3.741935e+000,0.000000e+000,2.321203e+000,2.321203e+000,1.298401e+000,1.254430e+000,2.245077e+000,1.222275e+000,1.178305e+000,1.729832e-004,1.729832e-004,,,,,,,,,,,,,,,,,,,,
1524281030.645,,0.000000e+000,3.399862e+001,3.399936e+001,1,0,3.870968e+000,0.000000e+000,2.219882e+000,2.219882e+000,1.200257e+000,1.152827e+000,2.136812e+000,1.117187e+000,1.069757e+000,1.619893e-004,1.619893e-004,,,,,,,,,,,,,,,,,,,,
1524281043.040,,0.000000e+000,3.399714e+001,3.399936e+001,1,0,4.000000e+000,0.000000e+000,2.072786e+000,2.072786e+000,1.055717e+000,1.008531e+000,1.989853e+000,9.727842e-001,9.255985e-001,1.459910e-004,1.459910e-004,,,,,,,,,,,,,,,,,,,,
1524281068.451,,0.000000e+000,3.399936e+001,3.399936e+001,1,0,0.000000e+000,0.000000e+000,1.949645e+000,1.949645e+000,8.885952e-001,8.885952e-001,2.034159e+000,9.731086e-001,9.731086e-001,1.310083e-004,1.310083e-004,,,,,,,,,,,,,,,,,,,,
1524281081.243,,0.000000e+000,3.399862e+001,3.399862e+001,1,0,1.290323e-001,0.000000e+000,2.079194e+000,2.079194e+000,1.021050e+000,1.019569e+000,2.175836e+000,1.117692e+000,1.116210e+000,1.454975e-004,1.454975e-004,,,,,,,,,,,,,,,,,,,,
1524281094.091,,0.000000e+000,3.400082e+001,3.399862e+001,1,0,2.580645e-001,0.000000e+000,2.200504e+000,2.200504e+000,1.145175e+000,1.142171e+000,2.279235e+000,1.223906e+000,1.220902e+000,1.591162e-004,1.591162e-004,,,,,,,,,,,,,,,,,,,,
1524281107.141,,0.000000e+000,3.399862e+001,3.399936e+001,1,0,3.870968e-001,0.000000e+000,2.263523e+000,2.263523e+000,1.210893e+000,1.206473e+000,2.310276e+000,1.257646e+000,1.253226e+000,1.662367e-004,1.662367e-004,,,,,,,,,,,,,,,,,,,,
1524281119.734,,0.000000e+000,3.399788e+001,3.400082e+001,1,0,5.161290e-001,0.000000e+000,2.227207e+000,2.227207e+000,1.177253e+000,1.171344e+000,2.241807e+000,1.191853e+000,1.185943e+000,1.624269e-004,1.624269e-004,,,,,,,,,,,,,,,,,,,,
1524281132.529,,0.000000e+000,3.399862e+001,3.399936e+001,1,0,6.451613e-001,0.000000e+000,2.076448e+000,2.076448e+000,1.029158e+000,1.021797e+000,2.064156e+000,1.016866e+000,1.009505e+000,1.459785e-004,1.459785e-004,,,,,,,,,,,,,,,,,,,,
1524281145.262,,0.000000e+000,3.399862e+001,3.400082e+001,1,0,7.741935e-001,0.000000e+000,1.826963e+000,1.826963e+000,7.824085e-001,7.735305e-001,1.788027e+000,7.434731e-001,7.345951e-001,1.186552e-004,1.186552e-004,,,,,,,,,,,,,,,,,,,,
1524281157.997,,0.000000e+000,3.399788e+001,3.399936e+001,1,0,9.032258e-001,0.000000e+000,1.500114e+000,1.500114e+000,4.584668e-001,4.482695e-001,1.436174e+000,3.945260e-001,3.843287e-001,8.280560e-005,8.280560e-005,,,,,,,,,,,,,,,,,,,,
1524281171.395,,0.000000e+000,3.399788e+001,3.399862e+001,1,0,1.032258e+000,0.000000e+000,1.117876e+000,1.117876e+000,7.905456e-002,6.762981e-002,1.031274e+000,-7.547772e-003,-1.897252e-002,4.082358e-005,4.082358e-005,,,,,,,,,,,,,,,,,,,,
1524281183.930,,0.000000e+000,3.399788e+001,3.399862e+001,1,0,1.161290e+000,0.000000e+000,6.950485e-001,6.950485e-001,-3.411938e-001,-3.544854e-001,5.896265e-001,-4.466158e-001,-4.599074e-001,-5.617403e-006,-5.617403e-006,,,,,,,,,,,,,,,,,,,,
1524281196.195,,0.000000e+000,3.399788e+001,3.399936e+001,1,0,1.290323e+000,0.000000e+000,1.945525e-001,1.945525e-001,-7.904359e-001,-8.056000e-001,7.175647e-002,-9.132320e-001,-9.283961e-001,-5.526112e-005,-5.526112e-005,,,,,,,,,,,,,,,,,,,,
1524281209.333,,0.000000e+000,3.400009e+001,3.399862e+001,1,0,1.419355e+000,0.000000e+000,-2.432288e-001,-2.432288e-001,-1.272853e+000,-1.288070e+000,-3.668382e-001,-1.396462e+000,-1.411680e+000,-1.086451e-004,-1.086451e-004,,,,,,,,,,,,,,,,,,,,
1524281222.163,,0.000000e+000,3.399862e+001,3.399788e+001,1,0,1.548387e+000,0.000000e+000,-7.252613e-001,-7.252613e-001,-1.753130e+000,-1.769812e+000,-8.497415e-001,-1.877610e+000,-1.894292e+000,-1.617223e-004,-1.617223e-004,,,,,,,,,,,,,,,,,,,,
1524281235.016,,0.000000e+000,3.399788e+001,3.399862e+001,1,0,1.677419e+000,0.000000e+000,-1.191882e+000,-1.191882e+000,-2.217005e+000,-2.235923e+000,-1.292865e+000,-2.317988e+000,-2.336906e+000,-2.129956e-004,-2.129956e-004,,,,,,,,,,,,,,,,,,,,
1524281248.363,,0.000000e+000,3.399862e+001,3.399862e+001,1,0,1.806452e+000,0.000000e+000,-1.578698e+000,-1.578698e+000,-2.601383e+000,-2.621536e+000,-1.641948e+000,-2.664632e+000,-2.684785e+000,-2.555071e-004,-2.555071e-004,,,,,,,,,,,,,,,,,,,,
1524281261.059,,0.000000e+000,3.399714e+001,3.399788e+001,1,0,1.935484e+000,0.000000e+000,-1.819791e+000,-1.819791e+000,-2.839789e+000,-2.861443e+000,-1.837932e+000,-2.857930e+000,-2.879584e+000,-2.819116e-004,-2.819116e-004,,,,,,,,,,,,,,,,,,,,
1524281273.731,,0.000000e+000,3.399862e+001,3.399862e+001,1,0,2.064516e+000,0.000000e+000,-1.875639e+000,-1.875639e+000,-2.893329e+000,-2.916382e+000,-1.840926e+000,-2.858616e+000,-2.881669e+000,-2.879173e-004,-2.879173e-004,,,,,,,,,,,,,,,,,,,,
1524281286.106,,0.000000e+000,3.399788e+001,3.399714e+001,1,0,2.193548e+000,0.000000e+000,-1.724422e+000,-1.724422e+000,-2.738960e+000,-2.762730e+000,-1.651801e+000,-2.666339e+000,-2.690109e+000,-2.709794e-004,-2.709794e-004,,,,,,,,,,,,,,,,,,,,
1524281298.654,,0.000000e+000,3.399714e+001,3.399714e+001,1,0,2.322581e+000,0.000000e+000,-1.405203e+000,-1.405203e+000,-2.417840e+000,-2.443104e+000,-1.307654e+000,-2.320291e+000,-2.345555e+000,-2.356488e-004,-2.356488e-004,,,,,,,,,,,,,,,,,,,,
1524281311.789,,0.000000e+000,3.399567e+001,3.399862e+001,1,0,2.451613e+000,0.000000e+000,-9.777981e-001,-9.777981e-001,-1.987778e+000,-2.014366e+000,-8.698373e-001,-1.879818e+000,-1.906405e+000,-1.882930e-004,-1.882930e-004,,,,,,,,,,,,,,,,,,,,
1524281324.040,,0.000000e+000,3.400009e+001,3.399714e+001,1,0,2.580645e+000,0.000000e+000,-5.017166e-001,-5.017166e-001,-1.509560e+000,-1.538585e+000,-3.911134e-001,-1.398957e+000,-1.427982e+000,-1.356440e-004,-1.356440e-004,,,,,,,,,,,,,,,,,,,,
1524281336.762,,0.000000e+000,3.399714e+001,3.399862e+001,1,0,2.709677e+000,0.000000e+000,-1.983673e-002,-1.983673e-002,-1.024674e+000,-1.054313e+000,9.006331e-002,-9.147743e-001,-9.444125e-001,-8.223690e-005,-8.223690e-005,,,,,,,,,,,,,,,,,,,,
1524281349.405,,0.000000e+000,3.399788e+001,3.399788e+001,1,0,2.838710e+000,0.000000e+000,4.515145e-001,4.515145e-001,-5.509127e-001,-5.808338e-001,5.546886e-001,-4.477386e-001,-4.776597e-001,-3.003387e-005,-3.003387e-005,,,,,,,,,,,,,,,,,,,,
1524281361.963,,0.000000e+000,3.399862e+001,3.399862e+001,1,0,2.967742e+000,0.000000e+000,9.016556e-001,9.016556e-001,-9.831687e-002,-1.303609e-001,9.924029e-001,-7.569630e-003,-3.961366e-002,1.978743e-005,1.978743e-005,,,,,,,,,,,,,,,,,,,,
1524281374.560,,0.000000e+000,3.399862e+001,3.399936e+001,1,0,3.096774e+000,0.000000e+000,1.317311e+000,1.317311e+000,3.202122e-001,2.870026e-001,1.392937e+000,3.958381e-001,3.626285e-001,6.587984e-005,6.587984e-005,,,,,,,,,,,,,,,,,,,,
1524281387.615,,0.000000e+000,3.399936e+001,3.399788e+001,1,0,3.225806e+000,0.000000e+000,1.701381e+000,1.701381e+000,7.064599e-001,6.716435e-001,1.741253e+000,7.463315e-001,7.115151e-001,1.083888e-004,1.083888e-004,,,,,,,,,,,,,,,,,,,,
1524281400.358,,0.000000e+000,3.399714e+001,3.399936e+001,1,0,3.354839e+000,0.000000e+000,2.001831e+000,2.001831e+000,1.008807e+000,9.735287e-001,2.014273e+000,1.021249e+000,9.859706e-001,1.416830e-004,1.416830e-004,,,,,,,,,,,,,,,,,,,,
1524281413.391,,0.000000e+000,3.399788e+001,3.399862e+001,1,0,3.483871e+000,0.000000e+000,2.165255e+000,2.165255e+000,1.224457e+000,1.185277e+000,2.138197e+000,1.197398e+000,1.158219e+000,1.653033e-004,1.653033e-004,,,,,,,,,,,,,,,,,,,,
1524281426.216,,0.000000e+000,3.399862e+001,3.399936e+001,1,0,3.612903e+000,0.000000e+000,2.303349e+000,2.303349e+000,1.316796e+000,1.277460e+000,2.249980e+000,1.263426e+000,1.224091e+000,1.754189e-004,1.754189e-004,,,,,,,,,,,,,,,,,,,,
1524281438.414,,0.000000e+000,3.399862e+001,3.399862e+001,1,0,3.741935e+000,0.000000e+000,2.236362e+000,2.236362e+000,1.302924e+000,1.259753e+000,2.164202e+000,1.230764e+000,1.187592e+000,1.737266e-004,1.737266e-004,,,,,,,,,,,,,,,,,,,,
1524281450.991,,0.000000e+000,3.400156e+001,3.399862e+001,1,0,3.870968e+000,0.000000e+000,2.183414e+000,2.183414e+000,1.202904e+000,1.162340e+000,2.104957e+000,1.124448e+000,1.083884e+000,1.627285e-004,1.627285e-004,,,,,,,,,,,,,,,,,,,,
1524281464.872,,0.000000e+000,3.399788e+001,3.399936e+001,1,0,4.000000e+000,0.000000e+000,2.036469e+000,2.036469e+000,1.057793e+000,1.015563e+000,1.957898e+000,9.792221e-001,9.369920e-001,1.466090e-004,1.466090e-004,,,,,,,,,,,,,,,,,,,,
1524281489.787,,0.000000e+000,3.399862e+001,3.399936e+001,1,0,0.000000e+000,0.000000e+000,1.917601e+000,1.917601e+000,8.989911e-001,8.989911e-001,1.998328e+000,9.797176e-001,9.797176e-001,1.322239e-004,1.322239e-004,,,,,,,,,,,,,,,,,,,,
1524281502.607,,0.000000e+000,3.399936e+001,3.399862e+001,1,0,1.290323e-001,0.000000e+000,2.045930e+000,2.045930e+000,1.029371e+000,1.028004e+000,2.141864e+000,1.125305e+000,1.123938e+000,1.465058e-004,1.465058e-004,,,,,,,,,,,,,,,,,,,,
1524281514.837,,0.000000e+000,3.399714e+001,3.400009e+001,1,0,2.580645e-001,0.000000e+000,2.174258e+000,2.174258e+000,1.159165e+000,1.156348e+000,2.247092e+000,1.231999e+000,1.229182e+000,1.607739e-004,1.607739e-004,,,,,,,,,,,,,,,,,,,,
1524281527.375,,0.000000e+000,3.400009e+001,3.399862e+001,1,0,3.870968e-001,0.000000e+000,2.232090e+000,2.232090e+000,1.220012e+000,1.216017e+000,2.277969e+000,1.265892e+000,1.261896e+000,1.673181e-004,1.673181e-004,,,,,,,,,,,,,,,,,,,,
1524281540.438,,0.000000e+000,3.399862e+001,3.399936e+001,1,0,5.161290e-001,0.000000e+000,2.195010e+000,2.195010e+000,1.185143e+000,1.179770e+000,2.209460e+000,1.199593e+000,1.194220e+000,1.633870e-004,1.633870e-004,,,,,,,,,,,,,,,,,,,,
1524281552.968,,0.000000e+000,3.399788e+001,3.399788e+001,1,0,6.451613e-001,0.000000e+000,2.044556e+000,2.044556e+000,1.037048e+000,1.030229e+000,2.031018e+000,1.023509e+000,1.016690e+000,1.469695e-004,1.469695e-004,,,,,,,,,,,,,,,,,,,,
1524281565.643,,0.000000e+000,3.399936e+001,3.399936e+001,1,0,7.741935e-001,0.000000e+000,1.788815e+000,1.788815e+000,7.844028e-001,7.763656e-001,1.752885e+000,7.484724e-001,7.404352e-001,1.189877e-004,1.189877e-004,,,,,,,,,,,,,,,,,,,,
1524281578.478,,0.000000e+000,3.399936e+001,3.399862e+001,1,0,9.032258e-001,0.000000e+000,1.459525e+000,1.459525e+000,4.570172e-001,4.478533e-001,1.399475e+000,3.969669e-001,3.878031e-001,8.274706e-005,8.274706e-005,,,,,,,,,,,,,,,,,,,,
1524281591.251,,0.000000e+000,3.399788e+001,3.399862e+001,1,0,1.032258e+000,0.000000e+000,1.076829e+000,1.076829e+000,7.617359e-002,6.558228e-002,9.930604e-001,-7.595193e-003,-1.818651e-002,4.064452e-005,4.064452e-005,,,,,,,,,,,,,,,,,,,,
1524281603.944,,0.000000e+000,3.399788e+001,3.399788e+001,1,0,1.161290e+000,0.000000e+000,5.989166e-001,5.989166e-001,-3.507486e-001,-3.630265e-001,5.002267e-001,-4.494385e-001,-4.617164e-001,-6.527465e-006,-6.527465e-006,,,,,,,,,,,,,,,,,,,,
1524281616.736,,0.000000e+000,3.399788e+001,3.399862e+001,1,0,1.290323e+000,0.000000e+000,1.943999e-001,1.943999e-001,-8.003010e-001,-8.133458e-001,7.620563e-002,-9.184954e-001,-9.315401e-001,-5.625471e-005,-5.625471e-005,,,,,,,,,,,,,,,,,,,,
1524281629.349,,0.000000e+000,3.399936e+001,3.399936e+001,1,0,1.419355e+000,0.000000e+000,-2.906844e-001,-2.906844e-001,-1.284103e+000,-1.298861e+000,-4.119474e-001,-1.405366e+000,-1.420124e+000,-1.097004e-004,-1.097004e-004,,,,,,,,,,,,,,,,,,,,
1524281642.172,,0.000000e+000,3.399788e+001,3.399862e+001,1,0,1.548387e+000,0.000000e+000,-8.276494e-001,-8.276494e-001,-1.768894e+000,-1.784965e+000,-9.473371e-001,-1.888581e+000,-1.904653e+000,-1.632915e-004,-1.632915e-004,,,,,,,,,,,,,,,,,,,,
1524281654.754,,0.000000e+000,3.399788e+001,3.399788e+001,1,0,1.677419e+000,0.000000e+000,-1.246052e+000,-1.246052e+000,-2.232344e+000,-2.249256e+000,-1.345683e+000,-2.331975e+000,-2.348888e+000,-2.145271e-004,-2.145271e-004,,,,,,,,,,,,,,,,,,,,
1524281667.565,,0.000000e+000,3.399862e+001,3.399788e+001,1,0,1.806452e+000,0.000000e+000,-1.634852e+000,-1.634852e+000,-2.619594e+000,-2.637729e+000,-1.695781e+000,-2.680524e+000,-2.698658e+000,-2.573453e-004,-2.573453e-004,,,,,,,,,,,,,,,,,,,,
1524281680.322,,0.000000e+000,3.399641e+001,3.399936e+001,1,0,1.935484e+000,0.000000e+000,-1.877165e+000,-1.877165e+000,-2.859792e+000,-2.879206e+000,-1.892152e+000,-2.874779e+000,-2.894193e+000,-2.839391e-004,-2.839391e-004,,,,,,,,,,,,,,,,,,,,
1524281692.910,,0.000000e+000,3.399567e+001,3.399788e+001,1,0,2.064516e+000,0.000000e+000,-1.974060e+000,-1.974060e+000,-2.905736e+000,-2.927448e+000,-1.944405e+000,-2.876081e+000,-2.897793e+000,-2.890915e-004,-2.890915e-004,,,,,,,,,,,,,,,,,,,,
1524281705.730,,0.000000e+000,3.399714e+001,3.399788e+001,1,0,2.193548e+000,0.000000e+000,-1.774929e+000,-1.774929e+000,-2.752483e+000,-2.773916e+000,-1.704378e+000,-2.681931e+000,-2.703365e+000,-2.722728e-004,-2.722728e-004,,,,,,,,,,,,,,,,,,,,
1524281718.573,,0.000000e+000,3.399273e+001,3.400082e+001,1,0,2.322581e+000,0.000000e+000,-1.452964e+000,-1.452964e+000,-2.428669e+000,-2.451494e+000,-1.358476e+000,-2.334181e+000,-2.357006e+000,-2.366308e-004,-2.366308e-004,,,,,,,,,,,,,,,,,,,,
1524281731.380,,0.000000e+000,3.399641e+001,3.399936e+001,1,0,2.451613e+000,0.000000e+000,-1.019608e+000,-1.019608e+000,-1.993634e+000,-2.018156e+000,-9.169838e-001,-1.891010e+000,-1.915532e+000,-1.887243e-004,-1.887243e-004,,,,,,,,,,,,,,,,,,,,
1524281744.198,,0.000000e+000,3.400230e+001,3.399862e+001,1,0,2.580645e+000,0.000000e+000,-5.421531e-001,-5.421531e-001,-1.513825e+000,-1.539701e+000,-4.357437e-001,-1.407415e+000,-1.433291e+000,-1.358726e-004,-1.358726e-004,,,,,,,,,,,,,,,,,,,,
1524281757.038,,0.000000e+000,3.399347e+001,3.400009e+001,1,0,2.709677e+000,0.000000e+000,-5.767910e-002,-5.767910e-002,-1.027390e+000,-1.054015e+000,4.941721e-002,-9.202934e-001,-9.469187e-001,-8.228903e-005,-8.228903e-005,,,,,,,,,,,,,,,,,,,,
1524281769.846,,0.000000e+000,3.400009e+001,3.399936e+001,1,0,2.838710e+000,0.000000e+000,4.176394e-001,4.176394e-001,-5.500169e-001,-5.772806e-001,5.172884e-001,-4.503679e-001,-4.776316e-001,-2.969286e-005,-2.969286e-005,,,,,,,,,,,,,,,,,,,,
1524281782.821,,0.000000e+000,3.400377e+001,3.400082e+001,1,0,2.967742e+000,0.000000e+000,8.691539e-001,8.691539e-001,-9.637544e-002,-1.252875e-001,9.579154e-001,-7.613936e-003,-3.652596e-002,2.026076e-005,2.026076e-005,,,,,,,,,,,,,,,,,,,,
1524281795.914,,0.000000e+000,3.399714e+001,3.399936e+001,1,0,3.096774e+000,0.000000e+000,1.292744e+000,1.292744e+000,3.292431e-001,2.991707e-001,1.361627e+000,3.981258e-001,3.680534e-001,6.713950e-005,6.713950e-005,,,,,,,,,,,,,,,,,,,,
1524281808.727,,0.000000e+000,3.399788e+001,3.399788e+001,1,0,3.225806e+000,0.000000e+000,1.672694e+000,1.672694e+000,7.109180e-001,6.789535e-001,1.712517e+000,7.507412e-001,7.187767e-001,1.091460e-004,1.091460e-004,,,,,,,,,,,,,,,,,,,,
1524281821.224,,0.000000e+000,3.399862e+001,3.399862e+001,1,0,3.354839e+000,0.000000e+000,1.976043e+000,1.976043e+000,1.016252e+000,9.829665e-001,1.986905e+000,1.027113e+000,9.938276e-001,1.427440e-004,1.427440e-004,,,,,,,,,,,,,,,,,,,,
1524281833.789,,0.000000e+000,3.399788e+001,3.399936e+001,1,0,3.483871e+000,0.000000e+000,2.188449e+000,2.188449e+000,1.231379e+000,1.196166e+000,2.161203e+000,1.204133e+000,1.168920e+000,1.663681e-004,1.663681e-004,,,,,,,,,,,,,,,,,,,,
1524281846.242,,0.000000e+000,3.399641e+001,3.399936e+001,1,0,3.612903e+000,0.000000e+000,2.280308e+000,2.280308e+000,1.325090e+000,1.290738e+000,2.226177e+000,1.270958e+000,1.236606e+000,1.766850e-004,1.766850e-004,,,,,,,,,,,,,,,,,,,,
1524281859.082,,0.000000e+000,3.399936e+001,3.399936e+001,1,0,3.741935e+000,0.000000e+000,2.257420e+000,2.257420e+000,1.304480e+000,1.269038e+000,2.190295e+000,1.237355e+000,1.201914e+000,1.743313e-004,1.743313e-004,,,,,,,,,,,,,,,,,,,,
1524281871.908,,0.000000e+000,3.399788e+001,3.400009e+001,1,0,3.870968e+000,0.000000e+000,2.155032e+000,2.155032e+000,1.204022e+000,1.167499e+000,2.081456e+000,1.130446e+000,1.093924e+000,1.631633e-004,1.631633e-004,,,,,,,,,,,,,,,,,,,,
1524281884.723,,0.000000e+000,3.399862e+001,3.399936e+001,1,0,4.000000e+000,0.000000e+000,2.006866e+000,2.006866e+000,1.058369e+000,1.020154e+000,1.933177e+000,9.846790e-001,9.464641e-001,1.469956e-004,1.469956e-004,,,,,,,,,,,,,,,,,,,,
1524281910.516,,0.000000e+000,3.399862e+001,3.400009e+001,1,0,0.000000e+000,0.000000e+000,1.893645e+000,1.893645e+000,9.092343e-001,9.092343e-001,1.969361e+000,9.849511e-001,9.849511e-001,1.333192e-004,1.333192e-004,,,,,,,,,,,,,,,,,,,,
1524281922.978,,0.000000e+000,3.399788e+001,3.399862e+001,1,0,1.290323e-001,0.000000e+000,2.023041e+000,2.023041e+000,1.040004e+000,1.038771e+000,2.114392e+000,1.131355e+000,1.130122e+000,1.477052e-004,1.477052e-004,,,,,,,,,,,,,,,,,,,,
1524281935.546,,0.000000e+000,3.399862e+001,3.399862e+001,1,0,2.580645e-001,0.000000e+000,2.148928e+000,2.148928e+000,1.168558e+000,1.166077e+000,2.218836e+000,1.238466e+000,1.235984e+000,1.618087e-004,1.618087e-004,,,,,,,,,,,,,,,,,,,,
1524281948.359,,0.000000e+000,3.399862e+001,3.399936e+001,1,0,3.870968e-001,0.000000e+000,2.205081e+000,2.205081e+000,1.226746e+000,1.223134e+000,2.250907e+000,1.272572e+000,1.268960e+000,1.681098e-004,1.681098e-004,,,,,,,,,,,,,,,,,,,,
1524281961.179,,0.000000e+000,3.399862e+001,3.399862e+001,1,0,5.161290e-001,0.000000e+000,2.168154e+000,2.168154e+000,1.193010e+000,1.188339e+000,2.181177e+000,1.206033e+000,1.201362e+000,1.642756e-004,1.642756e-004,,,,,,,,,,,,,,,,,,,,
1524281974.024,,0.000000e+000,3.399936e+001,3.399936e+001,1,0,6.451613e-001,0.000000e+000,2.016022e+000,2.016022e+000,1.042955e+000,1.037055e+000,2.001868e+000,1.028800e+000,1.022900e+000,1.476423e-004,1.476423e-004,,,,,,,,,,,,,,,,,,,,
1524281986.817,,0.000000e+000,3.399714e+001,3.399936e+001,1,0,7.741935e-001,0.000000e+000,1.761196e+000,1.761196e+000,7.900248e-001,7.829889e-001,1.723374e+000,7.522025e-001,7.451667e-001,1.196484e-004,1.196484e-004,,,,,,,,,,,,,,,,,,,,
1524281999.674,,0.000000e+000,3.399714e+001,3.399936e+001,1,0,9.032258e-001,0.000000e+000,1.427024e+000,1.427024e+000,4.578612e-001,4.496739e-001,1.368235e+000,3.990726e-001,3.908852e-001,8.292012e-005,8.292012e-005,,,,,,,,,,,,,,,,,,,,
1524282012.487,,0.000000e+000,3.400009e+001,3.399862e+001,1,0,1.032258e+000,0.000000e+000,1.037614e+000,1.037614e+000,7.035346e-002,6.106520e-002,9.596247e-001,-7.635339e-003,-1.692361e-002,4.007915e-005,4.007915e-005,,,,,,,,,,,,,,,,,,,,
1524282026.442,,0.000000e+000,3.399862e+001,3.399788e+001,1,0,1.161290e+000,0.000000e+000,6.095979e-001,6.095979e-001,-3.553950e-001,-3.656789e-001,5.133306e-001,-4.516623e-001,-4.619462e-001,-6.990100e-006,-6.990100e-006,,,,,,,,,,,,,,,,,,,,
1524282038.263,,0.000000e+000,3.399788e+001,3.399936e+001,1,0,1.290323e+000,0.000000e+000,1.547265e-001,1.547265e-001,-8.078293e-001,-8.199553e-001,3.912745e-002,-9.234283e-001,-9.355543e-001,-5.695321e-005,-5.695321e-005,,,,,,,,,,,,,,,,,,,,
1524282051.298,,0.000000e+000,3.399714e+001,3.399862e+001,1,0,1.419355e+000,0.000000e+000,-3.349355e-001,-3.349355e-001,-1.295546e+000,-1.308718e+000,-4.516438e-001,-1.412254e+000,-1.425426e+000,-1.108561e-004,-1.108561e-004,,,,,,,,,,,,,,,,,,,,
1524282063.485,,0.000000e+000,3.399788e+001,3.399936e+001,1,0,1.548387e+000,0.000000e+000,-8.230717e-001,-8.230717e-001,-1.781805e+000,-1.796008e+000,-9.396484e-001,-1.898382e+000,-1.912585e+000,-1.645925e-004,-1.645925e-004,,,,,,,,,,,,,,,,,,,,
1524282076.103,,0.000000e+000,3.399862e+001,3.399788e+001,1,0,1.677419e+000,0.000000e+000,-1.289082e+000,-1.289082e+000,-2.245838e+000,-2.261178e+000,-1.387410e+000,-2.344166e+000,-2.359507e+000,-2.158734e-004,-2.158734e-004,,,,,,,,,,,,,,,,,,,,
1524282076.103,,0.000000e+000,3.399862e+001,3.399788e+001,1,0,4.000000e+000,0.000000e+000,1.993591e+000,1.993591e+000,1.058076e+000,1.021495e+000,1.922408e+000,9.868923e-001,9.503117e-001,1.470944e-004,1.470944e-004,,,,,,,,,,,,,,,,,,,,