File: Experimental Raw Data/MFn1 VRM/raw/MFn1_VRMac_35K_750s.dc.raw
[Header]
TITLE,MPMS DC Measurement
BYAPP,MPMS Measurement,2.1,Raw with ABS
FILEOPENTIME, 1524344008.845000 4/21/2018, 2:53:28 PM

INFO, APPNAME, MPMS MultiVu Application, Revision 1.61,  Build 082

INFO, NAME, MFn1
INFO, WEIGHT, 1.000
INFO, AREA, 1.000
INFO, LENGTH, 1.000
INFO, SHAPE, 0
INFO, COMMENT,
INFO, SEQUENCE FILE: VRMac_35K_750s_VRMde_35Klinear.seq


INFO, BACKGROUND DATA FILE:, None


STARTUPAXIS,X,8,LINEAR,AUTO,0.000000,0.000000
STARTUPAXIS,Y1,10,LINEAR,AUTO,0.000000,0.000000


STARTUPGROUP,Longitudinal
FIELDGROUP,Longitudinal,1,3,4,5,6,8,9,10,11,12,13,14,15,16,17,18,19,20,21,22,23
FIELDGROUP,Transverse,1,3,4,5,6,8,9,24,25,26,27,28,29,30,31,32,33,34,35,36,37

PLOT_APPEARANCE,ALL,HORZ_GRID_ON,VERT_GRID_ON,MARKERS_ONLY

[Data]
Time,Comment,Field (Oe),Start Temperature (K),End Temperature (K),Scan,Rejected,Position (cm),Rot Position (deg),Long Voltage,Long Average Voltage,Long Detrended Voltage,Long Demeaned Voltage,Long Regression Fit,Long Detrended Fit,Long Demeaned Fit,Long Scaled Response,Long Avg. Scaled Response,Long Background Response,Long Response [w/ABS],Long Detrended Resp. [w/ABS],Long Fit [w/ABS],Long Detrended Fit [w/ABS],Trans Voltage,Trans Average Voltage,Trans Detrended Voltage,Trans Demeaned Voltage,Trans Regression Fit,Trans Detrended Fit,Trans Demeaned Fit,Trans Scaled Response,Trans Avg Scaled Response,Trans Background Response,Trans Response [w/ABS],Trans Detrended Resp. [w/ABS],Trans Fit [w/ABS],Trans Detrended Fit [w/ABS],
1524344008.830,,0.000000e+000,3.499481e+001,3.500106e+001,1,0,0.000000e+000,0.000000e+000,1.315022e+000,1.315022e+000,7.913781e-001,7.913781e-001,1.425599e+000,9.019551e-001,9.019551e-001,1.187846e-004,1.187846e-004,,,,,,,,,,,,,,,,,,,,
1524344008.830,,0.000000e+000,3.499481e+001,3.500106e+001,1,0,1.161290e+000,0.000000e+000,2.247654e-001,2.247654e-001,-2.791556e-001,-2.988790e-001,9.081888e-002,-4.131021e-001,-4.328255e-001,-7.811577e-007,-7.811577e-007,,,,,,,,,,,,,,,,,,,,
1524344008.830,,0.000000e+000,3.499481e+001,3.500106e+001,1,0,2.322581e+000,0.000000e+000,-1.788052e+000,-1.788052e+000,-2.272250e+000,-2.311697e+000,-1.658218e+000,-2.142415e+000,-2.181862e+000,-2.221356e-004,-2.221356e-004,,,,,,,,,,,,,,,,,,,,
1524344008.830,,0.000000e+000,3.499481e+001,3.500106e+001,1,0,3.483871e+000,0.000000e+000,1.595636e+000,1.595636e+000,1.131162e+000,1.071991e+000,1.568090e+000,1.103616e+000,1.044446e+000,1.519216e-004,1.519216e-004,,,,,,,,,,,,,,,,,,,,
1524344021.582,,0.000000e+000,3.500106e+001,3.499950e+001,1,0,5.161290e-001,0.000000e+000,1.611810e+000,1.611810e+000,1.093024e+000,1.083675e+000,1.630672e+000,1.111886e+000,1.102536e+000,1.517618e-004,1.517618e-004,,,,,,,,,,,,,,,,,,,,
1524344021.582,,0.000000e+000,3.500106e+001,3.499950e+001,1,0,1.677419e+000,0.000000e+000,-1.525139e+000,-1.525139e+000,-2.022889e+000,-2.053275e+000,-1.660718e+000,-2.158468e+000,-2.188854e+000,-1.935730e-004,-1.935730e-004,,,,,,,,,,,,,,,,,,,,
1524344021.582,,0.000000e+000,3.500106e+001,3.499950e+001,1,0,2.838710e+000,0.000000e+000,-7.522698e-002,-7.522698e-002,-5.519399e-001,-6.033627e-001,6.051506e-002,-4.161979e-001,-4.676207e-001,-3.282643e-005,-3.282643e-005,,,,,,,,,,,,,,,,,,,,
1524344021.582,,0.000000e+000,3.500106e+001,3.499950e+001,1,0,4.000000e+000,0.000000e+000,1.477836e+000,1.477836e+000,1.022160e+000,9.497005e-001,1.364390e+000,9.087135e-001,8.362541e-001,1.393011e-004,1.393011e-004,,,,,,,,,,,,,,,,,,,,
1524344034.278,,0.000000e+000,3.499950e+001,3.500106e+001,1,0,1.032258e+000,0.000000e+000,6.121920e-001,6.121920e-001,1.031429e-001,8.426899e-002,5.019737e-001,-7.075319e-003,-2.594924e-002,4.203461e-005,4.203461e-005,,,,,,,,,,,,,,,,,,,,
1524344034.278,,0.000000e+000,3.499950e+001,3.500106e+001,1,0,2.193548e+000,0.000000e+000,-2.101472e+000,-2.101472e+000,-2.589288e+000,-2.629395e+000,-2.006923e+000,-2.494739e+000,-2.534846e+000,-2.565907e-004,-2.565907e-004,,,,,,,,,,,,,,,,,,,,
1524344034.278,,0.000000e+000,3.499950e+001,3.500106e+001,1,0,3.354839e+000,0.000000e+000,1.402457e+000,1.402457e+000,9.358740e-001,8.745338e-001,1.420456e+000,9.538729e-001,8.925327e-001,1.307886e-004,1.307886e-004,,,,,,,,,,,,,,,,,,,,
1524344046.983,,0.000000e+000,3.500028e+001,3.500106e+001,1,0,3.870968e-001,0.000000e+000,1.645380e+000,1.645380e+000,1.121825e+000,1.114047e+000,1.708800e+000,1.185244e+000,1.177466e+000,1.556380e-004,1.556380e-004,,,,,,,,,,,,,,,,,,,,
1524344046.983,,0.000000e+000,3.500028e+001,3.500106e+001,1,0,1.548387e+000,0.000000e+000,-1.105058e+000,-1.105058e+000,-1.605281e+000,-1.636392e+000,-1.265537e+000,-1.765759e+000,-1.796871e+000,-1.469675e-004,-1.469675e-004,,,,,,,,,,,,,,,,,,,,
1524344046.983,,0.000000e+000,3.500028e+001,3.500106e+001,1,0,2.709677e+000,0.000000e+000,-5.349813e-001,-5.349813e-001,-1.011870e+000,-1.066315e+000,-3.822481e-001,-8.591367e-001,-9.135819e-001,-8.321114e-005,-8.321114e-005,,,,,,,,,,,,,,,,,,,,
1524344046.983,,0.000000e+000,3.500028e+001,3.500106e+001,1,0,3.870968e+000,0.000000e+000,1.621271e+000,1.621271e+000,1.167716e+000,1.089937e+000,1.507548e+000,1.053993e+000,9.762143e-001,1.555525e-004,1.555525e-004,,,,,,,,,,,,,,,,,,,,
1524344060.638,,0.000000e+000,3.500106e+001,3.500184e+001,1,0,9.032258e-001,0.000000e+000,9.735256e-001,9.735256e-001,4.597076e-001,4.425375e-001,8.867404e-001,3.729224e-001,3.557523e-001,8.185077e-005,8.185077e-005,,,,,,,,,,,,,,,,,,,,
1524344060.638,,0.000000e+000,3.500106e+001,3.500184e+001,1,0,2.064516e+000,0.000000e+000,-2.241398e+000,-2.241398e+000,-2.733140e+000,-2.772386e+000,-2.205692e+000,-2.697434e+000,-2.736680e+000,-2.720489e-004,-2.720489e-004,,,,,,,,,,,,,,,,,,,,
1524344060.638,,0.000000e+000,3.500106e+001,3.500184e+001,1,0,3.225806e+000,0.000000e+000,1.113298e+000,1.113298e+000,6.436320e-001,5.823101e-001,1.172765e+000,7.030990e-001,6.417770e-001,9.889608e-005,9.889608e-005,,,,,,,,,,,,,,,,,,,,
1524344072.753,,0.000000e+000,3.499872e+001,3.500184e+001,1,0,2.580645e-001,0.000000e+000,1.594720e+000,1.594720e+000,1.066737e+000,1.061759e+000,1.690312e+000,1.162328e+000,1.157351e+000,1.498681e-004,1.498681e-004,,,,,,,,,,,,,,,,,,,,
1524344072.753,,0.000000e+000,3.499872e+001,3.500184e+001,1,0,1.419355e+000,0.000000e+000,-6.573586e-001,-6.573586e-001,-1.162945e+000,-1.190320e+000,-8.180701e-001,-1.323656e+000,-1.351031e+000,-9.778645e-005,-9.778645e-005,,,,,,,,,,,,,,,,,,,,
1524344072.753,,0.000000e+000,3.499872e+001,3.500184e+001,1,0,2.580645e+000,0.000000e+000,-9.950408e-001,-9.950408e-001,-1.478229e+000,-1.528002e+000,-8.404683e-001,-1.323657e+000,-1.373430e+000,-1.342202e-004,-1.342202e-004,,,,,,,,,,,,,,,,,,,,
1524344072.753,,0.000000e+000,3.499872e+001,3.500184e+001,1,0,3.741935e+000,0.000000e+000,1.724270e+000,1.724270e+000,1.263479e+000,1.191308e+000,1.623119e+000,1.162328e+000,1.090158e+000,1.666328e-004,1.666328e-004,,,,,,,,,,,,,,,,,,,,
1524344085.418,,0.000000e+000,3.500184e+001,3.499481e+001,1,0,7.741935e-001,0.000000e+000,1.282979e+000,1.282979e+000,7.636402e-001,7.473404e-001,1.227747e+000,7.084090e-001,6.921092e-001,1.159727e-004,1.159727e-004,,,,,,,,,,,,,,,,,,,,
1524344085.418,,0.000000e+000,3.500184e+001,3.499481e+001,1,0,1.935484e+000,0.000000e+000,-2.194858e+000,-2.194858e+000,-2.689746e+000,-2.730496e+000,-2.222915e+000,-2.717803e+000,-2.758553e+000,-2.668476e-004,-2.668476e-004,,,,,,,,,,,,,,,,,,,,
1524344085.418,,0.000000e+000,3.500184e+001,3.499481e+001,1,0,3.096774e+000,0.000000e+000,7.499809e-001,7.499809e-001,2.795420e-001,2.143428e-001,8.461771e-001,3.757382e-001,3.105389e-001,5.896401e-005,5.896401e-005,,,,,,,,,,,,,,,,,,,,
1524344098.116,,0.000000e+000,3.499481e+001,3.500498e+001,1,0,1.290323e-001,0.000000e+000,1.475853e+000,1.475853e+000,9.452926e-001,9.427250e-001,1.599331e+000,1.068771e+000,1.066203e+000,1.369288e-004,1.369288e-004,,,,,,,,,,,,,,,,,,,,
1524344098.116,,0.000000e+000,3.499481e+001,3.500498e+001,1,0,1.290323e+000,0.000000e+000,-2.079805e-001,-2.079805e-001,-7.154323e-001,-7.411081e-001,-3.637297e-001,-8.711817e-001,-8.968574e-001,-4.800342e-005,-4.800342e-005,,,,,,,,,,,,,,,,,,,,
1524344098.116,,0.000000e+000,3.499481e+001,3.500498e+001,1,0,2.451613e+000,0.000000e+000,-1.454948e+000,-1.454948e+000,-1.939291e+000,-1.988075e+000,-1.306173e+000,-1.790517e+000,-1.839301e+000,-1.847350e-004,-1.847350e-004,,,,,,,,,,,,,,,,,,,,
1524344098.116,,0.000000e+000,3.499481e+001,3.500498e+001,1,0,3.612903e+000,0.000000e+000,1.732662e+000,1.732662e+000,1.271426e+000,1.199534e+000,1.663098e+000,1.201862e+000,1.129970e+000,1.678129e-004,1.678129e-004,,,,,,,,,,,,,,,,,,,,
1524344110.841,,0.000000e+000,3.500498e+001,3.499872e+001,1,0,6.451613e-001,0.000000e+000,1.512779e+000,1.512779e+000,9.930669e-001,9.806030e-001,1.493708e+000,9.739950e-001,9.615310e-001,1.414654e-004,1.414654e-004,,,,,,,,,,,,,,,,,,,,
1524344110.841,,0.000000e+000,3.500498e+001,3.499872e+001,1,0,1.806452e+000,0.000000e+000,-1.959564e+000,-1.959564e+000,-2.456841e+000,-2.491740e+000,-2.050087e+000,-2.547364e+000,-2.582263e+000,-2.408229e-004,-2.408229e-004,,,,,,,,,,,,,,,,,,,,
1524344110.841,,0.000000e+000,3.500498e+001,3.499872e+001,1,0,2.967742e+000,0.000000e+000,3.472953e-001,3.472953e-001,-1.275471e-001,-1.848812e-001,4.676179e-001,-7.224565e-003,-6.455863e-002,1.452444e-005,1.452444e-005,,,,,,,,,,,,,,,,,,,,
1524344123.501,,0.000000e+000,3.499872e+001,3.499950e+001,1,0,0.000000e+000,0.000000e+000,1.358663e+000,1.358663e+000,8.237368e-001,8.237368e-001,1.470880e+000,9.359531e-001,9.359531e-001,1.238573e-004,1.238573e-004,,,,,,,,,,,,,,,,,,,,
1524344123.501,,0.000000e+000,3.499872e+001,3.499950e+001,1,0,1.161290e+000,0.000000e+000,2.183566e-001,2.183566e-001,-2.936060e-001,-3.165699e-001,8.328921e-002,-4.286734e-001,-4.516373e-001,-1.111352e-006,-1.111352e-006,,,,,,,,,,,,,,,,,,,,
1524344123.501,,0.000000e+000,3.499872e+001,3.499950e+001,1,0,2.322581e+000,0.000000e+000,-1.866026e+000,-1.866026e+000,-2.355025e+000,-2.400952e+000,-1.734172e+000,-2.223171e+000,-2.269098e+000,-2.302426e-004,-2.302426e-004,,,,,,,,,,,,,,,,,,,,
1524344123.501,,0.000000e+000,3.499872e+001,3.499950e+001,1,0,3.483871e+000,0.000000e+000,1.637293e+000,1.637293e+000,1.171258e+000,1.102367e+000,1.611250e+000,1.145216e+000,1.076324e+000,1.571331e-004,1.571331e-004,,,,,,,,,,,,,,,,,,,,
1524344135.994,,0.000000e+000,3.500028e+001,3.500106e+001,1,0,5.161290e-001,0.000000e+000,1.657130e+000,1.657130e+000,1.130655e+000,1.120429e+000,1.673297e+000,1.146822e+000,1.136596e+000,1.570161e-004,1.570161e-004,,,,,,,,,,,,,,,,,,,,
1524344135.994,,0.000000e+000,3.500028e+001,3.500106e+001,1,0,1.677419e+000,0.000000e+000,-1.584192e+000,-1.584192e+000,-2.087659e+000,-2.120893e+000,-1.722821e+000,-2.226288e+000,-2.259522e+000,-1.997619e-004,-1.997619e-004,,,,,,,,,,,,,,,,,,,,
1524344135.994,,0.000000e+000,3.500028e+001,3.500106e+001,1,0,2.838710e+000,0.000000e+000,-9.002823e-002,-9.002823e-002,-5.704870e-001,-6.267292e-001,5.118375e-002,-4.292750e-001,-4.855173e-001,-3.406042e-005,-3.406042e-005,,,,,,,,,,,,,,,,,,,,
1524344135.994,,0.000000e+000,3.500028e+001,3.500106e+001,1,0,4.000000e+000,0.000000e+000,1.512627e+000,1.512627e+000,1.055176e+000,9.759259e-001,1.394716e+000,9.372658e-001,8.580154e-001,1.436113e-004,1.436113e-004,,,,,,,,,,,,,,,,,,,,
1524344148.627,,0.000000e+000,3.499872e+001,3.499950e+001,1,0,1.032258e+000,0.000000e+000,6.236362e-001,6.236362e-001,1.051855e-001,8.480787e-002,5.111815e-001,-7.269226e-003,-2.764690e-002,4.316810e-005,4.316810e-005,,,,,,,,,,,,,,,,,,,,
1524344148.627,,0.000000e+000,3.499872e+001,3.499950e+001,1,0,2.193548e+000,0.000000e+000,-2.160525e+000,-2.160525e+000,-2.656051e+000,-2.699353e+000,-2.067582e+000,-2.563107e+000,-2.606410e+000,-2.631731e-004,-2.631731e-004,,,,,,,,,,,,,,,,,,,,
1524344148.627,,0.000000e+000,3.499872e+001,3.499950e+001,1,0,3.354839e+000,0.000000e+000,1.434196e+000,1.434196e+000,9.615946e-001,8.953671e-001,1.452615e+000,9.800140e-001,9.137865e-001,1.342857e-004,1.342857e-004,,,,,,,,,,,,,,,,,,,,
1524344161.372,,0.000000e+000,3.499794e+001,3.499872e+001,1,0,3.870968e-001,0.000000e+000,1.682765e+000,1.682765e+000,1.151792e+000,1.144108e+000,1.746041e+000,1.215067e+000,1.207384e+000,1.596573e-004,1.596573e-004,,,,,,,,,,,,,,,,,,,,
1524344161.372,,0.000000e+000,3.499794e+001,3.499872e+001,1,0,1.548387e+000,0.000000e+000,-1.140154e+000,-1.140154e+000,-1.648077e+000,-1.678811e+000,-1.302267e+000,-1.810190e+000,-1.840924e+000,-1.509556e-004,-1.509556e-004,,,,,,,,,,,,,,,,,,,,
1524344161.372,,0.000000e+000,3.499794e+001,3.499872e+001,1,0,2.709677e+000,0.000000e+000,-5.485618e-001,-5.485618e-001,-1.033434e+000,-1.087219e+000,-3.958826e-001,-8.807544e-001,-9.345394e-001,-8.483582e-005,-8.483582e-005,,,,,,,,,,,,,,,,,,,,
1524344161.372,,0.000000e+000,3.499794e+001,3.499872e+001,1,0,3.870968e+000,0.000000e+000,1.654841e+000,1.654841e+000,1.193020e+000,1.116184e+000,1.542335e+000,1.080514e+000,1.003678e+000,1.591196e-004,1.591196e-004,,,,,,,,,,,,,,,,,,,,
1524344173.952,,0.000000e+000,3.499950e+001,3.500028e+001,1,0,9.032258e-001,0.000000e+000,9.942779e-001,9.942779e-001,4.705892e-001,4.521440e-001,9.051517e-001,3.814630e-001,3.630178e-001,8.384306e-005,8.384306e-005,,,,,,,,,,,,,,,,,,,,
1524344173.952,,0.000000e+000,3.499950e+001,3.500028e+001,1,0,2.064516e+000,0.000000e+000,-2.299840e+000,-2.299840e+000,-2.799813e+000,-2.841974e+000,-2.259236e+000,-2.759209e+000,-2.801370e+000,-2.787341e-004,-2.787341e-004,,,,,,,,,,,,,,,,,,,,
1524344173.952,,0.000000e+000,3.499950e+001,3.500028e+001,1,0,3.225806e+000,0.000000e+000,1.133440e+000,1.133440e+000,6.571819e-001,5.913063e-001,1.195459e+000,7.192010e-001,6.533254e-001,1.009416e-004,1.009416e-004,,,,,,,,,,,,,,,,,,,,
1524344186.970,,0.000000e+000,3.499794e+001,3.499794e+001,1,0,2.580645e-001,0.000000e+000,1.626001e+000,1.626001e+000,1.089001e+000,1.083997e+000,1.723561e+000,1.186561e+000,1.181556e+000,1.529574e-004,1.529574e-004,,,,,,,,,,,,,,,,,,,,
1524344186.970,,0.000000e+000,3.499794e+001,3.499794e+001,1,0,1.419355e+000,0.000000e+000,-6.749066e-001,-6.749066e-001,-1.189385e+000,-1.216911e+000,-8.367734e-001,-1.351252e+000,-1.378778e+000,-1.000800e-004,-1.000800e-004,,,,,,,,,,,,,,,,,,,,
1524344186.970,,0.000000e+000,3.499794e+001,3.499794e+001,1,0,2.580645e+000,0.000000e+000,-1.016709e+000,-1.016709e+000,-1.508666e+000,-1.558713e+000,-8.592952e-001,-1.351253e+000,-1.401300e+000,-1.369637e-004,-1.369637e-004,,,,,,,,,,,,,,,,,,,,
1524344186.970,,0.000000e+000,3.499794e+001,3.499794e+001,1,0,3.741935e+000,0.000000e+000,1.755245e+000,1.755245e+000,1.285809e+000,1.213240e+000,1.655997e+000,1.186561e+000,1.113992e+000,1.697021e-004,1.697021e-004,,,,,,,,,,,,,,,,,,,,
1524344199.110,,0.000000e+000,3.500106e+001,3.499950e+001,1,0,7.741935e-001,0.000000e+000,1.305562e+000,1.305562e+000,7.765518e-001,7.600436e-001,1.250531e+000,7.215211e-001,7.050129e-001,1.179735e-004,1.179735e-004,,,,,,,,,,,,,,,,,,,,
1524344199.110,,0.000000e+000,3.500106e+001,3.499950e+001,1,0,1.935484e+000,0.000000e+000,-2.236057e+000,-2.236057e+000,-2.740305e+000,-2.781575e+000,-2.263860e+000,-2.768108e+000,-2.809378e+000,-2.718726e-004,-2.718726e-004,,,,,,,,,,,,,,,,,,,,
1524344199.110,,0.000000e+000,3.500106e+001,3.499950e+001,1,0,3.096774e+000,0.000000e+000,7.647822e-001,7.647822e-001,2.852968e-001,2.192639e-001,8.621783e-001,3.826929e-001,3.166600e-001,6.012918e-005,6.012918e-005,,,,,,,,,,,,,,,,,,,,
1524344211.780,,0.000000e+000,3.499950e+001,3.499872e+001,1,0,1.290323e-001,0.000000e+000,1.503014e+000,1.503014e+000,9.626271e-001,9.601234e-001,1.627497e+000,1.087110e+000,1.084606e+000,1.392862e-004,1.392862e-004,,,,,,,,,,,,,,,,,,,,
1524344211.780,,0.000000e+000,3.499950e+001,3.499872e+001,1,0,1.290323e+000,0.000000e+000,-2.134737e-001,-2.134737e-001,-7.313270e-001,-7.563639e-001,-3.682771e-001,-8.861303e-001,-9.111673e-001,-4.927002e-005,-4.927002e-005,,,,,,,,,,,,,,,,,,,,
1524344211.780,,0.000000e+000,3.499950e+001,3.499872e+001,1,0,2.451613e+000,0.000000e+000,-1.476616e+000,-1.476616e+000,-1.971936e+000,-2.019506e+000,-1.325920e+000,-1.821241e+000,-1.868811e+000,-1.878073e-004,-1.878073e-004,,,,,,,,,,,,,,,,,,,,
1524344211.780,,0.000000e+000,3.499950e+001,3.499872e+001,1,0,3.612903e+000,0.000000e+000,1.763943e+000,1.763943e+000,1.291156e+000,1.221053e+000,1.695272e+000,1.222485e+000,1.152382e+000,1.705614e-004,1.705614e-004,,,,,,,,,,,,,,,,,,,,
1524344224.483,,0.000000e+000,3.499872e+001,3.499715e+001,1,0,6.451613e-001,0.000000e+000,1.543603e+000,1.543603e+000,1.009231e+000,9.959936e-001,1.524159e+000,9.897872e-001,9.765499e-001,1.438542e-004,1.438542e-004,,,,,,,,,,,,,,,,,,,,
1524344224.483,,0.000000e+000,3.499872e+001,3.499715e+001,1,0,1.806452e+000,0.000000e+000,-1.986267e+000,-1.986267e+000,-2.496812e+000,-2.533876e+000,-2.078122e+000,-2.588667e+000,-2.625731e+000,-2.447300e-004,-2.447300e-004,,,,,,,,,,,,,,,,,,,,
1524344224.483,,0.000000e+000,3.499872e+001,3.499715e+001,1,0,2.967742e+000,0.000000e+000,3.552300e-001,3.552300e-001,-1.314879e-001,-1.923791e-001,4.793762e-001,-7.341722e-003,-6.823295e-002,1.449030e-005,1.449030e-005,,,,,,,,,,,,,,,,,,,,
1524344237.163,,0.000000e+000,3.499715e+001,3.499794e+001,1,0,0.000000e+000,0.000000e+000,1.383841e+000,1.383841e+000,8.358307e-001,8.358307e-001,1.497584e+000,9.495738e-001,9.495738e-001,1.256002e-004,1.256002e-004,,,,,,,,,,,,,,,,,,,,
1524344237.163,,0.000000e+000,3.499715e+001,3.499794e+001,1,0,1.161290e+000,0.000000e+000,2.276646e-001,2.276646e-001,-2.976107e-001,-3.203453e-001,9.036355e-002,-4.349118e-001,-4.576464e-001,-1.127879e-006,-1.127879e-006,,,,,,,,,,,,,,,,,,,,
1524344237.163,,0.000000e+000,3.499715e+001,3.499794e+001,1,0,2.322581e+000,0.000000e+000,-1.886320e+000,-1.886320e+000,-2.388861e+000,-2.434330e+000,-1.752983e+000,-2.255524e+000,-2.300993e+000,-2.335337e-004,-2.335337e-004,,,,,,,,,,,,,,,,,,,,
1524344237.163,,0.000000e+000,3.499715e+001,3.499794e+001,1,0,3.483871e+000,0.000000e+000,1.668269e+000,1.668269e+000,1.188463e+000,1.120259e+000,1.641688e+000,1.161881e+000,1.093678e+000,1.594903e-004,1.594903e-004,,,,,,,,,,,,,,,,,,,,
1524344250.113,,0.000000e+000,3.499637e+001,3.499872e+001,1,0,5.161290e-001,0.000000e+000,1.686275e+000,1.686275e+000,1.144950e+000,1.133802e+000,1.704885e+000,1.163560e+000,1.152412e+000,1.592277e-004,1.592277e-004,,,,,,,,,,,,,,,,,,,,
1524344250.113,,0.000000e+000,3.499637e+001,3.499872e+001,1,0,1.677419e+000,0.000000e+000,-1.605402e+000,-1.605402e+000,-2.121644e+000,-2.157875e+000,-1.742540e+000,-2.258782e+000,-2.295013e+000,-2.030297e-004,-2.030297e-004,,,,,,,,,,,,,,,,,,,,
1524344250.113,,0.000000e+000,3.499637e+001,3.499872e+001,1,0,2.838710e+000,0.000000e+000,-8.239872e-002,-8.239872e-002,-5.735575e-001,-6.348715e-001,5.561835e-002,-4.355404e-001,-4.968545e-001,-3.407003e-005,-3.407003e-005,,,,,,,,,,,,,,,,,,,,
1524344250.113,,0.000000e+000,3.499637e+001,3.499872e+001,1,0,4.000000e+000,0.000000e+000,1.536126e+000,1.536126e+000,1.070050e+000,9.836529e-001,1.417021e+000,9.509455e-001,8.645484e-001,1.454289e-004,1.454289e-004,,,,,,,,,,,,,,,,,,,,
1524344262.821,,0.000000e+000,3.500106e+001,3.499872e+001,1,0,1.032258e+000,0.000000e+000,6.329442e-001,6.329442e-001,1.064407e-001,8.341575e-002,5.191340e-001,-7.369474e-003,-3.039443e-002,4.390493e-005,4.390493e-005,,,,,,,,,,,,,,,,,,,,
1524344262.821,,0.000000e+000,3.500106e+001,3.499872e+001,1,0,2.193548e+000,0.000000e+000,-2.191653e+000,-2.191653e+000,-2.692254e+000,-2.741182e+000,-2.097845e+000,-2.598446e+000,-2.647374e+000,-2.667882e-004,-2.667882e-004,,,,,,,,,,,,,,,,,,,,
1524344262.821,,0.000000e+000,3.500106e+001,3.499872e+001,1,0,3.354839e+000,0.000000e+000,1.448997e+000,1.448997e+000,9.742993e-001,8.994682e-001,1.468223e+000,9.935257e-001,9.186946e-001,1.358476e-004,1.358476e-004,,,,,,,,,,,,,,,,,,,,
1524344275.719,,0.000000e+000,3.499872e+001,3.499794e+001,1,0,3.870968e-001,0.000000e+000,1.701991e+000,1.701991e+000,1.169997e+000,1.161723e+000,1.763595e+000,1.231601e+000,1.223326e+000,1.622583e-004,1.622583e-004,,,,,,,,,,,,,,,,,,,,
1524344275.719,,0.000000e+000,3.499872e+001,3.499794e+001,1,0,1.548387e+000,0.000000e+000,-1.166705e+000,-1.166705e+000,-1.673875e+000,-1.706973e+000,-1.327651e+000,-1.834821e+000,-1.867920e+000,-1.533401e-004,-1.533401e-004,,,,,,,,,,,,,,,,,,,,
1524344275.719,,0.000000e+000,3.499872e+001,3.499794e+001,1,0,2.709677e+000,0.000000e+000,-5.626001e-001,-5.626001e-001,-1.044947e+000,-1.102869e+000,-4.103924e-001,-8.927389e-001,-9.506611e-001,-8.577455e-005,-8.577455e-005,,,,,,,,,,,,,,,,,,,,
1524344275.719,,0.000000e+000,3.499872e+001,3.499794e+001,1,0,3.870968e+000,0.000000e+000,1.665370e+000,1.665370e+000,1.207847e+000,1.125101e+000,1.552739e+000,1.095217e+000,1.012471e+000,1.609566e-004,1.609566e-004,,,,,,,,,,,,,,,,,,,,
1524344288.179,,0.000000e+000,3.499403e+001,3.499872e+001,1,0,9.032258e-001,0.000000e+000,9.900053e-001,9.900053e-001,4.719515e-001,4.536776e-001,9.042164e-001,3.861626e-001,3.678887e-001,8.435103e-005,8.435103e-005,,,,,,,,,,,,,,,,,,,,
1524344288.179,,0.000000e+000,3.499403e+001,3.499872e+001,1,0,2.064516e+000,0.000000e+000,-2.335851e+000,-2.335851e+000,-2.830410e+000,-2.872179e+000,-2.298644e+000,-2.793203e+000,-2.834971e+000,-2.817360e-004,-2.817360e-004,,,,,,,,,,,,,,,,,,,,
1524344288.179,,0.000000e+000,3.499403e+001,3.499872e+001,1,0,3.225806e+000,0.000000e+000,1.135882e+000,1.135882e+000,6.648177e-001,5.995538e-001,1.199125e+000,7.280616e-001,6.627977e-001,1.021741e-004,1.021741e-004,,,,,,,,,,,,,,,,,,,,
1524344300.892,,0.000000e+000,3.499872e+001,3.499794e+001,1,0,2.580645e-001,0.000000e+000,1.635767e+000,1.635767e+000,1.104805e+000,1.099597e+000,1.732234e+000,1.201272e+000,1.196064e+000,1.551778e-004,1.551778e-004,,,,,,,,,,,,,,,,,,,,
1524344300.892,,0.000000e+000,3.499872e+001,3.499794e+001,1,0,1.419355e+000,0.000000e+000,-6.962692e-001,-6.962692e-001,-1.203797e+000,-1.232439e+000,-8.604773e-001,-1.368005e+000,-1.396647e+000,-1.012605e-004,-1.012605e-004,,,,,,,,,,,,,,,,,,,,
1524344300.892,,0.000000e+000,3.499872e+001,3.499794e+001,1,0,2.580645e+000,0.000000e+000,-1.039902e+000,-1.039902e+000,-1.523995e+000,-1.576072e+000,-8.839123e-001,-1.368005e+000,-1.420082e+000,-1.383127e-004,-1.383127e-004,,,,,,,,,,,,,,,,,,,,
1524344300.892,,0.000000e+000,3.499872e+001,3.499794e+001,1,0,3.741935e+000,0.000000e+000,1.762264e+000,1.762264e+000,1.301606e+000,1.226095e+000,1.661930e+000,1.201272e+000,1.125760e+000,1.717202e-004,1.717202e-004,,,,,,,,,,,,,,,,,,,,
1524344313.789,,0.000000e+000,3.499794e+001,3.499950e+001,1,0,7.741935e-001,0.000000e+000,1.304799e+000,1.304799e+000,7.848688e-001,7.693232e-001,1.249757e+000,7.298264e-001,7.142808e-001,1.191286e-004,1.191286e-004,,,,,,,,,,,,,,,,,,,,
1524344313.789,,0.000000e+000,3.499794e+001,3.499950e+001,1,0,1.935484e+000,0.000000e+000,-2.273900e+000,-2.273900e+000,-2.770511e+000,-2.809375e+000,-2.303359e+000,-2.799971e+000,-2.838835e+000,-2.748617e-004,-2.748617e-004,,,,,,,,,,,,,,,,,,,,
1524344313.789,,0.000000e+000,3.499794e+001,3.499950e+001,1,0,3.096774e+000,0.000000e+000,7.626459e-001,7.626459e-001,2.893523e-001,2.271702e-001,8.603915e-001,3.870979e-001,3.249158e-001,6.102655e-005,6.102655e-005,,,,,,,,,,,,,,,,,,,,
1524344326.250,,0.000000e+000,3.499794e+001,3.499950e+001,1,0,1.290323e-001,0.000000e+000,1.506828e+000,1.506828e+000,9.742342e-001,9.715731e-001,1.631858e+000,1.099264e+000,1.096603e+000,1.410747e-004,1.410747e-004,,,,,,,,,,,,,,,,,,,,
1524344326.250,,0.000000e+000,3.499794e+001,3.499950e+001,1,0,1.290323e+000,0.000000e+000,-2.310216e-001,-2.310216e-001,-7.396657e-001,-7.662769e-001,-3.873933e-001,-8.960374e-001,-9.226486e-001,-4.978642e-005,-4.978642e-005,,,,,,,,,,,,,,,,,,,,
1524344326.250,,0.000000e+000,3.499794e+001,3.499950e+001,1,0,2.451613e+000,0.000000e+000,-1.509728e+000,-1.509728e+000,-1.994422e+000,-2.044983e+000,-1.356908e+000,-1.841602e+000,-1.892164e+000,-1.899888e-004,-1.899888e-004,,,,,,,,,,,,,,,,,,,,
1524344326.250,,0.000000e+000,3.499794e+001,3.499950e+001,1,0,3.612903e+000,0.000000e+000,1.768368e+000,1.768368e+000,1.307624e+000,1.233113e+000,1.696896e+000,1.236152e+000,1.161641e+000,1.725736e-004,1.725736e-004,,,,,,,,,,,,,,,,,,,,
1524344339.277,,0.000000e+000,3.500184e+001,3.499794e+001,1,0,6.451613e-001,0.000000e+000,1.542992e+000,1.542992e+000,1.020375e+000,1.007251e+000,1.522573e+000,9.999561e-001,9.868321e-001,1.453792e-004,1.453792e-004,,,,,,,,,,,,,,,,,,,,
1524344339.277,,0.000000e+000,3.500184e+001,3.499794e+001,1,0,1.806452e+000,0.000000e+000,-2.024567e+000,-2.024567e+000,-2.523561e+000,-2.560308e+000,-2.116269e+000,-2.615263e+000,-2.652010e+000,-2.473709e-004,-2.473709e-004,,,,,,,,,,,,,,,,,,,,
1524344339.277,,0.000000e+000,3.500184e+001,3.499794e+001,1,0,2.967742e+000,0.000000e+000,3.437858e-001,3.437858e-001,-1.315853e-001,-1.919554e-001,4.679539e-001,-7.417169e-003,-6.778735e-002,1.480496e-005,1.480496e-005,,,,,,,,,,,,,,,,,,,,
1524344351.642,,0.000000e+000,3.499715e+001,3.500184e+001,1,0,0.000000e+000,0.000000e+000,1.381857e+000,1.381857e+000,8.461794e-001,8.461794e-001,1.495061e+000,9.593831e-001,9.593831e-001,1.271566e-004,1.271566e-004,,,,,,,,,,,,,,,,,,,,
1524344351.642,,0.000000e+000,3.499715e+001,3.500184e+001,1,0,1.161290e+000,0.000000e+000,2.084382e-001,2.084382e-001,-3.037187e-001,-3.272395e-001,7.275253e-002,-4.394045e-001,-4.629251e-001,-1.444965e-006,-1.444965e-006,,,,,,,,,,,,,,,,,,,,
1524344351.642,,0.000000e+000,3.499715e+001,3.500184e+001,1,0,2.322581e+000,0.000000e+000,-1.921111e+000,-1.921111e+000,-2.409747e+000,-2.456789e+000,-1.790187e+000,-2.278824e+000,-2.325865e+000,-2.355391e-004,-2.355391e-004,,,,,,,,,,,,,,,,,,,,
1524344351.642,,0.000000e+000,3.499715e+001,3.500184e+001,1,0,3.483871e+000,0.000000e+000,1.665370e+000,1.665370e+000,1.200254e+000,1.129692e+000,1.639000e+000,1.173884e+000,1.103322e+000,1.610325e-004,1.610325e-004,,,,,,,,,,,,,,,,,,,,
1524344364.223,,0.000000e+000,3.499481e+001,3.499481e+001,1,0,5.161290e-001,0.000000e+000,1.682460e+000,1.682460e+000,1.157045e+000,1.146565e+000,1.699637e+000,1.174222e+000,1.163742e+000,1.607009e-004,1.607009e-004,,,,,,,,,,,,,,,,,,,,
1524344364.223,,0.000000e+000,3.499481e+001,3.499481e+001,1,0,1.677419e+000,0.000000e+000,-1.640497e+000,-1.640497e+000,-2.142331e+000,-2.176393e+000,-1.777646e+000,-2.279480e+000,-2.313541e+000,-2.050631e-004,-2.050631e-004,,,,,,,,,,,,,,,,,,,,
1524344364.223,,0.000000e+000,3.499481e+001,3.499481e+001,1,0,2.838710e+000,0.000000e+000,-9.994660e-002,-9.994660e-002,-5.781997e-001,-6.358417e-001,3.872163e-002,-4.395314e-001,-4.971735e-001,-3.422253e-005,-3.422253e-005,,,,,,,,,,,,,,,,,,,,
1524344364.223,,0.000000e+000,3.499481e+001,3.499481e+001,1,0,4.000000e+000,0.000000e+000,1.529717e+000,1.529717e+000,1.075045e+000,9.938219e-001,1.414332e+000,9.596593e-001,8.784364e-001,1.464501e-004,1.464501e-004,,,,,,,,,,,,,,,,,,,,
1524344376.888,,0.000000e+000,3.499794e+001,3.499872e+001,1,0,1.032258e+000,0.000000e+000,6.250095e-001,6.250095e-001,1.090118e-001,8.859026e-002,5.085592e-001,-7.438516e-003,-2.786005e-002,4.429563e-005,4.429563e-005,,,,,,,,,,,,,,,,,,,,
1524344376.888,,0.000000e+000,3.499794e+001,3.499872e+001,1,0,2.193548e+000,0.000000e+000,-2.226139e+000,-2.226139e+000,-2.719162e+000,-2.762558e+000,-2.129777e+000,-2.622801e+000,-2.666196e+000,-2.694346e-004,-2.694346e-004,,,,,,,,,,,,,,,,,,,,
1524344376.888,,0.000000e+000,3.499794e+001,3.499872e+001,1,0,3.354839e+000,0.000000e+000,1.453727e+000,1.453727e+000,9.836777e-001,9.173077e-001,1.472887e+000,1.002838e+000,9.364679e-001,1.374202e-004,1.374202e-004,,,,,,,,,,,,,,,,,,,,
1524344389.628,,0.000000e+000,3.499715e+001,3.500028e+001,1,0,3.870968e-001,0.000000e+000,1.706264e+000,1.706264e+000,1.177158e+000,1.169533e+000,1.770531e+000,1.241424e+000,1.233800e+000,1.630934e-004,1.630934e-004,,,,,,,,,,,,,,,,,,,,
1524344389.628,,0.000000e+000,3.499715e+001,3.500028e+001,1,0,1.548387e+000,0.000000e+000,-1.181048e+000,-1.181048e+000,-1.687281e+000,-1.717779e+000,-1.343224e+000,-1.849456e+000,-1.879954e+000,-1.546307e-004,-1.546307e-004,,,,,,,,,,,,,,,,,,,,
1524344389.628,,0.000000e+000,3.499715e+001,3.500028e+001,1,0,2.709677e+000,0.000000e+000,-5.676356e-001,-5.676356e-001,-1.050995e+000,-1.104366e+000,-4.165005e-001,-8.998596e-001,-9.532312e-001,-8.610987e-005,-8.610987e-005,,,,,,,,,,,,,,,,,,,,
1524344389.628,,0.000000e+000,3.499715e+001,3.500028e+001,1,0,3.870968e+000,0.000000e+000,1.678492e+000,1.678492e+000,1.218007e+000,1.141762e+000,1.564438e+000,1.103952e+000,1.027707e+000,1.625530e-004,1.625530e-004,,,,,,,,,,,,,,,,,,,,
1524344402.488,,0.000000e+000,3.499715e+001,3.499637e+001,1,0,9.032258e-001,0.000000e+000,9.977874e-001,9.977874e-001,4.765529e-001,4.586414e-001,9.107669e-001,3.895324e-001,3.716208e-001,8.509379e-005,8.509379e-005,,,,,,,,,,,,,,,,,,,,
1524344402.488,,0.000000e+000,3.499715e+001,3.499637e+001,1,0,2.064516e+000,0.000000e+000,-2.355993e+000,-2.355993e+000,-2.854198e+000,-2.895139e+000,-2.319371e+000,-2.817577e+000,-2.858518e+000,-2.840914e-004,-2.840914e-004,,,,,,,,,,,,,,,,,,,,
1524344402.488,,0.000000e+000,3.499715e+001,3.499637e+001,1,0,3.225806e+000,0.000000e+000,1.147784e+000,1.147784e+000,6.726072e-001,6.086376e-001,1.209591e+000,7.344149e-001,6.704452e-001,1.033372e-004,1.033372e-004,,,,,,,,,,,,,,,,,,,,
1524344415.233,,0.000000e+000,3.499637e+001,3.500028e+001,1,0,2.580645e-001,0.000000e+000,1.649653e+000,1.649653e+000,1.114051e+000,1.108829e+000,1.746060e+000,1.210458e+000,1.205237e+000,1.564396e-004,1.564396e-004,,,,,,,,,,,,,,,,,,,,
1524344415.233,,0.000000e+000,3.499637e+001,3.500028e+001,1,0,1.419355e+000,0.000000e+000,-7.025254e-001,-7.025254e-001,-1.214630e+000,-1.243349e+000,-8.663623e-001,-1.378466e+000,-1.407186e+000,-1.022187e-004,-1.022187e-004,,,,,,,,,,,,,,,,,,,,
1524344415.233,,0.000000e+000,3.499637e+001,3.500028e+001,1,0,2.580645e+000,0.000000e+000,-1.042954e+000,-1.042954e+000,-1.531561e+000,-1.583778e+000,-8.898605e-001,-1.378467e+000,-1.430684e+000,-1.389150e-004,-1.389150e-004,,,,,,,,,,,,,,,,,,,,
1524344415.233,,0.000000e+000,3.499637e+001,3.500028e+001,1,0,3.741935e+000,0.000000e+000,1.773556e+000,1.773556e+000,1.308447e+000,1.232732e+000,1.675567e+000,1.210458e+000,1.134743e+000,1.727028e-004,1.727028e-004,,,,,,,,,,,,,,,,,,,,
1524344427.931,,0.000000e+000,3.500028e+001,3.499794e+001,1,0,7.741935e-001,0.000000e+000,1.320363e+000,1.320363e+000,7.936321e-001,7.781132e-001,1.262458e+000,7.357265e-001,7.202077e-001,1.203408e-004,1.203408e-004,,,,,,,,,,,,,,,,,,,,
1524344427.931,,0.000000e+000,3.500028e+001,3.499794e+001,1,0,1.935484e+000,0.000000e+000,-2.292516e+000,-2.292516e+000,-2.795968e+000,-2.834765e+000,-2.319154e+000,-2.822607e+000,-2.861404e+000,-2.774222e-004,-2.774222e-004,,,,,,,,,,,,,,,,,,,,
1524344427.931,,0.000000e+000,3.500028e+001,3.499794e+001,1,0,3.096774e+000,0.000000e+000,7.721065e-001,7.721065e-001,2.919320e-001,2.298566e-001,8.704019e-001,3.902274e-001,3.281519e-001,6.156234e-005,6.156234e-005,,,,,,,,,,,,,,,,,,,,
1524344440.714,,0.000000e+000,3.499794e+001,3.499950e+001,1,0,1.290323e-001,0.000000e+000,1.525139e+000,1.525139e+000,9.843221e-001,9.817971e-001,1.648442e+000,1.107624e+000,1.105099e+000,1.422763e-004,1.422763e-004,,,,,,,,,,,,,,,,,,,,
1524344440.714,,0.000000e+000,3.499794e+001,3.499950e+001,1,0,1.290323e+000,0.000000e+000,-2.302586e-001,-2.302586e-001,-7.483510e-001,-7.736008e-001,-3.847596e-001,-9.028519e-001,-9.281017e-001,-5.056594e-005,-5.056594e-005,,,,,,,,,,,,,,,,,,,,
1524344440.714,,0.000000e+000,3.499794e+001,3.499950e+001,1,0,2.451613e+000,0.000000e+000,-1.507897e+000,-1.507897e+000,-2.003264e+000,-2.051239e+000,-1.360240e+000,-1.855608e+000,-1.903583e+000,-1.906956e-004,-1.906956e-004,,,,,,,,,,,,,,,,,,,,
1524344440.714,,0.000000e+000,3.499794e+001,3.499950e+001,1,0,3.612903e+000,0.000000e+000,1.785611e+000,1.785611e+000,1.312968e+000,1.242269e+000,1.718197e+000,1.245554e+000,1.174855e+000,1.735222e-004,1.735222e-004,,,,,,,,,,,,,,,,,,,,
1524344453.364,,0.000000e+000,3.500263e+001,3.499872e+001,1,0,6.451613e-001,0.000000e+000,1.561303e+000,1.561303e+000,1.028587e+000,1.015465e+000,1.540087e+000,1.007370e+000,9.942483e-001,1.465131e-004,1.465131e-004,,,,,,,,,,,,,,,,,,,,
1524344453.364,,0.000000e+000,3.500263e+001,3.499872e+001,1,0,1.806452e+000,0.000000e+000,-2.035401e+000,-2.035401e+000,-2.544497e+000,-2.581239e+000,-2.125558e+000,-2.634654e+000,-2.671396e+000,-2.494527e-004,-2.494527e-004,,,,,,,,,,,,,,,,,,,,
1524344453.364,,0.000000e+000,3.500263e+001,3.499872e+001,1,0,2.967742e+000,0.000000e+000,3.566034e-001,3.566034e-001,-1.288731e-001,-1.892349e-001,4.780043e-001,-7.472137e-003,-6.783399e-002,1.533256e-005,1.533256e-005,,,,,,,,,,,,,,,,,,,,
1524344466.107,,0.000000e+000,3.499715e+001,3.499950e+001,1,0,0.000000e+000,0.000000e+000,1.399100e+000,1.399100e+000,8.530280e-001,8.530280e-001,1.512217e+000,9.661453e-001,9.661453e-001,1.281112e-004,1.281112e-004,,,,,,,,,,,,,,,,,,,,
1524344466.107,,0.000000e+000,3.499715e+001,3.499950e+001,1,0,1.161290e+000,0.000000e+000,2.143893e-001,2.143893e-001,-3.083060e-001,-3.316824e-001,8.019363e-002,-4.425016e-001,-4.658781e-001,-1.741548e-006,-1.741548e-006,,,,,,,,,,,,,,,,,,,,
1524344466.107,,0.000000e+000,3.499715e+001,3.499950e+001,1,0,2.322581e+000,0.000000e+000,-1.925994e+000,-1.925994e+000,-2.425313e+000,-2.472065e+000,-1.795567e+000,-2.294886e+000,-2.341639e+000,-2.370363e-004,-2.370363e-004,,,,,,,,,,,,,,,,,,,,
1524344466.107,,0.000000e+000,3.499715e+001,3.499950e+001,1,0,3.483871e+000,0.000000e+000,1.684596e+000,1.684596e+000,1.208654e+000,1.138524e+000,1.658100e+000,1.182158e+000,1.112029e+000,1.621900e-004,1.621900e-004,,,,,,,,,,,,,,,,,,,,
1524344478.777,,0.000000e+000,3.499715e+001,3.499872e+001,1,0,5.161290e-001,0.000000e+000,1.700771e+000,1.700771e+000,1.164362e+000,1.154016e+000,1.719077e+000,1.182668e+000,1.172322e+000,1.617016e-004,1.617016e-004,,,,,,,,,,,,,,,,,,,,
1524344478.777,,0.000000e+000,3.499715e+001,3.499872e+001,1,0,1.677419e+000,0.000000e+000,-1.646601e+000,-1.646601e+000,-2.159731e+000,-2.193356e+000,-1.782746e+000,-2.295876e+000,-2.329501e+000,-2.067673e-004,-2.067673e-004,,,,,,,,,,,,,,,,,,,,
1524344478.777,,0.000000e+000,3.499715e+001,3.499872e+001,1,0,2.838710e+000,0.000000e+000,-9.018082e-002,-9.018082e-002,-5.800313e-001,-6.369357e-001,4.715763e-002,-4.426929e-001,-4.995972e-001,-3.418687e-005,-3.418687e-005,,,,,,,,,,,,,,,,,,,,
1524344478.777,,0.000000e+000,3.499715e+001,3.499872e+001,1,0,4.000000e+000,0.000000e+000,1.548028e+000,1.548028e+000,1.081456e+000,1.001273e+000,1.433133e+000,9.665620e-001,8.863786e-001,1.474175e-004,1.474175e-004,,,,,,,,,,,,,,,,,,,,
1524344491.412,,0.000000e+000,3.499872e+001,3.499872e+001,1,0,1.032258e+000,0.000000e+000,6.344701e-001,6.344701e-001,1.067412e-001,8.610290e-002,5.202395e-001,-7.489339e-003,-2.812767e-002,4.427081e-005,4.427081e-005,,,,,,,,,,,,,,,,,,,,
1524344491.412,,0.000000e+000,3.499872e+001,3.499872e+001,1,0,2.193548e+000,0.000000e+000,-2.229954e+000,-2.229954e+000,-2.734464e+000,-2.778321e+000,-2.136200e+000,-2.640710e+000,-2.684567e+000,-2.709153e-004,-2.709153e-004,,,,,,,,,,,,,,,,,,,,
1524344491.412,,0.000000e+000,3.499872e+001,3.499872e+001,1,0,3.354839e+000,0.000000e+000,1.472038e+000,1.472038e+000,9.907452e-001,9.236706e-001,1.490978e+000,1.009686e+000,9.426112e-001,1.383898e-004,1.383898e-004,,,,,,,,,,,,,,,,,,,,
1524344504.137,,0.000000e+000,3.499872e+001,3.499794e+001,1,0,3.870968e-001,0.000000e+000,1.731136e+000,1.731136e+000,1.189555e+000,1.181754e+000,1.791588e+000,1.250008e+000,1.242207e+000,1.647289e-004,1.647289e-004,,,,,,,,,,,,,,,,,,,,
1524344504.137,,0.000000e+000,3.499872e+001,3.499794e+001,1,0,1.548387e+000,0.000000e+000,-1.182879e+000,-1.182879e+000,-1.701057e+000,-1.732261e+000,-1.344066e+000,-1.862243e+000,-1.893447e+000,-1.559219e-004,-1.559219e-004,,,,,,,,,,,,,,,,,,,,
1524344504.137,,0.000000e+000,3.499872e+001,3.499794e+001,1,0,2.709677e+000,0.000000e+000,-5.629053e-001,-5.629053e-001,-1.057680e+000,-1.112287e+000,-4.113069e-001,-9.060812e-001,-9.606885e-001,-8.665773e-005,-8.665773e-005,,,,,,,,,,,,,,,,,,,,
1524344504.137,,0.000000e+000,3.499872e+001,3.499794e+001,1,0,3.870968e+000,0.000000e+000,1.696345e+000,1.696345e+000,1.224974e+000,1.146964e+000,1.582956e+000,1.111585e+000,1.033575e+000,1.634725e-004,1.634725e-004,,,,,,,,,,,,,,,,,,,,
1524344516.817,,0.000000e+000,3.499794e+001,3.499794e+001,1,0,9.032258e-001,0.000000e+000,1.010910e+000,1.010910e+000,4.797289e-001,4.624568e-001,9.231713e-001,3.919901e-001,3.747180e-001,8.558216e-005,8.558216e-005,,,,,,,,,,,,,,,,,,,,
1524344516.817,,0.000000e+000,3.499794e+001,3.499794e+001,1,0,2.064516e+000,0.000000e+000,-2.366216e+000,-2.366216e+000,-2.875190e+000,-2.914670e+000,-2.326380e+000,-2.835354e+000,-2.874834e+000,-2.862090e-004,-2.862090e-004,,,,,,,,,,,,,,,,,,,,
1524344516.817,,0.000000e+000,3.499794e+001,3.499794e+001,1,0,3.225806e+000,0.000000e+000,1.165026e+000,1.165026e+000,6.782591e-001,6.165730e-001,1.225816e+000,7.390487e-001,6.773626e-001,1.042197e-004,1.042197e-004,,,,,,,,,,,,,,,,,,,,
1524344529.497,,0.000000e+000,3.499794e+001,3.499950e+001,1,0,2.580645e-001,0.000000e+000,1.664912e+000,1.664912e+000,1.118782e+000,1.113694e+000,1.764750e+000,1.218620e+000,1.213532e+000,1.571037e-004,1.571037e-004,,,,,,,,,,,,,,,,,,,,
1524344529.497,,0.000000e+000,3.499794e+001,3.499950e+001,1,0,1.419355e+000,0.000000e+000,-7.023728e-001,-7.023728e-001,-1.225608e+000,-1.253590e+000,-8.645264e-001,-1.387761e+000,-1.415744e+000,-1.032435e-004,-1.032435e-004,,,,,,,,,,,,,,,,,,,,
1524344529.497,,0.000000e+000,3.499794e+001,3.499950e+001,1,0,2.580645e+000,0.000000e+000,-1.041581e+000,-1.041581e+000,-1.541921e+000,-1.592798e+000,-8.874218e-001,-1.387762e+000,-1.438639e+000,-1.398273e-004,-1.398273e-004,,,,,,,,,,,,,,,,,,,,
1524344529.497,,0.000000e+000,3.499794e+001,3.499950e+001,1,0,3.741935e+000,0.000000e+000,1.797360e+000,1.797360e+000,1.319915e+000,1.246143e+000,1.696065e+000,1.218620e+000,1.144848e+000,1.742431e-004,1.742431e-004,,,,,,,,,,,,,,,,,,,,
1524344542.185,,0.000000e+000,3.499715e+001,3.499950e+001,1,0,7.741935e-001,0.000000e+000,1.331960e+000,1.331960e+000,7.936867e-001,7.780703e-001,1.278364e+000,7.400908e-001,7.244744e-001,1.205419e-004,1.205419e-004,,,,,,,,,,,,,,,,,,,,
1524344542.185,,0.000000e+000,3.499715e+001,3.499950e+001,1,0,1.935484e+000,0.000000e+000,-2.294499e+000,-2.294499e+000,-2.809348e+000,-2.848389e+000,-2.324502e+000,-2.839350e+000,-2.878391e+000,-2.787141e-004,-2.787141e-004,,,,,,,,,,,,,,,,,,,,
1524344542.185,,0.000000e+000,3.499715e+001,3.499950e+001,1,0,3.096774e+000,0.000000e+000,7.849241e-001,7.849241e-001,2.934998e-001,2.310345e-001,8.839664e-001,3.925422e-001,3.300768e-001,6.190884e-005,6.190884e-005,,,,,,,,,,,,,,,,,,,,
1524344554.848,,0.000000e+000,3.499715e+001,3.499872e+001,1,0,1.290323e-001,0.000000e+000,1.542229e+000,1.542229e+000,9.905590e-001,9.880032e-001,1.666219e+000,1.114549e+000,1.111993e+000,1.431910e-004,1.431910e-004,,,,,,,,,,,,,,,,,,,,
1524344554.848,,0.000000e+000,3.499715e+001,3.499872e+001,1,0,1.290323e+000,0.000000e+000,-2.256809e-001,-2.256809e-001,-7.543485e-001,-7.799070e-001,-3.798288e-001,-9.084963e-001,-9.340549e-001,-5.102150e-005,-5.102150e-005,,,,,,,,,,,,,,,,,,,,
1524344554.848,,0.000000e+000,3.499715e+001,3.499872e+001,1,0,2.451613e+000,0.000000e+000,-1.511864e+000,-1.511864e+000,-2.017529e+000,-2.066090e+000,-1.361544e+000,-1.867209e+000,-1.915770e+000,-1.920837e-004,-1.920837e-004,,,,,,,,,,,,,,,,,,,,
1524344554.848,,0.000000e+000,3.499715e+001,3.499872e+001,1,0,3.612903e+000,0.000000e+000,1.806973e+000,1.806973e+000,1.324311e+000,1.252747e+000,1.736003e+000,1.253341e+000,1.181777e+000,1.749390e-004,1.749390e-004,,,,,,,,,,,,,,,,,,,,
1524344567.560,,0.000000e+000,3.499715e+001,3.499872e+001,1,0,6.451613e-001,0.000000e+000,1.575647e+000,1.575647e+000,1.034496e+000,1.021518e+000,1.555458e+000,1.014308e+000,1.001329e+000,1.473565e-004,1.473565e-004,,,,,,,,,,,,,,,,,,,,
1524344567.560,,0.000000e+000,3.499715e+001,3.499872e+001,1,0,1.806452e+000,0.000000e+000,-2.042878e+000,-2.042878e+000,-2.560666e+000,-2.597007e+000,-2.135011e+000,-2.652799e+000,-2.689140e+000,-2.510264e-004,-2.510264e-004,,,,,,,,,,,,,,,,,,,,
1524344567.560,,0.000000e+000,3.499715e+001,3.499872e+001,1,0,2.967742e+000,0.000000e+000,3.656062e-001,3.656062e-001,-1.288199e-001,-1.885230e-001,4.869024e-001,-7.523595e-003,-6.722674e-002,1.556773e-005,1.556773e-005,,,,,,,,,,,,,,,,,,,,
1524344580.256,,0.000000e+000,3.499872e+001,3.499872e+001,1,0,0.000000e+000,0.000000e+000,1.418021e+000,1.418021e+000,8.593702e-001,8.593702e-001,1.530972e+000,9.723217e-001,9.723217e-001,1.290700e-004,1.290700e-004,,,,,,,,,,,,,,,,,,,,
1524344580.256,,0.000000e+000,3.499872e+001,3.499872e+001,1,0,1.161290e+000,0.000000e+000,2.243076e-001,2.243076e-001,-3.104880e-001,-3.343432e-001,8.946517e-002,-4.453304e-001,-4.691856e-001,-1.758472e-006,-1.758472e-006,,,,,,,,,,,,,,,,,,,,
1524344580.256,,0.000000e+000,3.499872e+001,3.499872e+001,1,0,2.322581e+000,0.000000e+000,-1.930571e+000,-1.930571e+000,-2.441512e+000,-2.489222e+000,-1.798616e+000,-2.309557e+000,-2.357267e+000,-2.386350e-004,-2.386350e-004,,,,,,,,,,,,,,,,,,,,
1524344580.256,,0.000000e+000,3.499872e+001,3.499872e+001,1,0,3.483871e+000,0.000000e+000,1.703517e+000,1.703517e+000,1.216432e+000,1.144866e+000,1.676800e+000,1.189715e+000,1.118150e+000,1.632016e-004,1.632016e-004,,,,,,,,,,,,,,,,,,,,
1524344592.776,,0.000000e+000,3.499872e+001,3.499715e+001,1,0,5.161290e-001,0.000000e+000,1.716487e+000,1.716487e+000,1.168359e+000,1.158336e+000,1.737957e+000,1.189829e+000,1.179806e+000,1.622623e-004,1.622623e-004,,,,,,,,,,,,,,,,,,,,
1524344592.776,,0.000000e+000,3.499872e+001,3.499715e+001,1,0,1.677419e+000,0.000000e+000,-1.645380e+000,-1.645380e+000,-2.170956e+000,-2.203532e+000,-1.784202e+000,-2.309777e+000,-2.342354e+000,-2.078326e-004,-2.078326e-004,,,,,,,,,,,,,,,,,,,,
1524344592.776,,0.000000e+000,3.499872e+001,3.499715e+001,1,0,2.838710e+000,0.000000e+000,-8.300908e-002,-8.300908e-002,-5.860315e-001,-6.411607e-001,5.764892e-002,-4.453735e-001,-5.005028e-001,-3.462231e-005,-3.462231e-005,,,,,,,,,,,,,,,,,,,,
1524344592.776,,0.000000e+000,3.499872e+001,3.499715e+001,1,0,4.000000e+000,0.000000e+000,1.570611e+000,1.570611e+000,1.090142e+000,1.012460e+000,1.452884e+000,9.724147e-001,8.947327e-001,1.486557e-004,1.486557e-004,,,,,,,,,,,,,,,,,,,,
1524344605.471,,0.000000e+000,3.499715e+001,3.499950e+001,1,0,1.032258e+000,0.000000e+000,5.908293e-001,5.908293e-001,1.024492e-001,8.036929e-002,4.808495e-001,-7.530609e-003,-2.961048e-002,4.406799e-005,4.406799e-005,,,,,,,,,,,,,,,,,,,,
1524344605.471,,0.000000e+000,3.499715e+001,3.499950e+001,1,0,2.193548e+000,0.000000e+000,-2.284123e+000,-2.284123e+000,-2.747663e+000,-2.794583e+000,-2.191733e+000,-2.655273e+000,-2.702193e+000,-2.722201e-004,-2.722201e-004,,,,,,,,,,,,,,,,,,,,
1524344605.471,,0.000000e+000,3.499715e+001,3.499950e+001,1,0,3.354839e+000,0.000000e+000,1.435721e+000,1.435721e+000,9.970210e-001,9.252614e-001,1.453954e+000,1.015254e+000,9.434943e-001,1.391144e-004,1.391144e-004,,,,,,,,,,,,,,,,,,,,
1524344618.291,,0.000000e+000,3.499794e+001,3.499950e+001,1,0,3.870968e-001,0.000000e+000,1.741054e+000,1.741054e+000,1.197186e+000,1.189620e+000,1.801522e+000,1.257654e+000,1.250087e+000,1.656892e-004,1.656892e-004,,,,,,,,,,,,,,,,,,,,
1524344618.291,,0.000000e+000,3.499794e+001,3.499950e+001,1,0,1.548387e+000,0.000000e+000,-1.190967e+000,-1.190967e+000,-1.712135e+000,-1.742401e+000,-1.352466e+000,-1.873634e+000,-1.903901e+000,-1.569741e-004,-1.569741e-004,,,,,,,,,,,,,,,,,,,,
1524344618.291,,0.000000e+000,3.499794e+001,3.499950e+001,1,0,2.709677e+000,0.000000e+000,-5.624475e-001,-5.624475e-001,-1.060915e+000,-1.113882e+000,-4.131558e-001,-9.116237e-001,-9.645905e-001,-8.679297e-005,-8.679297e-005,,,,,,,,,,,,,,,,,,,,
1524344618.291,,0.000000e+000,3.499794e+001,3.499950e+001,1,0,3.870968e+000,0.000000e+000,1.703975e+000,1.703975e+000,1.228207e+000,1.152540e+000,1.594152e+000,1.118385e+000,1.042717e+000,1.641027e-004,1.641027e-004,,,,,,,,,,,,,,,,,,,,
1524344630.839,,0.000000e+000,3.499794e+001,3.499872e+001,1,0,9.032258e-001,0.000000e+000,1.021286e+000,1.021286e+000,4.828267e-001,4.652341e-001,9.326890e-001,3.942293e-001,3.766367e-001,8.613028e-005,8.613028e-005,,,,,,,,,,,,,,,,,,,,
1524344630.839,,0.000000e+000,3.499794e+001,3.499872e+001,1,0,2.064516e+000,0.000000e+000,-2.376440e+000,-2.376440e+000,-2.892281e+000,-2.932492e+000,-2.335710e+000,-2.851551e+000,-2.891762e+000,-2.879186e-004,-2.879186e-004,,,,,,,,,,,,,,,,,,,,
1524344630.839,,0.000000e+000,3.499794e+001,3.499872e+001,1,0,3.225806e+000,0.000000e+000,1.174792e+000,1.174792e+000,6.815705e-001,6.187398e-001,1.236492e+000,7.432704e-001,6.804397e-001,1.047308e-004,1.047308e-004,,,,,,,,,,,,,,,,,,,,
1524344643.682,,0.000000e+000,3.499715e+001,3.499950e+001,1,0,2.580645e-001,0.000000e+000,1.682765e+000,1.682765e+000,1.128137e+000,1.122859e+000,1.779485e+000,1.224857e+000,1.219579e+000,1.583892e-004,1.583892e-004,,,,,,,,,,,,,,,,,,,,
1524344643.682,,0.000000e+000,3.499715e+001,3.499950e+001,1,0,1.419355e+000,0.000000e+000,-7.042038e-001,-7.042038e-001,-1.235084e+000,-1.264109e+000,-8.639832e-001,-1.394863e+000,-1.423889e+000,-1.040984e-004,-1.040984e-004,,,,,,,,,,,,,,,,,,,,
1524344643.682,,0.000000e+000,3.499715e+001,3.499950e+001,1,0,2.580645e+000,0.000000e+000,-1.038682e+000,-1.038682e+000,-1.545814e+000,-1.598587e+000,-8.877316e-001,-1.394864e+000,-1.447637e+000,-1.401289e-004,-1.401289e-004,,,,,,,,,,,,,,,,,,,,
1524344643.682,,0.000000e+000,3.499715e+001,3.499950e+001,1,0,3.741935e+000,0.000000e+000,1.806516e+000,1.806516e+000,1.323131e+000,1.246610e+000,1.708241e+000,1.224857e+000,1.148336e+000,1.746632e-004,1.746632e-004,,,,,,,,,,,,,,,,,,,,
1524344656.339,,0.000000e+000,3.499872e+001,3.499715e+001,1,0,7.741935e-001,0.000000e+000,1.344015e+000,1.344015e+000,7.976955e-001,7.825297e-001,1.290233e+000,7.439142e-001,7.287484e-001,1.210927e-004,1.210927e-004,,,,,,,,,,,,,,,,,,,,
1524344656.339,,0.000000e+000,3.499872e+001,3.499715e+001,1,0,1.935484e+000,0.000000e+000,-2.301213e+000,-2.301213e+000,-2.824784e+000,-2.862698e+000,-2.330448e+000,-2.854019e+000,-2.891933e+000,-2.802590e-004,-2.802590e-004,,,,,,,,,,,,,,,,,,,,
1524344656.339,,0.000000e+000,3.499872e+001,3.499715e+001,1,0,3.096774e+000,0.000000e+000,7.974365e-001,7.974365e-001,2.966147e-001,2.359515e-001,8.953919e-001,3.945701e-001,3.339069e-001,6.246043e-005,6.246043e-005,,,,,,,,,,,,,,,,,,,,
1524344668.919,,0.000000e+000,3.499715e+001,3.499872e+001,1,0,1.290323e-001,0.000000e+000,1.558404e+000,1.558404e+000,9.966702e-001,9.941242e-001,1.681593e+000,1.119860e+000,1.117314e+000,1.440034e-004,1.440034e-004,,,,,,,,,,,,,,,,,,,,
1524344668.919,,0.000000e+000,3.499715e+001,3.499872e+001,1,0,1.290323e+000,0.000000e+000,-2.201877e-001,-2.201877e-001,-7.590072e-001,-7.844673e-001,-3.740058e-001,-9.128253e-001,-9.382854e-001,-5.139094e-005,-5.139094e-005,,,,,,,,,,,,,,,,,,,,
1524344668.919,,0.000000e+000,3.499715e+001,3.499872e+001,1,0,2.451613e+000,0.000000e+000,-1.508354e+000,-1.508354e+000,-2.024260e+000,-2.072634e+000,-1.360201e+000,-1.876106e+000,-1.924480e+000,-1.926753e-004,-1.926753e-004,,,,,,,,,,,,,,,,,,,,
1524344668.919,,0.000000e+000,3.499715e+001,3.499872e+001,1,0,3.612903e+000,0.000000e+000,1.823148e+000,1.823148e+000,1.330156e+000,1.258868e+000,1.752304e+000,1.259313e+000,1.188025e+000,1.757415e-004,1.757415e-004,,,,,,,,,,,,,,,,,,,,
1524344681.615,,0.000000e+000,3.499872e+001,3.499794e+001,1,0,6.451613e-001,0.000000e+000,1.595331e+000,1.595331e+000,1.040743e+000,1.027820e+000,1.573485e+000,1.018898e+000,1.005975e+000,1.481784e-004,1.481784e-004,,,,,,,,,,,,,,,,,,,,
1524344681.615,,0.000000e+000,3.499872e+001,3.499794e+001,1,0,1.806452e+000,0.000000e+000,-2.040894e+000,-2.040894e+000,-2.572220e+000,-2.608405e+000,-2.133477e+000,-2.664803e+000,-2.700988e+000,-2.521611e-004,-2.521611e-004,,,,,,,,,,,,,,,,,,,,
1524344681.615,,0.000000e+000,3.499872e+001,3.499794e+001,1,0,2.967742e+000,0.000000e+000,3.788815e-001,3.788815e-001,-1.291821e-001,-1.886292e-001,5.005060e-001,-7.557609e-003,-6.700474e-002,1.567516e-005,1.567516e-005,,,,,,,,,,,,,,,,,,,,
1524344681.615,,0.000000e+000,3.499872e+001,3.499794e+001,1,0,4.000000e+000,0.000000e+000,1.580377e+000,1.580377e+000,1.092991e+000,1.012866e+000,1.463529e+000,9.761431e-001,8.960187e-001,1.490000e-004,1.490000e-004,,,,,,,,,,,,,,,,,,,,