File: Experimental Raw Data/MFn1 VRM/raw/MFn1_VRMac_35K_750s_VRMde_35K.dc.raw
[Header]
TITLE,MPMS DC Measurement
BYAPP,MPMS Measurement,2.1,Raw with ABS
FILEOPENTIME, 1524344734.493000 4/21/2018, 3:05:34 PM

INFO, APPNAME, MPMS MultiVu Application, Revision 1.61,  Build 082

INFO, NAME, MFn1
INFO, WEIGHT, 1.000
INFO, AREA, 1.000
INFO, LENGTH, 1.000
INFO, SHAPE, 0
INFO, COMMENT,
INFO, SEQUENCE FILE: VRMac_35K_750s_VRMde_35Klinear.seq


INFO, BACKGROUND DATA FILE:, None


STARTUPAXIS,X,8,LINEAR,AUTO,0.000000,0.000000
STARTUPAXIS,Y1,10,LINEAR,AUTO,0.000000,0.000000


STARTUPGROUP,Longitudinal
FIELDGROUP,Longitudinal,1,3,4,5,6,8,9,10,11,12,13,14,15,16,17,18,19,20,21,22,23
FIELDGROUP,Transverse,1,3,4,5,6,8,9,24,25,26,27,28,29,30,31,32,33,34,35,36,37

PLOT_APPEARANCE,ALL,HORZ_GRID_ON,VERT_GRID_ON,MARKERS_ONLY

[Data]
Time,Comment,Field (Oe),Start Temperature (K),End Temperature (K),Scan,Rejected,Position (cm),Rot Position (deg),Long Voltage,Long Average Voltage,Long Detrended Voltage,Long Demeaned Voltage,Long Regression Fit,Long Detrended Fit,Long Demeaned Fit,Long Scaled Response,Long Avg. Scaled Response,Long Background Response,Long Response [w/ABS],Long Detrended Resp. [w/ABS],Long Fit [w/ABS],Long Detrended Fit [w/ABS],Trans Voltage,Trans Average Voltage,Trans Detrended Voltage,Trans Demeaned Voltage,Trans Regression Fit,Trans Detrended Fit,Trans Demeaned Fit,Trans Scaled Response,Trans Avg Scaled Response,Trans Background Response,Trans Response [w/ABS],Trans Detrended Resp. [w/ABS],Trans Fit [w/ABS],Trans Detrended Fit [w/ABS],
1524344734.478,,0.000000e+000,3.499715e+001,3.499637e+001,1,0,0.000000e+000,0.000000e+000,3.464714e+000,3.464714e+000,2.015846e-001,2.015846e-001,3.458889e+000,1.957600e-001,1.957600e-001,3.196445e-006,3.196445e-006,,,,,,,,,,,,,,,,,,,,
1524344760.023,,0.000000e+000,3.499715e+001,3.499794e+001,1,0,2.580645e-001,0.000000e+000,3.414206e+000,3.414206e+000,1.130174e-001,1.346796e-001,3.467425e+000,1.662360e-001,1.878982e-001,1.192442e-006,1.192442e-006,,,,,,,,,,,,,,,,,,,,
1524344785.399,,0.000000e+000,3.500184e+001,3.499950e+001,1,0,5.161290e-001,0.000000e+000,3.401999e+000,3.401999e+000,8.072506e-002,1.265740e-001,3.437304e+000,1.160298e-001,1.618788e-001,4.513568e-007,4.513568e-007,,,,,,,,,,,,,,,,,,,,
1524344810.824,,0.000000e+000,3.499872e+001,3.499872e+001,1,0,7.741935e-001,0.000000e+000,3.392691e+000,3.392691e+000,3.481887e-002,1.035862e-001,3.408689e+000,5.081676e-002,1.195841e-001,-4.056055e-007,-4.056055e-007,,,,,,,,,,,,,,,,,,,,
1524344836.149,,0.000000e+000,3.499872e+001,3.499637e+001,1,0,1.032258e+000,0.000000e+000,3.435874e+000,3.435874e+000,4.479922e-002,1.348720e-001,3.390727e+000,-3.479570e-004,8.972478e-002,3.491004e-008,3.491004e-008,,,,,,,,,,,,,,,,,,,,
1524344861.787,,0.000000e+000,3.499715e+001,3.500028e+001,1,0,1.290323e+000,0.000000e+000,3.466239e+000,3.466239e+000,4.667961e-002,1.622701e-001,3.393140e+000,-2.642000e-002,8.917046e-002,2.761080e-007,2.761080e-007,,,,,,,,,,,,,,,,,,,,
1524344887.165,,0.000000e+000,3.499794e+001,3.499950e+001,1,0,1.548387e+000,0.000000e+000,3.469749e+000,3.469749e+000,1.166334e-002,1.581590e-001,3.422804e+000,-3.528127e-002,1.112144e-001,-2.533779e-007,-2.533779e-007,,,,,,,,,,,,,,,,,,,,
1524344912.266,,0.000000e+000,3.499715e+001,3.499872e+001,1,0,1.806452e+000,0.000000e+000,3.487602e+000,3.487602e+000,2.287569e-003,1.588354e-001,3.483893e+000,-1.421748e-003,1.551261e-001,-1.929147e-007,-1.929147e-007,,,,,,,,,,,,,,,,,,,,
1524344937.556,,0.000000e+000,3.499794e+001,3.499872e+001,1,0,2.064516e+000,0.000000e+000,3.510491e+000,3.510491e+000,-4.215837e-003,1.823997e-001,3.538435e+000,2.372849e-002,2.103441e-001,-5.929905e-008,-5.929905e-008,,,,,,,,,,,,,,,,,,,,
1524344962.879,,0.000000e+000,3.499637e+001,3.499872e+001,1,0,2.322581e+000,0.000000e+000,3.562066e+000,3.562066e+000,1.153699e-002,2.193642e-001,3.592109e+000,4.158011e-002,2.494073e-001,5.667534e-007,5.667534e-007,,,,,,,,,,,,,,,,,,,,
1524344988.252,,0.000000e+000,3.499559e+001,3.499872e+001,1,0,2.580645e+000,0.000000e+000,3.569391e+000,3.569391e+000,-8.477949e-003,2.252083e-001,3.613639e+000,3.577016e-002,2.694564e-001,4.259055e-007,4.259055e-007,,,,,,,,,,,,,,,,,,,,
1524345013.625,,0.000000e+000,3.500263e+001,3.499872e+001,1,0,2.838710e+000,0.000000e+000,3.601892e+000,3.601892e+000,-5.022729e-003,2.616274e-001,3.622642e+000,1.572708e-002,2.823772e-001,8.275674e-007,8.275674e-007,,,,,,,,,,,,,,,,,,,,
1524345039.002,,0.000000e+000,3.499559e+001,3.499872e+001,1,0,3.096774e+000,0.000000e+000,3.625086e+000,3.625086e+000,-9.627879e-003,2.703996e-001,3.618311e+000,-1.640302e-002,2.636244e-001,9.861687e-007,9.861687e-007,,,,,,,,,,,,,,,,,,,,
1524345064.403,,0.000000e+000,3.500028e+001,3.499794e+001,1,0,3.354839e+000,0.000000e+000,3.669642e+000,3.669642e+000,3.647093e-003,3.142853e-001,3.616291e+000,-4.970431e-002,2.609339e-001,1.620065e-006,1.620065e-006,,,,,,,,,,,,,,,,,,,,
1524345090.568,,0.000000e+000,3.499715e+001,3.499950e+001,1,0,3.612903e+000,0.000000e+000,3.657740e+000,3.657740e+000,-4.510143e-002,2.858291e-001,3.636489e+000,-6.635264e-002,2.645779e-001,8.480274e-007,8.480274e-007,,,,,,,,,,,,,,,,,,,,
1524345115.346,,0.000000e+000,3.499715e+001,3.499950e+001,1,0,3.870968e+000,0.000000e+000,3.624475e+000,3.624475e+000,-8.819767e-002,2.528238e-001,3.651520e+000,-6.115361e-002,2.798679e-001,1.364388e-007,1.364388e-007,,,,,,,,,,,,,,,,,,,,
1524345153.502,,0.000000e+000,3.499872e+001,3.499950e+001,1,0,0.000000e+000,0.000000e+000,3.339132e+000,3.339132e+000,-5.153871e-002,-5.153871e-002,3.326706e+000,-6.396437e-002,-6.396437e-002,-4.192567e-006,-4.192567e-006,,,,,,,,,,,,,,,,,,,,
1524345178.889,,0.000000e+000,3.500028e+001,3.500106e+001,1,0,2.580645e-001,0.000000e+000,3.305867e+000,3.305867e+000,-1.123471e-001,-8.869553e-002,3.334966e+000,-8.324860e-002,-5.959702e-002,-5.253183e-006,-5.253183e-006,,,,,,,,,,,,,,,,,,,,
1524345203.690,,0.000000e+000,3.499794e+001,3.499950e+001,1,0,5.161290e-001,0.000000e+000,3.331502e+000,3.331502e+000,-1.212156e-001,-7.549524e-002,3.366042e+000,-8.667588e-002,-4.095554e-002,-5.063601e-006,-5.063601e-006,,,,,,,,,,,,,,,,,,,,
1524345229.068,,0.000000e+000,3.499794e+001,3.499872e+001,1,0,7.741935e-001,0.000000e+000,3.401541e+000,3.401541e+000,-7.265788e-002,-3.568411e-003,3.417731e+000,-5.646854e-002,1.262093e-002,-3.687994e-006,-3.687994e-006,,,,,,,,,,,,,,,,,,,,
1524345254.211,,0.000000e+000,3.499794e+001,3.499872e+001,1,0,1.032258e+000,0.000000e+000,3.539483e+000,3.539483e+000,3.943256e-002,1.310480e-001,3.500653e+000,6.025210e-004,9.221792e-002,-8.933275e-007,-8.933275e-007,,,,,,,,,,,,,,,,,,,,
1524345280.568,,0.000000e+000,3.499872e+001,3.500028e+001,1,0,1.290323e+000,0.000000e+000,3.662623e+000,3.662623e+000,1.366394e-001,2.535930e-001,3.602881e+000,7.689793e-002,1.938515e-001,1.541179e-006,1.541179e-006,,,,,,,,,,,,,,,,,,,,
1524345305.934,,0.000000e+000,3.499872e+001,3.499872e+001,1,0,1.548387e+000,0.000000e+000,3.757381e+000,3.757381e+000,1.979943e-001,3.376133e-001,3.721074e+000,1.616872e-001,3.013062e-001,3.230103e-006,3.230103e-006,,,,,,,,,,,,,,,,,,,,
1524345331.319,,0.000000e+000,3.499794e+001,3.499794e+001,1,0,1.806452e+000,0.000000e+000,3.834287e+000,3.834287e+000,2.446350e-001,4.085493e-001,3.827174e+000,2.375225e-001,4.014368e-001,4.580987e-006,4.580987e-006,,,,,,,,,,,,,,,,,,,,
1524345356.632,,0.000000e+000,3.499950e+001,3.499794e+001,1,0,2.064516e+000,0.000000e+000,3.861448e+000,3.861448e+000,2.445302e-001,4.318922e-001,3.878670e+000,2.617526e-001,4.491146e-001,4.907706e-006,4.907706e-006,,,,,,,,,,,,,,,,,,,,
1524345382.092,,0.000000e+000,3.499794e+001,3.499794e+001,1,0,2.322581e+000,0.000000e+000,3.834592e+000,3.834592e+000,1.847658e-001,3.977988e-001,3.866751e+000,2.169244e-001,4.299574e-001,3.925757e-006,3.925757e-006,,,,,,,,,,,,,,,,,,,,
1524345407.463,,0.000000e+000,3.499872e+001,3.499794e+001,1,0,2.580645e+000,0.000000e+000,3.752193e+000,3.752193e+000,7.809108e-002,3.093178e-001,3.808574e+000,1.344718e-001,3.656986e-001,1.885113e-006,1.885113e-006,,,,,,,,,,,,,,,,,,,,
1524345432.781,,0.000000e+000,3.499872e+001,3.499872e+001,1,0,2.838710e+000,0.000000e+000,3.725338e+000,3.725338e+000,2.483794e-002,2.811501e-001,3.744806e+000,4.430648e-002,3.006186e-001,1.040680e-006,1.040680e-006,,,,,,,,,,,,,,,,,,,,
1524345458.146,,0.000000e+000,3.499715e+001,3.500106e+001,1,0,3.096774e+000,0.000000e+000,3.693141e+000,3.693141e+000,-3.242798e-002,2.450898e-001,3.685412e+000,-4.015656e-002,2.373612e-001,9.294308e-008,9.294308e-008,,,,,,,,,,,,,,,,,,,,
1524345483.604,,0.000000e+000,3.499872e+001,3.499794e+001,1,0,3.354839e+000,0.000000e+000,3.703975e+000,3.703975e+000,-5.552218e-002,2.495372e-001,3.654347e+000,-1.051500e-001,1.999094e-001,-5.999755e-008,-5.999755e-008,,,,,,,,,,,,,,,,,,,,
1524345508.992,,0.000000e+000,3.499872e+001,3.499794e+001,1,0,3.612903e+000,0.000000e+000,3.685817e+000,3.685817e+000,-9.815450e-002,2.312701e-001,3.651282e+000,-1.326897e-001,1.967349e-001,-6.625487e-007,-6.625487e-007,,,,,,,,,,,,,,,,,,,,
1524345534.370,,0.000000e+000,3.499872e+001,3.499950e+001,1,0,3.870968e+000,0.000000e+000,3.671168e+000,3.671168e+000,-1.377577e-001,2.113729e-001,3.690109e+000,-1.188171e-001,2.303135e-001,-1.222055e-006,-1.222055e-006,,,,,,,,,,,,,,,,,,,,
1524345572.843,,0.000000e+000,3.499794e+001,3.499872e+001,1,0,0.000000e+000,0.000000e+000,3.367056e+000,3.367056e+000,-9.983516e-002,-9.983516e-002,3.360353e+000,-1.065376e-001,-1.065376e-001,-5.557507e-006,-5.557507e-006,,,,,,,,,,,,,,,,,,,,
1524345597.296,,0.000000e+000,3.500106e+001,3.499950e+001,1,0,2.580645e-001,0.000000e+000,3.324789e+000,3.324789e+000,-1.701703e-001,-1.466377e-001,3.359554e+000,-1.354048e-001,-1.118722e-001,-6.783826e-006,-6.783826e-006,,,,,,,,,,,,,,,,,,,,
1524345622.579,,0.000000e+000,3.499715e+001,3.499872e+001,1,0,5.161290e-001,0.000000e+000,3.339590e+000,3.339590e+000,-1.840189e-001,-1.373949e-001,3.391346e+000,-1.322625e-001,-8.563852e-002,-6.727001e-006,-6.727001e-006,,,,,,,,,,,,,,,,,,,,
1524345648.456,,0.000000e+000,3.499715e+001,3.499950e+001,1,0,7.741935e-001,0.000000e+000,3.456779e+000,3.456779e+000,-9.640000e-002,-2.615118e-002,3.467925e+000,-8.525345e-002,-1.500463e-002,-4.481204e-006,-4.481204e-006,,,,,,,,,,,,,,,,,,,,
1524345673.364,,0.000000e+000,3.499950e+001,3.499794e+001,1,0,1.032258e+000,0.000000e+000,3.641413e+000,3.641413e+000,5.483170e-002,1.469586e-001,3.587455e+000,8.732826e-004,9.300017e-002,-7.852068e-007,-7.852068e-007,,,,,,,,,,,,,,,,,,,,
1524345698.300,,0.000000e+000,3.499872e+001,3.499950e+001,1,0,1.290323e+000,0.000000e+000,3.782559e+000,3.782559e+000,1.747481e-001,2.916479e-001,3.714700e+000,1.068887e-001,2.237885e-001,2.176690e-006,2.176690e-006,,,,,,,,,,,,,,,,,,,,
1524345723.685,,0.000000e+000,3.499794e+001,3.499872e+001,1,0,1.548387e+000,0.000000e+000,3.903105e+000,3.903105e+000,2.677613e-001,4.059751e-001,3.856712e+000,2.213679e-001,3.595817e-001,4.576388e-006,4.576388e-006,,,,,,,,,,,,,,,,,,,,
1524345749.070,,0.000000e+000,3.499872e+001,3.499794e+001,1,0,1.806452e+000,0.000000e+000,3.984131e+000,3.984131e+000,3.251623e-001,4.862888e-001,3.975912e+000,3.169435e-001,4.780700e-001,6.175411e-006,6.175411e-006,,,,,,,,,,,,,,,,,,,,
1524345774.343,,0.000000e+000,3.499715e+001,3.499872e+001,1,0,2.064516e+000,0.000000e+000,4.007019e+000,4.007019e+000,3.287469e-001,5.130355e-001,4.020061e+000,3.417894e-001,5.260780e-001,6.589005e-006,6.589005e-006,,,,,,,,,,,,,,,,,,,,
1524345799.704,,0.000000e+000,3.499872e+001,3.499872e+001,1,0,2.322581e+000,0.000000e+000,3.949340e+000,3.949340e+000,2.477606e-001,4.580514e-001,3.982771e+000,2.811914e-001,4.914823e-001,5.136419e-006,5.136419e-006,,,,,,,,,,,,,,,,,,,,
1524345824.646,,0.000000e+000,3.499794e+001,3.499794e+001,1,0,2.580645e+000,0.000000e+000,3.844816e+000,3.844816e+000,1.147000e-001,3.464603e-001,3.900708e+000,1.705925e-001,4.023528e-001,2.532586e-006,2.532586e-006,,,,,,,,,,,,,,,,,,,,
1524345850.047,,0.000000e+000,3.499872e+001,3.500028e+001,1,0,2.838710e+000,0.000000e+000,3.793546e+000,3.793546e+000,3.548950e-002,2.901797e-001,3.813580e+000,5.552357e-002,3.102138e-001,1.111330e-006,1.111330e-006,,,,,,,,,,,,,,,,,,,,
1524345875.427,,0.000000e+000,3.499872e+001,3.499950e+001,1,0,3.096774e+000,0.000000e+000,3.754482e+000,3.754482e+000,-3.247102e-002,2.453797e-001,3.737677e+000,-4.927666e-002,2.285740e-001,-5.104812e-008,-5.104812e-008,,,,,,,,,,,,,,,,,,,,
1524345900.818,,0.000000e+000,3.499794e+001,3.500106e+001,1,0,3.354839e+000,0.000000e+000,3.727474e+000,3.727474e+000,-7.957841e-002,2.200594e-001,3.678480e+000,-1.285725e-001,1.710653e-001,-7.671770e-007,-7.671770e-007,,,,,,,,,,,,,,,,,,,,
1524345926.198,,0.000000e+000,3.499794e+001,3.500028e+001,1,0,3.612903e+000,0.000000e+000,3.700008e+000,3.700008e+000,-1.263317e-001,1.937482e-001,3.665750e+000,-1.605899e-001,1.594901e-001,-1.484485e-006,-1.484485e-006,,,,,,,,,,,,,,,,,,,,
1524345951.763,,0.000000e+000,3.499715e+001,3.499950e+001,1,0,3.870968e+000,0.000000e+000,3.681392e+000,3.681392e+000,-1.710037e-001,1.787326e-001,3.709401e+000,-1.429945e-001,2.067418e-001,-2.086628e-006,-2.086628e-006,,,,,,,,,,,,,,,,,,,,
1524345991.084,,0.000000e+000,3.499872e+001,3.499950e+001,1,0,0.000000e+000,0.000000e+000,3.393149e+000,3.393149e+000,-1.194458e-001,-1.194458e-001,3.385962e+000,-1.266327e-001,-1.266327e-001,-6.091170e-006,-6.091170e-006,,,,,,,,,,,,,,,,,,,,
1524346016.507,,0.000000e+000,3.499950e+001,3.499872e+001,1,0,2.580645e-001,0.000000e+000,3.340658e+000,3.340658e+000,-1.972939e-001,-1.739600e-001,3.377670e+000,-1.602813e-001,-1.369474e-001,-7.489769e-006,-7.489769e-006,,,,,,,,,,,,,,,,,,,,
1524346041.887,,0.000000e+000,3.499872e+001,3.499872e+001,1,0,5.161290e-001,0.000000e+000,3.354849e+000,3.354849e+000,-2.052730e-001,-1.585741e-001,3.403275e+000,-1.568468e-001,-1.101480e-001,-7.328243e-006,-7.328243e-006,,,,,,,,,,,,,,,,,,,,
1524346067.270,,0.000000e+000,3.499950e+001,3.499872e+001,1,0,7.741935e-001,0.000000e+000,3.471733e+000,3.471733e+000,-1.112082e-001,-4.288745e-002,3.484104e+000,-9.883666e-002,-3.051591e-002,-4.877409e-006,-4.877409e-006,,,,,,,,,,,,,,,,,,,,
1524346092.425,,0.000000e+000,3.499872e+001,3.499715e+001,1,0,1.032258e+000,0.000000e+000,3.655451e+000,3.655451e+000,5.782712e-002,1.478558e-001,3.598631e+000,1.006961e-003,9.103560e-002,-8.011557e-007,-8.011557e-007,,,,,,,,,,,,,,,,,,,,
1524346117.783,,0.000000e+000,3.499872e+001,3.499950e+001,1,0,1.290323e+000,0.000000e+000,3.822385e+000,3.822385e+000,2.039781e-001,3.175733e-001,3.741686e+000,1.232791e-001,2.368743e-001,2.735949e-006,2.735949e-006,,,,,,,,,,,,,,,,,,,,
1524346143.194,,0.000000e+000,3.500028e+001,3.500028e+001,1,0,1.548387e+000,0.000000e+000,3.935149e+000,3.935149e+000,2.951691e-001,4.327970e-001,3.892784e+000,2.528041e-001,3.904319e-001,5.078720e-006,5.078720e-006,,,,,,,,,,,,,,,,,,,,
1524346168.256,,0.000000e+000,3.499950e+001,3.499872e+001,1,0,1.806452e+000,0.000000e+000,4.030365e+000,4.030365e+000,3.643632e-001,5.234971e-001,4.026258e+000,3.602562e-001,5.193901e-001,6.941642e-006,6.941642e-006,,,,,,,,,,,,,,,,,,,,
1524346193.427,,0.000000e+000,3.499872e+001,3.499794e+001,1,0,2.064516e+000,0.000000e+000,4.071717e+000,4.071717e+000,3.774583e-001,5.634465e-001,4.084214e+000,3.899553e-001,5.759435e-001,7.558992e-006,7.558992e-006,,,,,,,,,,,,,,,,,,,,
1524346218.555,,0.000000e+000,3.499637e+001,3.500028e+001,1,0,2.322581e+000,0.000000e+000,4.005798e+000,4.005798e+000,2.843105e-001,4.925072e-001,4.037852e+000,3.163640e-001,5.245607e-001,5.843511e-006,5.843511e-006,,,,,,,,,,,,,,,,,,,,
1524346243.850,,0.000000e+000,3.500028e+001,3.500263e+001,1,0,2.580645e+000,0.000000e+000,3.883269e+000,3.883269e+000,1.313954e-001,3.622496e-001,3.943673e+000,1.917995e-001,4.226537e-001,2.802830e-006,2.802830e-006,,,,,,,,,,,,,,,,,,,,
1524346269.273,,0.000000e+000,3.499950e+001,3.499872e+001,1,0,2.838710e+000,0.000000e+000,3.815671e+000,3.815671e+000,3.460303e-002,2.887456e-001,3.843300e+000,6.223216e-002,3.163748e-001,9.953073e-007,9.953073e-007,,,,,,,,,,,,,,,,,,,,
1524346294.676,,0.000000e+000,3.499872e+001,3.500263e+001,1,0,3.096774e+000,0.000000e+000,3.771725e+000,3.771725e+000,-3.605337e-002,2.371242e-001,3.752365e+000,-5.541296e-002,2.177646e-001,-2.518063e-007,-2.518063e-007,,,,,,,,,,,,,,,,,,,,
1524346320.056,,0.000000e+000,3.499794e+001,3.500028e+001,1,0,3.354839e+000,0.000000e+000,3.730373e+000,3.730373e+000,-1.071112e-001,1.942806e-001,3.695327e+000,-1.421578e-001,1.592340e-001,-1.447945e-006,-1.447945e-006,,,,,,,,,,,,,,,,,,,,
1524346345.442,,0.000000e+000,3.499950e+001,3.499950e+001,1,0,3.612903e+000,0.000000e+000,3.723049e+000,3.723049e+000,-1.428060e-001,1.790431e-001,3.690083e+000,-1.757724e-001,1.460767e-001,-1.911889e-006,-1.911889e-006,,,,,,,,,,,,,,,,,,,,
1524346370.169,,0.000000e+000,3.499794e+001,3.499950e+001,1,0,3.870968e+000,0.000000e+000,3.695277e+000,3.695277e+000,-1.965266e-001,1.473014e-001,3.733710e+000,-1.580936e-001,1.857345e-001,-2.776287e-006,-2.776287e-006,,,,,,,,,,,,,,,,,,,,
1524346408.103,,0.000000e+000,3.499794e+001,3.500028e+001,1,0,0.000000e+000,0.000000e+000,3.412528e+000,3.412528e+000,-1.330130e-001,-1.330130e-001,3.407114e+000,-1.384265e-001,-1.384265e-001,-6.441347e-006,-6.441347e-006,,,,,,,,,,,,,,,,,,,,
1524346433.463,,0.000000e+000,3.499950e+001,3.499950e+001,1,0,2.580645e-001,0.000000e+000,3.344778e+000,3.344778e+000,-2.261416e-001,-2.033706e-001,3.395793e+000,-1.751265e-001,-1.523554e-001,-8.146308e-006,-8.146308e-006,,,,,,,,,,,,,,,,,,,,
1524346458.886,,0.000000e+000,3.499794e+001,3.499872e+001,1,0,5.161290e-001,0.000000e+000,3.386587e+000,3.386587e+000,-2.098811e-001,-1.640067e-001,3.424416e+000,-1.720527e-001,-1.261783e-001,-7.474897e-006,-7.474897e-006,,,,,,,,,,,,,,,,,,,,
1524346484.319,,0.000000e+000,3.499950e+001,3.499872e+001,1,0,7.741935e-001,0.000000e+000,3.503929e+000,3.503929e+000,-1.190418e-001,-5.098629e-002,3.515182e+000,-1.077894e-001,-3.973389e-002,-5.119495e-006,-5.119495e-006,,,,,,,,,,,,,,,,,,,,
1524346509.632,,0.000000e+000,3.499950e+001,3.499872e+001,1,0,1.032258e+000,0.000000e+000,3.690089e+000,3.690089e+000,4.448211e-002,1.361542e-001,3.646700e+000,1.093268e-003,9.276533e-002,-1.189779e-006,-1.189779e-006,,,,,,,,,,,,,,,,,,,,
1524346534.727,,0.000000e+000,3.499715e+001,3.499950e+001,1,0,1.290323e+000,0.000000e+000,3.877318e+000,3.877318e+000,2.107352e-001,3.237538e-001,3.798502e+000,1.319198e-001,2.449384e-001,2.830435e-006,2.830435e-006,,,,,,,,,,,,,,,,,,,,
1524346559.892,,0.000000e+000,3.499794e+001,3.499403e+001,1,0,1.548387e+000,0.000000e+000,3.936522e+000,3.936522e+000,3.095240e-001,4.440744e-001,3.899740e+000,2.727410e-001,4.072914e-001,5.342095e-006,5.342095e-006,,,,,,,,,,,,,,,,,,,,
1524346585.753,,0.000000e+000,3.499794e+001,3.499950e+001,1,0,1.806452e+000,0.000000e+000,4.025483e+000,4.025483e+000,3.932705e-001,5.634637e-001,4.018882e+000,3.866701e-001,5.568633e-001,7.499955e-006,7.499955e-006,,,,,,,,,,,,,,,,,,,,
1524346610.918,,0.000000e+000,3.499872e+001,3.499950e+001,1,0,2.064516e+000,0.000000e+000,4.108186e+000,4.108186e+000,4.041927e-001,5.925350e-001,4.119314e+000,4.153202e-001,6.036625e-001,8.094343e-006,8.094343e-006,,,,,,,,,,,,,,,,,,,,
1524346636.428,,0.000000e+000,3.499950e+001,3.499794e+001,1,0,2.322581e+000,0.000000e+000,4.031891e+000,4.031891e+000,2.855914e-001,4.952898e-001,4.083025e+000,3.367250e-001,5.464234e-001,5.819806e-006,5.819806e-006,,,,,,,,,,,,,,,,,,,,
1524346662.079,,0.000000e+000,3.500106e+001,3.499950e+001,1,0,2.580645e+000,0.000000e+000,3.924010e+000,3.924010e+000,1.491961e-001,3.788886e-001,3.980945e+000,2.061310e-001,4.358234e-001,3.127469e-006,3.127469e-006,,,,,,,,,,,,,,,,,,,,
1524346686.717,,0.000000e+000,3.499794e+001,3.499950e+001,1,0,2.838710e+000,0.000000e+000,3.826963e+000,3.826963e+000,2.921295e-002,2.818642e-001,3.863607e+000,6.585717e-002,3.185084e-001,8.190254e-007,8.190254e-007,,,,,,,,,,,,,,,,,,,,
1524346712.029,,0.000000e+000,3.499403e+001,3.499872e+001,1,0,3.096774e+000,0.000000e+000,3.766232e+000,3.766232e+000,-5.462454e-002,2.186632e-001,3.762290e+000,-5.856583e-002,2.147219e-001,-7.110939e-007,-7.110939e-007,,,,,,,,,,,,,,,,,,,,
1524346737.412,,0.000000e+000,3.499950e+001,3.499872e+001,1,0,3.354839e+000,0.000000e+000,3.747311e+000,3.747311e+000,-9.786014e-002,1.975551e-001,3.695167e+000,-1.500035e-001,1.454117e-001,-1.327557e-006,-1.327557e-006,,,,,,,,,,,,,,,,,,,,
1524346762.885,,0.000000e+000,3.499794e+001,3.499872e+001,1,0,3.612903e+000,0.000000e+000,3.707179e+000,3.707179e+000,-1.672631e-001,1.557314e-001,3.687347e+000,-1.870955e-001,1.358991e-001,-2.500383e-006,-2.500383e-006,,,,,,,,,,,,,,,,,,,,
1524346788.451,,0.000000e+000,3.499872e+001,3.499872e+001,1,0,3.870968e+000,0.000000e+000,3.697261e+000,3.697261e+000,-1.893005e-001,1.474102e-001,3.718783e+000,-1.677789e-001,1.689317e-001,-2.721616e-006,-2.721616e-006,,,,,,,,,,,,,,,,,,,,
1524346825.844,,0.000000e+000,3.499794e+001,3.499950e+001,1,0,0.000000e+000,0.000000e+000,3.396658e+000,3.396658e+000,-1.437004e-001,-1.437004e-001,3.393521e+000,-1.468379e-001,-1.468379e-001,-6.719216e-006,-6.719216e-006,,,,,,,,,,,,,,,,,,,,
1524346850.989,,0.000000e+000,3.499794e+001,3.500028e+001,1,0,2.580645e-001,0.000000e+000,3.326925e+000,3.326925e+000,-2.279101e-001,-2.052784e-001,3.370806e+000,-1.840287e-001,-1.613970e-001,-8.216986e-006,-8.216986e-006,,,,,,,,,,,,,,,,,,,,
1524346876.199,,0.000000e+000,3.499794e+001,3.499794e+001,1,0,5.161290e-001,0.000000e+000,3.355154e+000,3.355154e+000,-2.136771e-001,-1.679997e-001,3.388928e+000,-1.799028e-001,-1.342254e-001,-7.591530e-006,-7.591530e-006,,,,,,,,,,,,,,,,,,,,
1524346902.072,,0.000000e+000,3.499794e+001,3.499950e+001,1,0,7.741935e-001,0.000000e+000,3.463340e+000,3.463340e+000,-1.219584e-001,-5.421090e-002,3.472390e+000,-1.129083e-001,-4.516077e-002,-5.219757e-006,-5.219757e-006,,,,,,,,,,,,,,,,,,,,
1524346927.515,,0.000000e+000,3.499950e+001,3.499872e+001,1,0,1.032258e+000,0.000000e+000,3.652247e+000,3.652247e+000,4.921726e-002,1.403315e-001,3.604172e+000,1.142062e-003,9.225631e-002,-1.117980e-006,-1.117980e-006,,,,,,,,,,,,,,,,,,,,
1524346952.796,,0.000000e+000,3.499872e+001,3.500106e+001,1,0,1.290323e+000,0.000000e+000,3.842985e+000,3.842985e+000,2.223427e-001,3.385289e-001,3.759568e+000,1.389258e-001,2.551119e-001,3.012843e-006,3.012843e-006,,,,,,,,,,,,,,,,,,,,
1524346978.051,,0.000000e+000,3.500028e+001,3.499715e+001,1,0,1.548387e+000,0.000000e+000,3.984131e+000,3.984131e+000,3.376895e-001,4.655626e-001,3.930307e+000,2.838660e-001,4.117391e-001,5.955109e-006,5.955109e-006,,,,,,,,,,,,,,,,,,,,
1524347003.461,,0.000000e+000,3.499324e+001,3.499715e+001,1,0,1.806452e+000,0.000000e+000,4.066529e+000,4.066529e+000,4.104644e-001,5.714159e-001,4.061983e+000,4.059182e-001,5.668697e-001,7.848648e-006,7.848648e-006,,,,,,,,,,,,,,,,,,,,
1524347029.189,,0.000000e+000,3.500184e+001,3.499950e+001,1,0,2.064516e+000,0.000000e+000,4.105592e+000,4.105592e+000,4.263654e-001,6.108577e-001,4.118841e+000,4.396143e-001,6.241066e-001,8.528557e-006,8.528557e-006,,,,,,,,,,,,,,,,,,,,
1524347054.335,,0.000000e+000,3.499872e+001,3.499637e+001,1,0,2.322581e+000,0.000000e+000,4.024415e+000,4.024415e+000,3.212923e-001,5.272090e-001,4.058240e+000,3.551182e-001,5.610349e-001,6.550123e-006,6.550123e-006,,,,,,,,,,,,,,,,,,,,
1524347079.357,,0.000000e+000,3.499950e+001,3.500106e+001,1,0,2.580645e+000,0.000000e+000,3.882811e+000,3.882811e+000,1.551814e-001,3.818533e-001,3.942919e+000,2.152900e-001,4.419620e-001,3.208479e-006,3.208479e-006,,,,,,,,,,,,,,,,,,,,
1524347104.788,,0.000000e+000,3.499950e+001,3.499950e+001,1,0,2.838710e+000,0.000000e+000,3.802548e+000,3.802548e+000,4.629893e-002,2.956486e-001,3.825307e+000,6.905718e-002,3.184068e-001,1.136839e-006,1.136839e-006,,,,,,,,,,,,,,,,,,,,
1524347130.196,,0.000000e+000,3.500263e+001,3.500184e+001,1,0,3.096774e+000,0.000000e+000,3.735561e+000,3.735561e+000,-4.427906e-002,2.296040e-001,3.718618e+000,-6.122228e-002,2.126608e-001,-5.219044e-007,-5.219044e-007,,,,,,,,,,,,,,,,,,,,
1524347155.601,,0.000000e+000,3.499872e+001,3.499872e+001,1,0,3.354839e+000,0.000000e+000,3.694514e+000,3.694514e+000,-1.098897e-001,1.871362e-001,3.647311e+000,-1.570926e-001,1.399333e-001,-1.627079e-006,-1.627079e-006,,,,,,,,,,,,,,,,,,,,
1524347180.854,,0.000000e+000,3.499872e+001,3.499950e+001,1,0,3.612903e+000,0.000000e+000,3.400016e+000,3.400016e+000,-1.663609e-001,1.301897e-001,3.371869e+000,-1.945074e-001,1.020432e-001,-2.691013e-006,-2.691013e-006,,,,,,,,,,,,,,,,,,,,
1524347206.042,,0.000000e+000,3.500106e+001,3.499872e+001,1,0,3.870968e+000,0.000000e+000,3.619287e+000,3.619287e+000,-2.020702e-001,1.445701e-001,3.648095e+000,-1.732623e-001,1.733780e-001,-2.963498e-006,-2.963498e-006,,,,,,,,,,,,,,,,,,,,
1524347244.005,,0.000000e+000,3.499715e+001,3.499950e+001,1,0,0.000000e+000,0.000000e+000,3.340047e+000,3.340047e+000,-1.495326e-001,-1.495326e-001,3.337686e+000,-1.518943e-001,-1.518943e-001,-6.902745e-006,-6.902745e-006,,,,,,,,,,,,,,,,,,,,
1524347269.465,,0.000000e+000,3.499950e+001,3.499950e+001,1,0,2.580645e-001,0.000000e+000,3.280079e+000,3.280079e+000,-2.418850e-001,-2.188361e-001,3.330386e+000,-1.915780e-001,-1.685290e-001,-8.605391e-006,-8.605391e-006,,,,,,,,,,,,,,,,,,,,
1524347294.778,,0.000000e+000,3.499794e+001,3.499950e+001,1,0,5.161290e-001,0.000000e+000,3.329977e+000,3.329977e+000,-2.263133e-001,-1.806099e-001,3.368563e+000,-1.877269e-001,-1.420236e-001,-7.912546e-006,-7.912546e-006,,,,,,,,,,,,,,,,,,,,
1524347320.481,,0.000000e+000,3.499794e+001,3.499872e+001,1,0,7.741935e-001,0.000000e+000,3.471885e+000,3.471885e+000,-1.149982e-001,-4.640412e-002,3.469356e+000,-1.175271e-001,-4.893303e-002,-5.124792e-006,-5.124792e-006,,,,,,,,,,,,,,,,,,,,
1524347345.946,,0.000000e+000,3.499872e+001,3.500028e+001,1,0,1.032258e+000,0.000000e+000,3.677577e+000,3.677577e+000,6.158819e-002,1.539285e-001,3.617164e+000,1.175068e-003,9.351540e-002,-8.893985e-007,-8.893985e-007,,,,,,,,,,,,,,,,,,,,
1524347371.361,,0.000000e+000,3.499872e+001,3.499872e+001,1,0,1.290323e+000,0.000000e+000,3.876860e+000,3.876860e+000,2.278298e-001,3.403513e-001,3.792929e+000,1.438989e-001,2.564204e-001,3.129448e-006,3.129448e-006,,,,,,,,,,,,,,,,,,,,
1524347396.278,,0.000000e+000,3.499794e+001,3.499872e+001,1,0,1.548387e+000,0.000000e+000,4.006714e+000,4.006714e+000,3.342832e-001,4.707723e-001,3.966938e+000,2.945073e-001,4.309964e-001,5.807422e-006,5.807422e-006,,,,,,,,,,,,,,,,,,,,
1524347421.666,,0.000000e+000,3.499794e+001,3.499950e+001,1,0,1.806452e+000,0.000000e+000,4.130007e+000,4.130007e+000,4.310643e-001,5.917883e-001,4.117120e+000,4.181778e-001,5.789018e-001,8.274743e-006,8.274743e-006,,,,,,,,,,,,,,,,,,,,
1524347447.497,,0.000000e+000,3.499872e+001,3.499872e+001,1,0,2.064516e+000,0.000000e+000,4.122225e+000,4.122225e+000,4.349670e-001,6.186485e-001,4.136678e+000,4.494200e-001,6.331015e-001,8.696443e-006,8.696443e-006,,,,,,,,,,,,,,,,,,,,
1524347472.860,,0.000000e+000,3.499794e+001,3.499950e+001,1,0,2.322581e+000,0.000000e+000,3.766079e+000,3.766079e+000,3.107800e-001,5.021160e-001,3.820719e+000,3.654201e-001,5.567560e-001,6.260510e-006,6.260510e-006,,,,,,,,,,,,,,,,,,,,
1524347498.095,,0.000000e+000,3.499872e+001,3.499872e+001,1,0,2.580645e+000,0.000000e+000,3.883116e+000,3.883116e+000,1.735270e-001,4.039147e-001,3.930122e+000,2.205329e-001,4.509206e-001,3.602036e-006,3.602036e-006,,,,,,,,,,,,,,,,,,,,
1524347523.900,,0.000000e+000,3.499872e+001,3.500028e+001,1,0,2.838710e+000,0.000000e+000,3.515068e+000,3.515068e+000,3.211654e-002,2.747595e-001,3.554561e+000,7.160963e-002,3.142526e-001,7.589551e-007,7.589551e-007,,,,,,,,,,,,,,,,,,,,
1524347549.263,,0.000000e+000,3.499872e+001,3.499794e+001,1,0,3.096774e+000,0.000000e+000,3.690547e+000,3.690547e+000,-5.179031e-002,2.240748e-001,3.679371e+000,-6.296618e-002,2.128990e-001,-7.049966e-007,-7.049966e-007,,,,,,,,,,,,,,,,,,,,
1524347574.731,,0.000000e+000,3.499872e+001,3.499950e+001,1,0,3.354839e+000,0.000000e+000,3.398031e+000,3.398031e+000,-1.154973e-001,1.643379e-001,3.351116e+000,-1.624128e-001,1.174223e-001,-1.885681e-006,-1.885681e-006,,,,,,,,,,,,,,,,,,,,
1524347600.184,,0.000000e+000,3.499872e+001,3.499872e+001,1,0,3.612903e+000,0.000000e+000,3.607996e+000,3.607996e+000,-1.705671e-001,1.472285e-001,3.577307e+000,-2.012554e-001,1.165402e-001,-2.677873e-006,-2.677873e-006,,,,,,,,,,,,,,,,,,,,
1524347625.477,,0.000000e+000,3.499950e+001,3.499872e+001,1,0,3.870968e+000,0.000000e+000,3.602197e+000,3.602197e+000,-2.131672e-001,1.326385e-001,3.636587e+000,-1.787777e-001,1.670280e-001,-3.245164e-006,-3.245164e-006,,,,,,,,,,,,,,,,,,,,
1524347663.350,,0.000000e+000,3.499872e+001,3.500028e+001,1,0,0.000000e+000,0.000000e+000,3.327077e+000,3.327077e+000,-1.585603e-001,-1.585603e-001,3.328865e+000,-1.567729e-001,-1.567729e-001,-7.116440e-006,-7.116440e-006,,,,,,,,,,,,,,,,,,,,
1524347689.505,,0.000000e+000,3.499872e+001,3.499872e+001,1,0,2.580645e-001,0.000000e+000,3.276265e+000,3.276265e+000,-2.393394e-001,-2.165205e-001,3.318928e+000,-1.966758e-001,-1.738570e-001,-8.552408e-006,-8.552408e-006,,,,,,,,,,,,,,,,,,,,
1524347714.891,,0.000000e+000,3.499794e+001,3.499950e+001,1,0,5.161290e-001,0.000000e+000,3.309682e+000,3.309682e+000,-2.330276e-001,-1.876075e-001,3.350279e+000,-1.924309e-001,-1.470108e-001,-8.073417e-006,-8.073417e-006,,,,,,,,,,,,,,,,,,,,
1524347739.184,,0.000000e+000,3.499950e+001,3.499872e+001,1,0,7.741935e-001,0.000000e+000,3.426413e+000,3.426413e+000,-1.299879e-001,-6.302094e-002,3.437151e+000,-1.192497e-001,-5.228281e-002,-5.432128e-006,-5.432128e-006,,,,,,,,,,,,,,,,,,,,
1524347764.331,,0.000000e+000,3.499950e+001,3.499872e+001,1,0,1.032258e+000,0.000000e+000,3.621119e+000,3.621119e+000,5.131608e-002,1.413586e-001,3.571013e+000,1.210980e-003,9.125352e-002,-1.114211e-006,-1.114211e-006,,,,,,,,,,,,,,,,,,,,
1524347789.292,,0.000000e+000,3.499715e+001,3.499872e+001,1,0,1.290323e+000,0.000000e+000,3.802243e+000,3.802243e+000,2.135315e-001,3.263524e-001,3.735722e+000,1.470104e-001,2.598312e-001,2.790170e-006,2.790170e-006,,,,,,,,,,,,,,,,,,,,
1524347814.717,,0.000000e+000,3.499715e+001,3.499872e+001,1,0,1.548387e+000,0.000000e+000,3.968414e+000,3.968414e+000,3.551611e-001,4.926393e-001,3.916610e+000,3.033571e-001,4.408352e-001,6.234375e-006,6.234375e-006,,,,,,,,,,,,,,,,,,,,
1524347839.980,,0.000000e+000,3.499872e+001,3.500028e+001,1,0,1.806452e+000,0.000000e+000,4.076295e+000,4.076295e+000,4.388852e-001,5.981746e-001,4.067141e+000,4.297313e-001,5.890207e-001,8.422372e-006,8.422372e-006,,,,,,,,,,,,,,,,,,,,
1524347865.060,,0.000000e+000,3.499950e+001,3.499950e+001,1,0,2.064516e+000,0.000000e+000,4.104829e+000,4.104829e+000,4.440419e-001,6.253781e-001,4.124151e+000,4.633638e-001,6.447001e-001,8.865041e-006,8.865041e-006,,,,,,,,,,,,,,,,,,,,
1524347890.521,,0.000000e+000,3.499794e+001,3.499715e+001,1,0,2.322581e+000,0.000000e+000,4.022583e+000,4.022583e+000,3.371630e-001,5.405526e-001,4.062429e+000,3.770085e-001,5.803981e-001,6.835980e-006,6.835980e-006,,,,,,,,,,,,,,,,,,,,
1524347915.814,,0.000000e+000,3.499715e+001,3.499794e+001,1,0,2.580645e+000,0.000000e+000,3.880064e+000,3.880064e+000,1.712981e-001,3.950357e-001,3.935954e+000,2.271875e-001,4.509251e-001,3.501016e-006,3.501016e-006,,,,,,,,,,,,,,,,,,,,
1524347941.201,,0.000000e+000,3.499950e+001,3.499872e+001,1,0,2.838710e+000,0.000000e+000,3.777218e+000,3.777218e+000,4.327873e-002,2.920408e-001,3.806742e+000,7.280234e-002,3.215644e-001,1.015142e-006,1.015142e-006,,,,,,,,,,,,,,,,,,,,
1524347966.089,,0.000000e+000,3.499950e+001,3.499872e+001,1,0,3.096774e+000,0.000000e+000,3.697109e+000,3.697109e+000,-6.116442e-002,2.085605e-001,3.693609e+000,-6.466369e-002,2.050612e-001,-9.707437e-007,-9.707437e-007,,,,,,,,,,,,,,,,,,,,
1524347991.392,,0.000000e+000,3.499950e+001,3.499872e+001,1,0,3.354839e+000,0.000000e+000,3.663996e+000,3.663996e+000,-1.152103e-001,1.741514e-001,3.613170e+000,-1.660366e-001,1.233251e-001,-1.845037e-006,-1.845037e-006,,,,,,,,,,,,,,,,,,,,
1524348016.860,,0.000000e+000,3.499950e+001,3.499794e+001,1,0,3.612903e+000,0.000000e+000,3.627985e+000,3.627985e+000,-1.805283e-001,1.379690e-001,3.601743e+000,-2.067701e-001,1.117272e-001,-2.920497e-006,-2.920497e-006,,,,,,,,,,,,,,,,,,,,
1524348042.163,,0.000000e+000,3.500106e+001,3.499950e+001,1,0,3.870968e+000,0.000000e+000,3.628290e+000,3.628290e+000,-2.010853e-001,1.378772e-001,3.645592e+000,-1.837835e-001,1.551790e-001,-3.055189e-006,-3.055189e-006,,,,,,,,,,,,,,,,,,,,
1524348080.298,,0.000000e+000,3.499872e+001,3.499872e+001,1,0,0.000000e+000,0.000000e+000,3.324941e+000,3.324941e+000,-1.672175e-001,-1.672175e-001,3.331343e+000,-1.608155e-001,-1.608155e-001,-7.296694e-006,-7.296694e-006,,,,,,,,,,,,,,,,,,,,
1524348105.619,,0.000000e+000,3.499872e+001,3.499950e+001,1,0,2.580645e-001,0.000000e+000,3.258869e+000,3.258869e+000,-2.531260e-001,-2.303631e-001,3.309986e+000,-2.020090e-001,-1.792462e-001,-8.878327e-006,-8.878327e-006,,,,,,,,,,,,,,,,,,,,
1524348130.992,,0.000000e+000,3.499872e+001,3.499872e+001,1,0,5.161290e-001,0.000000e+000,3.304494e+000,3.304494e+000,-2.266669e-001,-1.809940e-001,3.334891e+000,-1.962695e-001,-1.505966e-001,-7.963914e-006,-7.963914e-006,,,,,,,,,,,,,,,,,,,,
1524348156.550,,0.000000e+000,3.499950e+001,3.500028e+001,1,0,7.741935e-001,0.000000e+000,3.430228e+000,3.430228e+000,-1.255143e-001,-5.745101e-002,3.433268e+000,-1.224745e-001,-5.441117e-002,-5.386144e-006,-5.386144e-006,,,,,,,,,,,,,,,,,,,,
1524348181.760,,0.000000e+000,3.499950e+001,3.499872e+001,1,0,1.032258e+000,0.000000e+000,3.631037e+000,3.631037e+000,5.167460e-002,1.412151e-001,3.580601e+000,1.238577e-003,9.077907e-002,-1.122287e-006,-1.122287e-006,,,,,,,,,,,,,,,,,,,,
1524348207.160,,0.000000e+000,3.499872e+001,3.499950e+001,1,0,1.290323e+000,0.000000e+000,3.836423e+000,3.836423e+000,2.366575e-001,3.496523e-001,3.750268e+000,1.505021e-001,2.634969e-001,3.275127e-006,3.275127e-006,,,,,,,,,,,,,,,,,,,,
1524348232.493,,0.000000e+000,3.500106e+001,3.499950e+001,1,0,1.548387e+000,0.000000e+000,3.983215e+000,3.983215e+000,3.662511e-001,5.055194e-001,3.929088e+000,3.121236e-001,4.513919e-001,6.442147e-006,6.442147e-006,,,,,,,,,,,,,,,,,,,,
1524348257.556,,0.000000e+000,3.499872e+001,3.499950e+001,1,0,1.806452e+000,0.000000e+000,4.089113e+000,4.089113e+000,4.492789e-001,6.077104e-001,4.077340e+000,4.375062e-001,5.959377e-001,8.634786e-006,8.634786e-006,,,,,,,,,,,,,,,,,,,,
1524348284.474,,0.000000e+000,3.499872e+001,3.499950e+001,1,0,2.064516e+000,0.000000e+000,4.115511e+000,4.115511e+000,4.524731e-001,6.333838e-001,4.133223e+000,4.701847e-001,6.510954e-001,9.035924e-006,9.035924e-006,,,,,,,,,,,,,,,,,,,,
1524348309.672,,0.000000e+000,3.500263e+001,3.499950e+001,1,0,2.322581e+000,0.000000e+000,4.021515e+000,4.021515e+000,3.384959e-001,5.425348e-001,4.066815e+000,3.837954e-001,5.878344e-001,6.848350e-006,6.848350e-006,,,,,,,,,,,,,,,,,,,,
1524348334.460,,0.000000e+000,3.499950e+001,3.499794e+001,1,0,2.580645e+000,0.000000e+000,3.884489e+000,3.884489e+000,1.814550e-001,4.065323e-001,3.934401e+000,2.313663e-001,4.564435e-001,3.710797e-006,3.710797e-006,,,,,,,,,,,,,,,,,,,,
1524348359.670,,0.000000e+000,3.499794e+001,3.499950e+001,1,0,2.838710e+000,0.000000e+000,3.772946e+000,3.772946e+000,4.860034e-002,2.940884e-001,3.798514e+000,7.416907e-002,3.196571e-001,1.099135e-006,1.099135e-006,,,,,,,,,,,,,,,,,,,,
1524348385.233,,0.000000e+000,3.499559e+001,3.499872e+001,1,0,3.096774e+000,0.000000e+000,3.696651e+000,3.696651e+000,-4.904649e-002,2.203374e-001,3.679907e+000,-6.579039e-002,2.035935e-001,-7.230119e-007,-7.230119e-007,,,,,,,,,,,,,,,,,,,,
1524348410.653,,0.000000e+000,3.499872e+001,3.500028e+001,1,0,3.354839e+000,0.000000e+000,3.645380e+000,3.645380e+000,-1.185834e-001,1.725461e-001,3.595135e+000,-1.688286e-001,1.223009e-001,-1.926208e-006,-1.926208e-006,,,,,,,,,,,,,,,,,,,,
1524348435.989,,0.000000e+000,3.499950e+001,3.499872e+001,1,0,3.612903e+000,0.000000e+000,3.613031e+000,3.613031e+000,-1.736290e-001,1.436193e-001,3.577840e+000,-2.088201e-001,1.084282e-001,-2.786692e-006,-2.786692e-006,,,,,,,,,,,,,,,,,,,,
1524348461.244,,0.000000e+000,3.499246e+001,3.499872e+001,1,0,3.870968e+000,0.000000e+000,3.596246e+000,3.596246e+000,-2.085191e-001,1.309140e-001,3.618842e+000,-1.859232e-001,1.535099e-001,-3.227862e-006,-3.227862e-006,,,,,,,,,,,,,,,,,,,,
1524348499.555,,0.000000e+000,3.500341e+001,3.500028e+001,1,0,0.000000e+000,0.000000e+000,3.298848e+000,3.298848e+000,-1.664069e-001,-1.664069e-001,3.302536e+000,-1.627192e-001,-1.627192e-001,-7.256953e-006,-7.256953e-006,,,,,,,,,,,,,,,,,,,,
1524348525.620,,0.000000e+000,3.499872e+001,3.500028e+001,1,0,2.580645e-001,0.000000e+000,3.235218e+000,3.235218e+000,-2.504221e-001,-2.278652e-001,3.280818e+000,-2.048217e-001,-1.822648e-001,-8.812596e-006,-8.812596e-006,,,,,,,,,,,,,,,,,,,,
1524348551.045,,0.000000e+000,3.499872e+001,3.499950e+001,1,0,5.161290e-001,0.000000e+000,3.265431e+000,3.265431e+000,-2.411694e-001,-1.962020e-001,3.307625e+000,-1.989753e-001,-1.540079e-001,-8.268311e-006,-8.268311e-006,,,,,,,,,,,,,,,,,,,,
1524348576.433,,0.000000e+000,3.499950e+001,3.499950e+001,1,0,7.741935e-001,0.000000e+000,3.392691e+000,3.392691e+000,-1.317088e-001,-6.389713e-002,3.400393e+000,-1.240064e-001,-5.619478e-002,-5.529859e-006,-5.529859e-006,,,,,,,,,,,,,,,,,,,,
1524348601.834,,0.000000e+000,3.499872e+001,3.499950e+001,1,0,1.032258e+000,0.000000e+000,3.612573e+000,3.612573e+000,6.554142e-002,1.553779e-001,3.548292e+000,1.260437e-003,9.109688e-002,-8.385832e-007,-8.385832e-007,,,,,,,,,,,,,,,,,,,,
1524348627.562,,0.000000e+000,3.499794e+001,3.499950e+001,1,0,1.290323e+000,0.000000e+000,3.783474e+000,3.783474e+000,2.214263e-001,3.371096e-001,3.714280e+000,1.522315e-001,2.679148e-001,2.905392e-006,2.905392e-006,,,,,,,,,,,,,,,,,,,,
1524348652.942,,0.000000e+000,3.499950e+001,3.500028e+001,1,0,1.548387e+000,0.000000e+000,3.954681e+000,3.954681e+000,3.696772e-001,5.052783e-001,3.899578e+000,3.145747e-001,4.501758e-001,6.525268e-006,6.525268e-006,,,,,,,,,,,,,,,,,,,,
1524348678.350,,0.000000e+000,3.499715e+001,3.499950e+001,1,0,1.806452e+000,0.000000e+000,4.049745e+000,4.049745e+000,4.462253e-001,6.043327e-001,4.050993e+000,4.474742e-001,6.055815e-001,8.544448e-006,8.544448e-006,,,,,,,,,,,,,,,,,,,,
1524348703.888,,0.000000e+000,3.500028e+001,3.499872e+001,1,0,2.064516e+000,0.000000e+000,4.103151e+000,4.103151e+000,4.730725e-001,6.448503e-001,4.114754e+000,4.846754e-001,6.564531e-001,9.454496e-006,9.454496e-006,,,,,,,,,,,,,,,,,,,,
1524348729.070,,0.000000e+000,3.500028e+001,3.499872e+001,1,0,2.322581e+000,0.000000e+000,3.991607e+000,3.991607e+000,3.468606e-001,5.473979e-001,4.033065e+000,3.883180e-001,5.888553e-001,7.013543e-006,7.013543e-006,,,,,,,,,,,,,,,,,,,,
1524348754.583,,0.000000e+000,3.500106e+001,3.499794e+001,1,0,2.580645e+000,0.000000e+000,3.826810e+000,3.826810e+000,1.666044e-001,3.917818e-001,3.892402e+000,2.321960e-001,4.573734e-001,3.379726e-006,3.379726e-006,,,,,,,,,,,,,,,,,,,,
1524348780.394,,0.000000e+000,3.500106e+001,3.499950e+001,1,0,2.838710e+000,0.000000e+000,3.734340e+000,3.734340e+000,4.921571e-002,2.921989e-001,3.760305e+000,7.518044e-002,3.181636e-001,1.087639e-006,1.087639e-006,,,,,,,,,,,,,,,,,,,,
1524348805.239,,0.000000e+000,3.499715e+001,3.499872e+001,1,0,3.096774e+000,0.000000e+000,3.657130e+000,3.657130e+000,-4.872195e-002,2.192276e-001,3.639740e+000,-6.611173e-002,2.018378e-001,-7.284398e-007,-7.284398e-007,,,,,,,,,,,,,,,,,,,,
1524348830.617,,0.000000e+000,3.499637e+001,3.500028e+001,1,0,3.354839e+000,0.000000e+000,3.600366e+000,3.600366e+000,-1.247632e-001,1.668673e-001,3.554155e+000,-1.709740e-001,1.206565e-001,-2.072775e-006,-2.072775e-006,,,,,,,,,,,,,,,,,,,,
1524348856.005,,0.000000e+000,3.499637e+001,3.499950e+001,1,0,3.612903e+000,0.000000e+000,3.553216e+000,3.553216e+000,-1.949602e-001,1.171393e-001,3.537039e+000,-2.111372e-001,1.009624e-001,-3.302703e-006,-3.302703e-006,,,,,,,,,,,,,,,,,,,,
1524348881.405,,0.000000e+000,3.499950e+001,3.499950e+001,1,0,3.870968e+000,0.000000e+000,3.553368e+000,3.553368e+000,-2.183773e-001,1.160805e-001,3.584086e+000,-1.876599e-001,1.467979e-001,-3.490481e-006,-3.490481e-006,,,,,,,,,,,,,,,,,,,,
1524348919.583,,0.000000e+000,3.499872e+001,3.499872e+001,1,0,0.000000e+000,0.000000e+000,3.261616e+000,3.261616e+000,-1.712449e-001,-1.712449e-001,3.268252e+000,-1.646090e-001,-1.646090e-001,-7.389142e-006,-7.389142e-006,,,,,,,,,,,,,,,,,,,,
1524348944.869,,0.000000e+000,3.499950e+001,3.499872e+001,1,0,2.580645e-001,0.000000e+000,3.215839e+000,3.215839e+000,-2.492679e-001,-2.267621e-001,3.258797e+000,-2.063094e-001,-1.838036e-001,-8.789662e-006,-8.789662e-006,,,,,,,,,,,,,,,,,,,,
1524348970.187,,0.000000e+000,3.499715e+001,3.499872e+001,1,0,5.161290e-001,0.000000e+000,3.259327e+000,3.259327e+000,-2.368036e-001,-1.923518e-001,3.295002e+000,-2.011290e-001,-1.566772e-001,-8.161471e-006,-8.161471e-006,,,,,,,,,,,,,,,,,,,,
1524348995.585,,0.000000e+000,3.500106e+001,3.499950e+001,1,0,7.741935e-001,0.000000e+000,3.392538e+000,3.392538e+000,-1.298234e-001,-6.358337e-002,3.396690e+000,-1.256715e-001,-5.943155e-002,-5.465685e-006,-5.465685e-006,,,,,,,,,,,,,,,,,,,,
1524349020.510,,0.000000e+000,3.499950e+001,3.499715e+001,1,0,1.032258e+000,0.000000e+000,3.592279e+000,3.592279e+000,5.065081e-002,1.401432e-001,3.542906e+000,1.277655e-003,9.077001e-002,-1.176624e-006,-1.176624e-006,,,,,,,,,,,,,,,,,,,,
1524349045.818,,0.000000e+000,3.499872e+001,3.499872e+001,1,0,1.290323e+000,0.000000e+000,3.804685e+000,3.804685e+000,2.402579e-001,3.529215e-001,3.719394e+000,1.549674e-001,2.676311e-001,3.326597e-006,3.326597e-006,,,,,,,,,,,,,,,,,,,,
1524349071.221,,0.000000e+000,3.499950e+001,3.499872e+001,1,0,1.548387e+000,0.000000e+000,3.960327e+000,3.960327e+000,3.740715e-001,5.087225e-001,3.906145e+000,3.198900e-001,4.545410e-001,6.608592e-006,6.608592e-006,,,,,,,,,,,,,,,,,,,,
1524349096.566,,0.000000e+000,3.499950e+001,3.499872e+001,1,0,1.806452e+000,0.000000e+000,4.063172e+000,4.063172e+000,4.534750e-001,6.105330e-001,4.062804e+000,4.531064e-001,6.101644e-001,8.692834e-006,8.692834e-006,,,,,,,,,,,,,,,,,,,,
1524349121.934,,0.000000e+000,3.500106e+001,3.499794e+001,1,0,2.064516e+000,0.000000e+000,4.095674e+000,4.095674e+000,4.647442e-001,6.440878e-001,4.116418e+000,4.854885e-001,6.648321e-001,9.272408e-006,9.272408e-006,,,,,,,,,,,,,,,,,,,,
1524349147.357,,0.000000e+000,3.499950e+001,3.499794e+001,1,0,2.322581e+000,0.000000e+000,4.012512e+000,4.012512e+000,3.543411e-001,5.520139e-001,4.050821e+000,3.926497e-001,5.903225e-001,7.161027e-006,7.161027e-006,,,,,,,,,,,,,,,,,,,,
1524349172.697,,0.000000e+000,3.499950e+001,3.499950e+001,1,0,2.580645e+000,0.000000e+000,3.865568e+000,3.865568e+000,1.892747e-001,4.127662e-001,3.914039e+000,2.377459e-001,4.612374e-001,3.849476e-006,3.849476e-006,,,,,,,,,,,,,,,,,,,,
1524349198.067,,0.000000e+000,3.499950e+001,3.499872e+001,1,0,2.838710e+000,0.000000e+000,3.746243e+000,3.746243e+000,4.622599e-002,2.942958e-001,3.776436e+000,7.641956e-002,3.244894e-001,1.026390e-006,1.026390e-006,,,,,,,,,,,,,,,,,,,,
1524349223.428,,0.000000e+000,3.499872e+001,3.499950e+001,1,0,3.096774e+000,0.000000e+000,3.657282e+000,3.657282e+000,-6.341442e-002,2.043874e-001,3.653220e+000,-6.747636e-002,2.003255e-001,-1.075066e-006,-1.075066e-006,,,,,,,,,,,,,,,,,,,,
1524349248.801,,0.000000e+000,3.499950e+001,3.499872e+001,1,0,3.354839e+000,0.000000e+000,3.619135e+000,3.619135e+000,-1.240718e-001,1.701865e-001,3.569984e+000,-1.732227e-001,1.210356e-001,-2.055735e-006,-2.055735e-006,,,,,,,,,,,,,,,,,,,,
1524349274.036,,0.000000e+000,3.499872e+001,3.500028e+001,1,0,3.612903e+000,0.000000e+000,3.583429e+000,3.583429e+000,-1.808330e-001,1.358554e-001,3.549269e+000,-2.149926e-001,1.016958e-001,-2.980029e-006,-2.980029e-006,,,,,,,,,,,,,,,,,,,,
1524349299.191,,0.000000e+000,3.499950e+001,3.499950e+001,1,0,3.870968e+000,0.000000e+000,3.582513e+000,3.582513e+000,-2.036285e-001,1.330469e-001,3.594253e+000,-1.918882e-001,1.447871e-001,-3.172914e-006,-3.172914e-006,,,,,,,,,,,,,,,,,,,,
1524349336.542,,0.000000e+000,3.499950e+001,3.500028e+001,1,0,0.000000e+000,0.000000e+000,3.278401e+000,3.278401e+000,-1.705461e-001,-1.705461e-001,3.282184e+000,-1.667626e-001,-1.667626e-001,-7.404378e-006,-7.404378e-006,,,,,,,,,,,,,,,,,,,,
1524349361.125,,0.000000e+000,3.499872e+001,3.499794e+001,1,0,2.580645e-001,0.000000e+000,3.217517e+000,3.217517e+000,-2.540845e-001,-2.319918e-001,3.262456e+000,-2.091461e-001,-1.870534e-001,-8.869436e-006,-8.869436e-006,,,,,,,,,,,,,,,,,,,,
1524349386.080,,0.000000e+000,3.499872e+001,3.499950e+001,1,0,5.161290e-001,0.000000e+000,3.259022e+000,3.259022e+000,-2.355526e-001,-1.906779e-001,3.291075e+000,-2.034994e-001,-1.586246e-001,-8.164207e-006,-8.164207e-006,,,,,,,,,,,,,,,,,,,,
1524349411.503,,0.000000e+000,3.500106e+001,3.499872e+001,1,0,7.741935e-001,0.000000e+000,3.401694e+000,3.401694e+000,-1.147315e-001,-4.768276e-002,3.389575e+000,-1.268511e-001,-5.980229e-002,-5.161375e-006,-5.161375e-006,,,,,,,,,,,,,,,,,,,,
1524349436.823,,0.000000e+000,3.500028e+001,3.499794e+001,1,0,1.032258e+000,0.000000e+000,3.598840e+000,3.598840e+000,6.329110e-002,1.537769e-001,3.536842e+000,1.292489e-003,9.177828e-002,-9.237701e-007,-9.237701e-007,,,,,,,,,,,,,,,,,,,,
1524349462.194,,0.000000e+000,3.499872e+001,3.499950e+001,1,0,1.290323e+000,0.000000e+000,3.789578e+000,3.789578e+000,2.313178e-001,3.447623e-001,3.714072e+000,1.558116e-001,2.692561e-001,3.117195e-006,3.117195e-006,,,,,,,,,,,,,,,,,,,,
1524349487.624,,0.000000e+000,3.499950e+001,3.500028e+001,1,0,1.548387e+000,0.000000e+000,3.954681e+000,3.954681e+000,3.732938e-001,5.084808e-001,3.902509e+000,3.211223e-001,4.563093e-001,6.584974e-006,6.584974e-006,,,,,,,,,,,,,,,,,,,,
1524349513.047,,0.000000e+000,3.499715e+001,3.499950e+001,1,0,1.806452e+000,0.000000e+000,4.072785e+000,4.072785e+000,4.681443e-001,6.240814e-001,4.060992e+000,4.563507e-001,6.122878e-001,9.010662e-006,9.010662e-006,,,,,,,,,,,,,,,,,,,,
1524349538.445,,0.000000e+000,3.500028e+001,3.500028e+001,1,0,2.064516e+000,0.000000e+000,4.079652e+000,4.079652e+000,4.530376e-001,6.307659e-001,4.114518e+000,4.879030e-001,6.656313e-001,9.008043e-006,9.008043e-006,,,,,,,,,,,,,,,,,,,,
1524349563.778,,0.000000e+000,3.499872e+001,3.499794e+001,1,0,2.322581e+000,0.000000e+000,4.009308e+000,4.009308e+000,3.552151e-001,5.589290e-001,4.050682e+000,3.965889e-001,6.003027e-001,7.182040e-006,7.182040e-006,,,,,,,,,,,,,,,,,,,,
1524349589.201,,0.000000e+000,3.499872e+001,3.500028e+001,1,0,2.580645e+000,0.000000e+000,3.867552e+000,3.867552e+000,1.777612e-001,3.993778e-001,3.928919e+000,2.391285e-001,4.607451e-001,3.582987e-006,3.582987e-006,,,,,,,,,,,,,,,,,,,,
1524349614.584,,0.000000e+000,3.499950e+001,3.499950e+001,1,0,2.838710e+000,0.000000e+000,3.755093e+000,3.755093e+000,4.358916e-002,2.878399e-001,3.787859e+000,7.635550e-002,3.206062e-001,9.525247e-007,9.525247e-007,,,,,,,,,,,,,,,,,,,,
1524349640.059,,0.000000e+000,3.499950e+001,3.500028e+001,1,0,3.096774e+000,0.000000e+000,3.682765e+000,3.682765e+000,-5.301281e-002,2.185149e-001,3.668572e+000,-6.720539e-002,2.043223e-001,-8.218631e-007,-8.218631e-007,,,,,,,,,,,,,,,,,,,,
1524349665.339,,0.000000e+000,3.499872e+001,3.499872e+001,1,0,3.354839e+000,0.000000e+000,3.631037e+000,3.631037e+000,-1.256167e-001,1.646888e-001,3.583067e+000,-1.735867e-001,1.167188e-001,-2.115557e-006,-2.115557e-006,,,,,,,,,,,,,,,,,,,,
1524349690.657,,0.000000e+000,3.499794e+001,3.499950e+001,1,0,3.612903e+000,0.000000e+000,3.580224e+000,3.580224e+000,-1.964450e-001,1.160116e-001,3.560920e+000,-2.157488e-001,9.670782e-002,-3.356079e-006,-3.356079e-006,,,,,,,,,,,,,,,,,,,,
1524349716.030,,0.000000e+000,3.499872e+001,3.499950e+001,1,0,3.870968e+000,0.000000e+000,3.564813e+000,3.564813e+000,-2.205930e-001,1.218944e-001,3.593209e+000,-1.921966e-001,1.502907e-001,-3.507666e-006,-3.507666e-006,,,,,,,,,,,,,,,,,,,,
1524349753.581,,0.000000e+000,3.499872e+001,3.499950e+001,1,0,0.000000e+000,0.000000e+000,3.272907e+000,3.272907e+000,-1.813984e-001,-1.813984e-001,3.286087e+000,-1.682186e-001,-1.682186e-001,-7.654700e-006,-7.654700e-006,,,,,,,,,,,,,,,,,,,,
1524349779.016,,0.000000e+000,3.499872e+001,3.499872e+001,1,0,2.580645e-001,0.000000e+000,3.212482e+000,3.212482e+000,-2.653747e-001,-2.429323e-001,3.267737e+000,-2.101200e-001,-1.876776e-001,-9.158262e-006,-9.158262e-006,,,,,,,,,,,,,,,,,,,,
1524349804.189,,0.000000e+000,3.499872e+001,3.499950e+001,1,0,5.161290e-001,0.000000e+000,3.267109e+000,3.267109e+000,-2.395326e-001,-1.943014e-001,3.301270e+000,-2.053718e-001,-1.601405e-001,-8.276940e-006,-8.276940e-006,,,,,,,,,,,,,,,,,,,,
1524349829.564,,0.000000e+000,3.500419e+001,3.499872e+001,1,0,7.741935e-001,0.000000e+000,3.417105e+000,3.417105e+000,-1.162730e-001,-4.930663e-002,3.405689e+000,-1.276897e-001,-6.072330e-002,-5.200563e-006,-5.200563e-006,,,,,,,,,,,,,,,,,,,,
1524349854.985,,0.000000e+000,3.500419e+001,3.499872e+001,1,0,1.032258e+000,0.000000e+000,3.612573e+000,3.612573e+000,5.732867e-002,1.474102e-001,3.556545e+000,1.299828e-003,9.138131e-002,-1.055858e-006,-1.055858e-006,,,,,,,,,,,,,,,,,,,,
1524349880.355,,0.000000e+000,3.500028e+001,3.499950e+001,1,0,1.290323e+000,0.000000e+000,3.804074e+000,3.804074e+000,2.265310e-001,3.393278e-001,3.734718e+000,1.571751e-001,2.699718e-001,3.007430e-006,3.007430e-006,,,,,,,,,,,,,,,,,,,,
1524349905.680,,0.000000e+000,3.499950e+001,3.499950e+001,1,0,1.548387e+000,0.000000e+000,3.978637e+000,3.978637e+000,3.758874e-001,5.059772e-001,3.924494e+000,3.217437e-001,4.518335e-001,6.662071e-006,6.662071e-006,,,,,,,,,,,,,,,,,,,,
1524349931.753,,0.000000e+000,3.499950e+001,3.499872e+001,1,0,1.806452e+000,0.000000e+000,4.100709e+000,4.100709e+000,4.804482e-001,6.369832e-001,4.078839e+000,4.585781e-001,6.151130e-001,9.275973e-006,9.275973e-006,,,,,,,,,,,,,,,,,,,,
1524349956.631,,0.000000e+000,3.499872e+001,3.500028e+001,1,0,2.064516e+000,0.000000e+000,4.124514e+000,4.124514e+000,4.752451e-001,6.532462e-001,4.141728e+000,4.924594e-001,6.704605e-001,9.488183e-006,9.488183e-006,,,,,,,,,,,,,,,,,,,,
1524349982.006,,0.000000e+000,3.499794e+001,3.500028e+001,1,0,2.322581e+000,0.000000e+000,4.013275e+000,4.013275e+000,3.401019e-001,5.476573e-001,4.070754e+000,3.975803e-001,6.051357e-001,6.853690e-006,6.853690e-006,,,,,,,,,,,,,,,,,,,,
1524350007.897,,0.000000e+000,3.499872e+001,3.499872e+001,1,0,2.580645e+000,0.000000e+000,3.865110e+000,3.865110e+000,1.755692e-001,4.047258e-001,3.930361e+000,2.408201e-001,4.699767e-001,3.551992e-006,3.551992e-006,,,,,,,,,,,,,,,,,,,,
1524350032.712,,0.000000e+000,3.499872e+001,3.499950e+001,1,0,2.838710e+000,0.000000e+000,3.775235e+000,3.775235e+000,4.987770e-002,2.930603e-001,3.802317e+000,7.695966e-002,3.201423e-001,1.078151e-006,1.078151e-006,,,,,,,,,,,,,,,,,,,,
1524350058.628,,0.000000e+000,3.499950e+001,3.499872e+001,1,0,3.096774e+000,0.000000e+000,3.698482e+000,3.698482e+000,-5.041823e-002,2.215471e-001,3.681240e+000,-6.766042e-002,2.043049e-001,-7.695344e-007,-7.695344e-007,,,,,,,,,,,,,,,,,,,,
1524350083.858,,0.000000e+000,3.499794e+001,3.499872e+001,1,0,3.354839e+000,0.000000e+000,3.650721e+000,3.650721e+000,-1.272474e-001,1.663375e-001,3.600865e+000,-1.771038e-001,1.164811e-001,-2.153713e-006,-2.153713e-006,,,,,,,,,,,,,,,,,,,,
1524350109.556,,0.000000e+000,3.499794e+001,3.500028e+001,1,0,3.612903e+000,0.000000e+000,3.602808e+000,3.602808e+000,-1.940553e-001,1.176941e-001,3.579296e+000,-2.175667e-001,9.418273e-002,-3.317022e-006,-3.317022e-006,,,,,,,,,,,,,,,,,,,,
1524350134.704,,0.000000e+000,3.499950e+001,3.499872e+001,1,0,3.870968e+000,0.000000e+000,3.346456e+000,3.346456e+000,-2.246289e-001,1.003454e-001,3.378709e+000,-1.923756e-001,1.325986e-001,-3.722234e-006,-3.722234e-006,,,,,,,,,,,,,,,,,,,,
1524350147.374,,0.000000e+000,3.499715e+001,3.499950e+001,1,0,4.000000e+000,0.000000e+000,3.612573e+000,3.612573e+000,-2.132573e-001,1.372674e-001,3.657073e+000,-1.687582e-001,1.817665e-001,-3.211695e-006,-3.211695e-006,,,,,,,,,,,,,,,,,,,,