File: Experimental Raw Data/MFn1 VRM/raw/MFn1_VRMac_36K_3000s.dc.raw
[Header]
TITLE,MPMS DC Measurement
BYAPP,MPMS Measurement,2.1,Raw with ABS
FILEOPENTIME, 1524298329.737000 4/21/2018, 2:12:09 AM

INFO, APPNAME, MPMS MultiVu Application, Revision 1.61,  Build 082

INFO, NAME, MFn1
INFO, WEIGHT, 1.000
INFO, AREA, 1.000
INFO, LENGTH, 1.000
INFO, SHAPE, 0
INFO, COMMENT,
INFO, SEQUENCE FILE: VRMac_36K_3000s_VRMde_35K.seq


INFO, BACKGROUND DATA FILE:, None


STARTUPAXIS,X,8,LINEAR,AUTO,0.000000,0.000000
STARTUPAXIS,Y1,10,LINEAR,AUTO,0.000000,0.000000


STARTUPGROUP,Longitudinal
FIELDGROUP,Longitudinal,1,3,4,5,6,8,9,10,11,12,13,14,15,16,17,18,19,20,21,22,23
FIELDGROUP,Transverse,1,3,4,5,6,8,9,24,25,26,27,28,29,30,31,32,33,34,35,36,37

PLOT_APPEARANCE,ALL,HORZ_GRID_ON,VERT_GRID_ON,MARKERS_ONLY

[Data]
Time,Comment,Field (Oe),Start Temperature (K),End Temperature (K),Scan,Rejected,Position (cm),Rot Position (deg),Long Voltage,Long Average Voltage,Long Detrended Voltage,Long Demeaned Voltage,Long Regression Fit,Long Detrended Fit,Long Demeaned Fit,Long Scaled Response,Long Avg. Scaled Response,Long Background Response,Long Response [w/ABS],Long Detrended Resp. [w/ABS],Long Fit [w/ABS],Long Detrended Fit [w/ABS],Trans Voltage,Trans Average Voltage,Trans Detrended Voltage,Trans Demeaned Voltage,Trans Regression Fit,Trans Detrended Fit,Trans Demeaned Fit,Trans Scaled Response,Trans Avg Scaled Response,Trans Background Response,Trans Response [w/ABS],Trans Detrended Resp. [w/ABS],Trans Fit [w/ABS],Trans Detrended Fit [w/ABS],
1524298329.719,,0.000000e+000,3.599653e+001,3.599736e+001,1,0,0.000000e+000,0.000000e+000,5.683986e-001,5.683986e-001,8.049477e-001,8.049477e-001,6.794797e-001,9.160288e-001,9.160288e-001,1.205873e-004,1.205873e-004,,,,,,,,,,,,,,,,,,,,
1524298342.319,,0.000000e+000,3.600068e+001,3.600068e+001,1,0,1.290323e-001,0.000000e+000,7.074082e-001,7.074082e-001,9.375436e-001,9.355457e-001,8.284463e-001,1.058582e+000,1.056584e+000,1.351812e-004,1.351812e-004,,,,,,,,,,,,,,,,,,,,
1524298354.914,,0.000000e+000,3.599819e+001,3.599819e+001,1,0,2.580645e-001,0.000000e+000,8.464180e-001,8.464180e-001,1.070129e+000,1.065735e+000,9.417251e-001,1.165436e+000,1.161042e+000,1.500323e-004,1.500323e-004,,,,,,,,,,,,,,,,,,,,
1524298367.492,,0.000000e+000,3.599819e+001,3.599902e+001,1,0,3.870968e-001,0.000000e+000,9.199665e-001,9.199665e-001,1.140548e+000,1.133573e+000,9.830047e-001,1.203586e+000,1.196611e+000,1.579139e-004,1.579139e-004,,,,,,,,,,,,,,,,,,,,
1524298380.027,,0.000000e+000,3.599902e+001,3.599902e+001,1,0,5.161290e-001,0.000000e+000,9.053178e-001,9.053178e-001,1.125374e+000,1.115696e+000,9.249550e-001,1.145011e+000,1.135333e+000,1.562701e-004,1.562701e-004,,,,,,,,,,,,,,,,,,,,
1524298392.688,,0.000000e+000,3.600068e+001,3.599736e+001,1,0,6.451613e-001,0.000000e+000,7.853819e-001,7.853819e-001,1.002664e+000,9.904337e-001,7.625135e-001,9.797956e-001,9.675654e-001,1.426666e-004,1.426666e-004,,,,,,,,,,,,,,,,,,,,
1524298405.218,,0.000000e+000,3.599736e+001,3.599736e+001,1,0,7.741935e-001,0.000000e+000,5.629053e-001,5.629053e-001,7.774396e-001,7.625312e-001,5.043501e-001,7.188844e-001,7.039760e-001,1.177742e-004,1.177742e-004,,,,,,,,,,,,,,,,,,,,
1524298417.833,,0.000000e+000,3.599736e+001,3.599653e+001,1,0,9.032258e-001,0.000000e+000,2.598611e-001,2.598611e-001,4.713167e-001,4.530214e-001,1.706944e-001,3.821499e-001,3.638546e-001,8.396446e-005,8.396446e-005,,,,,,,,,,,,,,,,,,,,
1524298430.396,,0.000000e+000,3.599653e+001,3.600068e+001,1,0,1.032258e+000,0.000000e+000,-1.103227e-001,-1.103227e-001,1.037352e-001,8.430842e-002,-2.213861e-001,-7.328205e-003,-2.675499e-002,4.318722e-005,4.318722e-005,,,,,,,,,,,,,,,,,,,,
1524298443.023,,0.000000e+000,3.599736e+001,3.599653e+001,1,0,1.161290e+000,0.000000e+000,-5.114824e-001,-5.114824e-001,-3.002695e-001,-3.227559e-001,-6.459984e-001,-4.347855e-001,-4.572719e-001,-1.443266e-006,-1.443266e-006,,,,,,,,,,,,,,,,,,,,
1524298455.621,,0.000000e+000,3.599653e+001,3.599653e+001,1,0,1.290323e+000,0.000000e+000,-9.498741e-001,-9.498741e-001,-7.373431e-001,-7.634799e-001,-1.102828e+000,-8.902974e-001,-9.164342e-001,-4.974630e-005,-4.974630e-005,,,,,,,,,,,,,,,,,,,,
1524298468.149,,0.000000e+000,3.599653e+001,3.599736e+001,1,0,1.419355e+000,0.000000e+000,-1.415427e+000,-1.415427e+000,-1.202756e+000,-1.230897e+000,-1.577458e+000,-1.364787e+000,-1.392928e+000,-1.012330e-004,-1.012330e-004,,,,,,,,,,,,,,,,,,,,
1524298480.729,,0.000000e+000,3.599902e+001,3.599984e+001,1,0,1.548387e+000,0.000000e+000,-1.889067e+000,-1.889067e+000,-1.672929e+000,-1.703019e+000,-2.053970e+000,-1.837832e+000,-1.867922e+000,-1.532500e-004,-1.532500e-004,,,,,,,,,,,,,,,,,,,,
1524298493.294,,0.000000e+000,3.599902e+001,3.599653e+001,1,0,1.677419e+000,0.000000e+000,-2.348211e+000,-2.348211e+000,-2.131193e+000,-2.164018e+000,-2.487900e+000,-2.270882e+000,-2.303707e+000,-2.039679e-004,-2.039679e-004,,,,,,,,,,,,,,,,,,,,
1524298507.119,,0.000000e+000,3.599653e+001,3.599736e+001,1,0,1.806452e+000,0.000000e+000,-2.745556e+000,-2.745556e+000,-2.525551e+000,-2.560958e+000,-2.836674e+000,-2.616670e+000,-2.652076e+000,-2.475845e-004,-2.475845e-004,,,,,,,,,,,,,,,,,,,,
1524298519.189,,0.000000e+000,3.599819e+001,3.599902e+001,1,0,1.935484e+000,0.000000e+000,-3.001144e+000,-3.001144e+000,-2.781291e+000,-2.819465e+000,-3.028766e+000,-2.808913e+000,-2.847086e+000,-2.759546e-004,-2.759546e-004,,,,,,,,,,,,,,,,,,,,
1524298532.285,,0.000000e+000,3.599736e+001,3.599736e+001,1,0,2.064516e+000,0.000000e+000,-3.074998e+000,-3.074998e+000,-2.851072e+000,-2.892979e+000,-3.037798e+000,-2.813872e+000,-2.855779e+000,-2.837893e-004,-2.837893e-004,,,,,,,,,,,,,,,,,,,,
1524298544.865,,0.000000e+000,3.599902e+001,3.599736e+001,1,0,2.193548e+000,0.000000e+000,-2.949264e+000,-2.949264e+000,-2.722541e+000,-2.767229e+000,-2.855091e+000,-2.628368e+000,-2.673056e+000,-2.697504e-004,-2.697504e-004,,,,,,,,,,,,,,,,,,,,
1524298557.427,,0.000000e+000,3.599819e+001,3.599653e+001,1,0,2.322581e+000,0.000000e+000,-2.651713e+000,-2.651713e+000,-2.422199e+000,-2.470188e+000,-2.518564e+000,-2.289050e+000,-2.337039e+000,-2.367843e-004,-2.367843e-004,,,,,,,,,,,,,,,,,,,,
1524298570.035,,0.000000e+000,3.599653e+001,3.599902e+001,1,0,2.451613e+000,0.000000e+000,-2.242771e+000,-2.242771e+000,-2.009654e+000,-2.057187e+000,-2.091434e+000,-1.858317e+000,-1.905850e+000,-1.913494e-004,-1.913494e-004,,,,,,,,,,,,,,,,,,,,
1524298582.120,,0.000000e+000,3.599819e+001,3.599819e+001,1,0,2.580645e+000,0.000000e+000,-1.776608e+000,-1.776608e+000,-1.541376e+000,-1.592397e+000,-1.618949e+000,-1.383717e+000,-1.434738e+000,-1.398603e-004,-1.398603e-004,,,,,,,,,,,,,,,,,,,,
1524298595.258,,0.000000e+000,3.599819e+001,3.599984e+001,1,0,2.709677e+000,0.000000e+000,-1.297169e+000,-1.297169e+000,-1.058652e+000,-1.112775e+000,-1.144726e+000,-9.062080e-001,-9.603307e-001,-8.675131e-005,-8.675131e-005,,,,,,,,,,,,,,,,,,,,
1524298607.798,,0.000000e+000,3.599736e+001,3.599902e+001,1,0,2.838710e+000,0.000000e+000,-8.244449e-001,-8.244449e-001,-5.835649e-001,-6.408094e-001,-6.846915e-001,-4.438115e-001,-5.010560e-001,-3.450569e-005,-3.450569e-005,,,,,,,,,,,,,,,,,,,,
1524298620.386,,0.000000e+000,3.600068e+001,3.599736e+001,1,0,2.967742e+000,0.000000e+000,-3.776608e-001,-3.776608e-001,-1.328774e-001,-1.931318e-001,-2.522953e-001,-7.511886e-003,-6.776629e-002,1.505823e-005,1.505823e-005,,,,,,,,,,,,,,,,,,,,
1524298632.851,,0.000000e+000,3.599405e+001,3.599819e+001,1,0,3.096774e+000,0.000000e+000,4.318303e-002,4.318303e-002,2.907456e-001,2.281063e-001,1.453609e-001,3.929234e-001,3.302842e-001,6.163069e-005,6.163069e-005,,,,,,,,,,,,,,,,,,,,
1524298645.359,,0.000000e+000,3.599653e+001,3.599902e+001,1,0,3.225806e+000,0.000000e+000,4.310674e-001,4.310674e-001,6.809288e-001,6.188525e-001,4.919523e-001,7.418137e-001,6.797374e-001,1.046197e-004,1.046197e-004,,,,,,,,,,,,,,,,,,,,
1524298657.839,,0.000000e+000,3.599653e+001,3.599819e+001,1,0,3.354839e+000,0.000000e+000,7.444877e-001,7.444877e-001,9.978591e-001,9.308856e-001,7.623426e-001,1.015714e+000,9.487404e-001,1.393632e-004,1.393632e-004,,,,,,,,,,,,,,,,,,,,
1524298670.392,,0.000000e+000,3.600483e+001,3.599902e+001,1,0,3.483871e+000,0.000000e+000,9.662012e-001,9.662012e-001,1.220846e+000,1.153711e+000,9.369442e-001,1.191589e+000,1.124454e+000,1.638766e-004,1.638766e-004,,,,,,,,,,,,,,,,,,,,
1524298682.987,,0.000000e+000,3.599239e+001,3.599819e+001,1,0,3.612903e+000,0.000000e+000,1.068589e+000,1.068589e+000,1.329908e+000,1.251457e+000,9.973542e-001,1.258673e+000,1.180222e+000,1.754629e-004,1.754629e-004,,,,,,,,,,,,,,,,,,,,
1524298695.549,,0.000000e+000,3.599487e+001,3.599736e+001,1,0,3.741935e+000,0.000000e+000,1.065537e+000,1.065537e+000,1.328488e+000,1.251195e+000,9.631610e-001,1.226111e+000,1.148819e+000,1.752599e-004,1.752599e-004,,,,,,,,,,,,,,,,,,,,
1524298708.147,,0.000000e+000,3.599239e+001,3.599736e+001,1,0,3.870968e+000,0.000000e+000,9.665064e-001,9.665064e-001,1.235228e+000,1.151266e+000,8.527921e-001,1.121514e+000,1.037552e+000,1.646700e-004,1.646700e-004,,,,,,,,,,,,,,,,,,,,
1524298720.712,,0.000000e+000,3.599321e+001,3.599902e+001,1,0,4.000000e+000,0.000000e+000,8.210880e-001,8.210880e-001,1.092559e+000,1.009931e+000,7.059011e-001,9.773722e-001,8.947440e-001,1.488998e-004,1.488998e-004,,,,,,,,,,,,,,,,,,,,
1524298746.205,,0.000000e+000,3.600150e+001,3.599736e+001,1,0,0.000000e+000,0.000000e+000,6.749066e-001,6.749066e-001,8.647987e-001,8.647987e-001,7.887298e-001,9.786220e-001,9.786220e-001,1.297660e-004,1.297660e-004,,,,,,,,,,,,,,,,,,,,
1524298758.718,,0.000000e+000,3.599819e+001,3.599984e+001,1,0,1.290323e-001,0.000000e+000,8.082704e-001,8.082704e-001,1.002092e+000,9.996384e-001,9.319139e-001,1.125735e+000,1.123282e+000,1.446668e-004,1.446668e-004,,,,,,,,,,,,,,,,,,,,
1524298771.228,,0.000000e+000,3.599902e+001,3.599819e+001,1,0,2.580645e-001,0.000000e+000,9.407187e-001,9.407187e-001,1.135984e+000,1.130767e+000,1.037829e+000,1.233094e+000,1.227877e+000,1.594358e-004,1.594358e-004,,,,,,,,,,,,,,,,,,,,
1524298783.791,,0.000000e+000,3.599736e+001,3.599902e+001,1,0,3.870968e-001,0.000000e+000,1.004807e+000,1.004807e+000,1.205755e+000,1.198302e+000,1.065703e+000,1.266651e+000,1.259198e+000,1.668236e-004,1.668236e-004,,,,,,,,,,,,,,,,,,,,
1524298796.408,,0.000000e+000,3.599819e+001,3.599819e+001,1,0,5.161290e-001,0.000000e+000,9.825284e-001,9.825284e-001,1.184133e+000,1.173175e+000,1.000555e+000,1.202160e+000,1.191201e+000,1.645242e-004,1.645242e-004,,,,,,,,,,,,,,,,,,,,
1524298808.969,,0.000000e+000,3.599902e+001,3.599819e+001,1,0,6.451613e-001,0.000000e+000,8.419929e-001,8.419929e-001,1.047900e+000,1.034557e+000,8.195167e-001,1.025423e+000,1.012081e+000,1.492335e-004,1.492335e-004,,,,,,,,,,,,,,,,,,,,
1524298821.564,,0.000000e+000,3.599736e+001,3.599984e+001,1,0,7.741935e-001,0.000000e+000,5.958648e-001,5.958648e-001,8.064050e-001,7.910321e-001,5.399328e-001,7.504730e-001,7.351001e-001,1.223538e-004,1.223538e-004,,,,,,,,,,,,,,,,,,,,
1524298834.141,,0.000000e+000,3.599736e+001,3.599819e+001,1,0,9.032258e-001,0.000000e+000,2.763409e-001,2.763409e-001,4.885931e-001,4.697791e-001,1.860518e-001,3.983040e-001,3.794900e-001,8.719901e-005,8.719901e-005,,,,,,,,,,,,,,,,,,,,
1524298846.689,,0.000000e+000,3.599736e+001,3.599984e+001,1,0,1.032258e+000,0.000000e+000,-1.132219e-001,-1.132219e-001,1.023102e-001,8.143830e-002,-2.231561e-001,-7.623909e-003,-2.849582e-002,4.435639e-005,4.435639e-005,,,,,,,,,,,,,,,,,,,,
1524298859.319,,0.000000e+000,3.599902e+001,3.599902e+001,1,0,1.161290e+000,0.000000e+000,-5.328450e-001,-5.328450e-001,-3.150394e-001,-3.375505e-001,-6.688980e-001,-4.510924e-001,-4.736035e-001,-1.927961e-006,-1.927961e-006,,,,,,,,,,,,,,,,,,,,
1524298871.937,,0.000000e+000,3.599819e+001,3.599902e+001,1,0,1.290323e+000,0.000000e+000,-9.875639e-001,-9.875639e-001,-7.686279e-001,-7.945926e-001,-1.142055e+000,-9.231194e-001,-9.490840e-001,-5.207879e-005,-5.207879e-005,,,,,,,,,,,,,,,,,,,,
1524298884.497,,0.000000e+000,3.599653e+001,3.599902e+001,1,0,1.419355e+000,0.000000e+000,-1.470665e+000,-1.470665e+000,-1.248241e+000,-1.277223e+000,-1.634821e+000,-1.412397e+000,-1.441379e+000,-1.051578e-004,-1.051578e-004,,,,,,,,,,,,,,,,,,,,
1524298897.245,,0.000000e+000,3.599819e+001,3.599819e+001,1,0,1.548387e+000,0.000000e+000,-1.961242e+000,-1.961242e+000,-1.735990e+000,-1.769915e+000,-2.124949e+000,-1.899697e+000,-1.933622e+000,-1.590926e-004,-1.590926e-004,,,,,,,,,,,,,,,,,,,,
1524298909.678,,0.000000e+000,3.599736e+001,3.599819e+001,1,0,1.677419e+000,0.000000e+000,-2.441596e+000,-2.441596e+000,-2.207011e+000,-2.241125e+000,-2.580824e+000,-2.346239e+000,-2.380353e+000,-2.112958e-004,-2.112958e-004,,,,,,,,,,,,,,,,,,,,
1524298922.263,,0.000000e+000,3.599653e+001,3.599902e+001,1,0,1.806452e+000,0.000000e+000,-2.847944e+000,-2.847944e+000,-2.610334e+000,-2.646299e+000,-2.936529e+000,-2.698919e+000,-2.734884e+000,-2.559666e-004,-2.559666e-004,,,,,,,,,,,,,,,,,,,,
1524298934.385,,0.000000e+000,3.599984e+001,3.599902e+001,1,0,1.935484e+000,0.000000e+000,-3.107347e+000,-3.107347e+000,-2.868460e+000,-2.905745e+000,-3.134183e+000,-2.895295e+000,-2.932580e+000,-2.846266e-004,-2.846266e-004,,,,,,,,,,,,,,,,,,,,
1524298946.971,,0.000000e+000,3.599653e+001,3.599819e+001,1,0,2.064516e+000,0.000000e+000,-3.177844e+000,-3.177844e+000,-2.936403e+000,-2.979146e+000,-3.138863e+000,-2.897422e+000,-2.940165e+000,-2.922893e-004,-2.922893e-004,,,,,,,,,,,,,,,,,,,,
1524298959.531,,0.000000e+000,3.599736e+001,3.599819e+001,1,0,2.193548e+000,0.000000e+000,-3.039445e+000,-3.039445e+000,-2.795011e+000,-2.838709e+000,-2.946917e+000,-2.702484e+000,-2.746182e+000,-2.768678e-004,-2.768678e-004,,,,,,,,,,,,,,,,,,,,
1524298972.146,,0.000000e+000,3.599819e+001,3.599902e+001,1,0,2.322581e+000,0.000000e+000,-2.734569e+000,-2.734569e+000,-2.486443e+000,-2.534363e+000,-2.601518e+000,-2.353391e+000,-2.401311e+000,-2.430018e-004,-2.430018e-004,,,,,,,,,,,,,,,,,,,,
1524298984.726,,0.000000e+000,3.599736e+001,3.599819e+001,1,0,2.451613e+000,0.000000e+000,-2.308690e+000,-2.308690e+000,-2.055882e+000,-2.106753e+000,-2.159920e+000,-1.907112e+000,-1.957983e+000,-1.956804e-004,-1.956804e-004,,,,,,,,,,,,,,,,,,,,
1524298997.304,,0.000000e+000,3.599736e+001,3.599902e+001,1,0,2.580645e+000,0.000000e+000,-1.829557e+000,-1.829557e+000,-1.575146e+000,-1.626382e+000,-1.674007e+000,-1.419596e+000,-1.470833e+000,-1.427848e-004,-1.427848e-004,,,,,,,,,,,,,,,,,,,,
1524299009.892,,0.000000e+000,3.599736e+001,3.599902e+001,1,0,2.709677e+000,0.000000e+000,-1.339132e+000,-1.339132e+000,-1.079674e+000,-1.133722e+000,-1.188718e+000,-9.292596e-001,-9.833078e-001,-8.827830e-005,-8.827830e-005,,,,,,,,,,,,,,,,,,,,
1524299022.504,,0.000000e+000,3.599819e+001,3.599736e+001,1,0,2.838710e+000,0.000000e+000,-8.552682e-001,-8.552682e-001,-5.938407e-001,-6.503628e-001,-7.160883e-001,-4.546607e-001,-5.111830e-001,-3.486287e-005,-3.486287e-005,,,,,,,,,,,,,,,,,,,,
1524299035.102,,0.000000e+000,3.599819e+001,3.599902e+001,1,0,2.967742e+000,0.000000e+000,-3.974975e-001,-3.974975e-001,-1.317634e-001,-1.933976e-001,-2.734230e-001,-7.688876e-003,-6.932305e-002,1.588234e-005,1.588234e-005,,,,,,,,,,,,,,,,,,,,
1524299047.640,,0.000000e+000,3.599736e+001,3.599819e+001,1,0,3.096774e+000,0.000000e+000,3.463798e-002,3.463798e-002,3.042834e-001,2.429027e-001,1.325887e-001,4.022340e-001,3.408533e-001,6.389608e-005,6.389608e-005,,,,,,,,,,,,,,,,,,,,
1524299060.710,,0.000000e+000,3.599736e+001,3.599902e+001,1,0,3.225806e+000,0.000000e+000,4.240482e-001,4.240482e-001,6.972170e-001,6.312274e-001,4.856058e-001,7.587746e-001,6.927849e-001,1.070214e-004,1.070214e-004,,,,,,,,,,,,,,,,,,,,
1524299072.968,,0.000000e+000,3.599736e+001,3.599902e+001,1,0,3.354839e+000,0.000000e+000,7.441825e-001,7.441825e-001,1.020704e+000,9.513538e-001,7.620915e-001,1.038613e+000,9.692628e-001,1.425179e-004,1.425179e-004,,,,,,,,,,,,,,,,,,,,
1524299085.398,,0.000000e+000,3.599736e+001,3.599902e+001,1,0,3.483871e+000,0.000000e+000,9.689479e-001,9.689479e-001,1.246427e+000,1.178213e+000,9.400402e-001,1.217519e+000,1.149306e+000,1.673459e-004,1.673459e-004,,,,,,,,,,,,,,,,,,,,
1524299097.725,,0.000000e+000,3.599819e+001,3.599819e+001,1,0,3.612903e+000,0.000000e+000,1.076066e+000,1.076066e+000,1.357857e+000,1.285359e+000,1.004218e+000,1.286010e+000,1.213511e+000,1.794221e-004,1.794221e-004,,,,,,,,,,,,,,,,,,,,
1524299109.911,,0.000000e+000,3.599736e+001,3.599984e+001,1,0,3.741935e+000,0.000000e+000,1.066148e+000,1.066148e+000,1.350670e+000,1.278391e+000,9.679359e-001,1.252459e+000,1.180179e+000,1.785523e-004,1.785523e-004,,,,,,,,,,,,,,,,,,,,
1524299122.533,,0.000000e+000,3.599819e+001,3.599819e+001,1,0,3.870968e+000,0.000000e+000,9.694057e-001,9.694057e-001,1.256772e+000,1.180990e+000,8.573960e-001,1.144762e+000,1.068980e+000,1.679880e-004,1.679880e-004,,,,,,,,,,,,,,,,,,,,
1524299135.221,,0.000000e+000,3.599819e+001,3.599984e+001,1,0,4.000000e+000,0.000000e+000,8.184940e-001,8.184940e-001,1.109945e+000,1.030335e+000,7.059450e-001,9.973961e-001,9.177858e-001,1.515722e-004,1.515722e-004,,,,,,,,,,,,,,,,,,,,
1524299160.394,,0.000000e+000,3.599653e+001,3.599819e+001,1,0,0.000000e+000,0.000000e+000,6.697184e-001,6.697184e-001,8.843157e-001,8.843157e-001,7.833218e-001,9.979191e-001,9.979191e-001,1.324799e-004,1.324799e-004,,,,,,,,,,,,,,,,,,,,
1524299172.981,,0.000000e+000,3.599819e+001,3.599819e+001,1,0,1.290323e-001,0.000000e+000,8.061341e-001,8.061341e-001,1.022932e+000,1.020408e+000,9.292768e-001,1.146075e+000,1.143550e+000,1.476113e-004,1.476113e-004,,,,,,,,,,,,,,,,,,,,
1524299185.559,,0.000000e+000,3.599819e+001,3.599902e+001,1,0,2.580645e-001,0.000000e+000,9.369040e-001,9.369040e-001,1.156985e+000,1.151923e+000,1.035064e+000,1.255145e+000,1.250082e+000,1.622395e-004,1.622395e-004,,,,,,,,,,,,,,,,,,,,
1524299198.137,,0.000000e+000,3.599653e+001,3.599902e+001,1,0,3.870968e-001,0.000000e+000,1.007706e+000,1.007706e+000,1.230647e+000,1.223062e+000,1.067227e+000,1.290168e+000,1.282583e+000,1.701953e-004,1.701953e-004,,,,,,,,,,,,,,,,,,,,
1524299210.717,,0.000000e+000,3.599902e+001,3.599902e+001,1,0,5.161290e-001,0.000000e+000,9.793240e-001,9.793240e-001,1.205767e+000,1.195950e+000,9.970410e-001,1.223484e+000,1.213667e+000,1.672292e-004,1.672292e-004,,,,,,,,,,,,,,,,,,,,
1524299223.310,,0.000000e+000,3.599902e+001,3.599902e+001,1,0,6.451613e-001,0.000000e+000,8.371099e-001,8.371099e-001,1.066207e+000,1.053634e+000,8.146231e-001,1.043720e+000,1.031147e+000,1.516978e-004,1.516978e-004,,,,,,,,,,,,,,,,,,,,
1524299235.880,,0.000000e+000,3.599902e+001,3.599819e+001,1,0,7.741935e-001,0.000000e+000,5.876249e-001,5.876249e-001,8.195999e-001,8.057485e-001,5.311101e-001,7.630850e-001,7.492337e-001,1.241633e-004,1.241633e-004,,,,,,,,,,,,,,,,,,,,
1524299248.455,,0.000000e+000,3.599736e+001,3.599819e+001,1,0,9.032258e-001,0.000000e+000,2.551309e-001,2.551309e-001,4.900147e-001,4.720207e-001,1.699282e-001,4.048120e-001,3.868181e-001,8.779910e-005,8.779910e-005,,,,,,,,,,,,,,,,,,,,
1524299261.058,,0.000000e+000,3.599653e+001,3.599819e+001,1,0,1.032258e+000,0.000000e+000,-1.347372e-001,-1.347372e-001,1.040063e-001,8.508229e-002,-2.464923e-001,-7.748852e-003,-2.667288e-002,4.492757e-005,4.492757e-005,,,,,,,,,,,,,,,,,,,,
1524299273.665,,0.000000e+000,3.599819e+001,3.599902e+001,1,0,1.161290e+000,0.000000e+000,-5.703822e-001,-5.703822e-001,-3.282647e-001,-3.502660e-001,-7.007096e-001,-4.585921e-001,-4.805934e-001,-2.888235e-006,-2.888235e-006,,,,,,,,,,,,,,,,,,,,
1524299286.261,,0.000000e+000,3.599819e+001,3.599902e+001,1,0,1.290323e+000,0.000000e+000,-1.026474e+000,-1.026474e+000,-7.849774e-001,-8.097774e-001,-1.178922e+000,-9.374247e-001,-9.622247e-001,-5.343889e-005,-5.343889e-005,,,,,,,,,,,,,,,,,,,,
1524299298.811,,0.000000e+000,3.599736e+001,3.599984e+001,1,0,1.419355e+000,0.000000e+000,-1.520714e+000,-1.520714e+000,-1.274069e+000,-1.301202e+000,-1.681341e+000,-1.434695e+000,-1.461829e+000,-1.075628e-004,-1.075628e-004,,,,,,,,,,,,,,,,,,,,
1524299311.438,,0.000000e+000,3.599487e+001,3.599819e+001,1,0,1.548387e+000,0.000000e+000,-2.020142e+000,-2.020142e+000,-1.769985e+000,-1.799767e+000,-2.179149e+000,-1.928993e+000,-1.958774e+000,-1.624431e-004,-1.624431e-004,,,,,,,,,,,,,,,,,,,,
1524299323.999,,0.000000e+000,3.599819e+001,3.599902e+001,1,0,1.677419e+000,0.000000e+000,-2.498512e+000,-2.498512e+000,-2.246412e+000,-2.279431e+000,-2.634800e+000,-2.382700e+000,-2.415718e+000,-2.151656e-004,-2.151656e-004,,,,,,,,,,,,,,,,,,,,
1524299336.596,,0.000000e+000,3.599902e+001,3.599984e+001,1,0,1.806452e+000,0.000000e+000,-2.908522e+000,-2.908522e+000,-2.652895e+000,-2.688347e+000,-2.994612e+000,-2.738984e+000,-2.774436e+000,-2.601951e-004,-2.601951e-004,,,,,,,,,,,,,,,,,,,,
1524299349.184,,0.000000e+000,3.599653e+001,3.599819e+001,1,0,1.935484e+000,0.000000e+000,-3.169757e+000,-3.169757e+000,-2.910667e+000,-2.947446e+000,-3.196961e+000,-2.937871e+000,-2.974650e+000,-2.888175e-004,-2.888175e-004,,,,,,,,,,,,,,,,,,,,
1524299361.762,,0.000000e+000,3.599819e+001,3.599902e+001,1,0,2.064516e+000,0.000000e+000,-3.242237e+000,-3.242237e+000,-2.978482e+000,-3.017945e+000,-3.203036e+000,-2.939281e+000,-2.978743e+000,-2.964652e-004,-2.964652e-004,,,,,,,,,,,,,,,,,,,,
1524299374.372,,0.000000e+000,3.599902e+001,3.599902e+001,1,0,2.193548e+000,0.000000e+000,-3.100633e+000,-3.100633e+000,-2.835393e+000,-2.877153e+000,-3.007823e+000,-2.742583e+000,-2.784343e+000,-2.808388e-004,-2.808388e-004,,,,,,,,,,,,,,,,,,,,
1524299386.935,,0.000000e+000,3.599819e+001,3.599902e+001,1,0,2.322581e+000,0.000000e+000,-2.782483e+000,-2.782483e+000,-2.514038e+000,-2.557461e+000,-2.655257e+000,-2.386812e+000,-2.430235e+000,-2.455485e-004,-2.455485e-004,,,,,,,,,,,,,,,,,,,,
1524299399.545,,0.000000e+000,3.599984e+001,3.599902e+001,1,0,2.451613e+000,0.000000e+000,-2.347600e+000,-2.347600e+000,-2.076348e+000,-2.123115e+000,-2.204976e+000,-1.933723e+000,-1.980491e+000,-1.974386e-004,-1.974386e-004,,,,,,,,,,,,,,,,,,,,
1524299412.092,,0.000000e+000,3.599902e+001,3.599819e+001,1,0,2.580645e+000,0.000000e+000,-1.862364e+000,-1.862364e+000,-1.586912e+000,-1.634975e+000,-1.714805e+000,-1.439353e+000,-1.487416e+000,-1.435870e-004,-1.435870e-004,,,,,,,,,,,,,,,,,,,,
1524299424.670,,0.000000e+000,3.599984e+001,3.599819e+001,1,0,2.709677e+000,0.000000e+000,-1.366751e+000,-1.366751e+000,-1.090464e+000,-1.139817e+000,-1.217889e+000,-9.416029e-001,-9.909561e-001,-8.895488e-005,-8.895488e-005,,,,,,,,,,,,,,,,,,,,
1524299437.253,,0.000000e+000,3.599487e+001,3.599902e+001,1,0,2.838710e+000,0.000000e+000,-8.792248e-001,-8.792248e-001,-5.976445e-001,-6.540425e-001,-7.429480e-001,-4.613677e-001,-5.177656e-001,-3.480951e-005,-3.480951e-005,,,,,,,,,,,,,,,,,,,,
1524299449.850,,0.000000e+000,3.599984e+001,3.599902e+001,1,0,2.967742e+000,0.000000e+000,-4.167239e-001,-4.167239e-001,-1.311828e-001,-1.906003e-001,-2.933371e-001,-7.795997e-003,-6.721354e-002,1.644396e-005,1.644396e-005,,,,,,,,,,,,,,,,,,,,
1524299462.448,,0.000000e+000,3.599902e+001,3.599736e+001,1,0,3.096774e+000,0.000000e+000,1.739528e-002,1.739528e-002,3.093842e-001,2.490238e-001,1.155122e-001,4.075011e-001,3.471406e-001,6.490345e-005,6.490345e-005,,,,,,,,,,,,,,,,,,,,
1524299475.028,,0.000000e+000,3.599653e+001,3.599984e+001,1,0,3.225806e+000,0.000000e+000,4.176394e-001,4.176394e-001,7.105436e-001,6.509410e-001,4.756102e-001,7.685143e-001,7.089118e-001,1.090803e-004,1.090803e-004,,,,,,,,,,,,,,,,,,,,
1524299487.621,,0.000000e+000,3.599902e+001,3.599819e+001,1,0,3.354839e+000,0.000000e+000,7.389944e-001,7.389944e-001,1.033932e+000,9.720917e-001,7.560182e-001,1.050956e+000,9.891154e-001,1.445802e-004,1.445802e-004,,,,,,,,,,,,,,,,,,,,
1524299500.061,,0.000000e+000,3.599819e+001,3.599819e+001,1,0,3.483871e+000,0.000000e+000,9.629969e-001,9.629969e-001,1.262521e+000,1.194281e+000,9.330321e-001,1.232556e+000,1.164316e+000,1.695155e-004,1.695155e-004,,,,,,,,,,,,,,,,,,,,
1524299512.784,,0.000000e+000,3.599819e+001,3.599819e+001,1,0,3.612903e+000,0.000000e+000,1.067979e+000,1.067979e+000,1.370565e+000,1.302488e+000,9.990783e-001,1.301664e+000,1.233588e+000,1.813588e-004,1.813588e-004,,,,,,,,,,,,,,,,,,,,
1524299525.374,,0.000000e+000,3.599653e+001,3.599819e+001,1,0,3.741935e+000,0.000000e+000,1.054246e+000,1.054246e+000,1.361928e+000,1.290523e+000,9.595359e-001,1.267218e+000,1.195813e+000,1.802013e-004,1.802013e-004,,,,,,,,,,,,,,,,,,,,
1524299537.974,,0.000000e+000,3.599653e+001,3.599902e+001,1,0,3.870968e+000,0.000000e+000,9.547570e-001,9.547570e-001,1.265316e+000,1.194913e+000,8.479718e-001,1.158531e+000,1.088128e+000,1.695070e-004,1.695070e-004,,,,,,,,,,,,,,,,,,,,
1524299550.534,,0.000000e+000,3.599902e+001,3.599902e+001,1,0,4.000000e+000,0.000000e+000,8.032349e-001,8.032349e-001,1.116268e+000,1.041779e+000,6.957290e-001,1.008762e+000,9.342735e-001,1.528233e-004,1.528233e-004,,,,,,,,,,,,,,,,,,,,
1524299575.682,,0.000000e+000,3.599984e+001,3.599819e+001,1,0,0.000000e+000,0.000000e+000,6.562905e-001,6.562905e-001,8.985180e-001,8.985180e-001,7.677050e-001,1.009933e+000,1.009933e+000,1.342403e-004,1.342403e-004,,,,,,,,,,,,,,,,,,,,
1524299588.278,,0.000000e+000,3.599819e+001,3.599819e+001,1,0,1.290323e-001,0.000000e+000,7.945372e-001,7.945372e-001,1.041690e+000,1.039387e+000,9.122577e-001,1.159410e+000,1.157107e+000,1.498172e-004,1.498172e-004,,,,,,,,,,,,,,,,,,,,
1524299600.785,,0.000000e+000,3.599819e+001,3.599819e+001,1,0,2.580645e-001,0.000000e+000,9.282063e-001,9.282063e-001,1.177577e+000,1.172813e+000,1.020484e+000,1.269854e+000,1.265090e+000,1.647390e-004,1.647390e-004,,,,,,,,,,,,,,,,,,,,
1524299613.503,,0.000000e+000,3.599819e+001,3.599984e+001,1,0,3.870968e-001,0.000000e+000,9.947357e-001,9.947357e-001,1.247500e+000,1.240735e+000,1.052165e+000,1.304928e+000,1.298164e+000,1.721703e-004,1.721703e-004,,,,,,,,,,,,,,,,,,,,
1524299626.053,,0.000000e+000,3.599819e+001,3.599902e+001,1,0,5.161290e-001,0.000000e+000,9.658961e-001,9.658961e-001,1.219312e+000,1.209869e+000,9.834685e-001,1.236884e+000,1.227442e+000,1.689965e-004,1.689965e-004,,,,,,,,,,,,,,,,,,,,
1524299638.601,,0.000000e+000,3.599819e+001,3.599902e+001,1,0,6.451613e-001,0.000000e+000,8.210880e-001,8.210880e-001,1.077525e+000,1.065656e+000,7.988486e-001,1.055286e+000,1.043416e+000,1.531937e-004,1.531937e-004,,,,,,,,,,,,,,,,,,,,
1524299651.218,,0.000000e+000,3.599902e+001,3.599570e+001,1,0,7.741935e-001,0.000000e+000,5.679408e-001,5.679408e-001,8.277392e-001,8.133547e-001,5.121489e-001,7.719473e-001,7.575628e-001,1.254965e-004,1.254965e-004,,,,,,,,,,,,,,,,,,,,
1524299663.546,,0.000000e+000,3.599902e+001,3.599819e+001,1,0,9.032258e-001,0.000000e+000,2.317845e-001,2.317845e-001,4.930548e-001,4.764802e-001,1.481284e-001,4.093987e-001,3.928241e-001,8.837174e-005,8.837174e-005,,,,,,,,,,,,,,,,,,,,
1524299676.136,,0.000000e+000,3.599321e+001,3.599819e+001,1,0,1.032258e+000,0.000000e+000,-1.655604e-001,-1.655604e-001,9.808266e-002,7.922776e-002,-2.714765e-001,-7.833419e-003,-2.668832e-002,4.462009e-005,4.462009e-005,,,,,,,,,,,,,,,,,,,,
1524299688.827,,0.000000e+000,3.599819e+001,3.599984e+001,1,0,1.161290e+000,0.000000e+000,-6.002899e-001,-6.002899e-001,-3.339016e-001,-3.549035e-001,-7.299806e-001,-4.635923e-001,-4.845941e-001,-3.212612e-006,-3.212612e-006,,,,,,,,,,,,,,,,,,,,
1524299701.304,,0.000000e+000,3.599902e+001,3.599984e+001,1,0,1.290323e+000,0.000000e+000,-1.069200e+000,-1.069200e+000,-7.995706e-001,-8.224881e-001,-1.217487e+000,-9.478581e-001,-9.707756e-001,-5.476715e-005,-5.476715e-005,,,,,,,,,,,,,,,,,,,,
1524299713.887,,0.000000e+000,3.599239e+001,3.599819e+001,1,0,1.419355e+000,0.000000e+000,-1.565728e+000,-1.565728e+000,-1.292828e+000,-1.318932e+000,-1.722401e+000,-1.449501e+000,-1.475605e+000,-1.093314e-004,-1.093314e-004,,,,,,,,,,,,,,,,,,,,
1524299726.560,,0.000000e+000,3.599819e+001,3.599984e+001,1,0,1.548387e+000,0.000000e+000,-2.069123e+000,-2.069123e+000,-1.792803e+000,-1.821386e+000,-2.225182e+000,-1.948862e+000,-1.977444e+000,-1.646547e-004,-1.646547e-004,,,,,,,,,,,,,,,,,,,,
1524299739.047,,0.000000e+000,3.599984e+001,3.599902e+001,1,0,1.677419e+000,0.000000e+000,-2.555886e+000,-2.555886e+000,-2.276333e+000,-2.306731e+000,-2.687789e+000,-2.408236e+000,-2.438634e+000,-2.181585e-004,-2.181585e-004,,,,,,,,,,,,,,,,,,,,
1524299751.632,,0.000000e+000,3.599736e+001,3.599902e+001,1,0,1.806452e+000,0.000000e+000,-2.969406e+000,-2.969406e+000,-2.685568e+000,-2.717052e+000,-3.052115e+000,-2.768277e+000,-2.799761e+000,-2.634867e-004,-2.634867e-004,,,,,,,,,,,,,,,,,,,,
1524299764.238,,0.000000e+000,3.599487e+001,3.599819e+001,1,0,1.935484e+000,0.000000e+000,-3.229267e+000,-3.229267e+000,-2.944054e+000,-2.978672e+000,-3.253185e+000,-2.967972e+000,-3.002590e+000,-2.921762e-004,-2.921762e-004,,,,,,,,,,,,,,,,,,,,
1524299776.803,,0.000000e+000,3.599819e+001,3.599984e+001,1,0,2.064516e+000,0.000000e+000,-3.293507e+000,-3.293507e+000,-3.004975e+000,-3.041719e+000,-3.257588e+000,-2.969055e+000,-3.005800e+000,-2.990552e-004,-2.990552e-004,,,,,,,,,,,,,,,,,,,,
1524299789.403,,0.000000e+000,3.599984e+001,3.599819e+001,1,0,2.193548e+000,0.000000e+000,-3.150988e+000,-3.150988e+000,-2.859305e+000,-2.898460e+000,-3.060706e+000,-2.769022e+000,-2.808178e+000,-2.831491e-004,-2.831491e-004,,,,,,,,,,,,,,,,,,,,
1524299801.986,,0.000000e+000,3.599073e+001,3.599819e+001,1,0,2.322581e+000,0.000000e+000,-2.827192e+000,-2.827192e+000,-2.532815e+000,-2.570971e+000,-2.704545e+000,-2.410168e+000,-2.448326e+000,-2.472506e-004,-2.472506e-004,,,,,,,,,,,,,,,,,,,,
1524299814.656,,0.000000e+000,3.600400e+001,3.599819e+001,1,0,2.451613e+000,0.000000e+000,-2.388800e+000,-2.388800e+000,-2.090612e+000,-2.135139e+000,-2.250971e+000,-1.952783e+000,-1.997311e+000,-1.986638e-004,-1.986638e-004,,,,,,,,,,,,,,,,,,,,
1524299827.166,,0.000000e+000,3.599819e+001,3.599984e+001,1,0,2.580645e+000,0.000000e+000,-1.896391e+000,-1.896391e+000,-1.594966e+000,-1.640944e+000,-1.754463e+000,-1.453038e+000,-1.499016e+000,-1.441341e-004,-1.441341e-004,,,,,,,,,,,,,,,,,,,,
1524299839.746,,0.000000e+000,3.599487e+001,3.599902e+001,1,0,2.709677e+000,0.000000e+000,-1.395132e+000,-1.395132e+000,-1.092396e+000,-1.139416e+000,-1.253077e+000,-9.503403e-001,-9.973601e-001,-8.882320e-005,-8.882320e-005,,,,,,,,,,,,,,,,,,,,
1524299852.334,,0.000000e+000,3.599819e+001,3.599902e+001,1,0,2.838710e+000,0.000000e+000,-9.022660e-001,-9.022660e-001,-5.967389e-001,-6.469016e-001,-7.706587e-001,-4.651317e-001,-5.152943e-001,-3.431010e-005,-3.431010e-005,,,,,,,,,,,,,,,,,,,,
1524299864.902,,0.000000e+000,3.599570e+001,3.599902e+001,1,0,2.967742e+000,0.000000e+000,-4.327459e-001,-4.327459e-001,-1.234675e-001,-1.752046e-001,-3.171450e-001,-7.866613e-003,-5.960372e-002,1.777237e-005,1.777237e-005,,,,,,,,,,,,,,,,,,,,
1524299877.482,,0.000000e+000,3.599902e+001,3.599736e+001,1,0,3.096774e+000,0.000000e+000,3.356985e-003,3.356985e-003,3.155093e-001,2.603112e-001,9.900187e-002,4.111542e-001,3.559561e-001,6.600366e-005,6.600366e-005,,,,,,,,,,,,,,,,,,,,
1524299890.072,,0.000000e+000,3.600400e+001,3.599819e+001,1,0,3.225806e+000,0.000000e+000,4.037537e-001,4.037537e-001,7.184843e-001,6.622162e-001,4.609580e-001,7.756886e-001,7.194204e-001,1.103516e-004,1.103516e-004,,,,,,,,,,,,,,,,,,,,
1524299902.660,,0.000000e+000,3.599405e+001,3.599819e+001,1,0,3.354839e+000,0.000000e+000,7.290761e-001,7.290761e-001,1.045655e+000,9.866917e-001,7.445828e-001,1.061162e+000,1.002198e+000,1.462731e-004,1.462731e-004,,,,,,,,,,,,,,,,,,,,
1524299915.252,,0.000000e+000,3.599819e+001,3.599902e+001,1,0,3.483871e+000,0.000000e+000,9.552148e-001,9.552148e-001,1.274552e+000,1.214713e+000,9.252948e-001,1.244632e+000,1.184793e+000,1.714231e-004,1.714231e-004,,,,,,,,,,,,,,,,,,,,
1524299927.828,,0.000000e+000,3.599902e+001,3.599819e+001,1,0,3.612903e+000,0.000000e+000,1.058671e+000,1.058671e+000,1.382230e+000,1.318751e+000,9.902534e-001,1.313812e+000,1.250333e+000,1.830989e-004,1.830989e-004,,,,,,,,,,,,,,,,,,,,
1524299940.530,,0.000000e+000,3.599321e+001,3.599819e+001,1,0,3.741935e+000,0.000000e+000,1.042649e+000,1.042649e+000,1.369598e+000,1.304237e+000,9.519938e-001,1.278942e+000,1.213582e+000,1.815542e-004,1.815542e-004,,,,,,,,,,,,,,,,,,,,
1524299953.000,,0.000000e+000,3.599902e+001,3.599902e+001,1,0,3.870968e+000,0.000000e+000,9.431601e-001,9.431601e-001,1.272946e+000,1.205942e+000,8.389837e-001,1.168770e+000,1.101766e+000,1.707561e-004,1.707561e-004,,,,,,,,,,,,,,,,,,,,
1524299965.588,,0.000000e+000,3.599902e+001,3.599819e+001,1,0,4.000000e+000,0.000000e+000,7.893492e-001,7.893492e-001,1.120887e+000,1.053158e+000,6.862937e-001,1.017831e+000,9.501021e-001,1.538727e-004,1.538727e-004,,,,,,,,,,,,,,,,,,,,
1524299990.761,,0.000000e+000,3.600317e+001,3.599902e+001,1,0,0.000000e+000,0.000000e+000,6.436256e-001,6.436256e-001,9.109035e-001,9.109035e-001,7.510540e-001,1.018332e+000,1.018332e+000,1.356991e-004,1.356991e-004,,,,,,,,,,,,,,,,,,,,
1524300003.339,,0.000000e+000,3.599073e+001,3.599902e+001,1,0,1.290323e-001,0.000000e+000,7.858396e-001,7.858396e-001,1.053916e+000,1.051793e+000,9.009421e-001,1.169019e+000,1.166896e+000,1.512435e-004,1.512435e-004,,,,,,,,,,,,,,,,,,,,
1524300015.946,,0.000000e+000,3.599902e+001,3.599902e+001,1,0,2.580645e-001,0.000000e+000,9.233234e-001,9.233234e-001,1.191419e+000,1.186906e+000,1.013391e+000,1.281487e+000,1.276974e+000,1.664391e-004,1.664391e-004,,,,,,,,,,,,,,,,,,,,
1524300028.509,,0.000000e+000,3.599984e+001,3.599819e+001,1,0,3.870968e-001,0.000000e+000,9.826810e-001,9.826810e-001,1.256845e+000,1.250284e+000,1.041761e+000,1.315925e+000,1.309364e+000,1.734126e-004,1.734126e-004,,,,,,,,,,,,,,,,,,,,
1524300041.094,,0.000000e+000,3.600317e+001,3.599819e+001,1,0,5.161290e-001,0.000000e+000,9.552148e-001,9.552148e-001,1.230386e+000,1.221632e+000,9.720575e-001,1.247228e+000,1.238475e+000,1.703441e-004,1.703441e-004,,,,,,,,,,,,,,,,,,,,
1524300053.682,,0.000000e+000,3.599819e+001,3.599819e+001,1,0,6.451613e-001,0.000000e+000,8.072023e-001,8.072023e-001,1.084701e+000,1.073966e+000,7.864845e-001,1.063983e+000,1.053248e+000,1.540778e-004,1.540778e-004,,,,,,,,,,,,,,,,,,,,
1524300066.272,,0.000000e+000,3.599819e+001,3.599984e+001,1,0,7.741935e-001,0.000000e+000,5.506981e-001,5.506981e-001,8.301629e-001,8.172562e-001,4.981864e-001,7.776513e-001,7.647444e-001,1.258319e-004,1.258319e-004,,,,,,,,,,,,,,,,,,,,
1524300078.865,,0.000000e+000,3.600317e+001,3.599984e+001,1,0,9.032258e-001,0.000000e+000,2.113374e-001,2.113374e-001,4.933364e-001,4.781252e-001,1.307151e-001,4.127141e-001,3.975029e-001,8.854417e-005,8.854417e-005,,,,,,,,,,,,,,,,,,,,
1524300091.447,,0.000000e+000,3.599405e+001,3.599902e+001,1,0,1.032258e+000,0.000000e+000,-1.913481e-001,-1.913481e-001,9.362203e-002,7.613462e-002,-2.928668e-001,-7.896602e-003,-2.538401e-002,4.429578e-005,4.429578e-005,,,,,,,,,,,,,,,,,,,,
1524300104.138,,0.000000e+000,3.599902e+001,3.599902e+001,1,0,1.161290e+000,0.000000e+000,-6.285191e-001,-6.285191e-001,-3.417303e-001,-3.613694e-001,-7.540584e-001,-4.672696e-001,-4.869087e-001,-3.890906e-006,-3.890906e-006,,,,,,,,,,,,,,,,,,,,
1524300116.620,,0.000000e+000,3.599902e+001,3.599902e+001,1,0,1.290323e+000,0.000000e+000,-1.103227e+000,-1.103227e+000,-8.137280e-001,-8.353629e-001,-1.244578e+000,-9.550786e-001,-9.767135e-001,-5.613331e-005,-5.613331e-005,,,,,,,,,,,,,,,,,,,,
1524300129.213,,0.000000e+000,3.599321e+001,3.599819e+001,1,0,1.419355e+000,0.000000e+000,-1.602350e+000,-1.602350e+000,-1.310140e+000,-1.333352e+000,-1.753540e+000,-1.461329e+000,-1.484542e+000,-1.110630e-004,-1.110630e-004,,,,,,,,,,,,,,,,,,,,
1524300141.798,,0.000000e+000,3.600317e+001,3.599984e+001,1,0,1.548387e+000,0.000000e+000,-2.108492e+000,-2.108492e+000,-1.814731e+000,-1.840189e+000,-2.257989e+000,-1.964228e+000,-1.989686e+000,-1.668846e-004,-1.668846e-004,,,,,,,,,,,,,,,,,,,,
1524300154.378,,0.000000e+000,3.599984e+001,3.599819e+001,1,0,1.677419e+000,0.000000e+000,-2.594339e+000,-2.594339e+000,-2.298324e+000,-2.326235e+000,-2.721649e+000,-2.425634e+000,-2.453546e+000,-2.203848e-004,-2.203848e-004,,,,,,,,,,,,,,,,,,,,
1524300166.958,,0.000000e+000,3.600068e+001,3.599902e+001,1,0,1.806452e+000,0.000000e+000,-3.007401e+000,-3.007401e+000,-2.708804e+000,-2.739025e+000,-3.087281e+000,-2.788685e+000,-2.818906e+000,-2.658202e-004,-2.658202e-004,,,,,,,,,,,,,,,,,,,,
1524300179.551,,0.000000e+000,3.599487e+001,3.599819e+001,1,0,1.935484e+000,0.000000e+000,-3.269703e+000,-3.269703e+000,-2.968970e+000,-3.000243e+000,-3.291174e+000,-2.990441e+000,-3.021714e+000,-2.946869e-004,-2.946869e-004,,,,,,,,,,,,,,,,,,,,
1524300192.134,,0.000000e+000,3.599321e+001,3.599902e+001,1,0,2.064516e+000,0.000000e+000,-3.329824e+000,-3.329824e+000,-3.026096e+000,-3.060218e+000,-3.295573e+000,-2.991846e+000,-3.025968e+000,-3.011296e-004,-3.011296e-004,,,,,,,,,,,,,,,,,,,,
1524300204.734,,0.000000e+000,3.599902e+001,3.599902e+001,1,0,2.193548e+000,0.000000e+000,-3.182879e+000,-3.182879e+000,-2.877861e+000,-2.913741e+000,-3.094915e+000,-2.789896e+000,-2.825777e+000,-2.849295e-004,-2.849295e-004,,,,,,,,,,,,,,,,,,,,
1524300217.317,,0.000000e+000,3.600400e+001,3.599819e+001,1,0,2.322581e+000,0.000000e+000,-2.854810e+000,-2.854810e+000,-2.547194e+000,-2.585110e+000,-2.735894e+000,-2.428277e+000,-2.466193e+000,-2.485897e-004,-2.485897e-004,,,,,,,,,,,,,,,,,,,,
1524300229.912,,0.000000e+000,3.599156e+001,3.599902e+001,1,0,2.451613e+000,0.000000e+000,-2.410010e+000,-2.410010e+000,-2.099465e+000,-2.139296e+000,-2.277421e+000,-1.966876e+000,-2.006707e+000,-1.993417e-004,-1.993417e-004,,,,,,,,,,,,,,,,,,,,
1524300242.587,,0.000000e+000,3.599902e+001,3.599819e+001,1,0,2.580645e+000,0.000000e+000,-1.912261e+000,-1.912261e+000,-1.598901e+000,-1.640914e+000,-1.776790e+000,-1.463431e+000,-1.505444e+000,-1.442696e-004,-1.442696e-004,,,,,,,,,,,,,,,,,,,,
1524300255.095,,0.000000e+000,3.599819e+001,3.599902e+001,1,0,2.709677e+000,0.000000e+000,-1.407797e+000,-1.407797e+000,-1.092875e+000,-1.136656e+000,-1.272249e+000,-9.573270e-001,-1.001108e+000,-8.857396e-005,-8.857396e-005,,,,,,,,,,,,,,,,,,,,
1524300267.677,,0.000000e+000,3.600234e+001,3.599902e+001,1,0,2.838710e+000,0.000000e+000,-9.143206e-001,-9.143206e-001,-5.964172e-001,-6.432905e-001,-7.864015e-001,-4.684981e-001,-5.153714e-001,-3.396704e-005,-3.396704e-005,,,,,,,,,,,,,,,,,,,,
1524300280.268,,0.000000e+000,3.599736e+001,3.599984e+001,1,0,2.967742e+000,0.000000e+000,-4.425116e-001,-4.425116e-001,-1.210222e-001,-1.705131e-001,-3.294085e-001,-7.919060e-003,-5.740994e-002,1.831363e-005,1.831363e-005,,,,,,,,,,,,,,,,,,,,
1524300292.838,,0.000000e+000,3.599984e+001,3.599819e+001,1,0,3.096774e+000,0.000000e+000,-3.204395e-003,-3.204395e-003,3.205071e-001,2.701364e-001,9.040840e-002,4.141199e-001,3.637491e-001,6.691620e-005,6.691620e-005,,,,,,,,,,,,,,,,,,,,
1524300305.438,,0.000000e+000,3.599819e+001,3.599902e+001,1,0,3.225806e+000,0.000000e+000,4.011597e-001,4.011597e-001,7.269191e-001,6.758613e-001,4.554273e-001,7.811868e-001,7.301290e-001,1.116593e-004,1.116593e-004,,,,,,,,,,,,,,,,,,,,
1524300318.016,,0.000000e+000,3.600234e+001,3.599819e+001,1,0,3.354839e+000,0.000000e+000,7.257191e-001,7.257191e-001,1.054289e+000,1.001303e+000,7.401513e-001,1.068721e+000,1.015736e+000,1.476359e-004,1.476359e-004,,,,,,,,,,,,,,,,,,,,
1524300330.593,,0.000000e+000,3.599156e+001,3.599902e+001,1,0,3.483871e+000,0.000000e+000,9.523156e-001,9.523156e-001,1.283278e+000,1.227740e+000,9.223646e-001,1.253327e+000,1.197789e+000,1.727489e-004,1.727489e-004,,,,,,,,,,,,,,,,,,,,
1524300343.184,,0.000000e+000,3.599902e+001,3.599984e+001,1,0,3.612903e+000,0.000000e+000,1.055467e+000,1.055467e+000,1.389471e+000,1.330685e+000,9.890326e-001,1.323037e+000,1.264251e+000,1.842814e-004,1.842814e-004,,,,,,,,,,,,,,,,,,,,
1524300355.774,,0.000000e+000,3.599321e+001,3.599819e+001,1,0,3.741935e+000,0.000000e+000,1.038224e+000,1.038224e+000,1.375513e+000,1.315521e+000,9.505950e-001,1.287884e+000,1.227893e+000,1.826192e-004,1.826192e-004,,,,,,,,,,,,,,,,,,,,
1524300368.351,,0.000000e+000,3.599819e+001,3.599984e+001,1,0,3.870968e+000,0.000000e+000,9.362936e-001,9.362936e-001,1.276456e+000,1.214241e+000,8.362554e-001,1.176417e+000,1.114202e+000,1.715275e-004,1.715275e-004,,,,,,,,,,,,,,,,,,,,
1524300380.937,,0.000000e+000,3.599653e+001,3.599984e+001,1,0,4.000000e+000,0.000000e+000,7.821774e-001,7.821774e-001,1.123043e+000,1.060631e+000,6.839636e-001,1.024829e+000,9.624174e-001,1.545310e-004,1.545310e-004,,,,,,,,,,,,,,,,,,,,
1524300406.130,,0.000000e+000,3.600317e+001,3.599902e+001,1,0,0.000000e+000,0.000000e+000,6.434730e-001,6.434730e-001,9.223420e-001,9.223420e-001,7.463920e-001,1.025261e+000,1.025261e+000,1.370329e-004,1.370329e-004,,,,,,,,,,,,,,,,,,,,
1524300418.697,,0.000000e+000,3.600234e+001,3.599819e+001,1,0,1.290323e-001,0.000000e+000,7.829404e-001,7.829404e-001,1.065146e+000,1.063144e+000,8.952636e-001,1.177469e+000,1.175467e+000,1.525901e-004,1.525901e-004,,,,,,,,,,,,,,,,,,,,
1524300431.295,,0.000000e+000,3.599819e+001,3.599819e+001,1,0,2.580645e-001,0.000000e+000,9.193560e-001,9.193560e-001,1.202203e+000,1.198098e+000,1.006315e+000,1.289162e+000,1.285057e+000,1.676226e-004,1.676226e-004,,,,,,,,,,,,,,,,,,,,
1524300443.993,,0.000000e+000,3.599819e+001,3.599984e+001,1,0,3.870968e-001,0.000000e+000,9.817654e-001,9.817654e-001,1.268175e+000,1.262032e+000,1.038007e+000,1.324417e+000,1.318273e+000,1.747460e-004,1.747460e-004,,,,,,,,,,,,,,,,,,,,
1524300456.460,,0.000000e+000,3.599819e+001,3.599736e+001,1,0,5.161290e-001,0.000000e+000,9.514000e-001,9.514000e-001,1.239530e+000,1.231436e+000,9.667866e-001,1.254917e+000,1.246823e+000,1.714156e-004,1.714156e-004,,,,,,,,,,,,,,,,,,,,
1524300469.058,,0.000000e+000,3.600234e+001,3.599902e+001,1,0,6.451613e-001,0.000000e+000,8.001831e-001,8.001831e-001,1.090998e+000,1.080974e+000,7.802789e-001,1.071093e+000,1.061069e+000,1.548814e-004,1.548814e-004,,,,,,,,,,,,,,,,,,,,
1524300481.661,,0.000000e+000,3.599902e+001,3.599819e+001,1,0,7.741935e-001,0.000000e+000,5.415427e-001,5.415427e-001,8.345451e-001,8.227769e-001,4.900240e-001,7.830264e-001,7.712581e-001,1.264091e-004,1.264091e-004,,,,,,,,,,,,,,,,,,,,
1524300494.243,,0.000000e+000,3.599819e+001,3.599736e+001,1,0,9.032258e-001,0.000000e+000,1.977569e-001,1.977569e-001,4.917125e-001,4.774958e-001,1.213029e-001,4.152585e-001,4.010417e-001,8.847812e-005,8.847812e-005,,,,,,,,,,,,,,,,,,,,
1524300506.821,,0.000000e+000,3.599239e+001,3.599902e+001,1,0,1.032258e+000,0.000000e+000,-2.063020e-001,-2.063020e-001,9.028371e-002,7.408549e-002,-3.045329e-001,-7.947262e-003,-2.414548e-002,4.404876e-005,4.404876e-005,,,,,,,,,,,,,,,,,,,,
1524300519.426,,0.000000e+000,3.600317e+001,3.599902e+001,1,0,1.161290e+000,0.000000e+000,-6.495765e-001,-6.495765e-001,-3.502030e-001,-3.680983e-001,-7.696959e-001,-4.703224e-001,-4.882177e-001,-4.704241e-006,-4.704241e-006,,,,,,,,,,,,,,,,,,,,
1524300532.104,,0.000000e+000,3.599902e+001,3.599736e+001,1,0,1.290323e+000,0.000000e+000,-1.125048e+000,-1.125048e+000,-8.242106e-001,-8.447641e-001,-1.262234e+000,-9.613966e-001,-9.819501e-001,-5.711685e-005,-5.711685e-005,,,,,,,,,,,,,,,,,,,,
1524300544.582,,0.000000e+000,3.599736e+001,3.599902e+001,1,0,1.419355e+000,0.000000e+000,-1.626764e+000,-1.626764e+000,-1.323118e+000,-1.344942e+000,-1.773860e+000,-1.470214e+000,-1.492038e+000,-1.123374e-004,-1.123374e-004,,,,,,,,,,,,,,,,,,,,
1524300557.247,,0.000000e+000,3.599736e+001,3.599902e+001,1,0,1.548387e+000,0.000000e+000,-2.137789e+000,-2.137789e+000,-1.831746e+000,-1.855647e+000,-2.282512e+000,-1.976469e+000,-2.000370e+000,-1.685909e-004,-1.685909e-004,,,,,,,,,,,,,,,,,,,,
1524300569.757,,0.000000e+000,3.599819e+001,3.599819e+001,1,0,1.677419e+000,0.000000e+000,-2.625772e+000,-2.625772e+000,-2.317810e+000,-2.343280e+000,-2.748528e+000,-2.440565e+000,-2.466035e+000,-2.223674e-004,-2.223674e-004,,,,,,,,,,,,,,,,,,,,
1524300582.355,,0.000000e+000,3.599819e+001,3.599984e+001,1,0,1.806452e+000,0.000000e+000,-3.038682e+000,-3.038682e+000,-2.728533e+000,-2.756138e+000,-3.115288e+000,-2.805139e+000,-2.832745e+000,-2.678239e-004,-2.678239e-004,,,,,,,,,,,,,,,,,,,,
1524300594.947,,0.000000e+000,3.600400e+001,3.599902e+001,1,0,1.935484e+000,0.000000e+000,-3.299153e+000,-3.299153e+000,-2.987625e+000,-3.017452e+000,-3.320831e+000,-3.009304e+000,-3.039130e+000,-2.965418e-004,-2.965418e-004,,,,,,,,,,,,,,,,,,,,
1524300607.510,,0.000000e+000,3.599736e+001,3.599902e+001,1,0,2.064516e+000,0.000000e+000,-3.357748e+000,-3.357748e+000,-3.044225e+000,-3.075735e+000,-3.322611e+000,-3.009088e+000,-3.040599e+000,-3.029345e-004,-3.029345e-004,,,,,,,,,,,,,,,,,,,,
1524300620.230,,0.000000e+000,3.599902e+001,3.600068e+001,1,0,2.193548e+000,0.000000e+000,-3.257648e+000,-3.257648e+000,-2.891353e+000,-2.926072e+000,-3.173182e+000,-2.806886e+000,-2.841605e+000,-2.862107e-004,-2.862107e-004,,,,,,,,,,,,,,,,,,,,
1524300632.688,,0.000000e+000,3.600068e+001,3.599736e+001,1,0,2.322581e+000,0.000000e+000,-2.877699e+000,-2.877699e+000,-2.556868e+000,-2.591677e+000,-2.763283e+000,-2.442452e+000,-2.477261e+000,-2.494337e-004,-2.494337e-004,,,,,,,,,,,,,,,,,,,,
1524300645.275,,0.000000e+000,3.599984e+001,3.599902e+001,1,0,2.451613e+000,0.000000e+000,-2.478218e+000,-2.478218e+000,-2.105881e+000,-2.143867e+000,-2.351100e+000,-1.978763e+000,-2.016749e+000,-1.998262e-004,-1.998262e-004,,,,,,,,,,,,,,,,,,,,
1524300658.001,,0.000000e+000,3.599653e+001,3.599819e+001,1,0,2.580645e+000,0.000000e+000,-1.928435e+000,-1.928435e+000,-1.603805e+000,-1.641339e+000,-1.797111e+000,-1.472480e+000,-1.510015e+000,-1.445333e-004,-1.445333e-004,,,,,,,,,,,,,,,,,,,,
1524300670.443,,0.000000e+000,3.599819e+001,3.599819e+001,1,0,2.709677e+000,0.000000e+000,-1.420768e+000,-1.420768e+000,-1.095564e+000,-1.135753e+000,-1.288289e+000,-9.630854e-001,-1.003275e+000,-8.860382e-005,-8.860382e-005,,,,,,,,,,,,,,,,,,,,
1524300683.051,,0.000000e+000,3.599819e+001,3.599984e+001,1,0,2.838710e+000,0.000000e+000,-9.214923e-001,-9.214923e-001,-5.952192e-001,-6.369506e-001,-7.975256e-001,-4.712525e-001,-5.129839e-001,-3.352995e-005,-3.352995e-005,,,,,,,,,,,,,,,,,,,,
1524300695.634,,0.000000e+000,3.600317e+001,3.599902e+001,1,0,2.967742e+000,0.000000e+000,-4.444953e-001,-4.444953e-001,-1.163353e-001,-1.606275e-001,-3.361274e-001,-7.967450e-003,-5.225959e-002,1.915621e-005,1.915621e-005,,,,,,,,,,,,,,,,,,,,
1524300708.221,,0.000000e+000,3.599321e+001,3.599736e+001,1,0,3.096774e+000,0.000000e+000,-2.136263e-003,-2.136263e-003,3.281294e-001,2.799918e-001,8.624499e-002,4.165106e-001,3.683731e-001,6.800509e-005,6.800509e-005,,,,,,,,,,,,,,,,,,,,
1524300720.802,,0.000000e+000,3.599736e+001,3.599984e+001,1,0,3.225806e+000,0.000000e+000,4.005493e-001,4.005493e-001,7.333251e-001,6.850088e-001,4.528996e-001,7.856753e-001,7.373590e-001,1.126316e-004,1.126316e-004,,,,,,,,,,,,,,,,,,,,
1524300733.404,,0.000000e+000,3.599570e+001,3.599902e+001,1,0,3.354839e+000,0.000000e+000,7.275501e-001,7.275501e-001,1.061747e+000,1.011466e+000,7.405413e-001,1.074738e+000,1.024457e+000,1.487243e-004,1.487243e-004,,,,,,,,,,,,,,,,,,,,
1524300745.969,,0.000000e+000,3.599321e+001,3.599819e+001,1,0,3.483871e+000,0.000000e+000,9.532311e-001,9.532311e-001,1.289392e+000,1.236962e+000,9.239655e-001,1.260126e+000,1.207696e+000,1.736993e-004,1.736993e-004,,,,,,,,,,,,,,,,,,,,
1524300758.572,,0.000000e+000,3.599487e+001,3.599819e+001,1,0,3.612903e+000,0.000000e+000,1.057755e+000,1.057755e+000,1.395693e+000,1.341852e+000,9.923387e-001,1.330276e+000,1.276435e+000,1.853103e-004,1.853103e-004,,,,,,,,,,,,,,,,,,,,
1524300771.137,,0.000000e+000,3.599819e+001,3.599902e+001,1,0,3.741935e+000,0.000000e+000,1.039597e+000,1.039597e+000,1.380502e+000,1.323525e+000,9.539485e-001,1.294854e+000,1.237876e+000,1.834509e-004,1.834509e-004,,,,,,,,,,,,,,,,,,,,
1524300783.725,,0.000000e+000,3.599653e+001,3.599902e+001,1,0,3.870968e+000,0.000000e+000,9.388876e-001,9.388876e-001,1.280975e+000,1.223345e+000,8.412042e-001,1.183292e+000,1.125661e+000,1.723815e-004,1.723815e-004,,,,,,,,,,,,,,,,,,,,
1524300796.323,,0.000000e+000,3.599405e+001,3.599819e+001,1,0,4.000000e+000,0.000000e+000,7.818723e-001,7.818723e-001,1.124954e+000,1.066391e+000,6.873618e-001,1.030443e+000,9.718801e-001,1.550637e-004,1.550637e-004,,,,,,,,,,,,,,,,,,,,
1524300821.486,,0.000000e+000,3.599819e+001,3.599902e+001,1,0,0.000000e+000,0.000000e+000,6.488136e-001,6.488136e-001,9.332540e-001,9.332540e-001,7.462761e-001,1.030717e+000,1.030717e+000,1.382636e-004,1.382636e-004,,,,,,,,,,,,,,,,,,,,
1524300834.076,,0.000000e+000,3.599819e+001,3.599819e+001,1,0,1.290323e-001,0.000000e+000,7.881285e-001,7.881285e-001,1.074800e+000,1.072882e+000,8.973740e-001,1.184046e+000,1.182127e+000,1.537494e-004,1.537494e-004,,,,,,,,,,,,,,,,,,,,
1524300846.661,,0.000000e+000,3.600483e+001,3.599819e+001,1,0,2.580645e-001,0.000000e+000,9.208820e-001,9.208820e-001,1.209770e+000,1.205926e+000,1.007184e+000,1.296072e+000,1.292228e+000,1.685041e-004,1.685041e-004,,,,,,,,,,,,,,,,,,,,
1524300859.254,,0.000000e+000,3.599819e+001,3.599819e+001,1,0,3.870968e-001,0.000000e+000,9.860380e-001,9.860380e-001,1.276569e+000,1.270787e+000,1.041178e+000,1.331709e+000,1.325927e+000,1.757427e-004,1.757427e-004,,,,,,,,,,,,,,,,,,,,
1524300871.834,,0.000000e+000,3.599819e+001,3.599902e+001,1,0,5.161290e-001,0.000000e+000,9.542992e-001,9.542992e-001,1.247421e+000,1.239844e+000,9.687976e-001,1.261919e+000,1.254343e+000,1.723605e-004,1.723605e-004,,,,,,,,,,,,,,,,,,,,
1524300884.424,,0.000000e+000,3.599736e+001,3.599736e+001,1,0,6.451613e-001,0.000000e+000,8.004883e-001,8.004883e-001,1.095303e+000,1.085883e+000,7.817893e-001,1.076604e+000,1.067184e+000,1.554326e-004,1.554326e-004,,,,,,,,,,,,,,,,,,,,
1524300896.997,,0.000000e+000,3.599321e+001,3.599902e+001,1,0,7.741935e-001,0.000000e+000,5.391012e-001,5.391012e-001,8.356870e-001,8.242436e-001,4.906453e-001,7.872310e-001,7.757876e-001,1.266742e-004,1.266742e-004,,,,,,,,,,,,,,,,,,,,
1524300909.587,,0.000000e+000,3.599902e+001,3.599819e+001,1,0,9.032258e-001,0.000000e+000,1.927214e-001,1.927214e-001,4.917259e-001,4.786654e-001,1.186514e-001,4.176559e-001,4.045954e-001,8.856658e-005,8.856658e-005,,,,,,,,,,,,,,,,,,,,
1524300922.180,,0.000000e+000,3.599156e+001,3.599819e+001,1,0,1.032258e+000,0.000000e+000,-2.110323e-001,-2.110323e-001,8.914569e-002,7.376367e-002,-3.081683e-001,-7.990297e-003,-2.337232e-002,4.404532e-005,4.404532e-005,,,,,,,,,,,,,,,,,,,,
1524300934.765,,0.000000e+000,3.600400e+001,3.599902e+001,1,0,1.161290e+000,0.000000e+000,-6.584268e-001,-6.584268e-001,-3.549646e-001,-3.717664e-001,-7.762465e-001,-4.727843e-001,-4.895861e-001,-5.115056e-006,-5.115056e-006,,,,,,,,,,,,,,,,,,,,
1524300947.332,,0.000000e+000,3.599902e+001,3.599984e+001,1,0,1.290323e+000,0.000000e+000,-1.138170e+000,-1.138170e+000,-8.330325e-001,-8.517054e-001,-1.271456e+000,-9.663178e-001,-9.849907e-001,-5.799740e-005,-5.799740e-005,,,,,,,,,,,,,,,,,,,,
1524300960.015,,0.000000e+000,3.599984e+001,3.599902e+001,1,0,1.419355e+000,0.000000e+000,-1.646296e+000,-1.646296e+000,-1.339213e+000,-1.359548e+000,-1.785106e+000,-1.478024e+000,-1.498358e+000,-1.139828e-004,-1.139828e-004,,,,,,,,,,,,,,,,,,,,
1524300972.510,,0.000000e+000,3.599819e+001,3.599736e+001,1,0,1.548387e+000,0.000000e+000,-2.154421e+000,-2.154421e+000,-1.845200e+000,-1.867724e+000,-2.295889e+000,-1.986667e+000,-2.009191e+000,-1.699345e-004,-1.699345e-004,,,,,,,,,,,,,,,,,,,,
1524300985.383,,0.000000e+000,3.600234e+001,3.599984e+001,1,0,1.677419e+000,0.000000e+000,-2.647898e+000,-2.647898e+000,-2.336733e+000,-2.360699e+000,-2.764224e+000,-2.453059e+000,-2.477025e+000,-2.243075e-004,-2.243075e-004,,,,,,,,,,,,,,,,,,,,
1524300985.383,,0.000000e+000,3.600234e+001,3.599984e+001,1,0,4.000000e+000,0.000000e+000,7.830930e-001,7.830930e-001,1.127442e+000,1.070292e+000,6.883872e-001,1.032736e+000,9.755862e-001,1.554639e-004,1.554639e-004,,,,,,,,,,,,,,,,,,,,