File: Experimental Raw Data/MFn1 VRM/raw/MFn1_VRMac_34K_6000s.dc.raw
[Header]
TITLE,MPMS DC Measurement
BYAPP,MPMS Measurement,2.1,Raw with ABS
FILEOPENTIME, 1524257604.759000 4/20/2018, 2:53:24 PM

INFO, APPNAME, MPMS MultiVu Application, Revision 1.61,  Build 082

INFO, NAME, MFn1
INFO, WEIGHT, 1.000
INFO, AREA, 1.000
INFO, LENGTH, 1.000
INFO, SHAPE, 0
INFO, COMMENT,
INFO, SEQUENCE FILE: VRMac_34K_6000s_VRMde_35K.seq


INFO, BACKGROUND DATA FILE:, None


STARTUPAXIS,X,8,LINEAR,AUTO,0.000000,0.000000
STARTUPAXIS,Y1,10,LINEAR,AUTO,0.000000,0.000000


STARTUPGROUP,Longitudinal
FIELDGROUP,Longitudinal,1,3,4,5,6,8,9,10,11,12,13,14,15,16,17,18,19,20,21,22,23
FIELDGROUP,Transverse,1,3,4,5,6,8,9,24,25,26,27,28,29,30,31,32,33,34,35,36,37

PLOT_APPEARANCE,ALL,HORZ_GRID_ON,VERT_GRID_ON,MARKERS_ONLY

[Data]
Time,Comment,Field (Oe),Start Temperature (K),End Temperature (K),Scan,Rejected,Position (cm),Rot Position (deg),Long Voltage,Long Average Voltage,Long Detrended Voltage,Long Demeaned Voltage,Long Regression Fit,Long Detrended Fit,Long Demeaned Fit,Long Scaled Response,Long Avg. Scaled Response,Long Background Response,Long Response [w/ABS],Long Detrended Resp. [w/ABS],Long Fit [w/ABS],Long Detrended Fit [w/ABS],Trans Voltage,Trans Average Voltage,Trans Detrended Voltage,Trans Demeaned Voltage,Trans Regression Fit,Trans Detrended Fit,Trans Demeaned Fit,Trans Scaled Response,Trans Avg Scaled Response,Trans Background Response,Trans Response [w/ABS],Trans Detrended Resp. [w/ABS],Trans Fit [w/ABS],Trans Detrended Fit [w/ABS],
1524257604.731,,0.000000e+000,3.400451e+001,3.399862e+001,1,0,0.000000e+000,0.000000e+000,-5.450523e-001,-5.450523e-001,1.594072e+000,1.594072e+000,3.227359e-002,2.171397e+000,2.171397e+000,1.049060e-004,1.049060e-004,,,,,,,,,,,,,,,,,,,,
1524257629.924,,0.000000e+000,3.399641e+001,3.400009e+001,1,0,2.580645e-001,0.000000e+000,2.975509e-001,2.975509e-001,2.340403e+000,2.305955e+000,7.539623e-001,2.796814e+000,2.762367e+000,1.387172e-004,1.387172e-004,,,,,,,,,,,,,,,,,,,,
1524257655.210,,0.000000e+000,3.400377e+001,3.399862e+001,1,0,5.161290e-001,0.000000e+000,6.367590e-001,6.367590e-001,2.667690e+000,2.595581e+000,7.264878e-001,2.757419e+000,2.685309e+000,1.527872e-004,1.527872e-004,,,,,,,,,,,,,,,,,,,,
1524257680.113,,0.000000e+000,3.400009e+001,3.400082e+001,1,0,7.741935e-001,0.000000e+000,-1.388571e-002,-1.388571e-002,2.032082e+000,1.921696e+000,-3.127647e-001,1.733203e+000,1.622818e+000,1.240075e-004,1.240075e-004,,,,,,,,,,,,,,,,,,,,
1524257705.448,,0.000000e+000,3.399936e+001,3.400009e+001,1,0,1.032258e+000,0.000000e+000,-1.537957e+000,-1.537957e+000,5.343458e-001,3.845882e-001,-2.090004e+000,-1.770133e-002,-1.674589e-001,5.708772e-005,5.708772e-005,,,,,,,,,,,,,,,,,,,,
1524257731.091,,0.000000e+000,3.399788e+001,3.399936e+001,1,0,1.290323e+000,0.000000e+000,-3.548791e+000,-3.548791e+000,-1.442576e+000,-1.631033e+000,-4.257587e+000,-2.151373e+000,-2.339830e+000,-3.108704e-005,-3.108704e-005,,,,,,,,,,,,,,,,,,,,
1524257756.456,,0.000000e+000,3.399788e+001,3.399862e+001,1,0,1.548387e+000,0.000000e+000,-5.823911e+000,-5.823911e+000,-3.680872e+000,-3.909164e+000,-6.584107e+000,-4.441069e+000,-4.669360e+000,-1.308311e-004,-1.308311e-004,,,,,,,,,,,,,,,,,,,,
1524257781.844,,0.000000e+000,3.399788e+001,3.399862e+001,1,0,1.806452e+000,0.000000e+000,-8.025330e+000,-8.025330e+000,-5.841718e+000,-6.108258e+000,-8.509558e+000,-6.325946e+000,-6.592486e+000,-2.272007e-004,-2.272007e-004,,,,,,,,,,,,,,,,,,,,
1524257806.567,,0.000000e+000,3.399714e+001,3.399936e+001,1,0,2.064516e+000,0.000000e+000,-9.170672e+000,-9.170672e+000,-6.947308e+000,-7.252786e+000,-9.029412e+000,-6.806047e+000,-7.111526e+000,-2.770169e-004,-2.770169e-004,,,,,,,,,,,,,,,,,,,,
1524257831.315,,0.000000e+000,3.399641e+001,3.399862e+001,1,0,2.322581e+000,0.000000e+000,-8.464942e+000,-8.464942e+000,-6.201411e+000,-6.546472e+000,-7.801724e+000,-5.538193e+000,-5.883253e+000,-2.451414e-004,-2.451414e-004,,,,,,,,,,,,,,,,,,,,
1524257855.960,,0.000000e+000,3.399862e+001,3.399788e+001,1,0,2.580645e+000,0.000000e+000,-6.455787e+000,-6.455787e+000,-4.149930e+000,-4.534722e+000,-5.651349e+000,-3.345492e+000,-3.730284e+000,-1.556697e-004,-1.556697e-004,,,,,,,,,,,,,,,,,,,,
1524257881.441,,0.000000e+000,3.399788e+001,3.399788e+001,1,0,2.838710e+000,0.000000e+000,-4.116732e+000,-4.116732e+000,-1.768795e+000,-2.193325e+000,-3.420990e+000,-1.073054e+000,-1.497584e+000,-5.165135e-005,-5.165135e-005,,,,,,,,,,,,,,,,,,,,
1524257906.696,,0.000000e+000,3.400009e+001,3.399788e+001,1,0,3.096774e+000,0.000000e+000,-1.937133e+000,-1.937133e+000,4.523424e-001,-1.160240e-002,-1.439458e+000,9.500177e-001,4.860729e-001,4.528745e-005,4.528745e-005,,,,,,,,,,,,,,,,,,,,
1524257931.656,,0.000000e+000,3.399788e+001,3.399641e+001,1,0,3.354839e+000,0.000000e+000,-1.171893e-001,-1.171893e-001,2.312317e+000,1.810085e+000,2.628604e-002,2.455792e+000,1.953560e+000,1.263106e-004,1.263106e-004,,,,,,,,,,,,,,,,,,,,
1524257956.477,,0.000000e+000,3.399714e+001,3.399862e+001,1,0,3.612903e+000,0.000000e+000,8.976883e-001,8.976883e-001,3.369926e+000,2.826992e+000,5.718910e-001,3.044129e+000,2.501194e+000,1.718803e-004,1.718803e-004,,,,,,,,,,,,,,,,,,,,
1524257981.830,,0.000000e+000,3.399936e+001,3.399862e+001,1,0,3.870968e+000,0.000000e+000,8.178836e-001,8.178836e-001,3.331572e+000,2.751357e+000,1.981017e-001,2.711790e+000,2.131576e+000,1.691212e-004,1.691212e-004,,,,,,,,,,,,,,,,,,,,
1524258020.345,,0.000000e+000,3.399788e+001,3.400009e+001,1,0,0.000000e+000,0.000000e+000,-1.643397e-001,-1.643397e-001,1.773348e+000,1.773348e+000,4.300230e-001,2.367711e+000,2.367711e+000,1.175136e-004,1.175136e-004,,,,,,,,,,,,,,,,,,,,
1524258045.955,,0.000000e+000,3.399936e+001,3.399714e+001,1,0,2.580645e-001,0.000000e+000,5.313191e-001,5.313191e-001,2.509731e+000,2.470855e+000,1.002538e+000,2.980950e+000,2.942074e+000,1.489519e-004,1.489519e-004,,,,,,,,,,,,,,,,,,,,
1524258071.608,,0.000000e+000,3.399862e+001,3.399641e+001,1,0,5.161290e-001,0.000000e+000,7.995728e-001,7.995728e-001,2.820131e+000,2.742646e+000,8.855241e-001,2.906082e+000,2.828597e+000,1.615306e-004,1.615306e-004,,,,,,,,,,,,,,,,,,,,
1524258096.871,,0.000000e+000,3.399788e+001,3.399936e+001,1,0,7.741935e-001,0.000000e+000,7.003891e-002,7.003891e-002,2.130105e+000,2.013226e+000,-2.450047e-001,1.815061e+000,1.698182e+000,1.300143e-004,1.300143e-004,,,,,,,,,,,,,,,,,,,,
1524258122.554,,0.000000e+000,3.399714e+001,3.399936e+001,1,0,1.032258e+000,0.000000e+000,-1.558251e+000,-1.558251e+000,5.444922e-001,3.886291e-001,-2.121186e+000,-1.844227e-002,-1.743054e-001,5.893351e-005,5.893351e-005,,,,,,,,,,,,,,,,,,,,
1524258147.254,,0.000000e+000,3.399862e+001,3.400009e+001,1,0,1.290323e+000,0.000000e+000,-3.650111e+000,-3.650111e+000,-1.505083e+000,-1.699553e+000,-4.377065e+000,-2.232038e+000,-2.426507e+000,-3.264120e-005,-3.264120e-005,,,,,,,,,,,,,,,,,,,,
1524258171.867,,0.000000e+000,3.399714e+001,3.399862e+001,1,0,1.548387e+000,0.000000e+000,-6.002136e+000,-6.002136e+000,-3.817083e+000,-4.051419e+000,-6.778844e+000,-4.593791e+000,-4.828126e+000,-1.357707e-004,-1.357707e-004,,,,,,,,,,,,,,,,,,,,
1524258197.523,,0.000000e+000,3.399788e+001,3.394276e+001,1,0,1.806452e+000,0.000000e+000,-8.269474e+000,-8.269474e+000,-6.037138e+000,-6.310512e+000,-8.759243e+000,-6.526907e+000,-6.800281e+000,-2.348578e-004,-2.348578e-004,,,,,,,,,,,,,,,,,,,,
1524258223.126,,0.000000e+000,3.400230e+001,3.399862e+001,1,0,2.064516e+000,0.000000e+000,-9.423972e+000,-9.423972e+000,-7.151764e+000,-7.461710e+000,-9.279038e+000,-7.006831e+000,-7.316776e+000,-2.851631e-004,-2.851631e-004,,,,,,,,,,,,,,,,,,,,
1524258249.011,,0.000000e+000,3.399714e+001,3.399788e+001,1,0,2.322581e+000,0.000000e+000,-8.676738e+000,-8.676738e+000,-6.362876e+000,-6.714684e+000,-8.005172e+000,-5.691310e+000,-6.043118e+000,-2.514667e-004,-2.514667e-004,,,,,,,,,,,,,,,,,,,,
1524258275.034,,0.000000e+000,3.399714e+001,3.399936e+001,1,0,2.580645e+000,0.000000e+000,-6.596780e+000,-6.596780e+000,-4.239990e+000,-4.630154e+000,-5.790588e+000,-3.433799e+000,-3.823961e+000,-1.588873e-004,-1.588873e-004,,,,,,,,,,,,,,,,,,,,
1524258301.274,,0.000000e+000,3.399862e+001,3.399788e+001,1,0,2.838710e+000,0.000000e+000,-4.201114e+000,-4.201114e+000,-1.800728e+000,-2.230206e+000,-3.500089e+000,-1.099704e+000,-1.529182e+000,-5.235612e-005,-5.235612e-005,,,,,,,,,,,,,,,,,,,,
1524258326.625,,0.000000e+000,3.399714e+001,3.399862e+001,1,0,3.096774e+000,0.000000e+000,-1.969329e+000,-1.969329e+000,4.732886e-001,7.070303e-003,-1.470000e+000,9.726182e-001,5.064000e-001,4.690562e-005,4.690562e-005,,,,,,,,,,,,,,,,,,,,
1524258352.065,,0.000000e+000,3.399641e+001,3.399788e+001,1,0,3.354839e+000,0.000000e+000,-1.170367e-001,-1.170367e-001,2.368375e+000,1.861944e+000,2.592016e-002,2.511332e+000,2.004901e+000,1.294184e-004,1.294184e-004,,,,,,,,,,,,,,,,,,,,
1524258377.510,,0.000000e+000,3.399862e+001,3.399714e+001,1,0,3.612903e+000,0.000000e+000,9.050126e-001,9.050126e-001,3.433606e+000,2.888585e+000,5.812128e-001,3.109806e+000,2.564785e+000,1.753167e-004,1.753167e-004,,,,,,,,,,,,,,,,,,,,
1524258415.688,,0.000000e+000,3.399714e+001,3.399862e+001,1,0,3.870968e+000,0.000000e+000,3.260853e-001,3.260853e-001,1.355160e+000,1.122444e+000,7.828696e-002,1.107362e+000,8.746459e-001,1.722181e-004,1.722181e-004,,,,,,,,,,,,,,,,,,,,
1524258454.124,,0.000000e+000,3.399788e+001,3.399936e+001,1,0,0.000000e+000,0.000000e+000,-6.988632e-002,-6.988632e-002,7.295291e-001,7.295291e-001,1.661867e-001,9.656021e-001,9.656021e-001,1.203467e-004,1.203467e-004,,,,,,,,,,,,,,,,,,,,
1524258479.259,,0.000000e+000,3.399641e+001,3.399862e+001,1,0,2.580645e-001,0.000000e+000,2.099641e-001,2.099641e-001,1.025772e+000,1.010210e+000,3.990293e-001,1.214837e+000,1.199275e+000,1.519450e-004,1.519450e-004,,,,,,,,,,,,,,,,,,,,
1524258504.637,,0.000000e+000,3.399788e+001,3.399862e+001,1,0,5.161290e-001,0.000000e+000,3.128099e-001,3.128099e-001,1.146333e+000,1.115420e+000,3.496864e-001,1.183209e+000,1.152297e+000,1.640758e-004,1.640758e-004,,,,,,,,,,,,,,,,,,,,
1524258530.415,,0.000000e+000,3.399714e+001,3.400009e+001,1,0,7.741935e-001,0.000000e+000,9.765774e-003,9.765774e-003,8.608945e-001,8.144641e-001,-1.126993e-001,7.384294e-001,6.919990e-001,1.314759e-004,1.314759e-004,,,,,,,,,,,,,,,,,,,,
1524258555.688,,0.000000e+000,3.399936e+001,3.400009e+001,1,0,1.032258e+000,0.000000e+000,-6.547647e-001,-6.547647e-001,2.134627e-001,1.514887e-001,-8.757265e-001,-7.499136e-003,-6.947309e-002,5.893686e-005,5.893686e-005,,,,,,,,,,,,,,,,,,,,
1524258581.273,,0.000000e+000,3.399936e+001,3.399788e+001,1,0,1.290323e+000,0.000000e+000,-1.503624e+000,-1.503624e+000,-6.175417e-001,-6.949177e-001,-1.793372e+000,-9.072893e-001,-9.846653e-001,-3.387229e-005,-3.387229e-005,,,,,,,,,,,,,,,,,,,,
1524258606.911,,0.000000e+000,3.399641e+001,3.399862e+001,1,0,1.548387e+000,0.000000e+000,-2.462348e+000,-2.462348e+000,-1.559437e+000,-1.652311e+000,-2.769395e+000,-1.866483e+000,-1.959357e+000,-1.389028e-004,-1.389028e-004,,,,,,,,,,,,,,,,,,,,
1524258632.757,,0.000000e+000,3.399788e+001,3.399936e+001,1,0,1.806452e+000,0.000000e+000,-3.423972e+000,-3.423972e+000,-2.455556e+000,-2.564263e+000,-3.619301e+000,-2.650885e+000,-2.759592e+000,-2.388815e-004,-2.388815e-004,,,,,,,,,,,,,,,,,,,,
1524258658.420,,0.000000e+000,3.400009e+001,3.399936e+001,1,0,2.064516e+000,0.000000e+000,-3.839475e+000,-3.839475e+000,-2.904515e+000,-3.028464e+000,-3.778958e+000,-2.843998e+000,-2.967947e+000,-2.895439e-004,-2.895439e-004,,,,,,,,,,,,,,,,,,,,
1524258683.435,,0.000000e+000,3.399788e+001,3.399862e+001,1,0,2.322581e+000,0.000000e+000,-3.526207e+000,-3.526207e+000,-2.574472e+000,-2.714272e+000,-3.260926e+000,-2.309190e+000,-2.448990e+000,-2.542506e-004,-2.542506e-004,,,,,,,,,,,,,,,,,,,,
1524258708.583,,0.000000e+000,3.399936e+001,3.399862e+001,1,0,2.580645e+000,0.000000e+000,-2.678874e+000,-2.678874e+000,-1.710983e+000,-1.865489e+000,-2.360275e+000,-1.392385e+000,-1.546890e+000,-1.600918e-004,-1.600918e-004,,,,,,,,,,,,,,,,,,,,
1524258735.176,,0.000000e+000,3.399862e+001,3.399788e+001,1,0,2.838710e+000,0.000000e+000,-1.709926e+000,-1.709926e+000,-7.241051e-001,-8.942732e-001,-1.431544e+000,-4.457227e-001,-6.158908e-001,-5.233198e-005,-5.233198e-005,,,,,,,,,,,,,,,,,,,,
1524258760.896,,0.000000e+000,3.399714e+001,3.400009e+001,1,0,3.096774e+000,0.000000e+000,-8.085756e-001,-8.085756e-001,1.978156e-001,1.157361e-002,-6.122091e-001,3.941821e-001,2.079401e-001,4.825744e-005,4.825744e-005,,,,,,,,,,,,,,,,,,,,
1524258786.549,,0.000000e+000,3.399862e+001,3.399936e+001,1,0,3.354839e+000,0.000000e+000,-6.225681e-002,-6.225681e-002,9.608572e-001,7.604111e-001,-5.712107e-003,1.017402e+000,8.169558e-001,1.313678e-004,1.313678e-004,,,,,,,,,,,,,,,,,,,,
1524258812.204,,0.000000e+000,3.399788e+001,3.399862e+001,1,0,3.612903e+000,0.000000e+000,3.456168e-001,3.456168e-001,1.386072e+000,1.170223e+000,2.191286e-001,1.259584e+000,1.043735e+000,1.771706e-004,1.771706e-004,,,,,,,,,,,,,,,,,,,,
1524258837.860,,0.000000e+000,3.399714e+001,3.399936e+001,1,0,3.870968e+000,0.000000e+000,3.111314e-001,3.111314e-001,1.368349e+000,1.137622e+000,6.360244e-002,1.120820e+000,8.900935e-001,1.741204e-004,1.741204e-004,,,,,,,,,,,,,,,,,,,,
1524258876.348,,0.000000e+000,3.399936e+001,3.399788e+001,1,0,0.000000e+000,0.000000e+000,-8.834974e-002,-8.834974e-002,7.416559e-001,7.416559e-001,1.466444e-001,9.766501e-001,9.766501e-001,1.219446e-004,1.219446e-004,,,,,,,,,,,,,,,,,,,,
1524258901.998,,0.000000e+000,3.399641e+001,3.399714e+001,1,0,2.580645e-001,0.000000e+000,1.475547e-001,1.475547e-001,1.041420e+000,1.025982e+000,3.346528e-001,1.228518e+000,1.213080e+000,1.539598e-004,1.539598e-004,,,,,,,,,,,,,,,,,,,,
1524258927.218,,0.000000e+000,3.399788e+001,3.399936e+001,1,0,5.161290e-001,0.000000e+000,2.987716e-001,2.987716e-001,1.163492e+000,1.132822e+000,3.316128e-001,1.196333e+000,1.165663e+000,1.662622e-004,1.662622e-004,,,,,,,,,,,,,,,,,,,,
1524258953.209,,0.000000e+000,3.399862e+001,3.399862e+001,1,0,7.741935e-001,0.000000e+000,-1.205463e-002,-1.205463e-002,8.701334e-001,8.241943e-001,-1.357390e-001,7.464490e-001,7.005099e-001,1.327755e-004,1.327755e-004,,,,,,,,,,,,,,,,,,,,
1524258978.522,,0.000000e+000,3.399788e+001,3.399936e+001,1,0,1.032258e+000,0.000000e+000,-6.845197e-001,-6.845197e-001,2.151455e-001,1.536774e-001,-9.072449e-001,-7.579733e-003,-6.904781e-002,5.942202e-005,5.942202e-005,,,,,,,,,,,,,,,,,,,,
1524259004.650,,0.000000e+000,3.399788e+001,3.399788e+001,1,0,1.290323e+000,0.000000e+000,-1.546960e+000,-1.546960e+000,-6.292092e-001,-7.062885e-001,-1.834669e+000,-9.169187e-001,-9.939979e-001,-3.484121e-005,-3.484121e-005,,,,,,,,,,,,,,,,,,,,
1524259030.312,,0.000000e+000,3.399936e+001,3.399714e+001,1,0,1.548387e+000,0.000000e+000,-2.515450e+000,-2.515450e+000,-1.579393e+000,-1.671238e+000,-2.821573e+000,-1.885516e+000,-1.977361e+000,-1.408089e-004,-1.408089e-004,,,,,,,,,,,,,,,,,,,,
1524259055.890,,0.000000e+000,3.399788e+001,3.400009e+001,1,0,1.806452e+000,0.000000e+000,-3.438926e+000,-3.438926e+000,-2.484519e+000,-2.591393e+000,-3.630826e+000,-2.676419e+000,-2.783294e+000,-2.417910e-004,-2.417910e-004,,,,,,,,,,,,,,,,,,,,
1524259082.506,,0.000000e+000,3.400156e+001,3.400009e+001,1,0,2.064516e+000,0.000000e+000,-3.905089e+000,-3.905089e+000,-2.932143e+000,-3.054263e+000,-3.844851e+000,-2.871906e+000,-2.994025e+000,-2.922817e-004,-2.922817e-004,,,,,,,,,,,,,,,,,,,,
1524259107.369,,0.000000e+000,3.399936e+001,3.399862e+001,1,0,2.322581e+000,0.000000e+000,-3.583276e+000,-3.583276e+000,-2.594181e+000,-2.731510e+000,-3.320276e+000,-2.331180e+000,-2.468510e+000,-2.561026e-004,-2.561026e-004,,,,,,,,,,,,,,,,,,,,
1524259132.124,,0.000000e+000,3.399936e+001,3.399862e+001,1,0,2.580645e+000,0.000000e+000,-2.727093e+000,-2.727093e+000,-1.721500e+000,-1.874058e+000,-2.411190e+000,-1.405597e+000,-1.558156e+000,-1.609233e-004,-1.609233e-004,,,,,,,,,,,,,,,,,,,,
1524259157.734,,0.000000e+000,3.399936e+001,3.399862e+001,1,0,2.838710e+000,0.000000e+000,-1.750362e+000,-1.750362e+000,-7.268268e-001,-8.952100e-001,-1.473363e+000,-4.498276e-001,-6.182108e-001,-5.230555e-005,-5.230555e-005,,,,,,,,,,,,,,,,,,,,
1524259183.175,,0.000000e+000,3.399788e+001,3.399862e+001,1,0,3.096774e+000,0.000000e+000,-8.395514e-001,-8.395514e-001,2.008493e-001,1.778418e-002,-6.426464e-001,3.977543e-001,2.146891e-001,4.895841e-005,4.895841e-005,,,,,,,,,,,,,,,,,,,,
1524259208.298,,0.000000e+000,3.399862e+001,3.399862e+001,1,0,3.354839e+000,0.000000e+000,-8.987564e-002,-8.987564e-002,9.677995e-001,7.693887e-001,-3.123358e-002,1.026442e+000,8.280308e-001,1.324725e-004,1.324725e-004,,,,,,,,,,,,,,,,,,,,
1524259233.495,,0.000000e+000,3.399862e+001,3.399862e+001,1,0,3.612903e+000,0.000000e+000,3.198291e-001,3.198291e-001,1.395780e+000,1.183302e+000,1.945597e-001,1.270510e+000,1.058032e+000,1.786241e-004,1.786241e-004,,,,,,,,,,,,,,,,,,,,
1524259259.608,,0.000000e+000,3.399862e+001,3.399936e+001,1,0,3.870968e+000,0.000000e+000,2.319371e-001,2.319371e-001,1.374851e+000,1.145715e+000,-1.251468e-002,1.130399e+000,9.012634e-001,1.751623e-004,1.751623e-004,,,,,,,,,,,,,,,,,,,,
1524259297.636,,0.000000e+000,3.399936e+001,3.399936e+001,1,0,0.000000e+000,0.000000e+000,-1.187152e-001,-1.187152e-001,7.528692e-001,7.528692e-001,1.132956e-001,9.848799e-001,9.848799e-001,1.233585e-004,1.233585e-004,,,,,,,,,,,,,,,,,,,,
1524259323.182,,0.000000e+000,3.399788e+001,3.400009e+001,1,0,2.580645e-001,0.000000e+000,1.644922e-001,1.644922e-001,1.053449e+000,1.038283e+000,3.496855e-001,1.238643e+000,1.223476e+000,1.554108e-004,1.554108e-004,,,,,,,,,,,,,,,,,,,,
1524259348.837,,0.000000e+000,3.399862e+001,3.400009e+001,1,0,5.161290e-001,0.000000e+000,2.677958e-001,2.677958e-001,1.173907e+000,1.143680e+000,3.001583e-001,1.206269e+000,1.176042e+000,1.675785e-004,1.675785e-004,,,,,,,,,,,,,,,,,,,,
1524259374.793,,0.000000e+000,3.399862e+001,3.399862e+001,1,0,7.741935e-001,0.000000e+000,-5.188067e-002,-5.188067e-002,8.708951e-001,8.254344e-001,-1.703009e-001,7.524748e-001,7.070141e-001,1.330575e-004,1.330575e-004,,,,,,,,,,,,,,,,,,,,
1524259399.725,,0.000000e+000,3.399788e+001,3.399862e+001,1,0,1.032258e+000,0.000000e+000,-7.277027e-001,-7.277027e-001,2.124917e-001,1.518855e-001,-9.478335e-001,-7.639062e-003,-6.824529e-002,5.931596e-005,5.931596e-005,,,,,,,,,,,,,,,,,,,,
1524259425.483,,0.000000e+000,3.399862e+001,3.399862e+001,1,0,1.290323e+000,0.000000e+000,-1.596704e+000,-1.596704e+000,-6.390696e-001,-7.149110e-001,-1.881708e+000,-9.240732e-001,-9.999146e-001,-3.573377e-005,-3.573377e-005,,,,,,,,,,,,,,,,,,,,
1524259451.374,,0.000000e+000,3.399936e+001,3.399714e+001,1,0,1.548387e+000,0.000000e+000,-2.572366e+000,-2.572366e+000,-1.596377e+000,-1.686489e+000,-2.876116e+000,-1.900127e+000,-1.990240e+000,-1.424760e-004,-1.424760e-004,,,,,,,,,,,,,,,,,,,,
1524259476.931,,0.000000e+000,3.399862e+001,3.399788e+001,1,0,1.806452e+000,0.000000e+000,-3.499046e+000,-3.499046e+000,-2.505887e+000,-2.611293e+000,-3.688004e+000,-2.694844e+000,-2.800250e+000,-2.439434e-004,-2.439434e-004,,,,,,,,,,,,,,,,,,,,
1524259502.264,,0.000000e+000,3.399714e+001,3.399936e+001,1,0,2.064516e+000,0.000000e+000,-3.962768e+000,-3.962768e+000,-2.952288e+000,-3.072616e+000,-3.903473e+000,-2.892993e+000,-3.013321e+000,-2.942688e-004,-2.942688e-004,,,,,,,,,,,,,,,,,,,,
1524259527.912,,0.000000e+000,3.399862e+001,3.399862e+001,1,0,2.322581e+000,0.000000e+000,-3.686275e+000,-3.686275e+000,-2.609286e+000,-2.745651e+000,-3.425587e+000,-2.348598e+000,-2.484963e+000,-2.575238e-004,-2.575238e-004,,,,,,,,,,,,,,,,,,,,
1524259553.670,,0.000000e+000,3.399714e+001,3.399788e+001,1,0,2.580645e+000,0.000000e+000,-2.773633e+000,-2.773633e+000,-1.727730e+000,-1.877953e+000,-2.461756e+000,-1.415854e+000,-1.566076e+000,-1.613420e-004,-1.613420e-004,,,,,,,,,,,,,,,,,,,,
1524259578.405,,0.000000e+000,3.399936e+001,3.399862e+001,1,0,2.838710e+000,0.000000e+000,-1.790646e+000,-1.790646e+000,-7.264940e-001,-8.920850e-001,-1.517290e+000,-4.531375e-001,-6.187285e-001,-5.197601e-005,-5.197601e-005,,,,,,,,,,,,,,,,,,,,
1524259604.248,,0.000000e+000,3.399788e+001,3.399862e+001,1,0,3.096774e+000,0.000000e+000,-8.714427e-001,-8.714427e-001,2.083795e-001,2.936047e-002,-6.792551e-001,4.005671e-001,2.215481e-001,5.011784e-005,5.011784e-005,,,,,,,,,,,,,,,,,,,,
1524259629.169,,0.000000e+000,3.399862e+001,3.400009e+001,1,0,3.354839e+000,0.000000e+000,-1.185626e-001,-1.185626e-001,9.784920e-001,7.844086e-001,-6.349799e-002,1.033557e+000,8.394731e-001,1.339997e-004,1.339997e-004,,,,,,,,,,,,,,,,,,,,
1524259654.587,,0.000000e+000,3.399862e+001,3.399862e+001,1,0,3.612903e+000,0.000000e+000,2.931258e-001,2.931258e-001,1.406439e+000,1.198326e+000,1.658067e-001,1.279120e+000,1.071007e+000,1.801577e-004,1.801577e-004,,,,,,,,,,,,,,,,,,,,
1524259680.212,,0.000000e+000,3.399788e+001,3.399936e+001,1,0,3.870968e+000,0.000000e+000,2.475013e-001,2.475013e-001,1.377690e+000,1.154168e+000,7.764907e-003,1.137953e+000,9.144321e-001,1.758864e-004,1.758864e-004,,,,,,,,,,,,,,,,,,,,
1524259719.683,,0.000000e+000,3.400009e+001,3.399567e+001,1,0,0.000000e+000,0.000000e+000,-1.467918e-001,-1.467918e-001,7.631512e-001,7.631512e-001,8.147281e-002,9.914157e-001,9.914157e-001,1.245351e-004,1.245351e-004,,,,,,,,,,,,,,,,,,,,
1524259745.913,,0.000000e+000,3.400082e+001,3.399862e+001,1,0,2.580645e-001,0.000000e+000,1.371786e-001,1.371786e-001,1.064175e+000,1.049251e+000,3.196393e-001,1.246636e+000,1.231712e+000,1.566780e-004,1.566780e-004,,,,,,,,,,,,,,,,,,,,
1524259771.533,,0.000000e+000,3.399788e+001,3.399862e+001,1,0,5.161290e-001,0.000000e+000,2.363622e-001,2.363622e-001,1.181077e+000,1.151351e+000,2.690933e-001,1.213808e+000,1.184082e+000,1.684616e-004,1.684616e-004,,,,,,,,,,,,,,,,,,,,
1524259797.101,,0.000000e+000,3.399862e+001,3.399862e+001,1,0,7.741935e-001,0.000000e+000,-8.697642e-002,-8.697642e-002,8.749702e-001,8.303024e-001,-2.045515e-001,7.573951e-001,7.127273e-001,1.336219e-004,1.336219e-004,,,,,,,,,,,,,,,,,,,,
1524259822.097,,0.000000e+000,3.400082e+001,3.399788e+001,1,0,1.032258e+000,0.000000e+000,-7.719539e-001,-7.719539e-001,2.069981e-001,1.476473e-001,-9.866383e-001,-7.686276e-003,-6.703711e-002,5.881902e-005,5.881902e-005,,,,,,,,,,,,,,,,,,,,
1524259847.907,,0.000000e+000,3.399788e+001,3.399788e+001,1,0,1.290323e+000,0.000000e+000,-1.644312e+000,-1.644312e+000,-6.484190e-001,-7.224333e-001,-1.925707e+000,-9.298141e-001,-1.003828e+000,-3.664219e-005,-3.664219e-005,,,,,,,,,,,,,,,,,,,,
1524259873.775,,0.000000e+000,3.399641e+001,3.399936e+001,1,0,1.548387e+000,0.000000e+000,-2.622568e+000,-2.622568e+000,-1.610865e+000,-1.700002e+000,-2.923327e+000,-1.911623e+000,-2.000761e+000,-1.439035e-004,-1.439035e-004,,,,,,,,,,,,,,,,,,,,
1524259899.235,,0.000000e+000,3.399936e+001,3.399936e+001,1,0,1.806452e+000,0.000000e+000,-3.553368e+000,-3.553368e+000,-2.524724e+000,-2.628529e+000,-3.742105e+000,-2.713460e+000,-2.817266e+000,-2.458153e-004,-2.458153e-004,,,,,,,,,,,,,,,,,,,,
1524259924.356,,0.000000e+000,3.399862e+001,3.400009e+001,1,0,2.064516e+000,0.000000e+000,-4.016633e+000,-4.016633e+000,-2.970865e+000,-3.089335e+000,-3.956388e+000,-2.910620e+000,-3.029090e+000,-2.961209e-004,-2.961209e-004,,,,,,,,,,,,,,,,,,,,
1524259949.318,,0.000000e+000,3.399862e+001,3.399936e+001,1,0,2.322581e+000,0.000000e+000,-3.683986e+000,-3.683986e+000,-2.620712e+000,-2.754642e+000,-3.425771e+000,-2.362497e+000,-2.496426e+000,-2.585716e-004,-2.585716e-004,,,,,,,,,,,,,,,,,,,,
1524259975.199,,0.000000e+000,3.399567e+001,3.399862e+001,1,0,2.580645e+000,0.000000e+000,-2.811017e+000,-2.811017e+000,-1.732580e+000,-1.879790e+000,-2.502707e+000,-1.424270e+000,-1.571479e+000,-1.616384e-004,-1.616384e-004,,,,,,,,,,,,,,,,,,,,
1524260000.604,,0.000000e+000,3.399788e+001,3.399936e+001,1,0,2.838710e+000,0.000000e+000,-1.819028e+000,-1.819028e+000,-7.228540e-001,-8.846278e-001,-1.551998e+000,-4.558242e-001,-6.175979e-001,-5.130301e-005,-5.130301e-005,,,,,,,,,,,,,,,,,,,,
1524260026.595,,0.000000e+000,3.399714e+001,3.399936e+001,1,0,3.096774e+000,0.000000e+000,-9.010453e-001,-9.010453e-001,2.111439e-001,3.507483e-002,-7.092079e-001,4.029813e-001,2.269122e-001,5.069128e-005,5.069128e-005,,,,,,,,,,,,,,,,,,,,
1524260052.240,,0.000000e+000,3.399788e+001,3.399936e+001,1,0,3.354839e+000,0.000000e+000,-1.445029e-001,-1.445029e-001,9.838243e-001,7.933431e-001,-8.850157e-002,1.039826e+000,8.493445e-001,1.348879e-004,1.348879e-004,,,,,,,,,,,,,,,,,,,,
1524260077.795,,0.000000e+000,3.399788e+001,3.399936e+001,1,0,3.612903e+000,0.000000e+000,2.661173e-001,2.661173e-001,1.411152e+000,1.207949e+000,1.411266e-001,1.286161e+000,1.082958e+000,1.810141e-004,1.810141e-004,,,,,,,,,,,,,,,,,,,,
1524260103.978,,0.000000e+000,3.399936e+001,3.400009e+001,1,0,3.870968e+000,0.000000e+000,2.189670e-001,2.189670e-001,1.381065e+000,1.160735e+000,-1.771847e-002,1.144380e+000,9.240495e-001,1.765520e-004,1.765520e-004,,,,,,,,,,,,,,,,,,,,
1524260142.441,,0.000000e+000,3.399714e+001,3.399862e+001,1,0,0.000000e+000,0.000000e+000,-1.748684e-001,-1.748684e-001,7.701643e-001,7.701643e-001,5.195204e-002,9.969847e-001,9.969847e-001,1.253693e-004,1.253693e-004,,,,,,,,,,,,,,,,,,,,
1524260167.504,,0.000000e+000,3.399936e+001,3.399936e+001,1,0,2.580645e-001,0.000000e+000,1.084916e-001,1.084916e-001,1.070108e+000,1.055474e+000,2.917986e-001,1.253415e+000,1.238781e+000,1.573621e-004,1.573621e-004,,,,,,,,,,,,,,,,,,,,
1524260192.994,,0.000000e+000,3.399788e+001,3.399862e+001,1,0,5.161290e-001,0.000000e+000,2.114900e-001,2.114900e-001,1.189728e+000,1.160472e+000,2.421304e-001,1.220369e+000,1.191112e+000,1.694890e-004,1.694890e-004,,,,,,,,,,,,,,,,,,,,
1524260218.312,,0.000000e+000,3.399420e+001,3.399862e+001,1,0,7.741935e-001,0.000000e+000,-1.145953e-001,-1.145953e-001,8.798808e-001,8.361185e-001,-2.327712e-001,7.617050e-001,7.179426e-001,1.342397e-004,1.342397e-004,,,,,,,,,,,,,,,,,,,,
1524260243.818,,0.000000e+000,3.399862e+001,3.400009e+001,1,0,1.032258e+000,0.000000e+000,-8.044556e-001,-8.044556e-001,2.064881e-001,1.477105e-001,-1.018675e+000,-7.730868e-003,-6.650847e-002,5.890813e-005,5.890813e-005,,,,,,,,,,,,,,,,,,,,
1524260269.376,,0.000000e+000,3.399788e+001,3.399862e+001,1,0,1.290323e+000,0.000000e+000,-1.682155e+000,-1.682155e+000,-6.537725e-001,-7.264556e-001,-1.963106e+000,-9.347240e-001,-1.007407e+000,-3.711827e-005,-3.711827e-005,,,,,,,,,,,,,,,,,,,,
1524260295.418,,0.000000e+000,3.399714e+001,3.399936e+001,1,0,1.548387e+000,0.000000e+000,-2.668650e+000,-2.668650e+000,-1.625142e+000,-1.712311e+000,-2.965106e+000,-1.921598e+000,-2.008767e+000,-1.453544e-004,-1.453544e-004,,,,,,,,,,,,,,,,,,,,
1524260320.559,,0.000000e+000,3.399936e+001,3.399936e+001,1,0,1.806452e+000,0.000000e+000,-3.604334e+000,-3.604334e+000,-2.543997e+000,-2.645931e+000,-3.788095e+000,-2.727758e+000,-2.829693e+000,-2.477883e-004,-2.477883e-004,,,,,,,,,,,,,,,,,,,,
1524260345.292,,0.000000e+000,3.399788e+001,3.400009e+001,1,0,2.064516e+000,0.000000e+000,-4.062104e+000,-4.062104e+000,-2.985188e+000,-3.101565e+000,-4.001928e+000,-2.925012e+000,-3.041389e+000,-2.975385e-004,-2.975385e-004,,,,,,,,,,,,,,,,,,,,
1524260370.797,,0.000000e+000,3.399936e+001,3.399936e+001,1,0,2.322581e+000,0.000000e+000,-3.720760e+000,-3.720760e+000,-2.627255e+000,-2.758462e+000,-3.467821e+000,-2.374316e+000,-2.505523e+000,-2.591058e-004,-2.591058e-004,,,,,,,,,,,,,,,,,,,,
1524260396.450,,0.000000e+000,3.399862e+001,3.399936e+001,1,0,2.580645e+000,0.000000e+000,-2.841535e+000,-2.841535e+000,-1.732342e+000,-1.877248e+000,-2.540715e+000,-1.431522e+000,-1.576429e+000,-1.614112e-004,-1.614112e-004,,,,,,,,,,,,,,,,,,,,
1524260421.938,,0.000000e+000,3.399862e+001,3.400009e+001,1,0,2.838710e+000,0.000000e+000,-1.849699e+000,-1.849699e+000,-7.244654e-001,-8.834685e-001,-1.583257e+000,-4.580240e-001,-6.170272e-001,-5.126637e-005,-5.126637e-005,,,,,,,,,,,,,,,,,,,,
1524260446.878,,0.000000e+000,3.399714e+001,3.399862e+001,1,0,3.096774e+000,0.000000e+000,-9.245442e-001,-9.245442e-001,2.158822e-001,4.210407e-002,-7.354355e-001,4.049909e-001,2.312127e-001,5.143322e-005,5.143322e-005,,,,,,,,,,,,,,,,,,,,
1524260472.661,,0.000000e+000,3.399936e+001,3.399936e+001,1,0,3.354839e+000,0.000000e+000,-1.664759e-001,-1.664759e-001,9.903631e-001,8.035715e-001,-1.121873e-001,1.044652e+000,8.578601e-001,1.358675e-004,1.358675e-004,,,,,,,,,,,,,,,,,,,,
1524260498.519,,0.000000e+000,3.399862e+001,3.399862e+001,1,0,3.612903e+000,0.000000e+000,2.418555e-001,2.418555e-001,1.414488e+000,1.212121e+000,1.200892e-001,1.292722e+000,1.090355e+000,1.815728e-004,1.815728e-004,,,,,,,,,,,,,,,,,,,,
1524260523.537,,0.000000e+000,3.399788e+001,3.399862e+001,1,0,3.870968e+000,0.000000e+000,1.927214e-001,1.927214e-001,1.381628e+000,1.165980e+000,-3.919674e-002,1.149710e+000,9.340615e-001,1.769297e-004,1.769297e-004,,,,,,,,,,,,,,,,,,,,
1524260560.955,,0.000000e+000,3.399862e+001,3.399936e+001,1,0,0.000000e+000,0.000000e+000,-1.992828e-001,-1.992828e-001,7.759610e-001,7.759610e-001,2.637164e-002,1.001615e+000,1.001615e+000,1.259572e-004,1.259572e-004,,,,,,,,,,,,,,,,,,,,
1524260586.518,,0.000000e+000,3.399862e+001,3.399936e+001,1,0,2.580645e-001,0.000000e+000,8.911268e-002,8.911268e-002,1.080299e+000,1.065933e+000,2.682493e-001,1.259436e+000,1.245069e+000,1.585073e-004,1.585073e-004,,,,,,,,,,,,,,,,,,,,
1524260611.931,,0.000000e+000,3.399788e+001,3.399936e+001,1,0,5.161290e-001,0.000000e+000,1.879911e-001,1.879911e-001,1.195557e+000,1.166829e+000,2.186299e-001,1.226196e+000,1.197467e+000,1.701734e-004,1.701734e-004,,,,,,,,,,,,,,,,,,,,
1524260637.379,,0.000000e+000,3.399936e+001,3.399788e+001,1,0,7.741935e-001,0.000000e+000,-1.458762e-001,-1.458762e-001,8.777089e-001,8.346807e-001,-2.586273e-001,7.649578e-001,7.219297e-001,1.340515e-004,1.340515e-004,,,,,,,,,,,,,,,,,,,,
1524260662.929,,0.000000e+000,3.399862e+001,3.399936e+001,1,0,1.032258e+000,0.000000e+000,-8.371099e-001,-8.371099e-001,2.024370e-001,1.449450e-001,-1.047310e+000,-7.763047e-003,-6.525505e-002,5.850632e-005,5.850632e-005,,,,,,,,,,,,,,,,,,,,
1524260688.144,,0.000000e+000,3.399862e+001,3.399788e+001,1,0,1.290323e+000,0.000000e+000,-1.721675e+000,-1.721675e+000,-6.663586e-001,-7.378868e-001,-1.994175e+000,-9.388584e-001,-1.010387e+000,-3.841179e-005,-3.841179e-005,,,,,,,,,,,,,,,,,,,,
1524260713.280,,0.000000e+000,3.400009e+001,3.399862e+001,1,0,1.548387e+000,0.000000e+000,-2.708781e+000,-2.708781e+000,-1.637817e+000,-1.723605e+000,-3.001184e+000,-1.930219e+000,-2.016007e+000,-1.466385e-004,-1.466385e-004,,,,,,,,,,,,,,,,,,,,
1524260738.947,,0.000000e+000,3.399936e+001,3.399862e+001,1,0,1.806452e+000,0.000000e+000,-3.642329e+000,-3.642329e+000,-2.555401e+000,-2.655720e+000,-3.826222e+000,-2.739295e+000,-2.839613e+000,-2.489236e-004,-2.489236e-004,,,,,,,,,,,,,,,,,,,,
1524260764.570,,0.000000e+000,3.400009e+001,3.400009e+001,1,0,2.064516e+000,0.000000e+000,-4.099184e+000,-4.099184e+000,-2.997146e+000,-3.111310e+000,-4.039905e+000,-2.937867e+000,-3.052031e+000,-2.987116e-004,-2.987116e-004,,,,,,,,,,,,,,,,,,,,
1524260790.361,,0.000000e+000,3.399862e+001,3.399862e+001,1,0,2.322581e+000,0.000000e+000,-3.755245e+000,-3.755245e+000,-2.637621e+000,-2.765897e+000,-3.501922e+000,-2.384298e+000,-2.512574e+000,-2.600847e-004,-2.600847e-004,,,,,,,,,,,,,,,,,,,,
1524260815.454,,0.000000e+000,3.399936e+001,3.399936e+001,1,0,2.580645e+000,0.000000e+000,-2.870070e+000,-2.870070e+000,-1.737297e+000,-1.880181e+000,-2.570618e+000,-1.437845e+000,-1.580730e+000,-1.617826e-004,-1.617826e-004,,,,,,,,,,,,,,,,,,,,
1524260841.571,,0.000000e+000,3.399936e+001,3.399788e+001,1,0,2.838710e+000,0.000000e+000,-1.870146e+000,-1.870146e+000,-7.200167e-001,-8.787295e-001,-1.610112e+000,-4.599828e-001,-6.186955e-001,-5.063182e-005,-5.063182e-005,,,,,,,,,,,,,,,,,,,,
1524260866.774,,0.000000e+000,3.399862e+001,3.399936e+001,1,0,3.096774e+000,0.000000e+000,-9.460593e-001,-9.460593e-001,2.200294e-001,4.801917e-002,-7.592880e-001,4.068007e-001,2.347906e-001,5.208049e-005,5.208049e-005,,,,,,,,,,,,,,,,,,,,
1524260892.447,,0.000000e+000,3.399936e+001,3.399936e+001,1,0,3.354839e+000,0.000000e+000,-1.867704e-001,-1.867704e-001,9.933407e-001,8.089291e-001,-1.310318e-001,1.049079e+000,8.646677e-001,1.364029e-004,1.364029e-004,,,,,,,,,,,,,,,,,,,,
1524260918.553,,0.000000e+000,3.399936e+001,3.399788e+001,1,0,3.612903e+000,0.000000e+000,2.233921e-001,2.233921e-001,1.419374e+000,1.220161e+000,1.022608e-001,1.298243e+000,1.099030e+000,1.823528e-004,1.823528e-004,,,,,,,,,,,,,,,,,,,,
1524260944.203,,0.000000e+000,3.399936e+001,3.399936e+001,1,0,3.870968e+000,0.000000e+000,1.722744e-001,1.722744e-001,1.383650e+000,1.171094e+000,-5.668818e-002,1.154687e+000,9.421313e-001,1.774019e-004,1.774019e-004,,,,,,,,,,,,,,,,,,,,
1524260982.573,,0.000000e+000,3.399862e+001,3.399936e+001,1,0,0.000000e+000,0.000000e+000,-2.159152e-001,-2.159152e-001,7.857741e-001,7.857741e-001,3.974979e-003,1.005664e+000,1.005664e+000,1.270619e-004,1.270619e-004,,,,,,,,,,,,,,,,,,,,
1524261008.424,,0.000000e+000,3.399862e+001,3.399936e+001,1,0,2.580645e-001,0.000000e+000,7.095445e-002,7.095445e-002,1.087645e+000,1.073456e+000,2.480999e-001,1.264790e+000,1.250602e+000,1.593664e-004,1.593664e-004,,,,,,,,,,,,,,,,,,,,
1524261034.082,,0.000000e+000,3.399936e+001,3.400009e+001,1,0,5.161290e-001,0.000000e+000,1.686122e-001,1.686122e-001,1.200974e+000,1.172600e+000,1.990474e-001,1.231409e+000,1.203035e+000,1.708328e-004,1.708328e-004,,,,,,,,,,,,,,,,,,,,
1524261059.750,,0.000000e+000,3.399936e+001,3.399936e+001,1,0,7.741935e-001,0.000000e+000,-1.672389e-001,-1.672389e-001,8.790390e-001,8.367634e-001,-2.780962e-001,7.681817e-001,7.259061e-001,1.342462e-004,1.342462e-004,,,,,,,,,,,,,,,,,,,,
1524261085.080,,0.000000e+000,3.399936e+001,3.399936e+001,1,0,1.032258e+000,0.000000e+000,-8.644236e-001,-8.644236e-001,1.992286e-001,1.426848e-001,-1.071448e+000,-7.795960e-003,-6.433976e-002,5.822338e-005,5.822338e-005,,,,,,,,,,,,,,,,,,,,
1524261110.720,,0.000000e+000,3.400009e+001,3.399936e+001,1,0,1.290323e+000,0.000000e+000,-1.749294e+000,-1.749294e+000,-6.694579e-001,-7.402878e-001,-2.022459e+000,-9.426224e-001,-1.013452e+000,-3.865277e-005,-3.865277e-005,,,,,,,,,,,,,,,,,,,,
1524261135.848,,0.000000e+000,3.399788e+001,3.399862e+001,1,0,1.548387e+000,0.000000e+000,-2.742809e+000,-2.742809e+000,-1.647129e+000,-1.731433e+000,-3.033706e+000,-1.938026e+000,-2.022330e+000,-1.475675e-004,-1.475675e-004,,,,,,,,,,,,,,,,,,,,
1524261161.409,,0.000000e+000,3.399862e+001,3.399936e+001,1,0,1.806452e+000,0.000000e+000,-3.681849e+000,-3.681849e+000,-2.570622e+000,-2.669686e+000,-3.862066e+000,-2.750839e+000,-2.849903e+000,-2.504770e-004,-2.504770e-004,,,,,,,,,,,,,,,,,,,,
1524261186.852,,0.000000e+000,3.400156e+001,3.399862e+001,1,0,2.064516e+000,0.000000e+000,-4.137484e+000,-4.137484e+000,-3.010327e+000,-3.123644e+000,-4.078058e+000,-2.950902e+000,-3.064219e+000,-3.000210e-004,-3.000210e-004,,,,,,,,,,,,,,,,,,,,
1524261212.274,,0.000000e+000,3.400009e+001,3.399936e+001,1,0,2.322581e+000,0.000000e+000,-3.781643e+000,-3.781643e+000,-2.639642e+000,-2.765534e+000,-3.535108e+000,-2.393107e+000,-2.518998e+000,-2.601642e-004,-2.601642e-004,,,,,,,,,,,,,,,,,,,,
1524261238.017,,0.000000e+000,3.399788e+001,3.399936e+001,1,0,2.580645e+000,0.000000e+000,-2.896010e+000,-2.896010e+000,-1.738559e+000,-1.877397e+000,-2.600918e+000,-1.443467e+000,-1.582306e+000,-1.617287e-004,-1.617287e-004,,,,,,,,,,,,,,,,,,,,
1524261263.920,,0.000000e+000,3.399862e+001,3.399862e+001,1,0,2.838710e+000,0.000000e+000,-1.893797e+000,-1.893797e+000,-7.198972e-001,-8.747748e-001,-1.635775e+000,-4.618754e-001,-6.167531e-001,-5.040257e-005,-5.040257e-005,,,,,,,,,,,,,,,,,,,,
1524261288.946,,0.000000e+000,3.399862e+001,3.399862e+001,1,0,3.096774e+000,0.000000e+000,-9.623865e-001,-9.623865e-001,2.258011e-001,5.859816e-002,-7.799248e-001,4.082628e-001,2.410598e-001,5.295861e-005,5.295861e-005,,,,,,,,,,,,,,,,,,,,
1524261313.711,,0.000000e+000,3.400082e+001,3.399862e+001,1,0,3.354839e+000,0.000000e+000,-4.097658e+000,-4.097658e+000,8.900340e-001,-4.025014e+000,-4.072124e+000,9.155672e-001,-3.999481e+000,-1.962727e-005,-1.962727e-005,,,,,,,,,,,,,,,,,,,,
1524261339.139,,0.000000e+000,3.399936e+001,3.399862e+001,1,0,3.612903e+000,0.000000e+000,2.047761e-001,2.047761e-001,1.423380e+000,1.229559e+000,8.490758e-002,1.303512e+000,1.109691e+000,1.831029e-004,1.831029e-004,,,,,,,,,,,,,,,,,,,,
1524261364.789,,0.000000e+000,3.400009e+001,3.399788e+001,1,0,3.870968e+000,0.000000e+000,1.527428e-001,1.527428e-001,1.387419e+000,1.177147e+000,-7.614891e-002,1.158527e+000,9.482549e-001,1.780063e-004,1.780063e-004,,,,,,,,,,,,,,,,,,,,
1524261403.317,,0.000000e+000,3.399862e+001,3.399936e+001,1,0,0.000000e+000,0.000000e+000,-2.365148e-001,-2.365148e-001,7.910883e-001,7.910883e-001,-1.830732e-002,1.009296e+000,1.009296e+000,1.276445e-004,1.276445e-004,,,,,,,,,,,,,,,,,,,,
1524261428.965,,0.000000e+000,3.400009e+001,3.399714e+001,1,0,2.580645e-001,0.000000e+000,5.294881e-002,5.294881e-002,1.095484e+000,1.081418e+000,2.270568e-001,1.269592e+000,1.255526e+000,1.602933e-004,1.602933e-004,,,,,,,,,,,,,,,,,,,,
1524261453.930,,0.000000e+000,3.399862e+001,3.399936e+001,1,0,5.161290e-001,0.000000e+000,1.448081e-001,1.448081e-001,1.202743e+000,1.174911e+000,1.779787e-001,1.235913e+000,1.208082e+000,1.710316e-004,1.710316e-004,,,,,,,,,,,,,,,,,,,,
1524261478.626,,0.000000e+000,3.399936e+001,3.399936e+001,1,0,7.741935e-001,0.000000e+000,-1.928740e-001,-1.928740e-001,8.806663e-001,8.389865e-001,-3.026890e-001,7.708514e-001,7.291716e-001,1.344688e-004,1.344688e-004,,,,,,,,,,,,,,,,,,,,
1524261503.894,,0.000000e+000,3.399936e+001,3.399788e+001,1,0,1.032258e+000,0.000000e+000,-8.914320e-001,-8.914320e-001,1.971323e-001,1.416589e-001,-1.096388e+000,-7.823370e-003,-6.329679e-002,5.803190e-005,5.803190e-005,,,,,,,,,,,,,,,,,,,,
1524261529.422,,0.000000e+000,3.399862e+001,3.400009e+001,1,0,1.290323e+000,0.000000e+000,-1.781033e+000,-1.781033e+000,-6.770020e-001,-7.458233e-001,-2.050207e+000,-9.461758e-001,-1.014997e+000,-3.944451e-005,-3.944451e-005,,,,,,,,,,,,,,,,,,,,
1524261554.757,,0.000000e+000,3.399567e+001,3.399862e+001,1,0,1.548387e+000,0.000000e+000,-2.777142e+000,-2.777142e+000,-1.657678e+000,-1.739935e+000,-3.064338e+000,-1.944874e+000,-2.027131e+000,-1.486610e-004,-1.486610e-004,,,,,,,,,,,,,,,,,,,,
1524261580.420,,0.000000e+000,3.399936e+001,3.399862e+001,1,0,1.806452e+000,0.000000e+000,-3.717098e+000,-3.717098e+000,-2.582920e+000,-2.679108e+000,-3.893587e+000,-2.759410e+000,-2.855597e+000,-2.517557e-004,-2.517557e-004,,,,,,,,,,,,,,,,,,,,
1524261605.530,,0.000000e+000,3.399788e+001,3.399936e+001,1,0,2.064516e+000,0.000000e+000,-4.165102e+000,-4.165102e+000,-3.015354e+000,-3.125471e+000,-4.108622e+000,-2.958874e+000,-3.068990e+000,-3.004808e-004,-3.004808e-004,,,,,,,,,,,,,,,,,,,,
1524261631.243,,0.000000e+000,3.399862e+001,3.399788e+001,1,0,2.322581e+000,0.000000e+000,-3.808652e+000,-3.808652e+000,-2.644071e+000,-2.768715e+000,-3.565329e+000,-2.400748e+000,-2.525392e+000,-2.605368e-004,-2.605368e-004,,,,,,,,,,,,,,,,,,,,
1524261656.911,,0.000000e+000,3.400009e+001,3.399936e+001,1,0,2.580645e+000,0.000000e+000,-2.918288e+000,-2.918288e+000,-1.739358e+000,-1.877771e+000,-2.626631e+000,-1.447702e+000,-1.586115e+000,-1.617149e-004,-1.617149e-004,,,,,,,,,,,,,,,,,,,,
1524261683.126,,0.000000e+000,3.400009e+001,3.399714e+001,1,0,2.838710e+000,0.000000e+000,-1.912566e+000,-1.912566e+000,-7.186951e-001,-8.701733e-001,-1.657099e+000,-4.632278e-001,-6.147060e-001,-5.010125e-005,-5.010125e-005,,,,,,,,,,,,,,,,,,,,
1524261708.574,,0.000000e+000,3.399936e+001,3.399862e+001,1,0,3.096774e+000,0.000000e+000,-9.793240e-001,-9.793240e-001,2.288473e-001,6.446081e-002,-7.986624e-001,4.095089e-001,2.451224e-001,5.346697e-005,5.346697e-005,,,,,,,,,,,,,,,,,,,,
1524261733.360,,0.000000e+000,3.399936e+001,3.399862e+001,1,0,3.354839e+000,0.000000e+000,-2.160677e-001,-2.160677e-001,1.007030e+000,8.297574e-001,-1.662651e-001,1.056833e+000,8.795601e-001,1.383640e-004,1.383640e-004,,,,,,,,,,,,,,,,,,,,
1524261758.937,,0.000000e+000,3.399714e+001,3.399862e+001,1,0,3.612903e+000,0.000000e+000,1.902800e-001,1.902800e-001,1.428588e+000,1.237786e+000,6.901534e-002,1.307324e+000,1.116521e+000,1.838715e-004,1.838715e-004,,,,,,,,,,,,,,,,,,,,
1524261784.343,,0.000000e+000,3.400009e+001,3.399862e+001,1,0,3.870968e+000,0.000000e+000,1.326009e-001,1.326009e-001,1.386677e+000,1.181646e+000,-9.138571e-002,1.162690e+000,9.576594e-001,1.782273e-004,1.782273e-004,,,,,,,,,,,,,,,,,,,,
1524261822.533,,0.000000e+000,3.399862e+001,3.399862e+001,1,0,0.000000e+000,0.000000e+000,-2.546731e-001,-2.546731e-001,7.949829e-001,7.949829e-001,-3.672991e-002,1.012926e+000,1.012926e+000,1.280859e-004,1.280859e-004,,,,,,,,,,,,,,,,,,,,
1524261848.304,,0.000000e+000,3.399862e+001,3.400009e+001,1,0,2.580645e-001,0.000000e+000,3.570611e-002,3.570611e-002,1.101312e+000,1.087659e+000,2.079135e-001,1.273520e+000,1.259867e+000,1.608315e-004,1.608315e-004,,,,,,,,,,,,,,,,,,,,
1524261873.437,,0.000000e+000,3.399788e+001,3.399936e+001,1,0,5.161290e-001,0.000000e+000,1.269551e-001,1.269551e-001,1.208137e+000,1.180886e+000,1.589742e-001,1.240156e+000,1.212905e+000,1.716154e-004,1.716154e-004,,,,,,,,,,,,,,,,,,,,
1524261898.987,,0.000000e+000,3.399936e+001,3.399862e+001,1,0,7.741935e-001,0.000000e+000,-2.099641e-001,-2.099641e-001,8.860213e-001,8.452257e-001,-3.228143e-001,7.731711e-001,7.323755e-001,1.350542e-004,1.350542e-004,,,,,,,,,,,,,,,,,,,,
1524261924.587,,0.000000e+000,3.399493e+001,3.399936e+001,1,0,1.032258e+000,0.000000e+000,-9.169146e-001,-9.169146e-001,1.937319e-001,1.392307e-001,-1.118495e+000,-7.848401e-003,-6.234968e-002,5.769345e-005,5.769345e-005,,,,,,,,,,,,,,,,,,,,
1524261950.343,,0.000000e+000,3.399126e+001,3.399936e+001,1,0,1.290323e+000,0.000000e+000,-1.807736e+000,-1.807736e+000,-6.824201e-001,-7.504343e-001,-2.074181e+000,-9.488647e-001,-1.016879e+000,-3.998267e-005,-3.998267e-005,,,,,,,,,,,,,,,,,,,,
1524261975.676,,0.000000e+000,3.399862e+001,3.399936e+001,1,0,1.548387e+000,0.000000e+000,-2.805524e+000,-2.805524e+000,-1.666490e+000,-1.748627e+000,-3.089846e+000,-1.950812e+000,-2.032949e+000,-1.495367e-004,-1.495367e-004,,,,,,,,,,,,,,,,,,,,
1524262001.316,,0.000000e+000,3.399936e+001,3.399936e+001,1,0,1.806452e+000,0.000000e+000,-3.746395e+000,-3.746395e+000,-2.591755e+000,-2.687076e+000,-3.922197e+000,-2.767557e+000,-2.862878e+000,-2.526414e-004,-2.526414e-004,,,,,,,,,,,,,,,,,,,,
1524262027.081,,0.000000e+000,3.399936e+001,3.399936e+001,1,0,2.064516e+000,0.000000e+000,-4.198062e+000,-4.198062e+000,-3.028068e+000,-3.137271e+000,-4.138895e+000,-2.968901e+000,-3.078104e+000,-3.017714e-004,-3.017714e-004,,,,,,,,,,,,,,,,,,,,
1524262052.109,,0.000000e+000,3.399936e+001,3.399862e+001,1,0,2.322581e+000,0.000000e+000,-3.836423e+000,-3.836423e+000,-2.650967e+000,-2.774079e+000,-3.594627e+000,-2.409170e+000,-2.532282e+000,-2.611681e-004,-2.611681e-004,,,,,,,,,,,,,,,,,,,,
1524262077.655,,0.000000e+000,3.399862e+001,3.399862e+001,1,0,2.580645e+000,0.000000e+000,-2.940566e+000,-2.940566e+000,-1.739847e+000,-1.875058e+000,-2.652980e+000,-1.452261e+000,-1.587472e+000,-1.616135e-004,-1.616135e-004,,,,,,,,,,,,,,,,,,,,
1524262102.868,,0.000000e+000,3.400082e+001,3.399936e+001,1,0,2.838710e+000,0.000000e+000,-1.929503e+000,-1.929503e+000,-7.157931e-001,-8.642688e-001,-1.678674e+000,-4.649636e-001,-6.134393e-001,-4.959403e-005,-4.959403e-005,,,,,,,,,,,,,,,,,,,,
1524262128.198,,0.000000e+000,3.399936e+001,3.399788e+001,1,0,3.096774e+000,0.000000e+000,-9.993134e-001,-9.993134e-001,2.300087e-001,6.817281e-002,-8.185338e-001,4.107882e-001,2.489524e-001,5.376304e-005,5.376304e-005,,,,,,,,,,,,,,,,,,,,
1524262153.648,,0.000000e+000,3.399788e+001,3.399862e+001,1,0,3.354839e+000,0.000000e+000,-2.345312e-001,-2.345312e-001,1.010145e+000,8.340135e-001,-1.850361e-001,1.059640e+000,8.835085e-001,1.388279e-004,1.388279e-004,,,,,,,,,,,,,,,,,,,,
1524262179.039,,0.000000e+000,3.399862e+001,3.399936e+001,1,0,3.612903e+000,0.000000e+000,1.692225e-001,1.692225e-001,1.428853e+000,1.239703e+000,5.149797e-002,1.311128e+000,1.121978e+000,1.840495e-004,1.840495e-004,,,,,,,,,,,,,,,,,,,,
1524262204.829,,0.000000e+000,3.399862e+001,3.399936e+001,1,0,3.870968e+000,0.000000e+000,1.126116e-001,1.126116e-001,1.387482e+000,1.183076e+000,-1.084777e-001,1.166393e+000,9.619868e-001,1.784418e-004,1.784418e-004,,,,,,,,,,,,,,,,,,,,
1524262242.620,,0.000000e+000,3.399936e+001,3.399714e+001,1,0,0.000000e+000,0.000000e+000,-2.693217e-001,-2.693217e-001,8.031160e-001,8.031160e-001,-5.643845e-002,1.015999e+000,1.015999e+000,1.290004e-004,1.290004e-004,,,,,,,,,,,,,,,,,,,,
1524262267.227,,0.000000e+000,3.399936e+001,3.399936e+001,1,0,2.580645e-001,0.000000e+000,1.785306e-002,1.785306e-002,1.105328e+000,1.091816e+000,1.898317e-001,1.277306e+000,1.263795e+000,1.613011e-004,1.613011e-004,,,,,,,,,,,,,,,,,,,,
1524262291.928,,0.000000e+000,3.399936e+001,3.399714e+001,1,0,5.161290e-001,0.000000e+000,1.109331e-001,1.109331e-001,1.213701e+000,1.186517e+000,1.402591e-001,1.243027e+000,1.215843e+000,1.722903e-004,1.722903e-004,,,,,,,,,,,,,,,,,,,,
1524262317.278,,0.000000e+000,3.399936e+001,3.400009e+001,1,0,7.741935e-001,0.000000e+000,-2.351415e-001,-2.351415e-001,8.837413e-001,8.435313e-001,-3.432182e-001,7.756647e-001,7.354546e-001,1.348395e-004,1.348395e-004,,,,,,,,,,,,,,,,,,,,
1524262342.853,,0.000000e+000,3.399936e+001,3.400304e+001,1,0,1.032258e+000,0.000000e+000,-9.385824e-001,-9.385824e-001,1.946309e-001,1.408480e-001,-1.141083e+000,-7.869571e-003,-6.165242e-002,5.783141e-005,5.783141e-005,,,,,,,,,,,,,,,,,,,,
1524262368.376,,0.000000e+000,3.399862e+001,3.399936e+001,1,0,1.290323e+000,0.000000e+000,-1.836881e+000,-1.836881e+000,-6.896477e-001,-7.575864e-001,-2.099110e+000,-9.518763e-001,-1.019815e+000,-4.067985e-005,-4.067985e-005,,,,,,,,,,,,,,,,,,,,
1524262393.599,,0.000000e+000,3.399788e+001,3.399862e+001,1,0,1.548387e+000,0.000000e+000,-2.838178e+000,-2.838178e+000,-1.676343e+000,-1.757275e+000,-3.118348e+000,-1.956512e+000,-2.037445e+000,-1.505544e-004,-1.505544e-004,,,,,,,,,,,,,,,,,,,,
1524262418.957,,0.000000e+000,3.399788e+001,3.399788e+001,1,0,1.806452e+000,0.000000e+000,-3.777218e+000,-3.777218e+000,-2.600505e+000,-2.694406e+000,-3.951419e+000,-2.774705e+000,-2.868607e+000,-2.535338e-004,-2.535338e-004,,,,,,,,,,,,,,,,,,,,
1524262444.460,,0.000000e+000,3.399788e+001,3.399788e+001,1,0,2.064516e+000,0.000000e+000,-4.227359e+000,-4.227359e+000,-3.035645e+000,-3.142532e+000,-4.170100e+000,-2.978385e+000,-3.085273e+000,-3.024980e-004,-3.024980e-004,,,,,,,,,,,,,,,,,,,,
1524262470.030,,0.000000e+000,3.399788e+001,3.400082e+001,1,0,2.322581e+000,0.000000e+000,-3.861143e+000,-3.861143e+000,-2.654292e+000,-2.775600e+000,-3.624070e+000,-2.417219e+000,-2.538527e+000,-2.614076e-004,-2.614076e-004,,,,,,,,,,,,,,,,,,,,
1524262494.896,,0.000000e+000,3.399714e+001,3.399862e+001,1,0,2.580645e+000,0.000000e+000,-2.962081e+000,-2.962081e+000,-1.740574e+000,-1.873608e+000,-2.678497e+000,-1.456990e+000,-1.590024e+000,-1.615516e-004,-1.615516e-004,,,,,,,,,,,,,,,,,,,,
1524262520.791,,0.000000e+000,3.399936e+001,3.399936e+001,1,0,2.838710e+000,0.000000e+000,-1.951171e+000,-1.951171e+000,-7.152302e-001,-8.626888e-001,-1.702149e+000,-4.662084e-001,-6.136670e-001,-4.942252e-005,-4.942252e-005,,,,,,,,,,,,,,,,,,,,
1524262546.547,,0.000000e+000,3.399936e+001,3.399788e+001,1,0,3.096774e+000,0.000000e+000,-1.014572e+000,-1.014572e+000,2.355773e-001,7.543027e-002,-8.381631e-001,4.119866e-001,2.518395e-001,5.451654e-005,5.451654e-005,,,,,,,,,,,,,,,,,,,,
1524262572.227,,0.000000e+000,3.399936e+001,3.400009e+001,1,0,3.354839e+000,0.000000e+000,-2.507057e-001,-2.507057e-001,1.013657e+000,8.398448e-001,-2.019531e-001,1.062410e+000,8.885974e-001,1.393695e-004,1.393695e-004,,,,,,,,,,,,,,,,,,,,
1524262597.522,,0.000000e+000,3.399862e+001,3.399936e+001,1,0,3.612903e+000,0.000000e+000,1.512169e-001,1.512169e-001,1.430999e+000,1.243656e+000,3.512761e-002,1.314909e+000,1.127567e+000,1.844396e-004,1.844396e-004,,,,,,,,,,,,,,,,,,,,
1524262622.885,,0.000000e+000,3.399862e+001,3.399936e+001,1,0,3.870968e+000,0.000000e+000,4.440375e-002,4.440375e-002,1.386919e+000,1.186464e+000,-1.730658e-001,1.169450e+000,9.689947e-001,1.786058e-004,1.786058e-004,,,,,,,,,,,,,,,,,,,,
1524262661.168,,0.000000e+000,3.399788e+001,3.399936e+001,1,0,0.000000e+000,0.000000e+000,-2.905318e-001,-2.905318e-001,8.080261e-001,8.080261e-001,-7.947397e-002,1.019084e+000,1.019084e+000,1.293617e-004,1.293617e-004,,,,,,,,,,,,,,,,,,,,
1524262686.201,,0.000000e+000,3.399862e+001,3.400009e+001,1,0,2.580645e-001,0.000000e+000,9.155413e-004,9.155413e-004,1.112159e+000,1.098909e+000,1.696626e-001,1.280906e+000,1.267656e+000,1.620169e-004,1.620169e-004,,,,,,,,,,,,,,,,,,,,
1524262711.864,,0.000000e+000,3.399862e+001,3.400009e+001,1,0,5.161290e-001,0.000000e+000,9.430075e-002,9.430075e-002,1.219449e+000,1.193059e+000,1.217449e-001,1.246893e+000,1.220503e+000,1.728582e-004,1.728582e-004,,,,,,,,,,,,,,,,,,,,
1524262737.499,,0.000000e+000,3.399862e+001,3.399862e+001,1,0,7.741935e-001,0.000000e+000,-2.516213e-001,-2.516213e-001,8.877971e-001,8.485019e-001,-3.616133e-001,7.778051e-001,7.385098e-001,1.352706e-004,1.352706e-004,,,,,,,,,,,,,,,,,,,,
1524262762.642,,0.000000e+000,3.399936e+001,3.399936e+001,1,0,1.032258e+000,0.000000e+000,-9.636073e-001,-9.636073e-001,1.896697e-001,1.371859e-001,-1.161169e+000,-7.891636e-003,-6.037545e-002,5.728588e-005,5.728588e-005,,,,,,,,,,,,,,,,,,,,
1524262788.348,,0.000000e+000,3.399788e+001,3.400009e+001,1,0,1.290323e+000,0.000000e+000,-1.863737e+000,-1.863737e+000,-6.964630e-001,-7.625027e-001,-2.121148e+000,-9.538736e-001,-1.019913e+000,-4.144013e-005,-4.144013e-005,,,,,,,,,,,,,,,,,,,,
1524262813.998,,0.000000e+000,3.399788e+001,3.399936e+001,1,0,1.548387e+000,0.000000e+000,-2.864424e+000,-2.864424e+000,-1.682669e+000,-1.762034e+000,-3.142635e+000,-1.960881e+000,-2.040246e+000,-1.512131e-004,-1.512131e-004,,,,,,,,,,,,,,,,,,,,
1524262840.801,,0.000000e+000,3.399567e+001,3.399788e+001,1,0,1.806452e+000,0.000000e+000,-3.809415e+000,-3.809415e+000,-2.612859e+000,-2.705130e+000,-3.981073e+000,-2.784517e+000,-2.876788e+000,-2.547943e-004,-2.547943e-004,,,,,,,,,,,,,,,,,,,,
1524262866.314,,0.000000e+000,3.399862e+001,3.399788e+001,1,0,2.064516e+000,0.000000e+000,-4.302434e+000,-4.302434e+000,-3.042500e+000,-3.149383e+000,-4.246016e+000,-2.986082e+000,-3.092965e+000,-3.031699e-004,-3.031699e-004,,,,,,,,,,,,,,,,,,,,
1524262892.099,,0.000000e+000,3.399936e+001,3.399862e+001,1,0,2.322581e+000,0.000000e+000,-3.937285e+000,-3.937285e+000,-2.661711e+000,-2.781126e+000,-3.699319e+000,-2.423744e+000,-2.543159e+000,-2.621187e-004,-2.621187e-004,,,,,,,,,,,,,,,,,,,,
1524262917.714,,0.000000e+000,3.399862e+001,3.399936e+001,1,0,2.580645e+000,0.000000e+000,-2.984665e+000,-2.984665e+000,-1.743325e+000,-1.875584e+000,-2.701550e+000,-1.460209e+000,-1.592469e+000,-1.617700e-004,-1.617700e-004,,,,,,,,,,,,,,,,,,,,
1524262942.922,,0.000000e+000,3.399862e+001,3.399936e+001,1,0,2.838710e+000,0.000000e+000,-1.969024e+000,-1.969024e+000,-7.133807e-001,-8.582262e-001,-1.722821e+000,-4.671780e-001,-6.120235e-001,-4.909368e-005,-4.909368e-005,,,,,,,,,,,,,,,,,,,,
1524262968.275,,0.000000e+000,3.399936e+001,3.400009e+001,1,0,3.096774e+000,0.000000e+000,-1.030594e+000,-1.030594e+000,2.376803e-001,8.153498e-002,-8.552154e-001,4.130592e-001,2.569139e-001,5.493799e-005,5.493799e-005,,,,,,,,,,,,,,,,,,,,
1524262993.953,,0.000000e+000,3.399862e+001,3.400009e+001,1,0,3.354839e+000,0.000000e+000,-2.650492e-001,-2.650492e-001,1.017701e+000,8.477404e-001,-2.172652e-001,1.065485e+000,8.955244e-001,1.400247e-004,1.400247e-004,,,,,,,,,,,,,,,,,,,,
1524262993.953,,0.000000e+000,3.399862e+001,3.400009e+001,1,0,4.000000e+000,0.000000e+000,-6.500343e-002,-6.500343e-002,1.250431e+000,1.047786e+000,-2.946595e-001,1.020775e+000,8.181301e-001,1.632983e-004,1.632983e-004,,,,,,,,,,,,,,,,,,,,