File: Experimental Raw Data/MFn1 VRM/raw/MFn1_VRMac_36K_6000s.dc.raw
[Header]
TITLE,MPMS DC Measurement
BYAPP,MPMS Measurement,2.1,Raw with ABS
FILEOPENTIME, 1524317037.578000 4/21/2018, 7:23:57 AM

INFO, APPNAME, MPMS MultiVu Application, Revision 1.61,  Build 082

INFO, NAME, MFn1
INFO, WEIGHT, 1.000
INFO, AREA, 1.000
INFO, LENGTH, 1.000
INFO, SHAPE, 0
INFO, COMMENT,
INFO, SEQUENCE FILE: VRMac_36K_6000s_VRMde_35K.seq


INFO, BACKGROUND DATA FILE:, None


STARTUPAXIS,X,8,LINEAR,AUTO,0.000000,0.000000
STARTUPAXIS,Y1,10,LINEAR,AUTO,0.000000,0.000000


STARTUPGROUP,Longitudinal
FIELDGROUP,Longitudinal,1,3,4,5,6,8,9,10,11,12,13,14,15,16,17,18,19,20,21,22,23
FIELDGROUP,Transverse,1,3,4,5,6,8,9,24,25,26,27,28,29,30,31,32,33,34,35,36,37

PLOT_APPEARANCE,ALL,HORZ_GRID_ON,VERT_GRID_ON,MARKERS_ONLY

[Data]
Time,Comment,Field (Oe),Start Temperature (K),End Temperature (K),Scan,Rejected,Position (cm),Rot Position (deg),Long Voltage,Long Average Voltage,Long Detrended Voltage,Long Demeaned Voltage,Long Regression Fit,Long Detrended Fit,Long Demeaned Fit,Long Scaled Response,Long Avg. Scaled Response,Long Background Response,Long Response [w/ABS],Long Detrended Resp. [w/ABS],Long Fit [w/ABS],Long Detrended Fit [w/ABS],Trans Voltage,Trans Average Voltage,Trans Detrended Voltage,Trans Demeaned Voltage,Trans Regression Fit,Trans Detrended Fit,Trans Demeaned Fit,Trans Scaled Response,Trans Avg Scaled Response,Trans Background Response,Trans Response [w/ABS],Trans Detrended Resp. [w/ABS],Trans Fit [w/ABS],Trans Detrended Fit [w/ABS],
1524317037.561,,0.000000e+000,3.599653e+001,3.600068e+001,1,0,0.000000e+000,0.000000e+000,5.629053e-001,5.629053e-001,8.114237e-001,8.114237e-001,6.685959e-001,9.171142e-001,9.171142e-001,1.212842e-004,1.212842e-004,,,,,,,,,,,,,,,,,,,,
1524317063.501,,0.000000e+000,3.599653e+001,3.600150e+001,1,0,1.290323e-001,0.000000e+000,7.132067e-001,7.132067e-001,9.480852e-001,9.460581e-001,8.326633e-001,1.067542e+000,1.065515e+000,1.366261e-004,1.366261e-004,,,,,,,,,,,,,,,,,,,,
1524317088.664,,0.000000e+000,3.599984e+001,3.599984e+001,1,0,2.580645e-001,0.000000e+000,8.624399e-001,8.624399e-001,1.083751e+000,1.079347e+000,9.575471e-001,1.178858e+000,1.174454e+000,1.518832e-004,1.518832e-004,,,,,,,,,,,,,,,,,,,,
1524317113.760,,0.000000e+000,3.599902e+001,3.599819e+001,1,0,3.870968e-001,0.000000e+000,9.459068e-001,9.459068e-001,1.160084e+000,1.153245e+000,1.005461e+000,1.219638e+000,1.212799e+000,1.604270e-004,1.604270e-004,,,,,,,,,,,,,,,,,,,,
1524317139.005,,0.000000e+000,3.599736e+001,3.600068e+001,1,0,5.161290e-001,0.000000e+000,9.341573e-001,9.341573e-001,1.143827e+000,1.134373e+000,9.518493e-001,1.161519e+000,1.152065e+000,1.586919e-004,1.586919e-004,,,,,,,,,,,,,,,,,,,,
1524317164.145,,0.000000e+000,3.599819e+001,3.599819e+001,1,0,6.451613e-001,0.000000e+000,8.084230e-001,8.084230e-001,1.017249e+000,1.005139e+000,7.866870e-001,9.955128e-001,9.834026e-001,1.447409e-004,1.447409e-004,,,,,,,,,,,,,,,,,,,,
1524317189.336,,0.000000e+000,3.599819e+001,3.599902e+001,1,0,7.741935e-001,0.000000e+000,5.748073e-001,5.748073e-001,7.837276e-001,7.694849e-001,5.218549e-001,7.307751e-001,7.165324e-001,1.188910e-004,1.188910e-004,,,,,,,,,,,,,,,,,,,,
1524317214.464,,0.000000e+000,3.600068e+001,3.599736e+001,1,0,9.032258e-001,0.000000e+000,2.658122e-001,2.658122e-001,4.755591e-001,4.584900e-001,1.791088e-001,3.888557e-001,3.717866e-001,8.485520e-005,8.485520e-005,,,,,,,,,,,,,,,,,,,,
1524317239.419,,0.000000e+000,3.599736e+001,3.599902e+001,1,0,1.032258e+000,0.000000e+000,-1.077287e-001,-1.077287e-001,1.033428e-001,8.351710e-002,-2.185332e-001,-7.461730e-003,-2.728744e-002,4.372533e-005,4.372533e-005,,,,,,,,,,,,,,,,,,,,
1524317264.582,,0.000000e+000,3.599736e+001,3.599819e+001,1,0,1.161290e+000,0.000000e+000,-5.276570e-001,-5.276570e-001,-3.142571e-001,-3.363866e-001,-6.560731e-001,-4.426732e-001,-4.648027e-001,-2.452347e-006,-2.452347e-006,,,,,,,,,,,,,,,,,,,,
1524317289.760,,0.000000e+000,3.600150e+001,3.599736e+001,1,0,1.290323e+000,0.000000e+000,-9.709316e-001,-9.709316e-001,-7.553592e-001,-7.799920e-001,-1.122577e+000,-9.070050e-001,-9.316378e-001,-5.122164e-005,-5.122164e-005,,,,,,,,,,,,,,,,,,,,
1524317314.938,,0.000000e+000,3.599736e+001,3.599736e+001,1,0,1.419355e+000,0.000000e+000,-1.448844e+000,-1.448844e+000,-1.230996e+000,-1.257407e+000,-1.608188e+000,-1.390340e+000,-1.416751e+000,-1.038275e-004,-1.038275e-004,,,,,,,,,,,,,,,,,,,,
1524317340.103,,0.000000e+000,3.599819e+001,3.599819e+001,1,0,1.548387e+000,0.000000e+000,-1.934081e+000,-1.934081e+000,-1.713655e+000,-1.743167e+000,-2.093080e+000,-1.872653e+000,-1.902166e+000,-1.571744e-004,-1.571744e-004,,,,,,,,,,,,,,,,,,,,
1524317365.171,,0.000000e+000,3.599819e+001,3.599819e+001,1,0,1.677419e+000,0.000000e+000,-2.409094e+000,-2.409094e+000,-2.184282e+000,-2.216020e+000,-2.542082e+000,-2.317270e+000,-2.349008e+000,-2.092135e-004,-2.092135e-004,,,,,,,,,,,,,,,,,,,,
1524317390.431,,0.000000e+000,3.599819e+001,3.599819e+001,1,0,1.806452e+000,0.000000e+000,-2.805982e+000,-2.805982e+000,-2.579523e+000,-2.614161e+000,-2.894007e+000,-2.667549e+000,-2.702186e+000,-2.529468e-004,-2.529468e-004,,,,,,,,,,,,,,,,,,,,
1524317415.607,,0.000000e+000,3.599736e+001,3.599819e+001,1,0,1.935484e+000,0.000000e+000,-3.067063e+000,-3.067063e+000,-2.838294e+000,-2.875293e+000,-3.094665e+000,-2.865896e+000,-2.902895e+000,-2.816216e-004,-2.816216e-004,,,,,,,,,,,,,,,,,,,,
1524317440.787,,0.000000e+000,3.599736e+001,3.599902e+001,1,0,2.064516e+000,0.000000e+000,-3.142138e+000,-3.142138e+000,-2.910689e+000,-2.950137e+000,-3.101720e+000,-2.870271e+000,-2.909719e+000,-2.897425e-004,-2.897425e-004,,,,,,,,,,,,,,,,,,,,
1524317465.927,,0.000000e+000,3.599736e+001,3.599902e+001,1,0,2.193548e+000,0.000000e+000,-3.056993e+000,-3.056993e+000,-2.773278e+000,-2.814978e+000,-2.966095e+000,-2.682381e+000,-2.724081e+000,-2.746935e-004,-2.746935e-004,,,,,,,,,,,,,,,,,,,,
1524317491.115,,0.000000e+000,3.599653e+001,3.599736e+001,1,0,2.322581e+000,0.000000e+000,-2.749065e+000,-2.749065e+000,-2.463792e+000,-2.508485e+000,-2.622125e+000,-2.336852e+000,-2.381545e+000,-2.406934e-004,-2.406934e-004,,,,,,,,,,,,,,,,,,,,
1524317516.281,,0.000000e+000,3.600068e+001,3.599902e+001,1,0,2.451613e+000,0.000000e+000,-2.326085e+000,-2.326085e+000,-2.038477e+000,-2.084916e+000,-2.183939e+000,-1.896330e+000,-1.942769e+000,-1.938800e-004,-1.938800e-004,,,,,,,,,,,,,,,,,,,,
1524317541.436,,0.000000e+000,3.599819e+001,3.599736e+001,1,0,2.580645e+000,0.000000e+000,-1.855344e+000,-1.855344e+000,-1.563199e+000,-1.612346e+000,-1.704567e+000,-1.412422e+000,-1.461568e+000,-1.415931e-004,-1.415931e-004,,,,,,,,,,,,,,,,,,,,
1524317566.631,,0.000000e+000,3.600400e+001,3.599819e+001,1,0,2.709677e+000,0.000000e+000,-1.368124e+000,-1.368124e+000,-1.073714e+000,-1.125992e+000,-1.219177e+000,-9.247673e-001,-9.770453e-001,-8.774082e-005,-8.774082e-005,,,,,,,,,,,,,,,,,,,,
1524317591.792,,0.000000e+000,3.599736e+001,3.599736e+001,1,0,2.838710e+000,0.000000e+000,-8.848707e-001,-8.848707e-001,-5.869783e-001,-6.429295e-001,-7.509440e-001,-4.530515e-001,-5.090027e-001,-3.420618e-005,-3.420618e-005,,,,,,,,,,,,,,,,,,,,
1524317616.980,,0.000000e+000,3.599819e+001,3.599819e+001,1,0,2.967742e+000,0.000000e+000,-4.335088e-001,-4.335088e-001,-1.309137e-001,-1.891000e-001,-3.102648e-001,-7.669617e-003,-6.585598e-002,1.597883e-005,1.597883e-005,,,,,,,,,,,,,,,,,,,,
1524317642.092,,0.000000e+000,3.599819e+001,3.599819e+001,1,0,3.096774e+000,0.000000e+000,0.000000e+000,0.000000e+000,3.050790e-001,2.458904e-001,9.626906e-002,4.013480e-001,3.421595e-001,6.397064e-005,6.397064e-005,,,,,,,,,,,,,,,,,,,,
1524317667.290,,0.000000e+000,3.599736e+001,3.599819e+001,1,0,3.225806e+000,0.000000e+000,4.434272e-001,4.434272e-001,6.985561e-001,6.389955e-001,5.022187e-001,7.573477e-001,6.977870e-001,1.072888e-004,1.072888e-004,,,,,,,,,,,,,,,,,,,,
1524317692.496,,0.000000e+000,3.599819e+001,3.599819e+001,1,0,3.354839e+000,0.000000e+000,7.101549e-001,7.101549e-001,1.020401e+000,9.525106e-001,7.271013e-001,1.037347e+000,9.694569e-001,1.424888e-004,1.424888e-004,,,,,,,,,,,,,,,,,,,,
1524317717.608,,0.000000e+000,3.599736e+001,3.599819e+001,1,0,3.483871e+000,0.000000e+000,9.803922e-001,9.803922e-001,1.245332e+000,1.178661e+000,9.529970e-001,1.217937e+000,1.151266e+000,1.672844e-004,1.672844e-004,,,,,,,,,,,,,,,,,,,,
1524317742.811,,0.000000e+000,3.599736e+001,3.599902e+001,1,0,3.612903e+000,0.000000e+000,1.087816e+000,1.087816e+000,1.354009e+000,1.285159e+000,1.019722e+000,1.285915e+000,1.217065e+000,1.791149e-004,1.791149e-004,,,,,,,,,,,,,,,,,,,,
1524317767.959,,0.000000e+000,3.599819e+001,3.599819e+001,1,0,3.741935e+000,0.000000e+000,1.085985e+000,1.085985e+000,1.353790e+000,1.284308e+000,9.857191e-001,1.253524e+000,1.184042e+000,1.790194e-004,1.790194e-004,,,,,,,,,,,,,,,,,,,,
1524317793.155,,0.000000e+000,3.599736e+001,3.599984e+001,1,0,3.870968e+000,0.000000e+000,9.825284e-001,9.825284e-001,1.251556e+000,1.179831e+000,8.768915e-001,1.145919e+000,1.074194e+000,1.675891e-004,1.675891e-004,,,,,,,,,,,,,,,,,,,,
1524317818.805,,0.000000e+000,3.599736e+001,3.599736e+001,1,0,4.000000e+000,0.000000e+000,8.337529e-001,8.337529e-001,1.110502e+000,1.035007e+000,7.217875e-001,9.985370e-001,9.230415e-001,1.518217e-004,1.518217e-004,,,,,,,,,,,,,,,,,,,,
1524317857.066,,0.000000e+000,3.599984e+001,3.599570e+001,1,0,0.000000e+000,0.000000e+000,6.918440e-001,6.918440e-001,8.902234e-001,8.902234e-001,8.012911e-001,9.996704e-001,9.996704e-001,1.331161e-004,1.331161e-004,,,,,,,,,,,,,,,,,,,,
1524317881.713,,0.000000e+000,3.599819e+001,3.599736e+001,1,0,1.290323e-001,0.000000e+000,8.261234e-001,8.261234e-001,1.028392e+000,1.025959e+000,9.471293e-001,1.149398e+000,1.146965e+000,1.482082e-004,1.482082e-004,,,,,,,,,,,,,,,,,,,,
1524317907.374,,0.000000e+000,3.599984e+001,3.599902e+001,1,0,2.580645e-001,0.000000e+000,9.602503e-001,9.602503e-001,1.164860e+000,1.159938e+000,1.054627e+000,1.259237e+000,1.254315e+000,1.631431e-004,1.631431e-004,,,,,,,,,,,,,,,,,,,,
1524317932.269,,0.000000e+000,3.600068e+001,3.599570e+001,1,0,3.870968e-001,0.000000e+000,1.029831e+000,1.029831e+000,1.237935e+000,1.230382e+000,1.086644e+000,1.294747e+000,1.287194e+000,1.711035e-004,1.711035e-004,,,,,,,,,,,,,,,,,,,,
1524317957.707,,0.000000e+000,3.599984e+001,3.599736e+001,1,0,5.161290e-001,0.000000e+000,9.971771e-001,9.971771e-001,1.209811e+000,1.199993e+000,1.014529e+000,1.227163e+000,1.217345e+000,1.677725e-004,1.677725e-004,,,,,,,,,,,,,,,,,,,,
1524317982.860,,0.000000e+000,3.600068e+001,3.599653e+001,1,0,6.451613e-001,0.000000e+000,8.497750e-001,8.497750e-001,1.067470e+000,1.055972e+000,8.305860e-001,1.048281e+000,1.036783e+000,1.518113e-004,1.518113e-004,,,,,,,,,,,,,,,,,,,,
1524318008.048,,0.000000e+000,3.599736e+001,3.599902e+001,1,0,7.741935e-001,0.000000e+000,5.978485e-001,5.978485e-001,8.193194e-001,8.049662e-001,5.455531e-001,7.670240e-001,7.526708e-001,1.243567e-004,1.243567e-004,,,,,,,,,,,,,,,,,,,,
1524318033.193,,0.000000e+000,3.599736e+001,3.599570e+001,1,0,9.032258e-001,0.000000e+000,2.664225e-001,2.664225e-001,4.931130e-001,4.759865e-001,1.804163e-001,4.071068e-001,3.899803e-001,8.824556e-005,8.824556e-005,,,,,,,,,,,,,,,,,,,,
1524318058.326,,0.000000e+000,3.599902e+001,3.599736e+001,1,0,1.032258e+000,0.000000e+000,-1.304646e-001,-1.304646e-001,9.743914e-002,7.832851e-002,-2.356938e-001,-7.790010e-003,-2.690065e-002,4.438660e-005,4.438660e-005,,,,,,,,,,,,,,,,,,,,
1524318083.524,,0.000000e+000,3.599736e+001,3.599653e+001,1,0,1.161290e+000,0.000000e+000,-5.693141e-001,-5.693141e-001,-3.328062e-001,-3.535712e-001,-6.978282e-001,-4.613203e-001,-4.820853e-001,-3.263689e-006,-3.263689e-006,,,,,,,,,,,,,,,,,,,,
1524318108.692,,0.000000e+000,3.599902e+001,3.599819e+001,1,0,1.290323e+000,0.000000e+000,-1.035325e+000,-1.035325e+000,-7.941515e-001,-8.179090e-001,-1.185071e+000,-9.438977e-001,-9.676552e-001,-5.427119e-005,-5.427119e-005,,,,,,,,,,,,,,,,,,,,
1524318133.832,,0.000000e+000,3.599819e+001,3.599984e+001,1,0,1.419355e+000,0.000000e+000,-1.532311e+000,-1.532311e+000,-1.287763e+000,-1.313385e+000,-1.688563e+000,-1.444015e+000,-1.469638e+000,-1.089101e-004,-1.089101e-004,,,,,,,,,,,,,,,,,,,,
1524318158.680,,0.000000e+000,3.599653e+001,3.599736e+001,1,0,1.548387e+000,0.000000e+000,-2.036774e+000,-2.036774e+000,-1.788557e+000,-1.816270e+000,-2.190197e+000,-1.941980e+000,-1.969693e+000,-1.643197e-004,-1.643197e-004,,,,,,,,,,,,,,,,,,,,
1524318183.790,,0.000000e+000,3.599736e+001,3.600068e+001,1,0,1.677419e+000,0.000000e+000,-2.518349e+000,-2.518349e+000,-2.269473e+000,-2.299034e+000,-2.648213e+000,-2.399337e+000,-2.428898e+000,-2.175339e-004,-2.175339e-004,,,,,,,,,,,,,,,,,,,,
1524318208.831,,0.000000e+000,3.599819e+001,3.599819e+001,1,0,1.806452e+000,0.000000e+000,-2.926223e+000,-2.926223e+000,-2.674358e+000,-2.707015e+000,-3.011328e+000,-2.759464e+000,-2.792121e+000,-2.623444e-004,-2.623444e-004,,,,,,,,,,,,,,,,,,,,
1524318234.159,,0.000000e+000,3.599902e+001,3.599902e+001,1,0,1.935484e+000,0.000000e+000,-3.194018e+000,-3.194018e+000,-2.935572e+000,-2.969177e+000,-3.218905e+000,-2.960459e+000,-2.994064e+000,-2.913253e-004,-2.913253e-004,,,,,,,,,,,,,,,,,,,,
1524318259.679,,0.000000e+000,3.599570e+001,3.599819e+001,1,0,2.064516e+000,0.000000e+000,-3.310445e+000,-3.310445e+000,-2.998650e+000,-3.039452e+000,-3.272853e+000,-2.961058e+000,-3.001860e+000,-2.984545e-004,-2.984545e-004,,,,,,,,,,,,,,,,,,,,
1524318284.564,,0.000000e+000,3.599902e+001,3.599819e+001,1,0,2.193548e+000,0.000000e+000,-3.168994e+000,-3.168994e+000,-2.850430e+000,-2.891086e+000,-3.081534e+000,-2.762971e+000,-2.803626e+000,-2.822508e-004,-2.822508e-004,,,,,,,,,,,,,,,,,,,,
1524318309.210,,0.000000e+000,3.599819e+001,3.599653e+001,1,0,2.322581e+000,0.000000e+000,-2.800793e+000,-2.800793e+000,-2.529083e+000,-2.570817e+000,-2.677468e+000,-2.405757e+000,-2.447491e+000,-2.469351e-004,-2.469351e-004,,,,,,,,,,,,,,,,,,,,
1524318334.180,,0.000000e+000,3.599819e+001,3.599902e+001,1,0,2.451613e+000,0.000000e+000,-2.363012e+000,-2.363012e+000,-2.087077e+000,-2.131361e+000,-2.225926e+000,-1.949991e+000,-1.994275e+000,-1.983172e-004,-1.983172e-004,,,,,,,,,,,,,,,,,,,,
1524318359.333,,0.000000e+000,3.599902e+001,3.599819e+001,1,0,2.580645e+000,0.000000e+000,-1.877470e+000,-1.877470e+000,-1.596940e+000,-1.642200e+000,-1.732680e+000,-1.452150e+000,-1.497410e+000,-1.443600e-004,-1.443600e-004,,,,,,,,,,,,,,,,,,,,
1524318384.521,,0.000000e+000,3.599736e+001,3.599819e+001,1,0,2.709677e+000,0.000000e+000,-1.375448e+000,-1.375448e+000,-1.093155e+000,-1.141531e+000,-1.232245e+000,-9.499516e-001,-9.983275e-001,-8.894638e-005,-8.894638e-005,,,,,,,,,,,,,,,,,,,,
1524318409.649,,0.000000e+000,3.599819e+001,3.599819e+001,1,0,2.838710e+000,0.000000e+000,-8.825818e-001,-8.825818e-001,-5.947729e-001,-6.469383e-001,-7.528265e-001,-4.650176e-001,-5.171829e-001,-3.414469e-005,-3.414469e-005,,,,,,,,,,,,,,,,,,,,
1524318434.867,,0.000000e+000,3.599819e+001,3.599902e+001,1,0,2.967742e+000,0.000000e+000,-4.254215e-001,-4.254215e-001,-1.267642e-001,-1.835797e-001,-3.065227e-001,-7.865290e-003,-6.468087e-002,1.728137e-005,1.728137e-005,,,,,,,,,,,,,,,,,,,,
1524318459.999,,0.000000e+000,3.599819e+001,3.599902e+001,1,0,3.096774e+000,0.000000e+000,1.709010e-002,1.709010e-002,3.187141e-001,2.603417e-001,1.096807e-001,4.113046e-001,3.529323e-001,6.628651e-005,6.628651e-005,,,,,,,,,,,,,,,,,,,,
1524318485.172,,0.000000e+000,3.599819e+001,3.599902e+001,1,0,3.225806e+000,0.000000e+000,4.182498e-001,4.182498e-001,7.207786e-001,6.637504e-001,4.732401e-001,7.757689e-001,7.187407e-001,1.105869e-004,1.105869e-004,,,,,,,,,,,,,,,,,,,,
1524318510.335,,0.000000e+000,3.599819e+001,3.599819e+001,1,0,3.354839e+000,0.000000e+000,7.370108e-001,7.370108e-001,1.046657e+000,9.868568e-001,7.520242e-001,1.061670e+000,1.001870e+000,1.463745e-004,1.463745e-004,,,,,,,,,,,,,,,,,,,,
1524318535.528,,0.000000e+000,3.599736e+001,3.599984e+001,1,0,3.483871e+000,0.000000e+000,9.611658e-001,9.611658e-001,1.272831e+000,1.213705e+000,9.338529e-001,1.245518e+000,1.186392e+000,1.712789e-004,1.712789e-004,,,,,,,,,,,,,,,,,,,,
1524318560.698,,0.000000e+000,3.599736e+001,3.599819e+001,1,0,3.612903e+000,0.000000e+000,1.057755e+000,1.057755e+000,1.383818e+000,1.321120e+000,9.893954e-001,1.315458e+000,1.252760e+000,1.833407e-004,1.833407e-004,,,,,,,,,,,,,,,,,,,,
1524318585.864,,0.000000e+000,3.600068e+001,3.599819e+001,1,0,3.741935e+000,0.000000e+000,1.046006e+000,1.046006e+000,1.374389e+000,1.312490e+000,9.519860e-001,1.280369e+000,1.218470e+000,1.822378e-004,1.822378e-004,,,,,,,,,,,,,,,,,,,,
1524318611.054,,0.000000e+000,3.599736e+001,3.599819e+001,1,0,3.870968e+000,0.000000e+000,9.350728e-001,9.350728e-001,1.271119e+000,1.202966e+000,8.346344e-001,1.170681e+000,1.102527e+000,1.705671e-004,1.705671e-004,,,,,,,,,,,,,,,,,,,,
1524318636.167,,0.000000e+000,3.599902e+001,3.599819e+001,1,0,4.000000e+000,0.000000e+000,7.859922e-001,7.859922e-001,1.122291e+000,1.053716e+000,6.831725e-001,1.019472e+000,9.508964e-001,1.540493e-004,1.540493e-004,,,,,,,,,,,,,,,,,,,,
1524318673.958,,0.000000e+000,3.599819e+001,3.599902e+001,1,0,0.000000e+000,0.000000e+000,6.465248e-001,6.465248e-001,9.186329e-001,9.186329e-001,7.480160e-001,1.020124e+000,1.020124e+000,1.365851e-004,1.365851e-004,,,,,,,,,,,,,,,,,,,,
1524318699.145,,0.000000e+000,3.599736e+001,3.599819e+001,1,0,1.290323e-001,0.000000e+000,7.843137e-001,7.843137e-001,1.059329e+000,1.057140e+000,8.976640e-001,1.172679e+000,1.170491e+000,1.520130e-004,1.520130e-004,,,,,,,,,,,,,,,,,,,,
1524318724.293,,0.000000e+000,3.599653e+001,3.599902e+001,1,0,2.580645e-001,0.000000e+000,9.156939e-001,9.156939e-001,1.191193e+000,1.186779e+000,1.008390e+000,1.283889e+000,1.279475e+000,1.664260e-004,1.664260e-004,,,,,,,,,,,,,,,,,,,,
1524318749.481,,0.000000e+000,3.599819e+001,3.599819e+001,1,0,3.870968e-001,0.000000e+000,9.849699e-001,9.849699e-001,1.263609e+000,1.256692e+000,1.040799e+000,1.319438e+000,1.312522e+000,1.743551e-004,1.743551e-004,,,,,,,,,,,,,,,,,,,,
1524318774.624,,0.000000e+000,3.599819e+001,3.599902e+001,1,0,5.161290e-001,0.000000e+000,9.446861e-001,9.446861e-001,1.234128e+000,1.225311e+000,9.617726e-001,1.251215e+000,1.242397e+000,1.708751e-004,1.708751e-004,,,,,,,,,,,,,,,,,,,,
1524318799.819,,0.000000e+000,3.599736e+001,3.599902e+001,1,0,6.451613e-001,0.000000e+000,7.948424e-001,7.948424e-001,1.086958e+000,1.075817e+000,7.753025e-001,1.067418e+000,1.056277e+000,1.544952e-004,1.544952e-004,,,,,,,,,,,,,,,,,,,,
1524318824.745,,0.000000e+000,3.599819e+001,3.599819e+001,1,0,7.741935e-001,0.000000e+000,5.326924e-001,5.326924e-001,8.315782e-001,8.186036e-001,4.821487e-001,7.810345e-001,7.680599e-001,1.261384e-004,1.261384e-004,,,,,,,,,,,,,,,,,,,,
1524318849.913,,0.000000e+000,3.599902e+001,3.599984e+001,1,0,9.032258e-001,0.000000e+000,1.916533e-001,1.916533e-001,4.949607e-001,4.802040e-001,1.111379e-001,4.144453e-001,3.996886e-001,8.882013e-005,8.882013e-005,,,,,,,,,,,,,,,,,,,,
1524318875.115,,0.000000e+000,3.599819e+001,3.599819e+001,1,0,1.032258e+000,0.000000e+000,-2.134737e-001,-2.134737e-001,9.215655e-002,7.460202e-002,-3.135599e-001,-7.929618e-003,-2.548414e-002,4.427557e-005,4.427557e-005,,,,,,,,,,,,,,,,,,,,
1524318900.283,,0.000000e+000,3.599902e+001,3.599902e+001,1,0,1.161290e+000,0.000000e+000,-6.524758e-001,-6.524758e-001,-3.446168e-001,-3.657485e-001,-7.773585e-001,-4.694995e-001,-4.906312e-001,-3.973691e-006,-3.973691e-006,,,,,,,,,,,,,,,,,,,,
1524318925.359,,0.000000e+000,3.599902e+001,3.599902e+001,1,0,1.290323e+000,0.000000e+000,-1.134356e+000,-1.134356e+000,-8.172832e-001,-8.395485e-001,-1.275875e+000,-9.588022e-001,-9.810676e-001,-5.637229e-005,-5.637229e-005,,,,,,,,,,,,,,,,,,,,
1524318950.634,,0.000000e+000,3.599819e+001,3.599819e+001,1,0,1.419355e+000,0.000000e+000,-1.644465e+000,-1.644465e+000,-1.321986e+000,-1.345707e+000,-1.790534e+000,-1.468056e+000,-1.491776e+000,-1.122039e-004,-1.122039e-004,,,,,,,,,,,,,,,,,,,,
1524318975.804,,0.000000e+000,3.599902e+001,3.599736e+001,1,0,1.548387e+000,0.000000e+000,-2.150301e+000,-2.150301e+000,-1.824927e+000,-1.850422e+000,-2.298705e+000,-1.973330e+000,-1.998825e+000,-1.678567e-004,-1.678567e-004,,,,,,,,,,,,,,,,,,,,
1524319000.992,,0.000000e+000,3.599819e+001,3.599819e+001,1,0,1.677419e+000,0.000000e+000,-2.640269e+000,-2.640269e+000,-2.314395e+000,-2.341530e+000,-2.764527e+000,-2.438653e+000,-2.465788e+000,-2.219929e-004,-2.219929e-004,,,,,,,,,,,,,,,,,,,,
1524319026.155,,0.000000e+000,3.599819e+001,3.599902e+001,1,0,1.806452e+000,0.000000e+000,-3.054703e+000,-3.054703e+000,-2.723078e+000,-2.752229e+000,-3.135132e+000,-2.803506e+000,-2.832657e+000,-2.672292e-004,-2.672292e-004,,,,,,,,,,,,,,,,,,,,
1524319051.336,,0.000000e+000,3.599819e+001,3.599819e+001,1,0,1.935484e+000,0.000000e+000,-3.320058e+000,-3.320058e+000,-2.985037e+000,-3.016073e+000,-3.341626e+000,-3.006605e+000,-3.037642e+000,-2.962829e-004,-2.962829e-004,,,,,,,,,,,,,,,,,,,,
1524319076.513,,0.000000e+000,3.599819e+001,3.599902e+001,1,0,2.064516e+000,0.000000e+000,-3.383078e+000,-3.383078e+000,-3.045405e+000,-3.078789e+000,-3.345795e+000,-3.008122e+000,-3.041507e+000,-3.030797e-004,-3.030797e-004,,,,,,,,,,,,,,,,,,,,
1524319101.689,,0.000000e+000,3.599819e+001,3.599902e+001,1,0,2.193548e+000,0.000000e+000,-3.229114e+000,-3.229114e+000,-2.888986e+000,-2.924451e+000,-3.146139e+000,-2.806010e+000,-2.841476e+000,-2.859647e-004,-2.859647e-004,,,,,,,,,,,,,,,,,,,,
1524319127.169,,0.000000e+000,3.599902e+001,3.599902e+001,1,0,2.322581e+000,0.000000e+000,-2.898909e+000,-2.898909e+000,-2.557943e+000,-2.594441e+000,-2.783324e+000,-2.442357e+000,-2.478855e+000,-2.495708e-004,-2.495708e-004,,,,,,,,,,,,,,,,,,,,
1524319152.505,,0.000000e+000,3.599653e+001,3.599736e+001,1,0,2.451613e+000,0.000000e+000,-2.450446e+000,-2.450446e+000,-2.107448e+000,-2.146399e+000,-2.321916e+000,-1.978918e+000,-2.017869e+000,-2.000095e-004,-2.000095e-004,,,,,,,,,,,,,,,,,,,,
1524319177.727,,0.000000e+000,3.599819e+001,3.599984e+001,1,0,2.580645e+000,0.000000e+000,-1.954833e+000,-1.954833e+000,-1.608905e+000,-1.650780e+000,-1.819405e+000,-1.473477e+000,-1.515352e+000,-1.451456e-004,-1.451456e-004,,,,,,,,,,,,,,,,,,,,
1524319202.868,,0.000000e+000,3.599819e+001,3.600068e+001,1,0,2.709677e+000,0.000000e+000,-1.444266e+000,-1.444266e+000,-1.094850e+000,-1.138326e+000,-1.313112e+000,-9.636949e-001,-1.007171e+000,-8.856744e-005,-8.856744e-005,,,,,,,,,,,,,,,,,,,,
1524319228.031,,0.000000e+000,3.599653e+001,3.599819e+001,1,0,2.838710e+000,0.000000e+000,-9.452964e-001,-9.452964e-001,-5.948462e-001,-6.386585e-001,-8.219481e-001,-4.714979e-001,-5.153102e-001,-3.351680e-005,-3.351680e-005,,,,,,,,,,,,,,,,,,,,
1524319253.274,,0.000000e+000,3.599902e+001,3.599902e+001,1,0,2.967742e+000,0.000000e+000,-4.715038e-001,-4.715038e-001,-1.197634e-001,-1.653922e-001,-3.597167e-001,-7.976380e-003,-5.360520e-002,1.878293e-005,1.878293e-005,,,,,,,,,,,,,,,,,,,,
1524319278.431,,0.000000e+000,3.599902e+001,3.600150e+001,1,0,3.096774e+000,0.000000e+000,-2.487221e-002,-2.487221e-002,3.294917e-001,2.828677e-001,6.260344e-002,4.169674e-001,3.703434e-001,6.823108e-005,6.823108e-005,,,,,,,,,,,,,,,,,,,,
1524319303.574,,0.000000e+000,3.599984e+001,3.599653e+001,1,0,3.225806e+000,0.000000e+000,3.784238e-001,3.784238e-001,7.350139e-001,6.859117e-001,4.298409e-001,7.864311e-001,7.373288e-001,1.128278e-004,1.128278e-004,,,,,,,,,,,,,,,,,,,,
1524319329.015,,0.000000e+000,3.599902e+001,3.599819e+001,1,0,3.354839e+000,0.000000e+000,7.038987e-001,7.038987e-001,1.061815e+000,1.011521e+000,7.183378e-001,1.076254e+000,1.025960e+000,1.487781e-004,1.487781e-004,,,,,,,,,,,,,,,,,,,,
1524319354.218,,0.000000e+000,3.599653e+001,3.599653e+001,1,0,3.483871e+000,0.000000e+000,9.279011e-001,9.279011e-001,1.288662e+000,1.236679e+000,9.012342e-001,1.261995e+000,1.210012e+000,1.736818e-004,1.736818e-004,,,,,,,,,,,,,,,,,,,,
1524319379.388,,0.000000e+000,3.599902e+001,3.599819e+001,1,0,3.612903e+000,0.000000e+000,1.036088e+000,1.036088e+000,1.398464e+000,1.344029e+000,9.703829e-001,1.332759e+000,1.278324e+000,1.856583e-004,1.856583e-004,,,,,,,,,,,,,,,,,,,,
1524319404.563,,0.000000e+000,3.600068e+001,3.599902e+001,1,0,3.741935e+000,0.000000e+000,1.020829e+000,1.020829e+000,1.383791e+000,1.327947e+000,9.343777e-001,1.297340e+000,1.241496e+000,1.839161e-004,1.839161e-004,,,,,,,,,,,,,,,,,,,,
1524319429.074,,0.000000e+000,3.599736e+001,3.599819e+001,1,0,3.870968e+000,0.000000e+000,9.156939e-001,9.156939e-001,1.281487e+000,1.223421e+000,8.198848e-001,1.185678e+000,1.127612e+000,1.724891e-004,1.724891e-004,,,,,,,,,,,,,,,,,,,,
1524319454.127,,0.000000e+000,3.599819e+001,3.599736e+001,1,0,4.000000e+000,0.000000e+000,7.620355e-001,7.620355e-001,1.128150e+000,1.069583e+000,6.665901e-001,1.032705e+000,9.741379e-001,1.554888e-004,1.554888e-004,,,,,,,,,,,,,,,,,,,,
1524319491.897,,0.000000e+000,3.599819e+001,3.599736e+001,1,0,0.000000e+000,0.000000e+000,6.324865e-001,6.324865e-001,9.387351e-001,9.387351e-001,7.269220e-001,1.033171e+000,1.033171e+000,1.389403e-004,1.389403e-004,,,,,,,,,,,,,,,,,,,,
1524319517.092,,0.000000e+000,3.599653e+001,3.599819e+001,1,0,1.290323e-001,0.000000e+000,7.696651e-001,7.696651e-001,1.078108e+000,1.076216e+000,8.785520e-001,1.186995e+000,1.185103e+000,1.541689e-004,1.541689e-004,,,,,,,,,,,,,,,,,,,,
1524319542.250,,0.000000e+000,3.599819e+001,3.599819e+001,1,0,2.580645e-001,0.000000e+000,9.039444e-001,9.039444e-001,1.215181e+000,1.211438e+000,9.880762e-001,1.299312e+000,1.295570e+000,1.691337e-004,1.691337e-004,,,,,,,,,,,,,,,,,,,,
1524319567.476,,0.000000e+000,3.599984e+001,3.599902e+001,1,0,3.870968e-001,0.000000e+000,9.698634e-001,9.698634e-001,1.282861e+000,1.277191e+000,1.022866e+000,1.335864e+000,1.330194e+000,1.765059e-004,1.765059e-004,,,,,,,,,,,,,,,,,,,,
1524319593.114,,0.000000e+000,3.599984e+001,3.600068e+001,1,0,5.161290e-001,0.000000e+000,9.314107e-001,9.314107e-001,1.247509e+000,1.240227e+000,9.496656e-001,1.265764e+000,1.258482e+000,1.724089e-004,1.724089e-004,,,,,,,,,,,,,,,,,,,,
1524319618.226,,0.000000e+000,3.599984e+001,3.599902e+001,1,0,6.451613e-001,0.000000e+000,7.786679e-001,7.786679e-001,1.096203e+000,1.087093e+000,7.625847e-001,1.080120e+000,1.071010e+000,1.555923e-004,1.555923e-004,,,,,,,,,,,,,,,,,,,,
1524319643.902,,0.000000e+000,3.599819e+001,3.599653e+001,1,0,7.741935e-001,0.000000e+000,5.175860e-001,5.175860e-001,8.368270e-001,8.259827e-001,4.705875e-001,7.898285e-001,7.789842e-001,1.268396e-004,1.268396e-004,,,,,,,,,,,,,,,,,,,,
1524319669.360,,0.000000e+000,3.599736e+001,3.600150e+001,1,0,9.032258e-001,0.000000e+000,1.689174e-001,1.689174e-001,4.904716e-001,4.779347e-001,9.740312e-002,4.189574e-001,4.064204e-001,8.848474e-005,8.848474e-005,,,,,,,,,,,,,,,,,,,,
1524319694.517,,0.000000e+000,3.599736e+001,3.599902e+001,1,0,1.032258e+000,0.000000e+000,-2.381933e-001,-2.381933e-001,8.508866e-002,7.060272e-002,-3.312997e-001,-8.017672e-003,-2.250361e-002,4.364955e-005,4.364955e-005,,,,,,,,,,,,,,,,,,,,
1524319719.678,,0.000000e+000,3.599653e+001,3.599902e+001,1,0,1.161290e+000,0.000000e+000,-6.846723e-001,-6.846723e-001,-3.595740e-001,-3.756485e-001,-7.996143e-001,-4.745160e-001,-4.905904e-001,-5.540816e-006,-5.540816e-006,,,,,,,,,,,,,,,,,,,,
1524319744.841,,0.000000e+000,3.599984e+001,3.599736e+001,1,0,1.290323e+000,0.000000e+000,-1.166094e+000,-1.166094e+000,-8.391931e-001,-8.572342e-001,-1.296958e+000,-9.700564e-001,-9.880975e-001,-5.857438e-005,-5.857438e-005,,,,,,,,,,,,,,,,,,,,
1524319770.029,,0.000000e+000,3.599984e+001,3.599902e+001,1,0,1.419355e+000,0.000000e+000,-1.673457e+000,-1.673457e+000,-1.344255e+000,-1.363654e+000,-1.813266e+000,-1.484064e+000,-1.503464e+000,-1.144316e-004,-1.144316e-004,,,,,,,,,,,,,,,,,,,,
1524319795.176,,0.000000e+000,3.599984e+001,3.599819e+001,1,0,1.548387e+000,0.000000e+000,-2.187228e+000,-2.187228e+000,-1.856317e+000,-1.877482e+000,-2.325727e+000,-1.994816e+000,-2.015981e+000,-1.710543e-004,-1.710543e-004,,,,,,,,,,,,,,,,,,,,
1524319820.384,,0.000000e+000,3.599902e+001,3.599984e+001,1,0,1.677419e+000,0.000000e+000,-2.679332e+000,-2.679332e+000,-2.346826e+000,-2.369672e+000,-2.795872e+000,-2.463367e+000,-2.486212e+000,-2.252976e-004,-2.252976e-004,,,,,,,,,,,,,,,,,,,,
1524319845.560,,0.000000e+000,3.599902e+001,3.599984e+001,1,0,1.806452e+000,0.000000e+000,-3.095445e+000,-3.095445e+000,-2.761233e+000,-2.785844e+000,-3.166270e+000,-2.832058e+000,-2.856669e+000,-2.711387e-004,-2.711387e-004,,,,,,,,,,,,,,,,,,,,
1524319870.700,,0.000000e+000,3.599736e+001,3.599736e+001,1,0,1.935484e+000,0.000000e+000,-3.353933e+000,-3.353933e+000,-3.017334e+000,-3.043728e+000,-3.374064e+000,-3.037466e+000,-3.063859e+000,-2.995191e-004,-2.995191e-004,,,,,,,,,,,,,,,,,,,,
1524319895.855,,0.000000e+000,3.600068e+001,3.599819e+001,1,0,2.064516e+000,0.000000e+000,-3.411002e+000,-3.411002e+000,-3.073028e+000,-3.100798e+000,-3.376886e+000,-3.038913e+000,-3.066683e+000,-3.057767e-004,-3.057767e-004,,,,,,,,,,,,,,,,,,,,
1524319921.073,,0.000000e+000,3.599819e+001,3.599984e+001,1,0,2.193548e+000,0.000000e+000,-3.253223e+000,-3.253223e+000,-2.913371e+000,-2.942451e+000,-3.174244e+000,-2.834392e+000,-2.863472e+000,-2.882798e-004,-2.882798e-004,,,,,,,,,,,,,,,,,,,,
1524319946.231,,0.000000e+000,3.599819e+001,3.599902e+001,1,0,2.322581e+000,0.000000e+000,-2.915084e+000,-2.915084e+000,-2.573412e+000,-2.604372e+000,-2.808571e+000,-2.466899e+000,-2.497860e+000,-2.508891e-004,-2.508891e-004,,,,,,,,,,,,,,,,,,,,
1524319971.407,,0.000000e+000,3.599819e+001,3.599819e+001,1,0,2.451613e+000,0.000000e+000,-2.461738e+000,-2.461738e+000,-2.118614e+000,-2.151317e+000,-2.341902e+000,-1.998778e+000,-2.031481e+000,-2.008252e-004,-2.008252e-004,,,,,,,,,,,,,,,,,,,,
1524319996.582,,0.000000e+000,3.599819e+001,3.599984e+001,1,0,2.580645e+000,0.000000e+000,-1.954376e+000,-1.954376e+000,-1.610303e+000,-1.644875e+000,-1.831723e+000,-1.487650e+000,-1.522222e+000,-1.448609e-004,-1.448609e-004,,,,,,,,,,,,,,,,,,,,
1524320021.767,,0.000000e+000,3.599984e+001,3.599736e+001,1,0,2.709677e+000,0.000000e+000,-1.443351e+000,-1.443351e+000,-1.096954e+000,-1.132357e+000,-1.319351e+000,-9.729540e-001,-1.008357e+000,-8.832635e-005,-8.832635e-005,,,,,,,,,,,,,,,,,,,,
1524320046.920,,0.000000e+000,3.599736e+001,3.600234e+001,1,0,2.838710e+000,0.000000e+000,-9.402609e-001,-9.402609e-001,-5.927848e-001,-6.294777e-001,-8.236971e-001,-4.762210e-001,-5.129138e-001,-3.280343e-005,-3.280343e-005,,,,,,,,,,,,,,,,,,,,
1524320072.003,,0.000000e+000,3.599819e+001,3.599570e+001,1,0,2.967742e+000,0.000000e+000,-4.582284e-001,-4.582284e-001,-1.084963e-001,-1.473910e-001,-3.577835e-001,-8.051406e-003,-4.694602e-002,2.049883e-005,2.049883e-005,,,,,,,,,,,,,,,,,,,,
1524320097.276,,0.000000e+000,3.599736e+001,3.599819e+001,1,0,3.096774e+000,0.000000e+000,-1.220722e-002,-1.220722e-002,3.388908e-001,2.987495e-001,6.981644e-002,4.209145e-001,3.807731e-001,6.975025e-005,6.975025e-005,,,,,,,,,,,,,,,,,,,,
1524320122.436,,0.000000e+000,3.599819e+001,3.599902e+001,1,0,3.225806e+000,0.000000e+000,3.909361e-001,3.909361e-001,7.430898e-001,7.015234e-001,4.417247e-001,7.938783e-001,7.523119e-001,1.142430e-004,1.142430e-004,,,,,,,,,,,,,,,,,,,,
1524320147.614,,0.000000e+000,3.599902e+001,3.599736e+001,1,0,3.354839e+000,0.000000e+000,7.209888e-001,7.209888e-001,1.074834e+000,1.031760e+000,7.325213e-001,1.086366e+000,1.043292e+000,1.507401e-004,1.507401e-004,,,,,,,,,,,,,,,,,,,,
1524320172.777,,0.000000e+000,3.599819e+001,3.599902e+001,1,0,3.483871e+000,0.000000e+000,9.469749e-001,9.469749e-001,1.301791e+000,1.257197e+000,9.189135e-001,1.273730e+000,1.229136e+000,1.756700e-004,1.756700e-004,,,,,,,,,,,,,,,,,,,,
1524320197.982,,0.000000e+000,3.599902e+001,3.599653e+001,1,0,3.612903e+000,0.000000e+000,1.049363e+000,1.049363e+000,1.405278e+000,1.360471e+000,9.888089e-001,1.344724e+000,1.299917e+000,1.870238e-004,1.870238e-004,,,,,,,,,,,,,,,,,,,,
1524320223.125,,0.000000e+000,3.599902e+001,3.599736e+001,1,0,3.741935e+000,0.000000e+000,1.029526e+000,1.029526e+000,1.387647e+000,1.340714e+000,9.509833e-001,1.309104e+000,1.262171e+000,1.849473e-004,1.849473e-004,,,,,,,,,,,,,,,,,,,,
1524320248.326,,0.000000e+000,3.600068e+001,3.600068e+001,1,0,3.870968e+000,0.000000e+000,9.246967e-001,9.246967e-001,1.284297e+000,1.236028e+000,8.366609e-001,1.196262e+000,1.147992e+000,1.734436e-004,1.734436e-004,,,,,,,,,,,,,,,,,,,,
1524320273.476,,0.000000e+000,3.599653e+001,3.600068e+001,1,0,4.000000e+000,0.000000e+000,7.678340e-001,7.678340e-001,1.128799e+000,1.079400e+000,6.807896e-001,1.041755e+000,9.923559e-001,1.561884e-004,1.561884e-004,,,,,,,,,,,,,,,,,,,,
1524320311.244,,0.000000e+000,3.599736e+001,3.599902e+001,1,0,0.000000e+000,0.000000e+000,6.424048e-001,6.424048e-001,9.534988e-001,9.534988e-001,7.312590e-001,1.042353e+000,1.042353e+000,1.404764e-004,1.404764e-004,,,,,,,,,,,,,,,,,,,,
1524320336.427,,0.000000e+000,3.599984e+001,3.599819e+001,1,0,1.290323e-001,0.000000e+000,7.830930e-001,7.830930e-001,1.095731e+000,1.094154e+000,8.847710e-001,1.197409e+000,1.195832e+000,1.560692e-004,1.560692e-004,,,,,,,,,,,,,,,,,,,,
1524320361.525,,0.000000e+000,3.599984e+001,3.599653e+001,1,0,2.580645e-001,0.000000e+000,9.190509e-001,9.190509e-001,1.233022e+000,1.229857e+000,9.969514e-001,1.310922e+000,1.307757e+000,1.711121e-004,1.711121e-004,,,,,,,,,,,,,,,,,,,,
1524320386.773,,0.000000e+000,3.600150e+001,3.599984e+001,1,0,3.870968e-001,0.000000e+000,9.802396e-001,9.802396e-001,1.295979e+000,1.291318e+000,1.031267e+000,1.347006e+000,1.342345e+000,1.779211e-004,1.779211e-004,,,,,,,,,,,,,,,,,,,,
1524320411.940,,0.000000e+000,3.599736e+001,3.599819e+001,1,0,5.161290e-001,0.000000e+000,9.457542e-001,9.457542e-001,1.263104e+000,1.256891e+000,9.593069e-001,1.276657e+000,1.270444e+000,1.741892e-004,1.741892e-004,,,,,,,,,,,,,,,,,,,,
1524320437.098,,0.000000e+000,3.599736e+001,3.600068e+001,1,0,6.451613e-001,0.000000e+000,7.870603e-001,7.870603e-001,1.106450e+000,1.098671e+000,7.699165e-001,1.089306e+000,1.081527e+000,1.567999e-004,1.567999e-004,,,,,,,,,,,,,,,,,,,,
1524320462.251,,0.000000e+000,3.600068e+001,3.599902e+001,1,0,7.741935e-001,0.000000e+000,5.189593e-001,5.189593e-001,8.402331e-001,8.310007e-001,4.753656e-001,7.966394e-001,7.874070e-001,1.273144e-004,1.273144e-004,,,,,,,,,,,,,,,,,,,,
1524320487.464,,0.000000e+000,3.599902e+001,3.599736e+001,1,0,9.032258e-001,0.000000e+000,1.670863e-001,1.670863e-001,4.894201e-001,4.787633e-001,1.001723e-001,4.225061e-001,4.118493e-001,8.848240e-005,8.848240e-005,,,,,,,,,,,,,,,,,,,,
1524320512.635,,0.000000e+000,3.599902e+001,3.600068e+001,1,0,1.032258e+000,0.000000e+000,-2.450599e-001,-2.450599e-001,7.896815e-002,6.685384e-002,-3.321139e-001,-8.085880e-003,-2.020019e-002,4.309365e-005,4.309365e-005,,,,,,,,,,,,,,,,,,,,
1524320537.815,,0.000000e+000,3.599819e+001,3.599984e+001,1,0,1.161290e+000,0.000000e+000,-6.961166e-001,-6.961166e-001,-3.711534e-001,-3.847795e-001,-8.033813e-001,-4.784181e-001,-4.920442e-001,-6.674789e-006,-6.674789e-006,,,,,,,,,,,,,,,,,,,,
1524320563.008,,0.000000e+000,3.599819e+001,3.599653e+001,1,0,1.290323e+000,0.000000e+000,-1.182574e+000,-1.182574e+000,-8.556137e-001,-8.707432e-001,-1.304904e+000,-9.779440e-001,-9.930735e-001,-6.023324e-005,-6.023324e-005,,,,,,,,,,,,,,,,,,,,
1524320588.191,,0.000000e+000,3.599902e+001,3.599819e+001,1,0,1.419355e+000,0.000000e+000,-1.692989e+000,-1.692989e+000,-1.364740e+000,-1.381029e+000,-1.824144e+000,-1.495895e+000,-1.512185e+000,-1.165199e-004,-1.165199e-004,,,,,,,,,,,,,,,,,,,,
1524320613.329,,0.000000e+000,3.599736e+001,3.599819e+001,1,0,1.548387e+000,0.000000e+000,-2.210117e+000,-2.210117e+000,-1.881029e+000,-1.899006e+000,-2.339989e+000,-2.010901e+000,-2.028878e+000,-1.735807e-004,-1.735807e-004,,,,,,,,,,,,,,,,,,,,
1524320638.501,,0.000000e+000,3.599736e+001,3.599819e+001,1,0,1.677419e+000,0.000000e+000,-2.704814e+000,-2.704814e+000,-2.374444e+000,-2.393546e+000,-2.813682e+000,-2.483312e+000,-2.502413e+000,-2.281280e-004,-2.281280e-004,,,,,,,,,,,,,,,,,,,,
1524320663.679,,0.000000e+000,3.599819e+001,3.599902e+001,1,0,1.806452e+000,0.000000e+000,-3.120928e+000,-3.120928e+000,-2.788573e+000,-2.809062e+000,-3.186728e+000,-2.854373e+000,-2.874861e+000,-2.739251e-004,-2.739251e-004,,,,,,,,,,,,,,,,,,,,
1524320688.870,,0.000000e+000,3.599902e+001,3.599736e+001,1,0,1.935484e+000,0.000000e+000,-3.378958e+000,-3.378958e+000,-3.046362e+000,-3.068452e+000,-3.394352e+000,-3.061757e+000,-3.083846e+000,-3.024659e-004,-3.024659e-004,,,,,,,,,,,,,,,,,,,,
1524320714.063,,0.000000e+000,3.599819e+001,3.600150e+001,1,0,2.064516e+000,0.000000e+000,-3.428550e+000,-3.428550e+000,-3.094777e+000,-3.118159e+000,-3.396528e+000,-3.062755e+000,-3.086137e+000,-3.079046e-004,-3.079046e-004,,,,,,,,,,,,,,,,,,,,
1524320739.193,,0.000000e+000,3.599653e+001,3.599736e+001,1,0,2.193548e+000,0.000000e+000,-3.265431e+000,-3.265431e+000,-2.930313e+000,-2.954950e+000,-3.191231e+000,-2.856113e+000,-2.880750e+000,-2.898647e-004,-2.898647e-004,,,,,,,,,,,,,,,,,,,,
1524320764.386,,0.000000e+000,3.599984e+001,3.599653e+001,1,0,2.322581e+000,0.000000e+000,-2.923018e+000,-2.923018e+000,-2.585881e+000,-2.612287e+000,-2.822957e+000,-2.485820e+000,-2.512226e+000,-2.519625e-004,-2.519625e-004,,,,,,,,,,,,,,,,,,,,
1524320789.574,,0.000000e+000,3.599819e+001,3.599984e+001,1,0,2.451613e+000,0.000000e+000,-2.462959e+000,-2.462959e+000,-2.124395e+000,-2.151336e+000,-2.352490e+000,-2.013926e+000,-2.040868e+000,-2.011321e-004,-2.011321e-004,,,,,,,,,,,,,,,,,,,,
1524320814.737,,0.000000e+000,3.599653e+001,3.600068e+001,1,0,2.580645e+000,0.000000e+000,-1.952239e+000,-1.952239e+000,-1.612453e+000,-1.640770e+000,-1.838524e+000,-1.498738e+000,-1.527055e+000,-1.447459e-004,-1.447459e-004,,,,,,,,,,,,,,,,,,,,
1524320839.922,,0.000000e+000,3.599902e+001,3.599570e+001,1,0,2.709677e+000,0.000000e+000,-1.434958e+000,-1.434958e+000,-1.094001e+000,-1.123685e+000,-1.321112e+000,-9.801553e-001,-1.009839e+000,-8.764331e-005,-8.764331e-005,,,,,,,,,,,,,,,,,,,,
1524320865.072,,0.000000e+000,3.599819e+001,3.599736e+001,1,0,2.838710e+000,0.000000e+000,-9.315633e-001,-9.315633e-001,-5.886855e-001,-6.200235e-001,-8.226362e-001,-4.797585e-001,-5.110965e-001,-3.198667e-005,-3.198667e-005,,,,,,,,,,,,,,,,,,,,
1524320890.263,,0.000000e+000,3.599902e+001,3.599984e+001,1,0,2.967742e+000,0.000000e+000,-4.469368e-001,-4.469368e-001,-1.031055e-001,-1.356210e-001,-3.519420e-001,-8.110785e-003,-4.062629e-002,2.149299e-005,2.149299e-005,,,,,,,,,,,,,,,,,,,,
1524320915.425,,0.000000e+000,3.599819e+001,3.600150e+001,1,0,3.096774e+000,0.000000e+000,1.068132e-003,1.068132e-003,3.462495e-001,3.123854e-001,7.889239e-002,4.240737e-001,3.902096e-001,7.097640e-005,7.097640e-005,,,,,,,,,,,,,,,,,,,,
1524320940.593,,0.000000e+000,3.600150e+001,3.599819e+001,1,0,3.225806e+000,0.000000e+000,4.075685e-001,4.075685e-001,7.541866e-001,7.188234e-001,4.530910e-001,7.997092e-001,7.643460e-001,1.158862e-004,1.158862e-004,,,,,,,,,,,,,,,,,,,,
1524320965.726,,0.000000e+000,3.599736e+001,3.599819e+001,1,0,3.354839e+000,0.000000e+000,7.379263e-001,7.379263e-001,1.085430e+000,1.049481e+000,7.467855e-001,1.094289e+000,1.058340e+000,1.523647e-004,1.523647e-004,,,,,,,,,,,,,,,,,,,,
1524320990.964,,0.000000e+000,3.599736e+001,3.600150e+001,1,0,3.483871e+000,0.000000e+000,9.622339e-001,9.622339e-001,1.310998e+000,1.274228e+000,9.343132e-001,1.283077e+000,1.246307e+000,1.771763e-004,1.771763e-004,,,,,,,,,,,,,,,,,,,,
1524321016.134,,0.000000e+000,3.599819e+001,3.599902e+001,1,0,3.612903e+000,0.000000e+000,1.062181e+000,1.062181e+000,1.411984e+000,1.374148e+000,1.004418e+000,1.354222e+000,1.316386e+000,1.882289e-004,1.882289e-004,,,,,,,,,,,,,,,,,,,,
1524321041.320,,0.000000e+000,3.599984e+001,3.599819e+001,1,0,3.741935e+000,0.000000e+000,1.041581e+000,1.041581e+000,1.391716e+000,1.352144e+000,9.683567e-001,1.318492e+000,1.278920e+000,1.858882e-004,1.858882e-004,,,,,,,,,,,,,,,,,,,,
1524321066.493,,0.000000e+000,3.599902e+001,3.600068e+001,1,0,3.870968e+000,0.000000e+000,9.326314e-001,9.326314e-001,1.284308e+000,1.243610e+000,8.528872e-001,1.204563e+000,1.163866e+000,1.739461e-004,1.739461e-004,,,,,,,,,,,,,,,,,,,,
1524321091.653,,0.000000e+000,3.599653e+001,3.599736e+001,1,0,4.000000e+000,0.000000e+000,7.760739e-001,7.760739e-001,1.128720e+000,1.086932e+000,6.965398e-001,1.049186e+000,1.007398e+000,1.566982e-004,1.566982e-004,,,,,,,,,,,,,,,,,,,,
1524321129.406,,0.000000e+000,3.599736e+001,3.599984e+001,1,0,0.000000e+000,0.000000e+000,6.572061e-001,6.572061e-001,9.683160e-001,9.683160e-001,7.385384e-001,1.049648e+000,1.049648e+000,1.420731e-004,1.420731e-004,,,,,,,,,,,,,,,,,,,,
1524321154.569,,0.000000e+000,3.599984e+001,3.599819e+001,1,0,1.290323e-001,0.000000e+000,7.983520e-001,7.983520e-001,1.111089e+000,1.109775e+000,8.928127e-001,1.205549e+000,1.204236e+000,1.577094e-004,1.577094e-004,,,,,,,,,,,,,,,,,,,,
1524321179.757,,0.000000e+000,3.600150e+001,3.599984e+001,1,0,2.580645e-001,0.000000e+000,9.329366e-001,9.329366e-001,1.247302e+000,1.244726e+000,1.005529e+000,1.319895e+000,1.317318e+000,1.726246e-004,1.726246e-004,,,,,,,,,,,,,,,,,,,,
1524321204.940,,0.000000e+000,3.599902e+001,3.599819e+001,1,0,3.870968e-001,0.000000e+000,9.925994e-001,9.925994e-001,1.308252e+000,1.304412e+000,1.040556e+000,1.356209e+000,1.352368e+000,1.792526e-004,1.792526e-004,,,,,,,,,,,,,,,,,,,,
1524321230.135,,0.000000e+000,3.599819e+001,3.599902e+001,1,0,5.161290e-001,0.000000e+000,9.060807e-001,9.060807e-001,1.271640e+000,1.266147e+000,9.196482e-001,1.285208e+000,1.279715e+000,1.752034e-004,1.752034e-004,,,,,,,,,,,,,,,,,,,,
1524321255.310,,0.000000e+000,3.599984e+001,3.599736e+001,1,0,6.451613e-001,0.000000e+000,7.428092e-001,7.428092e-001,1.111858e+000,1.105270e+000,7.276114e-001,1.096660e+000,1.090072e+000,1.574391e-004,1.574391e-004,,,,,,,,,,,,,,,,,,,,
1524321280.461,,0.000000e+000,3.599819e+001,3.600150e+001,1,0,7.741935e-001,0.000000e+000,5.221637e-001,5.221637e-001,8.414448e-001,8.338818e-001,4.823599e-001,8.016410e-001,7.940780e-001,1.274642e-004,1.274642e-004,,,,,,,,,,,,,,,,,,,,
1524321305.661,,0.000000e+000,3.599819e+001,3.599984e+001,1,0,9.032258e-001,0.000000e+000,1.672389e-001,1.672389e-001,4.872557e-001,4.782763e-001,1.053335e-001,4.253503e-001,4.163709e-001,8.831950e-005,8.831950e-005,,,,,,,,,,,,,,,,,,,,
1524321330.817,,0.000000e+000,3.599984e+001,3.599902e+001,1,0,1.032258e+000,0.000000e+000,-2.493324e-001,-2.493324e-001,7.223158e-002,6.209849e-002,-3.297020e-001,-8.138051e-003,-1.827115e-002,4.243017e-005,4.243017e-005,,,,,,,,,,,,,,,,,,,,
1524321355.997,,0.000000e+000,3.600068e+001,3.600068e+001,1,0,1.161290e+000,0.000000e+000,-7.034409e-001,-7.034409e-001,-3.811748e-001,-3.925984e-001,-8.038589e-001,-4.815928e-001,-4.930165e-001,-7.674840e-006,-7.674840e-006,,,,,,,,,,,,,,,,,,,,
1524321381.127,,0.000000e+000,3.599653e+001,3.599984e+001,1,0,1.290323e+000,0.000000e+000,-1.191577e+000,-1.191577e+000,-8.682976e-001,-8.808094e-001,-1.307753e+000,-9.844739e-001,-9.969856e-001,-6.151455e-005,-6.151455e-005,,,,,,,,,,,,,,,,,,,,
1524321406.368,,0.000000e+000,3.599984e+001,3.599902e+001,1,0,1.419355e+000,0.000000e+000,-1.705653e+000,-1.705653e+000,-1.381233e+000,-1.394549e+000,-1.830000e+000,-1.505580e+000,-1.518895e+000,-1.182118e-004,-1.182118e-004,,,,,,,,,,,,,,,,,,,,
1524321431.523,,0.000000e+000,3.600068e+001,3.600068e+001,1,0,1.548387e+000,0.000000e+000,-2.225986e+000,-2.225986e+000,-1.900972e+000,-1.915977e+000,-2.348903e+000,-2.023889e+000,-2.038893e+000,-1.756280e-004,-1.756280e-004,,,,,,,,,,,,,,,,,,,,
1524321456.688,,0.000000e+000,3.599736e+001,3.599819e+001,1,0,1.677419e+000,0.000000e+000,-2.722820e+000,-2.722820e+000,-2.396322e+000,-2.412679e+000,-2.825598e+000,-2.499100e+000,-2.515458e+000,-2.303672e-004,-2.303672e-004,,,,,,,,,,,,,,,,,,,,
1524321481.889,,0.000000e+000,3.599902e+001,3.599653e+001,1,0,1.806452e+000,0.000000e+000,-3.140002e+000,-3.140002e+000,-2.812388e+000,-2.829947e+000,-3.199748e+000,-2.872135e+000,-2.889694e+000,-2.763668e-004,-2.763668e-004,,,,,,,,,,,,,,,,,,,,
1524321507.072,,0.000000e+000,3.599819e+001,3.600317e+001,1,0,1.935484e+000,0.000000e+000,-3.395285e+000,-3.395285e+000,-3.067150e+000,-3.085626e+000,-3.409299e+000,-3.081164e+000,-3.099640e+000,-3.045554e-004,-3.045554e-004,,,,,,,,,,,,,,,,,,,,
1524321532.182,,0.000000e+000,3.599902e+001,3.599984e+001,1,0,2.064516e+000,0.000000e+000,-3.441062e+000,-3.441062e+000,-3.112055e+000,-3.131284e+000,-3.410759e+000,-3.081752e+000,-3.100981e+000,-3.095929e-004,-3.095929e-004,,,,,,,,,,,,,,,,,,,,
1524321557.395,,0.000000e+000,3.599902e+001,3.599984e+001,1,0,2.193548e+000,0.000000e+000,-3.272602e+000,-3.272602e+000,-2.942701e+000,-2.963378e+000,-3.204242e+000,-2.874341e+000,-2.895017e+000,-2.909913e-004,-2.909913e-004,,,,,,,,,,,,,,,,,,,,
1524321582.618,,0.000000e+000,3.599902e+001,3.599984e+001,1,0,2.322581e+000,0.000000e+000,-2.924849e+000,-2.924849e+000,-2.594068e+000,-2.615653e+000,-2.832258e+000,-2.501477e+000,-2.523062e+000,-2.526048e-004,-2.526048e-004,,,,,,,,,,,,,,,,,,,,
1524321607.761,,0.000000e+000,3.599819e+001,3.599902e+001,1,0,2.451613e+000,0.000000e+000,-2.460670e+000,-2.460670e+000,-2.128880e+000,-2.151956e+000,-2.358113e+000,-2.026323e+000,-2.049399e+000,-2.013676e-004,-2.013676e-004,,,,,,,,,,,,,,,,,,,,
1524321632.953,,0.000000e+000,3.599984e+001,3.599736e+001,1,0,2.580645e+000,0.000000e+000,-1.946288e+000,-1.946288e+000,-1.613370e+000,-1.636759e+000,-1.840698e+000,-1.507779e+000,-1.531168e+000,-1.445625e-004,-1.445625e-004,,,,,,,,,,,,,,,,,,,,
1524321658.111,,0.000000e+000,3.599902e+001,3.600068e+001,1,0,2.709677e+000,0.000000e+000,-1.428855e+000,-1.428855e+000,-1.095071e+000,-1.120231e+000,-1.320009e+000,-9.862260e-001,-1.011386e+000,-8.746594e-005,-8.746594e-005,,,,,,,,,,,,,,,,,,,,
1524321683.239,,0.000000e+000,3.599736e+001,3.599984e+001,1,0,2.838710e+000,0.000000e+000,-9.208820e-001,-9.208820e-001,-5.858316e-001,-6.117226e-001,-8.175920e-001,-4.825417e-001,-5.084326e-001,-3.135825e-005,-3.135825e-005,,,,,,,,,,,,,,,,,,,,
1524321708.465,,0.000000e+000,3.599819e+001,3.599736e+001,1,0,2.967742e+000,0.000000e+000,-4.332036e-001,-4.332036e-001,-9.748860e-002,-1.244696e-001,-3.438737e-001,-8.158645e-003,-3.513962e-002,2.244413e-005,2.244413e-005,,,,,,,,,,,,,,,,,,,,
1524321733.650,,0.000000e+000,3.599984e+001,3.599984e+001,1,0,3.096774e+000,0.000000e+000,1.846342e-002,1.846342e-002,3.551345e-001,3.272349e-001,8.993298e-002,4.266041e-001,3.987044e-001,7.231292e-005,7.231292e-005,,,,,,,,,,,,,,,,,,,,
1524321758.833,,0.000000e+000,3.599819e+001,3.599736e+001,1,0,3.225806e+000,0.000000e+000,4.246586e-001,4.246586e-001,7.619837e-001,7.326244e-001,4.671760e-001,8.045012e-001,7.751419e-001,1.171159e-004,1.171159e-004,,,,,,,,,,,,,,,,,,,,
1524321783.976,,0.000000e+000,3.599984e+001,3.599819e+001,1,0,3.354839e+000,0.000000e+000,7.554742e-001,7.554742e-001,1.093160e+000,1.063934e+000,7.629372e-001,1.100623e+000,1.071397e+000,1.536122e-004,1.536122e-004,,,,,,,,,,,,,,,,,,,,
1524321809.171,,0.000000e+000,3.599736e+001,3.599819e+001,1,0,3.483871e+000,0.000000e+000,9.814603e-001,9.814603e-001,1.320050e+000,1.289147e+000,9.518359e-001,1.290426e+000,1.259522e+000,1.785517e-004,1.785517e-004,,,,,,,,,,,,,,,,,,,,
1524321834.376,,0.000000e+000,3.599819e+001,3.599819e+001,1,0,3.612903e+000,0.000000e+000,1.077745e+000,1.077745e+000,1.417070e+000,1.385666e+000,1.022769e+000,1.362095e+000,1.330691e+000,1.891971e-004,1.891971e-004,,,,,,,,,,,,,,,,,,,,
1524321859.522,,0.000000e+000,3.599984e+001,3.600068e+001,1,0,3.741935e+000,0.000000e+000,1.053788e+000,1.053788e+000,1.393663e+000,1.360878e+000,9.861560e-001,1.326031e+000,1.293246e+000,1.865281e-004,1.865281e-004,,,,,,,,,,,,,,,,,,,,
1524321884.715,,0.000000e+000,3.599819e+001,3.599653e+001,1,0,3.870968e+000,0.000000e+000,9.428549e-001,9.428549e-001,1.283238e+000,1.249711e+000,8.712067e-001,1.211590e+000,1.178062e+000,1.742795e-004,1.742795e-004,,,,,,,,,,,,,,,,,,,,
1524321909.925,,0.000000e+000,3.599984e+001,3.599736e+001,1,0,4.000000e+000,0.000000e+000,7.861448e-001,7.861448e-001,1.127176e+000,1.093426e+000,7.141963e-001,1.055228e+000,1.021477e+000,1.570176e-004,1.570176e-004,,,,,,,,,,,,,,,,,,,,
1524321947.671,,0.000000e+000,3.599819e+001,3.600068e+001,1,0,0.000000e+000,0.000000e+000,6.723125e-001,6.723125e-001,9.785741e-001,9.785741e-001,7.491585e-001,1.055420e+000,1.055420e+000,1.431453e-004,1.431453e-004,,,,,,,,,,,,,,,,,,,,
1524321972.853,,0.000000e+000,3.599819e+001,3.599819e+001,1,0,1.290323e-001,0.000000e+000,8.166628e-001,8.166628e-001,1.124205e+000,1.123124e+000,9.048464e-001,1.212389e+000,1.211307e+000,1.591009e-004,1.591009e-004,,,,,,,,,,,,,,,,,,,,
1524321998.044,,0.000000e+000,3.599984e+001,3.599819e+001,1,0,2.580645e-001,0.000000e+000,9.500267e-001,9.500267e-001,1.258618e+000,1.256499e+000,1.018564e+000,1.327155e+000,1.325036e+000,1.738315e-004,1.738315e-004,,,,,,,,,,,,,,,,,,,,
1524322023.204,,0.000000e+000,3.599819e+001,3.599984e+001,1,0,3.870968e-001,0.000000e+000,1.008774e+000,1.008774e+000,1.317971e+000,1.314802e+000,1.054507e+000,1.363704e+000,1.360535e+000,1.803057e-004,1.803057e-004,,,,,,,,,,,,,,,,,,,,
1524322048.365,,0.000000e+000,3.599736e+001,3.599819e+001,1,0,5.161290e-001,0.000000e+000,9.691005e-001,9.691005e-001,1.278747e+000,1.274488e+000,9.824790e-001,1.292125e+000,1.287867e+000,1.759080e-004,1.759080e-004,,,,,,,,,,,,,,,,,,,,
1524322073.570,,0.000000e+000,3.600068e+001,3.599819e+001,1,0,6.451613e-001,0.000000e+000,8.062867e-001,8.062867e-001,1.116574e+000,1.111244e+000,7.921644e-001,1.102452e+000,1.097121e+000,1.579434e-004,1.579434e-004,,,,,,,,,,,,,,,,,,,,
1524322098.768,,0.000000e+000,3.599736e+001,3.599819e+001,1,0,7.741935e-001,0.000000e+000,5.329976e-001,5.329976e-001,8.440114e-001,8.376070e-001,4.951706e-001,8.061844e-001,7.997800e-001,1.278036e-004,1.278036e-004,,,,,,,,,,,,,,,,,,,,
1524322123.911,,0.000000e+000,3.599984e+001,3.599902e+001,1,0,9.032258e-001,0.000000e+000,1.738003e-001,1.738003e-001,4.854291e-001,4.779407e-001,1.160200e-001,4.276488e-001,4.201604e-001,8.816723e-005,8.816723e-005,,,,,,,,,,,,,,,,,,,,
1524322149.106,,0.000000e+000,3.599902e+001,3.599902e+001,1,0,1.032258e+000,0.000000e+000,-2.450599e-001,-2.450599e-001,6.792621e-002,5.959289e-002,-3.211686e-001,-8.182522e-003,-1.651585e-002,4.201556e-005,4.201556e-005,,,,,,,,,,,,,,,,,,,,
1524322174.261,,0.000000e+000,3.599819e+001,3.599984e+001,1,0,1.161290e+000,0.000000e+000,-7.029831e-001,-7.029831e-001,-3.889653e-001,-3.983884e-001,-7.981071e-001,-4.840892e-001,-4.935123e-001,-8.465591e-006,-8.465591e-006,,,,,,,,,,,,,,,,,,,,
1524322199.447,,0.000000e+000,3.599984e+001,3.599902e+001,1,0,1.290323e+000,0.000000e+000,-1.194476e+000,-1.194476e+000,-8.795770e-001,-8.897401e-001,-1.304469e+000,-9.895695e-001,-9.997326e-001,-6.267922e-005,-6.267922e-005,,,,,,,,,,,,,,,,,,,,
1524322224.637,,0.000000e+000,3.599736e+001,3.599902e+001,1,0,1.419355e+000,0.000000e+000,-1.711757e+000,-1.711757e+000,-1.395887e+000,-1.406965e+000,-1.829470e+000,-1.513600e+000,-1.524678e+000,-1.197160e-004,-1.197160e-004,,,,,,,,,,,,,,,,,,,,
1524322249.807,,0.000000e+000,3.599984e+001,3.599653e+001,1,0,1.548387e+000,0.000000e+000,-2.234836e+000,-2.234836e+000,-1.917919e+000,-1.929805e+000,-2.351224e+000,-2.034307e+000,-2.046193e+000,-1.773907e-004,-1.773907e-004,,,,,,,,,,,,,,,,,,,,
1524322275.018,,0.000000e+000,3.599902e+001,3.600150e+001,1,0,1.677419e+000,0.000000e+000,-2.733654e+000,-2.733654e+000,-2.415832e+000,-2.428972e+000,-2.829612e+000,-2.511791e+000,-2.524931e+000,-2.323936e-004,-2.323936e-004,,,,,,,,,,,,,,,,,,,,
1524322300.126,,0.000000e+000,3.599902e+001,3.599736e+001,1,0,1.806452e+000,0.000000e+000,-3.148547e+000,-3.148547e+000,-2.831224e+000,-2.845617e+000,-3.203727e+000,-2.886404e+000,-2.900798e+000,-2.783021e-004,-2.783021e-004,,,,,,,,,,,,,,,,,,,,
1524322325.351,,0.000000e+000,3.600068e+001,3.599984e+001,1,0,1.935484e+000,0.000000e+000,-3.403983e+000,-3.403983e+000,-3.084474e+000,-3.099623e+000,-3.416554e+000,-3.097045e+000,-3.112195e+000,-3.063006e-004,-3.063006e-004,,,,,,,,,,,,,,,,,,,,
1524322337.946,,0.000000e+000,3.599819e+001,3.599736e+001,1,0,4.000000e+000,0.000000e+000,7.919433e-001,7.919433e-001,1.126457e+000,1.096187e+000,7.234147e-001,1.057928e+000,1.027659e+000,1.571530e-004,1.571530e-004,,,,,,,,,,,,,,,,,,,,