File: Input_All/MFn1_TRMac_36K_0.16Kmin_VRMde_35K.dc.dat
[Header]
TITLE,MPMS DC Measurement
BYAPP,MPMS Measurement,2.1,Summary
FILEOPENTIME, 1524533731.320000 4/23/2018, 7:35:31 PM

INFO, APPNAME, MPMS MultiVu Application, Revision 1.61,  Build 082

INFO, NAME, MFn1
INFO, WEIGHT, 1.000
INFO, AREA, 1.000
INFO, LENGTH, 1.000
INFO, SHAPE, 0
INFO, COMMENT,
INFO, SEQUENCE FILE: TRMac_36K_0.16Kmin_VRMde_35K.seq


INFO, BACKGROUND DATA FILE:, None


STARTUPAXIS,X,4,LINEAR,AUTO,0.000000,0.000000
STARTUPAXIS,Y1,5,LINEAR,AUTO,0.000000,0.000000


STARTUPGROUP,Longitudinal
FIELDGROUP,Longitudinal,1,2,3,4,5,6,7,8,9,15,16,17,18,27,28
FIELDGROUP,Transverse,1,2,3,4,10,11,12,13,14,19,20,21,22,27,28

PLOT_APPEARANCE,ALL,HORZ_GRID_ON,VERT_GRID_ON,MARKERS_AND_LINES

[Data]
Time,Comment,Field (Oe),Temperature (K),Long Moment (emu),Long Scan Std Dev,Long Algorithm,Long Reg Fit,Long Percent Error (%),Trans Moment (emu),Trans Scan Std Dev,Trans Algorithm,Trans Reg Fit,Trans Percent Error (%),Long Moment [w/o ABS] (emu),Long Scan Std Dev [w/o ABS],Long Reg Fit [w/o ABS],Long Percent Error [w/o ABS] (%),Trans Moment [w/o ABS] (emu),Trans Scan Std Dev [w/o ABS],Trans Reg Fit [w/o ABS],Trans Percent Error [w/o ABS] (%),Points per Scan,Scans per Measurement,Scan Length (cm),Delta Temp (K),Rot Position (deg),Error,EC Comp. Running,Using ABS,
1524533731.320,,0.000000e+000,3.499677e+001,1.331517e-006,0.000000e+000,3,5.131522e-001,0.000000e+000,,,,,,,,,,,,,,32,1,4.000000e+000,5.470276e-003,0.000000e+000,0,,0,
1524533769.433,,0.000000e+000,3.499676e+001,2.407199e-006,0.000000e+000,3,7.076621e-001,0.000000e+000,,,,,,,,,,,,,,32,1,4.000000e+000,7.820129e-004,0.000000e+000,0,,0,
1524533807.882,,0.000000e+000,3.499872e+001,3.239487e-006,0.000000e+000,3,7.872903e-001,0.000000e+000,,,,,,,,,,,,,,32,1,4.000000e+000,0.000000e+000,0.000000e+000,0,,0,
1524533845.657,,0.000000e+000,3.500302e+001,3.839558e-006,0.000000e+000,3,8.183022e-001,0.000000e+000,,,,,,,,,,,,,,32,1,4.000000e+000,5.481720e-003,0.000000e+000,0,,0,
1524533884.065,,0.000000e+000,3.500732e+001,4.288877e-006,0.000000e+000,3,8.413322e-001,0.000000e+000,,,,,,,,,,,,,,32,1,4.000000e+000,1.560211e-003,0.000000e+000,0,,0,
1524533921.763,,0.000000e+000,3.500145e+001,4.684463e-006,0.000000e+000,3,8.522189e-001,0.000000e+000,,,,,,,,,,,,,,32,1,4.000000e+000,2.349854e-003,0.000000e+000,0,,0,
1524533959.691,,0.000000e+000,3.499872e+001,5.052014e-006,0.000000e+000,3,8.496172e-001,0.000000e+000,,,,,,,,,,,,,,32,1,4.000000e+000,0.000000e+000,0.000000e+000,0,,0,
1524533997.414,,0.000000e+000,3.499872e+001,5.247653e-006,0.000000e+000,3,8.697173e-001,0.000000e+000,,,,,,,,,,,,,,32,1,4.000000e+000,0.000000e+000,0.000000e+000,0,,0,
1524534035.005,,0.000000e+000,3.499911e+001,5.444616e-006,0.000000e+000,3,8.761590e-001,0.000000e+000,,,,,,,,,,,,,,32,1,4.000000e+000,7.820129e-004,0.000000e+000,0,,0,
1524534073.088,,0.000000e+000,3.499794e+001,5.572740e-006,0.000000e+000,3,8.752170e-001,0.000000e+000,,,,,,,,,,,,,,32,1,4.000000e+000,0.000000e+000,0.000000e+000,0,,0,
1524534110.909,,0.000000e+000,3.500028e+001,5.732709e-006,0.000000e+000,3,8.832221e-001,0.000000e+000,,,,,,,,,,,,,,32,1,4.000000e+000,3.120422e-003,0.000000e+000,0,,0,
1524534148.454,,0.000000e+000,3.499872e+001,5.859370e-006,0.000000e+000,3,8.823797e-001,0.000000e+000,,,,,,,,,,,,,,32,1,4.000000e+000,0.000000e+000,0.000000e+000,0,,0,
1524534186.475,,0.000000e+000,3.499872e+001,5.991869e-006,0.000000e+000,3,8.820803e-001,0.000000e+000,,,,,,,,,,,,,,32,1,4.000000e+000,1.560211e-003,0.000000e+000,0,,0,
1524534224.343,,0.000000e+000,3.499872e+001,6.137036e-006,0.000000e+000,3,8.754835e-001,0.000000e+000,,,,,,,,,,,,,,32,1,4.000000e+000,0.000000e+000,0.000000e+000,0,,0,
1524534262.576,,0.000000e+000,3.499833e+001,6.160427e-006,0.000000e+000,3,8.846694e-001,0.000000e+000,,,,,,,,,,,,,,32,1,4.000000e+000,2.349854e-003,0.000000e+000,0,,0,
1524534300.346,,0.000000e+000,3.499754e+001,6.230343e-006,0.000000e+000,3,8.883185e-001,0.000000e+000,,,,,,,,,,,,,,32,1,4.000000e+000,7.896423e-004,0.000000e+000,0,,0,
1524534338.719,,0.000000e+000,3.499872e+001,6.308494e-006,0.000000e+000,3,8.933671e-001,0.000000e+000,,,,,,,,,,,,,,32,1,4.000000e+000,1.560211e-003,0.000000e+000,0,,0,
1524534376.790,,0.000000e+000,3.499833e+001,6.389566e-006,0.000000e+000,3,8.898161e-001,0.000000e+000,,,,,,,,,,,,,,32,1,4.000000e+000,7.781982e-004,0.000000e+000,0,,0,
1524534416.070,,0.000000e+000,3.499833e+001,6.447613e-006,0.000000e+000,3,8.935980e-001,0.000000e+000,,,,,,,,,,,,,,32,1,4.000000e+000,7.781982e-004,0.000000e+000,0,,0,
1524534452.586,,0.000000e+000,3.499872e+001,6.513390e-006,0.000000e+000,3,8.927385e-001,0.000000e+000,,,,,,,,,,,,,,32,1,4.000000e+000,1.560211e-003,0.000000e+000,0,,0,
1524534490.522,,0.000000e+000,3.499833e+001,6.546172e-006,0.000000e+000,3,8.934297e-001,0.000000e+000,,,,,,,,,,,,,,32,1,4.000000e+000,7.781982e-004,0.000000e+000,0,,0,
1524534528.555,,0.000000e+000,3.499833e+001,6.604922e-006,0.000000e+000,3,8.928528e-001,0.000000e+000,,,,,,,,,,,,,,32,1,4.000000e+000,2.349854e-003,0.000000e+000,0,,0,
1524534566.235,,0.000000e+000,3.499833e+001,6.656284e-006,0.000000e+000,3,8.959951e-001,0.000000e+000,,,,,,,,,,,,,,32,1,4.000000e+000,7.781982e-004,0.000000e+000,0,,0,
1524534604.211,,0.000000e+000,3.499872e+001,6.700130e-006,0.000000e+000,3,8.961075e-001,0.000000e+000,,,,,,,,,,,,,,32,1,4.000000e+000,1.560211e-003,0.000000e+000,0,,0,
1524534641.909,,0.000000e+000,3.499872e+001,6.733580e-006,0.000000e+000,3,8.997818e-001,0.000000e+000,,,,,,,,,,,,,,32,1,4.000000e+000,1.560211e-003,0.000000e+000,0,,0,
1524534680.289,,0.000000e+000,3.499950e+001,6.786371e-006,0.000000e+000,3,9.021685e-001,0.000000e+000,,,,,,,,,,,,,,32,1,4.000000e+000,0.000000e+000,0.000000e+000,0,,0,
1524534717.602,,0.000000e+000,3.499911e+001,6.796098e-006,0.000000e+000,3,8.991973e-001,0.000000e+000,,,,,,,,,,,,,,32,1,4.000000e+000,3.910065e-003,0.000000e+000,0,,0,
1524534755.941,,0.000000e+000,3.499872e+001,6.837139e-006,0.000000e+000,3,8.995577e-001,0.000000e+000,,,,,,,,,,,,,,32,1,4.000000e+000,0.000000e+000,0.000000e+000,0,,0,
1524534794.061,,0.000000e+000,3.499833e+001,6.870704e-006,0.000000e+000,3,8.975007e-001,0.000000e+000,,,,,,,,,,,,,,32,1,4.000000e+000,2.349854e-003,0.000000e+000,0,,0,
1524534832.572,,0.000000e+000,3.499872e+001,6.877202e-006,0.000000e+000,3,8.987610e-001,0.000000e+000,,,,,,,,,,,,,,32,1,4.000000e+000,1.560211e-003,0.000000e+000,0,,0,
1524534870.335,,0.000000e+000,3.499715e+001,6.900455e-006,0.000000e+000,3,9.000474e-001,0.000000e+000,,,,,,,,,,,,,,32,1,4.000000e+000,1.571655e-003,0.000000e+000,0,,0,
1524534907.343,,0.000000e+000,3.499833e+001,6.927866e-006,0.000000e+000,3,9.012390e-001,0.000000e+000,,,,,,,,,,,,,,32,1,4.000000e+000,7.781982e-004,0.000000e+000,0,,0,
1524534945.391,,0.000000e+000,3.499872e+001,6.876909e-006,0.000000e+000,3,9.004664e-001,0.000000e+000,,,,,,,,,,,,,,32,1,4.000000e+000,1.560211e-003,0.000000e+000,0,,0,
1524534983.281,,0.000000e+000,3.499872e+001,6.934928e-006,0.000000e+000,3,8.985986e-001,0.000000e+000,,,,,,,,,,,,,,32,1,4.000000e+000,1.560211e-003,0.000000e+000,0,,0,
1524535020.659,,0.000000e+000,3.499833e+001,6.987148e-006,0.000000e+000,3,8.967388e-001,0.000000e+000,,,,,,,,,,,,,,32,1,4.000000e+000,7.781982e-004,0.000000e+000,0,,0,
1524535058.885,,0.000000e+000,3.499911e+001,6.983899e-006,0.000000e+000,3,8.992488e-001,0.000000e+000,,,,,,,,,,,,,,32,1,4.000000e+000,2.338409e-003,0.000000e+000,0,,0,
1524535097.023,,0.000000e+000,3.499872e+001,7.016316e-006,0.000000e+000,3,8.993068e-001,0.000000e+000,,,,,,,,,,,,,,32,1,4.000000e+000,1.560211e-003,0.000000e+000,0,,0,
1524535135.013,,0.000000e+000,3.499872e+001,7.018005e-006,0.000000e+000,3,9.004764e-001,0.000000e+000,,,,,,,,,,,,,,32,1,4.000000e+000,0.000000e+000,0.000000e+000,0,,0,
1524535172.564,,0.000000e+000,3.499950e+001,7.066822e-006,0.000000e+000,3,8.981038e-001,0.000000e+000,,,,,,,,,,,,,,32,1,4.000000e+000,1.560211e-003,0.000000e+000,0,,0,
1524535210.652,,0.000000e+000,3.500067e+001,7.106225e-006,0.000000e+000,3,9.008890e-001,0.000000e+000,,,,,,,,,,,,,,32,1,4.000000e+000,2.338409e-003,0.000000e+000,0,,0,
1524535249.755,,0.000000e+000,3.499872e+001,7.089698e-006,0.000000e+000,3,9.011479e-001,0.000000e+000,,,,,,,,,,,,,,32,1,4.000000e+000,1.560211e-003,0.000000e+000,0,,0,
1524535286.918,,0.000000e+000,3.499872e+001,7.120355e-006,0.000000e+000,3,9.015358e-001,0.000000e+000,,,,,,,,,,,,,,32,1,4.000000e+000,0.000000e+000,0.000000e+000,0,,0,
1524535325.361,,0.000000e+000,3.499677e+001,7.112417e-006,0.000000e+000,3,9.013219e-001,0.000000e+000,,,,,,,,,,,,,,32,1,4.000000e+000,2.349854e-003,0.000000e+000,0,,0,
1524535363.839,,0.000000e+000,3.499754e+001,7.132347e-006,0.000000e+000,3,9.004815e-001,0.000000e+000,,,,,,,,,,,,,,32,1,4.000000e+000,3.910065e-003,0.000000e+000,0,,0,
1524535402.172,,0.000000e+000,3.499754e+001,7.132972e-006,0.000000e+000,3,9.004803e-001,0.000000e+000,,,,,,,,,,,,,,32,1,4.000000e+000,7.896423e-004,0.000000e+000,0,,0,
1524535440.486,,0.000000e+000,3.500028e+001,7.165811e-006,0.000000e+000,3,9.029709e-001,0.000000e+000,,,,,,,,,,,,,,32,1,4.000000e+000,1.560211e-003,0.000000e+000,0,,0,
1524535478.229,,0.000000e+000,3.499715e+001,7.187193e-006,0.000000e+000,3,9.031035e-001,0.000000e+000,,,,,,,,,,,,,,32,1,4.000000e+000,4.692078e-003,0.000000e+000,0,,0,
1524535516.204,,0.000000e+000,3.499911e+001,7.162649e-006,0.000000e+000,3,9.031726e-001,0.000000e+000,,,,,,,,,,,,,,32,1,4.000000e+000,7.820129e-004,0.000000e+000,0,,0,
1524535555.360,,0.000000e+000,3.499715e+001,7.142729e-006,0.000000e+000,3,9.028309e-001,0.000000e+000,,,,,,,,,,,,,,32,1,4.000000e+000,3.128052e-003,0.000000e+000,0,,0,
1524535593.558,,0.000000e+000,3.499911e+001,7.047363e-006,0.000000e+000,3,9.046998e-001,0.000000e+000,,,,,,,,,,,,,,32,1,4.000000e+000,7.820129e-004,0.000000e+000,0,,0,
1524535631.686,,0.000000e+000,3.499833e+001,7.181920e-006,0.000000e+000,3,9.037950e-001,0.000000e+000,,,,,,,,,,,,,,32,1,4.000000e+000,7.781982e-004,0.000000e+000,0,,0,
1524535669.994,,0.000000e+000,3.499833e+001,7.197961e-006,0.000000e+000,3,9.052390e-001,0.000000e+000,,,,,,,,,,,,,,32,1,4.000000e+000,7.781982e-004,0.000000e+000,0,,0,
1524535708.019,,0.000000e+000,3.499950e+001,7.233071e-006,0.000000e+000,3,9.060329e-001,0.000000e+000,,,,,,,,,,,,,,32,1,4.000000e+000,1.560211e-003,0.000000e+000,0,,0,
1524535745.833,,0.000000e+000,3.499793e+001,7.231534e-006,0.000000e+000,3,9.065893e-001,0.000000e+000,,,,,,,,,,,,,,32,1,4.000000e+000,1.567841e-003,0.000000e+000,0,,0,
1524535783.673,,0.000000e+000,3.499833e+001,7.186872e-006,0.000000e+000,3,9.035512e-001,0.000000e+000,,,,,,,,,,,,,,32,1,4.000000e+000,7.781982e-004,0.000000e+000,0,,0,
1524535821.844,,0.000000e+000,3.499911e+001,7.243060e-006,0.000000e+000,3,9.018404e-001,0.000000e+000,,,,,,,,,,,,,,32,1,4.000000e+000,2.338409e-003,0.000000e+000,0,,0,
1524535859.927,,0.000000e+000,3.499872e+001,7.284839e-006,0.000000e+000,3,9.031262e-001,0.000000e+000,,,,,,,,,,,,,,32,1,4.000000e+000,1.560211e-003,0.000000e+000,0,,0,
1524535897.570,,0.000000e+000,3.499872e+001,7.277496e-006,0.000000e+000,3,9.036226e-001,0.000000e+000,,,,,,,,,,,,,,32,1,4.000000e+000,0.000000e+000,0.000000e+000,0,,0,
1524535935.653,,0.000000e+000,3.499950e+001,7.215591e-006,0.000000e+000,3,9.017264e-001,0.000000e+000,,,,,,,,,,,,,,32,1,4.000000e+000,0.000000e+000,0.000000e+000,0,,0,
1524535972.978,,0.000000e+000,3.499950e+001,7.260754e-006,0.000000e+000,3,9.029127e-001,0.000000e+000,,,,,,,,,,,,,,32,1,4.000000e+000,1.560211e-003,0.000000e+000,0,,0,
1524536010.221,,0.000000e+000,3.499833e+001,7.264746e-006,0.000000e+000,3,9.044768e-001,0.000000e+000,,,,,,,,,,,,,,32,1,4.000000e+000,7.781982e-004,0.000000e+000,0,,0,
1524536048.147,,0.000000e+000,3.499872e+001,7.279871e-006,0.000000e+000,3,9.031088e-001,0.000000e+000,,,,,,,,,,,,,,32,1,4.000000e+000,0.000000e+000,0.000000e+000,0,,0,
1524536086.748,,0.000000e+000,3.499911e+001,7.288554e-006,0.000000e+000,3,9.037073e-001,0.000000e+000,,,,,,,,,,,,,,32,1,4.000000e+000,2.338409e-003,0.000000e+000,0,,0,
1524536123.578,,0.000000e+000,3.499832e+001,7.242251e-006,0.000000e+000,3,9.033439e-001,0.000000e+000,,,,,,,,,,,,,,32,1,4.000000e+000,3.910065e-003,0.000000e+000,0,,0,
1524536161.781,,0.000000e+000,3.499950e+001,7.295426e-006,0.000000e+000,3,9.043821e-001,0.000000e+000,,,,,,,,,,,,,,32,1,4.000000e+000,1.560211e-003,0.000000e+000,0,,0,
1524536200.599,,0.000000e+000,3.499911e+001,7.298568e-006,0.000000e+000,3,9.019956e-001,0.000000e+000,,,,,,,,,,,,,,32,1,4.000000e+000,7.820129e-004,0.000000e+000,0,,0,
1524536239.002,,0.000000e+000,3.499950e+001,7.352487e-006,0.000000e+000,3,9.036304e-001,0.000000e+000,,,,,,,,,,,,,,32,1,4.000000e+000,1.560211e-003,0.000000e+000,0,,0,
1524536277.090,,0.000000e+000,3.499872e+001,7.350573e-006,0.000000e+000,3,9.040561e-001,0.000000e+000,,,,,,,,,,,,,,32,1,4.000000e+000,0.000000e+000,0.000000e+000,0,,0,
1524536315.206,,0.000000e+000,3.499833e+001,7.298167e-006,0.000000e+000,3,9.035130e-001,0.000000e+000,,,,,,,,,,,,,,32,1,4.000000e+000,7.781982e-004,0.000000e+000,0,,0,
1524536353.174,,0.000000e+000,3.499950e+001,7.325729e-006,0.000000e+000,3,9.058070e-001,0.000000e+000,,,,,,,,,,,,,,32,1,4.000000e+000,1.560211e-003,0.000000e+000,0,,0,
1524536390.447,,0.000000e+000,3.499872e+001,7.293999e-006,0.000000e+000,3,9.028295e-001,0.000000e+000,,,,,,,,,,,,,,32,1,4.000000e+000,0.000000e+000,0.000000e+000,0,,0,
1524536428.073,,0.000000e+000,3.499872e+001,7.309708e-006,0.000000e+000,3,9.063407e-001,0.000000e+000,,,,,,,,,,,,,,32,1,4.000000e+000,0.000000e+000,0.000000e+000,0,,0,
1524536466.598,,0.000000e+000,3.499872e+001,7.317683e-006,0.000000e+000,3,9.077817e-001,0.000000e+000,,,,,,,,,,,,,,32,1,4.000000e+000,0.000000e+000,0.000000e+000,0,,0,
1524536504.236,,0.000000e+000,3.499911e+001,7.288055e-006,0.000000e+000,3,9.030724e-001,0.000000e+000,,,,,,,,,,,,,,32,1,4.000000e+000,7.820129e-004,0.000000e+000,0,,0,
1524536542.782,,0.000000e+000,3.499989e+001,7.336240e-006,0.000000e+000,3,9.066733e-001,0.000000e+000,,,,,,,,,,,,,,32,1,4.000000e+000,7.781982e-004,0.000000e+000,0,,0,
1524536580.285,,0.000000e+000,3.499872e+001,7.306097e-006,0.000000e+000,3,9.090509e-001,0.000000e+000,,,,,,,,,,,,,,32,1,4.000000e+000,1.560211e-003,0.000000e+000,0,,0,
1524536617.990,,0.000000e+000,3.499872e+001,7.322519e-006,0.000000e+000,3,9.038658e-001,0.000000e+000,,,,,,,,,,,,,,32,1,4.000000e+000,1.560211e-003,0.000000e+000,0,,0,
1524536655.221,,0.000000e+000,3.499872e+001,7.331829e-006,0.000000e+000,3,9.052856e-001,0.000000e+000,,,,,,,,,,,,,,32,1,4.000000e+000,0.000000e+000,0.000000e+000,0,,0,
1524536693.251,,0.000000e+000,3.499833e+001,7.337040e-006,0.000000e+000,3,9.014198e-001,0.000000e+000,,,,,,,,,,,,,,32,1,4.000000e+000,2.349854e-003,0.000000e+000,0,,0,
1524536732.022,,0.000000e+000,3.499950e+001,7.326704e-006,0.000000e+000,3,9.051795e-001,0.000000e+000,,,,,,,,,,,,,,32,1,4.000000e+000,0.000000e+000,0.000000e+000,0,,0,
1524536769.700,,0.000000e+000,3.499989e+001,7.356742e-006,0.000000e+000,3,9.075803e-001,0.000000e+000,,,,,,,,,,,,,,32,1,4.000000e+000,7.781982e-004,0.000000e+000,0,,0,
1524536808.228,,0.000000e+000,3.499872e+001,7.325079e-006,0.000000e+000,3,9.048275e-001,0.000000e+000,,,,,,,,,,,,,,32,1,4.000000e+000,0.000000e+000,0.000000e+000,0,,0,
1524536845.881,,0.000000e+000,3.499950e+001,7.349658e-006,0.000000e+000,3,9.057277e-001,0.000000e+000,,,,,,,,,,,,,,32,1,4.000000e+000,0.000000e+000,0.000000e+000,0,,0,
1524536883.934,,0.000000e+000,3.499833e+001,7.356677e-006,0.000000e+000,3,9.076325e-001,0.000000e+000,,,,,,,,,,,,,,32,1,4.000000e+000,7.781982e-004,0.000000e+000,0,,0,
1524536922.487,,0.000000e+000,3.499872e+001,7.347334e-006,0.000000e+000,3,9.046763e-001,0.000000e+000,,,,,,,,,,,,,,32,1,4.000000e+000,0.000000e+000,0.000000e+000,0,,0,
1524536959.435,,0.000000e+000,3.499950e+001,7.329172e-006,0.000000e+000,3,9.046937e-001,0.000000e+000,,,,,,,,,,,,,,32,1,4.000000e+000,0.000000e+000,0.000000e+000,0,,0,
1524536997.388,,0.000000e+000,3.499872e+001,7.361098e-006,0.000000e+000,3,9.023656e-001,0.000000e+000,,,,,,,,,,,,,,32,1,4.000000e+000,1.560211e-003,0.000000e+000,0,,0,
1524537036.006,,0.000000e+000,3.499911e+001,7.372124e-006,0.000000e+000,3,9.066993e-001,0.000000e+000,,,,,,,,,,,,,,32,1,4.000000e+000,7.820129e-004,0.000000e+000,0,,0,
1524537074.079,,0.000000e+000,3.499911e+001,7.357588e-006,0.000000e+000,3,9.060278e-001,0.000000e+000,,,,,,,,,,,,,,32,1,4.000000e+000,7.820129e-004,0.000000e+000,0,,0,
1524537111.548,,0.000000e+000,3.499833e+001,7.329034e-006,0.000000e+000,3,9.029320e-001,0.000000e+000,,,,,,,,,,,,,,32,1,4.000000e+000,7.781982e-004,0.000000e+000,0,,0,
1524537149.356,,0.000000e+000,3.499989e+001,7.355829e-006,0.000000e+000,3,9.025853e-001,0.000000e+000,,,,,,,,,,,,,,32,1,4.000000e+000,7.781982e-004,0.000000e+000,0,,0,
1524537187.186,,0.000000e+000,3.499754e+001,7.343391e-006,0.000000e+000,3,9.012772e-001,0.000000e+000,,,,,,,,,,,,,,32,1,4.000000e+000,7.896423e-004,0.000000e+000,0,,0,
1524537225.262,,0.000000e+000,3.499833e+001,7.359912e-006,0.000000e+000,3,9.043225e-001,0.000000e+000,,,,,,,,,,,,,,32,1,4.000000e+000,7.781982e-004,0.000000e+000,0,,0,
1524537263.372,,0.000000e+000,3.499872e+001,7.356970e-006,0.000000e+000,3,9.028602e-001,0.000000e+000,,,,,,,,,,,,,,32,1,4.000000e+000,1.560211e-003,0.000000e+000,0,,0,
1524537302.243,,0.000000e+000,3.499754e+001,7.370603e-006,0.000000e+000,3,9.031626e-001,0.000000e+000,,,,,,,,,,,,,,32,1,4.000000e+000,7.896423e-004,0.000000e+000,0,,0,
1524537340.308,,0.000000e+000,3.499911e+001,7.340787e-006,0.000000e+000,3,9.030693e-001,0.000000e+000,,,,,,,,,,,,,,32,1,4.000000e+000,7.820129e-004,0.000000e+000,0,,0,
1524537377.864,,0.000000e+000,3.499911e+001,7.350993e-006,0.000000e+000,3,9.077570e-001,0.000000e+000,,,,,,,,,,,,,,32,1,4.000000e+000,7.820129e-004,0.000000e+000,0,,0,
1524537416.325,,0.000000e+000,3.499950e+001,7.381351e-006,0.000000e+000,3,9.029355e-001,0.000000e+000,,,,,,,,,,,,,,32,1,4.000000e+000,0.000000e+000,0.000000e+000,0,,0,
1524537454.290,,0.000000e+000,3.499989e+001,7.378776e-006,0.000000e+000,3,9.067909e-001,0.000000e+000,,,,,,,,,,,,,,32,1,4.000000e+000,3.898621e-003,0.000000e+000,0,,0,
1524537492.236,,0.000000e+000,3.499950e+001,7.403188e-006,0.000000e+000,3,9.054902e-001,0.000000e+000,,,,,,,,,,,,,,32,1,4.000000e+000,1.560211e-003,0.000000e+000,0,,0,
1524537530.421,,0.000000e+000,3.499793e+001,7.386415e-006,0.000000e+000,3,9.061772e-001,0.000000e+000,,,,,,,,,,,,,,32,1,4.000000e+000,3.131866e-003,0.000000e+000,0,,0,
1524537568.512,,0.000000e+000,3.499872e+001,7.386617e-006,0.000000e+000,3,9.040674e-001,0.000000e+000,,,,,,,,,,,,,,32,1,4.000000e+000,0.000000e+000,0.000000e+000,0,,0,
1524537606.612,,0.000000e+000,3.499911e+001,7.321274e-006,0.000000e+000,3,9.028542e-001,0.000000e+000,,,,,,,,,,,,,,32,1,4.000000e+000,7.820129e-004,0.000000e+000,0,,0,
1524537645.223,,0.000000e+000,3.499911e+001,7.456723e-006,0.000000e+000,3,9.093686e-001,0.000000e+000,,,,,,,,,,,,,,32,1,4.000000e+000,7.820129e-004,0.000000e+000,0,,0,
1524537682.773,,0.000000e+000,3.499911e+001,7.406207e-006,0.000000e+000,3,9.078925e-001,0.000000e+000,,,,,,,,,,,,,,32,1,4.000000e+000,7.820129e-004,0.000000e+000,0,,0,
1524537721.546,,0.000000e+000,3.499911e+001,7.396881e-006,0.000000e+000,3,9.073619e-001,0.000000e+000,,,,,,,,,,,,,,32,1,4.000000e+000,7.820129e-004,0.000000e+000,0,,0,
1524537758.927,,0.000000e+000,3.499872e+001,7.378779e-006,0.000000e+000,3,9.070224e-001,0.000000e+000,,,,,,,,,,,,,,32,1,4.000000e+000,1.560211e-003,0.000000e+000,0,,0,
1524537796.453,,0.000000e+000,3.499911e+001,7.384633e-006,0.000000e+000,3,9.040031e-001,0.000000e+000,,,,,,,,,,,,,,32,1,4.000000e+000,7.820129e-004,0.000000e+000,0,,0,
1524537834.493,,0.000000e+000,3.499872e+001,7.390794e-006,0.000000e+000,3,9.035035e-001,0.000000e+000,,,,,,,,,,,,,,32,1,4.000000e+000,0.000000e+000,0.000000e+000,0,,0,
1524537872.629,,0.000000e+000,3.499950e+001,7.403901e-006,0.000000e+000,3,9.049937e-001,0.000000e+000,,,,,,,,,,,,,,32,1,4.000000e+000,1.560211e-003,0.000000e+000,0,,0,
1524537911.244,,0.000000e+000,3.499872e+001,7.396523e-006,0.000000e+000,3,9.031013e-001,0.000000e+000,,,,,,,,,,,,,,32,1,4.000000e+000,1.560211e-003,0.000000e+000,0,,0,
1524537948.252,,0.000000e+000,3.499911e+001,7.363281e-006,0.000000e+000,3,9.043843e-001,0.000000e+000,,,,,,,,,,,,,,32,1,4.000000e+000,7.820129e-004,0.000000e+000,0,,0,
1524537986.285,,0.000000e+000,3.499950e+001,7.373854e-006,0.000000e+000,3,9.057558e-001,0.000000e+000,,,,,,,,,,,,,,32,1,4.000000e+000,0.000000e+000,0.000000e+000,0,,0,
1524538024.378,,0.000000e+000,3.499950e+001,7.375436e-006,0.000000e+000,3,9.014708e-001,0.000000e+000,,,,,,,,,,,,,,32,1,4.000000e+000,0.000000e+000,0.000000e+000,0,,0,
1524538062.214,,0.000000e+000,3.499754e+001,7.406308e-006,0.000000e+000,3,9.019651e-001,0.000000e+000,,,,,,,,,,,,,,32,1,4.000000e+000,7.896423e-004,0.000000e+000,0,,0,
1524538100.472,,0.000000e+000,3.499950e+001,7.403406e-006,0.000000e+000,3,9.042059e-001,0.000000e+000,,,,,,,,,,,,,,32,1,4.000000e+000,1.560211e-003,0.000000e+000,0,,0,
1524538139.105,,0.000000e+000,3.499872e+001,7.376155e-006,0.000000e+000,3,9.036792e-001,0.000000e+000,,,,,,,,,,,,,,32,1,4.000000e+000,1.560211e-003,0.000000e+000,0,,0,
1524538176.176,,0.000000e+000,3.499872e+001,7.399373e-006,0.000000e+000,3,9.017745e-001,0.000000e+000,,,,,,,,,,,,,,32,1,4.000000e+000,1.560211e-003,0.000000e+000,0,,0,
1524538214.251,,0.000000e+000,3.499833e+001,7.403836e-006,0.000000e+000,3,9.035540e-001,0.000000e+000,,,,,,,,,,,,,,32,1,4.000000e+000,7.781982e-004,0.000000e+000,0,,0,
1524538252.512,,0.000000e+000,3.499989e+001,7.396578e-006,0.000000e+000,3,9.072598e-001,0.000000e+000,,,,,,,,,,,,,,32,1,4.000000e+000,7.781982e-004,0.000000e+000,0,,0,
1524538290.770,,0.000000e+000,3.499989e+001,7.403207e-006,0.000000e+000,3,9.040722e-001,0.000000e+000,,,,,,,,,,,,,,32,1,4.000000e+000,7.781982e-004,0.000000e+000,0,,0,
1524538329.043,,0.000000e+000,3.499911e+001,7.404273e-006,0.000000e+000,3,9.012878e-001,0.000000e+000,,,,,,,,,,,,,,32,1,4.000000e+000,7.820129e-004,0.000000e+000,0,,0,
1524538367.283,,0.000000e+000,3.499793e+001,7.383529e-006,0.000000e+000,3,9.029809e-001,0.000000e+000,,,,,,,,,,,,,,32,1,4.000000e+000,1.567841e-003,0.000000e+000,0,,0,
1524538404.924,,0.000000e+000,3.499911e+001,7.468715e-006,0.000000e+000,3,9.044143e-001,0.000000e+000,,,,,,,,,,,,,,32,1,4.000000e+000,7.820129e-004,0.000000e+000,0,,0,
1524538442.445,,0.000000e+000,3.499872e+001,7.393123e-006,0.000000e+000,3,9.005005e-001,0.000000e+000,,,,,,,,,,,,,,32,1,4.000000e+000,0.000000e+000,0.000000e+000,0,,0,
1524538481.095,,0.000000e+000,3.499950e+001,7.423144e-006,0.000000e+000,3,9.060475e-001,0.000000e+000,,,,,,,,,,,,,,32,1,4.000000e+000,1.560211e-003,0.000000e+000,0,,0,
1524538519.118,,0.000000e+000,3.499872e+001,7.422498e-006,0.000000e+000,3,9.057877e-001,0.000000e+000,,,,,,,,,,,,,,32,1,4.000000e+000,0.000000e+000,0.000000e+000,0,,0,
1524538557.179,,0.000000e+000,3.499872e+001,7.391949e-006,0.000000e+000,3,9.060413e-001,0.000000e+000,,,,,,,,,,,,,,32,1,4.000000e+000,0.000000e+000,0.000000e+000,0,,0,
1524538595.287,,0.000000e+000,3.499833e+001,7.414211e-006,0.000000e+000,3,9.087113e-001,0.000000e+000,,,,,,,,,,,,,,32,1,4.000000e+000,7.781982e-004,0.000000e+000,0,,0,
1524538633.432,,0.000000e+000,3.499950e+001,7.434908e-006,0.000000e+000,3,9.022533e-001,0.000000e+000,,,,,,,,,,,,,,32,1,4.000000e+000,1.560211e-003,0.000000e+000,0,,0,
1524538672.035,,0.000000e+000,3.499872e+001,7.433705e-006,0.000000e+000,3,9.026741e-001,0.000000e+000,,,,,,,,,,,,,,32,1,4.000000e+000,0.000000e+000,0.000000e+000,0,,0,
1524538709.318,,0.000000e+000,3.499872e+001,7.430364e-006,0.000000e+000,3,9.011108e-001,0.000000e+000,,,,,,,,,,,,,,32,1,4.000000e+000,1.560211e-003,0.000000e+000,0,,0,
1524538747.582,,0.000000e+000,3.499911e+001,7.404723e-006,0.000000e+000,3,9.049969e-001,0.000000e+000,,,,,,,,,,,,,,32,1,4.000000e+000,7.820129e-004,0.000000e+000,0,,0,
1524538785.662,,0.000000e+000,3.499911e+001,7.393553e-006,0.000000e+000,3,9.018936e-001,0.000000e+000,,,,,,,,,,,,,,32,1,4.000000e+000,7.820129e-004,0.000000e+000,0,,0,
1524538823.743,,0.000000e+000,3.499833e+001,7.424328e-006,0.000000e+000,3,9.039559e-001,0.000000e+000,,,,,,,,,,,,,,32,1,4.000000e+000,7.781982e-004,0.000000e+000,0,,0,
1524538862.358,,0.000000e+000,3.499950e+001,7.431640e-006,0.000000e+000,3,9.064137e-001,0.000000e+000,,,,,,,,,,,,,,32,1,4.000000e+000,3.120422e-003,0.000000e+000,0,,0,
1524538901.086,,0.000000e+000,3.499794e+001,7.419495e-006,0.000000e+000,3,9.088674e-001,0.000000e+000,,,,,,,,,,,,,,32,1,4.000000e+000,0.000000e+000,0.000000e+000,0,,0,
1524538938.879,,0.000000e+000,3.499911e+001,7.399530e-006,0.000000e+000,3,9.058269e-001,0.000000e+000,,,,,,,,,,,,,,32,1,4.000000e+000,7.820129e-004,0.000000e+000,0,,0,
1524538977.085,,0.000000e+000,3.500028e+001,7.441030e-006,0.000000e+000,3,9.074785e-001,0.000000e+000,,,,,,,,,,,,,,32,1,4.000000e+000,1.560211e-003,0.000000e+000,0,,0,
1524539015.130,,0.000000e+000,3.499911e+001,7.410390e-006,0.000000e+000,3,9.038254e-001,0.000000e+000,,,,,,,,,,,,,,32,1,4.000000e+000,2.338409e-003,0.000000e+000,0,,0,
1524539053.384,,0.000000e+000,3.499911e+001,7.447561e-006,0.000000e+000,3,9.085991e-001,0.000000e+000,,,,,,,,,,,,,,32,1,4.000000e+000,7.820129e-004,0.000000e+000,0,,0,
1524539091.144,,0.000000e+000,3.499794e+001,7.433714e-006,0.000000e+000,3,9.041722e-001,0.000000e+000,,,,,,,,,,,,,,32,1,4.000000e+000,0.000000e+000,0.000000e+000,0,,0,
1524539129.047,,0.000000e+000,3.499950e+001,7.409547e-006,0.000000e+000,3,9.031988e-001,0.000000e+000,,,,,,,,,,,,,,32,1,4.000000e+000,0.000000e+000,0.000000e+000,0,,0,
1524539167.370,,0.000000e+000,3.499950e+001,7.422058e-006,0.000000e+000,3,9.042775e-001,0.000000e+000,,,,,,,,,,,,,,32,1,4.000000e+000,1.560211e-003,0.000000e+000,0,,0,
1524539205.408,,0.000000e+000,3.499911e+001,7.378070e-006,0.000000e+000,3,9.059440e-001,0.000000e+000,,,,,,,,,,,,,,32,1,4.000000e+000,2.338409e-003,0.000000e+000,0,,0,
1524539243.446,,0.000000e+000,3.499872e+001,7.380276e-006,0.000000e+000,3,9.033059e-001,0.000000e+000,,,,,,,,,,,,,,32,1,4.000000e+000,0.000000e+000,0.000000e+000,0,,0,
1524539281.522,,0.000000e+000,3.499911e+001,7.417029e-006,0.000000e+000,3,9.034153e-001,0.000000e+000,,,,,,,,,,,,,,32,1,4.000000e+000,7.820129e-004,0.000000e+000,0,,0,
1524539319.542,,0.000000e+000,3.499950e+001,7.428900e-006,0.000000e+000,3,9.033179e-001,0.000000e+000,,,,,,,,,,,,,,32,1,4.000000e+000,1.560211e-003,0.000000e+000,0,,0,
1524539357.645,,0.000000e+000,3.499911e+001,7.406536e-006,0.000000e+000,3,9.029517e-001,0.000000e+000,,,,,,,,,,,,,,32,1,4.000000e+000,7.820129e-004,0.000000e+000,0,,0,
1524539395.696,,0.000000e+000,3.499911e+001,7.381586e-006,0.000000e+000,3,9.042261e-001,0.000000e+000,,,,,,,,,,,,,,32,1,4.000000e+000,7.820129e-004,0.000000e+000,0,,0,
1524539433.722,,0.000000e+000,3.499833e+001,7.407892e-006,0.000000e+000,3,9.029617e-001,0.000000e+000,,,,,,,,,,,,,,32,1,4.000000e+000,7.781982e-004,0.000000e+000,0,,0,
1524539471.825,,0.000000e+000,3.499833e+001,7.439374e-006,0.000000e+000,3,9.049669e-001,0.000000e+000,,,,,,,,,,,,,,32,1,4.000000e+000,7.781982e-004,0.000000e+000,0,,0,
1524539509.643,,0.000000e+000,3.499833e+001,7.425132e-006,0.000000e+000,3,9.068046e-001,0.000000e+000,,,,,,,,,,,,,,32,1,4.000000e+000,7.781982e-004,0.000000e+000,0,,0,
1524539547.351,,0.000000e+000,3.499950e+001,7.419922e-006,0.000000e+000,3,9.045473e-001,0.000000e+000,,,,,,,,,,,,,,32,1,4.000000e+000,0.000000e+000,0.000000e+000,0,,0,
1524539584.681,,0.000000e+000,3.500028e+001,7.373845e-006,0.000000e+000,3,9.063788e-001,0.000000e+000,,,,,,,,,,,,,,32,1,4.000000e+000,0.000000e+000,0.000000e+000,0,,0,
1524539623.052,,0.000000e+000,3.499911e+001,7.376313e-006,0.000000e+000,3,9.027019e-001,0.000000e+000,,,,,,,,,,,,,,32,1,4.000000e+000,7.820129e-004,0.000000e+000,0,,0,
1524539661.565,,0.000000e+000,3.499950e+001,7.389939e-006,0.000000e+000,3,9.041052e-001,0.000000e+000,,,,,,,,,,,,,,32,1,4.000000e+000,1.560211e-003,0.000000e+000,0,,0,
1524539699.128,,0.000000e+000,3.499872e+001,7.390013e-006,0.000000e+000,3,9.036747e-001,0.000000e+000,,,,,,,,,,,,,,32,1,4.000000e+000,0.000000e+000,0.000000e+000,0,,0,
1524539736.506,,0.000000e+000,3.499911e+001,7.407791e-006,0.000000e+000,3,9.057385e-001,0.000000e+000,,,,,,,,,,,,,,32,1,4.000000e+000,7.820129e-004,0.000000e+000,0,,0,
1524539774.567,,0.000000e+000,3.500106e+001,7.385889e-006,0.000000e+000,3,9.072621e-001,0.000000e+000,,,,,,,,,,,,,,32,1,4.000000e+000,4.692078e-003,0.000000e+000,0,,0,
1524539812.622,,0.000000e+000,3.499950e+001,7.431006e-006,0.000000e+000,3,9.061626e-001,0.000000e+000,,,,,,,,,,,,,,32,1,4.000000e+000,1.560211e-003,0.000000e+000,0,,0,
1524539850.598,,0.000000e+000,3.499989e+001,7.418836e-006,0.000000e+000,3,9.007888e-001,0.000000e+000,,,,,,,,,,,,,,32,1,4.000000e+000,2.342224e-003,0.000000e+000,0,,0,
1524539888.906,,0.000000e+000,3.499872e+001,7.413222e-006,0.000000e+000,3,9.048540e-001,0.000000e+000,,,,,,,,,,,,,,32,1,4.000000e+000,0.000000e+000,0.000000e+000,0,,0,
1524539927.481,,0.000000e+000,3.499950e+001,7.396805e-006,0.000000e+000,3,9.047724e-001,0.000000e+000,,,,,,,,,,,,,,32,1,4.000000e+000,1.560211e-003,0.000000e+000,0,,0,
1524539965.004,,0.000000e+000,3.499872e+001,7.391707e-006,0.000000e+000,3,9.037418e-001,0.000000e+000,,,,,,,,,,,,,,32,1,4.000000e+000,0.000000e+000,0.000000e+000,0,,0,
1524540003.105,,0.000000e+000,3.499989e+001,7.386370e-006,0.000000e+000,3,9.057952e-001,0.000000e+000,,,,,,,,,,,,,,32,1,4.000000e+000,2.342224e-003,0.000000e+000,0,,0,
1524540041.701,,0.000000e+000,3.499833e+001,7.437985e-006,0.000000e+000,3,9.023305e-001,0.000000e+000,,,,,,,,,,,,,,32,1,4.000000e+000,7.781982e-004,0.000000e+000,0,,0,
1524540079.989,,0.000000e+000,3.499989e+001,7.406420e-006,0.000000e+000,3,9.060878e-001,0.000000e+000,,,,,,,,,,,,,,32,1,4.000000e+000,2.342224e-003,0.000000e+000,0,,0,
1524540118.062,,0.000000e+000,3.500106e+001,7.429437e-006,0.000000e+000,3,9.068147e-001,0.000000e+000,,,,,,,,,,,,,,32,1,4.000000e+000,0.000000e+000,0.000000e+000,0,,0,
1524540156.097,,0.000000e+000,3.500106e+001,7.390879e-006,0.000000e+000,3,9.012265e-001,0.000000e+000,,,,,,,,,,,,,,32,1,4.000000e+000,4.692078e-003,0.000000e+000,0,,0,
1524540193.955,,0.000000e+000,3.499872e+001,7.407009e-006,0.000000e+000,3,9.042447e-001,0.000000e+000,,,,,,,,,,,,,,32,1,4.000000e+000,1.560211e-003,0.000000e+000,0,,0,
1524540231.758,,0.000000e+000,3.499833e+001,7.383223e-006,0.000000e+000,3,9.036788e-001,0.000000e+000,,,,,,,,,,,,,,32,1,4.000000e+000,7.781982e-004,0.000000e+000,0,,0,
1524540269.776,,0.000000e+000,3.499911e+001,7.450716e-006,0.000000e+000,3,9.013060e-001,0.000000e+000,,,,,,,,,,,,,,32,1,4.000000e+000,7.820129e-004,0.000000e+000,0,,0,
1524540307.399,,0.000000e+000,3.500028e+001,7.436503e-006,0.000000e+000,3,9.062306e-001,0.000000e+000,,,,,,,,,,,,,,32,1,4.000000e+000,1.560211e-003,0.000000e+000,0,,0,
1524540345.210,,0.000000e+000,3.499989e+001,7.415837e-006,0.000000e+000,3,9.070030e-001,0.000000e+000,,,,,,,,,,,,,,32,1,4.000000e+000,7.781982e-004,0.000000e+000,0,,0,
1524540383.296,,0.000000e+000,3.499872e+001,7.385325e-006,0.000000e+000,3,9.058918e-001,0.000000e+000,,,,,,,,,,,,,,32,1,4.000000e+000,0.000000e+000,0.000000e+000,0,,0,
1524540421.051,,0.000000e+000,3.499950e+001,7.400504e-006,0.000000e+000,3,9.063805e-001,0.000000e+000,,,,,,,,,,,,,,32,1,4.000000e+000,0.000000e+000,0.000000e+000,0,,0,
1524540458.889,,0.000000e+000,3.499872e+001,7.434574e-006,0.000000e+000,3,9.028571e-001,0.000000e+000,,,,,,,,,,,,,,32,1,4.000000e+000,1.560211e-003,0.000000e+000,0,,0,
1524540496.312,,0.000000e+000,3.499911e+001,7.413267e-006,0.000000e+000,3,9.031863e-001,0.000000e+000,,,,,,,,,,,,,,32,1,4.000000e+000,2.338409e-003,0.000000e+000,0,,0,
1524540534.330,,0.000000e+000,3.499911e+001,7.409489e-006,0.000000e+000,3,9.042859e-001,0.000000e+000,,,,,,,,,,,,,,32,1,4.000000e+000,7.820129e-004,0.000000e+000,0,,0,
1524540571.991,,0.000000e+000,3.499793e+001,7.424887e-006,0.000000e+000,3,9.084194e-001,0.000000e+000,,,,,,,,,,,,,,32,1,4.000000e+000,1.567841e-003,0.000000e+000,0,,0,
1524540610.334,,0.000000e+000,3.499872e+001,7.422349e-006,0.000000e+000,3,9.068021e-001,0.000000e+000,,,,,,,,,,,,,,32,1,4.000000e+000,0.000000e+000,0.000000e+000,0,,0,
1524540648.202,,0.000000e+000,3.499872e+001,7.426599e-006,0.000000e+000,3,9.003223e-001,0.000000e+000,,,,,,,,,,,,,,32,1,4.000000e+000,0.000000e+000,0.000000e+000,0,,0,
1524540686.040,,0.000000e+000,3.499833e+001,7.438930e-006,0.000000e+000,3,9.044607e-001,0.000000e+000,,,,,,,,,,,,,,32,1,4.000000e+000,7.781982e-004,0.000000e+000,0,,0,
1524540723.963,,0.000000e+000,3.499911e+001,7.411538e-006,0.000000e+000,3,9.059757e-001,0.000000e+000,,,,,,,,,,,,,,32,1,4.000000e+000,7.820129e-004,0.000000e+000,0,,0,
1524540761.989,,0.000000e+000,3.499911e+001,7.440343e-006,0.000000e+000,3,9.053020e-001,0.000000e+000,,,,,,,,,,,,,,32,1,4.000000e+000,2.338409e-003,0.000000e+000,0,,0,
1524540800.094,,0.000000e+000,3.499715e+001,7.411620e-006,0.000000e+000,3,9.063180e-001,0.000000e+000,,,,,,,,,,,,,,32,1,4.000000e+000,3.128052e-003,0.000000e+000,0,,0,
1524540838.137,,0.000000e+000,3.499872e+001,7.415404e-006,0.000000e+000,3,9.071324e-001,0.000000e+000,,,,,,,,,,,,,,32,1,4.000000e+000,1.560211e-003,0.000000e+000,0,,0,
1524540876.145,,0.000000e+000,3.499911e+001,7.425193e-006,0.000000e+000,3,9.077166e-001,0.000000e+000,,,,,,,,,,,,,,32,1,4.000000e+000,7.820129e-004,0.000000e+000,0,,0,
1524540913.681,,0.000000e+000,3.499715e+001,7.435695e-006,0.000000e+000,3,9.048293e-001,0.000000e+000,,,,,,,,,,,,,,32,1,4.000000e+000,3.128052e-003,0.000000e+000,0,,0,
1524540951.524,,0.000000e+000,3.499872e+001,7.432318e-006,0.000000e+000,3,9.066638e-001,0.000000e+000,,,,,,,,,,,,,,32,1,4.000000e+000,0.000000e+000,0.000000e+000,0,,0,
1524540989.787,,0.000000e+000,3.499872e+001,7.397065e-006,0.000000e+000,3,9.065526e-001,0.000000e+000,,,,,,,,,,,,,,32,1,4.000000e+000,0.000000e+000,0.000000e+000,0,,0,
1524541027.842,,0.000000e+000,3.499872e+001,7.409121e-006,0.000000e+000,3,9.092649e-001,0.000000e+000,,,,,,,,,,,,,,32,1,4.000000e+000,1.560211e-003,0.000000e+000,0,,0,
1524541065.971,,0.000000e+000,3.499872e+001,7.416409e-006,0.000000e+000,3,9.057769e-001,0.000000e+000,,,,,,,,,,,,,,32,1,4.000000e+000,1.560211e-003,0.000000e+000,0,,0,
1524541103.951,,0.000000e+000,3.499950e+001,7.428741e-006,0.000000e+000,3,9.044710e-001,0.000000e+000,,,,,,,,,,,,,,32,1,4.000000e+000,1.560211e-003,0.000000e+000,0,,0,
1524541142.052,,0.000000e+000,3.499872e+001,7.422822e-006,0.000000e+000,3,9.094291e-001,0.000000e+000,,,,,,,,,,,,,,32,1,4.000000e+000,1.560211e-003,0.000000e+000,0,,0,
1524541179.570,,0.000000e+000,3.499911e+001,7.420880e-006,0.000000e+000,3,9.033169e-001,0.000000e+000,,,,,,,,,,,,,,32,1,4.000000e+000,7.820129e-004,0.000000e+000,0,,0,
1524541216.938,,0.000000e+000,3.499950e+001,7.416504e-006,0.000000e+000,3,9.073368e-001,0.000000e+000,,,,,,,,,,,,,,32,1,4.000000e+000,0.000000e+000,0.000000e+000,0,,0,
1524541254.231,,0.000000e+000,3.499911e+001,7.410987e-006,0.000000e+000,3,9.009761e-001,0.000000e+000,,,,,,,,,,,,,,32,1,4.000000e+000,7.820129e-004,0.000000e+000,0,,0,
1524541291.989,,0.000000e+000,3.500067e+001,7.352367e-006,0.000000e+000,3,9.086233e-001,0.000000e+000,,,,,,,,,,,,,,32,1,4.000000e+000,2.338409e-003,0.000000e+000,0,,0,
1524541329.962,,0.000000e+000,3.499950e+001,7.409933e-006,0.000000e+000,3,9.068145e-001,0.000000e+000,,,,,,,,,,,,,,32,1,4.000000e+000,0.000000e+000,0.000000e+000,0,,0,
1524541367.865,,0.000000e+000,3.499911e+001,7.406778e-006,0.000000e+000,3,9.038820e-001,0.000000e+000,,,,,,,,,,,,,,32,1,4.000000e+000,7.820129e-004,0.000000e+000,0,,0,
1524541405.946,,0.000000e+000,3.499950e+001,7.381785e-006,0.000000e+000,3,9.048683e-001,0.000000e+000,,,,,,,,,,,,,,32,1,4.000000e+000,0.000000e+000,0.000000e+000,0,,0,
1524541443.736,,0.000000e+000,3.499911e+001,7.379646e-006,0.000000e+000,3,9.045305e-001,0.000000e+000,,,,,,,,,,,,,,32,1,4.000000e+000,7.820129e-004,0.000000e+000,0,,0,
1524541481.439,,0.000000e+000,3.499950e+001,7.419037e-006,0.000000e+000,3,9.092450e-001,0.000000e+000,,,,,,,,,,,,,,32,1,4.000000e+000,1.560211e-003,0.000000e+000,0,,0,
1524541519.245,,0.000000e+000,3.499911e+001,7.469505e-006,0.000000e+000,3,9.078715e-001,0.000000e+000,,,,,,,,,,,,,,32,1,4.000000e+000,7.820129e-004,0.000000e+000,0,,0,
1524541557.555,,0.000000e+000,3.499989e+001,7.425734e-006,0.000000e+000,3,9.030800e-001,0.000000e+000,,,,,,,,,,,,,,32,1,4.000000e+000,7.781982e-004,0.000000e+000,0,,0,
1524541595.361,,0.000000e+000,3.500106e+001,7.377372e-006,0.000000e+000,3,9.069831e-001,0.000000e+000,,,,,,,,,,,,,,32,1,4.000000e+000,4.692078e-003,0.000000e+000,0,,0,
1524541633.651,,0.000000e+000,3.499950e+001,7.391763e-006,0.000000e+000,3,9.070607e-001,0.000000e+000,,,,,,,,,,,,,,32,1,4.000000e+000,1.560211e-003,0.000000e+000,0,,0,
1524541671.427,,0.000000e+000,3.499911e+001,7.390362e-006,0.000000e+000,3,9.076218e-001,0.000000e+000,,,,,,,,,,,,,,32,1,4.000000e+000,7.820129e-004,0.000000e+000,0,,0,
1524541709.402,,0.000000e+000,3.499637e+001,7.415729e-006,0.000000e+000,3,9.047412e-001,0.000000e+000,,,,,,,,,,,,,,32,1,4.000000e+000,6.259918e-003,0.000000e+000,0,,0,
1524541747.948,,0.000000e+000,3.500028e+001,7.415676e-006,0.000000e+000,3,9.041870e-001,0.000000e+000,,,,,,,,,,,,,,32,1,4.000000e+000,1.560211e-003,0.000000e+000,0,,0,
1524541785.956,,0.000000e+000,3.499872e+001,7.372430e-006,0.000000e+000,3,9.050571e-001,0.000000e+000,,,,,,,,,,,,,,32,1,4.000000e+000,0.000000e+000,0.000000e+000,0,,0,
1524541824.309,,0.000000e+000,3.499794e+001,7.347292e-006,0.000000e+000,3,9.026738e-001,0.000000e+000,,,,,,,,,,,,,,32,1,4.000000e+000,0.000000e+000,0.000000e+000,0,,0,
1524541862.360,,0.000000e+000,3.500067e+001,7.373044e-006,0.000000e+000,3,9.025872e-001,0.000000e+000,,,,,,,,,,,,,,32,1,4.000000e+000,3.910065e-003,0.000000e+000,0,,0,
1524541900.348,,0.000000e+000,3.499872e+001,7.354284e-006,0.000000e+000,3,9.086965e-001,0.000000e+000,,,,,,,,,,,,,,32,1,4.000000e+000,0.000000e+000,0.000000e+000,0,,0,
1524541938.408,,0.000000e+000,3.499911e+001,7.402979e-006,0.000000e+000,3,9.062070e-001,0.000000e+000,,,,,,,,,,,,,,32,1,4.000000e+000,7.820129e-004,0.000000e+000,0,,0,
1524541976.481,,0.000000e+000,3.499989e+001,7.385462e-006,0.000000e+000,3,9.053998e-001,0.000000e+000,,,,,,,,,,,,,,32,1,4.000000e+000,7.781982e-004,0.000000e+000,0,,0,
1524542014.612,,0.000000e+000,3.499989e+001,7.363986e-006,0.000000e+000,3,9.058429e-001,0.000000e+000,,,,,,,,,,,,,,32,1,4.000000e+000,7.781982e-004,0.000000e+000,0,,0,
1524542052.170,,0.000000e+000,3.499911e+001,7.367098e-006,0.000000e+000,3,9.047047e-001,0.000000e+000,,,,,,,,,,,,,,32,1,4.000000e+000,7.820129e-004,0.000000e+000,0,,0,
1524542090.231,,0.000000e+000,3.499950e+001,7.366803e-006,0.000000e+000,3,9.040399e-001,0.000000e+000,,,,,,,,,,,,,,32,1,4.000000e+000,1.560211e-003,0.000000e+000,0,,0,
1524542128.296,,0.000000e+000,3.499950e+001,7.394020e-006,0.000000e+000,3,9.058741e-001,0.000000e+000,,,,,,,,,,,,,,32,1,4.000000e+000,0.000000e+000,0.000000e+000,0,,0,
1524542166.787,,0.000000e+000,3.499911e+001,7.399958e-006,0.000000e+000,3,9.041828e-001,0.000000e+000,,,,,,,,,,,,,,32,1,4.000000e+000,7.820129e-004,0.000000e+000,0,,0,
1524542205.065,,0.000000e+000,3.499989e+001,7.411621e-006,0.000000e+000,3,9.083831e-001,0.000000e+000,,,,,,,,,,,,,,32,1,4.000000e+000,7.781982e-004,0.000000e+000,0,,0,
1524542243.833,,0.000000e+000,3.499872e+001,7.398454e-006,0.000000e+000,3,9.038258e-001,0.000000e+000,,,,,,,,,,,,,,32,1,4.000000e+000,1.560211e-003,0.000000e+000,0,,0,
1524542282.641,,0.000000e+000,3.499911e+001,7.386525e-006,0.000000e+000,3,9.043712e-001,0.000000e+000,,,,,,,,,,,,,,32,1,4.000000e+000,7.820129e-004,0.000000e+000,0,,0,
1524542321.036,,0.000000e+000,3.499950e+001,7.415322e-006,0.000000e+000,3,9.050797e-001,0.000000e+000,,,,,,,,,,,,,,32,1,4.000000e+000,1.560211e-003,0.000000e+000,0,,0,
1524542359.099,,0.000000e+000,3.499911e+001,7.400482e-006,0.000000e+000,3,9.055803e-001,0.000000e+000,,,,,,,,,,,,,,32,1,4.000000e+000,7.820129e-004,0.000000e+000,0,,0,
1524542397.615,,0.000000e+000,3.499911e+001,7.453257e-006,0.000000e+000,3,9.042609e-001,0.000000e+000,,,,,,,,,,,,,,32,1,4.000000e+000,7.820129e-004,0.000000e+000,0,,0,
1524542435.723,,0.000000e+000,3.499872e+001,7.400574e-006,0.000000e+000,3,9.028055e-001,0.000000e+000,,,,,,,,,,,,,,32,1,4.000000e+000,1.560211e-003,0.000000e+000,0,,0,
1524542473.566,,0.000000e+000,3.499871e+001,7.378014e-006,0.000000e+000,3,9.001319e-001,0.000000e+000,,,,,,,,,,,,,,32,1,4.000000e+000,3.128052e-003,0.000000e+000,0,,0,
1524542511.569,,0.000000e+000,3.499793e+001,7.382505e-006,0.000000e+000,3,9.081461e-001,0.000000e+000,,,,,,,,,,,,,,32,1,4.000000e+000,1.567841e-003,0.000000e+000,0,,0,
1524542549.390,,0.000000e+000,3.499872e+001,7.372019e-006,0.000000e+000,3,9.052463e-001,0.000000e+000,,,,,,,,,,,,,,32,1,4.000000e+000,1.560211e-003,0.000000e+000,0,,0,
1524542587.428,,0.000000e+000,3.499911e+001,7.394706e-006,0.000000e+000,3,9.026738e-001,0.000000e+000,,,,,,,,,,,,,,32,1,4.000000e+000,7.820129e-004,0.000000e+000,0,,0,
1524542626.183,,0.000000e+000,3.499872e+001,7.372962e-006,0.000000e+000,3,9.036873e-001,0.000000e+000,,,,,,,,,,,,,,32,1,4.000000e+000,1.560211e-003,0.000000e+000,0,,0,
1524542664.392,,0.000000e+000,3.499754e+001,7.402111e-006,0.000000e+000,3,9.008001e-001,0.000000e+000,,,,,,,,,,,,,,32,1,4.000000e+000,7.896423e-004,0.000000e+000,0,,0,
1524542702.610,,0.000000e+000,3.499950e+001,7.389401e-006,0.000000e+000,3,9.037315e-001,0.000000e+000,,,,,,,,,,,,,,32,1,4.000000e+000,0.000000e+000,0.000000e+000,0,,0,
1524542741.468,,0.000000e+000,3.499950e+001,7.409922e-006,0.000000e+000,3,9.056002e-001,0.000000e+000,,,,,,,,,,,,,,32,1,4.000000e+000,0.000000e+000,0.000000e+000,0,,0,
1524542779.566,,0.000000e+000,3.499911e+001,7.404855e-006,0.000000e+000,3,9.037170e-001,0.000000e+000,,,,,,,,,,,,,,32,1,4.000000e+000,7.820129e-004,0.000000e+000,0,,0,
1524542817.149,,0.000000e+000,3.499793e+001,7.398465e-006,0.000000e+000,3,9.039677e-001,0.000000e+000,,,,,,,,,,,,,,32,1,4.000000e+000,1.567841e-003,0.000000e+000,0,,0,
1524542855.057,,0.000000e+000,3.499950e+001,7.366353e-006,0.000000e+000,3,9.078014e-001,0.000000e+000,,,,,,,,,,,,,,32,1,4.000000e+000,0.000000e+000,0.000000e+000,0,,0,
1524542893.125,,0.000000e+000,3.499911e+001,7.399162e-006,0.000000e+000,3,9.046798e-001,0.000000e+000,,,,,,,,,,,,,,32,1,4.000000e+000,7.820129e-004,0.000000e+000,0,,0,
1524542931.198,,0.000000e+000,3.499911e+001,7.435731e-006,0.000000e+000,3,9.085748e-001,0.000000e+000,,,,,,,,,,,,,,32,1,4.000000e+000,7.820129e-004,0.000000e+000,0,,0,
1524542969.611,,0.000000e+000,3.499911e+001,7.413784e-006,0.000000e+000,3,9.067388e-001,0.000000e+000,,,,,,,,,,,,,,32,1,4.000000e+000,7.820129e-004,0.000000e+000,0,,0,
1524543007.347,,0.000000e+000,3.499950e+001,7.408862e-006,0.000000e+000,3,9.063472e-001,0.000000e+000,,,,,,,,,,,,,,32,1,4.000000e+000,0.000000e+000,0.000000e+000,0,,0,
1524543044.940,,0.000000e+000,3.499950e+001,7.362057e-006,0.000000e+000,3,9.039676e-001,0.000000e+000,,,,,,,,,,,,,,32,1,4.000000e+000,0.000000e+000,0.000000e+000,0,,0,
1524543082.980,,0.000000e+000,3.499989e+001,7.387814e-006,0.000000e+000,3,9.035292e-001,0.000000e+000,,,,,,,,,,,,,,32,1,4.000000e+000,7.781982e-004,0.000000e+000,0,,0,
1524543121.501,,0.000000e+000,3.499950e+001,7.412748e-006,0.000000e+000,3,9.071186e-001,0.000000e+000,,,,,,,,,,,,,,32,1,4.000000e+000,1.560211e-003,0.000000e+000,0,,0,
1524543159.191,,0.000000e+000,3.499911e+001,7.424724e-006,0.000000e+000,3,9.053885e-001,0.000000e+000,,,,,,,,,,,,,,32,1,4.000000e+000,7.820129e-004,0.000000e+000,0,,0,
1524543196.934,,0.000000e+000,3.499911e+001,7.422043e-006,0.000000e+000,3,9.043571e-001,0.000000e+000,,,,,,,,,,,,,,32,1,4.000000e+000,7.820129e-004,0.000000e+000,0,,0,
1524543234.462,,0.000000e+000,3.499950e+001,7.392155e-006,0.000000e+000,3,9.051149e-001,0.000000e+000,,,,,,,,,,,,,,32,1,4.000000e+000,0.000000e+000,0.000000e+000,0,,0,
1524543272.508,,0.000000e+000,3.499911e+001,7.386614e-006,0.000000e+000,3,9.031553e-001,0.000000e+000,,,,,,,,,,,,,,32,1,4.000000e+000,7.820129e-004,0.000000e+000,0,,0,
1524543310.591,,0.000000e+000,3.499989e+001,7.415998e-006,0.000000e+000,3,9.033854e-001,0.000000e+000,,,,,,,,,,,,,,32,1,4.000000e+000,7.781982e-004,0.000000e+000,0,,0,
1524543348.667,,0.000000e+000,3.499989e+001,7.423941e-006,0.000000e+000,3,9.050149e-001,0.000000e+000,,,,,,,,,,,,,,32,1,4.000000e+000,7.781982e-004,0.000000e+000,0,,0,
1524543386.807,,0.000000e+000,3.499911e+001,7.420244e-006,0.000000e+000,3,9.033478e-001,0.000000e+000,,,,,,,,,,,,,,32,1,4.000000e+000,2.338409e-003,0.000000e+000,0,,0,
1524543424.130,,0.000000e+000,3.499989e+001,7.427762e-006,0.000000e+000,3,9.059891e-001,0.000000e+000,,,,,,,,,,,,,,32,1,4.000000e+000,7.781982e-004,0.000000e+000,0,,0,
1524543462.148,,0.000000e+000,3.499715e+001,7.431130e-006,0.000000e+000,3,9.028739e-001,0.000000e+000,,,,,,,,,,,,,,32,1,4.000000e+000,4.692078e-003,0.000000e+000,0,,0,
1524543500.341,,0.000000e+000,3.500106e+001,7.417892e-006,0.000000e+000,3,9.050958e-001,0.000000e+000,,,,,,,,,,,,,,32,1,4.000000e+000,1.560211e-003,0.000000e+000,0,,0,
1524543538.387,,0.000000e+000,3.499872e+001,7.407820e-006,0.000000e+000,3,9.038215e-001,0.000000e+000,,,,,,,,,,,,,,32,1,4.000000e+000,0.000000e+000,0.000000e+000,0,,0,
1524543576.475,,0.000000e+000,3.499793e+001,7.454338e-006,0.000000e+000,3,9.019706e-001,0.000000e+000,,,,,,,,,,,,,,32,1,4.000000e+000,3.131866e-003,0.000000e+000,0,,0,
1524543615.066,,0.000000e+000,3.499989e+001,7.388518e-006,0.000000e+000,3,9.028602e-001,0.000000e+000,,,,,,,,,,,,,,32,1,4.000000e+000,7.781982e-004,0.000000e+000,0,,0,
1524543652.721,,0.000000e+000,3.499911e+001,7.418428e-006,0.000000e+000,3,9.054809e-001,0.000000e+000,,,,,,,,,,,,,,32,1,4.000000e+000,7.820129e-004,0.000000e+000,0,,0,
1524543690.787,,0.000000e+000,3.499833e+001,7.393399e-006,0.000000e+000,3,9.009172e-001,0.000000e+000,,,,,,,,,,,,,,32,1,4.000000e+000,7.781982e-004,0.000000e+000,0,,0,
1524543728.687,,0.000000e+000,3.500067e+001,7.417996e-006,0.000000e+000,3,9.056885e-001,0.000000e+000,,,,,,,,,,,,,,32,1,4.000000e+000,2.338409e-003,0.000000e+000,0,,0,
1524543765.503,,0.000000e+000,3.499911e+001,7.398472e-006,0.000000e+000,3,9.049156e-001,0.000000e+000,,,,,,,,,,,,,,32,1,4.000000e+000,7.820129e-004,0.000000e+000,0,,0,
1524543802.986,,0.000000e+000,3.499950e+001,7.391511e-006,0.000000e+000,3,9.047797e-001,0.000000e+000,,,,,,,,,,,,,,32,1,4.000000e+000,0.000000e+000,0.000000e+000,0,,0,
1524543840.941,,0.000000e+000,3.499950e+001,7.363377e-006,0.000000e+000,3,9.077525e-001,0.000000e+000,,,,,,,,,,,,,,32,1,4.000000e+000,0.000000e+000,0.000000e+000,0,,0,
1524543878.612,,0.000000e+000,3.500028e+001,7.437153e-006,0.000000e+000,3,9.003235e-001,0.000000e+000,,,,,,,,,,,,,,32,1,4.000000e+000,3.120422e-003,0.000000e+000,0,,0,
1524543916.532,,0.000000e+000,3.499872e+001,7.391430e-006,0.000000e+000,3,9.047960e-001,0.000000e+000,,,,,,,,,,,,,,32,1,4.000000e+000,1.560211e-003,0.000000e+000,0,,0,
1524543954.678,,0.000000e+000,3.499911e+001,7.421365e-006,0.000000e+000,3,9.069961e-001,0.000000e+000,,,,,,,,,,,,,,32,1,4.000000e+000,7.820129e-004,0.000000e+000,0,,0,
1524543993.061,,0.000000e+000,3.499989e+001,7.418512e-006,0.000000e+000,3,9.042275e-001,0.000000e+000,,,,,,,,,,,,,,32,1,4.000000e+000,7.781982e-004,0.000000e+000,0,,0,
1524544031.734,,0.000000e+000,3.499950e+001,7.411803e-006,0.000000e+000,3,9.055670e-001,0.000000e+000,,,,,,,,,,,,,,32,1,4.000000e+000,0.000000e+000,0.000000e+000,0,,0,
1524544069.090,,0.000000e+000,3.499950e+001,7.395015e-006,0.000000e+000,3,9.060596e-001,0.000000e+000,,,,,,,,,,,,,,32,1,4.000000e+000,0.000000e+000,0.000000e+000,0,,0,
1524544106.935,,0.000000e+000,3.499911e+001,7.429994e-006,0.000000e+000,3,9.024613e-001,0.000000e+000,,,,,,,,,,,,,,32,1,4.000000e+000,7.820129e-004,0.000000e+000,0,,0,
1524544144.213,,0.000000e+000,3.499911e+001,7.409996e-006,0.000000e+000,3,9.006304e-001,0.000000e+000,,,,,,,,,,,,,,32,1,4.000000e+000,7.820129e-004,0.000000e+000,0,,0,
1524544182.391,,0.000000e+000,3.499872e+001,7.388660e-006,0.000000e+000,3,9.049314e-001,0.000000e+000,,,,,,,,,,,,,,32,1,4.000000e+000,1.560211e-003,0.000000e+000,0,,0,
1524544220.307,,0.000000e+000,3.499872e+001,7.404942e-006,0.000000e+000,3,9.060612e-001,0.000000e+000,,,,,,,,,,,,,,32,1,4.000000e+000,1.560211e-003,0.000000e+000,0,,0,
1524544258.385,,0.000000e+000,3.499950e+001,7.441439e-006,0.000000e+000,3,9.030316e-001,0.000000e+000,,,,,,,,,,,,,,32,1,4.000000e+000,1.560211e-003,0.000000e+000,0,,0,
1524544295.960,,0.000000e+000,3.500067e+001,7.440069e-006,0.000000e+000,3,9.028358e-001,0.000000e+000,,,,,,,,,,,,,,32,1,4.000000e+000,2.338409e-003,0.000000e+000,0,,0,
1524544333.999,,0.000000e+000,3.499989e+001,7.463103e-006,0.000000e+000,3,9.052516e-001,0.000000e+000,,,,,,,,,,,,,,32,1,4.000000e+000,7.781982e-004,0.000000e+000,0,,0,
1524544371.902,,0.000000e+000,3.499911e+001,7.422771e-006,0.000000e+000,3,9.086733e-001,0.000000e+000,,,,,,,,,,,,,,32,1,4.000000e+000,7.820129e-004,0.000000e+000,0,,0,
1524544410.552,,0.000000e+000,3.499950e+001,7.416197e-006,0.000000e+000,3,9.024194e-001,0.000000e+000,,,,,,,,,,,,,,32,1,4.000000e+000,0.000000e+000,0.000000e+000,0,,0,
1524544448.155,,0.000000e+000,3.499950e+001,7.392287e-006,0.000000e+000,3,9.035094e-001,0.000000e+000,,,,,,,,,,,,,,32,1,4.000000e+000,1.560211e-003,0.000000e+000,0,,0,
1524544486.211,,0.000000e+000,3.499872e+001,7.394289e-006,0.000000e+000,3,9.046395e-001,0.000000e+000,,,,,,,,,,,,,,32,1,4.000000e+000,0.000000e+000,0.000000e+000,0,,0,
1524544523.509,,0.000000e+000,3.499715e+001,7.429462e-006,0.000000e+000,3,9.013646e-001,0.000000e+000,,,,,,,,,,,,,,32,1,4.000000e+000,6.248474e-003,0.000000e+000,0,,0,
1524544561.292,,0.000000e+000,3.499872e+001,7.469442e-006,0.000000e+000,3,9.057895e-001,0.000000e+000,,,,,,,,,,,,,,32,1,4.000000e+000,1.560211e-003,0.000000e+000,0,,0,
1524544599.382,,0.000000e+000,3.499911e+001,7.457661e-006,0.000000e+000,3,9.045123e-001,0.000000e+000,,,,,,,,,,,,,,32,1,4.000000e+000,2.338409e-003,0.000000e+000,0,,0,
1524544637.233,,0.000000e+000,3.499833e+001,7.432344e-006,0.000000e+000,3,9.088986e-001,0.000000e+000,,,,,,,,,,,,,,32,1,4.000000e+000,2.349854e-003,0.000000e+000,0,,0,
1524544649.948,,0.000000e+000,3.500145e+001,7.426220e-006,0.000000e+000,3,9.062247e-001,0.000000e+000,,,,,,,,,,,,,,32,1,4.000000e+000,7.781982e-004,0.000000e+000,0,,0,