File: Input_All/MFn1_VRMac_35K_750s_VRMde_35K.dc.dat
[Header]
TITLE,MPMS DC Measurement
BYAPP,MPMS Measurement,2.1,Summary
FILEOPENTIME, 1524079914.123000 4/18/2018, 1:31:54 PM

INFO, APPNAME, MPMS MultiVu Application, Revision 1.61,  Build 082

INFO, NAME, MFn1
INFO, WEIGHT, 1.000
INFO, AREA, 1.000
INFO, LENGTH, 1.000
INFO, SHAPE, 0
INFO, COMMENT,
INFO, SEQUENCE FILE: VRMac_35K_750s_VRMde_35K.seq


INFO, BACKGROUND DATA FILE:, None


STARTUPAXIS,X,4,LINEAR,AUTO,0.000000,0.000000
STARTUPAXIS,Y1,5,LINEAR,AUTO,0.000000,0.000000


STARTUPGROUP,Longitudinal
FIELDGROUP,Longitudinal,1,2,3,4,5,6,7,8,9,15,16,17,18,27,28
FIELDGROUP,Transverse,1,2,3,4,10,11,12,13,14,19,20,21,22,27,28

PLOT_APPEARANCE,ALL,HORZ_GRID_ON,VERT_GRID_ON,MARKERS_AND_LINES

[Data]
Time,Comment,Field (Oe),Temperature (K),Long Moment (emu),Long Scan Std Dev,Long Algorithm,Long Reg Fit,Long Percent Error (%),Trans Moment (emu),Trans Scan Std Dev,Trans Algorithm,Trans Reg Fit,Trans Percent Error (%),Long Moment [w/o ABS] (emu),Long Scan Std Dev [w/o ABS],Long Reg Fit [w/o ABS],Long Percent Error [w/o ABS] (%),Trans Moment [w/o ABS] (emu),Trans Scan Std Dev [w/o ABS],Trans Reg Fit [w/o ABS],Trans Percent Error [w/o ABS] (%),Points per Scan,Scans per Measurement,Scan Length (cm),Delta Temp (K),Rot Position (deg),Error,EC Comp. Running,Using ABS,
1524079914.121,,0.000000e+000,3.499637e+001,-1.240172e-005,0.000000e+000,3,9.302642e-001,0.000000e+000,,,,,,,,,,,,,,32,1,4.000000e+000,1.560211e-003,0.000000e+000,0,,0,
1524079938.938,,0.000000e+000,3.499872e+001,-9.936274e-006,0.000000e+000,3,9.121360e-001,0.000000e+000,,,,,,,,,,,,,,32,1,4.000000e+000,1.560211e-003,0.000000e+000,0,,0,
1524079964.169,,0.000000e+000,3.499872e+001,-8.409914e-006,0.000000e+000,3,8.951234e-001,0.000000e+000,,,,,,,,,,,,,,32,1,4.000000e+000,0.000000e+000,0.000000e+000,0,,0,
1524079989.379,,0.000000e+000,3.499833e+001,-7.304018e-006,0.000000e+000,3,8.775772e-001,0.000000e+000,,,,,,,,,,,,,,32,1,4.000000e+000,7.781982e-004,0.000000e+000,0,,0,
1524080014.765,,0.000000e+000,3.499872e+001,-6.457110e-006,0.000000e+000,3,8.668183e-001,0.000000e+000,,,,,,,,,,,,,,32,1,4.000000e+000,1.560211e-003,0.000000e+000,0,,0,
1524080040.178,,0.000000e+000,3.499872e+001,-5.831223e-006,0.000000e+000,3,8.455730e-001,0.000000e+000,,,,,,,,,,,,,,32,1,4.000000e+000,0.000000e+000,0.000000e+000,0,,0,
1524080065.508,,0.000000e+000,3.499911e+001,-5.207590e-006,0.000000e+000,3,8.271095e-001,0.000000e+000,,,,,,,,,,,,,,32,1,4.000000e+000,7.820129e-004,0.000000e+000,0,,0,
1524080090.746,,0.000000e+000,3.499950e+001,-4.809314e-006,0.000000e+000,3,8.125336e-001,0.000000e+000,,,,,,,,,,,,,,32,1,4.000000e+000,1.560211e-003,0.000000e+000,0,,0,
1524080115.506,,0.000000e+000,3.499833e+001,-4.440106e-006,0.000000e+000,3,7.967845e-001,0.000000e+000,,,,,,,,,,,,,,32,1,4.000000e+000,2.349854e-003,0.000000e+000,0,,0,
1524080140.899,,0.000000e+000,3.499793e+001,-4.047696e-006,0.000000e+000,3,7.749082e-001,0.000000e+000,,,,,,,,,,,,,,32,1,4.000000e+000,1.567841e-003,0.000000e+000,0,,0,
1524080165.727,,0.000000e+000,3.499872e+001,-3.746972e-006,0.000000e+000,3,7.671008e-001,0.000000e+000,,,,,,,,,,,,,,32,1,4.000000e+000,0.000000e+000,0.000000e+000,0,,0,
1524080191.185,,0.000000e+000,3.499872e+001,-3.453178e-006,0.000000e+000,3,7.313743e-001,0.000000e+000,,,,,,,,,,,,,,32,1,4.000000e+000,0.000000e+000,0.000000e+000,0,,0,
1524080216.830,,0.000000e+000,3.499833e+001,-3.221447e-006,0.000000e+000,3,7.163739e-001,0.000000e+000,,,,,,,,,,,,,,32,1,4.000000e+000,7.781982e-004,0.000000e+000,0,,0,
1524080242.243,,0.000000e+000,3.499833e+001,-2.992132e-006,0.000000e+000,3,6.895038e-001,0.000000e+000,,,,,,,,,,,,,,32,1,4.000000e+000,7.781982e-004,0.000000e+000,0,,0,
1524080267.618,,0.000000e+000,3.499872e+001,-2.729339e-006,0.000000e+000,3,6.618347e-001,0.000000e+000,,,,,,,,,,,,,,32,1,4.000000e+000,0.000000e+000,0.000000e+000,0,,0,
1524080293.449,,0.000000e+000,3.499872e+001,-2.612765e-006,0.000000e+000,3,6.520586e-001,0.000000e+000,,,,,,,,,,,,,,32,1,4.000000e+000,1.560211e-003,0.000000e+000,0,,0,
1524080318.307,,0.000000e+000,3.499872e+001,-2.495998e-006,0.000000e+000,3,6.185259e-001,0.000000e+000,,,,,,,,,,,,,,32,1,4.000000e+000,1.560211e-003,0.000000e+000,0,,0,
1524080343.442,,0.000000e+000,3.499794e+001,-2.247966e-006,0.000000e+000,3,5.902720e-001,0.000000e+000,,,,,,,,,,,,,,32,1,4.000000e+000,0.000000e+000,0.000000e+000,0,,0,
1524080369.092,,0.000000e+000,3.499833e+001,-2.066803e-006,0.000000e+000,3,5.556169e-001,0.000000e+000,,,,,,,,,,,,,,32,1,4.000000e+000,7.781982e-004,0.000000e+000,0,,0,
1524080394.468,,0.000000e+000,3.499911e+001,-1.998417e-006,0.000000e+000,3,5.406748e-001,0.000000e+000,,,,,,,,,,,,,,32,1,4.000000e+000,7.820129e-004,0.000000e+000,0,,0,
1524080419.636,,0.000000e+000,3.499872e+001,-1.855758e-006,0.000000e+000,3,5.084538e-001,0.000000e+000,,,,,,,,,,,,,,32,1,4.000000e+000,0.000000e+000,0.000000e+000,0,,0,
1524080444.711,,0.000000e+000,3.499794e+001,-1.630664e-006,0.000000e+000,3,4.440921e-001,0.000000e+000,,,,,,,,,,,,,,32,1,4.000000e+000,0.000000e+000,0.000000e+000,0,,0,
1524080470.069,,0.000000e+000,3.499911e+001,-1.689113e-006,0.000000e+000,3,4.673243e-001,0.000000e+000,,,,,,,,,,,,,,32,1,4.000000e+000,7.820129e-004,0.000000e+000,0,,0,
1524080495.469,,0.000000e+000,3.499833e+001,-1.520228e-006,0.000000e+000,3,4.015432e-001,0.000000e+000,,,,,,,,,,,,,,32,1,4.000000e+000,2.349854e-003,0.000000e+000,0,,0,
1524080520.872,,0.000000e+000,3.499872e+001,-1.410754e-006,0.000000e+000,3,3.474239e-001,0.000000e+000,,,,,,,,,,,,,,32,1,4.000000e+000,0.000000e+000,0.000000e+000,0,,0,
1524080546.160,,0.000000e+000,3.499833e+001,-1.332946e-006,0.000000e+000,3,3.190453e-001,0.000000e+000,,,,,,,,,,,,,,32,1,4.000000e+000,7.781982e-004,0.000000e+000,0,,0,
1524080571.535,,0.000000e+000,3.499872e+001,-1.236281e-006,0.000000e+000,3,2.510521e-001,0.000000e+000,,,,,,,,,,,,,,32,1,4.000000e+000,0.000000e+000,0.000000e+000,0,,0,
1524080596.626,,0.000000e+000,3.499950e+001,-1.163562e-006,0.000000e+000,3,2.360326e-001,0.000000e+000,,,,,,,,,,,,,,32,1,4.000000e+000,0.000000e+000,0.000000e+000,0,,0,
1524080621.788,,0.000000e+000,3.499833e+001,-1.103564e-006,0.000000e+000,3,1.933830e-001,0.000000e+000,,,,,,,,,,,,,,32,1,4.000000e+000,7.781982e-004,0.000000e+000,0,,0,
1524080647.181,,0.000000e+000,3.499911e+001,-1.007829e-006,0.000000e+000,3,1.040577e-001,0.000000e+000,,,,,,,,,,,,,,32,1,4.000000e+000,7.820129e-004,0.000000e+000,0,,0,
1524080673.109,,0.000000e+000,3.499950e+001,-8.878847e-007,0.000000e+000,3,0.000000e+000,0.000000e+000,,,,,,,,,,,,,,32,1,4.000000e+000,0.000000e+000,0.000000e+000,0,,0,
1524080697.632,,0.000000e+000,3.499833e+001,-8.343347e-007,0.000000e+000,3,0.000000e+000,0.000000e+000,,,,,,,,,,,,,,32,1,4.000000e+000,7.781982e-004,0.000000e+000,0,,0,
1524080723.980,,0.000000e+000,3.499950e+001,-7.886719e-007,0.000000e+000,3,0.000000e+000,0.000000e+000,,,,,,,,,,,,,,32,1,4.000000e+000,1.560211e-003,0.000000e+000,0,,0,
1524080749.473,,0.000000e+000,3.499833e+001,-6.864732e-007,0.000000e+000,3,0.000000e+000,0.000000e+000,,,,,,,,,,,,,,32,1,4.000000e+000,7.781982e-004,0.000000e+000,0,,0,
1524080774.868,,0.000000e+000,3.499911e+001,-6.241788e-007,0.000000e+000,3,0.000000e+000,0.000000e+000,,,,,,,,,,,,,,32,1,4.000000e+000,7.820129e-004,0.000000e+000,0,,0,
1524080800.239,,0.000000e+000,3.500028e+001,-6.125527e-007,0.000000e+000,3,0.000000e+000,0.000000e+000,,,,,,,,,,,,,,32,1,4.000000e+000,3.120422e-003,0.000000e+000,0,,0,
1524080825.609,,0.000000e+000,3.499794e+001,-5.690548e-007,0.000000e+000,3,0.000000e+000,0.000000e+000,,,,,,,,,,,,,,32,1,4.000000e+000,0.000000e+000,0.000000e+000,0,,0,
1524080850.942,,0.000000e+000,3.499911e+001,-5.251028e-007,0.000000e+000,3,0.000000e+000,0.000000e+000,,,,,,,,,,,,,,32,1,4.000000e+000,7.820129e-004,0.000000e+000,0,,0,
1524080876.405,,0.000000e+000,3.499833e+001,7.245050e-007,0.000000e+000,3,0.000000e+000,0.000000e+000,,,,,,,,,,,,,,32,1,4.000000e+000,7.781982e-004,0.000000e+000,0,,0,
1524080901.778,,0.000000e+000,3.499833e+001,-4.263028e-007,0.000000e+000,3,0.000000e+000,0.000000e+000,,,,,,,,,,,,,,32,1,4.000000e+000,7.781982e-004,0.000000e+000,0,,0,
1524080926.666,,0.000000e+000,3.500028e+001,-4.177375e-007,0.000000e+000,3,0.000000e+000,0.000000e+000,,,,,,,,,,,,,,32,1,4.000000e+000,3.120422e-003,0.000000e+000,0,,0,
1524080951.238,,0.000000e+000,3.499911e+001,1.064633e-007,0.000000e+000,3,0.000000e+000,0.000000e+000,,,,,,,,,,,,,,32,1,4.000000e+000,7.820129e-004,0.000000e+000,0,,0,
1524080978.772,,0.000000e+000,3.499989e+001,7.494746e-007,0.000000e+000,3,0.000000e+000,0.000000e+000,,,,,,,,,,,,,,32,1,4.000000e+000,7.781982e-004,0.000000e+000,0,,0,
1524081004.190,,0.000000e+000,3.499793e+001,7.970298e-007,0.000000e+000,3,0.000000e+000,0.000000e+000,,,,,,,,,,,,,,32,1,4.000000e+000,1.567841e-003,0.000000e+000,0,,0,
1524081031.619,,0.000000e+000,3.500028e+001,6.373680e-007,0.000000e+000,3,0.000000e+000,0.000000e+000,,,,,,,,,,,,,,32,1,4.000000e+000,1.560211e-003,0.000000e+000,0,,0,
1524081060.254,,0.000000e+000,3.499911e+001,-1.740463e-007,0.000000e+000,2,0.000000e+000,0.000000e+000,,,,,,,,,,,,,,32,1,4.000000e+000,2.338409e-003,0.000000e+000,0,,0,
1524081088.580,,0.000000e+000,3.499989e+001,-9.625648e-008,0.000000e+000,2,0.000000e+000,0.000000e+000,,,,,,,,,,,,,,32,1,4.000000e+000,2.342224e-003,0.000000e+000,0,,0,
1524081115.351,,0.000000e+000,3.500028e+001,-1.130599e-007,0.000000e+000,2,0.000000e+000,0.000000e+000,,,,,,,,,,,,,,32,1,4.000000e+000,4.688263e-003,0.000000e+000,0,,0,
1524081142.245,,0.000000e+000,3.499911e+001,-7.691637e-008,0.000000e+000,2,0.000000e+000,0.000000e+000,,,,,,,,,,,,,,32,1,4.000000e+000,7.820129e-004,0.000000e+000,0,,0,
1524081165.945,,0.000000e+000,3.499950e+001,6.784368e-007,0.000000e+000,3,0.000000e+000,0.000000e+000,,,,,,,,,,,,,,32,1,4.000000e+000,0.000000e+000,0.000000e+000,0,,0,
1524081193.171,,0.000000e+000,3.500028e+001,-1.260634e-008,0.000000e+000,3,0.000000e+000,0.000000e+000,,,,,,,,,,,,,,32,1,4.000000e+000,1.560211e-003,0.000000e+000,0,,0,
1524081218.296,,0.000000e+000,3.499833e+001,-3.961088e-008,0.000000e+000,3,0.000000e+000,0.000000e+000,,,,,,,,,,,,,,32,1,4.000000e+000,7.781982e-004,0.000000e+000,0,,0,
1524081243.707,,0.000000e+000,3.499872e+001,-3.069240e-008,0.000000e+000,3,0.000000e+000,0.000000e+000,,,,,,,,,,,,,,32,1,4.000000e+000,1.560211e-003,0.000000e+000,0,,0,
1524081272.820,,0.000000e+000,3.499833e+001,7.098970e-008,0.000000e+000,2,0.000000e+000,0.000000e+000,,,,,,,,,,,,,,32,1,4.000000e+000,7.781982e-004,0.000000e+000,0,,0,
1524081297.830,,0.000000e+000,3.499911e+001,7.808066e-007,0.000000e+000,3,0.000000e+000,0.000000e+000,,,,,,,,,,,,,,32,1,4.000000e+000,7.820129e-004,0.000000e+000,0,,0,
1524081322.740,,0.000000e+000,3.499833e+001,7.685458e-007,0.000000e+000,3,0.000000e+000,0.000000e+000,,,,,,,,,,,,,,32,1,4.000000e+000,7.781982e-004,0.000000e+000,0,,0,
1524081351.414,,0.000000e+000,3.500028e+001,1.745262e-007,0.000000e+000,2,0.000000e+000,0.000000e+000,,,,,,,,,,,,,,32,1,4.000000e+000,1.560211e-003,0.000000e+000,0,,0,
1524081378.075,,0.000000e+000,3.499872e+001,1.717154e-007,0.000000e+000,2,0.000000e+000,0.000000e+000,,,,,,,,,,,,,,32,1,4.000000e+000,1.560211e-003,0.000000e+000,0,,0,
1524081405.544,,0.000000e+000,3.499833e+001,1.618044e-007,0.000000e+000,2,0.000000e+000,0.000000e+000,,,,,,,,,,,,,,32,1,4.000000e+000,7.781982e-004,0.000000e+000,0,,0,
1524081434.080,,0.000000e+000,3.499989e+001,2.470296e-007,0.000000e+000,2,0.000000e+000,0.000000e+000,,,,,,,,,,,,,,32,1,4.000000e+000,2.342224e-003,0.000000e+000,0,,0,
1524081461.008,,0.000000e+000,3.500028e+001,-2.506870e-007,0.000000e+000,3,0.000000e+000,0.000000e+000,,,,,,,,,,,,,,32,1,4.000000e+000,1.560211e-003,0.000000e+000,0,,0,
1524081487.592,,0.000000e+000,3.499794e+001,-2.556726e-007,0.000000e+000,3,0.000000e+000,0.000000e+000,,,,,,,,,,,,,,32,1,4.000000e+000,0.000000e+000,0.000000e+000,0,,0,
1524081512.517,,0.000000e+000,3.499833e+001,-2.316268e-007,0.000000e+000,3,0.000000e+000,0.000000e+000,,,,,,,,,,,,,,32,1,4.000000e+000,2.349854e-003,0.000000e+000,0,,0,
1524081539.306,,0.000000e+000,3.500067e+001,-2.193252e-007,0.000000e+000,3,0.000000e+000,0.000000e+000,,,,,,,,,,,,,,32,1,4.000000e+000,7.820129e-004,0.000000e+000,0,,0,
1524081564.231,,0.000000e+000,3.499911e+001,-2.221226e-007,0.000000e+000,3,0.000000e+000,0.000000e+000,,,,,,,,,,,,,,32,1,4.000000e+000,7.820129e-004,0.000000e+000,0,,0,
1524081591.854,,0.000000e+000,3.499950e+001,-3.640630e-007,0.000000e+000,3,0.000000e+000,0.000000e+000,,,,,,,,,,,,,,32,1,4.000000e+000,1.560211e-003,0.000000e+000,0,,0,
1524081618.703,,0.000000e+000,3.499872e+001,4.251272e-007,0.000000e+000,2,0.000000e+000,0.000000e+000,,,,,,,,,,,,,,32,1,4.000000e+000,0.000000e+000,0.000000e+000,0,,0,
1524081647.704,,0.000000e+000,3.499872e+001,4.129299e-007,0.000000e+000,2,0.000000e+000,0.000000e+000,,,,,,,,,,,,,,32,1,4.000000e+000,0.000000e+000,0.000000e+000,0,,0,
1524081676.241,,0.000000e+000,3.500028e+001,4.155894e-007,0.000000e+000,2,0.000000e+000,0.000000e+000,,,,,,,,,,,,,,32,1,4.000000e+000,0.000000e+000,0.000000e+000,0,,0,
1524081703.659,,0.000000e+000,3.499989e+001,1.158232e-006,0.000000e+000,3,2.250329e-001,0.000000e+000,,,,,,,,,,,,,,32,1,4.000000e+000,2.342224e-003,0.000000e+000,0,,0,
1524081733.129,,0.000000e+000,3.500028e+001,5.028922e-007,0.000000e+000,2,0.000000e+000,0.000000e+000,,,,,,,,,,,,,,32,1,4.000000e+000,1.560211e-003,0.000000e+000,0,,0,
1524081761.941,,0.000000e+000,3.499911e+001,4.867451e-007,0.000000e+000,2,0.000000e+000,0.000000e+000,,,,,,,,,,,,,,32,1,4.000000e+000,2.338409e-003,0.000000e+000,0,,0,
1524081787.898,,0.000000e+000,3.499911e+001,9.980024e-007,0.000000e+000,3,0.000000e+000,0.000000e+000,,,,,,,,,,,,,,32,1,4.000000e+000,7.820129e-004,0.000000e+000,0,,0,
1524081815.212,,0.000000e+000,3.500028e+001,1.105386e-006,0.000000e+000,3,1.417102e-001,0.000000e+000,,,,,,,,,,,,,,32,1,4.000000e+000,3.120422e-003,0.000000e+000,0,,0,
1524081843.155,,0.000000e+000,3.499872e+001,4.825744e-007,0.000000e+000,2,0.000000e+000,0.000000e+000,,,,,,,,,,,,,,32,1,4.000000e+000,0.000000e+000,0.000000e+000,0,,0,
1524081868.030,,0.000000e+000,3.499872e+001,1.054099e-006,0.000000e+000,3,8.595848e-002,0.000000e+000,,,,,,,,,,,,,,32,1,4.000000e+000,0.000000e+000,0.000000e+000,0,,0,
1524081920.077,,0.000000e+000,3.500067e+001,1.153422e-006,0.000000e+000,3,2.157666e-001,0.000000e+000,,,,,,,,,,,,,,32,1,4.000000e+000,2.338409e-003,0.000000e+000,0,,0,
1524081945.984,,0.000000e+000,3.499989e+001,1.163140e-006,0.000000e+000,3,2.324299e-001,0.000000e+000,,,,,,,,,,,,,,32,1,4.000000e+000,7.781982e-004,0.000000e+000,0,,0,
1524081971.195,,0.000000e+000,3.499911e+001,1.065937e-006,0.000000e+000,3,6.806345e-002,0.000000e+000,,,,,,,,,,,,,,32,1,4.000000e+000,7.820129e-004,0.000000e+000,0,,0,
1524081995.945,,0.000000e+000,3.499911e+001,1.193360e-006,0.000000e+000,3,2.091445e-001,0.000000e+000,,,,,,,,,,,,,,32,1,4.000000e+000,7.820129e-004,0.000000e+000,0,,0,
1524082021.336,,0.000000e+000,3.499872e+001,1.159340e-006,0.000000e+000,3,1.890985e-001,0.000000e+000,,,,,,,,,,,,,,32,1,4.000000e+000,0.000000e+000,0.000000e+000,0,,0,
1524082046.661,,0.000000e+000,3.499872e+001,1.216079e-006,0.000000e+000,3,2.664411e-001,0.000000e+000,,,,,,,,,,,,,,32,1,4.000000e+000,1.560211e-003,0.000000e+000,0,,0,
1524082071.536,,0.000000e+000,3.499872e+001,1.244440e-006,0.000000e+000,3,2.510743e-001,0.000000e+000,,,,,,,,,,,,,,32,1,4.000000e+000,1.560211e-003,0.000000e+000,0,,0,
1524082096.932,,0.000000e+000,3.499872e+001,1.241263e-006,0.000000e+000,3,2.266543e-001,0.000000e+000,,,,,,,,,,,,,,32,1,4.000000e+000,0.000000e+000,0.000000e+000,0,,0,
1524082122.290,,0.000000e+000,3.499950e+001,1.248945e-006,0.000000e+000,3,2.747501e-001,0.000000e+000,,,,,,,,,,,,,,32,1,4.000000e+000,1.560211e-003,0.000000e+000,0,,0,
1524082147.145,,0.000000e+000,3.499911e+001,1.214731e-006,0.000000e+000,3,2.403203e-001,0.000000e+000,,,,,,,,,,,,,,32,1,4.000000e+000,7.820129e-004,0.000000e+000,0,,0,
1524082172.760,,0.000000e+000,3.499872e+001,1.262806e-006,0.000000e+000,3,2.652103e-001,0.000000e+000,,,,,,,,,,,,,,32,1,4.000000e+000,0.000000e+000,0.000000e+000,0,,0,
1524082197.911,,0.000000e+000,3.499989e+001,1.265801e-006,0.000000e+000,3,2.664555e-001,0.000000e+000,,,,,,,,,,,,,,32,1,4.000000e+000,7.781982e-004,0.000000e+000,0,,0,
1524082223.259,,0.000000e+000,3.499872e+001,1.232235e-006,0.000000e+000,3,2.285487e-001,0.000000e+000,,,,,,,,,,,,,,32,1,4.000000e+000,0.000000e+000,0.000000e+000,0,,0,
1524082248.646,,0.000000e+000,3.499872e+001,1.270630e-006,0.000000e+000,3,2.664441e-001,0.000000e+000,,,,,,,,,,,,,,32,1,4.000000e+000,1.560211e-003,0.000000e+000,0,,0,
1524082274.079,,0.000000e+000,3.499911e+001,1.324966e-006,0.000000e+000,3,3.178042e-001,0.000000e+000,,,,,,,,,,,,,,32,1,4.000000e+000,2.338409e-003,0.000000e+000,0,,0,
1524082299.477,,0.000000e+000,3.499794e+001,1.327143e-006,0.000000e+000,3,3.105092e-001,0.000000e+000,,,,,,,,,,,,,,32,1,4.000000e+000,0.000000e+000,0.000000e+000,0,,0,
1524082324.790,,0.000000e+000,3.499833e+001,1.298725e-006,0.000000e+000,3,3.038386e-001,0.000000e+000,,,,,,,,,,,,,,32,1,4.000000e+000,7.781982e-004,0.000000e+000,0,,0,
1524082350.010,,0.000000e+000,3.499793e+001,1.303755e-006,0.000000e+000,3,2.875530e-001,0.000000e+000,,,,,,,,,,,,,,32,1,4.000000e+000,4.688263e-003,0.000000e+000,0,,0,
1524082375.686,,0.000000e+000,3.499872e+001,1.341790e-006,0.000000e+000,3,3.204307e-001,0.000000e+000,,,,,,,,,,,,,,32,1,4.000000e+000,1.560211e-003,0.000000e+000,0,,0,
1524082400.726,,0.000000e+000,3.499872e+001,1.393458e-006,0.000000e+000,3,3.384725e-001,0.000000e+000,,,,,,,,,,,,,,32,1,4.000000e+000,1.560211e-003,0.000000e+000,0,,0,
1524082427.142,,0.000000e+000,3.499911e+001,1.300540e-006,0.000000e+000,3,2.910960e-001,0.000000e+000,,,,,,,,,,,,,,32,1,4.000000e+000,7.820129e-004,0.000000e+000,0,,0,
1524082452.889,,0.000000e+000,3.500028e+001,1.349299e-006,0.000000e+000,3,3.222670e-001,0.000000e+000,,,,,,,,,,,,,,32,1,4.000000e+000,3.120422e-003,0.000000e+000,0,,0,
1524082478.270,,0.000000e+000,3.499872e+001,1.384480e-006,0.000000e+000,3,3.308052e-001,0.000000e+000,,,,,,,,,,,,,,32,1,4.000000e+000,1.560211e-003,0.000000e+000,0,,0,
1524082503.660,,0.000000e+000,3.499872e+001,1.421320e-006,0.000000e+000,3,3.265909e-001,0.000000e+000,,,,,,,,,,,,,,32,1,4.000000e+000,0.000000e+000,0.000000e+000,0,,0,
1524082528.681,,0.000000e+000,3.499911e+001,1.371000e-006,0.000000e+000,3,3.455090e-001,0.000000e+000,,,,,,,,,,,,,,32,1,4.000000e+000,7.820129e-004,0.000000e+000,0,,0,
1524082554.273,,0.000000e+000,3.499911e+001,1.386230e-006,0.000000e+000,3,3.368580e-001,0.000000e+000,,,,,,,,,,,,,,32,1,4.000000e+000,7.820129e-004,0.000000e+000,0,,0,
1524082578.991,,0.000000e+000,3.499872e+001,1.374149e-006,0.000000e+000,3,3.521714e-001,0.000000e+000,,,,,,,,,,,,,,32,1,4.000000e+000,0.000000e+000,0.000000e+000,0,,0,
1524082604.374,,0.000000e+000,3.499871e+001,1.374910e-006,0.000000e+000,3,3.347083e-001,0.000000e+000,,,,,,,,,,,,,,32,1,4.000000e+000,3.128052e-003,0.000000e+000,0,,0,
1524082630.462,,0.000000e+000,3.499872e+001,1.309223e-006,0.000000e+000,3,3.117232e-001,0.000000e+000,,,,,,,,,,,,,,32,1,4.000000e+000,0.000000e+000,0.000000e+000,0,,0,
1524082655.137,,0.000000e+000,3.499872e+001,1.401958e-006,0.000000e+000,3,3.912372e-001,0.000000e+000,,,,,,,,,,,,,,32,1,4.000000e+000,0.000000e+000,0.000000e+000,0,,0,
1524082680.995,,0.000000e+000,3.499872e+001,1.405117e-006,0.000000e+000,3,3.556872e-001,0.000000e+000,,,,,,,,,,,,,,32,1,4.000000e+000,0.000000e+000,0.000000e+000,0,,0,
1524082705.913,,0.000000e+000,3.499911e+001,1.424239e-006,0.000000e+000,3,3.603622e-001,0.000000e+000,,,,,,,,,,,,,,32,1,4.000000e+000,7.820129e-004,0.000000e+000,0,,0,
1524082731.296,,0.000000e+000,3.499911e+001,1.405575e-006,0.000000e+000,3,3.513533e-001,0.000000e+000,,,,,,,,,,,,,,32,1,4.000000e+000,7.820129e-004,0.000000e+000,0,,0,
1524082757.146,,0.000000e+000,3.499872e+001,1.398063e-006,0.000000e+000,3,3.597886e-001,0.000000e+000,,,,,,,,,,,,,,32,1,4.000000e+000,0.000000e+000,0.000000e+000,0,,0,
1524082782.064,,0.000000e+000,3.499911e+001,1.438141e-006,0.000000e+000,3,3.753280e-001,0.000000e+000,,,,,,,,,,,,,,32,1,4.000000e+000,7.820129e-004,0.000000e+000,0,,0,
1524082807.375,,0.000000e+000,3.499794e+001,1.403965e-006,0.000000e+000,3,3.629547e-001,0.000000e+000,,,,,,,,,,,,,,32,1,4.000000e+000,0.000000e+000,0.000000e+000,0,,0,
1524082832.770,,0.000000e+000,3.499989e+001,1.439405e-006,0.000000e+000,3,3.533578e-001,0.000000e+000,,,,,,,,,,,,,,32,1,4.000000e+000,7.781982e-004,0.000000e+000,0,,0,
1524082858.218,,0.000000e+000,3.499833e+001,1.442580e-006,0.000000e+000,3,3.761919e-001,0.000000e+000,,,,,,,,,,,,,,32,1,4.000000e+000,7.781982e-004,0.000000e+000,0,,0,
1524082883.611,,0.000000e+000,3.499872e+001,1.491490e-006,0.000000e+000,3,3.972578e-001,0.000000e+000,,,,,,,,,,,,,,32,1,4.000000e+000,1.560211e-003,0.000000e+000,0,,0,
1524082909.269,,0.000000e+000,3.499989e+001,1.499948e-006,0.000000e+000,3,3.839138e-001,0.000000e+000,,,,,,,,,,,,,,32,1,4.000000e+000,7.781982e-004,0.000000e+000,0,,0,
1524082934.697,,0.000000e+000,3.499833e+001,1.513790e-006,0.000000e+000,3,3.936253e-001,0.000000e+000,,,,,,,,,,,,,,32,1,4.000000e+000,7.781982e-004,0.000000e+000,0,,0,
1524082959.944,,0.000000e+000,3.499950e+001,1.502395e-006,0.000000e+000,3,4.126028e-001,0.000000e+000,,,,,,,,,,,,,,32,1,4.000000e+000,0.000000e+000,0.000000e+000,0,,0,
1524082985.335,,0.000000e+000,3.499989e+001,1.501341e-006,0.000000e+000,3,4.025407e-001,0.000000e+000,,,,,,,,,,,,,,32,1,4.000000e+000,7.781982e-004,0.000000e+000,0,,0,
1524083010.675,,0.000000e+000,3.499833e+001,1.551928e-006,0.000000e+000,3,3.856045e-001,0.000000e+000,,,,,,,,,,,,,,32,1,4.000000e+000,2.349854e-003,0.000000e+000,0,,0,
1524083035.961,,0.000000e+000,3.500028e+001,1.483465e-006,0.000000e+000,3,3.938033e-001,0.000000e+000,,,,,,,,,,,,,,32,1,4.000000e+000,3.120422e-003,0.000000e+000,0,,0,
1524083061.611,,0.000000e+000,3.499872e+001,1.491424e-006,0.000000e+000,3,3.887026e-001,0.000000e+000,,,,,,,,,,,,,,32,1,4.000000e+000,0.000000e+000,0.000000e+000,0,,0,
1524083087.564,,0.000000e+000,3.499911e+001,1.514820e-006,0.000000e+000,3,3.858739e-001,0.000000e+000,,,,,,,,,,,,,,32,1,4.000000e+000,7.820129e-004,0.000000e+000,0,,0,
1524083112.904,,0.000000e+000,3.499872e+001,1.526062e-006,0.000000e+000,3,3.935529e-001,0.000000e+000,,,,,,,,,,,,,,32,1,4.000000e+000,1.560211e-003,0.000000e+000,0,,0,
1524083137.974,,0.000000e+000,3.499833e+001,1.505264e-006,0.000000e+000,3,4.121219e-001,0.000000e+000,,,,,,,,,,,,,,32,1,4.000000e+000,7.781982e-004,0.000000e+000,0,,0,
1524083163.302,,0.000000e+000,3.499950e+001,1.485738e-006,0.000000e+000,3,3.983133e-001,0.000000e+000,,,,,,,,,,,,,,32,1,4.000000e+000,1.560211e-003,0.000000e+000,0,,0,
1524083188.285,,0.000000e+000,3.499989e+001,1.548229e-006,0.000000e+000,3,4.316460e-001,0.000000e+000,,,,,,,,,,,,,,32,1,4.000000e+000,2.342224e-003,0.000000e+000,0,,0,
1524083213.548,,0.000000e+000,3.499950e+001,1.536165e-006,0.000000e+000,3,4.016385e-001,0.000000e+000,,,,,,,,,,,,,,32,1,4.000000e+000,1.560211e-003,0.000000e+000,0,,0,
1524083239.378,,0.000000e+000,3.499872e+001,1.550407e-006,0.000000e+000,3,3.919498e-001,0.000000e+000,,,,,,,,,,,,,,32,1,4.000000e+000,0.000000e+000,0.000000e+000,0,,0,
1524083264.839,,0.000000e+000,3.499989e+001,1.543017e-006,0.000000e+000,3,4.379517e-001,0.000000e+000,,,,,,,,,,,,,,32,1,4.000000e+000,7.781982e-004,0.000000e+000,0,,0,
1524083290.227,,0.000000e+000,3.499872e+001,1.599526e-006,0.000000e+000,3,4.335101e-001,0.000000e+000,,,,,,,,,,,,,,32,1,4.000000e+000,1.560211e-003,0.000000e+000,0,,0,
1524083315.272,,0.000000e+000,3.499833e+001,1.675080e-006,0.000000e+000,3,4.157196e-001,0.000000e+000,,,,,,,,,,,,,,32,1,4.000000e+000,7.781982e-004,0.000000e+000,0,,0,
1524083340.427,,0.000000e+000,3.499911e+001,1.492199e-006,0.000000e+000,3,3.764962e-001,0.000000e+000,,,,,,,,,,,,,,32,1,4.000000e+000,7.820129e-004,0.000000e+000,0,,0,
1524083365.315,,0.000000e+000,3.499872e+001,1.523159e-006,0.000000e+000,3,3.915637e-001,0.000000e+000,,,,,,,,,,,,,,32,1,4.000000e+000,0.000000e+000,0.000000e+000,0,,0,
1524083390.591,,0.000000e+000,3.499872e+001,1.553718e-006,0.000000e+000,3,4.183595e-001,0.000000e+000,,,,,,,,,,,,,,32,1,4.000000e+000,0.000000e+000,0.000000e+000,0,,0,
1524083415.801,,0.000000e+000,3.499872e+001,1.586125e-006,0.000000e+000,3,4.085471e-001,0.000000e+000,,,,,,,,,,,,,,32,1,4.000000e+000,0.000000e+000,0.000000e+000,0,,0,
1524083441.001,,0.000000e+000,3.499950e+001,1.568965e-006,0.000000e+000,3,3.716278e-001,0.000000e+000,,,,,,,,,,,,,,32,1,4.000000e+000,0.000000e+000,0.000000e+000,0,,0,
1524083466.677,,0.000000e+000,3.499833e+001,1.623678e-006,0.000000e+000,3,4.606625e-001,0.000000e+000,,,,,,,,,,,,,,32,1,4.000000e+000,7.781982e-004,0.000000e+000,0,,0,
1524083492.600,,0.000000e+000,3.499911e+001,1.528043e-006,0.000000e+000,3,4.381518e-001,0.000000e+000,,,,,,,,,,,,,,32,1,4.000000e+000,7.820129e-004,0.000000e+000,0,,0,
1524083517.463,,0.000000e+000,3.499950e+001,1.584126e-006,0.000000e+000,3,4.281553e-001,0.000000e+000,,,,,,,,,,,,,,32,1,4.000000e+000,1.560211e-003,0.000000e+000,0,,0,
1524083542.538,,0.000000e+000,3.499911e+001,1.613074e-006,0.000000e+000,3,4.425066e-001,0.000000e+000,,,,,,,,,,,,,,32,1,4.000000e+000,7.820129e-004,0.000000e+000,0,,0,
1524083567.926,,0.000000e+000,3.499872e+001,1.608000e-006,0.000000e+000,3,4.321292e-001,0.000000e+000,,,,,,,,,,,,,,32,1,4.000000e+000,0.000000e+000,0.000000e+000,0,,0,
1524083593.309,,0.000000e+000,3.499950e+001,1.580626e-006,0.000000e+000,3,4.318159e-001,0.000000e+000,,,,,,,,,,,,,,32,1,4.000000e+000,0.000000e+000,0.000000e+000,0,,0,
1524083618.679,,0.000000e+000,3.499872e+001,1.639252e-006,0.000000e+000,3,4.609056e-001,0.000000e+000,,,,,,,,,,,,,,32,1,4.000000e+000,0.000000e+000,0.000000e+000,0,,0,
1524083643.582,,0.000000e+000,3.499872e+001,1.546509e-006,0.000000e+000,3,4.195842e-001,0.000000e+000,,,,,,,,,,,,,,32,1,4.000000e+000,0.000000e+000,0.000000e+000,0,,0,
1524083668.685,,0.000000e+000,3.499676e+001,1.570377e-006,0.000000e+000,3,4.176598e-001,0.000000e+000,,,,,,,,,,,,,,32,1,4.000000e+000,7.820129e-004,0.000000e+000,0,,0,
1524083693.325,,0.000000e+000,3.499833e+001,1.619620e-006,0.000000e+000,3,4.459509e-001,0.000000e+000,,,,,,,,,,,,,,32,1,4.000000e+000,7.781982e-004,0.000000e+000,0,,0,
1524083718.386,,0.000000e+000,3.499833e+001,1.626055e-006,0.000000e+000,3,4.444558e-001,0.000000e+000,,,,,,,,,,,,,,32,1,4.000000e+000,7.781982e-004,0.000000e+000,0,,0,
1524083743.916,,0.000000e+000,3.499950e+001,1.605233e-006,0.000000e+000,3,4.514972e-001,0.000000e+000,,,,,,,,,,,,,,32,1,4.000000e+000,0.000000e+000,0.000000e+000,0,,0,
1524083769.119,,0.000000e+000,3.499989e+001,1.624071e-006,0.000000e+000,3,4.422936e-001,0.000000e+000,,,,,,,,,,,,,,32,1,4.000000e+000,7.781982e-004,0.000000e+000,0,,0,
1524083794.512,,0.000000e+000,3.499989e+001,1.741465e-006,0.000000e+000,3,4.748861e-001,0.000000e+000,,,,,,,,,,,,,,32,1,4.000000e+000,7.781982e-004,0.000000e+000,0,,0,
1524083819.542,,0.000000e+000,3.499950e+001,1.629338e-006,0.000000e+000,3,4.386753e-001,0.000000e+000,,,,,,,,,,,,,,32,1,4.000000e+000,0.000000e+000,0.000000e+000,0,,0,
1524083844.787,,0.000000e+000,3.499911e+001,1.618347e-006,0.000000e+000,3,4.359646e-001,0.000000e+000,,,,,,,,,,,,,,32,1,4.000000e+000,2.338409e-003,0.000000e+000,0,,0,
1524083870.188,,0.000000e+000,3.499911e+001,1.662474e-006,0.000000e+000,3,4.594682e-001,0.000000e+000,,,,,,,,,,,,,,32,1,4.000000e+000,7.820129e-004,0.000000e+000,0,,0,
1524083895.558,,0.000000e+000,3.499833e+001,1.667932e-006,0.000000e+000,3,4.604767e-001,0.000000e+000,,,,,,,,,,,,,,32,1,4.000000e+000,7.781982e-004,0.000000e+000,0,,0,
1524083920.948,,0.000000e+000,3.499872e+001,1.626393e-006,0.000000e+000,3,4.185944e-001,0.000000e+000,,,,,,,,,,,,,,32,1,4.000000e+000,0.000000e+000,0.000000e+000,0,,0,
1524083946.336,,0.000000e+000,3.499911e+001,1.678659e-006,0.000000e+000,3,4.688999e-001,0.000000e+000,,,,,,,,,,,,,,32,1,4.000000e+000,7.820129e-004,0.000000e+000,0,,0,
1524083971.334,,0.000000e+000,3.499793e+001,1.600447e-006,0.000000e+000,3,4.618511e-001,0.000000e+000,,,,,,,,,,,,,,32,1,4.000000e+000,3.131866e-003,0.000000e+000,0,,0,
1524083996.547,,0.000000e+000,3.499911e+001,1.659893e-006,0.000000e+000,3,4.592721e-001,0.000000e+000,,,,,,,,,,,,,,32,1,4.000000e+000,7.820129e-004,0.000000e+000,0,,0,
1524084022.047,,0.000000e+000,3.499989e+001,1.651748e-006,0.000000e+000,3,4.532719e-001,0.000000e+000,,,,,,,,,,,,,,32,1,4.000000e+000,7.781982e-004,0.000000e+000,0,,0,
1524084047.315,,0.000000e+000,3.499950e+001,1.616643e-006,0.000000e+000,3,4.487770e-001,0.000000e+000,,,,,,,,,,,,,,32,1,4.000000e+000,0.000000e+000,0.000000e+000,0,,0,
1524084072.706,,0.000000e+000,3.499989e+001,1.548358e-006,0.000000e+000,3,4.205249e-001,0.000000e+000,,,,,,,,,,,,,,32,1,4.000000e+000,7.781982e-004,0.000000e+000,0,,0,
1524084098.049,,0.000000e+000,3.499950e+001,1.665009e-006,0.000000e+000,3,4.682057e-001,0.000000e+000,,,,,,,,,,,,,,32,1,4.000000e+000,0.000000e+000,0.000000e+000,0,,0,
1524084123.469,,0.000000e+000,3.499872e+001,1.694975e-006,0.000000e+000,3,4.724894e-001,0.000000e+000,,,,,,,,,,,,,,32,1,4.000000e+000,1.560211e-003,0.000000e+000,0,,0,
1524084148.599,,0.000000e+000,3.499872e+001,1.668043e-006,0.000000e+000,3,4.572785e-001,0.000000e+000,,,,,,,,,,,,,,32,1,4.000000e+000,0.000000e+000,0.000000e+000,0,,0,
1524084174.180,,0.000000e+000,3.499911e+001,1.657623e-006,0.000000e+000,3,4.747066e-001,0.000000e+000,,,,,,,,,,,,,,32,1,4.000000e+000,7.820129e-004,0.000000e+000,0,,0,
1524084200.153,,0.000000e+000,3.499911e+001,1.672659e-006,0.000000e+000,3,4.551743e-001,0.000000e+000,,,,,,,,,,,,,,32,1,4.000000e+000,7.820129e-004,0.000000e+000,0,,0,
1524084225.233,,0.000000e+000,3.499872e+001,1.695572e-006,0.000000e+000,3,4.724872e-001,0.000000e+000,,,,,,,,,,,,,,32,1,4.000000e+000,0.000000e+000,0.000000e+000,0,,0,
1524084250.618,,0.000000e+000,3.499950e+001,1.660371e-006,0.000000e+000,3,4.662692e-001,0.000000e+000,,,,,,,,,,,,,,32,1,4.000000e+000,0.000000e+000,0.000000e+000,0,,0,
1524084275.991,,0.000000e+000,3.499911e+001,1.678947e-006,0.000000e+000,3,4.653768e-001,0.000000e+000,,,,,,,,,,,,,,32,1,4.000000e+000,7.820129e-004,0.000000e+000,0,,0,
1524084300.877,,0.000000e+000,3.500028e+001,1.683074e-006,0.000000e+000,3,4.764068e-001,0.000000e+000,,,,,,,,,,,,,,32,1,4.000000e+000,3.120422e-003,0.000000e+000,0,,0,
1524084326.227,,0.000000e+000,3.500067e+001,1.683785e-006,0.000000e+000,3,4.731364e-001,0.000000e+000,,,,,,,,,,,,,,32,1,4.000000e+000,2.338409e-003,0.000000e+000,0,,0,
1524084351.552,,0.000000e+000,3.499871e+001,1.698686e-006,0.000000e+000,3,4.849648e-001,0.000000e+000,,,,,,,,,,,,,,32,1,4.000000e+000,3.128052e-003,0.000000e+000,0,,0,
1524084376.985,,0.000000e+000,3.499833e+001,1.712465e-006,0.000000e+000,3,4.774780e-001,0.000000e+000,,,,,,,,,,,,,,32,1,4.000000e+000,7.781982e-004,0.000000e+000,0,,0,
1524084402.303,,0.000000e+000,3.499989e+001,1.721518e-006,0.000000e+000,3,4.888096e-001,0.000000e+000,,,,,,,,,,,,,,32,1,4.000000e+000,7.781982e-004,0.000000e+000,0,,0,
1524084427.683,,0.000000e+000,3.499911e+001,1.718010e-006,0.000000e+000,3,4.784117e-001,0.000000e+000,,,,,,,,,,,,,,32,1,4.000000e+000,7.820129e-004,0.000000e+000,0,,0,
1524084453.146,,0.000000e+000,3.499911e+001,1.719373e-006,0.000000e+000,3,4.704781e-001,0.000000e+000,,,,,,,,,,,,,,32,1,4.000000e+000,7.820129e-004,0.000000e+000,0,,0,
1524084478.472,,0.000000e+000,3.499872e+001,1.719677e-006,0.000000e+000,3,4.975914e-001,0.000000e+000,,,,,,,,,,,,,,32,1,4.000000e+000,0.000000e+000,0.000000e+000,0,,0,
1524084503.847,,0.000000e+000,3.499754e+001,1.730269e-006,0.000000e+000,3,4.992910e-001,0.000000e+000,,,,,,,,,,,,,,32,1,4.000000e+000,3.910065e-003,0.000000e+000,0,,0,
1524084529.302,,0.000000e+000,3.499911e+001,1.748818e-006,0.000000e+000,3,4.841053e-001,0.000000e+000,,,,,,,,,,,,,,32,1,4.000000e+000,7.820129e-004,0.000000e+000,0,,0,
1524084554.608,,0.000000e+000,3.499911e+001,1.768517e-006,0.000000e+000,3,4.798955e-001,0.000000e+000,,,,,,,,,,,,,,32,1,4.000000e+000,7.820129e-004,0.000000e+000,0,,0,
1524084580.061,,0.000000e+000,3.499911e+001,1.730119e-006,0.000000e+000,3,4.859191e-001,0.000000e+000,,,,,,,,,,,,,,32,1,4.000000e+000,7.820129e-004,0.000000e+000,0,,0,
1524084605.459,,0.000000e+000,3.499989e+001,1.732790e-006,0.000000e+000,3,4.852999e-001,0.000000e+000,,,,,,,,,,,,,,32,1,4.000000e+000,7.781982e-004,0.000000e+000,0,,0,
1524084630.829,,0.000000e+000,3.499911e+001,1.738702e-006,0.000000e+000,3,4.812134e-001,0.000000e+000,,,,,,,,,,,,,,32,1,4.000000e+000,7.820129e-004,0.000000e+000,0,,0,
1524084656.222,,0.000000e+000,3.499950e+001,1.740475e-006,0.000000e+000,3,4.857963e-001,0.000000e+000,,,,,,,,,,,,,,32,1,4.000000e+000,1.560211e-003,0.000000e+000,0,,0,
1524084681.995,,0.000000e+000,3.499754e+001,1.746155e-006,0.000000e+000,3,4.841621e-001,0.000000e+000,,,,,,,,,,,,,,32,1,4.000000e+000,7.896423e-004,0.000000e+000,0,,0,
1524084707.280,,0.000000e+000,3.499911e+001,1.789260e-006,0.000000e+000,3,4.837324e-001,0.000000e+000,,,,,,,,,,,,,,32,1,4.000000e+000,7.820129e-004,0.000000e+000,0,,0,
1524084732.705,,0.000000e+000,3.499911e+001,1.746147e-006,0.000000e+000,3,4.797141e-001,0.000000e+000,,,,,,,,,,,,,,32,1,4.000000e+000,7.820129e-004,0.000000e+000,0,,0,
1524084758.513,,0.000000e+000,3.499833e+001,1.761997e-006,0.000000e+000,3,4.965838e-001,0.000000e+000,,,,,,,,,,,,,,32,1,4.000000e+000,7.781982e-004,0.000000e+000,0,,0,
1524084783.596,,0.000000e+000,3.499950e+001,1.760965e-006,0.000000e+000,3,4.825199e-001,0.000000e+000,,,,,,,,,,,,,,32,1,4.000000e+000,0.000000e+000,0.000000e+000,0,,0,
1524084810.024,,0.000000e+000,3.499833e+001,1.744786e-006,0.000000e+000,3,4.855776e-001,0.000000e+000,,,,,,,,,,,,,,32,1,4.000000e+000,7.781982e-004,0.000000e+000,0,,0,
1524084835.409,,0.000000e+000,3.499950e+001,1.747799e-006,0.000000e+000,3,4.778405e-001,0.000000e+000,,,,,,,,,,,,,,32,1,4.000000e+000,0.000000e+000,0.000000e+000,0,,0,
1524084860.802,,0.000000e+000,3.499911e+001,1.755344e-006,0.000000e+000,3,4.963456e-001,0.000000e+000,,,,,,,,,,,,,,32,1,4.000000e+000,7.820129e-004,0.000000e+000,0,,0,
1524084886.255,,0.000000e+000,3.499911e+001,1.749290e-006,0.000000e+000,3,4.942814e-001,0.000000e+000,,,,,,,,,,,,,,32,1,4.000000e+000,7.820129e-004,0.000000e+000,0,,0,
1524084911.131,,0.000000e+000,3.499872e+001,1.781856e-006,0.000000e+000,3,5.044916e-001,0.000000e+000,,,,,,,,,,,,,,32,1,4.000000e+000,0.000000e+000,0.000000e+000,0,,0,
1524084936.503,,0.000000e+000,3.499833e+001,1.748532e-006,0.000000e+000,3,4.843253e-001,0.000000e+000,,,,,,,,,,,,,,32,1,4.000000e+000,7.781982e-004,0.000000e+000,0,,0,
1524084961.894,,0.000000e+000,3.499911e+001,1.735045e-006,0.000000e+000,3,4.800386e-001,0.000000e+000,,,,,,,,,,,,,,32,1,4.000000e+000,2.338409e-003,0.000000e+000,0,,0,
1524084987.309,,0.000000e+000,3.499911e+001,1.774833e-006,0.000000e+000,3,4.989428e-001,0.000000e+000,,,,,,,,,,,,,,32,1,4.000000e+000,7.820129e-004,0.000000e+000,0,,0,
1524085012.667,,0.000000e+000,3.499833e+001,1.765816e-006,0.000000e+000,3,4.967741e-001,0.000000e+000,,,,,,,,,,,,,,32,1,4.000000e+000,2.349854e-003,0.000000e+000,0,,0,
1524085037.972,,0.000000e+000,3.499872e+001,1.739065e-006,0.000000e+000,3,4.945957e-001,0.000000e+000,,,,,,,,,,,,,,32,1,4.000000e+000,1.560211e-003,0.000000e+000,0,,0,
1524085063.368,,0.000000e+000,3.499950e+001,1.769250e-006,0.000000e+000,3,4.987457e-001,0.000000e+000,,,,,,,,,,,,,,32,1,4.000000e+000,3.120422e-003,0.000000e+000,0,,0,
1524085089.086,,0.000000e+000,3.499872e+001,1.785855e-006,0.000000e+000,3,5.030882e-001,0.000000e+000,,,,,,,,,,,,,,32,1,4.000000e+000,1.560211e-003,0.000000e+000,0,,0,
1524085114.153,,0.000000e+000,3.499911e+001,1.755015e-006,0.000000e+000,3,4.837433e-001,0.000000e+000,,,,,,,,,,,,,,32,1,4.000000e+000,7.820129e-004,0.000000e+000,0,,0,
1524085139.561,,0.000000e+000,3.499911e+001,1.808590e-006,0.000000e+000,3,4.948485e-001,0.000000e+000,,,,,,,,,,,,,,32,1,4.000000e+000,7.820129e-004,0.000000e+000,0,,0,
1524085164.469,,0.000000e+000,3.499911e+001,1.764611e-006,0.000000e+000,3,4.976330e-001,0.000000e+000,,,,,,,,,,,,,,32,1,4.000000e+000,7.820129e-004,0.000000e+000,0,,0,
1524085190.307,,0.000000e+000,3.499911e+001,1.806934e-006,0.000000e+000,3,5.047779e-001,0.000000e+000,,,,,,,,,,,,,,32,1,4.000000e+000,7.820129e-004,0.000000e+000,0,,0,
1524085215.720,,0.000000e+000,3.499872e+001,1.810949e-006,0.000000e+000,3,4.912969e-001,0.000000e+000,,,,,,,,,,,,,,32,1,4.000000e+000,1.560211e-003,0.000000e+000,0,,0,
1524085240.638,,0.000000e+000,3.499872e+001,1.774341e-006,0.000000e+000,3,4.910873e-001,0.000000e+000,,,,,,,,,,,,,,32,1,4.000000e+000,1.560211e-003,0.000000e+000,0,,0,
1524085266.486,,0.000000e+000,3.499911e+001,1.786747e-006,0.000000e+000,3,5.023524e-001,0.000000e+000,,,,,,,,,,,,,,32,1,4.000000e+000,7.820129e-004,0.000000e+000,0,,0,
1524085291.456,,0.000000e+000,3.499911e+001,1.807667e-006,0.000000e+000,3,5.077022e-001,0.000000e+000,,,,,,,,,,,,,,32,1,4.000000e+000,7.820129e-004,0.000000e+000,0,,0,
1524085317.251,,0.000000e+000,3.499950e+001,1.811659e-006,0.000000e+000,3,5.180734e-001,0.000000e+000,,,,,,,,,,,,,,32,1,4.000000e+000,0.000000e+000,0.000000e+000,0,,0,
1524085342.187,,0.000000e+000,3.499950e+001,1.809304e-006,0.000000e+000,3,5.090913e-001,0.000000e+000,,,,,,,,,,,,,,32,1,4.000000e+000,1.560211e-003,0.000000e+000,0,,0,
1524085367.485,,0.000000e+000,3.499872e+001,1.778684e-006,0.000000e+000,3,5.143703e-001,0.000000e+000,,,,,,,,,,,,,,32,1,4.000000e+000,0.000000e+000,0.000000e+000,0,,0,
1524085392.935,,0.000000e+000,3.499911e+001,1.782728e-006,0.000000e+000,3,4.996704e-001,0.000000e+000,,,,,,,,,,,,,,32,1,4.000000e+000,7.820129e-004,0.000000e+000,0,,0,
1524085418.333,,0.000000e+000,3.499911e+001,1.819326e-006,0.000000e+000,3,5.157546e-001,0.000000e+000,,,,,,,,,,,,,,32,1,4.000000e+000,7.820129e-004,0.000000e+000,0,,0,
1524085443.643,,0.000000e+000,3.499833e+001,1.812835e-006,0.000000e+000,3,4.977775e-001,0.000000e+000,,,,,,,,,,,,,,32,1,4.000000e+000,7.781982e-004,0.000000e+000,0,,0,
1524085456.323,,0.000000e+000,3.499833e+001,1.803282e-006,0.000000e+000,3,4.975794e-001,0.000000e+000,,,,,,,,,,,,,,32,1,4.000000e+000,7.781982e-004,0.000000e+000,0,,0,