File: Input_All/MFn1_VRMac_35K_3000s_VRMde_35K.dc.dat
[Header]
TITLE,MPMS DC Measurement
BYAPP,MPMS Measurement,2.1,Summary
FILEOPENTIME, 1524043254.661000 4/18/2018, 3:20:54 AM

INFO, APPNAME, MPMS MultiVu Application, Revision 1.61,  Build 082

INFO, NAME, MFn1
INFO, WEIGHT, 1.000
INFO, AREA, 1.000
INFO, LENGTH, 1.000
INFO, SHAPE, 0
INFO, COMMENT,
INFO, SEQUENCE FILE: VRMac_35K_3000s_VRMde_35K.seq


INFO, BACKGROUND DATA FILE:, None


STARTUPAXIS,X,4,LINEAR,AUTO,0.000000,0.000000
STARTUPAXIS,Y1,5,LINEAR,AUTO,0.000000,0.000000


STARTUPGROUP,Longitudinal
FIELDGROUP,Longitudinal,1,2,3,4,5,6,7,8,9,15,16,17,18,27,28
FIELDGROUP,Transverse,1,2,3,4,10,11,12,13,14,19,20,21,22,27,28

PLOT_APPEARANCE,ALL,HORZ_GRID_ON,VERT_GRID_ON,MARKERS_AND_LINES

[Data]
Time,Comment,Field (Oe),Temperature (K),Long Moment (emu),Long Scan Std Dev,Long Algorithm,Long Reg Fit,Long Percent Error (%),Trans Moment (emu),Trans Scan Std Dev,Trans Algorithm,Trans Reg Fit,Trans Percent Error (%),Long Moment [w/o ABS] (emu),Long Scan Std Dev [w/o ABS],Long Reg Fit [w/o ABS],Long Percent Error [w/o ABS] (%),Trans Moment [w/o ABS] (emu),Trans Scan Std Dev [w/o ABS],Trans Reg Fit [w/o ABS],Trans Percent Error [w/o ABS] (%),Points per Scan,Scans per Measurement,Scan Length (cm),Delta Temp (K),Rot Position (deg),Error,EC Comp. Running,Using ABS,
1524043254.656,,0.000000e+000,3.499794e+001,-1.950399e-005,0.000000e+000,3,9.547606e-001,0.000000e+000,,,,,,,,,,,,,,32,1,4.000000e+000,0.000000e+000,0.000000e+000,0,,0,
1524043293.149,,0.000000e+000,3.499950e+001,-1.603564e-005,0.000000e+000,3,9.440758e-001,0.000000e+000,,,,,,,,,,,,,,32,1,4.000000e+000,0.000000e+000,0.000000e+000,0,,0,
1524043331.147,,0.000000e+000,3.499872e+001,-1.409677e-005,0.000000e+000,3,9.343508e-001,0.000000e+000,,,,,,,,,,,,,,32,1,4.000000e+000,0.000000e+000,0.000000e+000,0,,0,
1524043369.200,,0.000000e+000,3.499872e+001,-1.290660e-005,0.000000e+000,3,9.286830e-001,0.000000e+000,,,,,,,,,,,,,,32,1,4.000000e+000,0.000000e+000,0.000000e+000,0,,0,
1524043406.903,,0.000000e+000,3.499911e+001,-1.184344e-005,0.000000e+000,3,9.228008e-001,0.000000e+000,,,,,,,,,,,,,,32,1,4.000000e+000,7.820129e-004,0.000000e+000,0,,0,
1524043444.994,,0.000000e+000,3.499872e+001,-1.105458e-005,0.000000e+000,3,9.181476e-001,0.000000e+000,,,,,,,,,,,,,,32,1,4.000000e+000,1.560211e-003,0.000000e+000,0,,0,
1524043482.569,,0.000000e+000,3.499950e+001,-1.043046e-005,0.000000e+000,3,9.142864e-001,0.000000e+000,,,,,,,,,,,,,,32,1,4.000000e+000,1.560211e-003,0.000000e+000,0,,0,
1524043521.075,,0.000000e+000,3.499833e+001,-9.831140e-006,0.000000e+000,3,9.086045e-001,0.000000e+000,,,,,,,,,,,,,,32,1,4.000000e+000,7.781982e-004,0.000000e+000,0,,0,
1524043559.161,,0.000000e+000,3.499677e+001,-9.268315e-006,0.000000e+000,3,8.989159e-001,0.000000e+000,,,,,,,,,,,,,,32,1,4.000000e+000,3.910065e-003,0.000000e+000,0,,0,
1524043597.476,,0.000000e+000,3.499833e+001,-8.825295e-006,0.000000e+000,3,8.970455e-001,0.000000e+000,,,,,,,,,,,,,,32,1,4.000000e+000,7.781982e-004,0.000000e+000,0,,0,
1524043635.612,,0.000000e+000,3.499872e+001,-8.400439e-006,0.000000e+000,3,8.895219e-001,0.000000e+000,,,,,,,,,,,,,,32,1,4.000000e+000,0.000000e+000,0.000000e+000,0,,0,
1524043674.242,,0.000000e+000,3.499911e+001,-8.082327e-006,0.000000e+000,3,8.887173e-001,0.000000e+000,,,,,,,,,,,,,,32,1,4.000000e+000,7.820129e-004,0.000000e+000,0,,0,
1524043711.525,,0.000000e+000,3.499911e+001,-7.756702e-006,0.000000e+000,3,8.814706e-001,0.000000e+000,,,,,,,,,,,,,,32,1,4.000000e+000,7.820129e-004,0.000000e+000,0,,0,
1524043749.281,,0.000000e+000,3.499872e+001,-7.465087e-006,0.000000e+000,3,8.758389e-001,0.000000e+000,,,,,,,,,,,,,,32,1,4.000000e+000,0.000000e+000,0.000000e+000,0,,0,
1524043787.512,,0.000000e+000,3.499911e+001,-7.141664e-006,0.000000e+000,3,8.701794e-001,0.000000e+000,,,,,,,,,,,,,,32,1,4.000000e+000,7.820129e-004,0.000000e+000,0,,0,
1524043826.610,,0.000000e+000,3.499911e+001,-6.899788e-006,0.000000e+000,3,8.680068e-001,0.000000e+000,,,,,,,,,,,,,,32,1,4.000000e+000,7.820129e-004,0.000000e+000,0,,0,
1524043864.715,,0.000000e+000,3.499872e+001,-6.642347e-006,0.000000e+000,3,8.658149e-001,0.000000e+000,,,,,,,,,,,,,,32,1,4.000000e+000,0.000000e+000,0.000000e+000,0,,0,
1524043902.698,,0.000000e+000,3.499950e+001,-6.487031e-006,0.000000e+000,3,8.648846e-001,0.000000e+000,,,,,,,,,,,,,,32,1,4.000000e+000,1.560211e-003,0.000000e+000,0,,0,
1524043940.741,,0.000000e+000,3.499833e+001,-6.220826e-006,0.000000e+000,3,8.566173e-001,0.000000e+000,,,,,,,,,,,,,,32,1,4.000000e+000,7.781982e-004,0.000000e+000,0,,0,
1524043978.804,,0.000000e+000,3.499911e+001,-6.015578e-006,0.000000e+000,3,8.520177e-001,0.000000e+000,,,,,,,,,,,,,,32,1,4.000000e+000,7.820129e-004,0.000000e+000,0,,0,
1524044017.245,,0.000000e+000,3.499911e+001,-5.872076e-006,0.000000e+000,3,8.281324e-001,0.000000e+000,,,,,,,,,,,,,,32,1,4.000000e+000,7.820129e-004,0.000000e+000,0,,0,
1524044055.160,,0.000000e+000,3.499833e+001,-5.648922e-006,0.000000e+000,3,8.424914e-001,0.000000e+000,,,,,,,,,,,,,,32,1,4.000000e+000,7.781982e-004,0.000000e+000,0,,0,
1524044093.356,,0.000000e+000,3.499872e+001,-5.476452e-006,0.000000e+000,3,8.321407e-001,0.000000e+000,,,,,,,,,,,,,,32,1,4.000000e+000,1.560211e-003,0.000000e+000,0,,0,
1524044130.956,,0.000000e+000,3.499480e+001,-5.316921e-006,0.000000e+000,3,8.288152e-001,0.000000e+000,,,,,,,,,,,,,,32,1,4.000000e+000,4.692078e-003,0.000000e+000,0,,0,
1524044168.929,,0.000000e+000,3.499872e+001,-5.202744e-006,0.000000e+000,3,8.242205e-001,0.000000e+000,,,,,,,,,,,,,,32,1,4.000000e+000,0.000000e+000,0.000000e+000,0,,0,
1524044206.943,,0.000000e+000,3.499872e+001,-5.041328e-006,0.000000e+000,3,8.207046e-001,0.000000e+000,,,,,,,,,,,,,,32,1,4.000000e+000,0.000000e+000,0.000000e+000,0,,0,
1524044245.013,,0.000000e+000,3.499872e+001,-4.887970e-006,0.000000e+000,3,8.137841e-001,0.000000e+000,,,,,,,,,,,,,,32,1,4.000000e+000,0.000000e+000,0.000000e+000,0,,0,
1524044283.086,,0.000000e+000,3.499833e+001,-4.783426e-006,0.000000e+000,3,8.134109e-001,0.000000e+000,,,,,,,,,,,,,,32,1,4.000000e+000,7.781982e-004,0.000000e+000,0,,0,
1524044321.114,,0.000000e+000,3.499911e+001,-4.640121e-006,0.000000e+000,3,8.161923e-001,0.000000e+000,,,,,,,,,,,,,,32,1,4.000000e+000,7.820129e-004,0.000000e+000,0,,0,
1524044359.155,,0.000000e+000,3.499911e+001,-4.547615e-006,0.000000e+000,3,7.935383e-001,0.000000e+000,,,,,,,,,,,,,,32,1,4.000000e+000,7.820129e-004,0.000000e+000,0,,0,
1524044397.208,,0.000000e+000,3.499911e+001,-4.457164e-006,0.000000e+000,3,7.943404e-001,0.000000e+000,,,,,,,,,,,,,,32,1,4.000000e+000,7.820129e-004,0.000000e+000,0,,0,
1524044435.861,,0.000000e+000,3.499833e+001,-4.318091e-006,0.000000e+000,3,7.882262e-001,0.000000e+000,,,,,,,,,,,,,,32,1,4.000000e+000,7.781982e-004,0.000000e+000,0,,0,
1524044472.824,,0.000000e+000,3.499989e+001,-4.230893e-006,0.000000e+000,3,7.877809e-001,0.000000e+000,,,,,,,,,,,,,,32,1,4.000000e+000,7.781982e-004,0.000000e+000,0,,0,
1524044510.892,,0.000000e+000,3.499950e+001,-4.133564e-006,0.000000e+000,3,7.826216e-001,0.000000e+000,,,,,,,,,,,,,,32,1,4.000000e+000,0.000000e+000,0.000000e+000,0,,0,
1524044548.060,,0.000000e+000,3.499872e+001,-4.046408e-006,0.000000e+000,3,7.758837e-001,0.000000e+000,,,,,,,,,,,,,,32,1,4.000000e+000,0.000000e+000,0.000000e+000,0,,0,
1524044585.443,,0.000000e+000,3.499911e+001,-3.951925e-006,0.000000e+000,3,7.735924e-001,0.000000e+000,,,,,,,,,,,,,,32,1,4.000000e+000,7.820129e-004,0.000000e+000,0,,0,
1524044622.721,,0.000000e+000,3.499872e+001,-3.841918e-006,0.000000e+000,3,7.676960e-001,0.000000e+000,,,,,,,,,,,,,,32,1,4.000000e+000,0.000000e+000,0.000000e+000,0,,0,
1524044660.482,,0.000000e+000,3.499833e+001,-3.748537e-006,0.000000e+000,3,7.581141e-001,0.000000e+000,,,,,,,,,,,,,,32,1,4.000000e+000,7.781982e-004,0.000000e+000,0,,0,
1524044697.635,,0.000000e+000,3.499872e+001,-3.690933e-006,0.000000e+000,3,7.551017e-001,0.000000e+000,,,,,,,,,,,,,,32,1,4.000000e+000,0.000000e+000,0.000000e+000,0,,0,
1524044736.035,,0.000000e+000,3.499872e+001,-3.527152e-006,0.000000e+000,3,7.345797e-001,0.000000e+000,,,,,,,,,,,,,,32,1,4.000000e+000,0.000000e+000,0.000000e+000,0,,0,
1524044774.103,,0.000000e+000,3.499950e+001,-3.486889e-006,0.000000e+000,3,7.375976e-001,0.000000e+000,,,,,,,,,,,,,,32,1,4.000000e+000,0.000000e+000,0.000000e+000,0,,0,
1524044812.006,,0.000000e+000,3.499794e+001,-3.396544e-006,0.000000e+000,3,7.412763e-001,0.000000e+000,,,,,,,,,,,,,,32,1,4.000000e+000,0.000000e+000,0.000000e+000,0,,0,
1524044849.859,,0.000000e+000,3.499872e+001,-3.335970e-006,0.000000e+000,3,7.261797e-001,0.000000e+000,,,,,,,,,,,,,,32,1,4.000000e+000,0.000000e+000,0.000000e+000,0,,0,
1524044887.483,,0.000000e+000,3.499872e+001,-3.300971e-006,0.000000e+000,3,7.308325e-001,0.000000e+000,,,,,,,,,,,,,,32,1,4.000000e+000,0.000000e+000,0.000000e+000,0,,0,
1524044925.543,,0.000000e+000,3.499833e+001,-3.231469e-006,0.000000e+000,3,7.278686e-001,0.000000e+000,,,,,,,,,,,,,,32,1,4.000000e+000,2.349854e-003,0.000000e+000,0,,0,
1524044964.024,,0.000000e+000,3.499872e+001,-3.187955e-006,0.000000e+000,3,7.164903e-001,0.000000e+000,,,,,,,,,,,,,,32,1,4.000000e+000,0.000000e+000,0.000000e+000,0,,0,
1524045001.699,,0.000000e+000,3.500028e+001,-3.063254e-006,0.000000e+000,3,7.013090e-001,0.000000e+000,,,,,,,,,,,,,,32,1,4.000000e+000,1.560211e-003,0.000000e+000,0,,0,
1524045040.097,,0.000000e+000,3.499950e+001,-3.059191e-006,0.000000e+000,3,7.058647e-001,0.000000e+000,,,,,,,,,,,,,,32,1,4.000000e+000,0.000000e+000,0.000000e+000,0,,0,
1524045077.700,,0.000000e+000,3.499872e+001,-3.010594e-006,0.000000e+000,3,6.992888e-001,0.000000e+000,,,,,,,,,,,,,,32,1,4.000000e+000,1.560211e-003,0.000000e+000,0,,0,
1524045115.751,,0.000000e+000,3.499950e+001,-2.928017e-006,0.000000e+000,3,6.954338e-001,0.000000e+000,,,,,,,,,,,,,,32,1,4.000000e+000,0.000000e+000,0.000000e+000,0,,0,
1524045153.352,,0.000000e+000,3.499989e+001,-2.886564e-006,0.000000e+000,3,6.965856e-001,0.000000e+000,,,,,,,,,,,,,,32,1,4.000000e+000,7.781982e-004,0.000000e+000,0,,0,
1524045191.855,,0.000000e+000,3.499872e+001,-2.782706e-006,0.000000e+000,3,6.688394e-001,0.000000e+000,,,,,,,,,,,,,,32,1,4.000000e+000,0.000000e+000,0.000000e+000,0,,0,
1524045229.500,,0.000000e+000,3.499950e+001,-2.720742e-006,0.000000e+000,3,6.647087e-001,0.000000e+000,,,,,,,,,,,,,,32,1,4.000000e+000,0.000000e+000,0.000000e+000,0,,0,
1524045266.891,,0.000000e+000,3.499950e+001,-2.670958e-006,0.000000e+000,3,6.702142e-001,0.000000e+000,,,,,,,,,,,,,,32,1,4.000000e+000,0.000000e+000,0.000000e+000,0,,0,
1524045304.251,,0.000000e+000,3.499911e+001,-2.631731e-006,0.000000e+000,3,6.521293e-001,0.000000e+000,,,,,,,,,,,,,,32,1,4.000000e+000,7.820129e-004,0.000000e+000,0,,0,
1524045342.099,,0.000000e+000,3.499911e+001,-2.596388e-006,0.000000e+000,3,6.554897e-001,0.000000e+000,,,,,,,,,,,,,,32,1,4.000000e+000,7.820129e-004,0.000000e+000,0,,0,
1524045379.790,,0.000000e+000,3.499911e+001,-2.539820e-006,0.000000e+000,3,6.406627e-001,0.000000e+000,,,,,,,,,,,,,,32,1,4.000000e+000,7.820129e-004,0.000000e+000,0,,0,
1524045417.705,,0.000000e+000,3.499871e+001,-2.498742e-006,0.000000e+000,3,6.337794e-001,0.000000e+000,,,,,,,,,,,,,,32,1,4.000000e+000,3.128052e-003,0.000000e+000,0,,0,
1524045455.988,,0.000000e+000,3.499872e+001,-2.280500e-006,0.000000e+000,3,6.016809e-001,0.000000e+000,,,,,,,,,,,,,,32,1,4.000000e+000,0.000000e+000,0.000000e+000,0,,0,
1524045494.059,,0.000000e+000,3.499872e+001,-2.376366e-006,0.000000e+000,3,6.114168e-001,0.000000e+000,,,,,,,,,,,,,,32,1,4.000000e+000,0.000000e+000,0.000000e+000,0,,0,
1524045532.059,,0.000000e+000,3.499950e+001,-2.349696e-006,0.000000e+000,3,6.192698e-001,0.000000e+000,,,,,,,,,,,,,,32,1,4.000000e+000,0.000000e+000,0.000000e+000,0,,0,
1524045570.695,,0.000000e+000,3.499872e+001,-2.301015e-006,0.000000e+000,3,6.090732e-001,0.000000e+000,,,,,,,,,,,,,,32,1,4.000000e+000,0.000000e+000,0.000000e+000,0,,0,
1524045609.668,,0.000000e+000,3.499989e+001,-2.231808e-006,0.000000e+000,3,5.957674e-001,0.000000e+000,,,,,,,,,,,,,,32,1,4.000000e+000,7.781982e-004,0.000000e+000,0,,0,
1524045647.721,,0.000000e+000,3.499950e+001,-2.189580e-006,0.000000e+000,3,5.909305e-001,0.000000e+000,,,,,,,,,,,,,,32,1,4.000000e+000,0.000000e+000,0.000000e+000,0,,0,
1524045686.504,,0.000000e+000,3.499754e+001,-2.146636e-006,0.000000e+000,3,5.813192e-001,0.000000e+000,,,,,,,,,,,,,,32,1,4.000000e+000,3.910065e-003,0.000000e+000,0,,0,
1524045723.952,,0.000000e+000,3.499950e+001,-2.156228e-006,0.000000e+000,3,5.848023e-001,0.000000e+000,,,,,,,,,,,,,,32,1,4.000000e+000,0.000000e+000,0.000000e+000,0,,0,
1524045762.138,,0.000000e+000,3.499950e+001,-2.085957e-006,0.000000e+000,3,5.683135e-001,0.000000e+000,,,,,,,,,,,,,,32,1,4.000000e+000,1.560211e-003,0.000000e+000,0,,0,
1524045800.071,,0.000000e+000,3.499754e+001,-2.079028e-006,0.000000e+000,3,5.594566e-001,0.000000e+000,,,,,,,,,,,,,,32,1,4.000000e+000,2.349854e-003,0.000000e+000,0,,0,
1524045838.154,,0.000000e+000,3.499793e+001,-2.010597e-006,0.000000e+000,3,5.544023e-001,0.000000e+000,,,,,,,,,,,,,,32,1,4.000000e+000,1.567841e-003,0.000000e+000,0,,0,
1524045876.217,,0.000000e+000,3.499989e+001,-1.962564e-006,0.000000e+000,3,5.246806e-001,0.000000e+000,,,,,,,,,,,,,,32,1,4.000000e+000,7.781982e-004,0.000000e+000,0,,0,
1524045913.910,,0.000000e+000,3.499872e+001,-1.944797e-006,0.000000e+000,3,5.313104e-001,0.000000e+000,,,,,,,,,,,,,,32,1,4.000000e+000,0.000000e+000,0.000000e+000,0,,0,
1524045952.151,,0.000000e+000,3.499911e+001,-1.880335e-006,0.000000e+000,3,5.372751e-001,0.000000e+000,,,,,,,,,,,,,,32,1,4.000000e+000,7.820129e-004,0.000000e+000,0,,0,
1524045989.444,,0.000000e+000,3.499833e+001,-1.867500e-006,0.000000e+000,3,5.100522e-001,0.000000e+000,,,,,,,,,,,,,,32,1,4.000000e+000,7.781982e-004,0.000000e+000,0,,0,
1524046026.857,,0.000000e+000,3.499911e+001,-1.824692e-006,0.000000e+000,3,5.046383e-001,0.000000e+000,,,,,,,,,,,,,,32,1,4.000000e+000,7.820129e-004,0.000000e+000,0,,0,
1524046064.887,,0.000000e+000,3.499911e+001,-1.795089e-006,0.000000e+000,3,4.982226e-001,0.000000e+000,,,,,,,,,,,,,,32,1,4.000000e+000,7.820129e-004,0.000000e+000,0,,0,
1524046102.723,,0.000000e+000,3.499911e+001,-1.779401e-006,0.000000e+000,3,4.772961e-001,0.000000e+000,,,,,,,,,,,,,,32,1,4.000000e+000,7.820129e-004,0.000000e+000,0,,0,
1524046140.971,,0.000000e+000,3.499911e+001,-1.746544e-006,0.000000e+000,3,4.873450e-001,0.000000e+000,,,,,,,,,,,,,,32,1,4.000000e+000,7.820129e-004,0.000000e+000,0,,0,
1524046179.041,,0.000000e+000,3.499989e+001,-1.713379e-006,0.000000e+000,3,4.703785e-001,0.000000e+000,,,,,,,,,,,,,,32,1,4.000000e+000,7.781982e-004,0.000000e+000,0,,0,
1524046216.635,,0.000000e+000,3.499833e+001,-1.656047e-006,0.000000e+000,3,4.391484e-001,0.000000e+000,,,,,,,,,,,,,,32,1,4.000000e+000,7.781982e-004,0.000000e+000,0,,0,
1524046255.210,,0.000000e+000,3.499911e+001,-1.616931e-006,0.000000e+000,3,4.421753e-001,0.000000e+000,,,,,,,,,,,,,,32,1,4.000000e+000,7.820129e-004,0.000000e+000,0,,0,
1524046293.426,,0.000000e+000,3.499950e+001,-1.625789e-006,0.000000e+000,3,4.411042e-001,0.000000e+000,,,,,,,,,,,,,,32,1,4.000000e+000,0.000000e+000,0.000000e+000,0,,0,
1524046331.484,,0.000000e+000,3.499989e+001,-1.623638e-006,0.000000e+000,3,4.544469e-001,0.000000e+000,,,,,,,,,,,,,,32,1,4.000000e+000,7.781982e-004,0.000000e+000,0,,0,
1524046369.547,,0.000000e+000,3.499872e+001,-1.571542e-006,0.000000e+000,3,4.363655e-001,0.000000e+000,,,,,,,,,,,,,,32,1,4.000000e+000,1.560211e-003,0.000000e+000,0,,0,
1524046407.615,,0.000000e+000,3.499833e+001,-1.573790e-006,0.000000e+000,3,4.508887e-001,0.000000e+000,,,,,,,,,,,,,,32,1,4.000000e+000,7.781982e-004,0.000000e+000,0,,0,
1524046445.658,,0.000000e+000,3.499872e+001,-1.484094e-006,0.000000e+000,3,3.931871e-001,0.000000e+000,,,,,,,,,,,,,,32,1,4.000000e+000,1.560211e-003,0.000000e+000,0,,0,
1524046483.721,,0.000000e+000,3.500028e+001,-1.474223e-006,0.000000e+000,3,3.952404e-001,0.000000e+000,,,,,,,,,,,,,,32,1,4.000000e+000,0.000000e+000,0.000000e+000,0,,0,
1524046521.787,,0.000000e+000,3.499950e+001,-1.451309e-006,0.000000e+000,3,3.909793e-001,0.000000e+000,,,,,,,,,,,,,,32,1,4.000000e+000,1.560211e-003,0.000000e+000,0,,0,
1524046559.850,,0.000000e+000,3.499950e+001,-1.411513e-006,0.000000e+000,3,3.758222e-001,0.000000e+000,,,,,,,,,,,,,,32,1,4.000000e+000,1.560211e-003,0.000000e+000,0,,0,
1524046597.963,,0.000000e+000,3.499833e+001,-1.391070e-006,0.000000e+000,3,3.491214e-001,0.000000e+000,,,,,,,,,,,,,,32,1,4.000000e+000,7.781982e-004,0.000000e+000,0,,0,
1524046636.043,,0.000000e+000,3.499911e+001,-1.364792e-006,0.000000e+000,3,3.467308e-001,0.000000e+000,,,,,,,,,,,,,,32,1,4.000000e+000,7.820129e-004,0.000000e+000,0,,0,
1524046674.044,,0.000000e+000,3.499911e+001,-1.327565e-006,0.000000e+000,3,3.191123e-001,0.000000e+000,,,,,,,,,,,,,,32,1,4.000000e+000,7.820129e-004,0.000000e+000,0,,0,
1524046712.174,,0.000000e+000,3.499872e+001,-1.347734e-006,0.000000e+000,3,3.276581e-001,0.000000e+000,,,,,,,,,,,,,,32,1,4.000000e+000,0.000000e+000,0.000000e+000,0,,0,
1524046750.230,,0.000000e+000,3.499872e+001,-1.293193e-006,0.000000e+000,3,3.000500e-001,0.000000e+000,,,,,,,,,,,,,,32,1,4.000000e+000,0.000000e+000,0.000000e+000,0,,0,
1524046787.788,,0.000000e+000,3.499950e+001,-1.288947e-006,0.000000e+000,3,3.230053e-001,0.000000e+000,,,,,,,,,,,,,,32,1,4.000000e+000,0.000000e+000,0.000000e+000,0,,0,
1524046826.281,,0.000000e+000,3.499911e+001,-1.293421e-006,0.000000e+000,3,2.912244e-001,0.000000e+000,,,,,,,,,,,,,,32,1,4.000000e+000,7.820129e-004,0.000000e+000,0,,0,
1524046863.899,,0.000000e+000,3.499911e+001,-1.223273e-006,0.000000e+000,3,2.665131e-001,0.000000e+000,,,,,,,,,,,,,,32,1,4.000000e+000,7.820129e-004,0.000000e+000,0,,0,
1524046901.862,,0.000000e+000,3.499833e+001,-1.213690e-006,0.000000e+000,3,2.565018e-001,0.000000e+000,,,,,,,,,,,,,,32,1,4.000000e+000,7.781982e-004,0.000000e+000,0,,0,
1524046939.918,,0.000000e+000,3.499989e+001,-1.208991e-006,0.000000e+000,3,2.525488e-001,0.000000e+000,,,,,,,,,,,,,,32,1,4.000000e+000,7.781982e-004,0.000000e+000,0,,0,
1524046977.991,,0.000000e+000,3.499950e+001,-1.149160e-006,0.000000e+000,3,2.069682e-001,0.000000e+000,,,,,,,,,,,,,,32,1,4.000000e+000,0.000000e+000,0.000000e+000,0,,0,
1524047016.076,,0.000000e+000,3.499794e+001,-1.103374e-006,0.000000e+000,3,1.493625e-001,0.000000e+000,,,,,,,,,,,,,,32,1,4.000000e+000,0.000000e+000,0.000000e+000,0,,0,
1524047053.677,,0.000000e+000,3.499911e+001,-1.104599e-006,0.000000e+000,3,1.886543e-001,0.000000e+000,,,,,,,,,,,,,,32,1,4.000000e+000,7.820129e-004,0.000000e+000,0,,0,
1524047091.067,,0.000000e+000,3.499872e+001,-1.092079e-006,0.000000e+000,3,1.658572e-001,0.000000e+000,,,,,,,,,,,,,,32,1,4.000000e+000,0.000000e+000,0.000000e+000,0,,0,
1524047128.493,,0.000000e+000,3.499911e+001,-1.064728e-006,0.000000e+000,3,9.528617e-002,0.000000e+000,,,,,,,,,,,,,,32,1,4.000000e+000,7.820129e-004,0.000000e+000,0,,0,
1524047166.569,,0.000000e+000,3.499989e+001,-1.063385e-006,0.000000e+000,3,1.444602e-001,0.000000e+000,,,,,,,,,,,,,,32,1,4.000000e+000,7.781982e-004,0.000000e+000,0,,0,
1524047204.579,,0.000000e+000,3.499950e+001,-1.016737e-006,0.000000e+000,3,9.006304e-002,0.000000e+000,,,,,,,,,,,,,,32,1,4.000000e+000,1.560211e-003,0.000000e+000,0,,0,
1524047242.680,,0.000000e+000,3.499872e+001,-9.959240e-007,0.000000e+000,3,8.297204e-002,0.000000e+000,,,,,,,,,,,,,,32,1,4.000000e+000,0.000000e+000,0.000000e+000,0,,0,
1524047280.678,,0.000000e+000,3.499833e+001,-9.702705e-007,0.000000e+000,3,5.865649e-002,0.000000e+000,,,,,,,,,,,,,,32,1,4.000000e+000,7.781982e-004,0.000000e+000,0,,0,
1524047318.751,,0.000000e+000,3.499989e+001,-9.745329e-007,0.000000e+000,3,5.852438e-002,0.000000e+000,,,,,,,,,,,,,,32,1,4.000000e+000,7.781982e-004,0.000000e+000,0,,0,
1524047357.604,,0.000000e+000,3.499911e+001,-9.435400e-007,0.000000e+000,3,3.848711e-002,0.000000e+000,,,,,,,,,,,,,,32,1,4.000000e+000,7.820129e-004,0.000000e+000,0,,0,
1524047396.097,,0.000000e+000,3.499950e+001,-9.387203e-007,0.000000e+000,3,2.886240e-002,0.000000e+000,,,,,,,,,,,,,,32,1,4.000000e+000,1.560211e-003,0.000000e+000,0,,0,
1524047433.250,,0.000000e+000,3.500028e+001,-9.451988e-007,0.000000e+000,3,3.818118e-002,0.000000e+000,,,,,,,,,,,,,,32,1,4.000000e+000,1.560211e-003,0.000000e+000,0,,0,
1524047471.050,,0.000000e+000,3.500067e+001,-9.058916e-007,0.000000e+000,3,0.000000e+000,0.000000e+000,,,,,,,,,,,,,,32,1,4.000000e+000,7.820129e-004,0.000000e+000,0,,0,
1524047508.578,,0.000000e+000,3.499989e+001,-8.872432e-007,0.000000e+000,3,0.000000e+000,0.000000e+000,,,,,,,,,,,,,,32,1,4.000000e+000,2.342224e-003,0.000000e+000,0,,0,
1524047546.432,,0.000000e+000,3.500028e+001,-9.119325e-007,0.000000e+000,3,1.528066e-002,0.000000e+000,,,,,,,,,,,,,,32,1,4.000000e+000,1.560211e-003,0.000000e+000,0,,0,
1524047584.167,,0.000000e+000,3.499989e+001,-8.637840e-007,0.000000e+000,3,0.000000e+000,0.000000e+000,,,,,,,,,,,,,,32,1,4.000000e+000,7.781982e-004,0.000000e+000,0,,0,
1524047622.240,,0.000000e+000,3.499989e+001,-8.521436e-007,0.000000e+000,3,0.000000e+000,0.000000e+000,,,,,,,,,,,,,,32,1,4.000000e+000,7.781982e-004,0.000000e+000,0,,0,
1524047660.303,,0.000000e+000,3.499872e+001,-7.934011e-007,0.000000e+000,3,0.000000e+000,0.000000e+000,,,,,,,,,,,,,,32,1,4.000000e+000,0.000000e+000,0.000000e+000,0,,0,
1524047698.484,,0.000000e+000,3.499950e+001,-8.491818e-007,0.000000e+000,3,0.000000e+000,0.000000e+000,,,,,,,,,,,,,,32,1,4.000000e+000,1.560211e-003,0.000000e+000,0,,0,
1524047735.914,,0.000000e+000,3.499989e+001,-7.707566e-007,0.000000e+000,3,0.000000e+000,0.000000e+000,,,,,,,,,,,,,,32,1,4.000000e+000,2.342224e-003,0.000000e+000,0,,0,
1524047773.927,,0.000000e+000,3.499989e+001,-7.806670e-007,0.000000e+000,3,0.000000e+000,0.000000e+000,,,,,,,,,,,,,,32,1,4.000000e+000,2.342224e-003,0.000000e+000,0,,0,
1524047811.883,,0.000000e+000,3.499950e+001,-7.363507e-007,0.000000e+000,3,0.000000e+000,0.000000e+000,,,,,,,,,,,,,,32,1,4.000000e+000,0.000000e+000,0.000000e+000,0,,0,
1524047849.939,,0.000000e+000,3.499793e+001,-7.250044e-007,0.000000e+000,3,0.000000e+000,0.000000e+000,,,,,,,,,,,,,,32,1,4.000000e+000,1.567841e-003,0.000000e+000,0,,0,
1524047887.859,,0.000000e+000,3.499989e+001,-6.868856e-007,0.000000e+000,3,0.000000e+000,0.000000e+000,,,,,,,,,,,,,,32,1,4.000000e+000,7.781982e-004,0.000000e+000,0,,0,
1524047926.050,,0.000000e+000,3.500106e+001,-6.923067e-007,0.000000e+000,3,0.000000e+000,0.000000e+000,,,,,,,,,,,,,,32,1,4.000000e+000,0.000000e+000,0.000000e+000,0,,0,
1524047963.683,,0.000000e+000,3.500028e+001,-6.638246e-007,0.000000e+000,3,0.000000e+000,0.000000e+000,,,,,,,,,,,,,,32,1,4.000000e+000,1.560211e-003,0.000000e+000,0,,0,
1524048001.603,,0.000000e+000,3.499872e+001,-6.636134e-007,0.000000e+000,3,0.000000e+000,0.000000e+000,,,,,,,,,,,,,,32,1,4.000000e+000,1.560211e-003,0.000000e+000,0,,0,
1524048039.811,,0.000000e+000,3.499833e+001,-6.343475e-007,0.000000e+000,3,0.000000e+000,0.000000e+000,,,,,,,,,,,,,,32,1,4.000000e+000,7.781982e-004,0.000000e+000,0,,0,
1524048077.224,,0.000000e+000,3.499911e+001,-6.005804e-007,0.000000e+000,3,0.000000e+000,0.000000e+000,,,,,,,,,,,,,,32,1,4.000000e+000,7.820129e-004,0.000000e+000,0,,0,
1524048114.592,,0.000000e+000,3.499911e+001,-6.372117e-007,0.000000e+000,3,0.000000e+000,0.000000e+000,,,,,,,,,,,,,,32,1,4.000000e+000,7.820129e-004,0.000000e+000,0,,0,
1524048151.868,,0.000000e+000,3.500028e+001,-6.233981e-007,0.000000e+000,3,0.000000e+000,0.000000e+000,,,,,,,,,,,,,,32,1,4.000000e+000,1.560211e-003,0.000000e+000,0,,0,
1524048189.936,,0.000000e+000,3.499833e+001,-5.741524e-007,0.000000e+000,3,0.000000e+000,0.000000e+000,,,,,,,,,,,,,,32,1,4.000000e+000,7.781982e-004,0.000000e+000,0,,0,
1524048227.757,,0.000000e+000,3.499872e+001,-5.926037e-007,0.000000e+000,3,0.000000e+000,0.000000e+000,,,,,,,,,,,,,,32,1,4.000000e+000,1.560211e-003,0.000000e+000,0,,0,
1524048265.490,,0.000000e+000,3.499950e+001,-4.802824e-007,0.000000e+000,3,0.000000e+000,0.000000e+000,,,,,,,,,,,,,,32,1,4.000000e+000,0.000000e+000,0.000000e+000,0,,0,
1524048303.443,,0.000000e+000,3.500185e+001,-5.345549e-007,0.000000e+000,3,0.000000e+000,0.000000e+000,,,,,,,,,,,,,,32,1,4.000000e+000,4.688263e-003,0.000000e+000,0,,0,
1524048342.231,,0.000000e+000,3.499989e+001,-5.097421e-007,0.000000e+000,3,0.000000e+000,0.000000e+000,,,,,,,,,,,,,,32,1,4.000000e+000,2.342224e-003,0.000000e+000,0,,0,
1524048379.701,,0.000000e+000,3.499950e+001,-5.227624e-007,0.000000e+000,3,0.000000e+000,0.000000e+000,,,,,,,,,,,,,,32,1,4.000000e+000,1.560211e-003,0.000000e+000,0,,0,
1524048417.747,,0.000000e+000,3.500028e+001,-3.826763e-007,0.000000e+000,3,0.000000e+000,0.000000e+000,,,,,,,,,,,,,,32,1,4.000000e+000,1.560211e-003,0.000000e+000,0,,0,
1524048455.785,,0.000000e+000,3.499872e+001,-4.079862e-007,0.000000e+000,3,0.000000e+000,0.000000e+000,,,,,,,,,,,,,,32,1,4.000000e+000,1.560211e-003,0.000000e+000,0,,0,
1524048506.571,,0.000000e+000,3.499950e+001,-3.730613e-007,0.000000e+000,3,0.000000e+000,0.000000e+000,,,,,,,,,,,,,,32,1,4.000000e+000,0.000000e+000,0.000000e+000,0,,0,
1524048544.636,,0.000000e+000,3.499989e+001,-3.940113e-007,0.000000e+000,3,0.000000e+000,0.000000e+000,,,,,,,,,,,,,,32,1,4.000000e+000,7.781982e-004,0.000000e+000,0,,0,
1524048582.702,,0.000000e+000,3.499950e+001,-2.971057e-007,0.000000e+000,3,0.000000e+000,0.000000e+000,,,,,,,,,,,,,,32,1,4.000000e+000,0.000000e+000,0.000000e+000,0,,0,
1524048620.752,,0.000000e+000,3.499950e+001,-3.955816e-007,0.000000e+000,3,0.000000e+000,0.000000e+000,,,,,,,,,,,,,,32,1,4.000000e+000,0.000000e+000,0.000000e+000,0,,0,
1524048670.968,,0.000000e+000,3.499872e+001,-2.501756e-007,0.000000e+000,3,0.000000e+000,0.000000e+000,,,,,,,,,,,,,,32,1,4.000000e+000,0.000000e+000,0.000000e+000,0,,0,
1524049143.537,,0.000000e+000,3.499872e+001,-3.247021e-007,0.000000e+000,2,0.000000e+000,0.000000e+000,,,,,,,,,,,,,,32,1,4.000000e+000,0.000000e+000,0.000000e+000,0,,0,
1524049185.376,,0.000000e+000,3.499833e+001,-3.250848e-007,0.000000e+000,2,0.000000e+000,0.000000e+000,,,,,,,,,,,,,,32,1,4.000000e+000,7.781982e-004,0.000000e+000,0,,0,
1524049224.680,,0.000000e+000,3.499872e+001,7.044606e-007,0.000000e+000,3,0.000000e+000,0.000000e+000,,,,,,,,,,,,,,32,1,4.000000e+000,0.000000e+000,0.000000e+000,0,,0,
1524049264.736,,0.000000e+000,3.500028e+001,-2.922118e-007,0.000000e+000,2,0.000000e+000,0.000000e+000,,,,,,,,,,,,,,32,1,4.000000e+000,1.560211e-003,0.000000e+000,0,,0,
1524049303.719,,0.000000e+000,3.499833e+001,6.679123e-007,0.000000e+000,3,0.000000e+000,0.000000e+000,,,,,,,,,,,,,,32,1,4.000000e+000,7.781982e-004,0.000000e+000,0,,0,
1524049347.232,,0.000000e+000,3.499911e+001,-1.881425e-007,0.000000e+000,2,0.000000e+000,0.000000e+000,,,,,,,,,,,,,,32,1,4.000000e+000,7.820129e-004,0.000000e+000,0,,0,
1524049389.675,,0.000000e+000,3.500106e+001,-2.332779e-007,0.000000e+000,2,0.000000e+000,0.000000e+000,,,,,,,,,,,,,,32,1,4.000000e+000,4.692078e-003,0.000000e+000,0,,0,
1524049431.675,,0.000000e+000,3.500067e+001,-2.004851e-007,0.000000e+000,2,0.000000e+000,0.000000e+000,,,,,,,,,,,,,,32,1,4.000000e+000,3.910065e-003,0.000000e+000,0,,0,
1524049472.266,,0.000000e+000,3.499989e+001,6.556875e-007,0.000000e+000,3,0.000000e+000,0.000000e+000,,,,,,,,,,,,,,32,1,4.000000e+000,7.781982e-004,0.000000e+000,0,,0,
1524049514.255,,0.000000e+000,3.499911e+001,7.147519e-007,0.000000e+000,3,0.000000e+000,0.000000e+000,,,,,,,,,,,,,,32,1,4.000000e+000,7.820129e-004,0.000000e+000,0,,0,
1524049555.597,,0.000000e+000,3.499950e+001,-1.767722e-007,0.000000e+000,2,0.000000e+000,0.000000e+000,,,,,,,,,,,,,,32,1,4.000000e+000,0.000000e+000,0.000000e+000,0,,0,
1524049596.429,,0.000000e+000,3.500028e+001,-2.016876e-007,0.000000e+000,2,0.000000e+000,0.000000e+000,,,,,,,,,,,,,,32,1,4.000000e+000,3.120422e-003,0.000000e+000,0,,0,
1524049638.688,,0.000000e+000,3.499989e+001,-1.716539e-007,0.000000e+000,2,0.000000e+000,0.000000e+000,,,,,,,,,,,,,,32,1,4.000000e+000,2.342224e-003,0.000000e+000,0,,0,
1524049679.045,,0.000000e+000,3.499989e+001,6.244650e-007,0.000000e+000,3,0.000000e+000,0.000000e+000,,,,,,,,,,,,,,32,1,4.000000e+000,7.041931e-003,0.000000e+000,0,,0,
1524049721.695,,0.000000e+000,3.500106e+001,-1.573452e-007,0.000000e+000,2,0.000000e+000,0.000000e+000,,,,,,,,,,,,,,32,1,4.000000e+000,1.560211e-003,0.000000e+000,0,,0,
1524049762.784,,0.000000e+000,3.499872e+001,-1.151475e-007,0.000000e+000,2,0.000000e+000,0.000000e+000,,,,,,,,,,,,,,32,1,4.000000e+000,0.000000e+000,0.000000e+000,0,,0,
1524049805.388,,0.000000e+000,3.500028e+001,-9.354859e-008,0.000000e+000,2,0.000000e+000,0.000000e+000,,,,,,,,,,,,,,32,1,4.000000e+000,1.560211e-003,0.000000e+000,0,,0,
1524049846.585,,0.000000e+000,3.500185e+001,-1.005466e-007,0.000000e+000,2,0.000000e+000,0.000000e+000,,,,,,,,,,,,,,32,1,4.000000e+000,4.688263e-003,0.000000e+000,0,,0,
1524049886.729,,0.000000e+000,3.499950e+001,-1.336178e-007,0.000000e+000,2,0.000000e+000,0.000000e+000,,,,,,,,,,,,,,32,1,4.000000e+000,0.000000e+000,0.000000e+000,0,,0,
1524049927.115,,0.000000e+000,3.500028e+001,-2.940655e-007,0.000000e+000,3,0.000000e+000,0.000000e+000,,,,,,,,,,,,,,32,1,4.000000e+000,1.560211e-003,0.000000e+000,0,,0,
1524049964.908,,0.000000e+000,3.499950e+001,6.340496e-007,0.000000e+000,3,0.000000e+000,0.000000e+000,,,,,,,,,,,,,,32,1,4.000000e+000,0.000000e+000,0.000000e+000,0,,0,
1524050006.506,,0.000000e+000,3.499950e+001,-1.185956e-007,0.000000e+000,2,0.000000e+000,0.000000e+000,,,,,,,,,,,,,,32,1,4.000000e+000,3.120422e-003,0.000000e+000,0,,0,
1524050047.347,,0.000000e+000,3.500028e+001,-8.305390e-008,0.000000e+000,2,0.000000e+000,0.000000e+000,,,,,,,,,,,,,,32,1,4.000000e+000,0.000000e+000,0.000000e+000,0,,0,
1524050085.703,,0.000000e+000,3.500028e+001,2.724533e-007,0.000000e+000,3,0.000000e+000,0.000000e+000,,,,,,,,,,,,,,32,1,4.000000e+000,1.560211e-003,0.000000e+000,0,,0,
1524050127.079,,0.000000e+000,3.499950e+001,-8.437882e-008,0.000000e+000,2,0.000000e+000,0.000000e+000,,,,,,,,,,,,,,32,1,4.000000e+000,0.000000e+000,0.000000e+000,0,,0,
1524050163.765,,0.000000e+000,3.499989e+001,2.742151e-007,0.000000e+000,3,0.000000e+000,0.000000e+000,,,,,,,,,,,,,,32,1,4.000000e+000,7.781982e-004,0.000000e+000,0,,0,
1524050203.368,,0.000000e+000,3.499911e+001,6.769958e-007,0.000000e+000,3,0.000000e+000,0.000000e+000,,,,,,,,,,,,,,32,1,4.000000e+000,2.338409e-003,0.000000e+000,0,,0,
1524050241.656,,0.000000e+000,3.499989e+001,2.478413e-008,0.000000e+000,3,0.000000e+000,0.000000e+000,,,,,,,,,,,,,,32,1,4.000000e+000,7.781982e-004,0.000000e+000,0,,0,
1524050283.048,,0.000000e+000,3.499911e+001,-6.673390e-008,0.000000e+000,2,0.000000e+000,0.000000e+000,,,,,,,,,,,,,,32,1,4.000000e+000,7.820129e-004,0.000000e+000,0,,0,
1524050320.451,,0.000000e+000,3.499911e+001,5.583375e-008,0.000000e+000,3,0.000000e+000,0.000000e+000,,,,,,,,,,,,,,32,1,4.000000e+000,7.820129e-004,0.000000e+000,0,,0,
1524050358.621,,0.000000e+000,3.499833e+001,3.076123e-008,0.000000e+000,3,0.000000e+000,0.000000e+000,,,,,,,,,,,,,,32,1,4.000000e+000,7.781982e-004,0.000000e+000,0,,0,
1524050396.664,,0.000000e+000,3.499833e+001,1.411680e-008,0.000000e+000,3,0.000000e+000,0.000000e+000,,,,,,,,,,,,,,32,1,4.000000e+000,2.349854e-003,0.000000e+000,0,,0,
1524050434.653,,0.000000e+000,3.500106e+001,6.471906e-007,0.000000e+000,3,0.000000e+000,0.000000e+000,,,,,,,,,,,,,,32,1,4.000000e+000,4.692078e-003,0.000000e+000,0,,0,
1524050472.688,,0.000000e+000,3.499950e+001,1.546088e-008,0.000000e+000,3,0.000000e+000,0.000000e+000,,,,,,,,,,,,,,32,1,4.000000e+000,1.560211e-003,0.000000e+000,0,,0,
1524050510.654,,0.000000e+000,3.500185e+001,3.339727e-008,0.000000e+000,3,0.000000e+000,0.000000e+000,,,,,,,,,,,,,,32,1,4.000000e+000,4.688263e-003,0.000000e+000,0,,0,
1524050549.684,,0.000000e+000,3.499872e+001,3.906904e-008,0.000000e+000,3,0.000000e+000,0.000000e+000,,,,,,,,,,,,,,32,1,4.000000e+000,0.000000e+000,0.000000e+000,0,,0,
1524050587.827,,0.000000e+000,3.499911e+001,4.674847e-010,0.000000e+000,3,0.000000e+000,0.000000e+000,,,,,,,,,,,,,,32,1,4.000000e+000,7.820129e-004,0.000000e+000,0,,0,
1524050625.828,,0.000000e+000,3.499911e+001,2.333638e-008,0.000000e+000,3,0.000000e+000,0.000000e+000,,,,,,,,,,,,,,32,1,4.000000e+000,7.820129e-004,0.000000e+000,0,,0,
1524050664.772,,0.000000e+000,3.499989e+001,2.868367e-011,0.000000e+000,3,0.000000e+000,0.000000e+000,,,,,,,,,,,,,,32,1,4.000000e+000,2.342224e-003,0.000000e+000,0,,0,
1524050702.855,,0.000000e+000,3.499950e+001,6.860616e-008,0.000000e+000,3,0.000000e+000,0.000000e+000,,,,,,,,,,,,,,32,1,4.000000e+000,0.000000e+000,0.000000e+000,0,,0,
1524050741.716,,0.000000e+000,3.499911e+001,-5.870913e-010,0.000000e+000,3,0.000000e+000,0.000000e+000,,,,,,,,,,,,,,32,1,4.000000e+000,7.820129e-004,0.000000e+000,0,,0,
1524050779.762,,0.000000e+000,3.499911e+001,7.849296e-009,0.000000e+000,3,0.000000e+000,0.000000e+000,,,,,,,,,,,,,,32,1,4.000000e+000,7.820129e-004,0.000000e+000,0,,0,
1524050818.297,,0.000000e+000,3.499950e+001,1.357519e-008,0.000000e+000,3,0.000000e+000,0.000000e+000,,,,,,,,,,,,,,32,1,4.000000e+000,1.560211e-003,0.000000e+000,0,,0,
1524050855.875,,0.000000e+000,3.499911e+001,1.944513e-009,0.000000e+000,3,0.000000e+000,0.000000e+000,,,,,,,,,,,,,,32,1,4.000000e+000,7.820129e-004,0.000000e+000,0,,0,
1524050893.933,,0.000000e+000,3.499989e+001,5.117890e-009,0.000000e+000,3,0.000000e+000,0.000000e+000,,,,,,,,,,,,,,32,1,4.000000e+000,7.781982e-004,0.000000e+000,0,,0,
1524050931.901,,0.000000e+000,3.499872e+001,8.846326e-009,0.000000e+000,3,0.000000e+000,0.000000e+000,,,,,,,,,,,,,,32,1,4.000000e+000,1.560211e-003,0.000000e+000,0,,0,
1524050970.009,,0.000000e+000,3.499833e+001,1.604885e-009,0.000000e+000,3,0.000000e+000,0.000000e+000,,,,,,,,,,,,,,32,1,4.000000e+000,7.781982e-004,0.000000e+000,0,,0,
1524051008.495,,0.000000e+000,3.499793e+001,1.291991e-008,0.000000e+000,3,0.000000e+000,0.000000e+000,,,,,,,,,,,,,,32,1,4.000000e+000,1.567841e-003,0.000000e+000,0,,0,
1524051045.720,,0.000000e+000,3.499911e+001,-2.429568e-010,0.000000e+000,3,0.000000e+000,0.000000e+000,,,,,,,,,,,,,,32,1,4.000000e+000,7.820129e-004,0.000000e+000,0,,0,
1524051083.686,,0.000000e+000,3.499911e+001,4.336552e-009,0.000000e+000,3,0.000000e+000,0.000000e+000,,,,,,,,,,,,,,32,1,4.000000e+000,7.820129e-004,0.000000e+000,0,,0,
1524051121.324,,0.000000e+000,3.499911e+001,1.028883e-009,0.000000e+000,3,0.000000e+000,0.000000e+000,,,,,,,,,,,,,,32,1,4.000000e+000,2.338409e-003,0.000000e+000,0,,0,
1524051159.187,,0.000000e+000,3.500028e+001,2.089910e-008,0.000000e+000,3,0.000000e+000,0.000000e+000,,,,,,,,,,,,,,32,1,4.000000e+000,1.560211e-003,0.000000e+000,0,,0,
1524051197.248,,0.000000e+000,3.499989e+001,1.038424e-007,0.000000e+000,3,0.000000e+000,0.000000e+000,,,,,,,,,,,,,,32,1,4.000000e+000,7.781982e-004,0.000000e+000,0,,0,
1524051235.853,,0.000000e+000,3.500028e+001,5.574620e-009,0.000000e+000,3,0.000000e+000,0.000000e+000,,,,,,,,,,,,,,32,1,4.000000e+000,1.560211e-003,0.000000e+000,0,,0,
1524051273.951,,0.000000e+000,3.499872e+001,3.301099e-008,0.000000e+000,3,0.000000e+000,0.000000e+000,,,,,,,,,,,,,,32,1,4.000000e+000,0.000000e+000,0.000000e+000,0,,0,
1524051311.944,,0.000000e+000,3.499989e+001,1.070063e-008,0.000000e+000,3,0.000000e+000,0.000000e+000,,,,,,,,,,,,,,32,1,4.000000e+000,7.781982e-004,0.000000e+000,0,,0,
1524051350.030,,0.000000e+000,3.499872e+001,3.070096e-008,0.000000e+000,3,0.000000e+000,0.000000e+000,,,,,,,,,,,,,,32,1,4.000000e+000,1.560211e-003,0.000000e+000,0,,0,
1524051388.338,,0.000000e+000,3.499989e+001,8.685738e-008,0.000000e+000,3,0.000000e+000,0.000000e+000,,,,,,,,,,,,,,32,1,4.000000e+000,7.781982e-004,0.000000e+000,0,,0,
1524051431.903,,0.000000e+000,3.499911e+001,1.407277e-007,0.000000e+000,2,0.000000e+000,0.000000e+000,,,,,,,,,,,,,,32,1,4.000000e+000,7.820129e-004,0.000000e+000,0,,0,
1524051468.749,,0.000000e+000,3.499833e+001,2.996489e-008,0.000000e+000,3,0.000000e+000,0.000000e+000,,,,,,,,,,,,,,32,1,4.000000e+000,7.781982e-004,0.000000e+000,0,,0,
1524051508.300,,0.000000e+000,3.500263e+001,6.614560e-008,0.000000e+000,3,0.000000e+000,0.000000e+000,,,,,,,,,,,,,,32,1,4.000000e+000,0.000000e+000,0.000000e+000,0,,0,
1524051545.670,,0.000000e+000,3.499989e+001,1.162611e-007,0.000000e+000,3,0.000000e+000,0.000000e+000,,,,,,,,,,,,,,32,1,4.000000e+000,7.781982e-004,0.000000e+000,0,,0,
1524051583.723,,0.000000e+000,3.499989e+001,6.088871e-008,0.000000e+000,3,0.000000e+000,0.000000e+000,,,,,,,,,,,,,,32,1,4.000000e+000,7.781982e-004,0.000000e+000,0,,0,
1524051621.774,,0.000000e+000,3.499950e+001,1.224045e-007,0.000000e+000,3,0.000000e+000,0.000000e+000,,,,,,,,,,,,,,32,1,4.000000e+000,1.560211e-003,0.000000e+000,0,,0,
1524051661.332,,0.000000e+000,3.499989e+001,1.024390e-007,0.000000e+000,2,0.000000e+000,0.000000e+000,,,,,,,,,,,,,,32,1,4.000000e+000,7.781982e-004,0.000000e+000,0,,0,
1524051700.144,,0.000000e+000,3.499833e+001,-5.555061e-007,0.000000e+000,3,0.000000e+000,0.000000e+000,,,,,,,,,,,,,,32,1,4.000000e+000,2.349854e-003,0.000000e+000,0,,0,
1524051742.125,,0.000000e+000,3.499833e+001,1.481555e-007,0.000000e+000,2,0.000000e+000,0.000000e+000,,,,,,,,,,,,,,32,1,4.000000e+000,7.781982e-004,0.000000e+000,0,,0,
1524051780.696,,0.000000e+000,3.499911e+001,-3.056715e-007,0.000000e+000,3,0.000000e+000,0.000000e+000,,,,,,,,,,,,,,32,1,4.000000e+000,7.820129e-004,0.000000e+000,0,,0,
1524051818.549,,0.000000e+000,3.500224e+001,6.038445e-007,0.000000e+000,3,0.000000e+000,0.000000e+000,,,,,,,,,,,,,,32,1,4.000000e+000,3.910065e-003,0.000000e+000,0,,0,
1524051860.531,,0.000000e+000,3.499793e+001,1.940500e-007,0.000000e+000,2,0.000000e+000,0.000000e+000,,,,,,,,,,,,,,32,1,4.000000e+000,3.131866e-003,0.000000e+000,0,,0,
1524051903.358,,0.000000e+000,3.500028e+001,1.906040e-007,0.000000e+000,2,0.000000e+000,0.000000e+000,,,,,,,,,,,,,,32,1,4.000000e+000,3.120422e-003,0.000000e+000,0,,0,
1524051941.009,,0.000000e+000,3.499950e+001,4.175335e-008,0.000000e+000,3,0.000000e+000,0.000000e+000,,,,,,,,,,,,,,32,1,4.000000e+000,0.000000e+000,0.000000e+000,0,,0,
1524051981.490,,0.000000e+000,3.499911e+001,7.035796e-008,0.000000e+000,3,0.000000e+000,0.000000e+000,,,,,,,,,,,,,,32,1,4.000000e+000,7.820129e-004,0.000000e+000,0,,0,
1524052021.066,,0.000000e+000,3.499950e+001,6.605337e-007,0.000000e+000,3,0.000000e+000,0.000000e+000,,,,,,,,,,,,,,32,1,4.000000e+000,0.000000e+000,0.000000e+000,0,,0,
1524052060.427,,0.000000e+000,3.499833e+001,1.981400e-007,0.000000e+000,2,0.000000e+000,0.000000e+000,,,,,,,,,,,,,,32,1,4.000000e+000,2.349854e-003,0.000000e+000,0,,0,
1524052099.808,,0.000000e+000,3.499911e+001,1.612965e-007,0.000000e+000,2,0.000000e+000,0.000000e+000,,,,,,,,,,,,,,32,1,4.000000e+000,7.820129e-004,0.000000e+000,0,,0,
1524052141.445,,0.000000e+000,3.500145e+001,2.428314e-007,0.000000e+000,2,0.000000e+000,0.000000e+000,,,,,,,,,,,,,,32,1,4.000000e+000,7.781982e-004,0.000000e+000,0,,0,
1524052183.034,,0.000000e+000,3.500067e+001,1.959361e-007,0.000000e+000,2,0.000000e+000,0.000000e+000,,,,,,,,,,,,,,32,1,4.000000e+000,3.910065e-003,0.000000e+000,0,,0,
1524052224.526,,0.000000e+000,3.500028e+001,2.815950e-007,0.000000e+000,2,0.000000e+000,0.000000e+000,,,,,,,,,,,,,,32,1,4.000000e+000,3.120422e-003,0.000000e+000,0,,0,
1524052263.564,,0.000000e+000,3.500028e+001,8.046636e-007,0.000000e+000,3,0.000000e+000,0.000000e+000,,,,,,,,,,,,,,32,1,4.000000e+000,1.560211e-003,0.000000e+000,0,,0,
1524052306.131,,0.000000e+000,3.499872e+001,2.761864e-007,0.000000e+000,2,0.000000e+000,0.000000e+000,,,,,,,,,,,,,,32,1,4.000000e+000,1.560211e-003,0.000000e+000,0,,0,
1524052347.878,,0.000000e+000,3.499911e+001,2.743821e-007,0.000000e+000,2,0.000000e+000,0.000000e+000,,,,,,,,,,,,,,32,1,4.000000e+000,7.820129e-004,0.000000e+000,0,,0,
1524052391.618,,0.000000e+000,3.499911e+001,2.779634e-007,0.000000e+000,2,0.000000e+000,0.000000e+000,,,,,,,,,,,,,,32,1,4.000000e+000,7.820129e-004,0.000000e+000,0,,0,
1524052435.315,,0.000000e+000,3.499950e+001,2.916531e-007,0.000000e+000,2,0.000000e+000,0.000000e+000,,,,,,,,,,,,,,32,1,4.000000e+000,0.000000e+000,0.000000e+000,0,,0,
1524052476.109,,0.000000e+000,3.499950e+001,2.668669e-007,0.000000e+000,2,0.000000e+000,0.000000e+000,,,,,,,,,,,,,,32,1,4.000000e+000,0.000000e+000,0.000000e+000,0,,0,
1524052517.091,,0.000000e+000,3.499911e+001,2.747476e-007,0.000000e+000,2,0.000000e+000,0.000000e+000,,,,,,,,,,,,,,32,1,4.000000e+000,7.820129e-004,0.000000e+000,0,,0,
1524052560.068,,0.000000e+000,3.499911e+001,2.877992e-007,0.000000e+000,2,0.000000e+000,0.000000e+000,,,,,,,,,,,,,,32,1,4.000000e+000,2.338409e-003,0.000000e+000,0,,0,
1524052599.569,,0.000000e+000,3.499911e+001,-2.553843e-007,0.000000e+000,3,0.000000e+000,0.000000e+000,,,,,,,,,,,,,,32,1,4.000000e+000,7.820129e-004,0.000000e+000,0,,0,
1524052641.015,,0.000000e+000,3.499833e+001,1.857598e-007,0.000000e+000,2,0.000000e+000,0.000000e+000,,,,,,,,,,,,,,32,1,4.000000e+000,7.781982e-004,0.000000e+000,0,,0,
1524052679.989,,0.000000e+000,3.499911e+001,7.321361e-007,0.000000e+000,3,0.000000e+000,0.000000e+000,,,,,,,,,,,,,,32,1,4.000000e+000,7.820129e-004,0.000000e+000,0,,0,
1524052720.037,,0.000000e+000,3.499911e+001,5.611435e-007,0.000000e+000,3,0.000000e+000,0.000000e+000,,,,,,,,,,,,,,32,1,4.000000e+000,7.820129e-004,0.000000e+000,0,,0,
1524052762.808,,0.000000e+000,3.499989e+001,2.633324e-007,0.000000e+000,2,0.000000e+000,0.000000e+000,,,,,,,,,,,,,,32,1,4.000000e+000,2.342224e-003,0.000000e+000,0,,0,
1524052801.824,,0.000000e+000,3.499911e+001,-2.298521e-007,0.000000e+000,3,0.000000e+000,0.000000e+000,,,,,,,,,,,,,,32,1,4.000000e+000,7.820129e-004,0.000000e+000,0,,0,
1524052842.633,,0.000000e+000,3.499950e+001,2.639114e-007,0.000000e+000,2,0.000000e+000,0.000000e+000,,,,,,,,,,,,,,32,1,4.000000e+000,0.000000e+000,0.000000e+000,0,,0,
1524052881.692,,0.000000e+000,3.500106e+001,-2.265445e-007,0.000000e+000,3,0.000000e+000,0.000000e+000,,,,,,,,,,,,,,32,1,4.000000e+000,1.560211e-003,0.000000e+000,0,,0,
1524052924.023,,0.000000e+000,3.499989e+001,3.575119e-007,0.000000e+000,2,0.000000e+000,0.000000e+000,,,,,,,,,,,,,,32,1,4.000000e+000,7.781982e-004,0.000000e+000,0,,0,
1524052964.034,,0.000000e+000,3.499911e+001,2.753630e-007,0.000000e+000,2,0.000000e+000,0.000000e+000,,,,,,,,,,,,,,32,1,4.000000e+000,7.820129e-004,0.000000e+000,0,,0,
1524053002.418,,0.000000e+000,3.499989e+001,-2.913288e-007,0.000000e+000,3,0.000000e+000,0.000000e+000,,,,,,,,,,,,,,32,1,4.000000e+000,7.781982e-004,0.000000e+000,0,,0,
1524053042.267,,0.000000e+000,3.499950e+001,2.783362e-007,0.000000e+000,2,0.000000e+000,0.000000e+000,,,,,,,,,,,,,,32,1,4.000000e+000,0.000000e+000,0.000000e+000,0,,0,
1524053079.537,,0.000000e+000,3.499950e+001,-2.481801e-007,0.000000e+000,3,0.000000e+000,0.000000e+000,,,,,,,,,,,,,,32,1,4.000000e+000,0.000000e+000,0.000000e+000,0,,0,
1524053119.878,,0.000000e+000,3.499715e+001,2.323713e-007,0.000000e+000,2,0.000000e+000,0.000000e+000,,,,,,,,,,,,,,32,1,4.000000e+000,4.692078e-003,0.000000e+000,0,,0,
1524053160.720,,0.000000e+000,3.499950e+001,2.666982e-007,0.000000e+000,2,0.000000e+000,0.000000e+000,,,,,,,,,,,,,,32,1,4.000000e+000,1.560211e-003,0.000000e+000,0,,0,
1524053200.411,,0.000000e+000,3.500028e+001,-3.542317e-007,0.000000e+000,3,0.000000e+000,0.000000e+000,,,,,,,,,,,,,,32,1,4.000000e+000,1.560211e-003,0.000000e+000,0,,0,
1524053238.429,,0.000000e+000,3.499833e+001,-2.058883e-007,0.000000e+000,3,0.000000e+000,0.000000e+000,,,,,,,,,,,,,,32,1,4.000000e+000,7.781982e-004,0.000000e+000,0,,0,
1524053278.520,,0.000000e+000,3.499872e+001,2.931297e-007,0.000000e+000,2,0.000000e+000,0.000000e+000,,,,,,,,,,,,,,32,1,4.000000e+000,0.000000e+000,0.000000e+000,0,,0,
1524053322.056,,0.000000e+000,3.499950e+001,3.722829e-007,0.000000e+000,2,0.000000e+000,0.000000e+000,,,,,,,,,,,,,,32,1,4.000000e+000,0.000000e+000,0.000000e+000,0,,0,
1524053363.331,,0.000000e+000,3.500067e+001,3.696377e-007,0.000000e+000,2,0.000000e+000,0.000000e+000,,,,,,,,,,,,,,32,1,4.000000e+000,2.338409e-003,0.000000e+000,0,,0,
1524053401.222,,0.000000e+000,3.499989e+001,-2.784805e-007,0.000000e+000,3,0.000000e+000,0.000000e+000,,,,,,,,,,,,,,32,1,4.000000e+000,7.781982e-004,0.000000e+000,0,,0,
1524053438.775,,0.000000e+000,3.499989e+001,-2.650427e-007,0.000000e+000,3,0.000000e+000,0.000000e+000,,,,,,,,,,,,,,32,1,4.000000e+000,7.781982e-004,0.000000e+000,0,,0,
1524053476.863,,0.000000e+000,3.499872e+001,-2.356391e-007,0.000000e+000,3,0.000000e+000,0.000000e+000,,,,,,,,,,,,,,32,1,4.000000e+000,0.000000e+000,0.000000e+000,0,,0,
1524053518.209,,0.000000e+000,3.499911e+001,3.627841e-007,0.000000e+000,2,0.000000e+000,0.000000e+000,,,,,,,,,,,,,,32,1,4.000000e+000,7.820129e-004,0.000000e+000,0,,0,
1524053561.346,,0.000000e+000,3.500106e+001,4.042355e-007,0.000000e+000,2,0.000000e+000,0.000000e+000,,,,,,,,,,,,,,32,1,4.000000e+000,1.560211e-003,0.000000e+000,0,,0,
1524053602.309,,0.000000e+000,3.499989e+001,-2.860980e-007,0.000000e+000,3,0.000000e+000,0.000000e+000,,,,,,,,,,,,,,32,1,4.000000e+000,2.342224e-003,0.000000e+000,0,,0,
1524053642.221,,0.000000e+000,3.499872e+001,3.699959e-007,0.000000e+000,2,0.000000e+000,0.000000e+000,,,,,,,,,,,,,,32,1,4.000000e+000,1.560211e-003,0.000000e+000,0,,0,
1524053680.056,,0.000000e+000,3.499950e+001,-3.097012e-007,0.000000e+000,3,0.000000e+000,0.000000e+000,,,,,,,,,,,,,,32,1,4.000000e+000,0.000000e+000,0.000000e+000,0,,0,
1524053720.405,,0.000000e+000,3.499950e+001,3.560281e-007,0.000000e+000,2,0.000000e+000,0.000000e+000,,,,,,,,,,,,,,32,1,4.000000e+000,1.560211e-003,0.000000e+000,0,,0,
1524053762.573,,0.000000e+000,3.500028e+001,4.305869e-007,0.000000e+000,2,0.000000e+000,0.000000e+000,,,,,,,,,,,,,,32,1,4.000000e+000,3.120422e-003,0.000000e+000,0,,0,
1524053804.645,,0.000000e+000,3.499911e+001,3.901285e-007,0.000000e+000,2,0.000000e+000,0.000000e+000,,,,,,,,,,,,,,32,1,4.000000e+000,7.820129e-004,0.000000e+000,0,,0,
1524053846.593,,0.000000e+000,3.499989e+001,4.252108e-007,0.000000e+000,2,0.000000e+000,0.000000e+000,,,,,,,,,,,,,,32,1,4.000000e+000,2.342224e-003,0.000000e+000,0,,0,
1524053888.780,,0.000000e+000,3.499911e+001,3.893147e-007,0.000000e+000,2,0.000000e+000,0.000000e+000,,,,,,,,,,,,,,32,1,4.000000e+000,7.820129e-004,0.000000e+000,0,,0,
1524053930.287,,0.000000e+000,3.499950e+001,4.265960e-007,0.000000e+000,2,0.000000e+000,0.000000e+000,,,,,,,,,,,,,,32,1,4.000000e+000,0.000000e+000,0.000000e+000,0,,0,
1524053972.659,,0.000000e+000,3.499989e+001,4.297674e-007,0.000000e+000,2,0.000000e+000,0.000000e+000,,,,,,,,,,,,,,32,1,4.000000e+000,7.781982e-004,0.000000e+000,0,,0,
1524054014.824,,0.000000e+000,3.499911e+001,3.784608e-007,0.000000e+000,2,0.000000e+000,0.000000e+000,,,,,,,,,,,,,,32,1,4.000000e+000,7.820129e-004,0.000000e+000,0,,0,
1524054057.105,,0.000000e+000,3.499950e+001,4.120668e-007,0.000000e+000,2,0.000000e+000,0.000000e+000,,,,,,,,,,,,,,32,1,4.000000e+000,1.560211e-003,0.000000e+000,0,,0,
1524054098.115,,0.000000e+000,3.500224e+001,4.232467e-007,0.000000e+000,2,0.000000e+000,0.000000e+000,,,,,,,,,,,,,,32,1,4.000000e+000,5.477905e-003,0.000000e+000,0,,0,
1524054139.797,,0.000000e+000,3.499989e+001,4.569394e-007,0.000000e+000,2,0.000000e+000,0.000000e+000,,,,,,,,,,,,,,32,1,4.000000e+000,2.342224e-003,0.000000e+000,0,,0,
1524054182.665,,0.000000e+000,3.500106e+001,4.434515e-007,0.000000e+000,2,0.000000e+000,0.000000e+000,,,,,,,,,,,,,,32,1,4.000000e+000,4.692078e-003,0.000000e+000,0,,0,
1524054223.634,,0.000000e+000,3.499950e+001,4.469708e-007,0.000000e+000,2,0.000000e+000,0.000000e+000,,,,,,,,,,,,,,32,1,4.000000e+000,1.560211e-003,0.000000e+000,0,,0,
1524054266.452,,0.000000e+000,3.499950e+001,4.291722e-007,0.000000e+000,2,0.000000e+000,0.000000e+000,,,,,,,,,,,,,,32,1,4.000000e+000,1.560211e-003,0.000000e+000,0,,0,
1524054308.749,,0.000000e+000,3.500028e+001,4.595488e-007,0.000000e+000,2,0.000000e+000,0.000000e+000,,,,,,,,,,,,,,32,1,4.000000e+000,1.560211e-003,0.000000e+000,0,,0,