File: Input_All/MFn1_VRMac_34K_3000s_VRMde_35K.dc.dat
[Header]
TITLE,MPMS DC Measurement
BYAPP,MPMS Measurement,2.1,Summary
FILEOPENTIME, 1524282205.215000 4/20/2018, 9:43:25 PM

INFO, APPNAME, MPMS MultiVu Application, Revision 1.61,  Build 082

INFO, NAME, MFn1
INFO, WEIGHT, 1.000
INFO, AREA, 1.000
INFO, LENGTH, 1.000
INFO, SHAPE, 0
INFO, COMMENT,
INFO, SEQUENCE FILE: VRMac_34K_3000s_VRMde_35K.seq


INFO, BACKGROUND DATA FILE:, None


STARTUPAXIS,X,4,LINEAR,AUTO,0.000000,0.000000
STARTUPAXIS,Y1,5,LINEAR,AUTO,0.000000,0.000000


STARTUPGROUP,Longitudinal
FIELDGROUP,Longitudinal,1,2,3,4,5,6,7,8,9,15,16,17,18,27,28
FIELDGROUP,Transverse,1,2,3,4,10,11,12,13,14,19,20,21,22,27,28

PLOT_APPEARANCE,ALL,HORZ_GRID_ON,VERT_GRID_ON,MARKERS_AND_LINES

[Data]
Time,Comment,Field (Oe),Temperature (K),Long Moment (emu),Long Scan Std Dev,Long Algorithm,Long Reg Fit,Long Percent Error (%),Trans Moment (emu),Trans Scan Std Dev,Trans Algorithm,Trans Reg Fit,Trans Percent Error (%),Long Moment [w/o ABS] (emu),Long Scan Std Dev [w/o ABS],Long Reg Fit [w/o ABS],Long Percent Error [w/o ABS] (%),Trans Moment [w/o ABS] (emu),Trans Scan Std Dev [w/o ABS],Trans Reg Fit [w/o ABS],Trans Percent Error [w/o ABS] (%),Points per Scan,Scans per Measurement,Scan Length (cm),Delta Temp (K),Rot Position (deg),Error,EC Comp. Running,Using ABS,
1524282205.195,,0.000000e+000,3.500262e+001,-5.371670e-006,0.000000e+000,2,8.473671e-001,0.000000e+000,,,,,,,,,,,,,,32,1,4.000000e+000,3.128052e-003,0.000000e+000,0,,0,
1524282243.556,,0.000000e+000,3.500263e+001,-4.197749e-006,0.000000e+000,2,8.062699e-001,0.000000e+000,,,,,,,,,,,,,,32,1,4.000000e+000,4.699707e-003,0.000000e+000,0,,0,
1524282281.634,,0.000000e+000,3.500067e+001,-3.147609e-006,0.000000e+000,2,7.370765e-001,0.000000e+000,,,,,,,,,,,,,,32,1,4.000000e+000,2.338409e-003,0.000000e+000,0,,0,
1524282319.712,,0.000000e+000,3.499754e+001,-2.306263e-006,0.000000e+000,2,6.394502e-001,0.000000e+000,,,,,,,,,,,,,,32,1,4.000000e+000,3.910065e-003,0.000000e+000,0,,0,
1524282357.722,,0.000000e+000,3.499989e+001,-1.656582e-006,0.000000e+000,2,5.086913e-001,0.000000e+000,,,,,,,,,,,,,,32,1,4.000000e+000,7.781982e-004,0.000000e+000,0,,0,
1524282395.803,,0.000000e+000,3.499911e+001,-1.097910e-006,0.000000e+000,2,2.400925e-001,0.000000e+000,,,,,,,,,,,,,,32,1,4.000000e+000,7.820129e-004,0.000000e+000,0,,0,
1524282433.863,,0.000000e+000,3.499950e+001,-6.736330e-007,0.000000e+000,2,0.000000e+000,0.000000e+000,,,,,,,,,,,,,,32,1,4.000000e+000,1.560211e-003,0.000000e+000,0,,0,
1524282471.939,,0.000000e+000,3.499950e+001,-2.451938e-007,0.000000e+000,2,0.000000e+000,0.000000e+000,,,,,,,,,,,,,,32,1,4.000000e+000,1.560211e-003,0.000000e+000,0,,0,
1524282510.012,,0.000000e+000,3.499911e+001,1.582005e-007,0.000000e+000,2,0.000000e+000,0.000000e+000,,,,,,,,,,,,,,32,1,4.000000e+000,7.820129e-004,0.000000e+000,0,,0,
1524282548.092,,0.000000e+000,3.499911e+001,4.985565e-007,0.000000e+000,2,0.000000e+000,0.000000e+000,,,,,,,,,,,,,,32,1,4.000000e+000,7.820129e-004,0.000000e+000,0,,0,
1524282586.185,,0.000000e+000,3.499950e+001,7.846197e-007,0.000000e+000,2,0.000000e+000,0.000000e+000,,,,,,,,,,,,,,32,1,4.000000e+000,0.000000e+000,0.000000e+000,0,,0,
1524282624.254,,0.000000e+000,3.499950e+001,1.050207e-006,0.000000e+000,2,1.853169e-001,0.000000e+000,,,,,,,,,,,,,,32,1,4.000000e+000,0.000000e+000,0.000000e+000,0,,0,
1524282662.322,,0.000000e+000,3.499872e+001,1.255833e-006,0.000000e+000,2,3.268598e-001,0.000000e+000,,,,,,,,,,,,,,32,1,4.000000e+000,0.000000e+000,0.000000e+000,0,,0,
1524282700.415,,0.000000e+000,3.499911e+001,1.484875e-006,0.000000e+000,2,4.420797e-001,0.000000e+000,,,,,,,,,,,,,,32,1,4.000000e+000,7.820129e-004,0.000000e+000,0,,0,
1524282738.495,,0.000000e+000,3.499950e+001,1.725684e-006,0.000000e+000,2,5.151184e-001,0.000000e+000,,,,,,,,,,,,,,32,1,4.000000e+000,1.560211e-003,0.000000e+000,0,,0,
1524282776.586,,0.000000e+000,3.499989e+001,1.905494e-006,0.000000e+000,2,5.433699e-001,0.000000e+000,,,,,,,,,,,,,,32,1,4.000000e+000,7.781982e-004,0.000000e+000,0,,0,
1524282814.531,,0.000000e+000,3.499950e+001,2.121866e-006,0.000000e+000,2,6.042004e-001,0.000000e+000,,,,,,,,,,,,,,32,1,4.000000e+000,0.000000e+000,0.000000e+000,0,,0,
1524282853.267,,0.000000e+000,3.499911e+001,2.223920e-006,0.000000e+000,2,6.177879e-001,0.000000e+000,,,,,,,,,,,,,,32,1,4.000000e+000,7.820129e-004,0.000000e+000,0,,0,
1524282891.088,,0.000000e+000,3.499833e+001,2.427417e-006,0.000000e+000,2,6.530208e-001,0.000000e+000,,,,,,,,,,,,,,32,1,4.000000e+000,7.781982e-004,0.000000e+000,0,,0,
1524282929.016,,0.000000e+000,3.500067e+001,2.595330e-006,0.000000e+000,2,6.734404e-001,0.000000e+000,,,,,,,,,,,,,,32,1,4.000000e+000,7.820129e-004,0.000000e+000,0,,0,
1524282966.864,,0.000000e+000,3.499872e+001,2.701575e-006,0.000000e+000,2,6.901692e-001,0.000000e+000,,,,,,,,,,,,,,32,1,4.000000e+000,0.000000e+000,0.000000e+000,0,,0,
1524283004.499,,0.000000e+000,3.499911e+001,2.810203e-006,0.000000e+000,2,6.988487e-001,0.000000e+000,,,,,,,,,,,,,,32,1,4.000000e+000,7.820129e-004,0.000000e+000,0,,0,
1524283043.012,,0.000000e+000,3.499911e+001,2.926152e-006,0.000000e+000,2,7.166096e-001,0.000000e+000,,,,,,,,,,,,,,32,1,4.000000e+000,7.820129e-004,0.000000e+000,0,,0,
1524283080.628,,0.000000e+000,3.499715e+001,2.998158e-006,0.000000e+000,2,7.131490e-001,0.000000e+000,,,,,,,,,,,,,,32,1,4.000000e+000,0.000000e+000,0.000000e+000,0,,0,
1524283118.951,,0.000000e+000,3.499911e+001,3.172342e-006,0.000000e+000,2,7.317984e-001,0.000000e+000,,,,,,,,,,,,,,32,1,4.000000e+000,7.820129e-004,0.000000e+000,0,,0,
1524283156.144,,0.000000e+000,3.499872e+001,3.245276e-006,0.000000e+000,2,7.428387e-001,0.000000e+000,,,,,,,,,,,,,,32,1,4.000000e+000,1.560211e-003,0.000000e+000,0,,0,
1524283195.159,,0.000000e+000,3.499911e+001,3.343652e-006,0.000000e+000,2,7.421727e-001,0.000000e+000,,,,,,,,,,,,,,32,1,4.000000e+000,7.820129e-004,0.000000e+000,0,,0,
1524283233.105,,0.000000e+000,3.499989e+001,3.430154e-006,0.000000e+000,2,7.537417e-001,0.000000e+000,,,,,,,,,,,,,,32,1,4.000000e+000,7.781982e-004,0.000000e+000,0,,0,
1524283271.118,,0.000000e+000,3.499950e+001,3.541455e-006,0.000000e+000,2,7.573328e-001,0.000000e+000,,,,,,,,,,,,,,32,1,4.000000e+000,0.000000e+000,0.000000e+000,0,,0,
1524283309.229,,0.000000e+000,3.499872e+001,3.633784e-006,0.000000e+000,2,7.647876e-001,0.000000e+000,,,,,,,,,,,,,,32,1,4.000000e+000,0.000000e+000,0.000000e+000,0,,0,
1524283347.409,,0.000000e+000,3.499950e+001,3.665461e-006,0.000000e+000,2,7.672306e-001,0.000000e+000,,,,,,,,,,,,,,32,1,4.000000e+000,0.000000e+000,0.000000e+000,0,,0,
1524283385.497,,0.000000e+000,3.499950e+001,3.743935e-006,0.000000e+000,2,7.675856e-001,0.000000e+000,,,,,,,,,,,,,,32,1,4.000000e+000,1.560211e-003,0.000000e+000,0,,0,
1524283423.573,,0.000000e+000,3.499950e+001,3.846831e-006,0.000000e+000,2,7.735082e-001,0.000000e+000,,,,,,,,,,,,,,32,1,4.000000e+000,0.000000e+000,0.000000e+000,0,,0,
1524283461.608,,0.000000e+000,3.499872e+001,3.894703e-006,0.000000e+000,2,7.774944e-001,0.000000e+000,,,,,,,,,,,,,,32,1,4.000000e+000,0.000000e+000,0.000000e+000,0,,0,
1524283499.409,,0.000000e+000,3.500028e+001,3.947588e-006,0.000000e+000,2,7.821388e-001,0.000000e+000,,,,,,,,,,,,,,32,1,4.000000e+000,1.560211e-003,0.000000e+000,0,,0,
1524283537.237,,0.000000e+000,3.499911e+001,4.017650e-006,0.000000e+000,2,7.835495e-001,0.000000e+000,,,,,,,,,,,,,,32,1,4.000000e+000,7.820129e-004,0.000000e+000,0,,0,
1524283575.365,,0.000000e+000,3.499911e+001,4.087855e-006,0.000000e+000,2,7.851340e-001,0.000000e+000,,,,,,,,,,,,,,32,1,4.000000e+000,7.820129e-004,0.000000e+000,0,,0,
1524283613.378,,0.000000e+000,3.499872e+001,4.155204e-006,0.000000e+000,2,7.886366e-001,0.000000e+000,,,,,,,,,,,,,,32,1,4.000000e+000,0.000000e+000,0.000000e+000,0,,0,
1524283651.436,,0.000000e+000,3.499989e+001,4.215543e-006,0.000000e+000,2,7.969861e-001,0.000000e+000,,,,,,,,,,,,,,32,1,4.000000e+000,7.781982e-004,0.000000e+000,0,,0,
1524283690.242,,0.000000e+000,3.499989e+001,4.232569e-006,0.000000e+000,2,7.937872e-001,0.000000e+000,,,,,,,,,,,,,,32,1,4.000000e+000,3.898621e-003,0.000000e+000,0,,0,
1524283728.725,,0.000000e+000,3.499989e+001,4.323653e-006,0.000000e+000,2,7.995073e-001,0.000000e+000,,,,,,,,,,,,,,32,1,4.000000e+000,7.781982e-004,0.000000e+000,0,,0,
1524283766.365,,0.000000e+000,3.499872e+001,4.314225e-006,0.000000e+000,2,7.977714e-001,0.000000e+000,,,,,,,,,,,,,,32,1,4.000000e+000,0.000000e+000,0.000000e+000,0,,0,
1524283804.293,,0.000000e+000,3.499911e+001,4.463397e-006,0.000000e+000,2,7.972767e-001,0.000000e+000,,,,,,,,,,,,,,32,1,4.000000e+000,7.820129e-004,0.000000e+000,0,,0,
1524283842.231,,0.000000e+000,3.499911e+001,4.431713e-006,0.000000e+000,2,8.035793e-001,0.000000e+000,,,,,,,,,,,,,,32,1,4.000000e+000,7.820129e-004,0.000000e+000,0,,0,
1524283879.807,,0.000000e+000,3.499871e+001,4.506826e-006,0.000000e+000,2,8.030978e-001,0.000000e+000,,,,,,,,,,,,,,32,1,4.000000e+000,3.128052e-003,0.000000e+000,0,,0,
1524283917.660,,0.000000e+000,3.499833e+001,4.576259e-006,0.000000e+000,2,8.122886e-001,0.000000e+000,,,,,,,,,,,,,,32,1,4.000000e+000,7.781982e-004,0.000000e+000,0,,0,
1524283955.693,,0.000000e+000,3.499872e+001,4.577723e-006,0.000000e+000,2,8.040941e-001,0.000000e+000,,,,,,,,,,,,,,32,1,4.000000e+000,1.560211e-003,0.000000e+000,0,,0,
1524283993.686,,0.000000e+000,3.499833e+001,4.656123e-006,0.000000e+000,2,8.072463e-001,0.000000e+000,,,,,,,,,,,,,,32,1,4.000000e+000,2.349854e-003,0.000000e+000,0,,0,
1524284031.729,,0.000000e+000,3.499950e+001,4.710602e-006,0.000000e+000,2,8.111562e-001,0.000000e+000,,,,,,,,,,,,,,32,1,4.000000e+000,0.000000e+000,0.000000e+000,0,,0,
1524284069.755,,0.000000e+000,3.499950e+001,4.694854e-006,0.000000e+000,2,8.105690e-001,0.000000e+000,,,,,,,,,,,,,,32,1,4.000000e+000,1.560211e-003,0.000000e+000,0,,0,
1524284107.860,,0.000000e+000,3.499833e+001,4.750510e-006,0.000000e+000,2,8.165364e-001,0.000000e+000,,,,,,,,,,,,,,32,1,4.000000e+000,7.781982e-004,0.000000e+000,0,,0,
1524284146.001,,0.000000e+000,3.499872e+001,4.791303e-006,0.000000e+000,2,8.157855e-001,0.000000e+000,,,,,,,,,,,,,,32,1,4.000000e+000,0.000000e+000,0.000000e+000,0,,0,
1524284183.482,,0.000000e+000,3.499911e+001,4.811114e-006,0.000000e+000,2,8.126408e-001,0.000000e+000,,,,,,,,,,,,,,32,1,4.000000e+000,7.820129e-004,0.000000e+000,0,,0,
1524284221.545,,0.000000e+000,3.499872e+001,4.818421e-006,0.000000e+000,2,8.293374e-001,0.000000e+000,,,,,,,,,,,,,,32,1,4.000000e+000,0.000000e+000,0.000000e+000,0,,0,
1524284259.578,,0.000000e+000,3.499911e+001,4.878741e-006,0.000000e+000,2,8.209959e-001,0.000000e+000,,,,,,,,,,,,,,32,1,4.000000e+000,7.820129e-004,0.000000e+000,0,,0,
1524284298.886,,0.000000e+000,3.499715e+001,4.903901e-006,0.000000e+000,2,8.227599e-001,0.000000e+000,,,,,,,,,,,,,,32,1,4.000000e+000,1.571655e-003,0.000000e+000,0,,0,
1524284336.034,,0.000000e+000,3.499950e+001,4.916621e-006,0.000000e+000,2,8.236265e-001,0.000000e+000,,,,,,,,,,,,,,32,1,4.000000e+000,1.560211e-003,0.000000e+000,0,,0,
1524284374.022,,0.000000e+000,3.499833e+001,4.980206e-006,0.000000e+000,2,8.238807e-001,0.000000e+000,,,,,,,,,,,,,,32,1,4.000000e+000,7.781982e-004,0.000000e+000,0,,0,
1524284412.110,,0.000000e+000,3.499872e+001,4.988157e-006,0.000000e+000,2,8.243148e-001,0.000000e+000,,,,,,,,,,,,,,32,1,4.000000e+000,0.000000e+000,0.000000e+000,0,,0,
1524284450.178,,0.000000e+000,3.499911e+001,5.018397e-006,0.000000e+000,2,8.250682e-001,0.000000e+000,,,,,,,,,,,,,,32,1,4.000000e+000,2.338409e-003,0.000000e+000,0,,0,
1524284488.338,,0.000000e+000,3.499872e+001,5.068907e-006,0.000000e+000,2,8.258335e-001,0.000000e+000,,,,,,,,,,,,,,32,1,4.000000e+000,0.000000e+000,0.000000e+000,0,,0,
1524284526.407,,0.000000e+000,3.499872e+001,5.100363e-006,0.000000e+000,2,8.283354e-001,0.000000e+000,,,,,,,,,,,,,,32,1,4.000000e+000,0.000000e+000,0.000000e+000,0,,0,
1524284564.400,,0.000000e+000,3.499911e+001,5.139200e-006,0.000000e+000,2,8.286587e-001,0.000000e+000,,,,,,,,,,,,,,32,1,4.000000e+000,7.820129e-004,0.000000e+000,0,,0,
1524284602.500,,0.000000e+000,3.499950e+001,5.136503e-006,0.000000e+000,2,8.269945e-001,0.000000e+000,,,,,,,,,,,,,,32,1,4.000000e+000,0.000000e+000,0.000000e+000,0,,0,
1524284640.571,,0.000000e+000,3.499833e+001,5.166066e-006,0.000000e+000,2,8.289463e-001,0.000000e+000,,,,,,,,,,,,,,32,1,4.000000e+000,2.349854e-003,0.000000e+000,0,,0,
1524284678.224,,0.000000e+000,3.499911e+001,5.192856e-006,0.000000e+000,2,8.305038e-001,0.000000e+000,,,,,,,,,,,,,,32,1,4.000000e+000,7.820129e-004,0.000000e+000,0,,0,
1524284716.757,,0.000000e+000,3.499950e+001,5.230422e-006,0.000000e+000,2,8.294249e-001,0.000000e+000,,,,,,,,,,,,,,32,1,4.000000e+000,0.000000e+000,0.000000e+000,0,,0,
1524284754.270,,0.000000e+000,3.499950e+001,5.240680e-006,0.000000e+000,2,8.343450e-001,0.000000e+000,,,,,,,,,,,,,,32,1,4.000000e+000,0.000000e+000,0.000000e+000,0,,0,
1524284791.903,,0.000000e+000,3.499950e+001,5.227931e-006,0.000000e+000,2,8.279971e-001,0.000000e+000,,,,,,,,,,,,,,32,1,4.000000e+000,3.120422e-003,0.000000e+000,0,,0,
1524284829.906,,0.000000e+000,3.499872e+001,5.267117e-006,0.000000e+000,2,8.335125e-001,0.000000e+000,,,,,,,,,,,,,,32,1,4.000000e+000,1.560211e-003,0.000000e+000,0,,0,
1524284867.989,,0.000000e+000,3.499911e+001,5.244710e-006,0.000000e+000,2,8.254379e-001,0.000000e+000,,,,,,,,,,,,,,32,1,4.000000e+000,7.820129e-004,0.000000e+000,0,,0,
1524284906.687,,0.000000e+000,3.500067e+001,5.358338e-006,0.000000e+000,2,8.274951e-001,0.000000e+000,,,,,,,,,,,,,,32,1,4.000000e+000,7.820129e-004,0.000000e+000,0,,0,
1524284945.033,,0.000000e+000,3.499872e+001,5.383446e-006,0.000000e+000,2,8.340315e-001,0.000000e+000,,,,,,,,,,,,,,32,1,4.000000e+000,1.560211e-003,0.000000e+000,0,,0,
1524284982.611,,0.000000e+000,3.499950e+001,5.373780e-006,0.000000e+000,2,8.336650e-001,0.000000e+000,,,,,,,,,,,,,,32,1,4.000000e+000,0.000000e+000,0.000000e+000,0,,0,
1524285020.411,,0.000000e+000,3.499715e+001,5.390274e-006,0.000000e+000,2,8.328124e-001,0.000000e+000,,,,,,,,,,,,,,32,1,4.000000e+000,3.128052e-003,0.000000e+000,0,,0,
1524285058.482,,0.000000e+000,3.500106e+001,5.400528e-006,0.000000e+000,2,8.368893e-001,0.000000e+000,,,,,,,,,,,,,,32,1,4.000000e+000,1.560211e-003,0.000000e+000,0,,0,
1524285096.075,,0.000000e+000,3.499989e+001,5.418412e-006,0.000000e+000,2,8.305474e-001,0.000000e+000,,,,,,,,,,,,,,32,1,4.000000e+000,7.781982e-004,0.000000e+000,0,,0,
1524285134.198,,0.000000e+000,3.499911e+001,5.434133e-006,0.000000e+000,2,8.366050e-001,0.000000e+000,,,,,,,,,,,,,,32,1,4.000000e+000,7.820129e-004,0.000000e+000,0,,0,
1524285172.203,,0.000000e+000,3.499989e+001,5.474880e-006,0.000000e+000,2,8.380023e-001,0.000000e+000,,,,,,,,,,,,,,32,1,4.000000e+000,7.781982e-004,0.000000e+000,0,,0,
1524285210.289,,0.000000e+000,3.499950e+001,5.492424e-006,0.000000e+000,2,8.332465e-001,0.000000e+000,,,,,,,,,,,,,,32,1,4.000000e+000,3.120422e-003,0.000000e+000,0,,0,
1524285248.387,,0.000000e+000,3.499950e+001,5.515515e-006,0.000000e+000,2,8.335892e-001,0.000000e+000,,,,,,,,,,,,,,32,1,4.000000e+000,1.560211e-003,0.000000e+000,0,,0,
1524285286.428,,0.000000e+000,3.499911e+001,5.532199e-006,0.000000e+000,2,8.384717e-001,0.000000e+000,,,,,,,,,,,,,,32,1,4.000000e+000,2.338409e-003,0.000000e+000,0,,0,
1524285324.526,,0.000000e+000,3.499872e+001,5.541105e-006,0.000000e+000,2,8.379007e-001,0.000000e+000,,,,,,,,,,,,,,32,1,4.000000e+000,1.560211e-003,0.000000e+000,0,,0,
1524285362.361,,0.000000e+000,3.499911e+001,5.561586e-006,0.000000e+000,2,8.409368e-001,0.000000e+000,,,,,,,,,,,,,,32,1,4.000000e+000,7.820129e-004,0.000000e+000,0,,0,
1524285400.202,,0.000000e+000,3.499754e+001,5.579917e-006,0.000000e+000,2,8.371300e-001,0.000000e+000,,,,,,,,,,,,,,32,1,4.000000e+000,2.349854e-003,0.000000e+000,0,,0,
1524285438.200,,0.000000e+000,3.499833e+001,5.586144e-006,0.000000e+000,2,8.384950e-001,0.000000e+000,,,,,,,,,,,,,,32,1,4.000000e+000,7.781982e-004,0.000000e+000,0,,0,
1524285476.275,,0.000000e+000,3.499793e+001,5.572473e-006,0.000000e+000,2,8.380412e-001,0.000000e+000,,,,,,,,,,,,,,32,1,4.000000e+000,3.131866e-003,0.000000e+000,0,,0,
1524285514.129,,0.000000e+000,3.499872e+001,5.646096e-006,0.000000e+000,2,8.385082e-001,0.000000e+000,,,,,,,,,,,,,,32,1,4.000000e+000,0.000000e+000,0.000000e+000,0,,0,
1524285551.927,,0.000000e+000,3.500067e+001,5.659397e-006,0.000000e+000,2,8.409344e-001,0.000000e+000,,,,,,,,,,,,,,32,1,4.000000e+000,7.820129e-004,0.000000e+000,0,,0,
1524285590.600,,0.000000e+000,3.499911e+001,5.668728e-006,0.000000e+000,2,8.367958e-001,0.000000e+000,,,,,,,,,,,,,,32,1,4.000000e+000,7.820129e-004,0.000000e+000,0,,0,
1524285628.715,,0.000000e+000,3.499911e+001,5.674784e-006,0.000000e+000,2,8.390188e-001,0.000000e+000,,,,,,,,,,,,,,32,1,4.000000e+000,7.820129e-004,0.000000e+000,0,,0,
1524285666.763,,0.000000e+000,3.499872e+001,5.665460e-006,0.000000e+000,2,8.363410e-001,0.000000e+000,,,,,,,,,,,,,,32,1,4.000000e+000,0.000000e+000,0.000000e+000,0,,0,
1524285704.836,,0.000000e+000,3.499911e+001,5.721776e-006,0.000000e+000,2,8.393682e-001,0.000000e+000,,,,,,,,,,,,,,32,1,4.000000e+000,7.820129e-004,0.000000e+000,0,,0,
1524285742.504,,0.000000e+000,3.500028e+001,5.692379e-006,0.000000e+000,2,8.388940e-001,0.000000e+000,,,,,,,,,,,,,,32,1,4.000000e+000,1.560211e-003,0.000000e+000,0,,0,
1524285781.025,,0.000000e+000,3.499989e+001,5.741840e-006,0.000000e+000,2,8.390570e-001,0.000000e+000,,,,,,,,,,,,,,32,1,4.000000e+000,5.477905e-003,0.000000e+000,0,,0,
1524285819.378,,0.000000e+000,3.499833e+001,5.729190e-006,0.000000e+000,2,8.406386e-001,0.000000e+000,,,,,,,,,,,,,,32,1,4.000000e+000,7.781982e-004,0.000000e+000,0,,0,
1524285857.556,,0.000000e+000,3.499911e+001,5.716031e-006,0.000000e+000,2,8.473346e-001,0.000000e+000,,,,,,,,,,,,,,32,1,4.000000e+000,7.820129e-004,0.000000e+000,0,,0,
1524285895.514,,0.000000e+000,3.499872e+001,5.744480e-006,0.000000e+000,2,8.459365e-001,0.000000e+000,,,,,,,,,,,,,,32,1,4.000000e+000,0.000000e+000,0.000000e+000,0,,0,
1524285933.410,,0.000000e+000,3.499950e+001,5.800895e-006,0.000000e+000,2,8.440213e-001,0.000000e+000,,,,,,,,,,,,,,32,1,4.000000e+000,0.000000e+000,0.000000e+000,0,,0,
1524285970.998,,0.000000e+000,3.499833e+001,5.799069e-006,0.000000e+000,2,8.442835e-001,0.000000e+000,,,,,,,,,,,,,,32,1,4.000000e+000,7.781982e-004,0.000000e+000,0,,0,
1524286009.038,,0.000000e+000,3.500028e+001,5.816596e-006,0.000000e+000,2,8.417625e-001,0.000000e+000,,,,,,,,,,,,,,32,1,4.000000e+000,3.120422e-003,0.000000e+000,0,,0,
1524286046.389,,0.000000e+000,3.500028e+001,5.837245e-006,0.000000e+000,2,8.442735e-001,0.000000e+000,,,,,,,,,,,,,,32,1,4.000000e+000,0.000000e+000,0.000000e+000,0,,0,
1524286084.809,,0.000000e+000,3.499911e+001,5.790183e-006,0.000000e+000,2,8.440773e-001,0.000000e+000,,,,,,,,,,,,,,32,1,4.000000e+000,7.820129e-004,0.000000e+000,0,,0,
1524286122.352,,0.000000e+000,3.499950e+001,5.791426e-006,0.000000e+000,2,8.458584e-001,0.000000e+000,,,,,,,,,,,,,,32,1,4.000000e+000,0.000000e+000,0.000000e+000,0,,0,
1524286160.498,,0.000000e+000,3.499911e+001,5.850626e-006,0.000000e+000,2,8.433666e-001,0.000000e+000,,,,,,,,,,,,,,32,1,4.000000e+000,7.820129e-004,0.000000e+000,0,,0,
1524286198.514,,0.000000e+000,3.499911e+001,5.836159e-006,0.000000e+000,2,8.459267e-001,0.000000e+000,,,,,,,,,,,,,,32,1,4.000000e+000,7.820129e-004,0.000000e+000,0,,0,
1524286236.579,,0.000000e+000,3.499911e+001,5.850643e-006,0.000000e+000,2,8.457813e-001,0.000000e+000,,,,,,,,,,,,,,32,1,4.000000e+000,2.338409e-003,0.000000e+000,0,,0,
1524286275.137,,0.000000e+000,3.499911e+001,5.877126e-006,0.000000e+000,2,8.466091e-001,0.000000e+000,,,,,,,,,,,,,,32,1,4.000000e+000,7.820129e-004,0.000000e+000,0,,0,
1524286311.658,,0.000000e+000,3.499950e+001,5.874876e-006,0.000000e+000,2,8.484153e-001,0.000000e+000,,,,,,,,,,,,,,32,1,4.000000e+000,0.000000e+000,0.000000e+000,0,,0,
1524286350.181,,0.000000e+000,3.500028e+001,5.916269e-006,0.000000e+000,2,8.469692e-001,0.000000e+000,,,,,,,,,,,,,,32,1,4.000000e+000,1.560211e-003,0.000000e+000,0,,0,
1524286387.656,,0.000000e+000,3.499989e+001,5.887568e-006,0.000000e+000,2,8.471071e-001,0.000000e+000,,,,,,,,,,,,,,32,1,4.000000e+000,7.781982e-004,0.000000e+000,0,,0,
1524286425.712,,0.000000e+000,3.499950e+001,5.889834e-006,0.000000e+000,2,8.428889e-001,0.000000e+000,,,,,,,,,,,,,,32,1,4.000000e+000,1.560211e-003,0.000000e+000,0,,0,
1524286463.800,,0.000000e+000,3.499911e+001,5.905969e-006,0.000000e+000,2,8.472176e-001,0.000000e+000,,,,,,,,,,,,,,32,1,4.000000e+000,7.820129e-004,0.000000e+000,0,,0,
1524286501.843,,0.000000e+000,3.499872e+001,5.927867e-006,0.000000e+000,2,8.448936e-001,0.000000e+000,,,,,,,,,,,,,,32,1,4.000000e+000,1.560211e-003,0.000000e+000,0,,0,
1524286539.691,,0.000000e+000,3.499950e+001,5.941802e-006,0.000000e+000,2,8.452619e-001,0.000000e+000,,,,,,,,,,,,,,32,1,4.000000e+000,0.000000e+000,0.000000e+000,0,,0,
1524286578.777,,0.000000e+000,3.499793e+001,5.944219e-006,0.000000e+000,2,8.499942e-001,0.000000e+000,,,,,,,,,,,,,,32,1,4.000000e+000,1.567841e-003,0.000000e+000,0,,0,
1524286616.352,,0.000000e+000,3.499911e+001,5.951945e-006,0.000000e+000,2,8.428640e-001,0.000000e+000,,,,,,,,,,,,,,32,1,4.000000e+000,7.820129e-004,0.000000e+000,0,,0,
1524286653.598,,0.000000e+000,3.499872e+001,5.958191e-006,0.000000e+000,2,8.484457e-001,0.000000e+000,,,,,,,,,,,,,,32,1,4.000000e+000,0.000000e+000,0.000000e+000,0,,0,
1524286691.713,,0.000000e+000,3.499872e+001,5.971652e-006,0.000000e+000,2,8.449960e-001,0.000000e+000,,,,,,,,,,,,,,32,1,4.000000e+000,1.560211e-003,0.000000e+000,0,,0,
1524286729.806,,0.000000e+000,3.499950e+001,6.013250e-006,0.000000e+000,2,8.456754e-001,0.000000e+000,,,,,,,,,,,,,,32,1,4.000000e+000,0.000000e+000,0.000000e+000,0,,0,
1524286767.844,,0.000000e+000,3.499833e+001,6.006809e-006,0.000000e+000,2,8.489496e-001,0.000000e+000,,,,,,,,,,,,,,32,1,4.000000e+000,7.781982e-004,0.000000e+000,0,,0,
1524286805.932,,0.000000e+000,3.499793e+001,6.017453e-006,0.000000e+000,2,8.478037e-001,0.000000e+000,,,,,,,,,,,,,,32,1,4.000000e+000,1.567841e-003,0.000000e+000,0,,0,
1524286843.958,,0.000000e+000,3.499833e+001,6.015031e-006,0.000000e+000,2,8.470930e-001,0.000000e+000,,,,,,,,,,,,,,32,1,4.000000e+000,2.349854e-003,0.000000e+000,0,,0,
1524286882.074,,0.000000e+000,3.499950e+001,5.999703e-006,0.000000e+000,2,8.492169e-001,0.000000e+000,,,,,,,,,,,,,,32,1,4.000000e+000,0.000000e+000,0.000000e+000,0,,0,
1524286920.227,,0.000000e+000,3.499754e+001,6.018376e-006,0.000000e+000,2,8.453159e-001,0.000000e+000,,,,,,,,,,,,,,32,1,4.000000e+000,7.896423e-004,0.000000e+000,0,,0,
1524286957.700,,0.000000e+000,3.500028e+001,6.040475e-006,0.000000e+000,2,8.450876e-001,0.000000e+000,,,,,,,,,,,,,,32,1,4.000000e+000,0.000000e+000,0.000000e+000,0,,0,
1524286995.778,,0.000000e+000,3.499989e+001,6.110209e-006,0.000000e+000,2,8.476261e-001,0.000000e+000,,,,,,,,,,,,,,32,1,4.000000e+000,7.781982e-004,0.000000e+000,0,,0,
1524287033.853,,0.000000e+000,3.499911e+001,6.067911e-006,0.000000e+000,2,8.457931e-001,0.000000e+000,,,,,,,,,,,,,,32,1,4.000000e+000,7.820129e-004,0.000000e+000,0,,0,
1524287071.949,,0.000000e+000,3.500028e+001,6.052244e-006,0.000000e+000,2,8.523051e-001,0.000000e+000,,,,,,,,,,,,,,32,1,4.000000e+000,1.560211e-003,0.000000e+000,0,,0,
1524287110.024,,0.000000e+000,3.499872e+001,6.062274e-006,0.000000e+000,2,8.465243e-001,0.000000e+000,,,,,,,,,,,,,,32,1,4.000000e+000,0.000000e+000,0.000000e+000,0,,0,
1524287148.095,,0.000000e+000,3.499950e+001,6.057283e-006,0.000000e+000,2,8.472432e-001,0.000000e+000,,,,,,,,,,,,,,32,1,4.000000e+000,1.560211e-003,0.000000e+000,0,,0,
1524287185.918,,0.000000e+000,3.499872e+001,6.100062e-006,0.000000e+000,2,8.492457e-001,0.000000e+000,,,,,,,,,,,,,,32,1,4.000000e+000,1.560211e-003,0.000000e+000,0,,0,
1524287223.694,,0.000000e+000,3.500028e+001,6.064658e-006,0.000000e+000,2,8.457841e-001,0.000000e+000,,,,,,,,,,,,,,32,1,4.000000e+000,0.000000e+000,0.000000e+000,0,,0,
1524287261.814,,0.000000e+000,3.499950e+001,6.080385e-006,0.000000e+000,2,8.455662e-001,0.000000e+000,,,,,,,,,,,,,,32,1,4.000000e+000,1.560211e-003,0.000000e+000,0,,0,
1524287299.895,,0.000000e+000,3.499872e+001,6.087421e-006,0.000000e+000,2,8.471416e-001,0.000000e+000,,,,,,,,,,,,,,32,1,4.000000e+000,0.000000e+000,0.000000e+000,0,,0,
1524287337.953,,0.000000e+000,3.499833e+001,6.102129e-006,0.000000e+000,2,8.430506e-001,0.000000e+000,,,,,,,,,,,,,,32,1,4.000000e+000,7.781982e-004,0.000000e+000,0,,0,
1524287375.763,,0.000000e+000,3.499950e+001,6.103610e-006,0.000000e+000,2,8.483251e-001,0.000000e+000,,,,,,,,,,,,,,32,1,4.000000e+000,0.000000e+000,0.000000e+000,0,,0,
1524287413.601,,0.000000e+000,3.499911e+001,6.156348e-006,0.000000e+000,2,8.477806e-001,0.000000e+000,,,,,,,,,,,,,,32,1,4.000000e+000,7.820129e-004,0.000000e+000,0,,0,
1524287451.799,,0.000000e+000,3.499793e+001,6.098046e-006,0.000000e+000,2,8.496847e-001,0.000000e+000,,,,,,,,,,,,,,32,1,4.000000e+000,1.567841e-003,0.000000e+000,0,,0,
1524287489.740,,0.000000e+000,3.499872e+001,6.105240e-006,0.000000e+000,2,8.504550e-001,0.000000e+000,,,,,,,,,,,,,,32,1,4.000000e+000,0.000000e+000,0.000000e+000,0,,0,
1524287527.166,,0.000000e+000,3.499911e+001,6.143907e-006,0.000000e+000,2,8.468434e-001,0.000000e+000,,,,,,,,,,,,,,32,1,4.000000e+000,7.820129e-004,0.000000e+000,0,,0,
1524287564.559,,0.000000e+000,3.499872e+001,6.141360e-006,0.000000e+000,2,8.507979e-001,0.000000e+000,,,,,,,,,,,,,,32,1,4.000000e+000,0.000000e+000,0.000000e+000,0,,0,
1524287603.114,,0.000000e+000,3.499911e+001,6.157567e-006,0.000000e+000,2,8.500050e-001,0.000000e+000,,,,,,,,,,,,,,32,1,4.000000e+000,2.338409e-003,0.000000e+000,0,,0,
1524287641.167,,0.000000e+000,3.499911e+001,6.143230e-006,0.000000e+000,2,8.528608e-001,0.000000e+000,,,,,,,,,,,,,,32,1,4.000000e+000,7.820129e-004,0.000000e+000,0,,0,
1524287678.823,,0.000000e+000,3.499911e+001,6.123470e-006,0.000000e+000,2,8.522066e-001,0.000000e+000,,,,,,,,,,,,,,32,1,4.000000e+000,7.820129e-004,0.000000e+000,0,,0,
1524287716.891,,0.000000e+000,3.499911e+001,6.134845e-006,0.000000e+000,2,8.496937e-001,0.000000e+000,,,,,,,,,,,,,,32,1,4.000000e+000,7.820129e-004,0.000000e+000,0,,0,
1524287754.871,,0.000000e+000,3.499872e+001,6.111350e-006,0.000000e+000,2,8.460841e-001,0.000000e+000,,,,,,,,,,,,,,32,1,4.000000e+000,1.560211e-003,0.000000e+000,0,,0,
1524287793.039,,0.000000e+000,3.499950e+001,6.164531e-006,0.000000e+000,2,8.496522e-001,0.000000e+000,,,,,,,,,,,,,,32,1,4.000000e+000,0.000000e+000,0.000000e+000,0,,0,
1524287831.040,,0.000000e+000,3.499989e+001,6.159640e-006,0.000000e+000,2,8.502646e-001,0.000000e+000,,,,,,,,,,,,,,32,1,4.000000e+000,7.781982e-004,0.000000e+000,0,,0,
1524287869.131,,0.000000e+000,3.499872e+001,6.145876e-006,0.000000e+000,2,8.524710e-001,0.000000e+000,,,,,,,,,,,,,,32,1,4.000000e+000,0.000000e+000,0.000000e+000,0,,0,
1524287906.761,,0.000000e+000,3.499950e+001,6.167745e-006,0.000000e+000,2,8.543041e-001,0.000000e+000,,,,,,,,,,,,,,32,1,4.000000e+000,1.560211e-003,0.000000e+000,0,,0,
1524287945.289,,0.000000e+000,3.499833e+001,6.174142e-006,0.000000e+000,2,8.512713e-001,0.000000e+000,,,,,,,,,,,,,,32,1,4.000000e+000,7.781982e-004,0.000000e+000,0,,0,
1524287982.950,,0.000000e+000,3.500028e+001,6.179046e-006,0.000000e+000,2,8.537135e-001,0.000000e+000,,,,,,,,,,,,,,32,1,4.000000e+000,1.560211e-003,0.000000e+000,0,,0,
1524288021.050,,0.000000e+000,3.499911e+001,6.193643e-006,0.000000e+000,2,8.495379e-001,0.000000e+000,,,,,,,,,,,,,,32,1,4.000000e+000,7.820129e-004,0.000000e+000,0,,0,
1524288059.093,,0.000000e+000,3.499911e+001,6.196204e-006,0.000000e+000,2,8.500428e-001,0.000000e+000,,,,,,,,,,,,,,32,1,4.000000e+000,7.820129e-004,0.000000e+000,0,,0,
1524288097.574,,0.000000e+000,3.499833e+001,6.198231e-006,0.000000e+000,2,8.527193e-001,0.000000e+000,,,,,,,,,,,,,,32,1,4.000000e+000,7.781982e-004,0.000000e+000,0,,0,
1524288135.539,,0.000000e+000,3.499989e+001,6.236747e-006,0.000000e+000,2,8.498210e-001,0.000000e+000,,,,,,,,,,,,,,32,1,4.000000e+000,7.781982e-004,0.000000e+000,0,,0,
1524288174.148,,0.000000e+000,3.499989e+001,6.221675e-006,0.000000e+000,2,8.497371e-001,0.000000e+000,,,,,,,,,,,,,,32,1,4.000000e+000,7.781982e-004,0.000000e+000,0,,0,
1524288212.181,,0.000000e+000,3.499911e+001,6.248385e-006,0.000000e+000,2,8.510641e-001,0.000000e+000,,,,,,,,,,,,,,32,1,4.000000e+000,7.820129e-004,0.000000e+000,0,,0,
1524288251.086,,0.000000e+000,3.499793e+001,6.217542e-006,0.000000e+000,2,8.466498e-001,0.000000e+000,,,,,,,,,,,,,,32,1,4.000000e+000,1.567841e-003,0.000000e+000,0,,0,
1524288289.169,,0.000000e+000,3.499911e+001,6.202333e-006,0.000000e+000,2,8.493350e-001,0.000000e+000,,,,,,,,,,,,,,32,1,4.000000e+000,7.820129e-004,0.000000e+000,0,,0,
1524288326.732,,0.000000e+000,3.499911e+001,6.223630e-006,0.000000e+000,2,8.510728e-001,0.000000e+000,,,,,,,,,,,,,,32,1,4.000000e+000,7.820129e-004,0.000000e+000,0,,0,
1524288365.278,,0.000000e+000,3.499950e+001,6.232303e-006,0.000000e+000,2,8.518653e-001,0.000000e+000,,,,,,,,,,,,,,32,1,4.000000e+000,0.000000e+000,0.000000e+000,0,,0,
1524288402.823,,0.000000e+000,3.499911e+001,6.223825e-006,0.000000e+000,2,8.529877e-001,0.000000e+000,,,,,,,,,,,,,,32,1,4.000000e+000,7.820129e-004,0.000000e+000,0,,0,
1524288441.341,,0.000000e+000,3.499754e+001,6.282517e-006,0.000000e+000,2,8.500730e-001,0.000000e+000,,,,,,,,,,,,,,32,1,4.000000e+000,2.349854e-003,0.000000e+000,0,,0,
1524288479.379,,0.000000e+000,3.499833e+001,6.301776e-006,0.000000e+000,2,8.475099e-001,0.000000e+000,,,,,,,,,,,,,,32,1,4.000000e+000,7.781982e-004,0.000000e+000,0,,0,
1524288517.168,,0.000000e+000,3.499793e+001,6.289494e-006,0.000000e+000,2,8.487229e-001,0.000000e+000,,,,,,,,,,,,,,32,1,4.000000e+000,4.688263e-003,0.000000e+000,0,,0,
1524288555.261,,0.000000e+000,3.499989e+001,6.269571e-006,0.000000e+000,2,8.498439e-001,0.000000e+000,,,,,,,,,,,,,,32,1,4.000000e+000,7.781982e-004,0.000000e+000,0,,0,
1524288594.229,,0.000000e+000,3.499911e+001,6.295113e-006,0.000000e+000,2,8.537385e-001,0.000000e+000,,,,,,,,,,,,,,32,1,4.000000e+000,2.338409e-003,0.000000e+000,0,,0,
1524288632.277,,0.000000e+000,3.499833e+001,6.276137e-006,0.000000e+000,2,8.518117e-001,0.000000e+000,,,,,,,,,,,,,,32,1,4.000000e+000,7.781982e-004,0.000000e+000,0,,0,
1524288671.172,,0.000000e+000,3.499911e+001,6.219474e-006,0.000000e+000,2,8.495511e-001,0.000000e+000,,,,,,,,,,,,,,32,1,4.000000e+000,7.820129e-004,0.000000e+000,0,,0,
1524288709.185,,0.000000e+000,3.499911e+001,6.248586e-006,0.000000e+000,2,8.532447e-001,0.000000e+000,,,,,,,,,,,,,,32,1,4.000000e+000,2.338409e-003,0.000000e+000,0,,0,
1524288747.301,,0.000000e+000,3.499989e+001,6.285898e-006,0.000000e+000,2,8.476897e-001,0.000000e+000,,,,,,,,,,,,,,32,1,4.000000e+000,7.781982e-004,0.000000e+000,0,,0,
1524288785.107,,0.000000e+000,3.499872e+001,6.312268e-006,0.000000e+000,2,8.550519e-001,0.000000e+000,,,,,,,,,,,,,,32,1,4.000000e+000,0.000000e+000,0.000000e+000,0,,0,
1524288822.890,,0.000000e+000,3.499950e+001,6.338811e-006,0.000000e+000,2,8.540536e-001,0.000000e+000,,,,,,,,,,,,,,32,1,4.000000e+000,0.000000e+000,0.000000e+000,0,,0,
1524288861.495,,0.000000e+000,3.499911e+001,6.239762e-006,0.000000e+000,2,8.502076e-001,0.000000e+000,,,,,,,,,,,,,,32,1,4.000000e+000,7.820129e-004,0.000000e+000,0,,0,
1524288899.456,,0.000000e+000,3.499989e+001,6.317285e-006,0.000000e+000,2,8.520903e-001,0.000000e+000,,,,,,,,,,,,,,32,1,4.000000e+000,7.781982e-004,0.000000e+000,0,,0,
1524288937.969,,0.000000e+000,3.499989e+001,6.326065e-006,0.000000e+000,2,8.526407e-001,0.000000e+000,,,,,,,,,,,,,,32,1,4.000000e+000,7.781982e-004,0.000000e+000,0,,0,
1524288975.859,,0.000000e+000,3.500028e+001,6.293445e-006,0.000000e+000,2,8.515244e-001,0.000000e+000,,,,,,,,,,,,,,32,1,4.000000e+000,0.000000e+000,0.000000e+000,0,,0,
1524289013.525,,0.000000e+000,3.499950e+001,6.351186e-006,0.000000e+000,2,8.510191e-001,0.000000e+000,,,,,,,,,,,,,,32,1,4.000000e+000,1.560211e-003,0.000000e+000,0,,0,
1524289051.630,,0.000000e+000,3.499793e+001,6.353218e-006,0.000000e+000,2,8.479413e-001,0.000000e+000,,,,,,,,,,,,,,32,1,4.000000e+000,3.131866e-003,0.000000e+000,0,,0,
1524289088.986,,0.000000e+000,3.499911e+001,6.287155e-006,0.000000e+000,2,8.483377e-001,0.000000e+000,,,,,,,,,,,,,,32,1,4.000000e+000,7.820129e-004,0.000000e+000,0,,0,
1524289127.464,,0.000000e+000,3.499911e+001,6.342562e-006,0.000000e+000,2,8.554077e-001,0.000000e+000,,,,,,,,,,,,,,32,1,4.000000e+000,7.820129e-004,0.000000e+000,0,,0,
1524289165.077,,0.000000e+000,3.499911e+001,6.293004e-006,0.000000e+000,2,8.514771e-001,0.000000e+000,,,,,,,,,,,,,,32,1,4.000000e+000,7.820129e-004,0.000000e+000,0,,0,
1524289203.173,,0.000000e+000,3.499911e+001,6.326546e-006,0.000000e+000,2,8.538790e-001,0.000000e+000,,,,,,,,,,,,,,32,1,4.000000e+000,7.820129e-004,0.000000e+000,0,,0,
1524289241.266,,0.000000e+000,3.499989e+001,6.308623e-006,0.000000e+000,2,8.536116e-001,0.000000e+000,,,,,,,,,,,,,,32,1,4.000000e+000,7.781982e-004,0.000000e+000,0,,0,
1524289279.349,,0.000000e+000,3.499950e+001,6.313925e-006,0.000000e+000,2,8.519970e-001,0.000000e+000,,,,,,,,,,,,,,32,1,4.000000e+000,0.000000e+000,0.000000e+000,0,,0,
1524289317.422,,0.000000e+000,3.499872e+001,6.315491e-006,0.000000e+000,2,8.543097e-001,0.000000e+000,,,,,,,,,,,,,,32,1,4.000000e+000,0.000000e+000,0.000000e+000,0,,0,
1524289355.950,,0.000000e+000,3.499950e+001,6.300008e-006,0.000000e+000,2,8.556926e-001,0.000000e+000,,,,,,,,,,,,,,32,1,4.000000e+000,0.000000e+000,0.000000e+000,0,,0,
1524289393.593,,0.000000e+000,3.499872e+001,6.307337e-006,0.000000e+000,2,8.550313e-001,0.000000e+000,,,,,,,,,,,,,,32,1,4.000000e+000,0.000000e+000,0.000000e+000,0,,0,
1524289431.581,,0.000000e+000,3.499989e+001,6.315736e-006,0.000000e+000,2,8.543282e-001,0.000000e+000,,,,,,,,,,,,,,32,1,4.000000e+000,7.781982e-004,0.000000e+000,0,,0,
1524289469.982,,0.000000e+000,3.499872e+001,6.328523e-006,0.000000e+000,2,8.537338e-001,0.000000e+000,,,,,,,,,,,,,,32,1,4.000000e+000,1.560211e-003,0.000000e+000,0,,0,
1524289507.315,,0.000000e+000,3.499911e+001,6.321968e-006,0.000000e+000,2,8.549001e-001,0.000000e+000,,,,,,,,,,,,,,32,1,4.000000e+000,7.820129e-004,0.000000e+000,0,,0,
1524289545.298,,0.000000e+000,3.499872e+001,6.286574e-006,0.000000e+000,2,8.545033e-001,0.000000e+000,,,,,,,,,,,,,,32,1,4.000000e+000,0.000000e+000,0.000000e+000,0,,0,
1524289583.483,,0.000000e+000,3.499911e+001,6.333428e-006,0.000000e+000,2,8.510093e-001,0.000000e+000,,,,,,,,,,,,,,32,1,4.000000e+000,7.820129e-004,0.000000e+000,0,,0,
1524289621.524,,0.000000e+000,3.499833e+001,6.374841e-006,0.000000e+000,2,8.529221e-001,0.000000e+000,,,,,,,,,,,,,,32,1,4.000000e+000,7.781982e-004,0.000000e+000,0,,0,
1524289659.104,,0.000000e+000,3.499911e+001,6.351266e-006,0.000000e+000,2,8.553715e-001,0.000000e+000,,,,,,,,,,,,,,32,1,4.000000e+000,7.820129e-004,0.000000e+000,0,,0,
1524289697.217,,0.000000e+000,3.499950e+001,6.345393e-006,0.000000e+000,2,8.524808e-001,0.000000e+000,,,,,,,,,,,,,,32,1,4.000000e+000,0.000000e+000,0.000000e+000,0,,0,
1524289735.298,,0.000000e+000,3.499950e+001,6.326905e-006,0.000000e+000,2,8.567417e-001,0.000000e+000,,,,,,,,,,,,,,32,1,4.000000e+000,0.000000e+000,0.000000e+000,0,,0,
1524289773.261,,0.000000e+000,3.499950e+001,6.318471e-006,0.000000e+000,2,8.541452e-001,0.000000e+000,,,,,,,,,,,,,,32,1,4.000000e+000,0.000000e+000,0.000000e+000,0,,0,
1524289811.419,,0.000000e+000,3.499872e+001,6.369196e-006,0.000000e+000,2,8.507651e-001,0.000000e+000,,,,,,,,,,,,,,32,1,4.000000e+000,0.000000e+000,0.000000e+000,0,,0,
1524289849.500,,0.000000e+000,3.499872e+001,6.375003e-006,0.000000e+000,2,8.536305e-001,0.000000e+000,,,,,,,,,,,,,,32,1,4.000000e+000,0.000000e+000,0.000000e+000,0,,0,
1524289887.520,,0.000000e+000,3.499872e+001,6.384674e-006,0.000000e+000,2,8.515818e-001,0.000000e+000,,,,,,,,,,,,,,32,1,4.000000e+000,0.000000e+000,0.000000e+000,0,,0,
1524289925.163,,0.000000e+000,3.500028e+001,6.345083e-006,0.000000e+000,2,8.545448e-001,0.000000e+000,,,,,,,,,,,,,,32,1,4.000000e+000,1.560211e-003,0.000000e+000,0,,0,
1524289963.171,,0.000000e+000,3.499833e+001,6.364035e-006,0.000000e+000,2,8.541366e-001,0.000000e+000,,,,,,,,,,,,,,32,1,4.000000e+000,7.781982e-004,0.000000e+000,0,,0,
1524290001.262,,0.000000e+000,3.499911e+001,6.369734e-006,0.000000e+000,2,8.574821e-001,0.000000e+000,,,,,,,,,,,,,,32,1,4.000000e+000,7.820129e-004,0.000000e+000,0,,0,
1524290038.910,,0.000000e+000,3.499911e+001,6.407477e-006,0.000000e+000,2,8.542997e-001,0.000000e+000,,,,,,,,,,,,,,32,1,4.000000e+000,7.820129e-004,0.000000e+000,0,,0,
1524290077.008,,0.000000e+000,3.499911e+001,6.370799e-006,0.000000e+000,2,8.543418e-001,0.000000e+000,,,,,,,,,,,,,,32,1,4.000000e+000,7.820129e-004,0.000000e+000,0,,0,
1524290115.316,,0.000000e+000,3.499989e+001,6.353558e-006,0.000000e+000,2,8.557199e-001,0.000000e+000,,,,,,,,,,,,,,32,1,4.000000e+000,7.781982e-004,0.000000e+000,0,,0,
1524290153.959,,0.000000e+000,3.500106e+001,6.407799e-006,0.000000e+000,2,8.565171e-001,0.000000e+000,,,,,,,,,,,,,,32,1,4.000000e+000,4.692078e-003,0.000000e+000,0,,0,
1524290191.887,,0.000000e+000,3.499833e+001,6.363932e-006,0.000000e+000,2,8.530506e-001,0.000000e+000,,,,,,,,,,,,,,32,1,4.000000e+000,7.781982e-004,0.000000e+000,0,,0,
1524290229.375,,0.000000e+000,3.499872e+001,6.417252e-006,0.000000e+000,2,8.507389e-001,0.000000e+000,,,,,,,,,,,,,,32,1,4.000000e+000,0.000000e+000,0.000000e+000,0,,0,
1524290266.831,,0.000000e+000,3.499911e+001,6.460700e-006,0.000000e+000,2,8.482940e-001,0.000000e+000,,,,,,,,,,,,,,32,1,4.000000e+000,7.820129e-004,0.000000e+000,0,,0,
1524290304.454,,0.000000e+000,3.499911e+001,6.396831e-006,0.000000e+000,2,8.567035e-001,0.000000e+000,,,,,,,,,,,,,,32,1,4.000000e+000,7.820129e-004,0.000000e+000,0,,0,
1524290342.987,,0.000000e+000,3.499872e+001,6.374291e-006,0.000000e+000,2,8.554481e-001,0.000000e+000,,,,,,,,,,,,,,32,1,4.000000e+000,0.000000e+000,0.000000e+000,0,,0,
1524290381.105,,0.000000e+000,3.499911e+001,6.413481e-006,0.000000e+000,2,8.535983e-001,0.000000e+000,,,,,,,,,,,,,,32,1,4.000000e+000,7.820129e-004,0.000000e+000,0,,0,
1524290418.628,,0.000000e+000,3.499872e+001,6.400559e-006,0.000000e+000,2,8.560401e-001,0.000000e+000,,,,,,,,,,,,,,32,1,4.000000e+000,0.000000e+000,0.000000e+000,0,,0,
1524290456.776,,0.000000e+000,3.499872e+001,6.416633e-006,0.000000e+000,2,8.524197e-001,0.000000e+000,,,,,,,,,,,,,,32,1,4.000000e+000,0.000000e+000,0.000000e+000,0,,0,
1524290494.797,,0.000000e+000,3.499911e+001,6.389881e-006,0.000000e+000,2,8.539535e-001,0.000000e+000,,,,,,,,,,,,,,32,1,4.000000e+000,7.820129e-004,0.000000e+000,0,,0,
1524290532.930,,0.000000e+000,3.499872e+001,6.411601e-006,0.000000e+000,2,8.544508e-001,0.000000e+000,,,,,,,,,,,,,,32,1,4.000000e+000,0.000000e+000,0.000000e+000,0,,0,
1524290570.595,,0.000000e+000,3.499989e+001,6.390222e-006,0.000000e+000,2,8.530192e-001,0.000000e+000,,,,,,,,,,,,,,32,1,4.000000e+000,7.781982e-004,0.000000e+000,0,,0,
1524290607.966,,0.000000e+000,3.499950e+001,6.423460e-006,0.000000e+000,2,8.557860e-001,0.000000e+000,,,,,,,,,,,,,,32,1,4.000000e+000,0.000000e+000,0.000000e+000,0,,0,
1524290645.879,,0.000000e+000,3.499911e+001,6.453713e-006,0.000000e+000,2,8.536299e-001,0.000000e+000,,,,,,,,,,,,,,32,1,4.000000e+000,7.820129e-004,0.000000e+000,0,,0,
1524290683.684,,0.000000e+000,3.499911e+001,6.413423e-006,0.000000e+000,2,8.539743e-001,0.000000e+000,,,,,,,,,,,,,,32,1,4.000000e+000,7.820129e-004,0.000000e+000,0,,0,
1524290721.767,,0.000000e+000,3.499872e+001,6.439419e-006,0.000000e+000,2,8.552878e-001,0.000000e+000,,,,,,,,,,,,,,32,1,4.000000e+000,0.000000e+000,0.000000e+000,0,,0,
1524290759.538,,0.000000e+000,3.499911e+001,6.451287e-006,0.000000e+000,2,8.517438e-001,0.000000e+000,,,,,,,,,,,,,,32,1,4.000000e+000,7.820129e-004,0.000000e+000,0,,0,
1524290797.256,,0.000000e+000,3.499950e+001,6.444954e-006,0.000000e+000,2,8.528295e-001,0.000000e+000,,,,,,,,,,,,,,32,1,4.000000e+000,1.560211e-003,0.000000e+000,0,,0,
1524290835.209,,0.000000e+000,3.499989e+001,6.456902e-006,0.000000e+000,2,8.571307e-001,0.000000e+000,,,,,,,,,,,,,,32,1,4.000000e+000,7.781982e-004,0.000000e+000,0,,0,
1524290873.240,,0.000000e+000,3.499950e+001,6.445775e-006,0.000000e+000,2,8.520898e-001,0.000000e+000,,,,,,,,,,,,,,32,1,4.000000e+000,0.000000e+000,0.000000e+000,0,,0,
1524290911.370,,0.000000e+000,3.499754e+001,6.452790e-006,0.000000e+000,2,8.536114e-001,0.000000e+000,,,,,,,,,,,,,,32,1,4.000000e+000,3.910065e-003,0.000000e+000,0,,0,
1524290948.891,,0.000000e+000,3.499832e+001,6.454923e-006,0.000000e+000,2,8.541926e-001,0.000000e+000,,,,,,,,,,,,,,32,1,4.000000e+000,3.910065e-003,0.000000e+000,0,,0,
1524290986.296,,0.000000e+000,3.499872e+001,6.451433e-006,0.000000e+000,2,8.551875e-001,0.000000e+000,,,,,,,,,,,,,,32,1,4.000000e+000,1.560211e-003,0.000000e+000,0,,0,
1524291024.712,,0.000000e+000,3.499911e+001,6.432644e-006,0.000000e+000,2,8.558708e-001,0.000000e+000,,,,,,,,,,,,,,32,1,4.000000e+000,7.820129e-004,0.000000e+000,0,,0,
1524291062.475,,0.000000e+000,3.499989e+001,6.467482e-006,0.000000e+000,2,8.551904e-001,0.000000e+000,,,,,,,,,,,,,,32,1,4.000000e+000,2.342224e-003,0.000000e+000,0,,0,
1524291100.593,,0.000000e+000,3.499911e+001,6.432085e-006,0.000000e+000,2,8.544407e-001,0.000000e+000,,,,,,,,,,,,,,32,1,4.000000e+000,7.820129e-004,0.000000e+000,0,,0,
1524291138.649,,0.000000e+000,3.499872e+001,6.438981e-006,0.000000e+000,2,8.581191e-001,0.000000e+000,,,,,,,,,,,,,,32,1,4.000000e+000,0.000000e+000,0.000000e+000,0,,0,
1524291176.072,,0.000000e+000,3.499950e+001,6.452908e-006,0.000000e+000,2,8.553584e-001,0.000000e+000,,,,,,,,,,,,,,32,1,4.000000e+000,0.000000e+000,0.000000e+000,0,,0,
1524291214.147,,0.000000e+000,3.500145e+001,6.458754e-006,0.000000e+000,2,8.538737e-001,0.000000e+000,,,,,,,,,,,,,,32,1,4.000000e+000,2.349854e-003,0.000000e+000,0,,0,
1524291252.080,,0.000000e+000,3.499872e+001,6.469881e-006,0.000000e+000,2,8.533019e-001,0.000000e+000,,,,,,,,,,,,,,32,1,4.000000e+000,0.000000e+000,0.000000e+000,0,,0,
1524291290.191,,0.000000e+000,3.499989e+001,6.460458e-006,0.000000e+000,2,8.521770e-001,0.000000e+000,,,,,,,,,,,,,,32,1,4.000000e+000,7.781982e-004,0.000000e+000,0,,0,
1524291328.256,,0.000000e+000,3.499872e+001,6.407919e-006,0.000000e+000,2,8.583078e-001,0.000000e+000,,,,,,,,,,,,,,32,1,4.000000e+000,0.000000e+000,0.000000e+000,0,,0,
1524291366.352,,0.000000e+000,3.499911e+001,6.473990e-006,0.000000e+000,2,8.536304e-001,0.000000e+000,,,,,,,,,,,,,,32,1,4.000000e+000,7.820129e-004,0.000000e+000,0,,0,
1524291405.052,,0.000000e+000,3.499911e+001,6.502045e-006,0.000000e+000,2,8.528556e-001,0.000000e+000,,,,,,,,,,,,,,32,1,4.000000e+000,3.910065e-003,0.000000e+000,0,,0,
1524291442.528,,0.000000e+000,3.499989e+001,6.492341e-006,0.000000e+000,2,8.556018e-001,0.000000e+000,,,,,,,,,,,,,,32,1,4.000000e+000,2.342224e-003,0.000000e+000,0,,0,
1524291480.626,,0.000000e+000,3.499989e+001,6.487864e-006,0.000000e+000,2,8.527822e-001,0.000000e+000,,,,,,,,,,,,,,32,1,4.000000e+000,7.781982e-004,0.000000e+000,0,,0,
1524291518.694,,0.000000e+000,3.499872e+001,6.462923e-006,0.000000e+000,2,8.533221e-001,0.000000e+000,,,,,,,,,,,,,,32,1,4.000000e+000,0.000000e+000,0.000000e+000,0,,0,
1524291557.367,,0.000000e+000,3.499989e+001,6.472402e-006,0.000000e+000,2,8.534667e-001,0.000000e+000,,,,,,,,,,,,,,32,1,4.000000e+000,7.781982e-004,0.000000e+000,0,,0,
1524291595.490,,0.000000e+000,3.500106e+001,6.473145e-006,0.000000e+000,2,8.532414e-001,0.000000e+000,,,,,,,,,,,,,,32,1,4.000000e+000,0.000000e+000,0.000000e+000,0,,0,
1524291632.993,,0.000000e+000,3.499911e+001,6.473659e-006,0.000000e+000,2,8.577546e-001,0.000000e+000,,,,,,,,,,,,,,32,1,4.000000e+000,2.338409e-003,0.000000e+000,0,,0,
1524291670.726,,0.000000e+000,3.499872e+001,6.461813e-006,0.000000e+000,2,8.540661e-001,0.000000e+000,,,,,,,,,,,,,,32,1,4.000000e+000,0.000000e+000,0.000000e+000,0,,0,
1524291708.604,,0.000000e+000,3.499911e+001,6.471484e-006,0.000000e+000,2,8.540196e-001,0.000000e+000,,,,,,,,,,,,,,32,1,4.000000e+000,7.820129e-004,0.000000e+000,0,,0,
1524291746.735,,0.000000e+000,3.499950e+001,6.457568e-006,0.000000e+000,2,8.543504e-001,0.000000e+000,,,,,,,,,,,,,,32,1,4.000000e+000,0.000000e+000,0.000000e+000,0,,0,
1524291784.838,,0.000000e+000,3.499950e+001,6.478769e-006,0.000000e+000,2,8.556103e-001,0.000000e+000,,,,,,,,,,,,,,32,1,4.000000e+000,1.560211e-003,0.000000e+000,0,,0,
1524291822.361,,0.000000e+000,3.499872e+001,6.473821e-006,0.000000e+000,2,8.545134e-001,0.000000e+000,,,,,,,,,,,,,,32,1,4.000000e+000,0.000000e+000,0.000000e+000,0,,0,
1524291860.182,,0.000000e+000,3.499872e+001,6.504629e-006,0.000000e+000,2,8.517836e-001,0.000000e+000,,,,,,,,,,,,,,32,1,4.000000e+000,0.000000e+000,0.000000e+000,0,,0,
1524291899.100,,0.000000e+000,3.499989e+001,6.508200e-006,0.000000e+000,2,8.509522e-001,0.000000e+000,,,,,,,,,,,,,,32,1,4.000000e+000,7.781982e-004,0.000000e+000,0,,0,
1524291936.218,,0.000000e+000,3.499950e+001,6.485766e-006,0.000000e+000,2,8.548874e-001,0.000000e+000,,,,,,,,,,,,,,32,1,4.000000e+000,1.560211e-003,0.000000e+000,0,,0,
1524291974.186,,0.000000e+000,3.499872e+001,6.475560e-006,0.000000e+000,2,8.546773e-001,0.000000e+000,,,,,,,,,,,,,,32,1,4.000000e+000,0.000000e+000,0.000000e+000,0,,0,
1524292012.276,,0.000000e+000,3.499950e+001,6.505871e-006,0.000000e+000,2,8.558571e-001,0.000000e+000,,,,,,,,,,,,,,32,1,4.000000e+000,0.000000e+000,0.000000e+000,0,,0,
1524292050.372,,0.000000e+000,3.499950e+001,6.513561e-006,0.000000e+000,2,8.528866e-001,0.000000e+000,,,,,,,,,,,,,,32,1,4.000000e+000,0.000000e+000,0.000000e+000,0,,0,
1524292087.887,,0.000000e+000,3.499911e+001,6.503622e-006,0.000000e+000,2,8.530576e-001,0.000000e+000,,,,,,,,,,,,,,32,1,4.000000e+000,7.820129e-004,0.000000e+000,0,,0,
1524292126.083,,0.000000e+000,3.499950e+001,6.517967e-006,0.000000e+000,2,8.567798e-001,0.000000e+000,,,,,,,,,,,,,,32,1,4.000000e+000,1.560211e-003,0.000000e+000,0,,0,
1524292164.051,,0.000000e+000,3.500067e+001,6.503427e-006,0.000000e+000,2,8.564866e-001,0.000000e+000,,,,,,,,,,,,,,32,1,4.000000e+000,7.820129e-004,0.000000e+000,0,,0,
1524292201.687,,0.000000e+000,3.499871e+001,6.521122e-006,0.000000e+000,2,8.566118e-001,0.000000e+000,,,,,,,,,,,,,,32,1,4.000000e+000,3.128052e-003,0.000000e+000,0,,0,
1524292239.572,,0.000000e+000,3.499911e+001,6.537599e-006,0.000000e+000,2,8.537670e-001,0.000000e+000,,,,,,,,,,,,,,32,1,4.000000e+000,7.820129e-004,0.000000e+000,0,,0,
1524292277.715,,0.000000e+000,3.499989e+001,6.569950e-006,0.000000e+000,2,8.569119e-001,0.000000e+000,,,,,,,,,,,,,,32,1,4.000000e+000,7.781982e-004,0.000000e+000,0,,0,
1524292315.898,,0.000000e+000,3.499872e+001,6.519199e-006,0.000000e+000,2,8.541603e-001,0.000000e+000,,,,,,,,,,,,,,32,1,4.000000e+000,1.560211e-003,0.000000e+000,0,,0,
1524292353.986,,0.000000e+000,3.499872e+001,6.504084e-006,0.000000e+000,2,8.524799e-001,0.000000e+000,,,,,,,,,,,,,,32,1,4.000000e+000,1.560211e-003,0.000000e+000,0,,0,
1524292392.057,,0.000000e+000,3.499911e+001,6.474047e-006,0.000000e+000,2,8.587464e-001,0.000000e+000,,,,,,,,,,,,,,32,1,4.000000e+000,7.820129e-004,0.000000e+000,0,,0,
1524292430.130,,0.000000e+000,3.499950e+001,6.529567e-006,0.000000e+000,2,8.543248e-001,0.000000e+000,,,,,,,,,,,,,,32,1,4.000000e+000,0.000000e+000,0.000000e+000,0,,0,
1524292468.223,,0.000000e+000,3.499911e+001,6.523932e-006,0.000000e+000,2,8.526798e-001,0.000000e+000,,,,,,,,,,,,,,32,1,4.000000e+000,7.820129e-004,0.000000e+000,0,,0,
1524292506.346,,0.000000e+000,3.499911e+001,6.523777e-006,0.000000e+000,2,8.511671e-001,0.000000e+000,,,,,,,,,,,,,,32,1,4.000000e+000,7.820129e-004,0.000000e+000,0,,0,
1524292543.542,,0.000000e+000,3.499989e+001,6.513911e-006,0.000000e+000,2,8.560771e-001,0.000000e+000,,,,,,,,,,,,,,32,1,4.000000e+000,7.781982e-004,0.000000e+000,0,,0,
1524292581.197,,0.000000e+000,3.499950e+001,6.518811e-006,0.000000e+000,2,8.548505e-001,0.000000e+000,,,,,,,,,,,,,,32,1,4.000000e+000,0.000000e+000,0.000000e+000,0,,0,
1524292619.303,,0.000000e+000,3.499989e+001,6.517991e-006,0.000000e+000,2,8.567519e-001,0.000000e+000,,,,,,,,,,,,,,32,1,4.000000e+000,7.781982e-004,0.000000e+000,0,,0,
1524292657.266,,0.000000e+000,3.499950e+001,6.550070e-006,0.000000e+000,2,8.578340e-001,0.000000e+000,,,,,,,,,,,,,,32,1,4.000000e+000,0.000000e+000,0.000000e+000,0,,0,
1524292695.604,,0.000000e+000,3.499950e+001,6.549631e-006,0.000000e+000,2,8.551764e-001,0.000000e+000,,,,,,,,,,,,,,32,1,4.000000e+000,1.560211e-003,0.000000e+000,0,,0,
1524292733.702,,0.000000e+000,3.499911e+001,6.532683e-006,0.000000e+000,2,8.565686e-001,0.000000e+000,,,,,,,,,,,,,,32,1,4.000000e+000,7.820129e-004,0.000000e+000,0,,0,
1524292771.417,,0.000000e+000,3.499911e+001,6.549944e-006,0.000000e+000,2,8.537269e-001,0.000000e+000,,,,,,,,,,,,,,32,1,4.000000e+000,7.820129e-004,0.000000e+000,0,,0,
1524292809.471,,0.000000e+000,3.499911e+001,6.566500e-006,0.000000e+000,2,8.515636e-001,0.000000e+000,,,,,,,,,,,,,,32,1,4.000000e+000,7.820129e-004,0.000000e+000,0,,0,
1524292847.444,,0.000000e+000,3.500028e+001,6.588888e-006,0.000000e+000,2,8.569042e-001,0.000000e+000,,,,,,,,,,,,,,32,1,4.000000e+000,3.120422e-003,0.000000e+000,0,,0,
1524292885.392,,0.000000e+000,3.500067e+001,6.588390e-006,0.000000e+000,2,8.531014e-001,0.000000e+000,,,,,,,,,,,,,,32,1,4.000000e+000,2.338409e-003,0.000000e+000,0,,0,
1524292923.210,,0.000000e+000,3.499950e+001,6.602552e-006,0.000000e+000,2,8.529314e-001,0.000000e+000,,,,,,,,,,,,,,32,1,4.000000e+000,1.560211e-003,0.000000e+000,0,,0,
1524292961.263,,0.000000e+000,3.499989e+001,6.588923e-006,0.000000e+000,2,8.518798e-001,0.000000e+000,,,,,,,,,,,,,,32,1,4.000000e+000,7.781982e-004,0.000000e+000,0,,0,
1524292999.458,,0.000000e+000,3.499911e+001,6.564760e-006,0.000000e+000,2,8.543566e-001,0.000000e+000,,,,,,,,,,,,,,32,1,4.000000e+000,7.820129e-004,0.000000e+000,0,,0,
1524293037.419,,0.000000e+000,3.499950e+001,6.554420e-006,0.000000e+000,2,8.565341e-001,0.000000e+000,,,,,,,,,,,,,,32,1,4.000000e+000,0.000000e+000,0.000000e+000,0,,0,
1524293050.137,,0.000000e+000,3.499911e+001,6.557445e-006,0.000000e+000,2,8.566937e-001,0.000000e+000,,,,,,,,,,,,,,32,1,4.000000e+000,7.820129e-004,0.000000e+000,0,,0,