File: Input_All/MFn1_VRMac_36K_6000s_VRMde_35K.dc.dat
[Header]
TITLE,MPMS DC Measurement
BYAPP,MPMS Measurement,2.1,Summary
FILEOPENTIME, 1524322486.883000 4/21/2018, 8:54:46 AM

INFO, APPNAME, MPMS MultiVu Application, Revision 1.61,  Build 082

INFO, NAME, MFn1
INFO, WEIGHT, 1.000
INFO, AREA, 1.000
INFO, LENGTH, 1.000
INFO, SHAPE, 0
INFO, COMMENT,
INFO, SEQUENCE FILE: VRMac_36K_6000s_VRMde_35K.seq


INFO, BACKGROUND DATA FILE:, None


STARTUPAXIS,X,4,LINEAR,AUTO,0.000000,0.000000
STARTUPAXIS,Y1,5,LINEAR,AUTO,0.000000,0.000000


STARTUPGROUP,Longitudinal
FIELDGROUP,Longitudinal,1,2,3,4,5,6,7,8,9,15,16,17,18,27,28
FIELDGROUP,Transverse,1,2,3,4,10,11,12,13,14,19,20,21,22,27,28

PLOT_APPEARANCE,ALL,HORZ_GRID_ON,VERT_GRID_ON,MARKERS_AND_LINES

[Data]
Time,Comment,Field (Oe),Temperature (K),Long Moment (emu),Long Scan Std Dev,Long Algorithm,Long Reg Fit,Long Percent Error (%),Trans Moment (emu),Trans Scan Std Dev,Trans Algorithm,Trans Reg Fit,Trans Percent Error (%),Long Moment [w/o ABS] (emu),Long Scan Std Dev [w/o ABS],Long Reg Fit [w/o ABS],Long Percent Error [w/o ABS] (%),Trans Moment [w/o ABS] (emu),Trans Scan Std Dev [w/o ABS],Trans Reg Fit [w/o ABS],Trans Percent Error [w/o ABS] (%),Points per Scan,Scans per Measurement,Scan Length (cm),Delta Temp (K),Rot Position (deg),Error,EC Comp. Running,Using ABS,
1524322486.881,,0.000000e+000,3.500028e+001,-1.662072e-005,0.000000e+000,2,9.552500e-001,0.000000e+000,,,,,,,,,,,,,,32,1,4.000000e+000,3.120422e-003,0.000000e+000,0,,0,
1524322524.334,,0.000000e+000,3.500145e+001,-1.593450e-005,0.000000e+000,2,9.534030e-001,0.000000e+000,,,,,,,,,,,,,,32,1,4.000000e+000,7.781982e-004,0.000000e+000,0,,0,
1524322562.195,,0.000000e+000,3.500067e+001,-1.515659e-005,0.000000e+000,2,9.502826e-001,0.000000e+000,,,,,,,,,,,,,,32,1,4.000000e+000,7.820129e-004,0.000000e+000,0,,0,
1524322600.343,,0.000000e+000,3.499911e+001,-1.451998e-005,0.000000e+000,2,9.463190e-001,0.000000e+000,,,,,,,,,,,,,,32,1,4.000000e+000,7.820129e-004,0.000000e+000,0,,0,
1524322638.453,,0.000000e+000,3.500067e+001,-1.394703e-005,0.000000e+000,2,9.448847e-001,0.000000e+000,,,,,,,,,,,,,,32,1,4.000000e+000,7.820129e-004,0.000000e+000,0,,0,
1524322676.971,,0.000000e+000,3.499911e+001,-1.340491e-005,0.000000e+000,2,9.418498e-001,0.000000e+000,,,,,,,,,,,,,,32,1,4.000000e+000,7.820129e-004,0.000000e+000,0,,0,
1524322714.992,,0.000000e+000,3.499833e+001,-1.295455e-005,0.000000e+000,2,9.385518e-001,0.000000e+000,,,,,,,,,,,,,,32,1,4.000000e+000,7.781982e-004,0.000000e+000,0,,0,
1524322753.295,,0.000000e+000,3.499872e+001,-1.250394e-005,0.000000e+000,2,9.376996e-001,0.000000e+000,,,,,,,,,,,,,,32,1,4.000000e+000,1.560211e-003,0.000000e+000,0,,0,
1524322791.278,,0.000000e+000,3.499911e+001,-1.212024e-005,0.000000e+000,2,9.344612e-001,0.000000e+000,,,,,,,,,,,,,,32,1,4.000000e+000,7.820129e-004,0.000000e+000,0,,0,
1524322829.364,,0.000000e+000,3.499950e+001,-1.178901e-005,0.000000e+000,2,9.327130e-001,0.000000e+000,,,,,,,,,,,,,,32,1,4.000000e+000,1.560211e-003,0.000000e+000,0,,0,
1524322866.859,,0.000000e+000,3.499950e+001,-1.141293e-005,0.000000e+000,2,9.319904e-001,0.000000e+000,,,,,,,,,,,,,,32,1,4.000000e+000,3.120422e-003,0.000000e+000,0,,0,
1524322905.150,,0.000000e+000,3.499950e+001,-1.116320e-005,0.000000e+000,2,9.290611e-001,0.000000e+000,,,,,,,,,,,,,,32,1,4.000000e+000,1.560211e-003,0.000000e+000,0,,0,
1524322943.038,,0.000000e+000,3.499872e+001,-1.082976e-005,0.000000e+000,2,9.265672e-001,0.000000e+000,,,,,,,,,,,,,,32,1,4.000000e+000,1.560211e-003,0.000000e+000,0,,0,
1524322981.793,,0.000000e+000,3.499872e+001,-1.055474e-005,0.000000e+000,2,9.253167e-001,0.000000e+000,,,,,,,,,,,,,,32,1,4.000000e+000,0.000000e+000,0.000000e+000,0,,0,
1524323019.761,,0.000000e+000,3.499911e+001,-1.029139e-005,0.000000e+000,2,9.223888e-001,0.000000e+000,,,,,,,,,,,,,,32,1,4.000000e+000,7.820129e-004,0.000000e+000,0,,0,
1524323057.912,,0.000000e+000,3.499911e+001,-1.009018e-005,0.000000e+000,2,9.234453e-001,0.000000e+000,,,,,,,,,,,,,,32,1,4.000000e+000,7.820129e-004,0.000000e+000,0,,0,
1524323096.027,,0.000000e+000,3.499911e+001,-9.839943e-006,0.000000e+000,2,9.218426e-001,0.000000e+000,,,,,,,,,,,,,,32,1,4.000000e+000,7.820129e-004,0.000000e+000,0,,0,
1524323134.160,,0.000000e+000,3.499911e+001,-9.626440e-006,0.000000e+000,2,9.170321e-001,0.000000e+000,,,,,,,,,,,,,,32,1,4.000000e+000,7.820129e-004,0.000000e+000,0,,0,
1524323172.974,,0.000000e+000,3.499833e+001,-9.346375e-006,0.000000e+000,2,9.168456e-001,0.000000e+000,,,,,,,,,,,,,,32,1,4.000000e+000,7.781982e-004,0.000000e+000,0,,0,
1524323211.189,,0.000000e+000,3.499950e+001,-9.189793e-006,0.000000e+000,2,9.145346e-001,0.000000e+000,,,,,,,,,,,,,,32,1,4.000000e+000,1.560211e-003,0.000000e+000,0,,0,
1524323248.907,,0.000000e+000,3.499950e+001,-8.991290e-006,0.000000e+000,2,9.123762e-001,0.000000e+000,,,,,,,,,,,,,,32,1,4.000000e+000,3.120422e-003,0.000000e+000,0,,0,
1524323286.593,,0.000000e+000,3.500068e+001,-8.830923e-006,0.000000e+000,2,9.109936e-001,0.000000e+000,,,,,,,,,,,,,,32,1,4.000000e+000,5.470276e-003,0.000000e+000,0,,0,
1524323324.073,,0.000000e+000,3.500028e+001,-8.669662e-006,0.000000e+000,2,9.099864e-001,0.000000e+000,,,,,,,,,,,,,,32,1,4.000000e+000,1.560211e-003,0.000000e+000,0,,0,
1524323362.251,,0.000000e+000,3.499872e+001,-8.451269e-006,0.000000e+000,2,9.060556e-001,0.000000e+000,,,,,,,,,,,,,,32,1,4.000000e+000,0.000000e+000,0.000000e+000,0,,0,
1524323400.467,,0.000000e+000,3.500028e+001,-8.312383e-006,0.000000e+000,2,9.061469e-001,0.000000e+000,,,,,,,,,,,,,,32,1,4.000000e+000,1.560211e-003,0.000000e+000,0,,0,
1524323438.178,,0.000000e+000,3.499872e+001,-8.134963e-006,0.000000e+000,2,9.004226e-001,0.000000e+000,,,,,,,,,,,,,,32,1,4.000000e+000,0.000000e+000,0.000000e+000,0,,0,
1524323476.321,,0.000000e+000,3.499911e+001,-8.007333e-006,0.000000e+000,2,8.981651e-001,0.000000e+000,,,,,,,,,,,,,,32,1,4.000000e+000,7.820129e-004,0.000000e+000,0,,0,
1524323514.359,,0.000000e+000,3.499872e+001,-7.851304e-006,0.000000e+000,2,8.965570e-001,0.000000e+000,,,,,,,,,,,,,,32,1,4.000000e+000,1.560211e-003,0.000000e+000,0,,0,
1524323552.442,,0.000000e+000,3.499872e+001,-7.699932e-006,0.000000e+000,2,8.996352e-001,0.000000e+000,,,,,,,,,,,,,,32,1,4.000000e+000,0.000000e+000,0.000000e+000,0,,0,
1524323590.397,,0.000000e+000,3.499911e+001,-7.541749e-006,0.000000e+000,2,8.949720e-001,0.000000e+000,,,,,,,,,,,,,,32,1,4.000000e+000,7.820129e-004,0.000000e+000,0,,0,
1524323628.580,,0.000000e+000,3.499872e+001,-7.443027e-006,0.000000e+000,2,8.926202e-001,0.000000e+000,,,,,,,,,,,,,,32,1,4.000000e+000,1.560211e-003,0.000000e+000,0,,0,
1524323666.168,,0.000000e+000,3.499950e+001,-7.314693e-006,0.000000e+000,2,8.937181e-001,0.000000e+000,,,,,,,,,,,,,,32,1,4.000000e+000,1.560211e-003,0.000000e+000,0,,0,
1524323703.431,,0.000000e+000,3.499950e+001,-7.185058e-006,0.000000e+000,2,8.901910e-001,0.000000e+000,,,,,,,,,,,,,,32,1,4.000000e+000,1.560211e-003,0.000000e+000,0,,0,
1524323741.127,,0.000000e+000,3.499989e+001,-7.047211e-006,0.000000e+000,2,8.880690e-001,0.000000e+000,,,,,,,,,,,,,,32,1,4.000000e+000,7.781982e-004,0.000000e+000,0,,0,
1524323779.732,,0.000000e+000,3.499833e+001,-6.906716e-006,0.000000e+000,2,8.872598e-001,0.000000e+000,,,,,,,,,,,,,,32,1,4.000000e+000,7.781982e-004,0.000000e+000,0,,0,
1524323817.398,,0.000000e+000,3.499989e+001,-6.820211e-006,0.000000e+000,2,8.852448e-001,0.000000e+000,,,,,,,,,,,,,,32,1,4.000000e+000,7.781982e-004,0.000000e+000,0,,0,
1524323855.441,,0.000000e+000,3.499989e+001,-6.750541e-006,0.000000e+000,2,8.849818e-001,0.000000e+000,,,,,,,,,,,,,,32,1,4.000000e+000,7.781982e-004,0.000000e+000,0,,0,
1524323893.574,,0.000000e+000,3.499911e+001,-6.595084e-006,0.000000e+000,2,8.852253e-001,0.000000e+000,,,,,,,,,,,,,,32,1,4.000000e+000,7.820129e-004,0.000000e+000,0,,0,
1524323931.750,,0.000000e+000,3.499950e+001,-6.493938e-006,0.000000e+000,2,8.794526e-001,0.000000e+000,,,,,,,,,,,,,,32,1,4.000000e+000,0.000000e+000,0.000000e+000,0,,0,
1524323969.410,,0.000000e+000,3.499833e+001,-6.399580e-006,0.000000e+000,2,8.786092e-001,0.000000e+000,,,,,,,,,,,,,,32,1,4.000000e+000,7.781982e-004,0.000000e+000,0,,0,
1524324007.543,,0.000000e+000,3.499872e+001,-6.259335e-006,0.000000e+000,2,8.768120e-001,0.000000e+000,,,,,,,,,,,,,,32,1,4.000000e+000,0.000000e+000,0.000000e+000,0,,0,
1524324045.569,,0.000000e+000,3.499950e+001,-6.196888e-006,0.000000e+000,2,8.753714e-001,0.000000e+000,,,,,,,,,,,,,,32,1,4.000000e+000,0.000000e+000,0.000000e+000,0,,0,
1524324083.784,,0.000000e+000,3.499911e+001,-6.094741e-006,0.000000e+000,2,8.760762e-001,0.000000e+000,,,,,,,,,,,,,,32,1,4.000000e+000,7.820129e-004,0.000000e+000,0,,0,
1524324121.918,,0.000000e+000,3.499911e+001,-5.975307e-006,0.000000e+000,2,8.652933e-001,0.000000e+000,,,,,,,,,,,,,,32,1,4.000000e+000,7.820129e-004,0.000000e+000,0,,0,
1524324160.081,,0.000000e+000,3.499911e+001,-5.877273e-006,0.000000e+000,2,8.706976e-001,0.000000e+000,,,,,,,,,,,,,,32,1,4.000000e+000,7.820129e-004,0.000000e+000,0,,0,
1524324198.674,,0.000000e+000,3.499794e+001,-5.767355e-006,0.000000e+000,2,8.652840e-001,0.000000e+000,,,,,,,,,,,,,,32,1,4.000000e+000,0.000000e+000,0.000000e+000,0,,0,
1524324236.792,,0.000000e+000,3.499911e+001,-5.691871e-006,0.000000e+000,2,8.618584e-001,0.000000e+000,,,,,,,,,,,,,,32,1,4.000000e+000,2.338409e-003,0.000000e+000,0,,0,
1524324275.150,,0.000000e+000,3.499911e+001,-5.644214e-006,0.000000e+000,2,8.635067e-001,0.000000e+000,,,,,,,,,,,,,,32,1,4.000000e+000,7.820129e-004,0.000000e+000,0,,0,
1524324313.498,,0.000000e+000,3.499911e+001,-5.522981e-006,0.000000e+000,2,8.582195e-001,0.000000e+000,,,,,,,,,,,,,,32,1,4.000000e+000,7.820129e-004,0.000000e+000,0,,0,
1524324351.561,,0.000000e+000,3.500145e+001,-5.405459e-006,0.000000e+000,2,8.554251e-001,0.000000e+000,,,,,,,,,,,,,,32,1,4.000000e+000,5.470276e-003,0.000000e+000,0,,0,
1524324389.551,,0.000000e+000,3.499872e+001,-5.369307e-006,0.000000e+000,2,8.550001e-001,0.000000e+000,,,,,,,,,,,,,,32,1,4.000000e+000,0.000000e+000,0.000000e+000,0,,0,
1524324427.829,,0.000000e+000,3.499754e+001,-5.235610e-006,0.000000e+000,2,8.486664e-001,0.000000e+000,,,,,,,,,,,,,,32,1,4.000000e+000,3.910065e-003,0.000000e+000,0,,0,
1524324465.807,,0.000000e+000,3.500068e+001,-5.212423e-006,0.000000e+000,2,8.523749e-001,0.000000e+000,,,,,,,,,,,,,,32,1,4.000000e+000,5.470276e-003,0.000000e+000,0,,0,
1524324504.176,,0.000000e+000,3.499989e+001,-5.088867e-006,0.000000e+000,2,8.442283e-001,0.000000e+000,,,,,,,,,,,,,,32,1,4.000000e+000,2.342224e-003,0.000000e+000,0,,0,
1524324541.926,,0.000000e+000,3.499911e+001,-5.046595e-006,0.000000e+000,2,8.337905e-001,0.000000e+000,,,,,,,,,,,,,,32,1,4.000000e+000,7.820129e-004,0.000000e+000,0,,0,
1524324579.918,,0.000000e+000,3.499911e+001,-4.952977e-006,0.000000e+000,2,8.417006e-001,0.000000e+000,,,,,,,,,,,,,,32,1,4.000000e+000,7.820129e-004,0.000000e+000,0,,0,
1524324618.948,,0.000000e+000,3.499911e+001,-4.878893e-006,0.000000e+000,2,8.348323e-001,0.000000e+000,,,,,,,,,,,,,,32,1,4.000000e+000,7.820129e-004,0.000000e+000,0,,0,
1524324657.094,,0.000000e+000,3.499833e+001,-4.793098e-006,0.000000e+000,2,8.291487e-001,0.000000e+000,,,,,,,,,,,,,,32,1,4.000000e+000,7.781982e-004,0.000000e+000,0,,0,
1524324695.617,,0.000000e+000,3.500067e+001,-4.758884e-006,0.000000e+000,2,8.337471e-001,0.000000e+000,,,,,,,,,,,,,,32,1,4.000000e+000,7.820129e-004,0.000000e+000,0,,0,
1524324734.101,,0.000000e+000,3.499872e+001,-4.645380e-006,0.000000e+000,2,8.275926e-001,0.000000e+000,,,,,,,,,,,,,,32,1,4.000000e+000,1.560211e-003,0.000000e+000,0,,0,
1524324771.249,,0.000000e+000,3.500028e+001,-4.634259e-006,0.000000e+000,2,8.274590e-001,0.000000e+000,,,,,,,,,,,,,,32,1,4.000000e+000,1.560211e-003,0.000000e+000,0,,0,
1524324809.189,,0.000000e+000,3.499833e+001,-4.517239e-006,0.000000e+000,2,8.287978e-001,0.000000e+000,,,,,,,,,,,,,,32,1,4.000000e+000,2.349854e-003,0.000000e+000,0,,0,
1524324846.960,,0.000000e+000,3.500185e+001,-4.460159e-006,0.000000e+000,2,8.164008e-001,0.000000e+000,,,,,,,,,,,,,,32,1,4.000000e+000,4.688263e-003,0.000000e+000,0,,0,
1524324884.378,,0.000000e+000,3.499911e+001,-4.451648e-006,0.000000e+000,2,8.243232e-001,0.000000e+000,,,,,,,,,,,,,,32,1,4.000000e+000,2.338409e-003,0.000000e+000,0,,0,
1524324922.358,,0.000000e+000,3.499950e+001,-4.325743e-006,0.000000e+000,2,8.208070e-001,0.000000e+000,,,,,,,,,,,,,,32,1,4.000000e+000,1.560211e-003,0.000000e+000,0,,0,
1524324961.084,,0.000000e+000,3.499911e+001,-4.307273e-006,0.000000e+000,2,8.172854e-001,0.000000e+000,,,,,,,,,,,,,,32,1,4.000000e+000,7.820129e-004,0.000000e+000,0,,0,
1524324998.637,,0.000000e+000,3.499989e+001,-4.217275e-006,0.000000e+000,2,8.160807e-001,0.000000e+000,,,,,,,,,,,,,,32,1,4.000000e+000,7.781982e-004,0.000000e+000,0,,0,
1524325036.442,,0.000000e+000,3.499989e+001,-4.161654e-006,0.000000e+000,2,8.119110e-001,0.000000e+000,,,,,,,,,,,,,,32,1,4.000000e+000,7.781982e-004,0.000000e+000,0,,0,
1524325074.030,,0.000000e+000,3.499872e+001,-4.142565e-006,0.000000e+000,2,8.143438e-001,0.000000e+000,,,,,,,,,,,,,,32,1,4.000000e+000,1.560211e-003,0.000000e+000,0,,0,
1524325112.311,,0.000000e+000,3.499715e+001,-4.049487e-006,0.000000e+000,2,8.055502e-001,0.000000e+000,,,,,,,,,,,,,,32,1,4.000000e+000,1.571655e-003,0.000000e+000,0,,0,
1524325150.264,,0.000000e+000,3.499989e+001,-3.990750e-006,0.000000e+000,2,7.978616e-001,0.000000e+000,,,,,,,,,,,,,,32,1,4.000000e+000,7.781982e-004,0.000000e+000,0,,0,
1524325187.915,,0.000000e+000,3.499911e+001,-3.916072e-006,0.000000e+000,2,7.915655e-001,0.000000e+000,,,,,,,,,,,,,,32,1,4.000000e+000,3.910065e-003,0.000000e+000,0,,0,
1524325225.910,,0.000000e+000,3.499911e+001,-3.839732e-006,0.000000e+000,2,7.920890e-001,0.000000e+000,,,,,,,,,,,,,,32,1,4.000000e+000,7.820129e-004,0.000000e+000,0,,0,
1524325263.886,,0.000000e+000,3.499833e+001,-3.788979e-006,0.000000e+000,2,7.810412e-001,0.000000e+000,,,,,,,,,,,,,,32,1,4.000000e+000,7.781982e-004,0.000000e+000,0,,0,
1524325301.674,,0.000000e+000,3.499911e+001,-3.762169e-006,0.000000e+000,2,7.909115e-001,0.000000e+000,,,,,,,,,,,,,,32,1,4.000000e+000,7.820129e-004,0.000000e+000,0,,0,
1524325339.899,,0.000000e+000,3.499833e+001,-3.705429e-006,0.000000e+000,2,7.803672e-001,0.000000e+000,,,,,,,,,,,,,,32,1,4.000000e+000,7.781982e-004,0.000000e+000,0,,0,
1524325377.685,,0.000000e+000,3.499911e+001,-3.596492e-006,0.000000e+000,2,7.780697e-001,0.000000e+000,,,,,,,,,,,,,,32,1,4.000000e+000,7.820129e-004,0.000000e+000,0,,0,
1524325415.548,,0.000000e+000,3.499950e+001,-3.551031e-006,0.000000e+000,2,7.768741e-001,0.000000e+000,,,,,,,,,,,,,,32,1,4.000000e+000,1.560211e-003,0.000000e+000,0,,0,
1524325453.524,,0.000000e+000,3.499950e+001,-3.516329e-006,0.000000e+000,2,7.618089e-001,0.000000e+000,,,,,,,,,,,,,,32,1,4.000000e+000,3.120422e-003,0.000000e+000,0,,0,
1524325491.909,,0.000000e+000,3.499872e+001,-3.495097e-006,0.000000e+000,2,7.725469e-001,0.000000e+000,,,,,,,,,,,,,,32,1,4.000000e+000,0.000000e+000,0.000000e+000,0,,0,
1524325530.042,,0.000000e+000,3.499911e+001,-3.443188e-006,0.000000e+000,2,7.685567e-001,0.000000e+000,,,,,,,,,,,,,,32,1,4.000000e+000,7.820129e-004,0.000000e+000,0,,0,
1524325567.840,,0.000000e+000,3.499871e+001,-3.387665e-006,0.000000e+000,2,7.614064e-001,0.000000e+000,,,,,,,,,,,,,,32,1,4.000000e+000,3.128052e-003,0.000000e+000,0,,0,
1524325606.263,,0.000000e+000,3.499872e+001,-3.346537e-006,0.000000e+000,2,7.635413e-001,0.000000e+000,,,,,,,,,,,,,,32,1,4.000000e+000,0.000000e+000,0.000000e+000,0,,0,
1524325643.916,,0.000000e+000,3.499989e+001,-3.300011e-006,0.000000e+000,2,7.566345e-001,0.000000e+000,,,,,,,,,,,,,,32,1,4.000000e+000,7.781982e-004,0.000000e+000,0,,0,
1524325681.767,,0.000000e+000,3.499950e+001,-3.260028e-006,0.000000e+000,2,7.480035e-001,0.000000e+000,,,,,,,,,,,,,,32,1,4.000000e+000,1.560211e-003,0.000000e+000,0,,0,
1524325719.670,,0.000000e+000,3.500028e+001,-3.176159e-006,0.000000e+000,2,7.494307e-001,0.000000e+000,,,,,,,,,,,,,,32,1,4.000000e+000,0.000000e+000,0.000000e+000,0,,0,
1524325757.968,,0.000000e+000,3.499989e+001,-3.175455e-006,0.000000e+000,2,7.383012e-001,0.000000e+000,,,,,,,,,,,,,,32,1,4.000000e+000,7.781982e-004,0.000000e+000,0,,0,
1524325795.926,,0.000000e+000,3.499950e+001,-3.092209e-006,0.000000e+000,2,7.388112e-001,0.000000e+000,,,,,,,,,,,,,,32,1,4.000000e+000,0.000000e+000,0.000000e+000,0,,0,
1524325833.397,,0.000000e+000,3.499833e+001,-3.039630e-006,0.000000e+000,2,7.366201e-001,0.000000e+000,,,,,,,,,,,,,,32,1,4.000000e+000,2.349854e-003,0.000000e+000,0,,0,
1524325871.577,,0.000000e+000,3.499872e+001,-3.018222e-006,0.000000e+000,2,7.359448e-001,0.000000e+000,,,,,,,,,,,,,,32,1,4.000000e+000,1.560211e-003,0.000000e+000,0,,0,
1524325909.710,,0.000000e+000,3.499950e+001,-3.006030e-006,0.000000e+000,2,7.344468e-001,0.000000e+000,,,,,,,,,,,,,,32,1,4.000000e+000,3.120422e-003,0.000000e+000,0,,0,
1524325947.061,,0.000000e+000,3.499911e+001,-2.929518e-006,0.000000e+000,2,7.241849e-001,0.000000e+000,,,,,,,,,,,,,,32,1,4.000000e+000,7.820129e-004,0.000000e+000,0,,0,
1524325985.466,,0.000000e+000,3.499950e+001,-2.891660e-006,0.000000e+000,2,7.293098e-001,0.000000e+000,,,,,,,,,,,,,,32,1,4.000000e+000,0.000000e+000,0.000000e+000,0,,0,
1524326023.689,,0.000000e+000,3.499950e+001,-2.799469e-006,0.000000e+000,2,7.115890e-001,0.000000e+000,,,,,,,,,,,,,,32,1,4.000000e+000,0.000000e+000,0.000000e+000,0,,0,
1524326061.805,,0.000000e+000,3.499911e+001,-2.755925e-006,0.000000e+000,2,7.021357e-001,0.000000e+000,,,,,,,,,,,,,,32,1,4.000000e+000,7.820129e-004,0.000000e+000,0,,0,
1524326101.018,,0.000000e+000,3.499833e+001,-2.746329e-006,0.000000e+000,2,7.180980e-001,0.000000e+000,,,,,,,,,,,,,,32,1,4.000000e+000,2.349854e-003,0.000000e+000,0,,0,
1524326139.069,,0.000000e+000,3.499989e+001,-2.716810e-006,0.000000e+000,2,7.051459e-001,0.000000e+000,,,,,,,,,,,,,,32,1,4.000000e+000,7.781982e-004,0.000000e+000,0,,0,
1524326177.022,,0.000000e+000,3.499872e+001,-2.669375e-006,0.000000e+000,2,6.948407e-001,0.000000e+000,,,,,,,,,,,,,,32,1,4.000000e+000,1.560211e-003,0.000000e+000,0,,0,
1524326214.810,,0.000000e+000,3.499833e+001,-2.610969e-006,0.000000e+000,2,6.937336e-001,0.000000e+000,,,,,,,,,,,,,,32,1,4.000000e+000,7.781982e-004,0.000000e+000,0,,0,
1524326252.518,,0.000000e+000,3.499911e+001,-2.559634e-006,0.000000e+000,2,6.900446e-001,0.000000e+000,,,,,,,,,,,,,,32,1,4.000000e+000,2.338409e-003,0.000000e+000,0,,0,
1524326290.673,,0.000000e+000,3.499950e+001,-2.523426e-006,0.000000e+000,2,6.913177e-001,0.000000e+000,,,,,,,,,,,,,,32,1,4.000000e+000,3.120422e-003,0.000000e+000,0,,0,
1524326328.761,,0.000000e+000,3.499989e+001,-2.490084e-006,0.000000e+000,2,6.757495e-001,0.000000e+000,,,,,,,,,,,,,,32,1,4.000000e+000,7.781982e-004,0.000000e+000,0,,0,
1524326366.762,,0.000000e+000,3.499872e+001,-2.424307e-006,0.000000e+000,2,6.550942e-001,0.000000e+000,,,,,,,,,,,,,,32,1,4.000000e+000,1.560211e-003,0.000000e+000,0,,0,
1524326404.950,,0.000000e+000,3.499794e+001,-2.392076e-006,0.000000e+000,2,6.663567e-001,0.000000e+000,,,,,,,,,,,,,,32,1,4.000000e+000,0.000000e+000,0.000000e+000,0,,0,
1524326442.933,,0.000000e+000,3.499950e+001,-2.348154e-006,0.000000e+000,2,6.498334e-001,0.000000e+000,,,,,,,,,,,,,,32,1,4.000000e+000,1.560211e-003,0.000000e+000,0,,0,
1524326480.679,,0.000000e+000,3.499872e+001,-2.339774e-006,0.000000e+000,2,6.563220e-001,0.000000e+000,,,,,,,,,,,,,,32,1,4.000000e+000,0.000000e+000,0.000000e+000,0,,0,
1524326518.094,,0.000000e+000,3.499872e+001,-2.349980e-006,0.000000e+000,2,6.645218e-001,0.000000e+000,,,,,,,,,,,,,,32,1,4.000000e+000,1.560211e-003,0.000000e+000,0,,0,
1524326556.702,,0.000000e+000,3.499989e+001,-2.256910e-006,0.000000e+000,2,6.462506e-001,0.000000e+000,,,,,,,,,,,,,,32,1,4.000000e+000,7.781982e-004,0.000000e+000,0,,0,
1524326594.808,,0.000000e+000,3.499950e+001,-2.238194e-006,0.000000e+000,2,6.507415e-001,0.000000e+000,,,,,,,,,,,,,,32,1,4.000000e+000,0.000000e+000,0.000000e+000,0,,0,
1524326632.946,,0.000000e+000,3.499911e+001,-2.184225e-006,0.000000e+000,2,6.408178e-001,0.000000e+000,,,,,,,,,,,,,,32,1,4.000000e+000,7.820129e-004,0.000000e+000,0,,0,
1524326671.099,,0.000000e+000,3.499950e+001,-2.138951e-006,0.000000e+000,2,6.114839e-001,0.000000e+000,,,,,,,,,,,,,,32,1,4.000000e+000,0.000000e+000,0.000000e+000,0,,0,
1524326708.764,,0.000000e+000,3.499872e+001,-2.162637e-006,0.000000e+000,2,6.442128e-001,0.000000e+000,,,,,,,,,,,,,,32,1,4.000000e+000,0.000000e+000,0.000000e+000,0,,0,
1524326747.360,,0.000000e+000,3.499911e+001,-2.139891e-006,0.000000e+000,2,6.337216e-001,0.000000e+000,,,,,,,,,,,,,,32,1,4.000000e+000,7.820129e-004,0.000000e+000,0,,0,
1524326785.481,,0.000000e+000,3.499911e+001,-2.074149e-006,0.000000e+000,2,6.165757e-001,0.000000e+000,,,,,,,,,,,,,,32,1,4.000000e+000,7.820129e-004,0.000000e+000,0,,0,
1524326823.614,,0.000000e+000,3.499989e+001,-2.008798e-006,0.000000e+000,2,6.056193e-001,0.000000e+000,,,,,,,,,,,,,,32,1,4.000000e+000,7.781982e-004,0.000000e+000,0,,0,
1524326861.789,,0.000000e+000,3.499872e+001,-1.966088e-006,0.000000e+000,2,5.951614e-001,0.000000e+000,,,,,,,,,,,,,,32,1,4.000000e+000,0.000000e+000,0.000000e+000,0,,0,
1524326899.352,,0.000000e+000,3.499950e+001,-1.963594e-006,0.000000e+000,2,5.982917e-001,0.000000e+000,,,,,,,,,,,,,,32,1,4.000000e+000,0.000000e+000,0.000000e+000,0,,0,
1524326937.513,,0.000000e+000,3.499950e+001,-1.937976e-006,0.000000e+000,2,5.852882e-001,0.000000e+000,,,,,,,,,,,,,,32,1,4.000000e+000,0.000000e+000,0.000000e+000,0,,0,
1524326975.641,,0.000000e+000,3.499989e+001,-1.924574e-006,0.000000e+000,2,5.914861e-001,0.000000e+000,,,,,,,,,,,,,,32,1,4.000000e+000,7.781982e-004,0.000000e+000,0,,0,
1524327013.314,,0.000000e+000,3.499989e+001,-1.883374e-006,0.000000e+000,2,5.860882e-001,0.000000e+000,,,,,,,,,,,,,,32,1,4.000000e+000,7.781982e-004,0.000000e+000,0,,0,
1524327050.667,,0.000000e+000,3.499872e+001,-1.819505e-006,0.000000e+000,2,5.560603e-001,0.000000e+000,,,,,,,,,,,,,,32,1,4.000000e+000,0.000000e+000,0.000000e+000,0,,0,
1524327088.788,,0.000000e+000,3.499989e+001,-1.827175e-006,0.000000e+000,2,5.563030e-001,0.000000e+000,,,,,,,,,,,,,,32,1,4.000000e+000,7.781982e-004,0.000000e+000,0,,0,
1524327126.933,,0.000000e+000,3.499911e+001,-1.743509e-006,0.000000e+000,2,5.278877e-001,0.000000e+000,,,,,,,,,,,,,,32,1,4.000000e+000,7.820129e-004,0.000000e+000,0,,0,
1524327165.051,,0.000000e+000,3.499793e+001,-1.745329e-006,0.000000e+000,2,5.351032e-001,0.000000e+000,,,,,,,,,,,,,,32,1,4.000000e+000,3.131866e-003,0.000000e+000,0,,0,
1524327202.934,,0.000000e+000,3.499950e+001,-1.712365e-006,0.000000e+000,2,5.152350e-001,0.000000e+000,,,,,,,,,,,,,,32,1,4.000000e+000,1.560211e-003,0.000000e+000,0,,0,
1524327241.967,,0.000000e+000,3.499950e+001,-1.651244e-006,0.000000e+000,2,5.257264e-001,0.000000e+000,,,,,,,,,,,,,,32,1,4.000000e+000,0.000000e+000,0.000000e+000,0,,0,
1524327279.888,,0.000000e+000,3.499793e+001,-1.638945e-006,0.000000e+000,2,4.939967e-001,0.000000e+000,,,,,,,,,,,,,,32,1,4.000000e+000,1.567841e-003,0.000000e+000,0,,0,
1524327318.676,,0.000000e+000,3.499676e+001,-1.625711e-006,0.000000e+000,2,5.177211e-001,0.000000e+000,,,,,,,,,,,,,,32,1,4.000000e+000,7.038116e-003,0.000000e+000,0,,0,
1524327356.549,,0.000000e+000,3.499872e+001,-1.590391e-006,0.000000e+000,2,4.805758e-001,0.000000e+000,,,,,,,,,,,,,,32,1,4.000000e+000,0.000000e+000,0.000000e+000,0,,0,
1524327394.890,,0.000000e+000,3.499950e+001,-1.564284e-006,0.000000e+000,2,4.782946e-001,0.000000e+000,,,,,,,,,,,,,,32,1,4.000000e+000,0.000000e+000,0.000000e+000,0,,0,
1524327432.533,,0.000000e+000,3.499872e+001,-1.519959e-006,0.000000e+000,2,4.712990e-001,0.000000e+000,,,,,,,,,,,,,,32,1,4.000000e+000,1.560211e-003,0.000000e+000,0,,0,
1524327470.783,,0.000000e+000,3.499950e+001,-1.473291e-006,0.000000e+000,2,4.548709e-001,0.000000e+000,,,,,,,,,,,,,,32,1,4.000000e+000,0.000000e+000,0.000000e+000,0,,0,
1524327508.804,,0.000000e+000,3.499950e+001,-1.481806e-006,0.000000e+000,2,4.622014e-001,0.000000e+000,,,,,,,,,,,,,,32,1,4.000000e+000,1.560211e-003,0.000000e+000,0,,0,
1524327546.934,,0.000000e+000,3.499911e+001,-1.444114e-006,0.000000e+000,2,4.385810e-001,0.000000e+000,,,,,,,,,,,,,,32,1,4.000000e+000,7.820129e-004,0.000000e+000,0,,0,
1524327585.072,,0.000000e+000,3.499950e+001,-1.425834e-006,0.000000e+000,2,4.181106e-001,0.000000e+000,,,,,,,,,,,,,,32,1,4.000000e+000,0.000000e+000,0.000000e+000,0,,0,
1524327622.323,,0.000000e+000,3.499677e+001,-1.384175e-006,0.000000e+000,2,4.233897e-001,0.000000e+000,,,,,,,,,,,,,,32,1,4.000000e+000,3.910065e-003,0.000000e+000,0,,0,
1524327660.026,,0.000000e+000,3.499950e+001,-1.353887e-006,0.000000e+000,2,4.121574e-001,0.000000e+000,,,,,,,,,,,,,,32,1,4.000000e+000,0.000000e+000,0.000000e+000,0,,0,
1524327698.151,,0.000000e+000,3.499911e+001,-1.379029e-006,0.000000e+000,2,4.075156e-001,0.000000e+000,,,,,,,,,,,,,,32,1,4.000000e+000,7.820129e-004,0.000000e+000,0,,0,
1524327736.467,,0.000000e+000,3.499911e+001,-1.288405e-006,0.000000e+000,2,3.615315e-001,0.000000e+000,,,,,,,,,,,,,,32,1,4.000000e+000,2.338409e-003,0.000000e+000,0,,0,
1524327774.440,,0.000000e+000,3.499950e+001,-1.277214e-006,0.000000e+000,2,3.719724e-001,0.000000e+000,,,,,,,,,,,,,,32,1,4.000000e+000,0.000000e+000,0.000000e+000,0,,0,
1524327812.871,,0.000000e+000,3.499911e+001,-1.242408e-006,0.000000e+000,2,3.505888e-001,0.000000e+000,,,,,,,,,,,,,,32,1,4.000000e+000,7.820129e-004,0.000000e+000,0,,0,
1524327850.714,,0.000000e+000,3.499911e+001,-1.194319e-006,0.000000e+000,2,3.375883e-001,0.000000e+000,,,,,,,,,,,,,,32,1,4.000000e+000,7.820129e-004,0.000000e+000,0,,0,
1524327888.842,,0.000000e+000,3.499911e+001,-1.201624e-006,0.000000e+000,2,3.320917e-001,0.000000e+000,,,,,,,,,,,,,,32,1,4.000000e+000,7.820129e-004,0.000000e+000,0,,0,
1524327927.412,,0.000000e+000,3.499989e+001,-1.198763e-006,0.000000e+000,2,3.271660e-001,0.000000e+000,,,,,,,,,,,,,,32,1,4.000000e+000,7.781982e-004,0.000000e+000,0,,0,
1524327964.990,,0.000000e+000,3.499989e+001,-1.183352e-006,0.000000e+000,2,3.269524e-001,0.000000e+000,,,,,,,,,,,,,,32,1,4.000000e+000,7.781982e-004,0.000000e+000,0,,0,
1524328003.126,,0.000000e+000,3.499911e+001,-1.122301e-006,0.000000e+000,2,2.856322e-001,0.000000e+000,,,,,,,,,,,,,,32,1,4.000000e+000,7.820129e-004,0.000000e+000,0,,0,
1524328041.319,,0.000000e+000,3.499872e+001,-1.075543e-006,0.000000e+000,2,2.398609e-001,0.000000e+000,,,,,,,,,,,,,,32,1,4.000000e+000,1.560211e-003,0.000000e+000,0,,0,
1524328079.727,,0.000000e+000,3.499911e+001,-1.057418e-006,0.000000e+000,2,2.535525e-001,0.000000e+000,,,,,,,,,,,,,,32,1,4.000000e+000,7.820129e-004,0.000000e+000,0,,0,
1524328117.043,,0.000000e+000,3.499950e+001,-1.037003e-006,0.000000e+000,2,2.224875e-001,0.000000e+000,,,,,,,,,,,,,,32,1,4.000000e+000,0.000000e+000,0.000000e+000,0,,0,
1524328155.391,,0.000000e+000,3.499950e+001,-9.928654e-007,0.000000e+000,2,1.961512e-001,0.000000e+000,,,,,,,,,,,,,,32,1,4.000000e+000,0.000000e+000,0.000000e+000,0,,0,
1524328193.154,,0.000000e+000,3.499911e+001,-9.985242e-007,0.000000e+000,2,1.969512e-001,0.000000e+000,,,,,,,,,,,,,,32,1,4.000000e+000,7.820129e-004,0.000000e+000,0,,0,
1524328230.852,,0.000000e+000,3.499950e+001,-9.724741e-007,0.000000e+000,2,2.097050e-001,0.000000e+000,,,,,,,,,,,,,,32,1,4.000000e+000,1.560211e-003,0.000000e+000,0,,0,
1524328269.272,,0.000000e+000,3.499911e+001,-9.465844e-007,0.000000e+000,2,1.593474e-001,0.000000e+000,,,,,,,,,,,,,,32,1,4.000000e+000,7.820129e-004,0.000000e+000,0,,0,
1524328307.168,,0.000000e+000,3.499950e+001,-9.335027e-007,0.000000e+000,2,1.549330e-001,0.000000e+000,,,,,,,,,,,,,,32,1,4.000000e+000,0.000000e+000,0.000000e+000,0,,0,
1524328344.593,,0.000000e+000,3.499911e+001,-9.147438e-007,0.000000e+000,2,1.329977e-001,0.000000e+000,,,,,,,,,,,,,,32,1,4.000000e+000,7.820129e-004,0.000000e+000,0,,0,
1524328382.184,,0.000000e+000,3.499950e+001,-9.267245e-007,0.000000e+000,2,1.019576e-001,0.000000e+000,,,,,,,,,,,,,,32,1,4.000000e+000,1.560211e-003,0.000000e+000,0,,0,
1524328420.282,,0.000000e+000,3.499950e+001,-8.405912e-007,0.000000e+000,2,3.797634e-002,0.000000e+000,,,,,,,,,,,,,,32,1,4.000000e+000,0.000000e+000,0.000000e+000,0,,0,
1524328458.465,,0.000000e+000,3.499989e+001,-8.313777e-007,0.000000e+000,2,2.645697e-002,0.000000e+000,,,,,,,,,,,,,,32,1,4.000000e+000,7.781982e-004,0.000000e+000,0,,0,
1524328496.568,,0.000000e+000,3.499872e+001,-7.879337e-007,0.000000e+000,2,0.000000e+000,0.000000e+000,,,,,,,,,,,,,,32,1,4.000000e+000,1.560211e-003,0.000000e+000,0,,0,
1524328534.701,,0.000000e+000,3.499911e+001,-8.044274e-007,0.000000e+000,2,0.000000e+000,0.000000e+000,,,,,,,,,,,,,,32,1,4.000000e+000,7.820129e-004,0.000000e+000,0,,0,
1524328572.829,,0.000000e+000,3.499833e+001,-7.488604e-007,0.000000e+000,2,0.000000e+000,0.000000e+000,,,,,,,,,,,,,,32,1,4.000000e+000,2.349854e-003,0.000000e+000,0,,0,
1524328610.092,,0.000000e+000,3.499950e+001,-7.503921e-007,0.000000e+000,2,0.000000e+000,0.000000e+000,,,,,,,,,,,,,,32,1,4.000000e+000,0.000000e+000,0.000000e+000,0,,0,
1524328647.783,,0.000000e+000,3.499950e+001,-7.184570e-007,0.000000e+000,2,0.000000e+000,0.000000e+000,,,,,,,,,,,,,,32,1,4.000000e+000,0.000000e+000,0.000000e+000,0,,0,
1524328685.896,,0.000000e+000,3.499833e+001,-6.834151e-007,0.000000e+000,2,0.000000e+000,0.000000e+000,,,,,,,,,,,,,,32,1,4.000000e+000,7.781982e-004,0.000000e+000,0,,0,
1524328723.949,,0.000000e+000,3.499872e+001,-6.890508e-007,0.000000e+000,2,0.000000e+000,0.000000e+000,,,,,,,,,,,,,,32,1,4.000000e+000,0.000000e+000,0.000000e+000,0,,0,
1524328762.175,,0.000000e+000,3.499794e+001,-6.575025e-007,0.000000e+000,2,0.000000e+000,0.000000e+000,,,,,,,,,,,,,,32,1,4.000000e+000,0.000000e+000,0.000000e+000,0,,0,
1524328799.925,,0.000000e+000,3.499950e+001,-6.303807e-007,0.000000e+000,2,0.000000e+000,0.000000e+000,,,,,,,,,,,,,,32,1,4.000000e+000,3.120422e-003,0.000000e+000,0,,0,
1524328837.876,,0.000000e+000,3.499911e+001,-5.956055e-007,0.000000e+000,2,0.000000e+000,0.000000e+000,,,,,,,,,,,,,,32,1,4.000000e+000,7.820129e-004,0.000000e+000,0,,0,
1524328875.996,,0.000000e+000,3.499911e+001,-5.646266e-007,0.000000e+000,2,0.000000e+000,0.000000e+000,,,,,,,,,,,,,,32,1,4.000000e+000,7.820129e-004,0.000000e+000,0,,0,
1524328914.079,,0.000000e+000,3.499950e+001,-5.637249e-007,0.000000e+000,2,0.000000e+000,0.000000e+000,,,,,,,,,,,,,,32,1,4.000000e+000,0.000000e+000,0.000000e+000,0,,0,
1524328952.115,,0.000000e+000,3.500067e+001,-5.814638e-007,0.000000e+000,2,0.000000e+000,0.000000e+000,,,,,,,,,,,,,,32,1,4.000000e+000,2.338409e-003,0.000000e+000,0,,0,
1524328991.408,,0.000000e+000,3.499833e+001,-5.608352e-007,0.000000e+000,2,0.000000e+000,0.000000e+000,,,,,,,,,,,,,,32,1,4.000000e+000,7.781982e-004,0.000000e+000,0,,0,
1524329030.291,,0.000000e+000,3.499911e+001,-4.914174e-007,0.000000e+000,2,0.000000e+000,0.000000e+000,,,,,,,,,,,,,,32,1,4.000000e+000,7.820129e-004,0.000000e+000,0,,0,
1524329068.219,,0.000000e+000,3.499989e+001,-3.914213e-007,0.000000e+000,2,0.000000e+000,0.000000e+000,,,,,,,,,,,,,,32,1,4.000000e+000,7.781982e-004,0.000000e+000,0,,0,
1524329105.817,,0.000000e+000,3.499989e+001,-4.628623e-007,0.000000e+000,2,0.000000e+000,0.000000e+000,,,,,,,,,,,,,,32,1,4.000000e+000,2.342224e-003,0.000000e+000,0,,0,
1524329143.413,,0.000000e+000,3.499911e+001,-3.842411e-007,0.000000e+000,2,0.000000e+000,0.000000e+000,,,,,,,,,,,,,,32,1,4.000000e+000,7.820129e-004,0.000000e+000,0,,0,
1524329181.621,,0.000000e+000,3.499950e+001,-4.197027e-007,0.000000e+000,2,0.000000e+000,0.000000e+000,,,,,,,,,,,,,,32,1,4.000000e+000,1.560211e-003,0.000000e+000,0,,0,
1524329219.516,,0.000000e+000,3.499950e+001,-3.684732e-007,0.000000e+000,2,0.000000e+000,0.000000e+000,,,,,,,,,,,,,,32,1,4.000000e+000,1.560211e-003,0.000000e+000,0,,0,
1524329257.292,,0.000000e+000,3.499911e+001,-3.474470e-007,0.000000e+000,2,0.000000e+000,0.000000e+000,,,,,,,,,,,,,,32,1,4.000000e+000,7.820129e-004,0.000000e+000,0,,0,
1524329296.137,,0.000000e+000,3.499872e+001,-2.781192e-007,0.000000e+000,2,0.000000e+000,0.000000e+000,,,,,,,,,,,,,,32,1,4.000000e+000,1.560211e-003,0.000000e+000,0,,0,
1524329334.200,,0.000000e+000,3.499989e+001,-2.923727e-007,0.000000e+000,2,0.000000e+000,0.000000e+000,,,,,,,,,,,,,,32,1,4.000000e+000,7.781982e-004,0.000000e+000,0,,0,
1524329372.466,,0.000000e+000,3.499715e+001,-2.711950e-007,0.000000e+000,2,0.000000e+000,0.000000e+000,,,,,,,,,,,,,,32,1,4.000000e+000,1.571655e-003,0.000000e+000,0,,0,
1524329410.159,,0.000000e+000,3.499872e+001,-2.249789e-007,0.000000e+000,2,0.000000e+000,0.000000e+000,,,,,,,,,,,,,,32,1,4.000000e+000,0.000000e+000,0.000000e+000,0,,0,
1524329448.282,,0.000000e+000,3.499911e+001,-2.360538e-007,0.000000e+000,2,0.000000e+000,0.000000e+000,,,,,,,,,,,,,,32,1,4.000000e+000,7.820129e-004,0.000000e+000,0,,0,
1524329486.465,,0.000000e+000,3.499950e+001,-2.984196e-007,0.000000e+000,2,0.000000e+000,0.000000e+000,,,,,,,,,,,,,,32,1,4.000000e+000,0.000000e+000,0.000000e+000,0,,0,
1524329524.578,,0.000000e+000,3.499989e+001,-2.485880e-007,0.000000e+000,2,0.000000e+000,0.000000e+000,,,,,,,,,,,,,,32,1,4.000000e+000,7.781982e-004,0.000000e+000,0,,0,
1524329562.721,,0.000000e+000,3.499950e+001,-2.274547e-007,0.000000e+000,2,0.000000e+000,0.000000e+000,,,,,,,,,,,,,,32,1,4.000000e+000,0.000000e+000,0.000000e+000,0,,0,
1524329600.822,,0.000000e+000,3.499872e+001,-2.496633e-007,0.000000e+000,2,0.000000e+000,0.000000e+000,,,,,,,,,,,,,,32,1,4.000000e+000,1.560211e-003,0.000000e+000,0,,0,
1524329638.940,,0.000000e+000,3.499950e+001,-2.119062e-007,0.000000e+000,2,0.000000e+000,0.000000e+000,,,,,,,,,,,,,,32,1,4.000000e+000,1.560211e-003,0.000000e+000,0,,0,
1524329677.088,,0.000000e+000,3.499872e+001,-1.496818e-007,0.000000e+000,2,0.000000e+000,0.000000e+000,,,,,,,,,,,,,,32,1,4.000000e+000,0.000000e+000,0.000000e+000,0,,0,
1524329714.874,,0.000000e+000,3.499911e+001,-1.695158e-007,0.000000e+000,2,0.000000e+000,0.000000e+000,,,,,,,,,,,,,,32,1,4.000000e+000,7.820129e-004,0.000000e+000,0,,0,
1524329754.547,,0.000000e+000,3.499872e+001,-1.444687e-007,0.000000e+000,2,0.000000e+000,0.000000e+000,,,,,,,,,,,,,,32,1,4.000000e+000,0.000000e+000,0.000000e+000,0,,0,
1524329792.212,,0.000000e+000,3.499911e+001,-9.773766e-008,0.000000e+000,2,0.000000e+000,0.000000e+000,,,,,,,,,,,,,,32,1,4.000000e+000,7.820129e-004,0.000000e+000,0,,0,
1524329829.880,,0.000000e+000,3.499950e+001,2.233242e-009,0.000000e+000,2,0.000000e+000,0.000000e+000,,,,,,,,,,,,,,32,1,4.000000e+000,1.560211e-003,0.000000e+000,0,,0,
1524329867.913,,0.000000e+000,3.499911e+001,-1.017725e-007,0.000000e+000,2,0.000000e+000,0.000000e+000,,,,,,,,,,,,,,32,1,4.000000e+000,7.820129e-004,0.000000e+000,0,,0,
1524329906.126,,0.000000e+000,3.499950e+001,-1.159884e-008,0.000000e+000,2,0.000000e+000,0.000000e+000,,,,,,,,,,,,,,32,1,4.000000e+000,1.560211e-003,0.000000e+000,0,,0,
1524329944.197,,0.000000e+000,3.499989e+001,-4.820436e-008,0.000000e+000,2,0.000000e+000,0.000000e+000,,,,,,,,,,,,,,32,1,4.000000e+000,7.781982e-004,0.000000e+000,0,,0,
1524329982.650,,0.000000e+000,3.499911e+001,5.029795e-008,0.000000e+000,2,0.000000e+000,0.000000e+000,,,,,,,,,,,,,,32,1,4.000000e+000,7.820129e-004,0.000000e+000,0,,0,
1524330020.468,,0.000000e+000,3.499911e+001,2.347338e-008,0.000000e+000,2,0.000000e+000,0.000000e+000,,,,,,,,,,,,,,32,1,4.000000e+000,7.820129e-004,0.000000e+000,0,,0,
1524330058.136,,0.000000e+000,3.499950e+001,-5.930792e-008,0.000000e+000,2,0.000000e+000,0.000000e+000,,,,,,,,,,,,,,32,1,4.000000e+000,0.000000e+000,0.000000e+000,0,,0,
1524330096.737,,0.000000e+000,3.499950e+001,6.686067e-008,0.000000e+000,2,0.000000e+000,0.000000e+000,,,,,,,,,,,,,,32,1,4.000000e+000,1.560211e-003,0.000000e+000,0,,0,
1524330134.847,,0.000000e+000,3.499911e+001,4.749905e-008,0.000000e+000,2,0.000000e+000,0.000000e+000,,,,,,,,,,,,,,32,1,4.000000e+000,7.820129e-004,0.000000e+000,0,,0,
1524330172.555,,0.000000e+000,3.499950e+001,1.699485e-008,0.000000e+000,2,0.000000e+000,0.000000e+000,,,,,,,,,,,,,,32,1,4.000000e+000,0.000000e+000,0.000000e+000,0,,0,
1524330211.096,,0.000000e+000,3.499950e+001,8.866810e-008,0.000000e+000,2,0.000000e+000,0.000000e+000,,,,,,,,,,,,,,32,1,4.000000e+000,0.000000e+000,0.000000e+000,0,,0,
1524330248.689,,0.000000e+000,3.499911e+001,7.103626e-008,0.000000e+000,2,0.000000e+000,0.000000e+000,,,,,,,,,,,,,,32,1,4.000000e+000,7.820129e-004,0.000000e+000,0,,0,
1524330286.802,,0.000000e+000,3.499911e+001,7.757571e-008,0.000000e+000,2,0.000000e+000,0.000000e+000,,,,,,,,,,,,,,32,1,4.000000e+000,7.820129e-004,0.000000e+000,0,,0,
1524330325.498,,0.000000e+000,3.499950e+001,1.422254e-007,0.000000e+000,2,0.000000e+000,0.000000e+000,,,,,,,,,,,,,,32,1,4.000000e+000,0.000000e+000,0.000000e+000,0,,0,
1524330363.676,,0.000000e+000,3.500068e+001,1.721364e-007,0.000000e+000,2,0.000000e+000,0.000000e+000,,,,,,,,,,,,,,32,1,4.000000e+000,5.470276e-003,0.000000e+000,0,,0,
1524330401.226,,0.000000e+000,3.499989e+001,2.440127e-007,0.000000e+000,2,0.000000e+000,0.000000e+000,,,,,,,,,,,,,,32,1,4.000000e+000,2.342224e-003,0.000000e+000,0,,0,
1524330438.814,,0.000000e+000,3.499989e+001,1.571941e-007,0.000000e+000,2,0.000000e+000,0.000000e+000,,,,,,,,,,,,,,32,1,4.000000e+000,7.781982e-004,0.000000e+000,0,,0,
1524330476.497,,0.000000e+000,3.499911e+001,2.073652e-007,0.000000e+000,2,0.000000e+000,0.000000e+000,,,,,,,,,,,,,,32,1,4.000000e+000,7.820129e-004,0.000000e+000,0,,0,
1524330514.545,,0.000000e+000,3.499911e+001,2.230204e-007,0.000000e+000,2,0.000000e+000,0.000000e+000,,,,,,,,,,,,,,32,1,4.000000e+000,7.820129e-004,0.000000e+000,0,,0,
1524330552.743,,0.000000e+000,3.499872e+001,3.222697e-007,0.000000e+000,2,0.000000e+000,0.000000e+000,,,,,,,,,,,,,,32,1,4.000000e+000,0.000000e+000,0.000000e+000,0,,0,
1524330590.854,,0.000000e+000,3.499872e+001,2.723046e-007,0.000000e+000,2,0.000000e+000,0.000000e+000,,,,,,,,,,,,,,32,1,4.000000e+000,1.560211e-003,0.000000e+000,0,,0,
1524330628.984,,0.000000e+000,3.499911e+001,2.251454e-007,0.000000e+000,2,0.000000e+000,0.000000e+000,,,,,,,,,,,,,,32,1,4.000000e+000,7.820129e-004,0.000000e+000,0,,0,
1524330666.640,,0.000000e+000,3.499833e+001,2.695587e-007,0.000000e+000,2,0.000000e+000,0.000000e+000,,,,,,,,,,,,,,32,1,4.000000e+000,7.781982e-004,0.000000e+000,0,,0,
1524330705.211,,0.000000e+000,3.499950e+001,3.176782e-007,0.000000e+000,2,0.000000e+000,0.000000e+000,,,,,,,,,,,,,,32,1,4.000000e+000,0.000000e+000,0.000000e+000,0,,0,
1524330743.339,,0.000000e+000,3.499911e+001,4.050345e-007,0.000000e+000,2,0.000000e+000,0.000000e+000,,,,,,,,,,,,,,32,1,4.000000e+000,7.820129e-004,0.000000e+000,0,,0,
1524330781.459,,0.000000e+000,3.499989e+001,2.938066e-007,0.000000e+000,2,0.000000e+000,0.000000e+000,,,,,,,,,,,,,,32,1,4.000000e+000,7.781982e-004,0.000000e+000,0,,0,
1524330819.537,,0.000000e+000,3.499989e+001,3.571871e-007,0.000000e+000,2,0.000000e+000,0.000000e+000,,,,,,,,,,,,,,32,1,4.000000e+000,7.781982e-004,0.000000e+000,0,,0,
1524330857.403,,0.000000e+000,3.499872e+001,3.889391e-007,0.000000e+000,2,0.000000e+000,0.000000e+000,,,,,,,,,,,,,,32,1,4.000000e+000,0.000000e+000,0.000000e+000,0,,0,
1524330895.498,,0.000000e+000,3.499950e+001,3.951515e-007,0.000000e+000,2,0.000000e+000,0.000000e+000,,,,,,,,,,,,,,32,1,4.000000e+000,0.000000e+000,0.000000e+000,0,,0,
1524330933.806,,0.000000e+000,3.499911e+001,4.185811e-007,0.000000e+000,2,0.000000e+000,0.000000e+000,,,,,,,,,,,,,,32,1,4.000000e+000,7.820129e-004,0.000000e+000,0,,0,
1524330971.965,,0.000000e+000,3.499911e+001,4.315854e-007,0.000000e+000,2,0.000000e+000,0.000000e+000,,,,,,,,,,,,,,32,1,4.000000e+000,7.820129e-004,0.000000e+000,0,,0,
1524331010.078,,0.000000e+000,3.499872e+001,4.272072e-007,0.000000e+000,2,0.000000e+000,0.000000e+000,,,,,,,,,,,,,,32,1,4.000000e+000,1.560211e-003,0.000000e+000,0,,0,
1524331048.061,,0.000000e+000,3.499833e+001,4.958038e-007,0.000000e+000,2,0.000000e+000,0.000000e+000,,,,,,,,,,,,,,32,1,4.000000e+000,7.781982e-004,0.000000e+000,0,,0,
1524331086.209,,0.000000e+000,3.499793e+001,4.286698e-007,0.000000e+000,2,0.000000e+000,0.000000e+000,,,,,,,,,,,,,,32,1,4.000000e+000,3.131866e-003,0.000000e+000,0,,0,
1524331124.337,,0.000000e+000,3.499989e+001,4.504506e-007,0.000000e+000,2,0.000000e+000,0.000000e+000,,,,,,,,,,,,,,32,1,4.000000e+000,7.781982e-004,0.000000e+000,0,,0,
1524331161.930,,0.000000e+000,3.500028e+001,5.491619e-007,0.000000e+000,2,0.000000e+000,0.000000e+000,,,,,,,,,,,,,,32,1,4.000000e+000,1.560211e-003,0.000000e+000,0,,0,
1524331199.425,,0.000000e+000,3.499911e+001,5.061344e-007,0.000000e+000,2,0.000000e+000,0.000000e+000,,,,,,,,,,,,,,32,1,4.000000e+000,7.820129e-004,0.000000e+000,0,,0,
1524331237.901,,0.000000e+000,3.499872e+001,5.212039e-007,0.000000e+000,2,0.000000e+000,0.000000e+000,,,,,,,,,,,,,,32,1,4.000000e+000,1.560211e-003,0.000000e+000,0,,0,
1524331275.021,,0.000000e+000,3.499911e+001,4.813874e-007,0.000000e+000,2,0.000000e+000,0.000000e+000,,,,,,,,,,,,,,32,1,4.000000e+000,7.820129e-004,0.000000e+000,0,,0,
1524331313.145,,0.000000e+000,3.499989e+001,5.665680e-007,0.000000e+000,2,0.000000e+000,0.000000e+000,,,,,,,,,,,,,,32,1,4.000000e+000,7.781982e-004,0.000000e+000,0,,0,
1524331350.858,,0.000000e+000,3.499911e+001,5.718805e-007,0.000000e+000,2,0.000000e+000,0.000000e+000,,,,,,,,,,,,,,32,1,4.000000e+000,2.338409e-003,0.000000e+000,0,,0,
1524331388.968,,0.000000e+000,3.500028e+001,5.547876e-007,0.000000e+000,2,0.000000e+000,0.000000e+000,,,,,,,,,,,,,,32,1,4.000000e+000,3.120422e-003,0.000000e+000,0,,0,
1524331427.101,,0.000000e+000,3.499950e+001,5.894703e-007,0.000000e+000,2,0.000000e+000,0.000000e+000,,,,,,,,,,,,,,32,1,4.000000e+000,0.000000e+000,0.000000e+000,0,,0,
1524331465.144,,0.000000e+000,3.499950e+001,5.704476e-007,0.000000e+000,2,0.000000e+000,0.000000e+000,,,,,,,,,,,,,,32,1,4.000000e+000,0.000000e+000,0.000000e+000,0,,0,
1524331503.347,,0.000000e+000,3.499911e+001,6.249848e-007,0.000000e+000,2,0.000000e+000,0.000000e+000,,,,,,,,,,,,,,32,1,4.000000e+000,7.820129e-004,0.000000e+000,0,,0,
1524331541.458,,0.000000e+000,3.499872e+001,6.299741e-007,0.000000e+000,2,0.000000e+000,0.000000e+000,,,,,,,,,,,,,,32,1,4.000000e+000,0.000000e+000,0.000000e+000,0,,0,
1524331579.891,,0.000000e+000,3.499950e+001,6.243090e-007,0.000000e+000,2,0.000000e+000,0.000000e+000,,,,,,,,,,,,,,32,1,4.000000e+000,1.560211e-003,0.000000e+000,0,,0,
1524331617.724,,0.000000e+000,3.499950e+001,6.563216e-007,0.000000e+000,2,0.000000e+000,0.000000e+000,,,,,,,,,,,,,,32,1,4.000000e+000,1.560211e-003,0.000000e+000,0,,0,
1524331655.800,,0.000000e+000,3.499872e+001,6.681426e-007,0.000000e+000,2,0.000000e+000,0.000000e+000,,,,,,,,,,,,,,32,1,4.000000e+000,1.560211e-003,0.000000e+000,0,,0,
1524331694.278,,0.000000e+000,3.499950e+001,7.646148e-007,0.000000e+000,2,0.000000e+000,0.000000e+000,,,,,,,,,,,,,,32,1,4.000000e+000,0.000000e+000,0.000000e+000,0,,0,
1524331731.966,,0.000000e+000,3.499989e+001,7.510070e-007,0.000000e+000,2,0.000000e+000,0.000000e+000,,,,,,,,,,,,,,32,1,4.000000e+000,7.781982e-004,0.000000e+000,0,,0,
1524331770.734,,0.000000e+000,3.499793e+001,7.492533e-007,0.000000e+000,2,0.000000e+000,0.000000e+000,,,,,,,,,,,,,,32,1,4.000000e+000,3.131866e-003,0.000000e+000,0,,0,
1524331809.127,,0.000000e+000,3.499911e+001,7.225058e-007,0.000000e+000,2,0.000000e+000,0.000000e+000,,,,,,,,,,,,,,32,1,4.000000e+000,7.820129e-004,0.000000e+000,0,,0,
1524331847.047,,0.000000e+000,3.499989e+001,7.499102e-007,0.000000e+000,2,0.000000e+000,0.000000e+000,,,,,,,,,,,,,,32,1,4.000000e+000,7.781982e-004,0.000000e+000,0,,0,
1524331885.183,,0.000000e+000,3.499911e+001,7.610954e-007,0.000000e+000,2,0.000000e+000,0.000000e+000,,,,,,,,,,,,,,32,1,4.000000e+000,7.820129e-004,0.000000e+000,0,,0,
1524331923.296,,0.000000e+000,3.499872e+001,7.612228e-007,0.000000e+000,2,0.000000e+000,0.000000e+000,,,,,,,,,,,,,,32,1,4.000000e+000,0.000000e+000,0.000000e+000,0,,0,
1524331961.454,,0.000000e+000,3.499872e+001,7.592824e-007,0.000000e+000,2,0.000000e+000,0.000000e+000,,,,,,,,,,,,,,32,1,4.000000e+000,0.000000e+000,0.000000e+000,0,,0,
1524331999.595,,0.000000e+000,3.499950e+001,7.973156e-007,0.000000e+000,2,0.000000e+000,0.000000e+000,,,,,,,,,,,,,,32,1,4.000000e+000,0.000000e+000,0.000000e+000,0,,0,
1524332037.253,,0.000000e+000,3.499833e+001,8.552406e-007,0.000000e+000,2,8.064432e-002,0.000000e+000,,,,,,,,,,,,,,32,1,4.000000e+000,7.781982e-004,0.000000e+000,0,,0,
1524332075.318,,0.000000e+000,3.499911e+001,8.112505e-007,0.000000e+000,2,0.000000e+000,0.000000e+000,,,,,,,,,,,,,,32,1,4.000000e+000,7.820129e-004,0.000000e+000,0,,0,
1524332113.511,,0.000000e+000,3.499989e+001,8.439312e-007,0.000000e+000,2,1.674590e-002,0.000000e+000,,,,,,,,,,,,,,32,1,4.000000e+000,7.781982e-004,0.000000e+000,0,,0,
1524332151.957,,0.000000e+000,3.500028e+001,8.493931e-007,0.000000e+000,2,9.664473e-003,0.000000e+000,,,,,,,,,,,,,,32,1,4.000000e+000,0.000000e+000,0.000000e+000,0,,0,
1524332190.102,,0.000000e+000,3.499911e+001,8.785291e-007,0.000000e+000,2,7.036167e-002,0.000000e+000,,,,,,,,,,,,,,32,1,4.000000e+000,7.820129e-004,0.000000e+000,0,,0,
1524332227.900,,0.000000e+000,3.499911e+001,8.940701e-007,0.000000e+000,2,7.076599e-002,0.000000e+000,,,,,,,,,,,,,,32,1,4.000000e+000,7.820129e-004,0.000000e+000,0,,0,
1524332265.564,,0.000000e+000,3.499911e+001,9.332495e-007,0.000000e+000,2,9.286583e-002,0.000000e+000,,,,,,,,,,,,,,32,1,4.000000e+000,7.820129e-004,0.000000e+000,0,,0,
1524332303.994,,0.000000e+000,3.499950e+001,8.820718e-007,0.000000e+000,2,8.991195e-002,0.000000e+000,,,,,,,,,,,,,,32,1,4.000000e+000,1.560211e-003,0.000000e+000,0,,0,
1524332342.995,,0.000000e+000,3.500028e+001,9.239425e-007,0.000000e+000,2,9.106269e-002,0.000000e+000,,,,,,,,,,,,,,32,1,4.000000e+000,3.120422e-003,0.000000e+000,0,,0,
1524332381.490,,0.000000e+000,3.499989e+001,8.690635e-007,0.000000e+000,2,6.907252e-002,0.000000e+000,,,,,,,,,,,,,,32,1,4.000000e+000,7.781982e-004,0.000000e+000,0,,0,
1524332419.643,,0.000000e+000,3.499911e+001,9.400040e-007,0.000000e+000,2,1.148220e-001,0.000000e+000,,,,,,,,,,,,,,32,1,4.000000e+000,7.820129e-004,0.000000e+000,0,,0,
1524332457.321,,0.000000e+000,3.499950e+001,9.117148e-007,0.000000e+000,2,8.072426e-002,0.000000e+000,,,,,,,,,,,,,,32,1,4.000000e+000,0.000000e+000,0.000000e+000,0,,0,
1524332495.897,,0.000000e+000,3.499911e+001,9.187684e-007,0.000000e+000,2,1.265798e-001,0.000000e+000,,,,,,,,,,,,,,32,1,4.000000e+000,7.820129e-004,0.000000e+000,0,,0,
1524332533.592,,0.000000e+000,3.499950e+001,9.687018e-007,0.000000e+000,2,1.630851e-001,0.000000e+000,,,,,,,,,,,,,,32,1,4.000000e+000,0.000000e+000,0.000000e+000,0,,0,
1524332572.160,,0.000000e+000,3.499950e+001,9.435383e-007,0.000000e+000,2,1.321109e-001,0.000000e+000,,,,,,,,,,,,,,32,1,4.000000e+000,0.000000e+000,0.000000e+000,0,,0,
1524332609.866,,0.000000e+000,3.499950e+001,9.328483e-007,0.000000e+000,2,1.332655e-001,0.000000e+000,,,,,,,,,,,,,,32,1,4.000000e+000,0.000000e+000,0.000000e+000,0,,0,
1524332648.029,,0.000000e+000,3.499950e+001,9.846849e-007,0.000000e+000,2,1.725304e-001,0.000000e+000,,,,,,,,,,,,,,32,1,4.000000e+000,1.560211e-003,0.000000e+000,0,,0,
1524332686.150,,0.000000e+000,3.499911e+001,1.012153e-006,0.000000e+000,2,2.073731e-001,0.000000e+000,,,,,,,,,,,,,,32,1,4.000000e+000,7.820129e-004,0.000000e+000,0,,0,
1524332724.738,,0.000000e+000,3.499989e+001,1.013508e-006,0.000000e+000,2,1.818283e-001,0.000000e+000,,,,,,,,,,,,,,32,1,4.000000e+000,7.781982e-004,0.000000e+000,0,,0,
1524332762.848,,0.000000e+000,3.499872e+001,1.010829e-006,0.000000e+000,2,1.889222e-001,0.000000e+000,,,,,,,,,,,,,,32,1,4.000000e+000,0.000000e+000,0.000000e+000,0,,0,
1524332800.566,,0.000000e+000,3.499989e+001,1.018919e-006,0.000000e+000,2,2.056111e-001,0.000000e+000,,,,,,,,,,,,,,32,1,4.000000e+000,7.781982e-004,0.000000e+000,0,,0,
1524332839.139,,0.000000e+000,3.499911e+001,1.035153e-006,0.000000e+000,2,2.148723e-001,0.000000e+000,,,,,,,,,,,,,,32,1,4.000000e+000,7.820129e-004,0.000000e+000,0,,0,
1524332876.855,,0.000000e+000,3.499950e+001,1.077682e-006,0.000000e+000,2,2.415526e-001,0.000000e+000,,,,,,,,,,,,,,32,1,4.000000e+000,0.000000e+000,0.000000e+000,0,,0,
1524332914.981,,0.000000e+000,3.499872e+001,1.067451e-006,0.000000e+000,2,1.999579e-001,0.000000e+000,,,,,,,,,,,,,,32,1,4.000000e+000,0.000000e+000,0.000000e+000,0,,0,
1524332953.104,,0.000000e+000,3.499911e+001,1.055325e-006,0.000000e+000,2,2.227313e-001,0.000000e+000,,,,,,,,,,,,,,32,1,4.000000e+000,7.820129e-004,0.000000e+000,0,,0,
1524332991.242,,0.000000e+000,3.499950e+001,1.100488e-006,0.000000e+000,2,2.694595e-001,0.000000e+000,,,,,,,,,,,,,,32,1,4.000000e+000,0.000000e+000,0.000000e+000,0,,0,
1524333029.280,,0.000000e+000,3.499911e+001,1.077941e-006,0.000000e+000,2,2.465122e-001,0.000000e+000,,,,,,,,,,,,,,32,1,4.000000e+000,7.820129e-004,0.000000e+000,0,,0,
1524333067.453,,0.000000e+000,3.499989e+001,1.126016e-006,0.000000e+000,2,2.596494e-001,0.000000e+000,,,,,,,,,,,,,,32,1,4.000000e+000,7.781982e-004,0.000000e+000,0,,0,
1524333106.078,,0.000000e+000,3.499911e+001,1.143920e-006,0.000000e+000,2,2.783643e-001,0.000000e+000,,,,,,,,,,,,,,32,1,4.000000e+000,7.820129e-004,0.000000e+000,0,,0,
1524333144.629,,0.000000e+000,3.499911e+001,1.170506e-006,0.000000e+000,2,2.898120e-001,0.000000e+000,,,,,,,,,,,,,,32,1,4.000000e+000,7.820129e-004,0.000000e+000,0,,0,
1524333182.737,,0.000000e+000,3.500067e+001,1.322823e-006,0.000000e+000,2,3.734457e-001,0.000000e+000,,,,,,,,,,,,,,32,1,4.000000e+000,2.338409e-003,0.000000e+000,0,,0,
1524333208.107,,0.000000e+000,3.499950e+001,1.145153e-006,0.000000e+000,2,2.828625e-001,0.000000e+000,,,,,,,,,,,,,,32,1,4.000000e+000,0.000000e+000,0.000000e+000,0,,0,