File: Input_All/MFn1_TRMac_36K_0.04Kmin_VRMde_35K.dc.dat
[Header]
TITLE,MPMS DC Measurement
BYAPP,MPMS Measurement,2.1,Summary
FILEOPENTIME, 1524355798.650000 4/21/2018, 6:09:58 PM

INFO, APPNAME, MPMS MultiVu Application, Revision 1.61,  Build 082

INFO, NAME, MFn1
INFO, WEIGHT, 1.000
INFO, AREA, 1.000
INFO, LENGTH, 1.000
INFO, SHAPE, 0
INFO, COMMENT,
INFO, SEQUENCE FILE: TRMac_36K_0.04Kmin_VRMde_35K.seq


INFO, BACKGROUND DATA FILE:, None


STARTUPAXIS,X,4,LINEAR,AUTO,0.000000,0.000000
STARTUPAXIS,Y1,5,LINEAR,AUTO,0.000000,0.000000


STARTUPGROUP,Longitudinal
FIELDGROUP,Longitudinal,1,2,3,4,5,6,7,8,9,15,16,17,18,27,28
FIELDGROUP,Transverse,1,2,3,4,10,11,12,13,14,19,20,21,22,27,28

PLOT_APPEARANCE,ALL,HORZ_GRID_ON,VERT_GRID_ON,MARKERS_AND_LINES

[Data]
Time,Comment,Field (Oe),Temperature (K),Long Moment (emu),Long Scan Std Dev,Long Algorithm,Long Reg Fit,Long Percent Error (%),Trans Moment (emu),Trans Scan Std Dev,Trans Algorithm,Trans Reg Fit,Trans Percent Error (%),Long Moment [w/o ABS] (emu),Long Scan Std Dev [w/o ABS],Long Reg Fit [w/o ABS],Long Percent Error [w/o ABS] (%),Trans Moment [w/o ABS] (emu),Trans Scan Std Dev [w/o ABS],Trans Reg Fit [w/o ABS],Trans Percent Error [w/o ABS] (%),Points per Scan,Scans per Measurement,Scan Length (cm),Delta Temp (K),Rot Position (deg),Error,EC Comp. Running,Using ABS,
1524355798.647,,0.000000e+000,3.499598e+001,-2.353964e-005,0.000000e+000,2,9.681669e-001,0.000000e+000,,,,,,,,,,,,,,32,1,4.000000e+000,7.781982e-004,0.000000e+000,0,,0,
1524355836.165,,0.000000e+000,3.499715e+001,-2.201758e-005,0.000000e+000,2,9.633413e-001,0.000000e+000,,,,,,,,,,,,,,32,1,4.000000e+000,0.000000e+000,0.000000e+000,0,,0,
1524355873.666,,0.000000e+000,3.499911e+001,-2.076098e-005,0.000000e+000,2,9.603924e-001,0.000000e+000,,,,,,,,,,,,,,32,1,4.000000e+000,7.820129e-004,0.000000e+000,0,,0,
1524355911.762,,0.000000e+000,3.499872e+001,-1.975820e-005,0.000000e+000,2,9.581612e-001,0.000000e+000,,,,,,,,,,,,,,32,1,4.000000e+000,1.560211e-003,0.000000e+000,0,,0,
1524355949.835,,0.000000e+000,3.499872e+001,-1.898320e-005,0.000000e+000,2,9.565051e-001,0.000000e+000,,,,,,,,,,,,,,32,1,4.000000e+000,1.560211e-003,0.000000e+000,0,,0,
1524355987.638,,0.000000e+000,3.499793e+001,-1.829824e-005,0.000000e+000,2,9.536202e-001,0.000000e+000,,,,,,,,,,,,,,32,1,4.000000e+000,1.567841e-003,0.000000e+000,0,,0,
1524356025.911,,0.000000e+000,3.499833e+001,-1.772429e-005,0.000000e+000,2,9.530961e-001,0.000000e+000,,,,,,,,,,,,,,32,1,4.000000e+000,7.781982e-004,0.000000e+000,0,,0,
1524356063.636,,0.000000e+000,3.499793e+001,-1.718011e-005,0.000000e+000,2,9.530052e-001,0.000000e+000,,,,,,,,,,,,,,32,1,4.000000e+000,1.567841e-003,0.000000e+000,0,,0,
1524356101.574,,0.000000e+000,3.499833e+001,-1.665242e-005,0.000000e+000,2,9.502425e-001,0.000000e+000,,,,,,,,,,,,,,32,1,4.000000e+000,2.349854e-003,0.000000e+000,0,,0,
1524356139.632,,0.000000e+000,3.499911e+001,-1.622897e-005,0.000000e+000,2,9.490016e-001,0.000000e+000,,,,,,,,,,,,,,32,1,4.000000e+000,7.820129e-004,0.000000e+000,0,,0,
1524356177.680,,0.000000e+000,3.499911e+001,-1.586603e-005,0.000000e+000,2,9.488543e-001,0.000000e+000,,,,,,,,,,,,,,32,1,4.000000e+000,2.338409e-003,0.000000e+000,0,,0,
1524356215.751,,0.000000e+000,3.499833e+001,-1.548123e-005,0.000000e+000,2,9.467236e-001,0.000000e+000,,,,,,,,,,,,,,32,1,4.000000e+000,2.349854e-003,0.000000e+000,0,,0,
1524356253.966,,0.000000e+000,3.499833e+001,-1.518076e-005,0.000000e+000,2,9.467354e-001,0.000000e+000,,,,,,,,,,,,,,32,1,4.000000e+000,7.781982e-004,0.000000e+000,0,,0,
1524356292.027,,0.000000e+000,3.499911e+001,-1.486151e-005,0.000000e+000,2,9.457368e-001,0.000000e+000,,,,,,,,,,,,,,32,1,4.000000e+000,2.338409e-003,0.000000e+000,0,,0,
1524356329.948,,0.000000e+000,3.499833e+001,-1.451271e-005,0.000000e+000,2,9.418521e-001,0.000000e+000,,,,,,,,,,,,,,32,1,4.000000e+000,2.349854e-003,0.000000e+000,0,,0,
1524356368.018,,0.000000e+000,3.499833e+001,-1.425528e-005,0.000000e+000,2,9.428607e-001,0.000000e+000,,,,,,,,,,,,,,32,1,4.000000e+000,7.781982e-004,0.000000e+000,0,,0,
1524356407.116,,0.000000e+000,3.499833e+001,-1.401157e-005,0.000000e+000,2,9.428343e-001,0.000000e+000,,,,,,,,,,,,,,32,1,4.000000e+000,7.781982e-004,0.000000e+000,0,,0,
1524356445.659,,0.000000e+000,3.499872e+001,-1.367097e-005,0.000000e+000,2,9.400811e-001,0.000000e+000,,,,,,,,,,,,,,32,1,4.000000e+000,0.000000e+000,0.000000e+000,0,,0,
1524356484.530,,0.000000e+000,3.499872e+001,-1.350281e-005,0.000000e+000,2,9.405530e-001,0.000000e+000,,,,,,,,,,,,,,32,1,4.000000e+000,0.000000e+000,0.000000e+000,0,,0,
1524356522.080,,0.000000e+000,3.499833e+001,-1.326050e-005,0.000000e+000,2,9.394992e-001,0.000000e+000,,,,,,,,,,,,,,32,1,4.000000e+000,7.781982e-004,0.000000e+000,0,,0,
1524356560.114,,0.000000e+000,3.499833e+001,-1.308114e-005,0.000000e+000,2,9.365389e-001,0.000000e+000,,,,,,,,,,,,,,32,1,4.000000e+000,7.781982e-004,0.000000e+000,0,,0,
1524356598.462,,0.000000e+000,3.499793e+001,-1.287752e-005,0.000000e+000,2,9.391519e-001,0.000000e+000,,,,,,,,,,,,,,32,1,4.000000e+000,1.567841e-003,0.000000e+000,0,,0,
1524356636.200,,0.000000e+000,3.499794e+001,-1.267197e-005,0.000000e+000,2,9.347127e-001,0.000000e+000,,,,,,,,,,,,,,32,1,4.000000e+000,0.000000e+000,0.000000e+000,0,,0,
1524356674.470,,0.000000e+000,3.499911e+001,-1.252329e-005,0.000000e+000,2,9.358320e-001,0.000000e+000,,,,,,,,,,,,,,32,1,4.000000e+000,7.820129e-004,0.000000e+000,0,,0,
1524356712.573,,0.000000e+000,3.499872e+001,-1.222678e-005,0.000000e+000,2,9.333567e-001,0.000000e+000,,,,,,,,,,,,,,32,1,4.000000e+000,1.560211e-003,0.000000e+000,0,,0,
1524356750.644,,0.000000e+000,3.499833e+001,-1.207859e-005,0.000000e+000,2,9.318981e-001,0.000000e+000,,,,,,,,,,,,,,32,1,4.000000e+000,2.349854e-003,0.000000e+000,0,,0,
1524356788.697,,0.000000e+000,3.499872e+001,-1.193910e-005,0.000000e+000,2,9.332363e-001,0.000000e+000,,,,,,,,,,,,,,32,1,4.000000e+000,1.560211e-003,0.000000e+000,0,,0,
1524356826.837,,0.000000e+000,3.499833e+001,-1.179474e-005,0.000000e+000,2,9.306371e-001,0.000000e+000,,,,,,,,,,,,,,32,1,4.000000e+000,7.781982e-004,0.000000e+000,0,,0,
1524356865.475,,0.000000e+000,3.499911e+001,-1.161247e-005,0.000000e+000,2,9.305102e-001,0.000000e+000,,,,,,,,,,,,,,32,1,4.000000e+000,2.338409e-003,0.000000e+000,0,,0,
1524356904.161,,0.000000e+000,3.499872e+001,-1.145953e-005,0.000000e+000,2,9.304842e-001,0.000000e+000,,,,,,,,,,,,,,32,1,4.000000e+000,0.000000e+000,0.000000e+000,0,,0,
1524356941.607,,0.000000e+000,3.499715e+001,-1.132223e-005,0.000000e+000,2,9.291760e-001,0.000000e+000,,,,,,,,,,,,,,32,1,4.000000e+000,3.128052e-003,0.000000e+000,0,,0,
1524356979.365,,0.000000e+000,3.499794e+001,-1.119395e-005,0.000000e+000,2,9.304466e-001,0.000000e+000,,,,,,,,,,,,,,32,1,4.000000e+000,0.000000e+000,0.000000e+000,0,,0,
1524357016.618,,0.000000e+000,3.499950e+001,-1.101611e-005,0.000000e+000,2,9.249305e-001,0.000000e+000,,,,,,,,,,,,,,32,1,4.000000e+000,1.560211e-003,0.000000e+000,0,,0,
1524357054.701,,0.000000e+000,3.499911e+001,-1.093686e-005,0.000000e+000,2,9.253966e-001,0.000000e+000,,,,,,,,,,,,,,32,1,4.000000e+000,7.820129e-004,0.000000e+000,0,,0,
1524357092.771,,0.000000e+000,3.499833e+001,-1.075526e-005,0.000000e+000,2,9.264468e-001,0.000000e+000,,,,,,,,,,,,,,32,1,4.000000e+000,7.781982e-004,0.000000e+000,0,,0,
1524357130.869,,0.000000e+000,3.499950e+001,-1.064993e-005,0.000000e+000,2,9.229749e-001,0.000000e+000,,,,,,,,,,,,,,32,1,4.000000e+000,1.560211e-003,0.000000e+000,0,,0,
1524357168.670,,0.000000e+000,3.499754e+001,-1.051742e-005,0.000000e+000,2,9.207958e-001,0.000000e+000,,,,,,,,,,,,,,32,1,4.000000e+000,2.349854e-003,0.000000e+000,0,,0,
1524357206.141,,0.000000e+000,3.499872e+001,-1.043561e-005,0.000000e+000,2,9.239799e-001,0.000000e+000,,,,,,,,,,,,,,32,1,4.000000e+000,1.560211e-003,0.000000e+000,0,,0,
1524357243.749,,0.000000e+000,3.499872e+001,-1.032838e-005,0.000000e+000,2,9.229236e-001,0.000000e+000,,,,,,,,,,,,,,32,1,4.000000e+000,1.560211e-003,0.000000e+000,0,,0,
1524357281.814,,0.000000e+000,3.499833e+001,-1.018700e-005,0.000000e+000,2,9.209583e-001,0.000000e+000,,,,,,,,,,,,,,32,1,4.000000e+000,7.781982e-004,0.000000e+000,0,,0,
1524357319.245,,0.000000e+000,3.499872e+001,-1.002906e-005,0.000000e+000,2,9.203569e-001,0.000000e+000,,,,,,,,,,,,,,32,1,4.000000e+000,1.560211e-003,0.000000e+000,0,,0,
1524357357.133,,0.000000e+000,3.499911e+001,-9.985954e-006,0.000000e+000,2,9.184588e-001,0.000000e+000,,,,,,,,,,,,,,32,1,4.000000e+000,7.820129e-004,0.000000e+000,0,,0,
1524357395.776,,0.000000e+000,3.499715e+001,-9.874590e-006,0.000000e+000,2,9.186155e-001,0.000000e+000,,,,,,,,,,,,,,32,1,4.000000e+000,1.571655e-003,0.000000e+000,0,,0,
1524357433.304,,0.000000e+000,3.499833e+001,-9.788730e-006,0.000000e+000,2,9.170973e-001,0.000000e+000,,,,,,,,,,,,,,32,1,4.000000e+000,7.781982e-004,0.000000e+000,0,,0,
1524357471.329,,0.000000e+000,3.499911e+001,-9.670964e-006,0.000000e+000,2,9.170265e-001,0.000000e+000,,,,,,,,,,,,,,32,1,4.000000e+000,7.820129e-004,0.000000e+000,0,,0,
1524357509.092,,0.000000e+000,3.499833e+001,-9.547549e-006,0.000000e+000,2,9.162773e-001,0.000000e+000,,,,,,,,,,,,,,32,1,4.000000e+000,7.781982e-004,0.000000e+000,0,,0,
1524357548.065,,0.000000e+000,3.499872e+001,-9.458038e-006,0.000000e+000,2,9.130540e-001,0.000000e+000,,,,,,,,,,,,,,32,1,4.000000e+000,1.560211e-003,0.000000e+000,0,,0,
1524357585.041,,0.000000e+000,3.499872e+001,-9.397867e-006,0.000000e+000,2,9.141471e-001,0.000000e+000,,,,,,,,,,,,,,32,1,4.000000e+000,0.000000e+000,0.000000e+000,0,,0,
1524357623.122,,0.000000e+000,3.499911e+001,-9.286865e-006,0.000000e+000,2,9.134862e-001,0.000000e+000,,,,,,,,,,,,,,32,1,4.000000e+000,7.820129e-004,0.000000e+000,0,,0,
1524357661.190,,0.000000e+000,3.499872e+001,-9.188019e-006,0.000000e+000,2,9.121928e-001,0.000000e+000,,,,,,,,,,,,,,32,1,4.000000e+000,1.560211e-003,0.000000e+000,0,,0,
1524357699.060,,0.000000e+000,3.499833e+001,-9.093507e-006,0.000000e+000,2,9.093064e-001,0.000000e+000,,,,,,,,,,,,,,32,1,4.000000e+000,7.781982e-004,0.000000e+000,0,,0,
1524357737.301,,0.000000e+000,3.499872e+001,-8.995183e-006,0.000000e+000,2,9.100022e-001,0.000000e+000,,,,,,,,,,,,,,32,1,4.000000e+000,1.560211e-003,0.000000e+000,0,,0,
1524357775.019,,0.000000e+000,3.499911e+001,-8.951578e-006,0.000000e+000,2,9.111701e-001,0.000000e+000,,,,,,,,,,,,,,32,1,4.000000e+000,7.820129e-004,0.000000e+000,0,,0,
1524357813.117,,0.000000e+000,3.499911e+001,-8.885274e-006,0.000000e+000,2,9.105852e-001,0.000000e+000,,,,,,,,,,,,,,32,1,4.000000e+000,2.338409e-003,0.000000e+000,0,,0,
1524357850.382,,0.000000e+000,3.499794e+001,-8.754739e-006,0.000000e+000,2,9.071416e-001,0.000000e+000,,,,,,,,,,,,,,32,1,4.000000e+000,0.000000e+000,0.000000e+000,0,,0,
1524357887.815,,0.000000e+000,3.499794e+001,-8.710631e-006,0.000000e+000,2,9.089687e-001,0.000000e+000,,,,,,,,,,,,,,32,1,4.000000e+000,0.000000e+000,0.000000e+000,0,,0,
1524357926.544,,0.000000e+000,3.499950e+001,-8.584202e-006,0.000000e+000,2,9.085857e-001,0.000000e+000,,,,,,,,,,,,,,32,1,4.000000e+000,3.120422e-003,0.000000e+000,0,,0,
1524357964.379,,0.000000e+000,3.500067e+001,-8.509652e-006,0.000000e+000,2,8.981771e-001,0.000000e+000,,,,,,,,,,,,,,32,1,4.000000e+000,3.910065e-003,0.000000e+000,0,,0,
1524358001.985,,0.000000e+000,3.499872e+001,-8.476264e-006,0.000000e+000,2,9.086722e-001,0.000000e+000,,,,,,,,,,,,,,32,1,4.000000e+000,0.000000e+000,0.000000e+000,0,,0,
1524358040.763,,0.000000e+000,3.500145e+001,-8.379233e-006,0.000000e+000,2,9.035156e-001,0.000000e+000,,,,,,,,,,,,,,32,1,4.000000e+000,7.781982e-004,0.000000e+000,0,,0,
1524358078.621,,0.000000e+000,3.499872e+001,-8.279831e-006,0.000000e+000,2,9.034048e-001,0.000000e+000,,,,,,,,,,,,,,32,1,4.000000e+000,1.560211e-003,0.000000e+000,0,,0,
1524358116.696,,0.000000e+000,3.500067e+001,-8.201157e-006,0.000000e+000,2,9.030511e-001,0.000000e+000,,,,,,,,,,,,,,32,1,4.000000e+000,7.820129e-004,0.000000e+000,0,,0,
1524358154.484,,0.000000e+000,3.499950e+001,-8.094124e-006,0.000000e+000,2,9.046785e-001,0.000000e+000,,,,,,,,,,,,,,32,1,4.000000e+000,0.000000e+000,0.000000e+000,0,,0,
1524358191.872,,0.000000e+000,3.499911e+001,-8.093031e-006,0.000000e+000,2,9.040182e-001,0.000000e+000,,,,,,,,,,,,,,32,1,4.000000e+000,7.820129e-004,0.000000e+000,0,,0,
1524358229.948,,0.000000e+000,3.499872e+001,-8.030735e-006,0.000000e+000,2,9.040742e-001,0.000000e+000,,,,,,,,,,,,,,32,1,4.000000e+000,0.000000e+000,0.000000e+000,0,,0,
1524358267.921,,0.000000e+000,3.499872e+001,-7.979625e-006,0.000000e+000,2,9.020753e-001,0.000000e+000,,,,,,,,,,,,,,32,1,4.000000e+000,0.000000e+000,0.000000e+000,0,,0,
1524358306.059,,0.000000e+000,3.499833e+001,-7.869808e-006,0.000000e+000,2,8.996662e-001,0.000000e+000,,,,,,,,,,,,,,32,1,4.000000e+000,7.781982e-004,0.000000e+000,0,,0,
1524358344.137,,0.000000e+000,3.499950e+001,-7.811557e-006,0.000000e+000,2,8.957299e-001,0.000000e+000,,,,,,,,,,,,,,32,1,4.000000e+000,0.000000e+000,0.000000e+000,0,,0,
1524358381.470,,0.000000e+000,3.499832e+001,-7.745982e-006,0.000000e+000,2,8.944994e-001,0.000000e+000,,,,,,,,,,,,,,32,1,4.000000e+000,3.910065e-003,0.000000e+000,0,,0,
1524358418.966,,0.000000e+000,3.499950e+001,-7.693267e-006,0.000000e+000,2,8.970140e-001,0.000000e+000,,,,,,,,,,,,,,32,1,4.000000e+000,0.000000e+000,0.000000e+000,0,,0,
1524358457.051,,0.000000e+000,3.499989e+001,-7.667912e-006,0.000000e+000,2,8.940895e-001,0.000000e+000,,,,,,,,,,,,,,32,1,4.000000e+000,7.781982e-004,0.000000e+000,0,,0,
1524358494.867,,0.000000e+000,3.499911e+001,-7.555048e-006,0.000000e+000,2,8.930778e-001,0.000000e+000,,,,,,,,,,,,,,32,1,4.000000e+000,7.820129e-004,0.000000e+000,0,,0,
1524358532.607,,0.000000e+000,3.499911e+001,-7.480789e-006,0.000000e+000,2,8.940967e-001,0.000000e+000,,,,,,,,,,,,,,32,1,4.000000e+000,2.338409e-003,0.000000e+000,0,,0,
1524358570.633,,0.000000e+000,3.499950e+001,-7.456645e-006,0.000000e+000,2,8.912728e-001,0.000000e+000,,,,,,,,,,,,,,32,1,4.000000e+000,0.000000e+000,0.000000e+000,0,,0,
1524358608.206,,0.000000e+000,3.499911e+001,-7.371948e-006,0.000000e+000,2,8.913667e-001,0.000000e+000,,,,,,,,,,,,,,32,1,4.000000e+000,7.820129e-004,0.000000e+000,0,,0,
1524358646.294,,0.000000e+000,3.499677e+001,-7.335761e-006,0.000000e+000,2,8.934499e-001,0.000000e+000,,,,,,,,,,,,,,32,1,4.000000e+000,5.470276e-003,0.000000e+000,0,,0,
1524358684.325,,0.000000e+000,3.499911e+001,-7.267033e-006,0.000000e+000,2,8.913953e-001,0.000000e+000,,,,,,,,,,,,,,32,1,4.000000e+000,7.820129e-004,0.000000e+000,0,,0,
1524358722.520,,0.000000e+000,3.499833e+001,-7.198381e-006,0.000000e+000,2,8.889924e-001,0.000000e+000,,,,,,,,,,,,,,32,1,4.000000e+000,7.781982e-004,0.000000e+000,0,,0,
1524358760.583,,0.000000e+000,3.499872e+001,-7.106743e-006,0.000000e+000,2,8.887196e-001,0.000000e+000,,,,,,,,,,,,,,32,1,4.000000e+000,1.560211e-003,0.000000e+000,0,,0,
1524358799.241,,0.000000e+000,3.499911e+001,-7.112249e-006,0.000000e+000,2,8.874269e-001,0.000000e+000,,,,,,,,,,,,,,32,1,4.000000e+000,7.820129e-004,0.000000e+000,0,,0,
1524358836.869,,0.000000e+000,3.499911e+001,-7.042157e-006,0.000000e+000,2,8.881239e-001,0.000000e+000,,,,,,,,,,,,,,32,1,4.000000e+000,2.338409e-003,0.000000e+000,0,,0,
1524358874.855,,0.000000e+000,3.500106e+001,-6.977280e-006,0.000000e+000,2,8.860857e-001,0.000000e+000,,,,,,,,,,,,,,32,1,4.000000e+000,3.128052e-003,0.000000e+000,0,,0,
1524358912.928,,0.000000e+000,3.499754e+001,-6.922113e-006,0.000000e+000,2,8.849105e-001,0.000000e+000,,,,,,,,,,,,,,32,1,4.000000e+000,2.349854e-003,0.000000e+000,0,,0,
1524358950.999,,0.000000e+000,3.499793e+001,-6.886211e-006,0.000000e+000,2,8.810284e-001,0.000000e+000,,,,,,,,,,,,,,32,1,4.000000e+000,1.567841e-003,0.000000e+000,0,,0,
1524358989.039,,0.000000e+000,3.499793e+001,-6.815567e-006,0.000000e+000,2,8.803164e-001,0.000000e+000,,,,,,,,,,,,,,32,1,4.000000e+000,1.567841e-003,0.000000e+000,0,,0,
1524359027.147,,0.000000e+000,3.499833e+001,-6.776873e-006,0.000000e+000,2,8.829850e-001,0.000000e+000,,,,,,,,,,,,,,32,1,4.000000e+000,2.349854e-003,0.000000e+000,0,,0,
1524359065.345,,0.000000e+000,3.499872e+001,-6.733858e-006,0.000000e+000,2,8.835689e-001,0.000000e+000,,,,,,,,,,,,,,32,1,4.000000e+000,0.000000e+000,0.000000e+000,0,,0,
1524359103.248,,0.000000e+000,3.499950e+001,-6.654632e-006,0.000000e+000,2,8.791943e-001,0.000000e+000,,,,,,,,,,,,,,32,1,4.000000e+000,0.000000e+000,0.000000e+000,0,,0,
1524359141.324,,0.000000e+000,3.499911e+001,-6.608292e-006,0.000000e+000,2,8.795645e-001,0.000000e+000,,,,,,,,,,,,,,32,1,4.000000e+000,7.820129e-004,0.000000e+000,0,,0,
1524359178.897,,0.000000e+000,3.500028e+001,-6.539799e-006,0.000000e+000,2,8.743132e-001,0.000000e+000,,,,,,,,,,,,,,32,1,4.000000e+000,1.560211e-003,0.000000e+000,0,,0,
1524359216.965,,0.000000e+000,3.499989e+001,-6.482889e-006,0.000000e+000,2,8.752080e-001,0.000000e+000,,,,,,,,,,,,,,32,1,4.000000e+000,7.781982e-004,0.000000e+000,0,,0,
1524359254.808,,0.000000e+000,3.499950e+001,-6.454826e-006,0.000000e+000,2,8.790581e-001,0.000000e+000,,,,,,,,,,,,,,32,1,4.000000e+000,0.000000e+000,0.000000e+000,0,,0,
1524359292.766,,0.000000e+000,3.499950e+001,-6.406134e-006,0.000000e+000,2,8.781434e-001,0.000000e+000,,,,,,,,,,,,,,32,1,4.000000e+000,0.000000e+000,0.000000e+000,0,,0,
1524359330.542,,0.000000e+000,3.499793e+001,-6.369424e-006,0.000000e+000,2,8.754250e-001,0.000000e+000,,,,,,,,,,,,,,32,1,4.000000e+000,1.567841e-003,0.000000e+000,0,,0,
1524359368.405,,0.000000e+000,3.499950e+001,-6.303135e-006,0.000000e+000,2,8.740748e-001,0.000000e+000,,,,,,,,,,,,,,32,1,4.000000e+000,0.000000e+000,0.000000e+000,0,,0,
1524359406.478,,0.000000e+000,3.499911e+001,-6.290043e-006,0.000000e+000,2,8.708006e-001,0.000000e+000,,,,,,,,,,,,,,32,1,4.000000e+000,7.820129e-004,0.000000e+000,0,,0,
1524359444.093,,0.000000e+000,3.499911e+001,-6.267133e-006,0.000000e+000,2,8.775201e-001,0.000000e+000,,,,,,,,,,,,,,32,1,4.000000e+000,7.820129e-004,0.000000e+000,0,,0,
1524359482.056,,0.000000e+000,3.499872e+001,-6.205898e-006,0.000000e+000,2,8.744927e-001,0.000000e+000,,,,,,,,,,,,,,32,1,4.000000e+000,0.000000e+000,0.000000e+000,0,,0,
1524359520.459,,0.000000e+000,3.499872e+001,-6.137205e-006,0.000000e+000,2,8.760612e-001,0.000000e+000,,,,,,,,,,,,,,32,1,4.000000e+000,0.000000e+000,0.000000e+000,0,,0,
1524359558.765,,0.000000e+000,3.499950e+001,-6.097825e-006,0.000000e+000,2,8.699335e-001,0.000000e+000,,,,,,,,,,,,,,32,1,4.000000e+000,0.000000e+000,0.000000e+000,0,,0,
1524359597.731,,0.000000e+000,3.499872e+001,-6.078293e-006,0.000000e+000,2,8.698477e-001,0.000000e+000,,,,,,,,,,,,,,32,1,4.000000e+000,1.560211e-003,0.000000e+000,0,,0,
1524359634.731,,0.000000e+000,3.499833e+001,-6.040609e-006,0.000000e+000,2,8.687453e-001,0.000000e+000,,,,,,,,,,,,,,32,1,4.000000e+000,7.781982e-004,0.000000e+000,0,,0,
1524359672.777,,0.000000e+000,3.499911e+001,-5.976115e-006,0.000000e+000,2,8.604368e-001,0.000000e+000,,,,,,,,,,,,,,32,1,4.000000e+000,7.820129e-004,0.000000e+000,0,,0,
1524359710.347,,0.000000e+000,3.499950e+001,-5.899513e-006,0.000000e+000,2,8.550301e-001,0.000000e+000,,,,,,,,,,,,,,32,1,4.000000e+000,1.560211e-003,0.000000e+000,0,,0,
1524359748.925,,0.000000e+000,3.499950e+001,-5.872663e-006,0.000000e+000,2,8.623391e-001,0.000000e+000,,,,,,,,,,,,,,32,1,4.000000e+000,0.000000e+000,0.000000e+000,0,,0,
1524359786.366,,0.000000e+000,3.499911e+001,-5.849943e-006,0.000000e+000,2,8.601976e-001,0.000000e+000,,,,,,,,,,,,,,32,1,4.000000e+000,7.820129e-004,0.000000e+000,0,,0,
1524359824.449,,0.000000e+000,3.499872e+001,-5.829142e-006,0.000000e+000,2,8.703228e-001,0.000000e+000,,,,,,,,,,,,,,32,1,4.000000e+000,1.560211e-003,0.000000e+000,0,,0,
1524359862.074,,0.000000e+000,3.499911e+001,-5.767595e-006,0.000000e+000,2,8.607996e-001,0.000000e+000,,,,,,,,,,,,,,32,1,4.000000e+000,7.820129e-004,0.000000e+000,0,,0,
1524359900.405,,0.000000e+000,3.499911e+001,-5.736324e-006,0.000000e+000,2,8.575017e-001,0.000000e+000,,,,,,,,,,,,,,32,1,4.000000e+000,7.820129e-004,0.000000e+000,0,,0,
1524359938.261,,0.000000e+000,3.499872e+001,-5.686728e-006,0.000000e+000,2,8.601416e-001,0.000000e+000,,,,,,,,,,,,,,32,1,4.000000e+000,0.000000e+000,0.000000e+000,0,,0,
1524359975.666,,0.000000e+000,3.499872e+001,-5.651736e-006,0.000000e+000,2,8.528682e-001,0.000000e+000,,,,,,,,,,,,,,32,1,4.000000e+000,0.000000e+000,0.000000e+000,0,,0,
1524360013.064,,0.000000e+000,3.499950e+001,-5.630853e-006,0.000000e+000,2,8.594193e-001,0.000000e+000,,,,,,,,,,,,,,32,1,4.000000e+000,0.000000e+000,0.000000e+000,0,,0,
1524360051.055,,0.000000e+000,3.499833e+001,-5.643338e-006,0.000000e+000,2,8.672121e-001,0.000000e+000,,,,,,,,,,,,,,32,1,4.000000e+000,7.781982e-004,0.000000e+000,0,,0,
1524360089.643,,0.000000e+000,3.499950e+001,-5.528881e-006,0.000000e+000,2,8.588663e-001,0.000000e+000,,,,,,,,,,,,,,32,1,4.000000e+000,0.000000e+000,0.000000e+000,0,,0,
1524360127.211,,0.000000e+000,3.499989e+001,-5.489510e-006,0.000000e+000,2,8.571411e-001,0.000000e+000,,,,,,,,,,,,,,32,1,4.000000e+000,7.781982e-004,0.000000e+000,0,,0,
1524360165.509,,0.000000e+000,3.499911e+001,-5.432710e-006,0.000000e+000,2,8.543868e-001,0.000000e+000,,,,,,,,,,,,,,32,1,4.000000e+000,7.820129e-004,0.000000e+000,0,,0,
1524360203.734,,0.000000e+000,3.499950e+001,-5.407902e-006,0.000000e+000,2,8.507412e-001,0.000000e+000,,,,,,,,,,,,,,32,1,4.000000e+000,0.000000e+000,0.000000e+000,0,,0,
1524360241.785,,0.000000e+000,3.499950e+001,-5.402856e-006,0.000000e+000,2,8.550465e-001,0.000000e+000,,,,,,,,,,,,,,32,1,4.000000e+000,0.000000e+000,0.000000e+000,0,,0,
1524360279.918,,0.000000e+000,3.499911e+001,-5.353423e-006,0.000000e+000,2,8.504454e-001,0.000000e+000,,,,,,,,,,,,,,32,1,4.000000e+000,7.820129e-004,0.000000e+000,0,,0,
1524360317.974,,0.000000e+000,3.499911e+001,-5.369207e-006,0.000000e+000,2,8.576392e-001,0.000000e+000,,,,,,,,,,,,,,32,1,4.000000e+000,7.820129e-004,0.000000e+000,0,,0,
1524360355.989,,0.000000e+000,3.499911e+001,-5.267266e-006,0.000000e+000,2,8.483797e-001,0.000000e+000,,,,,,,,,,,,,,32,1,4.000000e+000,7.820129e-004,0.000000e+000,0,,0,
1524360393.715,,0.000000e+000,3.499911e+001,-5.254002e-006,0.000000e+000,2,8.492279e-001,0.000000e+000,,,,,,,,,,,,,,32,1,4.000000e+000,2.338409e-003,0.000000e+000,0,,0,
1524360431.190,,0.000000e+000,3.499872e+001,-5.222029e-006,0.000000e+000,2,8.497444e-001,0.000000e+000,,,,,,,,,,,,,,32,1,4.000000e+000,1.560211e-003,0.000000e+000,0,,0,
1524360469.191,,0.000000e+000,3.499872e+001,-5.194584e-006,0.000000e+000,2,8.464829e-001,0.000000e+000,,,,,,,,,,,,,,32,1,4.000000e+000,0.000000e+000,0.000000e+000,0,,0,
1524360507.216,,0.000000e+000,3.499911e+001,-5.147485e-006,0.000000e+000,2,8.437425e-001,0.000000e+000,,,,,,,,,,,,,,32,1,4.000000e+000,7.820129e-004,0.000000e+000,0,,0,
1524360545.310,,0.000000e+000,3.499911e+001,-5.106854e-006,0.000000e+000,2,8.445770e-001,0.000000e+000,,,,,,,,,,,,,,32,1,4.000000e+000,7.820129e-004,0.000000e+000,0,,0,
1524360583.008,,0.000000e+000,3.499911e+001,-5.063361e-006,0.000000e+000,2,8.418533e-001,0.000000e+000,,,,,,,,,,,,,,32,1,4.000000e+000,7.820129e-004,0.000000e+000,0,,0,
1524360621.493,,0.000000e+000,3.500028e+001,-5.037688e-006,0.000000e+000,2,8.437022e-001,0.000000e+000,,,,,,,,,,,,,,32,1,4.000000e+000,0.000000e+000,0.000000e+000,0,,0,
1524360658.984,,0.000000e+000,3.499911e+001,-5.028187e-006,0.000000e+000,2,8.425559e-001,0.000000e+000,,,,,,,,,,,,,,32,1,4.000000e+000,7.820129e-004,0.000000e+000,0,,0,
1524360697.019,,0.000000e+000,3.499911e+001,-4.977785e-006,0.000000e+000,2,8.371561e-001,0.000000e+000,,,,,,,,,,,,,,32,1,4.000000e+000,7.820129e-004,0.000000e+000,0,,0,
1524360735.117,,0.000000e+000,3.499950e+001,-4.932419e-006,0.000000e+000,2,8.377348e-001,0.000000e+000,,,,,,,,,,,,,,32,1,4.000000e+000,0.000000e+000,0.000000e+000,0,,0,
1524360773.178,,0.000000e+000,3.499872e+001,-4.908034e-006,0.000000e+000,2,8.368792e-001,0.000000e+000,,,,,,,,,,,,,,32,1,4.000000e+000,1.560211e-003,0.000000e+000,0,,0,
1524360811.476,,0.000000e+000,3.499950e+001,-4.847259e-006,0.000000e+000,2,8.350927e-001,0.000000e+000,,,,,,,,,,,,,,32,1,4.000000e+000,1.560211e-003,0.000000e+000,0,,0,
1524360849.439,,0.000000e+000,3.499911e+001,-4.874801e-006,0.000000e+000,2,8.411931e-001,0.000000e+000,,,,,,,,,,,,,,32,1,4.000000e+000,7.820129e-004,0.000000e+000,0,,0,
1524360887.354,,0.000000e+000,3.500028e+001,-4.862177e-006,0.000000e+000,2,8.322089e-001,0.000000e+000,,,,,,,,,,,,,,32,1,4.000000e+000,1.560211e-003,0.000000e+000,0,,0,
1524360925.407,,0.000000e+000,3.500028e+001,-4.768931e-006,0.000000e+000,2,8.315998e-001,0.000000e+000,,,,,,,,,,,,,,32,1,4.000000e+000,1.560211e-003,0.000000e+000,0,,0,
1524360963.481,,0.000000e+000,3.499950e+001,-4.761611e-006,0.000000e+000,2,8.315232e-001,0.000000e+000,,,,,,,,,,,,,,32,1,4.000000e+000,1.560211e-003,0.000000e+000,0,,0,
1524361001.526,,0.000000e+000,3.499833e+001,-4.748226e-006,0.000000e+000,2,8.299268e-001,0.000000e+000,,,,,,,,,,,,,,32,1,4.000000e+000,2.349854e-003,0.000000e+000,0,,0,
1524361039.609,,0.000000e+000,3.499754e+001,-4.736090e-006,0.000000e+000,2,8.306381e-001,0.000000e+000,,,,,,,,,,,,,,32,1,4.000000e+000,2.349854e-003,0.000000e+000,0,,0,
1524361077.615,,0.000000e+000,3.499872e+001,-4.726669e-006,0.000000e+000,2,8.262672e-001,0.000000e+000,,,,,,,,,,,,,,32,1,4.000000e+000,0.000000e+000,0.000000e+000,0,,0,
1524361115.723,,0.000000e+000,3.499950e+001,-4.597635e-006,0.000000e+000,2,8.211301e-001,0.000000e+000,,,,,,,,,,,,,,32,1,4.000000e+000,0.000000e+000,0.000000e+000,0,,0,
1524361153.728,,0.000000e+000,3.499911e+001,-4.585223e-006,0.000000e+000,2,8.249314e-001,0.000000e+000,,,,,,,,,,,,,,32,1,4.000000e+000,7.820129e-004,0.000000e+000,0,,0,
1524361192.371,,0.000000e+000,3.499989e+001,-4.572330e-006,0.000000e+000,2,8.228353e-001,0.000000e+000,,,,,,,,,,,,,,32,1,4.000000e+000,7.781982e-004,0.000000e+000,0,,0,
1524361229.370,,0.000000e+000,3.499950e+001,-4.618717e-006,0.000000e+000,2,8.278838e-001,0.000000e+000,,,,,,,,,,,,,,32,1,4.000000e+000,0.000000e+000,0.000000e+000,0,,0,
1524361267.693,,0.000000e+000,3.499950e+001,-4.547019e-006,0.000000e+000,2,8.258262e-001,0.000000e+000,,,,,,,,,,,,,,32,1,4.000000e+000,0.000000e+000,0.000000e+000,0,,0,
1524361305.243,,0.000000e+000,3.499911e+001,-4.503576e-006,0.000000e+000,2,8.158288e-001,0.000000e+000,,,,,,,,,,,,,,32,1,4.000000e+000,2.338409e-003,0.000000e+000,0,,0,
1524361343.299,,0.000000e+000,3.499872e+001,-4.482584e-006,0.000000e+000,2,8.269003e-001,0.000000e+000,,,,,,,,,,,,,,32,1,4.000000e+000,0.000000e+000,0.000000e+000,0,,0,
1524361380.719,,0.000000e+000,3.499872e+001,-4.482361e-006,0.000000e+000,2,8.193687e-001,0.000000e+000,,,,,,,,,,,,,,32,1,4.000000e+000,0.000000e+000,0.000000e+000,0,,0,
1524361418.467,,0.000000e+000,3.499911e+001,-4.396283e-006,0.000000e+000,2,8.149927e-001,0.000000e+000,,,,,,,,,,,,,,32,1,4.000000e+000,7.820129e-004,0.000000e+000,0,,0,
1524361455.620,,0.000000e+000,3.499950e+001,-4.400757e-006,0.000000e+000,2,8.230547e-001,0.000000e+000,,,,,,,,,,,,,,32,1,4.000000e+000,0.000000e+000,0.000000e+000,0,,0,
1524361492.678,,0.000000e+000,3.499950e+001,-4.424113e-006,0.000000e+000,2,8.188810e-001,0.000000e+000,,,,,,,,,,,,,,32,1,4.000000e+000,0.000000e+000,0.000000e+000,0,,0,
1524361530.511,,0.000000e+000,3.499950e+001,-4.329037e-006,0.000000e+000,2,8.149769e-001,0.000000e+000,,,,,,,,,,,,,,32,1,4.000000e+000,0.000000e+000,0.000000e+000,0,,0,
1524361568.072,,0.000000e+000,3.499950e+001,-4.297978e-006,0.000000e+000,2,8.094564e-001,0.000000e+000,,,,,,,,,,,,,,32,1,4.000000e+000,0.000000e+000,0.000000e+000,0,,0,
1524361606.197,,0.000000e+000,3.499950e+001,-4.264428e-006,0.000000e+000,2,8.110542e-001,0.000000e+000,,,,,,,,,,,,,,32,1,4.000000e+000,0.000000e+000,0.000000e+000,0,,0,
1524361643.963,,0.000000e+000,3.499872e+001,-4.252424e-006,0.000000e+000,2,8.129740e-001,0.000000e+000,,,,,,,,,,,,,,32,1,4.000000e+000,0.000000e+000,0.000000e+000,0,,0,
1524361681.806,,0.000000e+000,3.499911e+001,-4.243674e-006,0.000000e+000,2,8.125939e-001,0.000000e+000,,,,,,,,,,,,,,32,1,4.000000e+000,7.820129e-004,0.000000e+000,0,,0,
1524361719.022,,0.000000e+000,3.499715e+001,-4.197392e-006,0.000000e+000,2,8.136098e-001,0.000000e+000,,,,,,,,,,,,,,32,1,4.000000e+000,4.692078e-003,0.000000e+000,0,,0,
1524361757.280,,0.000000e+000,3.499872e+001,-4.160175e-006,0.000000e+000,2,8.074146e-001,0.000000e+000,,,,,,,,,,,,,,32,1,4.000000e+000,0.000000e+000,0.000000e+000,0,,0,
1524361795.498,,0.000000e+000,3.499950e+001,-4.107732e-006,0.000000e+000,2,7.984152e-001,0.000000e+000,,,,,,,,,,,,,,32,1,4.000000e+000,0.000000e+000,0.000000e+000,0,,0,
1524361833.498,,0.000000e+000,3.499989e+001,-4.147970e-006,0.000000e+000,2,8.056620e-001,0.000000e+000,,,,,,,,,,,,,,32,1,4.000000e+000,7.781982e-004,0.000000e+000,0,,0,
1524361871.596,,0.000000e+000,3.499872e+001,-4.021372e-006,0.000000e+000,2,7.996421e-001,0.000000e+000,,,,,,,,,,,,,,32,1,4.000000e+000,1.560211e-003,0.000000e+000,0,,0,
1524361909.610,,0.000000e+000,3.499872e+001,-4.064816e-006,0.000000e+000,2,8.016737e-001,0.000000e+000,,,,,,,,,,,,,,32,1,4.000000e+000,1.560211e-003,0.000000e+000,0,,0,
1524361947.230,,0.000000e+000,3.499676e+001,-4.025094e-006,0.000000e+000,2,8.033140e-001,0.000000e+000,,,,,,,,,,,,,,32,1,4.000000e+000,7.820129e-004,0.000000e+000,0,,0,
1524361985.238,,0.000000e+000,3.499911e+001,-4.017482e-006,0.000000e+000,2,7.972700e-001,0.000000e+000,,,,,,,,,,,,,,32,1,4.000000e+000,7.820129e-004,0.000000e+000,0,,0,
1524362023.794,,0.000000e+000,3.499989e+001,-3.998190e-006,0.000000e+000,2,7.996904e-001,0.000000e+000,,,,,,,,,,,,,,32,1,4.000000e+000,7.781982e-004,0.000000e+000,0,,0,
1524362061.852,,0.000000e+000,3.499911e+001,-3.968295e-006,0.000000e+000,2,7.971659e-001,0.000000e+000,,,,,,,,,,,,,,32,1,4.000000e+000,2.338409e-003,0.000000e+000,0,,0,
1524362100.057,,0.000000e+000,3.499872e+001,-3.968591e-006,0.000000e+000,2,8.012130e-001,0.000000e+000,,,,,,,,,,,,,,32,1,4.000000e+000,1.560211e-003,0.000000e+000,0,,0,
1524362137.970,,0.000000e+000,3.499989e+001,-3.902527e-006,0.000000e+000,2,7.956361e-001,0.000000e+000,,,,,,,,,,,,,,32,1,4.000000e+000,7.781982e-004,0.000000e+000,0,,0,
1524362175.996,,0.000000e+000,3.499872e+001,-3.890319e-006,0.000000e+000,2,7.941421e-001,0.000000e+000,,,,,,,,,,,,,,32,1,4.000000e+000,1.560211e-003,0.000000e+000,0,,0,
1524362214.036,,0.000000e+000,3.499950e+001,-3.852133e-006,0.000000e+000,2,7.885285e-001,0.000000e+000,,,,,,,,,,,,,,32,1,4.000000e+000,0.000000e+000,0.000000e+000,0,,0,
1524362251.874,,0.000000e+000,3.499911e+001,-3.830582e-006,0.000000e+000,2,7.850620e-001,0.000000e+000,,,,,,,,,,,,,,32,1,4.000000e+000,3.910065e-003,0.000000e+000,0,,0,
1524362289.713,,0.000000e+000,3.500028e+001,-3.800695e-006,0.000000e+000,2,7.850608e-001,0.000000e+000,,,,,,,,,,,,,,32,1,4.000000e+000,1.560211e-003,0.000000e+000,0,,0,
1524362327.778,,0.000000e+000,3.499793e+001,-3.756149e-006,0.000000e+000,2,7.850936e-001,0.000000e+000,,,,,,,,,,,,,,32,1,4.000000e+000,3.131866e-003,0.000000e+000,0,,0,
1524362365.656,,0.000000e+000,3.500028e+001,-3.754728e-006,0.000000e+000,2,7.875330e-001,0.000000e+000,,,,,,,,,,,,,,32,1,4.000000e+000,1.560211e-003,0.000000e+000,0,,0,
1524362403.759,,0.000000e+000,3.499872e+001,-3.717280e-006,0.000000e+000,2,7.809796e-001,0.000000e+000,,,,,,,,,,,,,,32,1,4.000000e+000,1.560211e-003,0.000000e+000,0,,0,
1524362441.925,,0.000000e+000,3.499950e+001,-3.703691e-006,0.000000e+000,2,7.815650e-001,0.000000e+000,,,,,,,,,,,,,,32,1,4.000000e+000,0.000000e+000,0.000000e+000,0,,0,
1524362479.935,,0.000000e+000,3.499872e+001,-3.732727e-006,0.000000e+000,2,7.893209e-001,0.000000e+000,,,,,,,,,,,,,,32,1,4.000000e+000,0.000000e+000,0.000000e+000,0,,0,
1524362517.788,,0.000000e+000,3.499950e+001,-3.652224e-006,0.000000e+000,2,7.723138e-001,0.000000e+000,,,,,,,,,,,,,,32,1,4.000000e+000,0.000000e+000,0.000000e+000,0,,0,
1524362555.562,,0.000000e+000,3.499872e+001,-3.629284e-006,0.000000e+000,2,7.762462e-001,0.000000e+000,,,,,,,,,,,,,,32,1,4.000000e+000,1.560211e-003,0.000000e+000,0,,0,
1524362593.490,,0.000000e+000,3.499833e+001,-3.584820e-006,0.000000e+000,2,7.709979e-001,0.000000e+000,,,,,,,,,,,,,,32,1,4.000000e+000,7.781982e-004,0.000000e+000,0,,0,
1524362631.310,,0.000000e+000,3.499872e+001,-3.581870e-006,0.000000e+000,2,7.803304e-001,0.000000e+000,,,,,,,,,,,,,,32,1,4.000000e+000,1.560211e-003,0.000000e+000,0,,0,
1524362668.966,,0.000000e+000,3.499911e+001,-3.632239e-006,0.000000e+000,2,7.939324e-001,0.000000e+000,,,,,,,,,,,,,,32,1,4.000000e+000,7.820129e-004,0.000000e+000,0,,0,
1524362707.019,,0.000000e+000,3.499872e+001,-3.563537e-006,0.000000e+000,2,7.776292e-001,0.000000e+000,,,,,,,,,,,,,,32,1,4.000000e+000,0.000000e+000,0.000000e+000,0,,0,
1524362745.067,,0.000000e+000,3.499911e+001,-3.534836e-006,0.000000e+000,2,7.831017e-001,0.000000e+000,,,,,,,,,,,,,,32,1,4.000000e+000,7.820129e-004,0.000000e+000,0,,0,
1524362783.582,,0.000000e+000,3.499989e+001,-3.497375e-006,0.000000e+000,2,7.698991e-001,0.000000e+000,,,,,,,,,,,,,,32,1,4.000000e+000,7.781982e-004,0.000000e+000,0,,0,
1524362821.208,,0.000000e+000,3.500028e+001,-3.489121e-006,0.000000e+000,2,7.709045e-001,0.000000e+000,,,,,,,,,,,,,,32,1,4.000000e+000,1.560211e-003,0.000000e+000,0,,0,
1524362859.731,,0.000000e+000,3.499911e+001,-3.505264e-006,0.000000e+000,2,7.756288e-001,0.000000e+000,,,,,,,,,,,,,,32,1,4.000000e+000,7.820129e-004,0.000000e+000,0,,0,
1524362897.769,,0.000000e+000,3.499872e+001,-3.430257e-006,0.000000e+000,2,7.744867e-001,0.000000e+000,,,,,,,,,,,,,,32,1,4.000000e+000,0.000000e+000,0.000000e+000,0,,0,
1524362934.764,,0.000000e+000,3.499911e+001,-3.417984e-006,0.000000e+000,2,7.677689e-001,0.000000e+000,,,,,,,,,,,,,,32,1,4.000000e+000,7.820129e-004,0.000000e+000,0,,0,
1524362972.680,,0.000000e+000,3.499911e+001,-3.414566e-006,0.000000e+000,2,7.675411e-001,0.000000e+000,,,,,,,,,,,,,,32,1,4.000000e+000,7.820129e-004,0.000000e+000,0,,0,
1524363010.701,,0.000000e+000,3.499950e+001,-3.393880e-006,0.000000e+000,2,7.564329e-001,0.000000e+000,,,,,,,,,,,,,,32,1,4.000000e+000,0.000000e+000,0.000000e+000,0,,0,
1524363048.814,,0.000000e+000,3.499989e+001,-3.371460e-006,0.000000e+000,2,7.592823e-001,0.000000e+000,,,,,,,,,,,,,,32,1,4.000000e+000,7.781982e-004,0.000000e+000,0,,0,
1524363087.414,,0.000000e+000,3.499989e+001,-3.351505e-006,0.000000e+000,2,7.651439e-001,0.000000e+000,,,,,,,,,,,,,,32,1,4.000000e+000,7.781982e-004,0.000000e+000,0,,0,
1524363125.995,,0.000000e+000,3.499950e+001,-3.295138e-006,0.000000e+000,2,7.495523e-001,0.000000e+000,,,,,,,,,,,,,,32,1,4.000000e+000,0.000000e+000,0.000000e+000,0,,0,
1524363163.923,,0.000000e+000,3.500106e+001,-3.270279e-006,0.000000e+000,2,7.484366e-001,0.000000e+000,,,,,,,,,,,,,,32,1,4.000000e+000,0.000000e+000,0.000000e+000,0,,0,
1524363201.311,,0.000000e+000,3.499911e+001,-3.283266e-006,0.000000e+000,2,7.585433e-001,0.000000e+000,,,,,,,,,,,,,,32,1,4.000000e+000,7.820129e-004,0.000000e+000,0,,0,
1524363239.269,,0.000000e+000,3.499950e+001,-3.260164e-006,0.000000e+000,2,7.609438e-001,0.000000e+000,,,,,,,,,,,,,,32,1,4.000000e+000,0.000000e+000,0.000000e+000,0,,0,
1524363277.475,,0.000000e+000,3.499872e+001,-3.232527e-006,0.000000e+000,2,7.511331e-001,0.000000e+000,,,,,,,,,,,,,,32,1,4.000000e+000,0.000000e+000,0.000000e+000,0,,0,
1524363315.950,,0.000000e+000,3.499911e+001,-3.228326e-006,0.000000e+000,2,7.505593e-001,0.000000e+000,,,,,,,,,,,,,,32,1,4.000000e+000,7.820129e-004,0.000000e+000,0,,0,
1524363353.998,,0.000000e+000,3.499989e+001,-3.189315e-006,0.000000e+000,2,7.566795e-001,0.000000e+000,,,,,,,,,,,,,,32,1,4.000000e+000,7.781982e-004,0.000000e+000,0,,0,
1524363392.074,,0.000000e+000,3.499950e+001,-3.184025e-006,0.000000e+000,2,7.527839e-001,0.000000e+000,,,,,,,,,,,,,,32,1,4.000000e+000,0.000000e+000,0.000000e+000,0,,0,
1524363430.142,,0.000000e+000,3.499832e+001,-3.173862e-006,0.000000e+000,2,7.448189e-001,0.000000e+000,,,,,,,,,,,,,,32,1,4.000000e+000,3.910065e-003,0.000000e+000,0,,0,
1524363467.735,,0.000000e+000,3.499872e+001,-3.138022e-006,0.000000e+000,2,7.465113e-001,0.000000e+000,,,,,,,,,,,,,,32,1,4.000000e+000,0.000000e+000,0.000000e+000,0,,0,
1524363505.785,,0.000000e+000,3.499950e+001,-3.161849e-006,0.000000e+000,2,7.470805e-001,0.000000e+000,,,,,,,,,,,,,,32,1,4.000000e+000,1.560211e-003,0.000000e+000,0,,0,
1524363543.823,,0.000000e+000,3.499833e+001,-3.122209e-006,0.000000e+000,2,7.533857e-001,0.000000e+000,,,,,,,,,,,,,,32,1,4.000000e+000,2.349854e-003,0.000000e+000,0,,0,
1524363581.069,,0.000000e+000,3.499950e+001,-3.076474e-006,0.000000e+000,2,7.340628e-001,0.000000e+000,,,,,,,,,,,,,,32,1,4.000000e+000,0.000000e+000,0.000000e+000,0,,0,
1524363619.170,,0.000000e+000,3.499754e+001,-3.060671e-006,0.000000e+000,2,7.295527e-001,0.000000e+000,,,,,,,,,,,,,,32,1,4.000000e+000,5.470276e-003,0.000000e+000,0,,0,
1524363657.998,,0.000000e+000,3.499911e+001,-3.072395e-006,0.000000e+000,2,7.376588e-001,0.000000e+000,,,,,,,,,,,,,,32,1,4.000000e+000,7.820129e-004,0.000000e+000,0,,0,
1524363696.341,,0.000000e+000,3.499911e+001,-3.019310e-006,0.000000e+000,2,7.410522e-001,0.000000e+000,,,,,,,,,,,,,,32,1,4.000000e+000,2.338409e-003,0.000000e+000,0,,0,
1524363734.271,,0.000000e+000,3.499872e+001,-2.995705e-006,0.000000e+000,2,7.237669e-001,0.000000e+000,,,,,,,,,,,,,,32,1,4.000000e+000,0.000000e+000,0.000000e+000,0,,0,
1524363772.102,,0.000000e+000,3.499950e+001,-2.951175e-006,0.000000e+000,2,7.293760e-001,0.000000e+000,,,,,,,,,,,,,,32,1,4.000000e+000,0.000000e+000,0.000000e+000,0,,0,
1524363810.160,,0.000000e+000,3.499950e+001,-2.941859e-006,0.000000e+000,2,7.324718e-001,0.000000e+000,,,,,,,,,,,,,,32,1,4.000000e+000,0.000000e+000,0.000000e+000,0,,0,
1524363848.083,,0.000000e+000,3.499989e+001,-2.942661e-006,0.000000e+000,2,7.298317e-001,0.000000e+000,,,,,,,,,,,,,,32,1,4.000000e+000,7.781982e-004,0.000000e+000,0,,0,
1524363886.334,,0.000000e+000,3.499950e+001,-2.913730e-006,0.000000e+000,2,7.277273e-001,0.000000e+000,,,,,,,,,,,,,,32,1,4.000000e+000,0.000000e+000,0.000000e+000,0,,0,
1524363923.924,,0.000000e+000,3.499911e+001,-2.905492e-006,0.000000e+000,2,7.207534e-001,0.000000e+000,,,,,,,,,,,,,,32,1,4.000000e+000,7.820129e-004,0.000000e+000,0,,0,
1524363962.420,,0.000000e+000,3.499950e+001,-2.915121e-006,0.000000e+000,2,7.248757e-001,0.000000e+000,,,,,,,,,,,,,,32,1,4.000000e+000,0.000000e+000,0.000000e+000,0,,0,
1524364000.035,,0.000000e+000,3.499872e+001,-2.872494e-006,0.000000e+000,2,7.227691e-001,0.000000e+000,,,,,,,,,,,,,,32,1,4.000000e+000,1.560211e-003,0.000000e+000,0,,0,
1524364038.083,,0.000000e+000,3.499989e+001,-2.879394e-006,0.000000e+000,2,7.207716e-001,0.000000e+000,,,,,,,,,,,,,,32,1,4.000000e+000,7.781982e-004,0.000000e+000,0,,0,
1524364076.149,,0.000000e+000,3.499950e+001,-2.870356e-006,0.000000e+000,2,7.234489e-001,0.000000e+000,,,,,,,,,,,,,,32,1,4.000000e+000,1.560211e-003,0.000000e+000,0,,0,
1524364114.672,,0.000000e+000,3.499872e+001,-2.825225e-006,0.000000e+000,2,7.209430e-001,0.000000e+000,,,,,,,,,,,,,,32,1,4.000000e+000,0.000000e+000,0.000000e+000,0,,0,
1524364151.517,,0.000000e+000,3.499911e+001,-2.805448e-006,0.000000e+000,2,7.147965e-001,0.000000e+000,,,,,,,,,,,,,,32,1,4.000000e+000,7.820129e-004,0.000000e+000,0,,0,
1524364189.593,,0.000000e+000,3.499989e+001,-2.786957e-006,0.000000e+000,2,7.071020e-001,0.000000e+000,,,,,,,,,,,,,,32,1,4.000000e+000,7.781982e-004,0.000000e+000,0,,0,
1524364227.634,,0.000000e+000,3.499872e+001,-2.790096e-006,0.000000e+000,2,7.067414e-001,0.000000e+000,,,,,,,,,,,,,,32,1,4.000000e+000,0.000000e+000,0.000000e+000,0,,0,
1524364265.676,,0.000000e+000,3.499950e+001,-2.702963e-006,0.000000e+000,2,6.867539e-001,0.000000e+000,,,,,,,,,,,,,,32,1,4.000000e+000,0.000000e+000,0.000000e+000,0,,0,
1524364303.725,,0.000000e+000,3.499911e+001,-2.745713e-006,0.000000e+000,2,7.101219e-001,0.000000e+000,,,,,,,,,,,,,,32,1,4.000000e+000,7.820129e-004,0.000000e+000,0,,0,
1524364340.915,,0.000000e+000,3.500067e+001,-2.732935e-006,0.000000e+000,2,7.102904e-001,0.000000e+000,,,,,,,,,,,,,,32,1,4.000000e+000,2.338409e-003,0.000000e+000,0,,0,
1524364378.988,,0.000000e+000,3.499911e+001,-2.677439e-006,0.000000e+000,2,7.007065e-001,0.000000e+000,,,,,,,,,,,,,,32,1,4.000000e+000,7.820129e-004,0.000000e+000,0,,0,
1524364416.586,,0.000000e+000,3.499911e+001,-2.697677e-006,0.000000e+000,2,7.067193e-001,0.000000e+000,,,,,,,,,,,,,,32,1,4.000000e+000,7.820129e-004,0.000000e+000,0,,0,
1524364455.132,,0.000000e+000,3.499950e+001,-2.636727e-006,0.000000e+000,2,6.896420e-001,0.000000e+000,,,,,,,,,,,,,,32,1,4.000000e+000,0.000000e+000,0.000000e+000,0,,0,
1524364493.142,,0.000000e+000,3.499911e+001,-2.667567e-006,0.000000e+000,2,7.061425e-001,0.000000e+000,,,,,,,,,,,,,,32,1,4.000000e+000,7.820129e-004,0.000000e+000,0,,0,
1524364531.255,,0.000000e+000,3.499950e+001,-2.632446e-006,0.000000e+000,2,6.871313e-001,0.000000e+000,,,,,,,,,,,,,,32,1,4.000000e+000,0.000000e+000,0.000000e+000,0,,0,
1524364568.879,,0.000000e+000,3.499911e+001,-2.634418e-006,0.000000e+000,2,7.041585e-001,0.000000e+000,,,,,,,,,,,,,,32,1,4.000000e+000,7.820129e-004,0.000000e+000,0,,0,
1524364606.102,,0.000000e+000,3.499833e+001,-2.588638e-006,0.000000e+000,2,6.883311e-001,0.000000e+000,,,,,,,,,,,,,,32,1,4.000000e+000,7.781982e-004,0.000000e+000,0,,0,
1524364643.935,,0.000000e+000,3.499872e+001,-2.563769e-006,0.000000e+000,2,6.712646e-001,0.000000e+000,,,,,,,,,,,,,,32,1,4.000000e+000,0.000000e+000,0.000000e+000,0,,0,
1524364682.940,,0.000000e+000,3.499950e+001,-2.546465e-006,0.000000e+000,2,6.796651e-001,0.000000e+000,,,,,,,,,,,,,,32,1,4.000000e+000,1.560211e-003,0.000000e+000,0,,0,
1524364721.071,,0.000000e+000,3.499794e+001,-2.532609e-006,0.000000e+000,2,6.777791e-001,0.000000e+000,,,,,,,,,,,,,,32,1,4.000000e+000,0.000000e+000,0.000000e+000,0,,0,
1524364759.071,,0.000000e+000,3.499950e+001,-2.531903e-006,0.000000e+000,2,6.794991e-001,0.000000e+000,,,,,,,,,,,,,,32,1,4.000000e+000,1.560211e-003,0.000000e+000,0,,0,
1524364796.677,,0.000000e+000,3.499754e+001,-2.507920e-006,0.000000e+000,2,6.854095e-001,0.000000e+000,,,,,,,,,,,,,,32,1,4.000000e+000,7.896423e-004,0.000000e+000,0,,0,
1524364834.720,,0.000000e+000,3.499872e+001,-2.496620e-006,0.000000e+000,2,6.661758e-001,0.000000e+000,,,,,,,,,,,,,,32,1,4.000000e+000,1.560211e-003,0.000000e+000,0,,0,
1524364872.793,,0.000000e+000,3.499872e+001,-2.563761e-006,0.000000e+000,2,6.915697e-001,0.000000e+000,,,,,,,,,,,,,,32,1,4.000000e+000,0.000000e+000,0.000000e+000,0,,0,
1524364910.871,,0.000000e+000,3.499950e+001,-2.475893e-006,0.000000e+000,2,6.765832e-001,0.000000e+000,,,,,,,,,,,,,,32,1,4.000000e+000,0.000000e+000,0.000000e+000,0,,0,
1524364948.841,,0.000000e+000,3.499872e+001,-2.459944e-006,0.000000e+000,2,6.783932e-001,0.000000e+000,,,,,,,,,,,,,,32,1,4.000000e+000,1.560211e-003,0.000000e+000,0,,0,
1524364986.897,,0.000000e+000,3.499989e+001,-2.448755e-006,0.000000e+000,2,6.777976e-001,0.000000e+000,,,,,,,,,,,,,,32,1,4.000000e+000,7.781982e-004,0.000000e+000,0,,0,
1524365024.583,,0.000000e+000,3.499950e+001,-2.413881e-006,0.000000e+000,2,6.671530e-001,0.000000e+000,,,,,,,,,,,,,,32,1,4.000000e+000,0.000000e+000,0.000000e+000,0,,0,
1524365062.603,,0.000000e+000,3.499872e+001,-2.427527e-006,0.000000e+000,2,6.688964e-001,0.000000e+000,,,,,,,,,,,,,,32,1,4.000000e+000,1.560211e-003,0.000000e+000,0,,0,
1524365101.756,,0.000000e+000,3.499950e+001,-2.406569e-006,0.000000e+000,2,6.730306e-001,0.000000e+000,,,,,,,,,,,,,,32,1,4.000000e+000,1.560211e-003,0.000000e+000,0,,0,
1524365139.447,,0.000000e+000,3.499911e+001,-2.389648e-006,0.000000e+000,2,6.571278e-001,0.000000e+000,,,,,,,,,,,,,,32,1,4.000000e+000,2.338409e-003,0.000000e+000,0,,0,
1524365177.520,,0.000000e+000,3.499950e+001,-2.359037e-006,0.000000e+000,2,6.559511e-001,0.000000e+000,,,,,,,,,,,,,,32,1,4.000000e+000,0.000000e+000,0.000000e+000,0,,0,
1524365215.246,,0.000000e+000,3.499989e+001,-2.323909e-006,0.000000e+000,2,6.493438e-001,0.000000e+000,,,,,,,,,,,,,,32,1,4.000000e+000,7.781982e-004,0.000000e+000,0,,0,
1524365252.881,,0.000000e+000,3.499754e+001,-2.356319e-006,0.000000e+000,2,6.531345e-001,0.000000e+000,,,,,,,,,,,,,,32,1,4.000000e+000,7.896423e-004,0.000000e+000,0,,0,
1524365290.302,,0.000000e+000,3.500028e+001,-2.322634e-006,0.000000e+000,2,6.558296e-001,0.000000e+000,,,,,,,,,,,,,,32,1,4.000000e+000,0.000000e+000,0.000000e+000,0,,0,
1524365328.645,,0.000000e+000,3.499754e+001,-2.307174e-006,0.000000e+000,2,6.523623e-001,0.000000e+000,,,,,,,,,,,,,,32,1,4.000000e+000,3.910065e-003,0.000000e+000,0,,0,
1524365366.653,,0.000000e+000,3.499637e+001,-2.263904e-006,0.000000e+000,2,6.420000e-001,0.000000e+000,,,,,,,,,,,,,,32,1,4.000000e+000,6.259918e-003,0.000000e+000,0,,0,
1524365404.778,,0.000000e+000,3.499950e+001,-2.255910e-006,0.000000e+000,2,6.421323e-001,0.000000e+000,,,,,,,,,,,,,,32,1,4.000000e+000,0.000000e+000,0.000000e+000,0,,0,
1524365442.669,,0.000000e+000,3.499754e+001,-2.238184e-006,0.000000e+000,2,6.238437e-001,0.000000e+000,,,,,,,,,,,,,,32,1,4.000000e+000,3.910065e-003,0.000000e+000,0,,0,
1524365480.357,,0.000000e+000,3.499754e+001,-2.217986e-006,0.000000e+000,2,6.224515e-001,0.000000e+000,,,,,,,,,,,,,,32,1,4.000000e+000,7.896423e-004,0.000000e+000,0,,0,
1524365518.367,,0.000000e+000,3.499950e+001,-2.227191e-006,0.000000e+000,2,6.375728e-001,0.000000e+000,,,,,,,,,,,,,,32,1,4.000000e+000,1.560211e-003,0.000000e+000,0,,0,
1524365556.420,,0.000000e+000,3.499950e+001,-2.198893e-006,0.000000e+000,2,6.308725e-001,0.000000e+000,,,,,,,,,,,,,,32,1,4.000000e+000,0.000000e+000,0.000000e+000,0,,0,
1524365594.611,,0.000000e+000,3.499833e+001,-2.188760e-006,0.000000e+000,2,6.278325e-001,0.000000e+000,,,,,,,,,,,,,,32,1,4.000000e+000,2.349854e-003,0.000000e+000,0,,0,
1524365632.667,,0.000000e+000,3.499950e+001,-2.168440e-006,0.000000e+000,2,6.252864e-001,0.000000e+000,,,,,,,,,,,,,,32,1,4.000000e+000,1.560211e-003,0.000000e+000,0,,0,
1524365670.710,,0.000000e+000,3.499833e+001,-2.163217e-006,0.000000e+000,2,6.185448e-001,0.000000e+000,,,,,,,,,,,,,,32,1,4.000000e+000,7.781982e-004,0.000000e+000,0,,0,
1524365709.885,,0.000000e+000,3.499989e+001,-2.113605e-006,0.000000e+000,2,6.098955e-001,0.000000e+000,,,,,,,,,,,,,,32,1,4.000000e+000,7.781982e-004,0.000000e+000,0,,0,
1524365748.408,,0.000000e+000,3.499911e+001,-2.143843e-006,0.000000e+000,2,6.162642e-001,0.000000e+000,,,,,,,,,,,,,,32,1,4.000000e+000,7.820129e-004,0.000000e+000,0,,0,
1524365786.464,,0.000000e+000,3.499950e+001,-2.104792e-006,0.000000e+000,2,6.200575e-001,0.000000e+000,,,,,,,,,,,,,,32,1,4.000000e+000,1.560211e-003,0.000000e+000,0,,0,
1524365824.512,,0.000000e+000,3.499989e+001,-2.110968e-006,0.000000e+000,2,6.218953e-001,0.000000e+000,,,,,,,,,,,,,,32,1,4.000000e+000,7.781982e-004,0.000000e+000,0,,0,
1524365861.905,,0.000000e+000,3.499793e+001,-2.111096e-006,0.000000e+000,2,5.973349e-001,0.000000e+000,,,,,,,,,,,,,,32,1,4.000000e+000,1.567841e-003,0.000000e+000,0,,0,
1524365900.386,,0.000000e+000,3.499911e+001,-2.081157e-006,0.000000e+000,2,6.128302e-001,0.000000e+000,,,,,,,,,,,,,,32,1,4.000000e+000,7.820129e-004,0.000000e+000,0,,0,
1524365939.031,,0.000000e+000,3.499989e+001,-2.073138e-006,0.000000e+000,2,6.146375e-001,0.000000e+000,,,,,,,,,,,,,,32,1,4.000000e+000,7.781982e-004,0.000000e+000,0,,0,
1524365977.199,,0.000000e+000,3.499911e+001,-2.089067e-006,0.000000e+000,2,6.053501e-001,0.000000e+000,,,,,,,,,,,,,,32,1,4.000000e+000,2.338409e-003,0.000000e+000,0,,0,
1524366015.190,,0.000000e+000,3.500028e+001,-2.029295e-006,0.000000e+000,2,5.940402e-001,0.000000e+000,,,,,,,,,,,,,,32,1,4.000000e+000,0.000000e+000,0.000000e+000,0,,0,
1524366053.210,,0.000000e+000,3.499950e+001,-1.995305e-006,0.000000e+000,2,5.772172e-001,0.000000e+000,,,,,,,,,,,,,,32,1,4.000000e+000,1.560211e-003,0.000000e+000,0,,0,
1524366091.438,,0.000000e+000,3.499911e+001,-2.007426e-006,0.000000e+000,2,5.958965e-001,0.000000e+000,,,,,,,,,,,,,,32,1,4.000000e+000,7.820129e-004,0.000000e+000,0,,0,
1524366128.999,,0.000000e+000,3.499911e+001,-2.029644e-006,0.000000e+000,2,6.040553e-001,0.000000e+000,,,,,,,,,,,,,,32,1,4.000000e+000,7.820129e-004,0.000000e+000,0,,0,
1524366167.052,,0.000000e+000,3.499911e+001,-1.957501e-006,0.000000e+000,2,5.715710e-001,0.000000e+000,,,,,,,,,,,,,,32,1,4.000000e+000,7.820129e-004,0.000000e+000,0,,0,
1524366205.110,,0.000000e+000,3.499950e+001,-1.964633e-006,0.000000e+000,2,5.887749e-001,0.000000e+000,,,,,,,,,,,,,,32,1,4.000000e+000,0.000000e+000,0.000000e+000,0,,0,
1524366243.221,,0.000000e+000,3.499950e+001,-1.941712e-006,0.000000e+000,2,5.702849e-001,0.000000e+000,,,,,,,,,,,,,,32,1,4.000000e+000,0.000000e+000,0.000000e+000,0,,0,
1524366281.269,,0.000000e+000,3.500067e+001,-1.942665e-006,0.000000e+000,2,5.786480e-001,0.000000e+000,,,,,,,,,,,,,,32,1,4.000000e+000,2.338409e-003,0.000000e+000,0,,0,
1524366319.309,,0.000000e+000,3.499950e+001,-1.939984e-006,0.000000e+000,2,5.784228e-001,0.000000e+000,,,,,,,,,,,,,,32,1,4.000000e+000,0.000000e+000,0.000000e+000,0,,0,
1524366357.410,,0.000000e+000,3.499833e+001,-1.912059e-006,0.000000e+000,2,5.551354e-001,0.000000e+000,,,,,,,,,,,,,,32,1,4.000000e+000,7.781982e-004,0.000000e+000,0,,0,
1524366395.408,,0.000000e+000,3.499793e+001,-1.905699e-006,0.000000e+000,2,5.688601e-001,0.000000e+000,,,,,,,,,,,,,,32,1,4.000000e+000,3.131866e-003,0.000000e+000,0,,0,
1524366433.258,,0.000000e+000,3.499793e+001,-1.871068e-006,0.000000e+000,2,5.469098e-001,0.000000e+000,,,,,,,,,,,,,,32,1,4.000000e+000,3.131866e-003,0.000000e+000,0,,0,
1524366446.809,,0.000000e+000,3.499872e+001,-1.867707e-006,0.000000e+000,2,5.593137e-001,0.000000e+000,,,,,,,,,,,,,,32,1,4.000000e+000,0.000000e+000,0.000000e+000,0,,0,