File: Input_All/MFn1_TRMac_37K_0.08Kmin_VRMde_35K.dc.dat
[Header]
TITLE,MPMS DC Measurement
BYAPP,MPMS Measurement,2.1,Summary
FILEOPENTIME, 1524372328.850000 4/21/2018, 10:45:28 PM

INFO, APPNAME, MPMS MultiVu Application, Revision 1.61,  Build 082

INFO, NAME, MFn1
INFO, WEIGHT, 1.000
INFO, AREA, 1.000
INFO, LENGTH, 1.000
INFO, SHAPE, 0
INFO, COMMENT,
INFO, SEQUENCE FILE: TRMac_37K_0.08Kmin_VRMde_35K.seq


INFO, BACKGROUND DATA FILE:, None


STARTUPAXIS,X,4,LINEAR,AUTO,0.000000,0.000000
STARTUPAXIS,Y1,5,LINEAR,AUTO,0.000000,0.000000


STARTUPGROUP,Longitudinal
FIELDGROUP,Longitudinal,1,2,3,4,5,6,7,8,9,15,16,17,18,27,28
FIELDGROUP,Transverse,1,2,3,4,10,11,12,13,14,19,20,21,22,27,28

PLOT_APPEARANCE,ALL,HORZ_GRID_ON,VERT_GRID_ON,MARKERS_AND_LINES

[Data]
Time,Comment,Field (Oe),Temperature (K),Long Moment (emu),Long Scan Std Dev,Long Algorithm,Long Reg Fit,Long Percent Error (%),Trans Moment (emu),Trans Scan Std Dev,Trans Algorithm,Trans Reg Fit,Trans Percent Error (%),Long Moment [w/o ABS] (emu),Long Scan Std Dev [w/o ABS],Long Reg Fit [w/o ABS],Long Percent Error [w/o ABS] (%),Trans Moment [w/o ABS] (emu),Trans Scan Std Dev [w/o ABS],Trans Reg Fit [w/o ABS],Trans Percent Error [w/o ABS] (%),Points per Scan,Scans per Measurement,Scan Length (cm),Delta Temp (K),Rot Position (deg),Error,EC Comp. Running,Using ABS,
1524372328.847,,0.000000e+000,3.499442e+001,-2.968693e-005,0.000000e+000,2,9.750352e-001,0.000000e+000,,,,,,,,,,,,,,32,1,4.000000e+000,3.910065e-003,0.000000e+000,0,,0,
1524372366.493,,0.000000e+000,3.499950e+001,-2.768260e-005,0.000000e+000,2,9.711275e-001,0.000000e+000,,,,,,,,,,,,,,32,1,4.000000e+000,3.120422e-003,0.000000e+000,0,,0,
1524372404.576,,0.000000e+000,3.499833e+001,-2.618220e-005,0.000000e+000,2,9.694514e-001,0.000000e+000,,,,,,,,,,,,,,32,1,4.000000e+000,7.781982e-004,0.000000e+000,0,,0,
1524372442.216,,0.000000e+000,3.499911e+001,-2.510122e-005,0.000000e+000,2,9.672945e-001,0.000000e+000,,,,,,,,,,,,,,32,1,4.000000e+000,7.820129e-004,0.000000e+000,0,,0,
1524372480.205,,0.000000e+000,3.499754e+001,-2.428184e-005,0.000000e+000,2,9.660984e-001,0.000000e+000,,,,,,,,,,,,,,32,1,4.000000e+000,7.896423e-004,0.000000e+000,0,,0,
1524372518.648,,0.000000e+000,3.499833e+001,-2.346870e-005,0.000000e+000,2,9.667323e-001,0.000000e+000,,,,,,,,,,,,,,32,1,4.000000e+000,7.781982e-004,0.000000e+000,0,,0,
1524372556.781,,0.000000e+000,3.499872e+001,-2.284939e-005,0.000000e+000,2,9.641441e-001,0.000000e+000,,,,,,,,,,,,,,32,1,4.000000e+000,0.000000e+000,0.000000e+000,0,,0,
1524372594.366,,0.000000e+000,3.499794e+001,-2.228777e-005,0.000000e+000,2,9.657651e-001,0.000000e+000,,,,,,,,,,,,,,32,1,4.000000e+000,0.000000e+000,0.000000e+000,0,,0,
1524372632.222,,0.000000e+000,3.499911e+001,-2.181057e-005,0.000000e+000,2,9.620513e-001,0.000000e+000,,,,,,,,,,,,,,32,1,4.000000e+000,2.338409e-003,0.000000e+000,0,,0,
1524372669.542,,0.000000e+000,3.499872e+001,-2.129792e-005,0.000000e+000,2,9.618444e-001,0.000000e+000,,,,,,,,,,,,,,32,1,4.000000e+000,0.000000e+000,0.000000e+000,0,,0,
1524372707.598,,0.000000e+000,3.499911e+001,-2.089875e-005,0.000000e+000,2,9.606738e-001,0.000000e+000,,,,,,,,,,,,,,32,1,4.000000e+000,7.820129e-004,0.000000e+000,0,,0,
1524372744.886,,0.000000e+000,3.499911e+001,-2.059354e-005,0.000000e+000,2,9.598631e-001,0.000000e+000,,,,,,,,,,,,,,32,1,4.000000e+000,7.820129e-004,0.000000e+000,0,,0,
1524372783.619,,0.000000e+000,3.499833e+001,-2.018963e-005,0.000000e+000,2,9.597291e-001,0.000000e+000,,,,,,,,,,,,,,32,1,4.000000e+000,7.781982e-004,0.000000e+000,0,,0,
1524372821.927,,0.000000e+000,3.500028e+001,-1.983906e-005,0.000000e+000,2,9.600237e-001,0.000000e+000,,,,,,,,,,,,,,32,1,4.000000e+000,3.120422e-003,0.000000e+000,0,,0,
1524372859.105,,0.000000e+000,3.499833e+001,-1.955191e-005,0.000000e+000,2,9.594439e-001,0.000000e+000,,,,,,,,,,,,,,32,1,4.000000e+000,7.781982e-004,0.000000e+000,0,,0,
1524372897.023,,0.000000e+000,3.499794e+001,-1.921377e-005,0.000000e+000,2,9.576086e-001,0.000000e+000,,,,,,,,,,,,,,32,1,4.000000e+000,0.000000e+000,0.000000e+000,0,,0,
1524372934.731,,0.000000e+000,3.499794e+001,-1.897082e-005,0.000000e+000,2,9.556939e-001,0.000000e+000,,,,,,,,,,,,,,32,1,4.000000e+000,0.000000e+000,0.000000e+000,0,,0,
1524372972.357,,0.000000e+000,3.499715e+001,-1.870826e-005,0.000000e+000,2,9.564878e-001,0.000000e+000,,,,,,,,,,,,,,32,1,4.000000e+000,1.571655e-003,0.000000e+000,0,,0,
1524373009.970,,0.000000e+000,3.499911e+001,-1.845306e-005,0.000000e+000,2,9.560718e-001,0.000000e+000,,,,,,,,,,,,,,32,1,4.000000e+000,2.338409e-003,0.000000e+000,0,,0,
1524373047.565,,0.000000e+000,3.499872e+001,-1.822403e-005,0.000000e+000,2,9.557916e-001,0.000000e+000,,,,,,,,,,,,,,32,1,4.000000e+000,1.560211e-003,0.000000e+000,0,,0,
1524373084.713,,0.000000e+000,3.499833e+001,-1.800741e-005,0.000000e+000,2,9.563164e-001,0.000000e+000,,,,,,,,,,,,,,32,1,4.000000e+000,7.781982e-004,0.000000e+000,0,,0,
1524373123.514,,0.000000e+000,3.499989e+001,-1.781779e-005,0.000000e+000,2,9.529438e-001,0.000000e+000,,,,,,,,,,,,,,32,1,4.000000e+000,7.781982e-004,0.000000e+000,0,,0,
1524373160.457,,0.000000e+000,3.499989e+001,-1.767807e-005,0.000000e+000,2,9.547489e-001,0.000000e+000,,,,,,,,,,,,,,32,1,4.000000e+000,7.781982e-004,0.000000e+000,0,,0,
1524373198.430,,0.000000e+000,3.499794e+001,-1.743388e-005,0.000000e+000,2,9.552017e-001,0.000000e+000,,,,,,,,,,,,,,32,1,4.000000e+000,0.000000e+000,0.000000e+000,0,,0,
1524373236.501,,0.000000e+000,3.499833e+001,-1.724999e-005,0.000000e+000,2,9.550397e-001,0.000000e+000,,,,,,,,,,,,,,32,1,4.000000e+000,7.781982e-004,0.000000e+000,0,,0,
1524373274.119,,0.000000e+000,3.499872e+001,-1.707948e-005,0.000000e+000,2,9.529332e-001,0.000000e+000,,,,,,,,,,,,,,32,1,4.000000e+000,0.000000e+000,0.000000e+000,0,,0,
1524373312.172,,0.000000e+000,3.499794e+001,-1.690301e-005,0.000000e+000,2,9.545406e-001,0.000000e+000,,,,,,,,,,,,,,32,1,4.000000e+000,0.000000e+000,0.000000e+000,0,,0,
1524373350.697,,0.000000e+000,3.499911e+001,-1.665637e-005,0.000000e+000,2,9.524145e-001,0.000000e+000,,,,,,,,,,,,,,32,1,4.000000e+000,7.820129e-004,0.000000e+000,0,,0,
1524373388.310,,0.000000e+000,3.499911e+001,-1.658519e-005,0.000000e+000,2,9.536681e-001,0.000000e+000,,,,,,,,,,,,,,32,1,4.000000e+000,7.820129e-004,0.000000e+000,0,,0,
1524373426.383,,0.000000e+000,3.499872e+001,-1.640351e-005,0.000000e+000,2,9.530486e-001,0.000000e+000,,,,,,,,,,,,,,32,1,4.000000e+000,0.000000e+000,0.000000e+000,0,,0,
1524373464.887,,0.000000e+000,3.499911e+001,-1.629625e-005,0.000000e+000,2,9.511600e-001,0.000000e+000,,,,,,,,,,,,,,32,1,4.000000e+000,7.820129e-004,0.000000e+000,0,,0,
1524373502.507,,0.000000e+000,3.499872e+001,-1.615757e-005,0.000000e+000,2,9.519015e-001,0.000000e+000,,,,,,,,,,,,,,32,1,4.000000e+000,0.000000e+000,0.000000e+000,0,,0,
1524373540.343,,0.000000e+000,3.499950e+001,-1.598122e-005,0.000000e+000,2,9.537708e-001,0.000000e+000,,,,,,,,,,,,,,32,1,4.000000e+000,1.560211e-003,0.000000e+000,0,,0,
1524373577.871,,0.000000e+000,3.499872e+001,-1.583911e-005,0.000000e+000,2,9.496854e-001,0.000000e+000,,,,,,,,,,,,,,32,1,4.000000e+000,1.560211e-003,0.000000e+000,0,,0,
1524373615.916,,0.000000e+000,3.499833e+001,-1.570126e-005,0.000000e+000,2,9.498932e-001,0.000000e+000,,,,,,,,,,,,,,32,1,4.000000e+000,2.349854e-003,0.000000e+000,0,,0,
1524373654.009,,0.000000e+000,3.499872e+001,-1.557484e-005,0.000000e+000,2,9.474776e-001,0.000000e+000,,,,,,,,,,,,,,32,1,4.000000e+000,1.560211e-003,0.000000e+000,0,,0,
1524373692.075,,0.000000e+000,3.499872e+001,-1.545791e-005,0.000000e+000,2,9.487603e-001,0.000000e+000,,,,,,,,,,,,,,32,1,4.000000e+000,0.000000e+000,0.000000e+000,0,,0,
1524373729.513,,0.000000e+000,3.499754e+001,-1.529288e-005,0.000000e+000,2,9.495504e-001,0.000000e+000,,,,,,,,,,,,,,32,1,4.000000e+000,2.349854e-003,0.000000e+000,0,,0,
1524373767.673,,0.000000e+000,3.500028e+001,-1.521171e-005,0.000000e+000,2,9.468912e-001,0.000000e+000,,,,,,,,,,,,,,32,1,4.000000e+000,0.000000e+000,0.000000e+000,0,,0,
1524373805.512,,0.000000e+000,3.499911e+001,-1.506434e-005,0.000000e+000,2,9.491443e-001,0.000000e+000,,,,,,,,,,,,,,32,1,4.000000e+000,7.820129e-004,0.000000e+000,0,,0,
1524373843.102,,0.000000e+000,3.499872e+001,-1.496288e-005,0.000000e+000,2,9.465843e-001,0.000000e+000,,,,,,,,,,,,,,32,1,4.000000e+000,0.000000e+000,0.000000e+000,0,,0,
1524373881.118,,0.000000e+000,3.499950e+001,-1.486207e-005,0.000000e+000,2,9.480298e-001,0.000000e+000,,,,,,,,,,,,,,32,1,4.000000e+000,1.560211e-003,0.000000e+000,0,,0,
1524373919.068,,0.000000e+000,3.499872e+001,-1.477427e-005,0.000000e+000,2,9.478750e-001,0.000000e+000,,,,,,,,,,,,,,32,1,4.000000e+000,0.000000e+000,0.000000e+000,0,,0,
1524373956.719,,0.000000e+000,3.499794e+001,-1.469387e-005,0.000000e+000,2,9.458402e-001,0.000000e+000,,,,,,,,,,,,,,32,1,4.000000e+000,0.000000e+000,0.000000e+000,0,,0,
1524373994.797,,0.000000e+000,3.499872e+001,-1.457151e-005,0.000000e+000,2,9.470435e-001,0.000000e+000,,,,,,,,,,,,,,32,1,4.000000e+000,0.000000e+000,0.000000e+000,0,,0,
1524374032.882,,0.000000e+000,3.499833e+001,-1.441206e-005,0.000000e+000,2,9.468799e-001,0.000000e+000,,,,,,,,,,,,,,32,1,4.000000e+000,7.781982e-004,0.000000e+000,0,,0,
1524374070.963,,0.000000e+000,3.499989e+001,-1.435647e-005,0.000000e+000,2,9.456816e-001,0.000000e+000,,,,,,,,,,,,,,32,1,4.000000e+000,2.342224e-003,0.000000e+000,0,,0,
1524374108.944,,0.000000e+000,3.499950e+001,-1.424528e-005,0.000000e+000,2,9.463573e-001,0.000000e+000,,,,,,,,,,,,,,32,1,4.000000e+000,0.000000e+000,0.000000e+000,0,,0,
1524374147.022,,0.000000e+000,3.499950e+001,-1.415118e-005,0.000000e+000,2,9.457037e-001,0.000000e+000,,,,,,,,,,,,,,32,1,4.000000e+000,1.560211e-003,0.000000e+000,0,,0,
1524374185.095,,0.000000e+000,3.499911e+001,-1.405223e-005,0.000000e+000,2,9.463419e-001,0.000000e+000,,,,,,,,,,,,,,32,1,4.000000e+000,2.338409e-003,0.000000e+000,0,,0,
1524374223.188,,0.000000e+000,3.499950e+001,-1.393227e-005,0.000000e+000,2,9.461514e-001,0.000000e+000,,,,,,,,,,,,,,32,1,4.000000e+000,0.000000e+000,0.000000e+000,0,,0,
1524374261.613,,0.000000e+000,3.499911e+001,-1.381356e-005,0.000000e+000,2,9.418069e-001,0.000000e+000,,,,,,,,,,,,,,32,1,4.000000e+000,7.820129e-004,0.000000e+000,0,,0,
1524374299.701,,0.000000e+000,3.499872e+001,-1.374113e-005,0.000000e+000,2,9.426932e-001,0.000000e+000,,,,,,,,,,,,,,32,1,4.000000e+000,0.000000e+000,0.000000e+000,0,,0,
1524374337.382,,0.000000e+000,3.499872e+001,-1.366063e-005,0.000000e+000,2,9.432645e-001,0.000000e+000,,,,,,,,,,,,,,32,1,4.000000e+000,0.000000e+000,0.000000e+000,0,,0,
1524374375.490,,0.000000e+000,3.499950e+001,-1.359502e-005,0.000000e+000,2,9.440553e-001,0.000000e+000,,,,,,,,,,,,,,32,1,4.000000e+000,0.000000e+000,0.000000e+000,0,,0,
1524374413.555,,0.000000e+000,3.499833e+001,-1.344590e-005,0.000000e+000,2,9.460465e-001,0.000000e+000,,,,,,,,,,,,,,32,1,4.000000e+000,7.781982e-004,0.000000e+000,0,,0,
1524374451.186,,0.000000e+000,3.499950e+001,-1.342868e-005,0.000000e+000,2,9.440749e-001,0.000000e+000,,,,,,,,,,,,,,32,1,4.000000e+000,0.000000e+000,0.000000e+000,0,,0,
1524374489.219,,0.000000e+000,3.499872e+001,-1.335492e-005,0.000000e+000,2,9.402360e-001,0.000000e+000,,,,,,,,,,,,,,32,1,4.000000e+000,0.000000e+000,0.000000e+000,0,,0,
1524374526.800,,0.000000e+000,3.500028e+001,-1.329013e-005,0.000000e+000,2,9.437406e-001,0.000000e+000,,,,,,,,,,,,,,32,1,4.000000e+000,1.560211e-003,0.000000e+000,0,,0,
1524374564.883,,0.000000e+000,3.499989e+001,-1.319385e-005,0.000000e+000,2,9.409017e-001,0.000000e+000,,,,,,,,,,,,,,32,1,4.000000e+000,7.781982e-004,0.000000e+000,0,,0,
1524374602.861,,0.000000e+000,3.499833e+001,-1.311677e-005,0.000000e+000,2,9.424421e-001,0.000000e+000,,,,,,,,,,,,,,32,1,4.000000e+000,7.781982e-004,0.000000e+000,0,,0,
1524374640.939,,0.000000e+000,3.499833e+001,-1.305168e-005,0.000000e+000,2,9.423504e-001,0.000000e+000,,,,,,,,,,,,,,32,1,4.000000e+000,7.781982e-004,0.000000e+000,0,,0,
1524374679.077,,0.000000e+000,3.499950e+001,-1.296655e-005,0.000000e+000,2,9.394683e-001,0.000000e+000,,,,,,,,,,,,,,32,1,4.000000e+000,0.000000e+000,0.000000e+000,0,,0,
1524374717.075,,0.000000e+000,3.499833e+001,-1.291822e-005,0.000000e+000,2,9.424577e-001,0.000000e+000,,,,,,,,,,,,,,32,1,4.000000e+000,2.349854e-003,0.000000e+000,0,,0,
1524374755.176,,0.000000e+000,3.499950e+001,-1.283971e-005,0.000000e+000,2,9.407163e-001,0.000000e+000,,,,,,,,,,,,,,32,1,4.000000e+000,0.000000e+000,0.000000e+000,0,,0,
1524374793.301,,0.000000e+000,3.499872e+001,-1.274577e-005,0.000000e+000,2,9.396209e-001,0.000000e+000,,,,,,,,,,,,,,32,1,4.000000e+000,1.560211e-003,0.000000e+000,0,,0,
1524374831.807,,0.000000e+000,3.499911e+001,-1.258081e-005,0.000000e+000,2,9.413518e-001,0.000000e+000,,,,,,,,,,,,,,32,1,4.000000e+000,7.820129e-004,0.000000e+000,0,,0,
1524374868.960,,0.000000e+000,3.499911e+001,-1.262225e-005,0.000000e+000,2,9.407603e-001,0.000000e+000,,,,,,,,,,,,,,32,1,4.000000e+000,7.820129e-004,0.000000e+000,0,,0,
1524374907.478,,0.000000e+000,3.499872e+001,-1.257594e-005,0.000000e+000,2,9.412692e-001,0.000000e+000,,,,,,,,,,,,,,32,1,4.000000e+000,0.000000e+000,0.000000e+000,0,,0,
1524374945.536,,0.000000e+000,3.499872e+001,-1.247630e-005,0.000000e+000,2,9.407470e-001,0.000000e+000,,,,,,,,,,,,,,32,1,4.000000e+000,0.000000e+000,0.000000e+000,0,,0,
1524374983.179,,0.000000e+000,3.499872e+001,-1.242049e-005,0.000000e+000,2,9.399416e-001,0.000000e+000,,,,,,,,,,,,,,32,1,4.000000e+000,0.000000e+000,0.000000e+000,0,,0,
1524375021.707,,0.000000e+000,3.499794e+001,-1.239452e-005,0.000000e+000,2,9.387965e-001,0.000000e+000,,,,,,,,,,,,,,32,1,4.000000e+000,0.000000e+000,0.000000e+000,0,,0,
1524375059.345,,0.000000e+000,3.499833e+001,-1.232429e-005,0.000000e+000,2,9.409971e-001,0.000000e+000,,,,,,,,,,,,,,32,1,4.000000e+000,7.781982e-004,0.000000e+000,0,,0,
1524375097.405,,0.000000e+000,3.499911e+001,-1.224255e-005,0.000000e+000,2,9.367146e-001,0.000000e+000,,,,,,,,,,,,,,32,1,4.000000e+000,7.820129e-004,0.000000e+000,0,,0,
1524375135.484,,0.000000e+000,3.499872e+001,-1.218946e-005,0.000000e+000,2,9.389259e-001,0.000000e+000,,,,,,,,,,,,,,32,1,4.000000e+000,1.560211e-003,0.000000e+000,0,,0,
1524375173.547,,0.000000e+000,3.499911e+001,-1.211114e-005,0.000000e+000,2,9.388960e-001,0.000000e+000,,,,,,,,,,,,,,32,1,4.000000e+000,7.820129e-004,0.000000e+000,0,,0,
1524375212.067,,0.000000e+000,3.499833e+001,-1.204916e-005,0.000000e+000,2,9.374815e-001,0.000000e+000,,,,,,,,,,,,,,32,1,4.000000e+000,7.781982e-004,0.000000e+000,0,,0,
1524375250.145,,0.000000e+000,3.499872e+001,-1.198782e-005,0.000000e+000,2,9.376898e-001,0.000000e+000,,,,,,,,,,,,,,32,1,4.000000e+000,0.000000e+000,0.000000e+000,0,,0,
1524375288.431,,0.000000e+000,3.499989e+001,-1.190170e-005,0.000000e+000,2,9.366217e-001,0.000000e+000,,,,,,,,,,,,,,32,1,4.000000e+000,2.342224e-003,0.000000e+000,0,,0,
1524375325.991,,0.000000e+000,3.499833e+001,-1.183518e-005,0.000000e+000,2,9.353039e-001,0.000000e+000,,,,,,,,,,,,,,32,1,4.000000e+000,2.349854e-003,0.000000e+000,0,,0,
1524375364.702,,0.000000e+000,3.499872e+001,-1.177482e-005,0.000000e+000,2,9.357024e-001,0.000000e+000,,,,,,,,,,,,,,32,1,4.000000e+000,0.000000e+000,0.000000e+000,0,,0,
1524375402.453,,0.000000e+000,3.499872e+001,-1.176924e-005,0.000000e+000,2,9.352691e-001,0.000000e+000,,,,,,,,,,,,,,32,1,4.000000e+000,1.560211e-003,0.000000e+000,0,,0,
1524375440.301,,0.000000e+000,3.499833e+001,-1.167323e-005,0.000000e+000,2,9.341007e-001,0.000000e+000,,,,,,,,,,,,,,32,1,4.000000e+000,7.781982e-004,0.000000e+000,0,,0,
1524375478.424,,0.000000e+000,3.499872e+001,-1.160950e-005,0.000000e+000,2,9.334507e-001,0.000000e+000,,,,,,,,,,,,,,32,1,4.000000e+000,0.000000e+000,0.000000e+000,0,,0,
1524375516.452,,0.000000e+000,3.499950e+001,-1.159004e-005,0.000000e+000,2,9.334809e-001,0.000000e+000,,,,,,,,,,,,,,32,1,4.000000e+000,1.560211e-003,0.000000e+000,0,,0,
1524375554.577,,0.000000e+000,3.499950e+001,-1.150617e-005,0.000000e+000,2,9.333975e-001,0.000000e+000,,,,,,,,,,,,,,32,1,4.000000e+000,0.000000e+000,0.000000e+000,0,,0,
1524375592.640,,0.000000e+000,3.499872e+001,-1.146991e-005,0.000000e+000,2,9.318208e-001,0.000000e+000,,,,,,,,,,,,,,32,1,4.000000e+000,0.000000e+000,0.000000e+000,0,,0,
1524375630.651,,0.000000e+000,3.499950e+001,-1.139329e-005,0.000000e+000,2,9.350134e-001,0.000000e+000,,,,,,,,,,,,,,32,1,4.000000e+000,3.120422e-003,0.000000e+000,0,,0,
1524375669.399,,0.000000e+000,3.499833e+001,-1.134122e-005,0.000000e+000,2,9.335257e-001,0.000000e+000,,,,,,,,,,,,,,32,1,4.000000e+000,7.781982e-004,0.000000e+000,0,,0,
1524375707.909,,0.000000e+000,3.499872e+001,-1.128253e-005,0.000000e+000,2,9.301444e-001,0.000000e+000,,,,,,,,,,,,,,32,1,4.000000e+000,0.000000e+000,0.000000e+000,0,,0,
1524375745.845,,0.000000e+000,3.499911e+001,-1.124767e-005,0.000000e+000,2,9.333484e-001,0.000000e+000,,,,,,,,,,,,,,32,1,4.000000e+000,7.820129e-004,0.000000e+000,0,,0,
1524375784.018,,0.000000e+000,3.499950e+001,-1.117177e-005,0.000000e+000,2,9.307872e-001,0.000000e+000,,,,,,,,,,,,,,32,1,4.000000e+000,0.000000e+000,0.000000e+000,0,,0,
1524375822.071,,0.000000e+000,3.500028e+001,-1.112560e-005,0.000000e+000,2,9.327643e-001,0.000000e+000,,,,,,,,,,,,,,32,1,4.000000e+000,0.000000e+000,0.000000e+000,0,,0,
1524375860.152,,0.000000e+000,3.499833e+001,-1.108147e-005,0.000000e+000,2,9.311552e-001,0.000000e+000,,,,,,,,,,,,,,32,1,4.000000e+000,7.781982e-004,0.000000e+000,0,,0,
1524375897.910,,0.000000e+000,3.499950e+001,-1.104429e-005,0.000000e+000,2,9.301828e-001,0.000000e+000,,,,,,,,,,,,,,32,1,4.000000e+000,3.120422e-003,0.000000e+000,0,,0,
1524375935.828,,0.000000e+000,3.499950e+001,-1.099408e-005,0.000000e+000,2,9.317173e-001,0.000000e+000,,,,,,,,,,,,,,32,1,4.000000e+000,1.560211e-003,0.000000e+000,0,,0,
1524375973.846,,0.000000e+000,3.499872e+001,-1.096381e-005,0.000000e+000,2,9.316268e-001,0.000000e+000,,,,,,,,,,,,,,32,1,4.000000e+000,1.560211e-003,0.000000e+000,0,,0,
1524376011.714,,0.000000e+000,3.499872e+001,-1.088394e-005,0.000000e+000,2,9.273123e-001,0.000000e+000,,,,,,,,,,,,,,32,1,4.000000e+000,0.000000e+000,0.000000e+000,0,,0,
1524376049.154,,0.000000e+000,3.499872e+001,-1.082364e-005,0.000000e+000,2,9.320558e-001,0.000000e+000,,,,,,,,,,,,,,32,1,4.000000e+000,0.000000e+000,0.000000e+000,0,,0,
1524376087.218,,0.000000e+000,3.499911e+001,-1.078909e-005,0.000000e+000,2,9.303923e-001,0.000000e+000,,,,,,,,,,,,,,32,1,4.000000e+000,7.820129e-004,0.000000e+000,0,,0,
1524376124.748,,0.000000e+000,3.499911e+001,-1.081722e-005,0.000000e+000,2,9.308233e-001,0.000000e+000,,,,,,,,,,,,,,32,1,4.000000e+000,2.338409e-003,0.000000e+000,0,,0,
1524376162.814,,0.000000e+000,3.499872e+001,-1.072725e-005,0.000000e+000,2,9.295030e-001,0.000000e+000,,,,,,,,,,,,,,32,1,4.000000e+000,0.000000e+000,0.000000e+000,0,,0,
1524376200.904,,0.000000e+000,3.499950e+001,-1.067625e-005,0.000000e+000,2,9.311215e-001,0.000000e+000,,,,,,,,,,,,,,32,1,4.000000e+000,0.000000e+000,0.000000e+000,0,,0,
1524376239.037,,0.000000e+000,3.499950e+001,-1.061852e-005,0.000000e+000,2,9.287651e-001,0.000000e+000,,,,,,,,,,,,,,32,1,4.000000e+000,1.560211e-003,0.000000e+000,0,,0,
1524376277.040,,0.000000e+000,3.499833e+001,-1.057982e-005,0.000000e+000,2,9.295560e-001,0.000000e+000,,,,,,,,,,,,,,32,1,4.000000e+000,7.781982e-004,0.000000e+000,0,,0,
1524376315.101,,0.000000e+000,3.499833e+001,-1.054123e-005,0.000000e+000,2,9.294652e-001,0.000000e+000,,,,,,,,,,,,,,32,1,4.000000e+000,7.781982e-004,0.000000e+000,0,,0,
1524376353.176,,0.000000e+000,3.500067e+001,-1.049710e-005,0.000000e+000,2,9.308674e-001,0.000000e+000,,,,,,,,,,,,,,32,1,4.000000e+000,7.820129e-004,0.000000e+000,0,,0,
1524376391.274,,0.000000e+000,3.499871e+001,-1.047220e-005,0.000000e+000,2,9.273924e-001,0.000000e+000,,,,,,,,,,,,,,32,1,4.000000e+000,3.128052e-003,0.000000e+000,0,,0,
1524376429.347,,0.000000e+000,3.499911e+001,-1.039678e-005,0.000000e+000,2,9.285895e-001,0.000000e+000,,,,,,,,,,,,,,32,1,4.000000e+000,7.820129e-004,0.000000e+000,0,,0,
1524376467.686,,0.000000e+000,3.499950e+001,-1.032528e-005,0.000000e+000,2,9.285128e-001,0.000000e+000,,,,,,,,,,,,,,32,1,4.000000e+000,0.000000e+000,0.000000e+000,0,,0,
1524376504.956,,0.000000e+000,3.499911e+001,-1.030446e-005,0.000000e+000,2,9.255129e-001,0.000000e+000,,,,,,,,,,,,,,32,1,4.000000e+000,7.820129e-004,0.000000e+000,0,,0,
1524376543.537,,0.000000e+000,3.499950e+001,-1.028254e-005,0.000000e+000,2,9.288576e-001,0.000000e+000,,,,,,,,,,,,,,32,1,4.000000e+000,0.000000e+000,0.000000e+000,0,,0,
1524376579.990,,0.000000e+000,3.499950e+001,-1.024011e-005,0.000000e+000,2,9.262399e-001,0.000000e+000,,,,,,,,,,,,,,32,1,4.000000e+000,3.120422e-003,0.000000e+000,0,,0,
1524376617.955,,0.000000e+000,3.499911e+001,-1.018684e-005,0.000000e+000,2,9.239176e-001,0.000000e+000,,,,,,,,,,,,,,32,1,4.000000e+000,7.820129e-004,0.000000e+000,0,,0,
1524376656.023,,0.000000e+000,3.499911e+001,-1.012420e-005,0.000000e+000,2,9.256504e-001,0.000000e+000,,,,,,,,,,,,,,32,1,4.000000e+000,7.820129e-004,0.000000e+000,0,,0,
1524376693.774,,0.000000e+000,3.499871e+001,-1.010265e-005,0.000000e+000,2,9.247755e-001,0.000000e+000,,,,,,,,,,,,,,32,1,4.000000e+000,3.128052e-003,0.000000e+000,0,,0,
1524376732.227,,0.000000e+000,3.499950e+001,-1.008397e-005,0.000000e+000,2,9.261134e-001,0.000000e+000,,,,,,,,,,,,,,32,1,4.000000e+000,1.560211e-003,0.000000e+000,0,,0,
1524376770.815,,0.000000e+000,3.499871e+001,-1.001636e-005,0.000000e+000,2,9.220641e-001,0.000000e+000,,,,,,,,,,,,,,32,1,4.000000e+000,3.128052e-003,0.000000e+000,0,,0,
1524376809.676,,0.000000e+000,3.499911e+001,-9.994332e-006,0.000000e+000,2,9.235111e-001,0.000000e+000,,,,,,,,,,,,,,32,1,4.000000e+000,7.820129e-004,0.000000e+000,0,,0,
1524376847.749,,0.000000e+000,3.499793e+001,-9.949163e-006,0.000000e+000,2,9.247026e-001,0.000000e+000,,,,,,,,,,,,,,32,1,4.000000e+000,1.567841e-003,0.000000e+000,0,,0,
1524376886.127,,0.000000e+000,3.499871e+001,-9.926039e-006,0.000000e+000,2,9.229960e-001,0.000000e+000,,,,,,,,,,,,,,32,1,4.000000e+000,3.128052e-003,0.000000e+000,0,,0,
1524376924.850,,0.000000e+000,3.499989e+001,-9.875745e-006,0.000000e+000,2,9.239333e-001,0.000000e+000,,,,,,,,,,,,,,32,1,4.000000e+000,2.342224e-003,0.000000e+000,0,,0,
1524376962.888,,0.000000e+000,3.500068e+001,-9.832629e-006,0.000000e+000,2,9.231428e-001,0.000000e+000,,,,,,,,,,,,,,32,1,4.000000e+000,5.470276e-003,0.000000e+000,0,,0,
1524377000.853,,0.000000e+000,3.499989e+001,-9.767247e-006,0.000000e+000,2,9.193994e-001,0.000000e+000,,,,,,,,,,,,,,32,1,4.000000e+000,7.781982e-004,0.000000e+000,0,,0,
1524377038.809,,0.000000e+000,3.499911e+001,-9.739540e-006,0.000000e+000,2,9.221332e-001,0.000000e+000,,,,,,,,,,,,,,32,1,4.000000e+000,7.820129e-004,0.000000e+000,0,,0,
1524377076.834,,0.000000e+000,3.499950e+001,-9.698039e-006,0.000000e+000,2,9.222950e-001,0.000000e+000,,,,,,,,,,,,,,32,1,4.000000e+000,0.000000e+000,0.000000e+000,0,,0,
1524377115.088,,0.000000e+000,3.499793e+001,-9.676749e-006,0.000000e+000,2,9.206692e-001,0.000000e+000,,,,,,,,,,,,,,32,1,4.000000e+000,3.131866e-003,0.000000e+000,0,,0,
1524377153.403,,0.000000e+000,3.499715e+001,-9.650199e-006,0.000000e+000,2,9.247916e-001,0.000000e+000,,,,,,,,,,,,,,32,1,4.000000e+000,6.248474e-003,0.000000e+000,0,,0,
1524377191.931,,0.000000e+000,3.499950e+001,-9.609405e-006,0.000000e+000,2,9.244024e-001,0.000000e+000,,,,,,,,,,,,,,32,1,4.000000e+000,1.560211e-003,0.000000e+000,0,,0,
1524377229.959,,0.000000e+000,3.499872e+001,-9.579126e-006,0.000000e+000,2,9.236962e-001,0.000000e+000,,,,,,,,,,,,,,32,1,4.000000e+000,0.000000e+000,0.000000e+000,0,,0,
1524377267.625,,0.000000e+000,3.499872e+001,-9.550401e-006,0.000000e+000,2,9.237335e-001,0.000000e+000,,,,,,,,,,,,,,32,1,4.000000e+000,0.000000e+000,0.000000e+000,0,,0,
1524377306.140,,0.000000e+000,3.499911e+001,-9.513180e-006,0.000000e+000,2,9.228467e-001,0.000000e+000,,,,,,,,,,,,,,32,1,4.000000e+000,7.820129e-004,0.000000e+000,0,,0,
1524377343.763,,0.000000e+000,3.499911e+001,-9.497725e-006,0.000000e+000,2,9.238709e-001,0.000000e+000,,,,,,,,,,,,,,32,1,4.000000e+000,7.820129e-004,0.000000e+000,0,,0,
1524377381.817,,0.000000e+000,3.499911e+001,-9.444843e-006,0.000000e+000,2,9.198266e-001,0.000000e+000,,,,,,,,,,,,,,32,1,4.000000e+000,7.820129e-004,0.000000e+000,0,,0,
1524377419.875,,0.000000e+000,3.499911e+001,-9.444140e-006,0.000000e+000,2,9.183103e-001,0.000000e+000,,,,,,,,,,,,,,32,1,4.000000e+000,7.820129e-004,0.000000e+000,0,,0,
1524377457.968,,0.000000e+000,3.499911e+001,-9.378519e-006,0.000000e+000,2,9.207751e-001,0.000000e+000,,,,,,,,,,,,,,32,1,4.000000e+000,7.820129e-004,0.000000e+000,0,,0,
1524377496.361,,0.000000e+000,3.499950e+001,-9.339556e-006,0.000000e+000,2,9.211363e-001,0.000000e+000,,,,,,,,,,,,,,32,1,4.000000e+000,0.000000e+000,0.000000e+000,0,,0,
1524377534.916,,0.000000e+000,3.499833e+001,-9.320685e-006,0.000000e+000,2,9.177791e-001,0.000000e+000,,,,,,,,,,,,,,32,1,4.000000e+000,7.781982e-004,0.000000e+000,0,,0,
1524377573.577,,0.000000e+000,3.499911e+001,-9.283478e-006,0.000000e+000,2,9.189513e-001,0.000000e+000,,,,,,,,,,,,,,32,1,4.000000e+000,7.820129e-004,0.000000e+000,0,,0,
1524377611.115,,0.000000e+000,3.499911e+001,-9.275878e-006,0.000000e+000,2,9.195879e-001,0.000000e+000,,,,,,,,,,,,,,32,1,4.000000e+000,7.820129e-004,0.000000e+000,0,,0,
1524377649.158,,0.000000e+000,3.499833e+001,-9.186542e-006,0.000000e+000,2,9.191350e-001,0.000000e+000,,,,,,,,,,,,,,32,1,4.000000e+000,2.349854e-003,0.000000e+000,0,,0,
1524377687.228,,0.000000e+000,3.499872e+001,-9.184376e-006,0.000000e+000,2,9.167973e-001,0.000000e+000,,,,,,,,,,,,,,32,1,4.000000e+000,0.000000e+000,0.000000e+000,0,,0,
1524377725.624,,0.000000e+000,3.499950e+001,-9.184231e-006,0.000000e+000,2,9.162054e-001,0.000000e+000,,,,,,,,,,,,,,32,1,4.000000e+000,0.000000e+000,0.000000e+000,0,,0,
1524377763.385,,0.000000e+000,3.499911e+001,-9.148129e-006,0.000000e+000,2,9.186876e-001,0.000000e+000,,,,,,,,,,,,,,32,1,4.000000e+000,7.820129e-004,0.000000e+000,0,,0,
1524377801.315,,0.000000e+000,3.499950e+001,-9.066804e-006,0.000000e+000,2,9.181291e-001,0.000000e+000,,,,,,,,,,,,,,32,1,4.000000e+000,1.560211e-003,0.000000e+000,0,,0,
1524377839.711,,0.000000e+000,3.499950e+001,-9.051315e-006,0.000000e+000,2,9.171984e-001,0.000000e+000,,,,,,,,,,,,,,32,1,4.000000e+000,0.000000e+000,0.000000e+000,0,,0,
1524377877.549,,0.000000e+000,3.500224e+001,-9.021980e-006,0.000000e+000,2,9.169782e-001,0.000000e+000,,,,,,,,,,,,,,32,1,4.000000e+000,2.349854e-003,0.000000e+000,0,,0,
1524377915.679,,0.000000e+000,3.499793e+001,-8.979946e-006,0.000000e+000,2,9.156084e-001,0.000000e+000,,,,,,,,,,,,,,32,1,4.000000e+000,1.567841e-003,0.000000e+000,0,,0,
1524377953.550,,0.000000e+000,3.500067e+001,-8.973965e-006,0.000000e+000,2,9.153031e-001,0.000000e+000,,,,,,,,,,,,,,32,1,4.000000e+000,3.910065e-003,0.000000e+000,0,,0,
1524377991.670,,0.000000e+000,3.499989e+001,-8.940755e-006,0.000000e+000,2,9.135852e-001,0.000000e+000,,,,,,,,,,,,,,32,1,4.000000e+000,2.342224e-003,0.000000e+000,0,,0,
1524378030.354,,0.000000e+000,3.499950e+001,-8.909592e-006,0.000000e+000,2,9.138899e-001,0.000000e+000,,,,,,,,,,,,,,32,1,4.000000e+000,0.000000e+000,0.000000e+000,0,,0,
1524378068.472,,0.000000e+000,3.499872e+001,-8.873457e-006,0.000000e+000,2,9.119903e-001,0.000000e+000,,,,,,,,,,,,,,32,1,4.000000e+000,1.560211e-003,0.000000e+000,0,,0,
1524378106.512,,0.000000e+000,3.500028e+001,-8.830563e-006,0.000000e+000,2,9.121979e-001,0.000000e+000,,,,,,,,,,,,,,32,1,4.000000e+000,1.560211e-003,0.000000e+000,0,,0,
1524378144.538,,0.000000e+000,3.499872e+001,-8.805305e-006,0.000000e+000,2,9.125552e-001,0.000000e+000,,,,,,,,,,,,,,32,1,4.000000e+000,1.560211e-003,0.000000e+000,0,,0,
1524378182.618,,0.000000e+000,3.499950e+001,-8.790743e-006,0.000000e+000,2,9.114931e-001,0.000000e+000,,,,,,,,,,,,,,32,1,4.000000e+000,0.000000e+000,0.000000e+000,0,,0,
1524378220.659,,0.000000e+000,3.499833e+001,-8.742272e-006,0.000000e+000,2,9.133672e-001,0.000000e+000,,,,,,,,,,,,,,32,1,4.000000e+000,7.781982e-004,0.000000e+000,0,,0,
1524378258.752,,0.000000e+000,3.499872e+001,-8.723111e-006,0.000000e+000,2,9.110960e-001,0.000000e+000,,,,,,,,,,,,,,32,1,4.000000e+000,0.000000e+000,0.000000e+000,0,,0,
1524378296.982,,0.000000e+000,3.499833e+001,-8.682042e-006,0.000000e+000,2,9.118717e-001,0.000000e+000,,,,,,,,,,,,,,32,1,4.000000e+000,7.781982e-004,0.000000e+000,0,,0,
1524378335.020,,0.000000e+000,3.499833e+001,-8.657403e-006,0.000000e+000,2,9.100878e-001,0.000000e+000,,,,,,,,,,,,,,32,1,4.000000e+000,7.781982e-004,0.000000e+000,0,,0,
1524378372.056,,0.000000e+000,3.499911e+001,-8.687840e-006,0.000000e+000,2,9.162604e-001,0.000000e+000,,,,,,,,,,,,,,32,1,4.000000e+000,7.820129e-004,0.000000e+000,0,,0,
1524378410.129,,0.000000e+000,3.499833e+001,-8.619089e-006,0.000000e+000,2,9.122889e-001,0.000000e+000,,,,,,,,,,,,,,32,1,4.000000e+000,2.349854e-003,0.000000e+000,0,,0,
1524378449.115,,0.000000e+000,3.499872e+001,-8.610213e-006,0.000000e+000,2,9.126379e-001,0.000000e+000,,,,,,,,,,,,,,32,1,4.000000e+000,1.560211e-003,0.000000e+000,0,,0,
1524378486.658,,0.000000e+000,3.499911e+001,-8.584611e-006,0.000000e+000,2,9.130245e-001,0.000000e+000,,,,,,,,,,,,,,32,1,4.000000e+000,7.820129e-004,0.000000e+000,0,,0,
1524378524.761,,0.000000e+000,3.499793e+001,-8.515996e-006,0.000000e+000,2,9.100947e-001,0.000000e+000,,,,,,,,,,,,,,32,1,4.000000e+000,3.131866e-003,0.000000e+000,0,,0,
1524378562.809,,0.000000e+000,3.499911e+001,-8.543190e-006,0.000000e+000,2,9.109235e-001,0.000000e+000,,,,,,,,,,,,,,32,1,4.000000e+000,7.820129e-004,0.000000e+000,0,,0,
1524378600.207,,0.000000e+000,3.499872e+001,-8.486998e-006,0.000000e+000,2,9.090252e-001,0.000000e+000,,,,,,,,,,,,,,32,1,4.000000e+000,1.560211e-003,0.000000e+000,0,,0,
1524378638.385,,0.000000e+000,3.499833e+001,-8.472121e-006,0.000000e+000,2,9.093145e-001,0.000000e+000,,,,,,,,,,,,,,32,1,4.000000e+000,2.349854e-003,0.000000e+000,0,,0,
1524378676.463,,0.000000e+000,3.499950e+001,-8.458934e-006,0.000000e+000,2,9.100552e-001,0.000000e+000,,,,,,,,,,,,,,32,1,4.000000e+000,0.000000e+000,0.000000e+000,0,,0,
1524378714.529,,0.000000e+000,3.499833e+001,-8.397206e-006,0.000000e+000,2,9.108300e-001,0.000000e+000,,,,,,,,,,,,,,32,1,4.000000e+000,7.781982e-004,0.000000e+000,0,,0,
1524378753.129,,0.000000e+000,3.499872e+001,-8.375220e-006,0.000000e+000,2,9.080785e-001,0.000000e+000,,,,,,,,,,,,,,32,1,4.000000e+000,0.000000e+000,0.000000e+000,0,,0,
1524378790.672,,0.000000e+000,3.499950e+001,-8.368355e-006,0.000000e+000,2,9.103647e-001,0.000000e+000,,,,,,,,,,,,,,32,1,4.000000e+000,1.560211e-003,0.000000e+000,0,,0,
1524378828.718,,0.000000e+000,3.499950e+001,-8.318912e-006,0.000000e+000,2,9.075533e-001,0.000000e+000,,,,,,,,,,,,,,32,1,4.000000e+000,0.000000e+000,0.000000e+000,0,,0,
1524378866.766,,0.000000e+000,3.499872e+001,-8.315872e-006,0.000000e+000,2,9.096460e-001,0.000000e+000,,,,,,,,,,,,,,32,1,4.000000e+000,0.000000e+000,0.000000e+000,0,,0,
1524378904.844,,0.000000e+000,3.500028e+001,-8.305535e-006,0.000000e+000,2,9.097559e-001,0.000000e+000,,,,,,,,,,,,,,32,1,4.000000e+000,1.560211e-003,0.000000e+000,0,,0,
1524378942.904,,0.000000e+000,3.499950e+001,-8.239889e-006,0.000000e+000,2,9.062732e-001,0.000000e+000,,,,,,,,,,,,,,32,1,4.000000e+000,1.560211e-003,0.000000e+000,0,,0,
1524378980.992,,0.000000e+000,3.499833e+001,-8.234464e-006,0.000000e+000,2,9.092881e-001,0.000000e+000,,,,,,,,,,,,,,32,1,4.000000e+000,7.781982e-004,0.000000e+000,0,,0,
1524379018.381,,0.000000e+000,3.499872e+001,-8.219632e-006,0.000000e+000,2,9.081147e-001,0.000000e+000,,,,,,,,,,,,,,32,1,4.000000e+000,0.000000e+000,0.000000e+000,0,,0,
1524379056.456,,0.000000e+000,3.499833e+001,-8.194659e-006,0.000000e+000,2,9.086050e-001,0.000000e+000,,,,,,,,,,,,,,32,1,4.000000e+000,7.781982e-004,0.000000e+000,0,,0,
1524379094.517,,0.000000e+000,3.499989e+001,-8.150764e-006,0.000000e+000,2,9.105281e-001,0.000000e+000,,,,,,,,,,,,,,32,1,4.000000e+000,7.781982e-004,0.000000e+000,0,,0,
1524379132.532,,0.000000e+000,3.499911e+001,-8.147770e-006,0.000000e+000,2,9.045263e-001,0.000000e+000,,,,,,,,,,,,,,32,1,4.000000e+000,2.338409e-003,0.000000e+000,0,,0,
1524379170.703,,0.000000e+000,3.499911e+001,-8.109756e-006,0.000000e+000,2,9.067999e-001,0.000000e+000,,,,,,,,,,,,,,32,1,4.000000e+000,7.820129e-004,0.000000e+000,0,,0,
1524379208.771,,0.000000e+000,3.499950e+001,-8.087849e-006,0.000000e+000,2,9.059378e-001,0.000000e+000,,,,,,,,,,,,,,32,1,4.000000e+000,0.000000e+000,0.000000e+000,0,,0,
1524379246.971,,0.000000e+000,3.499989e+001,-8.070129e-006,0.000000e+000,2,9.055611e-001,0.000000e+000,,,,,,,,,,,,,,32,1,4.000000e+000,7.781982e-004,0.000000e+000,0,,0,
1524379284.294,,0.000000e+000,3.500067e+001,-8.028018e-006,0.000000e+000,2,9.042647e-001,0.000000e+000,,,,,,,,,,,,,,32,1,4.000000e+000,7.820129e-004,0.000000e+000,0,,0,
1524379322.450,,0.000000e+000,3.499911e+001,-7.961798e-006,0.000000e+000,2,9.051335e-001,0.000000e+000,,,,,,,,,,,,,,32,1,4.000000e+000,7.820129e-004,0.000000e+000,0,,0,
1524379361.011,,0.000000e+000,3.499950e+001,-7.944290e-006,0.000000e+000,2,9.028134e-001,0.000000e+000,,,,,,,,,,,,,,32,1,4.000000e+000,1.560211e-003,0.000000e+000,0,,0,
1524379398.531,,0.000000e+000,3.499989e+001,-7.962217e-006,0.000000e+000,2,9.058281e-001,0.000000e+000,,,,,,,,,,,,,,32,1,4.000000e+000,7.781982e-004,0.000000e+000,0,,0,
1524379435.724,,0.000000e+000,3.499715e+001,-7.968111e-006,0.000000e+000,2,9.036763e-001,0.000000e+000,,,,,,,,,,,,,,32,1,4.000000e+000,3.128052e-003,0.000000e+000,0,,0,
1524379474.185,,0.000000e+000,3.499754e+001,-7.877024e-006,0.000000e+000,2,9.032260e-001,0.000000e+000,,,,,,,,,,,,,,32,1,4.000000e+000,7.896423e-004,0.000000e+000,0,,0,
1524379512.223,,0.000000e+000,3.499950e+001,-7.830947e-006,0.000000e+000,2,9.027146e-001,0.000000e+000,,,,,,,,,,,,,,32,1,4.000000e+000,0.000000e+000,0.000000e+000,0,,0,
1524379549.891,,0.000000e+000,3.499911e+001,-7.854283e-006,0.000000e+000,2,9.042256e-001,0.000000e+000,,,,,,,,,,,,,,32,1,4.000000e+000,7.820129e-004,0.000000e+000,0,,0,
1524379587.999,,0.000000e+000,3.499950e+001,-7.810297e-006,0.000000e+000,2,9.036942e-001,0.000000e+000,,,,,,,,,,,,,,32,1,4.000000e+000,0.000000e+000,0.000000e+000,0,,0,
1524379625.494,,0.000000e+000,3.499872e+001,-7.868518e-006,0.000000e+000,2,9.105294e-001,0.000000e+000,,,,,,,,,,,,,,32,1,4.000000e+000,0.000000e+000,0.000000e+000,0,,0,
1524379663.137,,0.000000e+000,3.499872e+001,-7.814462e-006,0.000000e+000,2,9.067623e-001,0.000000e+000,,,,,,,,,,,,,,32,1,4.000000e+000,1.560211e-003,0.000000e+000,0,,0,
1524379701.966,,0.000000e+000,3.499989e+001,-7.751284e-006,0.000000e+000,2,9.018767e-001,0.000000e+000,,,,,,,,,,,,,,32,1,4.000000e+000,7.781982e-004,0.000000e+000,0,,0,
1524379739.241,,0.000000e+000,3.499950e+001,-7.763410e-006,0.000000e+000,2,9.001929e-001,0.000000e+000,,,,,,,,,,,,,,32,1,4.000000e+000,1.560211e-003,0.000000e+000,0,,0,
1524379777.322,,0.000000e+000,3.499950e+001,-7.794992e-006,0.000000e+000,2,9.048004e-001,0.000000e+000,,,,,,,,,,,,,,32,1,4.000000e+000,0.000000e+000,0.000000e+000,0,,0,
1524379814.552,,0.000000e+000,3.499950e+001,-7.724312e-006,0.000000e+000,2,9.026672e-001,0.000000e+000,,,,,,,,,,,,,,32,1,4.000000e+000,1.560211e-003,0.000000e+000,0,,0,
1524379852.655,,0.000000e+000,3.499950e+001,-7.698542e-006,0.000000e+000,2,9.008595e-001,0.000000e+000,,,,,,,,,,,,,,32,1,4.000000e+000,0.000000e+000,0.000000e+000,0,,0,
1524379890.706,,0.000000e+000,3.499950e+001,-7.652332e-006,0.000000e+000,2,9.007557e-001,0.000000e+000,,,,,,,,,,,,,,32,1,4.000000e+000,1.560211e-003,0.000000e+000,0,,0,
1524379928.779,,0.000000e+000,3.500028e+001,-7.638964e-006,0.000000e+000,2,9.016914e-001,0.000000e+000,,,,,,,,,,,,,,32,1,4.000000e+000,1.560211e-003,0.000000e+000,0,,0,
1524379966.807,,0.000000e+000,3.499715e+001,-7.616825e-006,0.000000e+000,2,8.990034e-001,0.000000e+000,,,,,,,,,,,,,,32,1,4.000000e+000,1.571655e-003,0.000000e+000,0,,0,
1524380004.850,,0.000000e+000,3.500028e+001,-7.598036e-006,0.000000e+000,2,9.019099e-001,0.000000e+000,,,,,,,,,,,,,,32,1,4.000000e+000,0.000000e+000,0.000000e+000,0,,0,
1524380042.911,,0.000000e+000,3.500028e+001,-7.559613e-006,0.000000e+000,2,8.999782e-001,0.000000e+000,,,,,,,,,,,,,,32,1,4.000000e+000,1.560211e-003,0.000000e+000,0,,0,
1524380080.976,,0.000000e+000,3.499950e+001,-7.573266e-006,0.000000e+000,2,9.011880e-001,0.000000e+000,,,,,,,,,,,,,,32,1,4.000000e+000,1.560211e-003,0.000000e+000,0,,0,
1524380119.059,,0.000000e+000,3.499754e+001,-7.524038e-006,0.000000e+000,2,9.008059e-001,0.000000e+000,,,,,,,,,,,,,,32,1,4.000000e+000,7.896423e-004,0.000000e+000,0,,0,
1524380157.137,,0.000000e+000,3.499950e+001,-7.501105e-006,0.000000e+000,2,8.977636e-001,0.000000e+000,,,,,,,,,,,,,,32,1,4.000000e+000,0.000000e+000,0.000000e+000,0,,0,
1524380195.158,,0.000000e+000,3.500106e+001,-7.522071e-006,0.000000e+000,2,8.994333e-001,0.000000e+000,,,,,,,,,,,,,,32,1,4.000000e+000,4.692078e-003,0.000000e+000,0,,0,
1524380232.881,,0.000000e+000,3.499872e+001,-7.481614e-006,0.000000e+000,2,9.004208e-001,0.000000e+000,,,,,,,,,,,,,,32,1,4.000000e+000,1.560211e-003,0.000000e+000,0,,0,
1524380270.949,,0.000000e+000,3.499911e+001,-7.431428e-006,0.000000e+000,2,8.997340e-001,0.000000e+000,,,,,,,,,,,,,,32,1,4.000000e+000,7.820129e-004,0.000000e+000,0,,0,
1524380308.819,,0.000000e+000,3.499950e+001,-7.416380e-006,0.000000e+000,2,8.994247e-001,0.000000e+000,,,,,,,,,,,,,,32,1,4.000000e+000,0.000000e+000,0.000000e+000,0,,0,
1524380346.625,,0.000000e+000,3.499872e+001,-7.381367e-006,0.000000e+000,2,8.936835e-001,0.000000e+000,,,,,,,,,,,,,,32,1,4.000000e+000,0.000000e+000,0.000000e+000,0,,0,
1524380384.321,,0.000000e+000,3.499950e+001,-7.366385e-006,0.000000e+000,2,9.003199e-001,0.000000e+000,,,,,,,,,,,,,,32,1,4.000000e+000,0.000000e+000,0.000000e+000,0,,0,
1524380422.996,,0.000000e+000,3.499793e+001,-7.338146e-006,0.000000e+000,2,8.907961e-001,0.000000e+000,,,,,,,,,,,,,,32,1,4.000000e+000,3.131866e-003,0.000000e+000,0,,0,
1524380461.009,,0.000000e+000,3.499833e+001,-7.347434e-006,0.000000e+000,2,8.964729e-001,0.000000e+000,,,,,,,,,,,,,,32,1,4.000000e+000,7.781982e-004,0.000000e+000,0,,0,
1524380498.565,,0.000000e+000,3.499911e+001,-7.303036e-006,0.000000e+000,2,8.974044e-001,0.000000e+000,,,,,,,,,,,,,,32,1,4.000000e+000,7.820129e-004,0.000000e+000,0,,0,
1524380536.638,,0.000000e+000,3.500067e+001,-7.242244e-006,0.000000e+000,2,8.919677e-001,0.000000e+000,,,,,,,,,,,,,,32,1,4.000000e+000,2.338409e-003,0.000000e+000,0,,0,
1524380574.046,,0.000000e+000,3.499794e+001,-7.255996e-006,0.000000e+000,2,8.971327e-001,0.000000e+000,,,,,,,,,,,,,,32,1,4.000000e+000,0.000000e+000,0.000000e+000,0,,0,
1524380612.159,,0.000000e+000,3.499989e+001,-7.239148e-006,0.000000e+000,2,8.996069e-001,0.000000e+000,,,,,,,,,,,,,,32,1,4.000000e+000,2.342224e-003,0.000000e+000,0,,0,
1524380650.067,,0.000000e+000,3.499911e+001,-7.218744e-006,0.000000e+000,2,8.922872e-001,0.000000e+000,,,,,,,,,,,,,,32,1,4.000000e+000,7.820129e-004,0.000000e+000,0,,0,
1524380688.360,,0.000000e+000,3.499872e+001,-7.201469e-006,0.000000e+000,2,8.967762e-001,0.000000e+000,,,,,,,,,,,,,,32,1,4.000000e+000,0.000000e+000,0.000000e+000,0,,0,
1524380725.788,,0.000000e+000,3.499911e+001,-7.167848e-006,0.000000e+000,2,8.938327e-001,0.000000e+000,,,,,,,,,,,,,,32,1,4.000000e+000,7.820129e-004,0.000000e+000,0,,0,
1524380763.971,,0.000000e+000,3.500028e+001,-7.133783e-006,0.000000e+000,2,8.907372e-001,0.000000e+000,,,,,,,,,,,,,,32,1,4.000000e+000,1.560211e-003,0.000000e+000,0,,0,
1524380802.039,,0.000000e+000,3.499911e+001,-7.119333e-006,0.000000e+000,2,8.920981e-001,0.000000e+000,,,,,,,,,,,,,,32,1,4.000000e+000,2.338409e-003,0.000000e+000,0,,0,
1524380839.722,,0.000000e+000,3.499911e+001,-7.124158e-006,0.000000e+000,2,8.946463e-001,0.000000e+000,,,,,,,,,,,,,,32,1,4.000000e+000,7.820129e-004,0.000000e+000,0,,0,
1524380877.353,,0.000000e+000,3.499911e+001,-7.093552e-006,0.000000e+000,2,8.961335e-001,0.000000e+000,,,,,,,,,,,,,,32,1,4.000000e+000,7.820129e-004,0.000000e+000,0,,0,
1524380915.861,,0.000000e+000,3.499911e+001,-7.095047e-006,0.000000e+000,2,8.962851e-001,0.000000e+000,,,,,,,,,,,,,,32,1,4.000000e+000,7.820129e-004,0.000000e+000,0,,0,
1524380953.464,,0.000000e+000,3.499911e+001,-7.085961e-006,0.000000e+000,2,8.957288e-001,0.000000e+000,,,,,,,,,,,,,,32,1,4.000000e+000,7.820129e-004,0.000000e+000,0,,0,
1524380991.522,,0.000000e+000,3.499872e+001,-7.106630e-006,0.000000e+000,2,8.962472e-001,0.000000e+000,,,,,,,,,,,,,,32,1,4.000000e+000,0.000000e+000,0.000000e+000,0,,0,
1524381030.018,,0.000000e+000,3.499833e+001,-7.036640e-006,0.000000e+000,2,8.947718e-001,0.000000e+000,,,,,,,,,,,,,,32,1,4.000000e+000,7.781982e-004,0.000000e+000,0,,0,
1524381067.666,,0.000000e+000,3.499872e+001,-7.040501e-006,0.000000e+000,2,8.904893e-001,0.000000e+000,,,,,,,,,,,,,,32,1,4.000000e+000,0.000000e+000,0.000000e+000,0,,0,
1524381105.761,,0.000000e+000,3.499911e+001,-7.016499e-006,0.000000e+000,2,8.949383e-001,0.000000e+000,,,,,,,,,,,,,,32,1,4.000000e+000,7.820129e-004,0.000000e+000,0,,0,
1524381143.649,,0.000000e+000,3.499950e+001,-6.963283e-006,0.000000e+000,2,8.946693e-001,0.000000e+000,,,,,,,,,,,,,,32,1,4.000000e+000,0.000000e+000,0.000000e+000,0,,0,
1524381182.110,,0.000000e+000,3.499911e+001,-6.939033e-006,0.000000e+000,2,8.913233e-001,0.000000e+000,,,,,,,,,,,,,,32,1,4.000000e+000,7.820129e-004,0.000000e+000,0,,0,
1524381220.188,,0.000000e+000,3.499872e+001,-6.925151e-006,0.000000e+000,2,8.895400e-001,0.000000e+000,,,,,,,,,,,,,,32,1,4.000000e+000,1.560211e-003,0.000000e+000,0,,0,
1524381258.231,,0.000000e+000,3.500106e+001,-6.899670e-006,0.000000e+000,2,8.904244e-001,0.000000e+000,,,,,,,,,,,,,,32,1,4.000000e+000,1.560211e-003,0.000000e+000,0,,0,
1524381296.144,,0.000000e+000,3.499911e+001,-6.874146e-006,0.000000e+000,2,8.896561e-001,0.000000e+000,,,,,,,,,,,,,,32,1,4.000000e+000,2.338409e-003,0.000000e+000,0,,0,
1524381334.209,,0.000000e+000,3.499872e+001,-6.860653e-006,0.000000e+000,2,8.909902e-001,0.000000e+000,,,,,,,,,,,,,,32,1,4.000000e+000,1.560211e-003,0.000000e+000,0,,0,
1524381372.308,,0.000000e+000,3.499911e+001,-6.838794e-006,0.000000e+000,2,8.895000e-001,0.000000e+000,,,,,,,,,,,,,,32,1,4.000000e+000,2.338409e-003,0.000000e+000,0,,0,
1524381410.328,,0.000000e+000,3.499950e+001,-6.822757e-006,0.000000e+000,2,8.896809e-001,0.000000e+000,,,,,,,,,,,,,,32,1,4.000000e+000,0.000000e+000,0.000000e+000,0,,0,
1524381448.484,,0.000000e+000,3.499833e+001,-6.848334e-006,0.000000e+000,2,8.857450e-001,0.000000e+000,,,,,,,,,,,,,,32,1,4.000000e+000,7.781982e-004,0.000000e+000,0,,0,
1524381486.554,,0.000000e+000,3.499911e+001,-6.797136e-006,0.000000e+000,2,8.882905e-001,0.000000e+000,,,,,,,,,,,,,,32,1,4.000000e+000,7.820129e-004,0.000000e+000,0,,0,
1524381524.632,,0.000000e+000,3.499911e+001,-6.760595e-006,0.000000e+000,2,8.870547e-001,0.000000e+000,,,,,,,,,,,,,,32,1,4.000000e+000,7.820129e-004,0.000000e+000,0,,0,
1524381562.868,,0.000000e+000,3.499793e+001,-6.749560e-006,0.000000e+000,2,8.892863e-001,0.000000e+000,,,,,,,,,,,,,,32,1,4.000000e+000,1.567841e-003,0.000000e+000,0,,0,
1524381600.788,,0.000000e+000,3.499950e+001,-6.733211e-006,0.000000e+000,2,8.868545e-001,0.000000e+000,,,,,,,,,,,,,,32,1,4.000000e+000,0.000000e+000,0.000000e+000,0,,0,
1524381638.849,,0.000000e+000,3.499911e+001,-6.695675e-006,0.000000e+000,2,8.866346e-001,0.000000e+000,,,,,,,,,,,,,,32,1,4.000000e+000,7.820129e-004,0.000000e+000,0,,0,
1524381676.214,,0.000000e+000,3.499715e+001,-6.695056e-006,0.000000e+000,2,8.858997e-001,0.000000e+000,,,,,,,,,,,,,,32,1,4.000000e+000,4.692078e-003,0.000000e+000,0,,0,
1524381714.633,,0.000000e+000,3.499637e+001,-6.614386e-006,0.000000e+000,2,8.865733e-001,0.000000e+000,,,,,,,,,,,,,,32,1,4.000000e+000,1.560211e-003,0.000000e+000,0,,0,
1524381752.998,,0.000000e+000,3.499833e+001,-6.649068e-006,0.000000e+000,2,8.867075e-001,0.000000e+000,,,,,,,,,,,,,,32,1,4.000000e+000,7.781982e-004,0.000000e+000,0,,0,
1524381790.274,,0.000000e+000,3.499911e+001,-6.643154e-006,0.000000e+000,2,8.821951e-001,0.000000e+000,,,,,,,,,,,,,,32,1,4.000000e+000,2.338409e-003,0.000000e+000,0,,0,
1524381828.547,,0.000000e+000,3.499872e+001,-6.648644e-006,0.000000e+000,2,8.875430e-001,0.000000e+000,,,,,,,,,,,,,,32,1,4.000000e+000,0.000000e+000,0.000000e+000,0,,0,
1524381867.182,,0.000000e+000,3.499989e+001,-6.646898e-006,0.000000e+000,2,8.851731e-001,0.000000e+000,,,,,,,,,,,,,,32,1,4.000000e+000,7.781982e-004,0.000000e+000,0,,0,
1524381904.725,,0.000000e+000,3.499872e+001,-6.598134e-006,0.000000e+000,2,8.866101e-001,0.000000e+000,,,,,,,,,,,,,,32,1,4.000000e+000,0.000000e+000,0.000000e+000,0,,0,
1524381942.396,,0.000000e+000,3.499872e+001,-6.562299e-006,0.000000e+000,2,8.879001e-001,0.000000e+000,,,,,,,,,,,,,,32,1,4.000000e+000,1.560211e-003,0.000000e+000,0,,0,
1524381980.469,,0.000000e+000,3.499950e+001,-6.543809e-006,0.000000e+000,2,8.832204e-001,0.000000e+000,,,,,,,,,,,,,,32,1,4.000000e+000,0.000000e+000,0.000000e+000,0,,0,
1524382018.877,,0.000000e+000,3.499872e+001,-6.568146e-006,0.000000e+000,2,8.908449e-001,0.000000e+000,,,,,,,,,,,,,,32,1,4.000000e+000,1.560211e-003,0.000000e+000,0,,0,
1524382056.865,,0.000000e+000,3.499989e+001,-6.576963e-006,0.000000e+000,2,8.885448e-001,0.000000e+000,,,,,,,,,,,,,,32,1,4.000000e+000,7.781982e-004,0.000000e+000,0,,0,
1524382095.311,,0.000000e+000,3.500067e+001,-6.496108e-006,0.000000e+000,2,8.838193e-001,0.000000e+000,,,,,,,,,,,,,,32,1,4.000000e+000,3.910065e-003,0.000000e+000,0,,0,
1524382133.036,,0.000000e+000,3.500028e+001,-6.484450e-006,0.000000e+000,2,8.831952e-001,0.000000e+000,,,,,,,,,,,,,,32,1,4.000000e+000,1.560211e-003,0.000000e+000,0,,0,
1524382171.107,,0.000000e+000,3.499872e+001,-6.464204e-006,0.000000e+000,2,8.802481e-001,0.000000e+000,,,,,,,,,,,,,,32,1,4.000000e+000,1.560211e-003,0.000000e+000,0,,0,
1524382208.675,,0.000000e+000,3.499911e+001,-6.472805e-006,0.000000e+000,2,8.814676e-001,0.000000e+000,,,,,,,,,,,,,,32,1,4.000000e+000,7.820129e-004,0.000000e+000,0,,0,
1524382246.908,,0.000000e+000,3.499950e+001,-6.442143e-006,0.000000e+000,2,8.826560e-001,0.000000e+000,,,,,,,,,,,,,,32,1,4.000000e+000,1.560211e-003,0.000000e+000,0,,0,
1524382285.878,,0.000000e+000,3.499950e+001,-6.434282e-006,0.000000e+000,2,8.806461e-001,0.000000e+000,,,,,,,,,,,,,,32,1,4.000000e+000,0.000000e+000,0.000000e+000,0,,0,
1524382323.011,,0.000000e+000,3.499872e+001,-6.412646e-006,0.000000e+000,2,8.843870e-001,0.000000e+000,,,,,,,,,,,,,,32,1,4.000000e+000,1.560211e-003,0.000000e+000,0,,0,
1524382360.897,,0.000000e+000,3.499950e+001,-6.355763e-006,0.000000e+000,2,8.730457e-001,0.000000e+000,,,,,,,,,,,,,,32,1,4.000000e+000,0.000000e+000,0.000000e+000,0,,0,
1524382398.603,,0.000000e+000,3.499871e+001,-6.381781e-006,0.000000e+000,2,8.822896e-001,0.000000e+000,,,,,,,,,,,,,,32,1,4.000000e+000,3.128052e-003,0.000000e+000,0,,0,
1524382436.476,,0.000000e+000,3.499950e+001,-6.376765e-006,0.000000e+000,2,8.808028e-001,0.000000e+000,,,,,,,,,,,,,,32,1,4.000000e+000,0.000000e+000,0.000000e+000,0,,0,
1524382474.521,,0.000000e+000,3.499989e+001,-6.354031e-006,0.000000e+000,2,8.806425e-001,0.000000e+000,,,,,,,,,,,,,,32,1,4.000000e+000,2.342224e-003,0.000000e+000,0,,0,
1524382513.384,,0.000000e+000,3.499911e+001,-6.333922e-006,0.000000e+000,2,8.801457e-001,0.000000e+000,,,,,,,,,,,,,,32,1,4.000000e+000,7.820129e-004,0.000000e+000,0,,0,
1524382551.732,,0.000000e+000,3.499950e+001,-6.286425e-006,0.000000e+000,2,8.846490e-001,0.000000e+000,,,,,,,,,,,,,,32,1,4.000000e+000,0.000000e+000,0.000000e+000,0,,0,
1524382588.993,,0.000000e+000,3.499911e+001,-6.299946e-006,0.000000e+000,2,8.803875e-001,0.000000e+000,,,,,,,,,,,,,,32,1,4.000000e+000,7.820129e-004,0.000000e+000,0,,0,
1524382627.058,,0.000000e+000,3.499950e+001,-6.313580e-006,0.000000e+000,2,8.856204e-001,0.000000e+000,,,,,,,,,,,,,,32,1,4.000000e+000,0.000000e+000,0.000000e+000,0,,0,
1524382664.892,,0.000000e+000,3.499911e+001,-6.294821e-006,0.000000e+000,2,8.848817e-001,0.000000e+000,,,,,,,,,,,,,,32,1,4.000000e+000,7.820129e-004,0.000000e+000,0,,0,
1524382702.985,,0.000000e+000,3.499872e+001,-6.264767e-006,0.000000e+000,2,8.774015e-001,0.000000e+000,,,,,,,,,,,,,,32,1,4.000000e+000,0.000000e+000,0.000000e+000,0,,0,
1524382740.443,,0.000000e+000,3.499950e+001,-6.211174e-006,0.000000e+000,2,8.764391e-001,0.000000e+000,,,,,,,,,,,,,,32,1,4.000000e+000,0.000000e+000,0.000000e+000,0,,0,
1524382778.273,,0.000000e+000,3.499911e+001,-6.209864e-006,0.000000e+000,2,8.742815e-001,0.000000e+000,,,,,,,,,,,,,,32,1,4.000000e+000,7.820129e-004,0.000000e+000,0,,0,
1524382815.731,,0.000000e+000,3.499950e+001,-6.193033e-006,0.000000e+000,2,8.805513e-001,0.000000e+000,,,,,,,,,,,,,,32,1,4.000000e+000,0.000000e+000,0.000000e+000,0,,0,
1524382853.339,,0.000000e+000,3.499911e+001,-6.183587e-006,0.000000e+000,2,8.827481e-001,0.000000e+000,,,,,,,,,,,,,,32,1,4.000000e+000,7.820129e-004,0.000000e+000,0,,0,
1524382890.597,,0.000000e+000,3.499911e+001,-6.228041e-006,0.000000e+000,2,8.775159e-001,0.000000e+000,,,,,,,,,,,,,,32,1,4.000000e+000,7.820129e-004,0.000000e+000,0,,0,
1524382928.665,,0.000000e+000,3.499989e+001,-6.144041e-006,0.000000e+000,2,8.789862e-001,0.000000e+000,,,,,,,,,,,,,,32,1,4.000000e+000,7.781982e-004,0.000000e+000,0,,0,
1524382966.731,,0.000000e+000,3.499911e+001,-6.145131e-006,0.000000e+000,2,8.762993e-001,0.000000e+000,,,,,,,,,,,,,,32,1,4.000000e+000,7.820129e-004,0.000000e+000,0,,0,
1524382979.176,,0.000000e+000,3.499911e+001,-6.110062e-006,0.000000e+000,2,8.724754e-001,0.000000e+000,,,,,,,,,,,,,,32,1,4.000000e+000,7.820129e-004,0.000000e+000,0,,0,