File: Input_All/TC04-12-01K_TRMac_58K_0.32Kmin_VRMde_55K.dc.dat
[Header]
TITLE,MPMS DC Measurement
BYAPP,MPMS Measurement,2.1,Summary
FILEOPENTIME, 1524639209.627000 4/25/2018, 12:53:29 AM

INFO, APPNAME, MPMS MultiVu Application, Revision 1.61,  Build 082

INFO, NAME, TC04-12-01K
INFO, WEIGHT, 1.000
INFO, AREA, 1.000
INFO, LENGTH, 1.000
INFO, SHAPE, 0
INFO, COMMENT,
INFO, SEQUENCE FILE: TRMac_58K_0.32Kmin_VRMde_55K.seq


INFO, BACKGROUND DATA FILE:, None


STARTUPAXIS,X,4,LINEAR,AUTO,0.000000,0.000000
STARTUPAXIS,Y1,5,LINEAR,AUTO,0.000000,0.000000


STARTUPGROUP,Longitudinal
FIELDGROUP,Longitudinal,1,2,3,4,5,6,7,8,9,15,16,17,18,27,28
FIELDGROUP,Transverse,1,2,3,4,10,11,12,13,14,19,20,21,22,27,28

PLOT_APPEARANCE,ALL,HORZ_GRID_ON,VERT_GRID_ON,MARKERS_AND_LINES

[Data]
Time,Comment,Field (Oe),Temperature (K),Long Moment (emu),Long Scan Std Dev,Long Algorithm,Long Reg Fit,Long Percent Error (%),Trans Moment (emu),Trans Scan Std Dev,Trans Algorithm,Trans Reg Fit,Trans Percent Error (%),Long Moment [w/o ABS] (emu),Long Scan Std Dev [w/o ABS],Long Reg Fit [w/o ABS],Long Percent Error [w/o ABS] (%),Trans Moment [w/o ABS] (emu),Trans Scan Std Dev [w/o ABS],Trans Reg Fit [w/o ABS],Trans Percent Error [w/o ABS] (%),Points per Scan,Scans per Measurement,Scan Length (cm),Delta Temp (K),Rot Position (deg),Error,EC Comp. Running,Using ABS,
1524639209.627,,0.000000e+000,5.499643e+001,7.031198e-006,0.000000e+000,3,7.900227e-001,0.000000e+000,,,,,,,,,,,,,,32,1,4.000000e+000,1.708984e-002,0.000000e+000,0,,0,
1524639247.747,,0.000000e+000,5.500958e+001,5.249594e-006,0.000000e+000,3,7.642401e-001,0.000000e+000,,,,,,,,,,,,,,32,1,4.000000e+000,1.319885e-003,0.000000e+000,0,,0,
1524639285.557,,0.000000e+000,5.501418e+001,4.404751e-006,0.000000e+000,3,7.473528e-001,0.000000e+000,,,,,,,,,,,,,,32,1,4.000000e+000,7.892609e-003,0.000000e+000,0,,0,
1524639323.217,,0.000000e+000,5.500892e+001,3.738711e-006,0.000000e+000,3,7.325041e-001,0.000000e+000,,,,,,,,,,,,,,32,1,4.000000e+000,5.260468e-003,0.000000e+000,0,,0,
1524639360.947,,0.000000e+000,5.500037e+001,3.391520e-006,0.000000e+000,3,7.063273e-001,0.000000e+000,,,,,,,,,,,,,,32,1,4.000000e+000,6.587982e-003,0.000000e+000,0,,0,
1524639398.797,,0.000000e+000,5.499972e+001,2.996816e-006,0.000000e+000,3,6.967592e-001,0.000000e+000,,,,,,,,,,,,,,32,1,4.000000e+000,5.268097e-003,0.000000e+000,0,,0,
1524639435.787,,0.000000e+000,5.500037e+001,2.797511e-006,0.000000e+000,3,6.941549e-001,0.000000e+000,,,,,,,,,,,,,,32,1,4.000000e+000,3.959656e-003,0.000000e+000,0,,0,
1524639473.607,,0.000000e+000,5.499773e+001,2.578635e-006,0.000000e+000,3,6.680574e-001,0.000000e+000,,,,,,,,,,,,,,32,1,4.000000e+000,1.308441e-003,0.000000e+000,0,,0,
1524639510.497,,0.000000e+000,5.500037e+001,2.354516e-006,0.000000e+000,3,6.099153e-001,0.000000e+000,,,,,,,,,,,,,,32,1,4.000000e+000,9.201050e-003,0.000000e+000,0,,0,
1524639548.968,,0.000000e+000,5.499972e+001,2.176084e-006,0.000000e+000,3,6.242437e-001,0.000000e+000,,,,,,,,,,,,,,32,1,4.000000e+000,7.900238e-003,0.000000e+000,0,,0,
1524639586.648,,0.000000e+000,5.499642e+001,2.162486e-006,0.000000e+000,3,5.781674e-001,0.000000e+000,,,,,,,,,,,,,,32,1,4.000000e+000,3.940582e-003,0.000000e+000,0,,0,
1524639624.628,,0.000000e+000,5.499445e+001,1.998866e-006,0.000000e+000,3,6.010358e-001,0.000000e+000,,,,,,,,,,,,,,32,1,4.000000e+000,1.052094e-002,0.000000e+000,0,,0,
1524639662.048,,0.000000e+000,5.499642e+001,1.858354e-006,0.000000e+000,3,5.392336e-001,0.000000e+000,,,,,,,,,,,,,,32,1,4.000000e+000,3.940582e-003,0.000000e+000,0,,0,
1524639699.418,,0.000000e+000,5.500103e+001,1.876956e-006,0.000000e+000,3,5.573604e-001,0.000000e+000,,,,,,,,,,,,,,32,1,4.000000e+000,2.639771e-003,0.000000e+000,0,,0,
1524639737.478,,0.000000e+000,5.500169e+001,1.613095e-006,0.000000e+000,3,4.833095e-001,0.000000e+000,,,,,,,,,,,,,,32,1,4.000000e+000,9.208679e-003,0.000000e+000,0,,0,
1524639774.988,,0.000000e+000,5.500103e+001,1.654691e-006,0.000000e+000,3,4.616212e-001,0.000000e+000,,,,,,,,,,,,,,32,1,4.000000e+000,2.639771e-003,0.000000e+000,0,,0,
1524639812.838,,0.000000e+000,5.499840e+001,1.656294e-006,0.000000e+000,3,5.218034e-001,0.000000e+000,,,,,,,,,,,,,,32,1,4.000000e+000,7.900238e-003,0.000000e+000,0,,0,
1524639850.278,,0.000000e+000,5.499972e+001,1.380009e-006,0.000000e+000,3,4.381043e-001,0.000000e+000,,,,,,,,,,,,,,32,1,4.000000e+000,5.268097e-003,0.000000e+000,0,,0,
1524639887.438,,0.000000e+000,5.499774e+001,1.494282e-006,0.000000e+000,3,4.197239e-001,0.000000e+000,,,,,,,,,,,,,,32,1,4.000000e+000,3.940582e-003,0.000000e+000,0,,0,
1524639925.168,,0.000000e+000,5.500235e+001,1.323489e-006,0.000000e+000,3,4.112563e-001,0.000000e+000,,,,,,,,,,,,,,32,1,4.000000e+000,0.000000e+000,0.000000e+000,0,,0,
1524639962.868,,0.000000e+000,5.500366e+001,1.395192e-006,0.000000e+000,3,3.656035e-001,0.000000e+000,,,,,,,,,,,,,,32,1,4.000000e+000,2.620697e-003,0.000000e+000,0,,0,
1524640000.168,,0.000000e+000,5.500300e+001,1.237504e-006,0.000000e+000,3,3.617948e-001,0.000000e+000,,,,,,,,,,,,,,32,1,4.000000e+000,3.940582e-003,0.000000e+000,0,,0,
1524640038.418,,0.000000e+000,5.499840e+001,1.348563e-006,0.000000e+000,3,2.996100e-001,0.000000e+000,,,,,,,,,,,,,,32,1,4.000000e+000,5.260468e-003,0.000000e+000,0,,0,
1524640076.118,,0.000000e+000,5.499183e+001,1.257598e-006,0.000000e+000,3,2.641567e-001,0.000000e+000,,,,,,,,,,,,,,32,1,4.000000e+000,7.888794e-003,0.000000e+000,0,,0,
1524640113.808,,0.000000e+000,5.500037e+001,1.158380e-006,0.000000e+000,3,1.992312e-001,0.000000e+000,,,,,,,,,,,,,,32,1,4.000000e+000,1.319885e-003,0.000000e+000,0,,0,
1524640151.628,,0.000000e+000,5.499511e+001,1.223418e-006,0.000000e+000,3,2.062892e-001,0.000000e+000,,,,,,,,,,,,,,32,1,4.000000e+000,6.568909e-003,0.000000e+000,0,,0,
1524640189.808,,0.000000e+000,5.499708e+001,1.239669e-006,0.000000e+000,3,2.781105e-001,0.000000e+000,,,,,,,,,,,,,,32,1,4.000000e+000,5.260468e-003,0.000000e+000,0,,0,
1524640227.618,,0.000000e+000,5.499840e+001,9.397343e-007,0.000000e+000,3,0.000000e+000,0.000000e+000,,,,,,,,,,,,,,32,1,4.000000e+000,7.900238e-003,0.000000e+000,0,,0,
1524640267.559,,0.000000e+000,5.499906e+001,3.883924e-007,0.000000e+000,2,0.000000e+000,0.000000e+000,,,,,,,,,,,,,,32,1,4.000000e+000,9.220123e-003,0.000000e+000,0,,0,
1524640309.155,,0.000000e+000,5.500563e+001,3.476906e-007,0.000000e+000,2,0.000000e+000,0.000000e+000,,,,,,,,,,,,,,32,1,4.000000e+000,1.448059e-002,0.000000e+000,0,,0,
1524640352.791,,0.000000e+000,5.499380e+001,2.855898e-007,0.000000e+000,2,0.000000e+000,0.000000e+000,,,,,,,,,,,,,,32,1,4.000000e+000,6.572723e-003,0.000000e+000,0,,0,
1524640396.027,,0.000000e+000,5.500037e+001,1.991160e-007,0.000000e+000,2,0.000000e+000,0.000000e+000,,,,,,,,,,,,,,32,1,4.000000e+000,1.319885e-003,0.000000e+000,0,,0,
1524640436.901,,0.000000e+000,5.499642e+001,1.906261e-007,0.000000e+000,2,0.000000e+000,0.000000e+000,,,,,,,,,,,,,,32,1,4.000000e+000,3.940582e-003,0.000000e+000,0,,0,
1524640478.085,,0.000000e+000,5.499840e+001,2.107200e-007,0.000000e+000,2,0.000000e+000,0.000000e+000,,,,,,,,,,,,,,32,1,4.000000e+000,2.628326e-003,0.000000e+000,0,,0,
1524640514.605,,0.000000e+000,5.499445e+001,-1.912601e-006,0.000000e+000,3,7.987350e-001,0.000000e+000,,,,,,,,,,,,,,32,1,4.000000e+000,2.628326e-003,0.000000e+000,0,,0,
1524640554.057,,0.000000e+000,5.499972e+001,1.797179e-007,0.000000e+000,2,0.000000e+000,0.000000e+000,,,,,,,,,,,,,,32,1,4.000000e+000,7.900238e-003,0.000000e+000,0,,0,
1524640591.447,,0.000000e+000,5.499445e+001,-1.828607e-006,0.000000e+000,3,8.111073e-001,0.000000e+000,,,,,,,,,,,,,,32,1,4.000000e+000,2.628326e-003,0.000000e+000,0,,0,
1524640630.309,,0.000000e+000,5.499773e+001,-1.769501e-006,0.000000e+000,3,8.075756e-001,0.000000e+000,,,,,,,,,,,,,,32,1,4.000000e+000,1.308441e-003,0.000000e+000,0,,0,
1524640670.041,,0.000000e+000,5.499708e+001,5.738863e-008,0.000000e+000,2,0.000000e+000,0.000000e+000,,,,,,,,,,,,,,32,1,4.000000e+000,5.260468e-003,0.000000e+000,0,,0,
1524640709.353,,0.000000e+000,5.499643e+001,1.070655e-006,0.000000e+000,3,1.965064e-002,0.000000e+000,,,,,,,,,,,,,,32,1,4.000000e+000,1.312256e-003,0.000000e+000,0,,0,
1524640752.599,,0.000000e+000,5.499971e+001,5.000897e-008,0.000000e+000,2,0.000000e+000,0.000000e+000,,,,,,,,,,,,,,32,1,4.000000e+000,0.000000e+000,0.000000e+000,0,,0,
1524640791.991,,0.000000e+000,5.499905e+001,7.582219e-008,0.000000e+000,2,0.000000e+000,0.000000e+000,,,,,,,,,,,,,,32,1,4.000000e+000,1.319885e-003,0.000000e+000,0,,0,
1524640829.321,,0.000000e+000,5.499643e+001,1.145029e-006,0.000000e+000,3,1.183049e-001,0.000000e+000,,,,,,,,,,,,,,32,1,4.000000e+000,1.312256e-003,0.000000e+000,0,,0,
1524640869.613,,0.000000e+000,5.499708e+001,-3.327153e-008,0.000000e+000,2,0.000000e+000,0.000000e+000,,,,,,,,,,,,,,32,1,4.000000e+000,0.000000e+000,0.000000e+000,0,,0,
1524640908.475,,0.000000e+000,5.500103e+001,1.242482e-006,0.000000e+000,3,2.275299e-001,0.000000e+000,,,,,,,,,,,,,,32,1,4.000000e+000,1.316071e-002,0.000000e+000,0,,0,
1524640947.607,,0.000000e+000,5.499182e+001,1.172439e-006,0.000000e+000,3,1.899841e-001,0.000000e+000,,,,,,,,,,,,,,32,1,4.000000e+000,5.260468e-003,0.000000e+000,0,,0,
1524640986.640,,0.000000e+000,5.499905e+001,1.104684e-006,0.000000e+000,3,1.721637e-001,0.000000e+000,,,,,,,,,,,,,,32,1,4.000000e+000,1.319885e-003,0.000000e+000,0,,0,
1524641026.082,,0.000000e+000,5.499511e+001,-4.359065e-008,0.000000e+000,2,0.000000e+000,0.000000e+000,,,,,,,,,,,,,,32,1,4.000000e+000,1.319885e-003,0.000000e+000,0,,0,
1524641065.324,,0.000000e+000,5.500037e+001,-6.665937e-008,0.000000e+000,2,0.000000e+000,0.000000e+000,,,,,,,,,,,,,,32,1,4.000000e+000,1.319885e-003,0.000000e+000,0,,0,
1524641103.214,,0.000000e+000,5.499380e+001,1.130308e-006,0.000000e+000,3,1.573500e-001,0.000000e+000,,,,,,,,,,,,,,32,1,4.000000e+000,1.308441e-003,0.000000e+000,0,,0,
1524641141.474,,0.000000e+000,5.499972e+001,8.930120e-007,0.000000e+000,3,2.115333e-002,0.000000e+000,,,,,,,,,,,,,,32,1,4.000000e+000,5.268097e-003,0.000000e+000,0,,0,
1524641180.016,,0.000000e+000,5.499709e+001,9.259634e-007,0.000000e+000,3,1.782546e-001,0.000000e+000,,,,,,,,,,,,,,32,1,4.000000e+000,7.888794e-003,0.000000e+000,0,,0,
1524641217.376,,0.000000e+000,5.500103e+001,9.824902e-007,0.000000e+000,3,5.422903e-002,0.000000e+000,,,,,,,,,,,,,,32,1,4.000000e+000,2.639771e-003,0.000000e+000,0,,0,
1524641255.076,,0.000000e+000,5.499642e+001,9.344967e-007,0.000000e+000,3,8.953235e-002,0.000000e+000,,,,,,,,,,,,,,32,1,4.000000e+000,3.940582e-003,0.000000e+000,0,,0,
1524641292.956,,0.000000e+000,5.500300e+001,9.452285e-007,0.000000e+000,3,2.804634e-002,0.000000e+000,,,,,,,,,,,,,,32,1,4.000000e+000,9.220123e-003,0.000000e+000,0,,0,
1524641330.976,,0.000000e+000,5.499380e+001,1.022896e-006,0.000000e+000,3,1.159762e-001,0.000000e+000,,,,,,,,,,,,,,32,1,4.000000e+000,3.948212e-003,0.000000e+000,0,,0,
1524641368.026,,0.000000e+000,5.499708e+001,9.763062e-007,0.000000e+000,3,9.884387e-002,0.000000e+000,,,,,,,,,,,,,,32,1,4.000000e+000,5.260468e-003,0.000000e+000,0,,0,
1524641405.456,,0.000000e+000,5.499905e+001,1.224579e-006,0.000000e+000,3,1.897223e-001,0.000000e+000,,,,,,,,,,,,,,32,1,4.000000e+000,3.948212e-003,0.000000e+000,0,,0,
1524641442.766,,0.000000e+000,5.500037e+001,1.118828e-006,0.000000e+000,3,2.029780e-001,0.000000e+000,,,,,,,,,,,,,,32,1,4.000000e+000,6.587982e-003,0.000000e+000,0,,0,
1524641482.426,,0.000000e+000,5.499445e+001,1.106315e-006,0.000000e+000,3,1.853940e-001,0.000000e+000,,,,,,,,,,,,,,32,1,4.000000e+000,7.881165e-003,0.000000e+000,0,,0,
1524641524.170,,0.000000e+000,5.499773e+001,-2.843395e-007,0.000000e+000,2,0.000000e+000,0.000000e+000,,,,,,,,,,,,,,32,1,4.000000e+000,1.308441e-003,0.000000e+000,0,,0,
1524641563.452,,0.000000e+000,5.499511e+001,-2.791713e-007,0.000000e+000,2,0.000000e+000,0.000000e+000,,,,,,,,,,,,,,32,1,4.000000e+000,3.940582e-003,0.000000e+000,0,,0,
1524641605.738,,0.000000e+000,5.499841e+001,-2.901319e-007,0.000000e+000,2,0.000000e+000,0.000000e+000,,,,,,,,,,,,,,32,1,4.000000e+000,1.052856e-002,0.000000e+000,0,,0,
1524641646.242,,0.000000e+000,5.499511e+001,1.046903e-006,0.000000e+000,3,5.784303e-002,0.000000e+000,,,,,,,,,,,,,,32,1,4.000000e+000,3.940582e-003,0.000000e+000,0,,0,
1524641690.179,,0.000000e+000,5.500037e+001,-3.163823e-007,0.000000e+000,2,0.000000e+000,0.000000e+000,,,,,,,,,,,,,,32,1,4.000000e+000,1.184082e-002,0.000000e+000,0,,0,
1524641732.425,,0.000000e+000,5.500169e+001,-3.364798e-007,0.000000e+000,2,0.000000e+000,0.000000e+000,,,,,,,,,,,,,,32,1,4.000000e+000,1.184082e-002,0.000000e+000,0,,0,
1524641775.561,,0.000000e+000,5.499708e+001,-3.419445e-007,0.000000e+000,2,0.000000e+000,0.000000e+000,,,,,,,,,,,,,,32,1,4.000000e+000,5.260468e-003,0.000000e+000,0,,0,
1524641817.547,,0.000000e+000,5.499709e+001,-3.864903e-007,0.000000e+000,2,0.000000e+000,0.000000e+000,,,,,,,,,,,,,,32,1,4.000000e+000,7.888794e-003,0.000000e+000,0,,0,
1524641859.473,,0.000000e+000,5.499445e+001,-4.221834e-007,0.000000e+000,2,0.000000e+000,0.000000e+000,,,,,,,,,,,,,,32,1,4.000000e+000,7.881165e-003,0.000000e+000,0,,0,
1524641900.999,,0.000000e+000,5.499708e+001,-3.937912e-007,0.000000e+000,2,0.000000e+000,0.000000e+000,,,,,,,,,,,,,,32,1,4.000000e+000,5.260468e-003,0.000000e+000,0,,0,
1524641944.405,,0.000000e+000,5.499314e+001,-4.207340e-007,0.000000e+000,2,0.000000e+000,0.000000e+000,,,,,,,,,,,,,,32,1,4.000000e+000,5.260468e-003,0.000000e+000,0,,0,
1524641986.611,,0.000000e+000,5.499905e+001,-4.308638e-007,0.000000e+000,2,0.000000e+000,0.000000e+000,,,,,,,,,,,,,,32,1,4.000000e+000,3.948212e-003,0.000000e+000,0,,0,
1524642030.127,,0.000000e+000,5.499248e+001,-4.448970e-007,0.000000e+000,2,0.000000e+000,0.000000e+000,,,,,,,,,,,,,,32,1,4.000000e+000,1.319885e-003,0.000000e+000,0,,0,
1524642072.213,,0.000000e+000,5.500037e+001,-3.991956e-007,0.000000e+000,2,0.000000e+000,0.000000e+000,,,,,,,,,,,,,,32,1,4.000000e+000,6.587982e-003,0.000000e+000,0,,0,
1524642114.709,,0.000000e+000,5.499971e+001,-3.939723e-007,0.000000e+000,2,0.000000e+000,0.000000e+000,,,,,,,,,,,,,,32,1,4.000000e+000,1.052094e-002,0.000000e+000,0,,0,
1524642157.145,,0.000000e+000,5.499643e+001,-4.240732e-007,0.000000e+000,2,0.000000e+000,0.000000e+000,,,,,,,,,,,,,,32,1,4.000000e+000,1.184082e-002,0.000000e+000,0,,0,
1524642199.621,,0.000000e+000,5.500432e+001,-3.947028e-007,0.000000e+000,2,0.000000e+000,0.000000e+000,,,,,,,,,,,,,,32,1,4.000000e+000,3.940582e-003,0.000000e+000,0,,0,
1524642242.407,,0.000000e+000,5.499708e+001,-5.352015e-007,0.000000e+000,2,0.000000e+000,0.000000e+000,,,,,,,,,,,,,,32,1,4.000000e+000,0.000000e+000,0.000000e+000,0,,0,
1524642285.423,,0.000000e+000,5.499709e+001,-4.934910e-007,0.000000e+000,2,0.000000e+000,0.000000e+000,,,,,,,,,,,,,,32,1,4.000000e+000,1.052856e-002,0.000000e+000,0,,0,
1524642328.349,,0.000000e+000,5.499774e+001,-4.390096e-007,0.000000e+000,2,0.000000e+000,0.000000e+000,,,,,,,,,,,,,,32,1,4.000000e+000,3.940582e-003,0.000000e+000,0,,0,
1524642371.735,,0.000000e+000,5.500037e+001,-4.927829e-007,0.000000e+000,2,0.000000e+000,0.000000e+000,,,,,,,,,,,,,,32,1,4.000000e+000,3.959656e-003,0.000000e+000,0,,0,
1524642413.872,,0.000000e+000,5.500300e+001,-4.729316e-007,0.000000e+000,2,0.000000e+000,0.000000e+000,,,,,,,,,,,,,,32,1,4.000000e+000,6.580353e-003,0.000000e+000,0,,0,
1524642457.298,,0.000000e+000,5.500497e+001,-5.194015e-007,0.000000e+000,2,0.000000e+000,0.000000e+000,,,,,,,,,,,,,,32,1,4.000000e+000,0.000000e+000,0.000000e+000,0,,0,
1524642500.184,,0.000000e+000,5.499972e+001,-4.958148e-007,0.000000e+000,2,0.000000e+000,0.000000e+000,,,,,,,,,,,,,,32,1,4.000000e+000,7.900238e-003,0.000000e+000,0,,0,
1524642542.310,,0.000000e+000,5.499708e+001,-4.575372e-007,0.000000e+000,2,0.000000e+000,0.000000e+000,,,,,,,,,,,,,,32,1,4.000000e+000,2.620697e-003,0.000000e+000,0,,0,
1524642584.846,,0.000000e+000,5.500037e+001,-5.325993e-007,0.000000e+000,2,0.000000e+000,0.000000e+000,,,,,,,,,,,,,,32,1,4.000000e+000,1.319885e-003,0.000000e+000,0,,0,
1524642627.762,,0.000000e+000,5.499577e+001,-5.177341e-007,0.000000e+000,2,0.000000e+000,0.000000e+000,,,,,,,,,,,,,,32,1,4.000000e+000,7.888794e-003,0.000000e+000,0,,0,
1524642670.448,,0.000000e+000,5.499248e+001,-5.156795e-007,0.000000e+000,2,0.000000e+000,0.000000e+000,,,,,,,,,,,,,,32,1,4.000000e+000,1.182938e-002,0.000000e+000,0,,0,
1524642713.164,,0.000000e+000,5.499840e+001,-5.549046e-007,0.000000e+000,2,0.000000e+000,0.000000e+000,,,,,,,,,,,,,,32,1,4.000000e+000,2.628326e-003,0.000000e+000,0,,0,
1524642754.980,,0.000000e+000,5.500234e+001,-4.971890e-007,0.000000e+000,2,0.000000e+000,0.000000e+000,,,,,,,,,,,,,,32,1,4.000000e+000,5.260468e-003,0.000000e+000,0,,0,
1524642797.726,,0.000000e+000,5.500432e+001,-4.846910e-007,0.000000e+000,2,0.000000e+000,0.000000e+000,,,,,,,,,,,,,,32,1,4.000000e+000,1.300812e-003,0.000000e+000,0,,0,
1524642838.240,,0.000000e+000,5.499577e+001,-5.180663e-007,0.000000e+000,2,0.000000e+000,0.000000e+000,,,,,,,,,,,,,,32,1,4.000000e+000,2.632141e-003,0.000000e+000,0,,0,
1524642879.532,,0.000000e+000,5.500300e+001,-5.113685e-007,0.000000e+000,2,0.000000e+000,0.000000e+000,,,,,,,,,,,,,,32,1,4.000000e+000,9.220123e-003,0.000000e+000,0,,0,
1524642922.898,,0.000000e+000,5.500366e+001,-5.478758e-007,0.000000e+000,2,0.000000e+000,0.000000e+000,,,,,,,,,,,,,,32,1,4.000000e+000,2.620697e-003,0.000000e+000,0,,0,
1524642967.174,,0.000000e+000,5.500103e+001,-5.761414e-007,0.000000e+000,2,0.000000e+000,0.000000e+000,,,,,,,,,,,,,,32,1,4.000000e+000,7.888794e-003,0.000000e+000,0,,0,
1524643008.278,,0.000000e+000,5.500169e+001,-5.502327e-007,0.000000e+000,2,0.000000e+000,0.000000e+000,,,,,,,,,,,,,,32,1,4.000000e+000,3.959656e-003,0.000000e+000,0,,0,
1524643049.122,,0.000000e+000,5.499709e+001,-1.823266e-006,0.000000e+000,3,7.397776e-001,0.000000e+000,,,,,,,,,,,,,,32,1,4.000000e+000,1.052856e-002,0.000000e+000,0,,0,
1524643092.648,,0.000000e+000,5.500037e+001,-5.336109e-007,0.000000e+000,2,0.000000e+000,0.000000e+000,,,,,,,,,,,,,,32,1,4.000000e+000,6.587982e-003,0.000000e+000,0,,0,
1524643135.735,,0.000000e+000,5.500300e+001,-5.983719e-007,0.000000e+000,2,0.000000e+000,0.000000e+000,,,,,,,,,,,,,,32,1,4.000000e+000,9.220123e-003,0.000000e+000,0,,0,
1524643176.799,,0.000000e+000,5.499314e+001,-5.341972e-007,0.000000e+000,2,0.000000e+000,0.000000e+000,,,,,,,,,,,,,,32,1,4.000000e+000,5.260468e-003,0.000000e+000,0,,0,
1524643218.243,,0.000000e+000,5.499511e+001,-1.597892e-006,0.000000e+000,3,7.074353e-001,0.000000e+000,,,,,,,,,,,,,,32,1,4.000000e+000,9.201050e-003,0.000000e+000,0,,0,
1524643261.519,,0.000000e+000,5.499839e+001,-5.331694e-007,0.000000e+000,2,0.000000e+000,0.000000e+000,,,,,,,,,,,,,,32,1,4.000000e+000,0.000000e+000,0.000000e+000,0,,0,
1524643302.213,,0.000000e+000,5.500169e+001,-1.591337e-006,0.000000e+000,3,7.276243e-001,0.000000e+000,,,,,,,,,,,,,,32,1,4.000000e+000,1.319885e-003,0.000000e+000,0,,0,
1524643345.039,,0.000000e+000,5.499709e+001,-5.653366e-007,0.000000e+000,2,0.000000e+000,0.000000e+000,,,,,,,,,,,,,,32,1,4.000000e+000,1.052856e-002,0.000000e+000,0,,0,
1524643385.473,,0.000000e+000,5.499577e+001,-4.885231e-007,0.000000e+000,2,0.000000e+000,0.000000e+000,,,,,,,,,,,,,,32,1,4.000000e+000,0.000000e+000,0.000000e+000,0,,0,
1524643428.269,,0.000000e+000,5.499445e+001,-5.665274e-007,0.000000e+000,2,0.000000e+000,0.000000e+000,,,,,,,,,,,,,,32,1,4.000000e+000,2.628326e-003,0.000000e+000,0,,0,
1524643469.593,,0.000000e+000,5.499117e+001,-5.717018e-007,0.000000e+000,2,0.000000e+000,0.000000e+000,,,,,,,,,,,,,,32,1,4.000000e+000,9.208679e-003,0.000000e+000,0,,0,
1524643510.147,,0.000000e+000,5.499642e+001,-1.617867e-006,0.000000e+000,3,7.184100e-001,0.000000e+000,,,,,,,,,,,,,,32,1,4.000000e+000,3.940582e-003,0.000000e+000,0,,0,
1524643549.809,,0.000000e+000,5.500103e+001,-1.709053e-006,0.000000e+000,3,7.411358e-001,0.000000e+000,,,,,,,,,,,,,,32,1,4.000000e+000,5.279541e-003,0.000000e+000,0,,0,
1524643591.833,,0.000000e+000,5.499511e+001,-1.716722e-006,0.000000e+000,3,6.973464e-001,0.000000e+000,,,,,,,,,,,,,,32,1,4.000000e+000,1.184082e-002,0.000000e+000,0,,0,
1524643633.287,,0.000000e+000,5.499774e+001,-5.861900e-007,0.000000e+000,2,0.000000e+000,0.000000e+000,,,,,,,,,,,,,,32,1,4.000000e+000,1.446152e-002,0.000000e+000,0,,0,
1524643672.379,,0.000000e+000,5.499775e+001,-5.399462e-007,0.000000e+000,2,0.000000e+000,0.000000e+000,,,,,,,,,,,,,,32,1,4.000000e+000,1.184845e-002,0.000000e+000,0,,0,
1524643711.831,,0.000000e+000,5.499971e+001,-1.488683e-006,0.000000e+000,3,7.309308e-001,0.000000e+000,,,,,,,,,,,,,,32,1,4.000000e+000,0.000000e+000,0.000000e+000,0,,0,
1524643753.085,,0.000000e+000,5.500235e+001,-1.715253e-006,0.000000e+000,3,7.725527e-001,0.000000e+000,,,,,,,,,,,,,,32,1,4.000000e+000,0.000000e+000,0.000000e+000,0,,0,
1524643795.711,,0.000000e+000,5.500300e+001,-5.595469e-007,0.000000e+000,2,0.000000e+000,0.000000e+000,,,,,,,,,,,,,,32,1,4.000000e+000,9.220123e-003,0.000000e+000,0,,0,
1524643834.904,,0.000000e+000,5.499906e+001,-1.601474e-006,0.000000e+000,3,5.965319e-001,0.000000e+000,,,,,,,,,,,,,,32,1,4.000000e+000,9.220123e-003,0.000000e+000,0,,0,
1524643879.610,,0.000000e+000,5.500366e+001,-5.866693e-007,0.000000e+000,2,0.000000e+000,0.000000e+000,,,,,,,,,,,,,,32,1,4.000000e+000,2.620697e-003,0.000000e+000,0,,0,
1524643918.562,,0.000000e+000,5.499643e+001,-1.591843e-006,0.000000e+000,3,6.873661e-001,0.000000e+000,,,,,,,,,,,,,,32,1,4.000000e+000,9.208679e-003,0.000000e+000,0,,0,
1524643958.464,,0.000000e+000,5.499577e+001,-5.321265e-007,0.000000e+000,2,0.000000e+000,0.000000e+000,,,,,,,,,,,,,,32,1,4.000000e+000,0.000000e+000,0.000000e+000,0,,0,
1524643998.186,,0.000000e+000,5.499511e+001,-5.169565e-007,0.000000e+000,2,0.000000e+000,0.000000e+000,,,,,,,,,,,,,,32,1,4.000000e+000,1.319885e-003,0.000000e+000,0,,0,
1524644039.360,,0.000000e+000,5.500169e+001,-1.768230e-006,0.000000e+000,3,7.659690e-001,0.000000e+000,,,,,,,,,,,,,,32,1,4.000000e+000,3.959656e-003,0.000000e+000,0,,0,
1524644078.712,,0.000000e+000,5.500103e+001,-1.727663e-006,0.000000e+000,3,7.737892e-001,0.000000e+000,,,,,,,,,,,,,,32,1,4.000000e+000,0.000000e+000,0.000000e+000,0,,0,
1524644119.956,,0.000000e+000,5.499577e+001,-6.006979e-007,0.000000e+000,2,0.000000e+000,0.000000e+000,,,,,,,,,,,,,,32,1,4.000000e+000,2.632141e-003,0.000000e+000,0,,0,
1524644160.170,,0.000000e+000,5.499577e+001,-1.748973e-006,0.000000e+000,3,7.050572e-001,0.000000e+000,,,,,,,,,,,,,,32,1,4.000000e+000,2.632141e-003,0.000000e+000,0,,0,
1524644199.552,,0.000000e+000,5.499643e+001,-1.729264e-006,0.000000e+000,3,7.136939e-001,0.000000e+000,,,,,,,,,,,,,,32,1,4.000000e+000,1.312256e-003,0.000000e+000,0,,0,
1524644238.554,,0.000000e+000,5.499773e+001,-1.822208e-006,0.000000e+000,3,7.306617e-001,0.000000e+000,,,,,,,,,,,,,,32,1,4.000000e+000,1.308441e-003,0.000000e+000,0,,0,
1524644275.964,,0.000000e+000,5.499577e+001,-1.608891e-006,0.000000e+000,3,7.510833e-001,0.000000e+000,,,,,,,,,,,,,,32,1,4.000000e+000,5.249023e-003,0.000000e+000,0,,0,
1524644315.376,,0.000000e+000,5.500037e+001,-1.621869e-006,0.000000e+000,3,7.296107e-001,0.000000e+000,,,,,,,,,,,,,,32,1,4.000000e+000,1.319885e-003,0.000000e+000,0,,0,
1524644356.610,,0.000000e+000,5.499577e+001,-5.955284e-007,0.000000e+000,2,0.000000e+000,0.000000e+000,,,,,,,,,,,,,,32,1,4.000000e+000,5.249023e-003,0.000000e+000,0,,0,
1524644394.660,,0.000000e+000,5.499905e+001,-1.672736e-006,0.000000e+000,3,7.277633e-001,0.000000e+000,,,,,,,,,,,,,,32,1,4.000000e+000,1.319885e-003,0.000000e+000,0,,0,
1524644433.242,,0.000000e+000,5.499840e+001,-1.895645e-006,0.000000e+000,3,6.330557e-001,0.000000e+000,,,,,,,,,,,,,,32,1,4.000000e+000,2.628326e-003,0.000000e+000,0,,0,
1524644472.022,,0.000000e+000,5.499708e+001,-1.854487e-006,0.000000e+000,3,7.768212e-001,0.000000e+000,,,,,,,,,,,,,,32,1,4.000000e+000,5.260468e-003,0.000000e+000,0,,0,
1524644511.874,,0.000000e+000,5.499840e+001,-1.815513e-006,0.000000e+000,3,7.184154e-001,0.000000e+000,,,,,,,,,,,,,,32,1,4.000000e+000,5.260468e-003,0.000000e+000,0,,0,
1524644551.557,,0.000000e+000,5.499577e+001,-1.769862e-006,0.000000e+000,3,7.598709e-001,0.000000e+000,,,,,,,,,,,,,,32,1,4.000000e+000,7.888794e-003,0.000000e+000,0,,0,
1524644591.019,,0.000000e+000,5.499511e+001,-1.731608e-006,0.000000e+000,3,7.197912e-001,0.000000e+000,,,,,,,,,,,,,,32,1,4.000000e+000,3.940582e-003,0.000000e+000,0,,0,
1524644630.621,,0.000000e+000,5.499643e+001,-1.781076e-006,0.000000e+000,3,7.427089e-001,0.000000e+000,,,,,,,,,,,,,,32,1,4.000000e+000,6.568909e-003,0.000000e+000,0,,0,
1524644670.243,,0.000000e+000,5.500037e+001,-1.676401e-006,0.000000e+000,3,7.112905e-001,0.000000e+000,,,,,,,,,,,,,,32,1,4.000000e+000,3.959656e-003,0.000000e+000,0,,0,
1524644710.455,,0.000000e+000,5.499379e+001,-1.680262e-006,0.000000e+000,3,7.287842e-001,0.000000e+000,,,,,,,,,,,,,,32,1,4.000000e+000,9.201050e-003,0.000000e+000,0,,0,
1524644749.607,,0.000000e+000,5.499905e+001,-1.686825e-006,0.000000e+000,3,7.145416e-001,0.000000e+000,,,,,,,,,,,,,,32,1,4.000000e+000,1.319885e-003,0.000000e+000,0,,0,
1524644787.547,,0.000000e+000,5.499774e+001,-1.771469e-006,0.000000e+000,3,7.502832e-001,0.000000e+000,,,,,,,,,,,,,,32,1,4.000000e+000,6.580353e-003,0.000000e+000,0,,0,
1524644826.859,,0.000000e+000,5.499773e+001,-5.609264e-007,0.000000e+000,2,0.000000e+000,0.000000e+000,,,,,,,,,,,,,,32,1,4.000000e+000,1.308441e-003,0.000000e+000,0,,0,
1524644864.119,,0.000000e+000,5.499577e+001,-1.660148e-006,0.000000e+000,3,7.225055e-001,0.000000e+000,,,,,,,,,,,,,,32,1,4.000000e+000,0.000000e+000,0.000000e+000,0,,0,
1524644901.519,,0.000000e+000,5.499643e+001,-1.776133e-006,0.000000e+000,3,7.627116e-001,0.000000e+000,,,,,,,,,,,,,,32,1,4.000000e+000,1.312256e-003,0.000000e+000,0,,0,
1524644938.609,,0.000000e+000,5.499773e+001,-1.610946e-006,0.000000e+000,3,7.127941e-001,0.000000e+000,,,,,,,,,,,,,,32,1,4.000000e+000,1.308441e-003,0.000000e+000,0,,0,
1524644977.811,,0.000000e+000,5.500695e+001,-1.701936e-006,0.000000e+000,3,7.088226e-001,0.000000e+000,,,,,,,,,,,,,,32,1,4.000000e+000,1.319885e-003,0.000000e+000,0,,0,
1524645017.353,,0.000000e+000,5.500235e+001,-1.555983e-006,0.000000e+000,3,7.183012e-001,0.000000e+000,,,,,,,,,,,,,,32,1,4.000000e+000,0.000000e+000,0.000000e+000,0,,0,
1524645055.423,,0.000000e+000,5.499971e+001,-1.750927e-006,0.000000e+000,3,7.511712e-001,0.000000e+000,,,,,,,,,,,,,,32,1,4.000000e+000,2.639771e-003,0.000000e+000,0,,0,
1524645095.075,,0.000000e+000,5.499972e+001,-5.681182e-007,0.000000e+000,2,0.000000e+000,0.000000e+000,,,,,,,,,,,,,,32,1,4.000000e+000,7.900238e-003,0.000000e+000,0,,0,
1524645134.977,,0.000000e+000,5.499708e+001,-1.757447e-006,0.000000e+000,3,7.599779e-001,0.000000e+000,,,,,,,,,,,,,,32,1,4.000000e+000,0.000000e+000,0.000000e+000,0,,0,
1524645173.839,,0.000000e+000,5.499642e+001,-1.609811e-006,0.000000e+000,3,7.427911e-001,0.000000e+000,,,,,,,,,,,,,,32,1,4.000000e+000,3.940582e-003,0.000000e+000,0,,0,
1524645213.871,,0.000000e+000,5.499774e+001,-5.744994e-007,0.000000e+000,2,0.000000e+000,0.000000e+000,,,,,,,,,,,,,,32,1,4.000000e+000,3.940582e-003,0.000000e+000,0,,0,
1524645253.024,,0.000000e+000,5.499774e+001,-6.175862e-007,0.000000e+000,2,0.000000e+000,0.000000e+000,,,,,,,,,,,,,,32,1,4.000000e+000,3.940582e-003,0.000000e+000,0,,0,
1524645293.136,,0.000000e+000,5.499643e+001,-5.967091e-007,0.000000e+000,2,0.000000e+000,0.000000e+000,,,,,,,,,,,,,,32,1,4.000000e+000,9.208679e-003,0.000000e+000,0,,0,
1524645330.336,,0.000000e+000,5.499972e+001,-1.780659e-006,0.000000e+000,3,7.193640e-001,0.000000e+000,,,,,,,,,,,,,,32,1,4.000000e+000,5.268097e-003,0.000000e+000,0,,0,
1524645370.638,,0.000000e+000,5.499643e+001,-1.768522e-006,0.000000e+000,3,7.236536e-001,0.000000e+000,,,,,,,,,,,,,,32,1,4.000000e+000,1.312256e-003,0.000000e+000,0,,0,
1524645408.648,,0.000000e+000,5.499445e+001,-1.699120e-006,0.000000e+000,3,7.117809e-001,0.000000e+000,,,,,,,,,,,,,,32,1,4.000000e+000,0.000000e+000,0.000000e+000,0,,0,
1524645448.280,,0.000000e+000,5.499840e+001,-1.625861e-006,0.000000e+000,3,7.301325e-001,0.000000e+000,,,,,,,,,,,,,,32,1,4.000000e+000,5.260468e-003,0.000000e+000,0,,0,
1524645485.510,,0.000000e+000,5.499839e+001,-1.665023e-006,0.000000e+000,3,7.715508e-001,0.000000e+000,,,,,,,,,,,,,,32,1,4.000000e+000,0.000000e+000,0.000000e+000,0,,0,
1524645523.410,,0.000000e+000,5.499445e+001,-1.680845e-006,0.000000e+000,3,7.465661e-001,0.000000e+000,,,,,,,,,,,,,,32,1,4.000000e+000,0.000000e+000,0.000000e+000,0,,0,
1524645562.882,,0.000000e+000,5.499643e+001,-1.669130e-006,0.000000e+000,3,7.278990e-001,0.000000e+000,,,,,,,,,,,,,,32,1,4.000000e+000,1.312256e-003,0.000000e+000,0,,0,
1524645600.922,,0.000000e+000,5.499905e+001,-1.712437e-006,0.000000e+000,3,7.162395e-001,0.000000e+000,,,,,,,,,,,,,,32,1,4.000000e+000,1.319885e-003,0.000000e+000,0,,0,
1524645641.064,,0.000000e+000,5.499840e+001,-6.006521e-007,0.000000e+000,2,0.000000e+000,0.000000e+000,,,,,,,,,,,,,,32,1,4.000000e+000,2.628326e-003,0.000000e+000,0,,0,
1524645678.904,,0.000000e+000,5.499642e+001,-1.747845e-006,0.000000e+000,3,7.448248e-001,0.000000e+000,,,,,,,,,,,,,,32,1,4.000000e+000,3.940582e-003,0.000000e+000,0,,0,
1524645716.554,,0.000000e+000,5.499445e+001,-1.696992e-006,0.000000e+000,3,7.044442e-001,0.000000e+000,,,,,,,,,,,,,,32,1,4.000000e+000,5.260468e-003,0.000000e+000,0,,0,
1524645754.514,,0.000000e+000,5.499248e+001,-1.812065e-006,0.000000e+000,3,7.625186e-001,0.000000e+000,,,,,,,,,,,,,,32,1,4.000000e+000,1.319885e-003,0.000000e+000,0,,0,
1524645792.354,,0.000000e+000,5.499774e+001,-1.641822e-006,0.000000e+000,3,7.403428e-001,0.000000e+000,,,,,,,,,,,,,,32,1,4.000000e+000,3.940582e-003,0.000000e+000,0,,0,
1524645830.844,,0.000000e+000,5.499840e+001,-1.700928e-006,0.000000e+000,3,6.878879e-001,0.000000e+000,,,,,,,,,,,,,,32,1,4.000000e+000,1.842117e-002,0.000000e+000,0,,0,
1524645868.404,,0.000000e+000,5.499313e+001,1.024958e-006,0.000000e+000,3,0.000000e+000,0.000000e+000,,,,,,,,,,,,,,32,1,4.000000e+000,2.628326e-003,0.000000e+000,0,,0,
1524645905.544,,0.000000e+000,5.499643e+001,-1.584218e-006,0.000000e+000,3,7.429240e-001,0.000000e+000,,,,,,,,,,,,,,32,1,4.000000e+000,1.312256e-003,0.000000e+000,0,,0,
1524645943.514,,0.000000e+000,5.499642e+001,-1.827278e-006,0.000000e+000,3,7.484984e-001,0.000000e+000,,,,,,,,,,,,,,32,1,4.000000e+000,3.940582e-003,0.000000e+000,0,,0,
1524645980.615,,0.000000e+000,5.499643e+001,-1.719057e-006,0.000000e+000,3,7.051611e-001,0.000000e+000,,,,,,,,,,,,,,32,1,4.000000e+000,1.312256e-003,0.000000e+000,0,,0,
1524646018.465,,0.000000e+000,5.499773e+001,-1.705644e-006,0.000000e+000,3,7.609535e-001,0.000000e+000,,,,,,,,,,,,,,32,1,4.000000e+000,1.308441e-003,0.000000e+000,0,,0,
1524646055.665,,0.000000e+000,5.500168e+001,-1.674398e-006,0.000000e+000,3,7.266660e-001,0.000000e+000,,,,,,,,,,,,,,32,1,4.000000e+000,6.580353e-003,0.000000e+000,0,,0,
1524646095.655,,0.000000e+000,5.499642e+001,-6.454514e-007,0.000000e+000,2,0.000000e+000,0.000000e+000,,,,,,,,,,,,,,32,1,4.000000e+000,3.940582e-003,0.000000e+000,0,,0,
1524646133.205,,0.000000e+000,5.499972e+001,-1.889018e-006,0.000000e+000,3,7.491928e-001,0.000000e+000,,,,,,,,,,,,,,32,1,4.000000e+000,5.268097e-003,0.000000e+000,0,,0,
1524646171.275,,0.000000e+000,5.499445e+001,-1.728244e-006,0.000000e+000,3,7.262098e-001,0.000000e+000,,,,,,,,,,,,,,32,1,4.000000e+000,5.260468e-003,0.000000e+000,0,,0,
1524646210.447,,0.000000e+000,5.499577e+001,-1.765360e-006,0.000000e+000,3,7.186584e-001,0.000000e+000,,,,,,,,,,,,,,32,1,4.000000e+000,1.316071e-002,0.000000e+000,0,,0,
1524646248.227,,0.000000e+000,5.499840e+001,-1.792425e-006,0.000000e+000,3,7.161772e-001,0.000000e+000,,,,,,,,,,,,,,32,1,4.000000e+000,5.260468e-003,0.000000e+000,0,,0,
1524646286.007,,0.000000e+000,5.499906e+001,-1.767359e-006,0.000000e+000,3,7.131999e-001,0.000000e+000,,,,,,,,,,,,,,32,1,4.000000e+000,9.220123e-003,0.000000e+000,0,,0,
1524646325.509,,0.000000e+000,5.499905e+001,-1.659454e-006,0.000000e+000,3,7.292752e-001,0.000000e+000,,,,,,,,,,,,,,32,1,4.000000e+000,3.948212e-003,0.000000e+000,0,,0,
1524646365.331,,0.000000e+000,5.499840e+001,-6.384047e-007,0.000000e+000,2,0.000000e+000,0.000000e+000,,,,,,,,,,,,,,32,1,4.000000e+000,5.260468e-003,0.000000e+000,0,,0,
1524646405.683,,0.000000e+000,5.499445e+001,-6.381499e-007,0.000000e+000,2,0.000000e+000,0.000000e+000,,,,,,,,,,,,,,32,1,4.000000e+000,1.314926e-002,0.000000e+000,0,,0,
1524646442.693,,0.000000e+000,5.499643e+001,-1.802216e-006,0.000000e+000,3,7.143868e-001,0.000000e+000,,,,,,,,,,,,,,32,1,4.000000e+000,1.184082e-002,0.000000e+000,0,,0,
1524646482.715,,0.000000e+000,5.499840e+001,-1.835649e-006,0.000000e+000,3,7.212295e-001,0.000000e+000,,,,,,,,,,,,,,32,1,4.000000e+000,2.628326e-003,0.000000e+000,0,,0,
1524646520.895,,0.000000e+000,5.499643e+001,-1.791716e-006,0.000000e+000,3,7.623225e-001,0.000000e+000,,,,,,,,,,,,,,32,1,4.000000e+000,9.208679e-003,0.000000e+000,0,,0,
1524646558.005,,0.000000e+000,5.500037e+001,-1.759962e-006,0.000000e+000,3,7.403947e-001,0.000000e+000,,,,,,,,,,,,,,32,1,4.000000e+000,3.959656e-003,0.000000e+000,0,,0,
1524646595.445,,0.000000e+000,5.499643e+001,-1.756126e-006,0.000000e+000,3,7.290350e-001,0.000000e+000,,,,,,,,,,,,,,32,1,4.000000e+000,1.708984e-002,0.000000e+000,0,,0,
1524646633.585,,0.000000e+000,5.499905e+001,-1.720232e-006,0.000000e+000,3,6.939259e-001,0.000000e+000,,,,,,,,,,,,,,32,1,4.000000e+000,1.319885e-003,0.000000e+000,0,,0,
1524646672.016,,0.000000e+000,5.499577e+001,-1.798606e-006,0.000000e+000,3,7.602520e-001,0.000000e+000,,,,,,,,,,,,,,32,1,4.000000e+000,5.249023e-003,0.000000e+000,0,,0,
1524646709.356,,0.000000e+000,5.500301e+001,-1.688153e-006,0.000000e+000,3,7.350511e-001,0.000000e+000,,,,,,,,,,,,,,32,1,4.000000e+000,1.446915e-002,0.000000e+000,0,,0,
1524646749.108,,0.000000e+000,5.500037e+001,-6.119567e-007,0.000000e+000,2,0.000000e+000,0.000000e+000,,,,,,,,,,,,,,32,1,4.000000e+000,1.319885e-003,0.000000e+000,0,,0,
1524646787.668,,0.000000e+000,5.499511e+001,-1.800300e-006,0.000000e+000,3,7.277761e-001,0.000000e+000,,,,,,,,,,,,,,32,1,4.000000e+000,3.940582e-003,0.000000e+000,0,,0,
1524646825.078,,0.000000e+000,5.499972e+001,-1.696447e-006,0.000000e+000,3,7.346118e-001,0.000000e+000,,,,,,,,,,,,,,32,1,4.000000e+000,5.268097e-003,0.000000e+000,0,,0,
1524646863.860,,0.000000e+000,5.499643e+001,-1.622999e-006,0.000000e+000,3,7.507452e-001,0.000000e+000,,,,,,,,,,,,,,32,1,4.000000e+000,1.448059e-002,0.000000e+000,0,,0,
1524646901.180,,0.000000e+000,5.499511e+001,-1.782971e-006,0.000000e+000,3,7.287027e-001,0.000000e+000,,,,,,,,,,,,,,32,1,4.000000e+000,3.940582e-003,0.000000e+000,0,,0,
1524646938.480,,0.000000e+000,5.499445e+001,-1.683104e-006,0.000000e+000,3,7.392791e-001,0.000000e+000,,,,,,,,,,,,,,32,1,4.000000e+000,7.881165e-003,0.000000e+000,0,,0,
1524646976.290,,0.000000e+000,5.499840e+001,-1.815356e-006,0.000000e+000,3,7.397632e-001,0.000000e+000,,,,,,,,,,,,,,32,1,4.000000e+000,7.900238e-003,0.000000e+000,0,,0,
1524647013.140,,0.000000e+000,5.499972e+001,-1.661952e-006,0.000000e+000,3,7.298661e-001,0.000000e+000,,,,,,,,,,,,,,32,1,4.000000e+000,1.578903e-002,0.000000e+000,0,,0,
1524647051.200,,0.000000e+000,5.499511e+001,-1.689807e-006,0.000000e+000,3,7.557685e-001,0.000000e+000,,,,,,,,,,,,,,32,1,4.000000e+000,1.319885e-003,0.000000e+000,0,,0,
1524647089.030,,0.000000e+000,5.500169e+001,-1.664793e-006,0.000000e+000,3,7.340172e-001,0.000000e+000,,,,,,,,,,,,,,32,1,4.000000e+000,1.319885e-003,0.000000e+000,0,,0,
1524647129.092,,0.000000e+000,5.500235e+001,-5.878874e-007,0.000000e+000,2,0.000000e+000,0.000000e+000,,,,,,,,,,,,,,32,1,4.000000e+000,2.639771e-003,0.000000e+000,0,,0,
1524647166.952,,0.000000e+000,5.499840e+001,-1.685079e-006,0.000000e+000,3,6.796287e-001,0.000000e+000,,,,,,,,,,,,,,32,1,4.000000e+000,5.260468e-003,0.000000e+000,0,,0,
1524647204.982,,0.000000e+000,5.499380e+001,-1.679193e-006,0.000000e+000,3,7.430430e-001,0.000000e+000,,,,,,,,,,,,,,32,1,4.000000e+000,3.948212e-003,0.000000e+000,0,,0,
1524647242.682,,0.000000e+000,5.499577e+001,-1.532406e-006,0.000000e+000,3,7.148031e-001,0.000000e+000,,,,,,,,,,,,,,32,1,4.000000e+000,5.249023e-003,0.000000e+000,0,,0,
1524647281.282,,0.000000e+000,5.500300e+001,-1.706279e-006,0.000000e+000,3,7.409682e-001,0.000000e+000,,,,,,,,,,,,,,32,1,4.000000e+000,3.940582e-003,0.000000e+000,0,,0,
1524647319.782,,0.000000e+000,5.499313e+001,-1.718008e-006,0.000000e+000,3,7.358128e-001,0.000000e+000,,,,,,,,,,,,,,32,1,4.000000e+000,7.892609e-003,0.000000e+000,0,,0,
1524647357.782,,0.000000e+000,5.499445e+001,-1.718611e-006,0.000000e+000,3,7.536924e-001,0.000000e+000,,,,,,,,,,,,,,32,1,4.000000e+000,0.000000e+000,0.000000e+000,0,,0,
1524647395.653,,0.000000e+000,5.499314e+001,-1.690063e-006,0.000000e+000,3,7.229013e-001,0.000000e+000,,,,,,,,,,,,,,32,1,4.000000e+000,0.000000e+000,0.000000e+000,0,,0,
1524647433.593,,0.000000e+000,5.499577e+001,-1.798678e-006,0.000000e+000,3,7.667033e-001,0.000000e+000,,,,,,,,,,,,,,32,1,4.000000e+000,7.888794e-003,0.000000e+000,0,,0,
1524647471.503,,0.000000e+000,5.499117e+001,-1.616548e-006,0.000000e+000,3,7.499384e-001,0.000000e+000,,,,,,,,,,,,,,32,1,4.000000e+000,3.952026e-003,0.000000e+000,0,,0,
1524647508.813,,0.000000e+000,5.499511e+001,-1.818941e-006,0.000000e+000,3,7.540410e-001,0.000000e+000,,,,,,,,,,,,,,32,1,4.000000e+000,9.201050e-003,0.000000e+000,0,,0,
1524647546.763,,0.000000e+000,5.499511e+001,-1.757427e-006,0.000000e+000,3,7.941505e-001,0.000000e+000,,,,,,,,,,,,,,32,1,4.000000e+000,1.319885e-003,0.000000e+000,0,,0,
1524647584.733,,0.000000e+000,5.499643e+001,-1.712304e-006,0.000000e+000,3,6.972660e-001,0.000000e+000,,,,,,,,,,,,,,32,1,4.000000e+000,1.312256e-003,0.000000e+000,0,,0,
1524647622.573,,0.000000e+000,5.500169e+001,-1.689039e-006,0.000000e+000,3,7.497025e-001,0.000000e+000,,,,,,,,,,,,,,32,1,4.000000e+000,1.319885e-003,0.000000e+000,0,,0,
1524647660.263,,0.000000e+000,5.499709e+001,-1.699734e-006,0.000000e+000,3,7.477206e-001,0.000000e+000,,,,,,,,,,,,,,32,1,4.000000e+000,1.316071e-002,0.000000e+000,0,,0,
1524647697.753,,0.000000e+000,5.499840e+001,-1.743622e-006,0.000000e+000,3,7.890080e-001,0.000000e+000,,,,,,,,,,,,,,32,1,4.000000e+000,5.260468e-003,0.000000e+000,0,,0,
1524647738.263,,0.000000e+000,5.499643e+001,-1.807576e-006,0.000000e+000,3,7.254024e-001,0.000000e+000,,,,,,,,,,,,,,32,1,4.000000e+000,1.184082e-002,0.000000e+000,0,,0,
1524647775.603,,0.000000e+000,5.499643e+001,-1.620968e-006,0.000000e+000,3,7.394114e-001,0.000000e+000,,,,,,,,,,,,,,32,1,4.000000e+000,1.184082e-002,0.000000e+000,0,,0,
1524647813.553,,0.000000e+000,5.500037e+001,-1.839775e-006,0.000000e+000,3,7.263685e-001,0.000000e+000,,,,,,,,,,,,,,32,1,4.000000e+000,1.319885e-003,0.000000e+000,0,,0,
1524647851.833,,0.000000e+000,5.499248e+001,-1.604374e-006,0.000000e+000,3,7.411692e-001,0.000000e+000,,,,,,,,,,,,,,32,1,4.000000e+000,3.940582e-003,0.000000e+000,0,,0,
1524647889.363,,0.000000e+000,5.499840e+001,-1.703494e-006,0.000000e+000,3,7.140053e-001,0.000000e+000,,,,,,,,,,,,,,32,1,4.000000e+000,5.260468e-003,0.000000e+000,0,,0,
1524647927.113,,0.000000e+000,5.499313e+001,-1.733286e-006,0.000000e+000,3,7.370312e-001,0.000000e+000,,,,,,,,,,,,,,32,1,4.000000e+000,2.628326e-003,0.000000e+000,0,,0,
1524647965.073,,0.000000e+000,5.499380e+001,-1.717210e-006,0.000000e+000,3,7.414127e-001,0.000000e+000,,,,,,,,,,,,,,32,1,4.000000e+000,1.182938e-002,0.000000e+000,0,,0,
1524648002.593,,0.000000e+000,5.499445e+001,-1.797084e-006,0.000000e+000,3,7.364987e-001,0.000000e+000,,,,,,,,,,,,,,32,1,4.000000e+000,0.000000e+000,0.000000e+000,0,,0,
1524648041.173,,0.000000e+000,5.499775e+001,-1.754578e-006,0.000000e+000,3,7.842618e-001,0.000000e+000,,,,,,,,,,,,,,32,1,4.000000e+000,9.208679e-003,0.000000e+000,0,,0,
1524648078.943,,0.000000e+000,5.499906e+001,-1.705927e-006,0.000000e+000,3,7.304745e-001,0.000000e+000,,,,,,,,,,,,,,32,1,4.000000e+000,6.580353e-003,0.000000e+000,0,,0,
1524648116.984,,0.000000e+000,5.499971e+001,-1.744430e-006,0.000000e+000,3,7.575866e-001,0.000000e+000,,,,,,,,,,,,,,32,1,4.000000e+000,2.639771e-003,0.000000e+000,0,,0,
1524648154.584,,0.000000e+000,5.499577e+001,-1.747650e-006,0.000000e+000,3,7.498394e-001,0.000000e+000,,,,,,,,,,,,,,32,1,4.000000e+000,7.888794e-003,0.000000e+000,0,,0,
1524648192.614,,0.000000e+000,5.500103e+001,-1.790363e-006,0.000000e+000,3,7.666965e-001,0.000000e+000,,,,,,,,,,,,,,32,1,4.000000e+000,2.639771e-003,0.000000e+000,0,,0,
1524648230.344,,0.000000e+000,5.499313e+001,-1.663093e-006,0.000000e+000,3,7.180063e-001,0.000000e+000,,,,,,,,,,,,,,32,1,4.000000e+000,1.050949e-002,0.000000e+000,0,,0,
1524648268.224,,0.000000e+000,5.499445e+001,-1.708267e-006,0.000000e+000,3,7.415586e-001,0.000000e+000,,,,,,,,,,,,,,32,1,4.000000e+000,5.260468e-003,0.000000e+000,0,,0,
1524648305.854,,0.000000e+000,5.499905e+001,-1.625872e-006,0.000000e+000,3,7.135660e-001,0.000000e+000,,,,,,,,,,,,,,32,1,4.000000e+000,3.948212e-003,0.000000e+000,0,,0,
1524648343.854,,0.000000e+000,5.499709e+001,-1.678753e-006,0.000000e+000,3,7.321815e-001,0.000000e+000,,,,,,,,,,,,,,32,1,4.000000e+000,1.052856e-002,0.000000e+000,0,,0,
1524648381.454,,0.000000e+000,5.499840e+001,-1.634141e-006,0.000000e+000,3,7.332641e-001,0.000000e+000,,,,,,,,,,,,,,32,1,4.000000e+000,5.260468e-003,0.000000e+000,0,,0,
1524648419.494,,0.000000e+000,5.499905e+001,-1.725565e-006,0.000000e+000,3,7.273133e-001,0.000000e+000,,,,,,,,,,,,,,32,1,4.000000e+000,3.948212e-003,0.000000e+000,0,,0,
1524648457.074,,0.000000e+000,5.499708e+001,-1.537903e-006,0.000000e+000,3,6.726664e-001,0.000000e+000,,,,,,,,,,,,,,32,1,4.000000e+000,2.620697e-003,0.000000e+000,0,,0,
1524648494.974,,0.000000e+000,5.499314e+001,-1.665080e-006,0.000000e+000,3,7.458802e-001,0.000000e+000,,,,,,,,,,,,,,32,1,4.000000e+000,5.260468e-003,0.000000e+000,0,,0,
1524648532.214,,0.000000e+000,5.499445e+001,-1.616389e-006,0.000000e+000,3,6.927347e-001,0.000000e+000,,,,,,,,,,,,,,32,1,4.000000e+000,7.881165e-003,0.000000e+000,0,,0,
1524648570.134,,0.000000e+000,5.499905e+001,-1.666241e-006,0.000000e+000,3,7.557295e-001,0.000000e+000,,,,,,,,,,,,,,32,1,4.000000e+000,1.319885e-003,0.000000e+000,0,,0,
1524648608.054,,0.000000e+000,5.499643e+001,-1.525805e-006,0.000000e+000,3,7.221391e-001,0.000000e+000,,,,,,,,,,,,,,32,1,4.000000e+000,1.448059e-002,0.000000e+000,0,,0,
1524648645.744,,0.000000e+000,5.499773e+001,-1.619619e-006,0.000000e+000,3,6.941774e-001,0.000000e+000,,,,,,,,,,,,,,32,1,4.000000e+000,1.308441e-003,0.000000e+000,0,,0,
1524648683.034,,0.000000e+000,5.500563e+001,-1.721527e-006,0.000000e+000,3,7.819031e-001,0.000000e+000,,,,,,,,,,,,,,32,1,4.000000e+000,1.448059e-002,0.000000e+000,0,,0,
1524648720.724,,0.000000e+000,5.499643e+001,-1.562138e-006,0.000000e+000,3,6.529000e-001,0.000000e+000,,,,,,,,,,,,,,32,1,4.000000e+000,1.184082e-002,0.000000e+000,0,,0,
1524648758.644,,0.000000e+000,5.499577e+001,-1.717776e-006,0.000000e+000,3,7.502384e-001,0.000000e+000,,,,,,,,,,,,,,32,1,4.000000e+000,2.632141e-003,0.000000e+000,0,,0,
1524648796.764,,0.000000e+000,5.499643e+001,-1.641598e-006,0.000000e+000,3,7.218713e-001,0.000000e+000,,,,,,,,,,,,,,32,1,4.000000e+000,9.208679e-003,0.000000e+000,0,,0,
1524648834.685,,0.000000e+000,5.499774e+001,-1.667486e-006,0.000000e+000,3,7.135763e-001,0.000000e+000,,,,,,,,,,,,,,32,1,4.000000e+000,3.940582e-003,0.000000e+000,0,,0,
1524648872.675,,0.000000e+000,5.499773e+001,-1.725478e-006,0.000000e+000,3,7.669523e-001,0.000000e+000,,,,,,,,,,,,,,32,1,4.000000e+000,1.308441e-003,0.000000e+000,0,,0,
1524648910.325,,0.000000e+000,5.500037e+001,-1.656589e-006,0.000000e+000,3,7.105926e-001,0.000000e+000,,,,,,,,,,,,,,32,1,4.000000e+000,1.319885e-003,0.000000e+000,0,,0,
1524648948.315,,0.000000e+000,5.499971e+001,-1.704874e-006,0.000000e+000,3,7.478739e-001,0.000000e+000,,,,,,,,,,,,,,32,1,4.000000e+000,2.639771e-003,0.000000e+000,0,,0,
1524648985.885,,0.000000e+000,5.499380e+001,-1.620576e-006,0.000000e+000,3,7.266296e-001,0.000000e+000,,,,,,,,,,,,,,32,1,4.000000e+000,3.948212e-003,0.000000e+000,0,,0,
1524649023.935,,0.000000e+000,5.499643e+001,-1.696975e-006,0.000000e+000,3,7.332520e-001,0.000000e+000,,,,,,,,,,,,,,32,1,4.000000e+000,1.312256e-003,0.000000e+000,0,,0,
1524649061.535,,0.000000e+000,5.499577e+001,-1.602709e-006,0.000000e+000,3,7.103265e-001,0.000000e+000,,,,,,,,,,,,,,32,1,4.000000e+000,1.052094e-002,0.000000e+000,0,,0,
1524649099.565,,0.000000e+000,5.499708e+001,-1.737701e-006,0.000000e+000,3,7.433202e-001,0.000000e+000,,,,,,,,,,,,,,32,1,4.000000e+000,2.620697e-003,0.000000e+000,0,,0,
1524649137.205,,0.000000e+000,5.499380e+001,-1.650643e-006,0.000000e+000,3,7.239302e-001,0.000000e+000,,,,,,,,,,,,,,32,1,4.000000e+000,1.710129e-002,0.000000e+000,0,,0,
1524649174.655,,0.000000e+000,5.499117e+001,-1.739267e-006,0.000000e+000,3,7.524834e-001,0.000000e+000,,,,,,,,,,,,,,32,1,4.000000e+000,1.312256e-003,0.000000e+000,0,,0,
1524649212.295,,0.000000e+000,5.499905e+001,-1.656275e-006,0.000000e+000,3,7.141492e-001,0.000000e+000,,,,,,,,,,,,,,32,1,4.000000e+000,1.319885e-003,0.000000e+000,0,,0,
1524649250.245,,0.000000e+000,5.499906e+001,-1.712525e-006,0.000000e+000,3,7.423944e-001,0.000000e+000,,,,,,,,,,,,,,32,1,4.000000e+000,9.220123e-003,0.000000e+000,0,,0,
1524649287.905,,0.000000e+000,5.499708e+001,-1.686809e-006,0.000000e+000,3,7.242864e-001,0.000000e+000,,,,,,,,,,,,,,32,1,4.000000e+000,0.000000e+000,0.000000e+000,0,,0,
1524649325.525,,0.000000e+000,5.499972e+001,-1.692108e-006,0.000000e+000,3,7.486153e-001,0.000000e+000,,,,,,,,,,,,,,32,1,4.000000e+000,5.268097e-003,0.000000e+000,0,,0,
1524649363.005,,0.000000e+000,5.500037e+001,-1.596798e-006,0.000000e+000,3,7.033607e-001,0.000000e+000,,,,,,,,,,,,,,32,1,4.000000e+000,1.319885e-003,0.000000e+000,0,,0,
1524649401.765,,0.000000e+000,5.499313e+001,-1.686410e-006,0.000000e+000,3,7.181881e-001,0.000000e+000,,,,,,,,,,,,,,32,1,4.000000e+000,2.628326e-003,0.000000e+000,0,,0,
1524649440.855,,0.000000e+000,5.499248e+001,-1.654943e-006,0.000000e+000,3,7.041886e-001,0.000000e+000,,,,,,,,,,,,,,32,1,4.000000e+000,1.182938e-002,0.000000e+000,0,,0,
1524649478.795,,0.000000e+000,5.499051e+001,-1.774181e-006,0.000000e+000,3,7.842011e-001,0.000000e+000,,,,,,,,,,,,,,32,1,4.000000e+000,2.632141e-003,0.000000e+000,0,,0,
1524649516.325,,0.000000e+000,5.499643e+001,-1.726019e-006,0.000000e+000,3,7.265943e-001,0.000000e+000,,,,,,,,,,,,,,32,1,4.000000e+000,1.312256e-003,0.000000e+000,0,,0,
1524649554.196,,0.000000e+000,5.500103e+001,-1.778410e-006,0.000000e+000,3,7.458357e-001,0.000000e+000,,,,,,,,,,,,,,32,1,4.000000e+000,7.888794e-003,0.000000e+000,0,,0,
1524649591.996,,0.000000e+000,5.500169e+001,-1.805754e-006,0.000000e+000,3,7.243564e-001,0.000000e+000,,,,,,,,,,,,,,32,1,4.000000e+000,3.959656e-003,0.000000e+000,0,,0,
1524649629.276,,0.000000e+000,5.499511e+001,-1.781504e-006,0.000000e+000,3,7.476007e-001,0.000000e+000,,,,,,,,,,,,,,32,1,4.000000e+000,3.940582e-003,0.000000e+000,0,,0,
1524649667.136,,0.000000e+000,5.499708e+001,-1.708828e-006,0.000000e+000,3,7.292870e-001,0.000000e+000,,,,,,,,,,,,,,32,1,4.000000e+000,5.260468e-003,0.000000e+000,0,,0,
1524649705.126,,0.000000e+000,5.499774e+001,-1.740747e-006,0.000000e+000,3,7.343568e-001,0.000000e+000,,,,,,,,,,,,,,32,1,4.000000e+000,3.940582e-003,0.000000e+000,0,,0,
1524649742.726,,0.000000e+000,5.500037e+001,-1.707845e-006,0.000000e+000,3,7.226536e-001,0.000000e+000,,,,,,,,,,,,,,32,1,4.000000e+000,1.319885e-003,0.000000e+000,0,,0,
1524649780.776,,0.000000e+000,5.499773e+001,-1.807413e-006,0.000000e+000,3,7.578258e-001,0.000000e+000,,,,,,,,,,,,,,32,1,4.000000e+000,1.308441e-003,0.000000e+000,0,,0,
1524649818.816,,0.000000e+000,5.500103e+001,-1.779241e-006,0.000000e+000,3,7.525849e-001,0.000000e+000,,,,,,,,,,,,,,32,1,4.000000e+000,2.639771e-003,0.000000e+000,0,,0,
1524649856.686,,0.000000e+000,5.498985e+001,-1.729812e-006,0.000000e+000,3,7.212723e-001,0.000000e+000,,,,,,,,,,,,,,32,1,4.000000e+000,6.580353e-003,0.000000e+000,0,,0,
1524649895.296,,0.000000e+000,5.499051e+001,-1.761356e-006,0.000000e+000,3,7.240195e-001,0.000000e+000,,,,,,,,,,,,,,32,1,4.000000e+000,7.888794e-003,0.000000e+000,0,,0,
1524649933.096,,0.000000e+000,5.499971e+001,-1.788012e-006,0.000000e+000,3,7.557211e-001,0.000000e+000,,,,,,,,,,,,,,32,1,4.000000e+000,2.639771e-003,0.000000e+000,0,,0,
1524649970.186,,0.000000e+000,5.500497e+001,-1.700099e-006,0.000000e+000,3,7.134420e-001,0.000000e+000,,,,,,,,,,,,,,32,1,4.000000e+000,0.000000e+000,0.000000e+000,0,,0,
1524650008.326,,0.000000e+000,5.499643e+001,-1.829681e-006,0.000000e+000,3,7.191219e-001,0.000000e+000,,,,,,,,,,,,,,32,1,4.000000e+000,1.312256e-003,0.000000e+000,0,,0,
1524650046.306,,0.000000e+000,5.499445e+001,-1.758062e-006,0.000000e+000,3,7.463903e-001,0.000000e+000,,,,,,,,,,,,,,32,1,4.000000e+000,2.628326e-003,0.000000e+000,0,,0,
1524650084.186,,0.000000e+000,5.500169e+001,-1.720597e-006,0.000000e+000,3,7.191304e-001,0.000000e+000,,,,,,,,,,,,,,32,1,4.000000e+000,1.319885e-003,0.000000e+000,0,,0,
1524650121.586,,0.000000e+000,5.500037e+001,-1.777692e-006,0.000000e+000,3,7.600032e-001,0.000000e+000,,,,,,,,,,,,,,32,1,4.000000e+000,1.319885e-003,0.000000e+000,0,,0,
1524650158.516,,0.000000e+000,5.499183e+001,-1.662286e-006,0.000000e+000,3,7.183374e-001,0.000000e+000,,,,,,,,,,,,,,32,1,4.000000e+000,1.840973e-002,0.000000e+000,0,,0,
1524650195.916,,0.000000e+000,5.499708e+001,-1.710041e-006,0.000000e+000,3,7.375288e-001,0.000000e+000,,,,,,,,,,,,,,32,1,4.000000e+000,2.620697e-003,0.000000e+000,0,,0,
1524650233.376,,0.000000e+000,5.499380e+001,-1.661770e-006,0.000000e+000,3,7.037849e-001,0.000000e+000,,,,,,,,,,,,,,32,1,4.000000e+000,3.948212e-003,0.000000e+000,0,,0,
1524650270.757,,0.000000e+000,5.499182e+001,-1.808758e-006,0.000000e+000,3,7.396949e-001,0.000000e+000,,,,,,,,,,,,,,32,1,4.000000e+000,0.000000e+000,0.000000e+000,0,,0,
1524650308.757,,0.000000e+000,5.499313e+001,-1.714035e-006,0.000000e+000,3,7.567315e-001,0.000000e+000,,,,,,,,,,,,,,32,1,4.000000e+000,2.628326e-003,0.000000e+000,0,,0,
1524650346.667,,0.000000e+000,5.499774e+001,-1.623370e-006,0.000000e+000,3,7.216181e-001,0.000000e+000,,,,,,,,,,,,,,32,1,4.000000e+000,3.940582e-003,0.000000e+000,0,,0,