File: Input_All/TC04-12-01K_VRMac_57K_12000s_VRMde_55K.dc.dat
[Header]
TITLE,MPMS DC Measurement
BYAPP,MPMS Measurement,2.1,Summary
FILEOPENTIME, 1524156068.138000 4/19/2018, 10:41:08 AM

INFO, APPNAME, MPMS MultiVu Application, Revision 1.61,  Build 082

INFO, NAME, TC04-12-01K
INFO, WEIGHT, 1.000
INFO, AREA, 1.000
INFO, LENGTH, 1.000
INFO, SHAPE, 0
INFO, COMMENT,
INFO, SEQUENCE FILE: VRMac_57K_12000s_VRMde_55K.seq


INFO, BACKGROUND DATA FILE:, None


STARTUPAXIS,X,4,LINEAR,AUTO,0.000000,0.000000
STARTUPAXIS,Y1,5,LINEAR,AUTO,0.000000,0.000000


STARTUPGROUP,Longitudinal
FIELDGROUP,Longitudinal,1,2,3,4,5,6,7,8,9,15,16,17,18,27,28
FIELDGROUP,Transverse,1,2,3,4,10,11,12,13,14,19,20,21,22,27,28

PLOT_APPEARANCE,ALL,HORZ_GRID_ON,VERT_GRID_ON,MARKERS_AND_LINES

[Data]
Time,Comment,Field (Oe),Temperature (K),Long Moment (emu),Long Scan Std Dev,Long Algorithm,Long Reg Fit,Long Percent Error (%),Trans Moment (emu),Trans Scan Std Dev,Trans Algorithm,Trans Reg Fit,Trans Percent Error (%),Long Moment [w/o ABS] (emu),Long Scan Std Dev [w/o ABS],Long Reg Fit [w/o ABS],Long Percent Error [w/o ABS] (%),Trans Moment [w/o ABS] (emu),Trans Scan Std Dev [w/o ABS],Trans Reg Fit [w/o ABS],Trans Percent Error [w/o ABS] (%),Points per Scan,Scans per Measurement,Scan Length (cm),Delta Temp (K),Rot Position (deg),Error,EC Comp. Running,Using ABS,
1524156068.138,,0.000000e+000,5.498261e+001,-1.269759e-005,0.000000e+000,3,9.627585e-001,0.000000e+000,,,,,,,,,,,,,,32,1,4.000000e+000,1.314926e-002,0.000000e+000,0,,0,
1524156106.508,,0.000000e+000,5.502274e+001,-1.263327e-005,0.000000e+000,3,9.666131e-001,0.000000e+000,,,,,,,,,,,,,,32,1,4.000000e+000,3.948212e-003,0.000000e+000,0,,0,
1524156143.828,,0.000000e+000,5.502538e+001,-1.235868e-005,0.000000e+000,3,9.596439e-001,0.000000e+000,,,,,,,,,,,,,,32,1,4.000000e+000,1.319885e-003,0.000000e+000,0,,0,
1524156181.808,,0.000000e+000,5.501221e+001,-1.206256e-005,0.000000e+000,3,9.656268e-001,0.000000e+000,,,,,,,,,,,,,,32,1,4.000000e+000,1.319885e-003,0.000000e+000,0,,0,
1524156219.218,,0.000000e+000,5.501221e+001,-1.189906e-005,0.000000e+000,3,9.637499e-001,0.000000e+000,,,,,,,,,,,,,,32,1,4.000000e+000,3.952026e-003,0.000000e+000,0,,0,
1524156256.918,,0.000000e+000,5.500893e+001,-1.161090e-005,0.000000e+000,3,9.646095e-001,0.000000e+000,,,,,,,,,,,,,,32,1,4.000000e+000,2.628326e-003,0.000000e+000,0,,0,
1524156294.859,,0.000000e+000,5.499905e+001,-1.142774e-005,0.000000e+000,3,9.650252e-001,0.000000e+000,,,,,,,,,,,,,,32,1,4.000000e+000,1.319885e-003,0.000000e+000,0,,0,
1524156332.889,,0.000000e+000,5.499971e+001,-1.113283e-005,0.000000e+000,3,9.586967e-001,0.000000e+000,,,,,,,,,,,,,,32,1,4.000000e+000,2.639771e-003,0.000000e+000,0,,0,
1524156370.749,,0.000000e+000,5.499117e+001,-1.081491e-005,0.000000e+000,3,9.603905e-001,0.000000e+000,,,,,,,,,,,,,,32,1,4.000000e+000,3.952026e-003,0.000000e+000,0,,0,
1524156407.909,,0.000000e+000,5.499840e+001,-1.083011e-005,0.000000e+000,3,9.596103e-001,0.000000e+000,,,,,,,,,,,,,,32,1,4.000000e+000,5.260468e-003,0.000000e+000,0,,0,
1524156445.719,,0.000000e+000,5.499839e+001,-1.057337e-005,0.000000e+000,3,9.569391e-001,0.000000e+000,,,,,,,,,,,,,,32,1,4.000000e+000,0.000000e+000,0.000000e+000,0,,0,
1524156484.499,,0.000000e+000,5.499839e+001,-1.043121e-005,0.000000e+000,3,9.616463e-001,0.000000e+000,,,,,,,,,,,,,,32,1,4.000000e+000,0.000000e+000,0.000000e+000,0,,0,
1524156522.379,,0.000000e+000,5.500037e+001,-1.022467e-005,0.000000e+000,3,9.676527e-001,0.000000e+000,,,,,,,,,,,,,,32,1,4.000000e+000,3.959656e-003,0.000000e+000,0,,0,
1524156560.549,,0.000000e+000,5.499972e+001,-1.001230e-005,0.000000e+000,3,9.546577e-001,0.000000e+000,,,,,,,,,,,,,,32,1,4.000000e+000,5.268097e-003,0.000000e+000,0,,0,
1524156598.529,,0.000000e+000,5.499642e+001,-9.835569e-006,0.000000e+000,3,9.615520e-001,0.000000e+000,,,,,,,,,,,,,,32,1,4.000000e+000,3.940582e-003,0.000000e+000,0,,0,
1524156635.889,,0.000000e+000,5.500498e+001,-9.753715e-006,0.000000e+000,3,9.587144e-001,0.000000e+000,,,,,,,,,,,,,,32,1,4.000000e+000,2.620697e-003,0.000000e+000,0,,0,
1524156673.679,,0.000000e+000,5.499905e+001,-9.610790e-006,0.000000e+000,3,9.581130e-001,0.000000e+000,,,,,,,,,,,,,,32,1,4.000000e+000,1.319885e-003,0.000000e+000,0,,0,
1524156710.849,,0.000000e+000,5.499971e+001,-9.491408e-006,0.000000e+000,3,9.560905e-001,0.000000e+000,,,,,,,,,,,,,,32,1,4.000000e+000,2.639771e-003,0.000000e+000,0,,0,
1524156748.839,,0.000000e+000,5.499248e+001,-9.320156e-006,0.000000e+000,3,9.704034e-001,0.000000e+000,,,,,,,,,,,,,,32,1,4.000000e+000,1.319885e-003,0.000000e+000,0,,0,
1524156786.069,,0.000000e+000,5.500300e+001,-9.130825e-006,0.000000e+000,3,9.563775e-001,0.000000e+000,,,,,,,,,,,,,,32,1,4.000000e+000,9.220123e-003,0.000000e+000,0,,0,
1524156823.839,,0.000000e+000,5.500037e+001,-9.039241e-006,0.000000e+000,3,9.620156e-001,0.000000e+000,,,,,,,,,,,,,,32,1,4.000000e+000,3.959656e-003,0.000000e+000,0,,0,
1524156861.359,,0.000000e+000,5.499840e+001,-9.004527e-006,0.000000e+000,3,9.618557e-001,0.000000e+000,,,,,,,,,,,,,,32,1,4.000000e+000,2.628326e-003,0.000000e+000,0,,0,
1524156898.579,,0.000000e+000,5.500234e+001,-8.857464e-006,0.000000e+000,3,9.524973e-001,0.000000e+000,,,,,,,,,,,,,,32,1,4.000000e+000,5.260468e-003,0.000000e+000,0,,0,
1524156937.009,,0.000000e+000,5.500235e+001,-8.718869e-006,0.000000e+000,3,9.579849e-001,0.000000e+000,,,,,,,,,,,,,,32,1,4.000000e+000,1.052856e-002,0.000000e+000,0,,0,
1524156974.299,,0.000000e+000,5.499972e+001,-8.644887e-006,0.000000e+000,3,9.546224e-001,0.000000e+000,,,,,,,,,,,,,,32,1,4.000000e+000,5.268097e-003,0.000000e+000,0,,0,
1524157012.000,,0.000000e+000,5.499840e+001,-8.553049e-006,0.000000e+000,3,9.554472e-001,0.000000e+000,,,,,,,,,,,,,,32,1,4.000000e+000,5.260468e-003,0.000000e+000,0,,0,
1524157049.480,,0.000000e+000,5.500103e+001,-8.473401e-006,0.000000e+000,3,9.525334e-001,0.000000e+000,,,,,,,,,,,,,,32,1,4.000000e+000,5.279541e-003,0.000000e+000,0,,0,
1524157087.080,,0.000000e+000,5.499773e+001,-8.313261e-006,0.000000e+000,3,9.544594e-001,0.000000e+000,,,,,,,,,,,,,,32,1,4.000000e+000,1.308441e-003,0.000000e+000,0,,0,
1524157124.470,,0.000000e+000,5.499905e+001,-8.356980e-006,0.000000e+000,3,9.535560e-001,0.000000e+000,,,,,,,,,,,,,,32,1,4.000000e+000,3.948212e-003,0.000000e+000,0,,0,
1524157162.500,,0.000000e+000,5.499445e+001,-8.139990e-006,0.000000e+000,3,9.479305e-001,0.000000e+000,,,,,,,,,,,,,,32,1,4.000000e+000,2.628326e-003,0.000000e+000,0,,0,
1524157201.160,,0.000000e+000,5.498919e+001,-8.037357e-006,0.000000e+000,3,9.528228e-001,0.000000e+000,,,,,,,,,,,,,,32,1,4.000000e+000,1.578140e-002,0.000000e+000,0,,0,
1524157239.370,,0.000000e+000,5.499313e+001,-7.931919e-006,0.000000e+000,3,9.582353e-001,0.000000e+000,,,,,,,,,,,,,,32,1,4.000000e+000,2.630997e-002,0.000000e+000,0,,0,
1524157276.430,,0.000000e+000,5.499905e+001,-7.937848e-006,0.000000e+000,3,9.492372e-001,0.000000e+000,,,,,,,,,,,,,,32,1,4.000000e+000,1.319885e-003,0.000000e+000,0,,0,
1524157313.660,,0.000000e+000,5.499511e+001,-7.841081e-006,0.000000e+000,3,9.518027e-001,0.000000e+000,,,,,,,,,,,,,,32,1,4.000000e+000,9.201050e-003,0.000000e+000,0,,0,
1524157351.370,,0.000000e+000,5.499380e+001,-7.738213e-006,0.000000e+000,3,9.493970e-001,0.000000e+000,,,,,,,,,,,,,,32,1,4.000000e+000,6.572723e-003,0.000000e+000,0,,0,
1524157388.980,,0.000000e+000,5.500103e+001,-7.645759e-006,0.000000e+000,3,9.480449e-001,0.000000e+000,,,,,,,,,,,,,,32,1,4.000000e+000,0.000000e+000,0.000000e+000,0,,0,
1524157426.650,,0.000000e+000,5.499905e+001,-7.620137e-006,0.000000e+000,3,9.538891e-001,0.000000e+000,,,,,,,,,,,,,,32,1,4.000000e+000,1.319885e-003,0.000000e+000,0,,0,
1524157464.500,,0.000000e+000,5.500169e+001,-7.562548e-006,0.000000e+000,3,9.530823e-001,0.000000e+000,,,,,,,,,,,,,,32,1,4.000000e+000,1.319885e-003,0.000000e+000,0,,0,
1524157502.340,,0.000000e+000,5.499972e+001,-7.451419e-006,0.000000e+000,3,9.501209e-001,0.000000e+000,,,,,,,,,,,,,,32,1,4.000000e+000,5.268097e-003,0.000000e+000,0,,0,
1524157540.730,,0.000000e+000,5.499577e+001,-7.372403e-006,0.000000e+000,3,9.487931e-001,0.000000e+000,,,,,,,,,,,,,,32,1,4.000000e+000,2.632141e-003,0.000000e+000,0,,0,
1524157577.870,,0.000000e+000,5.499840e+001,-7.346329e-006,0.000000e+000,3,9.560566e-001,0.000000e+000,,,,,,,,,,,,,,32,1,4.000000e+000,2.628326e-003,0.000000e+000,0,,0,
1524157615.120,,0.000000e+000,5.500103e+001,-7.256825e-006,0.000000e+000,3,9.625636e-001,0.000000e+000,,,,,,,,,,,,,,32,1,4.000000e+000,0.000000e+000,0.000000e+000,0,,0,
1524157652.630,,0.000000e+000,5.499774e+001,-7.178698e-006,0.000000e+000,3,9.593371e-001,0.000000e+000,,,,,,,,,,,,,,32,1,4.000000e+000,3.940582e-003,0.000000e+000,0,,0,
1524157690.750,,0.000000e+000,5.500168e+001,-7.087976e-006,0.000000e+000,3,9.470467e-001,0.000000e+000,,,,,,,,,,,,,,32,1,4.000000e+000,6.580353e-003,0.000000e+000,0,,0,
1524157728.971,,0.000000e+000,5.499643e+001,-7.103022e-006,0.000000e+000,3,9.482249e-001,0.000000e+000,,,,,,,,,,,,,,32,1,4.000000e+000,1.312256e-003,0.000000e+000,0,,0,
1524157766.951,,0.000000e+000,5.499971e+001,-6.983681e-006,0.000000e+000,3,9.524224e-001,0.000000e+000,,,,,,,,,,,,,,32,1,4.000000e+000,2.639771e-003,0.000000e+000,0,,0,
1524157804.831,,0.000000e+000,5.499511e+001,-6.882621e-006,0.000000e+000,3,9.559462e-001,0.000000e+000,,,,,,,,,,,,,,32,1,4.000000e+000,6.568909e-003,0.000000e+000,0,,0,
1524157842.511,,0.000000e+000,5.499643e+001,-6.931982e-006,0.000000e+000,3,9.499636e-001,0.000000e+000,,,,,,,,,,,,,,32,1,4.000000e+000,1.312256e-003,0.000000e+000,0,,0,
1524157880.511,,0.000000e+000,5.499839e+001,-6.775356e-006,0.000000e+000,3,9.562209e-001,0.000000e+000,,,,,,,,,,,,,,32,1,4.000000e+000,0.000000e+000,0.000000e+000,0,,0,
1524157918.231,,0.000000e+000,5.499773e+001,-6.773096e-006,0.000000e+000,3,9.462546e-001,0.000000e+000,,,,,,,,,,,,,,32,1,4.000000e+000,1.308441e-003,0.000000e+000,0,,0,
1524157956.151,,0.000000e+000,5.499708e+001,-6.648976e-006,0.000000e+000,3,9.523233e-001,0.000000e+000,,,,,,,,,,,,,,32,1,4.000000e+000,2.620697e-003,0.000000e+000,0,,0,
1524157993.821,,0.000000e+000,5.499577e+001,-6.661988e-006,0.000000e+000,3,9.458863e-001,0.000000e+000,,,,,,,,,,,,,,32,1,4.000000e+000,0.000000e+000,0.000000e+000,0,,0,
1524158031.891,,0.000000e+000,5.500629e+001,-6.556914e-006,0.000000e+000,3,9.627575e-001,0.000000e+000,,,,,,,,,,,,,,32,1,4.000000e+000,5.249023e-003,0.000000e+000,0,,0,
1524158070.351,,0.000000e+000,5.499248e+001,-6.583847e-006,0.000000e+000,3,9.488787e-001,0.000000e+000,,,,,,,,,,,,,,32,1,4.000000e+000,1.319885e-003,0.000000e+000,0,,0,
1524158107.481,,0.000000e+000,5.499841e+001,-6.564627e-006,0.000000e+000,3,9.470329e-001,0.000000e+000,,,,,,,,,,,,,,32,1,4.000000e+000,1.052856e-002,0.000000e+000,0,,0,
1524158145.671,,0.000000e+000,5.499773e+001,-6.522805e-006,0.000000e+000,3,9.453916e-001,0.000000e+000,,,,,,,,,,,,,,32,1,4.000000e+000,1.308441e-003,0.000000e+000,0,,0,
1524158183.871,,0.000000e+000,5.499380e+001,-6.371008e-006,0.000000e+000,3,9.395122e-001,0.000000e+000,,,,,,,,,,,,,,32,1,4.000000e+000,1.308441e-003,0.000000e+000,0,,0,
1524158221.531,,0.000000e+000,5.499511e+001,-6.357193e-006,0.000000e+000,3,9.588691e-001,0.000000e+000,,,,,,,,,,,,,,32,1,4.000000e+000,1.319885e-003,0.000000e+000,0,,0,
1524158259.431,,0.000000e+000,5.499379e+001,-6.295298e-006,0.000000e+000,3,9.481550e-001,0.000000e+000,,,,,,,,,,,,,,32,1,4.000000e+000,9.201050e-003,0.000000e+000,0,,0,
1524158298.121,,0.000000e+000,5.499577e+001,-6.210288e-006,0.000000e+000,3,9.321117e-001,0.000000e+000,,,,,,,,,,,,,,32,1,4.000000e+000,5.249023e-003,0.000000e+000,0,,0,
1524158336.191,,0.000000e+000,5.499643e+001,-6.179180e-006,0.000000e+000,3,9.495572e-001,0.000000e+000,,,,,,,,,,,,,,32,1,4.000000e+000,6.568909e-003,0.000000e+000,0,,0,
1524158373.361,,0.000000e+000,5.500234e+001,-6.190412e-006,0.000000e+000,3,9.420847e-001,0.000000e+000,,,,,,,,,,,,,,32,1,4.000000e+000,7.900238e-003,0.000000e+000,0,,0,
1524158411.471,,0.000000e+000,5.500169e+001,-6.117836e-006,0.000000e+000,3,9.423136e-001,0.000000e+000,,,,,,,,,,,,,,32,1,4.000000e+000,9.208679e-003,0.000000e+000,0,,0,
1524158449.852,,0.000000e+000,5.499972e+001,-6.041776e-006,0.000000e+000,3,9.461421e-001,0.000000e+000,,,,,,,,,,,,,,32,1,4.000000e+000,5.268097e-003,0.000000e+000,0,,0,
1524158486.972,,0.000000e+000,5.499708e+001,-6.014406e-006,0.000000e+000,3,9.446102e-001,0.000000e+000,,,,,,,,,,,,,,32,1,4.000000e+000,0.000000e+000,0.000000e+000,0,,0,
1524158549.282,,0.000000e+000,5.499971e+001,-5.890688e-006,0.000000e+000,3,9.461325e-001,0.000000e+000,,,,,,,,,,,,,,32,1,4.000000e+000,2.639771e-003,0.000000e+000,0,,0,
1524158587.032,,0.000000e+000,5.499840e+001,-5.909424e-006,0.000000e+000,3,9.454010e-001,0.000000e+000,,,,,,,,,,,,,,32,1,4.000000e+000,2.628326e-003,0.000000e+000,0,,0,
1524158624.382,,0.000000e+000,5.499773e+001,-5.812150e-006,0.000000e+000,3,9.404752e-001,0.000000e+000,,,,,,,,,,,,,,32,1,4.000000e+000,1.308441e-003,0.000000e+000,0,,0,
1524158662.232,,0.000000e+000,5.500300e+001,-5.888173e-006,0.000000e+000,3,9.401835e-001,0.000000e+000,,,,,,,,,,,,,,32,1,4.000000e+000,3.940582e-003,0.000000e+000,0,,0,
1524158700.702,,0.000000e+000,5.499773e+001,-5.832869e-006,0.000000e+000,3,9.392983e-001,0.000000e+000,,,,,,,,,,,,,,32,1,4.000000e+000,1.308441e-003,0.000000e+000,0,,0,
1524158738.542,,0.000000e+000,5.500037e+001,-5.819553e-006,0.000000e+000,3,9.441693e-001,0.000000e+000,,,,,,,,,,,,,,32,1,4.000000e+000,1.319885e-003,0.000000e+000,0,,0,
1524158776.662,,0.000000e+000,5.499773e+001,-5.740226e-006,0.000000e+000,3,9.390462e-001,0.000000e+000,,,,,,,,,,,,,,32,1,4.000000e+000,1.308441e-003,0.000000e+000,0,,0,
1524158852.222,,0.000000e+000,5.500103e+001,-5.632952e-006,0.000000e+000,3,9.461927e-001,0.000000e+000,,,,,,,,,,,,,,32,1,4.000000e+000,5.279541e-003,0.000000e+000,0,,0,
1524158889.352,,0.000000e+000,5.499183e+001,-5.669131e-006,0.000000e+000,3,9.380316e-001,0.000000e+000,,,,,,,,,,,,,,32,1,4.000000e+000,7.888794e-003,0.000000e+000,0,,0,
1524158926.762,,0.000000e+000,5.499840e+001,-5.560134e-006,0.000000e+000,3,9.494402e-001,0.000000e+000,,,,,,,,,,,,,,32,1,4.000000e+000,7.900238e-003,0.000000e+000,0,,0,
1524158964.712,,0.000000e+000,5.499905e+001,-5.595728e-006,0.000000e+000,3,9.303485e-001,0.000000e+000,,,,,,,,,,,,,,32,1,4.000000e+000,1.319885e-003,0.000000e+000,0,,0,
1524159002.912,,0.000000e+000,5.499642e+001,-5.486585e-006,0.000000e+000,3,9.284410e-001,0.000000e+000,,,,,,,,,,,,,,32,1,4.000000e+000,3.940582e-003,0.000000e+000,0,,0,
1524159040.802,,0.000000e+000,5.499840e+001,-5.384652e-006,0.000000e+000,3,9.386799e-001,0.000000e+000,,,,,,,,,,,,,,32,1,4.000000e+000,5.260468e-003,0.000000e+000,0,,0,
1524159078.442,,0.000000e+000,5.499905e+001,-5.404630e-006,0.000000e+000,3,9.313454e-001,0.000000e+000,,,,,,,,,,,,,,32,1,4.000000e+000,3.948212e-003,0.000000e+000,0,,0,
1524159116.542,,0.000000e+000,5.499511e+001,-5.325825e-006,0.000000e+000,3,9.544768e-001,0.000000e+000,,,,,,,,,,,,,,32,1,4.000000e+000,1.319885e-003,0.000000e+000,0,,0,
1524159154.203,,0.000000e+000,5.499577e+001,-5.370393e-006,0.000000e+000,3,9.362029e-001,0.000000e+000,,,,,,,,,,,,,,32,1,4.000000e+000,5.249023e-003,0.000000e+000,0,,0,
1524159191.823,,0.000000e+000,5.499773e+001,-5.271781e-006,0.000000e+000,3,9.581418e-001,0.000000e+000,,,,,,,,,,,,,,32,1,4.000000e+000,1.308441e-003,0.000000e+000,0,,0,
1524159228.863,,0.000000e+000,5.500300e+001,-5.345834e-006,0.000000e+000,3,9.394275e-001,0.000000e+000,,,,,,,,,,,,,,32,1,4.000000e+000,3.940582e-003,0.000000e+000,0,,0,
1524159266.793,,0.000000e+000,5.500037e+001,-5.251993e-006,0.000000e+000,3,9.399377e-001,0.000000e+000,,,,,,,,,,,,,,32,1,4.000000e+000,1.319885e-003,0.000000e+000,0,,0,
1524159304.663,,0.000000e+000,5.499905e+001,-5.255741e-006,0.000000e+000,3,9.322503e-001,0.000000e+000,,,,,,,,,,,,,,32,1,4.000000e+000,1.319885e-003,0.000000e+000,0,,0,
1524159341.723,,0.000000e+000,5.500629e+001,-5.145191e-006,0.000000e+000,3,9.387023e-001,0.000000e+000,,,,,,,,,,,,,,32,1,4.000000e+000,7.888794e-003,0.000000e+000,0,,0,
1524159379.773,,0.000000e+000,5.499313e+001,-5.106258e-006,0.000000e+000,3,9.345663e-001,0.000000e+000,,,,,,,,,,,,,,32,1,4.000000e+000,1.050949e-002,0.000000e+000,0,,0,
1524159417.423,,0.000000e+000,5.499511e+001,-5.143389e-006,0.000000e+000,3,9.326563e-001,0.000000e+000,,,,,,,,,,,,,,32,1,4.000000e+000,6.568909e-003,0.000000e+000,0,,0,
1524159455.403,,0.000000e+000,5.500432e+001,-5.050581e-006,0.000000e+000,3,9.479290e-001,0.000000e+000,,,,,,,,,,,,,,32,1,4.000000e+000,3.940582e-003,0.000000e+000,0,,0,
1524159493.523,,0.000000e+000,5.499905e+001,-5.093760e-006,0.000000e+000,3,9.335233e-001,0.000000e+000,,,,,,,,,,,,,,32,1,4.000000e+000,3.948212e-003,0.000000e+000,0,,0,
1524159531.043,,0.000000e+000,5.499577e+001,-5.053065e-006,0.000000e+000,3,9.357346e-001,0.000000e+000,,,,,,,,,,,,,,32,1,4.000000e+000,7.888794e-003,0.000000e+000,0,,0,
1524159569.043,,0.000000e+000,5.499313e+001,-5.050320e-006,0.000000e+000,3,9.282517e-001,0.000000e+000,,,,,,,,,,,,,,32,1,4.000000e+000,7.892609e-003,0.000000e+000,0,,0,
1524159606.373,,0.000000e+000,5.500037e+001,-4.984009e-006,0.000000e+000,3,9.241535e-001,0.000000e+000,,,,,,,,,,,,,,32,1,4.000000e+000,3.959656e-003,0.000000e+000,0,,0,
1524159644.723,,0.000000e+000,5.499708e+001,-4.967436e-006,0.000000e+000,3,9.346693e-001,0.000000e+000,,,,,,,,,,,,,,32,1,4.000000e+000,5.260468e-003,0.000000e+000,0,,0,
1524159681.303,,0.000000e+000,5.499643e+001,-4.946504e-006,0.000000e+000,3,9.346225e-001,0.000000e+000,,,,,,,,,,,,,,32,1,4.000000e+000,1.312256e-003,0.000000e+000,0,,0,
1524159719.183,,0.000000e+000,5.499773e+001,-4.962729e-006,0.000000e+000,3,9.375499e-001,0.000000e+000,,,,,,,,,,,,,,32,1,4.000000e+000,1.308441e-003,0.000000e+000,0,,0,
1524159757.063,,0.000000e+000,5.500893e+001,-4.825901e-006,0.000000e+000,3,9.491752e-001,0.000000e+000,,,,,,,,,,,,,,32,1,4.000000e+000,2.628326e-003,0.000000e+000,0,,0,
1524159795.093,,0.000000e+000,5.500629e+001,-4.850863e-006,0.000000e+000,3,9.311466e-001,0.000000e+000,,,,,,,,,,,,,,32,1,4.000000e+000,2.639771e-003,0.000000e+000,0,,0,
1524159832.733,,0.000000e+000,5.500169e+001,-4.825294e-006,0.000000e+000,3,9.321852e-001,0.000000e+000,,,,,,,,,,,,,,32,1,4.000000e+000,1.319885e-003,0.000000e+000,0,,0,
1524159870.524,,0.000000e+000,5.499905e+001,-4.755880e-006,0.000000e+000,3,9.395927e-001,0.000000e+000,,,,,,,,,,,,,,32,1,4.000000e+000,1.319885e-003,0.000000e+000,0,,0,
1524159907.694,,0.000000e+000,5.499905e+001,-4.771775e-006,0.000000e+000,3,9.273930e-001,0.000000e+000,,,,,,,,,,,,,,32,1,4.000000e+000,1.319885e-003,0.000000e+000,0,,0,
1524159945.474,,0.000000e+000,5.500169e+001,-4.700682e-006,0.000000e+000,3,9.323826e-001,0.000000e+000,,,,,,,,,,,,,,32,1,4.000000e+000,1.319885e-003,0.000000e+000,0,,0,
1524159982.864,,0.000000e+000,5.499839e+001,-4.699386e-006,0.000000e+000,3,9.294229e-001,0.000000e+000,,,,,,,,,,,,,,32,1,4.000000e+000,0.000000e+000,0.000000e+000,0,,0,
1524160020.434,,0.000000e+000,5.499708e+001,-4.642092e-006,0.000000e+000,3,9.376360e-001,0.000000e+000,,,,,,,,,,,,,,32,1,4.000000e+000,0.000000e+000,0.000000e+000,0,,0,
1524160058.324,,0.000000e+000,5.499445e+001,-4.685991e-006,0.000000e+000,3,9.349900e-001,0.000000e+000,,,,,,,,,,,,,,32,1,4.000000e+000,1.052094e-002,0.000000e+000,0,,0,
1524160095.884,,0.000000e+000,5.499708e+001,-4.636775e-006,0.000000e+000,3,9.334341e-001,0.000000e+000,,,,,,,,,,,,,,32,1,4.000000e+000,2.620697e-003,0.000000e+000,0,,0,
1524160133.674,,0.000000e+000,5.500037e+001,-4.552662e-006,0.000000e+000,3,9.337795e-001,0.000000e+000,,,,,,,,,,,,,,32,1,4.000000e+000,3.959656e-003,0.000000e+000,0,,0,
1524160172.274,,0.000000e+000,5.500037e+001,-4.616986e-006,0.000000e+000,3,9.309488e-001,0.000000e+000,,,,,,,,,,,,,,32,1,4.000000e+000,1.184082e-002,0.000000e+000,0,,0,
1524160209.414,,0.000000e+000,5.499445e+001,-4.510421e-006,0.000000e+000,3,9.214794e-001,0.000000e+000,,,,,,,,,,,,,,32,1,4.000000e+000,1.052094e-002,0.000000e+000,0,,0,
1524160247.874,,0.000000e+000,5.499972e+001,-4.474483e-006,0.000000e+000,3,9.313654e-001,0.000000e+000,,,,,,,,,,,,,,32,1,4.000000e+000,5.268097e-003,0.000000e+000,0,,0,
1524160285.524,,0.000000e+000,5.499774e+001,-4.539160e-006,0.000000e+000,3,9.258388e-001,0.000000e+000,,,,,,,,,,,,,,32,1,4.000000e+000,3.940582e-003,0.000000e+000,0,,0,
1524160324.134,,0.000000e+000,5.499445e+001,-4.517812e-006,0.000000e+000,3,9.220145e-001,0.000000e+000,,,,,,,,,,,,,,32,1,4.000000e+000,2.628326e-003,0.000000e+000,0,,0,
1524160362.474,,0.000000e+000,5.500629e+001,-4.428814e-006,0.000000e+000,3,9.217826e-001,0.000000e+000,,,,,,,,,,,,,,32,1,4.000000e+000,1.580048e-002,0.000000e+000,0,,0,
1524160399.864,,0.000000e+000,5.499773e+001,-4.442718e-006,0.000000e+000,3,9.279649e-001,0.000000e+000,,,,,,,,,,,,,,32,1,4.000000e+000,1.308441e-003,0.000000e+000,0,,0,
1524160437.584,,0.000000e+000,5.499577e+001,-4.442295e-006,0.000000e+000,3,9.239421e-001,0.000000e+000,,,,,,,,,,,,,,32,1,4.000000e+000,2.632141e-003,0.000000e+000,0,,0,
1524160475.644,,0.000000e+000,5.500037e+001,-4.446863e-006,0.000000e+000,3,9.224607e-001,0.000000e+000,,,,,,,,,,,,,,32,1,4.000000e+000,3.959656e-003,0.000000e+000,0,,0,
1524160512.744,,0.000000e+000,5.499577e+001,-4.334856e-006,0.000000e+000,3,9.392253e-001,0.000000e+000,,,,,,,,,,,,,,32,1,4.000000e+000,2.632141e-003,0.000000e+000,0,,0,
1524160550.614,,0.000000e+000,5.499840e+001,-4.389057e-006,0.000000e+000,3,9.178103e-001,0.000000e+000,,,,,,,,,,,,,,32,1,4.000000e+000,5.260468e-003,0.000000e+000,0,,0,
1524160588.795,,0.000000e+000,5.500169e+001,-4.341299e-006,0.000000e+000,3,9.255294e-001,0.000000e+000,,,,,,,,,,,,,,32,1,4.000000e+000,3.959656e-003,0.000000e+000,0,,0,
1524160626.585,,0.000000e+000,5.499643e+001,-4.300769e-006,0.000000e+000,3,9.282534e-001,0.000000e+000,,,,,,,,,,,,,,32,1,4.000000e+000,1.312256e-003,0.000000e+000,0,,0,
1524160663.935,,0.000000e+000,5.499839e+001,-4.364509e-006,0.000000e+000,3,9.221033e-001,0.000000e+000,,,,,,,,,,,,,,32,1,4.000000e+000,0.000000e+000,0.000000e+000,0,,0,
1524160702.065,,0.000000e+000,5.499380e+001,-4.259900e-006,0.000000e+000,3,9.193562e-001,0.000000e+000,,,,,,,,,,,,,,32,1,4.000000e+000,3.948212e-003,0.000000e+000,0,,0,
1524160739.645,,0.000000e+000,5.500498e+001,-4.350356e-006,0.000000e+000,3,9.282388e-001,0.000000e+000,,,,,,,,,,,,,,32,1,4.000000e+000,2.620697e-003,0.000000e+000,0,,0,
1524160777.005,,0.000000e+000,5.499840e+001,-4.196172e-006,0.000000e+000,3,9.350969e-001,0.000000e+000,,,,,,,,,,,,,,32,1,4.000000e+000,5.260468e-003,0.000000e+000,0,,0,
1524160814.955,,0.000000e+000,5.499643e+001,-4.213759e-006,0.000000e+000,3,9.096770e-001,0.000000e+000,,,,,,,,,,,,,,32,1,4.000000e+000,1.312256e-003,0.000000e+000,0,,0,
1524160852.255,,0.000000e+000,5.499972e+001,-4.219496e-006,0.000000e+000,3,9.178233e-001,0.000000e+000,,,,,,,,,,,,,,32,1,4.000000e+000,5.268097e-003,0.000000e+000,0,,0,
1524160890.005,,0.000000e+000,5.499577e+001,-4.157758e-006,0.000000e+000,3,9.240272e-001,0.000000e+000,,,,,,,,,,,,,,32,1,4.000000e+000,0.000000e+000,0.000000e+000,0,,0,
1524160927.755,,0.000000e+000,5.499773e+001,-4.149940e-006,0.000000e+000,3,9.134535e-001,0.000000e+000,,,,,,,,,,,,,,32,1,4.000000e+000,1.308441e-003,0.000000e+000,0,,0,
1524160965.685,,0.000000e+000,5.500235e+001,-4.125076e-006,0.000000e+000,3,9.214070e-001,0.000000e+000,,,,,,,,,,,,,,32,1,4.000000e+000,2.639771e-003,0.000000e+000,0,,0,
1524161003.275,,0.000000e+000,5.499840e+001,-4.126023e-006,0.000000e+000,3,9.275115e-001,0.000000e+000,,,,,,,,,,,,,,32,1,4.000000e+000,1.578140e-002,0.000000e+000,0,,0,
1524161042.005,,0.000000e+000,5.500366e+001,-4.041456e-006,0.000000e+000,3,9.144111e-001,0.000000e+000,,,,,,,,,,,,,,32,1,4.000000e+000,1.315689e-002,0.000000e+000,0,,0,
1524161079.785,,0.000000e+000,5.499971e+001,-4.040822e-006,0.000000e+000,3,9.213343e-001,0.000000e+000,,,,,,,,,,,,,,32,1,4.000000e+000,2.639771e-003,0.000000e+000,0,,0,
1524161117.955,,0.000000e+000,5.500103e+001,-4.121775e-006,0.000000e+000,3,9.152969e-001,0.000000e+000,,,,,,,,,,,,,,32,1,4.000000e+000,2.639771e-003,0.000000e+000,0,,0,
1524161155.315,,0.000000e+000,5.500234e+001,-4.052843e-006,0.000000e+000,3,9.147689e-001,0.000000e+000,,,,,,,,,,,,,,32,1,4.000000e+000,7.900238e-003,0.000000e+000,0,,0,
1524161193.575,,0.000000e+000,5.500103e+001,-3.960472e-006,0.000000e+000,3,9.118786e-001,0.000000e+000,,,,,,,,,,,,,,32,1,4.000000e+000,0.000000e+000,0.000000e+000,0,,0,
1524161231.005,,0.000000e+000,5.500037e+001,-4.058306e-006,0.000000e+000,3,9.021235e-001,0.000000e+000,,,,,,,,,,,,,,32,1,4.000000e+000,1.319885e-003,0.000000e+000,0,,0,
1524161268.435,,0.000000e+000,5.500169e+001,-3.964652e-006,0.000000e+000,3,9.203312e-001,0.000000e+000,,,,,,,,,,,,,,32,1,4.000000e+000,1.319885e-003,0.000000e+000,0,,0,
1524161306.226,,0.000000e+000,5.500103e+001,-3.948454e-006,0.000000e+000,3,9.101548e-001,0.000000e+000,,,,,,,,,,,,,,32,1,4.000000e+000,5.279541e-003,0.000000e+000,0,,0,
1524161344.536,,0.000000e+000,5.499380e+001,-3.826912e-006,0.000000e+000,3,9.118752e-001,0.000000e+000,,,,,,,,,,,,,,32,1,4.000000e+000,1.308441e-003,0.000000e+000,0,,0,
1524161382.906,,0.000000e+000,5.500301e+001,-3.864477e-006,0.000000e+000,3,9.198887e-001,0.000000e+000,,,,,,,,,,,,,,32,1,4.000000e+000,1.319885e-003,0.000000e+000,0,,0,
1524161421.186,,0.000000e+000,5.499643e+001,-3.944891e-006,0.000000e+000,3,9.112851e-001,0.000000e+000,,,,,,,,,,,,,,32,1,4.000000e+000,1.312256e-003,0.000000e+000,0,,0,
1524161458.596,,0.000000e+000,5.499708e+001,-3.828064e-006,0.000000e+000,3,9.231511e-001,0.000000e+000,,,,,,,,,,,,,,32,1,4.000000e+000,5.260468e-003,0.000000e+000,0,,0,
1524161495.766,,0.000000e+000,5.499643e+001,-3.908805e-006,0.000000e+000,3,9.089712e-001,0.000000e+000,,,,,,,,,,,,,,32,1,4.000000e+000,1.448059e-002,0.000000e+000,0,,0,
1524161533.876,,0.000000e+000,5.500301e+001,-3.854177e-006,0.000000e+000,3,9.068926e-001,0.000000e+000,,,,,,,,,,,,,,32,1,4.000000e+000,1.319885e-003,0.000000e+000,0,,0,
1524161572.186,,0.000000e+000,5.499708e+001,-3.852506e-006,0.000000e+000,3,9.122013e-001,0.000000e+000,,,,,,,,,,,,,,32,1,4.000000e+000,2.620697e-003,0.000000e+000,0,,0,
1524161609.736,,0.000000e+000,5.499642e+001,-3.818238e-006,0.000000e+000,3,9.169571e-001,0.000000e+000,,,,,,,,,,,,,,32,1,4.000000e+000,3.940582e-003,0.000000e+000,0,,0,
1524161647.526,,0.000000e+000,5.499182e+001,-3.815361e-006,0.000000e+000,3,9.057553e-001,0.000000e+000,,,,,,,,,,,,,,32,1,4.000000e+000,5.260468e-003,0.000000e+000,0,,0,
1524161710.096,,0.000000e+000,5.499380e+001,-3.802301e-006,0.000000e+000,3,9.155529e-001,0.000000e+000,,,,,,,,,,,,,,32,1,4.000000e+000,1.710129e-002,0.000000e+000,0,,0,
1524161748.636,,0.000000e+000,5.499643e+001,-3.777991e-006,0.000000e+000,3,9.136801e-001,0.000000e+000,,,,,,,,,,,,,,32,1,4.000000e+000,1.312256e-003,0.000000e+000,0,,0,
1524161785.746,,0.000000e+000,5.499314e+001,-3.774270e-006,0.000000e+000,3,9.089761e-001,0.000000e+000,,,,,,,,,,,,,,32,1,4.000000e+000,1.578140e-002,0.000000e+000,0,,0,
1524161823.826,,0.000000e+000,5.499708e+001,-3.686079e-006,0.000000e+000,3,9.051362e-001,0.000000e+000,,,,,,,,,,,,,,32,1,4.000000e+000,2.620697e-003,0.000000e+000,0,,0,
1524161861.496,,0.000000e+000,5.500037e+001,-3.761104e-006,0.000000e+000,3,8.986541e-001,0.000000e+000,,,,,,,,,,,,,,32,1,4.000000e+000,3.959656e-003,0.000000e+000,0,,0,
1524161899.396,,0.000000e+000,5.499971e+001,-3.713614e-006,0.000000e+000,3,9.043726e-001,0.000000e+000,,,,,,,,,,,,,,32,1,4.000000e+000,2.639771e-003,0.000000e+000,0,,0,
1524161936.586,,0.000000e+000,5.499709e+001,-3.673588e-006,0.000000e+000,3,9.056731e-001,0.000000e+000,,,,,,,,,,,,,,32,1,4.000000e+000,7.888794e-003,0.000000e+000,0,,0,
1524161974.606,,0.000000e+000,5.499117e+001,-3.649692e-006,0.000000e+000,3,9.046235e-001,0.000000e+000,,,,,,,,,,,,,,32,1,4.000000e+000,3.952026e-003,0.000000e+000,0,,0,
1524162012.287,,0.000000e+000,5.499971e+001,-3.665008e-006,0.000000e+000,3,9.020844e-001,0.000000e+000,,,,,,,,,,,,,,32,1,4.000000e+000,2.639771e-003,0.000000e+000,0,,0,
1524162050.297,,0.000000e+000,5.499972e+001,-3.649633e-006,0.000000e+000,3,9.100146e-001,0.000000e+000,,,,,,,,,,,,,,32,1,4.000000e+000,1.314926e-002,0.000000e+000,0,,0,
1524162087.887,,0.000000e+000,5.499577e+001,-3.658318e-006,0.000000e+000,3,9.096651e-001,0.000000e+000,,,,,,,,,,,,,,32,1,4.000000e+000,0.000000e+000,0.000000e+000,0,,0,
1524162125.947,,0.000000e+000,5.499117e+001,-3.594265e-006,0.000000e+000,3,9.081569e-001,0.000000e+000,,,,,,,,,,,,,,32,1,4.000000e+000,3.952026e-003,0.000000e+000,0,,0,
1524162163.597,,0.000000e+000,5.499511e+001,-3.632113e-006,0.000000e+000,3,8.987773e-001,0.000000e+000,,,,,,,,,,,,,,32,1,4.000000e+000,1.184082e-002,0.000000e+000,0,,0,
1524162201.607,,0.000000e+000,5.499775e+001,-3.561181e-006,0.000000e+000,3,9.105877e-001,0.000000e+000,,,,,,,,,,,,,,32,1,4.000000e+000,9.208679e-003,0.000000e+000,0,,0,
1524162239.297,,0.000000e+000,5.499905e+001,-3.559941e-006,0.000000e+000,3,9.081810e-001,0.000000e+000,,,,,,,,,,,,,,32,1,4.000000e+000,3.948212e-003,0.000000e+000,0,,0,
1524162277.067,,0.000000e+000,5.500169e+001,-3.546910e-006,0.000000e+000,3,9.035171e-001,0.000000e+000,,,,,,,,,,,,,,32,1,4.000000e+000,1.184082e-002,0.000000e+000,0,,0,
1524162314.697,,0.000000e+000,5.500103e+001,-3.534622e-006,0.000000e+000,3,8.973464e-001,0.000000e+000,,,,,,,,,,,,,,32,1,4.000000e+000,0.000000e+000,0.000000e+000,0,,0,
1524162351.847,,0.000000e+000,5.499972e+001,-3.497151e-006,0.000000e+000,3,8.990384e-001,0.000000e+000,,,,,,,,,,,,,,32,1,4.000000e+000,1.314926e-002,0.000000e+000,0,,0,
1524162389.487,,0.000000e+000,5.499905e+001,-3.579163e-006,0.000000e+000,3,8.916139e-001,0.000000e+000,,,,,,,,,,,,,,32,1,4.000000e+000,1.319885e-003,0.000000e+000,0,,0,
1524162427.377,,0.000000e+000,5.500300e+001,-3.484107e-006,0.000000e+000,3,8.971513e-001,0.000000e+000,,,,,,,,,,,,,,32,1,4.000000e+000,3.940582e-003,0.000000e+000,0,,0,
1524162464.797,,0.000000e+000,5.500234e+001,-3.465137e-006,0.000000e+000,3,9.084597e-001,0.000000e+000,,,,,,,,,,,,,,32,1,4.000000e+000,7.900238e-003,0.000000e+000,0,,0,
1524162502.527,,0.000000e+000,5.499511e+001,-3.502358e-006,0.000000e+000,3,8.975742e-001,0.000000e+000,,,,,,,,,,,,,,32,1,4.000000e+000,6.568909e-003,0.000000e+000,0,,0,
1524162540.497,,0.000000e+000,5.499840e+001,-3.349884e-006,0.000000e+000,3,8.979589e-001,0.000000e+000,,,,,,,,,,,,,,32,1,4.000000e+000,5.260468e-003,0.000000e+000,0,,0,
1524162578.167,,0.000000e+000,5.499905e+001,-3.499944e-006,0.000000e+000,3,8.946665e-001,0.000000e+000,,,,,,,,,,,,,,32,1,4.000000e+000,1.319885e-003,0.000000e+000,0,,0,
1524162615.837,,0.000000e+000,5.499511e+001,-3.417018e-006,0.000000e+000,3,9.059312e-001,0.000000e+000,,,,,,,,,,,,,,32,1,4.000000e+000,6.568909e-003,0.000000e+000,0,,0,
1524162653.877,,0.000000e+000,5.500234e+001,-3.466540e-006,0.000000e+000,3,9.046012e-001,0.000000e+000,,,,,,,,,,,,,,32,1,4.000000e+000,7.900238e-003,0.000000e+000,0,,0,
1524162691.587,,0.000000e+000,5.499972e+001,-3.436159e-006,0.000000e+000,3,8.972723e-001,0.000000e+000,,,,,,,,,,,,,,32,1,4.000000e+000,5.268097e-003,0.000000e+000,0,,0,
1524162729.468,,0.000000e+000,5.499708e+001,-3.433108e-006,0.000000e+000,3,8.948432e-001,0.000000e+000,,,,,,,,,,,,,,32,1,4.000000e+000,2.620697e-003,0.000000e+000,0,,0,
1524162767.238,,0.000000e+000,5.500497e+001,-3.384564e-006,0.000000e+000,3,8.882574e-001,0.000000e+000,,,,,,,,,,,,,,32,1,4.000000e+000,1.578903e-002,0.000000e+000,0,,0,
1524162805.158,,0.000000e+000,5.499905e+001,-3.353443e-006,0.000000e+000,3,8.877248e-001,0.000000e+000,,,,,,,,,,,,,,32,1,4.000000e+000,3.948212e-003,0.000000e+000,0,,0,
1524162842.908,,0.000000e+000,5.499643e+001,-3.372201e-006,0.000000e+000,3,8.864672e-001,0.000000e+000,,,,,,,,,,,,,,32,1,4.000000e+000,6.568909e-003,0.000000e+000,0,,0,
1524162880.828,,0.000000e+000,5.500103e+001,-3.325100e-006,0.000000e+000,3,8.905780e-001,0.000000e+000,,,,,,,,,,,,,,32,1,4.000000e+000,5.279541e-003,0.000000e+000,0,,0,
1524162918.598,,0.000000e+000,5.499905e+001,-3.408489e-006,0.000000e+000,3,8.960487e-001,0.000000e+000,,,,,,,,,,,,,,32,1,4.000000e+000,1.972961e-002,0.000000e+000,0,,0,
1524162956.508,,0.000000e+000,5.499905e+001,-3.330183e-006,0.000000e+000,3,8.934156e-001,0.000000e+000,,,,,,,,,,,,,,32,1,4.000000e+000,1.319885e-003,0.000000e+000,0,,0,
1524162994.278,,0.000000e+000,5.500169e+001,-3.285382e-006,0.000000e+000,3,8.860321e-001,0.000000e+000,,,,,,,,,,,,,,32,1,4.000000e+000,9.208679e-003,0.000000e+000,0,,0,
1524163032.178,,0.000000e+000,5.499774e+001,-3.267240e-006,0.000000e+000,3,8.929744e-001,0.000000e+000,,,,,,,,,,,,,,32,1,4.000000e+000,3.940582e-003,0.000000e+000,0,,0,
1524163069.938,,0.000000e+000,5.499708e+001,-3.314857e-006,0.000000e+000,3,8.976704e-001,0.000000e+000,,,,,,,,,,,,,,32,1,4.000000e+000,0.000000e+000,0.000000e+000,0,,0,
1524163107.848,,0.000000e+000,5.499840e+001,-3.240711e-006,0.000000e+000,3,8.885590e-001,0.000000e+000,,,,,,,,,,,,,,32,1,4.000000e+000,2.628326e-003,0.000000e+000,0,,0,
1524163145.618,,0.000000e+000,5.499774e+001,-3.310405e-006,0.000000e+000,3,8.890497e-001,0.000000e+000,,,,,,,,,,,,,,32,1,4.000000e+000,3.940582e-003,0.000000e+000,0,,0,
1524163183.528,,0.000000e+000,5.499643e+001,-3.262402e-006,0.000000e+000,3,8.849713e-001,0.000000e+000,,,,,,,,,,,,,,32,1,4.000000e+000,1.312256e-003,0.000000e+000,0,,0,
1524163221.298,,0.000000e+000,5.499643e+001,-3.262278e-006,0.000000e+000,3,8.854593e-001,0.000000e+000,,,,,,,,,,,,,,32,1,4.000000e+000,1.312256e-003,0.000000e+000,0,,0,
1524163259.208,,0.000000e+000,5.499906e+001,-3.243198e-006,0.000000e+000,3,8.806775e-001,0.000000e+000,,,,,,,,,,,,,,32,1,4.000000e+000,6.580353e-003,0.000000e+000,0,,0,
1524163296.968,,0.000000e+000,5.499774e+001,-3.244957e-006,0.000000e+000,3,8.823009e-001,0.000000e+000,,,,,,,,,,,,,,32,1,4.000000e+000,3.940582e-003,0.000000e+000,0,,0,
1524163334.888,,0.000000e+000,5.499511e+001,-3.210933e-006,0.000000e+000,3,8.827701e-001,0.000000e+000,,,,,,,,,,,,,,32,1,4.000000e+000,1.319885e-003,0.000000e+000,0,,0,
1524163372.648,,0.000000e+000,5.499840e+001,-3.226967e-006,0.000000e+000,3,8.841161e-001,0.000000e+000,,,,,,,,,,,,,,32,1,4.000000e+000,7.900238e-003,0.000000e+000,0,,0,
1524163410.558,,0.000000e+000,5.499313e+001,-3.203074e-006,0.000000e+000,3,8.846032e-001,0.000000e+000,,,,,,,,,,,,,,32,1,4.000000e+000,2.628326e-003,0.000000e+000,0,,0,
1524163447.929,,0.000000e+000,5.500103e+001,-3.214494e-006,0.000000e+000,3,8.852931e-001,0.000000e+000,,,,,,,,,,,,,,32,1,4.000000e+000,5.279541e-003,0.000000e+000,0,,0,
1524163486.019,,0.000000e+000,5.500037e+001,-3.212112e-006,0.000000e+000,3,8.934817e-001,0.000000e+000,,,,,,,,,,,,,,32,1,4.000000e+000,3.959656e-003,0.000000e+000,0,,0,
1524163524.279,,0.000000e+000,5.499905e+001,-3.182471e-006,0.000000e+000,3,8.863350e-001,0.000000e+000,,,,,,,,,,,,,,32,1,4.000000e+000,1.319885e-003,0.000000e+000,0,,0,
1524163562.139,,0.000000e+000,5.500563e+001,-3.103434e-006,0.000000e+000,3,8.880022e-001,0.000000e+000,,,,,,,,,,,,,,32,1,4.000000e+000,1.319885e-003,0.000000e+000,0,,0,
1524163599.869,,0.000000e+000,5.499905e+001,-3.123137e-006,0.000000e+000,3,8.737894e-001,0.000000e+000,,,,,,,,,,,,,,32,1,4.000000e+000,1.319885e-003,0.000000e+000,0,,0,
1524163637.799,,0.000000e+000,5.499708e+001,-3.123819e-006,0.000000e+000,3,8.792691e-001,0.000000e+000,,,,,,,,,,,,,,32,1,4.000000e+000,2.620697e-003,0.000000e+000,0,,0,
1524163675.619,,0.000000e+000,5.499643e+001,-3.212146e-006,0.000000e+000,3,8.775426e-001,0.000000e+000,,,,,,,,,,,,,,32,1,4.000000e+000,1.448059e-002,0.000000e+000,0,,0,
1524163713.499,,0.000000e+000,5.499971e+001,-3.104926e-006,0.000000e+000,3,8.862633e-001,0.000000e+000,,,,,,,,,,,,,,32,1,4.000000e+000,2.639771e-003,0.000000e+000,0,,0,
1524163751.159,,0.000000e+000,5.500168e+001,-3.140927e-006,0.000000e+000,3,8.800167e-001,0.000000e+000,,,,,,,,,,,,,,32,1,4.000000e+000,6.580353e-003,0.000000e+000,0,,0,
1524163789.189,,0.000000e+000,5.499577e+001,-3.103646e-006,0.000000e+000,3,8.757665e-001,0.000000e+000,,,,,,,,,,,,,,32,1,4.000000e+000,7.888794e-003,0.000000e+000,0,,0,
1524163826.819,,0.000000e+000,5.500169e+001,-3.081068e-006,0.000000e+000,3,8.786850e-001,0.000000e+000,,,,,,,,,,,,,,32,1,4.000000e+000,1.319885e-003,0.000000e+000,0,,0,
1524163864.849,,0.000000e+000,5.499380e+001,-3.065738e-006,0.000000e+000,3,8.766918e-001,0.000000e+000,,,,,,,,,,,,,,32,1,4.000000e+000,3.948212e-003,0.000000e+000,0,,0,
1524163902.449,,0.000000e+000,5.499971e+001,-3.068081e-006,0.000000e+000,3,8.815225e-001,0.000000e+000,,,,,,,,,,,,,,32,1,4.000000e+000,2.639771e-003,0.000000e+000,0,,0,
1524163940.519,,0.000000e+000,5.500037e+001,-3.143890e-006,0.000000e+000,3,8.779638e-001,0.000000e+000,,,,,,,,,,,,,,32,1,4.000000e+000,3.959656e-003,0.000000e+000,0,,0,
1524163978.119,,0.000000e+000,5.499577e+001,-3.054932e-006,0.000000e+000,3,8.677304e-001,0.000000e+000,,,,,,,,,,,,,,32,1,4.000000e+000,5.249023e-003,0.000000e+000,0,,0,
1524164016.189,,0.000000e+000,5.500431e+001,-2.974875e-006,0.000000e+000,3,8.835428e-001,0.000000e+000,,,,,,,,,,,,,,32,1,4.000000e+000,1.184845e-002,0.000000e+000,0,,0,
1524164053.819,,0.000000e+000,5.499906e+001,-3.122012e-006,0.000000e+000,3,8.704236e-001,0.000000e+000,,,,,,,,,,,,,,32,1,4.000000e+000,6.580353e-003,0.000000e+000,0,,0,
1524164091.639,,0.000000e+000,5.500432e+001,-3.039736e-006,0.000000e+000,3,8.816751e-001,0.000000e+000,,,,,,,,,,,,,,32,1,4.000000e+000,1.446915e-002,0.000000e+000,0,,0,
1524164130.290,,0.000000e+000,5.499709e+001,-2.960054e-006,0.000000e+000,3,8.642760e-001,0.000000e+000,,,,,,,,,,,,,,32,1,4.000000e+000,7.888794e-003,0.000000e+000,0,,0,
1524164168.270,,0.000000e+000,5.500169e+001,-3.111415e-006,0.000000e+000,3,8.551298e-001,0.000000e+000,,,,,,,,,,,,,,32,1,4.000000e+000,1.446915e-002,0.000000e+000,0,,0,
1524164206.320,,0.000000e+000,5.499841e+001,-2.998039e-006,0.000000e+000,3,8.850086e-001,0.000000e+000,,,,,,,,,,,,,,32,1,4.000000e+000,1.052856e-002,0.000000e+000,0,,0,
1524164244.380,,0.000000e+000,5.500234e+001,-2.973620e-006,0.000000e+000,3,8.670949e-001,0.000000e+000,,,,,,,,,,,,,,32,1,4.000000e+000,7.900238e-003,0.000000e+000,0,,0,
1524164281.460,,0.000000e+000,5.499905e+001,-3.043833e-006,0.000000e+000,3,8.803568e-001,0.000000e+000,,,,,,,,,,,,,,32,1,4.000000e+000,1.319885e-003,0.000000e+000,0,,0,
1524164319.940,,0.000000e+000,5.500037e+001,-2.921444e-006,0.000000e+000,3,8.684298e-001,0.000000e+000,,,,,,,,,,,,,,32,1,4.000000e+000,9.201050e-003,0.000000e+000,0,,0,
1524164357.920,,0.000000e+000,5.500301e+001,-2.886394e-006,0.000000e+000,3,8.525032e-001,0.000000e+000,,,,,,,,,,,,,,32,1,4.000000e+000,1.319885e-003,0.000000e+000,0,,0,
1524164396.010,,0.000000e+000,5.499773e+001,-2.912155e-006,0.000000e+000,3,8.755373e-001,0.000000e+000,,,,,,,,,,,,,,32,1,4.000000e+000,1.308441e-003,0.000000e+000,0,,0,
1524164434.050,,0.000000e+000,5.499642e+001,-2.923563e-006,0.000000e+000,3,8.737451e-001,0.000000e+000,,,,,,,,,,,,,,32,1,4.000000e+000,3.940582e-003,0.000000e+000,0,,0,
1524164471.420,,0.000000e+000,5.499643e+001,-2.984426e-006,0.000000e+000,3,8.552511e-001,0.000000e+000,,,,,,,,,,,,,,32,1,4.000000e+000,1.708984e-002,0.000000e+000,0,,0,
1524164509.190,,0.000000e+000,5.499774e+001,-2.897941e-006,0.000000e+000,3,8.717808e-001,0.000000e+000,,,,,,,,,,,,,,32,1,4.000000e+000,1.446152e-002,0.000000e+000,0,,0,
1524164547.110,,0.000000e+000,5.499643e+001,-2.916788e-006,0.000000e+000,3,8.572276e-001,0.000000e+000,,,,,,,,,,,,,,32,1,4.000000e+000,6.568909e-003,0.000000e+000,0,,0,
1524164584.880,,0.000000e+000,5.499379e+001,-2.944881e-006,0.000000e+000,3,8.643193e-001,0.000000e+000,,,,,,,,,,,,,,32,1,4.000000e+000,9.201050e-003,0.000000e+000,0,,0,
1524164622.490,,0.000000e+000,5.499906e+001,-2.899265e-006,0.000000e+000,3,8.744600e-001,0.000000e+000,,,,,,,,,,,,,,32,1,4.000000e+000,9.220123e-003,0.000000e+000,0,,0,
1524164660.410,,0.000000e+000,5.499445e+001,-2.903757e-006,0.000000e+000,3,8.616939e-001,0.000000e+000,,,,,,,,,,,,,,32,1,4.000000e+000,7.881165e-003,0.000000e+000,0,,0,
1524164698.290,,0.000000e+000,5.499643e+001,-2.856918e-006,0.000000e+000,3,8.736125e-001,0.000000e+000,,,,,,,,,,,,,,32,1,4.000000e+000,6.568909e-003,0.000000e+000,0,,0,
1524164735.740,,0.000000e+000,5.499708e+001,-3.052876e-006,0.000000e+000,3,8.621913e-001,0.000000e+000,,,,,,,,,,,,,,32,1,4.000000e+000,0.000000e+000,0.000000e+000,0,,0,
1524164773.300,,0.000000e+000,5.500235e+001,-2.798510e-006,0.000000e+000,3,8.580872e-001,0.000000e+000,,,,,,,,,,,,,,32,1,4.000000e+000,0.000000e+000,0.000000e+000,0,,0,
1524164810.660,,0.000000e+000,5.500300e+001,-2.896229e-006,0.000000e+000,3,8.702489e-001,0.000000e+000,,,,,,,,,,,,,,32,1,4.000000e+000,6.580353e-003,0.000000e+000,0,,0,
1524164848.641,,0.000000e+000,5.500037e+001,-2.873027e-006,0.000000e+000,3,8.598705e-001,0.000000e+000,,,,,,,,,,,,,,32,1,4.000000e+000,3.959656e-003,0.000000e+000,0,,0,
1524164886.591,,0.000000e+000,5.500103e+001,-2.914242e-006,0.000000e+000,3,8.575453e-001,0.000000e+000,,,,,,,,,,,,,,32,1,4.000000e+000,0.000000e+000,0.000000e+000,0,,0,
1524164924.331,,0.000000e+000,5.500563e+001,-2.862547e-006,0.000000e+000,3,8.680270e-001,0.000000e+000,,,,,,,,,,,,,,32,1,4.000000e+000,6.568909e-003,0.000000e+000,0,,0,
1524164987.071,,0.000000e+000,5.500300e+001,-2.777477e-006,0.000000e+000,3,8.612857e-001,0.000000e+000,,,,,,,,,,,,,,32,1,4.000000e+000,1.183701e-002,0.000000e+000,0,,0,
1524165025.201,,0.000000e+000,5.500169e+001,-2.777983e-006,0.000000e+000,3,8.648717e-001,0.000000e+000,,,,,,,,,,,,,,32,1,4.000000e+000,1.319885e-003,0.000000e+000,0,,0,
1524165062.931,,0.000000e+000,5.499577e+001,-2.963176e-006,0.000000e+000,3,8.616022e-001,0.000000e+000,,,,,,,,,,,,,,32,1,4.000000e+000,5.249023e-003,0.000000e+000,0,,0,
1524165100.511,,0.000000e+000,5.499839e+001,-2.819856e-006,0.000000e+000,3,8.592272e-001,0.000000e+000,,,,,,,,,,,,,,32,1,4.000000e+000,0.000000e+000,0.000000e+000,0,,0,
1524165138.491,,0.000000e+000,5.499643e+001,-2.852279e-006,0.000000e+000,3,8.646610e-001,0.000000e+000,,,,,,,,,,,,,,32,1,4.000000e+000,9.208679e-003,0.000000e+000,0,,0,
1524165176.261,,0.000000e+000,5.500103e+001,-2.818808e-006,0.000000e+000,3,8.608945e-001,0.000000e+000,,,,,,,,,,,,,,32,1,4.000000e+000,5.279541e-003,0.000000e+000,0,,0,
1524165214.581,,0.000000e+000,5.500366e+001,-2.687333e-006,0.000000e+000,3,8.599205e-001,0.000000e+000,,,,,,,,,,,,,,32,1,4.000000e+000,5.260468e-003,0.000000e+000,0,,0,
1524165252.181,,0.000000e+000,5.499840e+001,-2.809043e-006,0.000000e+000,3,8.447477e-001,0.000000e+000,,,,,,,,,,,,,,32,1,4.000000e+000,2.628326e-003,0.000000e+000,0,,0,
1524165290.241,,0.000000e+000,5.499577e+001,-2.754346e-006,0.000000e+000,3,8.511646e-001,0.000000e+000,,,,,,,,,,,,,,32,1,4.000000e+000,0.000000e+000,0.000000e+000,0,,0,
1524165328.601,,0.000000e+000,5.500103e+001,-2.839663e-006,0.000000e+000,3,8.601962e-001,0.000000e+000,,,,,,,,,,,,,,32,1,4.000000e+000,5.279541e-003,0.000000e+000,0,,0,
1524165366.201,,0.000000e+000,5.500103e+001,-2.703125e-006,0.000000e+000,3,8.579283e-001,0.000000e+000,,,,,,,,,,,,,,32,1,4.000000e+000,5.279541e-003,0.000000e+000,0,,0,
1524165403.901,,0.000000e+000,5.499775e+001,-2.647214e-006,0.000000e+000,3,8.459488e-001,0.000000e+000,,,,,,,,,,,,,,32,1,4.000000e+000,9.208679e-003,0.000000e+000,0,,0,
1524165441.661,,0.000000e+000,5.499708e+001,-2.660439e-006,0.000000e+000,3,8.531714e-001,0.000000e+000,,,,,,,,,,,,,,32,1,4.000000e+000,0.000000e+000,0.000000e+000,0,,0,
1524165479.791,,0.000000e+000,5.499775e+001,-2.663014e-006,0.000000e+000,3,8.492776e-001,0.000000e+000,,,,,,,,,,,,,,32,1,4.000000e+000,9.208679e-003,0.000000e+000,0,,0,
1524165517.221,,0.000000e+000,5.499708e+001,-2.788633e-006,0.000000e+000,3,8.505199e-001,0.000000e+000,,,,,,,,,,,,,,32,1,4.000000e+000,0.000000e+000,0.000000e+000,0,,0,
1524165555.591,,0.000000e+000,5.500695e+001,-2.750882e-006,0.000000e+000,3,8.517994e-001,0.000000e+000,,,,,,,,,,,,,,32,1,4.000000e+000,9.201050e-003,0.000000e+000,0,,0,
1524165593.502,,0.000000e+000,5.499577e+001,-2.647975e-006,0.000000e+000,3,8.583617e-001,0.000000e+000,,,,,,,,,,,,,,32,1,4.000000e+000,2.632141e-003,0.000000e+000,0,,0,
1524165632.122,,0.000000e+000,5.499905e+001,-2.611652e-006,0.000000e+000,3,8.438768e-001,0.000000e+000,,,,,,,,,,,,,,32,1,4.000000e+000,1.319885e-003,0.000000e+000,0,,0,
1524165669.942,,0.000000e+000,5.499905e+001,-2.675410e-006,0.000000e+000,3,8.398930e-001,0.000000e+000,,,,,,,,,,,,,,32,1,4.000000e+000,1.319885e-003,0.000000e+000,0,,0,
1524165707.402,,0.000000e+000,5.500037e+001,-2.568573e-006,0.000000e+000,3,8.549368e-001,0.000000e+000,,,,,,,,,,,,,,32,1,4.000000e+000,3.959656e-003,0.000000e+000,0,,0,
1524165745.082,,0.000000e+000,5.499840e+001,-2.693221e-006,0.000000e+000,3,8.468128e-001,0.000000e+000,,,,,,,,,,,,,,32,1,4.000000e+000,5.260468e-003,0.000000e+000,0,,0,
1524165783.132,,0.000000e+000,5.499971e+001,-2.600818e-006,0.000000e+000,3,8.378061e-001,0.000000e+000,,,,,,,,,,,,,,32,1,4.000000e+000,1.052094e-002,0.000000e+000,0,,0,
1524165820.762,,0.000000e+000,5.499971e+001,-2.633841e-006,0.000000e+000,3,8.367634e-001,0.000000e+000,,,,,,,,,,,,,,32,1,4.000000e+000,0.000000e+000,0.000000e+000,0,,0,
1524165858.762,,0.000000e+000,5.499708e+001,-2.623058e-006,0.000000e+000,3,8.273508e-001,0.000000e+000,,,,,,,,,,,,,,32,1,4.000000e+000,5.260468e-003,0.000000e+000,0,,0,
1524165896.652,,0.000000e+000,5.499708e+001,-2.552375e-006,0.000000e+000,3,8.308609e-001,0.000000e+000,,,,,,,,,,,,,,32,1,4.000000e+000,0.000000e+000,0.000000e+000,0,,0,
1524165934.852,,0.000000e+000,5.500103e+001,-2.663714e-006,0.000000e+000,3,8.387549e-001,0.000000e+000,,,,,,,,,,,,,,32,1,4.000000e+000,0.000000e+000,0.000000e+000,0,,0,
1524165997.552,,0.000000e+000,5.500234e+001,-2.599738e-006,0.000000e+000,3,8.339251e-001,0.000000e+000,,,,,,,,,,,,,,32,1,4.000000e+000,5.260468e-003,0.000000e+000,0,,0,
1524166034.772,,0.000000e+000,5.499774e+001,-2.643421e-006,0.000000e+000,3,8.421861e-001,0.000000e+000,,,,,,,,,,,,,,32,1,4.000000e+000,3.940582e-003,0.000000e+000,0,,0,
1524166072.412,,0.000000e+000,5.499972e+001,-2.525378e-006,0.000000e+000,3,8.324593e-001,0.000000e+000,,,,,,,,,,,,,,32,1,4.000000e+000,5.268097e-003,0.000000e+000,0,,0,
1524166109.742,,0.000000e+000,5.499577e+001,-2.625903e-006,0.000000e+000,3,8.445378e-001,0.000000e+000,,,,,,,,,,,,,,32,1,4.000000e+000,5.249023e-003,0.000000e+000,0,,0,
1524166147.942,,0.000000e+000,5.499905e+001,-2.587615e-006,0.000000e+000,3,8.402249e-001,0.000000e+000,,,,,,,,,,,,,,32,1,4.000000e+000,1.319885e-003,0.000000e+000,0,,0,
1524166185.952,,0.000000e+000,5.499380e+001,-2.536492e-006,0.000000e+000,3,8.302822e-001,0.000000e+000,,,,,,,,,,,,,,32,1,4.000000e+000,1.710129e-002,0.000000e+000,0,,0,
1524166223.622,,0.000000e+000,5.500169e+001,-2.599791e-006,0.000000e+000,3,8.319231e-001,0.000000e+000,,,,,,,,,,,,,,32,1,4.000000e+000,9.208679e-003,0.000000e+000,0,,0,
1524166287.103,,0.000000e+000,5.499840e+001,-2.497244e-006,0.000000e+000,3,8.319119e-001,0.000000e+000,,,,,,,,,,,,,,32,1,4.000000e+000,7.900238e-003,0.000000e+000,0,,0,
1524166325.253,,0.000000e+000,5.500169e+001,-2.543421e-006,0.000000e+000,3,8.317791e-001,0.000000e+000,,,,,,,,,,,,,,32,1,4.000000e+000,1.319885e-003,0.000000e+000,0,,0,
1524166362.583,,0.000000e+000,5.499577e+001,-2.547843e-006,0.000000e+000,3,8.208777e-001,0.000000e+000,,,,,,,,,,,,,,32,1,4.000000e+000,2.632141e-003,0.000000e+000,0,,0,
1524166400.633,,0.000000e+000,5.499380e+001,-2.490674e-006,0.000000e+000,3,8.188390e-001,0.000000e+000,,,,,,,,,,,,,,32,1,4.000000e+000,6.572723e-003,0.000000e+000,0,,0,
1524166438.523,,0.000000e+000,5.500103e+001,-2.556499e-006,0.000000e+000,3,7.993495e-001,0.000000e+000,,,,,,,,,,,,,,32,1,4.000000e+000,0.000000e+000,0.000000e+000,0,,0,
1524166476.643,,0.000000e+000,5.499248e+001,-2.572719e-006,0.000000e+000,3,8.396836e-001,0.000000e+000,,,,,,,,,,,,,,32,1,4.000000e+000,9.201050e-003,0.000000e+000,0,,0,
1524166514.683,,0.000000e+000,5.499445e+001,-2.506637e-006,0.000000e+000,3,8.296596e-001,0.000000e+000,,,,,,,,,,,,,,32,1,4.000000e+000,5.260468e-003,0.000000e+000,0,,0,
1524166552.253,,0.000000e+000,5.499775e+001,-2.602345e-006,0.000000e+000,3,8.142606e-001,0.000000e+000,,,,,,,,,,,,,,32,1,4.000000e+000,9.208679e-003,0.000000e+000,0,,0,
1524166590.203,,0.000000e+000,5.500103e+001,-2.533329e-006,0.000000e+000,3,8.442824e-001,0.000000e+000,,,,,,,,,,,,,,32,1,4.000000e+000,0.000000e+000,0.000000e+000,0,,0,
1524166627.773,,0.000000e+000,5.499248e+001,-2.496461e-006,0.000000e+000,3,8.250802e-001,0.000000e+000,,,,,,,,,,,,,,32,1,4.000000e+000,6.580353e-003,0.000000e+000,0,,0,
1524166665.353,,0.000000e+000,5.499708e+001,-2.567473e-006,0.000000e+000,3,8.492820e-001,0.000000e+000,,,,,,,,,,,,,,32,1,4.000000e+000,0.000000e+000,0.000000e+000,0,,0,
1524166703.313,,0.000000e+000,5.499708e+001,-2.444365e-006,0.000000e+000,3,8.228781e-001,0.000000e+000,,,,,,,,,,,,,,32,1,4.000000e+000,2.620697e-003,0.000000e+000,0,,0,
1524166740.513,,0.000000e+000,5.499971e+001,-2.575678e-006,0.000000e+000,3,8.307840e-001,0.000000e+000,,,,,,,,,,,,,,32,1,4.000000e+000,0.000000e+000,0.000000e+000,0,,0,
1524166777.893,,0.000000e+000,5.499577e+001,-2.424632e-006,0.000000e+000,3,8.275447e-001,0.000000e+000,,,,,,,,,,,,,,32,1,4.000000e+000,0.000000e+000,0.000000e+000,0,,0,
1524166814.863,,0.000000e+000,5.500037e+001,-2.589585e-006,0.000000e+000,3,8.173482e-001,0.000000e+000,,,,,,,,,,,,,,32,1,4.000000e+000,1.319885e-003,0.000000e+000,0,,0,
1524166852.223,,0.000000e+000,5.500169e+001,-2.461340e-006,0.000000e+000,3,8.217923e-001,0.000000e+000,,,,,,,,,,,,,,32,1,4.000000e+000,1.319885e-003,0.000000e+000,0,,0,
1524166890.253,,0.000000e+000,5.499906e+001,-2.520281e-006,0.000000e+000,3,8.233765e-001,0.000000e+000,,,,,,,,,,,,,,32,1,4.000000e+000,6.580353e-003,0.000000e+000,0,,0,
1524166928.303,,0.000000e+000,5.499380e+001,-2.483790e-006,0.000000e+000,3,8.310645e-001,0.000000e+000,,,,,,,,,,,,,,32,1,4.000000e+000,6.572723e-003,0.000000e+000,0,,0,
1524166953.443,,0.000000e+000,5.500366e+001,-2.464360e-006,0.000000e+000,3,8.090578e-001,0.000000e+000,,,,,,,,,,,,,,32,1,4.000000e+000,5.260468e-003,0.000000e+000,0,,0,