File: Input_All/TC04-12-01K_VRMac_55K_1500s_VRMde_55K.dc.dat
[Header]
TITLE,MPMS DC Measurement
BYAPP,MPMS Measurement,2.1,Summary
FILEOPENTIME, 1524090253.290000 4/18/2018, 4:24:13 PM

INFO, APPNAME, MPMS MultiVu Application, Revision 1.61,  Build 082

INFO, NAME, TC04-12-01K
INFO, WEIGHT, 1.000
INFO, AREA, 1.000
INFO, LENGTH, 1.000
INFO, SHAPE, 0
INFO, COMMENT,
INFO, SEQUENCE FILE: VRMac_55K_1500s_VRMde_55K.seq


INFO, BACKGROUND DATA FILE:, None


STARTUPAXIS,X,4,LINEAR,AUTO,0.000000,0.000000
STARTUPAXIS,Y1,5,LINEAR,AUTO,0.000000,0.000000


STARTUPGROUP,Longitudinal
FIELDGROUP,Longitudinal,1,2,3,4,5,6,7,8,9,15,16,17,18,27,28
FIELDGROUP,Transverse,1,2,3,4,10,11,12,13,14,19,20,21,22,27,28

PLOT_APPEARANCE,ALL,HORZ_GRID_ON,VERT_GRID_ON,MARKERS_AND_LINES

[Data]
Time,Comment,Field (Oe),Temperature (K),Long Moment (emu),Long Scan Std Dev,Long Algorithm,Long Reg Fit,Long Percent Error (%),Trans Moment (emu),Trans Scan Std Dev,Trans Algorithm,Trans Reg Fit,Trans Percent Error (%),Long Moment [w/o ABS] (emu),Long Scan Std Dev [w/o ABS],Long Reg Fit [w/o ABS],Long Percent Error [w/o ABS] (%),Trans Moment [w/o ABS] (emu),Trans Scan Std Dev [w/o ABS],Trans Reg Fit [w/o ABS],Trans Percent Error [w/o ABS] (%),Points per Scan,Scans per Measurement,Scan Length (cm),Delta Temp (K),Rot Position (deg),Error,EC Comp. Running,Using ABS,
1524090253.290,,0.000000e+000,5.499577e+001,-1.254101e-005,0.000000e+000,3,9.641700e-001,0.000000e+000,,,,,,,,,,,,,,32,1,4.000000e+000,7.888794e-003,0.000000e+000,0,,0,
1524090278.350,,0.000000e+000,5.500103e+001,-9.504884e-006,0.000000e+000,3,9.633191e-001,0.000000e+000,,,,,,,,,,,,,,32,1,4.000000e+000,2.639771e-003,0.000000e+000,0,,0,
1524090303.570,,0.000000e+000,5.499643e+001,-7.964979e-006,0.000000e+000,3,9.573739e-001,0.000000e+000,,,,,,,,,,,,,,32,1,4.000000e+000,6.568909e-003,0.000000e+000,0,,0,
1524090328.750,,0.000000e+000,5.499905e+001,-6.864685e-006,0.000000e+000,3,9.531267e-001,0.000000e+000,,,,,,,,,,,,,,32,1,4.000000e+000,1.319885e-003,0.000000e+000,0,,0,
1524090353.930,,0.000000e+000,5.499971e+001,-5.978593e-006,0.000000e+000,3,9.452818e-001,0.000000e+000,,,,,,,,,,,,,,32,1,4.000000e+000,2.639771e-003,0.000000e+000,0,,0,
1524090379.180,,0.000000e+000,5.499840e+001,-5.476445e-006,0.000000e+000,3,9.458357e-001,0.000000e+000,,,,,,,,,,,,,,32,1,4.000000e+000,5.260468e-003,0.000000e+000,0,,0,
1524090404.360,,0.000000e+000,5.500037e+001,-4.925203e-006,0.000000e+000,3,9.433092e-001,0.000000e+000,,,,,,,,,,,,,,32,1,4.000000e+000,1.319885e-003,0.000000e+000,0,,0,
1524090429.560,,0.000000e+000,5.499643e+001,-4.549546e-006,0.000000e+000,3,9.311343e-001,0.000000e+000,,,,,,,,,,,,,,32,1,4.000000e+000,1.312256e-003,0.000000e+000,0,,0,
1524090454.770,,0.000000e+000,5.499840e+001,-4.112345e-006,0.000000e+000,3,9.184333e-001,0.000000e+000,,,,,,,,,,,,,,32,1,4.000000e+000,2.628326e-003,0.000000e+000,0,,0,
1524090479.970,,0.000000e+000,5.499577e+001,-3.844238e-006,0.000000e+000,3,9.183094e-001,0.000000e+000,,,,,,,,,,,,,,32,1,4.000000e+000,0.000000e+000,0.000000e+000,0,,0,
1524090505.180,,0.000000e+000,5.499972e+001,-3.583019e-006,0.000000e+000,3,9.052007e-001,0.000000e+000,,,,,,,,,,,,,,32,1,4.000000e+000,5.268097e-003,0.000000e+000,0,,0,
1524090530.400,,0.000000e+000,5.499643e+001,-3.410664e-006,0.000000e+000,3,8.893372e-001,0.000000e+000,,,,,,,,,,,,,,32,1,4.000000e+000,6.568909e-003,0.000000e+000,0,,0,
1524090555.630,,0.000000e+000,5.499971e+001,-3.185663e-006,0.000000e+000,3,8.849714e-001,0.000000e+000,,,,,,,,,,,,,,32,1,4.000000e+000,2.639771e-003,0.000000e+000,0,,0,
1524090580.811,,0.000000e+000,5.499971e+001,-2.987984e-006,0.000000e+000,3,8.664712e-001,0.000000e+000,,,,,,,,,,,,,,32,1,4.000000e+000,2.639771e-003,0.000000e+000,0,,0,
1524090606.051,,0.000000e+000,5.500234e+001,-2.934614e-006,0.000000e+000,3,8.515429e-001,0.000000e+000,,,,,,,,,,,,,,32,1,4.000000e+000,7.900238e-003,0.000000e+000,0,,0,
1524090630.941,,0.000000e+000,5.499774e+001,-2.748982e-006,0.000000e+000,3,8.309234e-001,0.000000e+000,,,,,,,,,,,,,,32,1,4.000000e+000,3.940582e-003,0.000000e+000,0,,0,
1524090656.461,,0.000000e+000,5.499511e+001,-2.748847e-006,0.000000e+000,3,8.185801e-001,0.000000e+000,,,,,,,,,,,,,,32,1,4.000000e+000,3.940582e-003,0.000000e+000,0,,0,
1524090681.671,,0.000000e+000,5.499445e+001,-2.699785e-006,0.000000e+000,3,8.128709e-001,0.000000e+000,,,,,,,,,,,,,,32,1,4.000000e+000,0.000000e+000,0.000000e+000,0,,0,
1524090706.291,,0.000000e+000,5.499840e+001,-2.590671e-006,0.000000e+000,3,7.996707e-001,0.000000e+000,,,,,,,,,,,,,,32,1,4.000000e+000,5.260468e-003,0.000000e+000,0,,0,
1524090734.943,,0.000000e+000,5.500103e+001,-5.939218e-007,0.000000e+000,2,0.000000e+000,0.000000e+000,,,,,,,,,,,,,,32,1,4.000000e+000,0.000000e+000,0.000000e+000,0,,0,
1524090764.477,,0.000000e+000,5.499905e+001,-4.139943e-007,0.000000e+000,2,0.000000e+000,0.000000e+000,,,,,,,,,,,,,,32,1,4.000000e+000,3.948212e-003,0.000000e+000,0,,0,
1524090793.041,,0.000000e+000,5.499839e+001,-3.847147e-007,0.000000e+000,2,0.000000e+000,0.000000e+000,,,,,,,,,,,,,,32,1,4.000000e+000,0.000000e+000,0.000000e+000,0,,0,
1524090818.241,,0.000000e+000,5.499773e+001,2.525519e-006,0.000000e+000,3,6.286022e-001,0.000000e+000,,,,,,,,,,,,,,32,1,4.000000e+000,1.308441e-003,0.000000e+000,0,,0,
1524090843.451,,0.000000e+000,5.499182e+001,2.468665e-006,0.000000e+000,3,6.146502e-001,0.000000e+000,,,,,,,,,,,,,,32,1,4.000000e+000,1.052094e-002,0.000000e+000,0,,0,
1524090868.661,,0.000000e+000,5.499708e+001,-2.680735e-006,0.000000e+000,3,7.667488e-001,0.000000e+000,,,,,,,,,,,,,,32,1,4.000000e+000,5.260468e-003,0.000000e+000,0,,0,
1524090895.193,,0.000000e+000,5.500235e+001,-2.736780e-006,0.000000e+000,3,7.421976e-001,0.000000e+000,,,,,,,,,,,,,,32,1,4.000000e+000,2.639771e-003,0.000000e+000,0,,0,
1524090920.043,,0.000000e+000,5.499380e+001,-2.657358e-006,0.000000e+000,3,7.292815e-001,0.000000e+000,,,,,,,,,,,,,,32,1,4.000000e+000,3.948212e-003,0.000000e+000,0,,0,
1524090945.043,,0.000000e+000,5.499380e+001,-2.717290e-006,0.000000e+000,3,7.492387e-001,0.000000e+000,,,,,,,,,,,,,,32,1,4.000000e+000,3.948212e-003,0.000000e+000,0,,0,
1524090973.857,,0.000000e+000,5.499380e+001,3.283633e-007,0.000000e+000,2,0.000000e+000,0.000000e+000,,,,,,,,,,,,,,32,1,4.000000e+000,1.308441e-003,0.000000e+000,0,,0,
1524091001.851,,0.000000e+000,5.500431e+001,5.205647e-007,0.000000e+000,2,0.000000e+000,0.000000e+000,,,,,,,,,,,,,,32,1,4.000000e+000,9.208679e-003,0.000000e+000,0,,0,
1524091030.845,,0.000000e+000,5.500301e+001,6.084591e-007,0.000000e+000,2,0.000000e+000,0.000000e+000,,,,,,,,,,,,,,32,1,4.000000e+000,1.319885e-003,0.000000e+000,0,,0,
1524091060.329,,0.000000e+000,5.500037e+001,7.064940e-007,0.000000e+000,2,0.000000e+000,0.000000e+000,,,,,,,,,,,,,,32,1,4.000000e+000,6.587982e-003,0.000000e+000,0,,0,
1524091087.601,,0.000000e+000,5.499577e+001,6.604305e-007,0.000000e+000,2,0.000000e+000,0.000000e+000,,,,,,,,,,,,,,32,1,4.000000e+000,5.249023e-003,0.000000e+000,0,,0,
1524091112.241,,0.000000e+000,5.499905e+001,2.360672e-006,0.000000e+000,3,7.158487e-001,0.000000e+000,,,,,,,,,,,,,,32,1,4.000000e+000,1.319885e-003,0.000000e+000,0,,0,
1524091138.223,,0.000000e+000,5.499577e+001,2.373710e-006,0.000000e+000,3,7.076929e-001,0.000000e+000,,,,,,,,,,,,,,32,1,4.000000e+000,1.052094e-002,0.000000e+000,0,,0,
1524091163.593,,0.000000e+000,5.499577e+001,2.395692e-006,0.000000e+000,3,6.956205e-001,0.000000e+000,,,,,,,,,,,,,,32,1,4.000000e+000,0.000000e+000,0.000000e+000,0,,0,
1524091188.443,,0.000000e+000,5.500365e+001,2.351880e-006,0.000000e+000,3,6.952764e-001,0.000000e+000,,,,,,,,,,,,,,32,1,4.000000e+000,1.052856e-002,0.000000e+000,0,,0,
1524091213.153,,0.000000e+000,5.499972e+001,2.432445e-006,0.000000e+000,3,7.420488e-001,0.000000e+000,,,,,,,,,,,,,,32,1,4.000000e+000,5.268097e-003,0.000000e+000,0,,0,
1524091238.083,,0.000000e+000,5.499839e+001,2.434534e-006,0.000000e+000,3,7.431182e-001,0.000000e+000,,,,,,,,,,,,,,32,1,4.000000e+000,0.000000e+000,0.000000e+000,0,,0,
1524091263.523,,0.000000e+000,5.499971e+001,2.435178e-006,0.000000e+000,3,7.293981e-001,0.000000e+000,,,,,,,,,,,,,,32,1,4.000000e+000,0.000000e+000,0.000000e+000,0,,0,
1524091288.514,,0.000000e+000,5.499709e+001,2.526966e-006,0.000000e+000,3,7.390825e-001,0.000000e+000,,,,,,,,,,,,,,32,1,4.000000e+000,7.888794e-003,0.000000e+000,0,,0,
1524091313.794,,0.000000e+000,5.500103e+001,2.612949e-006,0.000000e+000,3,7.564699e-001,0.000000e+000,,,,,,,,,,,,,,32,1,4.000000e+000,7.888794e-003,0.000000e+000,0,,0,
1524091339.224,,0.000000e+000,5.499971e+001,2.512031e-006,0.000000e+000,3,7.689443e-001,0.000000e+000,,,,,,,,,,,,,,32,1,4.000000e+000,0.000000e+000,0.000000e+000,0,,0,
1524091364.704,,0.000000e+000,5.500169e+001,2.471539e-006,0.000000e+000,3,7.785890e-001,0.000000e+000,,,,,,,,,,,,,,32,1,4.000000e+000,3.959656e-003,0.000000e+000,0,,0,
1524091390.554,,0.000000e+000,5.499445e+001,2.481000e-006,0.000000e+000,3,7.616581e-001,0.000000e+000,,,,,,,,,,,,,,32,1,4.000000e+000,0.000000e+000,0.000000e+000,0,,0,
1524091415.654,,0.000000e+000,5.500037e+001,2.514956e-006,0.000000e+000,3,7.579985e-001,0.000000e+000,,,,,,,,,,,,,,32,1,4.000000e+000,6.587982e-003,0.000000e+000,0,,0,
1524091440.734,,0.000000e+000,5.499841e+001,2.511423e-006,0.000000e+000,3,7.691641e-001,0.000000e+000,,,,,,,,,,,,,,32,1,4.000000e+000,1.052856e-002,0.000000e+000,0,,0,
1524091465.724,,0.000000e+000,5.499642e+001,2.574000e-006,0.000000e+000,3,7.769144e-001,0.000000e+000,,,,,,,,,,,,,,32,1,4.000000e+000,3.940582e-003,0.000000e+000,0,,0,
1524091491.414,,0.000000e+000,5.499971e+001,2.636033e-006,0.000000e+000,3,7.659969e-001,0.000000e+000,,,,,,,,,,,,,,32,1,4.000000e+000,0.000000e+000,0.000000e+000,0,,0,
1524091516.644,,0.000000e+000,5.499971e+001,2.626074e-006,0.000000e+000,3,7.753505e-001,0.000000e+000,,,,,,,,,,,,,,32,1,4.000000e+000,2.639771e-003,0.000000e+000,0,,0,
1524091541.794,,0.000000e+000,5.499972e+001,2.685867e-006,0.000000e+000,3,8.057567e-001,0.000000e+000,,,,,,,,,,,,,,32,1,4.000000e+000,5.268097e-003,0.000000e+000,0,,0,
1524091567.204,,0.000000e+000,5.499906e+001,2.581507e-006,0.000000e+000,3,8.136574e-001,0.000000e+000,,,,,,,,,,,,,,32,1,4.000000e+000,6.580353e-003,0.000000e+000,0,,0,
1524091591.964,,0.000000e+000,5.499971e+001,2.678133e-006,0.000000e+000,3,8.005007e-001,0.000000e+000,,,,,,,,,,,,,,32,1,4.000000e+000,2.639771e-003,0.000000e+000,0,,0,
1524091617.164,,0.000000e+000,5.499380e+001,2.688925e-006,0.000000e+000,3,8.017043e-001,0.000000e+000,,,,,,,,,,,,,,32,1,4.000000e+000,3.948212e-003,0.000000e+000,0,,0,
1524091642.844,,0.000000e+000,5.499445e+001,2.686561e-006,0.000000e+000,3,8.144882e-001,0.000000e+000,,,,,,,,,,,,,,32,1,4.000000e+000,7.881165e-003,0.000000e+000,0,,0,
1524091667.564,,0.000000e+000,5.499708e+001,2.727005e-006,0.000000e+000,3,8.077960e-001,0.000000e+000,,,,,,,,,,,,,,32,1,4.000000e+000,2.620697e-003,0.000000e+000,0,,0,
1524091692.764,,0.000000e+000,5.499380e+001,2.718491e-006,0.000000e+000,3,8.220657e-001,0.000000e+000,,,,,,,,,,,,,,32,1,4.000000e+000,3.948212e-003,0.000000e+000,0,,0,
1524091718.154,,0.000000e+000,5.499841e+001,2.743981e-006,0.000000e+000,3,8.198064e-001,0.000000e+000,,,,,,,,,,,,,,32,1,4.000000e+000,1.052856e-002,0.000000e+000,0,,0,
1524091742.494,,0.000000e+000,5.499972e+001,2.839780e-006,0.000000e+000,3,8.123487e-001,0.000000e+000,,,,,,,,,,,,,,32,1,4.000000e+000,5.268097e-003,0.000000e+000,0,,0,
1524091767.084,,0.000000e+000,5.499643e+001,2.857039e-006,0.000000e+000,3,8.155620e-001,0.000000e+000,,,,,,,,,,,,,,32,1,4.000000e+000,1.312256e-003,0.000000e+000,0,,0,
1524091792.964,,0.000000e+000,5.499905e+001,2.819613e-006,0.000000e+000,3,8.356954e-001,0.000000e+000,,,,,,,,,,,,,,32,1,4.000000e+000,3.948212e-003,0.000000e+000,0,,0,
1524091818.104,,0.000000e+000,5.499642e+001,2.806689e-006,0.000000e+000,3,8.291464e-001,0.000000e+000,,,,,,,,,,,,,,32,1,4.000000e+000,3.940582e-003,0.000000e+000,0,,0,
1524091842.854,,0.000000e+000,5.500695e+001,2.791159e-006,0.000000e+000,3,8.499287e-001,0.000000e+000,,,,,,,,,,,,,,32,1,4.000000e+000,1.319885e-003,0.000000e+000,0,,0,
1524091867.994,,0.000000e+000,5.499773e+001,2.839752e-006,0.000000e+000,3,8.321926e-001,0.000000e+000,,,,,,,,,,,,,,32,1,4.000000e+000,1.308441e-003,0.000000e+000,0,,0,
1524091892.604,,0.000000e+000,5.499643e+001,2.863531e-006,0.000000e+000,3,8.477945e-001,0.000000e+000,,,,,,,,,,,,,,32,1,4.000000e+000,1.312256e-003,0.000000e+000,0,,0,
1524091917.744,,0.000000e+000,5.500037e+001,2.871469e-006,0.000000e+000,3,8.334150e-001,0.000000e+000,,,,,,,,,,,,,,32,1,4.000000e+000,6.587982e-003,0.000000e+000,0,,0,
1524091942.614,,0.000000e+000,5.499313e+001,2.872509e-006,0.000000e+000,3,8.466809e-001,0.000000e+000,,,,,,,,,,,,,,32,1,4.000000e+000,2.628326e-003,0.000000e+000,0,,0,
1524091968.294,,0.000000e+000,5.499708e+001,2.956602e-006,0.000000e+000,3,8.137816e-001,0.000000e+000,,,,,,,,,,,,,,32,1,4.000000e+000,0.000000e+000,0.000000e+000,0,,0,
1524091993.035,,0.000000e+000,5.500169e+001,2.988488e-006,0.000000e+000,3,8.255274e-001,0.000000e+000,,,,,,,,,,,,,,32,1,4.000000e+000,1.319885e-003,0.000000e+000,0,,0,
1524092018.365,,0.000000e+000,5.499773e+001,2.984696e-006,0.000000e+000,3,8.285896e-001,0.000000e+000,,,,,,,,,,,,,,32,1,4.000000e+000,1.308441e-003,0.000000e+000,0,,0,
1524092043.755,,0.000000e+000,5.499839e+001,3.038844e-006,0.000000e+000,3,8.517349e-001,0.000000e+000,,,,,,,,,,,,,,32,1,4.000000e+000,0.000000e+000,0.000000e+000,0,,0,
1524092068.905,,0.000000e+000,5.499905e+001,3.013497e-006,0.000000e+000,3,8.380932e-001,0.000000e+000,,,,,,,,,,,,,,32,1,4.000000e+000,3.948212e-003,0.000000e+000,0,,0,
1524092094.695,,0.000000e+000,5.499840e+001,3.082405e-006,0.000000e+000,3,8.334790e-001,0.000000e+000,,,,,,,,,,,,,,32,1,4.000000e+000,5.260468e-003,0.000000e+000,0,,0,
1524092119.815,,0.000000e+000,5.500235e+001,3.052470e-006,0.000000e+000,3,8.610802e-001,0.000000e+000,,,,,,,,,,,,,,32,1,4.000000e+000,1.052856e-002,0.000000e+000,0,,0,
1524092144.505,,0.000000e+000,5.499445e+001,3.070872e-006,0.000000e+000,3,8.513219e-001,0.000000e+000,,,,,,,,,,,,,,32,1,4.000000e+000,0.000000e+000,0.000000e+000,0,,0,
1524092169.875,,0.000000e+000,5.499445e+001,3.107225e-006,0.000000e+000,3,8.521072e-001,0.000000e+000,,,,,,,,,,,,,,32,1,4.000000e+000,5.260468e-003,0.000000e+000,0,,0,
1524092195.345,,0.000000e+000,5.500168e+001,3.017060e-006,0.000000e+000,3,8.563337e-001,0.000000e+000,,,,,,,,,,,,,,32,1,4.000000e+000,6.580353e-003,0.000000e+000,0,,0,
1524092221.335,,0.000000e+000,5.499313e+001,2.984037e-006,0.000000e+000,3,8.444241e-001,0.000000e+000,,,,,,,,,,,,,,32,1,4.000000e+000,7.892609e-003,0.000000e+000,0,,0,
1524092246.525,,0.000000e+000,5.499906e+001,3.083584e-006,0.000000e+000,3,8.488889e-001,0.000000e+000,,,,,,,,,,,,,,32,1,4.000000e+000,6.580353e-003,0.000000e+000,0,,0,
1524092271.715,,0.000000e+000,5.499577e+001,3.104683e-006,0.000000e+000,3,8.599990e-001,0.000000e+000,,,,,,,,,,,,,,32,1,4.000000e+000,5.249023e-003,0.000000e+000,0,,0,
1524092296.925,,0.000000e+000,5.499905e+001,3.096178e-006,0.000000e+000,3,8.661310e-001,0.000000e+000,,,,,,,,,,,,,,32,1,4.000000e+000,1.319885e-003,0.000000e+000,0,,0,
1524092322.145,,0.000000e+000,5.500037e+001,3.150727e-006,0.000000e+000,3,8.559284e-001,0.000000e+000,,,,,,,,,,,,,,32,1,4.000000e+000,1.319885e-003,0.000000e+000,0,,0,
1524092346.805,,0.000000e+000,5.499774e+001,3.137440e-006,0.000000e+000,3,8.768263e-001,0.000000e+000,,,,,,,,,,,,,,32,1,4.000000e+000,3.940582e-003,0.000000e+000,0,,0,
1524092372.055,,0.000000e+000,5.499972e+001,3.150949e-006,0.000000e+000,3,8.548895e-001,0.000000e+000,,,,,,,,,,,,,,32,1,4.000000e+000,5.268097e-003,0.000000e+000,0,,0,
1524092397.305,,0.000000e+000,5.499511e+001,3.118480e-006,0.000000e+000,3,8.504822e-001,0.000000e+000,,,,,,,,,,,,,,32,1,4.000000e+000,3.940582e-003,0.000000e+000,0,,0,
1524092422.725,,0.000000e+000,5.499511e+001,3.103097e-006,0.000000e+000,3,8.575384e-001,0.000000e+000,,,,,,,,,,,,,,32,1,4.000000e+000,3.940582e-003,0.000000e+000,0,,0,
1524092447.565,,0.000000e+000,5.499708e+001,3.247755e-006,0.000000e+000,3,8.492050e-001,0.000000e+000,,,,,,,,,,,,,,32,1,4.000000e+000,2.620697e-003,0.000000e+000,0,,0,
1524092472.685,,0.000000e+000,5.499905e+001,3.295286e-006,0.000000e+000,3,8.443758e-001,0.000000e+000,,,,,,,,,,,,,,32,1,4.000000e+000,1.319885e-003,0.000000e+000,0,,0,
1524092497.515,,0.000000e+000,5.499775e+001,3.287969e-006,0.000000e+000,3,8.512697e-001,0.000000e+000,,,,,,,,,,,,,,32,1,4.000000e+000,9.208679e-003,0.000000e+000,0,,0,
1524092522.405,,0.000000e+000,5.500300e+001,3.268262e-006,0.000000e+000,3,8.451914e-001,0.000000e+000,,,,,,,,,,,,,,32,1,4.000000e+000,6.580353e-003,0.000000e+000,0,,0,
1524092547.825,,0.000000e+000,5.499774e+001,3.257509e-006,0.000000e+000,3,8.551823e-001,0.000000e+000,,,,,,,,,,,,,,32,1,4.000000e+000,6.580353e-003,0.000000e+000,0,,0,
1524092572.895,,0.000000e+000,5.499511e+001,3.231747e-006,0.000000e+000,3,8.457266e-001,0.000000e+000,,,,,,,,,,,,,,32,1,4.000000e+000,1.319885e-003,0.000000e+000,0,,0,
1524092598.155,,0.000000e+000,5.499971e+001,3.291517e-006,0.000000e+000,3,8.534786e-001,0.000000e+000,,,,,,,,,,,,,,32,1,4.000000e+000,2.639771e-003,0.000000e+000,0,,0,
1524092623.165,,0.000000e+000,5.499773e+001,3.329712e-006,0.000000e+000,3,8.602960e-001,0.000000e+000,,,,,,,,,,,,,,32,1,4.000000e+000,1.308441e-003,0.000000e+000,0,,0,
1524092648.755,,0.000000e+000,5.500234e+001,3.311264e-006,0.000000e+000,3,8.692734e-001,0.000000e+000,,,,,,,,,,,,,,32,1,4.000000e+000,7.900238e-003,0.000000e+000,0,,0,
1524092674.615,,0.000000e+000,5.500169e+001,3.305314e-006,0.000000e+000,3,8.620514e-001,0.000000e+000,,,,,,,,,,,,,,32,1,4.000000e+000,1.319885e-003,0.000000e+000,0,,0,
1524092699.275,,0.000000e+000,5.499906e+001,3.239981e-006,0.000000e+000,3,8.656747e-001,0.000000e+000,,,,,,,,,,,,,,32,1,4.000000e+000,6.580353e-003,0.000000e+000,0,,0,
1524092724.626,,0.000000e+000,5.500037e+001,3.307550e-006,0.000000e+000,3,8.746225e-001,0.000000e+000,,,,,,,,,,,,,,32,1,4.000000e+000,1.319885e-003,0.000000e+000,0,,0,
1524092750.616,,0.000000e+000,5.500103e+001,3.241049e-006,0.000000e+000,3,8.621678e-001,0.000000e+000,,,,,,,,,,,,,,32,1,4.000000e+000,0.000000e+000,0.000000e+000,0,,0,
1524092775.616,,0.000000e+000,5.500037e+001,3.332847e-006,0.000000e+000,3,8.624550e-001,0.000000e+000,,,,,,,,,,,,,,32,1,4.000000e+000,1.319885e-003,0.000000e+000,0,,0,
1524092800.626,,0.000000e+000,5.500103e+001,3.281870e-006,0.000000e+000,3,8.533265e-001,0.000000e+000,,,,,,,,,,,,,,32,1,4.000000e+000,7.888794e-003,0.000000e+000,0,,0,
1524092826.056,,0.000000e+000,5.500235e+001,3.384869e-006,0.000000e+000,3,8.606170e-001,0.000000e+000,,,,,,,,,,,,,,32,1,4.000000e+000,2.639771e-003,0.000000e+000,0,,0,
1524092851.136,,0.000000e+000,5.499972e+001,3.363114e-006,0.000000e+000,3,8.628892e-001,0.000000e+000,,,,,,,,,,,,,,32,1,4.000000e+000,7.900238e-003,0.000000e+000,0,,0,
1524092876.176,,0.000000e+000,5.499906e+001,3.402450e-006,0.000000e+000,3,8.549179e-001,0.000000e+000,,,,,,,,,,,,,,32,1,4.000000e+000,1.710129e-002,0.000000e+000,0,,0,
1524092900.866,,0.000000e+000,5.500300e+001,3.342933e-006,0.000000e+000,3,8.740177e-001,0.000000e+000,,,,,,,,,,,,,,32,1,4.000000e+000,1.183701e-002,0.000000e+000,0,,0,
1524092926.176,,0.000000e+000,5.499905e+001,3.419601e-006,0.000000e+000,3,8.653214e-001,0.000000e+000,,,,,,,,,,,,,,32,1,4.000000e+000,3.948212e-003,0.000000e+000,0,,0,
1524092952.036,,0.000000e+000,5.499445e+001,3.455233e-006,0.000000e+000,3,8.697640e-001,0.000000e+000,,,,,,,,,,,,,,32,1,4.000000e+000,2.628326e-003,0.000000e+000,0,,0,
1524092978.206,,0.000000e+000,5.500498e+001,3.386524e-006,0.000000e+000,3,8.795469e-001,0.000000e+000,,,,,,,,,,,,,,32,1,4.000000e+000,2.620697e-003,0.000000e+000,0,,0,
1524093003.276,,0.000000e+000,5.500497e+001,3.331729e-006,0.000000e+000,3,8.849608e-001,0.000000e+000,,,,,,,,,,,,,,32,1,4.000000e+000,7.888794e-003,0.000000e+000,0,,0,
1524093028.336,,0.000000e+000,5.499577e+001,3.403749e-006,0.000000e+000,3,8.822055e-001,0.000000e+000,,,,,,,,,,,,,,32,1,4.000000e+000,0.000000e+000,0.000000e+000,0,,0,
1524093053.566,,0.000000e+000,5.499774e+001,3.437245e-006,0.000000e+000,3,8.673350e-001,0.000000e+000,,,,,,,,,,,,,,32,1,4.000000e+000,3.940582e-003,0.000000e+000,0,,0,
1524093078.746,,0.000000e+000,5.500103e+001,3.454076e-006,0.000000e+000,3,8.754415e-001,0.000000e+000,,,,,,,,,,,,,,32,1,4.000000e+000,5.279541e-003,0.000000e+000,0,,0,
1524093103.966,,0.000000e+000,5.500235e+001,3.443219e-006,0.000000e+000,3,8.840700e-001,0.000000e+000,,,,,,,,,,,,,,32,1,4.000000e+000,2.639771e-003,0.000000e+000,0,,0,
1524093129.166,,0.000000e+000,5.500103e+001,3.440476e-006,0.000000e+000,3,8.747231e-001,0.000000e+000,,,,,,,,,,,,,,32,1,4.000000e+000,0.000000e+000,0.000000e+000,0,,0,
1524093154.406,,0.000000e+000,5.500103e+001,3.439826e-006,0.000000e+000,3,8.678163e-001,0.000000e+000,,,,,,,,,,,,,,32,1,4.000000e+000,1.577759e-002,0.000000e+000,0,,0,
1524093179.776,,0.000000e+000,5.499380e+001,3.428843e-006,0.000000e+000,3,8.727674e-001,0.000000e+000,,,,,,,,,,,,,,32,1,4.000000e+000,3.948212e-003,0.000000e+000,0,,0,
1524093204.926,,0.000000e+000,5.499379e+001,3.424058e-006,0.000000e+000,3,8.721199e-001,0.000000e+000,,,,,,,,,,,,,,32,1,4.000000e+000,9.201050e-003,0.000000e+000,0,,0,
1524093230.116,,0.000000e+000,5.500037e+001,3.546381e-006,0.000000e+000,3,8.789196e-001,0.000000e+000,,,,,,,,,,,,,,32,1,4.000000e+000,9.201050e-003,0.000000e+000,0,,0,
1524093255.716,,0.000000e+000,5.499182e+001,3.559780e-006,0.000000e+000,3,8.637809e-001,0.000000e+000,,,,,,,,,,,,,,32,1,4.000000e+000,5.260468e-003,0.000000e+000,0,,0,
1524093281.366,,0.000000e+000,5.499642e+001,3.542683e-006,0.000000e+000,3,8.682643e-001,0.000000e+000,,,,,,,,,,,,,,32,1,4.000000e+000,3.940582e-003,0.000000e+000,0,,0,
1524093306.526,,0.000000e+000,5.499840e+001,3.572146e-006,0.000000e+000,3,8.647988e-001,0.000000e+000,,,,,,,,,,,,,,32,1,4.000000e+000,2.628326e-003,0.000000e+000,0,,0,
1524093331.426,,0.000000e+000,5.499971e+001,3.551743e-006,0.000000e+000,3,8.644535e-001,0.000000e+000,,,,,,,,,,,,,,32,1,4.000000e+000,1.052094e-002,0.000000e+000,0,,0,
1524093356.386,,0.000000e+000,5.499840e+001,3.557164e-006,0.000000e+000,3,8.629256e-001,0.000000e+000,,,,,,,,,,,,,,32,1,4.000000e+000,2.628326e-003,0.000000e+000,0,,0,
1524093381.466,,0.000000e+000,5.499774e+001,3.533879e-006,0.000000e+000,3,8.624633e-001,0.000000e+000,,,,,,,,,,,,,,32,1,4.000000e+000,3.940582e-003,0.000000e+000,0,,0,
1524093406.466,,0.000000e+000,5.499972e+001,3.563060e-006,0.000000e+000,3,8.837273e-001,0.000000e+000,,,,,,,,,,,,,,32,1,4.000000e+000,5.268097e-003,0.000000e+000,0,,0,
1524093431.917,,0.000000e+000,5.499971e+001,3.525864e-006,0.000000e+000,3,8.776782e-001,0.000000e+000,,,,,,,,,,,,,,32,1,4.000000e+000,2.639771e-003,0.000000e+000,0,,0,
1524093457.417,,0.000000e+000,5.499577e+001,3.522825e-006,0.000000e+000,3,8.907594e-001,0.000000e+000,,,,,,,,,,,,,,32,1,4.000000e+000,5.249023e-003,0.000000e+000,0,,0,
1524093482.997,,0.000000e+000,5.499511e+001,3.562295e-006,0.000000e+000,3,8.831724e-001,0.000000e+000,,,,,,,,,,,,,,32,1,4.000000e+000,1.319885e-003,0.000000e+000,0,,0,
1524093508.027,,0.000000e+000,5.500432e+001,3.541591e-006,0.000000e+000,3,8.856122e-001,0.000000e+000,,,,,,,,,,,,,,32,1,4.000000e+000,6.580353e-003,0.000000e+000,0,,0,
1524093533.127,,0.000000e+000,5.499905e+001,3.595817e-006,0.000000e+000,3,8.762270e-001,0.000000e+000,,,,,,,,,,,,,,32,1,4.000000e+000,1.446915e-002,0.000000e+000,0,,0,
1524093558.737,,0.000000e+000,5.499511e+001,3.518061e-006,0.000000e+000,3,8.766254e-001,0.000000e+000,,,,,,,,,,,,,,32,1,4.000000e+000,1.319885e-003,0.000000e+000,0,,0,
1524093584.547,,0.000000e+000,5.499840e+001,3.639136e-006,0.000000e+000,3,8.880233e-001,0.000000e+000,,,,,,,,,,,,,,32,1,4.000000e+000,7.900238e-003,0.000000e+000,0,,0,
1524093609.757,,0.000000e+000,5.499906e+001,3.559936e-006,0.000000e+000,3,8.817283e-001,0.000000e+000,,,,,,,,,,,,,,32,1,4.000000e+000,9.220123e-003,0.000000e+000,0,,0,
1524093635.797,,0.000000e+000,5.499182e+001,3.543508e-006,0.000000e+000,3,8.924269e-001,0.000000e+000,,,,,,,,,,,,,,32,1,4.000000e+000,5.260468e-003,0.000000e+000,0,,0,
1524093661.317,,0.000000e+000,5.499511e+001,3.624713e-006,0.000000e+000,3,9.092771e-001,0.000000e+000,,,,,,,,,,,,,,32,1,4.000000e+000,1.184082e-002,0.000000e+000,0,,0,
1524093686.367,,0.000000e+000,5.499774e+001,3.597736e-006,0.000000e+000,3,8.867521e-001,0.000000e+000,,,,,,,,,,,,,,32,1,4.000000e+000,6.580353e-003,0.000000e+000,0,,0,
1524093711.547,,0.000000e+000,5.499643e+001,3.605557e-006,0.000000e+000,3,8.827407e-001,0.000000e+000,,,,,,,,,,,,,,32,1,4.000000e+000,1.312256e-003,0.000000e+000,0,,0,
1524093736.677,,0.000000e+000,5.499708e+001,3.549195e-006,0.000000e+000,3,8.847134e-001,0.000000e+000,,,,,,,,,,,,,,32,1,4.000000e+000,2.620697e-003,0.000000e+000,0,,0,
1524093761.977,,0.000000e+000,5.499840e+001,3.591913e-006,0.000000e+000,3,8.891559e-001,0.000000e+000,,,,,,,,,,,,,,32,1,4.000000e+000,2.628326e-003,0.000000e+000,0,,0,
1524093787.187,,0.000000e+000,5.499577e+001,3.644984e-006,0.000000e+000,3,8.849114e-001,0.000000e+000,,,,,,,,,,,,,,32,1,4.000000e+000,2.632141e-003,0.000000e+000,0,,0,
1524093812.417,,0.000000e+000,5.499708e+001,3.611294e-006,0.000000e+000,3,8.894675e-001,0.000000e+000,,,,,,,,,,,,,,32,1,4.000000e+000,2.620697e-003,0.000000e+000,0,,0,
1524093837.777,,0.000000e+000,5.500168e+001,3.615304e-006,0.000000e+000,3,8.860555e-001,0.000000e+000,,,,,,,,,,,,,,32,1,4.000000e+000,6.580353e-003,0.000000e+000,0,,0,
1524093862.977,,0.000000e+000,5.499117e+001,3.606662e-006,0.000000e+000,3,8.876784e-001,0.000000e+000,,,,,,,,,,,,,,32,1,4.000000e+000,3.952026e-003,0.000000e+000,0,,0,
1524093888.307,,0.000000e+000,5.499577e+001,3.701858e-006,0.000000e+000,3,8.806387e-001,0.000000e+000,,,,,,,,,,,,,,32,1,4.000000e+000,2.632141e-003,0.000000e+000,0,,0,
1524093913.527,,0.000000e+000,5.499708e+001,3.727385e-006,0.000000e+000,3,8.793156e-001,0.000000e+000,,,,,,,,,,,,,,32,1,4.000000e+000,5.260468e-003,0.000000e+000,0,,0,
1524093938.807,,0.000000e+000,5.499642e+001,3.674345e-006,0.000000e+000,3,8.840172e-001,0.000000e+000,,,,,,,,,,,,,,32,1,4.000000e+000,3.940582e-003,0.000000e+000,0,,0,
1524093963.497,,0.000000e+000,5.499577e+001,3.681210e-006,0.000000e+000,3,8.739218e-001,0.000000e+000,,,,,,,,,,,,,,32,1,4.000000e+000,1.578903e-002,0.000000e+000,0,,0,
1524093988.947,,0.000000e+000,5.499445e+001,3.647798e-006,0.000000e+000,3,8.967164e-001,0.000000e+000,,,,,,,,,,,,,,32,1,4.000000e+000,5.260468e-003,0.000000e+000,0,,0,
1524094015.267,,0.000000e+000,5.499840e+001,3.654966e-006,0.000000e+000,3,8.898314e-001,0.000000e+000,,,,,,,,,,,,,,32,1,4.000000e+000,2.628326e-003,0.000000e+000,0,,0,
1524094040.287,,0.000000e+000,5.499905e+001,3.618557e-006,0.000000e+000,3,8.926845e-001,0.000000e+000,,,,,,,,,,,,,,32,1,4.000000e+000,1.319885e-003,0.000000e+000,0,,0,
1524094065.497,,0.000000e+000,5.499905e+001,3.691968e-006,0.000000e+000,3,8.983919e-001,0.000000e+000,,,,,,,,,,,,,,32,1,4.000000e+000,3.948212e-003,0.000000e+000,0,,0,
1524094090.677,,0.000000e+000,5.499708e+001,3.712705e-006,0.000000e+000,3,8.924875e-001,0.000000e+000,,,,,,,,,,,,,,32,1,4.000000e+000,0.000000e+000,0.000000e+000,0,,0,
1524094115.917,,0.000000e+000,5.500235e+001,3.705132e-006,0.000000e+000,3,8.938688e-001,0.000000e+000,,,,,,,,,,,,,,32,1,4.000000e+000,2.639771e-003,0.000000e+000,0,,0,
1524094141.098,,0.000000e+000,5.499445e+001,3.713696e-006,0.000000e+000,3,8.968873e-001,0.000000e+000,,,,,,,,,,,,,,32,1,4.000000e+000,2.628326e-003,0.000000e+000,0,,0,
1524094166.458,,0.000000e+000,5.499972e+001,3.739413e-006,0.000000e+000,3,8.993707e-001,0.000000e+000,,,,,,,,,,,,,,32,1,4.000000e+000,7.900238e-003,0.000000e+000,0,,0,
1524094192.308,,0.000000e+000,5.499511e+001,3.740799e-006,0.000000e+000,3,8.765147e-001,0.000000e+000,,,,,,,,,,,,,,32,1,4.000000e+000,1.319885e-003,0.000000e+000,0,,0,
1524094217.478,,0.000000e+000,5.500366e+001,3.742299e-006,0.000000e+000,3,8.782415e-001,0.000000e+000,,,,,,,,,,,,,,32,1,4.000000e+000,5.260468e-003,0.000000e+000,0,,0,
1524094242.328,,0.000000e+000,5.499840e+001,3.739682e-006,0.000000e+000,3,8.832245e-001,0.000000e+000,,,,,,,,,,,,,,32,1,4.000000e+000,5.260468e-003,0.000000e+000,0,,0,
1524094267.198,,0.000000e+000,5.499840e+001,3.778229e-006,0.000000e+000,3,8.882596e-001,0.000000e+000,,,,,,,,,,,,,,32,1,4.000000e+000,7.900238e-003,0.000000e+000,0,,0,
1524094291.958,,0.000000e+000,5.499577e+001,3.796618e-006,0.000000e+000,3,8.819908e-001,0.000000e+000,,,,,,,,,,,,,,32,1,4.000000e+000,2.632141e-003,0.000000e+000,0,,0,
1524094316.938,,0.000000e+000,5.500169e+001,3.759719e-006,0.000000e+000,3,8.793678e-001,0.000000e+000,,,,,,,,,,,,,,32,1,4.000000e+000,1.446915e-002,0.000000e+000,0,,0,
1524094341.988,,0.000000e+000,5.500169e+001,3.774124e-006,0.000000e+000,3,8.850026e-001,0.000000e+000,,,,,,,,,,,,,,32,1,4.000000e+000,1.319885e-003,0.000000e+000,0,,0,