File: Input_All/TC04-12-01K_VRMac_54K_6000s_VRMde_55K.dc.dat
[Header]
TITLE,MPMS DC Measurement
BYAPP,MPMS Measurement,2.1,Summary
FILEOPENTIME, 1524231915.702000 4/20/2018, 7:45:15 AM

INFO, APPNAME, MPMS MultiVu Application, Revision 1.61,  Build 082

INFO, NAME, TC04-12-01K
INFO, WEIGHT, 1.000
INFO, AREA, 1.000
INFO, LENGTH, 1.000
INFO, SHAPE, 0
INFO, COMMENT,
INFO, SEQUENCE FILE: VRMac_54K_6000s_VRMde_55K.seq


INFO, BACKGROUND DATA FILE:, None


STARTUPAXIS,X,4,LINEAR,AUTO,0.000000,0.000000
STARTUPAXIS,Y1,5,LINEAR,AUTO,0.000000,0.000000


STARTUPGROUP,Longitudinal
FIELDGROUP,Longitudinal,1,2,3,4,5,6,7,8,9,15,16,17,18,27,28
FIELDGROUP,Transverse,1,2,3,4,10,11,12,13,14,19,20,21,22,27,28

PLOT_APPEARANCE,ALL,HORZ_GRID_ON,VERT_GRID_ON,MARKERS_AND_LINES

[Data]
Time,Comment,Field (Oe),Temperature (K),Long Moment (emu),Long Scan Std Dev,Long Algorithm,Long Reg Fit,Long Percent Error (%),Trans Moment (emu),Trans Scan Std Dev,Trans Algorithm,Trans Reg Fit,Trans Percent Error (%),Long Moment [w/o ABS] (emu),Long Scan Std Dev [w/o ABS],Long Reg Fit [w/o ABS],Long Percent Error [w/o ABS] (%),Trans Moment [w/o ABS] (emu),Trans Scan Std Dev [w/o ABS],Trans Reg Fit [w/o ABS],Trans Percent Error [w/o ABS] (%),Points per Scan,Scans per Measurement,Scan Length (cm),Delta Temp (K),Rot Position (deg),Error,EC Comp. Running,Using ABS,
1524231915.702,,0.000000e+000,5.415960e+001,-1.685846e-005,0.000000e+000,3,9.651915e-001,0.000000e+000,,,,,,,,,,,,,,32,1,4.000000e+000,3.148727e-001,0.000000e+000,0,,0,
1524231955.602,,0.000000e+000,5.500237e+001,-1.249652e-005,0.000000e+000,3,9.556499e-001,0.000000e+000,,,,,,,,,,,,,,32,1,4.000000e+000,7.105255e-002,0.000000e+000,0,,0,
1524231993.083,,0.000000e+000,5.505700e+001,-1.007394e-005,0.000000e+000,3,9.510042e-001,0.000000e+000,,,,,,,,,,,,,,32,1,4.000000e+000,6.591797e-003,0.000000e+000,0,,0,
1524232031.313,,0.000000e+000,5.502209e+001,-8.659713e-006,0.000000e+000,3,9.588364e-001,0.000000e+000,,,,,,,,,,,,,,32,1,4.000000e+000,2.628326e-003,0.000000e+000,0,,0,
1524232069.023,,0.000000e+000,5.500169e+001,-7.682846e-006,0.000000e+000,3,9.430919e-001,0.000000e+000,,,,,,,,,,,,,,32,1,4.000000e+000,9.208679e-003,0.000000e+000,0,,0,
1524232106.993,,0.000000e+000,5.500103e+001,-6.875612e-006,0.000000e+000,3,9.575664e-001,0.000000e+000,,,,,,,,,,,,,,32,1,4.000000e+000,0.000000e+000,0.000000e+000,0,,0,
1524232144.303,,0.000000e+000,5.500037e+001,-6.303173e-006,0.000000e+000,3,9.423391e-001,0.000000e+000,,,,,,,,,,,,,,32,1,4.000000e+000,1.184082e-002,0.000000e+000,0,,0,
1524232181.943,,0.000000e+000,5.499906e+001,-5.750278e-006,0.000000e+000,3,9.385427e-001,0.000000e+000,,,,,,,,,,,,,,32,1,4.000000e+000,6.580353e-003,0.000000e+000,0,,0,
1524232219.453,,0.000000e+000,5.499511e+001,-5.380032e-006,0.000000e+000,3,9.394826e-001,0.000000e+000,,,,,,,,,,,,,,32,1,4.000000e+000,9.201050e-003,0.000000e+000,0,,0,
1524232258.093,,0.000000e+000,5.500235e+001,-4.976685e-006,0.000000e+000,3,9.411243e-001,0.000000e+000,,,,,,,,,,,,,,32,1,4.000000e+000,0.000000e+000,0.000000e+000,0,,0,
1524232296.073,,0.000000e+000,5.500168e+001,-4.643071e-006,0.000000e+000,3,9.265995e-001,0.000000e+000,,,,,,,,,,,,,,32,1,4.000000e+000,6.580353e-003,0.000000e+000,0,,0,
1524232333.703,,0.000000e+000,5.499774e+001,-4.373294e-006,0.000000e+000,3,9.191087e-001,0.000000e+000,,,,,,,,,,,,,,32,1,4.000000e+000,3.940582e-003,0.000000e+000,0,,0,
1524232370.973,,0.000000e+000,5.499839e+001,-4.024093e-006,0.000000e+000,3,9.110868e-001,0.000000e+000,,,,,,,,,,,,,,32,1,4.000000e+000,0.000000e+000,0.000000e+000,0,,0,
1524232408.283,,0.000000e+000,5.499445e+001,-3.882539e-006,0.000000e+000,3,9.061534e-001,0.000000e+000,,,,,,,,,,,,,,32,1,4.000000e+000,7.881165e-003,0.000000e+000,0,,0,
1524232445.623,,0.000000e+000,5.499643e+001,-3.616958e-006,0.000000e+000,3,9.184574e-001,0.000000e+000,,,,,,,,,,,,,,32,1,4.000000e+000,6.568909e-003,0.000000e+000,0,,0,
1524232483.223,,0.000000e+000,5.500301e+001,-3.463178e-006,0.000000e+000,3,8.973134e-001,0.000000e+000,,,,,,,,,,,,,,32,1,4.000000e+000,1.319885e-003,0.000000e+000,0,,0,
1524232521.323,,0.000000e+000,5.499709e+001,-3.262891e-006,0.000000e+000,3,9.013250e-001,0.000000e+000,,,,,,,,,,,,,,32,1,4.000000e+000,1.052856e-002,0.000000e+000,0,,0,
1524232559.383,,0.000000e+000,5.499905e+001,-3.091427e-006,0.000000e+000,3,8.783739e-001,0.000000e+000,,,,,,,,,,,,,,32,1,4.000000e+000,1.319885e-003,0.000000e+000,0,,0,
1524232597.173,,0.000000e+000,5.500103e+001,-2.954253e-006,0.000000e+000,3,8.711370e-001,0.000000e+000,,,,,,,,,,,,,,32,1,4.000000e+000,2.639771e-003,0.000000e+000,0,,0,
1524232635.643,,0.000000e+000,5.499708e+001,-2.856985e-006,0.000000e+000,3,8.971981e-001,0.000000e+000,,,,,,,,,,,,,,32,1,4.000000e+000,5.260468e-003,0.000000e+000,0,,0,
1524232673.893,,0.000000e+000,5.499380e+001,-2.791394e-006,0.000000e+000,3,8.758575e-001,0.000000e+000,,,,,,,,,,,,,,32,1,4.000000e+000,3.948212e-003,0.000000e+000,0,,0,
1524232711.614,,0.000000e+000,5.500169e+001,-2.659870e-006,0.000000e+000,3,8.637246e-001,0.000000e+000,,,,,,,,,,,,,,32,1,4.000000e+000,1.319885e-003,0.000000e+000,0,,0,
1524232749.744,,0.000000e+000,5.499051e+001,-2.501634e-006,0.000000e+000,3,8.596118e-001,0.000000e+000,,,,,,,,,,,,,,32,1,4.000000e+000,7.888794e-003,0.000000e+000,0,,0,
1524232787.824,,0.000000e+000,5.499773e+001,-2.483318e-006,0.000000e+000,3,8.448331e-001,0.000000e+000,,,,,,,,,,,,,,32,1,4.000000e+000,1.308441e-003,0.000000e+000,0,,0,
1524232825.074,,0.000000e+000,5.499839e+001,-2.495796e-006,0.000000e+000,3,8.503758e-001,0.000000e+000,,,,,,,,,,,,,,32,1,4.000000e+000,0.000000e+000,0.000000e+000,0,,0,
1524232862.924,,0.000000e+000,5.499643e+001,-2.379301e-006,0.000000e+000,3,8.388174e-001,0.000000e+000,,,,,,,,,,,,,,32,1,4.000000e+000,6.568909e-003,0.000000e+000,0,,0,
1524232900.644,,0.000000e+000,5.499248e+001,-2.388986e-006,0.000000e+000,3,8.420098e-001,0.000000e+000,,,,,,,,,,,,,,32,1,4.000000e+000,1.319885e-003,0.000000e+000,0,,0,
1524232938.534,,0.000000e+000,5.499840e+001,-2.232281e-006,0.000000e+000,3,8.023104e-001,0.000000e+000,,,,,,,,,,,,,,32,1,4.000000e+000,2.628326e-003,0.000000e+000,0,,0,
1524232981.388,,0.000000e+000,5.499971e+001,-5.953524e-007,0.000000e+000,2,0.000000e+000,0.000000e+000,,,,,,,,,,,,,,32,1,4.000000e+000,0.000000e+000,0.000000e+000,0,,0,
1524233025.264,,0.000000e+000,5.499971e+001,-5.299102e-007,0.000000e+000,2,0.000000e+000,0.000000e+000,,,,,,,,,,,,,,32,1,4.000000e+000,2.639771e-003,0.000000e+000,0,,0,
1524233067.760,,0.000000e+000,5.499643e+001,-4.080997e-007,0.000000e+000,2,0.000000e+000,0.000000e+000,,,,,,,,,,,,,,32,1,4.000000e+000,1.312256e-003,0.000000e+000,0,,0,
1524233108.614,,0.000000e+000,5.499840e+001,-3.578976e-007,0.000000e+000,2,0.000000e+000,0.000000e+000,,,,,,,,,,,,,,32,1,4.000000e+000,2.628326e-003,0.000000e+000,0,,0,
1524233145.644,,0.000000e+000,5.499971e+001,2.169607e-006,0.000000e+000,3,6.075943e-001,0.000000e+000,,,,,,,,,,,,,,32,1,4.000000e+000,0.000000e+000,0.000000e+000,0,,0,
1524233183.644,,0.000000e+000,5.499971e+001,2.119440e-006,0.000000e+000,3,6.545913e-001,0.000000e+000,,,,,,,,,,,,,,32,1,4.000000e+000,0.000000e+000,0.000000e+000,0,,0,
1524233220.794,,0.000000e+000,5.499577e+001,-2.257209e-006,0.000000e+000,3,7.317435e-001,0.000000e+000,,,,,,,,,,,,,,32,1,4.000000e+000,2.632141e-003,0.000000e+000,0,,0,
1524233260.166,,0.000000e+000,5.500037e+001,-2.220399e-006,0.000000e+000,3,7.487792e-001,0.000000e+000,,,,,,,,,,,,,,32,1,4.000000e+000,1.319885e-003,0.000000e+000,0,,0,
1524233299.238,,0.000000e+000,5.499511e+001,-5.518069e-008,0.000000e+000,2,0.000000e+000,0.000000e+000,,,,,,,,,,,,,,32,1,4.000000e+000,6.568909e-003,0.000000e+000,0,,0,
1524233336.458,,0.000000e+000,5.499840e+001,-2.313048e-006,0.000000e+000,3,7.174004e-001,0.000000e+000,,,,,,,,,,,,,,32,1,4.000000e+000,2.628326e-003,0.000000e+000,0,,0,
1524233374.338,,0.000000e+000,5.500366e+001,-2.315835e-006,0.000000e+000,3,7.708177e-001,0.000000e+000,,,,,,,,,,,,,,32,1,4.000000e+000,1.315689e-002,0.000000e+000,0,,0,
1524233416.563,,0.000000e+000,5.499774e+001,4.002564e-007,0.000000e+000,2,0.000000e+000,0.000000e+000,,,,,,,,,,,,,,32,1,4.000000e+000,3.940582e-003,0.000000e+000,0,,0,
1524233459.779,,0.000000e+000,5.499380e+001,3.945914e-007,0.000000e+000,2,0.000000e+000,0.000000e+000,,,,,,,,,,,,,,32,1,4.000000e+000,3.948212e-003,0.000000e+000,0,,0,
1524233503.115,,0.000000e+000,5.499971e+001,4.876044e-007,0.000000e+000,2,0.000000e+000,0.000000e+000,,,,,,,,,,,,,,32,1,4.000000e+000,2.639771e-003,0.000000e+000,0,,0,
1524233545.161,,0.000000e+000,5.499905e+001,5.479885e-007,0.000000e+000,2,0.000000e+000,0.000000e+000,,,,,,,,,,,,,,32,1,4.000000e+000,1.319885e-003,0.000000e+000,0,,0,
1524233587.157,,0.000000e+000,5.499905e+001,6.356873e-007,0.000000e+000,2,0.000000e+000,0.000000e+000,,,,,,,,,,,,,,32,1,4.000000e+000,3.948212e-003,0.000000e+000,0,,0,
1524233637.047,,0.000000e+000,5.499905e+001,2.122388e-006,0.000000e+000,3,6.858184e-001,0.000000e+000,,,,,,,,,,,,,,32,1,4.000000e+000,1.319885e-003,0.000000e+000,0,,0,
1524233674.647,,0.000000e+000,5.500497e+001,2.026904e-006,0.000000e+000,3,7.158690e-001,0.000000e+000,,,,,,,,,,,,,,32,1,4.000000e+000,1.578903e-002,0.000000e+000,0,,0,
1524233712.157,,0.000000e+000,5.499445e+001,2.122250e-006,0.000000e+000,3,6.984696e-001,0.000000e+000,,,,,,,,,,,,,,32,1,4.000000e+000,2.628326e-003,0.000000e+000,0,,0,
1524233750.207,,0.000000e+000,5.500169e+001,2.096739e-006,0.000000e+000,3,7.291804e-001,0.000000e+000,,,,,,,,,,,,,,32,1,4.000000e+000,3.959656e-003,0.000000e+000,0,,0,
1524233788.757,,0.000000e+000,5.498853e+001,2.179941e-006,0.000000e+000,3,7.098569e-001,0.000000e+000,,,,,,,,,,,,,,32,1,4.000000e+000,1.308441e-003,0.000000e+000,0,,0,
1524233826.897,,0.000000e+000,5.499840e+001,2.271838e-006,0.000000e+000,3,6.930712e-001,0.000000e+000,,,,,,,,,,,,,,32,1,4.000000e+000,2.628326e-003,0.000000e+000,0,,0,
1524233864.797,,0.000000e+000,5.499511e+001,2.156961e-006,0.000000e+000,3,7.030522e-001,0.000000e+000,,,,,,,,,,,,,,32,1,4.000000e+000,3.940582e-003,0.000000e+000,0,,0,
1524233902.607,,0.000000e+000,5.499643e+001,2.267320e-006,0.000000e+000,3,7.269607e-001,0.000000e+000,,,,,,,,,,,,,,32,1,4.000000e+000,6.568909e-003,0.000000e+000,0,,0,
1524233939.857,,0.000000e+000,5.499511e+001,2.109960e-006,0.000000e+000,3,7.232809e-001,0.000000e+000,,,,,,,,,,,,,,32,1,4.000000e+000,1.319885e-003,0.000000e+000,0,,0,
1524233977.447,,0.000000e+000,5.499972e+001,2.242291e-006,0.000000e+000,3,7.254256e-001,0.000000e+000,,,,,,,,,,,,,,32,1,4.000000e+000,5.268097e-003,0.000000e+000,0,,0,
1524234015.477,,0.000000e+000,5.499511e+001,2.134682e-006,0.000000e+000,3,7.339078e-001,0.000000e+000,,,,,,,,,,,,,,32,1,4.000000e+000,3.940582e-003,0.000000e+000,0,,0,
1524234053.057,,0.000000e+000,5.499708e+001,2.126241e-006,0.000000e+000,3,7.179459e-001,0.000000e+000,,,,,,,,,,,,,,32,1,4.000000e+000,5.260468e-003,0.000000e+000,0,,0,
1524234091.127,,0.000000e+000,5.499774e+001,2.113475e-006,0.000000e+000,3,7.390333e-001,0.000000e+000,,,,,,,,,,,,,,32,1,4.000000e+000,3.940582e-003,0.000000e+000,0,,0,
1524234128.688,,0.000000e+000,5.499314e+001,2.203525e-006,0.000000e+000,3,7.297778e-001,0.000000e+000,,,,,,,,,,,,,,32,1,4.000000e+000,5.260468e-003,0.000000e+000,0,,0,
1524234166.718,,0.000000e+000,5.499511e+001,2.167871e-006,0.000000e+000,3,7.407126e-001,0.000000e+000,,,,,,,,,,,,,,32,1,4.000000e+000,1.319885e-003,0.000000e+000,0,,0,
1524234204.318,,0.000000e+000,5.499511e+001,2.257295e-006,0.000000e+000,3,7.194054e-001,0.000000e+000,,,,,,,,,,,,,,32,1,4.000000e+000,6.568909e-003,0.000000e+000,0,,0,
1524234242.378,,0.000000e+000,5.500103e+001,2.183126e-006,0.000000e+000,3,7.496436e-001,0.000000e+000,,,,,,,,,,,,,,32,1,4.000000e+000,5.279541e-003,0.000000e+000,0,,0,
1524234280.838,,0.000000e+000,5.500300e+001,2.288414e-006,0.000000e+000,3,7.755024e-001,0.000000e+000,,,,,,,,,,,,,,32,1,4.000000e+000,1.183701e-002,0.000000e+000,0,,0,
1524234318.248,,0.000000e+000,5.499773e+001,2.335671e-006,0.000000e+000,3,7.722995e-001,0.000000e+000,,,,,,,,,,,,,,32,1,4.000000e+000,1.308441e-003,0.000000e+000,0,,0,
1524234355.898,,0.000000e+000,5.499511e+001,2.340982e-006,0.000000e+000,3,7.532537e-001,0.000000e+000,,,,,,,,,,,,,,32,1,4.000000e+000,1.319885e-003,0.000000e+000,0,,0,
1524234393.878,,0.000000e+000,5.500301e+001,2.326168e-006,0.000000e+000,3,7.804062e-001,0.000000e+000,,,,,,,,,,,,,,32,1,4.000000e+000,1.319885e-003,0.000000e+000,0,,0,
1524234432.028,,0.000000e+000,5.499774e+001,2.430982e-006,0.000000e+000,3,7.726782e-001,0.000000e+000,,,,,,,,,,,,,,32,1,4.000000e+000,3.940582e-003,0.000000e+000,0,,0,
1524234469.228,,0.000000e+000,5.499511e+001,2.395927e-006,0.000000e+000,3,7.814348e-001,0.000000e+000,,,,,,,,,,,,,,32,1,4.000000e+000,3.940582e-003,0.000000e+000,0,,0,
1524234507.028,,0.000000e+000,5.499840e+001,2.485682e-006,0.000000e+000,3,7.892404e-001,0.000000e+000,,,,,,,,,,,,,,32,1,4.000000e+000,2.628326e-003,0.000000e+000,0,,0,
1524234544.258,,0.000000e+000,5.499774e+001,2.360534e-006,0.000000e+000,3,7.894852e-001,0.000000e+000,,,,,,,,,,,,,,32,1,4.000000e+000,3.940582e-003,0.000000e+000,0,,0,
1524234582.098,,0.000000e+000,5.499445e+001,2.512646e-006,0.000000e+000,3,7.942282e-001,0.000000e+000,,,,,,,,,,,,,,32,1,4.000000e+000,0.000000e+000,0.000000e+000,0,,0,
1524234619.528,,0.000000e+000,5.500169e+001,2.442474e-006,0.000000e+000,3,7.869377e-001,0.000000e+000,,,,,,,,,,,,,,32,1,4.000000e+000,1.319885e-003,0.000000e+000,0,,0,
1524234657.688,,0.000000e+000,5.499708e+001,2.464072e-006,0.000000e+000,3,8.068119e-001,0.000000e+000,,,,,,,,,,,,,,32,1,4.000000e+000,5.260468e-003,0.000000e+000,0,,0,
1524234695.368,,0.000000e+000,5.499972e+001,2.551913e-006,0.000000e+000,3,7.733931e-001,0.000000e+000,,,,,,,,,,,,,,32,1,4.000000e+000,5.268097e-003,0.000000e+000,0,,0,
1524234733.298,,0.000000e+000,5.499445e+001,2.486834e-006,0.000000e+000,3,8.079998e-001,0.000000e+000,,,,,,,,,,,,,,32,1,4.000000e+000,5.260468e-003,0.000000e+000,0,,0,
1524234770.968,,0.000000e+000,5.499642e+001,2.545391e-006,0.000000e+000,3,7.774790e-001,0.000000e+000,,,,,,,,,,,,,,32,1,4.000000e+000,3.940582e-003,0.000000e+000,0,,0,
1524234808.928,,0.000000e+000,5.500037e+001,2.516662e-006,0.000000e+000,3,7.975456e-001,0.000000e+000,,,,,,,,,,,,,,32,1,4.000000e+000,3.959656e-003,0.000000e+000,0,,0,
1524234846.379,,0.000000e+000,5.499840e+001,2.581620e-006,0.000000e+000,3,7.885390e-001,0.000000e+000,,,,,,,,,,,,,,32,1,4.000000e+000,2.628326e-003,0.000000e+000,0,,0,
1524234883.899,,0.000000e+000,5.499313e+001,2.585434e-006,0.000000e+000,3,8.049392e-001,0.000000e+000,,,,,,,,,,,,,,32,1,4.000000e+000,2.628326e-003,0.000000e+000,0,,0,
1524234921.599,,0.000000e+000,5.499906e+001,2.528240e-006,0.000000e+000,3,8.205466e-001,0.000000e+000,,,,,,,,,,,,,,32,1,4.000000e+000,9.220123e-003,0.000000e+000,0,,0,
1524234959.549,,0.000000e+000,5.499642e+001,2.642763e-006,0.000000e+000,3,8.034175e-001,0.000000e+000,,,,,,,,,,,,,,32,1,4.000000e+000,3.940582e-003,0.000000e+000,0,,0,
1524234997.469,,0.000000e+000,5.500037e+001,2.574895e-006,0.000000e+000,3,8.105673e-001,0.000000e+000,,,,,,,,,,,,,,32,1,4.000000e+000,6.587982e-003,0.000000e+000,0,,0,
1524235035.059,,0.000000e+000,5.499577e+001,2.607226e-006,0.000000e+000,3,7.968791e-001,0.000000e+000,,,,,,,,,,,,,,32,1,4.000000e+000,5.249023e-003,0.000000e+000,0,,0,
1524235073.099,,0.000000e+000,5.499773e+001,2.593372e-006,0.000000e+000,3,7.964000e-001,0.000000e+000,,,,,,,,,,,,,,32,1,4.000000e+000,1.308441e-003,0.000000e+000,0,,0,
1524235111.009,,0.000000e+000,5.499775e+001,2.693695e-006,0.000000e+000,3,7.994769e-001,0.000000e+000,,,,,,,,,,,,,,32,1,4.000000e+000,9.208679e-003,0.000000e+000,0,,0,
1524235148.699,,0.000000e+000,5.499577e+001,2.628177e-006,0.000000e+000,3,8.140033e-001,0.000000e+000,,,,,,,,,,,,,,32,1,4.000000e+000,2.632141e-003,0.000000e+000,0,,0,
1524235186.399,,0.000000e+000,5.500103e+001,2.717949e-006,0.000000e+000,3,8.038825e-001,0.000000e+000,,,,,,,,,,,,,,32,1,4.000000e+000,2.639771e-003,0.000000e+000,0,,0,
1524235224.349,,0.000000e+000,5.499642e+001,2.657421e-006,0.000000e+000,3,8.329527e-001,0.000000e+000,,,,,,,,,,,,,,32,1,4.000000e+000,3.940582e-003,0.000000e+000,0,,0,
1524235261.989,,0.000000e+000,5.499643e+001,2.740858e-006,0.000000e+000,3,7.960555e-001,0.000000e+000,,,,,,,,,,,,,,32,1,4.000000e+000,1.312256e-003,0.000000e+000,0,,0,
1524235299.939,,0.000000e+000,5.499577e+001,2.788699e-006,0.000000e+000,3,8.530993e-001,0.000000e+000,,,,,,,,,,,,,,32,1,4.000000e+000,2.632141e-003,0.000000e+000,0,,0,
1524235337.269,,0.000000e+000,5.499643e+001,2.732008e-006,0.000000e+000,3,8.137176e-001,0.000000e+000,,,,,,,,,,,,,,32,1,4.000000e+000,6.568909e-003,0.000000e+000,0,,0,
1524235375.239,,0.000000e+000,5.500037e+001,2.684305e-006,0.000000e+000,3,8.175716e-001,0.000000e+000,,,,,,,,,,,,,,32,1,4.000000e+000,1.709747e-002,0.000000e+000,0,,0,
1524235412.829,,0.000000e+000,5.500498e+001,2.756142e-006,0.000000e+000,3,8.423195e-001,0.000000e+000,,,,,,,,,,,,,,32,1,4.000000e+000,5.260468e-003,0.000000e+000,0,,0,
1524235450.149,,0.000000e+000,5.499445e+001,2.734198e-006,0.000000e+000,3,8.171318e-001,0.000000e+000,,,,,,,,,,,,,,32,1,4.000000e+000,7.881165e-003,0.000000e+000,0,,0,
1524235487.889,,0.000000e+000,5.499709e+001,2.842678e-006,0.000000e+000,3,8.290243e-001,0.000000e+000,,,,,,,,,,,,,,32,1,4.000000e+000,7.888794e-003,0.000000e+000,0,,0,
1524235525.169,,0.000000e+000,5.499971e+001,2.775273e-006,0.000000e+000,3,8.470936e-001,0.000000e+000,,,,,,,,,,,,,,32,1,4.000000e+000,2.639771e-003,0.000000e+000,0,,0,
1524235562.810,,0.000000e+000,5.499774e+001,2.837315e-006,0.000000e+000,3,8.051558e-001,0.000000e+000,,,,,,,,,,,,,,32,1,4.000000e+000,6.580353e-003,0.000000e+000,0,,0,
1524235600.840,,0.000000e+000,5.500365e+001,2.785600e-006,0.000000e+000,3,8.376181e-001,0.000000e+000,,,,,,,,,,,,,,32,1,4.000000e+000,1.052856e-002,0.000000e+000,0,,0,
1524235638.440,,0.000000e+000,5.499445e+001,2.875130e-006,0.000000e+000,3,8.257370e-001,0.000000e+000,,,,,,,,,,,,,,32,1,4.000000e+000,7.881165e-003,0.000000e+000,0,,0,
1524235676.460,,0.000000e+000,5.499971e+001,2.805387e-006,0.000000e+000,3,8.267225e-001,0.000000e+000,,,,,,,,,,,,,,32,1,4.000000e+000,2.639771e-003,0.000000e+000,0,,0,
1524235714.060,,0.000000e+000,5.499248e+001,2.903124e-006,0.000000e+000,3,8.230871e-001,0.000000e+000,,,,,,,,,,,,,,32,1,4.000000e+000,1.182938e-002,0.000000e+000,0,,0,
1524235752.090,,0.000000e+000,5.500103e+001,2.816811e-006,0.000000e+000,3,8.334023e-001,0.000000e+000,,,,,,,,,,,,,,32,1,4.000000e+000,2.639771e-003,0.000000e+000,0,,0,
1524235789.700,,0.000000e+000,5.499840e+001,2.815384e-006,0.000000e+000,3,8.252852e-001,0.000000e+000,,,,,,,,,,,,,,32,1,4.000000e+000,7.900238e-003,0.000000e+000,0,,0,
1524235827.190,,0.000000e+000,5.499905e+001,2.872220e-006,0.000000e+000,3,8.633918e-001,0.000000e+000,,,,,,,,,,,,,,32,1,4.000000e+000,1.319885e-003,0.000000e+000,0,,0,
1524235864.780,,0.000000e+000,5.498985e+001,2.851130e-006,0.000000e+000,3,8.289031e-001,0.000000e+000,,,,,,,,,,,,,,32,1,4.000000e+000,9.201050e-003,0.000000e+000,0,,0,
1524235902.840,,0.000000e+000,5.499313e+001,2.873917e-006,0.000000e+000,3,8.424821e-001,0.000000e+000,,,,,,,,,,,,,,32,1,4.000000e+000,1.050949e-002,0.000000e+000,0,,0,
1524235940.410,,0.000000e+000,5.499839e+001,2.923067e-006,0.000000e+000,3,8.395011e-001,0.000000e+000,,,,,,,,,,,,,,32,1,4.000000e+000,0.000000e+000,0.000000e+000,0,,0,
1524235978.420,,0.000000e+000,5.500563e+001,2.876393e-006,0.000000e+000,3,8.406961e-001,0.000000e+000,,,,,,,,,,,,,,32,1,4.000000e+000,6.568909e-003,0.000000e+000,0,,0,
1524236016.950,,0.000000e+000,5.499446e+001,2.912004e-006,0.000000e+000,3,8.441558e-001,0.000000e+000,,,,,,,,,,,,,,32,1,4.000000e+000,1.842117e-002,0.000000e+000,0,,0,
1524236054.220,,0.000000e+000,5.499774e+001,2.903783e-006,0.000000e+000,3,8.443108e-001,0.000000e+000,,,,,,,,,,,,,,32,1,4.000000e+000,6.580353e-003,0.000000e+000,0,,0,
1524236092.530,,0.000000e+000,5.499905e+001,2.897560e-006,0.000000e+000,3,8.580027e-001,0.000000e+000,,,,,,,,,,,,,,32,1,4.000000e+000,1.319885e-003,0.000000e+000,0,,0,
1524236129.860,,0.000000e+000,5.499643e+001,2.926829e-006,0.000000e+000,3,8.545547e-001,0.000000e+000,,,,,,,,,,,,,,32,1,4.000000e+000,9.208679e-003,0.000000e+000,0,,0,
1524236167.670,,0.000000e+000,5.499577e+001,2.956967e-006,0.000000e+000,3,8.560855e-001,0.000000e+000,,,,,,,,,,,,,,32,1,4.000000e+000,2.632141e-003,0.000000e+000,0,,0,
1524236205.470,,0.000000e+000,5.499511e+001,2.935546e-006,0.000000e+000,3,8.460842e-001,0.000000e+000,,,,,,,,,,,,,,32,1,4.000000e+000,6.568909e-003,0.000000e+000,0,,0,
1524236243.840,,0.000000e+000,5.499380e+001,2.891444e-006,0.000000e+000,3,8.557310e-001,0.000000e+000,,,,,,,,,,,,,,32,1,4.000000e+000,3.948212e-003,0.000000e+000,0,,0,
1524236281.351,,0.000000e+000,5.500103e+001,3.006690e-006,0.000000e+000,3,8.329532e-001,0.000000e+000,,,,,,,,,,,,,,32,1,4.000000e+000,0.000000e+000,0.000000e+000,0,,0,
1524236319.281,,0.000000e+000,5.499708e+001,2.921157e-006,0.000000e+000,3,8.644419e-001,0.000000e+000,,,,,,,,,,,,,,32,1,4.000000e+000,5.260468e-003,0.000000e+000,0,,0,
1524236356.941,,0.000000e+000,5.499709e+001,3.015514e-006,0.000000e+000,3,8.428175e-001,0.000000e+000,,,,,,,,,,,,,,32,1,4.000000e+000,1.052856e-002,0.000000e+000,0,,0,
1524236394.891,,0.000000e+000,5.499708e+001,2.948563e-006,0.000000e+000,3,8.677090e-001,0.000000e+000,,,,,,,,,,,,,,32,1,4.000000e+000,5.260468e-003,0.000000e+000,0,,0,
1524236432.361,,0.000000e+000,5.499839e+001,3.007942e-006,0.000000e+000,3,8.501485e-001,0.000000e+000,,,,,,,,,,,,,,32,1,4.000000e+000,0.000000e+000,0.000000e+000,0,,0,
1524236470.671,,0.000000e+000,5.500169e+001,3.047159e-006,0.000000e+000,3,8.572186e-001,0.000000e+000,,,,,,,,,,,,,,32,1,4.000000e+000,9.208679e-003,0.000000e+000,0,,0,
1524236508.891,,0.000000e+000,5.499708e+001,3.011401e-006,0.000000e+000,3,8.643757e-001,0.000000e+000,,,,,,,,,,,,,,32,1,4.000000e+000,5.260468e-003,0.000000e+000,0,,0,
1524236546.431,,0.000000e+000,5.499773e+001,3.035432e-006,0.000000e+000,3,8.476290e-001,0.000000e+000,,,,,,,,,,,,,,32,1,4.000000e+000,1.308441e-003,0.000000e+000,0,,0,
1524236583.801,,0.000000e+000,5.499774e+001,3.026366e-006,0.000000e+000,3,8.518574e-001,0.000000e+000,,,,,,,,,,,,,,32,1,4.000000e+000,6.580353e-003,0.000000e+000,0,,0,
1524236621.891,,0.000000e+000,5.499972e+001,3.022131e-006,0.000000e+000,3,8.722503e-001,0.000000e+000,,,,,,,,,,,,,,32,1,4.000000e+000,7.900238e-003,0.000000e+000,0,,0,
1524236658.941,,0.000000e+000,5.499577e+001,3.096571e-006,0.000000e+000,3,8.687876e-001,0.000000e+000,,,,,,,,,,,,,,32,1,4.000000e+000,0.000000e+000,0.000000e+000,0,,0,
1524236696.151,,0.000000e+000,5.499972e+001,3.138870e-006,0.000000e+000,3,8.743090e-001,0.000000e+000,,,,,,,,,,,,,,32,1,4.000000e+000,7.900238e-003,0.000000e+000,0,,0,
1524236733.581,,0.000000e+000,5.499642e+001,3.113836e-006,0.000000e+000,3,8.906262e-001,0.000000e+000,,,,,,,,,,,,,,32,1,4.000000e+000,3.940582e-003,0.000000e+000,0,,0,
1524236771.481,,0.000000e+000,5.499512e+001,3.149309e-006,0.000000e+000,3,8.562802e-001,0.000000e+000,,,,,,,,,,,,,,32,1,4.000000e+000,1.446915e-002,0.000000e+000,0,,0,
1524236809.641,,0.000000e+000,5.499774e+001,3.164671e-006,0.000000e+000,3,8.503621e-001,0.000000e+000,,,,,,,,,,,,,,32,1,4.000000e+000,6.580353e-003,0.000000e+000,0,,0,
1524236847.601,,0.000000e+000,5.500431e+001,3.119049e-006,0.000000e+000,3,8.635127e-001,0.000000e+000,,,,,,,,,,,,,,32,1,4.000000e+000,1.184845e-002,0.000000e+000,0,,0,
1524236885.041,,0.000000e+000,5.499906e+001,3.216271e-006,0.000000e+000,3,8.445687e-001,0.000000e+000,,,,,,,,,,,,,,32,1,4.000000e+000,9.220123e-003,0.000000e+000,0,,0,
1524236923.201,,0.000000e+000,5.500103e+001,3.159325e-006,0.000000e+000,3,8.618795e-001,0.000000e+000,,,,,,,,,,,,,,32,1,4.000000e+000,0.000000e+000,0.000000e+000,0,,0,
1524236961.051,,0.000000e+000,5.499971e+001,3.175622e-006,0.000000e+000,3,8.685865e-001,0.000000e+000,,,,,,,,,,,,,,32,1,4.000000e+000,2.639771e-003,0.000000e+000,0,,0,
1524236999.212,,0.000000e+000,5.499774e+001,3.207728e-006,0.000000e+000,3,8.599591e-001,0.000000e+000,,,,,,,,,,,,,,32,1,4.000000e+000,3.940582e-003,0.000000e+000,0,,0,
1524237037.162,,0.000000e+000,5.499708e+001,3.147088e-006,0.000000e+000,3,8.819209e-001,0.000000e+000,,,,,,,,,,,,,,32,1,4.000000e+000,2.620697e-003,0.000000e+000,0,,0,
1524237074.292,,0.000000e+000,5.499971e+001,3.258436e-006,0.000000e+000,3,8.550526e-001,0.000000e+000,,,,,,,,,,,,,,32,1,4.000000e+000,2.639771e-003,0.000000e+000,0,,0,
1524237111.832,,0.000000e+000,5.499379e+001,3.278951e-006,0.000000e+000,3,8.961625e-001,0.000000e+000,,,,,,,,,,,,,,32,1,4.000000e+000,9.201050e-003,0.000000e+000,0,,0,
1524237150.152,,0.000000e+000,5.499708e+001,3.182302e-006,0.000000e+000,3,8.945560e-001,0.000000e+000,,,,,,,,,,,,,,32,1,4.000000e+000,2.620697e-003,0.000000e+000,0,,0,
1524237188.342,,0.000000e+000,5.499905e+001,3.197062e-006,0.000000e+000,3,8.533533e-001,0.000000e+000,,,,,,,,,,,,,,32,1,4.000000e+000,1.319885e-003,0.000000e+000,0,,0,
1524237226.232,,0.000000e+000,5.499709e+001,3.084198e-006,0.000000e+000,3,8.727601e-001,0.000000e+000,,,,,,,,,,,,,,32,1,4.000000e+000,1.316071e-002,0.000000e+000,0,,0,
1524237263.742,,0.000000e+000,5.499248e+001,3.241989e-006,0.000000e+000,3,8.562726e-001,0.000000e+000,,,,,,,,,,,,,,32,1,4.000000e+000,3.940582e-003,0.000000e+000,0,,0,
1524237300.942,,0.000000e+000,5.499248e+001,3.194938e-006,0.000000e+000,3,8.642632e-001,0.000000e+000,,,,,,,,,,,,,,32,1,4.000000e+000,1.182938e-002,0.000000e+000,0,,0,
1524237339.292,,0.000000e+000,5.500629e+001,3.203779e-006,0.000000e+000,3,8.733346e-001,0.000000e+000,,,,,,,,,,,,,,32,1,4.000000e+000,1.052094e-002,0.000000e+000,0,,0,
1524237376.562,,0.000000e+000,5.499774e+001,3.185583e-006,0.000000e+000,3,8.674036e-001,0.000000e+000,,,,,,,,,,,,,,32,1,4.000000e+000,3.940582e-003,0.000000e+000,0,,0,
1524237414.392,,0.000000e+000,5.499577e+001,3.144512e-006,0.000000e+000,3,8.805791e-001,0.000000e+000,,,,,,,,,,,,,,32,1,4.000000e+000,0.000000e+000,0.000000e+000,0,,0,
1524237452.182,,0.000000e+000,5.499248e+001,3.204065e-006,0.000000e+000,3,8.696378e-001,0.000000e+000,,,,,,,,,,,,,,32,1,4.000000e+000,3.940582e-003,0.000000e+000,0,,0,
1524237490.442,,0.000000e+000,5.500301e+001,3.165629e-006,0.000000e+000,3,8.800516e-001,0.000000e+000,,,,,,,,,,,,,,32,1,4.000000e+000,1.319885e-003,0.000000e+000,0,,0,
1524237528.692,,0.000000e+000,5.499972e+001,3.284875e-006,0.000000e+000,3,8.658717e-001,0.000000e+000,,,,,,,,,,,,,,32,1,4.000000e+000,5.268097e-003,0.000000e+000,0,,0,
1524237566.582,,0.000000e+000,5.499840e+001,3.256057e-006,0.000000e+000,3,8.742579e-001,0.000000e+000,,,,,,,,,,,,,,32,1,4.000000e+000,2.628326e-003,0.000000e+000,0,,0,
1524237604.482,,0.000000e+000,5.499643e+001,3.251723e-006,0.000000e+000,3,8.726636e-001,0.000000e+000,,,,,,,,,,,,,,32,1,4.000000e+000,1.312256e-003,0.000000e+000,0,,0,
1524237642.252,,0.000000e+000,5.499972e+001,3.286282e-006,0.000000e+000,3,8.762685e-001,0.000000e+000,,,,,,,,,,,,,,32,1,4.000000e+000,7.900238e-003,0.000000e+000,0,,0,
1524237680.012,,0.000000e+000,5.499774e+001,3.219321e-006,0.000000e+000,3,8.726435e-001,0.000000e+000,,,,,,,,,,,,,,32,1,4.000000e+000,3.940582e-003,0.000000e+000,0,,0,
1524237716.933,,0.000000e+000,5.499511e+001,3.307679e-006,0.000000e+000,3,8.590654e-001,0.000000e+000,,,,,,,,,,,,,,32,1,4.000000e+000,1.319885e-003,0.000000e+000,0,,0,
1524237754.543,,0.000000e+000,5.500103e+001,3.267707e-006,0.000000e+000,3,8.783360e-001,0.000000e+000,,,,,,,,,,,,,,32,1,4.000000e+000,5.279541e-003,0.000000e+000,0,,0,
1524237791.653,,0.000000e+000,5.499972e+001,3.347547e-006,0.000000e+000,3,8.599491e-001,0.000000e+000,,,,,,,,,,,,,,32,1,4.000000e+000,5.268097e-003,0.000000e+000,0,,0,
1524237829.623,,0.000000e+000,5.499773e+001,3.303863e-006,0.000000e+000,3,8.789803e-001,0.000000e+000,,,,,,,,,,,,,,32,1,4.000000e+000,1.308441e-003,0.000000e+000,0,,0,
1524237867.283,,0.000000e+000,5.499577e+001,3.333378e-006,0.000000e+000,3,8.633682e-001,0.000000e+000,,,,,,,,,,,,,,32,1,4.000000e+000,0.000000e+000,0.000000e+000,0,,0,
1524237905.243,,0.000000e+000,5.499840e+001,3.346034e-006,0.000000e+000,3,8.886011e-001,0.000000e+000,,,,,,,,,,,,,,32,1,4.000000e+000,1.314926e-002,0.000000e+000,0,,0,
1524237942.873,,0.000000e+000,5.499708e+001,3.358945e-006,0.000000e+000,3,8.721548e-001,0.000000e+000,,,,,,,,,,,,,,32,1,4.000000e+000,2.620697e-003,0.000000e+000,0,,0,
1524237980.753,,0.000000e+000,5.499905e+001,3.283560e-006,0.000000e+000,3,8.718008e-001,0.000000e+000,,,,,,,,,,,,,,32,1,4.000000e+000,3.948212e-003,0.000000e+000,0,,0,
1524238019.223,,0.000000e+000,5.499773e+001,3.347480e-006,0.000000e+000,3,8.820757e-001,0.000000e+000,,,,,,,,,,,,,,32,1,4.000000e+000,1.308441e-003,0.000000e+000,0,,0,
1524238057.023,,0.000000e+000,5.499840e+001,3.375834e-006,0.000000e+000,3,8.798474e-001,0.000000e+000,,,,,,,,,,,,,,32,1,4.000000e+000,2.628326e-003,0.000000e+000,0,,0,
1524238094.653,,0.000000e+000,5.500432e+001,3.315866e-006,0.000000e+000,3,8.798782e-001,0.000000e+000,,,,,,,,,,,,,,32,1,4.000000e+000,3.940582e-003,0.000000e+000,0,,0,
1524238132.803,,0.000000e+000,5.499708e+001,3.322809e-006,0.000000e+000,3,8.754863e-001,0.000000e+000,,,,,,,,,,,,,,32,1,4.000000e+000,2.620697e-003,0.000000e+000,0,,0,
1524238170.943,,0.000000e+000,5.499773e+001,3.328050e-006,0.000000e+000,3,8.606836e-001,0.000000e+000,,,,,,,,,,,,,,32,1,4.000000e+000,1.308441e-003,0.000000e+000,0,,0,
1524238208.863,,0.000000e+000,5.499577e+001,3.314957e-006,0.000000e+000,3,8.871193e-001,0.000000e+000,,,,,,,,,,,,,,32,1,4.000000e+000,5.249023e-003,0.000000e+000,0,,0,
1524238247.333,,0.000000e+000,5.500234e+001,3.364923e-006,0.000000e+000,3,8.948160e-001,0.000000e+000,,,,,,,,,,,,,,32,1,4.000000e+000,5.260468e-003,0.000000e+000,0,,0,
1524238284.853,,0.000000e+000,5.499708e+001,3.445376e-006,0.000000e+000,3,8.909291e-001,0.000000e+000,,,,,,,,,,,,,,32,1,4.000000e+000,2.620697e-003,0.000000e+000,0,,0,
1524238323.003,,0.000000e+000,5.499183e+001,3.350845e-006,0.000000e+000,3,8.841017e-001,0.000000e+000,,,,,,,,,,,,,,32,1,4.000000e+000,2.632141e-003,0.000000e+000,0,,0,
1524238360.953,,0.000000e+000,5.500169e+001,3.305444e-006,0.000000e+000,3,8.786103e-001,0.000000e+000,,,,,,,,,,,,,,32,1,4.000000e+000,1.319885e-003,0.000000e+000,0,,0,
1524238398.804,,0.000000e+000,5.499708e+001,3.411770e-006,0.000000e+000,3,8.724707e-001,0.000000e+000,,,,,,,,,,,,,,32,1,4.000000e+000,2.620697e-003,0.000000e+000,0,,0,
1524238436.604,,0.000000e+000,5.499775e+001,3.392104e-006,0.000000e+000,3,8.800434e-001,0.000000e+000,,,,,,,,,,,,,,32,1,4.000000e+000,9.208679e-003,0.000000e+000,0,,0,
1524238473.924,,0.000000e+000,5.499839e+001,3.432016e-006,0.000000e+000,3,8.771828e-001,0.000000e+000,,,,,,,,,,,,,,32,1,4.000000e+000,0.000000e+000,0.000000e+000,0,,0,
1524238511.324,,0.000000e+000,5.500037e+001,3.363143e-006,0.000000e+000,3,8.868753e-001,0.000000e+000,,,,,,,,,,,,,,32,1,4.000000e+000,1.319885e-003,0.000000e+000,0,,0,
1524238548.624,,0.000000e+000,5.499642e+001,3.445359e-006,0.000000e+000,3,8.669493e-001,0.000000e+000,,,,,,,,,,,,,,32,1,4.000000e+000,3.940582e-003,0.000000e+000,0,,0,
1524238586.584,,0.000000e+000,5.499643e+001,3.369955e-006,0.000000e+000,3,8.754342e-001,0.000000e+000,,,,,,,,,,,,,,32,1,4.000000e+000,1.312256e-003,0.000000e+000,0,,0,
1524238624.174,,0.000000e+000,5.500169e+001,3.409102e-006,0.000000e+000,3,8.913241e-001,0.000000e+000,,,,,,,,,,,,,,32,1,4.000000e+000,3.959656e-003,0.000000e+000,0,,0,
1524238661.624,,0.000000e+000,5.499972e+001,3.400390e-006,0.000000e+000,3,8.753359e-001,0.000000e+000,,,,,,,,,,,,,,32,1,4.000000e+000,5.268097e-003,0.000000e+000,0,,0,
1524238699.424,,0.000000e+000,5.500234e+001,3.382282e-006,0.000000e+000,3,8.826278e-001,0.000000e+000,,,,,,,,,,,,,,32,1,4.000000e+000,7.900238e-003,0.000000e+000,0,,0,
1524238737.484,,0.000000e+000,5.499840e+001,3.418601e-006,0.000000e+000,3,8.712325e-001,0.000000e+000,,,,,,,,,,,,,,32,1,4.000000e+000,5.260468e-003,0.000000e+000,0,,0,
1524238775.234,,0.000000e+000,5.499774e+001,3.290425e-006,0.000000e+000,3,8.904625e-001,0.000000e+000,,,,,,,,,,,,,,32,1,4.000000e+000,6.580353e-003,0.000000e+000,0,,0,
1524238812.554,,0.000000e+000,5.499709e+001,3.449049e-006,0.000000e+000,3,8.702046e-001,0.000000e+000,,,,,,,,,,,,,,32,1,4.000000e+000,7.888794e-003,0.000000e+000,0,,0,
1524238850.974,,0.000000e+000,5.499906e+001,3.497594e-006,0.000000e+000,3,8.712764e-001,0.000000e+000,,,,,,,,,,,,,,32,1,4.000000e+000,6.580353e-003,0.000000e+000,0,,0,
1524238888.884,,0.000000e+000,5.499577e+001,3.406893e-006,0.000000e+000,3,8.869897e-001,0.000000e+000,,,,,,,,,,,,,,32,1,4.000000e+000,2.632141e-003,0.000000e+000,0,,0,
1524238926.284,,0.000000e+000,5.499512e+001,3.480433e-006,0.000000e+000,3,8.672525e-001,0.000000e+000,,,,,,,,,,,,,,32,1,4.000000e+000,1.446915e-002,0.000000e+000,0,,0,
1524238964.494,,0.000000e+000,5.499906e+001,3.433493e-006,0.000000e+000,3,8.833467e-001,0.000000e+000,,,,,,,,,,,,,,32,1,4.000000e+000,6.580353e-003,0.000000e+000,0,,0,
1524239001.624,,0.000000e+000,5.499840e+001,3.490542e-006,0.000000e+000,3,8.695775e-001,0.000000e+000,,,,,,,,,,,,,,32,1,4.000000e+000,2.628326e-003,0.000000e+000,0,,0,
1524239039.354,,0.000000e+000,5.499511e+001,3.419280e-006,0.000000e+000,3,8.824945e-001,0.000000e+000,,,,,,,,,,,,,,32,1,4.000000e+000,9.201050e-003,0.000000e+000,0,,0,
1524239076.484,,0.000000e+000,5.500103e+001,3.483540e-006,0.000000e+000,3,8.748705e-001,0.000000e+000,,,,,,,,,,,,,,32,1,4.000000e+000,7.888794e-003,0.000000e+000,0,,0,
1524239114.625,,0.000000e+000,5.499774e+001,3.511456e-006,0.000000e+000,3,8.937272e-001,0.000000e+000,,,,,,,,,,,,,,32,1,4.000000e+000,3.940582e-003,0.000000e+000,0,,0,
1524239151.765,,0.000000e+000,5.499643e+001,3.478239e-006,0.000000e+000,3,8.684756e-001,0.000000e+000,,,,,,,,,,,,,,32,1,4.000000e+000,1.312256e-003,0.000000e+000,0,,0,
1524239189.345,,0.000000e+000,5.499511e+001,3.475715e-006,0.000000e+000,3,8.823500e-001,0.000000e+000,,,,,,,,,,,,,,32,1,4.000000e+000,3.940582e-003,0.000000e+000,0,,0,
1524239227.215,,0.000000e+000,5.499840e+001,3.430482e-006,0.000000e+000,3,8.840809e-001,0.000000e+000,,,,,,,,,,,,,,32,1,4.000000e+000,5.260468e-003,0.000000e+000,0,,0,
1524239264.495,,0.000000e+000,5.500037e+001,3.461420e-006,0.000000e+000,3,8.804502e-001,0.000000e+000,,,,,,,,,,,,,,32,1,4.000000e+000,1.319885e-003,0.000000e+000,0,,0,
1524239302.295,,0.000000e+000,5.499511e+001,3.430142e-006,0.000000e+000,3,8.952434e-001,0.000000e+000,,,,,,,,,,,,,,32,1,4.000000e+000,3.940582e-003,0.000000e+000,0,,0,
1524239340.315,,0.000000e+000,5.500103e+001,3.437310e-006,0.000000e+000,3,9.053108e-001,0.000000e+000,,,,,,,,,,,,,,32,1,4.000000e+000,1.052094e-002,0.000000e+000,0,,0,
1524239378.225,,0.000000e+000,5.500300e+001,3.536705e-006,0.000000e+000,3,8.911920e-001,0.000000e+000,,,,,,,,,,,,,,32,1,4.000000e+000,6.580353e-003,0.000000e+000,0,,0,
1524239415.445,,0.000000e+000,5.499972e+001,3.505028e-006,0.000000e+000,3,8.717075e-001,0.000000e+000,,,,,,,,,,,,,,32,1,4.000000e+000,5.268097e-003,0.000000e+000,0,,0,
1524239454.225,,0.000000e+000,5.499445e+001,3.416943e-006,0.000000e+000,3,8.990239e-001,0.000000e+000,,,,,,,,,,,,,,32,1,4.000000e+000,5.260468e-003,0.000000e+000,0,,0,
1524239491.725,,0.000000e+000,5.499577e+001,3.567224e-006,0.000000e+000,3,8.749864e-001,0.000000e+000,,,,,,,,,,,,,,32,1,4.000000e+000,1.052094e-002,0.000000e+000,0,,0,
1524239530.005,,0.000000e+000,5.499577e+001,3.447512e-006,0.000000e+000,3,8.954078e-001,0.000000e+000,,,,,,,,,,,,,,32,1,4.000000e+000,1.052094e-002,0.000000e+000,0,,0,
1524239567.845,,0.000000e+000,5.499708e+001,3.553991e-006,0.000000e+000,3,8.951635e-001,0.000000e+000,,,,,,,,,,,,,,32,1,4.000000e+000,2.620697e-003,0.000000e+000,0,,0,
1524239606.055,,0.000000e+000,5.499840e+001,3.549306e-006,0.000000e+000,3,8.800317e-001,0.000000e+000,,,,,,,,,,,,,,32,1,4.000000e+000,5.260468e-003,0.000000e+000,0,,0,
1524239643.335,,0.000000e+000,5.499511e+001,3.462692e-006,0.000000e+000,3,8.949622e-001,0.000000e+000,,,,,,,,,,,,,,32,1,4.000000e+000,1.319885e-003,0.000000e+000,0,,0,
1524239680.895,,0.000000e+000,5.499248e+001,3.542028e-006,0.000000e+000,3,8.810203e-001,0.000000e+000,,,,,,,,,,,,,,32,1,4.000000e+000,1.446152e-002,0.000000e+000,0,,0,
1524239718.485,,0.000000e+000,5.499577e+001,3.503676e-006,0.000000e+000,3,8.906779e-001,0.000000e+000,,,,,,,,,,,,,,32,1,4.000000e+000,2.632141e-003,0.000000e+000,0,,0,
1524239756.575,,0.000000e+000,5.499775e+001,3.556982e-006,0.000000e+000,3,8.861474e-001,0.000000e+000,,,,,,,,,,,,,,32,1,4.000000e+000,9.208679e-003,0.000000e+000,0,,0,
1524239794.445,,0.000000e+000,5.499511e+001,3.572599e-006,0.000000e+000,3,8.779244e-001,0.000000e+000,,,,,,,,,,,,,,32,1,4.000000e+000,1.184082e-002,0.000000e+000,0,,0,
1524239832.126,,0.000000e+000,5.499971e+001,3.609832e-006,0.000000e+000,3,8.936059e-001,0.000000e+000,,,,,,,,,,,,,,32,1,4.000000e+000,0.000000e+000,0.000000e+000,0,,0,
1524239869.956,,0.000000e+000,5.499905e+001,3.551253e-006,0.000000e+000,3,8.774542e-001,0.000000e+000,,,,,,,,,,,,,,32,1,4.000000e+000,3.948212e-003,0.000000e+000,0,,0,
1524239908.136,,0.000000e+000,5.499775e+001,3.549189e-006,0.000000e+000,3,8.853077e-001,0.000000e+000,,,,,,,,,,,,,,32,1,4.000000e+000,9.208679e-003,0.000000e+000,0,,0,
1524239946.076,,0.000000e+000,5.499774e+001,3.513608e-006,0.000000e+000,3,9.024656e-001,0.000000e+000,,,,,,,,,,,,,,32,1,4.000000e+000,3.940582e-003,0.000000e+000,0,,0,
1524239983.966,,0.000000e+000,5.499840e+001,3.579953e-006,0.000000e+000,3,8.760560e-001,0.000000e+000,,,,,,,,,,,,,,32,1,4.000000e+000,7.900238e-003,0.000000e+000,0,,0,
1524240021.926,,0.000000e+000,5.500103e+001,3.608283e-006,0.000000e+000,3,8.932434e-001,0.000000e+000,,,,,,,,,,,,,,32,1,4.000000e+000,0.000000e+000,0.000000e+000,0,,0,
1524240059.596,,0.000000e+000,5.499708e+001,3.602216e-006,0.000000e+000,3,8.856322e-001,0.000000e+000,,,,,,,,,,,,,,32,1,4.000000e+000,0.000000e+000,0.000000e+000,0,,0,
1524240097.526,,0.000000e+000,5.499840e+001,3.582539e-006,0.000000e+000,3,8.897164e-001,0.000000e+000,,,,,,,,,,,,,,32,1,4.000000e+000,5.260468e-003,0.000000e+000,0,,0,
1524240135.096,,0.000000e+000,5.500300e+001,3.666709e-006,0.000000e+000,3,8.853706e-001,0.000000e+000,,,,,,,,,,,,,,32,1,4.000000e+000,9.220123e-003,0.000000e+000,0,,0,
1524240173.136,,0.000000e+000,5.499511e+001,3.611333e-006,0.000000e+000,3,8.922237e-001,0.000000e+000,,,,,,,,,,,,,,32,1,4.000000e+000,3.940582e-003,0.000000e+000,0,,0,
1524240210.326,,0.000000e+000,5.499708e+001,3.587789e-006,0.000000e+000,3,9.045095e-001,0.000000e+000,,,,,,,,,,,,,,32,1,4.000000e+000,2.620697e-003,0.000000e+000,0,,0,
1524240248.086,,0.000000e+000,5.499774e+001,3.569347e-006,0.000000e+000,3,8.843040e-001,0.000000e+000,,,,,,,,,,,,,,32,1,4.000000e+000,6.580353e-003,0.000000e+000,0,,0,
1524240285.476,,0.000000e+000,5.499840e+001,3.656313e-006,0.000000e+000,3,8.978420e-001,0.000000e+000,,,,,,,,,,,,,,32,1,4.000000e+000,5.260468e-003,0.000000e+000,0,,0,
1524240348.606,,0.000000e+000,5.500169e+001,3.576613e-006,0.000000e+000,3,8.840698e-001,0.000000e+000,,,,,,,,,,,,,,32,1,4.000000e+000,1.319885e-003,0.000000e+000,0,,0,
1524240386.406,,0.000000e+000,5.500169e+001,3.543869e-006,0.000000e+000,3,8.863682e-001,0.000000e+000,,,,,,,,,,,,,,32,1,4.000000e+000,1.319885e-003,0.000000e+000,0,,0,
1524240424.206,,0.000000e+000,5.499511e+001,3.579795e-006,0.000000e+000,3,8.934575e-001,0.000000e+000,,,,,,,,,,,,,,32,1,4.000000e+000,6.568909e-003,0.000000e+000,0,,0,
1524240462.286,,0.000000e+000,5.499183e+001,3.634409e-006,0.000000e+000,3,8.958784e-001,0.000000e+000,,,,,,,,,,,,,,32,1,4.000000e+000,2.632141e-003,0.000000e+000,0,,0,
1524240524.206,,0.000000e+000,5.499906e+001,3.660912e-006,0.000000e+000,3,8.940582e-001,0.000000e+000,,,,,,,,,,,,,,32,1,4.000000e+000,9.220123e-003,0.000000e+000,0,,0,
1524240562.077,,0.000000e+000,5.499708e+001,3.549867e-006,0.000000e+000,3,8.967599e-001,0.000000e+000,,,,,,,,,,,,,,32,1,4.000000e+000,2.620697e-003,0.000000e+000,0,,0,
1524240599.617,,0.000000e+000,5.499445e+001,3.686065e-006,0.000000e+000,3,8.708903e-001,0.000000e+000,,,,,,,,,,,,,,32,1,4.000000e+000,2.628326e-003,0.000000e+000,0,,0,
1524240637.187,,0.000000e+000,5.499313e+001,3.605992e-006,0.000000e+000,3,8.911526e-001,0.000000e+000,,,,,,,,,,,,,,32,1,4.000000e+000,2.628326e-003,0.000000e+000,0,,0,
1524240675.277,,0.000000e+000,5.499972e+001,3.577046e-006,0.000000e+000,3,8.927535e-001,0.000000e+000,,,,,,,,,,,,,,32,1,4.000000e+000,1.314926e-002,0.000000e+000,0,,0,
1524240713.007,,0.000000e+000,5.499643e+001,3.650860e-006,0.000000e+000,3,8.833585e-001,0.000000e+000,,,,,,,,,,,,,,32,1,4.000000e+000,1.312256e-003,0.000000e+000,0,,0,
1524240750.887,,0.000000e+000,5.499774e+001,3.632455e-006,0.000000e+000,3,8.959270e-001,0.000000e+000,,,,,,,,,,,,,,32,1,4.000000e+000,3.940582e-003,0.000000e+000,0,,0,
1524240788.627,,0.000000e+000,5.499643e+001,3.652442e-006,0.000000e+000,3,8.884054e-001,0.000000e+000,,,,,,,,,,,,,,32,1,4.000000e+000,1.312256e-003,0.000000e+000,0,,0,
1524240826.507,,0.000000e+000,5.500169e+001,3.564128e-006,0.000000e+000,3,8.894472e-001,0.000000e+000,,,,,,,,,,,,,,32,1,4.000000e+000,1.319885e-003,0.000000e+000,0,,0,
1524240864.227,,0.000000e+000,5.500432e+001,3.602884e-006,0.000000e+000,3,8.878385e-001,0.000000e+000,,,,,,,,,,,,,,32,1,4.000000e+000,6.580353e-003,0.000000e+000,0,,0,
1524240902.097,,0.000000e+000,5.499840e+001,3.604605e-006,0.000000e+000,3,8.930889e-001,0.000000e+000,,,,,,,,,,,,,,32,1,4.000000e+000,5.260468e-003,0.000000e+000,0,,0,
1524240939.187,,0.000000e+000,5.499708e+001,3.668104e-006,0.000000e+000,3,8.914140e-001,0.000000e+000,,,,,,,,,,,,,,32,1,4.000000e+000,5.260468e-003,0.000000e+000,0,,0,
1524240977.017,,0.000000e+000,5.500103e+001,3.606159e-006,0.000000e+000,3,8.972263e-001,0.000000e+000,,,,,,,,,,,,,,32,1,4.000000e+000,2.639771e-003,0.000000e+000,0,,0,
1524241014.517,,0.000000e+000,5.499840e+001,3.666759e-006,0.000000e+000,3,8.992839e-001,0.000000e+000,,,,,,,,,,,,,,32,1,4.000000e+000,7.900238e-003,0.000000e+000,0,,0,
1524241051.857,,0.000000e+000,5.499643e+001,3.681380e-006,0.000000e+000,3,9.010916e-001,0.000000e+000,,,,,,,,,,,,,,32,1,4.000000e+000,6.568909e-003,0.000000e+000,0,,0,
1524241090.227,,0.000000e+000,5.499314e+001,3.613730e-006,0.000000e+000,3,8.986130e-001,0.000000e+000,,,,,,,,,,,,,,32,1,4.000000e+000,5.260468e-003,0.000000e+000,0,,0,
1524241128.367,,0.000000e+000,5.499773e+001,3.634099e-006,0.000000e+000,3,8.961199e-001,0.000000e+000,,,,,,,,,,,,,,32,1,4.000000e+000,1.308441e-003,0.000000e+000,0,,0,
1524241166.087,,0.000000e+000,5.499708e+001,3.659105e-006,0.000000e+000,3,8.860754e-001,0.000000e+000,,,,,,,,,,,,,,32,1,4.000000e+000,2.620697e-003,0.000000e+000,0,,0,
1524241203.957,,0.000000e+000,5.500037e+001,3.604365e-006,0.000000e+000,3,8.989558e-001,0.000000e+000,,,,,,,,,,,,,,32,1,4.000000e+000,3.959656e-003,0.000000e+000,0,,0,
1524241241.707,,0.000000e+000,5.500300e+001,3.654407e-006,0.000000e+000,3,8.873441e-001,0.000000e+000,,,,,,,,,,,,,,32,1,4.000000e+000,9.220123e-003,0.000000e+000,0,,0,
1524241279.318,,0.000000e+000,5.499972e+001,3.605129e-006,0.000000e+000,3,8.963919e-001,0.000000e+000,,,,,,,,,,,,,,32,1,4.000000e+000,5.268097e-003,0.000000e+000,0,,0,
1524241317.018,,0.000000e+000,5.499906e+001,3.678676e-006,0.000000e+000,3,8.806853e-001,0.000000e+000,,,,,,,,,,,,,,32,1,4.000000e+000,6.580353e-003,0.000000e+000,0,,0,
1524241354.908,,0.000000e+000,5.499380e+001,3.683469e-006,0.000000e+000,3,8.904942e-001,0.000000e+000,,,,,,,,,,,,,,32,1,4.000000e+000,1.446915e-002,0.000000e+000,0,,0,
1524241393.228,,0.000000e+000,5.499972e+001,3.646167e-006,0.000000e+000,3,8.935496e-001,0.000000e+000,,,,,,,,,,,,,,32,1,4.000000e+000,7.900238e-003,0.000000e+000,0,,0,
1524241430.808,,0.000000e+000,5.499642e+001,3.710612e-006,0.000000e+000,3,8.764703e-001,0.000000e+000,,,,,,,,,,,,,,32,1,4.000000e+000,3.940582e-003,0.000000e+000,0,,0,
1524241468.838,,0.000000e+000,5.500432e+001,3.664448e-006,0.000000e+000,3,8.970098e-001,0.000000e+000,,,,,,,,,,,,,,32,1,4.000000e+000,1.300812e-003,0.000000e+000,0,,0,
1524241506.428,,0.000000e+000,5.500037e+001,3.755527e-006,0.000000e+000,3,8.872227e-001,0.000000e+000,,,,,,,,,,,,,,32,1,4.000000e+000,1.319885e-003,0.000000e+000,0,,0,
1524241544.468,,0.000000e+000,5.499643e+001,3.681732e-006,0.000000e+000,3,9.022875e-001,0.000000e+000,,,,,,,,,,,,,,32,1,4.000000e+000,9.208679e-003,0.000000e+000,0,,0,
1524241582.018,,0.000000e+000,5.499840e+001,3.707306e-006,0.000000e+000,3,8.852975e-001,0.000000e+000,,,,,,,,,,,,,,32,1,4.000000e+000,2.628326e-003,0.000000e+000,0,,0,
1524241620.018,,0.000000e+000,5.499643e+001,3.626067e-006,0.000000e+000,3,8.963215e-001,0.000000e+000,,,,,,,,,,,,,,32,1,4.000000e+000,1.312256e-003,0.000000e+000,0,,0,
1524241657.708,,0.000000e+000,5.500037e+001,3.717534e-006,0.000000e+000,3,8.815348e-001,0.000000e+000,,,,,,,,,,,,,,32,1,4.000000e+000,1.319885e-003,0.000000e+000,0,,0,
1524241695.638,,0.000000e+000,5.500301e+001,3.775897e-006,0.000000e+000,3,9.021394e-001,0.000000e+000,,,,,,,,,,,,,,32,1,4.000000e+000,1.319885e-003,0.000000e+000,0,,0,
1524241733.268,,0.000000e+000,5.499577e+001,3.750347e-006,0.000000e+000,3,8.828072e-001,0.000000e+000,,,,,,,,,,,,,,32,1,4.000000e+000,2.632141e-003,0.000000e+000,0,,0,
1524241771.268,,0.000000e+000,5.499972e+001,3.774608e-006,0.000000e+000,3,9.261863e-001,0.000000e+000,,,,,,,,,,,,,,32,1,4.000000e+000,7.900238e-003,0.000000e+000,0,,0,
1524241809.138,,0.000000e+000,5.499972e+001,3.783669e-006,0.000000e+000,3,9.112340e-001,0.000000e+000,,,,,,,,,,,,,,32,1,4.000000e+000,5.268097e-003,0.000000e+000,0,,0,
1524241847.008,,0.000000e+000,5.499971e+001,3.680284e-006,0.000000e+000,3,8.999292e-001,0.000000e+000,,,,,,,,,,,,,,32,1,4.000000e+000,2.639771e-003,0.000000e+000,0,,0,
1524241885.308,,0.000000e+000,5.499840e+001,3.649300e-006,0.000000e+000,3,9.033625e-001,0.000000e+000,,,,,,,,,,,,,,32,1,4.000000e+000,7.900238e-003,0.000000e+000,0,,0,
1524241922.428,,0.000000e+000,5.499313e+001,3.691887e-006,0.000000e+000,3,8.998261e-001,0.000000e+000,,,,,,,,,,,,,,32,1,4.000000e+000,2.628326e-003,0.000000e+000,0,,0,
1524241960.438,,0.000000e+000,5.499577e+001,3.668187e-006,0.000000e+000,3,9.045375e-001,0.000000e+000,,,,,,,,,,,,,,32,1,4.000000e+000,5.249023e-003,0.000000e+000,0,,0,
1524241998.459,,0.000000e+000,5.500103e+001,3.721848e-006,0.000000e+000,3,8.853452e-001,0.000000e+000,,,,,,,,,,,,,,32,1,4.000000e+000,5.279541e-003,0.000000e+000,0,,0,
1524242035.869,,0.000000e+000,5.499773e+001,3.672878e-006,0.000000e+000,3,8.960006e-001,0.000000e+000,,,,,,,,,,,,,,32,1,4.000000e+000,1.308441e-003,0.000000e+000,0,,0,
1524242072.999,,0.000000e+000,5.499577e+001,3.678977e-006,0.000000e+000,3,8.918934e-001,0.000000e+000,,,,,,,,,,,,,,32,1,4.000000e+000,5.249023e-003,0.000000e+000,0,,0,
1524242111.659,,0.000000e+000,5.500563e+001,3.714576e-006,0.000000e+000,3,8.960300e-001,0.000000e+000,,,,,,,,,,,,,,32,1,4.000000e+000,1.319885e-003,0.000000e+000,0,,0,
1524242149.199,,0.000000e+000,5.499773e+001,3.795201e-006,0.000000e+000,3,8.991722e-001,0.000000e+000,,,,,,,,,,,,,,32,1,4.000000e+000,1.308441e-003,0.000000e+000,0,,0,
1524242187.129,,0.000000e+000,5.499708e+001,3.666552e-006,0.000000e+000,3,8.976892e-001,0.000000e+000,,,,,,,,,,,,,,32,1,4.000000e+000,5.260468e-003,0.000000e+000,0,,0,
1524242224.639,,0.000000e+000,5.500432e+001,3.820493e-006,0.000000e+000,3,8.859977e-001,0.000000e+000,,,,,,,,,,,,,,32,1,4.000000e+000,3.940582e-003,0.000000e+000,0,,0,
1524242262.719,,0.000000e+000,5.499774e+001,3.744886e-006,0.000000e+000,3,9.056135e-001,0.000000e+000,,,,,,,,,,,,,,32,1,4.000000e+000,3.940582e-003,0.000000e+000,0,,0,
1524242300.069,,0.000000e+000,5.500103e+001,3.789752e-006,0.000000e+000,3,8.906106e-001,0.000000e+000,,,,,,,,,,,,,,32,1,4.000000e+000,1.577759e-002,0.000000e+000,0,,0,
1524242337.769,,0.000000e+000,5.500103e+001,3.733702e-006,0.000000e+000,3,9.035406e-001,0.000000e+000,,,,,,,,,,,,,,32,1,4.000000e+000,2.639771e-003,0.000000e+000,0,,0,
1524242375.309,,0.000000e+000,5.499643e+001,3.800999e-006,0.000000e+000,3,8.916494e-001,0.000000e+000,,,,,,,,,,,,,,32,1,4.000000e+000,6.568909e-003,0.000000e+000,0,,0,
1524242413.299,,0.000000e+000,5.499708e+001,3.750434e-006,0.000000e+000,3,8.963947e-001,0.000000e+000,,,,,,,,,,,,,,32,1,4.000000e+000,2.620697e-003,0.000000e+000,0,,0,
1524242451.319,,0.000000e+000,5.499972e+001,3.699204e-006,0.000000e+000,3,9.026106e-001,0.000000e+000,,,,,,,,,,,,,,32,1,4.000000e+000,5.268097e-003,0.000000e+000,0,,0,
1524242489.069,,0.000000e+000,5.500169e+001,3.815343e-006,0.000000e+000,3,9.058843e-001,0.000000e+000,,,,,,,,,,,,,,32,1,4.000000e+000,1.319885e-003,0.000000e+000,0,,0,
1524242527.159,,0.000000e+000,5.499511e+001,3.834704e-006,0.000000e+000,3,8.966413e-001,0.000000e+000,,,,,,,,,,,,,,32,1,4.000000e+000,3.940582e-003,0.000000e+000,0,,0,
1524242565.129,,0.000000e+000,5.500366e+001,3.733149e-006,0.000000e+000,3,9.032841e-001,0.000000e+000,,,,,,,,,,,,,,32,1,4.000000e+000,2.620697e-003,0.000000e+000,0,,0,
1524242602.679,,0.000000e+000,5.499511e+001,3.750267e-006,0.000000e+000,3,8.887086e-001,0.000000e+000,,,,,,,,,,,,,,32,1,4.000000e+000,6.568909e-003,0.000000e+000,0,,0,
1524242640.759,,0.000000e+000,5.500168e+001,3.773114e-006,0.000000e+000,3,9.052890e-001,0.000000e+000,,,,,,,,,,,,,,32,1,4.000000e+000,6.580353e-003,0.000000e+000,0,,0,
1524242678.339,,0.000000e+000,5.499840e+001,3.792212e-006,0.000000e+000,3,8.874595e-001,0.000000e+000,,,,,,,,,,,,,,32,1,4.000000e+000,2.628326e-003,0.000000e+000,0,,0,
1524242716.320,,0.000000e+000,5.500037e+001,3.790738e-006,0.000000e+000,3,9.041612e-001,0.000000e+000,,,,,,,,,,,,,,32,1,4.000000e+000,1.319885e-003,0.000000e+000,0,,0,
1524242753.910,,0.000000e+000,5.499840e+001,3.759504e-006,0.000000e+000,3,8.911356e-001,0.000000e+000,,,,,,,,,,,,,,32,1,4.000000e+000,2.628326e-003,0.000000e+000,0,,0,
1524242791.950,,0.000000e+000,5.499905e+001,3.750056e-006,0.000000e+000,3,9.017844e-001,0.000000e+000,,,,,,,,,,,,,,32,1,4.000000e+000,3.948212e-003,0.000000e+000,0,,0,
1524242829.600,,0.000000e+000,5.498985e+001,3.803832e-006,0.000000e+000,3,9.127311e-001,0.000000e+000,,,,,,,,,,,,,,32,1,4.000000e+000,1.319885e-003,0.000000e+000,0,,0,
1524242842.430,,0.000000e+000,5.500103e+001,3.810960e-006,0.000000e+000,3,9.272227e-001,0.000000e+000,,,,,,,,,,,,,,32,1,4.000000e+000,5.279541e-003,0.000000e+000,0,,0,