File: Input_All/TC04-12-01K_VRMac_56K_3000s_VRMde_55K.dc.dat
[Header]
TITLE,MPMS DC Measurement
BYAPP,MPMS Measurement,2.1,Summary
FILEOPENTIME, 1524281814.276000 4/20/2018, 9:36:54 PM

INFO, APPNAME, MPMS MultiVu Application, Revision 1.61,  Build 082

INFO, NAME, TC04-12-01K
INFO, WEIGHT, 1.000
INFO, AREA, 1.000
INFO, LENGTH, 1.000
INFO, SHAPE, 0
INFO, COMMENT,
INFO, SEQUENCE FILE: VRMac_56K_3000s_VRMde_55K.seq


INFO, BACKGROUND DATA FILE:, None


STARTUPAXIS,X,4,LINEAR,AUTO,0.000000,0.000000
STARTUPAXIS,Y1,5,LINEAR,AUTO,0.000000,0.000000


STARTUPGROUP,Longitudinal
FIELDGROUP,Longitudinal,1,2,3,4,5,6,7,8,9,15,16,17,18,27,28
FIELDGROUP,Transverse,1,2,3,4,10,11,12,13,14,19,20,21,22,27,28

PLOT_APPEARANCE,ALL,HORZ_GRID_ON,VERT_GRID_ON,MARKERS_AND_LINES

[Data]
Time,Comment,Field (Oe),Temperature (K),Long Moment (emu),Long Scan Std Dev,Long Algorithm,Long Reg Fit,Long Percent Error (%),Trans Moment (emu),Trans Scan Std Dev,Trans Algorithm,Trans Reg Fit,Trans Percent Error (%),Long Moment [w/o ABS] (emu),Long Scan Std Dev [w/o ABS],Long Reg Fit [w/o ABS],Long Percent Error [w/o ABS] (%),Trans Moment [w/o ABS] (emu),Trans Scan Std Dev [w/o ABS],Trans Reg Fit [w/o ABS],Trans Percent Error [w/o ABS] (%),Points per Scan,Scans per Measurement,Scan Length (cm),Delta Temp (K),Rot Position (deg),Error,EC Comp. Running,Using ABS,
1524281814.276,,0.000000e+000,5.598676e+001,-1.415140e-005,0.000000e+000,2,9.038550e-001,0.000000e+000,,,,,,,,,,,,,,32,1,4.000000e+000,3.123093e-002,0.000000e+000,0,,0,
1524281853.246,,0.000000e+000,5.578377e+001,-1.048496e-005,0.000000e+000,2,8.604266e-001,0.000000e+000,,,,,,,,,,,,,,32,1,4.000000e+000,8.769989e-002,0.000000e+000,0,,0,
1524281890.866,,0.000000e+000,5.533847e+001,-9.051415e-006,0.000000e+000,2,8.375231e-001,0.000000e+000,,,,,,,,,,,,,,32,1,4.000000e+000,1.782227e-001,0.000000e+000,0,,0,
1524281931.236,,0.000000e+000,5.490121e+001,-8.107108e-006,0.000000e+000,2,8.044000e-001,0.000000e+000,,,,,,,,,,,,,,32,1,4.000000e+000,2.628326e-003,0.000000e+000,0,,0,
1524281969.126,,0.000000e+000,5.497013e+001,-7.396671e-006,0.000000e+000,2,7.870426e-001,0.000000e+000,,,,,,,,,,,,,,32,1,4.000000e+000,2.497101e-002,0.000000e+000,0,,0,
1524282007.087,,0.000000e+000,5.501682e+001,-6.892708e-006,0.000000e+000,2,7.717199e-001,0.000000e+000,,,,,,,,,,,,,,32,1,4.000000e+000,1.580048e-002,0.000000e+000,0,,0,
1524282045.247,,0.000000e+000,5.500958e+001,-6.395434e-006,0.000000e+000,2,7.605301e-001,0.000000e+000,,,,,,,,,,,,,,32,1,4.000000e+000,1.319885e-003,0.000000e+000,0,,0,
1524282082.307,,0.000000e+000,5.501485e+001,-6.079520e-006,0.000000e+000,2,7.309952e-001,0.000000e+000,,,,,,,,,,,,,,32,1,4.000000e+000,3.948212e-003,0.000000e+000,0,,0,
1524282120.007,,0.000000e+000,5.500892e+001,-5.688949e-006,0.000000e+000,2,7.372553e-001,0.000000e+000,,,,,,,,,,,,,,32,1,4.000000e+000,5.260468e-003,0.000000e+000,0,,0,
1524282157.707,,0.000000e+000,5.500300e+001,-5.408582e-006,0.000000e+000,2,7.147235e-001,0.000000e+000,,,,,,,,,,,,,,32,1,4.000000e+000,3.940582e-003,0.000000e+000,0,,0,
1524282195.637,,0.000000e+000,5.500103e+001,-4.955896e-006,0.000000e+000,2,6.966150e-001,0.000000e+000,,,,,,,,,,,,,,32,1,4.000000e+000,2.639771e-003,0.000000e+000,0,,0,
1524282234.257,,0.000000e+000,5.500037e+001,-4.871843e-006,0.000000e+000,2,6.817802e-001,0.000000e+000,,,,,,,,,,,,,,32,1,4.000000e+000,1.319885e-003,0.000000e+000,0,,0,
1524282271.777,,0.000000e+000,5.500037e+001,-4.615867e-006,0.000000e+000,2,6.508097e-001,0.000000e+000,,,,,,,,,,,,,,32,1,4.000000e+000,1.319885e-003,0.000000e+000,0,,0,
1524282309.677,,0.000000e+000,5.500235e+001,-4.373772e-006,0.000000e+000,2,6.427484e-001,0.000000e+000,,,,,,,,,,,,,,32,1,4.000000e+000,2.639771e-003,0.000000e+000,0,,0,
1524282347.567,,0.000000e+000,5.500300e+001,-4.133463e-006,0.000000e+000,2,6.090439e-001,0.000000e+000,,,,,,,,,,,,,,32,1,4.000000e+000,1.183701e-002,0.000000e+000,0,,0,
1524282385.467,,0.000000e+000,5.499445e+001,-4.022565e-006,0.000000e+000,2,6.073534e-001,0.000000e+000,,,,,,,,,,,,,,32,1,4.000000e+000,1.052094e-002,0.000000e+000,0,,0,
1524282423.267,,0.000000e+000,5.499774e+001,-3.832961e-006,0.000000e+000,2,5.760131e-001,0.000000e+000,,,,,,,,,,,,,,32,1,4.000000e+000,6.580353e-003,0.000000e+000,0,,0,
1524282461.087,,0.000000e+000,5.499380e+001,-3.581592e-006,0.000000e+000,2,5.517653e-001,0.000000e+000,,,,,,,,,,,,,,32,1,4.000000e+000,3.948212e-003,0.000000e+000,0,,0,
1524282498.857,,0.000000e+000,5.499380e+001,-3.439138e-006,0.000000e+000,2,5.515723e-001,0.000000e+000,,,,,,,,,,,,,,32,1,4.000000e+000,1.308441e-003,0.000000e+000,0,,0,
1524282536.437,,0.000000e+000,5.500235e+001,-3.222933e-006,0.000000e+000,2,5.226402e-001,0.000000e+000,,,,,,,,,,,,,,32,1,4.000000e+000,1.052856e-002,0.000000e+000,0,,0,
1524282574.247,,0.000000e+000,5.499708e+001,-3.171232e-006,0.000000e+000,2,5.198204e-001,0.000000e+000,,,,,,,,,,,,,,32,1,4.000000e+000,5.260468e-003,0.000000e+000,0,,0,
1524282612.097,,0.000000e+000,5.500037e+001,-2.952245e-006,0.000000e+000,2,4.444341e-001,0.000000e+000,,,,,,,,,,,,,,32,1,4.000000e+000,1.319885e-003,0.000000e+000,0,,0,
1524282650.037,,0.000000e+000,5.499643e+001,-2.822515e-006,0.000000e+000,2,4.448834e-001,0.000000e+000,,,,,,,,,,,,,,32,1,4.000000e+000,1.312256e-003,0.000000e+000,0,,0,
1524282687.318,,0.000000e+000,5.499840e+001,-2.677173e-006,0.000000e+000,2,4.020993e-001,0.000000e+000,,,,,,,,,,,,,,32,1,4.000000e+000,7.900238e-003,0.000000e+000,0,,0,
1524282724.908,,0.000000e+000,5.500037e+001,-2.564759e-006,0.000000e+000,2,4.094465e-001,0.000000e+000,,,,,,,,,,,,,,32,1,4.000000e+000,1.319885e-003,0.000000e+000,0,,0,
1524282762.248,,0.000000e+000,5.500169e+001,-2.488345e-006,0.000000e+000,2,3.442874e-001,0.000000e+000,,,,,,,,,,,,,,32,1,4.000000e+000,1.709747e-002,0.000000e+000,0,,0,
1524282799.648,,0.000000e+000,5.499972e+001,-2.380865e-006,0.000000e+000,2,3.579979e-001,0.000000e+000,,,,,,,,,,,,,,32,1,4.000000e+000,5.268097e-003,0.000000e+000,0,,0,
1524282837.558,,0.000000e+000,5.499643e+001,-2.269804e-006,0.000000e+000,2,2.815730e-001,0.000000e+000,,,,,,,,,,,,,,32,1,4.000000e+000,6.568909e-003,0.000000e+000,0,,0,
1524282874.728,,0.000000e+000,5.499248e+001,-2.172226e-006,0.000000e+000,2,2.821175e-001,0.000000e+000,,,,,,,,,,,,,,32,1,4.000000e+000,6.580353e-003,0.000000e+000,0,,0,
1524282912.118,,0.000000e+000,5.499709e+001,-2.070934e-006,0.000000e+000,2,1.821843e-001,0.000000e+000,,,,,,,,,,,,,,32,1,4.000000e+000,1.052856e-002,0.000000e+000,0,,0,
1524282949.858,,0.000000e+000,5.499445e+001,-2.002317e-006,0.000000e+000,2,2.176554e-001,0.000000e+000,,,,,,,,,,,,,,32,1,4.000000e+000,5.260468e-003,0.000000e+000,0,,0,
1524282986.668,,0.000000e+000,5.499117e+001,-1.939345e-006,0.000000e+000,2,1.251641e-001,0.000000e+000,,,,,,,,,,,,,,32,1,4.000000e+000,9.208679e-003,0.000000e+000,0,,0,
1524283024.348,,0.000000e+000,5.499906e+001,-1.819286e-006,0.000000e+000,2,1.392761e-001,0.000000e+000,,,,,,,,,,,,,,32,1,4.000000e+000,6.580353e-003,0.000000e+000,0,,0,
1524283062.278,,0.000000e+000,5.499773e+001,-1.726252e-006,0.000000e+000,2,4.186801e-002,0.000000e+000,,,,,,,,,,,,,,32,1,4.000000e+000,1.308441e-003,0.000000e+000,0,,0,
1524283099.448,,0.000000e+000,5.499840e+001,-1.629865e-006,0.000000e+000,2,1.186407e-002,0.000000e+000,,,,,,,,,,,,,,32,1,4.000000e+000,2.628326e-003,0.000000e+000,0,,0,
1524283137.388,,0.000000e+000,5.499708e+001,-1.636265e-006,0.000000e+000,2,0.000000e+000,0.000000e+000,,,,,,,,,,,,,,32,1,4.000000e+000,5.260468e-003,0.000000e+000,0,,0,
1524283175.118,,0.000000e+000,5.499511e+001,-1.490275e-006,0.000000e+000,2,0.000000e+000,0.000000e+000,,,,,,,,,,,,,,32,1,4.000000e+000,9.201050e-003,0.000000e+000,0,,0,
1524283213.488,,0.000000e+000,5.500103e+001,-1.384020e-006,0.000000e+000,2,0.000000e+000,0.000000e+000,,,,,,,,,,,,,,32,1,4.000000e+000,2.639771e-003,0.000000e+000,0,,0,
1524283251.458,,0.000000e+000,5.499840e+001,-1.357395e-006,0.000000e+000,2,0.000000e+000,0.000000e+000,,,,,,,,,,,,,,32,1,4.000000e+000,2.628326e-003,0.000000e+000,0,,0,
1524283289.238,,0.000000e+000,5.499577e+001,-1.253413e-006,0.000000e+000,2,0.000000e+000,0.000000e+000,,,,,,,,,,,,,,32,1,4.000000e+000,7.888794e-003,0.000000e+000,0,,0,
1524283327.558,,0.000000e+000,5.499905e+001,-1.176028e-006,0.000000e+000,2,0.000000e+000,0.000000e+000,,,,,,,,,,,,,,32,1,4.000000e+000,1.319885e-003,0.000000e+000,0,,0,
1524283364.878,,0.000000e+000,5.499643e+001,-1.155873e-006,0.000000e+000,2,0.000000e+000,0.000000e+000,,,,,,,,,,,,,,32,1,4.000000e+000,1.312256e-003,0.000000e+000,0,,0,
1524283403.199,,0.000000e+000,5.499183e+001,-1.149821e-006,0.000000e+000,2,0.000000e+000,0.000000e+000,,,,,,,,,,,,,,32,1,4.000000e+000,2.632141e-003,0.000000e+000,0,,0,
1524283441.099,,0.000000e+000,5.499708e+001,-9.936474e-007,0.000000e+000,2,0.000000e+000,0.000000e+000,,,,,,,,,,,,,,32,1,4.000000e+000,2.620697e-003,0.000000e+000,0,,0,
1524283479.489,,0.000000e+000,5.500169e+001,-8.875635e-007,0.000000e+000,2,0.000000e+000,0.000000e+000,,,,,,,,,,,,,,32,1,4.000000e+000,3.959656e-003,0.000000e+000,0,,0,
1524283516.929,,0.000000e+000,5.499905e+001,-8.258892e-007,0.000000e+000,2,0.000000e+000,0.000000e+000,,,,,,,,,,,,,,32,1,4.000000e+000,1.319885e-003,0.000000e+000,0,,0,
1524283554.509,,0.000000e+000,5.500235e+001,-7.740170e-007,0.000000e+000,2,0.000000e+000,0.000000e+000,,,,,,,,,,,,,,32,1,4.000000e+000,2.639771e-003,0.000000e+000,0,,0,
1524283592.469,,0.000000e+000,5.499642e+001,-7.920526e-007,0.000000e+000,2,0.000000e+000,0.000000e+000,,,,,,,,,,,,,,32,1,4.000000e+000,3.940582e-003,0.000000e+000,0,,0,
1524283630.769,,0.000000e+000,5.500563e+001,-7.608614e-007,0.000000e+000,2,0.000000e+000,0.000000e+000,,,,,,,,,,,,,,32,1,4.000000e+000,1.319885e-003,0.000000e+000,0,,0,
1524283667.779,,0.000000e+000,5.500564e+001,-6.389257e-007,0.000000e+000,2,0.000000e+000,0.000000e+000,,,,,,,,,,,,,,32,1,4.000000e+000,3.940582e-003,0.000000e+000,0,,0,
1524283705.479,,0.000000e+000,5.500037e+001,-5.387931e-007,0.000000e+000,2,0.000000e+000,0.000000e+000,,,,,,,,,,,,,,32,1,4.000000e+000,1.319885e-003,0.000000e+000,0,,0,
1524283743.239,,0.000000e+000,5.499708e+001,-4.780835e-007,0.000000e+000,2,0.000000e+000,0.000000e+000,,,,,,,,,,,,,,32,1,4.000000e+000,5.260468e-003,0.000000e+000,0,,0,
1524283781.239,,0.000000e+000,5.500037e+001,-4.710293e-007,0.000000e+000,2,0.000000e+000,0.000000e+000,,,,,,,,,,,,,,32,1,4.000000e+000,3.959656e-003,0.000000e+000,0,,0,
1524283818.599,,0.000000e+000,5.500301e+001,-5.184310e-007,0.000000e+000,2,0.000000e+000,0.000000e+000,,,,,,,,,,,,,,32,1,4.000000e+000,1.319885e-003,0.000000e+000,0,,0,
1524283857.009,,0.000000e+000,5.499972e+001,-3.957955e-007,0.000000e+000,2,0.000000e+000,0.000000e+000,,,,,,,,,,,,,,32,1,4.000000e+000,5.268097e-003,0.000000e+000,0,,0,
1524283895.139,,0.000000e+000,5.499708e+001,-3.661145e-007,0.000000e+000,2,0.000000e+000,0.000000e+000,,,,,,,,,,,,,,32,1,4.000000e+000,2.620697e-003,0.000000e+000,0,,0,
1524283932.839,,0.000000e+000,5.499248e+001,-3.641718e-007,0.000000e+000,2,0.000000e+000,0.000000e+000,,,,,,,,,,,,,,32,1,4.000000e+000,6.580353e-003,0.000000e+000,0,,0,
1524283970.809,,0.000000e+000,5.500300e+001,-2.858933e-007,0.000000e+000,2,0.000000e+000,0.000000e+000,,,,,,,,,,,,,,32,1,4.000000e+000,9.220123e-003,0.000000e+000,0,,0,
1524284008.509,,0.000000e+000,5.499511e+001,-2.220894e-007,0.000000e+000,2,0.000000e+000,0.000000e+000,,,,,,,,,,,,,,32,1,4.000000e+000,3.940582e-003,0.000000e+000,0,,0,
1524284046.319,,0.000000e+000,5.499774e+001,-2.016841e-007,0.000000e+000,2,0.000000e+000,0.000000e+000,,,,,,,,,,,,,,32,1,4.000000e+000,3.940582e-003,0.000000e+000,0,,0,
1524284083.869,,0.000000e+000,5.500234e+001,-1.413421e-007,0.000000e+000,2,0.000000e+000,0.000000e+000,,,,,,,,,,,,,,32,1,4.000000e+000,7.900238e-003,0.000000e+000,0,,0,
1524284122.020,,0.000000e+000,5.499773e+001,-1.743881e-007,0.000000e+000,2,0.000000e+000,0.000000e+000,,,,,,,,,,,,,,32,1,4.000000e+000,1.308441e-003,0.000000e+000,0,,0,
1524284159.640,,0.000000e+000,5.499313e+001,-1.184977e-007,0.000000e+000,2,0.000000e+000,0.000000e+000,,,,,,,,,,,,,,32,1,4.000000e+000,1.050949e-002,0.000000e+000,0,,0,
1524284197.520,,0.000000e+000,5.499840e+001,-4.323752e-008,0.000000e+000,2,0.000000e+000,0.000000e+000,,,,,,,,,,,,,,32,1,4.000000e+000,2.628326e-003,0.000000e+000,0,,0,
1524284235.440,,0.000000e+000,5.500695e+001,5.571645e-008,0.000000e+000,2,0.000000e+000,0.000000e+000,,,,,,,,,,,,,,32,1,4.000000e+000,6.568909e-003,0.000000e+000,0,,0,
1524284273.110,,0.000000e+000,5.500169e+001,7.572482e-008,0.000000e+000,2,0.000000e+000,0.000000e+000,,,,,,,,,,,,,,32,1,4.000000e+000,3.959656e-003,0.000000e+000,0,,0,
1524284311.570,,0.000000e+000,5.500300e+001,8.818019e-008,0.000000e+000,2,0.000000e+000,0.000000e+000,,,,,,,,,,,,,,32,1,4.000000e+000,9.220123e-003,0.000000e+000,0,,0,
1524284348.960,,0.000000e+000,5.499773e+001,4.197879e-008,0.000000e+000,2,0.000000e+000,0.000000e+000,,,,,,,,,,,,,,32,1,4.000000e+000,1.308441e-003,0.000000e+000,0,,0,
1524284386.870,,0.000000e+000,5.499511e+001,1.181385e-007,0.000000e+000,2,0.000000e+000,0.000000e+000,,,,,,,,,,,,,,32,1,4.000000e+000,6.568909e-003,0.000000e+000,0,,0,
1524284424.650,,0.000000e+000,5.499577e+001,9.188071e-008,0.000000e+000,2,0.000000e+000,0.000000e+000,,,,,,,,,,,,,,32,1,4.000000e+000,1.316071e-002,0.000000e+000,0,,0,
1524284462.480,,0.000000e+000,5.499577e+001,1.971073e-007,0.000000e+000,2,0.000000e+000,0.000000e+000,,,,,,,,,,,,,,32,1,4.000000e+000,5.249023e-003,0.000000e+000,0,,0,
1524284500.320,,0.000000e+000,5.499577e+001,1.970704e-007,0.000000e+000,2,0.000000e+000,0.000000e+000,,,,,,,,,,,,,,32,1,4.000000e+000,5.249023e-003,0.000000e+000,0,,0,
1524284538.120,,0.000000e+000,5.499445e+001,2.827566e-007,0.000000e+000,2,0.000000e+000,0.000000e+000,,,,,,,,,,,,,,32,1,4.000000e+000,5.260468e-003,0.000000e+000,0,,0,
1524284576.410,,0.000000e+000,5.499774e+001,2.549591e-007,0.000000e+000,2,0.000000e+000,0.000000e+000,,,,,,,,,,,,,,32,1,4.000000e+000,6.580353e-003,0.000000e+000,0,,0,
1524284614.790,,0.000000e+000,5.499905e+001,2.691201e-007,0.000000e+000,2,0.000000e+000,0.000000e+000,,,,,,,,,,,,,,32,1,4.000000e+000,1.319885e-003,0.000000e+000,0,,0,
1524284652.870,,0.000000e+000,5.499379e+001,3.829086e-007,0.000000e+000,2,0.000000e+000,0.000000e+000,,,,,,,,,,,,,,32,1,4.000000e+000,9.201050e-003,0.000000e+000,0,,0,
1524284690.620,,0.000000e+000,5.499971e+001,3.737364e-007,0.000000e+000,2,0.000000e+000,0.000000e+000,,,,,,,,,,,,,,32,1,4.000000e+000,0.000000e+000,0.000000e+000,0,,0,
1524284727.970,,0.000000e+000,5.500037e+001,3.969647e-007,0.000000e+000,2,0.000000e+000,0.000000e+000,,,,,,,,,,,,,,32,1,4.000000e+000,1.709747e-002,0.000000e+000,0,,0,
1524284766.640,,0.000000e+000,5.500169e+001,4.389155e-007,0.000000e+000,2,0.000000e+000,0.000000e+000,,,,,,,,,,,,,,32,1,4.000000e+000,1.446915e-002,0.000000e+000,0,,0,
1524284804.110,,0.000000e+000,5.500169e+001,5.173246e-007,0.000000e+000,2,0.000000e+000,0.000000e+000,,,,,,,,,,,,,,32,1,4.000000e+000,1.446915e-002,0.000000e+000,0,,0,
1524284842.131,,0.000000e+000,5.499905e+001,5.417506e-007,0.000000e+000,2,0.000000e+000,0.000000e+000,,,,,,,,,,,,,,32,1,4.000000e+000,1.319885e-003,0.000000e+000,0,,0,
1524284879.711,,0.000000e+000,5.499380e+001,5.260912e-007,0.000000e+000,2,0.000000e+000,0.000000e+000,,,,,,,,,,,,,,32,1,4.000000e+000,1.308441e-003,0.000000e+000,0,,0,
1524284917.751,,0.000000e+000,5.499840e+001,5.500643e-007,0.000000e+000,2,0.000000e+000,0.000000e+000,,,,,,,,,,,,,,32,1,4.000000e+000,5.260468e-003,0.000000e+000,0,,0,
1524284955.021,,0.000000e+000,5.499511e+001,5.221651e-007,0.000000e+000,2,0.000000e+000,0.000000e+000,,,,,,,,,,,,,,32,1,4.000000e+000,9.201050e-003,0.000000e+000,0,,0,
1524284992.381,,0.000000e+000,5.499577e+001,5.986261e-007,0.000000e+000,2,0.000000e+000,0.000000e+000,,,,,,,,,,,,,,32,1,4.000000e+000,2.632141e-003,0.000000e+000,0,,0,
1524285030.141,,0.000000e+000,5.499841e+001,6.445069e-007,0.000000e+000,2,0.000000e+000,0.000000e+000,,,,,,,,,,,,,,32,1,4.000000e+000,1.052856e-002,0.000000e+000,0,,0,
1524285068.261,,0.000000e+000,5.500103e+001,7.220161e-007,0.000000e+000,2,0.000000e+000,0.000000e+000,,,,,,,,,,,,,,32,1,4.000000e+000,5.279541e-003,0.000000e+000,0,,0,
1524285106.261,,0.000000e+000,5.500103e+001,7.087818e-007,0.000000e+000,2,0.000000e+000,0.000000e+000,,,,,,,,,,,,,,32,1,4.000000e+000,2.639771e-003,0.000000e+000,0,,0,
1524285143.811,,0.000000e+000,5.499445e+001,6.689783e-007,0.000000e+000,2,0.000000e+000,0.000000e+000,,,,,,,,,,,,,,32,1,4.000000e+000,0.000000e+000,0.000000e+000,0,,0,
1524285181.881,,0.000000e+000,5.499773e+001,7.290657e-007,0.000000e+000,2,0.000000e+000,0.000000e+000,,,,,,,,,,,,,,32,1,4.000000e+000,1.308441e-003,0.000000e+000,0,,0,
1524285219.751,,0.000000e+000,5.499773e+001,7.285754e-007,0.000000e+000,2,0.000000e+000,0.000000e+000,,,,,,,,,,,,,,32,1,4.000000e+000,1.308441e-003,0.000000e+000,0,,0,
1524285257.791,,0.000000e+000,5.500234e+001,8.106936e-007,0.000000e+000,2,0.000000e+000,0.000000e+000,,,,,,,,,,,,,,32,1,4.000000e+000,5.260468e-003,0.000000e+000,0,,0,
1524285295.291,,0.000000e+000,5.499840e+001,7.988924e-007,0.000000e+000,2,0.000000e+000,0.000000e+000,,,,,,,,,,,,,,32,1,4.000000e+000,2.628326e-003,0.000000e+000,0,,0,
1524285332.901,,0.000000e+000,5.499905e+001,8.085894e-007,0.000000e+000,2,0.000000e+000,0.000000e+000,,,,,,,,,,,,,,32,1,4.000000e+000,1.319885e-003,0.000000e+000,0,,0,
1524285370.231,,0.000000e+000,5.499709e+001,6.965271e-007,0.000000e+000,2,0.000000e+000,0.000000e+000,,,,,,,,,,,,,,32,1,4.000000e+000,1.316071e-002,0.000000e+000,0,,0,
1524285408.991,,0.000000e+000,5.499445e+001,7.456213e-007,0.000000e+000,2,0.000000e+000,0.000000e+000,,,,,,,,,,,,,,32,1,4.000000e+000,5.260468e-003,0.000000e+000,0,,0,
1524285446.871,,0.000000e+000,5.500498e+001,8.013049e-007,0.000000e+000,2,0.000000e+000,0.000000e+000,,,,,,,,,,,,,,32,1,4.000000e+000,2.620697e-003,0.000000e+000,0,,0,
1524285484.841,,0.000000e+000,5.499972e+001,8.094108e-007,0.000000e+000,2,0.000000e+000,0.000000e+000,,,,,,,,,,,,,,32,1,4.000000e+000,5.268097e-003,0.000000e+000,0,,0,
1524285521.991,,0.000000e+000,5.499840e+001,8.814077e-007,0.000000e+000,2,0.000000e+000,0.000000e+000,,,,,,,,,,,,,,32,1,4.000000e+000,5.260468e-003,0.000000e+000,0,,0,
1524285559.842,,0.000000e+000,5.499511e+001,8.192479e-007,0.000000e+000,2,0.000000e+000,0.000000e+000,,,,,,,,,,,,,,32,1,4.000000e+000,3.940582e-003,0.000000e+000,0,,0,
1524285597.592,,0.000000e+000,5.499971e+001,8.691503e-007,0.000000e+000,2,0.000000e+000,0.000000e+000,,,,,,,,,,,,,,32,1,4.000000e+000,1.052094e-002,0.000000e+000,0,,0,
1524285635.572,,0.000000e+000,5.499445e+001,8.338524e-007,0.000000e+000,2,0.000000e+000,0.000000e+000,,,,,,,,,,,,,,32,1,4.000000e+000,5.260468e-003,0.000000e+000,0,,0,
1524285673.182,,0.000000e+000,5.500235e+001,9.180177e-007,0.000000e+000,2,0.000000e+000,0.000000e+000,,,,,,,,,,,,,,32,1,4.000000e+000,2.639771e-003,0.000000e+000,0,,0,
1524285711.202,,0.000000e+000,5.499905e+001,9.549077e-007,0.000000e+000,2,0.000000e+000,0.000000e+000,,,,,,,,,,,,,,32,1,4.000000e+000,1.319885e-003,0.000000e+000,0,,0,
1524285748.822,,0.000000e+000,5.499971e+001,1.031364e-006,0.000000e+000,2,0.000000e+000,0.000000e+000,,,,,,,,,,,,,,32,1,4.000000e+000,2.639771e-003,0.000000e+000,0,,0,
1524285786.762,,0.000000e+000,5.499511e+001,1.048258e-006,0.000000e+000,2,0.000000e+000,0.000000e+000,,,,,,,,,,,,,,32,1,4.000000e+000,1.319885e-003,0.000000e+000,0,,0,
1524285824.432,,0.000000e+000,5.500037e+001,1.086535e-006,0.000000e+000,2,0.000000e+000,0.000000e+000,,,,,,,,,,,,,,32,1,4.000000e+000,1.319885e-003,0.000000e+000,0,,0,
1524285862.382,,0.000000e+000,5.499708e+001,1.155647e-006,0.000000e+000,2,0.000000e+000,0.000000e+000,,,,,,,,,,,,,,32,1,4.000000e+000,2.620697e-003,0.000000e+000,0,,0,
1524285899.562,,0.000000e+000,5.499841e+001,1.151772e-006,0.000000e+000,2,0.000000e+000,0.000000e+000,,,,,,,,,,,,,,32,1,4.000000e+000,1.052856e-002,0.000000e+000,0,,0,
1524285937.652,,0.000000e+000,5.499774e+001,1.162389e-006,0.000000e+000,2,0.000000e+000,0.000000e+000,,,,,,,,,,,,,,32,1,4.000000e+000,3.940582e-003,0.000000e+000,0,,0,
1524285975.462,,0.000000e+000,5.499709e+001,1.042506e-006,0.000000e+000,2,0.000000e+000,0.000000e+000,,,,,,,,,,,,,,32,1,4.000000e+000,7.888794e-003,0.000000e+000,0,,0,
1524286013.262,,0.000000e+000,5.499709e+001,1.136163e-006,0.000000e+000,2,0.000000e+000,0.000000e+000,,,,,,,,,,,,,,32,1,4.000000e+000,7.888794e-003,0.000000e+000,0,,0,
1524286050.282,,0.000000e+000,5.500235e+001,1.169739e-006,0.000000e+000,2,0.000000e+000,0.000000e+000,,,,,,,,,,,,,,32,1,4.000000e+000,0.000000e+000,0.000000e+000,0,,0,
1524286088.442,,0.000000e+000,5.499380e+001,1.240034e-006,0.000000e+000,2,0.000000e+000,0.000000e+000,,,,,,,,,,,,,,32,1,4.000000e+000,3.948212e-003,0.000000e+000,0,,0,
1524286126.212,,0.000000e+000,5.499840e+001,1.208459e-006,0.000000e+000,2,0.000000e+000,0.000000e+000,,,,,,,,,,,,,,32,1,4.000000e+000,2.628326e-003,0.000000e+000,0,,0,
1524286163.872,,0.000000e+000,5.500497e+001,1.200443e-006,0.000000e+000,2,0.000000e+000,0.000000e+000,,,,,,,,,,,,,,32,1,4.000000e+000,7.888794e-003,0.000000e+000,0,,0,
1524286202.192,,0.000000e+000,5.500169e+001,1.217685e-006,0.000000e+000,2,0.000000e+000,0.000000e+000,,,,,,,,,,,,,,32,1,4.000000e+000,1.319885e-003,0.000000e+000,0,,0,
1524286239.502,,0.000000e+000,5.500037e+001,1.285668e-006,0.000000e+000,2,0.000000e+000,0.000000e+000,,,,,,,,,,,,,,32,1,4.000000e+000,3.959656e-003,0.000000e+000,0,,0,
1524286277.293,,0.000000e+000,5.499709e+001,1.294675e-006,0.000000e+000,2,0.000000e+000,0.000000e+000,,,,,,,,,,,,,,32,1,4.000000e+000,1.052856e-002,0.000000e+000,0,,0,
1524286314.753,,0.000000e+000,5.500037e+001,1.255657e-006,0.000000e+000,2,0.000000e+000,0.000000e+000,,,,,,,,,,,,,,32,1,4.000000e+000,6.587982e-003,0.000000e+000,0,,0,
1524286352.933,,0.000000e+000,5.500366e+001,1.362850e-006,0.000000e+000,2,0.000000e+000,0.000000e+000,,,,,,,,,,,,,,32,1,4.000000e+000,7.900238e-003,0.000000e+000,0,,0,
1524286390.563,,0.000000e+000,5.499840e+001,1.382506e-006,0.000000e+000,2,0.000000e+000,0.000000e+000,,,,,,,,,,,,,,32,1,4.000000e+000,7.900238e-003,0.000000e+000,0,,0,
1524286428.043,,0.000000e+000,5.500432e+001,1.323864e-006,0.000000e+000,2,0.000000e+000,0.000000e+000,,,,,,,,,,,,,,32,1,4.000000e+000,1.446915e-002,0.000000e+000,0,,0,
1524286465.803,,0.000000e+000,5.500432e+001,1.350695e-006,0.000000e+000,2,0.000000e+000,0.000000e+000,,,,,,,,,,,,,,32,1,4.000000e+000,1.300812e-003,0.000000e+000,0,,0,
1524286503.903,,0.000000e+000,5.500498e+001,1.344797e-006,0.000000e+000,2,0.000000e+000,0.000000e+000,,,,,,,,,,,,,,32,1,4.000000e+000,2.620697e-003,0.000000e+000,0,,0,
1524286542.423,,0.000000e+000,5.499643e+001,1.337490e-006,0.000000e+000,2,0.000000e+000,0.000000e+000,,,,,,,,,,,,,,32,1,4.000000e+000,1.312256e-003,0.000000e+000,0,,0,
1524286580.963,,0.000000e+000,5.499906e+001,1.410722e-006,0.000000e+000,2,0.000000e+000,0.000000e+000,,,,,,,,,,,,,,32,1,4.000000e+000,9.220123e-003,0.000000e+000,0,,0,
1524286618.593,,0.000000e+000,5.500037e+001,1.372227e-006,0.000000e+000,2,0.000000e+000,0.000000e+000,,,,,,,,,,,,,,32,1,4.000000e+000,3.959656e-003,0.000000e+000,0,,0,
1524286656.293,,0.000000e+000,5.499840e+001,1.447957e-006,0.000000e+000,2,0.000000e+000,0.000000e+000,,,,,,,,,,,,,,32,1,4.000000e+000,2.628326e-003,0.000000e+000,0,,0,
1524286694.313,,0.000000e+000,5.499577e+001,1.469094e-006,0.000000e+000,2,0.000000e+000,0.000000e+000,,,,,,,,,,,,,,32,1,4.000000e+000,2.632141e-003,0.000000e+000,0,,0,
1524286732.763,,0.000000e+000,5.499182e+001,1.395701e-006,0.000000e+000,2,0.000000e+000,0.000000e+000,,,,,,,,,,,,,,32,1,4.000000e+000,5.260468e-003,0.000000e+000,0,,0,
1524286769.883,,0.000000e+000,5.500169e+001,1.437974e-006,0.000000e+000,2,0.000000e+000,0.000000e+000,,,,,,,,,,,,,,32,1,4.000000e+000,1.319885e-003,0.000000e+000,0,,0,
1524286806.713,,0.000000e+000,5.500103e+001,1.514163e-006,0.000000e+000,2,0.000000e+000,0.000000e+000,,,,,,,,,,,,,,32,1,4.000000e+000,1.052094e-002,0.000000e+000,0,,0,
1524286844.363,,0.000000e+000,5.499511e+001,1.469917e-006,0.000000e+000,2,0.000000e+000,0.000000e+000,,,,,,,,,,,,,,32,1,4.000000e+000,3.940582e-003,0.000000e+000,0,,0,
1524286881.563,,0.000000e+000,5.499773e+001,1.507722e-006,0.000000e+000,2,0.000000e+000,0.000000e+000,,,,,,,,,,,,,,32,1,4.000000e+000,1.308441e-003,0.000000e+000,0,,0,
1524286918.973,,0.000000e+000,5.499313e+001,1.530127e-006,0.000000e+000,2,0.000000e+000,0.000000e+000,,,,,,,,,,,,,,32,1,4.000000e+000,1.314926e-002,0.000000e+000,0,,0,
1524286956.673,,0.000000e+000,5.500169e+001,1.533251e-006,0.000000e+000,2,0.000000e+000,0.000000e+000,,,,,,,,,,,,,,32,1,4.000000e+000,3.959656e-003,0.000000e+000,0,,0,
1524286994.814,,0.000000e+000,5.499971e+001,1.500640e-006,0.000000e+000,2,0.000000e+000,0.000000e+000,,,,,,,,,,,,,,32,1,4.000000e+000,0.000000e+000,0.000000e+000,0,,0,
1524287032.274,,0.000000e+000,5.499248e+001,1.494131e-006,0.000000e+000,2,0.000000e+000,0.000000e+000,,,,,,,,,,,,,,32,1,4.000000e+000,1.319885e-003,0.000000e+000,0,,0,
1524287070.104,,0.000000e+000,5.499840e+001,1.605762e-006,0.000000e+000,2,0.000000e+000,0.000000e+000,,,,,,,,,,,,,,32,1,4.000000e+000,2.628326e-003,0.000000e+000,0,,0,
1524287108.024,,0.000000e+000,5.500103e+001,1.570000e-006,0.000000e+000,2,0.000000e+000,0.000000e+000,,,,,,,,,,,,,,32,1,4.000000e+000,5.279541e-003,0.000000e+000,0,,0,
1524287145.944,,0.000000e+000,5.499117e+001,1.538470e-006,0.000000e+000,2,0.000000e+000,0.000000e+000,,,,,,,,,,,,,,32,1,4.000000e+000,9.208679e-003,0.000000e+000,0,,0,
1524287183.874,,0.000000e+000,5.499642e+001,1.627205e-006,0.000000e+000,2,0.000000e+000,0.000000e+000,,,,,,,,,,,,,,32,1,4.000000e+000,3.940582e-003,0.000000e+000,0,,0,
1524287222.554,,0.000000e+000,5.499577e+001,1.651198e-006,0.000000e+000,2,4.388392e-002,0.000000e+000,,,,,,,,,,,,,,32,1,4.000000e+000,5.249023e-003,0.000000e+000,0,,0,
1524287260.244,,0.000000e+000,5.499511e+001,1.632410e-006,0.000000e+000,2,0.000000e+000,0.000000e+000,,,,,,,,,,,,,,32,1,4.000000e+000,6.568909e-003,0.000000e+000,0,,0,
1524287298.184,,0.000000e+000,5.500168e+001,1.694249e-006,0.000000e+000,2,5.434875e-002,0.000000e+000,,,,,,,,,,,,,,32,1,4.000000e+000,6.580353e-003,0.000000e+000,0,,0,
1524287335.844,,0.000000e+000,5.499380e+001,1.679121e-006,0.000000e+000,2,2.488573e-004,0.000000e+000,,,,,,,,,,,,,,32,1,4.000000e+000,1.308441e-003,0.000000e+000,0,,0,
1524287373.274,,0.000000e+000,5.499774e+001,1.629999e-006,0.000000e+000,2,3.204816e-002,0.000000e+000,,,,,,,,,,,,,,32,1,4.000000e+000,6.580353e-003,0.000000e+000,0,,0,
1524287410.954,,0.000000e+000,5.500169e+001,1.685136e-006,0.000000e+000,2,4.630052e-003,0.000000e+000,,,,,,,,,,,,,,32,1,4.000000e+000,1.319885e-003,0.000000e+000,0,,0,
1524287448.884,,0.000000e+000,5.499511e+001,1.680156e-006,0.000000e+000,2,5.858023e-002,0.000000e+000,,,,,,,,,,,,,,32,1,4.000000e+000,1.319885e-003,0.000000e+000,0,,0,
1524287487.014,,0.000000e+000,5.499314e+001,1.667273e-006,0.000000e+000,2,3.564580e-002,0.000000e+000,,,,,,,,,,,,,,32,1,4.000000e+000,5.260468e-003,0.000000e+000,0,,0,
1524287525.134,,0.000000e+000,5.499511e+001,1.741978e-006,0.000000e+000,2,1.826186e-002,0.000000e+000,,,,,,,,,,,,,,32,1,4.000000e+000,1.319885e-003,0.000000e+000,0,,0,
1524287562.454,,0.000000e+000,5.499643e+001,1.737102e-006,0.000000e+000,2,6.640957e-002,0.000000e+000,,,,,,,,,,,,,,32,1,4.000000e+000,1.312256e-003,0.000000e+000,0,,0,
1524287600.244,,0.000000e+000,5.499905e+001,1.656190e-006,0.000000e+000,2,0.000000e+000,0.000000e+000,,,,,,,,,,,,,,32,1,4.000000e+000,3.948212e-003,0.000000e+000,0,,0,
1524287638.394,,0.000000e+000,5.499643e+001,1.785595e-006,0.000000e+000,2,8.736347e-002,0.000000e+000,,,,,,,,,,,,,,32,1,4.000000e+000,1.312256e-003,0.000000e+000,0,,0,
1524287676.904,,0.000000e+000,5.500235e+001,1.766601e-006,0.000000e+000,2,1.174702e-001,0.000000e+000,,,,,,,,,,,,,,32,1,4.000000e+000,2.639771e-003,0.000000e+000,0,,0,
1524287714.775,,0.000000e+000,5.499183e+001,1.698124e-006,0.000000e+000,2,4.870621e-002,0.000000e+000,,,,,,,,,,,,,,32,1,4.000000e+000,2.632141e-003,0.000000e+000,0,,0,
1524287752.385,,0.000000e+000,5.499839e+001,1.806203e-006,0.000000e+000,2,1.009176e-001,0.000000e+000,,,,,,,,,,,,,,32,1,4.000000e+000,0.000000e+000,0.000000e+000,0,,0,
1524287790.305,,0.000000e+000,5.499577e+001,1.744474e-006,0.000000e+000,2,7.897662e-002,0.000000e+000,,,,,,,,,,,,,,32,1,4.000000e+000,1.052094e-002,0.000000e+000,0,,0,
1524287828.775,,0.000000e+000,5.499511e+001,1.788035e-006,0.000000e+000,2,9.065987e-002,0.000000e+000,,,,,,,,,,,,,,32,1,4.000000e+000,3.940582e-003,0.000000e+000,0,,0,
1524287866.265,,0.000000e+000,5.499905e+001,1.792747e-006,0.000000e+000,2,8.487945e-002,0.000000e+000,,,,,,,,,,,,,,32,1,4.000000e+000,1.972961e-002,0.000000e+000,0,,0,
1524287903.845,,0.000000e+000,5.499906e+001,1.792006e-006,0.000000e+000,2,1.015489e-001,0.000000e+000,,,,,,,,,,,,,,32,1,4.000000e+000,9.220123e-003,0.000000e+000,0,,0,
1524287941.445,,0.000000e+000,5.499773e+001,1.874499e-006,0.000000e+000,2,1.171750e-001,0.000000e+000,,,,,,,,,,,,,,32,1,4.000000e+000,1.308441e-003,0.000000e+000,0,,0,
1524287978.625,,0.000000e+000,5.500234e+001,1.822154e-006,0.000000e+000,2,5.785006e-002,0.000000e+000,,,,,,,,,,,,,,32,1,4.000000e+000,5.260468e-003,0.000000e+000,0,,0,
1524288016.285,,0.000000e+000,5.499577e+001,1.802341e-006,0.000000e+000,2,8.616909e-002,0.000000e+000,,,,,,,,,,,,,,32,1,4.000000e+000,2.632141e-003,0.000000e+000,0,,0,
1524288054.255,,0.000000e+000,5.499511e+001,1.786569e-006,0.000000e+000,2,9.353215e-002,0.000000e+000,,,,,,,,,,,,,,32,1,4.000000e+000,3.940582e-003,0.000000e+000,0,,0,
1524288091.935,,0.000000e+000,5.499709e+001,1.871504e-006,0.000000e+000,2,9.483126e-002,0.000000e+000,,,,,,,,,,,,,,32,1,4.000000e+000,7.888794e-003,0.000000e+000,0,,0,
1524288130.845,,0.000000e+000,5.500366e+001,1.876253e-006,0.000000e+000,2,1.482319e-001,0.000000e+000,,,,,,,,,,,,,,32,1,4.000000e+000,2.620697e-003,0.000000e+000,0,,0,
1524288169.745,,0.000000e+000,5.500234e+001,1.823237e-006,0.000000e+000,2,1.338529e-001,0.000000e+000,,,,,,,,,,,,,,32,1,4.000000e+000,5.260468e-003,0.000000e+000,0,,0,
1524288208.025,,0.000000e+000,5.500365e+001,1.876553e-006,0.000000e+000,2,1.005968e-001,0.000000e+000,,,,,,,,,,,,,,32,1,4.000000e+000,1.052856e-002,0.000000e+000,0,,0,
1524288245.485,,0.000000e+000,5.499511e+001,1.821668e-006,0.000000e+000,2,9.902497e-002,0.000000e+000,,,,,,,,,,,,,,32,1,4.000000e+000,1.319885e-003,0.000000e+000,0,,0,
1524288283.325,,0.000000e+000,5.499511e+001,1.869855e-006,0.000000e+000,2,1.427448e-001,0.000000e+000,,,,,,,,,,,,,,32,1,4.000000e+000,3.940582e-003,0.000000e+000,0,,0,
1524288321.065,,0.000000e+000,5.500169e+001,1.897275e-006,0.000000e+000,2,1.378469e-001,0.000000e+000,,,,,,,,,,,,,,32,1,4.000000e+000,3.959656e-003,0.000000e+000,0,,0,
1524288358.965,,0.000000e+000,5.499511e+001,1.868454e-006,0.000000e+000,2,1.476946e-001,0.000000e+000,,,,,,,,,,,,,,32,1,4.000000e+000,3.940582e-003,0.000000e+000,0,,0,
1524288396.705,,0.000000e+000,5.500037e+001,1.963949e-006,0.000000e+000,2,1.595534e-001,0.000000e+000,,,,,,,,,,,,,,32,1,4.000000e+000,1.709747e-002,0.000000e+000,0,,0,
1524288434.586,,0.000000e+000,5.499248e+001,1.900278e-006,0.000000e+000,2,1.572212e-001,0.000000e+000,,,,,,,,,,,,,,32,1,4.000000e+000,9.201050e-003,0.000000e+000,0,,0,
1524288472.316,,0.000000e+000,5.499774e+001,1.930661e-006,0.000000e+000,2,1.369979e-001,0.000000e+000,,,,,,,,,,,,,,32,1,4.000000e+000,6.580353e-003,0.000000e+000,0,,0,
1524288510.206,,0.000000e+000,5.499774e+001,1.950328e-006,0.000000e+000,2,1.774697e-001,0.000000e+000,,,,,,,,,,,,,,32,1,4.000000e+000,6.580353e-003,0.000000e+000,0,,0,
1524288547.996,,0.000000e+000,5.500037e+001,1.990210e-006,0.000000e+000,2,1.568193e-001,0.000000e+000,,,,,,,,,,,,,,32,1,4.000000e+000,6.587982e-003,0.000000e+000,0,,0,
1524288585.806,,0.000000e+000,5.499577e+001,1.917056e-006,0.000000e+000,2,1.549078e-001,0.000000e+000,,,,,,,,,,,,,,32,1,4.000000e+000,2.632141e-003,0.000000e+000,0,,0,
1524288623.556,,0.000000e+000,5.499511e+001,1.955730e-006,0.000000e+000,2,1.616928e-001,0.000000e+000,,,,,,,,,,,,,,32,1,4.000000e+000,3.940582e-003,0.000000e+000,0,,0,
1524288661.216,,0.000000e+000,5.499971e+001,1.900132e-006,0.000000e+000,2,1.583710e-001,0.000000e+000,,,,,,,,,,,,,,32,1,4.000000e+000,2.639771e-003,0.000000e+000,0,,0,
1524288698.876,,0.000000e+000,5.499971e+001,1.958545e-006,0.000000e+000,2,1.471572e-001,0.000000e+000,,,,,,,,,,,,,,32,1,4.000000e+000,1.052094e-002,0.000000e+000,0,,0,
1524288736.356,,0.000000e+000,5.499971e+001,1.977173e-006,0.000000e+000,2,1.917225e-001,0.000000e+000,,,,,,,,,,,,,,32,1,4.000000e+000,0.000000e+000,0.000000e+000,0,,0,
1524288773.676,,0.000000e+000,5.500366e+001,1.968785e-006,0.000000e+000,2,1.324243e-001,0.000000e+000,,,,,,,,,,,,,,32,1,4.000000e+000,2.620697e-003,0.000000e+000,0,,0,
1524288811.646,,0.000000e+000,5.499774e+001,2.047184e-006,0.000000e+000,2,1.874196e-001,0.000000e+000,,,,,,,,,,,,,,32,1,4.000000e+000,6.580353e-003,0.000000e+000,0,,0,
1524288849.636,,0.000000e+000,5.500169e+001,2.006140e-006,0.000000e+000,2,1.849339e-001,0.000000e+000,,,,,,,,,,,,,,32,1,4.000000e+000,1.319885e-003,0.000000e+000,0,,0,
1524288887.246,,0.000000e+000,5.499905e+001,2.013301e-006,0.000000e+000,2,1.778080e-001,0.000000e+000,,,,,,,,,,,,,,32,1,4.000000e+000,1.319885e-003,0.000000e+000,0,,0,
1524288925.266,,0.000000e+000,5.499905e+001,2.018994e-006,0.000000e+000,2,1.966007e-001,0.000000e+000,,,,,,,,,,,,,,32,1,4.000000e+000,1.319885e-003,0.000000e+000,0,,0,
1524288962.756,,0.000000e+000,5.499577e+001,2.054537e-006,0.000000e+000,2,1.980802e-001,0.000000e+000,,,,,,,,,,,,,,32,1,4.000000e+000,5.249023e-003,0.000000e+000,0,,0,
1524289000.866,,0.000000e+000,5.500169e+001,2.055595e-006,0.000000e+000,2,2.075097e-001,0.000000e+000,,,,,,,,,,,,,,32,1,4.000000e+000,1.319885e-003,0.000000e+000,0,,0,
1524289038.226,,0.000000e+000,5.499511e+001,2.038165e-006,0.000000e+000,2,1.656261e-001,0.000000e+000,,,,,,,,,,,,,,32,1,4.000000e+000,9.201050e-003,0.000000e+000,0,,0,
1524289075.986,,0.000000e+000,5.499708e+001,2.033020e-006,0.000000e+000,2,1.992261e-001,0.000000e+000,,,,,,,,,,,,,,32,1,4.000000e+000,5.260468e-003,0.000000e+000,0,,0,
1524289113.767,,0.000000e+000,5.499643e+001,2.071251e-006,0.000000e+000,2,1.910235e-001,0.000000e+000,,,,,,,,,,,,,,32,1,4.000000e+000,1.312256e-003,0.000000e+000,0,,0,
1524289151.737,,0.000000e+000,5.499774e+001,2.052118e-006,0.000000e+000,2,1.935564e-001,0.000000e+000,,,,,,,,,,,,,,32,1,4.000000e+000,3.940582e-003,0.000000e+000,0,,0,
1524289189.687,,0.000000e+000,5.499708e+001,2.001704e-006,0.000000e+000,2,1.928193e-001,0.000000e+000,,,,,,,,,,,,,,32,1,4.000000e+000,5.260468e-003,0.000000e+000,0,,0,
1524289227.187,,0.000000e+000,5.499774e+001,2.127865e-006,0.000000e+000,2,2.336342e-001,0.000000e+000,,,,,,,,,,,,,,32,1,4.000000e+000,3.940582e-003,0.000000e+000,0,,0,
1524289265.007,,0.000000e+000,5.499708e+001,2.099939e-006,0.000000e+000,2,2.472594e-001,0.000000e+000,,,,,,,,,,,,,,32,1,4.000000e+000,2.620697e-003,0.000000e+000,0,,0,
1524289302.137,,0.000000e+000,5.499971e+001,2.095274e-006,0.000000e+000,2,2.011432e-001,0.000000e+000,,,,,,,,,,,,,,32,1,4.000000e+000,2.639771e-003,0.000000e+000,0,,0,
1524289339.707,,0.000000e+000,5.500234e+001,2.136534e-006,0.000000e+000,2,2.438175e-001,0.000000e+000,,,,,,,,,,,,,,32,1,4.000000e+000,7.900238e-003,0.000000e+000,0,,0,
1524289377.207,,0.000000e+000,5.499840e+001,2.130981e-006,0.000000e+000,2,2.110353e-001,0.000000e+000,,,,,,,,,,,,,,32,1,4.000000e+000,2.628326e-003,0.000000e+000,0,,0,
1524289414.747,,0.000000e+000,5.500103e+001,2.148876e-006,0.000000e+000,2,2.347647e-001,0.000000e+000,,,,,,,,,,,,,,32,1,4.000000e+000,2.639771e-003,0.000000e+000,0,,0,
1524289452.367,,0.000000e+000,5.499840e+001,2.069907e-006,0.000000e+000,2,2.155941e-001,0.000000e+000,,,,,,,,,,,,,,32,1,4.000000e+000,1.314926e-002,0.000000e+000,0,,0,
1524289491.457,,0.000000e+000,5.499708e+001,2.116591e-006,0.000000e+000,2,2.141291e-001,0.000000e+000,,,,,,,,,,,,,,32,1,4.000000e+000,2.620697e-003,0.000000e+000,0,,0,
1524289529.017,,0.000000e+000,5.500037e+001,2.178098e-006,0.000000e+000,2,2.321670e-001,0.000000e+000,,,,,,,,,,,,,,32,1,4.000000e+000,1.319885e-003,0.000000e+000,0,,0,
1524289567.017,,0.000000e+000,5.499905e+001,2.165109e-006,0.000000e+000,2,2.435042e-001,0.000000e+000,,,,,,,,,,,,,,32,1,4.000000e+000,1.319885e-003,0.000000e+000,0,,0,
1524289604.527,,0.000000e+000,5.499905e+001,2.154312e-006,0.000000e+000,2,1.934469e-001,0.000000e+000,,,,,,,,,,,,,,32,1,4.000000e+000,1.182938e-002,0.000000e+000,0,,0,
1524289642.387,,0.000000e+000,5.499380e+001,2.206721e-006,0.000000e+000,2,2.350769e-001,0.000000e+000,,,,,,,,,,,,,,32,1,4.000000e+000,1.182938e-002,0.000000e+000,0,,0,
1524289680.477,,0.000000e+000,5.499905e+001,2.149473e-006,0.000000e+000,2,2.589219e-001,0.000000e+000,,,,,,,,,,,,,,32,1,4.000000e+000,1.319885e-003,0.000000e+000,0,,0,
1524289718.427,,0.000000e+000,5.499380e+001,2.168097e-006,0.000000e+000,2,2.216383e-001,0.000000e+000,,,,,,,,,,,,,,32,1,4.000000e+000,1.182938e-002,0.000000e+000,0,,0,
1524289755.987,,0.000000e+000,5.499642e+001,2.200919e-006,0.000000e+000,2,2.693819e-001,0.000000e+000,,,,,,,,,,,,,,32,1,4.000000e+000,3.940582e-003,0.000000e+000,0,,0,
1524289792.867,,0.000000e+000,5.499313e+001,2.195509e-006,0.000000e+000,2,2.251568e-001,0.000000e+000,,,,,,,,,,,,,,32,1,4.000000e+000,1.314926e-002,0.000000e+000,0,,0,
1524289830.578,,0.000000e+000,5.499577e+001,2.207007e-006,0.000000e+000,2,2.578443e-001,0.000000e+000,,,,,,,,,,,,,,32,1,4.000000e+000,2.632141e-003,0.000000e+000,0,,0,
1524289868.728,,0.000000e+000,5.498722e+001,2.133798e-006,0.000000e+000,2,2.245692e-001,0.000000e+000,,,,,,,,,,,,,,32,1,4.000000e+000,6.580353e-003,0.000000e+000,0,,0,
1524289906.628,,0.000000e+000,5.499905e+001,2.198354e-006,0.000000e+000,2,2.342129e-001,0.000000e+000,,,,,,,,,,,,,,32,1,4.000000e+000,1.319885e-003,0.000000e+000,0,,0,
1524289944.528,,0.000000e+000,5.499905e+001,2.227545e-006,0.000000e+000,2,2.556044e-001,0.000000e+000,,,,,,,,,,,,,,32,1,4.000000e+000,1.319885e-003,0.000000e+000,0,,0,
1524289982.488,,0.000000e+000,5.499840e+001,2.174533e-006,0.000000e+000,2,2.137735e-001,0.000000e+000,,,,,,,,,,,,,,32,1,4.000000e+000,2.628326e-003,0.000000e+000,0,,0,
1524290020.338,,0.000000e+000,5.499972e+001,2.243567e-006,0.000000e+000,2,2.945638e-001,0.000000e+000,,,,,,,,,,,,,,32,1,4.000000e+000,5.268097e-003,0.000000e+000,0,,0,
1524290058.098,,0.000000e+000,5.499577e+001,2.228300e-006,0.000000e+000,2,2.385972e-001,0.000000e+000,,,,,,,,,,,,,,32,1,4.000000e+000,5.249023e-003,0.000000e+000,0,,0,
1524290095.768,,0.000000e+000,5.499380e+001,2.247370e-006,0.000000e+000,2,2.739844e-001,0.000000e+000,,,,,,,,,,,,,,32,1,4.000000e+000,3.948212e-003,0.000000e+000,0,,0,
1524290134.218,,0.000000e+000,5.499972e+001,2.301542e-006,0.000000e+000,2,2.830975e-001,0.000000e+000,,,,,,,,,,,,,,32,1,4.000000e+000,5.268097e-003,0.000000e+000,0,,0,
1524290172.078,,0.000000e+000,5.499577e+001,2.185429e-006,0.000000e+000,2,2.194647e-001,0.000000e+000,,,,,,,,,,,,,,32,1,4.000000e+000,5.249023e-003,0.000000e+000,0,,0,
1524290210.248,,0.000000e+000,5.499905e+001,2.227269e-006,0.000000e+000,2,2.612858e-001,0.000000e+000,,,,,,,,,,,,,,32,1,4.000000e+000,1.319885e-003,0.000000e+000,0,,0,
1524290248.368,,0.000000e+000,5.499709e+001,2.234843e-006,0.000000e+000,2,2.908529e-001,0.000000e+000,,,,,,,,,,,,,,32,1,4.000000e+000,1.316071e-002,0.000000e+000,0,,0,
1524290286.068,,0.000000e+000,5.500301e+001,2.252005e-006,0.000000e+000,2,2.574677e-001,0.000000e+000,,,,,,,,,,,,,,32,1,4.000000e+000,1.319885e-003,0.000000e+000,0,,0,
1524290324.238,,0.000000e+000,5.500037e+001,2.314324e-006,0.000000e+000,2,2.904915e-001,0.000000e+000,,,,,,,,,,,,,,32,1,4.000000e+000,1.319885e-003,0.000000e+000,0,,0,
1524290362.088,,0.000000e+000,5.500497e+001,2.266280e-006,0.000000e+000,2,2.914192e-001,0.000000e+000,,,,,,,,,,,,,,32,1,4.000000e+000,7.888794e-003,0.000000e+000,0,,0,
1524290399.308,,0.000000e+000,5.500037e+001,2.272946e-006,0.000000e+000,2,2.710750e-001,0.000000e+000,,,,,,,,,,,,,,32,1,4.000000e+000,9.201050e-003,0.000000e+000,0,,0,
1524290437.298,,0.000000e+000,5.500169e+001,2.309270e-006,0.000000e+000,2,2.886379e-001,0.000000e+000,,,,,,,,,,,,,,32,1,4.000000e+000,9.208679e-003,0.000000e+000,0,,0,
1524290474.998,,0.000000e+000,5.499709e+001,2.265996e-006,0.000000e+000,2,2.661247e-001,0.000000e+000,,,,,,,,,,,,,,32,1,4.000000e+000,7.888794e-003,0.000000e+000,0,,0,
1524290512.648,,0.000000e+000,5.499840e+001,2.288481e-006,0.000000e+000,2,3.069018e-001,0.000000e+000,,,,,,,,,,,,,,32,1,4.000000e+000,7.900238e-003,0.000000e+000,0,,0,
1524290550.439,,0.000000e+000,5.500168e+001,2.222906e-006,0.000000e+000,2,2.588438e-001,0.000000e+000,,,,,,,,,,,,,,32,1,4.000000e+000,6.580353e-003,0.000000e+000,0,,0,
1524290588.289,,0.000000e+000,5.500037e+001,2.313796e-006,0.000000e+000,2,2.846682e-001,0.000000e+000,,,,,,,,,,,,,,32,1,4.000000e+000,3.959656e-003,0.000000e+000,0,,0,
1524290626.299,,0.000000e+000,5.499445e+001,2.308150e-006,0.000000e+000,2,3.098356e-001,0.000000e+000,,,,,,,,,,,,,,32,1,4.000000e+000,7.881165e-003,0.000000e+000,0,,0,
1524290663.959,,0.000000e+000,5.499773e+001,2.329698e-006,0.000000e+000,2,2.758449e-001,0.000000e+000,,,,,,,,,,,,,,32,1,4.000000e+000,1.308441e-003,0.000000e+000,0,,0,
1524290701.889,,0.000000e+000,5.499906e+001,2.367418e-006,0.000000e+000,2,3.139604e-001,0.000000e+000,,,,,,,,,,,,,,32,1,4.000000e+000,6.580353e-003,0.000000e+000,0,,0,
1524290739.569,,0.000000e+000,5.499971e+001,2.327757e-006,0.000000e+000,2,2.786085e-001,0.000000e+000,,,,,,,,,,,,,,32,1,4.000000e+000,0.000000e+000,0.000000e+000,0,,0,
1524290777.519,,0.000000e+000,5.499971e+001,2.364393e-006,0.000000e+000,2,3.092400e-001,0.000000e+000,,,,,,,,,,,,,,32,1,4.000000e+000,0.000000e+000,0.000000e+000,0,,0,
1524290815.169,,0.000000e+000,5.499774e+001,2.330508e-006,0.000000e+000,2,2.826667e-001,0.000000e+000,,,,,,,,,,,,,,32,1,4.000000e+000,3.940582e-003,0.000000e+000,0,,0,
1524290852.869,,0.000000e+000,5.499971e+001,2.317112e-006,0.000000e+000,2,2.916487e-001,0.000000e+000,,,,,,,,,,,,,,32,1,4.000000e+000,2.639771e-003,0.000000e+000,0,,0,
1524290890.319,,0.000000e+000,5.499839e+001,2.341713e-006,0.000000e+000,2,2.521601e-001,0.000000e+000,,,,,,,,,,,,,,32,1,4.000000e+000,0.000000e+000,0.000000e+000,0,,0,
1524290928.209,,0.000000e+000,5.499643e+001,2.360503e-006,0.000000e+000,2,3.050374e-001,0.000000e+000,,,,,,,,,,,,,,32,1,4.000000e+000,1.312256e-003,0.000000e+000,0,,0,
1524290965.549,,0.000000e+000,5.499840e+001,2.345480e-006,0.000000e+000,2,2.609760e-001,0.000000e+000,,,,,,,,,,,,,,32,1,4.000000e+000,7.900238e-003,0.000000e+000,0,,0,
1524291002.669,,0.000000e+000,5.500432e+001,2.330087e-006,0.000000e+000,2,3.244104e-001,0.000000e+000,,,,,,,,,,,,,,32,1,4.000000e+000,1.710129e-002,0.000000e+000,0,,0,
1524291040.249,,0.000000e+000,5.500498e+001,2.361941e-006,0.000000e+000,2,2.841874e-001,0.000000e+000,,,,,,,,,,,,,,32,1,4.000000e+000,5.260468e-003,0.000000e+000,0,,0,
1524291078.069,,0.000000e+000,5.499972e+001,2.311148e-006,0.000000e+000,2,2.949307e-001,0.000000e+000,,,,,,,,,,,,,,32,1,4.000000e+000,7.900238e-003,0.000000e+000,0,,0,
1524291115.409,,0.000000e+000,5.500037e+001,2.357980e-006,0.000000e+000,2,2.910526e-001,0.000000e+000,,,,,,,,,,,,,,32,1,4.000000e+000,1.184082e-002,0.000000e+000,0,,0,
1524291154.069,,0.000000e+000,5.499379e+001,2.360458e-006,0.000000e+000,2,3.198445e-001,0.000000e+000,,,,,,,,,,,,,,32,1,4.000000e+000,9.201050e-003,0.000000e+000,0,,0,
1524291191.509,,0.000000e+000,5.500103e+001,2.383097e-006,0.000000e+000,2,2.886139e-001,0.000000e+000,,,,,,,,,,,,,,32,1,4.000000e+000,2.639771e-003,0.000000e+000,0,,0,
1524291229.549,,0.000000e+000,5.499445e+001,2.398763e-006,0.000000e+000,2,3.370023e-001,0.000000e+000,,,,,,,,,,,,,,32,1,4.000000e+000,2.628326e-003,0.000000e+000,0,,0,
1524291266.440,,0.000000e+000,5.499577e+001,2.405024e-006,0.000000e+000,2,2.971805e-001,0.000000e+000,,,,,,,,,,,,,,32,1,4.000000e+000,2.632141e-003,0.000000e+000,0,,0,
1524291304.050,,0.000000e+000,5.499642e+001,2.388793e-006,0.000000e+000,2,3.438730e-001,0.000000e+000,,,,,,,,,,,,,,32,1,4.000000e+000,3.940582e-003,0.000000e+000,0,,0,
1524291341.360,,0.000000e+000,5.499775e+001,2.389159e-006,0.000000e+000,2,2.900721e-001,0.000000e+000,,,,,,,,,,,,,,32,1,4.000000e+000,9.208679e-003,0.000000e+000,0,,0,
1524291378.790,,0.000000e+000,5.499643e+001,2.407789e-006,0.000000e+000,2,3.061678e-001,0.000000e+000,,,,,,,,,,,,,,32,1,4.000000e+000,1.312256e-003,0.000000e+000,0,,0,
1524291416.770,,0.000000e+000,5.500103e+001,2.358834e-006,0.000000e+000,2,3.165421e-001,0.000000e+000,,,,,,,,,,,,,,32,1,4.000000e+000,2.639771e-003,0.000000e+000,0,,0,
1524291454.490,,0.000000e+000,5.500366e+001,2.369504e-006,0.000000e+000,2,2.948807e-001,0.000000e+000,,,,,,,,,,,,,,32,1,4.000000e+000,5.260468e-003,0.000000e+000,0,,0,
1524291492.320,,0.000000e+000,5.499708e+001,2.408538e-006,0.000000e+000,2,3.224992e-001,0.000000e+000,,,,,,,,,,,,,,32,1,4.000000e+000,2.620697e-003,0.000000e+000,0,,0,
1524291530.840,,0.000000e+000,5.500037e+001,2.429921e-006,0.000000e+000,2,3.386522e-001,0.000000e+000,,,,,,,,,,,,,,32,1,4.000000e+000,9.201050e-003,0.000000e+000,0,,0,
1524291567.950,,0.000000e+000,5.499840e+001,2.396827e-006,0.000000e+000,2,2.907292e-001,0.000000e+000,,,,,,,,,,,,,,32,1,4.000000e+000,5.260468e-003,0.000000e+000,0,,0,
1524291605.940,,0.000000e+000,5.499840e+001,2.464963e-006,0.000000e+000,2,3.185945e-001,0.000000e+000,,,,,,,,,,,,,,32,1,4.000000e+000,1.314926e-002,0.000000e+000,0,,0,
1524291644.110,,0.000000e+000,5.499445e+001,2.407070e-006,0.000000e+000,2,3.340552e-001,0.000000e+000,,,,,,,,,,,,,,32,1,4.000000e+000,1.052094e-002,0.000000e+000,0,,0,
1524291681.510,,0.000000e+000,5.500037e+001,2.402117e-006,0.000000e+000,2,2.982251e-001,0.000000e+000,,,,,,,,,,,,,,32,1,4.000000e+000,1.319885e-003,0.000000e+000,0,,0,
1524291719.320,,0.000000e+000,5.499380e+001,2.476938e-006,0.000000e+000,2,3.649445e-001,0.000000e+000,,,,,,,,,,,,,,32,1,4.000000e+000,1.308441e-003,0.000000e+000,0,,0,
1524291756.910,,0.000000e+000,5.499445e+001,2.437215e-006,0.000000e+000,2,2.831636e-001,0.000000e+000,,,,,,,,,,,,,,32,1,4.000000e+000,2.628326e-003,0.000000e+000,0,,0,
1524291795.110,,0.000000e+000,5.499840e+001,2.425748e-006,0.000000e+000,2,3.085495e-001,0.000000e+000,,,,,,,,,,,,,,32,1,4.000000e+000,5.260468e-003,0.000000e+000,0,,0,
1524291833.100,,0.000000e+000,5.500103e+001,2.358652e-006,0.000000e+000,2,2.764379e-001,0.000000e+000,,,,,,,,,,,,,,32,1,4.000000e+000,2.639771e-003,0.000000e+000,0,,0,
1524291870.690,,0.000000e+000,5.499905e+001,2.448753e-006,0.000000e+000,2,3.310878e-001,0.000000e+000,,,,,,,,,,,,,,32,1,4.000000e+000,1.182938e-002,0.000000e+000,0,,0,
1524291908.670,,0.000000e+000,5.499840e+001,2.416197e-006,0.000000e+000,2,3.209307e-001,0.000000e+000,,,,,,,,,,,,,,32,1,4.000000e+000,2.628326e-003,0.000000e+000,0,,0,
1524291946.430,,0.000000e+000,5.499445e+001,2.485588e-006,0.000000e+000,2,3.436136e-001,0.000000e+000,,,,,,,,,,,,,,32,1,4.000000e+000,7.881165e-003,0.000000e+000,0,,0,
1524291984.271,,0.000000e+000,5.499643e+001,2.424619e-006,0.000000e+000,2,3.224504e-001,0.000000e+000,,,,,,,,,,,,,,32,1,4.000000e+000,6.568909e-003,0.000000e+000,0,,0,
1524292022.011,,0.000000e+000,5.500037e+001,2.475724e-006,0.000000e+000,2,3.384321e-001,0.000000e+000,,,,,,,,,,,,,,32,1,4.000000e+000,1.446915e-002,0.000000e+000,0,,0,
1524292059.871,,0.000000e+000,5.499380e+001,2.451932e-006,0.000000e+000,2,3.243546e-001,0.000000e+000,,,,,,,,,,,,,,32,1,4.000000e+000,1.308441e-003,0.000000e+000,0,,0,
1524292097.591,,0.000000e+000,5.499445e+001,2.457657e-006,0.000000e+000,2,3.319629e-001,0.000000e+000,,,,,,,,,,,,,,32,1,4.000000e+000,1.052094e-002,0.000000e+000,0,,0,
1524292135.471,,0.000000e+000,5.499511e+001,2.467042e-006,0.000000e+000,2,3.430000e-001,0.000000e+000,,,,,,,,,,,,,,32,1,4.000000e+000,1.319885e-003,0.000000e+000,0,,0,
1524292173.211,,0.000000e+000,5.499643e+001,2.517303e-006,0.000000e+000,2,3.409382e-001,0.000000e+000,,,,,,,,,,,,,,32,1,4.000000e+000,1.312256e-003,0.000000e+000,0,,0,
1524292210.851,,0.000000e+000,5.500103e+001,2.380812e-006,0.000000e+000,2,3.148988e-001,0.000000e+000,,,,,,,,,,,,,,32,1,4.000000e+000,7.888794e-003,0.000000e+000,0,,0,
1524292248.411,,0.000000e+000,5.499905e+001,2.506063e-006,0.000000e+000,2,3.314031e-001,0.000000e+000,,,,,,,,,,,,,,32,1,4.000000e+000,3.948212e-003,0.000000e+000,0,,0,
1524292286.361,,0.000000e+000,5.499380e+001,2.482690e-006,0.000000e+000,2,3.445298e-001,0.000000e+000,,,,,,,,,,,,,,32,1,4.000000e+000,1.446915e-002,0.000000e+000,0,,0,
1524292323.941,,0.000000e+000,5.499774e+001,2.452095e-006,0.000000e+000,2,2.917526e-001,0.000000e+000,,,,,,,,,,,,,,32,1,4.000000e+000,3.940582e-003,0.000000e+000,0,,0,
1524292361.831,,0.000000e+000,5.499971e+001,2.569663e-006,0.000000e+000,2,3.474061e-001,0.000000e+000,,,,,,,,,,,,,,32,1,4.000000e+000,0.000000e+000,0.000000e+000,0,,0,
1524292399.791,,0.000000e+000,5.500497e+001,2.493765e-006,0.000000e+000,2,3.662528e-001,0.000000e+000,,,,,,,,,,,,,,32,1,4.000000e+000,7.888794e-003,0.000000e+000,0,,0,
1524292437.531,,0.000000e+000,5.499905e+001,2.481956e-006,0.000000e+000,2,3.384039e-001,0.000000e+000,,,,,,,,,,,,,,32,1,4.000000e+000,1.319885e-003,0.000000e+000,0,,0,
1524292475.261,,0.000000e+000,5.500103e+001,2.543937e-006,0.000000e+000,2,3.768543e-001,0.000000e+000,,,,,,,,,,,,,,32,1,4.000000e+000,2.368164e-002,0.000000e+000,0,,0,
1524292512.701,,0.000000e+000,5.500366e+001,2.550970e-006,0.000000e+000,2,3.425582e-001,0.000000e+000,,,,,,,,,,,,,,32,1,4.000000e+000,2.620697e-003,0.000000e+000,0,,0,
1524292549.871,,0.000000e+000,5.499445e+001,2.559048e-006,0.000000e+000,2,3.659715e-001,0.000000e+000,,,,,,,,,,,,,,32,1,4.000000e+000,7.881165e-003,0.000000e+000,0,,0,
1524292562.271,,0.000000e+000,5.500432e+001,2.473694e-006,0.000000e+000,2,3.151611e-001,0.000000e+000,,,,,,,,,,,,,,32,1,4.000000e+000,3.940582e-003,0.000000e+000,0,,0,