File: Input_All/TC04-12-01K_VRMac_56K_6000s_VRMde_55K.dc.dat
[Header]
TITLE,MPMS DC Measurement
BYAPP,MPMS Measurement,2.1,Summary
FILEOPENTIME, 1524261952.828000 4/20/2018, 4:05:52 PM

INFO, APPNAME, MPMS MultiVu Application, Revision 1.61,  Build 082

INFO, NAME, TC04-12-01K
INFO, WEIGHT, 1.000
INFO, AREA, 1.000
INFO, LENGTH, 1.000
INFO, SHAPE, 0
INFO, COMMENT,
INFO, SEQUENCE FILE: VRMac_56K_6000s_VRMde_55K.seq


INFO, BACKGROUND DATA FILE:, None


STARTUPAXIS,X,4,LINEAR,AUTO,0.000000,0.000000
STARTUPAXIS,Y1,5,LINEAR,AUTO,0.000000,0.000000


STARTUPGROUP,Longitudinal
FIELDGROUP,Longitudinal,1,2,3,4,5,6,7,8,9,15,16,17,18,27,28
FIELDGROUP,Transverse,1,2,3,4,10,11,12,13,14,19,20,21,22,27,28

PLOT_APPEARANCE,ALL,HORZ_GRID_ON,VERT_GRID_ON,MARKERS_AND_LINES

[Data]
Time,Comment,Field (Oe),Temperature (K),Long Moment (emu),Long Scan Std Dev,Long Algorithm,Long Reg Fit,Long Percent Error (%),Trans Moment (emu),Trans Scan Std Dev,Trans Algorithm,Trans Reg Fit,Trans Percent Error (%),Long Moment [w/o ABS] (emu),Long Scan Std Dev [w/o ABS],Long Reg Fit [w/o ABS],Long Percent Error [w/o ABS] (%),Trans Moment [w/o ABS] (emu),Trans Scan Std Dev [w/o ABS],Trans Reg Fit [w/o ABS],Trans Percent Error [w/o ABS] (%),Points per Scan,Scans per Measurement,Scan Length (cm),Delta Temp (K),Rot Position (deg),Error,EC Comp. Running,Using ABS,
1524261952.828,,0.000000e+000,5.597523e+001,-1.729914e-005,0.000000e+000,2,9.274498e-001,0.000000e+000,,,,,,,,,,,,,,32,1,4.000000e+000,5.158997e-002,0.000000e+000,0,,0,
1524261992.529,,0.000000e+000,5.578848e+001,-1.361434e-005,0.000000e+000,2,8.915318e-001,0.000000e+000,,,,,,,,,,,,,,32,1,4.000000e+000,5.397034e-002,0.000000e+000,0,,0,
1524262032.329,,0.000000e+000,5.553650e+001,-1.166593e-005,0.000000e+000,2,8.715525e-001,0.000000e+000,,,,,,,,,,,,,,32,1,4.000000e+000,7.897949e-002,0.000000e+000,0,,0,
1524262072.009,,0.000000e+000,5.523017e+001,-1.116763e-005,0.000000e+000,2,8.712037e-001,0.000000e+000,,,,,,,,,,,,,,32,1,4.000000e+000,9.410095e-002,0.000000e+000,0,,0,
1524262111.419,,0.000000e+000,5.495633e+001,-9.840508e-006,0.000000e+000,2,8.409778e-001,0.000000e+000,,,,,,,,,,,,,,32,1,4.000000e+000,1.576996e-002,0.000000e+000,0,,0,
1524262149.419,,0.000000e+000,5.497473e+001,-9.398219e-006,0.000000e+000,2,8.341301e-001,0.000000e+000,,,,,,,,,,,,,,32,1,4.000000e+000,0.000000e+000,0.000000e+000,0,,0,
1524262187.769,,0.000000e+000,5.499709e+001,-9.103998e-006,0.000000e+000,2,8.286721e-001,0.000000e+000,,,,,,,,,,,,,,32,1,4.000000e+000,1.316071e-002,0.000000e+000,0,,0,
1524262225.759,,0.000000e+000,5.500300e+001,-8.550438e-006,0.000000e+000,2,8.073314e-001,0.000000e+000,,,,,,,,,,,,,,32,1,4.000000e+000,9.220123e-003,0.000000e+000,0,,0,
1524262263.699,,0.000000e+000,5.499971e+001,-8.208682e-006,0.000000e+000,2,8.239123e-001,0.000000e+000,,,,,,,,,,,,,,32,1,4.000000e+000,0.000000e+000,0.000000e+000,0,,0,
1524262301.519,,0.000000e+000,5.500300e+001,-7.978674e-006,0.000000e+000,2,7.967762e-001,0.000000e+000,,,,,,,,,,,,,,32,1,4.000000e+000,3.940582e-003,0.000000e+000,0,,0,
1524262339.459,,0.000000e+000,5.499577e+001,-7.616659e-006,0.000000e+000,2,7.911155e-001,0.000000e+000,,,,,,,,,,,,,,32,1,4.000000e+000,1.052094e-002,0.000000e+000,0,,0,
1524262377.329,,0.000000e+000,5.499708e+001,-7.252293e-006,0.000000e+000,2,7.877819e-001,0.000000e+000,,,,,,,,,,,,,,32,1,4.000000e+000,5.260468e-003,0.000000e+000,0,,0,
1524262414.809,,0.000000e+000,5.499313e+001,-7.008825e-006,0.000000e+000,2,7.785864e-001,0.000000e+000,,,,,,,,,,,,,,32,1,4.000000e+000,2.628326e-003,0.000000e+000,0,,0,
1524262452.079,,0.000000e+000,5.500037e+001,-6.860086e-006,0.000000e+000,2,7.607101e-001,0.000000e+000,,,,,,,,,,,,,,32,1,4.000000e+000,3.959656e-003,0.000000e+000,0,,0,
1524262490.099,,0.000000e+000,5.499840e+001,-6.713305e-006,0.000000e+000,2,7.708209e-001,0.000000e+000,,,,,,,,,,,,,,32,1,4.000000e+000,5.260468e-003,0.000000e+000,0,,0,
1524262528.109,,0.000000e+000,5.499511e+001,-6.571898e-006,0.000000e+000,2,7.541341e-001,0.000000e+000,,,,,,,,,,,,,,32,1,4.000000e+000,3.940582e-003,0.000000e+000,0,,0,
1524262566.079,,0.000000e+000,5.500103e+001,-6.202829e-006,0.000000e+000,2,7.312855e-001,0.000000e+000,,,,,,,,,,,,,,32,1,4.000000e+000,5.279541e-003,0.000000e+000,0,,0,
1524262603.689,,0.000000e+000,5.499905e+001,-6.012473e-006,0.000000e+000,2,7.487821e-001,0.000000e+000,,,,,,,,,,,,,,32,1,4.000000e+000,1.319885e-003,0.000000e+000,0,,0,
1524262642.069,,0.000000e+000,5.499708e+001,-5.895709e-006,0.000000e+000,2,7.267816e-001,0.000000e+000,,,,,,,,,,,,,,32,1,4.000000e+000,2.620697e-003,0.000000e+000,0,,0,
1524262680.119,,0.000000e+000,5.499972e+001,-5.550311e-006,0.000000e+000,2,7.007865e-001,0.000000e+000,,,,,,,,,,,,,,32,1,4.000000e+000,7.900238e-003,0.000000e+000,0,,0,
1524262718.180,,0.000000e+000,5.499971e+001,-5.364641e-006,0.000000e+000,2,7.147045e-001,0.000000e+000,,,,,,,,,,,,,,32,1,4.000000e+000,2.639771e-003,0.000000e+000,0,,0,
1524262755.550,,0.000000e+000,5.499774e+001,-5.395983e-006,0.000000e+000,2,6.998596e-001,0.000000e+000,,,,,,,,,,,,,,32,1,4.000000e+000,3.940582e-003,0.000000e+000,0,,0,
1524262793.380,,0.000000e+000,5.499642e+001,-5.149560e-006,0.000000e+000,2,6.899074e-001,0.000000e+000,,,,,,,,,,,,,,32,1,4.000000e+000,3.940582e-003,0.000000e+000,0,,0,
1524262830.610,,0.000000e+000,5.500300e+001,-5.019950e-006,0.000000e+000,2,6.765346e-001,0.000000e+000,,,,,,,,,,,,,,32,1,4.000000e+000,3.940582e-003,0.000000e+000,0,,0,
1524262868.540,,0.000000e+000,5.499708e+001,-4.932072e-006,0.000000e+000,2,6.729001e-001,0.000000e+000,,,,,,,,,,,,,,32,1,4.000000e+000,2.620697e-003,0.000000e+000,0,,0,
1524262905.800,,0.000000e+000,5.499840e+001,-4.784027e-006,0.000000e+000,2,6.550291e-001,0.000000e+000,,,,,,,,,,,,,,32,1,4.000000e+000,2.628326e-003,0.000000e+000,0,,0,
1524262943.730,,0.000000e+000,5.499511e+001,-4.586236e-006,0.000000e+000,2,6.539190e-001,0.000000e+000,,,,,,,,,,,,,,32,1,4.000000e+000,6.568909e-003,0.000000e+000,0,,0,
1524262981.560,,0.000000e+000,5.500169e+001,-4.623804e-006,0.000000e+000,2,6.360875e-001,0.000000e+000,,,,,,,,,,,,,,32,1,4.000000e+000,3.959656e-003,0.000000e+000,0,,0,
1524263019.620,,0.000000e+000,5.499643e+001,-4.465236e-006,0.000000e+000,2,6.489819e-001,0.000000e+000,,,,,,,,,,,,,,32,1,4.000000e+000,1.708984e-002,0.000000e+000,0,,0,
1524263057.630,,0.000000e+000,5.499643e+001,-4.341125e-006,0.000000e+000,2,6.518788e-001,0.000000e+000,,,,,,,,,,,,,,32,1,4.000000e+000,6.568909e-003,0.000000e+000,0,,0,
1524263095.030,,0.000000e+000,5.499906e+001,-4.285844e-006,0.000000e+000,2,6.341004e-001,0.000000e+000,,,,,,,,,,,,,,32,1,4.000000e+000,6.580353e-003,0.000000e+000,0,,0,
1524263146.870,,0.000000e+000,5.500366e+001,-4.148141e-006,0.000000e+000,2,6.005430e-001,0.000000e+000,,,,,,,,,,,,,,32,1,4.000000e+000,5.260468e-003,0.000000e+000,0,,0,
1524263184.670,,0.000000e+000,5.499708e+001,-4.026144e-006,0.000000e+000,2,5.797281e-001,0.000000e+000,,,,,,,,,,,,,,32,1,4.000000e+000,5.260468e-003,0.000000e+000,0,,0,
1524263222.260,,0.000000e+000,5.499643e+001,-3.918090e-006,0.000000e+000,2,6.197492e-001,0.000000e+000,,,,,,,,,,,,,,32,1,4.000000e+000,1.312256e-003,0.000000e+000,0,,0,
1524263259.810,,0.000000e+000,5.499511e+001,-3.886616e-006,0.000000e+000,2,5.835189e-001,0.000000e+000,,,,,,,,,,,,,,32,1,4.000000e+000,1.184082e-002,0.000000e+000,0,,0,
1524263297.770,,0.000000e+000,5.500037e+001,-3.809118e-006,0.000000e+000,2,5.849764e-001,0.000000e+000,,,,,,,,,,,,,,32,1,4.000000e+000,1.319885e-003,0.000000e+000,0,,0,
1524263335.280,,0.000000e+000,5.500169e+001,-3.753913e-006,0.000000e+000,2,5.950825e-001,0.000000e+000,,,,,,,,,,,,,,32,1,4.000000e+000,1.319885e-003,0.000000e+000,0,,0,
1524263373.180,,0.000000e+000,5.499642e+001,-3.749004e-006,0.000000e+000,2,5.705739e-001,0.000000e+000,,,,,,,,,,,,,,32,1,4.000000e+000,2.499008e-002,0.000000e+000,0,,0,
1524263410.751,,0.000000e+000,5.500235e+001,-3.468708e-006,0.000000e+000,2,5.278060e-001,0.000000e+000,,,,,,,,,,,,,,32,1,4.000000e+000,1.052856e-002,0.000000e+000,0,,0,
1524263448.571,,0.000000e+000,5.499577e+001,-3.346091e-006,0.000000e+000,2,5.152535e-001,0.000000e+000,,,,,,,,,,,,,,32,1,4.000000e+000,2.632141e-003,0.000000e+000,0,,0,
1524263486.251,,0.000000e+000,5.499643e+001,-3.424986e-006,0.000000e+000,2,5.080543e-001,0.000000e+000,,,,,,,,,,,,,,32,1,4.000000e+000,1.184082e-002,0.000000e+000,0,,0,
1524263524.321,,0.000000e+000,5.499314e+001,-3.329083e-006,0.000000e+000,2,5.271895e-001,0.000000e+000,,,,,,,,,,,,,,32,1,4.000000e+000,0.000000e+000,0.000000e+000,0,,0,
1524263562.271,,0.000000e+000,5.499183e+001,-3.087847e-006,0.000000e+000,2,4.696224e-001,0.000000e+000,,,,,,,,,,,,,,32,1,4.000000e+000,2.632141e-003,0.000000e+000,0,,0,
1524263600.391,,0.000000e+000,5.500037e+001,-3.110503e-006,0.000000e+000,2,4.495131e-001,0.000000e+000,,,,,,,,,,,,,,32,1,4.000000e+000,6.587982e-003,0.000000e+000,0,,0,
1524263638.451,,0.000000e+000,5.499906e+001,-2.988836e-006,0.000000e+000,2,4.417777e-001,0.000000e+000,,,,,,,,,,,,,,32,1,4.000000e+000,6.580353e-003,0.000000e+000,0,,0,
1524263676.351,,0.000000e+000,5.499577e+001,-3.052475e-006,0.000000e+000,2,4.499483e-001,0.000000e+000,,,,,,,,,,,,,,32,1,4.000000e+000,7.888794e-003,0.000000e+000,0,,0,
1524263714.541,,0.000000e+000,5.499774e+001,-2.914122e-006,0.000000e+000,2,4.391250e-001,0.000000e+000,,,,,,,,,,,,,,32,1,4.000000e+000,3.940582e-003,0.000000e+000,0,,0,
1524263752.111,,0.000000e+000,5.500037e+001,-2.891598e-006,0.000000e+000,2,4.605022e-001,0.000000e+000,,,,,,,,,,,,,,32,1,4.000000e+000,1.319885e-003,0.000000e+000,0,,0,
1524263789.751,,0.000000e+000,5.500037e+001,-2.775765e-006,0.000000e+000,2,4.313428e-001,0.000000e+000,,,,,,,,,,,,,,32,1,4.000000e+000,1.319885e-003,0.000000e+000,0,,0,
1524263827.551,,0.000000e+000,5.499840e+001,-2.728914e-006,0.000000e+000,2,4.224294e-001,0.000000e+000,,,,,,,,,,,,,,32,1,4.000000e+000,5.260468e-003,0.000000e+000,0,,0,
1524263865.491,,0.000000e+000,5.500103e+001,-2.620831e-006,0.000000e+000,2,3.662620e-001,0.000000e+000,,,,,,,,,,,,,,32,1,4.000000e+000,5.279541e-003,0.000000e+000,0,,0,
1524263903.471,,0.000000e+000,5.499905e+001,-2.581728e-006,0.000000e+000,2,3.910388e-001,0.000000e+000,,,,,,,,,,,,,,32,1,4.000000e+000,3.948212e-003,0.000000e+000,0,,0,
1524263941.591,,0.000000e+000,5.499840e+001,-2.603600e-006,0.000000e+000,2,3.875318e-001,0.000000e+000,,,,,,,,,,,,,,32,1,4.000000e+000,2.628326e-003,0.000000e+000,0,,0,
1524263979.091,,0.000000e+000,5.500103e+001,-2.446260e-006,0.000000e+000,2,3.273117e-001,0.000000e+000,,,,,,,,,,,,,,32,1,4.000000e+000,5.279541e-003,0.000000e+000,0,,0,
1524264017.091,,0.000000e+000,5.500037e+001,-2.403186e-006,0.000000e+000,2,3.584308e-001,0.000000e+000,,,,,,,,,,,,,,32,1,4.000000e+000,1.319885e-003,0.000000e+000,0,,0,
1524264054.441,,0.000000e+000,5.499840e+001,-2.255839e-006,0.000000e+000,2,2.679060e-001,0.000000e+000,,,,,,,,,,,,,,32,1,4.000000e+000,2.628326e-003,0.000000e+000,0,,0,
1524264092.691,,0.000000e+000,5.500366e+001,-2.284371e-006,0.000000e+000,2,2.963724e-001,0.000000e+000,,,,,,,,,,,,,,32,1,4.000000e+000,5.260468e-003,0.000000e+000,0,,0,
1524264131.462,,0.000000e+000,5.500301e+001,-2.282556e-006,0.000000e+000,2,3.124592e-001,0.000000e+000,,,,,,,,,,,,,,32,1,4.000000e+000,1.319885e-003,0.000000e+000,0,,0,
1524264169.802,,0.000000e+000,5.499972e+001,-2.243477e-006,0.000000e+000,2,2.852618e-001,0.000000e+000,,,,,,,,,,,,,,32,1,4.000000e+000,5.268097e-003,0.000000e+000,0,,0,
1524264206.892,,0.000000e+000,5.499643e+001,-2.200507e-006,0.000000e+000,2,2.701294e-001,0.000000e+000,,,,,,,,,,,,,,32,1,4.000000e+000,1.448059e-002,0.000000e+000,0,,0,
1524264244.452,,0.000000e+000,5.500103e+001,-2.176087e-006,0.000000e+000,2,2.268794e-001,0.000000e+000,,,,,,,,,,,,,,32,1,4.000000e+000,5.279541e-003,0.000000e+000,0,,0,
1524264282.382,,0.000000e+000,5.499708e+001,-2.113382e-006,0.000000e+000,2,2.341811e-001,0.000000e+000,,,,,,,,,,,,,,32,1,4.000000e+000,2.620697e-003,0.000000e+000,0,,0,
1524264320.202,,0.000000e+000,5.500103e+001,-2.103208e-006,0.000000e+000,2,2.057320e-001,0.000000e+000,,,,,,,,,,,,,,32,1,4.000000e+000,0.000000e+000,0.000000e+000,0,,0,
1524264358.112,,0.000000e+000,5.500234e+001,-2.006316e-006,0.000000e+000,2,1.963566e-001,0.000000e+000,,,,,,,,,,,,,,32,1,4.000000e+000,7.900238e-003,0.000000e+000,0,,0,
1524264396.472,,0.000000e+000,5.499773e+001,-2.023054e-006,0.000000e+000,2,1.977501e-001,0.000000e+000,,,,,,,,,,,,,,32,1,4.000000e+000,1.308441e-003,0.000000e+000,0,,0,
1524264434.012,,0.000000e+000,5.499708e+001,-1.889277e-006,0.000000e+000,2,1.193479e-001,0.000000e+000,,,,,,,,,,,,,,32,1,4.000000e+000,0.000000e+000,0.000000e+000,0,,0,
1524264471.872,,0.000000e+000,5.499773e+001,-1.824533e-006,0.000000e+000,2,1.036137e-001,0.000000e+000,,,,,,,,,,,,,,32,1,4.000000e+000,1.308441e-003,0.000000e+000,0,,0,
1524264509.662,,0.000000e+000,5.500169e+001,-1.758431e-006,0.000000e+000,2,7.066751e-002,0.000000e+000,,,,,,,,,,,,,,32,1,4.000000e+000,9.208679e-003,0.000000e+000,0,,0,
1524264547.612,,0.000000e+000,5.499840e+001,-1.833408e-006,0.000000e+000,2,1.339640e-001,0.000000e+000,,,,,,,,,,,,,,32,1,4.000000e+000,1.842117e-002,0.000000e+000,0,,0,
1524264585.402,,0.000000e+000,5.499643e+001,-1.754068e-006,0.000000e+000,2,1.038135e-001,0.000000e+000,,,,,,,,,,,,,,32,1,4.000000e+000,1.312256e-003,0.000000e+000,0,,0,
1524264622.872,,0.000000e+000,5.499642e+001,-1.776964e-006,0.000000e+000,2,8.052630e-002,0.000000e+000,,,,,,,,,,,,,,32,1,4.000000e+000,3.940582e-003,0.000000e+000,0,,0,
1524264660.842,,0.000000e+000,5.499773e+001,-1.666031e-006,0.000000e+000,2,0.000000e+000,0.000000e+000,,,,,,,,,,,,,,32,1,4.000000e+000,1.308441e-003,0.000000e+000,0,,0,
1524264698.292,,0.000000e+000,5.499642e+001,-1.639149e-006,0.000000e+000,2,1.000009e-002,0.000000e+000,,,,,,,,,,,,,,32,1,4.000000e+000,3.940582e-003,0.000000e+000,0,,0,
1524264736.042,,0.000000e+000,5.500037e+001,-1.627128e-006,0.000000e+000,2,0.000000e+000,0.000000e+000,,,,,,,,,,,,,,32,1,4.000000e+000,6.587982e-003,0.000000e+000,0,,0,
1524264773.582,,0.000000e+000,5.499577e+001,-1.590900e-006,0.000000e+000,2,0.000000e+000,0.000000e+000,,,,,,,,,,,,,,32,1,4.000000e+000,0.000000e+000,0.000000e+000,0,,0,
1524264811.752,,0.000000e+000,5.500432e+001,-1.610696e-006,0.000000e+000,2,0.000000e+000,0.000000e+000,,,,,,,,,,,,,,32,1,4.000000e+000,1.300812e-003,0.000000e+000,0,,0,
1524264849.483,,0.000000e+000,5.500103e+001,-1.403798e-006,0.000000e+000,2,0.000000e+000,0.000000e+000,,,,,,,,,,,,,,32,1,4.000000e+000,1.316071e-002,0.000000e+000,0,,0,
1524264887.703,,0.000000e+000,5.499380e+001,-1.444444e-006,0.000000e+000,2,0.000000e+000,0.000000e+000,,,,,,,,,,,,,,32,1,4.000000e+000,1.308441e-003,0.000000e+000,0,,0,
1524264925.723,,0.000000e+000,5.500037e+001,-1.411575e-006,0.000000e+000,2,0.000000e+000,0.000000e+000,,,,,,,,,,,,,,32,1,4.000000e+000,6.587982e-003,0.000000e+000,0,,0,
1524264963.733,,0.000000e+000,5.500037e+001,-1.294774e-006,0.000000e+000,2,0.000000e+000,0.000000e+000,,,,,,,,,,,,,,32,1,4.000000e+000,3.959656e-003,0.000000e+000,0,,0,
1524265001.473,,0.000000e+000,5.499445e+001,-1.278692e-006,0.000000e+000,2,0.000000e+000,0.000000e+000,,,,,,,,,,,,,,32,1,4.000000e+000,0.000000e+000,0.000000e+000,0,,0,
1524265038.973,,0.000000e+000,5.499773e+001,-1.248032e-006,0.000000e+000,2,0.000000e+000,0.000000e+000,,,,,,,,,,,,,,32,1,4.000000e+000,1.308441e-003,0.000000e+000,0,,0,
1524265076.673,,0.000000e+000,5.500235e+001,-1.186516e-006,0.000000e+000,2,0.000000e+000,0.000000e+000,,,,,,,,,,,,,,32,1,4.000000e+000,1.052856e-002,0.000000e+000,0,,0,
1524265113.993,,0.000000e+000,5.500234e+001,-1.250894e-006,0.000000e+000,2,0.000000e+000,0.000000e+000,,,,,,,,,,,,,,32,1,4.000000e+000,7.900238e-003,0.000000e+000,0,,0,
1524265153.273,,0.000000e+000,5.500497e+001,-1.121276e-006,0.000000e+000,2,0.000000e+000,0.000000e+000,,,,,,,,,,,,,,32,1,4.000000e+000,1.052856e-002,0.000000e+000,0,,0,
1524265191.063,,0.000000e+000,5.499773e+001,-1.150566e-006,0.000000e+000,2,0.000000e+000,0.000000e+000,,,,,,,,,,,,,,32,1,4.000000e+000,1.308441e-003,0.000000e+000,0,,0,
1524265228.693,,0.000000e+000,5.498985e+001,-1.035291e-006,0.000000e+000,2,0.000000e+000,0.000000e+000,,,,,,,,,,,,,,32,1,4.000000e+000,6.580353e-003,0.000000e+000,0,,0,
1524265266.793,,0.000000e+000,5.500431e+001,-1.057557e-006,0.000000e+000,2,0.000000e+000,0.000000e+000,,,,,,,,,,,,,,32,1,4.000000e+000,9.208679e-003,0.000000e+000,0,,0,
1524265304.263,,0.000000e+000,5.499774e+001,-1.024329e-006,0.000000e+000,2,0.000000e+000,0.000000e+000,,,,,,,,,,,,,,32,1,4.000000e+000,1.710129e-002,0.000000e+000,0,,0,
1524265342.593,,0.000000e+000,5.500366e+001,-9.626747e-007,0.000000e+000,2,0.000000e+000,0.000000e+000,,,,,,,,,,,,,,32,1,4.000000e+000,2.620697e-003,0.000000e+000,0,,0,
1524265380.363,,0.000000e+000,5.500037e+001,-9.767460e-007,0.000000e+000,2,0.000000e+000,0.000000e+000,,,,,,,,,,,,,,32,1,4.000000e+000,3.959656e-003,0.000000e+000,0,,0,
1524265417.553,,0.000000e+000,5.499839e+001,-9.708428e-007,0.000000e+000,2,0.000000e+000,0.000000e+000,,,,,,,,,,,,,,32,1,4.000000e+000,0.000000e+000,0.000000e+000,0,,0,
1524265455.553,,0.000000e+000,5.500366e+001,-9.746163e-007,0.000000e+000,2,0.000000e+000,0.000000e+000,,,,,,,,,,,,,,32,1,4.000000e+000,5.260468e-003,0.000000e+000,0,,0,
1524265493.183,,0.000000e+000,5.499972e+001,-9.322135e-007,0.000000e+000,2,0.000000e+000,0.000000e+000,,,,,,,,,,,,,,32,1,4.000000e+000,7.900238e-003,0.000000e+000,0,,0,
1524265530.973,,0.000000e+000,5.499643e+001,-8.895830e-007,0.000000e+000,2,0.000000e+000,0.000000e+000,,,,,,,,,,,,,,32,1,4.000000e+000,1.312256e-003,0.000000e+000,0,,0,
1524265567.994,,0.000000e+000,5.500169e+001,-8.602231e-007,0.000000e+000,2,0.000000e+000,0.000000e+000,,,,,,,,,,,,,,32,1,4.000000e+000,1.184082e-002,0.000000e+000,0,,0,
1524265606.054,,0.000000e+000,5.499643e+001,-8.348704e-007,0.000000e+000,2,0.000000e+000,0.000000e+000,,,,,,,,,,,,,,32,1,4.000000e+000,1.312256e-003,0.000000e+000,0,,0,
1524265644.114,,0.000000e+000,5.499774e+001,-7.908545e-007,0.000000e+000,2,0.000000e+000,0.000000e+000,,,,,,,,,,,,,,32,1,4.000000e+000,6.580353e-003,0.000000e+000,0,,0,
1524265681.914,,0.000000e+000,5.499775e+001,-8.391730e-007,0.000000e+000,2,0.000000e+000,0.000000e+000,,,,,,,,,,,,,,32,1,4.000000e+000,1.184845e-002,0.000000e+000,0,,0,
1524265719.534,,0.000000e+000,5.499840e+001,-7.669959e-007,0.000000e+000,2,0.000000e+000,0.000000e+000,,,,,,,,,,,,,,32,1,4.000000e+000,2.628326e-003,0.000000e+000,0,,0,
1524265758.094,,0.000000e+000,5.500301e+001,-7.144390e-007,0.000000e+000,2,0.000000e+000,0.000000e+000,,,,,,,,,,,,,,32,1,4.000000e+000,1.319885e-003,0.000000e+000,0,,0,
1524265795.674,,0.000000e+000,5.500498e+001,-7.224899e-007,0.000000e+000,2,0.000000e+000,0.000000e+000,,,,,,,,,,,,,,32,1,4.000000e+000,5.260468e-003,0.000000e+000,0,,0,
1524265833.614,,0.000000e+000,5.500169e+001,-7.371266e-007,0.000000e+000,2,0.000000e+000,0.000000e+000,,,,,,,,,,,,,,32,1,4.000000e+000,1.319885e-003,0.000000e+000,0,,0,
1524265871.504,,0.000000e+000,5.499972e+001,-6.854328e-007,0.000000e+000,2,0.000000e+000,0.000000e+000,,,,,,,,,,,,,,32,1,4.000000e+000,5.268097e-003,0.000000e+000,0,,0,
1524265909.164,,0.000000e+000,5.499643e+001,-6.038464e-007,0.000000e+000,2,0.000000e+000,0.000000e+000,,,,,,,,,,,,,,32,1,4.000000e+000,1.312256e-003,0.000000e+000,0,,0,
1524265947.414,,0.000000e+000,5.499905e+001,-6.488000e-007,0.000000e+000,2,0.000000e+000,0.000000e+000,,,,,,,,,,,,,,32,1,4.000000e+000,3.948212e-003,0.000000e+000,0,,0,
1524265985.244,,0.000000e+000,5.499906e+001,-6.779272e-007,0.000000e+000,2,0.000000e+000,0.000000e+000,,,,,,,,,,,,,,32,1,4.000000e+000,6.580353e-003,0.000000e+000,0,,0,
1524266022.954,,0.000000e+000,5.500103e+001,-5.366998e-007,0.000000e+000,2,0.000000e+000,0.000000e+000,,,,,,,,,,,,,,32,1,4.000000e+000,5.279541e-003,0.000000e+000,0,,0,
1524266061.514,,0.000000e+000,5.499905e+001,-5.775624e-007,0.000000e+000,2,0.000000e+000,0.000000e+000,,,,,,,,,,,,,,32,1,4.000000e+000,3.948212e-003,0.000000e+000,0,,0,
1524266098.204,,0.000000e+000,5.500300e+001,-4.886955e-007,0.000000e+000,2,0.000000e+000,0.000000e+000,,,,,,,,,,,,,,32,1,4.000000e+000,6.580353e-003,0.000000e+000,0,,0,
1524266135.324,,0.000000e+000,5.500037e+001,-5.102386e-007,0.000000e+000,2,0.000000e+000,0.000000e+000,,,,,,,,,,,,,,32,1,4.000000e+000,9.201050e-003,0.000000e+000,0,,0,
1524266173.554,,0.000000e+000,5.499313e+001,-4.373787e-007,0.000000e+000,2,0.000000e+000,0.000000e+000,,,,,,,,,,,,,,32,1,4.000000e+000,1.314926e-002,0.000000e+000,0,,0,
1524266211.304,,0.000000e+000,5.500103e+001,-4.263894e-007,0.000000e+000,2,0.000000e+000,0.000000e+000,,,,,,,,,,,,,,32,1,4.000000e+000,0.000000e+000,0.000000e+000,0,,0,
1524266248.604,,0.000000e+000,5.499840e+001,-4.242822e-007,0.000000e+000,2,0.000000e+000,0.000000e+000,,,,,,,,,,,,,,32,1,4.000000e+000,2.628326e-003,0.000000e+000,0,,0,
1524266286.375,,0.000000e+000,5.499839e+001,-4.128027e-007,0.000000e+000,2,0.000000e+000,0.000000e+000,,,,,,,,,,,,,,32,1,4.000000e+000,0.000000e+000,0.000000e+000,0,,0,
1524266336.405,,0.000000e+000,5.499577e+001,-4.347820e-007,0.000000e+000,2,0.000000e+000,0.000000e+000,,,,,,,,,,,,,,32,1,4.000000e+000,5.249023e-003,0.000000e+000,0,,0,
1524266374.395,,0.000000e+000,5.499577e+001,-3.166416e-007,0.000000e+000,2,0.000000e+000,0.000000e+000,,,,,,,,,,,,,,32,1,4.000000e+000,2.632141e-003,0.000000e+000,0,,0,
1524266412.405,,0.000000e+000,5.499840e+001,-3.592974e-007,0.000000e+000,2,0.000000e+000,0.000000e+000,,,,,,,,,,,,,,32,1,4.000000e+000,2.628326e-003,0.000000e+000,0,,0,
1524266449.935,,0.000000e+000,5.499972e+001,-2.519105e-007,0.000000e+000,2,0.000000e+000,0.000000e+000,,,,,,,,,,,,,,32,1,4.000000e+000,1.314926e-002,0.000000e+000,0,,0,
1524266487.805,,0.000000e+000,5.499248e+001,-3.033316e-007,0.000000e+000,2,0.000000e+000,0.000000e+000,,,,,,,,,,,,,,32,1,4.000000e+000,3.940582e-003,0.000000e+000,0,,0,
1524266525.635,,0.000000e+000,5.499642e+001,-3.294807e-007,0.000000e+000,2,0.000000e+000,0.000000e+000,,,,,,,,,,,,,,32,1,4.000000e+000,3.940582e-003,0.000000e+000,0,,0,
1524266563.505,,0.000000e+000,5.500103e+001,-3.572206e-007,0.000000e+000,2,0.000000e+000,0.000000e+000,,,,,,,,,,,,,,32,1,4.000000e+000,7.888794e-003,0.000000e+000,0,,0,
1524266600.915,,0.000000e+000,5.500103e+001,-2.379665e-007,0.000000e+000,2,0.000000e+000,0.000000e+000,,,,,,,,,,,,,,32,1,4.000000e+000,1.316071e-002,0.000000e+000,0,,0,
1524266639.135,,0.000000e+000,5.500103e+001,-1.334798e-007,0.000000e+000,2,0.000000e+000,0.000000e+000,,,,,,,,,,,,,,32,1,4.000000e+000,2.639771e-003,0.000000e+000,0,,0,
1524266676.745,,0.000000e+000,5.499840e+001,-2.255386e-007,0.000000e+000,2,0.000000e+000,0.000000e+000,,,,,,,,,,,,,,32,1,4.000000e+000,5.260468e-003,0.000000e+000,0,,0,
1524266714.625,,0.000000e+000,5.499905e+001,-2.089089e-007,0.000000e+000,2,0.000000e+000,0.000000e+000,,,,,,,,,,,,,,32,1,4.000000e+000,3.948212e-003,0.000000e+000,0,,0,
1524266752.995,,0.000000e+000,5.499642e+001,-1.787386e-007,0.000000e+000,2,0.000000e+000,0.000000e+000,,,,,,,,,,,,,,32,1,4.000000e+000,3.940582e-003,0.000000e+000,0,,0,
1524266790.365,,0.000000e+000,5.499972e+001,-1.409033e-007,0.000000e+000,2,0.000000e+000,0.000000e+000,,,,,,,,,,,,,,32,1,4.000000e+000,1.314926e-002,0.000000e+000,0,,0,
1524266828.735,,0.000000e+000,5.499905e+001,-1.361572e-007,0.000000e+000,2,0.000000e+000,0.000000e+000,,,,,,,,,,,,,,32,1,4.000000e+000,1.319885e-003,0.000000e+000,0,,0,
1524266866.335,,0.000000e+000,5.499577e+001,-7.621098e-008,0.000000e+000,2,0.000000e+000,0.000000e+000,,,,,,,,,,,,,,32,1,4.000000e+000,1.052094e-002,0.000000e+000,0,,0,
1524266904.285,,0.000000e+000,5.499840e+001,-1.001945e-007,0.000000e+000,2,0.000000e+000,0.000000e+000,,,,,,,,,,,,,,32,1,4.000000e+000,2.628326e-003,0.000000e+000,0,,0,
1524266941.665,,0.000000e+000,5.499380e+001,-6.554281e-008,0.000000e+000,2,0.000000e+000,0.000000e+000,,,,,,,,,,,,,,32,1,4.000000e+000,1.182938e-002,0.000000e+000,0,,0,
1524266979.556,,0.000000e+000,5.499971e+001,-6.271819e-008,0.000000e+000,2,0.000000e+000,0.000000e+000,,,,,,,,,,,,,,32,1,4.000000e+000,0.000000e+000,0.000000e+000,0,,0,
1524267017.286,,0.000000e+000,5.499774e+001,-1.892788e-008,0.000000e+000,2,0.000000e+000,0.000000e+000,,,,,,,,,,,,,,32,1,4.000000e+000,6.580353e-003,0.000000e+000,0,,0,
1524267055.166,,0.000000e+000,5.499708e+001,1.559934e-008,0.000000e+000,2,0.000000e+000,0.000000e+000,,,,,,,,,,,,,,32,1,4.000000e+000,2.620697e-003,0.000000e+000,0,,0,
1524267093.136,,0.000000e+000,5.499905e+001,3.040156e-008,0.000000e+000,2,0.000000e+000,0.000000e+000,,,,,,,,,,,,,,32,1,4.000000e+000,3.948212e-003,0.000000e+000,0,,0,
1524267130.556,,0.000000e+000,5.499248e+001,7.239475e-009,0.000000e+000,2,0.000000e+000,0.000000e+000,,,,,,,,,,,,,,32,1,4.000000e+000,1.319885e-003,0.000000e+000,0,,0,
1524267168.316,,0.000000e+000,5.499775e+001,5.703159e-008,0.000000e+000,2,0.000000e+000,0.000000e+000,,,,,,,,,,,,,,32,1,4.000000e+000,1.184845e-002,0.000000e+000,0,,0,
1524267206.516,,0.000000e+000,5.499839e+001,2.594458e-008,0.000000e+000,2,0.000000e+000,0.000000e+000,,,,,,,,,,,,,,32,1,4.000000e+000,0.000000e+000,0.000000e+000,0,,0,
1524267244.376,,0.000000e+000,5.500103e+001,1.222762e-007,0.000000e+000,2,0.000000e+000,0.000000e+000,,,,,,,,,,,,,,32,1,4.000000e+000,5.279541e-003,0.000000e+000,0,,0,
1524267283.046,,0.000000e+000,5.499708e+001,1.285638e-007,0.000000e+000,2,0.000000e+000,0.000000e+000,,,,,,,,,,,,,,32,1,4.000000e+000,0.000000e+000,0.000000e+000,0,,0,
1524267320.346,,0.000000e+000,5.500367e+001,1.550440e-007,0.000000e+000,2,0.000000e+000,0.000000e+000,,,,,,,,,,,,,,32,1,4.000000e+000,0.000000e+000,0.000000e+000,0,,0,
1524267358.166,,0.000000e+000,5.500169e+001,8.901065e-008,0.000000e+000,2,0.000000e+000,0.000000e+000,,,,,,,,,,,,,,32,1,4.000000e+000,1.319885e-003,0.000000e+000,0,,0,
1524267395.866,,0.000000e+000,5.499643e+001,1.190705e-007,0.000000e+000,2,0.000000e+000,0.000000e+000,,,,,,,,,,,,,,32,1,4.000000e+000,1.312256e-003,0.000000e+000,0,,0,
1524267433.946,,0.000000e+000,5.499445e+001,1.551763e-007,0.000000e+000,2,0.000000e+000,0.000000e+000,,,,,,,,,,,,,,32,1,4.000000e+000,2.628326e-003,0.000000e+000,0,,0,
1524267471.646,,0.000000e+000,5.499971e+001,2.624921e-007,0.000000e+000,2,0.000000e+000,0.000000e+000,,,,,,,,,,,,,,32,1,4.000000e+000,2.639771e-003,0.000000e+000,0,,0,
1524267509.646,,0.000000e+000,5.499709e+001,1.843903e-007,0.000000e+000,2,0.000000e+000,0.000000e+000,,,,,,,,,,,,,,32,1,4.000000e+000,1.316071e-002,0.000000e+000,0,,0,
1524267547.316,,0.000000e+000,5.500037e+001,2.295130e-007,0.000000e+000,2,0.000000e+000,0.000000e+000,,,,,,,,,,,,,,32,1,4.000000e+000,3.959656e-003,0.000000e+000,0,,0,
1524267585.406,,0.000000e+000,5.499840e+001,2.257093e-007,0.000000e+000,2,0.000000e+000,0.000000e+000,,,,,,,,,,,,,,32,1,4.000000e+000,1.314926e-002,0.000000e+000,0,,0,
1524267623.056,,0.000000e+000,5.499511e+001,2.740149e-007,0.000000e+000,2,0.000000e+000,0.000000e+000,,,,,,,,,,,,,,32,1,4.000000e+000,1.319885e-003,0.000000e+000,0,,0,
1524267661.136,,0.000000e+000,5.499445e+001,2.452894e-007,0.000000e+000,2,0.000000e+000,0.000000e+000,,,,,,,,,,,,,,32,1,4.000000e+000,2.628326e-003,0.000000e+000,0,,0,
1524267698.797,,0.000000e+000,5.499906e+001,2.640158e-007,0.000000e+000,2,0.000000e+000,0.000000e+000,,,,,,,,,,,,,,32,1,4.000000e+000,9.220123e-003,0.000000e+000,0,,0,
1524267736.877,,0.000000e+000,5.499380e+001,2.366847e-007,0.000000e+000,2,0.000000e+000,0.000000e+000,,,,,,,,,,,,,,32,1,4.000000e+000,3.948212e-003,0.000000e+000,0,,0,
1524267774.677,,0.000000e+000,5.500037e+001,3.429108e-007,0.000000e+000,2,0.000000e+000,0.000000e+000,,,,,,,,,,,,,,32,1,4.000000e+000,1.319885e-003,0.000000e+000,0,,0,
1524267812.567,,0.000000e+000,5.499971e+001,3.085305e-007,0.000000e+000,2,0.000000e+000,0.000000e+000,,,,,,,,,,,,,,32,1,4.000000e+000,0.000000e+000,0.000000e+000,0,,0,
1524267849.817,,0.000000e+000,5.500234e+001,2.953819e-007,0.000000e+000,2,0.000000e+000,0.000000e+000,,,,,,,,,,,,,,32,1,4.000000e+000,7.900238e-003,0.000000e+000,0,,0,
1524267887.387,,0.000000e+000,5.499709e+001,3.659539e-007,0.000000e+000,2,0.000000e+000,0.000000e+000,,,,,,,,,,,,,,32,1,4.000000e+000,7.888794e-003,0.000000e+000,0,,0,
1524267924.567,,0.000000e+000,5.499642e+001,3.403019e-007,0.000000e+000,2,0.000000e+000,0.000000e+000,,,,,,,,,,,,,,32,1,4.000000e+000,3.940582e-003,0.000000e+000,0,,0,
1524267962.577,,0.000000e+000,5.499905e+001,3.634594e-007,0.000000e+000,2,0.000000e+000,0.000000e+000,,,,,,,,,,,,,,32,1,4.000000e+000,3.948212e-003,0.000000e+000,0,,0,
1524268000.367,,0.000000e+000,5.500366e+001,3.665293e-007,0.000000e+000,2,0.000000e+000,0.000000e+000,,,,,,,,,,,,,,32,1,4.000000e+000,2.620697e-003,0.000000e+000,0,,0,
1524268038.927,,0.000000e+000,5.499577e+001,3.802490e-007,0.000000e+000,2,0.000000e+000,0.000000e+000,,,,,,,,,,,,,,32,1,4.000000e+000,2.632141e-003,0.000000e+000,0,,0,
1524268076.417,,0.000000e+000,5.500235e+001,4.688641e-007,0.000000e+000,2,0.000000e+000,0.000000e+000,,,,,,,,,,,,,,32,1,4.000000e+000,1.052856e-002,0.000000e+000,0,,0,
1524268114.417,,0.000000e+000,5.499971e+001,4.321372e-007,0.000000e+000,2,0.000000e+000,0.000000e+000,,,,,,,,,,,,,,32,1,4.000000e+000,2.639771e-003,0.000000e+000,0,,0,
1524268152.007,,0.000000e+000,5.500037e+001,4.222883e-007,0.000000e+000,2,0.000000e+000,0.000000e+000,,,,,,,,,,,,,,32,1,4.000000e+000,1.319885e-003,0.000000e+000,0,,0,
1524268189.587,,0.000000e+000,5.499643e+001,4.681505e-007,0.000000e+000,2,0.000000e+000,0.000000e+000,,,,,,,,,,,,,,32,1,4.000000e+000,6.568909e-003,0.000000e+000,0,,0,
1524268228.097,,0.000000e+000,5.500169e+001,4.347484e-007,0.000000e+000,2,0.000000e+000,0.000000e+000,,,,,,,,,,,,,,32,1,4.000000e+000,3.959656e-003,0.000000e+000,0,,0,
1524268266.227,,0.000000e+000,5.499380e+001,5.507781e-007,0.000000e+000,2,0.000000e+000,0.000000e+000,,,,,,,,,,,,,,32,1,4.000000e+000,1.182938e-002,0.000000e+000,0,,0,
1524268304.397,,0.000000e+000,5.499774e+001,5.364780e-007,0.000000e+000,2,0.000000e+000,0.000000e+000,,,,,,,,,,,,,,32,1,4.000000e+000,3.940582e-003,0.000000e+000,0,,0,
1524268342.477,,0.000000e+000,5.499445e+001,4.409492e-007,0.000000e+000,2,0.000000e+000,0.000000e+000,,,,,,,,,,,,,,32,1,4.000000e+000,0.000000e+000,0.000000e+000,0,,0,
1524268380.267,,0.000000e+000,5.500432e+001,5.531109e-007,0.000000e+000,2,0.000000e+000,0.000000e+000,,,,,,,,,,,,,,32,1,4.000000e+000,1.300812e-003,0.000000e+000,0,,0,
1524268418.208,,0.000000e+000,5.500365e+001,5.108679e-007,0.000000e+000,2,0.000000e+000,0.000000e+000,,,,,,,,,,,,,,32,1,4.000000e+000,1.052856e-002,0.000000e+000,0,,0,
1524268455.998,,0.000000e+000,5.499775e+001,5.475957e-007,0.000000e+000,2,0.000000e+000,0.000000e+000,,,,,,,,,,,,,,32,1,4.000000e+000,1.184845e-002,0.000000e+000,0,,0,
1524268493.938,,0.000000e+000,5.499445e+001,4.813223e-007,0.000000e+000,2,0.000000e+000,0.000000e+000,,,,,,,,,,,,,,32,1,4.000000e+000,2.628326e-003,0.000000e+000,0,,0,
1524268531.778,,0.000000e+000,5.499248e+001,5.970126e-007,0.000000e+000,2,0.000000e+000,0.000000e+000,,,,,,,,,,,,,,32,1,4.000000e+000,3.940582e-003,0.000000e+000,0,,0,
1524268570.308,,0.000000e+000,5.499906e+001,5.392316e-007,0.000000e+000,2,0.000000e+000,0.000000e+000,,,,,,,,,,,,,,32,1,4.000000e+000,6.580353e-003,0.000000e+000,0,,0,
1524268608.198,,0.000000e+000,5.499774e+001,5.200040e-007,0.000000e+000,2,0.000000e+000,0.000000e+000,,,,,,,,,,,,,,32,1,4.000000e+000,3.940582e-003,0.000000e+000,0,,0,
1524268646.038,,0.000000e+000,5.500103e+001,6.436449e-007,0.000000e+000,2,0.000000e+000,0.000000e+000,,,,,,,,,,,,,,32,1,4.000000e+000,2.639771e-003,0.000000e+000,0,,0,
1524268683.628,,0.000000e+000,5.499972e+001,6.450151e-007,0.000000e+000,2,0.000000e+000,0.000000e+000,,,,,,,,,,,,,,32,1,4.000000e+000,7.900238e-003,0.000000e+000,0,,0,
1524268721.468,,0.000000e+000,5.499774e+001,5.759108e-007,0.000000e+000,2,0.000000e+000,0.000000e+000,,,,,,,,,,,,,,32,1,4.000000e+000,6.580353e-003,0.000000e+000,0,,0,
1524268759.398,,0.000000e+000,5.499183e+001,6.878292e-007,0.000000e+000,2,0.000000e+000,0.000000e+000,,,,,,,,,,,,,,32,1,4.000000e+000,2.632141e-003,0.000000e+000,0,,0,
1524268797.208,,0.000000e+000,5.500103e+001,6.729059e-007,0.000000e+000,2,0.000000e+000,0.000000e+000,,,,,,,,,,,,,,32,1,4.000000e+000,2.639771e-003,0.000000e+000,0,,0,
1524268834.578,,0.000000e+000,5.499971e+001,6.776870e-007,0.000000e+000,2,0.000000e+000,0.000000e+000,,,,,,,,,,,,,,32,1,4.000000e+000,2.639771e-003,0.000000e+000,0,,0,
1524268872.958,,0.000000e+000,5.500498e+001,6.347469e-007,0.000000e+000,2,0.000000e+000,0.000000e+000,,,,,,,,,,,,,,32,1,4.000000e+000,5.260468e-003,0.000000e+000,0,,0,
1524268910.428,,0.000000e+000,5.499313e+001,7.297637e-007,0.000000e+000,2,0.000000e+000,0.000000e+000,,,,,,,,,,,,,,32,1,4.000000e+000,1.050949e-002,0.000000e+000,0,,0,
1524268948.568,,0.000000e+000,5.500103e+001,6.877360e-007,0.000000e+000,2,0.000000e+000,0.000000e+000,,,,,,,,,,,,,,32,1,4.000000e+000,5.279541e-003,0.000000e+000,0,,0,
1524268986.398,,0.000000e+000,5.500827e+001,6.823462e-007,0.000000e+000,2,0.000000e+000,0.000000e+000,,,,,,,,,,,,,,32,1,4.000000e+000,9.201050e-003,0.000000e+000,0,,0,
1524269024.358,,0.000000e+000,5.499709e+001,7.081243e-007,0.000000e+000,2,0.000000e+000,0.000000e+000,,,,,,,,,,,,,,32,1,4.000000e+000,7.888794e-003,0.000000e+000,0,,0,
1524269061.408,,0.000000e+000,5.499512e+001,7.887827e-007,0.000000e+000,2,0.000000e+000,0.000000e+000,,,,,,,,,,,,,,32,1,4.000000e+000,1.710892e-002,0.000000e+000,0,,0,
1524269099.538,,0.000000e+000,5.500037e+001,7.349853e-007,0.000000e+000,2,0.000000e+000,0.000000e+000,,,,,,,,,,,,,,32,1,4.000000e+000,9.201050e-003,0.000000e+000,0,,0,
1524269137.159,,0.000000e+000,5.499840e+001,7.592297e-007,0.000000e+000,2,0.000000e+000,0.000000e+000,,,,,,,,,,,,,,32,1,4.000000e+000,2.628326e-003,0.000000e+000,0,,0,
1524269175.269,,0.000000e+000,5.499839e+001,7.606178e-007,0.000000e+000,2,0.000000e+000,0.000000e+000,,,,,,,,,,,,,,32,1,4.000000e+000,0.000000e+000,0.000000e+000,0,,0,
1524269212.969,,0.000000e+000,5.499708e+001,8.107869e-007,0.000000e+000,2,0.000000e+000,0.000000e+000,,,,,,,,,,,,,,32,1,4.000000e+000,2.620697e-003,0.000000e+000,0,,0,
1524269250.549,,0.000000e+000,5.499445e+001,7.968828e-007,0.000000e+000,2,0.000000e+000,0.000000e+000,,,,,,,,,,,,,,32,1,4.000000e+000,2.628326e-003,0.000000e+000,0,,0,
1524269288.529,,0.000000e+000,5.500234e+001,8.287761e-007,0.000000e+000,2,0.000000e+000,0.000000e+000,,,,,,,,,,,,,,32,1,4.000000e+000,7.900238e-003,0.000000e+000,0,,0,
1524269326.579,,0.000000e+000,5.500103e+001,8.785113e-007,0.000000e+000,2,0.000000e+000,0.000000e+000,,,,,,,,,,,,,,32,1,4.000000e+000,1.577759e-002,0.000000e+000,0,,0,
1524269364.419,,0.000000e+000,5.500366e+001,8.164168e-007,0.000000e+000,2,0.000000e+000,0.000000e+000,,,,,,,,,,,,,,32,1,4.000000e+000,1.315689e-002,0.000000e+000,0,,0,
1524269402.059,,0.000000e+000,5.499708e+001,7.885496e-007,0.000000e+000,2,0.000000e+000,0.000000e+000,,,,,,,,,,,,,,32,1,4.000000e+000,5.260468e-003,0.000000e+000,0,,0,
1524269439.749,,0.000000e+000,5.500234e+001,8.151671e-007,0.000000e+000,2,0.000000e+000,0.000000e+000,,,,,,,,,,,,,,32,1,4.000000e+000,5.260468e-003,0.000000e+000,0,,0,
1524269478.239,,0.000000e+000,5.500103e+001,7.780999e-007,0.000000e+000,2,0.000000e+000,0.000000e+000,,,,,,,,,,,,,,32,1,4.000000e+000,5.279541e-003,0.000000e+000,0,,0,
1524269515.909,,0.000000e+000,5.500103e+001,8.025822e-007,0.000000e+000,2,0.000000e+000,0.000000e+000,,,,,,,,,,,,,,32,1,4.000000e+000,7.888794e-003,0.000000e+000,0,,0,
1524269553.889,,0.000000e+000,5.500234e+001,7.967749e-007,0.000000e+000,2,0.000000e+000,0.000000e+000,,,,,,,,,,,,,,32,1,4.000000e+000,5.260468e-003,0.000000e+000,0,,0,
1524269591.729,,0.000000e+000,5.499840e+001,7.917785e-007,0.000000e+000,2,0.000000e+000,0.000000e+000,,,,,,,,,,,,,,32,1,4.000000e+000,7.900238e-003,0.000000e+000,0,,0,
1524269629.059,,0.000000e+000,5.499773e+001,8.675595e-007,0.000000e+000,2,0.000000e+000,0.000000e+000,,,,,,,,,,,,,,32,1,4.000000e+000,1.308441e-003,0.000000e+000,0,,0,
1524269666.879,,0.000000e+000,5.500629e+001,8.186498e-007,0.000000e+000,2,0.000000e+000,0.000000e+000,,,,,,,,,,,,,,32,1,4.000000e+000,7.888794e-003,0.000000e+000,0,,0,
1524269704.259,,0.000000e+000,5.500037e+001,8.015240e-007,0.000000e+000,2,0.000000e+000,0.000000e+000,,,,,,,,,,,,,,32,1,4.000000e+000,1.319885e-003,0.000000e+000,0,,0,
1524269741.099,,0.000000e+000,5.499445e+001,8.500864e-007,0.000000e+000,2,0.000000e+000,0.000000e+000,,,,,,,,,,,,,,32,1,4.000000e+000,7.881165e-003,0.000000e+000,0,,0,
1524269779.059,,0.000000e+000,5.499905e+001,8.418428e-007,0.000000e+000,2,0.000000e+000,0.000000e+000,,,,,,,,,,,,,,32,1,4.000000e+000,1.319885e-003,0.000000e+000,0,,0,
1524269817.069,,0.000000e+000,5.499642e+001,7.453060e-007,0.000000e+000,2,0.000000e+000,0.000000e+000,,,,,,,,,,,,,,32,1,4.000000e+000,3.940582e-003,0.000000e+000,0,,0,
1524269854.610,,0.000000e+000,5.500169e+001,8.364686e-007,0.000000e+000,2,0.000000e+000,0.000000e+000,,,,,,,,,,,,,,32,1,4.000000e+000,9.208679e-003,0.000000e+000,0,,0,
1524269892.440,,0.000000e+000,5.500169e+001,8.640011e-007,0.000000e+000,2,0.000000e+000,0.000000e+000,,,,,,,,,,,,,,32,1,4.000000e+000,3.959656e-003,0.000000e+000,0,,0,
1524269930.150,,0.000000e+000,5.499840e+001,9.230366e-007,0.000000e+000,2,0.000000e+000,0.000000e+000,,,,,,,,,,,,,,32,1,4.000000e+000,5.260468e-003,0.000000e+000,0,,0,
1524269968.220,,0.000000e+000,5.499709e+001,9.540180e-007,0.000000e+000,2,0.000000e+000,0.000000e+000,,,,,,,,,,,,,,32,1,4.000000e+000,7.888794e-003,0.000000e+000,0,,0,
1524270005.870,,0.000000e+000,5.499972e+001,9.954437e-007,0.000000e+000,2,0.000000e+000,0.000000e+000,,,,,,,,,,,,,,32,1,4.000000e+000,1.314926e-002,0.000000e+000,0,,0,
1524270043.910,,0.000000e+000,5.499577e+001,9.735542e-007,0.000000e+000,2,0.000000e+000,0.000000e+000,,,,,,,,,,,,,,32,1,4.000000e+000,5.249023e-003,0.000000e+000,0,,0,
1524270081.870,,0.000000e+000,5.499773e+001,1.021285e-006,0.000000e+000,2,0.000000e+000,0.000000e+000,,,,,,,,,,,,,,32,1,4.000000e+000,1.308441e-003,0.000000e+000,0,,0,
1524270119.370,,0.000000e+000,5.499972e+001,1.065192e-006,0.000000e+000,2,0.000000e+000,0.000000e+000,,,,,,,,,,,,,,32,1,4.000000e+000,5.268097e-003,0.000000e+000,0,,0,
1524270157.020,,0.000000e+000,5.498985e+001,9.740977e-007,0.000000e+000,2,0.000000e+000,0.000000e+000,,,,,,,,,,,,,,32,1,4.000000e+000,1.319885e-003,0.000000e+000,0,,0,
1524270195.170,,0.000000e+000,5.499708e+001,1.029322e-006,0.000000e+000,2,0.000000e+000,0.000000e+000,,,,,,,,,,,,,,32,1,4.000000e+000,1.578140e-002,0.000000e+000,0,,0,
1524270232.780,,0.000000e+000,5.499839e+001,1.084147e-006,0.000000e+000,2,0.000000e+000,0.000000e+000,,,,,,,,,,,,,,32,1,4.000000e+000,0.000000e+000,0.000000e+000,0,,0,
1524270270.640,,0.000000e+000,5.500037e+001,1.026719e-006,0.000000e+000,2,0.000000e+000,0.000000e+000,,,,,,,,,,,,,,32,1,4.000000e+000,3.959656e-003,0.000000e+000,0,,0,
1524270308.840,,0.000000e+000,5.499643e+001,1.062442e-006,0.000000e+000,2,0.000000e+000,0.000000e+000,,,,,,,,,,,,,,32,1,4.000000e+000,1.312256e-003,0.000000e+000,0,,0,
1524270345.830,,0.000000e+000,5.499313e+001,9.992535e-007,0.000000e+000,2,0.000000e+000,0.000000e+000,,,,,,,,,,,,,,32,1,4.000000e+000,1.314926e-002,0.000000e+000,0,,0,
1524270384.070,,0.000000e+000,5.499905e+001,1.036299e-006,0.000000e+000,2,0.000000e+000,0.000000e+000,,,,,,,,,,,,,,32,1,4.000000e+000,3.948212e-003,0.000000e+000,0,,0,
1524270421.970,,0.000000e+000,5.499643e+001,1.089336e-006,0.000000e+000,2,0.000000e+000,0.000000e+000,,,,,,,,,,,,,,32,1,4.000000e+000,9.208679e-003,0.000000e+000,0,,0,
1524270459.610,,0.000000e+000,5.499906e+001,1.089352e-006,0.000000e+000,2,0.000000e+000,0.000000e+000,,,,,,,,,,,,,,32,1,4.000000e+000,6.580353e-003,0.000000e+000,0,,0,
1524270497.680,,0.000000e+000,5.500037e+001,1.108228e-006,0.000000e+000,2,0.000000e+000,0.000000e+000,,,,,,,,,,,,,,32,1,4.000000e+000,9.201050e-003,0.000000e+000,0,,0,
1524270534.690,,0.000000e+000,5.499905e+001,1.105419e-006,0.000000e+000,2,0.000000e+000,0.000000e+000,,,,,,,,,,,,,,32,1,4.000000e+000,1.319885e-003,0.000000e+000,0,,0,
1524270572.411,,0.000000e+000,5.499577e+001,1.147632e-006,0.000000e+000,2,0.000000e+000,0.000000e+000,,,,,,,,,,,,,,32,1,4.000000e+000,0.000000e+000,0.000000e+000,0,,0,
1524270609.971,,0.000000e+000,5.499445e+001,1.070850e-006,0.000000e+000,2,0.000000e+000,0.000000e+000,,,,,,,,,,,,,,32,1,4.000000e+000,2.628326e-003,0.000000e+000,0,,0,
1524270648.131,,0.000000e+000,5.499445e+001,1.092919e-006,0.000000e+000,2,0.000000e+000,0.000000e+000,,,,,,,,,,,,,,32,1,4.000000e+000,1.052094e-002,0.000000e+000,0,,0,
1524270685.871,,0.000000e+000,5.499840e+001,1.172606e-006,0.000000e+000,2,0.000000e+000,0.000000e+000,,,,,,,,,,,,,,32,1,4.000000e+000,5.260468e-003,0.000000e+000,0,,0,
1524270723.551,,0.000000e+000,5.500103e+001,1.120691e-006,0.000000e+000,2,0.000000e+000,0.000000e+000,,,,,,,,,,,,,,32,1,4.000000e+000,2.639771e-003,0.000000e+000,0,,0,
1524270760.941,,0.000000e+000,5.499708e+001,1.148588e-006,0.000000e+000,2,0.000000e+000,0.000000e+000,,,,,,,,,,,,,,32,1,4.000000e+000,5.260468e-003,0.000000e+000,0,,0,
1524270798.511,,0.000000e+000,5.499643e+001,1.134477e-006,0.000000e+000,2,0.000000e+000,0.000000e+000,,,,,,,,,,,,,,32,1,4.000000e+000,1.312256e-003,0.000000e+000,0,,0,
1524270837.091,,0.000000e+000,5.499709e+001,1.178508e-006,0.000000e+000,2,0.000000e+000,0.000000e+000,,,,,,,,,,,,,,32,1,4.000000e+000,7.888794e-003,0.000000e+000,0,,0,
1524270874.531,,0.000000e+000,5.499906e+001,1.196429e-006,0.000000e+000,2,0.000000e+000,0.000000e+000,,,,,,,,,,,,,,32,1,4.000000e+000,6.580353e-003,0.000000e+000,0,,0,
1524270912.381,,0.000000e+000,5.499708e+001,1.142976e-006,0.000000e+000,2,0.000000e+000,0.000000e+000,,,,,,,,,,,,,,32,1,4.000000e+000,2.620697e-003,0.000000e+000,0,,0,
1524270950.231,,0.000000e+000,5.499773e+001,1.213420e-006,0.000000e+000,2,0.000000e+000,0.000000e+000,,,,,,,,,,,,,,32,1,4.000000e+000,1.308441e-003,0.000000e+000,0,,0,
1524270987.811,,0.000000e+000,5.500103e+001,1.214840e-006,0.000000e+000,2,0.000000e+000,0.000000e+000,,,,,,,,,,,,,,32,1,4.000000e+000,2.639771e-003,0.000000e+000,0,,0,
1524271026.211,,0.000000e+000,5.500169e+001,1.181780e-006,0.000000e+000,2,0.000000e+000,0.000000e+000,,,,,,,,,,,,,,32,1,4.000000e+000,3.959656e-003,0.000000e+000,0,,0,
1524271063.811,,0.000000e+000,5.499972e+001,1.219544e-006,0.000000e+000,2,0.000000e+000,0.000000e+000,,,,,,,,,,,,,,32,1,4.000000e+000,7.900238e-003,0.000000e+000,0,,0,
1524271101.411,,0.000000e+000,5.499116e+001,1.205477e-006,0.000000e+000,2,0.000000e+000,0.000000e+000,,,,,,,,,,,,,,32,1,4.000000e+000,1.446152e-002,0.000000e+000,0,,0,
1524271139.011,,0.000000e+000,5.499445e+001,1.207400e-006,0.000000e+000,2,0.000000e+000,0.000000e+000,,,,,,,,,,,,,,32,1,4.000000e+000,5.260468e-003,0.000000e+000,0,,0,
1524271176.791,,0.000000e+000,5.499445e+001,1.148174e-006,0.000000e+000,2,0.000000e+000,0.000000e+000,,,,,,,,,,,,,,32,1,4.000000e+000,7.881165e-003,0.000000e+000,0,,0,
1524271215.641,,0.000000e+000,5.500037e+001,1.270114e-006,0.000000e+000,2,0.000000e+000,0.000000e+000,,,,,,,,,,,,,,32,1,4.000000e+000,6.587982e-003,0.000000e+000,0,,0,
1524271253.921,,0.000000e+000,5.499708e+001,1.272518e-006,0.000000e+000,2,0.000000e+000,0.000000e+000,,,,,,,,,,,,,,32,1,4.000000e+000,5.260468e-003,0.000000e+000,0,,0,
1524271292.142,,0.000000e+000,5.499773e+001,1.242384e-006,0.000000e+000,2,0.000000e+000,0.000000e+000,,,,,,,,,,,,,,32,1,4.000000e+000,1.308441e-003,0.000000e+000,0,,0,
1524271329.332,,0.000000e+000,5.499972e+001,1.237621e-006,0.000000e+000,2,0.000000e+000,0.000000e+000,,,,,,,,,,,,,,32,1,4.000000e+000,7.900238e-003,0.000000e+000,0,,0,
1524271367.422,,0.000000e+000,5.499774e+001,1.292357e-006,0.000000e+000,2,0.000000e+000,0.000000e+000,,,,,,,,,,,,,,32,1,4.000000e+000,6.580353e-003,0.000000e+000,0,,0,
1524271404.642,,0.000000e+000,5.499971e+001,1.275935e-006,0.000000e+000,2,0.000000e+000,0.000000e+000,,,,,,,,,,,,,,32,1,4.000000e+000,2.639771e-003,0.000000e+000,0,,0,
1524271442.552,,0.000000e+000,5.500103e+001,1.284067e-006,0.000000e+000,2,0.000000e+000,0.000000e+000,,,,,,,,,,,,,,32,1,4.000000e+000,2.639771e-003,0.000000e+000,0,,0,
1524271480.802,,0.000000e+000,5.500432e+001,1.240370e-006,0.000000e+000,2,0.000000e+000,0.000000e+000,,,,,,,,,,,,,,32,1,4.000000e+000,3.940582e-003,0.000000e+000,0,,0,
1524271518.972,,0.000000e+000,5.500694e+001,1.345113e-006,0.000000e+000,2,0.000000e+000,0.000000e+000,,,,,,,,,,,,,,32,1,4.000000e+000,3.948212e-003,0.000000e+000,0,,0,
1524271557.452,,0.000000e+000,5.500300e+001,1.330052e-006,0.000000e+000,2,0.000000e+000,0.000000e+000,,,,,,,,,,,,,,32,1,4.000000e+000,3.940582e-003,0.000000e+000,0,,0,
1524271595.872,,0.000000e+000,5.500366e+001,1.152604e-006,0.000000e+000,2,0.000000e+000,0.000000e+000,,,,,,,,,,,,,,32,1,4.000000e+000,2.620697e-003,0.000000e+000,0,,0,
1524271634.222,,0.000000e+000,5.499839e+001,1.279573e-006,0.000000e+000,2,0.000000e+000,0.000000e+000,,,,,,,,,,,,,,32,1,4.000000e+000,0.000000e+000,0.000000e+000,0,,0,
1524271671.692,,0.000000e+000,5.499971e+001,1.352951e-006,0.000000e+000,2,0.000000e+000,0.000000e+000,,,,,,,,,,,,,,32,1,4.000000e+000,2.639771e-003,0.000000e+000,0,,0,
1524271709.842,,0.000000e+000,5.499708e+001,1.354827e-006,0.000000e+000,2,0.000000e+000,0.000000e+000,,,,,,,,,,,,,,32,1,4.000000e+000,5.260468e-003,0.000000e+000,0,,0,
1524271747.702,,0.000000e+000,5.499971e+001,1.299322e-006,0.000000e+000,2,0.000000e+000,0.000000e+000,,,,,,,,,,,,,,32,1,4.000000e+000,0.000000e+000,0.000000e+000,0,,0,
1524271785.912,,0.000000e+000,5.499905e+001,1.391408e-006,0.000000e+000,2,0.000000e+000,0.000000e+000,,,,,,,,,,,,,,32,1,4.000000e+000,3.948212e-003,0.000000e+000,0,,0,
1524271823.982,,0.000000e+000,5.499774e+001,1.364211e-006,0.000000e+000,2,0.000000e+000,0.000000e+000,,,,,,,,,,,,,,32,1,4.000000e+000,3.940582e-003,0.000000e+000,0,,0,
1524271861.242,,0.000000e+000,5.499905e+001,1.382988e-006,0.000000e+000,2,0.000000e+000,0.000000e+000,,,,,,,,,,,,,,32,1,4.000000e+000,1.319885e-003,0.000000e+000,0,,0,
1524271899.192,,0.000000e+000,5.499905e+001,1.385070e-006,0.000000e+000,2,0.000000e+000,0.000000e+000,,,,,,,,,,,,,,32,1,4.000000e+000,1.319885e-003,0.000000e+000,0,,0,
1524271937.062,,0.000000e+000,5.499577e+001,1.336965e-006,0.000000e+000,2,0.000000e+000,0.000000e+000,,,,,,,,,,,,,,32,1,4.000000e+000,7.888794e-003,0.000000e+000,0,,0,
1524271975.033,,0.000000e+000,5.499577e+001,1.375897e-006,0.000000e+000,2,0.000000e+000,0.000000e+000,,,,,,,,,,,,,,32,1,4.000000e+000,5.249023e-003,0.000000e+000,0,,0,
1524272012.703,,0.000000e+000,5.499577e+001,1.360393e-006,0.000000e+000,2,0.000000e+000,0.000000e+000,,,,,,,,,,,,,,32,1,4.000000e+000,0.000000e+000,0.000000e+000,0,,0,
1524272050.903,,0.000000e+000,5.499840e+001,1.337957e-006,0.000000e+000,2,0.000000e+000,0.000000e+000,,,,,,,,,,,,,,32,1,4.000000e+000,2.628326e-003,0.000000e+000,0,,0,
1524272088.913,,0.000000e+000,5.500037e+001,1.444203e-006,0.000000e+000,2,0.000000e+000,0.000000e+000,,,,,,,,,,,,,,32,1,4.000000e+000,1.319885e-003,0.000000e+000,0,,0,
1524272126.863,,0.000000e+000,5.499971e+001,1.414846e-006,0.000000e+000,2,0.000000e+000,0.000000e+000,,,,,,,,,,,,,,32,1,4.000000e+000,2.639771e-003,0.000000e+000,0,,0,
1524272164.603,,0.000000e+000,5.499511e+001,1.402003e-006,0.000000e+000,2,0.000000e+000,0.000000e+000,,,,,,,,,,,,,,32,1,4.000000e+000,6.568909e-003,0.000000e+000,0,,0,
1524272202.583,,0.000000e+000,5.499577e+001,1.378543e-006,0.000000e+000,2,0.000000e+000,0.000000e+000,,,,,,,,,,,,,,32,1,4.000000e+000,2.632141e-003,0.000000e+000,0,,0,
1524272240.133,,0.000000e+000,5.499577e+001,1.395259e-006,0.000000e+000,2,0.000000e+000,0.000000e+000,,,,,,,,,,,,,,32,1,4.000000e+000,5.249023e-003,0.000000e+000,0,,0,
1524272277.123,,0.000000e+000,5.499972e+001,1.438330e-006,0.000000e+000,2,0.000000e+000,0.000000e+000,,,,,,,,,,,,,,32,1,4.000000e+000,5.268097e-003,0.000000e+000,0,,0,
1524272315.603,,0.000000e+000,5.500037e+001,1.453460e-006,0.000000e+000,2,0.000000e+000,0.000000e+000,,,,,,,,,,,,,,32,1,4.000000e+000,3.959656e-003,0.000000e+000,0,,0,
1524272353.363,,0.000000e+000,5.500037e+001,1.480225e-006,0.000000e+000,2,0.000000e+000,0.000000e+000,,,,,,,,,,,,,,32,1,4.000000e+000,1.319885e-003,0.000000e+000,0,,0,
1524272391.353,,0.000000e+000,5.500037e+001,1.506485e-006,0.000000e+000,2,0.000000e+000,0.000000e+000,,,,,,,,,,,,,,32,1,4.000000e+000,1.319885e-003,0.000000e+000,0,,0,
1524272428.713,,0.000000e+000,5.500301e+001,1.491061e-006,0.000000e+000,2,0.000000e+000,0.000000e+000,,,,,,,,,,,,,,32,1,4.000000e+000,1.446915e-002,0.000000e+000,0,,0,
1524272466.483,,0.000000e+000,5.499905e+001,1.532418e-006,0.000000e+000,2,0.000000e+000,0.000000e+000,,,,,,,,,,,,,,32,1,4.000000e+000,3.948212e-003,0.000000e+000,0,,0,
1524272503.913,,0.000000e+000,5.500497e+001,1.488347e-006,0.000000e+000,2,0.000000e+000,0.000000e+000,,,,,,,,,,,,,,32,1,4.000000e+000,7.888794e-003,0.000000e+000,0,,0,
1524272541.133,,0.000000e+000,5.500103e+001,1.444717e-006,0.000000e+000,2,0.000000e+000,0.000000e+000,,,,,,,,,,,,,,32,1,4.000000e+000,5.279541e-003,0.000000e+000,0,,0,
1524272578.813,,0.000000e+000,5.499840e+001,1.481547e-006,0.000000e+000,2,0.000000e+000,0.000000e+000,,,,,,,,,,,,,,32,1,4.000000e+000,5.260468e-003,0.000000e+000,0,,0,
1524272616.293,,0.000000e+000,5.499773e+001,1.528404e-006,0.000000e+000,2,0.000000e+000,0.000000e+000,,,,,,,,,,,,,,32,1,4.000000e+000,1.308441e-003,0.000000e+000,0,,0,
1524272653.723,,0.000000e+000,5.500365e+001,1.515077e-006,0.000000e+000,2,0.000000e+000,0.000000e+000,,,,,,,,,,,,,,32,1,4.000000e+000,1.052856e-002,0.000000e+000,0,,0,
1524272691.494,,0.000000e+000,5.499971e+001,1.520900e-006,0.000000e+000,2,0.000000e+000,0.000000e+000,,,,,,,,,,,,,,32,1,4.000000e+000,2.639771e-003,0.000000e+000,0,,0,
1524272704.194,,0.000000e+000,5.500563e+001,1.502455e-006,0.000000e+000,2,0.000000e+000,0.000000e+000,,,,,,,,,,,,,,32,1,4.000000e+000,1.448059e-002,0.000000e+000,0,,0,