File: Input_All/TC04-12-01K_VRMac_55K_6000s_VRMde_55K.dc.dat
[Header]
TITLE,MPMS DC Measurement
BYAPP,MPMS Measurement,2.1,Summary
FILEOPENTIME, 1524050228.062000 4/18/2018, 5:17:08 AM

INFO, APPNAME, MPMS MultiVu Application, Revision 1.61,  Build 082

INFO, NAME, TC04-12-01K
INFO, WEIGHT, 1.000
INFO, AREA, 1.000
INFO, LENGTH, 1.000
INFO, SHAPE, 0
INFO, COMMENT,
INFO, SEQUENCE FILE: VRMac_55K_6000s_VRMde_55K.seq


INFO, BACKGROUND DATA FILE:, None


STARTUPAXIS,X,4,LINEAR,AUTO,0.000000,0.000000
STARTUPAXIS,Y1,5,LINEAR,AUTO,0.000000,0.000000


STARTUPGROUP,Longitudinal
FIELDGROUP,Longitudinal,1,2,3,4,5,6,7,8,9,15,16,17,18,27,28
FIELDGROUP,Transverse,1,2,3,4,10,11,12,13,14,19,20,21,22,27,28

PLOT_APPEARANCE,ALL,HORZ_GRID_ON,VERT_GRID_ON,MARKERS_AND_LINES

[Data]
Time,Comment,Field (Oe),Temperature (K),Long Moment (emu),Long Scan Std Dev,Long Algorithm,Long Reg Fit,Long Percent Error (%),Trans Moment (emu),Trans Scan Std Dev,Trans Algorithm,Trans Reg Fit,Trans Percent Error (%),Long Moment [w/o ABS] (emu),Long Scan Std Dev [w/o ABS],Long Reg Fit [w/o ABS],Long Percent Error [w/o ABS] (%),Trans Moment [w/o ABS] (emu),Trans Scan Std Dev [w/o ABS],Trans Reg Fit [w/o ABS],Trans Percent Error [w/o ABS] (%),Points per Scan,Scans per Measurement,Scan Length (cm),Delta Temp (K),Rot Position (deg),Error,EC Comp. Running,Using ABS,
1524050228.062,,0.000000e+000,5.500037e+001,-1.799655e-005,0.000000e+000,3,9.680738e-001,0.000000e+000,,,,,,,,,,,,,,32,1,4.000000e+000,1.319885e-003,0.000000e+000,0,,0,
1524050266.002,,0.000000e+000,5.499379e+001,-1.395323e-005,0.000000e+000,3,9.649979e-001,0.000000e+000,,,,,,,,,,,,,,32,1,4.000000e+000,9.201050e-003,0.000000e+000,0,,0,
1524050303.632,,0.000000e+000,5.500498e+001,-1.207905e-005,0.000000e+000,3,9.615077e-001,0.000000e+000,,,,,,,,,,,,,,32,1,4.000000e+000,5.260468e-003,0.000000e+000,0,,0,
1524050341.632,,0.000000e+000,5.499774e+001,-1.072731e-005,0.000000e+000,3,9.665996e-001,0.000000e+000,,,,,,,,,,,,,,32,1,4.000000e+000,3.940582e-003,0.000000e+000,0,,0,
1524050379.252,,0.000000e+000,5.499643e+001,-9.818795e-006,0.000000e+000,3,9.558204e-001,0.000000e+000,,,,,,,,,,,,,,32,1,4.000000e+000,9.208679e-003,0.000000e+000,0,,0,
1524050417.282,,0.000000e+000,5.500235e+001,-9.058956e-006,0.000000e+000,3,9.609061e-001,0.000000e+000,,,,,,,,,,,,,,32,1,4.000000e+000,2.639771e-003,0.000000e+000,0,,0,
1524050454.842,,0.000000e+000,5.500169e+001,-8.486576e-006,0.000000e+000,3,9.570706e-001,0.000000e+000,,,,,,,,,,,,,,32,1,4.000000e+000,3.959656e-003,0.000000e+000,0,,0,
1524050492.252,,0.000000e+000,5.499445e+001,-8.010049e-006,0.000000e+000,3,9.554297e-001,0.000000e+000,,,,,,,,,,,,,,32,1,4.000000e+000,7.881165e-003,0.000000e+000,0,,0,
1524050528.962,,0.000000e+000,5.499840e+001,-7.524213e-006,0.000000e+000,3,9.573382e-001,0.000000e+000,,,,,,,,,,,,,,32,1,4.000000e+000,2.628326e-003,0.000000e+000,0,,0,
1524050566.952,,0.000000e+000,5.500300e+001,-7.091720e-006,0.000000e+000,3,9.557182e-001,0.000000e+000,,,,,,,,,,,,,,32,1,4.000000e+000,9.220123e-003,0.000000e+000,0,,0,
1524050604.353,,0.000000e+000,5.499905e+001,-6.843519e-006,0.000000e+000,3,9.522226e-001,0.000000e+000,,,,,,,,,,,,,,32,1,4.000000e+000,3.948212e-003,0.000000e+000,0,,0,
1524050642.243,,0.000000e+000,5.499708e+001,-6.459842e-006,0.000000e+000,3,9.484034e-001,0.000000e+000,,,,,,,,,,,,,,32,1,4.000000e+000,0.000000e+000,0.000000e+000,0,,0,
1524050679.353,,0.000000e+000,5.500103e+001,-6.183609e-006,0.000000e+000,3,9.452363e-001,0.000000e+000,,,,,,,,,,,,,,32,1,4.000000e+000,0.000000e+000,0.000000e+000,0,,0,
1524050716.973,,0.000000e+000,5.500037e+001,-5.872804e-006,0.000000e+000,3,9.454053e-001,0.000000e+000,,,,,,,,,,,,,,32,1,4.000000e+000,6.587982e-003,0.000000e+000,0,,0,
1524050754.603,,0.000000e+000,5.499972e+001,-5.677492e-006,0.000000e+000,3,9.403542e-001,0.000000e+000,,,,,,,,,,,,,,32,1,4.000000e+000,7.900238e-003,0.000000e+000,0,,0,
1524050792.603,,0.000000e+000,5.500103e+001,-5.450436e-006,0.000000e+000,3,9.420256e-001,0.000000e+000,,,,,,,,,,,,,,32,1,4.000000e+000,1.316071e-002,0.000000e+000,0,,0,
1524050830.183,,0.000000e+000,5.499708e+001,-5.312966e-006,0.000000e+000,3,9.355122e-001,0.000000e+000,,,,,,,,,,,,,,32,1,4.000000e+000,2.620697e-003,0.000000e+000,0,,0,
1524050868.163,,0.000000e+000,5.499972e+001,-5.053066e-006,0.000000e+000,3,9.418957e-001,0.000000e+000,,,,,,,,,,,,,,32,1,4.000000e+000,5.268097e-003,0.000000e+000,0,,0,
1524050905.373,,0.000000e+000,5.500366e+001,-4.869787e-006,0.000000e+000,3,9.272873e-001,0.000000e+000,,,,,,,,,,,,,,32,1,4.000000e+000,5.260468e-003,0.000000e+000,0,,0,
1524050943.023,,0.000000e+000,5.500235e+001,-4.710241e-006,0.000000e+000,3,9.191227e-001,0.000000e+000,,,,,,,,,,,,,,32,1,4.000000e+000,2.639771e-003,0.000000e+000,0,,0,
1524050980.753,,0.000000e+000,5.500234e+001,-4.548897e-006,0.000000e+000,3,9.193172e-001,0.000000e+000,,,,,,,,,,,,,,32,1,4.000000e+000,5.260468e-003,0.000000e+000,0,,0,
1524051018.633,,0.000000e+000,5.499643e+001,-4.462544e-006,0.000000e+000,3,9.240360e-001,0.000000e+000,,,,,,,,,,,,,,32,1,4.000000e+000,6.568909e-003,0.000000e+000,0,,0,
1524051056.373,,0.000000e+000,5.499905e+001,-4.314434e-006,0.000000e+000,3,9.127479e-001,0.000000e+000,,,,,,,,,,,,,,32,1,4.000000e+000,1.446915e-002,0.000000e+000,0,,0,
1524051094.673,,0.000000e+000,5.499774e+001,-4.154599e-006,0.000000e+000,3,9.190637e-001,0.000000e+000,,,,,,,,,,,,,,32,1,4.000000e+000,6.580353e-003,0.000000e+000,0,,0,
1524051131.703,,0.000000e+000,5.499774e+001,-4.071770e-006,0.000000e+000,3,8.896210e-001,0.000000e+000,,,,,,,,,,,,,,32,1,4.000000e+000,6.580353e-003,0.000000e+000,0,,0,
1524051168.993,,0.000000e+000,5.500234e+001,-3.947248e-006,0.000000e+000,3,9.148292e-001,0.000000e+000,,,,,,,,,,,,,,32,1,4.000000e+000,7.900238e-003,0.000000e+000,0,,0,
1524051206.333,,0.000000e+000,5.500300e+001,-3.919314e-006,0.000000e+000,3,9.023668e-001,0.000000e+000,,,,,,,,,,,,,,32,1,4.000000e+000,9.220123e-003,0.000000e+000,0,,0,
1524051244.163,,0.000000e+000,5.499708e+001,-3.760918e-006,0.000000e+000,3,9.158627e-001,0.000000e+000,,,,,,,,,,,,,,32,1,4.000000e+000,0.000000e+000,0.000000e+000,0,,0,
1524051282.493,,0.000000e+000,5.500169e+001,-3.747157e-006,0.000000e+000,3,9.040620e-001,0.000000e+000,,,,,,,,,,,,,,32,1,4.000000e+000,3.959656e-003,0.000000e+000,0,,0,
1524051319.424,,0.000000e+000,5.499774e+001,-3.567007e-006,0.000000e+000,3,9.047171e-001,0.000000e+000,,,,,,,,,,,,,,32,1,4.000000e+000,3.940582e-003,0.000000e+000,0,,0,
1524051357.634,,0.000000e+000,5.500103e+001,-3.587372e-006,0.000000e+000,3,8.992311e-001,0.000000e+000,,,,,,,,,,,,,,32,1,4.000000e+000,7.888794e-003,0.000000e+000,0,,0,
1524051395.084,,0.000000e+000,5.499773e+001,-3.417322e-006,0.000000e+000,3,8.952039e-001,0.000000e+000,,,,,,,,,,,,,,32,1,4.000000e+000,1.308441e-003,0.000000e+000,0,,0,
1524051433.084,,0.000000e+000,5.500103e+001,-3.433960e-006,0.000000e+000,3,8.809002e-001,0.000000e+000,,,,,,,,,,,,,,32,1,4.000000e+000,7.888794e-003,0.000000e+000,0,,0,
1524051470.684,,0.000000e+000,5.499577e+001,-3.255052e-006,0.000000e+000,3,8.712984e-001,0.000000e+000,,,,,,,,,,,,,,32,1,4.000000e+000,5.249023e-003,0.000000e+000,0,,0,
1524051508.724,,0.000000e+000,5.500366e+001,-3.256122e-006,0.000000e+000,3,8.818827e-001,0.000000e+000,,,,,,,,,,,,,,32,1,4.000000e+000,5.260468e-003,0.000000e+000,0,,0,
1524051546.344,,0.000000e+000,5.499971e+001,-3.155670e-006,0.000000e+000,3,8.720561e-001,0.000000e+000,,,,,,,,,,,,,,32,1,4.000000e+000,2.639771e-003,0.000000e+000,0,,0,
1524051584.274,,0.000000e+000,5.499839e+001,-3.086819e-006,0.000000e+000,3,8.631555e-001,0.000000e+000,,,,,,,,,,,,,,32,1,4.000000e+000,0.000000e+000,0.000000e+000,0,,0,
1524051621.924,,0.000000e+000,5.500629e+001,-3.072971e-006,0.000000e+000,3,8.629099e-001,0.000000e+000,,,,,,,,,,,,,,32,1,4.000000e+000,5.249023e-003,0.000000e+000,0,,0,
1524051659.704,,0.000000e+000,5.499643e+001,-2.935532e-006,0.000000e+000,3,8.758728e-001,0.000000e+000,,,,,,,,,,,,,,32,1,4.000000e+000,6.568909e-003,0.000000e+000,0,,0,
1524051697.804,,0.000000e+000,5.499773e+001,-2.992935e-006,0.000000e+000,3,8.398876e-001,0.000000e+000,,,,,,,,,,,,,,32,1,4.000000e+000,1.308441e-003,0.000000e+000,0,,0,
1524051735.354,,0.000000e+000,5.499971e+001,-2.949168e-006,0.000000e+000,3,8.654435e-001,0.000000e+000,,,,,,,,,,,,,,32,1,4.000000e+000,2.639771e-003,0.000000e+000,0,,0,
1524051773.094,,0.000000e+000,5.499248e+001,-2.856744e-006,0.000000e+000,3,8.514107e-001,0.000000e+000,,,,,,,,,,,,,,32,1,4.000000e+000,1.710129e-002,0.000000e+000,0,,0,
1524051810.594,,0.000000e+000,5.499773e+001,-3.023926e-006,0.000000e+000,3,8.235976e-001,0.000000e+000,,,,,,,,,,,,,,32,1,4.000000e+000,1.308441e-003,0.000000e+000,0,,0,
1524051848.174,,0.000000e+000,5.499708e+001,-2.789269e-006,0.000000e+000,3,8.187754e-001,0.000000e+000,,,,,,,,,,,,,,32,1,4.000000e+000,0.000000e+000,0.000000e+000,0,,0,
1524051885.484,,0.000000e+000,5.499971e+001,-2.890025e-006,0.000000e+000,3,8.215593e-001,0.000000e+000,,,,,,,,,,,,,,32,1,4.000000e+000,2.639771e-003,0.000000e+000,0,,0,
1524051923.454,,0.000000e+000,5.499511e+001,-2.757371e-006,0.000000e+000,3,8.112318e-001,0.000000e+000,,,,,,,,,,,,,,32,1,4.000000e+000,1.319885e-003,0.000000e+000,0,,0,
1524051985.944,,0.000000e+000,5.499774e+001,-2.784922e-006,0.000000e+000,3,7.846379e-001,0.000000e+000,,,,,,,,,,,,,,32,1,4.000000e+000,6.580353e-003,0.000000e+000,0,,0,
1524052023.505,,0.000000e+000,5.499971e+001,-2.678357e-006,0.000000e+000,3,7.921916e-001,0.000000e+000,,,,,,,,,,,,,,32,1,4.000000e+000,0.000000e+000,0.000000e+000,0,,0,
1524052061.825,,0.000000e+000,5.499839e+001,-2.707845e-006,0.000000e+000,3,7.943847e-001,0.000000e+000,,,,,,,,,,,,,,32,1,4.000000e+000,0.000000e+000,0.000000e+000,0,,0,
1524052099.725,,0.000000e+000,5.500300e+001,-2.756743e-006,0.000000e+000,3,7.982295e-001,0.000000e+000,,,,,,,,,,,,,,32,1,4.000000e+000,3.940582e-003,0.000000e+000,0,,0,
1524052137.465,,0.000000e+000,5.500037e+001,-2.643833e-006,0.000000e+000,3,8.115109e-001,0.000000e+000,,,,,,,,,,,,,,32,1,4.000000e+000,6.587982e-003,0.000000e+000,0,,0,
1524052177.385,,0.000000e+000,5.500235e+001,-8.452596e-007,0.000000e+000,2,0.000000e+000,0.000000e+000,,,,,,,,,,,,,,32,1,4.000000e+000,1.052856e-002,0.000000e+000,0,,0,
1524052219.701,,0.000000e+000,5.499840e+001,-6.925601e-007,0.000000e+000,2,0.000000e+000,0.000000e+000,,,,,,,,,,,,,,32,1,4.000000e+000,2.628326e-003,0.000000e+000,0,,0,
1524052261.937,,0.000000e+000,5.500366e+001,-6.580137e-007,0.000000e+000,2,0.000000e+000,0.000000e+000,,,,,,,,,,,,,,32,1,4.000000e+000,5.260468e-003,0.000000e+000,0,,0,
1524052304.083,,0.000000e+000,5.499971e+001,-5.991015e-007,0.000000e+000,2,0.000000e+000,0.000000e+000,,,,,,,,,,,,,,32,1,4.000000e+000,2.639771e-003,0.000000e+000,0,,0,
1524052346.379,,0.000000e+000,5.499906e+001,-5.614688e-007,0.000000e+000,2,0.000000e+000,0.000000e+000,,,,,,,,,,,,,,32,1,4.000000e+000,6.580353e-003,0.000000e+000,0,,0,
1524052388.445,,0.000000e+000,5.499511e+001,-4.551072e-007,0.000000e+000,2,0.000000e+000,0.000000e+000,,,,,,,,,,,,,,32,1,4.000000e+000,1.319885e-003,0.000000e+000,0,,0,
1524052430.821,,0.000000e+000,5.500235e+001,-4.502788e-007,0.000000e+000,2,0.000000e+000,0.000000e+000,,,,,,,,,,,,,,32,1,4.000000e+000,2.639771e-003,0.000000e+000,0,,0,
1524052474.607,,0.000000e+000,5.500234e+001,-4.335527e-007,0.000000e+000,2,0.000000e+000,0.000000e+000,,,,,,,,,,,,,,32,1,4.000000e+000,5.260468e-003,0.000000e+000,0,,0,
1524052514.621,,0.000000e+000,5.499971e+001,2.472869e-006,0.000000e+000,3,6.229868e-001,0.000000e+000,,,,,,,,,,,,,,32,1,4.000000e+000,2.639771e-003,0.000000e+000,0,,0,
1524052556.585,,0.000000e+000,5.500037e+001,-3.631262e-007,0.000000e+000,2,0.000000e+000,0.000000e+000,,,,,,,,,,,,,,32,1,4.000000e+000,1.319885e-003,0.000000e+000,0,,0,
1524052596.157,,0.000000e+000,5.500169e+001,2.598366e-006,0.000000e+000,3,6.426217e-001,0.000000e+000,,,,,,,,,,,,,,32,1,4.000000e+000,1.319885e-003,0.000000e+000,0,,0,
1524052634.047,,0.000000e+000,5.499839e+001,2.477127e-006,0.000000e+000,3,6.487268e-001,0.000000e+000,,,,,,,,,,,,,,32,1,4.000000e+000,0.000000e+000,0.000000e+000,0,,0,
1524052671.727,,0.000000e+000,5.499840e+001,2.664987e-006,0.000000e+000,3,6.660784e-001,0.000000e+000,,,,,,,,,,,,,,32,1,4.000000e+000,2.628326e-003,0.000000e+000,0,,0,
1524052709.627,,0.000000e+000,5.499445e+001,2.423167e-006,0.000000e+000,3,6.529808e-001,0.000000e+000,,,,,,,,,,,,,,32,1,4.000000e+000,0.000000e+000,0.000000e+000,0,,0,
1524052747.378,,0.000000e+000,5.500432e+001,2.521693e-006,0.000000e+000,3,6.385969e-001,0.000000e+000,,,,,,,,,,,,,,32,1,4.000000e+000,6.580353e-003,0.000000e+000,0,,0,
1524052787.280,,0.000000e+000,5.499906e+001,-6.455868e-008,0.000000e+000,2,0.000000e+000,0.000000e+000,,,,,,,,,,,,,,32,1,4.000000e+000,6.580353e-003,0.000000e+000,0,,0,
1524052828.014,,0.000000e+000,5.499840e+001,-2.608356e-006,0.000000e+000,3,7.371207e-001,0.000000e+000,,,,,,,,,,,,,,32,1,4.000000e+000,5.260468e-003,0.000000e+000,0,,0,
1524052872.050,,0.000000e+000,5.499905e+001,7.084250e-008,0.000000e+000,2,0.000000e+000,0.000000e+000,,,,,,,,,,,,,,32,1,4.000000e+000,1.319885e-003,0.000000e+000,0,,0,
1524052911.192,,0.000000e+000,5.499905e+001,-6.185876e-008,0.000000e+000,2,0.000000e+000,0.000000e+000,,,,,,,,,,,,,,32,1,4.000000e+000,1.972961e-002,0.000000e+000,0,,0,
1524052949.974,,0.000000e+000,5.500234e+001,5.747546e-008,0.000000e+000,2,0.000000e+000,0.000000e+000,,,,,,,,,,,,,,32,1,4.000000e+000,7.900238e-003,0.000000e+000,0,,0,
1524052990.428,,0.000000e+000,5.499972e+001,7.757937e-008,0.000000e+000,2,0.000000e+000,0.000000e+000,,,,,,,,,,,,,,32,1,4.000000e+000,5.268097e-003,0.000000e+000,0,,0,
1524053027.738,,0.000000e+000,5.499972e+001,-2.594952e-006,0.000000e+000,3,7.345673e-001,0.000000e+000,,,,,,,,,,,,,,32,1,4.000000e+000,5.268097e-003,0.000000e+000,0,,0,
1524053065.668,,0.000000e+000,5.499774e+001,-2.574760e-006,0.000000e+000,3,7.331835e-001,0.000000e+000,,,,,,,,,,,,,,32,1,4.000000e+000,6.580353e-003,0.000000e+000,0,,0,
1524053103.398,,0.000000e+000,5.500235e+001,-2.625144e-006,0.000000e+000,3,7.236432e-001,0.000000e+000,,,,,,,,,,,,,,32,1,4.000000e+000,2.639771e-003,0.000000e+000,0,,0,
1524053141.268,,0.000000e+000,5.499773e+001,-2.502113e-006,0.000000e+000,3,7.290346e-001,0.000000e+000,,,,,,,,,,,,,,32,1,4.000000e+000,1.308441e-003,0.000000e+000,0,,0,
1524053178.808,,0.000000e+000,5.500300e+001,-2.595339e-006,0.000000e+000,3,7.211573e-001,0.000000e+000,,,,,,,,,,,,,,32,1,4.000000e+000,9.220123e-003,0.000000e+000,0,,0,
1524053216.858,,0.000000e+000,5.499905e+001,-2.566012e-006,0.000000e+000,3,7.265738e-001,0.000000e+000,,,,,,,,,,,,,,32,1,4.000000e+000,1.319885e-003,0.000000e+000,0,,0,
1524053255.830,,0.000000e+000,5.500366e+001,-2.515625e-006,0.000000e+000,3,7.040301e-001,0.000000e+000,,,,,,,,,,,,,,32,1,4.000000e+000,7.900238e-003,0.000000e+000,0,,0,
1524053298.746,,0.000000e+000,5.500366e+001,4.272976e-007,0.000000e+000,2,0.000000e+000,0.000000e+000,,,,,,,,,,,,,,32,1,4.000000e+000,7.900238e-003,0.000000e+000,0,,0,
1524053340.572,,0.000000e+000,5.499642e+001,3.694049e-007,0.000000e+000,2,0.000000e+000,0.000000e+000,,,,,,,,,,,,,,32,1,4.000000e+000,3.940582e-003,0.000000e+000,0,,0,
1524053382.648,,0.000000e+000,5.498985e+001,4.550488e-007,0.000000e+000,2,0.000000e+000,0.000000e+000,,,,,,,,,,,,,,32,1,4.000000e+000,1.446152e-002,0.000000e+000,0,,0,
1524053424.604,,0.000000e+000,5.499511e+001,5.477507e-007,0.000000e+000,2,0.000000e+000,0.000000e+000,,,,,,,,,,,,,,32,1,4.000000e+000,3.940582e-003,0.000000e+000,0,,0,
1524053467.271,,0.000000e+000,5.499643e+001,5.015485e-007,0.000000e+000,2,0.000000e+000,0.000000e+000,,,,,,,,,,,,,,32,1,4.000000e+000,1.312256e-003,0.000000e+000,0,,0,
1524053510.547,,0.000000e+000,5.500694e+001,5.876450e-007,0.000000e+000,2,0.000000e+000,0.000000e+000,,,,,,,,,,,,,,32,1,4.000000e+000,3.948212e-003,0.000000e+000,0,,0,
1524053552.793,,0.000000e+000,5.499182e+001,6.046482e-007,0.000000e+000,2,0.000000e+000,0.000000e+000,,,,,,,,,,,,,,32,1,4.000000e+000,5.260468e-003,0.000000e+000,0,,0,
1524053595.789,,0.000000e+000,5.499840e+001,5.950163e-007,0.000000e+000,2,0.000000e+000,0.000000e+000,,,,,,,,,,,,,,32,1,4.000000e+000,7.900238e-003,0.000000e+000,0,,0,
1524053637.985,,0.000000e+000,5.499775e+001,6.317235e-007,0.000000e+000,2,0.000000e+000,0.000000e+000,,,,,,,,,,,,,,32,1,4.000000e+000,9.208679e-003,0.000000e+000,0,,0,
1524053680.179,,0.000000e+000,5.500037e+001,-1.341513e-006,0.000000e+000,3,0.000000e+000,0.000000e+000,,,,,,,,,,,,,,32,1,4.000000e+000,1.184082e-002,0.000000e+000,0,,0,
1524053721.103,,0.000000e+000,5.499643e+001,2.447918e-006,0.000000e+000,3,7.211491e-001,0.000000e+000,,,,,,,,,,,,,,32,1,4.000000e+000,1.184082e-002,0.000000e+000,0,,0,
1524053763.629,,0.000000e+000,5.499577e+001,7.627720e-007,0.000000e+000,2,0.000000e+000,0.000000e+000,,,,,,,,,,,,,,32,1,4.000000e+000,5.249023e-003,0.000000e+000,0,,0,
1524053804.063,,0.000000e+000,5.499971e+001,7.663305e-007,0.000000e+000,2,0.000000e+000,0.000000e+000,,,,,,,,,,,,,,32,1,4.000000e+000,0.000000e+000,0.000000e+000,0,,0,
1524053844.327,,0.000000e+000,5.499905e+001,7.810988e-007,0.000000e+000,2,0.000000e+000,0.000000e+000,,,,,,,,,,,,,,32,1,4.000000e+000,1.182938e-002,0.000000e+000,0,,0,
1524053881.507,,0.000000e+000,5.500169e+001,2.367754e-006,0.000000e+000,3,7.222815e-001,0.000000e+000,,,,,,,,,,,,,,32,1,4.000000e+000,3.959656e-003,0.000000e+000,0,,0,
1524053919.417,,0.000000e+000,5.500037e+001,2.443936e-006,0.000000e+000,3,7.026988e-001,0.000000e+000,,,,,,,,,,,,,,32,1,4.000000e+000,3.959656e-003,0.000000e+000,0,,0,
1524053957.067,,0.000000e+000,5.499708e+001,2.546884e-006,0.000000e+000,3,7.044486e-001,0.000000e+000,,,,,,,,,,,,,,32,1,4.000000e+000,2.620697e-003,0.000000e+000,0,,0,
1524053995.007,,0.000000e+000,5.499511e+001,2.347945e-006,0.000000e+000,3,7.326783e-001,0.000000e+000,,,,,,,,,,,,,,32,1,4.000000e+000,6.568909e-003,0.000000e+000,0,,0,
1524054032.607,,0.000000e+000,5.499971e+001,2.474038e-006,0.000000e+000,3,7.319615e-001,0.000000e+000,,,,,,,,,,,,,,32,1,4.000000e+000,0.000000e+000,0.000000e+000,0,,0,
1524054070.577,,0.000000e+000,5.499773e+001,2.398227e-006,0.000000e+000,3,7.532409e-001,0.000000e+000,,,,,,,,,,,,,,32,1,4.000000e+000,1.308441e-003,0.000000e+000,0,,0,
1524054108.247,,0.000000e+000,5.500037e+001,2.504265e-006,0.000000e+000,3,7.189797e-001,0.000000e+000,,,,,,,,,,,,,,32,1,4.000000e+000,3.959656e-003,0.000000e+000,0,,0,
1524054146.168,,0.000000e+000,5.499840e+001,2.453168e-006,0.000000e+000,3,7.441357e-001,0.000000e+000,,,,,,,,,,,,,,32,1,4.000000e+000,5.260468e-003,0.000000e+000,0,,0,
1524054183.788,,0.000000e+000,5.500103e+001,2.484590e-006,0.000000e+000,3,7.273468e-001,0.000000e+000,,,,,,,,,,,,,,32,1,4.000000e+000,5.279541e-003,0.000000e+000,0,,0,
1524054222.088,,0.000000e+000,5.499774e+001,2.427778e-006,0.000000e+000,3,7.290103e-001,0.000000e+000,,,,,,,,,,,,,,32,1,4.000000e+000,3.940582e-003,0.000000e+000,0,,0,
1524054259.558,,0.000000e+000,5.499972e+001,2.439004e-006,0.000000e+000,3,7.616003e-001,0.000000e+000,,,,,,,,,,,,,,32,1,4.000000e+000,5.268097e-003,0.000000e+000,0,,0,
1524054297.498,,0.000000e+000,5.499248e+001,2.460693e-006,0.000000e+000,3,7.546905e-001,0.000000e+000,,,,,,,,,,,,,,32,1,4.000000e+000,3.940582e-003,0.000000e+000,0,,0,
1524054335.058,,0.000000e+000,5.499971e+001,2.440193e-006,0.000000e+000,3,7.303447e-001,0.000000e+000,,,,,,,,,,,,,,32,1,4.000000e+000,0.000000e+000,0.000000e+000,0,,0,
1524054373.808,,0.000000e+000,5.500695e+001,2.442479e-006,0.000000e+000,3,7.494778e-001,0.000000e+000,,,,,,,,,,,,,,32,1,4.000000e+000,9.201050e-003,0.000000e+000,0,,0,
1524054411.818,,0.000000e+000,5.499775e+001,2.518797e-006,0.000000e+000,3,7.889464e-001,0.000000e+000,,,,,,,,,,,,,,32,1,4.000000e+000,9.208679e-003,0.000000e+000,0,,0,
1524054449.368,,0.000000e+000,5.499445e+001,2.512765e-006,0.000000e+000,3,7.280873e-001,0.000000e+000,,,,,,,,,,,,,,32,1,4.000000e+000,2.628326e-003,0.000000e+000,0,,0,
1524054488.228,,0.000000e+000,5.500300e+001,2.316039e-006,0.000000e+000,3,7.606047e-001,0.000000e+000,,,,,,,,,,,,,,32,1,4.000000e+000,6.580353e-003,0.000000e+000,0,,0,
1524054525.338,,0.000000e+000,5.499642e+001,2.576594e-006,0.000000e+000,3,7.700858e-001,0.000000e+000,,,,,,,,,,,,,,32,1,4.000000e+000,3.940582e-003,0.000000e+000,0,,0,
1524054562.808,,0.000000e+000,5.500103e+001,2.460010e-006,0.000000e+000,3,7.389258e-001,0.000000e+000,,,,,,,,,,,,,,32,1,4.000000e+000,7.888794e-003,0.000000e+000,0,,0,
1524054601.458,,0.000000e+000,5.500103e+001,2.400034e-006,0.000000e+000,3,7.549961e-001,0.000000e+000,,,,,,,,,,,,,,32,1,4.000000e+000,5.279541e-003,0.000000e+000,0,,0,
1524054639.448,,0.000000e+000,5.499905e+001,2.429392e-006,0.000000e+000,3,7.624897e-001,0.000000e+000,,,,,,,,,,,,,,32,1,4.000000e+000,3.948212e-003,0.000000e+000,0,,0,
1524054677.318,,0.000000e+000,5.499972e+001,2.467872e-006,0.000000e+000,3,7.491144e-001,0.000000e+000,,,,,,,,,,,,,,32,1,4.000000e+000,5.268097e-003,0.000000e+000,0,,0,
1524054715.278,,0.000000e+000,5.500169e+001,2.429531e-006,0.000000e+000,3,7.507190e-001,0.000000e+000,,,,,,,,,,,,,,32,1,4.000000e+000,3.959656e-003,0.000000e+000,0,,0,
1524054752.938,,0.000000e+000,5.499840e+001,2.382348e-006,0.000000e+000,3,7.354237e-001,0.000000e+000,,,,,,,,,,,,,,32,1,4.000000e+000,5.260468e-003,0.000000e+000,0,,0,
1524054790.918,,0.000000e+000,5.499773e+001,2.187795e-006,0.000000e+000,3,7.636598e-001,0.000000e+000,,,,,,,,,,,,,,32,1,4.000000e+000,1.308441e-003,0.000000e+000,0,,0,
1524054828.618,,0.000000e+000,5.500103e+001,2.274267e-006,0.000000e+000,3,7.588819e-001,0.000000e+000,,,,,,,,,,,,,,32,1,4.000000e+000,5.279541e-003,0.000000e+000,0,,0,
1524054865.919,,0.000000e+000,5.499709e+001,2.348745e-006,0.000000e+000,3,7.681469e-001,0.000000e+000,,,,,,,,,,,,,,32,1,4.000000e+000,7.888794e-003,0.000000e+000,0,,0,
1524054903.759,,0.000000e+000,5.500629e+001,2.535772e-006,0.000000e+000,3,7.946074e-001,0.000000e+000,,,,,,,,,,,,,,32,1,4.000000e+000,2.639771e-003,0.000000e+000,0,,0,
1524054942.009,,0.000000e+000,5.499445e+001,2.357509e-006,0.000000e+000,3,7.783739e-001,0.000000e+000,,,,,,,,,,,,,,32,1,4.000000e+000,2.628326e-003,0.000000e+000,0,,0,
1524054979.439,,0.000000e+000,5.499708e+001,2.478584e-006,0.000000e+000,3,7.714347e-001,0.000000e+000,,,,,,,,,,,,,,32,1,4.000000e+000,5.260468e-003,0.000000e+000,0,,0,
1524055016.129,,0.000000e+000,5.499840e+001,2.562112e-006,0.000000e+000,3,7.628280e-001,0.000000e+000,,,,,,,,,,,,,,32,1,4.000000e+000,2.628326e-003,0.000000e+000,0,,0,
1524055053.899,,0.000000e+000,5.500432e+001,2.516395e-006,0.000000e+000,3,7.728552e-001,0.000000e+000,,,,,,,,,,,,,,32,1,4.000000e+000,3.940582e-003,0.000000e+000,0,,0,
1524055090.999,,0.000000e+000,5.499708e+001,2.597315e-006,0.000000e+000,3,7.705135e-001,0.000000e+000,,,,,,,,,,,,,,32,1,4.000000e+000,2.620697e-003,0.000000e+000,0,,0,
1524055129.009,,0.000000e+000,5.500103e+001,2.569751e-006,0.000000e+000,3,7.779090e-001,0.000000e+000,,,,,,,,,,,,,,32,1,4.000000e+000,2.639771e-003,0.000000e+000,0,,0,
1524055166.019,,0.000000e+000,5.499643e+001,2.559481e-006,0.000000e+000,3,7.649888e-001,0.000000e+000,,,,,,,,,,,,,,32,1,4.000000e+000,1.448059e-002,0.000000e+000,0,,0,
1524055203.859,,0.000000e+000,5.500168e+001,2.485794e-006,0.000000e+000,3,8.034230e-001,0.000000e+000,,,,,,,,,,,,,,32,1,4.000000e+000,6.580353e-003,0.000000e+000,0,,0,
1524055241.589,,0.000000e+000,5.499775e+001,2.559015e-006,0.000000e+000,3,7.856770e-001,0.000000e+000,,,,,,,,,,,,,,32,1,4.000000e+000,9.208679e-003,0.000000e+000,0,,0,
1524055279.289,,0.000000e+000,5.500103e+001,2.466662e-006,0.000000e+000,3,8.209965e-001,0.000000e+000,,,,,,,,,,,,,,32,1,4.000000e+000,5.279541e-003,0.000000e+000,0,,0,
1524055317.549,,0.000000e+000,5.499708e+001,2.590655e-006,0.000000e+000,3,7.933452e-001,0.000000e+000,,,,,,,,,,,,,,32,1,4.000000e+000,0.000000e+000,0.000000e+000,0,,0,
1524055355.769,,0.000000e+000,5.500365e+001,2.593876e-006,0.000000e+000,3,7.646432e-001,0.000000e+000,,,,,,,,,,,,,,32,1,4.000000e+000,1.052856e-002,0.000000e+000,0,,0,
1524055393.699,,0.000000e+000,5.499972e+001,2.530504e-006,0.000000e+000,3,8.028623e-001,0.000000e+000,,,,,,,,,,,,,,32,1,4.000000e+000,5.268097e-003,0.000000e+000,0,,0,
1524055431.249,,0.000000e+000,5.499773e+001,2.682658e-006,0.000000e+000,3,7.830565e-001,0.000000e+000,,,,,,,,,,,,,,32,1,4.000000e+000,1.308441e-003,0.000000e+000,0,,0,
1524055469.469,,0.000000e+000,5.499708e+001,2.567018e-006,0.000000e+000,3,7.905581e-001,0.000000e+000,,,,,,,,,,,,,,32,1,4.000000e+000,2.620697e-003,0.000000e+000,0,,0,
1524055507.669,,0.000000e+000,5.500037e+001,2.581996e-006,0.000000e+000,3,7.993680e-001,0.000000e+000,,,,,,,,,,,,,,32,1,4.000000e+000,1.319885e-003,0.000000e+000,0,,0,
1524055545.409,,0.000000e+000,5.499905e+001,2.678542e-006,0.000000e+000,3,7.752820e-001,0.000000e+000,,,,,,,,,,,,,,32,1,4.000000e+000,1.319885e-003,0.000000e+000,0,,0,
1524055582.600,,0.000000e+000,5.499709e+001,2.568599e-006,0.000000e+000,3,8.049423e-001,0.000000e+000,,,,,,,,,,,,,,32,1,4.000000e+000,1.052856e-002,0.000000e+000,0,,0,
1524055620.050,,0.000000e+000,5.499972e+001,2.685617e-006,0.000000e+000,3,8.041670e-001,0.000000e+000,,,,,,,,,,,,,,32,1,4.000000e+000,5.268097e-003,0.000000e+000,0,,0,
1524055657.290,,0.000000e+000,5.500563e+001,2.686030e-006,0.000000e+000,3,7.964116e-001,0.000000e+000,,,,,,,,,,,,,,32,1,4.000000e+000,1.319885e-003,0.000000e+000,0,,0,
1524055695.510,,0.000000e+000,5.499773e+001,2.577425e-006,0.000000e+000,3,8.224190e-001,0.000000e+000,,,,,,,,,,,,,,32,1,4.000000e+000,1.308441e-003,0.000000e+000,0,,0,
1524055733.270,,0.000000e+000,5.499643e+001,2.720455e-006,0.000000e+000,3,7.844929e-001,0.000000e+000,,,,,,,,,,,,,,32,1,4.000000e+000,9.208679e-003,0.000000e+000,0,,0,
1524055770.710,,0.000000e+000,5.499708e+001,2.715578e-006,0.000000e+000,3,8.391309e-001,0.000000e+000,,,,,,,,,,,,,,32,1,4.000000e+000,2.620697e-003,0.000000e+000,0,,0,
1524055808.320,,0.000000e+000,5.499445e+001,2.730774e-006,0.000000e+000,3,7.898753e-001,0.000000e+000,,,,,,,,,,,,,,32,1,4.000000e+000,2.628326e-003,0.000000e+000,0,,0,
1524055846.370,,0.000000e+000,5.499577e+001,2.632035e-006,0.000000e+000,3,7.957301e-001,0.000000e+000,,,,,,,,,,,,,,32,1,4.000000e+000,5.249023e-003,0.000000e+000,0,,0,
1524055883.460,,0.000000e+000,5.499773e+001,2.685450e-006,0.000000e+000,3,7.863581e-001,0.000000e+000,,,,,,,,,,,,,,32,1,4.000000e+000,1.308441e-003,0.000000e+000,0,,0,
1524055920.850,,0.000000e+000,5.499380e+001,2.674411e-006,0.000000e+000,3,8.123639e-001,0.000000e+000,,,,,,,,,,,,,,32,1,4.000000e+000,3.948212e-003,0.000000e+000,0,,0,
1524055958.510,,0.000000e+000,5.499971e+001,2.715583e-006,0.000000e+000,3,7.850127e-001,0.000000e+000,,,,,,,,,,,,,,32,1,4.000000e+000,1.052094e-002,0.000000e+000,0,,0,
1524055996.500,,0.000000e+000,5.499972e+001,2.549684e-006,0.000000e+000,3,7.877755e-001,0.000000e+000,,,,,,,,,,,,,,32,1,4.000000e+000,5.268097e-003,0.000000e+000,0,,0,
1524056033.690,,0.000000e+000,5.499511e+001,2.709754e-006,0.000000e+000,3,8.081298e-001,0.000000e+000,,,,,,,,,,,,,,32,1,4.000000e+000,6.568909e-003,0.000000e+000,0,,0,
1524056071.510,,0.000000e+000,5.499972e+001,2.550996e-006,0.000000e+000,3,8.022028e-001,0.000000e+000,,,,,,,,,,,,,,32,1,4.000000e+000,5.268097e-003,0.000000e+000,0,,0,
1524056110.070,,0.000000e+000,5.499577e+001,2.539448e-006,0.000000e+000,3,8.308222e-001,0.000000e+000,,,,,,,,,,,,,,32,1,4.000000e+000,7.888794e-003,0.000000e+000,0,,0,
1524056147.670,,0.000000e+000,5.500037e+001,2.721056e-006,0.000000e+000,3,8.320144e-001,0.000000e+000,,,,,,,,,,,,,,32,1,4.000000e+000,6.587982e-003,0.000000e+000,0,,0,
1524056185.820,,0.000000e+000,5.499971e+001,2.575644e-006,0.000000e+000,3,8.111045e-001,0.000000e+000,,,,,,,,,,,,,,32,1,4.000000e+000,0.000000e+000,0.000000e+000,0,,0,
1524056224.120,,0.000000e+000,5.500103e+001,2.603660e-006,0.000000e+000,3,8.159246e-001,0.000000e+000,,,,,,,,,,,,,,32,1,4.000000e+000,0.000000e+000,0.000000e+000,0,,0,
1524056261.280,,0.000000e+000,5.500103e+001,2.753762e-006,0.000000e+000,3,8.062425e-001,0.000000e+000,,,,,,,,,,,,,,32,1,4.000000e+000,7.888794e-003,0.000000e+000,0,,0,
1524056298.711,,0.000000e+000,5.499971e+001,2.644997e-006,0.000000e+000,3,8.069076e-001,0.000000e+000,,,,,,,,,,,,,,32,1,4.000000e+000,2.639771e-003,0.000000e+000,0,,0,
1524056336.701,,0.000000e+000,5.499971e+001,2.654667e-006,0.000000e+000,3,8.302181e-001,0.000000e+000,,,,,,,,,,,,,,32,1,4.000000e+000,2.639771e-003,0.000000e+000,0,,0,
1524056373.761,,0.000000e+000,5.499511e+001,2.790700e-006,0.000000e+000,3,8.422131e-001,0.000000e+000,,,,,,,,,,,,,,32,1,4.000000e+000,1.319885e-003,0.000000e+000,0,,0,
1524056411.981,,0.000000e+000,5.499708e+001,2.681029e-006,0.000000e+000,3,8.195888e-001,0.000000e+000,,,,,,,,,,,,,,32,1,4.000000e+000,0.000000e+000,0.000000e+000,0,,0,
1524056449.181,,0.000000e+000,5.499511e+001,2.814915e-006,0.000000e+000,3,8.190410e-001,0.000000e+000,,,,,,,,,,,,,,32,1,4.000000e+000,1.972198e-002,0.000000e+000,0,,0,
1524056487.111,,0.000000e+000,5.500497e+001,2.809448e-006,0.000000e+000,3,8.170602e-001,0.000000e+000,,,,,,,,,,,,,,32,1,4.000000e+000,0.000000e+000,0.000000e+000,0,,0,
1524056525.091,,0.000000e+000,5.499775e+001,2.736800e-006,0.000000e+000,3,8.289520e-001,0.000000e+000,,,,,,,,,,,,,,32,1,4.000000e+000,1.184845e-002,0.000000e+000,0,,0,
1524056563.131,,0.000000e+000,5.500037e+001,2.770323e-006,0.000000e+000,3,8.284419e-001,0.000000e+000,,,,,,,,,,,,,,32,1,4.000000e+000,3.959656e-003,0.000000e+000,0,,0,
1524056602.061,,0.000000e+000,5.499380e+001,2.818012e-006,0.000000e+000,3,8.114399e-001,0.000000e+000,,,,,,,,,,,,,,32,1,4.000000e+000,1.308441e-003,0.000000e+000,0,,0,
1524056639.541,,0.000000e+000,5.499905e+001,2.795131e-006,0.000000e+000,3,8.246230e-001,0.000000e+000,,,,,,,,,,,,,,32,1,4.000000e+000,3.948212e-003,0.000000e+000,0,,0,
1524056676.901,,0.000000e+000,5.499905e+001,2.841373e-006,0.000000e+000,3,8.126459e-001,0.000000e+000,,,,,,,,,,,,,,32,1,4.000000e+000,1.319885e-003,0.000000e+000,0,,0,
1524056714.421,,0.000000e+000,5.499840e+001,2.770954e-006,0.000000e+000,3,8.415806e-001,0.000000e+000,,,,,,,,,,,,,,32,1,4.000000e+000,2.628326e-003,0.000000e+000,0,,0,
1524056752.181,,0.000000e+000,5.499773e+001,2.864683e-006,0.000000e+000,3,8.263195e-001,0.000000e+000,,,,,,,,,,,,,,32,1,4.000000e+000,1.308441e-003,0.000000e+000,0,,0,
1524056790.291,,0.000000e+000,5.500169e+001,2.844114e-006,0.000000e+000,3,8.263551e-001,0.000000e+000,,,,,,,,,,,,,,32,1,4.000000e+000,9.208679e-003,0.000000e+000,0,,0,
1524056828.261,,0.000000e+000,5.499708e+001,2.781037e-006,0.000000e+000,3,8.256127e-001,0.000000e+000,,,,,,,,,,,,,,32,1,4.000000e+000,2.620697e-003,0.000000e+000,0,,0,
1524056865.841,,0.000000e+000,5.499905e+001,2.804172e-006,0.000000e+000,3,8.141336e-001,0.000000e+000,,,,,,,,,,,,,,32,1,4.000000e+000,1.319885e-003,0.000000e+000,0,,0,
1524056903.611,,0.000000e+000,5.499774e+001,2.761071e-006,0.000000e+000,3,8.513748e-001,0.000000e+000,,,,,,,,,,,,,,32,1,4.000000e+000,3.940582e-003,0.000000e+000,0,,0,
1524056941.001,,0.000000e+000,5.500037e+001,2.851920e-006,0.000000e+000,3,8.207422e-001,0.000000e+000,,,,,,,,,,,,,,32,1,4.000000e+000,9.201050e-003,0.000000e+000,0,,0,
1524056978.941,,0.000000e+000,5.500169e+001,2.803949e-006,0.000000e+000,3,8.479477e-001,0.000000e+000,,,,,,,,,,,,,,32,1,4.000000e+000,3.959656e-003,0.000000e+000,0,,0,
1524057016.812,,0.000000e+000,5.499840e+001,2.869845e-006,0.000000e+000,3,8.465363e-001,0.000000e+000,,,,,,,,,,,,,,32,1,4.000000e+000,2.628326e-003,0.000000e+000,0,,0,
1524057054.732,,0.000000e+000,5.500301e+001,2.776859e-006,0.000000e+000,3,8.283044e-001,0.000000e+000,,,,,,,,,,,,,,32,1,4.000000e+000,1.319885e-003,0.000000e+000,0,,0,
1524057092.772,,0.000000e+000,5.499774e+001,2.737908e-006,0.000000e+000,3,8.413828e-001,0.000000e+000,,,,,,,,,,,,,,32,1,4.000000e+000,3.940582e-003,0.000000e+000,0,,0,
1524057130.592,,0.000000e+000,5.499708e+001,2.859913e-006,0.000000e+000,3,8.097033e-001,0.000000e+000,,,,,,,,,,,,,,32,1,4.000000e+000,2.620697e-003,0.000000e+000,0,,0,
1524057168.152,,0.000000e+000,5.500103e+001,2.893971e-006,0.000000e+000,3,8.545303e-001,0.000000e+000,,,,,,,,,,,,,,32,1,4.000000e+000,2.639771e-003,0.000000e+000,0,,0,
1524057205.902,,0.000000e+000,5.500498e+001,2.866220e-006,0.000000e+000,3,8.433634e-001,0.000000e+000,,,,,,,,,,,,,,32,1,4.000000e+000,2.620697e-003,0.000000e+000,0,,0,
1524057244.782,,0.000000e+000,5.499972e+001,2.983901e-006,0.000000e+000,3,8.367059e-001,0.000000e+000,,,,,,,,,,,,,,32,1,4.000000e+000,1.314926e-002,0.000000e+000,0,,0,
1524057283.092,,0.000000e+000,5.500037e+001,2.906430e-006,0.000000e+000,3,8.350601e-001,0.000000e+000,,,,,,,,,,,,,,32,1,4.000000e+000,1.319885e-003,0.000000e+000,0,,0,
1524057320.472,,0.000000e+000,5.500695e+001,2.930158e-006,0.000000e+000,3,8.375437e-001,0.000000e+000,,,,,,,,,,,,,,32,1,4.000000e+000,6.568909e-003,0.000000e+000,0,,0,
1524057357.732,,0.000000e+000,5.499511e+001,2.891567e-006,0.000000e+000,3,8.309141e-001,0.000000e+000,,,,,,,,,,,,,,32,1,4.000000e+000,3.940582e-003,0.000000e+000,0,,0,
1524057395.632,,0.000000e+000,5.500103e+001,2.862399e-006,0.000000e+000,3,8.417756e-001,0.000000e+000,,,,,,,,,,,,,,32,1,4.000000e+000,5.279541e-003,0.000000e+000,0,,0,
1524057433.142,,0.000000e+000,5.499577e+001,2.895179e-006,0.000000e+000,3,8.406195e-001,0.000000e+000,,,,,,,,,,,,,,32,1,4.000000e+000,2.632141e-003,0.000000e+000,0,,0,
1524057471.332,,0.000000e+000,5.499840e+001,2.866116e-006,0.000000e+000,3,8.460932e-001,0.000000e+000,,,,,,,,,,,,,,32,1,4.000000e+000,5.260468e-003,0.000000e+000,0,,0,
1524057509.312,,0.000000e+000,5.500103e+001,2.931152e-006,0.000000e+000,3,8.293243e-001,0.000000e+000,,,,,,,,,,,,,,32,1,4.000000e+000,2.639771e-003,0.000000e+000,0,,0,
1524057547.202,,0.000000e+000,5.499380e+001,2.895883e-006,0.000000e+000,3,8.271913e-001,0.000000e+000,,,,,,,,,,,,,,32,1,4.000000e+000,3.948212e-003,0.000000e+000,0,,0,
1524057584.512,,0.000000e+000,5.499313e+001,2.986775e-006,0.000000e+000,3,8.327054e-001,0.000000e+000,,,,,,,,,,,,,,32,1,4.000000e+000,2.628326e-003,0.000000e+000,0,,0,
1524057622.262,,0.000000e+000,5.499643e+001,2.855419e-006,0.000000e+000,3,8.403938e-001,0.000000e+000,,,,,,,,,,,,,,32,1,4.000000e+000,1.312256e-003,0.000000e+000,0,,0,
1524057659.912,,0.000000e+000,5.499577e+001,2.960218e-006,0.000000e+000,3,8.488199e-001,0.000000e+000,,,,,,,,,,,,,,32,1,4.000000e+000,2.632141e-003,0.000000e+000,0,,0,
1524057697.312,,0.000000e+000,5.500168e+001,2.855275e-006,0.000000e+000,3,8.467199e-001,0.000000e+000,,,,,,,,,,,,,,32,1,4.000000e+000,6.580353e-003,0.000000e+000,0,,0,
1524057734.893,,0.000000e+000,5.500498e+001,2.916490e-006,0.000000e+000,3,8.338597e-001,0.000000e+000,,,,,,,,,,,,,,32,1,4.000000e+000,5.260468e-003,0.000000e+000,0,,0,
1524057772.803,,0.000000e+000,5.500103e+001,2.886837e-006,0.000000e+000,3,8.268566e-001,0.000000e+000,,,,,,,,,,,,,,32,1,4.000000e+000,7.888794e-003,0.000000e+000,0,,0,
1524057810.283,,0.000000e+000,5.500169e+001,2.851689e-006,0.000000e+000,3,8.563476e-001,0.000000e+000,,,,,,,,,,,,,,32,1,4.000000e+000,1.319885e-003,0.000000e+000,0,,0,
1524057847.833,,0.000000e+000,5.499774e+001,2.940397e-006,0.000000e+000,3,8.293411e-001,0.000000e+000,,,,,,,,,,,,,,32,1,4.000000e+000,3.940582e-003,0.000000e+000,0,,0,
1524057885.833,,0.000000e+000,5.499708e+001,2.794507e-006,0.000000e+000,3,8.398142e-001,0.000000e+000,,,,,,,,,,,,,,32,1,4.000000e+000,0.000000e+000,0.000000e+000,0,,0,
1524057923.243,,0.000000e+000,5.500432e+001,2.872945e-006,0.000000e+000,3,8.344883e-001,0.000000e+000,,,,,,,,,,,,,,32,1,4.000000e+000,6.580353e-003,0.000000e+000,0,,0,
1524057961.413,,0.000000e+000,5.500300e+001,2.850713e-006,0.000000e+000,3,8.414448e-001,0.000000e+000,,,,,,,,,,,,,,32,1,4.000000e+000,6.580353e-003,0.000000e+000,0,,0,
1524057999.543,,0.000000e+000,5.499906e+001,2.827807e-006,0.000000e+000,3,8.670843e-001,0.000000e+000,,,,,,,,,,,,,,32,1,4.000000e+000,6.580353e-003,0.000000e+000,0,,0,
1524058037.433,,0.000000e+000,5.499971e+001,2.878692e-006,0.000000e+000,3,8.340952e-001,0.000000e+000,,,,,,,,,,,,,,32,1,4.000000e+000,2.639771e-003,0.000000e+000,0,,0,
1524058074.803,,0.000000e+000,5.499840e+001,2.872031e-006,0.000000e+000,3,8.562515e-001,0.000000e+000,,,,,,,,,,,,,,32,1,4.000000e+000,2.628326e-003,0.000000e+000,0,,0,
1524058112.583,,0.000000e+000,5.499642e+001,2.922881e-006,0.000000e+000,3,8.326544e-001,0.000000e+000,,,,,,,,,,,,,,32,1,4.000000e+000,3.940582e-003,0.000000e+000,0,,0,
1524058149.893,,0.000000e+000,5.499774e+001,2.833678e-006,0.000000e+000,3,8.563110e-001,0.000000e+000,,,,,,,,,,,,,,32,1,4.000000e+000,6.580353e-003,0.000000e+000,0,,0,
1524058187.553,,0.000000e+000,5.500432e+001,2.912431e-006,0.000000e+000,3,8.351350e-001,0.000000e+000,,,,,,,,,,,,,,32,1,4.000000e+000,1.446915e-002,0.000000e+000,0,,0,
1524058225.323,,0.000000e+000,5.500103e+001,2.852976e-006,0.000000e+000,3,8.512475e-001,0.000000e+000,,,,,,,,,,,,,,32,1,4.000000e+000,0.000000e+000,0.000000e+000,0,,0,
1524058263.183,,0.000000e+000,5.500103e+001,2.889591e-006,0.000000e+000,3,8.384976e-001,0.000000e+000,,,,,,,,,,,,,,32,1,4.000000e+000,2.639771e-003,0.000000e+000,0,,0,
1524058301.293,,0.000000e+000,5.499313e+001,2.802338e-006,0.000000e+000,3,8.701603e-001,0.000000e+000,,,,,,,,,,,,,,32,1,4.000000e+000,7.892609e-003,0.000000e+000,0,,0,
1524058339.373,,0.000000e+000,5.499971e+001,2.871447e-006,0.000000e+000,3,8.577188e-001,0.000000e+000,,,,,,,,,,,,,,32,1,4.000000e+000,1.052094e-002,0.000000e+000,0,,0,
1524058377.183,,0.000000e+000,5.499905e+001,2.873206e-006,0.000000e+000,3,8.523796e-001,0.000000e+000,,,,,,,,,,,,,,32,1,4.000000e+000,1.319885e-003,0.000000e+000,0,,0,
1524058414.693,,0.000000e+000,5.500103e+001,2.832666e-006,0.000000e+000,3,8.684704e-001,0.000000e+000,,,,,,,,,,,,,,32,1,4.000000e+000,0.000000e+000,0.000000e+000,0,,0,
1524058451.714,,0.000000e+000,5.499906e+001,2.840317e-006,0.000000e+000,3,8.461267e-001,0.000000e+000,,,,,,,,,,,,,,32,1,4.000000e+000,6.580353e-003,0.000000e+000,0,,0,
1524058488.954,,0.000000e+000,5.500169e+001,2.941847e-006,0.000000e+000,3,8.410392e-001,0.000000e+000,,,,,,,,,,,,,,32,1,4.000000e+000,3.959656e-003,0.000000e+000,0,,0,
1524058526.374,,0.000000e+000,5.499972e+001,2.871804e-006,0.000000e+000,3,8.567862e-001,0.000000e+000,,,,,,,,,,,,,,32,1,4.000000e+000,5.268097e-003,0.000000e+000,0,,0,
1524058563.694,,0.000000e+000,5.500169e+001,3.004567e-006,0.000000e+000,3,8.372229e-001,0.000000e+000,,,,,,,,,,,,,,32,1,4.000000e+000,3.959656e-003,0.000000e+000,0,,0,
1524058601.494,,0.000000e+000,5.500037e+001,2.926716e-006,0.000000e+000,3,8.491364e-001,0.000000e+000,,,,,,,,,,,,,,32,1,4.000000e+000,6.587982e-003,0.000000e+000,0,,0,
1524058638.604,,0.000000e+000,5.500037e+001,2.978773e-006,0.000000e+000,3,8.436959e-001,0.000000e+000,,,,,,,,,,,,,,32,1,4.000000e+000,1.319885e-003,0.000000e+000,0,,0,
1524058676.884,,0.000000e+000,5.499840e+001,2.938943e-006,0.000000e+000,3,8.678303e-001,0.000000e+000,,,,,,,,,,,,,,32,1,4.000000e+000,2.628326e-003,0.000000e+000,0,,0,
1524058714.664,,0.000000e+000,5.499839e+001,2.901343e-006,0.000000e+000,3,8.663931e-001,0.000000e+000,,,,,,,,,,,,,,32,1,4.000000e+000,0.000000e+000,0.000000e+000,0,,0,
1524058752.584,,0.000000e+000,5.500037e+001,3.026814e-006,0.000000e+000,3,8.408706e-001,0.000000e+000,,,,,,,,,,,,,,32,1,4.000000e+000,1.184082e-002,0.000000e+000,0,,0,
1524058791.124,,0.000000e+000,5.499840e+001,2.984226e-006,0.000000e+000,3,8.576536e-001,0.000000e+000,,,,,,,,,,,,,,32,1,4.000000e+000,2.628326e-003,0.000000e+000,0,,0,
1524058829.614,,0.000000e+000,5.499380e+001,2.897491e-006,0.000000e+000,3,8.657774e-001,0.000000e+000,,,,,,,,,,,,,,32,1,4.000000e+000,1.446915e-002,0.000000e+000,0,,0,
1524058866.844,,0.000000e+000,5.499643e+001,3.034181e-006,0.000000e+000,3,8.644341e-001,0.000000e+000,,,,,,,,,,,,,,32,1,4.000000e+000,1.312256e-003,0.000000e+000,0,,0,
1524058905.544,,0.000000e+000,5.500037e+001,3.070952e-006,0.000000e+000,3,8.503702e-001,0.000000e+000,,,,,,,,,,,,,,32,1,4.000000e+000,9.201050e-003,0.000000e+000,0,,0,
1524058943.414,,0.000000e+000,5.499972e+001,3.124785e-006,0.000000e+000,3,8.615589e-001,0.000000e+000,,,,,,,,,,,,,,32,1,4.000000e+000,7.900238e-003,0.000000e+000,0,,0,
1524058981.114,,0.000000e+000,5.500563e+001,3.187305e-006,0.000000e+000,3,8.413438e-001,0.000000e+000,,,,,,,,,,,,,,32,1,4.000000e+000,1.448059e-002,0.000000e+000,0,,0,
1524059019.054,,0.000000e+000,5.500300e+001,3.062944e-006,0.000000e+000,3,8.589400e-001,0.000000e+000,,,,,,,,,,,,,,32,1,4.000000e+000,3.940582e-003,0.000000e+000,0,,0,
1524059056.704,,0.000000e+000,5.499841e+001,3.189876e-006,0.000000e+000,3,8.515595e-001,0.000000e+000,,,,,,,,,,,,,,32,1,4.000000e+000,1.052856e-002,0.000000e+000,0,,0,
1524059094.374,,0.000000e+000,5.500103e+001,3.105146e-006,0.000000e+000,3,8.785182e-001,0.000000e+000,,,,,,,,,,,,,,32,1,4.000000e+000,7.888794e-003,0.000000e+000,0,,0,
1524059132.614,,0.000000e+000,5.499775e+001,3.068427e-006,0.000000e+000,3,8.791049e-001,0.000000e+000,,,,,,,,,,,,,,32,1,4.000000e+000,1.184845e-002,0.000000e+000,0,,0,
1524059170.375,,0.000000e+000,5.499839e+001,3.138805e-006,0.000000e+000,3,8.475242e-001,0.000000e+000,,,,,,,,,,,,,,32,1,4.000000e+000,0.000000e+000,0.000000e+000,0,,0,
1524059221.255,,0.000000e+000,5.500234e+001,3.120023e-006,0.000000e+000,3,8.710209e-001,0.000000e+000,,,,,,,,,,,,,,32,1,4.000000e+000,5.260468e-003,0.000000e+000,0,,0,
1524059258.425,,0.000000e+000,5.498853e+001,3.135280e-006,0.000000e+000,3,8.483600e-001,0.000000e+000,,,,,,,,,,,,,,32,1,4.000000e+000,3.948212e-003,0.000000e+000,0,,0,
1524059308.825,,0.000000e+000,5.500366e+001,3.193166e-006,0.000000e+000,3,8.456103e-001,0.000000e+000,,,,,,,,,,,,,,32,1,4.000000e+000,2.620697e-003,0.000000e+000,0,,0,
1524059346.065,,0.000000e+000,5.499971e+001,3.147523e-006,0.000000e+000,3,8.613387e-001,0.000000e+000,,,,,,,,,,,,,,32,1,4.000000e+000,2.639771e-003,0.000000e+000,0,,0,
1524059420.755,,0.000000e+000,5.499774e+001,3.108774e-006,0.000000e+000,3,8.624412e-001,0.000000e+000,,,,,,,,,,,,,,32,1,4.000000e+000,6.580353e-003,0.000000e+000,0,,0,
1524059458.565,,0.000000e+000,5.500169e+001,3.138429e-006,0.000000e+000,3,8.724138e-001,0.000000e+000,,,,,,,,,,,,,,32,1,4.000000e+000,1.184082e-002,0.000000e+000,0,,0,
1524059495.935,,0.000000e+000,5.499972e+001,3.152488e-006,0.000000e+000,3,8.812234e-001,0.000000e+000,,,,,,,,,,,,,,32,1,4.000000e+000,5.268097e-003,0.000000e+000,0,,0,
1524059533.725,,0.000000e+000,5.499971e+001,3.139768e-006,0.000000e+000,3,8.673816e-001,0.000000e+000,,,,,,,,,,,,,,32,1,4.000000e+000,2.639771e-003,0.000000e+000,0,,0,
1524059571.875,,0.000000e+000,5.499773e+001,3.200551e-006,0.000000e+000,3,8.478174e-001,0.000000e+000,,,,,,,,,,,,,,32,1,4.000000e+000,1.308441e-003,0.000000e+000,0,,0,
1524059609.795,,0.000000e+000,5.500366e+001,3.071808e-006,0.000000e+000,3,8.533987e-001,0.000000e+000,,,,,,,,,,,,,,32,1,4.000000e+000,5.260468e-003,0.000000e+000,0,,0,
1524059647.385,,0.000000e+000,5.500103e+001,3.164866e-006,0.000000e+000,3,8.431497e-001,0.000000e+000,,,,,,,,,,,,,,32,1,4.000000e+000,5.279541e-003,0.000000e+000,0,,0,
1524059685.425,,0.000000e+000,5.499905e+001,3.159951e-006,0.000000e+000,3,8.656341e-001,0.000000e+000,,,,,,,,,,,,,,32,1,4.000000e+000,1.319885e-003,0.000000e+000,0,,0,
1524059723.075,,0.000000e+000,5.500366e+001,3.184694e-006,0.000000e+000,3,8.575810e-001,0.000000e+000,,,,,,,,,,,,,,32,1,4.000000e+000,2.620697e-003,0.000000e+000,0,,0,
1524059798.625,,0.000000e+000,5.500037e+001,3.190320e-006,0.000000e+000,3,8.406662e-001,0.000000e+000,,,,,,,,,,,,,,32,1,4.000000e+000,1.446915e-002,0.000000e+000,0,,0,
1524059861.876,,0.000000e+000,5.500432e+001,3.127046e-006,0.000000e+000,3,8.618058e-001,0.000000e+000,,,,,,,,,,,,,,32,1,4.000000e+000,3.940582e-003,0.000000e+000,0,,0,
1524059899.466,,0.000000e+000,5.499182e+001,3.118997e-006,0.000000e+000,3,8.515925e-001,0.000000e+000,,,,,,,,,,,,,,32,1,4.000000e+000,1.314163e-002,0.000000e+000,0,,0,
1524059936.946,,0.000000e+000,5.499773e+001,3.170436e-006,0.000000e+000,3,8.745924e-001,0.000000e+000,,,,,,,,,,,,,,32,1,4.000000e+000,1.308441e-003,0.000000e+000,0,,0,
1524059974.576,,0.000000e+000,5.499577e+001,3.194810e-006,0.000000e+000,3,8.621599e-001,0.000000e+000,,,,,,,,,,,,,,32,1,4.000000e+000,7.888794e-003,0.000000e+000,0,,0,
1524060061.906,,0.000000e+000,5.500366e+001,3.105964e-006,0.000000e+000,3,8.725817e-001,0.000000e+000,,,,,,,,,,,,,,32,1,4.000000e+000,5.260468e-003,0.000000e+000,0,,0,
1524060125.026,,0.000000e+000,5.499380e+001,3.206709e-006,0.000000e+000,3,8.839939e-001,0.000000e+000,,,,,,,,,,,,,,32,1,4.000000e+000,6.572723e-003,0.000000e+000,0,,0,
1524060162.226,,0.000000e+000,5.499971e+001,3.139799e-006,0.000000e+000,3,8.794422e-001,0.000000e+000,,,,,,,,,,,,,,32,1,4.000000e+000,0.000000e+000,0.000000e+000,0,,0,
1524060199.336,,0.000000e+000,5.499971e+001,3.271682e-006,0.000000e+000,3,8.739861e-001,0.000000e+000,,,,,,,,,,,,,,32,1,4.000000e+000,2.639771e-003,0.000000e+000,0,,0,
1524060237.226,,0.000000e+000,5.499182e+001,3.180589e-006,0.000000e+000,3,8.601084e-001,0.000000e+000,,,,,,,,,,,,,,32,1,4.000000e+000,1.052094e-002,0.000000e+000,0,,0,
1524060276.146,,0.000000e+000,5.499511e+001,3.256539e-006,0.000000e+000,3,8.735703e-001,0.000000e+000,,,,,,,,,,,,,,32,1,4.000000e+000,3.940582e-003,0.000000e+000,0,,0,
1524060313.826,,0.000000e+000,5.500432e+001,3.258875e-006,0.000000e+000,3,8.537534e-001,0.000000e+000,,,,,,,,,,,,,,32,1,4.000000e+000,3.940582e-003,0.000000e+000,0,,0,
1524060351.786,,0.000000e+000,5.499708e+001,3.259775e-006,0.000000e+000,3,8.757285e-001,0.000000e+000,,,,,,,,,,,,,,32,1,4.000000e+000,5.260468e-003,0.000000e+000,0,,0,
1524060389.446,,0.000000e+000,5.500431e+001,3.269083e-006,0.000000e+000,3,8.547924e-001,0.000000e+000,,,,,,,,,,,,,,32,1,4.000000e+000,9.208679e-003,0.000000e+000,0,,0,
1524060427.456,,0.000000e+000,5.499511e+001,3.208232e-006,0.000000e+000,3,8.731406e-001,0.000000e+000,,,,,,,,,,,,,,32,1,4.000000e+000,9.201050e-003,0.000000e+000,0,,0,
1524060465.536,,0.000000e+000,5.499642e+001,3.127740e-006,0.000000e+000,3,8.855685e-001,0.000000e+000,,,,,,,,,,,,,,32,1,4.000000e+000,3.940582e-003,0.000000e+000,0,,0,
1524060503.486,,0.000000e+000,5.499971e+001,3.235795e-006,0.000000e+000,3,8.614357e-001,0.000000e+000,,,,,,,,,,,,,,32,1,4.000000e+000,2.639771e-003,0.000000e+000,0,,0,
1524060541.396,,0.000000e+000,5.500235e+001,3.239632e-006,0.000000e+000,3,8.829956e-001,0.000000e+000,,,,,,,,,,,,,,32,1,4.000000e+000,0.000000e+000,0.000000e+000,0,,0,
1524060578.297,,0.000000e+000,5.499773e+001,3.258298e-006,0.000000e+000,3,8.650345e-001,0.000000e+000,,,,,,,,,,,,,,32,1,4.000000e+000,1.308441e-003,0.000000e+000,0,,0,
1524060615.347,,0.000000e+000,5.500301e+001,3.204143e-006,0.000000e+000,3,8.752701e-001,0.000000e+000,,,,,,,,,,,,,,32,1,4.000000e+000,1.319885e-003,0.000000e+000,0,,0,
1524060690.367,,0.000000e+000,5.500103e+001,3.187226e-006,0.000000e+000,3,8.881617e-001,0.000000e+000,,,,,,,,,,,,,,32,1,4.000000e+000,5.279541e-003,0.000000e+000,0,,0,
1524060728.527,,0.000000e+000,5.499905e+001,3.297804e-006,0.000000e+000,3,8.817777e-001,0.000000e+000,,,,,,,,,,,,,,32,1,4.000000e+000,1.319885e-003,0.000000e+000,0,,0,
1524060766.227,,0.000000e+000,5.499051e+001,3.202193e-006,0.000000e+000,3,8.604268e-001,0.000000e+000,,,,,,,,,,,,,,32,1,4.000000e+000,2.632141e-003,0.000000e+000,0,,0,
1524060804.497,,0.000000e+000,5.500103e+001,3.159969e-006,0.000000e+000,3,8.704983e-001,0.000000e+000,,,,,,,,,,,,,,32,1,4.000000e+000,0.000000e+000,0.000000e+000,0,,0,
1524060866.397,,0.000000e+000,5.500234e+001,3.134195e-006,0.000000e+000,3,8.566826e-001,0.000000e+000,,,,,,,,,,,,,,32,1,4.000000e+000,7.900238e-003,0.000000e+000,0,,0,
1524060903.877,,0.000000e+000,5.500629e+001,3.299401e-006,0.000000e+000,3,8.627197e-001,0.000000e+000,,,,,,,,,,,,,,32,1,4.000000e+000,1.316071e-002,0.000000e+000,0,,0,
1524060942.127,,0.000000e+000,5.499248e+001,3.188465e-006,0.000000e+000,3,8.730060e-001,0.000000e+000,,,,,,,,,,,,,,32,1,4.000000e+000,1.182938e-002,0.000000e+000,0,,0,
1524060980.507,,0.000000e+000,5.499839e+001,3.116100e-006,0.000000e+000,3,8.874831e-001,0.000000e+000,,,,,,,,,,,,,,32,1,4.000000e+000,0.000000e+000,0.000000e+000,0,,0,
1524061018.767,,0.000000e+000,5.499905e+001,3.090366e-006,0.000000e+000,3,8.847576e-001,0.000000e+000,,,,,,,,,,,,,,32,1,4.000000e+000,1.182938e-002,0.000000e+000,0,,0,
1524061056.357,,0.000000e+000,5.499774e+001,3.213140e-006,0.000000e+000,3,8.654197e-001,0.000000e+000,,,,,,,,,,,,,,32,1,4.000000e+000,6.580353e-003,0.000000e+000,0,,0,
1524061143.637,,0.000000e+000,5.500169e+001,3.175381e-006,0.000000e+000,3,8.851084e-001,0.000000e+000,,,,,,,,,,,,,,32,1,4.000000e+000,9.208679e-003,0.000000e+000,0,,0,
1524061206.517,,0.000000e+000,5.500037e+001,3.260280e-006,0.000000e+000,3,8.668937e-001,0.000000e+000,,,,,,,,,,,,,,32,1,4.000000e+000,1.319885e-003,0.000000e+000,0,,0,
1524061243.927,,0.000000e+000,5.499840e+001,3.233953e-006,0.000000e+000,3,8.918716e-001,0.000000e+000,,,,,,,,,,,,,,32,1,4.000000e+000,7.900238e-003,0.000000e+000,0,,0,
1524061281.507,,0.000000e+000,5.500169e+001,3.181691e-006,0.000000e+000,3,8.576813e-001,0.000000e+000,,,,,,,,,,,,,,32,1,4.000000e+000,1.709747e-002,0.000000e+000,0,,0,
1524061319.348,,0.000000e+000,5.499971e+001,3.201073e-006,0.000000e+000,3,8.961182e-001,0.000000e+000,,,,,,,,,,,,,,32,1,4.000000e+000,2.639771e-003,0.000000e+000,0,,0,
1524061356.708,,0.000000e+000,5.499840e+001,3.277028e-006,0.000000e+000,3,8.679911e-001,0.000000e+000,,,,,,,,,,,,,,32,1,4.000000e+000,2.628326e-003,0.000000e+000,0,,0,
1524061394.608,,0.000000e+000,5.499971e+001,3.298563e-006,0.000000e+000,3,9.016650e-001,0.000000e+000,,,,,,,,,,,,,,32,1,4.000000e+000,0.000000e+000,0.000000e+000,0,,0,
1524061432.948,,0.000000e+000,5.499708e+001,3.186760e-006,0.000000e+000,3,8.861284e-001,0.000000e+000,,,,,,,,,,,,,,32,1,4.000000e+000,2.620697e-003,0.000000e+000,0,,0,
1524061471.686,,0.000000e+000,5.500235e+001,3.250394e-006,0.000000e+000,3,8.850772e-001,0.000000e+000,,,,,,,,,,,,,,32,1,4.000000e+000,2.639771e-003,0.000000e+000,0,,0,