File: Input_All/TC04-12-01K_TRMac_58K_0.16Kmin_VRMde_55K.dc.dat
[Header]
TITLE,MPMS DC Measurement
BYAPP,MPMS Measurement,2.1,Summary
FILEOPENTIME, 1524659957.370000 4/25/2018, 6:39:17 AM

INFO, APPNAME, MPMS MultiVu Application, Revision 1.61,  Build 082

INFO, NAME, TC04-12-01K
INFO, WEIGHT, 1.000
INFO, AREA, 1.000
INFO, LENGTH, 1.000
INFO, SHAPE, 0
INFO, COMMENT,
INFO, SEQUENCE FILE: TRMac_58K_0.16Kmin_VRMde_55K.seq


INFO, BACKGROUND DATA FILE:, None


STARTUPAXIS,X,4,LINEAR,AUTO,0.000000,0.000000
STARTUPAXIS,Y1,5,LINEAR,AUTO,0.000000,0.000000


STARTUPGROUP,Longitudinal
FIELDGROUP,Longitudinal,1,2,3,4,5,6,7,8,9,15,16,17,18,27,28
FIELDGROUP,Transverse,1,2,3,4,10,11,12,13,14,19,20,21,22,27,28

PLOT_APPEARANCE,ALL,HORZ_GRID_ON,VERT_GRID_ON,MARKERS_AND_LINES

[Data]
Time,Comment,Field (Oe),Temperature (K),Long Moment (emu),Long Scan Std Dev,Long Algorithm,Long Reg Fit,Long Percent Error (%),Trans Moment (emu),Trans Scan Std Dev,Trans Algorithm,Trans Reg Fit,Trans Percent Error (%),Long Moment [w/o ABS] (emu),Long Scan Std Dev [w/o ABS],Long Reg Fit [w/o ABS],Long Percent Error [w/o ABS] (%),Trans Moment [w/o ABS] (emu),Trans Scan Std Dev [w/o ABS],Trans Reg Fit [w/o ABS],Trans Percent Error [w/o ABS] (%),Points per Scan,Scans per Measurement,Scan Length (cm),Delta Temp (K),Rot Position (deg),Error,EC Comp. Running,Using ABS,
1524659957.370,,0.000000e+000,5.499182e+001,1.007399e-005,0.000000e+000,3,7.998458e-001,0.000000e+000,,,,,,,,,,,,,,32,1,4.000000e+000,0.000000e+000,0.000000e+000,0,,0,
1524659983.120,,0.000000e+000,5.499906e+001,8.491489e-006,0.000000e+000,3,7.958435e-001,0.000000e+000,,,,,,,,,,,,,,32,1,4.000000e+000,6.580353e-003,0.000000e+000,0,,0,
1524660007.920,,0.000000e+000,5.499577e+001,7.604008e-006,0.000000e+000,3,7.766622e-001,0.000000e+000,,,,,,,,,,,,,,32,1,4.000000e+000,1.316071e-002,0.000000e+000,0,,0,
1524660033.130,,0.000000e+000,5.499248e+001,6.923547e-006,0.000000e+000,3,7.665113e-001,0.000000e+000,,,,,,,,,,,,,,32,1,4.000000e+000,1.319885e-003,0.000000e+000,0,,0,
1524660058.380,,0.000000e+000,5.500103e+001,6.395616e-006,0.000000e+000,3,7.754575e-001,0.000000e+000,,,,,,,,,,,,,,32,1,4.000000e+000,1.052094e-002,0.000000e+000,0,,0,
1524660083.590,,0.000000e+000,5.498985e+001,6.020541e-006,0.000000e+000,3,7.586876e-001,0.000000e+000,,,,,,,,,,,,,,32,1,4.000000e+000,3.940582e-003,0.000000e+000,0,,0,
1524660108.800,,0.000000e+000,5.499773e+001,5.671516e-006,0.000000e+000,3,7.569811e-001,0.000000e+000,,,,,,,,,,,,,,32,1,4.000000e+000,1.308441e-003,0.000000e+000,0,,0,
1524660134.050,,0.000000e+000,5.499642e+001,5.399118e-006,0.000000e+000,3,7.575044e-001,0.000000e+000,,,,,,,,,,,,,,32,1,4.000000e+000,3.940582e-003,0.000000e+000,0,,0,
1524660159.240,,0.000000e+000,5.500103e+001,5.179942e-006,0.000000e+000,3,7.532024e-001,0.000000e+000,,,,,,,,,,,,,,32,1,4.000000e+000,2.639771e-003,0.000000e+000,0,,0,
1524660184.480,,0.000000e+000,5.500169e+001,5.001698e-006,0.000000e+000,3,7.595566e-001,0.000000e+000,,,,,,,,,,,,,,32,1,4.000000e+000,9.208679e-003,0.000000e+000,0,,0,
1524660209.690,,0.000000e+000,5.500037e+001,4.864701e-006,0.000000e+000,3,7.566090e-001,0.000000e+000,,,,,,,,,,,,,,32,1,4.000000e+000,3.959656e-003,0.000000e+000,0,,0,
1524660234.940,,0.000000e+000,5.500169e+001,4.636623e-006,0.000000e+000,3,7.510230e-001,0.000000e+000,,,,,,,,,,,,,,32,1,4.000000e+000,1.319885e-003,0.000000e+000,0,,0,
1524660260.171,,0.000000e+000,5.500235e+001,4.453997e-006,0.000000e+000,3,7.523018e-001,0.000000e+000,,,,,,,,,,,,,,32,1,4.000000e+000,0.000000e+000,0.000000e+000,0,,0,
1524660285.401,,0.000000e+000,5.499906e+001,4.344652e-006,0.000000e+000,3,7.494749e-001,0.000000e+000,,,,,,,,,,,,,,32,1,4.000000e+000,6.580353e-003,0.000000e+000,0,,0,
1524660310.591,,0.000000e+000,5.499972e+001,4.198671e-006,0.000000e+000,3,7.413507e-001,0.000000e+000,,,,,,,,,,,,,,32,1,4.000000e+000,5.268097e-003,0.000000e+000,0,,0,
1524660335.821,,0.000000e+000,5.499313e+001,4.028147e-006,0.000000e+000,3,7.405541e-001,0.000000e+000,,,,,,,,,,,,,,32,1,4.000000e+000,7.892609e-003,0.000000e+000,0,,0,
1524660361.031,,0.000000e+000,5.499839e+001,3.921505e-006,0.000000e+000,3,7.407447e-001,0.000000e+000,,,,,,,,,,,,,,32,1,4.000000e+000,0.000000e+000,0.000000e+000,0,,0,
1524660386.271,,0.000000e+000,5.499642e+001,3.853791e-006,0.000000e+000,3,7.282035e-001,0.000000e+000,,,,,,,,,,,,,,32,1,4.000000e+000,3.940582e-003,0.000000e+000,0,,0,
1524660411.481,,0.000000e+000,5.499183e+001,3.692659e-006,0.000000e+000,3,7.268250e-001,0.000000e+000,,,,,,,,,,,,,,32,1,4.000000e+000,7.888794e-003,0.000000e+000,0,,0,
1524660436.831,,0.000000e+000,5.499839e+001,3.576007e-006,0.000000e+000,3,7.285426e-001,0.000000e+000,,,,,,,,,,,,,,32,1,4.000000e+000,0.000000e+000,0.000000e+000,0,,0,
1524660461.701,,0.000000e+000,5.499511e+001,3.441965e-006,0.000000e+000,3,7.301462e-001,0.000000e+000,,,,,,,,,,,,,,32,1,4.000000e+000,1.319885e-003,0.000000e+000,0,,0,
1524660487.661,,0.000000e+000,5.500234e+001,3.336648e-006,0.000000e+000,3,7.337733e-001,0.000000e+000,,,,,,,,,,,,,,32,1,4.000000e+000,7.900238e-003,0.000000e+000,0,,0,
1524660512.521,,0.000000e+000,5.499313e+001,3.270733e-006,0.000000e+000,3,7.221707e-001,0.000000e+000,,,,,,,,,,,,,,32,1,4.000000e+000,7.892609e-003,0.000000e+000,0,,0,
1524660537.871,,0.000000e+000,5.499643e+001,3.244939e-006,0.000000e+000,3,7.266635e-001,0.000000e+000,,,,,,,,,,,,,,32,1,4.000000e+000,6.568909e-003,0.000000e+000,0,,0,
1524660562.881,,0.000000e+000,5.500037e+001,3.186332e-006,0.000000e+000,3,7.357137e-001,0.000000e+000,,,,,,,,,,,,,,32,1,4.000000e+000,3.959656e-003,0.000000e+000,0,,0,
1524660587.761,,0.000000e+000,5.499642e+001,3.125746e-006,0.000000e+000,3,7.299328e-001,0.000000e+000,,,,,,,,,,,,,,32,1,4.000000e+000,3.940582e-003,0.000000e+000,0,,0,
1524660613.011,,0.000000e+000,5.499511e+001,3.086171e-006,0.000000e+000,3,7.341847e-001,0.000000e+000,,,,,,,,,,,,,,32,1,4.000000e+000,1.319885e-003,0.000000e+000,0,,0,
1524660638.451,,0.000000e+000,5.499577e+001,2.982566e-006,0.000000e+000,3,7.516943e-001,0.000000e+000,,,,,,,,,,,,,,32,1,4.000000e+000,0.000000e+000,0.000000e+000,0,,0,
1524660664.351,,0.000000e+000,5.500169e+001,2.906643e-006,0.000000e+000,3,6.879948e-001,0.000000e+000,,,,,,,,,,,,,,32,1,4.000000e+000,1.184082e-002,0.000000e+000,0,,0,
1524660689.451,,0.000000e+000,5.499577e+001,2.893978e-006,0.000000e+000,3,6.726419e-001,0.000000e+000,,,,,,,,,,,,,,32,1,4.000000e+000,5.249023e-003,0.000000e+000,0,,0,
1524660714.891,,0.000000e+000,5.499774e+001,2.760785e-006,0.000000e+000,3,6.885661e-001,0.000000e+000,,,,,,,,,,,,,,32,1,4.000000e+000,3.940582e-003,0.000000e+000,0,,0,
1524660740.151,,0.000000e+000,5.499248e+001,2.658483e-006,0.000000e+000,3,6.761659e-001,0.000000e+000,,,,,,,,,,,,,,32,1,4.000000e+000,3.940582e-003,0.000000e+000,0,,0,
1524660765.321,,0.000000e+000,5.499511e+001,2.623437e-006,0.000000e+000,3,6.821978e-001,0.000000e+000,,,,,,,,,,,,,,32,1,4.000000e+000,6.568909e-003,0.000000e+000,0,,0,
1524660790.381,,0.000000e+000,5.499314e+001,2.636912e-006,0.000000e+000,3,6.709699e-001,0.000000e+000,,,,,,,,,,,,,,32,1,4.000000e+000,0.000000e+000,0.000000e+000,0,,0,
1524660815.681,,0.000000e+000,5.499511e+001,2.602359e-006,0.000000e+000,3,6.776229e-001,0.000000e+000,,,,,,,,,,,,,,32,1,4.000000e+000,1.319885e-003,0.000000e+000,0,,0,
1524660840.841,,0.000000e+000,5.498985e+001,2.513446e-006,0.000000e+000,3,6.637425e-001,0.000000e+000,,,,,,,,,,,,,,32,1,4.000000e+000,9.201050e-003,0.000000e+000,0,,0,
1524660866.151,,0.000000e+000,5.499643e+001,2.508847e-006,0.000000e+000,3,6.698662e-001,0.000000e+000,,,,,,,,,,,,,,32,1,4.000000e+000,1.312256e-003,0.000000e+000,0,,0,
1524660891.271,,0.000000e+000,5.499117e+001,2.451580e-006,0.000000e+000,3,6.647246e-001,0.000000e+000,,,,,,,,,,,,,,32,1,4.000000e+000,1.312256e-003,0.000000e+000,0,,0,
1524660916.531,,0.000000e+000,5.500037e+001,2.432916e-006,0.000000e+000,3,6.651977e-001,0.000000e+000,,,,,,,,,,,,,,32,1,4.000000e+000,1.319885e-003,0.000000e+000,0,,0,
1524660941.771,,0.000000e+000,5.499709e+001,2.359481e-006,0.000000e+000,3,6.487213e-001,0.000000e+000,,,,,,,,,,,,,,32,1,4.000000e+000,7.888794e-003,0.000000e+000,0,,0,
1524660966.992,,0.000000e+000,5.499380e+001,2.381123e-006,0.000000e+000,3,6.491785e-001,0.000000e+000,,,,,,,,,,,,,,32,1,4.000000e+000,1.446915e-002,0.000000e+000,0,,0,
1524660992.162,,0.000000e+000,5.499905e+001,2.343726e-006,0.000000e+000,3,6.473952e-001,0.000000e+000,,,,,,,,,,,,,,32,1,4.000000e+000,1.319885e-003,0.000000e+000,0,,0,
1524661017.492,,0.000000e+000,5.499577e+001,2.351750e-006,0.000000e+000,3,6.478613e-001,0.000000e+000,,,,,,,,,,,,,,32,1,4.000000e+000,1.052094e-002,0.000000e+000,0,,0,
1524661042.682,,0.000000e+000,5.499708e+001,2.245085e-006,0.000000e+000,3,6.338778e-001,0.000000e+000,,,,,,,,,,,,,,32,1,4.000000e+000,0.000000e+000,0.000000e+000,0,,0,
1524661067.842,,0.000000e+000,5.500169e+001,2.242322e-006,0.000000e+000,3,6.328519e-001,0.000000e+000,,,,,,,,,,,,,,32,1,4.000000e+000,1.446915e-002,0.000000e+000,0,,0,
1524661093.062,,0.000000e+000,5.499314e+001,2.162984e-006,0.000000e+000,3,6.198052e-001,0.000000e+000,,,,,,,,,,,,,,32,1,4.000000e+000,0.000000e+000,0.000000e+000,0,,0,
1524661118.282,,0.000000e+000,5.499248e+001,2.131080e-006,0.000000e+000,3,6.118755e-001,0.000000e+000,,,,,,,,,,,,,,32,1,4.000000e+000,6.580353e-003,0.000000e+000,0,,0,
1524661143.482,,0.000000e+000,5.499906e+001,2.134822e-006,0.000000e+000,3,6.113702e-001,0.000000e+000,,,,,,,,,,,,,,32,1,4.000000e+000,6.580353e-003,0.000000e+000,0,,0,
1524661168.772,,0.000000e+000,5.498919e+001,2.096409e-006,0.000000e+000,3,6.173462e-001,0.000000e+000,,,,,,,,,,,,,,32,1,4.000000e+000,5.260468e-003,0.000000e+000,0,,0,
1524661194.242,,0.000000e+000,5.499117e+001,2.102729e-006,0.000000e+000,3,6.245908e-001,0.000000e+000,,,,,,,,,,,,,,32,1,4.000000e+000,6.568909e-003,0.000000e+000,0,,0,
1524661219.222,,0.000000e+000,5.499577e+001,2.109760e-006,0.000000e+000,3,6.168051e-001,0.000000e+000,,,,,,,,,,,,,,32,1,4.000000e+000,1.052094e-002,0.000000e+000,0,,0,
1524661244.402,,0.000000e+000,5.499774e+001,2.032849e-006,0.000000e+000,3,6.176603e-001,0.000000e+000,,,,,,,,,,,,,,32,1,4.000000e+000,3.940582e-003,0.000000e+000,0,,0,
1524661269.152,,0.000000e+000,5.499774e+001,1.966642e-006,0.000000e+000,3,5.657183e-001,0.000000e+000,,,,,,,,,,,,,,32,1,4.000000e+000,6.580353e-003,0.000000e+000,0,,0,
1524661294.282,,0.000000e+000,5.499905e+001,1.953276e-006,0.000000e+000,3,5.851982e-001,0.000000e+000,,,,,,,,,,,,,,32,1,4.000000e+000,1.319885e-003,0.000000e+000,0,,0,
1524661319.182,,0.000000e+000,5.499708e+001,1.929305e-006,0.000000e+000,3,5.966089e-001,0.000000e+000,,,,,,,,,,,,,,32,1,4.000000e+000,2.620697e-003,0.000000e+000,0,,0,
1524661344.612,,0.000000e+000,5.499775e+001,1.895510e-006,0.000000e+000,3,6.351004e-001,0.000000e+000,,,,,,,,,,,,,,32,1,4.000000e+000,1.184845e-002,0.000000e+000,0,,0,
1524661369.662,,0.000000e+000,5.499905e+001,1.880108e-006,0.000000e+000,3,6.000937e-001,0.000000e+000,,,,,,,,,,,,,,32,1,4.000000e+000,3.948212e-003,0.000000e+000,0,,0,
1524661394.902,,0.000000e+000,5.499972e+001,1.893306e-006,0.000000e+000,3,5.610164e-001,0.000000e+000,,,,,,,,,,,,,,32,1,4.000000e+000,7.900238e-003,0.000000e+000,0,,0,
1524661421.312,,0.000000e+000,5.499577e+001,1.884149e-006,0.000000e+000,3,5.556145e-001,0.000000e+000,,,,,,,,,,,,,,32,1,4.000000e+000,0.000000e+000,0.000000e+000,0,,0,
1524661446.472,,0.000000e+000,5.499774e+001,1.808383e-006,0.000000e+000,3,5.657563e-001,0.000000e+000,,,,,,,,,,,,,,32,1,4.000000e+000,3.940582e-003,0.000000e+000,0,,0,
1524661472.222,,0.000000e+000,5.499971e+001,1.790149e-006,0.000000e+000,3,6.045592e-001,0.000000e+000,,,,,,,,,,,,,,32,1,4.000000e+000,2.639771e-003,0.000000e+000,0,,0,
1524661497.132,,0.000000e+000,5.499905e+001,1.816373e-006,0.000000e+000,3,5.737005e-001,0.000000e+000,,,,,,,,,,,,,,32,1,4.000000e+000,1.319885e-003,0.000000e+000,0,,0,
1524661522.462,,0.000000e+000,5.499905e+001,1.798387e-006,0.000000e+000,3,5.999954e-001,0.000000e+000,,,,,,,,,,,,,,32,1,4.000000e+000,3.948212e-003,0.000000e+000,0,,0,
1524661547.112,,0.000000e+000,5.498853e+001,1.715139e-006,0.000000e+000,3,5.442581e-001,0.000000e+000,,,,,,,,,,,,,,32,1,4.000000e+000,6.572723e-003,0.000000e+000,0,,0,
1524661572.442,,0.000000e+000,5.500037e+001,1.799839e-006,0.000000e+000,3,5.956690e-001,0.000000e+000,,,,,,,,,,,,,,32,1,4.000000e+000,3.959656e-003,0.000000e+000,0,,0,
1524661597.702,,0.000000e+000,5.499511e+001,1.730550e-006,0.000000e+000,3,5.643030e-001,0.000000e+000,,,,,,,,,,,,,,32,1,4.000000e+000,1.319885e-003,0.000000e+000,0,,0,
1524661622.232,,0.000000e+000,5.500564e+001,1.723296e-006,0.000000e+000,3,5.170393e-001,0.000000e+000,,,,,,,,,,,,,,32,1,4.000000e+000,3.940582e-003,0.000000e+000,0,,0,
1524661647.032,,0.000000e+000,5.499577e+001,1.748651e-006,0.000000e+000,3,5.647404e-001,0.000000e+000,,,,,,,,,,,,,,32,1,4.000000e+000,5.249023e-003,0.000000e+000,0,,0,
1524661671.713,,0.000000e+000,5.499708e+001,1.703858e-006,0.000000e+000,3,6.137009e-001,0.000000e+000,,,,,,,,,,,,,,32,1,4.000000e+000,5.260468e-003,0.000000e+000,0,,0,
1524661696.363,,0.000000e+000,5.499708e+001,1.676649e-006,0.000000e+000,3,5.999681e-001,0.000000e+000,,,,,,,,,,,,,,32,1,4.000000e+000,0.000000e+000,0.000000e+000,0,,0,
1524661721.783,,0.000000e+000,5.500103e+001,1.731500e-006,0.000000e+000,3,5.273314e-001,0.000000e+000,,,,,,,,,,,,,,32,1,4.000000e+000,2.639771e-003,0.000000e+000,0,,0,
1524661746.783,,0.000000e+000,5.500234e+001,1.636152e-006,0.000000e+000,3,4.763780e-001,0.000000e+000,,,,,,,,,,,,,,32,1,4.000000e+000,5.260468e-003,0.000000e+000,0,,0,
1524661772.393,,0.000000e+000,5.499905e+001,1.603278e-006,0.000000e+000,3,4.801505e-001,0.000000e+000,,,,,,,,,,,,,,32,1,4.000000e+000,1.319885e-003,0.000000e+000,0,,0,
1524661797.543,,0.000000e+000,5.499643e+001,1.601155e-006,0.000000e+000,3,4.621730e-001,0.000000e+000,,,,,,,,,,,,,,32,1,4.000000e+000,1.312256e-003,0.000000e+000,0,,0,
1524661822.463,,0.000000e+000,5.499445e+001,1.646252e-006,0.000000e+000,3,4.786422e-001,0.000000e+000,,,,,,,,,,,,,,32,1,4.000000e+000,5.260468e-003,0.000000e+000,0,,0,
1524661847.533,,0.000000e+000,5.499642e+001,1.599437e-006,0.000000e+000,3,4.871809e-001,0.000000e+000,,,,,,,,,,,,,,32,1,4.000000e+000,3.940582e-003,0.000000e+000,0,,0,
1524661872.763,,0.000000e+000,5.499445e+001,1.379418e-006,0.000000e+000,3,3.994432e-001,0.000000e+000,,,,,,,,,,,,,,32,1,4.000000e+000,5.260468e-003,0.000000e+000,0,,0,
1524661897.933,,0.000000e+000,5.499905e+001,1.594433e-006,0.000000e+000,3,5.017859e-001,0.000000e+000,,,,,,,,,,,,,,32,1,4.000000e+000,1.182938e-002,0.000000e+000,0,,0,
1524661923.103,,0.000000e+000,5.499182e+001,1.568493e-006,0.000000e+000,3,4.689221e-001,0.000000e+000,,,,,,,,,,,,,,32,1,4.000000e+000,5.260468e-003,0.000000e+000,0,,0,
1524661948.373,,0.000000e+000,5.500366e+001,1.550179e-006,0.000000e+000,3,4.638559e-001,0.000000e+000,,,,,,,,,,,,,,32,1,4.000000e+000,5.260468e-003,0.000000e+000,0,,0,
1524661973.563,,0.000000e+000,5.499708e+001,1.540234e-006,0.000000e+000,3,4.817219e-001,0.000000e+000,,,,,,,,,,,,,,32,1,4.000000e+000,0.000000e+000,0.000000e+000,0,,0,
1524661998.803,,0.000000e+000,5.500234e+001,1.465036e-006,0.000000e+000,3,4.591198e-001,0.000000e+000,,,,,,,,,,,,,,32,1,4.000000e+000,5.260468e-003,0.000000e+000,0,,0,
1524662024.053,,0.000000e+000,5.499577e+001,1.458215e-006,0.000000e+000,3,4.832214e-001,0.000000e+000,,,,,,,,,,,,,,32,1,4.000000e+000,2.632141e-003,0.000000e+000,0,,0,
1524662049.273,,0.000000e+000,5.499708e+001,1.459156e-006,0.000000e+000,3,4.871162e-001,0.000000e+000,,,,,,,,,,,,,,32,1,4.000000e+000,1.578140e-002,0.000000e+000,0,,0,
1524662074.473,,0.000000e+000,5.500103e+001,1.469072e-006,0.000000e+000,3,5.186061e-001,0.000000e+000,,,,,,,,,,,,,,32,1,4.000000e+000,1.316071e-002,0.000000e+000,0,,0,
1524662099.713,,0.000000e+000,5.499643e+001,1.395428e-006,0.000000e+000,3,4.575467e-001,0.000000e+000,,,,,,,,,,,,,,32,1,4.000000e+000,1.312256e-003,0.000000e+000,0,,0,
1524662124.843,,0.000000e+000,5.499380e+001,1.521644e-006,0.000000e+000,3,4.737615e-001,0.000000e+000,,,,,,,,,,,,,,32,1,4.000000e+000,1.308441e-003,0.000000e+000,0,,0,
1524662150.113,,0.000000e+000,5.499905e+001,1.466468e-006,0.000000e+000,3,4.548417e-001,0.000000e+000,,,,,,,,,,,,,,32,1,4.000000e+000,3.948212e-003,0.000000e+000,0,,0,
1524662175.453,,0.000000e+000,5.500103e+001,1.411266e-006,0.000000e+000,3,5.326892e-001,0.000000e+000,,,,,,,,,,,,,,32,1,4.000000e+000,0.000000e+000,0.000000e+000,0,,0,
1524662200.583,,0.000000e+000,5.499511e+001,1.491199e-006,0.000000e+000,3,4.751031e-001,0.000000e+000,,,,,,,,,,,,,,32,1,4.000000e+000,6.568909e-003,0.000000e+000,0,,0,
1524662225.803,,0.000000e+000,5.499840e+001,1.458511e-006,0.000000e+000,3,4.072925e-001,0.000000e+000,,,,,,,,,,,,,,32,1,4.000000e+000,1.314926e-002,0.000000e+000,0,,0,
1524662250.763,,0.000000e+000,5.499577e+001,1.320434e-006,0.000000e+000,3,3.862436e-001,0.000000e+000,,,,,,,,,,,,,,32,1,4.000000e+000,2.632141e-003,0.000000e+000,0,,0,
1524662275.493,,0.000000e+000,5.500037e+001,1.312801e-006,0.000000e+000,3,4.266833e-001,0.000000e+000,,,,,,,,,,,,,,32,1,4.000000e+000,9.201050e-003,0.000000e+000,0,,0,
1524662300.713,,0.000000e+000,5.499380e+001,1.426619e-006,0.000000e+000,3,4.292656e-001,0.000000e+000,,,,,,,,,,,,,,32,1,4.000000e+000,1.308441e-003,0.000000e+000,0,,0,
1524662325.933,,0.000000e+000,5.499445e+001,1.361670e-006,0.000000e+000,3,4.222351e-001,0.000000e+000,,,,,,,,,,,,,,32,1,4.000000e+000,5.260468e-003,0.000000e+000,0,,0,
1524662350.443,,0.000000e+000,5.499380e+001,1.378299e-006,0.000000e+000,3,4.680777e-001,0.000000e+000,,,,,,,,,,,,,,32,1,4.000000e+000,6.572723e-003,0.000000e+000,0,,0,
1524662375.533,,0.000000e+000,5.499774e+001,1.372234e-006,0.000000e+000,3,4.663891e-001,0.000000e+000,,,,,,,,,,,,,,32,1,4.000000e+000,6.580353e-003,0.000000e+000,0,,0,
1524662401.884,,0.000000e+000,5.499709e+001,1.532655e-006,0.000000e+000,3,5.116324e-001,0.000000e+000,,,,,,,,,,,,,,32,1,4.000000e+000,7.888794e-003,0.000000e+000,0,,0,
1524662427.164,,0.000000e+000,5.499972e+001,1.445937e-006,0.000000e+000,3,4.327894e-001,0.000000e+000,,,,,,,,,,,,,,32,1,4.000000e+000,5.268097e-003,0.000000e+000,0,,0,
1524662451.954,,0.000000e+000,5.500168e+001,1.392529e-006,0.000000e+000,3,4.123208e-001,0.000000e+000,,,,,,,,,,,,,,32,1,4.000000e+000,6.580353e-003,0.000000e+000,0,,0,
1524662476.994,,0.000000e+000,5.499314e+001,1.429056e-006,0.000000e+000,3,4.265794e-001,0.000000e+000,,,,,,,,,,,,,,32,1,4.000000e+000,0.000000e+000,0.000000e+000,0,,0,
1524662502.584,,0.000000e+000,5.499643e+001,1.323139e-006,0.000000e+000,3,3.379309e-001,0.000000e+000,,,,,,,,,,,,,,32,1,4.000000e+000,1.448059e-002,0.000000e+000,0,,0,
1524662527.474,,0.000000e+000,5.499773e+001,1.281904e-006,0.000000e+000,3,3.359922e-001,0.000000e+000,,,,,,,,,,,,,,32,1,4.000000e+000,1.308441e-003,0.000000e+000,0,,0,
1524662552.594,,0.000000e+000,5.499708e+001,1.454689e-006,0.000000e+000,3,4.610673e-001,0.000000e+000,,,,,,,,,,,,,,32,1,4.000000e+000,2.620697e-003,0.000000e+000,0,,0,
1524662577.654,,0.000000e+000,5.499971e+001,1.303368e-006,0.000000e+000,3,3.592446e-001,0.000000e+000,,,,,,,,,,,,,,32,1,4.000000e+000,2.639771e-003,0.000000e+000,0,,0,
1524662602.994,,0.000000e+000,5.500037e+001,1.360675e-006,0.000000e+000,3,3.986333e-001,0.000000e+000,,,,,,,,,,,,,,32,1,4.000000e+000,1.319885e-003,0.000000e+000,0,,0,
1524662628.824,,0.000000e+000,5.500037e+001,1.430013e-006,0.000000e+000,3,4.464657e-001,0.000000e+000,,,,,,,,,,,,,,32,1,4.000000e+000,6.587982e-003,0.000000e+000,0,,0,
1524662654.304,,0.000000e+000,5.499642e+001,1.392205e-006,0.000000e+000,3,4.308252e-001,0.000000e+000,,,,,,,,,,,,,,32,1,4.000000e+000,3.940582e-003,0.000000e+000,0,,0,
1524662679.134,,0.000000e+000,5.499775e+001,1.365166e-006,0.000000e+000,3,4.502213e-001,0.000000e+000,,,,,,,,,,,,,,32,1,4.000000e+000,1.184845e-002,0.000000e+000,0,,0,
1524662704.074,,0.000000e+000,5.500235e+001,1.281062e-006,0.000000e+000,3,3.355417e-001,0.000000e+000,,,,,,,,,,,,,,32,1,4.000000e+000,1.052856e-002,0.000000e+000,0,,0,
1524662729.294,,0.000000e+000,5.499577e+001,1.373180e-006,0.000000e+000,3,4.130103e-001,0.000000e+000,,,,,,,,,,,,,,32,1,4.000000e+000,7.888794e-003,0.000000e+000,0,,0,
1524662754.124,,0.000000e+000,5.500037e+001,1.340615e-006,0.000000e+000,3,4.572189e-001,0.000000e+000,,,,,,,,,,,,,,32,1,4.000000e+000,6.587982e-003,0.000000e+000,0,,0,
1524662779.404,,0.000000e+000,5.499774e+001,1.350617e-006,0.000000e+000,3,3.431414e-001,0.000000e+000,,,,,,,,,,,,,,32,1,4.000000e+000,3.940582e-003,0.000000e+000,0,,0,
1524662805.014,,0.000000e+000,5.499643e+001,1.337651e-006,0.000000e+000,3,3.624490e-001,0.000000e+000,,,,,,,,,,,,,,32,1,4.000000e+000,6.568909e-003,0.000000e+000,0,,0,
1524662830.574,,0.000000e+000,5.499773e+001,1.283460e-006,0.000000e+000,3,4.223911e-001,0.000000e+000,,,,,,,,,,,,,,32,1,4.000000e+000,1.308441e-003,0.000000e+000,0,,0,
1524662855.794,,0.000000e+000,5.499643e+001,1.248066e-006,0.000000e+000,3,3.065754e-001,0.000000e+000,,,,,,,,,,,,,,32,1,4.000000e+000,1.312256e-003,0.000000e+000,0,,0,
1524662881.034,,0.000000e+000,5.499643e+001,1.359299e-006,0.000000e+000,3,3.959018e-001,0.000000e+000,,,,,,,,,,,,,,32,1,4.000000e+000,6.568909e-003,0.000000e+000,0,,0,
1524662905.584,,0.000000e+000,5.499511e+001,1.336615e-006,0.000000e+000,3,3.529724e-001,0.000000e+000,,,,,,,,,,,,,,32,1,4.000000e+000,1.319885e-003,0.000000e+000,0,,0,
1524662931.004,,0.000000e+000,5.500037e+001,1.276842e-006,0.000000e+000,3,2.988902e-001,0.000000e+000,,,,,,,,,,,,,,32,1,4.000000e+000,3.959656e-003,0.000000e+000,0,,0,
1524662956.124,,0.000000e+000,5.499314e+001,1.259250e-006,0.000000e+000,3,3.589680e-001,0.000000e+000,,,,,,,,,,,,,,32,1,4.000000e+000,5.260468e-003,0.000000e+000,0,,0,
1524662981.334,,0.000000e+000,5.499643e+001,1.242101e-006,0.000000e+000,3,3.386534e-001,0.000000e+000,,,,,,,,,,,,,,32,1,4.000000e+000,1.312256e-003,0.000000e+000,0,,0,
1524663006.824,,0.000000e+000,5.499840e+001,1.182967e-006,0.000000e+000,3,3.366396e-001,0.000000e+000,,,,,,,,,,,,,,32,1,4.000000e+000,2.628326e-003,0.000000e+000,0,,0,
1524663032.654,,0.000000e+000,5.499511e+001,1.077103e-006,0.000000e+000,3,1.932594e-001,0.000000e+000,,,,,,,,,,,,,,32,1,4.000000e+000,1.184082e-002,0.000000e+000,0,,0,
1524663058.284,,0.000000e+000,5.499709e+001,1.305646e-006,0.000000e+000,3,3.758529e-001,0.000000e+000,,,,,,,,,,,,,,32,1,4.000000e+000,7.888794e-003,0.000000e+000,0,,0,
1524663082.954,,0.000000e+000,5.499773e+001,1.293537e-006,0.000000e+000,3,3.630566e-001,0.000000e+000,,,,,,,,,,,,,,32,1,4.000000e+000,1.308441e-003,0.000000e+000,0,,0,
1524663107.635,,0.000000e+000,5.499183e+001,1.263549e-006,0.000000e+000,3,3.167815e-001,0.000000e+000,,,,,,,,,,,,,,32,1,4.000000e+000,2.632141e-003,0.000000e+000,0,,0,
1524663132.885,,0.000000e+000,5.500169e+001,1.257026e-006,0.000000e+000,3,3.253958e-001,0.000000e+000,,,,,,,,,,,,,,32,1,4.000000e+000,1.319885e-003,0.000000e+000,0,,0,
1524663158.245,,0.000000e+000,5.500234e+001,1.293964e-006,0.000000e+000,3,2.858367e-001,0.000000e+000,,,,,,,,,,,,,,32,1,4.000000e+000,5.260468e-003,0.000000e+000,0,,0,
1524663183.705,,0.000000e+000,5.499445e+001,1.187846e-006,0.000000e+000,3,2.236417e-001,0.000000e+000,,,,,,,,,,,,,,32,1,4.000000e+000,5.260468e-003,0.000000e+000,0,,0,
1524663209.015,,0.000000e+000,5.499577e+001,1.140993e-006,0.000000e+000,3,2.332523e-001,0.000000e+000,,,,,,,,,,,,,,32,1,4.000000e+000,7.888794e-003,0.000000e+000,0,,0,
1524663234.065,,0.000000e+000,5.499773e+001,1.109644e-006,0.000000e+000,3,2.132108e-001,0.000000e+000,,,,,,,,,,,,,,32,1,4.000000e+000,1.308441e-003,0.000000e+000,0,,0,
1524663259.805,,0.000000e+000,5.499840e+001,1.196446e-006,0.000000e+000,3,2.690905e-001,0.000000e+000,,,,,,,,,,,,,,32,1,4.000000e+000,2.628326e-003,0.000000e+000,0,,0,
1524663284.675,,0.000000e+000,5.499511e+001,1.172374e-006,0.000000e+000,3,3.025408e-001,0.000000e+000,,,,,,,,,,,,,,32,1,4.000000e+000,1.319885e-003,0.000000e+000,0,,0,
1524663310.135,,0.000000e+000,5.499905e+001,1.180074e-006,0.000000e+000,3,2.880656e-001,0.000000e+000,,,,,,,,,,,,,,32,1,4.000000e+000,1.319885e-003,0.000000e+000,0,,0,
1524663335.515,,0.000000e+000,5.500037e+001,1.012805e-006,0.000000e+000,3,2.579652e-002,0.000000e+000,,,,,,,,,,,,,,32,1,4.000000e+000,6.587982e-003,0.000000e+000,0,,0,
1524663361.535,,0.000000e+000,5.499774e+001,1.176512e-006,0.000000e+000,3,2.699589e-001,0.000000e+000,,,,,,,,,,,,,,32,1,4.000000e+000,3.940582e-003,0.000000e+000,0,,0,
1524663386.725,,0.000000e+000,5.499840e+001,1.219081e-006,0.000000e+000,3,3.079637e-001,0.000000e+000,,,,,,,,,,,,,,32,1,4.000000e+000,7.900238e-003,0.000000e+000,0,,0,
1524663411.955,,0.000000e+000,5.499445e+001,1.186868e-006,0.000000e+000,3,3.172813e-001,0.000000e+000,,,,,,,,,,,,,,32,1,4.000000e+000,5.260468e-003,0.000000e+000,0,,0,
1524663437.185,,0.000000e+000,5.500037e+001,1.179441e-006,0.000000e+000,3,2.777140e-001,0.000000e+000,,,,,,,,,,,,,,32,1,4.000000e+000,6.587982e-003,0.000000e+000,0,,0,
1524663462.415,,0.000000e+000,5.500037e+001,1.118625e-006,0.000000e+000,3,2.220905e-001,0.000000e+000,,,,,,,,,,,,,,32,1,4.000000e+000,1.319885e-003,0.000000e+000,0,,0,
1524663487.635,,0.000000e+000,5.500103e+001,1.082590e-006,0.000000e+000,3,2.102921e-001,0.000000e+000,,,,,,,,,,,,,,32,1,4.000000e+000,5.279541e-003,0.000000e+000,0,,0,
1524663512.295,,0.000000e+000,5.499971e+001,1.089269e-006,0.000000e+000,3,3.104944e-001,0.000000e+000,,,,,,,,,,,,,,32,1,4.000000e+000,2.639771e-003,0.000000e+000,0,,0,
1524663537.305,,0.000000e+000,5.499379e+001,1.126917e-006,0.000000e+000,3,2.279284e-001,0.000000e+000,,,,,,,,,,,,,,32,1,4.000000e+000,9.201050e-003,0.000000e+000,0,,0,
1524663562.595,,0.000000e+000,5.499643e+001,-1.977966e-008,0.000000e+000,3,0.000000e+000,0.000000e+000,,,,,,,,,,,,,,32,1,4.000000e+000,1.312256e-003,0.000000e+000,0,,0,
1524663588.125,,0.000000e+000,5.499051e+001,1.054963e-006,0.000000e+000,3,2.223561e-001,0.000000e+000,,,,,,,,,,,,,,32,1,4.000000e+000,2.632141e-003,0.000000e+000,0,,0,
1524663613.695,,0.000000e+000,5.499971e+001,1.023064e-006,0.000000e+000,3,1.218465e-001,0.000000e+000,,,,,,,,,,,,,,32,1,4.000000e+000,0.000000e+000,0.000000e+000,0,,0,
1524663638.805,,0.000000e+000,5.499380e+001,1.125506e-006,0.000000e+000,3,2.782754e-001,0.000000e+000,,,,,,,,,,,,,,32,1,4.000000e+000,1.308441e-003,0.000000e+000,0,,0,
1524663663.625,,0.000000e+000,5.499313e+001,1.128173e-006,0.000000e+000,3,2.358252e-001,0.000000e+000,,,,,,,,,,,,,,32,1,4.000000e+000,2.628326e-003,0.000000e+000,0,,0,
1524663689.735,,0.000000e+000,5.499775e+001,1.095072e-006,0.000000e+000,3,1.817279e-001,0.000000e+000,,,,,,,,,,,,,,32,1,4.000000e+000,9.208679e-003,0.000000e+000,0,,0,
1524663716.975,,0.000000e+000,5.499445e+001,3.771235e-007,0.000000e+000,2,0.000000e+000,0.000000e+000,,,,,,,,,,,,,,32,1,4.000000e+000,2.628326e-003,0.000000e+000,0,,0,
1524663741.035,,0.000000e+000,5.500234e+001,1.214060e-006,0.000000e+000,3,3.277611e-001,0.000000e+000,,,,,,,,,,,,,,32,1,4.000000e+000,5.260468e-003,0.000000e+000,0,,0,
1524663766.195,,0.000000e+000,5.500103e+001,-9.245505e-008,0.000000e+000,3,0.000000e+000,0.000000e+000,,,,,,,,,,,,,,32,1,4.000000e+000,7.888794e-003,0.000000e+000,0,,0,
1524663790.735,,0.000000e+000,5.499709e+001,1.062662e-006,0.000000e+000,3,3.648905e-002,0.000000e+000,,,,,,,,,,,,,,32,1,4.000000e+000,1.052856e-002,0.000000e+000,0,,0,
1524663816.036,,0.000000e+000,5.500563e+001,1.157613e-006,0.000000e+000,3,1.542063e-001,0.000000e+000,,,,,,,,,,,,,,32,1,4.000000e+000,6.568909e-003,0.000000e+000,0,,0,
1524663844.520,,0.000000e+000,5.500037e+001,3.058020e-007,0.000000e+000,2,0.000000e+000,0.000000e+000,,,,,,,,,,,,,,32,1,4.000000e+000,6.587982e-003,0.000000e+000,0,,0,
1524663871.122,,0.000000e+000,5.499774e+001,3.897092e-007,0.000000e+000,2,0.000000e+000,0.000000e+000,,,,,,,,,,,,,,32,1,4.000000e+000,3.940582e-003,0.000000e+000,0,,0,
1524663897.334,,0.000000e+000,5.499511e+001,5.915622e-007,0.000000e+000,3,0.000000e+000,0.000000e+000,,,,,,,,,,,,,,32,1,4.000000e+000,1.184082e-002,0.000000e+000,0,,0,
1524663926.538,,0.000000e+000,5.499577e+001,3.472489e-007,0.000000e+000,2,0.000000e+000,0.000000e+000,,,,,,,,,,,,,,32,1,4.000000e+000,0.000000e+000,0.000000e+000,0,,0,
1524663950.898,,0.000000e+000,5.499708e+001,1.355792e-007,0.000000e+000,3,0.000000e+000,0.000000e+000,,,,,,,,,,,,,,32,1,4.000000e+000,2.620697e-003,0.000000e+000,0,,0,
1524663980.182,,0.000000e+000,5.499905e+001,2.886703e-007,0.000000e+000,2,0.000000e+000,0.000000e+000,,,,,,,,,,,,,,32,1,4.000000e+000,3.948212e-003,0.000000e+000,0,,0,
1524664008.246,,0.000000e+000,5.500169e+001,2.991052e-007,0.000000e+000,2,0.000000e+000,0.000000e+000,,,,,,,,,,,,,,32,1,4.000000e+000,3.959656e-003,0.000000e+000,0,,0,
1524664036.340,,0.000000e+000,5.499117e+001,3.151913e-007,0.000000e+000,2,0.000000e+000,0.000000e+000,,,,,,,,,,,,,,32,1,4.000000e+000,1.972961e-002,0.000000e+000,0,,0,
1524664064.974,,0.000000e+000,5.500234e+001,2.597697e-007,0.000000e+000,2,0.000000e+000,0.000000e+000,,,,,,,,,,,,,,32,1,4.000000e+000,7.900238e-003,0.000000e+000,0,,0,
1524664092.648,,0.000000e+000,5.499906e+001,3.209097e-007,0.000000e+000,2,0.000000e+000,0.000000e+000,,,,,,,,,,,,,,32,1,4.000000e+000,6.580353e-003,0.000000e+000,0,,0,
1524664121.102,,0.000000e+000,5.500169e+001,3.225419e-007,0.000000e+000,2,0.000000e+000,0.000000e+000,,,,,,,,,,,,,,32,1,4.000000e+000,1.319885e-003,0.000000e+000,0,,0,
1524664149.506,,0.000000e+000,5.499643e+001,1.884742e-007,0.000000e+000,2,0.000000e+000,0.000000e+000,,,,,,,,,,,,,,32,1,4.000000e+000,9.208679e-003,0.000000e+000,0,,0,
1524664178.380,,0.000000e+000,5.499314e+001,2.061431e-007,0.000000e+000,2,0.000000e+000,0.000000e+000,,,,,,,,,,,,,,32,1,4.000000e+000,5.260468e-003,0.000000e+000,0,,0,
1524664206.524,,0.000000e+000,5.499840e+001,2.764548e-007,0.000000e+000,2,0.000000e+000,0.000000e+000,,,,,,,,,,,,,,32,1,4.000000e+000,2.628326e-003,0.000000e+000,0,,0,
1524664234.918,,0.000000e+000,5.499905e+001,2.371635e-007,0.000000e+000,2,0.000000e+000,0.000000e+000,,,,,,,,,,,,,,32,1,4.000000e+000,3.948212e-003,0.000000e+000,0,,0,
1524664263.342,,0.000000e+000,5.499643e+001,2.912168e-007,0.000000e+000,2,0.000000e+000,0.000000e+000,,,,,,,,,,,,,,32,1,4.000000e+000,1.312256e-003,0.000000e+000,0,,0,
1524664289.974,,0.000000e+000,5.499840e+001,2.882199e-007,0.000000e+000,2,0.000000e+000,0.000000e+000,,,,,,,,,,,,,,32,1,4.000000e+000,2.628326e-003,0.000000e+000,0,,0,
1524664319.438,,0.000000e+000,5.500629e+001,1.820450e-007,0.000000e+000,2,0.000000e+000,0.000000e+000,,,,,,,,,,,,,,32,1,4.000000e+000,2.639771e-003,0.000000e+000,0,,0,
1524664348.252,,0.000000e+000,5.499774e+001,2.840104e-007,0.000000e+000,2,0.000000e+000,0.000000e+000,,,,,,,,,,,,,,32,1,4.000000e+000,6.580353e-003,0.000000e+000,0,,0,
1524664374.814,,0.000000e+000,5.500169e+001,-1.874813e-006,0.000000e+000,3,8.605093e-001,0.000000e+000,,,,,,,,,,,,,,32,1,4.000000e+000,1.319885e-003,0.000000e+000,0,,0,
1524664403.268,,0.000000e+000,5.499840e+001,1.986469e-007,0.000000e+000,2,0.000000e+000,0.000000e+000,,,,,,,,,,,,,,32,1,4.000000e+000,5.260468e-003,0.000000e+000,0,,0,
1524664431.992,,0.000000e+000,5.499774e+001,1.874813e-007,0.000000e+000,2,0.000000e+000,0.000000e+000,,,,,,,,,,,,,,32,1,4.000000e+000,3.940582e-003,0.000000e+000,0,,0,
1524664460.056,,0.000000e+000,5.499708e+001,2.198640e-007,0.000000e+000,2,0.000000e+000,0.000000e+000,,,,,,,,,,,,,,32,1,4.000000e+000,2.620697e-003,0.000000e+000,0,,0,
1524664488.340,,0.000000e+000,5.499117e+001,1.812863e-007,0.000000e+000,2,0.000000e+000,0.000000e+000,,,,,,,,,,,,,,32,1,4.000000e+000,9.208679e-003,0.000000e+000,0,,0,
1524664517.714,,0.000000e+000,5.499709e+001,1.738912e-007,0.000000e+000,2,0.000000e+000,0.000000e+000,,,,,,,,,,,,,,32,1,4.000000e+000,1.316071e-002,0.000000e+000,0,,0,
1524664545.497,,0.000000e+000,5.499577e+001,1.949238e-007,0.000000e+000,2,0.000000e+000,0.000000e+000,,,,,,,,,,,,,,32,1,4.000000e+000,5.249023e-003,0.000000e+000,0,,0,
1524664573.491,,0.000000e+000,5.499773e+001,2.459914e-007,0.000000e+000,2,0.000000e+000,0.000000e+000,,,,,,,,,,,,,,32,1,4.000000e+000,1.308441e-003,0.000000e+000,0,,0,
1524664598.111,,0.000000e+000,5.499774e+001,-1.707111e-006,0.000000e+000,3,7.943186e-001,0.000000e+000,,,,,,,,,,,,,,32,1,4.000000e+000,3.940582e-003,0.000000e+000,0,,0,
1524664626.915,,0.000000e+000,5.500301e+001,2.132287e-007,0.000000e+000,2,0.000000e+000,0.000000e+000,,,,,,,,,,,,,,32,1,4.000000e+000,1.319885e-003,0.000000e+000,0,,0,
1524664653.747,,0.000000e+000,5.500958e+001,1.823766e-007,0.000000e+000,2,0.000000e+000,0.000000e+000,,,,,,,,,,,,,,32,1,4.000000e+000,1.446915e-002,0.000000e+000,0,,0,
1524664679.429,,0.000000e+000,5.500169e+001,-1.777034e-006,0.000000e+000,3,8.137844e-001,0.000000e+000,,,,,,,,,,,,,,32,1,4.000000e+000,1.319885e-003,0.000000e+000,0,,0,
1524664705.951,,0.000000e+000,5.500234e+001,-1.918664e-006,0.000000e+000,3,8.428786e-001,0.000000e+000,,,,,,,,,,,,,,32,1,4.000000e+000,1.314926e-002,0.000000e+000,0,,0,
1524664733.575,,0.000000e+000,5.499840e+001,2.139106e-007,0.000000e+000,2,0.000000e+000,0.000000e+000,,,,,,,,,,,,,,32,1,4.000000e+000,1.578140e-002,0.000000e+000,0,,0,
1524664759.877,,0.000000e+000,5.499839e+001,1.895980e-007,0.000000e+000,2,0.000000e+000,0.000000e+000,,,,,,,,,,,,,,32,1,4.000000e+000,0.000000e+000,0.000000e+000,0,,0,
1524664784.687,,0.000000e+000,5.499709e+001,-1.796368e-006,0.000000e+000,3,8.153461e-001,0.000000e+000,,,,,,,,,,,,,,32,1,4.000000e+000,7.888794e-003,0.000000e+000,0,,0,
1524664811.409,,0.000000e+000,5.499971e+001,-1.925039e-006,0.000000e+000,3,8.266268e-001,0.000000e+000,,,,,,,,,,,,,,32,1,4.000000e+000,1.052094e-002,0.000000e+000,0,,0,
1524664838.161,,0.000000e+000,5.499380e+001,-1.649934e-006,0.000000e+000,3,8.154547e-001,0.000000e+000,,,,,,,,,,,,,,32,1,4.000000e+000,3.948212e-003,0.000000e+000,0,,0,
1524664864.423,,0.000000e+000,5.499445e+001,-1.852067e-006,0.000000e+000,3,8.309033e-001,0.000000e+000,,,,,,,,,,,,,,32,1,4.000000e+000,7.881165e-003,0.000000e+000,0,,0,
1524664879.045,,0.000000e+000,5.499577e+001,1.811833e-007,0.000000e+000,2,0.000000e+000,0.000000e+000,,,,,,,,,,,,,,32,1,4.000000e+000,5.249023e-003,0.000000e+000,0,,0,