File: Input_All/TC04-12-01K_TRMac_57K_0.08Kmin_VRMde_55K.dc.dat
[Header]
TITLE,MPMS DC Measurement
BYAPP,MPMS Measurement,2.1,Summary
FILEOPENTIME, 1524381560.653000 4/22/2018, 1:19:20 AM

INFO, APPNAME, MPMS MultiVu Application, Revision 1.61,  Build 082

INFO, NAME, TC04-12-01K
INFO, WEIGHT, 1.000
INFO, AREA, 1.000
INFO, LENGTH, 1.000
INFO, SHAPE, 0
INFO, COMMENT,
INFO, SEQUENCE FILE: TRMac_57K_0.08Kmin_VRMde_55K.seq


INFO, BACKGROUND DATA FILE:, None


STARTUPAXIS,X,4,LINEAR,AUTO,0.000000,0.000000
STARTUPAXIS,Y1,5,LINEAR,AUTO,0.000000,0.000000


STARTUPGROUP,Longitudinal
FIELDGROUP,Longitudinal,1,2,3,4,5,6,7,8,9,15,16,17,18,27,28
FIELDGROUP,Transverse,1,2,3,4,10,11,12,13,14,19,20,21,22,27,28

PLOT_APPEARANCE,ALL,HORZ_GRID_ON,VERT_GRID_ON,MARKERS_AND_LINES

[Data]
Time,Comment,Field (Oe),Temperature (K),Long Moment (emu),Long Scan Std Dev,Long Algorithm,Long Reg Fit,Long Percent Error (%),Trans Moment (emu),Trans Scan Std Dev,Trans Algorithm,Trans Reg Fit,Trans Percent Error (%),Long Moment [w/o ABS] (emu),Long Scan Std Dev [w/o ABS],Long Reg Fit [w/o ABS],Long Percent Error [w/o ABS] (%),Trans Moment [w/o ABS] (emu),Trans Scan Std Dev [w/o ABS],Trans Reg Fit [w/o ABS],Trans Percent Error [w/o ABS] (%),Points per Scan,Scans per Measurement,Scan Length (cm),Delta Temp (K),Rot Position (deg),Error,EC Comp. Running,Using ABS,
1524381560.653,,0.000000e+000,5.499577e+001,-9.237002e-006,0.000000e+000,2,8.524060e-001,0.000000e+000,,,,,,,,,,,,,,32,1,4.000000e+000,5.249023e-003,0.000000e+000,0,,0,
1524381598.523,,0.000000e+000,5.499511e+001,-6.276918e-006,0.000000e+000,2,7.648922e-001,0.000000e+000,,,,,,,,,,,,,,32,1,4.000000e+000,1.319885e-003,0.000000e+000,0,,0,
1524381636.333,,0.000000e+000,5.499906e+001,-4.674630e-006,0.000000e+000,2,6.957314e-001,0.000000e+000,,,,,,,,,,,,,,32,1,4.000000e+000,6.580353e-003,0.000000e+000,0,,0,
1524381673.683,,0.000000e+000,5.500497e+001,-3.673989e-006,0.000000e+000,2,5.740479e-001,0.000000e+000,,,,,,,,,,,,,,32,1,4.000000e+000,0.000000e+000,0.000000e+000,0,,0,
1524381711.453,,0.000000e+000,5.499511e+001,-2.860501e-006,0.000000e+000,2,4.832948e-001,0.000000e+000,,,,,,,,,,,,,,32,1,4.000000e+000,1.319885e-003,0.000000e+000,0,,0,
1524381749.033,,0.000000e+000,5.499971e+001,-2.324065e-006,0.000000e+000,2,3.339938e-001,0.000000e+000,,,,,,,,,,,,,,32,1,4.000000e+000,2.639771e-003,0.000000e+000,0,,0,
1524381786.763,,0.000000e+000,5.500234e+001,-1.901401e-006,0.000000e+000,2,1.773077e-001,0.000000e+000,,,,,,,,,,,,,,32,1,4.000000e+000,1.314926e-002,0.000000e+000,0,,0,
1524381823.963,,0.000000e+000,5.499643e+001,-1.534861e-006,0.000000e+000,2,0.000000e+000,0.000000e+000,,,,,,,,,,,,,,32,1,4.000000e+000,1.312256e-003,0.000000e+000,0,,0,
1524381861.764,,0.000000e+000,5.500366e+001,-1.116292e-006,0.000000e+000,2,0.000000e+000,0.000000e+000,,,,,,,,,,,,,,32,1,4.000000e+000,5.260468e-003,0.000000e+000,0,,0,
1524381900.414,,0.000000e+000,5.499643e+001,-8.262307e-007,0.000000e+000,2,0.000000e+000,0.000000e+000,,,,,,,,,,,,,,32,1,4.000000e+000,6.568909e-003,0.000000e+000,0,,0,
1524381938.174,,0.000000e+000,5.499642e+001,-5.322887e-007,0.000000e+000,2,0.000000e+000,0.000000e+000,,,,,,,,,,,,,,32,1,4.000000e+000,3.940582e-003,0.000000e+000,0,,0,
1524381975.834,,0.000000e+000,5.500037e+001,-3.940193e-007,0.000000e+000,2,0.000000e+000,0.000000e+000,,,,,,,,,,,,,,32,1,4.000000e+000,3.959656e-003,0.000000e+000,0,,0,
1524382014.014,,0.000000e+000,5.499709e+001,-4.374692e-008,0.000000e+000,2,0.000000e+000,0.000000e+000,,,,,,,,,,,,,,32,1,4.000000e+000,7.888794e-003,0.000000e+000,0,,0,
1524382051.874,,0.000000e+000,5.499905e+001,1.256038e-007,0.000000e+000,2,0.000000e+000,0.000000e+000,,,,,,,,,,,,,,32,1,4.000000e+000,3.948212e-003,0.000000e+000,0,,0,
1524382089.804,,0.000000e+000,5.499773e+001,2.927309e-007,0.000000e+000,2,0.000000e+000,0.000000e+000,,,,,,,,,,,,,,32,1,4.000000e+000,1.308441e-003,0.000000e+000,0,,0,
1524382127.044,,0.000000e+000,5.500169e+001,4.746088e-007,0.000000e+000,2,0.000000e+000,0.000000e+000,,,,,,,,,,,,,,32,1,4.000000e+000,9.208679e-003,0.000000e+000,0,,0,
1524382164.744,,0.000000e+000,5.499709e+001,6.903663e-007,0.000000e+000,2,0.000000e+000,0.000000e+000,,,,,,,,,,,,,,32,1,4.000000e+000,7.888794e-003,0.000000e+000,0,,0,
1524382202.734,,0.000000e+000,5.499380e+001,7.364994e-007,0.000000e+000,2,0.000000e+000,0.000000e+000,,,,,,,,,,,,,,32,1,4.000000e+000,1.308441e-003,0.000000e+000,0,,0,
1524382240.194,,0.000000e+000,5.500103e+001,8.440649e-007,0.000000e+000,2,0.000000e+000,0.000000e+000,,,,,,,,,,,,,,32,1,4.000000e+000,2.639771e-003,0.000000e+000,0,,0,
1524382277.964,,0.000000e+000,5.499839e+001,9.800559e-007,0.000000e+000,2,0.000000e+000,0.000000e+000,,,,,,,,,,,,,,32,1,4.000000e+000,0.000000e+000,0.000000e+000,0,,0,
1524382315.934,,0.000000e+000,5.499643e+001,1.017595e-006,0.000000e+000,2,0.000000e+000,0.000000e+000,,,,,,,,,,,,,,32,1,4.000000e+000,1.312256e-003,0.000000e+000,0,,0,
1524382353.874,,0.000000e+000,5.499971e+001,1.213044e-006,0.000000e+000,2,0.000000e+000,0.000000e+000,,,,,,,,,,,,,,32,1,4.000000e+000,1.052094e-002,0.000000e+000,0,,0,
1524382391.794,,0.000000e+000,5.499643e+001,1.291109e-006,0.000000e+000,2,0.000000e+000,0.000000e+000,,,,,,,,,,,,,,32,1,4.000000e+000,1.312256e-003,0.000000e+000,0,,0,
1524382429.464,,0.000000e+000,5.499643e+001,1.409802e-006,0.000000e+000,2,0.000000e+000,0.000000e+000,,,,,,,,,,,,,,32,1,4.000000e+000,1.312256e-003,0.000000e+000,0,,0,
1524382467.504,,0.000000e+000,5.499511e+001,1.456405e-006,0.000000e+000,2,0.000000e+000,0.000000e+000,,,,,,,,,,,,,,32,1,4.000000e+000,6.568909e-003,0.000000e+000,0,,0,
1524382505.174,,0.000000e+000,5.499511e+001,1.545848e-006,0.000000e+000,2,0.000000e+000,0.000000e+000,,,,,,,,,,,,,,32,1,4.000000e+000,3.940582e-003,0.000000e+000,0,,0,
1524382544.064,,0.000000e+000,5.500168e+001,1.624074e-006,0.000000e+000,2,1.626009e-002,0.000000e+000,,,,,,,,,,,,,,32,1,4.000000e+000,6.580353e-003,0.000000e+000,0,,0,
1524382582.585,,0.000000e+000,5.499445e+001,1.691893e-006,0.000000e+000,2,7.264389e-002,0.000000e+000,,,,,,,,,,,,,,32,1,4.000000e+000,7.881165e-003,0.000000e+000,0,,0,
1524382621.115,,0.000000e+000,5.499708e+001,1.749684e-006,0.000000e+000,2,6.271164e-002,0.000000e+000,,,,,,,,,,,,,,32,1,4.000000e+000,5.260468e-003,0.000000e+000,0,,0,
1524382658.805,,0.000000e+000,5.499117e+001,1.821171e-006,0.000000e+000,2,8.679080e-002,0.000000e+000,,,,,,,,,,,,,,32,1,4.000000e+000,6.568909e-003,0.000000e+000,0,,0,
1524382697.415,,0.000000e+000,5.499708e+001,1.847860e-006,0.000000e+000,2,1.323985e-001,0.000000e+000,,,,,,,,,,,,,,32,1,4.000000e+000,2.620697e-003,0.000000e+000,0,,0,
1524382735.685,,0.000000e+000,5.499445e+001,1.815468e-006,0.000000e+000,2,1.411543e-001,0.000000e+000,,,,,,,,,,,,,,32,1,4.000000e+000,0.000000e+000,0.000000e+000,0,,0,
1524382773.115,,0.000000e+000,5.500366e+001,1.968765e-006,0.000000e+000,2,1.929790e-001,0.000000e+000,,,,,,,,,,,,,,32,1,4.000000e+000,5.260468e-003,0.000000e+000,0,,0,
1524382811.155,,0.000000e+000,5.500235e+001,2.019307e-006,0.000000e+000,2,2.341591e-001,0.000000e+000,,,,,,,,,,,,,,32,1,4.000000e+000,0.000000e+000,0.000000e+000,0,,0,
1524382848.825,,0.000000e+000,5.500037e+001,2.098971e-006,0.000000e+000,2,2.281315e-001,0.000000e+000,,,,,,,,,,,,,,32,1,4.000000e+000,9.201050e-003,0.000000e+000,0,,0,
1524382886.855,,0.000000e+000,5.500037e+001,2.077061e-006,0.000000e+000,2,2.485390e-001,0.000000e+000,,,,,,,,,,,,,,32,1,4.000000e+000,6.587982e-003,0.000000e+000,0,,0,
1524382924.455,,0.000000e+000,5.499511e+001,2.141891e-006,0.000000e+000,2,2.612368e-001,0.000000e+000,,,,,,,,,,,,,,32,1,4.000000e+000,6.568909e-003,0.000000e+000,0,,0,
1524382962.495,,0.000000e+000,5.499708e+001,2.162028e-006,0.000000e+000,2,2.618337e-001,0.000000e+000,,,,,,,,,,,,,,32,1,4.000000e+000,0.000000e+000,0.000000e+000,0,,0,
1524383000.125,,0.000000e+000,5.499840e+001,2.244656e-006,0.000000e+000,2,2.785391e-001,0.000000e+000,,,,,,,,,,,,,,32,1,4.000000e+000,7.900238e-003,0.000000e+000,0,,0,
1524383038.105,,0.000000e+000,5.500235e+001,2.278279e-006,0.000000e+000,2,3.128861e-001,0.000000e+000,,,,,,,,,,,,,,32,1,4.000000e+000,1.052856e-002,0.000000e+000,0,,0,
1524383075.825,,0.000000e+000,5.499577e+001,2.311963e-006,0.000000e+000,2,3.077929e-001,0.000000e+000,,,,,,,,,,,,,,32,1,4.000000e+000,1.052094e-002,0.000000e+000,0,,0,
1524383113.065,,0.000000e+000,5.500037e+001,2.319566e-006,0.000000e+000,2,3.192083e-001,0.000000e+000,,,,,,,,,,,,,,32,1,4.000000e+000,3.959656e-003,0.000000e+000,0,,0,
1524383150.875,,0.000000e+000,5.499445e+001,2.395402e-006,0.000000e+000,2,3.265845e-001,0.000000e+000,,,,,,,,,,,,,,32,1,4.000000e+000,0.000000e+000,0.000000e+000,0,,0,
1524383188.615,,0.000000e+000,5.499840e+001,2.411530e-006,0.000000e+000,2,3.530959e-001,0.000000e+000,,,,,,,,,,,,,,32,1,4.000000e+000,5.260468e-003,0.000000e+000,0,,0,
1524383226.015,,0.000000e+000,5.500037e+001,2.454943e-006,0.000000e+000,2,3.337848e-001,0.000000e+000,,,,,,,,,,,,,,32,1,4.000000e+000,9.201050e-003,0.000000e+000,0,,0,
1524383263.995,,0.000000e+000,5.500037e+001,2.451832e-006,0.000000e+000,2,3.628003e-001,0.000000e+000,,,,,,,,,,,,,,32,1,4.000000e+000,1.184082e-002,0.000000e+000,0,,0,
1524383301.646,,0.000000e+000,5.500037e+001,2.498944e-006,0.000000e+000,2,3.638426e-001,0.000000e+000,,,,,,,,,,,,,,32,1,4.000000e+000,6.587982e-003,0.000000e+000,0,,0,
1524383339.556,,0.000000e+000,5.500300e+001,2.574547e-006,0.000000e+000,2,3.811624e-001,0.000000e+000,,,,,,,,,,,,,,32,1,4.000000e+000,6.580353e-003,0.000000e+000,0,,0,
1524383377.216,,0.000000e+000,5.499643e+001,2.531821e-006,0.000000e+000,2,3.587362e-001,0.000000e+000,,,,,,,,,,,,,,32,1,4.000000e+000,1.312256e-003,0.000000e+000,0,,0,
1524383414.746,,0.000000e+000,5.500103e+001,2.647541e-006,0.000000e+000,2,4.010623e-001,0.000000e+000,,,,,,,,,,,,,,32,1,4.000000e+000,1.052094e-002,0.000000e+000,0,,0,
1524383452.696,,0.000000e+000,5.499577e+001,2.567355e-006,0.000000e+000,2,3.737324e-001,0.000000e+000,,,,,,,,,,,,,,32,1,4.000000e+000,2.632141e-003,0.000000e+000,0,,0,
1524383490.506,,0.000000e+000,5.500103e+001,2.603761e-006,0.000000e+000,2,3.934967e-001,0.000000e+000,,,,,,,,,,,,,,32,1,4.000000e+000,1.052094e-002,0.000000e+000,0,,0,
1524383528.346,,0.000000e+000,5.499972e+001,2.574960e-006,0.000000e+000,2,3.766021e-001,0.000000e+000,,,,,,,,,,,,,,32,1,4.000000e+000,1.314926e-002,0.000000e+000,0,,0,
1524383566.156,,0.000000e+000,5.499906e+001,2.653976e-006,0.000000e+000,2,4.000468e-001,0.000000e+000,,,,,,,,,,,,,,32,1,4.000000e+000,6.580353e-003,0.000000e+000,0,,0,
1524383603.526,,0.000000e+000,5.500103e+001,2.669407e-006,0.000000e+000,2,3.777314e-001,0.000000e+000,,,,,,,,,,,,,,32,1,4.000000e+000,7.888794e-003,0.000000e+000,0,,0,
1524383641.036,,0.000000e+000,5.499773e+001,2.715065e-006,0.000000e+000,2,4.093950e-001,0.000000e+000,,,,,,,,,,,,,,32,1,4.000000e+000,1.308441e-003,0.000000e+000,0,,0,
1524383678.796,,0.000000e+000,5.500037e+001,2.738705e-006,0.000000e+000,2,4.246366e-001,0.000000e+000,,,,,,,,,,,,,,32,1,4.000000e+000,9.201050e-003,0.000000e+000,0,,0,
1524383715.856,,0.000000e+000,5.499708e+001,2.789911e-006,0.000000e+000,2,4.188090e-001,0.000000e+000,,,,,,,,,,,,,,32,1,4.000000e+000,2.620697e-003,0.000000e+000,0,,0,
1524383754.066,,0.000000e+000,5.500169e+001,2.803793e-006,0.000000e+000,2,4.266722e-001,0.000000e+000,,,,,,,,,,,,,,32,1,4.000000e+000,1.184082e-002,0.000000e+000,0,,0,
1524383791.226,,0.000000e+000,5.499708e+001,2.867877e-006,0.000000e+000,2,4.127127e-001,0.000000e+000,,,,,,,,,,,,,,32,1,4.000000e+000,0.000000e+000,0.000000e+000,0,,0,
1524383829.136,,0.000000e+000,5.499774e+001,2.862451e-006,0.000000e+000,2,4.312077e-001,0.000000e+000,,,,,,,,,,,,,,32,1,4.000000e+000,6.580353e-003,0.000000e+000,0,,0,
1524383866.206,,0.000000e+000,5.500169e+001,2.841959e-006,0.000000e+000,2,4.240195e-001,0.000000e+000,,,,,,,,,,,,,,32,1,4.000000e+000,1.972961e-002,0.000000e+000,0,,0,
1524383903.686,,0.000000e+000,5.499248e+001,2.827207e-006,0.000000e+000,2,4.440991e-001,0.000000e+000,,,,,,,,,,,,,,32,1,4.000000e+000,1.446152e-002,0.000000e+000,0,,0,
1524383941.366,,0.000000e+000,5.500497e+001,2.851115e-006,0.000000e+000,2,4.265617e-001,0.000000e+000,,,,,,,,,,,,,,32,1,4.000000e+000,0.000000e+000,0.000000e+000,0,,0,
1524383979.976,,0.000000e+000,5.500366e+001,2.907547e-006,0.000000e+000,2,4.390954e-001,0.000000e+000,,,,,,,,,,,,,,32,1,4.000000e+000,5.260468e-003,0.000000e+000,0,,0,
1524384017.477,,0.000000e+000,5.499445e+001,2.919667e-006,0.000000e+000,2,4.584555e-001,0.000000e+000,,,,,,,,,,,,,,32,1,4.000000e+000,1.578903e-002,0.000000e+000,0,,0,
1524384055.837,,0.000000e+000,5.499709e+001,2.917772e-006,0.000000e+000,2,4.416987e-001,0.000000e+000,,,,,,,,,,,,,,32,1,4.000000e+000,1.052856e-002,0.000000e+000,0,,0,
1524384093.907,,0.000000e+000,5.499642e+001,2.892499e-006,0.000000e+000,2,4.589370e-001,0.000000e+000,,,,,,,,,,,,,,32,1,4.000000e+000,3.940582e-003,0.000000e+000,0,,0,
1524384131.657,,0.000000e+000,5.499183e+001,2.890165e-006,0.000000e+000,2,4.312841e-001,0.000000e+000,,,,,,,,,,,,,,32,1,4.000000e+000,2.632141e-003,0.000000e+000,0,,0,
1524384169.547,,0.000000e+000,5.499774e+001,2.951582e-006,0.000000e+000,2,4.664355e-001,0.000000e+000,,,,,,,,,,,,,,32,1,4.000000e+000,3.940582e-003,0.000000e+000,0,,0,
1524384208.007,,0.000000e+000,5.499841e+001,2.881035e-006,0.000000e+000,2,4.389586e-001,0.000000e+000,,,,,,,,,,,,,,32,1,4.000000e+000,1.052856e-002,0.000000e+000,0,,0,
1524384245.497,,0.000000e+000,5.499577e+001,2.925676e-006,0.000000e+000,2,4.552040e-001,0.000000e+000,,,,,,,,,,,,,,32,1,4.000000e+000,0.000000e+000,0.000000e+000,0,,0,
1524384283.147,,0.000000e+000,5.500037e+001,2.882724e-006,0.000000e+000,2,4.333842e-001,0.000000e+000,,,,,,,,,,,,,,32,1,4.000000e+000,6.587982e-003,0.000000e+000,0,,0,
1524384320.967,,0.000000e+000,5.499445e+001,2.941968e-006,0.000000e+000,2,4.584517e-001,0.000000e+000,,,,,,,,,,,,,,32,1,4.000000e+000,2.628326e-003,0.000000e+000,0,,0,
1524384359.297,,0.000000e+000,5.499445e+001,3.082669e-006,0.000000e+000,2,4.709009e-001,0.000000e+000,,,,,,,,,,,,,,32,1,4.000000e+000,5.260468e-003,0.000000e+000,0,,0,
1524384396.927,,0.000000e+000,5.499905e+001,2.997020e-006,0.000000e+000,2,4.523885e-001,0.000000e+000,,,,,,,,,,,,,,32,1,4.000000e+000,1.319885e-003,0.000000e+000,0,,0,
1524384434.827,,0.000000e+000,5.499643e+001,3.024345e-006,0.000000e+000,2,4.765780e-001,0.000000e+000,,,,,,,,,,,,,,32,1,4.000000e+000,1.312256e-003,0.000000e+000,0,,0,
1524384471.967,,0.000000e+000,5.499972e+001,2.982305e-006,0.000000e+000,2,4.363185e-001,0.000000e+000,,,,,,,,,,,,,,32,1,4.000000e+000,7.900238e-003,0.000000e+000,0,,0,
1524384510.347,,0.000000e+000,5.499840e+001,3.040700e-006,0.000000e+000,2,4.700682e-001,0.000000e+000,,,,,,,,,,,,,,32,1,4.000000e+000,2.628326e-003,0.000000e+000,0,,0,
1524384548.297,,0.000000e+000,5.500563e+001,3.070217e-006,0.000000e+000,2,4.860241e-001,0.000000e+000,,,,,,,,,,,,,,32,1,4.000000e+000,6.568909e-003,0.000000e+000,0,,0,
1524384585.937,,0.000000e+000,5.499773e+001,3.068465e-006,0.000000e+000,2,4.711154e-001,0.000000e+000,,,,,,,,,,,,,,32,1,4.000000e+000,1.308441e-003,0.000000e+000,0,,0,
1524384623.767,,0.000000e+000,5.499971e+001,3.079565e-006,0.000000e+000,2,4.907170e-001,0.000000e+000,,,,,,,,,,,,,,32,1,4.000000e+000,0.000000e+000,0.000000e+000,0,,0,
1524384661.017,,0.000000e+000,5.500103e+001,3.158145e-006,0.000000e+000,2,4.879851e-001,0.000000e+000,,,,,,,,,,,,,,32,1,4.000000e+000,1.052094e-002,0.000000e+000,0,,0,
1524384699.048,,0.000000e+000,5.499577e+001,3.051648e-006,0.000000e+000,2,4.865133e-001,0.000000e+000,,,,,,,,,,,,,,32,1,4.000000e+000,5.249023e-003,0.000000e+000,0,,0,
1524384736.708,,0.000000e+000,5.499773e+001,3.108246e-006,0.000000e+000,2,4.753051e-001,0.000000e+000,,,,,,,,,,,,,,32,1,4.000000e+000,1.308441e-003,0.000000e+000,0,,0,
1524384774.718,,0.000000e+000,5.499577e+001,3.114526e-006,0.000000e+000,2,4.819014e-001,0.000000e+000,,,,,,,,,,,,,,32,1,4.000000e+000,2.632141e-003,0.000000e+000,0,,0,
1524384812.258,,0.000000e+000,5.500168e+001,3.084626e-006,0.000000e+000,2,4.485741e-001,0.000000e+000,,,,,,,,,,,,,,32,1,4.000000e+000,6.580353e-003,0.000000e+000,0,,0,
1524384849.798,,0.000000e+000,5.499840e+001,3.093776e-006,0.000000e+000,2,4.842741e-001,0.000000e+000,,,,,,,,,,,,,,32,1,4.000000e+000,2.628326e-003,0.000000e+000,0,,0,
1524384887.468,,0.000000e+000,5.499511e+001,3.201396e-006,0.000000e+000,2,4.988338e-001,0.000000e+000,,,,,,,,,,,,,,32,1,4.000000e+000,1.319885e-003,0.000000e+000,0,,0,
1524384925.458,,0.000000e+000,5.500431e+001,3.140799e-006,0.000000e+000,2,5.004733e-001,0.000000e+000,,,,,,,,,,,,,,32,1,4.000000e+000,9.208679e-003,0.000000e+000,0,,0,
1524384962.898,,0.000000e+000,5.500300e+001,3.166263e-006,0.000000e+000,2,4.785427e-001,0.000000e+000,,,,,,,,,,,,,,32,1,4.000000e+000,1.183701e-002,0.000000e+000,0,,0,
1524385000.598,,0.000000e+000,5.499972e+001,3.149007e-006,0.000000e+000,2,5.044776e-001,0.000000e+000,,,,,,,,,,,,,,32,1,4.000000e+000,7.900238e-003,0.000000e+000,0,,0,
1524385038.468,,0.000000e+000,5.499972e+001,3.105256e-006,0.000000e+000,2,4.868878e-001,0.000000e+000,,,,,,,,,,,,,,32,1,4.000000e+000,1.578903e-002,0.000000e+000,0,,0,
1524385076.398,,0.000000e+000,5.499773e+001,3.167798e-006,0.000000e+000,2,4.825778e-001,0.000000e+000,,,,,,,,,,,,,,32,1,4.000000e+000,1.308441e-003,0.000000e+000,0,,0,
1524385114.508,,0.000000e+000,5.500497e+001,3.173855e-006,0.000000e+000,2,4.981240e-001,0.000000e+000,,,,,,,,,,,,,,32,1,4.000000e+000,0.000000e+000,0.000000e+000,0,,0,
1524385152.238,,0.000000e+000,5.499248e+001,3.197116e-006,0.000000e+000,2,4.826140e-001,0.000000e+000,,,,,,,,,,,,,,32,1,4.000000e+000,1.319885e-003,0.000000e+000,0,,0,
1524385190.138,,0.000000e+000,5.499643e+001,3.198614e-006,0.000000e+000,2,5.004434e-001,0.000000e+000,,,,,,,,,,,,,,32,1,4.000000e+000,1.312256e-003,0.000000e+000,0,,0,
1524385228.188,,0.000000e+000,5.500300e+001,3.254539e-006,0.000000e+000,2,4.982973e-001,0.000000e+000,,,,,,,,,,,,,,32,1,4.000000e+000,3.940582e-003,0.000000e+000,0,,0,
1524385266.058,,0.000000e+000,5.499708e+001,3.239662e-006,0.000000e+000,2,5.149850e-001,0.000000e+000,,,,,,,,,,,,,,32,1,4.000000e+000,5.260468e-003,0.000000e+000,0,,0,
1524385304.988,,0.000000e+000,5.500103e+001,3.258664e-006,0.000000e+000,2,5.165778e-001,0.000000e+000,,,,,,,,,,,,,,32,1,4.000000e+000,0.000000e+000,0.000000e+000,0,,0,
1524385342.518,,0.000000e+000,5.499774e+001,3.296532e-006,0.000000e+000,2,5.060656e-001,0.000000e+000,,,,,,,,,,,,,,32,1,4.000000e+000,6.580353e-003,0.000000e+000,0,,0,
1524385380.088,,0.000000e+000,5.500103e+001,3.336295e-006,0.000000e+000,2,5.107933e-001,0.000000e+000,,,,,,,,,,,,,,32,1,4.000000e+000,5.279541e-003,0.000000e+000,0,,0,
1524385418.359,,0.000000e+000,5.500432e+001,3.281565e-006,0.000000e+000,2,5.017465e-001,0.000000e+000,,,,,,,,,,,,,,32,1,4.000000e+000,1.300812e-003,0.000000e+000,0,,0,
1524385456.009,,0.000000e+000,5.499840e+001,3.336125e-006,0.000000e+000,2,5.016774e-001,0.000000e+000,,,,,,,,,,,,,,32,1,4.000000e+000,5.260468e-003,0.000000e+000,0,,0,
1524385493.889,,0.000000e+000,5.500234e+001,3.299174e-006,0.000000e+000,2,5.005703e-001,0.000000e+000,,,,,,,,,,,,,,32,1,4.000000e+000,1.314926e-002,0.000000e+000,0,,0,
1524385531.209,,0.000000e+000,5.499971e+001,3.368399e-006,0.000000e+000,2,4.988698e-001,0.000000e+000,,,,,,,,,,,,,,32,1,4.000000e+000,2.639771e-003,0.000000e+000,0,,0,
1524385568.729,,0.000000e+000,5.499773e+001,3.366322e-006,0.000000e+000,2,5.092352e-001,0.000000e+000,,,,,,,,,,,,,,32,1,4.000000e+000,1.308441e-003,0.000000e+000,0,,0,
1524385605.899,,0.000000e+000,5.499773e+001,3.483980e-006,0.000000e+000,2,5.149562e-001,0.000000e+000,,,,,,,,,,,,,,32,1,4.000000e+000,1.308441e-003,0.000000e+000,0,,0,
1524385643.869,,0.000000e+000,5.499971e+001,3.409855e-006,0.000000e+000,2,5.028421e-001,0.000000e+000,,,,,,,,,,,,,,32,1,4.000000e+000,1.052094e-002,0.000000e+000,0,,0,
1524385681.769,,0.000000e+000,5.499380e+001,3.416365e-006,0.000000e+000,2,5.167124e-001,0.000000e+000,,,,,,,,,,,,,,32,1,4.000000e+000,3.948212e-003,0.000000e+000,0,,0,
1524385719.539,,0.000000e+000,5.500168e+001,3.433744e-006,0.000000e+000,2,5.192038e-001,0.000000e+000,,,,,,,,,,,,,,32,1,4.000000e+000,6.580353e-003,0.000000e+000,0,,0,
1524385757.449,,0.000000e+000,5.499906e+001,3.431557e-006,0.000000e+000,2,5.204223e-001,0.000000e+000,,,,,,,,,,,,,,32,1,4.000000e+000,9.220123e-003,0.000000e+000,0,,0,
1524385794.859,,0.000000e+000,5.499511e+001,3.519158e-006,0.000000e+000,2,5.262456e-001,0.000000e+000,,,,,,,,,,,,,,32,1,4.000000e+000,1.319885e-003,0.000000e+000,0,,0,
1524385833.509,,0.000000e+000,5.499971e+001,3.456435e-006,0.000000e+000,2,5.235273e-001,0.000000e+000,,,,,,,,,,,,,,32,1,4.000000e+000,2.639771e-003,0.000000e+000,0,,0,
1524385871.019,,0.000000e+000,5.499840e+001,3.492165e-006,0.000000e+000,2,5.041655e-001,0.000000e+000,,,,,,,,,,,,,,32,1,4.000000e+000,2.628326e-003,0.000000e+000,0,,0,
1524385909.019,,0.000000e+000,5.500169e+001,3.428656e-006,0.000000e+000,2,5.119210e-001,0.000000e+000,,,,,,,,,,,,,,32,1,4.000000e+000,9.208679e-003,0.000000e+000,0,,0,
1524385946.979,,0.000000e+000,5.499840e+001,3.434836e-006,0.000000e+000,2,4.983862e-001,0.000000e+000,,,,,,,,,,,,,,32,1,4.000000e+000,5.260468e-003,0.000000e+000,0,,0,
1524385985.019,,0.000000e+000,5.499972e+001,3.436952e-006,0.000000e+000,2,5.080180e-001,0.000000e+000,,,,,,,,,,,,,,32,1,4.000000e+000,7.900238e-003,0.000000e+000,0,,0,
1524386023.179,,0.000000e+000,5.499708e+001,3.379276e-006,0.000000e+000,2,4.972843e-001,0.000000e+000,,,,,,,,,,,,,,32,1,4.000000e+000,5.260468e-003,0.000000e+000,0,,0,
1524386060.229,,0.000000e+000,5.499905e+001,3.449858e-006,0.000000e+000,2,5.152417e-001,0.000000e+000,,,,,,,,,,,,,,32,1,4.000000e+000,3.948212e-003,0.000000e+000,0,,0,
1524386097.169,,0.000000e+000,5.499511e+001,3.470436e-006,0.000000e+000,2,4.843368e-001,0.000000e+000,,,,,,,,,,,,,,32,1,4.000000e+000,1.319885e-003,0.000000e+000,0,,0,
1524386134.970,,0.000000e+000,5.500169e+001,3.525950e-006,0.000000e+000,2,5.320308e-001,0.000000e+000,,,,,,,,,,,,,,32,1,4.000000e+000,1.319885e-003,0.000000e+000,0,,0,
1524386172.310,,0.000000e+000,5.499971e+001,3.471172e-006,0.000000e+000,2,4.804357e-001,0.000000e+000,,,,,,,,,,,,,,32,1,4.000000e+000,2.639771e-003,0.000000e+000,0,,0,
1524386210.660,,0.000000e+000,5.499445e+001,3.464462e-006,0.000000e+000,2,5.358567e-001,0.000000e+000,,,,,,,,,,,,,,32,1,4.000000e+000,0.000000e+000,0.000000e+000,0,,0,
1524386248.510,,0.000000e+000,5.500103e+001,3.492805e-006,0.000000e+000,2,5.296243e-001,0.000000e+000,,,,,,,,,,,,,,32,1,4.000000e+000,2.639771e-003,0.000000e+000,0,,0,
1524386285.630,,0.000000e+000,5.499839e+001,3.507632e-006,0.000000e+000,2,5.124163e-001,0.000000e+000,,,,,,,,,,,,,,32,1,4.000000e+000,0.000000e+000,0.000000e+000,0,,0,
1524386323.600,,0.000000e+000,5.500103e+001,3.494439e-006,0.000000e+000,2,5.161805e-001,0.000000e+000,,,,,,,,,,,,,,32,1,4.000000e+000,5.279541e-003,0.000000e+000,0,,0,
1524386361.200,,0.000000e+000,5.499905e+001,3.517863e-006,0.000000e+000,2,5.222362e-001,0.000000e+000,,,,,,,,,,,,,,32,1,4.000000e+000,3.948212e-003,0.000000e+000,0,,0,
1524386399.160,,0.000000e+000,5.500366e+001,3.479199e-006,0.000000e+000,2,5.228500e-001,0.000000e+000,,,,,,,,,,,,,,32,1,4.000000e+000,7.900238e-003,0.000000e+000,0,,0,
1524386436.640,,0.000000e+000,5.499248e+001,3.510786e-006,0.000000e+000,2,4.808795e-001,0.000000e+000,,,,,,,,,,,,,,32,1,4.000000e+000,3.940582e-003,0.000000e+000,0,,0,
1524386474.760,,0.000000e+000,5.499971e+001,3.605275e-006,0.000000e+000,2,5.422094e-001,0.000000e+000,,,,,,,,,,,,,,32,1,4.000000e+000,2.639771e-003,0.000000e+000,0,,0,
1524386512.720,,0.000000e+000,5.499577e+001,3.483786e-006,0.000000e+000,2,4.958151e-001,0.000000e+000,,,,,,,,,,,,,,32,1,4.000000e+000,2.632141e-003,0.000000e+000,0,,0,
1524386549.450,,0.000000e+000,5.499840e+001,3.570318e-006,0.000000e+000,2,5.167194e-001,0.000000e+000,,,,,,,,,,,,,,32,1,4.000000e+000,2.628326e-003,0.000000e+000,0,,0,
1524386587.450,,0.000000e+000,5.499314e+001,3.550207e-006,0.000000e+000,2,5.272288e-001,0.000000e+000,,,,,,,,,,,,,,32,1,4.000000e+000,5.260468e-003,0.000000e+000,0,,0,
1524386625.390,,0.000000e+000,5.500103e+001,3.567562e-006,0.000000e+000,2,5.188113e-001,0.000000e+000,,,,,,,,,,,,,,32,1,4.000000e+000,7.888794e-003,0.000000e+000,0,,0,
1524386663.050,,0.000000e+000,5.499642e+001,3.530341e-006,0.000000e+000,2,5.351279e-001,0.000000e+000,,,,,,,,,,,,,,32,1,4.000000e+000,3.940582e-003,0.000000e+000,0,,0,
1524386700.250,,0.000000e+000,5.499643e+001,3.528402e-006,0.000000e+000,2,5.156879e-001,0.000000e+000,,,,,,,,,,,,,,32,1,4.000000e+000,1.708984e-002,0.000000e+000,0,,0,
1524386738.180,,0.000000e+000,5.499709e+001,3.590240e-006,0.000000e+000,2,5.440372e-001,0.000000e+000,,,,,,,,,,,,,,32,1,4.000000e+000,7.888794e-003,0.000000e+000,0,,0,
1524386775.850,,0.000000e+000,5.500037e+001,3.548789e-006,0.000000e+000,2,5.415121e-001,0.000000e+000,,,,,,,,,,,,,,32,1,4.000000e+000,1.319885e-003,0.000000e+000,0,,0,
1524386814.450,,0.000000e+000,5.499773e+001,3.480732e-006,0.000000e+000,2,5.178975e-001,0.000000e+000,,,,,,,,,,,,,,32,1,4.000000e+000,1.308441e-003,0.000000e+000,0,,0,
1524386852.051,,0.000000e+000,5.500235e+001,3.578927e-006,0.000000e+000,2,5.386659e-001,0.000000e+000,,,,,,,,,,,,,,32,1,4.000000e+000,2.639771e-003,0.000000e+000,0,,0,
1524386890.081,,0.000000e+000,5.499839e+001,3.492597e-006,0.000000e+000,2,5.375307e-001,0.000000e+000,,,,,,,,,,,,,,32,1,4.000000e+000,0.000000e+000,0.000000e+000,0,,0,
1524386927.671,,0.000000e+000,5.500761e+001,3.492631e-006,0.000000e+000,2,5.142272e-001,0.000000e+000,,,,,,,,,,,,,,32,1,4.000000e+000,1.052094e-002,0.000000e+000,0,,0,
1524386965.721,,0.000000e+000,5.500366e+001,3.533277e-006,0.000000e+000,2,5.389305e-001,0.000000e+000,,,,,,,,,,,,,,32,1,4.000000e+000,2.620697e-003,0.000000e+000,0,,0,
1524387003.411,,0.000000e+000,5.499643e+001,3.547813e-006,0.000000e+000,2,5.473689e-001,0.000000e+000,,,,,,,,,,,,,,32,1,4.000000e+000,1.312256e-003,0.000000e+000,0,,0,
1524387041.381,,0.000000e+000,5.499971e+001,3.502744e-006,0.000000e+000,2,5.321376e-001,0.000000e+000,,,,,,,,,,,,,,32,1,4.000000e+000,2.639771e-003,0.000000e+000,0,,0,
1524387079.031,,0.000000e+000,5.499840e+001,3.480363e-006,0.000000e+000,2,5.102406e-001,0.000000e+000,,,,,,,,,,,,,,32,1,4.000000e+000,2.628326e-003,0.000000e+000,0,,0,
1524387117.061,,0.000000e+000,5.500103e+001,3.457201e-006,0.000000e+000,2,5.400807e-001,0.000000e+000,,,,,,,,,,,,,,32,1,4.000000e+000,2.639771e-003,0.000000e+000,0,,0,
1524387154.841,,0.000000e+000,5.499905e+001,3.489011e-006,0.000000e+000,2,5.125251e-001,0.000000e+000,,,,,,,,,,,,,,32,1,4.000000e+000,1.446915e-002,0.000000e+000,0,,0,
1524387192.901,,0.000000e+000,5.499445e+001,3.514825e-006,0.000000e+000,2,5.196611e-001,0.000000e+000,,,,,,,,,,,,,,32,1,4.000000e+000,2.628326e-003,0.000000e+000,0,,0,
1524387231.091,,0.000000e+000,5.499642e+001,3.480793e-006,0.000000e+000,2,5.348175e-001,0.000000e+000,,,,,,,,,,,,,,32,1,4.000000e+000,3.940582e-003,0.000000e+000,0,,0,
1524387268.781,,0.000000e+000,5.500037e+001,3.508404e-006,0.000000e+000,2,5.088671e-001,0.000000e+000,,,,,,,,,,,,,,32,1,4.000000e+000,3.959656e-003,0.000000e+000,0,,0,
1524387306.341,,0.000000e+000,5.499905e+001,3.491956e-006,0.000000e+000,2,5.393330e-001,0.000000e+000,,,,,,,,,,,,,,32,1,4.000000e+000,1.319885e-003,0.000000e+000,0,,0,
1524387344.151,,0.000000e+000,5.499708e+001,3.396696e-006,0.000000e+000,2,5.030522e-001,0.000000e+000,,,,,,,,,,,,,,32,1,4.000000e+000,2.620697e-003,0.000000e+000,0,,0,
1524387381.851,,0.000000e+000,5.499379e+001,3.479015e-006,0.000000e+000,2,5.348952e-001,0.000000e+000,,,,,,,,,,,,,,32,1,4.000000e+000,9.201050e-003,0.000000e+000,0,,0,
1524387420.051,,0.000000e+000,5.499972e+001,3.429910e-006,0.000000e+000,2,5.306792e-001,0.000000e+000,,,,,,,,,,,,,,32,1,4.000000e+000,5.268097e-003,0.000000e+000,0,,0,
1524387457.861,,0.000000e+000,5.500366e+001,3.496201e-006,0.000000e+000,2,5.117496e-001,0.000000e+000,,,,,,,,,,,,,,32,1,4.000000e+000,1.578140e-002,0.000000e+000,0,,0,
1524387495.741,,0.000000e+000,5.499380e+001,3.450096e-006,0.000000e+000,2,5.246139e-001,0.000000e+000,,,,,,,,,,,,,,32,1,4.000000e+000,6.572723e-003,0.000000e+000,0,,0,
1524387533.021,,0.000000e+000,5.499248e+001,3.472476e-006,0.000000e+000,2,5.215778e-001,0.000000e+000,,,,,,,,,,,,,,32,1,4.000000e+000,1.319885e-003,0.000000e+000,0,,0,
1524387571.222,,0.000000e+000,5.499839e+001,3.426662e-006,0.000000e+000,2,5.247811e-001,0.000000e+000,,,,,,,,,,,,,,32,1,4.000000e+000,0.000000e+000,0.000000e+000,0,,0,
1524387609.562,,0.000000e+000,5.499774e+001,3.413480e-006,0.000000e+000,2,5.152363e-001,0.000000e+000,,,,,,,,,,,,,,32,1,4.000000e+000,3.940582e-003,0.000000e+000,0,,0,
1524387647.112,,0.000000e+000,5.499774e+001,3.523924e-006,0.000000e+000,2,5.324255e-001,0.000000e+000,,,,,,,,,,,,,,32,1,4.000000e+000,3.940582e-003,0.000000e+000,0,,0,
1524387684.582,,0.000000e+000,5.500103e+001,3.499145e-006,0.000000e+000,2,5.364690e-001,0.000000e+000,,,,,,,,,,,,,,32,1,4.000000e+000,0.000000e+000,0.000000e+000,0,,0,
1524387722.352,,0.000000e+000,5.499774e+001,3.479138e-006,0.000000e+000,2,5.215878e-001,0.000000e+000,,,,,,,,,,,,,,32,1,4.000000e+000,3.940582e-003,0.000000e+000,0,,0,
1524387760.432,,0.000000e+000,5.499773e+001,3.493752e-006,0.000000e+000,2,5.055649e-001,0.000000e+000,,,,,,,,,,,,,,32,1,4.000000e+000,1.308441e-003,0.000000e+000,0,,0,
1524387798.622,,0.000000e+000,5.500103e+001,3.514865e-006,0.000000e+000,2,5.415284e-001,0.000000e+000,,,,,,,,,,,,,,32,1,4.000000e+000,0.000000e+000,0.000000e+000,0,,0,
1524387836.322,,0.000000e+000,5.499906e+001,3.498238e-006,0.000000e+000,2,5.069784e-001,0.000000e+000,,,,,,,,,,,,,,32,1,4.000000e+000,6.580353e-003,0.000000e+000,0,,0,
1524387873.712,,0.000000e+000,5.500168e+001,3.497824e-006,0.000000e+000,2,5.144371e-001,0.000000e+000,,,,,,,,,,,,,,32,1,4.000000e+000,6.580353e-003,0.000000e+000,0,,0,
1524387911.622,,0.000000e+000,5.500169e+001,3.491401e-006,0.000000e+000,2,4.933220e-001,0.000000e+000,,,,,,,,,,,,,,32,1,4.000000e+000,9.208679e-003,0.000000e+000,0,,0,
1524387949.562,,0.000000e+000,5.500235e+001,3.463237e-006,0.000000e+000,2,4.993919e-001,0.000000e+000,,,,,,,,,,,,,,32,1,4.000000e+000,2.639771e-003,0.000000e+000,0,,0,
1524387988.002,,0.000000e+000,5.500103e+001,3.434007e-006,0.000000e+000,2,5.236029e-001,0.000000e+000,,,,,,,,,,,,,,32,1,4.000000e+000,2.639771e-003,0.000000e+000,0,,0,
1524388025.962,,0.000000e+000,5.499182e+001,3.546766e-006,0.000000e+000,2,5.386745e-001,0.000000e+000,,,,,,,,,,,,,,32,1,4.000000e+000,1.052094e-002,0.000000e+000,0,,0,
1524388063.672,,0.000000e+000,5.499643e+001,3.530765e-006,0.000000e+000,2,5.053449e-001,0.000000e+000,,,,,,,,,,,,,,32,1,4.000000e+000,1.312256e-003,0.000000e+000,0,,0,
1524388101.742,,0.000000e+000,5.499905e+001,3.515979e-006,0.000000e+000,2,5.369274e-001,0.000000e+000,,,,,,,,,,,,,,32,1,4.000000e+000,1.319885e-003,0.000000e+000,0,,0,
1524388139.562,,0.000000e+000,5.499445e+001,3.504269e-006,0.000000e+000,2,5.186512e-001,0.000000e+000,,,,,,,,,,,,,,32,1,4.000000e+000,5.260468e-003,0.000000e+000,0,,0,
1524388177.342,,0.000000e+000,5.499445e+001,3.447941e-006,0.000000e+000,2,5.254815e-001,0.000000e+000,,,,,,,,,,,,,,32,1,4.000000e+000,7.881165e-003,0.000000e+000,0,,0,
1524388215.222,,0.000000e+000,5.500234e+001,3.552740e-006,0.000000e+000,2,5.344229e-001,0.000000e+000,,,,,,,,,,,,,,32,1,4.000000e+000,5.260468e-003,0.000000e+000,0,,0,
1524388252.732,,0.000000e+000,5.499971e+001,3.462418e-006,0.000000e+000,2,5.308704e-001,0.000000e+000,,,,,,,,,,,,,,32,1,4.000000e+000,2.639771e-003,0.000000e+000,0,,0,
1524388289.813,,0.000000e+000,5.499708e+001,3.541631e-006,0.000000e+000,2,5.346138e-001,0.000000e+000,,,,,,,,,,,,,,32,1,4.000000e+000,2.620697e-003,0.000000e+000,0,,0,
1524388328.523,,0.000000e+000,5.500234e+001,3.531930e-006,0.000000e+000,2,5.543488e-001,0.000000e+000,,,,,,,,,,,,,,32,1,4.000000e+000,1.578903e-002,0.000000e+000,0,,0,
1524388365.973,,0.000000e+000,5.499709e+001,3.665988e-006,0.000000e+000,2,5.243700e-001,0.000000e+000,,,,,,,,,,,,,,32,1,4.000000e+000,1.052856e-002,0.000000e+000,0,,0,
1524388403.633,,0.000000e+000,5.499709e+001,3.555513e-006,0.000000e+000,2,5.406793e-001,0.000000e+000,,,,,,,,,,,,,,32,1,4.000000e+000,1.052856e-002,0.000000e+000,0,,0,
1524388441.623,,0.000000e+000,5.499380e+001,3.597010e-006,0.000000e+000,2,5.537462e-001,0.000000e+000,,,,,,,,,,,,,,32,1,4.000000e+000,1.308441e-003,0.000000e+000,0,,0,
1524388479.883,,0.000000e+000,5.500169e+001,3.621894e-006,0.000000e+000,2,5.286191e-001,0.000000e+000,,,,,,,,,,,,,,32,1,4.000000e+000,3.959656e-003,0.000000e+000,0,,0,
1524388517.323,,0.000000e+000,5.499841e+001,3.629795e-006,0.000000e+000,2,5.535030e-001,0.000000e+000,,,,,,,,,,,,,,32,1,4.000000e+000,1.052856e-002,0.000000e+000,0,,0,
1524388554.903,,0.000000e+000,5.499117e+001,3.612353e-006,0.000000e+000,2,5.276490e-001,0.000000e+000,,,,,,,,,,,,,,32,1,4.000000e+000,1.312256e-003,0.000000e+000,0,,0,
1524388592.493,,0.000000e+000,5.499971e+001,3.633055e-006,0.000000e+000,2,5.466719e-001,0.000000e+000,,,,,,,,,,,,,,32,1,4.000000e+000,2.639771e-003,0.000000e+000,0,,0,
1524388629.833,,0.000000e+000,5.500037e+001,3.660127e-006,0.000000e+000,2,5.400531e-001,0.000000e+000,,,,,,,,,,,,,,32,1,4.000000e+000,1.319885e-003,0.000000e+000,0,,0,
1524388667.823,,0.000000e+000,5.499906e+001,3.632688e-006,0.000000e+000,2,5.450407e-001,0.000000e+000,,,,,,,,,,,,,,32,1,4.000000e+000,6.580353e-003,0.000000e+000,0,,0,
1524388705.433,,0.000000e+000,5.499643e+001,3.637112e-006,0.000000e+000,2,5.493037e-001,0.000000e+000,,,,,,,,,,,,,,32,1,4.000000e+000,1.184082e-002,0.000000e+000,0,,0,
1524388743.463,,0.000000e+000,5.500103e+001,3.616214e-006,0.000000e+000,2,5.454745e-001,0.000000e+000,,,,,,,,,,,,,,32,1,4.000000e+000,0.000000e+000,0.000000e+000,0,,0,
1524388781.253,,0.000000e+000,5.500037e+001,3.655627e-006,0.000000e+000,2,5.384821e-001,0.000000e+000,,,,,,,,,,,,,,32,1,4.000000e+000,2.499008e-002,0.000000e+000,0,,0,
1524388819.053,,0.000000e+000,5.499971e+001,3.659197e-006,0.000000e+000,2,5.527369e-001,0.000000e+000,,,,,,,,,,,,,,32,1,4.000000e+000,2.639771e-003,0.000000e+000,0,,0,
1524388856.503,,0.000000e+000,5.500432e+001,3.617321e-006,0.000000e+000,2,5.409731e-001,0.000000e+000,,,,,,,,,,,,,,32,1,4.000000e+000,6.580353e-003,0.000000e+000,0,,0,
1524388893.793,,0.000000e+000,5.500432e+001,3.648562e-006,0.000000e+000,2,5.295914e-001,0.000000e+000,,,,,,,,,,,,,,32,1,4.000000e+000,1.300812e-003,0.000000e+000,0,,0,
1524388931.813,,0.000000e+000,5.500366e+001,3.639804e-006,0.000000e+000,2,5.545302e-001,0.000000e+000,,,,,,,,,,,,,,32,1,4.000000e+000,5.260468e-003,0.000000e+000,0,,0,
1524388969.743,,0.000000e+000,5.499971e+001,3.611417e-006,0.000000e+000,2,5.380813e-001,0.000000e+000,,,,,,,,,,,,,,32,1,4.000000e+000,0.000000e+000,0.000000e+000,0,,0,
1524389007.214,,0.000000e+000,5.499577e+001,3.612525e-006,0.000000e+000,2,5.281578e-001,0.000000e+000,,,,,,,,,,,,,,32,1,4.000000e+000,2.632141e-003,0.000000e+000,0,,0,
1524389045.114,,0.000000e+000,5.499708e+001,3.654092e-006,0.000000e+000,2,5.612658e-001,0.000000e+000,,,,,,,,,,,,,,32,1,4.000000e+000,2.620697e-003,0.000000e+000,0,,0,
1524389082.944,,0.000000e+000,5.500103e+001,3.693089e-006,0.000000e+000,2,5.270548e-001,0.000000e+000,,,,,,,,,,,,,,32,1,4.000000e+000,7.888794e-003,0.000000e+000,0,,0,
1524389120.824,,0.000000e+000,5.499840e+001,3.692842e-006,0.000000e+000,2,5.511020e-001,0.000000e+000,,,,,,,,,,,,,,32,1,4.000000e+000,2.628326e-003,0.000000e+000,0,,0,
1524389158.414,,0.000000e+000,5.500037e+001,3.655757e-006,0.000000e+000,2,5.384944e-001,0.000000e+000,,,,,,,,,,,,,,32,1,4.000000e+000,1.184082e-002,0.000000e+000,0,,0,
1524389196.514,,0.000000e+000,5.499642e+001,3.681591e-006,0.000000e+000,2,5.613592e-001,0.000000e+000,,,,,,,,,,,,,,32,1,4.000000e+000,3.940582e-003,0.000000e+000,0,,0,
1524389234.074,,0.000000e+000,5.499774e+001,3.682041e-006,0.000000e+000,2,5.499221e-001,0.000000e+000,,,,,,,,,,,,,,32,1,4.000000e+000,6.580353e-003,0.000000e+000,0,,0,
1524389272.184,,0.000000e+000,5.499577e+001,3.654165e-006,0.000000e+000,2,5.470638e-001,0.000000e+000,,,,,,,,,,,,,,32,1,4.000000e+000,2.632141e-003,0.000000e+000,0,,0,
1524389309.944,,0.000000e+000,5.500169e+001,3.650189e-006,0.000000e+000,2,5.375684e-001,0.000000e+000,,,,,,,,,,,,,,32,1,4.000000e+000,1.446915e-002,0.000000e+000,0,,0,
1524389348.014,,0.000000e+000,5.500234e+001,3.707449e-006,0.000000e+000,2,5.599550e-001,0.000000e+000,,,,,,,,,,,,,,32,1,4.000000e+000,5.260468e-003,0.000000e+000,0,,0,
1524389385.454,,0.000000e+000,5.499248e+001,3.632106e-006,0.000000e+000,2,5.309471e-001,0.000000e+000,,,,,,,,,,,,,,32,1,4.000000e+000,6.580353e-003,0.000000e+000,0,,0,
1524389423.524,,0.000000e+000,5.499708e+001,3.659307e-006,0.000000e+000,2,5.562385e-001,0.000000e+000,,,,,,,,,,,,,,32,1,4.000000e+000,2.620697e-003,0.000000e+000,0,,0,
1524389461.224,,0.000000e+000,5.499708e+001,3.731541e-006,0.000000e+000,2,5.510815e-001,0.000000e+000,,,,,,,,,,,,,,32,1,4.000000e+000,2.620697e-003,0.000000e+000,0,,0,
1524389499.194,,0.000000e+000,5.499643e+001,3.679765e-006,0.000000e+000,2,5.519446e-001,0.000000e+000,,,,,,,,,,,,,,32,1,4.000000e+000,1.184082e-002,0.000000e+000,0,,0,
1524389537.114,,0.000000e+000,5.499708e+001,3.704590e-006,0.000000e+000,2,5.368139e-001,0.000000e+000,,,,,,,,,,,,,,32,1,4.000000e+000,1.578140e-002,0.000000e+000,0,,0,
1524389575.024,,0.000000e+000,5.500168e+001,3.688604e-006,0.000000e+000,2,5.481274e-001,0.000000e+000,,,,,,,,,,,,,,32,1,4.000000e+000,6.580353e-003,0.000000e+000,0,,0,
1524389612.814,,0.000000e+000,5.499971e+001,3.653365e-006,0.000000e+000,2,5.571513e-001,0.000000e+000,,,,,,,,,,,,,,32,1,4.000000e+000,2.639771e-003,0.000000e+000,0,,0,
1524389650.614,,0.000000e+000,5.499512e+001,3.700611e-006,0.000000e+000,2,5.308579e-001,0.000000e+000,,,,,,,,,,,,,,32,1,4.000000e+000,1.710892e-002,0.000000e+000,0,,0,
1524389688.954,,0.000000e+000,5.499511e+001,3.660421e-006,0.000000e+000,2,5.490717e-001,0.000000e+000,,,,,,,,,,,,,,32,1,4.000000e+000,3.940582e-003,0.000000e+000,0,,0,
1524389726.755,,0.000000e+000,5.500300e+001,3.682070e-006,0.000000e+000,2,5.404245e-001,0.000000e+000,,,,,,,,,,,,,,32,1,4.000000e+000,6.580353e-003,0.000000e+000,0,,0,
1524389764.445,,0.000000e+000,5.499905e+001,3.706102e-006,0.000000e+000,2,5.537865e-001,0.000000e+000,,,,,,,,,,,,,,32,1,4.000000e+000,1.319885e-003,0.000000e+000,0,,0,
1524389802.275,,0.000000e+000,5.499642e+001,3.659666e-006,0.000000e+000,2,5.474915e-001,0.000000e+000,,,,,,,,,,,,,,32,1,4.000000e+000,3.940582e-003,0.000000e+000,0,,0,
1524389840.365,,0.000000e+000,5.499971e+001,3.670041e-006,0.000000e+000,2,5.438818e-001,0.000000e+000,,,,,,,,,,,,,,32,1,4.000000e+000,2.639771e-003,0.000000e+000,0,,0,
1524389877.445,,0.000000e+000,5.499511e+001,3.718676e-006,0.000000e+000,2,5.427550e-001,0.000000e+000,,,,,,,,,,,,,,32,1,4.000000e+000,1.319885e-003,0.000000e+000,0,,0,
1524389915.005,,0.000000e+000,5.500037e+001,3.719191e-006,0.000000e+000,2,5.599692e-001,0.000000e+000,,,,,,,,,,,,,,32,1,4.000000e+000,1.319885e-003,0.000000e+000,0,,0,
1524389952.825,,0.000000e+000,5.499774e+001,3.644964e-006,0.000000e+000,2,5.195338e-001,0.000000e+000,,,,,,,,,,,,,,32,1,4.000000e+000,3.940582e-003,0.000000e+000,0,,0,
1524389989.975,,0.000000e+000,5.500103e+001,3.706675e-006,0.000000e+000,2,5.574899e-001,0.000000e+000,,,,,,,,,,,,,,32,1,4.000000e+000,0.000000e+000,0.000000e+000,0,,0,
1524390027.645,,0.000000e+000,5.500037e+001,3.631362e-006,0.000000e+000,2,5.412985e-001,0.000000e+000,,,,,,,,,,,,,,32,1,4.000000e+000,1.446915e-002,0.000000e+000,0,,0,
1524390067.035,,0.000000e+000,5.500497e+001,3.710157e-006,0.000000e+000,2,5.523748e-001,0.000000e+000,,,,,,,,,,,,,,32,1,4.000000e+000,1.578903e-002,0.000000e+000,0,,0,
1524390104.335,,0.000000e+000,5.499840e+001,3.735906e-006,0.000000e+000,2,5.445055e-001,0.000000e+000,,,,,,,,,,,,,,32,1,4.000000e+000,5.260468e-003,0.000000e+000,0,,0,
1524390142.265,,0.000000e+000,5.499182e+001,3.709222e-006,0.000000e+000,2,5.606151e-001,0.000000e+000,,,,,,,,,,,,,,32,1,4.000000e+000,0.000000e+000,0.000000e+000,0,,0,
1524390179.585,,0.000000e+000,5.499051e+001,3.730196e-006,0.000000e+000,2,5.306914e-001,0.000000e+000,,,,,,,,,,,,,,32,1,4.000000e+000,1.052094e-002,0.000000e+000,0,,0,
1524390217.645,,0.000000e+000,5.500168e+001,3.750443e-006,0.000000e+000,2,5.503987e-001,0.000000e+000,,,,,,,,,,,,,,32,1,4.000000e+000,6.580353e-003,0.000000e+000,0,,0,
1524390254.995,,0.000000e+000,5.499248e+001,3.734011e-006,0.000000e+000,2,5.341581e-001,0.000000e+000,,,,,,,,,,,,,,32,1,4.000000e+000,6.580353e-003,0.000000e+000,0,,0,
1524390292.745,,0.000000e+000,5.499511e+001,3.740824e-006,0.000000e+000,2,5.606630e-001,0.000000e+000,,,,,,,,,,,,,,32,1,4.000000e+000,1.319885e-003,0.000000e+000,0,,0,
1524390331.105,,0.000000e+000,5.500169e+001,3.611366e-006,0.000000e+000,2,5.496855e-001,0.000000e+000,,,,,,,,,,,,,,32,1,4.000000e+000,9.208679e-003,0.000000e+000,0,,0,
1524390369.035,,0.000000e+000,5.499773e+001,3.689139e-006,0.000000e+000,2,5.329303e-001,0.000000e+000,,,,,,,,,,,,,,32,1,4.000000e+000,1.308441e-003,0.000000e+000,0,,0,
1524390406.845,,0.000000e+000,5.500103e+001,3.673654e-006,0.000000e+000,2,5.694314e-001,0.000000e+000,,,,,,,,,,,,,,32,1,4.000000e+000,7.888794e-003,0.000000e+000,0,,0,
1524390444.536,,0.000000e+000,5.500037e+001,3.754413e-006,0.000000e+000,2,5.650579e-001,0.000000e+000,,,,,,,,,,,,,,32,1,4.000000e+000,3.959656e-003,0.000000e+000,0,,0,
1524390481.826,,0.000000e+000,5.499577e+001,3.714680e-006,0.000000e+000,2,5.405438e-001,0.000000e+000,,,,,,,,,,,,,,32,1,4.000000e+000,0.000000e+000,0.000000e+000,0,,0,
1524390519.766,,0.000000e+000,5.500103e+001,3.670503e-006,0.000000e+000,2,5.527413e-001,0.000000e+000,,,,,,,,,,,,,,32,1,4.000000e+000,5.279541e-003,0.000000e+000,0,,0,
1524390557.346,,0.000000e+000,5.499773e+001,3.706970e-006,0.000000e+000,2,5.252079e-001,0.000000e+000,,,,,,,,,,,,,,32,1,4.000000e+000,1.308441e-003,0.000000e+000,0,,0,
1524390595.016,,0.000000e+000,5.499182e+001,3.723469e-006,0.000000e+000,2,5.508526e-001,0.000000e+000,,,,,,,,,,,,,,32,1,4.000000e+000,1.052094e-002,0.000000e+000,0,,0,
1524390632.226,,0.000000e+000,5.500300e+001,3.744361e-006,0.000000e+000,2,5.561710e-001,0.000000e+000,,,,,,,,,,,,,,32,1,4.000000e+000,6.580353e-003,0.000000e+000,0,,0,
1524390670.216,,0.000000e+000,5.499775e+001,3.737542e-006,0.000000e+000,2,5.458222e-001,0.000000e+000,,,,,,,,,,,,,,32,1,4.000000e+000,9.208679e-003,0.000000e+000,0,,0,
1524390708.066,,0.000000e+000,5.499445e+001,3.664739e-006,0.000000e+000,2,5.445362e-001,0.000000e+000,,,,,,,,,,,,,,32,1,4.000000e+000,2.628326e-003,0.000000e+000,0,,0,
1524390745.676,,0.000000e+000,5.499445e+001,3.671773e-006,0.000000e+000,2,5.522273e-001,0.000000e+000,,,,,,,,,,,,,,32,1,4.000000e+000,7.881165e-003,0.000000e+000,0,,0,
1524390783.196,,0.000000e+000,5.499774e+001,3.650325e-006,0.000000e+000,2,5.337849e-001,0.000000e+000,,,,,,,,,,,,,,32,1,4.000000e+000,3.940582e-003,0.000000e+000,0,,0,
1524390821.026,,0.000000e+000,5.500563e+001,3.758474e-006,0.000000e+000,2,5.566202e-001,0.000000e+000,,,,,,,,,,,,,,32,1,4.000000e+000,6.568909e-003,0.000000e+000,0,,0,
1524390858.886,,0.000000e+000,5.500169e+001,3.604654e-006,0.000000e+000,2,5.341776e-001,0.000000e+000,,,,,,,,,,,,,,32,1,4.000000e+000,1.446915e-002,0.000000e+000,0,,0,
1524390896.926,,0.000000e+000,5.499577e+001,3.775032e-006,0.000000e+000,2,5.647286e-001,0.000000e+000,,,,,,,,,,,,,,32,1,4.000000e+000,2.632141e-003,0.000000e+000,0,,0,
1524390934.006,,0.000000e+000,5.500103e+001,3.698607e-006,0.000000e+000,2,5.344517e-001,0.000000e+000,,,,,,,,,,,,,,32,1,4.000000e+000,1.052094e-002,0.000000e+000,0,,0,
1524390972.166,,0.000000e+000,5.499445e+001,3.673553e-006,0.000000e+000,2,5.276896e-001,0.000000e+000,,,,,,,,,,,,,,32,1,4.000000e+000,0.000000e+000,0.000000e+000,0,,0,
1524391010.266,,0.000000e+000,5.500037e+001,3.702241e-006,0.000000e+000,2,5.631949e-001,0.000000e+000,,,,,,,,,,,,,,32,1,4.000000e+000,1.319885e-003,0.000000e+000,0,,0,
1524391048.236,,0.000000e+000,5.500037e+001,3.641202e-006,0.000000e+000,2,5.556093e-001,0.000000e+000,,,,,,,,,,,,,,32,1,4.000000e+000,1.319885e-003,0.000000e+000,0,,0,
1524391086.146,,0.000000e+000,5.499906e+001,3.757014e-006,0.000000e+000,2,5.434195e-001,0.000000e+000,,,,,,,,,,,,,,32,1,4.000000e+000,6.580353e-003,0.000000e+000,0,,0,
1524391124.177,,0.000000e+000,5.499709e+001,3.707279e-006,0.000000e+000,2,5.545959e-001,0.000000e+000,,,,,,,,,,,,,,32,1,4.000000e+000,7.888794e-003,0.000000e+000,0,,0,
1524391161.757,,0.000000e+000,5.499445e+001,3.734248e-006,0.000000e+000,2,5.376859e-001,0.000000e+000,,,,,,,,,,,,,,32,1,4.000000e+000,5.260468e-003,0.000000e+000,0,,0,
1524391199.767,,0.000000e+000,5.499839e+001,3.721107e-006,0.000000e+000,2,5.481918e-001,0.000000e+000,,,,,,,,,,,,,,32,1,4.000000e+000,0.000000e+000,0.000000e+000,0,,0,
1524391237.607,,0.000000e+000,5.499839e+001,3.709139e-006,0.000000e+000,2,5.406849e-001,0.000000e+000,,,,,,,,,,,,,,32,1,4.000000e+000,0.000000e+000,0.000000e+000,0,,0,
1524391275.487,,0.000000e+000,5.499511e+001,3.720710e-006,0.000000e+000,2,5.607430e-001,0.000000e+000,,,,,,,,,,,,,,32,1,4.000000e+000,1.319885e-003,0.000000e+000,0,,0,
1524391313.147,,0.000000e+000,5.500169e+001,3.691079e-006,0.000000e+000,2,5.509328e-001,0.000000e+000,,,,,,,,,,,,,,32,1,4.000000e+000,3.959656e-003,0.000000e+000,0,,0,
1524391351.217,,0.000000e+000,5.499643e+001,3.707958e-006,0.000000e+000,2,5.562639e-001,0.000000e+000,,,,,,,,,,,,,,32,1,4.000000e+000,1.312256e-003,0.000000e+000,0,,0,
1524391388.317,,0.000000e+000,5.499182e+001,3.707394e-006,0.000000e+000,2,5.276328e-001,0.000000e+000,,,,,,,,,,,,,,32,1,4.000000e+000,1.578140e-002,0.000000e+000,0,,0,
1524391426.047,,0.000000e+000,5.500103e+001,3.729722e-006,0.000000e+000,2,5.608571e-001,0.000000e+000,,,,,,,,,,,,,,32,1,4.000000e+000,2.639771e-003,0.000000e+000,0,,0,
1524391464.477,,0.000000e+000,5.500037e+001,3.712110e-006,0.000000e+000,2,5.559046e-001,0.000000e+000,,,,,,,,,,,,,,32,1,4.000000e+000,6.587982e-003,0.000000e+000,0,,0,
1524391502.287,,0.000000e+000,5.499906e+001,3.695639e-006,0.000000e+000,2,5.443249e-001,0.000000e+000,,,,,,,,,,,,,,32,1,4.000000e+000,9.220123e-003,0.000000e+000,0,,0,
1524391540.157,,0.000000e+000,5.500169e+001,3.621195e-006,0.000000e+000,2,5.437819e-001,0.000000e+000,,,,,,,,,,,,,,32,1,4.000000e+000,3.959656e-003,0.000000e+000,0,,0,
1524391577.917,,0.000000e+000,5.499445e+001,3.802279e-006,0.000000e+000,2,5.389314e-001,0.000000e+000,,,,,,,,,,,,,,32,1,4.000000e+000,2.628326e-003,0.000000e+000,0,,0,
1524391615.837,,0.000000e+000,5.500563e+001,3.681203e-006,0.000000e+000,2,5.555307e-001,0.000000e+000,,,,,,,,,,,,,,32,1,4.000000e+000,9.208679e-003,0.000000e+000,0,,0,
1524391653.597,,0.000000e+000,5.499774e+001,3.851562e-006,0.000000e+000,2,5.482010e-001,0.000000e+000,,,,,,,,,,,,,,32,1,4.000000e+000,6.580353e-003,0.000000e+000,0,,0,
1524391691.507,,0.000000e+000,5.500037e+001,3.688491e-006,0.000000e+000,2,5.584942e-001,0.000000e+000,,,,,,,,,,,,,,32,1,4.000000e+000,1.319885e-003,0.000000e+000,0,,0,
1524391729.297,,0.000000e+000,5.499906e+001,3.845128e-006,0.000000e+000,2,5.477770e-001,0.000000e+000,,,,,,,,,,,,,,32,1,4.000000e+000,9.220123e-003,0.000000e+000,0,,0,
1524391767.197,,0.000000e+000,5.499972e+001,3.639205e-006,0.000000e+000,2,5.507943e-001,0.000000e+000,,,,,,,,,,,,,,32,1,4.000000e+000,7.900238e-003,0.000000e+000,0,,0,
1524391804.967,,0.000000e+000,5.500234e+001,3.794175e-006,0.000000e+000,2,5.466021e-001,0.000000e+000,,,,,,,,,,,,,,32,1,4.000000e+000,7.900238e-003,0.000000e+000,0,,0,
1524391842.868,,0.000000e+000,5.499839e+001,3.629686e-006,0.000000e+000,2,5.417103e-001,0.000000e+000,,,,,,,,,,,,,,32,1,4.000000e+000,0.000000e+000,0.000000e+000,0,,0,
1524391880.648,,0.000000e+000,5.499643e+001,3.670028e-006,0.000000e+000,2,5.459749e-001,0.000000e+000,,,,,,,,,,,,,,32,1,4.000000e+000,9.208679e-003,0.000000e+000,0,,0,
1524391918.558,,0.000000e+000,5.500037e+001,3.618868e-006,0.000000e+000,2,5.451419e-001,0.000000e+000,,,,,,,,,,,,,,32,1,4.000000e+000,1.446915e-002,0.000000e+000,0,,0,
1524391956.258,,0.000000e+000,5.499775e+001,3.654507e-006,0.000000e+000,2,5.375492e-001,0.000000e+000,,,,,,,,,,,,,,32,1,4.000000e+000,1.972961e-002,0.000000e+000,0,,0,
1524391993.868,,0.000000e+000,5.500037e+001,3.595285e-006,0.000000e+000,2,5.495791e-001,0.000000e+000,,,,,,,,,,,,,,32,1,4.000000e+000,3.959656e-003,0.000000e+000,0,,0,
1524392030.958,,0.000000e+000,5.499643e+001,3.697497e-006,0.000000e+000,2,5.471196e-001,0.000000e+000,,,,,,,,,,,,,,32,1,4.000000e+000,9.208679e-003,0.000000e+000,0,,0,
1524392069.048,,0.000000e+000,5.499971e+001,3.671924e-006,0.000000e+000,2,5.557775e-001,0.000000e+000,,,,,,,,,,,,,,32,1,4.000000e+000,0.000000e+000,0.000000e+000,0,,0,
1524392106.828,,0.000000e+000,5.499840e+001,3.659499e-006,0.000000e+000,2,5.331025e-001,0.000000e+000,,,,,,,,,,,,,,32,1,4.000000e+000,2.894211e-002,0.000000e+000,0,,0,
1524392144.708,,0.000000e+000,5.499971e+001,3.595791e-006,0.000000e+000,2,5.428220e-001,0.000000e+000,,,,,,,,,,,,,,32,1,4.000000e+000,2.639771e-003,0.000000e+000,0,,0,
1524392182.348,,0.000000e+000,5.499709e+001,3.634631e-006,0.000000e+000,2,5.426807e-001,0.000000e+000,,,,,,,,,,,,,,32,1,4.000000e+000,1.316071e-002,0.000000e+000,0,,0,
1524392220.388,,0.000000e+000,5.500169e+001,3.660081e-006,0.000000e+000,2,5.560539e-001,0.000000e+000,,,,,,,,,,,,,,32,1,4.000000e+000,1.319885e-003,0.000000e+000,0,,0,
1524392258.028,,0.000000e+000,5.500432e+001,3.707002e-006,0.000000e+000,2,5.457629e-001,0.000000e+000,,,,,,,,,,,,,,32,1,4.000000e+000,1.300812e-003,0.000000e+000,0,,0,
1524392296.058,,0.000000e+000,5.499971e+001,3.664180e-006,0.000000e+000,2,5.491404e-001,0.000000e+000,,,,,,,,,,,,,,32,1,4.000000e+000,2.639771e-003,0.000000e+000,0,,0,
1524392333.638,,0.000000e+000,5.499577e+001,3.686570e-006,0.000000e+000,2,5.388222e-001,0.000000e+000,,,,,,,,,,,,,,32,1,4.000000e+000,1.052094e-002,0.000000e+000,0,,0,
1524392371.748,,0.000000e+000,5.500103e+001,3.624616e-006,0.000000e+000,2,5.469982e-001,0.000000e+000,,,,,,,,,,,,,,32,1,4.000000e+000,2.639771e-003,0.000000e+000,0,,0,
1524392409.338,,0.000000e+000,5.500563e+001,3.661225e-006,0.000000e+000,2,5.433027e-001,0.000000e+000,,,,,,,,,,,,,,32,1,4.000000e+000,1.319885e-003,0.000000e+000,0,,0,