File: Input_All/TC04-12-01K_VRMac_55K_750s_VRMde_55K.dc.dat
[Header]
TITLE,MPMS DC Measurement
BYAPP,MPMS Measurement,2.1,Summary
FILEOPENTIME, 1524102813.684000 4/18/2018, 7:53:33 PM

INFO, APPNAME, MPMS MultiVu Application, Revision 1.61,  Build 082

INFO, NAME, TC04-12-01K
INFO, WEIGHT, 1.000
INFO, AREA, 1.000
INFO, LENGTH, 1.000
INFO, SHAPE, 0
INFO, COMMENT,
INFO, SEQUENCE FILE: VRMac_55K_750s_VRMde_55K.seq


INFO, BACKGROUND DATA FILE:, None


STARTUPAXIS,X,4,LINEAR,AUTO,0.000000,0.000000
STARTUPAXIS,Y1,5,LINEAR,AUTO,0.000000,0.000000


STARTUPGROUP,Longitudinal
FIELDGROUP,Longitudinal,1,2,3,4,5,6,7,8,9,15,16,17,18,27,28
FIELDGROUP,Transverse,1,2,3,4,10,11,12,13,14,19,20,21,22,27,28

PLOT_APPEARANCE,ALL,HORZ_GRID_ON,VERT_GRID_ON,MARKERS_AND_LINES

[Data]
Time,Comment,Field (Oe),Temperature (K),Long Moment (emu),Long Scan Std Dev,Long Algorithm,Long Reg Fit,Long Percent Error (%),Trans Moment (emu),Trans Scan Std Dev,Trans Algorithm,Trans Reg Fit,Trans Percent Error (%),Long Moment [w/o ABS] (emu),Long Scan Std Dev [w/o ABS],Long Reg Fit [w/o ABS],Long Percent Error [w/o ABS] (%),Trans Moment [w/o ABS] (emu),Trans Scan Std Dev [w/o ABS],Trans Reg Fit [w/o ABS],Trans Percent Error [w/o ABS] (%),Points per Scan,Scans per Measurement,Scan Length (cm),Delta Temp (K),Rot Position (deg),Error,EC Comp. Running,Using ABS,
1524102813.684,,0.000000e+000,5.500037e+001,-9.748572e-006,0.000000e+000,3,9.560798e-001,0.000000e+000,,,,,,,,,,,,,,32,1,4.000000e+000,3.959656e-003,0.000000e+000,0,,0,
1524102826.614,,0.000000e+000,5.499643e+001,-7.910417e-006,0.000000e+000,3,9.670499e-001,0.000000e+000,,,,,,,,,,,,,,32,1,4.000000e+000,6.568909e-003,0.000000e+000,0,,0,
1524102839.084,,0.000000e+000,5.499313e+001,-6.926044e-006,0.000000e+000,3,9.479926e-001,0.000000e+000,,,,,,,,,,,,,,32,1,4.000000e+000,2.628326e-003,0.000000e+000,0,,0,
1524102851.764,,0.000000e+000,5.499840e+001,-5.918645e-006,0.000000e+000,3,9.414943e-001,0.000000e+000,,,,,,,,,,,,,,32,1,4.000000e+000,7.900238e-003,0.000000e+000,0,,0,
1524102864.454,,0.000000e+000,5.499577e+001,-5.337447e-006,0.000000e+000,3,9.321430e-001,0.000000e+000,,,,,,,,,,,,,,32,1,4.000000e+000,2.632141e-003,0.000000e+000,0,,0,
1524102877.014,,0.000000e+000,5.499708e+001,-4.798180e-006,0.000000e+000,3,9.488272e-001,0.000000e+000,,,,,,,,,,,,,,32,1,4.000000e+000,5.260468e-003,0.000000e+000,0,,0,
1524102889.664,,0.000000e+000,5.499380e+001,-4.450550e-006,0.000000e+000,3,9.163471e-001,0.000000e+000,,,,,,,,,,,,,,32,1,4.000000e+000,3.948212e-003,0.000000e+000,0,,0,
1524102902.374,,0.000000e+000,5.500103e+001,-3.998157e-006,0.000000e+000,3,9.092872e-001,0.000000e+000,,,,,,,,,,,,,,32,1,4.000000e+000,1.577759e-002,0.000000e+000,0,,0,
1524102915.124,,0.000000e+000,5.500694e+001,-3.670020e-006,0.000000e+000,3,9.025383e-001,0.000000e+000,,,,,,,,,,,,,,32,1,4.000000e+000,3.948212e-003,0.000000e+000,0,,0,
1524102927.714,,0.000000e+000,5.500037e+001,-3.383615e-006,0.000000e+000,3,8.902340e-001,0.000000e+000,,,,,,,,,,,,,,32,1,4.000000e+000,9.201050e-003,0.000000e+000,0,,0,
1524102941.264,,0.000000e+000,5.499906e+001,-3.129469e-006,0.000000e+000,3,8.870623e-001,0.000000e+000,,,,,,,,,,,,,,32,1,4.000000e+000,6.580353e-003,0.000000e+000,0,,0,
1524102953.644,,0.000000e+000,5.499445e+001,-3.044886e-006,0.000000e+000,3,8.822661e-001,0.000000e+000,,,,,,,,,,,,,,32,1,4.000000e+000,2.628326e-003,0.000000e+000,0,,0,
1524102966.294,,0.000000e+000,5.500431e+001,-2.802519e-006,0.000000e+000,3,8.826804e-001,0.000000e+000,,,,,,,,,,,,,,32,1,4.000000e+000,1.184845e-002,0.000000e+000,0,,0,
1524102978.714,,0.000000e+000,5.499840e+001,-2.716467e-006,0.000000e+000,3,8.652345e-001,0.000000e+000,,,,,,,,,,,,,,32,1,4.000000e+000,2.628326e-003,0.000000e+000,0,,0,
1524102991.504,,0.000000e+000,5.499708e+001,-2.460348e-006,0.000000e+000,3,8.475626e-001,0.000000e+000,,,,,,,,,,,,,,32,1,4.000000e+000,5.260468e-003,0.000000e+000,0,,0,
1524103003.914,,0.000000e+000,5.499642e+001,-2.508064e-006,0.000000e+000,3,8.467389e-001,0.000000e+000,,,,,,,,,,,,,,32,1,4.000000e+000,3.940582e-003,0.000000e+000,0,,0,
1524103016.654,,0.000000e+000,5.499708e+001,-2.326306e-006,0.000000e+000,3,8.293658e-001,0.000000e+000,,,,,,,,,,,,,,32,1,4.000000e+000,0.000000e+000,0.000000e+000,0,,0,
1524103031.214,,0.000000e+000,5.499511e+001,-7.147073e-007,0.000000e+000,2,0.000000e+000,0.000000e+000,,,,,,,,,,,,,,32,1,4.000000e+000,3.940582e-003,0.000000e+000,0,,0,
1524103044.996,,0.000000e+000,5.499577e+001,-4.989917e-007,0.000000e+000,2,0.000000e+000,0.000000e+000,,,,,,,,,,,,,,32,1,4.000000e+000,5.249023e-003,0.000000e+000,0,,0,
1524103059.478,,0.000000e+000,5.499773e+001,-3.230370e-007,0.000000e+000,2,0.000000e+000,0.000000e+000,,,,,,,,,,,,,,32,1,4.000000e+000,1.308441e-003,0.000000e+000,0,,0,
1524103071.938,,0.000000e+000,5.500761e+001,2.127559e-006,0.000000e+000,3,6.214691e-001,0.000000e+000,,,,,,,,,,,,,,32,1,4.000000e+000,1.052094e-002,0.000000e+000,0,,0,
1524103084.678,,0.000000e+000,5.499840e+001,2.227940e-006,0.000000e+000,3,6.402184e-001,0.000000e+000,,,,,,,,,,,,,,32,1,4.000000e+000,2.628326e-003,0.000000e+000,0,,0,
1524103097.268,,0.000000e+000,5.499577e+001,-2.366531e-006,0.000000e+000,3,7.693861e-001,0.000000e+000,,,,,,,,,,,,,,32,1,4.000000e+000,2.632141e-003,0.000000e+000,0,,0,
1524103112.250,,0.000000e+000,5.500235e+001,3.744311e-008,0.000000e+000,2,0.000000e+000,0.000000e+000,,,,,,,,,,,,,,32,1,4.000000e+000,1.052856e-002,0.000000e+000,0,,0,
1524103124.720,,0.000000e+000,5.499445e+001,-2.458672e-006,0.000000e+000,3,7.523110e-001,0.000000e+000,,,,,,,,,,,,,,32,1,4.000000e+000,1.314926e-002,0.000000e+000,0,,0,
1524103138.662,,0.000000e+000,5.499971e+001,3.282326e-007,0.000000e+000,2,0.000000e+000,0.000000e+000,,,,,,,,,,,,,,32,1,4.000000e+000,2.639771e-003,0.000000e+000,0,,0,
1524103153.044,,0.000000e+000,5.499708e+001,4.727014e-007,0.000000e+000,2,0.000000e+000,0.000000e+000,,,,,,,,,,,,,,32,1,4.000000e+000,5.260468e-003,0.000000e+000,0,,0,
1524103167.166,,0.000000e+000,5.500366e+001,5.519508e-007,0.000000e+000,2,0.000000e+000,0.000000e+000,,,,,,,,,,,,,,32,1,4.000000e+000,5.260468e-003,0.000000e+000,0,,0,
1524103181.548,,0.000000e+000,5.499512e+001,5.726519e-007,0.000000e+000,2,0.000000e+000,0.000000e+000,,,,,,,,,,,,,,32,1,4.000000e+000,1.710892e-002,0.000000e+000,0,,0,
1524103196.340,,0.000000e+000,5.499906e+001,6.022550e-007,0.000000e+000,2,0.000000e+000,0.000000e+000,,,,,,,,,,,,,,32,1,4.000000e+000,9.220123e-003,0.000000e+000,0,,0,
1524103208.750,,0.000000e+000,5.500234e+001,2.122540e-006,0.000000e+000,3,7.011726e-001,0.000000e+000,,,,,,,,,,,,,,32,1,4.000000e+000,5.260468e-003,0.000000e+000,0,,0,
1524103221.050,,0.000000e+000,5.499774e+001,2.048572e-006,0.000000e+000,3,6.730191e-001,0.000000e+000,,,,,,,,,,,,,,32,1,4.000000e+000,6.580353e-003,0.000000e+000,0,,0,
1524103233.440,,0.000000e+000,5.499905e+001,2.117388e-006,0.000000e+000,3,7.278807e-001,0.000000e+000,,,,,,,,,,,,,,32,1,4.000000e+000,3.948212e-003,0.000000e+000,0,,0,
1524103246.100,,0.000000e+000,5.499379e+001,2.172393e-006,0.000000e+000,3,7.204822e-001,0.000000e+000,,,,,,,,,,,,,,32,1,4.000000e+000,9.201050e-003,0.000000e+000,0,,0,
1524103258.720,,0.000000e+000,5.499445e+001,2.145156e-006,0.000000e+000,3,7.115995e-001,0.000000e+000,,,,,,,,,,,,,,32,1,4.000000e+000,7.881165e-003,0.000000e+000,0,,0,
1524103271.270,,0.000000e+000,5.499577e+001,2.267667e-006,0.000000e+000,3,7.184687e-001,0.000000e+000,,,,,,,,,,,,,,32,1,4.000000e+000,2.632141e-003,0.000000e+000,0,,0,
1524103283.820,,0.000000e+000,5.499445e+001,2.243121e-006,0.000000e+000,3,7.218383e-001,0.000000e+000,,,,,,,,,,,,,,32,1,4.000000e+000,2.628326e-003,0.000000e+000,0,,0,
1524103296.070,,0.000000e+000,5.499643e+001,2.322356e-006,0.000000e+000,3,7.188938e-001,0.000000e+000,,,,,,,,,,,,,,32,1,4.000000e+000,1.312256e-003,0.000000e+000,0,,0,
1524103308.680,,0.000000e+000,5.499708e+001,2.256956e-006,0.000000e+000,3,7.501643e-001,0.000000e+000,,,,,,,,,,,,,,32,1,4.000000e+000,2.620697e-003,0.000000e+000,0,,0,
1524103321.160,,0.000000e+000,5.500103e+001,2.300190e-006,0.000000e+000,3,7.297508e-001,0.000000e+000,,,,,,,,,,,,,,32,1,4.000000e+000,5.279541e-003,0.000000e+000,0,,0,
1524103333.880,,0.000000e+000,5.499773e+001,2.275286e-006,0.000000e+000,3,7.540250e-001,0.000000e+000,,,,,,,,,,,,,,32,1,4.000000e+000,1.308441e-003,0.000000e+000,0,,0,
1524103346.340,,0.000000e+000,5.499905e+001,2.370557e-006,0.000000e+000,3,7.358791e-001,0.000000e+000,,,,,,,,,,,,,,32,1,4.000000e+000,3.948212e-003,0.000000e+000,0,,0,
1524103359.080,,0.000000e+000,5.499248e+001,2.329416e-006,0.000000e+000,3,7.689137e-001,0.000000e+000,,,,,,,,,,,,,,32,1,4.000000e+000,1.319885e-003,0.000000e+000,0,,0,
1524103371.550,,0.000000e+000,5.499314e+001,2.401217e-006,0.000000e+000,3,7.560945e-001,0.000000e+000,,,,,,,,,,,,,,32,1,4.000000e+000,5.260468e-003,0.000000e+000,0,,0,
1524103384.310,,0.000000e+000,5.499840e+001,2.379005e-006,0.000000e+000,3,7.872558e-001,0.000000e+000,,,,,,,,,,,,,,32,1,4.000000e+000,7.900238e-003,0.000000e+000,0,,0,
1524103396.720,,0.000000e+000,5.499775e+001,2.479149e-006,0.000000e+000,3,7.541525e-001,0.000000e+000,,,,,,,,,,,,,,32,1,4.000000e+000,1.184845e-002,0.000000e+000,0,,0,
1524103409.510,,0.000000e+000,5.499840e+001,2.468201e-006,0.000000e+000,3,7.817066e-001,0.000000e+000,,,,,,,,,,,,,,32,1,4.000000e+000,7.900238e-003,0.000000e+000,0,,0,
1524103421.951,,0.000000e+000,5.500103e+001,2.582569e-006,0.000000e+000,3,7.742268e-001,0.000000e+000,,,,,,,,,,,,,,32,1,4.000000e+000,1.052094e-002,0.000000e+000,0,,0,
1524103434.621,,0.000000e+000,5.499642e+001,2.513176e-006,0.000000e+000,3,7.991671e-001,0.000000e+000,,,,,,,,,,,,,,32,1,4.000000e+000,3.940582e-003,0.000000e+000,0,,0,
1524103446.761,,0.000000e+000,5.499380e+001,2.548180e-006,0.000000e+000,3,7.873223e-001,0.000000e+000,,,,,,,,,,,,,,32,1,4.000000e+000,3.948212e-003,0.000000e+000,0,,0,
1524103459.341,,0.000000e+000,5.499313e+001,2.523904e-006,0.000000e+000,3,7.965072e-001,0.000000e+000,,,,,,,,,,,,,,32,1,4.000000e+000,1.314926e-002,0.000000e+000,0,,0,
1524103471.841,,0.000000e+000,5.500037e+001,2.632805e-006,0.000000e+000,3,7.674395e-001,0.000000e+000,,,,,,,,,,,,,,32,1,4.000000e+000,1.319885e-003,0.000000e+000,0,,0,
1524103484.561,,0.000000e+000,5.499905e+001,2.600172e-006,0.000000e+000,3,8.017921e-001,0.000000e+000,,,,,,,,,,,,,,32,1,4.000000e+000,3.948212e-003,0.000000e+000,0,,0,
1524103497.041,,0.000000e+000,5.500037e+001,2.697660e-006,0.000000e+000,3,7.609131e-001,0.000000e+000,,,,,,,,,,,,,,32,1,4.000000e+000,1.319885e-003,0.000000e+000,0,,0,
1524103509.781,,0.000000e+000,5.499971e+001,2.646892e-006,0.000000e+000,3,8.088403e-001,0.000000e+000,,,,,,,,,,,,,,32,1,4.000000e+000,2.639771e-003,0.000000e+000,0,,0,
1524103522.251,,0.000000e+000,5.499708e+001,2.705806e-006,0.000000e+000,3,7.917343e-001,0.000000e+000,,,,,,,,,,,,,,32,1,4.000000e+000,5.260468e-003,0.000000e+000,0,,0,
1524103534.981,,0.000000e+000,5.499840e+001,2.695201e-006,0.000000e+000,3,8.131015e-001,0.000000e+000,,,,,,,,,,,,,,32,1,4.000000e+000,2.628326e-003,0.000000e+000,0,,0,
1524103547.391,,0.000000e+000,5.499905e+001,2.756340e-006,0.000000e+000,3,7.992426e-001,0.000000e+000,,,,,,,,,,,,,,32,1,4.000000e+000,1.319885e-003,0.000000e+000,0,,0,
1524103560.311,,0.000000e+000,5.499445e+001,2.740238e-006,0.000000e+000,3,8.096225e-001,0.000000e+000,,,,,,,,,,,,,,32,1,4.000000e+000,0.000000e+000,0.000000e+000,0,,0,
1524103572.681,,0.000000e+000,5.499642e+001,2.726907e-006,0.000000e+000,3,8.305581e-001,0.000000e+000,,,,,,,,,,,,,,32,1,4.000000e+000,3.940582e-003,0.000000e+000,0,,0,
1524103585.351,,0.000000e+000,5.499445e+001,2.772492e-006,0.000000e+000,3,8.150843e-001,0.000000e+000,,,,,,,,,,,,,,32,1,4.000000e+000,7.881165e-003,0.000000e+000,0,,0,
1524103598.221,,0.000000e+000,5.499643e+001,2.754071e-006,0.000000e+000,3,8.312076e-001,0.000000e+000,,,,,,,,,,,,,,32,1,4.000000e+000,1.184082e-002,0.000000e+000,0,,0,
1524103610.791,,0.000000e+000,5.499840e+001,2.825688e-006,0.000000e+000,3,8.119056e-001,0.000000e+000,,,,,,,,,,,,,,32,1,4.000000e+000,7.900238e-003,0.000000e+000,0,,0,
1524103623.731,,0.000000e+000,5.499774e+001,2.814042e-006,0.000000e+000,3,8.354151e-001,0.000000e+000,,,,,,,,,,,,,,32,1,4.000000e+000,3.940582e-003,0.000000e+000,0,,0,
1524103636.191,,0.000000e+000,5.500037e+001,2.872649e-006,0.000000e+000,3,8.193280e-001,0.000000e+000,,,,,,,,,,,,,,32,1,4.000000e+000,1.319885e-003,0.000000e+000,0,,0,
1524103648.941,,0.000000e+000,5.500037e+001,2.839079e-006,0.000000e+000,3,8.328681e-001,0.000000e+000,,,,,,,,,,,,,,32,1,4.000000e+000,1.319885e-003,0.000000e+000,0,,0,
1524103661.391,,0.000000e+000,5.499905e+001,2.950964e-006,0.000000e+000,3,8.162136e-001,0.000000e+000,,,,,,,,,,,,,,32,1,4.000000e+000,1.319885e-003,0.000000e+000,0,,0,
1524103674.181,,0.000000e+000,5.499708e+001,2.926716e-006,0.000000e+000,3,8.248779e-001,0.000000e+000,,,,,,,,,,,,,,32,1,4.000000e+000,2.620697e-003,0.000000e+000,0,,0,
1524103686.791,,0.000000e+000,5.499380e+001,2.958166e-006,0.000000e+000,3,8.508520e-001,0.000000e+000,,,,,,,,,,,,,,32,1,4.000000e+000,6.572723e-003,0.000000e+000,0,,0,
1524103699.571,,0.000000e+000,5.499906e+001,2.896423e-006,0.000000e+000,3,8.390648e-001,0.000000e+000,,,,,,,,,,,,,,32,1,4.000000e+000,6.580353e-003,0.000000e+000,0,,0,
1524103712.131,,0.000000e+000,5.499380e+001,2.923682e-006,0.000000e+000,3,8.516311e-001,0.000000e+000,,,,,,,,,,,,,,32,1,4.000000e+000,1.308441e-003,0.000000e+000,0,,0,
1524103724.711,,0.000000e+000,5.499840e+001,2.927811e-006,0.000000e+000,3,8.348194e-001,0.000000e+000,,,,,,,,,,,,,,32,1,4.000000e+000,2.628326e-003,0.000000e+000,0,,0,
1524103737.831,,0.000000e+000,5.499840e+001,2.909687e-006,0.000000e+000,3,8.566300e-001,0.000000e+000,,,,,,,,,,,,,,32,1,4.000000e+000,2.628326e-003,0.000000e+000,0,,0,
1524103749.611,,0.000000e+000,5.499380e+001,2.923682e-006,0.000000e+000,3,8.571720e-001,0.000000e+000,,,,,,,,,,,,,,32,1,4.000000e+000,6.572723e-003,0.000000e+000,0,,0,
1524103762.201,,0.000000e+000,5.499248e+001,3.029931e-006,0.000000e+000,3,8.532141e-001,0.000000e+000,,,,,,,,,,,,,,32,1,4.000000e+000,3.940582e-003,0.000000e+000,0,,0,
1524103774.461,,0.000000e+000,5.499511e+001,2.938647e-006,0.000000e+000,3,8.330148e-001,0.000000e+000,,,,,,,,,,,,,,32,1,4.000000e+000,1.319885e-003,0.000000e+000,0,,0,
1524103786.611,,0.000000e+000,5.499709e+001,3.086887e-006,0.000000e+000,3,8.386075e-001,0.000000e+000,,,,,,,,,,,,,,32,1,4.000000e+000,1.052856e-002,0.000000e+000,0,,0,
1524103799.071,,0.000000e+000,5.499511e+001,3.063977e-006,0.000000e+000,3,8.719054e-001,0.000000e+000,,,,,,,,,,,,,,32,1,4.000000e+000,1.319885e-003,0.000000e+000,0,,0,
1524103811.751,,0.000000e+000,5.500234e+001,3.135394e-006,0.000000e+000,3,8.455929e-001,0.000000e+000,,,,,,,,,,,,,,32,1,4.000000e+000,5.260468e-003,0.000000e+000,0,,0,
1524103824.461,,0.000000e+000,5.499774e+001,3.031672e-006,0.000000e+000,3,8.662637e-001,0.000000e+000,,,,,,,,,,,,,,32,1,4.000000e+000,1.446152e-002,0.000000e+000,0,,0,
1524103836.851,,0.000000e+000,5.499775e+001,3.080333e-006,0.000000e+000,3,8.601022e-001,0.000000e+000,,,,,,,,,,,,,,32,1,4.000000e+000,1.184845e-002,0.000000e+000,0,,0,
1524103849.551,,0.000000e+000,5.499839e+001,3.110416e-006,0.000000e+000,3,8.552818e-001,0.000000e+000,,,,,,,,,,,,,,32,1,4.000000e+000,0.000000e+000,0.000000e+000,0,,0,
1524103862.321,,0.000000e+000,5.499971e+001,3.108073e-006,0.000000e+000,3,8.626153e-001,0.000000e+000,,,,,,,,,,,,,,32,1,4.000000e+000,2.639771e-003,0.000000e+000,0,,0,
1524103874.841,,0.000000e+000,5.500037e+001,3.117924e-006,0.000000e+000,3,8.519823e-001,0.000000e+000,,,,,,,,,,,,,,32,1,4.000000e+000,1.319885e-003,0.000000e+000,0,,0,
1524103887.381,,0.000000e+000,5.499708e+001,3.096781e-006,0.000000e+000,3,8.839918e-001,0.000000e+000,,,,,,,,,,,,,,32,1,4.000000e+000,0.000000e+000,0.000000e+000,0,,0,
1524103899.751,,0.000000e+000,5.499577e+001,3.199103e-006,0.000000e+000,3,8.481969e-001,0.000000e+000,,,,,,,,,,,,,,32,1,4.000000e+000,2.632141e-003,0.000000e+000,0,,0,
1524103912.371,,0.000000e+000,5.499445e+001,3.100072e-006,0.000000e+000,3,8.830568e-001,0.000000e+000,,,,,,,,,,,,,,32,1,4.000000e+000,2.628326e-003,0.000000e+000,0,,0,
1524103924.871,,0.000000e+000,5.500169e+001,3.198547e-006,0.000000e+000,3,8.347369e-001,0.000000e+000,,,,,,,,,,,,,,32,1,4.000000e+000,9.208679e-003,0.000000e+000,0,,0,
1524103937.721,,0.000000e+000,5.500037e+001,3.142162e-006,0.000000e+000,3,8.541975e-001,0.000000e+000,,,,,,,,,,,,,,32,1,4.000000e+000,1.319885e-003,0.000000e+000,0,,0,
1524103950.111,,0.000000e+000,5.499841e+001,3.215488e-006,0.000000e+000,3,8.768344e-001,0.000000e+000,,,,,,,,,,,,,,32,1,4.000000e+000,1.052856e-002,0.000000e+000,0,,0,
1524103962.941,,0.000000e+000,5.499642e+001,3.182026e-006,0.000000e+000,3,8.547347e-001,0.000000e+000,,,,,,,,,,,,,,32,1,4.000000e+000,3.940582e-003,0.000000e+000,0,,0,
1524103975.081,,0.000000e+000,5.499511e+001,3.158398e-006,0.000000e+000,3,8.418174e-001,0.000000e+000,,,,,,,,,,,,,,32,1,4.000000e+000,6.568909e-003,0.000000e+000,0,,0,
1524103988.631,,0.000000e+000,5.499906e+001,3.184462e-006,0.000000e+000,3,8.621249e-001,0.000000e+000,,,,,,,,,,,,,,32,1,4.000000e+000,9.220123e-003,0.000000e+000,0,,0,
1524104000.761,,0.000000e+000,5.499708e+001,3.097285e-006,0.000000e+000,3,8.509209e-001,0.000000e+000,,,,,,,,,,,,,,32,1,4.000000e+000,2.620697e-003,0.000000e+000,0,,0,
1524104013.881,,0.000000e+000,5.499774e+001,3.202392e-006,0.000000e+000,3,8.606694e-001,0.000000e+000,,,,,,,,,,,,,,32,1,4.000000e+000,3.940582e-003,0.000000e+000,0,,0,
1524104025.921,,0.000000e+000,5.499905e+001,3.341925e-006,0.000000e+000,3,8.773122e-001,0.000000e+000,,,,,,,,,,,,,,32,1,4.000000e+000,1.319885e-003,0.000000e+000,0,,0,
1524104038.491,,0.000000e+000,5.499248e+001,3.294061e-006,0.000000e+000,3,8.954924e-001,0.000000e+000,,,,,,,,,,,,,,32,1,4.000000e+000,1.182938e-002,0.000000e+000,0,,0,
1524104051.011,,0.000000e+000,5.499643e+001,3.285770e-006,0.000000e+000,3,8.514806e-001,0.000000e+000,,,,,,,,,,,,,,32,1,4.000000e+000,1.312256e-003,0.000000e+000,0,,0,
1524104063.911,,0.000000e+000,5.500300e+001,3.239146e-006,0.000000e+000,3,8.818797e-001,0.000000e+000,,,,,,,,,,,,,,32,1,4.000000e+000,6.580353e-003,0.000000e+000,0,,0,
1524104077.191,,0.000000e+000,5.500234e+001,3.287106e-006,0.000000e+000,3,8.730165e-001,0.000000e+000,,,,,,,,,,,,,,32,1,4.000000e+000,7.900238e-003,0.000000e+000,0,,0,
1524104089.931,,0.000000e+000,5.499839e+001,3.292944e-006,0.000000e+000,3,8.558426e-001,0.000000e+000,,,,,,,,,,,,,,32,1,4.000000e+000,0.000000e+000,0.000000e+000,0,,0,
1524104102.511,,0.000000e+000,5.499117e+001,3.244774e-006,0.000000e+000,3,8.763525e-001,0.000000e+000,,,,,,,,,,,,,,32,1,4.000000e+000,1.312256e-003,0.000000e+000,0,,0,
1524104115.021,,0.000000e+000,5.499577e+001,3.303377e-006,0.000000e+000,3,8.589209e-001,0.000000e+000,,,,,,,,,,,,,,32,1,4.000000e+000,1.052094e-002,0.000000e+000,0,,0,
1524104127.861,,0.000000e+000,5.499642e+001,3.304848e-006,0.000000e+000,3,8.773481e-001,0.000000e+000,,,,,,,,,,,,,,32,1,4.000000e+000,3.940582e-003,0.000000e+000,0,,0,
1524104140.012,,0.000000e+000,5.499445e+001,3.336635e-006,0.000000e+000,3,8.696051e-001,0.000000e+000,,,,,,,,,,,,,,32,1,4.000000e+000,5.260468e-003,0.000000e+000,0,,0,
1524104152.522,,0.000000e+000,5.499840e+001,3.308077e-006,0.000000e+000,3,8.814628e-001,0.000000e+000,,,,,,,,,,,,,,32,1,4.000000e+000,5.260468e-003,0.000000e+000,0,,0,
1524104164.872,,0.000000e+000,5.499839e+001,3.388993e-006,0.000000e+000,3,8.603454e-001,0.000000e+000,,,,,,,,,,,,,,32,1,4.000000e+000,0.000000e+000,0.000000e+000,0,,0,
1524104177.532,,0.000000e+000,5.499642e+001,3.268629e-006,0.000000e+000,3,8.861521e-001,0.000000e+000,,,,,,,,,,,,,,32,1,4.000000e+000,3.940582e-003,0.000000e+000,0,,0,
1524104189.892,,0.000000e+000,5.500103e+001,3.341591e-006,0.000000e+000,3,8.899215e-001,0.000000e+000,,,,,,,,,,,,,,32,1,4.000000e+000,5.279541e-003,0.000000e+000,0,,0,
1524104202.642,,0.000000e+000,5.500301e+001,3.357254e-006,0.000000e+000,3,8.604400e-001,0.000000e+000,,,,,,,,,,,,,,32,1,4.000000e+000,1.319885e-003,0.000000e+000,0,,0,
1524104215.282,,0.000000e+000,5.499840e+001,3.264286e-006,0.000000e+000,3,8.808986e-001,0.000000e+000,,,,,,,,,,,,,,32,1,4.000000e+000,7.900238e-003,0.000000e+000,0,,0,
1524104227.882,,0.000000e+000,5.499708e+001,3.341283e-006,0.000000e+000,3,8.719545e-001,0.000000e+000,,,,,,,,,,,,,,32,1,4.000000e+000,5.260468e-003,0.000000e+000,0,,0,
1524104240.502,,0.000000e+000,5.499906e+001,3.344986e-006,0.000000e+000,3,8.757998e-001,0.000000e+000,,,,,,,,,,,,,,32,1,4.000000e+000,6.580353e-003,0.000000e+000,0,,0,
1524104253.072,,0.000000e+000,5.499445e+001,3.368054e-006,0.000000e+000,3,8.767948e-001,0.000000e+000,,,,,,,,,,,,,,32,1,4.000000e+000,2.628326e-003,0.000000e+000,0,,0,
1524104265.512,,0.000000e+000,5.499511e+001,3.343859e-006,0.000000e+000,3,8.707544e-001,0.000000e+000,,,,,,,,,,,,,,32,1,4.000000e+000,3.940582e-003,0.000000e+000,0,,0,
1524104277.892,,0.000000e+000,5.499773e+001,3.462127e-006,0.000000e+000,3,8.757896e-001,0.000000e+000,,,,,,,,,,,,,,32,1,4.000000e+000,1.308441e-003,0.000000e+000,0,,0,
1524104290.692,,0.000000e+000,5.499577e+001,3.341762e-006,0.000000e+000,3,8.780360e-001,0.000000e+000,,,,,,,,,,,,,,32,1,4.000000e+000,5.249023e-003,0.000000e+000,0,,0,
1524104303.622,,0.000000e+000,5.499314e+001,3.446252e-006,0.000000e+000,3,8.756496e-001,0.000000e+000,,,,,,,,,,,,,,32,1,4.000000e+000,5.260468e-003,0.000000e+000,0,,0,
1524104316.332,,0.000000e+000,5.499841e+001,3.395618e-006,0.000000e+000,3,8.823932e-001,0.000000e+000,,,,,,,,,,,,,,32,1,4.000000e+000,1.052856e-002,0.000000e+000,0,,0,
1524104328.742,,0.000000e+000,5.499445e+001,3.399206e-006,0.000000e+000,3,8.679659e-001,0.000000e+000,,,,,,,,,,,,,,32,1,4.000000e+000,0.000000e+000,0.000000e+000,0,,0,
1524104341.552,,0.000000e+000,5.500564e+001,3.436641e-006,0.000000e+000,3,8.792672e-001,0.000000e+000,,,,,,,,,,,,,,32,1,4.000000e+000,3.940582e-003,0.000000e+000,0,,0,
1524104353.912,,0.000000e+000,5.500103e+001,3.429400e-006,0.000000e+000,3,8.688998e-001,0.000000e+000,,,,,,,,,,,,,,32,1,4.000000e+000,5.279541e-003,0.000000e+000,0,,0,
1524104366.562,,0.000000e+000,5.499774e+001,3.442715e-006,0.000000e+000,3,8.893056e-001,0.000000e+000,,,,,,,,,,,,,,32,1,4.000000e+000,6.580353e-003,0.000000e+000,0,,0,
1524104379.142,,0.000000e+000,5.500103e+001,3.524888e-006,0.000000e+000,3,8.742093e-001,0.000000e+000,,,,,,,,,,,,,,32,1,4.000000e+000,7.888794e-003,0.000000e+000,0,,0,
1524104391.282,,0.000000e+000,5.500103e+001,3.442808e-006,0.000000e+000,3,8.760324e-001,0.000000e+000,,,,,,,,,,,,,,32,1,4.000000e+000,7.888794e-003,0.000000e+000,0,,0,
1524104403.762,,0.000000e+000,5.499972e+001,3.441020e-006,0.000000e+000,3,8.776450e-001,0.000000e+000,,,,,,,,,,,,,,32,1,4.000000e+000,5.268097e-003,0.000000e+000,0,,0,
1524104416.092,,0.000000e+000,5.500037e+001,3.447299e-006,0.000000e+000,3,8.791551e-001,0.000000e+000,,,,,,,,,,,,,,32,1,4.000000e+000,3.959656e-003,0.000000e+000,0,,0,
1524104429.322,,0.000000e+000,5.499905e+001,3.494617e-006,0.000000e+000,3,8.937105e-001,0.000000e+000,,,,,,,,,,,,,,32,1,4.000000e+000,3.948212e-003,0.000000e+000,0,,0,
1524104441.442,,0.000000e+000,5.499840e+001,3.475347e-006,0.000000e+000,3,8.851147e-001,0.000000e+000,,,,,,,,,,,,,,32,1,4.000000e+000,2.628326e-003,0.000000e+000,0,,0,
1524104453.892,,0.000000e+000,5.500300e+001,3.504035e-006,0.000000e+000,3,8.871267e-001,0.000000e+000,,,,,,,,,,,,,,32,1,4.000000e+000,6.580353e-003,0.000000e+000,0,,0,
1524104466.142,,0.000000e+000,5.499642e+001,3.548828e-006,0.000000e+000,3,8.912119e-001,0.000000e+000,,,,,,,,,,,,,,32,1,4.000000e+000,3.940582e-003,0.000000e+000,0,,0,
1524104479.302,,0.000000e+000,5.499511e+001,3.497416e-006,0.000000e+000,3,8.851756e-001,0.000000e+000,,,,,,,,,,,,,,32,1,4.000000e+000,1.319885e-003,0.000000e+000,0,,0,
1524104491.592,,0.000000e+000,5.500103e+001,3.529686e-006,0.000000e+000,3,8.760472e-001,0.000000e+000,,,,,,,,,,,,,,32,1,4.000000e+000,5.279541e-003,0.000000e+000,0,,0,
1524104504.022,,0.000000e+000,5.499972e+001,3.467720e-006,0.000000e+000,3,8.858933e-001,0.000000e+000,,,,,,,,,,,,,,32,1,4.000000e+000,5.268097e-003,0.000000e+000,0,,0,
1524104516.722,,0.000000e+000,5.499643e+001,3.549217e-006,0.000000e+000,3,8.758687e-001,0.000000e+000,,,,,,,,,,,,,,32,1,4.000000e+000,1.312256e-003,0.000000e+000,0,,0,
1524104529.342,,0.000000e+000,5.499840e+001,3.530000e-006,0.000000e+000,3,8.870381e-001,0.000000e+000,,,,,,,,,,,,,,32,1,4.000000e+000,7.900238e-003,0.000000e+000,0,,0,
1524104541.842,,0.000000e+000,5.500169e+001,3.552162e-006,0.000000e+000,3,8.785831e-001,0.000000e+000,,,,,,,,,,,,,,32,1,4.000000e+000,3.959656e-003,0.000000e+000,0,,0,
1524104554.692,,0.000000e+000,5.499840e+001,3.504703e-006,0.000000e+000,3,8.817781e-001,0.000000e+000,,,,,,,,,,,,,,32,1,4.000000e+000,2.628326e-003,0.000000e+000,0,,0,
1524104567.182,,0.000000e+000,5.499643e+001,3.603450e-006,0.000000e+000,3,8.842186e-001,0.000000e+000,,,,,,,,,,,,,,32,1,4.000000e+000,9.208679e-003,0.000000e+000,0,,0,
1524104579.582,,0.000000e+000,5.499840e+001,3.553371e-006,0.000000e+000,3,8.984692e-001,0.000000e+000,,,,,,,,,,,,,,32,1,4.000000e+000,5.260468e-003,0.000000e+000,0,,0,
1524104591.902,,0.000000e+000,5.499313e+001,3.594537e-006,0.000000e+000,3,8.749200e-001,0.000000e+000,,,,,,,,,,,,,,32,1,4.000000e+000,7.892609e-003,0.000000e+000,0,,0,
1524104604.712,,0.000000e+000,5.499972e+001,3.587635e-006,0.000000e+000,3,9.080539e-001,0.000000e+000,,,,,,,,,,,,,,32,1,4.000000e+000,7.900238e-003,0.000000e+000,0,,0,
1524104617.102,,0.000000e+000,5.499905e+001,3.645226e-006,0.000000e+000,3,8.783307e-001,0.000000e+000,,,,,,,,,,,,,,32,1,4.000000e+000,3.948212e-003,0.000000e+000,0,,0,
1524104629.782,,0.000000e+000,5.499840e+001,3.579771e-006,0.000000e+000,3,8.954644e-001,0.000000e+000,,,,,,,,,,,,,,32,1,4.000000e+000,2.628326e-003,0.000000e+000,0,,0,
1524104642.132,,0.000000e+000,5.499708e+001,3.605474e-006,0.000000e+000,3,8.729748e-001,0.000000e+000,,,,,,,,,,,,,,32,1,4.000000e+000,5.260468e-003,0.000000e+000,0,,0,
1524104654.962,,0.000000e+000,5.499905e+001,3.637122e-006,0.000000e+000,3,8.891805e-001,0.000000e+000,,,,,,,,,,,,,,32,1,4.000000e+000,3.948212e-003,0.000000e+000,0,,0,
1524104667.092,,0.000000e+000,5.499972e+001,3.650842e-006,0.000000e+000,3,8.912975e-001,0.000000e+000,,,,,,,,,,,,,,32,1,4.000000e+000,5.268097e-003,0.000000e+000,0,,0,
1524104679.752,,0.000000e+000,5.500103e+001,3.638701e-006,0.000000e+000,3,9.146005e-001,0.000000e+000,,,,,,,,,,,,,,32,1,4.000000e+000,7.888794e-003,0.000000e+000,0,,0,
1524104692.082,,0.000000e+000,5.499380e+001,3.703766e-006,0.000000e+000,3,9.105130e-001,0.000000e+000,,,,,,,,,,,,,,32,1,4.000000e+000,1.308441e-003,0.000000e+000,0,,0,
1524104705.002,,0.000000e+000,5.499841e+001,3.615103e-006,0.000000e+000,3,8.987406e-001,0.000000e+000,,,,,,,,,,,,,,32,1,4.000000e+000,1.052856e-002,0.000000e+000,0,,0,
1524104717.522,,0.000000e+000,5.499577e+001,3.578878e-006,0.000000e+000,3,8.931873e-001,0.000000e+000,,,,,,,,,,,,,,32,1,4.000000e+000,5.249023e-003,0.000000e+000,0,,0,
1524104730.012,,0.000000e+000,5.499642e+001,3.648427e-006,0.000000e+000,3,8.962444e-001,0.000000e+000,,,,,,,,,,,,,,32,1,4.000000e+000,3.940582e-003,0.000000e+000,0,,0,
1524104743.262,,0.000000e+000,5.500300e+001,3.574301e-006,0.000000e+000,3,9.025546e-001,0.000000e+000,,,,,,,,,,,,,,32,1,4.000000e+000,3.940582e-003,0.000000e+000,0,,0,
1524104755.712,,0.000000e+000,5.499709e+001,3.689642e-006,0.000000e+000,3,8.823556e-001,0.000000e+000,,,,,,,,,,,,,,32,1,4.000000e+000,7.888794e-003,0.000000e+000,0,,0,
1524104768.472,,0.000000e+000,5.499577e+001,3.582913e-006,0.000000e+000,3,8.984139e-001,0.000000e+000,,,,,,,,,,,,,,32,1,4.000000e+000,5.249023e-003,0.000000e+000,0,,0,
1524104781.192,,0.000000e+000,5.500234e+001,3.660464e-006,0.000000e+000,3,8.816332e-001,0.000000e+000,,,,,,,,,,,,,,32,1,4.000000e+000,7.900238e-003,0.000000e+000,0,,0,
1524104794.482,,0.000000e+000,5.499445e+001,3.666608e-006,0.000000e+000,3,8.966507e-001,0.000000e+000,,,,,,,,,,,,,,32,1,4.000000e+000,7.881165e-003,0.000000e+000,0,,0,
1524104806.982,,0.000000e+000,5.499773e+001,3.700469e-006,0.000000e+000,3,8.989984e-001,0.000000e+000,,,,,,,,,,,,,,32,1,4.000000e+000,1.308441e-003,0.000000e+000,0,,0,
1524104819.432,,0.000000e+000,5.500037e+001,3.707998e-006,0.000000e+000,3,9.051178e-001,0.000000e+000,,,,,,,,,,,,,,32,1,4.000000e+000,6.587982e-003,0.000000e+000,0,,0,
1524104832.222,,0.000000e+000,5.499643e+001,3.647422e-006,0.000000e+000,3,8.979554e-001,0.000000e+000,,,,,,,,,,,,,,32,1,4.000000e+000,1.312256e-003,0.000000e+000,0,,0,
1524104844.572,,0.000000e+000,5.499708e+001,3.750054e-006,0.000000e+000,3,8.914620e-001,0.000000e+000,,,,,,,,,,,,,,32,1,4.000000e+000,0.000000e+000,0.000000e+000,0,,0,
1524104857.243,,0.000000e+000,5.499972e+001,3.641598e-006,0.000000e+000,3,9.023782e-001,0.000000e+000,,,,,,,,,,,,,,32,1,4.000000e+000,5.268097e-003,0.000000e+000,0,,0,
1524104869.653,,0.000000e+000,5.499906e+001,3.729437e-006,0.000000e+000,3,8.822744e-001,0.000000e+000,,,,,,,,,,,,,,32,1,4.000000e+000,6.580353e-003,0.000000e+000,0,,0,
1524104882.233,,0.000000e+000,5.499840e+001,3.678858e-006,0.000000e+000,3,9.060091e-001,0.000000e+000,,,,,,,,,,,,,,32,1,4.000000e+000,2.628326e-003,0.000000e+000,0,,0,
1524104894.793,,0.000000e+000,5.499774e+001,3.711540e-006,0.000000e+000,3,8.853848e-001,0.000000e+000,,,,,,,,,,,,,,32,1,4.000000e+000,6.580353e-003,0.000000e+000,0,,0,
1524104907.603,,0.000000e+000,5.499972e+001,3.702038e-006,0.000000e+000,3,8.981913e-001,0.000000e+000,,,,,,,,,,,,,,32,1,4.000000e+000,7.900238e-003,0.000000e+000,0,,0,
1524104919.933,,0.000000e+000,5.500169e+001,3.718517e-006,0.000000e+000,3,8.954396e-001,0.000000e+000,,,,,,,,,,,,,,32,1,4.000000e+000,1.184082e-002,0.000000e+000,0,,0,
1524104932.553,,0.000000e+000,5.499840e+001,3.716400e-006,0.000000e+000,3,9.167846e-001,0.000000e+000,,,,,,,,,,,,,,32,1,4.000000e+000,5.260468e-003,0.000000e+000,0,,0,
1524104944.773,,0.000000e+000,5.500234e+001,3.733465e-006,0.000000e+000,3,8.983434e-001,0.000000e+000,,,,,,,,,,,,,,32,1,4.000000e+000,7.900238e-003,0.000000e+000,0,,0,
1524104957.463,,0.000000e+000,5.499313e+001,3.720211e-006,0.000000e+000,3,9.101505e-001,0.000000e+000,,,,,,,,,,,,,,32,1,4.000000e+000,2.628326e-003,0.000000e+000,0,,0,
1524104969.873,,0.000000e+000,5.499511e+001,3.766252e-006,0.000000e+000,3,8.915709e-001,0.000000e+000,,,,,,,,,,,,,,32,1,4.000000e+000,6.568909e-003,0.000000e+000,0,,0,
1524104982.673,,0.000000e+000,5.499840e+001,3.699086e-006,0.000000e+000,3,9.033445e-001,0.000000e+000,,,,,,,,,,,,,,32,1,4.000000e+000,2.628326e-003,0.000000e+000,0,,0,
1524104994.813,,0.000000e+000,5.499577e+001,3.782287e-006,0.000000e+000,3,8.969392e-001,0.000000e+000,,,,,,,,,,,,,,32,1,4.000000e+000,5.249023e-003,0.000000e+000,0,,0,
1524105007.253,,0.000000e+000,5.499972e+001,3.722130e-006,0.000000e+000,3,9.113892e-001,0.000000e+000,,,,,,,,,,,,,,32,1,4.000000e+000,5.268097e-003,0.000000e+000,0,,0,
1524105019.753,,0.000000e+000,5.499972e+001,3.761105e-006,0.000000e+000,3,8.863950e-001,0.000000e+000,,,,,,,,,,,,,,32,1,4.000000e+000,7.900238e-003,0.000000e+000,0,,0,
1524105032.533,,0.000000e+000,5.499840e+001,3.744919e-006,0.000000e+000,3,9.052324e-001,0.000000e+000,,,,,,,,,,,,,,32,1,4.000000e+000,5.260468e-003,0.000000e+000,0,,0,
1524105044.723,,0.000000e+000,5.500432e+001,3.815215e-006,0.000000e+000,3,8.931922e-001,0.000000e+000,,,,,,,,,,,,,,32,1,4.000000e+000,6.580353e-003,0.000000e+000,0,,0,
1524105057.733,,0.000000e+000,5.499905e+001,3.749310e-006,0.000000e+000,3,9.062042e-001,0.000000e+000,,,,,,,,,,,,,,32,1,4.000000e+000,1.446915e-002,0.000000e+000,0,,0,
1524105070.153,,0.000000e+000,5.499839e+001,3.787131e-006,0.000000e+000,3,9.006885e-001,0.000000e+000,,,,,,,,,,,,,,32,1,4.000000e+000,0.000000e+000,0.000000e+000,0,,0,
1524105082.953,,0.000000e+000,5.499971e+001,3.773439e-006,0.000000e+000,3,9.171565e-001,0.000000e+000,,,,,,,,,,,,,,32,1,4.000000e+000,2.639771e-003,0.000000e+000,0,,0,
1524105095.093,,0.000000e+000,5.499117e+001,3.841743e-006,0.000000e+000,3,8.991071e-001,0.000000e+000,,,,,,,,,,,,,,32,1,4.000000e+000,9.208679e-003,0.000000e+000,0,,0,
1524105107.563,,0.000000e+000,5.500037e+001,3.772201e-006,0.000000e+000,3,9.118904e-001,0.000000e+000,,,,,,,,,,,,,,32,1,4.000000e+000,3.959656e-003,0.000000e+000,0,,0,
1524105120.033,,0.000000e+000,5.499971e+001,3.793014e-006,0.000000e+000,3,8.929815e-001,0.000000e+000,,,,,,,,,,,,,,32,1,4.000000e+000,2.639771e-003,0.000000e+000,0,,0,
1524105132.803,,0.000000e+000,5.499709e+001,3.726052e-006,0.000000e+000,3,9.083985e-001,0.000000e+000,,,,,,,,,,,,,,32,1,4.000000e+000,7.888794e-003,0.000000e+000,0,,0,
1524105144.923,,0.000000e+000,5.499248e+001,3.789382e-006,0.000000e+000,3,9.027807e-001,0.000000e+000,,,,,,,,,,,,,,32,1,4.000000e+000,9.201050e-003,0.000000e+000,0,,0,
1524105157.573,,0.000000e+000,5.500037e+001,3.810723e-006,0.000000e+000,3,9.217010e-001,0.000000e+000,,,,,,,,,,,,,,32,1,4.000000e+000,6.587982e-003,0.000000e+000,0,,0,
1524105170.103,,0.000000e+000,5.499773e+001,3.876009e-006,0.000000e+000,3,9.123598e-001,0.000000e+000,,,,,,,,,,,,,,32,1,4.000000e+000,1.308441e-003,0.000000e+000,0,,0,
1524105182.803,,0.000000e+000,5.499708e+001,3.787455e-006,0.000000e+000,3,8.996365e-001,0.000000e+000,,,,,,,,,,,,,,32,1,4.000000e+000,0.000000e+000,0.000000e+000,0,,0,
1524105195.313,,0.000000e+000,5.499577e+001,3.790799e-006,0.000000e+000,3,8.973573e-001,0.000000e+000,,,,,,,,,,,,,,32,1,4.000000e+000,1.052094e-002,0.000000e+000,0,,0,
1524105207.483,,0.000000e+000,5.500103e+001,3.763921e-006,0.000000e+000,3,8.968654e-001,0.000000e+000,,,,,,,,,,,,,,32,1,4.000000e+000,0.000000e+000,0.000000e+000,0,,0,
1524105219.973,,0.000000e+000,5.499445e+001,3.769440e-006,0.000000e+000,3,9.006593e-001,0.000000e+000,,,,,,,,,,,,,,32,1,4.000000e+000,1.052094e-002,0.000000e+000,0,,0,
1524105232.443,,0.000000e+000,5.499840e+001,3.704363e-006,0.000000e+000,3,8.870844e-001,0.000000e+000,,,,,,,,,,,,,,32,1,4.000000e+000,2.628326e-003,0.000000e+000,0,,0,
1524105245.733,,0.000000e+000,5.499972e+001,3.669721e-006,0.000000e+000,3,9.002611e-001,0.000000e+000,,,,,,,,,,,,,,32,1,4.000000e+000,7.900238e-003,0.000000e+000,0,,0,
1524105257.843,,0.000000e+000,5.499840e+001,3.787714e-006,0.000000e+000,3,8.932022e-001,0.000000e+000,,,,,,,,,,,,,,32,1,4.000000e+000,5.260468e-003,0.000000e+000,0,,0,
1524105270.933,,0.000000e+000,5.499971e+001,3.747755e-006,0.000000e+000,3,9.044003e-001,0.000000e+000,,,,,,,,,,,,,,32,1,4.000000e+000,2.639771e-003,0.000000e+000,0,,0,
1524105282.863,,0.000000e+000,5.499839e+001,3.852293e-006,0.000000e+000,3,8.964130e-001,0.000000e+000,,,,,,,,,,,,,,32,1,4.000000e+000,0.000000e+000,0.000000e+000,0,,0,
1524105295.793,,0.000000e+000,5.500103e+001,3.802299e-006,0.000000e+000,3,8.983269e-001,0.000000e+000,,,,,,,,,,,,,,32,1,4.000000e+000,5.279541e-003,0.000000e+000,0,,0,
1524105308.963,,0.000000e+000,5.500037e+001,3.811725e-006,0.000000e+000,3,8.924005e-001,0.000000e+000,,,,,,,,,,,,,,32,1,4.000000e+000,3.959656e-003,0.000000e+000,0,,0,
1524105322.123,,0.000000e+000,5.499511e+001,3.841478e-006,0.000000e+000,3,9.092202e-001,0.000000e+000,,,,,,,,,,,,,,32,1,4.000000e+000,3.940582e-003,0.000000e+000,0,,0,
1524105335.023,,0.000000e+000,5.499840e+001,3.856133e-006,0.000000e+000,3,9.151958e-001,0.000000e+000,,,,,,,,,,,,,,32,1,4.000000e+000,5.260468e-003,0.000000e+000,0,,0,
1524105346.813,,0.000000e+000,5.500169e+001,3.793968e-006,0.000000e+000,3,9.069939e-001,0.000000e+000,,,,,,,,,,,,,,32,1,4.000000e+000,1.184082e-002,0.000000e+000,0,,0,
1524105359.863,,0.000000e+000,5.499906e+001,3.794309e-006,0.000000e+000,3,9.090617e-001,0.000000e+000,,,,,,,,,,,,,,32,1,4.000000e+000,1.710129e-002,0.000000e+000,0,,0,
1524105372.373,,0.000000e+000,5.499445e+001,3.884280e-006,0.000000e+000,3,8.984272e-001,0.000000e+000,,,,,,,,,,,,,,32,1,4.000000e+000,7.881165e-003,0.000000e+000,0,,0,
1524105385.323,,0.000000e+000,5.499708e+001,3.882056e-006,0.000000e+000,3,9.110177e-001,0.000000e+000,,,,,,,,,,,,,,32,1,4.000000e+000,2.620697e-003,0.000000e+000,0,,0,
1524105397.723,,0.000000e+000,5.499577e+001,3.876544e-006,0.000000e+000,3,8.936613e-001,0.000000e+000,,,,,,,,,,,,,,32,1,4.000000e+000,0.000000e+000,0.000000e+000,0,,0,
1524105410.503,,0.000000e+000,5.500103e+001,3.854516e-006,0.000000e+000,3,9.100451e-001,0.000000e+000,,,,,,,,,,,,,,32,1,4.000000e+000,2.639771e-003,0.000000e+000,0,,0,
1524105422.963,,0.000000e+000,5.500169e+001,3.866195e-006,0.000000e+000,3,8.901645e-001,0.000000e+000,,,,,,,,,,,,,,32,1,4.000000e+000,1.446915e-002,0.000000e+000,0,,0,
1524105435.733,,0.000000e+000,5.499840e+001,3.860288e-006,0.000000e+000,3,9.108777e-001,0.000000e+000,,,,,,,,,,,,,,32,1,4.000000e+000,5.260468e-003,0.000000e+000,0,,0,
1524105448.183,,0.000000e+000,5.499971e+001,3.897480e-006,0.000000e+000,3,9.013339e-001,0.000000e+000,,,,,,,,,,,,,,32,1,4.000000e+000,2.639771e-003,0.000000e+000,0,,0,
1524105460.933,,0.000000e+000,5.499577e+001,3.877653e-006,0.000000e+000,3,9.164488e-001,0.000000e+000,,,,,,,,,,,,,,32,1,4.000000e+000,2.632141e-003,0.000000e+000,0,,0,
1524105473.403,,0.000000e+000,5.499906e+001,3.908098e-006,0.000000e+000,3,8.954852e-001,0.000000e+000,,,,,,,,,,,,,,32,1,4.000000e+000,6.580353e-003,0.000000e+000,0,,0,
1524105486.133,,0.000000e+000,5.499643e+001,3.928072e-006,0.000000e+000,3,9.078285e-001,0.000000e+000,,,,,,,,,,,,,,32,1,4.000000e+000,1.312256e-003,0.000000e+000,0,,0,
1524105498.593,,0.000000e+000,5.499774e+001,3.940634e-006,0.000000e+000,3,8.964104e-001,0.000000e+000,,,,,,,,,,,,,,32,1,4.000000e+000,3.940582e-003,0.000000e+000,0,,0,
1524105511.333,,0.000000e+000,5.499774e+001,3.912993e-006,0.000000e+000,3,9.103082e-001,0.000000e+000,,,,,,,,,,,,,,32,1,4.000000e+000,3.940582e-003,0.000000e+000,0,,0,
1524105523.793,,0.000000e+000,5.500366e+001,3.934931e-006,0.000000e+000,3,8.953623e-001,0.000000e+000,,,,,,,,,,,,,,32,1,4.000000e+000,7.900238e-003,0.000000e+000,0,,0,
1524105536.543,,0.000000e+000,5.499840e+001,3.917993e-006,0.000000e+000,3,9.073246e-001,0.000000e+000,,,,,,,,,,,,,,32,1,4.000000e+000,2.628326e-003,0.000000e+000,0,,0,