File: Experimental Raw Data/TC04-12-01K VRMac VRMde/raw/TC04-12-01K_VRMac_55K_750s.dc.raw
[Header]
TITLE,MPMS DC Measurement
BYAPP,MPMS Measurement,2.1,Raw with ABS
FILEOPENTIME, 1524340039.566000 4/21/2018, 1:47:19 PM

INFO, APPNAME, MPMS MultiVu Application, Revision 1.61,  Build 082

INFO, NAME, TC04-12-01K
INFO, WEIGHT, 1.000
INFO, AREA, 1.000
INFO, LENGTH, 1.000
INFO, SHAPE, 0
INFO, COMMENT,
INFO, SEQUENCE FILE: VRMac_55K_750s_VRMde_55Klinear.seq


INFO, BACKGROUND DATA FILE:, None


STARTUPAXIS,X,8,LINEAR,AUTO,0.000000,0.000000
STARTUPAXIS,Y1,10,LINEAR,AUTO,0.000000,0.000000


STARTUPGROUP,Longitudinal
FIELDGROUP,Longitudinal,1,3,4,5,6,8,9,10,11,12,13,14,15,16,17,18,19,20,21,22,23
FIELDGROUP,Transverse,1,3,4,5,6,8,9,24,25,26,27,28,29,30,31,32,33,34,35,36,37

PLOT_APPEARANCE,ALL,HORZ_GRID_ON,VERT_GRID_ON,MARKERS_ONLY

[Data]
Time,Comment,Field (Oe),Start Temperature (K),End Temperature (K),Scan,Rejected,Position (cm),Rot Position (deg),Long Voltage,Long Average Voltage,Long Detrended Voltage,Long Demeaned Voltage,Long Regression Fit,Long Detrended Fit,Long Demeaned Fit,Long Scaled Response,Long Avg. Scaled Response,Long Background Response,Long Response [w/ABS],Long Detrended Resp. [w/ABS],Long Fit [w/ABS],Long Detrended Fit [w/ABS],Trans Voltage,Trans Average Voltage,Trans Detrended Voltage,Trans Demeaned Voltage,Trans Regression Fit,Trans Detrended Fit,Trans Demeaned Fit,Trans Scaled Response,Trans Avg Scaled Response,Trans Background Response,Trans Response [w/ABS],Trans Detrended Resp. [w/ABS],Trans Fit [w/ABS],Trans Detrended Fit [w/ABS],
1524340039.556,,0.000000e+000,5.520694e+001,5.522019e+001,1,0,0.000000e+000,0.000000e+000,2.735027e+000,2.735027e+000,6.162047e-001,6.162047e-001,3.369318e+000,1.250496e+000,1.250496e+000,2.891392e-005,2.891392e-005,,,,,,,,,,,,,,,,,,,,
1524340039.556,,0.000000e+000,5.520694e+001,5.522019e+001,1,0,1.161290e+000,0.000000e+000,2.100404e+000,2.100404e+000,2.545815e-001,-1.841807e-002,1.273086e+000,-5.727363e-001,-8.457359e-001,1.676403e-005,1.676403e-005,,,,,,,,,,,,,,,,,,,,
1524340039.556,,0.000000e+000,5.520694e+001,5.522019e+001,1,0,2.322581e+000,0.000000e+000,-2.184482e+000,-2.184482e+000,-3.757305e+000,-4.303304e+000,-1.397481e+000,-2.970304e+000,-3.516304e+000,-7.696872e-005,-7.696872e-005,,,,,,,,,,,,,,,,,,,,
1524340039.556,,0.000000e+000,5.520694e+001,5.522019e+001,1,0,3.483871e+000,0.000000e+000,2.891890e+000,2.891890e+000,1.592066e+000,7.730675e-001,2.829908e+000,1.530084e+000,7.110858e-001,3.852128e-005,3.852128e-005,,,,,,,,,,,,,,,,,,,,
1524340051.916,,0.000000e+000,5.522815e+001,5.525599e+001,1,0,5.161290e-001,0.000000e+000,3.472496e+000,3.472496e+000,1.423187e+000,1.293287e+000,3.653901e+000,1.604592e+000,1.474692e+000,4.590521e-005,4.590521e-005,,,,,,,,,,,,,,,,,,,,
1524340051.916,,0.000000e+000,5.522815e+001,5.525599e+001,1,0,1.677419e+000,0.000000e+000,-4.818799e-001,-4.818799e-001,-2.238912e+000,-2.661089e+000,-1.357911e+000,-3.114944e+000,-3.537120e+000,-4.029708e-005,-4.029708e-005,,,,,,,,,,,,,,,,,,,,
1524340051.916,,0.000000e+000,5.522815e+001,5.525599e+001,1,0,2.838710e+000,0.000000e+000,-2.626078e-001,-2.626078e-001,-1.727364e+000,-2.441817e+000,8.641295e-001,-6.006263e-001,-1.315079e+000,-3.321893e-005,-3.321893e-005,,,,,,,,,,,,,,,,,,,,
1524340051.916,,0.000000e+000,5.522815e+001,5.525599e+001,1,0,4.000000e+000,0.000000e+000,3.697566e+000,3.697566e+000,2.525087e+000,1.518357e+000,2.483869e+000,1.311389e+000,3.046598e-001,5.746785e-005,5.746785e-005,,,,,,,,,,,,,,,,,,,,
1524340064.466,,0.000000e+000,5.525599e+001,5.528120e+001,1,0,1.032258e+000,0.000000e+000,2.734569e+000,2.734569e+000,7.602127e-001,4.886813e-001,1.963925e+000,-1.043168e-002,-2.819630e-001,2.955013e-005,2.955013e-005,,,,,,,,,,,,,,,,,,,,
1524340064.466,,0.000000e+000,5.525599e+001,5.528120e+001,1,0,2.193548e+000,0.000000e+000,-2.461433e+000,-2.461433e+000,-4.130317e+000,-4.707321e+000,-2.009276e+000,-3.678160e+000,-4.255164e+000,-8.430403e-005,-8.430403e-005,,,,,,,,,,,,,,,,,,,,
1524340064.466,,0.000000e+000,5.525599e+001,5.528120e+001,1,0,3.354839e+000,0.000000e+000,2.525216e+000,2.525216e+000,1.161804e+000,2.793276e-001,2.769770e+000,1.406359e+000,5.238819e-001,2.942262e-005,2.942262e-005,,,,,,,,,,,,,,,,,,,,
1524340921.467,,0.000000e+000,5.527191e+001,5.525334e+001,1,0,3.870968e-001,0.000000e+000,4.585336e+000,4.585336e+000,1.659187e+000,1.535203e+000,5.051606e+000,2.125456e+000,2.001472e+000,5.548879e-005,5.548879e-005,,,,,,,,,,,,,,,,,,,,
1524340921.467,,0.000000e+000,5.527191e+001,5.525334e+001,1,0,1.548387e+000,0.000000e+000,4.797437e-001,4.797437e-001,-2.074453e+000,-2.570390e+000,-6.122779e-001,-3.166474e+000,-3.662412e+000,-3.349959e-005,-3.349959e-005,,,,,,,,,,,,,,,,,,,,
1524340921.467,,0.000000e+000,5.527191e+001,5.525334e+001,1,0,2.709677e+000,0.000000e+000,-8.201724e-001,-8.201724e-001,-3.002416e+000,-3.870306e+000,6.415839e-001,-1.540660e+000,-2.408550e+000,-5.978149e-005,-5.978149e-005,,,,,,,,,,,,,,,,,,,,
1524340921.467,,0.000000e+000,5.527191e+001,5.525334e+001,1,0,3.870968e+000,0.000000e+000,4.899367e+000,4.899367e+000,3.089077e+000,1.849233e+000,3.700380e+000,1.890089e+000,6.502459e-001,7.082042e-005,7.082042e-005,,,,,,,,,,,,,,,,,,,,
1524340933.867,,0.000000e+000,5.525334e+001,5.523742e+001,1,0,9.032258e-001,0.000000e+000,4.150149e+000,4.150149e+000,1.363511e+000,1.067064e+000,3.454029e+000,6.673911e-001,3.709445e-001,4.656706e-005,4.656706e-005,,,,,,,,,,,,,,,,,,,,
1524340933.867,,0.000000e+000,5.525334e+001,5.523742e+001,1,0,2.064516e+000,0.000000e+000,-2.406958e+000,-2.406958e+000,-4.812450e+000,-5.490043e+000,-2.421900e+000,-4.827392e+000,-5.504984e+000,-9.714384e-005,-9.714384e-005,,,,,,,,,,,,,,,,,,,,
1524340933.867,,0.000000e+000,5.525334e+001,5.523742e+001,1,0,3.225806e+000,0.000000e+000,2.686809e+000,2.686809e+000,6.624616e-001,-3.962760e-001,3.282630e+000,1.258283e+000,1.995454e-001,1.954065e-005,1.954065e-005,,,,,,,,,,,,,,,,,,,,
1524340946.287,,0.000000e+000,5.523875e+001,5.523212e+001,1,0,2.580645e-001,0.000000e+000,4.623941e+000,4.623941e+000,1.398449e+000,1.310631e+000,5.302274e+000,2.076781e+000,1.988963e+000,5.083718e-005,5.083718e-005,,,,,,,,,,,,,,,,,,,,
1524340946.287,,0.000000e+000,5.523875e+001,5.523212e+001,1,0,1.419355e+000,0.000000e+000,1.597772e+000,1.597772e+000,-1.232538e+000,-1.715538e+000,4.652770e-001,-2.365033e+000,-2.848034e+000,-1.385318e-005,-1.385318e-005,,,,,,,,,,,,,,,,,,,,
1524340946.287,,0.000000e+000,5.523875e+001,5.523212e+001,1,0,2.580645e+000,0.000000e+000,-1.418326e+000,-1.418326e+000,-3.853455e+000,-4.731637e+000,7.009431e-002,-2.365034e+000,-3.243216e+000,-7.831847e-005,-7.831847e-005,,,,,,,,,,,,,,,,,,,,
1524340946.287,,0.000000e+000,5.523875e+001,5.523212e+001,1,0,3.741935e+000,0.000000e+000,5.003891e+000,5.003891e+000,2.963945e+000,1.690580e+000,4.116728e+000,2.076782e+000,8.034177e-001,6.816126e-005,6.816126e-005,,,,,,,,,,,,,,,,,,,,
1524340959.417,,0.000000e+000,5.522285e+001,5.522152e+001,1,0,7.741935e-001,0.000000e+000,4.493324e+000,4.493324e+000,1.685805e+000,1.429018e+000,4.070401e+000,1.262881e+000,1.006094e+000,5.450394e-005,5.450394e-005,,,,,,,,,,,,,,,,,,,,
1524340959.417,,0.000000e+000,5.522285e+001,5.522152e+001,1,0,1.935484e+000,0.000000e+000,-1.941405e+000,-1.941405e+000,-4.363745e+000,-5.005712e+000,-2.422689e+000,-4.845029e+000,-5.486996e+000,-8.644178e-005,-8.644178e-005,,,,,,,,,,,,,,,,,,,,
1524340959.417,,0.000000e+000,5.522285e+001,5.522152e+001,1,0,3.096774e+000,0.000000e+000,1.826963e+000,1.826963e+000,-2.101966e-001,-1.237344e+000,2.706988e+000,6.698288e-001,-3.573184e-001,6.502887e-007,6.502887e-007,,,,,,,,,,,,,,,,,,,,
1524340972.117,,0.000000e+000,5.522285e+001,5.520430e+001,1,0,1.290323e-001,0.000000e+000,4.365911e+000,4.365911e+000,1.106543e+000,1.063306e+000,5.163265e+000,1.903896e+000,1.860659e+000,4.485953e-005,4.485953e-005,,,,,,,,,,,,,,,,,,,,
1524340972.117,,0.000000e+000,5.522285e+001,5.520430e+001,1,0,1.290323e+000,0.000000e+000,2.442054e+000,2.442054e+000,-4.281808e-001,-8.605521e-001,1.318321e+000,-1.551913e+000,-1.984285e+000,4.760615e-006,4.760615e-006,,,,,,,,,,,,,,,,,,,,
1524340972.117,,0.000000e+000,5.522285e+001,5.520430e+001,1,0,2.451613e+000,0.000000e+000,-2.054627e+000,-2.054627e+000,-4.535728e+000,-5.357233e+000,-7.085065e-001,-3.189607e+000,-4.011112e+000,-9.284054e-005,-9.284054e-005,,,,,,,,,,,,,,,,,,,,
1524340972.117,,0.000000e+000,5.522285e+001,5.520430e+001,1,0,3.612903e+000,0.000000e+000,4.744030e+000,4.744030e+000,2.652064e+000,1.441424e+000,4.232950e+000,2.140984e+000,9.303439e-001,6.200752e-005,6.200752e-005,,,,,,,,,,,,,,,,,,,,
1524340984.497,,0.000000e+000,5.520430e+001,5.519901e+001,1,0,6.451613e-001,0.000000e+000,4.705730e+000,4.705730e+000,1.835412e+000,1.619490e+000,4.602312e+000,1.731994e+000,1.516073e+000,5.857375e-005,5.857375e-005,,,,,,,,,,,,,,,,,,,,
1524340984.497,,0.000000e+000,5.520430e+001,5.519901e+001,1,0,1.806452e+000,0.000000e+000,-1.214923e+000,-1.214923e+000,-3.696582e+000,-4.301163e+000,-2.048160e+000,-4.529819e+000,-5.134399e+000,-7.085652e-005,-7.085652e-005,,,,,,,,,,,,,,,,,,,,
1524340984.497,,0.000000e+000,5.520430e+001,5.519901e+001,1,0,2.967742e+000,0.000000e+000,9.504845e-001,9.504845e-001,-1.142516e+000,-2.135755e+000,2.080153e+000,-1.284702e-002,-1.006087e+000,-1.956448e-005,-1.956448e-005,,,,,,,,,,,,,,,,,,,,
1524340996.837,,0.000000e+000,5.519767e+001,5.519106e+001,1,0,0.000000e+000,0.000000e+000,4.213779e+000,4.213779e+000,8.942568e-001,8.942568e-001,4.981116e+000,1.661594e+000,1.661594e+000,4.090475e-005,4.090475e-005,,,,,,,,,,,,,,,,,,,,
1524340996.837,,0.000000e+000,5.519767e+001,5.519106e+001,1,0,1.161290e+000,0.000000e+000,3.177539e+000,3.177539e+000,2.518840e-001,-1.419833e-001,2.164633e+000,-7.610223e-001,-1.154890e+000,2.067922e-005,2.067922e-005,,,,,,,,,,,,,,,,,,,,
1524340996.837,,0.000000e+000,5.519767e+001,5.519106e+001,1,0,2.322581e+000,0.000000e+000,-2.426795e+000,-2.426795e+000,-4.958582e+000,-5.746317e+000,-1.414999e+000,-3.946787e+000,-4.734521e+000,-1.016426e-004,-1.016426e-004,,,,,,,,,,,,,,,,,,,,
1524340996.837,,0.000000e+000,5.519767e+001,5.519106e+001,1,0,3.483871e+000,0.000000e+000,4.278935e+000,4.278935e+000,2.141015e+000,9.594128e-001,4.171017e+000,2.033097e+000,8.514950e-001,5.116384e-005,5.116384e-005,,,,,,,,,,,,,,,,,,,,
1524341009.727,,0.000000e+000,5.518576e+001,5.517783e+001,1,0,5.161290e-001,0.000000e+000,4.730907e+000,4.730907e+000,1.815905e+000,1.643419e+000,4.948735e+000,2.033733e+000,1.861247e+000,5.878867e-005,5.878867e-005,,,,,,,,,,,,,,,,,,,,
1524341009.727,,0.000000e+000,5.518576e+001,5.517783e+001,1,0,1.677419e+000,0.000000e+000,-3.805600e-001,-3.805600e-001,-2.907468e+000,-3.468048e+000,-1.421114e+000,-3.948022e+000,-4.508602e+000,-5.256062e-005,-5.256062e-005,,,,,,,,,,,,,,,,,,,,
1524341009.727,,0.000000e+000,5.518576e+001,5.517783e+001,1,0,2.838710e+000,0.000000e+000,1.159686e-002,1.159686e-002,-2.127217e+000,-3.075891e+000,1.377552e+000,-7.612613e-001,-1.709935e+000,-4.090468e-005,-4.090468e-005,,,,,,,,,,,,,,,,,,,,
1524341009.727,,0.000000e+000,5.518576e+001,5.517783e+001,1,0,4.000000e+000,0.000000e+000,4.881056e+000,4.881056e+000,3.130336e+000,1.793568e+000,3.412834e+000,1.662115e+000,3.253465e-001,7.081832e-005,7.081832e-005,,,,,,,,,,,,,,,,,,,,
1524341022.207,,0.000000e+000,5.517783e+001,5.517386e+001,1,0,1.032258e+000,0.000000e+000,3.649500e+000,3.649500e+000,9.007522e-001,5.577075e-001,2.735860e+000,-1.288784e-002,-3.559325e-001,3.575418e-005,3.575418e-005,,,,,,,,,,,,,,,,,,,,
1524341022.207,,0.000000e+000,5.517783e+001,5.517386e+001,1,0,2.193548e+000,0.000000e+000,-2.693065e+000,-2.693065e+000,-5.055888e+000,-5.784858e+000,-2.181346e+000,-4.544169e+000,-5.273139e+000,-1.031261e-004,-1.031261e-004,,,,,,,,,,,,,,,,,,,,
1524341022.207,,0.000000e+000,5.517783e+001,5.517386e+001,1,0,3.354839e+000,0.000000e+000,3.425803e+000,3.425803e+000,1.448905e+000,3.340101e-001,3.714378e+000,1.737480e+000,6.225853e-001,3.650483e-005,3.650483e-005,,,,,,,,,,,,,,,,,,,,
1524341034.357,,0.000000e+000,5.517386e+001,5.516988e+001,1,0,3.870968e-001,0.000000e+000,4.641947e+000,4.641947e+000,1.665138e+000,1.533875e+000,5.126818e+000,2.150009e+000,2.018746e+000,5.619739e-005,5.619739e-005,,,,,,,,,,,,,,,,,,,,
1524341034.357,,0.000000e+000,5.517386e+001,5.516988e+001,1,0,1.548387e+000,0.000000e+000,5.084306e-001,5.084306e-001,-2.074589e+000,-2.599642e+000,-6.200328e-001,-3.203053e+000,-3.728105e+000,-3.325241e-005,-3.325241e-005,,,,,,,,,,,,,,,,,,,,
1524341034.357,,0.000000e+000,5.517386e+001,5.516988e+001,1,0,2.709677e+000,0.000000e+000,-8.615244e-001,-8.615244e-001,-3.050755e+000,-3.969597e+000,6.307737e-001,-1.558457e+000,-2.477299e+000,-6.093701e-005,-6.093701e-005,,,,,,,,,,,,,,,,,,,,
1524341034.357,,0.000000e+000,5.517386e+001,5.516988e+001,1,0,3.870968e+000,0.000000e+000,4.940261e+000,4.940261e+000,3.144820e+000,1.832189e+000,3.707364e+000,1.911923e+000,5.992918e-001,7.166578e-005,7.166578e-005,,,,,,,,,,,,,,,,,,,,
1524341046.807,,0.000000e+000,5.516063e+001,5.515931e+001,1,0,9.032258e-001,0.000000e+000,4.173038e+000,4.173038e+000,1.379435e+000,1.075737e+000,3.469166e+000,6.755639e-001,3.718657e-001,4.718558e-005,4.718558e-005,,,,,,,,,,,,,,,,,,,,
1524341046.807,,0.000000e+000,5.516063e+001,5.515931e+001,1,0,2.064516e+000,0.000000e+000,-2.461280e+000,-2.461280e+000,-4.864413e+000,-5.558580e+000,-2.483375e+000,-4.886508e+000,-5.580675e+000,-9.818152e-005,-9.818152e-005,,,,,,,,,,,,,,,,,,,,
1524341046.807,,0.000000e+000,5.516063e+001,5.515931e+001,1,0,3.225806e+000,0.000000e+000,2.674754e+000,2.674754e+000,6.620898e-001,-4.225464e-001,3.286356e+000,1.273692e+000,1.890557e-001,1.951710e-005,1.951710e-005,,,,,,,,,,,,,,,,,,,,
1524341059.137,,0.000000e+000,5.515534e+001,5.514741e+001,1,0,2.580645e-001,0.000000e+000,4.449531e+000,4.449531e+000,1.429024e+000,1.342288e+000,5.120085e+000,2.099578e+000,2.012842e+000,5.152966e-005,5.152966e-005,,,,,,,,,,,,,,,,,,,,
1524341059.137,,0.000000e+000,5.515534e+001,5.514741e+001,1,0,1.419355e+000,0.000000e+000,1.369802e+000,1.369802e+000,-1.260393e+000,-1.737440e+000,2.392013e-001,-2.390994e+000,-2.868041e+000,-1.439403e-005,-1.439403e-005,,,,,,,,,,,,,,,,,,,,
1524341059.137,,0.000000e+000,5.515534e+001,5.514741e+001,1,0,2.580645e+000,0.000000e+000,-1.656519e+000,-1.656519e+000,-3.896404e+000,-4.763762e+000,-1.511107e-001,-2.390995e+000,-3.258353e+000,-7.912409e-005,-7.912409e-005,,,,,,,,,,,,,,,,,,,,
1524341059.137,,0.000000e+000,5.515534e+001,5.514741e+001,1,0,3.741935e+000,0.000000e+000,4.847486e+000,4.847486e+000,2.997913e+000,1.740244e+000,3.949151e+000,2.099578e+000,8.419089e-001,6.914731e-005,6.914731e-005,,,,,,,,,,,,,,,,,,,,
1524341071.287,,0.000000e+000,5.514477e+001,5.514212e+001,1,0,7.741935e-001,0.000000e+000,4.570535e+000,4.570535e+000,1.702973e+000,1.443930e+000,4.143122e+000,1.275560e+000,1.016517e+000,5.504900e-005,5.504900e-005,,,,,,,,,,,,,,,,,,,,
1524341071.287,,0.000000e+000,5.514477e+001,5.514212e+001,1,0,1.935484e+000,0.000000e+000,-1.912718e+000,-1.912718e+000,-4.391716e+000,-5.039323e+000,-2.414674e+000,-4.893672e+000,-5.541279e+000,-8.695601e-005,-8.695601e-005,,,,,,,,,,,,,,,,,,,,
1524341071.287,,0.000000e+000,5.514477e+001,5.514212e+001,1,0,3.096774e+000,0.000000e+000,1.869230e+000,1.869230e+000,-2.212032e-001,-1.257374e+000,2.766987e+000,6.765535e-001,-3.596175e-001,4.647954e-007,4.647954e-007,,,,,,,,,,,,,,,,,,,,
1524341083.847,,0.000000e+000,5.513816e+001,5.513286e+001,1,0,1.290323e-001,0.000000e+000,4.215305e+000,4.215305e+000,1.120994e+000,1.077567e+000,5.014549e+000,1.920238e+000,1.876811e+000,4.531611e-005,4.531611e-005,,,,,,,,,,,,,,,,,,,,
1524341083.847,,0.000000e+000,5.513816e+001,5.513286e+001,1,0,1.290323e+000,0.000000e+000,2.240482e+000,2.240482e+000,-4.629850e-001,-8.972557e-001,1.138233e+000,-1.565234e+000,-1.999504e+000,4.090878e-006,4.090878e-006,,,,,,,,,,,,,,,,,,,,
1524341083.847,,0.000000e+000,5.513816e+001,5.513286e+001,1,0,2.451613e+000,0.000000e+000,-2.252995e+000,-2.252995e+000,-4.565618e+000,-5.390732e+000,-9.043606e-001,-3.216984e+000,-4.042099e+000,-9.342592e-005,-9.342592e-005,,,,,,,,,,,,,,,,,,,,
1524341083.847,,0.000000e+000,5.513816e+001,5.513286e+001,1,0,3.612903e+000,0.000000e+000,4.565042e+000,4.565042e+000,2.643262e+000,1.427304e+000,4.081140e+000,2.159360e+000,9.434023e-001,6.186799e-005,6.186799e-005,,,,,,,,,,,,,,,,,,,,
1524341096.137,,0.000000e+000,5.512891e+001,5.512230e+001,1,0,6.451613e-001,0.000000e+000,4.785992e+000,4.785992e+000,1.854941e+000,1.637944e+000,4.677874e+000,1.746823e+000,1.529825e+000,5.913637e-005,5.913637e-005,,,,,,,,,,,,,,,,,,,,
1524341096.137,,0.000000e+000,5.512891e+001,5.512230e+001,1,0,1.806452e+000,0.000000e+000,-1.190051e+000,-1.190051e+000,-3.730505e+000,-4.338099e+000,-2.028148e+000,-4.568603e+000,-5.176197e+000,-7.151743e-005,-7.151743e-005,,,,,,,,,,,,,,,,,,,,
1524341096.137,,0.000000e+000,5.512891e+001,5.512230e+001,1,0,2.967742e+000,0.000000e+000,9.854276e-001,9.854276e-001,-1.164430e+000,-2.162621e+000,2.136901e+000,-1.295721e-002,-1.011148e+000,-1.998587e-005,-1.998587e-005,,,,,,,,,,,,,,,,,,,,
1524341108.817,,0.000000e+000,5.511570e+001,5.511702e+001,1,0,0.000000e+000,0.000000e+000,4.072480e+000,4.072480e+000,9.124453e-001,9.124453e-001,4.835995e+000,1.675960e+000,1.675960e+000,4.142934e-005,4.142934e-005,,,,,,,,,,,,,,,,,,,,
1524341108.817,,0.000000e+000,5.511570e+001,5.511702e+001,1,0,1.161290e+000,0.000000e+000,3.050126e+000,3.050126e+000,2.849177e-001,-1.099091e-001,1.997606e+000,-7.676021e-001,-1.162429e+000,2.152131e-005,2.152131e-005,,,,,,,,,,,,,,,,,,,,
1524341108.817,,0.000000e+000,5.511570e+001,5.511702e+001,1,0,2.322581e+000,0.000000e+000,-2.614023e+000,-2.614023e+000,-4.984404e+000,-5.774058e+000,-1.610529e+000,-3.980911e+000,-4.770564e+000,-1.021302e-004,-1.021302e-004,,,,,,,,,,,,,,,,,,,,
1524341108.817,,0.000000e+000,5.511570e+001,5.511702e+001,1,0,3.483871e+000,0.000000e+000,4.110323e+000,4.110323e+000,2.134768e+000,9.502881e-001,4.026229e+000,2.050675e+000,8.661945e-001,5.109945e-005,5.109945e-005,,,,,,,,,,,,,,,,,,,,
1524341121.227,,0.000000e+000,5.511702e+001,5.510646e+001,1,0,5.161290e-001,0.000000e+000,4.799420e+000,4.799420e+000,1.818536e+000,1.643807e+000,5.032560e+000,2.051676e+000,1.876947e+000,5.903895e-005,5.903895e-005,,,,,,,,,,,,,,,,,,,,
1524341121.227,,0.000000e+000,5.511702e+001,5.510646e+001,1,0,1.677419e+000,0.000000e+000,-3.445487e-001,-3.445487e-001,-2.932293e+000,-3.500162e+000,-1.395108e+000,-3.982852e+000,-4.550721e+000,-5.299915e-005,-5.299915e-005,,,,,,,,,,,,,,,,,,,,
1524341121.227,,0.000000e+000,5.511702e+001,5.510646e+001,1,0,2.838710e+000,0.000000e+000,5.951019e-002,5.951019e-002,-2.135094e+000,-3.096103e+000,1.426627e+000,-7.679772e-001,-1.728987e+000,-4.103962e-005,-4.103962e-005,,,,,,,,,,,,,,,,,,,,
1524341121.227,,0.000000e+000,5.511702e+001,5.510646e+001,1,0,4.000000e+000,0.000000e+000,4.958724e+000,4.958724e+000,3.157261e+000,1.803111e+000,3.478242e+000,1.676778e+000,3.226280e-001,7.138602e-005,7.138602e-005,,,,,,,,,,,,,,,,,,,,
1524341133.847,,0.000000e+000,5.510117e+001,5.509589e+001,1,0,1.032258e+000,0.000000e+000,3.709773e+000,3.709773e+000,9.031439e-001,5.555341e-001,2.793638e+000,-1.299137e-002,-3.606012e-001,3.595866e-005,3.595866e-005,,,,,,,,,,,,,,,,,,,,
1524341133.847,,0.000000e+000,5.510117e+001,5.509589e+001,1,0,2.193548e+000,0.000000e+000,-2.683299e+000,-2.683299e+000,-5.098867e+000,-5.837538e+000,-2.165217e+000,-4.580786e+000,-5.319457e+000,-1.040122e-004,-1.040122e-004,,,,,,,,,,,,,,,,,,,,
1524341133.847,,0.000000e+000,5.510117e+001,5.509589e+001,1,0,3.354839e+000,0.000000e+000,3.505608e+000,3.505608e+000,1.481100e+000,3.513684e-001,3.775989e+000,1.751481e+000,6.217494e-001,3.722236e-005,3.722236e-005,,,,,,,,,,,,,,,,,,,,
1524341146.307,,0.000000e+000,5.509589e+001,5.508666e+001,1,0,3.870968e-001,0.000000e+000,4.709087e+000,4.709087e+000,1.677979e+000,1.546187e+000,5.200336e+000,2.169228e+000,2.037436e+000,5.661409e-005,5.661409e-005,,,,,,,,,,,,,,,,,,,,
1524341146.307,,0.000000e+000,5.509589e+001,5.508666e+001,1,0,1.548387e+000,0.000000e+000,5.159075e-001,5.159075e-001,-2.119823e+000,-2.646992e+000,-5.959537e-001,-3.231684e+000,-3.758854e+000,-3.415733e-005,-3.415733e-005,,,,,,,,,,,,,,,,,,,,
1524341146.307,,0.000000e+000,5.509589e+001,5.508666e+001,1,0,2.709677e+000,0.000000e+000,-8.239872e-001,-8.239872e-001,-3.064341e+000,-3.986887e+000,6.679658e-001,-1.572388e+000,-2.494934e+000,-6.115824e-005,-6.115824e-005,,,,,,,,,,,,,,,,,,,,
1524341146.307,,0.000000e+000,5.509589e+001,5.508666e+001,1,0,3.870968e+000,0.000000e+000,5.007401e+000,5.007401e+000,3.162424e+000,1.844501e+000,3.773990e+000,1.929013e+000,6.110897e-001,7.211799e-005,7.211799e-005,,,,,,,,,,,,,,,,,,,,
1524341159.047,,0.000000e+000,5.508007e+001,5.507743e+001,1,0,9.032258e-001,0.000000e+000,4.241550e+000,4.241550e+000,1.383108e+000,1.076124e+000,3.538878e+000,6.804360e-001,3.734519e-001,4.740544e-005,4.740544e-005,,,,,,,,,,,,,,,,,,,,
1524341159.047,,0.000000e+000,5.508007e+001,5.507743e+001,1,0,2.064516e+000,0.000000e+000,-2.435340e+000,-2.435340e+000,-4.899088e+000,-5.600766e+000,-2.458002e+000,-4.921750e+000,-5.623428e+000,-9.888166e-005,-9.888166e-005,,,,,,,,,,,,,,,,,,,,
1524341159.047,,0.000000e+000,5.508007e+001,5.507743e+001,1,0,3.225806e+000,0.000000e+000,2.742962e+000,2.742962e+000,6.739070e-001,-4.224644e-001,3.351933e+000,1.282878e+000,1.865063e-001,1.979310e-005,1.979310e-005,,,,,,,,,,,,,,,,,,,,
1524341171.467,,0.000000e+000,5.506952e+001,5.506425e+001,1,0,2.580645e-001,0.000000e+000,4.525826e+000,4.525826e+000,1.441247e+000,1.354162e+000,5.197681e+000,2.113102e+000,2.026016e+000,5.190802e-005,5.190802e-005,,,,,,,,,,,,,,,,,,,,
1524341171.467,,0.000000e+000,5.506952e+001,5.506425e+001,1,0,1.419355e+000,0.000000e+000,1.431144e+000,1.431144e+000,-1.261551e+000,-1.740521e+000,2.862998e-001,-2.406394e+000,-2.885365e+000,-1.433817e-005,-1.433817e-005,,,,,,,,,,,,,,,,,,,,
1524341171.467,,0.000000e+000,5.506952e+001,5.506425e+001,1,0,2.580645e+000,0.000000e+000,-1.631647e+000,-1.631647e+000,-3.932457e+000,-4.803312e+000,-1.055857e-001,-2.406395e+000,-3.277250e+000,-7.987159e-005,-7.987159e-005,,,,,,,,,,,,,,,,,,,,
1524341171.467,,0.000000e+000,5.506952e+001,5.506425e+001,1,0,3.741935e+000,0.000000e+000,4.905928e+000,4.905928e+000,2.997003e+000,1.734264e+000,4.022027e+000,2.113102e+000,8.503625e-001,6.916181e-005,6.916181e-005,,,,,,,,,,,,,,,,,,,,
1524341184.267,,0.000000e+000,5.506425e+001,5.506425e+001,1,0,7.741935e-001,0.000000e+000,4.624247e+000,4.624247e+000,1.705206e+000,1.442806e+000,4.203247e+000,1.284206e+000,1.021806e+000,5.525185e-005,5.525185e-005,,,,,,,,,,,,,,,,,,,,
1524341184.267,,0.000000e+000,5.506425e+001,5.506425e+001,1,0,1.935484e+000,0.000000e+000,-1.904479e+000,-1.904479e+000,-4.429918e+000,-5.085919e+000,-2.401404e+000,-4.926844e+000,-5.582845e+000,-8.773193e-005,-8.773193e-005,,,,,,,,,,,,,,,,,,,,
1524341184.267,,0.000000e+000,5.506425e+001,5.506425e+001,1,0,3.096774e+000,0.000000e+000,1.918517e+000,1.918517e+000,-2.133224e-001,-1.262924e+000,2.812979e+000,6.811395e-001,-3.684618e-001,6.437840e-007,6.437840e-007,,,,,,,,,,,,,,,,,,,,
1524341196.827,,0.000000e+000,5.506425e+001,5.504975e+001,1,0,1.290323e-001,0.000000e+000,4.271153e+000,4.271153e+000,1.129260e+000,1.085466e+000,5.078437e+000,1.936544e+000,1.892750e+000,4.567259e-005,4.567259e-005,,,,,,,,,,,,,,,,,,,,
1524341196.827,,0.000000e+000,5.506425e+001,5.504975e+001,1,0,1.290323e+000,0.000000e+000,2.299077e+000,2.299077e+000,-4.486675e-001,-8.866105e-001,1.169219e+000,-1.578525e+000,-2.016468e+000,4.533358e-006,4.533358e-006,,,,,,,,,,,,,,,,,,,,
1524341196.827,,0.000000e+000,5.506425e+001,5.504975e+001,1,0,2.451613e+000,0.000000e+000,-2.249332e+000,-2.249332e+000,-4.602928e+000,-5.435019e+000,-8.907062e-001,-3.244302e+000,-4.076394e+000,-9.418654e-005,-9.418654e-005,,,,,,,,,,,,,,,,,,,,
1524341196.827,,0.000000e+000,5.506425e+001,5.504975e+001,1,0,3.612903e+000,0.000000e+000,4.665904e+000,4.665904e+000,2.706457e+000,1.480216e+000,4.137144e+000,2.177697e+000,9.514563e-001,6.330440e-005,6.330440e-005,,,,,,,,,,,,,,,,,,,,
1524341209.807,,0.000000e+000,5.504975e+001,5.504447e+001,1,0,6.451613e-001,0.000000e+000,4.829328e+000,4.829328e+000,1.860970e+000,1.641818e+000,4.728684e+000,1.760326e+000,1.541173e+000,5.942269e-005,5.942269e-005,,,,,,,,,,,,,,,,,,,,
1524341209.807,,0.000000e+000,5.504975e+001,5.504447e+001,1,0,1.806452e+000,0.000000e+000,-1.188830e+000,-1.188830e+000,-3.762713e+000,-4.376341e+000,-2.030035e+000,-4.603919e+000,-5.217546e+000,-7.214348e-005,-7.214348e-005,,,,,,,,,,,,,,,,,,,,
1524341209.807,,0.000000e+000,5.504975e+001,5.504447e+001,1,0,2.967742e+000,0.000000e+000,1.017014e+000,1.017014e+000,-1.162394e+000,-2.170497e+000,2.166351e+000,-1.305730e-002,-1.021160e+000,-1.990436e-005,-1.990436e-005,,,,,,,,,,,,,,,,,,,,
1524341222.627,,0.000000e+000,5.504447e+001,5.503657e+001,1,0,0.000000e+000,0.000000e+000,4.128176e+000,4.128176e+000,9.267118e-001,9.267118e-001,4.890930e+000,1.689466e+000,1.689466e+000,4.180086e-005,4.180086e-005,,,,,,,,,,,,,,,,,,,,
1524341222.627,,0.000000e+000,5.504447e+001,5.503657e+001,1,0,1.161290e+000,0.000000e+000,3.085374e+000,3.085374e+000,2.773655e-001,-1.160898e-001,2.034221e+000,-7.737877e-001,-1.167243e+000,2.142563e-005,2.142563e-005,,,,,,,,,,,,,,,,,,,,
1524341222.627,,0.000000e+000,5.504447e+001,5.503657e+001,1,0,2.322581e+000,0.000000e+000,-2.603037e+000,-2.603037e+000,-5.017590e+000,-5.804501e+000,-1.598437e+000,-4.012990e+000,-4.799901e+000,-1.027783e-004,-1.027783e-004,,,,,,,,,,,,,,,,,,,,
1524341222.627,,0.000000e+000,5.504447e+001,5.503657e+001,1,0,3.483871e+000,0.000000e+000,4.186160e+000,4.186160e+000,2.165062e+000,9.846961e-001,4.088298e+000,2.067200e+000,8.868344e-001,5.189050e-005,5.189050e-005,,,,,,,,,,,,,,,,,,,,
1524341235.147,,0.000000e+000,5.503262e+001,5.502867e+001,1,0,5.161290e-001,0.000000e+000,4.882734e+000,4.882734e+000,1.849027e+000,1.673335e+000,5.096317e+000,2.062610e+000,1.886917e+000,5.981983e-005,5.981983e-005,,,,,,,,,,,,,,,,,,,,
1524341235.147,,0.000000e+000,5.503262e+001,5.502867e+001,1,0,1.677419e+000,0.000000e+000,-3.228809e-001,-3.228809e-001,-2.961280e+000,-3.532281e+000,-1.365679e+000,-4.004078e+000,-4.575079e+000,-5.357990e-005,-5.357990e-005,,,,,,,,,,,,,,,,,,,,
1524341235.147,,0.000000e+000,5.503262e+001,5.502867e+001,1,0,2.838710e+000,0.000000e+000,7.339589e-002,7.339589e-002,-2.169694e+000,-3.136004e+000,1.471020e+000,-7.720701e-001,-1.738379e+000,-4.177814e-005,-4.177814e-005,,,,,,,,,,,,,,,,,,,,
1524341235.147,,0.000000e+000,5.503262e+001,5.502867e+001,1,0,4.000000e+000,0.000000e+000,5.012894e+000,5.012894e+000,3.165112e+000,1.803494e+000,3.533496e+000,1.685714e+000,3.240967e-001,7.156397e-005,7.156397e-005,,,,,,,,,,,,,,,,,,,,
1524341248.117,,0.000000e+000,5.502867e+001,5.501813e+001,1,0,1.032258e+000,0.000000e+000,3.759670e+000,3.759670e+000,9.052421e-001,5.509224e-001,2.841330e+000,-1.309878e-002,-3.674185e-001,3.618932e-005,3.618932e-005,,,,,,,,,,,,,,,,,,,,
1524341248.117,,0.000000e+000,5.502867e+001,5.501813e+001,1,0,2.193548e+000,0.000000e+000,-2.681315e+000,-2.681315e+000,-5.137134e+000,-5.890063e+000,-2.162742e+000,-4.618561e+000,-5.371490e+000,-1.047962e-004,-1.047962e-004,,,,,,,,,,,,,,,,,,,,
1524341248.117,,0.000000e+000,5.502867e+001,5.501813e+001,1,0,3.354839e+000,0.000000e+000,3.550011e+000,3.550011e+000,1.492803e+000,3.412633e-001,3.823133e+000,1.765925e+000,6.143854e-001,3.744271e-005,3.744271e-005,,,,,,,,,,,,,,,,,,,,
1524341260.608,,0.000000e+000,5.502340e+001,5.501813e+001,1,0,3.870968e-001,0.000000e+000,4.742962e+000,4.742962e+000,1.674697e+000,1.542089e+000,5.248471e+000,2.180206e+000,2.047598e+000,5.664664e-005,5.664664e-005,,,,,,,,,,,,,,,,,,,,
1524341260.608,,0.000000e+000,5.502340e+001,5.501813e+001,1,0,1.548387e+000,0.000000e+000,5.746548e-001,5.746548e-001,-2.095788e+000,-2.626218e+000,-5.775969e-001,-3.248039e+000,-3.778470e+000,-3.355067e-005,-3.355067e-005,,,,,,,,,,,,,,,,,,,,
1524341260.608,,0.000000e+000,5.502340e+001,5.501813e+001,1,0,2.709677e+000,0.000000e+000,-8.467231e-001,-8.467231e-001,-3.119343e+000,-4.047596e+000,6.922742e-001,-1.580345e+000,-2.508599e+000,-6.235451e-005,-6.235451e-005,,,,,,,,,,,,,,,,,,,,
1524341260.608,,0.000000e+000,5.502340e+001,5.501813e+001,1,0,3.870968e+000,0.000000e+000,5.054551e+000,5.054551e+000,3.179754e+000,1.853678e+000,3.813572e+000,1.938776e+000,6.126993e-001,7.250191e-005,7.250191e-005,,,,,,,,,,,,,,,,,,,,
1524341273.798,,0.000000e+000,5.501155e+001,5.501551e+001,1,0,9.032258e-001,0.000000e+000,4.285344e+000,4.285344e+000,1.392326e+000,1.089432e+000,3.577931e+000,6.849133e-001,3.820193e-001,4.760943e-005,4.760943e-005,,,,,,,,,,,,,,,,,,,,
1524341273.798,,0.000000e+000,5.501155e+001,5.501551e+001,1,0,2.064516e+000,0.000000e+000,-2.429236e+000,-2.429236e+000,-4.932818e+000,-5.625148e+000,-2.450552e+000,-4.954134e+000,-5.646463e+000,-9.955919e-005,-9.955919e-005,,,,,,,,,,,,,,,,,,,,
1524341273.798,,0.000000e+000,5.501155e+001,5.501551e+001,1,0,3.225806e+000,0.000000e+000,2.800336e+000,2.800336e+000,6.861886e-001,-3.955758e-001,3.405466e+000,1.291319e+000,2.095544e-001,2.022227e-005,2.022227e-005,,,,,,,,,,,,,,,,,,,,
1524341286.688,,0.000000e+000,5.501155e+001,5.501813e+001,1,0,2.580645e-001,0.000000e+000,4.577859e+000,4.577859e+000,1.436815e+000,1.348772e+000,5.266983e+000,2.125938e+000,2.037896e+000,5.197169e-005,5.197169e-005,,,,,,,,,,,,,,,,,,,,
1524341286.688,,0.000000e+000,5.501155e+001,5.501813e+001,1,0,1.419355e+000,0.000000e+000,1.447471e+000,1.447471e+000,-1.297381e+000,-1.781616e+000,3.238394e-001,-2.421013e+000,-2.905247e+000,-1.504044e-005,-1.504044e-005,,,,,,,,,,,,,,,,,,,,
1524341286.688,,0.000000e+000,5.501155e+001,5.501813e+001,1,0,2.580645e+000,0.000000e+000,-1.617761e+000,-1.617761e+000,-3.966422e+000,-4.846848e+000,-7.235342e-002,-2.421014e+000,-3.301440e+000,-8.059633e-005,-8.059633e-005,,,,,,,,,,,,,,,,,,,,
1524341286.688,,0.000000e+000,5.501155e+001,5.501813e+001,1,0,3.741935e+000,0.000000e+000,4.975967e+000,4.975967e+000,3.023499e+000,1.746880e+000,4.078407e+000,2.125939e+000,8.493199e-001,6.972418e-005,6.972418e-005,,,,,,,,,,,,,,,,,,,,
1524341298.708,,0.000000e+000,5.501813e+001,5.500892e+001,1,0,7.741935e-001,0.000000e+000,4.684978e+000,4.684978e+000,1.717442e+000,1.449657e+000,4.258391e+000,1.290856e+000,1.023071e+000,5.570905e-005,5.570905e-005,,,,,,,,,,,,,,,,,,,,
1524341298.708,,0.000000e+000,5.501813e+001,5.500892e+001,1,0,1.935484e+000,0.000000e+000,-1.889677e+000,-1.889677e+000,-4.455535e+000,-5.124998e+000,-2.386496e+000,-4.952353e+000,-5.621816e+000,-8.824107e-005,-8.824107e-005,,,,,,,,,,,,,,,,,,,,
1524341298.708,,0.000000e+000,5.501813e+001,5.500892e+001,1,0,3.096774e+000,0.000000e+000,1.927825e+000,1.927825e+000,-2.363549e-001,-1.307495e+000,2.848846e+000,6.846663e-001,-3.864744e-001,7.203926e-008,7.203926e-008,,,,,,,,,,,,,,,,,,,,
1524341311.548,,0.000000e+000,5.500761e+001,5.500367e+001,1,0,1.290323e-001,0.000000e+000,4.330816e+000,4.330816e+000,1.154475e+000,1.110210e+000,5.121315e+000,1.944974e+000,1.900709e+000,4.638560e-005,4.638560e-005,,,,,,,,,,,,,,,,,,,,
1524341311.548,,0.000000e+000,5.500761e+001,5.500367e+001,1,0,1.290323e+000,0.000000e+000,2.332189e+000,2.332189e+000,-4.457681e-001,-8.884172e-001,1.192560e+000,-1.585397e+000,-2.028046e+000,4.684509e-006,4.684509e-006,,,,,,,,,,,,,,,,,,,,
1524341311.548,,0.000000e+000,5.500761e+001,5.500367e+001,1,0,2.451613e+000,0.000000e+000,-2.247044e+000,-2.247044e+000,-4.626616e+000,-5.467649e+000,-8.788512e-001,-3.258424e+000,-4.099457e+000,-9.469274e-005,-9.469274e-005,,,,,,,,,,,,,,,,,,,,
1524341311.548,,0.000000e+000,5.500761e+001,5.500367e+001,1,0,3.612903e+000,0.000000e+000,4.668650e+000,4.668650e+000,2.687462e+000,1.448044e+000,4.168365e+000,2.187176e+000,9.477584e-001,6.283998e-005,6.283998e-005,,,,,,,,,,,,,,,,,,,,
1524341324.048,,0.000000e+000,5.500497e+001,5.500367e+001,1,0,6.451613e-001,0.000000e+000,4.852979e+000,4.852979e+000,1.853831e+000,1.635879e+000,4.768923e+000,1.769775e+000,1.551822e+000,5.928447e-005,5.928447e-005,,,,,,,,,,,,,,,,,,,,
1524341324.048,,0.000000e+000,5.500497e+001,5.500367e+001,1,0,1.806452e+000,0.000000e+000,-1.176013e+000,-1.176013e+000,-3.782846e+000,-4.393113e+000,-2.021796e+000,-4.628630e+000,-5.238896e+000,-7.253991e-005,-7.253991e-005,,,,,,,,,,,,,,,,,,,,
1524341324.048,,0.000000e+000,5.500497e+001,5.500367e+001,1,0,2.967742e+000,0.000000e+000,1.047227e+000,1.047227e+000,-1.167292e+000,-2.169874e+000,2.201391e+000,-1.312723e-002,-1.015709e+000,-1.992810e-005,-1.992810e-005,,,,,,,,,,,,,,,,,,,,
1524341336.998,,0.000000e+000,5.500235e+001,5.500235e+001,1,0,0.000000e+000,0.000000e+000,4.176394e+000,4.176394e+000,9.339843e-001,9.339843e-001,4.938016e+000,1.695606e+000,1.695606e+000,4.205872e-005,4.205872e-005,,,,,,,,,,,,,,,,,,,,
1524341336.998,,0.000000e+000,5.500235e+001,5.500235e+001,1,0,1.161290e+000,0.000000e+000,3.119097e+000,3.119097e+000,2.722988e-001,-1.233134e-001,2.070198e+000,-7.765999e-001,-1.172212e+000,2.137556e-005,2.137556e-005,,,,,,,,,,,,,,,,,,,,
1524341336.998,,0.000000e+000,5.500235e+001,5.500235e+001,1,0,2.322581e+000,0.000000e+000,-2.595712e+000,-2.595712e+000,-5.046898e+000,-5.838122e+000,-1.576389e+000,-4.027575e+000,-4.818799e+000,-1.034023e-004,-1.034023e-004,,,,,,,,,,,,,,,,,,,,
1524341336.998,,0.000000e+000,5.500235e+001,5.500235e+001,1,0,3.483871e+000,0.000000e+000,4.211948e+000,4.211948e+000,2.156374e+000,9.695377e-001,4.130287e+000,2.074713e+000,8.878765e-001,5.169522e-005,5.169522e-005,,,,,,,,,,,,,,,,,,,,
1524341349.428,,0.000000e+000,5.500235e+001,5.499314e+001,1,0,5.161290e-001,0.000000e+000,4.917220e+000,4.917220e+000,1.840169e+000,1.664637e+000,5.155484e+000,2.078433e+000,1.902901e+000,5.969910e-005,5.969910e-005,,,,,,,,,,,,,,,,,,,,
1524341349.428,,0.000000e+000,5.500235e+001,5.499314e+001,1,0,1.677419e+000,0.000000e+000,-2.903792e-001,-2.903792e-001,-2.972483e+000,-3.542962e+000,-1.352691e+000,-4.034795e+000,-4.605274e+000,-5.374764e-005,-5.374764e-005,,,,,,,,,,,,,,,,,,,,
1524341349.428,,0.000000e+000,5.500235e+001,5.499314e+001,1,0,2.838710e+000,0.000000e+000,1.112383e-001,1.112383e-001,-2.175918e+000,-3.141345e+000,1.509164e+000,-7.779930e-001,-1.743419e+000,-4.182922e-005,-4.182922e-005,,,,,,,,,,,,,,,,,,,,
1524341349.428,,0.000000e+000,5.500235e+001,5.499314e+001,1,0,4.000000e+000,0.000000e+000,5.080645e+000,5.080645e+000,3.188435e+000,1.828062e+000,3.590856e+000,1.698646e+000,3.382726e-001,7.217866e-005,7.217866e-005,,,,,,,,,,,,,,,,,,,,
1524341362.268,,0.000000e+000,5.499971e+001,5.499314e+001,1,0,1.032258e+000,0.000000e+000,3.816434e+000,3.816434e+000,8.968396e-001,5.444293e-001,2.906431e+000,-1.316282e-002,-3.655732e-001,3.602872e-005,3.602872e-005,,,,,,,,,,,,,,,,,,,,
1524341362.268,,0.000000e+000,5.499971e+001,5.499314e+001,1,0,2.193548e+000,0.000000e+000,-2.649119e+000,-2.649119e+000,-5.172252e+000,-5.921124e+000,-2.118030e+000,-4.641163e+000,-5.390035e+000,-1.055218e-004,-1.055218e-004,,,,,,,,,,,,,,,,,,,,
1524341362.268,,0.000000e+000,5.499971e+001,5.499314e+001,1,0,3.354839e+000,0.000000e+000,3.603723e+000,3.603723e+000,1.477052e+000,3.317187e-001,3.901237e+000,1.774567e+000,6.292329e-001,3.718191e-005,3.718191e-005,,,,,,,,,,,,,,,,,,,,
1524341374.898,,0.000000e+000,5.499577e+001,5.499314e+001,1,0,3.870968e-001,0.000000e+000,4.841230e+000,4.841230e+000,1.698918e+000,1.567290e+000,5.338550e+000,2.196239e+000,2.064610e+000,5.720799e-005,5.720799e-005,,,,,,,,,,,,,,,,,,,,
1524341374.898,,0.000000e+000,5.499577e+001,5.499314e+001,1,0,1.548387e+000,0.000000e+000,6.137179e-001,6.137179e-001,-2.133708e+000,-2.660222e+000,-5.244988e-001,-3.271925e+000,-3.798439e+000,-3.433442e-005,-3.433442e-005,,,,,,,,,,,,,,,,,,,,
1524341374.898,,0.000000e+000,5.499577e+001,5.499314e+001,1,0,2.709677e+000,0.000000e+000,-7.502861e-001,-7.502861e-001,-3.102827e+000,-4.024226e+000,7.605737e-001,-1.591967e+000,-2.513366e+000,-6.187784e-005,-6.187784e-005,,,,,,,,,,,,,,,,,,,,
1524341374.898,,0.000000e+000,5.499577e+001,5.499314e+001,1,0,3.870968e+000,0.000000e+000,5.145495e+000,5.145495e+000,3.187840e+000,1.871555e+000,3.910688e+000,1.953033e+000,6.367481e-001,7.283391e-005,7.283391e-005,,,,,,,,,,,,,,,,,,,,
1524341387.548,,0.000000e+000,5.499971e+001,5.500103e+001,1,0,9.032258e-001,0.000000e+000,4.375219e+000,4.375219e+000,1.405606e+000,1.094049e+000,3.657866e+000,6.882530e-001,3.766954e-001,4.811668e-005,4.811668e-005,,,,,,,,,,,,,,,,,,,,
1524341387.548,,0.000000e+000,5.499971e+001,5.500103e+001,1,0,2.064516e+000,0.000000e+000,-2.390784e+000,-2.390784e+000,-4.959823e+000,-5.671954e+000,-2.409253e+000,-4.978292e+000,-5.690424e+000,-1.001183e-004,-1.001183e-004,,,,,,,,,,,,,,,,,,,,
1524341387.548,,0.000000e+000,5.499971e+001,5.500103e+001,1,0,3.225806e+000,0.000000e+000,2.825208e+000,2.825208e+000,6.567430e-001,-4.559627e-001,3.466080e+000,1.297616e+000,1.849098e-001,1.944266e-005,1.944266e-005,,,,,,,,,,,,,,,,,,,,
1524341399.888,,0.000000e+000,5.499971e+001,5.499182e+001,1,0,2.580645e-001,0.000000e+000,4.643168e+000,4.643168e+000,1.450218e+000,1.362169e+000,5.331991e+000,2.139040e+000,2.050992e+000,5.233962e-005,5.233962e-005,,,,,,,,,,,,,,,,,,,,
1524341399.888,,0.000000e+000,5.499971e+001,5.499182e+001,1,0,1.419355e+000,0.000000e+000,1.532616e+000,1.532616e+000,-1.264117e+000,-1.748383e+000,3.607996e-001,-2.435933e+000,-2.920199e+000,-1.422898e-005,-1.422898e-005,,,,,,,,,,,,,,,,,,,,
1524341399.888,,0.000000e+000,5.499971e+001,5.499182e+001,1,0,2.580645e+000,0.000000e+000,-1.573663e+000,-1.573663e+000,-3.974178e+000,-4.854661e+000,-3.541869e-002,-2.435934e+000,-3.316417e+000,-8.070207e-005,-8.070207e-005,,,,,,,,,,,,,,,,,,,,
1524341399.888,,0.000000e+000,5.499971e+001,5.499182e+001,1,0,3.741935e+000,0.000000e+000,5.054399e+000,5.054399e+000,3.050101e+000,1.773400e+000,4.143339e+000,2.139041e+000,8.623400e-001,7.038597e-005,7.038597e-005,,,,,,,,,,,,,,,,,,,,
1524341412.598,,0.000000e+000,5.499182e+001,5.499708e+001,1,0,7.741935e-001,0.000000e+000,4.746624e+000,4.746624e+000,1.728944e+000,1.462045e+000,4.316571e+000,1.298891e+000,1.031991e+000,5.601375e-005,5.601375e-005,,,,,,,,,,,,,,,,,,,,
1524341412.598,,0.000000e+000,5.499182e+001,5.499708e+001,1,0,1.935484e+000,0.000000e+000,-1.872892e+000,-1.872892e+000,-4.490222e+000,-5.157472e+000,-2.365851e+000,-4.983181e+000,-5.650430e+000,-8.894892e-005,-8.894892e-005,,,,,,,,,,,,,,,,,,,,
1524341412.598,,0.000000e+000,5.499182e+001,5.499708e+001,1,0,3.096774e+000,0.000000e+000,2.005341e+000,2.005341e+000,-2.116400e-001,-1.279239e+000,2.905909e+000,6.889282e-001,-3.786705e-001,7.116250e-007,7.116250e-007,,,,,,,,,,,,,,,,,,,,
1524341425.598,,0.000000e+000,5.499708e+001,5.500497e+001,1,0,1.290323e-001,0.000000e+000,4.408789e+000,4.408789e+000,1.170603e+000,1.126721e+000,5.197011e+000,1.958824e+000,1.914942e+000,4.674178e-005,4.674178e-005,,,,,,,,,,,,,,,,,,,,
1524341425.598,,0.000000e+000,5.499708e+001,5.500497e+001,1,0,1.290323e+000,0.000000e+000,2.364233e+000,2.364233e+000,-4.790162e-001,-9.178355e-001,1.246563e+000,-1.596686e+000,-2.035505e+000,3.988498e-006,3.988498e-006,,,,,,,,,,,,,,,,,,,,
1524341425.598,,0.000000e+000,5.499708e+001,5.500497e+001,1,0,2.451613e+000,0.000000e+000,-2.218509e+000,-2.218509e+000,-4.666821e+000,-5.500577e+000,-8.333152e-001,-3.281627e+000,-4.115384e+000,-9.549287e-005,-9.549287e-005,,,,,,,,,,,,,,,,,,,,
1524341425.598,,0.000000e+000,5.499708e+001,5.500497e+001,1,0,3.612903e+000,0.000000e+000,4.751659e+000,4.751659e+000,2.698285e+000,1.469591e+000,4.256125e+000,2.202751e+000,9.740572e-001,6.323167e-005,6.323167e-005,,,,,,,,,,,,,,,,,,,,
1524341438.148,,0.000000e+000,5.499445e+001,5.500367e+001,1,0,6.451613e-001,0.000000e+000,4.951095e+000,4.951095e+000,1.879970e+000,1.660423e+000,4.850598e+000,1.779473e+000,1.559926e+000,5.997900e-005,5.997900e-005,,,,,,,,,,,,,,,,,,,,
1524341438.148,,0.000000e+000,5.499445e+001,5.500367e+001,1,0,1.806452e+000,0.000000e+000,-1.126268e+000,-1.126268e+000,-3.802209e+000,-4.416941e+000,-1.978052e+000,-4.653993e+000,-5.268724e+000,-7.290509e-005,-7.290509e-005,,,,,,,,,,,,,,,,,,,,
1524341438.148,,0.000000e+000,5.499445e+001,5.500367e+001,1,0,2.967742e+000,0.000000e+000,1.089036e+000,1.089036e+000,-1.191719e+000,-2.201636e+000,2.267556e+000,-1.319923e-002,-1.023116e+000,-2.044923e-005,-2.044923e-005,,,,,,,,,,,,,,,,,,,,
1524341451.058,,0.000000e+000,5.499051e+001,5.499839e+001,1,0,0.000000e+000,0.000000e+000,4.248569e+000,4.248569e+000,9.448819e-001,9.448819e-001,5.009938e+000,1.706251e+000,1.706251e+000,4.234062e-005,4.234062e-005,,,,,,,,,,,,,,,,,,,,
1524341451.058,,0.000000e+000,5.499051e+001,5.499839e+001,1,0,1.161290e+000,0.000000e+000,3.168536e+000,3.168536e+000,2.592556e-001,-1.351514e-001,2.127805e+000,-7.814756e-001,-1.175883e+000,2.114034e-005,2.114034e-005,,,,,,,,,,,,,,,,,,,,
1524341451.058,,0.000000e+000,5.499051e+001,5.499839e+001,1,0,2.322581e+000,0.000000e+000,-2.554666e+000,-2.554666e+000,-5.069539e+000,-5.858353e+000,-1.537986e+000,-4.052860e+000,-4.841674e+000,-1.038341e-004,-1.038341e-004,,,,,,,,,,,,,,,,,,,,
1524341451.058,,0.000000e+000,5.499051e+001,5.499839e+001,1,0,3.483871e+000,0.000000e+000,4.297246e+000,4.297246e+000,2.176780e+000,9.935584e-001,4.208205e+000,2.087738e+000,9.045172e-001,5.224346e-005,5.224346e-005,,,,,,,,,,,,,,,,,,,,
1524341463.488,,0.000000e+000,5.499839e+001,5.499314e+001,1,0,5.161290e-001,0.000000e+000,4.990921e+000,4.990921e+000,1.854530e+000,1.677791e+000,5.223321e+000,2.086930e+000,1.910191e+000,6.011695e-005,6.011695e-005,,,,,,,,,,,,,,,,,,,,
1524341463.488,,0.000000e+000,5.499839e+001,5.499314e+001,1,0,1.677419e+000,0.000000e+000,-2.500954e-001,-2.500954e-001,-2.988825e+000,-3.563226e+000,-1.312561e+000,-4.051291e+000,-4.625691e+000,-5.405645e-005,-5.405645e-005,,,,,,,,,,,,,,,,,,,,
1524341463.488,,0.000000e+000,5.499839e+001,5.499314e+001,1,0,2.838710e+000,0.000000e+000,1.799039e-001,1.799039e-001,-2.161164e+000,-3.133226e+000,1.559894e+000,-7.811738e-001,-1.753236e+000,-4.148348e-005,-4.148348e-005,,,,,,,,,,,,,,,,,,,,
1524341463.488,,0.000000e+000,5.499839e+001,5.499314e+001,1,0,4.000000e+000,0.000000e+000,5.137102e+000,5.137102e+000,3.193696e+000,1.823972e+000,3.648997e+000,1.705590e+000,3.358665e-001,7.227177e-005,7.227177e-005,,,,,,,,,,,,,,,,,,,,
1524341476.308,,0.000000e+000,5.499971e+001,5.500103e+001,1,0,1.032258e+000,0.000000e+000,3.868620e+000,3.868620e+000,9.079559e-001,5.545893e-001,2.947450e+000,-1.321462e-002,-3.665812e-001,3.633409e-005,3.633409e-005,,,,,,,,,,,,,,,,,,,,
1524341476.308,,0.000000e+000,5.499971e+001,5.500103e+001,1,0,2.193548e+000,0.000000e+000,-2.626230e+000,-2.626230e+000,-5.189357e+000,-5.940261e+000,-2.096319e+000,-4.659446e+000,-5.410350e+000,-1.058633e-004,-1.058633e-004,,,,,,,,,,,,,,,,,,,,
1524341476.308,,0.000000e+000,5.499971e+001,5.500103e+001,1,0,3.354839e+000,0.000000e+000,3.643397e+000,3.643397e+000,1.477807e+000,3.293660e-001,3.947147e+000,1.781557e+000,6.331158e-001,3.722365e-005,3.722365e-005,,,,,,,,,,,,,,,,,,,,
1524341488.678,,0.000000e+000,5.499445e+001,5.499971e+001,1,0,3.870968e-001,0.000000e+000,4.906996e+000,4.906996e+000,1.716284e+000,1.583995e+000,5.396090e+000,2.205378e+000,2.073088e+000,5.768318e-005,5.768318e-005,,,,,,,,,,,,,,,,,,,,
1524341488.678,,0.000000e+000,5.499445e+001,5.499971e+001,1,0,1.548387e+000,0.000000e+000,6.337072e-001,6.337072e-001,-2.160138e+000,-2.689294e+000,-4.916947e-001,-3.285540e+000,-3.814696e+000,-3.486758e-005,-3.486758e-005,,,,,,,,,,,,,,,,,,,,
1524341488.678,,0.000000e+000,5.499445e+001,5.499971e+001,1,0,2.709677e+000,0.000000e+000,-7.487602e-001,-7.487602e-001,-3.145739e+000,-4.071762e+000,7.983868e-001,-1.598592e+000,-2.524615e+000,-6.280890e-005,-6.280890e-005,,,,,,,,,,,,,,,,,,,,
1524341488.678,,0.000000e+000,5.499445e+001,5.499971e+001,1,0,3.870968e+000,0.000000e+000,5.205463e+000,5.205463e+000,3.205352e+000,1.882461e+000,3.961271e+000,1.961160e+000,6.382694e-001,7.322378e-005,7.322378e-005,,,,,,,,,,,,,,,,,,,,
1524341501.518,,0.000000e+000,5.499577e+001,5.499577e+001,1,0,9.032258e-001,0.000000e+000,4.427253e+000,4.427253e+000,1.405469e+000,1.096692e+000,3.713046e+000,6.912622e-001,3.824852e-001,4.811168e-005,4.811168e-005,,,,,,,,,,,,,,,,,,,,
1524341501.518,,0.000000e+000,5.499577e+001,5.499577e+001,1,0,2.064516e+000,0.000000e+000,-2.352026e+000,-2.352026e+000,-4.976810e+000,-5.682587e+000,-2.375274e+000,-5.000059e+000,-5.705834e+000,-1.004466e-004,-1.004466e-004,,,,,,,,,,,,,,,,,,,,
1524341501.518,,0.000000e+000,5.499577e+001,5.499577e+001,1,0,3.225806e+000,0.000000e+000,2.935683e+000,2.935683e+000,7.078977e-001,-3.948774e-001,3.531075e+000,1.303289e+000,2.005138e-001,2.069057e-005,2.069057e-005,,,,,,,,,,,,,,,,,,,,
1524341513.898,,0.000000e+000,5.499708e+001,5.499839e+001,1,0,2.580645e-001,0.000000e+000,4.706035e+000,4.706035e+000,1.453524e+000,1.365524e+000,5.401906e+000,2.149394e+000,2.061394e+000,5.246224e-005,5.246224e-005,,,,,,,,,,,,,,,,,,,,
1524341513.898,,0.000000e+000,5.499708e+001,5.499839e+001,1,0,1.419355e+000,0.000000e+000,1.548943e+000,1.548943e+000,-1.307567e+000,-1.791568e+000,4.087865e-001,-2.447724e+000,-2.931725e+000,-1.514812e-005,-1.514812e-005,,,,,,,,,,,,,,,,,,,,
1524341513.898,,0.000000e+000,5.499708e+001,5.499839e+001,1,0,2.580645e+000,0.000000e+000,-1.521782e+000,-1.521782e+000,-3.982292e+000,-4.862294e+000,1.278518e-002,-2.447725e+000,-3.327726e+000,-8.082821e-005,-8.082821e-005,,,,,,,,,,,,,,,,,,,,
1524341513.898,,0.000000e+000,5.499708e+001,5.499839e+001,1,0,3.741935e+000,0.000000e+000,5.127184e+000,5.127184e+000,3.062674e+000,1.786673e+000,4.213904e+000,2.149394e+000,8.733926e-001,7.072542e-005,7.072542e-005,,,,,,,,,,,,,,,,,,,,
1524341526.738,,0.000000e+000,5.498393e+001,5.500235e+001,1,0,7.741935e-001,0.000000e+000,4.821088e+000,4.821088e+000,1.747909e+000,1.480916e+000,4.378822e+000,1.305643e+000,1.038650e+000,5.649735e-005,5.649735e-005,,,,,,,,,,,,,,,,,,,,
1524341526.738,,0.000000e+000,5.498393e+001,5.500235e+001,1,0,1.935484e+000,0.000000e+000,-1.830014e+000,-1.830014e+000,-4.502705e+000,-5.170186e+000,-2.336392e+000,-5.009083e+000,-5.676563e+000,-8.917023e-005,-8.917023e-005,,,,,,,,,,,,,,,,,,,,
1524341526.738,,0.000000e+000,5.498393e+001,5.500235e+001,1,0,3.096774e+000,0.000000e+000,2.050050e+000,2.050050e+000,-2.221528e-001,-1.290122e+000,2.964712e+000,6.925094e-001,-3.754599e-001,5.322727e-007,5.322727e-007,,,,,,,,,,,,,,,,,,,,
1524341539.148,,0.000000e+000,5.499971e+001,5.500103e+001,1,0,1.290323e-001,0.000000e+000,4.444953e+000,4.444953e+000,1.157593e+000,1.112974e+000,5.253311e+000,1.965952e+000,1.921332e+000,4.665080e-005,4.665080e-005,,,,,,,,,,,,,,,,,,,,
1524341539.148,,0.000000e+000,5.499971e+001,5.500103e+001,1,0,1.290323e+000,0.000000e+000,2.394903e+000,2.394903e+000,-4.908794e-001,-9.370759e-001,1.283287e+000,-1.602496e+000,-2.048692e+000,3.824207e-006,3.824207e-006,,,,,,,,,,,,,,,,,,,,
1524341539.148,,0.000000e+000,5.499971e+001,5.500103e+001,1,0,2.451613e+000,0.000000e+000,-2.196689e+000,-2.196689e+000,-4.680895e+000,-5.528668e+000,-8.093618e-001,-3.293568e+000,-4.141341e+000,-9.580550e-005,-9.580550e-005,,,,,,,,,,,,,,,,,,,,
1524341539.148,,0.000000e+000,5.499971e+001,5.500103e+001,1,0,3.612903e+000,0.000000e+000,4.792248e+000,4.792248e+000,2.709619e+000,1.460269e+000,4.293395e+000,2.210766e+000,9.614158e-001,6.338798e-005,6.338798e-005,,,,,,,,,,,,,,,,,,,,
1524341551.968,,0.000000e+000,5.499708e+001,5.500103e+001,1,0,6.451613e-001,0.000000e+000,4.986801e+000,4.986801e+000,1.886021e+000,1.664267e+000,4.888048e+000,1.787269e+000,1.565514e+000,6.023191e-005,6.023191e-005,,,,,,,,,,,,,,,,,,,,
1524341551.968,,0.000000e+000,5.499708e+001,5.500103e+001,1,0,1.806452e+000,0.000000e+000,-1.119860e+000,-1.119860e+000,-3.821482e+000,-4.442393e+000,-1.972760e+000,-4.674382e+000,-5.295294e+000,-7.327738e-005,-7.327738e-005,,,,,,,,,,,,,,,,,,,,
1524341551.968,,0.000000e+000,5.499708e+001,5.500103e+001,1,0,2.967742e+000,0.000000e+000,1.131456e+000,1.131456e+000,-1.171008e+000,-2.191077e+000,2.289208e+000,-1.325708e-002,-1.033326e+000,-1.998709e-005,-1.998709e-005,,,,,,,,,,,,,,,,,,,,
1524341551.968,,0.000000e+000,5.499708e+001,5.500103e+001,1,0,4.000000e+000,0.000000e+000,5.150225e+000,5.150225e+000,3.202567e+000,1.827691e+000,3.659930e+000,1.712271e+000,3.373957e-001,7.247511e-005,7.247511e-005,,,,,,,,,,,,,,,,,,,,