File: Experimental Raw Data/TC04-12-01K VRMac VRMde/raw/TC04-12-01K_VRMac_57K_6000s.dc.raw
[Header]
TITLE,MPMS DC Measurement
BYAPP,MPMS Measurement,2.1,Raw with ABS
FILEOPENTIME, 1524318854.668000 4/21/2018, 7:54:14 AM

INFO, APPNAME, MPMS MultiVu Application, Revision 1.61,  Build 082

INFO, NAME, TC04-12-01K
INFO, WEIGHT, 1.000
INFO, AREA, 1.000
INFO, LENGTH, 1.000
INFO, SHAPE, 0
INFO, COMMENT,
INFO, SEQUENCE FILE: VRMac_57K_6000s_VRMde_55K.seq


INFO, BACKGROUND DATA FILE:, None


STARTUPAXIS,X,8,LINEAR,AUTO,0.000000,0.000000
STARTUPAXIS,Y1,10,LINEAR,AUTO,0.000000,0.000000


STARTUPGROUP,Longitudinal
FIELDGROUP,Longitudinal,1,3,4,5,6,8,9,10,11,12,13,14,15,16,17,18,19,20,21,22,23
FIELDGROUP,Transverse,1,3,4,5,6,8,9,24,25,26,27,28,29,30,31,32,33,34,35,36,37

PLOT_APPEARANCE,ALL,HORZ_GRID_ON,VERT_GRID_ON,MARKERS_ONLY

[Data]
Time,Comment,Field (Oe),Start Temperature (K),End Temperature (K),Scan,Rejected,Position (cm),Rot Position (deg),Long Voltage,Long Average Voltage,Long Detrended Voltage,Long Demeaned Voltage,Long Regression Fit,Long Detrended Fit,Long Demeaned Fit,Long Scaled Response,Long Avg. Scaled Response,Long Background Response,Long Response [w/ABS],Long Detrended Resp. [w/ABS],Long Fit [w/ABS],Long Detrended Fit [w/ABS],Trans Voltage,Trans Average Voltage,Trans Detrended Voltage,Trans Demeaned Voltage,Trans Regression Fit,Trans Detrended Fit,Trans Demeaned Fit,Trans Scaled Response,Trans Avg Scaled Response,Trans Background Response,Trans Response [w/ABS],Trans Detrended Resp. [w/ABS],Trans Fit [w/ABS],Trans Detrended Fit [w/ABS],
1524318854.648,,0.000000e+000,5.709012e+001,5.707466e+001,1,0,0.000000e+000,0.000000e+000,-3.526055e+000,-3.526055e+000,6.529999e-001,6.529999e-001,-2.875514e+000,1.303541e+000,1.303541e+000,3.030973e-005,3.030973e-005,,,,,,,,,,,,,,,,,,,,
1524318879.798,,0.000000e+000,5.707044e+001,5.705640e+001,1,0,2.580645e-001,0.000000e+000,-2.975814e+000,-2.975814e+000,1.147292e+000,1.075430e+000,-2.366135e+000,1.756971e+000,1.685109e+000,4.196368e-005,4.196368e-005,,,,,,,,,,,,,,,,,,,,
1524318904.498,,0.000000e+000,5.704797e+001,5.704656e+001,1,0,5.161290e-001,0.000000e+000,-2.561532e+000,-2.561532e+000,1.568442e+000,1.412895e+000,-2.365200e+000,1.764774e+000,1.609226e+000,5.110203e-005,5.110203e-005,,,,,,,,,,,,,,,,,,,,
1524318929.328,,0.000000e+000,5.702832e+001,5.703112e+001,1,0,7.741935e-001,0.000000e+000,-2.676432e+000,-2.676432e+000,1.527809e+000,1.292468e+000,-3.079568e+000,1.124674e+000,8.893323e-001,4.928836e-005,4.928836e-005,,,,,,,,,,,,,,,,,,,,
1524318954.328,,0.000000e+000,5.702832e+001,5.702692e+001,1,0,1.032258e+000,0.000000e+000,-3.443961e+000,-3.443961e+000,8.253289e-001,5.056281e-001,-4.280886e+000,-1.159611e-002,-3.312969e-001,3.265699e-005,3.265699e-005,,,,,,,,,,,,,,,,,,,,
1524318979.528,,0.000000e+000,5.701569e+001,5.701709e+001,1,0,1.290323e+000,0.000000e+000,-4.680858e+000,-4.680858e+000,-3.558691e-001,-7.602952e-001,-5.746202e+000,-1.421213e+000,-1.825639e+000,5.239301e-006,5.239301e-006,,,,,,,,,,,,,,,,,,,,
1524319004.978,,0.000000e+000,5.701850e+001,5.700587e+001,1,0,1.548387e+000,0.000000e+000,-6.227512e+000,-6.227512e+000,-1.855700e+000,-2.344115e+000,-7.323815e+000,-2.952003e+000,-3.440418e+000,-2.936850e-005,-2.936850e-005,,,,,,,,,,,,,,,,,,,,
1524319029.648,,0.000000e+000,5.700728e+001,5.701148e+001,1,0,1.806452e+000,0.000000e+000,-7.830625e+000,-7.830625e+000,-3.412687e+000,-3.988011e+000,-8.645847e+000,-4.227910e+000,-4.803233e+000,-6.527778e-005,-6.527778e-005,,,,,,,,,,,,,,,,,,,,
1524319054.988,,0.000000e+000,5.701008e+001,5.700447e+001,1,0,2.064516e+000,0.000000e+000,-9.053178e+000,-9.053178e+000,-4.569709e+000,-5.237267e+000,-9.054199e+000,-4.570730e+000,-5.238288e+000,-9.228439e-005,-9.228439e-005,,,,,,,,,,,,,,,,,,,,
1524319080.638,,0.000000e+000,5.699465e+001,5.699746e+001,1,0,2.322581e+000,0.000000e+000,-9.294881e+000,-9.294881e+000,-4.720712e+000,-5.487775e+000,-8.308586e+000,-3.734417e+000,-4.501480e+000,-9.686514e-005,-9.686514e-005,,,,,,,,,,,,,,,,,,,,
1524319104.988,,0.000000e+000,5.700167e+001,5.700167e+001,1,0,2.580645e+000,0.000000e+000,-8.407111e+000,-8.407111e+000,-3.749797e+000,-4.600190e+000,-6.919709e+000,-2.262395e+000,-3.112788e+000,-7.637512e-005,-7.637512e-005,,,,,,,,,,,,,,,,,,,,
1524319129.859,,0.000000e+000,5.700167e+001,5.699886e+001,1,0,2.838710e+000,0.000000e+000,-6.796521e+000,-6.796521e+000,-2.069382e+000,-3.001052e+000,-5.454595e+000,-7.274566e-001,-1.659127e+000,-4.001745e-005,-4.001745e-005,,,,,,,,,,,,,,,,,,,,
1524319154.579,,0.000000e+000,5.700167e+001,5.700306e+001,1,0,3.096774e+000,0.000000e+000,-5.008926e+000,-5.008926e+000,-2.346393e-001,-1.259181e+000,-4.128685e+000,6.456020e-001,-3.789401e-001,-2.717134e-007,-2.717134e-007,,,,,,,,,,,,,,,,,,,,
1524319180.039,,0.000000e+000,5.698624e+001,5.701148e+001,1,0,3.354839e+000,0.000000e+000,-3.452354e+000,-3.452354e+000,1.388430e+000,2.683680e-001,-3.168013e+000,1.672770e+000,5.527084e-001,3.471876e-005,3.471876e-005,,,,,,,,,,,,,,,,,,,,
1524319205.339,,0.000000e+000,5.699746e+001,5.699186e+001,1,0,3.612903e+000,0.000000e+000,-2.329595e+000,-2.329595e+000,2.588490e+000,1.376601e+000,-2.839225e+000,2.078861e+000,8.669710e-001,6.026537e-005,6.026537e-005,,,,,,,,,,,,,,,,,,,,
1524319231.269,,0.000000e+000,5.700026e+001,5.699746e+001,1,0,3.870968e+000,0.000000e+000,-1.908293e+000,-1.908293e+000,3.093393e+000,1.784475e+000,-3.144077e+000,1.857609e+000,5.486913e-001,7.023540e-005,7.023540e-005,,,,,,,,,,,,,,,,,,,,
1524319268.989,,0.000000e+000,5.699746e+001,5.700026e+001,1,0,0.000000e+000,0.000000e+000,-2.825055e+000,-2.825055e+000,8.585305e-001,8.585305e-001,-2.057845e+000,1.625741e+000,1.625741e+000,3.980599e-005,3.980599e-005,,,,,,,,,,,,,,,,,,,,
1524319294.429,,0.000000e+000,5.699465e+001,5.699465e+001,1,0,2.580645e-001,0.000000e+000,-2.353857e+000,-2.353857e+000,1.376627e+000,1.288836e+000,-1.680988e+000,2.049496e+000,1.961705e+000,5.020549e-005,5.020549e-005,,,,,,,,,,,,,,,,,,,,
1524319319.129,,0.000000e+000,5.699746e+001,5.701008e+001,1,0,5.161290e-001,0.000000e+000,-2.036164e+000,-2.036164e+000,1.782221e+000,1.604481e+000,-1.816738e+000,2.001648e+000,1.823907e+000,5.809026e-005,5.809026e-005,,,,,,,,,,,,,,,,,,,,
1524319344.839,,0.000000e+000,5.699045e+001,5.700167e+001,1,0,7.741935e-001,0.000000e+000,-2.247959e+000,-2.247959e+000,1.661872e+000,1.396887e+000,-2.657036e+000,1.252795e+000,9.878109e-001,5.407647e-005,5.407647e-005,,,,,,,,,,,,,,,,,,,,
1524319370.379,,0.000000e+000,5.699746e+001,5.699465e+001,1,0,1.032258e+000,0.000000e+000,-3.062638e+000,-3.062638e+000,9.096397e-001,5.585713e-001,-3.985029e+000,-1.275095e-002,-3.638194e-001,3.595008e-005,3.595008e-005,,,,,,,,,,,,,,,,,,,,
1524319396.029,,0.000000e+000,5.699606e+001,5.700026e+001,1,0,1.290323e+000,0.000000e+000,-4.443427e+000,-4.443427e+000,-4.020700e-001,-8.442297e-001,-5.586437e+000,-1.545080e+000,-1.987239e+000,5.376918e-006,5.376918e-006,,,,,,,,,,,,,,,,,,,,
1524319421.329,,0.000000e+000,5.699746e+001,5.699045e+001,1,0,1.548387e+000,0.000000e+000,-6.159609e+000,-6.159609e+000,-2.042149e+000,-2.574633e+000,-7.302438e+000,-3.184978e+000,-3.717462e+000,-3.255621e-005,-3.255621e-005,,,,,,,,,,,,,,,,,,,,
1524319446.129,,0.000000e+000,5.699606e+001,5.700306e+001,1,0,1.806452e+000,0.000000e+000,-7.890440e+000,-7.890440e+000,-3.685070e+000,-4.309594e+000,-8.734679e+000,-4.529309e+000,-5.153833e+000,-7.056858e-005,-7.056858e-005,,,,,,,,,,,,,,,,,,,,
1524319472.129,,0.000000e+000,5.699746e+001,5.699746e+001,1,0,2.064516e+000,0.000000e+000,-9.128557e+000,-9.128557e+000,-4.847235e+000,-5.557994e+000,-9.149670e+000,-4.868348e+000,-5.579106e+000,-9.784570e-005,-9.784570e-005,,,,,,,,,,,,,,,,,,,,
1524319497.219,,0.000000e+000,5.701008e+001,5.700306e+001,1,0,2.322581e+000,0.000000e+000,-9.368734e+000,-9.368734e+000,-5.010187e+000,-5.815931e+000,-8.321075e+000,-3.962528e+000,-4.768272e+000,-1.027900e-004,-1.027900e-004,,,,,,,,,,,,,,,,,,,,
1524319523.359,,0.000000e+000,5.699746e+001,5.699886e+001,1,0,2.580645e+000,0.000000e+000,-8.419471e+000,-8.419471e+000,-3.963701e+000,-4.862306e+000,-6.846025e+000,-2.390255e+000,-3.288860e+000,-8.073627e-005,-8.073627e-005,,,,,,,,,,,,,,,,,,,,
1524319548.509,,0.000000e+000,5.699186e+001,5.700587e+001,1,0,2.838710e+000,0.000000e+000,-6.691386e+000,-6.691386e+000,-2.147659e+000,-3.143428e+000,-5.310600e+000,-7.668728e-001,-1.762642e+000,-4.148917e-005,-4.148917e-005,,,,,,,,,,,,,,,,,,,,
1524319573.779,,0.000000e+000,5.700026e+001,5.699606e+001,1,0,3.096774e+000,0.000000e+000,-4.892195e+000,-4.892195e+000,-2.462579e-001,-1.323105e+000,-3.966657e+000,6.792806e-001,-3.975661e-001,-2.659945e-007,-2.659945e-007,,,,,,,,,,,,,,,,,,,,
1524319599.439,,0.000000e+000,5.700306e+001,5.699325e+001,1,0,3.354839e+000,0.000000e+000,-3.260700e+000,-3.260700e+000,1.472963e+000,3.103178e-001,-2.977637e+000,1.756027e+000,5.933816e-001,3.687076e-005,3.687076e-005,,,,,,,,,,,,,,,,,,,,
1524319624.459,,0.000000e+000,5.699465e+001,5.699465e+001,1,0,3.612903e+000,0.000000e+000,-2.125124e+000,-2.125124e+000,2.675918e+000,1.422822e+000,-2.627074e+000,2.173968e+000,9.208713e-001,6.242443e-005,6.242443e-005,,,,,,,,,,,,,,,,,,,,
1524319649.689,,0.000000e+000,5.699746e+001,5.699746e+001,1,0,3.870968e+000,0.000000e+000,-1.695888e+000,-1.695888e+000,3.185628e+000,1.832278e+000,-2.943891e+000,1.937624e+000,5.842745e-001,7.243024e-005,7.243024e-005,,,,,,,,,,,,,,,,,,,,
1524319687.359,,0.000000e+000,5.699886e+001,5.698904e+001,1,0,0.000000e+000,0.000000e+000,-2.616922e+000,-2.616922e+000,9.130063e-001,9.130063e-001,-1.838395e+000,1.691533e+000,1.691533e+000,4.183015e-005,4.183015e-005,,,,,,,,,,,,,,,,,,,,
1524319712.499,,0.000000e+000,5.699465e+001,5.700587e+001,1,0,2.580645e-001,0.000000e+000,-2.178836e+000,-2.178836e+000,1.437560e+000,1.347514e+000,-1.485226e+000,2.131170e+000,2.041123e+000,5.221694e-005,5.221694e-005,,,,,,,,,,,,,,,,,,,,
1524319738.319,,0.000000e+000,5.699606e+001,5.699186e+001,1,0,5.161290e-001,0.000000e+000,-1.855955e+000,-1.855955e+000,1.848228e+000,1.667629e+000,-1.627062e+000,2.077121e+000,1.896523e+000,6.008925e-005,6.008925e-005,,,,,,,,,,,,,,,,,,,,
1524319762.679,,0.000000e+000,5.700587e+001,5.700167e+001,1,0,7.741935e-001,0.000000e+000,-2.063478e+000,-2.063478e+000,1.736388e+000,1.466697e+000,-2.501905e+000,1.297960e+000,1.028270e+000,5.623800e-005,5.623800e-005,,,,,,,,,,,,,,,,,,,,
1524319787.539,,0.000000e+000,5.701008e+001,5.699606e+001,1,0,1.032258e+000,0.000000e+000,-2.929885e+000,-2.929885e+000,9.305811e-001,5.693901e-001,-3.873656e+000,-1.318932e-002,-3.743804e-001,3.692774e-005,3.692774e-005,,,,,,,,,,,,,,,,,,,,
1524319813.089,,0.000000e+000,5.699465e+001,5.699886e+001,1,0,1.290323e+000,0.000000e+000,-4.391089e+000,-4.391089e+000,-4.554464e-001,-9.064410e-001,-5.530439e+000,-1.594796e+000,-2.045791e+000,4.601927e-006,4.601927e-006,,,,,,,,,,,,,,,,,,,,
1524319838.270,,0.000000e+000,5.699606e+001,5.700167e+001,1,0,1.548387e+000,0.000000e+000,-6.111391e+000,-6.111391e+000,-2.090596e+000,-2.637438e+000,-7.303483e+000,-3.282689e+000,-3.829530e+000,-3.324613e-005,-3.324613e-005,,,,,,,,,,,,,,,,,,,,
1524319863.230,,0.000000e+000,5.699746e+001,5.699325e+001,1,0,1.806452e+000,0.000000e+000,-7.918059e+000,-7.918059e+000,-3.796277e+000,-4.434458e+000,-8.786959e+000,-4.665176e+000,-5.303357e+000,-7.270843e-005,-7.270843e-005,,,,,,,,,,,,,,,,,,,,
1524319888.720,,0.000000e+000,5.699325e+001,5.699465e+001,1,0,2.064516e+000,0.000000e+000,-9.209888e+000,-9.209888e+000,-4.995001e+000,-5.721469e+000,-9.231462e+000,-5.016576e+000,-5.743044e+000,-1.008261e-004,-1.008261e-004,,,,,,,,,,,,,,,,,,,,
1524319914.070,,0.000000e+000,5.699465e+001,5.700447e+001,1,0,2.322581e+000,0.000000e+000,-9.418784e+000,-9.418784e+000,-5.120656e+000,-5.940562e+000,-8.373378e+000,-4.075250e+000,-4.895156e+000,-1.049796e-004,-1.049796e-004,,,,,,,,,,,,,,,,,,,,
1524319939.230,,0.000000e+000,5.700167e+001,5.699746e+001,1,0,2.580645e+000,0.000000e+000,-8.422675e+000,-8.422675e+000,-4.037214e+000,-4.948377e+000,-6.845286e+000,-2.459826e+000,-3.370988e+000,-8.210517e-005,-8.210517e-005,,,,,,,,,,,,,,,,,,,,
1524319965.140,,0.000000e+000,5.701008e+001,5.699886e+001,1,0,2.838710e+000,0.000000e+000,-6.670329e+000,-6.670329e+000,-2.204619e+000,-3.203662e+000,-5.253754e+000,-7.880440e-001,-1.787087e+000,-4.247589e-005,-4.247589e-005,,,,,,,,,,,,,,,,,,,,
1524319990.280,,0.000000e+000,5.700167e+001,5.699886e+001,1,0,3.096774e+000,0.000000e+000,-4.783703e+000,-4.783703e+000,-2.354519e-001,-1.341866e+000,-3.851244e+000,6.970069e-001,-4.094071e-001,1.044828e-007,1.044828e-007,,,,,,,,,,,,,,,,,,,,
1524320015.970,,0.000000e+000,5.700447e+001,5.699186e+001,1,0,3.354839e+000,0.000000e+000,-3.137408e+000,-3.137408e+000,1.506369e+000,3.129718e-001,-2.842564e+000,1.801213e+000,6.078155e-001,3.771402e-005,3.771402e-005,,,,,,,,,,,,,,,,,,,,
1524320041.220,,0.000000e+000,5.700026e+001,5.699325e+001,1,0,3.612903e+000,0.000000e+000,-1.982300e+000,-1.982300e+000,2.753360e+000,1.474726e+000,-2.507048e+000,2.228611e+000,9.499774e-001,6.426070e-005,6.426070e-005,,,,,,,,,,,,,,,,,,,,
1524320066.930,,0.000000e+000,5.700306e+001,5.700728e+001,1,0,3.870968e+000,0.000000e+000,-1.577020e+000,-1.577020e+000,3.260361e+000,1.875370e+000,-2.852154e+000,1.985227e+000,6.002357e-001,7.414239e-005,7.414239e-005,,,,,,,,,,,,,,,,,,,,
1524320103.920,,0.000000e+000,5.699606e+001,5.699606e+001,1,0,0.000000e+000,0.000000e+000,-2.522927e+000,-2.522927e+000,9.364707e-001,9.364707e-001,-1.729266e+000,1.730132e+000,1.730132e+000,4.277240e-005,4.277240e-005,,,,,,,,,,,,,,,,,,,,
1524320129.920,,0.000000e+000,5.699746e+001,5.699746e+001,1,0,2.580645e-001,0.000000e+000,-2.075227e+000,-2.075227e+000,1.478527e+000,1.387526e+000,-1.374391e+000,2.179364e+000,2.088363e+000,5.347801e-005,5.347801e-005,,,,,,,,,,,,,,,,,,,,
1524320155.000,,0.000000e+000,5.700167e+001,5.700306e+001,1,0,5.161290e-001,0.000000e+000,-1.737697e+000,-1.737697e+000,1.894482e+000,1.711110e+000,-1.508516e+000,2.123663e+000,1.940291e+000,6.148937e-005,6.148937e-005,,,,,,,,,,,,,,,,,,,,
1524320180.250,,0.000000e+000,5.699325e+001,5.699465e+001,1,0,7.741935e-001,0.000000e+000,-1.945373e+000,-1.945373e+000,1.773351e+000,1.497713e+000,-2.393539e+000,1.325185e+000,1.049546e+000,5.743658e-005,5.743658e-005,,,,,,,,,,,,,,,,,,,,
1524320205.270,,0.000000e+000,5.700587e+001,5.699886e+001,1,0,1.032258e+000,0.000000e+000,-2.875563e+000,-2.875563e+000,9.262546e-001,5.557842e-001,-3.815287e+000,-1.346934e-002,-3.839397e-001,3.719609e-005,3.719609e-005,,,,,,,,,,,,,,,,,,,,
1524320230.470,,0.000000e+000,5.699465e+001,5.699465e+001,1,0,1.290323e+000,0.000000e+000,-4.335851e+000,-4.335851e+000,-4.436572e-001,-9.015648e-001,-5.522475e+000,-1.630281e+000,-2.088188e+000,5.168709e-006,5.168709e-006,,,,,,,,,,,,,,,,,,,,
1524320255.360,,0.000000e+000,5.699886e+001,5.699606e+001,1,0,1.548387e+000,0.000000e+000,-6.137178e+000,-6.137178e+000,-2.153899e+000,-2.702272e+000,-7.337711e+000,-3.354432e+000,-3.902805e+000,-3.441166e-005,-3.441166e-005,,,,,,,,,,,,,,,,,,,,
1524320280.520,,0.000000e+000,5.699606e+001,5.700587e+001,1,0,1.806452e+000,0.000000e+000,-7.947661e+000,-7.947661e+000,-3.877815e+000,-4.521703e+000,-8.835383e+000,-4.765537e+000,-5.409425e+000,-7.428251e-005,-7.428251e-005,,,,,,,,,,,,,,,,,,,,
1524320305.710,,0.000000e+000,5.700167e+001,5.699606e+001,1,0,2.064516e+000,0.000000e+000,-9.269398e+000,-9.269398e+000,-5.105073e+000,-5.842197e+000,-9.283193e+000,-5.118868e+000,-5.855992e+000,-1.030638e-004,-1.030638e-004,,,,,,,,,,,,,,,,,,,,
1524320330.750,,0.000000e+000,5.700167e+001,5.700167e+001,1,0,2.322581e+000,0.000000e+000,-9.459373e+000,-9.459373e+000,-5.205683e+000,-6.038639e+000,-8.403573e+000,-4.149883e+000,-4.982839e+000,-1.067025e-004,-1.067025e-004,,,,,,,,,,,,,,,,,,,,
1524320355.980,,0.000000e+000,5.699886e+001,5.699325e+001,1,0,2.580645e+000,0.000000e+000,-8.458228e+000,-8.458228e+000,-4.113085e+000,-5.038901e+000,-6.850773e+000,-2.505630e+000,-3.431446e+000,-8.364179e-005,-8.364179e-005,,,,,,,,,,,,,,,,,,,,
1524320381.010,,0.000000e+000,5.699045e+001,5.699045e+001,1,0,2.838710e+000,0.000000e+000,-6.682689e+000,-6.682689e+000,-2.249058e+000,-3.263090e+000,-5.237099e+000,-8.034683e-001,-1.817501e+000,-4.331591e-005,-4.331591e-005,,,,,,,,,,,,,,,,,,,,
1524320406.280,,0.000000e+000,5.699465e+001,5.700587e+001,1,0,3.096774e+000,0.000000e+000,-4.758678e+000,-4.758678e+000,-2.327350e-001,-1.342209e+000,-3.815874e+000,7.100696e-001,-3.994045e-001,3.590685e-007,3.590685e-007,,,,,,,,,,,,,,,,,,,,
1524320430.690,,0.000000e+000,5.700306e+001,5.699606e+001,1,0,3.354839e+000,0.000000e+000,-3.085374e+000,-3.085374e+000,1.524139e+000,3.335881e-001,-2.777178e+000,1.832335e+000,6.417844e-001,3.832231e-005,3.832231e-005,,,,,,,,,,,,,,,,,,,,
1524320456.370,,0.000000e+000,5.699746e+001,5.700306e+001,1,0,3.612903e+000,0.000000e+000,-1.905089e+000,-1.905089e+000,2.805738e+000,1.513135e+000,-2.443328e+000,2.267499e+000,9.748962e-001,6.553438e-005,6.553438e-005,,,,,,,,,,,,,,,,,,,,
1524320481.060,,0.000000e+000,5.701148e+001,5.699045e+001,1,0,3.870968e+000,0.000000e+000,-1.475853e+000,-1.475853e+000,3.320612e+000,1.938654e+000,-2.777395e+000,2.019069e+000,6.371109e-001,7.570253e-005,7.570253e-005,,,,,,,,,,,,,,,,,,,,
1524320518.430,,0.000000e+000,5.699886e+001,5.699186e+001,1,0,0.000000e+000,0.000000e+000,-2.443427e+000,-2.443427e+000,9.642391e-001,9.642391e-001,-1.647609e+000,1.760057e+000,1.760057e+000,4.367370e-005,4.367370e-005,,,,,,,,,,,,,,,,,,,,
1524320543.161,,0.000000e+000,5.700026e+001,5.699045e+001,1,0,2.580645e-001,0.000000e+000,-1.992370e+000,-1.992370e+000,1.508470e+000,1.415667e+000,-1.286888e+000,2.213952e+000,2.121150e+000,5.450755e-005,5.450755e-005,,,,,,,,,,,,,,,,,,,,
1524320568.261,,0.000000e+000,5.699606e+001,5.699186e+001,1,0,5.161290e-001,0.000000e+000,-1.667659e+000,-1.667659e+000,1.927068e+000,1.742583e+000,-1.438604e+000,2.156123e+000,1.971638e+000,6.243789e-005,6.243789e-005,,,,,,,,,,,,,,,,,,,,
1524320593.271,,0.000000e+000,5.698765e+001,5.699606e+001,1,0,7.741935e-001,0.000000e+000,-1.882506e+000,-1.882506e+000,1.796339e+000,1.518261e+000,-2.333170e+000,1.345674e+000,1.067596e+000,5.818259e-005,5.818259e-005,,,,,,,,,,,,,,,,,,,,
1524320618.241,,0.000000e+000,5.698904e+001,5.699886e+001,1,0,1.032258e+000,0.000000e+000,-2.823072e+000,-2.823072e+000,9.581712e-001,5.906405e-001,-3.794915e+000,-1.367179e-002,-3.812025e-001,3.803843e-005,3.803843e-005,,,,,,,,,,,,,,,,,,,,
1524320643.151,,0.000000e+000,5.700447e+001,5.699746e+001,1,0,1.290323e+000,0.000000e+000,-4.360571e+000,-4.360571e+000,-4.884347e-001,-9.505327e-001,-5.525815e+000,-1.653679e+000,-2.115777e+000,4.364920e-006,4.364920e-006,,,,,,,,,,,,,,,,,,,,
1524320667.991,,0.000000e+000,5.699325e+001,5.699325e+001,1,0,1.548387e+000,0.000000e+000,-6.184635e+000,-6.184635e+000,-2.214907e+000,-2.768772e+000,-7.374204e+000,-3.404477e+000,-3.958342e+000,-3.558207e-005,-3.558207e-005,,,,,,,,,,,,,,,,,,,,
1524320693.741,,0.000000e+000,5.700167e+001,5.699886e+001,1,0,1.806452e+000,0.000000e+000,-8.009308e+000,-8.009308e+000,-3.945924e+000,-4.593804e+000,-8.894405e+000,-4.831021e+000,-5.478902e+000,-7.564222e-005,-7.564222e-005,,,,,,,,,,,,,,,,,,,,
1524320719.231,,0.000000e+000,5.700306e+001,5.699746e+001,1,0,2.064516e+000,0.000000e+000,-9.353170e+000,-9.353170e+000,-5.178532e+000,-5.924777e+000,-9.359720e+000,-5.185082e+000,-5.931327e+000,-1.045627e-004,-1.045627e-004,,,,,,,,,,,,,,,,,,,,
1524320744.271,,0.000000e+000,5.699186e+001,5.699465e+001,1,0,2.322581e+000,0.000000e+000,-9.542687e+000,-9.542687e+000,-5.270911e+000,-6.104010e+000,-8.480919e+000,-4.209142e+000,-5.042241e+000,-1.079983e-004,-1.079983e-004,,,,,,,,,,,,,,,,,,,,
1524320769.061,,0.000000e+000,5.700587e+001,5.699606e+001,1,0,2.580645e+000,0.000000e+000,-8.504921e+000,-8.504921e+000,-4.143695e+000,-5.072350e+000,-6.899734e+000,-2.538508e+000,-3.467163e+000,-8.418600e-005,-8.418600e-005,,,,,,,,,,,,,,,,,,,,
1524320794.481,,0.000000e+000,5.700026e+001,5.699746e+001,1,0,2.838710e+000,0.000000e+000,-6.689097e+000,-6.689097e+000,-2.244232e+000,-3.259948e+000,-5.257391e+000,-8.125260e-001,-1.828243e+000,-4.308681e-005,-4.308681e-005,,,,,,,,,,,,,,,,,,,,
1524320819.331,,0.000000e+000,5.698765e+001,5.701008e+001,1,0,3.096774e+000,0.000000e+000,-4.750439e+000,-4.750439e+000,-2.220447e-001,-1.336672e+000,-3.809634e+000,7.187595e-001,-3.958681e-001,7.105118e-007,7.105118e-007,,,,,,,,,,,,,,,,,,,,
1524320844.321,,0.000000e+000,5.699886e+001,5.700026e+001,1,0,3.354839e+000,0.000000e+000,-3.073320e+000,-3.073320e+000,1.547896e+000,3.415790e-001,-2.765063e+000,1.856153e+000,6.498358e-001,3.890683e-005,3.890683e-005,,,,,,,,,,,,,,,,,,,,
1524320869.301,,0.000000e+000,5.699746e+001,5.699746e+001,1,0,3.612903e+000,0.000000e+000,-1.872435e+000,-1.872435e+000,2.837044e+000,1.545588e+000,-2.412419e+000,2.297060e+000,1.005604e+000,6.639058e-005,6.639058e-005,,,,,,,,,,,,,,,,,,,,
1524320894.601,,0.000000e+000,5.700026e+001,5.700587e+001,1,0,3.870968e+000,0.000000e+000,-1.480278e+000,-1.480278e+000,3.327069e+000,1.937406e+000,-2.763449e+000,2.043898e+000,6.542344e-001,7.593205e-005,7.593205e-005,,,,,,,,,,,,,,,,,,,,
1524320931.981,,0.000000e+000,5.700868e+001,5.699325e+001,1,0,0.000000e+000,0.000000e+000,-2.211338e+000,-2.211338e+000,9.884312e-001,9.884312e-001,-1.417682e+000,1.782087e+000,1.782087e+000,4.442246e-005,4.442246e-005,,,,,,,,,,,,,,,,,,,,
1524320957.541,,0.000000e+000,5.700167e+001,5.700167e+001,1,0,2.580645e-001,0.000000e+000,-1.758144e+000,-1.758144e+000,1.533757e+000,1.440808e+000,-1.049872e+000,2.242030e+000,2.149081e+000,5.523267e-005,5.523267e-005,,,,,,,,,,,,,,,,,,,,
1524320983.051,,0.000000e+000,5.699186e+001,5.701429e+001,1,0,5.161290e-001,0.000000e+000,-1.672541e+000,-1.672541e+000,1.931535e+000,1.746021e+000,-1.421567e+000,2.182510e+000,1.996996e+000,6.272219e-005,6.272219e-005,,,,,,,,,,,,,,,,,,,,
1524321008.351,,0.000000e+000,5.699606e+001,5.699886e+001,1,0,7.741935e-001,0.000000e+000,-1.901274e+000,-1.901274e+000,1.794652e+000,1.517241e+000,-2.333316e+000,1.362610e+000,1.085199e+000,5.827355e-005,5.827355e-005,,,,,,,,,,,,,,,,,,,,
1524321034.161,,0.000000e+000,5.699746e+001,5.698765e+001,1,0,1.032258e+000,0.000000e+000,-2.830396e+000,-2.830396e+000,9.542879e-001,5.833316e-001,-3.798515e+000,-1.383075e-002,-3.847871e-001,3.813312e-005,3.813312e-005,,,,,,,,,,,,,,,,,,,,
1524321059.371,,0.000000e+000,5.699886e+001,5.700167e+001,1,0,1.290323e+000,0.000000e+000,-4.344854e+000,-4.344854e+000,-4.757230e-001,-9.372230e-001,-5.541994e+000,-1.672863e+000,-2.134363e+000,4.777467e-006,4.777467e-006,,,,,,,,,,,,,,,,,,,,
1524321084.631,,0.000000e+000,5.699606e+001,5.700447e+001,1,0,1.548387e+000,0.000000e+000,-6.204166e+000,-6.204166e+000,-2.234523e+000,-2.789442e+000,-7.412135e+000,-3.442492e+000,-3.997411e+000,-3.588737e-005,-3.588737e-005,,,,,,,,,,,,,,,,,,,,
1524321109.681,,0.000000e+000,5.700306e+001,5.699746e+001,1,0,1.806452e+000,0.000000e+000,-8.063172e+000,-8.063172e+000,-4.004154e+000,-4.653172e+000,-8.947718e+000,-4.888699e+000,-5.537718e+000,-7.680438e-005,-7.680438e-005,,,,,,,,,,,,,,,,,,,,
1524321135.701,,0.000000e+000,5.698904e+001,5.699465e+001,1,0,2.064516e+000,0.000000e+000,-9.381552e+000,-9.381552e+000,-5.230325e+000,-5.970824e+000,-9.395480e+000,-5.244253e+000,-5.984753e+000,-1.055860e-004,-1.055860e-004,,,,,,,,,,,,,,,,,,,,
1524321160.561,,0.000000e+000,5.699045e+001,5.699186e+001,1,0,2.322581e+000,0.000000e+000,-9.577783e+000,-9.577783e+000,-5.331726e+000,-6.167671e+000,-8.504169e+000,-4.258113e+000,-5.094058e+000,-1.092292e-004,-1.092292e-004,,,,,,,,,,,,,,,,,,,,
1524321185.791,,0.000000e+000,5.700026e+001,5.700306e+001,1,0,2.580645e+000,0.000000e+000,-8.526283e+000,-8.526283e+000,-4.184323e+000,-5.115011e+000,-6.908141e+000,-2.566181e+000,-3.496869e+000,-8.497506e-005,-8.497506e-005,,,,,,,,,,,,,,,,,,,,
1524321210.561,,0.000000e+000,5.700587e+001,5.699465e+001,1,0,2.838710e+000,0.000000e+000,-6.699016e+000,-6.699016e+000,-2.257655e+000,-3.286056e+000,-5.264441e+000,-8.230802e-001,-1.851481e+000,-4.329272e-005,-4.329272e-005,,,,,,,,,,,,,,,,,,,,
1524321236.521,,0.000000e+000,5.699606e+001,5.699746e+001,1,0,3.096774e+000,0.000000e+000,-4.762188e+000,-4.762188e+000,-2.247450e-001,-1.343351e+000,-3.810564e+000,7.268791e-001,-3.917267e-001,7.596827e-007,7.596827e-007,,,,,,,,,,,,,,,,,,,,
1524321262.132,,0.000000e+000,5.699325e+001,5.699325e+001,1,0,3.354839e+000,0.000000e+000,-3.049210e+000,-3.049210e+000,1.589169e+000,3.867977e-001,-2.762696e+000,1.875684e+000,6.733122e-001,3.997478e-005,3.997478e-005,,,,,,,,,,,,,,,,,,,,
1524321286.942,,0.000000e+000,5.700167e+001,5.700447e+001,1,0,3.612903e+000,0.000000e+000,-1.862211e+000,-1.862211e+000,2.861434e+000,1.573346e+000,-2.399749e+000,2.323896e+000,1.035807e+000,6.709331e-005,6.709331e-005,,,,,,,,,,,,,,,,,,,,
1524321312.622,,0.000000e+000,5.699325e+001,5.700167e+001,1,0,3.870968e+000,0.000000e+000,-1.440452e+000,-1.440452e+000,3.370173e+000,1.983822e+000,-2.744287e+000,2.066337e+000,6.799862e-001,7.704637e-005,7.704637e-005,,,,,,,,,,,,,,,,,,,,
1524321351.022,,0.000000e+000,5.699886e+001,5.699886e+001,1,0,0.000000e+000,0.000000e+000,-2.414283e+000,-2.414283e+000,1.003837e+000,1.003837e+000,-1.618904e+000,1.799215e+000,1.799215e+000,4.488952e-005,4.488952e-005,,,,,,,,,,,,,,,,,,,,
1524321376.142,,0.000000e+000,5.700026e+001,5.699465e+001,1,0,2.580645e-001,0.000000e+000,-1.960937e+000,-1.960937e+000,1.555431e+000,1.462734e+000,-1.250683e+000,2.265684e+000,2.172988e+000,5.581413e-005,5.581413e-005,,,,,,,,,,,,,,,,,,,,
1524321402.332,,0.000000e+000,5.700447e+001,5.699746e+001,1,0,5.161290e-001,0.000000e+000,-1.635920e+000,-1.635920e+000,1.970079e+000,1.783403e+000,-1.401168e+000,2.204830e+000,2.018155e+000,6.375210e-005,6.375210e-005,,,,,,,,,,,,,,,,,,,,
1524321427.632,,0.000000e+000,5.699886e+001,5.700306e+001,1,0,7.741935e-001,0.000000e+000,-1.906920e+000,-1.906920e+000,1.804640e+000,1.526529e+000,-2.334553e+000,1.377007e+000,1.098896e+000,5.863611e-005,5.863611e-005,,,,,,,,,,,,,,,,,,,,
1524321453.062,,0.000000e+000,5.698904e+001,5.700587e+001,1,0,1.032258e+000,0.000000e+000,-2.850385e+000,-2.850385e+000,9.528880e-001,5.840871e-001,-3.817244e+000,-1.397112e-002,-3.827720e-001,3.818970e-005,3.818970e-005,,,,,,,,,,,,,,,,,,,,
1524321477.802,,0.000000e+000,5.700306e+001,5.699886e+001,1,0,1.290323e+000,0.000000e+000,-4.390936e+000,-4.390936e+000,-5.090432e-001,-9.697461e-001,-5.572105e+000,-1.690212e+000,-2.150915e+000,4.146801e-006,4.146801e-006,,,,,,,,,,,,,,,,,,,,
1524321502.522,,0.000000e+000,5.699465e+001,5.699606e+001,1,0,1.548387e+000,0.000000e+000,-6.242619e+000,-6.242619e+000,-2.268302e+000,-2.821676e+000,-7.450286e+000,-3.475970e+000,-4.029344e+000,-3.653577e-005,-3.653577e-005,,,,,,,,,,,,,,,,,,,,
1524321527.312,,0.000000e+000,5.699886e+001,5.700587e+001,1,0,1.806452e+000,0.000000e+000,-8.099642e+000,-8.099642e+000,-4.037482e+000,-4.685071e+000,-8.992599e+000,-4.930439e+000,-5.578027e+000,-7.745207e-005,-7.745207e-005,,,,,,,,,,,,,,,,,,,,
1524321552.262,,0.000000e+000,5.699606e+001,5.700026e+001,1,0,2.064516e+000,0.000000e+000,-9.430991e+000,-9.430991e+000,-5.279994e+000,-6.022022e+000,-9.444262e+000,-5.293264e+000,-6.035293e+000,-1.065879e-004,-1.065879e-004,,,,,,,,,,,,,,,,,,,,
1524321578.022,,0.000000e+000,5.699465e+001,5.700167e+001,1,0,2.322581e+000,0.000000e+000,-9.628138e+000,-9.628138e+000,-5.388275e+000,-6.218741e+000,-8.539505e+000,-4.299643e+000,-5.130108e+000,-1.103680e-004,-1.103680e-004,,,,,,,,,,,,,,,,,,,,
1524321602.742,,0.000000e+000,5.699465e+001,5.699606e+001,1,0,2.580645e+000,0.000000e+000,-8.525826e+000,-8.525826e+000,-4.195255e+000,-5.120248e+000,-6.922771e+000,-2.592200e+000,-3.517193e+000,-8.508204e-005,-8.508204e-005,,,,,,,,,,,,,,,,,,,,
1524321628.682,,0.000000e+000,5.700447e+001,5.699746e+001,1,0,2.838710e+000,0.000000e+000,-6.696422e+000,-6.696422e+000,-2.270537e+000,-3.289077e+000,-5.255518e+000,-8.296331e-001,-1.848173e+000,-4.344415e-005,-4.344415e-005,,,,,,,,,,,,,,,,,,,,
1524321653.682,,0.000000e+000,5.699886e+001,5.700587e+001,1,0,3.096774e+000,0.000000e+000,-4.736248e+000,-4.736248e+000,-2.127016e-001,-1.325426e+000,-3.790678e+000,7.328682e-001,-3.798566e-001,1.156193e-006,1.156193e-006,,,,,,,,,,,,,,,,,,,,
1524321678.792,,0.000000e+000,5.699325e+001,5.699186e+001,1,0,3.354839e+000,0.000000e+000,-3.017930e+000,-3.017930e+000,1.600730e+000,3.844719e-001,-2.726860e+000,1.891799e+000,6.755412e-001,4.025012e-005,4.025012e-005,,,,,,,,,,,,,,,,,,,,
1524321704.842,,0.000000e+000,5.700447e+001,5.700447e+001,1,0,3.612903e+000,0.000000e+000,-1.819638e+000,-1.819638e+000,2.884078e+000,1.588622e+000,-2.362347e+000,2.341369e+000,1.045914e+000,6.763845e-005,6.763845e-005,,,,,,,,,,,,,,,,,,,,
1524321729.192,,0.000000e+000,5.700167e+001,5.700026e+001,1,0,3.870968e+000,0.000000e+000,-1.407187e+000,-1.407187e+000,3.391694e+000,1.993823e+000,-2.714874e+000,2.084007e+000,6.861355e-001,7.754454e-005,7.754454e-005,,,,,,,,,,,,,,,,,,,,
1524321767.562,,0.000000e+000,5.699746e+001,5.699886e+001,1,0,0.000000e+000,0.000000e+000,-2.379950e+000,-2.379950e+000,1.023394e+000,1.023394e+000,-1.586532e+000,1.816812e+000,1.816812e+000,4.542073e-005,4.542073e-005,,,,,,,,,,,,,,,,,,,,
1524321792.362,,0.000000e+000,5.699325e+001,5.699606e+001,1,0,2.580645e-001,0.000000e+000,-1.925383e+000,-1.925383e+000,1.571418e+000,1.478578e+000,-1.210219e+000,2.286582e+000,2.193743e+000,5.629398e-005,5.629398e-005,,,,,,,,,,,,,,,,,,,,
1524321817.482,,0.000000e+000,5.700868e+001,5.700447e+001,1,0,5.161290e-001,0.000000e+000,-1.595636e+000,-1.595636e+000,1.993476e+000,1.808362e+000,-1.364882e+000,2.224230e+000,2.039117e+000,6.431124e-005,6.431124e-005,,,,,,,,,,,,,,,,,,,,
1524321842.162,,0.000000e+000,5.700728e+001,5.700026e+001,1,0,7.741935e-001,0.000000e+000,-1.616236e+000,-1.616236e+000,1.850907e+000,1.571169e+000,-2.077486e+000,1.389657e+000,1.109920e+000,5.981642e-005,5.981642e-005,,,,,,,,,,,,,,,,,,,,
1524321867.492,,0.000000e+000,5.699465e+001,5.700167e+001,1,0,1.032258e+000,0.000000e+000,-2.638285e+000,-2.638285e+000,9.298090e-001,5.566974e-001,-3.582184e+000,-1.409015e-002,-3.872018e-001,3.783400e-005,3.783400e-005,,,,,,,,,,,,,,,,,,,,
1524321892.752,,0.000000e+000,5.699465e+001,5.700306e+001,1,0,1.290323e+000,0.000000e+000,-4.414435e+000,-4.414435e+000,-5.291647e-001,-9.934382e-001,-5.589818e+000,-1.704548e+000,-2.168821e+000,3.826019e-006,3.826019e-006,,,,,,,,,,,,,,,,,,,,
1524321918.042,,0.000000e+000,5.700167e+001,5.700167e+001,1,0,1.548387e+000,0.000000e+000,-6.262760e+000,-6.262760e+000,-2.287741e+000,-2.841064e+000,-7.481012e+000,-3.505993e+000,-4.059316e+000,-3.686888e-005,-3.686888e-005,,,,,,,,,,,,,,,,,,,,
1524321943.092,,0.000000e+000,5.699746e+001,5.700306e+001,1,0,1.806452e+000,0.000000e+000,-8.156404e+000,-8.156404e+000,-4.091002e+000,-4.737553e+000,-9.044049e+000,-4.978646e+000,-5.625197e+000,-7.853498e-005,-7.853498e-005,,,,,,,,,,,,,,,,,,,,
1524321968.222,,0.000000e+000,5.700026e+001,5.699746e+001,1,0,2.064516e+000,0.000000e+000,-9.477074e+000,-9.477074e+000,-5.326577e+000,-6.065998e+000,-9.495108e+000,-5.344611e+000,-6.084032e+000,-1.075137e-004,-1.075137e-004,,,,,,,,,,,,,,,,,,,,
1524321993.043,,0.000000e+000,5.699186e+001,5.699746e+001,1,0,2.322581e+000,0.000000e+000,-9.653925e+000,-9.653925e+000,-5.413129e+000,-6.250603e+000,-8.576440e+000,-4.335644e+000,-5.173118e+000,-1.108394e-004,-1.108394e-004,,,,,,,,,,,,,,,,,,,,
1524322018.563,,0.000000e+000,5.700026e+001,5.699746e+001,1,0,2.580645e+000,0.000000e+000,-8.556802e+000,-8.556802e+000,-4.221652e+000,-5.148878e+000,-6.946508e+000,-2.611358e+000,-3.538584e+000,-8.559242e-005,-8.559242e-005,,,,,,,,,,,,,,,,,,,,
1524322044.123,,0.000000e+000,5.700026e+001,5.699746e+001,1,0,2.838710e+000,0.000000e+000,-6.699321e+000,-6.699321e+000,-2.271759e+000,-3.289990e+000,-5.264256e+000,-8.366944e-001,-1.854925e+000,-4.336973e-005,-4.336973e-005,,,,,,,,,,,,,,,,,,,,
1524322069.213,,0.000000e+000,5.699886e+001,5.699606e+001,1,0,3.096774e+000,0.000000e+000,-4.735638e+000,-4.735638e+000,-2.165558e-001,-1.328320e+000,-3.779346e+000,7.397358e-001,-3.720284e-001,1.185486e-006,1.185486e-006,,,,,,,,,,,,,,,,,,,,
1524322094.093,,0.000000e+000,5.699886e+001,5.700306e+001,1,0,3.354839e+000,0.000000e+000,-2.991531e+000,-2.991531e+000,1.615493e+000,4.151947e-001,-2.698155e+000,1.908869e+000,7.085707e-001,4.078244e-005,4.078244e-005,,,,,,,,,,,,,,,,,,,,
1524322119.353,,0.000000e+000,5.699746e+001,5.700026e+001,1,0,3.612903e+000,0.000000e+000,-1.815824e+000,-1.815824e+000,2.889349e+000,1.590997e+000,-2.341747e+000,2.363426e+000,1.065074e+000,6.784814e-005,6.784814e-005,,,,,,,,,,,,,,,,,,,,
1524322144.463,,0.000000e+000,5.699045e+001,5.700026e+001,1,0,3.870968e+000,0.000000e+000,-1.396506e+000,-1.396506e+000,3.401623e+000,2.010368e+000,-2.696062e+000,2.102067e+000,7.108126e-001,7.791644e-005,7.791644e-005,,,,,,,,,,,,,,,,,,,,
1524322181.703,,0.000000e+000,5.700167e+001,5.699045e+001,1,0,0.000000e+000,0.000000e+000,-2.367743e+000,-2.367743e+000,1.036157e+000,1.036157e+000,-1.573481e+000,1.830418e+000,1.830418e+000,4.574873e-005,4.574873e-005,,,,,,,,,,,,,,,,,,,,
1524322207.073,,0.000000e+000,5.700306e+001,5.699186e+001,1,0,2.580645e-001,0.000000e+000,-1.899748e+000,-1.899748e+000,1.593795e+000,1.501614e+000,-1.189536e+000,2.304007e+000,2.211826e+000,5.681810e-005,5.681810e-005,,,,,,,,,,,,,,,,,,,,
1524322232.123,,0.000000e+000,5.700306e+001,5.699325e+001,1,0,5.161290e-001,0.000000e+000,-1.571221e+000,-1.571221e+000,2.012717e+000,1.827810e+000,-1.339500e+000,2.244438e+000,2.059531e+000,6.483990e-005,6.483990e-005,,,,,,,,,,,,,,,,,,,,
1524322256.963,,0.000000e+000,5.698904e+001,5.699886e+001,1,0,7.741935e-001,0.000000e+000,-1.819333e+000,-1.819333e+000,1.860170e+000,1.584453e+000,-2.280065e+000,1.399438e+000,1.123721e+000,6.001198e-005,6.001198e-005,,,,,,,,,,,,,,,,,,,,
1524322281.753,,0.000000e+000,5.699606e+001,5.700306e+001,1,0,1.032258e+000,0.000000e+000,-2.815595e+000,-2.815595e+000,9.497501e-001,5.798295e-001,-3.779542e+000,-1.419765e-002,-3.841183e-001,3.832544e-005,3.832544e-005,,,,,,,,,,,,,,,,,,,,
1524322306.853,,0.000000e+000,5.700167e+001,5.699325e+001,1,0,1.290323e+000,0.000000e+000,-4.388647e+000,-4.388647e+000,-5.336589e-001,-9.896667e-001,-5.574391e+000,-1.719403e+000,-2.175411e+000,3.761088e-006,3.761088e-006,,,,,,,,,,,,,,,,,,,,
1524322331.853,,0.000000e+000,5.699465e+001,5.700026e+001,1,0,1.548387e+000,0.000000e+000,-6.270543e+000,-6.270543e+000,-2.323624e+000,-2.875443e+000,-7.481682e+000,-3.534764e+000,-4.086583e+000,-3.758016e-005,-3.758016e-005,,,,,,,,,,,,,,,,,,,,
1524322357.033,,0.000000e+000,5.699045e+001,5.699886e+001,1,0,1.806452e+000,0.000000e+000,-8.158999e+000,-8.158999e+000,-4.125828e+000,-4.776734e+000,-9.048955e+000,-5.015784e+000,-5.666690e+000,-7.921791e-005,-7.921791e-005,,,,,,,,,,,,,,,,,,,,
1524322382.903,,0.000000e+000,5.699886e+001,5.700728e+001,1,0,2.064516e+000,0.000000e+000,-9.511559e+000,-9.511559e+000,-5.367609e+000,-6.103394e+000,-9.517722e+000,-5.373772e+000,-6.109557e+000,-1.083643e-004,-1.083643e-004,,,,,,,,,,,,,,,,,,,,
1524322407.943,,0.000000e+000,5.699746e+001,5.699325e+001,1,0,2.322581e+000,0.000000e+000,-9.657741e+000,-9.657741e+000,-5.433198e+000,-6.267294e+000,-8.590037e+000,-4.365495e+000,-5.199591e+000,-1.111991e-004,-1.111991e-004,,,,,,,,,,,,,,,,,,,,
1524322433.123,,0.000000e+000,5.699325e+001,5.698765e+001,1,0,2.580645e+000,0.000000e+000,-8.562600e+000,-8.562600e+000,-4.251993e+000,-5.170987e+000,-6.943103e+000,-2.632496e+000,-3.551490e+000,-8.614689e-005,-8.614689e-005,,,,,,,,,,,,,,,,,,,,
1524322457.723,,0.000000e+000,5.700026e+001,5.699465e+001,1,0,2.838710e+000,0.000000e+000,-6.716869e+000,-6.716869e+000,-2.311729e+000,-3.330824e+000,-5.247870e+000,-8.427303e-001,-1.861826e+000,-4.418114e-005,-4.418114e-005,,,,,,,,,,,,,,,,,,,,
1524322482.793,,0.000000e+000,5.699886e+001,5.701148e+001,1,0,3.096774e+000,0.000000e+000,-4.700541e+000,-4.700541e+000,-2.020416e-001,-1.314831e+000,-3.754087e+000,7.444124e-001,-3.683767e-001,1.579640e-006,1.579640e-006,,,,,,,,,,,,,,,,,,,,
1524322508.403,,0.000000e+000,5.699465e+001,5.699886e+001,1,0,3.354839e+000,0.000000e+000,-2.958877e+000,-2.958877e+000,1.631361e+000,4.338965e-001,-2.670166e+000,1.920073e+000,7.226079e-001,4.122403e-005,4.122403e-005,,,,,,,,,,,,,,,,,,,,
1524322534.103,,0.000000e+000,5.698344e+001,5.699325e+001,1,0,3.612903e+000,0.000000e+000,-1.785000e+000,-1.785000e+000,2.913577e+000,1.616751e+000,-2.318817e+000,2.379761e+000,1.082934e+000,6.848207e-005,6.848207e-005,,,,,,,,,,,,,,,,,,,,
1524322559.583,,0.000000e+000,5.699325e+001,5.700167e+001,1,0,3.870968e+000,0.000000e+000,-1.377127e+000,-1.377127e+000,3.422291e+000,2.027847e+000,-2.683414e+000,2.116004e+000,7.215600e-001,7.843437e-005,7.843437e-005,,,,,,,,,,,,,,,,,,,,
1524322597.063,,0.000000e+000,5.700026e+001,5.700026e+001,1,0,0.000000e+000,0.000000e+000,-2.357061e+000,-2.357061e+000,1.046668e+000,1.046668e+000,-1.560380e+000,1.843349e+000,1.843349e+000,4.608287e-005,4.608287e-005,,,,,,,,,,,,,,,,,,,,
1524322622.423,,0.000000e+000,5.700167e+001,5.700026e+001,1,0,2.580645e-001,0.000000e+000,-1.881132e+000,-1.881132e+000,1.610931e+000,1.518368e+000,-1.172991e+000,2.319072e+000,2.226509e+000,5.731745e-005,5.731745e-005,,,,,,,,,,,,,,,,,,,,
1524322647.343,,0.000000e+000,5.699606e+001,5.699746e+001,1,0,5.161290e-001,0.000000e+000,-1.555657e+000,-1.555657e+000,2.029104e+000,1.845186e+000,-1.326326e+000,2.258436e+000,2.074517e+000,6.523822e-005,6.523822e-005,,,,,,,,,,,,,,,,,,,,
1524322672.713,,0.000000e+000,5.699465e+001,5.699886e+001,1,0,7.741935e-001,0.000000e+000,-1.810483e+000,-1.810483e+000,1.859020e+000,1.581051e+000,-2.260390e+000,1.409114e+000,1.131144e+000,6.012195e-005,6.012195e-005,,,,,,,,,,,,,,,,,,,,
1524322697.544,,0.000000e+000,5.700447e+001,5.699886e+001,1,0,1.032258e+000,0.000000e+000,-2.803235e+000,-2.803235e+000,9.567057e-001,5.850191e-001,-3.774233e+000,-1.429254e-002,-3.859792e-001,3.858544e-005,3.858544e-005,,,,,,,,,,,,,,,,,,,,
1524322722.744,,0.000000e+000,5.699465e+001,5.699746e+001,1,0,1.290323e+000,0.000000e+000,-4.423591e+000,-4.423591e+000,-5.711160e-001,-1.035483e+000,-5.582074e+000,-1.729599e+000,-2.193966e+000,3.063324e-006,3.063324e-006,,,,,,,,,,,,,,,,,,,,
1524322748.424,,0.000000e+000,5.698765e+001,5.700587e+001,1,0,1.548387e+000,0.000000e+000,-6.313420e+000,-6.313420e+000,-2.367764e+000,-2.924853e+000,-7.498174e+000,-3.552517e+000,-4.109607e+000,-3.848373e-005,-3.848373e-005,,,,,,,,,,,,,,,,,,,,
1524322773.314,,0.000000e+000,5.700306e+001,5.699606e+001,1,0,1.806452e+000,0.000000e+000,-8.191348e+000,-8.191348e+000,-4.155499e+000,-4.803519e+000,-9.082636e+000,-5.046787e+000,-5.694807e+000,-7.981175e-005,-7.981175e-005,,,,,,,,,,,,,,,,,,,,
1524322798.294,,0.000000e+000,5.699606e+001,5.699325e+001,1,0,2.064516e+000,0.000000e+000,-9.521477e+000,-9.521477e+000,-5.400152e+000,-6.140900e+000,-9.534431e+000,-5.413105e+000,-6.153853e+000,-1.090065e-004,-1.090065e-004,,,,,,,,,,,,,,,,,,,,
1524322823.454,,0.000000e+000,5.699606e+001,5.700167e+001,1,0,2.322581e+000,0.000000e+000,-9.674678e+000,-9.674678e+000,-5.464801e+000,-6.299638e+000,-8.602490e+000,-4.392613e+000,-5.227451e+000,-1.118327e-004,-1.118327e-004,,,,,,,,,,,,,,,,,,,,
1524322848.484,,0.000000e+000,5.699746e+001,5.700447e+001,1,0,2.580645e+000,0.000000e+000,-8.562753e+000,-8.562753e+000,-4.260577e+000,-5.185420e+000,-6.950127e+000,-2.647951e+000,-3.572794e+000,-8.628810e-005,-8.628810e-005,,,,,,,,,,,,,,,,,,,,
1524322873.864,,0.000000e+000,5.699465e+001,5.699325e+001,1,0,2.838710e+000,0.000000e+000,-6.700541e+000,-6.700541e+000,-2.304488e+000,-3.317975e+000,-5.244313e+000,-8.482597e-001,-1.861747e+000,-4.391605e-005,-4.391605e-005,,,,,,,,,,,,,,,,,,,,
1524322899.624,,0.000000e+000,5.699746e+001,5.699886e+001,1,0,3.096774e+000,0.000000e+000,-4.688945e+000,-4.688945e+000,-2.027522e-001,-1.305432e+000,-3.736867e+000,7.493252e-001,-3.533547e-001,1.696084e-006,1.696084e-006,,,,,,,,,,,,,,,,,,,,
1524322924.924,,0.000000e+000,5.699886e+001,5.699465e+001,1,0,3.354839e+000,0.000000e+000,-2.943008e+000,-2.943008e+000,1.634020e+000,4.396491e-001,-2.643923e+000,1.933105e+000,7.387335e-001,4.138332e-005,4.138332e-005,,,,,,,,,,,,,,,,,,,,
1524322950.394,,0.000000e+000,5.700026e+001,5.699746e+001,1,0,3.612903e+000,0.000000e+000,-1.755245e+000,-1.755245e+000,2.913205e+000,1.623018e+000,-2.274974e+000,2.393477e+000,1.103289e+000,6.858700e-005,6.858700e-005,,,,,,,,,,,,,,,,,,,,
1524322975.404,,0.000000e+000,5.699186e+001,5.700447e+001,1,0,3.870968e+000,0.000000e+000,-1.328450e+000,-1.328450e+000,3.429112e+000,2.044169e+000,-2.630960e+000,2.126603e+000,7.416594e-001,7.871530e-005,7.871530e-005,,,,,,,,,,,,,,,,,,,,
1524323013.544,,0.000000e+000,5.699186e+001,5.699606e+001,1,0,0.000000e+000,0.000000e+000,-2.317082e+000,-2.317082e+000,1.057076e+000,1.057076e+000,-1.518392e+000,1.855767e+000,1.855767e+000,4.635959e-005,4.635959e-005,,,,,,,,,,,,,,,,,,,,
1524323039.024,,0.000000e+000,5.699606e+001,5.700167e+001,1,0,2.580645e-001,0.000000e+000,-1.863737e+000,-1.863737e+000,1.592397e+000,1.499615e+000,-1.124833e+000,2.331301e+000,2.238519e+000,5.698855e-005,5.698855e-005,,,,,,,,,,,,,,,,,,,,
1524323064.134,,0.000000e+000,5.699746e+001,5.699886e+001,1,0,5.161290e-001,0.000000e+000,-1.508507e+000,-1.508507e+000,2.037120e+000,1.851998e+000,-1.274015e+000,2.271612e+000,2.086490e+000,6.553899e-005,6.553899e-005,,,,,,,,,,,,,,,,,,,,
1524323089.754,,0.000000e+000,5.700167e+001,5.699746e+001,1,0,7.741935e-001,0.000000e+000,-1.766995e+000,-1.766995e+000,1.873671e+000,1.596049e+000,-2.223464e+000,1.417201e+000,1.139579e+000,6.051015e-005,6.051015e-005,,,,,,,,,,,,,,,,,,,,
1524323115.254,,0.000000e+000,5.700728e+001,5.699465e+001,1,0,1.032258e+000,0.000000e+000,-2.786908e+000,-2.786908e+000,9.459538e-001,5.775423e-001,-3.747247e+000,-1.438498e-002,-3.827965e-001,3.837699e-005,3.837699e-005,,,,,,,,,,,,,,,,,,,,
1524323141.584,,0.000000e+000,5.699465e+001,5.699465e+001,1,0,1.290323e+000,0.000000e+000,-4.397192e+000,-4.397192e+000,-5.764875e-001,-1.039011e+000,-5.559827e+000,-1.739122e+000,-2.201645e+000,2.994318e-006,2.994318e-006,,,,,,,,,,,,,,,,,,,,
1524323166.474,,0.000000e+000,5.699606e+001,5.700026e+001,1,0,1.548387e+000,0.000000e+000,-6.304723e+000,-6.304723e+000,-2.394434e+000,-2.949755e+000,-7.485813e+000,-3.575524e+000,-4.130845e+000,-3.900970e-005,-3.900970e-005,,,,,,,,,,,,,,,,,,,,
1524323190.964,,0.000000e+000,5.700728e+001,5.700587e+001,1,0,1.806452e+000,0.000000e+000,-8.200656e+000,-8.200656e+000,-4.204160e+000,-4.853097e+000,-9.076692e+000,-5.080196e+000,-5.729133e+000,-8.081822e-005,-8.081822e-005,,,,,,,,,,,,,,,,,,,,
1524323216.444,,0.000000e+000,5.700167e+001,5.700026e+001,1,0,2.064516e+000,0.000000e+000,-9.510643e+000,-9.510643e+000,-5.420959e+000,-6.164909e+000,-9.532737e+000,-5.443053e+000,-6.187003e+000,-1.094064e-004,-1.094064e-004,,,,,,,,,,,,,,,,,,,,
1524323242.024,,0.000000e+000,5.700167e+001,5.700728e+001,1,0,2.322581e+000,0.000000e+000,-9.667811e+000,-9.667811e+000,-5.490509e+000,-6.324736e+000,-8.596976e+000,-4.419674e+000,-5.253901e+000,-1.123319e-004,-1.123319e-004,,,,,,,,,,,,,,,,,,,,
1524323267.474,,0.000000e+000,5.699746e+001,5.700306e+001,1,0,2.580645e+000,0.000000e+000,-8.540627e+000,-8.540627e+000,-4.271573e+000,-5.198754e+000,-6.932955e+000,-2.663900e+000,-3.591081e+000,-8.646918e-005,-8.646918e-005,,,,,,,,,,,,,,,,,,,,
1524323293.034,,0.000000e+000,5.700026e+001,5.700026e+001,1,0,2.838710e+000,0.000000e+000,-6.664989e+000,-6.664989e+000,-2.309237e+000,-3.326123e+000,-5.207946e+000,-8.521944e-001,-1.869081e+000,-4.398130e-005,-4.398130e-005,,,,,,,,,,,,,,,,,,,,
1524323318.454,,0.000000e+000,5.699886e+001,5.700026e+001,1,0,3.096774e+000,0.000000e+000,-4.641490e+000,-4.641490e+000,-1.945062e-001,-1.296907e+000,-3.693628e+000,7.533553e-001,-3.490455e-001,1.946639e-006,1.946639e-006,,,,,,,,,,,,,,,,,,,,
1524323344.094,,0.000000e+000,5.699746e+001,5.698904e+001,1,0,3.354839e+000,0.000000e+000,-2.873579e+000,-2.873579e+000,1.660608e+000,4.620686e-001,-2.589810e+000,1.944377e+000,7.458377e-001,4.202273e-005,4.202273e-005,,,,,,,,,,,,,,,,,,,,
1524323369.114,,0.000000e+000,5.699465e+001,5.699465e+001,1,0,3.612903e+000,0.000000e+000,-1.685206e+000,-1.685206e+000,2.943962e+000,1.653589e+000,-2.222147e+000,2.407021e+000,1.116648e+000,6.934148e-005,6.934148e-005,,,,,,,,,,,,,,,,,,,,
1524323395.004,,0.000000e+000,5.700447e+001,5.699746e+001,1,0,3.870968e+000,0.000000e+000,-1.297475e+000,-1.297475e+000,3.417553e+000,2.035575e+000,-2.573441e+000,2.141587e+000,7.596090e-001,7.856314e-005,7.856314e-005,,,,,,,,,,,,,,,,,,,,
1524323432.435,,0.000000e+000,5.699606e+001,5.699606e+001,1,0,0.000000e+000,0.000000e+000,-2.256657e+000,-2.256657e+000,1.067036e+000,1.067036e+000,-1.460382e+000,1.863311e+000,1.863311e+000,4.671462e-005,4.671462e-005,,,,,,,,,,,,,,,,,,,,
1524323457.135,,0.000000e+000,5.700306e+001,5.699325e+001,1,0,2.580645e-001,0.000000e+000,-1.786984e+000,-1.786984e+000,1.632437e+000,1.539974e+000,-1.072708e+000,2.346713e+000,2.254250e+000,5.793115e-005,5.793115e-005,,,,,,,,,,,,,,,,,,,,
1524323482.945,,0.000000e+000,5.700167e+001,5.700728e+001,1,0,5.161290e-001,0.000000e+000,-1.480888e+000,-1.480888e+000,2.031590e+000,1.847231e+000,-1.228785e+000,2.283694e+000,2.099335e+000,6.544701e-005,6.544701e-005,,,,,,,,,,,,,,,,,,,,
1524323507.815,,0.000000e+000,5.700587e+001,5.699465e+001,1,0,7.741935e-001,0.000000e+000,-1.726558e+000,-1.726558e+000,1.880289e+000,1.604878e+000,-2.182347e+000,1.424501e+000,1.149089e+000,6.066816e-005,6.066816e-005,,,,,,,,,,,,,,,,,,,,
1524323532.775,,0.000000e+000,5.700306e+001,5.700026e+001,1,0,1.032258e+000,0.000000e+000,-2.746166e+000,-2.746166e+000,9.484985e-001,5.808282e-001,-3.709117e+000,-1.445225e-002,-3.821225e-001,3.848012e-005,3.848012e-005,,,,,,,,,,,,,,,,,,,,
1524323557.865,,0.000000e+000,5.699606e+001,5.700587e+001,1,0,1.290323e+000,0.000000e+000,-4.382086e+000,-4.382086e+000,-5.931869e-001,-1.051908e+000,-5.536924e+000,-1.748025e+000,-2.206746e+000,2.651839e-006,2.651839e-006,,,,,,,,,,,,,,,,,,,,
1524323583.395,,0.000000e+000,5.699606e+001,5.700026e+001,1,0,1.548387e+000,0.000000e+000,-6.263218e+000,-6.263218e+000,-2.384159e+000,-2.933857e+000,-7.473056e+000,-3.593997e+000,-4.143695e+000,-3.874196e-005,-3.874196e-005,,,,,,,,,,,,,,,,,,,,
1524323608.115,,0.000000e+000,5.700306e+001,5.700447e+001,1,0,1.806452e+000,0.000000e+000,-8.185245e+000,-8.185245e+000,-4.214279e+000,-4.859326e+000,-9.072865e+000,-5.101900e+000,-5.746947e+000,-8.099887e-005,-8.099887e-005,,,,,,,,,,,,,,,,,,,,
1524323633.425,,0.000000e+000,5.699746e+001,5.698624e+001,1,0,2.064516e+000,0.000000e+000,-9.523003e+000,-9.523003e+000,-5.454957e+000,-6.192098e+000,-9.545827e+000,-5.477782e+000,-6.214922e+000,-1.100859e-004,-1.100859e-004,,,,,,,,,,,,,,,,,,,,
1524323658.295,,0.000000e+000,5.700167e+001,5.701008e+001,1,0,2.322581e+000,0.000000e+000,-9.658504e+000,-9.658504e+000,-5.505128e+000,-6.329915e+000,-8.597125e+000,-4.443749e+000,-5.268537e+000,-1.125731e-004,-1.125731e-004,,,,,,,,,,,,,,,,,,,,
1524323683.285,,0.000000e+000,5.699606e+001,5.700167e+001,1,0,2.580645e+000,0.000000e+000,-8.315404e+000,-8.315404e+000,-4.294482e+000,-5.217348e+000,-6.697878e+000,-2.676956e+000,-3.599822e+000,-8.690738e-005,-8.690738e-005,,,,,,,,,,,,,,,,,,,,
1524323708.435,,0.000000e+000,5.699886e+001,5.699325e+001,1,0,2.838710e+000,0.000000e+000,-6.611734e+000,-6.611734e+000,-2.289067e+000,-3.294230e+000,-5.180073e+000,-8.574054e-001,-1.862569e+000,-4.340484e-005,-4.340484e-005,,,,,,,,,,,,,,,,,,,,
1524323733.945,,0.000000e+000,5.700026e+001,5.700587e+001,1,0,3.096774e+000,0.000000e+000,-4.604715e+000,-4.604715e+000,-1.862998e-001,-1.283231e+000,-3.661010e+000,7.574048e-001,-3.395269e-001,2.224027e-006,2.224027e-006,,,,,,,,,,,,,,,,,,,,
1524323758.795,,0.000000e+000,5.699465e+001,5.699325e+001,1,0,3.354839e+000,0.000000e+000,-2.842145e+000,-2.842145e+000,1.667209e+000,4.666650e-001,-2.554899e+000,1.954456e+000,7.539120e-001,4.222100e-005,4.222100e-005,,,,,,,,,,,,,,,,,,,,
1524323784.535,,0.000000e+000,5.699465e+001,5.701008e+001,1,0,3.612903e+000,0.000000e+000,-1.649195e+000,-1.649195e+000,2.949594e+000,1.662479e+000,-2.179396e+000,2.419393e+000,1.132278e+000,6.955130e-005,6.955130e-005,,,,,,,,,,,,,,,,,,,,
1524323809.235,,0.000000e+000,5.699746e+001,5.699465e+001,1,0,3.870968e+000,0.000000e+000,-1.238727e+000,-1.238727e+000,3.453045e+000,2.071593e+000,-2.539716e+000,2.152056e+000,7.706039e-001,7.941954e-005,7.941954e-005,,,,,,,,,,,,,,,,,,,,
1524323847.475,,0.000000e+000,5.699606e+001,5.700026e+001,1,0,0.000000e+000,0.000000e+000,-2.233768e+000,-2.233768e+000,1.075049e+000,1.075049e+000,-1.434005e+000,1.874813e+000,1.874813e+000,4.690571e-005,4.690571e-005,,,,,,,,,,,,,,,,,,,,
1524323872.645,,0.000000e+000,5.699886e+001,5.699746e+001,1,0,2.580645e-001,0.000000e+000,-1.762722e+000,-1.762722e+000,1.641029e+000,1.548683e+000,-1.043735e+000,2.360016e+000,2.267670e+000,5.818025e-005,5.818025e-005,,,,,,,,,,,,,,,,,,,,
1524323899.085,,0.000000e+000,5.699186e+001,5.699186e+001,1,0,5.161290e-001,0.000000e+000,-1.429313e+000,-1.429313e+000,2.063264e+000,1.878388e+000,-1.196208e+000,2.296369e+000,2.111493e+000,6.624442e-005,6.624442e-005,,,,,,,,,,,,,,,,,,,,
1524323923.955,,0.000000e+000,5.699606e+001,5.700306e+001,1,0,7.741935e-001,0.000000e+000,-1.700923e+000,-1.700923e+000,1.883518e+000,1.607066e+000,-2.154198e+000,1.430243e+000,1.153791e+000,6.081382e-005,6.081382e-005,,,,,,,,,,,,,,,,,,,,
1524323948.905,,0.000000e+000,5.700167e+001,5.699465e+001,1,0,1.032258e+000,0.000000e+000,-2.734874e+000,-2.734874e+000,9.394971e-001,5.712838e-001,-3.688898e+000,-1.452628e-002,-3.827395e-001,3.834855e-005,3.834855e-005,,,,,,,,,,,,,,,,,,,,
1524323974.995,,0.000000e+000,5.699465e+001,5.699606e+001,1,0,1.290323e+000,0.000000e+000,-4.348821e+000,-4.348821e+000,-5.820576e-001,-1.042598e+000,-5.523393e+000,-1.756630e+000,-2.217170e+000,2.975270e-006,2.975270e-006,,,,,,,,,,,,,,,,,,,,
1524324000.155,,0.000000e+000,5.700728e+001,5.699886e+001,1,0,1.548387e+000,0.000000e+000,-6.269780e+000,-6.269780e+000,-2.414384e+000,-2.967237e+000,-7.467248e+000,-3.611853e+000,-4.164706e+000,-3.934342e-005,-3.934342e-005,,,,,,,,,,,,,,,,,,,,
1524324025.505,,0.000000e+000,5.699465e+001,5.699746e+001,1,0,1.806452e+000,0.000000e+000,-8.144960e+000,-8.144960e+000,-4.205130e+000,-4.852247e+000,-9.059745e+000,-5.119914e+000,-5.767032e+000,-8.074813e-005,-8.074813e-005,,,,,,,,,,,,,,,,,,,,
1524324051.245,,0.000000e+000,5.699325e+001,5.700587e+001,1,0,2.064516e+000,0.000000e+000,-9.510185e+000,-9.510185e+000,-5.479819e+000,-6.221900e+000,-9.528486e+000,-5.498120e+000,-6.240201e+000,-1.105987e-004,-1.105987e-004,,,,,,,,,,,,,,,,,,,,
1524324076.605,,0.000000e+000,5.700728e+001,5.699325e+001,1,0,2.322581e+000,0.000000e+000,-9.653772e+000,-9.653772e+000,-5.532626e+000,-6.361505e+000,-8.581858e+000,-4.460711e+000,-5.289590e+000,-1.131497e-004,-1.131497e-004,,,,,,,,,,,,,,,,,,,,
1524324102.375,,0.000000e+000,5.699465e+001,5.699746e+001,1,0,2.580645e+000,0.000000e+000,-8.505684e+000,-8.505684e+000,-4.294450e+000,-5.214713e+000,-6.900323e+000,-2.689090e+000,-3.609352e+000,-8.684280e-005,-8.684280e-005,,,,,,,,,,,,,,,,,,,,
1524324127.206,,0.000000e+000,5.699045e+001,5.700167e+001,1,0,2.838710e+000,0.000000e+000,-6.590066e+000,-6.590066e+000,-2.294385e+000,-3.303846e+000,-5.157308e+000,-8.616269e-001,-1.871088e+000,-4.348264e-005,-4.348264e-005,,,,,,,,,,,,,,,,,,,,
1524324152.126,,0.000000e+000,5.698904e+001,5.700728e+001,1,0,3.096774e+000,0.000000e+000,-4.576333e+000,-4.576333e+000,-1.844635e-001,-1.289358e+000,-3.630842e+000,7.610273e-001,-3.438675e-001,2.281275e-006,2.281275e-006,,,,,,,,,,,,,,,,,,,,
1524324164.386,,0.000000e+000,5.700728e+001,5.700026e+001,1,0,4.000000e+000,0.000000e+000,-1.305409e+000,-1.305409e+000,3.409687e+000,1.976538e+000,-2.835920e+000,1.879176e+000,4.460270e-001,7.775602e-005,7.775602e-005,,,,,,,,,,,,,,,,,,,,