File: Experimental Raw Data/TC04-12-01K VRMac VRMde/raw/TC04-12-01K_VRMac_56K_3000s.dc.raw
[Header]
TITLE,MPMS DC Measurement
BYAPP,MPMS Measurement,2.1,Raw with ABS
FILEOPENTIME, 1524279112.873000 4/20/2018, 8:51:52 PM

INFO, APPNAME, MPMS MultiVu Application, Revision 1.61,  Build 082

INFO, NAME, TC04-12-01K
INFO, WEIGHT, 1.000
INFO, AREA, 1.000
INFO, LENGTH, 1.000
INFO, SHAPE, 0
INFO, COMMENT,
INFO, SEQUENCE FILE: VRMac_56K_3000s_VRMde_55K.seq


INFO, BACKGROUND DATA FILE:, None


STARTUPAXIS,X,8,LINEAR,AUTO,0.000000,0.000000
STARTUPAXIS,Y1,10,LINEAR,AUTO,0.000000,0.000000


STARTUPGROUP,Longitudinal
FIELDGROUP,Longitudinal,1,3,4,5,6,8,9,10,11,12,13,14,15,16,17,18,19,20,21,22,23
FIELDGROUP,Transverse,1,3,4,5,6,8,9,24,25,26,27,28,29,30,31,32,33,34,35,36,37

PLOT_APPEARANCE,ALL,HORZ_GRID_ON,VERT_GRID_ON,MARKERS_ONLY

[Data]
Time,Comment,Field (Oe),Start Temperature (K),End Temperature (K),Scan,Rejected,Position (cm),Rot Position (deg),Long Voltage,Long Average Voltage,Long Detrended Voltage,Long Demeaned Voltage,Long Regression Fit,Long Detrended Fit,Long Demeaned Fit,Long Scaled Response,Long Avg. Scaled Response,Long Background Response,Long Response [w/ABS],Long Detrended Resp. [w/ABS],Long Fit [w/ABS],Long Detrended Fit [w/ABS],Trans Voltage,Trans Average Voltage,Trans Detrended Voltage,Trans Demeaned Voltage,Trans Regression Fit,Trans Detrended Fit,Trans Demeaned Fit,Trans Scaled Response,Trans Avg Scaled Response,Trans Background Response,Trans Response [w/ABS],Trans Detrended Resp. [w/ABS],Trans Fit [w/ABS],Trans Detrended Fit [w/ABS],
1524279112.863,,0.000000e+000,5.606495e+001,5.604181e+001,1,0,0.000000e+000,0.000000e+000,3.375753e+000,3.375753e+000,6.083844e-001,6.083844e-001,4.028083e+000,1.260714e+000,1.260714e+000,2.675210e-005,2.675210e-005,,,,,,,,,,,,,,,,,,,,
1524279125.873,,0.000000e+000,5.604181e+001,5.604045e+001,1,0,1.290323e-001,0.000000e+000,4.074159e+000,4.074159e+000,8.596359e-001,8.320658e-001,4.736102e+000,1.521579e+000,1.494009e+000,3.379022e-005,3.379022e-005,,,,,,,,,,,,,,,,,,,,
1524279138.913,,0.000000e+000,5.604045e+001,5.603773e+001,1,0,2.580645e-001,0.000000e+000,4.634928e+000,4.634928e+000,1.132032e+000,1.069227e+000,5.214753e+000,1.711858e+000,1.649052e+000,4.047831e-005,4.047831e-005,,,,,,,,,,,,,,,,,,,,
1524279151.453,,0.000000e+000,5.603773e+001,5.602005e+001,1,0,3.870968e-001,0.000000e+000,5.062943e+000,5.062943e+000,1.367366e+000,1.265085e+000,5.490223e+000,1.794646e+000,1.692365e+000,4.595249e-005,4.595249e-005,,,,,,,,,,,,,,,,,,,,
1524279164.113,,0.000000e+000,5.602005e+001,5.602005e+001,1,0,5.161290e-001,0.000000e+000,5.332723e+000,5.332723e+000,1.526364e+000,1.384347e+000,5.532648e+000,1.726289e+000,1.584272e+000,4.937741e-005,4.937741e-005,,,,,,,,,,,,,,,,,,,,
1524279176.563,,0.000000e+000,5.602005e+001,5.601733e+001,1,0,6.451613e-001,0.000000e+000,5.463951e+000,5.463951e+000,1.579337e+000,1.395496e+000,5.374496e+000,1.489882e+000,1.306041e+000,5.033751e-005,5.033751e-005,,,,,,,,,,,,,,,,,,,,
1524279189.553,,0.000000e+000,5.601462e+001,5.601326e+001,1,0,7.741935e-001,0.000000e+000,5.405509e+000,5.405509e+000,1.479243e+000,1.254018e+000,5.026710e+000,1.100443e+000,8.752184e-001,4.775761e-005,4.775761e-005,,,,,,,,,,,,,,,,,,,,
1524279201.713,,0.000000e+000,5.601326e+001,5.600375e+001,1,0,9.032258e-001,0.000000e+000,5.179828e+000,5.179828e+000,1.232809e+000,9.611135e-001,4.535194e+000,5.881757e-001,3.164802e-001,4.192460e-005,4.192460e-005,,,,,,,,,,,,,,,,,,,,
1524279214.323,,0.000000e+000,5.600375e+001,5.600238e+001,1,0,1.032258e+000,0.000000e+000,4.778363e+000,4.778363e+000,8.350713e-001,5.234246e-001,3.931937e+000,-1.135394e-002,-3.230007e-001,3.255853e-005,3.255853e-005,,,,,,,,,,,,,,,,,,,,
1524279226.593,,0.000000e+000,5.600238e+001,5.600646e+001,1,0,1.161290e+000,0.000000e+000,4.240177e+000,4.240177e+000,3.042849e-001,-5.284262e-002,3.260914e+000,-6.749784e-001,-1.032106e+000,2.023268e-005,2.023268e-005,,,,,,,,,,,,,,,,,,,,
1524279239.703,,0.000000e+000,5.600646e+001,5.599152e+001,1,0,1.290323e+000,0.000000e+000,3.582971e+000,3.582971e+000,-3.343806e-001,-7.346485e-001,2.527735e+000,-1.389616e+000,-1.789884e+000,5.465859e-006,5.465859e-006,,,,,,,,,,,,,,,,,,,,
1524279252.303,,0.000000e+000,5.599152e+001,5.599695e+001,1,0,1.419355e+000,0.000000e+000,2.821393e+000,2.821393e+000,-1.064891e+000,-1.509475e+000,1.751567e+000,-2.134717e+000,-2.579300e+000,-1.138728e-005,-1.138728e-005,,,,,,,,,,,,,,,,,,,,
1524279264.993,,0.000000e+000,5.599967e+001,5.600238e+001,1,0,1.548387e+000,0.000000e+000,2.025330e+000,2.025330e+000,-1.829592e+000,-2.320691e+000,9.691375e-001,-2.885785e+000,-3.376884e+000,-2.899730e-005,-2.899730e-005,,,,,,,,,,,,,,,,,,,,
1524279277.463,,0.000000e+000,5.600238e+001,5.599695e+001,1,0,1.677419e+000,0.000000e+000,1.226978e+000,1.226978e+000,-2.595814e+000,-3.129549e+000,2.431707e-001,-3.579621e+000,-4.113356e+000,-4.668123e-005,-4.668123e-005,,,,,,,,,,,,,,,,,,,,
1524279290.693,,0.000000e+000,5.600238e+001,5.600646e+001,1,0,1.806452e+000,0.000000e+000,4.261845e-001,4.261845e-001,-3.349705e+000,-3.933444e+000,-3.569488e-001,-4.132838e+000,-4.716577e+000,-6.408330e-005,-6.408330e-005,,,,,,,,,,,,,,,,,,,,
1524279303.273,,0.000000e+000,5.599288e+001,5.599831e+001,1,0,1.935484e+000,0.000000e+000,-2.502480e-001,-2.502480e-001,-3.983094e+000,-4.608585e+000,-7.171243e-001,-4.449971e+000,-5.075461e+000,-7.882052e-005,-7.882052e-005,,,,,,,,,,,,,,,,,,,,
1524279315.773,,0.000000e+000,5.599831e+001,5.600238e+001,1,0,2.064516e+000,0.000000e+000,-7.612726e-001,-7.612726e-001,-4.450918e+000,-5.115178e+000,-7.808906e-001,-4.470536e+000,-5.134796e+000,-8.985055e-005,-8.985055e-005,,,,,,,,,,,,,,,,,,,,
1524279328.443,,0.000000e+000,5.600238e+001,5.600782e+001,1,0,2.193548e+000,0.000000e+000,-1.030442e+000,-1.030442e+000,-4.674791e+000,-5.390264e+000,-5.317582e-001,-4.176108e+000,-4.891580e+000,-9.546819e-005,-9.546819e-005,,,,,,,,,,,,,,,,,,,,
1524279341.043,,0.000000e+000,5.599967e+001,5.599695e+001,1,0,2.322581e+000,0.000000e+000,-1.015030e+000,-1.015030e+000,-4.612703e+000,-5.371120e+000,-5.284119e-002,-3.650514e+000,-4.408932e+000,-9.466312e-005,-9.466312e-005,,,,,,,,,,,,,,,,,,,,
1524279353.593,,0.000000e+000,5.599695e+001,5.599967e+001,1,0,2.451613e+000,0.000000e+000,-7.168689e-001,-7.168689e-001,-4.268116e+000,-5.070319e+000,5.883434e-001,-2.962904e+000,-3.765107e+000,-8.757319e-005,-8.757319e-005,,,,,,,,,,,,,,,,,,,,
1524279366.303,,0.000000e+000,5.599967e+001,5.598880e+001,1,0,2.580645e+000,0.000000e+000,-1.924163e-001,-1.924163e-001,-3.690444e+000,-4.541057e+000,1.283645e+000,-2.214382e+000,-3.064996e+000,-7.526754e-005,-7.526754e-005,,,,,,,,,,,,,,,,,,,,
1524279379.013,,0.000000e+000,5.598880e+001,5.600103e+001,1,0,2.709677e+000,0.000000e+000,5.328450e-001,5.328450e-001,-2.918139e+000,-3.809423e+000,2.000142e+000,-1.450841e+000,-2.342126e+000,-5.861351e-005,-5.861351e-005,,,,,,,,,,,,,,,,,,,,
1524279391.953,,0.000000e+000,5.599424e+001,5.600238e+001,1,0,2.838710e+000,0.000000e+000,1.349355e+000,1.349355e+000,-2.052509e+000,-2.991876e+000,2.689837e+000,-7.120273e-001,-1.651395e+000,-3.989344e-005,-3.989344e-005,,,,,,,,,,,,,,,,,,,,
1524279404.093,,0.000000e+000,5.599695e+001,5.599967e+001,1,0,2.967742e+000,0.000000e+000,2.210269e+000,2.210269e+000,-1.137124e+000,-2.125691e+000,3.335338e+000,-1.205510e-002,-1.000622e+000,-2.008675e-005,-2.008675e-005,,,,,,,,,,,,,,,,,,,,
1524279416.673,,0.000000e+000,5.599967e+001,5.599831e+001,1,0,3.096774e+000,0.000000e+000,3.034256e+000,3.034256e+000,-2.550456e-001,-1.289492e+000,3.920724e+000,6.314219e-001,-4.030247e-001,-1.008040e-006,-1.008040e-006,,,,,,,,,,,,,,,,,,,,
1524279429.143,,0.000000e+000,5.599831e+001,5.599831e+001,1,0,3.225806e+000,0.000000e+000,3.831846e+000,3.831846e+000,5.895106e-001,-4.785550e-001,4.436863e+000,1.194528e+000,1.264629e-001,1.731377e-005,1.731377e-005,,,,,,,,,,,,,,,,,,,,
1524279441.783,,0.000000e+000,5.599831e+001,5.599559e+001,1,0,3.354839e+000,0.000000e+000,4.534676e+000,4.534676e+000,1.347484e+000,2.273612e-001,4.825441e+000,1.638250e+000,5.181265e-001,3.358803e-005,3.358803e-005,,,,,,,,,,,,,,,,,,,,
1524279454.233,,0.000000e+000,5.599559e+001,5.599695e+001,1,0,3.483871e+000,0.000000e+000,5.153277e+000,5.153277e+000,2.011454e+000,8.530488e-001,5.069008e+000,1.927185e+000,7.687798e-001,4.785218e-005,4.785218e-005,,,,,,,,,,,,,,,,,,,,
1524279466.603,,0.000000e+000,5.599424e+001,5.599831e+001,1,0,3.612903e+000,0.000000e+000,5.622797e+000,5.622797e+000,2.541636e+000,1.327478e+000,5.115062e+000,2.033900e+000,8.197427e-001,5.897650e-005,5.897650e-005,,,,,,,,,,,,,,,,,,,,
1524279479.023,,0.000000e+000,5.599831e+001,5.600103e+001,1,0,3.741935e+000,0.000000e+000,5.908598e+000,5.908598e+000,2.880863e+000,1.625104e+000,5.013623e+000,1.985888e+000,7.301292e-001,6.595605e-005,6.595605e-005,,,,,,,,,,,,,,,,,,,,
1524279491.283,,0.000000e+000,5.599424e+001,5.600918e+001,1,0,3.870968e+000,0.000000e+000,6.022126e+000,6.022126e+000,3.050275e+000,1.743075e+000,4.788402e+000,1.816551e+000,5.093513e-001,6.905147e-005,6.905147e-005,,,,,,,,,,,,,,,,,,,,
1524279503.563,,0.000000e+000,5.599288e+001,5.600375e+001,1,0,4.000000e+000,0.000000e+000,5.974823e+000,5.974823e+000,3.055697e+000,1.707796e+000,4.505488e+000,1.586362e+000,2.384610e-001,6.857434e-005,6.857434e-005,,,,,,,,,,,,,,,,,,,,
1524279528.863,,0.000000e+000,5.600238e+001,5.599831e+001,1,0,0.000000e+000,0.000000e+000,5.089342e+000,5.089342e+000,8.365374e-001,8.365374e-001,5.846212e+000,1.593407e+000,1.593407e+000,3.917045e-005,3.917045e-005,,,,,,,,,,,,,,,,,,,,
1524279541.593,,0.000000e+000,5.598880e+001,5.599967e+001,1,0,1.290323e-001,0.000000e+000,5.249104e+000,5.249104e+000,1.052483e+000,1.008914e+000,6.026046e+000,1.829425e+000,1.785856e+000,4.330099e-005,4.330099e-005,,,,,,,,,,,,,,,,,,,,
1524279554.043,,0.000000e+000,5.599967e+001,5.599831e+001,1,0,2.580645e-001,0.000000e+000,5.464714e+000,5.464714e+000,1.317680e+000,1.229645e+000,6.154737e+000,2.007703e+000,1.919668e+000,4.869621e-005,4.869621e-005,,,,,,,,,,,,,,,,,,,,
1524279566.613,,0.000000e+000,5.599559e+001,5.599559e+001,1,0,3.870968e-001,0.000000e+000,5.661402e+000,5.661402e+000,1.568571e+000,1.437139e+000,6.156789e+000,2.063958e+000,1.932526e+000,5.361615e-005,5.361615e-005,,,,,,,,,,,,,,,,,,,,
1524279579.103,,0.000000e+000,5.599695e+001,5.599559e+001,1,0,5.161290e-001,0.000000e+000,5.788662e+000,5.788662e+000,1.746650e+000,1.569897e+000,6.003248e+000,1.961235e+000,1.784483e+000,5.703807e-005,5.703807e-005,,,,,,,,,,,,,,,,,,,,
1524279591.513,,0.000000e+000,5.599559e+001,5.600375e+001,1,0,6.451613e-001,0.000000e+000,5.775845e+000,5.775845e+000,1.783101e+000,1.562193e+000,5.667293e+000,1.674549e+000,1.453641e+000,5.720257e-005,5.720257e-005,,,,,,,,,,,,,,,,,,,,
1524279604.353,,0.000000e+000,5.600375e+001,5.599831e+001,1,0,7.741935e-001,0.000000e+000,5.598840e+000,5.598840e+000,1.664241e+000,1.397956e+000,5.159899e+000,1.225300e+000,9.590149e-001,5.392565e-005,5.392565e-005,,,,,,,,,,,,,,,,,,,,
1524279617.163,,0.000000e+000,5.599831e+001,5.600103e+001,1,0,9.032258e-001,0.000000e+000,5.246815e+000,5.246815e+000,1.366745e+000,1.057006e+000,4.531582e+000,6.515126e-001,3.417735e-001,4.662459e-005,4.662459e-005,,,,,,,,,,,,,,,,,,,,
1524279629.833,,0.000000e+000,5.599016e+001,5.599424e+001,1,0,1.032258e+000,0.000000e+000,4.726787e+000,4.726787e+000,9.054726e-001,5.526342e-001,3.808844e+000,-1.247013e-002,-3.653085e-001,3.564537e-005,3.564537e-005,,,,,,,,,,,,,,,,,,,,
1524279642.613,,0.000000e+000,5.599831e+001,5.599695e+001,1,0,1.161290e+000,0.000000e+000,4.076295e+000,4.076295e+000,3.075051e-001,-9.135866e-002,3.029862e+000,-7.389274e-001,-1.137791e+000,2.166222e-005,2.166222e-005,,,,,,,,,,,,,,,,,,,,
1524279654.753,,0.000000e+000,5.599695e+001,5.599152e+001,1,0,1.290323e+000,0.000000e+000,3.331350e+000,3.331350e+000,-3.814379e-001,-8.227959e-001,2.200908e+000,-1.511880e+000,-1.953238e+000,5.600697e-006,5.600697e-006,,,,,,,,,,,,,,,,,,,,
1524279667.613,,0.000000e+000,5.599559e+001,5.599967e+001,1,0,1.419355e+000,0.000000e+000,2.507820e+000,2.507820e+000,-1.154612e+000,-1.642365e+000,1.347969e+000,-2.314463e+000,-2.802215e+000,-1.231242e-005,-1.231242e-005,,,,,,,,,,,,,,,,,,,,
1524279679.913,,0.000000e+000,5.599695e+001,5.600103e+001,1,0,1.548387e+000,0.000000e+000,1.607233e+000,1.607233e+000,-1.996018e+000,-2.527050e+000,4.872378e-001,-3.116013e+000,-3.647045e+000,-3.176472e-005,-3.176472e-005,,,,,,,,,,,,,,,,,,,,
1524279692.443,,0.000000e+000,5.600103e+001,5.599967e+001,1,0,1.677419e+000,0.000000e+000,7.164111e-001,7.164111e-001,-2.830071e+000,-3.413011e+000,-3.110907e-001,-3.857573e+000,-4.440513e+000,-5.101449e-005,-5.101449e-005,,,,,,,,,,,,,,,,,,,,
1524279704.923,,0.000000e+000,5.599967e+001,5.599831e+001,1,0,1.806452e+000,0.000000e+000,-8.606088e-002,-8.606088e-002,-3.584263e+000,-4.208325e+000,-9.327769e-001,-4.430979e+000,-5.055041e+000,-6.855071e-005,-6.855071e-005,,,,,,,,,,,,,,,,,,,,
1524279718.123,,0.000000e+000,5.599831e+001,5.599831e+001,1,0,1.935484e+000,0.000000e+000,-8.154421e-001,-8.154421e-001,-4.253244e+000,-4.923761e+000,-1.324616e+000,-4.762418e+000,-5.432935e+000,-8.414155e-005,-8.414155e-005,,,,,,,,,,,,,,,,,,,,
1524279730.563,,0.000000e+000,5.600238e+001,5.600238e+001,1,0,2.064516e+000,0.000000e+000,-1.370413e+000,-1.370413e+000,-4.746513e+000,-5.460118e+000,-1.389348e+000,-4.765449e+000,-5.479053e+000,-9.582459e-005,-9.582459e-005,,,,,,,,,,,,,,,,,,,,
1524279743.173,,0.000000e+000,5.600238e+001,5.599831e+001,1,0,2.193548e+000,0.000000e+000,-1.645228e+000,-1.645228e+000,-4.969855e+000,-5.729403e+000,-1.130502e+000,-4.455130e+000,-5.214678e+000,-1.014557e-004,-1.014557e-004,,,,,,,,,,,,,,,,,,,,
1524279756.413,,0.000000e+000,5.600238e+001,5.599831e+001,1,0,2.322581e+000,0.000000e+000,-1.619745e+000,-1.619745e+000,-4.886158e+000,-5.695186e+000,-6.096777e-001,-3.876090e+000,-4.685119e+000,-1.002616e-004,-1.002616e-004,,,,,,,,,,,,,,,,,,,,
1524279769.023,,0.000000e+000,5.599559e+001,5.599695e+001,1,0,2.451613e+000,0.000000e+000,-1.324941e+000,-1.324941e+000,-4.533077e+000,-5.383962e+000,6.378000e-002,-3.144356e+000,-3.995241e+000,-9.301497e-005,-9.301497e-005,,,,,,,,,,,,,,,,,,,,
1524279781.333,,0.000000e+000,5.599695e+001,5.599559e+001,1,0,2.580645e+000,0.000000e+000,-7.360952e-001,-7.360952e-001,-3.887176e+000,-4.779970e+000,8.107786e-001,-2.340302e+000,-3.233096e+000,-7.923355e-005,-7.923355e-005,,,,,,,,,,,,,,,,,,,,
1524279793.883,,0.000000e+000,5.599559e+001,5.600103e+001,1,0,2.709677e+000,0.000000e+000,1.907378e-002,1.907378e-002,-3.072511e+000,-4.012334e+000,1.558198e+000,-1.533386e+000,-2.473209e+000,-6.167937e-005,-6.167937e-005,,,,,,,,,,,,,,,,,,,,
1524279806.353,,0.000000e+000,5.599695e+001,5.599424e+001,1,0,2.838710e+000,0.000000e+000,8.719006e-001,8.719006e-001,-2.162907e+000,-3.152167e+000,2.283821e+000,-7.509869e-001,-1.740247e+000,-4.202696e-005,-4.202696e-005,,,,,,,,,,,,,,,,,,,,
1524279819.523,,0.000000e+000,5.599695e+001,5.599559e+001,1,0,2.967742e+000,0.000000e+000,1.783017e+000,1.783017e+000,-1.189759e+000,-2.224529e+000,2.960067e+000,-1.270893e-002,-1.047479e+000,-2.093805e-005,-2.093805e-005,,,,,,,,,,,,,,,,,,,,
1524279831.954,,0.000000e+000,5.600238e+001,5.599559e+001,1,0,3.096774e+000,0.000000e+000,2.652934e+000,2.652934e+000,-2.644323e-001,-1.340811e+000,3.581967e+000,6.646012e-001,-4.117777e-001,-9.057258e-007,-9.057258e-007,,,,,,,,,,,,,,,,,,,,
1524279844.354,,0.000000e+000,5.599559e+001,5.599695e+001,1,0,3.225806e+000,0.000000e+000,3.493248e+000,3.493248e+000,6.385891e-001,-4.954054e-001,4.110150e+000,1.255491e+000,1.214964e-001,1.855720e-005,1.855720e-005,,,,,,,,,,,,,,,,,,,,
1524279857.404,,0.000000e+000,5.599695e+001,5.599695e+001,1,0,3.354839e+000,0.000000e+000,4.247959e+000,4.247959e+000,1.440380e+000,2.849333e-001,4.525059e+000,1.717480e+000,5.620334e-001,3.594560e-005,3.594560e-005,,,,,,,,,,,,,,,,,,,,
1524279869.964,,0.000000e+000,5.599695e+001,5.599559e+001,1,0,3.483871e+000,0.000000e+000,4.842908e+000,4.842908e+000,2.106275e+000,8.947747e-001,4.753575e+000,2.016941e+000,8.054411e-001,5.011178e-005,5.011178e-005,,,,,,,,,,,,,,,,,,,,
1524279882.614,,0.000000e+000,5.599559e+001,5.600375e+001,1,0,3.612903e+000,0.000000e+000,5.323415e+000,5.323415e+000,2.641604e+000,1.375559e+000,4.813159e+000,2.131349e+000,8.653040e-001,6.135664e-005,6.135664e-005,,,,,,,,,,,,,,,,,,,,
1524279894.964,,0.000000e+000,5.600375e+001,5.599695e+001,1,0,3.741935e+000,0.000000e+000,5.616693e+000,5.616693e+000,2.997309e+000,1.683104e+000,4.693884e+000,2.074500e+000,7.602947e-001,6.861185e-005,6.861185e-005,,,,,,,,,,,,,,,,,,,,
1524279907.424,,0.000000e+000,5.599559e+001,5.600103e+001,1,0,3.870968e+000,0.000000e+000,5.722744e+000,5.722744e+000,3.154945e+000,1.813468e+000,4.464666e+000,1.896867e+000,5.553894e-001,7.159905e-005,7.159905e-005,,,,,,,,,,,,,,,,,,,,
1524279920.324,,0.000000e+000,5.599831e+001,5.600782e+001,1,0,4.000000e+000,0.000000e+000,5.675746e+000,5.675746e+000,3.175062e+000,1.777838e+000,4.155833e+000,1.655149e+000,2.579246e-001,7.132223e-005,7.132223e-005,,,,,,,,,,,,,,,,,,,,
1524279945.224,,0.000000e+000,5.599695e+001,5.599695e+001,1,0,0.000000e+000,0.000000e+000,4.751202e+000,4.751202e+000,8.849931e-001,8.849931e-001,5.522516e+000,1.656308e+000,1.656308e+000,4.104580e-005,4.104580e-005,,,,,,,,,,,,,,,,,,,,
1524279957.574,,0.000000e+000,5.599288e+001,5.599831e+001,1,0,1.290323e-001,0.000000e+000,5.119097e+000,5.119097e+000,1.097309e+000,1.052306e+000,5.925954e+000,1.904166e+000,1.859164e+000,4.503609e-005,4.503609e-005,,,,,,,,,,,,,,,,,,,,
1524279970.314,,0.000000e+000,5.599152e+001,5.600375e+001,1,0,2.580645e-001,0.000000e+000,5.138781e+000,5.138781e+000,1.401021e+000,1.310048e+000,5.823442e+000,2.085682e+000,1.994709e+000,5.125799e-005,5.125799e-005,,,,,,,,,,,,,,,,,,,,
1524279983.604,,0.000000e+000,5.599559e+001,5.599424e+001,1,0,3.870968e-001,0.000000e+000,5.324330e+000,5.324330e+000,1.649760e+000,1.513532e+000,5.819415e+000,2.144844e+000,2.008617e+000,5.613587e-005,5.613587e-005,,,,,,,,,,,,,,,,,,,,
1524279995.484,,0.000000e+000,5.599424e+001,5.599424e+001,1,0,5.161290e-001,0.000000e+000,5.651637e+000,5.651637e+000,1.810609e+000,1.627703e+000,5.875120e+000,2.034093e+000,1.851186e+000,5.911860e-005,5.911860e-005,,,,,,,,,,,,,,,,,,,,
1524280007.834,,0.000000e+000,5.599424e+001,5.599967e+001,1,0,6.451613e-001,0.000000e+000,5.396354e+000,5.396354e+000,1.847045e+000,1.621106e+000,5.287584e+000,1.738275e+000,1.512336e+000,5.918631e-005,5.918631e-005,,,,,,,,,,,,,,,,,,,,
1524280020.254,,0.000000e+000,5.599152e+001,5.600238e+001,1,0,7.741935e-001,0.000000e+000,5.197986e+000,5.197986e+000,1.707123e+000,1.434802e+000,4.761525e+000,1.270662e+000,9.983413e-001,5.541321e-005,5.541321e-005,,,,,,,,,,,,,,,,,,,,
1524280032.814,,0.000000e+000,5.599559e+001,5.599831e+001,1,0,9.032258e-001,0.000000e+000,4.830396e+000,4.830396e+000,1.403300e+000,1.087961e+000,4.101931e+000,6.748349e-001,3.594964e-001,4.791784e-005,4.791784e-005,,,,,,,,,,,,,,,,,,,,
1524280045.094,,0.000000e+000,5.599831e+001,5.599424e+001,1,0,1.032258e+000,0.000000e+000,4.298772e+000,4.298772e+000,9.282310e-001,5.649219e-001,3.357641e+000,-1.289988e-002,-3.762090e-001,3.666154e-005,3.666154e-005,,,,,,,,,,,,,,,,,,,,
1524280057.644,,0.000000e+000,5.600510e+001,5.599288e+001,1,0,1.161290e+000,0.000000e+000,3.620966e+000,3.620966e+000,3.092416e-001,-9.769511e-002,2.547244e+000,-7.644802e-001,-1.171417e+000,2.215091e-005,2.215091e-005,,,,,,,,,,,,,,,,,,,,
1524280070.184,,0.000000e+000,5.599288e+001,5.600238e+001,1,0,1.290323e+000,0.000000e+000,2.852064e+000,2.852064e+000,-3.973978e-001,-8.563113e-001,1.687320e+000,-1.562142e+000,-2.021055e+000,5.737224e-006,5.737224e-006,,,,,,,,,,,,,,,,,,,,
1524280082.784,,0.000000e+000,5.600238e+001,5.599831e+001,1,0,1.419355e+000,0.000000e+000,1.984894e+000,1.984894e+000,-1.200481e+000,-1.703621e+000,7.920551e-001,-2.393319e+000,-2.896459e+000,-1.288538e-005,-1.288538e-005,,,,,,,,,,,,,,,,,,,,
1524280095.364,,0.000000e+000,5.599831e+001,5.599695e+001,1,0,1.548387e+000,0.000000e+000,1.069352e+000,1.069352e+000,-2.048010e+000,-2.595578e+000,-9.828761e-002,-3.215650e+000,-3.763218e+000,-3.251790e-005,-3.251790e-005,,,,,,,,,,,,,,,,,,,,
1524280107.744,,0.000000e+000,5.599695e+001,5.599967e+001,1,0,1.677419e+000,0.000000e+000,1.451133e-001,1.451133e-001,-2.909470e+000,-3.503494e+000,-9.256571e-001,-3.980240e+000,-4.574264e+000,-5.242128e-005,-5.242128e-005,,,,,,,,,,,,,,,,,,,,
1524280120.184,,0.000000e+000,5.599831e+001,5.599695e+001,1,0,1.806452e+000,0.000000e+000,-7.220569e-001,-7.220569e-001,-3.708827e+000,-4.348321e+000,-1.590110e+000,-4.576880e+000,-5.216373e+000,-7.096231e-005,-7.096231e-005,,,,,,,,,,,,,,,,,,,,
1524280133.384,,0.000000e+000,5.600103e+001,5.600646e+001,1,0,1.935484e+000,0.000000e+000,-1.499657e+000,-1.499657e+000,-4.421827e+000,-5.108786e+000,-1.989699e+000,-4.911870e+000,-5.598828e+000,-8.756900e-005,-8.756900e-005,,,,,,,,,,,,,,,,,,,,
1524280145.774,,0.000000e+000,5.600375e+001,5.599559e+001,1,0,2.064516e+000,0.000000e+000,-2.042878e+000,-2.042878e+000,-4.902627e+000,-5.633389e+000,-2.051583e+000,-4.911333e+000,-5.642095e+000,-9.899745e-005,-9.899745e-005,,,,,,,,,,,,,,,,,,,,
1524280158.384,,0.000000e+000,5.599288e+001,5.599967e+001,1,0,2.193548e+000,0.000000e+000,-2.321813e+000,-2.321813e+000,-5.116479e+000,-5.896006e+000,-1.788597e+000,-4.583264e+000,-5.362790e+000,-1.044536e-004,-1.044536e-004,,,,,,,,,,,,,,,,,,,,
1524280171.324,,0.000000e+000,5.599016e+001,5.599831e+001,1,0,2.322581e+000,0.000000e+000,-2.302434e+000,-2.302434e+000,-5.036044e+000,-5.855289e+000,-1.257854e+000,-3.991463e+000,-4.810709e+000,-1.033166e-004,-1.033166e-004,,,,,,,,,,,,,,,,,,,,
1524280184.104,,0.000000e+000,5.599831e+001,5.599695e+001,1,0,2.451613e+000,0.000000e+000,-1.959411e+000,-1.959411e+000,-4.632293e+000,-5.497472e+000,-5.613185e-001,-3.234201e+000,-4.099380e+000,-9.496781e-005,-9.496781e-005,,,,,,,,,,,,,,,,,,,,
1524280196.534,,0.000000e+000,5.599695e+001,5.599967e+001,1,0,2.580645e+000,0.000000e+000,-1.353933e+000,-1.353933e+000,-3.966510e+000,-4.876998e+000,2.035473e-001,-2.409029e+000,-3.319518e+000,-8.075355e-005,-8.075355e-005,,,,,,,,,,,,,,,,,,,,
1524280209.064,,0.000000e+000,5.600238e+001,5.600238e+001,1,0,2.709677e+000,0.000000e+000,-5.778592e-001,-5.778592e-001,-3.124033e+000,-4.087082e+000,9.708153e-001,-1.575358e+000,-2.538408e+000,-6.262977e-005,-6.262977e-005,,,,,,,,,,,,,,,,,,,,
1524280221.594,,0.000000e+000,5.599559e+001,5.599695e+001,1,0,2.838710e+000,0.000000e+000,2.955672e-001,2.955672e-001,-2.189670e+000,-3.189612e+000,1.713385e+000,-7.718529e-001,-1.771795e+000,-4.237576e-005,-4.237576e-005,,,,,,,,,,,,,,,,,,,,
1524280234.094,,0.000000e+000,5.598745e+001,5.599288e+001,1,0,2.967742e+000,0.000000e+000,1.207904e+000,1.207904e+000,-1.214394e+000,-2.268929e+000,2.409237e+000,-1.306131e-002,-1.067596e+000,-2.128870e-005,-2.128870e-005,,,,,,,,,,,,,,,,,,,,
1524280246.224,,0.000000e+000,5.599152e+001,5.599559e+001,1,0,3.096774e+000,0.000000e+000,2.119173e+000,2.119173e+000,-2.426859e-001,-1.334892e+000,3.044698e+000,6.828390e-001,-4.093673e-001,-2.100060e-007,-2.100060e-007,,,,,,,,,,,,,,,,,,,,
1524280259.034,,0.000000e+000,5.599695e+001,5.600375e+001,1,0,3.225806e+000,0.000000e+000,2.956435e+000,2.956435e+000,6.596231e-001,-4.843040e-001,3.584605e+000,1.287793e+000,1.438656e-001,1.924650e-005,1.924650e-005,,,,,,,,,,,,,,,,,,,,
1524280271.554,,0.000000e+000,5.599016e+001,5.599695e+001,1,0,3.354839e+000,0.000000e+000,3.709163e+000,3.709163e+000,1.477454e+000,2.896020e-001,3.995394e+000,1.763685e+000,5.758331e-001,3.686723e-005,3.686723e-005,,,,,,,,,,,,,,,,,,,,
1524280284.114,,0.000000e+000,5.599695e+001,5.599424e+001,1,0,3.483871e+000,0.000000e+000,4.339056e+000,4.339056e+000,2.172212e+000,9.320917e-001,4.235504e+000,2.068660e+000,8.285398e-001,5.167886e-005,5.167886e-005,,,,,,,,,,,,,,,,,,,,
1524280297.164,,0.000000e+000,5.599967e+001,5.599424e+001,1,0,3.612903e+000,0.000000e+000,4.791485e+000,4.791485e+000,2.685083e+000,1.405751e+000,4.290315e+000,2.183913e+000,9.045811e-001,6.250486e-005,6.250486e-005,,,,,,,,,,,,,,,,,,,,
1524280309.694,,0.000000e+000,5.599559e+001,5.599288e+001,1,0,3.741935e+000,0.000000e+000,5.107500e+000,5.107500e+000,3.066926e+000,1.739865e+000,4.167301e+000,2.126727e+000,7.996662e-001,7.034895e-005,7.034895e-005,,,,,,,,,,,,,,,,,,,,
1524280322.324,,0.000000e+000,5.599967e+001,5.599016e+001,1,0,3.870968e+000,0.000000e+000,5.197680e+000,5.197680e+000,3.224472e+000,1.847855e+000,3.919224e+000,1.946016e+000,5.693989e-001,7.317839e-005,7.317839e-005,,,,,,,,,,,,,,,,,,,,
1524280334.954,,0.000000e+000,5.599559e+001,5.599695e+001,1,0,4.000000e+000,0.000000e+000,5.132982e+000,5.132982e+000,3.221308e+000,1.800760e+000,3.608384e+000,1.696709e+000,2.761610e-001,7.245244e-005,7.245244e-005,,,,,,,,,,,,,,,,,,,,
1524280359.994,,0.000000e+000,5.599967e+001,5.600103e+001,1,0,0.000000e+000,0.000000e+000,4.206607e+000,4.206607e+000,9.119401e-001,9.119401e-001,4.991590e+000,1.696923e+000,1.696923e+000,4.204124e-005,4.204124e-005,,,,,,,,,,,,,,,,,,,,
1524280372.644,,0.000000e+000,5.599695e+001,5.599152e+001,1,0,1.290323e-001,0.000000e+000,4.354467e+000,4.354467e+000,1.115095e+000,1.069077e+000,5.188608e+000,1.949236e+000,1.903219e+000,4.590813e-005,4.590813e-005,,,,,,,,,,,,,,,,,,,,
1524280384.944,,0.000000e+000,5.600103e+001,5.599559e+001,1,0,2.580645e-001,0.000000e+000,4.616922e+000,4.616922e+000,1.444861e+000,1.352757e+000,5.306743e+000,2.134681e+000,2.042578e+000,5.260515e-005,5.260515e-005,,,,,,,,,,,,,,,,,,,,
1524280397.654,,0.000000e+000,5.599559e+001,5.599831e+001,1,0,3.870968e-001,0.000000e+000,4.814221e+000,4.814221e+000,1.699129e+000,1.560654e+000,5.310988e+000,2.195896e+000,2.057420e+000,5.763608e-005,5.763608e-005,,,,,,,,,,,,,,,,,,,,
1524280410.254,,0.000000e+000,5.599831e+001,5.599152e+001,1,0,5.161290e-001,0.000000e+000,4.910811e+000,4.910811e+000,1.864127e+000,1.679920e+000,5.128466e+000,2.081782e+000,1.897574e+000,6.062402e-005,6.062402e-005,,,,,,,,,,,,,,,,,,,,
1524280423.014,,0.000000e+000,5.599152e+001,5.599288e+001,1,0,6.451613e-001,0.000000e+000,4.847028e+000,4.847028e+000,1.863357e+000,1.635035e+000,4.760753e+000,1.777082e+000,1.548759e+000,5.986740e-005,5.986740e-005,,,,,,,,,,,,,,,,,,,,
1524280435.634,,0.000000e+000,5.599288e+001,5.600238e+001,1,0,7.741935e-001,0.000000e+000,4.678569e+000,4.678569e+000,1.748345e+000,1.471466e+000,4.229723e+000,1.299499e+000,1.022620e+000,5.668798e-005,5.668798e-005,,,,,,,,,,,,,,,,,,,,
1524280448.324,,0.000000e+000,5.599831e+001,5.599831e+001,1,0,9.032258e-001,0.000000e+000,4.285038e+000,4.285038e+000,1.421518e+000,1.098432e+000,3.553041e+000,6.895210e-001,3.664348e-001,4.870127e-005,4.870127e-005,,,,,,,,,,,,,,,,,,,,
1524280460.934,,0.000000e+000,5.599967e+001,5.599831e+001,1,0,1.032258e+000,0.000000e+000,3.739528e+000,3.739528e+000,9.398438e-001,5.717719e-001,2.786481e+000,-1.320329e-002,-3.812752e-001,3.724267e-005,3.724267e-005,,,,,,,,,,,,,,,,,,,,
1524280473.564,,0.000000e+000,5.599288e+001,5.600646e+001,1,0,1.161290e+000,0.000000e+000,3.020371e+000,3.020371e+000,2.867981e-001,-1.266556e-001,1.952824e+000,-7.807494e-001,-1.194203e+000,2.195055e-005,2.195055e-005,,,,,,,,,,,,,,,,,,,,
1524280486.184,,0.000000e+000,5.599967e+001,5.600375e+001,1,0,1.290323e+000,0.000000e+000,2.209506e+000,2.209506e+000,-4.614922e-001,-9.213052e-001,1.073568e+000,-1.597430e+000,-2.057243e+000,4.557376e-006,4.557376e-006,,,,,,,,,,,,,,,,,,,,
1524280498.664,,0.000000e+000,5.599967e+001,5.599559e+001,1,0,1.419355e+000,0.000000e+000,1.372244e+000,1.372244e+000,-1.237392e+000,-1.742913e+000,1.612287e-001,-2.448407e+000,-2.953928e+000,-1.344542e-005,-1.344542e-005,,,,,,,,,,,,,,,,,,,,
1524280510.794,,0.000000e+000,5.599559e+001,5.599152e+001,1,0,1.548387e+000,0.000000e+000,4.348822e-001,4.348822e-001,-2.114719e+000,-2.666240e+000,-7.388116e-001,-3.288413e+000,-3.839933e+000,-3.374559e-005,-3.374559e-005,,,,,,,,,,,,,,,,,,,,
1524280523.714,,0.000000e+000,5.599152e+001,5.599831e+001,1,0,1.677419e+000,0.000000e+000,-4.876783e-001,-4.876783e-001,-2.971990e+000,-3.568257e+000,-1.581087e+000,-4.065399e+000,-4.661666e+000,-5.357889e-005,-5.357889e-005,,,,,,,,,,,,,,,,,,,,
1524280535.784,,0.000000e+000,5.599831e+001,5.599695e+001,1,0,1.806452e+000,0.000000e+000,-1.367361e+000,-1.367361e+000,-3.793207e+000,-4.435196e+000,-2.243481e+000,-4.669327e+000,-5.311316e+000,-7.262386e-005,-7.262386e-005,,,,,,,,,,,,,,,,,,,,
1524280548.425,,0.000000e+000,5.599695e+001,5.599695e+001,1,0,1.935484e+000,0.000000e+000,-2.133669e+000,-2.133669e+000,-4.492926e+000,-5.180965e+000,-2.647443e+000,-5.006699e+000,-5.694739e+000,-8.894672e-005,-8.894672e-005,,,,,,,,,,,,,,,,,,,,
1524280560.815,,0.000000e+000,5.600238e+001,5.598610e+001,1,0,2.064516e+000,0.000000e+000,-2.694591e+000,-2.694591e+000,-4.990926e+000,-5.727606e+000,-2.713446e+000,-5.009781e+000,-5.746461e+000,-1.007549e-004,-1.007549e-004,,,,,,,,,,,,,,,,,,,,
1524280573.245,,0.000000e+000,5.599967e+001,5.600238e+001,1,0,2.193548e+000,0.000000e+000,-3.011979e+000,-3.011979e+000,-5.242265e+000,-6.022735e+000,-2.449882e+000,-4.680168e+000,-5.460638e+000,-1.070352e-004,-1.070352e-004,,,,,,,,,,,,,,,,,,,,
1524280585.845,,0.000000e+000,5.599967e+001,5.599695e+001,1,0,2.322581e+000,0.000000e+000,-2.972457e+000,-2.972457e+000,-5.137175e+000,-5.963043e+000,-1.904224e+000,-4.068942e+000,-4.894810e+000,-1.053784e-004,-1.053784e-004,,,,,,,,,,,,,,,,,,,,
1524280598.235,,0.000000e+000,5.599695e+001,5.599695e+001,1,0,2.451613e+000,0.000000e+000,-2.623026e+000,-2.623026e+000,-4.730072e+000,-5.601773e+000,-1.191513e+000,-3.298559e+000,-4.170260e+000,-9.695341e-005,-9.695341e-005,,,,,,,,,,,,,,,,,,,,
1524280611.055,,0.000000e+000,5.600782e+001,5.599695e+001,1,0,2.580645e+000,0.000000e+000,-1.992370e+000,-1.992370e+000,-4.032834e+000,-4.955894e+000,-4.144591e-001,-2.454923e+000,-3.377983e+000,-8.206945e-005,-8.206945e-005,,,,,,,,,,,,,,,,,,,,
1524280623.395,,0.000000e+000,5.599288e+001,5.599288e+001,1,0,2.709677e+000,0.000000e+000,-1.182269e+000,-1.182269e+000,-3.162941e+000,-4.126549e+000,3.745388e-001,-1.606133e+000,-2.569741e+000,-6.328763e-005,-6.328763e-005,,,,,,,,,,,,,,,,,,,,
1524280636.715,,0.000000e+000,5.598880e+001,5.600238e+001,1,0,2.838710e+000,0.000000e+000,-2.781720e-001,-2.781720e-001,-2.196511e+000,-3.199808e+000,1.131951e+000,-7.863876e-001,-1.789685e+000,-4.233691e-005,-4.233691e-005,,,,,,,,,,,,,,,,,,,,
1524280649.875,,0.000000e+000,5.599967e+001,5.599559e+001,1,0,2.967742e+000,0.000000e+000,6.178378e-001,6.178378e-001,-1.236904e+000,-2.291695e+000,1.841430e+000,-1.331163e-002,-1.068103e+000,-2.158265e-005,-2.158265e-005,,,,,,,,,,,,,,,,,,,,
1524280662.595,,0.000000e+000,5.599559e+001,5.600238e+001,1,0,3.096774e+000,0.000000e+000,1.543908e+000,1.543908e+000,-2.457341e-001,-1.346972e+000,2.485409e+000,6.957664e-001,-4.054718e-001,-1.179797e-007,-1.179797e-007,,,,,,,,,,,,,,,,,,,,
1524280675.235,,0.000000e+000,5.599967e+001,5.599967e+001,1,0,3.225806e+000,0.000000e+000,2.409400e+000,2.409400e+000,6.828318e-001,-4.716132e-001,3.038457e+000,1.311890e+000,1.574447e-001,1.991113e-005,1.991113e-005,,,,,,,,,,,,,,,,,,,,
1524280687.585,,0.000000e+000,5.599967e+001,5.599831e+001,1,0,3.354839e+000,0.000000e+000,3.174335e+000,3.174335e+000,1.507097e+000,3.103905e-001,3.462853e+000,1.795615e+000,5.989091e-001,3.767548e-005,3.767548e-005,,,,,,,,,,,,,,,,,,,,
1524280700.495,,0.000000e+000,5.599424e+001,5.600510e+001,1,0,3.483871e+000,0.000000e+000,3.806973e+000,3.806973e+000,2.204600e+000,9.604695e-001,3.707392e+000,2.105018e+000,8.608878e-001,5.257061e-005,5.257061e-005,,,,,,,,,,,,,,,,,,,,
1524280712.685,,0.000000e+000,5.600238e+001,5.599152e+001,1,0,3.612903e+000,0.000000e+000,4.292210e+000,4.292210e+000,2.751731e+000,1.462247e+000,3.764594e+000,2.224115e+000,9.346304e-001,6.412945e-005,6.412945e-005,,,,,,,,,,,,,,,,,,,,
1524280725.235,,0.000000e+000,5.598610e+001,5.599831e+001,1,0,3.741935e+000,0.000000e+000,4.579996e+000,4.579996e+000,3.102711e+000,1.764544e+000,3.643246e+000,2.165962e+000,8.277941e-001,7.127482e-005,7.127482e-005,,,,,,,,,,,,,,,,,,,,
1524280738.145,,0.000000e+000,5.599831e+001,5.599695e+001,1,0,3.870968e+000,0.000000e+000,4.691997e+000,4.691997e+000,3.274674e+000,1.891979e+000,3.397161e+000,1.979839e+000,5.971441e-001,7.444827e-005,7.444827e-005,,,,,,,,,,,,,,,,,,,,
1524280750.605,,0.000000e+000,5.599695e+001,5.599967e+001,1,0,4.000000e+000,0.000000e+000,4.607919e+000,4.607919e+000,3.254346e+000,1.819935e+000,3.077489e+000,1.723916e+000,2.895048e-001,7.326459e-005,7.326459e-005,,,,,,,,,,,,,,,,,,,,
1524280775.455,,0.000000e+000,5.599559e+001,5.599695e+001,1,0,0.000000e+000,0.000000e+000,3.694057e+000,3.694057e+000,9.387162e-001,9.387162e-001,4.481638e+000,1.726298e+000,1.726298e+000,4.294265e-005,4.294265e-005,,,,,,,,,,,,,,,,,,,,
1524280788.675,,0.000000e+000,5.599559e+001,5.599695e+001,1,0,1.290323e-001,0.000000e+000,3.836576e+000,3.836576e+000,1.147659e+000,1.101727e+000,4.672144e+000,1.983227e+000,1.937295e+000,4.681027e-005,4.681027e-005,,,,,,,,,,,,,,,,,,,,
1524280800.605,,0.000000e+000,5.599695e+001,5.599695e+001,1,0,2.580645e-001,0.000000e+000,4.095216e+000,4.095216e+000,1.465730e+000,1.373547e+000,4.799693e+000,2.170206e+000,2.078023e+000,5.326344e-005,5.326344e-005,,,,,,,,,,,,,,,,,,,,
1524280813.115,,0.000000e+000,5.600103e+001,5.599559e+001,1,0,3.870968e-001,0.000000e+000,4.301671e+000,4.301671e+000,1.731674e+000,1.593178e+000,4.802281e+000,2.232284e+000,2.093788e+000,5.854803e-005,5.854803e-005,,,,,,,,,,,,,,,,,,,,
1524280825.775,,0.000000e+000,5.598880e+001,5.599831e+001,1,0,5.161290e-001,0.000000e+000,4.395667e+000,4.395667e+000,1.890214e+000,1.706681e+000,4.619781e+000,2.114328e+000,1.930795e+000,6.135125e-005,6.135125e-005,,,,,,,,,,,,,,,,,,,,
1524280837.935,,0.000000e+000,5.599831e+001,5.600103e+001,1,0,6.451613e-001,0.000000e+000,4.358739e+000,4.358739e+000,1.916291e+000,1.685524e+000,4.247652e+000,1.805203e+000,1.574436e+000,6.130224e-005,6.130224e-005,,,,,,,,,,,,,,,,,,,,
1524280850.335,,0.000000e+000,5.600375e+001,5.599967e+001,1,0,7.741935e-001,0.000000e+000,4.153201e+000,4.153201e+000,1.766518e+000,1.488728e+000,3.706458e+000,1.319776e+000,1.041985e+000,5.728854e-005,5.728854e-005,,,,,,,,,,,,,,,,,,,,
1524280862.715,,0.000000e+000,5.599967e+001,5.599831e+001,1,0,9.032258e-001,0.000000e+000,3.759670e+000,3.759670e+000,1.435622e+000,1.112196e+000,3.025006e+000,7.009566e-001,3.775311e-001,4.920648e-005,4.920648e-005,,,,,,,,,,,,,,,,,,,,
1524280875.055,,0.000000e+000,5.599831e+001,5.600375e+001,1,0,1.032258e+000,0.000000e+000,3.199970e+000,3.199970e+000,9.347894e-001,5.626862e-001,2.251780e+000,-1.340029e-002,-3.855035e-001,3.735156e-005,3.735156e-005,,,,,,,,,,,,,,,,,,,,
1524280887.415,,0.000000e+000,5.599288e+001,5.600103e+001,1,0,1.161290e+000,0.000000e+000,2.502022e+000,2.502022e+000,2.999325e-001,-1.154943e-001,1.408724e+000,-7.933651e-001,-1.208792e+000,2.244456e-005,2.244456e-005,,,,,,,,,,,,,,,,,,,,
1524280899.825,,0.000000e+000,5.600103e+001,5.599831e+001,1,0,1.290323e+000,0.000000e+000,1.694362e+000,1.694362e+000,-4.411206e-001,-9.111487e-001,5.117629e-001,-1.623719e+000,-2.093748e+000,5.279129e-006,5.279129e-006,,,,,,,,,,,,,,,,,,,,
1524280912.735,,0.000000e+000,5.599831e+001,5.601326e+001,1,0,1.419355e+000,0.000000e+000,7.890440e-001,7.890440e-001,-1.278392e+000,-1.789790e+000,-4.156278e-001,-2.483064e+000,-2.994461e+000,-1.416844e-005,-1.416844e-005,,,,,,,,,,,,,,,,,,,,
1524280924.865,,0.000000e+000,5.599559e+001,5.599288e+001,1,0,1.548387e+000,0.000000e+000,-1.451133e-001,-1.451133e-001,-2.146526e+000,-2.704429e+000,-1.337636e+000,-3.339048e+000,-3.896952e+000,-3.425748e-005,-3.425748e-005,,,,,,,,,,,,,,,,,,,,
1524280937.515,,0.000000e+000,5.599288e+001,5.599831e+001,1,0,1.677419e+000,0.000000e+000,-1.069810e+000,-1.069810e+000,-3.009490e+000,-3.609743e+000,-2.185500e+000,-4.125180e+000,-4.725432e+000,-5.424186e-005,-5.424186e-005,,,,,,,,,,,,,,,,,,,,
1524280949.975,,0.000000e+000,5.599152e+001,5.600510e+001,1,0,1.806452e+000,0.000000e+000,-1.975433e+000,-1.975433e+000,-3.856899e+000,-4.506669e+000,-2.856365e+000,-4.737831e+000,-5.387601e+000,-7.387167e-005,-7.387167e-005,,,,,,,,,,,,,,,,,,,,
1524280962.365,,0.000000e+000,5.599288e+001,5.599424e+001,1,0,1.935484e+000,0.000000e+000,-2.741588e+000,-2.741588e+000,-4.562864e+000,-5.256442e+000,-3.263406e+000,-5.084682e+000,-5.778260e+000,-9.033378e-005,-9.033378e-005,,,,,,,,,,,,,,,,,,,,
1524280975.125,,0.000000e+000,5.599288e+001,5.599288e+001,1,0,2.064516e+000,0.000000e+000,-3.313191e+000,-3.313191e+000,-5.075500e+000,-5.816129e+000,-3.326068e+000,-5.088377e+000,-5.829006e+000,-1.024723e-004,-1.024723e-004,,,,,,,,,,,,,,,,,,,,
1524280987.335,,0.000000e+000,5.599559e+001,5.600375e+001,1,0,2.193548e+000,0.000000e+000,-3.586786e+000,-3.586786e+000,-5.289454e+000,-6.078153e+000,-3.040437e+000,-4.743106e+000,-5.531805e+000,-1.079507e-004,-1.079507e-004,,,,,,,,,,,,,,,,,,,,
1524280999.875,,0.000000e+000,5.600646e+001,5.598473e+001,1,0,2.322581e+000,0.000000e+000,-3.547723e+000,-3.547723e+000,-5.188733e+000,-6.016789e+000,-2.492942e+000,-4.133952e+000,-4.962008e+000,-1.063571e-004,-1.063571e-004,,,,,,,,,,,,,,,,,,,,
1524281013.005,,0.000000e+000,5.598473e+001,5.600103e+001,1,0,2.451613e+000,0.000000e+000,-3.183948e+000,-3.183948e+000,-4.764005e+000,-5.646014e+000,-1.766757e+000,-3.346815e+000,-4.228824e+000,-9.757690e-005,-9.757690e-005,,,,,,,,,,,,,,,,,,,,
1524281025.325,,0.000000e+000,5.600103e+001,5.600510e+001,1,0,2.580645e+000,0.000000e+000,-2.548104e+000,-2.548104e+000,-4.067982e+000,-4.994279e+000,-9.698069e-001,-2.489684e+000,-3.415981e+000,-8.270785e-005,-8.270785e-005,,,,,,,,,,,,,,,,,,,,
1524281038.275,,0.000000e+000,5.600510e+001,5.600103e+001,1,0,2.709677e+000,0.000000e+000,-1.748379e+000,-1.748379e+000,-3.204071e+000,-4.176429e+000,-1.746062e-001,-1.630298e+000,-2.602656e+000,-6.407305e-005,-6.407305e-005,,,,,,,,,,,,,,,,,,,,
1524281051.365,,0.000000e+000,5.600103e+001,5.599967e+001,1,0,2.838710e+000,0.000000e+000,-8.102540e-001,-8.102540e-001,-2.211025e+000,-3.223983e+000,6.036379e-001,-7.971329e-001,-1.810091e+000,-4.255116e-005,-4.255116e-005,,,,,,,,,,,,,,,,,,,,
1524281063.845,,0.000000e+000,5.599967e+001,5.600238e+001,1,0,2.967742e+000,0.000000e+000,1.136797e-001,1.136797e-001,-1.221688e+000,-2.294254e+000,1.321874e+000,-1.349360e-002,-1.086060e+000,-2.117595e-005,-2.117595e-005,,,,,,,,,,,,,,,,,,,,
1524281076.295,,0.000000e+000,5.600238e+001,5.598880e+001,1,0,3.096774e+000,0.000000e+000,1.045243e+000,1.045243e+000,-2.378169e-001,-1.340225e+000,1.988131e+000,7.050707e-001,-3.973374e-001,2.023917e-007,2.023917e-007,,,,,,,,,,,,,,,,,,,,
1524281088.905,,0.000000e+000,5.598880e+001,5.599152e+001,1,0,3.225806e+000,0.000000e+000,1.915160e+000,1.915160e+000,6.943772e-001,-4.654201e-001,2.550250e+000,1.329468e+000,1.696703e-001,2.028874e-005,2.028874e-005,,,,,,,,,,,,,,,,,,,,
1524281101.425,,0.000000e+000,5.599152e+001,5.600375e+001,1,0,3.354839e+000,0.000000e+000,2.688487e+000,2.688487e+000,1.526308e+000,3.254650e-001,2.983379e+000,1.821200e+000,6.203568e-001,3.823945e-005,3.823945e-005,,,,,,,,,,,,,,,,,,,,
1524281114.025,,0.000000e+000,5.599695e+001,5.599967e+001,1,0,3.483871e+000,0.000000e+000,3.330892e+000,3.330892e+000,2.233327e+000,9.819148e-001,3.230383e+000,2.132818e+000,8.814054e-001,5.331426e-005,5.331426e-005,,,,,,,,,,,,,,,,,,,,
1524281126.965,,0.000000e+000,5.599967e+001,5.600103e+001,1,0,3.612903e+000,0.000000e+000,3.827573e+000,3.827573e+000,2.784981e+000,1.491146e+000,3.298568e+000,2.255977e+000,9.621418e-001,6.500420e-005,6.500420e-005,,,,,,,,,,,,,,,,,,,,
1524281140.155,,0.000000e+000,5.600103e+001,5.598745e+001,1,0,3.741935e+000,0.000000e+000,4.120089e+000,4.120089e+000,3.140381e+000,1.797834e+000,3.173173e+000,2.193465e+000,8.509178e-001,7.222869e-005,7.222869e-005,,,,,,,,,,,,,,,,,,,,
1524281153.045,,0.000000e+000,5.598745e+001,5.600103e+001,1,0,3.870968e+000,0.000000e+000,4.223545e+000,4.223545e+000,3.307656e+000,1.917741e+000,2.921163e+000,2.005274e+000,6.153588e-001,7.527752e-005,7.527752e-005,,,,,,,,,,,,,,,,,,,,
1524281166.235,,0.000000e+000,5.600103e+001,5.599831e+001,1,0,4.000000e+000,0.000000e+000,4.154269e+000,4.154269e+000,3.298303e+000,1.865261e+000,2.601782e+000,1.745817e+000,3.127747e-001,7.439973e-005,7.439973e-005,,,,,,,,,,,,,,,,,,,,
1524281191.455,,0.000000e+000,5.599695e+001,5.599695e+001,1,0,0.000000e+000,0.000000e+000,3.214618e+000,3.214618e+000,9.494801e-001,9.494801e-001,4.015195e+000,1.750057e+000,1.750057e+000,4.335787e-005,4.335787e-005,,,,,,,,,,,,,,,,,,,,
1524281203.975,,0.000000e+000,5.599016e+001,5.600103e+001,1,0,1.290323e-001,0.000000e+000,3.394980e+000,3.394980e+000,1.200317e+000,1.154226e+000,4.203239e+000,2.008577e+000,1.962485e+000,4.816520e-005,4.816520e-005,,,,,,,,,,,,,,,,,,,,
1524281217.175,,0.000000e+000,5.599424e+001,5.600238e+001,1,0,2.580645e-001,0.000000e+000,3.634547e+000,3.634547e+000,1.497129e+000,1.404344e+000,4.336739e+000,2.199322e+000,2.106536e+000,5.417651e-005,5.417651e-005,,,,,,,,,,,,,,,,,,,,
1524281229.415,,0.000000e+000,5.599967e+001,5.599831e+001,1,0,3.870968e-001,0.000000e+000,3.814298e+000,3.814298e+000,1.736835e+000,1.597685e+000,4.337206e+000,2.259744e+000,2.120594e+000,5.884233e-005,5.884233e-005,,,,,,,,,,,,,,,,,,,,
1524281242.135,,0.000000e+000,5.599424e+001,5.599967e+001,1,0,5.161290e-001,0.000000e+000,3.910429e+000,3.910429e+000,1.893897e+000,1.707899e+000,4.156500e+000,2.139968e+000,1.953970e+000,6.167550e-005,6.167550e-005,,,,,,,,,,,,,,,,,,,,
1524281255.586,,0.000000e+000,5.599967e+001,5.599559e+001,1,0,6.451613e-001,0.000000e+000,3.883421e+000,3.883421e+000,1.926329e+000,1.695347e+000,3.785887e+000,1.828795e+000,1.597813e+000,6.168040e-005,6.168040e-005,,,,,,,,,,,,,,,,,,,,
1524281268.116,,0.000000e+000,5.600238e+001,5.599695e+001,1,0,7.741935e-001,0.000000e+000,3.678492e+000,3.678492e+000,1.783218e+000,1.505694e+000,3.231055e+000,1.335780e+000,1.058256e+000,5.779194e-005,5.779194e-005,,,,,,,,,,,,,,,,,,,,
1524281281.026,,0.000000e+000,5.599559e+001,5.599967e+001,1,0,9.032258e-001,0.000000e+000,3.283436e+000,3.283436e+000,1.448196e+000,1.122076e+000,2.544235e+000,7.089955e-001,3.828750e-001,4.966551e-005,4.966551e-005,,,,,,,,,,,,,,,,,,,,
1524281293.296,,0.000000e+000,5.599967e+001,5.599288e+001,1,0,1.032258e+000,0.000000e+000,2.722057e+000,2.722057e+000,9.429872e-001,5.727580e-001,1.765501e+000,-1.356903e-002,-3.837982e-001,3.765048e-005,3.765048e-005,,,,,,,,,,,,,,,,,,,,
1524281305.676,,0.000000e+000,5.599288e+001,5.599831e+001,1,0,1.161290e+000,0.000000e+000,2.006866e+000,2.006866e+000,2.854878e-001,-1.340556e-001,9.175055e-001,-8.038731e-001,-1.223417e+000,2.231531e-005,2.231531e-005,,,,,,,,,,,,,,,,,,,,
1524281318.276,,0.000000e+000,5.599831e+001,5.600238e+001,1,0,1.290323e+000,0.000000e+000,1.191577e+000,1.191577e+000,-4.670483e-001,-9.282035e-001,1.827343e-002,-1.640352e+000,-2.101507e+000,4.742524e-006,4.742524e-006,,,,,,,,,,,,,,,,,,,,
1524281331.286,,0.000000e+000,5.600375e+001,5.600103e+001,1,0,1.419355e+000,0.000000e+000,2.887007e-001,2.887007e-001,-1.315482e+000,-1.824464e+000,-9.077281e-001,-2.511910e+000,-3.020893e+000,-1.488098e-005,-1.488098e-005,,,,,,,,,,,,,,,,,,,,
1524281343.956,,0.000000e+000,5.600103e+001,5.600238e+001,1,0,1.548387e+000,0.000000e+000,-6.320287e-001,-6.320287e-001,-2.177484e+000,-2.732155e+000,-1.835158e+000,-3.380613e+000,-3.935284e+000,-3.482288e-005,-3.482288e-005,,,,,,,,,,,,,,,,,,,,
1524281356.416,,0.000000e+000,5.599288e+001,5.600238e+001,1,0,1.677419e+000,0.000000e+000,-1.573968e+000,-1.573968e+000,-3.067089e+000,-3.668830e+000,-2.679762e+000,-4.172883e+000,-4.774624e+000,-5.539424e-005,-5.539424e-005,,,,,,,,,,,,,,,,,,,,
1524281368.896,,0.000000e+000,5.600375e+001,5.599424e+001,1,0,1.806452e+000,0.000000e+000,-2.475624e+000,-2.475624e+000,-3.912510e+000,-4.560606e+000,-3.361260e+000,-4.798146e+000,-5.446242e+000,-7.497347e-005,-7.497347e-005,,,,,,,,,,,,,,,,,,,,
1524281381.506,,0.000000e+000,5.599424e+001,5.599967e+001,1,0,1.935484e+000,0.000000e+000,-3.251545e+000,-3.251545e+000,-4.627910e+000,-5.324772e+000,-3.767336e+000,-5.143701e+000,-5.840563e+000,-9.165474e-005,-9.165474e-005,,,,,,,,,,,,,,,,,,,,
1524281394.026,,0.000000e+000,5.599967e+001,5.600375e+001,1,0,2.064516e+000,0.000000e+000,-3.832151e+000,-3.832151e+000,-5.150119e+000,-5.888824e+000,-3.834558e+000,-5.152526e+000,-5.891232e+000,-1.039965e-004,-1.039965e-004,,,,,,,,,,,,,,,,,,,,
1524281406.586,,0.000000e+000,5.599695e+001,5.599831e+001,1,0,2.193548e+000,0.000000e+000,-4.096895e+000,-4.096895e+000,-5.355124e+000,-6.142056e+000,-3.543500e+000,-4.801730e+000,-5.588662e+000,-1.092764e-004,-1.092764e-004,,,,,,,,,,,,,,,,,,,,
1524281418.996,,0.000000e+000,5.599831e+001,5.599831e+001,1,0,2.322581e+000,0.000000e+000,-4.057374e+000,-4.057374e+000,-5.259912e+000,-6.089425e+000,-2.979061e+000,-4.181599e+000,-5.011112e+000,-1.078205e-004,-1.078205e-004,,,,,,,,,,,,,,,,,,,,
1524281431.526,,0.000000e+000,5.599016e+001,5.599831e+001,1,0,2.451613e+000,0.000000e+000,-3.671931e+000,-3.671931e+000,-4.813520e+000,-5.695064e+000,-2.241593e+000,-3.383183e+000,-4.264726e+000,-9.855929e-005,-9.855929e-005,,,,,,,,,,,,,,,,,,,,
1524281444.036,,0.000000e+000,5.599695e+001,5.600103e+001,1,0,2.580645e+000,0.000000e+000,-3.018845e+000,-3.018845e+000,-4.103856e+000,-5.025539e+000,-1.435191e+000,-2.520202e+000,-3.441885e+000,-8.335544e-005,-8.335544e-005,,,,,,,,,,,,,,,,,,,,
1524281456.426,,0.000000e+000,5.600103e+001,5.599695e+001,1,0,2.709677e+000,0.000000e+000,-2.190890e+000,-2.190890e+000,-3.218519e+000,-4.190005e+000,-6.198581e-001,-1.647487e+000,-2.618973e+000,-6.427310e-005,-6.427310e-005,,,,,,,,,,,,,,,,,,,,
1524281468.776,,0.000000e+000,5.599288e+001,5.599831e+001,1,0,2.838710e+000,0.000000e+000,-1.268940e+000,-1.268940e+000,-2.237284e+000,-3.255213e+000,1.618345e-001,-8.065094e-001,-1.824438e+000,-4.302674e-005,-4.302674e-005,,,,,,,,,,,,,,,,,,,,
1524281481.286,,0.000000e+000,5.599831e+001,5.599967e+001,1,0,2.967742e+000,0.000000e+000,-3.109789e-001,-3.109789e-001,-1.221691e+000,-2.290406e+000,8.970703e-001,-1.364185e-002,-1.082357e+000,-2.103280e-005,-2.103280e-005,,,,,,,,,,,,,,,,,,,,
1524281494.416,,0.000000e+000,5.599967e+001,5.599288e+001,1,0,3.096774e+000,0.000000e+000,6.112764e-001,6.112764e-001,-2.411013e-001,-1.359868e+000,1.566018e+000,7.136404e-001,-4.051260e-001,1.804328e-007,1.804328e-007,,,,,,,,,,,,,,,,,,,,
1524281507.006,,0.000000e+000,5.599424e+001,5.600103e+001,1,0,3.225806e+000,0.000000e+000,1.501945e+000,1.501945e+000,7.099781e-001,-4.485718e-001,2.136344e+000,1.344377e+000,1.858267e-001,2.077161e-005,2.077161e-005,,,,,,,,,,,,,,,,,,,,
1524281519.686,,0.000000e+000,5.599695e+001,5.600238e+001,1,0,3.354839e+000,0.000000e+000,2.298466e+000,2.298466e+000,1.565117e+000,3.577564e-001,2.574763e+000,1.841414e+000,6.340532e-001,3.919360e-005,3.919360e-005,,,,,,,,,,,,,,,,,,,,
1524281532.266,,0.000000e+000,5.599559e+001,5.599424e+001,1,0,3.483871e+000,0.000000e+000,2.930038e+000,2.930038e+000,2.255857e+000,1.000175e+000,2.832504e+000,2.158323e+000,9.026415e-001,5.392633e-005,5.392633e-005,,,,,,,,,,,,,,,,,,,,
1524281544.956,,0.000000e+000,5.599424e+001,5.599967e+001,1,0,3.612903e+000,0.000000e+000,3.404288e+000,3.404288e+000,2.788455e+000,1.481965e+000,2.894873e+000,2.279040e+000,9.725507e-001,6.511385e-005,6.511385e-005,,,,,,,,,,,,,,,,,,,,
1524281557.266,,0.000000e+000,5.599967e+001,5.600103e+001,1,0,3.741935e+000,0.000000e+000,3.712673e+000,3.712673e+000,3.154022e+000,1.803005e+000,2.777303e+000,2.218652e+000,8.676345e-001,7.260519e-005,7.260519e-005,,,,,,,,,,,,,,,,,,,,
1524281569.576,,0.000000e+000,5.600103e+001,5.600510e+001,1,0,3.870968e+000,0.000000e+000,3.811856e+000,3.811856e+000,3.310093e+000,1.908746e+000,2.531448e+000,2.029684e+000,6.283369e-001,7.538795e-005,7.538795e-005,,,,,,,,,,,,,,,,,,,,
1524281582.056,,0.000000e+000,5.600238e+001,5.599831e+001,1,0,4.000000e+000,0.000000e+000,3.778897e+000,3.778897e+000,3.328401e+000,1.898710e+000,2.217308e+000,1.766812e+000,3.371212e-001,7.523399e-005,7.523399e-005,,,,,,,,,,,,,,,,,,,,
1524281607.106,,0.000000e+000,5.599424e+001,5.600238e+001,1,0,0.000000e+000,0.000000e+000,2.825361e+000,2.825361e+000,9.654665e-001,9.654665e-001,3.626090e+000,1.766196e+000,1.766196e+000,4.378110e-005,4.378110e-005,,,,,,,,,,,,,,,,,,,,
1524281620.096,,0.000000e+000,5.600510e+001,5.599695e+001,1,0,1.290323e-001,0.000000e+000,3.007858e+000,3.007858e+000,1.205340e+000,1.158919e+000,3.833003e+000,2.030484e+000,1.984063e+000,4.847269e-005,4.847269e-005,,,,,,,,,,,,,,,,,,,,
1524281632.256,,0.000000e+000,5.599695e+001,5.599695e+001,1,0,2.580645e-001,0.000000e+000,3.240101e+000,3.240101e+000,1.499626e+000,1.406973e+000,3.963044e+000,2.222569e+000,2.129916e+000,5.433931e-005,5.433931e-005,,,,,,,,,,,,,,,,,,,,
1524281644.556,,0.000000e+000,5.599831e+001,5.600375e+001,1,0,3.870968e-001,0.000000e+000,3.461662e+000,3.461662e+000,1.774160e+000,1.634078e+000,3.970908e+000,2.283406e+000,2.143325e+000,5.985358e-005,5.985358e-005,,,,,,,,,,,,,,,,,,,,
1524281657.096,,0.000000e+000,5.599831e+001,5.599831e+001,1,0,5.161290e-001,0.000000e+000,3.544976e+000,3.544976e+000,1.922995e+000,1.738567e+000,3.785521e+000,2.163540e+000,1.979112e+000,6.238394e-005,6.238394e-005,,,,,,,,,,,,,,,,,,,,
1524281669.636,,0.000000e+000,5.599831e+001,5.599695e+001,1,0,6.451613e-001,0.000000e+000,3.523308e+000,3.523308e+000,1.954277e+000,1.722232e+000,3.415739e+000,1.846709e+000,1.614663e+000,6.244994e-005,6.244994e-005,,,,,,,,,,,,,,,,,,,,
1524281682.156,,0.000000e+000,5.599695e+001,5.599559e+001,1,0,7.741935e-001,0.000000e+000,3.298848e+000,3.298848e+000,1.792126e+000,1.515180e+000,2.857976e+000,1.351254e+000,1.074308e+000,5.810932e-005,5.810932e-005,,,,,,,,,,,,,,,,,,,,
1524281694.756,,0.000000e+000,5.599559e+001,5.599831e+001,1,0,9.032258e-001,0.000000e+000,2.908675e+000,2.908675e+000,1.453905e+000,1.129401e+000,2.171610e+000,7.168403e-001,3.923362e-001,4.988998e-005,4.988998e-005,,,,,,,,,,,,,,,,,,,,
1524281707.726,,0.000000e+000,5.599831e+001,5.599831e+001,1,0,1.032258e+000,0.000000e+000,2.349279e+000,2.349279e+000,9.491887e-001,5.775050e-001,1.386374e+000,-1.371622e-002,-3.853999e-001,3.793308e-005,3.793308e-005,,,,,,,,,,,,,,,,,,,,
1524281720.126,,0.000000e+000,5.599831e+001,5.600103e+001,1,0,1.161290e+000,0.000000e+000,1.638819e+000,1.638819e+000,2.946864e-001,-1.226475e-001,5.325053e-001,-8.116272e-001,-1.228961e+000,2.260728e-005,2.260728e-005,,,,,,,,,,,,,,,,,,,,
1524281733.516,,0.000000e+000,5.600103e+001,5.599559e+001,1,0,1.290323e+000,0.000000e+000,8.105593e-001,8.105593e-001,-4.777150e-001,-9.416602e-001,-3.724567e-001,-1.660731e+000,-2.124676e+000,4.668647e-006,4.668647e-006,,,,,,,,,,,,,,,,,,,,
1524281746.266,,0.000000e+000,5.599152e+001,5.600238e+001,1,0,1.419355e+000,0.000000e+000,-8.667126e-002,-8.667126e-002,-1.316156e+000,-1.827351e+000,-1.308348e+000,-2.537833e+000,-3.049028e+000,-1.476474e-005,-1.476474e-005,,,,,,,,,,,,,,,,,,,,
1524281758.846,,0.000000e+000,5.600238e+001,5.600238e+001,1,0,1.548387e+000,0.000000e+000,-1.034104e+000,-1.034104e+000,-2.206283e+000,-2.760488e+000,-2.240045e+000,-3.412224e+000,-3.966429e+000,-3.536164e-005,-3.536164e-005,,,,,,,,,,,,,,,,,,,,
1524281771.336,,0.000000e+000,5.599288e+001,5.600103e+001,1,0,1.677419e+000,0.000000e+000,-1.987182e+000,-1.987182e+000,-3.104794e+000,-3.704760e+000,-3.098333e+000,-4.215944e+000,-4.815910e+000,-5.612407e-005,-5.612407e-005,,,,,,,,,,,,,,,,,,,,
1524281771.336,,0.000000e+000,5.599288e+001,5.600103e+001,1,0,4.000000e+000,0.000000e+000,3.597314e+000,3.597314e+000,3.310425e+000,1.879737e+000,2.061799e+000,1.774910e+000,3.442216e-001,7.487748e-005,7.487748e-005,,,,,,,,,,,,,,,,,,,,