File: Experimental Raw Data/TC04-12-01K VRMac VRMde/raw/TC04-12-01K_VRMac_56K_6000s.dc.raw
[Header]
TITLE,MPMS DC Measurement
BYAPP,MPMS Measurement,2.1,Raw with ABS
FILEOPENTIME, 1524256549.571000 4/20/2018, 2:35:49 PM

INFO, APPNAME, MPMS MultiVu Application, Revision 1.61,  Build 082

INFO, NAME, TC04-12-01K
INFO, WEIGHT, 1.000
INFO, AREA, 1.000
INFO, LENGTH, 1.000
INFO, SHAPE, 0
INFO, COMMENT,
INFO, SEQUENCE FILE: VRMac_56K_6000s_VRMde_55K.seq


INFO, BACKGROUND DATA FILE:, None


STARTUPAXIS,X,8,LINEAR,AUTO,0.000000,0.000000
STARTUPAXIS,Y1,10,LINEAR,AUTO,0.000000,0.000000


STARTUPGROUP,Longitudinal
FIELDGROUP,Longitudinal,1,3,4,5,6,8,9,10,11,12,13,14,15,16,17,18,19,20,21,22,23
FIELDGROUP,Transverse,1,3,4,5,6,8,9,24,25,26,27,28,29,30,31,32,33,34,35,36,37

PLOT_APPEARANCE,ALL,HORZ_GRID_ON,VERT_GRID_ON,MARKERS_ONLY

[Data]
Time,Comment,Field (Oe),Start Temperature (K),End Temperature (K),Scan,Rejected,Position (cm),Rot Position (deg),Long Voltage,Long Average Voltage,Long Detrended Voltage,Long Demeaned Voltage,Long Regression Fit,Long Detrended Fit,Long Demeaned Fit,Long Scaled Response,Long Avg. Scaled Response,Long Background Response,Long Response [w/ABS],Long Detrended Resp. [w/ABS],Long Fit [w/ABS],Long Detrended Fit [w/ABS],Trans Voltage,Trans Average Voltage,Trans Detrended Voltage,Trans Demeaned Voltage,Trans Regression Fit,Trans Detrended Fit,Trans Demeaned Fit,Trans Scaled Response,Trans Avg Scaled Response,Trans Background Response,Trans Response [w/ABS],Trans Detrended Resp. [w/ABS],Trans Fit [w/ABS],Trans Detrended Fit [w/ABS],
1524256549.561,,0.000000e+000,5.605678e+001,5.604454e+001,1,0,0.000000e+000,0.000000e+000,6.884565e+000,6.884565e+000,5.724640e-001,5.724640e-001,7.590345e+000,1.278244e+000,1.278244e+000,2.611773e-005,2.611773e-005,,,,,,,,,,,,,,,,,,,,
1524256575.211,,0.000000e+000,5.602957e+001,5.603229e+001,1,0,1.290323e-001,0.000000e+000,7.993744e+000,7.993744e+000,8.570795e-001,8.246450e-001,8.714180e+000,1.577516e+000,1.545081e+000,3.510097e-005,3.510097e-005,,,,,,,,,,,,,,,,,,,,
1524256600.231,,0.000000e+000,5.602005e+001,5.602277e+001,1,0,2.580645e-001,0.000000e+000,8.642710e+000,8.642710e+000,1.145755e+000,1.072496e+000,9.284071e+000,1.787117e+000,1.713858e+000,4.222585e-005,4.222585e-005,,,,,,,,,,,,,,,,,,,,
1524256650.331,,0.000000e+000,5.600238e+001,5.600103e+001,1,0,3.870968e-001,0.000000e+000,-1.116197e+000,-1.116197e+000,2.840121e-001,2.596686e-001,-1.018963e+000,3.812471e-001,3.569036e-001,4.889906e-005,4.889906e-005,,,,,,,,,,,,,,,,,,,,
1524256675.561,,0.000000e+000,5.600918e+001,5.600375e+001,1,0,5.161290e-001,0.000000e+000,-1.079118e+000,-1.079118e+000,3.195558e-001,2.865345e-001,-1.032510e+000,3.661640e-001,3.331428e-001,5.251842e-005,5.251842e-005,,,,,,,,,,,,,,,,,,,,
1524256700.841,,0.000000e+000,5.599152e+001,5.600510e+001,1,0,6.451613e-001,0.000000e+000,-1.064775e+000,-1.064775e+000,3.368655e-001,2.951001e-001,-1.086099e+000,3.155410e-001,2.737756e-001,5.401330e-005,5.401330e-005,,,,,,,,,,,,,,,,,,,,
1524256726.191,,0.000000e+000,5.600238e+001,5.599559e+001,1,0,7.741935e-001,0.000000e+000,-1.088273e+000,-1.088273e+000,3.190227e-001,2.677970e-001,-1.174323e+000,2.329726e-001,1.817470e-001,5.162566e-005,5.162566e-005,,,,,,,,,,,,,,,,,,,,
1524256751.341,,0.000000e+000,5.600103e+001,5.600238e+001,1,0,9.032258e-001,0.000000e+000,-1.147326e+000,-1.147326e+000,2.679733e-001,2.075884e-001,-1.290864e+000,1.244353e-001,6.405044e-002,4.541082e-005,4.541082e-005,,,,,,,,,,,,,,,,,,,,
1524256775.881,,0.000000e+000,5.599967e+001,5.599967e+001,1,0,1.032258e+000,0.000000e+000,-1.241016e+000,-1.241016e+000,1.830478e-001,1.138830e-001,-1.426461e+000,-2.397075e-003,-7.156181e-002,3.535827e-005,3.535827e-005,,,,,,,,,,,,,,,,,,,,
1524256800.901,,0.000000e+000,5.599288e+001,5.600375e+001,1,0,1.161290e+000,0.000000e+000,-1.367666e+000,-1.367666e+000,6.906062e-002,-9.336710e-003,-1.579580e+000,-1.428536e-001,-2.212509e-001,2.208265e-005,2.208265e-005,,,,,,,,,,,,,,,,,,,,
1524256826.041,,0.000000e+000,5.599288e+001,5.599695e+001,1,0,1.290323e+000,0.000000e+000,-1.510948e+000,-1.510948e+000,-6.732790e-002,-1.551372e-001,-1.737076e+000,-2.934552e-001,-3.812644e-001,6.272952e-006,6.272952e-006,,,,,,,,,,,,,,,,,,,,
1524256851.341,,0.000000e+000,5.600238e+001,5.600238e+001,1,0,1.419355e+000,0.000000e+000,-1.667506e+000,-1.667506e+000,-2.134810e-001,-3.106699e-001,-1.904293e+000,-4.502681e-001,-5.474570e-001,-1.066129e-005,-1.066129e-005,,,,,,,,,,,,,,,,,,,,
1524256876.761,,0.000000e+000,5.600103e+001,5.599016e+001,1,0,1.548387e+000,0.000000e+000,-1.838407e+000,-1.838407e+000,-3.739657e-001,-4.806712e-001,-2.073147e+000,-6.087058e-001,-7.154113e-001,-2.917874e-005,-2.917874e-005,,,,,,,,,,,,,,,,,,,,
1524256902.101,,0.000000e+000,5.599695e+001,5.601597e+001,1,0,1.677419e+000,0.000000e+000,-2.014496e+000,-2.014496e+000,-5.381535e-001,-6.538755e-001,-2.230902e+000,-7.545599e-001,-8.702818e-001,-4.814574e-005,-4.814574e-005,,,,,,,,,,,,,,,,,,,,
1524256927.341,,0.000000e+000,5.599967e+001,5.599424e+001,1,0,1.806452e+000,0.000000e+000,-2.186007e+000,-2.186007e+000,-6.981292e-001,-8.227595e-001,-2.359942e+000,-8.720641e-001,-9.966944e-001,-6.662816e-005,-6.662816e-005,,,,,,,,,,,,,,,,,,,,
1524256952.511,,0.000000e+000,5.599695e+001,5.599695e+001,1,0,1.935484e+000,0.000000e+000,-2.335241e+000,-2.335241e+000,-8.369858e-001,-9.708270e-001,-2.434892e+000,-9.366369e-001,-1.070478e+000,-8.279140e-005,-8.279140e-005,,,,,,,,,,,,,,,,,,,,
1524256977.662,,0.000000e+000,5.599967e+001,5.599695e+001,1,0,2.064516e+000,0.000000e+000,-2.450904e+000,-2.450904e+000,-9.409486e-001,-1.083688e+000,-2.451353e+000,-9.413971e-001,-1.084136e+000,-9.502107e-005,-9.502107e-005,,,,,,,,,,,,,,,,,,,,
1524257003.422,,0.000000e+000,5.599559e+001,5.598610e+001,1,0,2.193548e+000,0.000000e+000,-2.512245e+000,-2.512245e+000,-9.912429e-001,-1.143967e+000,-2.401554e+000,-8.805513e-001,-1.033275e+000,-1.012810e-004,-1.012810e-004,,,,,,,,,,,,,,,,,,,,
1524257028.142,,0.000000e+000,5.600510e+001,5.599288e+001,1,0,2.322581e+000,0.000000e+000,-2.517739e+000,-2.517739e+000,-9.850079e-001,-1.148019e+000,-2.301400e+000,-7.686698e-001,-9.316806e-001,-1.012328e-004,-1.012328e-004,,,,,,,,,,,,,,,,,,,,
1524257053.072,,0.000000e+000,5.599424e+001,5.600238e+001,1,0,2.451613e+000,0.000000e+000,-2.454414e+000,-2.454414e+000,-9.088922e-001,-1.081452e+000,-2.170313e+000,-6.247919e-001,-7.973520e-001,-9.337111e-005,-9.337111e-005,,,,,,,,,,,,,,,,,,,,
1524257078.342,,0.000000e+000,5.600103e+001,5.600646e+001,1,0,2.580645e+000,0.000000e+000,-2.339666e+000,-2.339666e+000,-7.842678e-001,-9.656141e-001,-2.021461e+000,-4.660629e-001,-6.474092e-001,-8.008914e-005,-8.008914e-005,,,,,,,,,,,,,,,,,,,,
1524257103.682,,0.000000e+000,5.599695e+001,5.600510e+001,1,0,2.709677e+000,0.000000e+000,-2.185550e+000,-2.185550e+000,-6.175539e-001,-8.084086e-001,-1.873267e+000,-3.052716e-001,-4.961263e-001,-6.212562e-005,-6.212562e-005,,,,,,,,,,,,,,,,,,,,
1524257128.972,,0.000000e+000,5.600103e+001,5.600238e+001,1,0,2.838710e+000,0.000000e+000,-2.013275e+000,-2.013275e+000,-4.327384e-001,-6.342485e-001,-1.730412e+000,-1.498745e-001,-3.513846e-001,-4.214802e-005,-4.214802e-005,,,,,,,,,,,,,,,,,,,,
1524257154.192,,0.000000e+000,5.599967e+001,5.599424e+001,1,0,2.967742e+000,0.000000e+000,-1.834440e+000,-1.834440e+000,-2.416985e-001,-4.515724e-001,-1.595277e+000,-2.535668e-003,-2.124096e-001,-2.145392e-005,-2.145392e-005,,,,,,,,,,,,,,,,,,,,
1524257179.272,,0.000000e+000,5.600375e+001,5.599831e+001,1,0,3.096774e+000,0.000000e+000,-1.658961e+000,-1.658961e+000,-5.421852e-002,-2.747961e-001,-1.471679e+000,1.330630e-001,-8.751464e-002,-1.182983e-006,-1.182983e-006,,,,,,,,,,,,,,,,,,,,
1524257204.902,,0.000000e+000,5.599559e+001,5.599831e+001,1,0,3.225806e+000,0.000000e+000,-1.493706e+000,-1.493706e+000,1.245723e-001,-1.056274e-001,-1.366876e+000,2.514017e-001,2.120197e-002,1.812229e-005,1.812229e-005,,,,,,,,,,,,,,,,,,,,
1524257230.372,,0.000000e+000,5.599967e+001,5.599967e+001,1,0,3.354839e+000,0.000000e+000,-1.344167e+000,-1.344167e+000,2.848680e-001,4.685426e-002,-1.284284e+000,3.447511e-001,1.067374e-001,3.541788e-005,3.541788e-005,,,,,,,,,,,,,,,,,,,,
1524257255.512,,0.000000e+000,5.599695e+001,5.600103e+001,1,0,3.483871e+000,0.000000e+000,-1.218738e+000,-1.218738e+000,4.236675e-001,1.740391e-001,-1.237642e+000,4.047640e-001,1.551356e-001,5.018545e-005,5.018545e-005,,,,,,,,,,,,,,,,,,,,
1524257280.642,,0.000000e+000,5.599831e+001,5.600238e+001,1,0,3.612903e+000,0.000000e+000,-1.119097e+000,-1.119097e+000,5.359536e-001,2.779325e-001,-1.227087e+000,4.279636e-001,1.699425e-001,6.209224e-005,6.209224e-005,,,,,,,,,,,,,,,,,,,,
1524257306.072,,0.000000e+000,5.599967e+001,5.599016e+001,1,0,3.741935e+000,0.000000e+000,-1.059129e+000,-1.059129e+000,6.081360e-001,3.409989e-001,-1.249348e+000,4.179167e-001,1.507796e-001,6.951034e-005,6.951034e-005,,,,,,,,,,,,,,,,,,,,
1524257331.262,,0.000000e+000,5.599695e+001,5.600510e+001,1,0,3.870968e+000,0.000000e+000,-1.037461e+000,-1.037461e+000,6.424487e-001,3.655789e-001,-1.297285e+000,3.826247e-001,1.057549e-001,7.266298e-005,7.266298e-005,,,,,,,,,,,,,,,,,,,,
1524257356.512,,0.000000e+000,5.599559e+001,5.599831e+001,1,0,4.000000e+000,0.000000e+000,-1.048142e+000,-1.048142e+000,6.445033e-001,3.582042e-001,-1.358894e+000,3.337510e-001,4.745197e-002,7.221600e-005,7.221600e-005,,,,,,,,,,,,,,,,,,,,
1524257394.032,,0.000000e+000,5.600375e+001,5.600375e+001,1,0,0.000000e+000,0.000000e+000,-1.243610e+000,-1.243610e+000,1.684153e-001,1.684153e-001,-1.077356e+000,3.346699e-001,3.346699e-001,4.048945e-005,4.048945e-005,,,,,,,,,,,,,,,,,,,,
1524257419.092,,0.000000e+000,5.599424e+001,5.600103e+001,1,0,1.290323e-001,0.000000e+000,-1.211566e+000,-1.211566e+000,2.135044e-001,2.041528e-001,-1.040465e+000,3.846063e-001,3.752546e-001,4.485654e-005,4.485654e-005,,,,,,,,,,,,,,,,,,,,
1524257444.262,,0.000000e+000,5.599695e+001,5.600103e+001,1,0,2.580645e-001,0.000000e+000,-1.166552e+000,-1.166552e+000,2.726128e-001,2.540243e-001,-1.017314e+000,4.218511e-001,4.032626e-001,5.072978e-005,5.072978e-005,,,,,,,,,,,,,,,,,,,,
1524257469.032,,0.000000e+000,5.599831e+001,5.600510e+001,1,0,3.870968e-001,0.000000e+000,-1.123674e+000,-1.123674e+000,3.291570e-001,3.012931e-001,-1.018586e+000,4.342452e-001,4.063814e-001,5.637188e-005,5.637188e-005,,,,,,,,,,,,,,,,,,,,
1524257494.502,,0.000000e+000,5.599559e+001,5.599695e+001,1,0,5.161290e-001,0.000000e+000,-1.100023e+000,-1.100023e+000,3.652292e-001,3.280452e-001,-1.053015e+000,4.122376e-001,3.750536e-001,5.973899e-005,5.973899e-005,,,,,,,,,,,,,,,,,,,,
1524257519.692,,0.000000e+000,5.599016e+001,5.600238e+001,1,0,6.451613e-001,0.000000e+000,-1.102922e+000,-1.102922e+000,3.754346e-001,3.290217e-001,-1.126367e+000,3.519892e-001,3.055763e-001,6.018646e-005,6.018646e-005,,,,,,,,,,,,,,,,,,,,
1524257544.802,,0.000000e+000,5.599831e+001,5.600103e+001,1,0,7.741935e-001,0.000000e+000,-1.137102e+000,-1.137102e+000,3.527920e-001,2.965896e-001,-1.232054e+000,2.578404e-001,2.016380e-001,5.704665e-005,5.704665e-005,,,,,,,,,,,,,,,,,,,,
1524257569.552,,0.000000e+000,5.599695e+001,5.599288e+001,1,0,9.032258e-001,0.000000e+000,-1.212177e+000,-1.212177e+000,2.905051e-001,2.249722e-001,-1.365705e+000,1.369769e-001,7.144403e-002,4.940259e-005,4.940259e-005,,,,,,,,,,,,,,,,,,,,
1524257595.452,,0.000000e+000,5.600238e+001,5.600375e+001,1,0,1.032258e+000,0.000000e+000,-1.318837e+000,-1.318837e+000,1.973418e-001,1.221591e-001,-1.518806e+000,-2.627157e-003,-7.780981e-002,3.834267e-005,3.834267e-005,,,,,,,,,,,,,,,,,,,,
1524257620.402,,0.000000e+000,5.599831e+001,5.599831e+001,1,0,1.161290e+000,0.000000e+000,-1.461051e+000,-1.461051e+000,6.798450e-002,-1.708329e-002,-1.684496e+000,-1.554597e-001,-2.405275e-001,2.321674e-005,2.321674e-005,,,,,,,,,,,,,,,,,,,,
1524257646.062,,0.000000e+000,5.599967e+001,5.599152e+001,1,0,1.290323e+000,0.000000e+000,-1.618067e+000,-1.618067e+000,-7.515725e-002,-1.688777e-001,-1.860959e+000,-3.180499e-001,-4.117703e-001,6.495015e-006,6.495015e-006,,,,,,,,,,,,,,,,,,,,
1524257670.902,,0.000000e+000,5.600103e+001,5.599424e+001,1,0,1.419355e+000,0.000000e+000,-1.794156e+000,-1.794156e+000,-2.378235e-001,-3.410821e-001,-2.043275e+000,-4.869427e-001,-5.902014e-001,-1.236307e-005,-1.236307e-005,,,,,,,,,,,,,,,,,,,,
1524257696.253,,0.000000e+000,5.598880e+001,5.599967e+001,1,0,1.548387e+000,0.000000e+000,-1.977722e+000,-1.977722e+000,-4.083639e-001,-5.203764e-001,-2.224896e+000,-6.555378e-001,-7.675503e-001,-3.211544e-005,-3.211544e-005,,,,,,,,,,,,,,,,,,,,
1524257720.923,,0.000000e+000,5.599152e+001,5.599152e+001,1,0,1.677419e+000,0.000000e+000,-2.166018e+000,-2.166018e+000,-5.842415e-001,-7.057109e-001,-2.391794e+000,-8.100170e-001,-9.314864e-001,-5.245415e-005,-5.245415e-005,,,,,,,,,,,,,,,,,,,,
1524257745.513,,0.000000e+000,5.600375e+001,5.599016e+001,1,0,1.806452e+000,0.000000e+000,6.103609e-001,6.103609e-001,-7.487908e-001,-8.798624e-001,4.261578e-001,-9.329939e-001,-1.064065e+000,-7.151207e-005,-7.151207e-005,,,,,,,,,,,,,,,,,,,,
1524257771.053,,0.000000e+000,5.599559e+001,5.599967e+001,1,0,1.935484e+000,0.000000e+000,4.443427e-001,4.443427e-001,-9.011438e-001,-1.042748e+000,3.433763e-001,-1.002110e+000,-1.143715e+000,-8.921418e-005,-8.921418e-005,,,,,,,,,,,,,,,,,,,,
1524257796.573,,0.000000e+000,5.599152e+001,5.599967e+001,1,0,2.064516e+000,0.000000e+000,-2.623178e+000,-2.623178e+000,-1.001838e+000,-1.153160e+000,-2.623416e+000,-1.002076e+000,-1.153398e+000,-1.011710e-004,-1.011710e-004,,,,,,,,,,,,,,,,,,,,
1524257821.603,,0.000000e+000,5.599424e+001,5.600510e+001,1,0,2.193548e+000,0.000000e+000,2.665751e-001,2.665751e-001,-1.051707e+000,-1.211850e+000,3.822211e-001,-9.360613e-001,-1.096204e+000,-1.074252e-004,-1.074252e-004,,,,,,,,,,,,,,,,,,,,
1524257847.013,,0.000000e+000,5.599967e+001,5.599152e+001,1,0,2.322581e+000,0.000000e+000,2.685588e-001,2.685588e-001,-1.035400e+000,-1.205590e+000,4.886803e-001,-8.152787e-001,-9.854686e-001,-1.063000e-004,-1.063000e-004,,,,,,,,,,,,,,,,,,,,
1524257872.313,,0.000000e+000,5.599967e+001,5.600103e+001,1,0,2.451613e+000,0.000000e+000,-2.620279e+000,-2.620279e+000,-9.556684e-001,-1.135715e+000,-2.324941e+000,-6.603301e-001,-8.403767e-001,-9.810016e-005,-9.810016e-005,,,,,,,,,,,,,,,,,,,,
1524257897.303,,0.000000e+000,5.599967e+001,5.599695e+001,1,0,2.580645e+000,0.000000e+000,-2.499886e+000,-2.499886e+000,-8.214449e-001,-1.011062e+000,-2.170875e+000,-4.924346e-001,-6.820514e-001,-8.378303e-005,-8.378303e-005,,,,,,,,,,,,,,,,,,,,
1524257922.533,,0.000000e+000,5.599424e+001,5.599695e+001,1,0,2.709677e+000,0.000000e+000,6.179904e-001,6.179904e-001,-6.442857e-001,-8.415409e-001,9.400232e-001,-3.222528e-001,-5.195081e-001,-6.464755e-005,-6.464755e-005,,,,,,,,,,,,,,,,,,,,
1524257947.613,,0.000000e+000,5.600918e+001,5.600238e+001,1,0,2.838710e+000,0.000000e+000,7.974365e-001,7.974365e-001,-4.507667e-001,-6.588142e-001,1.090385e+000,-1.578178e-001,-3.658652e-001,-4.374227e-005,-4.374227e-005,,,,,,,,,,,,,,,,,,,,
1524257972.473,,0.000000e+000,5.599831e+001,5.600103e+001,1,0,2.967742e+000,0.000000e+000,9.869536e-001,9.869536e-001,-2.470693e-001,-4.633127e-001,1.231353e+000,-2.670020e-003,-2.189134e-001,-2.164394e-005,-2.164394e-005,,,,,,,,,,,,,,,,,,,,
1524257997.723,,0.000000e+000,5.600510e+001,5.599831e+001,1,0,3.096774e+000,0.000000e+000,-1.787747e+000,-1.787747e+000,-5.416154e-002,-2.814822e-001,-1.593927e+000,1.396581e-001,-8.766258e-002,-8.243951e-007,-8.243951e-007,,,,,,,,,,,,,,,,,,,,
1524258022.783,,0.000000e+000,5.599424e+001,5.600238e+001,1,0,3.225806e+000,0.000000e+000,-1.621729e+000,-1.621729e+000,1.277536e-001,-1.102210e-001,-1.485777e+000,2.637054e-001,2.573073e-002,1.878233e-005,1.878233e-005,,,,,,,,,,,,,,,,,,,,
1524258048.273,,0.000000e+000,5.599288e+001,5.599424e+001,1,0,3.354839e+000,0.000000e+000,1.496452e+000,1.496452e+000,3.052177e-001,5.906856e-002,1.552526e+000,3.612910e-001,1.151419e-001,3.796272e-005,3.796272e-005,,,,,,,,,,,,,,,,,,,,
1524258073.433,,0.000000e+000,5.600103e+001,5.599424e+001,1,0,3.483871e+000,0.000000e+000,1.620355e+000,1.620355e+000,4.440390e-001,1.879309e-001,1.599992e+000,4.236758e-001,1.675677e-001,5.275916e-005,5.275916e-005,,,,,,,,,,,,,,,,,,,,
1524258098.373,,0.000000e+000,5.599424e+001,5.600238e+001,1,0,3.612903e+000,0.000000e+000,1.720607e+000,1.720607e+000,5.580129e-001,2.935541e-001,1.610433e+000,4.478381e-001,1.833793e-001,6.484389e-005,6.484389e-005,,,,,,,,,,,,,,,,,,,,
1524258123.903,,0.000000e+000,5.599967e+001,5.599967e+001,1,0,3.741935e+000,0.000000e+000,1.779965e+000,1.779965e+000,6.318432e-001,3.576069e-001,1.584659e+000,4.365371e-001,1.623007e-001,7.239527e-005,7.239527e-005,,,,,,,,,,,,,,,,,,,,
1524258148.693,,0.000000e+000,5.600103e+001,5.599831e+001,1,0,3.870968e+000,0.000000e+000,1.797818e+000,1.797818e+000,6.640077e-001,3.812362e-001,1.532932e+000,3.991216e-001,1.163502e-001,7.532704e-005,7.532704e-005,,,,,,,,,,,,,,,,,,,,
1524258173.873,,0.000000e+000,5.599288e+001,5.599559e+001,1,0,4.000000e+000,0.000000e+000,1.781949e+000,1.781949e+000,6.646340e-001,3.687885e-001,1.464961e+000,3.476466e-001,5.180109e-002,7.456214e-005,7.456214e-005,,,,,,,,,,,,,,,,,,,,
1524258211.653,,0.000000e+000,5.599424e+001,5.598880e+001,1,0,0.000000e+000,0.000000e+000,1.628748e+000,1.628748e+000,1.786059e-001,1.786059e-001,1.798419e+000,3.482766e-001,3.482766e-001,4.219523e-005,4.219523e-005,,,,,,,,,,,,,,,,,,,,
1524258236.743,,0.000000e+000,5.599559e+001,5.600375e+001,1,0,1.290323e-001,0.000000e+000,1.659419e+000,1.659419e+000,2.232973e-001,2.137971e-001,1.836296e+000,4.001743e-001,3.906741e-001,4.655233e-005,4.655233e-005,,,,,,,,,,,,,,,,,,,,
1524258261.873,,0.000000e+000,5.599831e+001,5.599424e+001,1,0,2.580645e-001,0.000000e+000,1.666285e+000,1.666285e+000,2.923534e-001,2.733340e-001,1.812587e+000,4.386548e-001,4.196354e-001,5.358737e-005,5.358737e-005,,,,,,,,,,,,,,,,,,,,
1524258286.923,,0.000000e+000,5.599288e+001,5.600103e+001,1,0,3.870968e-001,0.000000e+000,1.705196e+000,1.705196e+000,3.443955e-001,3.157078e-001,1.811871e+000,4.510705e-001,4.223828e-001,5.875441e-005,5.875441e-005,,,,,,,,,,,,,,,,,,,,
1524258312.033,,0.000000e+000,5.599967e+001,5.599559e+001,1,0,5.161290e-001,0.000000e+000,1.724422e+000,1.724422e+000,3.788925e-001,3.407972e-001,1.772823e+000,4.272935e-001,3.891982e-001,6.186137e-005,6.186137e-005,,,,,,,,,,,,,,,,,,,,
1524258337.063,,0.000000e+000,5.599967e+001,5.599016e+001,1,0,6.451613e-001,0.000000e+000,1.764096e+000,1.764096e+000,3.872741e-001,3.394953e-001,1.741831e+000,3.650100e-001,3.172312e-001,6.212902e-005,6.212902e-005,,,,,,,,,,,,,,,,,,,,
1524258362.403,,0.000000e+000,5.599424e+001,5.600238e+001,1,0,7.741935e-001,0.000000e+000,1.676814e+000,1.676814e+000,3.624782e-001,3.050562e-001,1.581347e+000,2.670111e-001,2.095891e-001,5.866395e-005,5.866395e-005,,,,,,,,,,,,,,,,,,,,
1524258387.693,,0.000000e+000,5.599016e+001,5.600103e+001,1,0,9.032258e-001,0.000000e+000,1.597314e+000,1.597314e+000,2.988071e-001,2.321922e-001,1.440114e+000,1.416071e-001,7.499218e-002,5.080040e-005,5.080040e-005,,,,,,,,,,,,,,,,,,,,
1524258412.694,,0.000000e+000,5.599831e+001,5.599016e+001,1,0,1.032258e+000,0.000000e+000,1.483482e+000,1.483482e+000,1.990920e-001,1.227466e-001,1.281677e+000,-2.713457e-003,-7.905889e-002,3.898251e-005,3.898251e-005,,,,,,,,,,,,,,,,,,,,
1524258437.884,,0.000000e+000,5.599695e+001,5.600103e+001,1,0,1.161290e+000,0.000000e+000,1.338064e+000,1.338064e+000,6.872216e-002,-1.728022e-002,1.108685e+000,-1.606567e-001,-2.466590e-001,2.371860e-005,2.371860e-005,,,,,,,,,,,,,,,,,,,,
1524258463.004,,0.000000e+000,5.599695e+001,5.599831e+001,1,0,1.290323e+000,0.000000e+000,1.173114e+000,1.173114e+000,-8.127586e-002,-1.767471e-001,9.257109e-001,-3.286785e-001,-4.241498e-001,6.252405e-006,6.252405e-006,,,,,,,,,,,,,,,,,,,,
1524258487.984,,0.000000e+000,5.599695e+001,5.599967e+001,1,0,1.419355e+000,0.000000e+000,9.900053e-001,9.900053e-001,-2.487610e-001,-3.534665e-001,7.359121e-001,-5.028542e-001,-6.075596e-001,-1.317964e-005,-1.317964e-005,,,,,,,,,,,,,,,,,,,,
1524258513.044,,0.000000e+000,5.599831e+001,5.600782e+001,1,0,1.548387e+000,0.000000e+000,7.920958e-001,7.920958e-001,-4.318275e-001,-5.459308e-001,5.472504e-001,-6.766729e-001,-7.907762e-001,-3.433469e-005,-3.433469e-005,,,,,,,,,,,,,,,,,,,,
1524258538.554,,0.000000e+000,5.600238e+001,5.599831e+001,1,0,1.677419e+000,0.000000e+000,6.056306e-001,6.056306e-001,-6.028945e-001,-7.271027e-001,3.729737e-001,-8.355514e-001,-9.597596e-001,-5.414963e-005,-5.414963e-005,,,,,,,,,,,,,,,,,,,,
1524258564.064,,0.000000e+000,5.599288e+001,5.600238e+001,1,0,1.806452e+000,0.000000e+000,4.095522e-001,4.095522e-001,-7.825886e-001,-9.158842e-001,2.308939e-001,-9.612469e-001,-1.094543e+000,-7.493459e-005,-7.493459e-005,,,,,,,,,,,,,,,,,,,,
1524258589.424,,0.000000e+000,5.599831e+001,5.599967e+001,1,0,1.935484e+000,0.000000e+000,2.468910e-001,2.468910e-001,-9.307541e-001,-1.073471e+000,1.457649e-001,-1.031880e+000,-1.174598e+000,-9.218953e-005,-9.218953e-005,,,,,,,,,,,,,,,,,,,,
1524258614.924,,0.000000e+000,5.599831e+001,5.599016e+001,1,0,2.064516e+000,0.000000e+000,1.261921e-001,1.261921e-001,-1.036590e+000,-1.188541e+000,1.287191e-001,-1.034063e+000,-1.186014e+000,-1.047006e-004,-1.047006e-004,,,,,,,,,,,,,,,,,,,,
1524258640.534,,0.000000e+000,5.600510e+001,5.600375e+001,1,0,2.193548e+000,0.000000e+000,6.576639e-002,6.576639e-002,-1.081053e+000,-1.243482e+000,1.834191e-001,-9.634001e-001,-1.125830e+000,-1.103937e-004,-1.103937e-004,,,,,,,,,,,,,,,,,,,,
1524258666.104,,0.000000e+000,5.599288e+001,5.600375e+001,1,0,2.322581e+000,0.000000e+000,6.897078e-002,6.897078e-002,-1.061575e+000,-1.233574e+000,2.918519e-001,-8.386937e-001,-1.010693e+000,-1.089230e-004,-1.089230e-004,,,,,,,,,,,,,,,,,,,,
1524258691.364,,0.000000e+000,5.599831e+001,5.600103e+001,1,0,2.451613e+000,0.000000e+000,1.377890e-001,1.377890e-001,-9.774014e-001,-1.159001e+000,4.358062e-001,-6.793842e-001,-8.609841e-001,-1.002278e-004,-1.002278e-004,,,,,,,,,,,,,,,,,,,,
1524258716.514,,0.000000e+000,5.599967e+001,5.599695e+001,1,0,2.580645e+000,0.000000e+000,2.641337e-001,2.641337e-001,-8.362945e-001,-1.027534e+000,5.941893e-001,-5.062389e-001,-6.974789e-001,-8.515592e-005,-8.515592e-005,,,,,,,,,,,,,,,,,,,,
1524258741.284,,0.000000e+000,5.598880e+001,5.599559e+001,1,0,2.709677e+000,0.000000e+000,4.203860e-001,4.203860e-001,-6.624669e-001,-8.650825e-001,7.515199e-001,-3.313330e-001,-5.339487e-001,-6.646838e-005,-6.646838e-005,,,,,,,,,,,,,,,,,,,,
1524258766.224,,0.000000e+000,5.599695e+001,5.599559e+001,1,0,2.838710e+000,0.000000e+000,6.140230e-001,6.140230e-001,-4.551503e-001,-6.644240e-001,9.070024e-001,-1.621709e-001,-3.714446e-001,-4.394993e-005,-4.394993e-005,,,,,,,,,,,,,,,,,,,,
1524258791.334,,0.000000e+000,5.599967e+001,5.599424e+001,1,0,2.967742e+000,0.000000e+000,8.046082e-001,8.046082e-001,-2.493258e-001,-4.690409e-001,1.051189e+000,-2.745225e-003,-2.224603e-001,-2.166418e-005,-2.166418e-005,,,,,,,,,,,,,,,,,,,,
1524258815.964,,0.000000e+000,5.599559e+001,5.599288e+001,1,0,3.096774e+000,0.000000e+000,9.887846e-001,9.887846e-001,-5.022657e-002,-2.822579e-001,1.182532e+000,1.435208e-001,-8.851051e-002,-1.984445e-007,-1.984445e-007,,,,,,,,,,,,,,,,,,,,
1524258840.864,,0.000000e+000,5.600238e+001,5.600238e+001,1,0,3.225806e+000,0.000000e+000,1.210956e+000,1.210956e+000,1.394873e-001,-9.979689e-002,1.342281e+000,2.708128e-001,3.152859e-002,2.035951e-005,2.035951e-005,,,,,,,,,,,,,,,,,,,,
1524258865.984,,0.000000e+000,5.600103e+001,5.599695e+001,1,0,3.354839e+000,0.000000e+000,1.360647e+000,1.360647e+000,3.055084e-001,5.753410e-002,1.425792e+000,3.706535e-001,1.226792e-001,3.823212e-005,3.823212e-005,,,,,,,,,,,,,,,,,,,,
1524258890.624,,0.000000e+000,5.600375e+001,5.600375e+001,1,0,3.483871e+000,0.000000e+000,1.494926e+000,1.494926e+000,4.551239e-001,1.970911e-001,1.474426e+000,4.346240e-001,1.765912e-001,5.422790e-005,5.422790e-005,,,,,,,,,,,,,,,,,,,,
1524258915.954,,0.000000e+000,5.599152e+001,5.599559e+001,1,0,3.612903e+000,0.000000e+000,1.550927e+000,1.550927e+000,5.733821e-001,3.067714e-001,1.436940e+000,4.593948e-001,1.927841e-001,6.678097e-005,6.678097e-005,,,,,,,,,,,,,,,,,,,,
1524258941.624,,0.000000e+000,5.599695e+001,5.599695e+001,1,0,3.741935e+000,0.000000e+000,1.604944e+000,1.604944e+000,6.424181e-001,3.656919e-001,1.409716e+000,4.471898e-001,1.704636e-001,7.376635e-005,7.376635e-005,,,,,,,,,,,,,,,,,,,,
1524258967.084,,0.000000e+000,5.599967e+001,5.599967e+001,1,0,3.870968e+000,0.000000e+000,1.621271e+000,1.621271e+000,6.760461e-001,3.880031e-001,1.353803e+000,4.085779e-001,1.205349e-001,7.675042e-005,7.675042e-005,,,,,,,,,,,,,,,,,,,,
1524258992.334,,0.000000e+000,5.599424e+001,5.599967e+001,1,0,4.000000e+000,0.000000e+000,1.605402e+000,1.605402e+000,6.742740e-001,3.781407e-001,1.286940e+000,3.558126e-001,5.967927e-002,7.589426e-005,7.589426e-005,,,,,,,,,,,,,,,,,,,,
1524259029.734,,0.000000e+000,5.599424e+001,5.599831e+001,1,0,0.000000e+000,0.000000e+000,1.406119e+000,1.406119e+000,1.847047e-001,1.847047e-001,1.578037e+000,3.566232e-001,3.566232e-001,4.335139e-005,4.335139e-005,,,,,,,,,,,,,,,,,,,,
1524259055.474,,0.000000e+000,5.600510e+001,5.599559e+001,1,0,1.290323e-001,0.000000e+000,1.438315e+000,1.438315e+000,2.331713e-001,2.235829e-001,1.615062e+000,4.099181e-001,4.003297e-001,4.802708e-005,4.802708e-005,,,,,,,,,,,,,,,,,,,,
1524259079.734,,0.000000e+000,5.599831e+001,5.599152e+001,1,0,2.580645e-001,0.000000e+000,1.487755e+000,1.487755e+000,2.971792e-001,2.780020e-001,1.638981e+000,4.484061e-001,4.292289e-001,5.445837e-005,5.445837e-005,,,,,,,,,,,,,,,,,,,,
1524259105.004,,0.000000e+000,5.599152e+001,5.600375e+001,1,0,3.870968e-001,0.000000e+000,1.530022e+000,1.530022e+000,3.547127e-001,3.257267e-001,1.636718e+000,4.614083e-001,4.324224e-001,6.026032e-005,6.026032e-005,,,,,,,,,,,,,,,,,,,,
1524259130.155,,0.000000e+000,5.599967e+001,5.600103e+001,1,0,5.161290e-001,0.000000e+000,1.547417e+000,1.547417e+000,3.893425e-001,3.512486e-001,1.595276e+000,4.372013e-001,3.991075e-001,6.329227e-005,6.329227e-005,,,,,,,,,,,,,,,,,,,,
1524259155.185,,0.000000e+000,5.599967e+001,5.599559e+001,1,0,6.451613e-001,0.000000e+000,1.541924e+000,1.541924e+000,3.983270e-001,3.503894e-001,1.516200e+000,3.726027e-001,3.246651e-001,6.362564e-005,6.362564e-005,,,,,,,,,,,,,,,,,,,,
1524259180.495,,0.000000e+000,5.599559e+001,5.599424e+001,1,0,7.741935e-001,0.000000e+000,1.496605e+000,1.496605e+000,3.676849e-001,3.100564e-001,1.401600e+000,2.726801e-001,2.150517e-001,5.951177e-005,5.951177e-005,,,,,,,,,,,,,,,,,,,,
1524259205.575,,0.000000e+000,5.599831e+001,5.599967e+001,1,0,9.032258e-001,0.000000e+000,1.413596e+000,1.413596e+000,3.021950e-001,2.348689e-001,1.256119e+000,1.447187e-001,7.739258e-002,5.149347e-005,5.149347e-005,,,,,,,,,,,,,,,,,,,,
1524259230.645,,0.000000e+000,5.600103e+001,5.599695e+001,1,0,1.032258e+000,0.000000e+000,1.295949e+000,1.295949e+000,2.005861e-001,1.243210e-001,1.092591e+000,-2.771243e-003,-7.903636e-002,3.938658e-005,3.938658e-005,,,,,,,,,,,,,,,,,,,,
1524259255.715,,0.000000e+000,5.599831e+001,5.599695e+001,1,0,1.161290e+000,0.000000e+000,1.148547e+000,1.148547e+000,6.651381e-002,-1.978910e-002,9.180782e-001,-1.639545e-001,-2.502574e-001,2.372226e-005,2.372226e-005,,,,,,,,,,,,,,,,,,,,
1524259280.595,,0.000000e+000,5.599424e+001,5.599559e+001,1,0,1.290323e+000,0.000000e+000,9.802396e-001,9.802396e-001,-8.655801e-002,-1.821098e-001,7.314888e-001,-3.353088e-001,-4.308606e-001,5.895810e-006,5.895810e-006,,,,,,,,,,,,,,,,,,,,
1524259306.205,,0.000000e+000,5.599831e+001,5.600103e+001,1,0,1.419355e+000,0.000000e+000,7.864500e-001,7.864500e-001,-2.640556e-001,-3.691379e-001,5.378472e-001,-5.126584e-001,-6.177407e-001,-1.465448e-005,-1.465448e-005,,,,,,,,,,,,,,,,,,,,
1524259331.095,,0.000000e+000,5.599831e+001,5.599831e+001,1,0,1.548387e+000,0.000000e+000,5.996796e-001,5.996796e-001,-4.372355e-001,-5.522077e-001,3.467557e-001,-6.901594e-001,-8.051316e-001,-3.469206e-005,-3.469206e-005,,,,,,,,,,,,,,,,,,,,
1524259356.685,,0.000000e+000,5.600103e+001,5.599288e+001,1,0,1.677419e+000,0.000000e+000,3.981079e-001,3.981079e-001,-6.232617e-001,-7.487861e-001,1.698595e-001,-8.515102e-001,-9.770345e-001,-5.618820e-005,-5.618820e-005,,,,,,,,,,,,,,,,,,,,
1524259381.815,,0.000000e+000,5.600646e+001,5.600238e+001,1,0,1.806452e+000,0.000000e+000,2.072175e-001,2.072175e-001,-7.994435e-001,-9.329063e-001,2.663738e-002,-9.800237e-001,-1.113486e+000,-7.659297e-005,-7.659297e-005,,,,,,,,,,,,,,,,,,,,
1524259406.385,,0.000000e+000,5.600103e+001,5.599831e+001,1,0,1.935484e+000,0.000000e+000,4.043641e-002,4.043641e-002,-9.511472e-001,-1.094360e+000,-5.958269e-002,-1.051166e+000,-1.194379e+000,-9.425287e-005,-9.425287e-005,,,,,,,,,,,,,,,,,,,,
1524259431.385,,0.000000e+000,5.601054e+001,5.599695e+001,1,0,2.064516e+000,0.000000e+000,-7.354849e-002,-7.354849e-002,-1.051159e+000,-1.203433e+000,-7.440495e-002,-1.052015e+000,-1.204289e+000,-1.061298e-004,-1.061298e-004,,,,,,,,,,,,,,,,,,,,
1524259456.285,,0.000000e+000,5.599559e+001,5.599288e+001,1,0,2.193548e+000,0.000000e+000,-1.326009e-001,-1.326009e-001,-1.095614e+000,-1.257099e+000,-1.760831e-002,-9.806211e-001,-1.142107e+000,-1.118095e-004,-1.118095e-004,,,,,,,,,,,,,,,,,,,,
1524259481.255,,0.000000e+000,5.599967e+001,5.599424e+001,1,0,2.322581e+000,0.000000e+000,-1.283284e-001,-1.283284e-001,-1.075633e+000,-1.248595e+000,9.299957e-002,-8.543053e-001,-1.027267e+000,-1.102901e-004,-1.102901e-004,,,,,,,,,,,,,,,,,,,,
1524259506.725,,0.000000e+000,5.600510e+001,5.599967e+001,1,0,2.451613e+000,0.000000e+000,-5.828946e-002,-5.828946e-002,-9.894742e-001,-1.171536e+000,2.388595e-001,-6.923252e-001,-8.743870e-001,-1.013645e-004,-1.013645e-004,,,,,,,,,,,,,,,,,,,,
1524259544.765,,0.000000e+000,5.599424e+001,5.599695e+001,1,0,2.580645e+000,0.000000e+000,1.651026e-001,1.651026e-001,-2.119259e+000,-2.595586e+000,9.952959e-001,-1.289066e+000,-1.765393e+000,-8.620565e-005,-8.620565e-005,,,,,,,,,,,,,,,,,,,,
1524259569.695,,0.000000e+000,5.599695e+001,5.600646e+001,1,0,2.709677e+000,0.000000e+000,5.874723e-001,5.874723e-001,-1.662349e+000,-2.163595e+000,1.407864e+000,-8.419572e-001,-1.343204e+000,-6.651395e-005,-6.651395e-005,,,,,,,,,,,,,,,,,,,,
1524259594.795,,0.000000e+000,5.600103e+001,5.599424e+001,1,0,2.838710e+000,0.000000e+000,1.055314e+000,1.055314e+000,-1.154770e+000,-1.680781e+000,1.797740e+000,-4.123446e-001,-9.383548e-001,-4.453347e-005,-4.453347e-005,,,,,,,,,,,,,,,,,,,,
1524259620.395,,0.000000e+000,5.599695e+001,5.600646e+001,1,0,2.967742e+000,0.000000e+000,1.530632e+000,1.530632e+000,-6.448349e-001,-1.194282e+000,2.168492e+000,-6.975353e-003,-5.564225e-001,-2.243905e-005,-2.243905e-005,,,,,,,,,,,,,,,,,,,,
1524259646.675,,0.000000e+000,5.599831e+001,5.599288e+001,1,0,3.096774e+000,0.000000e+000,2.130465e+000,2.130465e+000,-1.235474e-001,-6.959405e-001,2.619061e+000,3.650485e-001,-2.073445e-001,1.737499e-007,1.737499e-007,,,,,,,,,,,,,,,,,,,,
1524259671.585,,0.000000e+000,5.600510e+001,5.599831e+001,1,0,3.225806e+000,0.000000e+000,2.560006e+000,2.560006e+000,3.425682e-001,-2.588563e-001,2.906286e+000,6.888480e-001,8.742356e-002,2.024966e-005,2.024966e-005,,,,,,,,,,,,,,,,,,,,
1524259696.665,,0.000000e+000,5.599016e+001,5.599831e+001,1,0,3.354839e+000,0.000000e+000,2.974594e+000,2.974594e+000,7.911395e-001,1.747169e-001,3.126303e+000,9.428488e-001,3.264263e-001,3.969988e-005,3.969988e-005,,,,,,,,,,,,,,,,,,,,
1524259722.445,,0.000000e+000,5.599831e+001,5.599831e+001,1,0,3.483871e+000,0.000000e+000,3.301594e+000,3.301594e+000,1.157162e+000,5.137417e-001,3.250567e+000,1.106134e+000,4.627140e-001,5.532221e-005,5.532221e-005,,,,,,,,,,,,,,,,,,,,
1524259746.955,,0.000000e+000,5.600103e+001,5.599559e+001,1,0,3.612903e+000,0.000000e+000,3.431754e+000,3.431754e+000,1.442300e+000,7.763166e-001,3.155577e+000,1.166123e+000,5.001397e-001,6.736127e-005,6.736127e-005,,,,,,,,,,,,,,,,,,,,
1524259772.465,,0.000000e+000,5.599559e+001,5.599424e+001,1,0,3.741935e+000,0.000000e+000,3.590753e+000,3.590753e+000,1.632698e+000,9.480262e-001,3.095462e+000,1.137407e+000,4.527354e-001,7.525793e-005,7.525793e-005,,,,,,,,,,,,,,,,,,,,
1524259797.755,,0.000000e+000,5.599424e+001,5.599695e+001,1,0,3.870968e+000,0.000000e+000,3.628290e+000,3.628290e+000,1.709906e+000,9.967885e-001,2.958264e+000,1.039880e+000,3.267620e-001,7.794469e-005,7.794469e-005,,,,,,,,,,,,,,,,,,,,
1524259822.955,,0.000000e+000,5.599831e+001,5.599559e+001,1,0,4.000000e+000,0.000000e+000,3.591363e+000,3.591363e+000,1.704855e+000,9.751158e-001,2.792231e+000,9.057226e-001,1.759834e-001,7.711972e-005,7.711972e-005,,,,,,,,,,,,,,,,,,,,
1524259860.886,,0.000000e+000,5.599831e+001,5.600375e+001,1,0,0.000000e+000,0.000000e+000,3.081712e+000,3.081712e+000,4.800656e-001,4.800656e-001,3.506174e+000,9.045272e-001,9.045272e-001,4.424019e-005,4.424019e-005,,,,,,,,,,,,,,,,,,,,
1524259885.896,,0.000000e+000,5.599288e+001,5.599967e+001,1,0,1.290323e-001,0.000000e+000,3.160754e+000,3.160754e+000,5.940745e-001,5.701311e-001,3.607693e+000,1.041013e+000,1.017070e+000,4.869723e-005,4.869723e-005,,,,,,,,,,,,,,,,,,,,
1524259911.366,,0.000000e+000,5.599559e+001,5.600782e+001,1,0,2.580645e-001,0.000000e+000,3.278401e+000,3.278401e+000,7.535511e-001,7.059762e-001,3.663511e+000,1.138661e+000,1.091086e+000,5.504095e-005,5.504095e-005,,,,,,,,,,,,,,,,,,,,
1524259936.486,,0.000000e+000,5.600646e+001,5.599831e+001,1,0,3.870968e-001,0.000000e+000,3.394217e+000,3.394217e+000,9.055583e-001,8.339677e-001,3.659328e+000,1.170669e+000,1.099079e+000,6.116393e-005,6.116393e-005,,,,,,,,,,,,,,,,,,,,
1524259961.376,,0.000000e+000,5.600375e+001,5.599967e+001,1,0,5.161290e-001,0.000000e+000,3.446708e+000,3.446708e+000,9.932525e-001,8.987188e-001,3.563338e+000,1.109882e+000,1.015349e+000,6.430111e-005,6.430111e-005,,,,,,,,,,,,,,,,,,,,
1524259986.176,,0.000000e+000,5.599967e+001,5.600646e+001,1,0,6.451613e-001,0.000000e+000,3.419089e+000,3.419089e+000,1.001658e+000,8.836312e-001,3.365263e+000,9.478322e-001,8.298051e-001,6.397657e-005,6.397657e-005,,,,,,,,,,,,,,,,,,,,
1524260011.236,,0.000000e+000,5.599288e+001,5.599559e+001,1,0,7.741935e-001,0.000000e+000,3.317922e+000,3.317922e+000,9.375939e-001,7.962496e-001,3.072471e+000,6.921434e-001,5.507991e-001,6.038291e-005,6.038291e-005,,,,,,,,,,,,,,,,,,,,
1524260037.216,,0.000000e+000,5.599424e+001,5.599559e+001,1,0,9.032258e-001,0.000000e+000,3.106279e+000,3.106279e+000,7.595468e-001,5.923083e-001,2.713637e+000,3.669043e-001,1.996658e-001,5.180016e-005,5.180016e-005,,,,,,,,,,,,,,,,,,,,
1524260062.886,,0.000000e+000,5.600103e+001,5.600103e+001,1,0,1.032258e+000,0.000000e+000,2.809644e+000,2.809644e+000,4.983819e-001,3.067143e-001,2.304235e+000,-7.026389e-003,-1.986940e-001,3.944202e-005,3.944202e-005,,,,,,,,,,,,,,,,,,,,
1524260088.596,,0.000000e+000,5.599695e+001,5.599967e+001,1,0,1.161290e+000,0.000000e+000,2.438849e+000,2.438849e+000,1.625353e-001,-5.389071e-002,1.860250e+000,-4.160641e-001,-6.324900e-001,2.374461e-005,2.374461e-005,,,,,,,,,,,,,,,,,,,,
1524260113.786,,0.000000e+000,5.599695e+001,5.599152e+001,1,0,1.290323e+000,0.000000e+000,1.997711e+000,1.997711e+000,-2.404173e-001,-4.805460e-001,1.387488e+000,-8.506406e-001,-1.090769e+000,5.014459e-006,5.014459e-006,,,,,,,,,,,,,,,,,,,,
1524260138.816,,0.000000e+000,5.599152e+001,5.599016e+001,1,0,1.419355e+000,0.000000e+000,1.528344e+000,1.528344e+000,-6.731130e-001,-9.365957e-001,8.994079e-001,-1.302049e+000,-1.565531e+000,-1.503951e-005,-1.503951e-005,,,,,,,,,,,,,,,,,,,,
1524260164.196,,0.000000e+000,5.600510e+001,5.599967e+001,1,0,1.548387e+000,0.000000e+000,1.043870e+000,1.043870e+000,-1.120824e+000,-1.406663e+000,4.144067e-001,-1.750287e+000,-2.036126e+000,-3.577731e-005,-3.577731e-005,,,,,,,,,,,,,,,,,,,,
1524260189.536,,0.000000e+000,5.599831e+001,5.599831e+001,1,0,1.677419e+000,0.000000e+000,5.458152e-001,5.458152e-001,-1.583352e+000,-1.892010e+000,-3.316247e-002,-2.162329e+000,-2.470988e+000,-5.716020e-005,-5.716020e-005,,,,,,,,,,,,,,,,,,,,
1524260214.316,,0.000000e+000,5.600103e+001,5.599831e+001,1,0,1.806452e+000,0.000000e+000,6.713970e-002,6.713970e-002,-2.030168e+000,-2.360861e+000,-3.900192e-001,-2.487327e+000,-2.818020e+000,-7.783547e-005,-7.783547e-005,,,,,,,,,,,,,,,,,,,,
1524260239.546,,0.000000e+000,5.600238e+001,5.600510e+001,1,0,1.935484e+000,0.000000e+000,-3.372244e-001,-3.372244e-001,-2.396214e+000,-2.750329e+000,-6.094394e-001,-2.668430e+000,-3.022544e+000,-9.489676e-005,-9.489676e-005,,,,,,,,,,,,,,,,,,,,
1524260264.646,,0.000000e+000,5.600646e+001,5.599559e+001,1,0,2.064516e+000,0.000000e+000,-6.385901e-001,-6.385901e-001,-2.662110e+000,-3.039691e+000,-6.452090e-001,-2.668728e+000,-3.046310e+000,-1.074842e-004,-1.074842e-004,,,,,,,,,,,,,,,,,,,,
1524260290.226,,0.000000e+000,5.599424e+001,5.600375e+001,1,0,2.193548e+000,0.000000e+000,-7.901121e-001,-7.901121e-001,-2.778788e+000,-3.182330e+000,-4.982946e-001,-2.486970e+000,-2.890512e+000,-1.134172e-004,-1.134172e-004,,,,,,,,,,,,,,,,,,,,
1524260315.566,,0.000000e+000,5.599288e+001,5.600238e+001,1,0,2.322581e+000,0.000000e+000,-7.685969e-001,-7.685969e-001,-2.721439e+000,-3.153847e+000,-2.135772e-001,-2.166419e+000,-2.598827e+000,-1.115685e-004,-1.115685e-004,,,,,,,,,,,,,,,,,,,,
1524260340.466,,0.000000e+000,5.599831e+001,5.599831e+001,1,0,2.451613e+000,0.000000e+000,-5.775540e-001,-5.775540e-001,-2.497574e+000,-2.954360e+000,1.643825e-001,-1.755638e+000,-2.212424e+000,-1.022733e-004,-1.022733e-004,,,,,,,,,,,,,,,,,,,,
1524260365.646,,0.000000e+000,5.599288e+001,5.599695e+001,1,0,2.580645e+000,0.000000e+000,-2.432288e-001,-2.432288e-001,-2.125548e+000,-2.602268e+000,5.760337e-001,-1.306286e+000,-1.783005e+000,-8.633286e-005,-8.633286e-005,,,,,,,,,,,,,,,,,,,,
1524260390.626,,0.000000e+000,5.599695e+001,5.600782e+001,1,0,2.709677e+000,0.000000e+000,1.734951e-001,1.734951e-001,-1.674995e+000,-2.173445e+000,9.940753e-001,-8.544147e-001,-1.352865e+000,-6.688424e-005,-6.688424e-005,,,,,,,,,,,,,,,,,,,,
1524260415.286,,0.000000e+000,5.599559e+001,5.599831e+001,1,0,2.838710e+000,0.000000e+000,6.533913e-001,6.533913e-001,-1.159518e+000,-1.682910e+000,1.395018e+000,-4.178917e-001,-9.412835e-001,-4.456502e-005,-4.456502e-005,,,,,,,,,,,,,,,,,,,,
1524260440.716,,0.000000e+000,5.599695e+001,5.599424e+001,1,0,2.967742e+000,0.000000e+000,1.143053e+000,1.143053e+000,-6.327689e-001,-1.181351e+000,1.768757e+000,-7.065302e-003,-5.556479e-001,-2.174030e-005,-2.174030e-005,,,,,,,,,,,,,,,,,,,,
1524260465.876,,0.000000e+000,5.599831e+001,5.599967e+001,1,0,3.096774e+000,0.000000e+000,1.626612e+000,1.626612e+000,-1.126226e-001,-6.879092e-001,2.109115e+000,3.698804e-001,-2.054062e-001,7.868803e-007,7.868803e-007,,,,,,,,,,,,,,,,,,,,
1524260490.896,,0.000000e+000,5.600375e+001,5.599288e+001,1,0,3.225806e+000,0.000000e+000,2.071107e+000,2.071107e+000,3.620806e-001,-2.276423e-001,2.406242e+000,6.972158e-001,1.074929e-001,2.139714e-005,2.139714e-005,,,,,,,,,,,,,,,,,,,,
1524260516.586,,0.000000e+000,5.599559e+001,5.600238e+001,1,0,3.354839e+000,0.000000e+000,2.486763e+000,2.486763e+000,8.124198e-001,1.915834e-001,2.629555e+000,9.552120e-001,3.343756e-001,4.075211e-005,4.075211e-005,,,,,,,,,,,,,,,,,,,,
1524260541.237,,0.000000e+000,5.599695e+001,5.599288e+001,1,0,3.483871e+000,0.000000e+000,2.807050e+000,2.807050e+000,1.168631e+000,5.214922e-001,2.758283e+000,1.119864e+000,4.727256e-001,5.593368e-005,5.593368e-005,,,,,,,,,,,,,,,,,,,,
1524260566.447,,0.000000e+000,5.599559e+001,5.599695e+001,1,0,3.612903e+000,0.000000e+000,3.061265e+000,3.061265e+000,1.453402e+000,7.913175e-001,2.790268e+000,1.182405e+000,5.203202e-001,6.807349e-005,6.807349e-005,,,,,,,,,,,,,,,,,,,,
1524260590.967,,0.000000e+000,5.599831e+001,5.600238e+001,1,0,3.741935e+000,0.000000e+000,3.204547e+000,3.204547e+000,1.634285e+000,9.454486e-001,2.719913e+000,1.149651e+000,4.608150e-001,7.539790e-005,7.539790e-005,,,,,,,,,,,,,,,,,,,,
1524260616.157,,0.000000e+000,5.599559e+001,5.599152e+001,1,0,3.870968e+000,0.000000e+000,3.256581e+000,3.256581e+000,1.721624e+000,1.005308e+000,2.586212e+000,1.051256e+000,3.349395e-001,7.855127e-005,7.855127e-005,,,,,,,,,,,,,,,,,,,,
1524260641.337,,0.000000e+000,5.600375e+001,5.600646e+001,1,0,4.000000e+000,0.000000e+000,3.210040e+000,3.210040e+000,1.711716e+000,9.676051e-001,2.414547e+000,9.162232e-001,1.721120e-001,7.734892e-005,7.734892e-005,,,,,,,,,,,,,,,,,,,,
1524260679.657,,0.000000e+000,5.599831e+001,5.600510e+001,1,0,0.000000e+000,0.000000e+000,2.708171e+000,2.708171e+000,4.866717e-001,4.866717e-001,3.138719e+000,9.172192e-001,9.172192e-001,4.467248e-005,4.467248e-005,,,,,,,,,,,,,,,,,,,,
1524260704.937,,0.000000e+000,5.598880e+001,5.599695e+001,1,0,1.290323e-001,0.000000e+000,2.804608e+000,2.804608e+000,6.126143e-001,5.885720e-001,3.245188e+000,1.053195e+000,1.029152e+000,4.970670e-005,4.970670e-005,,,,,,,,,,,,,,,,,,,,
1524260730.567,,0.000000e+000,5.598745e+001,5.599288e+001,1,0,2.580645e-001,0.000000e+000,2.937209e+000,2.937209e+000,7.804350e-001,7.325721e-001,3.310579e+000,1.153804e+000,1.105941e+000,5.645739e-005,5.645739e-005,,,,,,,,,,,,,,,,,,,,
1524260755.767,,0.000000e+000,5.599831e+001,5.599831e+001,1,0,3.870968e-001,0.000000e+000,3.037766e+000,3.037766e+000,9.188320e-001,8.477786e-001,3.303962e+000,1.185027e+000,1.113974e+000,6.183521e-005,6.183521e-005,,,,,,,,,,,,,,,,,,,,
1524260780.367,,0.000000e+000,5.599695e+001,5.599831e+001,1,0,5.161290e-001,0.000000e+000,3.091020e+000,3.091020e+000,1.002455e+000,9.066513e-001,3.209335e+000,1.120770e+000,1.024966e+000,6.493705e-005,6.493705e-005,,,,,,,,,,,,,,,,,,,,
1524260805.597,,0.000000e+000,5.600375e+001,5.600103e+001,1,0,6.451613e-001,0.000000e+000,3.078355e+000,3.078355e+000,1.023107e+000,9.027846e-001,3.012917e+000,9.576689e-001,8.373468e-001,6.520156e-005,6.520156e-005,,,,,,,,,,,,,,,,,,,,
1524260830.357,,0.000000e+000,5.599695e+001,5.599424e+001,1,0,7.741935e-001,0.000000e+000,2.953231e+000,2.953231e+000,9.361317e-001,7.931907e-001,2.717047e+000,6.999476e-001,5.570066e-001,6.052596e-005,6.052596e-005,,,,,,,,,,,,,,,,,,,,
1524260855.407,,0.000000e+000,5.600510e+001,5.599695e+001,1,0,9.032258e-001,0.000000e+000,2.740062e+000,2.740062e+000,7.550054e-001,5.866399e-001,2.357639e+000,3.725815e-001,2.042160e-001,5.182048e-005,5.182048e-005,,,,,,,,,,,,,,,,,,,,
1524260880.507,,0.000000e+000,5.599967e+001,5.599559e+001,1,0,1.032258e+000,0.000000e+000,2.438239e+000,2.438239e+000,4.916025e-001,3.021231e-001,1.939510e+000,-7.126987e-003,-1.966064e-001,3.924661e-005,3.924661e-005,,,,,,,,,,,,,,,,,,,,
1524260905.497,,0.000000e+000,5.600103e+001,5.599695e+001,1,0,1.161290e+000,0.000000e+000,2.071412e+000,2.071412e+000,1.548861e-001,-5.864048e-002,1.495959e+000,-4.205675e-001,-6.340940e-001,2.346822e-005,2.346822e-005,,,,,,,,,,,,,,,,,,,,
1524260930.757,,0.000000e+000,5.599695e+001,5.599288e+001,1,0,1.290323e+000,0.000000e+000,1.625239e+000,1.625239e+000,-2.537468e-001,-4.900373e-001,1.017581e+000,-8.614048e-001,-1.097695e+000,4.505360e-006,4.505360e-006,,,,,,,,,,,,,,,,,,,,
1524260955.557,,0.000000e+000,5.600510e+001,5.599424e+001,1,0,1.419355e+000,0.000000e+000,1.155413e+000,1.155413e+000,-6.932235e-001,-9.532015e-001,5.313923e-001,-1.317244e+000,-1.577222e+000,-1.584300e-005,-1.584300e-005,,,,,,,,,,,,,,,,,,,,
1524260980.337,,0.000000e+000,5.600510e+001,5.599695e+001,1,0,1.548387e+000,0.000000e+000,6.535439e-001,6.535439e-001,-1.161262e+000,-1.449025e+000,4.335301e-002,-1.771453e+000,-2.059216e+000,-3.742498e-005,-3.742498e-005,,,,,,,,,,,,,,,,,,,,
1524261005.437,,0.000000e+000,5.599288e+001,5.600238e+001,1,0,1.677419e+000,0.000000e+000,1.556420e-001,1.556420e-001,-1.615425e+000,-1.926471e+000,-4.142883e-001,-2.185355e+000,-2.496401e+000,-5.845402e-005,-5.845402e-005,,,,,,,,,,,,,,,,,,,,
1524261030.847,,0.000000e+000,5.599831e+001,5.599288e+001,1,0,1.806452e+000,0.000000e+000,-3.163195e-001,-3.163195e-001,-2.055629e+000,-2.388201e+000,-7.766393e-001,-2.515948e+000,-2.848520e+000,-7.883112e-005,-7.883112e-005,,,,,,,,,,,,,,,,,,,,
1524261056.117,,0.000000e+000,5.599831e+001,5.599559e+001,1,0,1.935484e+000,0.000000e+000,-7.228199e-001,-7.228199e-001,-2.433854e+000,-2.789459e+000,-9.850656e-001,-2.696100e+000,-3.051704e+000,-9.645477e-005,-9.645477e-005,,,,,,,,,,,,,,,,,,,,
1524261081.577,,0.000000e+000,5.599559e+001,5.599559e+001,1,0,2.064516e+000,0.000000e+000,-1.022660e+000,-1.022660e+000,-2.697720e+000,-3.079364e+000,-1.026778e+000,-2.701838e+000,-3.083482e+000,-1.089326e-004,-1.089326e-004,,,,,,,,,,,,,,,,,,,,
1524261106.867,,0.000000e+000,5.600103e+001,5.599967e+001,1,0,2.193548e+000,0.000000e+000,-1.170062e+000,-1.170062e+000,-2.812291e+000,-3.217502e+000,-8.723715e-001,-2.514601e+000,-2.919811e+000,-1.147875e-004,-1.147875e-004,,,,,,,,,,,,,,,,,,,,
1524261132.457,,0.000000e+000,5.599559e+001,5.599424e+001,1,0,2.322581e+000,0.000000e+000,-1.134356e+000,-1.134356e+000,-2.743730e+000,-3.168503e+000,-5.802858e-001,-2.189660e+000,-2.614434e+000,-1.124060e-004,-1.124060e-004,,,,,,,,,,,,,,,,,,,,
1524261157.547,,0.000000e+000,5.599831e+001,5.600510e+001,1,0,2.451613e+000,0.000000e+000,-9.581140e-001,-9.581140e-001,-2.532596e+000,-2.986500e+000,-2.011391e-001,-1.775621e+000,-2.229525e+000,-1.036878e-004,-1.036878e-004,,,,,,,,,,,,,,,,,,,,
1524261182.787,,0.000000e+000,5.599831e+001,5.599967e+001,1,0,2.580645e+000,0.000000e+000,-5.961700e-001,-5.961700e-001,-2.139993e+000,-2.615630e+000,2.261851e-001,-1.317638e+000,-1.793275e+000,-8.686808e-005,-8.686808e-005,,,,,,,,,,,,,,,,,,,,
1524261207.657,,0.000000e+000,5.600375e+001,5.599424e+001,1,0,2.709677e+000,0.000000e+000,-1.683070e-001,-1.683070e-001,-1.678642e+000,-2.177908e+000,6.460972e-001,-8.642379e-001,-1.363504e+000,-6.691710e-005,-6.691710e-005,,,,,,,,,,,,,,,,,,,,
1524261233.857,,0.000000e+000,5.600510e+001,5.599967e+001,1,0,2.838710e+000,0.000000e+000,3.149462e-001,3.149462e-001,-1.161164e+000,-1.690852e+000,1.053775e+000,-4.223356e-001,-9.520234e-001,-4.456779e-005,-4.456779e-005,,,,,,,,,,,,,,,,,,,,
1524261258.788,,0.000000e+000,5.600510e+001,5.600646e+001,1,0,2.967742e+000,0.000000e+000,8.088807e-001,8.088807e-001,-6.364311e-001,-1.181653e+000,1.438179e+000,-7.132813e-003,-5.523545e-001,-2.175770e-005,-2.175770e-005,,,,,,,,,,,,,,,,,,,,
1524261283.918,,0.000000e+000,5.599831e+001,5.600103e+001,1,0,3.096774e+000,0.000000e+000,1.301289e+000,1.301289e+000,-1.096712e-001,-6.844437e-001,1.784957e+000,3.739964e-001,-2.007761e-001,1.056571e-006,1.056571e-006,,,,,,,,,,,,,,,,,,,,
1524261334.528,,0.000000e+000,5.600375e+001,5.599424e+001,1,0,3.225806e+000,0.000000e+000,1.757839e+000,1.757839e+000,3.858506e-001,-2.059335e-001,2.076471e+000,7.044824e-001,1.126983e-001,2.256021e-005,2.256021e-005,,,,,,,,,,,,,,,,,,,,
1524261359.478,,0.000000e+000,5.599695e+001,5.599288e+001,1,0,3.354839e+000,0.000000e+000,2.155032e+000,2.155032e+000,8.177556e-001,1.971629e-001,2.302360e+000,9.650835e-001,3.444908e-001,4.111663e-005,4.111663e-005,,,,,,,,,,,,,,,,,,,,
1524261384.368,,0.000000e+000,5.599424e+001,5.600103e+001,1,0,3.483871e+000,0.000000e+000,2.495155e+000,2.495155e+000,1.186587e+000,5.473284e-001,2.439044e+000,1.130476e+000,4.912168e-001,5.694917e-005,5.694917e-005,,,,,,,,,,,,,,,,,,,,
1524261409.178,,0.000000e+000,5.600103e+001,5.600375e+001,1,0,3.612903e+000,0.000000e+000,2.753033e+000,2.753033e+000,1.473508e+000,8.114084e-001,2.474663e+000,1.195138e+000,5.330385e-001,6.910031e-005,6.910031e-005,,,,,,,,,,,,,,,,,,,,
1524261434.308,,0.000000e+000,5.599424e+001,5.600375e+001,1,0,3.741935e+000,0.000000e+000,2.888380e+000,2.888380e+000,1.642907e+000,9.555938e-001,2.406184e+000,1.160711e+000,4.733977e-001,7.591894e-005,7.591894e-005,,,,,,,,,,,,,,,,,,,,
1524261459.458,,0.000000e+000,5.600510e+001,5.599695e+001,1,0,3.870968e+000,0.000000e+000,2.941329e+000,2.941329e+000,1.727597e+000,1.021749e+000,2.276584e+000,1.062852e+000,3.570035e-001,7.910043e-005,7.910043e-005,,,,,,,,,,,,,,,,,,,,
1524261484.478,,0.000000e+000,5.599967e+001,5.599288e+001,1,0,4.000000e+000,0.000000e+000,2.888380e+000,2.888380e+000,1.710490e+000,9.717743e-001,2.103292e+000,9.254022e-001,1.866863e-001,7.749397e-005,7.749397e-005,,,,,,,,,,,,,,,,,,,,
1524261522.958,,0.000000e+000,5.599288e+001,5.599559e+001,1,0,0.000000e+000,0.000000e+000,2.405280e+000,2.405280e+000,5.047376e-001,5.047376e-001,2.827343e+000,9.268007e-001,9.268007e-001,4.551653e-005,4.551653e-005,,,,,,,,,,,,,,,,,,,,
1524261548.248,,0.000000e+000,5.600646e+001,5.599967e+001,1,0,1.290323e-001,0.000000e+000,2.496376e+000,2.496376e+000,6.227539e-001,5.987895e-001,2.937919e+000,1.064297e+000,1.040332e+000,5.025211e-005,5.025211e-005,,,,,,,,,,,,,,,,,,,,
1524261573.238,,0.000000e+000,5.599831e+001,5.599695e+001,1,0,2.580645e-001,0.000000e+000,2.622111e+000,2.622111e+000,7.860909e-001,7.385809e-001,2.999038e+000,1.163018e+000,1.115508e+000,5.673456e-005,5.673456e-005,,,,,,,,,,,,,,,,,,,,
1524261598.398,,0.000000e+000,5.599695e+001,5.599559e+001,1,0,3.870968e-001,0.000000e+000,2.728161e+000,2.728161e+000,9.269327e-001,8.564225e-001,2.998924e+000,1.197696e+000,1.127186e+000,6.225752e-005,6.225752e-005,,,,,,,,,,,,,,,,,,,,
1524261623.318,,0.000000e+000,5.600238e+001,5.599152e+001,1,0,5.161290e-001,0.000000e+000,2.782330e+000,2.782330e+000,1.008012e+000,9.119534e-001,2.908226e+000,1.133907e+000,1.037849e+000,6.534692e-005,6.534692e-005,,,,,,,,,,,,,,,,,,,,
1524261649.378,,0.000000e+000,5.599967e+001,5.599831e+001,1,0,6.451613e-001,0.000000e+000,2.767224e+000,2.767224e+000,1.025844e+000,9.066794e-001,2.707707e+000,9.663277e-001,8.471627e-001,6.535948e-005,6.535948e-005,,,,,,,,,,,,,,,,,,,,
1524261674.318,,0.000000e+000,5.599831e+001,5.599967e+001,1,0,7.741935e-001,0.000000e+000,2.659647e+000,2.659647e+000,9.486308e-001,8.060640e-001,2.419551e+000,7.085342e-001,5.659674e-001,6.121348e-005,6.121348e-005,,,,,,,,,,,,,,,,,,,,
1524261699.768,,0.000000e+000,5.600375e+001,5.599424e+001,1,0,9.032258e-001,0.000000e+000,2.451972e+000,2.451972e+000,7.744096e-001,6.080821e-001,2.052754e+000,3.751913e-001,2.088637e-001,5.269801e-005,5.269801e-005,,,,,,,,,,,,,,,,,,,,
1524261724.978,,0.000000e+000,5.599695e+001,5.599424e+001,1,0,1.032258e+000,0.000000e+000,2.265202e+000,2.265202e+000,5.012926e-001,3.109986e-001,1.756715e+000,-7.193878e-003,-1.974880e-001,3.981523e-005,3.981523e-005,,,,,,,,,,,,,,,,,,,,
1524261749.928,,0.000000e+000,5.600646e+001,5.599288e+001,1,0,1.161290e+000,0.000000e+000,1.880522e+000,1.880522e+000,1.501127e-001,-6.317425e-002,1.305331e+000,-4.250783e-001,-6.383653e-001,2.337786e-005,2.337786e-005,,,,,,,,,,,,,,,,,,,,
1524261774.888,,0.000000e+000,5.599831e+001,5.600103e+001,1,0,1.290323e+000,0.000000e+000,1.323873e+000,1.323873e+000,-2.593357e-001,-4.961324e-001,7.123027e-001,-8.709057e-001,-1.107702e+000,4.395915e-006,4.395915e-006,,,,,,,,,,,,,,,,,,,,
1524261800.008,,0.000000e+000,5.599152e+001,5.599559e+001,1,0,1.419355e+000,0.000000e+000,8.581674e-001,8.581674e-001,-6.947187e-001,-9.569000e-001,2.244684e-001,-1.328418e+000,-1.590599e+000,-1.578139e-005,-1.578139e-005,,,,,,,,,,,,,,,,,,,,
1524261824.548,,0.000000e+000,5.599831e+001,5.599559e+001,1,0,1.548387e+000,0.000000e+000,3.608759e-001,3.608759e-001,-1.160171e+000,-1.442995e+000,-2.703930e-001,-1.791440e+000,-2.074264e+000,-3.728395e-005,-3.728395e-005,,,,,,,,,,,,,,,,,,,,
1524261849.218,,0.000000e+000,5.599288e+001,5.599967e+001,1,0,1.677419e+000,0.000000e+000,-1.342794e-001,-1.342794e-001,-1.624421e+000,-1.932874e+000,-7.154183e-001,-2.205560e+000,-2.514013e+000,-5.876036e-005,-5.876036e-005,,,,,,,,,,,,,,,,,,,,
1524261874.738,,0.000000e+000,5.599559e+001,5.599016e+001,1,0,1.806452e+000,0.000000e+000,-6.147860e-001,-6.147860e-001,-2.074544e+000,-2.404250e+000,-1.082582e+000,-2.542341e+000,-2.872046e+000,-7.955995e-005,-7.955995e-005,,,,,,,,,,,,,,,,,,,,
1524261899.488,,0.000000e+000,5.600238e+001,5.600103e+001,1,0,1.935484e+000,0.000000e+000,-1.040818e+000,-1.040818e+000,-2.467172e+000,-2.824485e+000,-1.300537e+000,-2.726891e+000,-3.084204e+000,-9.780548e-005,-9.780548e-005,,,,,,,,,,,,,,,,,,,,
1524261912.018,,0.000000e+000,5.599152e+001,5.599695e+001,1,0,4.000000e+000,0.000000e+000,2.771649e+000,2.771649e+000,1.723113e+000,9.964182e-001,1.979364e+000,9.308288e-001,2.041336e-001,7.830794e-005,7.830794e-005,,,,,,,,,,,,,,,,,,,,