File: Experimental Raw Data/TC04-12-01K VRMac VRMde/raw/TC04-12-01K_VRMac_55K_750s_VRMde_55K.dc.raw
[Header]
TITLE,MPMS DC Measurement
BYAPP,MPMS Measurement,2.1,Raw with ABS
FILEOPENTIME, 1524341592.178000 4/21/2018, 2:13:12 PM

INFO, APPNAME, MPMS MultiVu Application, Revision 1.61,  Build 082

INFO, NAME, TC04-12-01K
INFO, WEIGHT, 1.000
INFO, AREA, 1.000
INFO, LENGTH, 1.000
INFO, SHAPE, 0
INFO, COMMENT,
INFO, SEQUENCE FILE: VRMac_55K_750s_VRMde_55Klinear.seq


INFO, BACKGROUND DATA FILE:, None


STARTUPAXIS,X,8,LINEAR,AUTO,0.000000,0.000000
STARTUPAXIS,Y1,10,LINEAR,AUTO,0.000000,0.000000


STARTUPGROUP,Longitudinal
FIELDGROUP,Longitudinal,1,3,4,5,6,8,9,10,11,12,13,14,15,16,17,18,19,20,21,22,23
FIELDGROUP,Transverse,1,3,4,5,6,8,9,24,25,26,27,28,29,30,31,32,33,34,35,36,37

PLOT_APPEARANCE,ALL,HORZ_GRID_ON,VERT_GRID_ON,MARKERS_ONLY

[Data]
Time,Comment,Field (Oe),Start Temperature (K),End Temperature (K),Scan,Rejected,Position (cm),Rot Position (deg),Long Voltage,Long Average Voltage,Long Detrended Voltage,Long Demeaned Voltage,Long Regression Fit,Long Detrended Fit,Long Demeaned Fit,Long Scaled Response,Long Avg. Scaled Response,Long Background Response,Long Response [w/ABS],Long Detrended Resp. [w/ABS],Long Fit [w/ABS],Long Detrended Fit [w/ABS],Trans Voltage,Trans Average Voltage,Trans Detrended Voltage,Trans Demeaned Voltage,Trans Regression Fit,Trans Detrended Fit,Trans Demeaned Fit,Trans Scaled Response,Trans Avg Scaled Response,Trans Background Response,Trans Response [w/ABS],Trans Detrended Resp. [w/ABS],Trans Fit [w/ABS],Trans Detrended Fit [w/ABS],
1524341592.168,,0.000000e+000,5.500497e+001,5.499577e+001,1,0,0.000000e+000,0.000000e+000,4.480812e+000,4.480812e+000,3.065252e-001,3.065252e-001,4.511614e+000,3.373275e-001,3.373275e-001,8.530827e-006,8.530827e-006,,,,,,,,,,,,,,,,,,,,
1524341604.538,,0.000000e+000,5.500235e+001,5.499445e+001,1,0,1.290323e-001,0.000000e+000,4.457160e+000,4.457160e+000,2.762940e-001,2.786131e-001,4.512970e+000,3.321040e-001,3.344231e-001,7.555733e-006,7.555733e-006,,,,,,,,,,,,,,,,,,,,
1524341617.228,,0.000000e+000,5.499971e+001,5.499182e+001,1,0,2.580645e-001,0.000000e+000,4.437476e+000,4.437476e+000,2.496007e-001,2.547340e-001,4.511134e+000,3.232587e-001,3.283920e-001,6.735485e-006,6.735485e-006,,,,,,,,,,,,,,,,,,,,
1524341629.728,,0.000000e+000,5.499051e+001,5.499971e+001,1,0,3.870968e-001,0.000000e+000,4.434272e+000,4.434272e+000,2.394529e-001,2.473278e-001,4.496387e+000,3.015676e-001,3.094425e-001,6.382281e-006,6.382281e-006,,,,,,,,,,,,,,,,,,,,
1524341642.478,,0.000000e+000,5.499577e+001,5.500103e+001,1,0,5.161290e-001,0.000000e+000,4.447852e+000,4.447852e+000,2.376055e-001,2.493448e-001,4.472594e+000,2.623472e-001,2.740865e-001,6.202637e-006,6.202637e-006,,,,,,,,,,,,,,,,,,,,
1524341654.828,,0.000000e+000,5.499839e+001,5.499314e+001,1,0,6.451613e-001,0.000000e+000,4.443732e+000,4.443732e+000,2.143769e-001,2.283163e-001,4.437261e+000,2.079058e-001,2.218451e-001,5.651091e-006,5.651091e-006,,,,,,,,,,,,,,,,,,,,
1524341667.298,,0.000000e+000,5.499577e+001,5.499577e+001,1,0,7.741935e-001,0.000000e+000,4.395972e+000,4.395972e+000,1.653146e-001,1.821313e-001,4.373409e+000,1.427516e-001,1.595683e-001,4.515270e-006,4.515270e-006,,,,,,,,,,,,,,,,,,,,
1524341679.958,,0.000000e+000,5.499971e+001,5.499839e+001,1,0,9.032258e-001,0.000000e+000,4.371405e+000,4.371405e+000,1.219727e-001,1.441679e-001,4.320338e+000,7.090578e-002,9.310102e-002,3.464404e-006,3.464404e-006,,,,,,,,,,,,,,,,,,,,
1524341692.678,,0.000000e+000,5.499971e+001,5.500761e+001,1,0,1.032258e+000,0.000000e+000,4.306249e+000,4.306249e+000,5.108679e-002,7.103920e-002,4.253889e+000,-1.272790e-003,1.867962e-002,1.932684e-006,1.932684e-006,,,,,,,,,,,,,,,,,,,,
1524341705.308,,0.000000e+000,5.500761e+001,5.500235e+001,1,0,1.161290e+000,0.000000e+000,4.261539e+000,4.261539e+000,5.632577e-003,2.634001e-002,4.184781e+000,-7.112628e-002,-5.041885e-002,9.135110e-007,9.135110e-007,,,,,,,,,,,,,,,,,,,,
1524341717.548,,0.000000e+000,5.500629e+001,5.500103e+001,1,0,1.290323e+000,0.000000e+000,4.189670e+000,4.189670e+000,-6.822430e-002,-3.987598e-002,4.120129e+000,-1.377653e-001,-1.094170e-001,-7.995550e-007,-7.995550e-007,,,,,,,,,,,,,,,,,,,,
1524341729.958,,0.000000e+000,5.500103e+001,5.500235e+001,1,0,1.419355e+000,0.000000e+000,4.148623e+000,4.148623e+000,-1.203093e-001,-9.369993e-002,4.067893e+000,-2.010393e-001,-1.744299e-001,-1.937296e-006,-1.937296e-006,,,,,,,,,,,,,,,,,,,,
1524341742.698,,0.000000e+000,5.497998e+001,5.499839e+001,1,0,1.548387e+000,0.000000e+000,4.121920e+000,4.121920e+000,-1.577619e-001,-1.251011e-001,4.025367e+000,-2.543147e-001,-2.216539e-001,-2.807777e-006,-2.807777e-006,,,,,,,,,,,,,,,,,,,,
1524341755.298,,0.000000e+000,5.499839e+001,5.500235e+001,1,0,1.677419e+000,0.000000e+000,4.066224e+000,4.066224e+000,-2.179455e-001,-1.866212e-001,3.983773e+000,-3.003971e-001,-2.690728e-001,-4.137983e-006,-4.137983e-006,,,,,,,,,,,,,,,,,,,,
1524341767.498,,0.000000e+000,5.499577e+001,5.499577e+001,1,0,1.806452e+000,0.000000e+000,4.035096e+000,4.035096e+000,-2.614435e-001,-2.182903e-001,3.966433e+000,-3.301062e-001,-2.869530e-001,-5.125330e-006,-5.125330e-006,,,,,,,,,,,,,,,,,,,,
1524341779.918,,0.000000e+000,5.501155e+001,5.498788e+001,1,0,1.935484e+000,0.000000e+000,4.031739e+000,4.031739e+000,-3.005139e-001,-2.489753e-001,3.993451e+000,-3.388018e-001,-2.872632e-001,-5.989044e-006,-5.989044e-006,,,,,,,,,,,,,,,,,,,,
1524341792.518,,0.000000e+000,5.498788e+001,5.499971e+001,1,0,2.064516e+000,0.000000e+000,4.034485e+000,4.034485e+000,-3.312913e-001,-2.754483e-001,4.043318e+000,-3.224584e-001,-2.666154e-001,-6.661634e-006,-6.661634e-006,,,,,,,,,,,,,,,,,,,,
1524341805.298,,0.000000e+000,5.499445e+001,5.499971e+001,1,0,2.193548e+000,0.000000e+000,4.078432e+000,4.078432e+000,-3.266239e-001,-2.692723e-001,4.123674e+000,-2.813816e-001,-2.240300e-001,-6.553964e-006,-6.553964e-006,,,,,,,,,,,,,,,,,,,,
1524341817.798,,0.000000e+000,5.499577e+001,5.499314e+001,1,0,2.322581e+000,0.000000e+000,4.113985e+000,4.113985e+000,-3.181744e-001,-2.623005e-001,4.192977e+000,-2.391825e-001,-1.833086e-001,-6.340342e-006,-6.340342e-006,,,,,,,,,,,,,,,,,,,,
1524341830.548,,0.000000e+000,5.499839e+001,5.499314e+001,1,0,2.451613e+000,0.000000e+000,4.170290e+000,4.170290e+000,-2.816719e-001,-2.228327e-001,4.266294e+000,-1.856679e-001,-1.268287e-001,-5.505906e-006,-5.505906e-006,,,,,,,,,,,,,,,,,,,,
1524341843.168,,0.000000e+000,5.499577e+001,5.500892e+001,1,0,2.580645e+000,0.000000e+000,4.231632e+000,4.231632e+000,-2.329335e-001,-1.766005e-001,4.333008e+000,-1.315575e-001,-7.522440e-002,-4.419213e-006,-4.419213e-006,,,,,,,,,,,,,,,,,,,,
1524341855.908,,0.000000e+000,5.499314e+001,5.500497e+001,1,0,2.709677e+000,0.000000e+000,4.296483e+000,4.296483e+000,-1.777376e-001,-1.179981e-001,4.392674e+000,-8.154567e-002,-2.180624e-002,-3.172492e-006,-3.172492e-006,,,,,,,,,,,,,,,,,,,,
1524341868.958,,0.000000e+000,5.500629e+001,5.499839e+001,1,0,2.838710e+000,0.000000e+000,4.341802e+000,4.341802e+000,-1.412800e-001,-7.869101e-002,4.444326e+000,-3.875576e-002,2.383327e-002,-2.331493e-006,-2.331493e-006,,,,,,,,,,,,,,,,,,,,
1524341880.928,,0.000000e+000,5.499839e+001,5.499839e+001,1,0,2.967742e+000,0.000000e+000,4.397955e+000,4.397955e+000,-9.916703e-002,-2.395105e-002,4.496505e+000,-6.176636e-004,7.459831e-002,-1.331908e-006,-1.331908e-006,,,,,,,,,,,,,,,,,,,,
1524341894.198,,0.000000e+000,5.499839e+001,5.499577e+001,1,0,3.096774e+000,0.000000e+000,4.526436e+000,4.526436e+000,-1.573162e-002,7.336855e-002,4.573387e+000,3.121919e-002,1.203194e-001,6.204646e-007,6.204646e-007,,,,,,,,,,,,,,,,,,,,
1524341906.158,,0.000000e+000,5.499577e+001,5.499182e+001,1,0,3.225806e+000,0.000000e+000,4.596475e+000,4.596475e+000,9.836243e-003,9.511375e-002,4.642488e+000,5.584912e-002,1.411266e-001,1.178880e-006,1.178880e-006,,,,,,,,,,,,,,,,,,,,
1524341919.088,,0.000000e+000,5.499182e+001,5.499577e+001,1,0,3.354839e+000,0.000000e+000,4.693217e+000,4.693217e+000,7.578591e-002,1.560802e-001,4.692821e+000,7.538918e-002,1.556835e-001,2.646877e-006,2.646877e-006,,,,,,,,,,,,,,,,,,,,
1524341931.748,,0.000000e+000,5.499577e+001,5.499839e+001,1,0,3.483871e+000,0.000000e+000,4.732585e+000,4.732585e+000,1.072855e-001,1.758814e-001,4.708770e+000,8.347037e-002,1.520662e-001,3.276989e-006,3.276989e-006,,,,,,,,,,,,,,,,,,,,
1524341944.318,,0.000000e+000,5.499839e+001,5.500367e+001,1,0,3.612903e+000,0.000000e+000,4.768597e+000,4.768597e+000,1.375660e-001,2.130604e-001,4.718325e+000,8.729403e-002,1.627884e-001,4.016561e-006,4.016561e-006,,,,,,,,,,,,,,,,,,,,
1524341957.038,,0.000000e+000,5.500367e+001,5.499182e+001,1,0,3.741935e+000,0.000000e+000,4.778973e+000,4.778973e+000,1.282732e-001,2.111874e-001,4.731187e+000,8.048699e-002,1.634011e-001,3.858615e-006,3.858615e-006,,,,,,,,,,,,,,,,,,,,
1524341969.769,,0.000000e+000,5.499839e+001,5.499577e+001,1,0,3.870968e+000,0.000000e+000,4.814221e+000,4.814221e+000,1.479676e-001,2.317524e-001,4.735980e+000,6.972627e-002,1.535110e-001,4.305533e-006,4.305533e-006,,,,,,,,,,,,,,,,,,,,
1524341982.249,,0.000000e+000,5.499577e+001,5.499839e+001,1,0,4.000000e+000,0.000000e+000,4.803388e+000,4.803388e+000,1.309871e-001,2.150011e-001,4.729566e+000,5.716506e-002,1.411791e-001,3.925379e-006,3.925379e-006,,,,,,,,,,,,,,,,,,,,
1524342007.459,,0.000000e+000,5.499445e+001,5.499971e+001,1,0,0.000000e+000,0.000000e+000,4.645152e+000,4.645152e+000,3.042030e-002,3.042030e-002,4.667393e+000,5.266190e-002,5.266190e-002,2.303859e-007,2.303859e-007,,,,,,,,,,,,,,,,,,,,
1524342020.099,,0.000000e+000,5.500103e+001,5.500892e+001,1,0,1.290323e-001,0.000000e+000,4.611429e+000,4.611429e+000,-3.601610e-002,-3.284311e-002,4.705503e+000,5.805720e-002,6.123018e-002,-1.161519e-006,-1.161519e-006,,,,,,,,,,,,,,,,,,,,
1524342032.659,,0.000000e+000,5.499708e+001,5.499708e+001,1,0,2.580645e-001,0.000000e+000,4.659037e+000,4.659037e+000,-1.864215e-002,-1.224852e-002,4.739591e+000,6.191185e-002,6.830549e-002,-7.392082e-007,-7.392082e-007,,,,,,,,,,,,,,,,,,,,
1524342045.419,,0.000000e+000,5.499577e+001,5.500235e+001,1,0,3.870968e-001,0.000000e+000,4.716716e+000,4.716716e+000,1.248069e-002,2.170515e-002,4.764562e+000,6.032605e-002,6.955051e-002,1.021544e-008,1.021544e-008,,,,,,,,,,,,,,,,,,,,
1524342057.849,,0.000000e+000,5.499839e+001,5.498919e+001,1,0,5.161290e-001,0.000000e+000,4.736095e+000,4.736095e+000,1.029481e-002,2.277613e-002,4.780403e+000,5.460205e-002,6.708336e-002,-1.426088e-008,-1.426088e-008,,,,,,,,,,,,,,,,,,,,
1524342070.439,,0.000000e+000,5.498788e+001,5.500367e+001,1,0,6.451613e-001,0.000000e+000,4.787365e+000,4.787365e+000,4.442288e-002,5.954456e-002,4.786530e+000,4.358746e-002,5.870914e-002,7.913914e-007,7.913914e-007,,,,,,,,,,,,,,,,,,,,
1524342083.079,,0.000000e+000,5.499839e+001,5.499839e+001,1,0,7.741935e-001,0.000000e+000,4.840772e+000,4.840772e+000,7.596172e-002,9.333086e-002,4.794723e+000,2.991260e-002,4.728174e-002,1.543085e-006,1.543085e-006,,,,,,,,,,,,,,,,,,,,
1524342095.849,,0.000000e+000,5.499445e+001,5.499971e+001,1,0,9.032258e-001,0.000000e+000,4.852521e+000,4.852521e+000,6.903669e-002,8.940458e-002,4.798479e+000,1.499435e-002,3.536224e-002,1.415538e-006,1.415538e-006,,,,,,,,,,,,,,,,,,,,
1524342108.279,,0.000000e+000,5.499971e+001,5.499314e+001,1,0,1.032258e+000,0.000000e+000,4.874495e+000,4.874495e+000,7.624093e-002,1.017685e-001,4.797963e+000,-2.909601e-004,2.523661e-002,1.591980e-006,1.591980e-006,,,,,,,,,,,,,,,,,,,,
1524342121.059,,0.000000e+000,5.499314e+001,5.499971e+001,1,0,1.161290e+000,0.000000e+000,4.879072e+000,4.879072e+000,5.749732e-002,8.584452e-002,4.805629e+000,-1.594562e-002,1.240158e-002,1.206528e-006,1.206528e-006,,,,,,,,,,,,,,,,,,,,
1524342133.509,,0.000000e+000,5.500103e+001,5.499577e+001,1,0,1.290323e+000,0.000000e+000,4.900130e+000,4.900130e+000,5.777051e-002,8.802509e-002,4.809969e+000,-3.238986e-002,-2.135277e-003,1.268359e-006,1.268359e-006,,,,,,,,,,,,,,,,,,,,
1524342146.279,,0.000000e+000,5.499051e+001,5.499971e+001,1,0,1.419355e+000,0.000000e+000,4.908064e+000,4.908064e+000,4.039410e-002,7.120323e-002,4.823590e+000,-4.408046e-002,-1.327133e-002,9.153446e-007,9.153446e-007,,,,,,,,,,,,,,,,,,,,
1524342158.739,,0.000000e+000,5.499971e+001,5.500103e+001,1,0,1.548387e+000,0.000000e+000,4.934920e+000,4.934920e+000,4.938000e-002,8.127928e-002,4.829305e+000,-5.623562e-002,-2.433634e-002,1.155189e-006,1.155189e-006,,,,,,,,,,,,,,,,,,,,
1524342171.539,,0.000000e+000,5.499314e+001,5.500235e+001,1,0,1.677419e+000,0.000000e+000,4.957199e+000,4.957199e+000,2.657044e-002,6.835318e-002,4.866044e+000,-6.458414e-002,-2.280140e-002,6.510236e-007,6.510236e-007,,,,,,,,,,,,,,,,,,,,
1524342183.989,,0.000000e+000,5.499839e+001,5.499839e+001,1,0,1.806452e+000,0.000000e+000,4.967422e+000,4.967422e+000,-1.314515e-002,3.605938e-002,4.904985e+000,-7.558173e-002,-2.637720e-002,-1.921871e-007,-1.921871e-007,,,,,,,,,,,,,,,,,,,,
1524342196.199,,0.000000e+000,5.499577e+001,5.500103e+001,1,0,1.935484e+000,0.000000e+000,4.975357e+000,4.975357e+000,-4.207564e-002,2.799034e-003,4.945869e+000,-7.156325e-002,-2.668858e-002,-8.036295e-007,-8.036295e-007,,,,,,,,,,,,,,,,,,,,
1524342208.659,,0.000000e+000,5.499839e+001,5.500235e+001,1,0,2.064516e+000,0.000000e+000,4.969253e+000,4.969253e+000,-7.551883e-002,-2.700853e-002,4.979308e+000,-6.546377e-002,-1.695347e-002,-1.519729e-006,-1.519729e-006,,,,,,,,,,,,,,,,,,,,
1524342221.429,,0.000000e+000,5.499708e+001,5.499708e+001,1,0,2.193548e+000,0.000000e+000,4.973068e+000,4.973068e+000,-1.119040e-001,-5.088997e-002,5.024849e+000,-6.012235e-002,8.916855e-004,-2.277520e-006,-2.277520e-006,,,,,,,,,,,,,,,,,,,,
1524342233.809,,0.000000e+000,5.500497e+001,5.499971e+001,1,0,2.322581e+000,0.000000e+000,4.991684e+000,4.991684e+000,-1.205046e-001,-6.418753e-002,5.062898e+000,-4.929039e-002,7.026672e-003,-2.441695e-006,-2.441695e-006,,,,,,,,,,,,,,,,,,,,
1524342246.689,,0.000000e+000,5.499971e+001,5.499708e+001,1,0,2.451613e+000,0.000000e+000,4.994583e+000,4.994583e+000,-1.349540e-001,-7.736444e-002,5.088896e+000,-4.064085e-002,1.694870e-002,-2.720713e-006,-2.720713e-006,,,,,,,,,,,,,,,,,,,,
1524342259.099,,0.000000e+000,5.499577e+001,5.499839e+001,1,0,2.580645e+000,0.000000e+000,5.013351e+000,5.013351e+000,-1.349805e-001,-7.042503e-002,5.121955e+000,-2.637652e-002,3.817892e-002,-2.680492e-006,-2.680492e-006,,,,,,,,,,,,,,,,,,,,
1524342271.859,,0.000000e+000,5.499708e+001,5.499971e+001,1,0,2.709677e+000,0.000000e+000,5.051194e+000,5.051194e+000,-1.185864e-001,-4.994392e-002,5.153806e+000,-1.597435e-002,5.266809e-002,-2.271525e-006,-2.271525e-006,,,,,,,,,,,,,,,,,,,,
1524342284.899,,0.000000e+000,5.499971e+001,5.500103e+001,1,0,2.838710e+000,0.000000e+000,5.086596e+000,5.086596e+000,-1.002214e-001,-3.189898e-002,5.179597e+000,-7.219988e-003,6.110239e-002,-1.836568e-006,-1.836568e-006,,,,,,,,,,,,,,,,,,,,
1524342296.949,,0.000000e+000,5.500103e+001,5.499445e+001,1,0,2.967742e+000,0.000000e+000,5.121996e+000,5.121996e+000,-8.813073e-002,-1.286364e-002,5.210012e+000,-1.142272e-004,7.515287e-002,-1.508073e-006,-1.508073e-006,,,,,,,,,,,,,,,,,,,,
1524342309.539,,0.000000e+000,5.499839e+001,5.499839e+001,1,0,3.096774e+000,0.000000e+000,5.190051e+000,5.190051e+000,-5.185412e-002,2.032518e-002,5.248099e+000,6.194131e-003,7.837343e-002,-6.784685e-007,-6.784685e-007,,,,,,,,,,,,,,,,,,,,
1524342322.159,,0.000000e+000,5.499839e+001,5.499577e+001,1,0,3.225806e+000,0.000000e+000,5.253682e+000,5.253682e+000,-1.921713e-002,6.162119e-002,5.281473e+000,8.574373e-003,8.941269e-002,1.013104e-007,1.013104e-007,,,,,,,,,,,,,,,,,,,,
1524342334.959,,0.000000e+000,5.499577e+001,5.500761e+001,1,0,3.354839e+000,0.000000e+000,5.295491e+000,5.295491e+000,-2.700990e-003,8.206558e-002,5.310166e+000,1.197463e-002,9.674120e-002,5.243637e-007,5.243637e-007,,,,,,,,,,,,,,,,,,,,
1524342347.369,,0.000000e+000,5.500103e+001,5.499971e+001,1,0,3.483871e+000,0.000000e+000,5.362173e+000,5.362173e+000,2.983413e-002,1.185451e-001,5.343735e+000,1.139579e-002,1.001067e-001,1.290377e-006,1.290377e-006,,,,,,,,,,,,,,,,,,,,
1524342360.139,,0.000000e+000,5.499314e+001,5.500497e+001,1,0,3.612903e+000,0.000000e+000,5.398795e+000,5.398795e+000,4.443701e-002,1.291013e-001,5.368122e+000,1.376351e-002,9.842777e-002,1.625653e-006,1.625653e-006,,,,,,,,,,,,,,,,,,,,
1524342372.579,,0.000000e+000,5.500497e+001,5.499839e+001,1,0,3.741935e+000,0.000000e+000,5.461814e+000,5.461814e+000,8.292575e-002,1.716552e-001,5.390115e+000,1.122661e-002,9.995604e-002,2.526940e-006,2.526940e-006,,,,,,,,,,,,,,,,,,,,
1524342385.359,,0.000000e+000,5.499839e+001,5.499577e+001,1,0,3.870968e+000,0.000000e+000,5.502098e+000,5.502098e+000,9.414943e-002,1.900363e-001,5.416422e+000,8.473711e-003,1.043606e-001,2.842804e-006,2.842804e-006,,,,,,,,,,,,,,,,,,,,
1524342397.739,,0.000000e+000,5.499708e+001,5.499051e+001,1,0,4.000000e+000,0.000000e+000,5.517205e+000,5.517205e+000,8.201745e-002,1.838341e-001,5.441884e+000,6.696729e-003,1.085134e-001,2.635177e-006,2.635177e-006,,,,,,,,,,,,,,,,,,,,
1524342423.069,,0.000000e+000,5.499708e+001,5.500235e+001,1,0,0.000000e+000,0.000000e+000,5.362326e+000,5.362326e+000,-1.901293e-002,-1.901293e-002,5.385457e+000,4.117966e-003,4.117966e-003,-1.237233e-006,-1.237233e-006,,,,,,,,,,,,,,,,,,,,
1524342435.849,,0.000000e+000,5.499708e+001,5.499971e+001,1,0,1.290323e-001,0.000000e+000,5.325093e+000,5.325093e+000,-9.413939e-002,-9.107351e-002,5.424534e+000,5.301664e-003,8.367538e-003,-2.736313e-006,-2.736313e-006,,,,,,,,,,,,,,,,,,,,
1524342448.109,,0.000000e+000,5.499708e+001,5.500497e+001,1,0,2.580645e-001,0.000000e+000,5.373312e+000,5.373312e+000,-6.713434e-002,-5.988312e-002,5.442759e+000,2.312697e-003,9.563923e-003,-2.217799e-006,-2.217799e-006,,,,,,,,,,,,,,,,,,,,
1524342460.999,,0.000000e+000,5.500235e+001,5.500103e+001,1,0,3.870968e-001,0.000000e+000,5.431602e+000,5.431602e+000,-4.437872e-002,-3.436804e-002,5.476404e+000,4.239446e-004,1.043463e-002,-1.611159e-006,-1.611159e-006,,,,,,,,,,,,,,,,,,,,
1524342473.189,,0.000000e+000,5.499971e+001,5.499577e+001,1,0,5.161290e-001,0.000000e+000,5.471885e+000,5.471885e+000,-3.792557e-002,-2.485609e-002,5.509996e+000,1.856340e-004,1.325512e-002,-1.406501e-006,-1.406501e-006,,,,,,,,,,,,,,,,,,,,
1524342485.739,,0.000000e+000,5.500235e+001,5.499971e+001,1,0,6.451613e-001,0.000000e+000,5.553979e+000,5.553979e+000,1.310101e-002,2.762365e-002,5.540338e+000,-5.408200e-004,1.398182e-002,-1.649605e-007,-1.649605e-007,,,,,,,,,,,,,,,,,,,,
1524342498.219,,0.000000e+000,5.499971e+001,5.499577e+001,1,0,7.741935e-001,0.000000e+000,5.609369e+000,5.609369e+000,4.759338e-002,6.669998e-002,5.561141e+000,-6.344011e-004,1.847219e-002,6.075425e-007,6.075425e-007,,,,,,,,,,,,,,,,,,,,
1524342510.939,,0.000000e+000,5.499708e+001,5.499708e+001,1,0,9.032258e-001,0.000000e+000,5.639582e+000,5.639582e+000,5.221672e-002,7.461739e-002,5.586621e+000,-7.436776e-004,2.165699e-002,7.497729e-007,7.497729e-007,,,,,,,,,,,,,,,,,,,,
1524342523.419,,0.000000e+000,5.499971e+001,5.499839e+001,1,0,1.032258e+000,0.000000e+000,5.704128e+000,5.704128e+000,8.578329e-002,1.115227e-001,5.618382e+000,3.700145e-005,2.577639e-002,1.526263e-006,1.526263e-006,,,,,,,,,,,,,,,,,,,,
1524342536.199,,0.000000e+000,5.499577e+001,5.500235e+001,1,0,1.161290e+000,0.000000e+000,5.720150e+000,5.720150e+000,7.972047e-002,1.080108e-001,5.642481e+000,2.051327e-003,3.034163e-002,1.448177e-006,1.448177e-006,,,,,,,,,,,,,,,,,,,,
1524342548.639,,0.000000e+000,5.500235e+001,5.499971e+001,1,0,1.290323e+000,0.000000e+000,5.754025e+000,5.754025e+000,8.507074e-002,1.167827e-001,5.672843e+000,3.889698e-003,3.560162e-002,1.614448e-006,1.614448e-006,,,,,,,,,,,,,,,,,,,,
1524342561.419,,0.000000e+000,5.499839e+001,5.500235e+001,1,0,1.419355e+000,0.000000e+000,5.785000e+000,5.785000e+000,8.853751e-002,1.190004e-001,5.702816e+000,6.352721e-003,3.681564e-002,1.764274e-006,1.764274e-006,,,,,,,,,,,,,,,,,,,,
1524342573.849,,0.000000e+000,5.499839e+001,5.499839e+001,1,0,1.548387e+000,0.000000e+000,5.827573e+000,5.827573e+000,1.152419e-001,1.534705e-001,5.723531e+000,1.120036e-002,4.942894e-002,2.371613e-006,2.371613e-006,,,,,,,,,,,,,,,,,,,,
1524342586.629,,0.000000e+000,5.499971e+001,5.500235e+001,1,0,1.677419e+000,0.000000e+000,5.845273e+000,5.845273e+000,1.096299e-001,1.465650e-001,5.751639e+000,1.599531e-002,5.293036e-002,2.300512e-006,2.300512e-006,,,,,,,,,,,,,,,,,,,,
1524342599.049,,0.000000e+000,5.500235e+001,5.499445e+001,1,0,1.806452e+000,0.000000e+000,5.853666e+000,5.853666e+000,8.775207e-002,1.375237e-001,5.787931e+000,2.201769e-002,7.178926e-002,1.829292e-006,1.829292e-006,,,,,,,,,,,,,,,,,,,,
1524342611.849,,0.000000e+000,5.499577e+001,5.499314e+001,1,0,1.935484e+000,0.000000e+000,5.850156e+000,5.850156e+000,4.875931e-002,1.031451e-001,5.825002e+000,2.360519e-002,7.799101e-002,1.010252e-006,1.010252e-006,,,,,,,,,,,,,,,,,,,,
1524342624.239,,0.000000e+000,5.501155e+001,5.500367e+001,1,0,2.064516e+000,0.000000e+000,5.858396e+000,5.858396e+000,9.804521e-003,6.724739e-002,5.875761e+000,2.716902e-002,8.461189e-002,1.854787e-007,1.854787e-007,,,,,,,,,,,,,,,,,,,,
1524342637.059,,0.000000e+000,5.499708e+001,5.499314e+001,1,0,2.193548e+000,0.000000e+000,5.861144e+000,5.861144e+000,-2.930578e-002,2.959490e-002,5.917950e+000,2.750078e-002,8.640146e-002,-6.430782e-007,-6.430782e-007,,,,,,,,,,,,,,,,,,,,
1524342649.449,,0.000000e+000,5.499314e+001,5.500629e+001,1,0,2.322581e+000,0.000000e+000,5.871520e+000,5.871520e+000,-5.676740e-002,7.078171e-003,5.953408e+000,2.512128e-002,8.896685e-002,-1.205422e-006,-1.205422e-006,,,,,,,,,,,,,,,,,,,,
1524342662.329,,0.000000e+000,5.499839e+001,5.500497e+001,1,0,2.451613e+000,0.000000e+000,5.884642e+000,5.884642e+000,-7.603601e-002,-1.458120e-002,5.983851e+000,2.317330e-002,8.462811e-002,-1.609093e-006,-1.609093e-006,,,,,,,,,,,,,,,,,,,,
1524342674.719,,0.000000e+000,5.500367e+001,5.499445e+001,1,0,2.580645e+000,0.000000e+000,5.897765e+000,5.897765e+000,-8.533606e-002,-2.230883e-002,6.001717e+000,1.861634e-002,8.164358e-002,-1.780601e-006,-1.780601e-006,,,,,,,,,,,,,,,,,,,,
1524342687.540,,0.000000e+000,5.499708e+001,5.499708e+001,1,0,2.709677e+000,0.000000e+000,5.917143e+000,5.917143e+000,-8.116434e-002,-1.919556e-002,6.009999e+000,1.169111e-002,7.365990e-002,-1.653389e-006,-1.653389e-006,,,,,,,,,,,,,,,,,,,,
1524342699.970,,0.000000e+000,5.500103e+001,5.500497e+001,1,0,2.838710e+000,0.000000e+000,5.931792e+000,5.931792e+000,-7.999244e-002,-1.255560e-002,6.018132e+000,6.347030e-003,7.378387e-002,-1.581124e-006,-1.581124e-006,,,,,,,,,,,,,,,,,,,,
1524342712.760,,0.000000e+000,5.499708e+001,5.499314e+001,1,0,2.967742e+000,0.000000e+000,5.956359e+000,5.956359e+000,-7.355552e-002,-9.160995e-003,6.030016e+000,1.015156e-004,6.449604e-002,-1.416367e-006,-1.416367e-006,,,,,,,,,,,,,,,,,,,,
1524342725.160,,0.000000e+000,5.499314e+001,5.499971e+001,1,0,3.096774e+000,0.000000e+000,5.987640e+000,5.987640e+000,-6.025826e-002,1.067924e-002,6.041595e+000,-6.303182e-003,6.463432e-002,-1.073699e-006,-1.073699e-006,,,,,,,,,,,,,,,,,,,,
1524342737.950,,0.000000e+000,5.499445e+001,5.500367e+001,1,0,3.225806e+000,0.000000e+000,6.027619e+000,6.027619e+000,-3.877514e-002,3.516722e-002,6.054599e+000,-1.179522e-002,6.214714e-002,-5.485490e-007,-5.485490e-007,,,,,,,,,,,,,,,,,,,,
1524342750.340,,0.000000e+000,5.500497e+001,5.499314e+001,1,0,3.354839e+000,0.000000e+000,6.072785e+000,6.072785e+000,-1.320516e-002,6.537962e-002,6.069745e+000,-1.624547e-002,6.233931e-002,7.648487e-008,7.648487e-008,,,,,,,,,,,,,,,,,,,,
1524342763.200,,0.000000e+000,5.499839e+001,5.500367e+001,1,0,3.483871e+000,0.000000e+000,6.091249e+000,6.091249e+000,-1.163272e-002,6.996346e-002,6.082884e+000,-1.999787e-002,6.159830e-002,1.515145e-007,1.515145e-007,,,,,,,,,,,,,,,,,,,,
1524342775.410,,0.000000e+000,5.500367e+001,5.499708e+001,1,0,3.612903e+000,0.000000e+000,6.156710e+000,6.156710e+000,3.309369e-002,1.228089e-001,6.100615e+000,-2.300144e-002,6.671381e-002,1.220469e-006,1.220469e-006,,,,,,,,,,,,,,,,,,,,
1524342788.110,,0.000000e+000,5.499577e+001,5.499708e+001,1,0,3.741935e+000,0.000000e+000,6.166628e+000,6.166628e+000,2.478812e-002,1.140528e-001,6.119256e+000,-2.258374e-002,6.668091e-002,1.056236e-006,1.056236e-006,,,,,,,,,,,,,,,,,,,,
1524342800.480,,0.000000e+000,5.500103e+001,5.500761e+001,1,0,3.870968e+000,0.000000e+000,6.225986e+000,6.225986e+000,5.475011e-002,1.567850e-001,6.150166e+000,-2.107033e-002,8.096457e-002,1.839071e-006,1.839071e-006,,,,,,,,,,,,,,,,,,,,
1524342813.060,,0.000000e+000,5.500235e+001,5.499577e+001,1,0,4.000000e+000,0.000000e+000,6.241245e+000,6.241245e+000,5.366060e-002,1.466184e-001,6.169348e+000,-1.823691e-002,7.472086e-002,1.773209e-006,1.773209e-006,,,,,,,,,,,,,,,,,,,,
1524342838.330,,0.000000e+000,5.500103e+001,5.499182e+001,1,0,0.000000e+000,0.000000e+000,6.056306e+000,6.056306e+000,-5.462265e-002,-5.462265e-002,6.091117e+000,-1.981163e-002,-1.981163e-002,-2.027198e-006,-2.027198e-006,,,,,,,,,,,,,,,,,,,,
1524342850.890,,0.000000e+000,5.499971e+001,5.499839e+001,1,0,1.290323e-001,0.000000e+000,6.031129e+000,6.031129e+000,-1.003670e-001,-9.742785e-002,6.110030e+000,-2.146621e-002,-1.852703e-002,-2.999848e-006,-2.999848e-006,,,,,,,,,,,,,,,,,,,,
1524342863.580,,0.000000e+000,5.498919e+001,5.499839e+001,1,0,2.580645e-001,0.000000e+000,6.055696e+000,6.055696e+000,-9.100508e-002,-8.544970e-002,6.119520e+000,-2.718043e-002,-2.162504e-002,-2.733432e-006,-2.733432e-006,,,,,,,,,,,,,,,,,,,,
1524342876.210,,0.000000e+000,5.499971e+001,5.499971e+001,1,0,3.870968e-001,0.000000e+000,6.093843e+000,6.093843e+000,-7.494321e-002,-6.633282e-002,6.142985e+000,-2.580132e-002,-1.719093e-002,-2.339511e-006,-2.339511e-006,,,,,,,,,,,,,,,,,,,,
1524342889.000,,0.000000e+000,5.499971e+001,5.500367e+001,1,0,5.161290e-001,0.000000e+000,6.142825e+000,6.142825e+000,-4.413405e-002,-3.172493e-002,6.161109e+000,-2.584973e-002,-1.344061e-002,-1.655426e-006,-1.655426e-006,,,,,,,,,,,,,,,,,,,,
1524342901.630,,0.000000e+000,5.499577e+001,5.499577e+001,1,0,6.451613e-001,0.000000e+000,6.202335e+000,6.202335e+000,-1.085370e-002,5.141735e-003,6.188885e+000,-2.430337e-002,-8.307934e-003,-8.945644e-007,-8.945644e-007,,,,,,,,,,,,,,,,,,,,
1524342913.910,,0.000000e+000,5.499839e+001,5.499708e+001,1,0,7.741935e-001,0.000000e+000,6.252842e+000,6.252842e+000,1.467373e-002,3.185177e-002,6.221190e+000,-1.697777e-002,2.002716e-004,-2.220913e-007,-2.220913e-007,,,,,,,,,,,,,,,,,,,,
1524342926.560,,0.000000e+000,5.499708e+001,5.499839e+001,1,0,9.032258e-001,0.000000e+000,6.301061e+000,6.301061e+000,4.107598e-002,6.020832e-002,6.250491e+000,-9.494027e-003,9.638309e-003,4.192989e-007,4.192989e-007,,,,,,,,,,,,,,,,,,,,
1524342938.980,,0.000000e+000,5.499839e+001,5.499971e+001,1,0,1.032258e+000,0.000000e+000,6.352179e+000,6.352179e+000,7.682627e-002,9.969759e-002,6.275534e+000,1.818500e-004,2.305317e-002,1.244567e-006,1.244567e-006,,,,,,,,,,,,,,,,,,,,
1524342951.830,,0.000000e+000,5.499445e+001,5.499577e+001,1,0,1.161290e+000,0.000000e+000,6.392157e+000,6.392157e+000,9.394460e-002,1.191587e-001,6.308620e+000,1.040798e-002,3.562212e-002,1.680484e-006,1.680484e-006,,,,,,,,,,,,,,,,,,,,
1524342963.970,,0.000000e+000,5.499051e+001,5.499577e+001,1,0,1.290323e+000,0.000000e+000,6.428931e+000,6.428931e+000,1.062402e-001,1.373410e-001,6.344534e+000,2.184339e-002,5.294418e-002,1.967826e-006,1.967826e-006,,,,,,,,,,,,,,,,,,,,
1524342976.470,,0.000000e+000,5.499708e+001,5.499839e+001,1,0,1.419355e+000,0.000000e+000,6.500191e+000,6.500191e+000,1.486764e-001,1.796808e-001,6.387114e+000,3.559923e-002,6.660366e-002,2.972112e-006,2.972112e-006,,,,,,,,,,,,,,,,,,,,
1524342988.860,,0.000000e+000,5.499839e+001,5.500367e+001,1,0,1.548387e+000,0.000000e+000,6.537270e+000,6.537270e+000,1.627932e-001,1.998415e-001,6.425989e+000,5.151230e-002,8.856058e-002,3.303197e-006,3.303197e-006,,,,,,,,,,,,,,,,,,,,
1524343001.720,,0.000000e+000,5.499971e+001,5.499314e+001,1,0,1.677419e+000,0.000000e+000,6.550851e+000,6.550851e+000,1.574532e-001,1.961679e-001,6.456249e+000,6.285156e-002,1.015663e-001,3.235938e-006,3.235938e-006,,,,,,,,,,,,,,,,,,,,
1524343014.380,,0.000000e+000,5.499839e+001,5.499839e+001,1,0,1.806452e+000,0.000000e+000,6.543221e+000,6.543221e+000,1.341337e-001,1.786876e-001,6.481724e+000,7.263697e-002,1.171908e-001,2.753630e-006,2.753630e-006,,,,,,,,,,,,,,,,,,,,
1524343027.080,,0.000000e+000,5.499839e+001,5.499445e+001,1,0,1.935484e+000,0.000000e+000,6.520791e+000,6.520791e+000,8.782079e-002,1.400328e-001,6.513001e+000,8.003166e-002,1.322436e-001,1.758948e-006,1.758948e-006,,,,,,,,,,,,,,,,,,,,
1524343040.180,,0.000000e+000,5.499314e+001,5.499971e+001,1,0,2.064516e+000,0.000000e+000,6.518197e+000,6.518197e+000,4.969658e-002,1.041055e-001,6.540164e+000,7.166447e-002,1.260734e-001,9.767537e-007,9.767537e-007,,,,,,,,,,,,,,,,,,,,
1524343052.100,,0.000000e+000,5.499971e+001,5.499839e+001,1,0,2.193548e+000,0.000000e+000,6.522011e+000,6.522011e+000,2.415965e-002,8.027411e-002,6.576367e+000,7.851528e-002,1.346297e-001,4.266331e-007,4.266331e-007,,,,,,,,,,,,,,,,,,,,
1524343065.060,,0.000000e+000,5.499839e+001,5.499182e+001,1,0,2.322581e+000,0.000000e+000,6.521554e+000,6.521554e+000,-2.195556e-003,5.338478e-002,6.590258e+000,6.650857e-002,1.220889e-001,-1.162407e-007,-1.162407e-007,,,,,,,,,,,,,,,,,,,,
1524343077.640,,0.000000e+000,5.499182e+001,5.499182e+001,1,0,2.451613e+000,0.000000e+000,6.516060e+000,6.516060e+000,-3.441655e-002,2.310658e-002,6.606902e+000,5.642522e-002,1.139483e-001,-8.021307e-007,-8.021307e-007,,,,,,,,,,,,,,,,,,,,
1524343090.080,,0.000000e+000,5.499182e+001,5.499839e+001,1,0,2.580645e+000,0.000000e+000,6.495156e+000,6.495156e+000,-7.096672e-002,-1.132107e-002,6.608648e+000,4.252576e-002,1.021714e-001,-1.579494e-006,-1.579494e-006,,,,,,,,,,,,,,,,,,,,
1524343102.430,,0.000000e+000,5.499839e+001,5.499971e+001,1,0,2.709677e+000,0.000000e+000,6.491341e+000,6.491341e+000,-8.912338e-002,-2.739096e-002,6.608942e+000,2.847706e-002,9.020948e-002,-1.948880e-006,-1.948880e-006,,,,,,,,,,,,,,,,,,,,
1524343115.270,,0.000000e+000,5.499971e+001,5.500235e+001,1,0,2.838710e+000,0.000000e+000,6.517891e+000,6.517891e+000,-8.361813e-002,-2.062035e-002,6.615130e+000,1.362089e-002,7.661867e-002,-1.785054e-006,-1.785054e-006,,,,,,,,,,,,,,,,,,,,
1524343127.420,,0.000000e+000,5.500235e+001,5.499577e+001,1,0,2.967742e+000,0.000000e+000,6.534218e+000,6.534218e+000,-8.841936e-002,-2.211380e-002,6.622873e+000,2.351545e-004,6.654072e-002,-1.851469e-006,-1.851469e-006,,,,,,,,,,,,,,,,,,,,
1524343139.850,,0.000000e+000,5.499577e+001,5.499971e+001,1,0,3.096774e+000,0.000000e+000,6.565804e+000,6.565804e+000,-8.528511e-002,-5.836487e-003,6.639020e+000,-1.206915e-002,6.737947e-002,-1.680892e-006,-1.680892e-006,,,,,,,,,,,,,,,,,,,,
1524343152.650,,0.000000e+000,5.499314e+001,5.500235e+001,1,0,3.225806e+000,0.000000e+000,6.606393e+000,6.606393e+000,-7.134161e-002,5.279064e-003,6.653927e+000,-2.380810e-002,5.281258e-002,-1.363660e-006,-1.363660e-006,,,,,,,,,,,,,,,,,,,,
1524343165.120,,0.000000e+000,5.499708e+001,5.499577e+001,1,0,3.354839e+000,0.000000e+000,6.673076e+000,6.673076e+000,-3.884220e-002,4.498816e-002,6.679160e+000,-3.275776e-002,5.107260e-002,-5.679321e-007,-5.679321e-007,,,,,,,,,,,,,,,,,,,,
1524343177.850,,0.000000e+000,5.500103e+001,5.500235e+001,1,0,3.483871e+000,0.000000e+000,6.716106e+000,6.716106e+000,-1.334760e-002,6.768370e-002,6.689175e+000,-4.027841e-002,4.075289e-002,1.688022e-009,1.688022e-009,,,,,,,,,,,,,,,,,,,,
1524343190.980,,0.000000e+000,5.500235e+001,5.499182e+001,1,0,3.612903e+000,0.000000e+000,6.761425e+000,6.761425e+000,7.655852e-003,8.941507e-002,6.713283e+000,-4.048610e-002,4.127312e-002,5.110051e-007,5.110051e-007,,,,,,,,,,,,,,,,,,,,
1524343203.290,,0.000000e+000,5.499182e+001,5.499839e+001,1,0,3.741935e+000,0.000000e+000,6.811018e+000,6.811018e+000,3.725507e-002,1.270156e-001,6.730349e+000,-4.341386e-002,4.634666e-002,1.230568e-006,1.230568e-006,,,,,,,,,,,,,,,,,,,,
1524343215.880,,0.000000e+000,5.499839e+001,5.500103e+001,1,0,3.870968e+000,0.000000e+000,6.849012e+000,6.849012e+000,3.939641e-002,1.383038e-001,6.775207e+000,-3.440892e-002,6.449842e-002,1.397944e-006,1.397944e-006,,,,,,,,,,,,,,,,,,,,
1524343228.080,,0.000000e+000,5.500103e+001,5.499708e+001,1,0,4.000000e+000,0.000000e+000,6.868086e+000,6.868086e+000,5.112524e-002,1.415677e-001,6.784972e+000,-3.198890e-002,5.845356e-002,1.608278e-006,1.608278e-006,,,,,,,,,,,,,,,,,,,,
1524343252.800,,0.000000e+000,5.500103e+001,5.500367e+001,1,0,0.000000e+000,0.000000e+000,6.666209e+000,6.666209e+000,-9.271288e-002,-9.271288e-002,6.724414e+000,-3.450775e-002,-3.450775e-002,-3.020687e-006,-3.020687e-006,,,,,,,,,,,,,,,,,,,,
1524343265.470,,0.000000e+000,5.499314e+001,5.499445e+001,1,0,1.290323e-001,0.000000e+000,6.648662e+000,6.648662e+000,-1.416918e-001,-1.379414e-001,6.750247e+000,-4.010685e-002,-3.635645e-002,-4.204310e-006,-4.204310e-006,,,,,,,,,,,,,,,,,,,,
1524343278.200,,0.000000e+000,5.500103e+001,5.499182e+001,1,0,2.580645e-001,0.000000e+000,6.722820e+000,6.722820e+000,-1.146134e-001,-1.079464e-001,6.796116e+000,-4.131684e-002,-3.464985e-002,-3.445952e-006,-3.445952e-006,,,,,,,,,,,,,,,,,,,,
1524343291.260,,0.000000e+000,5.500761e+001,5.499182e+001,1,0,3.870968e-001,0.000000e+000,6.784924e+000,6.784924e+000,-8.880612e-002,-7.879162e-002,6.831032e+000,-4.269835e-002,-3.268385e-002,-2.821704e-006,-2.821704e-006,,,,,,,,,,,,,,,,,,,,
1524343303.360,,0.000000e+000,5.499182e+001,5.499708e+001,1,0,5.161290e-001,0.000000e+000,6.840162e+000,6.840162e+000,-6.391086e-002,-5.316925e-002,6.860827e+000,-4.324569e-002,-3.250408e-002,-2.118468e-006,-2.118468e-006,,,,,,,,,,,,,,,,,,,,
1524343316.060,,0.000000e+000,5.499708e+001,5.499708e+001,1,0,6.451613e-001,0.000000e+000,6.881971e+000,6.881971e+000,-4.328971e-002,-2.885532e-002,6.890249e+000,-3.501230e-002,-2.057791e-002,-1.637352e-006,-1.637352e-006,,,,,,,,,,,,,,,,,,,,
1524343328.600,,0.000000e+000,5.499708e+001,5.499971e+001,1,0,7.741935e-001,0.000000e+000,6.930495e+000,6.930495e+000,-1.632301e-002,-1.227856e-003,6.919051e+000,-2.776710e-002,-1.267195e-002,-9.577197e-007,-9.577197e-007,,,,,,,,,,,,,,,,,,,,
1524343341.200,,0.000000e+000,5.499708e+001,5.500103e+001,1,0,9.032258e-001,0.000000e+000,7.002975e+000,7.002975e+000,4.250663e-002,5.959749e-002,6.946031e+000,-1.443822e-002,2.652645e-003,4.086760e-007,4.086760e-007,,,,,,,,,,,,,,,,,,,,
1524343353.570,,0.000000e+000,5.498919e+001,5.499708e+001,1,0,1.032258e+000,0.000000e+000,7.044175e+000,7.044175e+000,7.445362e-002,9.459305e-002,6.969995e+000,2.744496e-004,2.041388e-002,1.152192e-006,1.152192e-006,,,,,,,,,,,,,,,,,,,,
1524343365.880,,0.000000e+000,5.499971e+001,5.500235e+001,1,0,1.161290e+000,0.000000e+000,7.087968e+000,7.087968e+000,1.079629e-001,1.335187e-001,6.996678e+000,1.667292e-002,4.222870e-002,1.901091e-006,1.901091e-006,,,,,,,,,,,,,,,,,,,,
1524343378.480,,0.000000e+000,5.500235e+001,5.499182e+001,1,0,1.290323e+000,0.000000e+000,7.137255e+000,7.137255e+000,1.421231e-001,1.701784e-001,7.031055e+000,3.592293e-002,6.397820e-002,2.696819e-006,2.696819e-006,,,,,,,,,,,,,,,,,,,,
1524343391.090,,0.000000e+000,5.499182e+001,5.499839e+001,1,0,1.419355e+000,0.000000e+000,7.186542e+000,7.186542e+000,1.720859e-001,2.076669e-001,7.065874e+000,5.141840e-002,8.699942e-002,3.395515e-006,3.395515e-006,,,,,,,,,,,,,,,,,,,,
1524343403.851,,0.000000e+000,5.499445e+001,5.499577e+001,1,0,1.548387e+000,0.000000e+000,7.220417e+000,7.220417e+000,1.805307e-001,2.187190e-001,7.110084e+000,7.019819e-002,1.083865e-001,3.631430e-006,3.631430e-006,,,,,,,,,,,,,,,,,,,,
1524343416.781,,0.000000e+000,5.499051e+001,5.499839e+001,1,0,1.677419e+000,0.000000e+000,7.250782e+000,7.250782e+000,1.851989e-001,2.250938e-001,7.152288e+000,8.670484e-002,1.265998e-001,3.787369e-006,3.787369e-006,,,,,,,,,,,,,,,,,,,,
1524343428.881,,0.000000e+000,5.499839e+001,5.499839e+001,1,0,1.806452e+000,0.000000e+000,7.241779e+000,7.241779e+000,1.573566e-001,2.037048e-001,7.184456e+000,1.000336e-001,1.463819e-001,3.204477e-006,3.204477e-006,,,,,,,,,,,,,,,,,,,,
1524343441.511,,0.000000e+000,5.499839e+001,5.499839e+001,1,0,1.935484e+000,0.000000e+000,7.231708e+000,7.231708e+000,1.119442e-001,1.610622e-001,7.228263e+000,1.084995e-001,1.576176e-001,2.236397e-006,2.236397e-006,,,,,,,,,,,,,,,,,,,,
1524343454.261,,0.000000e+000,5.499577e+001,5.500103e+001,1,0,2.064516e+000,0.000000e+000,7.215229e+000,7.215229e+000,7.325536e-002,1.175642e-001,7.255515e+000,1.135414e-001,1.578503e-001,1.405599e-006,1.405599e-006,,,,,,,,,,,,,,,,,,,,
1524343466.681,,0.000000e+000,5.499182e+001,5.499971e+001,1,0,2.193548e+000,0.000000e+000,7.184100e+000,7.184100e+000,2.508468e-002,7.189465e-002,7.264890e+000,1.058742e-001,1.526842e-001,3.698806e-007,3.698806e-007,,,,,,,,,,,,,,,,,,,,
1524343479.311,,0.000000e+000,5.499577e+001,5.499708e+001,1,0,2.322581e+000,0.000000e+000,7.191119e+000,7.191119e+000,1.106231e-002,6.265879e-002,7.276770e+000,9.671323e-002,1.483097e-001,8.911593e-008,8.911593e-008,,,,,,,,,,,,,,,,,,,,
1524343492.421,,0.000000e+000,5.499708e+001,5.500103e+001,1,0,2.451613e+000,0.000000e+000,7.190661e+000,7.190661e+000,-1.605429e-002,4.287958e-002,7.282880e+000,7.616411e-002,1.350980e-001,-4.546600e-007,-4.546600e-007,,,,,,,,,,,,,,,,,,,,
1524343504.531,,0.000000e+000,5.500103e+001,5.499182e+001,1,0,2.580645e+000,0.000000e+000,7.181964e+000,7.181964e+000,-4.216760e-002,1.628828e-002,7.281769e+000,5.763727e-002,1.160932e-001,-1.008360e-006,-1.008360e-006,,,,,,,,,,,,,,,,,,,,
1524343517.621,,0.000000e+000,5.499708e+001,5.499971e+001,1,0,2.709677e+000,0.000000e+000,7.185473e+000,7.185473e+000,-6.176818e-002,-1.061440e-003,7.285017e+000,3.777587e-002,9.848261e-002,-1.406239e-006,-1.406239e-006,,,,,,,,,,,,,,,,,,,,
1524343529.741,,0.000000e+000,5.499971e+001,5.500103e+001,1,0,2.838710e+000,0.000000e+000,7.199969e+000,7.199969e+000,-7.532214e-002,-1.717091e-003,7.293541e+000,1.824999e-002,9.185505e-002,-1.618668e-006,-1.618668e-006,,,,,,,,,,,,,,,,,,,,
1524343542.331,,0.000000e+000,5.500103e+001,5.499708e+001,1,0,2.967742e+000,0.000000e+000,7.230487e+000,7.230487e+000,-9.779498e-002,-1.544285e-002,7.328588e+000,3.056843e-004,8.265781e-002,-2.042449e-006,-2.042449e-006,,,,,,,,,,,,,,,,,,,,
1524343554.951,,0.000000e+000,5.499839e+001,5.499314e+001,1,0,3.096774e+000,0.000000e+000,7.275960e+000,7.275960e+000,-9.149188e-002,-1.669121e-002,7.350968e+000,-1.648396e-002,5.831671e-002,-1.915148e-006,-1.915148e-006,,,,,,,,,,,,,,,,,,,,
1524343568.041,,0.000000e+000,5.499839e+001,5.500103e+001,1,0,3.225806e+000,0.000000e+000,7.340047e+000,7.340047e+000,-6.162351e-002,2.277660e-002,7.372315e+000,-2.935546e-002,5.504465e-002,-1.149660e-006,-1.149660e-006,,,,,,,,,,,,,,,,,,,,
1524343580.291,,0.000000e+000,5.500103e+001,5.499314e+001,1,0,3.354839e+000,0.000000e+000,7.371023e+000,7.371023e+000,-4.497892e-002,2.908611e-002,7.374046e+000,-4.195625e-002,3.210878e-002,-8.211937e-007,-8.211937e-007,,,,,,,,,,,,,,,,,,,,
1524343592.951,,0.000000e+000,5.499314e+001,5.499839e+001,1,0,3.483871e+000,0.000000e+000,7.420004e+000,7.420004e+000,-1.951881e-002,6.406689e-002,7.393893e+000,-4.562994e-002,3.795576e-002,-1.484295e-007,-1.484295e-007,,,,,,,,,,,,,,,,,,,,
1524343605.541,,0.000000e+000,5.499839e+001,5.499577e+001,1,0,3.612903e+000,0.000000e+000,7.455558e+000,7.455558e+000,9.491029e-003,8.908081e-002,7.394252e+000,-5.181545e-002,2.777433e-002,4.805042e-007,4.805042e-007,,,,,,,,,,,,,,,,,,,,
1524343618.781,,0.000000e+000,5.499577e+001,5.499839e+001,1,0,3.741935e+000,0.000000e+000,7.458610e+000,7.458610e+000,-4.211853e-003,7.990265e-002,7.412823e+000,-4.999871e-002,3.411579e-002,2.304732e-007,2.304732e-007,,,,,,,,,,,,,,,,,,,,
1524343631.421,,0.000000e+000,5.499708e+001,5.500367e+001,1,0,3.870968e+000,0.000000e+000,7.490044e+000,7.490044e+000,1.934296e-002,1.045089e-001,7.424674e+000,-4.602712e-002,3.913879e-002,7.848721e-007,7.848721e-007,,,,,,,,,,,,,,,,,,,,
1524343644.151,,0.000000e+000,5.499314e+001,5.499708e+001,1,0,4.000000e+000,0.000000e+000,7.713436e+000,7.713436e+000,3.458538e-002,1.011705e-001,7.635267e+000,-4.358349e-002,2.300167e-002,9.854848e-007,9.854848e-007,,,,,,,,,,,,,,,,,,,,
1524343669.541,,0.000000e+000,5.499839e+001,5.499708e+001,1,0,0.000000e+000,0.000000e+000,7.565576e+000,7.565576e+000,-7.561827e-002,-7.561827e-002,7.596624e+000,-4.456949e-002,-4.456949e-002,-2.730376e-006,-2.730376e-006,,,,,,,,,,,,,,,,,,,,
1524343682.151,,0.000000e+000,5.500103e+001,5.499314e+001,1,0,1.290323e-001,0.000000e+000,7.339437e+000,7.339437e+000,-1.253762e-001,-1.222281e-001,7.417928e+000,-4.688495e-002,-4.373693e-002,-3.747933e-006,-3.747933e-006,,,,,,,,,,,,,,,,,,,,
1524343694.761,,0.000000e+000,5.499839e+001,5.499839e+001,1,0,2.580645e-001,0.000000e+000,7.378500e+000,7.378500e+000,-1.203571e-001,-1.148677e-001,7.445180e+000,-5.367671e-002,-4.818726e-002,-3.519934e-006,-3.519934e-006,,,,,,,,,,,,,,,,,,,,
1524343707.501,,0.000000e+000,5.501024e+001,5.499708e+001,1,0,3.870968e-001,0.000000e+000,7.429313e+000,7.429313e+000,-9.979673e-002,-9.194517e-002,7.474016e+000,-5.509372e-002,-4.724216e-002,-2.995424e-006,-2.995424e-006,,,,,,,,,,,,,,,,,,,,
1524343720.161,,0.000000e+000,5.499708e+001,5.499577e+001,1,0,5.161290e-001,0.000000e+000,7.484245e+000,7.484245e+000,-6.707813e-002,-5.714321e-002,7.497030e+000,-5.429269e-002,-4.435778e-002,-2.213463e-006,-2.213463e-006,,,,,,,,,,,,,,,,,,,,
1524343732.711,,0.000000e+000,5.499051e+001,5.499577e+001,1,0,6.451613e-001,0.000000e+000,7.511406e+000,7.511406e+000,-5.714560e-002,-4.486036e-002,7.523969e+000,-4.458237e-002,-3.229713e-002,-1.939450e-006,-1.939450e-006,,,,,,,,,,,,,,,,,,,,
1524343745.371,,0.000000e+000,5.499577e+001,5.500235e+001,1,0,7.741935e-001,0.000000e+000,7.583429e+000,7.583429e+000,-5.788461e-003,8.949280e-003,7.554429e+000,-3.478922e-002,-2.005148e-002,-7.736380e-007,-7.736380e-007,,,,,,,,,,,,,,,,,,,,
1524343757.931,,0.000000e+000,5.500235e+001,5.500103e+001,1,0,9.032258e-001,0.000000e+000,7.647059e+000,7.647059e+000,3.997437e-002,5.669975e-002,7.588821e+000,-1.826366e-002,-1.538277e-003,2.972956e-007,2.972956e-007,,,,,,,,,,,,,,,,,,,,
1524343770.611,,0.000000e+000,5.500103e+001,5.499445e+001,1,0,1.032258e+000,0.000000e+000,7.701838e+000,7.701838e+000,7.750868e-002,9.833193e-002,7.624680e+000,3.502294e-004,2.117348e-002,1.146924e-006,1.146924e-006,,,,,,,,,,,,,,,,,,,,
1524343783.141,,0.000000e+000,5.498656e+001,5.499577e+001,1,0,1.161290e+000,0.000000e+000,7.755246e+000,7.755246e+000,1.131684e-001,1.382256e-001,7.662982e+000,2.090473e-002,4.596186e-002,1.962675e-006,1.962675e-006,,,,,,,,,,,,,,,,,,,,
1524343795.711,,0.000000e+000,5.499577e+001,5.499051e+001,1,0,1.290323e+000,0.000000e+000,7.810178e+000,7.810178e+000,1.510608e-001,1.817451e-001,7.702387e+000,4.327036e-002,7.395458e-002,2.823974e-006,2.823974e-006,,,,,,,,,,,,,,,,,,,,
1524343808.151,,0.000000e+000,5.499051e+001,5.499445e+001,1,0,1.419355e+000,0.000000e+000,7.859464e+000,7.859464e+000,1.801021e-001,2.117357e-001,7.744821e+000,6.545904e-002,9.709263e-002,3.534922e-006,3.534922e-006,,,,,,,,,,,,,,,,,,,,
1524343820.501,,0.000000e+000,5.499314e+001,5.499708e+001,1,0,1.548387e+000,0.000000e+000,7.880522e+000,7.880522e+000,1.862387e-001,2.211857e-001,7.785320e+000,9.103720e-002,1.259842e-001,3.702648e-006,3.702648e-006,,,,,,,,,,,,,,,,,,,,
1524343833.341,,0.000000e+000,5.499708e+001,5.500497e+001,1,0,1.677419e+000,0.000000e+000,8.120241e+000,8.120241e+000,1.857051e-001,2.165022e-001,8.045364e+000,1.108283e-001,1.416254e-001,3.758614e-006,3.758614e-006,,,,,,,,,,,,,,,,,,,,
1524343845.471,,0.000000e+000,5.500497e+001,5.500367e+001,1,0,1.806452e+000,0.000000e+000,7.892577e+000,7.892577e+000,1.650489e-001,2.123094e-001,7.857904e+000,1.303762e-001,1.776366e-001,3.302644e-006,3.302644e-006,,,,,,,,,,,,,,,,,,,,
1524343858.231,,0.000000e+000,5.499971e+001,5.499445e+001,1,0,1.935484e+000,0.000000e+000,7.897765e+000,7.897765e+000,1.395488e-001,1.856761e-001,7.895908e+000,1.376915e-001,1.838188e-001,2.789922e-006,2.789922e-006,,,,,,,,,,,,,,,,,,,,
1524343871.431,,0.000000e+000,5.499445e+001,5.499314e+001,1,0,2.064516e+000,0.000000e+000,7.897307e+000,7.897307e+000,1.154056e-001,1.630983e-001,7.923230e+000,1.413279e-001,1.890206e-001,2.287386e-006,2.287386e-006,,,,,,,,,,,,,,,,,,,,
1524343884.571,,0.000000e+000,5.499314e+001,5.498919e+001,1,0,2.193548e+000,0.000000e+000,7.885405e+000,7.885405e+000,7.459605e-002,1.282444e-001,7.946674e+000,1.358658e-001,1.895142e-001,1.413951e-006,1.413951e-006,,,,,,,,,,,,,,,,,,,,
1524343896.931,,0.000000e+000,5.499708e+001,5.499971e+001,1,0,2.322581e+000,0.000000e+000,7.845121e+000,7.845121e+000,1.489662e-002,6.763172e-002,7.947840e+000,1.176159e-001,1.703510e-001,1.199078e-007,1.199078e-007,,,,,,,,,,,,,,,,,,,,
1524343909.271,,0.000000e+000,5.499577e+001,5.500761e+001,1,0,2.451613e+000,0.000000e+000,8.060884e+000,8.060884e+000,-4.259268e-003,4.304218e-002,8.157162e+000,9.201892e-002,1.393204e-001,-2.766028e-007,-2.766028e-007,,,,,,,,,,,,,,,,,,,,
1524343922.171,,0.000000e+000,5.500761e+001,5.500497e+001,1,0,2.580645e+000,0.000000e+000,7.825894e+000,7.825894e+000,-3.951403e-002,3.072500e-002,7.932578e+000,6.716922e-002,1.374083e-001,-9.529176e-007,-9.529176e-007,,,,,,,,,,,,,,,,,,,,
1524343934.261,,0.000000e+000,5.500497e+001,5.499708e+001,1,0,2.709677e+000,0.000000e+000,7.839323e+000,7.839323e+000,-5.128382e-002,9.789944e-003,7.936782e+000,4.617549e-002,1.072493e-001,-1.228735e-006,-1.228735e-006,,,,,,,,,,,,,,,,,,,,
1524343946.891,,0.000000e+000,5.500761e+001,5.499971e+001,1,0,2.838710e+000,0.000000e+000,7.843900e+000,7.843900e+000,-7.156968e-002,-7.932186e-003,7.937121e+000,2.165103e-002,8.528852e-002,-1.627050e-006,-1.627050e-006,,,,,,,,,,,,,,,,,,,,
1524343959.631,,0.000000e+000,5.499708e+001,5.499051e+001,1,0,2.967742e+000,0.000000e+000,7.857786e+000,7.857786e+000,-7.356118e-002,-1.398277e-002,7.931726e+000,3.795698e-004,5.995798e-002,-1.673325e-006,-1.673325e-006,,,,,,,,,,,,,,,,,,,,
1524343972.571,,0.000000e+000,5.499051e+001,5.499708e+001,1,0,3.096774e+000,0.000000e+000,7.871672e+000,7.871672e+000,-7.931919e-002,-1.258278e-002,7.931723e+000,-1.926823e-002,4.746819e-002,-1.730339e-006,-1.730339e-006,,,,,,,,,,,,,,,,,,,,
1524343984.691,,0.000000e+000,5.499708e+001,5.499314e+001,1,0,3.225806e+000,0.000000e+000,7.883421e+000,7.883421e+000,-8.613826e-002,-1.581907e-002,7.933307e+000,-3.625251e-002,3.406668e-002,-1.836219e-006,-1.836219e-006,,,,,,,,,,,,,,,,,,,,
1524343997.811,,0.000000e+000,5.499839e+001,5.500235e+001,1,0,3.354839e+000,0.000000e+000,7.943694e+000,7.943694e+000,-5.624916e-002,2.948093e-002,7.949978e+000,-4.996493e-002,3.576517e-002,-1.052715e-006,-1.052715e-006,,,,,,,,,,,,,,,,,,,,
1524344009.911,,0.000000e+000,5.500235e+001,5.500497e+001,1,0,3.483871e+000,0.000000e+000,7.981994e+000,7.981994e+000,-3.865877e-002,4.015541e-002,7.960735e+000,-5.991760e-002,1.889658e-002,-6.824848e-007,-6.824848e-007,,,,,,,,,,,,,,,,,,,,
1524344022.541,,0.000000e+000,5.499839e+001,5.499839e+001,1,0,3.612903e+000,0.000000e+000,8.041657e+000,8.041657e+000,-1.541796e-002,7.721090e-002,7.994514e+000,-6.256095e-002,3.006792e-002,-4.365575e-008,-4.365575e-008,,,,,,,,,,,,,,,,,,,,
1524344034.911,,0.000000e+000,5.499839e+001,5.500103e+001,1,0,3.741935e+000,0.000000e+000,8.077363e+000,8.077363e+000,1.514551e-003,8.950090e-002,8.012735e+000,-6.311309e-002,2.487326e-002,3.174355e-007,3.174355e-007,,,,,,,,,,,,,,,,,,,,
1524344046.921,,0.000000e+000,5.499314e+001,5.499708e+001,1,0,3.870968e+000,0.000000e+000,8.117800e+000,8.117800e+000,1.511629e-002,1.145906e-001,8.045937e+000,-5.674688e-002,4.272747e-002,7.326598e-007,7.326598e-007,,,,,,,,,,,,,,,,,,,,
1524344059.801,,0.000000e+000,5.500103e+001,5.500497e+001,1,0,4.000000e+000,0.000000e+000,-6.626078e+000,-6.626078e+000,2.319346e-002,1.206474e-001,-6.699581e+000,-5.031003e-002,4.714394e-002,9.169744e-007,9.169744e-007,,,,,,,,,,,,,,,,,,,,
1524344085.161,,0.000000e+000,5.499708e+001,5.499445e+001,1,0,0.000000e+000,0.000000e+000,7.990997e+000,7.990997e+000,-8.722401e-002,-8.722401e-002,8.028358e+000,-4.986382e-002,-4.986382e-002,-2.973509e-006,-2.973509e-006,,,,,,,,,,,,,,,,,,,,
1524344098.101,,0.000000e+000,5.499445e+001,5.500103e+001,1,0,1.290323e-001,0.000000e+000,7.965362e+000,7.965362e+000,-1.421043e-001,-1.395192e-001,8.051085e+000,-5.638183e-002,-5.379677e-002,-4.053989e-006,-4.053989e-006,,,,,,,,,,,,,,,,,,,,
1524344110.662,,0.000000e+000,5.500103e+001,5.499445e+001,1,0,2.580645e-001,0.000000e+000,7.986115e+000,7.986115e+000,-1.353061e-001,-1.295748e-001,8.054824e+000,-6.659677e-002,-6.086540e-002,-3.945228e-006,-3.945228e-006,,,,,,,,,,,,,,,,,,,,
1524344123.932,,0.000000e+000,5.499445e+001,5.500235e+001,1,0,3.870968e-001,0.000000e+000,8.020447e+000,8.020447e+000,-1.210989e-001,-1.130342e-001,8.073326e+000,-6.821958e-002,-6.015491e-002,-3.550900e-006,-3.550900e-006,,,,,,,,,,,,,,,,,,,,
1524344136.512,,0.000000e+000,5.500235e+001,5.499577e+001,1,0,5.161290e-001,0.000000e+000,8.080415e+000,8.080415e+000,-8.352855e-002,-7.167149e-002,8.100768e+000,-6.317523e-002,-5.131817e-002,-2.710731e-006,-2.710731e-006,,,,,,,,,,,,,,,,,,,,
1524344149.132,,0.000000e+000,5.499577e+001,5.499182e+001,1,0,6.451613e-001,0.000000e+000,8.141909e+000,8.141909e+000,-4.928683e-002,-3.614140e-002,8.136144e+000,-5.505179e-002,-4.190636e-002,-1.856068e-006,-1.856068e-006,,,,,,,,,,,,,,,,,,,,
1524344161.792,,0.000000e+000,5.499182e+001,5.499971e+001,1,0,7.741935e-001,0.000000e+000,8.206302e+000,8.206302e+000,1.405563e-003,1.837349e-002,8.164702e+000,-4.019371e-002,-2.322578e-002,-7.116178e-007,-7.116178e-007,,,,,,,,,,,,,,,,,,,,
1524344174.492,,0.000000e+000,5.499971e+001,5.500497e+001,1,0,9.032258e-001,0.000000e+000,8.259251e+000,8.259251e+000,3.979538e-002,5.752563e-002,8.198317e+000,-2.113869e-002,-3.408432e-003,2.288143e-007,2.288143e-007,,,,,,,,,,,,,,,,,,,,
1524344187.112,,0.000000e+000,5.499971e+001,5.499445e+001,1,0,1.032258e+000,0.000000e+000,8.317388e+000,8.317388e+000,8.365068e-002,1.062183e-001,8.234133e+000,3.958605e-004,2.296352e-002,1.221400e-006,1.221400e-006,,,,,,,,,,,,,,,,,,,,
1524344199.352,,0.000000e+000,5.499839e+001,5.500235e+001,1,0,1.161290e+000,0.000000e+000,8.364691e+000,8.364691e+000,1.155721e-001,1.449432e-001,8.273082e+000,2.396310e-002,5.333424e-002,1.926557e-006,1.926557e-006,,,,,,,,,,,,,,,,,,,,
1524344211.772,,0.000000e+000,5.500892e+001,5.499839e+001,1,0,1.290323e+000,0.000000e+000,8.436103e+000,8.436103e+000,1.567185e-001,1.877165e-001,8.328209e+000,4.882454e-002,7.982254e-002,2.909277e-006,2.909277e-006,,,,,,,,,,,,,,,,,,,,
1524344224.492,,0.000000e+000,5.499839e+001,5.499445e+001,1,0,1.419355e+000,0.000000e+000,-6.302281e+000,-6.302281e+000,1.682822e-001,2.011032e-001,-6.394570e+000,7.599320e-002,1.088142e-001,3.215595e-006,3.215595e-006,,,,,,,,,,,,,,,,,,,,
1524344237.132,,0.000000e+000,5.499445e+001,5.499577e+001,1,0,1.548387e+000,0.000000e+000,-6.258793e+000,-6.258793e+000,1.876171e-001,2.232938e-001,-6.345149e+000,1.012610e-001,1.369376e-001,3.695750e-006,3.695750e-006,,,,,,,,,,,,,,,,,,,,
1524344249.642,,0.000000e+000,5.499708e+001,5.499971e+001,1,0,1.677419e+000,0.000000e+000,8.567788e+000,8.567788e+000,2.187418e-001,2.614584e-001,8.474252e+000,1.252054e-001,1.679220e-001,4.423404e-006,4.423404e-006,,,,,,,,,,,,,,,,,,,,
1524344262.412,,0.000000e+000,5.499708e+001,5.499971e+001,1,0,1.806452e+000,0.000000e+000,-6.186618e+000,-6.186618e+000,2.077263e-001,2.493548e-001,-6.250433e+000,1.439112e-001,1.855397e-001,4.233210e-006,4.233210e-006,,,,,,,,,,,,,,,,,,,,
1524344274.832,,0.000000e+000,5.499971e+001,5.500103e+001,1,0,1.935484e+000,0.000000e+000,-6.195011e+000,-6.195011e+000,1.740242e-001,2.197208e-001,-6.211871e+000,1.571637e-001,2.028604e-001,3.517431e-006,3.517431e-006,,,,,,,,,,,,,,,,,,,,
1524344274.832,,0.000000e+000,5.499971e+001,5.500103e+001,1,0,4.000000e+000,0.000000e+000,-6.304265e+000,-6.304265e+000,1.602670e-002,1.104665e-001,-6.373978e+000,-5.368593e-002,4.075384e-002,7.124618e-007,7.124618e-007,,,,,,,,,,,,,,,,,,,,