File: Experimental Raw Data/TC04-12-01K VRMac VRMde/raw/TC04-12-01K_VRMac_54K_3000s.dc.raw
[Header]
TITLE,MPMS DC Measurement
BYAPP,MPMS Measurement,2.1,Raw with ABS
FILEOPENTIME, 1524298981.650000 4/21/2018, 2:23:01 AM

INFO, APPNAME, MPMS MultiVu Application, Revision 1.61,  Build 082

INFO, NAME, TC04-12-01K
INFO, WEIGHT, 1.000
INFO, AREA, 1.000
INFO, LENGTH, 1.000
INFO, SHAPE, 0
INFO, COMMENT,
INFO, SEQUENCE FILE: VRMac_54K_3000s_VRMde_55K.seq


INFO, BACKGROUND DATA FILE:, None


STARTUPAXIS,X,8,LINEAR,AUTO,0.000000,0.000000
STARTUPAXIS,Y1,10,LINEAR,AUTO,0.000000,0.000000


STARTUPGROUP,Longitudinal
FIELDGROUP,Longitudinal,1,3,4,5,6,8,9,10,11,12,13,14,15,16,17,18,19,20,21,22,23
FIELDGROUP,Transverse,1,3,4,5,6,8,9,24,25,26,27,28,29,30,31,32,33,34,35,36,37

PLOT_APPEARANCE,ALL,HORZ_GRID_ON,VERT_GRID_ON,MARKERS_ONLY

[Data]
Time,Comment,Field (Oe),Start Temperature (K),End Temperature (K),Scan,Rejected,Position (cm),Rot Position (deg),Long Voltage,Long Average Voltage,Long Detrended Voltage,Long Demeaned Voltage,Long Regression Fit,Long Detrended Fit,Long Demeaned Fit,Long Scaled Response,Long Avg. Scaled Response,Long Background Response,Long Response [w/ABS],Long Detrended Resp. [w/ABS],Long Fit [w/ABS],Long Detrended Fit [w/ABS],Trans Voltage,Trans Average Voltage,Trans Detrended Voltage,Trans Demeaned Voltage,Trans Regression Fit,Trans Detrended Fit,Trans Demeaned Fit,Trans Scaled Response,Trans Avg Scaled Response,Trans Background Response,Trans Response [w/ABS],Trans Detrended Resp. [w/ABS],Trans Fit [w/ABS],Trans Detrended Fit [w/ABS],
1524298981.640,,0.000000e+000,5.405568e+001,5.404293e+001,1,0,0.000000e+000,0.000000e+000,2.883497e+000,2.883497e+000,6.231918e-001,6.231918e-001,3.484568e+000,1.224262e+000,1.224262e+000,2.687052e-005,2.687052e-005,,,,,,,,,,,,,,,,,,,,
1524298994.190,,0.000000e+000,5.404293e+001,5.403655e+001,1,0,1.290323e-001,0.000000e+000,3.448386e+000,3.448386e+000,8.742545e-001,8.477511e-001,4.050011e+000,1.475879e+000,1.449376e+000,3.362753e-005,3.362753e-005,,,,,,,,,,,,,,,,,,,,
1524299006.630,,0.000000e+000,5.403655e+001,5.402508e+001,1,0,2.580645e-001,0.000000e+000,3.893797e+000,3.893797e+000,1.133196e+000,1.075654e+000,4.426596e+000,1.665995e+000,1.608453e+000,3.973749e-005,3.973749e-005,,,,,,,,,,,,,,,,,,,,
1524299019.010,,0.000000e+000,5.402508e+001,5.401616e+001,1,0,3.870968e-001,0.000000e+000,4.248875e+000,4.248875e+000,1.344720e+000,1.253023e+000,4.649979e+000,1.745824e+000,1.654127e+000,4.454325e-005,4.454325e-005,,,,,,,,,,,,,,,,,,,,
1524299031.750,,0.000000e+000,5.401616e+001,5.401616e+001,1,0,5.161290e-001,0.000000e+000,4.480049e+000,4.480049e+000,1.480793e+000,1.352308e+000,4.672474e+000,1.673219e+000,1.544733e+000,4.749702e-005,4.749702e-005,,,,,,,,,,,,,,,,,,,,
1524299044.270,,0.000000e+000,5.401744e+001,5.401489e+001,1,0,6.451613e-001,0.000000e+000,4.587930e+000,4.587930e+000,1.534033e+000,1.367219e+000,4.501681e+000,1.447784e+000,1.280970e+000,4.852977e-005,4.852977e-005,,,,,,,,,,,,,,,,,,,,
1524299056.790,,0.000000e+000,5.401489e+001,5.401616e+001,1,0,7.741935e-001,0.000000e+000,4.510262e+000,4.510262e+000,1.426142e+000,1.221500e+000,4.152385e+000,1.068265e+000,8.636231e-001,4.581086e-005,4.581086e-005,,,,,,,,,,,,,,,,,,,,
1524299069.670,,0.000000e+000,5.400979e+001,5.400216e+001,1,0,9.032258e-001,0.000000e+000,4.279850e+000,4.279850e+000,1.173194e+000,9.291575e-001,3.680086e+000,5.734294e-001,3.293934e-001,3.985470e-005,3.985470e-005,,,,,,,,,,,,,,,,,,,,
1524299081.800,,0.000000e+000,5.400598e+001,5.400216e+001,1,0,1.032258e+000,0.000000e+000,3.866026e+000,3.866026e+000,7.612016e-001,4.820797e-001,3.093789e+000,-1.103497e-002,-2.901568e-001,3.018537e-005,3.018537e-005,,,,,,,,,,,,,,,,,,,,
1524299094.510,,0.000000e+000,5.399834e+001,5.400216e+001,1,0,1.161290e+000,0.000000e+000,3.327840e+000,3.327840e+000,2.203057e-001,-1.046712e-001,2.449594e+000,-6.579410e-001,-9.829180e-001,1.776771e-005,1.776771e-005,,,,,,,,,,,,,,,,,,,,
1524299107.280,,0.000000e+000,5.399834e+001,5.400979e+001,1,0,1.290323e+000,0.000000e+000,2.698864e+000,2.698864e+000,-3.893325e-001,-7.502105e-001,1.735785e+000,-1.352412e+000,-1.713289e+000,3.656271e-006,3.656271e-006,,,,,,,,,,,,,,,,,,,,
1524299120.151,,0.000000e+000,5.399961e+001,5.399707e+001,1,0,1.419355e+000,0.000000e+000,1.990997e+000,1.990997e+000,-1.083639e+000,-1.486454e+000,9.918276e-001,-2.082809e+000,-2.485624e+000,-1.229687e-005,-1.229687e-005,,,,,,,,,,,,,,,,,,,,
1524299132.651,,0.000000e+000,5.399961e+001,5.399834e+001,1,0,1.548387e+000,0.000000e+000,1.225299e+000,1.225299e+000,-1.826146e+000,-2.265775e+000,2.401100e-001,-2.811335e+000,-3.250965e+000,-2.939574e-005,-2.939574e-005,,,,,,,,,,,,,,,,,,,,
1524299145.511,,0.000000e+000,5.400725e+001,5.399834e+001,1,0,1.677419e+000,0.000000e+000,4.312200e-001,4.312200e-001,-2.591501e+000,-3.078447e+000,-4.652935e-001,-3.488014e+000,-3.974961e+000,-4.696987e-005,-4.696987e-005,,,,,,,,,,,,,,,,,,,,
1524299158.391,,0.000000e+000,5.400470e+001,5.400343e+001,1,0,1.806452e+000,0.000000e+000,-3.015183e-001,-3.015183e-001,-3.292944e+000,-3.820624e+000,-1.034683e+000,-4.026109e+000,-4.553790e+000,-6.315858e-005,-6.315858e-005,,,,,,,,,,,,,,,,,,,,
1524299171.171,,0.000000e+000,5.400343e+001,5.399834e+001,1,0,1.935484e+000,0.000000e+000,-9.452964e-001,-9.452964e-001,-3.902636e+000,-4.467359e+000,-1.378499e+000,-4.335839e+000,-4.900561e+000,-7.730614e-005,-7.730614e-005,,,,,,,,,,,,,,,,,,,,
1524299183.491,,0.000000e+000,5.399834e+001,5.400979e+001,1,0,2.064516e+000,0.000000e+000,-1.406119e+000,-1.406119e+000,-4.330725e+000,-4.944732e+000,-1.434143e+000,-4.358749e+000,-4.972756e+000,-8.738931e-005,-8.738931e-005,,,,,,,,,,,,,,,,,,,,
1524299195.921,,0.000000e+000,5.400979e+001,5.400343e+001,1,0,2.193548e+000,0.000000e+000,-1.631800e+000,-1.631800e+000,-4.520625e+000,-5.172227e+000,-1.181736e+000,-4.070560e+000,-4.722163e+000,-9.219018e-005,-9.219018e-005,,,,,,,,,,,,,,,,,,,,
1524299208.311,,0.000000e+000,5.400343e+001,5.399452e+001,1,0,2.322581e+000,0.000000e+000,-1.597925e+000,-1.597925e+000,-4.444552e+000,-5.139052e+000,-7.125783e-001,-3.559206e+000,-4.253705e+000,-9.102279e-005,-9.102279e-005,,,,,,,,,,,,,,,,,,,,
1524299220.771,,0.000000e+000,5.399452e+001,5.400216e+001,1,0,2.451613e+000,0.000000e+000,-1.282521e+000,-1.282521e+000,-4.089538e+000,-4.820128e+000,-8.371139e-002,-2.890729e+000,-3.621319e+000,-8.362953e-005,-8.362953e-005,,,,,,,,,,,,,,,,,,,,
1524299233.171,,0.000000e+000,5.400216e+001,5.399198e+001,1,0,2.580645e+000,0.000000e+000,-7.553216e-001,-7.553216e-001,-3.521480e+000,-4.290916e+000,6.081672e-001,-2.157991e+000,-2.927427e+000,-7.147537e-005,-7.147537e-005,,,,,,,,,,,,,,,,,,,,
1524299245.591,,0.000000e+000,5.399452e+001,5.399452e+001,1,0,2.709677e+000,0.000000e+000,1.470970e-001,1.470970e-001,-2.792148e+000,-3.607098e+000,1.523690e+000,-1.415556e+000,-2.230505e+000,-5.574501e-005,-5.574501e-005,,,,,,,,,,,,,,,,,,,,
1524299258.021,,0.000000e+000,5.399452e+001,5.399070e+001,1,0,2.838710e+000,0.000000e+000,7.602045e-001,7.602045e-001,-1.914378e+000,-2.758955e+000,1.979816e+000,-6.947657e-001,-1.539343e+000,-3.663412e-005,-3.663412e-005,,,,,,,,,,,,,,,,,,,,
1524299270.661,,0.000000e+000,5.398815e+001,5.399707e+001,1,0,2.967742e+000,0.000000e+000,1.601129e+000,1.601129e+000,-1.043478e+000,-1.922424e+000,2.632845e+000,-1.176216e-002,-8.907084e-001,-1.770735e-005,-1.770735e-005,,,,,,,,,,,,,,,,,,,,
1524299283.301,,0.000000e+000,5.399834e+001,5.399834e+001,1,0,3.096774e+000,0.000000e+000,2.410468e+000,2.410468e+000,-1.859348e-001,-1.119483e+000,3.213397e+000,6.169946e-001,-3.165538e-001,8.370844e-007,8.370844e-007,,,,,,,,,,,,,,,,,,,,
1524299295.821,,0.000000e+000,5.399324e+001,5.399961e+001,1,0,3.225806e+000,0.000000e+000,3.168384e+000,3.168384e+000,6.210175e-001,-3.532872e-001,3.712958e+000,1.165592e+000,1.912870e-001,1.830207e-005,1.830207e-005,,,,,,,,,,,,,,,,,,,,
1524299308.741,,0.000000e+000,5.399579e+001,5.399707e+001,1,0,3.354839e+000,0.000000e+000,3.833066e+000,3.833066e+000,1.330156e+000,3.075728e-001,4.100933e+000,1.598022e+000,5.754392e-001,3.353692e-005,3.353692e-005,,,,,,,,,,,,,,,,,,,,
1524299321.321,,0.000000e+000,5.400088e+001,5.399834e+001,1,0,3.483871e+000,0.000000e+000,4.406500e+000,4.406500e+000,1.948091e+000,8.914330e-001,4.336306e+000,1.877897e+000,8.212383e-001,4.681967e-005,4.681967e-005,,,,,,,,,,,,,,,,,,,,
1524299333.971,,0.000000e+000,5.399579e+001,5.399324e+001,1,0,3.612903e+000,0.000000e+000,4.844892e+000,4.844892e+000,2.430248e+000,1.330193e+000,4.401178e+000,1.986535e+000,8.864794e-001,5.700738e-005,5.700738e-005,,,,,,,,,,,,,,,,,,,,
1524299346.641,,0.000000e+000,5.399707e+001,5.400088e+001,1,0,3.741935e+000,0.000000e+000,5.120470e+000,5.120470e+000,2.755767e+000,1.614164e+000,4.303314e+000,1.938611e+000,7.970080e-001,6.370726e-005,6.370726e-005,,,,,,,,,,,,,,,,,,,,
1524299358.991,,0.000000e+000,5.399707e+001,5.399579e+001,1,0,3.870968e+000,0.000000e+000,5.228351e+000,5.228351e+000,2.907108e+000,1.727767e+000,4.095526e+000,1.774282e+000,5.949419e-001,6.653303e-005,6.653303e-005,,,,,,,,,,,,,,,,,,,,
1524299371.511,,0.000000e+000,5.399579e+001,5.399579e+001,1,0,4.000000e+000,0.000000e+000,5.170367e+000,5.170367e+000,2.889851e+000,1.667138e+000,3.831615e+000,1.551099e+000,3.283861e-001,6.557088e-005,6.557088e-005,,,,,,,,,,,,,,,,,,,,
1524299396.181,,0.000000e+000,5.400088e+001,5.399707e+001,1,0,0.000000e+000,0.000000e+000,4.368200e+000,4.368200e+000,8.681142e-001,8.681142e-001,5.056337e+000,1.556251e+000,1.556251e+000,3.872958e-005,3.872958e-005,,,,,,,,,,,,,,,,,,,,
1524299408.511,,0.000000e+000,5.398942e+001,5.400216e+001,1,0,1.290323e-001,0.000000e+000,4.519112e+000,4.519112e+000,1.068926e+000,1.029263e+000,5.238400e+000,1.788214e+000,1.748551e+000,4.259119e-005,4.259119e-005,,,,,,,,,,,,,,,,,,,,
1524299420.881,,0.000000e+000,5.399707e+001,5.399452e+001,1,0,2.580645e-001,0.000000e+000,4.732738e+000,4.732738e+000,1.325684e+000,1.245718e+000,5.370063e+000,1.963009e+000,1.883043e+000,4.783225e-005,4.783225e-005,,,,,,,,,,,,,,,,,,,,
1524299433.311,,0.000000e+000,5.399707e+001,5.399961e+001,1,0,3.870968e-001,0.000000e+000,4.918898e+000,4.918898e+000,1.558188e+000,1.438967e+000,5.375874e+000,2.015163e+000,1.895942e+000,5.238008e-005,5.238008e-005,,,,,,,,,,,,,,,,,,,,
1524299446.051,,0.000000e+000,5.399452e+001,5.399707e+001,1,0,5.161290e-001,0.000000e+000,5.019150e+000,5.019150e+000,1.704128e+000,1.543794e+000,5.228476e+000,1.913453e+000,1.753119e+000,5.513023e-005,5.513023e-005,,,,,,,,,,,,,,,,,,,,
1524299458.351,,0.000000e+000,5.399707e+001,5.399834e+001,1,0,6.451613e-001,0.000000e+000,4.988937e+000,4.988937e+000,1.724225e+000,1.524177e+000,4.900275e+000,1.635563e+000,1.435514e+000,5.499096e-005,5.499096e-005,,,,,,,,,,,,,,,,,,,,
1524299471.011,,0.000000e+000,5.399707e+001,5.399198e+001,1,0,7.741935e-001,0.000000e+000,4.817121e+000,4.817121e+000,1.600558e+000,1.360104e+000,4.414503e+000,1.197940e+000,9.574862e-001,5.165967e-005,5.165967e-005,,,,,,,,,,,,,,,,,,,,
1524299483.581,,0.000000e+000,5.400216e+001,5.400216e+001,1,0,9.032258e-001,0.000000e+000,4.439002e+000,4.439002e+000,1.276411e+000,9.962070e-001,3.798640e+000,6.360492e-001,3.558455e-001,4.382266e-005,4.382266e-005,,,,,,,,,,,,,,,,,,,,
1524299496.531,,0.000000e+000,5.399579e+001,5.399834e+001,1,0,1.032258e+000,0.000000e+000,3.935760e+000,3.935760e+000,8.210286e-001,5.012751e-001,3.102551e+000,-1.217943e-002,-3.319330e-001,3.305179e-005,3.305179e-005,,,,,,,,,,,,,,,,,,,,
1524299508.581,,0.000000e+000,5.400216e+001,5.399707e+001,1,0,1.161290e+000,0.000000e+000,3.304646e+000,3.304646e+000,2.416802e-001,-1.168742e-001,2.340967e+000,-7.219992e-001,-1.080554e+000,1.951679e-005,1.951679e-005,,,,,,,,,,,,,,,,,,,,
1524299521.281,,0.000000e+000,5.399707e+001,5.399707e+001,1,0,1.290323e+000,0.000000e+000,2.557565e+000,2.557565e+000,-4.599481e-001,-8.624992e-001,1.539218e+000,-1.478295e+000,-1.880846e+000,3.294517e-006,3.294517e-006,,,,,,,,,,,,,,,,,,,,
1524299533.661,,0.000000e+000,5.399198e+001,5.400470e+001,1,0,1.419355e+000,0.000000e+000,1.775692e+000,1.775692e+000,-1.192992e+000,-1.634700e+000,7.044926e-001,-2.264192e+000,-2.705900e+000,-1.367938e-005,-1.367938e-005,,,,,,,,,,,,,,,,,,,,
1524299546.671,,0.000000e+000,5.399579e+001,5.400343e+001,1,0,1.548387e+000,0.000000e+000,9.335470e-001,9.335470e-001,-1.990098e+000,-2.476196e+000,-1.213683e-001,-3.045013e+000,-3.531111e+000,-3.206780e-005,-3.206780e-005,,,,,,,,,,,,,,,,,,,,
1524299558.901,,0.000000e+000,5.399324e+001,5.399834e+001,1,0,1.677419e+000,0.000000e+000,8.010986e-002,8.010986e-002,-2.797036e+000,-3.321338e+000,-8.916858e-001,-3.768832e+000,-4.293134e+000,-5.068729e-005,-5.068729e-005,,,,,,,,,,,,,,,,,,,,
1524299571.701,,0.000000e+000,5.400088e+001,5.399961e+001,1,0,1.806452e+000,0.000000e+000,-7.165637e-001,-7.165637e-001,-3.550970e+000,-4.116818e+000,-1.502945e+000,-4.337352e+000,-4.903200e+000,-6.812267e-005,-6.812267e-005,,,,,,,,,,,,,,,,,,,,
1524299584.451,,0.000000e+000,5.399961e+001,5.399961e+001,1,0,1.935484e+000,0.000000e+000,-1.418479e+000,-1.418479e+000,-4.208262e+000,-4.810737e+000,-1.868063e+000,-4.657846e+000,-5.260322e+000,-8.340240e-005,-8.340240e-005,,,,,,,,,,,,,,,,,,,,
1524299597.121,,0.000000e+000,5.399961e+001,5.399834e+001,1,0,2.064516e+000,0.000000e+000,-1.894102e+000,-1.894102e+000,-4.634901e+000,-5.284580e+000,-1.921778e+000,-4.662577e+000,-5.312256e+000,-9.352893e-005,-9.352893e-005,,,,,,,,,,,,,,,,,,,,
1524299609.991,,0.000000e+000,5.399707e+001,5.399324e+001,1,0,2.193548e+000,0.000000e+000,-2.133364e+000,-2.133364e+000,-4.824149e+000,-5.518706e+000,-1.665527e+000,-4.356312e+000,-5.050869e+000,-9.834930e-005,-9.834930e-005,,,,,,,,,,,,,,,,,,,,
1524299622.591,,0.000000e+000,5.399324e+001,5.399070e+001,1,0,2.322581e+000,0.000000e+000,-2.086214e+000,-2.086214e+000,-4.723951e+000,-5.457536e+000,-1.151898e+000,-3.789635e+000,-4.523220e+000,-9.671701e-005,-9.671701e-005,,,,,,,,,,,,,,,,,,,,
1524299635.401,,0.000000e+000,5.399070e+001,5.399198e+001,1,0,2.451613e+000,0.000000e+000,-1.750057e+000,-1.750057e+000,-4.337633e+000,-5.111455e+000,-4.886861e-001,-3.076262e+000,-3.850084e+000,-8.866563e-005,-8.866563e-005,,,,,,,,,,,,,,,,,,,,
1524299647.991,,0.000000e+000,5.399198e+001,5.400216e+001,1,0,2.580645e+000,0.000000e+000,-1.158617e+000,-1.158617e+000,-3.698398e+000,-4.512734e+000,2.512502e-001,-2.288530e+000,-3.102866e+000,-7.498666e-005,-7.498666e-005,,,,,,,,,,,,,,,,,,,,
1524299660.791,,0.000000e+000,5.400216e+001,5.399452e+001,1,0,2.709677e+000,0.000000e+000,-4.303044e-001,-4.303044e-001,-2.925284e+000,-3.782624e+000,9.947820e-001,-1.500198e+000,-2.357538e+000,-5.829768e-005,-5.829768e-005,,,,,,,,,,,,,,,,,,,,
1524299673.651,,0.000000e+000,5.399452e+001,5.399961e+001,1,0,2.838710e+000,0.000000e+000,4.191653e-001,4.191653e-001,-2.025444e+000,-2.925325e+000,1.710814e+000,-7.337953e-001,-1.633677e+000,-3.880545e-005,-3.880545e-005,,,,,,,,,,,,,,,,,,,,
1524299686.341,,0.000000e+000,5.399961e+001,5.400598e+001,1,0,2.967742e+000,0.000000e+000,1.306630e+000,1.306630e+000,-1.090909e+000,-2.029735e+000,2.385122e+000,-1.241669e-002,-9.512432e-001,-1.850845e-005,-1.850845e-005,,,,,,,,,,,,,,,,,,,,
1524299698.841,,0.000000e+000,5.401107e+001,5.400216e+001,1,0,3.096774e+000,0.000000e+000,2.165103e+000,2.165103e+000,-1.854185e-001,-1.162686e+000,3.000310e+000,6.497890e-001,-3.274786e-001,1.145134e-006,1.145134e-006,,,,,,,,,,,,,,,,,,,,
1524299711.851,,0.000000e+000,5.399452e+001,5.399961e+001,1,0,3.225806e+000,0.000000e+000,2.949874e+000,2.949874e+000,6.465155e-001,-3.719645e-001,3.529019e+000,1.225661e+000,2.071807e-001,1.913404e-005,1.913404e-005,,,,,,,,,,,,,,,,,,,,
1524299723.871,,0.000000e+000,5.399452e+001,5.399198e+001,1,0,3.354839e+000,0.000000e+000,3.659419e+000,3.659419e+000,1.399547e+000,3.417928e-001,3.940567e+000,1.680695e+000,6.229408e-001,3.539152e-005,3.539152e-005,,,,,,,,,,,,,,,,,,,,
1524299736.671,,0.000000e+000,5.399961e+001,5.399070e+001,1,0,3.483871e+000,0.000000e+000,4.258488e+000,4.258488e+000,2.046595e+000,9.429653e-001,4.185312e+000,1.973419e+000,8.697894e-001,4.923107e-005,4.923107e-005,,,,,,,,,,,,,,,,,,,,
1524299748.741,,0.000000e+000,5.399579e+001,5.399834e+001,1,0,3.612903e+000,0.000000e+000,4.726635e+000,4.726635e+000,2.564294e+000,1.419959e+000,4.245342e+000,2.083002e+000,9.386659e-001,6.019478e-005,6.019478e-005,,,,,,,,,,,,,,,,,,,,
1524299761.561,,0.000000e+000,5.399579e+001,5.399961e+001,1,0,3.741935e+000,0.000000e+000,5.000687e+000,5.000687e+000,2.884077e+000,1.699898e+000,4.147198e+000,2.030589e+000,8.464100e-001,6.675575e-005,6.675575e-005,,,,,,,,,,,,,,,,,,,,
1524299773.841,,0.000000e+000,5.399579e+001,5.399070e+001,1,0,3.870968e+000,0.000000e+000,5.099260e+000,5.099260e+000,3.023489e+000,1.808186e+000,3.932812e+000,1.857041e+000,6.417372e-001,6.934406e-005,6.934406e-005,,,,,,,,,,,,,,,,,,,,
1524299786.621,,0.000000e+000,5.399834e+001,5.399579e+001,1,0,4.000000e+000,0.000000e+000,5.029374e+000,5.029374e+000,3.008305e+000,1.731778e+000,3.639970e+000,1.618902e+000,3.423748e-001,6.825857e-005,6.825857e-005,,,,,,,,,,,,,,,,,,,,
1524299811.461,,0.000000e+000,5.399707e+001,5.399961e+001,1,0,0.000000e+000,0.000000e+000,4.195163e+000,4.195163e+000,9.176688e-001,9.176688e-001,4.899256e+000,1.621762e+000,1.621762e+000,4.051105e-005,4.051105e-005,,,,,,,,,,,,,,,,,,,,
1524299824.071,,0.000000e+000,5.399198e+001,5.399324e+001,1,0,1.290323e-001,0.000000e+000,4.343175e+000,4.343175e+000,1.115216e+000,1.074415e+000,5.093237e+000,1.865278e+000,1.824477e+000,4.430812e-005,4.430812e-005,,,,,,,,,,,,,,,,,,,,
1524299836.332,,0.000000e+000,5.400088e+001,5.398942e+001,1,0,2.580645e-001,0.000000e+000,4.598306e+000,4.598306e+000,1.415510e+000,1.333288e+000,5.224264e+000,2.041467e+000,1.959246e+000,5.047279e-005,5.047279e-005,,,,,,,,,,,,,,,,,,,,
1524299849.642,,0.000000e+000,5.398942e+001,5.398815e+001,1,0,3.870968e-001,0.000000e+000,4.780194e+000,4.780194e+000,1.648445e+000,1.525417e+000,5.231372e+000,2.099622e+000,1.976595e+000,5.505914e-005,5.505914e-005,,,,,,,,,,,,,,,,,,,,
1524299861.452,,0.000000e+000,5.398815e+001,5.399324e+001,1,0,5.161290e-001,0.000000e+000,4.877546e+000,4.877546e+000,1.786558e+000,1.620593e+000,5.081264e+000,1.990276e+000,1.824311e+000,5.762230e-005,5.762230e-005,,,,,,,,,,,,,,,,,,,,
1524299874.782,,0.000000e+000,5.399324e+001,5.399452e+001,1,0,6.451613e-001,0.000000e+000,5.042191e+000,5.042191e+000,1.791286e+000,1.586719e+000,4.953033e+000,1.702128e+000,1.497561e+000,5.704608e-005,5.704608e-005,,,,,,,,,,,,,,,,,,,,
1524299887.602,,0.000000e+000,5.399961e+001,5.399961e+001,1,0,7.741935e-001,0.000000e+000,4.625162e+000,4.625162e+000,1.646388e+000,1.400640e+000,4.221776e+000,1.243002e+000,9.972544e-001,5.319306e-005,5.319306e-005,,,,,,,,,,,,,,,,,,,,
1524299900.572,,0.000000e+000,5.400216e+001,5.399707e+001,1,0,9.032258e-001,0.000000e+000,4.265049e+000,4.265049e+000,1.332824e+000,1.045579e+000,3.592839e+000,6.606139e-001,3.733692e-001,4.560578e-005,4.560578e-005,,,,,,,,,,,,,,,,,,,,
1524299912.712,,0.000000e+000,5.399198e+001,5.399961e+001,1,0,1.032258e+000,0.000000e+000,3.741359e+000,3.741359e+000,8.553532e-001,5.262892e-001,2.873382e+000,-1.262435e-002,-3.416884e-001,3.432290e-005,3.432290e-005,,,,,,,,,,,,,,,,,,,,
1524299925.392,,0.000000e+000,5.400216e+001,5.400598e+001,1,0,1.161290e+000,0.000000e+000,3.048295e+000,3.048295e+000,2.166426e-001,-1.559336e-001,2.084282e+000,-7.473705e-001,-1.119947e+000,1.946852e-005,1.946852e-005,,,,,,,,,,,,,,,,,,,,
1524299937.762,,0.000000e+000,5.399707e+001,5.399324e+001,1,0,1.290323e+000,0.000000e+000,2.306554e+000,2.306554e+000,-4.730241e-001,-8.831465e-001,1.248893e+000,-1.530684e+000,-1.940807e+000,3.428489e-006,3.428489e-006,,,,,,,,,,,,,,,,,,,,
1524299950.802,,0.000000e+000,5.399707e+001,5.400470e+001,1,0,1.419355e+000,0.000000e+000,1.469597e+000,1.469597e+000,-1.261224e+000,-1.713928e+000,3.890942e-001,-2.341727e+000,-2.794431e+000,-1.478492e-005,-1.478492e-005,,,,,,,,,,,,,,,,,,,,
1524299963.492,,0.000000e+000,5.400470e+001,5.399452e+001,1,0,1.548387e+000,0.000000e+000,6.019684e-001,6.019684e-001,-2.082407e+000,-2.573050e+000,-4.658716e-001,-3.150248e+000,-3.640890e+000,-3.375526e-005,-3.375526e-005,,,,,,,,,,,,,,,,,,,,
1524299976.382,,0.000000e+000,5.399707e+001,5.399324e+001,1,0,1.677419e+000,0.000000e+000,-2.708476e-001,-2.708476e-001,-2.905561e+000,-3.443145e+000,-1.257893e+000,-3.892607e+000,-4.430190e+000,-5.273570e-005,-5.273570e-005,,,,,,,,,,,,,,,,,,,,
1524299989.252,,0.000000e+000,5.399324e+001,5.400088e+001,1,0,1.806452e+000,0.000000e+000,-1.095750e+000,-1.095750e+000,-3.681737e+000,-4.263942e+000,-1.890736e+000,-4.476723e+000,-5.058928e+000,-7.068700e-005,-7.068700e-005,,,,,,,,,,,,,,,,,,,,
1524300002.052,,0.000000e+000,5.400088e+001,5.398942e+001,1,0,1.935484e+000,0.000000e+000,-1.802243e+000,-1.802243e+000,-4.335535e+000,-4.955941e+000,-2.269234e+000,-4.802526e+000,-5.422933e+000,-8.591644e-005,-8.591644e-005,,,,,,,,,,,,,,,,,,,,
1524300014.362,,0.000000e+000,5.398942e+001,5.399707e+001,1,0,2.064516e+000,0.000000e+000,-2.307927e+000,-2.307927e+000,-4.791052e+000,-5.455882e+000,-2.325318e+000,-4.808443e+000,-5.473273e+000,-9.670175e-005,-9.670175e-005,,,,,,,,,,,,,,,,,,,,
1524300026.952,,0.000000e+000,5.399707e+001,5.399579e+001,1,0,2.193548e+000,0.000000e+000,-2.546578e+000,-2.546578e+000,-4.982834e+000,-5.680392e+000,-2.050523e+000,-4.486778e+000,-5.184337e+000,-1.015889e-004,-1.015889e-004,,,,,,,,,,,,,,,,,,,,
1524300039.642,,0.000000e+000,5.399707e+001,5.400216e+001,1,0,2.322581e+000,0.000000e+000,-2.475318e+000,-2.475318e+000,-4.863081e+000,-5.608226e+000,-1.520182e+000,-3.907944e+000,-4.653090e+000,-9.952635e-005,-9.952635e-005,,,,,,,,,,,,,,,,,,,,
1524300052.192,,0.000000e+000,5.400216e+001,5.400216e+001,1,0,2.451613e+000,0.000000e+000,-2.134432e+000,-2.134432e+000,-4.468554e+000,-5.257613e+000,-8.313264e-001,-3.165448e+000,-3.954508e+000,-9.133187e-005,-9.133187e-005,,,,,,,,,,,,,,,,,,,,
1524300065.032,,0.000000e+000,5.399707e+001,5.399961e+001,1,0,2.580645e+000,0.000000e+000,-1.512322e+000,-1.512322e+000,-3.800875e+000,-4.628730e+000,-6.923079e-002,-2.357785e+000,-3.185639e+000,-7.700754e-005,-7.700754e-005,,,,,,,,,,,,,,,,,,,,
1524300077.162,,0.000000e+000,5.399579e+001,5.399579e+001,1,0,2.709677e+000,0.000000e+000,-7.548639e-001,-7.548639e-001,-2.994339e+000,-3.863181e+000,6.962324e-001,-1.543243e+000,-2.412085e+000,-5.958674e-005,-5.958674e-005,,,,,,,,,,,,,,,,,,,,
1524300089.892,,0.000000e+000,5.399961e+001,5.400088e+001,1,0,2.838710e+000,0.000000e+000,1.338216e-001,1.338216e-001,-2.054377e+000,-2.966203e+000,1.432710e+000,-7.554880e-001,-1.667315e+000,-3.919653e-005,-3.919653e-005,,,,,,,,,,,,,,,,,,,,
1524300102.462,,0.000000e+000,5.400216e+001,5.399834e+001,1,0,2.967742e+000,0.000000e+000,1.022660e+000,1.022660e+000,-1.112905e+000,-2.066309e+000,2.122791e+000,-1.277383e-002,-9.661782e-001,-1.877050e-005,-1.877050e-005,,,,,,,,,,,,,,,,,,,,
1524300115.292,,0.000000e+000,5.400216e+001,5.399707e+001,1,0,3.096774e+000,0.000000e+000,1.902342e+000,1.902342e+000,-1.869010e-001,-1.182137e+000,2.758254e+000,6.690102e-001,-3.262258e-001,1.326167e-006,1.326167e-006,,,,,,,,,,,,,,,,,,,,
1524300127.692,,0.000000e+000,5.399452e+001,5.398942e+001,1,0,3.225806e+000,0.000000e+000,2.720531e+000,2.720531e+000,6.850181e-001,-3.521616e-001,3.297903e+000,1.262390e+000,2.252107e-001,2.020187e-005,2.020187e-005,,,,,,,,,,,,,,,,,,,,
1524300140.172,,0.000000e+000,5.398815e+001,5.399961e+001,1,0,3.354839e+000,0.000000e+000,3.420157e+000,3.420157e+000,1.438008e+000,3.549793e-001,3.708698e+000,1.726548e+000,6.435199e-001,3.638484e-005,3.638484e-005,,,,,,,,,,,,,,,,,,,,
1524300153.132,,0.000000e+000,5.400343e+001,5.399834e+001,1,0,3.483871e+000,0.000000e+000,4.045777e+000,4.045777e+000,2.109308e+000,9.891717e-001,3.963074e+000,2.026605e+000,9.064686e-001,5.081076e-005,5.081076e-005,,,,,,,,,,,,,,,,,,,,
1524300165.742,,0.000000e+000,5.399834e+001,5.399579e+001,1,0,3.612903e+000,0.000000e+000,4.507210e+000,4.507210e+000,2.621956e+000,1.461571e+000,4.023952e+000,2.138699e+000,9.783134e-001,6.165740e-005,6.165740e-005,,,,,,,,,,,,,,,,,,,,
1524300178.632,,0.000000e+000,5.399961e+001,5.399452e+001,1,0,3.741935e+000,0.000000e+000,4.781720e+000,4.781720e+000,2.949672e+000,1.738985e+000,3.917442e+000,2.085394e+000,8.747070e-001,6.832160e-005,6.832160e-005,,,,,,,,,,,,,,,,,,,,
1524300191.322,,0.000000e+000,5.399452e+001,5.399198e+001,1,0,3.870968e+000,0.000000e+000,4.868391e+000,4.868391e+000,3.090776e+000,1.842231e+000,3.682329e+000,1.904714e+000,6.561687e-001,7.087861e-005,7.087861e-005,,,,,,,,,,,,,,,,,,,,
1524300203.732,,0.000000e+000,5.399198e+001,5.400088e+001,1,0,4.000000e+000,0.000000e+000,4.778668e+000,4.778668e+000,3.061299e+000,1.763639e+000,3.378422e+000,1.661053e+000,3.633933e-001,6.955980e-005,6.955980e-005,,,,,,,,,,,,,,,,,,,,
1524300229.022,,0.000000e+000,5.399452e+001,5.399834e+001,1,0,0.000000e+000,0.000000e+000,3.938506e+000,3.938506e+000,9.445984e-001,9.445984e-001,4.655016e+000,1.661109e+000,1.661109e+000,4.150744e-005,4.150744e-005,,,,,,,,,,,,,,,,,,,,
1524300241.592,,0.000000e+000,5.399834e+001,5.399324e+001,1,0,1.290323e-001,0.000000e+000,4.099946e+000,4.099946e+000,1.158618e+000,1.117257e+000,4.850984e+000,1.909656e+000,1.868294e+000,4.565077e-005,4.565077e-005,,,,,,,,,,,,,,,,,,,,
1524300254.222,,0.000000e+000,5.399579e+001,5.400088e+001,1,0,2.580645e-001,0.000000e+000,4.349584e+000,4.349584e+000,1.456657e+000,1.373550e+000,4.984422e+000,2.091495e+000,2.008388e+000,5.174051e-005,5.174051e-005,,,,,,,,,,,,,,,,,,,,
1524300266.502,,0.000000e+000,5.399961e+001,5.400598e+001,1,0,3.870968e-001,0.000000e+000,4.512550e+000,4.512550e+000,1.668163e+000,1.543666e+000,4.994849e+000,2.150462e+000,2.025964e+000,5.584727e-005,5.584727e-005,,,,,,,,,,,,,,,,,,,,
1524300279.312,,0.000000e+000,5.399452e+001,5.399707e+001,1,0,5.161290e-001,0.000000e+000,4.626078e+000,4.626078e+000,1.830853e+000,1.664092e+000,4.833191e+000,2.037967e+000,1.871206e+000,5.890002e-005,5.890002e-005,,,,,,,,,,,,,,,,,,,,
1524300291.472,,0.000000e+000,5.399961e+001,5.399707e+001,1,0,6.451613e-001,0.000000e+000,4.583047e+000,4.583047e+000,1.841694e+000,1.634302e+000,4.481214e+000,1.739860e+000,1.532469e+000,5.849628e-005,5.849628e-005,,,,,,,,,,,,,,,,,,,,
1524300304.062,,0.000000e+000,5.399070e+001,5.398942e+001,1,0,7.741935e-001,0.000000e+000,4.370489e+000,4.370489e+000,1.680933e+000,1.430893e+000,3.962268e+000,1.272712e+000,1.022672e+000,5.431975e-005,5.431975e-005,,,,,,,,,,,,,,,,,,,,
1524300316.652,,0.000000e+000,5.399834e+001,5.399579e+001,1,0,9.032258e-001,0.000000e+000,3.989624e+000,3.989624e+000,1.354659e+000,1.064826e+000,3.310094e+000,6.751293e-001,3.852961e-001,4.637399e-005,4.637399e-005,,,,,,,,,,,,,,,,,,,,
1524300329.532,,0.000000e+000,5.399961e+001,5.399198e+001,1,0,1.032258e+000,0.000000e+000,3.449455e+000,3.449455e+000,8.636457e-001,5.312009e-001,2.572882e+000,-1.292673e-002,-3.453715e-001,3.480957e-005,3.480957e-005,,,,,,,,,,,,,,,,,,,,
1524300341.692,,0.000000e+000,5.399707e+001,5.399834e+001,1,0,1.161290e+000,0.000000e+000,2.760662e+000,2.760662e+000,2.241746e-001,-1.522837e-001,1.771852e+000,-7.646362e-001,-1.141094e+000,1.992393e-005,1.992393e-005,,,,,,,,,,,,,,,,,,,,
1524300354.162,,0.000000e+000,5.399324e+001,5.400088e+001,1,0,1.290323e+000,0.000000e+000,1.971466e+000,1.971466e+000,-5.115757e-001,-9.308360e-001,9.183841e-001,-1.564657e+000,-1.983917e+000,2.877881e-006,2.877881e-006,,,,,,,,,,,,,,,,,,,,
1524300366.672,,0.000000e+000,5.400343e+001,5.399707e+001,1,0,1.419355e+000,0.000000e+000,1.132525e+000,1.132525e+000,-1.294584e+000,-1.752949e+000,3.158811e-002,-2.395521e+000,-2.853886e+000,-1.525148e-005,-1.525148e-005,,,,,,,,,,,,,,,,,,,,
1524300379.072,,0.000000e+000,5.399707e+001,5.400343e+001,1,0,1.548387e+000,0.000000e+000,2.282750e-001,2.282750e-001,-2.148421e+000,-2.650263e+000,-8.411055e-001,-3.217801e+000,-3.719643e+000,-3.495350e-005,-3.495350e-005,,,,,,,,,,,,,,,,,,,,
1524300391.622,,0.000000e+000,5.400343e+001,5.399961e+001,1,0,1.677419e+000,0.000000e+000,-6.623942e-001,-6.623942e-001,-2.983765e+000,-3.525660e+000,-1.655557e+000,-3.976927e+000,-4.518822e+000,-5.424020e-005,-5.424020e-005,,,,,,,,,,,,,,,,,,,,
1524300404.352,,0.000000e+000,5.399961e+001,5.399834e+001,1,0,1.806452e+000,0.000000e+000,-1.510185e+000,-1.510185e+000,-3.778336e+000,-4.365703e+000,-2.306403e+000,-4.574553e+000,-5.161921e+000,-7.260455e-005,-7.260455e-005,,,,,,,,,,,,,,,,,,,,
1524300417.392,,0.000000e+000,5.399834e+001,5.399961e+001,1,0,1.935484e+000,0.000000e+000,-2.220340e+000,-2.220340e+000,-4.433599e+000,-5.062808e+000,-2.696574e+000,-4.909832e+000,-5.539041e+000,-8.786532e-005,-8.786532e-005,,,,,,,,,,,,,,,,,,,,
1524300429.892,,0.000000e+000,5.399579e+001,5.399961e+001,1,0,2.064516e+000,0.000000e+000,-2.726482e+000,-2.726482e+000,-4.891230e+000,-5.555030e+000,-2.744713e+000,-4.909461e+000,-5.573261e+000,-9.871569e-005,-9.871569e-005,,,,,,,,,,,,,,,,,,,,
1524300442.692,,0.000000e+000,5.400088e+001,5.400343e+001,1,0,2.193548e+000,0.000000e+000,-2.962997e+000,-2.962997e+000,-5.074737e+000,-5.787531e+000,-2.466301e+000,-4.578041e+000,-5.290834e+000,-1.034454e-004,-1.034454e-004,,,,,,,,,,,,,,,,,,,,
1524300455.242,,0.000000e+000,5.400343e+001,5.400216e+001,1,0,2.322581e+000,0.000000e+000,-2.889296e+000,-2.889296e+000,-4.951250e+000,-5.699349e+000,-1.924046e+000,-3.986000e+000,-4.734099e+000,-1.012893e-004,-1.012893e-004,,,,,,,,,,,,,,,,,,,,
1524300468.092,,0.000000e+000,5.399452e+001,5.399579e+001,1,0,2.451613e+000,0.000000e+000,-2.530404e+000,-2.530404e+000,-4.541312e+000,-5.335395e+000,-1.222335e+000,-3.233243e+000,-4.027326e+000,-9.274251e-005,-9.274251e-005,,,,,,,,,,,,,,,,,,,,
1524300480.722,,0.000000e+000,5.399324e+001,5.399707e+001,1,0,2.580645e+000,0.000000e+000,-1.898528e+000,-1.898528e+000,-3.858289e+000,-4.691003e+000,-4.458693e-001,-2.405631e+000,-3.238345e+000,-7.808957e-005,-7.808957e-005,,,,,,,,,,,,,,,,,,,,
1524300493.112,,0.000000e+000,5.399579e+001,5.399452e+001,1,0,2.709677e+000,0.000000e+000,-1.097124e+000,-1.097124e+000,-3.000053e+000,-3.877691e+000,3.300123e-001,-1.572917e+000,-2.450555e+000,-5.954249e-005,-5.954249e-005,,,,,,,,,,,,,,,,,,,,
1524300505.502,,0.000000e+000,5.399579e+001,5.399198e+001,1,0,2.838710e+000,0.000000e+000,-2.354467e-001,-2.354467e-001,-2.082030e+000,-3.005951e+000,1.076154e+000,-7.704287e-001,-1.694350e+000,-3.965556e-005,-3.965556e-005,,,,,,,,,,,,,,,,,,,,
1524300518.402,,0.000000e+000,5.398688e+001,5.399452e+001,1,0,2.967742e+000,0.000000e+000,6.819257e-001,6.819257e-001,-1.115325e+000,-2.074880e+000,1.784233e+000,-1.301754e-002,-9.725728e-001,-1.864983e-005,-1.864983e-005,,,,,,,,,,,,,,,,,,,,
1524300531.072,,0.000000e+000,5.399834e+001,5.399961e+001,1,0,3.096774e+000,0.000000e+000,1.544213e+000,1.544213e+000,-2.016290e-001,-1.201997e+000,2.427088e+000,6.812459e-001,-3.191223e-001,1.166649e-006,1.166649e-006,,,,,,,,,,,,,,,,,,,,
1524300543.353,,0.000000e+000,5.399834e+001,5.399707e+001,1,0,3.225806e+000,0.000000e+000,2.375830e+000,2.375830e+000,6.866417e-001,-3.612783e-001,2.975356e+000,1.286168e+000,2.382483e-001,2.038010e-005,2.038010e-005,,,,,,,,,,,,,,,,,,,,
1524300555.683,,0.000000e+000,5.399834e+001,5.400470e+001,1,0,3.354839e+000,0.000000e+000,3.109636e+000,3.109636e+000,1.477272e+000,3.882523e-001,3.390136e+000,1.757771e+000,6.687522e-001,3.742097e-005,3.742097e-005,,,,,,,,,,,,,,,,,,,,
1524300568.163,,0.000000e+000,5.399961e+001,5.399834e+001,1,0,3.483871e+000,0.000000e+000,3.734798e+000,3.734798e+000,2.159550e+000,1.025554e+000,3.636016e+000,2.060768e+000,9.267721e-001,5.202735e-005,5.202735e-005,,,,,,,,,,,,,,,,,,,,
1524300580.473,,0.000000e+000,5.399834e+001,5.399961e+001,1,0,3.612903e+000,0.000000e+000,4.192874e+000,4.192874e+000,2.665948e+000,1.500296e+000,3.705719e+000,2.178793e+000,1.013141e+000,6.280759e-005,6.280759e-005,,,,,,,,,,,,,,,,,,,,
1524300592.953,,0.000000e+000,5.400343e+001,5.399961e+001,1,0,3.741935e+000,0.000000e+000,4.461738e+000,4.461738e+000,2.992006e+000,1.774173e+000,3.590532e+000,2.120800e+000,9.029675e-001,6.940147e-005,6.940147e-005,,,,,,,,,,,,,,,,,,,,
1524300605.033,,0.000000e+000,5.401107e+001,5.399707e+001,1,0,3.870968e+000,0.000000e+000,4.548867e+000,4.548867e+000,3.131811e+000,1.870260e+000,3.356433e+000,1.939376e+000,6.778259e-001,7.189848e-005,7.189848e-005,,,,,,,,,,,,,,,,,,,,
1524300617.813,,0.000000e+000,5.398306e+001,5.399070e+001,1,0,4.000000e+000,0.000000e+000,4.470588e+000,4.470588e+000,3.110924e+000,1.803173e+000,3.049007e+000,1.689343e+000,3.815916e-001,7.077780e-005,7.077780e-005,,,,,,,,,,,,,,,,,,,,
1524300643.153,,0.000000e+000,5.399834e+001,5.399579e+001,1,0,0.000000e+000,0.000000e+000,3.592432e+000,3.592432e+000,9.596400e-001,9.596400e-001,4.322582e+000,1.689790e+000,1.689790e+000,4.213209e-005,4.213209e-005,,,,,,,,,,,,,,,,,,,,
1524300655.263,,0.000000e+000,5.399324e+001,5.399579e+001,1,0,1.290323e-001,0.000000e+000,3.742733e+000,3.742733e+000,1.170508e+000,1.128614e+000,4.513855e+000,1.941630e+000,1.899736e+000,4.621266e-005,4.621266e-005,,,,,,,,,,,,,,,,,,,,
1524300668.023,,0.000000e+000,5.400216e+001,5.400088e+001,1,0,2.580645e-001,0.000000e+000,3.998169e+000,3.998169e+000,1.478947e+000,1.394909e+000,4.645399e+000,2.126176e+000,2.042138e+000,5.251176e-005,5.251176e-005,,,,,,,,,,,,,,,,,,,,
1524300680.103,,0.000000e+000,5.399707e+001,5.400088e+001,1,0,3.870968e-001,0.000000e+000,4.167239e+000,4.167239e+000,1.704999e+000,1.579528e+000,4.648854e+000,2.186615e+000,2.061143e+000,5.691314e-005,5.691314e-005,,,,,,,,,,,,,,,,,,,,
1524300692.783,,0.000000e+000,5.398815e+001,5.400216e+001,1,0,5.161290e-001,0.000000e+000,4.274357e+000,4.274357e+000,1.860095e+000,1.690836e+000,4.486457e+000,2.072194e+000,1.902936e+000,5.984255e-005,5.984255e-005,,,,,,,,,,,,,,,,,,,,
1524300704.913,,0.000000e+000,5.399452e+001,5.399579e+001,1,0,6.451613e-001,0.000000e+000,4.226902e+000,4.226902e+000,1.871486e+000,1.661732e+000,4.124407e+000,1.768992e+000,1.559238e+000,5.941763e-005,5.941763e-005,,,,,,,,,,,,,,,,,,,,
1524300717.603,,0.000000e+000,5.399707e+001,5.399961e+001,1,0,7.741935e-001,0.000000e+000,4.001373e+000,4.001373e+000,1.701389e+000,1.447923e+000,3.593244e+000,1.293260e+000,1.039794e+000,5.503293e-005,5.503293e-005,,,,,,,,,,,,,,,,,,,,
1524300730.103,,0.000000e+000,5.399707e+001,5.400216e+001,1,0,9.032258e-001,0.000000e+000,3.608454e+000,3.608454e+000,1.365265e+000,1.070191e+000,2.928960e+000,6.857715e-001,3.906975e-001,4.687694e-005,4.687694e-005,,,,,,,,,,,,,,,,,,,,
1524300743.023,,0.000000e+000,5.399324e+001,5.399707e+001,1,0,1.032258e+000,0.000000e+000,3.047074e+000,3.047074e+000,8.622906e-001,5.253229e-001,2.171649e+000,-1.313451e-002,-3.501022e-001,3.501722e-005,3.501722e-005,,,,,,,,,,,,,,,,,,,,
1524300755.623,,0.000000e+000,5.399324e+001,5.399961e+001,1,0,1.161290e+000,0.000000e+000,2.338445e+000,2.338445e+000,2.097844e-001,-1.685753e-001,1.351963e+000,-7.766979e-001,-1.155058e+000,1.979411e-005,1.979411e-005,,,,,,,,,,,,,,,,,,,,
1524300768.013,,0.000000e+000,5.399707e+001,5.399834e+001,1,0,1.290323e+000,0.000000e+000,1.540551e+000,1.540551e+000,-5.307720e-001,-9.506420e-001,4.822348e-001,-1.589088e+000,-2.008958e+000,2.623659e-006,2.623659e-006,,,,,,,,,,,,,,,,,,,,
1524300780.573,,0.000000e+000,5.400216e+001,5.400216e+001,1,0,1.419355e+000,0.000000e+000,7.003891e-001,7.003891e-001,-1.313521e+000,-1.774172e+000,-4.185651e-001,-2.432475e+000,-2.893126e+000,-1.549280e-005,-1.549280e-005,,,,,,,,,,,,,,,,,,,,
1524300793.263,,0.000000e+000,5.400216e+001,5.399707e+001,1,0,1.548387e+000,0.000000e+000,-2.038605e-001,-2.038605e-001,-2.161713e+000,-2.667638e+000,-1.311937e+000,-3.269789e+000,-3.775714e+000,-3.505700e-005,-3.505700e-005,,,,,,,,,,,,,,,,,,,,
1524300805.413,,0.000000e+000,5.399324e+001,5.400088e+001,1,0,1.677419e+000,0.000000e+000,-1.116350e+000,-1.116350e+000,-3.015439e+000,-3.569451e+000,-2.137751e+000,-4.036840e+000,-4.590851e+000,-5.474928e-005,-5.474928e-005,,,,,,,,,,,,,,,,,,,,
1524300818.083,,0.000000e+000,5.399961e+001,5.399961e+001,1,0,1.806452e+000,0.000000e+000,-1.999237e+000,-1.999237e+000,-3.826861e+000,-4.418095e+000,-2.816530e+000,-4.644154e+000,-5.235388e+000,-7.351703e-005,-7.351703e-005,,,,,,,,,,,,,,,,,,,,
1524300830.293,,0.000000e+000,5.399961e+001,5.400598e+001,1,0,1.935484e+000,0.000000e+000,-2.736095e+000,-2.736095e+000,-4.509969e+000,-5.140777e+000,-3.207857e+000,-4.981730e+000,-5.612538e+000,-8.941157e-005,-8.941157e-005,,,,,,,,,,,,,,,,,,,,
1524300842.923,,0.000000e+000,5.398942e+001,5.399834e+001,1,0,2.064516e+000,0.000000e+000,-3.245289e+000,-3.245289e+000,-4.964334e+000,-5.637301e+000,-3.265736e+000,-4.984780e+000,-5.657747e+000,-1.001864e-004,-1.001864e-004,,,,,,,,,,,,,,,,,,,,
1524300855.483,,0.000000e+000,5.399961e+001,5.399834e+001,1,0,2.193548e+000,0.000000e+000,-3.492943e+000,-3.492943e+000,-5.155726e+000,-5.873819e+000,-2.987897e+000,-4.650680e+000,-5.368773e+000,-1.050894e-004,-1.050894e-004,,,,,,,,,,,,,,,,,,,,
1524300868.353,,0.000000e+000,5.399961e+001,5.398815e+001,1,0,2.322581e+000,0.000000e+000,-3.439841e+000,-3.439841e+000,-5.041757e+000,-5.803836e+000,-2.445578e+000,-4.047494e+000,-4.809573e+000,-1.031725e-004,-1.031725e-004,,,,,,,,,,,,,,,,,,,,
1524300880.523,,0.000000e+000,5.399834e+001,5.399834e+001,1,0,2.451613e+000,0.000000e+000,-3.068894e+000,-3.068894e+000,-4.614605e+000,-5.413586e+000,-1.733594e+000,-3.279305e+000,-4.078285e+000,-9.423827e-005,-9.423827e-005,,,,,,,,,,,,,,,,,,,,
1524300893.783,,0.000000e+000,5.400470e+001,5.400088e+001,1,0,2.580645e+000,0.000000e+000,-2.413519e+000,-2.413519e+000,-3.906146e+000,-4.743134e+000,-9.477030e-001,-2.440330e+000,-3.277318e+000,-7.901578e-005,-7.901578e-005,,,,,,,,,,,,,,,,,,,,
1524300906.223,,0.000000e+000,5.399707e+001,5.400343e+001,1,0,2.709677e+000,0.000000e+000,-1.598993e+000,-1.598993e+000,-3.041153e+000,-3.923019e+000,-1.552790e-001,-1.597439e+000,-2.479305e+000,-6.030712e-005,-6.030712e-005,,,,,,,,,,,,,,,,,,,,
1524300918.593,,0.000000e+000,5.400343e+001,5.400216e+001,1,0,2.838710e+000,0.000000e+000,-7.040513e-001,-7.040513e-001,-2.081785e+000,-3.012157e+000,5.961463e-001,-7.815875e-001,-1.711960e+000,-3.951996e-005,-3.951996e-005,,,,,,,,,,,,,,,,,,,,
1524300931.073,,0.000000e+000,5.399579e+001,5.398942e+001,1,0,2.967742e+000,0.000000e+000,2.055390e-001,2.055390e-001,-1.118663e+000,-2.088124e+000,1.310981e+000,-1.322069e-002,-9.826819e-001,-1.860190e-005,-1.860190e-005,,,,,,,,,,,,,,,,,,,,
1524300943.473,,0.000000e+000,5.398942e+001,5.399707e+001,1,0,3.096774e+000,0.000000e+000,1.083085e+000,1.083085e+000,-1.856220e-001,-1.195641e+000,1.960215e+000,6.915076e-001,-3.185112e-001,1.638437e-006,1.638437e-006,,,,,,,,,,,,,,,,,,,,
1524300955.963,,0.000000e+000,5.399707e+001,5.399961e+001,1,0,3.225806e+000,0.000000e+000,1.911650e+000,1.911650e+000,7.022015e-001,-3.589638e-001,2.512795e+000,1.303346e+000,2.421811e-001,2.079934e-005,2.079934e-005,,,,,,,,,,,,,,,,,,,,
1524300968.463,,0.000000e+000,5.399961e+001,5.399834e+001,1,0,3.354839e+000,0.000000e+000,2.669413e+000,2.669413e+000,1.519069e+000,4.153175e-001,2.933903e+000,1.783558e+000,6.798069e-001,3.842723e-005,3.842723e-005,,,,,,,,,,,,,,,,,,,,
1524300981.143,,0.000000e+000,5.400088e+001,5.399579e+001,1,0,3.483871e+000,0.000000e+000,3.277485e+000,3.277485e+000,2.178763e+000,1.041468e+000,3.192067e+000,2.093344e+000,9.560499e-001,5.260909e-005,5.260909e-005,,,,,,,,,,,,,,,,,,,,
1524300993.393,,0.000000e+000,5.399579e+001,5.399070e+001,1,0,3.612903e+000,0.000000e+000,3.729763e+000,3.729763e+000,2.690739e+000,1.503876e+000,3.248486e+000,2.209462e+000,1.022600e+000,6.337508e-005,6.337508e-005,,,,,,,,,,,,,,,,,,,,
1524301005.753,,0.000000e+000,5.399834e+001,5.399834e+001,1,0,3.741935e+000,0.000000e+000,4.011139e+000,4.011139e+000,3.026877e+000,1.803514e+000,3.136832e+000,2.152570e+000,9.292073e-001,7.030691e-005,7.030691e-005,,,,,,,,,,,,,,,,,,,,
1524301018.143,,0.000000e+000,5.399961e+001,5.399961e+001,1,0,3.870968e+000,0.000000e+000,4.079195e+000,4.079195e+000,3.159222e+000,1.887744e+000,2.884871e+000,1.964899e+000,6.934206e-001,7.258423e-005,7.258423e-005,,,,,,,,,,,,,,,,,,,,
1524301030.603,,0.000000e+000,5.399834e+001,5.399834e+001,1,0,4.000000e+000,0.000000e+000,3.993286e+000,3.993286e+000,3.134753e+000,1.839876e+000,2.569907e+000,1.711373e+000,4.164965e-001,7.154961e-005,7.154961e-005,,,,,,,,,,,,,,,,,,,,
1524301055.933,,0.000000e+000,5.399324e+001,5.399579e+001,1,0,0.000000e+000,0.000000e+000,3.125353e+000,3.125353e+000,9.857757e-001,9.857757e-001,3.853290e+000,1.713712e+000,1.713712e+000,4.285820e-005,4.285820e-005,,,,,,,,,,,,,,,,,,,,
1524301068.363,,0.000000e+000,5.399579e+001,5.399579e+001,1,0,1.290323e-001,0.000000e+000,3.277485e+000,3.277485e+000,1.193116e+000,1.151226e+000,4.054132e+000,1.969762e+000,1.927873e+000,4.687650e-005,4.687650e-005,,,,,,,,,,,,,,,,,,,,
1524301080.833,,0.000000e+000,5.399579e+001,5.399834e+001,1,0,2.580645e-001,0.000000e+000,3.535210e+000,3.535210e+000,1.505531e+000,1.421243e+000,4.185861e+000,2.156181e+000,2.071894e+000,5.328636e-005,5.328636e-005,,,,,,,,,,,,,,,,,,,,
1524301093.593,,0.000000e+000,5.399834e+001,5.399579e+001,1,0,3.870968e-001,0.000000e+000,3.721676e+000,3.721676e+000,1.750132e+000,1.624230e+000,4.188864e+000,2.217321e+000,2.091419e+000,5.810331e-005,5.810331e-005,,,,,,,,,,,,,,,,,,,,
1524301106.333,,0.000000e+000,5.400088e+001,5.399324e+001,1,0,5.161290e-001,0.000000e+000,3.822080e+000,3.822080e+000,1.889217e+000,1.720891e+000,4.031344e+000,2.098481e+000,1.930155e+000,6.059329e-005,6.059329e-005,,,,,,,,,,,,,,,,,,,,
1524301119.193,,0.000000e+000,5.399834e+001,5.400088e+001,1,0,6.451613e-001,0.000000e+000,3.761044e+000,3.761044e+000,1.883566e+000,1.671248e+000,3.669047e+000,1.791569e+000,1.579251e+000,5.990860e-005,5.990860e-005,,,,,,,,,,,,,,,,,,,,
1524301132.053,,0.000000e+000,5.400088e+001,5.399452e+001,1,0,7.741935e-001,0.000000e+000,3.532769e+000,3.532769e+000,1.704094e+000,1.446383e+000,3.138749e+000,1.310073e+000,1.052363e+000,5.533690e-005,5.533690e-005,,,,,,,,,,,,,,,,,,,,
1524301144.813,,0.000000e+000,5.399452e+001,5.399834e+001,1,0,9.032258e-001,0.000000e+000,3.135882e+000,3.135882e+000,1.378358e+000,1.081542e+000,2.452635e+000,6.951107e-001,3.982952e-001,4.735120e-005,4.735120e-005,,,,,,,,,,,,,,,,,,,,
1524301157.163,,0.000000e+000,5.399834e+001,5.398942e+001,1,0,1.032258e+000,0.000000e+000,2.556954e+000,2.556954e+000,8.600951e-001,5.199435e-001,1.683550e+000,-1.330912e-002,-3.534608e-001,3.515922e-005,3.515922e-005,,,,,,,,,,,,,,,,,,,,
1524301169.613,,0.000000e+000,5.399961e+001,5.399961e+001,1,0,1.161290e+000,0.000000e+000,1.866789e+000,1.866789e+000,2.296229e-001,-1.512159e-001,8.498666e-001,-7.872993e-001,-1.168138e+000,2.041478e-005,2.041478e-005,,,,,,,,,,,,,,,,,,,,
1524301182.443,,0.000000e+000,5.399707e+001,5.399834e+001,1,0,1.290323e+000,0.000000e+000,1.046464e+000,1.046464e+000,-5.379621e-001,-9.612362e-001,-2.629928e-002,-1.610725e+000,-2.033999e+000,2.641256e-006,2.641256e-006,,,,,,,,,,,,,,,,,,,,
1524301194.983,,0.000000e+000,5.398434e+001,5.399961e+001,1,0,1.419355e+000,0.000000e+000,1.567101e-001,1.567101e-001,-1.371115e+000,-1.835386e+000,-9.340677e-001,-2.461893e+000,-2.926164e+000,-1.662425e-005,-1.662425e-005,,,,,,,,,,,,,,,,,,,,
1524301207.873,,0.000000e+000,5.399961e+001,5.400088e+001,1,0,1.548387e+000,0.000000e+000,-7.257191e-001,-7.257191e-001,-2.196957e+000,-2.709764e+000,-1.839901e+000,-3.311139e+000,-3.823946e+000,-3.567497e-005,-3.567497e-005,,,,,,,,,,,,,,,,,,,,
1524301220.503,,0.000000e+000,5.400088e+001,5.399961e+001,1,0,1.677419e+000,0.000000e+000,-1.654688e+000,-1.654688e+000,-3.068490e+000,-3.614130e+000,-2.677076e+000,-4.090877e+000,-4.636518e+000,-5.581092e-005,-5.581092e-005,,,,,,,,,,,,,,,,,,,,
1524301233.123,,0.000000e+000,5.399961e+001,5.399707e+001,1,0,1.806452e+000,0.000000e+000,-2.523995e+000,-2.523995e+000,-3.881382e+000,-4.474609e+000,-3.343684e+000,-4.701071e+000,-5.294298e+000,-7.459674e-005,-7.459674e-005,,,,,,,,,,,,,,,,,,,,
1524301245.793,,0.000000e+000,5.399707e+001,5.400216e+001,1,0,1.935484e+000,0.000000e+000,-3.266957e+000,-3.266957e+000,-4.569983e+000,-5.204667e+000,-3.741218e+000,-5.044244e+000,-5.678928e+000,-9.061203e-005,-9.061203e-005,,,,,,,,,,,,,,,,,,,,
1524301258.144,,0.000000e+000,5.399579e+001,5.399324e+001,1,0,2.064516e+000,0.000000e+000,-3.789884e+000,-3.789884e+000,-5.031379e+000,-5.706354e+000,-3.804440e+000,-5.045935e+000,-5.720910e+000,-1.015499e-004,-1.015499e-004,,,,,,,,,,,,,,,,,,,,
1524301270.914,,0.000000e+000,5.399324e+001,5.399324e+001,1,0,2.193548e+000,0.000000e+000,-4.032807e+000,-4.032807e+000,-5.221600e+000,-5.941098e+000,-3.521697e+000,-4.710489e+000,-5.429988e+000,-1.064209e-004,-1.064209e-004,,,,,,,,,,,,,,,,,,,,
1524301283.834,,0.000000e+000,5.399834e+001,5.399707e+001,1,0,2.322581e+000,0.000000e+000,-3.953308e+000,-3.953308e+000,-5.082525e+000,-5.840348e+000,-2.969771e+000,-4.098989e+000,-4.856812e+000,-1.039338e-004,-1.039338e-004,,,,,,,,,,,,,,,,,,,,
1524301296.794,,0.000000e+000,5.400470e+001,5.399834e+001,1,0,2.451613e+000,0.000000e+000,-3.566034e+000,-3.566034e+000,-4.635769e+000,-5.440047e+000,-2.250122e+000,-3.319857e+000,-4.124136e+000,-9.458866e-005,-9.458866e-005,,,,,,,,,,,,,,,,,,,,
1524301308.954,,0.000000e+000,5.399452e+001,5.400343e+001,1,0,2.580645e+000,0.000000e+000,-2.934005e+000,-2.934005e+000,-3.945512e+000,-4.782772e+000,-1.457506e+000,-2.469013e+000,-3.306273e+000,-7.976613e-005,-7.976613e-005,,,,,,,,,,,,,,,,,,,,
1524301321.624,,0.000000e+000,5.399834e+001,5.399579e+001,1,0,2.709677e+000,0.000000e+000,-2.115968e+000,-2.115968e+000,-3.067554e+000,-3.956528e+000,-6.642081e-001,-1.615794e+000,-2.504768e+000,-6.079736e-005,-6.079736e-005,,,,,,,,,,,,,,,,,,,,
1524301334.664,,0.000000e+000,5.399452e+001,5.400598e+001,1,0,2.838710e+000,0.000000e+000,-1.205768e+000,-1.205768e+000,-2.101619e+000,-3.026836e+000,1.052540e-001,-7.905970e-001,-1.715814e+000,-3.981256e-005,-3.981256e-005,,,,,,,,,,,,,,,,,,,,
1524301347.234,,0.000000e+000,5.399707e+001,5.400088e+001,1,0,2.967742e+000,0.000000e+000,-2.769513e-001,-2.769513e-001,-1.120685e+000,-2.088657e+000,8.303491e-001,-1.338492e-002,-9.813570e-001,-1.850182e-005,-1.850182e-005,,,,,,,,,,,,,,,,,,,,
1524301360.064,,0.000000e+000,5.399324e+001,5.399324e+001,1,0,3.096774e+000,0.000000e+000,6.062409e-001,6.062409e-001,-1.769834e-001,-1.191643e+000,1.483178e+000,6.999537e-001,-3.147054e-001,1.942806e-006,1.942806e-006,,,,,,,,,,,,,,,,,,,,
1524301372.744,,0.000000e+000,5.399324e+001,5.398815e+001,1,0,3.225806e+000,0.000000e+000,1.450828e+000,1.450828e+000,7.264324e-001,-3.322116e-001,2.044160e+000,1.319764e+000,2.611202e-001,2.149517e-005,2.149517e-005,,,,,,,,,,,,,,,,,,,,
1524301385.174,,0.000000e+000,5.398815e+001,5.399579e+001,1,0,3.354839e+000,0.000000e+000,2.206455e+000,2.206455e+000,1.544820e+000,4.384060e-001,2.467252e+000,1.805618e+000,6.992040e-001,3.912426e-005,3.912426e-005,,,,,,,,,,,,,,,,,,,,
1524301397.964,,0.000000e+000,5.400470e+001,5.399579e+001,1,0,3.483871e+000,0.000000e+000,2.810712e+000,2.810712e+000,2.201134e+000,1.058864e+000,2.725106e+000,2.115529e+000,9.732581e-001,5.319546e-005,5.319546e-005,,,,,,,,,,,,,,,,,,,,
1524301410.604,,0.000000e+000,5.399579e+001,5.399579e+001,1,0,3.612903e+000,0.000000e+000,3.251545e+000,3.251545e+000,2.703081e+000,1.514929e+000,2.783340e+000,2.234876e+000,1.046724e+000,6.377039e-005,6.377039e-005,,,,,,,,,,,,,,,,,,,,
1524301423.104,,0.000000e+000,5.399579e+001,5.398815e+001,1,0,3.741935e+000,0.000000e+000,3.531090e+000,3.531090e+000,3.029177e+000,1.807830e+000,2.674536e+000,2.172623e+000,9.512757e-001,7.047609e-005,7.047609e-005,,,,,,,,,,,,,,,,,,,,
1524301435.704,,0.000000e+000,5.398815e+001,5.399198e+001,1,0,3.870968e+000,0.000000e+000,3.608606e+000,3.608606e+000,3.164526e+000,1.900260e+000,2.434347e+000,1.990267e+000,7.260004e-001,7.289844e-005,7.289844e-005,,,,,,,,,,,,,,,,,,,,
1524301447.924,,0.000000e+000,5.399198e+001,5.400088e+001,1,0,4.000000e+000,0.000000e+000,3.517205e+000,3.517205e+000,3.140750e+000,1.816647e+000,2.106693e+000,1.730238e+000,4.061346e-001,7.158868e-005,7.158868e-005,,,,,,,,,,,,,,,,,,,,
1524301473.084,,0.000000e+000,5.399198e+001,5.400343e+001,1,0,0.000000e+000,0.000000e+000,2.667430e+000,2.667430e+000,1.000912e+000,1.000912e+000,3.399694e+000,1.733176e+000,1.733176e+000,4.347172e-005,4.347172e-005,,,,,,,,,,,,,,,,,,,,
1524301485.944,,0.000000e+000,5.400343e+001,5.399579e+001,1,0,1.290323e-001,0.000000e+000,2.834058e+000,2.834058e+000,1.224268e+000,1.181665e+000,3.603056e+000,1.993266e+000,1.950663e+000,4.785999e-005,4.785999e-005,,,,,,,,,,,,,,,,,,,,
1524301498.864,,0.000000e+000,5.399579e+001,5.399961e+001,1,0,2.580645e-001,0.000000e+000,3.080339e+000,3.080339e+000,1.532567e+000,1.448055e+000,3.727174e+000,2.179402e+000,2.094890e+000,5.403336e-005,5.403336e-005,,,,,,,,,,,,,,,,,,,,
1524301511.474,,0.000000e+000,5.399961e+001,5.399579e+001,1,0,3.870968e-001,0.000000e+000,3.264820e+000,3.264820e+000,1.768693e+000,1.641541e+000,3.735945e+000,2.239818e+000,2.112666e+000,5.870908e-005,5.870908e-005,,,,,,,,,,,,,,,,,,,,
1524301524.054,,0.000000e+000,5.399579e+001,5.399198e+001,1,0,5.161290e-001,0.000000e+000,3.322042e+000,3.322042e+000,1.885209e+000,1.715539e+000,3.558203e+000,2.121370e+000,1.951700e+000,6.068294e-005,6.068294e-005,,,,,,,,,,,,,,,,,,,,
1524301536.704,,0.000000e+000,5.399834e+001,5.400470e+001,1,0,6.451613e-001,0.000000e+000,3.288624e+000,3.288624e+000,1.908509e+000,1.696614e+000,3.190276e+000,1.810160e+000,1.598265e+000,6.056871e-005,6.056871e-005,,,,,,,,,,,,,,,,,,,,
1524301548.954,,0.000000e+000,5.399452e+001,5.399961e+001,1,0,7.741935e-001,0.000000e+000,3.056077e+000,3.056077e+000,1.729572e+000,1.475672e+000,2.650953e+000,1.324448e+000,1.070548e+000,5.593902e-005,5.593902e-005,,,,,,,,,,,,,,,,,,,,
1524301561.524,,0.000000e+000,5.399707e+001,5.399452e+001,1,0,9.032258e-001,0.000000e+000,2.648966e+000,2.648966e+000,1.381966e+000,1.083536e+000,1.969426e+000,7.024249e-001,4.039952e-001,4.757863e-005,4.757863e-005,,,,,,,,,,,,,,,,,,,,
1524301573.804,,0.000000e+000,5.399579e+001,5.399324e+001,1,0,1.032258e+000,0.000000e+000,2.078279e+000,2.078279e+000,8.712741e-001,5.321513e-001,1.193557e+000,-1.344779e-002,-3.525705e-001,3.551117e-005,3.551117e-005,,,,,,,,,,,,,,,,,,,,
1524301586.624,,0.000000e+000,5.400088e+001,5.399961e+001,1,0,1.161290e+000,0.000000e+000,1.342794e+000,1.342794e+000,1.961724e-001,-1.853027e-001,3.512757e-001,-7.953458e-001,-1.176821e+000,1.978833e-005,1.978833e-005,,,,,,,,,,,,,,,,,,,,
1524301598.764,,0.000000e+000,5.400725e+001,5.399707e+001,1,0,1.290323e+000,0.000000e+000,5.404745e-001,5.404745e-001,-5.506933e-001,-9.730815e-001,-5.354432e-001,-1.626611e+000,-2.048999e+000,2.459874e-006,2.459874e-006,,,,,,,,,,,,,,,,,,,,
1524301611.454,,0.000000e+000,5.399070e+001,5.399070e+001,1,0,1.419355e+000,0.000000e+000,-3.482109e-001,-3.482109e-001,-1.384819e+000,-1.849537e+000,-1.452661e+000,-2.489269e+000,-2.953987e+000,-1.680338e-005,-1.680338e-005,,,,,,,,,,,,,,,,,,,,
1524301623.644,,0.000000e+000,5.399961e+001,5.399834e+001,1,0,1.548387e+000,0.000000e+000,-1.247883e+000,-1.247883e+000,-2.232583e+000,-2.739696e+000,-2.362287e+000,-3.346988e+000,-3.854100e+000,-3.637472e-005,-3.637472e-005,,,,,,,,,,,,,,,,,,,,
1524301636.224,,0.000000e+000,5.399198e+001,5.400852e+001,1,0,1.677419e+000,0.000000e+000,-2.178378e+000,-2.178378e+000,-3.105917e+000,-3.656218e+000,-3.206250e+000,-4.133789e+000,-4.684090e+000,-5.651652e-005,-5.651652e-005,,,,,,,,,,,,,,,,,,,,
1524301636.224,,0.000000e+000,5.399198e+001,5.400852e+001,1,0,4.000000e+000,0.000000e+000,3.343557e+000,3.343557e+000,3.177974e+000,1.865717e+000,1.905905e+000,1.740322e+000,4.280648e-001,7.257448e-005,7.257448e-005,,,,,,,,,,,,,,,,,,,,