File: Experimental Raw Data/MFn1 TRM/MFn1_TRMac_36K_0.02Kmin_VRMde_35K.dc.dat
[Header]
TITLE,MPMS DC Measurement
BYAPP,MPMS Measurement,2.1,Summary
FILEOPENTIME, 1524405095.676000 4/22/2018, 7:51:35 AM

INFO, APPNAME, MPMS MultiVu Application, Revision 1.61,  Build 082

INFO, NAME, MFn1
INFO, WEIGHT, 1.000
INFO, AREA, 1.000
INFO, LENGTH, 1.000
INFO, SHAPE, 0
INFO, COMMENT,
INFO, SEQUENCE FILE: TRMac_36K_0.02Kmin_VRMde_35K.seq


INFO, BACKGROUND DATA FILE:, None


STARTUPAXIS,X,4,LINEAR,AUTO,0.000000,0.000000
STARTUPAXIS,Y1,5,LINEAR,AUTO,0.000000,0.000000


STARTUPGROUP,Longitudinal
FIELDGROUP,Longitudinal,1,2,3,4,5,6,7,8,9,15,16,17,18,27,28
FIELDGROUP,Transverse,1,2,3,4,10,11,12,13,14,19,20,21,22,27,28

PLOT_APPEARANCE,ALL,HORZ_GRID_ON,VERT_GRID_ON,MARKERS_AND_LINES

[Data]
Time,Comment,Field (Oe),Temperature (K),Long Moment (emu),Long Scan Std Dev,Long Algorithm,Long Reg Fit,Long Percent Error (%),Trans Moment (emu),Trans Scan Std Dev,Trans Algorithm,Trans Reg Fit,Trans Percent Error (%),Long Moment [w/o ABS] (emu),Long Scan Std Dev [w/o ABS],Long Reg Fit [w/o ABS],Long Percent Error [w/o ABS] (%),Trans Moment [w/o ABS] (emu),Trans Scan Std Dev [w/o ABS],Trans Reg Fit [w/o ABS],Trans Percent Error [w/o ABS] (%),Points per Scan,Scans per Measurement,Scan Length (cm),Delta Temp (K),Rot Position (deg),Error,EC Comp. Running,Using ABS,
1524405095.673,,0.000000e+000,3.498113e+001,-3.015675e-005,0.000000e+000,2,9.774330e-001,0.000000e+000,,,,,,,,,,,,,,32,1,4.000000e+000,2.338409e-003,0.000000e+000,0,,0,
1524405134.481,,0.000000e+000,3.499246e+001,-2.551174e-005,0.000000e+000,2,9.672454e-001,0.000000e+000,,,,,,,,,,,,,,32,1,4.000000e+000,4.688263e-003,0.000000e+000,0,,0,
1524405173.152,,0.000000e+000,3.499989e+001,-2.309110e-005,0.000000e+000,2,9.644226e-001,0.000000e+000,,,,,,,,,,,,,,32,1,4.000000e+000,7.781982e-004,0.000000e+000,0,,0,
1524405211.912,,0.000000e+000,3.499793e+001,-2.167125e-005,0.000000e+000,2,9.596778e-001,0.000000e+000,,,,,,,,,,,,,,32,1,4.000000e+000,3.131866e-003,0.000000e+000,0,,0,
1524405249.940,,0.000000e+000,3.499754e+001,-2.050305e-005,0.000000e+000,2,9.592031e-001,0.000000e+000,,,,,,,,,,,,,,32,1,4.000000e+000,2.349854e-003,0.000000e+000,0,,0,
1524405288.003,,0.000000e+000,3.499754e+001,-1.969272e-005,0.000000e+000,2,9.557652e-001,0.000000e+000,,,,,,,,,,,,,,32,1,4.000000e+000,2.349854e-003,0.000000e+000,0,,0,
1524405326.479,,0.000000e+000,3.499833e+001,-1.889759e-005,0.000000e+000,2,9.554942e-001,0.000000e+000,,,,,,,,,,,,,,32,1,4.000000e+000,2.349854e-003,0.000000e+000,0,,0,
1524405364.570,,0.000000e+000,3.499950e+001,-1.823441e-005,0.000000e+000,2,9.538532e-001,0.000000e+000,,,,,,,,,,,,,,32,1,4.000000e+000,3.120422e-003,0.000000e+000,0,,0,
1524405403.118,,0.000000e+000,3.499793e+001,-1.768463e-005,0.000000e+000,2,9.513302e-001,0.000000e+000,,,,,,,,,,,,,,32,1,4.000000e+000,1.567841e-003,0.000000e+000,0,,0,
1524405440.651,,0.000000e+000,3.499794e+001,-1.717121e-005,0.000000e+000,2,9.503897e-001,0.000000e+000,,,,,,,,,,,,,,32,1,4.000000e+000,0.000000e+000,0.000000e+000,0,,0,
1524405477.799,,0.000000e+000,3.499754e+001,-1.673737e-005,0.000000e+000,2,9.497833e-001,0.000000e+000,,,,,,,,,,,,,,32,1,4.000000e+000,2.349854e-003,0.000000e+000,0,,0,
1524405515.719,,0.000000e+000,3.499872e+001,-1.628273e-005,0.000000e+000,2,9.470940e-001,0.000000e+000,,,,,,,,,,,,,,32,1,4.000000e+000,1.560211e-003,0.000000e+000,0,,0,
1524405554.047,,0.000000e+000,3.499754e+001,-1.590937e-005,0.000000e+000,2,9.483160e-001,0.000000e+000,,,,,,,,,,,,,,32,1,4.000000e+000,7.896423e-004,0.000000e+000,0,,0,
1524405591.908,,0.000000e+000,3.499677e+001,-1.558996e-005,0.000000e+000,2,9.451758e-001,0.000000e+000,,,,,,,,,,,,,,32,1,4.000000e+000,3.910065e-003,0.000000e+000,0,,0,
1524405629.726,,0.000000e+000,3.500067e+001,-1.526239e-005,0.000000e+000,2,9.471989e-001,0.000000e+000,,,,,,,,,,,,,,32,1,4.000000e+000,2.338409e-003,0.000000e+000,0,,0,
1524405667.514,,0.000000e+000,3.499715e+001,-1.497224e-005,0.000000e+000,2,9.447221e-001,0.000000e+000,,,,,,,,,,,,,,32,1,4.000000e+000,3.128052e-003,0.000000e+000,0,,0,
1524405705.317,,0.000000e+000,3.499793e+001,-1.464791e-005,0.000000e+000,2,9.439192e-001,0.000000e+000,,,,,,,,,,,,,,32,1,4.000000e+000,1.567841e-003,0.000000e+000,0,,0,
1524405742.765,,0.000000e+000,3.499793e+001,-1.440240e-005,0.000000e+000,2,9.425502e-001,0.000000e+000,,,,,,,,,,,,,,32,1,4.000000e+000,1.567841e-003,0.000000e+000,0,,0,
1524405780.801,,0.000000e+000,3.499872e+001,-1.411238e-005,0.000000e+000,2,9.391866e-001,0.000000e+000,,,,,,,,,,,,,,32,1,4.000000e+000,1.560211e-003,0.000000e+000,0,,0,
1524405819.159,,0.000000e+000,3.499638e+001,-1.389709e-005,0.000000e+000,2,9.394000e-001,0.000000e+000,,,,,,,,,,,,,,32,1,4.000000e+000,3.131866e-003,0.000000e+000,0,,0,
1524405856.934,,0.000000e+000,3.499794e+001,-1.366199e-005,0.000000e+000,2,9.393413e-001,0.000000e+000,,,,,,,,,,,,,,32,1,4.000000e+000,0.000000e+000,0.000000e+000,0,,0,
1524405894.965,,0.000000e+000,3.499911e+001,-1.343581e-005,0.000000e+000,2,9.376293e-001,0.000000e+000,,,,,,,,,,,,,,32,1,4.000000e+000,7.820129e-004,0.000000e+000,0,,0,
1524405932.995,,0.000000e+000,3.499754e+001,-1.320874e-005,0.000000e+000,2,9.371884e-001,0.000000e+000,,,,,,,,,,,,,,32,1,4.000000e+000,7.896423e-004,0.000000e+000,0,,0,
1524405970.806,,0.000000e+000,3.499676e+001,-1.298068e-005,0.000000e+000,2,9.359643e-001,0.000000e+000,,,,,,,,,,,,,,32,1,4.000000e+000,7.820129e-004,0.000000e+000,0,,0,
1524406009.109,,0.000000e+000,3.499833e+001,-1.278202e-005,0.000000e+000,2,9.343649e-001,0.000000e+000,,,,,,,,,,,,,,32,1,4.000000e+000,7.781982e-004,0.000000e+000,0,,0,
1524406047.167,,0.000000e+000,3.499833e+001,-1.259470e-005,0.000000e+000,2,9.340544e-001,0.000000e+000,,,,,,,,,,,,,,32,1,4.000000e+000,2.349854e-003,0.000000e+000,0,,0,
1524406085.258,,0.000000e+000,3.499833e+001,-1.242088e-005,0.000000e+000,2,9.331317e-001,0.000000e+000,,,,,,,,,,,,,,32,1,4.000000e+000,7.781982e-004,0.000000e+000,0,,0,
1524406123.288,,0.000000e+000,3.499715e+001,-1.226640e-005,0.000000e+000,2,9.336718e-001,0.000000e+000,,,,,,,,,,,,,,32,1,4.000000e+000,0.000000e+000,0.000000e+000,0,,0,
1524406161.144,,0.000000e+000,3.499871e+001,-1.209826e-005,0.000000e+000,2,9.320309e-001,0.000000e+000,,,,,,,,,,,,,,32,1,4.000000e+000,3.128052e-003,0.000000e+000,0,,0,
1524406199.174,,0.000000e+000,3.499833e+001,-1.192525e-005,0.000000e+000,2,9.294803e-001,0.000000e+000,,,,,,,,,,,,,,32,1,4.000000e+000,7.781982e-004,0.000000e+000,0,,0,
1524406237.247,,0.000000e+000,3.499872e+001,-1.177646e-005,0.000000e+000,2,9.287079e-001,0.000000e+000,,,,,,,,,,,,,,32,1,4.000000e+000,0.000000e+000,0.000000e+000,0,,0,
1524406275.518,,0.000000e+000,3.499754e+001,-1.161025e-005,0.000000e+000,2,9.293193e-001,0.000000e+000,,,,,,,,,,,,,,32,1,4.000000e+000,7.896423e-004,0.000000e+000,0,,0,
1524406313.581,,0.000000e+000,3.499793e+001,-1.149623e-005,0.000000e+000,2,9.279042e-001,0.000000e+000,,,,,,,,,,,,,,32,1,4.000000e+000,1.567841e-003,0.000000e+000,0,,0,
1524406351.417,,0.000000e+000,3.499794e+001,-1.134668e-005,0.000000e+000,2,9.275199e-001,0.000000e+000,,,,,,,,,,,,,,32,1,4.000000e+000,0.000000e+000,0.000000e+000,0,,0,
1524406402.432,,0.000000e+000,3.499871e+001,-1.115327e-005,0.000000e+000,2,9.255581e-001,0.000000e+000,,,,,,,,,,,,,,32,1,4.000000e+000,3.128052e-003,0.000000e+000,0,,0,
1524406440.538,,0.000000e+000,3.499871e+001,-1.104706e-005,0.000000e+000,2,9.225246e-001,0.000000e+000,,,,,,,,,,,,,,32,1,4.000000e+000,3.128052e-003,0.000000e+000,0,,0,
1524406478.936,,0.000000e+000,3.499872e+001,-1.090605e-005,0.000000e+000,2,9.259660e-001,0.000000e+000,,,,,,,,,,,,,,32,1,4.000000e+000,1.560211e-003,0.000000e+000,0,,0,
1524406516.429,,0.000000e+000,3.499754e+001,-1.082872e-005,0.000000e+000,2,9.229521e-001,0.000000e+000,,,,,,,,,,,,,,32,1,4.000000e+000,7.896423e-004,0.000000e+000,0,,0,
1524406554.265,,0.000000e+000,3.499911e+001,-1.067080e-005,0.000000e+000,2,9.229408e-001,0.000000e+000,,,,,,,,,,,,,,32,1,4.000000e+000,2.338409e-003,0.000000e+000,0,,0,
1524406592.090,,0.000000e+000,3.499754e+001,-1.054530e-005,0.000000e+000,2,9.237107e-001,0.000000e+000,,,,,,,,,,,,,,32,1,4.000000e+000,7.896423e-004,0.000000e+000,0,,0,
1524406629.561,,0.000000e+000,3.499911e+001,-1.044974e-005,0.000000e+000,2,9.165168e-001,0.000000e+000,,,,,,,,,,,,,,32,1,4.000000e+000,7.820129e-004,0.000000e+000,0,,0,
1524406667.884,,0.000000e+000,3.499950e+001,-1.033766e-005,0.000000e+000,2,9.201689e-001,0.000000e+000,,,,,,,,,,,,,,32,1,4.000000e+000,0.000000e+000,0.000000e+000,0,,0,
1524406705.747,,0.000000e+000,3.499950e+001,-1.023590e-005,0.000000e+000,2,9.185085e-001,0.000000e+000,,,,,,,,,,,,,,32,1,4.000000e+000,1.560211e-003,0.000000e+000,0,,0,
1524406743.652,,0.000000e+000,3.499833e+001,-1.009257e-005,0.000000e+000,2,9.178662e-001,0.000000e+000,,,,,,,,,,,,,,32,1,4.000000e+000,2.349854e-003,0.000000e+000,0,,0,
1524406782.368,,0.000000e+000,3.499872e+001,-1.002133e-005,0.000000e+000,2,9.201984e-001,0.000000e+000,,,,,,,,,,,,,,32,1,4.000000e+000,0.000000e+000,0.000000e+000,0,,0,
1524406820.568,,0.000000e+000,3.499911e+001,-9.933360e-006,0.000000e+000,2,9.156855e-001,0.000000e+000,,,,,,,,,,,,,,32,1,4.000000e+000,7.820129e-004,0.000000e+000,0,,0,
1524406858.344,,0.000000e+000,3.499833e+001,-9.836893e-006,0.000000e+000,2,9.172738e-001,0.000000e+000,,,,,,,,,,,,,,32,1,4.000000e+000,7.781982e-004,0.000000e+000,0,,0,
1524406896.717,,0.000000e+000,3.499872e+001,-9.733815e-006,0.000000e+000,2,9.171365e-001,0.000000e+000,,,,,,,,,,,,,,32,1,4.000000e+000,1.560211e-003,0.000000e+000,0,,0,
1524406934.055,,0.000000e+000,3.499872e+001,-9.663117e-006,0.000000e+000,2,9.143894e-001,0.000000e+000,,,,,,,,,,,,,,32,1,4.000000e+000,0.000000e+000,0.000000e+000,0,,0,
1524406972.021,,0.000000e+000,3.499833e+001,-9.503649e-006,0.000000e+000,2,9.148015e-001,0.000000e+000,,,,,,,,,,,,,,32,1,4.000000e+000,2.349854e-003,0.000000e+000,0,,0,
1524407010.976,,0.000000e+000,3.499833e+001,-9.433099e-006,0.000000e+000,2,9.138715e-001,0.000000e+000,,,,,,,,,,,,,,32,1,4.000000e+000,2.349854e-003,0.000000e+000,0,,0,
1524407049.079,,0.000000e+000,3.499911e+001,-9.371680e-006,0.000000e+000,2,9.122242e-001,0.000000e+000,,,,,,,,,,,,,,32,1,4.000000e+000,7.820129e-004,0.000000e+000,0,,0,
1524407086.042,,0.000000e+000,3.499793e+001,-9.276447e-006,0.000000e+000,2,9.138812e-001,0.000000e+000,,,,,,,,,,,,,,32,1,4.000000e+000,1.567841e-003,0.000000e+000,0,,0,
1524407123.905,,0.000000e+000,3.499872e+001,-9.174211e-006,0.000000e+000,2,9.094443e-001,0.000000e+000,,,,,,,,,,,,,,32,1,4.000000e+000,1.560211e-003,0.000000e+000,0,,0,
1524407161.676,,0.000000e+000,3.499833e+001,-9.114485e-006,0.000000e+000,2,9.117349e-001,0.000000e+000,,,,,,,,,,,,,,32,1,4.000000e+000,7.781982e-004,0.000000e+000,0,,0,
1524407199.799,,0.000000e+000,3.499950e+001,-9.025506e-006,0.000000e+000,2,9.089802e-001,0.000000e+000,,,,,,,,,,,,,,32,1,4.000000e+000,0.000000e+000,0.000000e+000,0,,0,
1524407237.857,,0.000000e+000,3.499833e+001,-8.955019e-006,0.000000e+000,2,9.086007e-001,0.000000e+000,,,,,,,,,,,,,,32,1,4.000000e+000,7.781982e-004,0.000000e+000,0,,0,
1524407275.928,,0.000000e+000,3.499872e+001,-8.883080e-006,0.000000e+000,2,9.097014e-001,0.000000e+000,,,,,,,,,,,,,,32,1,4.000000e+000,1.560211e-003,0.000000e+000,0,,0,
1524407313.978,,0.000000e+000,3.499911e+001,-8.787481e-006,0.000000e+000,2,9.059858e-001,0.000000e+000,,,,,,,,,,,,,,32,1,4.000000e+000,7.820129e-004,0.000000e+000,0,,0,
1524407352.056,,0.000000e+000,3.499872e+001,-8.742238e-006,0.000000e+000,2,9.098517e-001,0.000000e+000,,,,,,,,,,,,,,32,1,4.000000e+000,1.560211e-003,0.000000e+000,0,,0,
1524407389.922,,0.000000e+000,3.499911e+001,-8.595667e-006,0.000000e+000,2,9.044650e-001,0.000000e+000,,,,,,,,,,,,,,32,1,4.000000e+000,7.820129e-004,0.000000e+000,0,,0,
1524407428.177,,0.000000e+000,3.499989e+001,-8.543695e-006,0.000000e+000,2,9.041281e-001,0.000000e+000,,,,,,,,,,,,,,32,1,4.000000e+000,7.781982e-004,0.000000e+000,0,,0,
1524407465.925,,0.000000e+000,3.499911e+001,-8.514802e-006,0.000000e+000,2,9.050851e-001,0.000000e+000,,,,,,,,,,,,,,32,1,4.000000e+000,2.338409e-003,0.000000e+000,0,,0,
1524407503.988,,0.000000e+000,3.499715e+001,-8.385198e-006,0.000000e+000,2,9.065437e-001,0.000000e+000,,,,,,,,,,,,,,32,1,4.000000e+000,0.000000e+000,0.000000e+000,0,,0,
1524407541.919,,0.000000e+000,3.499911e+001,-8.337600e-006,0.000000e+000,2,9.023508e-001,0.000000e+000,,,,,,,,,,,,,,32,1,4.000000e+000,7.820129e-004,0.000000e+000,0,,0,
1524407579.955,,0.000000e+000,3.499950e+001,-8.261482e-006,0.000000e+000,2,9.036750e-001,0.000000e+000,,,,,,,,,,,,,,32,1,4.000000e+000,0.000000e+000,0.000000e+000,0,,0,
1524407617.170,,0.000000e+000,3.499793e+001,-8.178922e-006,0.000000e+000,2,9.006959e-001,0.000000e+000,,,,,,,,,,,,,,32,1,4.000000e+000,1.567841e-003,0.000000e+000,0,,0,
1524407654.848,,0.000000e+000,3.499872e+001,-8.113627e-006,0.000000e+000,2,9.016438e-001,0.000000e+000,,,,,,,,,,,,,,32,1,4.000000e+000,0.000000e+000,0.000000e+000,0,,0,
1524407692.856,,0.000000e+000,3.499793e+001,-8.099792e-006,0.000000e+000,2,9.034523e-001,0.000000e+000,,,,,,,,,,,,,,32,1,4.000000e+000,1.567841e-003,0.000000e+000,0,,0,
1524407730.929,,0.000000e+000,3.499989e+001,-8.007841e-006,0.000000e+000,2,8.988093e-001,0.000000e+000,,,,,,,,,,,,,,32,1,4.000000e+000,2.342224e-003,0.000000e+000,0,,0,
1524407768.195,,0.000000e+000,3.499833e+001,-7.936068e-006,0.000000e+000,2,8.991535e-001,0.000000e+000,,,,,,,,,,,,,,32,1,4.000000e+000,7.781982e-004,0.000000e+000,0,,0,
1524407806.265,,0.000000e+000,3.499677e+001,-7.862334e-006,0.000000e+000,2,8.979473e-001,0.000000e+000,,,,,,,,,,,,,,32,1,4.000000e+000,5.470276e-003,0.000000e+000,0,,0,
1524407844.379,,0.000000e+000,3.499911e+001,-7.791354e-006,0.000000e+000,2,8.945131e-001,0.000000e+000,,,,,,,,,,,,,,32,1,4.000000e+000,7.820129e-004,0.000000e+000,0,,0,
1524407882.414,,0.000000e+000,3.499793e+001,-7.751390e-006,0.000000e+000,2,8.949523e-001,0.000000e+000,,,,,,,,,,,,,,32,1,4.000000e+000,3.131866e-003,0.000000e+000,0,,0,
1524407920.105,,0.000000e+000,3.499911e+001,-7.692855e-006,0.000000e+000,2,8.956826e-001,0.000000e+000,,,,,,,,,,,,,,32,1,4.000000e+000,7.820129e-004,0.000000e+000,0,,0,
1524407958.075,,0.000000e+000,3.499872e+001,-7.624091e-006,0.000000e+000,2,8.946657e-001,0.000000e+000,,,,,,,,,,,,,,32,1,4.000000e+000,1.560211e-003,0.000000e+000,0,,0,
1524407996.138,,0.000000e+000,3.499911e+001,-7.564012e-006,0.000000e+000,2,8.933662e-001,0.000000e+000,,,,,,,,,,,,,,32,1,4.000000e+000,7.820129e-004,0.000000e+000,0,,0,
1524408034.236,,0.000000e+000,3.499911e+001,-7.499331e-006,0.000000e+000,2,8.906671e-001,0.000000e+000,,,,,,,,,,,,,,32,1,4.000000e+000,7.820129e-004,0.000000e+000,0,,0,
1524408071.417,,0.000000e+000,3.499950e+001,-7.429410e-006,0.000000e+000,2,8.903801e-001,0.000000e+000,,,,,,,,,,,,,,32,1,4.000000e+000,1.560211e-003,0.000000e+000,0,,0,
1524408109.075,,0.000000e+000,3.499833e+001,-7.420254e-006,0.000000e+000,2,8.957697e-001,0.000000e+000,,,,,,,,,,,,,,32,1,4.000000e+000,7.781982e-004,0.000000e+000,0,,0,
1524408147.600,,0.000000e+000,3.499911e+001,-7.330439e-006,0.000000e+000,2,8.900475e-001,0.000000e+000,,,,,,,,,,,,,,32,1,4.000000e+000,7.820129e-004,0.000000e+000,0,,0,
1524408185.648,,0.000000e+000,3.499872e+001,-7.273880e-006,0.000000e+000,2,8.930385e-001,0.000000e+000,,,,,,,,,,,,,,32,1,4.000000e+000,0.000000e+000,0.000000e+000,0,,0,
1524408223.234,,0.000000e+000,3.499793e+001,-7.204465e-006,0.000000e+000,2,8.884022e-001,0.000000e+000,,,,,,,,,,,,,,32,1,4.000000e+000,1.567841e-003,0.000000e+000,0,,0,
1524408261.320,,0.000000e+000,3.499872e+001,-7.160308e-006,0.000000e+000,2,8.885244e-001,0.000000e+000,,,,,,,,,,,,,,32,1,4.000000e+000,0.000000e+000,0.000000e+000,0,,0,
1524408299.395,,0.000000e+000,3.499872e+001,-7.114417e-006,0.000000e+000,2,8.846938e-001,0.000000e+000,,,,,,,,,,,,,,32,1,4.000000e+000,1.560211e-003,0.000000e+000,0,,0,
1524408336.963,,0.000000e+000,3.499989e+001,-7.072497e-006,0.000000e+000,2,8.860407e-001,0.000000e+000,,,,,,,,,,,,,,32,1,4.000000e+000,2.342224e-003,0.000000e+000,0,,0,
1524408375.476,,0.000000e+000,3.499833e+001,-7.001011e-006,0.000000e+000,2,8.890279e-001,0.000000e+000,,,,,,,,,,,,,,32,1,4.000000e+000,7.781982e-004,0.000000e+000,0,,0,
1524408413.547,,0.000000e+000,3.499793e+001,-7.003463e-006,0.000000e+000,2,8.868167e-001,0.000000e+000,,,,,,,,,,,,,,32,1,4.000000e+000,1.567841e-003,0.000000e+000,0,,0,
1524408451.167,,0.000000e+000,3.499911e+001,-6.917616e-006,0.000000e+000,2,8.852720e-001,0.000000e+000,,,,,,,,,,,,,,32,1,4.000000e+000,7.820129e-004,0.000000e+000,0,,0,
1524408489.688,,0.000000e+000,3.499794e+001,-6.875144e-006,0.000000e+000,2,8.886929e-001,0.000000e+000,,,,,,,,,,,,,,32,1,4.000000e+000,0.000000e+000,0.000000e+000,0,,0,
1524408527.314,,0.000000e+000,3.499872e+001,-6.807475e-006,0.000000e+000,2,8.830754e-001,0.000000e+000,,,,,,,,,,,,,,32,1,4.000000e+000,1.560211e-003,0.000000e+000,0,,0,
1524408566.389,,0.000000e+000,3.499989e+001,-6.782025e-006,0.000000e+000,2,8.818152e-001,0.000000e+000,,,,,,,,,,,,,,32,1,4.000000e+000,7.781982e-004,0.000000e+000,0,,0,
1524408604.035,,0.000000e+000,3.499911e+001,-6.690319e-006,0.000000e+000,2,8.800825e-001,0.000000e+000,,,,,,,,,,,,,,32,1,4.000000e+000,7.820129e-004,0.000000e+000,0,,0,
1524408641.740,,0.000000e+000,3.499911e+001,-6.642970e-006,0.000000e+000,2,8.799645e-001,0.000000e+000,,,,,,,,,,,,,,32,1,4.000000e+000,7.820129e-004,0.000000e+000,0,,0,
1524408679.088,,0.000000e+000,3.499872e+001,-6.647117e-006,0.000000e+000,2,8.833902e-001,0.000000e+000,,,,,,,,,,,,,,32,1,4.000000e+000,1.560211e-003,0.000000e+000,0,,0,
1524408717.056,,0.000000e+000,3.500067e+001,-6.596451e-006,0.000000e+000,2,8.825642e-001,0.000000e+000,,,,,,,,,,,,,,32,1,4.000000e+000,7.820129e-004,0.000000e+000,0,,0,
1524408755.247,,0.000000e+000,3.499872e+001,-6.568966e-006,0.000000e+000,2,8.794190e-001,0.000000e+000,,,,,,,,,,,,,,32,1,4.000000e+000,0.000000e+000,0.000000e+000,0,,0,
1524408793.312,,0.000000e+000,3.499950e+001,-6.502724e-006,0.000000e+000,2,8.808203e-001,0.000000e+000,,,,,,,,,,,,,,32,1,4.000000e+000,0.000000e+000,0.000000e+000,0,,0,
1524408831.820,,0.000000e+000,3.499872e+001,-6.441905e-006,0.000000e+000,2,8.769762e-001,0.000000e+000,,,,,,,,,,,,,,32,1,4.000000e+000,0.000000e+000,0.000000e+000,0,,0,
1524408869.913,,0.000000e+000,3.499911e+001,-6.446773e-006,0.000000e+000,2,8.761892e-001,0.000000e+000,,,,,,,,,,,,,,32,1,4.000000e+000,7.820129e-004,0.000000e+000,0,,0,
1524408907.534,,0.000000e+000,3.499872e+001,-6.368090e-006,0.000000e+000,2,8.762354e-001,0.000000e+000,,,,,,,,,,,,,,32,1,4.000000e+000,1.560211e-003,0.000000e+000,0,,0,
1524408945.602,,0.000000e+000,3.499911e+001,-6.354895e-006,0.000000e+000,2,8.743787e-001,0.000000e+000,,,,,,,,,,,,,,32,1,4.000000e+000,7.820129e-004,0.000000e+000,0,,0,
1524408983.578,,0.000000e+000,3.499872e+001,-6.274610e-006,0.000000e+000,2,8.775487e-001,0.000000e+000,,,,,,,,,,,,,,32,1,4.000000e+000,1.560211e-003,0.000000e+000,0,,0,
1524409020.976,,0.000000e+000,3.499911e+001,-6.213585e-006,0.000000e+000,2,8.703346e-001,0.000000e+000,,,,,,,,,,,,,,32,1,4.000000e+000,7.820129e-004,0.000000e+000,0,,0,
1524409058.164,,0.000000e+000,3.499872e+001,-6.182507e-006,0.000000e+000,2,8.703693e-001,0.000000e+000,,,,,,,,,,,,,,32,1,4.000000e+000,1.560211e-003,0.000000e+000,0,,0,
1524409095.802,,0.000000e+000,3.499872e+001,-6.151192e-006,0.000000e+000,2,8.733497e-001,0.000000e+000,,,,,,,,,,,,,,32,1,4.000000e+000,0.000000e+000,0.000000e+000,0,,0,
1524409133.880,,0.000000e+000,3.499950e+001,-6.115138e-006,0.000000e+000,2,8.710061e-001,0.000000e+000,,,,,,,,,,,,,,32,1,4.000000e+000,0.000000e+000,0.000000e+000,0,,0,
1524409172.356,,0.000000e+000,3.499950e+001,-6.063603e-006,0.000000e+000,2,8.692361e-001,0.000000e+000,,,,,,,,,,,,,,32,1,4.000000e+000,0.000000e+000,0.000000e+000,0,,0,
1524409210.439,,0.000000e+000,3.499872e+001,-6.039902e-006,0.000000e+000,2,8.718780e-001,0.000000e+000,,,,,,,,,,,,,,32,1,4.000000e+000,0.000000e+000,0.000000e+000,0,,0,
1524409248.089,,0.000000e+000,3.499833e+001,-5.987676e-006,0.000000e+000,2,8.648860e-001,0.000000e+000,,,,,,,,,,,,,,32,1,4.000000e+000,7.781982e-004,0.000000e+000,0,,0,
1524409286.180,,0.000000e+000,3.499911e+001,-5.948415e-006,0.000000e+000,2,8.695027e-001,0.000000e+000,,,,,,,,,,,,,,32,1,4.000000e+000,7.820129e-004,0.000000e+000,0,,0,
1524409324.233,,0.000000e+000,3.499872e+001,-5.900253e-006,0.000000e+000,2,8.666057e-001,0.000000e+000,,,,,,,,,,,,,,32,1,4.000000e+000,0.000000e+000,0.000000e+000,0,,0,
1524409362.288,,0.000000e+000,3.499950e+001,-5.861401e-006,0.000000e+000,2,8.618331e-001,0.000000e+000,,,,,,,,,,,,,,32,1,4.000000e+000,1.560211e-003,0.000000e+000,0,,0,
1524409400.354,,0.000000e+000,3.499872e+001,-5.793926e-006,0.000000e+000,2,8.611945e-001,0.000000e+000,,,,,,,,,,,,,,32,1,4.000000e+000,0.000000e+000,0.000000e+000,0,,0,
1524409438.349,,0.000000e+000,3.499989e+001,-5.772450e-006,0.000000e+000,2,8.633900e-001,0.000000e+000,,,,,,,,,,,,,,32,1,4.000000e+000,7.781982e-004,0.000000e+000,0,,0,
1524409476.007,,0.000000e+000,3.499754e+001,-5.738713e-006,0.000000e+000,2,8.625973e-001,0.000000e+000,,,,,,,,,,,,,,32,1,4.000000e+000,3.910065e-003,0.000000e+000,0,,0,
1524409514.058,,0.000000e+000,3.499871e+001,-5.767003e-006,0.000000e+000,2,8.618792e-001,0.000000e+000,,,,,,,,,,,,,,32,1,4.000000e+000,3.128052e-003,0.000000e+000,0,,0,
1524409552.156,,0.000000e+000,3.499872e+001,-5.688050e-006,0.000000e+000,2,8.564199e-001,0.000000e+000,,,,,,,,,,,,,,32,1,4.000000e+000,1.560211e-003,0.000000e+000,0,,0,
1524409589.444,,0.000000e+000,3.499872e+001,-5.653687e-006,0.000000e+000,2,8.619220e-001,0.000000e+000,,,,,,,,,,,,,,32,1,4.000000e+000,0.000000e+000,0.000000e+000,0,,0,
1524409627.172,,0.000000e+000,3.499950e+001,-5.586510e-006,0.000000e+000,2,8.564148e-001,0.000000e+000,,,,,,,,,,,,,,32,1,4.000000e+000,0.000000e+000,0.000000e+000,0,,0,
1524409665.220,,0.000000e+000,3.499793e+001,-5.550024e-006,0.000000e+000,2,8.536738e-001,0.000000e+000,,,,,,,,,,,,,,32,1,4.000000e+000,4.688263e-003,0.000000e+000,0,,0,
1524409703.136,,0.000000e+000,3.499989e+001,-5.544346e-006,0.000000e+000,2,8.571868e-001,0.000000e+000,,,,,,,,,,,,,,32,1,4.000000e+000,7.781982e-004,0.000000e+000,0,,0,
1524409740.334,,0.000000e+000,3.499872e+001,-5.503725e-006,0.000000e+000,2,8.542886e-001,0.000000e+000,,,,,,,,,,,,,,32,1,4.000000e+000,0.000000e+000,0.000000e+000,0,,0,
1524409778.272,,0.000000e+000,3.499872e+001,-5.427640e-006,0.000000e+000,2,8.540541e-001,0.000000e+000,,,,,,,,,,,,,,32,1,4.000000e+000,1.560211e-003,0.000000e+000,0,,0,
1524409816.062,,0.000000e+000,3.499911e+001,-5.404464e-006,0.000000e+000,2,8.533635e-001,0.000000e+000,,,,,,,,,,,,,,32,1,4.000000e+000,7.820129e-004,0.000000e+000,0,,0,
1524409854.103,,0.000000e+000,3.499872e+001,-5.394114e-006,0.000000e+000,2,8.525264e-001,0.000000e+000,,,,,,,,,,,,,,32,1,4.000000e+000,0.000000e+000,0.000000e+000,0,,0,
1524409892.644,,0.000000e+000,3.499950e+001,-5.312847e-006,0.000000e+000,2,8.554397e-001,0.000000e+000,,,,,,,,,,,,,,32,1,4.000000e+000,0.000000e+000,0.000000e+000,0,,0,
1524409930.179,,0.000000e+000,3.499872e+001,-5.359876e-006,0.000000e+000,2,8.585656e-001,0.000000e+000,,,,,,,,,,,,,,32,1,4.000000e+000,0.000000e+000,0.000000e+000,0,,0,
1524409967.797,,0.000000e+000,3.499754e+001,-5.313827e-006,0.000000e+000,2,8.445013e-001,0.000000e+000,,,,,,,,,,,,,,32,1,4.000000e+000,7.896423e-004,0.000000e+000,0,,0,
1524410005.793,,0.000000e+000,3.499794e+001,-5.274790e-006,0.000000e+000,2,8.550105e-001,0.000000e+000,,,,,,,,,,,,,,32,1,4.000000e+000,0.000000e+000,0.000000e+000,0,,0,
1524410043.946,,0.000000e+000,3.499950e+001,-5.213808e-006,0.000000e+000,2,8.459477e-001,0.000000e+000,,,,,,,,,,,,,,32,1,4.000000e+000,1.560211e-003,0.000000e+000,0,,0,
1524410082.021,,0.000000e+000,3.499794e+001,-5.171093e-006,0.000000e+000,2,8.447117e-001,0.000000e+000,,,,,,,,,,,,,,32,1,4.000000e+000,0.000000e+000,0.000000e+000,0,,0,
1524410120.027,,0.000000e+000,3.500106e+001,-5.167959e-006,0.000000e+000,2,8.481525e-001,0.000000e+000,,,,,,,,,,,,,,32,1,4.000000e+000,1.560211e-003,0.000000e+000,0,,0,
1524410158.590,,0.000000e+000,3.499911e+001,-5.102498e-006,0.000000e+000,2,8.421018e-001,0.000000e+000,,,,,,,,,,,,,,32,1,4.000000e+000,7.820129e-004,0.000000e+000,0,,0,
1524410196.215,,0.000000e+000,3.499911e+001,-5.071616e-006,0.000000e+000,2,8.446220e-001,0.000000e+000,,,,,,,,,,,,,,32,1,4.000000e+000,7.820129e-004,0.000000e+000,0,,0,
1524410233.846,,0.000000e+000,3.499872e+001,-5.053299e-006,0.000000e+000,2,8.464222e-001,0.000000e+000,,,,,,,,,,,,,,32,1,4.000000e+000,1.560211e-003,0.000000e+000,0,,0,
1524410272.329,,0.000000e+000,3.499872e+001,-5.062222e-006,0.000000e+000,2,8.398686e-001,0.000000e+000,,,,,,,,,,,,,,32,1,4.000000e+000,0.000000e+000,0.000000e+000,0,,0,
1524410310.452,,0.000000e+000,3.499872e+001,-4.987513e-006,0.000000e+000,2,8.375741e-001,0.000000e+000,,,,,,,,,,,,,,32,1,4.000000e+000,0.000000e+000,0.000000e+000,0,,0,
1524410348.023,,0.000000e+000,3.499911e+001,-4.923495e-006,0.000000e+000,2,8.370354e-001,0.000000e+000,,,,,,,,,,,,,,32,1,4.000000e+000,7.820129e-004,0.000000e+000,0,,0,
1524410386.073,,0.000000e+000,3.499872e+001,-4.925267e-006,0.000000e+000,2,8.377247e-001,0.000000e+000,,,,,,,,,,,,,,32,1,4.000000e+000,1.560211e-003,0.000000e+000,0,,0,
1524410424.594,,0.000000e+000,3.499950e+001,-4.893609e-006,0.000000e+000,2,8.378915e-001,0.000000e+000,,,,,,,,,,,,,,32,1,4.000000e+000,1.560211e-003,0.000000e+000,0,,0,
1524410462.579,,0.000000e+000,3.499911e+001,-4.844866e-006,0.000000e+000,2,8.276968e-001,0.000000e+000,,,,,,,,,,,,,,32,1,4.000000e+000,7.820129e-004,0.000000e+000,0,,0,
1524410500.858,,0.000000e+000,3.499793e+001,-4.841462e-006,0.000000e+000,2,8.406337e-001,0.000000e+000,,,,,,,,,,,,,,32,1,4.000000e+000,1.567841e-003,0.000000e+000,0,,0,
1524410538.698,,0.000000e+000,3.499833e+001,-4.838745e-006,0.000000e+000,2,8.353928e-001,0.000000e+000,,,,,,,,,,,,,,32,1,4.000000e+000,2.349854e-003,0.000000e+000,0,,0,
1524410576.289,,0.000000e+000,3.499911e+001,-4.757974e-006,0.000000e+000,2,8.278363e-001,0.000000e+000,,,,,,,,,,,,,,32,1,4.000000e+000,7.820129e-004,0.000000e+000,0,,0,
1524410614.339,,0.000000e+000,3.499950e+001,-4.700402e-006,0.000000e+000,2,8.257503e-001,0.000000e+000,,,,,,,,,,,,,,32,1,4.000000e+000,0.000000e+000,0.000000e+000,0,,0,
1524410652.060,,0.000000e+000,3.499911e+001,-4.688141e-006,0.000000e+000,2,8.267442e-001,0.000000e+000,,,,,,,,,,,,,,32,1,4.000000e+000,7.820129e-004,0.000000e+000,0,,0,
1524410690.145,,0.000000e+000,3.499950e+001,-4.656209e-006,0.000000e+000,2,8.253561e-001,0.000000e+000,,,,,,,,,,,,,,32,1,4.000000e+000,0.000000e+000,0.000000e+000,0,,0,
1524410728.166,,0.000000e+000,3.499950e+001,-4.670556e-006,0.000000e+000,2,8.348800e-001,0.000000e+000,,,,,,,,,,,,,,32,1,4.000000e+000,0.000000e+000,0.000000e+000,0,,0,
1524410765.614,,0.000000e+000,3.499989e+001,-4.638308e-006,0.000000e+000,2,8.306924e-001,0.000000e+000,,,,,,,,,,,,,,32,1,4.000000e+000,2.342224e-003,0.000000e+000,0,,0,
1524410803.129,,0.000000e+000,3.499872e+001,-4.619842e-006,0.000000e+000,2,8.259075e-001,0.000000e+000,,,,,,,,,,,,,,32,1,4.000000e+000,0.000000e+000,0.000000e+000,0,,0,
1524410841.172,,0.000000e+000,3.499911e+001,-4.568996e-006,0.000000e+000,2,8.235164e-001,0.000000e+000,,,,,,,,,,,,,,32,1,4.000000e+000,7.820129e-004,0.000000e+000,0,,0,
1524410879.243,,0.000000e+000,3.499911e+001,-4.547494e-006,0.000000e+000,2,8.176592e-001,0.000000e+000,,,,,,,,,,,,,,32,1,4.000000e+000,7.820129e-004,0.000000e+000,0,,0,
1524410916.667,,0.000000e+000,3.499911e+001,-4.526933e-006,0.000000e+000,2,8.205357e-001,0.000000e+000,,,,,,,,,,,,,,32,1,4.000000e+000,7.820129e-004,0.000000e+000,0,,0,
1524410955.142,,0.000000e+000,3.499754e+001,-4.476795e-006,0.000000e+000,2,8.188276e-001,0.000000e+000,,,,,,,,,,,,,,32,1,4.000000e+000,3.910065e-003,0.000000e+000,0,,0,
1524410992.983,,0.000000e+000,3.499833e+001,-4.482131e-006,0.000000e+000,2,8.211498e-001,0.000000e+000,,,,,,,,,,,,,,32,1,4.000000e+000,7.781982e-004,0.000000e+000,0,,0,
1524411031.672,,0.000000e+000,3.499793e+001,-4.428139e-006,0.000000e+000,2,8.206030e-001,0.000000e+000,,,,,,,,,,,,,,32,1,4.000000e+000,1.567841e-003,0.000000e+000,0,,0,
1524411069.761,,0.000000e+000,3.499872e+001,-4.430346e-006,0.000000e+000,2,8.200668e-001,0.000000e+000,,,,,,,,,,,,,,32,1,4.000000e+000,0.000000e+000,0.000000e+000,0,,0,
1524411108.411,,0.000000e+000,3.499872e+001,-4.394169e-006,0.000000e+000,2,8.187985e-001,0.000000e+000,,,,,,,,,,,,,,32,1,4.000000e+000,0.000000e+000,0.000000e+000,0,,0,
1524411146.282,,0.000000e+000,3.499911e+001,-4.322113e-006,0.000000e+000,2,8.139639e-001,0.000000e+000,,,,,,,,,,,,,,32,1,4.000000e+000,7.820129e-004,0.000000e+000,0,,0,
1524411183.928,,0.000000e+000,3.499872e+001,-4.309584e-006,0.000000e+000,2,8.070973e-001,0.000000e+000,,,,,,,,,,,,,,32,1,4.000000e+000,0.000000e+000,0.000000e+000,0,,0,
1524411221.579,,0.000000e+000,3.499872e+001,-4.294150e-006,0.000000e+000,2,8.196984e-001,0.000000e+000,,,,,,,,,,,,,,32,1,4.000000e+000,1.560211e-003,0.000000e+000,0,,0,
1524411258.847,,0.000000e+000,3.499872e+001,-4.257495e-006,0.000000e+000,2,8.070332e-001,0.000000e+000,,,,,,,,,,,,,,32,1,4.000000e+000,0.000000e+000,0.000000e+000,0,,0,
1524411296.897,,0.000000e+000,3.499950e+001,-4.269756e-006,0.000000e+000,2,8.101013e-001,0.000000e+000,,,,,,,,,,,,,,32,1,4.000000e+000,0.000000e+000,0.000000e+000,0,,0,
1524411334.985,,0.000000e+000,3.499911e+001,-4.189846e-006,0.000000e+000,2,8.057198e-001,0.000000e+000,,,,,,,,,,,,,,32,1,4.000000e+000,7.820129e-004,0.000000e+000,0,,0,
1524411373.593,,0.000000e+000,3.499950e+001,-4.237330e-006,0.000000e+000,2,8.139402e-001,0.000000e+000,,,,,,,,,,,,,,32,1,4.000000e+000,1.560211e-003,0.000000e+000,0,,0,
1524411411.046,,0.000000e+000,3.499794e+001,-4.164441e-006,0.000000e+000,2,8.084467e-001,0.000000e+000,,,,,,,,,,,,,,32,1,4.000000e+000,0.000000e+000,0.000000e+000,0,,0,
1524411448.609,,0.000000e+000,3.499872e+001,-4.150398e-006,0.000000e+000,2,8.067746e-001,0.000000e+000,,,,,,,,,,,,,,32,1,4.000000e+000,1.560211e-003,0.000000e+000,0,,0,
1524411486.675,,0.000000e+000,3.499950e+001,-4.098577e-006,0.000000e+000,2,7.982924e-001,0.000000e+000,,,,,,,,,,,,,,32,1,4.000000e+000,0.000000e+000,0.000000e+000,0,,0,
1524411524.738,,0.000000e+000,3.499911e+001,-4.123062e-006,0.000000e+000,2,8.048452e-001,0.000000e+000,,,,,,,,,,,,,,32,1,4.000000e+000,7.820129e-004,0.000000e+000,0,,0,
1524411562.763,,0.000000e+000,3.499950e+001,-4.082268e-006,0.000000e+000,2,7.979563e-001,0.000000e+000,,,,,,,,,,,,,,32,1,4.000000e+000,0.000000e+000,0.000000e+000,0,,0,
1524411599.962,,0.000000e+000,3.499989e+001,-4.061571e-006,0.000000e+000,2,7.996414e-001,0.000000e+000,,,,,,,,,,,,,,32,1,4.000000e+000,7.781982e-004,0.000000e+000,0,,0,
1524411638.585,,0.000000e+000,3.499793e+001,-4.047584e-006,0.000000e+000,2,8.001001e-001,0.000000e+000,,,,,,,,,,,,,,32,1,4.000000e+000,3.131866e-003,0.000000e+000,0,,0,
1524411676.205,,0.000000e+000,3.499950e+001,-3.981167e-006,0.000000e+000,2,7.867109e-001,0.000000e+000,,,,,,,,,,,,,,32,1,4.000000e+000,0.000000e+000,0.000000e+000,0,,0,
1524411715.051,,0.000000e+000,3.500028e+001,-3.992087e-006,0.000000e+000,2,7.999012e-001,0.000000e+000,,,,,,,,,,,,,,32,1,4.000000e+000,0.000000e+000,0.000000e+000,0,,0,
1524411752.036,,0.000000e+000,3.499950e+001,-3.985652e-006,0.000000e+000,2,7.975802e-001,0.000000e+000,,,,,,,,,,,,,,32,1,4.000000e+000,0.000000e+000,0.000000e+000,0,,0,
1524411790.122,,0.000000e+000,3.499872e+001,-3.917260e-006,0.000000e+000,2,7.968962e-001,0.000000e+000,,,,,,,,,,,,,,32,1,4.000000e+000,0.000000e+000,0.000000e+000,0,,0,
1524411827.712,,0.000000e+000,3.500028e+001,-3.871647e-006,0.000000e+000,2,7.893016e-001,0.000000e+000,,,,,,,,,,,,,,32,1,4.000000e+000,1.560211e-003,0.000000e+000,0,,0,
1524411865.773,,0.000000e+000,3.499989e+001,-3.881883e-006,0.000000e+000,2,7.859579e-001,0.000000e+000,,,,,,,,,,,,,,32,1,4.000000e+000,7.781982e-004,0.000000e+000,0,,0,
1524411903.404,,0.000000e+000,3.499911e+001,-3.853780e-006,0.000000e+000,2,7.887745e-001,0.000000e+000,,,,,,,,,,,,,,32,1,4.000000e+000,7.820129e-004,0.000000e+000,0,,0,
1524411941.754,,0.000000e+000,3.499950e+001,-3.829180e-006,0.000000e+000,2,7.889360e-001,0.000000e+000,,,,,,,,,,,,,,32,1,4.000000e+000,0.000000e+000,0.000000e+000,0,,0,
1524411978.442,,0.000000e+000,3.499911e+001,-3.807381e-006,0.000000e+000,2,7.921552e-001,0.000000e+000,,,,,,,,,,,,,,32,1,4.000000e+000,7.820129e-004,0.000000e+000,0,,0,
1524412016.120,,0.000000e+000,3.499911e+001,-3.793550e-006,0.000000e+000,2,7.804603e-001,0.000000e+000,,,,,,,,,,,,,,32,1,4.000000e+000,7.820129e-004,0.000000e+000,0,,0,
1524412054.993,,0.000000e+000,3.499950e+001,-3.730217e-006,0.000000e+000,2,7.803651e-001,0.000000e+000,,,,,,,,,,,,,,32,1,4.000000e+000,0.000000e+000,0.000000e+000,0,,0,
1524412093.281,,0.000000e+000,3.499950e+001,-3.738918e-006,0.000000e+000,2,7.811735e-001,0.000000e+000,,,,,,,,,,,,,,32,1,4.000000e+000,0.000000e+000,0.000000e+000,0,,0,
1524412131.349,,0.000000e+000,3.500028e+001,-3.735945e-006,0.000000e+000,2,7.839720e-001,0.000000e+000,,,,,,,,,,,,,,32,1,4.000000e+000,0.000000e+000,0.000000e+000,0,,0,
1524412169.340,,0.000000e+000,3.500028e+001,-3.671644e-006,0.000000e+000,2,7.777644e-001,0.000000e+000,,,,,,,,,,,,,,32,1,4.000000e+000,1.560211e-003,0.000000e+000,0,,0,
1524412207.388,,0.000000e+000,3.500028e+001,-3.678035e-006,0.000000e+000,2,7.797670e-001,0.000000e+000,,,,,,,,,,,,,,32,1,4.000000e+000,1.560211e-003,0.000000e+000,0,,0,
1524412245.716,,0.000000e+000,3.499911e+001,-3.642654e-006,0.000000e+000,2,7.760015e-001,0.000000e+000,,,,,,,,,,,,,,32,1,4.000000e+000,7.820129e-004,0.000000e+000,0,,0,
1524412283.744,,0.000000e+000,3.499950e+001,-3.613953e-006,0.000000e+000,2,7.677819e-001,0.000000e+000,,,,,,,,,,,,,,32,1,4.000000e+000,0.000000e+000,0.000000e+000,0,,0,
1524412321.140,,0.000000e+000,3.499950e+001,-3.612310e-006,0.000000e+000,2,7.783631e-001,0.000000e+000,,,,,,,,,,,,,,32,1,4.000000e+000,0.000000e+000,0.000000e+000,0,,0,
1524412359.193,,0.000000e+000,3.499950e+001,-3.615439e-006,0.000000e+000,2,7.817403e-001,0.000000e+000,,,,,,,,,,,,,,32,1,4.000000e+000,0.000000e+000,0.000000e+000,0,,0,
1524412397.238,,0.000000e+000,3.499950e+001,-3.573861e-006,0.000000e+000,2,7.732853e-001,0.000000e+000,,,,,,,,,,,,,,32,1,4.000000e+000,0.000000e+000,0.000000e+000,0,,0,
1524412434.776,,0.000000e+000,3.499989e+001,-3.557674e-006,0.000000e+000,2,7.813849e-001,0.000000e+000,,,,,,,,,,,,,,32,1,4.000000e+000,2.342224e-003,0.000000e+000,0,,0,
1524412472.852,,0.000000e+000,3.499911e+001,-3.539139e-006,0.000000e+000,2,7.742900e-001,0.000000e+000,,,,,,,,,,,,,,32,1,4.000000e+000,7.820129e-004,0.000000e+000,0,,0,
1524412510.908,,0.000000e+000,3.499911e+001,-3.531793e-006,0.000000e+000,2,7.702043e-001,0.000000e+000,,,,,,,,,,,,,,32,1,4.000000e+000,2.338409e-003,0.000000e+000,0,,0,
1524412548.891,,0.000000e+000,3.499950e+001,-3.497866e-006,0.000000e+000,2,7.727909e-001,0.000000e+000,,,,,,,,,,,,,,32,1,4.000000e+000,1.560211e-003,0.000000e+000,0,,0,
1524412587.206,,0.000000e+000,3.499950e+001,-3.472864e-006,0.000000e+000,2,7.657294e-001,0.000000e+000,,,,,,,,,,,,,,32,1,4.000000e+000,0.000000e+000,0.000000e+000,0,,0,
1524412625.284,,0.000000e+000,3.499754e+001,-3.443725e-006,0.000000e+000,2,7.705301e-001,0.000000e+000,,,,,,,,,,,,,,32,1,4.000000e+000,5.470276e-003,0.000000e+000,0,,0,
1524412662.775,,0.000000e+000,3.500028e+001,-3.401009e-006,0.000000e+000,2,7.596934e-001,0.000000e+000,,,,,,,,,,,,,,32,1,4.000000e+000,1.560211e-003,0.000000e+000,0,,0,
1524412700.945,,0.000000e+000,3.499950e+001,-3.364232e-006,0.000000e+000,2,7.498633e-001,0.000000e+000,,,,,,,,,,,,,,32,1,4.000000e+000,0.000000e+000,0.000000e+000,0,,0,
1524412739.013,,0.000000e+000,3.499950e+001,-3.381551e-006,0.000000e+000,2,7.612395e-001,0.000000e+000,,,,,,,,,,,,,,32,1,4.000000e+000,0.000000e+000,0.000000e+000,0,,0,
1524412776.716,,0.000000e+000,3.499911e+001,-3.364259e-006,0.000000e+000,2,7.623150e-001,0.000000e+000,,,,,,,,,,,,,,32,1,4.000000e+000,7.820129e-004,0.000000e+000,0,,0,
1524412814.802,,0.000000e+000,3.499950e+001,-3.328221e-006,0.000000e+000,2,7.589041e-001,0.000000e+000,,,,,,,,,,,,,,32,1,4.000000e+000,0.000000e+000,0.000000e+000,0,,0,
1524412852.385,,0.000000e+000,3.499950e+001,-3.315691e-006,0.000000e+000,2,7.541587e-001,0.000000e+000,,,,,,,,,,,,,,32,1,4.000000e+000,0.000000e+000,0.000000e+000,0,,0,
1524412890.445,,0.000000e+000,3.499872e+001,-3.306374e-006,0.000000e+000,2,7.532738e-001,0.000000e+000,,,,,,,,,,,,,,32,1,4.000000e+000,1.560211e-003,0.000000e+000,0,,0,
1524412928.434,,0.000000e+000,3.499872e+001,-3.340258e-006,0.000000e+000,2,7.636138e-001,0.000000e+000,,,,,,,,,,,,,,32,1,4.000000e+000,1.560211e-003,0.000000e+000,0,,0,
1524412966.554,,0.000000e+000,3.499872e+001,-3.270931e-006,0.000000e+000,2,7.526946e-001,0.000000e+000,,,,,,,,,,,,,,32,1,4.000000e+000,1.560211e-003,0.000000e+000,0,,0,
1524413004.650,,0.000000e+000,3.499911e+001,-3.219122e-006,0.000000e+000,2,7.447042e-001,0.000000e+000,,,,,,,,,,,,,,32,1,4.000000e+000,7.820129e-004,0.000000e+000,0,,0,
1524413042.673,,0.000000e+000,3.499872e+001,-3.196626e-006,0.000000e+000,2,7.428438e-001,0.000000e+000,,,,,,,,,,,,,,32,1,4.000000e+000,0.000000e+000,0.000000e+000,0,,0,
1524413080.673,,0.000000e+000,3.499911e+001,-3.197422e-006,0.000000e+000,2,7.454115e-001,0.000000e+000,,,,,,,,,,,,,,32,1,4.000000e+000,7.820129e-004,0.000000e+000,0,,0,
1524413118.321,,0.000000e+000,3.499872e+001,-3.189196e-006,0.000000e+000,2,7.475308e-001,0.000000e+000,,,,,,,,,,,,,,32,1,4.000000e+000,0.000000e+000,0.000000e+000,0,,0,
1524413156.117,,0.000000e+000,3.499911e+001,-3.155825e-006,0.000000e+000,2,7.500900e-001,0.000000e+000,,,,,,,,,,,,,,32,1,4.000000e+000,7.820129e-004,0.000000e+000,0,,0,
1524413193.648,,0.000000e+000,3.499950e+001,-3.130896e-006,0.000000e+000,2,7.377233e-001,0.000000e+000,,,,,,,,,,,,,,32,1,4.000000e+000,0.000000e+000,0.000000e+000,0,,0,
1524413231.626,,0.000000e+000,3.500067e+001,-3.110802e-006,0.000000e+000,2,7.419515e-001,0.000000e+000,,,,,,,,,,,,,,32,1,4.000000e+000,7.820129e-004,0.000000e+000,0,,0,
1524413270.274,,0.000000e+000,3.499833e+001,-3.089496e-006,0.000000e+000,2,7.361264e-001,0.000000e+000,,,,,,,,,,,,,,32,1,4.000000e+000,7.781982e-004,0.000000e+000,0,,0,
1524413306.617,,0.000000e+000,3.499911e+001,-3.065461e-006,0.000000e+000,2,7.261895e-001,0.000000e+000,,,,,,,,,,,,,,32,1,4.000000e+000,2.338409e-003,0.000000e+000,0,,0,
1524413344.777,,0.000000e+000,3.500067e+001,-3.036288e-006,0.000000e+000,2,7.239268e-001,0.000000e+000,,,,,,,,,,,,,,32,1,4.000000e+000,3.910065e-003,0.000000e+000,0,,0,
1524413382.828,,0.000000e+000,3.499872e+001,-3.042717e-006,0.000000e+000,2,7.343133e-001,0.000000e+000,,,,,,,,,,,,,,32,1,4.000000e+000,0.000000e+000,0.000000e+000,0,,0,
1524413421.093,,0.000000e+000,3.499911e+001,-3.020753e-006,0.000000e+000,2,7.265765e-001,0.000000e+000,,,,,,,,,,,,,,32,1,4.000000e+000,7.820129e-004,0.000000e+000,0,,0,
1524413459.454,,0.000000e+000,3.499872e+001,-2.969540e-006,0.000000e+000,2,7.305566e-001,0.000000e+000,,,,,,,,,,,,,,32,1,4.000000e+000,0.000000e+000,0.000000e+000,0,,0,
1524413497.519,,0.000000e+000,3.499911e+001,-2.983125e-006,0.000000e+000,2,7.216582e-001,0.000000e+000,,,,,,,,,,,,,,32,1,4.000000e+000,7.820129e-004,0.000000e+000,0,,0,
1524413535.570,,0.000000e+000,3.499911e+001,-2.995037e-006,0.000000e+000,2,7.297534e-001,0.000000e+000,,,,,,,,,,,,,,32,1,4.000000e+000,7.820129e-004,0.000000e+000,0,,0,
1524413573.328,,0.000000e+000,3.500028e+001,-2.937635e-006,0.000000e+000,2,7.268890e-001,0.000000e+000,,,,,,,,,,,,,,32,1,4.000000e+000,1.560211e-003,0.000000e+000,0,,0,
1524413611.699,,0.000000e+000,3.499911e+001,-2.932574e-006,0.000000e+000,2,7.215267e-001,0.000000e+000,,,,,,,,,,,,,,32,1,4.000000e+000,7.820129e-004,0.000000e+000,0,,0,
1524413649.764,,0.000000e+000,3.499872e+001,-2.883956e-006,0.000000e+000,2,7.230147e-001,0.000000e+000,,,,,,,,,,,,,,32,1,4.000000e+000,0.000000e+000,0.000000e+000,0,,0,
1524413687.320,,0.000000e+000,3.499911e+001,-2.874357e-006,0.000000e+000,2,7.128280e-001,0.000000e+000,,,,,,,,,,,,,,32,1,4.000000e+000,7.820129e-004,0.000000e+000,0,,0,
1524413725.485,,0.000000e+000,3.499911e+001,-2.874064e-006,0.000000e+000,2,7.140974e-001,0.000000e+000,,,,,,,,,,,,,,32,1,4.000000e+000,7.820129e-004,0.000000e+000,0,,0,
1524413763.441,,0.000000e+000,3.499911e+001,-2.867574e-006,0.000000e+000,2,7.200648e-001,0.000000e+000,,,,,,,,,,,,,,32,1,4.000000e+000,7.820129e-004,0.000000e+000,0,,0,
1524413801.516,,0.000000e+000,3.499911e+001,-2.850470e-006,0.000000e+000,2,7.048523e-001,0.000000e+000,,,,,,,,,,,,,,32,1,4.000000e+000,7.820129e-004,0.000000e+000,0,,0,
1524413839.572,,0.000000e+000,3.499911e+001,-2.795773e-006,0.000000e+000,2,7.045141e-001,0.000000e+000,,,,,,,,,,,,,,32,1,4.000000e+000,7.820129e-004,0.000000e+000,0,,0,
1524413877.178,,0.000000e+000,3.499911e+001,-2.752605e-006,0.000000e+000,2,6.934984e-001,0.000000e+000,,,,,,,,,,,,,,32,1,4.000000e+000,7.820129e-004,0.000000e+000,0,,0,
1524413915.243,,0.000000e+000,3.499872e+001,-2.753304e-006,0.000000e+000,2,6.943335e-001,0.000000e+000,,,,,,,,,,,,,,32,1,4.000000e+000,1.560211e-003,0.000000e+000,0,,0,
1524413953.729,,0.000000e+000,3.499872e+001,-2.763773e-006,0.000000e+000,2,7.069473e-001,0.000000e+000,,,,,,,,,,,,,,32,1,4.000000e+000,1.560211e-003,0.000000e+000,0,,0,
1524413991.794,,0.000000e+000,3.499872e+001,-2.732041e-006,0.000000e+000,2,6.974776e-001,0.000000e+000,,,,,,,,,,,,,,32,1,4.000000e+000,0.000000e+000,0.000000e+000,0,,0,
1524414030.552,,0.000000e+000,3.499989e+001,-2.728598e-006,0.000000e+000,2,7.029418e-001,0.000000e+000,,,,,,,,,,,,,,32,1,4.000000e+000,7.781982e-004,0.000000e+000,0,,0,
1524414069.020,,0.000000e+000,3.499989e+001,-2.671494e-006,0.000000e+000,2,6.843773e-001,0.000000e+000,,,,,,,,,,,,,,32,1,4.000000e+000,7.781982e-004,0.000000e+000,0,,0,
1524414107.586,,0.000000e+000,3.500028e+001,-2.655195e-006,0.000000e+000,2,6.881335e-001,0.000000e+000,,,,,,,,,,,,,,32,1,4.000000e+000,1.560211e-003,0.000000e+000,0,,0,
1524414146.439,,0.000000e+000,3.499833e+001,-2.666744e-006,0.000000e+000,2,6.928560e-001,0.000000e+000,,,,,,,,,,,,,,32,1,4.000000e+000,7.781982e-004,0.000000e+000,0,,0,
1524414184.422,,0.000000e+000,3.499833e+001,-2.646646e-006,0.000000e+000,2,6.940627e-001,0.000000e+000,,,,,,,,,,,,,,32,1,4.000000e+000,7.781982e-004,0.000000e+000,0,,0,
1524414222.505,,0.000000e+000,3.499989e+001,-2.638304e-006,0.000000e+000,2,6.938462e-001,0.000000e+000,,,,,,,,,,,,,,32,1,4.000000e+000,7.781982e-004,0.000000e+000,0,,0,
1524414260.101,,0.000000e+000,3.499911e+001,-2.606955e-006,0.000000e+000,2,6.841163e-001,0.000000e+000,,,,,,,,,,,,,,32,1,4.000000e+000,7.820129e-004,0.000000e+000,0,,0,
1524414298.084,,0.000000e+000,3.499872e+001,-2.622957e-006,0.000000e+000,2,6.930421e-001,0.000000e+000,,,,,,,,,,,,,,32,1,4.000000e+000,1.560211e-003,0.000000e+000,0,,0,
1524414336.654,,0.000000e+000,3.499833e+001,-2.580800e-006,0.000000e+000,2,6.812504e-001,0.000000e+000,,,,,,,,,,,,,,32,1,4.000000e+000,2.349854e-003,0.000000e+000,0,,0,
1524414374.725,,0.000000e+000,3.499833e+001,-2.554322e-006,0.000000e+000,2,6.837625e-001,0.000000e+000,,,,,,,,,,,,,,32,1,4.000000e+000,2.349854e-003,0.000000e+000,0,,0,
1524414412.993,,0.000000e+000,3.499833e+001,-2.557339e-006,0.000000e+000,2,6.749514e-001,0.000000e+000,,,,,,,,,,,,,,32,1,4.000000e+000,7.781982e-004,0.000000e+000,0,,0,
1524414451.061,,0.000000e+000,3.499872e+001,-2.503753e-006,0.000000e+000,2,6.794670e-001,0.000000e+000,,,,,,,,,,,,,,32,1,4.000000e+000,1.560211e-003,0.000000e+000,0,,0,
1524414489.172,,0.000000e+000,3.499950e+001,-2.490787e-006,0.000000e+000,2,6.832484e-001,0.000000e+000,,,,,,,,,,,,,,32,1,4.000000e+000,1.560211e-003,0.000000e+000,0,,0,
1524414527.175,,0.000000e+000,3.499950e+001,-2.474110e-006,0.000000e+000,2,6.608273e-001,0.000000e+000,,,,,,,,,,,,,,32,1,4.000000e+000,1.560211e-003,0.000000e+000,0,,0,
1524414565.228,,0.000000e+000,3.499872e+001,-2.480159e-006,0.000000e+000,2,6.763883e-001,0.000000e+000,,,,,,,,,,,,,,32,1,4.000000e+000,0.000000e+000,0.000000e+000,0,,0,
1524414603.408,,0.000000e+000,3.499911e+001,-2.452972e-006,0.000000e+000,2,6.629745e-001,0.000000e+000,,,,,,,,,,,,,,32,1,4.000000e+000,2.338409e-003,0.000000e+000,0,,0,
1524414641.479,,0.000000e+000,3.500067e+001,-2.483292e-006,0.000000e+000,2,6.732696e-001,0.000000e+000,,,,,,,,,,,,,,32,1,4.000000e+000,2.338409e-003,0.000000e+000,0,,0,
1524414679.529,,0.000000e+000,3.499911e+001,-2.422865e-006,0.000000e+000,2,6.636423e-001,0.000000e+000,,,,,,,,,,,,,,32,1,4.000000e+000,7.820129e-004,0.000000e+000,0,,0,
1524414717.577,,0.000000e+000,3.499833e+001,-2.400101e-006,0.000000e+000,2,6.492856e-001,0.000000e+000,,,,,,,,,,,,,,32,1,4.000000e+000,7.781982e-004,0.000000e+000,0,,0,
1524414755.383,,0.000000e+000,3.499793e+001,-2.395360e-006,0.000000e+000,2,6.564849e-001,0.000000e+000,,,,,,,,,,,,,,32,1,4.000000e+000,1.567841e-003,0.000000e+000,0,,0,
1524414793.183,,0.000000e+000,3.499911e+001,-2.368953e-006,0.000000e+000,2,6.502436e-001,0.000000e+000,,,,,,,,,,,,,,32,1,4.000000e+000,7.820129e-004,0.000000e+000,0,,0,
1524414831.252,,0.000000e+000,3.499794e+001,-2.314516e-006,0.000000e+000,2,6.389284e-001,0.000000e+000,,,,,,,,,,,,,,32,1,4.000000e+000,0.000000e+000,0.000000e+000,0,,0,
1524414869.462,,0.000000e+000,3.499950e+001,-2.329082e-006,0.000000e+000,2,6.497827e-001,0.000000e+000,,,,,,,,,,,,,,32,1,4.000000e+000,0.000000e+000,0.000000e+000,0,,0,
1524414907.553,,0.000000e+000,3.499950e+001,-2.303340e-006,0.000000e+000,2,6.410127e-001,0.000000e+000,,,,,,,,,,,,,,32,1,4.000000e+000,0.000000e+000,0.000000e+000,0,,0,
1524414946.411,,0.000000e+000,3.499911e+001,-2.330914e-006,0.000000e+000,2,6.550263e-001,0.000000e+000,,,,,,,,,,,,,,32,1,4.000000e+000,7.820129e-004,0.000000e+000,0,,0,
1524414983.496,,0.000000e+000,3.499989e+001,-2.318715e-006,0.000000e+000,2,6.453408e-001,0.000000e+000,,,,,,,,,,,,,,32,1,4.000000e+000,7.781982e-004,0.000000e+000,0,,0,
1524415021.577,,0.000000e+000,3.499989e+001,-2.322515e-006,0.000000e+000,2,6.388730e-001,0.000000e+000,,,,,,,,,,,,,,32,1,4.000000e+000,7.781982e-004,0.000000e+000,0,,0,
1524415059.607,,0.000000e+000,3.499950e+001,-2.298458e-006,0.000000e+000,2,6.502567e-001,0.000000e+000,,,,,,,,,,,,,,32,1,4.000000e+000,0.000000e+000,0.000000e+000,0,,0,
1524415097.670,,0.000000e+000,3.499950e+001,-2.245456e-006,0.000000e+000,2,6.299767e-001,0.000000e+000,,,,,,,,,,,,,,32,1,4.000000e+000,1.560211e-003,0.000000e+000,0,,0,
1524415135.701,,0.000000e+000,3.499989e+001,-2.262701e-006,0.000000e+000,2,6.249048e-001,0.000000e+000,,,,,,,,,,,,,,32,1,4.000000e+000,7.781982e-004,0.000000e+000,0,,0,
1524415173.812,,0.000000e+000,3.499911e+001,-2.242012e-006,0.000000e+000,2,6.313664e-001,0.000000e+000,,,,,,,,,,,,,,32,1,4.000000e+000,7.820129e-004,0.000000e+000,0,,0,
1524415211.595,,0.000000e+000,3.499872e+001,-2.222141e-006,0.000000e+000,2,6.231654e-001,0.000000e+000,,,,,,,,,,,,,,32,1,4.000000e+000,0.000000e+000,0.000000e+000,0,,0,
1524415249.415,,0.000000e+000,3.499911e+001,-2.168429e-006,0.000000e+000,2,6.139088e-001,0.000000e+000,,,,,,,,,,,,,,32,1,4.000000e+000,7.820129e-004,0.000000e+000,0,,0,
1524415287.906,,0.000000e+000,3.499872e+001,-2.161445e-006,0.000000e+000,2,6.188860e-001,0.000000e+000,,,,,,,,,,,,,,32,1,4.000000e+000,1.560211e-003,0.000000e+000,0,,0,
1524415326.556,,0.000000e+000,3.500028e+001,-2.168342e-006,0.000000e+000,2,6.109042e-001,0.000000e+000,,,,,,,,,,,,,,32,1,4.000000e+000,1.560211e-003,0.000000e+000,0,,0,
1524415363.539,,0.000000e+000,3.499950e+001,-2.170634e-006,0.000000e+000,2,6.273912e-001,0.000000e+000,,,,,,,,,,,,,,32,1,4.000000e+000,0.000000e+000,0.000000e+000,0,,0,
1524415401.577,,0.000000e+000,3.499871e+001,-2.162151e-006,0.000000e+000,2,6.168284e-001,0.000000e+000,,,,,,,,,,,,,,32,1,4.000000e+000,3.128052e-003,0.000000e+000,0,,0,
1524415439.658,,0.000000e+000,3.500028e+001,-2.154864e-006,0.000000e+000,2,6.091776e-001,0.000000e+000,,,,,,,,,,,,,,32,1,4.000000e+000,0.000000e+000,0.000000e+000,0,,0,
1524415477.841,,0.000000e+000,3.500106e+001,-2.093993e-006,0.000000e+000,2,6.081794e-001,0.000000e+000,,,,,,,,,,,,,,32,1,4.000000e+000,4.692078e-003,0.000000e+000,0,,0,
1524415515.737,,0.000000e+000,3.499872e+001,-2.088654e-006,0.000000e+000,2,6.082076e-001,0.000000e+000,,,,,,,,,,,,,,32,1,4.000000e+000,0.000000e+000,0.000000e+000,0,,0,
1524415553.820,,0.000000e+000,3.499833e+001,-2.082865e-006,0.000000e+000,2,5.964994e-001,0.000000e+000,,,,,,,,,,,,,,32,1,4.000000e+000,2.349854e-003,0.000000e+000,0,,0,
1524415591.863,,0.000000e+000,3.499989e+001,-2.079867e-006,0.000000e+000,2,5.974553e-001,0.000000e+000,,,,,,,,,,,,,,32,1,4.000000e+000,7.781982e-004,0.000000e+000,0,,0,
1524415629.913,,0.000000e+000,3.499950e+001,-2.064639e-006,0.000000e+000,2,5.973393e-001,0.000000e+000,,,,,,,,,,,,,,32,1,4.000000e+000,0.000000e+000,0.000000e+000,0,,0,
1524415667.769,,0.000000e+000,3.499911e+001,-2.018700e-006,0.000000e+000,2,5.810906e-001,0.000000e+000,,,,,,,,,,,,,,32,1,4.000000e+000,7.820129e-004,0.000000e+000,0,,0,
1524415706.717,,0.000000e+000,3.499950e+001,-2.032592e-006,0.000000e+000,2,6.018873e-001,0.000000e+000,,,,,,,,,,,,,,32,1,4.000000e+000,1.560211e-003,0.000000e+000,0,,0,
1524415745.182,,0.000000e+000,3.499911e+001,-2.019545e-006,0.000000e+000,2,5.883597e-001,0.000000e+000,,,,,,,,,,,,,,32,1,4.000000e+000,7.820129e-004,0.000000e+000,0,,0,
1524415757.770,,0.000000e+000,3.499950e+001,-2.049083e-006,0.000000e+000,2,5.904786e-001,0.000000e+000,,,,,,,,,,,,,,32,1,4.000000e+000,1.560211e-003,0.000000e+000,0,,0,