File: Experimental Raw Data/MFn1 TRM/MFn1_TRMac_36.5K_0.32Kmin_VRMde_35K.dc.dat
[Header]
TITLE,MPMS DC Measurement
BYAPP,MPMS Measurement,2.1,Summary
FILEOPENTIME, 1524689565.212000 4/25/2018, 2:52:45 PM

INFO, APPNAME, MPMS MultiVu Application, Revision 1.61,  Build 082

INFO, NAME, MFn1
INFO, WEIGHT, 1.000
INFO, AREA, 1.000
INFO, LENGTH, 1.000
INFO, SHAPE, 0
INFO, COMMENT,
INFO, SEQUENCE FILE: TRMac_36.5K_0.32Kmin_VRMde_35K.seq


INFO, BACKGROUND DATA FILE:, None


STARTUPAXIS,X,4,LINEAR,AUTO,0.000000,0.000000
STARTUPAXIS,Y1,5,LINEAR,AUTO,0.000000,0.000000


STARTUPGROUP,Longitudinal
FIELDGROUP,Longitudinal,1,2,3,4,5,6,7,8,9,15,16,17,18,27,28
FIELDGROUP,Transverse,1,2,3,4,10,11,12,13,14,19,20,21,22,27,28

PLOT_APPEARANCE,ALL,HORZ_GRID_ON,VERT_GRID_ON,MARKERS_AND_LINES

[Data]
Time,Comment,Field (Oe),Temperature (K),Long Moment (emu),Long Scan Std Dev,Long Algorithm,Long Reg Fit,Long Percent Error (%),Trans Moment (emu),Trans Scan Std Dev,Trans Algorithm,Trans Reg Fit,Trans Percent Error (%),Long Moment [w/o ABS] (emu),Long Scan Std Dev [w/o ABS],Long Reg Fit [w/o ABS],Long Percent Error [w/o ABS] (%),Trans Moment [w/o ABS] (emu),Trans Scan Std Dev [w/o ABS],Trans Reg Fit [w/o ABS],Trans Percent Error [w/o ABS] (%),Points per Scan,Scans per Measurement,Scan Length (cm),Delta Temp (K),Rot Position (deg),Error,EC Comp. Running,Using ABS,
1524689565.209,,0.000000e+000,3.511487e+001,-3.179520e-006,0.000000e+000,3,7.658868e-001,0.000000e+000,,,,,,,,,,,,,,32,1,4.000000e+000,9.441376e-003,0.000000e+000,0,,0,
1524689603.160,,0.000000e+000,3.515113e+001,-1.099768e-006,0.000000e+000,3,3.133872e-001,0.000000e+000,,,,,,,,,,,,,,32,1,4.000000e+000,1.736069e-002,0.000000e+000,0,,0,
1524689832.606,,0.000000e+000,3.515114e+001,4.162703e-006,0.000000e+000,3,8.221062e-001,0.000000e+000,,,,,,,,,,,,,,32,1,4.000000e+000,1.263046e-002,0.000000e+000,0,,0,
1524689871.195,,0.000000e+000,3.513418e+001,4.353684e-006,0.000000e+000,3,8.430987e-001,0.000000e+000,,,,,,,,,,,,,,32,1,4.000000e+000,2.368927e-003,0.000000e+000,0,,0,
1524689909.068,,0.000000e+000,3.512629e+001,4.427153e-006,0.000000e+000,3,8.410730e-001,0.000000e+000,,,,,,,,,,,,,,32,1,4.000000e+000,7.781982e-004,0.000000e+000,0,,0,
1524689946.643,,0.000000e+000,3.511802e+001,4.647620e-006,0.000000e+000,3,8.505054e-001,0.000000e+000,,,,,,,,,,,,,,32,1,4.000000e+000,4.730225e-003,0.000000e+000,0,,0,
1524689984.984,,0.000000e+000,3.510227e+001,4.943564e-006,0.000000e+000,3,8.542789e-001,0.000000e+000,,,,,,,,,,,,,,32,1,4.000000e+000,0.000000e+000,0.000000e+000,0,,0,
1524690022.629,,0.000000e+000,3.509480e+001,5.024277e-006,0.000000e+000,3,8.564747e-001,0.000000e+000,,,,,,,,,,,,,,32,1,4.000000e+000,2.361298e-003,0.000000e+000,0,,0,
1524690060.937,,0.000000e+000,3.509402e+001,5.125698e-006,0.000000e+000,3,8.639805e-001,0.000000e+000,,,,,,,,,,,,,,32,1,4.000000e+000,7.896423e-004,0.000000e+000,0,,0,
1524690099.483,,0.000000e+000,3.509362e+001,5.293198e-006,0.000000e+000,3,8.692595e-001,0.000000e+000,,,,,,,,,,,,,,32,1,4.000000e+000,3.139496e-003,0.000000e+000,0,,0,
1524690137.368,,0.000000e+000,3.509008e+001,5.347634e-006,0.000000e+000,3,8.689160e-001,0.000000e+000,,,,,,,,,,,,,,32,1,4.000000e+000,2.357483e-003,0.000000e+000,0,,0,
1524690175.227,,0.000000e+000,3.508379e+001,5.504760e-006,0.000000e+000,3,8.763515e-001,0.000000e+000,,,,,,,,,,,,,,32,1,4.000000e+000,7.781982e-004,0.000000e+000,0,,0,
1524690213.085,,0.000000e+000,3.507475e+001,5.597907e-006,0.000000e+000,3,8.781275e-001,0.000000e+000,,,,,,,,,,,,,,32,1,4.000000e+000,1.560211e-003,0.000000e+000,0,,0,
1524690250.945,,0.000000e+000,3.506062e+001,5.696851e-006,0.000000e+000,3,8.791261e-001,0.000000e+000,,,,,,,,,,,,,,32,1,4.000000e+000,4.707336e-003,0.000000e+000,0,,0,
1524690288.806,,0.000000e+000,3.504375e+001,5.749896e-006,0.000000e+000,3,8.811242e-001,0.000000e+000,,,,,,,,,,,,,,32,1,4.000000e+000,5.489349e-003,0.000000e+000,0,,0,
1524690326.716,,0.000000e+000,3.502063e+001,5.833492e-006,0.000000e+000,3,8.788546e-001,0.000000e+000,,,,,,,,,,,,,,32,1,4.000000e+000,6.259918e-003,0.000000e+000,0,,0,
1524690364.704,,0.000000e+000,3.500106e+001,5.923497e-006,0.000000e+000,3,8.885950e-001,0.000000e+000,,,,,,,,,,,,,,32,1,4.000000e+000,0.000000e+000,0.000000e+000,0,,0,
1524690402.800,,0.000000e+000,3.499715e+001,5.928722e-006,0.000000e+000,3,8.894602e-001,0.000000e+000,,,,,,,,,,,,,,32,1,4.000000e+000,0.000000e+000,0.000000e+000,0,,0,
1524690440.893,,0.000000e+000,3.499833e+001,5.991189e-006,0.000000e+000,3,8.832357e-001,0.000000e+000,,,,,,,,,,,,,,32,1,4.000000e+000,2.349854e-003,0.000000e+000,0,,0,
1524690478.983,,0.000000e+000,3.499872e+001,6.010794e-006,0.000000e+000,3,8.865691e-001,0.000000e+000,,,,,,,,,,,,,,32,1,4.000000e+000,0.000000e+000,0.000000e+000,0,,0,
1524690517.084,,0.000000e+000,3.499833e+001,6.136845e-006,0.000000e+000,3,8.859642e-001,0.000000e+000,,,,,,,,,,,,,,32,1,4.000000e+000,7.781982e-004,0.000000e+000,0,,0,
1524690555.170,,0.000000e+000,3.499793e+001,6.199140e-006,0.000000e+000,3,8.888783e-001,0.000000e+000,,,,,,,,,,,,,,32,1,4.000000e+000,1.567841e-003,0.000000e+000,0,,0,
1524690593.383,,0.000000e+000,3.499833e+001,6.252109e-006,0.000000e+000,3,8.886421e-001,0.000000e+000,,,,,,,,,,,,,,32,1,4.000000e+000,7.781982e-004,0.000000e+000,0,,0,
1524690631.516,,0.000000e+000,3.499676e+001,6.289922e-006,0.000000e+000,3,8.874286e-001,0.000000e+000,,,,,,,,,,,,,,32,1,4.000000e+000,7.820129e-004,0.000000e+000,0,,0,
1524690669.571,,0.000000e+000,3.499833e+001,6.382617e-006,0.000000e+000,3,8.899727e-001,0.000000e+000,,,,,,,,,,,,,,32,1,4.000000e+000,7.781982e-004,0.000000e+000,0,,0,
1524690707.664,,0.000000e+000,3.499793e+001,6.379159e-006,0.000000e+000,3,8.910342e-001,0.000000e+000,,,,,,,,,,,,,,32,1,4.000000e+000,1.567841e-003,0.000000e+000,0,,0,
1524690745.797,,0.000000e+000,3.499872e+001,6.424267e-006,0.000000e+000,3,8.876082e-001,0.000000e+000,,,,,,,,,,,,,,32,1,4.000000e+000,1.560211e-003,0.000000e+000,0,,0,
1524690783.820,,0.000000e+000,3.499833e+001,6.433102e-006,0.000000e+000,3,8.912255e-001,0.000000e+000,,,,,,,,,,,,,,32,1,4.000000e+000,7.781982e-004,0.000000e+000,0,,0,
1524690821.758,,0.000000e+000,3.499872e+001,6.463128e-006,0.000000e+000,3,8.963616e-001,0.000000e+000,,,,,,,,,,,,,,32,1,4.000000e+000,0.000000e+000,0.000000e+000,0,,0,
1524690859.847,,0.000000e+000,3.499794e+001,6.449738e-006,0.000000e+000,3,8.933894e-001,0.000000e+000,,,,,,,,,,,,,,32,1,4.000000e+000,0.000000e+000,0.000000e+000,0,,0,
1524690898.120,,0.000000e+000,3.499794e+001,6.442263e-006,0.000000e+000,3,8.901846e-001,0.000000e+000,,,,,,,,,,,,,,32,1,4.000000e+000,0.000000e+000,0.000000e+000,0,,0,
1524690936.208,,0.000000e+000,3.499872e+001,6.557037e-006,0.000000e+000,3,8.887762e-001,0.000000e+000,,,,,,,,,,,,,,32,1,4.000000e+000,1.560211e-003,0.000000e+000,0,,0,
1524690974.303,,0.000000e+000,3.499833e+001,6.581812e-006,0.000000e+000,3,8.894612e-001,0.000000e+000,,,,,,,,,,,,,,32,1,4.000000e+000,7.781982e-004,0.000000e+000,0,,0,
1524691012.866,,0.000000e+000,3.499754e+001,6.649333e-006,0.000000e+000,3,8.963177e-001,0.000000e+000,,,,,,,,,,,,,,32,1,4.000000e+000,7.896423e-004,0.000000e+000,0,,0,
1524691050.867,,0.000000e+000,3.499911e+001,6.679567e-006,0.000000e+000,3,8.955879e-001,0.000000e+000,,,,,,,,,,,,,,32,1,4.000000e+000,7.820129e-004,0.000000e+000,0,,0,
1524691088.967,,0.000000e+000,3.499833e+001,6.636792e-006,0.000000e+000,3,8.915853e-001,0.000000e+000,,,,,,,,,,,,,,32,1,4.000000e+000,7.781982e-004,0.000000e+000,0,,0,
1524691127.050,,0.000000e+000,3.499715e+001,6.708802e-006,0.000000e+000,3,8.917576e-001,0.000000e+000,,,,,,,,,,,,,,32,1,4.000000e+000,3.128052e-003,0.000000e+000,0,,0,
1524691165.151,,0.000000e+000,3.499715e+001,6.754651e-006,0.000000e+000,3,8.902971e-001,0.000000e+000,,,,,,,,,,,,,,32,1,4.000000e+000,1.571655e-003,0.000000e+000,0,,0,
1524691204.039,,0.000000e+000,3.499833e+001,6.665132e-006,0.000000e+000,3,8.951205e-001,0.000000e+000,,,,,,,,,,,,,,32,1,4.000000e+000,2.349854e-003,0.000000e+000,0,,0,
1524691241.645,,0.000000e+000,3.499871e+001,6.732692e-006,0.000000e+000,3,8.958288e-001,0.000000e+000,,,,,,,,,,,,,,32,1,4.000000e+000,3.128052e-003,0.000000e+000,0,,0,
1524691279.258,,0.000000e+000,3.499872e+001,6.688228e-006,0.000000e+000,3,9.000303e-001,0.000000e+000,,,,,,,,,,,,,,32,1,4.000000e+000,0.000000e+000,0.000000e+000,0,,0,
1524691317.223,,0.000000e+000,3.499794e+001,6.784441e-006,0.000000e+000,3,8.994083e-001,0.000000e+000,,,,,,,,,,,,,,32,1,4.000000e+000,0.000000e+000,0.000000e+000,0,,0,
1524691355.321,,0.000000e+000,3.499793e+001,6.794588e-006,0.000000e+000,3,8.939226e-001,0.000000e+000,,,,,,,,,,,,,,32,1,4.000000e+000,3.131866e-003,0.000000e+000,0,,0,
1524691393.407,,0.000000e+000,3.499872e+001,6.813123e-006,0.000000e+000,3,8.965863e-001,0.000000e+000,,,,,,,,,,,,,,32,1,4.000000e+000,0.000000e+000,0.000000e+000,0,,0,
1524691431.277,,0.000000e+000,3.499833e+001,6.851513e-006,0.000000e+000,3,8.953717e-001,0.000000e+000,,,,,,,,,,,,,,32,1,4.000000e+000,2.349854e-003,0.000000e+000,0,,0,
1524691468.851,,0.000000e+000,3.499872e+001,6.810039e-006,0.000000e+000,3,8.966365e-001,0.000000e+000,,,,,,,,,,,,,,32,1,4.000000e+000,0.000000e+000,0.000000e+000,0,,0,
1524691506.609,,0.000000e+000,3.499715e+001,6.863057e-006,0.000000e+000,3,9.019141e-001,0.000000e+000,,,,,,,,,,,,,,32,1,4.000000e+000,1.571655e-003,0.000000e+000,0,,0,
1524691544.447,,0.000000e+000,3.499794e+001,6.839719e-006,0.000000e+000,3,8.981965e-001,0.000000e+000,,,,,,,,,,,,,,32,1,4.000000e+000,0.000000e+000,0.000000e+000,0,,0,
1524691582.102,,0.000000e+000,3.499754e+001,6.867131e-006,0.000000e+000,3,8.985935e-001,0.000000e+000,,,,,,,,,,,,,,32,1,4.000000e+000,7.896423e-004,0.000000e+000,0,,0,
1524691620.193,,0.000000e+000,3.499871e+001,6.832220e-006,0.000000e+000,3,8.988099e-001,0.000000e+000,,,,,,,,,,,,,,32,1,4.000000e+000,3.128052e-003,0.000000e+000,0,,0,
1524691658.073,,0.000000e+000,3.499715e+001,6.869599e-006,0.000000e+000,3,9.007514e-001,0.000000e+000,,,,,,,,,,,,,,32,1,4.000000e+000,1.571655e-003,0.000000e+000,0,,0,
1524691695.641,,0.000000e+000,3.499950e+001,6.871662e-006,0.000000e+000,3,8.970129e-001,0.000000e+000,,,,,,,,,,,,,,32,1,4.000000e+000,1.560211e-003,0.000000e+000,0,,0,
1524691733.719,,0.000000e+000,3.499637e+001,6.902390e-006,0.000000e+000,3,8.975809e-001,0.000000e+000,,,,,,,,,,,,,,32,1,4.000000e+000,1.560211e-003,0.000000e+000,0,,0,
1524691771.965,,0.000000e+000,3.499715e+001,6.923497e-006,0.000000e+000,3,8.986712e-001,0.000000e+000,,,,,,,,,,,,,,32,1,4.000000e+000,1.571655e-003,0.000000e+000,0,,0,
1524691810.055,,0.000000e+000,3.499598e+001,6.886203e-006,0.000000e+000,3,9.004579e-001,0.000000e+000,,,,,,,,,,,,,,32,1,4.000000e+000,2.342224e-003,0.000000e+000,0,,0,
1524691848.048,,0.000000e+000,3.499793e+001,6.898605e-006,0.000000e+000,3,8.934836e-001,0.000000e+000,,,,,,,,,,,,,,32,1,4.000000e+000,1.567841e-003,0.000000e+000,0,,0,
1524691886.154,,0.000000e+000,3.499911e+001,6.936006e-006,0.000000e+000,3,9.006807e-001,0.000000e+000,,,,,,,,,,,,,,32,1,4.000000e+000,2.338409e-003,0.000000e+000,0,,0,
1524691924.820,,0.000000e+000,3.499793e+001,6.920763e-006,0.000000e+000,3,9.003368e-001,0.000000e+000,,,,,,,,,,,,,,32,1,4.000000e+000,3.131866e-003,0.000000e+000,0,,0,
1524691962.123,,0.000000e+000,3.499832e+001,6.942606e-006,0.000000e+000,3,8.945132e-001,0.000000e+000,,,,,,,,,,,,,,32,1,4.000000e+000,3.910065e-003,0.000000e+000,0,,0,
1524691999.941,,0.000000e+000,3.499872e+001,6.950232e-006,0.000000e+000,3,8.974138e-001,0.000000e+000,,,,,,,,,,,,,,32,1,4.000000e+000,1.560211e-003,0.000000e+000,0,,0,
1524692038.269,,0.000000e+000,3.499872e+001,6.955371e-006,0.000000e+000,3,8.991371e-001,0.000000e+000,,,,,,,,,,,,,,32,1,4.000000e+000,1.560211e-003,0.000000e+000,0,,0,
1524692076.682,,0.000000e+000,3.499793e+001,7.015988e-006,0.000000e+000,3,9.002495e-001,0.000000e+000,,,,,,,,,,,,,,32,1,4.000000e+000,1.567841e-003,0.000000e+000,0,,0,
1524692114.315,,0.000000e+000,3.499754e+001,6.947210e-006,0.000000e+000,3,8.998436e-001,0.000000e+000,,,,,,,,,,,,,,32,1,4.000000e+000,7.896423e-004,0.000000e+000,0,,0,
1524692152.386,,0.000000e+000,3.499872e+001,6.979221e-006,0.000000e+000,3,8.980758e-001,0.000000e+000,,,,,,,,,,,,,,32,1,4.000000e+000,1.560211e-003,0.000000e+000,0,,0,
1524692190.491,,0.000000e+000,3.499872e+001,6.996113e-006,0.000000e+000,3,8.968413e-001,0.000000e+000,,,,,,,,,,,,,,32,1,4.000000e+000,0.000000e+000,0.000000e+000,0,,0,
1524692228.612,,0.000000e+000,3.499911e+001,6.974225e-006,0.000000e+000,3,8.959500e-001,0.000000e+000,,,,,,,,,,,,,,32,1,4.000000e+000,7.820129e-004,0.000000e+000,0,,0,
1524692266.705,,0.000000e+000,3.499911e+001,7.004811e-006,0.000000e+000,3,8.978477e-001,0.000000e+000,,,,,,,,,,,,,,32,1,4.000000e+000,7.820129e-004,0.000000e+000,0,,0,
1524692304.795,,0.000000e+000,3.499872e+001,6.990639e-006,0.000000e+000,3,8.990063e-001,0.000000e+000,,,,,,,,,,,,,,32,1,4.000000e+000,1.560211e-003,0.000000e+000,0,,0,
1524692342.878,,0.000000e+000,3.499872e+001,7.019763e-006,0.000000e+000,3,8.997505e-001,0.000000e+000,,,,,,,,,,,,,,32,1,4.000000e+000,1.560211e-003,0.000000e+000,0,,0,
1524692380.984,,0.000000e+000,3.499833e+001,7.008937e-006,0.000000e+000,3,8.967984e-001,0.000000e+000,,,,,,,,,,,,,,32,1,4.000000e+000,2.349854e-003,0.000000e+000,0,,0,
1524692419.127,,0.000000e+000,3.499872e+001,7.029418e-006,0.000000e+000,3,8.971662e-001,0.000000e+000,,,,,,,,,,,,,,32,1,4.000000e+000,0.000000e+000,0.000000e+000,0,,0,
1524692456.680,,0.000000e+000,3.499989e+001,7.030983e-006,0.000000e+000,3,8.957686e-001,0.000000e+000,,,,,,,,,,,,,,32,1,4.000000e+000,7.781982e-004,0.000000e+000,0,,0,
1524692495.348,,0.000000e+000,3.499833e+001,6.986675e-006,0.000000e+000,3,9.004821e-001,0.000000e+000,,,,,,,,,,,,,,32,1,4.000000e+000,7.781982e-004,0.000000e+000,0,,0,
1524692532.181,,0.000000e+000,3.499872e+001,7.028269e-006,0.000000e+000,3,8.985475e-001,0.000000e+000,,,,,,,,,,,,,,32,1,4.000000e+000,1.560211e-003,0.000000e+000,0,,0,
1524692569.807,,0.000000e+000,3.499911e+001,7.030082e-006,0.000000e+000,3,8.981363e-001,0.000000e+000,,,,,,,,,,,,,,32,1,4.000000e+000,2.338409e-003,0.000000e+000,0,,0,
1524692607.800,,0.000000e+000,3.500106e+001,7.055166e-006,0.000000e+000,3,8.977977e-001,0.000000e+000,,,,,,,,,,,,,,32,1,4.000000e+000,4.692078e-003,0.000000e+000,0,,0,
1524692645.895,,0.000000e+000,3.499911e+001,7.086227e-006,0.000000e+000,3,9.009219e-001,0.000000e+000,,,,,,,,,,,,,,32,1,4.000000e+000,7.820129e-004,0.000000e+000,0,,0,
1524692684.663,,0.000000e+000,3.499833e+001,7.046130e-006,0.000000e+000,3,9.033758e-001,0.000000e+000,,,,,,,,,,,,,,32,1,4.000000e+000,7.781982e-004,0.000000e+000,0,,0,
1524692722.466,,0.000000e+000,3.499872e+001,7.036189e-006,0.000000e+000,3,9.015669e-001,0.000000e+000,,,,,,,,,,,,,,32,1,4.000000e+000,0.000000e+000,0.000000e+000,0,,0,
1524692761.549,,0.000000e+000,3.499833e+001,7.102765e-006,0.000000e+000,3,9.014717e-001,0.000000e+000,,,,,,,,,,,,,,32,1,4.000000e+000,7.781982e-004,0.000000e+000,0,,0,
1524692799.705,,0.000000e+000,3.499598e+001,7.019342e-006,0.000000e+000,3,9.042984e-001,0.000000e+000,,,,,,,,,,,,,,32,1,4.000000e+000,8.598328e-003,0.000000e+000,0,,0,
1524692837.603,,0.000000e+000,3.499833e+001,7.060821e-006,0.000000e+000,3,8.976262e-001,0.000000e+000,,,,,,,,,,,,,,32,1,4.000000e+000,7.781982e-004,0.000000e+000,0,,0,
1524692875.486,,0.000000e+000,3.499871e+001,7.078189e-006,0.000000e+000,3,8.958817e-001,0.000000e+000,,,,,,,,,,,,,,32,1,4.000000e+000,4.692078e-003,0.000000e+000,0,,0,
1524692913.587,,0.000000e+000,3.499677e+001,7.094789e-006,0.000000e+000,3,9.013367e-001,0.000000e+000,,,,,,,,,,,,,,32,1,4.000000e+000,3.910065e-003,0.000000e+000,0,,0,
1524692951.557,,0.000000e+000,3.499754e+001,7.073172e-006,0.000000e+000,3,8.996984e-001,0.000000e+000,,,,,,,,,,,,,,32,1,4.000000e+000,7.030487e-003,0.000000e+000,0,,0,
1524692989.268,,0.000000e+000,3.499872e+001,7.073199e-006,0.000000e+000,3,9.009063e-001,0.000000e+000,,,,,,,,,,,,,,32,1,4.000000e+000,1.560211e-003,0.000000e+000,0,,0,
1524693027.088,,0.000000e+000,3.499677e+001,7.099081e-006,0.000000e+000,3,9.010043e-001,0.000000e+000,,,,,,,,,,,,,,32,1,4.000000e+000,3.910065e-003,0.000000e+000,0,,0,
1524693065.596,,0.000000e+000,3.499794e+001,7.190024e-006,0.000000e+000,3,9.026556e-001,0.000000e+000,,,,,,,,,,,,,,32,1,4.000000e+000,0.000000e+000,0.000000e+000,0,,0,
1524693103.612,,0.000000e+000,3.499833e+001,7.070163e-006,0.000000e+000,3,9.030877e-001,0.000000e+000,,,,,,,,,,,,,,32,1,4.000000e+000,7.781982e-004,0.000000e+000,0,,0,
1524693142.350,,0.000000e+000,3.499638e+001,7.091429e-006,0.000000e+000,3,8.996651e-001,0.000000e+000,,,,,,,,,,,,,,32,1,4.000000e+000,4.688263e-003,0.000000e+000,0,,0,
1524693180.256,,0.000000e+000,3.499833e+001,7.119207e-006,0.000000e+000,3,8.963856e-001,0.000000e+000,,,,,,,,,,,,,,32,1,4.000000e+000,7.781982e-004,0.000000e+000,0,,0,
1524693218.139,,0.000000e+000,3.499833e+001,7.123582e-006,0.000000e+000,3,8.969561e-001,0.000000e+000,,,,,,,,,,,,,,32,1,4.000000e+000,7.781982e-004,0.000000e+000,0,,0,
1524693256.919,,0.000000e+000,3.499793e+001,7.102872e-006,0.000000e+000,3,9.007846e-001,0.000000e+000,,,,,,,,,,,,,,32,1,4.000000e+000,1.567841e-003,0.000000e+000,0,,0,
1524693295.705,,0.000000e+000,3.499872e+001,7.113218e-006,0.000000e+000,3,9.023083e-001,0.000000e+000,,,,,,,,,,,,,,32,1,4.000000e+000,1.560211e-003,0.000000e+000,0,,0,
1524693333.703,,0.000000e+000,3.499911e+001,7.094480e-006,0.000000e+000,3,8.940082e-001,0.000000e+000,,,,,,,,,,,,,,32,1,4.000000e+000,7.820129e-004,0.000000e+000,0,,0,
1524693371.758,,0.000000e+000,3.499638e+001,7.111789e-006,0.000000e+000,3,8.960972e-001,0.000000e+000,,,,,,,,,,,,,,32,1,4.000000e+000,3.131866e-003,0.000000e+000,0,,0,
1524693409.649,,0.000000e+000,3.499872e+001,7.139950e-006,0.000000e+000,3,8.968896e-001,0.000000e+000,,,,,,,,,,,,,,32,1,4.000000e+000,1.560211e-003,0.000000e+000,0,,0,
1524693447.465,,0.000000e+000,3.499833e+001,7.217051e-006,0.000000e+000,3,9.037970e-001,0.000000e+000,,,,,,,,,,,,,,32,1,4.000000e+000,7.781982e-004,0.000000e+000,0,,0,
1524693485.680,,0.000000e+000,3.499793e+001,7.156840e-006,0.000000e+000,3,8.984260e-001,0.000000e+000,,,,,,,,,,,,,,32,1,4.000000e+000,1.567841e-003,0.000000e+000,0,,0,
1524693523.668,,0.000000e+000,3.499794e+001,7.130001e-006,0.000000e+000,3,8.990959e-001,0.000000e+000,,,,,,,,,,,,,,32,1,4.000000e+000,0.000000e+000,0.000000e+000,0,,0,
1524693561.644,,0.000000e+000,3.499911e+001,7.115912e-006,0.000000e+000,3,8.943503e-001,0.000000e+000,,,,,,,,,,,,,,32,1,4.000000e+000,7.820129e-004,0.000000e+000,0,,0,
1524693599.989,,0.000000e+000,3.499872e+001,7.153251e-006,0.000000e+000,3,9.016058e-001,0.000000e+000,,,,,,,,,,,,,,32,1,4.000000e+000,1.560211e-003,0.000000e+000,0,,0,
1524693637.365,,0.000000e+000,3.499911e+001,7.189285e-006,0.000000e+000,3,9.047212e-001,0.000000e+000,,,,,,,,,,,,,,32,1,4.000000e+000,2.338409e-003,0.000000e+000,0,,0,
1524693675.438,,0.000000e+000,3.499833e+001,7.162040e-006,0.000000e+000,3,8.955058e-001,0.000000e+000,,,,,,,,,,,,,,32,1,4.000000e+000,7.781982e-004,0.000000e+000,0,,0,
1524693713.348,,0.000000e+000,3.499754e+001,7.165841e-006,0.000000e+000,3,9.006401e-001,0.000000e+000,,,,,,,,,,,,,,32,1,4.000000e+000,3.910065e-003,0.000000e+000,0,,0,
1524693751.454,,0.000000e+000,3.499832e+001,7.182721e-006,0.000000e+000,3,9.038445e-001,0.000000e+000,,,,,,,,,,,,,,32,1,4.000000e+000,7.030487e-003,0.000000e+000,0,,0,
1524693789.562,,0.000000e+000,3.499715e+001,7.171053e-006,0.000000e+000,3,8.979064e-001,0.000000e+000,,,,,,,,,,,,,,32,1,4.000000e+000,0.000000e+000,0.000000e+000,0,,0,
1524693827.687,,0.000000e+000,3.499911e+001,7.169825e-006,0.000000e+000,3,9.033181e-001,0.000000e+000,,,,,,,,,,,,,,32,1,4.000000e+000,7.820129e-004,0.000000e+000,0,,0,
1524693865.858,,0.000000e+000,3.499911e+001,7.148572e-006,0.000000e+000,3,9.022642e-001,0.000000e+000,,,,,,,,,,,,,,32,1,4.000000e+000,7.820129e-004,0.000000e+000,0,,0,
1524693903.909,,0.000000e+000,3.499872e+001,7.190044e-006,0.000000e+000,3,8.979853e-001,0.000000e+000,,,,,,,,,,,,,,32,1,4.000000e+000,1.560211e-003,0.000000e+000,0,,0,
1524693941.719,,0.000000e+000,3.499872e+001,7.174307e-006,0.000000e+000,3,9.063747e-001,0.000000e+000,,,,,,,,,,,,,,32,1,4.000000e+000,0.000000e+000,0.000000e+000,0,,0,
1524693979.605,,0.000000e+000,3.499989e+001,7.169019e-006,0.000000e+000,3,9.037226e-001,0.000000e+000,,,,,,,,,,,,,,32,1,4.000000e+000,7.781982e-004,0.000000e+000,0,,0,
1524694016.898,,0.000000e+000,3.499872e+001,7.200526e-006,0.000000e+000,3,9.008694e-001,0.000000e+000,,,,,,,,,,,,,,32,1,4.000000e+000,1.560211e-003,0.000000e+000,0,,0,
1524694055.058,,0.000000e+000,3.499794e+001,7.222657e-006,0.000000e+000,3,8.989587e-001,0.000000e+000,,,,,,,,,,,,,,32,1,4.000000e+000,0.000000e+000,0.000000e+000,0,,0,
1524694092.741,,0.000000e+000,3.499950e+001,7.222742e-006,0.000000e+000,3,9.017600e-001,0.000000e+000,,,,,,,,,,,,,,32,1,4.000000e+000,0.000000e+000,0.000000e+000,0,,0,
1524694130.895,,0.000000e+000,3.499989e+001,7.196187e-006,0.000000e+000,3,9.054993e-001,0.000000e+000,,,,,,,,,,,,,,32,1,4.000000e+000,2.342224e-003,0.000000e+000,0,,0,
1524694169.125,,0.000000e+000,3.500106e+001,7.181974e-006,0.000000e+000,3,9.024276e-001,0.000000e+000,,,,,,,,,,,,,,32,1,4.000000e+000,3.128052e-003,0.000000e+000,0,,0,
1524694207.133,,0.000000e+000,3.499911e+001,7.195224e-006,0.000000e+000,3,8.993247e-001,0.000000e+000,,,,,,,,,,,,,,32,1,4.000000e+000,7.820129e-004,0.000000e+000,0,,0,
1524694244.396,,0.000000e+000,3.500028e+001,7.162676e-006,0.000000e+000,3,9.020348e-001,0.000000e+000,,,,,,,,,,,,,,32,1,4.000000e+000,1.560211e-003,0.000000e+000,0,,0,
1524694283.074,,0.000000e+000,3.499911e+001,7.208639e-006,0.000000e+000,3,9.037350e-001,0.000000e+000,,,,,,,,,,,,,,32,1,4.000000e+000,7.820129e-004,0.000000e+000,0,,0,
1524694321.487,,0.000000e+000,3.499872e+001,7.195554e-006,0.000000e+000,3,9.009991e-001,0.000000e+000,,,,,,,,,,,,,,32,1,4.000000e+000,1.560211e-003,0.000000e+000,0,,0,
1524694359.508,,0.000000e+000,3.499833e+001,7.209700e-006,0.000000e+000,3,9.009365e-001,0.000000e+000,,,,,,,,,,,,,,32,1,4.000000e+000,7.781982e-004,0.000000e+000,0,,0,
1524694397.598,,0.000000e+000,3.499872e+001,7.195542e-006,0.000000e+000,3,8.982199e-001,0.000000e+000,,,,,,,,,,,,,,32,1,4.000000e+000,1.560211e-003,0.000000e+000,0,,0,
1524694435.724,,0.000000e+000,3.499911e+001,7.212053e-006,0.000000e+000,3,9.003711e-001,0.000000e+000,,,,,,,,,,,,,,32,1,4.000000e+000,7.820129e-004,0.000000e+000,0,,0,
1524694473.584,,0.000000e+000,3.499833e+001,7.308061e-006,0.000000e+000,3,9.017771e-001,0.000000e+000,,,,,,,,,,,,,,32,1,4.000000e+000,7.781982e-004,0.000000e+000,0,,0,
1524694511.098,,0.000000e+000,3.499833e+001,7.246525e-006,0.000000e+000,3,9.004589e-001,0.000000e+000,,,,,,,,,,,,,,32,1,4.000000e+000,7.781982e-004,0.000000e+000,0,,0,
1524694548.768,,0.000000e+000,3.499950e+001,7.210040e-006,0.000000e+000,3,9.056128e-001,0.000000e+000,,,,,,,,,,,,,,32,1,4.000000e+000,0.000000e+000,0.000000e+000,0,,0,
1524694586.756,,0.000000e+000,3.499833e+001,7.137043e-006,0.000000e+000,3,9.031477e-001,0.000000e+000,,,,,,,,,,,,,,32,1,4.000000e+000,7.781982e-004,0.000000e+000,0,,0,
1524694624.857,,0.000000e+000,3.499793e+001,7.173217e-006,0.000000e+000,3,9.029422e-001,0.000000e+000,,,,,,,,,,,,,,32,1,4.000000e+000,1.567841e-003,0.000000e+000,0,,0,
1524694662.975,,0.000000e+000,3.499950e+001,7.183678e-006,0.000000e+000,3,9.012296e-001,0.000000e+000,,,,,,,,,,,,,,32,1,4.000000e+000,3.120422e-003,0.000000e+000,0,,0,
1524694701.353,,0.000000e+000,3.499872e+001,7.235220e-006,0.000000e+000,3,9.031313e-001,0.000000e+000,,,,,,,,,,,,,,32,1,4.000000e+000,1.560211e-003,0.000000e+000,0,,0,
1524694739.556,,0.000000e+000,3.499911e+001,7.234415e-006,0.000000e+000,3,9.036977e-001,0.000000e+000,,,,,,,,,,,,,,32,1,4.000000e+000,7.820129e-004,0.000000e+000,0,,0,
1524694777.657,,0.000000e+000,3.499911e+001,7.245209e-006,0.000000e+000,3,8.994324e-001,0.000000e+000,,,,,,,,,,,,,,32,1,4.000000e+000,7.820129e-004,0.000000e+000,0,,0,
1524694815.752,,0.000000e+000,3.499872e+001,7.211301e-006,0.000000e+000,3,8.997971e-001,0.000000e+000,,,,,,,,,,,,,,32,1,4.000000e+000,1.560211e-003,0.000000e+000,0,,0,
1524694853.843,,0.000000e+000,3.499911e+001,7.238745e-006,0.000000e+000,3,9.002063e-001,0.000000e+000,,,,,,,,,,,,,,32,1,4.000000e+000,2.338409e-003,0.000000e+000,0,,0,
1524694892.498,,0.000000e+000,3.499989e+001,7.221596e-006,0.000000e+000,3,9.012973e-001,0.000000e+000,,,,,,,,,,,,,,32,1,4.000000e+000,2.342224e-003,0.000000e+000,0,,0,
1524694929.776,,0.000000e+000,3.499989e+001,7.173778e-006,0.000000e+000,3,8.974311e-001,0.000000e+000,,,,,,,,,,,,,,32,1,4.000000e+000,7.781982e-004,0.000000e+000,0,,0,
1524694967.304,,0.000000e+000,3.499872e+001,7.243667e-006,0.000000e+000,3,9.056277e-001,0.000000e+000,,,,,,,,,,,,,,32,1,4.000000e+000,0.000000e+000,0.000000e+000,0,,0,
1524695005.382,,0.000000e+000,3.499833e+001,7.234191e-006,0.000000e+000,3,9.021252e-001,0.000000e+000,,,,,,,,,,,,,,32,1,4.000000e+000,7.781982e-004,0.000000e+000,0,,0,
1524695042.963,,0.000000e+000,3.499911e+001,7.227139e-006,0.000000e+000,3,9.018634e-001,0.000000e+000,,,,,,,,,,,,,,32,1,4.000000e+000,2.338409e-003,0.000000e+000,0,,0,
1524695081.308,,0.000000e+000,3.499793e+001,7.255379e-006,0.000000e+000,3,9.043814e-001,0.000000e+000,,,,,,,,,,,,,,32,1,4.000000e+000,1.567841e-003,0.000000e+000,0,,0,
1524695119.439,,0.000000e+000,3.499872e+001,7.215166e-006,0.000000e+000,3,9.059911e-001,0.000000e+000,,,,,,,,,,,,,,32,1,4.000000e+000,0.000000e+000,0.000000e+000,0,,0,
1524695157.392,,0.000000e+000,3.499793e+001,7.238096e-006,0.000000e+000,3,9.003557e-001,0.000000e+000,,,,,,,,,,,,,,32,1,4.000000e+000,3.131866e-003,0.000000e+000,0,,0,
1524695194.430,,0.000000e+000,3.499833e+001,7.242112e-006,0.000000e+000,3,9.036657e-001,0.000000e+000,,,,,,,,,,,,,,32,1,4.000000e+000,7.781982e-004,0.000000e+000,0,,0,
1524695232.531,,0.000000e+000,3.499911e+001,7.243490e-006,0.000000e+000,3,9.020044e-001,0.000000e+000,,,,,,,,,,,,,,32,1,4.000000e+000,7.820129e-004,0.000000e+000,0,,0,
1524695270.044,,0.000000e+000,3.499833e+001,7.284355e-006,0.000000e+000,3,9.000689e-001,0.000000e+000,,,,,,,,,,,,,,32,1,4.000000e+000,7.781982e-004,0.000000e+000,0,,0,
1524695307.959,,0.000000e+000,3.499911e+001,7.272323e-006,0.000000e+000,3,8.971684e-001,0.000000e+000,,,,,,,,,,,,,,32,1,4.000000e+000,2.338409e-003,0.000000e+000,0,,0,
1524695346.047,,0.000000e+000,3.499950e+001,7.239214e-006,0.000000e+000,3,9.014325e-001,0.000000e+000,,,,,,,,,,,,,,32,1,4.000000e+000,0.000000e+000,0.000000e+000,0,,0,
1524695383.913,,0.000000e+000,3.499950e+001,7.259543e-006,0.000000e+000,3,8.970258e-001,0.000000e+000,,,,,,,,,,,,,,32,1,4.000000e+000,0.000000e+000,0.000000e+000,0,,0,
1524695422.819,,0.000000e+000,3.499989e+001,7.264913e-006,0.000000e+000,3,9.021200e-001,0.000000e+000,,,,,,,,,,,,,,32,1,4.000000e+000,7.781982e-004,0.000000e+000,0,,0,
1524695461.167,,0.000000e+000,3.499833e+001,7.255217e-006,0.000000e+000,3,9.014481e-001,0.000000e+000,,,,,,,,,,,,,,32,1,4.000000e+000,7.781982e-004,0.000000e+000,0,,0,
1524695499.570,,0.000000e+000,3.499872e+001,7.294227e-006,0.000000e+000,3,8.989643e-001,0.000000e+000,,,,,,,,,,,,,,32,1,4.000000e+000,0.000000e+000,0.000000e+000,0,,0,
1524695537.338,,0.000000e+000,3.499911e+001,7.292918e-006,0.000000e+000,3,9.043060e-001,0.000000e+000,,,,,,,,,,,,,,32,1,4.000000e+000,7.820129e-004,0.000000e+000,0,,0,
1524695575.456,,0.000000e+000,3.499754e+001,7.271943e-006,0.000000e+000,3,9.058427e-001,0.000000e+000,,,,,,,,,,,,,,32,1,4.000000e+000,7.896423e-004,0.000000e+000,0,,0,
1524695613.569,,0.000000e+000,3.499833e+001,7.251808e-006,0.000000e+000,3,9.029242e-001,0.000000e+000,,,,,,,,,,,,,,32,1,4.000000e+000,7.781982e-004,0.000000e+000,0,,0,
1524695650.967,,0.000000e+000,3.499793e+001,7.252833e-006,0.000000e+000,3,9.030635e-001,0.000000e+000,,,,,,,,,,,,,,32,1,4.000000e+000,1.567841e-003,0.000000e+000,0,,0,
1524695688.500,,0.000000e+000,3.499833e+001,7.274169e-006,0.000000e+000,3,8.987424e-001,0.000000e+000,,,,,,,,,,,,,,32,1,4.000000e+000,2.349854e-003,0.000000e+000,0,,0,
1524695726.095,,0.000000e+000,3.499677e+001,7.282470e-006,0.000000e+000,3,9.025112e-001,0.000000e+000,,,,,,,,,,,,,,32,1,4.000000e+000,3.910065e-003,0.000000e+000,0,,0,
1524695764.221,,0.000000e+000,3.499872e+001,7.237093e-006,0.000000e+000,3,9.023059e-001,0.000000e+000,,,,,,,,,,,,,,32,1,4.000000e+000,0.000000e+000,0.000000e+000,0,,0,
1524695802.952,,0.000000e+000,3.499872e+001,7.228579e-006,0.000000e+000,3,9.024458e-001,0.000000e+000,,,,,,,,,,,,,,32,1,4.000000e+000,1.560211e-003,0.000000e+000,0,,0,
1524695841.600,,0.000000e+000,3.499911e+001,7.258025e-006,0.000000e+000,3,9.004728e-001,0.000000e+000,,,,,,,,,,,,,,32,1,4.000000e+000,7.820129e-004,0.000000e+000,0,,0,
1524695878.765,,0.000000e+000,3.499793e+001,7.268103e-006,0.000000e+000,3,9.047716e-001,0.000000e+000,,,,,,,,,,,,,,32,1,4.000000e+000,1.567841e-003,0.000000e+000,0,,0,
1524695916.773,,0.000000e+000,3.499950e+001,7.271472e-006,0.000000e+000,3,9.033280e-001,0.000000e+000,,,,,,,,,,,,,,32,1,4.000000e+000,1.560211e-003,0.000000e+000,0,,0,
1524695954.871,,0.000000e+000,3.499950e+001,7.274164e-006,0.000000e+000,3,9.025882e-001,0.000000e+000,,,,,,,,,,,,,,32,1,4.000000e+000,0.000000e+000,0.000000e+000,0,,0,
1524695993.337,,0.000000e+000,3.499989e+001,7.286399e-006,0.000000e+000,3,9.032590e-001,0.000000e+000,,,,,,,,,,,,,,32,1,4.000000e+000,7.781982e-004,0.000000e+000,0,,0,
1524696031.462,,0.000000e+000,3.499950e+001,7.293159e-006,0.000000e+000,3,9.026927e-001,0.000000e+000,,,,,,,,,,,,,,32,1,4.000000e+000,0.000000e+000,0.000000e+000,0,,0,
1524696070.143,,0.000000e+000,3.499793e+001,7.303374e-006,0.000000e+000,3,9.013231e-001,0.000000e+000,,,,,,,,,,,,,,32,1,4.000000e+000,1.567841e-003,0.000000e+000,0,,0,
1524696108.174,,0.000000e+000,3.499872e+001,7.325008e-006,0.000000e+000,3,9.022369e-001,0.000000e+000,,,,,,,,,,,,,,32,1,4.000000e+000,0.000000e+000,0.000000e+000,0,,0,
1524696145.774,,0.000000e+000,3.499911e+001,7.290423e-006,0.000000e+000,3,9.023207e-001,0.000000e+000,,,,,,,,,,,,,,32,1,4.000000e+000,7.820129e-004,0.000000e+000,0,,0,
1524696183.095,,0.000000e+000,3.499950e+001,7.291424e-006,0.000000e+000,3,9.014117e-001,0.000000e+000,,,,,,,,,,,,,,32,1,4.000000e+000,1.560211e-003,0.000000e+000,0,,0,
1524696220.888,,0.000000e+000,3.500028e+001,7.277070e-006,0.000000e+000,3,9.010048e-001,0.000000e+000,,,,,,,,,,,,,,32,1,4.000000e+000,1.560211e-003,0.000000e+000,0,,0,
1524696259.028,,0.000000e+000,3.499872e+001,7.295960e-006,0.000000e+000,3,9.015895e-001,0.000000e+000,,,,,,,,,,,,,,32,1,4.000000e+000,0.000000e+000,0.000000e+000,0,,0,
1524696296.476,,0.000000e+000,3.499872e+001,7.315329e-006,0.000000e+000,3,9.045792e-001,0.000000e+000,,,,,,,,,,,,,,32,1,4.000000e+000,0.000000e+000,0.000000e+000,0,,0,
1524696334.599,,0.000000e+000,3.499911e+001,7.304592e-006,0.000000e+000,3,9.080287e-001,0.000000e+000,,,,,,,,,,,,,,32,1,4.000000e+000,7.820129e-004,0.000000e+000,0,,0,
1524696372.765,,0.000000e+000,3.499989e+001,7.292149e-006,0.000000e+000,3,9.051667e-001,0.000000e+000,,,,,,,,,,,,,,32,1,4.000000e+000,2.342224e-003,0.000000e+000,0,,0,
1524696410.663,,0.000000e+000,3.500067e+001,7.290388e-006,0.000000e+000,3,8.990259e-001,0.000000e+000,,,,,,,,,,,,,,32,1,4.000000e+000,7.820129e-004,0.000000e+000,0,,0,
1524696448.439,,0.000000e+000,3.499911e+001,7.315654e-006,0.000000e+000,3,9.035211e-001,0.000000e+000,,,,,,,,,,,,,,32,1,4.000000e+000,7.820129e-004,0.000000e+000,0,,0,
1524696486.339,,0.000000e+000,3.499638e+001,7.332288e-006,0.000000e+000,3,9.028246e-001,0.000000e+000,,,,,,,,,,,,,,32,1,4.000000e+000,4.688263e-003,0.000000e+000,0,,0,
1524696524.152,,0.000000e+000,3.500028e+001,7.314135e-006,0.000000e+000,3,9.030142e-001,0.000000e+000,,,,,,,,,,,,,,32,1,4.000000e+000,1.560211e-003,0.000000e+000,0,,0,
1524696562.230,,0.000000e+000,3.499872e+001,7.302779e-006,0.000000e+000,3,9.043203e-001,0.000000e+000,,,,,,,,,,,,,,32,1,4.000000e+000,0.000000e+000,0.000000e+000,0,,0,
1524696600.348,,0.000000e+000,3.499872e+001,7.314456e-006,0.000000e+000,3,9.065633e-001,0.000000e+000,,,,,,,,,,,,,,32,1,4.000000e+000,1.560211e-003,0.000000e+000,0,,0,
1524696638.561,,0.000000e+000,3.499872e+001,7.339335e-006,0.000000e+000,3,9.036038e-001,0.000000e+000,,,,,,,,,,,,,,32,1,4.000000e+000,0.000000e+000,0.000000e+000,0,,0,
1524696675.759,,0.000000e+000,3.499911e+001,7.325446e-006,0.000000e+000,3,9.032485e-001,0.000000e+000,,,,,,,,,,,,,,32,1,4.000000e+000,7.820129e-004,0.000000e+000,0,,0,
1524696713.415,,0.000000e+000,3.499911e+001,7.302924e-006,0.000000e+000,3,9.029803e-001,0.000000e+000,,,,,,,,,,,,,,32,1,4.000000e+000,2.338409e-003,0.000000e+000,0,,0,
1524696751.510,,0.000000e+000,3.499950e+001,7.307531e-006,0.000000e+000,3,9.051248e-001,0.000000e+000,,,,,,,,,,,,,,32,1,4.000000e+000,0.000000e+000,0.000000e+000,0,,0,
1524696789.511,,0.000000e+000,3.499833e+001,7.340787e-006,0.000000e+000,3,9.061918e-001,0.000000e+000,,,,,,,,,,,,,,32,1,4.000000e+000,7.781982e-004,0.000000e+000,0,,0,
1524696827.694,,0.000000e+000,3.499872e+001,7.345648e-006,0.000000e+000,3,8.992126e-001,0.000000e+000,,,,,,,,,,,,,,32,1,4.000000e+000,0.000000e+000,0.000000e+000,0,,0,
1524696865.287,,0.000000e+000,3.499754e+001,7.270314e-006,0.000000e+000,3,9.041849e-001,0.000000e+000,,,,,,,,,,,,,,32,1,4.000000e+000,7.896423e-004,0.000000e+000,0,,0,
1524696902.565,,0.000000e+000,3.499950e+001,7.316545e-006,0.000000e+000,3,9.023451e-001,0.000000e+000,,,,,,,,,,,,,,32,1,4.000000e+000,1.560211e-003,0.000000e+000,0,,0,
1524696940.658,,0.000000e+000,3.499950e+001,7.318935e-006,0.000000e+000,3,9.018105e-001,0.000000e+000,,,,,,,,,,,,,,32,1,4.000000e+000,1.560211e-003,0.000000e+000,0,,0,
1524696979.381,,0.000000e+000,3.499872e+001,7.302001e-006,0.000000e+000,3,9.026139e-001,0.000000e+000,,,,,,,,,,,,,,32,1,4.000000e+000,1.560211e-003,0.000000e+000,0,,0,
1524697017.174,,0.000000e+000,3.499833e+001,7.302217e-006,0.000000e+000,3,9.030766e-001,0.000000e+000,,,,,,,,,,,,,,32,1,4.000000e+000,7.781982e-004,0.000000e+000,0,,0,
1524697055.710,,0.000000e+000,3.499911e+001,7.289183e-006,0.000000e+000,3,9.021108e-001,0.000000e+000,,,,,,,,,,,,,,32,1,4.000000e+000,7.820129e-004,0.000000e+000,0,,0,
1524697093.810,,0.000000e+000,3.499793e+001,7.305244e-006,0.000000e+000,3,9.058913e-001,0.000000e+000,,,,,,,,,,,,,,32,1,4.000000e+000,1.567841e-003,0.000000e+000,0,,0,
1524697131.929,,0.000000e+000,3.499950e+001,7.303402e-006,0.000000e+000,3,9.034490e-001,0.000000e+000,,,,,,,,,,,,,,32,1,4.000000e+000,0.000000e+000,0.000000e+000,0,,0,
1524697169.462,,0.000000e+000,3.499911e+001,7.293543e-006,0.000000e+000,3,9.040860e-001,0.000000e+000,,,,,,,,,,,,,,32,1,4.000000e+000,7.820129e-004,0.000000e+000,0,,0,
1524697207.980,,0.000000e+000,3.499872e+001,7.314287e-006,0.000000e+000,3,9.025112e-001,0.000000e+000,,,,,,,,,,,,,,32,1,4.000000e+000,0.000000e+000,0.000000e+000,0,,0,
1524697245.898,,0.000000e+000,3.500185e+001,7.288967e-006,0.000000e+000,3,9.013662e-001,0.000000e+000,,,,,,,,,,,,,,32,1,4.000000e+000,1.567841e-003,0.000000e+000,0,,0,
1524697283.753,,0.000000e+000,3.499950e+001,7.258745e-006,0.000000e+000,3,9.003911e-001,0.000000e+000,,,,,,,,,,,,,,32,1,4.000000e+000,0.000000e+000,0.000000e+000,0,,0,
1524697322.194,,0.000000e+000,3.499950e+001,7.351829e-006,0.000000e+000,3,9.022681e-001,0.000000e+000,,,,,,,,,,,,,,32,1,4.000000e+000,0.000000e+000,0.000000e+000,0,,0,
1524697360.457,,0.000000e+000,3.499872e+001,7.249213e-006,0.000000e+000,3,9.010499e-001,0.000000e+000,,,,,,,,,,,,,,32,1,4.000000e+000,0.000000e+000,0.000000e+000,0,,0,
1524697399.462,,0.000000e+000,3.499911e+001,7.268780e-006,0.000000e+000,3,9.046123e-001,0.000000e+000,,,,,,,,,,,,,,32,1,4.000000e+000,7.820129e-004,0.000000e+000,0,,0,
1524697436.983,,0.000000e+000,3.499833e+001,7.291589e-006,0.000000e+000,3,8.994794e-001,0.000000e+000,,,,,,,,,,,,,,32,1,4.000000e+000,2.349854e-003,0.000000e+000,0,,0,
1524697475.779,,0.000000e+000,3.499911e+001,7.299997e-006,0.000000e+000,3,9.011349e-001,0.000000e+000,,,,,,,,,,,,,,32,1,4.000000e+000,7.820129e-004,0.000000e+000,0,,0,
1524697514.254,,0.000000e+000,3.499989e+001,7.279700e-006,0.000000e+000,3,9.078479e-001,0.000000e+000,,,,,,,,,,,,,,32,1,4.000000e+000,7.781982e-004,0.000000e+000,0,,0,
1524697551.595,,0.000000e+000,3.499950e+001,7.329790e-006,0.000000e+000,3,9.071548e-001,0.000000e+000,,,,,,,,,,,,,,32,1,4.000000e+000,0.000000e+000,0.000000e+000,0,,0,
1524697589.565,,0.000000e+000,3.499950e+001,7.286008e-006,0.000000e+000,3,9.013017e-001,0.000000e+000,,,,,,,,,,,,,,32,1,4.000000e+000,0.000000e+000,0.000000e+000,0,,0,
1524697627.723,,0.000000e+000,3.499911e+001,7.284923e-006,0.000000e+000,3,8.998211e-001,0.000000e+000,,,,,,,,,,,,,,32,1,4.000000e+000,7.820129e-004,0.000000e+000,0,,0,
1524697665.776,,0.000000e+000,3.499872e+001,7.355669e-006,0.000000e+000,3,9.045686e-001,0.000000e+000,,,,,,,,,,,,,,32,1,4.000000e+000,0.000000e+000,0.000000e+000,0,,0,
1524697703.954,,0.000000e+000,3.499872e+001,7.267999e-006,0.000000e+000,3,9.000419e-001,0.000000e+000,,,,,,,,,,,,,,32,1,4.000000e+000,1.560211e-003,0.000000e+000,0,,0,