File: Experimental Raw Data/MFn1 TRM/MFn1_TRMac_36K_0.08Kmin_VRMde_35K.dc.dat
[Header]
TITLE,MPMS DC Measurement
BYAPP,MPMS Measurement,2.1,Summary
FILEOPENTIME, 1524514281.514000 4/23/2018, 2:11:21 PM

INFO, APPNAME, MPMS MultiVu Application, Revision 1.61,  Build 082

INFO, NAME, MFn1
INFO, WEIGHT, 1.000
INFO, AREA, 1.000
INFO, LENGTH, 1.000
INFO, SHAPE, 0
INFO, COMMENT,
INFO, SEQUENCE FILE: TRMac_36K_0.08Kmin_VRMde_35K.seq


INFO, BACKGROUND DATA FILE:, None


STARTUPAXIS,X,4,LINEAR,AUTO,0.000000,0.000000
STARTUPAXIS,Y1,5,LINEAR,AUTO,0.000000,0.000000


STARTUPGROUP,Longitudinal
FIELDGROUP,Longitudinal,1,2,3,4,5,6,7,8,9,15,16,17,18,27,28
FIELDGROUP,Transverse,1,2,3,4,10,11,12,13,14,19,20,21,22,27,28

PLOT_APPEARANCE,ALL,HORZ_GRID_ON,VERT_GRID_ON,MARKERS_AND_LINES

[Data]
Time,Comment,Field (Oe),Temperature (K),Long Moment (emu),Long Scan Std Dev,Long Algorithm,Long Reg Fit,Long Percent Error (%),Trans Moment (emu),Trans Scan Std Dev,Trans Algorithm,Trans Reg Fit,Trans Percent Error (%),Long Moment [w/o ABS] (emu),Long Scan Std Dev [w/o ABS],Long Reg Fit [w/o ABS],Long Percent Error [w/o ABS] (%),Trans Moment [w/o ABS] (emu),Trans Scan Std Dev [w/o ABS],Trans Reg Fit [w/o ABS],Trans Percent Error [w/o ABS] (%),Points per Scan,Scans per Measurement,Scan Length (cm),Delta Temp (K),Rot Position (deg),Error,EC Comp. Running,Using ABS,
1524514281.512,,0.000000e+000,3.499520e+001,-2.535928e-005,0.000000e+000,3,9.720199e-001,0.000000e+000,,,,,,,,,,,,,,32,1,4.000000e+000,2.338409e-003,0.000000e+000,0,,0,
1524514306.872,,0.000000e+000,3.499637e+001,-2.395148e-005,0.000000e+000,3,9.705169e-001,0.000000e+000,,,,,,,,,,,,,,32,1,4.000000e+000,0.000000e+000,0.000000e+000,0,,0,
1524514332.230,,0.000000e+000,3.499754e+001,-2.282467e-005,0.000000e+000,3,9.658504e-001,0.000000e+000,,,,,,,,,,,,,,32,1,4.000000e+000,7.896423e-004,0.000000e+000,0,,0,
1524514357.648,,0.000000e+000,3.499872e+001,-2.191480e-005,0.000000e+000,3,9.663862e-001,0.000000e+000,,,,,,,,,,,,,,32,1,4.000000e+000,0.000000e+000,0.000000e+000,0,,0,
1524514383.406,,0.000000e+000,3.499833e+001,-2.110640e-005,0.000000e+000,3,9.655601e-001,0.000000e+000,,,,,,,,,,,,,,32,1,4.000000e+000,7.781982e-004,0.000000e+000,0,,0,
1524514408.811,,0.000000e+000,3.499950e+001,-2.042116e-005,0.000000e+000,3,9.648368e-001,0.000000e+000,,,,,,,,,,,,,,32,1,4.000000e+000,0.000000e+000,0.000000e+000,0,,0,
1524514434.451,,0.000000e+000,3.499754e+001,-1.991519e-005,0.000000e+000,3,9.638936e-001,0.000000e+000,,,,,,,,,,,,,,32,1,4.000000e+000,7.896423e-004,0.000000e+000,0,,0,
1524514459.809,,0.000000e+000,3.499872e+001,-1.939736e-005,0.000000e+000,3,9.632383e-001,0.000000e+000,,,,,,,,,,,,,,32,1,4.000000e+000,0.000000e+000,0.000000e+000,0,,0,
1524514485.187,,0.000000e+000,3.499559e+001,-1.897967e-005,0.000000e+000,3,9.640916e-001,0.000000e+000,,,,,,,,,,,,,,32,1,4.000000e+000,6.259918e-003,0.000000e+000,0,,0,
1524514509.920,,0.000000e+000,3.499950e+001,-1.851035e-005,0.000000e+000,3,9.623427e-001,0.000000e+000,,,,,,,,,,,,,,32,1,4.000000e+000,0.000000e+000,0.000000e+000,0,,0,
1524514535.193,,0.000000e+000,3.499833e+001,-1.810099e-005,0.000000e+000,3,9.591907e-001,0.000000e+000,,,,,,,,,,,,,,32,1,4.000000e+000,7.781982e-004,0.000000e+000,0,,0,
1524514560.548,,0.000000e+000,3.499911e+001,-1.776778e-005,0.000000e+000,3,9.578023e-001,0.000000e+000,,,,,,,,,,,,,,32,1,4.000000e+000,7.820129e-004,0.000000e+000,0,,0,
1524514585.924,,0.000000e+000,3.499794e+001,-1.744524e-005,0.000000e+000,3,9.584693e-001,0.000000e+000,,,,,,,,,,,,,,32,1,4.000000e+000,0.000000e+000,0.000000e+000,0,,0,
1524514611.311,,0.000000e+000,3.499794e+001,-1.709101e-005,0.000000e+000,3,9.550629e-001,0.000000e+000,,,,,,,,,,,,,,32,1,4.000000e+000,0.000000e+000,0.000000e+000,0,,0,
1524514636.699,,0.000000e+000,3.499989e+001,-1.681236e-005,0.000000e+000,3,9.569452e-001,0.000000e+000,,,,,,,,,,,,,,32,1,4.000000e+000,2.342224e-003,0.000000e+000,0,,0,
1524514662.042,,0.000000e+000,3.499754e+001,-1.652632e-005,0.000000e+000,3,9.556975e-001,0.000000e+000,,,,,,,,,,,,,,32,1,4.000000e+000,7.896423e-004,0.000000e+000,0,,0,
1524514687.467,,0.000000e+000,3.499794e+001,-1.632667e-005,0.000000e+000,3,9.554459e-001,0.000000e+000,,,,,,,,,,,,,,32,1,4.000000e+000,0.000000e+000,0.000000e+000,0,,0,
1524514712.833,,0.000000e+000,3.499833e+001,-1.603699e-005,0.000000e+000,3,9.547855e-001,0.000000e+000,,,,,,,,,,,,,,32,1,4.000000e+000,7.781982e-004,0.000000e+000,0,,0,
1524514738.191,,0.000000e+000,3.499793e+001,-1.581729e-005,0.000000e+000,3,9.537406e-001,0.000000e+000,,,,,,,,,,,,,,32,1,4.000000e+000,1.567841e-003,0.000000e+000,0,,0,
1524514763.581,,0.000000e+000,3.499754e+001,-1.559012e-005,0.000000e+000,3,9.523323e-001,0.000000e+000,,,,,,,,,,,,,,32,1,4.000000e+000,7.896423e-004,0.000000e+000,0,,0,
1524514788.954,,0.000000e+000,3.499794e+001,-1.533884e-005,0.000000e+000,3,9.528686e-001,0.000000e+000,,,,,,,,,,,,,,32,1,4.000000e+000,0.000000e+000,0.000000e+000,0,,0,
1524514814.344,,0.000000e+000,3.499872e+001,-1.512693e-005,0.000000e+000,3,9.499970e-001,0.000000e+000,,,,,,,,,,,,,,32,1,4.000000e+000,1.560211e-003,0.000000e+000,0,,0,
1524514839.740,,0.000000e+000,3.499833e+001,-1.494886e-005,0.000000e+000,3,9.512559e-001,0.000000e+000,,,,,,,,,,,,,,32,1,4.000000e+000,7.781982e-004,0.000000e+000,0,,0,
1524514865.133,,0.000000e+000,3.499754e+001,-1.479509e-005,0.000000e+000,3,9.513174e-001,0.000000e+000,,,,,,,,,,,,,,32,1,4.000000e+000,7.896423e-004,0.000000e+000,0,,0,
1524514890.333,,0.000000e+000,3.499833e+001,-1.460153e-005,0.000000e+000,3,9.458628e-001,0.000000e+000,,,,,,,,,,,,,,32,1,4.000000e+000,7.781982e-004,0.000000e+000,0,,0,
1524514915.326,,0.000000e+000,3.499833e+001,-1.441987e-005,0.000000e+000,3,9.502121e-001,0.000000e+000,,,,,,,,,,,,,,32,1,4.000000e+000,7.781982e-004,0.000000e+000,0,,0,
1524514939.831,,0.000000e+000,3.499833e+001,-1.442953e-005,0.000000e+000,3,9.479221e-001,0.000000e+000,,,,,,,,,,,,,,32,1,4.000000e+000,7.781982e-004,0.000000e+000,0,,0,
1524514965.697,,0.000000e+000,3.499754e+001,-1.410856e-005,0.000000e+000,3,9.491537e-001,0.000000e+000,,,,,,,,,,,,,,32,1,4.000000e+000,2.349854e-003,0.000000e+000,0,,0,
1524514990.537,,0.000000e+000,3.499872e+001,-1.398438e-005,0.000000e+000,3,9.479716e-001,0.000000e+000,,,,,,,,,,,,,,32,1,4.000000e+000,0.000000e+000,0.000000e+000,0,,0,
1524515015.932,,0.000000e+000,3.499833e+001,-1.383114e-005,0.000000e+000,3,9.472205e-001,0.000000e+000,,,,,,,,,,,,,,32,1,4.000000e+000,2.349854e-003,0.000000e+000,0,,0,
1524515041.293,,0.000000e+000,3.499950e+001,-1.367350e-005,0.000000e+000,3,9.478614e-001,0.000000e+000,,,,,,,,,,,,,,32,1,4.000000e+000,0.000000e+000,0.000000e+000,0,,0,
1524515066.698,,0.000000e+000,3.499872e+001,-1.353151e-005,0.000000e+000,3,9.462688e-001,0.000000e+000,,,,,,,,,,,,,,32,1,4.000000e+000,1.560211e-003,0.000000e+000,0,,0,
1524515092.038,,0.000000e+000,3.499754e+001,-1.336529e-005,0.000000e+000,3,9.472501e-001,0.000000e+000,,,,,,,,,,,,,,32,1,4.000000e+000,7.896423e-004,0.000000e+000,0,,0,
1524515117.386,,0.000000e+000,3.499833e+001,-1.326708e-005,0.000000e+000,3,9.466084e-001,0.000000e+000,,,,,,,,,,,,,,32,1,4.000000e+000,2.349854e-003,0.000000e+000,0,,0,
1524515142.769,,0.000000e+000,3.499872e+001,-1.315728e-005,0.000000e+000,3,9.444249e-001,0.000000e+000,,,,,,,,,,,,,,32,1,4.000000e+000,0.000000e+000,0.000000e+000,0,,0,
1524515168.140,,0.000000e+000,3.499872e+001,-1.303367e-005,0.000000e+000,3,9.452662e-001,0.000000e+000,,,,,,,,,,,,,,32,1,4.000000e+000,0.000000e+000,0.000000e+000,0,,0,
1524515207.005,,0.000000e+000,3.499872e+001,-1.273522e-005,0.000000e+000,3,9.442353e-001,0.000000e+000,,,,,,,,,,,,,,32,1,4.000000e+000,1.560211e-003,0.000000e+000,0,,0,
1524515232.386,,0.000000e+000,3.499872e+001,-1.270554e-005,0.000000e+000,3,9.437369e-001,0.000000e+000,,,,,,,,,,,,,,32,1,4.000000e+000,0.000000e+000,0.000000e+000,0,,0,
1524515258.218,,0.000000e+000,3.499911e+001,-1.257060e-005,0.000000e+000,3,9.422092e-001,0.000000e+000,,,,,,,,,,,,,,32,1,4.000000e+000,7.820129e-004,0.000000e+000,0,,0,
1524515283.194,,0.000000e+000,3.499911e+001,-1.246457e-005,0.000000e+000,3,9.419424e-001,0.000000e+000,,,,,,,,,,,,,,32,1,4.000000e+000,7.820129e-004,0.000000e+000,0,,0,
1524515308.519,,0.000000e+000,3.499911e+001,-1.237055e-005,0.000000e+000,3,9.423270e-001,0.000000e+000,,,,,,,,,,,,,,32,1,4.000000e+000,7.820129e-004,0.000000e+000,0,,0,
1524515333.897,,0.000000e+000,3.499911e+001,-1.225237e-005,0.000000e+000,3,9.394123e-001,0.000000e+000,,,,,,,,,,,,,,32,1,4.000000e+000,7.820129e-004,0.000000e+000,0,,0,
1524515359.292,,0.000000e+000,3.499950e+001,-1.217700e-005,0.000000e+000,3,9.402981e-001,0.000000e+000,,,,,,,,,,,,,,32,1,4.000000e+000,1.560211e-003,0.000000e+000,0,,0,
1524515385.400,,0.000000e+000,3.499872e+001,-1.203420e-005,0.000000e+000,3,9.407402e-001,0.000000e+000,,,,,,,,,,,,,,32,1,4.000000e+000,0.000000e+000,0.000000e+000,0,,0,
1524515410.048,,0.000000e+000,3.499794e+001,-1.193719e-005,0.000000e+000,3,9.375326e-001,0.000000e+000,,,,,,,,,,,,,,32,1,4.000000e+000,0.000000e+000,0.000000e+000,0,,0,
1524515436.183,,0.000000e+000,3.499833e+001,-1.184300e-005,0.000000e+000,3,9.383317e-001,0.000000e+000,,,,,,,,,,,,,,32,1,4.000000e+000,7.781982e-004,0.000000e+000,0,,0,
1524515461.236,,0.000000e+000,3.499911e+001,-1.176442e-005,0.000000e+000,3,9.386634e-001,0.000000e+000,,,,,,,,,,,,,,32,1,4.000000e+000,7.820129e-004,0.000000e+000,0,,0,
1524515486.609,,0.000000e+000,3.499911e+001,-1.166205e-005,0.000000e+000,3,9.383621e-001,0.000000e+000,,,,,,,,,,,,,,32,1,4.000000e+000,7.820129e-004,0.000000e+000,0,,0,
1524515511.995,,0.000000e+000,3.499794e+001,-1.157248e-005,0.000000e+000,3,9.376983e-001,0.000000e+000,,,,,,,,,,,,,,32,1,4.000000e+000,0.000000e+000,0.000000e+000,0,,0,
1524515536.922,,0.000000e+000,3.499911e+001,-1.149752e-005,0.000000e+000,3,9.380348e-001,0.000000e+000,,,,,,,,,,,,,,32,1,4.000000e+000,7.820129e-004,0.000000e+000,0,,0,
1524515562.773,,0.000000e+000,3.499833e+001,-1.137239e-005,0.000000e+000,3,9.352412e-001,0.000000e+000,,,,,,,,,,,,,,32,1,4.000000e+000,7.781982e-004,0.000000e+000,0,,0,
1524515588.133,,0.000000e+000,3.499989e+001,-1.130125e-005,0.000000e+000,3,9.365277e-001,0.000000e+000,,,,,,,,,,,,,,32,1,4.000000e+000,7.781982e-004,0.000000e+000,0,,0,
1524515613.144,,0.000000e+000,3.499950e+001,-1.117326e-005,0.000000e+000,3,9.347533e-001,0.000000e+000,,,,,,,,,,,,,,32,1,4.000000e+000,1.560211e-003,0.000000e+000,0,,0,
1524515638.354,,0.000000e+000,3.499833e+001,-1.109864e-005,0.000000e+000,3,9.338694e-001,0.000000e+000,,,,,,,,,,,,,,32,1,4.000000e+000,7.781982e-004,0.000000e+000,0,,0,
1524515663.794,,0.000000e+000,3.499950e+001,-1.102361e-005,0.000000e+000,3,9.341115e-001,0.000000e+000,,,,,,,,,,,,,,32,1,4.000000e+000,0.000000e+000,0.000000e+000,0,,0,
1524515689.187,,0.000000e+000,3.499833e+001,-1.096976e-005,0.000000e+000,3,9.292141e-001,0.000000e+000,,,,,,,,,,,,,,32,1,4.000000e+000,7.781982e-004,0.000000e+000,0,,0,
1524515714.960,,0.000000e+000,3.499833e+001,-1.086330e-005,0.000000e+000,3,9.335098e-001,0.000000e+000,,,,,,,,,,,,,,32,1,4.000000e+000,7.781982e-004,0.000000e+000,0,,0,
1524515739.875,,0.000000e+000,3.499833e+001,-1.081186e-005,0.000000e+000,3,9.351534e-001,0.000000e+000,,,,,,,,,,,,,,32,1,4.000000e+000,7.781982e-004,0.000000e+000,0,,0,
1524515764.806,,0.000000e+000,3.499833e+001,-1.070258e-005,0.000000e+000,3,9.321517e-001,0.000000e+000,,,,,,,,,,,,,,32,1,4.000000e+000,7.781982e-004,0.000000e+000,0,,0,
1524515790.181,,0.000000e+000,3.499833e+001,-1.064568e-005,0.000000e+000,3,9.327262e-001,0.000000e+000,,,,,,,,,,,,,,32,1,4.000000e+000,7.781982e-004,0.000000e+000,0,,0,
1524515815.557,,0.000000e+000,3.499872e+001,-1.063055e-005,0.000000e+000,3,9.357123e-001,0.000000e+000,,,,,,,,,,,,,,32,1,4.000000e+000,1.560211e-003,0.000000e+000,0,,0,
1524515840.964,,0.000000e+000,3.499989e+001,-1.051522e-005,0.000000e+000,3,9.318374e-001,0.000000e+000,,,,,,,,,,,,,,32,1,4.000000e+000,7.781982e-004,0.000000e+000,0,,0,
1524515866.080,,0.000000e+000,3.499872e+001,-1.042964e-005,0.000000e+000,3,9.305425e-001,0.000000e+000,,,,,,,,,,,,,,32,1,4.000000e+000,0.000000e+000,0.000000e+000,0,,0,
1524515890.913,,0.000000e+000,3.499872e+001,-1.036977e-005,0.000000e+000,3,9.285012e-001,0.000000e+000,,,,,,,,,,,,,,32,1,4.000000e+000,1.560211e-003,0.000000e+000,0,,0,
1524515916.308,,0.000000e+000,3.499754e+001,-1.028123e-005,0.000000e+000,3,9.286829e-001,0.000000e+000,,,,,,,,,,,,,,32,1,4.000000e+000,3.910065e-003,0.000000e+000,0,,0,
1524515941.638,,0.000000e+000,3.499677e+001,-1.021987e-005,0.000000e+000,3,9.275265e-001,0.000000e+000,,,,,,,,,,,,,,32,1,4.000000e+000,3.910065e-003,0.000000e+000,0,,0,
1524515967.069,,0.000000e+000,3.499833e+001,-1.016811e-005,0.000000e+000,3,9.276674e-001,0.000000e+000,,,,,,,,,,,,,,32,1,4.000000e+000,2.349854e-003,0.000000e+000,0,,0,
1524515992.442,,0.000000e+000,3.499911e+001,-1.008339e-005,0.000000e+000,3,9.272245e-001,0.000000e+000,,,,,,,,,,,,,,32,1,4.000000e+000,2.338409e-003,0.000000e+000,0,,0,
1524516017.807,,0.000000e+000,3.499950e+001,-9.993844e-006,0.000000e+000,3,9.268697e-001,0.000000e+000,,,,,,,,,,,,,,32,1,4.000000e+000,1.560211e-003,0.000000e+000,0,,0,
1524516043.180,,0.000000e+000,3.499754e+001,-9.936819e-006,0.000000e+000,3,9.261082e-001,0.000000e+000,,,,,,,,,,,,,,32,1,4.000000e+000,7.896423e-004,0.000000e+000,0,,0,
1524516069.100,,0.000000e+000,3.499911e+001,-9.891084e-006,0.000000e+000,3,9.255649e-001,0.000000e+000,,,,,,,,,,,,,,32,1,4.000000e+000,7.820129e-004,0.000000e+000,0,,0,
1524516107.411,,0.000000e+000,3.499793e+001,-9.755853e-006,0.000000e+000,3,9.273303e-001,0.000000e+000,,,,,,,,,,,,,,32,1,4.000000e+000,1.567841e-003,0.000000e+000,0,,0,
1524516133.254,,0.000000e+000,3.499715e+001,-9.746722e-006,0.000000e+000,3,9.242135e-001,0.000000e+000,,,,,,,,,,,,,,32,1,4.000000e+000,1.571655e-003,0.000000e+000,0,,0,
1524516158.177,,0.000000e+000,3.499715e+001,-9.658730e-006,0.000000e+000,3,9.249033e-001,0.000000e+000,,,,,,,,,,,,,,32,1,4.000000e+000,1.571655e-003,0.000000e+000,0,,0,
1524516183.547,,0.000000e+000,3.499833e+001,-9.585975e-006,0.000000e+000,3,9.263765e-001,0.000000e+000,,,,,,,,,,,,,,32,1,4.000000e+000,7.781982e-004,0.000000e+000,0,,0,
1524516208.850,,0.000000e+000,3.499989e+001,-9.569700e-006,0.000000e+000,3,9.264681e-001,0.000000e+000,,,,,,,,,,,,,,32,1,4.000000e+000,7.781982e-004,0.000000e+000,0,,0,
1524516234.300,,0.000000e+000,3.499911e+001,-9.501478e-006,0.000000e+000,3,9.231376e-001,0.000000e+000,,,,,,,,,,,,,,32,1,4.000000e+000,7.820129e-004,0.000000e+000,0,,0,
1524516259.696,,0.000000e+000,3.499833e+001,-9.429171e-006,0.000000e+000,3,9.245511e-001,0.000000e+000,,,,,,,,,,,,,,32,1,4.000000e+000,7.781982e-004,0.000000e+000,0,,0,
1524516285.018,,0.000000e+000,3.499872e+001,-9.375384e-006,0.000000e+000,3,9.232896e-001,0.000000e+000,,,,,,,,,,,,,,32,1,4.000000e+000,1.560211e-003,0.000000e+000,0,,0,
1524516310.384,,0.000000e+000,3.499989e+001,-9.317871e-006,0.000000e+000,3,9.223148e-001,0.000000e+000,,,,,,,,,,,,,,32,1,4.000000e+000,7.781982e-004,0.000000e+000,0,,0,
1524516335.844,,0.000000e+000,3.500067e+001,-9.261508e-006,0.000000e+000,3,9.197717e-001,0.000000e+000,,,,,,,,,,,,,,32,1,4.000000e+000,2.338409e-003,0.000000e+000,0,,0,
1524516361.637,,0.000000e+000,3.499989e+001,-9.203653e-006,0.000000e+000,3,9.224174e-001,0.000000e+000,,,,,,,,,,,,,,32,1,4.000000e+000,7.781982e-004,0.000000e+000,0,,0,
1524516386.095,,0.000000e+000,3.499911e+001,-9.157615e-006,0.000000e+000,3,9.216847e-001,0.000000e+000,,,,,,,,,,,,,,32,1,4.000000e+000,7.820129e-004,0.000000e+000,0,,0,
1524516411.385,,0.000000e+000,3.499911e+001,-9.118088e-006,0.000000e+000,3,9.233223e-001,0.000000e+000,,,,,,,,,,,,,,32,1,4.000000e+000,7.820129e-004,0.000000e+000,0,,0,
1524516436.833,,0.000000e+000,3.499794e+001,-9.043625e-006,0.000000e+000,3,9.188321e-001,0.000000e+000,,,,,,,,,,,,,,32,1,4.000000e+000,0.000000e+000,0.000000e+000,0,,0,
1524516462.216,,0.000000e+000,3.499793e+001,-8.991802e-006,0.000000e+000,3,9.178606e-001,0.000000e+000,,,,,,,,,,,,,,32,1,4.000000e+000,1.567841e-003,0.000000e+000,0,,0,
1524516487.604,,0.000000e+000,3.500067e+001,-8.964020e-006,0.000000e+000,3,9.185707e-001,0.000000e+000,,,,,,,,,,,,,,32,1,4.000000e+000,7.820129e-004,0.000000e+000,0,,0,
1524516512.899,,0.000000e+000,3.499989e+001,-8.925669e-006,0.000000e+000,3,9.199181e-001,0.000000e+000,,,,,,,,,,,,,,32,1,4.000000e+000,7.781982e-004,0.000000e+000,0,,0,
1524516538.545,,0.000000e+000,3.499872e+001,-8.872443e-006,0.000000e+000,3,9.174536e-001,0.000000e+000,,,,,,,,,,,,,,32,1,4.000000e+000,0.000000e+000,0.000000e+000,0,,0,
1524516564.110,,0.000000e+000,3.499794e+001,-8.754589e-006,0.000000e+000,3,9.148182e-001,0.000000e+000,,,,,,,,,,,,,,32,1,4.000000e+000,0.000000e+000,0.000000e+000,0,,0,
1524516589.433,,0.000000e+000,3.499677e+001,-8.720387e-006,0.000000e+000,3,9.139731e-001,0.000000e+000,,,,,,,,,,,,,,32,1,4.000000e+000,2.349854e-003,0.000000e+000,0,,0,
1524516615.306,,0.000000e+000,3.499872e+001,-8.656628e-006,0.000000e+000,3,9.162552e-001,0.000000e+000,,,,,,,,,,,,,,32,1,4.000000e+000,0.000000e+000,0.000000e+000,0,,0,
1524516640.361,,0.000000e+000,3.499833e+001,-8.708095e-006,0.000000e+000,3,9.131699e-001,0.000000e+000,,,,,,,,,,,,,,32,1,4.000000e+000,2.349854e-003,0.000000e+000,0,,0,
1524516665.582,,0.000000e+000,3.499911e+001,-8.603652e-006,0.000000e+000,3,9.145461e-001,0.000000e+000,,,,,,,,,,,,,,32,1,4.000000e+000,2.338409e-003,0.000000e+000,0,,0,
1524516690.967,,0.000000e+000,3.499833e+001,-8.564794e-006,0.000000e+000,3,9.145390e-001,0.000000e+000,,,,,,,,,,,,,,32,1,4.000000e+000,7.781982e-004,0.000000e+000,0,,0,
1524516716.342,,0.000000e+000,3.499872e+001,-8.530564e-006,0.000000e+000,3,9.159315e-001,0.000000e+000,,,,,,,,,,,,,,32,1,4.000000e+000,0.000000e+000,0.000000e+000,0,,0,
1524516741.710,,0.000000e+000,3.499872e+001,-8.471130e-006,0.000000e+000,3,9.118205e-001,0.000000e+000,,,,,,,,,,,,,,32,1,4.000000e+000,0.000000e+000,0.000000e+000,0,,0,
1524516767.141,,0.000000e+000,3.499911e+001,-8.423734e-006,0.000000e+000,3,9.130473e-001,0.000000e+000,,,,,,,,,,,,,,32,1,4.000000e+000,7.820129e-004,0.000000e+000,0,,0,
1524523035.842,,0.000000e+000,3.499324e+001,2.355602e-006,0.000000e+000,3,7.290643e-001,0.000000e+000,,,,,,,,,,,,,,32,1,4.000000e+000,0.000000e+000,0.000000e+000,0,,0,
1524523061.155,,0.000000e+000,3.499833e+001,2.779520e-006,0.000000e+000,3,7.471758e-001,0.000000e+000,,,,,,,,,,,,,,32,1,4.000000e+000,7.781982e-004,0.000000e+000,0,,0,
1524523085.513,,0.000000e+000,3.500106e+001,3.253788e-006,0.000000e+000,3,7.856500e-001,0.000000e+000,,,,,,,,,,,,,,32,1,4.000000e+000,3.128052e-003,0.000000e+000,0,,0,
1524523110.839,,0.000000e+000,3.500536e+001,3.711699e-006,0.000000e+000,3,8.021657e-001,0.000000e+000,,,,,,,,,,,,,,32,1,4.000000e+000,2.349854e-003,0.000000e+000,0,,0,
1524523136.241,,0.000000e+000,3.500576e+001,3.935803e-006,0.000000e+000,3,8.216010e-001,0.000000e+000,,,,,,,,,,,,,,32,1,4.000000e+000,0.000000e+000,0.000000e+000,0,,0,
1524523161.632,,0.000000e+000,3.500184e+001,4.167299e-006,0.000000e+000,3,8.298578e-001,0.000000e+000,,,,,,,,,,,,,,32,1,4.000000e+000,0.000000e+000,0.000000e+000,0,,0,
1524523186.957,,0.000000e+000,3.499872e+001,4.426214e-006,0.000000e+000,3,8.293969e-001,0.000000e+000,,,,,,,,,,,,,,32,1,4.000000e+000,1.560211e-003,0.000000e+000,0,,0,
1524523251.314,,0.000000e+000,3.509126e+001,5.477658e-006,0.000000e+000,3,8.773016e-001,0.000000e+000,,,,,,,,,,,,,,32,1,4.000000e+000,3.139496e-003,0.000000e+000,0,,0,
1524523276.540,,0.000000e+000,3.503356e+001,5.200803e-006,0.000000e+000,3,8.661070e-001,0.000000e+000,,,,,,,,,,,,,,32,1,4.000000e+000,2.900314e-002,0.000000e+000,0,,0,
1524523301.550,,0.000000e+000,3.500067e+001,5.271472e-006,0.000000e+000,3,8.731220e-001,0.000000e+000,,,,,,,,,,,,,,32,1,4.000000e+000,7.820129e-004,0.000000e+000,0,,0,
1524523327.045,,0.000000e+000,3.499833e+001,5.295302e-006,0.000000e+000,3,8.743837e-001,0.000000e+000,,,,,,,,,,,,,,32,1,4.000000e+000,7.781982e-004,0.000000e+000,0,,0,
1524523351.653,,0.000000e+000,3.499833e+001,5.409291e-006,0.000000e+000,3,8.675772e-001,0.000000e+000,,,,,,,,,,,,,,32,1,4.000000e+000,7.781982e-004,0.000000e+000,0,,0,
1524523377.009,,0.000000e+000,3.499833e+001,5.467432e-006,0.000000e+000,3,8.747137e-001,0.000000e+000,,,,,,,,,,,,,,32,1,4.000000e+000,7.781982e-004,0.000000e+000,0,,0,
1524523402.271,,0.000000e+000,3.499793e+001,5.578806e-006,0.000000e+000,3,8.693041e-001,0.000000e+000,,,,,,,,,,,,,,32,1,4.000000e+000,1.567841e-003,0.000000e+000,0,,0,
1524523427.709,,0.000000e+000,3.499793e+001,5.608769e-006,0.000000e+000,3,8.703694e-001,0.000000e+000,,,,,,,,,,,,,,32,1,4.000000e+000,1.567841e-003,0.000000e+000,0,,0,
1524523452.942,,0.000000e+000,3.499872e+001,5.632297e-006,0.000000e+000,3,8.813509e-001,0.000000e+000,,,,,,,,,,,,,,32,1,4.000000e+000,1.560211e-003,0.000000e+000,0,,0,
1524523478.312,,0.000000e+000,3.499793e+001,5.708453e-006,0.000000e+000,3,8.792315e-001,0.000000e+000,,,,,,,,,,,,,,32,1,4.000000e+000,1.567841e-003,0.000000e+000,0,,0,
1524523503.550,,0.000000e+000,3.499833e+001,5.785311e-006,0.000000e+000,3,8.729524e-001,0.000000e+000,,,,,,,,,,,,,,32,1,4.000000e+000,7.781982e-004,0.000000e+000,0,,0,
1524523528.858,,0.000000e+000,3.499794e+001,5.824427e-006,0.000000e+000,3,8.847162e-001,0.000000e+000,,,,,,,,,,,,,,32,1,4.000000e+000,0.000000e+000,0.000000e+000,0,,0,
1524523554.369,,0.000000e+000,3.499715e+001,5.833863e-006,0.000000e+000,3,8.869143e-001,0.000000e+000,,,,,,,,,,,,,,32,1,4.000000e+000,1.571655e-003,0.000000e+000,0,,0,
1524523579.146,,0.000000e+000,3.499833e+001,5.875398e-006,0.000000e+000,3,8.758358e-001,0.000000e+000,,,,,,,,,,,,,,32,1,4.000000e+000,7.781982e-004,0.000000e+000,0,,0,
1524523605.254,,0.000000e+000,3.499950e+001,5.930822e-006,0.000000e+000,3,8.796033e-001,0.000000e+000,,,,,,,,,,,,,,32,1,4.000000e+000,1.560211e-003,0.000000e+000,0,,0,
1524523630.380,,0.000000e+000,3.499833e+001,5.997288e-006,0.000000e+000,3,8.837515e-001,0.000000e+000,,,,,,,,,,,,,,32,1,4.000000e+000,7.781982e-004,0.000000e+000,0,,0,
1524523655.455,,0.000000e+000,3.499442e+001,6.064239e-006,0.000000e+000,3,8.830960e-001,0.000000e+000,,,,,,,,,,,,,,32,1,4.000000e+000,5.470276e-003,0.000000e+000,0,,0,
1524523681.018,,0.000000e+000,3.499794e+001,6.126333e-006,0.000000e+000,3,8.874888e-001,0.000000e+000,,,,,,,,,,,,,,32,1,4.000000e+000,0.000000e+000,0.000000e+000,0,,0,
1524523706.901,,0.000000e+000,3.499872e+001,6.133512e-006,0.000000e+000,3,8.888524e-001,0.000000e+000,,,,,,,,,,,,,,32,1,4.000000e+000,1.560211e-003,0.000000e+000,0,,0,
1524523731.794,,0.000000e+000,3.499833e+001,6.165237e-006,0.000000e+000,3,8.882557e-001,0.000000e+000,,,,,,,,,,,,,,32,1,4.000000e+000,7.781982e-004,0.000000e+000,0,,0,
1524523757.177,,0.000000e+000,3.499872e+001,6.176469e-006,0.000000e+000,3,8.903366e-001,0.000000e+000,,,,,,,,,,,,,,32,1,4.000000e+000,1.560211e-003,0.000000e+000,0,,0,
1524523782.549,,0.000000e+000,3.499872e+001,6.168870e-006,0.000000e+000,3,8.816723e-001,0.000000e+000,,,,,,,,,,,,,,32,1,4.000000e+000,0.000000e+000,0.000000e+000,0,,0,
1524523808.427,,0.000000e+000,3.499989e+001,6.277264e-006,0.000000e+000,3,8.849939e-001,0.000000e+000,,,,,,,,,,,,,,32,1,4.000000e+000,5.477905e-003,0.000000e+000,0,,0,
1524523833.938,,0.000000e+000,3.499911e+001,6.252192e-006,0.000000e+000,3,8.887626e-001,0.000000e+000,,,,,,,,,,,,,,32,1,4.000000e+000,7.820129e-004,0.000000e+000,0,,0,
1524523860.091,,0.000000e+000,3.499754e+001,6.384522e-006,0.000000e+000,3,8.998274e-001,0.000000e+000,,,,,,,,,,,,,,32,1,4.000000e+000,7.896423e-004,0.000000e+000,0,,0,
1524523885.478,,0.000000e+000,3.499911e+001,6.364472e-006,0.000000e+000,3,8.865061e-001,0.000000e+000,,,,,,,,,,,,,,32,1,4.000000e+000,3.910065e-003,0.000000e+000,0,,0,
1524523910.726,,0.000000e+000,3.499871e+001,6.300175e-006,0.000000e+000,3,8.875923e-001,0.000000e+000,,,,,,,,,,,,,,32,1,4.000000e+000,3.128052e-003,0.000000e+000,0,,0,
1524523936.409,,0.000000e+000,3.499598e+001,6.338106e-006,0.000000e+000,3,8.973066e-001,0.000000e+000,,,,,,,,,,,,,,32,1,4.000000e+000,7.781982e-004,0.000000e+000,0,,0,
1524523961.840,,0.000000e+000,3.499911e+001,6.381447e-006,0.000000e+000,3,8.945549e-001,0.000000e+000,,,,,,,,,,,,,,32,1,4.000000e+000,7.820129e-004,0.000000e+000,0,,0,
1524523987.633,,0.000000e+000,3.499832e+001,6.373842e-006,0.000000e+000,3,8.868167e-001,0.000000e+000,,,,,,,,,,,,,,32,1,4.000000e+000,3.910065e-003,0.000000e+000,0,,0,
1524524012.555,,0.000000e+000,3.499833e+001,6.404371e-006,0.000000e+000,3,8.924300e-001,0.000000e+000,,,,,,,,,,,,,,32,1,4.000000e+000,7.781982e-004,0.000000e+000,0,,0,
1524524036.971,,0.000000e+000,3.499833e+001,6.426078e-006,0.000000e+000,3,8.976014e-001,0.000000e+000,,,,,,,,,,,,,,32,1,4.000000e+000,7.781982e-004,0.000000e+000,0,,0,
1524524061.934,,0.000000e+000,3.499871e+001,6.484338e-006,0.000000e+000,3,8.861657e-001,0.000000e+000,,,,,,,,,,,,,,32,1,4.000000e+000,3.128052e-003,0.000000e+000,0,,0,
1524524087.226,,0.000000e+000,3.499793e+001,6.462051e-006,0.000000e+000,3,8.924894e-001,0.000000e+000,,,,,,,,,,,,,,32,1,4.000000e+000,1.567841e-003,0.000000e+000,0,,0,
1524524112.527,,0.000000e+000,3.499794e+001,6.474056e-006,0.000000e+000,3,8.887441e-001,0.000000e+000,,,,,,,,,,,,,,32,1,4.000000e+000,0.000000e+000,0.000000e+000,0,,0,
1524524137.897,,0.000000e+000,3.499911e+001,6.481130e-006,0.000000e+000,3,8.875520e-001,0.000000e+000,,,,,,,,,,,,,,32,1,4.000000e+000,7.820129e-004,0.000000e+000,0,,0,
1524524163.240,,0.000000e+000,3.499833e+001,6.570425e-006,0.000000e+000,3,8.949834e-001,0.000000e+000,,,,,,,,,,,,,,32,1,4.000000e+000,2.349854e-003,0.000000e+000,0,,0,
1524524188.160,,0.000000e+000,3.499872e+001,6.546612e-006,0.000000e+000,3,8.964472e-001,0.000000e+000,,,,,,,,,,,,,,32,1,4.000000e+000,1.560211e-003,0.000000e+000,0,,0,
1524524213.368,,0.000000e+000,3.500028e+001,6.534260e-006,0.000000e+000,3,8.946670e-001,0.000000e+000,,,,,,,,,,,,,,32,1,4.000000e+000,1.560211e-003,0.000000e+000,0,,0,
1524524238.799,,0.000000e+000,3.499872e+001,6.574840e-006,0.000000e+000,3,8.953394e-001,0.000000e+000,,,,,,,,,,,,,,32,1,4.000000e+000,1.560211e-003,0.000000e+000,0,,0,
1524524264.159,,0.000000e+000,3.499793e+001,6.564755e-006,0.000000e+000,3,8.991640e-001,0.000000e+000,,,,,,,,,,,,,,32,1,4.000000e+000,1.567841e-003,0.000000e+000,0,,0,
1524524289.664,,0.000000e+000,3.499793e+001,6.622976e-006,0.000000e+000,3,8.921040e-001,0.000000e+000,,,,,,,,,,,,,,32,1,4.000000e+000,3.131866e-003,0.000000e+000,0,,0,
1524524314.542,,0.000000e+000,3.499950e+001,6.604389e-006,0.000000e+000,3,8.970861e-001,0.000000e+000,,,,,,,,,,,,,,32,1,4.000000e+000,4.688263e-003,0.000000e+000,0,,0,
1524524339.885,,0.000000e+000,3.499833e+001,6.686353e-006,0.000000e+000,3,8.994424e-001,0.000000e+000,,,,,,,,,,,,,,32,1,4.000000e+000,7.781982e-004,0.000000e+000,0,,0,
1524524365.708,,0.000000e+000,3.499754e+001,6.637889e-006,0.000000e+000,3,8.974017e-001,0.000000e+000,,,,,,,,,,,,,,32,1,4.000000e+000,2.349854e-003,0.000000e+000,0,,0,
1524524390.613,,0.000000e+000,3.499871e+001,6.617993e-006,0.000000e+000,3,8.938995e-001,0.000000e+000,,,,,,,,,,,,,,32,1,4.000000e+000,3.128052e-003,0.000000e+000,0,,0,
1524524415.981,,0.000000e+000,3.499872e+001,6.625588e-006,0.000000e+000,3,8.908254e-001,0.000000e+000,,,,,,,,,,,,,,32,1,4.000000e+000,0.000000e+000,0.000000e+000,0,,0,
1524524441.439,,0.000000e+000,3.499989e+001,6.750329e-006,0.000000e+000,3,8.921846e-001,0.000000e+000,,,,,,,,,,,,,,32,1,4.000000e+000,7.781982e-004,0.000000e+000,0,,0,
1524524467.272,,0.000000e+000,3.499754e+001,6.679599e-006,0.000000e+000,3,8.923321e-001,0.000000e+000,,,,,,,,,,,,,,32,1,4.000000e+000,3.910065e-003,0.000000e+000,0,,0,
1524524492.122,,0.000000e+000,3.499872e+001,6.689348e-006,0.000000e+000,3,8.948755e-001,0.000000e+000,,,,,,,,,,,,,,32,1,4.000000e+000,0.000000e+000,0.000000e+000,0,,0,
1524524517.015,,0.000000e+000,3.499911e+001,6.707899e-006,0.000000e+000,3,8.953120e-001,0.000000e+000,,,,,,,,,,,,,,32,1,4.000000e+000,7.820129e-004,0.000000e+000,0,,0,
1524524542.113,,0.000000e+000,3.499833e+001,6.658970e-006,0.000000e+000,3,8.938261e-001,0.000000e+000,,,,,,,,,,,,,,32,1,4.000000e+000,7.781982e-004,0.000000e+000,0,,0,
1524524567.734,,0.000000e+000,3.499871e+001,6.714649e-006,0.000000e+000,3,8.955305e-001,0.000000e+000,,,,,,,,,,,,,,32,1,4.000000e+000,3.128052e-003,0.000000e+000,0,,0,
1524524593.089,,0.000000e+000,3.499911e+001,6.699070e-006,0.000000e+000,3,8.946702e-001,0.000000e+000,,,,,,,,,,,,,,32,1,4.000000e+000,7.820129e-004,0.000000e+000,0,,0,
1524524618.492,,0.000000e+000,3.499872e+001,6.781373e-006,0.000000e+000,3,8.986665e-001,0.000000e+000,,,,,,,,,,,,,,32,1,4.000000e+000,1.560211e-003,0.000000e+000,0,,0,
1524524643.645,,0.000000e+000,3.499872e+001,6.727486e-006,0.000000e+000,3,8.928373e-001,0.000000e+000,,,,,,,,,,,,,,32,1,4.000000e+000,0.000000e+000,0.000000e+000,0,,0,
1524524669.195,,0.000000e+000,3.499754e+001,6.722923e-006,0.000000e+000,3,8.963596e-001,0.000000e+000,,,,,,,,,,,,,,32,1,4.000000e+000,2.349854e-003,0.000000e+000,0,,0,
1524524694.643,,0.000000e+000,3.499872e+001,6.751616e-006,0.000000e+000,3,9.011961e-001,0.000000e+000,,,,,,,,,,,,,,32,1,4.000000e+000,1.560211e-003,0.000000e+000,0,,0,
1524524720.016,,0.000000e+000,3.499754e+001,6.746012e-006,0.000000e+000,3,8.965821e-001,0.000000e+000,,,,,,,,,,,,,,32,1,4.000000e+000,2.349854e-003,0.000000e+000,0,,0,
1524524744.814,,0.000000e+000,3.499833e+001,6.722941e-006,0.000000e+000,3,8.933161e-001,0.000000e+000,,,,,,,,,,,,,,32,1,4.000000e+000,2.349854e-003,0.000000e+000,0,,0,
1524524769.959,,0.000000e+000,3.499911e+001,6.760848e-006,0.000000e+000,3,8.960618e-001,0.000000e+000,,,,,,,,,,,,,,32,1,4.000000e+000,7.820129e-004,0.000000e+000,0,,0,
1524524794.712,,0.000000e+000,3.500028e+001,6.759020e-006,0.000000e+000,3,8.974670e-001,0.000000e+000,,,,,,,,,,,,,,32,1,4.000000e+000,6.259918e-003,0.000000e+000,0,,0,
1524524819.662,,0.000000e+000,3.499872e+001,6.772796e-006,0.000000e+000,3,8.971416e-001,0.000000e+000,,,,,,,,,,,,,,32,1,4.000000e+000,0.000000e+000,0.000000e+000,0,,0,
1524524845.465,,0.000000e+000,3.499754e+001,6.783067e-006,0.000000e+000,3,8.976047e-001,0.000000e+000,,,,,,,,,,,,,,32,1,4.000000e+000,7.896423e-004,0.000000e+000,0,,0,
1524524870.498,,0.000000e+000,3.499911e+001,6.785256e-006,0.000000e+000,3,9.008321e-001,0.000000e+000,,,,,,,,,,,,,,32,1,4.000000e+000,7.820129e-004,0.000000e+000,0,,0,
1524524895.793,,0.000000e+000,3.499794e+001,6.806264e-006,0.000000e+000,3,8.982916e-001,0.000000e+000,,,,,,,,,,,,,,32,1,4.000000e+000,0.000000e+000,0.000000e+000,0,,0,
1524524921.201,,0.000000e+000,3.499911e+001,6.755688e-006,0.000000e+000,3,8.992377e-001,0.000000e+000,,,,,,,,,,,,,,32,1,4.000000e+000,2.338409e-003,0.000000e+000,0,,0,
1524524946.454,,0.000000e+000,3.499911e+001,6.760268e-006,0.000000e+000,3,9.007587e-001,0.000000e+000,,,,,,,,,,,,,,32,1,4.000000e+000,7.820129e-004,0.000000e+000,0,,0,
1524524972.344,,0.000000e+000,3.499911e+001,6.814601e-006,0.000000e+000,3,9.019826e-001,0.000000e+000,,,,,,,,,,,,,,32,1,4.000000e+000,7.820129e-004,0.000000e+000,0,,0,
1524524997.555,,0.000000e+000,3.499872e+001,6.807806e-006,0.000000e+000,3,8.983982e-001,0.000000e+000,,,,,,,,,,,,,,32,1,4.000000e+000,1.560211e-003,0.000000e+000,0,,0,
1524525022.980,,0.000000e+000,3.499911e+001,6.832507e-006,0.000000e+000,3,8.953915e-001,0.000000e+000,,,,,,,,,,,,,,32,1,4.000000e+000,7.820129e-004,0.000000e+000,0,,0,
1524525048.846,,0.000000e+000,3.499872e+001,6.825920e-006,0.000000e+000,3,8.967193e-001,0.000000e+000,,,,,,,,,,,,,,32,1,4.000000e+000,1.560211e-003,0.000000e+000,0,,0,
1524525074.203,,0.000000e+000,3.499833e+001,6.825178e-006,0.000000e+000,3,8.982755e-001,0.000000e+000,,,,,,,,,,,,,,32,1,4.000000e+000,7.781982e-004,0.000000e+000,0,,0,
1524525100.309,,0.000000e+000,3.499754e+001,6.822818e-006,0.000000e+000,3,9.021068e-001,0.000000e+000,,,,,,,,,,,,,,32,1,4.000000e+000,2.349854e-003,0.000000e+000,0,,0,
1524525125.757,,0.000000e+000,3.499833e+001,6.854724e-006,0.000000e+000,3,8.932104e-001,0.000000e+000,,,,,,,,,,,,,,32,1,4.000000e+000,7.781982e-004,0.000000e+000,0,,0,
1524525151.140,,0.000000e+000,3.499794e+001,6.830118e-006,0.000000e+000,3,8.990569e-001,0.000000e+000,,,,,,,,,,,,,,32,1,4.000000e+000,0.000000e+000,0.000000e+000,0,,0,
1524525176.032,,0.000000e+000,3.500028e+001,6.802448e-006,0.000000e+000,3,8.971097e-001,0.000000e+000,,,,,,,,,,,,,,32,1,4.000000e+000,1.560211e-003,0.000000e+000,0,,0,
1524525201.405,,0.000000e+000,3.499872e+001,6.810579e-006,0.000000e+000,3,8.973693e-001,0.000000e+000,,,,,,,,,,,,,,32,1,4.000000e+000,1.560211e-003,0.000000e+000,0,,0,
1524525226.723,,0.000000e+000,3.499989e+001,6.838482e-006,0.000000e+000,3,9.014076e-001,0.000000e+000,,,,,,,,,,,,,,32,1,4.000000e+000,2.342224e-003,0.000000e+000,0,,0,
1524525251.694,,0.000000e+000,3.499950e+001,6.827584e-006,0.000000e+000,3,8.989922e-001,0.000000e+000,,,,,,,,,,,,,,32,1,4.000000e+000,0.000000e+000,0.000000e+000,0,,0,
1524525277.034,,0.000000e+000,3.499833e+001,6.857274e-006,0.000000e+000,3,9.003575e-001,0.000000e+000,,,,,,,,,,,,,,32,1,4.000000e+000,7.781982e-004,0.000000e+000,0,,0,
1524525302.327,,0.000000e+000,3.499794e+001,6.875799e-006,0.000000e+000,3,8.973830e-001,0.000000e+000,,,,,,,,,,,,,,32,1,4.000000e+000,0.000000e+000,0.000000e+000,0,,0,
1524525327.715,,0.000000e+000,3.499754e+001,6.853860e-006,0.000000e+000,3,8.959582e-001,0.000000e+000,,,,,,,,,,,,,,32,1,4.000000e+000,7.896423e-004,0.000000e+000,0,,0,
1524525352.653,,0.000000e+000,3.499911e+001,6.850735e-006,0.000000e+000,3,8.969956e-001,0.000000e+000,,,,,,,,,,,,,,32,1,4.000000e+000,7.820129e-004,0.000000e+000,0,,0,
1524525378.030,,0.000000e+000,3.499989e+001,6.849028e-006,0.000000e+000,3,8.996322e-001,0.000000e+000,,,,,,,,,,,,,,32,1,4.000000e+000,2.342224e-003,0.000000e+000,0,,0,
1524525403.408,,0.000000e+000,3.499872e+001,6.830162e-006,0.000000e+000,3,8.987137e-001,0.000000e+000,,,,,,,,,,,,,,32,1,4.000000e+000,1.560211e-003,0.000000e+000,0,,0,
1524525428.706,,0.000000e+000,3.499871e+001,6.820336e-006,0.000000e+000,3,9.011707e-001,0.000000e+000,,,,,,,,,,,,,,32,1,4.000000e+000,3.128052e-003,0.000000e+000,0,,0,
1524525454.087,,0.000000e+000,3.499911e+001,6.899764e-006,0.000000e+000,3,8.987385e-001,0.000000e+000,,,,,,,,,,,,,,32,1,4.000000e+000,2.338409e-003,0.000000e+000,0,,0,
1524525479.542,,0.000000e+000,3.499911e+001,6.892896e-006,0.000000e+000,3,8.990092e-001,0.000000e+000,,,,,,,,,,,,,,32,1,4.000000e+000,7.820129e-004,0.000000e+000,0,,0,
1524525504.862,,0.000000e+000,3.499833e+001,6.906634e-006,0.000000e+000,3,8.963102e-001,0.000000e+000,,,,,,,,,,,,,,32,1,4.000000e+000,7.781982e-004,0.000000e+000,0,,0,
1524525530.890,,0.000000e+000,3.499911e+001,6.925512e-006,0.000000e+000,3,9.001933e-001,0.000000e+000,,,,,,,,,,,,,,32,1,4.000000e+000,7.820129e-004,0.000000e+000,0,,0,
1524525556.035,,0.000000e+000,3.499754e+001,6.908986e-006,0.000000e+000,3,8.969736e-001,0.000000e+000,,,,,,,,,,,,,,32,1,4.000000e+000,7.896423e-004,0.000000e+000,0,,0,
1524525580.983,,0.000000e+000,3.499481e+001,6.914219e-006,0.000000e+000,3,9.029503e-001,0.000000e+000,,,,,,,,,,,,,,32,1,4.000000e+000,7.820129e-003,0.000000e+000,0,,0,
1524525606.371,,0.000000e+000,3.499872e+001,6.894316e-006,0.000000e+000,3,9.001397e-001,0.000000e+000,,,,,,,,,,,,,,32,1,4.000000e+000,1.560211e-003,0.000000e+000,0,,0,
1524525631.754,,0.000000e+000,3.499754e+001,6.893069e-006,0.000000e+000,3,8.979369e-001,0.000000e+000,,,,,,,,,,,,,,32,1,4.000000e+000,7.896423e-004,0.000000e+000,0,,0,
1524525657.137,,0.000000e+000,3.499989e+001,6.881291e-006,0.000000e+000,3,9.006357e-001,0.000000e+000,,,,,,,,,,,,,,32,1,4.000000e+000,7.781982e-004,0.000000e+000,0,,0,
1524525682.747,,0.000000e+000,3.499559e+001,6.859117e-006,0.000000e+000,3,8.984085e-001,0.000000e+000,,,,,,,,,,,,,,32,1,4.000000e+000,6.259918e-003,0.000000e+000,0,,0,
1524525707.270,,0.000000e+000,3.499872e+001,6.894164e-006,0.000000e+000,3,8.967636e-001,0.000000e+000,,,,,,,,,,,,,,32,1,4.000000e+000,1.560211e-003,0.000000e+000,0,,0,
1524525732.481,,0.000000e+000,3.499950e+001,6.951638e-006,0.000000e+000,3,8.969488e-001,0.000000e+000,,,,,,,,,,,,,,32,1,4.000000e+000,1.560211e-003,0.000000e+000,0,,0,
1524525757.898,,0.000000e+000,3.499833e+001,6.938918e-006,0.000000e+000,3,8.973876e-001,0.000000e+000,,,,,,,,,,,,,,32,1,4.000000e+000,7.781982e-004,0.000000e+000,0,,0,
1524525783.081,,0.000000e+000,3.499833e+001,6.961865e-006,0.000000e+000,3,9.053519e-001,0.000000e+000,,,,,,,,,,,,,,32,1,4.000000e+000,7.781982e-004,0.000000e+000,0,,0,
1524525808.359,,0.000000e+000,3.499911e+001,6.972022e-006,0.000000e+000,3,8.987283e-001,0.000000e+000,,,,,,,,,,,,,,32,1,4.000000e+000,2.338409e-003,0.000000e+000,0,,0,
1524525833.107,,0.000000e+000,3.499872e+001,6.886440e-006,0.000000e+000,3,8.994825e-001,0.000000e+000,,,,,,,,,,,,,,32,1,4.000000e+000,1.560211e-003,0.000000e+000,0,,0,
1524525858.482,,0.000000e+000,3.499950e+001,6.891834e-006,0.000000e+000,3,8.974415e-001,0.000000e+000,,,,,,,,,,,,,,32,1,4.000000e+000,1.560211e-003,0.000000e+000,0,,0,
1524525883.295,,0.000000e+000,3.499911e+001,6.913092e-006,0.000000e+000,3,8.984929e-001,0.000000e+000,,,,,,,,,,,,,,32,1,4.000000e+000,7.820129e-004,0.000000e+000,0,,0,
1524525908.721,,0.000000e+000,3.499833e+001,6.971610e-006,0.000000e+000,3,8.981166e-001,0.000000e+000,,,,,,,,,,,,,,32,1,4.000000e+000,7.781982e-004,0.000000e+000,0,,0,
1524525934.094,,0.000000e+000,3.499833e+001,6.935681e-006,0.000000e+000,3,8.980644e-001,0.000000e+000,,,,,,,,,,,,,,32,1,4.000000e+000,7.781982e-004,0.000000e+000,0,,0,
1524525959.446,,0.000000e+000,3.500028e+001,6.948415e-006,0.000000e+000,3,8.998259e-001,0.000000e+000,,,,,,,,,,,,,,32,1,4.000000e+000,0.000000e+000,0.000000e+000,0,,0,
1524525984.834,,0.000000e+000,3.499833e+001,6.933330e-006,0.000000e+000,3,8.994808e-001,0.000000e+000,,,,,,,,,,,,,,32,1,4.000000e+000,7.781982e-004,0.000000e+000,0,,0,
1524526010.192,,0.000000e+000,3.499794e+001,6.935238e-006,0.000000e+000,3,8.972119e-001,0.000000e+000,,,,,,,,,,,,,,32,1,4.000000e+000,0.000000e+000,0.000000e+000,0,,0,
1524526035.615,,0.000000e+000,3.499833e+001,6.945414e-006,0.000000e+000,3,8.993110e-001,0.000000e+000,,,,,,,,,,,,,,32,1,4.000000e+000,2.349854e-003,0.000000e+000,0,,0,
1524526060.540,,0.000000e+000,3.499871e+001,6.979638e-006,0.000000e+000,3,9.031374e-001,0.000000e+000,,,,,,,,,,,,,,32,1,4.000000e+000,3.128052e-003,0.000000e+000,0,,0,
1524526085.861,,0.000000e+000,3.499989e+001,6.988504e-006,0.000000e+000,3,8.983751e-001,0.000000e+000,,,,,,,,,,,,,,32,1,4.000000e+000,7.781982e-004,0.000000e+000,0,,0,
1524526111.284,,0.000000e+000,3.499833e+001,6.993002e-006,0.000000e+000,3,9.004407e-001,0.000000e+000,,,,,,,,,,,,,,32,1,4.000000e+000,7.781982e-004,0.000000e+000,0,,0,
1524526136.534,,0.000000e+000,3.499872e+001,6.983180e-006,0.000000e+000,3,9.020769e-001,0.000000e+000,,,,,,,,,,,,,,32,1,4.000000e+000,0.000000e+000,0.000000e+000,0,,0,
1524526161.349,,0.000000e+000,3.499715e+001,6.954241e-006,0.000000e+000,3,8.986457e-001,0.000000e+000,,,,,,,,,,,,,,32,1,4.000000e+000,0.000000e+000,0.000000e+000,0,,0,
1524526186.792,,0.000000e+000,3.499989e+001,6.974090e-006,0.000000e+000,3,9.043838e-001,0.000000e+000,,,,,,,,,,,,,,32,1,4.000000e+000,7.781982e-004,0.000000e+000,0,,0,
1524526211.455,,0.000000e+000,3.499638e+001,6.944914e-006,0.000000e+000,3,9.011554e-001,0.000000e+000,,,,,,,,,,,,,,32,1,4.000000e+000,3.131866e-003,0.000000e+000,0,,0,
1524526237.290,,0.000000e+000,3.499911e+001,6.920764e-006,0.000000e+000,3,9.004664e-001,0.000000e+000,,,,,,,,,,,,,,32,1,4.000000e+000,7.820129e-004,0.000000e+000,0,,0,
1524526262.196,,0.000000e+000,3.499911e+001,6.979677e-006,0.000000e+000,3,9.020608e-001,0.000000e+000,,,,,,,,,,,,,,32,1,4.000000e+000,7.820129e-004,0.000000e+000,0,,0,
1524526287.596,,0.000000e+000,3.499950e+001,6.973154e-006,0.000000e+000,3,9.003087e-001,0.000000e+000,,,,,,,,,,,,,,32,1,4.000000e+000,1.560211e-003,0.000000e+000,0,,0,
1524526312.962,,0.000000e+000,3.499872e+001,6.981547e-006,0.000000e+000,3,8.984813e-001,0.000000e+000,,,,,,,,,,,,,,32,1,4.000000e+000,1.560211e-003,0.000000e+000,0,,0,
1524526338.334,,0.000000e+000,3.499872e+001,6.965319e-006,0.000000e+000,3,8.982669e-001,0.000000e+000,,,,,,,,,,,,,,32,1,4.000000e+000,0.000000e+000,0.000000e+000,0,,0,
1524526363.650,,0.000000e+000,3.499911e+001,6.964025e-006,0.000000e+000,3,9.018316e-001,0.000000e+000,,,,,,,,,,,,,,32,1,4.000000e+000,7.820129e-004,0.000000e+000,0,,0,
1524526389.115,,0.000000e+000,3.500145e+001,6.952439e-006,0.000000e+000,3,9.032147e-001,0.000000e+000,,,,,,,,,,,,,,32,1,4.000000e+000,7.781982e-004,0.000000e+000,0,,0,
1524526414.416,,0.000000e+000,3.499872e+001,6.969040e-006,0.000000e+000,3,8.953845e-001,0.000000e+000,,,,,,,,,,,,,,32,1,4.000000e+000,1.560211e-003,0.000000e+000,0,,0,
1524526439.818,,0.000000e+000,3.499911e+001,6.983866e-006,0.000000e+000,3,9.013997e-001,0.000000e+000,,,,,,,,,,,,,,32,1,4.000000e+000,2.338409e-003,0.000000e+000,0,,0,
1524526465.189,,0.000000e+000,3.499911e+001,7.003352e-006,0.000000e+000,3,9.031282e-001,0.000000e+000,,,,,,,,,,,,,,32,1,4.000000e+000,2.338409e-003,0.000000e+000,0,,0,
1524526490.574,,0.000000e+000,3.499911e+001,6.972846e-006,0.000000e+000,3,8.980538e-001,0.000000e+000,,,,,,,,,,,,,,32,1,4.000000e+000,7.820129e-004,0.000000e+000,0,,0,
1524526515.950,,0.000000e+000,3.499950e+001,6.970857e-006,0.000000e+000,3,9.000334e-001,0.000000e+000,,,,,,,,,,,,,,32,1,4.000000e+000,0.000000e+000,0.000000e+000,0,,0,
1524526541.695,,0.000000e+000,3.499754e+001,6.968056e-006,0.000000e+000,3,9.016690e-001,0.000000e+000,,,,,,,,,,,,,,32,1,4.000000e+000,7.896423e-004,0.000000e+000,0,,0,
1524526567.093,,0.000000e+000,3.499911e+001,6.958862e-006,0.000000e+000,3,8.994561e-001,0.000000e+000,,,,,,,,,,,,,,32,1,4.000000e+000,7.820129e-004,0.000000e+000,0,,0,
1524526592.951,,0.000000e+000,3.499833e+001,6.996599e-006,0.000000e+000,3,9.019396e-001,0.000000e+000,,,,,,,,,,,,,,32,1,4.000000e+000,2.349854e-003,0.000000e+000,0,,0,
1524526617.884,,0.000000e+000,3.499911e+001,6.987813e-006,0.000000e+000,3,9.012317e-001,0.000000e+000,,,,,,,,,,,,,,32,1,4.000000e+000,7.820129e-004,0.000000e+000,0,,0,
1524526643.261,,0.000000e+000,3.500106e+001,6.999730e-006,0.000000e+000,3,8.995329e-001,0.000000e+000,,,,,,,,,,,,,,32,1,4.000000e+000,3.128052e-003,0.000000e+000,0,,0,
1524526668.594,,0.000000e+000,3.499793e+001,6.959811e-006,0.000000e+000,3,9.002119e-001,0.000000e+000,,,,,,,,,,,,,,32,1,4.000000e+000,1.567841e-003,0.000000e+000,0,,0,
1524526693.972,,0.000000e+000,3.499911e+001,6.980306e-006,0.000000e+000,3,8.982157e-001,0.000000e+000,,,,,,,,,,,,,,32,1,4.000000e+000,2.338409e-003,0.000000e+000,0,,0,
1524526719.395,,0.000000e+000,3.499950e+001,6.986436e-006,0.000000e+000,3,9.006963e-001,0.000000e+000,,,,,,,,,,,,,,32,1,4.000000e+000,1.560211e-003,0.000000e+000,0,,0,
1524526744.770,,0.000000e+000,3.499950e+001,7.004793e-006,0.000000e+000,3,8.979709e-001,0.000000e+000,,,,,,,,,,,,,,32,1,4.000000e+000,0.000000e+000,0.000000e+000,0,,0,
1524526770.116,,0.000000e+000,3.499872e+001,6.960415e-006,0.000000e+000,3,9.004732e-001,0.000000e+000,,,,,,,,,,,,,,32,1,4.000000e+000,0.000000e+000,0.000000e+000,0,,0,
1524526795.216,,0.000000e+000,3.499794e+001,6.960273e-006,0.000000e+000,3,9.028988e-001,0.000000e+000,,,,,,,,,,,,,,32,1,4.000000e+000,0.000000e+000,0.000000e+000,0,,0,
1524526820.411,,0.000000e+000,3.499950e+001,6.973979e-006,0.000000e+000,3,8.980060e-001,0.000000e+000,,,,,,,,,,,,,,32,1,4.000000e+000,0.000000e+000,0.000000e+000,0,,0,
1524526845.784,,0.000000e+000,3.499911e+001,6.974460e-006,0.000000e+000,3,8.972756e-001,0.000000e+000,,,,,,,,,,,,,,32,1,4.000000e+000,7.820129e-004,0.000000e+000,0,,0,
1524526871.107,,0.000000e+000,3.499950e+001,6.983163e-006,0.000000e+000,3,9.010902e-001,0.000000e+000,,,,,,,,,,,,,,32,1,4.000000e+000,1.560211e-003,0.000000e+000,0,,0,
1524526897.170,,0.000000e+000,3.499911e+001,6.990269e-006,0.000000e+000,3,9.016638e-001,0.000000e+000,,,,,,,,,,,,,,32,1,4.000000e+000,7.820129e-004,0.000000e+000,0,,0,
1524526923.123,,0.000000e+000,3.499950e+001,7.001599e-006,0.000000e+000,3,9.000714e-001,0.000000e+000,,,,,,,,,,,,,,32,1,4.000000e+000,0.000000e+000,0.000000e+000,0,,0,
1524526947.556,,0.000000e+000,3.499754e+001,6.982345e-006,0.000000e+000,3,9.025391e-001,0.000000e+000,,,,,,,,,,,,,,32,1,4.000000e+000,7.896423e-004,0.000000e+000,0,,0,
1524526972.934,,0.000000e+000,3.499872e+001,6.947999e-006,0.000000e+000,3,9.002091e-001,0.000000e+000,,,,,,,,,,,,,,32,1,4.000000e+000,0.000000e+000,0.000000e+000,0,,0,
1524526998.307,,0.000000e+000,3.499950e+001,6.947801e-006,0.000000e+000,3,9.024372e-001,0.000000e+000,,,,,,,,,,,,,,32,1,4.000000e+000,0.000000e+000,0.000000e+000,0,,0,
1524527023.054,,0.000000e+000,3.499989e+001,7.049476e-006,0.000000e+000,3,9.021132e-001,0.000000e+000,,,,,,,,,,,,,,32,1,4.000000e+000,2.342224e-003,0.000000e+000,0,,0,
1524527048.295,,0.000000e+000,3.499872e+001,7.028294e-006,0.000000e+000,3,9.006326e-001,0.000000e+000,,,,,,,,,,,,,,32,1,4.000000e+000,1.560211e-003,0.000000e+000,0,,0,
1524527073.678,,0.000000e+000,3.499911e+001,6.953327e-006,0.000000e+000,3,9.016806e-001,0.000000e+000,,,,,,,,,,,,,,32,1,4.000000e+000,7.820129e-004,0.000000e+000,0,,0,
1524527099.038,,0.000000e+000,3.500028e+001,7.037171e-006,0.000000e+000,3,8.984764e-001,0.000000e+000,,,,,,,,,,,,,,32,1,4.000000e+000,1.560211e-003,0.000000e+000,0,,0,
1524527124.561,,0.000000e+000,3.499989e+001,7.000191e-006,0.000000e+000,3,9.009166e-001,0.000000e+000,,,,,,,,,,,,,,32,1,4.000000e+000,7.781982e-004,0.000000e+000,0,,0,
1524527150.346,,0.000000e+000,3.499754e+001,6.965580e-006,0.000000e+000,3,8.988695e-001,0.000000e+000,,,,,,,,,,,,,,32,1,4.000000e+000,7.896423e-004,0.000000e+000,0,,0,
1524527175.204,,0.000000e+000,3.499911e+001,6.972670e-006,0.000000e+000,3,8.975046e-001,0.000000e+000,,,,,,,,,,,,,,32,1,4.000000e+000,7.820129e-004,0.000000e+000,0,,0,
1524527200.595,,0.000000e+000,3.499872e+001,6.996460e-006,0.000000e+000,3,9.054389e-001,0.000000e+000,,,,,,,,,,,,,,32,1,4.000000e+000,1.560211e-003,0.000000e+000,0,,0,
1524527225.922,,0.000000e+000,3.499989e+001,7.004685e-006,0.000000e+000,3,8.987758e-001,0.000000e+000,,,,,,,,,,,,,,32,1,4.000000e+000,7.781982e-004,0.000000e+000,0,,0,
1524527251.358,,0.000000e+000,3.499793e+001,7.003594e-006,0.000000e+000,3,8.975659e-001,0.000000e+000,,,,,,,,,,,,,,32,1,4.000000e+000,1.567841e-003,0.000000e+000,0,,0,
1524527276.728,,0.000000e+000,3.499794e+001,6.995832e-006,0.000000e+000,3,8.978267e-001,0.000000e+000,,,,,,,,,,,,,,32,1,4.000000e+000,0.000000e+000,0.000000e+000,0,,0,
1524527302.084,,0.000000e+000,3.499793e+001,7.028385e-006,0.000000e+000,3,8.969661e-001,0.000000e+000,,,,,,,,,,,,,,32,1,4.000000e+000,1.567841e-003,0.000000e+000,0,,0,
1524527327.454,,0.000000e+000,3.499911e+001,6.985032e-006,0.000000e+000,3,8.924847e-001,0.000000e+000,,,,,,,,,,,,,,32,1,4.000000e+000,7.820129e-004,0.000000e+000,0,,0,
1524527352.842,,0.000000e+000,3.499950e+001,6.979602e-006,0.000000e+000,3,8.958637e-001,0.000000e+000,,,,,,,,,,,,,,32,1,4.000000e+000,0.000000e+000,0.000000e+000,0,,0,
1524527378.240,,0.000000e+000,3.499911e+001,7.034278e-006,0.000000e+000,3,9.030356e-001,0.000000e+000,,,,,,,,,,,,,,32,1,4.000000e+000,7.820129e-004,0.000000e+000,0,,0,
1524527403.545,,0.000000e+000,3.499989e+001,6.996866e-006,0.000000e+000,3,8.979960e-001,0.000000e+000,,,,,,,,,,,,,,32,1,4.000000e+000,2.342224e-003,0.000000e+000,0,,0,
1524527428.948,,0.000000e+000,3.499793e+001,7.013003e-006,0.000000e+000,3,9.005299e-001,0.000000e+000,,,,,,,,,,,,,,32,1,4.000000e+000,1.567841e-003,0.000000e+000,0,,0,
1524527454.318,,0.000000e+000,3.499950e+001,6.981703e-006,0.000000e+000,3,8.975537e-001,0.000000e+000,,,,,,,,,,,,,,32,1,4.000000e+000,0.000000e+000,0.000000e+000,0,,0,
1524527479.726,,0.000000e+000,3.499793e+001,6.972395e-006,0.000000e+000,3,9.008776e-001,0.000000e+000,,,,,,,,,,,,,,32,1,4.000000e+000,1.567841e-003,0.000000e+000,0,,0,
1524527505.067,,0.000000e+000,3.499950e+001,6.995814e-006,0.000000e+000,3,9.000814e-001,0.000000e+000,,,,,,,,,,,,,,32,1,4.000000e+000,1.560211e-003,0.000000e+000,0,,0,
1524527530.489,,0.000000e+000,3.499872e+001,7.014432e-006,0.000000e+000,3,8.992462e-001,0.000000e+000,,,,,,,,,,,,,,32,1,4.000000e+000,0.000000e+000,0.000000e+000,0,,0,
1524527555.822,,0.000000e+000,3.499911e+001,7.002298e-006,0.000000e+000,3,9.013458e-001,0.000000e+000,,,,,,,,,,,,,,32,1,4.000000e+000,7.820129e-004,0.000000e+000,0,,0,
1524527581.193,,0.000000e+000,3.499950e+001,6.971895e-006,0.000000e+000,3,8.990636e-001,0.000000e+000,,,,,,,,,,,,,,32,1,4.000000e+000,0.000000e+000,0.000000e+000,0,,0,
1524527606.653,,0.000000e+000,3.499833e+001,6.989386e-006,0.000000e+000,3,9.051476e-001,0.000000e+000,,,,,,,,,,,,,,32,1,4.000000e+000,7.781982e-004,0.000000e+000,0,,0,
1524527631.898,,0.000000e+000,3.499989e+001,7.036630e-006,0.000000e+000,3,8.996624e-001,0.000000e+000,,,,,,,,,,,,,,32,1,4.000000e+000,7.781982e-004,0.000000e+000,0,,0,
1524527656.774,,0.000000e+000,3.499950e+001,6.992643e-006,0.000000e+000,3,8.983845e-001,0.000000e+000,,,,,,,,,,,,,,32,1,4.000000e+000,0.000000e+000,0.000000e+000,0,,0,
1524527682.152,,0.000000e+000,3.499833e+001,6.948411e-006,0.000000e+000,3,8.974840e-001,0.000000e+000,,,,,,,,,,,,,,32,1,4.000000e+000,7.781982e-004,0.000000e+000,0,,0,
1524527707.322,,0.000000e+000,3.499911e+001,7.017818e-006,0.000000e+000,3,8.965615e-001,0.000000e+000,,,,,,,,,,,,,,32,1,4.000000e+000,7.820129e-004,0.000000e+000,0,,0,
1524527732.880,,0.000000e+000,3.499911e+001,7.018466e-006,0.000000e+000,3,8.975725e-001,0.000000e+000,,,,,,,,,,,,,,32,1,4.000000e+000,7.820129e-004,0.000000e+000,0,,0,
1524527758.325,,0.000000e+000,3.499833e+001,7.041068e-006,0.000000e+000,3,9.063506e-001,0.000000e+000,,,,,,,,,,,,,,32,1,4.000000e+000,7.781982e-004,0.000000e+000,0,,0,
1524527783.686,,0.000000e+000,3.499950e+001,7.005893e-006,0.000000e+000,3,9.025592e-001,0.000000e+000,,,,,,,,,,,,,,32,1,4.000000e+000,1.560211e-003,0.000000e+000,0,,0,
1524527808.524,,0.000000e+000,3.499911e+001,6.975370e-006,0.000000e+000,3,9.040856e-001,0.000000e+000,,,,,,,,,,,,,,32,1,4.000000e+000,7.820129e-004,0.000000e+000,0,,0,
1524527833.911,,0.000000e+000,3.499911e+001,-1.222113e-004,0.000000e+000,3,3.370943e-001,0.000000e+000,,,,,,,,,,,,,,32,1,4.000000e+000,7.820129e-004,0.000000e+000,0,,0,
1524527859.222,,0.000000e+000,3.499754e+001,7.031151e-006,0.000000e+000,3,8.989438e-001,0.000000e+000,,,,,,,,,,,,,,32,1,4.000000e+000,2.349854e-003,0.000000e+000,0,,0,
1524527884.607,,0.000000e+000,3.499950e+001,7.022500e-006,0.000000e+000,3,9.014874e-001,0.000000e+000,,,,,,,,,,,,,,32,1,4.000000e+000,1.560211e-003,0.000000e+000,0,,0,
1524527909.983,,0.000000e+000,3.499833e+001,7.003667e-006,0.000000e+000,3,8.986217e-001,0.000000e+000,,,,,,,,,,,,,,32,1,4.000000e+000,7.781982e-004,0.000000e+000,0,,0,
1524527935.360,,0.000000e+000,3.500106e+001,7.093126e-006,0.000000e+000,3,9.021742e-001,0.000000e+000,,,,,,,,,,,,,,32,1,4.000000e+000,3.128052e-003,0.000000e+000,0,,0,
1524527960.681,,0.000000e+000,3.499833e+001,7.025121e-006,0.000000e+000,3,8.954061e-001,0.000000e+000,,,,,,,,,,,,,,32,1,4.000000e+000,7.781982e-004,0.000000e+000,0,,0,
1524527986.064,,0.000000e+000,3.499989e+001,6.976201e-006,0.000000e+000,3,9.035716e-001,0.000000e+000,,,,,,,,,,,,,,32,1,4.000000e+000,7.781982e-004,0.000000e+000,0,,0,
1524528011.459,,0.000000e+000,3.499950e+001,6.985479e-006,0.000000e+000,3,9.019901e-001,0.000000e+000,,,,,,,,,,,,,,32,1,4.000000e+000,1.560211e-003,0.000000e+000,0,,0,
1524528036.837,,0.000000e+000,3.499911e+001,7.020200e-006,0.000000e+000,3,8.990680e-001,0.000000e+000,,,,,,,,,,,,,,32,1,4.000000e+000,2.338409e-003,0.000000e+000,0,,0,
1524528049.490,,0.000000e+000,3.499950e+001,7.015877e-006,0.000000e+000,3,8.980040e-001,0.000000e+000,,,,,,,,,,,,,,32,1,4.000000e+000,1.560211e-003,0.000000e+000,0,,0,