File: Experimental Raw Data/TC04-12-01K Acquisition/TC04-12-01K_VRMac_54K_3000s.dc.dat
[Header]
TITLE,MPMS DC Measurement
BYAPP,MPMS Measurement,2.1,Summary
FILEOPENTIME, 1524298981.640000 4/21/2018, 2:23:01 AM

INFO, APPNAME, MPMS MultiVu Application, Revision 1.61,  Build 082

INFO, NAME, TC04-12-01K
INFO, WEIGHT, 1.000
INFO, AREA, 1.000
INFO, LENGTH, 1.000
INFO, SHAPE, 0
INFO, COMMENT,
INFO, SEQUENCE FILE: VRMac_54K_3000s_VRMde_55K.seq


INFO, BACKGROUND DATA FILE:, None


STARTUPAXIS,X,4,LINEAR,AUTO,0.000000,0.000000
STARTUPAXIS,Y1,5,LINEAR,AUTO,0.000000,0.000000


STARTUPGROUP,Longitudinal
FIELDGROUP,Longitudinal,1,2,3,4,5,6,7,8,9,15,16,17,18,27,28
FIELDGROUP,Transverse,1,2,3,4,10,11,12,13,14,19,20,21,22,27,28

PLOT_APPEARANCE,ALL,HORZ_GRID_ON,VERT_GRID_ON,MARKERS_AND_LINES

[Data]
Time,Comment,Field (Oe),Temperature (K),Long Moment (emu),Long Scan Std Dev,Long Algorithm,Long Reg Fit,Long Percent Error (%),Trans Moment (emu),Trans Scan Std Dev,Trans Algorithm,Trans Reg Fit,Trans Percent Error (%),Long Moment [w/o ABS] (emu),Long Scan Std Dev [w/o ABS],Long Reg Fit [w/o ABS],Long Percent Error [w/o ABS] (%),Trans Moment [w/o ABS] (emu),Trans Scan Std Dev [w/o ABS],Trans Reg Fit [w/o ABS],Trans Percent Error [w/o ABS] (%),Points per Scan,Scans per Measurement,Scan Length (cm),Delta Temp (K),Rot Position (deg),Error,EC Comp. Running,Using ABS,
1524298981.640,,0.000000e+000,5.404930e+001,-4.787456e-005,0.000000e+000,2,6.710421e-001,0.000000e+000,,,,,,,,,,,,,,32,1,4.000000e+000,1.274872e-002,0.000000e+000,0,,0,
1524298994.190,,0.000000e+000,5.403974e+001,-5.025665e-005,0.000000e+000,2,6.760780e-001,0.000000e+000,,,,,,,,,,,,,,32,1,4.000000e+000,6.381989e-003,0.000000e+000,0,,0,
1524299006.630,,0.000000e+000,5.403082e+001,-5.182783e-005,0.000000e+000,2,6.786103e-001,0.000000e+000,,,,,,,,,,,,,,32,1,4.000000e+000,1.146698e-002,0.000000e+000,0,,0,
1524299019.010,,0.000000e+000,5.402062e+001,-5.286561e-005,0.000000e+000,2,6.793189e-001,0.000000e+000,,,,,,,,,,,,,,32,1,4.000000e+000,8.922577e-003,0.000000e+000,0,,0,
1524299031.750,,0.000000e+000,5.401616e+001,-5.347489e-005,0.000000e+000,2,6.776128e-001,0.000000e+000,,,,,,,,,,,,,,32,1,4.000000e+000,0.000000e+000,0.000000e+000,0,,0,
1524299044.270,,0.000000e+000,5.401617e+001,-5.423964e-005,0.000000e+000,2,6.799905e-001,0.000000e+000,,,,,,,,,,,,,,32,1,4.000000e+000,2.552032e-003,0.000000e+000,0,,0,
1524299056.790,,0.000000e+000,5.401553e+001,-5.474575e-005,0.000000e+000,2,6.773120e-001,0.000000e+000,,,,,,,,,,,,,,32,1,4.000000e+000,1.270294e-003,0.000000e+000,0,,0,
1524299069.670,,0.000000e+000,5.400597e+001,-5.540511e-005,0.000000e+000,2,6.799402e-001,0.000000e+000,,,,,,,,,,,,,,32,1,4.000000e+000,7.629395e-003,0.000000e+000,0,,0,
1524299081.800,,0.000000e+000,5.400407e+001,-5.573545e-005,0.000000e+000,2,6.785964e-001,0.000000e+000,,,,,,,,,,,,,,32,1,4.000000e+000,3.822327e-003,0.000000e+000,0,,0,
1524299094.510,,0.000000e+000,5.400025e+001,-5.617523e-005,0.000000e+000,2,6.802748e-001,0.000000e+000,,,,,,,,,,,,,,32,1,4.000000e+000,3.818512e-003,0.000000e+000,0,,0,
1524299107.280,,0.000000e+000,5.400407e+001,-5.649729e-005,0.000000e+000,2,6.796202e-001,0.000000e+000,,,,,,,,,,,,,,32,1,4.000000e+000,1.144791e-002,0.000000e+000,0,,0,
1524299120.151,,0.000000e+000,5.399834e+001,-5.689739e-005,0.000000e+000,2,6.820391e-001,0.000000e+000,,,,,,,,,,,,,,32,1,4.000000e+000,2.540588e-003,0.000000e+000,0,,0,
1524299132.651,,0.000000e+000,5.399898e+001,-5.714282e-005,0.000000e+000,2,6.807483e-001,0.000000e+000,,,,,,,,,,,,,,32,1,4.000000e+000,1.270294e-003,0.000000e+000,0,,0,
1524299145.511,,0.000000e+000,5.400280e+001,-5.742352e-005,0.000000e+000,2,6.818877e-001,0.000000e+000,,,,,,,,,,,,,,32,1,4.000000e+000,8.911133e-003,0.000000e+000,0,,0,
1524299158.391,,0.000000e+000,5.400407e+001,-5.767189e-005,0.000000e+000,2,6.813436e-001,0.000000e+000,,,,,,,,,,,,,,32,1,4.000000e+000,1.270294e-003,0.000000e+000,0,,0,
1524299171.171,,0.000000e+000,5.400089e+001,-5.791762e-005,0.000000e+000,2,6.810184e-001,0.000000e+000,,,,,,,,,,,,,,32,1,4.000000e+000,5.088806e-003,0.000000e+000,0,,0,
1524299183.491,,0.000000e+000,5.400407e+001,-5.822365e-005,0.000000e+000,2,6.830267e-001,0.000000e+000,,,,,,,,,,,,,,32,1,4.000000e+000,1.144791e-002,0.000000e+000,0,,0,
1524299195.921,,0.000000e+000,5.400661e+001,-5.830862e-005,0.000000e+000,2,6.817008e-001,0.000000e+000,,,,,,,,,,,,,,32,1,4.000000e+000,6.359100e-003,0.000000e+000,0,,0,
1524299208.311,,0.000000e+000,5.399897e+001,-5.859555e-005,0.000000e+000,2,6.824353e-001,0.000000e+000,,,,,,,,,,,,,,32,1,4.000000e+000,8.911133e-003,0.000000e+000,0,,0,
1524299220.771,,0.000000e+000,5.399834e+001,-5.875656e-005,0.000000e+000,2,6.817465e-001,0.000000e+000,,,,,,,,,,,,,,32,1,4.000000e+000,7.640839e-003,0.000000e+000,0,,0,
1524299233.171,,0.000000e+000,5.399707e+001,-5.895118e-005,0.000000e+000,2,6.830255e-001,0.000000e+000,,,,,,,,,,,,,,32,1,4.000000e+000,1.017761e-002,0.000000e+000,0,,0,
1524299245.591,,0.000000e+000,5.399452e+001,-5.913508e-005,0.000000e+000,2,6.817182e-001,0.000000e+000,,,,,,,,,,,,,,32,1,4.000000e+000,0.000000e+000,0.000000e+000,0,,0,
1524299258.021,,0.000000e+000,5.399261e+001,-5.931927e-005,0.000000e+000,2,6.850138e-001,0.000000e+000,,,,,,,,,,,,,,32,1,4.000000e+000,3.818512e-003,0.000000e+000,0,,0,
1524299270.661,,0.000000e+000,5.399261e+001,-5.940812e-005,0.000000e+000,2,6.830587e-001,0.000000e+000,,,,,,,,,,,,,,32,1,4.000000e+000,8.918762e-003,0.000000e+000,0,,0,
1524299283.301,,0.000000e+000,5.399834e+001,-5.961447e-005,0.000000e+000,2,6.844597e-001,0.000000e+000,,,,,,,,,,,,,,32,1,4.000000e+000,0.000000e+000,0.000000e+000,0,,0,
1524299295.821,,0.000000e+000,5.399643e+001,-5.973356e-005,0.000000e+000,2,6.825823e-001,0.000000e+000,,,,,,,,,,,,,,32,1,4.000000e+000,6.370544e-003,0.000000e+000,0,,0,
1524299308.741,,0.000000e+000,5.399643e+001,-5.986817e-005,0.000000e+000,2,6.841505e-001,0.000000e+000,,,,,,,,,,,,,,32,1,4.000000e+000,1.281738e-003,0.000000e+000,0,,0,
1524299321.321,,0.000000e+000,5.399961e+001,-6.001625e-005,0.000000e+000,2,6.830057e-001,0.000000e+000,,,,,,,,,,,,,,32,1,4.000000e+000,2.540588e-003,0.000000e+000,0,,0,
1524299333.971,,0.000000e+000,5.399451e+001,-6.015462e-005,0.000000e+000,2,6.840030e-001,0.000000e+000,,,,,,,,,,,,,,32,1,4.000000e+000,2.548218e-003,0.000000e+000,0,,0,
1524299346.641,,0.000000e+000,5.399898e+001,-6.030869e-005,0.000000e+000,2,6.839955e-001,0.000000e+000,,,,,,,,,,,,,,32,1,4.000000e+000,3.810883e-003,0.000000e+000,0,,0,
1524299358.991,,0.000000e+000,5.399643e+001,-6.041788e-005,0.000000e+000,2,6.845052e-001,0.000000e+000,,,,,,,,,,,,,,32,1,4.000000e+000,1.281738e-003,0.000000e+000,0,,0,
1524299371.511,,0.000000e+000,5.399579e+001,-6.065543e-005,0.000000e+000,2,6.854389e-001,0.000000e+000,,,,,,,,,,,,,,32,1,4.000000e+000,0.000000e+000,0.000000e+000,0,,0,
1524299383.761,,0.000000e+000,5.399834e+001,-6.064227e-005,0.000000e+000,2,6.850662e-001,0.000000e+000,,,,,,,,,,,,,,32,1,4.000000e+000,5.092621e-003,0.000000e+000,0,,0,
1524299396.181,,0.000000e+000,5.399898e+001,-6.085691e-005,0.000000e+000,2,6.858970e-001,0.000000e+000,,,,,,,,,,,,,,32,1,4.000000e+000,3.810883e-003,0.000000e+000,0,,0,
1524299408.511,,0.000000e+000,5.399579e+001,-6.089229e-005,0.000000e+000,2,6.843358e-001,0.000000e+000,,,,,,,,,,,,,,32,1,4.000000e+000,1.273727e-002,0.000000e+000,0,,0,
1524299420.881,,0.000000e+000,5.399580e+001,-6.106770e-005,0.000000e+000,2,6.864016e-001,0.000000e+000,,,,,,,,,,,,,,32,1,4.000000e+000,2.552032e-003,0.000000e+000,0,,0,
1524299433.311,,0.000000e+000,5.399834e+001,-6.102154e-005,0.000000e+000,2,6.843781e-001,0.000000e+000,,,,,,,,,,,,,,32,1,4.000000e+000,2.540588e-003,0.000000e+000,0,,0,
1524299446.051,,0.000000e+000,5.399580e+001,-6.115258e-005,0.000000e+000,2,6.866171e-001,0.000000e+000,,,,,,,,,,,,,,32,1,4.000000e+000,2.552032e-003,0.000000e+000,0,,0,
1524299458.351,,0.000000e+000,5.399770e+001,-6.127456e-005,0.000000e+000,2,6.851094e-001,0.000000e+000,,,,,,,,,,,,,,32,1,4.000000e+000,1.270294e-003,0.000000e+000,0,,0,
1524299471.011,,0.000000e+000,5.399453e+001,-6.139129e-005,0.000000e+000,2,6.864020e-001,0.000000e+000,,,,,,,,,,,,,,32,1,4.000000e+000,5.088806e-003,0.000000e+000,0,,0,
1524299483.581,,0.000000e+000,5.400216e+001,-6.145546e-005,0.000000e+000,2,6.855118e-001,0.000000e+000,,,,,,,,,,,,,,32,1,4.000000e+000,0.000000e+000,0.000000e+000,0,,0,
1524299496.531,,0.000000e+000,5.399706e+001,-6.151560e-005,0.000000e+000,2,6.865140e-001,0.000000e+000,,,,,,,,,,,,,,32,1,4.000000e+000,2.552032e-003,0.000000e+000,0,,0,
1524299508.581,,0.000000e+000,5.399961e+001,-6.164452e-005,0.000000e+000,2,6.846128e-001,0.000000e+000,,,,,,,,,,,,,,32,1,4.000000e+000,5.088806e-003,0.000000e+000,0,,0,
1524299521.281,,0.000000e+000,5.399707e+001,-6.175609e-005,0.000000e+000,2,6.882977e-001,0.000000e+000,,,,,,,,,,,,,,32,1,4.000000e+000,0.000000e+000,0.000000e+000,0,,0,
1524299533.661,,0.000000e+000,5.399834e+001,-6.185233e-005,0.000000e+000,2,6.851207e-001,0.000000e+000,,,,,,,,,,,,,,32,1,4.000000e+000,1.271820e-002,0.000000e+000,0,,0,
1524299546.671,,0.000000e+000,5.399961e+001,-6.189253e-005,0.000000e+000,2,6.865824e-001,0.000000e+000,,,,,,,,,,,,,,32,1,4.000000e+000,7.640839e-003,0.000000e+000,0,,0,
1524299558.901,,0.000000e+000,5.399579e+001,-6.204665e-005,0.000000e+000,2,6.860259e-001,0.000000e+000,,,,,,,,,,,,,,32,1,4.000000e+000,5.100250e-003,0.000000e+000,0,,0,
1524299571.701,,0.000000e+000,5.400024e+001,-6.213028e-005,0.000000e+000,2,6.868544e-001,0.000000e+000,,,,,,,,,,,,,,32,1,4.000000e+000,1.270294e-003,0.000000e+000,0,,0,
1524299584.451,,0.000000e+000,5.399961e+001,-6.221896e-005,0.000000e+000,2,6.875817e-001,0.000000e+000,,,,,,,,,,,,,,32,1,4.000000e+000,0.000000e+000,0.000000e+000,0,,0,
1524299597.121,,0.000000e+000,5.399898e+001,-6.228215e-005,0.000000e+000,2,6.873237e-001,0.000000e+000,,,,,,,,,,,,,,32,1,4.000000e+000,1.270294e-003,0.000000e+000,0,,0,
1524299609.991,,0.000000e+000,5.399516e+001,-6.240186e-005,0.000000e+000,2,6.880388e-001,0.000000e+000,,,,,,,,,,,,,,32,1,4.000000e+000,3.829956e-003,0.000000e+000,0,,0,
1524299622.591,,0.000000e+000,5.399197e+001,-6.238913e-005,0.000000e+000,2,6.867587e-001,0.000000e+000,,,,,,,,,,,,,,32,1,4.000000e+000,2.540588e-003,0.000000e+000,0,,0,
1524299635.401,,0.000000e+000,5.399134e+001,-6.252769e-005,0.000000e+000,2,6.872476e-001,0.000000e+000,,,,,,,,,,,,,,32,1,4.000000e+000,1.281738e-003,0.000000e+000,0,,0,
1524299647.991,,0.000000e+000,5.399707e+001,-6.251718e-005,0.000000e+000,2,6.868249e-001,0.000000e+000,,,,,,,,,,,,,,32,1,4.000000e+000,1.017761e-002,0.000000e+000,0,,0,
1524299660.791,,0.000000e+000,5.399834e+001,-6.267102e-005,0.000000e+000,2,6.880017e-001,0.000000e+000,,,,,,,,,,,,,,32,1,4.000000e+000,7.640839e-003,0.000000e+000,0,,0,
1524299673.651,,0.000000e+000,5.399706e+001,-6.265163e-005,0.000000e+000,2,6.867859e-001,0.000000e+000,,,,,,,,,,,,,,32,1,4.000000e+000,5.092621e-003,0.000000e+000,0,,0,
1524299686.341,,0.000000e+000,5.400280e+001,-6.271296e-005,0.000000e+000,2,6.894050e-001,0.000000e+000,,,,,,,,,,,,,,32,1,4.000000e+000,6.370544e-003,0.000000e+000,0,,0,
1524299698.841,,0.000000e+000,5.400661e+001,-6.278307e-005,0.000000e+000,2,6.869309e-001,0.000000e+000,,,,,,,,,,,,,,32,1,4.000000e+000,8.911133e-003,0.000000e+000,0,,0,
1524299711.851,,0.000000e+000,5.399706e+001,-6.281193e-005,0.000000e+000,2,6.881883e-001,0.000000e+000,,,,,,,,,,,,,,32,1,4.000000e+000,5.092621e-003,0.000000e+000,0,,0,
1524299723.871,,0.000000e+000,5.399325e+001,-6.296542e-005,0.000000e+000,2,6.863928e-001,0.000000e+000,,,,,,,,,,,,,,32,1,4.000000e+000,2.536774e-003,0.000000e+000,0,,0,
1524299736.671,,0.000000e+000,5.399516e+001,-6.306907e-005,0.000000e+000,2,6.885582e-001,0.000000e+000,,,,,,,,,,,,,,32,1,4.000000e+000,8.911133e-003,0.000000e+000,0,,0,
1524299748.741,,0.000000e+000,5.399706e+001,-6.307574e-005,0.000000e+000,2,6.860721e-001,0.000000e+000,,,,,,,,,,,,,,32,1,4.000000e+000,2.552032e-003,0.000000e+000,0,,0,
1524299761.561,,0.000000e+000,5.399770e+001,-6.317006e-005,0.000000e+000,2,6.886392e-001,0.000000e+000,,,,,,,,,,,,,,32,1,4.000000e+000,3.822327e-003,0.000000e+000,0,,0,
1524299773.841,,0.000000e+000,5.399324e+001,-6.323597e-005,0.000000e+000,2,6.865746e-001,0.000000e+000,,,,,,,,,,,,,,32,1,4.000000e+000,5.088806e-003,0.000000e+000,0,,0,
1524299786.621,,0.000000e+000,5.399706e+001,-6.330685e-005,0.000000e+000,2,6.889956e-001,0.000000e+000,,,,,,,,,,,,,,32,1,4.000000e+000,2.552032e-003,0.000000e+000,0,,0,
1524299799.221,,0.000000e+000,5.399580e+001,-6.340010e-005,0.000000e+000,2,6.875402e-001,0.000000e+000,,,,,,,,,,,,,,32,1,4.000000e+000,7.629395e-003,0.000000e+000,0,,0,
1524299811.461,,0.000000e+000,5.399834e+001,-6.341870e-005,0.000000e+000,2,6.895648e-001,0.000000e+000,,,,,,,,,,,,,,32,1,4.000000e+000,2.540588e-003,0.000000e+000,0,,0,
1524299824.071,,0.000000e+000,5.399261e+001,-6.351646e-005,0.000000e+000,2,6.874543e-001,0.000000e+000,,,,,,,,,,,,,,32,1,4.000000e+000,1.258850e-003,0.000000e+000,0,,0,
1524299836.332,,0.000000e+000,5.399515e+001,-6.350849e-005,0.000000e+000,2,6.885718e-001,0.000000e+000,,,,,,,,,,,,,,32,1,4.000000e+000,1.145935e-002,0.000000e+000,0,,0,
1524299849.642,,0.000000e+000,5.398878e+001,-6.357905e-005,0.000000e+000,2,6.873838e-001,0.000000e+000,,,,,,,,,,,,,,32,1,4.000000e+000,1.270294e-003,0.000000e+000,0,,0,
1524299861.452,,0.000000e+000,5.399070e+001,-6.360780e-005,0.000000e+000,2,6.883935e-001,0.000000e+000,,,,,,,,,,,,,,32,1,4.000000e+000,5.088806e-003,0.000000e+000,0,,0,
1524299874.782,,0.000000e+000,5.399388e+001,-6.376836e-005,0.000000e+000,2,6.882787e-001,0.000000e+000,,,,,,,,,,,,,,32,1,4.000000e+000,1.277924e-003,0.000000e+000,0,,0,
1524299887.602,,0.000000e+000,5.399961e+001,-6.370059e-005,0.000000e+000,2,6.889811e-001,0.000000e+000,,,,,,,,,,,,,,32,1,4.000000e+000,0.000000e+000,0.000000e+000,0,,0,
1524299900.572,,0.000000e+000,5.399961e+001,-6.382891e-005,0.000000e+000,2,6.898366e-001,0.000000e+000,,,,,,,,,,,,,,32,1,4.000000e+000,5.088806e-003,0.000000e+000,0,,0,
1524299912.712,,0.000000e+000,5.399580e+001,-6.376266e-005,0.000000e+000,2,6.884078e-001,0.000000e+000,,,,,,,,,,,,,,32,1,4.000000e+000,7.629395e-003,0.000000e+000,0,,0,
1524299925.392,,0.000000e+000,5.400407e+001,-6.381075e-005,0.000000e+000,2,6.894892e-001,0.000000e+000,,,,,,,,,,,,,,32,1,4.000000e+000,3.822327e-003,0.000000e+000,0,,0,
1524299937.762,,0.000000e+000,5.399516e+001,-6.394467e-005,0.000000e+000,2,6.880449e-001,0.000000e+000,,,,,,,,,,,,,,32,1,4.000000e+000,3.829956e-003,0.000000e+000,0,,0,
1524299950.802,,0.000000e+000,5.400089e+001,-6.397041e-005,0.000000e+000,2,6.901685e-001,0.000000e+000,,,,,,,,,,,,,,32,1,4.000000e+000,7.629395e-003,0.000000e+000,0,,0,
1524299963.492,,0.000000e+000,5.399961e+001,-6.403150e-005,0.000000e+000,2,6.889770e-001,0.000000e+000,,,,,,,,,,,,,,32,1,4.000000e+000,1.018143e-002,0.000000e+000,0,,0,
1524299976.382,,0.000000e+000,5.399516e+001,-6.408437e-005,0.000000e+000,2,6.895018e-001,0.000000e+000,,,,,,,,,,,,,,32,1,4.000000e+000,3.829956e-003,0.000000e+000,0,,0,
1524299989.252,,0.000000e+000,5.399706e+001,-6.412670e-005,0.000000e+000,2,6.891392e-001,0.000000e+000,,,,,,,,,,,,,,32,1,4.000000e+000,7.640839e-003,0.000000e+000,0,,0,
1524300002.052,,0.000000e+000,5.399515e+001,-6.415157e-005,0.000000e+000,2,6.886145e-001,0.000000e+000,,,,,,,,,,,,,,32,1,4.000000e+000,1.145935e-002,0.000000e+000,0,,0,
1524300014.362,,0.000000e+000,5.399325e+001,-6.423061e-005,0.000000e+000,2,6.900647e-001,0.000000e+000,,,,,,,,,,,,,,32,1,4.000000e+000,7.648468e-003,0.000000e+000,0,,0,
1524300026.952,,0.000000e+000,5.399643e+001,-6.427072e-005,0.000000e+000,2,6.892919e-001,0.000000e+000,,,,,,,,,,,,,,32,1,4.000000e+000,1.281738e-003,0.000000e+000,0,,0,
1524300039.642,,0.000000e+000,5.399961e+001,-6.433685e-005,0.000000e+000,2,6.902420e-001,0.000000e+000,,,,,,,,,,,,,,32,1,4.000000e+000,5.088806e-003,0.000000e+000,0,,0,
1524300052.192,,0.000000e+000,5.400216e+001,-6.434046e-005,0.000000e+000,2,6.883603e-001,0.000000e+000,,,,,,,,,,,,,,32,1,4.000000e+000,0.000000e+000,0.000000e+000,0,,0,
1524300065.032,,0.000000e+000,5.399834e+001,-6.440905e-005,0.000000e+000,2,6.903545e-001,0.000000e+000,,,,,,,,,,,,,,32,1,4.000000e+000,2.540588e-003,0.000000e+000,0,,0,
1524300077.162,,0.000000e+000,5.399579e+001,-6.446926e-005,0.000000e+000,2,6.891826e-001,0.000000e+000,,,,,,,,,,,,,,32,1,4.000000e+000,0.000000e+000,0.000000e+000,0,,0,
1524300089.892,,0.000000e+000,5.400024e+001,-6.450376e-005,0.000000e+000,2,6.906193e-001,0.000000e+000,,,,,,,,,,,,,,32,1,4.000000e+000,1.270294e-003,0.000000e+000,0,,0,
1524300102.462,,0.000000e+000,5.400025e+001,-6.451847e-005,0.000000e+000,2,6.891021e-001,0.000000e+000,,,,,,,,,,,,,,32,1,4.000000e+000,3.818512e-003,0.000000e+000,0,,0,
1524300115.292,,0.000000e+000,5.399961e+001,-6.464023e-005,0.000000e+000,2,6.910629e-001,0.000000e+000,,,,,,,,,,,,,,32,1,4.000000e+000,5.088806e-003,0.000000e+000,0,,0,
1524300127.692,,0.000000e+000,5.399197e+001,-6.469424e-005,0.000000e+000,2,6.899325e-001,0.000000e+000,,,,,,,,,,,,,,32,1,4.000000e+000,5.096436e-003,0.000000e+000,0,,0,
1524300140.172,,0.000000e+000,5.399388e+001,-6.468323e-005,0.000000e+000,2,6.908146e-001,0.000000e+000,,,,,,,,,,,,,,32,1,4.000000e+000,1.145935e-002,0.000000e+000,0,,0,
1524300153.132,,0.000000e+000,5.400089e+001,-6.476884e-005,0.000000e+000,2,6.898854e-001,0.000000e+000,,,,,,,,,,,,,,32,1,4.000000e+000,5.088806e-003,0.000000e+000,0,,0,
1524300165.742,,0.000000e+000,5.399706e+001,-6.476232e-005,0.000000e+000,2,6.908538e-001,0.000000e+000,,,,,,,,,,,,,,32,1,4.000000e+000,2.552032e-003,0.000000e+000,0,,0,
1524300178.632,,0.000000e+000,5.399706e+001,-6.487502e-005,0.000000e+000,2,6.918804e-001,0.000000e+000,,,,,,,,,,,,,,32,1,4.000000e+000,5.092621e-003,0.000000e+000,0,,0,
1524300191.322,,0.000000e+000,5.399325e+001,-6.485934e-005,0.000000e+000,2,6.913362e-001,0.000000e+000,,,,,,,,,,,,,,32,1,4.000000e+000,2.536774e-003,0.000000e+000,0,,0,
1524300203.732,,0.000000e+000,5.399643e+001,-6.495517e-005,0.000000e+000,2,6.927119e-001,0.000000e+000,,,,,,,,,,,,,,32,1,4.000000e+000,8.899689e-003,0.000000e+000,0,,0,
1524300216.332,,0.000000e+000,5.399834e+001,-6.491810e-005,0.000000e+000,2,6.910014e-001,0.000000e+000,,,,,,,,,,,,,,32,1,4.000000e+000,5.092621e-003,0.000000e+000,0,,0,
1524300229.022,,0.000000e+000,5.399643e+001,-6.495736e-005,0.000000e+000,2,6.920685e-001,0.000000e+000,,,,,,,,,,,,,,32,1,4.000000e+000,3.822327e-003,0.000000e+000,0,,0,
1524300241.592,,0.000000e+000,5.399579e+001,-6.502761e-005,0.000000e+000,2,6.904113e-001,0.000000e+000,,,,,,,,,,,,,,32,1,4.000000e+000,5.100250e-003,0.000000e+000,0,,0,
1524300254.222,,0.000000e+000,5.399834e+001,-6.506481e-005,0.000000e+000,2,6.928798e-001,0.000000e+000,,,,,,,,,,,,,,32,1,4.000000e+000,5.092621e-003,0.000000e+000,0,,0,
1524300266.502,,0.000000e+000,5.400280e+001,-6.511852e-005,0.000000e+000,2,6.909757e-001,0.000000e+000,,,,,,,,,,,,,,32,1,4.000000e+000,6.370544e-003,0.000000e+000,0,,0,
1524300279.312,,0.000000e+000,5.399580e+001,-6.513197e-005,0.000000e+000,2,6.923538e-001,0.000000e+000,,,,,,,,,,,,,,32,1,4.000000e+000,2.552032e-003,0.000000e+000,0,,0,
1524300291.472,,0.000000e+000,5.399834e+001,-6.518195e-005,0.000000e+000,2,6.909767e-001,0.000000e+000,,,,,,,,,,,,,,32,1,4.000000e+000,2.540588e-003,0.000000e+000,0,,0,
1524300304.062,,0.000000e+000,5.399006e+001,-6.522315e-005,0.000000e+000,2,6.926843e-001,0.000000e+000,,,,,,,,,,,,,,32,1,4.000000e+000,1.277924e-003,0.000000e+000,0,,0,
1524300316.652,,0.000000e+000,5.399706e+001,-6.523140e-005,0.000000e+000,2,6.914023e-001,0.000000e+000,,,,,,,,,,,,,,32,1,4.000000e+000,2.552032e-003,0.000000e+000,0,,0,
1524300329.532,,0.000000e+000,5.399580e+001,-6.528990e-005,0.000000e+000,2,6.925461e-001,0.000000e+000,,,,,,,,,,,,,,32,1,4.000000e+000,7.629395e-003,0.000000e+000,0,,0,
1524300341.692,,0.000000e+000,5.399770e+001,-6.528488e-005,0.000000e+000,2,6.909568e-001,0.000000e+000,,,,,,,,,,,,,,32,1,4.000000e+000,1.270294e-003,0.000000e+000,0,,0,
1524300354.162,,0.000000e+000,5.399706e+001,-6.536389e-005,0.000000e+000,2,6.929020e-001,0.000000e+000,,,,,,,,,,,,,,32,1,4.000000e+000,7.640839e-003,0.000000e+000,0,,0,
1524300366.672,,0.000000e+000,5.400025e+001,-6.543993e-005,0.000000e+000,2,6.919343e-001,0.000000e+000,,,,,,,,,,,,,,32,1,4.000000e+000,6.359100e-003,0.000000e+000,0,,0,
1524300379.072,,0.000000e+000,5.400025e+001,-6.540459e-005,0.000000e+000,2,6.927058e-001,0.000000e+000,,,,,,,,,,,,,,32,1,4.000000e+000,6.359100e-003,0.000000e+000,0,,0,
1524300391.622,,0.000000e+000,5.400152e+001,-6.547255e-005,0.000000e+000,2,6.922016e-001,0.000000e+000,,,,,,,,,,,,,,32,1,4.000000e+000,3.818512e-003,0.000000e+000,0,,0,
1524300404.352,,0.000000e+000,5.399898e+001,-6.552806e-005,0.000000e+000,2,6.929477e-001,0.000000e+000,,,,,,,,,,,,,,32,1,4.000000e+000,1.270294e-003,0.000000e+000,0,,0,
1524300417.392,,0.000000e+000,5.399898e+001,-6.558497e-005,0.000000e+000,2,6.942565e-001,0.000000e+000,,,,,,,,,,,,,,32,1,4.000000e+000,1.270294e-003,0.000000e+000,0,,0,
1524300429.892,,0.000000e+000,5.399770e+001,-6.558000e-005,0.000000e+000,2,6.927797e-001,0.000000e+000,,,,,,,,,,,,,,32,1,4.000000e+000,3.822327e-003,0.000000e+000,0,,0,
1524300442.692,,0.000000e+000,5.400216e+001,-6.557799e-005,0.000000e+000,2,6.934873e-001,0.000000e+000,,,,,,,,,,,,,,32,1,4.000000e+000,2.548218e-003,0.000000e+000,0,,0,
1524300455.242,,0.000000e+000,5.400279e+001,-6.562191e-005,0.000000e+000,2,6.924948e-001,0.000000e+000,,,,,,,,,,,,,,32,1,4.000000e+000,1.270294e-003,0.000000e+000,0,,0,
1524300468.092,,0.000000e+000,5.399516e+001,-6.571845e-005,0.000000e+000,2,6.938252e-001,0.000000e+000,,,,,,,,,,,,,,32,1,4.000000e+000,1.270294e-003,0.000000e+000,0,,0,
1524300480.722,,0.000000e+000,5.399516e+001,-6.571609e-005,0.000000e+000,2,6.925524e-001,0.000000e+000,,,,,,,,,,,,,,32,1,4.000000e+000,3.829956e-003,0.000000e+000,0,,0,
1524300493.112,,0.000000e+000,5.399516e+001,-6.570888e-005,0.000000e+000,2,6.937402e-001,0.000000e+000,,,,,,,,,,,,,,32,1,4.000000e+000,1.270294e-003,0.000000e+000,0,,0,
1524300505.502,,0.000000e+000,5.399389e+001,-6.577937e-005,0.000000e+000,2,6.933891e-001,0.000000e+000,,,,,,,,,,,,,,32,1,4.000000e+000,3.807068e-003,0.000000e+000,0,,0,
1524300518.402,,0.000000e+000,5.399070e+001,-6.574835e-005,0.000000e+000,2,6.939406e-001,0.000000e+000,,,,,,,,,,,,,,32,1,4.000000e+000,7.637024e-003,0.000000e+000,0,,0,
1524300531.072,,0.000000e+000,5.399898e+001,-6.582249e-005,0.000000e+000,2,6.933594e-001,0.000000e+000,,,,,,,,,,,,,,32,1,4.000000e+000,1.270294e-003,0.000000e+000,0,,0,
1524300543.353,,0.000000e+000,5.399770e+001,-6.591279e-005,0.000000e+000,2,6.945409e-001,0.000000e+000,,,,,,,,,,,,,,32,1,4.000000e+000,1.270294e-003,0.000000e+000,0,,0,
1524300555.683,,0.000000e+000,5.400152e+001,-6.585299e-005,0.000000e+000,2,6.927928e-001,0.000000e+000,,,,,,,,,,,,,,32,1,4.000000e+000,6.359100e-003,0.000000e+000,0,,0,
1524300568.163,,0.000000e+000,5.399898e+001,-6.586069e-005,0.000000e+000,2,6.943164e-001,0.000000e+000,,,,,,,,,,,,,,32,1,4.000000e+000,1.270294e-003,0.000000e+000,0,,0,
1524300580.473,,0.000000e+000,5.399898e+001,-6.597642e-005,0.000000e+000,2,6.928166e-001,0.000000e+000,,,,,,,,,,,,,,32,1,4.000000e+000,1.270294e-003,0.000000e+000,0,,0,
1524300592.953,,0.000000e+000,5.400152e+001,-6.597647e-005,0.000000e+000,2,6.939945e-001,0.000000e+000,,,,,,,,,,,,,,32,1,4.000000e+000,3.818512e-003,0.000000e+000,0,,0,
1524300605.033,,0.000000e+000,5.400407e+001,-6.603968e-005,0.000000e+000,2,6.929883e-001,0.000000e+000,,,,,,,,,,,,,,32,1,4.000000e+000,1.399994e-002,0.000000e+000,0,,0,
1524300617.813,,0.000000e+000,5.398688e+001,-6.606145e-005,0.000000e+000,2,6.948953e-001,0.000000e+000,,,,,,,,,,,,,,32,1,4.000000e+000,7.640839e-003,0.000000e+000,0,,0,
1524300630.213,,0.000000e+000,5.400024e+001,-6.603508e-005,0.000000e+000,2,6.935860e-001,0.000000e+000,,,,,,,,,,,,,,32,1,4.000000e+000,8.911133e-003,0.000000e+000,0,,0,
1524300643.153,,0.000000e+000,5.399706e+001,-6.607893e-005,0.000000e+000,2,6.950140e-001,0.000000e+000,,,,,,,,,,,,,,32,1,4.000000e+000,2.552032e-003,0.000000e+000,0,,0,
1524300655.263,,0.000000e+000,5.399451e+001,-6.611642e-005,0.000000e+000,2,6.933435e-001,0.000000e+000,,,,,,,,,,,,,,32,1,4.000000e+000,2.548218e-003,0.000000e+000,0,,0,
1524300668.023,,0.000000e+000,5.400152e+001,-6.614372e-005,0.000000e+000,2,6.948352e-001,0.000000e+000,,,,,,,,,,,,,,32,1,4.000000e+000,1.277924e-003,0.000000e+000,0,,0,
1524300680.103,,0.000000e+000,5.399898e+001,-6.621327e-005,0.000000e+000,2,6.926912e-001,0.000000e+000,,,,,,,,,,,,,,32,1,4.000000e+000,3.810883e-003,0.000000e+000,0,,0,
1524300692.783,,0.000000e+000,5.399516e+001,-6.622586e-005,0.000000e+000,2,6.959687e-001,0.000000e+000,,,,,,,,,,,,,,32,1,4.000000e+000,1.400757e-002,0.000000e+000,0,,0,
1524300704.913,,0.000000e+000,5.399516e+001,-6.627333e-005,0.000000e+000,2,6.933652e-001,0.000000e+000,,,,,,,,,,,,,,32,1,4.000000e+000,1.270294e-003,0.000000e+000,0,,0,
1524300717.603,,0.000000e+000,5.399834e+001,-6.627615e-005,0.000000e+000,2,6.950299e-001,0.000000e+000,,,,,,,,,,,,,,32,1,4.000000e+000,2.540588e-003,0.000000e+000,0,,0,
1524300730.103,,0.000000e+000,5.399961e+001,-6.625967e-005,0.000000e+000,2,6.933249e-001,0.000000e+000,,,,,,,,,,,,,,32,1,4.000000e+000,5.088806e-003,0.000000e+000,0,,0,
1524300743.023,,0.000000e+000,5.399516e+001,-6.634031e-005,0.000000e+000,2,6.953396e-001,0.000000e+000,,,,,,,,,,,,,,32,1,4.000000e+000,3.829956e-003,0.000000e+000,0,,0,
1524300755.623,,0.000000e+000,5.399643e+001,-6.631471e-005,0.000000e+000,2,6.934695e-001,0.000000e+000,,,,,,,,,,,,,,32,1,4.000000e+000,6.370544e-003,0.000000e+000,0,,0,
1524300768.013,,0.000000e+000,5.399770e+001,-6.638451e-005,0.000000e+000,2,6.948944e-001,0.000000e+000,,,,,,,,,,,,,,32,1,4.000000e+000,1.270294e-003,0.000000e+000,0,,0,
1524300780.573,,0.000000e+000,5.400216e+001,-6.644943e-005,0.000000e+000,2,6.949194e-001,0.000000e+000,,,,,,,,,,,,,,32,1,4.000000e+000,0.000000e+000,0.000000e+000,0,,0,
1524300793.263,,0.000000e+000,5.399961e+001,-6.646129e-005,0.000000e+000,2,6.950960e-001,0.000000e+000,,,,,,,,,,,,,,32,1,4.000000e+000,5.088806e-003,0.000000e+000,0,,0,
1524300805.413,,0.000000e+000,5.399706e+001,-6.645890e-005,0.000000e+000,2,6.943197e-001,0.000000e+000,,,,,,,,,,,,,,32,1,4.000000e+000,7.640839e-003,0.000000e+000,0,,0,
1524300818.083,,0.000000e+000,5.399961e+001,-6.652506e-005,0.000000e+000,2,6.956794e-001,0.000000e+000,,,,,,,,,,,,,,32,1,4.000000e+000,0.000000e+000,0.000000e+000,0,,0,
1524300830.293,,0.000000e+000,5.400280e+001,-6.654537e-005,0.000000e+000,2,6.953322e-001,0.000000e+000,,,,,,,,,,,,,,32,1,4.000000e+000,6.370544e-003,0.000000e+000,0,,0,
1524300842.923,,0.000000e+000,5.399388e+001,-6.658610e-005,0.000000e+000,2,6.959996e-001,0.000000e+000,,,,,,,,,,,,,,32,1,4.000000e+000,8.918762e-003,0.000000e+000,0,,0,
1524300855.483,,0.000000e+000,5.399898e+001,-6.661852e-005,0.000000e+000,2,6.951611e-001,0.000000e+000,,,,,,,,,,,,,,32,1,4.000000e+000,1.270294e-003,0.000000e+000,0,,0,
1524300868.353,,0.000000e+000,5.399388e+001,-6.663428e-005,0.000000e+000,2,6.962338e-001,0.000000e+000,,,,,,,,,,,,,,32,1,4.000000e+000,1.145935e-002,0.000000e+000,0,,0,
1524300880.523,,0.000000e+000,5.399834e+001,-6.665471e-005,0.000000e+000,2,6.955724e-001,0.000000e+000,,,,,,,,,,,,,,32,1,4.000000e+000,0.000000e+000,0.000000e+000,0,,0,
1524300893.783,,0.000000e+000,5.400279e+001,-6.666398e-005,0.000000e+000,2,6.964027e-001,0.000000e+000,,,,,,,,,,,,,,32,1,4.000000e+000,3.818512e-003,0.000000e+000,0,,0,
1524300906.223,,0.000000e+000,5.400025e+001,-6.673329e-005,0.000000e+000,2,6.956031e-001,0.000000e+000,,,,,,,,,,,,,,32,1,4.000000e+000,6.359100e-003,0.000000e+000,0,,0,
1524300918.593,,0.000000e+000,5.400279e+001,-6.673212e-005,0.000000e+000,2,6.964706e-001,0.000000e+000,,,,,,,,,,,,,,32,1,4.000000e+000,1.270294e-003,0.000000e+000,0,,0,
1524300931.073,,0.000000e+000,5.399261e+001,-6.677408e-005,0.000000e+000,2,6.954353e-001,0.000000e+000,,,,,,,,,,,,,,32,1,4.000000e+000,6.366730e-003,0.000000e+000,0,,0,
1524300943.473,,0.000000e+000,5.399325e+001,-6.681397e-005,0.000000e+000,2,6.969522e-001,0.000000e+000,,,,,,,,,,,,,,32,1,4.000000e+000,7.648468e-003,0.000000e+000,0,,0,
1524300955.963,,0.000000e+000,5.399834e+001,-6.679313e-005,0.000000e+000,2,6.956826e-001,0.000000e+000,,,,,,,,,,,,,,32,1,4.000000e+000,2.540588e-003,0.000000e+000,0,,0,
1524300968.463,,0.000000e+000,5.399898e+001,-6.681906e-005,0.000000e+000,2,6.972767e-001,0.000000e+000,,,,,,,,,,,,,,32,1,4.000000e+000,1.270294e-003,0.000000e+000,0,,0,
1524300981.143,,0.000000e+000,5.399834e+001,-6.690180e-005,0.000000e+000,2,6.962451e-001,0.000000e+000,,,,,,,,,,,,,,32,1,4.000000e+000,5.092621e-003,0.000000e+000,0,,0,
1524300993.393,,0.000000e+000,5.399324e+001,-6.690512e-005,0.000000e+000,2,6.974528e-001,0.000000e+000,,,,,,,,,,,,,,32,1,4.000000e+000,5.088806e-003,0.000000e+000,0,,0,
1524301005.753,,0.000000e+000,5.399834e+001,-6.696480e-005,0.000000e+000,2,6.961290e-001,0.000000e+000,,,,,,,,,,,,,,32,1,4.000000e+000,0.000000e+000,0.000000e+000,0,,0,
1524301018.143,,0.000000e+000,5.399961e+001,-6.690877e-005,0.000000e+000,2,6.966598e-001,0.000000e+000,,,,,,,,,,,,,,32,1,4.000000e+000,0.000000e+000,0.000000e+000,0,,0,
1524301030.603,,0.000000e+000,5.399834e+001,-6.692293e-005,0.000000e+000,2,6.959953e-001,0.000000e+000,,,,,,,,,,,,,,32,1,4.000000e+000,0.000000e+000,0.000000e+000,0,,0,
1524301043.363,,0.000000e+000,5.399580e+001,-6.703064e-005,0.000000e+000,2,6.975772e-001,0.000000e+000,,,,,,,,,,,,,,32,1,4.000000e+000,2.552032e-003,0.000000e+000,0,,0,
1524301055.933,,0.000000e+000,5.399451e+001,-6.701440e-005,0.000000e+000,2,6.956016e-001,0.000000e+000,,,,,,,,,,,,,,32,1,4.000000e+000,2.548218e-003,0.000000e+000,0,,0,
1524301068.363,,0.000000e+000,5.399579e+001,-6.707438e-005,0.000000e+000,2,6.972750e-001,0.000000e+000,,,,,,,,,,,,,,32,1,4.000000e+000,0.000000e+000,0.000000e+000,0,,0,
1524301080.833,,0.000000e+000,5.399706e+001,-6.707716e-005,0.000000e+000,2,6.968582e-001,0.000000e+000,,,,,,,,,,,,,,32,1,4.000000e+000,2.552032e-003,0.000000e+000,0,,0,
1524301093.593,,0.000000e+000,5.399706e+001,-6.714308e-005,0.000000e+000,2,6.973793e-001,0.000000e+000,,,,,,,,,,,,,,32,1,4.000000e+000,2.552032e-003,0.000000e+000,0,,0,
1524301106.333,,0.000000e+000,5.399706e+001,-6.706597e-005,0.000000e+000,2,6.962038e-001,0.000000e+000,,,,,,,,,,,,,,32,1,4.000000e+000,7.640839e-003,0.000000e+000,0,,0,
1524301119.193,,0.000000e+000,5.399961e+001,-6.711917e-005,0.000000e+000,2,6.978226e-001,0.000000e+000,,,,,,,,,,,,,,32,1,4.000000e+000,2.540588e-003,0.000000e+000,0,,0,
1524301132.053,,0.000000e+000,5.399770e+001,-6.713782e-005,0.000000e+000,2,6.971201e-001,0.000000e+000,,,,,,,,,,,,,,32,1,4.000000e+000,6.362915e-003,0.000000e+000,0,,0,
1524301144.813,,0.000000e+000,5.399643e+001,-6.716204e-005,0.000000e+000,2,6.972250e-001,0.000000e+000,,,,,,,,,,,,,,32,1,4.000000e+000,3.822327e-003,0.000000e+000,0,,0,
1524301157.163,,0.000000e+000,5.399388e+001,-6.722129e-005,0.000000e+000,2,6.983973e-001,0.000000e+000,,,,,,,,,,,,,,32,1,4.000000e+000,8.918762e-003,0.000000e+000,0,,0,
1524301169.613,,0.000000e+000,5.399961e+001,-6.721986e-005,0.000000e+000,2,6.973255e-001,0.000000e+000,,,,,,,,,,,,,,32,1,4.000000e+000,0.000000e+000,0.000000e+000,0,,0,
1524301182.443,,0.000000e+000,5.399770e+001,-6.728840e-005,0.000000e+000,2,6.988436e-001,0.000000e+000,,,,,,,,,,,,,,32,1,4.000000e+000,1.270294e-003,0.000000e+000,0,,0,
1524301194.983,,0.000000e+000,5.399197e+001,-6.725306e-005,0.000000e+000,2,6.972992e-001,0.000000e+000,,,,,,,,,,,,,,32,1,4.000000e+000,1.527023e-002,0.000000e+000,0,,0,
1524301207.873,,0.000000e+000,5.400024e+001,-6.730176e-005,0.000000e+000,2,6.985559e-001,0.000000e+000,,,,,,,,,,,,,,32,1,4.000000e+000,1.270294e-003,0.000000e+000,0,,0,
1524301220.503,,0.000000e+000,5.400024e+001,-6.734851e-005,0.000000e+000,2,6.976592e-001,0.000000e+000,,,,,,,,,,,,,,32,1,4.000000e+000,1.270294e-003,0.000000e+000,0,,0,
1524301233.123,,0.000000e+000,5.399834e+001,-6.734036e-005,0.000000e+000,2,6.980064e-001,0.000000e+000,,,,,,,,,,,,,,32,1,4.000000e+000,2.540588e-003,0.000000e+000,0,,0,
1524301245.793,,0.000000e+000,5.399961e+001,-6.738042e-005,0.000000e+000,2,6.979141e-001,0.000000e+000,,,,,,,,,,,,,,32,1,4.000000e+000,5.088806e-003,0.000000e+000,0,,0,
1524301258.144,,0.000000e+000,5.399451e+001,-6.740300e-005,0.000000e+000,2,6.992168e-001,0.000000e+000,,,,,,,,,,,,,,32,1,4.000000e+000,2.548218e-003,0.000000e+000,0,,0,
1524301270.914,,0.000000e+000,5.399324e+001,-6.747526e-005,0.000000e+000,2,6.994964e-001,0.000000e+000,,,,,,,,,,,,,,32,1,4.000000e+000,0.000000e+000,0.000000e+000,0,,0,
1524301283.834,,0.000000e+000,5.399770e+001,-6.748205e-005,0.000000e+000,2,6.975653e-001,0.000000e+000,,,,,,,,,,,,,,32,1,4.000000e+000,1.270294e-003,0.000000e+000,0,,0,
1524301296.794,,0.000000e+000,5.400152e+001,-6.747896e-005,0.000000e+000,2,6.991256e-001,0.000000e+000,,,,,,,,,,,,,,32,1,4.000000e+000,6.359100e-003,0.000000e+000,0,,0,
1524301308.954,,0.000000e+000,5.399897e+001,-6.744755e-005,0.000000e+000,2,6.980398e-001,0.000000e+000,,,,,,,,,,,,,,32,1,4.000000e+000,8.911133e-003,0.000000e+000,0,,0,
1524301321.624,,0.000000e+000,5.399706e+001,-6.750008e-005,0.000000e+000,2,6.982676e-001,0.000000e+000,,,,,,,,,,,,,,32,1,4.000000e+000,2.552032e-003,0.000000e+000,0,,0,
1524301334.664,,0.000000e+000,5.400025e+001,-6.750135e-005,0.000000e+000,2,6.970659e-001,0.000000e+000,,,,,,,,,,,,,,32,1,4.000000e+000,1.146317e-002,0.000000e+000,0,,0,
1524301347.234,,0.000000e+000,5.399898e+001,-6.760372e-005,0.000000e+000,2,6.983544e-001,0.000000e+000,,,,,,,,,,,,,,32,1,4.000000e+000,3.810883e-003,0.000000e+000,0,,0,
1524301360.064,,0.000000e+000,5.399324e+001,-6.763001e-005,0.000000e+000,2,6.992550e-001,0.000000e+000,,,,,,,,,,,,,,32,1,4.000000e+000,0.000000e+000,0.000000e+000,0,,0,
1524301372.744,,0.000000e+000,5.399070e+001,-6.763451e-005,0.000000e+000,2,6.991026e-001,0.000000e+000,,,,,,,,,,,,,,32,1,4.000000e+000,5.088806e-003,0.000000e+000,0,,0,
1524301385.174,,0.000000e+000,5.399197e+001,-6.764549e-005,0.000000e+000,2,6.994417e-001,0.000000e+000,,,,,,,,,,,,,,32,1,4.000000e+000,7.637024e-003,0.000000e+000,0,,0,
1524301397.964,,0.000000e+000,5.400024e+001,-6.761080e-005,0.000000e+000,2,6.988722e-001,0.000000e+000,,,,,,,,,,,,,,32,1,4.000000e+000,8.911133e-003,0.000000e+000,0,,0,
1524301410.604,,0.000000e+000,5.399579e+001,-6.767467e-005,0.000000e+000,2,6.996223e-001,0.000000e+000,,,,,,,,,,,,,,32,1,4.000000e+000,0.000000e+000,0.000000e+000,0,,0,
1524301423.104,,0.000000e+000,5.399197e+001,-6.758863e-005,0.000000e+000,2,6.984918e-001,0.000000e+000,,,,,,,,,,,,,,32,1,4.000000e+000,7.637024e-003,0.000000e+000,0,,0,
1524301435.704,,0.000000e+000,5.399007e+001,-6.777258e-005,0.000000e+000,2,6.995525e-001,0.000000e+000,,,,,,,,,,,,,,32,1,4.000000e+000,3.829956e-003,0.000000e+000,0,,0,
1524301447.924,,0.000000e+000,5.399643e+001,-6.766065e-005,0.000000e+000,2,6.986678e-001,0.000000e+000,,,,,,,,,,,,,,32,1,4.000000e+000,8.899689e-003,0.000000e+000,0,,0,
1524301460.404,,0.000000e+000,5.399643e+001,-6.780526e-005,0.000000e+000,2,6.995766e-001,0.000000e+000,,,,,,,,,,,,,,32,1,4.000000e+000,8.899689e-003,0.000000e+000,0,,0,
1524301473.084,,0.000000e+000,5.399770e+001,-6.777553e-005,0.000000e+000,2,6.999503e-001,0.000000e+000,,,,,,,,,,,,,,32,1,4.000000e+000,1.144791e-002,0.000000e+000,0,,0,
1524301485.944,,0.000000e+000,5.399961e+001,-6.787471e-005,0.000000e+000,2,7.006135e-001,0.000000e+000,,,,,,,,,,,,,,32,1,4.000000e+000,7.640839e-003,0.000000e+000,0,,0,
1524301498.864,,0.000000e+000,5.399770e+001,-6.779953e-005,0.000000e+000,2,6.998452e-001,0.000000e+000,,,,,,,,,,,,,,32,1,4.000000e+000,3.822327e-003,0.000000e+000,0,,0,
1524301511.474,,0.000000e+000,5.399770e+001,-6.782432e-005,0.000000e+000,2,7.004994e-001,0.000000e+000,,,,,,,,,,,,,,32,1,4.000000e+000,3.822327e-003,0.000000e+000,0,,0,
1524301524.054,,0.000000e+000,5.399389e+001,-6.779747e-005,0.000000e+000,2,6.988868e-001,0.000000e+000,,,,,,,,,,,,,,32,1,4.000000e+000,3.807068e-003,0.000000e+000,0,,0,
1524301536.704,,0.000000e+000,5.400152e+001,-6.781566e-005,0.000000e+000,2,7.000022e-001,0.000000e+000,,,,,,,,,,,,,,32,1,4.000000e+000,6.359100e-003,0.000000e+000,0,,0,
1524301548.954,,0.000000e+000,5.399706e+001,-6.787448e-005,0.000000e+000,2,6.983597e-001,0.000000e+000,,,,,,,,,,,,,,32,1,4.000000e+000,5.092621e-003,0.000000e+000,0,,0,
1524301561.524,,0.000000e+000,5.399580e+001,-6.786874e-005,0.000000e+000,2,7.002029e-001,0.000000e+000,,,,,,,,,,,,,,32,1,4.000000e+000,2.552032e-003,0.000000e+000,0,,0,
1524301573.804,,0.000000e+000,5.399451e+001,-6.792133e-005,0.000000e+000,2,6.988863e-001,0.000000e+000,,,,,,,,,,,,,,32,1,4.000000e+000,2.548218e-003,0.000000e+000,0,,0,
1524301586.624,,0.000000e+000,5.400024e+001,-6.790688e-005,0.000000e+000,2,7.006809e-001,0.000000e+000,,,,,,,,,,,,,,32,1,4.000000e+000,1.270294e-003,0.000000e+000,0,,0,
1524301598.764,,0.000000e+000,5.400216e+001,-6.795204e-005,0.000000e+000,2,6.991704e-001,0.000000e+000,,,,,,,,,,,,,,32,1,4.000000e+000,1.018143e-002,0.000000e+000,0,,0,
1524301611.454,,0.000000e+000,5.399070e+001,-6.800091e-005,0.000000e+000,2,7.011061e-001,0.000000e+000,,,,,,,,,,,,,,32,1,4.000000e+000,0.000000e+000,0.000000e+000,0,,0,
1524301623.644,,0.000000e+000,5.399898e+001,-6.803042e-005,0.000000e+000,2,6.992729e-001,0.000000e+000,,,,,,,,,,,,,,32,1,4.000000e+000,1.270294e-003,0.000000e+000,0,,0,
1524301636.224,,0.000000e+000,5.400025e+001,-6.805497e-005,0.000000e+000,2,7.006753e-001,0.000000e+000,,,,,,,,,,,,,,32,1,4.000000e+000,1.653671e-002,0.000000e+000,0,,0,