File: Experimental Raw Data/TC04-12-01K Acquisition/TC04-12-01K_VRMac_57K_6000s.dc.dat
[Header]
TITLE,MPMS DC Measurement
BYAPP,MPMS Measurement,2.1,Summary
FILEOPENTIME, 1524318854.648000 4/21/2018, 7:54:14 AM

INFO, APPNAME, MPMS MultiVu Application, Revision 1.61,  Build 082

INFO, NAME, TC04-12-01K
INFO, WEIGHT, 1.000
INFO, AREA, 1.000
INFO, LENGTH, 1.000
INFO, SHAPE, 0
INFO, COMMENT,
INFO, SEQUENCE FILE: VRMac_57K_6000s_VRMde_55K.seq


INFO, BACKGROUND DATA FILE:, None


STARTUPAXIS,X,4,LINEAR,AUTO,0.000000,0.000000
STARTUPAXIS,Y1,5,LINEAR,AUTO,0.000000,0.000000


STARTUPGROUP,Longitudinal
FIELDGROUP,Longitudinal,1,2,3,4,5,6,7,8,9,15,16,17,18,27,28
FIELDGROUP,Transverse,1,2,3,4,10,11,12,13,14,19,20,21,22,27,28

PLOT_APPEARANCE,ALL,HORZ_GRID_ON,VERT_GRID_ON,MARKERS_AND_LINES

[Data]
Time,Comment,Field (Oe),Temperature (K),Long Moment (emu),Long Scan Std Dev,Long Algorithm,Long Reg Fit,Long Percent Error (%),Trans Moment (emu),Trans Scan Std Dev,Trans Algorithm,Trans Reg Fit,Trans Percent Error (%),Long Moment [w/o ABS] (emu),Long Scan Std Dev [w/o ABS],Long Reg Fit [w/o ABS],Long Percent Error [w/o ABS] (%),Trans Moment [w/o ABS] (emu),Trans Scan Std Dev [w/o ABS],Trans Reg Fit [w/o ABS],Trans Percent Error [w/o ABS] (%),Points per Scan,Scans per Measurement,Scan Length (cm),Delta Temp (K),Rot Position (deg),Error,EC Comp. Running,Using ABS,
1524318854.648,,0.000000e+000,5.708239e+001,-5.097474e-005,0.000000e+000,2,6.571032e-001,0.000000e+000,,,,,,,,,,,,,,32,1,4.000000e+000,1.545715e-002,0.000000e+000,0,,0,
1524318879.798,,0.000000e+000,5.706342e+001,-5.465803e-005,0.000000e+000,2,6.596894e-001,0.000000e+000,,,,,,,,,,,,,,32,1,4.000000e+000,1.403809e-002,0.000000e+000,0,,0,
1524318904.498,,0.000000e+000,5.704726e+001,-5.640091e-005,0.000000e+000,2,6.603321e-001,0.000000e+000,,,,,,,,,,,,,,32,1,4.000000e+000,1.411438e-003,0.000000e+000,0,,0,
1524318929.328,,0.000000e+000,5.702972e+001,-5.763659e-005,0.000000e+000,2,6.609325e-001,0.000000e+000,,,,,,,,,,,,,,32,1,4.000000e+000,2.799988e-003,0.000000e+000,0,,0,
1524318954.328,,0.000000e+000,5.702762e+001,-5.856957e-005,0.000000e+000,2,6.619851e-001,0.000000e+000,,,,,,,,,,,,,,32,1,4.000000e+000,1.399994e-003,0.000000e+000,0,,0,
1524318979.528,,0.000000e+000,5.701639e+001,-5.937151e-005,0.000000e+000,2,6.623537e-001,0.000000e+000,,,,,,,,,,,,,,32,1,4.000000e+000,1.399994e-003,0.000000e+000,0,,0,
1524319004.978,,0.000000e+000,5.701218e+001,-6.000203e-005,0.000000e+000,2,6.639512e-001,0.000000e+000,,,,,,,,,,,,,,32,1,4.000000e+000,1.263046e-002,0.000000e+000,0,,0,
1524319029.648,,0.000000e+000,5.700938e+001,-6.056258e-005,0.000000e+000,2,6.643314e-001,0.000000e+000,,,,,,,,,,,,,,32,1,4.000000e+000,4.199982e-003,0.000000e+000,0,,0,
1524319054.988,,0.000000e+000,5.700727e+001,-6.105527e-005,0.000000e+000,2,6.652135e-001,0.000000e+000,,,,,,,,,,,,,,32,1,4.000000e+000,5.607605e-003,0.000000e+000,0,,0,
1524319080.638,,0.000000e+000,5.699606e+001,-6.148007e-005,0.000000e+000,2,6.654652e-001,0.000000e+000,,,,,,,,,,,,,,32,1,4.000000e+000,2.807617e-003,0.000000e+000,0,,0,
1524319104.988,,0.000000e+000,5.700167e+001,-6.180326e-005,0.000000e+000,2,6.654866e-001,0.000000e+000,,,,,,,,,,,,,,32,1,4.000000e+000,0.000000e+000,0.000000e+000,0,,0,
1524319129.859,,0.000000e+000,5.700027e+001,-6.211041e-005,0.000000e+000,2,6.654180e-001,0.000000e+000,,,,,,,,,,,,,,32,1,4.000000e+000,2.811432e-003,0.000000e+000,0,,0,
1524319154.579,,0.000000e+000,5.700237e+001,-6.237852e-005,0.000000e+000,2,6.663803e-001,0.000000e+000,,,,,,,,,,,,,,32,1,4.000000e+000,1.388550e-003,0.000000e+000,0,,0,
1524319180.039,,0.000000e+000,5.699886e+001,-6.266850e-005,0.000000e+000,2,6.666669e-001,0.000000e+000,,,,,,,,,,,,,,32,1,4.000000e+000,2.523804e-002,0.000000e+000,0,,0,
1524319205.339,,0.000000e+000,5.699466e+001,-6.295036e-005,0.000000e+000,2,6.665720e-001,0.000000e+000,,,,,,,,,,,,,,32,1,4.000000e+000,5.599976e-003,0.000000e+000,0,,0,
1524319231.269,,0.000000e+000,5.699886e+001,-6.325531e-005,0.000000e+000,2,6.662809e-001,0.000000e+000,,,,,,,,,,,,,,32,1,4.000000e+000,2.799988e-003,0.000000e+000,0,,0,
1524319255.999,,0.000000e+000,5.700097e+001,-6.348334e-005,0.000000e+000,2,6.684126e-001,0.000000e+000,,,,,,,,,,,,,,32,1,4.000000e+000,7.011414e-003,0.000000e+000,0,,0,
1524319281.909,,0.000000e+000,5.699746e+001,-6.371921e-005,0.000000e+000,2,6.680214e-001,0.000000e+000,,,,,,,,,,,,,,32,1,4.000000e+000,5.607605e-003,0.000000e+000,0,,0,
1524319307.159,,0.000000e+000,5.699606e+001,-6.398559e-005,0.000000e+000,2,6.693624e-001,0.000000e+000,,,,,,,,,,,,,,32,1,4.000000e+000,2.807617e-003,0.000000e+000,0,,0,
1524319332.389,,0.000000e+000,5.700027e+001,-6.406404e-005,0.000000e+000,2,6.688459e-001,0.000000e+000,,,,,,,,,,,,,,32,1,4.000000e+000,1.962662e-002,0.000000e+000,0,,0,
1524319357.979,,0.000000e+000,5.699957e+001,-6.428194e-005,0.000000e+000,2,6.689323e-001,0.000000e+000,,,,,,,,,,,,,,32,1,4.000000e+000,4.211426e-003,0.000000e+000,0,,0,
1524319383.449,,0.000000e+000,5.699535e+001,-6.449368e-005,0.000000e+000,2,6.696607e-001,0.000000e+000,,,,,,,,,,,,,,32,1,4.000000e+000,1.407623e-003,0.000000e+000,0,,0,
1524319408.929,,0.000000e+000,5.699956e+001,-6.463610e-005,0.000000e+000,2,6.689049e-001,0.000000e+000,,,,,,,,,,,,,,32,1,4.000000e+000,1.399994e-003,0.000000e+000,0,,0,
1524319433.779,,0.000000e+000,5.699326e+001,-6.483160e-005,0.000000e+000,2,6.704471e-001,0.000000e+000,,,,,,,,,,,,,,32,1,4.000000e+000,5.607605e-003,0.000000e+000,0,,0,
1524319459.069,,0.000000e+000,5.699325e+001,-6.498371e-005,0.000000e+000,2,6.699486e-001,0.000000e+000,,,,,,,,,,,,,,32,1,4.000000e+000,8.419037e-003,0.000000e+000,0,,0,
1524319484.649,,0.000000e+000,5.700377e+001,-6.507744e-005,0.000000e+000,2,6.707861e-001,0.000000e+000,,,,,,,,,,,,,,32,1,4.000000e+000,1.261902e-002,0.000000e+000,0,,0,
1524319510.229,,0.000000e+000,5.699816e+001,-6.525649e-005,0.000000e+000,2,6.701346e-001,0.000000e+000,,,,,,,,,,,,,,32,1,4.000000e+000,1.399994e-003,0.000000e+000,0,,0,
1524319535.739,,0.000000e+000,5.699255e+001,-6.543416e-005,0.000000e+000,2,6.698830e-001,0.000000e+000,,,,,,,,,,,,,,32,1,4.000000e+000,1.392365e-003,0.000000e+000,0,,0,
1524319561.169,,0.000000e+000,5.700307e+001,-6.549602e-005,0.000000e+000,2,6.698762e-001,0.000000e+000,,,,,,,,,,,,,,32,1,4.000000e+000,5.611420e-003,0.000000e+000,0,,0,
1524319586.439,,0.000000e+000,5.699817e+001,-6.567063e-005,0.000000e+000,2,6.708067e-001,0.000000e+000,,,,,,,,,,,,,,32,1,4.000000e+000,1.261139e-002,0.000000e+000,0,,0,
1524319611.669,,0.000000e+000,5.699815e+001,-6.586770e-005,0.000000e+000,2,6.707751e-001,0.000000e+000,,,,,,,,,,,,,,32,1,4.000000e+000,9.807587e-003,0.000000e+000,0,,0,
1524319636.689,,0.000000e+000,5.699746e+001,-6.596884e-005,0.000000e+000,2,6.722102e-001,0.000000e+000,,,,,,,,,,,,,,32,1,4.000000e+000,0.000000e+000,0.000000e+000,0,,0,
1524319662.129,,0.000000e+000,5.699886e+001,-6.606320e-005,0.000000e+000,2,6.722807e-001,0.000000e+000,,,,,,,,,,,,,,32,1,4.000000e+000,8.407593e-003,0.000000e+000,0,,0,
1524319687.359,,0.000000e+000,5.699395e+001,-6.614708e-005,0.000000e+000,2,6.709253e-001,0.000000e+000,,,,,,,,,,,,,,32,1,4.000000e+000,9.819031e-003,0.000000e+000,0,,0,
1524319712.499,,0.000000e+000,5.700026e+001,-6.629907e-005,0.000000e+000,2,6.717691e-001,0.000000e+000,,,,,,,,,,,,,,32,1,4.000000e+000,1.121902e-002,0.000000e+000,0,,0,
1524319738.319,,0.000000e+000,5.699396e+001,-6.638330e-005,0.000000e+000,2,6.731266e-001,0.000000e+000,,,,,,,,,,,,,,32,1,4.000000e+000,4.199982e-003,0.000000e+000,0,,0,
1524319762.679,,0.000000e+000,5.700377e+001,-6.651704e-005,0.000000e+000,2,6.720223e-001,0.000000e+000,,,,,,,,,,,,,,32,1,4.000000e+000,4.199982e-003,0.000000e+000,0,,0,
1524319787.539,,0.000000e+000,5.700307e+001,-6.661582e-005,0.000000e+000,2,6.725423e-001,0.000000e+000,,,,,,,,,,,,,,32,1,4.000000e+000,1.401901e-002,0.000000e+000,0,,0,
1524319813.089,,0.000000e+000,5.699676e+001,-6.662297e-005,0.000000e+000,2,6.723884e-001,0.000000e+000,,,,,,,,,,,,,,32,1,4.000000e+000,4.207611e-003,0.000000e+000,0,,0,
1524319838.270,,0.000000e+000,5.699886e+001,-6.672349e-005,0.000000e+000,2,6.720962e-001,0.000000e+000,,,,,,,,,,,,,,32,1,4.000000e+000,5.611420e-003,0.000000e+000,0,,0,
1524319863.230,,0.000000e+000,5.699535e+001,-6.682618e-005,0.000000e+000,2,6.724183e-001,0.000000e+000,,,,,,,,,,,,,,32,1,4.000000e+000,4.207611e-003,0.000000e+000,0,,0,
1524319888.720,,0.000000e+000,5.699395e+001,-6.701083e-005,0.000000e+000,2,6.738642e-001,0.000000e+000,,,,,,,,,,,,,,32,1,4.000000e+000,1.399994e-003,0.000000e+000,0,,0,
1524319914.070,,0.000000e+000,5.699956e+001,-6.709123e-005,0.000000e+000,2,6.745410e-001,0.000000e+000,,,,,,,,,,,,,,32,1,4.000000e+000,9.819031e-003,0.000000e+000,0,,0,
1524319939.230,,0.000000e+000,5.699957e+001,-6.719656e-005,0.000000e+000,2,6.742904e-001,0.000000e+000,,,,,,,,,,,,,,32,1,4.000000e+000,4.211426e-003,0.000000e+000,0,,0,
1524319965.140,,0.000000e+000,5.700447e+001,-6.728338e-005,0.000000e+000,2,6.738039e-001,0.000000e+000,,,,,,,,,,,,,,32,1,4.000000e+000,1.121902e-002,0.000000e+000,0,,0,
1524319990.280,,0.000000e+000,5.700027e+001,-6.734530e-005,0.000000e+000,2,6.730720e-001,0.000000e+000,,,,,,,,,,,,,,32,1,4.000000e+000,2.811432e-003,0.000000e+000,0,,0,
1524320015.970,,0.000000e+000,5.699817e+001,-6.748045e-005,0.000000e+000,2,6.765952e-001,0.000000e+000,,,,,,,,,,,,,,32,1,4.000000e+000,1.261139e-002,0.000000e+000,0,,0,
1524320041.220,,0.000000e+000,5.699676e+001,-6.748498e-005,0.000000e+000,2,6.751963e-001,0.000000e+000,,,,,,,,,,,,,,32,1,4.000000e+000,7.007599e-003,0.000000e+000,0,,0,
1524320066.930,,0.000000e+000,5.700517e+001,-6.760095e-005,0.000000e+000,2,6.758882e-001,0.000000e+000,,,,,,,,,,,,,,32,1,4.000000e+000,4.219055e-003,0.000000e+000,0,,0,
1524320091.610,,0.000000e+000,5.699606e+001,-6.769371e-005,0.000000e+000,2,6.754280e-001,0.000000e+000,,,,,,,,,,,,,,32,1,4.000000e+000,0.000000e+000,0.000000e+000,0,,0,
1524320116.770,,0.000000e+000,5.699676e+001,-6.773102e-005,0.000000e+000,2,6.761925e-001,0.000000e+000,,,,,,,,,,,,,,32,1,4.000000e+000,1.399994e-003,0.000000e+000,0,,0,
1524320142.620,,0.000000e+000,5.699466e+001,-6.782646e-005,0.000000e+000,2,6.751162e-001,0.000000e+000,,,,,,,,,,,,,,32,1,4.000000e+000,5.599976e-003,0.000000e+000,0,,0,
1524320167.670,,0.000000e+000,5.699956e+001,-6.791372e-005,0.000000e+000,2,6.750785e-001,0.000000e+000,,,,,,,,,,,,,,32,1,4.000000e+000,1.399994e-003,0.000000e+000,0,,0,
1524320192.750,,0.000000e+000,5.700237e+001,-6.803458e-005,0.000000e+000,2,6.761540e-001,0.000000e+000,,,,,,,,,,,,,,32,1,4.000000e+000,7.011414e-003,0.000000e+000,0,,0,
1524320217.860,,0.000000e+000,5.699816e+001,-6.809726e-005,0.000000e+000,2,6.768445e-001,0.000000e+000,,,,,,,,,,,,,,32,1,4.000000e+000,1.399994e-003,0.000000e+000,0,,0,
1524320243.060,,0.000000e+000,5.699816e+001,-6.815703e-005,0.000000e+000,2,6.766119e-001,0.000000e+000,,,,,,,,,,,,,,32,1,4.000000e+000,1.541901e-002,0.000000e+000,0,,0,
1524320268.070,,0.000000e+000,5.699115e+001,-6.818429e-005,0.000000e+000,2,6.782346e-001,0.000000e+000,,,,,,,,,,,,,,32,1,4.000000e+000,9.819031e-003,0.000000e+000,0,,0,
1524320293.100,,0.000000e+000,5.700097e+001,-6.817129e-005,0.000000e+000,2,6.768900e-001,0.000000e+000,,,,,,,,,,,,,,32,1,4.000000e+000,1.411438e-003,0.000000e+000,0,,0,
1524320318.360,,0.000000e+000,5.699677e+001,-6.829006e-005,0.000000e+000,2,6.767960e-001,0.000000e+000,,,,,,,,,,,,,,32,1,4.000000e+000,9.811401e-003,0.000000e+000,0,,0,
1524320343.130,,0.000000e+000,5.700027e+001,-6.838551e-005,0.000000e+000,2,6.771805e-001,0.000000e+000,,,,,,,,,,,,,,32,1,4.000000e+000,2.811432e-003,0.000000e+000,0,,0,
1524320368.220,,0.000000e+000,5.699185e+001,-6.841792e-005,0.000000e+000,2,6.777179e-001,0.000000e+000,,,,,,,,,,,,,,32,1,4.000000e+000,2.799988e-003,0.000000e+000,0,,0,
1524320393.560,,0.000000e+000,5.699255e+001,-6.847474e-005,0.000000e+000,2,6.767375e-001,0.000000e+000,,,,,,,,,,,,,,32,1,4.000000e+000,4.199982e-003,0.000000e+000,0,,0,
1524320418.340,,0.000000e+000,5.700446e+001,-6.858350e-005,0.000000e+000,2,6.777645e-001,0.000000e+000,,,,,,,,,,,,,,32,1,4.000000e+000,2.811432e-003,0.000000e+000,0,,0,
1524320443.610,,0.000000e+000,5.700027e+001,-6.863438e-005,0.000000e+000,2,6.788294e-001,0.000000e+000,,,,,,,,,,,,,,32,1,4.000000e+000,2.811432e-003,0.000000e+000,0,,0,
1524320468.730,,0.000000e+000,5.700377e+001,-6.868195e-005,0.000000e+000,2,6.787024e-001,0.000000e+000,,,,,,,,,,,,,,32,1,4.000000e+000,1.541901e-002,0.000000e+000,0,,0,
1524320493.220,,0.000000e+000,5.699045e+001,-6.878829e-005,0.000000e+000,2,6.797859e-001,0.000000e+000,,,,,,,,,,,,,,32,1,4.000000e+000,0.000000e+000,0.000000e+000,0,,0,
1524320518.430,,0.000000e+000,5.699536e+001,-6.882669e-005,0.000000e+000,2,6.792669e-001,0.000000e+000,,,,,,,,,,,,,,32,1,4.000000e+000,6.999969e-003,0.000000e+000,0,,0,
1524320543.161,,0.000000e+000,5.699535e+001,-6.887437e-005,0.000000e+000,2,6.798245e-001,0.000000e+000,,,,,,,,,,,,,,32,1,4.000000e+000,9.807587e-003,0.000000e+000,0,,0,
1524320568.261,,0.000000e+000,5.699396e+001,-6.890814e-005,0.000000e+000,2,6.791378e-001,0.000000e+000,,,,,,,,,,,,,,32,1,4.000000e+000,4.199982e-003,0.000000e+000,0,,0,
1524320593.271,,0.000000e+000,5.699186e+001,-6.896224e-005,0.000000e+000,2,6.798728e-001,0.000000e+000,,,,,,,,,,,,,,32,1,4.000000e+000,8.407593e-003,0.000000e+000,0,,0,
1524320618.241,,0.000000e+000,5.699395e+001,-6.905277e-005,0.000000e+000,2,6.792631e-001,0.000000e+000,,,,,,,,,,,,,,32,1,4.000000e+000,9.819031e-003,0.000000e+000,0,,0,
1524320643.151,,0.000000e+000,5.700097e+001,-6.908281e-005,0.000000e+000,2,6.799808e-001,0.000000e+000,,,,,,,,,,,,,,32,1,4.000000e+000,7.011414e-003,0.000000e+000,0,,0,
1524320667.991,,0.000000e+000,5.699325e+001,-6.919893e-005,0.000000e+000,2,6.807357e-001,0.000000e+000,,,,,,,,,,,,,,32,1,4.000000e+000,0.000000e+000,0.000000e+000,0,,0,
1524320693.741,,0.000000e+000,5.700027e+001,-6.920184e-005,0.000000e+000,2,6.809586e-001,0.000000e+000,,,,,,,,,,,,,,32,1,4.000000e+000,2.811432e-003,0.000000e+000,0,,0,
1524320719.231,,0.000000e+000,5.700026e+001,-6.926172e-005,0.000000e+000,2,6.812968e-001,0.000000e+000,,,,,,,,,,,,,,32,1,4.000000e+000,5.599976e-003,0.000000e+000,0,,0,
1524320744.271,,0.000000e+000,5.699326e+001,-6.929551e-005,0.000000e+000,2,6.799798e-001,0.000000e+000,,,,,,,,,,,,,,32,1,4.000000e+000,2.792358e-003,0.000000e+000,0,,0,
1524320769.061,,0.000000e+000,5.700097e+001,-6.934600e-005,0.000000e+000,2,6.807070e-001,0.000000e+000,,,,,,,,,,,,,,32,1,4.000000e+000,9.811401e-003,0.000000e+000,0,,0,
1524320794.481,,0.000000e+000,5.699886e+001,-6.937365e-005,0.000000e+000,2,6.805340e-001,0.000000e+000,,,,,,,,,,,,,,32,1,4.000000e+000,2.799988e-003,0.000000e+000,0,,0,
1524320819.331,,0.000000e+000,5.699886e+001,-6.944707e-005,0.000000e+000,2,6.811987e-001,0.000000e+000,,,,,,,,,,,,,,32,1,4.000000e+000,2.242661e-002,0.000000e+000,0,,0,
1524320844.321,,0.000000e+000,5.699956e+001,-6.953874e-005,0.000000e+000,2,6.812592e-001,0.000000e+000,,,,,,,,,,,,,,32,1,4.000000e+000,1.399994e-003,0.000000e+000,0,,0,
1524320869.301,,0.000000e+000,5.699746e+001,-6.955767e-005,0.000000e+000,2,6.819722e-001,0.000000e+000,,,,,,,,,,,,,,32,1,4.000000e+000,0.000000e+000,0.000000e+000,0,,0,
1524320894.601,,0.000000e+000,5.700307e+001,-6.959883e-005,0.000000e+000,2,6.817612e-001,0.000000e+000,,,,,,,,,,,,,,32,1,4.000000e+000,5.611420e-003,0.000000e+000,0,,0,
1524320919.831,,0.000000e+000,5.700307e+001,-6.968071e-005,0.000000e+000,2,6.823793e-001,0.000000e+000,,,,,,,,,,,,,,32,1,4.000000e+000,1.121902e-002,0.000000e+000,0,,0,
1524320945.061,,0.000000e+000,5.699746e+001,-6.968748e-005,0.000000e+000,2,6.829051e-001,0.000000e+000,,,,,,,,,,,,,,32,1,4.000000e+000,8.419037e-003,0.000000e+000,0,,0,
1524320970.541,,0.000000e+000,5.700237e+001,-6.977801e-005,0.000000e+000,2,6.831062e-001,0.000000e+000,,,,,,,,,,,,,,32,1,4.000000e+000,1.388550e-003,0.000000e+000,0,,0,
1524320995.811,,0.000000e+000,5.700517e+001,-6.983490e-005,0.000000e+000,2,6.833084e-001,0.000000e+000,,,,,,,,,,,,,,32,1,4.000000e+000,1.823044e-002,0.000000e+000,0,,0,
1524321020.981,,0.000000e+000,5.699816e+001,-6.990050e-005,0.000000e+000,2,6.820725e-001,0.000000e+000,,,,,,,,,,,,,,32,1,4.000000e+000,1.399994e-003,0.000000e+000,0,,0,
1524321046.851,,0.000000e+000,5.700237e+001,-6.988257e-005,0.000000e+000,2,6.831878e-001,0.000000e+000,,,,,,,,,,,,,,32,1,4.000000e+000,7.011414e-003,0.000000e+000,0,,0,
1524321071.911,,0.000000e+000,5.699886e+001,-6.992352e-005,0.000000e+000,2,6.839130e-001,0.000000e+000,,,,,,,,,,,,,,32,1,4.000000e+000,5.611420e-003,0.000000e+000,0,,0,
1524321096.861,,0.000000e+000,5.700377e+001,-6.998583e-005,0.000000e+000,2,6.832975e-001,0.000000e+000,,,,,,,,,,,,,,32,1,4.000000e+000,1.411438e-003,0.000000e+000,0,,0,
1524321122.551,,0.000000e+000,5.699816e+001,-7.007652e-005,0.000000e+000,2,6.830400e-001,0.000000e+000,,,,,,,,,,,,,,32,1,4.000000e+000,1.399994e-003,0.000000e+000,0,,0,
1524321148.031,,0.000000e+000,5.699746e+001,-7.009514e-005,0.000000e+000,2,6.816654e-001,0.000000e+000,,,,,,,,,,,,,,32,1,4.000000e+000,5.607605e-003,0.000000e+000,0,,0,
1524321172.821,,0.000000e+000,5.699606e+001,-7.004103e-005,0.000000e+000,2,6.829825e-001,0.000000e+000,,,,,,,,,,,,,,32,1,4.000000e+000,8.399963e-003,0.000000e+000,0,,0,
1524321198.211,,0.000000e+000,5.700166e+001,-7.016207e-005,0.000000e+000,2,6.830531e-001,0.000000e+000,,,,,,,,,,,,,,32,1,4.000000e+000,8.411407e-003,0.000000e+000,0,,0,
1524321223.391,,0.000000e+000,5.699535e+001,-7.024406e-005,0.000000e+000,2,6.839728e-001,0.000000e+000,,,,,,,,,,,,,,32,1,4.000000e+000,1.407623e-003,0.000000e+000,0,,0,
1524321249.651,,0.000000e+000,5.699396e+001,-7.029004e-005,0.000000e+000,2,6.846732e-001,0.000000e+000,,,,,,,,,,,,,,32,1,4.000000e+000,7.007599e-003,0.000000e+000,0,,0,
1524321274.542,,0.000000e+000,5.699746e+001,-7.037839e-005,0.000000e+000,2,6.848614e-001,0.000000e+000,,,,,,,,,,,,,,32,1,4.000000e+000,8.419037e-003,0.000000e+000,0,,0,
1524321300.052,,0.000000e+000,5.699815e+001,-7.030566e-005,0.000000e+000,2,6.843410e-001,0.000000e+000,,,,,,,,,,,,,,32,1,4.000000e+000,9.807587e-003,0.000000e+000,0,,0,
1524321325.252,,0.000000e+000,5.700167e+001,-7.039559e-005,0.000000e+000,2,6.849768e-001,0.000000e+000,,,,,,,,,,,,,,32,1,4.000000e+000,0.000000e+000,0.000000e+000,0,,0,
1524321351.022,,0.000000e+000,5.699886e+001,-7.035798e-005,0.000000e+000,2,6.842269e-001,0.000000e+000,,,,,,,,,,,,,,32,1,4.000000e+000,0.000000e+000,0.000000e+000,0,,0,
1524321376.142,,0.000000e+000,5.699746e+001,-7.048371e-005,0.000000e+000,2,6.840337e-001,0.000000e+000,,,,,,,,,,,,,,32,1,4.000000e+000,5.607605e-003,0.000000e+000,0,,0,
1524321402.332,,0.000000e+000,5.700097e+001,-7.046481e-005,0.000000e+000,2,6.842114e-001,0.000000e+000,,,,,,,,,,,,,,32,1,4.000000e+000,7.011414e-003,0.000000e+000,0,,0,
1524321427.632,,0.000000e+000,5.700096e+001,-7.056797e-005,0.000000e+000,2,6.848030e-001,0.000000e+000,,,,,,,,,,,,,,32,1,4.000000e+000,4.199982e-003,0.000000e+000,0,,0,
1524321453.062,,0.000000e+000,5.699746e+001,-7.056523e-005,0.000000e+000,2,6.846238e-001,0.000000e+000,,,,,,,,,,,,,,32,1,4.000000e+000,1.683044e-002,0.000000e+000,0,,0,
1524321477.802,,0.000000e+000,5.700096e+001,-7.060899e-005,0.000000e+000,2,6.851310e-001,0.000000e+000,,,,,,,,,,,,,,32,1,4.000000e+000,4.199982e-003,0.000000e+000,0,,0,
1524321502.522,,0.000000e+000,5.699535e+001,-7.065209e-005,0.000000e+000,2,6.848619e-001,0.000000e+000,,,,,,,,,,,,,,32,1,4.000000e+000,1.407623e-003,0.000000e+000,0,,0,
1524321527.312,,0.000000e+000,5.700237e+001,-7.062593e-005,0.000000e+000,2,6.850626e-001,0.000000e+000,,,,,,,,,,,,,,32,1,4.000000e+000,7.011414e-003,0.000000e+000,0,,0,
1524321552.262,,0.000000e+000,5.699816e+001,-7.070680e-005,0.000000e+000,2,6.856455e-001,0.000000e+000,,,,,,,,,,,,,,32,1,4.000000e+000,4.199982e-003,0.000000e+000,0,,0,
1524321578.022,,0.000000e+000,5.699816e+001,-7.078543e-005,0.000000e+000,2,6.851009e-001,0.000000e+000,,,,,,,,,,,,,,32,1,4.000000e+000,7.019043e-003,0.000000e+000,0,,0,
1524321602.742,,0.000000e+000,5.699535e+001,-7.081272e-005,0.000000e+000,2,6.851243e-001,0.000000e+000,,,,,,,,,,,,,,32,1,4.000000e+000,1.407623e-003,0.000000e+000,0,,0,
1524321628.682,,0.000000e+000,5.700097e+001,-7.083427e-005,0.000000e+000,2,6.856875e-001,0.000000e+000,,,,,,,,,,,,,,32,1,4.000000e+000,7.011414e-003,0.000000e+000,0,,0,
1524321653.682,,0.000000e+000,5.700237e+001,-7.081025e-005,0.000000e+000,2,6.856322e-001,0.000000e+000,,,,,,,,,,,,,,32,1,4.000000e+000,7.011414e-003,0.000000e+000,0,,0,
1524321678.792,,0.000000e+000,5.699255e+001,-7.087419e-005,0.000000e+000,2,6.854514e-001,0.000000e+000,,,,,,,,,,,,,,32,1,4.000000e+000,1.392365e-003,0.000000e+000,0,,0,
1524321704.842,,0.000000e+000,5.700447e+001,-7.089943e-005,0.000000e+000,2,6.847665e-001,0.000000e+000,,,,,,,,,,,,,,32,1,4.000000e+000,0.000000e+000,0.000000e+000,0,,0,
1524321729.192,,0.000000e+000,5.700097e+001,-7.096463e-005,0.000000e+000,2,6.860935e-001,0.000000e+000,,,,,,,,,,,,,,32,1,4.000000e+000,1.411438e-003,0.000000e+000,0,,0,
1524321754.502,,0.000000e+000,5.699326e+001,-7.099037e-005,0.000000e+000,2,6.863828e-001,0.000000e+000,,,,,,,,,,,,,,32,1,4.000000e+000,2.792358e-003,0.000000e+000,0,,0,
1524321779.952,,0.000000e+000,5.699606e+001,-7.108264e-005,0.000000e+000,2,6.868349e-001,0.000000e+000,,,,,,,,,,,,,,32,1,4.000000e+000,5.607605e-003,0.000000e+000,0,,0,
1524321804.902,,0.000000e+000,5.700027e+001,-7.114714e-005,0.000000e+000,2,6.875712e-001,0.000000e+000,,,,,,,,,,,,,,32,1,4.000000e+000,1.681900e-002,0.000000e+000,0,,0,
1524321829.652,,0.000000e+000,5.700027e+001,-7.115834e-005,0.000000e+000,2,6.871522e-001,0.000000e+000,,,,,,,,,,,,,,32,1,4.000000e+000,8.411407e-003,0.000000e+000,0,,0,
1524321854.482,,0.000000e+000,5.699816e+001,-7.116719e-005,0.000000e+000,2,6.868490e-001,0.000000e+000,,,,,,,,,,,,,,32,1,4.000000e+000,7.019043e-003,0.000000e+000,0,,0,
1524321880.222,,0.000000e+000,5.699886e+001,-7.121987e-005,0.000000e+000,2,6.880699e-001,0.000000e+000,,,,,,,,,,,,,,32,1,4.000000e+000,5.611420e-003,0.000000e+000,0,,0,
1524321905.532,,0.000000e+000,5.699815e+001,-7.129937e-005,0.000000e+000,2,6.888071e-001,0.000000e+000,,,,,,,,,,,,,,32,1,4.000000e+000,9.807587e-003,0.000000e+000,0,,0,
1524321930.602,,0.000000e+000,5.699606e+001,-7.127598e-005,0.000000e+000,2,6.886657e-001,0.000000e+000,,,,,,,,,,,,,,32,1,4.000000e+000,5.607605e-003,0.000000e+000,0,,0,
1524321955.632,,0.000000e+000,5.700166e+001,-7.130508e-005,0.000000e+000,2,6.881444e-001,0.000000e+000,,,,,,,,,,,,,,32,1,4.000000e+000,2.799988e-003,0.000000e+000,0,,0,
1524321980.833,,0.000000e+000,5.699466e+001,-7.136441e-005,0.000000e+000,2,6.878996e-001,0.000000e+000,,,,,,,,,,,,,,32,1,4.000000e+000,5.599976e-003,0.000000e+000,0,,0,
1524322005.703,,0.000000e+000,5.699606e+001,-7.134772e-005,0.000000e+000,2,6.881853e-001,0.000000e+000,,,,,,,,,,,,,,32,1,4.000000e+000,2.807617e-003,0.000000e+000,0,,0,
1524322031.503,,0.000000e+000,5.699746e+001,-7.140017e-005,0.000000e+000,2,6.876814e-001,0.000000e+000,,,,,,,,,,,,,,32,1,4.000000e+000,5.607605e-003,0.000000e+000,0,,0,
1524322056.623,,0.000000e+000,5.699676e+001,-7.149454e-005,0.000000e+000,2,6.888121e-001,0.000000e+000,,,,,,,,,,,,,,32,1,4.000000e+000,4.207611e-003,0.000000e+000,0,,0,
1524322081.743,,0.000000e+000,5.699956e+001,-7.144039e-005,0.000000e+000,2,6.891450e-001,0.000000e+000,,,,,,,,,,,,,,32,1,4.000000e+000,1.399994e-003,0.000000e+000,0,,0,
1524322106.843,,0.000000e+000,5.699676e+001,-7.150444e-005,0.000000e+000,2,6.897378e-001,0.000000e+000,,,,,,,,,,,,,,32,1,4.000000e+000,4.207611e-003,0.000000e+000,0,,0,
1524322131.903,,0.000000e+000,5.699535e+001,-7.154622e-005,0.000000e+000,2,6.894168e-001,0.000000e+000,,,,,,,,,,,,,,32,1,4.000000e+000,9.807587e-003,0.000000e+000,0,,0,
1524322157.083,,0.000000e+000,5.699746e+001,-7.156640e-005,0.000000e+000,2,6.889318e-001,0.000000e+000,,,,,,,,,,,,,,32,1,4.000000e+000,5.607605e-003,0.000000e+000,0,,0,
1524322181.703,,0.000000e+000,5.699606e+001,-7.157817e-005,0.000000e+000,2,6.879334e-001,0.000000e+000,,,,,,,,,,,,,,32,1,4.000000e+000,1.121902e-002,0.000000e+000,0,,0,
1524322207.073,,0.000000e+000,5.699746e+001,-7.167590e-005,0.000000e+000,2,6.890199e-001,0.000000e+000,,,,,,,,,,,,,,32,1,4.000000e+000,1.119995e-002,0.000000e+000,0,,0,
1524322232.123,,0.000000e+000,5.699815e+001,-7.173065e-005,0.000000e+000,2,6.898061e-001,0.000000e+000,,,,,,,,,,,,,,32,1,4.000000e+000,9.807587e-003,0.000000e+000,0,,0,
1524322256.963,,0.000000e+000,5.699395e+001,-7.171752e-005,0.000000e+000,2,6.897295e-001,0.000000e+000,,,,,,,,,,,,,,32,1,4.000000e+000,9.819031e-003,0.000000e+000,0,,0,
1524322281.753,,0.000000e+000,5.699956e+001,-7.170846e-005,0.000000e+000,2,6.885995e-001,0.000000e+000,,,,,,,,,,,,,,32,1,4.000000e+000,6.999969e-003,0.000000e+000,0,,0,
1524322306.853,,0.000000e+000,5.699746e+001,-7.182844e-005,0.000000e+000,2,6.904497e-001,0.000000e+000,,,,,,,,,,,,,,32,1,4.000000e+000,8.419037e-003,0.000000e+000,0,,0,
1524322331.853,,0.000000e+000,5.699746e+001,-7.184713e-005,0.000000e+000,2,6.904870e-001,0.000000e+000,,,,,,,,,,,,,,32,1,4.000000e+000,5.607605e-003,0.000000e+000,0,,0,
1524322357.033,,0.000000e+000,5.699466e+001,-7.184844e-005,0.000000e+000,2,6.905358e-001,0.000000e+000,,,,,,,,,,,,,,32,1,4.000000e+000,8.407593e-003,0.000000e+000,0,,0,
1524322382.903,,0.000000e+000,5.700307e+001,-7.178221e-005,0.000000e+000,2,6.909998e-001,0.000000e+000,,,,,,,,,,,,,,32,1,4.000000e+000,8.419037e-003,0.000000e+000,0,,0,
1524322407.943,,0.000000e+000,5.699535e+001,-7.186957e-005,0.000000e+000,2,6.910564e-001,0.000000e+000,,,,,,,,,,,,,,32,1,4.000000e+000,4.207611e-003,0.000000e+000,0,,0,
1524322433.123,,0.000000e+000,5.699045e+001,-7.191351e-005,0.000000e+000,2,6.902898e-001,0.000000e+000,,,,,,,,,,,,,,32,1,4.000000e+000,5.599976e-003,0.000000e+000,0,,0,
1524322457.723,,0.000000e+000,5.699746e+001,-7.195251e-005,0.000000e+000,2,6.904739e-001,0.000000e+000,,,,,,,,,,,,,,32,1,4.000000e+000,5.607605e-003,0.000000e+000,0,,0,
1524322482.793,,0.000000e+000,5.700517e+001,-7.192563e-005,0.000000e+000,2,6.908928e-001,0.000000e+000,,,,,,,,,,,,,,32,1,4.000000e+000,1.261902e-002,0.000000e+000,0,,0,
1524322508.403,,0.000000e+000,5.699676e+001,-7.193341e-005,0.000000e+000,2,6.916130e-001,0.000000e+000,,,,,,,,,,,,,,32,1,4.000000e+000,4.207611e-003,0.000000e+000,0,,0,
1524322534.103,,0.000000e+000,5.698835e+001,-7.206197e-005,0.000000e+000,2,6.918405e-001,0.000000e+000,,,,,,,,,,,,,,32,1,4.000000e+000,9.811401e-003,0.000000e+000,0,,0,
1524322559.583,,0.000000e+000,5.699746e+001,-7.205419e-005,0.000000e+000,2,6.918858e-001,0.000000e+000,,,,,,,,,,,,,,32,1,4.000000e+000,8.419037e-003,0.000000e+000,0,,0,
1524322584.303,,0.000000e+000,5.699606e+001,-7.210144e-005,0.000000e+000,2,6.924480e-001,0.000000e+000,,,,,,,,,,,,,,32,1,4.000000e+000,8.399963e-003,0.000000e+000,0,,0,
1524322610.103,,0.000000e+000,5.699746e+001,-7.211453e-005,0.000000e+000,2,6.925516e-001,0.000000e+000,,,,,,,,,,,,,,32,1,4.000000e+000,8.419037e-003,0.000000e+000,0,,0,
1524322634.823,,0.000000e+000,5.699886e+001,-7.213600e-005,0.000000e+000,2,6.927286e-001,0.000000e+000,,,,,,,,,,,,,,32,1,4.000000e+000,2.799988e-003,0.000000e+000,0,,0,
1524322660.113,,0.000000e+000,5.699606e+001,-7.209656e-005,0.000000e+000,2,6.924523e-001,0.000000e+000,,,,,,,,,,,,,,32,1,4.000000e+000,2.807617e-003,0.000000e+000,0,,0,
1524322685.304,,0.000000e+000,5.700027e+001,-7.218522e-005,0.000000e+000,2,6.924238e-001,0.000000e+000,,,,,,,,,,,,,,32,1,4.000000e+000,8.411407e-003,0.000000e+000,0,,0,
1524322710.124,,0.000000e+000,5.699396e+001,-7.215502e-005,0.000000e+000,2,6.909065e-001,0.000000e+000,,,,,,,,,,,,,,32,1,4.000000e+000,1.260757e-002,0.000000e+000,0,,0,
1524322735.004,,0.000000e+000,5.700447e+001,-7.219641e-005,0.000000e+000,2,6.920690e-001,0.000000e+000,,,,,,,,,,,,,,32,1,4.000000e+000,1.401901e-002,0.000000e+000,0,,0,
1524322760.614,,0.000000e+000,5.700447e+001,-7.222513e-005,0.000000e+000,2,6.918779e-001,0.000000e+000,,,,,,,,,,,,,,32,1,4.000000e+000,0.000000e+000,0.000000e+000,0,,0,
1524322785.504,,0.000000e+000,5.699535e+001,-7.223573e-005,0.000000e+000,2,6.923574e-001,0.000000e+000,,,,,,,,,,,,,,32,1,4.000000e+000,1.407623e-003,0.000000e+000,0,,0,
1524322810.914,,0.000000e+000,5.699466e+001,-7.230751e-005,0.000000e+000,2,6.924557e-001,0.000000e+000,,,,,,,,,,,,,,32,1,4.000000e+000,2.807617e-003,0.000000e+000,0,,0,
1524322836.164,,0.000000e+000,5.700307e+001,-7.240448e-005,0.000000e+000,2,6.938164e-001,0.000000e+000,,,,,,,,,,,,,,32,1,4.000000e+000,2.799988e-003,0.000000e+000,0,,0,
1524322861.464,,0.000000e+000,5.700027e+001,-7.237768e-005,0.000000e+000,2,6.936433e-001,0.000000e+000,,,,,,,,,,,,,,32,1,4.000000e+000,8.411407e-003,0.000000e+000,0,,0,
1524322887.274,,0.000000e+000,5.699676e+001,-7.243771e-005,0.000000e+000,2,6.942619e-001,0.000000e+000,,,,,,,,,,,,,,32,1,4.000000e+000,4.207611e-003,0.000000e+000,0,,0,
1524322912.164,,0.000000e+000,5.700237e+001,-7.242701e-005,0.000000e+000,2,6.942936e-001,0.000000e+000,,,,,,,,,,,,,,32,1,4.000000e+000,1.388550e-003,0.000000e+000,0,,0,
1524322937.914,,0.000000e+000,5.700447e+001,-7.243246e-005,0.000000e+000,2,6.945485e-001,0.000000e+000,,,,,,,,,,,,,,32,1,4.000000e+000,1.121902e-002,0.000000e+000,0,,0,
1524322962.914,,0.000000e+000,5.699536e+001,-7.247923e-005,0.000000e+000,2,6.940253e-001,0.000000e+000,,,,,,,,,,,,,,32,1,4.000000e+000,6.999969e-003,0.000000e+000,0,,0,
1524322988.344,,0.000000e+000,5.699115e+001,-7.253545e-005,0.000000e+000,2,6.945887e-001,0.000000e+000,,,,,,,,,,,,,,32,1,4.000000e+000,4.211426e-003,0.000000e+000,0,,0,
1524323013.544,,0.000000e+000,5.699396e+001,-7.256942e-005,0.000000e+000,2,6.947057e-001,0.000000e+000,,,,,,,,,,,,,,32,1,4.000000e+000,4.199982e-003,0.000000e+000,0,,0,
1524323039.024,,0.000000e+000,5.699886e+001,-7.252500e-005,0.000000e+000,2,6.944456e-001,0.000000e+000,,,,,,,,,,,,,,32,1,4.000000e+000,5.611420e-003,0.000000e+000,0,,0,
1524323064.134,,0.000000e+000,5.699816e+001,-7.259911e-005,0.000000e+000,2,6.948972e-001,0.000000e+000,,,,,,,,,,,,,,32,1,4.000000e+000,1.399994e-003,0.000000e+000,0,,0,
1524323089.754,,0.000000e+000,5.699957e+001,-7.262783e-005,0.000000e+000,2,6.955314e-001,0.000000e+000,,,,,,,,,,,,,,32,1,4.000000e+000,4.211426e-003,0.000000e+000,0,,0,
1524323115.254,,0.000000e+000,5.700097e+001,-7.265501e-005,0.000000e+000,2,6.956083e-001,0.000000e+000,,,,,,,,,,,,,,32,1,4.000000e+000,1.262665e-002,0.000000e+000,0,,0,
1524323141.584,,0.000000e+000,5.699465e+001,-7.265220e-005,0.000000e+000,2,6.956288e-001,0.000000e+000,,,,,,,,,,,,,,32,1,4.000000e+000,0.000000e+000,0.000000e+000,0,,0,
1524323166.474,,0.000000e+000,5.699816e+001,-7.267560e-005,0.000000e+000,2,6.952495e-001,0.000000e+000,,,,,,,,,,,,,,32,1,4.000000e+000,4.199982e-003,0.000000e+000,0,,0,
1524323190.964,,0.000000e+000,5.700658e+001,-7.277112e-005,0.000000e+000,2,6.957760e-001,0.000000e+000,,,,,,,,,,,,,,32,1,4.000000e+000,1.407623e-003,0.000000e+000,0,,0,
1524323216.444,,0.000000e+000,5.700097e+001,-7.270766e-005,0.000000e+000,2,6.956843e-001,0.000000e+000,,,,,,,,,,,,,,32,1,4.000000e+000,1.411438e-003,0.000000e+000,0,,0,
1524323242.024,,0.000000e+000,5.700447e+001,-7.276151e-005,0.000000e+000,2,6.952371e-001,0.000000e+000,,,,,,,,,,,,,,32,1,4.000000e+000,5.607605e-003,0.000000e+000,0,,0,
1524323267.474,,0.000000e+000,5.700026e+001,-7.277140e-005,0.000000e+000,2,6.951900e-001,0.000000e+000,,,,,,,,,,,,,,32,1,4.000000e+000,5.599976e-003,0.000000e+000,0,,0,
1524323293.034,,0.000000e+000,5.700026e+001,-7.276055e-005,0.000000e+000,2,6.951094e-001,0.000000e+000,,,,,,,,,,,,,,32,1,4.000000e+000,0.000000e+000,0.000000e+000,0,,0,
1524323318.454,,0.000000e+000,5.699956e+001,-7.278972e-005,0.000000e+000,2,6.956342e-001,0.000000e+000,,,,,,,,,,,,,,32,1,4.000000e+000,1.399994e-003,0.000000e+000,0,,0,
1524323344.094,,0.000000e+000,5.699325e+001,-7.284396e-005,0.000000e+000,2,6.951278e-001,0.000000e+000,,,,,,,,,,,,,,32,1,4.000000e+000,8.419037e-003,0.000000e+000,0,,0,
1524323369.114,,0.000000e+000,5.699465e+001,-7.288745e-005,0.000000e+000,2,6.948457e-001,0.000000e+000,,,,,,,,,,,,,,32,1,4.000000e+000,0.000000e+000,0.000000e+000,0,,0,
1524323395.004,,0.000000e+000,5.700097e+001,-7.292533e-005,0.000000e+000,2,6.963630e-001,0.000000e+000,,,,,,,,,,,,,,32,1,4.000000e+000,7.011414e-003,0.000000e+000,0,,0,
1524323419.945,,0.000000e+000,5.699535e+001,-7.293018e-005,0.000000e+000,2,6.960073e-001,0.000000e+000,,,,,,,,,,,,,,32,1,4.000000e+000,1.407623e-003,0.000000e+000,0,,0,
1524323444.815,,0.000000e+000,5.699956e+001,-7.294931e-005,0.000000e+000,2,6.967923e-001,0.000000e+000,,,,,,,,,,,,,,32,1,4.000000e+000,6.999969e-003,0.000000e+000,0,,0,
1524323470.495,,0.000000e+000,5.699115e+001,-7.307484e-005,0.000000e+000,2,6.963759e-001,0.000000e+000,,,,,,,,,,,,,,32,1,4.000000e+000,9.819031e-003,0.000000e+000,0,,0,
1524323495.475,,0.000000e+000,5.699886e+001,-7.297973e-005,0.000000e+000,2,6.965761e-001,0.000000e+000,,,,,,,,,,,,,,32,1,4.000000e+000,8.407593e-003,0.000000e+000,0,,0,
1524323520.245,,0.000000e+000,5.700447e+001,-7.298016e-005,0.000000e+000,2,6.968955e-001,0.000000e+000,,,,,,,,,,,,,,32,1,4.000000e+000,5.607605e-003,0.000000e+000,0,,0,
1524323545.545,,0.000000e+000,5.700026e+001,-7.303138e-005,0.000000e+000,2,6.974345e-001,0.000000e+000,,,,,,,,,,,,,,32,1,4.000000e+000,5.599976e-003,0.000000e+000,0,,0,
1524323571.025,,0.000000e+000,5.699956e+001,-7.305124e-005,0.000000e+000,2,6.970729e-001,0.000000e+000,,,,,,,,,,,,,,32,1,4.000000e+000,1.399994e-003,0.000000e+000,0,,0,
1524323595.885,,0.000000e+000,5.699815e+001,-7.304813e-005,0.000000e+000,2,6.968387e-001,0.000000e+000,,,,,,,,,,,,,,32,1,4.000000e+000,9.807587e-003,0.000000e+000,0,,0,
1524323621.085,,0.000000e+000,5.700097e+001,-7.310278e-005,0.000000e+000,2,6.977231e-001,0.000000e+000,,,,,,,,,,,,,,32,1,4.000000e+000,7.011414e-003,0.000000e+000,0,,0,
1524323645.995,,0.000000e+000,5.699325e+001,-7.313888e-005,0.000000e+000,2,6.981960e-001,0.000000e+000,,,,,,,,,,,,,,32,1,4.000000e+000,1.401901e-002,0.000000e+000,0,,0,
1524323671.115,,0.000000e+000,5.699676e+001,-7.312081e-005,0.000000e+000,2,6.975833e-001,0.000000e+000,,,,,,,,,,,,,,32,1,4.000000e+000,7.007599e-003,0.000000e+000,0,,0,
1524323696.275,,0.000000e+000,5.699465e+001,-7.318807e-005,0.000000e+000,2,6.975267e-001,0.000000e+000,,,,,,,,,,,,,,32,1,4.000000e+000,0.000000e+000,0.000000e+000,0,,0,
1524323721.765,,0.000000e+000,5.699535e+001,-7.322503e-005,0.000000e+000,2,6.981266e-001,0.000000e+000,,,,,,,,,,,,,,32,1,4.000000e+000,4.207611e-003,0.000000e+000,0,,0,
1524323746.635,,0.000000e+000,5.699746e+001,-7.321477e-005,0.000000e+000,2,6.976547e-001,0.000000e+000,,,,,,,,,,,,,,32,1,4.000000e+000,5.607605e-003,0.000000e+000,0,,0,
1524323772.195,,0.000000e+000,5.699676e+001,-7.319498e-005,0.000000e+000,2,6.968852e-001,0.000000e+000,,,,,,,,,,,,,,32,1,4.000000e+000,4.207611e-003,0.000000e+000,0,,0,
1524323797.075,,0.000000e+000,5.699816e+001,-7.325708e-005,0.000000e+000,2,6.979401e-001,0.000000e+000,,,,,,,,,,,,,,32,1,4.000000e+000,1.399994e-003,0.000000e+000,0,,0,
1524323822.315,,0.000000e+000,5.699535e+001,-7.327169e-005,0.000000e+000,2,6.987829e-001,0.000000e+000,,,,,,,,,,,,,,32,1,4.000000e+000,1.407623e-003,0.000000e+000,0,,0,
1524323847.475,,0.000000e+000,5.699816e+001,-7.331422e-005,0.000000e+000,2,6.983665e-001,0.000000e+000,,,,,,,,,,,,,,32,1,4.000000e+000,4.199982e-003,0.000000e+000,0,,0,
1524323872.645,,0.000000e+000,5.699816e+001,-7.341830e-005,0.000000e+000,2,6.989417e-001,0.000000e+000,,,,,,,,,,,,,,32,1,4.000000e+000,1.399994e-003,0.000000e+000,0,,0,
1524323899.085,,0.000000e+000,5.699186e+001,-7.339033e-005,0.000000e+000,2,6.988171e-001,0.000000e+000,,,,,,,,,,,,,,32,1,4.000000e+000,0.000000e+000,0.000000e+000,0,,0,
1524323923.955,,0.000000e+000,5.699956e+001,-7.329618e-005,0.000000e+000,2,6.984909e-001,0.000000e+000,,,,,,,,,,,,,,32,1,4.000000e+000,6.999969e-003,0.000000e+000,0,,0,
1524323948.905,,0.000000e+000,5.699816e+001,-7.336795e-005,0.000000e+000,2,6.994165e-001,0.000000e+000,,,,,,,,,,,,,,32,1,4.000000e+000,7.019043e-003,0.000000e+000,0,,0,
1524323974.995,,0.000000e+000,5.699535e+001,-7.338358e-005,0.000000e+000,2,6.989961e-001,0.000000e+000,,,,,,,,,,,,,,32,1,4.000000e+000,1.407623e-003,0.000000e+000,0,,0,
1524324000.155,,0.000000e+000,5.700307e+001,-7.341404e-005,0.000000e+000,2,6.987453e-001,0.000000e+000,,,,,,,,,,,,,,32,1,4.000000e+000,8.419037e-003,0.000000e+000,0,,0,
1524324025.505,,0.000000e+000,5.699606e+001,-7.334006e-005,0.000000e+000,2,6.984308e-001,0.000000e+000,,,,,,,,,,,,,,32,1,4.000000e+000,2.807617e-003,0.000000e+000,0,,0,
1524324051.245,,0.000000e+000,5.699956e+001,-7.344324e-005,0.000000e+000,2,6.984283e-001,0.000000e+000,,,,,,,,,,,,,,32,1,4.000000e+000,1.261902e-002,0.000000e+000,0,,0,
1524324076.605,,0.000000e+000,5.700027e+001,-7.343711e-005,0.000000e+000,2,6.977743e-001,0.000000e+000,,,,,,,,,,,,,,32,1,4.000000e+000,1.402664e-002,0.000000e+000,0,,0,
1524324102.375,,0.000000e+000,5.699606e+001,-7.345953e-005,0.000000e+000,2,6.981986e-001,0.000000e+000,,,,,,,,,,,,,,32,1,4.000000e+000,2.807617e-003,0.000000e+000,0,,0,
1524324127.206,,0.000000e+000,5.699606e+001,-7.356590e-005,0.000000e+000,2,6.983530e-001,0.000000e+000,,,,,,,,,,,,,,32,1,4.000000e+000,1.121902e-002,0.000000e+000,0,,0,
1524324152.126,,0.000000e+000,5.699816e+001,-7.353099e-005,0.000000e+000,2,6.989706e-001,0.000000e+000,,,,,,,,,,,,,,32,1,4.000000e+000,1.823807e-002,0.000000e+000,0,,0,
1524324164.386,,0.000000e+000,5.700377e+001,-7.348481e-005,0.000000e+000,2,6.986113e-001,0.000000e+000,,,,,,,,,,,,,,32,1,4.000000e+000,7.019043e-003,0.000000e+000,0,,0,