File: Experimental Raw Data/TC04-12-01K Acquisition/TC04-12-01K_VRMac_55K_12000s.dc.dat
[Header]
TITLE,MPMS DC Measurement
BYAPP,MPMS Measurement,2.1,Summary
FILEOPENTIME, 1524015835.999000 4/17/2018, 7:43:55 PM

INFO, APPNAME, MPMS MultiVu Application, Revision 1.61,  Build 082

INFO, NAME, TC04-12-01K
INFO, WEIGHT, 1.000
INFO, AREA, 1.000
INFO, LENGTH, 1.000
INFO, SHAPE, 0
INFO, COMMENT,
INFO, SEQUENCE FILE: VRMac_55K_12000s_VRMde_55K.seq


INFO, BACKGROUND DATA FILE:, None


STARTUPAXIS,X,4,LINEAR,AUTO,0.000000,0.000000
STARTUPAXIS,Y1,5,LINEAR,AUTO,0.000000,0.000000


STARTUPGROUP,Longitudinal
FIELDGROUP,Longitudinal,1,2,3,4,5,6,7,8,9,15,16,17,18,27,28
FIELDGROUP,Transverse,1,2,3,4,10,11,12,13,14,19,20,21,22,27,28

PLOT_APPEARANCE,ALL,HORZ_GRID_ON,VERT_GRID_ON,MARKERS_AND_LINES

[Data]
Time,Comment,Field (Oe),Temperature (K),Long Moment (emu),Long Scan Std Dev,Long Algorithm,Long Reg Fit,Long Percent Error (%),Trans Moment (emu),Trans Scan Std Dev,Trans Algorithm,Trans Reg Fit,Trans Percent Error (%),Long Moment [w/o ABS] (emu),Long Scan Std Dev [w/o ABS],Long Reg Fit [w/o ABS],Long Percent Error [w/o ABS] (%),Trans Moment [w/o ABS] (emu),Trans Scan Std Dev [w/o ABS],Trans Reg Fit [w/o ABS],Trans Percent Error [w/o ABS] (%),Points per Scan,Scans per Measurement,Scan Length (cm),Delta Temp (K),Rot Position (deg),Error,EC Comp. Running,Using ABS,
1524015835.999,,0.000000e+000,5.505568e+001,-5.432008e-005,0.000000e+000,3,9.730493e-001,0.000000e+000,,,,,,,,,,,,,,32,1,4.000000e+000,2.240753e-002,0.000000e+000,0,,0,
1524015874.829,,0.000000e+000,5.501485e+001,-5.964429e-005,0.000000e+000,3,9.736489e-001,0.000000e+000,,,,,,,,,,,,,,32,1,4.000000e+000,1.319885e-003,0.000000e+000,0,,0,
1524015912.269,,0.000000e+000,5.499774e+001,-6.187337e-005,0.000000e+000,3,9.720912e-001,0.000000e+000,,,,,,,,,,,,,,32,1,4.000000e+000,6.580353e-003,0.000000e+000,0,,0,
1524015949.899,,0.000000e+000,5.499709e+001,-6.332800e-005,0.000000e+000,3,9.734526e-001,0.000000e+000,,,,,,,,,,,,,,32,1,4.000000e+000,7.888794e-003,0.000000e+000,0,,0,
1524015987.529,,0.000000e+000,5.499642e+001,-6.431787e-005,0.000000e+000,3,9.725224e-001,0.000000e+000,,,,,,,,,,,,,,32,1,4.000000e+000,3.940582e-003,0.000000e+000,0,,0,
1524016025.549,,0.000000e+000,5.499906e+001,-6.522104e-005,0.000000e+000,3,9.733515e-001,0.000000e+000,,,,,,,,,,,,,,32,1,4.000000e+000,6.580353e-003,0.000000e+000,0,,0,
1524016063.979,,0.000000e+000,5.499577e+001,-6.589266e-005,0.000000e+000,3,9.743721e-001,0.000000e+000,,,,,,,,,,,,,,32,1,4.000000e+000,1.052094e-002,0.000000e+000,0,,0,
1524016101.549,,0.000000e+000,5.500103e+001,-6.648617e-005,0.000000e+000,3,9.725237e-001,0.000000e+000,,,,,,,,,,,,,,32,1,4.000000e+000,2.639771e-003,0.000000e+000,0,,0,
1524016139.479,,0.000000e+000,5.499314e+001,-6.693222e-005,0.000000e+000,3,9.736712e-001,0.000000e+000,,,,,,,,,,,,,,32,1,4.000000e+000,5.260468e-003,0.000000e+000,0,,0,
1524016177.139,,0.000000e+000,5.499905e+001,-6.742775e-005,0.000000e+000,3,9.725628e-001,0.000000e+000,,,,,,,,,,,,,,32,1,4.000000e+000,1.319885e-003,0.000000e+000,0,,0,
1524016215.089,,0.000000e+000,5.499905e+001,-6.782394e-005,0.000000e+000,3,9.736389e-001,0.000000e+000,,,,,,,,,,,,,,32,1,4.000000e+000,3.948212e-003,0.000000e+000,0,,0,
1524016252.749,,0.000000e+000,5.499905e+001,-6.819684e-005,0.000000e+000,3,9.726123e-001,0.000000e+000,,,,,,,,,,,,,,32,1,4.000000e+000,3.948212e-003,0.000000e+000,0,,0,
1524016290.699,,0.000000e+000,5.500037e+001,-6.852943e-005,0.000000e+000,3,9.732293e-001,0.000000e+000,,,,,,,,,,,,,,32,1,4.000000e+000,3.959656e-003,0.000000e+000,0,,0,
1524016328.340,,0.000000e+000,5.499773e+001,-6.885637e-005,0.000000e+000,3,9.724331e-001,0.000000e+000,,,,,,,,,,,,,,32,1,4.000000e+000,1.308441e-003,0.000000e+000,0,,0,
1524016366.350,,0.000000e+000,5.499773e+001,-6.911463e-005,0.000000e+000,3,9.738436e-001,0.000000e+000,,,,,,,,,,,,,,32,1,4.000000e+000,1.308441e-003,0.000000e+000,0,,0,
1524016404.090,,0.000000e+000,5.499643e+001,-6.948930e-005,0.000000e+000,3,9.744340e-001,0.000000e+000,,,,,,,,,,,,,,32,1,4.000000e+000,1.312256e-003,0.000000e+000,0,,0,
1524016441.380,,0.000000e+000,5.499642e+001,-6.964502e-005,0.000000e+000,3,9.743373e-001,0.000000e+000,,,,,,,,,,,,,,32,1,4.000000e+000,3.940582e-003,0.000000e+000,0,,0,
1524016479.330,,0.000000e+000,5.499905e+001,-6.999156e-005,0.000000e+000,3,9.741444e-001,0.000000e+000,,,,,,,,,,,,,,32,1,4.000000e+000,1.319885e-003,0.000000e+000,0,,0,
1524016516.930,,0.000000e+000,5.499643e+001,-7.018381e-005,0.000000e+000,3,9.737222e-001,0.000000e+000,,,,,,,,,,,,,,32,1,4.000000e+000,6.568909e-003,0.000000e+000,0,,0,
1524016553.790,,0.000000e+000,5.500234e+001,-7.036531e-005,0.000000e+000,3,9.738253e-001,0.000000e+000,,,,,,,,,,,,,,32,1,4.000000e+000,7.900238e-003,0.000000e+000,0,,0,
1524016591.390,,0.000000e+000,5.499577e+001,-7.057908e-005,0.000000e+000,3,9.742330e-001,0.000000e+000,,,,,,,,,,,,,,32,1,4.000000e+000,0.000000e+000,0.000000e+000,0,,0,
1524016628.670,,0.000000e+000,5.499773e+001,-7.074442e-005,0.000000e+000,3,9.741403e-001,0.000000e+000,,,,,,,,,,,,,,32,1,4.000000e+000,1.308441e-003,0.000000e+000,0,,0,
1524016666.570,,0.000000e+000,5.500366e+001,-7.088183e-005,0.000000e+000,3,9.738522e-001,0.000000e+000,,,,,,,,,,,,,,32,1,4.000000e+000,2.620697e-003,0.000000e+000,0,,0,
1524016704.180,,0.000000e+000,5.499773e+001,-7.114892e-005,0.000000e+000,3,9.737377e-001,0.000000e+000,,,,,,,,,,,,,,32,1,4.000000e+000,1.308441e-003,0.000000e+000,0,,0,
1524016741.750,,0.000000e+000,5.500234e+001,-7.127092e-005,0.000000e+000,3,9.740589e-001,0.000000e+000,,,,,,,,,,,,,,32,1,4.000000e+000,7.900238e-003,0.000000e+000,0,,0,
1524016779.260,,0.000000e+000,5.499905e+001,-7.142029e-005,0.000000e+000,3,9.723845e-001,0.000000e+000,,,,,,,,,,,,,,32,1,4.000000e+000,1.182938e-002,0.000000e+000,0,,0,
1524016817.010,,0.000000e+000,5.499643e+001,-7.157682e-005,0.000000e+000,3,9.734321e-001,0.000000e+000,,,,,,,,,,,,,,32,1,4.000000e+000,9.208679e-003,0.000000e+000,0,,0,
1524016854.340,,0.000000e+000,5.499971e+001,-7.175391e-005,0.000000e+000,3,9.725946e-001,0.000000e+000,,,,,,,,,,,,,,32,1,4.000000e+000,0.000000e+000,0.000000e+000,0,,0,
1524016892.150,,0.000000e+000,5.500037e+001,-7.187116e-005,0.000000e+000,3,9.734059e-001,0.000000e+000,,,,,,,,,,,,,,32,1,4.000000e+000,3.959656e-003,0.000000e+000,0,,0,
1524016929.420,,0.000000e+000,5.500037e+001,-7.199835e-005,0.000000e+000,3,9.727848e-001,0.000000e+000,,,,,,,,,,,,,,32,1,4.000000e+000,1.319885e-003,0.000000e+000,0,,0,
1524016966.950,,0.000000e+000,5.499379e+001,-7.210106e-005,0.000000e+000,3,9.735408e-001,0.000000e+000,,,,,,,,,,,,,,32,1,4.000000e+000,9.201050e-003,0.000000e+000,0,,0,
1524017004.450,,0.000000e+000,5.499972e+001,-7.224789e-005,0.000000e+000,3,9.731414e-001,0.000000e+000,,,,,,,,,,,,,,32,1,4.000000e+000,7.900238e-003,0.000000e+000,0,,0,
1524017041.931,,0.000000e+000,5.499380e+001,-7.235011e-005,0.000000e+000,3,9.747424e-001,0.000000e+000,,,,,,,,,,,,,,32,1,4.000000e+000,3.948212e-003,0.000000e+000,0,,0,
1524017079.041,,0.000000e+000,5.499445e+001,-7.251856e-005,0.000000e+000,3,9.730847e-001,0.000000e+000,,,,,,,,,,,,,,32,1,4.000000e+000,7.881165e-003,0.000000e+000,0,,0,
1524017116.921,,0.000000e+000,5.499577e+001,-7.262193e-005,0.000000e+000,3,9.734844e-001,0.000000e+000,,,,,,,,,,,,,,32,1,4.000000e+000,7.888794e-003,0.000000e+000,0,,0,
1524017154.281,,0.000000e+000,5.499643e+001,-7.269859e-005,0.000000e+000,3,9.733961e-001,0.000000e+000,,,,,,,,,,,,,,32,1,4.000000e+000,1.312256e-003,0.000000e+000,0,,0,
1524017192.181,,0.000000e+000,5.499709e+001,-7.285162e-005,0.000000e+000,3,9.730047e-001,0.000000e+000,,,,,,,,,,,,,,32,1,4.000000e+000,1.316071e-002,0.000000e+000,0,,0,
1524017230.441,,0.000000e+000,5.500432e+001,-7.297962e-005,0.000000e+000,3,9.741194e-001,0.000000e+000,,,,,,,,,,,,,,32,1,4.000000e+000,1.300812e-003,0.000000e+000,0,,0,
1524017267.491,,0.000000e+000,5.499840e+001,-7.302936e-005,0.000000e+000,3,9.742684e-001,0.000000e+000,,,,,,,,,,,,,,32,1,4.000000e+000,7.900238e-003,0.000000e+000,0,,0,
1524017304.421,,0.000000e+000,5.499839e+001,-7.318285e-005,0.000000e+000,3,9.740973e-001,0.000000e+000,,,,,,,,,,,,,,32,1,4.000000e+000,0.000000e+000,0.000000e+000,0,,0,
1524017341.501,,0.000000e+000,5.499051e+001,-7.327054e-005,0.000000e+000,3,9.739048e-001,0.000000e+000,,,,,,,,,,,,,,32,1,4.000000e+000,0.000000e+000,0.000000e+000,0,,0,
1524017379.591,,0.000000e+000,5.500300e+001,-7.338593e-005,0.000000e+000,3,9.742602e-001,0.000000e+000,,,,,,,,,,,,,,32,1,4.000000e+000,3.940582e-003,0.000000e+000,0,,0,
1524017416.821,,0.000000e+000,5.499577e+001,-7.340941e-005,0.000000e+000,3,9.722492e-001,0.000000e+000,,,,,,,,,,,,,,32,1,4.000000e+000,7.888794e-003,0.000000e+000,0,,0,
1524017454.961,,0.000000e+000,5.499511e+001,-7.351026e-005,0.000000e+000,3,9.733659e-001,0.000000e+000,,,,,,,,,,,,,,32,1,4.000000e+000,1.319885e-003,0.000000e+000,0,,0,
1524017492.631,,0.000000e+000,5.500037e+001,-7.366748e-005,0.000000e+000,3,9.726820e-001,0.000000e+000,,,,,,,,,,,,,,32,1,4.000000e+000,1.319885e-003,0.000000e+000,0,,0,
1524017530.591,,0.000000e+000,5.499840e+001,-7.371122e-005,0.000000e+000,3,9.735282e-001,0.000000e+000,,,,,,,,,,,,,,32,1,4.000000e+000,2.628326e-003,0.000000e+000,0,,0,
1524017568.231,,0.000000e+000,5.500234e+001,-7.384865e-005,0.000000e+000,3,9.727064e-001,0.000000e+000,,,,,,,,,,,,,,32,1,4.000000e+000,5.260468e-003,0.000000e+000,0,,0,
1524017605.991,,0.000000e+000,5.499643e+001,-7.387140e-005,0.000000e+000,3,9.742830e-001,0.000000e+000,,,,,,,,,,,,,,32,1,4.000000e+000,6.568909e-003,0.000000e+000,0,,0,
1524017643.351,,0.000000e+000,5.499577e+001,-7.401819e-005,0.000000e+000,3,9.728059e-001,0.000000e+000,,,,,,,,,,,,,,32,1,4.000000e+000,2.632141e-003,0.000000e+000,0,,0,
1524017681.261,,0.000000e+000,5.499708e+001,-7.404709e-005,0.000000e+000,3,9.738457e-001,0.000000e+000,,,,,,,,,,,,,,32,1,4.000000e+000,2.620697e-003,0.000000e+000,0,,0,
1524017718.411,,0.000000e+000,5.499971e+001,-7.411844e-005,0.000000e+000,3,9.735407e-001,0.000000e+000,,,,,,,,,,,,,,32,1,4.000000e+000,0.000000e+000,0.000000e+000,0,,0,
1524017756.732,,0.000000e+000,5.500169e+001,-7.416697e-005,0.000000e+000,3,9.735049e-001,0.000000e+000,,,,,,,,,,,,,,32,1,4.000000e+000,3.959656e-003,0.000000e+000,0,,0,
1524017795.262,,0.000000e+000,5.499380e+001,-7.429185e-005,0.000000e+000,3,9.736290e-001,0.000000e+000,,,,,,,,,,,,,,32,1,4.000000e+000,1.308441e-003,0.000000e+000,0,,0,
1524017832.682,,0.000000e+000,5.499839e+001,-7.431440e-005,0.000000e+000,3,9.746109e-001,0.000000e+000,,,,,,,,,,,,,,32,1,4.000000e+000,0.000000e+000,0.000000e+000,0,,0,
1524017871.482,,0.000000e+000,5.499642e+001,-7.450454e-005,0.000000e+000,3,9.747772e-001,0.000000e+000,,,,,,,,,,,,,,32,1,4.000000e+000,3.940582e-003,0.000000e+000,0,,0,
1524017908.872,,0.000000e+000,5.499380e+001,-7.460702e-005,0.000000e+000,3,9.736924e-001,0.000000e+000,,,,,,,,,,,,,,32,1,4.000000e+000,6.572723e-003,0.000000e+000,0,,0,
1524017946.112,,0.000000e+000,5.499775e+001,-7.455719e-005,0.000000e+000,3,9.753095e-001,0.000000e+000,,,,,,,,,,,,,,32,1,4.000000e+000,9.208679e-003,0.000000e+000,0,,0,
1524017984.772,,0.000000e+000,5.499905e+001,-7.460807e-005,0.000000e+000,3,9.739989e-001,0.000000e+000,,,,,,,,,,,,,,32,1,4.000000e+000,3.948212e-003,0.000000e+000,0,,0,
1524018022.672,,0.000000e+000,5.500037e+001,-7.481506e-005,0.000000e+000,3,9.733968e-001,0.000000e+000,,,,,,,,,,,,,,32,1,4.000000e+000,1.319885e-003,0.000000e+000,0,,0,
1524018060.232,,0.000000e+000,5.499445e+001,-7.481890e-005,0.000000e+000,3,9.731818e-001,0.000000e+000,,,,,,,,,,,,,,32,1,4.000000e+000,2.628326e-003,0.000000e+000,0,,0,
1524018098.302,,0.000000e+000,5.499971e+001,-7.491750e-005,0.000000e+000,3,9.737022e-001,0.000000e+000,,,,,,,,,,,,,,32,1,4.000000e+000,2.639771e-003,0.000000e+000,0,,0,
1524018135.952,,0.000000e+000,5.499577e+001,-7.492995e-005,0.000000e+000,3,9.723471e-001,0.000000e+000,,,,,,,,,,,,,,32,1,4.000000e+000,7.888794e-003,0.000000e+000,0,,0,
1524018173.892,,0.000000e+000,5.500037e+001,-7.494551e-005,0.000000e+000,3,9.740016e-001,0.000000e+000,,,,,,,,,,,,,,32,1,4.000000e+000,1.319885e-003,0.000000e+000,0,,0,
1524018211.542,,0.000000e+000,5.500103e+001,-7.502222e-005,0.000000e+000,3,9.730067e-001,0.000000e+000,,,,,,,,,,,,,,32,1,4.000000e+000,1.316071e-002,0.000000e+000,0,,0,
1524018249.542,,0.000000e+000,5.500563e+001,-7.511360e-005,0.000000e+000,3,9.745708e-001,0.000000e+000,,,,,,,,,,,,,,32,1,4.000000e+000,1.184082e-002,0.000000e+000,0,,0,
1524018286.642,,0.000000e+000,5.499906e+001,-7.519792e-005,0.000000e+000,3,9.728389e-001,0.000000e+000,,,,,,,,,,,,,,32,1,4.000000e+000,6.580353e-003,0.000000e+000,0,,0,
1524018324.502,,0.000000e+000,5.500235e+001,-7.520845e-005,0.000000e+000,3,9.744934e-001,0.000000e+000,,,,,,,,,,,,,,32,1,4.000000e+000,2.639771e-003,0.000000e+000,0,,0,
1524018362.562,,0.000000e+000,5.499511e+001,-7.526507e-005,0.000000e+000,3,9.745511e-001,0.000000e+000,,,,,,,,,,,,,,32,1,4.000000e+000,1.319885e-003,0.000000e+000,0,,0,
1524018400.242,,0.000000e+000,5.499577e+001,-7.532565e-005,0.000000e+000,3,9.750546e-001,0.000000e+000,,,,,,,,,,,,,,32,1,4.000000e+000,2.632141e-003,0.000000e+000,0,,0,
1524018437.302,,0.000000e+000,5.499971e+001,-7.533162e-005,0.000000e+000,3,9.746575e-001,0.000000e+000,,,,,,,,,,,,,,32,1,4.000000e+000,2.639771e-003,0.000000e+000,0,,0,
1524018475.493,,0.000000e+000,5.499971e+001,-7.549706e-005,0.000000e+000,3,9.750189e-001,0.000000e+000,,,,,,,,,,,,,,32,1,4.000000e+000,1.052094e-002,0.000000e+000,0,,0,
1524018512.803,,0.000000e+000,5.499511e+001,-7.550362e-005,0.000000e+000,3,9.727431e-001,0.000000e+000,,,,,,,,,,,,,,32,1,4.000000e+000,3.940582e-003,0.000000e+000,0,,0,
1524018550.623,,0.000000e+000,5.499906e+001,-7.560068e-005,0.000000e+000,3,9.742022e-001,0.000000e+000,,,,,,,,,,,,,,32,1,4.000000e+000,6.580353e-003,0.000000e+000,0,,0,
1524018588.373,,0.000000e+000,5.499708e+001,-7.552940e-005,0.000000e+000,3,9.732624e-001,0.000000e+000,,,,,,,,,,,,,,32,1,4.000000e+000,5.260468e-003,0.000000e+000,0,,0,
1524018626.233,,0.000000e+000,5.499774e+001,-7.566412e-005,0.000000e+000,3,9.743031e-001,0.000000e+000,,,,,,,,,,,,,,32,1,4.000000e+000,3.940582e-003,0.000000e+000,0,,0,
1524018663.973,,0.000000e+000,5.499905e+001,-7.579176e-005,0.000000e+000,3,9.733152e-001,0.000000e+000,,,,,,,,,,,,,,32,1,4.000000e+000,1.319885e-003,0.000000e+000,0,,0,
1524018701.853,,0.000000e+000,5.499708e+001,-7.575363e-005,0.000000e+000,3,9.739677e-001,0.000000e+000,,,,,,,,,,,,,,32,1,4.000000e+000,2.620697e-003,0.000000e+000,0,,0,
1524018739.583,,0.000000e+000,5.499709e+001,-7.578624e-005,0.000000e+000,3,9.733091e-001,0.000000e+000,,,,,,,,,,,,,,32,1,4.000000e+000,1.052856e-002,0.000000e+000,0,,0,
1524018777.943,,0.000000e+000,5.500037e+001,-7.579932e-005,0.000000e+000,3,9.741939e-001,0.000000e+000,,,,,,,,,,,,,,32,1,4.000000e+000,6.587982e-003,0.000000e+000,0,,0,
1524018815.363,,0.000000e+000,5.499643e+001,-7.602011e-005,0.000000e+000,3,9.736897e-001,0.000000e+000,,,,,,,,,,,,,,32,1,4.000000e+000,1.312256e-003,0.000000e+000,0,,0,
1524018853.323,,0.000000e+000,5.499642e+001,-7.597876e-005,0.000000e+000,3,9.738771e-001,0.000000e+000,,,,,,,,,,,,,,32,1,4.000000e+000,3.940582e-003,0.000000e+000,0,,0,
1524018891.063,,0.000000e+000,5.500168e+001,-7.607266e-005,0.000000e+000,3,9.751021e-001,0.000000e+000,,,,,,,,,,,,,,32,1,4.000000e+000,6.580353e-003,0.000000e+000,0,,0,
1524018928.383,,0.000000e+000,5.499773e+001,-7.606984e-005,0.000000e+000,3,9.748095e-001,0.000000e+000,,,,,,,,,,,,,,32,1,4.000000e+000,1.308441e-003,0.000000e+000,0,,0,
1524018965.993,,0.000000e+000,5.499643e+001,-7.604365e-005,0.000000e+000,3,9.736624e-001,0.000000e+000,,,,,,,,,,,,,,32,1,4.000000e+000,9.208679e-003,0.000000e+000,0,,0,
1524019004.003,,0.000000e+000,5.499840e+001,-7.610657e-005,0.000000e+000,3,9.742052e-001,0.000000e+000,,,,,,,,,,,,,,32,1,4.000000e+000,2.628326e-003,0.000000e+000,0,,0,
1524019041.033,,0.000000e+000,5.499248e+001,-7.619798e-005,0.000000e+000,3,9.731803e-001,0.000000e+000,,,,,,,,,,,,,,32,1,4.000000e+000,9.201050e-003,0.000000e+000,0,,0,
1524019079.313,,0.000000e+000,5.499840e+001,-7.623291e-005,0.000000e+000,3,9.746587e-001,0.000000e+000,,,,,,,,,,,,,,32,1,4.000000e+000,5.260468e-003,0.000000e+000,0,,0,
1524019116.063,,0.000000e+000,5.499971e+001,-7.631616e-005,0.000000e+000,3,9.745319e-001,0.000000e+000,,,,,,,,,,,,,,32,1,4.000000e+000,2.639771e-003,0.000000e+000,0,,0,
1524019154.493,,0.000000e+000,5.499379e+001,-7.633918e-005,0.000000e+000,3,9.735909e-001,0.000000e+000,,,,,,,,,,,,,,32,1,4.000000e+000,9.201050e-003,0.000000e+000,0,,0,
1524019192.484,,0.000000e+000,5.499313e+001,-7.636470e-005,0.000000e+000,3,9.737148e-001,0.000000e+000,,,,,,,,,,,,,,32,1,4.000000e+000,1.050949e-002,0.000000e+000,0,,0,
1524019230.504,,0.000000e+000,5.499445e+001,-7.643351e-005,0.000000e+000,3,9.747535e-001,0.000000e+000,,,,,,,,,,,,,,32,1,4.000000e+000,7.881165e-003,0.000000e+000,0,,0,
1524019268.484,,0.000000e+000,5.499971e+001,-7.648076e-005,0.000000e+000,3,9.731592e-001,0.000000e+000,,,,,,,,,,,,,,32,1,4.000000e+000,2.639771e-003,0.000000e+000,0,,0,
1524019306.384,,0.000000e+000,5.499577e+001,-7.648055e-005,0.000000e+000,3,9.741030e-001,0.000000e+000,,,,,,,,,,,,,,32,1,4.000000e+000,0.000000e+000,0.000000e+000,0,,0,
1524019344.024,,0.000000e+000,5.500103e+001,-7.646981e-005,0.000000e+000,3,9.737244e-001,0.000000e+000,,,,,,,,,,,,,,32,1,4.000000e+000,2.639771e-003,0.000000e+000,0,,0,
1524019381.994,,0.000000e+000,5.500234e+001,-7.654883e-005,0.000000e+000,3,9.741514e-001,0.000000e+000,,,,,,,,,,,,,,32,1,4.000000e+000,5.260468e-003,0.000000e+000,0,,0,
1524019419.754,,0.000000e+000,5.500169e+001,-7.664048e-005,0.000000e+000,3,9.741048e-001,0.000000e+000,,,,,,,,,,,,,,32,1,4.000000e+000,3.959656e-003,0.000000e+000,0,,0,
1524019457.264,,0.000000e+000,5.500234e+001,-7.667481e-005,0.000000e+000,3,9.746197e-001,0.000000e+000,,,,,,,,,,,,,,32,1,4.000000e+000,5.260468e-003,0.000000e+000,0,,0,
1524019495.494,,0.000000e+000,5.499774e+001,-7.671383e-005,0.000000e+000,3,9.745696e-001,0.000000e+000,,,,,,,,,,,,,,32,1,4.000000e+000,3.940582e-003,0.000000e+000,0,,0,
1524019532.794,,0.000000e+000,5.499972e+001,-7.676851e-005,0.000000e+000,3,9.742441e-001,0.000000e+000,,,,,,,,,,,,,,32,1,4.000000e+000,5.268097e-003,0.000000e+000,0,,0,
1524019570.884,,0.000000e+000,5.500366e+001,-7.681352e-005,0.000000e+000,3,9.750065e-001,0.000000e+000,,,,,,,,,,,,,,32,1,4.000000e+000,5.260468e-003,0.000000e+000,0,,0,
1524019608.764,,0.000000e+000,5.500234e+001,-7.689271e-005,0.000000e+000,3,9.740460e-001,0.000000e+000,,,,,,,,,,,,,,32,1,4.000000e+000,5.260468e-003,0.000000e+000,0,,0,
1524019646.684,,0.000000e+000,5.499709e+001,-7.677618e-005,0.000000e+000,3,9.740001e-001,0.000000e+000,,,,,,,,,,,,,,32,1,4.000000e+000,1.052856e-002,0.000000e+000,0,,0,
1524019683.774,,0.000000e+000,5.500235e+001,-7.689511e-005,0.000000e+000,3,9.737803e-001,0.000000e+000,,,,,,,,,,,,,,32,1,4.000000e+000,2.639771e-003,0.000000e+000,0,,0,
1524019721.094,,0.000000e+000,5.499774e+001,-7.692126e-005,0.000000e+000,3,9.736771e-001,0.000000e+000,,,,,,,,,,,,,,32,1,4.000000e+000,3.940582e-003,0.000000e+000,0,,0,
1524019758.754,,0.000000e+000,5.499905e+001,-7.697319e-005,0.000000e+000,3,9.737643e-001,0.000000e+000,,,,,,,,,,,,,,32,1,4.000000e+000,3.948212e-003,0.000000e+000,0,,0,
1524019796.134,,0.000000e+000,5.500498e+001,-7.698396e-005,0.000000e+000,3,9.743620e-001,0.000000e+000,,,,,,,,,,,,,,32,1,4.000000e+000,2.620697e-003,0.000000e+000,0,,0,
1524019833.174,,0.000000e+000,5.500893e+001,-7.700537e-005,0.000000e+000,3,9.735875e-001,0.000000e+000,,,,,,,,,,,,,,32,1,4.000000e+000,2.628326e-003,0.000000e+000,0,,0,
1524019870.774,,0.000000e+000,5.499840e+001,-7.714011e-005,0.000000e+000,3,9.747109e-001,0.000000e+000,,,,,,,,,,,,,,32,1,4.000000e+000,2.628326e-003,0.000000e+000,0,,0,
1524019908.325,,0.000000e+000,5.500564e+001,-7.713459e-005,0.000000e+000,3,9.741636e-001,0.000000e+000,,,,,,,,,,,,,,32,1,4.000000e+000,3.940582e-003,0.000000e+000,0,,0,
1524019946.585,,0.000000e+000,5.500103e+001,-7.716261e-005,0.000000e+000,3,9.742598e-001,0.000000e+000,,,,,,,,,,,,,,32,1,4.000000e+000,1.052094e-002,0.000000e+000,0,,0,
1524019984.325,,0.000000e+000,5.499577e+001,-7.722717e-005,0.000000e+000,3,9.736397e-001,0.000000e+000,,,,,,,,,,,,,,32,1,4.000000e+000,5.249023e-003,0.000000e+000,0,,0,
1524020022.195,,0.000000e+000,5.500366e+001,-7.722509e-005,0.000000e+000,3,9.744874e-001,0.000000e+000,,,,,,,,,,,,,,32,1,4.000000e+000,7.900238e-003,0.000000e+000,0,,0,
1524020059.915,,0.000000e+000,5.499840e+001,-7.721728e-005,0.000000e+000,3,9.739337e-001,0.000000e+000,,,,,,,,,,,,,,32,1,4.000000e+000,2.628326e-003,0.000000e+000,0,,0,
1524020097.785,,0.000000e+000,5.500563e+001,-7.730972e-005,0.000000e+000,3,9.744983e-001,0.000000e+000,,,,,,,,,,,,,,32,1,4.000000e+000,1.319885e-003,0.000000e+000,0,,0,
1524020134.875,,0.000000e+000,5.500300e+001,-7.731840e-005,0.000000e+000,3,9.741842e-001,0.000000e+000,,,,,,,,,,,,,,32,1,4.000000e+000,6.580353e-003,0.000000e+000,0,,0,
1524020172.705,,0.000000e+000,5.499971e+001,-7.738176e-005,0.000000e+000,3,9.744586e-001,0.000000e+000,,,,,,,,,,,,,,32,1,4.000000e+000,2.639771e-003,0.000000e+000,0,,0,
1524020210.205,,0.000000e+000,5.499839e+001,-7.738487e-005,0.000000e+000,3,9.741146e-001,0.000000e+000,,,,,,,,,,,,,,32,1,4.000000e+000,0.000000e+000,0.000000e+000,0,,0,
1524020247.555,,0.000000e+000,5.500366e+001,-7.748045e-005,0.000000e+000,3,9.746639e-001,0.000000e+000,,,,,,,,,,,,,,32,1,4.000000e+000,2.620697e-003,0.000000e+000,0,,0,
1524020285.805,,0.000000e+000,5.499643e+001,-7.750816e-005,0.000000e+000,3,9.731639e-001,0.000000e+000,,,,,,,,,,,,,,32,1,4.000000e+000,6.568909e-003,0.000000e+000,0,,0,
1524020324.455,,0.000000e+000,5.500893e+001,-7.749620e-005,0.000000e+000,3,9.739136e-001,0.000000e+000,,,,,,,,,,,,,,32,1,4.000000e+000,1.316071e-002,0.000000e+000,0,,0,
1524020362.005,,0.000000e+000,5.499971e+001,-7.759522e-005,0.000000e+000,3,9.738787e-001,0.000000e+000,,,,,,,,,,,,,,32,1,4.000000e+000,2.639771e-003,0.000000e+000,0,,0,
1524020400.405,,0.000000e+000,5.499577e+001,-7.767238e-005,0.000000e+000,3,9.743649e-001,0.000000e+000,,,,,,,,,,,,,,32,1,4.000000e+000,7.888794e-003,0.000000e+000,0,,0,
1524020438.875,,0.000000e+000,5.500366e+001,-7.759215e-005,0.000000e+000,3,9.739149e-001,0.000000e+000,,,,,,,,,,,,,,32,1,4.000000e+000,5.260468e-003,0.000000e+000,0,,0,
1524020476.165,,0.000000e+000,5.499708e+001,-7.771479e-005,0.000000e+000,3,9.743257e-001,0.000000e+000,,,,,,,,,,,,,,32,1,4.000000e+000,0.000000e+000,0.000000e+000,0,,0,
1524020513.995,,0.000000e+000,5.499511e+001,-7.775093e-005,0.000000e+000,3,9.750811e-001,0.000000e+000,,,,,,,,,,,,,,32,1,4.000000e+000,6.568909e-003,0.000000e+000,0,,0,
1524020552.195,,0.000000e+000,5.499971e+001,-7.770446e-005,0.000000e+000,3,9.738659e-001,0.000000e+000,,,,,,,,,,,,,,32,1,4.000000e+000,2.639771e-003,0.000000e+000,0,,0,
1524020589.565,,0.000000e+000,5.500300e+001,-7.784034e-005,0.000000e+000,3,9.742948e-001,0.000000e+000,,,,,,,,,,,,,,32,1,4.000000e+000,9.220123e-003,0.000000e+000,0,,0,
1524020627.466,,0.000000e+000,5.499840e+001,-7.787732e-005,0.000000e+000,3,9.742341e-001,0.000000e+000,,,,,,,,,,,,,,32,1,4.000000e+000,5.260468e-003,0.000000e+000,0,,0,
1524020665.086,,0.000000e+000,5.500301e+001,-7.783241e-005,0.000000e+000,3,9.733794e-001,0.000000e+000,,,,,,,,,,,,,,32,1,4.000000e+000,2.236938e-002,0.000000e+000,0,,0,
1524020703.196,,0.000000e+000,5.499972e+001,-7.790278e-005,0.000000e+000,3,9.745514e-001,0.000000e+000,,,,,,,,,,,,,,32,1,4.000000e+000,5.268097e-003,0.000000e+000,0,,0,
1524020740.696,,0.000000e+000,5.499972e+001,-7.791939e-005,0.000000e+000,3,9.735863e-001,0.000000e+000,,,,,,,,,,,,,,32,1,4.000000e+000,5.268097e-003,0.000000e+000,0,,0,
1524020778.846,,0.000000e+000,5.500432e+001,-7.798528e-005,0.000000e+000,3,9.743712e-001,0.000000e+000,,,,,,,,,,,,,,32,1,4.000000e+000,1.300812e-003,0.000000e+000,0,,0,
1524020816.946,,0.000000e+000,5.499774e+001,-7.798123e-005,0.000000e+000,3,9.747723e-001,0.000000e+000,,,,,,,,,,,,,,32,1,4.000000e+000,6.580353e-003,0.000000e+000,0,,0,
1524020854.916,,0.000000e+000,5.500037e+001,-7.796646e-005,0.000000e+000,3,9.731831e-001,0.000000e+000,,,,,,,,,,,,,,32,1,4.000000e+000,1.319885e-003,0.000000e+000,0,,0,
1524020892.736,,0.000000e+000,5.499708e+001,-7.806931e-005,0.000000e+000,3,9.737301e-001,0.000000e+000,,,,,,,,,,,,,,32,1,4.000000e+000,2.620697e-003,0.000000e+000,0,,0,
1524020930.376,,0.000000e+000,5.499774e+001,-7.805395e-005,0.000000e+000,3,9.728751e-001,0.000000e+000,,,,,,,,,,,,,,32,1,4.000000e+000,3.940582e-003,0.000000e+000,0,,0,
1524020968.766,,0.000000e+000,5.499708e+001,-7.803673e-005,0.000000e+000,3,9.733609e-001,0.000000e+000,,,,,,,,,,,,,,32,1,4.000000e+000,0.000000e+000,0.000000e+000,0,,0,
1524021006.656,,0.000000e+000,5.500103e+001,-7.803190e-005,0.000000e+000,3,9.748251e-001,0.000000e+000,,,,,,,,,,,,,,32,1,4.000000e+000,2.639771e-003,0.000000e+000,0,,0,
1524021044.316,,0.000000e+000,5.499708e+001,-7.809888e-005,0.000000e+000,3,9.731815e-001,0.000000e+000,,,,,,,,,,,,,,32,1,4.000000e+000,2.620697e-003,0.000000e+000,0,,0,
1524021082.236,,0.000000e+000,5.500301e+001,-7.809619e-005,0.000000e+000,3,9.742321e-001,0.000000e+000,,,,,,,,,,,,,,32,1,4.000000e+000,1.319885e-003,0.000000e+000,0,,0,
1524021119.876,,0.000000e+000,5.499905e+001,-7.816698e-005,0.000000e+000,3,9.733881e-001,0.000000e+000,,,,,,,,,,,,,,32,1,4.000000e+000,1.319885e-003,0.000000e+000,0,,0,
1524021157.816,,0.000000e+000,5.499708e+001,-7.818142e-005,0.000000e+000,3,9.738837e-001,0.000000e+000,,,,,,,,,,,,,,32,1,4.000000e+000,2.620697e-003,0.000000e+000,0,,0,
1524021195.446,,0.000000e+000,5.500367e+001,-7.819901e-005,0.000000e+000,3,9.741138e-001,0.000000e+000,,,,,,,,,,,,,,32,1,4.000000e+000,0.000000e+000,0.000000e+000,0,,0,
1524021233.386,,0.000000e+000,5.499906e+001,-7.820873e-005,0.000000e+000,3,9.743300e-001,0.000000e+000,,,,,,,,,,,,,,32,1,4.000000e+000,6.580353e-003,0.000000e+000,0,,0,
1524021271.026,,0.000000e+000,5.500103e+001,-7.825038e-005,0.000000e+000,3,9.731869e-001,0.000000e+000,,,,,,,,,,,,,,32,1,4.000000e+000,2.639771e-003,0.000000e+000,0,,0,
1524021308.957,,0.000000e+000,5.500169e+001,-7.828053e-005,0.000000e+000,3,9.739751e-001,0.000000e+000,,,,,,,,,,,,,,32,1,4.000000e+000,1.319885e-003,0.000000e+000,0,,0,
1524021346.597,,0.000000e+000,5.499708e+001,-7.831704e-005,0.000000e+000,3,9.730982e-001,0.000000e+000,,,,,,,,,,,,,,32,1,4.000000e+000,2.620697e-003,0.000000e+000,0,,0,
1524021384.517,,0.000000e+000,5.499709e+001,-7.832086e-005,0.000000e+000,3,9.742749e-001,0.000000e+000,,,,,,,,,,,,,,32,1,4.000000e+000,7.888794e-003,0.000000e+000,0,,0,
1524021421.817,,0.000000e+000,5.499906e+001,-7.834105e-005,0.000000e+000,3,9.738994e-001,0.000000e+000,,,,,,,,,,,,,,32,1,4.000000e+000,6.580353e-003,0.000000e+000,0,,0,
1524021458.977,,0.000000e+000,5.500103e+001,-7.838335e-005,0.000000e+000,3,9.747159e-001,0.000000e+000,,,,,,,,,,,,,,32,1,4.000000e+000,2.639771e-003,0.000000e+000,0,,0,
1524021496.577,,0.000000e+000,5.500300e+001,-7.837726e-005,0.000000e+000,3,9.746577e-001,0.000000e+000,,,,,,,,,,,,,,32,1,4.000000e+000,3.940582e-003,0.000000e+000,0,,0,
1524021534.457,,0.000000e+000,5.499905e+001,-7.838333e-005,0.000000e+000,3,9.729065e-001,0.000000e+000,,,,,,,,,,,,,,32,1,4.000000e+000,1.319885e-003,0.000000e+000,0,,0,
1524021572.657,,0.000000e+000,5.499972e+001,-7.839703e-005,0.000000e+000,3,9.743879e-001,0.000000e+000,,,,,,,,,,,,,,32,1,4.000000e+000,5.268097e-003,0.000000e+000,0,,0,
1524021610.537,,0.000000e+000,5.499577e+001,-7.844416e-005,0.000000e+000,3,9.735514e-001,0.000000e+000,,,,,,,,,,,,,,32,1,4.000000e+000,0.000000e+000,0.000000e+000,0,,0,
1524021648.457,,0.000000e+000,5.499709e+001,-7.842489e-005,0.000000e+000,3,9.736777e-001,0.000000e+000,,,,,,,,,,,,,,32,1,4.000000e+000,1.052856e-002,0.000000e+000,0,,0,
1524021686.357,,0.000000e+000,5.500497e+001,-7.851804e-005,0.000000e+000,3,9.741777e-001,0.000000e+000,,,,,,,,,,,,,,32,1,4.000000e+000,1.316071e-002,0.000000e+000,0,,0,
1524021724.357,,0.000000e+000,5.500234e+001,-7.856471e-005,0.000000e+000,3,9.729243e-001,0.000000e+000,,,,,,,,,,,,,,32,1,4.000000e+000,7.900238e-003,0.000000e+000,0,,0,
1524021762.397,,0.000000e+000,5.499248e+001,-7.853383e-005,0.000000e+000,3,9.735689e-001,0.000000e+000,,,,,,,,,,,,,,32,1,4.000000e+000,1.182938e-002,0.000000e+000,0,,0,
1524021799.977,,0.000000e+000,5.499971e+001,-7.859973e-005,0.000000e+000,3,9.727244e-001,0.000000e+000,,,,,,,,,,,,,,32,1,4.000000e+000,0.000000e+000,0.000000e+000,0,,0,
1524021837.937,,0.000000e+000,5.499839e+001,-7.860411e-005,0.000000e+000,3,9.737108e-001,0.000000e+000,,,,,,,,,,,,,,32,1,4.000000e+000,0.000000e+000,0.000000e+000,0,,0,
1524021875.497,,0.000000e+000,5.499248e+001,-7.866941e-005,0.000000e+000,3,9.731094e-001,0.000000e+000,,,,,,,,,,,,,,32,1,4.000000e+000,3.940582e-003,0.000000e+000,0,,0,
1524021913.497,,0.000000e+000,5.499708e+001,-7.865612e-005,0.000000e+000,3,9.739496e-001,0.000000e+000,,,,,,,,,,,,,,32,1,4.000000e+000,2.620697e-003,0.000000e+000,0,,0,
1524021951.057,,0.000000e+000,5.499906e+001,-7.874241e-005,0.000000e+000,3,9.743159e-001,0.000000e+000,,,,,,,,,,,,,,32,1,4.000000e+000,6.580353e-003,0.000000e+000,0,,0,
1524021988.847,,0.000000e+000,5.499773e+001,-7.869751e-005,0.000000e+000,3,9.730158e-001,0.000000e+000,,,,,,,,,,,,,,32,1,4.000000e+000,1.308441e-003,0.000000e+000,0,,0,
1524022027.038,,0.000000e+000,5.499643e+001,-7.872099e-005,0.000000e+000,3,9.738201e-001,0.000000e+000,,,,,,,,,,,,,,32,1,4.000000e+000,1.312256e-003,0.000000e+000,0,,0,
1524022065.038,,0.000000e+000,5.499774e+001,-7.876155e-005,0.000000e+000,3,9.737070e-001,0.000000e+000,,,,,,,,,,,,,,32,1,4.000000e+000,6.580353e-003,0.000000e+000,0,,0,
1524022102.278,,0.000000e+000,5.499971e+001,-7.888561e-005,0.000000e+000,3,9.727288e-001,0.000000e+000,,,,,,,,,,,,,,32,1,4.000000e+000,2.639771e-003,0.000000e+000,0,,0,
1524022139.658,,0.000000e+000,5.500300e+001,-7.874128e-005,0.000000e+000,3,9.725531e-001,0.000000e+000,,,,,,,,,,,,,,32,1,4.000000e+000,9.220123e-003,0.000000e+000,0,,0,
1524022176.878,,0.000000e+000,5.500366e+001,-7.885463e-005,0.000000e+000,3,9.727222e-001,0.000000e+000,,,,,,,,,,,,,,32,1,4.000000e+000,5.260468e-003,0.000000e+000,0,,0,
1524022214.508,,0.000000e+000,5.499774e+001,-7.881635e-005,0.000000e+000,3,9.732826e-001,0.000000e+000,,,,,,,,,,,,,,32,1,4.000000e+000,3.940582e-003,0.000000e+000,0,,0,
1524022251.618,,0.000000e+000,5.499840e+001,-7.884495e-005,0.000000e+000,3,9.721354e-001,0.000000e+000,,,,,,,,,,,,,,32,1,4.000000e+000,5.260468e-003,0.000000e+000,0,,0,
1524022288.968,,0.000000e+000,5.500168e+001,-7.891654e-005,0.000000e+000,3,9.731337e-001,0.000000e+000,,,,,,,,,,,,,,32,1,4.000000e+000,6.580353e-003,0.000000e+000,0,,0,
1524022326.698,,0.000000e+000,5.500234e+001,-7.886513e-005,0.000000e+000,3,9.722080e-001,0.000000e+000,,,,,,,,,,,,,,32,1,4.000000e+000,7.900238e-003,0.000000e+000,0,,0,
1524022364.538,,0.000000e+000,5.500103e+001,-7.894125e-005,0.000000e+000,3,9.733491e-001,0.000000e+000,,,,,,,,,,,,,,32,1,4.000000e+000,2.639771e-003,0.000000e+000,0,,0,
1524022401.868,,0.000000e+000,5.499839e+001,-7.886379e-005,0.000000e+000,3,9.729999e-001,0.000000e+000,,,,,,,,,,,,,,32,1,4.000000e+000,0.000000e+000,0.000000e+000,0,,0,
1524022440.188,,0.000000e+000,5.499379e+001,-7.902182e-005,0.000000e+000,3,9.732572e-001,0.000000e+000,,,,,,,,,,,,,,32,1,4.000000e+000,9.201050e-003,0.000000e+000,0,,0,
1524022477.998,,0.000000e+000,5.499774e+001,-7.901747e-005,0.000000e+000,3,9.723818e-001,0.000000e+000,,,,,,,,,,,,,,32,1,4.000000e+000,3.940582e-003,0.000000e+000,0,,0,
1524022515.918,,0.000000e+000,5.500037e+001,-7.899674e-005,0.000000e+000,3,9.737345e-001,0.000000e+000,,,,,,,,,,,,,,32,1,4.000000e+000,3.959656e-003,0.000000e+000,0,,0,
1524022553.858,,0.000000e+000,5.500234e+001,-7.906066e-005,0.000000e+000,3,9.740885e-001,0.000000e+000,,,,,,,,,,,,,,32,1,4.000000e+000,5.260468e-003,0.000000e+000,0,,0,
1524022592.298,,0.000000e+000,5.499774e+001,-7.900949e-005,0.000000e+000,3,9.726356e-001,0.000000e+000,,,,,,,,,,,,,,32,1,4.000000e+000,3.940582e-003,0.000000e+000,0,,0,
1524022630.378,,0.000000e+000,5.499709e+001,-7.909590e-005,0.000000e+000,3,9.734098e-001,0.000000e+000,,,,,,,,,,,,,,32,1,4.000000e+000,1.052856e-002,0.000000e+000,0,,0,
1524022668.218,,0.000000e+000,5.499709e+001,-7.911513e-005,0.000000e+000,3,9.741721e-001,0.000000e+000,,,,,,,,,,,,,,32,1,4.000000e+000,1.840973e-002,0.000000e+000,0,,0,
1524022705.038,,0.000000e+000,5.499905e+001,-7.914782e-005,0.000000e+000,3,9.741465e-001,0.000000e+000,,,,,,,,,,,,,,32,1,4.000000e+000,1.319885e-003,0.000000e+000,0,,0,
1524022742.539,,0.000000e+000,5.500432e+001,-7.910008e-005,0.000000e+000,3,9.726065e-001,0.000000e+000,,,,,,,,,,,,,,32,1,4.000000e+000,6.580353e-003,0.000000e+000,0,,0,
1524022780.369,,0.000000e+000,5.500037e+001,-7.914245e-005,0.000000e+000,3,9.734918e-001,0.000000e+000,,,,,,,,,,,,,,32,1,4.000000e+000,6.587982e-003,0.000000e+000,0,,0,
1524022817.969,,0.000000e+000,5.500037e+001,-7.918642e-005,0.000000e+000,3,9.733698e-001,0.000000e+000,,,,,,,,,,,,,,32,1,4.000000e+000,6.587982e-003,0.000000e+000,0,,0,
1524022855.119,,0.000000e+000,5.499445e+001,-7.917771e-005,0.000000e+000,3,9.734038e-001,0.000000e+000,,,,,,,,,,,,,,32,1,4.000000e+000,1.052094e-002,0.000000e+000,0,,0,
1524022893.409,,0.000000e+000,5.500301e+001,-7.924998e-005,0.000000e+000,3,9.739127e-001,0.000000e+000,,,,,,,,,,,,,,32,1,4.000000e+000,1.319885e-003,0.000000e+000,0,,0,
1524022931.519,,0.000000e+000,5.500037e+001,-7.926505e-005,0.000000e+000,3,9.735063e-001,0.000000e+000,,,,,,,,,,,,,,32,1,4.000000e+000,9.201050e-003,0.000000e+000,0,,0,
1524022968.999,,0.000000e+000,5.499905e+001,-7.923794e-005,0.000000e+000,3,9.736077e-001,0.000000e+000,,,,,,,,,,,,,,32,1,4.000000e+000,3.948212e-003,0.000000e+000,0,,0,
1524023006.819,,0.000000e+000,5.500300e+001,-7.935245e-005,0.000000e+000,3,9.747283e-001,0.000000e+000,,,,,,,,,,,,,,32,1,4.000000e+000,3.940582e-003,0.000000e+000,0,,0,
1524023044.579,,0.000000e+000,5.500103e+001,-7.930824e-005,0.000000e+000,3,9.736635e-001,0.000000e+000,,,,,,,,,,,,,,32,1,4.000000e+000,7.888794e-003,0.000000e+000,0,,0,
1524023082.539,,0.000000e+000,5.499840e+001,-7.940637e-005,0.000000e+000,3,9.734398e-001,0.000000e+000,,,,,,,,,,,,,,32,1,4.000000e+000,5.260468e-003,0.000000e+000,0,,0,
1524023120.959,,0.000000e+000,5.499839e+001,-7.934577e-005,0.000000e+000,3,9.722209e-001,0.000000e+000,,,,,,,,,,,,,,32,1,4.000000e+000,0.000000e+000,0.000000e+000,0,,0,
1524023158.499,,0.000000e+000,5.499905e+001,-7.937774e-005,0.000000e+000,3,9.742529e-001,0.000000e+000,,,,,,,,,,,,,,32,1,4.000000e+000,1.319885e-003,0.000000e+000,0,,0,
1524023196.219,,0.000000e+000,5.499642e+001,-7.948493e-005,0.000000e+000,3,9.741417e-001,0.000000e+000,,,,,,,,,,,,,,32,1,4.000000e+000,3.940582e-003,0.000000e+000,0,,0,
1524023233.469,,0.000000e+000,5.500629e+001,-7.938703e-005,0.000000e+000,3,9.729168e-001,0.000000e+000,,,,,,,,,,,,,,32,1,4.000000e+000,5.249023e-003,0.000000e+000,0,,0,
1524023271.199,,0.000000e+000,5.500300e+001,-7.940983e-005,0.000000e+000,3,9.737820e-001,0.000000e+000,,,,,,,,,,,,,,32,1,4.000000e+000,9.220123e-003,0.000000e+000,0,,0,
1524023308.709,,0.000000e+000,5.499774e+001,-7.944979e-005,0.000000e+000,3,9.723830e-001,0.000000e+000,,,,,,,,,,,,,,32,1,4.000000e+000,1.446152e-002,0.000000e+000,0,,0,
1524023345.939,,0.000000e+000,5.499708e+001,-7.955190e-005,0.000000e+000,3,9.734950e-001,0.000000e+000,,,,,,,,,,,,,,32,1,4.000000e+000,5.260468e-003,0.000000e+000,0,,0,
1524023383.569,,0.000000e+000,5.499839e+001,-7.946601e-005,0.000000e+000,3,9.733403e-001,0.000000e+000,,,,,,,,,,,,,,32,1,4.000000e+000,0.000000e+000,0.000000e+000,0,,0,
1524023422.689,,0.000000e+000,5.499445e+001,-7.951276e-005,0.000000e+000,3,9.734451e-001,0.000000e+000,,,,,,,,,,,,,,32,1,4.000000e+000,0.000000e+000,0.000000e+000,0,,0,
1524023460.510,,0.000000e+000,5.499905e+001,-7.953237e-005,0.000000e+000,3,9.721915e-001,0.000000e+000,,,,,,,,,,,,,,32,1,4.000000e+000,3.948212e-003,0.000000e+000,0,,0,
1524023497.880,,0.000000e+000,5.499642e+001,-7.948990e-005,0.000000e+000,3,9.732707e-001,0.000000e+000,,,,,,,,,,,,,,32,1,4.000000e+000,3.940582e-003,0.000000e+000,0,,0,
1524023535.230,,0.000000e+000,5.499512e+001,-7.956586e-005,0.000000e+000,3,9.727780e-001,0.000000e+000,,,,,,,,,,,,,,32,1,4.000000e+000,1.710892e-002,0.000000e+000,0,,0,
1524023572.720,,0.000000e+000,5.499971e+001,-7.952895e-005,0.000000e+000,3,9.733672e-001,0.000000e+000,,,,,,,,,,,,,,32,1,4.000000e+000,2.639771e-003,0.000000e+000,0,,0,
1524023609.990,,0.000000e+000,5.500498e+001,-7.958515e-005,0.000000e+000,3,9.731007e-001,0.000000e+000,,,,,,,,,,,,,,32,1,4.000000e+000,5.260468e-003,0.000000e+000,0,,0,
1524023647.960,,0.000000e+000,5.500234e+001,-7.958013e-005,0.000000e+000,3,9.732482e-001,0.000000e+000,,,,,,,,,,,,,,32,1,4.000000e+000,7.900238e-003,0.000000e+000,0,,0,
1524023684.860,,0.000000e+000,5.499905e+001,-7.960724e-005,0.000000e+000,3,9.725671e-001,0.000000e+000,,,,,,,,,,,,,,32,1,4.000000e+000,3.948212e-003,0.000000e+000,0,,0,
1524023722.980,,0.000000e+000,5.499577e+001,-7.960044e-005,0.000000e+000,3,9.736506e-001,0.000000e+000,,,,,,,,,,,,,,32,1,4.000000e+000,2.632141e-003,0.000000e+000,0,,0,
1524023760.330,,0.000000e+000,5.499642e+001,-7.962817e-005,0.000000e+000,3,9.733472e-001,0.000000e+000,,,,,,,,,,,,,,32,1,4.000000e+000,3.940582e-003,0.000000e+000,0,,0,
1524023798.260,,0.000000e+000,5.500037e+001,-7.965670e-005,0.000000e+000,3,9.736310e-001,0.000000e+000,,,,,,,,,,,,,,32,1,4.000000e+000,9.201050e-003,0.000000e+000,0,,0,
1524023835.660,,0.000000e+000,5.500235e+001,-7.959224e-005,0.000000e+000,3,9.728841e-001,0.000000e+000,,,,,,,,,,,,,,32,1,4.000000e+000,1.052856e-002,0.000000e+000,0,,0,
1524023873.700,,0.000000e+000,5.500563e+001,-7.964176e-005,0.000000e+000,3,9.739893e-001,0.000000e+000,,,,,,,,,,,,,,32,1,4.000000e+000,1.184082e-002,0.000000e+000,0,,0,
1524023911.220,,0.000000e+000,5.499511e+001,-7.971428e-005,0.000000e+000,3,9.719978e-001,0.000000e+000,,,,,,,,,,,,,,32,1,4.000000e+000,1.184082e-002,0.000000e+000,0,,0,
1524023949.530,,0.000000e+000,5.499445e+001,-7.980221e-005,0.000000e+000,3,9.729643e-001,0.000000e+000,,,,,,,,,,,,,,32,1,4.000000e+000,0.000000e+000,0.000000e+000,0,,0,
1524023988.220,,0.000000e+000,5.499840e+001,-7.977910e-005,0.000000e+000,3,9.729664e-001,0.000000e+000,,,,,,,,,,,,,,32,1,4.000000e+000,5.260468e-003,0.000000e+000,0,,0,
1524024025.610,,0.000000e+000,5.500234e+001,-7.981664e-005,0.000000e+000,3,9.740402e-001,0.000000e+000,,,,,,,,,,,,,,32,1,4.000000e+000,7.900238e-003,0.000000e+000,0,,0,
1524024062.610,,0.000000e+000,5.499775e+001,-7.978845e-005,0.000000e+000,3,9.743073e-001,0.000000e+000,,,,,,,,,,,,,,32,1,4.000000e+000,1.184845e-002,0.000000e+000,0,,0,
1524024099.830,,0.000000e+000,5.499577e+001,-7.983016e-005,0.000000e+000,3,9.730868e-001,0.000000e+000,,,,,,,,,,,,,,32,1,4.000000e+000,5.249023e-003,0.000000e+000,0,,0,
1524024138.100,,0.000000e+000,5.499642e+001,-7.986977e-005,0.000000e+000,3,9.725715e-001,0.000000e+000,,,,,,,,,,,,,,32,1,4.000000e+000,3.940582e-003,0.000000e+000,0,,0,
1524024175.461,,0.000000e+000,5.500300e+001,-7.986233e-005,0.000000e+000,3,9.724199e-001,0.000000e+000,,,,,,,,,,,,,,32,1,4.000000e+000,1.183701e-002,0.000000e+000,0,,0,
1524024213.661,,0.000000e+000,5.499906e+001,-7.988271e-005,0.000000e+000,3,9.728464e-001,0.000000e+000,,,,,,,,,,,,,,32,1,4.000000e+000,6.580353e-003,0.000000e+000,0,,0,
1524024250.961,,0.000000e+000,5.499905e+001,-7.985270e-005,0.000000e+000,3,9.728710e-001,0.000000e+000,,,,,,,,,,,,,,32,1,4.000000e+000,1.319885e-003,0.000000e+000,0,,0,
1524024288.321,,0.000000e+000,5.500103e+001,-7.995275e-005,0.000000e+000,3,9.730771e-001,0.000000e+000,,,,,,,,,,,,,,32,1,4.000000e+000,2.639771e-003,0.000000e+000,0,,0,
1524024326.001,,0.000000e+000,5.499971e+001,-7.990660e-005,0.000000e+000,3,9.728791e-001,0.000000e+000,,,,,,,,,,,,,,32,1,4.000000e+000,2.639771e-003,0.000000e+000,0,,0,
1524024363.421,,0.000000e+000,5.499709e+001,-7.995123e-005,0.000000e+000,3,9.724211e-001,0.000000e+000,,,,,,,,,,,,,,32,1,4.000000e+000,1.052856e-002,0.000000e+000,0,,0,
1524024400.461,,0.000000e+000,5.499774e+001,-7.997603e-005,0.000000e+000,3,9.736736e-001,0.000000e+000,,,,,,,,,,,,,,32,1,4.000000e+000,3.940582e-003,0.000000e+000,0,,0,
1524024438.451,,0.000000e+000,5.499972e+001,-7.999760e-005,0.000000e+000,3,9.733701e-001,0.000000e+000,,,,,,,,,,,,,,32,1,4.000000e+000,7.900238e-003,0.000000e+000,0,,0,
1524024476.501,,0.000000e+000,5.499841e+001,-7.996435e-005,0.000000e+000,3,9.724080e-001,0.000000e+000,,,,,,,,,,,,,,32,1,4.000000e+000,1.052856e-002,0.000000e+000,0,,0,
1524024514.711,,0.000000e+000,5.499445e+001,-8.000722e-005,0.000000e+000,3,9.742038e-001,0.000000e+000,,,,,,,,,,,,,,32,1,4.000000e+000,5.260468e-003,0.000000e+000,0,,0,
1524024552.041,,0.000000e+000,5.499313e+001,-8.008858e-005,0.000000e+000,3,9.722902e-001,0.000000e+000,,,,,,,,,,,,,,32,1,4.000000e+000,1.050949e-002,0.000000e+000,0,,0,
1524024589.981,,0.000000e+000,5.499972e+001,-8.006148e-005,0.000000e+000,3,9.734631e-001,0.000000e+000,,,,,,,,,,,,,,32,1,4.000000e+000,7.900238e-003,0.000000e+000,0,,0,
1524024627.571,,0.000000e+000,5.499906e+001,-8.003206e-005,0.000000e+000,3,9.728088e-001,0.000000e+000,,,,,,,,,,,,,,32,1,4.000000e+000,6.580353e-003,0.000000e+000,0,,0,
1524024665.611,,0.000000e+000,5.499905e+001,-8.012085e-005,0.000000e+000,3,9.736439e-001,0.000000e+000,,,,,,,,,,,,,,32,1,4.000000e+000,3.948212e-003,0.000000e+000,0,,0,
1524024703.001,,0.000000e+000,5.500235e+001,-8.008285e-005,0.000000e+000,3,9.732121e-001,0.000000e+000,,,,,,,,,,,,,,32,1,4.000000e+000,2.639771e-003,0.000000e+000,0,,0,
1524024740.611,,0.000000e+000,5.499773e+001,-8.010948e-005,0.000000e+000,3,9.735259e-001,0.000000e+000,,,,,,,,,,,,,,32,1,4.000000e+000,1.308441e-003,0.000000e+000,0,,0,
1524024778.291,,0.000000e+000,5.500037e+001,-8.016206e-005,0.000000e+000,3,9.725090e-001,0.000000e+000,,,,,,,,,,,,,,32,1,4.000000e+000,3.959656e-003,0.000000e+000,0,,0,
1524024816.191,,0.000000e+000,5.499971e+001,-8.011853e-005,0.000000e+000,3,9.736105e-001,0.000000e+000,,,,,,,,,,,,,,32,1,4.000000e+000,0.000000e+000,0.000000e+000,0,,0,
1524024853.831,,0.000000e+000,5.499972e+001,-8.015301e-005,0.000000e+000,3,9.723546e-001,0.000000e+000,,,,,,,,,,,,,,32,1,4.000000e+000,5.268097e-003,0.000000e+000,0,,0,
1524024892.152,,0.000000e+000,5.500103e+001,-8.014426e-005,0.000000e+000,3,9.733661e-001,0.000000e+000,,,,,,,,,,,,,,32,1,4.000000e+000,2.639771e-003,0.000000e+000,0,,0,
1524024929.832,,0.000000e+000,5.499577e+001,-8.021882e-005,0.000000e+000,3,9.740117e-001,0.000000e+000,,,,,,,,,,,,,,32,1,4.000000e+000,7.888794e-003,0.000000e+000,0,,0,
1524024967.722,,0.000000e+000,5.500037e+001,-8.023719e-005,0.000000e+000,3,9.721245e-001,0.000000e+000,,,,,,,,,,,,,,32,1,4.000000e+000,1.319885e-003,0.000000e+000,0,,0,
1524025005.692,,0.000000e+000,5.499905e+001,-8.022760e-005,0.000000e+000,3,9.735161e-001,0.000000e+000,,,,,,,,,,,,,,32,1,4.000000e+000,1.182938e-002,0.000000e+000,0,,0,
1524025043.132,,0.000000e+000,5.499643e+001,-8.019433e-005,0.000000e+000,3,9.742992e-001,0.000000e+000,,,,,,,,,,,,,,32,1,4.000000e+000,1.184082e-002,0.000000e+000,0,,0,
1524025080.592,,0.000000e+000,5.499773e+001,-8.023890e-005,0.000000e+000,3,9.734101e-001,0.000000e+000,,,,,,,,,,,,,,32,1,4.000000e+000,1.308441e-003,0.000000e+000,0,,0,
1524025117.902,,0.000000e+000,5.499905e+001,-8.035218e-005,0.000000e+000,3,9.743286e-001,0.000000e+000,,,,,,,,,,,,,,32,1,4.000000e+000,3.948212e-003,0.000000e+000,0,,0,
1524025155.732,,0.000000e+000,5.500103e+001,-8.026883e-005,0.000000e+000,3,9.729446e-001,0.000000e+000,,,,,,,,,,,,,,32,1,4.000000e+000,0.000000e+000,0.000000e+000,0,,0,
1524025193.062,,0.000000e+000,5.499708e+001,-8.036363e-005,0.000000e+000,3,9.743319e-001,0.000000e+000,,,,,,,,,,,,,,32,1,4.000000e+000,2.620697e-003,0.000000e+000,0,,0,
1524025230.282,,0.000000e+000,5.499511e+001,-8.036100e-005,0.000000e+000,3,9.733571e-001,0.000000e+000,,,,,,,,,,,,,,32,1,4.000000e+000,1.319885e-003,0.000000e+000,0,,0,
1524025267.842,,0.000000e+000,5.499905e+001,-8.030930e-005,0.000000e+000,3,9.734167e-001,0.000000e+000,,,,,,,,,,,,,,32,1,4.000000e+000,1.319885e-003,0.000000e+000,0,,0,
1524025305.812,,0.000000e+000,5.499840e+001,-8.038104e-005,0.000000e+000,3,9.733276e-001,0.000000e+000,,,,,,,,,,,,,,32,1,4.000000e+000,2.628326e-003,0.000000e+000,0,,0,
1524025343.382,,0.000000e+000,5.499971e+001,-8.037815e-005,0.000000e+000,3,9.733060e-001,0.000000e+000,,,,,,,,,,,,,,32,1,4.000000e+000,1.052094e-002,0.000000e+000,0,,0,
1524025381.372,,0.000000e+000,5.500037e+001,-8.039837e-005,0.000000e+000,3,9.735436e-001,0.000000e+000,,,,,,,,,,,,,,32,1,4.000000e+000,1.319885e-003,0.000000e+000,0,,0,
1524025419.002,,0.000000e+000,5.499708e+001,-8.034633e-005,0.000000e+000,3,9.730533e-001,0.000000e+000,,,,,,,,,,,,,,32,1,4.000000e+000,0.000000e+000,0.000000e+000,0,,0,
1524025456.982,,0.000000e+000,5.500366e+001,-8.040864e-005,0.000000e+000,3,9.732741e-001,0.000000e+000,,,,,,,,,,,,,,32,1,4.000000e+000,5.260468e-003,0.000000e+000,0,,0,
1524025494.582,,0.000000e+000,5.500235e+001,-8.042168e-005,0.000000e+000,3,9.731821e-001,0.000000e+000,,,,,,,,,,,,,,32,1,4.000000e+000,2.639771e-003,0.000000e+000,0,,0,
1524025532.532,,0.000000e+000,5.499643e+001,-8.053434e-005,0.000000e+000,3,9.727162e-001,0.000000e+000,,,,,,,,,,,,,,32,1,4.000000e+000,6.568909e-003,0.000000e+000,0,,0,
1524025570.202,,0.000000e+000,5.499905e+001,-8.049478e-005,0.000000e+000,3,9.723581e-001,0.000000e+000,,,,,,,,,,,,,,32,1,4.000000e+000,1.319885e-003,0.000000e+000,0,,0,
1524025608.143,,0.000000e+000,5.500235e+001,-8.045185e-005,0.000000e+000,3,9.735607e-001,0.000000e+000,,,,,,,,,,,,,,32,1,4.000000e+000,0.000000e+000,0.000000e+000,0,,0,
1524025645.763,,0.000000e+000,5.499905e+001,-8.053992e-005,0.000000e+000,3,9.725329e-001,0.000000e+000,,,,,,,,,,,,,,32,1,4.000000e+000,1.319885e-003,0.000000e+000,0,,0,
1524025683.513,,0.000000e+000,5.499971e+001,-8.051273e-005,0.000000e+000,3,9.743139e-001,0.000000e+000,,,,,,,,,,,,,,32,1,4.000000e+000,2.639771e-003,0.000000e+000,0,,0,
1524025720.823,,0.000000e+000,5.499905e+001,-8.055927e-005,0.000000e+000,3,9.727658e-001,0.000000e+000,,,,,,,,,,,,,,32,1,4.000000e+000,1.319885e-003,0.000000e+000,0,,0,
1524025758.433,,0.000000e+000,5.499905e+001,-8.058702e-005,0.000000e+000,3,9.732670e-001,0.000000e+000,,,,,,,,,,,,,,32,1,4.000000e+000,3.948212e-003,0.000000e+000,0,,0,
1524025795.643,,0.000000e+000,5.500103e+001,-8.055704e-005,0.000000e+000,3,9.726274e-001,0.000000e+000,,,,,,,,,,,,,,32,1,4.000000e+000,0.000000e+000,0.000000e+000,0,,0,
1524025833.973,,0.000000e+000,5.500695e+001,-8.057242e-005,0.000000e+000,3,9.734341e-001,0.000000e+000,,,,,,,,,,,,,,32,1,4.000000e+000,1.184082e-002,0.000000e+000,0,,0,
1524025871.853,,0.000000e+000,5.499840e+001,-8.056621e-005,0.000000e+000,3,9.732078e-001,0.000000e+000,,,,,,,,,,,,,,32,1,4.000000e+000,2.628326e-003,0.000000e+000,0,,0,
1524025909.373,,0.000000e+000,5.499511e+001,-8.062165e-005,0.000000e+000,3,9.732510e-001,0.000000e+000,,,,,,,,,,,,,,32,1,4.000000e+000,6.568909e-003,0.000000e+000,0,,0,
1524025947.033,,0.000000e+000,5.499971e+001,-8.064127e-005,0.000000e+000,3,9.728015e-001,0.000000e+000,,,,,,,,,,,,,,32,1,4.000000e+000,0.000000e+000,0.000000e+000,0,,0,
1524025984.963,,0.000000e+000,5.499839e+001,-8.060195e-005,0.000000e+000,3,9.735017e-001,0.000000e+000,,,,,,,,,,,,,,32,1,4.000000e+000,0.000000e+000,0.000000e+000,0,,0,
1524026022.613,,0.000000e+000,5.500037e+001,-8.064170e-005,0.000000e+000,3,9.728222e-001,0.000000e+000,,,,,,,,,,,,,,32,1,4.000000e+000,1.319885e-003,0.000000e+000,0,,0,
1524026060.533,,0.000000e+000,5.499840e+001,-8.065843e-005,0.000000e+000,3,9.738542e-001,0.000000e+000,,,,,,,,,,,,,,32,1,4.000000e+000,2.628326e-003,0.000000e+000,0,,0,
1524026098.183,,0.000000e+000,5.499774e+001,-8.066216e-005,0.000000e+000,3,9.727277e-001,0.000000e+000,,,,,,,,,,,,,,32,1,4.000000e+000,3.940582e-003,0.000000e+000,0,,0,
1524026136.113,,0.000000e+000,5.499971e+001,-8.065181e-005,0.000000e+000,3,9.738148e-001,0.000000e+000,,,,,,,,,,,,,,32,1,4.000000e+000,2.639771e-003,0.000000e+000,0,,0,
1524026173.953,,0.000000e+000,5.499577e+001,-8.072024e-005,0.000000e+000,3,9.746497e-001,0.000000e+000,,,,,,,,,,,,,,32,1,4.000000e+000,5.249023e-003,0.000000e+000,0,,0,
1524026212.533,,0.000000e+000,5.500169e+001,-8.065868e-005,0.000000e+000,3,9.735268e-001,0.000000e+000,,,,,,,,,,,,,,32,1,4.000000e+000,1.319885e-003,0.000000e+000,0,,0,
1524026250.473,,0.000000e+000,5.499774e+001,-8.074536e-005,0.000000e+000,3,9.743195e-001,0.000000e+000,,,,,,,,,,,,,,32,1,4.000000e+000,6.580353e-003,0.000000e+000,0,,0,
1524026288.503,,0.000000e+000,5.500037e+001,-8.083320e-005,0.000000e+000,3,9.749721e-001,0.000000e+000,,,,,,,,,,,,,,32,1,4.000000e+000,9.201050e-003,0.000000e+000,0,,0,
1524026326.604,,0.000000e+000,5.499906e+001,-8.078871e-005,0.000000e+000,3,9.727706e-001,0.000000e+000,,,,,,,,,,,,,,32,1,4.000000e+000,6.580353e-003,0.000000e+000,0,,0,
1524026364.294,,0.000000e+000,5.500431e+001,-8.080997e-005,0.000000e+000,3,9.737166e-001,0.000000e+000,,,,,,,,,,,,,,32,1,4.000000e+000,9.208679e-003,0.000000e+000,0,,0,
1524026401.484,,0.000000e+000,5.500300e+001,-8.077566e-005,0.000000e+000,3,9.729338e-001,0.000000e+000,,,,,,,,,,,,,,32,1,4.000000e+000,3.940582e-003,0.000000e+000,0,,0,
1524026439.674,,0.000000e+000,5.500234e+001,-8.085433e-005,0.000000e+000,3,9.734015e-001,0.000000e+000,,,,,,,,,,,,,,32,1,4.000000e+000,7.900238e-003,0.000000e+000,0,,0,
1524026477.134,,0.000000e+000,5.499774e+001,-8.084564e-005,0.000000e+000,3,9.740409e-001,0.000000e+000,,,,,,,,,,,,,,32,1,4.000000e+000,3.940582e-003,0.000000e+000,0,,0,
1524026489.894,,0.000000e+000,5.499708e+001,-8.081965e-005,0.000000e+000,3,9.729618e-001,0.000000e+000,,,,,,,,,,,,,,32,1,4.000000e+000,5.260468e-003,0.000000e+000,0,,0,