File: Experimental Raw Data/TC04-12-01K Acquisition/TC04-12-01K_VRMac_53K_12000s.dc.dat
[Header]
TITLE,MPMS DC Measurement
BYAPP,MPMS Measurement,2.1,Summary
FILEOPENTIME, 1524121653.160000 4/19/2018, 1:07:33 AM

INFO, APPNAME, MPMS MultiVu Application, Revision 1.61,  Build 082

INFO, NAME, TC04-12-01K
INFO, WEIGHT, 1.000
INFO, AREA, 1.000
INFO, LENGTH, 1.000
INFO, SHAPE, 0
INFO, COMMENT,
INFO, SEQUENCE FILE: VRMac_53K_12000s_VRMde_55K.seq


INFO, BACKGROUND DATA FILE:, None


STARTUPAXIS,X,4,LINEAR,AUTO,0.000000,0.000000
STARTUPAXIS,Y1,5,LINEAR,AUTO,0.000000,0.000000


STARTUPGROUP,Longitudinal
FIELDGROUP,Longitudinal,1,2,3,4,5,6,7,8,9,15,16,17,18,27,28
FIELDGROUP,Transverse,1,2,3,4,10,11,12,13,14,19,20,21,22,27,28

PLOT_APPEARANCE,ALL,HORZ_GRID_ON,VERT_GRID_ON,MARKERS_AND_LINES

[Data]
Time,Comment,Field (Oe),Temperature (K),Long Moment (emu),Long Scan Std Dev,Long Algorithm,Long Reg Fit,Long Percent Error (%),Trans Moment (emu),Trans Scan Std Dev,Trans Algorithm,Trans Reg Fit,Trans Percent Error (%),Long Moment [w/o ABS] (emu),Long Scan Std Dev [w/o ABS],Long Reg Fit [w/o ABS],Long Percent Error [w/o ABS] (%),Trans Moment [w/o ABS] (emu),Trans Scan Std Dev [w/o ABS],Trans Reg Fit [w/o ABS],Trans Percent Error [w/o ABS] (%),Points per Scan,Scans per Measurement,Scan Length (cm),Delta Temp (K),Rot Position (deg),Error,EC Comp. Running,Using ABS,
1524121653.160,,0.000000e+000,5.303551e+001,-5.143111e-005,0.000000e+000,3,9.713011e-001,0.000000e+000,,,,,,,,,,,,,,32,1,4.000000e+000,2.342987e-002,0.000000e+000,0,,0,
1524121691.110,,0.000000e+000,5.301333e+001,-5.645576e-005,0.000000e+000,3,9.713199e-001,0.000000e+000,,,,,,,,,,,,,,32,1,4.000000e+000,6.160736e-003,0.000000e+000,0,,0,
1524121728.740,,0.000000e+000,5.300716e+001,-5.856040e-005,0.000000e+000,3,9.720636e-001,0.000000e+000,,,,,,,,,,,,,,32,1,4.000000e+000,6.168365e-003,0.000000e+000,0,,0,
1524121766.200,,0.000000e+000,5.300655e+001,-5.996878e-005,0.000000e+000,3,9.713143e-001,0.000000e+000,,,,,,,,,,,,,,32,1,4.000000e+000,4.940033e-003,0.000000e+000,0,,0,
1524121804.610,,0.000000e+000,5.300040e+001,-6.109336e-005,0.000000e+000,3,9.739205e-001,0.000000e+000,,,,,,,,,,,,,,32,1,4.000000e+000,2.468109e-003,0.000000e+000,0,,0,
1524121841.650,,0.000000e+000,5.300224e+001,-6.185840e-005,0.000000e+000,3,9.734617e-001,0.000000e+000,,,,,,,,,,,,,,32,1,4.000000e+000,3.681183e-003,0.000000e+000,0,,0,
1524121879.580,,0.000000e+000,5.300163e+001,-6.255272e-005,0.000000e+000,3,9.734504e-001,0.000000e+000,,,,,,,,,,,,,,32,1,4.000000e+000,0.000000e+000,0.000000e+000,0,,0,
1524121916.830,,0.000000e+000,5.299916e+001,-6.318164e-005,0.000000e+000,3,9.735482e-001,0.000000e+000,,,,,,,,,,,,,,32,1,4.000000e+000,2.471924e-003,0.000000e+000,0,,0,
1524121954.540,,0.000000e+000,5.300224e+001,-6.365274e-005,0.000000e+000,3,9.735231e-001,0.000000e+000,,,,,,,,,,,,,,32,1,4.000000e+000,8.621216e-003,0.000000e+000,0,,0,
1524121991.601,,0.000000e+000,5.299854e+001,-6.415459e-005,0.000000e+000,3,9.734232e-001,0.000000e+000,,,,,,,,,,,,,,32,1,4.000000e+000,1.232147e-003,0.000000e+000,0,,0,
1524122029.531,,0.000000e+000,5.299978e+001,-6.452153e-005,0.000000e+000,3,9.729817e-001,0.000000e+000,,,,,,,,,,,,,,32,1,4.000000e+000,1.239777e-003,0.000000e+000,0,,0,
1524122066.521,,0.000000e+000,5.299732e+001,-6.495852e-005,0.000000e+000,3,9.736913e-001,0.000000e+000,,,,,,,,,,,,,,32,1,4.000000e+000,3.681183e-003,0.000000e+000,0,,0,
1524122104.701,,0.000000e+000,5.299301e+001,-6.524068e-005,0.000000e+000,3,9.743537e-001,0.000000e+000,,,,,,,,,,,,,,32,1,4.000000e+000,9.838104e-003,0.000000e+000,0,,0,
1524122142.011,,0.000000e+000,5.299732e+001,-6.557683e-005,0.000000e+000,3,9.735017e-001,0.000000e+000,,,,,,,,,,,,,,32,1,4.000000e+000,3.681183e-003,0.000000e+000,0,,0,
1524122179.331,,0.000000e+000,5.299547e+001,-6.582373e-005,0.000000e+000,3,9.729915e-001,0.000000e+000,,,,,,,,,,,,,,32,1,4.000000e+000,7.381439e-003,0.000000e+000,0,,0,
1524122216.471,,0.000000e+000,5.300040e+001,-6.611111e-005,0.000000e+000,3,9.732560e-001,0.000000e+000,,,,,,,,,,,,,,32,1,4.000000e+000,2.468109e-003,0.000000e+000,0,,0,
1524122254.891,,0.000000e+000,5.299670e+001,-6.634939e-005,0.000000e+000,3,9.714482e-001,0.000000e+000,,,,,,,,,,,,,,32,1,4.000000e+000,0.000000e+000,0.000000e+000,0,,0,
1524122293.781,,0.000000e+000,5.300040e+001,-6.657689e-005,0.000000e+000,3,9.734336e-001,0.000000e+000,,,,,,,,,,,,,,32,1,4.000000e+000,1.231003e-002,0.000000e+000,0,,0,
1524122331.751,,0.000000e+000,5.299670e+001,-6.691581e-005,0.000000e+000,3,9.730223e-001,0.000000e+000,,,,,,,,,,,,,,32,1,4.000000e+000,4.920959e-003,0.000000e+000,0,,0,
1524122369.491,,0.000000e+000,5.299916e+001,-6.701842e-005,0.000000e+000,3,9.725811e-001,0.000000e+000,,,,,,,,,,,,,,32,1,4.000000e+000,2.471924e-003,0.000000e+000,0,,0,
1524122407.651,,0.000000e+000,5.299609e+001,-6.725842e-005,0.000000e+000,3,9.729930e-001,0.000000e+000,,,,,,,,,,,,,,32,1,4.000000e+000,1.220703e-003,0.000000e+000,0,,0,
1524122445.121,,0.000000e+000,5.299609e+001,-6.746429e-005,0.000000e+000,3,9.722782e-001,0.000000e+000,,,,,,,,,,,,,,32,1,4.000000e+000,6.149292e-003,0.000000e+000,0,,0,
1524122482.621,,0.000000e+000,5.299486e+001,-6.762019e-005,0.000000e+000,3,9.734877e-001,0.000000e+000,,,,,,,,,,,,,,32,1,4.000000e+000,8.609772e-003,0.000000e+000,0,,0,
1524122520.201,,0.000000e+000,5.299855e+001,-6.776978e-005,0.000000e+000,3,9.724188e-001,0.000000e+000,,,,,,,,,,,,,,32,1,4.000000e+000,6.149292e-003,0.000000e+000,0,,0,
1524122557.561,,0.000000e+000,5.299916e+001,-6.797477e-005,0.000000e+000,3,9.732838e-001,0.000000e+000,,,,,,,,,,,,,,32,1,4.000000e+000,0.000000e+000,0.000000e+000,0,,0,
1524122595.021,,0.000000e+000,5.299670e+001,-6.814158e-005,0.000000e+000,3,9.727222e-001,0.000000e+000,,,,,,,,,,,,,,32,1,4.000000e+000,0.000000e+000,0.000000e+000,0,,0,
1524122633.641,,0.000000e+000,5.299301e+001,-6.833256e-005,0.000000e+000,3,9.730956e-001,0.000000e+000,,,,,,,,,,,,,,32,1,4.000000e+000,2.460480e-003,0.000000e+000,0,,0,
1524122671.281,,0.000000e+000,5.299362e+001,-6.848630e-005,0.000000e+000,3,9.740421e-001,0.000000e+000,,,,,,,,,,,,,,32,1,4.000000e+000,8.609772e-003,0.000000e+000,0,,0,
1524122709.172,,0.000000e+000,5.299978e+001,-6.855513e-005,0.000000e+000,3,9.736974e-001,0.000000e+000,,,,,,,,,,,,,,32,1,4.000000e+000,1.239777e-003,0.000000e+000,0,,0,
1524122746.172,,0.000000e+000,5.299855e+001,-6.874844e-005,0.000000e+000,3,9.736081e-001,0.000000e+000,,,,,,,,,,,,,,32,1,4.000000e+000,3.700256e-003,0.000000e+000,0,,0,
1524122784.112,,0.000000e+000,5.300163e+001,-6.886938e-005,0.000000e+000,3,9.740787e-001,0.000000e+000,,,,,,,,,,,,,,32,1,4.000000e+000,7.392883e-003,0.000000e+000,0,,0,
1524122821.192,,0.000000e+000,5.300101e+001,-6.904193e-005,0.000000e+000,3,9.739546e-001,0.000000e+000,,,,,,,,,,,,,,32,1,4.000000e+000,6.153107e-003,0.000000e+000,0,,0,
1524122859.052,,0.000000e+000,5.299609e+001,-6.912467e-005,0.000000e+000,3,9.735680e-001,0.000000e+000,,,,,,,,,,,,,,32,1,4.000000e+000,1.220703e-003,0.000000e+000,0,,0,
1524122896.082,,0.000000e+000,5.299609e+001,-6.929832e-005,0.000000e+000,3,9.742298e-001,0.000000e+000,,,,,,,,,,,,,,32,1,4.000000e+000,1.220703e-003,0.000000e+000,0,,0,
1524122934.002,,0.000000e+000,5.299609e+001,-6.939650e-005,0.000000e+000,3,9.738792e-001,0.000000e+000,,,,,,,,,,,,,,32,1,4.000000e+000,3.688812e-003,0.000000e+000,0,,0,
1524122970.972,,0.000000e+000,5.299916e+001,-6.951149e-005,0.000000e+000,3,9.741290e-001,0.000000e+000,,,,,,,,,,,,,,32,1,4.000000e+000,4.928589e-003,0.000000e+000,0,,0,
1524123008.942,,0.000000e+000,5.299609e+001,-6.962059e-005,0.000000e+000,3,9.741810e-001,0.000000e+000,,,,,,,,,,,,,,32,1,4.000000e+000,3.688812e-003,0.000000e+000,0,,0,
1524123045.922,,0.000000e+000,5.299793e+001,-6.977081e-005,0.000000e+000,3,9.739228e-001,0.000000e+000,,,,,,,,,,,,,,32,1,4.000000e+000,0.000000e+000,0.000000e+000,0,,0,
1524123083.902,,0.000000e+000,5.299978e+001,-6.986073e-005,0.000000e+000,3,9.741186e-001,0.000000e+000,,,,,,,,,,,,,,32,1,4.000000e+000,3.700256e-003,0.000000e+000,0,,0,
1524123120.932,,0.000000e+000,5.299731e+001,-6.997694e-005,0.000000e+000,3,9.740519e-001,0.000000e+000,,,,,,,,,,,,,,32,1,4.000000e+000,1.228333e-003,0.000000e+000,0,,0,
1524123158.852,,0.000000e+000,5.299916e+001,-7.001287e-005,0.000000e+000,3,9.741790e-001,0.000000e+000,,,,,,,,,,,,,,32,1,4.000000e+000,4.928589e-003,0.000000e+000,0,,0,
1524123196.762,,0.000000e+000,5.299732e+001,-7.014670e-005,0.000000e+000,3,9.741257e-001,0.000000e+000,,,,,,,,,,,,,,32,1,4.000000e+000,3.681183e-003,0.000000e+000,0,,0,
1524123234.482,,0.000000e+000,5.299794e+001,-7.020323e-005,0.000000e+000,3,9.725107e-001,0.000000e+000,,,,,,,,,,,,,,32,1,4.000000e+000,4.920959e-003,0.000000e+000,0,,0,
1524123272.072,,0.000000e+000,5.299731e+001,-7.035591e-005,0.000000e+000,3,9.741971e-001,0.000000e+000,,,,,,,,,,,,,,32,1,4.000000e+000,1.228333e-003,0.000000e+000,0,,0,
1524123309.312,,0.000000e+000,5.300101e+001,-7.038735e-005,0.000000e+000,3,9.732411e-001,0.000000e+000,,,,,,,,,,,,,,32,1,4.000000e+000,6.153107e-003,0.000000e+000,0,,0,
1524123346.692,,0.000000e+000,5.299916e+001,-7.042936e-005,0.000000e+000,3,9.726307e-001,0.000000e+000,,,,,,,,,,,,,,32,1,4.000000e+000,2.471924e-003,0.000000e+000,0,,0,
1524123384.932,,0.000000e+000,5.299731e+001,-7.059973e-005,0.000000e+000,3,9.737399e-001,0.000000e+000,,,,,,,,,,,,,,32,1,4.000000e+000,1.228333e-003,0.000000e+000,0,,0,
1524123421.903,,0.000000e+000,5.299547e+001,-7.071294e-005,0.000000e+000,3,9.730657e-001,0.000000e+000,,,,,,,,,,,,,,32,1,4.000000e+000,7.381439e-003,0.000000e+000,0,,0,
1524123459.793,,0.000000e+000,5.299793e+001,-7.073452e-005,0.000000e+000,3,9.725790e-001,0.000000e+000,,,,,,,,,,,,,,32,1,4.000000e+000,0.000000e+000,0.000000e+000,0,,0,
1524123497.833,,0.000000e+000,5.299793e+001,-7.090122e-005,0.000000e+000,3,9.732379e-001,0.000000e+000,,,,,,,,,,,,,,32,1,4.000000e+000,0.000000e+000,0.000000e+000,0,,0,
1524123535.563,,0.000000e+000,5.300224e+001,-7.090215e-005,0.000000e+000,3,9.723012e-001,0.000000e+000,,,,,,,,,,,,,,32,1,4.000000e+000,1.232147e-003,0.000000e+000,0,,0,
1524123573.593,,0.000000e+000,5.299854e+001,-7.098881e-005,0.000000e+000,3,9.725313e-001,0.000000e+000,,,,,,,,,,,,,,32,1,4.000000e+000,1.232147e-003,0.000000e+000,0,,0,
1524123610.743,,0.000000e+000,5.299978e+001,-7.110796e-005,0.000000e+000,3,9.721819e-001,0.000000e+000,,,,,,,,,,,,,,32,1,4.000000e+000,6.160736e-003,0.000000e+000,0,,0,
1524123648.573,,0.000000e+000,5.299055e+001,-7.116942e-005,0.000000e+000,3,9.715412e-001,0.000000e+000,,,,,,,,,,,,,,32,1,4.000000e+000,2.460480e-003,0.000000e+000,0,,0,
1524123687.423,,0.000000e+000,5.299363e+001,-7.127873e-005,0.000000e+000,3,9.727822e-001,0.000000e+000,,,,,,,,,,,,,,32,1,4.000000e+000,3.700256e-003,0.000000e+000,0,,0,
1524123725.913,,0.000000e+000,5.299732e+001,-7.141143e-005,0.000000e+000,3,9.728292e-001,0.000000e+000,,,,,,,,,,,,,,32,1,4.000000e+000,8.617401e-003,0.000000e+000,0,,0,
1524123763.143,,0.000000e+000,5.300101e+001,-7.138962e-005,0.000000e+000,3,9.732452e-001,0.000000e+000,,,,,,,,,,,,,,32,1,4.000000e+000,1.228333e-003,0.000000e+000,0,,0,
1524123801.093,,0.000000e+000,5.299486e+001,-7.153791e-005,0.000000e+000,3,9.735375e-001,0.000000e+000,,,,,,,,,,,,,,32,1,4.000000e+000,8.609772e-003,0.000000e+000,0,,0,
1524123839.063,,0.000000e+000,5.300225e+001,-7.152357e-005,0.000000e+000,3,9.715465e-001,0.000000e+000,,,,,,,,,,,,,,32,1,4.000000e+000,1.354218e-002,0.000000e+000,0,,0,
1524123877.853,,0.000000e+000,5.299793e+001,-7.157198e-005,0.000000e+000,3,9.730570e-001,0.000000e+000,,,,,,,,,,,,,,32,1,4.000000e+000,0.000000e+000,0.000000e+000,0,,0,
1524123915.233,,0.000000e+000,5.300285e+001,-7.167544e-005,0.000000e+000,3,9.722563e-001,0.000000e+000,,,,,,,,,,,,,,32,1,4.000000e+000,2.452850e-003,0.000000e+000,0,,0,
1524123952.893,,0.000000e+000,5.299178e+001,-7.171480e-005,0.000000e+000,3,9.728188e-001,0.000000e+000,,,,,,,,,,,,,,32,1,4.000000e+000,2.460480e-003,0.000000e+000,0,,0,
1524123991.283,,0.000000e+000,5.300409e+001,-7.181233e-005,0.000000e+000,3,9.741647e-001,0.000000e+000,,,,,,,,,,,,,,32,1,4.000000e+000,4.920959e-003,0.000000e+000,0,,0,
1524124029.013,,0.000000e+000,5.299486e+001,-7.189956e-005,0.000000e+000,3,9.740667e-001,0.000000e+000,,,,,,,,,,,,,,32,1,4.000000e+000,3.688812e-003,0.000000e+000,0,,0,
1524124067.123,,0.000000e+000,5.299670e+001,-7.193378e-005,0.000000e+000,3,9.728674e-001,0.000000e+000,,,,,,,,,,,,,,32,1,4.000000e+000,4.920959e-003,0.000000e+000,0,,0,
1524124104.853,,0.000000e+000,5.299855e+001,-7.201309e-005,0.000000e+000,3,9.731240e-001,0.000000e+000,,,,,,,,,,,,,,32,1,4.000000e+000,8.621216e-003,0.000000e+000,0,,0,
1524124142.414,,0.000000e+000,5.299854e+001,-7.208550e-005,0.000000e+000,3,9.729705e-001,0.000000e+000,,,,,,,,,,,,,,32,1,4.000000e+000,1.232147e-003,0.000000e+000,0,,0,
1524124181.074,,0.000000e+000,5.299916e+001,-7.204633e-005,0.000000e+000,3,9.741337e-001,0.000000e+000,,,,,,,,,,,,,,32,1,4.000000e+000,9.841919e-003,0.000000e+000,0,,0,
1524124219.514,,0.000000e+000,5.300040e+001,-7.216351e-005,0.000000e+000,3,9.714501e-001,0.000000e+000,,,,,,,,,,,,,,32,1,4.000000e+000,4.932404e-003,0.000000e+000,0,,0,
1524124257.584,,0.000000e+000,5.300286e+001,-7.221282e-005,0.000000e+000,3,9.735391e-001,0.000000e+000,,,,,,,,,,,,,,32,1,4.000000e+000,9.860992e-003,0.000000e+000,0,,0,
1524124295.264,,0.000000e+000,5.299731e+001,-7.232665e-005,0.000000e+000,3,9.735835e-001,0.000000e+000,,,,,,,,,,,,,,32,1,4.000000e+000,1.228333e-003,0.000000e+000,0,,0,
1524124333.134,,0.000000e+000,5.299547e+001,-7.231732e-005,0.000000e+000,3,9.723827e-001,0.000000e+000,,,,,,,,,,,,,,32,1,4.000000e+000,4.917145e-003,0.000000e+000,0,,0,
1524124370.934,,0.000000e+000,5.299854e+001,-7.237915e-005,0.000000e+000,3,9.727775e-001,0.000000e+000,,,,,,,,,,,,,,32,1,4.000000e+000,1.232147e-003,0.000000e+000,0,,0,
1524124408.414,,0.000000e+000,5.298808e+001,-7.245426e-005,0.000000e+000,3,9.733299e-001,0.000000e+000,,,,,,,,,,,,,,32,1,4.000000e+000,2.215195e-002,0.000000e+000,0,,0,
1524124445.614,,0.000000e+000,5.299731e+001,-7.254677e-005,0.000000e+000,3,9.728768e-001,0.000000e+000,,,,,,,,,,,,,,32,1,4.000000e+000,1.228333e-003,0.000000e+000,0,,0,
1524124483.204,,0.000000e+000,5.299917e+001,-7.266716e-005,0.000000e+000,3,9.733893e-001,0.000000e+000,,,,,,,,,,,,,,32,1,4.000000e+000,7.381439e-003,0.000000e+000,0,,0,
1524124521.234,,0.000000e+000,5.299916e+001,-7.262969e-005,0.000000e+000,3,9.722406e-001,0.000000e+000,,,,,,,,,,,,,,32,1,4.000000e+000,0.000000e+000,0.000000e+000,0,,0,
1524124559.324,,0.000000e+000,5.299855e+001,-7.270944e-005,0.000000e+000,3,9.730789e-001,0.000000e+000,,,,,,,,,,,,,,32,1,4.000000e+000,3.700256e-003,0.000000e+000,0,,0,
1524124596.914,,0.000000e+000,5.299486e+001,-7.275173e-005,0.000000e+000,3,9.731313e-001,0.000000e+000,,,,,,,,,,,,,,32,1,4.000000e+000,1.239777e-003,0.000000e+000,0,,0,
1524124634.914,,0.000000e+000,5.299731e+001,-7.274373e-005,0.000000e+000,3,9.733397e-001,0.000000e+000,,,,,,,,,,,,,,32,1,4.000000e+000,1.228333e-003,0.000000e+000,0,,0,
1524124673.124,,0.000000e+000,5.299548e+001,-7.286124e-005,0.000000e+000,3,9.737038e-001,0.000000e+000,,,,,,,,,,,,,,32,1,4.000000e+000,0.000000e+000,0.000000e+000,0,,0,
1524124710.484,,0.000000e+000,5.299916e+001,-7.289650e-005,0.000000e+000,3,9.729895e-001,0.000000e+000,,,,,,,,,,,,,,32,1,4.000000e+000,2.471924e-003,0.000000e+000,0,,0,
1524124748.294,,0.000000e+000,5.299854e+001,-7.293635e-005,0.000000e+000,3,9.732797e-001,0.000000e+000,,,,,,,,,,,,,,32,1,4.000000e+000,1.232147e-003,0.000000e+000,0,,0,
1524124786.744,,0.000000e+000,5.299732e+001,-7.296482e-005,0.000000e+000,3,9.718865e-001,0.000000e+000,,,,,,,,,,,,,,32,1,4.000000e+000,3.681183e-003,0.000000e+000,0,,0,
1524124825.334,,0.000000e+000,5.299794e+001,-7.303010e-005,0.000000e+000,3,9.735768e-001,0.000000e+000,,,,,,,,,,,,,,32,1,4.000000e+000,4.920959e-003,0.000000e+000,0,,0,
1524124862.365,,0.000000e+000,5.300163e+001,-7.311042e-005,0.000000e+000,3,9.735983e-001,0.000000e+000,,,,,,,,,,,,,,32,1,4.000000e+000,2.460480e-003,0.000000e+000,0,,0,
1524124900.365,,0.000000e+000,5.300286e+001,-7.313281e-005,0.000000e+000,3,9.738123e-001,0.000000e+000,,,,,,,,,,,,,,32,1,4.000000e+000,9.860992e-003,0.000000e+000,0,,0,
1524124938.745,,0.000000e+000,5.299855e+001,-7.322300e-005,0.000000e+000,3,9.732038e-001,0.000000e+000,,,,,,,,,,,,,,32,1,4.000000e+000,6.149292e-003,0.000000e+000,0,,0,
1524124975.835,,0.000000e+000,5.299670e+001,-7.320342e-005,0.000000e+000,3,9.735479e-001,0.000000e+000,,,,,,,,,,,,,,32,1,4.000000e+000,2.449036e-003,0.000000e+000,0,,0,
1524125012.825,,0.000000e+000,5.299917e+001,-7.330105e-005,0.000000e+000,3,9.722915e-001,0.000000e+000,,,,,,,,,,,,,,32,1,4.000000e+000,7.381439e-003,0.000000e+000,0,,0,
1524125050.635,,0.000000e+000,5.300040e+001,-7.334628e-005,0.000000e+000,3,9.720462e-001,0.000000e+000,,,,,,,,,,,,,,32,1,4.000000e+000,2.468109e-003,0.000000e+000,0,,0,
1524125087.915,,0.000000e+000,5.299300e+001,-7.335570e-005,0.000000e+000,3,9.717327e-001,0.000000e+000,,,,,,,,,,,,,,32,1,4.000000e+000,1.231003e-002,0.000000e+000,0,,0,
1524125126.285,,0.000000e+000,5.300101e+001,-7.341550e-005,0.000000e+000,3,9.735168e-001,0.000000e+000,,,,,,,,,,,,,,32,1,4.000000e+000,6.153107e-003,0.000000e+000,0,,0,
1524125163.325,,0.000000e+000,5.299425e+001,-7.350287e-005,0.000000e+000,3,9.735428e-001,0.000000e+000,,,,,,,,,,,,,,32,1,4.000000e+000,2.468109e-003,0.000000e+000,0,,0,
1524125201.255,,0.000000e+000,5.299732e+001,-7.350816e-005,0.000000e+000,3,9.731605e-001,0.000000e+000,,,,,,,,,,,,,,32,1,4.000000e+000,3.681183e-003,0.000000e+000,0,,0,
1524125238.965,,0.000000e+000,5.299916e+001,-7.359240e-005,0.000000e+000,3,9.738147e-001,0.000000e+000,,,,,,,,,,,,,,32,1,4.000000e+000,2.471924e-003,0.000000e+000,0,,0,
1524125276.915,,0.000000e+000,5.299978e+001,-7.355840e-005,0.000000e+000,3,9.728147e-001,0.000000e+000,,,,,,,,,,,,,,32,1,4.000000e+000,8.602142e-003,0.000000e+000,0,,0,
1524125315.725,,0.000000e+000,5.299793e+001,-7.373370e-005,0.000000e+000,3,9.732487e-001,0.000000e+000,,,,,,,,,,,,,,32,1,4.000000e+000,1.230240e-002,0.000000e+000,0,,0,
1524125352.605,,0.000000e+000,5.299670e+001,-7.360920e-005,0.000000e+000,3,9.720855e-001,0.000000e+000,,,,,,,,,,,,,,32,1,4.000000e+000,7.389069e-003,0.000000e+000,0,,0,
1524125390.435,,0.000000e+000,5.299486e+001,-7.367546e-005,0.000000e+000,3,9.726429e-001,0.000000e+000,,,,,,,,,,,,,,32,1,4.000000e+000,1.239777e-003,0.000000e+000,0,,0,
1524125428.825,,0.000000e+000,5.299916e+001,-7.377221e-005,0.000000e+000,3,9.736692e-001,0.000000e+000,,,,,,,,,,,,,,32,1,4.000000e+000,2.471924e-003,0.000000e+000,0,,0,
1524125465.955,,0.000000e+000,5.299854e+001,-7.375628e-005,0.000000e+000,3,9.726306e-001,0.000000e+000,,,,,,,,,,,,,,32,1,4.000000e+000,1.232147e-003,0.000000e+000,0,,0,
1524125503.415,,0.000000e+000,5.299978e+001,-7.378327e-005,0.000000e+000,3,9.736152e-001,0.000000e+000,,,,,,,,,,,,,,32,1,4.000000e+000,6.160736e-003,0.000000e+000,0,,0,
1524125540.395,,0.000000e+000,5.299731e+001,-7.383659e-005,0.000000e+000,3,9.731488e-001,0.000000e+000,,,,,,,,,,,,,,32,1,4.000000e+000,1.228333e-003,0.000000e+000,0,,0,
1524125578.036,,0.000000e+000,5.299793e+001,-7.390101e-005,0.000000e+000,3,9.740117e-001,0.000000e+000,,,,,,,,,,,,,,32,1,4.000000e+000,7.389069e-003,0.000000e+000,0,,0,
1524125615.326,,0.000000e+000,5.299485e+001,-7.399655e-005,0.000000e+000,3,9.726903e-001,0.000000e+000,,,,,,,,,,,,,,32,1,4.000000e+000,6.149292e-003,0.000000e+000,0,,0,
1524125652.006,,0.000000e+000,5.300101e+001,-7.395884e-005,0.000000e+000,3,9.724327e-001,0.000000e+000,,,,,,,,,,,,,,32,1,4.000000e+000,1.228333e-003,0.000000e+000,0,,0,
1524125689.676,,0.000000e+000,5.299916e+001,-7.402708e-005,0.000000e+000,3,9.727774e-001,0.000000e+000,,,,,,,,,,,,,,32,1,4.000000e+000,0.000000e+000,0.000000e+000,0,,0,
1524125727.746,,0.000000e+000,5.299486e+001,-7.407401e-005,0.000000e+000,3,9.732864e-001,0.000000e+000,,,,,,,,,,,,,,32,1,4.000000e+000,1.239777e-003,0.000000e+000,0,,0,
1524125766.256,,0.000000e+000,5.300101e+001,-7.404738e-005,0.000000e+000,3,9.723674e-001,0.000000e+000,,,,,,,,,,,,,,32,1,4.000000e+000,6.153107e-003,0.000000e+000,0,,0,
1524125803.986,,0.000000e+000,5.300471e+001,-7.411472e-005,0.000000e+000,3,9.728932e-001,0.000000e+000,,,,,,,,,,,,,,32,1,4.000000e+000,8.621216e-003,0.000000e+000,0,,0,
1524125841.676,,0.000000e+000,5.299425e+001,-7.417809e-005,0.000000e+000,3,9.732462e-001,0.000000e+000,,,,,,,,,,,,,,32,1,4.000000e+000,2.468109e-003,0.000000e+000,0,,0,
1524125879.386,,0.000000e+000,5.299732e+001,-7.417858e-005,0.000000e+000,3,9.723756e-001,0.000000e+000,,,,,,,,,,,,,,32,1,4.000000e+000,6.160736e-003,0.000000e+000,0,,0,
1524125917.276,,0.000000e+000,5.299732e+001,-7.416227e-005,0.000000e+000,3,9.729449e-001,0.000000e+000,,,,,,,,,,,,,,32,1,4.000000e+000,6.160736e-003,0.000000e+000,0,,0,
1524125954.816,,0.000000e+000,5.299854e+001,-7.427165e-005,0.000000e+000,3,9.731514e-001,0.000000e+000,,,,,,,,,,,,,,32,1,4.000000e+000,1.232147e-003,0.000000e+000,0,,0,
1524125993.066,,0.000000e+000,5.299239e+001,-7.421369e-005,0.000000e+000,3,9.718795e-001,0.000000e+000,,,,,,,,,,,,,,32,1,4.000000e+000,8.609772e-003,0.000000e+000,0,,0,
1524126031.126,,0.000000e+000,5.300040e+001,-7.431384e-005,0.000000e+000,3,9.726784e-001,0.000000e+000,,,,,,,,,,,,,,32,1,4.000000e+000,2.468109e-003,0.000000e+000,0,,0,
1524126068.736,,0.000000e+000,5.299854e+001,-7.429248e-005,0.000000e+000,3,9.717575e-001,0.000000e+000,,,,,,,,,,,,,,32,1,4.000000e+000,1.232147e-003,0.000000e+000,0,,0,
1524126106.656,,0.000000e+000,5.299547e+001,-7.435623e-005,0.000000e+000,3,9.728204e-001,0.000000e+000,,,,,,,,,,,,,,32,1,4.000000e+000,4.917145e-003,0.000000e+000,0,,0,
1524126143.956,,0.000000e+000,5.300040e+001,-7.440192e-005,0.000000e+000,3,9.727780e-001,0.000000e+000,,,,,,,,,,,,,,32,1,4.000000e+000,2.468109e-003,0.000000e+000,0,,0,
1524126181.696,,0.000000e+000,5.299670e+001,-7.441410e-005,0.000000e+000,3,9.729582e-001,0.000000e+000,,,,,,,,,,,,,,32,1,4.000000e+000,2.449036e-003,0.000000e+000,0,,0,
1524126219.756,,0.000000e+000,5.300285e+001,-7.454884e-005,0.000000e+000,3,9.732211e-001,0.000000e+000,,,,,,,,,,,,,,32,1,4.000000e+000,2.452850e-003,0.000000e+000,0,,0,
1524126257.096,,0.000000e+000,5.299240e+001,-7.451863e-005,0.000000e+000,3,9.719056e-001,0.000000e+000,,,,,,,,,,,,,,32,1,4.000000e+000,6.160736e-003,0.000000e+000,0,,0,
1524126294.817,,0.000000e+000,5.299363e+001,-7.452899e-005,0.000000e+000,3,9.728494e-001,0.000000e+000,,,,,,,,,,,,,,32,1,4.000000e+000,1.228333e-003,0.000000e+000,0,,0,
1524126332.627,,0.000000e+000,5.299855e+001,-7.455968e-005,0.000000e+000,3,9.724755e-001,0.000000e+000,,,,,,,,,,,,,,32,1,4.000000e+000,8.621216e-003,0.000000e+000,0,,0,
1524126370.347,,0.000000e+000,5.299793e+001,-7.459205e-005,0.000000e+000,3,9.726905e-001,0.000000e+000,,,,,,,,,,,,,,32,1,4.000000e+000,7.389069e-003,0.000000e+000,0,,0,
1524126407.547,,0.000000e+000,5.299855e+001,-7.462843e-005,0.000000e+000,3,9.725611e-001,0.000000e+000,,,,,,,,,,,,,,32,1,4.000000e+000,8.621216e-003,0.000000e+000,0,,0,
1524126445.257,,0.000000e+000,5.299978e+001,-7.465704e-005,0.000000e+000,3,9.729134e-001,0.000000e+000,,,,,,,,,,,,,,32,1,4.000000e+000,1.108170e-002,0.000000e+000,0,,0,
1524126483.017,,0.000000e+000,5.300348e+001,-7.468765e-005,0.000000e+000,3,9.728166e-001,0.000000e+000,,,,,,,,,,,,,,32,1,4.000000e+000,3.692627e-003,0.000000e+000,0,,0,
1524126520.787,,0.000000e+000,5.299670e+001,-7.471812e-005,0.000000e+000,3,9.731461e-001,0.000000e+000,,,,,,,,,,,,,,32,1,4.000000e+000,7.389069e-003,0.000000e+000,0,,0,
1524126557.987,,0.000000e+000,5.299670e+001,-7.479169e-005,0.000000e+000,3,9.728156e-001,0.000000e+000,,,,,,,,,,,,,,32,1,4.000000e+000,0.000000e+000,0.000000e+000,0,,0,
1524126595.857,,0.000000e+000,5.299547e+001,-7.470722e-005,0.000000e+000,3,9.726034e-001,0.000000e+000,,,,,,,,,,,,,,32,1,4.000000e+000,2.460480e-003,0.000000e+000,0,,0,
1524126633.907,,0.000000e+000,5.299916e+001,-7.467200e-005,0.000000e+000,3,9.728872e-001,0.000000e+000,,,,,,,,,,,,,,32,1,4.000000e+000,9.841919e-003,0.000000e+000,0,,0,
1524126671.927,,0.000000e+000,5.300040e+001,-7.475835e-005,0.000000e+000,3,9.736247e-001,0.000000e+000,,,,,,,,,,,,,,32,1,4.000000e+000,0.000000e+000,0.000000e+000,0,,0,
1524126708.957,,0.000000e+000,5.299917e+001,-7.478586e-005,0.000000e+000,3,9.736354e-001,0.000000e+000,,,,,,,,,,,,,,32,1,4.000000e+000,7.381439e-003,0.000000e+000,0,,0,
1524126747.097,,0.000000e+000,5.299916e+001,-7.485344e-005,0.000000e+000,3,9.738950e-001,0.000000e+000,,,,,,,,,,,,,,32,1,4.000000e+000,2.471924e-003,0.000000e+000,0,,0,
1524126783.987,,0.000000e+000,5.299916e+001,-7.484338e-005,0.000000e+000,3,9.728630e-001,0.000000e+000,,,,,,,,,,,,,,32,1,4.000000e+000,2.471924e-003,0.000000e+000,0,,0,
1524126821.677,,0.000000e+000,5.299732e+001,-7.487916e-005,0.000000e+000,3,9.732875e-001,0.000000e+000,,,,,,,,,,,,,,32,1,4.000000e+000,1.108170e-002,0.000000e+000,0,,0,
1524126858.997,,0.000000e+000,5.299794e+001,-7.491602e-005,0.000000e+000,3,9.737118e-001,0.000000e+000,,,,,,,,,,,,,,32,1,4.000000e+000,4.920959e-003,0.000000e+000,0,,0,
1524126896.737,,0.000000e+000,5.299793e+001,-7.489423e-005,0.000000e+000,3,9.726542e-001,0.000000e+000,,,,,,,,,,,,,,32,1,4.000000e+000,2.460480e-003,0.000000e+000,0,,0,
1524126935.267,,0.000000e+000,5.299731e+001,-7.500561e-005,0.000000e+000,3,9.733723e-001,0.000000e+000,,,,,,,,,,,,,,32,1,4.000000e+000,1.228333e-003,0.000000e+000,0,,0,
1524126973.337,,0.000000e+000,5.299916e+001,-7.505856e-005,0.000000e+000,3,9.739906e-001,0.000000e+000,,,,,,,,,,,,,,32,1,4.000000e+000,2.471924e-003,0.000000e+000,0,,0,
1524127012.178,,0.000000e+000,5.299424e+001,-7.509009e-005,0.000000e+000,3,9.728153e-001,0.000000e+000,,,,,,,,,,,,,,32,1,4.000000e+000,7.377625e-003,0.000000e+000,0,,0,
1524127049.508,,0.000000e+000,5.299670e+001,-7.503894e-005,0.000000e+000,3,9.728349e-001,0.000000e+000,,,,,,,,,,,,,,32,1,4.000000e+000,2.449036e-003,0.000000e+000,0,,0,
1524127087.648,,0.000000e+000,5.300717e+001,-7.521123e-005,0.000000e+000,3,9.727839e-001,0.000000e+000,,,,,,,,,,,,,,32,1,4.000000e+000,1.353836e-002,0.000000e+000,0,,0,
1524127125.198,,0.000000e+000,5.299978e+001,-7.513836e-005,0.000000e+000,3,9.715797e-001,0.000000e+000,,,,,,,,,,,,,,32,1,4.000000e+000,1.239777e-003,0.000000e+000,0,,0,
1524127163.118,,0.000000e+000,5.299670e+001,-7.517679e-005,0.000000e+000,3,9.725242e-001,0.000000e+000,,,,,,,,,,,,,,32,1,4.000000e+000,0.000000e+000,0.000000e+000,0,,0,
1524127201.408,,0.000000e+000,5.299793e+001,-7.521809e-005,0.000000e+000,3,9.746545e-001,0.000000e+000,,,,,,,,,,,,,,32,1,4.000000e+000,2.460480e-003,0.000000e+000,0,,0,
1524127239.458,,0.000000e+000,5.299978e+001,-7.525094e-005,0.000000e+000,3,9.727821e-001,0.000000e+000,,,,,,,,,,,,,,32,1,4.000000e+000,1.239777e-003,0.000000e+000,0,,0,
1524127278.148,,0.000000e+000,5.299609e+001,-7.529876e-005,0.000000e+000,3,9.739285e-001,0.000000e+000,,,,,,,,,,,,,,32,1,4.000000e+000,1.220703e-003,0.000000e+000,0,,0,
1524127315.318,,0.000000e+000,5.299609e+001,-7.528363e-005,0.000000e+000,3,9.735726e-001,0.000000e+000,,,,,,,,,,,,,,32,1,4.000000e+000,1.107788e-002,0.000000e+000,0,,0,
1524127353.688,,0.000000e+000,5.299670e+001,-7.531297e-005,0.000000e+000,3,9.730063e-001,0.000000e+000,,,,,,,,,,,,,,32,1,4.000000e+000,2.449036e-003,0.000000e+000,0,,0,
1524127392.008,,0.000000e+000,5.300163e+001,-7.539353e-005,0.000000e+000,3,9.736528e-001,0.000000e+000,,,,,,,,,,,,,,32,1,4.000000e+000,2.460480e-003,0.000000e+000,0,,0,
1524127429.358,,0.000000e+000,5.299731e+001,-7.534798e-005,0.000000e+000,3,9.728231e-001,0.000000e+000,,,,,,,,,,,,,,32,1,4.000000e+000,1.228333e-003,0.000000e+000,0,,0,
1524127467.478,,0.000000e+000,5.299978e+001,-7.548161e-005,0.000000e+000,3,9.732977e-001,0.000000e+000,,,,,,,,,,,,,,32,1,4.000000e+000,3.700256e-003,0.000000e+000,0,,0,
1524127505.538,,0.000000e+000,5.299916e+001,-7.543513e-005,0.000000e+000,3,9.722056e-001,0.000000e+000,,,,,,,,,,,,,,32,1,4.000000e+000,9.841919e-003,0.000000e+000,0,,0,
1524127543.438,,0.000000e+000,5.300162e+001,-7.545895e-005,0.000000e+000,3,9.730455e-001,0.000000e+000,,,,,,,,,,,,,,32,1,4.000000e+000,4.920959e-003,0.000000e+000,0,,0,
1524127581.408,,0.000000e+000,5.299609e+001,-7.549204e-005,0.000000e+000,3,9.723333e-001,0.000000e+000,,,,,,,,,,,,,,32,1,4.000000e+000,3.688812e-003,0.000000e+000,0,,0,
1524127619.068,,0.000000e+000,5.299855e+001,-7.545738e-005,0.000000e+000,3,9.729939e-001,0.000000e+000,,,,,,,,,,,,,,32,1,4.000000e+000,1.107025e-002,0.000000e+000,0,,0,
1524127657.438,,0.000000e+000,5.300224e+001,-7.550215e-005,0.000000e+000,3,9.731858e-001,0.000000e+000,,,,,,,,,,,,,,32,1,4.000000e+000,3.681183e-003,0.000000e+000,0,,0,
1524127695.738,,0.000000e+000,5.299670e+001,-7.562238e-005,0.000000e+000,3,9.739440e-001,0.000000e+000,,,,,,,,,,,,,,32,1,4.000000e+000,0.000000e+000,0.000000e+000,0,,0,
1524127733.159,,0.000000e+000,5.299793e+001,-7.553663e-005,0.000000e+000,3,9.725902e-001,0.000000e+000,,,,,,,,,,,,,,32,1,4.000000e+000,2.460480e-003,0.000000e+000,0,,0,
1524127770.589,,0.000000e+000,5.299117e+001,-7.556812e-005,0.000000e+000,3,9.728318e-001,0.000000e+000,,,,,,,,,,,,,,32,1,4.000000e+000,8.628845e-003,0.000000e+000,0,,0,
1524127807.709,,0.000000e+000,5.300285e+001,-7.559743e-005,0.000000e+000,3,9.724037e-001,0.000000e+000,,,,,,,,,,,,,,32,1,4.000000e+000,2.452850e-003,0.000000e+000,0,,0,
1524127845.459,,0.000000e+000,5.300471e+001,-7.560569e-005,0.000000e+000,3,9.723545e-001,0.000000e+000,,,,,,,,,,,,,,32,1,4.000000e+000,1.108932e-002,0.000000e+000,0,,0,
1524127883.679,,0.000000e+000,5.300040e+001,-7.573111e-005,0.000000e+000,3,9.729484e-001,0.000000e+000,,,,,,,,,,,,,,32,1,4.000000e+000,2.468109e-003,0.000000e+000,0,,0,
1524127921.159,,0.000000e+000,5.299978e+001,-7.565429e-005,0.000000e+000,3,9.724397e-001,0.000000e+000,,,,,,,,,,,,,,32,1,4.000000e+000,8.602142e-003,0.000000e+000,0,,0,
1524127958.889,,0.000000e+000,5.299609e+001,-7.572992e-005,0.000000e+000,3,9.731419e-001,0.000000e+000,,,,,,,,,,,,,,32,1,4.000000e+000,1.220703e-003,0.000000e+000,0,,0,
1524127996.579,,0.000000e+000,5.299978e+001,-7.570622e-005,0.000000e+000,3,9.728285e-001,0.000000e+000,,,,,,,,,,,,,,32,1,4.000000e+000,6.160736e-003,0.000000e+000,0,,0,
1524128034.309,,0.000000e+000,5.300101e+001,-7.576747e-005,0.000000e+000,3,9.728079e-001,0.000000e+000,,,,,,,,,,,,,,32,1,4.000000e+000,1.228333e-003,0.000000e+000,0,,0,
1524128071.489,,0.000000e+000,5.299916e+001,-7.578226e-005,0.000000e+000,3,9.721118e-001,0.000000e+000,,,,,,,,,,,,,,32,1,4.000000e+000,0.000000e+000,0.000000e+000,0,,0,
1524128109.229,,0.000000e+000,5.299670e+001,-7.578881e-005,0.000000e+000,3,9.726075e-001,0.000000e+000,,,,,,,,,,,,,,32,1,4.000000e+000,4.920959e-003,0.000000e+000,0,,0,
1524128146.849,,0.000000e+000,5.300163e+001,-7.584151e-005,0.000000e+000,3,9.720036e-001,0.000000e+000,,,,,,,,,,,,,,32,1,4.000000e+000,0.000000e+000,0.000000e+000,0,,0,
1524128184.669,,0.000000e+000,5.299793e+001,-7.582589e-005,0.000000e+000,3,9.724764e-001,0.000000e+000,,,,,,,,,,,,,,32,1,4.000000e+000,0.000000e+000,0.000000e+000,0,,0,
1524128223.129,,0.000000e+000,5.299670e+001,-7.584406e-005,0.000000e+000,3,9.729140e-001,0.000000e+000,,,,,,,,,,,,,,32,1,4.000000e+000,4.920959e-003,0.000000e+000,0,,0,
1524128260.269,,0.000000e+000,5.299302e+001,-7.589295e-005,0.000000e+000,3,9.720905e-001,0.000000e+000,,,,,,,,,,,,,,32,1,4.000000e+000,4.928589e-003,0.000000e+000,0,,0,
1524128298.619,,0.000000e+000,5.299363e+001,-7.592653e-005,0.000000e+000,3,9.722685e-001,0.000000e+000,,,,,,,,,,,,,,32,1,4.000000e+000,6.149292e-003,0.000000e+000,0,,0,
1524128335.869,,0.000000e+000,5.300286e+001,-7.598060e-005,0.000000e+000,3,9.724212e-001,0.000000e+000,,,,,,,,,,,,,,32,1,4.000000e+000,1.232147e-002,0.000000e+000,0,,0,
1524128373.569,,0.000000e+000,5.299916e+001,-7.596747e-005,0.000000e+000,3,9.724448e-001,0.000000e+000,,,,,,,,,,,,,,32,1,4.000000e+000,2.471924e-003,0.000000e+000,0,,0,
1524128410.969,,0.000000e+000,5.299670e+001,-7.603901e-005,0.000000e+000,3,9.729847e-001,0.000000e+000,,,,,,,,,,,,,,32,1,4.000000e+000,2.449036e-003,0.000000e+000,0,,0,
1524128449.560,,0.000000e+000,5.299609e+001,-7.598340e-005,0.000000e+000,3,9.721239e-001,0.000000e+000,,,,,,,,,,,,,,32,1,4.000000e+000,3.688812e-003,0.000000e+000,0,,0,
1524128487.690,,0.000000e+000,5.299978e+001,-7.607519e-005,0.000000e+000,3,9.725633e-001,0.000000e+000,,,,,,,,,,,,,,32,1,4.000000e+000,1.239777e-003,0.000000e+000,0,,0,
1524128524.830,,0.000000e+000,5.299609e+001,-7.610577e-005,0.000000e+000,3,9.736494e-001,0.000000e+000,,,,,,,,,,,,,,32,1,4.000000e+000,3.688812e-003,0.000000e+000,0,,0,
1524128562.440,,0.000000e+000,5.299609e+001,-7.606488e-005,0.000000e+000,3,9.726265e-001,0.000000e+000,,,,,,,,,,,,,,32,1,4.000000e+000,1.599121e-002,0.000000e+000,0,,0,
1524128599.930,,0.000000e+000,5.300101e+001,-7.609374e-005,0.000000e+000,3,9.730781e-001,0.000000e+000,,,,,,,,,,,,,,32,1,4.000000e+000,1.228333e-003,0.000000e+000,0,,0,
1524128637.550,,0.000000e+000,5.299916e+001,-7.614484e-005,0.000000e+000,3,9.727397e-001,0.000000e+000,,,,,,,,,,,,,,32,1,4.000000e+000,2.471924e-003,0.000000e+000,0,,0,
1524128675.690,,0.000000e+000,5.299978e+001,-7.623478e-005,0.000000e+000,3,9.733880e-001,0.000000e+000,,,,,,,,,,,,,,32,1,4.000000e+000,6.160736e-003,0.000000e+000,0,,0,
1524128712.990,,0.000000e+000,5.299670e+001,-7.617812e-005,0.000000e+000,3,9.727213e-001,0.000000e+000,,,,,,,,,,,,,,32,1,4.000000e+000,2.449036e-003,0.000000e+000,0,,0,
1524128751.640,,0.000000e+000,5.300101e+001,-7.617327e-005,0.000000e+000,3,9.731482e-001,0.000000e+000,,,,,,,,,,,,,,32,1,4.000000e+000,1.228333e-003,0.000000e+000,0,,0,
1524128789.250,,0.000000e+000,5.299609e+001,-7.617731e-005,0.000000e+000,3,9.720266e-001,0.000000e+000,,,,,,,,,,,,,,32,1,4.000000e+000,3.688812e-003,0.000000e+000,0,,0,
1524128827.170,,0.000000e+000,5.300101e+001,-7.622252e-005,0.000000e+000,3,9.732018e-001,0.000000e+000,,,,,,,,,,,,,,32,1,4.000000e+000,1.228333e-003,0.000000e+000,0,,0,
1524128865.170,,0.000000e+000,5.298993e+001,-7.634913e-005,0.000000e+000,3,9.729967e-001,0.000000e+000,,,,,,,,,,,,,,32,1,4.000000e+000,6.160736e-003,0.000000e+000,0,,0,
1524128902.210,,0.000000e+000,5.300040e+001,-7.623304e-005,0.000000e+000,3,9.722598e-001,0.000000e+000,,,,,,,,,,,,,,32,1,4.000000e+000,0.000000e+000,0.000000e+000,0,,0,
1524128940.950,,0.000000e+000,5.299855e+001,-7.628270e-005,0.000000e+000,3,9.738428e-001,0.000000e+000,,,,,,,,,,,,,,32,1,4.000000e+000,6.149292e-003,0.000000e+000,0,,0,
1524128978.300,,0.000000e+000,5.299916e+001,-7.629383e-005,0.000000e+000,3,9.723254e-001,0.000000e+000,,,,,,,,,,,,,,32,1,4.000000e+000,2.471924e-003,0.000000e+000,0,,0,
1524129015.950,,0.000000e+000,5.300163e+001,-7.630147e-005,0.000000e+000,3,9.721718e-001,0.000000e+000,,,,,,,,,,,,,,32,1,4.000000e+000,2.460480e-003,0.000000e+000,0,,0,
1524129054.140,,0.000000e+000,5.300532e+001,-7.646242e-005,0.000000e+000,3,9.723607e-001,0.000000e+000,,,,,,,,,,,,,,32,1,4.000000e+000,2.468109e-003,0.000000e+000,0,,0,
1524129091.430,,0.000000e+000,5.299855e+001,-7.634461e-005,0.000000e+000,3,9.728004e-001,0.000000e+000,,,,,,,,,,,,,,32,1,4.000000e+000,8.621216e-003,0.000000e+000,0,,0,
1524129129.200,,0.000000e+000,5.299363e+001,-7.645114e-005,0.000000e+000,3,9.729463e-001,0.000000e+000,,,,,,,,,,,,,,32,1,4.000000e+000,6.149292e-003,0.000000e+000,0,,0,
1524129166.271,,0.000000e+000,5.299239e+001,-7.637183e-005,0.000000e+000,3,9.720747e-001,0.000000e+000,,,,,,,,,,,,,,32,1,4.000000e+000,3.688812e-003,0.000000e+000,0,,0,
1524129204.061,,0.000000e+000,5.300101e+001,-7.642096e-005,0.000000e+000,3,9.730486e-001,0.000000e+000,,,,,,,,,,,,,,32,1,4.000000e+000,1.228333e-003,0.000000e+000,0,,0,
1524129241.341,,0.000000e+000,5.299670e+001,-7.641164e-005,0.000000e+000,3,9.720144e-001,0.000000e+000,,,,,,,,,,,,,,32,1,4.000000e+000,0.000000e+000,0.000000e+000,0,,0,
1524129279.591,,0.000000e+000,5.299854e+001,-7.647939e-005,0.000000e+000,3,9.729002e-001,0.000000e+000,,,,,,,,,,,,,,32,1,4.000000e+000,1.232147e-003,0.000000e+000,0,,0,
1524129317.131,,0.000000e+000,5.299609e+001,-7.649585e-005,0.000000e+000,3,9.717922e-001,0.000000e+000,,,,,,,,,,,,,,32,1,4.000000e+000,1.220703e-003,0.000000e+000,0,,0,
1524129355.091,,0.000000e+000,5.299732e+001,-7.646286e-005,0.000000e+000,3,9.727840e-001,0.000000e+000,,,,,,,,,,,,,,32,1,4.000000e+000,3.681183e-003,0.000000e+000,0,,0,
1524129392.301,,0.000000e+000,5.299732e+001,-7.647023e-005,0.000000e+000,3,9.718851e-001,0.000000e+000,,,,,,,,,,,,,,32,1,4.000000e+000,1.108170e-002,0.000000e+000,0,,0,
1524129430.701,,0.000000e+000,5.299547e+001,-7.654131e-005,0.000000e+000,3,9.733273e-001,0.000000e+000,,,,,,,,,,,,,,32,1,4.000000e+000,7.381439e-003,0.000000e+000,0,,0,
1524129467.781,,0.000000e+000,5.299670e+001,-7.655581e-005,0.000000e+000,3,9.736607e-001,0.000000e+000,,,,,,,,,,,,,,32,1,4.000000e+000,0.000000e+000,0.000000e+000,0,,0,
1524129505.651,,0.000000e+000,5.300162e+001,-7.659047e-005,0.000000e+000,3,9.737592e-001,0.000000e+000,,,,,,,,,,,,,,32,1,4.000000e+000,4.920959e-003,0.000000e+000,0,,0,
1524129542.671,,0.000000e+000,5.299609e+001,-7.657211e-005,0.000000e+000,3,9.724863e-001,0.000000e+000,,,,,,,,,,,,,,32,1,4.000000e+000,3.688812e-003,0.000000e+000,0,,0,
1524129580.441,,0.000000e+000,5.299916e+001,-7.658858e-005,0.000000e+000,3,9.725713e-001,0.000000e+000,,,,,,,,,,,,,,32,1,4.000000e+000,0.000000e+000,0.000000e+000,0,,0,
1524129617.661,,0.000000e+000,5.299609e+001,-7.666429e-005,0.000000e+000,3,9.723160e-001,0.000000e+000,,,,,,,,,,,,,,32,1,4.000000e+000,1.220703e-003,0.000000e+000,0,,0,
1524129655.931,,0.000000e+000,5.300040e+001,-7.664625e-005,0.000000e+000,3,9.728137e-001,0.000000e+000,,,,,,,,,,,,,,32,1,4.000000e+000,2.468109e-003,0.000000e+000,0,,0,
1524129693.181,,0.000000e+000,5.299670e+001,-7.661062e-005,0.000000e+000,3,9.720930e-001,0.000000e+000,,,,,,,,,,,,,,32,1,4.000000e+000,2.449036e-003,0.000000e+000,0,,0,
1524129731.421,,0.000000e+000,5.299978e+001,-7.664043e-005,0.000000e+000,3,9.732887e-001,0.000000e+000,,,,,,,,,,,,,,32,1,4.000000e+000,1.239777e-003,0.000000e+000,0,,0,
1524129768.511,,0.000000e+000,5.300040e+001,-7.665650e-005,0.000000e+000,3,9.728601e-001,0.000000e+000,,,,,,,,,,,,,,32,1,4.000000e+000,2.468109e-003,0.000000e+000,0,,0,
1524129806.351,,0.000000e+000,5.299239e+001,-7.664246e-005,0.000000e+000,3,9.735399e-001,0.000000e+000,,,,,,,,,,,,,,32,1,4.000000e+000,8.609772e-003,0.000000e+000,0,,0,
1524129843.531,,0.000000e+000,5.299731e+001,-7.663861e-005,0.000000e+000,3,9.727226e-001,0.000000e+000,,,,,,,,,,,,,,32,1,4.000000e+000,1.228333e-003,0.000000e+000,0,,0,
1524129881.352,,0.000000e+000,5.299731e+001,-7.675516e-005,0.000000e+000,3,9.724391e-001,0.000000e+000,,,,,,,,,,,,,,32,1,4.000000e+000,1.228333e-003,0.000000e+000,0,,0,
1524129919.552,,0.000000e+000,5.300471e+001,-7.672836e-005,0.000000e+000,3,9.728709e-001,0.000000e+000,,,,,,,,,,,,,,32,1,4.000000e+000,3.688812e-003,0.000000e+000,0,,0,
1524129957.292,,0.000000e+000,5.299548e+001,-7.679356e-005,0.000000e+000,3,9.726712e-001,0.000000e+000,,,,,,,,,,,,,,32,1,4.000000e+000,0.000000e+000,0.000000e+000,0,,0,
1524129994.582,,0.000000e+000,5.300101e+001,-7.678188e-005,0.000000e+000,3,9.732103e-001,0.000000e+000,,,,,,,,,,,,,,32,1,4.000000e+000,3.700256e-003,0.000000e+000,0,,0,
1524130031.782,,0.000000e+000,5.300285e+001,-7.687552e-005,0.000000e+000,3,9.732995e-001,0.000000e+000,,,,,,,,,,,,,,32,1,4.000000e+000,7.389069e-003,0.000000e+000,0,,0,
1524130069.702,,0.000000e+000,5.299916e+001,-7.683240e-005,0.000000e+000,3,9.730343e-001,0.000000e+000,,,,,,,,,,,,,,32,1,4.000000e+000,0.000000e+000,0.000000e+000,0,,0,
1524130107.862,,0.000000e+000,5.300163e+001,-7.692141e-005,0.000000e+000,3,9.733852e-001,0.000000e+000,,,,,,,,,,,,,,32,1,4.000000e+000,2.460480e-003,0.000000e+000,0,,0,
1524130144.632,,0.000000e+000,5.299855e+001,-7.692585e-005,0.000000e+000,3,9.730510e-001,0.000000e+000,,,,,,,,,,,,,,32,1,4.000000e+000,3.700256e-003,0.000000e+000,0,,0,
1524130182.922,,0.000000e+000,5.299609e+001,-7.696151e-005,0.000000e+000,3,9.734728e-001,0.000000e+000,,,,,,,,,,,,,,32,1,4.000000e+000,3.688812e-003,0.000000e+000,0,,0,
1524130221.052,,0.000000e+000,5.299978e+001,-7.689840e-005,0.000000e+000,3,9.727758e-001,0.000000e+000,,,,,,,,,,,,,,32,1,4.000000e+000,1.239777e-003,0.000000e+000,0,,0,
1524130259.282,,0.000000e+000,5.299609e+001,-7.694233e-005,0.000000e+000,3,9.728322e-001,0.000000e+000,,,,,,,,,,,,,,32,1,4.000000e+000,3.688812e-003,0.000000e+000,0,,0,
1524130296.412,,0.000000e+000,5.300040e+001,-7.697844e-005,0.000000e+000,3,9.728159e-001,0.000000e+000,,,,,,,,,,,,,,32,1,4.000000e+000,2.468109e-003,0.000000e+000,0,,0,
1524130334.832,,0.000000e+000,5.299731e+001,-7.697401e-005,0.000000e+000,3,9.731187e-001,0.000000e+000,,,,,,,,,,,,,,32,1,4.000000e+000,1.228333e-003,0.000000e+000,0,,0,
1524130371.792,,0.000000e+000,5.299917e+001,-7.699891e-005,0.000000e+000,3,9.719018e-001,0.000000e+000,,,,,,,,,,,,,,32,1,4.000000e+000,1.723862e-002,0.000000e+000,0,,0,
1524130409.852,,0.000000e+000,5.299855e+001,-7.702751e-005,0.000000e+000,3,9.737825e-001,0.000000e+000,,,,,,,,,,,,,,32,1,4.000000e+000,1.354218e-002,0.000000e+000,0,,0,
1524130446.902,,0.000000e+000,5.299916e+001,-7.706405e-005,0.000000e+000,3,9.740233e-001,0.000000e+000,,,,,,,,,,,,,,32,1,4.000000e+000,0.000000e+000,0.000000e+000,0,,0,
1524130484.782,,0.000000e+000,5.299486e+001,-7.707671e-005,0.000000e+000,3,9.736142e-001,0.000000e+000,,,,,,,,,,,,,,32,1,4.000000e+000,1.239777e-003,0.000000e+000,0,,0,
1524130521.812,,0.000000e+000,5.299917e+001,-7.704888e-005,0.000000e+000,3,9.732251e-001,0.000000e+000,,,,,,,,,,,,,,32,1,4.000000e+000,7.381439e-003,0.000000e+000,0,,0,
1524130560.152,,0.000000e+000,5.299854e+001,-7.702591e-005,0.000000e+000,3,9.727767e-001,0.000000e+000,,,,,,,,,,,,,,32,1,4.000000e+000,1.232147e-003,0.000000e+000,0,,0,
1524130596.743,,0.000000e+000,5.299486e+001,-7.702977e-005,0.000000e+000,3,9.728144e-001,0.000000e+000,,,,,,,,,,,,,,32,1,4.000000e+000,3.688812e-003,0.000000e+000,0,,0,
1524130634.513,,0.000000e+000,5.299978e+001,-7.707313e-005,0.000000e+000,3,9.732946e-001,0.000000e+000,,,,,,,,,,,,,,32,1,4.000000e+000,1.239777e-003,0.000000e+000,0,,0,
1524130671.693,,0.000000e+000,5.299978e+001,-7.709529e-005,0.000000e+000,3,9.729574e-001,0.000000e+000,,,,,,,,,,,,,,32,1,4.000000e+000,8.602142e-003,0.000000e+000,0,,0,
1524130710.063,,0.000000e+000,5.299732e+001,-7.707761e-005,0.000000e+000,3,9.727550e-001,0.000000e+000,,,,,,,,,,,,,,32,1,4.000000e+000,3.681183e-003,0.000000e+000,0,,0,
1524130748.443,,0.000000e+000,5.299916e+001,-7.710524e-005,0.000000e+000,3,9.728951e-001,0.000000e+000,,,,,,,,,,,,,,32,1,4.000000e+000,2.471924e-003,0.000000e+000,0,,0,
1524130786.033,,0.000000e+000,5.299978e+001,-7.713644e-005,0.000000e+000,3,9.723126e-001,0.000000e+000,,,,,,,,,,,,,,32,1,4.000000e+000,1.239777e-003,0.000000e+000,0,,0,
1524130824.493,,0.000000e+000,5.299609e+001,-7.716121e-005,0.000000e+000,3,9.741161e-001,0.000000e+000,,,,,,,,,,,,,,32,1,4.000000e+000,1.107788e-002,0.000000e+000,0,,0,
1524130861.573,,0.000000e+000,5.299855e+001,-7.719036e-005,0.000000e+000,3,9.735451e-001,0.000000e+000,,,,,,,,,,,,,,32,1,4.000000e+000,8.621216e-003,0.000000e+000,0,,0,
1524130899.443,,0.000000e+000,5.299670e+001,-7.720893e-005,0.000000e+000,3,9.734280e-001,0.000000e+000,,,,,,,,,,,,,,32,1,4.000000e+000,7.389069e-003,0.000000e+000,0,,0,
1524130937.133,,0.000000e+000,5.299731e+001,-7.729069e-005,0.000000e+000,3,9.740739e-001,0.000000e+000,,,,,,,,,,,,,,32,1,4.000000e+000,1.228333e-003,0.000000e+000,0,,0,
1524130974.243,,0.000000e+000,5.299855e+001,-7.722073e-005,0.000000e+000,3,9.728016e-001,0.000000e+000,,,,,,,,,,,,,,32,1,4.000000e+000,6.149292e-003,0.000000e+000,0,,0,
1524131011.623,,0.000000e+000,5.300040e+001,-7.725890e-005,0.000000e+000,3,9.741330e-001,0.000000e+000,,,,,,,,,,,,,,32,1,4.000000e+000,0.000000e+000,0.000000e+000,0,,0,
1524131049.893,,0.000000e+000,5.299855e+001,-7.730267e-005,0.000000e+000,3,9.727997e-001,0.000000e+000,,,,,,,,,,,,,,32,1,4.000000e+000,6.149292e-003,0.000000e+000,0,,0,
1524131087.453,,0.000000e+000,5.299547e+001,-7.726798e-005,0.000000e+000,3,9.729937e-001,0.000000e+000,,,,,,,,,,,,,,32,1,4.000000e+000,2.460480e-003,0.000000e+000,0,,0,
1524131124.773,,0.000000e+000,5.299916e+001,-7.734171e-005,0.000000e+000,3,9.737403e-001,0.000000e+000,,,,,,,,,,,,,,32,1,4.000000e+000,0.000000e+000,0.000000e+000,0,,0,
1524131162.013,,0.000000e+000,5.299609e+001,-7.727742e-005,0.000000e+000,3,9.730848e-001,0.000000e+000,,,,,,,,,,,,,,32,1,4.000000e+000,6.149292e-003,0.000000e+000,0,,0,
1524131199.063,,0.000000e+000,5.300163e+001,-7.735520e-005,0.000000e+000,3,9.733673e-001,0.000000e+000,,,,,,,,,,,,,,32,1,4.000000e+000,7.392883e-003,0.000000e+000,0,,0,
1524131236.803,,0.000000e+000,5.300101e+001,-7.736462e-005,0.000000e+000,3,9.728065e-001,0.000000e+000,,,,,,,,,,,,,,32,1,4.000000e+000,1.228333e-003,0.000000e+000,0,,0,
1524131274.063,,0.000000e+000,5.299731e+001,-7.737835e-005,0.000000e+000,3,9.720289e-001,0.000000e+000,,,,,,,,,,,,,,32,1,4.000000e+000,1.228333e-003,0.000000e+000,0,,0,
1524131311.744,,0.000000e+000,5.300040e+001,-7.740785e-005,0.000000e+000,3,9.730384e-001,0.000000e+000,,,,,,,,,,,,,,32,1,4.000000e+000,4.932404e-003,0.000000e+000,0,,0,
1524131349.004,,0.000000e+000,5.299854e+001,-7.732793e-005,0.000000e+000,3,9.721602e-001,0.000000e+000,,,,,,,,,,,,,,32,1,4.000000e+000,1.232147e-003,0.000000e+000,0,,0,
1524131387.414,,0.000000e+000,5.299363e+001,-7.734317e-005,0.000000e+000,3,9.733340e-001,0.000000e+000,,,,,,,,,,,,,,32,1,4.000000e+000,1.228333e-003,0.000000e+000,0,,0,
1524131424.424,,0.000000e+000,5.299547e+001,-7.743044e-005,0.000000e+000,3,9.734724e-001,0.000000e+000,,,,,,,,,,,,,,32,1,4.000000e+000,2.460480e-003,0.000000e+000,0,,0,
1524131462.364,,0.000000e+000,5.300162e+001,-7.746054e-005,0.000000e+000,3,9.732425e-001,0.000000e+000,,,,,,,,,,,,,,32,1,4.000000e+000,4.920959e-003,0.000000e+000,0,,0,
1524131500.024,,0.000000e+000,5.299978e+001,-7.751610e-005,0.000000e+000,3,9.738240e-001,0.000000e+000,,,,,,,,,,,,,,32,1,4.000000e+000,1.239777e-003,0.000000e+000,0,,0,
1524131537.154,,0.000000e+000,5.300040e+001,-7.750550e-005,0.000000e+000,3,9.729833e-001,0.000000e+000,,,,,,,,,,,,,,32,1,4.000000e+000,2.468109e-003,0.000000e+000,0,,0,
1524131574.254,,0.000000e+000,5.299855e+001,-7.745955e-005,0.000000e+000,3,9.722973e-001,0.000000e+000,,,,,,,,,,,,,,32,1,4.000000e+000,8.621216e-003,0.000000e+000,0,,0,
1524131612.094,,0.000000e+000,5.299609e+001,-7.751447e-005,0.000000e+000,3,9.729871e-001,0.000000e+000,,,,,,,,,,,,,,32,1,4.000000e+000,1.220703e-003,0.000000e+000,0,,0,
1524131649.214,,0.000000e+000,5.299732e+001,-7.749601e-005,0.000000e+000,3,9.729030e-001,0.000000e+000,,,,,,,,,,,,,,32,1,4.000000e+000,3.681183e-003,0.000000e+000,0,,0,
1524131687.044,,0.000000e+000,5.299793e+001,-7.754600e-005,0.000000e+000,3,9.724274e-001,0.000000e+000,,,,,,,,,,,,,,32,1,4.000000e+000,2.460480e-003,0.000000e+000,0,,0,
1524131725.224,,0.000000e+000,5.299670e+001,-7.760549e-005,0.000000e+000,3,9.728318e-001,0.000000e+000,,,,,,,,,,,,,,32,1,4.000000e+000,2.449036e-003,0.000000e+000,0,,0,
1524131763.494,,0.000000e+000,5.300347e+001,-7.756962e-005,0.000000e+000,3,9.718502e-001,0.000000e+000,,,,,,,,,,,,,,32,1,4.000000e+000,1.220703e-003,0.000000e+000,0,,0,
1524131801.534,,0.000000e+000,5.299547e+001,-7.756741e-005,0.000000e+000,3,9.729890e-001,0.000000e+000,,,,,,,,,,,,,,32,1,4.000000e+000,4.917145e-003,0.000000e+000,0,,0,
1524131838.974,,0.000000e+000,5.300532e+001,-7.761585e-005,0.000000e+000,3,9.718000e-001,0.000000e+000,,,,,,,,,,,,,,32,1,4.000000e+000,2.468109e-003,0.000000e+000,0,,0,
1524131877.044,,0.000000e+000,5.299363e+001,-7.759962e-005,0.000000e+000,3,9.733335e-001,0.000000e+000,,,,,,,,,,,,,,32,1,4.000000e+000,3.700256e-003,0.000000e+000,0,,0,
1524131913.984,,0.000000e+000,5.300101e+001,-7.767609e-005,0.000000e+000,3,9.727721e-001,0.000000e+000,,,,,,,,,,,,,,32,1,4.000000e+000,3.700256e-003,0.000000e+000,0,,0,
1524131951.994,,0.000000e+000,5.300285e+001,-7.763763e-005,0.000000e+000,3,9.736016e-001,0.000000e+000,,,,,,,,,,,,,,32,1,4.000000e+000,2.452850e-003,0.000000e+000,0,,0,
1524131988.994,,0.000000e+000,5.299609e+001,-7.767264e-005,0.000000e+000,3,9.735299e-001,0.000000e+000,,,,,,,,,,,,,,32,1,4.000000e+000,3.688812e-003,0.000000e+000,0,,0,
1524132026.945,,0.000000e+000,5.299301e+001,-7.767844e-005,0.000000e+000,3,9.734663e-001,0.000000e+000,,,,,,,,,,,,,,32,1,4.000000e+000,7.381439e-003,0.000000e+000,0,,0,
1524132063.945,,0.000000e+000,5.300039e+001,-7.774792e-005,0.000000e+000,3,9.731469e-001,0.000000e+000,,,,,,,,,,,,,,32,1,4.000000e+000,7.381439e-003,0.000000e+000,0,,0,
1524132102.095,,0.000000e+000,5.299732e+001,-7.773962e-005,0.000000e+000,3,9.736301e-001,0.000000e+000,,,,,,,,,,,,,,32,1,4.000000e+000,3.681183e-003,0.000000e+000,0,,0,
1524132139.805,,0.000000e+000,5.299854e+001,-7.771141e-005,0.000000e+000,3,9.735453e-001,0.000000e+000,,,,,,,,,,,,,,32,1,4.000000e+000,1.232147e-003,0.000000e+000,0,,0,
1524132178.305,,0.000000e+000,5.300040e+001,-7.769751e-005,0.000000e+000,3,9.720247e-001,0.000000e+000,,,,,,,,,,,,,,32,1,4.000000e+000,4.932404e-003,0.000000e+000,0,,0,
1524132216.095,,0.000000e+000,5.300101e+001,-7.770735e-005,0.000000e+000,3,9.728673e-001,0.000000e+000,,,,,,,,,,,,,,32,1,4.000000e+000,6.153107e-003,0.000000e+000,0,,0,
1524132253.685,,0.000000e+000,5.300285e+001,-7.775030e-005,0.000000e+000,3,9.720166e-001,0.000000e+000,,,,,,,,,,,,,,32,1,4.000000e+000,2.452850e-003,0.000000e+000,0,,0,