File: Experimental Raw Data/TC04-12-01K Acquisition/TC04-12-01K_VRMac_54K_6000s.dc.dat
[Header]
TITLE,MPMS DC Measurement
BYAPP,MPMS Measurement,2.1,Summary
FILEOPENTIME, 1524226577.055000 4/20/2018, 6:16:17 AM

INFO, APPNAME, MPMS MultiVu Application, Revision 1.61,  Build 082

INFO, NAME, TC04-12-01K
INFO, WEIGHT, 1.000
INFO, AREA, 1.000
INFO, LENGTH, 1.000
INFO, SHAPE, 0
INFO, COMMENT,
INFO, SEQUENCE FILE: VRMac_54K_6000s_VRMde_55K.seq


INFO, BACKGROUND DATA FILE:, None


STARTUPAXIS,X,4,LINEAR,AUTO,0.000000,0.000000
STARTUPAXIS,Y1,5,LINEAR,AUTO,0.000000,0.000000


STARTUPGROUP,Longitudinal
FIELDGROUP,Longitudinal,1,2,3,4,5,6,7,8,9,15,16,17,18,27,28
FIELDGROUP,Transverse,1,2,3,4,10,11,12,13,14,19,20,21,22,27,28

PLOT_APPEARANCE,ALL,HORZ_GRID_ON,VERT_GRID_ON,MARKERS_AND_LINES

[Data]
Time,Comment,Field (Oe),Temperature (K),Long Moment (emu),Long Scan Std Dev,Long Algorithm,Long Reg Fit,Long Percent Error (%),Trans Moment (emu),Trans Scan Std Dev,Trans Algorithm,Trans Reg Fit,Trans Percent Error (%),Long Moment [w/o ABS] (emu),Long Scan Std Dev [w/o ABS],Long Reg Fit [w/o ABS],Long Percent Error [w/o ABS] (%),Trans Moment [w/o ABS] (emu),Trans Scan Std Dev [w/o ABS],Trans Reg Fit [w/o ABS],Trans Percent Error [w/o ABS] (%),Points per Scan,Scans per Measurement,Scan Length (cm),Delta Temp (K),Rot Position (deg),Error,EC Comp. Running,Using ABS,
1524226577.055,,0.000000e+000,5.407163e+001,-5.209752e-005,0.000000e+000,3,9.700508e-001,0.000000e+000,,,,,,,,,,,,,,32,1,4.000000e+000,1.913071e-002,0.000000e+000,0,,0,
1524226602.415,,0.000000e+000,5.403974e+001,-5.611252e-005,0.000000e+000,3,9.705307e-001,0.000000e+000,,,,,,,,,,,,,,32,1,4.000000e+000,1.270294e-003,0.000000e+000,0,,0,
1524226628.425,,0.000000e+000,5.403336e+001,-5.807442e-005,0.000000e+000,3,9.697312e-001,0.000000e+000,,,,,,,,,,,,,,32,1,4.000000e+000,3.810883e-003,0.000000e+000,0,,0,
1524226653.435,,0.000000e+000,5.401489e+001,-5.949981e-005,0.000000e+000,3,9.697753e-001,0.000000e+000,,,,,,,,,,,,,,32,1,4.000000e+000,5.100250e-003,0.000000e+000,0,,0,
1524226678.335,,0.000000e+000,5.401170e+001,-6.042243e-005,0.000000e+000,3,9.696491e-001,0.000000e+000,,,,,,,,,,,,,,32,1,4.000000e+000,6.370544e-003,0.000000e+000,0,,0,
1524226728.685,,0.000000e+000,5.400216e+001,-6.188347e-005,0.000000e+000,3,9.703363e-001,0.000000e+000,,,,,,,,,,,,,,32,1,4.000000e+000,0.000000e+000,0.000000e+000,0,,0,
1524226754.435,,0.000000e+000,5.399898e+001,-6.251032e-005,0.000000e+000,3,9.707539e-001,0.000000e+000,,,,,,,,,,,,,,32,1,4.000000e+000,1.270294e-003,0.000000e+000,0,,0,
1524226779.075,,0.000000e+000,5.399898e+001,-6.301000e-005,0.000000e+000,3,9.700357e-001,0.000000e+000,,,,,,,,,,,,,,32,1,4.000000e+000,1.270294e-003,0.000000e+000,0,,0,
1524226804.675,,0.000000e+000,5.399961e+001,-6.345587e-005,0.000000e+000,3,9.715271e-001,0.000000e+000,,,,,,,,,,,,,,32,1,4.000000e+000,5.088806e-003,0.000000e+000,0,,0,
1524226829.295,,0.000000e+000,5.399770e+001,-6.379873e-005,0.000000e+000,3,9.698687e-001,0.000000e+000,,,,,,,,,,,,,,32,1,4.000000e+000,8.918762e-003,0.000000e+000,0,,0,
1524226854.895,,0.000000e+000,5.399834e+001,-6.422541e-005,0.000000e+000,3,9.716671e-001,0.000000e+000,,,,,,,,,,,,,,32,1,4.000000e+000,2.540588e-003,0.000000e+000,0,,0,
1524226880.635,,0.000000e+000,5.400471e+001,-6.450809e-005,0.000000e+000,3,9.708489e-001,0.000000e+000,,,,,,,,,,,,,,32,1,4.000000e+000,5.092621e-003,0.000000e+000,0,,0,
1524226905.715,,0.000000e+000,5.400025e+001,-6.478748e-005,0.000000e+000,3,9.716504e-001,0.000000e+000,,,,,,,,,,,,,,32,1,4.000000e+000,6.359100e-003,0.000000e+000,0,,0,
1524226930.565,,0.000000e+000,5.399898e+001,-6.515782e-005,0.000000e+000,3,9.713772e-001,0.000000e+000,,,,,,,,,,,,,,32,1,4.000000e+000,3.810883e-003,0.000000e+000,0,,0,
1524226955.845,,0.000000e+000,5.400152e+001,-6.531197e-005,0.000000e+000,3,9.706303e-001,0.000000e+000,,,,,,,,,,,,,,32,1,4.000000e+000,1.146317e-002,0.000000e+000,0,,0,
1524226981.216,,0.000000e+000,5.399961e+001,-6.561221e-005,0.000000e+000,3,9.715698e-001,0.000000e+000,,,,,,,,,,,,,,32,1,4.000000e+000,0.000000e+000,0.000000e+000,0,,0,
1524227006.036,,0.000000e+000,5.399770e+001,-6.591323e-005,0.000000e+000,3,9.714088e-001,0.000000e+000,,,,,,,,,,,,,,32,1,4.000000e+000,1.270294e-003,0.000000e+000,0,,0,
1524227031.546,,0.000000e+000,5.399898e+001,-6.610283e-005,0.000000e+000,3,9.716663e-001,0.000000e+000,,,,,,,,,,,,,,32,1,4.000000e+000,1.270294e-003,0.000000e+000,0,,0,
1524227057.276,,0.000000e+000,5.399516e+001,-6.639933e-005,0.000000e+000,3,9.712515e-001,0.000000e+000,,,,,,,,,,,,,,32,1,4.000000e+000,3.829956e-003,0.000000e+000,0,,0,
1524227082.666,,0.000000e+000,5.400152e+001,-6.648542e-005,0.000000e+000,3,9.704035e-001,0.000000e+000,,,,,,,,,,,,,,32,1,4.000000e+000,6.359100e-003,0.000000e+000,0,,0,
1524227107.626,,0.000000e+000,5.400025e+001,-6.666573e-005,0.000000e+000,3,9.699324e-001,0.000000e+000,,,,,,,,,,,,,,32,1,4.000000e+000,6.359100e-003,0.000000e+000,0,,0,
1524227132.846,,0.000000e+000,5.399961e+001,-6.693535e-005,0.000000e+000,3,9.700337e-001,0.000000e+000,,,,,,,,,,,,,,32,1,4.000000e+000,0.000000e+000,0.000000e+000,0,,0,
1524227157.876,,0.000000e+000,5.399770e+001,-6.698417e-005,0.000000e+000,3,9.704475e-001,0.000000e+000,,,,,,,,,,,,,,32,1,4.000000e+000,3.822327e-003,0.000000e+000,0,,0,
1524227182.796,,0.000000e+000,5.399325e+001,-6.725550e-005,0.000000e+000,3,9.714312e-001,0.000000e+000,,,,,,,,,,,,,,32,1,4.000000e+000,1.527023e-002,0.000000e+000,0,,0,
1524227207.526,,0.000000e+000,5.399898e+001,-6.738018e-005,0.000000e+000,3,9.712648e-001,0.000000e+000,,,,,,,,,,,,,,32,1,4.000000e+000,1.270294e-003,0.000000e+000,0,,0,
1524227232.386,,0.000000e+000,5.399897e+001,-6.759367e-005,0.000000e+000,3,9.710316e-001,0.000000e+000,,,,,,,,,,,,,,32,1,4.000000e+000,6.370544e-003,0.000000e+000,0,,0,
1524227257.226,,0.000000e+000,5.399707e+001,-6.769221e-005,0.000000e+000,3,9.705943e-001,0.000000e+000,,,,,,,,,,,,,,32,1,4.000000e+000,0.000000e+000,0.000000e+000,0,,0,
1524227282.046,,0.000000e+000,5.400343e+001,-6.778996e-005,0.000000e+000,3,9.709983e-001,0.000000e+000,,,,,,,,,,,,,,32,1,4.000000e+000,2.540588e-003,0.000000e+000,0,,0,
1524227306.906,,0.000000e+000,5.399643e+001,-6.795848e-005,0.000000e+000,3,9.718527e-001,0.000000e+000,,,,,,,,,,,,,,32,1,4.000000e+000,1.281738e-003,0.000000e+000,0,,0,
1524227332.036,,0.000000e+000,5.399770e+001,-6.808843e-005,0.000000e+000,3,9.703175e-001,0.000000e+000,,,,,,,,,,,,,,32,1,4.000000e+000,1.270294e-003,0.000000e+000,0,,0,
1524227357.086,,0.000000e+000,5.399706e+001,-6.828442e-005,0.000000e+000,3,9.715111e-001,0.000000e+000,,,,,,,,,,,,,,32,1,4.000000e+000,5.092621e-003,0.000000e+000,0,,0,
1524227382.176,,0.000000e+000,5.399643e+001,-6.835358e-005,0.000000e+000,3,9.709885e-001,0.000000e+000,,,,,,,,,,,,,,32,1,4.000000e+000,1.281738e-003,0.000000e+000,0,,0,
1524227407.186,,0.000000e+000,5.399770e+001,-6.847348e-005,0.000000e+000,3,9.708363e-001,0.000000e+000,,,,,,,,,,,,,,32,1,4.000000e+000,1.270294e-003,0.000000e+000,0,,0,
1524227432.136,,0.000000e+000,5.399834e+001,-6.858328e-005,0.000000e+000,3,9.713958e-001,0.000000e+000,,,,,,,,,,,,,,32,1,4.000000e+000,0.000000e+000,0.000000e+000,0,,0,
1524227457.206,,0.000000e+000,5.399389e+001,-6.875981e-005,0.000000e+000,3,9.719540e-001,0.000000e+000,,,,,,,,,,,,,,32,1,4.000000e+000,6.370544e-003,0.000000e+000,0,,0,
1524227483.836,,0.000000e+000,5.399389e+001,-6.878052e-005,0.000000e+000,3,9.717888e-001,0.000000e+000,,,,,,,,,,,,,,32,1,4.000000e+000,6.370544e-003,0.000000e+000,0,,0,
1524227509.256,,0.000000e+000,5.399706e+001,-6.894201e-005,0.000000e+000,3,9.717687e-001,0.000000e+000,,,,,,,,,,,,,,32,1,4.000000e+000,7.640839e-003,0.000000e+000,0,,0,
1524227534.216,,0.000000e+000,5.399643e+001,-6.901096e-005,0.000000e+000,3,9.716292e-001,0.000000e+000,,,,,,,,,,,,,,32,1,4.000000e+000,1.281738e-003,0.000000e+000,0,,0,
1524227559.686,,0.000000e+000,5.399261e+001,-6.910625e-005,0.000000e+000,3,9.718805e-001,0.000000e+000,,,,,,,,,,,,,,32,1,4.000000e+000,1.258850e-003,0.000000e+000,0,,0,
1524227584.576,,0.000000e+000,5.399961e+001,-6.918965e-005,0.000000e+000,3,9.723688e-001,0.000000e+000,,,,,,,,,,,,,,32,1,4.000000e+000,5.088806e-003,0.000000e+000,0,,0,
1524227609.406,,0.000000e+000,5.400216e+001,-6.934274e-005,0.000000e+000,3,9.722451e-001,0.000000e+000,,,,,,,,,,,,,,32,1,4.000000e+000,2.548218e-003,0.000000e+000,0,,0,
1524227634.426,,0.000000e+000,5.399580e+001,-6.943188e-005,0.000000e+000,3,9.707575e-001,0.000000e+000,,,,,,,,,,,,,,32,1,4.000000e+000,2.552032e-003,0.000000e+000,0,,0,
1524227659.366,,0.000000e+000,5.400152e+001,-6.947097e-005,0.000000e+000,3,9.707624e-001,0.000000e+000,,,,,,,,,,,,,,32,1,4.000000e+000,3.818512e-003,0.000000e+000,0,,0,
1524227684.786,,0.000000e+000,5.399706e+001,-6.959815e-005,0.000000e+000,3,9.705616e-001,0.000000e+000,,,,,,,,,,,,,,32,1,4.000000e+000,5.092621e-003,0.000000e+000,0,,0,
1524227709.837,,0.000000e+000,5.399451e+001,-6.974030e-005,0.000000e+000,3,9.711663e-001,0.000000e+000,,,,,,,,,,,,,,32,1,4.000000e+000,1.018906e-002,0.000000e+000,0,,0,
1524227734.977,,0.000000e+000,5.399516e+001,-6.973891e-005,0.000000e+000,3,9.719321e-001,0.000000e+000,,,,,,,,,,,,,,32,1,4.000000e+000,6.359100e-003,0.000000e+000,0,,0,
1524227759.957,,0.000000e+000,5.399707e+001,-6.987715e-005,0.000000e+000,3,9.701892e-001,0.000000e+000,,,,,,,,,,,,,,32,1,4.000000e+000,0.000000e+000,0.000000e+000,0,,0,
1524227785.157,,0.000000e+000,5.400152e+001,-6.993966e-005,0.000000e+000,3,9.711858e-001,0.000000e+000,,,,,,,,,,,,,,32,1,4.000000e+000,6.359100e-003,0.000000e+000,0,,0,
1524227810.187,,0.000000e+000,5.399834e+001,-7.007815e-005,0.000000e+000,3,9.727983e-001,0.000000e+000,,,,,,,,,,,,,,32,1,4.000000e+000,2.540588e-003,0.000000e+000,0,,0,
1524227834.817,,0.000000e+000,5.400597e+001,-7.017347e-005,0.000000e+000,3,9.705007e-001,0.000000e+000,,,,,,,,,,,,,,32,1,4.000000e+000,5.088806e-003,0.000000e+000,0,,0,
1524227859.787,,0.000000e+000,5.399897e+001,-7.017419e-005,0.000000e+000,3,9.709280e-001,0.000000e+000,,,,,,,,,,,,,,32,1,4.000000e+000,6.370544e-003,0.000000e+000,0,,0,
1524227885.037,,0.000000e+000,5.399452e+001,-7.029381e-005,0.000000e+000,3,9.706404e-001,0.000000e+000,,,,,,,,,,,,,,32,1,4.000000e+000,0.000000e+000,0.000000e+000,0,,0,
1524227910.527,,0.000000e+000,5.399388e+001,-7.043348e-005,0.000000e+000,3,9.724469e-001,0.000000e+000,,,,,,,,,,,,,,32,1,4.000000e+000,1.277924e-003,0.000000e+000,0,,0,
1524227935.537,,0.000000e+000,5.399580e+001,-7.041006e-005,0.000000e+000,3,9.725379e-001,0.000000e+000,,,,,,,,,,,,,,32,1,4.000000e+000,7.629395e-003,0.000000e+000,0,,0,
1524227961.557,,0.000000e+000,5.398880e+001,-7.053468e-005,0.000000e+000,3,9.719544e-001,0.000000e+000,,,,,,,,,,,,,,32,1,4.000000e+000,6.370544e-003,0.000000e+000,0,,0,
1524227986.857,,0.000000e+000,5.399388e+001,-7.067436e-005,0.000000e+000,3,9.723685e-001,0.000000e+000,,,,,,,,,,,,,,32,1,4.000000e+000,1.145935e-002,0.000000e+000,0,,0,
1524228012.157,,0.000000e+000,5.399898e+001,-7.065517e-005,0.000000e+000,3,9.714806e-001,0.000000e+000,,,,,,,,,,,,,,32,1,4.000000e+000,1.270294e-003,0.000000e+000,0,,0,
1524228037.557,,0.000000e+000,5.399516e+001,-7.074139e-005,0.000000e+000,3,9.718570e-001,0.000000e+000,,,,,,,,,,,,,,32,1,4.000000e+000,1.270294e-003,0.000000e+000,0,,0,
1524228062.407,,0.000000e+000,5.400025e+001,-7.076390e-005,0.000000e+000,3,9.722561e-001,0.000000e+000,,,,,,,,,,,,,,32,1,4.000000e+000,3.818512e-003,0.000000e+000,0,,0,
1524228087.207,,0.000000e+000,5.399834e+001,-7.087217e-005,0.000000e+000,3,9.712983e-001,0.000000e+000,,,,,,,,,,,,,,32,1,4.000000e+000,2.540588e-003,0.000000e+000,0,,0,
1524228112.027,,0.000000e+000,5.399643e+001,-7.090955e-005,0.000000e+000,3,9.718036e-001,0.000000e+000,,,,,,,,,,,,,,32,1,4.000000e+000,6.370544e-003,0.000000e+000,0,,0,
1524228136.667,,0.000000e+000,5.399643e+001,-7.097733e-005,0.000000e+000,3,9.720413e-001,0.000000e+000,,,,,,,,,,,,,,32,1,4.000000e+000,1.281738e-003,0.000000e+000,0,,0,
1524228161.487,,0.000000e+000,5.399643e+001,-7.101548e-005,0.000000e+000,3,9.720178e-001,0.000000e+000,,,,,,,,,,,,,,32,1,4.000000e+000,1.281738e-003,0.000000e+000,0,,0,
1524228186.497,,0.000000e+000,5.400088e+001,-7.110539e-005,0.000000e+000,3,9.718617e-001,0.000000e+000,,,,,,,,,,,,,,32,1,4.000000e+000,0.000000e+000,0.000000e+000,0,,0,
1524228211.147,,0.000000e+000,5.399516e+001,-7.114320e-005,0.000000e+000,3,9.719641e-001,0.000000e+000,,,,,,,,,,,,,,32,1,4.000000e+000,3.829956e-003,0.000000e+000,0,,0,
1524228236.157,,0.000000e+000,5.399707e+001,-7.121570e-005,0.000000e+000,3,9.719666e-001,0.000000e+000,,,,,,,,,,,,,,32,1,4.000000e+000,0.000000e+000,0.000000e+000,0,,0,
1524228261.017,,0.000000e+000,5.399898e+001,-7.126981e-005,0.000000e+000,3,9.716852e-001,0.000000e+000,,,,,,,,,,,,,,32,1,4.000000e+000,1.270294e-003,0.000000e+000,0,,0,
1524228285.797,,0.000000e+000,5.400089e+001,-7.134287e-005,0.000000e+000,3,9.725319e-001,0.000000e+000,,,,,,,,,,,,,,32,1,4.000000e+000,1.019287e-002,0.000000e+000,0,,0,
1524228311.227,,0.000000e+000,5.399643e+001,-7.144318e-005,0.000000e+000,3,9.723796e-001,0.000000e+000,,,,,,,,,,,,,,32,1,4.000000e+000,1.281738e-003,0.000000e+000,0,,0,
1524228336.047,,0.000000e+000,5.399770e+001,-7.142182e-005,0.000000e+000,3,9.711438e-001,0.000000e+000,,,,,,,,,,,,,,32,1,4.000000e+000,1.270294e-003,0.000000e+000,0,,0,
1524228360.907,,0.000000e+000,5.400088e+001,-7.151916e-005,0.000000e+000,3,9.712156e-001,0.000000e+000,,,,,,,,,,,,,,32,1,4.000000e+000,0.000000e+000,0.000000e+000,0,,0,
1524228385.757,,0.000000e+000,5.399770e+001,-7.155094e-005,0.000000e+000,3,9.714668e-001,0.000000e+000,,,,,,,,,,,,,,32,1,4.000000e+000,1.270294e-003,0.000000e+000,0,,0,
1524228410.558,,0.000000e+000,5.399452e+001,-7.161628e-005,0.000000e+000,3,9.719317e-001,0.000000e+000,,,,,,,,,,,,,,32,1,4.000000e+000,2.035904e-002,0.000000e+000,0,,0,
1524228435.228,,0.000000e+000,5.399961e+001,-7.163487e-005,0.000000e+000,3,9.717426e-001,0.000000e+000,,,,,,,,,,,,,,32,1,4.000000e+000,2.540588e-003,0.000000e+000,0,,0,
1524228460.258,,0.000000e+000,5.399643e+001,-7.173427e-005,0.000000e+000,3,9.716077e-001,0.000000e+000,,,,,,,,,,,,,,32,1,4.000000e+000,1.145935e-002,0.000000e+000,0,,0,
1524228485.078,,0.000000e+000,5.400215e+001,-7.174761e-005,0.000000e+000,3,9.716305e-001,0.000000e+000,,,,,,,,,,,,,,32,1,4.000000e+000,1.272964e-002,0.000000e+000,0,,0,
1524228509.938,,0.000000e+000,5.399770e+001,-7.184724e-005,0.000000e+000,3,9.715446e-001,0.000000e+000,,,,,,,,,,,,,,32,1,4.000000e+000,1.655960e-002,0.000000e+000,0,,0,
1524228534.818,,0.000000e+000,5.399898e+001,-7.183589e-005,0.000000e+000,3,9.729165e-001,0.000000e+000,,,,,,,,,,,,,,32,1,4.000000e+000,1.270294e-003,0.000000e+000,0,,0,
1524228560.148,,0.000000e+000,5.400089e+001,-7.194337e-005,0.000000e+000,3,9.715825e-001,0.000000e+000,,,,,,,,,,,,,,32,1,4.000000e+000,5.088806e-003,0.000000e+000,0,,0,
1524228584.818,,0.000000e+000,5.399706e+001,-7.203200e-005,0.000000e+000,3,9.726455e-001,0.000000e+000,,,,,,,,,,,,,,32,1,4.000000e+000,2.552032e-003,0.000000e+000,0,,0,
1524228609.878,,0.000000e+000,5.400024e+001,-7.202753e-005,0.000000e+000,3,9.714590e-001,0.000000e+000,,,,,,,,,,,,,,32,1,4.000000e+000,8.911133e-003,0.000000e+000,0,,0,
1524228634.808,,0.000000e+000,5.400089e+001,-7.206303e-005,0.000000e+000,3,9.715918e-001,0.000000e+000,,,,,,,,,,,,,,32,1,4.000000e+000,2.548218e-003,0.000000e+000,0,,0,
1524228660.658,,0.000000e+000,5.399834e+001,-7.216610e-005,0.000000e+000,3,9.713801e-001,0.000000e+000,,,,,,,,,,,,,,32,1,4.000000e+000,7.640839e-003,0.000000e+000,0,,0,
1524228685.508,,0.000000e+000,5.399643e+001,-7.215825e-005,0.000000e+000,3,9.729427e-001,0.000000e+000,,,,,,,,,,,,,,32,1,4.000000e+000,3.822327e-003,0.000000e+000,0,,0,
1524228711.108,,0.000000e+000,5.400025e+001,-7.228568e-005,0.000000e+000,3,9.728286e-001,0.000000e+000,,,,,,,,,,,,,,32,1,4.000000e+000,3.818512e-003,0.000000e+000,0,,0,
1524228735.828,,0.000000e+000,5.400089e+001,-7.222559e-005,0.000000e+000,3,9.720258e-001,0.000000e+000,,,,,,,,,,,,,,32,1,4.000000e+000,7.629395e-003,0.000000e+000,0,,0,
1524228760.388,,0.000000e+000,5.399580e+001,-7.227282e-005,0.000000e+000,3,9.715495e-001,0.000000e+000,,,,,,,,,,,,,,32,1,4.000000e+000,2.552032e-003,0.000000e+000,0,,0,
1524228786.138,,0.000000e+000,5.399516e+001,-7.232756e-005,0.000000e+000,3,9.712207e-001,0.000000e+000,,,,,,,,,,,,,,32,1,4.000000e+000,1.270294e-003,0.000000e+000,0,,0,
1524228812.018,,0.000000e+000,5.400216e+001,-7.241365e-005,0.000000e+000,3,9.712608e-001,0.000000e+000,,,,,,,,,,,,,,32,1,4.000000e+000,5.088806e-003,0.000000e+000,0,,0,
1524228837.468,,0.000000e+000,5.399451e+001,-7.252056e-005,0.000000e+000,3,9.727728e-001,0.000000e+000,,,,,,,,,,,,,,32,1,4.000000e+000,1.272964e-002,0.000000e+000,0,,0,
1524228862.128,,0.000000e+000,5.400024e+001,-7.251320e-005,0.000000e+000,3,9.726368e-001,0.000000e+000,,,,,,,,,,,,,,32,1,4.000000e+000,1.270294e-003,0.000000e+000,0,,0,
1524228887.078,,0.000000e+000,5.400216e+001,-7.254004e-005,0.000000e+000,3,9.712800e-001,0.000000e+000,,,,,,,,,,,,,,32,1,4.000000e+000,5.088806e-003,0.000000e+000,0,,0,
1524228912.008,,0.000000e+000,5.399706e+001,-7.255071e-005,0.000000e+000,3,9.714477e-001,0.000000e+000,,,,,,,,,,,,,,32,1,4.000000e+000,2.552032e-003,0.000000e+000,0,,0,
1524228937.018,,0.000000e+000,5.400152e+001,-7.263807e-005,0.000000e+000,3,9.708018e-001,0.000000e+000,,,,,,,,,,,,,,32,1,4.000000e+000,6.359100e-003,0.000000e+000,0,,0,
1524228962.008,,0.000000e+000,5.399961e+001,-7.264930e-005,0.000000e+000,3,9.725884e-001,0.000000e+000,,,,,,,,,,,,,,32,1,4.000000e+000,2.540588e-003,0.000000e+000,0,,0,
1524228986.858,,0.000000e+000,5.399706e+001,-7.273447e-005,0.000000e+000,3,9.726820e-001,0.000000e+000,,,,,,,,,,,,,,32,1,4.000000e+000,5.092621e-003,0.000000e+000,0,,0,
1524229011.708,,0.000000e+000,5.399770e+001,-7.280183e-005,0.000000e+000,3,9.724188e-001,0.000000e+000,,,,,,,,,,,,,,32,1,4.000000e+000,3.822327e-003,0.000000e+000,0,,0,
1524229036.568,,0.000000e+000,5.399834e+001,-7.278341e-005,0.000000e+000,3,9.727295e-001,0.000000e+000,,,,,,,,,,,,,,32,1,4.000000e+000,5.092621e-003,0.000000e+000,0,,0,
1524229061.408,,0.000000e+000,5.399706e+001,-7.283589e-005,0.000000e+000,3,9.717702e-001,0.000000e+000,,,,,,,,,,,,,,32,1,4.000000e+000,2.552032e-003,0.000000e+000,0,,0,
1524229086.898,,0.000000e+000,5.400152e+001,-7.285424e-005,0.000000e+000,3,9.712236e-001,0.000000e+000,,,,,,,,,,,,,,32,1,4.000000e+000,1.277924e-003,0.000000e+000,0,,0,
1524229111.598,,0.000000e+000,5.399643e+001,-7.290234e-005,0.000000e+000,3,9.725114e-001,0.000000e+000,,,,,,,,,,,,,,32,1,4.000000e+000,3.822327e-003,0.000000e+000,0,,0,
1524229136.559,,0.000000e+000,5.399134e+001,-7.291903e-005,0.000000e+000,3,9.715511e-001,0.000000e+000,,,,,,,,,,,,,,32,1,4.000000e+000,1.145935e-002,0.000000e+000,0,,0,
1524229162.399,,0.000000e+000,5.399770e+001,-7.295893e-005,0.000000e+000,3,9.724171e-001,0.000000e+000,,,,,,,,,,,,,,32,1,4.000000e+000,1.270294e-003,0.000000e+000,0,,0,
1524229186.789,,0.000000e+000,5.399834e+001,-7.295725e-005,0.000000e+000,3,9.720352e-001,0.000000e+000,,,,,,,,,,,,,,32,1,4.000000e+000,2.540588e-003,0.000000e+000,0,,0,
1524229211.919,,0.000000e+000,5.399261e+001,-7.306124e-005,0.000000e+000,3,9.707673e-001,0.000000e+000,,,,,,,,,,,,,,32,1,4.000000e+000,3.818512e-003,0.000000e+000,0,,0,
1524229236.959,,0.000000e+000,5.399516e+001,-7.306960e-005,0.000000e+000,3,9.729657e-001,0.000000e+000,,,,,,,,,,,,,,32,1,4.000000e+000,6.359100e-003,0.000000e+000,0,,0,
1524229261.809,,0.000000e+000,5.399707e+001,-7.311927e-005,0.000000e+000,3,9.718812e-001,0.000000e+000,,,,,,,,,,,,,,32,1,4.000000e+000,0.000000e+000,0.000000e+000,0,,0,
1524229286.609,,0.000000e+000,5.399516e+001,-7.312567e-005,0.000000e+000,3,9.717127e-001,0.000000e+000,,,,,,,,,,,,,,32,1,4.000000e+000,6.359100e-003,0.000000e+000,0,,0,
1524229311.449,,0.000000e+000,5.399898e+001,-7.316636e-005,0.000000e+000,3,9.715432e-001,0.000000e+000,,,,,,,,,,,,,,32,1,4.000000e+000,3.810883e-003,0.000000e+000,0,,0,
1524229336.209,,0.000000e+000,5.399261e+001,-7.324058e-005,0.000000e+000,3,9.714646e-001,0.000000e+000,,,,,,,,,,,,,,32,1,4.000000e+000,8.918762e-003,0.000000e+000,0,,0,
1524229361.159,,0.000000e+000,5.399961e+001,-7.323291e-005,0.000000e+000,3,9.719446e-001,0.000000e+000,,,,,,,,,,,,,,32,1,4.000000e+000,0.000000e+000,0.000000e+000,0,,0,
1524229386.819,,0.000000e+000,5.400216e+001,-7.326430e-005,0.000000e+000,3,9.721261e-001,0.000000e+000,,,,,,,,,,,,,,32,1,4.000000e+000,0.000000e+000,0.000000e+000,0,,0,
1524229411.999,,0.000000e+000,5.399706e+001,-7.342688e-005,0.000000e+000,3,9.727562e-001,0.000000e+000,,,,,,,,,,,,,,32,1,4.000000e+000,2.552032e-003,0.000000e+000,0,,0,
1524229437.229,,0.000000e+000,5.399706e+001,-7.341291e-005,0.000000e+000,3,9.728072e-001,0.000000e+000,,,,,,,,,,,,,,32,1,4.000000e+000,2.552032e-003,0.000000e+000,0,,0,
1524229462.769,,0.000000e+000,5.400152e+001,-7.342832e-005,0.000000e+000,3,9.722041e-001,0.000000e+000,,,,,,,,,,,,,,32,1,4.000000e+000,3.818512e-003,0.000000e+000,0,,0,
1524229487.719,,0.000000e+000,5.399451e+001,-7.348103e-005,0.000000e+000,3,9.721044e-001,0.000000e+000,,,,,,,,,,,,,,32,1,4.000000e+000,2.548218e-003,0.000000e+000,0,,0,
1524229512.839,,0.000000e+000,5.400024e+001,-7.347227e-005,0.000000e+000,3,9.726543e-001,0.000000e+000,,,,,,,,,,,,,,32,1,4.000000e+000,1.270294e-003,0.000000e+000,0,,0,
1524229538.299,,0.000000e+000,5.399388e+001,-7.345917e-005,0.000000e+000,3,9.717001e-001,0.000000e+000,,,,,,,,,,,,,,32,1,4.000000e+000,1.145935e-002,0.000000e+000,0,,0,
1524229563.679,,0.000000e+000,5.399961e+001,-7.347347e-005,0.000000e+000,3,9.721473e-001,0.000000e+000,,,,,,,,,,,,,,32,1,4.000000e+000,0.000000e+000,0.000000e+000,0,,0,
1524229589.089,,0.000000e+000,5.399133e+001,-7.356991e-005,0.000000e+000,3,9.718748e-001,0.000000e+000,,,,,,,,,,,,,,32,1,4.000000e+000,3.818512e-003,0.000000e+000,0,,0,
1524229614.699,,0.000000e+000,5.399643e+001,-7.358412e-005,0.000000e+000,3,9.721144e-001,0.000000e+000,,,,,,,,,,,,,,32,1,4.000000e+000,1.145935e-002,0.000000e+000,0,,0,
1524229640.059,,0.000000e+000,5.400024e+001,-7.362138e-005,0.000000e+000,3,9.721954e-001,0.000000e+000,,,,,,,,,,,,,,32,1,4.000000e+000,1.270294e-003,0.000000e+000,0,,0,
1524229665.599,,0.000000e+000,5.400025e+001,-7.370565e-005,0.000000e+000,3,9.712328e-001,0.000000e+000,,,,,,,,,,,,,,32,1,4.000000e+000,6.359100e-003,0.000000e+000,0,,0,
1524229690.439,,0.000000e+000,5.399834e+001,-7.372291e-005,0.000000e+000,3,9.710747e-001,0.000000e+000,,,,,,,,,,,,,,32,1,4.000000e+000,2.540588e-003,0.000000e+000,0,,0,
1524229715.299,,0.000000e+000,5.399770e+001,-7.372686e-005,0.000000e+000,3,9.713527e-001,0.000000e+000,,,,,,,,,,,,,,32,1,4.000000e+000,1.910019e-002,0.000000e+000,0,,0,
1524229740.279,,0.000000e+000,5.400089e+001,-7.375231e-005,0.000000e+000,3,9.708545e-001,0.000000e+000,,,,,,,,,,,,,,32,1,4.000000e+000,5.088806e-003,0.000000e+000,0,,0,
1524229765.609,,0.000000e+000,5.400025e+001,-7.374876e-005,0.000000e+000,3,9.714482e-001,0.000000e+000,,,,,,,,,,,,,,32,1,4.000000e+000,3.818512e-003,0.000000e+000,0,,0,
1524229790.739,,0.000000e+000,5.399643e+001,-7.380851e-005,0.000000e+000,3,9.714150e-001,0.000000e+000,,,,,,,,,,,,,,32,1,4.000000e+000,6.370544e-003,0.000000e+000,0,,0,
1524229815.429,,0.000000e+000,5.399707e+001,-7.379239e-005,0.000000e+000,3,9.717718e-001,0.000000e+000,,,,,,,,,,,,,,32,1,4.000000e+000,1.017761e-002,0.000000e+000,0,,0,
1524229840.610,,0.000000e+000,5.399580e+001,-7.386714e-005,0.000000e+000,3,9.712975e-001,0.000000e+000,,,,,,,,,,,,,,32,1,4.000000e+000,2.552032e-003,0.000000e+000,0,,0,
1524229865.650,,0.000000e+000,5.399643e+001,-7.391022e-005,0.000000e+000,3,9.720361e-001,0.000000e+000,,,,,,,,,,,,,,32,1,4.000000e+000,1.281738e-003,0.000000e+000,0,,0,
1524229890.360,,0.000000e+000,5.398751e+001,-7.397807e-005,0.000000e+000,3,9.717575e-001,0.000000e+000,,,,,,,,,,,,,,32,1,4.000000e+000,1.400757e-002,0.000000e+000,0,,0,
1524229915.290,,0.000000e+000,5.399770e+001,-7.398950e-005,0.000000e+000,3,9.718382e-001,0.000000e+000,,,,,,,,,,,,,,32,1,4.000000e+000,1.270294e-003,0.000000e+000,0,,0,
1524229940.130,,0.000000e+000,5.399770e+001,-7.397329e-005,0.000000e+000,3,9.711639e-001,0.000000e+000,,,,,,,,,,,,,,32,1,4.000000e+000,1.270294e-003,0.000000e+000,0,,0,
1524229965.620,,0.000000e+000,5.400089e+001,-7.404437e-005,0.000000e+000,3,9.727976e-001,0.000000e+000,,,,,,,,,,,,,,32,1,4.000000e+000,2.548218e-003,0.000000e+000,0,,0,
1524229991.480,,0.000000e+000,5.399834e+001,-7.406345e-005,0.000000e+000,3,9.732192e-001,0.000000e+000,,,,,,,,,,,,,,32,1,4.000000e+000,0.000000e+000,0.000000e+000,0,,0,
1524230015.820,,0.000000e+000,5.399961e+001,-7.417658e-005,0.000000e+000,3,9.740954e-001,0.000000e+000,,,,,,,,,,,,,,32,1,4.000000e+000,0.000000e+000,0.000000e+000,0,,0,
1524230041.000,,0.000000e+000,5.399579e+001,-7.409953e-005,0.000000e+000,3,9.730895e-001,0.000000e+000,,,,,,,,,,,,,,32,1,4.000000e+000,1.781845e-002,0.000000e+000,0,,0,
1524230065.950,,0.000000e+000,5.399706e+001,-7.419446e-005,0.000000e+000,3,9.719245e-001,0.000000e+000,,,,,,,,,,,,,,32,1,4.000000e+000,2.552032e-003,0.000000e+000,0,,0,
1524230091.460,,0.000000e+000,5.399643e+001,-7.421009e-005,0.000000e+000,3,9.730897e-001,0.000000e+000,,,,,,,,,,,,,,32,1,4.000000e+000,1.281738e-003,0.000000e+000,0,,0,
1524230116.970,,0.000000e+000,5.399961e+001,-7.419085e-005,0.000000e+000,3,9.717913e-001,0.000000e+000,,,,,,,,,,,,,,32,1,4.000000e+000,7.640839e-003,0.000000e+000,0,,0,
1524230142.090,,0.000000e+000,5.400024e+001,-7.422841e-005,0.000000e+000,3,9.723299e-001,0.000000e+000,,,,,,,,,,,,,,32,1,4.000000e+000,8.911133e-003,0.000000e+000,0,,0,
1524230167.190,,0.000000e+000,5.399834e+001,-7.429820e-005,0.000000e+000,3,9.724674e-001,0.000000e+000,,,,,,,,,,,,,,32,1,4.000000e+000,2.540588e-003,0.000000e+000,0,,0,
1524230192.830,,0.000000e+000,5.399388e+001,-7.430118e-005,0.000000e+000,3,9.712101e-001,0.000000e+000,,,,,,,,,,,,,,32,1,4.000000e+000,1.277924e-003,0.000000e+000,0,,0,
1524230218.130,,0.000000e+000,5.400471e+001,-7.433404e-005,0.000000e+000,3,9.715046e-001,0.000000e+000,,,,,,,,,,,,,,32,1,4.000000e+000,5.092621e-003,0.000000e+000,0,,0,
1524230243.060,,0.000000e+000,5.399451e+001,-7.439173e-005,0.000000e+000,3,9.718016e-001,0.000000e+000,,,,,,,,,,,,,,32,1,4.000000e+000,2.548218e-003,0.000000e+000,0,,0,
1524230268.390,,0.000000e+000,5.399897e+001,-7.442060e-005,0.000000e+000,3,9.708208e-001,0.000000e+000,,,,,,,,,,,,,,32,1,4.000000e+000,8.911133e-003,0.000000e+000,0,,0,
1524230293.290,,0.000000e+000,5.399707e+001,-7.440924e-005,0.000000e+000,3,9.721693e-001,0.000000e+000,,,,,,,,,,,,,,32,1,4.000000e+000,0.000000e+000,0.000000e+000,0,,0,
1524230318.600,,0.000000e+000,5.399834e+001,-7.442221e-005,0.000000e+000,3,9.710903e-001,0.000000e+000,,,,,,,,,,,,,,32,1,4.000000e+000,2.540588e-003,0.000000e+000,0,,0,
1524230343.550,,0.000000e+000,5.400089e+001,-7.447320e-005,0.000000e+000,3,9.716578e-001,0.000000e+000,,,,,,,,,,,,,,32,1,4.000000e+000,7.629395e-003,0.000000e+000,0,,0,
1524230368.840,,0.000000e+000,5.399579e+001,-7.445764e-005,0.000000e+000,3,9.712198e-001,0.000000e+000,,,,,,,,,,,,,,32,1,4.000000e+000,5.100250e-003,0.000000e+000,0,,0,
1524230393.740,,0.000000e+000,5.399834e+001,-7.453607e-005,0.000000e+000,3,9.720538e-001,0.000000e+000,,,,,,,,,,,,,,32,1,4.000000e+000,0.000000e+000,0.000000e+000,0,,0,
1524230418.650,,0.000000e+000,5.399707e+001,-7.455520e-005,0.000000e+000,3,9.720877e-001,0.000000e+000,,,,,,,,,,,,,,32,1,4.000000e+000,0.000000e+000,0.000000e+000,0,,0,
1524230444.040,,0.000000e+000,5.399324e+001,-7.457758e-005,0.000000e+000,3,9.720218e-001,0.000000e+000,,,,,,,,,,,,,,32,1,4.000000e+000,5.088806e-003,0.000000e+000,0,,0,
1524230469.120,,0.000000e+000,5.400025e+001,-7.461831e-005,0.000000e+000,3,9.715899e-001,0.000000e+000,,,,,,,,,,,,,,32,1,4.000000e+000,6.359100e-003,0.000000e+000,0,,0,
1524230494.980,,0.000000e+000,5.399579e+001,-7.461448e-005,0.000000e+000,3,9.723785e-001,0.000000e+000,,,,,,,,,,,,,,32,1,4.000000e+000,0.000000e+000,0.000000e+000,0,,0,
1524230519.750,,0.000000e+000,5.399451e+001,-7.462900e-005,0.000000e+000,3,9.727051e-001,0.000000e+000,,,,,,,,,,,,,,32,1,4.000000e+000,1.018906e-002,0.000000e+000,0,,0,
1524230545.311,,0.000000e+000,5.399770e+001,-7.472659e-005,0.000000e+000,3,9.724257e-001,0.000000e+000,,,,,,,,,,,,,,32,1,4.000000e+000,1.270294e-003,0.000000e+000,0,,0,
1524230570.861,,0.000000e+000,5.399961e+001,-7.476394e-005,0.000000e+000,3,9.724184e-001,0.000000e+000,,,,,,,,,,,,,,32,1,4.000000e+000,1.018143e-002,0.000000e+000,0,,0,
1524230596.251,,0.000000e+000,5.399961e+001,-7.474561e-005,0.000000e+000,3,9.717200e-001,0.000000e+000,,,,,,,,,,,,,,32,1,4.000000e+000,0.000000e+000,0.000000e+000,0,,0,
1524230621.791,,0.000000e+000,5.399261e+001,-7.470268e-005,0.000000e+000,3,9.714754e-001,0.000000e+000,,,,,,,,,,,,,,32,1,4.000000e+000,1.399994e-002,0.000000e+000,0,,0,
1524230647.201,,0.000000e+000,5.399007e+001,-7.478215e-005,0.000000e+000,3,9.716724e-001,0.000000e+000,,,,,,,,,,,,,,32,1,4.000000e+000,3.829956e-003,0.000000e+000,0,,0,
1524230672.201,,0.000000e+000,5.400470e+001,-7.476078e-005,0.000000e+000,3,9.724154e-001,0.000000e+000,,,,,,,,,,,,,,32,1,4.000000e+000,7.637024e-003,0.000000e+000,0,,0,
1524230697.531,,0.000000e+000,5.399706e+001,-7.477774e-005,0.000000e+000,3,9.720270e-001,0.000000e+000,,,,,,,,,,,,,,32,1,4.000000e+000,5.092621e-003,0.000000e+000,0,,0,
1524230722.071,,0.000000e+000,5.399388e+001,-7.486141e-005,0.000000e+000,3,9.724945e-001,0.000000e+000,,,,,,,,,,,,,,32,1,4.000000e+000,1.277924e-003,0.000000e+000,0,,0,
1524230747.011,,0.000000e+000,5.400152e+001,-7.483645e-005,0.000000e+000,3,9.722270e-001,0.000000e+000,,,,,,,,,,,,,,32,1,4.000000e+000,1.277924e-003,0.000000e+000,0,,0,
1524230772.511,,0.000000e+000,5.399770e+001,-7.489967e-005,0.000000e+000,3,9.722473e-001,0.000000e+000,,,,,,,,,,,,,,32,1,4.000000e+000,3.822327e-003,0.000000e+000,0,,0,
1524230797.341,,0.000000e+000,5.399961e+001,-7.492772e-005,0.000000e+000,3,9.716599e-001,0.000000e+000,,,,,,,,,,,,,,32,1,4.000000e+000,0.000000e+000,0.000000e+000,0,,0,
1524230821.971,,0.000000e+000,5.400661e+001,-7.489944e-005,0.000000e+000,3,9.718562e-001,0.000000e+000,,,,,,,,,,,,,,32,1,4.000000e+000,3.818512e-003,0.000000e+000,0,,0,
1524230847.381,,0.000000e+000,5.399643e+001,-7.495748e-005,0.000000e+000,3,9.707495e-001,0.000000e+000,,,,,,,,,,,,,,32,1,4.000000e+000,1.281738e-003,0.000000e+000,0,,0,
1524230872.131,,0.000000e+000,5.400470e+001,-7.498731e-005,0.000000e+000,3,9.715221e-001,0.000000e+000,,,,,,,,,,,,,,32,1,4.000000e+000,1.017761e-002,0.000000e+000,0,,0,
1524230897.131,,0.000000e+000,5.399453e+001,-7.499797e-005,0.000000e+000,3,9.714141e-001,0.000000e+000,,,,,,,,,,,,,,32,1,4.000000e+000,5.088806e-003,0.000000e+000,0,,0,
1524230923.031,,0.000000e+000,5.399643e+001,-7.502867e-005,0.000000e+000,3,9.727827e-001,0.000000e+000,,,,,,,,,,,,,,32,1,4.000000e+000,6.370544e-003,0.000000e+000,0,,0,
1524230948.061,,0.000000e+000,5.399770e+001,-7.506046e-005,0.000000e+000,3,9.729189e-001,0.000000e+000,,,,,,,,,,,,,,32,1,4.000000e+000,6.362915e-003,0.000000e+000,0,,0,
1524230973.021,,0.000000e+000,5.399770e+001,-7.509732e-005,0.000000e+000,3,9.723815e-001,0.000000e+000,,,,,,,,,,,,,,32,1,4.000000e+000,3.822327e-003,0.000000e+000,0,,0,
1524230998.011,,0.000000e+000,5.399961e+001,-7.511258e-005,0.000000e+000,3,9.719282e-001,0.000000e+000,,,,,,,,,,,,,,32,1,4.000000e+000,5.088806e-003,0.000000e+000,0,,0,
1524231022.501,,0.000000e+000,5.400089e+001,-7.516437e-005,0.000000e+000,3,9.729564e-001,0.000000e+000,,,,,,,,,,,,,,32,1,4.000000e+000,7.629395e-003,0.000000e+000,0,,0,
1524231047.731,,0.000000e+000,5.400216e+001,-7.519183e-005,0.000000e+000,3,9.712408e-001,0.000000e+000,,,,,,,,,,,,,,32,1,4.000000e+000,7.640839e-003,0.000000e+000,0,,0,
1524231072.671,,0.000000e+000,5.400152e+001,-7.521373e-005,0.000000e+000,3,9.725410e-001,0.000000e+000,,,,,,,,,,,,,,32,1,4.000000e+000,3.818512e-003,0.000000e+000,0,,0,
1524231097.011,,0.000000e+000,5.399898e+001,-7.519282e-005,0.000000e+000,3,9.711479e-001,0.000000e+000,,,,,,,,,,,,,,32,1,4.000000e+000,1.270294e-003,0.000000e+000,0,,0,
1524231121.921,,0.000000e+000,5.400089e+001,-7.521110e-005,0.000000e+000,3,9.713475e-001,0.000000e+000,,,,,,,,,,,,,,32,1,4.000000e+000,2.548218e-003,0.000000e+000,0,,0,
1524231147.101,,0.000000e+000,5.399898e+001,-7.517508e-005,0.000000e+000,3,9.709240e-001,0.000000e+000,,,,,,,,,,,,,,32,1,4.000000e+000,3.810883e-003,0.000000e+000,0,,0,
1524231172.051,,0.000000e+000,5.400279e+001,-7.519523e-005,0.000000e+000,3,9.714046e-001,0.000000e+000,,,,,,,,,,,,,,32,1,4.000000e+000,1.270294e-003,0.000000e+000,0,,0,
1524231196.851,,0.000000e+000,5.399961e+001,-7.525973e-005,0.000000e+000,3,9.710862e-001,0.000000e+000,,,,,,,,,,,,,,32,1,4.000000e+000,7.640839e-003,0.000000e+000,0,,0,
1524231221.751,,0.000000e+000,5.399579e+001,-7.529126e-005,0.000000e+000,3,9.708902e-001,0.000000e+000,,,,,,,,,,,,,,32,1,4.000000e+000,1.018143e-002,0.000000e+000,0,,0,
1524231247.021,,0.000000e+000,5.399770e+001,-7.530132e-005,0.000000e+000,3,9.709715e-001,0.000000e+000,,,,,,,,,,,,,,32,1,4.000000e+000,3.822327e-003,0.000000e+000,0,,0,
1524231272.552,,0.000000e+000,5.399898e+001,-7.532886e-005,0.000000e+000,3,9.723591e-001,0.000000e+000,,,,,,,,,,,,,,32,1,4.000000e+000,3.810883e-003,0.000000e+000,0,,0,
1524231297.892,,0.000000e+000,5.399834e+001,-7.535351e-005,0.000000e+000,3,9.728097e-001,0.000000e+000,,,,,,,,,,,,,,32,1,4.000000e+000,2.540588e-003,0.000000e+000,0,,0,
1524231322.472,,0.000000e+000,5.400024e+001,-7.533501e-005,0.000000e+000,3,9.720786e-001,0.000000e+000,,,,,,,,,,,,,,32,1,4.000000e+000,1.270294e-003,0.000000e+000,0,,0,
1524231347.622,,0.000000e+000,5.399834e+001,-7.539500e-005,0.000000e+000,3,9.727398e-001,0.000000e+000,,,,,,,,,,,,,,32,1,4.000000e+000,7.640839e-003,0.000000e+000,0,,0,
1524231372.972,,0.000000e+000,5.399834e+001,-7.543928e-005,0.000000e+000,3,9.723232e-001,0.000000e+000,,,,,,,,,,,,,,32,1,4.000000e+000,2.540588e-003,0.000000e+000,0,,0,
1524231397.792,,0.000000e+000,5.399579e+001,-7.544894e-005,0.000000e+000,3,9.725444e-001,0.000000e+000,,,,,,,,,,,,,,32,1,4.000000e+000,0.000000e+000,0.000000e+000,0,,0,
1524231422.402,,0.000000e+000,5.399770e+001,-7.541945e-005,0.000000e+000,3,9.713261e-001,0.000000e+000,,,,,,,,,,,,,,32,1,4.000000e+000,1.270294e-003,0.000000e+000,0,,0,
1524231448.022,,0.000000e+000,5.399324e+001,-7.545662e-005,0.000000e+000,3,9.723029e-001,0.000000e+000,,,,,,,,,,,,,,32,1,4.000000e+000,0.000000e+000,0.000000e+000,0,,0,
1524231473.772,,0.000000e+000,5.400216e+001,-7.549681e-005,0.000000e+000,3,9.720749e-001,0.000000e+000,,,,,,,,,,,,,,32,1,4.000000e+000,0.000000e+000,0.000000e+000,0,,0,
1524231498.872,,0.000000e+000,5.399706e+001,-7.549199e-005,0.000000e+000,3,9.724738e-001,0.000000e+000,,,,,,,,,,,,,,32,1,4.000000e+000,2.552032e-003,0.000000e+000,0,,0,
1524231524.142,,0.000000e+000,5.399643e+001,-7.552075e-005,0.000000e+000,3,9.721799e-001,0.000000e+000,,,,,,,,,,,,,,32,1,4.000000e+000,6.370544e-003,0.000000e+000,0,,0,
1524231549.332,,0.000000e+000,5.399770e+001,-7.552337e-005,0.000000e+000,3,9.721966e-001,0.000000e+000,,,,,,,,,,,,,,32,1,4.000000e+000,1.270294e-003,0.000000e+000,0,,0,
1524231574.492,,0.000000e+000,5.399451e+001,-7.557438e-005,0.000000e+000,3,9.724630e-001,0.000000e+000,,,,,,,,,,,,,,32,1,4.000000e+000,2.548218e-003,0.000000e+000,0,,0,
1524231600.302,,0.000000e+000,5.399007e+001,-7.562710e-005,0.000000e+000,3,9.724123e-001,0.000000e+000,,,,,,,,,,,,,,32,1,4.000000e+000,3.829956e-003,0.000000e+000,0,,0,
1524231625.522,,0.000000e+000,5.399388e+001,-7.562941e-005,0.000000e+000,3,9.711588e-001,0.000000e+000,,,,,,,,,,,,,,32,1,4.000000e+000,1.277924e-003,0.000000e+000,0,,0,
1524231650.492,,0.000000e+000,5.400025e+001,-7.560580e-005,0.000000e+000,3,9.718499e-001,0.000000e+000,,,,,,,,,,,,,,32,1,4.000000e+000,3.818512e-003,0.000000e+000,0,,0,
1524231675.912,,0.000000e+000,5.399961e+001,-7.564361e-005,0.000000e+000,3,9.719223e-001,0.000000e+000,,,,,,,,,,,,,,32,1,4.000000e+000,2.540588e-003,0.000000e+000,0,,0,
1524231700.852,,0.000000e+000,5.400089e+001,-7.565352e-005,0.000000e+000,3,9.715645e-001,0.000000e+000,,,,,,,,,,,,,,32,1,4.000000e+000,1.019287e-002,0.000000e+000,0,,0,
1524231725.792,,0.000000e+000,5.399770e+001,-7.564000e-005,0.000000e+000,3,9.718481e-001,0.000000e+000,,,,,,,,,,,,,,32,1,4.000000e+000,3.822327e-003,0.000000e+000,0,,0,
1524231750.552,,0.000000e+000,5.399389e+001,-7.566513e-005,0.000000e+000,3,9.713570e-001,0.000000e+000,,,,,,,,,,,,,,32,1,4.000000e+000,6.370544e-003,0.000000e+000,0,,0,
1524231775.302,,0.000000e+000,5.399516e+001,-7.571140e-005,0.000000e+000,3,9.711665e-001,0.000000e+000,,,,,,,,,,,,,,32,1,4.000000e+000,1.270294e-003,0.000000e+000,0,,0,
1524231800.212,,0.000000e+000,5.399325e+001,-7.574863e-005,0.000000e+000,3,9.714292e-001,0.000000e+000,,,,,,,,,,,,,,32,1,4.000000e+000,7.648468e-003,0.000000e+000,0,,0,
1524231826.132,,0.000000e+000,5.400089e+001,-7.583969e-005,0.000000e+000,3,9.728486e-001,0.000000e+000,,,,,,,,,,,,,,32,1,4.000000e+000,5.088806e-003,0.000000e+000,0,,0,
1524231850.762,,0.000000e+000,5.399579e+001,-7.579287e-005,0.000000e+000,3,9.711084e-001,0.000000e+000,,,,,,,,,,,,,,32,1,4.000000e+000,0.000000e+000,0.000000e+000,0,,0,
1524231875.722,,0.000000e+000,5.399643e+001,-7.581292e-005,0.000000e+000,3,9.721797e-001,0.000000e+000,,,,,,,,,,,,,,32,1,4.000000e+000,1.281738e-003,0.000000e+000,0,,0,
1524231888.442,,0.000000e+000,5.400025e+001,-7.578733e-005,0.000000e+000,3,9.716290e-001,0.000000e+000,,,,,,,,,,,,,,32,1,4.000000e+000,3.818512e-003,0.000000e+000,0,,0,