File: Experimental Raw Data/TC04-12-01K Acquisition/TC04-12-01K_VRMac_55K_6000s.dc.dat
[Header]
TITLE,MPMS DC Measurement
BYAPP,MPMS Measurement,2.1,Summary
FILEOPENTIME, 1524044899.965000 4/18/2018, 3:48:19 AM

INFO, APPNAME, MPMS MultiVu Application, Revision 1.61,  Build 082

INFO, NAME, TC04-12-01K
INFO, WEIGHT, 1.000
INFO, AREA, 1.000
INFO, LENGTH, 1.000
INFO, SHAPE, 0
INFO, COMMENT,
INFO, SEQUENCE FILE: VRMac_55K_6000s_VRMde_55K.seq


INFO, BACKGROUND DATA FILE:, None


STARTUPAXIS,X,4,LINEAR,AUTO,0.000000,0.000000
STARTUPAXIS,Y1,5,LINEAR,AUTO,0.000000,0.000000


STARTUPGROUP,Longitudinal
FIELDGROUP,Longitudinal,1,2,3,4,5,6,7,8,9,15,16,17,18,27,28
FIELDGROUP,Transverse,1,2,3,4,10,11,12,13,14,19,20,21,22,27,28

PLOT_APPEARANCE,ALL,HORZ_GRID_ON,VERT_GRID_ON,MARKERS_AND_LINES

[Data]
Time,Comment,Field (Oe),Temperature (K),Long Moment (emu),Long Scan Std Dev,Long Algorithm,Long Reg Fit,Long Percent Error (%),Trans Moment (emu),Trans Scan Std Dev,Trans Algorithm,Trans Reg Fit,Trans Percent Error (%),Long Moment [w/o ABS] (emu),Long Scan Std Dev [w/o ABS],Long Reg Fit [w/o ABS],Long Percent Error [w/o ABS] (%),Trans Moment [w/o ABS] (emu),Trans Scan Std Dev [w/o ABS],Trans Reg Fit [w/o ABS],Trans Percent Error [w/o ABS] (%),Points per Scan,Scans per Measurement,Scan Length (cm),Delta Temp (K),Rot Position (deg),Error,EC Comp. Running,Using ABS,
1524044899.965,,0.000000e+000,5.508534e+001,-5.397700e-005,0.000000e+000,3,9.743240e-001,0.000000e+000,,,,,,,,,,,,,,32,1,4.000000e+000,1.845932e-002,0.000000e+000,0,,0,
1524044924.815,,0.000000e+000,5.505041e+001,-5.816382e-005,0.000000e+000,3,9.758423e-001,0.000000e+000,,,,,,,,,,,,,,32,1,4.000000e+000,1.977158e-002,0.000000e+000,0,,0,
1524044949.435,,0.000000e+000,5.502143e+001,-6.024399e-005,0.000000e+000,3,9.748312e-001,0.000000e+000,,,,,,,,,,,,,,32,1,4.000000e+000,1.712036e-002,0.000000e+000,0,,0,
1524044974.455,,0.000000e+000,5.501353e+001,-6.161533e-005,0.000000e+000,3,9.758666e-001,0.000000e+000,,,,,,,,,,,,,,32,1,4.000000e+000,3.959656e-003,0.000000e+000,0,,0,
1524044999.915,,0.000000e+000,5.500432e+001,-6.263174e-005,0.000000e+000,3,9.760817e-001,0.000000e+000,,,,,,,,,,,,,,32,1,4.000000e+000,1.300812e-003,0.000000e+000,0,,0,
1524045025.645,,0.000000e+000,5.500037e+001,-6.345814e-005,0.000000e+000,3,9.779759e-001,0.000000e+000,,,,,,,,,,,,,,32,1,4.000000e+000,3.959656e-003,0.000000e+000,0,,0,
1524045050.885,,0.000000e+000,5.499445e+001,-6.414139e-005,0.000000e+000,3,9.756973e-001,0.000000e+000,,,,,,,,,,,,,,32,1,4.000000e+000,2.628326e-003,0.000000e+000,0,,0,
1524045076.085,,0.000000e+000,5.499905e+001,-6.473925e-005,0.000000e+000,3,9.752516e-001,0.000000e+000,,,,,,,,,,,,,,32,1,4.000000e+000,3.948212e-003,0.000000e+000,0,,0,
1524045101.675,,0.000000e+000,5.500103e+001,-6.519235e-005,0.000000e+000,3,9.751598e-001,0.000000e+000,,,,,,,,,,,,,,32,1,4.000000e+000,5.279541e-003,0.000000e+000,0,,0,
1524045126.875,,0.000000e+000,5.499905e+001,-6.556463e-005,0.000000e+000,3,9.750367e-001,0.000000e+000,,,,,,,,,,,,,,32,1,4.000000e+000,3.948212e-003,0.000000e+000,0,,0,
1524045152.055,,0.000000e+000,5.499905e+001,-6.609507e-005,0.000000e+000,3,9.760478e-001,0.000000e+000,,,,,,,,,,,,,,32,1,4.000000e+000,1.319885e-003,0.000000e+000,0,,0,
1524045177.165,,0.000000e+000,5.499577e+001,-6.645804e-005,0.000000e+000,3,9.737505e-001,0.000000e+000,,,,,,,,,,,,,,32,1,4.000000e+000,7.888794e-003,0.000000e+000,0,,0,
1524045202.505,,0.000000e+000,5.499775e+001,-6.681121e-005,0.000000e+000,3,9.743824e-001,0.000000e+000,,,,,,,,,,,,,,32,1,4.000000e+000,9.208679e-003,0.000000e+000,0,,0,
1524045228.015,,0.000000e+000,5.499380e+001,-6.712625e-005,0.000000e+000,3,9.741431e-001,0.000000e+000,,,,,,,,,,,,,,32,1,4.000000e+000,3.948212e-003,0.000000e+000,0,,0,
1524045253.175,,0.000000e+000,5.500169e+001,-6.739630e-005,0.000000e+000,3,9.765534e-001,0.000000e+000,,,,,,,,,,,,,,32,1,4.000000e+000,3.959656e-003,0.000000e+000,0,,0,
1524045278.325,,0.000000e+000,5.499906e+001,-6.761810e-005,0.000000e+000,3,9.746155e-001,0.000000e+000,,,,,,,,,,,,,,32,1,4.000000e+000,6.580353e-003,0.000000e+000,0,,0,
1524045303.405,,0.000000e+000,5.499840e+001,-6.793330e-005,0.000000e+000,3,9.752570e-001,0.000000e+000,,,,,,,,,,,,,,32,1,4.000000e+000,2.628326e-003,0.000000e+000,0,,0,
1524045328.295,,0.000000e+000,5.500301e+001,-6.821732e-005,0.000000e+000,3,9.754459e-001,0.000000e+000,,,,,,,,,,,,,,32,1,4.000000e+000,1.319885e-003,0.000000e+000,0,,0,
1524045353.725,,0.000000e+000,5.499511e+001,-6.843218e-005,0.000000e+000,3,9.748818e-001,0.000000e+000,,,,,,,,,,,,,,32,1,4.000000e+000,6.568909e-003,0.000000e+000,0,,0,
1524045379.535,,0.000000e+000,5.499708e+001,-6.858703e-005,0.000000e+000,3,9.753568e-001,0.000000e+000,,,,,,,,,,,,,,32,1,4.000000e+000,0.000000e+000,0.000000e+000,0,,0,
1524045404.555,,0.000000e+000,5.500761e+001,-6.880106e-005,0.000000e+000,3,9.748730e-001,0.000000e+000,,,,,,,,,,,,,,32,1,4.000000e+000,1.580048e-002,0.000000e+000,0,,0,
1524045429.875,,0.000000e+000,5.499248e+001,-6.894745e-005,0.000000e+000,3,9.753336e-001,0.000000e+000,,,,,,,,,,,,,,32,1,4.000000e+000,9.201050e-003,0.000000e+000,0,,0,
1524045454.795,,0.000000e+000,5.500037e+001,-6.912042e-005,0.000000e+000,3,9.748289e-001,0.000000e+000,,,,,,,,,,,,,,32,1,4.000000e+000,1.319885e-003,0.000000e+000,0,,0,
1524045479.925,,0.000000e+000,5.500301e+001,-6.928675e-005,0.000000e+000,3,9.744754e-001,0.000000e+000,,,,,,,,,,,,,,32,1,4.000000e+000,1.319885e-003,0.000000e+000,0,,0,
1524045505.235,,0.000000e+000,5.499773e+001,-6.946284e-005,0.000000e+000,3,9.742275e-001,0.000000e+000,,,,,,,,,,,,,,32,1,4.000000e+000,1.308441e-003,0.000000e+000,0,,0,
1524045530.115,,0.000000e+000,5.499971e+001,-6.963394e-005,0.000000e+000,3,9.747769e-001,0.000000e+000,,,,,,,,,,,,,,32,1,4.000000e+000,2.639771e-003,0.000000e+000,0,,0,
1524045555.065,,0.000000e+000,5.499445e+001,-6.977116e-005,0.000000e+000,3,9.748275e-001,0.000000e+000,,,,,,,,,,,,,,32,1,4.000000e+000,5.260468e-003,0.000000e+000,0,,0,
1524045580.286,,0.000000e+000,5.499840e+001,-6.999553e-005,0.000000e+000,3,9.744155e-001,0.000000e+000,,,,,,,,,,,,,,32,1,4.000000e+000,5.260468e-003,0.000000e+000,0,,0,
1524045605.476,,0.000000e+000,5.499708e+001,-7.012337e-005,0.000000e+000,3,9.747889e-001,0.000000e+000,,,,,,,,,,,,,,32,1,4.000000e+000,0.000000e+000,0.000000e+000,0,,0,
1524045630.476,,0.000000e+000,5.499971e+001,-7.021801e-005,0.000000e+000,3,9.747408e-001,0.000000e+000,,,,,,,,,,,,,,32,1,4.000000e+000,0.000000e+000,0.000000e+000,0,,0,
1524045655.816,,0.000000e+000,5.499577e+001,-7.032634e-005,0.000000e+000,3,9.746996e-001,0.000000e+000,,,,,,,,,,,,,,32,1,4.000000e+000,2.632141e-003,0.000000e+000,0,,0,
1524045680.986,,0.000000e+000,5.500037e+001,-7.049997e-005,0.000000e+000,3,9.746725e-001,0.000000e+000,,,,,,,,,,,,,,32,1,4.000000e+000,1.319885e-003,0.000000e+000,0,,0,
1524045706.176,,0.000000e+000,5.499577e+001,-7.060698e-005,0.000000e+000,3,9.745831e-001,0.000000e+000,,,,,,,,,,,,,,32,1,4.000000e+000,2.632141e-003,0.000000e+000,0,,0,
1524045731.386,,0.000000e+000,5.499511e+001,-7.076306e-005,0.000000e+000,3,9.751506e-001,0.000000e+000,,,,,,,,,,,,,,32,1,4.000000e+000,1.319885e-003,0.000000e+000,0,,0,
1524045756.626,,0.000000e+000,5.500037e+001,-7.084432e-005,0.000000e+000,3,9.749718e-001,0.000000e+000,,,,,,,,,,,,,,32,1,4.000000e+000,9.201050e-003,0.000000e+000,0,,0,
1524045781.766,,0.000000e+000,5.500037e+001,-7.101057e-005,0.000000e+000,3,9.750673e-001,0.000000e+000,,,,,,,,,,,,,,32,1,4.000000e+000,1.319885e-003,0.000000e+000,0,,0,
1524045806.986,,0.000000e+000,5.499972e+001,-7.106739e-005,0.000000e+000,3,9.750051e-001,0.000000e+000,,,,,,,,,,,,,,32,1,4.000000e+000,5.268097e-003,0.000000e+000,0,,0,
1524045832.176,,0.000000e+000,5.499774e+001,-7.117334e-005,0.000000e+000,3,9.740276e-001,0.000000e+000,,,,,,,,,,,,,,32,1,4.000000e+000,3.940582e-003,0.000000e+000,0,,0,
1524045857.336,,0.000000e+000,5.500235e+001,-7.134000e-005,0.000000e+000,3,9.745687e-001,0.000000e+000,,,,,,,,,,,,,,32,1,4.000000e+000,0.000000e+000,0.000000e+000,0,,0,
1524045882.606,,0.000000e+000,5.499577e+001,-7.137072e-005,0.000000e+000,3,9.744546e-001,0.000000e+000,,,,,,,,,,,,,,32,1,4.000000e+000,2.632141e-003,0.000000e+000,0,,0,
1524045907.756,,0.000000e+000,5.499972e+001,-7.153860e-005,0.000000e+000,3,9.747679e-001,0.000000e+000,,,,,,,,,,,,,,32,1,4.000000e+000,7.900238e-003,0.000000e+000,0,,0,
1524045932.906,,0.000000e+000,5.500103e+001,-7.162299e-005,0.000000e+000,3,9.742740e-001,0.000000e+000,,,,,,,,,,,,,,32,1,4.000000e+000,2.639771e-003,0.000000e+000,0,,0,
1524045958.176,,0.000000e+000,5.499708e+001,-7.170531e-005,0.000000e+000,3,9.747593e-001,0.000000e+000,,,,,,,,,,,,,,32,1,4.000000e+000,5.260468e-003,0.000000e+000,0,,0,
1524045983.326,,0.000000e+000,5.500037e+001,-7.176826e-005,0.000000e+000,3,9.747879e-001,0.000000e+000,,,,,,,,,,,,,,32,1,4.000000e+000,1.319885e-003,0.000000e+000,0,,0,
1524046008.676,,0.000000e+000,5.499773e+001,-7.197369e-005,0.000000e+000,3,9.748602e-001,0.000000e+000,,,,,,,,,,,,,,32,1,4.000000e+000,1.308441e-003,0.000000e+000,0,,0,
1524046033.746,,0.000000e+000,5.499840e+001,-7.199624e-005,0.000000e+000,3,9.746256e-001,0.000000e+000,,,,,,,,,,,,,,32,1,4.000000e+000,7.900238e-003,0.000000e+000,0,,0,
1524046058.906,,0.000000e+000,5.499708e+001,-7.210218e-005,0.000000e+000,3,9.751039e-001,0.000000e+000,,,,,,,,,,,,,,32,1,4.000000e+000,2.620697e-003,0.000000e+000,0,,0,
1524046084.126,,0.000000e+000,5.499577e+001,-7.216332e-005,0.000000e+000,3,9.750534e-001,0.000000e+000,,,,,,,,,,,,,,32,1,4.000000e+000,0.000000e+000,0.000000e+000,0,,0,
1524046109.336,,0.000000e+000,5.499380e+001,-7.225083e-005,0.000000e+000,3,9.753268e-001,0.000000e+000,,,,,,,,,,,,,,32,1,4.000000e+000,6.572723e-003,0.000000e+000,0,,0,
1524046134.516,,0.000000e+000,5.499905e+001,-7.227906e-005,0.000000e+000,3,9.747734e-001,0.000000e+000,,,,,,,,,,,,,,32,1,4.000000e+000,3.948212e-003,0.000000e+000,0,,0,
1524046159.706,,0.000000e+000,5.500103e+001,-7.244000e-005,0.000000e+000,3,9.750645e-001,0.000000e+000,,,,,,,,,,,,,,32,1,4.000000e+000,5.279541e-003,0.000000e+000,0,,0,
1524046185.036,,0.000000e+000,5.500037e+001,-7.243060e-005,0.000000e+000,3,9.750254e-001,0.000000e+000,,,,,,,,,,,,,,32,1,4.000000e+000,6.587982e-003,0.000000e+000,0,,0,
1524046209.886,,0.000000e+000,5.499972e+001,-7.258666e-005,0.000000e+000,3,9.745381e-001,0.000000e+000,,,,,,,,,,,,,,32,1,4.000000e+000,7.900238e-003,0.000000e+000,0,,0,
1524046234.856,,0.000000e+000,5.499708e+001,-7.269459e-005,0.000000e+000,3,9.743741e-001,0.000000e+000,,,,,,,,,,,,,,32,1,4.000000e+000,5.260468e-003,0.000000e+000,0,,0,
1524046259.706,,0.000000e+000,5.500037e+001,-7.273370e-005,0.000000e+000,3,9.745535e-001,0.000000e+000,,,,,,,,,,,,,,32,1,4.000000e+000,3.959656e-003,0.000000e+000,0,,0,
1524046284.846,,0.000000e+000,5.499642e+001,-7.277526e-005,0.000000e+000,3,9.750195e-001,0.000000e+000,,,,,,,,,,,,,,32,1,4.000000e+000,3.940582e-003,0.000000e+000,0,,0,
1524046309.887,,0.000000e+000,5.499773e+001,-7.280065e-005,0.000000e+000,3,9.747130e-001,0.000000e+000,,,,,,,,,,,,,,32,1,4.000000e+000,1.308441e-003,0.000000e+000,0,,0,
1524046334.767,,0.000000e+000,5.500234e+001,-7.295320e-005,0.000000e+000,3,9.750315e-001,0.000000e+000,,,,,,,,,,,,,,32,1,4.000000e+000,5.260468e-003,0.000000e+000,0,,0,
1524046359.767,,0.000000e+000,5.499840e+001,-7.299046e-005,0.000000e+000,3,9.755393e-001,0.000000e+000,,,,,,,,,,,,,,32,1,4.000000e+000,2.628326e-003,0.000000e+000,0,,0,
1524046384.637,,0.000000e+000,5.499445e+001,-7.312438e-005,0.000000e+000,3,9.755637e-001,0.000000e+000,,,,,,,,,,,,,,32,1,4.000000e+000,7.881165e-003,0.000000e+000,0,,0,
1524046409.607,,0.000000e+000,5.499773e+001,-7.315021e-005,0.000000e+000,3,9.748116e-001,0.000000e+000,,,,,,,,,,,,,,32,1,4.000000e+000,1.308441e-003,0.000000e+000,0,,0,
1524046434.487,,0.000000e+000,5.500235e+001,-7.320694e-005,0.000000e+000,3,9.756569e-001,0.000000e+000,,,,,,,,,,,,,,32,1,4.000000e+000,1.052856e-002,0.000000e+000,0,,0,
1524046460.267,,0.000000e+000,5.500169e+001,-7.332535e-005,0.000000e+000,3,9.767143e-001,0.000000e+000,,,,,,,,,,,,,,32,1,4.000000e+000,3.959656e-003,0.000000e+000,0,,0,
1524046486.137,,0.000000e+000,5.499511e+001,-7.342290e-005,0.000000e+000,3,9.765443e-001,0.000000e+000,,,,,,,,,,,,,,32,1,4.000000e+000,6.568909e-003,0.000000e+000,0,,0,
1524046511.657,,0.000000e+000,5.499182e+001,-7.334541e-005,0.000000e+000,3,9.757614e-001,0.000000e+000,,,,,,,,,,,,,,32,1,4.000000e+000,0.000000e+000,0.000000e+000,0,,0,
1524046537.257,,0.000000e+000,5.499905e+001,-7.341087e-005,0.000000e+000,3,9.757218e-001,0.000000e+000,,,,,,,,,,,,,,32,1,4.000000e+000,3.948212e-003,0.000000e+000,0,,0,
1524046562.507,,0.000000e+000,5.499643e+001,-7.349852e-005,0.000000e+000,3,9.755130e-001,0.000000e+000,,,,,,,,,,,,,,32,1,4.000000e+000,1.312256e-003,0.000000e+000,0,,0,
1524046588.077,,0.000000e+000,5.499905e+001,-7.353902e-005,0.000000e+000,3,9.748656e-001,0.000000e+000,,,,,,,,,,,,,,32,1,4.000000e+000,1.319885e-003,0.000000e+000,0,,0,
1524046613.247,,0.000000e+000,5.500366e+001,-7.361256e-005,0.000000e+000,3,9.752829e-001,0.000000e+000,,,,,,,,,,,,,,32,1,4.000000e+000,5.260468e-003,0.000000e+000,0,,0,
1524046638.517,,0.000000e+000,5.500168e+001,-7.363095e-005,0.000000e+000,3,9.766825e-001,0.000000e+000,,,,,,,,,,,,,,32,1,4.000000e+000,6.580353e-003,0.000000e+000,0,,0,
1524046663.747,,0.000000e+000,5.499971e+001,-7.381488e-005,0.000000e+000,3,9.758945e-001,0.000000e+000,,,,,,,,,,,,,,32,1,4.000000e+000,2.639771e-003,0.000000e+000,0,,0,
1524046690.097,,0.000000e+000,5.499708e+001,-7.378487e-005,0.000000e+000,3,9.760430e-001,0.000000e+000,,,,,,,,,,,,,,32,1,4.000000e+000,1.578140e-002,0.000000e+000,0,,0,
1524046714.847,,0.000000e+000,5.499773e+001,-7.386725e-005,0.000000e+000,3,9.746182e-001,0.000000e+000,,,,,,,,,,,,,,32,1,4.000000e+000,1.308441e-003,0.000000e+000,0,,0,
1524046740.257,,0.000000e+000,5.500169e+001,-7.387946e-005,0.000000e+000,3,9.748868e-001,0.000000e+000,,,,,,,,,,,,,,32,1,4.000000e+000,1.319885e-003,0.000000e+000,0,,0,
1524046765.757,,0.000000e+000,5.499839e+001,-7.396063e-005,0.000000e+000,3,9.747982e-001,0.000000e+000,,,,,,,,,,,,,,32,1,4.000000e+000,0.000000e+000,0.000000e+000,0,,0,
1524046790.917,,0.000000e+000,5.499774e+001,-7.394330e-005,0.000000e+000,3,9.753001e-001,0.000000e+000,,,,,,,,,,,,,,32,1,4.000000e+000,3.940582e-003,0.000000e+000,0,,0,
1524046815.847,,0.000000e+000,5.499905e+001,-7.410933e-005,0.000000e+000,3,9.752235e-001,0.000000e+000,,,,,,,,,,,,,,32,1,4.000000e+000,1.319885e-003,0.000000e+000,0,,0,
1524046840.827,,0.000000e+000,5.500695e+001,-7.412657e-005,0.000000e+000,3,9.749112e-001,0.000000e+000,,,,,,,,,,,,,,32,1,4.000000e+000,6.568909e-003,0.000000e+000,0,,0,
1524046865.927,,0.000000e+000,5.500169e+001,-7.419160e-005,0.000000e+000,3,9.748601e-001,0.000000e+000,,,,,,,,,,,,,,32,1,4.000000e+000,1.184082e-002,0.000000e+000,0,,0,
1524046891.227,,0.000000e+000,5.499775e+001,-7.429269e-005,0.000000e+000,3,9.759905e-001,0.000000e+000,,,,,,,,,,,,,,32,1,4.000000e+000,1.184845e-002,0.000000e+000,0,,0,
1524046915.917,,0.000000e+000,5.499445e+001,-7.432008e-005,0.000000e+000,3,9.755971e-001,0.000000e+000,,,,,,,,,,,,,,32,1,4.000000e+000,7.881165e-003,0.000000e+000,0,,0,
1524046941.087,,0.000000e+000,5.499314e+001,-7.435769e-005,0.000000e+000,3,9.758754e-001,0.000000e+000,,,,,,,,,,,,,,32,1,4.000000e+000,0.000000e+000,0.000000e+000,0,,0,
1524046966.317,,0.000000e+000,5.499577e+001,-7.438947e-005,0.000000e+000,3,9.762791e-001,0.000000e+000,,,,,,,,,,,,,,32,1,4.000000e+000,2.632141e-003,0.000000e+000,0,,0,
1524046991.667,,0.000000e+000,5.499577e+001,-7.447851e-005,0.000000e+000,3,9.765181e-001,0.000000e+000,,,,,,,,,,,,,,32,1,4.000000e+000,2.632141e-003,0.000000e+000,0,,0,
1524047016.848,,0.000000e+000,5.500103e+001,-7.448546e-005,0.000000e+000,3,9.762242e-001,0.000000e+000,,,,,,,,,,,,,,32,1,4.000000e+000,0.000000e+000,0.000000e+000,0,,0,
1524047042.088,,0.000000e+000,5.499905e+001,-7.453500e-005,0.000000e+000,3,9.759399e-001,0.000000e+000,,,,,,,,,,,,,,32,1,4.000000e+000,3.948212e-003,0.000000e+000,0,,0,
1524047067.268,,0.000000e+000,5.499774e+001,-7.457405e-005,0.000000e+000,3,9.759788e-001,0.000000e+000,,,,,,,,,,,,,,32,1,4.000000e+000,6.580353e-003,0.000000e+000,0,,0,
1524047092.498,,0.000000e+000,5.500103e+001,-7.458289e-005,0.000000e+000,3,9.764344e-001,0.000000e+000,,,,,,,,,,,,,,32,1,4.000000e+000,7.888794e-003,0.000000e+000,0,,0,
1524047117.648,,0.000000e+000,5.499773e+001,-7.462441e-005,0.000000e+000,3,9.763917e-001,0.000000e+000,,,,,,,,,,,,,,32,1,4.000000e+000,1.308441e-003,0.000000e+000,0,,0,
1524047142.878,,0.000000e+000,5.499840e+001,-7.471818e-005,0.000000e+000,3,9.760499e-001,0.000000e+000,,,,,,,,,,,,,,32,1,4.000000e+000,2.628326e-003,0.000000e+000,0,,0,
1524047168.068,,0.000000e+000,5.499643e+001,-7.477180e-005,0.000000e+000,3,9.766975e-001,0.000000e+000,,,,,,,,,,,,,,32,1,4.000000e+000,1.312256e-003,0.000000e+000,0,,0,
1524047193.268,,0.000000e+000,5.499840e+001,-7.482264e-005,0.000000e+000,3,9.756970e-001,0.000000e+000,,,,,,,,,,,,,,32,1,4.000000e+000,2.628326e-003,0.000000e+000,0,,0,
1524047218.508,,0.000000e+000,5.499774e+001,-7.486780e-005,0.000000e+000,3,9.762482e-001,0.000000e+000,,,,,,,,,,,,,,32,1,4.000000e+000,3.940582e-003,0.000000e+000,0,,0,
1524047243.698,,0.000000e+000,5.500037e+001,-7.495104e-005,0.000000e+000,3,9.761881e-001,0.000000e+000,,,,,,,,,,,,,,32,1,4.000000e+000,3.959656e-003,0.000000e+000,0,,0,
1524047268.338,,0.000000e+000,5.499774e+001,-7.496321e-005,0.000000e+000,3,9.760961e-001,0.000000e+000,,,,,,,,,,,,,,32,1,4.000000e+000,3.940582e-003,0.000000e+000,0,,0,
1524047293.558,,0.000000e+000,5.500037e+001,-7.502727e-005,0.000000e+000,3,9.765732e-001,0.000000e+000,,,,,,,,,,,,,,32,1,4.000000e+000,1.319885e-003,0.000000e+000,0,,0,
1524047318.798,,0.000000e+000,5.499708e+001,-7.504637e-005,0.000000e+000,3,9.763802e-001,0.000000e+000,,,,,,,,,,,,,,32,1,4.000000e+000,2.620697e-003,0.000000e+000,0,,0,
1524047343.958,,0.000000e+000,5.499708e+001,-7.506207e-005,0.000000e+000,3,9.764529e-001,0.000000e+000,,,,,,,,,,,,,,32,1,4.000000e+000,0.000000e+000,0.000000e+000,0,,0,
1524047369.198,,0.000000e+000,5.499577e+001,-7.515960e-005,0.000000e+000,3,9.761791e-001,0.000000e+000,,,,,,,,,,,,,,32,1,4.000000e+000,0.000000e+000,0.000000e+000,0,,0,
1524047394.148,,0.000000e+000,5.499643e+001,-7.511065e-005,0.000000e+000,3,9.759974e-001,0.000000e+000,,,,,,,,,,,,,,32,1,4.000000e+000,1.312256e-003,0.000000e+000,0,,0,
1524047419.588,,0.000000e+000,5.499971e+001,-7.518513e-005,0.000000e+000,3,9.756778e-001,0.000000e+000,,,,,,,,,,,,,,32,1,4.000000e+000,2.639771e-003,0.000000e+000,0,,0,
1524047444.368,,0.000000e+000,5.499708e+001,-7.526758e-005,0.000000e+000,3,9.763492e-001,0.000000e+000,,,,,,,,,,,,,,32,1,4.000000e+000,2.620697e-003,0.000000e+000,0,,0,
1524047469.398,,0.000000e+000,5.499905e+001,-7.525982e-005,0.000000e+000,3,9.762709e-001,0.000000e+000,,,,,,,,,,,,,,32,1,4.000000e+000,1.319885e-003,0.000000e+000,0,,0,
1524047494.788,,0.000000e+000,5.500169e+001,-7.526471e-005,0.000000e+000,3,9.757616e-001,0.000000e+000,,,,,,,,,,,,,,32,1,4.000000e+000,1.319885e-003,0.000000e+000,0,,0,
1524047520.188,,0.000000e+000,5.499511e+001,-7.532317e-005,0.000000e+000,3,9.757265e-001,0.000000e+000,,,,,,,,,,,,,,32,1,4.000000e+000,6.568909e-003,0.000000e+000,0,,0,
1524047545.438,,0.000000e+000,5.499774e+001,-7.536095e-005,0.000000e+000,3,9.754063e-001,0.000000e+000,,,,,,,,,,,,,,32,1,4.000000e+000,6.580353e-003,0.000000e+000,0,,0,
1524047570.328,,0.000000e+000,5.499906e+001,-7.544853e-005,0.000000e+000,3,9.759129e-001,0.000000e+000,,,,,,,,,,,,,,32,1,4.000000e+000,6.580353e-003,0.000000e+000,0,,0,
1524047595.308,,0.000000e+000,5.499773e+001,-7.545575e-005,0.000000e+000,3,9.750910e-001,0.000000e+000,,,,,,,,,,,,,,32,1,4.000000e+000,1.308441e-003,0.000000e+000,0,,0,
1524047620.208,,0.000000e+000,5.499643e+001,-7.555723e-005,0.000000e+000,3,9.760898e-001,0.000000e+000,,,,,,,,,,,,,,32,1,4.000000e+000,1.312256e-003,0.000000e+000,0,,0,
1524047645.478,,0.000000e+000,5.499511e+001,-7.555030e-005,0.000000e+000,3,9.768546e-001,0.000000e+000,,,,,,,,,,,,,,32,1,4.000000e+000,3.940582e-003,0.000000e+000,0,,0,
1524047670.798,,0.000000e+000,5.499183e+001,-7.560742e-005,0.000000e+000,3,9.763907e-001,0.000000e+000,,,,,,,,,,,,,,32,1,4.000000e+000,7.888794e-003,0.000000e+000,0,,0,
1524047696.098,,0.000000e+000,5.499773e+001,-7.563215e-005,0.000000e+000,3,9.760762e-001,0.000000e+000,,,,,,,,,,,,,,32,1,4.000000e+000,1.308441e-003,0.000000e+000,0,,0,
1524047721.449,,0.000000e+000,5.499708e+001,-7.569587e-005,0.000000e+000,3,9.764369e-001,0.000000e+000,,,,,,,,,,,,,,32,1,4.000000e+000,0.000000e+000,0.000000e+000,0,,0,
1524047746.649,,0.000000e+000,5.499774e+001,-7.571348e-005,0.000000e+000,3,9.760883e-001,0.000000e+000,,,,,,,,,,,,,,32,1,4.000000e+000,3.940582e-003,0.000000e+000,0,,0,
1524047771.839,,0.000000e+000,5.499643e+001,-7.571187e-005,0.000000e+000,3,9.763839e-001,0.000000e+000,,,,,,,,,,,,,,32,1,4.000000e+000,1.312256e-003,0.000000e+000,0,,0,
1524047797.059,,0.000000e+000,5.500037e+001,-7.570044e-005,0.000000e+000,3,9.760469e-001,0.000000e+000,,,,,,,,,,,,,,32,1,4.000000e+000,1.319885e-003,0.000000e+000,0,,0,
1524047822.259,,0.000000e+000,5.500103e+001,-7.578717e-005,0.000000e+000,3,9.758520e-001,0.000000e+000,,,,,,,,,,,,,,32,1,4.000000e+000,5.279541e-003,0.000000e+000,0,,0,
1524047847.429,,0.000000e+000,5.499840e+001,-7.582937e-005,0.000000e+000,3,9.756871e-001,0.000000e+000,,,,,,,,,,,,,,32,1,4.000000e+000,2.628326e-003,0.000000e+000,0,,0,
1524047872.669,,0.000000e+000,5.499773e+001,-7.582812e-005,0.000000e+000,3,9.750422e-001,0.000000e+000,,,,,,,,,,,,,,32,1,4.000000e+000,1.308441e-003,0.000000e+000,0,,0,
1524047897.629,,0.000000e+000,5.500037e+001,-7.584321e-005,0.000000e+000,3,9.749415e-001,0.000000e+000,,,,,,,,,,,,,,32,1,4.000000e+000,1.184082e-002,0.000000e+000,0,,0,
1524047923.679,,0.000000e+000,5.499117e+001,-7.586909e-005,0.000000e+000,3,9.747772e-001,0.000000e+000,,,,,,,,,,,,,,32,1,4.000000e+000,9.208679e-003,0.000000e+000,0,,0,
1524047948.669,,0.000000e+000,5.499840e+001,-7.589863e-005,0.000000e+000,3,9.750934e-001,0.000000e+000,,,,,,,,,,,,,,32,1,4.000000e+000,5.260468e-003,0.000000e+000,0,,0,
1524047973.789,,0.000000e+000,5.499643e+001,-7.594068e-005,0.000000e+000,3,9.747410e-001,0.000000e+000,,,,,,,,,,,,,,32,1,4.000000e+000,1.184082e-002,0.000000e+000,0,,0,
1524047999.309,,0.000000e+000,5.500037e+001,-7.598774e-005,0.000000e+000,3,9.765831e-001,0.000000e+000,,,,,,,,,,,,,,32,1,4.000000e+000,1.184082e-002,0.000000e+000,0,,0,
1524048024.719,,0.000000e+000,5.500497e+001,-7.605438e-005,0.000000e+000,3,9.756175e-001,0.000000e+000,,,,,,,,,,,,,,32,1,4.000000e+000,0.000000e+000,0.000000e+000,0,,0,
1524048049.979,,0.000000e+000,5.499643e+001,-7.606607e-005,0.000000e+000,3,9.758713e-001,0.000000e+000,,,,,,,,,,,,,,32,1,4.000000e+000,1.312256e-003,0.000000e+000,0,,0,
1524048075.319,,0.000000e+000,5.499774e+001,-7.611488e-005,0.000000e+000,3,9.757010e-001,0.000000e+000,,,,,,,,,,,,,,32,1,4.000000e+000,3.940582e-003,0.000000e+000,0,,0,
1524048100.319,,0.000000e+000,5.499577e+001,-7.611074e-005,0.000000e+000,3,9.754351e-001,0.000000e+000,,,,,,,,,,,,,,32,1,4.000000e+000,7.888794e-003,0.000000e+000,0,,0,
1524048125.199,,0.000000e+000,5.500103e+001,-7.610108e-005,0.000000e+000,3,9.755489e-001,0.000000e+000,,,,,,,,,,,,,,32,1,4.000000e+000,5.279541e-003,0.000000e+000,0,,0,
1524048150.379,,0.000000e+000,5.500169e+001,-7.616609e-005,0.000000e+000,3,9.751494e-001,0.000000e+000,,,,,,,,,,,,,,32,1,4.000000e+000,1.446915e-002,0.000000e+000,0,,0,
1524048175.209,,0.000000e+000,5.499708e+001,-7.622389e-005,0.000000e+000,3,9.754988e-001,0.000000e+000,,,,,,,,,,,,,,32,1,4.000000e+000,5.260468e-003,0.000000e+000,0,,0,
1524048201.199,,0.000000e+000,5.499774e+001,-7.620933e-005,0.000000e+000,3,9.746225e-001,0.000000e+000,,,,,,,,,,,,,,32,1,4.000000e+000,3.940582e-003,0.000000e+000,0,,0,
1524048225.919,,0.000000e+000,5.500103e+001,-7.622021e-005,0.000000e+000,3,9.747275e-001,0.000000e+000,,,,,,,,,,,,,,32,1,4.000000e+000,2.639771e-003,0.000000e+000,0,,0,
1524048251.079,,0.000000e+000,5.499708e+001,-7.631085e-005,0.000000e+000,3,9.746472e-001,0.000000e+000,,,,,,,,,,,,,,32,1,4.000000e+000,2.620697e-003,0.000000e+000,0,,0,
1524048276.179,,0.000000e+000,5.499840e+001,-7.628708e-005,0.000000e+000,3,9.751284e-001,0.000000e+000,,,,,,,,,,,,,,32,1,4.000000e+000,2.628326e-003,0.000000e+000,0,,0,
1524048301.389,,0.000000e+000,5.499708e+001,-7.630014e-005,0.000000e+000,3,9.751855e-001,0.000000e+000,,,,,,,,,,,,,,32,1,4.000000e+000,2.620697e-003,0.000000e+000,0,,0,
1524048326.689,,0.000000e+000,5.499642e+001,-7.634231e-005,0.000000e+000,3,9.744529e-001,0.000000e+000,,,,,,,,,,,,,,32,1,4.000000e+000,3.940582e-003,0.000000e+000,0,,0,
1524048351.889,,0.000000e+000,5.499839e+001,-7.636943e-005,0.000000e+000,3,9.739783e-001,0.000000e+000,,,,,,,,,,,,,,32,1,4.000000e+000,0.000000e+000,0.000000e+000,0,,0,
1524048377.519,,0.000000e+000,5.499708e+001,-7.644726e-005,0.000000e+000,3,9.754197e-001,0.000000e+000,,,,,,,,,,,,,,32,1,4.000000e+000,5.260468e-003,0.000000e+000,0,,0,
1524048402.949,,0.000000e+000,5.500103e+001,-7.647273e-005,0.000000e+000,3,9.759429e-001,0.000000e+000,,,,,,,,,,,,,,32,1,4.000000e+000,1.316071e-002,0.000000e+000,0,,0,
1524048428.239,,0.000000e+000,5.499708e+001,-7.649385e-005,0.000000e+000,3,9.756437e-001,0.000000e+000,,,,,,,,,,,,,,32,1,4.000000e+000,5.260468e-003,0.000000e+000,0,,0,
1524048453.240,,0.000000e+000,5.499577e+001,-7.649356e-005,0.000000e+000,3,9.754621e-001,0.000000e+000,,,,,,,,,,,,,,32,1,4.000000e+000,5.249023e-003,0.000000e+000,0,,0,
1524048478.460,,0.000000e+000,5.499905e+001,-7.649919e-005,0.000000e+000,3,9.748177e-001,0.000000e+000,,,,,,,,,,,,,,32,1,4.000000e+000,1.319885e-003,0.000000e+000,0,,0,
1524048503.420,,0.000000e+000,5.499708e+001,-7.648611e-005,0.000000e+000,3,9.754650e-001,0.000000e+000,,,,,,,,,,,,,,32,1,4.000000e+000,2.620697e-003,0.000000e+000,0,,0,
1524048528.260,,0.000000e+000,5.499971e+001,-7.654928e-005,0.000000e+000,3,9.754840e-001,0.000000e+000,,,,,,,,,,,,,,32,1,4.000000e+000,1.052094e-002,0.000000e+000,0,,0,
1524048553.090,,0.000000e+000,5.499642e+001,-7.657980e-005,0.000000e+000,3,9.758268e-001,0.000000e+000,,,,,,,,,,,,,,32,1,4.000000e+000,3.940582e-003,0.000000e+000,0,,0,
1524048578.470,,0.000000e+000,5.499708e+001,-7.662125e-005,0.000000e+000,3,9.753185e-001,0.000000e+000,,,,,,,,,,,,,,32,1,4.000000e+000,5.260468e-003,0.000000e+000,0,,0,
1524048603.820,,0.000000e+000,5.500301e+001,-7.656718e-005,0.000000e+000,3,9.748208e-001,0.000000e+000,,,,,,,,,,,,,,32,1,4.000000e+000,1.319885e-003,0.000000e+000,0,,0,
1524048629.640,,0.000000e+000,5.499445e+001,-7.661798e-005,0.000000e+000,3,9.748127e-001,0.000000e+000,,,,,,,,,,,,,,32,1,4.000000e+000,1.052094e-002,0.000000e+000,0,,0,
1524048654.970,,0.000000e+000,5.499577e+001,-7.673285e-005,0.000000e+000,3,9.747471e-001,0.000000e+000,,,,,,,,,,,,,,32,1,4.000000e+000,2.632141e-003,0.000000e+000,0,,0,
1524048680.310,,0.000000e+000,5.499905e+001,-7.668348e-005,0.000000e+000,3,9.746403e-001,0.000000e+000,,,,,,,,,,,,,,32,1,4.000000e+000,1.319885e-003,0.000000e+000,0,,0,
1524048705.180,,0.000000e+000,5.499642e+001,-7.674652e-005,0.000000e+000,3,9.751464e-001,0.000000e+000,,,,,,,,,,,,,,32,1,4.000000e+000,3.940582e-003,0.000000e+000,0,,0,
1524048730.300,,0.000000e+000,5.499840e+001,-7.674671e-005,0.000000e+000,3,9.753283e-001,0.000000e+000,,,,,,,,,,,,,,32,1,4.000000e+000,2.628326e-003,0.000000e+000,0,,0,
1524048755.650,,0.000000e+000,5.499971e+001,-7.683684e-005,0.000000e+000,3,9.749354e-001,0.000000e+000,,,,,,,,,,,,,,32,1,4.000000e+000,2.639771e-003,0.000000e+000,0,,0,
1524048781.300,,0.000000e+000,5.499643e+001,-7.677718e-005,0.000000e+000,3,9.758039e-001,0.000000e+000,,,,,,,,,,,,,,32,1,4.000000e+000,1.312256e-003,0.000000e+000,0,,0,
1524048806.780,,0.000000e+000,5.499709e+001,-7.684044e-005,0.000000e+000,3,9.757859e-001,0.000000e+000,,,,,,,,,,,,,,32,1,4.000000e+000,7.888794e-003,0.000000e+000,0,,0,
1524048832.000,,0.000000e+000,5.499577e+001,-7.681503e-005,0.000000e+000,3,9.750066e-001,0.000000e+000,,,,,,,,,,,,,,32,1,4.000000e+000,7.888794e-003,0.000000e+000,0,,0,
1524048857.390,,0.000000e+000,5.499380e+001,-7.688485e-005,0.000000e+000,3,9.751778e-001,0.000000e+000,,,,,,,,,,,,,,32,1,4.000000e+000,6.572723e-003,0.000000e+000,0,,0,
1524048882.720,,0.000000e+000,5.500366e+001,-7.690123e-005,0.000000e+000,3,9.740033e-001,0.000000e+000,,,,,,,,,,,,,,32,1,4.000000e+000,2.620697e-003,0.000000e+000,0,,0,
1524048907.820,,0.000000e+000,5.499709e+001,-7.685927e-005,0.000000e+000,3,9.750589e-001,0.000000e+000,,,,,,,,,,,,,,32,1,4.000000e+000,7.888794e-003,0.000000e+000,0,,0,
1524048932.730,,0.000000e+000,5.500103e+001,-7.697083e-005,0.000000e+000,3,9.743270e-001,0.000000e+000,,,,,,,,,,,,,,32,1,4.000000e+000,0.000000e+000,0.000000e+000,0,,0,
1524048958.000,,0.000000e+000,5.499643e+001,-7.695296e-005,0.000000e+000,3,9.761658e-001,0.000000e+000,,,,,,,,,,,,,,32,1,4.000000e+000,1.312256e-003,0.000000e+000,0,,0,
1524048982.690,,0.000000e+000,5.500235e+001,-7.702663e-005,0.000000e+000,3,9.744267e-001,0.000000e+000,,,,,,,,,,,,,,32,1,4.000000e+000,1.052856e-002,0.000000e+000,0,,0,
1524049007.550,,0.000000e+000,5.499773e+001,-7.699178e-005,0.000000e+000,3,9.743206e-001,0.000000e+000,,,,,,,,,,,,,,32,1,4.000000e+000,1.308441e-003,0.000000e+000,0,,0,
1524049032.540,,0.000000e+000,5.500761e+001,-7.705071e-005,0.000000e+000,3,9.743760e-001,0.000000e+000,,,,,,,,,,,,,,32,1,4.000000e+000,7.881165e-003,0.000000e+000,0,,0,
1524049057.600,,0.000000e+000,5.499445e+001,-7.706344e-005,0.000000e+000,3,9.740117e-001,0.000000e+000,,,,,,,,,,,,,,32,1,4.000000e+000,1.052094e-002,0.000000e+000,0,,0,
1524049082.670,,0.000000e+000,5.500103e+001,-7.702957e-005,0.000000e+000,3,9.746199e-001,0.000000e+000,,,,,,,,,,,,,,32,1,4.000000e+000,0.000000e+000,0.000000e+000,0,,0,
1524049108.520,,0.000000e+000,5.499643e+001,-7.712254e-005,0.000000e+000,3,9.754838e-001,0.000000e+000,,,,,,,,,,,,,,32,1,4.000000e+000,1.312256e-003,0.000000e+000,0,,0,
1524049133.980,,0.000000e+000,5.500169e+001,-7.719063e-005,0.000000e+000,3,9.761684e-001,0.000000e+000,,,,,,,,,,,,,,32,1,4.000000e+000,1.319885e-003,0.000000e+000,0,,0,
1524049158.681,,0.000000e+000,5.500037e+001,-7.714920e-005,0.000000e+000,3,9.749694e-001,0.000000e+000,,,,,,,,,,,,,,32,1,4.000000e+000,1.319885e-003,0.000000e+000,0,,0,
1524049183.601,,0.000000e+000,5.499642e+001,-7.717630e-005,0.000000e+000,3,9.752793e-001,0.000000e+000,,,,,,,,,,,,,,32,1,4.000000e+000,3.940582e-003,0.000000e+000,0,,0,
1524049208.991,,0.000000e+000,5.500300e+001,-7.723019e-005,0.000000e+000,3,9.756867e-001,0.000000e+000,,,,,,,,,,,,,,32,1,4.000000e+000,6.580353e-003,0.000000e+000,0,,0,
1524049234.191,,0.000000e+000,5.500103e+001,-7.726122e-005,0.000000e+000,3,9.752183e-001,0.000000e+000,,,,,,,,,,,,,,32,1,4.000000e+000,5.279541e-003,0.000000e+000,0,,0,
1524049259.421,,0.000000e+000,5.500037e+001,-7.716762e-005,0.000000e+000,3,9.746856e-001,0.000000e+000,,,,,,,,,,,,,,32,1,4.000000e+000,1.319885e-003,0.000000e+000,0,,0,
1524049284.801,,0.000000e+000,5.499905e+001,-7.723227e-005,0.000000e+000,3,9.743446e-001,0.000000e+000,,,,,,,,,,,,,,32,1,4.000000e+000,1.319885e-003,0.000000e+000,0,,0,
1524049310.231,,0.000000e+000,5.499708e+001,-7.726048e-005,0.000000e+000,3,9.740194e-001,0.000000e+000,,,,,,,,,,,,,,32,1,4.000000e+000,0.000000e+000,0.000000e+000,0,,0,
1524049335.421,,0.000000e+000,5.500037e+001,-7.733262e-005,0.000000e+000,3,9.747151e-001,0.000000e+000,,,,,,,,,,,,,,32,1,4.000000e+000,1.319885e-003,0.000000e+000,0,,0,
1524049360.641,,0.000000e+000,5.499840e+001,-7.732123e-005,0.000000e+000,3,9.738946e-001,0.000000e+000,,,,,,,,,,,,,,32,1,4.000000e+000,2.628326e-003,0.000000e+000,0,,0,
1524049385.861,,0.000000e+000,5.499774e+001,-7.736357e-005,0.000000e+000,3,9.746535e-001,0.000000e+000,,,,,,,,,,,,,,32,1,4.000000e+000,3.940582e-003,0.000000e+000,0,,0,
1524049410.991,,0.000000e+000,5.499773e+001,-7.738731e-005,0.000000e+000,3,9.745100e-001,0.000000e+000,,,,,,,,,,,,,,32,1,4.000000e+000,1.308441e-003,0.000000e+000,0,,0,
1524049436.201,,0.000000e+000,5.500103e+001,-7.736515e-005,0.000000e+000,3,9.739431e-001,0.000000e+000,,,,,,,,,,,,,,32,1,4.000000e+000,5.279541e-003,0.000000e+000,0,,0,
1524049461.671,,0.000000e+000,5.499773e+001,-7.746164e-005,0.000000e+000,3,9.754731e-001,0.000000e+000,,,,,,,,,,,,,,32,1,4.000000e+000,1.308441e-003,0.000000e+000,0,,0,
1524049487.061,,0.000000e+000,5.499708e+001,-7.754749e-005,0.000000e+000,3,9.753500e-001,0.000000e+000,,,,,,,,,,,,,,32,1,4.000000e+000,5.260468e-003,0.000000e+000,0,,0,
1524049512.961,,0.000000e+000,5.499840e+001,-7.739723e-005,0.000000e+000,3,9.748652e-001,0.000000e+000,,,,,,,,,,,,,,32,1,4.000000e+000,5.260468e-003,0.000000e+000,0,,0,
1524049538.151,,0.000000e+000,5.499840e+001,-7.744120e-005,0.000000e+000,3,9.740648e-001,0.000000e+000,,,,,,,,,,,,,,32,1,4.000000e+000,7.900238e-003,0.000000e+000,0,,0,
1524049563.261,,0.000000e+000,5.499577e+001,-7.750473e-005,0.000000e+000,3,9.741998e-001,0.000000e+000,,,,,,,,,,,,,,32,1,4.000000e+000,0.000000e+000,0.000000e+000,0,,0,
1524049588.721,,0.000000e+000,5.499380e+001,-7.756089e-005,0.000000e+000,3,9.759348e-001,0.000000e+000,,,,,,,,,,,,,,32,1,4.000000e+000,3.948212e-003,0.000000e+000,0,,0,
1524049613.691,,0.000000e+000,5.500037e+001,-7.748656e-005,0.000000e+000,3,9.758191e-001,0.000000e+000,,,,,,,,,,,,,,32,1,4.000000e+000,3.959656e-003,0.000000e+000,0,,0,
1524049639.411,,0.000000e+000,5.499511e+001,-7.759582e-005,0.000000e+000,3,9.756448e-001,0.000000e+000,,,,,,,,,,,,,,32,1,4.000000e+000,6.568909e-003,0.000000e+000,0,,0,
1524049664.641,,0.000000e+000,5.499642e+001,-7.757734e-005,0.000000e+000,3,9.755359e-001,0.000000e+000,,,,,,,,,,,,,,32,1,4.000000e+000,3.940582e-003,0.000000e+000,0,,0,
1524049689.501,,0.000000e+000,5.500498e+001,-7.754819e-005,0.000000e+000,3,9.750503e-001,0.000000e+000,,,,,,,,,,,,,,32,1,4.000000e+000,2.620697e-003,0.000000e+000,0,,0,
1524049714.731,,0.000000e+000,5.500301e+001,-7.762905e-005,0.000000e+000,3,9.754519e-001,0.000000e+000,,,,,,,,,,,,,,32,1,4.000000e+000,1.319885e-003,0.000000e+000,0,,0,
1524049739.371,,0.000000e+000,5.499971e+001,-7.759941e-005,0.000000e+000,3,9.750143e-001,0.000000e+000,,,,,,,,,,,,,,32,1,4.000000e+000,2.639771e-003,0.000000e+000,0,,0,
1524049764.621,,0.000000e+000,5.499643e+001,-7.766965e-005,0.000000e+000,3,9.748844e-001,0.000000e+000,,,,,,,,,,,,,,32,1,4.000000e+000,6.568909e-003,0.000000e+000,0,,0,
1524049789.591,,0.000000e+000,5.499774e+001,-7.770900e-005,0.000000e+000,3,9.757078e-001,0.000000e+000,,,,,,,,,,,,,,32,1,4.000000e+000,3.940582e-003,0.000000e+000,0,,0,
1524049814.331,,0.000000e+000,5.499906e+001,-7.768776e-005,0.000000e+000,3,9.743726e-001,0.000000e+000,,,,,,,,,,,,,,32,1,4.000000e+000,9.220123e-003,0.000000e+000,0,,0,
1524049839.391,,0.000000e+000,5.498985e+001,-7.773271e-005,0.000000e+000,3,9.746315e-001,0.000000e+000,,,,,,,,,,,,,,32,1,4.000000e+000,9.201050e-003,0.000000e+000,0,,0,
1524049864.292,,0.000000e+000,5.500037e+001,-7.774214e-005,0.000000e+000,3,9.747309e-001,0.000000e+000,,,,,,,,,,,,,,32,1,4.000000e+000,3.959656e-003,0.000000e+000,0,,0,
1524049889.692,,0.000000e+000,5.499972e+001,-7.780891e-005,0.000000e+000,3,9.749702e-001,0.000000e+000,,,,,,,,,,,,,,32,1,4.000000e+000,5.268097e-003,0.000000e+000,0,,0,
1524049914.342,,0.000000e+000,5.500103e+001,-7.781573e-005,0.000000e+000,3,9.750925e-001,0.000000e+000,,,,,,,,,,,,,,32,1,4.000000e+000,7.888794e-003,0.000000e+000,0,,0,
1524049939.552,,0.000000e+000,5.499643e+001,-7.783837e-005,0.000000e+000,3,9.751706e-001,0.000000e+000,,,,,,,,,,,,,,32,1,4.000000e+000,1.312256e-003,0.000000e+000,0,,0,
1524049964.972,,0.000000e+000,5.499905e+001,-7.785605e-005,0.000000e+000,3,9.741033e-001,0.000000e+000,,,,,,,,,,,,,,32,1,4.000000e+000,1.182938e-002,0.000000e+000,0,,0,
1524049990.192,,0.000000e+000,5.499905e+001,-7.790488e-005,0.000000e+000,3,9.741019e-001,0.000000e+000,,,,,,,,,,,,,,32,1,4.000000e+000,1.319885e-003,0.000000e+000,0,,0,
1524050015.152,,0.000000e+000,5.500037e+001,-7.792032e-005,0.000000e+000,3,9.743831e-001,0.000000e+000,,,,,,,,,,,,,,32,1,4.000000e+000,1.184082e-002,0.000000e+000,0,,0,
1524050040.472,,0.000000e+000,5.500695e+001,-7.789882e-005,0.000000e+000,3,9.748372e-001,0.000000e+000,,,,,,,,,,,,,,32,1,4.000000e+000,1.319885e-003,0.000000e+000,0,,0,
1524050065.162,,0.000000e+000,5.499774e+001,-7.794879e-005,0.000000e+000,3,9.758502e-001,0.000000e+000,,,,,,,,,,,,,,32,1,4.000000e+000,6.580353e-003,0.000000e+000,0,,0,
1524050090.542,,0.000000e+000,5.499774e+001,-7.797865e-005,0.000000e+000,3,9.762379e-001,0.000000e+000,,,,,,,,,,,,,,32,1,4.000000e+000,3.940582e-003,0.000000e+000,0,,0,
1524050115.792,,0.000000e+000,5.500497e+001,-7.796949e-005,0.000000e+000,3,9.746767e-001,0.000000e+000,,,,,,,,,,,,,,32,1,4.000000e+000,1.316071e-002,0.000000e+000,0,,0,
1524050140.972,,0.000000e+000,5.499642e+001,-7.797553e-005,0.000000e+000,3,9.756390e-001,0.000000e+000,,,,,,,,,,,,,,32,1,4.000000e+000,3.940582e-003,0.000000e+000,0,,0,
1524050165.652,,0.000000e+000,5.499380e+001,-7.795136e-005,0.000000e+000,3,9.751402e-001,0.000000e+000,,,,,,,,,,,,,,32,1,4.000000e+000,1.182938e-002,0.000000e+000,0,,0,
1524050190.372,,0.000000e+000,5.499248e+001,-7.802765e-005,0.000000e+000,3,9.745825e-001,0.000000e+000,,,,,,,,,,,,,,32,1,4.000000e+000,3.940582e-003,0.000000e+000,0,,0,
1524050202.842,,0.000000e+000,5.499708e+001,-7.796755e-005,0.000000e+000,3,9.735543e-001,0.000000e+000,,,,,,,,,,,,,,32,1,4.000000e+000,2.620697e-003,0.000000e+000,0,,0,