File: Experimental Raw Data/TC04-12-01K TRMac VRMde/Raw/TC04-12-01K_TRMac_56K_0.06Kmin_VRMde_55K.dc.raw
[Header]
TITLE,MPMS DC Measurement
BYAPP,MPMS Measurement,2.1,Raw with ABS
FILEOPENTIME, 1524673686.729000 4/25/2018, 10:28:06 AM

INFO, APPNAME, MPMS MultiVu Application, Revision 1.61,  Build 082

INFO, NAME, TC04-12-01K
INFO, WEIGHT, 1.000
INFO, AREA, 1.000
INFO, LENGTH, 1.000
INFO, SHAPE, 0
INFO, COMMENT,
INFO, SEQUENCE FILE: TRMac_56K_0.06Kmin_VRMde_55K.seq


INFO, BACKGROUND DATA FILE:, None


STARTUPAXIS,X,8,LINEAR,AUTO,0.000000,0.000000
STARTUPAXIS,Y1,10,LINEAR,AUTO,0.000000,0.000000


STARTUPGROUP,Longitudinal
FIELDGROUP,Longitudinal,1,3,4,5,6,8,9,10,11,12,13,14,15,16,17,18,19,20,21,22,23
FIELDGROUP,Transverse,1,3,4,5,6,8,9,24,25,26,27,28,29,30,31,32,33,34,35,36,37

PLOT_APPEARANCE,ALL,HORZ_GRID_ON,VERT_GRID_ON,MARKERS_ONLY

[Data]
Time,Comment,Field (Oe),Start Temperature (K),End Temperature (K),Scan,Rejected,Position (cm),Rot Position (deg),Long Voltage,Long Average Voltage,Long Detrended Voltage,Long Demeaned Voltage,Long Regression Fit,Long Detrended Fit,Long Demeaned Fit,Long Scaled Response,Long Avg. Scaled Response,Long Background Response,Long Response [w/ABS],Long Detrended Resp. [w/ABS],Long Fit [w/ABS],Long Detrended Fit [w/ABS],Trans Voltage,Trans Average Voltage,Trans Detrended Voltage,Trans Demeaned Voltage,Trans Regression Fit,Trans Detrended Fit,Trans Demeaned Fit,Trans Scaled Response,Trans Avg Scaled Response,Trans Background Response,Trans Response [w/ABS],Trans Detrended Resp. [w/ABS],Trans Fit [w/ABS],Trans Detrended Fit [w/ABS],
1524673686.719,,0.000000e+000,5.500367e+001,5.498788e+001,1,0,0.000000e+000,0.000000e+000,4.276951e+000,4.276951e+000,-5.492687e-003,-5.492687e-003,4.143825e+000,-1.386189e-001,-1.386189e-001,-7.400755e-006,-7.400755e-006,,,,,,,,,,,,,,,,,,,,
1524673699.259,,0.000000e+000,5.498788e+001,5.499314e+001,1,0,2.709677e+000,0.000000e+000,5.013504e+000,5.013504e+000,1.296253e-001,6.060238e-001,5.052657e+000,1.687784e-001,6.451769e-001,3.845111e-006,3.845111e-006,,,,,,,,,,,,,,,,,,,,
1524673724.599,,0.000000e+000,5.499708e+001,5.499839e+001,1,0,1.290323e+000,0.000000e+000,4.727245e+000,4.727245e+000,6.643564e-002,2.453446e-001,4.709200e+000,4.839116e-002,2.273002e-001,-5.999173e-007,-5.999173e-007,,,,,,,,,,,,,,,,,,,,
1524673737.199,,0.000000e+000,5.499971e+001,5.499839e+001,1,0,4.000000e+000,0.000000e+000,4.878309e+000,4.878309e+000,-1.449884e-001,3.579960e-001,4.912217e+000,-1.110810e-001,3.919034e-001,-3.072346e-007,-3.072346e-007,,,,,,,,,,,,,,,,,,,,
1524673761.879,,0.000000e+000,5.499445e+001,5.499314e+001,1,0,2.580645e+000,0.000000e+000,4.991379e+000,4.991379e+000,1.507644e-001,4.245753e-001,5.011502e+000,1.708879e-001,4.446988e-001,3.689973e-006,3.689973e-006,,,,,,,,,,,,,,,,,,,,
1524673786.689,,0.000000e+000,5.499314e+001,5.499708e+001,1,0,1.161290e+000,0.000000e+000,4.700541e+000,4.700541e+000,-1.467009e-002,8.914375e-002,4.698239e+000,-1.697274e-002,8.684111e-002,-1.845954e-006,-1.845954e-006,,,,,,,,,,,,,,,,,,,,
1524673799.049,,0.000000e+000,5.499182e+001,5.499708e+001,1,0,3.870968e+000,0.000000e+000,4.890516e+000,4.890516e+000,-7.766647e-002,2.646646e-001,4.882580e+000,-8.560295e-002,2.567282e-001,1.149165e-007,1.149165e-007,,,,,,,,,,,,,,,,,,,,
1524673823.890,,0.000000e+000,5.499445e+001,5.500103e+001,1,0,2.451613e+000,0.000000e+000,4.946364e+000,4.946364e+000,1.231014e-001,2.928863e-001,4.987138e+000,1.638752e-001,3.336601e-001,2.753863e-006,2.753863e-006,,,,,,,,,,,,,,,,,,,,
1524673849.640,,0.000000e+000,5.499708e+001,5.499839e+001,1,0,1.032258e+000,0.000000e+000,4.670176e+000,4.670176e+000,-6.674719e-002,3.753185e-003,4.695547e+000,-4.137659e-002,2.912378e-002,-2.762492e-006,-2.762492e-006,,,,,,,,,,,,,,,,,,,,
1524673862.730,,0.000000e+000,5.499839e+001,5.499577e+001,1,0,3.741935e+000,0.000000e+000,4.874647e+000,4.874647e+000,-3.675183e-002,1.911054e-001,4.848375e+000,-6.302413e-002,1.648331e-001,2.209563e-007,2.209563e-007,,,,,,,,,,,,,,,,,,,,
1524673888.540,,0.000000e+000,5.500103e+001,5.500367e+001,1,0,2.322581e+000,0.000000e+000,4.940871e+000,4.940871e+000,1.159068e-001,2.538810e-001,4.961401e+000,1.364361e-001,2.744102e-001,2.523360e-006,2.523360e-006,,,,,,,,,,,,,,,,,,,,
1524673913.750,,0.000000e+000,5.499708e+001,5.499971e+001,1,0,9.032258e-001,0.000000e+000,4.658427e+000,4.658427e+000,-9.416655e-002,-4.662848e-002,4.702758e+000,-4.983548e-002,-2.297401e-003,-3.163252e-006,-3.163252e-006,,,,,,,,,,,,,,,,,,,,
1524673926.480,,0.000000e+000,5.499971e+001,5.499314e+001,1,0,3.612903e+000,0.000000e+000,4.873121e+000,4.873121e+000,-1.284148e-002,1.536617e-001,4.850784e+000,-3.517844e-002,1.313248e-001,3.191526e-007,3.191526e-007,,,,,,,,,,,,,,,,,,,,
1524673951.740,,0.000000e+000,5.499445e+001,5.499708e+001,1,0,2.193548e+000,0.000000e+000,4.952468e+000,4.952468e+000,1.274879e-001,2.242651e-001,4.935344e+000,1.103637e-001,2.071409e-001,2.652523e-006,2.652523e-006,,,,,,,,,,,,,,,,,,,,
1524673976.460,,0.000000e+000,5.499577e+001,5.499839e+001,1,0,7.741935e-001,0.000000e+000,4.699168e+000,4.699168e+000,-1.005577e-001,-6.733465e-002,4.739321e+000,-6.040518e-002,-2.718210e-002,-3.241934e-006,-3.241934e-006,,,,,,,,,,,,,,,,,,,,
1524673989.350,,0.000000e+000,5.499839e+001,5.499971e+001,1,0,3.483871e+000,0.000000e+000,4.890822e+000,4.890822e+000,4.403503e-003,1.357889e-001,4.881500e+000,-4.918663e-003,1.264668e-001,4.750327e-007,4.750327e-007,,,,,,,,,,,,,,,,,,,,
1524674014.550,,0.000000e+000,5.499182e+001,5.499577e+001,1,0,2.064516e+000,0.000000e+000,4.939193e+000,4.939193e+000,9.918802e-002,1.690869e-001,4.912509e+000,7.250469e-002,1.424036e-001,1.966575e-006,1.966575e-006,,,,,,,,,,,,,,,,,,,,
1524674039.270,,0.000000e+000,5.499445e+001,5.499971e+001,1,0,6.451613e-001,0.000000e+000,4.716869e+000,4.716869e+000,-9.116306e-002,-7.348442e-002,4.771042e+000,-3.698960e-002,-1.931095e-002,-2.703760e-006,-2.703760e-006,,,,,,,,,,,,,,,,,,,,
1524674051.850,,0.000000e+000,5.499971e+001,5.499971e+001,1,0,3.354839e+000,0.000000e+000,4.881666e+000,4.881666e+000,2.697835e-003,8.817053e-002,4.897734e+000,1.876582e-002,1.042385e-001,1.454900e-007,1.454900e-007,,,,,,,,,,,,,,,,,,,,
1524674077.050,,0.000000e+000,5.500367e+001,5.499445e+001,1,0,1.935484e+000,0.000000e+000,4.896773e+000,4.896773e+000,4.841740e-002,9.130430e-002,4.883629e+000,3.527386e-002,7.816076e-002,8.085917e-007,8.085917e-007,,,,,,,,,,,,,,,,,,,,
1524674102.050,,0.000000e+000,5.499708e+001,5.500629e+001,1,0,5.161290e-001,0.000000e+000,4.771191e+000,4.771191e+000,-5.400502e-002,-4.257679e-002,4.797377e+000,-2.781950e-002,-1.639128e-002,-1.781227e-006,-1.781227e-006,,,,,,,,,,,,,,,,,,,,
1524674114.860,,0.000000e+000,5.499839e+001,5.499577e+001,1,0,3.225806e+000,0.000000e+000,4.893874e+000,4.893874e+000,9.405668e-003,7.897949e-002,4.924074e+000,3.960615e-002,1.091800e-001,2.255401e-007,2.255401e-007,,,,,,,,,,,,,,,,,,,,
1524674140.560,,0.000000e+000,5.499971e+001,5.500497e+001,1,0,1.806452e+000,0.000000e+000,4.900588e+000,4.900588e+000,2.226753e-002,5.698109e-002,4.884717e+000,6.396483e-003,4.111004e-002,1.986191e-007,1.986191e-007,,,,,,,,,,,,,,,,,,,,
1524674165.750,,0.000000e+000,5.499708e+001,5.500235e+001,1,0,3.870968e-001,0.000000e+000,4.857404e+000,4.857404e+000,-2.172800e-002,-1.584291e-002,4.865378e+000,-1.375385e-002,-7.868767e-003,-8.794304e-007,-8.794304e-007,,,,,,,,,,,,,,,,,,,,
1524674177.850,,0.000000e+000,5.500235e+001,5.499839e+001,1,0,3.096774e+000,0.000000e+000,4.948806e+000,4.948806e+000,2.373350e-002,6.010818e-002,4.991041e+000,6.596839e-002,1.023431e-001,3.308814e-007,3.308814e-007,,,,,,,,,,,,,,,,,,,,
1524674204.110,,0.000000e+000,5.499445e+001,5.499577e+001,1,0,1.677419e+000,0.000000e+000,4.921340e+000,4.921340e+000,-1.675454e-003,2.192450e-002,4.902765e+000,-2.025017e-002,3.349781e-003,-2.788292e-007,-2.788292e-007,,,,,,,,,,,,,,,,,,,,
1524674232.954,,0.000000e+000,5.499971e+001,5.500235e+001,1,0,2.580645e-001,0.000000e+000,4.946364e+000,4.946364e+000,4.856039e-002,5.539513e-002,4.890398e+000,-7.406462e-003,-5.717278e-004,3.595924e-007,3.595924e-007,,,,,,,,,,,,,,,,,,,,
1524674246.666,,0.000000e+000,5.499182e+001,5.499708e+001,1,0,2.967742e+000,0.000000e+000,4.996719e+000,4.996719e+000,1.630784e-002,9.662294e-002,4.980459e+000,4.769000e-005,8.036280e-002,7.147755e-007,7.147755e-007,,,,,,,,,,,,,,,,,,,,
1524674273.408,,0.000000e+000,5.499577e+001,5.500235e+001,1,0,1.548387e+000,0.000000e+000,4.901503e+000,4.901503e+000,-5.140109e-002,-1.958466e-002,4.961617e+000,8.713292e-003,4.052973e-002,-1.316541e-006,-1.316541e-006,,,,,,,,,,,,,,,,,,,,
1524674300.070,,0.000000e+000,5.499971e+001,5.499577e+001,1,0,1.290323e-001,0.000000e+000,4.995346e+000,4.995346e+000,6.504067e-002,6.761122e-002,4.925543e+000,-4.762565e-003,-2.192020e-003,8.712959e-007,8.712959e-007,,,,,,,,,,,,,,,,,,,,
1524674312.400,,0.000000e+000,5.500367e+001,5.500235e+001,1,0,2.838710e+000,0.000000e+000,5.009232e+000,5.009232e+000,3.513505e-002,-1.783371e-003,5.022287e+000,4.819085e-002,1.127243e-002,8.171774e-007,8.171774e-007,,,,,,,,,,,,,,,,,,,,
1524674337.510,,0.000000e+000,5.500367e+001,5.499971e+001,1,0,1.419355e+000,0.000000e+000,4.906996e+000,4.906996e+000,-7.888529e-002,-9.506845e-002,4.905265e+000,-8.061621e-002,-9.679937e-002,-1.134176e-006,-1.134176e-006,,,,,,,,,,,,,,,,,,,,
1524674364.262,,0.000000e+000,5.499577e+001,5.499839e+001,1,0,0.000000e+000,0.000000e+000,5.018998e+000,5.018998e+000,3.071308e-002,3.071308e-002,4.994334e+000,6.049633e-003,6.049633e-003,1.796376e-006,1.796376e-006,,,,,,,,,,,,,,,,,,,,
1524674376.512,,0.000000e+000,5.499839e+001,5.500103e+001,1,0,2.709677e+000,0.000000e+000,4.991379e+000,4.991379e+000,3.235276e-002,-2.949238e-003,5.012508e+000,5.348237e-002,1.818037e-002,8.164643e-007,8.164643e-007,,,,,,,,,,,,,,,,,,,,
1524674401.772,,0.000000e+000,5.499577e+001,5.500235e+001,1,0,1.290323e+000,0.000000e+000,4.856794e+000,4.856794e+000,-9.909134e-002,-1.171885e-001,4.856124e+000,-9.976082e-002,-1.178579e-001,-1.521345e-006,-1.521345e-006,,,,,,,,,,,,,,,,,,,,
1524674413.872,,0.000000e+000,5.500497e+001,5.499839e+001,1,0,4.000000e+000,0.000000e+000,4.940871e+000,4.940871e+000,2.334746e-002,-2.099514e-002,4.925197e+000,7.672866e-003,-3.666973e-002,1.137960e-007,1.137960e-007,,,,,,,,,,,,,,,,,,,,
1524674438.812,,0.000000e+000,5.499839e+001,5.499971e+001,1,0,2.580645e+000,0.000000e+000,4.941176e+000,4.941176e+000,2.027569e-002,-1.820564e-002,4.971735e+000,5.083428e-002,1.235294e-002,5.717302e-007,5.717302e-007,,,,,,,,,,,,,,,,,,,,
1524674463.702,,0.000000e+000,5.499839e+001,5.500103e+001,1,0,1.161290e+000,0.000000e+000,4.781720e+000,4.781720e+000,-7.552515e-002,-8.512354e-002,4.829324e+000,-2.792059e-002,-3.751898e-002,-1.698660e-006,-1.698660e-006,,,,,,,,,,,,,,,,,,,,
1524674476.242,,0.000000e+000,5.499839e+001,5.500367e+001,1,0,3.870968e+000,0.000000e+000,4.837263e+000,4.837263e+000,-4.296022e-003,3.467464e-002,4.837743e+000,-3.815371e-003,3.515530e-002,1.611043e-007,1.611043e-007,,,,,,,,,,,,,,,,,,,,
1524674501.422,,0.000000e+000,5.499708e+001,5.500629e+001,1,0,2.451613e+000,0.000000e+000,4.842756e+000,4.842756e+000,4.214339e-002,-9.871483e-003,4.846577e+000,4.596429e-002,-6.050587e-003,1.097054e-006,1.097054e-006,,,,,,,,,,,,,,,,,,,,
1524674528.015,,0.000000e+000,5.499708e+001,5.499314e+001,1,0,1.032258e+000,0.000000e+000,4.697795e+000,4.697795e+000,-8.290876e-002,-9.559917e-002,4.755234e+000,-2.546991e-002,-3.816032e-002,-1.777968e-006,-1.777968e-006,,,,,,,,,,,,,,,,,,,,
1524674541.585,,0.000000e+000,5.499314e+001,5.499051e+001,1,0,3.741935e+000,0.000000e+000,4.771191e+000,4.771191e+000,4.053378e-002,-1.767826e-002,4.766871e+000,3.621412e-002,-2.199793e-002,-1.205772e-007,-1.205772e-007,,,,,,,,,,,,,,,,,,,,
1524674566.765,,0.000000e+000,5.500367e+001,5.499708e+001,1,0,2.322581e+000,0.000000e+000,4.799573e+000,4.799573e+000,4.500080e-002,2.097654e-002,4.775758e+000,2.118564e-002,-2.838612e-003,6.287883e-007,6.287883e-007,,,,,,,,,,,,,,,,,,,,
1524674591.805,,0.000000e+000,5.499051e+001,5.499577e+001,1,0,9.032258e-001,0.000000e+000,4.687419e+000,4.687419e+000,-7.436912e-002,-8.627844e-002,4.738328e+000,-2.346007e-002,-3.536940e-002,-1.534994e-006,-1.534994e-006,,,,,,,,,,,,,,,,,,,,
1524674604.045,,0.000000e+000,5.499314e+001,5.499708e+001,1,0,3.612903e+000,0.000000e+000,4.752117e+000,4.752117e+000,2.476727e-002,-1.432085e-002,4.769278e+000,4.192816e-002,2.840042e-003,-1.880398e-007,-1.880398e-007,,,,,,,,,,,,,,,,,,,,
1524674628.805,,0.000000e+000,5.499182e+001,5.499445e+001,1,0,2.193548e+000,0.000000e+000,4.777905e+000,4.777905e+000,4.435810e-002,2.408457e-002,4.735060e+000,1.513325e-003,-1.876020e-002,7.037597e-007,7.037597e-007,,,,,,,,,,,,,,,,,,,,
1524674653.695,,0.000000e+000,5.499971e+001,5.499839e+001,1,0,7.741935e-001,0.000000e+000,4.670786e+000,4.670786e+000,-7.638063e-002,-8.398819e-002,4.733389e+000,-1.377811e-002,-2.138567e-002,-1.573775e-006,-1.573775e-006,,,,,,,,,,,,,,,,,,,,
1524674668.437,,0.000000e+000,5.499839e+001,5.499708e+001,1,0,3.483871e+000,0.000000e+000,4.759441e+000,4.759441e+000,5.488141e-003,3.559542e-002,4.761906e+000,7.952913e-003,3.806019e-002,3.560417e-007,3.560417e-007,,,,,,,,,,,,,,,,,,,,
1524674694.139,,0.000000e+000,5.500103e+001,5.499445e+001,1,0,2.064516e+000,0.000000e+000,4.749981e+000,4.749981e+000,2.941483e-002,-5.874634e-003,4.710041e+000,-1.052505e-002,-4.581451e-002,3.780733e-007,3.780733e-007,,,,,,,,,,,,,,,,,,,,
1524674723.733,,0.000000e+000,5.499971e+001,5.499445e+001,1,0,6.451613e-001,0.000000e+000,4.689403e+000,4.689403e+000,-3.404710e-002,-3.140497e-002,4.730248e+000,6.798770e-003,9.440899e-003,-8.012285e-007,-8.012285e-007,,,,,,,,,,,,,,,,,,,,
1524674737.945,,0.000000e+000,5.500103e+001,5.499839e+001,1,0,3.354839e+000,0.000000e+000,4.744183e+000,4.744183e+000,1.018265e-002,3.990507e-002,4.742760e+000,8.759771e-003,3.848219e-002,4.610047e-007,4.610047e-007,,,,,,,,,,,,,,,,,,,,
1524674766.759,,0.000000e+000,5.500235e+001,5.500103e+001,1,0,1.935484e+000,0.000000e+000,4.712139e+000,4.712139e+000,-3.914662e-003,4.433155e-003,4.693597e+000,-2.245647e-002,-1.410866e-002,-4.172034e-008,-4.172034e-008,,,,,,,,,,,,,,,,,,,,
1524674795.073,,0.000000e+000,5.499445e+001,5.498919e+001,1,0,5.161290e-001,0.000000e+000,4.703288e+000,4.703288e+000,4.911263e-003,5.806446e-003,4.708872e+000,1.049550e-002,1.139069e-002,1.272128e-007,1.272128e-007,,,,,,,,,,,,,,,,,,,,
1524674809.315,,0.000000e+000,5.500103e+001,5.500235e+001,1,0,3.225806e+000,0.000000e+000,4.714580e+000,4.714580e+000,1.373053e-002,2.131748e-002,4.706711e+000,5.861763e-003,1.344872e-002,3.998575e-007,3.998575e-007,,,,,,,,,,,,,,,,,,,,
1524674837.649,,0.000000e+000,5.499577e+001,5.500367e+001,1,0,1.806452e+000,0.000000e+000,4.670634e+000,4.670634e+000,-2.535312e-002,-2.377558e-002,4.674019e+000,-2.196805e-002,-2.039051e-002,-5.168113e-007,-5.168113e-007,,,,,,,,,,,,,,,,,,,,
1524674865.243,,0.000000e+000,5.499971e+001,5.499445e+001,1,0,3.870968e-001,0.000000e+000,4.720378e+000,4.720378e+000,3.442867e-002,3.582859e-002,4.694921e+000,8.971766e-003,1.037169e-002,7.277558e-007,7.277558e-007,,,,,,,,,,,,,,,,,,,,
1524674879.445,,0.000000e+000,5.500103e+001,5.499577e+001,1,0,3.096774e+000,0.000000e+000,4.703746e+000,4.703746e+000,1.337949e-002,2.302885e-002,4.693891e+000,3.523746e-003,1.317310e-002,4.066387e-007,4.066387e-007,,,,,,,,,,,,,,,,,,,,
1524674907.879,,0.000000e+000,5.500367e+001,5.499314e+001,1,0,1.677419e+000,0.000000e+000,4.628061e+000,4.628061e+000,-5.157429e-002,-4.951715e-002,4.655799e+000,-2.383668e-002,-2.177954e-002,-1.093285e-006,-1.093285e-006,,,,,,,,,,,,,,,,,,,,
1524674936.363,,0.000000e+000,5.499314e+001,5.499445e+001,1,0,2.580645e-001,0.000000e+000,4.736095e+000,4.736095e+000,6.944204e-002,6.960297e-002,4.680367e+000,1.371361e-002,1.387453e-002,1.606852e-006,1.606852e-006,,,,,,,,,,,,,,,,,,,,
1524674950.595,,0.000000e+000,5.499839e+001,5.499445e+001,1,0,2.967742e+000,0.000000e+000,4.682384e+000,4.682384e+000,1.425384e-002,1.668024e-002,4.668042e+000,-8.799291e-005,2.338409e-003,4.041794e-007,4.041794e-007,,,,,,,,,,,,,,,,,,,,
1524674978.439,,0.000000e+000,5.499971e+001,5.499445e+001,1,0,1.548387e+000,0.000000e+000,4.589914e+000,4.589914e+000,-7.571539e-002,-7.182598e-002,4.646050e+000,-1.957927e-002,-1.568985e-002,-1.642911e-006,-1.642911e-006,,,,,,,,,,,,,,,,,,,,
1524675006.843,,0.000000e+000,5.500235e+001,5.499971e+001,1,0,1.290323e-001,0.000000e+000,4.740673e+000,4.740673e+000,8.229917e-002,8.245897e-002,4.671256e+000,1.288169e-002,1.304150e-002,1.877808e-006,1.877808e-006,,,,,,,,,,,,,,,,,,,,
1524675021.275,,0.000000e+000,5.499839e+001,5.499314e+001,1,0,2.838710e+000,0.000000e+000,4.677653e+000,4.677653e+000,1.463128e-002,2.463150e-002,4.658078e+000,-4.944318e-003,5.055904e-003,4.412868e-007,4.412868e-007,,,,,,,,,,,,,,,,,,,,
1524675049.919,,0.000000e+000,5.499445e+001,5.499445e+001,1,0,1.419355e+000,0.000000e+000,4.579690e+000,4.579690e+000,-7.104006e-002,-7.276440e-002,4.634996e+000,-1.573458e-002,-1.745892e-002,-1.505701e-006,-1.505701e-006,,,,,,,,,,,,,,,,,,,,
1524675077.903,,0.000000e+000,5.500103e+001,5.499314e+001,1,0,0.000000e+000,0.000000e+000,4.766461e+000,4.766461e+000,1.327705e-001,1.327705e-001,4.644449e+000,1.075888e-002,1.075888e-002,2.949484e-006,2.949484e-006,,,,,,,,,,,,,,,,,,,,
1524675091.945,,0.000000e+000,5.498525e+001,5.500761e+001,1,0,2.709677e+000,0.000000e+000,4.665598e+000,4.665598e+000,2.338781e-002,2.826834e-002,4.631367e+000,-1.084337e-002,-5.962849e-003,6.171176e-007,6.171176e-007,,,,,,,,,,,,,,,,,,,,
1524675120.559,,0.000000e+000,5.499445e+001,5.499577e+001,1,0,1.290323e+000,0.000000e+000,4.542153e+000,4.542153e+000,-9.205642e-002,-9.394169e-002,4.623923e+000,-1.028600e-002,-1.217127e-002,-1.970533e-006,-1.970533e-006,,,,,,,,,,,,,,,,,,,,
1524675134.721,,0.000000e+000,5.499314e+001,5.501287e+001,1,0,4.000000e+000,0.000000e+000,4.644999e+000,4.644999e+000,1.608293e-002,9.891033e-003,4.639244e+000,1.032798e-002,4.136086e-003,3.805326e-007,3.805326e-007,,,,,,,,,,,,,,,,,,,,
1524675162.875,,0.000000e+000,5.499445e+001,5.499314e+001,1,0,2.580645e+000,0.000000e+000,4.650187e+000,4.650187e+000,2.585356e-002,2.914858e-002,4.606004e+000,-1.832969e-002,-1.503468e-002,6.721966e-007,6.721966e-007,,,,,,,,,,,,,,,,,,,,
1524675190.879,,0.000000e+000,5.499839e+001,5.499708e+001,1,0,1.161290e+000,0.000000e+000,4.524605e+000,4.524605e+000,-9.310927e-002,-9.391975e-002,4.612272e+000,-5.442287e-003,-6.252766e-003,-1.994951e-006,-1.994951e-006,,,,,,,,,,,,,,,,,,,,
1524675203.219,,0.000000e+000,5.500235e+001,5.499445e+001,1,0,3.870968e+000,0.000000e+000,4.631723e+000,4.631723e+000,5.070765e-002,-4.000711e-002,4.595560e+000,1.454384e-002,-7.617092e-002,4.915928e-007,4.915928e-007,,,,,,,,,,,,,,,,,,,,
1524675231.304,,0.000000e+000,5.500103e+001,5.500367e+001,1,0,2.451613e+000,0.000000e+000,4.465095e+000,4.465095e+000,2.409226e-002,7.338524e-004,4.415985e+000,-2.501767e-002,-4.837608e-002,5.589536e-007,5.589536e-007,,,,,,,,,,,,,,,,,,,,
1524675258.476,,0.000000e+000,5.499708e+001,5.499708e+001,1,0,1.032258e+000,0.000000e+000,4.582132e+000,4.582132e+000,-6.708205e-002,-8.797884e-002,4.649112e+000,-1.021624e-004,-2.099895e-002,-1.121545e-006,-1.121545e-006,,,,,,,,,,,,,,,,,,,,
1524675270.406,,0.000000e+000,5.500497e+001,5.499577e+001,1,0,3.741935e+000,0.000000e+000,4.319066e+000,4.319066e+000,4.350495e-002,-5.389166e-002,4.293305e+000,1.774382e-002,-7.965279e-002,3.316818e-007,3.316818e-007,,,,,,,,,,,,,,,,,,,,
1524675299.240,,0.000000e+000,5.499839e+001,5.499708e+001,1,0,2.322581e+000,0.000000e+000,4.524300e+000,4.524300e+000,2.057446e-002,-2.818966e-002,4.473743e+000,-2.998220e-002,-7.874632e-002,4.410686e-007,4.410686e-007,,,,,,,,,,,,,,,,,,,,
1524675326.182,,0.000000e+000,5.499971e+001,5.499445e+001,1,0,9.032258e-001,0.000000e+000,4.133516e+000,4.133516e+000,-7.886783e-002,-7.728815e-002,4.217414e+000,5.029760e-003,6.609440e-003,-1.710403e-006,-1.710403e-006,,,,,,,,,,,,,,,,,,,,
1524675340.064,,0.000000e+000,5.499971e+001,5.499839e+001,1,0,3.612903e+000,0.000000e+000,4.411841e+000,4.411841e+000,1.178616e-002,-5.842304e-002,4.415800e+000,1.574534e-002,-5.446386e-002,-1.242443e-007,-1.242443e-007,,,,,,,,,,,,,,,,,,,,
1524675367.116,,0.000000e+000,5.499577e+001,5.499577e+001,1,0,2.193548e+000,0.000000e+000,4.335699e+000,4.335699e+000,9.434319e-003,-2.961826e-002,4.293927e+000,-3.233709e-002,-7.138968e-002,2.365705e-007,2.365705e-007,,,,,,,,,,,,,,,,,,,,
1524675395.430,,0.000000e+000,5.499971e+001,5.500235e+001,1,0,7.741935e-001,0.000000e+000,4.020447e+000,4.020447e+000,-3.593828e-002,-3.531408e-002,4.066659e+000,1.027344e-002,1.089764e-002,-7.303606e-007,-7.303606e-007,,,,,,,,,,,,,,,,,,,,
1524675407.880,,0.000000e+000,5.499839e+001,5.499708e+001,1,0,3.483871e+000,0.000000e+000,4.109865e+000,4.109865e+000,4.140949e-002,-4.890442e-002,4.097916e+000,2.946042e-002,-6.085348e-002,4.375615e-007,4.375615e-007,,,,,,,,,,,,,,,,,,,,
1524675434.592,,0.000000e+000,5.499708e+001,5.499445e+001,1,0,2.064516e+000,0.000000e+000,4.031128e+000,4.031128e+000,-2.899366e-003,-7.796288e-004,3.996572e+000,-3.745623e-002,-3.533649e-002,1.942681e-008,1.942681e-008,,,,,,,,,,,,,,,,,,,,
1524675458.972,,0.000000e+000,5.500629e+001,5.499839e+001,1,0,6.451613e-001,0.000000e+000,4.068971e+000,4.068971e+000,-4.522392e-002,-5.607557e-002,4.070590e+000,-4.360410e-002,-5.445576e-002,-1.479202e-007,-1.479202e-007,,,,,,,,,,,,,,,,,,,,
1524675471.412,,0.000000e+000,5.499971e+001,5.499445e+001,1,0,3.354839e+000,0.000000e+000,4.122530e+000,4.122530e+000,2.573115e-002,-4.031372e-002,4.130635e+000,3.383642e-002,-3.220844e-002,2.817978e-007,2.817978e-007,,,,,,,,,,,,,,,,,,,,
1524675500.326,,0.000000e+000,5.499445e+001,5.500235e+001,1,0,1.935484e+000,0.000000e+000,4.149691e+000,4.149691e+000,-2.694163e-002,-2.049971e-002,4.137743e+000,-3.888973e-002,-3.244781e-002,-5.188922e-007,-5.188922e-007,,,,,,,,,,,,,,,,,,,,
1524675524.576,,0.000000e+000,5.499314e+001,5.500497e+001,1,0,5.161290e-001,0.000000e+000,4.242619e+000,4.242619e+000,-2.361692e-002,-3.322411e-002,4.238945e+000,-2.729000e-002,-3.689718e-002,4.425965e-007,4.425965e-007,,,,,,,,,,,,,,,,,,,,
1524675539.438,,0.000000e+000,5.499314e+001,5.499971e+001,1,0,3.225806e+000,0.000000e+000,4.271611e+000,4.271611e+000,1.027108e-002,1.600790e-002,4.271487e+000,1.014757e-002,1.588440e-002,3.485475e-007,3.485475e-007,,,,,,,,,,,,,,,,,,,,
1524675564.048,,0.000000e+000,5.499577e+001,5.499839e+001,1,0,1.806452e+000,0.000000e+000,4.262455e+000,4.262455e+000,-5.658912e-002,-9.210682e-002,4.257606e+000,-6.143808e-002,-9.695578e-002,-8.454226e-007,-8.454226e-007,,,,,,,,,,,,,,,,,,,,
1524675591.000,,0.000000e+000,5.500367e+001,5.499708e+001,1,0,3.870968e-001,0.000000e+000,4.393836e+000,4.393836e+000,-8.240325e-003,-1.690769e-002,4.390211e+000,-1.186524e-002,-2.053261e-002,9.938667e-007,9.938667e-007,,,,,,,,,,,,,,,,,,,,
1524675603.480,,0.000000e+000,5.499839e+001,5.499708e+001,1,0,3.096774e+000,0.000000e+000,4.387732e+000,4.387732e+000,2.932433e-002,-4.029322e-002,4.401886e+000,4.347829e-002,-2.613926e-002,4.317117e-007,4.317117e-007,,,,,,,,,,,,,,,,,,,,
1524675628.870,,0.000000e+000,5.499708e+001,5.499577e+001,1,0,1.677419e+000,0.000000e+000,4.525521e+000,4.525521e+000,-8.146688e-002,-1.496506e-001,4.530216e+000,-7.677146e-002,-1.449552e-001,-1.227803e-006,-1.227803e-006,,,,,,,,,,,,,,,,,,,,
1524675654.660,,0.000000e+000,5.499182e+001,5.499839e+001,1,0,2.580645e-001,0.000000e+000,4.367895e+000,4.367895e+000,2.116935e-002,1.614332e-002,4.356009e+000,9.282751e-003,4.256725e-003,1.639055e-006,1.639055e-006,,,,,,,,,,,,,,,,,,,,
1524675668.812,,0.000000e+000,5.499839e+001,5.499577e+001,1,0,2.967742e+000,0.000000e+000,4.341039e+000,4.341039e+000,4.277250e-005,1.757765e-002,4.340889e+000,-1.069544e-004,1.742792e-002,1.760782e-007,1.760782e-007,,,,,,,,,,,,,,,,,,,,
1524675694.072,,0.000000e+000,5.500103e+001,5.499708e+001,1,0,1.548387e+000,0.000000e+000,4.329443e+000,4.329443e+000,-8.423220e-002,-1.140237e-001,4.331585e+000,-8.208930e-002,-1.118808e-001,-1.391221e-006,-1.391221e-006,,,,,,,,,,,,,,,,,,,,
1524675719.162,,0.000000e+000,5.500103e+001,5.499971e+001,1,0,1.290323e-001,0.000000e+000,4.502174e+000,4.502174e+000,1.487886e-002,1.230717e-002,4.508554e+000,2.125846e-002,1.868677e-002,1.486129e-006,1.486129e-006,,,,,,,,,,,,,,,,,,,,
1524675731.942,,0.000000e+000,5.499577e+001,5.500629e+001,1,0,2.838710e+000,0.000000e+000,4.477607e+000,4.477607e+000,2.779329e-002,-4.908848e-002,4.502957e+000,5.314339e-002,-2.373838e-002,4.924223e-007,4.924223e-007,,,,,,,,,,,,,,,,,,,,
1524675759.314,,0.000000e+000,5.499445e+001,5.500235e+001,1,0,1.419355e+000,0.000000e+000,4.427711e+000,4.427711e+000,-7.610703e-002,-7.720804e-002,4.485175e+000,-1.864243e-002,-1.974344e-002,-1.609558e-006,-1.609558e-006,,,,,,,,,,,,,,,,,,,,
1524675784.714,,0.000000e+000,5.499971e+001,5.499839e+001,1,0,0.000000e+000,0.000000e+000,4.672160e+000,4.672160e+000,7.394266e-002,7.394266e-002,4.636628e+000,3.841019e-002,3.841019e-002,2.950532e-006,2.950532e-006,,,,,,,,,,,,,,,,,,,,
1524675796.904,,0.000000e+000,5.500103e+001,5.499708e+001,1,0,2.709677e+000,0.000000e+000,4.591135e+000,4.591135e+000,2.668752e-002,-4.158306e-002,4.613129e+000,4.868211e-002,-1.958847e-002,5.616457e-007,5.616457e-007,,,,,,,,,,,,,,,,,,,,
1524675821.944,,0.000000e+000,5.500103e+001,5.499445e+001,1,0,1.290323e+000,0.000000e+000,4.524758e+000,4.524758e+000,-1.065172e-001,-1.370058e-001,4.518317e+000,-1.129578e-001,-1.434464e-001,-1.664317e-006,-1.664317e-006,,,,,,,,,,,,,,,,,,,,
1524675834.664,,0.000000e+000,5.499182e+001,5.499182e+001,1,0,4.000000e+000,0.000000e+000,4.632181e+000,4.632181e+000,4.997458e-002,-4.829979e-002,4.595273e+000,1.306595e-002,-8.520842e-002,3.789610e-007,3.789610e-007,,,,,,,,,,,,,,,,,,,,
1524675859.864,,0.000000e+000,5.499971e+001,5.499445e+001,1,0,2.580645e+000,0.000000e+000,4.675822e+000,4.675822e+000,2.064898e-002,-4.328060e-002,4.691298e+000,3.612426e-002,-2.780533e-002,4.925678e-007,4.925678e-007,,,,,,,,,,,,,,,,,,,,
1524675885.204,,0.000000e+000,5.499577e+001,5.499577e+001,1,0,1.161290e+000,0.000000e+000,4.607461e+000,4.607461e+000,-1.158107e-001,-1.445642e-001,4.614018e+000,-1.092538e-001,-1.380072e-001,-1.793072e-006,-1.793072e-006,,,,,,,,,,,,,,,,,,,,
1524675898.024,,0.000000e+000,5.499577e+001,5.500497e+001,1,0,3.870968e+000,0.000000e+000,4.714275e+000,4.714275e+000,4.544364e-002,-4.102278e-002,4.683131e+000,1.429950e-002,-7.216692e-002,4.083122e-007,4.083122e-007,,,,,,,,,,,,,,,,,,,,
1524675922.934,,0.000000e+000,5.499182e+001,5.499708e+001,1,0,2.451613e+000,0.000000e+000,4.758831e+000,4.758831e+000,2.343101e-002,-2.683353e-002,4.756038e+000,2.063770e-002,-2.962685e-002,6.314949e-007,6.314949e-007,,,,,,,,,,,,,,,,,,,,
1524675947.655,,0.000000e+000,5.500367e+001,5.499708e+001,1,0,1.032258e+000,0.000000e+000,4.687572e+000,4.687572e+000,-1.150158e-001,-1.407619e-001,4.707552e+000,-9.503488e-002,-1.207809e-001,-1.720182e-006,-1.720182e-006,,,,,,,,,,,,,,,,,,,,
1524675960.255,,0.000000e+000,5.499182e+001,5.500235e+001,1,0,3.741935e+000,0.000000e+000,4.788281e+000,4.788281e+000,4.414309e-002,-4.787540e-002,4.763716e+000,1.957787e-002,-7.244062e-002,3.921596e-007,3.921596e-007,,,,,,,,,,,,,,,,,,,,
1524675984.875,,0.000000e+000,5.499971e+001,5.499971e+001,1,0,2.322581e+000,0.000000e+000,4.818799e+000,4.818799e+000,1.094216e-002,-4.567146e-002,4.814895e+000,7.037819e-003,-4.957581e-002,4.153117e-007,4.153117e-007,,,,,,,,,,,,,,,,,,,,
1524676035.285,,0.000000e+000,5.499839e+001,5.499971e+001,1,0,9.032258e-001,0.000000e+000,4.782177e+000,4.782177e+000,-8.956466e-002,-1.143699e-001,4.785615e+000,-8.612714e-002,-1.109324e-001,-1.004650e-006,-1.004650e-006,,,,,,,,,,,,,,,,,,,,
1524676047.915,,0.000000e+000,5.499314e+001,5.500103e+001,1,0,3.612903e+000,0.000000e+000,4.855115e+000,4.855115e+000,4.489015e-002,-3.598690e-002,4.834847e+000,2.462171e-002,-5.625534e-002,5.339680e-007,5.339680e-007,,,,,,,,,,,,,,,,,,,,
1524676074.145,,0.000000e+000,5.500235e+001,5.499971e+001,1,0,2.193548e+000,0.000000e+000,4.845808e+000,4.845808e+000,-6.653380e-004,-6.615639e-002,4.835598e+000,-1.087442e-002,-7.636547e-002,2.277811e-007,2.277811e-007,,,,,,,,,,,,,,,,,,,,
1524676099.345,,0.000000e+000,5.499708e+001,5.499708e+001,1,0,7.741935e-001,0.000000e+000,4.821088e+000,4.821088e+000,-7.400474e-002,-9.768248e-002,4.829376e+000,-6.571636e-002,-8.939409e-002,-5.263137e-007,-5.263137e-007,,,,,,,,,,,,,,,,,,,,
1524676111.385,,0.000000e+000,5.499708e+001,5.499708e+001,1,0,3.483871e+000,0.000000e+000,4.861372e+000,4.861372e+000,3.013546e-002,-4.677963e-002,4.858530e+000,2.729303e-002,-4.962206e-002,2.663874e-007,2.663874e-007,,,,,,,,,,,,,,,,,,,,
1524676136.535,,0.000000e+000,5.499839e+001,5.499577e+001,1,0,2.064516e+000,0.000000e+000,4.854200e+000,4.854200e+000,-1.995303e-002,-7.160044e-002,4.846272e+000,-2.788045e-002,-7.952785e-002,-1.470617e-007,-1.470617e-007,,,,,,,,,,,,,,,,,,,,
1524676161.675,,0.000000e+000,5.501024e+001,5.499708e+001,1,0,6.451613e-001,0.000000e+000,4.865339e+000,4.865339e+000,-4.848310e-002,-6.418180e-002,4.868906e+000,-4.491684e-002,-6.061554e-002,-3.169407e-008,-3.169407e-008,,,,,,,,,,,,,,,,,,,,
1524676174.425,,0.000000e+000,5.499314e+001,5.499577e+001,1,0,3.354839e+000,0.000000e+000,4.872816e+000,4.872816e+000,2.136103e-002,-7.237911e-002,4.888247e+000,3.679196e-002,-5.694818e-002,2.614979e-008,2.614979e-008,,,,,,,,,,,,,,,,,,,,
1524676199.625,,0.000000e+000,5.499839e+001,5.499577e+001,1,0,1.935484e+000,0.000000e+000,4.855268e+000,4.855268e+000,-4.403020e-002,-9.364939e-002,4.850604e+000,-4.869462e-002,-9.831381e-002,-5.955371e-007,-5.955371e-007,,,,,,,,,,,,,,,,,,,,
1524676224.845,,0.000000e+000,5.499051e+001,5.499839e+001,1,0,5.161290e-001,0.000000e+000,4.911269e+000,4.911269e+000,-2.276463e-002,-3.593779e-002,4.905714e+000,-2.831931e-002,-4.149246e-002,6.763294e-007,6.763294e-007,,,,,,,,,,,,,,,,,,,,
1524676237.065,,0.000000e+000,5.499839e+001,5.499971e+001,1,0,3.225806e+000,0.000000e+000,4.911726e+000,4.911726e+000,3.032573e-002,-4.453087e-002,4.920923e+000,3.952249e-002,-3.533411e-002,3.786554e-007,3.786554e-007,,,,,,,,,,,,,,,,,,,,
1524676262.165,,0.000000e+000,5.500103e+001,5.499577e+001,1,0,1.806452e+000,0.000000e+000,4.850843e+000,4.850843e+000,-5.891880e-002,-1.133251e-001,4.840999e+000,-6.876311e-002,-1.231694e-001,-8.781644e-007,-8.781644e-007,,,,,,,,,,,,,,,,,,,,
1524676286.885,,0.000000e+000,5.499051e+001,5.499445e+001,1,0,3.870968e-001,0.000000e+000,4.896773e+000,4.896773e+000,1.127364e-002,-1.724243e-003,4.879561e+000,-5.938269e-003,-1.893616e-002,1.653360e-006,1.653360e-006,,,,,,,,,,,,,,,,,,,,
1524676299.475,,0.000000e+000,5.499839e+001,5.499577e+001,1,0,3.096774e+000,0.000000e+000,4.773938e+000,4.773938e+000,1.373459e-002,-9.972000e-002,4.810531e+000,5.032755e-002,-6.312704e-002,-1.258013e-007,-1.258013e-007,,,,,,,,,,,,,,,,,,,,
1524676324.905,,0.000000e+000,5.500103e+001,5.499839e+001,1,0,1.677419e+000,0.000000e+000,4.678416e+000,4.678416e+000,-8.339893e-002,-1.367860e-001,4.680285e+000,-8.153068e-002,-1.349177e-001,-1.313805e-006,-1.313805e-006,,,,,,,,,,,,,,,,,,,,
1524676375.385,,0.000000e+000,5.499577e+001,5.499577e+001,1,0,2.580645e-001,0.000000e+000,4.795910e+000,4.795910e+000,3.058251e-002,2.337837e-002,4.776466e+000,1.113804e-002,3.933907e-003,1.973342e-006,1.973342e-006,,,,,,,,,,,,,,,,,,,,
1524676413.245,,0.000000e+000,5.499708e+001,5.500497e+001,1,0,2.967742e+000,0.000000e+000,4.725872e+000,4.725872e+000,2.558303e-002,-6.413889e-002,4.751477e+000,5.118823e-002,-3.853369e-002,3.175519e-007,3.175519e-007,,,,,,,,,,,,,,,,,,,,
1524676437.915,,0.000000e+000,5.499971e+001,5.499971e+001,1,0,1.548387e+000,0.000000e+000,4.624399e+000,4.624399e+000,-1.201697e-001,-1.667938e-001,4.643032e+000,-1.015368e-001,-1.481609e-001,-2.073051e-006,-2.073051e-006,,,,,,,,,,,,,,,,,,,,
1524676463.085,,0.000000e+000,5.499314e+001,5.500103e+001,1,0,1.290323e-001,0.000000e+000,4.816510e+000,4.816510e+000,1.619112e-002,1.249504e-002,4.827470e+000,2.715074e-002,2.345467e-002,1.811248e-006,1.811248e-006,,,,,,,,,,,,,,,,,,,,
1524676475.575,,0.000000e+000,5.499708e+001,5.499971e+001,1,0,2.838710e+000,0.000000e+000,4.746014e+000,4.746014e+000,2.281546e-002,-5.678749e-002,4.769792e+000,4.659390e-002,-3.300905e-002,3.491878e-007,3.491878e-007,,,,,,,,,,,,,,,,,,,,
1524676500.625,,0.000000e+000,5.499577e+001,5.499182e+001,1,0,1.419355e+000,0.000000e+000,4.666056e+000,4.666056e+000,-1.035745e-001,-1.394582e-001,4.663062e+000,-1.065691e-001,-1.424527e-001,-1.678622e-006,-1.678622e-006,,,,,,,,,,,,,,,,,,,,
1524676525.755,,0.000000e+000,5.500235e+001,5.499839e+001,1,0,0.000000e+000,0.000000e+000,4.876478e+000,4.876478e+000,6.514549e-002,6.514549e-002,4.847473e+000,3.614044e-002,3.614044e-002,2.905625e-006,2.905625e-006,,,,,,,,,,,,,,,,,,,,
1524676538.235,,0.000000e+000,5.498788e+001,5.500761e+001,1,0,2.709677e+000,0.000000e+000,4.762646e+000,4.762646e+000,2.508256e-002,-5.550575e-002,4.782897e+000,4.533383e-002,-3.525448e-002,4.719186e-007,4.719186e-007,,,,,,,,,,,,,,,,,,,,
1524676564.125,,0.000000e+000,5.499051e+001,5.499314e+001,1,0,1.290323e+000,0.000000e+000,4.683146e+000,4.683146e+000,-1.048916e-001,-1.392908e-001,4.674787e+000,-1.132510e-001,-1.476502e-001,-1.600216e-006,-1.600216e-006,,,,,,,,,,,,,,,,,,,,
1524676576.995,,0.000000e+000,5.500629e+001,5.499051e+001,1,0,4.000000e+000,0.000000e+000,4.769665e+000,4.769665e+000,5.321985e-002,-5.308390e-002,4.730234e+000,1.378827e-002,-9.251547e-002,4.089961e-007,4.089961e-007,,,,,,,,,,,,,,,,,,,,
1524676602.425,,0.000000e+000,5.499445e+001,5.499577e+001,1,0,2.580645e+000,0.000000e+000,4.760509e+000,4.760509e+000,-6.367657e-004,-7.691669e-002,4.793985e+000,3.283864e-002,-4.344130e-002,-2.674642e-008,-2.674642e-008,,,,,,,,,,,,,,,,,,,,
1524676627.675,,0.000000e+000,5.499577e+001,5.499839e+001,1,0,1.161290e+000,0.000000e+000,4.696269e+000,4.696269e+000,-1.116074e-001,-1.468225e-001,4.690848e+000,-1.170281e-001,-1.522431e-001,-1.594759e-006,-1.594759e-006,,,,,,,,,,,,,,,,,,,,
1524676640.465,,0.000000e+000,5.499314e+001,5.499445e+001,1,0,3.870968e+000,0.000000e+000,4.776227e+000,4.776227e+000,4.844140e-002,-6.403494e-002,4.746226e+000,1.844071e-002,-9.403563e-002,3.114983e-007,3.114983e-007,,,,,,,,,,,,,,,,,,,,
1524676665.546,,0.000000e+000,5.499708e+001,5.499839e+001,1,0,2.451613e+000,0.000000e+000,4.762798e+000,4.762798e+000,-9.969421e-003,-8.074045e-002,4.786781e+000,1.401358e-002,-5.675745e-002,-1.441658e-007,-1.441658e-007,,,,,,,,,,,,,,,,,,,,
1524676690.976,,0.000000e+000,5.499708e+001,5.499971e+001,1,0,1.032258e+000,0.000000e+000,4.698100e+000,4.698100e+000,-1.129983e-001,-1.482263e-001,4.707829e+000,-1.032689e-001,-1.384969e-001,-1.489912e-006,-1.489912e-006,,,,,,,,,,,,,,,,,,,,
1524676703.306,,0.000000e+000,5.499577e+001,5.500103e+001,1,0,3.741935e+000,0.000000e+000,4.784009e+000,4.784009e+000,4.247485e-002,-4.574442e-002,4.760480e+000,1.894675e-002,-6.927252e-002,3.838941e-007,3.838941e-007,,,,,,,,,,,,,,,,,,,,
1524676729.056,,0.000000e+000,5.498919e+001,5.500103e+001,1,0,2.322581e+000,0.000000e+000,4.791790e+000,4.791790e+000,1.049204e-002,-5.568600e-002,4.785434e+000,4.135798e-003,-6.204224e-002,3.991445e-007,3.991445e-007,,,,,,,,,,,,,,,,,,,,
1524676754.526,,0.000000e+000,5.499839e+001,5.499577e+001,1,0,9.032258e-001,0.000000e+000,4.745556e+000,4.745556e+000,-9.357873e-002,-1.234674e-001,4.754972e+000,-8.416263e-002,-1.140513e-001,-9.977812e-007,-9.977812e-007,,,,,,,,,,,,,,,,,,,,
1524676766.956,,0.000000e+000,5.499577e+001,5.499708e+001,1,0,3.612903e+000,0.000000e+000,4.779889e+000,4.779889e+000,2.460387e-002,-7.335997e-002,4.780307e+000,2.502254e-002,-7.294130e-002,-3.074820e-008,-3.074820e-008,,,,,,,,,,,,,,,,,,,,
1524676792.096,,0.000000e+000,5.499971e+001,5.500367e+001,1,0,2.193548e+000,0.000000e+000,4.774243e+000,4.774243e+000,-2.255486e-002,-8.174419e-002,4.779537e+000,-1.726054e-002,-7.644987e-002,-2.731249e-007,-2.731249e-007,,,,,,,,,,,,,,,,,,,,
1524676817.766,,0.000000e+000,5.499708e+001,5.499708e+001,1,0,7.741935e-001,0.000000e+000,4.773022e+000,4.773022e+000,-6.207304e-002,-8.436680e-002,4.777832e+000,-5.726318e-002,-7.955694e-002,-3.240712e-007,-3.240712e-007,,,,,,,,,,,,,,,,,,,,
1524676830.346,,0.000000e+000,5.500103e+001,5.499577e+001,1,0,3.483871e+000,0.000000e+000,4.811933e+000,4.811933e+000,4.777138e-002,-5.595255e-002,4.795200e+000,3.103868e-002,-7.268524e-002,5.012553e-007,5.012553e-007,,,,,,,,,,,,,,,,,,,,
1524676855.696,,0.000000e+000,5.499839e+001,5.499971e+001,1,0,2.064516e+000,0.000000e+000,4.784924e+000,4.784924e+000,-2.709036e-002,-8.276892e-002,4.778610e+000,-3.340464e-002,-8.908319e-002,-2.921297e-007,-2.921297e-007,,,,,,,,,,,,,,,,,,,,
1524676881.166,,0.000000e+000,5.499314e+001,5.500497e+001,1,0,6.451613e-001,0.000000e+000,4.817731e+000,4.817731e+000,-4.070227e-002,-5.918503e-002,4.820362e+000,-3.807156e-002,-5.655432e-002,2.254819e-007,2.254819e-007,,,,,,,,,,,,,,,,,,,,
1524676893.556,,0.000000e+000,5.499445e+001,5.500497e+001,1,0,3.354839e+000,0.000000e+000,4.810102e+000,4.810102e+000,3.410185e-002,-6.338310e-002,4.814955e+000,3.895557e-002,-5.852938e-002,2.953020e-007,2.953020e-007,,,,,,,,,,,,,,,,,,,,
1524676918.396,,0.000000e+000,5.499182e+001,5.499839e+001,1,0,1.935484e+000,0.000000e+000,4.787518e+000,4.787518e+000,-4.233468e-002,-1.011829e-001,4.780140e+000,-4.971231e-002,-1.085606e-001,-5.463080e-007,-5.463080e-007,,,,,,,,,,,,,,,,,,,,
1524676943.516,,0.000000e+000,5.499971e+001,5.499182e+001,1,0,5.161290e-001,0.000000e+000,4.850690e+000,4.850690e+000,-2.193667e-002,-3.730536e-002,4.843712e+000,-2.891470e-002,-4.428339e-002,8.250936e-007,8.250936e-007,,,,,,,,,,,,,,,,,,,,
1524676955.986,,0.000000e+000,5.499182e+001,5.499708e+001,1,0,3.225806e+000,0.000000e+000,4.833448e+000,4.833448e+000,3.995930e-002,-5.971336e-002,4.840083e+000,4.659402e-002,-5.307865e-002,4.742178e-007,4.742178e-007,,,,,,,,,,,,,,,,,,,,
1524676981.436,,0.000000e+000,5.500103e+001,5.499314e+001,1,0,1.806452e+000,0.000000e+000,4.728313e+000,4.728313e+000,-9.463879e-002,-1.477818e-001,4.741659e+000,-8.129260e-002,-1.344357e-001,-1.642708e-006,-1.642708e-006,,,,,,,,,,,,,,,,,,,,
1524677006.486,,0.000000e+000,5.499182e+001,5.499445e+001,1,0,3.870968e-001,0.000000e+000,4.889753e+000,4.889753e+000,3.038967e-003,-9.910107e-003,4.878976e+000,-7.738506e-003,-2.068758e-002,1.553664e-006,1.553664e-006,,,,,,,,,,,,,,,,,,,,
1524677019.076,,0.000000e+000,5.500892e+001,5.499839e+001,1,0,3.096774e+000,0.000000e+000,4.813001e+000,4.813001e+000,7.673474e-003,-7.809496e-002,4.855239e+000,4.991171e-002,-3.585672e-002,-1.177395e-007,-1.177395e-007,,,,,,,,,,,,,,,,,,,,
1524677044.206,,0.000000e+000,5.499839e+001,5.499314e+001,1,0,1.677419e+000,0.000000e+000,4.765087e+000,4.765087e+000,-8.876281e-002,-1.348414e-001,4.765762e+000,-8.808809e-002,-1.341667e-001,-1.456865e-006,-1.456865e-006,,,,,,,,,,,,,,,,,,,,
1524677068.846,,0.000000e+000,5.499839e+001,5.500103e+001,1,0,2.580645e-001,0.000000e+000,4.917525e+000,4.917525e+000,2.889384e-002,2.255583e-002,4.903616e+000,1.498497e-002,8.646965e-003,1.904860e-006,1.904860e-006,,,,,,,,,,,,,,,,,,,,
1524677081.486,,0.000000e+000,5.499839e+001,5.500367e+001,1,0,2.967742e+000,0.000000e+000,4.851148e+000,4.851148e+000,2.874243e-002,-6.099081e-002,4.873452e+000,5.104648e-002,-3.868675e-002,3.895984e-007,3.895984e-007,,,,,,,,,,,,,,,,,,,,
1524677106.196,,0.000000e+000,5.498656e+001,5.500103e+001,1,0,1.548387e+000,0.000000e+000,4.731365e+000,4.731365e+000,-1.271057e-001,-1.742439e-001,4.752828e+000,-1.056423e-001,-1.527805e-001,-2.231405e-006,-2.231405e-006,,,,,,,,,,,,,,,,,,,,
1524677131.596,,0.000000e+000,5.499839e+001,5.500367e+001,1,0,1.290323e-001,0.000000e+000,4.945754e+000,4.945754e+000,3.275171e-002,2.863789e-002,4.941605e+000,2.860275e-002,2.448893e-002,2.313391e-006,2.313391e-006,,,,,,,,,,,,,,,,,,,,
1524677144.236,,0.000000e+000,5.500367e+001,5.499182e+001,1,0,2.838710e+000,0.000000e+000,4.845350e+000,4.845350e+000,1.582674e-002,-6.296253e-002,4.876599e+000,4.707579e-002,-3.171349e-002,2.027373e-007,2.027373e-007,,,,,,,,,,,,,,,,,,,,
1524677168.966,,0.000000e+000,5.500103e+001,5.499445e+001,1,0,1.419355e+000,0.000000e+000,4.764935e+000,4.764935e+000,-1.054677e-001,-1.435733e-001,4.765752e+000,-1.046500e-001,-1.427555e-001,-1.726861e-006,-1.726861e-006,,,,,,,,,,,,,,,,,,,,
1524677193.416,,0.000000e+000,5.499708e+001,5.499577e+001,1,0,0.000000e+000,0.000000e+000,4.966812e+000,4.966812e+000,6.770039e-002,6.770039e-002,4.936332e+000,3.722048e-002,3.722048e-002,2.885237e-006,2.885237e-006,,,,,,,,,,,,,,,,,,,,
1524677206.706,,0.000000e+000,5.499839e+001,5.499314e+001,1,0,2.709677e+000,0.000000e+000,4.851606e+000,4.851606e+000,1.975209e-002,-6.126547e-002,4.873313e+000,4.145915e-002,-3.955841e-002,3.427704e-007,3.427704e-007,,,,,,,,,,,,,,,,,,,,
1524677231.656,,0.000000e+000,5.499971e+001,5.499708e+001,1,0,1.290323e+000,0.000000e+000,4.764172e+000,4.764172e+000,-1.147456e-001,-1.551399e-001,4.760061e+000,-1.188564e-001,-1.592507e-001,-1.754524e-006,-1.754524e-006,,,,,,,,,,,,,,,,,,,,
1524677244.586,,0.000000e+000,5.499708e+001,5.499971e+001,1,0,4.000000e+000,0.000000e+000,4.854658e+000,4.854658e+000,5.205213e-002,-6.270695e-002,4.817427e+000,1.482116e-002,-9.993792e-002,3.270252e-007,3.270252e-007,,,,,,,,,,,,,,,,,,,,
1524677269.816,,0.000000e+000,5.500103e+001,5.499708e+001,1,0,2.580645e+000,0.000000e+000,4.863203e+000,4.863203e+000,1.257100e-002,-6.130075e-002,4.879285e+000,2.865329e-002,-4.521847e-002,2.792949e-007,2.792949e-007,,,,,,,,,,,,,,,,,,,,
1524677295.136,,0.000000e+000,5.499314e+001,5.500235e+001,1,0,1.161290e+000,0.000000e+000,4.781262e+000,4.781262e+000,-1.105694e-001,-1.461658e-001,4.782573e+000,-1.092586e-001,-1.448550e-001,-1.605236e-006,-1.605236e-006,,,,,,,,,,,,,,,,,,,,
1524677307.956,,0.000000e+000,5.499051e+001,5.499839e+001,1,0,3.870968e+000,0.000000e+000,4.858015e+000,4.858015e+000,5.081262e-002,-7.286215e-002,4.824159e+000,1.695719e-002,-1.067176e-001,2.775487e-007,2.775487e-007,,,,,,,,,,,,,,,,,,,,
1524677332.696,,0.000000e+000,5.499708e+001,5.499708e+001,1,0,2.451613e+000,0.000000e+000,4.848096e+000,4.848096e+000,-1.484431e-003,-6.853819e-002,4.863360e+000,1.377960e-002,-5.327415e-002,3.284367e-008,3.284367e-008,,,,,,,,,,,,,,,,,,,,
1524677357.846,,0.000000e+000,5.499577e+001,5.500103e+001,1,0,1.032258e+000,0.000000e+000,4.797132e+000,4.797132e+000,-9.490446e-002,-1.240268e-001,4.802144e+000,-8.989242e-002,-1.190147e-001,-1.235036e-006,-1.235036e-006,,,,,,,,,,,,,,,,,,,,
1524677370.796,,0.000000e+000,5.500103e+001,5.499708e+001,1,0,3.741935e+000,0.000000e+000,4.863966e+000,4.863966e+000,4.636530e-002,-7.004118e-002,4.838386e+000,2.078537e-002,-9.562111e-002,2.780725e-007,2.780725e-007,,,,,,,,,,,,,,,,,,,,
1524677395.507,,0.000000e+000,5.499971e+001,5.499182e+001,1,0,2.322581e+000,0.000000e+000,4.864882e+000,4.864882e+000,4.007669e-003,-6.921625e-002,4.864410e+000,3.536554e-003,-6.968737e-002,2.379529e-007,2.379529e-007,,,,,,,,,,,,,,,,,,,,
1524677421.367,,0.000000e+000,5.500235e+001,5.499971e+001,1,0,9.032258e-001,0.000000e+000,4.837720e+000,4.837720e+000,-7.211356e-002,-9.841728e-002,4.843499e+000,-6.633477e-002,-9.263849e-002,-6.728224e-007,-6.728224e-007,,,,,,,,,,,,,,,,,,,,
1524677433.937,,0.000000e+000,5.499971e+001,5.499314e+001,1,0,3.612903e+000,0.000000e+000,4.857557e+000,4.857557e+000,3.878517e-002,-8.654547e-002,4.846083e+000,2.731151e-002,-9.801912e-002,1.100416e-007,1.100416e-007,,,,,,,,,,,,,,,,,,,,
1524677459.377,,0.000000e+000,5.499182e+001,5.499708e+001,1,0,2.193548e+000,0.000000e+000,4.704814e+000,4.704814e+000,-1.533329e-002,-9.439898e-002,4.704505e+000,-1.564228e-002,-9.470797e-002,-1.361041e-007,-1.361041e-007,,,,,,,,,,,,,,,,,,,,
1524677484.707,,0.000000e+000,5.499182e+001,5.499971e+001,1,0,7.741935e-001,0.000000e+000,4.893721e+000,4.893721e+000,-8.780963e-002,-1.265316e-001,4.916698e+000,-6.483323e-002,-1.035552e-001,-4.998583e-007,-4.998583e-007,,,,,,,,,,,,,,,,,,,,
1524677497.237,,0.000000e+000,5.499971e+001,5.500103e+001,1,0,3.483871e+000,0.000000e+000,4.609446e+000,4.609446e+000,4.372906e-002,-7.038260e-002,4.599838e+000,3.412175e-002,-7.998991e-002,3.557943e-007,3.557943e-007,,,,,,,,,,,,,,,,,,,,
1524677522.577,,0.000000e+000,5.500103e+001,5.500235e+001,1,0,2.064516e+000,0.000000e+000,4.485847e+000,4.485847e+000,-2.733023e-002,-9.682846e-002,4.476357e+000,-3.682120e-002,-1.063194e-001,-2.900633e-007,-2.900633e-007,,,,,,,,,,,,,,,,,,,,
1524677547.787,,0.000000e+000,5.500235e+001,5.500235e+001,1,0,6.451613e-001,0.000000e+000,4.559396e+000,4.559396e+000,-4.443899e-002,-6.091928e-002,4.560910e+000,-4.292455e-002,-5.940485e-002,1.176813e-007,1.176813e-007,,,,,,,,,,,,,,,,,,,,
1524677559.927,,0.000000e+000,5.499708e+001,5.499839e+001,1,0,3.354839e+000,0.000000e+000,4.579385e+000,4.579385e+000,1.290288e-002,-6.518030e-002,4.603516e+000,3.703370e-002,-4.104948e-002,-6.803020e-008,-6.803020e-008,,,,,,,,,,,,,,,,,,,,
1524677610.307,,0.000000e+000,5.500235e+001,5.498919e+001,1,0,1.935484e+000,0.000000e+000,4.635386e+000,4.635386e+000,-4.607492e-002,-9.250116e-002,4.628166e+000,-5.329471e-002,-9.972095e-002,-6.797200e-007,-6.797200e-007,,,,,,,,,,,,,,,,,,,,
1524677635.747,,0.000000e+000,5.499445e+001,5.500367e+001,1,0,5.161290e-001,0.000000e+000,4.712596e+000,4.712596e+000,-3.676787e-002,-5.081129e-002,4.735075e+000,-1.428976e-002,-2.833319e-002,3.362948e-007,3.362948e-007,,,,,,,,,,,,,,,,,,,,
1524677648.477,,0.000000e+000,5.500367e+001,5.499971e+001,1,0,3.225806e+000,0.000000e+000,4.706035e+000,4.706035e+000,3.231120e-002,-6.727934e-002,4.717606e+000,4.388165e-002,-5.570889e-002,2.959569e-007,2.959569e-007,,,,,,,,,,,,,,,,,,,,
1524677673.737,,0.000000e+000,5.499708e+001,5.499577e+001,1,0,1.806452e+000,0.000000e+000,4.681926e+000,4.681926e+000,-6.721412e-002,-1.188107e-001,4.679183e+000,-6.995641e-002,-1.215529e-001,-1.050008e-006,-1.050008e-006,,,,,,,,,,,,,,,,,,,,
1524677698.487,,0.000000e+000,5.500103e+001,5.499839e+001,1,0,3.870968e-001,0.000000e+000,4.803693e+000,4.803693e+000,-6.509251e-003,-1.761770e-002,4.806146e+000,-4.056401e-003,-1.516485e-002,1.121109e-006,1.121109e-006,,,,,,,,,,,,,,,,,,,,
1524677710.927,,0.000000e+000,5.499839e+001,5.499051e+001,1,0,3.096774e+000,0.000000e+000,4.773785e+000,4.773785e+000,3.322334e-002,-7.008791e-002,4.792249e+000,5.168743e-002,-5.162382e-002,3.666646e-007,3.666646e-007,,,,,,,,,,,,,,,,,,,,
1524677735.847,,0.000000e+000,5.498919e+001,5.499839e+001,1,0,1.677419e+000,0.000000e+000,4.708171e+000,4.708171e+000,-9.840665e-002,-1.497550e-001,4.713014e+000,-9.356389e-002,-1.449122e-001,-1.628709e-006,-1.628709e-006,,,,,,,,,,,,,,,,,,,,
1524677761.227,,0.000000e+000,5.499708e+001,5.499577e+001,1,0,2.580645e-001,0.000000e+000,4.892195e+000,4.892195e+000,2.680332e-002,1.807213e-002,4.876109e+000,1.071722e-002,1.986027e-003,2.156710e-006,2.156710e-006,,,,,,,,,,,,,,,,,,,,
1524677774.357,,0.000000e+000,5.499577e+001,5.499839e+001,1,0,2.967742e+000,0.000000e+000,4.817883e+000,4.817883e+000,2.363021e-002,-6.331968e-002,4.847892e+000,5.363900e-002,-3.331089e-002,2.994348e-007,2.994348e-007,,,,,,,,,,,,,,,,,,,,
1524677799.567,,0.000000e+000,5.499839e+001,5.499708e+001,1,0,1.548387e+000,0.000000e+000,4.729228e+000,4.729228e+000,-1.211841e-001,-1.656375e-001,4.739070e+000,-1.113427e-001,-1.557961e-001,-2.079512e-006,-2.079512e-006,,,,,,,,,,,,,,,,,,,,
1524677824.757,,0.000000e+000,5.499051e+001,5.499839e+001,1,0,1.290323e-001,0.000000e+000,4.948653e+000,4.948653e+000,3.583604e-002,3.180313e-002,4.942532e+000,2.971488e-002,2.568197e-002,2.342815e-006,2.342815e-006,,,,,,,,,,,,,,,,,,,,
1524677837.297,,0.000000e+000,5.499839e+001,5.500103e+001,1,0,2.838710e+000,0.000000e+000,4.844892e+000,4.844892e+000,7.216027e-003,-7.665110e-002,4.886396e+000,4.872041e-002,-3.514671e-002,-5.486072e-009,-5.486072e-009,,,,,,,,,,,,,,,,,,,,
1524677862.497,,0.000000e+000,5.500235e+001,5.500629e+001,1,0,1.419355e+000,0.000000e+000,4.775158e+000,4.775158e+000,-1.179341e-001,-1.592960e-001,4.779201e+000,-1.138915e-001,-1.552534e-001,-1.945053e-006,-1.945053e-006,,,,,,,,,,,,,,,,,,,,
1524677887.687,,0.000000e+000,5.499708e+001,5.499445e+001,1,0,0.000000e+000,0.000000e+000,5.012283e+000,5.012283e+000,7.274008e-002,7.274008e-002,4.980090e+000,4.054642e-002,4.054642e-002,3.140100e-006,3.140100e-006,,,,,,,,,,,,,,,,,,,,
1524677900.369,,0.000000e+000,5.499445e+001,5.499971e+001,1,0,2.709677e+000,0.000000e+000,4.888533e+000,4.888533e+000,1.100158e-002,-6.603861e-002,4.918252e+000,4.072093e-002,-3.631926e-002,1.691806e-007,1.691806e-007,,,,,,,,,,,,,,,,,,,,
1524677925.571,,0.000000e+000,5.499708e+001,5.499708e+001,1,0,1.290323e+000,0.000000e+000,4.817578e+000,4.817578e+000,-1.077791e-001,-1.443701e-001,4.813046e+000,-1.123120e-001,-1.489029e-001,-1.669352e-006,-1.669352e-006,,,,,,,,,,,,,,,,,,,,
1524677938.131,,0.000000e+000,5.499708e+001,5.500103e+001,1,0,4.000000e+000,0.000000e+000,4.910506e+000,4.910506e+000,5.457761e-002,-5.335379e-002,4.869671e+000,1.374271e-002,-9.418869e-002,4.264875e-007,4.264875e-007,,,,,,,,,,,,,,,,,,,,
1524677963.321,,0.000000e+000,5.500103e+001,5.499314e+001,1,0,2.580645e+000,0.000000e+000,4.917677e+000,4.917677e+000,1.400759e-002,-5.872393e-002,4.935114e+000,3.144458e-002,-4.128695e-002,3.075402e-007,3.075402e-007,,,,,,,,,,,,,,,,,,,,
1524677988.501,,0.000000e+000,5.499839e+001,5.499445e+001,1,0,1.161290e+000,0.000000e+000,4.849164e+000,4.849164e+000,-1.064836e-001,-1.389112e-001,4.848708e+000,-1.069400e-001,-1.393676e-001,-1.558976e-006,-1.558976e-006,,,,,,,,,,,,,,,,,,,,
1524678001.181,,0.000000e+000,5.499445e+001,5.499971e+001,1,0,3.870968e+000,0.000000e+000,4.912947e+000,4.912947e+000,2.556199e-002,-8.787489e-002,4.903011e+000,1.562566e-002,-9.781122e-002,-2.267479e-007,-2.267479e-007,,,,,,,,,,,,,,,,,,,,
1524678026.381,,0.000000e+000,5.499445e+001,5.499708e+001,1,0,2.451613e+000,0.000000e+000,4.947890e+000,4.947890e+000,1.354416e-002,-5.566645e-002,4.947504e+000,1.315744e-002,-5.605316e-002,3.722380e-007,3.722380e-007,,,,,,,,,,,,,,,,,,,,
1524678051.571,,0.000000e+000,5.499708e+001,5.499577e+001,1,0,1.032258e+000,0.000000e+000,4.873121e+000,4.873121e+000,-9.710792e-002,-1.233678e-001,4.881834e+000,-8.839516e-002,-1.146550e-001,-1.325650e-006,-1.325650e-006,,,,,,,,,,,,,,,,,,,,
1524678064.111,,0.000000e+000,5.500235e+001,5.500235e+001,1,0,3.741935e+000,0.000000e+000,4.952315e+000,4.952315e+000,4.890505e-002,-4.956007e-002,4.923939e+000,2.052895e-002,-7.793617e-002,4.607427e-007,4.607427e-007,,,,,,,,,,,,,,,,,,,,
1524678089.002,,0.000000e+000,5.499839e+001,5.498788e+001,1,0,2.322581e+000,0.000000e+000,4.887465e+000,4.887465e+000,4.708327e-003,-7.788420e-002,4.886378e+000,3.622092e-003,-7.897043e-002,2.272427e-007,2.272427e-007,,,,,,,,,,,,,,,,,,,,
1524678113.862,,0.000000e+000,5.500629e+001,5.499445e+001,1,0,9.032258e-001,0.000000e+000,4.827954e+000,4.827954e+000,-8.519232e-002,-1.151137e-001,4.833842e+000,-7.930434e-002,-1.092257e-001,-8.334318e-007,-8.334318e-007,,,,,,,,,,,,,,,,,,,,
1524678126.962,,0.000000e+000,5.499445e+001,5.499839e+001,1,0,3.612903e+000,0.000000e+000,4.877699e+000,4.877699e+000,4.172160e-002,-6.405926e-002,4.862120e+000,2.614238e-002,-7.963848e-002,3.042951e-007,3.042951e-007,,,,,,,,,,,,,,,,,,,,
1524678152.162,,0.000000e+000,5.499445e+001,5.499708e+001,1,0,2.193548e+000,0.000000e+000,4.879225e+000,4.879225e+000,-9.063219e-003,-7.185078e-002,4.870895e+000,-1.739261e-002,-8.018017e-002,2.146407e-008,2.146407e-008,,,,,,,,,,,,,,,,,,,,
1524678176.882,,0.000000e+000,5.500367e+001,5.499971e+001,1,0,7.741935e-001,0.000000e+000,4.860151e+000,4.860151e+000,-7.775576e-002,-1.004653e-001,4.888911e+000,-4.899627e-002,-7.170582e-002,-7.023482e-007,-7.023482e-007,,,,,,,,,,,,,,,,,,,,
1524678176.882,,0.000000e+000,5.500367e+001,5.499971e+001,1,0,4.000000e+000,0.000000e+000,4.895400e+000,4.895400e+000,5.211563e-002,-6.521702e-002,4.857889e+000,1.460523e-002,-1.027274e-001,3.160385e-007,3.160385e-007,,,,,,,,,,,,,,,,,,,,