File: Experimental Raw Data/TC04-12-01K TRMac VRMde/Raw/TC04-12-01K_TRMac_57K_0.06Kmin_VRMde_55K.dc.raw
[Header]
TITLE,MPMS DC Measurement
BYAPP,MPMS Measurement,2.1,Raw with ABS
FILEOPENTIME, 1524687525.955000 4/25/2018, 2:18:45 PM

INFO, APPNAME, MPMS MultiVu Application, Revision 1.61,  Build 082

INFO, NAME, TC04-12-01K
INFO, WEIGHT, 1.000
INFO, AREA, 1.000
INFO, LENGTH, 1.000
INFO, SHAPE, 0
INFO, COMMENT,
INFO, SEQUENCE FILE: TRMac_57K_0.06Kmin_VRMde_55K.seq


INFO, BACKGROUND DATA FILE:, None


STARTUPAXIS,X,8,LINEAR,AUTO,0.000000,0.000000
STARTUPAXIS,Y1,10,LINEAR,AUTO,0.000000,0.000000


STARTUPGROUP,Longitudinal
FIELDGROUP,Longitudinal,1,3,4,5,6,8,9,10,11,12,13,14,15,16,17,18,19,20,21,22,23
FIELDGROUP,Transverse,1,3,4,5,6,8,9,24,25,26,27,28,29,30,31,32,33,34,35,36,37

PLOT_APPEARANCE,ALL,HORZ_GRID_ON,VERT_GRID_ON,MARKERS_ONLY

[Data]
Time,Comment,Field (Oe),Start Temperature (K),End Temperature (K),Scan,Rejected,Position (cm),Rot Position (deg),Long Voltage,Long Average Voltage,Long Detrended Voltage,Long Demeaned Voltage,Long Regression Fit,Long Detrended Fit,Long Demeaned Fit,Long Scaled Response,Long Avg. Scaled Response,Long Background Response,Long Response [w/ABS],Long Detrended Resp. [w/ABS],Long Fit [w/ABS],Long Detrended Fit [w/ABS],Trans Voltage,Trans Average Voltage,Trans Detrended Voltage,Trans Demeaned Voltage,Trans Regression Fit,Trans Detrended Fit,Trans Demeaned Fit,Trans Scaled Response,Trans Avg Scaled Response,Trans Background Response,Trans Response [w/ABS],Trans Detrended Resp. [w/ABS],Trans Fit [w/ABS],Trans Detrended Fit [w/ABS],
1524687525.945,,0.000000e+000,5.498788e+001,5.499051e+001,1,0,0.000000e+000,0.000000e+000,4.174716e+000,4.174716e+000,1.932335e-002,1.932335e-002,3.957378e+000,-1.980145e-001,-1.980145e-001,-9.180716e-006,-9.180716e-006,,,,,,,,,,,,,,,,,,,,
1524687538.685,,0.000000e+000,5.499577e+001,5.499051e+001,1,0,3.096774e+000,0.000000e+000,4.960708e+000,4.960708e+000,2.436429e-003,7.578521e-001,4.925768e+000,-3.250334e-002,7.229123e-001,2.716391e-006,2.716391e-006,,,,,,,,,,,,,,,,,,,,
1524687563.925,,0.000000e+000,5.499577e+001,5.499839e+001,1,0,2.064516e+000,0.000000e+000,5.192035e+000,5.192035e+000,4.600617e-001,9.067502e-001,5.204961e+000,4.729878e-001,9.196763e-001,9.432988e-006,9.432988e-006,,,,,,,,,,,,,,,,,,,,
1524687589.875,,0.000000e+000,5.498919e+001,5.499445e+001,1,0,1.032258e+000,0.000000e+000,4.502174e+000,4.502174e+000,-6.196736e-002,1.363339e-001,4.521413e+000,-4.272889e-002,1.555724e-001,-4.997011e-006,-4.997011e-006,,,,,,,,,,,,,,,,,,,,
1524687615.045,,0.000000e+000,5.499971e+001,5.499708e+001,1,0,0.000000e+000,0.000000e+000,4.492256e+000,4.492256e+000,6.539917e-002,6.539917e-002,4.315764e+000,-1.110930e-001,-1.110930e-001,-4.311980e-006,-4.311980e-006,,,,,,,,,,,,,,,,,,,,
1524687628.025,,0.000000e+000,5.498788e+001,5.500497e+001,1,0,3.096774e+000,0.000000e+000,4.972763e+000,4.972763e+000,2.289122e-002,5.251923e-001,4.942964e+000,-6.907284e-003,4.953938e-001,2.276909e-006,2.276909e-006,,,,,,,,,,,,,,,,,,,,
1524687653.375,,0.000000e+000,5.500103e+001,5.499445e+001,1,0,2.064516e+000,0.000000e+000,5.092852e+000,5.092852e+000,3.075312e-001,6.140175e-001,5.109134e+000,3.238137e-001,6.303000e-001,6.278919e-006,6.278919e-006,,,,,,,,,,,,,,,,,,,,
1524687678.595,,0.000000e+000,5.499839e+001,5.499708e+001,1,0,1.032258e+000,0.000000e+000,4.542763e+000,4.542763e+000,-7.079093e-002,7.247925e-002,4.570134e+000,-4.342048e-002,9.984970e-002,-4.179688e-006,-4.179688e-006,,,,,,,,,,,,,,,,,,,,
1524687703.825,,0.000000e+000,5.500629e+001,5.499577e+001,1,0,0.000000e+000,0.000000e+000,4.568704e+000,4.568704e+000,7.452726e-002,7.452726e-002,4.413576e+000,-8.060026e-002,-8.060026e-002,-2.587243e-006,-2.587243e-006,,,,,,,,,,,,,,,,,,,,
1524687716.445,,0.000000e+000,5.499839e+001,5.499577e+001,1,0,3.096774e+000,0.000000e+000,4.902724e+000,4.902724e+000,2.276783e-002,4.080267e-001,4.892121e+000,1.216488e-002,3.974237e-001,1.804859e-006,1.804859e-006,,,,,,,,,,,,,,,,,,,,
1524687741.665,,0.000000e+000,5.499577e+001,5.500892e+001,1,0,2.064516e+000,0.000000e+000,5.004654e+000,5.004654e+000,2.414324e-001,4.834065e-001,5.021185e+000,2.579634e-001,4.999375e-001,4.904810e-006,4.904810e-006,,,,,,,,,,,,,,,,,,,,
1524687766.835,,0.000000e+000,5.499708e+001,5.500103e+001,1,0,1.032258e+000,0.000000e+000,4.571908e+000,4.571908e+000,-6.912302e-002,4.683876e-002,4.595839e+000,-4.519200e-002,7.076979e-002,-3.649533e-006,-3.649533e-006,,,,,,,,,,,,,,,,,,,,
1524687792.345,,0.000000e+000,5.500103e+001,5.500103e+001,1,0,0.000000e+000,0.000000e+000,4.616922e+000,4.616922e+000,7.858706e-002,7.858706e-002,4.474910e+000,-6.342554e-002,-6.342554e-002,-1.686654e-006,-1.686654e-006,,,,,,,,,,,,,,,,,,,,
1524687804.675,,0.000000e+000,5.499839e+001,5.499971e+001,1,0,3.096774e+000,0.000000e+000,4.855726e+000,4.855726e+000,3.799781e-003,3.170304e-001,4.871929e+000,2.000318e-002,3.332338e-001,1.070875e-006,1.070875e-006,,,,,,,,,,,,,,,,,,,,
1524687829.915,,0.000000e+000,5.499577e+001,5.499839e+001,1,0,2.064516e+000,0.000000e+000,4.968490e+000,4.968490e+000,2.214072e-001,4.167113e-001,4.965901e+000,2.188180e-001,4.141221e-001,4.502799e-006,4.502799e-006,,,,,,,,,,,,,,,,,,,,
1524687855.375,,0.000000e+000,5.499971e+001,5.500629e+001,1,0,1.032258e+000,0.000000e+000,4.573586e+000,4.573586e+000,-7.855371e-002,1.433516e-002,4.604386e+000,-4.775385e-002,4.513502e-002,-3.459005e-006,-3.459005e-006,,,,,,,,,,,,,,,,,,,,
1524687880.665,,0.000000e+000,5.499971e+001,5.499445e+001,1,0,0.000000e+000,0.000000e+000,4.646830e+000,4.646830e+000,8.887482e-002,8.887482e-002,4.504252e+000,-5.370283e-002,-5.370283e-002,-1.020802e-006,-1.020802e-006,,,,,,,,,,,,,,,,,,,,
1524687893.455,,0.000000e+000,5.498919e+001,5.499314e+001,1,0,3.096774e+000,0.000000e+000,4.859083e+000,4.859083e+000,2.392931e-002,2.905431e-001,4.859901e+000,2.474804e-002,2.913618e-001,1.349690e-006,1.349690e-006,,,,,,,,,,,,,,,,,,,,
1524687944.805,,0.000000e+000,5.499971e+001,5.499577e+001,1,0,2.064516e+000,0.000000e+000,4.927749e+000,4.927749e+000,1.932274e-001,3.582497e-001,4.911425e+000,1.769038e-001,3.419261e-001,3.953508e-006,3.953508e-006,,,,,,,,,,,,,,,,,,,,
1524687970.165,,0.000000e+000,5.499051e+001,5.499577e+001,1,0,1.032258e+000,0.000000e+000,4.571145e+000,4.571145e+000,-7.664543e-002,1.959801e-003,4.605319e+000,-4.247098e-002,3.613424e-002,-3.151697e-006,-3.151697e-006,,,,,,,,,,,,,,,,,,,,
1524687994.995,,0.000000e+000,5.500103e+001,5.499445e+001,1,0,0.000000e+000,0.000000e+000,4.670481e+000,4.670481e+000,1.017213e-001,1.017213e-001,4.525554e+000,-4.320574e-002,-4.320574e-002,-1.796288e-007,-1.796288e-007,,,,,,,,,,,,,,,,,,,,
1524688007.735,,0.000000e+000,5.499839e+001,5.499971e+001,1,0,3.096774e+000,0.000000e+000,4.808881e+000,4.808881e+000,2.529498e-002,2.342024e-001,4.814583e+000,3.099700e-002,2.399044e-001,1.136403e-006,1.136403e-006,,,,,,,,,,,,,,,,,,,,
1524688032.915,,0.000000e+000,5.499708e+001,5.499577e+001,1,0,2.064516e+000,0.000000e+000,4.872663e+000,4.872663e+000,1.684336e-001,3.065248e-001,4.857228e+000,1.529984e-001,2.910895e-001,3.426234e-006,3.426234e-006,,,,,,,,,,,,,,,,,,,,
1524688057.785,,0.000000e+000,5.500103e+001,5.499708e+001,1,0,1.032258e+000,0.000000e+000,4.549935e+000,4.549935e+000,-7.797523e-002,-1.266956e-002,4.580578e+000,-4.733224e-002,1.797342e-002,-2.949964e-006,-2.949964e-006,,,,,,,,,,,,,,,,,,,,
1524688083.395,,0.000000e+000,5.499708e+001,5.499445e+001,1,0,0.000000e+000,0.000000e+000,4.660410e+000,4.660410e+000,1.004004e-001,1.004004e-001,4.525044e+000,-3.496552e-002,-3.496552e-002,2.004526e-007,2.004526e-007,,,,,,,,,,,,,,,,,,,,
1524688095.676,,0.000000e+000,5.499971e+001,5.499314e+001,1,0,3.096774e+000,0.000000e+000,4.778363e+000,4.778363e+000,2.892792e-002,2.216396e-001,4.780047e+000,3.061211e-002,2.233238e-001,1.181645e-006,1.181645e-006,,,,,,,,,,,,,,,,,,,,
1524688120.486,,0.000000e+000,5.500103e+001,5.499839e+001,1,0,2.064516e+000,0.000000e+000,4.821088e+000,4.821088e+000,1.550325e-001,2.772145e-001,4.800537e+000,1.344813e-001,2.566633e-001,3.166584e-006,3.166584e-006,,,,,,,,,,,,,,,,,,,,
1524688146.196,,0.000000e+000,5.500103e+001,5.499839e+001,1,0,1.032258e+000,0.000000e+000,4.533150e+000,4.533150e+000,-6.912361e-002,-1.156092e-002,4.557809e+000,-4.446446e-002,1.309824e-002,-2.594999e-006,-2.594999e-006,,,,,,,,,,,,,,,,,,,,
1524688171.336,,0.000000e+000,5.499971e+001,5.499708e+001,1,0,0.000000e+000,0.000000e+000,4.636606e+000,4.636606e+000,9.618139e-002,9.618139e-002,4.510454e+000,-2.997112e-002,-2.997112e-002,4.232134e-007,4.232134e-007,,,,,,,,,,,,,,,,,,,,
1524688183.766,,0.000000e+000,5.499708e+001,5.499314e+001,1,0,3.096774e+000,0.000000e+000,4.735027e+000,4.735027e+000,3.334107e-002,2.042470e-001,4.734705e+000,3.301872e-002,2.039247e-001,1.186403e-006,1.186403e-006,,,,,,,,,,,,,,,,,,,,
1524688209.836,,0.000000e+000,5.499577e+001,5.500103e+001,1,0,2.064516e+000,0.000000e+000,4.753643e+000,4.753643e+000,1.164112e-001,2.219334e-001,4.746567e+000,1.093354e-001,2.148576e-001,2.312619e-006,2.312619e-006,,,,,,,,,,,,,,,,,,,,
1524688235.346,,0.000000e+000,5.500235e+001,5.500235e+001,1,0,1.032258e+000,0.000000e+000,4.502632e+000,4.502632e+000,-7.673541e-002,-2.685308e-002,4.533748e+000,-4.561940e-002,4.262924e-003,-2.639121e-006,-2.639121e-006,,,,,,,,,,,,,,,,,,,,
1524688260.606,,0.000000e+000,5.499708e+001,5.499708e+001,1,0,0.000000e+000,0.000000e+000,4.616312e+000,4.616312e+000,9.613895e-002,9.613895e-002,4.493850e+000,-2.632332e-002,-2.632332e-002,6.394694e-007,6.394694e-007,,,,,,,,,,,,,,,,,,,,
1524688273.016,,0.000000e+000,5.498656e+001,5.500235e+001,1,0,3.096774e+000,0.000000e+000,4.692454e+000,4.692454e+000,2.472178e-002,1.823792e-001,4.701331e+000,3.359858e-002,1.912560e-001,9.624928e-007,9.624928e-007,,,,,,,,,,,,,,,,,,,,
1524688298.286,,0.000000e+000,5.499839e+001,5.499839e+001,1,0,2.064516e+000,0.000000e+000,4.733959e+000,4.733959e+000,1.303079e-001,2.319202e-001,4.707216e+000,1.035650e-001,2.051773e-001,2.637666e-006,2.637666e-006,,,,,,,,,,,,,,,,,,,,
1524688323.516,,0.000000e+000,5.499971e+001,5.499839e+001,1,0,1.032258e+000,0.000000e+000,4.470130e+000,4.470130e+000,-7.848783e-002,-3.029442e-002,4.504588e+000,-4.403014e-002,4.163265e-003,-2.636036e-006,-2.636036e-006,,,,,,,,,,,,,,,,,,,,
1524688348.726,,0.000000e+000,5.499577e+001,5.500235e+001,1,0,0.000000e+000,0.000000e+000,4.573739e+000,4.573739e+000,8.323240e-002,8.323240e-002,4.467747e+000,-2.275991e-002,-2.275991e-002,3.237510e-007,3.237510e-007,,,,,,,,,,,,,,,,,,,,
1524688361.086,,0.000000e+000,5.499839e+001,5.500103e+001,1,0,3.096774e+000,0.000000e+000,4.660258e+000,4.660258e+000,3.417656e-002,1.633549e-001,4.668283e+000,4.220220e-002,1.713805e-001,1.015593e-006,1.015593e-006,,,,,,,,,,,,,,,,,,,,
1524688386.536,,0.000000e+000,5.499577e+001,5.499971e+001,1,0,2.064516e+000,0.000000e+000,4.694438e+000,4.694438e+000,1.157163e-001,1.981044e-001,4.667793e+000,8.907160e-002,1.714597e-001,2.313158e-006,2.313158e-006,,,,,,,,,,,,,,,,,,,,
1524688412.186,,0.000000e+000,5.499051e+001,5.499971e+001,1,0,1.032258e+000,0.000000e+000,4.448005e+000,4.448005e+000,-7.640463e-002,-3.487921e-002,4.481755e+000,-4.265410e-002,-1.128674e-003,-2.486006e-006,-2.486006e-006,,,,,,,,,,,,,,,,,,,,
1524688438.586,,0.000000e+000,5.499577e+001,5.499314e+001,1,0,0.000000e+000,0.000000e+000,4.573129e+000,4.573129e+000,1.025300e-001,1.025300e-001,4.451060e+000,-1.953888e-002,-1.953888e-002,9.850628e-007,9.850628e-007,,,,,,,,,,,,,,,,,,,,
1524688450.986,,0.000000e+000,5.499314e+001,5.500103e+001,1,0,3.096774e+000,0.000000e+000,4.618906e+000,4.618906e+000,3.180831e-002,1.480742e-001,4.638187e+000,5.108922e-002,1.673551e-001,8.695351e-007,8.695351e-007,,,,,,,,,,,,,,,,,,,,
1524688476.606,,0.000000e+000,5.499839e+001,5.499445e+001,1,0,2.064516e+000,0.000000e+000,4.653544e+000,4.653544e+000,1.144784e-001,1.948404e-001,4.622789e+000,8.372381e-002,1.640859e-001,2.300323e-006,2.300323e-006,,,,,,,,,,,,,,,,,,,,
1524688501.676,,0.000000e+000,5.499577e+001,5.500103e+001,1,0,1.032258e+000,0.000000e+000,4.411688e+000,4.411688e+000,-7.608376e-002,-3.901768e-002,4.444449e+000,-4.332314e-002,-6.257057e-003,-2.402012e-006,-2.402012e-006,,,,,,,,,,,,,,,,,,,,
1524688526.896,,0.000000e+000,5.499839e+001,5.500367e+001,1,0,0.000000e+000,0.000000e+000,4.540627e+000,4.540627e+000,1.026716e-001,1.026716e-001,4.419591e+000,-1.836443e-002,-1.836443e-002,1.104316e-006,1.104316e-006,,,,,,,,,,,,,,,,,,,,
1524688539.656,,0.000000e+000,5.500103e+001,5.499708e+001,1,0,3.096774e+000,0.000000e+000,4.579690e+000,4.579690e+000,3.898458e-002,1.373444e-001,4.589995e+000,4.928903e-002,1.476488e-001,9.661453e-007,9.661453e-007,,,,,,,,,,,,,,,,,,,,
1524688564.286,,0.000000e+000,5.499839e+001,5.499971e+001,1,0,2.064516e+000,0.000000e+000,4.605783e+000,4.605783e+000,1.076676e-001,1.723561e-001,4.573538e+000,7.542241e-002,1.401110e-001,2.129440e-006,2.129440e-006,,,,,,,,,,,,,,,,,,,,
1524688589.396,,0.000000e+000,5.499839e+001,5.500497e+001,1,0,1.032258e+000,0.000000e+000,4.381170e+000,4.381170e+000,-7.681228e-002,-4.564905e-002,4.412983e+000,-4.499962e-002,-1.383638e-002,-2.334113e-006,-2.334113e-006,,,,,,,,,,,,,,,,,,,,
1524688614.526,,0.000000e+000,5.499577e+001,5.500235e+001,1,0,0.000000e+000,0.000000e+000,4.522622e+000,4.522622e+000,1.043944e-001,1.043944e-001,4.401986e+000,-1.624155e-002,-1.624155e-002,1.423337e-006,1.423337e-006,,,,,,,,,,,,,,,,,,,,
1524688627.086,,0.000000e+000,5.499577e+001,5.501155e+001,1,0,3.096774e+000,0.000000e+000,4.534676e+000,4.534676e+000,3.156826e-002,1.231160e-001,4.553634e+000,5.052635e-002,1.420741e-001,7.948256e-007,7.948256e-007,,,,,,,,,,,,,,,,,,,,
1524688652.706,,0.000000e+000,5.500103e+001,5.499182e+001,1,0,2.064516e+000,0.000000e+000,4.559091e+000,4.559091e+000,9.797832e-002,1.508718e-001,4.520322e+000,5.920955e-002,1.121030e-001,1.919674e-006,1.919674e-006,,,,,,,,,,,,,,,,,,,,
1524688677.766,,0.000000e+000,5.499971e+001,5.499708e+001,1,0,1.032258e+000,0.000000e+000,4.354467e+000,4.354467e+000,-7.122487e-002,-4.323721e-002,4.384079e+000,-4.161233e-002,-1.362467e-002,-2.141620e-006,-2.141620e-006,,,,,,,,,,,,,,,,,,,,
1524688703.006,,0.000000e+000,5.499577e+001,5.500235e+001,1,0,0.000000e+000,0.000000e+000,4.493019e+000,4.493019e+000,9.994316e-002,9.994316e-002,4.378997e+000,-1.407909e-002,-1.407909e-002,1.430410e-006,1.430410e-006,,,,,,,,,,,,,,,,,,,,
1524688715.416,,0.000000e+000,5.499839e+001,5.499708e+001,1,0,3.096774e+000,0.000000e+000,4.505531e+000,4.505531e+000,3.624035e-002,1.189117e-001,4.522069e+000,5.277754e-002,1.354489e-001,8.422066e-007,8.422066e-007,,,,,,,,,,,,,,,,,,,,
1524688740.576,,0.000000e+000,5.498788e+001,5.499314e+001,1,0,2.064516e+000,0.000000e+000,4.529793e+000,4.529793e+000,9.488171e-002,1.494513e-001,4.491183e+000,5.627125e-002,1.108408e-001,1.869994e-006,1.869994e-006,,,,,,,,,,,,,,,,,,,,
1524688765.776,,0.000000e+000,5.498525e+001,5.499839e+001,1,0,1.032258e+000,0.000000e+000,4.330816e+000,4.330816e+000,-7.208808e-002,-4.450846e-002,4.363291e+000,-3.961261e-002,-1.203299e-002,-2.149041e-006,-2.149041e-006,,,,,,,,,,,,,,,,,,,,
1524688790.896,,0.000000e+000,5.499445e+001,5.500103e+001,1,0,0.000000e+000,0.000000e+000,4.480659e+000,4.480659e+000,1.025910e-001,1.025910e-001,4.365201e+000,-1.286650e-002,-1.286650e-002,1.517255e-006,1.517255e-006,,,,,,,,,,,,,,,,,,,,
1524688803.607,,0.000000e+000,5.500103e+001,5.500367e+001,1,0,3.096774e+000,0.000000e+000,4.487221e+000,4.487221e+000,3.955153e-002,1.053600e-001,4.502923e+000,5.525425e-002,1.210628e-001,8.225616e-007,8.225616e-007,,,,,,,,,,,,,,,,,,,,
1524688828.367,,0.000000e+000,5.499445e+001,5.499971e+001,1,0,2.064516e+000,0.000000e+000,4.507973e+000,4.507973e+000,8.945957e-002,1.347523e-001,4.472500e+000,5.398718e-002,9.927988e-002,1.728942e-006,1.728942e-006,,,,,,,,,,,,,,,,,,,,
1524688853.637,,0.000000e+000,5.499839e+001,5.499708e+001,1,0,1.032258e+000,0.000000e+000,4.320897e+000,4.320897e+000,-7.373217e-002,-5.196190e-002,4.352982e+000,-4.164771e-002,-1.987743e-002,-2.105648e-006,-2.105648e-006,,,,,,,,,,,,,,,,,,,,
1524688878.787,,0.000000e+000,5.499314e+001,5.499445e+001,1,0,0.000000e+000,0.000000e+000,4.482185e+000,4.482185e+000,1.033463e-001,1.033463e-001,4.367306e+000,-1.153231e-002,-1.153231e-002,1.695225e-006,1.695225e-006,,,,,,,,,,,,,,,,,,,,
1524688891.717,,0.000000e+000,5.499445e+001,5.500761e+001,1,0,3.096774e+000,0.000000e+000,4.486610e+000,4.486610e+000,4.506217e-002,1.087012e-001,4.505069e+000,6.352101e-002,1.271601e-001,9.147770e-007,9.147770e-007,,,,,,,,,,,,,,,,,,,,
1524688916.757,,0.000000e+000,5.499445e+001,5.500103e+001,1,0,2.064516e+000,0.000000e+000,4.509499e+000,4.509499e+000,8.088879e-002,1.225686e-001,4.473534e+000,4.492430e-002,8.660412e-002,1.548964e-006,1.548964e-006,,,,,,,,,,,,,,,,,,,,
1524688941.967,,0.000000e+000,5.499839e+001,5.499708e+001,1,0,1.032258e+000,0.000000e+000,4.342107e+000,4.342107e+000,-7.260664e-002,-5.554199e-002,4.374165e+000,-4.054888e-002,-2.348423e-002,-2.006826e-006,-2.006826e-006,,,,,,,,,,,,,,,,,,,,
1524688966.637,,0.000000e+000,5.499314e+001,5.499445e+001,1,0,0.000000e+000,0.000000e+000,4.496529e+000,4.496529e+000,9.327793e-002,9.327793e-002,4.392239e+000,-1.101208e-002,-1.101208e-002,1.414752e-006,1.414752e-006,,,,,,,,,,,,,,,,,,,,
1524688979.107,,0.000000e+000,5.499839e+001,5.499839e+001,1,0,3.096774e+000,0.000000e+000,4.524300e+000,4.524300e+000,3.824659e-002,1.081800e-001,4.548999e+000,6.294581e-002,1.328793e-001,8.177885e-007,8.177885e-007,,,,,,,,,,,,,,,,,,,,
1524689004.237,,0.000000e+000,5.499577e+001,5.500103e+001,1,0,2.064516e+000,0.000000e+000,4.580301e+000,4.580301e+000,8.640181e-002,1.348939e-001,4.535067e+000,4.116809e-002,8.966017e-002,1.679611e-006,1.679611e-006,,,,,,,,,,,,,,,,,,,,
1524689029.927,,0.000000e+000,5.500103e+001,5.499971e+001,1,0,1.032258e+000,0.000000e+000,4.422217e+000,4.422217e+000,-7.936925e-002,-6.300592e-002,4.460035e+000,-4.155178e-002,-2.518845e-002,-2.149842e-006,-2.149842e-006,,,,,,,,,,,,,,,,,,,,
1524689055.557,,0.000000e+000,5.499182e+001,5.498656e+001,1,0,0.000000e+000,0.000000e+000,4.550088e+000,4.550088e+000,9.346771e-002,9.346771e-002,4.446725e+000,-9.894848e-003,-9.894848e-003,1.605833e-006,1.605833e-006,,,,,,,,,,,,,,,,,,,,
1524689067.727,,0.000000e+000,5.499708e+001,5.499971e+001,1,0,3.096774e+000,0.000000e+000,4.571298e+000,4.571298e+000,4.073210e-002,9.826279e-002,4.597585e+000,6.701966e-002,1.245503e-001,7.891649e-007,7.891649e-007,,,,,,,,,,,,,,,,,,,,
1524689093.387,,0.000000e+000,5.500235e+001,5.499577e+001,1,0,2.064516e+000,0.000000e+000,4.620432e+000,4.620432e+000,7.573447e-002,1.188936e-001,4.564485e+000,1.978764e-002,6.294680e-002,1.462846e-006,1.462846e-006,,,,,,,,,,,,,,,,,,,,
1524689144.077,,0.000000e+000,5.498656e+001,5.499182e+001,1,0,1.032258e+000,0.000000e+000,4.508430e+000,4.508430e+000,-8.207771e-002,-6.755495e-002,4.552841e+000,-3.766748e-002,-2.314472e-002,-2.173445e-006,-2.173445e-006,,,,,,,,,,,,,,,,,,,,
1524689169.447,,0.000000e+000,5.500103e+001,5.500367e+001,1,0,0.000000e+000,0.000000e+000,4.720378e+000,4.720378e+000,9.912586e-002,9.912586e-002,4.612192e+000,-9.060383e-003,-9.060383e-003,1.788285e-006,1.788285e-006,,,,,,,,,,,,,,,,,,,,
1524689181.947,,0.000000e+000,5.499445e+001,5.498525e+001,1,0,3.096774e+000,0.000000e+000,4.741894e+000,4.741894e+000,4.603105e-002,1.054206e-001,4.762079e+000,6.621604e-002,1.256056e-001,9.451323e-007,9.451323e-007,,,,,,,,,,,,,,,,,,,,
1524689206.977,,0.000000e+000,5.499839e+001,5.499839e+001,1,0,2.064516e+000,0.000000e+000,4.793622e+000,4.793622e+000,7.290310e-002,1.140871e-001,4.741812e+000,2.109331e-002,6.227732e-002,1.401466e-006,1.401466e-006,,,,,,,,,,,,,,,,,,,,
1524689232.307,,0.000000e+000,5.499577e+001,5.499445e+001,1,0,1.032258e+000,0.000000e+000,4.681315e+000,4.681315e+000,-6.863613e-002,-5.026007e-002,4.716557e+000,-3.339500e-002,-1.501894e-002,-1.911365e-006,-1.911365e-006,,,,,,,,,,,,,,,,,,,,
1524689257.497,,0.000000e+000,5.499445e+001,5.499577e+001,1,0,0.000000e+000,0.000000e+000,4.883192e+000,4.883192e+000,1.054215e-001,1.054215e-001,4.773356e+000,-4.414082e-003,-4.414082e-003,1.894456e-006,1.894456e-006,,,,,,,,,,,,,,,,,,,,
1524689270.317,,0.000000e+000,5.500235e+001,5.499708e+001,1,0,3.096774e+000,0.000000e+000,4.888533e+000,4.888533e+000,4.302639e-002,8.622503e-002,4.914926e+000,6.941932e-002,1.126180e-001,8.065545e-007,8.065545e-007,,,,,,,,,,,,,,,,,,,,
1524689295.547,,0.000000e+000,5.498788e+001,5.499577e+001,1,0,2.064516e+000,0.000000e+000,4.940108e+000,4.940108e+000,5.586340e-002,1.434832e-001,4.898030e+000,1.378491e-002,1.014047e-001,1.372566e-006,1.372566e-006,,,,,,,,,,,,,,,,,,,,
1524689320.777,,0.000000e+000,5.498788e+001,5.500367e+001,1,0,1.032258e+000,0.000000e+000,4.804151e+000,4.804151e+000,-6.973621e-002,-3.037834e-002,4.877308e+000,3.421098e-003,4.277897e-002,-2.096727e-006,-2.096727e-006,,,,,,,,,,,,,,,,,,,,
1524689347.977,,0.000000e+000,5.499577e+001,5.499708e+001,1,0,0.000000e+000,0.000000e+000,4.997940e+000,4.997940e+000,1.279135e-001,1.279135e-001,4.861897e+000,-8.129597e-003,-8.129597e-003,1.829845e-006,1.829845e-006,,,,,,,,,,,,,,,,,,,,
1524689362.309,,0.000000e+000,5.499839e+001,5.500235e+001,1,0,3.096774e+000,0.000000e+000,5.000381e+000,5.000381e+000,1.483561e-002,1.097593e-001,4.982805e+000,-2.740610e-003,9.218311e-002,7.884519e-007,7.884519e-007,,,,,,,,,,,,,,,,,,,,
1524689386.529,,0.000000e+000,5.499314e+001,5.499839e+001,1,0,2.064516e+000,0.000000e+000,5.087816e+000,5.087816e+000,7.249257e-002,9.585047e-002,5.038417e+000,2.309367e-002,4.645157e-002,1.382316e-006,1.382316e-006,,,,,,,,,,,,,,,,,,,,
1524689414.291,,0.000000e+000,5.499708e+001,5.499839e+001,1,0,1.032258e+000,0.000000e+000,4.997940e+000,4.997940e+000,-6.490546e-002,-3.760481e-002,5.062894e+000,4.834123e-005,2.734900e-002,-1.872584e-006,-1.872584e-006,,,,,,,,,,,,,,,,,,,,
1524689443.305,,0.000000e+000,5.500629e+001,5.499839e+001,1,0,0.000000e+000,0.000000e+000,5.246663e+000,5.246663e+000,1.374726e-001,1.374726e-001,5.103985e+000,-5.204678e-003,-5.204678e-003,2.232031e-006,2.232031e-006,,,,,,,,,,,,,,,,,,,,
1524689458.047,,0.000000e+000,5.499839e+001,5.499314e+001,1,0,3.096774e+000,0.000000e+000,5.241780e+000,5.241780e+000,1.658538e-002,1.033659e-001,5.222386e+000,-2.808066e-003,8.397245e-002,7.834751e-007,7.834751e-007,,,,,,,,,,,,,,,,,,,,
1524689486.251,,0.000000e+000,5.499971e+001,5.499971e+001,1,0,2.064516e+000,0.000000e+000,5.312428e+000,5.312428e+000,5.346276e-002,1.152000e-001,5.277445e+000,1.847912e-002,8.021641e-002,1.182576e-006,1.182576e-006,,,,,,,,,,,,,,,,,,,,
1524689512.864,,0.000000e+000,5.499314e+001,5.499839e+001,1,0,1.032258e+000,0.000000e+000,5.194324e+000,5.194324e+000,-7.087746e-002,-4.224443e-002,5.265261e+000,5.969964e-005,2.869272e-002,-2.034125e-006,-2.034125e-006,,,,,,,,,,,,,,,,,,,,
1524689540.388,,0.000000e+000,5.499051e+001,5.499971e+001,1,0,0.000000e+000,0.000000e+000,5.395133e+000,5.395133e+000,1.174579e-001,1.174579e-001,5.270814e+000,-6.860733e-003,-6.860733e-003,1.624809e-006,1.624809e-006,,,,,,,,,,,,,,,,,,,,
1524689554.410,,0.000000e+000,5.500629e+001,5.499445e+001,1,0,3.096774e+000,0.000000e+000,5.390097e+000,5.390097e+000,1.485381e-002,1.004682e-001,5.374574e+000,-6.691441e-004,8.494520e-002,7.730559e-007,7.730559e-007,,,,,,,,,,,,,,,,,,,,
1524689582.494,,0.000000e+000,5.500235e+001,5.500103e+001,1,0,2.064516e+000,0.000000e+000,5.444266e+000,5.444266e+000,4.925087e-002,9.841537e-002,5.414328e+000,1.931265e-002,6.847715e-002,1.080742e-006,1.080742e-006,,,,,,,,,,,,,,,,,,,,
1524689608.716,,0.000000e+000,5.500629e+001,5.500367e+001,1,0,1.032258e+000,0.000000e+000,5.313649e+000,5.313649e+000,-1.478017e-001,-1.568007e-001,5.327455e+000,-1.339963e-001,-1.429954e-001,-2.478366e-006,-2.478366e-006,,,,,,,,,,,,,,,,,,,,
1524689636.108,,0.000000e+000,5.499445e+001,5.499445e+001,1,0,0.000000e+000,0.000000e+000,5.549097e+000,5.549097e+000,1.320796e-001,1.320796e-001,5.411588e+000,-5.428791e-003,-5.428791e-003,2.342887e-006,2.342887e-006,,,,,,,,,,,,,,,,,,,,
1524689650.740,,0.000000e+000,5.499445e+001,5.500235e+001,1,0,3.096774e+000,0.000000e+000,5.503014e+000,5.503014e+000,6.531086e-004,6.975079e-002,5.499953e+000,-2.407232e-003,6.669044e-002,3.405439e-007,3.405439e-007,,,,,,,,,,,,,,,,,,,,
1524689677.562,,0.000000e+000,5.499577e+001,5.499708e+001,1,0,2.064516e+000,0.000000e+000,5.410697e+000,5.410697e+000,2.822454e-002,-1.674175e-003,5.397196e+000,1.472385e-002,-1.517487e-002,1.031294e-006,1.031294e-006,,,,,,,,,,,,,,,,,,,,
1524689705.696,,0.000000e+000,5.499051e+001,5.499445e+001,1,0,1.032258e+000,0.000000e+000,5.492638e+000,5.492638e+000,-7.275041e-002,-6.690693e-002,5.565449e+000,6.071804e-005,5.904198e-003,-1.758686e-006,-1.758686e-006,,,,,,,,,,,,,,,,,,,,
1524689730.366,,0.000000e+000,5.499577e+001,5.499445e+001,1,0,0.000000e+000,0.000000e+000,5.381857e+000,5.381857e+000,4.294252e-002,4.294252e-002,5.341329e+000,2.414703e-003,2.414703e-003,1.977547e-006,1.977547e-006,,,,,,,,,,,,,,,,,,,,
1524689742.996,,0.000000e+000,5.499708e+001,5.499839e+001,1,0,3.096774e+000,0.000000e+000,5.347066e+000,5.347066e+000,6.198986e-003,-1.300764e-002,5.378075e+000,3.720723e-002,1.800060e-002,1.755834e-007,1.755834e-007,,,,,,,,,,,,,,,,,,,,
1524689769.528,,0.000000e+000,5.500629e+001,5.500103e+001,1,0,2.064516e+000,0.000000e+000,5.437552e+000,5.437552e+000,2.947312e-002,1.689243e-002,5.420904e+000,1.282435e-002,2.436638e-004,1.030043e-006,1.030043e-006,,,,,,,,,,,,,,,,,,,,
1524689796.710,,0.000000e+000,5.499182e+001,5.500367e+001,1,0,1.032258e+000,0.000000e+000,5.327229e+000,5.327229e+000,-6.264812e-002,-3.689528e-002,5.389926e+000,4.881620e-005,2.580166e-002,-1.800916e-006,-1.800916e-006,,,,,,,,,,,,,,,,,,,,
1524689821.870,,0.000000e+000,5.499314e+001,5.499971e+001,1,0,0.000000e+000,0.000000e+000,5.541008e+000,5.541008e+000,4.119682e-002,4.119682e-002,5.502960e+000,3.148079e-003,3.148079e-003,2.175278e-006,2.175278e-006,,,,,,,,,,,,,,,,,,,,
1524689836.642,,0.000000e+000,5.499971e+001,5.499708e+001,1,0,3.096774e+000,0.000000e+000,5.484550e+000,5.484550e+000,-5.245674e-003,5.634785e-002,5.487604e+000,-2.192009e-003,5.940151e-002,1.725566e-007,1.725566e-007,,,,,,,,,,,,,,,,,,,,
1524689864.806,,0.000000e+000,5.499577e+001,5.499971e+001,1,0,2.064516e+000,0.000000e+000,5.558557e+000,5.558557e+000,4.905085e-002,1.039414e-001,5.526108e+000,1.660160e-002,7.149220e-002,1.084933e-006,1.084933e-006,,,,,,,,,,,,,,,,,,,,
1524689889.516,,0.000000e+000,5.498919e+001,5.498919e+001,1,0,1.032258e+000,0.000000e+000,5.443198e+000,5.443198e+000,-1.234471e-001,-1.344500e-001,5.439597e+000,-1.270481e-001,-1.380510e-001,-1.949229e-006,-1.949229e-006,,,,,,,,,,,,,,,,,,,,
1524689915.126,,0.000000e+000,5.498262e+001,5.499445e+001,1,0,0.000000e+000,0.000000e+000,5.640650e+000,5.640650e+000,4.420614e-002,4.420614e-002,5.557931e+000,-3.851271e-002,-3.851271e-002,2.020563e-006,2.020563e-006,,,,,,,,,,,,,,,,,,,,
1524689927.496,,0.000000e+000,5.499971e+001,5.499577e+001,1,0,3.096774e+000,0.000000e+000,5.611658e+000,5.611658e+000,2.441262e-002,-5.032063e-003,5.619915e+000,3.267001e-002,3.225327e-003,5.116162e-007,5.116162e-007,,,,,,,,,,,,,,,,,,,,
1524689954.208,,0.000000e+000,5.499445e+001,5.500103e+001,1,0,2.064516e+000,0.000000e+000,5.642024e+000,5.642024e+000,1.729474e-002,-3.929615e-003,5.636569e+000,1.183972e-002,-9.384632e-003,7.695053e-007,7.695053e-007,,,,,,,,,,,,,,,,,,,,
1524689983.182,,0.000000e+000,5.498919e+001,5.499839e+001,1,0,1.032258e+000,0.000000e+000,5.511406e+000,5.511406e+000,-9.521757e-002,-7.577848e-002,5.606660e+000,3.637001e-005,1.947546e-002,-2.430228e-006,-2.430228e-006,,,,,,,,,,,,,,,,,,,,
1524690011.606,,0.000000e+000,5.499971e+001,5.500367e+001,1,0,0.000000e+000,0.000000e+000,5.734646e+000,5.734646e+000,1.333971e-001,1.333971e-001,5.602025e+000,7.762909e-004,7.762909e-004,2.638466e-006,2.638466e-006,,,,,,,,,,,,,,,,,,,,
1524690025.568,,0.000000e+000,5.499445e+001,5.499839e+001,1,0,3.096774e+000,0.000000e+000,5.669642e+000,5.669642e+000,9.146285e-003,5.177593e-002,5.660115e+000,-3.809212e-004,4.224873e-002,4.232279e-007,4.232279e-007,,,,,,,,,,,,,,,,,,,,
1524690052.180,,0.000000e+000,5.499839e+001,5.499314e+001,1,0,2.064516e+000,0.000000e+000,5.684749e+000,5.684749e+000,3.932167e-002,7.693577e-002,5.644791e+000,-6.363280e-004,3.697777e-002,8.977659e-007,8.977659e-007,,,,,,,,,,,,,,,,,,,,
1524690078.962,,0.000000e+000,5.500103e+001,5.498525e+001,1,0,1.032258e+000,0.000000e+000,5.544213e+000,5.544213e+000,-6.786127e-002,-3.782701e-002,5.612112e+000,3.748201e-005,3.007174e-002,-1.967943e-006,-1.967943e-006,,,,,,,,,,,,,,,,,,,,
1524690105.634,,0.000000e+000,5.499971e+001,5.499445e+001,1,0,0.000000e+000,0.000000e+000,5.744564e+000,5.744564e+000,4.074526e-002,4.074526e-002,5.715405e+000,1.158571e-002,1.158571e-002,2.108107e-006,2.108107e-006,,,,,,,,,,,,,,,,,,,,
1524690118.354,,0.000000e+000,5.499971e+001,5.499051e+001,1,0,3.096774e+000,0.000000e+000,5.704891e+000,5.704891e+000,2.349551e-002,6.008148e-003,5.712980e+000,3.158410e-002,1.409674e-002,5.496549e-007,5.496549e-007,,,,,,,,,,,,,,,,,,,,
1524690145.096,,0.000000e+000,5.499182e+001,5.499708e+001,1,0,2.064516e+000,0.000000e+000,5.718472e+000,5.718472e+000,2.654996e-002,5.121469e-002,5.689833e+000,-2.088405e-003,2.257633e-002,6.095215e-007,6.095215e-007,,,,,,,,,,,,,,,,,,,,
1524690170.986,,0.000000e+000,5.499182e+001,5.499445e+001,1,0,1.032258e+000,0.000000e+000,5.618830e+000,5.618830e+000,-1.123853e-001,-1.363273e-001,5.608454e+000,-1.227608e-001,-1.467028e-001,-1.534412e-006,-1.534412e-006,,,,,,,,,,,,,,,,,,,,
1524690196.036,,0.000000e+000,5.499314e+001,5.499577e+001,1,0,0.000000e+000,0.000000e+000,6.018922e+000,6.018922e+000,1.003904e-001,1.003904e-001,5.913981e+000,-4.549980e-003,-4.549980e-003,3.050925e-006,3.050925e-006,,,,,,,,,,,,,,,,,,,,
1524690208.966,,0.000000e+000,5.500235e+001,5.499708e+001,1,0,3.096774e+000,0.000000e+000,5.616846e+000,5.616846e+000,4.006327e-002,4.068851e-002,5.651215e+000,7.443226e-002,7.505751e-002,4.871981e-007,4.871981e-007,,,,,,,,,,,,,,,,,,,,
1524690234.207,,0.000000e+000,5.499051e+001,5.500367e+001,1,0,2.064516e+000,0.000000e+000,5.632410e+000,5.632410e+000,3.954847e-002,3.954172e-002,5.586136e+000,-6.725718e-003,-6.732464e-003,6.611226e-007,6.611226e-007,,,,,,,,,,,,,,,,,,,,
1524690261.219,,0.000000e+000,5.499708e+001,5.500235e+001,1,0,1.032258e+000,0.000000e+000,5.536736e+000,5.536736e+000,-6.747767e-002,-5.163050e-002,5.604224e+000,1.051649e-005,1.585770e-002,-1.738226e-006,-1.738226e-006,,,,,,,,,,,,,,,,,,,,
1524690286.049,,0.000000e+000,5.499839e+001,5.500103e+001,1,0,0.000000e+000,0.000000e+000,5.730526e+000,5.730526e+000,5.013227e-002,5.013227e-002,5.683251e+000,2.857685e-003,2.857685e-003,2.182089e-006,2.182089e-006,,,,,,,,,,,,,,,,,,,,
1524690300.731,,0.000000e+000,5.499577e+001,5.498919e+001,1,0,3.096774e+000,0.000000e+000,-9.115892e+000,-9.115892e+000,7.184739e-002,-5.203199e-001,-9.153674e+000,3.406568e-002,-5.581017e-001,-9.715150e-007,-9.715150e-007,,,,,,,,,,,,,,,,,,,,
1524690325.921,,0.000000e+000,5.499839e+001,5.500103e+001,1,0,2.064516e+000,0.000000e+000,5.700770e+000,5.700770e+000,3.804099e-002,4.380941e-002,5.661121e+000,-1.608022e-003,4.160404e-003,6.229675e-007,6.229675e-007,,,,,,,,,,,,,,,,,,,,
1524690354.785,,0.000000e+000,5.499839e+001,5.499314e+001,1,0,1.032258e+000,0.000000e+000,5.615625e+000,5.615625e+000,-6.724022e-002,-4.901838e-002,5.682859e+000,-6.651506e-006,1.821518e-002,-1.751643e-006,-1.751643e-006,,,,,,,,,,,,,,,,,,,,
1524690382.779,,0.000000e+000,5.500497e+001,5.498919e+001,1,0,0.000000e+000,0.000000e+000,5.835966e+000,5.835966e+000,1.423650e-001,1.423650e-001,5.695045e+000,1.444817e-003,1.444817e-003,2.629182e-006,2.629182e-006,,,,,,,,,,,,,,,,,,,,
1524690396.611,,0.000000e+000,5.499708e+001,5.499839e+001,1,0,3.096774e+000,0.000000e+000,5.752193e+000,5.752193e+000,-7.934008e-003,4.359341e-002,5.760909e+000,7.811449e-004,5.230856e-002,1.070730e-007,1.070730e-007,,,,,,,,,,,,,,,,,,,,
1524690425.585,,0.000000e+000,5.499577e+001,5.499051e+001,1,0,2.064516e+000,0.000000e+000,5.819791e+000,5.819791e+000,2.673618e-002,6.588459e-002,5.789916e+000,-3.138617e-003,3.600979e-002,6.227638e-007,6.227638e-007,,,,,,,,,,,,,,,,,,,,
1524690452.757,,0.000000e+000,5.499577e+001,5.499708e+001,1,0,1.032258e+000,0.000000e+000,5.694514e+000,5.694514e+000,-6.775531e-002,-4.704046e-002,5.762260e+000,-9.628013e-006,2.070522e-002,-1.795532e-006,-1.795532e-006,,,,,,,,,,,,,,,,,,,,
1524690477.987,,0.000000e+000,5.499839e+001,5.500629e+001,1,0,0.000000e+000,0.000000e+000,5.891356e+000,5.891356e+000,9.524584e-002,9.524584e-002,5.791452e+000,-4.657745e-003,-4.657745e-003,2.335088e-006,2.335088e-006,,,,,,,,,,,,,,,,,,,,
1524690492.619,,0.000000e+000,5.499577e+001,5.500497e+001,1,0,3.096774e+000,0.000000e+000,5.831235e+000,5.831235e+000,1.161267e-002,6.476498e-002,5.820292e+000,6.687846e-004,5.382109e-002,5.508191e-007,5.508191e-007,,,,,,,,,,,,,,,,,,,,
1524690518.951,,0.000000e+000,5.499839e+001,5.499708e+001,1,0,2.064516e+000,0.000000e+000,5.854581e+000,5.854581e+000,4.244924e-002,2.312231e-002,5.808503e+000,-3.629448e-003,-2.295637e-002,6.717746e-007,6.717746e-007,,,,,,,,,,,,,,,,,,,,
1524690545.963,,0.000000e+000,5.499708e+001,5.499971e+001,1,0,1.032258e+000,0.000000e+000,5.753262e+000,5.753262e+000,-7.011953e-002,-5.452013e-002,5.823375e+000,-6.351620e-006,1.559305e-002,-1.779466e-006,-1.779466e-006,,,,,,,,,,,,,,,,,,,,
1524690572.285,,0.000000e+000,5.500103e+001,5.499839e+001,1,0,0.000000e+000,0.000000e+000,5.951324e+000,5.951324e+000,1.365895e-001,1.365895e-001,5.815721e+000,9.870529e-004,9.870529e-004,2.525805e-006,2.525805e-006,,,,,,,,,,,,,,,,,,,,
1524690586.617,,0.000000e+000,5.500367e+001,5.499971e+001,1,0,3.096774e+000,0.000000e+000,5.866942e+000,5.866942e+000,-6.617448e-003,3.672409e-002,5.873968e+000,4.087472e-004,4.375029e-002,8.736970e-008,8.736970e-008,,,,,,,,,,,,,,,,,,,,
1524690612.227,,0.000000e+000,5.500103e+001,5.499839e+001,1,0,2.064516e+000,0.000000e+000,5.882353e+000,5.882353e+000,2.154690e-002,4.061699e-003,5.855943e+000,-4.863681e-003,-2.234888e-002,1.722656e-007,1.722656e-007,,,,,,,,,,,,,,,,,,,,
1524690638.329,,0.000000e+000,5.499314e+001,5.499839e+001,1,0,1.032258e+000,0.000000e+000,5.779812e+000,5.779812e+000,-8.998988e-002,-9.761333e-002,5.845902e+000,-2.390025e-002,-3.152370e-002,-2.000481e-006,-2.000481e-006,,,,,,,,,,,,,,,,,,,,
1524690663.849,,0.000000e+000,5.500367e+001,5.499971e+001,1,0,0.000000e+000,0.000000e+000,5.995422e+000,5.995422e+000,1.041980e-001,1.041980e-001,5.886988e+000,-4.236698e-003,-4.236698e-003,2.614106e-006,2.614106e-006,,,,,,,,,,,,,,,,,,,,
1524690676.529,,0.000000e+000,5.499971e+001,5.499314e+001,1,0,3.096774e+000,0.000000e+000,5.915617e+000,5.915617e+000,5.651025e-002,3.748322e-002,5.946199e+000,8.709220e-002,6.806517e-002,6.820192e-007,6.820192e-007,,,,,,,,,,,,,,,,,,,,
1524690705.333,,0.000000e+000,5.499708e+001,5.500103e+001,1,0,2.064516e+000,0.000000e+000,5.934386e+000,5.934386e+000,3.557892e-002,6.584597e-002,5.893659e+000,-5.148219e-003,2.511883e-002,8.206989e-007,8.206989e-007,,,,,,,,,,,,,,,,,,,,
1524690731.413,,0.000000e+000,5.500235e+001,5.499708e+001,1,0,1.032258e+000,0.000000e+000,5.828641e+000,5.828641e+000,-8.034324e-002,-8.999538e-002,5.881587e+000,-2.739810e-002,-3.705025e-002,-1.769076e-006,-1.769076e-006,,,,,,,,,,,,,,,,,,,,
1524690760.657,,0.000000e+000,5.499445e+001,5.499971e+001,1,0,0.000000e+000,0.000000e+000,5.990540e+000,5.990540e+000,1.356359e-001,1.356359e-001,5.856531e+000,1.627445e-003,1.627445e-003,2.651708e-006,2.651708e-006,,,,,,,,,,,,,,,,,,,,
1524690772.757,,0.000000e+000,5.500497e+001,5.499839e+001,1,0,3.096774e+000,0.000000e+000,5.910887e+000,5.910887e+000,5.465024e-002,1.925945e-002,5.937229e+000,8.099215e-002,4.560137e-002,5.845504e-007,5.845504e-007,,,,,,,,,,,,,,,,,,,,
1524690798.007,,0.000000e+000,5.499971e+001,5.500103e+001,1,0,2.064516e+000,0.000000e+000,5.894255e+000,5.894255e+000,3.940959e-002,2.470016e-002,5.849153e+000,-5.692529e-003,-2.040195e-002,6.110640e-007,6.110640e-007,,,,,,,,,,,,,,,,,,,,
1524690825.129,,0.000000e+000,5.499708e+001,5.499445e+001,1,0,1.032258e+000,0.000000e+000,5.795834e+000,5.795834e+000,-6.659463e-002,-5.295992e-002,5.862419e+000,-1.004152e-005,1.362467e-002,-1.670269e-006,-1.670269e-006,,,,,,,,,,,,,,,,,,,,
1524690850.861,,0.000000e+000,5.499577e+001,5.499445e+001,1,0,0.000000e+000,0.000000e+000,5.982147e+000,5.982147e+000,9.933090e-002,9.933090e-002,5.877001e+000,-5.814552e-003,-5.814552e-003,2.561952e-006,2.561952e-006,,,,,,,,,,,,,,,,,,,,
1524690865.253,,0.000000e+000,5.499708e+001,5.499445e+001,1,0,3.096774e+000,0.000000e+000,5.926147e+000,5.926147e+000,1.591235e-002,6.896877e-002,5.910853e+000,6.187558e-004,5.367517e-002,6.455521e-007,6.455521e-007,,,,,,,,,,,,,,,,,,,,
1524690890.023,,0.000000e+000,5.499971e+001,5.499839e+001,1,0,2.064516e+000,0.000000e+000,5.921874e+000,5.921874e+000,3.295566e-002,1.768732e-002,5.882861e+000,-6.057249e-003,-2.132559e-002,4.532631e-007,4.532631e-007,,,,,,,,,,,,,,,,,,,,
1524690915.623,,0.000000e+000,5.499971e+001,5.500629e+001,1,0,1.032258e+000,0.000000e+000,5.833066e+000,5.833066e+000,-7.932930e-002,-8.903074e-002,5.887031e+000,-2.536469e-002,-3.506613e-002,-1.738168e-006,-1.738168e-006,,,,,,,,,,,,,,,,,,,,
1524690940.684,,0.000000e+000,5.499577e+001,5.499445e+001,1,0,0.000000e+000,0.000000e+000,6.041810e+000,6.041810e+000,1.009979e-001,1.009979e-001,5.935967e+000,-4.844666e-003,-4.844666e-003,2.546149e-006,2.546149e-006,,,,,,,,,,,,,,,,,,,,
1524690955.116,,0.000000e+000,5.499708e+001,5.499314e+001,1,0,3.096774e+000,0.000000e+000,5.987335e+000,5.987335e+000,1.653260e-002,6.211758e-002,5.971407e+000,6.048102e-004,4.618979e-002,6.198243e-007,6.198243e-007,,,,,,,,,,,,,,,,,,,,
1524690979.686,,0.000000e+000,5.498656e+001,5.499839e+001,1,0,2.064516e+000,0.000000e+000,5.982605e+000,5.982605e+000,3.964215e-002,5.260944e-003,5.936759e+000,-6.203834e-003,-4.058504e-002,5.899929e-007,5.899929e-007,,,,,,,,,,,,,,,,,,,,
1524691004.986,,0.000000e+000,5.499839e+001,5.499445e+001,1,0,1.032258e+000,0.000000e+000,5.878386e+000,5.878386e+000,-8.020432e-002,-9.093761e-002,5.934003e+000,-2.458699e-002,-3.532028e-002,-1.741981e-006,-1.741981e-006,,,,,,,,,,,,,,,,,,,,
1524691032.218,,0.000000e+000,5.499445e+001,5.499839e+001,1,0,0.000000e+000,0.000000e+000,6.069734e+000,6.069734e+000,1.351771e-001,1.351771e-001,5.936252e+000,1.695633e-003,1.695633e-003,2.605229e-006,2.605229e-006,,,,,,,,,,,,,,,,,,,,
1524691044.308,,0.000000e+000,5.500103e+001,5.499839e+001,1,0,3.096774e+000,0.000000e+000,6.008240e+000,6.008240e+000,6.178439e-002,2.895212e-002,6.033860e+000,8.740485e-002,5.457258e-002,7.252675e-007,7.252675e-007,,,,,,,,,,,,,,,,,,,,
1524691069.528,,0.000000e+000,5.499445e+001,5.499839e+001,1,0,2.064516e+000,0.000000e+000,6.003967e+000,6.003967e+000,4.109132e-002,2.236223e-002,5.959637e+000,-3.238795e-003,-2.196789e-002,6.315822e-007,6.315822e-007,,,,,,,,,,,,,,,,,,,,
1524691096.060,,0.000000e+000,5.499182e+001,5.499577e+001,1,0,1.032258e+000,0.000000e+000,5.895323e+000,5.895323e+000,-6.465331e-002,-5.438662e-002,5.959970e+000,-6.582588e-006,1.026011e-002,-1.582666e-006,-1.582666e-006,,,,,,,,,,,,,,,,,,,,
1524691120.780,,0.000000e+000,5.498788e+001,5.499314e+001,1,0,0.000000e+000,0.000000e+000,6.083467e+000,6.083467e+000,1.073976e-001,1.073976e-001,5.972073e+000,-3.996372e-003,-3.996372e-003,2.616493e-006,2.616493e-006,,,,,,,,,,,,,,,,,,,,
1524691133.640,,0.000000e+000,5.499971e+001,5.499971e+001,1,0,3.096774e+000,0.000000e+000,6.008392e+000,6.008392e+000,5.217610e-002,2.019882e-002,6.031258e+000,7.504188e-002,4.306459e-002,5.828042e-007,5.828042e-007,,,,,,,,,,,,,,,,,,,,
1524691158.850,,0.000000e+000,5.499577e+001,5.500235e+001,1,0,2.064516e+000,0.000000e+000,6.012360e+000,6.012360e+000,4.180501e-002,1.365566e-002,5.965515e+000,-5.039955e-003,-3.318930e-002,6.543996e-007,6.543996e-007,,,,,,,,,,,,,,,,,,,,
1524691184.070,,0.000000e+000,5.499708e+001,5.499971e+001,1,0,1.032258e+000,0.000000e+000,5.889525e+000,5.889525e+000,-7.971128e-002,-9.237385e-002,5.943674e+000,-2.556261e-002,-3.822517e-002,-1.706823e-006,-1.706823e-006,,,,,,,,,,,,,,,,,,,,
1524691209.280,,0.000000e+000,5.500103e+001,5.499445e+001,1,0,0.000000e+000,0.000000e+000,6.086061e+000,6.086061e+000,1.052985e-001,1.052985e-001,5.975863e+000,-4.899502e-003,-4.899502e-003,2.739340e-006,2.739340e-006,,,,,,,,,,,,,,,,,,,,
1524691221.660,,0.000000e+000,5.500892e+001,5.500103e+001,1,0,3.096774e+000,0.000000e+000,6.008392e+000,6.008392e+000,5.720291e-002,3.736782e-002,6.033958e+000,8.276854e-002,6.293344e-002,7.148483e-007,7.148483e-007,,,,,,,,,,,,,,,,,,,,
1524691246.930,,0.000000e+000,5.500629e+001,5.499971e+001,1,0,2.064516e+000,0.000000e+000,5.990234e+000,5.990234e+000,3.425891e-002,1.700211e-002,5.949506e+000,-6.469661e-003,-2.372646e-002,5.027978e-007,5.027978e-007,,,,,,,,,,,,,,,,,,,,
1524691272.170,,0.000000e+000,5.499577e+001,5.499577e+001,1,0,1.032258e+000,0.000000e+000,5.888609e+000,5.888609e+000,-7.638159e-002,-8.511114e-002,5.942681e+000,-2.231017e-002,-3.103971e-002,-1.675537e-006,-1.675537e-006,,,,,,,,,,,,,,,,,,,,
1524691297.360,,0.000000e+000,5.500103e+001,5.499577e+001,1,0,0.000000e+000,0.000000e+000,6.085298e+000,6.085298e+000,1.084490e-001,1.084490e-001,5.972775e+000,-4.073620e-003,-4.073620e-003,2.829183e-006,2.829183e-006,,,,,,,,,,,,,,,,,,,,
1524691310.160,,0.000000e+000,5.500103e+001,5.500367e+001,1,0,3.096774e+000,0.000000e+000,5.992523e+000,5.992523e+000,5.512568e-002,1.811743e-002,6.017728e+000,8.033033e-002,4.332209e-002,5.931070e-007,5.931070e-007,,,,,,,,,,,,,,,,,,,,
1524691335.410,,0.000000e+000,5.499708e+001,5.500367e+001,1,0,2.064516e+000,0.000000e+000,5.980316e+000,5.980316e+000,3.513003e-002,1.490450e-002,5.940252e+000,-4.933828e-003,-2.515936e-002,5.039037e-007,5.039037e-007,,,,,,,,,,,,,,,,,,,,
1524691360.600,,0.000000e+000,5.499708e+001,5.499708e+001,1,0,1.032258e+000,0.000000e+000,5.873961e+000,5.873961e+000,-8.081660e-002,-9.348106e-002,5.929835e+000,-2.494273e-002,-3.760719e-002,-1.729612e-006,-1.729612e-006,,,,,,,,,,,,,,,,,,,,
1524691385.810,,0.000000e+000,5.499839e+001,5.499839e+001,1,0,0.000000e+000,0.000000e+000,6.076447e+000,6.076447e+000,1.032538e-001,1.032538e-001,5.968392e+000,-4.801273e-003,-4.801273e-003,2.752786e-006,2.752786e-006,,,,,,,,,,,,,,,,,,,,
1524691398.200,,0.000000e+000,5.499839e+001,5.499839e+001,1,0,3.096774e+000,0.000000e+000,5.994507e+000,5.994507e+000,5.000340e-002,2.341795e-002,6.017602e+000,7.309853e-002,4.651308e-002,5.715410e-007,5.715410e-007,,,,,,,,,,,,,,,,,,,,
1524691423.440,,0.000000e+000,5.499051e+001,5.500367e+001,1,0,2.064516e+000,0.000000e+000,5.962463e+000,5.962463e+000,3.105724e-002,1.732302e-002,5.923526e+000,-7.879371e-003,-2.161360e-002,4.427857e-007,4.427857e-007,,,,,,,,,,,,,,,,,,,,
1524691448.780,,0.000000e+000,5.498788e+001,5.501024e+001,1,0,1.032258e+000,0.000000e+000,5.868010e+000,5.868010e+000,-8.147494e-002,-9.332132e-002,5.927791e+000,-2.169435e-002,-3.354073e-002,-1.743872e-006,-1.743872e-006,,,,,,,,,,,,,,,,,,,,
1524691473.890,,0.000000e+000,5.500235e+001,5.500103e+001,1,0,0.000000e+000,0.000000e+000,6.070344e+000,6.070344e+000,1.034660e-001,1.034660e-001,5.962197e+000,-4.680634e-003,-4.680634e-003,2.733985e-006,2.733985e-006,,,,,,,,,,,,,,,,,,,,
1524691486.690,,0.000000e+000,5.499708e+001,5.499971e+001,1,0,3.096774e+000,0.000000e+000,5.977874e+000,5.977874e+000,5.338001e-002,1.827621e-002,6.006621e+000,8.212662e-002,4.702282e-002,5.523907e-007,5.523907e-007,,,,,,,,,,,,,,,,,,,,
1524691511.860,,0.000000e+000,5.499577e+001,5.499971e+001,1,0,2.064516e+000,0.000000e+000,5.980011e+000,5.980011e+000,3.756959e-002,1.026249e-002,5.937320e+000,-5.121162e-003,-3.242826e-002,5.459588e-007,5.459588e-007,,,,,,,,,,,,,,,,,,,,
1524691536.720,,0.000000e+000,5.499708e+001,5.500367e+001,1,0,1.032258e+000,0.000000e+000,5.880522e+000,5.880522e+000,-7.199331e-002,-8.391666e-002,5.927341e+000,-2.517458e-002,-3.709793e-002,-1.543463e-006,-1.543463e-006,,,,,,,,,,,,,,,,,,,,
1524691561.750,,0.000000e+000,5.499051e+001,5.500103e+001,1,0,0.000000e+000,0.000000e+000,6.070954e+000,6.070954e+000,1.050272e-001,1.050272e-001,5.961390e+000,-4.537582e-003,-4.537582e-003,2.846733e-006,2.846733e-006,,,,,,,,,,,,,,,,,,,,
1524691573.900,,0.000000e+000,5.499839e+001,5.499314e+001,1,0,3.096774e+000,0.000000e+000,5.980163e+000,5.980163e+000,4.835593e-002,2.491140e-002,6.004478e+000,7.267081e-002,4.922628e-002,5.541951e-007,5.541951e-007,,,,,,,,,,,,,,,,,,,,
1524691598.980,,0.000000e+000,5.500497e+001,5.499708e+001,1,0,2.064516e+000,0.000000e+000,5.925231e+000,5.925231e+000,3.797272e-002,1.008940e-002,5.881012e+000,-6.246297e-003,-3.412962e-002,5.862676e-007,5.862676e-007,,,,,,,,,,,,,,,,,,,,
1524691624.000,,0.000000e+000,5.498788e+001,5.499708e+001,1,0,1.032258e+000,0.000000e+000,5.741970e+000,5.741970e+000,-7.327224e-002,-9.101486e-002,5.792940e+000,-2.230217e-002,-4.004478e-002,-1.481123e-006,-1.481123e-006,,,,,,,,,,,,,,,,,,,,
1524691649.360,,0.000000e+000,5.499577e+001,5.499839e+001,1,0,0.000000e+000,0.000000e+000,5.857481e+000,5.857481e+000,1.043158e-001,1.043158e-001,5.748778e+000,-4.386902e-003,-4.386902e-003,2.943241e-006,2.943241e-006,,,,,,,,,,,,,,,,,,,,
1524691662.001,,0.000000e+000,5.499577e+001,5.499314e+001,1,0,3.096774e+000,0.000000e+000,5.719997e+000,5.719997e+000,5.044590e-002,-6.799698e-004,5.752464e+000,8.291231e-002,3.178644e-002,3.993628e-007,3.993628e-007,,,,,,,,,,,,,,,,,,,,
1524691687.311,,0.000000e+000,5.499577e+001,5.499314e+001,1,0,2.064516e+000,0.000000e+000,5.671473e+000,5.671473e+000,9.877881e-003,-2.070045e-002,5.651618e+000,-9.977141e-003,-4.055548e-002,-6.594928e-008,-6.594928e-008,,,,,,,,,,,,,,,,,,,,
1524691711.941,,0.000000e+000,5.499839e+001,5.499445e+001,1,0,1.032258e+000,0.000000e+000,5.615473e+000,5.615473e+000,-6.934904e-002,-8.460569e-002,5.660033e+000,-2.478908e-002,-4.004574e-002,-1.437205e-006,-1.437205e-006,,,,,,,,,,,,,,,,,,,,
1524691737.231,,0.000000e+000,5.500103e+001,5.499971e+001,1,0,0.000000e+000,0.000000e+000,5.781338e+000,5.781338e+000,8.116579e-002,8.116579e-002,5.695775e+000,-4.397392e-003,-4.397392e-003,2.240733e-006,2.240733e-006,,,,,,,,,,,,,,,,,,,,
1524691749.601,,0.000000e+000,5.499314e+001,5.499445e+001,1,0,3.096774e+000,0.000000e+000,5.723812e+000,5.723812e+000,5.345132e-002,2.497101e-002,5.745361e+000,7.500007e-002,4.651976e-002,6.266055e-007,6.266055e-007,,,,,,,,,,,,,,,,,,,,
1524691774.811,,0.000000e+000,5.500103e+001,5.499839e+001,1,0,2.064516e+000,0.000000e+000,5.715267e+000,5.715267e+000,3.432095e-002,9.767056e-003,5.673326e+000,-7.619742e-003,-3.217363e-002,4.964822e-007,4.964822e-007,,,,,,,,,,,,,,,,,,,,
1524691804.273,,0.000000e+000,5.499445e+001,5.499445e+001,1,0,1.032258e+000,0.000000e+000,5.629358e+000,5.629358e+000,-6.588461e-002,-6.009102e-002,5.695190e+000,-5.295360e-005,5.740643e-003,-1.509121e-006,-1.509121e-006,,,,,,,,,,,,,,,,,,,,
1524691830.255,,0.000000e+000,5.499971e+001,5.499708e+001,1,0,0.000000e+000,0.000000e+000,5.821622e+000,5.821622e+000,1.054525e-001,1.054525e-001,5.711843e+000,-4.325867e-003,-4.325867e-003,2.847955e-006,2.847955e-006,,,,,,,,,,,,,,,,,,,,
1524691843.015,,0.000000e+000,5.499445e+001,5.499971e+001,1,0,3.096774e+000,0.000000e+000,5.731747e+000,5.731747e+000,5.792406e-002,2.479601e-002,5.756048e+000,8.222511e-002,4.909706e-002,6.644404e-007,6.644404e-007,,,,,,,,,,,,,,,,,,,,
1524691868.215,,0.000000e+000,5.499971e+001,5.499445e+001,1,0,2.064516e+000,0.000000e+000,5.714199e+000,5.714199e+000,2.886982e-002,8.296967e-004,5.678608e+000,-6.720833e-003,-3.476095e-002,3.446185e-007,3.446185e-007,,,,,,,,,,,,,,,,,,,,
1524691893.325,,0.000000e+000,5.500103e+001,5.500235e+001,1,0,1.032258e+000,0.000000e+000,5.616999e+000,5.616999e+000,-8.658642e-002,-1.008492e-001,5.679629e+000,-2.395577e-002,-3.821850e-002,-1.833076e-006,-1.833076e-006,,,,,,,,,,,,,,,,,,,,
1524691922.319,,0.000000e+000,5.499182e+001,5.499577e+001,1,0,0.000000e+000,0.000000e+000,5.812314e+000,5.812314e+000,1.257029e-001,1.257029e-001,5.693373e+000,6.761551e-003,6.761551e-003,2.581219e-006,2.581219e-006,,,,,,,,,,,,,,,,,,,,
1524691936.401,,0.000000e+000,5.500235e+001,5.498788e+001,1,0,3.096774e+000,0.000000e+000,5.724575e+000,5.724575e+000,1.602862e-002,3.989220e-002,5.711147e+000,2.600411e-003,2.646399e-002,5.259935e-007,5.259935e-007,,,,,,,,,,,,,,,,,,,,
1524691963.283,,0.000000e+000,5.499577e+001,5.499971e+001,1,0,2.064516e+000,0.000000e+000,5.720913e+000,5.720913e+000,1.781635e-002,3.348589e-002,5.684106e+000,-1.899024e-002,-3.320694e-003,4.477042e-007,4.477042e-007,,,,,,,,,,,,,,,,,,,,
1524691991.157,,0.000000e+000,5.500235e+001,5.499314e+001,1,0,1.032258e+000,0.000000e+000,5.640650e+000,5.640650e+000,-7.476123e-002,-6.500816e-002,5.715352e+000,-5.943701e-005,9.693623e-003,-1.756969e-006,-1.756969e-006,,,,,,,,,,,,,,,,,,,,
1524692019.441,,0.000000e+000,5.499445e+001,5.500235e+001,1,0,0.000000e+000,0.000000e+000,5.875792e+000,5.875792e+000,1.431394e-001,1.431394e-001,5.740543e+000,7.890224e-003,7.890224e-003,2.997753e-006,2.997753e-006,,,,,,,,,,,,,,,,,,,,
1524692033.573,,0.000000e+000,5.499577e+001,5.500892e+001,1,0,3.096774e+000,0.000000e+000,5.785000e+000,5.785000e+000,1.790898e-002,3.552294e-002,5.769902e+000,2.810413e-003,2.042437e-002,5.384209e-007,5.384209e-007,,,,,,,,,,,,,,,,,,,,
1524692062.107,,0.000000e+000,5.499708e+001,5.499314e+001,1,0,2.064516e+000,0.000000e+000,5.762264e+000,5.762264e+000,-4.877018e-003,1.158381e-002,5.740631e+000,-2.651064e-002,-1.004982e-002,-4.243338e-008,-4.243338e-008,,,,,,,,,,,,,,,,,,,,
1524692090.191,,0.000000e+000,5.499445e+001,5.499051e+001,1,0,1.032258e+000,0.000000e+000,5.684443e+000,5.684443e+000,-9.417950e-002,-8.748007e-002,5.778565e+000,-5.804934e-005,6.641388e-003,-2.149376e-006,-2.149376e-006,,,,,,,,,,,,,,,,,,,,
1524692116.953,,0.000000e+000,5.499314e+001,5.499445e+001,1,0,0.000000e+000,0.000000e+000,5.917754e+000,5.917754e+000,1.034365e-001,1.034365e-001,5.809208e+000,-5.108833e-003,-5.108833e-003,3.027060e-006,3.027060e-006,,,,,,,,,,,,,,,,,,,,
1524692131.315,,0.000000e+000,5.499445e+001,5.499577e+001,1,0,3.096774e+000,0.000000e+000,5.797360e+000,5.797360e+000,1.587433e-002,3.482199e-002,5.784421e+000,2.934880e-003,2.188253e-002,5.019538e-007,5.019538e-007,,,,,,,,,,,,,,,,,,,,
1524692157.337,,0.000000e+000,5.499182e+001,5.500103e+001,1,0,2.064516e+000,0.000000e+000,5.795681e+000,5.795681e+000,1.097403e-002,2.502298e-002,5.763875e+000,-2.083196e-002,-6.783009e-003,2.981396e-007,2.981396e-007,,,,,,,,,,,,,,,,,,,,
1524692186.051,,0.000000e+000,5.500103e+001,5.499839e+001,1,0,1.032258e+000,0.000000e+000,5.707485e+000,5.707485e+000,-7.668467e-002,-6.839609e-002,5.784103e+000,-6.647408e-005,8.222103e-003,-1.773471e-006,-1.773471e-006,,,,,,,,,,,,,,,,,,,,
1524692214.365,,0.000000e+000,5.500367e+001,5.499971e+001,1,0,0.000000e+000,0.000000e+000,5.906004e+000,5.906004e+000,1.216822e-001,1.216822e-001,5.791571e+000,7.248878e-003,7.248878e-003,2.536690e-006,2.536690e-006,,,,,,,,,,,,,,,,,,,,
1524692228.577,,0.000000e+000,5.500235e+001,5.499839e+001,1,0,3.096774e+000,0.000000e+000,5.830015e+000,5.830015e+000,1.424112e-002,3.611517e-002,5.818676e+000,2.901933e-003,2.477598e-002,4.803587e-007,4.803587e-007,,,,,,,,,,,,,,,,,,,,
1524692257.081,,0.000000e+000,5.500103e+001,5.500235e+001,1,0,2.064516e+000,0.000000e+000,5.795529e+000,5.795529e+000,-1.057893e-002,3.499031e-003,5.781307e+000,-2.480108e-002,-1.072311e-002,-1.747976e-007,-1.747976e-007,,,,,,,,,,,,,,,,,,,,
1524692271.463,,0.000000e+000,5.499971e+001,5.499839e+001,1,0,4.000000e+000,0.000000e+000,5.820554e+000,5.820554e+000,-1.841015e-004,1.987600e-002,5.829634e+000,8.896308e-003,2.895641e-002,2.032612e-007,2.032612e-007,,,,,,,,,,,,,,,,,,,,