File: Experimental Raw Data/TC04-12-01K TRMac VRMde/Raw/TC04-12-01K_TRMac_56K_0.12Kmin_VRMde_55K.dc.raw
[Header]
TITLE,MPMS DC Measurement
BYAPP,MPMS Measurement,2.1,Raw with ABS
FILEOPENTIME, 1524607502.635000 4/24/2018, 4:05:02 PM

INFO, APPNAME, MPMS MultiVu Application, Revision 1.61,  Build 082

INFO, NAME, TC04-12-01K
INFO, WEIGHT, 1.000
INFO, AREA, 1.000
INFO, LENGTH, 1.000
INFO, SHAPE, 0
INFO, COMMENT,
INFO, SEQUENCE FILE: TRMac_56K_0.12Kmin_VRMde_55K.seq


INFO, BACKGROUND DATA FILE:, None


STARTUPAXIS,X,8,LINEAR,AUTO,0.000000,0.000000
STARTUPAXIS,Y1,10,LINEAR,AUTO,0.000000,0.000000


STARTUPGROUP,Longitudinal
FIELDGROUP,Longitudinal,1,3,4,5,6,8,9,10,11,12,13,14,15,16,17,18,19,20,21,22,23
FIELDGROUP,Transverse,1,3,4,5,6,8,9,24,25,26,27,28,29,30,31,32,33,34,35,36,37

PLOT_APPEARANCE,ALL,HORZ_GRID_ON,VERT_GRID_ON,MARKERS_ONLY

[Data]
Time,Comment,Field (Oe),Start Temperature (K),End Temperature (K),Scan,Rejected,Position (cm),Rot Position (deg),Long Voltage,Long Average Voltage,Long Detrended Voltage,Long Demeaned Voltage,Long Regression Fit,Long Detrended Fit,Long Demeaned Fit,Long Scaled Response,Long Avg. Scaled Response,Long Background Response,Long Response [w/ABS],Long Detrended Resp. [w/ABS],Long Fit [w/ABS],Long Detrended Fit [w/ABS],Trans Voltage,Trans Average Voltage,Trans Detrended Voltage,Trans Demeaned Voltage,Trans Regression Fit,Trans Detrended Fit,Trans Demeaned Fit,Trans Scaled Response,Trans Avg Scaled Response,Trans Background Response,Trans Response [w/ABS],Trans Detrended Resp. [w/ABS],Trans Fit [w/ABS],Trans Detrended Fit [w/ABS],
1524607502.625,,0.000000e+000,5.499577e+001,5.499971e+001,1,0,0.000000e+000,0.000000e+000,3.876250e+000,3.876250e+000,2.250409e-002,2.250409e-002,3.719873e+000,-1.338725e-001,-1.338725e-001,-6.184171e-006,-6.184171e-006,,,,,,,,,,,,,,,,,,,,
1524607502.625,,0.000000e+000,5.499577e+001,5.499971e+001,1,0,3.354839e+000,0.000000e+000,4.415808e+000,4.415808e+000,-9.839193e-002,5.620627e-001,4.383669e+000,-1.305312e-001,5.299234e-001,6.963528e-007,6.963528e-007,,,,,,,,,,,,,,,,,,,,
1524607515.625,,0.000000e+000,5.499708e+001,5.499314e+001,1,0,2.580645e+000,0.000000e+000,4.556039e+000,4.556039e+000,2.119157e-001,6.350186e-001,4.587204e+000,2.430809e-001,6.661837e-001,5.238704e-006,5.238704e-006,,,,,,,,,,,,,,,,,,,,
1524607528.385,,0.000000e+000,5.498919e+001,5.498919e+001,1,0,1.806452e+000,0.000000e+000,4.502174e+000,4.502174e+000,2.907030e-001,5.697436e-001,4.487333e+000,2.758619e-001,5.549026e-001,5.323294e-006,5.323294e-006,,,,,,,,,,,,,,,,,,,,
1524607540.695,,0.000000e+000,5.498919e+001,5.499445e+001,1,0,1.032258e+000,0.000000e+000,4.038910e+000,4.038910e+000,-8.248159e-002,6.013870e-002,4.076842e+000,-4.455015e-002,9.807014e-002,-4.454603e-006,-4.454603e-006,,,,,,,,,,,,,,,,,,,,
1524607553.255,,0.000000e+000,5.499839e+001,5.499314e+001,1,0,2.580645e-001,0.000000e+000,3.935454e+000,3.935454e+000,-1.108229e-001,-7.815838e-002,3.939050e+000,-1.072270e-001,-7.456255e-002,-6.236151e-006,-6.236151e-006,,,,,,,,,,,,,,,,,,,,
1524607553.255,,0.000000e+000,5.499839e+001,5.499314e+001,1,0,3.612903e+000,0.000000e+000,4.381933e+000,4.381933e+000,-8.898243e-002,3.683205e-001,4.356456e+000,-1.144594e-001,3.428435e-001,2.678280e-007,2.678280e-007,,,,,,,,,,,,,,,,,,,,
1524607565.885,,0.000000e+000,5.499839e+001,5.498788e+001,1,0,2.838710e+000,0.000000e+000,4.462043e+000,4.462043e+000,8.622748e-002,4.209003e-001,4.471200e+000,9.538371e-002,4.300566e-001,2.718079e-006,2.718079e-006,,,,,,,,,,,,,,,,,,,,
1524607578.765,,0.000000e+000,5.499577e+001,5.499051e+001,1,0,2.064516e+000,0.000000e+000,4.531014e+000,4.531014e+000,2.293248e-001,4.476533e-001,4.537192e+000,2.355032e-001,4.538317e-001,4.664791e-006,4.664791e-006,,,,,,,,,,,,,,,,,,,,
1524607591.305,,0.000000e+000,5.499051e+001,5.500497e+001,1,0,1.290323e+000,0.000000e+000,4.265507e+000,4.265507e+000,3.152238e-002,1.603923e-001,4.255626e+000,2.164183e-002,1.505117e-001,-8.107600e-007,-8.107600e-007,,,,,,,,,,,,,,,,,,,,
1524607604.055,,0.000000e+000,5.500497e+001,5.498788e+001,1,0,5.161290e-001,0.000000e+000,4.046082e+000,4.046082e+000,-1.371137e-001,-8.994341e-002,4.087747e+000,-9.544861e-002,-4.827833e-002,-5.441019e-006,-5.441019e-006,,,,,,,,,,,,,,,,,,,,
1524607604.055,,0.000000e+000,5.500497e+001,5.498788e+001,1,0,3.870968e+000,0.000000e+000,4.381323e+000,4.381323e+000,-1.084796e-001,2.452974e-001,4.393450e+000,-9.635225e-002,2.574248e-001,-5.776674e-007,-5.776674e-007,,,,,,,,,,,,,,,,,,,,
1524607616.585,,0.000000e+000,5.498788e+001,5.500235e+001,1,0,3.096774e+000,0.000000e+000,4.451972e+000,4.451972e+000,2.425876e-002,2.992954e-001,4.445793e+000,1.807943e-002,2.931161e-001,1.418302e-006,1.418302e-006,,,,,,,,,,,,,,,,,,,,
1524607629.005,,0.000000e+000,5.500235e+001,5.499839e+001,1,0,2.322581e+000,0.000000e+000,4.540322e+000,4.540322e+000,1.785232e-001,3.677034e-001,4.557608e+000,1.958090e-001,3.849893e-001,3.885187e-006,3.885187e-006,,,,,,,,,,,,,,,,,,,,
1524607641.855,,0.000000e+000,5.499839e+001,5.499577e+001,1,0,1.548387e+000,0.000000e+000,4.369879e+000,4.369879e+000,8.466415e-002,1.940212e-001,4.341594e+000,5.637913e-002,1.657362e-001,1.052249e-006,1.052249e-006,,,,,,,,,,,,,,,,,,,,
1524607654.005,,0.000000e+000,5.499577e+001,5.499708e+001,1,0,7.741935e-001,0.000000e+000,4.118868e+000,4.118868e+000,-1.146420e-001,-5.661964e-002,4.159814e+000,-7.369548e-002,-1.567316e-002,-4.223213e-006,-4.223213e-006,,,,,,,,,,,,,,,,,,,,
1524607666.475,,0.000000e+000,5.499314e+001,5.499839e+001,1,0,0.000000e+000,0.000000e+000,4.488289e+000,4.488289e+000,7.594824e-002,7.594824e-002,4.372909e+000,-3.943157e-002,-3.943157e-002,-1.123408e-008,-1.123408e-008,,,,,,,,,,,,,,,,,,,,
1524607666.475,,0.000000e+000,5.499314e+001,5.499839e+001,1,0,3.354839e+000,0.000000e+000,4.567788e+000,4.567788e+000,-1.350031e-002,1.554475e-001,4.557676e+000,-2.361212e-002,1.453357e-001,1.985172e-007,1.985172e-007,,,,,,,,,,,,,,,,,,,,
1524607679.115,,0.000000e+000,5.499839e+001,5.500367e+001,1,0,2.580645e+000,0.000000e+000,4.367895e+000,4.367895e+000,1.191039e-001,2.772422e-001,4.386724e+000,1.379323e-001,2.960706e-001,2.741130e-006,2.741130e-006,,,,,,,,,,,,,,,,,,,,
1524607691.605,,0.000000e+000,5.499577e+001,5.500235e+001,1,0,1.806452e+000,0.000000e+000,4.310521e+000,4.310521e+000,1.208839e-001,2.363405e-001,4.282526e+000,9.288926e-002,2.083459e-001,2.174638e-006,2.174638e-006,,,,,,,,,,,,,,,,,,,,
1524607704.255,,0.000000e+000,5.499708e+001,5.500235e+001,1,0,1.032258e+000,0.000000e+000,4.054780e+000,4.054780e+000,-9.258021e-002,-3.110027e-002,4.100994e+000,-4.636659e-002,1.511335e-002,-3.188718e-006,-3.188718e-006,,,,,,,,,,,,,,,,,,,,
1524607716.215,,0.000000e+000,5.499708e+001,5.499971e+001,1,0,2.580645e-001,0.000000e+000,4.070344e+000,4.070344e+000,-4.038910e-002,-2.507114e-002,4.064355e+000,-4.637770e-002,-3.105974e-002,-2.626562e-006,-2.626562e-006,,,,,,,,,,,,,,,,,,,,
1524607716.215,,0.000000e+000,5.499708e+001,5.499971e+001,1,0,3.612903e+000,0.000000e+000,4.279240e+000,4.279240e+000,-3.062633e-002,1.838250e-001,4.262557e+000,-4.730943e-002,1.671419e-001,2.524903e-007,2.524903e-007,,,,,,,,,,,,,,,,,,,,
1524607728.955,,0.000000e+000,5.500629e+001,5.499708e+001,1,0,2.838710e+000,0.000000e+000,4.332342e+000,4.332342e+000,6.794337e-002,2.267199e-001,4.347197e+000,8.279876e-002,2.415752e-001,1.786917e-006,1.786917e-006,,,,,,,,,,,,,,,,,,,,
1524607741.195,,0.000000e+000,5.500235e+001,5.500235e+001,1,0,2.064516e+000,0.000000e+000,4.371099e+000,4.371099e+000,1.387155e-001,2.539287e-001,4.346499e+000,1.141150e-001,2.293282e-001,2.824687e-006,2.824687e-006,,,,,,,,,,,,,,,,,,,,
1524607753.875,,0.000000e+000,5.500235e+001,5.499314e+001,1,0,1.290323e+000,0.000000e+000,4.151827e+000,4.151827e+000,-4.351779e-002,2.141666e-002,4.178465e+000,-1.688024e-002,4.805422e-002,-1.759196e-006,-1.759196e-006,,,,,,,,,,,,,,,,,,,,
1524607766.895,,0.000000e+000,5.499577e+001,5.499971e+001,1,0,5.161290e-001,0.000000e+000,4.086519e+000,4.086519e+000,-8.292783e-002,-5.835247e-002,4.121487e+000,-4.795993e-002,-2.338457e-002,-3.060704e-006,-3.060704e-006,,,,,,,,,,,,,,,,,,,,
1524607766.895,,0.000000e+000,5.499577e+001,5.499971e+001,1,0,3.870968e+000,0.000000e+000,4.302434e+000,4.302434e+000,-2.675248e-002,1.575627e-001,4.278003e+000,-5.118371e-002,1.331315e-001,2.036832e-007,2.036832e-007,,,,,,,,,,,,,,,,,,,,
1524607779.455,,0.000000e+000,5.499445e+001,5.499445e+001,1,0,3.096774e+000,0.000000e+000,4.334630e+000,4.334630e+000,3.369183e-002,1.799135e-001,4.345104e+000,4.416509e-002,1.903868e-001,1.081062e-006,1.081062e-006,,,,,,,,,,,,,,,,,,,,
1524607791.985,,0.000000e+000,5.499839e+001,5.498656e+001,1,0,2.322581e+000,0.000000e+000,4.385290e+000,4.385290e+000,1.159642e-001,2.185297e-001,4.387392e+000,1.180661e-001,2.206316e-001,2.446017e-006,2.446017e-006,,,,,,,,,,,,,,,,,,,,
1524607804.595,,0.000000e+000,5.498656e+001,5.499577e+001,1,0,1.548387e+000,0.000000e+000,4.272374e+000,4.272374e+000,2.791590e-002,9.706879e-002,4.259777e+000,1.531882e-002,8.447170e-002,8.224742e-008,8.224742e-008,,,,,,,,,,,,,,,,,,,,
1524607817.695,,0.000000e+000,5.499314e+001,5.500497e+001,1,0,7.741935e-001,0.000000e+000,4.127565e+000,4.127565e+000,-9.271728e-002,-6.226683e-002,4.171582e+000,-4.870091e-002,-1.825047e-002,-2.945802e-006,-2.945802e-006,,,,,,,,,,,,,,,,,,,,
1524607830.005,,0.000000e+000,5.499708e+001,5.499971e+001,1,0,0.000000e+000,0.000000e+000,4.297704e+000,4.297704e+000,1.021194e-001,1.021194e-001,4.176067e+000,-1.951694e-002,-1.951694e-002,9.519281e-007,9.519281e-007,,,,,,,,,,,,,,,,,,,,
1524607830.005,,0.000000e+000,5.499708e+001,5.499971e+001,1,0,3.354839e+000,0.000000e+000,4.334783e+000,4.334783e+000,-1.649880e-003,1.391988e-001,4.341082e+000,4.649139e-003,1.454978e-001,3.966416e-007,3.966416e-007,,,,,,,,,,,,,,,,,,,,
1524607842.965,,0.000000e+000,5.499577e+001,5.499708e+001,1,0,2.580645e+000,0.000000e+000,4.385443e+000,4.385443e+000,7.618817e-002,1.647501e-001,4.404810e+000,9.555586e-002,1.841178e-001,1.680717e-006,1.680717e-006,,,,,,,,,,,,,,,,,,,,
1524607855.605,,0.000000e+000,5.499577e+001,5.500235e+001,1,0,1.806452e+000,0.000000e+000,4.355535e+000,4.355535e+000,6.813961e-002,1.363516e-001,4.325526e+000,3.813081e-002,1.063428e-001,1.176901e-006,1.176901e-006,,,,,,,,,,,,,,,,,,,,
1524607868.365,,0.000000e+000,5.499971e+001,5.499971e+001,1,0,1.032258e+000,0.000000e+000,4.165102e+000,4.165102e+000,-9.852654e-002,-6.353283e-002,4.222366e+000,-4.126316e-002,-6.269455e-003,-2.854547e-006,-2.854547e-006,,,,,,,,,,,,,,,,,,,,
1524607881.275,,0.000000e+000,5.499971e+001,5.500761e+001,1,0,2.580645e-001,0.000000e+000,4.250858e+000,4.250858e+000,2.544325e-003,1.093626e-002,4.225591e+000,-2.272280e-002,-1.433086e-002,-8.617062e-007,-8.617062e-007,,,,,,,,,,,,,,,,,,,,
1524607881.275,,0.000000e+000,5.499971e+001,5.500761e+001,1,0,3.612903e+000,0.000000e+000,4.359655e+000,4.359655e+000,2.246238e-003,1.197333e-001,4.343341e+000,-1.406779e-002,1.034193e-001,4.056055e-007,4.056055e-007,,,,,,,,,,,,,,,,,,,,
1524607893.355,,0.000000e+000,5.500761e+001,5.499445e+001,1,0,2.838710e+000,0.000000e+000,4.394141e+000,4.394141e+000,5.634464e-002,1.439748e-001,4.416057e+000,7.826055e-002,1.658907e-001,1.292283e-006,1.292283e-006,,,,,,,,,,,,,,,,,,,,
1524607905.545,,0.000000e+000,5.500761e+001,5.499182e+001,1,0,2.064516e+000,0.000000e+000,4.397955e+000,4.397955e+000,8.201583e-002,1.448636e-001,4.372464e+000,5.652459e-002,1.193724e-001,1.598906e-006,1.598906e-006,,,,,,,,,,,,,,,,,,,,
1524607918.065,,0.000000e+000,5.499708e+001,5.499971e+001,1,0,1.290323e+000,0.000000e+000,4.259098e+000,4.259098e+000,-4.425051e-002,-1.176119e-002,4.275893e+000,-2.745583e-002,5.033493e-003,-1.431603e-006,-1.431603e-006,,,,,,,,,,,,,,,,,,,,
1524607930.155,,0.000000e+000,5.498788e+001,5.499577e+001,1,0,5.161290e-001,0.000000e+000,4.227817e+000,4.227817e+000,-5.456379e-002,-3.885126e-002,4.251627e+000,-3.075388e-002,-1.504135e-002,-1.988694e-006,-1.988694e-006,,,,,,,,,,,,,,,,,,,,
1524607930.155,,0.000000e+000,5.498788e+001,5.499577e+001,1,0,3.870968e+000,0.000000e+000,4.373846e+000,4.373846e+000,-1.066622e-002,1.071777e-001,4.351988e+000,-3.252396e-002,8.532000e-002,2.055313e-007,2.055313e-007,,,,,,,,,,,,,,,,,,,,
1524607942.925,,0.000000e+000,5.500497e+001,5.501024e+001,1,0,3.096774e+000,0.000000e+000,4.387884e+000,4.387884e+000,2.871628e-002,9.792852e-002,4.407976e+000,4.880829e-002,1.180205e-001,6.316695e-007,6.316695e-007,,,,,,,,,,,,,,,,,,,,
1524607955.285,,0.000000e+000,5.499839e+001,5.499839e+001,1,0,2.322581e+000,0.000000e+000,4.426490e+000,4.426490e+000,8.046762e-002,1.383977e-001,4.421596e+000,7.557384e-002,1.335039e-001,1.641645e-006,1.641645e-006,,,,,,,,,,,,,,,,,,,,
1524607967.985,,0.000000e+000,5.499971e+001,5.500235e+001,1,0,1.548387e+000,0.000000e+000,4.325322e+000,4.325322e+000,-2.248194e-003,3.148270e-002,4.317356e+000,-1.021424e-002,2.351665e-002,-4.062022e-007,-4.062022e-007,,,,,,,,,,,,,,,,,,,,
1524607980.245,,0.000000e+000,5.500235e+001,5.499708e+001,1,0,7.741935e-001,0.000000e+000,4.236668e+000,4.236668e+000,-7.801415e-002,-6.054831e-002,4.281109e+000,-3.357293e-002,-1.610708e-002,-2.260233e-006,-2.260233e-006,,,,,,,,,,,,,,,,,,,,
1524607992.795,,0.000000e+000,5.499971e+001,5.499445e+001,1,0,0.000000e+000,0.000000e+000,4.395819e+000,4.395819e+000,9.310675e-002,9.310675e-002,4.291513e+000,-1.119900e-002,-1.119900e-002,1.547873e-006,1.547873e-006,,,,,,,,,,,,,,,,,,,,
1524607992.795,,0.000000e+000,5.499971e+001,5.499445e+001,1,0,3.354839e+000,0.000000e+000,4.367132e+000,4.367132e+000,5.616555e-003,6.441975e-002,4.391876e+000,3.036059e-002,8.916378e-002,3.312016e-008,3.312016e-008,,,,,,,,,,,,,,,,,,,,
1524608005.505,,0.000000e+000,5.499971e+001,5.499577e+001,1,0,2.580645e+000,0.000000e+000,4.394598e+000,4.394598e+000,4.904339e-002,9.997606e-002,4.427175e+000,8.161995e-002,1.325526e-001,9.579089e-007,9.579089e-007,,,,,,,,,,,,,,,,,,,,
1524608018.175,,0.000000e+000,5.499577e+001,5.499971e+001,1,0,1.806452e+000,0.000000e+000,4.372168e+000,4.372168e+000,3.675903e-002,6.559706e-002,4.344420e+000,9.011404e-003,3.784943e-002,5.437178e-007,5.437178e-007,,,,,,,,,,,,,,,,,,,,
1524608030.835,,0.000000e+000,5.499445e+001,5.499971e+001,1,0,1.032258e+000,0.000000e+000,4.245670e+000,4.245670e+000,-7.483766e-002,-5.796766e-002,4.283553e+000,-3.695486e-002,-2.008486e-002,-2.039378e-006,-2.039378e-006,,,,,,,,,,,,,,,,,,,,
1524608043.005,,0.000000e+000,5.499314e+001,5.499577e+001,1,0,2.580645e-001,0.000000e+000,4.329137e+000,4.329137e+000,1.984510e-002,2.372980e-002,4.294499e+000,-1.479331e-002,-1.090860e-002,2.012530e-008,2.012530e-008,,,,,,,,,,,,,,,,,,,,
1524608043.005,,0.000000e+000,5.499314e+001,5.499577e+001,1,0,3.612903e+000,0.000000e+000,4.378119e+000,4.378119e+000,1.832511e-002,7.271099e-002,4.366044e+000,6.250644e-003,6.063652e-002,3.041205e-007,3.041205e-007,,,,,,,,,,,,,,,,,,,,
1524608055.995,,0.000000e+000,5.499839e+001,5.500367e+001,1,0,2.838710e+000,0.000000e+000,4.403601e+000,4.403601e+000,5.587096e-002,8.953333e-002,4.431902e+000,8.417220e-002,1.178346e-001,1.020380e-006,1.020380e-006,,,,,,,,,,,,,,,,,,,,
1524608068.115,,0.000000e+000,5.499445e+001,5.500235e+001,1,0,2.064516e+000,0.000000e+000,4.410925e+000,4.410925e+000,6.900416e-002,9.984589e-002,4.372368e+000,3.044663e-002,6.128836e-002,1.329332e-006,1.329332e-006,,,,,,,,,,,,,,,,,,,,
1524608080.925,,0.000000e+000,5.499577e+001,5.499182e+001,1,0,1.290323e+000,0.000000e+000,4.281071e+000,4.281071e+000,-5.496637e-002,-4.078579e-002,4.302797e+000,-3.324072e-002,-1.906013e-002,-1.505396e-006,-1.505396e-006,,,,,,,,,,,,,,,,,,,,
1524608093.445,,0.000000e+000,5.499182e+001,5.499839e+001,1,0,5.161290e-001,0.000000e+000,4.270237e+000,4.270237e+000,-5.779115e-002,-5.203915e-002,4.313198e+000,-1.483098e-002,-9.078979e-003,-1.578228e-006,-1.578228e-006,,,,,,,,,,,,,,,,,,,,
1524608093.445,,0.000000e+000,5.499182e+001,5.499839e+001,1,0,3.870968e+000,0.000000e+000,4.384985e+000,4.384985e+000,1.956835e-002,6.270838e-002,4.361229e+000,-4.187678e-003,3.895235e-002,2.877787e-007,2.877787e-007,,,,,,,,,,,,,,,,,,,,
1524608105.935,,0.000000e+000,5.499577e+001,5.499708e+001,1,0,3.096774e+000,0.000000e+000,4.398871e+000,4.398871e+000,3.737809e-002,7.247686e-002,4.416267e+000,5.477454e-002,8.987331e-002,7.151975e-007,7.151975e-007,,,,,,,,,,,,,,,,,,,,
1524608118.085,,0.000000e+000,5.499708e+001,5.499708e+001,1,0,2.322581e+000,0.000000e+000,4.426032e+000,4.426032e+000,7.684856e-002,9.982443e-002,4.387031e+000,3.784757e-002,6.082344e-002,1.504013e-006,1.504013e-006,,,,,,,,,,,,,,,,,,,,
1524608130.796,,0.000000e+000,5.499445e+001,5.499839e+001,1,0,1.548387e+000,0.000000e+000,4.307317e+000,4.307317e+000,-3.728841e-002,-2.859831e-002,4.316675e+000,-2.793001e-002,-1.923990e-002,-1.037217e-006,-1.037217e-006,,,,,,,,,,,,,,,,,,,,
1524608143.326,,0.000000e+000,5.499708e+001,5.499971e+001,1,0,7.741935e-001,0.000000e+000,4.258183e+000,4.258183e+000,-7.134603e-002,-5.806255e-002,4.323917e+000,-5.611170e-003,7.672310e-003,-1.925262e-006,-1.925262e-006,,,,,,,,,,,,,,,,,,,,
1524608158.046,,0.000000e+000,5.500235e+001,5.500235e+001,1,0,0.000000e+000,0.000000e+000,4.427558e+000,4.427558e+000,1.241026e-001,1.241026e-001,4.296103e+000,-7.351875e-003,-7.351875e-003,1.966793e-006,1.966793e-006,,,,,,,,,,,,,,,,,,,,
1524608158.046,,0.000000e+000,5.500235e+001,5.500235e+001,1,0,3.354839e+000,0.000000e+000,4.390631e+000,4.390631e+000,1.726212e-003,8.717537e-002,4.381230e+000,-7.674156e-003,7.777500e-002,5.049078e-007,5.049078e-007,,,,,,,,,,,,,,,,,,,,
1524608173.058,,0.000000e+000,5.500103e+001,5.500367e+001,1,0,2.580645e+000,0.000000e+000,4.398566e+000,4.398566e+000,2.914012e-002,8.450890e-002,4.378325e+000,8.899814e-003,6.426859e-002,7.964700e-007,7.964700e-007,,,,,,,,,,,,,,,,,,,,
1524608187.860,,0.000000e+000,5.499577e+001,5.500235e+001,1,0,1.806452e+000,0.000000e+000,4.361486e+000,4.361486e+000,8.759571e-003,4.834890e-002,4.367141e+000,1.441438e-002,5.400372e-002,9.823998e-008,9.823998e-008,,,,,,,,,,,,,,,,,,,,
1524608202.662,,0.000000e+000,5.499708e+001,5.499839e+001,1,0,1.032258e+000,0.000000e+000,4.269475e+000,4.269475e+000,-6.883707e-002,-4.486561e-002,4.338356e+000,4.491769e-005,2.401638e-002,-1.910783e-006,-1.910783e-006,,,,,,,,,,,,,,,,,,,,
1524608216.904,,0.000000e+000,5.499708e+001,5.500235e+001,1,0,2.580645e-001,0.000000e+000,4.368200e+000,4.368200e+000,4.031191e-002,4.561710e-002,4.322534e+000,-5.354309e-003,-4.911423e-005,3.396999e-007,3.396999e-007,,,,,,,,,,,,,,,,,,,,
1524608216.904,,0.000000e+000,5.499708e+001,5.500235e+001,1,0,3.612903e+000,0.000000e+000,4.388494e+000,4.388494e+000,-8.361434e-003,6.591129e-002,4.391355e+000,-5.500888e-003,6.877184e-002,2.794695e-007,2.794695e-007,,,,,,,,,,,,,,,,,,,,
1524608229.024,,0.000000e+000,5.499577e+001,5.499971e+001,1,0,2.838710e+000,0.000000e+000,4.413672e+000,4.413672e+000,3.900164e-002,7.465363e-003,4.421286e+000,4.661530e-002,1.507902e-002,9.217329e-007,9.217329e-007,,,,,,,,,,,,,,,,,,,,
1524608243.806,,0.000000e+000,5.499708e+001,5.500103e+001,1,0,2.064516e+000,0.000000e+000,4.399939e+000,4.399939e+000,3.269698e-002,7.497168e-002,4.381194e+000,1.395204e-002,5.622673e-002,7.194612e-007,7.194612e-007,,,,,,,,,,,,,,,,,,,,
1524608257.908,,0.000000e+000,5.499971e+001,5.499708e+001,1,0,1.290323e+000,0.000000e+000,4.274357e+000,4.274357e+000,-7.704513e-002,-5.126619e-002,4.355148e+000,3.745869e-003,2.952480e-002,-1.959241e-006,-1.959241e-006,,,,,,,,,,,,,,,,,,,,
1524608270.108,,0.000000e+000,5.499445e+001,5.499708e+001,1,0,5.161290e-001,0.000000e+000,4.332799e+000,4.332799e+000,-7.356109e-002,-8.024883e-002,4.334320e+000,-7.204094e-002,-7.872868e-002,-6.160117e-007,-6.160117e-007,,,,,,,,,,,,,,,,,,,,
1524608270.108,,0.000000e+000,5.499445e+001,5.499708e+001,1,0,3.870968e+000,0.000000e+000,4.392920e+000,4.392920e+000,3.002980e-002,-2.012825e-002,4.373183e+000,1.029256e-002,-3.986549e-002,2.607849e-007,2.607849e-007,,,,,,,,,,,,,,,,,,,,
1524608284.360,,0.000000e+000,5.499314e+001,5.500235e+001,1,0,3.096774e+000,0.000000e+000,4.397955e+000,4.397955e+000,1.241390e-002,6.885052e-002,4.383473e+000,-2.068598e-003,5.436802e-002,5.420152e-007,5.420152e-007,,,,,,,,,,,,,,,,,,,,
1524608296.610,,0.000000e+000,5.500761e+001,5.499577e+001,1,0,2.322581e+000,0.000000e+000,4.429084e+000,4.429084e+000,4.898095e-002,1.578522e-002,4.421772e+000,4.166865e-002,8.472919e-003,1.352470e-006,1.352470e-006,,,,,,,,,,,,,,,,,,,,
1524608309.350,,0.000000e+000,5.499445e+001,5.499839e+001,1,0,1.548387e+000,0.000000e+000,4.322728e+000,4.322728e+000,-6.613211e-002,-8.852053e-002,4.326314e+000,-6.254581e-002,-8.493423e-002,-8.781935e-007,-8.781935e-007,,,,,,,,,,,,,,,,,,,,
1524608322.010,,0.000000e+000,5.499839e+001,5.499577e+001,1,0,7.741935e-001,0.000000e+000,4.285649e+000,4.285649e+000,-1.129908e-001,-1.235447e-001,4.290308e+000,-1.083321e-001,-1.188860e-001,-1.593347e-006,-1.593347e-006,,,,,,,,,,,,,,,,,,,,
1524608334.970,,0.000000e+000,5.499577e+001,5.498788e+001,1,0,0.000000e+000,0.000000e+000,4.448768e+000,4.448768e+000,4.507446e-002,4.507446e-002,4.409347e+000,5.653858e-003,5.653858e-003,2.164044e-006,2.164044e-006,,,,,,,,,,,,,,,,,,,,
1524608334.970,,0.000000e+000,5.499577e+001,5.498788e+001,1,0,3.354839e+000,0.000000e+000,4.388494e+000,4.388494e+000,2.286069e-002,-1.519871e-002,4.389082e+000,2.344863e-002,-1.461077e-002,3.517198e-007,3.517198e-007,,,,,,,,,,,,,,,,,,,,
1524608347.330,,0.000000e+000,5.499708e+001,5.499971e+001,1,0,2.580645e+000,0.000000e+000,4.415808e+000,4.415808e+000,4.181577e-002,4.959106e-003,4.423163e+000,4.917051e-002,1.231384e-002,1.048407e-006,1.048407e-006,,,,,,,,,,,,,,,,,,,,
1524608362.002,,0.000000e+000,5.500761e+001,5.499839e+001,1,0,1.806452e+000,0.000000e+000,4.366522e+000,4.366522e+000,5.366370e-003,3.230143e-002,4.363757e+000,2.601191e-003,2.953625e-002,7.076596e-008,7.076596e-008,,,,,,,,,,,,,,,,,,,,
1524608374.422,,0.000000e+000,5.499445e+001,5.499445e+001,1,0,1.032258e+000,0.000000e+000,4.290226e+000,4.290226e+000,-6.876942e-002,-7.115364e-002,4.337309e+000,-2.168700e-002,-2.407122e-002,-1.589171e-006,-1.589171e-006,,,,,,,,,,,,,,,,,,,,
1524608389.194,,0.000000e+000,5.499314e+001,5.500367e+001,1,0,2.580645e-001,0.000000e+000,4.380865e+000,4.380865e+000,4.955672e-002,5.426359e-002,4.329357e+000,-1.951227e-003,2.755642e-003,6.240734e-007,6.240734e-007,,,,,,,,,,,,,,,,,,,,
1524608389.194,,0.000000e+000,5.499314e+001,5.500367e+001,1,0,3.612903e+000,0.000000e+000,4.388952e+000,4.388952e+000,-3.545415e-003,6.235075e-002,4.390493e+000,-2.004754e-003,6.389141e-002,3.489695e-007,3.489695e-007,,,,,,,,,,,,,,,,,,,,
1524608401.294,,0.000000e+000,5.499839e+001,5.499182e+001,1,0,2.838710e+000,0.000000e+000,4.409247e+000,4.409247e+000,5.163795e-002,4.487944e-002,4.420451e+000,6.284219e-002,5.608368e-002,7.809722e-007,7.809722e-007,,,,,,,,,,,,,,,,,,,,
1524608416.106,,0.000000e+000,5.498525e+001,5.500235e+001,1,0,2.064516e+000,0.000000e+000,4.395209e+000,4.395209e+000,2.638907e-002,5.677462e-002,4.369358e+000,5.378202e-004,3.092337e-002,6.027258e-007,6.027258e-007,,,,,,,,,,,,,,,,,,,,
1524608430.098,,0.000000e+000,5.499577e+001,5.500235e+001,1,0,1.290323e+000,0.000000e+000,4.296025e+000,4.296025e+000,-5.815280e-002,-3.705168e-002,4.353961e+000,-2.166107e-004,2.088451e-002,-1.471111e-006,-1.471111e-006,,,,,,,,,,,,,,,,,,,,
1524608444.510,,0.000000e+000,5.500235e+001,5.498919e+001,1,0,5.161290e-001,0.000000e+000,4.346685e+000,4.346685e+000,5.281962e-003,1.327705e-002,4.341618e+000,2.146140e-004,8.209705e-003,-2.233282e-007,-2.233282e-007,,,,,,,,,,,,,,,,,,,,
1524608444.510,,0.000000e+000,5.500235e+001,5.498919e+001,1,0,3.870968e+000,0.000000e+000,4.389257e+000,4.389257e+000,-4.113633e-003,5.584955e-002,4.393572e+000,2.012663e-004,6.016445e-002,3.410241e-007,3.410241e-007,,,,,,,,,,,,,,,,,,,,
1524608456.670,,0.000000e+000,5.499839e+001,5.499445e+001,1,0,3.096774e+000,0.000000e+000,4.380255e+000,4.380255e+000,3.189939e-002,1.260757e-002,4.419649e+000,7.129376e-002,5.200195e-002,2.178276e-007,2.178276e-007,,,,,,,,,,,,,,,,,,,,
1524608471.472,,0.000000e+000,5.499445e+001,5.499708e+001,1,0,2.322581e+000,0.000000e+000,4.408637e+000,4.408637e+000,3.787435e-002,6.971121e-002,4.368038e+000,-2.724516e-003,2.911234e-002,9.198411e-007,9.198411e-007,,,,,,,,,,,,,,,,,,,,
1524608485.414,,0.000000e+000,5.500629e+001,5.499314e+001,1,0,1.548387e+000,0.000000e+000,4.327001e+000,4.327001e+000,-3.586186e-002,-1.684999e-002,4.361270e+000,-1.592534e-003,1.741934e-002,-8.787611e-007,-8.787611e-007,,,,,,,,,,,,,,,,,,,,
1524608521.904,,0.000000e+000,5.499708e+001,5.500497e+001,1,0,7.741935e-001,0.000000e+000,4.290989e+000,4.290989e+000,-1.037273e-001,-1.168656e-001,4.295715e+000,-9.900180e-002,-1.121402e-001,-1.359891e-006,-1.359891e-006,,,,,,,,,,,,,,,,,,,,
1524608534.544,,0.000000e+000,5.500497e+001,5.499708e+001,1,0,0.000000e+000,0.000000e+000,4.453498e+000,4.453498e+000,9.357262e-002,9.357262e-002,4.355997e+000,-3.929138e-003,-3.929138e-003,2.364541e-006,2.364541e-006,,,,,,,,,,,,,,,,,,,,
1524608534.544,,0.000000e+000,5.500497e+001,5.499708e+001,1,0,3.354839e+000,0.000000e+000,4.376593e+000,4.376593e+000,4.061192e-002,1.666689e-002,4.394972e+000,5.899113e-002,3.504610e-002,3.536552e-007,3.536552e-007,,,,,,,,,,,,,,,,,,,,
1524608549.156,,0.000000e+000,5.499708e+001,5.500629e+001,1,0,2.580645e+000,0.000000e+000,4.393988e+000,4.393988e+000,3.193995e-002,6.814432e-002,4.360980e+000,-1.068625e-003,3.513575e-002,8.400821e-007,8.400821e-007,,,,,,,,,,,,,,,,,,,,
1524608561.266,,0.000000e+000,5.500235e+001,5.500103e+001,1,0,1.806452e+000,0.000000e+000,4.342718e+000,4.342718e+000,3.766682e-003,-1.648855e-002,4.316149e+000,-2.280173e-002,-4.305696e-002,-1.174776e-007,-1.174776e-007,,,,,,,,,,,,,,,,,,,,
1524608573.736,,0.000000e+000,5.500103e+001,5.499839e+001,1,0,1.032258e+000,0.000000e+000,4.252079e+000,4.252079e+000,-7.708721e-002,-9.081841e-002,4.304179e+000,-2.498751e-002,-3.871870e-002,-1.630833e-006,-1.630833e-006,,,,,,,,,,,,,,,,,,,,
1524608586.446,,0.000000e+000,5.499971e+001,5.499445e+001,1,0,2.580645e-001,0.000000e+000,4.337072e+000,4.337072e+000,3.760822e-002,3.346634e-002,4.291731e+000,-7.732795e-003,-1.187468e-002,1.278691e-006,1.278691e-006,,,,,,,,,,,,,,,,,,,,
1524608586.446,,0.000000e+000,5.499971e+001,5.499445e+001,1,0,3.612903e+000,0.000000e+000,4.274510e+000,4.274510e+000,2.889068e-002,-2.909565e-002,4.286689e+000,4.106958e-002,-1.691675e-002,-2.667366e-007,-2.667366e-007,,,,,,,,,,,,,,,,,,,,
1524608600.808,,0.000000e+000,5.498919e+001,5.499182e+001,1,0,2.838710e+000,0.000000e+000,4.283513e+000,4.283513e+000,3.063396e-002,5.445099e-002,4.252286e+000,-5.922024e-004,2.322483e-002,7.979397e-007,7.979397e-007,,,,,,,,,,,,,,,,,,,,
1524608612.728,,0.000000e+000,5.500103e+001,5.500103e+001,1,0,2.064516e+000,0.000000e+000,4.213321e+000,4.213321e+000,1.707900e-002,-5.572319e-003,4.187123e+000,-9.119388e-003,-3.177071e-002,1.290173e-007,1.290173e-007,,,,,,,,,,,,,,,,,,,,
1524608625.328,,0.000000e+000,5.499182e+001,5.499839e+001,1,0,1.290323e+000,0.000000e+000,4.109865e+000,4.109865e+000,-7.016023e-002,-8.847713e-002,4.145056e+000,-3.496965e-002,-5.328655e-002,-1.570123e-006,-1.570123e-006,,,,,,,,,,,,,,,,,,,,
1524608637.668,,0.000000e+000,5.499445e+001,5.500629e+001,1,0,5.161290e-001,0.000000e+000,4.150454e+000,4.150454e+000,-1.205139e-002,-1.479435e-002,4.153026e+000,-9.479807e-003,-1.222277e-002,-1.656153e-007,-1.656153e-007,,,,,,,,,,,,,,,,,,,,
1524608637.668,,0.000000e+000,5.499445e+001,5.500629e+001,1,0,3.870968e+000,0.000000e+000,4.185855e+000,4.185855e+000,4.117872e-002,2.060652e-002,4.159445e+000,1.476909e-002,-5.803108e-003,2.916495e-007,2.916495e-007,,,,,,,,,,,,,,,,,,,,
1524608650.598,,0.000000e+000,5.499839e+001,5.498919e+001,1,0,3.096774e+000,0.000000e+000,4.179141e+000,4.179141e+000,4.995323e-002,2.018785e-002,4.209089e+000,7.990098e-002,5.013561e-002,5.185429e-007,5.185429e-007,,,,,,,,,,,,,,,,,,,,
1524608662.978,,0.000000e+000,5.499182e+001,5.499314e+001,1,0,2.322581e+000,0.000000e+000,4.181582e+000,4.181582e+000,5.571949e-002,3.367949e-002,4.144558e+000,1.869547e-002,-3.344536e-003,8.918869e-007,8.918869e-007,,,,,,,,,,,,,,,,,,,,
1524608675.808,,0.000000e+000,5.499839e+001,5.500761e+001,1,0,1.548387e+000,0.000000e+000,4.088045e+000,4.088045e+000,-4.538405e-002,-5.877399e-002,4.099373e+000,-3.405583e-002,-4.744577e-002,-1.144013e-006,-1.144013e-006,,,,,,,,,,,,,,,,,,,,
1524608688.198,,0.000000e+000,5.499314e+001,5.499971e+001,1,0,7.741935e-001,0.000000e+000,4.076295e+000,4.076295e+000,-6.415673e-002,-6.966114e-002,4.123788e+000,-1.666375e-002,-2.216816e-002,-1.360677e-006,-1.360677e-006,,,,,,,,,,,,,,,,,,,,
1524608701.038,,0.000000e+000,5.499314e+001,5.499839e+001,1,0,0.000000e+000,0.000000e+000,4.253300e+000,4.253300e+000,9.922647e-002,9.922647e-002,4.148661e+000,-5.412579e-003,-5.412579e-003,2.584711e-006,2.584711e-006,,,,,,,,,,,,,,,,,,,,
1524608701.038,,0.000000e+000,5.499314e+001,5.499839e+001,1,0,3.354839e+000,0.000000e+000,4.158694e+000,4.158694e+000,3.830032e-002,4.620552e-003,4.191172e+000,7.077865e-002,3.709888e-002,1.367298e-007,1.367298e-007,,,,,,,,,,,,,,,,,,,,
1524608713.428,,0.000000e+000,5.499971e+001,5.500629e+001,1,0,2.580645e+000,0.000000e+000,4.193484e+000,4.193484e+000,6.298409e-002,4.470062e-002,4.175802e+000,4.530201e-002,2.701855e-002,9.960640e-007,9.960640e-007,,,,,,,,,,,,,,,,,,,,
1524608726.288,,0.000000e+000,5.499314e+001,5.500235e+001,1,0,1.806452e+000,0.000000e+000,4.132753e+000,4.132753e+000,-4.419510e-003,-2.505350e-002,4.111311e+000,-2.586192e-002,-4.649591e-002,-3.070163e-007,-3.070163e-007,,,,,,,,,,,,,,,,,,,,
1524608738.688,,0.000000e+000,5.499314e+001,5.499971e+001,1,0,1.032258e+000,0.000000e+000,4.068208e+000,4.068208e+000,-7.791856e-002,-8.547640e-002,4.120440e+000,-2.568677e-002,-3.324461e-002,-1.738590e-006,-1.738590e-006,,,,,,,,,,,,,,,,,,,,
1524608751.468,,0.000000e+000,5.499708e+001,5.499971e+001,1,0,2.580645e-001,0.000000e+000,4.191043e+000,4.191043e+000,3.276043e-002,2.972841e-002,4.150157e+000,-8.125495e-003,-1.115751e-002,1.062770e-006,1.062770e-006,,,,,,,,,,,,,,,,,,,,
1524608751.468,,0.000000e+000,5.499708e+001,5.499971e+001,1,0,3.612903e+000,0.000000e+000,4.152895e+000,4.152895e+000,3.402922e-002,-8.419037e-003,4.164785e+000,4.591915e-002,3.470898e-003,-9.118230e-008,-9.118230e-008,,,,,,,,,,,,,,,,,,,,
1524608763.878,,0.000000e+000,5.499971e+001,5.500892e+001,1,0,2.838710e+000,0.000000e+000,4.185550e+000,4.185550e+000,6.046129e-002,3.040218e-002,4.194529e+000,6.944013e-002,3.938103e-002,8.224160e-007,8.224160e-007,,,,,,,,,,,,,,,,,,,,
1524608776.698,,0.000000e+000,5.499708e+001,5.498919e+001,1,0,2.064516e+000,0.000000e+000,4.179446e+000,4.179446e+000,4.007124e-002,1.482677e-002,4.134762e+000,-4.612692e-003,-2.985716e-002,6.017654e-007,6.017654e-007,,,,,,,,,,,,,,,,,,,,
1524608789.098,,0.000000e+000,5.499445e+001,5.499051e+001,1,0,1.290323e+000,0.000000e+000,4.055543e+000,4.055543e+000,-8.804020e-002,-9.915733e-002,4.113395e+000,-3.018841e-002,-4.130554e-002,-2.009416e-006,-2.009416e-006,,,,,,,,,,,,,,,,,,,,
1524608801.908,,0.000000e+000,5.499577e+001,5.500497e+001,1,0,5.161290e-001,0.000000e+000,4.140535e+000,4.140535e+000,-1.217853e-002,-1.877117e-002,4.141224e+000,-1.148997e-002,-1.808262e-002,-5.631591e-009,-5.631591e-009,,,,,,,,,,,,,,,,,,,,
1524608801.908,,0.000000e+000,5.499577e+001,5.500497e+001,1,0,3.870968e+000,0.000000e+000,4.167086e+000,4.167086e+000,5.722445e-002,7.779598e-003,4.128797e+000,1.893490e-002,-3.050995e-002,3.318710e-007,3.318710e-007,,,,,,,,,,,,,,,,,,,,
1524608814.318,,0.000000e+000,5.500497e+001,5.499839e+001,1,0,3.096774e+000,0.000000e+000,4.174258e+000,4.174258e+000,4.891222e-002,2.787304e-002,4.196852e+000,7.150572e-002,5.046654e-002,5.849870e-007,5.849870e-007,,,,,,,,,,,,,,,,,,,,
1524608827.168,,0.000000e+000,5.500367e+001,5.500367e+001,1,0,2.322581e+000,0.000000e+000,4.158541e+000,4.158541e+000,3.648723e-002,2.153873e-003,4.141891e+000,1.983656e-002,-1.449680e-002,4.072062e-007,4.072062e-007,,,,,,,,,,,,,,,,,,,,
1524608839.619,,0.000000e+000,5.499971e+001,5.499708e+001,1,0,1.548387e+000,0.000000e+000,4.080720e+000,4.080720e+000,-5.190745e-002,-6.502914e-002,4.098541e+000,-3.408710e-002,-4.720879e-002,-1.287292e-006,-1.287292e-006,,,,,,,,,,,,,,,,,,,,
1524608852.379,,0.000000e+000,5.499971e+001,5.500367e+001,1,0,7.741935e-001,0.000000e+000,4.090791e+000,4.090791e+000,-5.750810e-002,-6.824207e-002,4.130198e+000,-1.810132e-002,-2.883530e-002,-1.093780e-006,-1.093780e-006,,,,,,,,,,,,,,,,,,,,
1524608864.919,,0.000000e+000,5.499314e+001,5.499051e+001,1,0,0.000000e+000,0.000000e+000,4.258793e+000,4.258793e+000,1.048365e-001,1.048365e-001,4.149536e+000,-4.420280e-003,-4.420280e-003,2.773944e-006,2.773944e-006,,,,,,,,,,,,,,,,,,,,
1524608864.919,,0.000000e+000,5.499314e+001,5.499051e+001,1,0,3.354839e+000,0.000000e+000,4.145724e+000,4.145724e+000,3.199184e-002,-8.232594e-003,4.183666e+000,6.993425e-002,2.970982e-002,-4.351023e-009,-4.351023e-009,,,,,,,,,,,,,,,,,,,,
1524608877.589,,0.000000e+000,5.499708e+001,5.499445e+001,1,0,2.580645e+000,0.000000e+000,4.180820e+000,4.180820e+000,6.164607e-002,2.905655e-002,4.165076e+000,4.590282e-002,1.331329e-002,8.955976e-007,8.955976e-007,,,,,,,,,,,,,,,,,,,,
1524608890.139,,0.000000e+000,5.500103e+001,5.500629e+001,1,0,1.806452e+000,0.000000e+000,4.110018e+000,4.110018e+000,-1.358308e-002,-3.524780e-002,4.098508e+000,-2.509250e-002,-4.675722e-002,-4.768954e-007,-4.768954e-007,,,,,,,,,,,,,,,,,,,,
1524608902.809,,0.000000e+000,5.499182e+001,5.498656e+001,1,0,1.032258e+000,0.000000e+000,4.059358e+000,4.059358e+000,-7.420246e-002,-9.079933e-002,4.107804e+000,-2.575581e-002,-4.235268e-002,-1.530774e-006,-1.530774e-006,,,,,,,,,,,,,,,,,,,,
1524608915.509,,0.000000e+000,5.498656e+001,5.500235e+001,1,0,2.580645e-001,0.000000e+000,4.149081e+000,4.149081e+000,1.310168e-002,9.819508e-003,4.129337e+000,-6.642243e-003,-9.924412e-003,6.531482e-007,6.531482e-007,,,,,,,,,,,,,,,,,,,,
1524608915.509,,0.000000e+000,5.498656e+001,5.500235e+001,1,0,3.612903e+000,0.000000e+000,4.128328e+000,4.128328e+000,3.501743e-002,-1.093292e-002,4.139349e+000,4.603809e-002,8.773804e-005,-3.470632e-008,-3.470632e-008,,,,,,,,,,,,,,,,,,,,
1524608928.039,,0.000000e+000,5.499577e+001,5.499971e+001,1,0,2.838710e+000,0.000000e+000,4.153353e+000,4.153353e+000,5.593763e-002,1.322079e-002,4.164554e+000,6.713853e-002,2.442169e-002,6.701302e-007,6.701302e-007,,,,,,,,,,,,,,,,,,,,
1524608940.419,,0.000000e+000,5.499971e+001,5.499839e+001,1,0,2.064516e+000,0.000000e+000,4.135042e+000,4.135042e+000,3.258952e-002,8.565426e-003,4.093049e+000,-9.404095e-003,-3.342819e-002,4.581671e-007,4.581671e-007,,,,,,,,,,,,,,,,,,,,
1524608953.239,,0.000000e+000,5.499314e+001,5.500629e+001,1,0,1.290323e+000,0.000000e+000,4.013123e+000,4.013123e+000,-9.570009e-002,-1.153798e-001,4.075805e+000,-3.301747e-002,-5.269718e-002,-2.121975e-006,-2.121975e-006,,,,,,,,,,,,,,,,,,,,
1524608965.669,,0.000000e+000,5.499839e+001,5.499577e+001,1,0,5.161290e-001,0.000000e+000,4.073091e+000,4.073091e+000,-3.795271e-002,-4.492712e-002,4.100397e+000,-1.064663e-002,-1.762104e-002,-5.600741e-007,-5.600741e-007,,,,,,,,,,,,,,,,,,,,
1524608965.669,,0.000000e+000,5.499839e+001,5.499577e+001,1,0,3.870968e+000,0.000000e+000,4.119173e+000,4.119173e+000,5.346343e-002,1.155376e-003,4.088348e+000,2.263829e-002,-2.966976e-002,2.304005e-007,2.304005e-007,,,,,,,,,,,,,,,,,,,,
1524608980.499,,0.000000e+000,5.499445e+001,5.499577e+001,1,0,3.096774e+000,0.000000e+000,4.129244e+000,4.129244e+000,2.136996e-002,4.418802e-002,4.110888e+000,3.014588e-003,2.583265e-002,6.464688e-007,6.464688e-007,,,,,,,,,,,,,,,,,,,,
1524608995.161,,0.000000e+000,5.500367e+001,5.499577e+001,1,0,2.322581e+000,0.000000e+000,4.132753e+000,4.132753e+000,3.540954e-002,4.287672e-002,4.078913e+000,-1.843062e-002,-1.096344e-002,8.573261e-007,8.573261e-007,,,,,,,,,,,,,,,,,,,,
1524609009.163,,0.000000e+000,5.499708e+001,5.499971e+001,1,0,1.548387e+000,0.000000e+000,4.034180e+000,4.034180e+000,-5.781215e-002,-4.774523e-002,4.075932e+000,-1.606076e-002,-5.993843e-003,-1.281514e-006,-1.281514e-006,,,,,,,,,,,,,,,,,,,,
1524609023.105,,0.000000e+000,5.499839e+001,5.499839e+001,1,0,7.741935e-001,0.000000e+000,4.037079e+000,4.037079e+000,-4.391476e-002,-3.982353e-002,4.086479e+000,5.485095e-003,9.576321e-003,-1.031251e-006,-1.031251e-006,,,,,,,,,,,,,,,,,,,,
1524609035.245,,0.000000e+000,5.499708e+001,5.499839e+001,1,0,0.000000e+000,0.000000e+000,4.211948e+000,4.211948e+000,1.023769e-001,1.023769e-001,4.105475e+000,-4.096031e-003,-4.096031e-003,2.970060e-006,2.970060e-006,,,,,,,,,,,,,,,,,,,,
1524609035.245,,0.000000e+000,5.499708e+001,5.499839e+001,1,0,3.354839e+000,0.000000e+000,4.097810e+000,4.097810e+000,5.583367e-002,-1.176071e-002,4.115053e+000,7.307611e-002,5.481720e-003,3.618334e-007,3.618334e-007,,,,,,,,,,,,,,,,,,,,
1524609049.887,,0.000000e+000,5.499839e+001,5.499314e+001,1,0,2.580645e+000,0.000000e+000,4.112459e+000,4.112459e+000,3.013428e-002,4.452133e-002,4.071242e+000,-1.108304e-002,3.304005e-003,7.721246e-007,7.721246e-007,,,,,,,,,,,,,,,,,,,,
1524609063.889,,0.000000e+000,5.499839e+001,5.499839e+001,1,0,1.806452e+000,0.000000e+000,4.050660e+000,4.050660e+000,-1.975359e-002,-1.061726e-002,4.048954e+000,-2.145924e-002,-1.232290e-002,-4.049216e-007,-4.049216e-007,,,,,,,,,,,,,,,,,,,,
1524609078.271,,0.000000e+000,5.499839e+001,5.499314e+001,1,0,1.032258e+000,0.000000e+000,3.993896e+000,3.993896e+000,-6.910621e-002,-6.387091e-002,4.062947e+000,-5.589752e-005,5.179405e-003,-1.570879e-006,-1.570879e-006,,,,,,,,,,,,,,,,,,,,
1524609092.213,,0.000000e+000,5.500367e+001,5.499839e+001,1,0,2.580645e-001,0.000000e+000,4.122377e+000,4.122377e+000,6.699032e-002,6.774712e-002,4.064501e+000,9.113736e-003,9.870529e-003,1.468303e-006,1.468303e-006,,,,,,,,,,,,,,,,,,,,
1524609092.213,,0.000000e+000,5.500367e+001,5.499839e+001,1,0,3.612903e+000,0.000000e+000,4.072022e+000,4.072022e+000,6.797054e-003,1.739216e-002,4.074588e+000,9.362915e-003,1.995802e-002,2.696033e-007,2.696033e-007,,,,,,,,,,,,,,,,,,,,
1524609106.785,,0.000000e+000,5.499314e+001,5.499051e+001,1,0,2.838710e+000,0.000000e+000,4.088197e+000,4.088197e+000,2.600128e-002,3.511667e-002,4.058554e+000,-3.641782e-003,5.473614e-003,6.729824e-007,6.729824e-007,,,,,,,,,,,,,,,,,,,,
1524609120.837,,0.000000e+000,5.499577e+001,5.499839e+001,1,0,2.064516e+000,0.000000e+000,4.061799e+000,4.061799e+000,8.769271e-003,1.696301e-002,4.028080e+000,-2.494932e-002,-1.675558e-002,2.552551e-007,2.552551e-007,,,,,,,,,,,,,,,,,,,,
1524609135.189,,0.000000e+000,5.499577e+001,5.500761e+001,1,0,1.290323e+000,0.000000e+000,3.981384e+000,3.981384e+000,-6.969505e-002,-6.735253e-002,4.041909e+000,-9.169872e-003,-6.827354e-003,-1.513123e-006,-1.513123e-006,,,,,,,,,,,,,,,,,,,,
1524609149.181,,0.000000e+000,5.499577e+001,5.501024e+001,1,0,5.161290e-001,0.000000e+000,4.050813e+000,4.050813e+000,1.287529e-002,1.472282e-002,4.047134e+000,9.196490e-003,1.104403e-002,2.575543e-007,2.575543e-007,,,,,,,,,,,,,,,,,,,,
1524609149.181,,0.000000e+000,5.499577e+001,5.501024e+001,1,0,3.870968e+000,0.000000e+000,4.055543e+000,4.055543e+000,5.596531e-003,1.945305e-002,4.058578e+000,8.631122e-003,2.248764e-002,2.737943e-007,2.737943e-007,,,,,,,,,,,,,,,,,,,,
1524609163.333,,0.000000e+000,5.498788e+001,5.499445e+001,1,0,3.096774e+000,0.000000e+000,4.062104e+000,4.062104e+000,1.243594e-002,3.186369e-002,4.052818e+000,3.150009e-003,2.257776e-002,4.311005e-007,4.311005e-007,,,,,,,,,,,,,,,,,,,,
1524609177.575,,0.000000e+000,5.499577e+001,5.499971e+001,1,0,2.322581e+000,0.000000e+000,4.064546e+000,4.064546e+000,2.329530e-002,3.647566e-002,4.019354e+000,-2.189599e-002,-8.715630e-003,6.079063e-007,6.079063e-007,,,,,,,,,,,,,,,,,,,,
1524609191.747,,0.000000e+000,5.499577e+001,5.499314e+001,1,0,1.548387e+000,0.000000e+000,3.964447e+000,3.964447e+000,-6.245534e-002,-5.547094e-002,4.007810e+000,-1.909177e-002,-1.210737e-002,-1.361652e-006,-1.361652e-006,,,,,,,,,,,,,,,,,,,,
1524609205.969,,0.000000e+000,5.500367e+001,5.500629e+001,1,0,7.741935e-001,0.000000e+000,3.984131e+000,3.984131e+000,-3.244332e-002,-2.977204e-002,4.023219e+000,6.645168e-003,9.316444e-003,-7.314520e-007,-7.314520e-007,,,,,,,,,,,,,,,,,,,,
1524609220.381,,0.000000e+000,5.500892e+001,5.498788e+001,1,0,0.000000e+000,0.000000e+000,4.141757e+000,4.141757e+000,1.316700e-001,1.316700e-001,4.020686e+000,1.059914e-002,1.059914e-002,2.887653e-006,2.887653e-006,,,,,,,,,,,,,,,,,,,,
1524609220.381,,0.000000e+000,5.500892e+001,5.498788e+001,1,0,3.354839e+000,0.000000e+000,4.032807e+000,4.032807e+000,8.748186e-003,2.272034e-002,4.035122e+000,1.106323e-002,2.503538e-002,3.485620e-007,3.485620e-007,,,,,,,,,,,,,,,,,,,,
1524609235.403,,0.000000e+000,5.500367e+001,5.499577e+001,1,0,2.580645e+000,0.000000e+000,4.043030e+000,4.043030e+000,2.716854e-002,3.937626e-002,4.000870e+000,-1.499197e-002,-2.784252e-003,7.163035e-007,7.163035e-007,,,,,,,,,,,,,,,,,,,,
1524609250.725,,0.000000e+000,5.500235e+001,5.499445e+001,1,0,1.806452e+000,0.000000e+000,3.976959e+000,3.976959e+000,-2.917664e-002,-2.270007e-002,3.977463e+000,-2.867262e-002,-2.219605e-002,-5.941110e-007,-5.941110e-007,,,,,,,,,,,,,,,,,,,,
1524609264.817,,0.000000e+000,5.500629e+001,5.499577e+001,1,0,1.032258e+000,0.000000e+000,3.918059e+000,3.918059e+000,-7.773618e-002,-7.533813e-002,3.995726e+000,-6.893952e-005,2.329111e-003,-1.712979e-006,-1.712979e-006,,,,,,,,,,,,,,,,,,,,
1524609278.649,,0.000000e+000,5.499708e+001,5.500103e+001,1,0,2.580645e-001,0.000000e+000,4.059358e+000,4.059358e+000,6.662199e-002,6.705308e-002,4.005909e+000,1.317379e-002,1.360488e-002,1.513821e-006,1.513821e-006,,,,,,,,,,,,,,,,,,,,
1524609278.649,,0.000000e+000,5.499708e+001,5.500103e+001,1,0,3.612903e+000,0.000000e+000,4.014954e+000,4.014954e+000,1.661376e-002,2.264905e-002,4.011874e+000,1.353435e-002,1.956964e-002,4.796311e-007,4.796311e-007,,,,,,,,,,,,,,,,,,,,
1524609292.351,,0.000000e+000,5.500103e+001,5.499314e+001,1,0,2.838710e+000,0.000000e+000,3.997406e+000,3.997406e+000,4.119095e-003,1.468039e-002,3.988720e+000,-4.567209e-003,5.994081e-003,2.034067e-007,2.034067e-007,,,,,,,,,,,,,,,,,,,,
1524609306.493,,0.000000e+000,5.499971e+001,5.499577e+001,1,0,2.064516e+000,0.000000e+000,3.985656e+000,3.985656e+000,6.070366e-003,4.485846e-003,3.951950e+000,-2.763630e-002,-2.922082e-002,1.963635e-007,1.963635e-007,,,,,,,,,,,,,,,,,,,,
1524609320.035,,0.000000e+000,5.499839e+001,5.500103e+001,1,0,1.290323e+000,0.000000e+000,3.875944e+000,3.875944e+000,-7.337881e-002,-7.427907e-002,3.940375e+000,-8.948093e-003,-9.848356e-003,-1.570443e-006,-1.570443e-006,,,,,,,,,,,,,,,,,,,,
1524609334.827,,0.000000e+000,5.499708e+001,5.499708e+001,1,0,5.161290e-001,0.000000e+000,3.940032e+000,3.940032e+000,1.350908e-002,1.314116e-002,3.938311e+000,1.178794e-002,1.142001e-002,3.803725e-007,3.803725e-007,,,,,,,,,,,,,,,,,,,,
1524609334.827,,0.000000e+000,5.499708e+001,5.499708e+001,1,0,3.870968e+000,0.000000e+000,3.932555e+000,3.932555e+000,8.423811e-003,5.664349e-003,3.935195e+000,1.106334e-002,8.303881e-003,2.310699e-007,2.310699e-007,,,,,,,,,,,,,,,,,,,,
1524609349.429,,0.000000e+000,5.499445e+001,5.499839e+001,1,0,3.096774e+000,0.000000e+000,3.929809e+000,3.929809e+000,1.992964e-002,1.879930e-002,3.914099e+000,4.219522e-003,3.089190e-003,5.072798e-007,5.072798e-007,,,,,,,,,,,,,,,,,,,,
1524609363.281,,0.000000e+000,5.499839e+001,5.499708e+001,1,0,2.322581e+000,0.000000e+000,3.925536e+000,3.925536e+000,2.439653e-002,2.669811e-002,3.874111e+000,-2.702798e-002,-2.472639e-002,6.240734e-007,6.240734e-007,,,,,,,,,,,,,,,,,,,,
1524609377.613,,0.000000e+000,5.499971e+001,5.499577e+001,1,0,1.548387e+000,0.000000e+000,3.830320e+000,3.830320e+000,-6.531092e-002,-5.921698e-002,3.876685e+000,-1.894565e-002,-1.285172e-002,-1.422086e-006,-1.422086e-006,,,,,,,,,,,,,,,,,,,,
1524609391.645,,0.000000e+000,5.500103e+001,5.500367e+001,1,0,7.741935e-001,0.000000e+000,3.848173e+000,3.848173e+000,-4.342102e-002,-4.140067e-002,3.899177e+000,7.583630e-003,9.603977e-003,-9.534706e-007,-9.534706e-007,,,,,,,,,,,,,,,,,,,,
1524609405.747,,0.000000e+000,5.499577e+001,5.499577e+001,1,0,0.000000e+000,0.000000e+000,4.028077e+000,4.028077e+000,1.321583e-001,1.321583e-001,3.906174e+000,1.025558e-002,1.025558e-002,3.022185e-006,3.022185e-006,,,,,,,,,,,,,,,,,,,,
1524609405.747,,0.000000e+000,5.499577e+001,5.499577e+001,1,0,3.354839e+000,0.000000e+000,3.910887e+000,3.910887e+000,1.516666e-002,1.496887e-002,3.906425e+000,1.070466e-002,1.050687e-002,4.045141e-007,4.045141e-007,,,,,,,,,,,,,,,,,,,,
1524609419.819,,0.000000e+000,5.500497e+001,5.499182e+001,1,0,2.580645e+000,0.000000e+000,3.919738e+000,3.919738e+000,2.306592e-002,2.733421e-002,3.879780e+000,-1.689136e-002,-1.262307e-002,6.066111e-007,6.066111e-007,,,,,,,,,,,,,,,,,,,,
1524609434.631,,0.000000e+000,5.500103e+001,5.500367e+001,1,0,1.806452e+000,0.000000e+000,3.856107e+000,3.856107e+000,-3.354819e-002,-3.046441e-002,3.856086e+000,-3.356965e-002,-3.048587e-002,-6.746995e-007,-6.746995e-007,,,,,,,,,,,,,,,,,,,,
1524609449.413,,0.000000e+000,5.499577e+001,5.499839e+001,1,0,1.032258e+000,0.000000e+000,3.790494e+000,3.790494e+000,-1.010141e-001,-9.944105e-002,3.891424e+000,-8.414558e-005,1.488924e-003,-2.208850e-006,-2.208850e-006,,,,,,,,,,,,,,,,,,,,
1524609463.995,,0.000000e+000,5.499839e+001,5.499314e+001,1,0,2.580645e-001,0.000000e+000,3.959869e+000,3.959869e+000,6.983034e-002,7.021785e-002,3.902193e+000,1.215449e-002,1.254201e-002,1.584674e-006,1.584674e-006,,,,,,,,,,,,,,,,,,,,
1524609463.995,,0.000000e+000,5.499839e+001,5.499314e+001,1,0,3.612903e+000,0.000000e+000,3.907988e+000,3.907988e+000,1.291179e-002,1.833701e-002,3.907563e+000,1.248693e-002,1.791215e-002,3.875757e-007,3.875757e-007,,,,,,,,,,,,,,,,,,,,
1524609478.297,,0.000000e+000,5.499971e+001,5.499971e+001,1,0,2.838710e+000,0.000000e+000,3.904479e+000,3.904479e+000,1.093392e-002,1.365280e-002,3.888612e+000,-4.932833e-003,-2.213955e-003,3.264140e-007,3.264140e-007,,,,,,,,,,,,,,,,,,,,
1524609492.649,,0.000000e+000,5.499839e+001,5.499839e+001,1,0,2.064516e+000,0.000000e+000,3.895781e+000,3.895781e+000,3.565444e-003,8.320332e-003,3.860036e+000,-3.217898e-002,-2.742410e-002,1.534208e-007,1.534208e-007,,,,,,,,,,,,,,,,,,,,
1524609507.281,,0.000000e+000,5.500235e+001,5.499708e+001,1,0,1.290323e+000,0.000000e+000,3.986572e+000,3.986572e+000,-1.041604e-001,-1.252162e-001,4.079079e+000,-1.165374e-002,-3.270960e-002,-2.074434e-006,-2.074434e-006,,,,,,,,,,,,,,,,,,,,
1524609521.403,,0.000000e+000,5.499577e+001,5.499445e+001,1,0,5.161290e-001,0.000000e+000,3.806211e+000,3.806211e+000,9.703358e-003,8.645773e-003,3.810645e+000,1.413794e-002,1.308036e-002,3.373134e-007,3.373134e-007,,,,,,,,,,,,,,,,,,,,
1524609521.403,,0.000000e+000,5.499577e+001,5.499445e+001,1,0,3.870968e+000,0.000000e+000,3.790494e+000,3.790494e+000,8.611077e-004,-7.070780e-003,3.802902e+000,1.326913e-002,5.337238e-003,3.728201e-008,3.728201e-008,,,,,,,,,,,,,,,,,,,,
1524609535.395,,0.000000e+000,5.499971e+001,5.499839e+001,1,0,3.096774e+000,0.000000e+000,3.811093e+000,3.811093e+000,1.643191e-002,2.815819e-002,3.798925e+000,4.263264e-003,1.598954e-002,4.976755e-007,4.976755e-007,,,,,,,,,,,,,,,,,,,,
1524609549.218,,0.000000e+000,5.500235e+001,5.499182e+001,1,0,2.322581e+000,0.000000e+000,3.819486e+000,3.819486e+000,2.577274e-002,2.597666e-002,3.769817e+000,-2.389581e-002,-2.369189e-002,6.418995e-007,6.418995e-007,,,,,,,,,,,,,,,,,,,,
1524609563.450,,0.000000e+000,5.500629e+001,5.499577e+001,1,0,1.548387e+000,0.000000e+000,3.738308e+000,3.738308e+000,-6.430924e-002,-6.255436e-002,3.780787e+000,-2.182948e-002,-2.007461e-002,-1.371111e-006,-1.371111e-006,,,,,,,,,,,,,,,,,,,,
1524609577.582,,0.000000e+000,5.499708e+001,5.499839e+001,1,0,7.741935e-001,0.000000e+000,3.759213e+000,3.759213e+000,-4.486332e-002,-4.323745e-002,3.812690e+000,8.614439e-003,1.024032e-002,-9.675568e-007,-9.675568e-007,,,,,,,,,,,,,,,,,,,,
1524609591.584,,0.000000e+000,5.499445e+001,5.500497e+001,1,0,0.000000e+000,0.000000e+000,3.944915e+000,3.944915e+000,1.334422e-001,1.334422e-001,3.822011e+000,1.053786e-002,1.053786e-002,3.046036e-006,3.046036e-006,,,,,,,,,,,,,,,,,,,,
1524609591.584,,0.000000e+000,5.499445e+001,5.500497e+001,1,0,3.354839e+000,0.000000e+000,3.821012e+000,3.821012e+000,8.980643e-003,9.539127e-003,3.823030e+000,1.099933e-002,1.155782e-002,2.726447e-007,2.726447e-007,,,,,,,,,,,,,,,,,,,,
1524609603.524,,0.000000e+000,5.500629e+001,5.499445e+001,1,0,2.580645e+000,0.000000e+000,3.835813e+000,3.835813e+000,2.342551e-002,-4.497051e-002,3.857570e+000,4.518264e-002,-2.321339e-002,5.145994e-007,5.145994e-007,,,,,,,,,,,,,,,,,,,,
1524609618.176,,0.000000e+000,5.499577e+001,5.499445e+001,1,0,1.806452e+000,0.000000e+000,3.779812e+000,3.779812e+000,-3.664064e-002,-3.754902e-002,3.784815e+000,-3.163838e-002,-3.254676e-002,-7.420604e-007,-7.420604e-007,,,,,,,,,,,,,,,,,,,,
1524609632.258,,0.000000e+000,5.499314e+001,5.499314e+001,1,0,1.032258e+000,0.000000e+000,3.744717e+000,3.744717e+000,-7.493168e-002,-7.618284e-002,3.819555e+000,-9.327859e-005,-1.344442e-003,-1.578781e-006,-1.578781e-006,,,,,,,,,,,,,,,,,,,,
1524609646.410,,0.000000e+000,5.499839e+001,5.500629e+001,1,0,2.580645e-001,0.000000e+000,3.891356e+000,3.891356e+000,7.065022e-002,7.043481e-002,3.837833e+000,1.712787e-002,1.691246e-002,1.689332e-006,1.689332e-006,,,,,,,,,,,,,,,,,,,,
1524609646.410,,0.000000e+000,5.499839e+001,5.500629e+001,1,0,3.612903e+000,0.000000e+000,3.828641e+000,3.828641e+000,1.073600e-002,7.720232e-003,3.835501e+000,1.759625e-002,1.458049e-002,3.085588e-007,3.085588e-007,,,,,,,,,,,,,,,,,,,,
1524609660.432,,0.000000e+000,5.500235e+001,5.499445e+001,1,0,2.838710e+000,0.000000e+000,3.840848e+000,3.840848e+000,2.297779e-002,2.927828e-002,3.812463e+000,-5.408089e-003,8.924007e-004,6.181072e-007,6.181072e-007,,,,,,,,,,,,,,,,,,,,
1524609674.424,,0.000000e+000,5.499839e+001,5.499445e+001,1,0,2.064516e+000,0.000000e+000,3.826658e+000,3.826658e+000,5.847918e-003,5.832195e-003,3.792293e+000,-2.851654e-002,-2.853227e-002,1.940643e-007,1.940643e-007,,,,,,,,,,,,,,,,,,,,
1524609688.586,,0.000000e+000,5.499577e+001,5.498919e+001,1,0,1.290323e+000,0.000000e+000,3.742428e+000,3.742428e+000,-7.692629e-002,-7.677054e-002,3.808631e+000,-1.072269e-002,-1.056695e-002,-1.646054e-006,-1.646054e-006,,,,,,,,,,,,,,,,,,,,
1524609702.768,,0.000000e+000,5.500235e+001,5.500497e+001,1,0,5.161290e-001,0.000000e+000,3.834897e+000,3.834897e+000,1.400449e-002,1.365590e-002,3.836543e+000,1.564982e-002,1.530123e-002,4.111353e-007,4.111353e-007,,,,,,,,,,,,,,,,,,,,
1524609702.768,,0.000000e+000,5.500235e+001,5.500497e+001,1,0,3.870968e+000,0.000000e+000,3.827115e+000,3.827115e+000,8.488358e-003,5.873919e-003,3.833315e+000,1.468796e-002,1.207352e-002,2.540619e-007,2.540619e-007,,,,,,,,,,,,,,,,,,,,
1524609717.370,,0.000000e+000,5.500103e+001,5.499577e+001,1,0,3.096774e+000,0.000000e+000,4.008087e+000,4.008087e+000,1.025387e-002,-3.720999e-002,4.002128e+000,4.294841e-003,-4.316902e-002,4.777394e-008,4.777394e-008,,,,,,,,,,,,,,,,,,,,
1524609731.752,,0.000000e+000,5.500367e+001,5.499708e+001,1,0,2.322581e+000,0.000000e+000,3.746853e+000,3.746853e+000,9.189887e-003,1.202703e-002,3.708867e+000,-2.879639e-002,-2.595925e-002,2.901361e-007,2.901361e-007,,,,,,,,,,,,,,,,,,,,
1524609743.952,,0.000000e+000,5.499314e+001,5.498788e+001,1,0,1.548387e+000,0.000000e+000,3.845884e+000,3.845884e+000,-1.158582e-001,-1.737442e-001,3.863792e+000,-9.795015e-002,-1.558361e-001,-1.905777e-006,-1.905777e-006,,,,,,,,,,,,,,,,,,,,
1524609757.882,,0.000000e+000,5.499182e+001,5.499577e+001,1,0,7.741935e-001,0.000000e+000,3.636378e+000,3.636378e+000,-4.130005e-002,-3.724289e-002,3.685781e+000,8.103143e-003,1.216030e-002,-9.497162e-007,-9.497162e-007,,,,,,,,,,,,,,,,,,,,
1524609772.904,,0.000000e+000,5.499445e+001,5.499051e+001,1,0,0.000000e+000,0.000000e+000,3.823758e+000,3.823758e+000,1.321445e-001,1.321445e-001,3.702539e+000,1.092553e-002,1.092553e-002,2.893663e-006,2.893663e-006,,,,,,,,,,,,,,,,,,,,
1524609772.904,,0.000000e+000,5.499445e+001,5.499051e+001,1,0,3.354839e+000,0.000000e+000,3.701534e+000,3.701534e+000,-4.808252e-003,9.919643e-003,3.717746e+000,1.140397e-002,2.613187e-002,5.222682e-008,5.222682e-008,,,,,,,,,,,,,,,,,,,,
1524609772.904,,0.000000e+000,5.499445e+001,5.499051e+001,1,0,4.000000e+000,0.000000e+000,3.721981e+000,3.721981e+000,1.280671e-002,3.036690e-002,3.720100e+000,1.092559e-002,2.848577e-002,4.881149e-007,4.881149e-007,,,,,,,,,,,,,,,,,,,,