File: Experimental Raw Data/TC04-12-01K TRMac VRMde/Raw/TC04-12-01K_TRMac_58K_0.16Kmin_VRMde_55K.dc.raw
[Header]
TITLE,MPMS DC Measurement
BYAPP,MPMS Measurement,2.1,Raw with ABS
FILEOPENTIME, 1524659957.380000 4/25/2018, 6:39:17 AM

INFO, APPNAME, MPMS MultiVu Application, Revision 1.61,  Build 082

INFO, NAME, TC04-12-01K
INFO, WEIGHT, 1.000
INFO, AREA, 1.000
INFO, LENGTH, 1.000
INFO, SHAPE, 0
INFO, COMMENT,
INFO, SEQUENCE FILE: TRMac_58K_0.16Kmin_VRMde_55K.seq


INFO, BACKGROUND DATA FILE:, None


STARTUPAXIS,X,8,LINEAR,AUTO,0.000000,0.000000
STARTUPAXIS,Y1,10,LINEAR,AUTO,0.000000,0.000000


STARTUPGROUP,Longitudinal
FIELDGROUP,Longitudinal,1,3,4,5,6,8,9,10,11,12,13,14,15,16,17,18,19,20,21,22,23
FIELDGROUP,Transverse,1,3,4,5,6,8,9,24,25,26,27,28,29,30,31,32,33,34,35,36,37

PLOT_APPEARANCE,ALL,HORZ_GRID_ON,VERT_GRID_ON,MARKERS_ONLY

[Data]
Time,Comment,Field (Oe),Start Temperature (K),End Temperature (K),Scan,Rejected,Position (cm),Rot Position (deg),Long Voltage,Long Average Voltage,Long Detrended Voltage,Long Demeaned Voltage,Long Regression Fit,Long Detrended Fit,Long Demeaned Fit,Long Scaled Response,Long Avg. Scaled Response,Long Background Response,Long Response [w/ABS],Long Detrended Resp. [w/ABS],Long Fit [w/ABS],Long Detrended Fit [w/ABS],Trans Voltage,Trans Average Voltage,Trans Detrended Voltage,Trans Demeaned Voltage,Trans Regression Fit,Trans Detrended Fit,Trans Demeaned Fit,Trans Scaled Response,Trans Avg Scaled Response,Trans Background Response,Trans Response [w/ABS],Trans Detrended Resp. [w/ABS],Trans Fit [w/ABS],Trans Detrended Fit [w/ABS],
1524659957.370,,0.000000e+000,5.499182e+001,5.499182e+001,1,0,0.000000e+000,0.000000e+000,1.351949e+000,1.351949e+000,-2.605593e-002,-2.605593e-002,1.133867e+000,-2.441382e-001,-2.441382e-001,-1.229385e-005,-1.229385e-005,,,,,,,,,,,,,,,,,,,,
1524659970.370,,0.000000e+000,5.499445e+001,5.499577e+001,1,0,3.483871e+000,0.000000e+000,2.268101e+000,2.268101e+000,-2.079418e-001,8.583468e-001,2.204631e+000,-2.714114e-001,7.948772e-001,4.823087e-007,4.823087e-007,,,,,,,,,,,,,,,,,,,,
1524659995.720,,0.000000e+000,5.500235e+001,5.500235e+001,1,0,2.838710e+000,0.000000e+000,2.424811e+000,2.424811e+000,1.506100e-001,9.418484e-001,2.416688e+000,1.424866e-001,9.337250e-001,5.438873e-006,5.438873e-006,,,,,,,,,,,,,,,,,,,,
1524660020.560,,0.000000e+000,5.498919e+001,5.499182e+001,1,0,2.193548e+000,0.000000e+000,2.627299e+000,2.627299e+000,4.874749e-001,1.031718e+000,2.673073e+000,5.332496e-001,1.077493e+000,1.037724e-005,1.037724e-005,,,,,,,,,,,,,,,,,,,,
1524660045.820,,0.000000e+000,5.499314e+001,5.500629e+001,1,0,1.548387e+000,0.000000e+000,2.357824e+000,2.357824e+000,3.324052e-001,6.861749e-001,2.294674e+000,2.692550e-001,6.230247e-001,4.819638e-006,4.819638e-006,,,,,,,,,,,,,,,,,,,,
1524660071.040,,0.000000e+000,5.499839e+001,5.498788e+001,1,0,9.032258e-001,0.000000e+000,1.751278e+000,1.751278e+000,-1.637363e-001,2.873409e-002,1.807486e+000,-1.075280e-001,8.494234e-002,-8.071183e-006,-8.071183e-006,,,,,,,,,,,,,,,,,,,,
1524660096.250,,0.000000e+000,5.499182e+001,5.499839e+001,1,0,2.580645e-001,0.000000e+000,1.642786e+000,1.642786e+000,-1.818559e-001,-1.339115e-001,1.649881e+000,-1.747611e-001,-1.268166e-001,-9.695614e-006,-9.695614e-006,,,,,,,,,,,,,,,,,,,,
1524660108.800,,0.000000e+000,5.499839e+001,5.499708e+001,1,0,3.741935e+000,0.000000e+000,2.286870e+000,2.286870e+000,-1.826960e-001,5.449462e-001,2.282151e+000,-1.874143e-001,5.402279e-001,-1.666340e-007,-1.666340e-007,,,,,,,,,,,,,,,,,,,,
1524660134.050,,0.000000e+000,5.499839e+001,5.499445e+001,1,0,3.096774e+000,0.000000e+000,2.355078e+000,2.355078e+000,1.265547e-002,5.744576e-001,2.336137e+000,-6.285459e-003,5.555167e-001,2.228291e-006,2.228291e-006,,,,,,,,,,,,,,,,,,,,
1524660159.240,,0.000000e+000,5.500235e+001,5.499971e+001,1,0,2.451613e+000,0.000000e+000,2.489967e+000,2.489967e+000,2.795277e-001,6.998166e-001,2.521497e+000,3.110576e-001,7.313465e-001,6.480281e-006,6.480281e-006,,,,,,,,,,,,,,,,,,,,
1524660184.480,,0.000000e+000,5.499708e+001,5.500629e+001,1,0,1.806452e+000,0.000000e+000,2.441901e+000,2.441901e+000,3.464263e-001,6.438859e-001,2.402284e+000,3.068092e-001,6.042688e-001,6.442075e-006,6.442075e-006,,,,,,,,,,,,,,,,,,,,
1524660209.690,,0.000000e+000,5.500235e+001,5.499839e+001,1,0,1.161290e+000,0.000000e+000,2.001373e+000,2.001373e+000,6.171413e-003,1.919776e-001,1.996571e+000,1.368709e-003,1.871749e-001,-2.599372e-006,-2.599372e-006,,,,,,,,,,,,,,,,,,,,
1524660234.940,,0.000000e+000,5.500235e+001,5.500103e+001,1,0,5.161290e-001,0.000000e+000,1.660640e+000,1.660640e+000,-2.476204e-001,-1.688408e-001,1.755123e+000,-1.531371e-001,-7.435751e-002,-9.547424e-006,-9.547424e-006,,,,,,,,,,,,,,,,,,,,
1524660247.621,,0.000000e+000,5.500103e+001,5.500235e+001,1,0,4.000000e+000,0.000000e+000,2.266270e+000,2.266270e+000,-1.694972e-001,4.253016e-001,2.300681e+000,-1.350863e-001,4.597125e-001,-3.417590e-007,-3.417590e-007,,,,,,,,,,,,,,,,,,,,
1524660272.841,,0.000000e+000,5.500235e+001,5.499839e+001,1,0,3.354839e+000,0.000000e+000,2.296941e+000,2.296941e+000,-3.801307e-002,4.371945e-001,2.254773e+000,-8.018073e-002,3.950268e-001,1.114240e-006,1.114240e-006,,,,,,,,,,,,,,,,,,,,
1524660298.061,,0.000000e+000,5.499577e+001,5.499708e+001,1,0,2.709677e+000,0.000000e+000,2.371710e+000,2.371710e+000,1.278016e-001,5.027157e-001,2.409764e+000,1.658556e-001,5.407697e-001,3.520545e-006,3.520545e-006,,,,,,,,,,,,,,,,,,,,
1524660323.281,,0.000000e+000,5.500235e+001,5.499839e+001,1,0,2.064516e+000,0.000000e+000,2.469215e+000,2.469215e+000,3.088516e-001,5.853156e-001,2.463525e+000,3.031615e-001,5.796255e-001,6.323397e-006,6.323397e-006,,,,,,,,,,,,,,,,,,,,
1524660348.501,,0.000000e+000,5.498919e+001,5.499839e+001,1,0,1.419355e+000,0.000000e+000,2.197452e+000,2.197452e+000,1.163041e-001,3.003689e-001,2.161684e+000,8.053607e-002,2.646009e-001,8.666320e-007,8.666320e-007,,,,,,,,,,,,,,,,,,,,
1524660373.721,,0.000000e+000,5.499839e+001,5.499971e+001,1,0,7.741935e-001,0.000000e+000,1.836271e+000,1.836271e+000,-1.673012e-001,-6.936693e-002,1.894325e+000,-1.092469e-001,-1.131260e-002,-6.573937e-006,-6.573937e-006,,,,,,,,,,,,,,,,,,,,
1524660398.941,,0.000000e+000,5.499445e+001,5.499577e+001,1,0,1.290323e-001,0.000000e+000,1.897612e+000,1.897612e+000,-3.837217e-002,-2.270722e-002,1.845692e+000,-9.029222e-002,-7.462728e-002,-4.683527e-006,-4.683527e-006,,,,,,,,,,,,,,,,,,,,
1524660411.481,,0.000000e+000,5.499577e+001,5.498788e+001,1,0,3.612903e+000,0.000000e+000,2.275425e+000,2.275425e+000,-7.726057e-002,3.543134e-001,2.241040e+000,-1.116460e-001,3.199279e-001,3.500099e-007,3.500099e-007,,,,,,,,,,,,,,,,,,,,
1524660436.831,,0.000000e+000,5.499839e+001,5.499839e+001,1,0,2.967742e+000,0.000000e+000,2.320592e+000,2.320592e+000,5.033546e-002,3.987751e-001,2.321199e+000,5.094271e-002,3.993824e-001,2.119930e-006,2.119930e-006,,,,,,,,,,,,,,,,,,,,
1524660461.701,,0.000000e+000,5.499577e+001,5.499445e+001,1,0,2.322581e+000,0.000000e+000,2.411536e+000,2.411536e+000,2.250023e-001,4.903418e-001,2.434483e+000,2.479498e-001,5.132893e-001,4.956586e-006,4.956586e-006,,,,,,,,,,,,,,,,,,,,
1524660487.661,,0.000000e+000,5.500629e+001,5.499839e+001,1,0,1.677419e+000,0.000000e+000,2.294499e+000,2.294499e+000,1.829631e-001,3.662618e-001,2.257550e+000,1.460137e-001,3.293124e-001,3.022076e-006,3.022076e-006,,,,,,,,,,,,,,,,,,,,
1524660512.521,,0.000000e+000,5.499708e+001,5.498919e+001,1,0,1.032258e+000,0.000000e+000,1.955291e+000,1.955291e+000,-8.270023e-002,2.720368e-002,1.986076e+000,-5.191491e-002,5.798900e-002,-3.845118e-006,-3.845118e-006,,,,,,,,,,,,,,,,,,,,
1524660537.871,,0.000000e+000,5.499971e+001,5.499314e+001,1,0,3.870968e-001,0.000000e+000,1.842374e+000,1.842374e+000,-1.219274e-001,-8.195305e-002,1.864573e+000,-9.972896e-002,-5.975461e-002,-5.595735e-006,-5.595735e-006,,,,,,,,,,,,,,,,,,,,
1524660550.281,,0.000000e+000,5.498788e+001,5.499577e+001,1,0,3.870968e+000,0.000000e+000,2.232242e+000,2.232242e+000,-9.764561e-002,3.112384e-001,2.224774e+000,-1.051141e-001,3.037699e-001,2.577144e-008,2.577144e-008,,,,,,,,,,,,,,,,,,,,
1524660575.251,,0.000000e+000,5.499577e+001,5.499314e+001,1,0,3.225806e+000,0.000000e+000,2.247807e+000,2.247807e+000,-2.308453e-003,3.294276e-001,2.231516e+000,-1.859936e-002,3.131367e-001,1.173386e-006,1.173386e-006,,,,,,,,,,,,,,,,,,,,
1524660600.261,,0.000000e+000,5.499839e+001,5.499971e+001,1,0,2.580645e+000,0.000000e+000,2.298314e+000,2.298314e+000,1.287896e-001,3.819162e-001,2.339227e+000,1.697030e-001,4.228295e-001,3.140398e-006,3.140398e-006,,,,,,,,,,,,,,,,,,,,
1524660625.171,,0.000000e+000,5.499577e+001,5.501024e+001,1,0,1.935484e+000,0.000000e+000,2.323491e+000,2.323491e+000,2.304810e-001,4.187388e-001,2.293806e+000,2.007952e-001,3.890531e-001,4.534297e-006,4.534297e-006,,,,,,,,,,,,,,,,,,,,
1524660651.561,,0.000000e+000,5.499577e+001,5.500761e+001,1,0,1.290323e+000,0.000000e+000,2.037690e+000,2.037690e+000,1.635660e-002,1.392971e-001,2.035908e+000,1.457537e-002,1.375159e-001,-1.081826e-006,-1.081826e-006,,,,,,,,,,,,,,,,,,,,
1524660677.131,,0.000000e+000,5.500761e+001,5.499971e+001,1,0,6.451613e-001,0.000000e+000,1.812619e+000,1.812619e+000,-1.475138e-001,-8.853424e-002,1.866821e+000,-9.331156e-002,-3.433204e-002,-5.497059e-006,-5.497059e-006,,,,,,,,,,,,,,,,,,,,
1524660702.531,,0.000000e+000,5.499839e+001,5.500367e+001,1,0,0.000000e+000,0.000000e+000,1.978943e+000,1.978943e+000,8.385384e-002,8.385384e-002,1.843030e+000,-5.205870e-002,-5.205870e-002,-1.046923e-006,-1.046923e-006,,,,,,,,,,,,,,,,,,,,
1524660714.891,,0.000000e+000,5.499577e+001,5.499971e+001,1,0,3.483871e+000,0.000000e+000,2.153506e+000,2.153506e+000,-5.067689e-002,2.632283e-001,2.141988e+000,-6.219441e-002,2.517108e-001,2.403176e-007,2.403176e-007,,,,,,,,,,,,,,,,,,,,
1524660740.151,,0.000000e+000,5.499445e+001,5.499051e+001,1,0,2.838710e+000,0.000000e+000,2.201114e+000,2.201114e+000,6.969478e-002,3.240677e-001,2.218299e+000,8.687999e-002,3.412529e-001,2.134460e-006,2.134460e-006,,,,,,,,,,,,,,,,,,,,
1524660765.321,,0.000000e+000,5.499182e+001,5.499839e+001,1,0,2.193548e+000,0.000000e+000,2.257725e+000,2.257725e+000,1.923216e-001,3.811417e-001,2.263311e+000,1.979080e-001,3.867280e-001,4.071662e-006,4.071662e-006,,,,,,,,,,,,,,,,,,,,
1524660790.381,,0.000000e+000,5.499314e+001,5.499314e+001,1,0,1.548387e+000,0.000000e+000,2.093996e+000,2.093996e+000,9.404235e-002,2.251564e-001,2.069630e+000,6.967692e-002,2.007910e-001,1.114866e-006,1.114866e-006,,,,,,,,,,,,,,,,,,,,
1524660815.681,,0.000000e+000,5.499445e+001,5.499577e+001,1,0,9.032258e-001,0.000000e+000,1.832303e+000,1.832303e+000,-1.034676e-001,-2.752888e-002,1.870060e+000,-6.571078e-002,1.022792e-002,-4.035472e-006,-4.035472e-006,,,,,,,,,,,,,,,,,,,,
1524660840.841,,0.000000e+000,5.498525e+001,5.499445e+001,1,0,2.580645e-001,0.000000e+000,1.817197e+000,1.817197e+000,-6.235292e-002,-4.137409e-002,1.813812e+000,-6.573835e-002,-4.475951e-002,-3.774257e-006,-3.774257e-006,,,,,,,,,,,,,,,,,,,,
1524660853.671,,0.000000e+000,5.499708e+001,5.499839e+001,1,0,3.741935e+000,0.000000e+000,2.096132e+000,2.096132e+000,-5.403040e-002,2.352974e-001,2.071509e+000,-7.865307e-002,2.106748e-001,1.624867e-007,1.624867e-007,,,,,,,,,,,,,,,,,,,,
1524660878.921,,0.000000e+000,5.499839e+001,5.499708e+001,1,0,3.096774e+000,0.000000e+000,2.116426e+000,2.116426e+000,2.742963e-002,2.638717e-001,2.120014e+000,3.101783e-002,2.674599e-001,1.295724e-006,1.295724e-006,,,,,,,,,,,,,,,,,,,,
1524660904.001,,0.000000e+000,5.499577e+001,5.500235e+001,1,0,2.451613e+000,0.000000e+000,2.182498e+000,2.182498e+000,1.527451e-001,3.302503e-001,2.205642e+000,1.758896e-001,3.533947e-001,3.405992e-006,3.405992e-006,,,,,,,,,,,,,,,,,,,,
1524660929.371,,0.000000e+000,5.499839e+001,5.500367e+001,1,0,1.806452e+000,0.000000e+000,2.126040e+000,2.126040e+000,1.519232e-001,2.810698e-001,2.090047e+000,1.159310e-001,2.450776e-001,2.776229e-006,2.776229e-006,,,,,,,,,,,,,,,,,,,,
1524660954.561,,0.000000e+000,5.499839e+001,5.498656e+001,1,0,1.161290e+000,0.000000e+000,1.863890e+000,1.863890e+000,-5.104616e-002,3.205252e-002,1.887124e+000,-2.781179e-002,5.528688e-002,-2.370332e-006,-2.370332e-006,,,,,,,,,,,,,,,,,,,,
1524660979.782,,0.000000e+000,5.499839e+001,5.500892e+001,1,0,5.161290e-001,0.000000e+000,1.742123e+000,1.742123e+000,-1.138334e-001,-7.751000e-002,1.780451e+000,-7.550468e-002,-3.918123e-002,-4.365706e-006,-4.365706e-006,,,,,,,,,,,,,,,,,,,,
1524660992.162,,0.000000e+000,5.499971e+001,5.499839e+001,1,0,4.000000e+000,0.000000e+000,2.028534e+000,2.028534e+000,-7.317477e-002,2.164195e-001,2.025950e+000,-7.575923e-002,2.138350e-001,-1.035005e-007,-1.035005e-007,,,,,,,,,,,,,,,,,,,,
1524661017.492,,0.000000e+000,5.499051e+001,5.500103e+001,1,0,3.354839e+000,0.000000e+000,2.029603e+000,2.029603e+000,-1.176009e-002,2.265280e-001,2.017102e+000,-2.426014e-002,2.140280e-001,6.190385e-007,6.190385e-007,,,,,,,,,,,,,,,,,,,,
1524661042.682,,0.000000e+000,5.499708e+001,5.499708e+001,1,0,2.709677e+000,0.000000e+000,2.045777e+000,2.045777e+000,6.923280e-002,2.551061e-001,2.089855e+000,1.133107e-001,2.991840e-001,1.801171e-006,1.801171e-006,,,,,,,,,,,,,,,,,,,,
1524661067.842,,0.000000e+000,5.500892e+001,5.499445e+001,1,0,2.064516e+000,0.000000e+000,2.089571e+000,2.089571e+000,1.730815e-001,3.140547e-001,2.071288e+000,1.547989e-001,2.957721e-001,3.527370e-006,3.527370e-006,,,,,,,,,,,,,,,,,,,,
1524661093.062,,0.000000e+000,5.499314e+001,5.499314e+001,1,0,1.419355e+000,0.000000e+000,1.877012e+000,1.877012e+000,1.130905e-002,1.048185e-001,1.884694e+000,1.899078e-002,1.125002e-001,-6.471091e-007,-6.471091e-007,,,,,,,,,,,,,,,,,,,,
1524661118.282,,0.000000e+000,5.498919e+001,5.499577e+001,1,0,7.741935e-001,0.000000e+000,1.705348e+000,1.705348e+000,-1.082992e-001,-5.850375e-002,1.745422e+000,-6.822547e-002,-1.842999e-002,-3.854599e-006,-3.854599e-006,,,,,,,,,,,,,,,,,,,,
1524661143.482,,0.000000e+000,5.499577e+001,5.500235e+001,1,0,1.290323e-001,0.000000e+000,1.775235e+000,1.775235e+000,1.553315e-002,2.387059e-002,1.716187e+000,-4.351455e-002,-3.517711e-002,-1.646498e-006,-1.646498e-006,,,,,,,,,,,,,,,,,,,,
1524661156.362,,0.000000e+000,5.499577e+001,5.499839e+001,1,0,3.612903e+000,0.000000e+000,1.935607e+000,1.935607e+000,-3.826871e-002,1.802679e-001,1.924914e+000,-4.896214e-002,1.695745e-001,2.820889e-008,2.820889e-008,,,,,,,,,,,,,,,,,,,,
1524661181.352,,0.000000e+000,5.499971e+001,5.500497e+001,1,0,2.967742e+000,0.000000e+000,1.963836e+000,1.963836e+000,4.392267e-002,2.151749e-001,1.982085e+000,6.217134e-002,2.334236e-001,1.319160e-006,1.319160e-006,,,,,,,,,,,,,,,,,,,,
1524661206.762,,0.000000e+000,5.499839e+001,5.498788e+001,1,0,2.322581e+000,0.000000e+000,2.005035e+000,2.005035e+000,1.320035e-001,2.677802e-001,2.030560e+000,1.575285e-001,2.933053e-001,2.814151e-006,2.814151e-006,,,,,,,,,,,,,,,,,,,,
1524661232.012,,0.000000e+000,5.499708e+001,5.499577e+001,1,0,1.677419e+000,0.000000e+000,1.910582e+000,1.910582e+000,8.414882e-002,1.805462e-001,1.889615e+000,6.318194e-002,1.595793e-001,1.260101e-006,1.260101e-006,,,,,,,,,,,,,,,,,,,,
1524661256.642,,0.000000e+000,5.499577e+001,5.499445e+001,1,0,1.032258e+000,0.000000e+000,1.703975e+000,1.703975e+000,-7.356691e-002,-1.485205e-002,1.729645e+000,-4.789734e-002,1.081753e-002,-2.732922e-006,-2.732922e-006,,,,,,,,,,,,,,,,,,,,
1524661281.732,,0.000000e+000,5.500103e+001,5.499971e+001,1,0,3.870968e-001,0.000000e+000,1.672541e+000,1.672541e+000,-6.645134e-002,-4.573894e-002,1.682021e+000,-5.697135e-002,-3.625894e-002,-2.972884e-006,-2.972884e-006,,,,,,,,,,,,,,,,,,,,
1524661294.282,,0.000000e+000,5.499971e+001,5.499839e+001,1,0,3.870968e+000,0.000000e+000,1.884642e+000,1.884642e+000,-4.685994e-002,1.734110e-001,1.868199e+000,-6.330236e-002,1.569686e-001,-1.786975e-008,-1.786975e-008,,,,,,,,,,,,,,,,,,,,
1524661319.182,,0.000000e+000,5.499577e+001,5.499839e+001,1,0,3.225806e+000,0.000000e+000,1.884184e+000,1.884184e+000,-3.538924e-003,1.761048e-001,1.896976e+000,9.252829e-003,1.888965e-001,4.664907e-007,4.664907e-007,,,,,,,,,,,,,,,,,,,,
1524661344.612,,0.000000e+000,5.500367e+001,5.499182e+001,1,0,2.580645e+000,0.000000e+000,1.955444e+000,1.955444e+000,1.036262e-001,2.583878e-001,1.976320e+000,1.245022e-001,2.792639e-001,2.429559e-006,2.429559e-006,,,,,,,,,,,,,,,,,,,,
1524661369.662,,0.000000e+000,5.499708e+001,5.500103e+001,1,0,1.935484e+000,0.000000e+000,1.945373e+000,1.945373e+000,1.286192e-001,2.324965e-001,1.913510e+000,9.675657e-002,2.006339e-001,2.478257e-006,2.478257e-006,,,,,,,,,,,,,,,,,,,,
1524661394.902,,0.000000e+000,5.499577e+001,5.500367e+001,1,0,1.290323e+000,0.000000e+000,1.739071e+000,1.739071e+000,-5.119089e-002,1.136339e-002,1.773060e+000,-1.720134e-002,4.535294e-002,-1.930995e-006,-1.930995e-006,,,,,,,,,,,,,,,,,,,,
1524661421.312,,0.000000e+000,5.499577e+001,5.499577e+001,1,0,6.451613e-001,0.000000e+000,1.656519e+000,1.656519e+000,-1.128858e-001,-7.941151e-002,1.707635e+000,-6.177001e-002,-2.829576e-002,-3.777721e-006,-3.777721e-006,,,,,,,,,,,,,,,,,,,,
1524661446.472,,0.000000e+000,5.499971e+001,5.499577e+001,1,0,0.000000e+000,0.000000e+000,1.851682e+000,1.851682e+000,1.001775e-001,1.001775e-001,1.723533e+000,-2.797186e-002,-2.797186e-002,5.672700e-007,5.672700e-007,,,,,,,,,,,,,,,,,,,,
1524661459.122,,0.000000e+000,5.499577e+001,5.499314e+001,1,0,3.483871e+000,0.000000e+000,1.907225e+000,1.907225e+000,-2.552458e-002,1.493269e-001,1.909543e+000,-2.320667e-002,1.516448e-001,4.026515e-008,4.026515e-008,,,,,,,,,,,,,,,,,,,,
1524661484.562,,0.000000e+000,5.500103e+001,5.499971e+001,1,0,2.838710e+000,0.000000e+000,1.956969e+000,1.956969e+000,4.312804e-002,1.889921e-001,1.996339e+000,8.249775e-002,2.283618e-001,1.181899e-006,1.181899e-006,,,,,,,,,,,,,,,,,,,,
1524661509.822,,0.000000e+000,5.499839e+001,5.499971e+001,1,0,2.193548e+000,0.000000e+000,2.031128e+000,2.031128e+000,1.401271e-001,2.543875e-001,2.017323e+000,1.263222e-001,2.405826e-001,2.937486e-006,2.937486e-006,,,,,,,,,,,,,,,,,,,,
1524661534.712,,0.000000e+000,5.498788e+001,5.500367e+001,1,0,1.548387e+000,0.000000e+000,1.904173e+000,1.904173e+000,3.731540e-002,1.186396e-001,1.892626e+000,2.576819e-002,1.070924e-001,2.053566e-007,2.053566e-007,,,,,,,,,,,,,,,,,,,,
1524661559.712,,0.000000e+000,5.500103e+001,5.499708e+001,1,0,9.032258e-001,0.000000e+000,1.754482e+000,1.754482e+000,-9.053537e-002,-4.599881e-002,1.790649e+000,-5.436847e-002,-9.831905e-003,-3.041787e-006,-3.041787e-006,,,,,,,,,,,,,,,,,,,,
1524661584.912,,0.000000e+000,5.499577e+001,5.499971e+001,1,0,2.580645e-001,0.000000e+000,1.810636e+000,1.810636e+000,-1.489895e-002,-2.142549e-003,1.787371e+000,-3.816360e-002,-2.540720e-002,-1.759843e-006,-1.759843e-006,,,,,,,,,,,,,,,,,,,,
1524661597.702,,0.000000e+000,5.499445e+001,5.499577e+001,1,0,3.741935e+000,0.000000e+000,1.990387e+000,1.990387e+000,-1.568968e-002,1.635131e-001,1.960273e+000,-4.580385e-002,1.333989e-001,3.690511e-007,3.690511e-007,,,,,,,,,,,,,,,,,,,,
1524661622.232,,0.000000e+000,5.500761e+001,5.500367e+001,1,0,3.096774e+000,0.000000e+000,2.028229e+000,2.028229e+000,3.555211e-002,1.825824e-001,2.035650e+000,4.297312e-002,1.900034e-001,1.118176e-006,1.118176e-006,,,,,,,,,,,,,,,,,,,,
1524661647.032,,0.000000e+000,5.499839e+001,5.499314e+001,1,0,2.451613e+000,0.000000e+000,2.108339e+000,2.108339e+000,1.196763e-001,2.334951e-001,2.120108e+000,1.314454e-001,2.452642e-001,2.599460e-006,2.599460e-006,,,,,,,,,,,,,,,,,,,,
1524661671.713,,0.000000e+000,5.499445e+001,5.499971e+001,1,0,1.806452e+000,0.000000e+000,2.072480e+000,2.072480e+000,8.837555e-002,1.735384e-001,2.044590e+000,6.048534e-002,1.456482e-001,1.535329e-006,1.535329e-006,,,,,,,,,,,,,,,,,,,,
1524661696.363,,0.000000e+000,5.499708e+001,5.499708e+001,1,0,1.161290e+000,0.000000e+000,1.907378e+000,1.907378e+000,-6.372119e-002,-1.058185e-002,1.936863e+000,-3.423585e-002,1.890349e-002,-2.224187e-006,-2.224187e-006,,,,,,,,,,,,,,,,,,,,
1524661721.783,,0.000000e+000,5.499971e+001,5.500235e+001,1,0,5.161290e-001,0.000000e+000,1.885100e+000,1.885100e+000,-8.304289e-002,-5.858099e-002,1.918979e+000,-4.916349e-002,-2.470160e-002,-3.061119e-006,-3.061119e-006,,,,,,,,,,,,,,,,,,,,
1524661734.303,,0.000000e+000,5.500235e+001,5.499971e+001,1,0,4.000000e+000,0.000000e+000,2.104372e+000,2.104372e+000,-4.767032e-002,1.501377e-001,2.098162e+000,-5.388041e-002,1.439276e-001,-1.293083e-007,-1.293083e-007,,,,,,,,,,,,,,,,,,,,
1524661759.733,,0.000000e+000,5.500497e+001,5.499708e+001,1,0,3.354839e+000,0.000000e+000,2.155184e+000,2.155184e+000,1.408774e-002,1.675105e-001,2.150269e+000,9.172743e-003,1.625955e-001,7.611161e-007,7.611161e-007,,,,,,,,,,,,,,,,,,,,
1524661784.963,,0.000000e+000,5.499971e+001,5.499577e+001,1,0,2.709677e+000,0.000000e+000,2.188144e+000,2.188144e+000,6.417885e-002,1.809278e-001,2.228738e+000,1.047727e-001,2.215216e-001,1.490378e-006,1.490378e-006,,,,,,,,,,,,,,,,,,,,
1524661809.953,,0.000000e+000,5.499708e+001,5.499182e+001,1,0,2.064516e+000,0.000000e+000,2.245670e+000,2.245670e+000,1.278055e-001,2.180862e-001,2.208592e+000,9.072708e-002,1.810079e-001,2.580076e-006,2.580076e-006,,,,,,,,,,,,,,,,,,,,
1524661834.923,,0.000000e+000,5.499708e+001,5.499314e+001,1,0,1.419355e+000,0.000000e+000,2.129702e+000,2.129702e+000,-5.170379e-003,5.690908e-002,2.126374e+000,-8.497749e-003,5.358171e-002,-7.428753e-007,-7.428753e-007,,,,,,,,,,,,,,,,,,,,
1524661860.283,,0.000000e+000,5.499839e+001,5.500235e+001,1,0,7.741935e-001,0.000000e+000,2.049897e+000,2.049897e+000,-1.068296e-001,-7.302642e-002,2.103484e+000,-5.324286e-002,-1.943970e-002,-3.358284e-006,-3.358284e-006,,,,,,,,,,,,,,,,,,,,
1524661885.493,,0.000000e+000,5.499577e+001,5.499314e+001,1,0,1.290323e-001,0.000000e+000,2.111238e+000,2.111238e+000,7.320555e-003,1.288271e-002,2.078439e+000,-2.547845e-002,-1.991630e-002,-1.131964e-006,-1.131964e-006,,,,,,,,,,,,,,,,,,,,
1524661897.933,,0.000000e+000,5.499314e+001,5.500497e+001,1,0,3.612903e+000,0.000000e+000,2.255741e+000,2.255741e+000,-2.645609e-002,1.397269e-001,2.254875e+000,-2.732250e-002,1.388605e-001,2.656452e-008,2.656452e-008,,,,,,,,,,,,,,,,,,,,
1524661923.103,,0.000000e+000,5.498919e+001,5.499445e+001,1,0,2.967742e+000,0.000000e+000,2.349584e+000,2.349584e+000,5.053457e-002,1.996193e-001,2.363565e+000,6.451591e-002,2.136006e-001,1.440159e-006,1.440159e-006,,,,,,,,,,,,,,,,,,,,
1524661948.373,,0.000000e+000,5.500103e+001,5.500629e+001,1,0,2.322581e+000,0.000000e+000,2.421759e+000,2.421759e+000,1.169593e-001,2.192256e-001,2.417925e+000,1.131246e-001,2.153909e-001,2.483415e-006,2.483415e-006,,,,,,,,,,,,,,,,,,,,
1524661973.563,,0.000000e+000,5.499708e+001,5.499708e+001,1,0,1.677419e+000,0.000000e+000,2.377050e+000,2.377050e+000,4.865511e-002,1.238213e-001,2.360424e+000,3.202828e-002,1.071944e-001,6.084010e-007,6.084010e-007,,,,,,,,,,,,,,,,,,,,
1524661998.803,,0.000000e+000,5.499971e+001,5.500497e+001,1,0,1.032258e+000,0.000000e+000,2.284886e+000,2.284886e+000,-7.598548e-002,-2.917266e-002,2.319774e+000,-4.109721e-002,5.715609e-003,-2.537927e-006,-2.537927e-006,,,,,,,,,,,,,,,,,,,,
1524662024.053,,0.000000e+000,5.499708e+001,5.499445e+001,1,0,3.870968e-001,0.000000e+000,2.350194e+000,2.350194e+000,-4.847392e-002,-3.349686e-002,2.363903e+000,-3.476557e-002,-1.978850e-002,-2.128283e-006,-2.128283e-006,,,,,,,,,,,,,,,,,,,,
1524662036.853,,0.000000e+000,5.499445e+001,5.500497e+001,1,0,3.870968e+000,0.000000e+000,2.538033e+000,2.538033e+000,-1.277483e-002,1.318259e-001,2.509632e+000,-4.117597e-002,1.034248e-001,2.450761e-007,2.450761e-007,,,,,,,,,,,,,,,,,,,,
1524662062.053,,0.000000e+000,5.499577e+001,5.499971e+001,1,0,3.225806e+000,0.000000e+000,2.602121e+000,2.602121e+000,2.261868e-002,1.320233e-001,2.608958e+000,2.945557e-002,1.388602e-001,7.138151e-007,7.138151e-007,,,,,,,,,,,,,,,,,,,,
1524662087.303,,0.000000e+000,5.499708e+001,5.499708e+001,1,0,2.580645e+000,0.000000e+000,2.680400e+000,2.680400e+000,8.494657e-002,1.783473e-001,2.698877e+000,1.034235e-001,1.968243e-001,1.865294e-006,1.865294e-006,,,,,,,,,,,,,,,,,,,,
1524662112.283,,0.000000e+000,5.499577e+001,5.500103e+001,1,0,1.935484e+000,0.000000e+000,2.690318e+000,2.690318e+000,9.251035e-002,1.616080e-001,2.654841e+000,5.703343e-002,1.261311e-001,1.738546e-006,1.738546e-006,,,,,,,,,,,,,,,,,,,,
1524662137.703,,0.000000e+000,5.499445e+001,5.500103e+001,1,0,1.290323e+000,0.000000e+000,2.536202e+000,2.536202e+000,-7.000808e-002,-2.056694e-002,2.578574e+000,-2.763610e-002,2.180505e-002,-2.184082e-006,-2.184082e-006,,,,,,,,,,,,,,,,,,,,
1524662163.083,,0.000000e+000,5.500103e+001,5.500103e+001,1,0,6.451613e-001,0.000000e+000,2.461128e+000,2.461128e+000,-7.421675e-002,-5.161476e-002,2.492863e+000,-4.248156e-002,-1.987958e-002,-2.496905e-006,-2.496905e-006,,,,,,,,,,,,,,,,,,,,
1524662188.073,,0.000000e+000,5.500103e+001,5.499445e+001,1,0,0.000000e+000,0.000000e+000,2.623636e+000,2.623636e+000,8.217978e-002,8.217978e-002,2.523719e+000,-1.773739e-002,-1.773739e-002,7.763883e-007,7.763883e-007,,,,,,,,,,,,,,,,,,,,
1524662200.583,,0.000000e+000,5.499182e+001,5.499839e+001,1,0,3.483871e+000,0.000000e+000,2.694896e+000,2.694896e+000,1.114398e-002,1.351693e-001,2.676385e+000,-7.366603e-003,1.166587e-001,5.764014e-007,5.764014e-007,,,,,,,,,,,,,,,,,,,,
1524662225.803,,0.000000e+000,5.499182e+001,5.500497e+001,1,0,2.838710e+000,0.000000e+000,2.757763e+000,2.757763e+000,6.214151e-002,1.770437e-001,2.782070e+000,8.644900e-002,2.013512e-001,1.499109e-006,1.499109e-006,,,,,,,,,,,,,,,,,,,,
1524662250.763,,0.000000e+000,5.499445e+001,5.499708e+001,1,0,2.193548e+000,0.000000e+000,2.824292e+000,2.824292e+000,1.081815e-001,1.887956e-001,2.797208e+000,8.109664e-002,1.617107e-001,2.233472e-006,2.233472e-006,,,,,,,,,,,,,,,,,,,,
1524662275.493,,0.000000e+000,5.499577e+001,5.500497e+001,1,0,1.548387e+000,0.000000e+000,2.738842e+000,2.738842e+000,1.881843e-002,7.699108e-002,2.722510e+000,2.486277e-003,6.065893e-002,-4.965113e-008,-4.965113e-008,,,,,,,,,,,,,,,,,,,,
1524662300.713,,0.000000e+000,5.499314e+001,5.499445e+001,1,0,9.032258e-001,0.000000e+000,2.635691e+000,2.635691e+000,-9.068455e-002,-6.128669e-002,2.679236e+000,-4.713930e-002,-1.774144e-002,-2.717556e-006,-2.717556e-006,,,,,,,,,,,,,,,,,,,,
1524662325.933,,0.000000e+000,5.499182e+001,5.499708e+001,1,0,2.580645e-001,0.000000e+000,2.728313e+000,2.728313e+000,3.121180e-003,1.309824e-002,2.701291e+000,-2.390071e-002,-1.392365e-002,-1.010660e-006,-1.010660e-006,,,,,,,,,,,,,,,,,,,,
1524662338.293,,0.000000e+000,5.499577e+001,5.499051e+001,1,0,3.741935e+000,0.000000e+000,2.870375e+000,2.870375e+000,2.815896e-004,1.250968e-001,2.838764e+000,-3.132914e-002,9.348607e-002,3.552705e-007,3.552705e-007,,,,,,,,,,,,,,,,,,,,
1524662363.053,,0.000000e+000,5.499182e+001,5.499971e+001,1,0,3.096774e+000,0.000000e+000,2.911116e+000,2.911116e+000,3.989795e-002,1.453006e-001,2.923884e+000,5.266574e-002,1.580684e-001,1.040782e-006,1.040782e-006,,,,,,,,,,,,,,,,,,,,
1524662388.784,,0.000000e+000,5.499708e+001,5.500103e+001,1,0,2.451613e+000,0.000000e+000,2.969253e+000,2.969253e+000,1.009244e-001,1.804240e-001,2.971196e+000,1.028678e-001,1.823673e-001,2.132962e-006,2.132962e-006,,,,,,,,,,,,,,,,,,,,
1524662414.334,,0.000000e+000,5.499314e+001,5.500235e+001,1,0,1.806452e+000,0.000000e+000,2.926223e+000,2.926223e+000,6.601677e-002,1.367140e-001,2.897536e+000,3.732977e-002,1.080270e-001,1.091306e-006,1.091306e-006,,,,,,,,,,,,,,,,,,,,
1524662439.284,,0.000000e+000,5.499708e+001,5.499839e+001,1,0,1.161290e+000,0.000000e+000,2.793927e+000,2.793927e+000,-5.423451e-002,-1.739979e-002,2.813663e+000,-3.449893e-002,2.335787e-003,-1.784574e-006,-1.784574e-006,,,,,,,,,,,,,,,,,,,,
1524662464.274,,0.000000e+000,5.499971e+001,5.499445e+001,1,0,5.161290e-001,0.000000e+000,2.802624e+000,2.802624e+000,-5.151457e-002,-3.326058e-002,2.821065e+000,-3.307385e-002,-1.481986e-002,-2.036002e-006,-2.036002e-006,,,,,,,,,,,,,,,,,,,,
1524662476.994,,0.000000e+000,5.499314e+001,5.499314e+001,1,0,4.000000e+000,0.000000e+000,2.972915e+000,2.972915e+000,-7.246813e-003,1.339350e-001,2.937438e+000,-4.272398e-002,9.845781e-002,3.250025e-007,3.250025e-007,,,,,,,,,,,,,,,,,,,,
1524662502.584,,0.000000e+000,5.500367e+001,5.498919e+001,1,0,3.354839e+000,0.000000e+000,2.977798e+000,2.977798e+000,2.731919e-002,1.296232e-001,2.973596e+000,2.311683e-002,1.254208e-001,7.761555e-007,7.761555e-007,,,,,,,,,,,,,,,,,,,,
1524662527.474,,0.000000e+000,5.499839e+001,5.499708e+001,1,0,2.709677e+000,0.000000e+000,2.990005e+000,2.990005e+000,3.990561e-002,1.204064e-001,3.041162e+000,9.106237e-002,1.715631e-001,8.596835e-007,8.596835e-007,,,,,,,,,,,,,,,,,,,,
1524662552.594,,0.000000e+000,5.499839e+001,5.499577e+001,1,0,2.064516e+000,0.000000e+000,3.048905e+000,3.048905e+000,1.047439e-001,1.588657e-001,3.017094e+000,7.293262e-002,1.270545e-001,2.062283e-006,2.062283e-006,,,,,,,,,,,,,,,,,,,,
1524662577.654,,0.000000e+000,5.500103e+001,5.499839e+001,1,0,1.419355e+000,0.000000e+000,2.892805e+000,2.892805e+000,-2.965871e-002,3.892899e-003,2.911356e+000,-1.110832e-002,2.244329e-002,-1.069435e-006,-1.069435e-006,,,,,,,,,,,,,,,,,,,,
1524662602.994,,0.000000e+000,5.500103e+001,5.499971e+001,1,0,7.741935e-001,0.000000e+000,2.817731e+000,2.817731e+000,-9.028854e-002,-7.164192e-002,2.864456e+000,-4.356351e-002,-2.491689e-002,-2.594505e-006,-2.594505e-006,,,,,,,,,,,,,,,,,,,,
1524662628.824,,0.000000e+000,5.499708e+001,5.500367e+001,1,0,1.290323e-001,0.000000e+000,2.920882e+000,2.920882e+000,1.767781e-002,2.092934e-002,2.884311e+000,-1.889298e-002,-1.564145e-002,-3.610767e-007,-3.610767e-007,,,,,,,,,,,,,,,,,,,,
1524662641.374,,0.000000e+000,5.499839e+001,5.500103e+001,1,0,3.612903e+000,0.000000e+000,2.972152e+000,2.972152e+000,-1.598090e-002,7.402873e-002,2.976716e+000,-1.141757e-002,7.859206e-002,-2.050074e-007,-2.050074e-007,,,,,,,,,,,,,,,,,,,,
1524662666.444,,0.000000e+000,5.499839e+001,5.499839e+001,1,0,2.967742e+000,0.000000e+000,3.014725e+000,3.014725e+000,4.504104e-002,1.098344e-001,3.038794e+000,6.910940e-002,1.339028e-001,9.394862e-007,9.394862e-007,,,,,,,,,,,,,,,,,,,,
1524662691.414,,0.000000e+000,5.499445e+001,5.499445e+001,1,0,2.322581e+000,0.000000e+000,3.058976e+000,3.058976e+000,1.063628e-001,1.617754e-001,3.036472e+000,8.385843e-002,1.392710e-001,2.158617e-006,2.158617e-006,,,,,,,,,,,,,,,,,,,,
1524662716.564,,0.000000e+000,5.499445e+001,5.499182e+001,1,0,1.677419e+000,0.000000e+000,2.970779e+000,2.970779e+000,2.728132e-002,6.681728e-002,2.951897e+000,8.399757e-003,4.793572e-002,2.692832e-007,2.692832e-007,,,,,,,,,,,,,,,,,,,,
1524662741.464,,0.000000e+000,5.499708e+001,5.500629e+001,1,0,1.032258e+000,0.000000e+000,2.838483e+000,2.838483e+000,-7.894324e-002,-5.485058e-002,2.873869e+000,-4.355715e-002,-1.946449e-002,-2.260771e-006,-2.260771e-006,,,,,,,,,,,,,,,,,,,,
1524662766.484,,0.000000e+000,5.499314e+001,5.499577e+001,1,0,3.870968e-001,0.000000e+000,2.870680e+000,2.870680e+000,-2.659065e-002,-1.680732e-002,2.874234e+000,-2.303631e-002,-1.325297e-002,-1.269625e-006,-1.269625e-006,,,,,,,,,,,,,,,,,,,,
1524662779.404,,0.000000e+000,5.499577e+001,5.499971e+001,1,0,3.870968e+000,0.000000e+000,2.985428e+000,2.985428e+000,1.695225e-002,1.030860e-001,2.944165e+000,-2.431085e-002,6.182289e-002,4.248141e-007,4.248141e-007,,,,,,,,,,,,,,,,,,,,
1524662805.014,,0.000000e+000,5.499971e+001,5.499314e+001,1,0,3.225806e+000,0.000000e+000,2.966964e+000,2.966964e+000,1.057062e-002,1.000922e-001,2.998080e+000,4.168687e-002,1.312084e-001,2.993183e-007,2.993183e-007,,,,,,,,,,,,,,,,,,,,
1524662830.574,,0.000000e+000,5.499708e+001,5.499839e+001,1,0,2.580645e+000,0.000000e+000,3.004044e+000,3.004044e+000,5.502770e-002,1.299536e-001,3.045626e+000,9.661052e-002,1.715364e-001,1.148306e-006,1.148306e-006,,,,,,,,,,,,,,,,,,,,
1524662855.794,,0.000000e+000,5.499708e+001,5.499577e+001,1,0,1.935484e+000,0.000000e+000,2.998550e+000,2.998550e+000,6.729218e-002,1.109927e-001,2.957595e+000,2.633664e-002,7.003713e-002,1.212204e-006,1.212204e-006,,,,,,,,,,,,,,,,,,,,
1524662881.034,,0.000000e+000,5.499314e+001,5.499971e+001,1,0,1.290323e+000,0.000000e+000,2.844587e+000,2.844587e+000,-7.271896e-002,-3.997064e-002,2.881891e+000,-3.541503e-002,-2.666712e-003,-2.091620e-006,-2.091620e-006,,,,,,,,,,,,,,,,,,,,
1524662905.584,,0.000000e+000,5.499445e+001,5.499577e+001,1,0,6.451613e-001,0.000000e+000,2.830701e+000,2.830701e+000,-1.037789e-001,-9.068251e-002,2.899469e+000,-3.501112e-002,-2.191472e-002,-2.836081e-006,-2.836081e-006,,,,,,,,,,,,,,,,,,,,
1524662931.004,,0.000000e+000,5.499839e+001,5.500235e+001,1,0,0.000000e+000,0.000000e+000,3.044327e+000,3.044327e+000,1.153412e-001,1.153412e-001,2.917419e+000,-1.156688e-002,-1.156688e-002,1.806664e-006,1.806664e-006,,,,,,,,,,,,,,,,,,,,
1524662943.694,,0.000000e+000,5.500497e+001,5.499314e+001,1,0,3.483871e+000,0.000000e+000,3.015183e+000,3.015183e+000,-8.565180e-004,7.342958e-002,3.034266e+000,1.822698e-002,9.251308e-002,-4.518370e-008,-4.518370e-008,,,,,,,,,,,,,,,,,,,,
1524662968.944,,0.000000e+000,5.499577e+001,5.500367e+001,1,0,2.838710e+000,0.000000e+000,3.071489e+000,3.071489e+000,6.423479e-002,1.241887e-001,3.099064e+000,9.180980e-002,1.517637e-001,1.294320e-006,1.294320e-006,,,,,,,,,,,,,,,,,,,,
1524662994.104,,0.000000e+000,5.499445e+001,5.499577e+001,1,0,2.193548e+000,0.000000e+000,3.088121e+000,3.088121e+000,9.762373e-002,1.385133e-001,3.051892e+000,6.139483e-002,1.022844e-001,1.923996e-006,1.923996e-006,,,,,,,,,,,,,,,,,,,,
1524663019.534,,0.000000e+000,5.499839e+001,5.500235e+001,1,0,1.548387e+000,0.000000e+000,2.964370e+000,2.964370e+000,-1.089608e-002,2.014709e-002,2.956868e+000,-1.839864e-002,1.264453e-002,-6.016635e-007,-6.016635e-007,,,,,,,,,,,,,,,,,,,,
1524663045.554,,0.000000e+000,5.498919e+001,5.499708e+001,1,0,9.032258e-001,0.000000e+000,2.851148e+000,2.851148e+000,-1.000018e-001,-8.110023e-002,2.910362e+000,-4.078790e-002,-2.188635e-002,-2.711022e-006,-2.711022e-006,,,,,,,,,,,,,,,,,,,,
1524663070.764,,0.000000e+000,5.499314e+001,5.499708e+001,1,0,2.580645e-001,0.000000e+000,2.953231e+000,2.953231e+000,1.730645e-003,6.533623e-003,2.936732e+000,-1.476864e-002,-9.965658e-003,-4.745234e-007,-4.745234e-007,,,,,,,,,,,,,,,,,,,,
1524663082.954,,0.000000e+000,5.499839e+001,5.499708e+001,1,0,3.741935e+000,0.000000e+000,3.019913e+000,3.019913e+000,-7.165572e-003,7.112670e-002,3.013532e+000,-1.354684e-002,6.474543e-002,-1.371955e-007,-1.371955e-007,,,,,,,,,,,,,,,,,,,,
1524663107.635,,0.000000e+000,5.499051e+001,5.499314e+001,1,0,3.096774e+000,0.000000e+000,3.044327e+000,3.044327e+000,4.636285e-002,1.127205e-001,3.067562e+000,6.959745e-002,1.359551e-001,9.412615e-007,9.412615e-007,,,,,,,,,,,,,,,,,,,,
1524663132.885,,0.000000e+000,5.500235e+001,5.500103e+001,1,0,2.451613e+000,0.000000e+000,3.059587e+000,3.059587e+000,8.986668e-002,1.318908e-001,3.050268e+000,8.054832e-002,1.225724e-001,1.768742e-006,1.768742e-006,,,,,,,,,,,,,,,,,,,,
1524663158.245,,0.000000e+000,5.499971e+001,5.500497e+001,1,0,1.806452e+000,0.000000e+000,3.003128e+000,3.003128e+000,4.527759e-002,7.488680e-002,2.961577e+000,3.726236e-003,3.333545e-002,6.960763e-007,6.960763e-007,,,,,,,,,,,,,,,,,,,,
1524663183.705,,0.000000e+000,5.499182e+001,5.499708e+001,1,0,1.161290e+000,0.000000e+000,2.878309e+000,2.878309e+000,-6.505606e-002,-4.506350e-002,2.904314e+000,-3.905174e-002,-1.905918e-002,-1.824461e-006,-1.824461e-006,,,,,,,,,,,,,,,,,,,,
1524663209.015,,0.000000e+000,5.499971e+001,5.499182e+001,1,0,5.161290e-001,0.000000e+000,2.883955e+000,2.883955e+000,-5.878829e-002,-4.779172e-002,2.920571e+000,-2.217244e-002,-1.117587e-002,-1.850174e-006,-1.850174e-006,,,,,,,,,,,,,,,,,,,,
1524663221.675,,0.000000e+000,5.500892e+001,5.499708e+001,1,0,4.000000e+000,0.000000e+000,3.038376e+000,3.038376e+000,1.920350e-002,9.376788e-002,2.987932e+000,-3.124110e-002,4.332328e-002,4.080939e-007,4.080939e-007,,,,,,,,,,,,,,,,,,,,
1524663246.925,,0.000000e+000,5.499182e+001,5.500235e+001,1,0,3.354839e+000,0.000000e+000,3.037308e+000,3.037308e+000,1.200313e-002,7.961488e-002,3.061990e+000,3.668470e-002,1.042964e-001,1.934095e-007,1.934095e-007,,,,,,,,,,,,,,,,,,,,
1524663272.185,,0.000000e+000,5.499839e+001,5.500103e+001,1,0,2.709677e+000,0.000000e+000,3.107805e+000,3.107805e+000,7.385098e-002,1.202595e-001,3.131503e+000,9.754883e-002,1.439574e-001,1.440261e-006,1.440261e-006,,,,,,,,,,,,,,,,,,,,
1524663297.515,,0.000000e+000,5.499577e+001,5.499839e+001,1,0,2.064516e+000,0.000000e+000,3.095140e+000,3.095140e+000,6.426321e-002,9.588099e-002,3.053982e+000,2.310477e-002,5.472255e-002,1.138586e-006,1.138586e-006,,,,,,,,,,,,,,,,,,,,
1524663322.805,,0.000000e+000,5.499577e+001,5.500367e+001,1,0,1.419355e+000,0.000000e+000,2.985885e+000,2.985885e+000,-4.078318e-002,-2.015924e-002,2.992977e+000,-3.369142e-002,-1.306748e-002,-1.237713e-006,-1.237713e-006,,,,,,,,,,,,,,,,,,,,
1524663348.685,,0.000000e+000,5.499708e+001,5.499708e+001,1,0,7.741935e-001,0.000000e+000,2.918135e+000,2.918135e+000,-1.054966e-001,-9.669065e-002,2.993708e+000,-2.992360e-002,-2.111769e-002,-2.662666e-006,-2.662666e-006,,,,,,,,,,,,,,,,,,,,
1524663374.005,,0.000000e+000,5.499577e+001,5.499314e+001,1,0,1.290323e-001,0.000000e+000,3.054246e+000,3.054246e+000,4.102994e-002,4.329491e-002,3.002824e+000,-1.039170e-002,-8.126736e-003,4.283356e-007,4.283356e-007,,,,,,,,,,,,,,,,,,,,
1524663386.725,,0.000000e+000,5.499445e+001,5.500235e+001,1,0,3.612903e+000,0.000000e+000,3.091326e+000,3.091326e+000,1.398767e-002,7.325959e-002,3.090559e+000,1.322163e-002,7.249355e-002,1.833978e-007,1.833978e-007,,,,,,,,,,,,,,,,,,,,
1524663411.955,,0.000000e+000,5.499708e+001,5.499182e+001,1,0,2.967742e+000,0.000000e+000,3.124285e+000,3.124285e+000,5.252557e-002,9.511447e-002,3.153260e+000,8.150058e-002,1.240895e-001,9.672949e-007,9.672949e-007,,,,,,,,,,,,,,,,,,,,
1524663437.185,,0.000000e+000,5.500367e+001,5.499708e+001,1,0,2.322581e+000,0.000000e+000,3.150530e+000,3.150530e+000,8.680334e-002,1.270742e-001,3.121958e+000,5.823126e-002,9.850216e-002,1.701308e-006,1.701308e-006,,,,,,,,,,,,,,,,,,,,
1524663462.415,,0.000000e+000,5.500103e+001,5.499971e+001,1,0,1.677419e+000,0.000000e+000,3.076066e+000,3.076066e+000,1.421435e-002,3.492737e-002,3.045577e+000,-1.627462e-002,4.438400e-003,3.894093e-008,3.894093e-008,,,,,,,,,,,,,,,,,,,,
1524663487.635,,0.000000e+000,5.499839e+001,5.500367e+001,1,0,1.032258e+000,0.000000e+000,2.972152e+000,2.972152e+000,-7.741363e-002,-6.293726e-002,3.016076e+000,-3.349025e-002,-1.901388e-002,-2.053115e-006,-2.053115e-006,,,,,,,,,,,,,,,,,,,,
1524663512.295,,0.000000e+000,5.500103e+001,5.499839e+001,1,0,3.870968e-001,0.000000e+000,3.028763e+000,3.028763e+000,-1.592843e-002,-1.020360e-002,3.029197e+000,-1.549451e-002,-9.769678e-003,-7.484487e-007,-7.484487e-007,,,,,,,,,,,,,,,,,,,,
1524663524.835,,0.000000e+000,5.500103e+001,5.499971e+001,1,0,3.870968e+000,0.000000e+000,3.118029e+000,3.118029e+000,1.717823e-002,8.241987e-002,3.097885e+000,-2.965753e-003,6.227589e-002,3.798486e-007,3.798486e-007,,,,,,,,,,,,,,,,,,,,
1524663549.625,,0.000000e+000,5.499971e+001,5.499971e+001,1,0,3.225806e+000,0.000000e+000,3.118639e+000,3.118639e+000,3.009904e-002,8.357072e-002,3.149134e+000,6.059373e-002,1.140654e-001,5.750771e-007,5.750771e-007,,,,,,,,,,,,,,,,,,,,
1524663575.595,,0.000000e+000,5.499839e+001,5.501024e+001,1,0,2.580645e+000,0.000000e+000,3.150073e+000,3.150073e+000,7.176971e-002,1.183956e-001,3.156376e+000,7.807302e-002,1.246989e-001,1.420529e-006,1.420529e-006,,,,,,,,,,,,,,,,,,,,
1524663601.295,,0.000000e+000,5.499182e+001,5.499708e+001,1,0,1.935484e+000,0.000000e+000,3.116045e+000,3.116045e+000,6.511479e-002,7.321239e-002,3.054193e+000,3.262572e-003,1.136017e-002,1.176173e-006,1.176173e-006,,,,,,,,,,,,,,,,,,,,
1524663626.475,,0.000000e+000,5.499839e+001,5.499314e+001,1,0,1.290323e+000,0.000000e+000,2.923476e+000,2.923476e+000,-7.674839e-002,-6.075144e-002,2.963912e+000,-3.631188e-002,-2.031493e-002,-2.003260e-006,-2.003260e-006,,,,,,,,,,,,,,,,,,,,
1524663651.145,,0.000000e+000,5.499708e+001,5.499182e+001,1,0,6.451613e-001,0.000000e+000,2.904555e+000,2.904555e+000,-6.925412e-002,-6.268644e-002,2.956511e+000,-1.729747e-002,-1.072979e-002,-1.805514e-006,-1.805514e-006,,,,,,,,,,,,,,,,,,,,
1524663676.435,,0.000000e+000,5.500235e+001,5.499839e+001,1,0,0.000000e+000,0.000000e+000,3.055314e+000,3.055314e+000,1.060593e-001,1.060593e-001,2.945702e+000,-3.552437e-003,-3.552437e-003,1.990775e-006,1.990775e-006,,,,,,,,,,,,,,,,,,,,
1524663689.735,,0.000000e+000,5.500235e+001,5.499314e+001,1,0,3.483871e+000,0.000000e+000,3.013810e+000,3.013810e+000,3.056623e-002,6.632471e-002,3.021062e+000,3.781893e-002,7.357740e-002,4.231260e-007,4.231260e-007,,,,,,,,,,,,,,,,,,,,
1524663716.975,,0.000000e+000,5.499314e+001,5.499577e+001,1,0,2.838710e+000,0.000000e+000,3.015946e+000,3.015946e+000,2.155031e-002,1.049662e-001,2.998813e+000,4.417077e-003,8.783293e-002,7.861090e-007,7.861090e-007,,,,,,,,,,,,,,,,,,,,
1524663741.035,,0.000000e+000,5.499971e+001,5.500497e+001,1,0,2.193548e+000,0.000000e+000,3.036850e+000,3.036850e+000,7.633612e-002,1.011755e-001,3.008106e+000,4.759142e-002,7.243085e-002,1.430104e-006,1.430104e-006,,,,,,,,,,,,,,,,,,,,
1524663766.195,,0.000000e+000,5.499708e+001,5.500497e+001,1,0,1.548387e+000,0.000000e+000,2.931258e+000,2.931258e+000,-2.758953e-002,2.178383e-002,2.961556e+000,2.708463e-003,5.208182e-002,-8.182396e-007,-8.182396e-007,,,,,,,,,,,,,,,,,,,,
1524663790.735,,0.000000e+000,5.500235e+001,5.499182e+001,1,0,9.032258e-001,0.000000e+000,2.862898e+000,2.862898e+000,-8.996486e-002,-7.936764e-002,2.927802e+000,-2.506088e-002,-1.446366e-002,-2.293542e-006,-2.293542e-006,,,,,,,,,,,,,,,,,,,,
1524663816.036,,0.000000e+000,5.500235e+001,5.500892e+001,1,0,2.580645e-001,0.000000e+000,2.962844e+000,2.962844e+000,1.809071e-002,2.054214e-002,2.932347e+000,-1.240637e-002,-9.954929e-003,1.434673e-007,1.434673e-007,,,,,,,,,,,,,,,,,,,,
1524663830.578,,0.000000e+000,5.500892e+001,5.498262e+001,1,0,3.741935e+000,0.000000e+000,2.992447e+000,2.992447e+000,-1.820626e-002,8.333302e-002,2.999316e+000,-1.133743e-002,9.020185e-002,2.387096e-007,2.387096e-007,,,,,,,,,,,,,,,,,,,,
1524663856.750,,0.000000e+000,5.500497e+001,5.499971e+001,1,0,3.096774e+000,0.000000e+000,2.990158e+000,2.990158e+000,2.173338e-002,6.897449e-002,3.007702e+000,3.927717e-002,8.651829e-002,5.145994e-007,5.145994e-007,,,,,,,,,,,,,,,,,,,,
1524663885.174,,0.000000e+000,5.499445e+001,5.499577e+001,1,0,2.451613e+000,0.000000e+000,3.038071e+000,3.038071e+000,6.933267e-002,1.407704e-001,2.984672e+000,1.593383e-002,8.737159e-002,1.691747e-006,1.691747e-006,,,,,,,,,,,,,,,,,,,,
1524663912.256,,0.000000e+000,5.499577e+001,5.499971e+001,1,0,1.806452e+000,0.000000e+000,2.961166e+000,2.961166e+000,2.512831e-002,7.570672e-002,2.958495e+000,2.245778e-002,7.303619e-002,4.273461e-007,4.273461e-007,,,,,,,,,,,,,,,,,,,,
1524663938.718,,0.000000e+000,5.499708e+001,5.499839e+001,1,0,1.161290e+000,0.000000e+000,2.851148e+000,2.851148e+000,-7.976572e-002,-7.062936e-002,2.903481e+000,-2.743308e-002,-1.829672e-002,-1.993714e-006,-1.993714e-006,,,,,,,,,,,,,,,,,,,,
1524663965.520,,0.000000e+000,5.500235e+001,5.499839e+001,1,0,5.161290e-001,0.000000e+000,2.883345e+000,2.883345e+000,-2.667500e-002,-1.172161e-002,2.899354e+000,-1.066639e-002,4.287004e-003,-1.293447e-006,-1.293447e-006,,,,,,,,,,,,,,,,,,,,
1524663980.182,,0.000000e+000,5.500103e+001,5.499708e+001,1,0,4.000000e+000,0.000000e+000,2.975662e+000,2.975662e+000,-3.064851e-002,6.968904e-002,2.998928e+000,-7.381954e-003,9.295559e-002,1.450826e-008,1.450826e-008,,,,,,,,,,,,,,,,,,,,
1524664008.246,,0.000000e+000,5.500367e+001,5.499971e+001,1,0,3.354839e+000,0.000000e+000,2.981308e+000,2.981308e+000,-3.386046e-003,8.536077e-002,2.976710e+000,-7.983711e-003,8.076310e-002,4.085741e-007,4.085741e-007,,,,,,,,,,,,,,,,,,,,
1524664036.340,,0.000000e+000,5.498130e+001,5.500103e+001,1,0,2.709677e+000,0.000000e+000,3.011979e+000,3.011979e+000,4.416664e-002,1.145153e-001,2.975357e+000,7.545071e-003,7.789373e-002,1.209206e-006,1.209206e-006,,,,,,,,,,,,,,,,,,,,
1524664064.974,,0.000000e+000,5.500629e+001,5.499839e+001,1,0,2.064516e+000,0.000000e+000,2.976883e+000,2.976883e+000,3.065180e-002,8.581424e-002,2.965678e+000,1.944685e-002,7.460928e-002,6.675255e-007,6.675255e-007,,,,,,,,,,,,,,,,,,,,
1524664092.648,,0.000000e+000,5.500235e+001,5.499577e+001,1,0,1.419355e+000,0.000000e+000,2.883040e+000,2.883040e+000,-4.627385e-002,-1.010752e-002,2.941061e+000,1.174746e-002,4.791379e-002,-1.308057e-006,-1.308057e-006,,,,,,,,,,,,,,,,,,,,
1524664121.102,,0.000000e+000,5.500235e+001,5.500103e+001,1,0,7.741935e-001,0.000000e+000,2.854200e+000,2.854200e+000,-5.308264e-002,-3.369570e-002,2.900989e+000,-6.293705e-003,1.309323e-002,-1.697408e-006,-1.697408e-006,,,,,,,,,,,,,,,,,,,,
1524664149.506,,0.000000e+000,5.499182e+001,5.500103e+001,1,0,1.290323e-001,0.000000e+000,2.956130e+000,2.956130e+000,7.366262e-002,7.684159e-002,2.876933e+000,-5.534785e-003,-2.355814e-003,9.281794e-007,9.281794e-007,,,,,,,,,,,,,,,,,,,,
1524664164.388,,0.000000e+000,5.499839e+001,5.500367e+001,1,0,3.612903e+000,0.000000e+000,2.959029e+000,2.959029e+000,-8.557705e-003,8.318329e-002,2.960410e+000,-7.177262e-003,8.456373e-002,3.828027e-007,3.828027e-007,,,,,,,,,,,,,,,,,,,,
1524664192.612,,0.000000e+000,5.499708e+001,5.499182e+001,1,0,2.967742e+000,0.000000e+000,2.833905e+000,2.833905e+000,1.705729e-002,8.168721e-002,2.816893e+000,4.493515e-005,6.467485e-002,6.576302e-007,6.576302e-007,,,,,,,,,,,,,,,,,,,,
1524664220.536,,0.000000e+000,5.499708e+001,5.499577e+001,1,0,2.322581e+000,0.000000e+000,2.734722e+000,2.734722e+000,4.966915e-002,1.059382e-001,2.698131e+000,1.307857e-002,6.934762e-002,1.190725e-006,1.190725e-006,,,,,,,,,,,,,,,,,,,,
1524664249.050,,0.000000e+000,5.499577e+001,5.500103e+001,1,0,1.677419e+000,0.000000e+000,2.689860e+000,2.689860e+000,-8.475969e-003,3.830719e-002,2.715408e+000,1.707201e-002,6.385517e-002,-3.702444e-007,-3.702444e-007,,,,,,,,,,,,,,,,,,,,
1524664275.202,,0.000000e+000,5.499445e+001,5.499708e+001,1,0,1.032258e+000,0.000000e+000,2.508126e+000,2.508126e+000,-1.280489e-001,-1.397071e-001,2.504683e+000,-1.314914e-001,-1.431496e-001,-2.012806e-006,-2.012806e-006,,,,,,,,,,,,,,,,,,,,
1524664304.956,,0.000000e+000,5.500235e+001,5.500367e+001,1,0,3.870968e-001,0.000000e+000,2.490883e+000,2.490883e+000,1.771182e-002,2.546859e-002,2.464613e+000,-8.557376e-003,-8.006096e-004,-1.288063e-007,-1.288063e-007,,,,,,,,,,,,,,,,,,,,
1524664319.438,,0.000000e+000,5.500761e+001,5.500497e+001,1,0,3.870968e+000,0.000000e+000,2.550393e+000,2.550393e+000,-1.517750e-002,7.754207e-002,2.560225e+000,-5.346070e-003,8.737350e-002,2.982270e-007,2.982270e-007,,,,,,,,,,,,,,,,,,,,
1524664348.252,,0.000000e+000,5.500103e+001,5.499445e+001,1,0,3.225806e+000,0.000000e+000,2.620432e+000,2.620432e+000,2.137635e-002,9.785461e-002,2.593514e+000,-5.541818e-003,7.093644e-002,8.635179e-007,8.635179e-007,,,,,,,,,,,,,,,,,,,,
1524664374.814,,0.000000e+000,5.500235e+001,5.500103e+001,1,0,2.580645e+000,0.000000e+000,2.663157e+000,2.663157e+000,4.893508e-002,1.265144e-002,2.675838e+000,6.161656e-002,2.533293e-002,1.271808e-006,1.271808e-006,,,,,,,,,,,,,,,,,,,,
1524664403.268,,0.000000e+000,5.499577e+001,5.500103e+001,1,0,1.935484e+000,0.000000e+000,2.640726e+000,2.640726e+000,9.619633e-003,6.458187e-002,2.645978e+000,1.487128e-002,6.983352e-002,1.546287e-007,1.546287e-007,,,,,,,,,,,,,,,,,,,,
1524664431.992,,0.000000e+000,5.499577e+001,5.499971e+001,1,0,1.290323e+000,0.000000e+000,2.581369e+000,2.581369e+000,-6.295005e-002,-2.808022e-002,2.648807e+000,4.487832e-003,3.935766e-002,-1.723864e-006,-1.723864e-006,,,,,,,,,,,,,,,,,,,,
1524664460.056,,0.000000e+000,5.499839e+001,5.499577e+001,1,0,6.451613e-001,0.000000e+000,2.619669e+000,2.619669e+000,-4.063545e-002,-2.392101e-002,2.654436e+000,-5.868773e-003,1.084566e-002,-1.467779e-006,-1.467779e-006,,,,,,,,,,,,,,,,,,,,
1524664488.340,,0.000000e+000,5.499577e+001,5.498656e+001,1,0,0.000000e+000,0.000000e+000,2.812238e+000,2.812238e+000,1.378648e-001,1.378648e-001,2.669737e+000,-4.636049e-003,-4.636049e-003,2.264453e-006,2.264453e-006,,,,,,,,,,,,,,,,,,,,
1524664503.112,,0.000000e+000,5.500235e+001,5.499577e+001,1,0,3.483871e+000,0.000000e+000,2.785992e+000,2.785992e+000,5.592965e-005,9.383368e-002,2.779782e+000,-6.154874e-003,8.762288e-002,5.636393e-007,5.636393e-007,,,,,,,,,,,,,,,,,,,,
1524664530.715,,0.000000e+000,5.500103e+001,5.500103e+001,1,0,2.838710e+000,0.000000e+000,2.825666e+000,2.825666e+000,3.956008e-002,5.183697e-003,2.840781e+000,5.467534e-002,2.029896e-002,9.540672e-007,9.540672e-007,,,,,,,,,,,,,,,,,,,,
1524664559.459,,0.000000e+000,5.499971e+001,5.499971e+001,1,0,2.193548e+000,0.000000e+000,2.842298e+000,2.842298e+000,3.845003e-002,9.003401e-002,2.818870e+000,1.502183e-002,6.660581e-002,8.913776e-007,8.913776e-007,,,,,,,,,,,,,,,,,,,,
1524664585.581,,0.000000e+000,5.500103e+001,5.499577e+001,1,0,1.548387e+000,0.000000e+000,2.784009e+000,2.784009e+000,-7.058399e-002,-8.644724e-002,2.785472e+000,-6.912058e-002,-8.498383e-002,-9.389623e-007,-9.389623e-007,,,,,,,,,,,,,,,,,,,,
1524664612.673,,0.000000e+000,5.499971e+001,5.499708e+001,1,0,9.032258e-001,0.000000e+000,2.733959e+000,2.733959e+000,-8.911790e-002,-6.690073e-002,2.820383e+000,-2.693549e-003,1.952362e-002,-2.437038e-006,-2.437038e-006,,,,,,,,,,,,,,,,,,,,
1524664639.185,,0.000000e+000,5.499314e+001,5.499182e+001,1,0,2.580645e-001,0.000000e+000,2.883497e+000,2.883497e+000,-2.689288e-002,-2.977133e-002,2.873881e+000,-3.650926e-002,-3.938770e-002,5.531765e-007,5.531765e-007,,,,,,,,,,,,,,,,,,,,
1524664653.747,,0.000000e+000,5.501682e+001,5.500235e+001,1,0,3.741935e+000,0.000000e+000,2.894636e+000,2.894636e+000,-1.457456e-002,6.943274e-002,2.903348e+000,-5.862511e-003,7.814479e-002,2.265879e-007,2.265879e-007,,,,,,,,,,,,,,,,,,,,
1524664679.429,,0.000000e+000,5.500235e+001,5.500103e+001,1,0,3.096774e+000,0.000000e+000,2.941634e+000,2.941634e+000,3.502582e-002,3.889084e-003,2.946424e+000,3.981588e-002,8.679152e-003,7.655617e-007,7.655617e-007,,,,,,,,,,,,,,,,,,,,
1524664705.951,,0.000000e+000,5.500892e+001,5.499577e+001,1,0,2.451613e+000,0.000000e+000,2.965133e+000,2.965133e+000,4.372755e-002,1.056337e-002,2.979797e+000,5.839149e-002,2.522731e-002,1.229942e-006,1.229942e-006,,,,,,,,,,,,,,,,,,,,
1524664733.575,,0.000000e+000,5.499051e+001,5.500629e+001,1,0,1.806452e+000,0.000000e+000,2.920119e+000,2.920119e+000,-4.925416e-004,4.378009e-002,2.935545e+000,1.493314e-002,5.920577e-002,-1.172739e-007,-1.172739e-007,,,,,,,,,,,,,,,,,,,,
1524664759.877,,0.000000e+000,5.499839e+001,5.499839e+001,1,0,1.161290e+000,0.000000e+000,2.835889e+000,2.835889e+000,-8.092576e-002,-4.983544e-002,2.919036e+000,2.220812e-003,3.331113e-002,-2.174784e-006,-2.174784e-006,,,,,,,,,,,,,,,,,,,,
1524664784.687,,0.000000e+000,5.499314e+001,5.500103e+001,1,0,5.161290e-001,0.000000e+000,2.868238e+000,2.868238e+000,-1.158357e-001,-1.211617e-001,2.898287e+000,-8.578737e-002,-9.111333e-002,-1.516761e-006,-1.516761e-006,,,,,,,,,,,,,,,,,,,,
1524664799.249,,0.000000e+000,5.500103e+001,5.500367e+001,1,0,4.000000e+000,0.000000e+000,2.984665e+000,2.984665e+000,-1.670682e-002,7.741094e-002,2.996454e+000,-4.917021e-003,8.920074e-002,2.957822e-007,2.957822e-007,,,,,,,,,,,,,,,,,,,,
1524664826.191,,0.000000e+000,5.500497e+001,5.499051e+001,1,0,3.354839e+000,0.000000e+000,3.009232e+000,3.009232e+000,-2.625027e-003,8.320451e-002,3.007045e+000,-4.811802e-003,8.101773e-002,4.277827e-007,4.277827e-007,,,,,,,,,,,,,,,,,,,,
1524664852.263,,0.000000e+000,5.500235e+001,5.499051e+001,1,0,2.709677e+000,0.000000e+000,3.043107e+000,3.043107e+000,3.986312e-002,1.098354e-001,3.009069e+000,5.825766e-003,7.579803e-002,1.123481e-006,1.123481e-006,,,,,,,,,,,,,,,,,,,,
1524664879.045,,0.000000e+000,5.499839e+001,5.499314e+001,1,0,2.064516e+000,0.000000e+000,3.055619e+000,3.055619e+000,4.774248e-002,1.017151e-001,3.021441e+000,1.356375e-002,6.753635e-002,1.062013e-006,1.062013e-006,,,,,,,,,,,,,,,,,,,,
1524664879.045,,0.000000e+000,5.499839e+001,5.499314e+001,1,0,4.000000e+000,0.000000e+000,3.038224e+000,3.038224e+000,-2.025233e-002,8.431959e-002,3.053843e+000,-4.633293e-003,9.993863e-002,2.962624e-007,2.962624e-007,,,,,,,,,,,,,,,,,,,,