File: Experimental Raw Data/MFn1 Acquisition/MFn1_VRMac_33K_6000s.dc.dat
[Header]
TITLE,MPMS DC Measurement
BYAPP,MPMS Measurement,2.1,Summary
FILEOPENTIME, 1524127786.057000 4/19/2018, 2:49:46 AM

INFO, APPNAME, MPMS MultiVu Application, Revision 1.61,  Build 082

INFO, NAME, MFn1
INFO, WEIGHT, 1.000
INFO, AREA, 1.000
INFO, LENGTH, 1.000
INFO, SHAPE, 0
INFO, COMMENT,
INFO, SEQUENCE FILE: VRMac_33K_6000s_VRMde_35K.seq


INFO, BACKGROUND DATA FILE:, None


STARTUPAXIS,X,4,LINEAR,AUTO,0.000000,0.000000
STARTUPAXIS,Y1,5,LINEAR,AUTO,0.000000,0.000000


STARTUPGROUP,Longitudinal
FIELDGROUP,Longitudinal,1,2,3,4,5,6,7,8,9,15,16,17,18,27,28
FIELDGROUP,Transverse,1,2,3,4,10,11,12,13,14,19,20,21,22,27,28

PLOT_APPEARANCE,ALL,HORZ_GRID_ON,VERT_GRID_ON,MARKERS_AND_LINES

[Data]
Time,Comment,Field (Oe),Temperature (K),Long Moment (emu),Long Scan Std Dev,Long Algorithm,Long Reg Fit,Long Percent Error (%),Trans Moment (emu),Trans Scan Std Dev,Trans Algorithm,Trans Reg Fit,Trans Percent Error (%),Long Moment [w/o ABS] (emu),Long Scan Std Dev [w/o ABS],Long Reg Fit [w/o ABS],Long Percent Error [w/o ABS] (%),Trans Moment [w/o ABS] (emu),Trans Scan Std Dev [w/o ABS],Trans Reg Fit [w/o ABS],Trans Percent Error [w/o ABS] (%),Points per Scan,Scans per Measurement,Scan Length (cm),Delta Temp (K),Rot Position (deg),Error,EC Comp. Running,Using ABS,
1524127786.054,,0.000000e+000,3.299750e+001,-1.689339e-004,0.000000e+000,3,9.921554e-001,0.000000e+000,,,,,,,,,,,,,,32,1,4.000000e+000,2.758026e-003,0.000000e+000,0,,0,
1524127811.392,,0.000000e+000,3.300060e+001,-1.718253e-004,0.000000e+000,3,9.924691e-001,0.000000e+000,,,,,,,,,,,,,,32,1,4.000000e+000,6.904602e-004,0.000000e+000,0,,0,
1524127836.317,,0.000000e+000,3.300095e+001,-1.735836e-004,0.000000e+000,3,9.926379e-001,0.000000e+000,,,,,,,,,,,,,,32,1,4.000000e+000,0.000000e+000,0.000000e+000,0,,0,
1524127862.290,,0.000000e+000,3.299957e+001,-1.748186e-004,0.000000e+000,3,9.924994e-001,0.000000e+000,,,,,,,,,,,,,,32,1,4.000000e+000,0.000000e+000,0.000000e+000,0,,0,
1524127888.018,,0.000000e+000,3.299923e+001,-1.758209e-004,0.000000e+000,3,9.925185e-001,0.000000e+000,,,,,,,,,,,,,,32,1,4.000000e+000,2.067566e-003,0.000000e+000,0,,0,
1524127913.263,,0.000000e+000,3.299819e+001,-1.766887e-004,0.000000e+000,3,9.925371e-001,0.000000e+000,,,,,,,,,,,,,,32,1,4.000000e+000,0.000000e+000,0.000000e+000,0,,0,
1524127938.009,,0.000000e+000,3.299854e+001,-1.772300e-004,0.000000e+000,3,9.924455e-001,0.000000e+000,,,,,,,,,,,,,,32,1,4.000000e+000,2.067566e-003,0.000000e+000,0,,0,
1524127963.339,,0.000000e+000,3.299785e+001,-1.779093e-004,0.000000e+000,3,9.927980e-001,0.000000e+000,,,,,,,,,,,,,,32,1,4.000000e+000,6.904602e-004,0.000000e+000,0,,0,
1524127989.430,,0.000000e+000,3.299750e+001,-1.785062e-004,0.000000e+000,3,9.927600e-001,0.000000e+000,,,,,,,,,,,,,,32,1,4.000000e+000,1.392365e-003,0.000000e+000,0,,0,
1524128014.605,,0.000000e+000,3.299819e+001,-1.790116e-004,0.000000e+000,3,9.926431e-001,0.000000e+000,,,,,,,,,,,,,,32,1,4.000000e+000,1.377106e-003,0.000000e+000,0,,0,
1524128040.275,,0.000000e+000,3.299750e+001,-1.794230e-004,0.000000e+000,3,9.926264e-001,0.000000e+000,,,,,,,,,,,,,,32,1,4.000000e+000,1.392365e-003,0.000000e+000,0,,0,
1524128065.511,,0.000000e+000,3.299750e+001,-1.797686e-004,0.000000e+000,3,9.926810e-001,0.000000e+000,,,,,,,,,,,,,,32,1,4.000000e+000,2.758026e-003,0.000000e+000,0,,0,
1524128091.431,,0.000000e+000,3.299854e+001,-1.801790e-004,0.000000e+000,3,9.928396e-001,0.000000e+000,,,,,,,,,,,,,,32,1,4.000000e+000,6.866455e-004,0.000000e+000,0,,0,
1524128117.126,,0.000000e+000,3.299785e+001,-1.805705e-004,0.000000e+000,3,9.927588e-001,0.000000e+000,,,,,,,,,,,,,,32,1,4.000000e+000,6.904602e-004,0.000000e+000,0,,0,
1524128142.702,,0.000000e+000,3.299819e+001,-1.809609e-004,0.000000e+000,3,9.927689e-001,0.000000e+000,,,,,,,,,,,,,,32,1,4.000000e+000,1.377106e-003,0.000000e+000,0,,0,
1524128168.647,,0.000000e+000,3.299854e+001,-1.811853e-004,0.000000e+000,3,9.925449e-001,0.000000e+000,,,,,,,,,,,,,,32,1,4.000000e+000,2.067566e-003,0.000000e+000,0,,0,
1524128193.800,,0.000000e+000,3.299750e+001,-1.815368e-004,0.000000e+000,3,9.927534e-001,0.000000e+000,,,,,,,,,,,,,,32,1,4.000000e+000,2.758026e-003,0.000000e+000,0,,0,
1524128219.123,,0.000000e+000,3.299888e+001,-1.818379e-004,0.000000e+000,3,9.927071e-001,0.000000e+000,,,,,,,,,,,,,,32,1,4.000000e+000,2.758026e-003,0.000000e+000,0,,0,
1524128244.771,,0.000000e+000,3.299854e+001,-1.820153e-004,0.000000e+000,3,9.928451e-001,0.000000e+000,,,,,,,,,,,,,,32,1,4.000000e+000,6.866455e-004,0.000000e+000,0,,0,
1524128270.626,,0.000000e+000,3.299750e+001,-1.823134e-004,0.000000e+000,3,9.927180e-001,0.000000e+000,,,,,,,,,,,,,,32,1,4.000000e+000,1.392365e-003,0.000000e+000,0,,0,
1524128295.779,,0.000000e+000,3.299854e+001,-1.825328e-004,0.000000e+000,3,9.927078e-001,0.000000e+000,,,,,,,,,,,,,,32,1,4.000000e+000,2.067566e-003,0.000000e+000,0,,0,
1524128320.842,,0.000000e+000,3.299854e+001,-1.827737e-004,0.000000e+000,3,9.929678e-001,0.000000e+000,,,,,,,,,,,,,,32,1,4.000000e+000,6.866455e-004,0.000000e+000,0,,0,
1524128345.650,,0.000000e+000,3.299819e+001,-1.829649e-004,0.000000e+000,3,9.927244e-001,0.000000e+000,,,,,,,,,,,,,,32,1,4.000000e+000,0.000000e+000,0.000000e+000,0,,0,
1524128370.648,,0.000000e+000,3.299784e+001,-1.831476e-004,0.000000e+000,3,9.929110e-001,0.000000e+000,,,,,,,,,,,,,,32,1,4.000000e+000,2.079010e-003,0.000000e+000,0,,0,
1524128395.338,,0.000000e+000,3.299888e+001,-1.833670e-004,0.000000e+000,3,9.926250e-001,0.000000e+000,,,,,,,,,,,,,,32,1,4.000000e+000,1.377106e-003,0.000000e+000,0,,0,
1524128420.311,,0.000000e+000,3.299819e+001,-1.834963e-004,0.000000e+000,3,9.929966e-001,0.000000e+000,,,,,,,,,,,,,,32,1,4.000000e+000,0.000000e+000,0.000000e+000,0,,0,
1524128446.216,,0.000000e+000,3.300095e+001,-1.836909e-004,0.000000e+000,3,9.929586e-001,0.000000e+000,,,,,,,,,,,,,,32,1,4.000000e+000,4.150391e-003,0.000000e+000,0,,0,
1524128470.902,,0.000000e+000,3.299819e+001,-1.839759e-004,0.000000e+000,3,9.926153e-001,0.000000e+000,,,,,,,,,,,,,,32,1,4.000000e+000,1.377106e-003,0.000000e+000,0,,0,
1524128495.882,,0.000000e+000,3.299784e+001,-1.840775e-004,0.000000e+000,3,9.930293e-001,0.000000e+000,,,,,,,,,,,,,,32,1,4.000000e+000,2.079010e-003,0.000000e+000,0,,0,
1524128521.787,,0.000000e+000,3.300027e+001,-1.842776e-004,0.000000e+000,3,9.930172e-001,0.000000e+000,,,,,,,,,,,,,,32,1,4.000000e+000,4.146576e-003,0.000000e+000,0,,0,
1524128547.005,,0.000000e+000,3.299888e+001,-1.844455e-004,0.000000e+000,3,9.929301e-001,0.000000e+000,,,,,,,,,,,,,,32,1,4.000000e+000,1.377106e-003,0.000000e+000,0,,0,
1524128573.246,,0.000000e+000,3.299854e+001,-1.845907e-004,0.000000e+000,3,9.926997e-001,0.000000e+000,,,,,,,,,,,,,,32,1,4.000000e+000,6.866455e-004,0.000000e+000,0,,0,
1524128597.916,,0.000000e+000,3.299577e+001,-1.847923e-004,0.000000e+000,3,9.930108e-001,0.000000e+000,,,,,,,,,,,,,,32,1,4.000000e+000,8.991241e-003,0.000000e+000,0,,0,
1524128623.321,,0.000000e+000,3.299681e+001,-1.848757e-004,0.000000e+000,3,9.928843e-001,0.000000e+000,,,,,,,,,,,,,,32,1,4.000000e+000,1.380920e-003,0.000000e+000,0,,0,
1524128648.277,,0.000000e+000,3.299819e+001,-1.850682e-004,0.000000e+000,3,9.927455e-001,0.000000e+000,,,,,,,,,,,,,,32,1,4.000000e+000,0.000000e+000,0.000000e+000,0,,0,
1524128672.932,,0.000000e+000,3.299854e+001,-1.851934e-004,0.000000e+000,3,9.929768e-001,0.000000e+000,,,,,,,,,,,,,,32,1,4.000000e+000,6.866455e-004,0.000000e+000,0,,0,
1524128698.578,,0.000000e+000,3.299819e+001,-1.852981e-004,0.000000e+000,3,9.928935e-001,0.000000e+000,,,,,,,,,,,,,,32,1,4.000000e+000,0.000000e+000,0.000000e+000,0,,0,
1524128722.778,,0.000000e+000,3.299819e+001,-1.854597e-004,0.000000e+000,3,9.928617e-001,0.000000e+000,,,,,,,,,,,,,,32,1,4.000000e+000,0.000000e+000,0.000000e+000,0,,0,
1524128748.591,,0.000000e+000,3.299922e+001,-1.856126e-004,0.000000e+000,3,9.929936e-001,0.000000e+000,,,,,,,,,,,,,,32,1,4.000000e+000,6.904602e-004,0.000000e+000,0,,0,
1524128774.034,,0.000000e+000,3.299888e+001,-1.856751e-004,0.000000e+000,3,9.928821e-001,0.000000e+000,,,,,,,,,,,,,,32,1,4.000000e+000,2.758026e-003,0.000000e+000,0,,0,
1524128799.306,,0.000000e+000,3.299854e+001,-1.858090e-004,0.000000e+000,3,9.930828e-001,0.000000e+000,,,,,,,,,,,,,,32,1,4.000000e+000,6.866455e-004,0.000000e+000,0,,0,
1524128825.107,,0.000000e+000,3.299715e+001,-1.859246e-004,0.000000e+000,3,9.930668e-001,0.000000e+000,,,,,,,,,,,,,,32,1,4.000000e+000,7.019043e-004,0.000000e+000,0,,0,
1524128850.657,,0.000000e+000,3.299854e+001,-1.860335e-004,0.000000e+000,3,9.929940e-001,0.000000e+000,,,,,,,,,,,,,,32,1,4.000000e+000,6.866455e-004,0.000000e+000,0,,0,
1524128876.333,,0.000000e+000,3.299854e+001,-1.861552e-004,0.000000e+000,3,9.928738e-001,0.000000e+000,,,,,,,,,,,,,,32,1,4.000000e+000,6.866455e-004,0.000000e+000,0,,0,
1524128901.766,,0.000000e+000,3.299888e+001,-1.862994e-004,0.000000e+000,3,9.930528e-001,0.000000e+000,,,,,,,,,,,,,,32,1,4.000000e+000,1.377106e-003,0.000000e+000,0,,0,
1524128927.313,,0.000000e+000,3.299784e+001,-1.864086e-004,0.000000e+000,3,9.929578e-001,0.000000e+000,,,,,,,,,,,,,,32,1,4.000000e+000,2.079010e-003,0.000000e+000,0,,0,
1524128952.929,,0.000000e+000,3.299750e+001,-1.865268e-004,0.000000e+000,3,9.928930e-001,0.000000e+000,,,,,,,,,,,,,,32,1,4.000000e+000,2.758026e-003,0.000000e+000,0,,0,
1524128978.382,,0.000000e+000,3.299785e+001,-1.866132e-004,0.000000e+000,3,9.931570e-001,0.000000e+000,,,,,,,,,,,,,,32,1,4.000000e+000,6.904602e-004,0.000000e+000,0,,0,
1524129004.077,,0.000000e+000,3.299819e+001,-1.867040e-004,0.000000e+000,3,9.929372e-001,0.000000e+000,,,,,,,,,,,,,,32,1,4.000000e+000,0.000000e+000,0.000000e+000,0,,0,
1524129028.280,,0.000000e+000,3.299854e+001,-1.868487e-004,0.000000e+000,3,9.928430e-001,0.000000e+000,,,,,,,,,,,,,,32,1,4.000000e+000,2.067566e-003,0.000000e+000,0,,0,
1524129053.328,,0.000000e+000,3.299819e+001,-1.869411e-004,0.000000e+000,3,9.929588e-001,0.000000e+000,,,,,,,,,,,,,,32,1,4.000000e+000,0.000000e+000,0.000000e+000,0,,0,
1524129077.946,,0.000000e+000,3.299819e+001,-1.870522e-004,0.000000e+000,3,9.927196e-001,0.000000e+000,,,,,,,,,,,,,,32,1,4.000000e+000,1.377106e-003,0.000000e+000,0,,0,
1524129103.471,,0.000000e+000,3.299819e+001,-1.871394e-004,0.000000e+000,3,9.929921e-001,0.000000e+000,,,,,,,,,,,,,,32,1,4.000000e+000,0.000000e+000,0.000000e+000,0,,0,
1524129128.314,,0.000000e+000,3.299854e+001,-1.872252e-004,0.000000e+000,3,9.930074e-001,0.000000e+000,,,,,,,,,,,,,,32,1,4.000000e+000,6.866455e-004,0.000000e+000,0,,0,
1524129152.917,,0.000000e+000,3.299750e+001,-1.873645e-004,0.000000e+000,3,9.928257e-001,0.000000e+000,,,,,,,,,,,,,,32,1,4.000000e+000,1.392365e-003,0.000000e+000,0,,0,
1524129178.415,,0.000000e+000,3.299646e+001,-1.874286e-004,0.000000e+000,3,9.928913e-001,0.000000e+000,,,,,,,,,,,,,,32,1,4.000000e+000,2.082825e-003,0.000000e+000,0,,0,
1524129203.287,,0.000000e+000,3.299854e+001,-1.875691e-004,0.000000e+000,3,9.928392e-001,0.000000e+000,,,,,,,,,,,,,,32,1,4.000000e+000,6.866455e-004,0.000000e+000,0,,0,
1524129228.288,,0.000000e+000,3.299957e+001,-1.875898e-004,0.000000e+000,3,9.930556e-001,0.000000e+000,,,,,,,,,,,,,,32,1,4.000000e+000,2.758026e-003,0.000000e+000,0,,0,
1524129253.996,,0.000000e+000,3.299819e+001,-1.876972e-004,0.000000e+000,3,9.929228e-001,0.000000e+000,,,,,,,,,,,,,,32,1,4.000000e+000,0.000000e+000,0.000000e+000,0,,0,
1524129278.191,,0.000000e+000,3.299923e+001,-1.877813e-004,0.000000e+000,3,9.928094e-001,0.000000e+000,,,,,,,,,,,,,,32,1,4.000000e+000,3.448486e-003,0.000000e+000,0,,0,
1524129303.661,,0.000000e+000,3.299923e+001,-1.878791e-004,0.000000e+000,3,9.929731e-001,0.000000e+000,,,,,,,,,,,,,,32,1,4.000000e+000,3.448486e-003,0.000000e+000,0,,0,
1524129327.822,,0.000000e+000,3.299923e+001,-1.879383e-004,0.000000e+000,3,9.928788e-001,0.000000e+000,,,,,,,,,,,,,,32,1,4.000000e+000,2.067566e-003,0.000000e+000,0,,0,
1524129353.215,,0.000000e+000,3.299819e+001,-1.880153e-004,0.000000e+000,3,9.929103e-001,0.000000e+000,,,,,,,,,,,,,,32,1,4.000000e+000,1.377106e-003,0.000000e+000,0,,0,
1524129378.872,,0.000000e+000,3.300130e+001,-1.881148e-004,0.000000e+000,3,9.930067e-001,0.000000e+000,,,,,,,,,,,,,,32,1,4.000000e+000,3.459930e-003,0.000000e+000,0,,0,
1524129403.533,,0.000000e+000,3.299922e+001,-1.881991e-004,0.000000e+000,3,9.928769e-001,0.000000e+000,,,,,,,,,,,,,,32,1,4.000000e+000,6.904602e-004,0.000000e+000,0,,0,
1524129428.713,,0.000000e+000,3.299888e+001,-1.882318e-004,0.000000e+000,3,9.928007e-001,0.000000e+000,,,,,,,,,,,,,,32,1,4.000000e+000,0.000000e+000,0.000000e+000,0,,0,
1524129454.439,,0.000000e+000,3.299854e+001,-1.883277e-004,0.000000e+000,3,9.930847e-001,0.000000e+000,,,,,,,,,,,,,,32,1,4.000000e+000,6.866455e-004,0.000000e+000,0,,0,
1524129480.026,,0.000000e+000,3.299854e+001,-1.883773e-004,0.000000e+000,3,9.928259e-001,0.000000e+000,,,,,,,,,,,,,,32,1,4.000000e+000,6.866455e-004,0.000000e+000,0,,0,
1524129505.644,,0.000000e+000,3.299784e+001,-1.885091e-004,0.000000e+000,3,9.929439e-001,0.000000e+000,,,,,,,,,,,,,,32,1,4.000000e+000,2.079010e-003,0.000000e+000,0,,0,
1524129531.487,,0.000000e+000,3.299922e+001,-1.885855e-004,0.000000e+000,3,9.931251e-001,0.000000e+000,,,,,,,,,,,,,,32,1,4.000000e+000,6.904602e-004,0.000000e+000,0,,0,
1524129556.963,,0.000000e+000,3.299923e+001,-1.886715e-004,0.000000e+000,3,9.929787e-001,0.000000e+000,,,,,,,,,,,,,,32,1,4.000000e+000,2.067566e-003,0.000000e+000,0,,0,
1524129581.838,,0.000000e+000,3.299785e+001,-1.887057e-004,0.000000e+000,3,9.928961e-001,0.000000e+000,,,,,,,,,,,,,,32,1,4.000000e+000,6.904602e-004,0.000000e+000,0,,0,
1524129607.538,,0.000000e+000,3.299957e+001,-1.887578e-004,0.000000e+000,3,9.930161e-001,0.000000e+000,,,,,,,,,,,,,,32,1,4.000000e+000,1.380920e-003,0.000000e+000,0,,0,
1524129633.484,,0.000000e+000,3.299819e+001,-1.888284e-004,0.000000e+000,3,9.930555e-001,0.000000e+000,,,,,,,,,,,,,,32,1,4.000000e+000,1.377106e-003,0.000000e+000,0,,0,
1524129659.394,,0.000000e+000,3.299922e+001,-1.889207e-004,0.000000e+000,3,9.929662e-001,0.000000e+000,,,,,,,,,,,,,,32,1,4.000000e+000,6.904602e-004,0.000000e+000,0,,0,
1524129684.702,,0.000000e+000,3.299888e+001,-1.889956e-004,0.000000e+000,3,9.928299e-001,0.000000e+000,,,,,,,,,,,,,,32,1,4.000000e+000,1.377106e-003,0.000000e+000,0,,0,
1524129710.490,,0.000000e+000,3.300026e+001,-1.890632e-004,0.000000e+000,3,9.931633e-001,0.000000e+000,,,,,,,,,,,,,,32,1,4.000000e+000,1.380920e-003,0.000000e+000,0,,0,
1524129735.668,,0.000000e+000,3.299923e+001,-1.891673e-004,0.000000e+000,3,9.929380e-001,0.000000e+000,,,,,,,,,,,,,,32,1,4.000000e+000,2.067566e-003,0.000000e+000,0,,0,
1524129761.568,,0.000000e+000,3.299888e+001,-1.892238e-004,0.000000e+000,3,9.930393e-001,0.000000e+000,,,,,,,,,,,,,,32,1,4.000000e+000,1.377106e-003,0.000000e+000,0,,0,
1524129786.728,,0.000000e+000,3.299854e+001,-1.893291e-004,0.000000e+000,3,9.927905e-001,0.000000e+000,,,,,,,,,,,,,,32,1,4.000000e+000,6.866455e-004,0.000000e+000,0,,0,
1524129811.709,,0.000000e+000,3.299888e+001,-1.893447e-004,0.000000e+000,3,9.928718e-001,0.000000e+000,,,,,,,,,,,,,,32,1,4.000000e+000,0.000000e+000,0.000000e+000,0,,0,
1524129836.867,,0.000000e+000,3.299854e+001,-1.894492e-004,0.000000e+000,3,9.927715e-001,0.000000e+000,,,,,,,,,,,,,,32,1,4.000000e+000,6.866455e-004,0.000000e+000,0,,0,
1524129862.762,,0.000000e+000,3.299957e+001,-1.894649e-004,0.000000e+000,3,9.929083e-001,0.000000e+000,,,,,,,,,,,,,,32,1,4.000000e+000,0.000000e+000,0.000000e+000,0,,0,
1524129887.910,,0.000000e+000,3.299818e+001,-1.895242e-004,0.000000e+000,3,9.928136e-001,0.000000e+000,,,,,,,,,,,,,,32,1,4.000000e+000,2.769470e-003,0.000000e+000,0,,0,
1524129913.115,,0.000000e+000,3.299957e+001,-1.896521e-004,0.000000e+000,3,9.927814e-001,0.000000e+000,,,,,,,,,,,,,,32,1,4.000000e+000,1.380920e-003,0.000000e+000,0,,0,
1524129938.101,,0.000000e+000,3.299957e+001,-1.897008e-004,0.000000e+000,3,9.928671e-001,0.000000e+000,,,,,,,,,,,,,,32,1,4.000000e+000,1.380920e-003,0.000000e+000,0,,0,
1524129963.781,,0.000000e+000,3.299922e+001,-1.897454e-004,0.000000e+000,3,9.929660e-001,0.000000e+000,,,,,,,,,,,,,,32,1,4.000000e+000,6.904602e-004,0.000000e+000,0,,0,
1524129988.709,,0.000000e+000,3.299922e+001,-1.898050e-004,0.000000e+000,3,9.928727e-001,0.000000e+000,,,,,,,,,,,,,,32,1,4.000000e+000,6.904602e-004,0.000000e+000,0,,0,
1524130013.884,,0.000000e+000,3.299784e+001,-1.898453e-004,0.000000e+000,3,9.928453e-001,0.000000e+000,,,,,,,,,,,,,,32,1,4.000000e+000,2.079010e-003,0.000000e+000,0,,0,
1524130038.702,,0.000000e+000,3.299888e+001,-1.898943e-004,0.000000e+000,3,9.929166e-001,0.000000e+000,,,,,,,,,,,,,,32,1,4.000000e+000,0.000000e+000,0.000000e+000,0,,0,
1524130064.515,,0.000000e+000,3.299750e+001,-1.899335e-004,0.000000e+000,3,9.929937e-001,0.000000e+000,,,,,,,,,,,,,,32,1,4.000000e+000,2.758026e-003,0.000000e+000,0,,0,
1524130090.305,,0.000000e+000,3.299888e+001,-1.900134e-004,0.000000e+000,3,9.929297e-001,0.000000e+000,,,,,,,,,,,,,,32,1,4.000000e+000,0.000000e+000,0.000000e+000,0,,0,
1524130115.691,,0.000000e+000,3.299784e+001,-1.900755e-004,0.000000e+000,3,9.930782e-001,0.000000e+000,,,,,,,,,,,,,,32,1,4.000000e+000,2.079010e-003,0.000000e+000,0,,0,
1524130141.206,,0.000000e+000,3.299819e+001,-1.900940e-004,0.000000e+000,3,9.930246e-001,0.000000e+000,,,,,,,,,,,,,,32,1,4.000000e+000,0.000000e+000,0.000000e+000,0,,0,
1524130166.617,,0.000000e+000,3.299888e+001,-1.901641e-004,0.000000e+000,3,9.928614e-001,0.000000e+000,,,,,,,,,,,,,,32,1,4.000000e+000,1.377106e-003,0.000000e+000,0,,0,
1524130192.127,,0.000000e+000,3.299888e+001,-1.902157e-004,0.000000e+000,3,9.931247e-001,0.000000e+000,,,,,,,,,,,,,,32,1,4.000000e+000,0.000000e+000,0.000000e+000,0,,0,
1524130217.787,,0.000000e+000,3.299854e+001,-1.902954e-004,0.000000e+000,3,9.927851e-001,0.000000e+000,,,,,,,,,,,,,,32,1,4.000000e+000,6.866455e-004,0.000000e+000,0,,0,
1524130243.145,,0.000000e+000,3.299992e+001,-1.903248e-004,0.000000e+000,3,9.930861e-001,0.000000e+000,,,,,,,,,,,,,,32,1,4.000000e+000,2.071381e-003,0.000000e+000,0,,0,
1524130268.886,,0.000000e+000,3.299888e+001,-1.903815e-004,0.000000e+000,3,9.929146e-001,0.000000e+000,,,,,,,,,,,,,,32,1,4.000000e+000,0.000000e+000,0.000000e+000,0,,0,
1524130294.338,,0.000000e+000,3.299888e+001,-1.904102e-004,0.000000e+000,3,9.930418e-001,0.000000e+000,,,,,,,,,,,,,,32,1,4.000000e+000,0.000000e+000,0.000000e+000,0,,0,
1524130320.036,,0.000000e+000,3.299854e+001,-1.905439e-004,0.000000e+000,3,9.930843e-001,0.000000e+000,,,,,,,,,,,,,,32,1,4.000000e+000,6.866455e-004,0.000000e+000,0,,0,
1524130344.272,,0.000000e+000,3.299888e+001,-1.905776e-004,0.000000e+000,3,9.929549e-001,0.000000e+000,,,,,,,,,,,,,,32,1,4.000000e+000,0.000000e+000,0.000000e+000,0,,0,
1524130369.900,,0.000000e+000,3.299854e+001,-1.906103e-004,0.000000e+000,3,9.931046e-001,0.000000e+000,,,,,,,,,,,,,,32,1,4.000000e+000,6.866455e-004,0.000000e+000,0,,0,
1524130395.810,,0.000000e+000,3.300061e+001,-1.906361e-004,0.000000e+000,3,9.930782e-001,0.000000e+000,,,,,,,,,,,,,,32,1,4.000000e+000,2.082825e-003,0.000000e+000,0,,0,
1524130421.720,,0.000000e+000,3.299646e+001,-1.906931e-004,0.000000e+000,3,9.930252e-001,0.000000e+000,,,,,,,,,,,,,,32,1,4.000000e+000,4.837036e-003,0.000000e+000,0,,0,
1524130447.626,,0.000000e+000,3.299646e+001,-1.907606e-004,0.000000e+000,3,9.931769e-001,0.000000e+000,,,,,,,,,,,,,,32,1,4.000000e+000,4.837036e-003,0.000000e+000,0,,0,
1524130473.536,,0.000000e+000,3.300130e+001,-1.907832e-004,0.000000e+000,3,9.931449e-001,0.000000e+000,,,,,,,,,,,,,,32,1,4.000000e+000,3.459930e-003,0.000000e+000,0,,0,
1524130498.786,,0.000000e+000,3.299923e+001,-1.908653e-004,0.000000e+000,3,9.929225e-001,0.000000e+000,,,,,,,,,,,,,,32,1,4.000000e+000,2.067566e-003,0.000000e+000,0,,0,
1524130523.452,,0.000000e+000,3.299888e+001,-1.909489e-004,0.000000e+000,3,9.928966e-001,0.000000e+000,,,,,,,,,,,,,,32,1,4.000000e+000,0.000000e+000,0.000000e+000,0,,0,
1524130549.237,,0.000000e+000,3.299715e+001,-1.909673e-004,0.000000e+000,3,9.930030e-001,0.000000e+000,,,,,,,,,,,,,,32,1,4.000000e+000,2.071381e-003,0.000000e+000,0,,0,
1524130574.683,,0.000000e+000,3.299819e+001,-1.910004e-004,0.000000e+000,3,9.930211e-001,0.000000e+000,,,,,,,,,,,,,,32,1,4.000000e+000,0.000000e+000,0.000000e+000,0,,0,
1524130600.145,,0.000000e+000,3.299819e+001,-1.910767e-004,0.000000e+000,3,9.929991e-001,0.000000e+000,,,,,,,,,,,,,,32,1,4.000000e+000,0.000000e+000,0.000000e+000,0,,0,
1524130625.536,,0.000000e+000,3.299819e+001,-1.911348e-004,0.000000e+000,3,9.929280e-001,0.000000e+000,,,,,,,,,,,,,,32,1,4.000000e+000,1.377106e-003,0.000000e+000,0,,0,
1524130650.791,,0.000000e+000,3.299854e+001,-1.911789e-004,0.000000e+000,3,9.930704e-001,0.000000e+000,,,,,,,,,,,,,,32,1,4.000000e+000,2.067566e-003,0.000000e+000,0,,0,
1524130676.361,,0.000000e+000,3.299715e+001,-1.911674e-004,0.000000e+000,3,9.930573e-001,0.000000e+000,,,,,,,,,,,,,,32,1,4.000000e+000,2.071381e-003,0.000000e+000,0,,0,
1524130701.857,,0.000000e+000,3.299715e+001,-1.912276e-004,0.000000e+000,3,9.931287e-001,0.000000e+000,,,,,,,,,,,,,,32,1,4.000000e+000,3.459930e-003,0.000000e+000,0,,0,
1524130727.542,,0.000000e+000,3.299749e+001,-1.913162e-004,0.000000e+000,3,9.928744e-001,0.000000e+000,,,,,,,,,,,,,,32,1,4.000000e+000,4.150391e-003,0.000000e+000,0,,0,
1524130751.743,,0.000000e+000,3.299957e+001,-1.913597e-004,0.000000e+000,3,9.928433e-001,0.000000e+000,,,,,,,,,,,,,,32,1,4.000000e+000,0.000000e+000,0.000000e+000,0,,0,
1524130776.750,,0.000000e+000,3.299784e+001,-1.913969e-004,0.000000e+000,3,9.929491e-001,0.000000e+000,,,,,,,,,,,,,,32,1,4.000000e+000,2.079010e-003,0.000000e+000,0,,0,
1524130802.091,,0.000000e+000,3.299819e+001,-1.914891e-004,0.000000e+000,3,9.928526e-001,0.000000e+000,,,,,,,,,,,,,,32,1,4.000000e+000,0.000000e+000,0.000000e+000,0,,0,
1524130827.089,,0.000000e+000,3.299992e+001,-1.914658e-004,0.000000e+000,3,9.931272e-001,0.000000e+000,,,,,,,,,,,,,,32,1,4.000000e+000,6.904602e-004,0.000000e+000,0,,0,
1524130851.739,,0.000000e+000,3.299854e+001,-1.915472e-004,0.000000e+000,3,9.929240e-001,0.000000e+000,,,,,,,,,,,,,,32,1,4.000000e+000,6.866455e-004,0.000000e+000,0,,0,
1524130876.934,,0.000000e+000,3.299922e+001,-1.915573e-004,0.000000e+000,3,9.928867e-001,0.000000e+000,,,,,,,,,,,,,,32,1,4.000000e+000,6.904602e-004,0.000000e+000,0,,0,
1524130902.557,,0.000000e+000,3.299854e+001,-1.916165e-004,0.000000e+000,3,9.930308e-001,0.000000e+000,,,,,,,,,,,,,,32,1,4.000000e+000,6.866455e-004,0.000000e+000,0,,0,
1524130928.030,,0.000000e+000,3.299888e+001,-1.916142e-004,0.000000e+000,3,9.931367e-001,0.000000e+000,,,,,,,,,,,,,,32,1,4.000000e+000,0.000000e+000,0.000000e+000,0,,0,
1524130953.941,,0.000000e+000,3.299922e+001,-1.916930e-004,0.000000e+000,3,9.932190e-001,0.000000e+000,,,,,,,,,,,,,,32,1,4.000000e+000,6.904602e-004,0.000000e+000,0,,0,
1524130979.323,,0.000000e+000,3.299785e+001,-1.917413e-004,0.000000e+000,3,9.931278e-001,0.000000e+000,,,,,,,,,,,,,,32,1,4.000000e+000,6.904602e-004,0.000000e+000,0,,0,
1524131005.001,,0.000000e+000,3.299888e+001,-1.917773e-004,0.000000e+000,3,9.928265e-001,0.000000e+000,,,,,,,,,,,,,,32,1,4.000000e+000,0.000000e+000,0.000000e+000,0,,0,
1524131029.219,,0.000000e+000,3.299922e+001,-1.918369e-004,0.000000e+000,3,9.928407e-001,0.000000e+000,,,,,,,,,,,,,,32,1,4.000000e+000,6.904602e-004,0.000000e+000,0,,0,
1524131054.690,,0.000000e+000,3.300060e+001,-1.918498e-004,0.000000e+000,3,9.930611e-001,0.000000e+000,,,,,,,,,,,,,,32,1,4.000000e+000,6.904602e-004,0.000000e+000,0,,0,
1524131079.572,,0.000000e+000,3.299957e+001,-1.919224e-004,0.000000e+000,3,9.929125e-001,0.000000e+000,,,,,,,,,,,,,,32,1,4.000000e+000,1.380920e-003,0.000000e+000,0,,0,
1524131104.563,,0.000000e+000,3.299854e+001,-1.919315e-004,0.000000e+000,3,9.931177e-001,0.000000e+000,,,,,,,,,,,,,,32,1,4.000000e+000,6.866455e-004,0.000000e+000,0,,0,
1524131129.233,,0.000000e+000,3.299888e+001,-1.920004e-004,0.000000e+000,3,9.929247e-001,0.000000e+000,,,,,,,,,,,,,,32,1,4.000000e+000,1.377106e-003,0.000000e+000,0,,0,
1524131154.219,,0.000000e+000,3.299819e+001,-1.919967e-004,0.000000e+000,3,9.931924e-001,0.000000e+000,,,,,,,,,,,,,,32,1,4.000000e+000,1.377106e-003,0.000000e+000,0,,0,
1524131178.884,,0.000000e+000,3.299922e+001,-1.920845e-004,0.000000e+000,3,9.928063e-001,0.000000e+000,,,,,,,,,,,,,,32,1,4.000000e+000,6.904602e-004,0.000000e+000,0,,0,
1524131203.887,,0.000000e+000,3.299888e+001,-1.920859e-004,0.000000e+000,3,9.930294e-001,0.000000e+000,,,,,,,,,,,,,,32,1,4.000000e+000,1.377106e-003,0.000000e+000,0,,0,
1524131229.500,,0.000000e+000,3.299784e+001,-1.921440e-004,0.000000e+000,3,9.929647e-001,0.000000e+000,,,,,,,,,,,,,,32,1,4.000000e+000,2.079010e-003,0.000000e+000,0,,0,
1524131255.312,,0.000000e+000,3.299957e+001,-1.921514e-004,0.000000e+000,3,9.929906e-001,0.000000e+000,,,,,,,,,,,,,,32,1,4.000000e+000,0.000000e+000,0.000000e+000,0,,0,
1524131280.588,,0.000000e+000,3.299854e+001,-1.922001e-004,0.000000e+000,3,9.931030e-001,0.000000e+000,,,,,,,,,,,,,,32,1,4.000000e+000,6.866455e-004,0.000000e+000,0,,0,
1524131306.468,,0.000000e+000,3.299957e+001,-1.922597e-004,0.000000e+000,3,9.930534e-001,0.000000e+000,,,,,,,,,,,,,,32,1,4.000000e+000,1.380920e-003,0.000000e+000,0,,0,
1524131332.264,,0.000000e+000,3.299957e+001,-1.922259e-004,0.000000e+000,3,9.931624e-001,0.000000e+000,,,,,,,,,,,,,,32,1,4.000000e+000,0.000000e+000,0.000000e+000,0,,0,
1524131357.884,,0.000000e+000,3.299888e+001,-1.923306e-004,0.000000e+000,3,9.930003e-001,0.000000e+000,,,,,,,,,,,,,,32,1,4.000000e+000,0.000000e+000,0.000000e+000,0,,0,
1524131383.292,,0.000000e+000,3.300130e+001,-1.923596e-004,0.000000e+000,3,9.930718e-001,0.000000e+000,,,,,,,,,,,,,,32,1,4.000000e+000,2.079010e-003,0.000000e+000,0,,0,
1524131408.782,,0.000000e+000,3.299888e+001,-1.924157e-004,0.000000e+000,3,9.929495e-001,0.000000e+000,,,,,,,,,,,,,,32,1,4.000000e+000,1.377106e-003,0.000000e+000,0,,0,
1524131434.423,,0.000000e+000,3.299888e+001,-1.924391e-004,0.000000e+000,3,9.931077e-001,0.000000e+000,,,,,,,,,,,,,,32,1,4.000000e+000,1.377106e-003,0.000000e+000,0,,0,
1524131460.016,,0.000000e+000,3.299923e+001,-1.925034e-004,0.000000e+000,3,9.929581e-001,0.000000e+000,,,,,,,,,,,,,,32,1,4.000000e+000,4.852295e-003,0.000000e+000,0,,0,
1524131485.388,,0.000000e+000,3.299992e+001,-1.924979e-004,0.000000e+000,3,9.930764e-001,0.000000e+000,,,,,,,,,,,,,,32,1,4.000000e+000,3.459930e-003,0.000000e+000,0,,0,
1524131511.201,,0.000000e+000,3.299922e+001,-1.925784e-004,0.000000e+000,3,9.928398e-001,0.000000e+000,,,,,,,,,,,,,,32,1,4.000000e+000,6.904602e-004,0.000000e+000,0,,0,
1524131536.467,,0.000000e+000,3.299854e+001,-1.925807e-004,0.000000e+000,3,9.930781e-001,0.000000e+000,,,,,,,,,,,,,,32,1,4.000000e+000,6.866455e-004,0.000000e+000,0,,0,
1524131561.147,,0.000000e+000,3.299854e+001,-1.926546e-004,0.000000e+000,3,9.929014e-001,0.000000e+000,,,,,,,,,,,,,,32,1,4.000000e+000,6.866455e-004,0.000000e+000,0,,0,
1524131586.307,,0.000000e+000,3.299957e+001,-1.926833e-004,0.000000e+000,3,9.929384e-001,0.000000e+000,,,,,,,,,,,,,,32,1,4.000000e+000,0.000000e+000,0.000000e+000,0,,0,
1524131611.740,,0.000000e+000,3.299888e+001,-1.927117e-004,0.000000e+000,3,9.930248e-001,0.000000e+000,,,,,,,,,,,,,,32,1,4.000000e+000,1.377106e-003,0.000000e+000,0,,0,
1524131637.433,,0.000000e+000,3.300026e+001,-1.927301e-004,0.000000e+000,3,9.931119e-001,0.000000e+000,,,,,,,,,,,,,,32,1,4.000000e+000,1.380920e-003,0.000000e+000,0,,0,
1524131663.106,,0.000000e+000,3.299854e+001,-1.927611e-004,0.000000e+000,3,9.929271e-001,0.000000e+000,,,,,,,,,,,,,,32,1,4.000000e+000,6.866455e-004,0.000000e+000,0,,0,
1524131687.371,,0.000000e+000,3.299888e+001,-1.927831e-004,0.000000e+000,3,9.929441e-001,0.000000e+000,,,,,,,,,,,,,,32,1,4.000000e+000,1.377106e-003,0.000000e+000,0,,0,
1524131713.009,,0.000000e+000,3.299680e+001,-1.928292e-004,0.000000e+000,3,9.930543e-001,0.000000e+000,,,,,,,,,,,,,,32,1,4.000000e+000,5.527496e-003,0.000000e+000,0,,0,
1524131738.842,,0.000000e+000,3.299888e+001,-1.928648e-004,0.000000e+000,3,9.930078e-001,0.000000e+000,,,,,,,,,,,,,,32,1,4.000000e+000,0.000000e+000,0.000000e+000,0,,0,
1524131764.525,,0.000000e+000,3.299922e+001,-1.929231e-004,0.000000e+000,3,9.931057e-001,0.000000e+000,,,,,,,,,,,,,,32,1,4.000000e+000,6.904602e-004,0.000000e+000,0,,0,
1524131789.860,,0.000000e+000,3.299854e+001,-1.929613e-004,0.000000e+000,3,9.930159e-001,0.000000e+000,,,,,,,,,,,,,,32,1,4.000000e+000,2.067566e-003,0.000000e+000,0,,0,
1524131815.706,,0.000000e+000,3.299750e+001,-1.929719e-004,0.000000e+000,3,9.928585e-001,0.000000e+000,,,,,,,,,,,,,,32,1,4.000000e+000,2.758026e-003,0.000000e+000,0,,0,
1524131840.804,,0.000000e+000,3.299715e+001,-1.930422e-004,0.000000e+000,3,9.930977e-001,0.000000e+000,,,,,,,,,,,,,,32,1,4.000000e+000,3.459930e-003,0.000000e+000,0,,0,
1524131866.676,,0.000000e+000,3.300130e+001,-1.930227e-004,0.000000e+000,3,9.930809e-001,0.000000e+000,,,,,,,,,,,,,,32,1,4.000000e+000,3.459930e-003,0.000000e+000,0,,0,
1524131892.247,,0.000000e+000,3.300130e+001,-1.930465e-004,0.000000e+000,3,9.931688e-001,0.000000e+000,,,,,,,,,,,,,,32,1,4.000000e+000,4.840851e-003,0.000000e+000,0,,0,
1524131916.957,,0.000000e+000,3.299957e+001,-1.931428e-004,0.000000e+000,3,9.928312e-001,0.000000e+000,,,,,,,,,,,,,,32,1,4.000000e+000,1.380920e-003,0.000000e+000,0,,0,
1524131942.145,,0.000000e+000,3.299750e+001,-1.931312e-004,0.000000e+000,3,9.928917e-001,0.000000e+000,,,,,,,,,,,,,,32,1,4.000000e+000,2.758026e-003,0.000000e+000,0,,0,
1524131967.310,,0.000000e+000,3.299888e+001,-1.931343e-004,0.000000e+000,3,9.933329e-001,0.000000e+000,,,,,,,,,,,,,,32,1,4.000000e+000,0.000000e+000,0.000000e+000,0,,0,
1524131992.026,,0.000000e+000,3.299957e+001,-1.932917e-004,0.000000e+000,3,9.928569e-001,0.000000e+000,,,,,,,,,,,,,,32,1,4.000000e+000,1.380920e-003,0.000000e+000,0,,0,
1524132017.001,,0.000000e+000,3.299992e+001,-1.932333e-004,0.000000e+000,3,9.931381e-001,0.000000e+000,,,,,,,,,,,,,,32,1,4.000000e+000,2.071381e-003,0.000000e+000,0,,0,
1524132042.687,,0.000000e+000,3.300061e+001,-1.932671e-004,0.000000e+000,3,9.931296e-001,0.000000e+000,,,,,,,,,,,,,,32,1,4.000000e+000,3.459930e-003,0.000000e+000,0,,0,
1524132067.292,,0.000000e+000,3.299922e+001,-1.932855e-004,0.000000e+000,3,9.928789e-001,0.000000e+000,,,,,,,,,,,,,,32,1,4.000000e+000,6.904602e-004,0.000000e+000,0,,0,
1524132092.595,,0.000000e+000,3.299854e+001,-1.933083e-004,0.000000e+000,3,9.930239e-001,0.000000e+000,,,,,,,,,,,,,,32,1,4.000000e+000,2.067566e-003,0.000000e+000,0,,0,
1524132118.250,,0.000000e+000,3.299888e+001,-1.933711e-004,0.000000e+000,3,9.929035e-001,0.000000e+000,,,,,,,,,,,,,,32,1,4.000000e+000,0.000000e+000,0.000000e+000,0,,0,
1524132144.128,,0.000000e+000,3.299785e+001,-1.934045e-004,0.000000e+000,3,9.928843e-001,0.000000e+000,,,,,,,,,,,,,,32,1,4.000000e+000,6.904602e-004,0.000000e+000,0,,0,
1524132168.991,,0.000000e+000,3.299854e+001,-1.934413e-004,0.000000e+000,3,9.929655e-001,0.000000e+000,,,,,,,,,,,,,,32,1,4.000000e+000,6.866455e-004,0.000000e+000,0,,0,
1524132194.624,,0.000000e+000,3.299922e+001,-1.934577e-004,0.000000e+000,3,9.930695e-001,0.000000e+000,,,,,,,,,,,,,,32,1,4.000000e+000,6.904602e-004,0.000000e+000,0,,0,
1524132220.029,,0.000000e+000,3.299854e+001,-1.935071e-004,0.000000e+000,3,9.930887e-001,0.000000e+000,,,,,,,,,,,,,,32,1,4.000000e+000,6.866455e-004,0.000000e+000,0,,0,
1524132245.602,,0.000000e+000,3.299888e+001,-1.935404e-004,0.000000e+000,3,9.928632e-001,0.000000e+000,,,,,,,,,,,,,,32,1,4.000000e+000,0.000000e+000,0.000000e+000,0,,0,
1524132271.297,,0.000000e+000,3.300130e+001,-1.935407e-004,0.000000e+000,3,9.932896e-001,0.000000e+000,,,,,,,,,,,,,,32,1,4.000000e+000,4.840851e-003,0.000000e+000,0,,0,
1524132297.223,,0.000000e+000,3.299750e+001,-1.935504e-004,0.000000e+000,3,9.930460e-001,0.000000e+000,,,,,,,,,,,,,,32,1,4.000000e+000,1.392365e-003,0.000000e+000,0,,0,
1524132322.466,,0.000000e+000,3.299888e+001,-1.936265e-004,0.000000e+000,3,9.929785e-001,0.000000e+000,,,,,,,,,,,,,,32,1,4.000000e+000,0.000000e+000,0.000000e+000,0,,0,
1524132347.159,,0.000000e+000,3.299957e+001,-1.936757e-004,0.000000e+000,3,9.928867e-001,0.000000e+000,,,,,,,,,,,,,,32,1,4.000000e+000,0.000000e+000,0.000000e+000,0,,0,
1524132372.816,,0.000000e+000,3.299750e+001,-1.936286e-004,0.000000e+000,3,9.930098e-001,0.000000e+000,,,,,,,,,,,,,,32,1,4.000000e+000,5.527496e-003,0.000000e+000,0,,0,
1524132397.507,,0.000000e+000,3.299888e+001,-1.937355e-004,0.000000e+000,3,9.928024e-001,0.000000e+000,,,,,,,,,,,,,,32,1,4.000000e+000,0.000000e+000,0.000000e+000,0,,0,
1524132422.485,,0.000000e+000,3.299992e+001,-1.937123e-004,0.000000e+000,3,9.931232e-001,0.000000e+000,,,,,,,,,,,,,,32,1,4.000000e+000,6.904602e-004,0.000000e+000,0,,0,
1524132448.192,,0.000000e+000,3.299922e+001,-1.937824e-004,0.000000e+000,3,9.930319e-001,0.000000e+000,,,,,,,,,,,,,,32,1,4.000000e+000,6.904602e-004,0.000000e+000,0,,0,
1524132472.440,,0.000000e+000,3.299923e+001,-1.938026e-004,0.000000e+000,3,9.929257e-001,0.000000e+000,,,,,,,,,,,,,,32,1,4.000000e+000,2.067566e-003,0.000000e+000,0,,0,
1524132498.078,,0.000000e+000,3.299750e+001,-1.937866e-004,0.000000e+000,3,9.931467e-001,0.000000e+000,,,,,,,,,,,,,,32,1,4.000000e+000,5.527496e-003,0.000000e+000,0,,0,
1524132522.784,,0.000000e+000,3.299922e+001,-1.938558e-004,0.000000e+000,3,9.928796e-001,0.000000e+000,,,,,,,,,,,,,,32,1,4.000000e+000,6.904602e-004,0.000000e+000,0,,0,
1524132547.759,,0.000000e+000,3.299888e+001,-1.938601e-004,0.000000e+000,3,9.932150e-001,0.000000e+000,,,,,,,,,,,,,,32,1,4.000000e+000,1.377106e-003,0.000000e+000,0,,0,
1524132573.467,,0.000000e+000,3.299957e+001,-1.939160e-004,0.000000e+000,3,9.930716e-001,0.000000e+000,,,,,,,,,,,,,,32,1,4.000000e+000,1.380920e-003,0.000000e+000,0,,0,
1524132597.690,,0.000000e+000,3.299888e+001,-1.939545e-004,0.000000e+000,3,9.929060e-001,0.000000e+000,,,,,,,,,,,,,,32,1,4.000000e+000,1.377106e-003,0.000000e+000,0,,0,
1524132623.360,,0.000000e+000,3.299818e+001,-1.939549e-004,0.000000e+000,3,9.931439e-001,0.000000e+000,,,,,,,,,,,,,,32,1,4.000000e+000,2.769470e-003,0.000000e+000,0,,0,
1524132649.073,,0.000000e+000,3.299957e+001,-1.939893e-004,0.000000e+000,3,9.931007e-001,0.000000e+000,,,,,,,,,,,,,,32,1,4.000000e+000,1.380920e-003,0.000000e+000,0,,0,
1524132673.991,,0.000000e+000,3.299922e+001,-1.940533e-004,0.000000e+000,3,9.928576e-001,0.000000e+000,,,,,,,,,,,,,,32,1,4.000000e+000,6.904602e-004,0.000000e+000,0,,0,
1524132698.951,,0.000000e+000,3.299819e+001,-1.940115e-004,0.000000e+000,3,9.931530e-001,0.000000e+000,,,,,,,,,,,,,,32,1,4.000000e+000,1.377106e-003,0.000000e+000,0,,0,
1524132724.872,,0.000000e+000,3.299715e+001,-1.940768e-004,0.000000e+000,3,9.931871e-001,0.000000e+000,,,,,,,,,,,,,,32,1,4.000000e+000,3.459930e-003,0.000000e+000,0,,0,
1524132751.152,,0.000000e+000,3.299922e+001,-1.940825e-004,0.000000e+000,3,9.929212e-001,0.000000e+000,,,,,,,,,,,,,,32,1,4.000000e+000,6.904602e-004,0.000000e+000,0,,0,
1524132775.892,,0.000000e+000,3.299922e+001,-1.941550e-004,0.000000e+000,3,9.929504e-001,0.000000e+000,,,,,,,,,,,,,,32,1,4.000000e+000,6.904602e-004,0.000000e+000,0,,0,
1524132801.348,,0.000000e+000,3.299888e+001,-1.942268e-004,0.000000e+000,3,9.930419e-001,0.000000e+000,,,,,,,,,,,,,,32,1,4.000000e+000,1.377106e-003,0.000000e+000,0,,0,
1524132825.588,,0.000000e+000,3.299888e+001,-1.941596e-004,0.000000e+000,3,9.929724e-001,0.000000e+000,,,,,,,,,,,,,,32,1,4.000000e+000,0.000000e+000,0.000000e+000,0,,0,
1524132851.236,,0.000000e+000,3.300026e+001,-1.941887e-004,0.000000e+000,3,9.930884e-001,0.000000e+000,,,,,,,,,,,,,,32,1,4.000000e+000,1.380920e-003,0.000000e+000,0,,0,
1524132875.924,,0.000000e+000,3.299922e+001,-1.942584e-004,0.000000e+000,3,9.929010e-001,0.000000e+000,,,,,,,,,,,,,,32,1,4.000000e+000,6.904602e-004,0.000000e+000,0,,0,
1524132900.909,,0.000000e+000,3.299819e+001,-1.942689e-004,0.000000e+000,3,9.930775e-001,0.000000e+000,,,,,,,,,,,,,,32,1,4.000000e+000,1.377106e-003,0.000000e+000,0,,0,
1524132926.830,,0.000000e+000,3.300130e+001,-1.942832e-004,0.000000e+000,3,9.931092e-001,0.000000e+000,,,,,,,,,,,,,,32,1,4.000000e+000,3.459930e-003,0.000000e+000,0,,0,
1524132952.540,,0.000000e+000,3.299922e+001,-1.943520e-004,0.000000e+000,3,9.930362e-001,0.000000e+000,,,,,,,,,,,,,,32,1,4.000000e+000,6.904602e-004,0.000000e+000,0,,0,
1524132976.758,,0.000000e+000,3.299888e+001,-1.943879e-004,0.000000e+000,3,9.929592e-001,0.000000e+000,,,,,,,,,,,,,,32,1,4.000000e+000,0.000000e+000,0.000000e+000,0,,0,
1524133002.436,,0.000000e+000,3.300130e+001,-1.943650e-004,0.000000e+000,3,9.930964e-001,0.000000e+000,,,,,,,,,,,,,,32,1,4.000000e+000,6.217957e-003,0.000000e+000,0,,0,
1524133027.366,,0.000000e+000,3.299888e+001,-1.944455e-004,0.000000e+000,3,9.928282e-001,0.000000e+000,,,,,,,,,,,,,,32,1,4.000000e+000,0.000000e+000,0.000000e+000,0,,0,
1524133051.811,,0.000000e+000,3.299785e+001,-1.944425e-004,0.000000e+000,3,9.929180e-001,0.000000e+000,,,,,,,,,,,,,,32,1,4.000000e+000,6.904602e-004,0.000000e+000,0,,0,
1524133077.289,,0.000000e+000,3.299957e+001,-1.944777e-004,0.000000e+000,3,9.929755e-001,0.000000e+000,,,,,,,,,,,,,,32,1,4.000000e+000,0.000000e+000,0.000000e+000,0,,0,
1524133101.507,,0.000000e+000,3.299750e+001,-1.945040e-004,0.000000e+000,3,9.930108e-001,0.000000e+000,,,,,,,,,,,,,,32,1,4.000000e+000,2.758026e-003,0.000000e+000,0,,0,
1524133114.195,,0.000000e+000,3.299922e+001,-1.944758e-004,0.000000e+000,3,9.931588e-001,0.000000e+000,,,,,,,,,,,,,,32,1,4.000000e+000,6.904602e-004,0.000000e+000,0,,0,