File: Experimental Raw Data/MFn1 Acquisition/MFn1_VRMac_40K_6000s.dc.dat
[Header]
TITLE,MPMS DC Measurement
BYAPP,MPMS Measurement,2.1,Summary
FILEOPENTIME, 1523939557.961000 4/16/2018, 10:32:37 PM

INFO, APPNAME, MPMS MultiVu Application, Revision 1.61,  Build 082

INFO, NAME, MFn1
INFO, WEIGHT, 1.000
INFO, AREA, 1.000
INFO, LENGTH, 1.000
INFO, SHAPE, 0
INFO, COMMENT,
INFO, SEQUENCE FILE: VRMac_40K_6000s_3000s_VRMde_40K.seq


INFO, BACKGROUND DATA FILE:, None


STARTUPAXIS,X,4,LINEAR,AUTO,0.000000,0.000000
STARTUPAXIS,Y1,5,LINEAR,AUTO,0.000000,0.000000


STARTUPGROUP,Longitudinal
FIELDGROUP,Longitudinal,1,2,3,4,5,6,7,8,9,15,16,17,18,27,28
FIELDGROUP,Transverse,1,2,3,4,10,11,12,13,14,19,20,21,22,27,28

PLOT_APPEARANCE,ALL,HORZ_GRID_ON,VERT_GRID_ON,MARKERS_AND_LINES

[Data]
Time,Comment,Field (Oe),Temperature (K),Long Moment (emu),Long Scan Std Dev,Long Algorithm,Long Reg Fit,Long Percent Error (%),Trans Moment (emu),Trans Scan Std Dev,Trans Algorithm,Trans Reg Fit,Trans Percent Error (%),Long Moment [w/o ABS] (emu),Long Scan Std Dev [w/o ABS],Long Reg Fit [w/o ABS],Long Percent Error [w/o ABS] (%),Trans Moment [w/o ABS] (emu),Trans Scan Std Dev [w/o ABS],Trans Reg Fit [w/o ABS],Trans Percent Error [w/o ABS] (%),Points per Scan,Scans per Measurement,Scan Length (cm),Delta Temp (K),Rot Position (deg),Error,EC Comp. Running,Using ABS,
1523939557.958,,0.000000e+000,3.999577e+001,-1.977921e-004,0.000000e+000,3,9.900588e-001,0.000000e+000,,,,,,,,,,,,,,32,1,4.000000e+000,4.131317e-003,0.000000e+000,0,,0,
1523939582.721,,0.000000e+000,3.999991e+001,-2.030134e-004,0.000000e+000,3,9.906132e-001,0.000000e+000,,,,,,,,,,,,,,32,1,4.000000e+000,0.000000e+000,0.000000e+000,0,,0,
1523939608.496,,0.000000e+000,3.999991e+001,-2.057833e-004,0.000000e+000,3,9.910192e-001,0.000000e+000,,,,,,,,,,,,,,32,1,4.000000e+000,0.000000e+000,0.000000e+000,0,,0,
1523939634.052,,0.000000e+000,3.999991e+001,-2.074615e-004,0.000000e+000,3,9.909592e-001,0.000000e+000,,,,,,,,,,,,,,32,1,4.000000e+000,2.059937e-003,0.000000e+000,0,,0,
1523939659.617,,0.000000e+000,4.000042e+001,-2.090056e-004,0.000000e+000,3,9.911079e-001,0.000000e+000,,,,,,,,,,,,,,32,1,4.000000e+000,1.029968e-003,0.000000e+000,0,,0,
1523939685.337,,0.000000e+000,3.999991e+001,-2.100693e-004,0.000000e+000,3,9.909748e-001,0.000000e+000,,,,,,,,,,,,,,32,1,4.000000e+000,2.059937e-003,0.000000e+000,0,,0,
1523939710.813,,0.000000e+000,3.999836e+001,-2.109241e-004,0.000000e+000,3,9.912137e-001,0.000000e+000,,,,,,,,,,,,,,32,1,4.000000e+000,1.037598e-003,0.000000e+000,0,,0,
1523939736.328,,0.000000e+000,3.999732e+001,-2.117372e-004,0.000000e+000,3,9.910772e-001,0.000000e+000,,,,,,,,,,,,,,32,1,4.000000e+000,3.108978e-003,0.000000e+000,0,,0,
1523939761.281,,0.000000e+000,3.999836e+001,-2.124757e-004,0.000000e+000,3,9.912081e-001,0.000000e+000,,,,,,,,,,,,,,32,1,4.000000e+000,3.097534e-003,0.000000e+000,0,,0,
1523939787.784,,0.000000e+000,3.999836e+001,-2.130798e-004,0.000000e+000,3,9.911311e-001,0.000000e+000,,,,,,,,,,,,,,32,1,4.000000e+000,1.037598e-003,0.000000e+000,0,,0,
1523939813.202,,0.000000e+000,3.999888e+001,-2.136869e-004,0.000000e+000,3,9.913365e-001,0.000000e+000,,,,,,,,,,,,,,32,1,4.000000e+000,0.000000e+000,0.000000e+000,0,,0,
1523939839.030,,0.000000e+000,3.999784e+001,-2.141474e-004,0.000000e+000,3,9.912357e-001,0.000000e+000,,,,,,,,,,,,,,32,1,4.000000e+000,0.000000e+000,0.000000e+000,0,,0,
1523939863.858,,0.000000e+000,3.999733e+001,-2.147642e-004,0.000000e+000,3,9.914047e-001,0.000000e+000,,,,,,,,,,,,,,32,1,4.000000e+000,1.029968e-003,0.000000e+000,0,,0,
1523939888.390,,0.000000e+000,3.999887e+001,-2.150126e-004,0.000000e+000,3,9.916110e-001,0.000000e+000,,,,,,,,,,,,,,32,1,4.000000e+000,2.067566e-003,0.000000e+000,0,,0,
1523939913.496,,0.000000e+000,4.000042e+001,-2.155003e-004,0.000000e+000,3,9.914082e-001,0.000000e+000,,,,,,,,,,,,,,32,1,4.000000e+000,5.157471e-003,0.000000e+000,0,,0,
1523939937.841,,0.000000e+000,3.999991e+001,-2.159740e-004,0.000000e+000,3,9.914419e-001,0.000000e+000,,,,,,,,,,,,,,32,1,4.000000e+000,0.000000e+000,0.000000e+000,0,,0,
1523939963.279,,0.000000e+000,3.999835e+001,-2.162323e-004,0.000000e+000,3,9.912823e-001,0.000000e+000,,,,,,,,,,,,,,32,1,4.000000e+000,5.168915e-003,0.000000e+000,0,,0,
1523939989.462,,0.000000e+000,3.999680e+001,-2.165910e-004,0.000000e+000,3,9.913843e-001,0.000000e+000,,,,,,,,,,,,,,32,1,4.000000e+000,2.071381e-003,0.000000e+000,0,,0,
1523940014.777,,0.000000e+000,3.999939e+001,-2.169316e-004,0.000000e+000,3,9.914798e-001,0.000000e+000,,,,,,,,,,,,,,32,1,4.000000e+000,1.029968e-003,0.000000e+000,0,,0,
1523940040.125,,0.000000e+000,3.999836e+001,-2.172351e-004,0.000000e+000,3,9.913778e-001,0.000000e+000,,,,,,,,,,,,,,32,1,4.000000e+000,1.037598e-003,0.000000e+000,0,,0,
1523940065.491,,0.000000e+000,3.999888e+001,-2.175637e-004,0.000000e+000,3,9.915209e-001,0.000000e+000,,,,,,,,,,,,,,32,1,4.000000e+000,0.000000e+000,0.000000e+000,0,,0,
1523940090.471,,0.000000e+000,3.999887e+001,-2.178730e-004,0.000000e+000,3,9.914250e-001,0.000000e+000,,,,,,,,,,,,,,32,1,4.000000e+000,2.067566e-003,0.000000e+000,0,,0,
1523940116.246,,0.000000e+000,3.999733e+001,-2.181805e-004,0.000000e+000,3,9.914644e-001,0.000000e+000,,,,,,,,,,,,,,32,1,4.000000e+000,1.029968e-003,0.000000e+000,0,,0,
1523940142.777,,0.000000e+000,3.999836e+001,-2.184066e-004,0.000000e+000,3,9.916688e-001,0.000000e+000,,,,,,,,,,,,,,32,1,4.000000e+000,1.037598e-003,0.000000e+000,0,,0,
1523940167.577,,0.000000e+000,3.999888e+001,-2.187199e-004,0.000000e+000,3,9.914508e-001,0.000000e+000,,,,,,,,,,,,,,32,1,4.000000e+000,0.000000e+000,0.000000e+000,0,,0,
1523940193.220,,0.000000e+000,3.999939e+001,-2.188876e-004,0.000000e+000,3,9.914871e-001,0.000000e+000,,,,,,,,,,,,,,32,1,4.000000e+000,1.029968e-003,0.000000e+000,0,,0,
1523940217.753,,0.000000e+000,3.999784e+001,-2.191885e-004,0.000000e+000,3,9.916200e-001,0.000000e+000,,,,,,,,,,,,,,32,1,4.000000e+000,2.067566e-003,0.000000e+000,0,,0,
1523940243.571,,0.000000e+000,3.999991e+001,-2.193875e-004,0.000000e+000,3,9.912754e-001,0.000000e+000,,,,,,,,,,,,,,32,1,4.000000e+000,2.059937e-003,0.000000e+000,0,,0,
1523940269.821,,0.000000e+000,3.999733e+001,-2.195547e-004,0.000000e+000,3,9.913505e-001,0.000000e+000,,,,,,,,,,,,,,32,1,4.000000e+000,1.029968e-003,0.000000e+000,0,,0,
1523940294.899,,0.000000e+000,3.999939e+001,-2.197857e-004,0.000000e+000,3,9.914743e-001,0.000000e+000,,,,,,,,,,,,,,32,1,4.000000e+000,3.097534e-003,0.000000e+000,0,,0,
1523940319.984,,0.000000e+000,3.999939e+001,-2.199679e-004,0.000000e+000,3,9.915268e-001,0.000000e+000,,,,,,,,,,,,,,32,1,4.000000e+000,1.029968e-003,0.000000e+000,0,,0,
1523940345.812,,0.000000e+000,3.999733e+001,-2.201863e-004,0.000000e+000,3,9.913986e-001,0.000000e+000,,,,,,,,,,,,,,32,1,4.000000e+000,1.029968e-003,0.000000e+000,0,,0,
1523940370.625,,0.000000e+000,3.999836e+001,-2.203880e-004,0.000000e+000,3,9.915553e-001,0.000000e+000,,,,,,,,,,,,,,32,1,4.000000e+000,1.037598e-003,0.000000e+000,0,,0,
1523940395.508,,0.000000e+000,3.999836e+001,-2.205745e-004,0.000000e+000,3,9.913480e-001,0.000000e+000,,,,,,,,,,,,,,32,1,4.000000e+000,1.037598e-003,0.000000e+000,0,,0,
1523940420.691,,0.000000e+000,3.999629e+001,-2.206725e-004,0.000000e+000,3,9.915406e-001,0.000000e+000,,,,,,,,,,,,,,32,1,4.000000e+000,5.168915e-003,0.000000e+000,0,,0,
1523940446.301,,0.000000e+000,3.999836e+001,-2.209446e-004,0.000000e+000,3,9.915610e-001,0.000000e+000,,,,,,,,,,,,,,32,1,4.000000e+000,1.037598e-003,0.000000e+000,0,,0,
1523940471.404,,0.000000e+000,4.000094e+001,-2.211154e-004,0.000000e+000,3,9.914505e-001,0.000000e+000,,,,,,,,,,,,,,32,1,4.000000e+000,4.119873e-003,0.000000e+000,0,,0,
1523940495.917,,0.000000e+000,3.999888e+001,-2.213209e-004,0.000000e+000,3,9.915619e-001,0.000000e+000,,,,,,,,,,,,,,32,1,4.000000e+000,0.000000e+000,0.000000e+000,0,,0,
1523940520.527,,0.000000e+000,3.999836e+001,-2.214346e-004,0.000000e+000,3,9.916300e-001,0.000000e+000,,,,,,,,,,,,,,32,1,4.000000e+000,1.037598e-003,0.000000e+000,0,,0,
1523940545.378,,0.000000e+000,3.999680e+001,-2.216416e-004,0.000000e+000,3,9.913449e-001,0.000000e+000,,,,,,,,,,,,,,32,1,4.000000e+000,2.071381e-003,0.000000e+000,0,,0,
1523940571.370,,0.000000e+000,3.999939e+001,-2.217319e-004,0.000000e+000,3,9.915756e-001,0.000000e+000,,,,,,,,,,,,,,32,1,4.000000e+000,3.097534e-003,0.000000e+000,0,,0,
1523940596.948,,0.000000e+000,3.999938e+001,-2.218585e-004,0.000000e+000,3,9.913939e-001,0.000000e+000,,,,,,,,,,,,,,32,1,4.000000e+000,7.228851e-003,0.000000e+000,0,,0,
1523940622.506,,0.000000e+000,3.999939e+001,-2.219462e-004,0.000000e+000,3,9.915681e-001,0.000000e+000,,,,,,,,,,,,,,32,1,4.000000e+000,3.097534e-003,0.000000e+000,0,,0,
1523940647.372,,0.000000e+000,3.999681e+001,-2.222207e-004,0.000000e+000,3,9.913570e-001,0.000000e+000,,,,,,,,,,,,,,32,1,4.000000e+000,4.138947e-003,0.000000e+000,0,,0,
1523940672.794,,0.000000e+000,3.999784e+001,-2.223681e-004,0.000000e+000,3,9.914939e-001,0.000000e+000,,,,,,,,,,,,,,32,1,4.000000e+000,6.198883e-003,0.000000e+000,0,,0,
1523940699.265,,0.000000e+000,3.999733e+001,-2.224975e-004,0.000000e+000,3,9.915983e-001,0.000000e+000,,,,,,,,,,,,,,32,1,4.000000e+000,1.029968e-003,0.000000e+000,0,,0,
1523940724.805,,0.000000e+000,3.999836e+001,-2.226023e-004,0.000000e+000,3,9.914863e-001,0.000000e+000,,,,,,,,,,,,,,32,1,4.000000e+000,1.037598e-003,0.000000e+000,0,,0,
1523940749.113,,0.000000e+000,3.999784e+001,-2.227723e-004,0.000000e+000,3,9.914274e-001,0.000000e+000,,,,,,,,,,,,,,32,1,4.000000e+000,0.000000e+000,0.000000e+000,0,,0,
1523940773.708,,0.000000e+000,3.999784e+001,-2.228875e-004,0.000000e+000,3,9.913753e-001,0.000000e+000,,,,,,,,,,,,,,32,1,4.000000e+000,0.000000e+000,0.000000e+000,0,,0,
1523940798.496,,0.000000e+000,3.999888e+001,-2.230211e-004,0.000000e+000,3,9.915733e-001,0.000000e+000,,,,,,,,,,,,,,32,1,4.000000e+000,0.000000e+000,0.000000e+000,0,,0,
1523940824.129,,0.000000e+000,3.999629e+001,-2.231015e-004,0.000000e+000,3,9.915336e-001,0.000000e+000,,,,,,,,,,,,,,32,1,4.000000e+000,5.168915e-003,0.000000e+000,0,,0,
1523940849.694,,0.000000e+000,4.000042e+001,-2.232829e-004,0.000000e+000,3,9.915427e-001,0.000000e+000,,,,,,,,,,,,,,32,1,4.000000e+000,3.089905e-003,0.000000e+000,0,,0,
1523940874.975,,0.000000e+000,3.999680e+001,-2.234087e-004,0.000000e+000,3,9.913811e-001,0.000000e+000,,,,,,,,,,,,,,32,1,4.000000e+000,2.071381e-003,0.000000e+000,0,,0,
1523940900.920,,0.000000e+000,3.999577e+001,-2.234950e-004,0.000000e+000,3,9.914490e-001,0.000000e+000,,,,,,,,,,,,,,32,1,4.000000e+000,4.131317e-003,0.000000e+000,0,,0,
1523940926.186,,0.000000e+000,3.999939e+001,-2.236200e-004,0.000000e+000,3,9.913606e-001,0.000000e+000,,,,,,,,,,,,,,32,1,4.000000e+000,1.029968e-003,0.000000e+000,0,,0,
1523940952.526,,0.000000e+000,3.999888e+001,-2.237152e-004,0.000000e+000,3,9.915975e-001,0.000000e+000,,,,,,,,,,,,,,32,1,4.000000e+000,0.000000e+000,0.000000e+000,0,,0,
1523940978.101,,0.000000e+000,3.999836e+001,-2.237996e-004,0.000000e+000,3,9.915765e-001,0.000000e+000,,,,,,,,,,,,,,32,1,4.000000e+000,1.037598e-003,0.000000e+000,0,,0,
1523941003.787,,0.000000e+000,3.999784e+001,-2.239604e-004,0.000000e+000,3,9.915781e-001,0.000000e+000,,,,,,,,,,,,,,32,1,4.000000e+000,0.000000e+000,0.000000e+000,0,,0,
1523941029.242,,0.000000e+000,3.999681e+001,-2.240326e-004,0.000000e+000,3,9.913601e-001,0.000000e+000,,,,,,,,,,,,,,32,1,4.000000e+000,0.000000e+000,0.000000e+000,0,,0,
1523941055.550,,0.000000e+000,3.999888e+001,-2.241681e-004,0.000000e+000,3,9.915157e-001,0.000000e+000,,,,,,,,,,,,,,32,1,4.000000e+000,0.000000e+000,0.000000e+000,0,,0,
1523941081.283,,0.000000e+000,3.999991e+001,-2.242855e-004,0.000000e+000,3,9.916157e-001,0.000000e+000,,,,,,,,,,,,,,32,1,4.000000e+000,0.000000e+000,0.000000e+000,0,,0,
1523941105.591,,0.000000e+000,4.000042e+001,-2.243952e-004,0.000000e+000,3,9.917516e-001,0.000000e+000,,,,,,,,,,,,,,32,1,4.000000e+000,1.029968e-003,0.000000e+000,0,,0,
1523941130.844,,0.000000e+000,3.999887e+001,-2.245282e-004,0.000000e+000,3,9.915470e-001,0.000000e+000,,,,,,,,,,,,,,32,1,4.000000e+000,2.067566e-003,0.000000e+000,0,,0,
1523941156.354,,0.000000e+000,3.999784e+001,-2.245717e-004,0.000000e+000,3,9.913543e-001,0.000000e+000,,,,,,,,,,,,,,32,1,4.000000e+000,2.067566e-003,0.000000e+000,0,,0,
1523941182.267,,0.000000e+000,3.999784e+001,-2.246926e-004,0.000000e+000,3,9.916171e-001,0.000000e+000,,,,,,,,,,,,,,32,1,4.000000e+000,0.000000e+000,0.000000e+000,0,,0,
1523941207.677,,0.000000e+000,3.999887e+001,-2.247835e-004,0.000000e+000,3,9.916810e-001,0.000000e+000,,,,,,,,,,,,,,32,1,4.000000e+000,2.067566e-003,0.000000e+000,0,,0,
1523941232.548,,0.000000e+000,3.999990e+001,-2.249442e-004,0.000000e+000,3,9.915546e-001,0.000000e+000,,,,,,,,,,,,,,32,1,4.000000e+000,6.187439e-003,0.000000e+000,0,,0,
1523941258.056,,0.000000e+000,3.999784e+001,-2.249716e-004,0.000000e+000,3,9.914743e-001,0.000000e+000,,,,,,,,,,,,,,32,1,4.000000e+000,0.000000e+000,0.000000e+000,0,,0,
1523941283.461,,0.000000e+000,3.999732e+001,-2.250738e-004,0.000000e+000,3,9.914278e-001,0.000000e+000,,,,,,,,,,,,,,32,1,4.000000e+000,3.108978e-003,0.000000e+000,0,,0,
1523941309.914,,0.000000e+000,3.999784e+001,-2.251353e-004,0.000000e+000,3,9.914949e-001,0.000000e+000,,,,,,,,,,,,,,32,1,4.000000e+000,2.067566e-003,0.000000e+000,0,,0,
1523941335.654,,0.000000e+000,3.999939e+001,-2.252036e-004,0.000000e+000,3,9.916988e-001,0.000000e+000,,,,,,,,,,,,,,32,1,4.000000e+000,1.029968e-003,0.000000e+000,0,,0,
1523941361.100,,0.000000e+000,3.999733e+001,-2.253947e-004,0.000000e+000,3,9.914630e-001,0.000000e+000,,,,,,,,,,,,,,32,1,4.000000e+000,1.029968e-003,0.000000e+000,0,,0,
1523941386.732,,0.000000e+000,3.999733e+001,-2.254348e-004,0.000000e+000,3,9.915429e-001,0.000000e+000,,,,,,,,,,,,,,32,1,4.000000e+000,1.029968e-003,0.000000e+000,0,,0,
1523941412.313,,0.000000e+000,3.999836e+001,-2.255218e-004,0.000000e+000,3,9.915146e-001,0.000000e+000,,,,,,,,,,,,,,32,1,4.000000e+000,3.097534e-003,0.000000e+000,0,,0,
1523941436.793,,0.000000e+000,3.999888e+001,-2.256149e-004,0.000000e+000,3,9.915215e-001,0.000000e+000,,,,,,,,,,,,,,32,1,4.000000e+000,0.000000e+000,0.000000e+000,0,,0,
1523941461.989,,0.000000e+000,3.999939e+001,-2.257255e-004,0.000000e+000,3,9.914203e-001,0.000000e+000,,,,,,,,,,,,,,32,1,4.000000e+000,3.097534e-003,0.000000e+000,0,,0,
1523941488.216,,0.000000e+000,3.999939e+001,-2.257496e-004,0.000000e+000,3,9.915392e-001,0.000000e+000,,,,,,,,,,,,,,32,1,4.000000e+000,1.029968e-003,0.000000e+000,0,,0,
1523941513.634,,0.000000e+000,3.999888e+001,-2.259241e-004,0.000000e+000,3,9.915017e-001,0.000000e+000,,,,,,,,,,,,,,32,1,4.000000e+000,0.000000e+000,0.000000e+000,0,,0,
1523941538.777,,0.000000e+000,3.999836e+001,-2.259785e-004,0.000000e+000,3,9.915441e-001,0.000000e+000,,,,,,,,,,,,,,32,1,4.000000e+000,1.037598e-003,0.000000e+000,0,,0,
1523941564.390,,0.000000e+000,3.999888e+001,-2.260230e-004,0.000000e+000,3,9.915408e-001,0.000000e+000,,,,,,,,,,,,,,32,1,4.000000e+000,0.000000e+000,0.000000e+000,0,,0,
1523941590.033,,0.000000e+000,3.999990e+001,-2.261080e-004,0.000000e+000,3,9.915149e-001,0.000000e+000,,,,,,,,,,,,,,32,1,4.000000e+000,4.127502e-003,0.000000e+000,0,,0,
1523941615.908,,0.000000e+000,3.999888e+001,-2.261955e-004,0.000000e+000,3,9.916266e-001,0.000000e+000,,,,,,,,,,,,,,32,1,4.000000e+000,0.000000e+000,0.000000e+000,0,,0,
1523941641.051,,0.000000e+000,3.999991e+001,-2.262546e-004,0.000000e+000,3,9.914737e-001,0.000000e+000,,,,,,,,,,,,,,32,1,4.000000e+000,2.059937e-003,0.000000e+000,0,,0,
1523941666.009,,0.000000e+000,3.999784e+001,-2.263582e-004,0.000000e+000,3,9.915112e-001,0.000000e+000,,,,,,,,,,,,,,32,1,4.000000e+000,2.067566e-003,0.000000e+000,0,,0,
1523941692.417,,0.000000e+000,3.999836e+001,-2.264270e-004,0.000000e+000,3,9.916486e-001,0.000000e+000,,,,,,,,,,,,,,32,1,4.000000e+000,3.097534e-003,0.000000e+000,0,,0,
1523941718.010,,0.000000e+000,3.999577e+001,-2.264537e-004,0.000000e+000,3,9.915366e-001,0.000000e+000,,,,,,,,,,,,,,32,1,4.000000e+000,2.071381e-003,0.000000e+000,0,,0,
1523941743.968,,0.000000e+000,3.999991e+001,-2.266041e-004,0.000000e+000,3,9.916847e-001,0.000000e+000,,,,,,,,,,,,,,32,1,4.000000e+000,0.000000e+000,0.000000e+000,0,,0,
1523941769.298,,0.000000e+000,3.999939e+001,-2.266598e-004,0.000000e+000,3,9.914626e-001,0.000000e+000,,,,,,,,,,,,,,32,1,4.000000e+000,1.029968e-003,0.000000e+000,0,,0,
1523941795.298,,0.000000e+000,3.999680e+001,-2.267110e-004,0.000000e+000,3,9.915041e-001,0.000000e+000,,,,,,,,,,,,,,32,1,4.000000e+000,2.071381e-003,0.000000e+000,0,,0,
1523941821.611,,0.000000e+000,4.000042e+001,-2.267948e-004,0.000000e+000,3,9.916115e-001,0.000000e+000,,,,,,,,,,,,,,32,1,4.000000e+000,1.029968e-003,0.000000e+000,0,,0,
1523941846.292,,0.000000e+000,3.999836e+001,-2.268524e-004,0.000000e+000,3,9.915321e-001,0.000000e+000,,,,,,,,,,,,,,32,1,4.000000e+000,1.037598e-003,0.000000e+000,0,,0,
1523941871.545,,0.000000e+000,3.999836e+001,-2.269600e-004,0.000000e+000,3,9.916275e-001,0.000000e+000,,,,,,,,,,,,,,32,1,4.000000e+000,1.037598e-003,0.000000e+000,0,,0,
1523941897.132,,0.000000e+000,3.999784e+001,-2.270304e-004,0.000000e+000,3,9.916018e-001,0.000000e+000,,,,,,,,,,,,,,32,1,4.000000e+000,0.000000e+000,0.000000e+000,0,,0,
1523941921.925,,0.000000e+000,3.999991e+001,-2.271244e-004,0.000000e+000,3,9.916528e-001,0.000000e+000,,,,,,,,,,,,,,32,1,4.000000e+000,2.059937e-003,0.000000e+000,0,,0,
1523941947.101,,0.000000e+000,3.999836e+001,-2.271633e-004,0.000000e+000,3,9.913993e-001,0.000000e+000,,,,,,,,,,,,,,32,1,4.000000e+000,1.037598e-003,0.000000e+000,0,,0,
1523941972.261,,0.000000e+000,3.999887e+001,-2.272660e-004,0.000000e+000,3,9.914529e-001,0.000000e+000,,,,,,,,,,,,,,32,1,4.000000e+000,2.067566e-003,0.000000e+000,0,,0,
1523941997.919,,0.000000e+000,4.000094e+001,-2.272999e-004,0.000000e+000,3,9.915633e-001,0.000000e+000,,,,,,,,,,,,,,32,1,4.000000e+000,2.059937e-003,0.000000e+000,0,,0,
1523942023.242,,0.000000e+000,3.999836e+001,-2.273614e-004,0.000000e+000,3,9.915258e-001,0.000000e+000,,,,,,,,,,,,,,32,1,4.000000e+000,3.097534e-003,0.000000e+000,0,,0,
1523942047.392,,0.000000e+000,3.999836e+001,-2.274290e-004,0.000000e+000,3,9.916435e-001,0.000000e+000,,,,,,,,,,,,,,32,1,4.000000e+000,1.037598e-003,0.000000e+000,0,,0,
1523942072.710,,0.000000e+000,3.999887e+001,-2.275284e-004,0.000000e+000,3,9.913499e-001,0.000000e+000,,,,,,,,,,,,,,32,1,4.000000e+000,6.198883e-003,0.000000e+000,0,,0,
1523942097.675,,0.000000e+000,3.999991e+001,-2.275556e-004,0.000000e+000,3,9.915943e-001,0.000000e+000,,,,,,,,,,,,,,32,1,4.000000e+000,2.059937e-003,0.000000e+000,0,,0,
1523942123.686,,0.000000e+000,3.999888e+001,-2.276275e-004,0.000000e+000,3,9.914968e-001,0.000000e+000,,,,,,,,,,,,,,32,1,4.000000e+000,0.000000e+000,0.000000e+000,0,,0,
1523942149.174,,0.000000e+000,4.000042e+001,-2.276332e-004,0.000000e+000,3,9.914268e-001,0.000000e+000,,,,,,,,,,,,,,32,1,4.000000e+000,1.029968e-003,0.000000e+000,0,,0,
1523942173.794,,0.000000e+000,3.999939e+001,-2.277681e-004,0.000000e+000,3,9.912782e-001,0.000000e+000,,,,,,,,,,,,,,32,1,4.000000e+000,1.029968e-003,0.000000e+000,0,,0,
1523942199.262,,0.000000e+000,3.999629e+001,-2.278191e-004,0.000000e+000,3,9.914997e-001,0.000000e+000,,,,,,,,,,,,,,32,1,4.000000e+000,3.101349e-003,0.000000e+000,0,,0,
1523942224.665,,0.000000e+000,3.999784e+001,-2.278342e-004,0.000000e+000,3,9.914640e-001,0.000000e+000,,,,,,,,,,,,,,32,1,4.000000e+000,2.067566e-003,0.000000e+000,0,,0,
1523942249.630,,0.000000e+000,3.999991e+001,-2.279096e-004,0.000000e+000,3,9.915742e-001,0.000000e+000,,,,,,,,,,,,,,32,1,4.000000e+000,0.000000e+000,0.000000e+000,0,,0,
1523942275.470,,0.000000e+000,4.000042e+001,-2.280189e-004,0.000000e+000,3,9.915600e-001,0.000000e+000,,,,,,,,,,,,,,32,1,4.000000e+000,3.089905e-003,0.000000e+000,0,,0,
1523942301.068,,0.000000e+000,3.999887e+001,-2.280295e-004,0.000000e+000,3,9.916126e-001,0.000000e+000,,,,,,,,,,,,,,32,1,4.000000e+000,6.198883e-003,0.000000e+000,0,,0,
1523942326.874,,0.000000e+000,3.999991e+001,-2.281240e-004,0.000000e+000,3,9.914697e-001,0.000000e+000,,,,,,,,,,,,,,32,1,4.000000e+000,0.000000e+000,0.000000e+000,0,,0,
1523942351.682,,0.000000e+000,3.999836e+001,-2.281999e-004,0.000000e+000,3,9.916241e-001,0.000000e+000,,,,,,,,,,,,,,32,1,4.000000e+000,1.037598e-003,0.000000e+000,0,,0,
1523942377.417,,0.000000e+000,3.999887e+001,-2.281947e-004,0.000000e+000,3,9.914102e-001,0.000000e+000,,,,,,,,,,,,,,32,1,4.000000e+000,2.067566e-003,0.000000e+000,0,,0,
1523942402.860,,0.000000e+000,3.999887e+001,-2.283311e-004,0.000000e+000,3,9.916083e-001,0.000000e+000,,,,,,,,,,,,,,32,1,4.000000e+000,1.033020e-002,0.000000e+000,0,,0,
1523942428.385,,0.000000e+000,3.999888e+001,-2.283286e-004,0.000000e+000,3,9.915218e-001,0.000000e+000,,,,,,,,,,,,,,32,1,4.000000e+000,0.000000e+000,0.000000e+000,0,,0,
1523942453.346,,0.000000e+000,3.999887e+001,-2.284125e-004,0.000000e+000,3,9.915892e-001,0.000000e+000,,,,,,,,,,,,,,32,1,4.000000e+000,2.067566e-003,0.000000e+000,0,,0,
1523942479.443,,0.000000e+000,4.000042e+001,-2.284753e-004,0.000000e+000,3,9.915164e-001,0.000000e+000,,,,,,,,,,,,,,32,1,4.000000e+000,1.029968e-003,0.000000e+000,0,,0,
1523942504.546,,0.000000e+000,3.999991e+001,-2.285703e-004,0.000000e+000,3,9.915559e-001,0.000000e+000,,,,,,,,,,,,,,32,1,4.000000e+000,0.000000e+000,0.000000e+000,0,,0,
1523942529.402,,0.000000e+000,3.999939e+001,-2.286270e-004,0.000000e+000,3,9.915519e-001,0.000000e+000,,,,,,,,,,,,,,32,1,4.000000e+000,1.029968e-003,0.000000e+000,0,,0,
1523942555.682,,0.000000e+000,3.999939e+001,-2.286302e-004,0.000000e+000,3,9.915963e-001,0.000000e+000,,,,,,,,,,,,,,32,1,4.000000e+000,3.097534e-003,0.000000e+000,0,,0,
1523942581.537,,0.000000e+000,3.999939e+001,-2.286658e-004,0.000000e+000,3,9.914083e-001,0.000000e+000,,,,,,,,,,,,,,32,1,4.000000e+000,3.097534e-003,0.000000e+000,0,,0,
1523942607.130,,0.000000e+000,3.999888e+001,-2.287681e-004,0.000000e+000,3,9.916613e-001,0.000000e+000,,,,,,,,,,,,,,32,1,4.000000e+000,0.000000e+000,0.000000e+000,0,,0,
1523942632.726,,0.000000e+000,3.999887e+001,-2.287979e-004,0.000000e+000,3,9.915163e-001,0.000000e+000,,,,,,,,,,,,,,32,1,4.000000e+000,2.067566e-003,0.000000e+000,0,,0,
1523942658.899,,0.000000e+000,3.999784e+001,-2.288348e-004,0.000000e+000,3,9.914251e-001,0.000000e+000,,,,,,,,,,,,,,32,1,4.000000e+000,2.067566e-003,0.000000e+000,0,,0,
1523942683.866,,0.000000e+000,3.999836e+001,-2.289191e-004,0.000000e+000,3,9.914392e-001,0.000000e+000,,,,,,,,,,,,,,32,1,4.000000e+000,1.037598e-003,0.000000e+000,0,,0,
1523942710.057,,0.000000e+000,3.999888e+001,-2.289682e-004,0.000000e+000,3,9.915248e-001,0.000000e+000,,,,,,,,,,,,,,32,1,4.000000e+000,0.000000e+000,0.000000e+000,0,,0,
1523942735.392,,0.000000e+000,3.999888e+001,-2.290032e-004,0.000000e+000,3,9.914363e-001,0.000000e+000,,,,,,,,,,,,,,32,1,4.000000e+000,0.000000e+000,0.000000e+000,0,,0,
1523942760.740,,0.000000e+000,3.999732e+001,-2.290502e-004,0.000000e+000,3,9.914016e-001,0.000000e+000,,,,,,,,,,,,,,32,1,4.000000e+000,3.108978e-003,0.000000e+000,0,,0,
1523942786.018,,0.000000e+000,3.999939e+001,-2.291238e-004,0.000000e+000,3,9.914550e-001,0.000000e+000,,,,,,,,,,,,,,32,1,4.000000e+000,5.157471e-003,0.000000e+000,0,,0,
1523942811.051,,0.000000e+000,3.999939e+001,-2.291773e-004,0.000000e+000,3,9.915439e-001,0.000000e+000,,,,,,,,,,,,,,32,1,4.000000e+000,1.029968e-003,0.000000e+000,0,,0,
1523942836.414,,0.000000e+000,3.999887e+001,-2.291881e-004,0.000000e+000,3,9.914511e-001,0.000000e+000,,,,,,,,,,,,,,32,1,4.000000e+000,2.067566e-003,0.000000e+000,0,,0,
1523942861.374,,0.000000e+000,3.999991e+001,-2.292391e-004,0.000000e+000,3,9.916028e-001,0.000000e+000,,,,,,,,,,,,,,32,1,4.000000e+000,2.059937e-003,0.000000e+000,0,,0,
1523942887.352,,0.000000e+000,3.999887e+001,-2.293048e-004,0.000000e+000,3,9.915325e-001,0.000000e+000,,,,,,,,,,,,,,32,1,4.000000e+000,2.067566e-003,0.000000e+000,0,,0,
1523942911.510,,0.000000e+000,3.999990e+001,-2.294262e-004,0.000000e+000,3,9.916957e-001,0.000000e+000,,,,,,,,,,,,,,32,1,4.000000e+000,4.127502e-003,0.000000e+000,0,,0,
1523942937.305,,0.000000e+000,4.000042e+001,-2.293705e-004,0.000000e+000,3,9.915686e-001,0.000000e+000,,,,,,,,,,,,,,32,1,4.000000e+000,3.089905e-003,0.000000e+000,0,,0,
1523942963.336,,0.000000e+000,3.999784e+001,-2.294507e-004,0.000000e+000,3,9.916030e-001,0.000000e+000,,,,,,,,,,,,,,32,1,4.000000e+000,0.000000e+000,0.000000e+000,0,,0,
1523942987.646,,0.000000e+000,3.999836e+001,-2.295629e-004,0.000000e+000,3,9.915906e-001,0.000000e+000,,,,,,,,,,,,,,32,1,4.000000e+000,1.037598e-003,0.000000e+000,0,,0,
1523943012.319,,0.000000e+000,3.999836e+001,-2.295816e-004,0.000000e+000,3,9.914774e-001,0.000000e+000,,,,,,,,,,,,,,32,1,4.000000e+000,1.037598e-003,0.000000e+000,0,,0,
1523943037.292,,0.000000e+000,3.999836e+001,-2.296008e-004,0.000000e+000,3,9.915036e-001,0.000000e+000,,,,,,,,,,,,,,32,1,4.000000e+000,1.037598e-003,0.000000e+000,0,,0,
1523943063.897,,0.000000e+000,3.999888e+001,-2.295848e-004,0.000000e+000,3,9.914953e-001,0.000000e+000,,,,,,,,,,,,,,32,1,4.000000e+000,0.000000e+000,0.000000e+000,0,,0,
1523943089.315,,0.000000e+000,4.000042e+001,-2.296728e-004,0.000000e+000,3,9.914034e-001,0.000000e+000,,,,,,,,,,,,,,32,1,4.000000e+000,1.029968e-003,0.000000e+000,0,,0,
1523943115.210,,0.000000e+000,3.999991e+001,-2.297604e-004,0.000000e+000,3,9.914886e-001,0.000000e+000,,,,,,,,,,,,,,32,1,4.000000e+000,0.000000e+000,0.000000e+000,0,,0,
1523943140.616,,0.000000e+000,3.999888e+001,-2.297730e-004,0.000000e+000,3,9.915869e-001,0.000000e+000,,,,,,,,,,,,,,32,1,4.000000e+000,0.000000e+000,0.000000e+000,0,,0,
1523943165.471,,0.000000e+000,3.999939e+001,-2.298548e-004,0.000000e+000,3,9.915863e-001,0.000000e+000,,,,,,,,,,,,,,32,1,4.000000e+000,3.097534e-003,0.000000e+000,0,,0,
1523943190.814,,0.000000e+000,3.999939e+001,-2.299121e-004,0.000000e+000,3,9.915078e-001,0.000000e+000,,,,,,,,,,,,,,32,1,4.000000e+000,1.029968e-003,0.000000e+000,0,,0,
1523943216.139,,0.000000e+000,3.999939e+001,-2.299396e-004,0.000000e+000,3,9.914614e-001,0.000000e+000,,,,,,,,,,,,,,32,1,4.000000e+000,3.097534e-003,0.000000e+000,0,,0,
1523943242.745,,0.000000e+000,3.999939e+001,-2.299527e-004,0.000000e+000,3,9.914867e-001,0.000000e+000,,,,,,,,,,,,,,32,1,4.000000e+000,1.029968e-003,0.000000e+000,0,,0,
1523943267.328,,0.000000e+000,3.999991e+001,-2.300112e-004,0.000000e+000,3,9.915717e-001,0.000000e+000,,,,,,,,,,,,,,32,1,4.000000e+000,0.000000e+000,0.000000e+000,0,,0,
1523943291.643,,0.000000e+000,3.999991e+001,-2.300690e-004,0.000000e+000,3,9.915577e-001,0.000000e+000,,,,,,,,,,,,,,32,1,4.000000e+000,2.059937e-003,0.000000e+000,0,,0,
1523943316.768,,0.000000e+000,3.999835e+001,-2.301314e-004,0.000000e+000,3,9.915767e-001,0.000000e+000,,,,,,,,,,,,,,32,1,4.000000e+000,5.168915e-003,0.000000e+000,0,,0,
1523943341.289,,0.000000e+000,3.999836e+001,-2.301659e-004,0.000000e+000,3,9.916387e-001,0.000000e+000,,,,,,,,,,,,,,32,1,4.000000e+000,1.037598e-003,0.000000e+000,0,,0,
1523943366.179,,0.000000e+000,3.999836e+001,-2.302481e-004,0.000000e+000,3,9.914650e-001,0.000000e+000,,,,,,,,,,,,,,32,1,4.000000e+000,3.097534e-003,0.000000e+000,0,,0,
1523943391.687,,0.000000e+000,3.999939e+001,-2.302260e-004,0.000000e+000,3,9.915538e-001,0.000000e+000,,,,,,,,,,,,,,32,1,4.000000e+000,1.029968e-003,0.000000e+000,0,,0,
1523943417.565,,0.000000e+000,3.999836e+001,-2.302951e-004,0.000000e+000,3,9.917157e-001,0.000000e+000,,,,,,,,,,,,,,32,1,4.000000e+000,1.037598e-003,0.000000e+000,0,,0,
1523943442.373,,0.000000e+000,3.999939e+001,-2.303217e-004,0.000000e+000,3,9.915613e-001,0.000000e+000,,,,,,,,,,,,,,32,1,4.000000e+000,1.029968e-003,0.000000e+000,0,,0,
1523943466.950,,0.000000e+000,3.999836e+001,-2.303559e-004,0.000000e+000,3,9.915910e-001,0.000000e+000,,,,,,,,,,,,,,32,1,4.000000e+000,1.037598e-003,0.000000e+000,0,,0,
1523943491.996,,0.000000e+000,3.999888e+001,-2.304284e-004,0.000000e+000,3,9.915808e-001,0.000000e+000,,,,,,,,,,,,,,32,1,4.000000e+000,0.000000e+000,0.000000e+000,0,,0,
1523943518.316,,0.000000e+000,3.999784e+001,-2.304789e-004,0.000000e+000,3,9.915776e-001,0.000000e+000,,,,,,,,,,,,,,32,1,4.000000e+000,0.000000e+000,0.000000e+000,0,,0,
1523943542.924,,0.000000e+000,4.000094e+001,-2.305022e-004,0.000000e+000,3,9.915652e-001,0.000000e+000,,,,,,,,,,,,,,32,1,4.000000e+000,4.119873e-003,0.000000e+000,0,,0,
1523943567.127,,0.000000e+000,3.999887e+001,-2.305770e-004,0.000000e+000,3,9.915677e-001,0.000000e+000,,,,,,,,,,,,,,32,1,4.000000e+000,2.067566e-003,0.000000e+000,0,,0,
1523943592.587,,0.000000e+000,4.000042e+001,-2.306132e-004,0.000000e+000,3,9.914382e-001,0.000000e+000,,,,,,,,,,,,,,32,1,4.000000e+000,1.029968e-003,0.000000e+000,0,,0,
1523943616.908,,0.000000e+000,3.999939e+001,-2.306488e-004,0.000000e+000,3,9.916326e-001,0.000000e+000,,,,,,,,,,,,,,32,1,4.000000e+000,1.029968e-003,0.000000e+000,0,,0,
1523943642.030,,0.000000e+000,3.999733e+001,-2.306841e-004,0.000000e+000,3,9.914005e-001,0.000000e+000,,,,,,,,,,,,,,32,1,4.000000e+000,1.029968e-003,0.000000e+000,0,,0,
1523943667.413,,0.000000e+000,3.999939e+001,-2.306856e-004,0.000000e+000,3,9.915314e-001,0.000000e+000,,,,,,,,,,,,,,32,1,4.000000e+000,1.029968e-003,0.000000e+000,0,,0,
1523943692.514,,0.000000e+000,3.999836e+001,-2.307715e-004,0.000000e+000,3,9.914256e-001,0.000000e+000,,,,,,,,,,,,,,32,1,4.000000e+000,1.037598e-003,0.000000e+000,0,,0,
1523943718.552,,0.000000e+000,4.000042e+001,-2.307573e-004,0.000000e+000,3,9.915600e-001,0.000000e+000,,,,,,,,,,,,,,32,1,4.000000e+000,1.029968e-003,0.000000e+000,0,,0,
1523943743.877,,0.000000e+000,3.999784e+001,-2.308261e-004,0.000000e+000,3,9.914174e-001,0.000000e+000,,,,,,,,,,,,,,32,1,4.000000e+000,2.067566e-003,0.000000e+000,0,,0,
1523943769.907,,0.000000e+000,3.999939e+001,-2.308588e-004,0.000000e+000,3,9.915524e-001,0.000000e+000,,,,,,,,,,,,,,32,1,4.000000e+000,1.029968e-003,0.000000e+000,0,,0,
1523943795.450,,0.000000e+000,3.999939e+001,-2.308818e-004,0.000000e+000,3,9.914900e-001,0.000000e+000,,,,,,,,,,,,,,32,1,4.000000e+000,1.029968e-003,0.000000e+000,0,,0,
1523943821.423,,0.000000e+000,3.999939e+001,-2.309867e-004,0.000000e+000,3,9.914293e-001,0.000000e+000,,,,,,,,,,,,,,32,1,4.000000e+000,1.029968e-003,0.000000e+000,0,,0,
1523943847.716,,0.000000e+000,3.999526e+001,-2.309363e-004,0.000000e+000,3,9.915112e-001,0.000000e+000,,,,,,,,,,,,,,32,1,4.000000e+000,7.240295e-003,0.000000e+000,0,,0,
1523943872.346,,0.000000e+000,3.999939e+001,-2.310635e-004,0.000000e+000,3,9.916088e-001,0.000000e+000,,,,,,,,,,,,,,32,1,4.000000e+000,1.029968e-003,0.000000e+000,0,,0,
1523943898.259,,0.000000e+000,3.999887e+001,-2.310415e-004,0.000000e+000,3,9.915043e-001,0.000000e+000,,,,,,,,,,,,,,32,1,4.000000e+000,2.067566e-003,0.000000e+000,0,,0,
1523943923.915,,0.000000e+000,3.999888e+001,-2.311360e-004,0.000000e+000,3,9.916262e-001,0.000000e+000,,,,,,,,,,,,,,32,1,4.000000e+000,0.000000e+000,0.000000e+000,0,,0,
1523943948.628,,0.000000e+000,3.999991e+001,-2.311697e-004,0.000000e+000,3,9.916577e-001,0.000000e+000,,,,,,,,,,,,,,32,1,4.000000e+000,2.059937e-003,0.000000e+000,0,,0,
1523943974.210,,0.000000e+000,3.999887e+001,-2.312114e-004,0.000000e+000,3,9.915311e-001,0.000000e+000,,,,,,,,,,,,,,32,1,4.000000e+000,2.067566e-003,0.000000e+000,0,,0,
1523944000.311,,0.000000e+000,3.999732e+001,-2.312181e-004,0.000000e+000,3,9.914026e-001,0.000000e+000,,,,,,,,,,,,,,32,1,4.000000e+000,3.108978e-003,0.000000e+000,0,,0,
1523944025.314,,0.000000e+000,3.999888e+001,-2.312387e-004,0.000000e+000,3,9.915159e-001,0.000000e+000,,,,,,,,,,,,,,32,1,4.000000e+000,0.000000e+000,0.000000e+000,0,,0,
1523944050.586,,0.000000e+000,3.999680e+001,-2.312569e-004,0.000000e+000,3,9.914843e-001,0.000000e+000,,,,,,,,,,,,,,32,1,4.000000e+000,2.071381e-003,0.000000e+000,0,,0,
1523944075.829,,0.000000e+000,4.000094e+001,-2.312945e-004,0.000000e+000,3,9.915128e-001,0.000000e+000,,,,,,,,,,,,,,32,1,4.000000e+000,2.059937e-003,0.000000e+000,0,,0,
1523944100.250,,0.000000e+000,3.999888e+001,-2.313490e-004,0.000000e+000,3,9.914820e-001,0.000000e+000,,,,,,,,,,,,,,32,1,4.000000e+000,0.000000e+000,0.000000e+000,0,,0,
1523944125.580,,0.000000e+000,3.999991e+001,-2.314181e-004,0.000000e+000,3,9.916208e-001,0.000000e+000,,,,,,,,,,,,,,32,1,4.000000e+000,2.059937e-003,0.000000e+000,0,,0,
1523944150.668,,0.000000e+000,3.999836e+001,-2.314551e-004,0.000000e+000,3,9.916017e-001,0.000000e+000,,,,,,,,,,,,,,32,1,4.000000e+000,1.037598e-003,0.000000e+000,0,,0,
1523944175.231,,0.000000e+000,3.999836e+001,-2.315014e-004,0.000000e+000,3,9.916105e-001,0.000000e+000,,,,,,,,,,,,,,32,1,4.000000e+000,3.097534e-003,0.000000e+000,0,,0,
1523944199.386,,0.000000e+000,3.999888e+001,-2.315489e-004,0.000000e+000,3,9.915857e-001,0.000000e+000,,,,,,,,,,,,,,32,1,4.000000e+000,0.000000e+000,0.000000e+000,0,,0,
1523944224.871,,0.000000e+000,3.999888e+001,-2.315987e-004,0.000000e+000,3,9.916444e-001,0.000000e+000,,,,,,,,,,,,,,32,1,4.000000e+000,0.000000e+000,0.000000e+000,0,,0,
1523944249.219,,0.000000e+000,3.999784e+001,-2.316136e-004,0.000000e+000,3,9.915594e-001,0.000000e+000,,,,,,,,,,,,,,32,1,4.000000e+000,4.138947e-003,0.000000e+000,0,,0,
1523944273.375,,0.000000e+000,3.999939e+001,-2.316461e-004,0.000000e+000,3,9.916845e-001,0.000000e+000,,,,,,,,,,,,,,32,1,4.000000e+000,1.029968e-003,0.000000e+000,0,,0,
1523944299.218,,0.000000e+000,3.999939e+001,-2.316523e-004,0.000000e+000,3,9.914274e-001,0.000000e+000,,,,,,,,,,,,,,32,1,4.000000e+000,1.029968e-003,0.000000e+000,0,,0,
1523944324.501,,0.000000e+000,3.999991e+001,-2.316685e-004,0.000000e+000,3,9.914559e-001,0.000000e+000,,,,,,,,,,,,,,32,1,4.000000e+000,0.000000e+000,0.000000e+000,0,,0,
1523944350.913,,0.000000e+000,3.999887e+001,-2.317406e-004,0.000000e+000,3,9.915336e-001,0.000000e+000,,,,,,,,,,,,,,32,1,4.000000e+000,2.067566e-003,0.000000e+000,0,,0,
1523944377.721,,0.000000e+000,3.999733e+001,-2.317273e-004,0.000000e+000,3,9.915537e-001,0.000000e+000,,,,,,,,,,,,,,32,1,4.000000e+000,1.029968e-003,0.000000e+000,0,,0,
1523944403.704,,0.000000e+000,3.999939e+001,-2.318019e-004,0.000000e+000,3,9.915016e-001,0.000000e+000,,,,,,,,,,,,,,32,1,4.000000e+000,1.029968e-003,0.000000e+000,0,,0,
1523944428.400,,0.000000e+000,3.999939e+001,-2.318393e-004,0.000000e+000,3,9.915474e-001,0.000000e+000,,,,,,,,,,,,,,32,1,4.000000e+000,1.029968e-003,0.000000e+000,0,,0,
1523944453.385,,0.000000e+000,4.000042e+001,-2.318581e-004,0.000000e+000,3,9.914825e-001,0.000000e+000,,,,,,,,,,,,,,32,1,4.000000e+000,3.089905e-003,0.000000e+000,0,,0,
1523944480.003,,0.000000e+000,3.999939e+001,-2.318353e-004,0.000000e+000,3,9.915440e-001,0.000000e+000,,,,,,,,,,,,,,32,1,4.000000e+000,1.029968e-003,0.000000e+000,0,,0,
1523944504.563,,0.000000e+000,3.999784e+001,-2.319083e-004,0.000000e+000,3,9.914215e-001,0.000000e+000,,,,,,,,,,,,,,32,1,4.000000e+000,2.067566e-003,0.000000e+000,0,,0,
1523944529.624,,0.000000e+000,3.999991e+001,-2.319960e-004,0.000000e+000,3,9.917467e-001,0.000000e+000,,,,,,,,,,,,,,32,1,4.000000e+000,2.059937e-003,0.000000e+000,0,,0,
1523944554.539,,0.000000e+000,3.999991e+001,-2.319943e-004,0.000000e+000,3,9.914567e-001,0.000000e+000,,,,,,,,,,,,,,32,1,4.000000e+000,0.000000e+000,0.000000e+000,0,,0,
1523944579.787,,0.000000e+000,3.999887e+001,-2.320463e-004,0.000000e+000,3,9.915395e-001,0.000000e+000,,,,,,,,,,,,,,32,1,4.000000e+000,2.067566e-003,0.000000e+000,0,,0,
1523944605.830,,0.000000e+000,3.999939e+001,-2.320656e-004,0.000000e+000,3,9.914873e-001,0.000000e+000,,,,,,,,,,,,,,32,1,4.000000e+000,1.029968e-003,0.000000e+000,0,,0,
1523944631.348,,0.000000e+000,3.999887e+001,-2.321123e-004,0.000000e+000,3,9.914366e-001,0.000000e+000,,,,,,,,,,,,,,32,1,4.000000e+000,2.067566e-003,0.000000e+000,0,,0,
1523944657.208,,0.000000e+000,4.000042e+001,-2.321275e-004,0.000000e+000,3,9.914688e-001,0.000000e+000,,,,,,,,,,,,,,32,1,4.000000e+000,1.029968e-003,0.000000e+000,0,,0,
1523944682.918,,0.000000e+000,3.999422e+001,-2.321324e-004,0.000000e+000,3,9.914851e-001,0.000000e+000,,,,,,,,,,,,,,32,1,4.000000e+000,7.232666e-003,0.000000e+000,0,,0,
1523944709.324,,0.000000e+000,4.000249e+001,-2.322168e-004,0.000000e+000,3,9.916686e-001,0.000000e+000,,,,,,,,,,,,,,32,1,4.000000e+000,7.221222e-003,0.000000e+000,0,,0,
1523944735.672,,0.000000e+000,3.999732e+001,-2.322558e-004,0.000000e+000,3,9.915484e-001,0.000000e+000,,,,,,,,,,,,,,32,1,4.000000e+000,3.108978e-003,0.000000e+000,0,,0,
1523944761.469,,0.000000e+000,3.999784e+001,-2.322715e-004,0.000000e+000,3,9.914576e-001,0.000000e+000,,,,,,,,,,,,,,32,1,4.000000e+000,0.000000e+000,0.000000e+000,0,,0,
1523944787.005,,0.000000e+000,3.999939e+001,-2.322866e-004,0.000000e+000,3,9.915428e-001,0.000000e+000,,,,,,,,,,,,,,32,1,4.000000e+000,1.029968e-003,0.000000e+000,0,,0,
1523944812.495,,0.000000e+000,3.999991e+001,-2.323529e-004,0.000000e+000,3,9.915679e-001,0.000000e+000,,,,,,,,,,,,,,32,1,4.000000e+000,0.000000e+000,0.000000e+000,0,,0,
1523944837.891,,0.000000e+000,3.999836e+001,-2.323486e-004,0.000000e+000,3,9.914368e-001,0.000000e+000,,,,,,,,,,,,,,32,1,4.000000e+000,1.037598e-003,0.000000e+000,0,,0,
1523944864.123,,0.000000e+000,3.999888e+001,-2.323896e-004,0.000000e+000,3,9.915411e-001,0.000000e+000,,,,,,,,,,,,,,32,1,4.000000e+000,0.000000e+000,0.000000e+000,0,,0,
1523944889.014,,0.000000e+000,3.999939e+001,-2.324263e-004,0.000000e+000,3,9.914752e-001,0.000000e+000,,,,,,,,,,,,,,32,1,4.000000e+000,1.029968e-003,0.000000e+000,0,,0,
1523944901.676,,0.000000e+000,3.999990e+001,-2.324564e-004,0.000000e+000,3,9.914537e-001,0.000000e+000,,,,,,,,,,,,,,32,1,4.000000e+000,4.127502e-003,0.000000e+000,0,,0,