File: Experimental Raw Data/MFn1 Acquisition/MFn1_VRMac_40K_3000s.dc.dat
[Header]
TITLE,MPMS DC Measurement
BYAPP,MPMS Measurement,2.1,Summary
FILEOPENTIME, 1523939557.961000 4/16/2018, 10:32:37 PM

INFO, APPNAME, MPMS MultiVu Application, Revision 1.61,  Build 082

INFO, NAME, MFn1
INFO, WEIGHT, 1.000
INFO, AREA, 1.000
INFO, LENGTH, 1.000
INFO, SHAPE, 0
INFO, COMMENT,
INFO, SEQUENCE FILE: VRMac_40K_6000s_3000s_VRMde_40K.seq


INFO, BACKGROUND DATA FILE:, None


STARTUPAXIS,X,4,LINEAR,AUTO,0.000000,0.000000
STARTUPAXIS,Y1,5,LINEAR,AUTO,0.000000,0.000000


STARTUPGROUP,Longitudinal
FIELDGROUP,Longitudinal,1,2,3,4,5,6,7,8,9,15,16,17,18,27,28
FIELDGROUP,Transverse,1,2,3,4,10,11,12,13,14,19,20,21,22,27,28

PLOT_APPEARANCE,ALL,HORZ_GRID_ON,VERT_GRID_ON,MARKERS_AND_LINES

[Data]
Time,Comment,Field (Oe),Temperature (K),Long Moment (emu),Long Scan Std Dev,Long Algorithm,Long Reg Fit,Long Percent Error (%),Trans Moment (emu),Trans Scan Std Dev,Trans Algorithm,Trans Reg Fit,Trans Percent Error (%),Long Moment [w/o ABS] (emu),Long Scan Std Dev [w/o ABS],Long Reg Fit [w/o ABS],Long Percent Error [w/o ABS] (%),Trans Moment [w/o ABS] (emu),Trans Scan Std Dev [w/o ABS],Trans Reg Fit [w/o ABS],Trans Percent Error [w/o ABS] (%),Points per Scan,Scans per Measurement,Scan Length (cm),Delta Temp (K),Rot Position (deg),Error,EC Comp. Running,Using ABS,
1523958196.332,,0.000000e+000,3.999888e+001,-2.011651e-004,0.000000e+000,3,9.907160e-001,0.000000e+000,,,,,,,,,,,,,,32,1,4.000000e+000,0.000000e+000,0.000000e+000,0,,0,
1523958208.699,,0.000000e+000,3.999939e+001,-2.026143e-004,0.000000e+000,3,9.908022e-001,0.000000e+000,,,,,,,,,,,,,,32,1,4.000000e+000,1.029968e-003,0.000000e+000,0,,0,
1523958220.874,,0.000000e+000,3.999991e+001,-2.038262e-004,0.000000e+000,3,9.910141e-001,0.000000e+000,,,,,,,,,,,,,,32,1,4.000000e+000,2.059937e-003,0.000000e+000,0,,0,
1523958233.027,,0.000000e+000,3.999887e+001,-2.048277e-004,0.000000e+000,3,9.910561e-001,0.000000e+000,,,,,,,,,,,,,,32,1,4.000000e+000,2.067566e-003,0.000000e+000,0,,0,
1523958245.187,,0.000000e+000,3.999836e+001,-2.055687e-004,0.000000e+000,3,9.912397e-001,0.000000e+000,,,,,,,,,,,,,,32,1,4.000000e+000,1.037598e-003,0.000000e+000,0,,0,
1523958257.235,,0.000000e+000,3.999991e+001,-2.063532e-004,0.000000e+000,3,9.910622e-001,0.000000e+000,,,,,,,,,,,,,,32,1,4.000000e+000,0.000000e+000,0.000000e+000,0,,0,
1523958270.290,,0.000000e+000,3.999991e+001,-2.070482e-004,0.000000e+000,3,9.911783e-001,0.000000e+000,,,,,,,,,,,,,,32,1,4.000000e+000,0.000000e+000,0.000000e+000,0,,0,
1523958283.030,,0.000000e+000,3.999732e+001,-2.076033e-004,0.000000e+000,3,9.912060e-001,0.000000e+000,,,,,,,,,,,,,,32,1,4.000000e+000,3.108978e-003,0.000000e+000,0,,0,
1523958295.681,,0.000000e+000,4.000094e+001,-2.080583e-004,0.000000e+000,3,9.910961e-001,0.000000e+000,,,,,,,,,,,,,,32,1,4.000000e+000,0.000000e+000,0.000000e+000,0,,0,
1523958309.408,,0.000000e+000,3.999939e+001,-2.086361e-004,0.000000e+000,3,9.913417e-001,0.000000e+000,,,,,,,,,,,,,,32,1,4.000000e+000,3.097534e-003,0.000000e+000,0,,0,
1523958321.888,,0.000000e+000,3.999991e+001,-2.091650e-004,0.000000e+000,3,9.912128e-001,0.000000e+000,,,,,,,,,,,,,,32,1,4.000000e+000,0.000000e+000,0.000000e+000,0,,0,
1523958335.024,,0.000000e+000,3.999991e+001,-2.093534e-004,0.000000e+000,3,9.915043e-001,0.000000e+000,,,,,,,,,,,,,,32,1,4.000000e+000,0.000000e+000,0.000000e+000,0,,0,
1523958348.326,,0.000000e+000,3.999887e+001,-2.099960e-004,0.000000e+000,3,9.912639e-001,0.000000e+000,,,,,,,,,,,,,,32,1,4.000000e+000,2.067566e-003,0.000000e+000,0,,0,
1523958361.011,,0.000000e+000,3.999577e+001,-2.103757e-004,0.000000e+000,3,9.913004e-001,0.000000e+000,,,,,,,,,,,,,,32,1,4.000000e+000,4.131317e-003,0.000000e+000,0,,0,
1523958373.657,,0.000000e+000,3.999681e+001,-2.105773e-004,0.000000e+000,3,9.911366e-001,0.000000e+000,,,,,,,,,,,,,,32,1,4.000000e+000,4.138947e-003,0.000000e+000,0,,0,
1523958386.234,,0.000000e+000,3.999887e+001,-2.109309e-004,0.000000e+000,3,9.912702e-001,0.000000e+000,,,,,,,,,,,,,,32,1,4.000000e+000,2.067566e-003,0.000000e+000,0,,0,
1523958398.582,,0.000000e+000,3.999939e+001,-2.112529e-004,0.000000e+000,3,9.912382e-001,0.000000e+000,,,,,,,,,,,,,,32,1,4.000000e+000,1.029968e-003,0.000000e+000,0,,0,
1523958412.012,,0.000000e+000,3.999836e+001,-2.115654e-004,0.000000e+000,3,9.914766e-001,0.000000e+000,,,,,,,,,,,,,,32,1,4.000000e+000,1.037598e-003,0.000000e+000,0,,0,
1523958424.417,,0.000000e+000,3.999887e+001,-2.118988e-004,0.000000e+000,3,9.913819e-001,0.000000e+000,,,,,,,,,,,,,,32,1,4.000000e+000,2.067566e-003,0.000000e+000,0,,0,
1523958436.598,,0.000000e+000,3.999836e+001,-2.122974e-004,0.000000e+000,3,9.916195e-001,0.000000e+000,,,,,,,,,,,,,,32,1,4.000000e+000,1.037598e-003,0.000000e+000,0,,0,
1523958449.040,,0.000000e+000,3.999836e+001,-2.125761e-004,0.000000e+000,3,9.914293e-001,0.000000e+000,,,,,,,,,,,,,,32,1,4.000000e+000,1.037598e-003,0.000000e+000,0,,0,
1523958461.415,,0.000000e+000,3.999836e+001,-2.127097e-004,0.000000e+000,3,9.913011e-001,0.000000e+000,,,,,,,,,,,,,,32,1,4.000000e+000,1.037598e-003,0.000000e+000,0,,0,
1523958473.833,,0.000000e+000,3.999577e+001,-2.128206e-004,0.000000e+000,3,9.911945e-001,0.000000e+000,,,,,,,,,,,,,,32,1,4.000000e+000,4.131317e-003,0.000000e+000,0,,0,
1523958486.163,,0.000000e+000,3.999629e+001,-2.131064e-004,0.000000e+000,3,9.915151e-001,0.000000e+000,,,,,,,,,,,,,,32,1,4.000000e+000,5.168915e-003,0.000000e+000,0,,0,
1523958498.843,,0.000000e+000,3.999733e+001,-2.133452e-004,0.000000e+000,3,9.913666e-001,0.000000e+000,,,,,,,,,,,,,,32,1,4.000000e+000,1.029968e-003,0.000000e+000,0,,0,
1523958511.644,,0.000000e+000,4.000042e+001,-2.135466e-004,0.000000e+000,3,9.914115e-001,0.000000e+000,,,,,,,,,,,,,,32,1,4.000000e+000,5.157471e-003,0.000000e+000,0,,0,
1523958525.199,,0.000000e+000,3.999526e+001,-2.138207e-004,0.000000e+000,3,9.915383e-001,0.000000e+000,,,,,,,,,,,,,,32,1,4.000000e+000,5.161285e-003,0.000000e+000,0,,0,
1523958538.139,,0.000000e+000,3.999939e+001,-2.139827e-004,0.000000e+000,3,9.912727e-001,0.000000e+000,,,,,,,,,,,,,,32,1,4.000000e+000,1.029968e-003,0.000000e+000,0,,0,
1523958551.844,,0.000000e+000,3.999732e+001,-2.142209e-004,0.000000e+000,3,9.913711e-001,0.000000e+000,,,,,,,,,,,,,,32,1,4.000000e+000,5.168915e-003,0.000000e+000,0,,0,
1523958564.174,,0.000000e+000,3.999681e+001,-2.144112e-004,0.000000e+000,3,9.913495e-001,0.000000e+000,,,,,,,,,,,,,,32,1,4.000000e+000,6.198883e-003,0.000000e+000,0,,0,
1523958576.715,,0.000000e+000,3.999733e+001,-2.145878e-004,0.000000e+000,3,9.913298e-001,0.000000e+000,,,,,,,,,,,,,,32,1,4.000000e+000,1.029968e-003,0.000000e+000,0,,0,
1523958589.772,,0.000000e+000,4.000042e+001,-2.147960e-004,0.000000e+000,3,9.914568e-001,0.000000e+000,,,,,,,,,,,,,,32,1,4.000000e+000,1.029968e-003,0.000000e+000,0,,0,
1523958602.335,,0.000000e+000,3.999887e+001,-2.149439e-004,0.000000e+000,3,9.912042e-001,0.000000e+000,,,,,,,,,,,,,,32,1,4.000000e+000,2.067566e-003,0.000000e+000,0,,0,
1523958615.823,,0.000000e+000,3.999887e+001,-2.150982e-004,0.000000e+000,3,9.914081e-001,0.000000e+000,,,,,,,,,,,,,,32,1,4.000000e+000,2.067566e-003,0.000000e+000,0,,0,
1523958627.973,,0.000000e+000,3.999888e+001,-2.152540e-004,0.000000e+000,3,9.915081e-001,0.000000e+000,,,,,,,,,,,,,,32,1,4.000000e+000,0.000000e+000,0.000000e+000,0,,0,
1523958640.126,,0.000000e+000,3.999888e+001,-2.154798e-004,0.000000e+000,3,9.915543e-001,0.000000e+000,,,,,,,,,,,,,,32,1,4.000000e+000,0.000000e+000,0.000000e+000,0,,0,
1523958652.266,,0.000000e+000,3.999888e+001,-2.156345e-004,0.000000e+000,3,9.914221e-001,0.000000e+000,,,,,,,,,,,,,,32,1,4.000000e+000,0.000000e+000,0.000000e+000,0,,0,
1523958664.946,,0.000000e+000,3.999784e+001,-2.158082e-004,0.000000e+000,3,9.913261e-001,0.000000e+000,,,,,,,,,,,,,,32,1,4.000000e+000,2.067566e-003,0.000000e+000,0,,0,
1523958677.306,,0.000000e+000,3.999680e+001,-2.159515e-004,0.000000e+000,3,9.914717e-001,0.000000e+000,,,,,,,,,,,,,,32,1,4.000000e+000,2.071381e-003,0.000000e+000,0,,0,
1523958689.714,,0.000000e+000,3.999888e+001,-2.160691e-004,0.000000e+000,3,9.914928e-001,0.000000e+000,,,,,,,,,,,,,,32,1,4.000000e+000,0.000000e+000,0.000000e+000,0,,0,
1523958701.887,,0.000000e+000,3.999784e+001,-2.162046e-004,0.000000e+000,3,9.915668e-001,0.000000e+000,,,,,,,,,,,,,,32,1,4.000000e+000,2.067566e-003,0.000000e+000,0,,0,
1523958714.304,,0.000000e+000,3.999836e+001,-2.162996e-004,0.000000e+000,3,9.916466e-001,0.000000e+000,,,,,,,,,,,,,,32,1,4.000000e+000,3.097534e-003,0.000000e+000,0,,0,
1523958726.099,,0.000000e+000,3.999784e+001,-2.165095e-004,0.000000e+000,3,9.915303e-001,0.000000e+000,,,,,,,,,,,,,,32,1,4.000000e+000,4.138947e-003,0.000000e+000,0,,0,
1523958738.967,,0.000000e+000,3.999887e+001,-2.166009e-004,0.000000e+000,3,9.916205e-001,0.000000e+000,,,,,,,,,,,,,,32,1,4.000000e+000,2.067566e-003,0.000000e+000,0,,0,
1523958751.547,,0.000000e+000,3.999836e+001,-2.167746e-004,0.000000e+000,3,9.913526e-001,0.000000e+000,,,,,,,,,,,,,,32,1,4.000000e+000,1.037598e-003,0.000000e+000,0,,0,
1523958764.152,,0.000000e+000,4.000094e+001,-2.168435e-004,0.000000e+000,3,9.915997e-001,0.000000e+000,,,,,,,,,,,,,,32,1,4.000000e+000,4.119873e-003,0.000000e+000,0,,0,
1523958776.690,,0.000000e+000,3.999887e+001,-2.169778e-004,0.000000e+000,3,9.914671e-001,0.000000e+000,,,,,,,,,,,,,,32,1,4.000000e+000,2.067566e-003,0.000000e+000,0,,0,
1523958789.218,,0.000000e+000,3.999888e+001,-2.170511e-004,0.000000e+000,3,9.915124e-001,0.000000e+000,,,,,,,,,,,,,,32,1,4.000000e+000,0.000000e+000,0.000000e+000,0,,0,
1523958801.795,,0.000000e+000,3.999939e+001,-2.171785e-004,0.000000e+000,3,9.913743e-001,0.000000e+000,,,,,,,,,,,,,,32,1,4.000000e+000,1.029968e-003,0.000000e+000,0,,0,
1523958815.286,,0.000000e+000,3.999887e+001,-2.172978e-004,0.000000e+000,3,9.915264e-001,0.000000e+000,,,,,,,,,,,,,,32,1,4.000000e+000,2.067566e-003,0.000000e+000,0,,0,
1523958827.418,,0.000000e+000,3.999784e+001,-2.174411e-004,0.000000e+000,3,9.915984e-001,0.000000e+000,,,,,,,,,,,,,,32,1,4.000000e+000,2.067566e-003,0.000000e+000,0,,0,
1523958839.438,,0.000000e+000,3.999784e+001,-2.175536e-004,0.000000e+000,3,9.917223e-001,0.000000e+000,,,,,,,,,,,,,,32,1,4.000000e+000,2.067566e-003,0.000000e+000,0,,0,
1523958852.479,,0.000000e+000,3.999784e+001,-2.176387e-004,0.000000e+000,3,9.913482e-001,0.000000e+000,,,,,,,,,,,,,,32,1,4.000000e+000,2.067566e-003,0.000000e+000,0,,0,
1523958864.766,,0.000000e+000,3.999681e+001,-2.178197e-004,0.000000e+000,3,9.913781e-001,0.000000e+000,,,,,,,,,,,,,,32,1,4.000000e+000,4.138947e-003,0.000000e+000,0,,0,
1523958876.964,,0.000000e+000,3.999784e+001,-2.179304e-004,0.000000e+000,3,9.916470e-001,0.000000e+000,,,,,,,,,,,,,,32,1,4.000000e+000,2.067566e-003,0.000000e+000,0,,0,
1523958889.197,,0.000000e+000,3.999836e+001,-2.180334e-004,0.000000e+000,3,9.915717e-001,0.000000e+000,,,,,,,,,,,,,,32,1,4.000000e+000,3.097534e-003,0.000000e+000,0,,0,
1523958901.684,,0.000000e+000,3.999887e+001,-2.181080e-004,0.000000e+000,3,9.916603e-001,0.000000e+000,,,,,,,,,,,,,,32,1,4.000000e+000,2.067566e-003,0.000000e+000,0,,0,
1523958914.310,,0.000000e+000,3.999784e+001,-2.182945e-004,0.000000e+000,3,9.914994e-001,0.000000e+000,,,,,,,,,,,,,,32,1,4.000000e+000,2.067566e-003,0.000000e+000,0,,0,
1523958927.067,,0.000000e+000,3.999629e+001,-2.183422e-004,0.000000e+000,3,9.916630e-001,0.000000e+000,,,,,,,,,,,,,,32,1,4.000000e+000,1.041412e-003,0.000000e+000,0,,0,
1523958939.542,,0.000000e+000,3.999733e+001,-2.183988e-004,0.000000e+000,3,9.915706e-001,0.000000e+000,,,,,,,,,,,,,,32,1,4.000000e+000,1.029968e-003,0.000000e+000,0,,0,
1523958952.045,,0.000000e+000,3.999836e+001,-2.184966e-004,0.000000e+000,3,9.917416e-001,0.000000e+000,,,,,,,,,,,,,,32,1,4.000000e+000,1.037598e-003,0.000000e+000,0,,0,
1523958965.285,,0.000000e+000,3.999836e+001,-2.186116e-004,0.000000e+000,3,9.916477e-001,0.000000e+000,,,,,,,,,,,,,,32,1,4.000000e+000,1.037598e-003,0.000000e+000,0,,0,
1523958977.813,,0.000000e+000,3.999732e+001,-2.188039e-004,0.000000e+000,3,9.915455e-001,0.000000e+000,,,,,,,,,,,,,,32,1,4.000000e+000,3.108978e-003,0.000000e+000,0,,0,
1523958990.426,,0.000000e+000,3.999681e+001,-2.188203e-004,0.000000e+000,3,9.915250e-001,0.000000e+000,,,,,,,,,,,,,,32,1,4.000000e+000,0.000000e+000,0.000000e+000,0,,0,
1523959002.956,,0.000000e+000,3.999836e+001,-2.188670e-004,0.000000e+000,3,9.914577e-001,0.000000e+000,,,,,,,,,,,,,,32,1,4.000000e+000,1.037598e-003,0.000000e+000,0,,0,
1523959015.509,,0.000000e+000,3.999836e+001,-2.189858e-004,0.000000e+000,3,9.915419e-001,0.000000e+000,,,,,,,,,,,,,,32,1,4.000000e+000,1.037598e-003,0.000000e+000,0,,0,
1523959027.876,,0.000000e+000,3.999784e+001,-2.191642e-004,0.000000e+000,3,9.914429e-001,0.000000e+000,,,,,,,,,,,,,,32,1,4.000000e+000,0.000000e+000,0.000000e+000,0,,0,
1523959039.996,,0.000000e+000,3.999836e+001,-2.192420e-004,0.000000e+000,3,9.915372e-001,0.000000e+000,,,,,,,,,,,,,,32,1,4.000000e+000,1.037598e-003,0.000000e+000,0,,0,
1523959052.434,,0.000000e+000,3.999733e+001,-2.193096e-004,0.000000e+000,3,9.916740e-001,0.000000e+000,,,,,,,,,,,,,,32,1,4.000000e+000,1.029968e-003,0.000000e+000,0,,0,
1523959064.942,,0.000000e+000,3.999784e+001,-2.193651e-004,0.000000e+000,3,9.915566e-001,0.000000e+000,,,,,,,,,,,,,,32,1,4.000000e+000,2.067566e-003,0.000000e+000,0,,0,
1523959078.182,,0.000000e+000,3.999836e+001,-2.194855e-004,0.000000e+000,3,9.915575e-001,0.000000e+000,,,,,,,,,,,,,,32,1,4.000000e+000,1.037598e-003,0.000000e+000,0,,0,
1523959091.280,,0.000000e+000,3.999887e+001,-2.195518e-004,0.000000e+000,3,9.915010e-001,0.000000e+000,,,,,,,,,,,,,,32,1,4.000000e+000,4.127502e-003,0.000000e+000,0,,0,
1523959103.502,,0.000000e+000,3.999887e+001,-2.196782e-004,0.000000e+000,3,9.913369e-001,0.000000e+000,,,,,,,,,,,,,,32,1,4.000000e+000,4.127502e-003,0.000000e+000,0,,0,
1523959116.043,,0.000000e+000,3.999888e+001,-2.197244e-004,0.000000e+000,3,9.915631e-001,0.000000e+000,,,,,,,,,,,,,,32,1,4.000000e+000,0.000000e+000,0.000000e+000,0,,0,
1523959128.463,,0.000000e+000,3.999836e+001,-2.197997e-004,0.000000e+000,3,9.915940e-001,0.000000e+000,,,,,,,,,,,,,,32,1,4.000000e+000,1.037598e-003,0.000000e+000,0,,0,
1523959140.518,,0.000000e+000,3.999784e+001,-2.199101e-004,0.000000e+000,3,9.916044e-001,0.000000e+000,,,,,,,,,,,,,,32,1,4.000000e+000,0.000000e+000,0.000000e+000,0,,0,
1523959152.961,,0.000000e+000,3.999836e+001,-2.198958e-004,0.000000e+000,3,9.916414e-001,0.000000e+000,,,,,,,,,,,,,,32,1,4.000000e+000,1.037598e-003,0.000000e+000,0,,0,
1523959166.128,,0.000000e+000,3.999733e+001,-2.200668e-004,0.000000e+000,3,9.914282e-001,0.000000e+000,,,,,,,,,,,,,,32,1,4.000000e+000,1.029968e-003,0.000000e+000,0,,0,
1523959178.616,,0.000000e+000,3.999888e+001,-2.201112e-004,0.000000e+000,3,9.914775e-001,0.000000e+000,,,,,,,,,,,,,,32,1,4.000000e+000,0.000000e+000,0.000000e+000,0,,0,
1523959191.029,,0.000000e+000,3.999888e+001,-2.202134e-004,0.000000e+000,3,9.916169e-001,0.000000e+000,,,,,,,,,,,,,,32,1,4.000000e+000,0.000000e+000,0.000000e+000,0,,0,
1523959204.051,,0.000000e+000,3.999888e+001,-2.202896e-004,0.000000e+000,3,9.915732e-001,0.000000e+000,,,,,,,,,,,,,,32,1,4.000000e+000,0.000000e+000,0.000000e+000,0,,0,
1523959216.564,,0.000000e+000,3.999939e+001,-2.203153e-004,0.000000e+000,3,9.915937e-001,0.000000e+000,,,,,,,,,,,,,,32,1,4.000000e+000,1.029968e-003,0.000000e+000,0,,0,
1523959228.974,,0.000000e+000,3.999887e+001,-2.204617e-004,0.000000e+000,3,9.917220e-001,0.000000e+000,,,,,,,,,,,,,,32,1,4.000000e+000,2.067566e-003,0.000000e+000,0,,0,
1523959242.387,,0.000000e+000,3.999836e+001,-2.204552e-004,0.000000e+000,3,9.916947e-001,0.000000e+000,,,,,,,,,,,,,,32,1,4.000000e+000,3.097534e-003,0.000000e+000,0,,0,
1523959254.710,,0.000000e+000,3.999888e+001,-2.205473e-004,0.000000e+000,3,9.915537e-001,0.000000e+000,,,,,,,,,,,,,,32,1,4.000000e+000,0.000000e+000,0.000000e+000,0,,0,
1523959267.630,,0.000000e+000,3.999888e+001,-2.206485e-004,0.000000e+000,3,9.915797e-001,0.000000e+000,,,,,,,,,,,,,,32,1,4.000000e+000,0.000000e+000,0.000000e+000,0,,0,
1523959281.287,,0.000000e+000,3.999836e+001,-2.207184e-004,0.000000e+000,3,9.917412e-001,0.000000e+000,,,,,,,,,,,,,,32,1,4.000000e+000,1.037598e-003,0.000000e+000,0,,0,
1523959293.688,,0.000000e+000,3.999784e+001,-2.207761e-004,0.000000e+000,3,9.917635e-001,0.000000e+000,,,,,,,,,,,,,,32,1,4.000000e+000,2.067566e-003,0.000000e+000,0,,0,
1523959306.125,,0.000000e+000,3.999474e+001,-2.208319e-004,0.000000e+000,3,9.917536e-001,0.000000e+000,,,,,,,,,,,,,,32,1,4.000000e+000,4.131317e-003,0.000000e+000,0,,0,
1523959318.486,,0.000000e+000,4.000042e+001,-2.209230e-004,0.000000e+000,3,9.916744e-001,0.000000e+000,,,,,,,,,,,,,,32,1,4.000000e+000,1.029968e-003,0.000000e+000,0,,0,
1523959330.663,,0.000000e+000,3.999836e+001,-2.210381e-004,0.000000e+000,3,9.917055e-001,0.000000e+000,,,,,,,,,,,,,,32,1,4.000000e+000,1.037598e-003,0.000000e+000,0,,0,
1523959342.841,,0.000000e+000,3.999784e+001,-2.211307e-004,0.000000e+000,3,9.916074e-001,0.000000e+000,,,,,,,,,,,,,,32,1,4.000000e+000,2.067566e-003,0.000000e+000,0,,0,
1523959355.714,,0.000000e+000,3.999836e+001,-2.210796e-004,0.000000e+000,3,9.915268e-001,0.000000e+000,,,,,,,,,,,,,,32,1,4.000000e+000,1.037598e-003,0.000000e+000,0,,0,
1523959368.111,,0.000000e+000,3.999784e+001,-2.211211e-004,0.000000e+000,3,9.914445e-001,0.000000e+000,,,,,,,,,,,,,,32,1,4.000000e+000,0.000000e+000,0.000000e+000,0,,0,
1523959380.286,,0.000000e+000,3.999888e+001,-2.212967e-004,0.000000e+000,3,9.916849e-001,0.000000e+000,,,,,,,,,,,,,,32,1,4.000000e+000,0.000000e+000,0.000000e+000,0,,0,
1523959392.442,,0.000000e+000,3.999887e+001,-2.213820e-004,0.000000e+000,3,9.916931e-001,0.000000e+000,,,,,,,,,,,,,,32,1,4.000000e+000,2.067566e-003,0.000000e+000,0,,0,
1523959404.482,,0.000000e+000,3.999681e+001,-2.213443e-004,0.000000e+000,3,9.914956e-001,0.000000e+000,,,,,,,,,,,,,,32,1,4.000000e+000,0.000000e+000,0.000000e+000,0,,0,
1523959416.942,,0.000000e+000,3.999887e+001,-2.214808e-004,0.000000e+000,3,9.916027e-001,0.000000e+000,,,,,,,,,,,,,,32,1,4.000000e+000,2.067566e-003,0.000000e+000,0,,0,
1523959429.407,,0.000000e+000,3.999680e+001,-2.214781e-004,0.000000e+000,3,9.916070e-001,0.000000e+000,,,,,,,,,,,,,,32,1,4.000000e+000,2.071381e-003,0.000000e+000,0,,0,
1523959442.060,,0.000000e+000,3.999887e+001,-2.215667e-004,0.000000e+000,3,9.914758e-001,0.000000e+000,,,,,,,,,,,,,,32,1,4.000000e+000,4.127502e-003,0.000000e+000,0,,0,
1523959454.768,,0.000000e+000,3.999733e+001,-2.215572e-004,0.000000e+000,3,9.914141e-001,0.000000e+000,,,,,,,,,,,,,,32,1,4.000000e+000,1.029968e-003,0.000000e+000,0,,0,
1523959467.613,,0.000000e+000,3.999836e+001,-2.216905e-004,0.000000e+000,3,9.913753e-001,0.000000e+000,,,,,,,,,,,,,,32,1,4.000000e+000,1.037598e-003,0.000000e+000,0,,0,
1523959480.243,,0.000000e+000,3.999991e+001,-2.217367e-004,0.000000e+000,3,9.915718e-001,0.000000e+000,,,,,,,,,,,,,,32,1,4.000000e+000,2.059937e-003,0.000000e+000,0,,0,
1523959493.193,,0.000000e+000,3.999784e+001,-2.218086e-004,0.000000e+000,3,9.915904e-001,0.000000e+000,,,,,,,,,,,,,,32,1,4.000000e+000,0.000000e+000,0.000000e+000,0,,0,
1523959505.858,,0.000000e+000,3.999836e+001,-2.218780e-004,0.000000e+000,3,9.915854e-001,0.000000e+000,,,,,,,,,,,,,,32,1,4.000000e+000,1.037598e-003,0.000000e+000,0,,0,
1523959518.291,,0.000000e+000,3.999939e+001,-2.219342e-004,0.000000e+000,3,9.915254e-001,0.000000e+000,,,,,,,,,,,,,,32,1,4.000000e+000,1.029968e-003,0.000000e+000,0,,0,
1523959530.684,,0.000000e+000,3.999681e+001,-2.219554e-004,0.000000e+000,3,9.916909e-001,0.000000e+000,,,,,,,,,,,,,,32,1,4.000000e+000,0.000000e+000,0.000000e+000,0,,0,
1523959543.284,,0.000000e+000,3.999784e+001,-2.220440e-004,0.000000e+000,3,9.915158e-001,0.000000e+000,,,,,,,,,,,,,,32,1,4.000000e+000,4.138947e-003,0.000000e+000,0,,0,
1523959556.264,,0.000000e+000,3.999888e+001,-2.220774e-004,0.000000e+000,3,9.915147e-001,0.000000e+000,,,,,,,,,,,,,,32,1,4.000000e+000,0.000000e+000,0.000000e+000,0,,0,
1523959569.424,,0.000000e+000,3.999888e+001,-2.221430e-004,0.000000e+000,3,9.914926e-001,0.000000e+000,,,,,,,,,,,,,,32,1,4.000000e+000,0.000000e+000,0.000000e+000,0,,0,
1523959581.887,,0.000000e+000,3.999991e+001,-2.222608e-004,0.000000e+000,3,9.916098e-001,0.000000e+000,,,,,,,,,,,,,,32,1,4.000000e+000,2.059937e-003,0.000000e+000,0,,0,
1523959594.507,,0.000000e+000,3.999784e+001,-2.223295e-004,0.000000e+000,3,9.915793e-001,0.000000e+000,,,,,,,,,,,,,,32,1,4.000000e+000,0.000000e+000,0.000000e+000,0,,0,
1523959606.987,,0.000000e+000,3.999939e+001,-2.223683e-004,0.000000e+000,3,9.915313e-001,0.000000e+000,,,,,,,,,,,,,,32,1,4.000000e+000,1.029968e-003,0.000000e+000,0,,0,
1523959619.590,,0.000000e+000,3.999939e+001,-2.223863e-004,0.000000e+000,3,9.917235e-001,0.000000e+000,,,,,,,,,,,,,,32,1,4.000000e+000,1.029968e-003,0.000000e+000,0,,0,
1523959631.930,,0.000000e+000,3.999680e+001,-2.224814e-004,0.000000e+000,3,9.916018e-001,0.000000e+000,,,,,,,,,,,,,,32,1,4.000000e+000,2.071381e-003,0.000000e+000,0,,0,
1523959644.238,,0.000000e+000,3.999784e+001,-2.224953e-004,0.000000e+000,3,9.913800e-001,0.000000e+000,,,,,,,,,,,,,,32,1,4.000000e+000,0.000000e+000,0.000000e+000,0,,0,
1523959657.180,,0.000000e+000,3.999784e+001,-2.225525e-004,0.000000e+000,3,9.914379e-001,0.000000e+000,,,,,,,,,,,,,,32,1,4.000000e+000,0.000000e+000,0.000000e+000,0,,0,
1523959670.093,,0.000000e+000,3.999784e+001,-2.225900e-004,0.000000e+000,3,9.916168e-001,0.000000e+000,,,,,,,,,,,,,,32,1,4.000000e+000,0.000000e+000,0.000000e+000,0,,0,
1523959682.693,,0.000000e+000,3.999681e+001,-2.226383e-004,0.000000e+000,3,9.914579e-001,0.000000e+000,,,,,,,,,,,,,,32,1,4.000000e+000,4.138947e-003,0.000000e+000,0,,0,
1523959695.746,,0.000000e+000,3.999836e+001,-2.227467e-004,0.000000e+000,3,9.915788e-001,0.000000e+000,,,,,,,,,,,,,,32,1,4.000000e+000,1.037598e-003,0.000000e+000,0,,0,
1523959709.064,,0.000000e+000,3.999939e+001,-2.227732e-004,0.000000e+000,3,9.915674e-001,0.000000e+000,,,,,,,,,,,,,,32,1,4.000000e+000,1.029968e-003,0.000000e+000,0,,0,
1523959722.169,,0.000000e+000,3.999784e+001,-2.228463e-004,0.000000e+000,3,9.916742e-001,0.000000e+000,,,,,,,,,,,,,,32,1,4.000000e+000,4.138947e-003,0.000000e+000,0,,0,
1523959735.269,,0.000000e+000,3.999887e+001,-2.228812e-004,0.000000e+000,3,9.915796e-001,0.000000e+000,,,,,,,,,,,,,,32,1,4.000000e+000,2.067566e-003,0.000000e+000,0,,0,
1523959747.989,,0.000000e+000,3.999887e+001,-2.229142e-004,0.000000e+000,3,9.914122e-001,0.000000e+000,,,,,,,,,,,,,,32,1,4.000000e+000,2.067566e-003,0.000000e+000,0,,0,
1523959760.589,,0.000000e+000,3.999991e+001,-2.230093e-004,0.000000e+000,3,9.915285e-001,0.000000e+000,,,,,,,,,,,,,,32,1,4.000000e+000,0.000000e+000,0.000000e+000,0,,0,
1523959773.260,,0.000000e+000,3.999784e+001,-2.230457e-004,0.000000e+000,3,9.915677e-001,0.000000e+000,,,,,,,,,,,,,,32,1,4.000000e+000,0.000000e+000,0.000000e+000,0,,0,
1523959786.660,,0.000000e+000,3.999888e+001,-2.231197e-004,0.000000e+000,3,9.915233e-001,0.000000e+000,,,,,,,,,,,,,,32,1,4.000000e+000,0.000000e+000,0.000000e+000,0,,0,
1523959799.073,,0.000000e+000,3.999888e+001,-2.231313e-004,0.000000e+000,3,9.916999e-001,0.000000e+000,,,,,,,,,,,,,,32,1,4.000000e+000,0.000000e+000,0.000000e+000,0,,0,
1523959811.245,,0.000000e+000,3.999836e+001,-2.231900e-004,0.000000e+000,3,9.916564e-001,0.000000e+000,,,,,,,,,,,,,,32,1,4.000000e+000,1.037598e-003,0.000000e+000,0,,0,
1523959824.190,,0.000000e+000,3.999733e+001,-2.231903e-004,0.000000e+000,3,9.915116e-001,0.000000e+000,,,,,,,,,,,,,,32,1,4.000000e+000,1.029968e-003,0.000000e+000,0,,0,
1523959836.806,,0.000000e+000,3.999939e+001,-2.232806e-004,0.000000e+000,3,9.916300e-001,0.000000e+000,,,,,,,,,,,,,,32,1,4.000000e+000,3.097534e-003,0.000000e+000,0,,0,
1523959850.136,,0.000000e+000,3.999836e+001,-2.233211e-004,0.000000e+000,3,9.915857e-001,0.000000e+000,,,,,,,,,,,,,,32,1,4.000000e+000,1.037598e-003,0.000000e+000,0,,0,
1523959862.681,,0.000000e+000,3.999991e+001,-2.233353e-004,0.000000e+000,3,9.915497e-001,0.000000e+000,,,,,,,,,,,,,,32,1,4.000000e+000,2.059937e-003,0.000000e+000,0,,0,
1523959875.521,,0.000000e+000,3.999888e+001,-2.234370e-004,0.000000e+000,3,9.915998e-001,0.000000e+000,,,,,,,,,,,,,,32,1,4.000000e+000,0.000000e+000,0.000000e+000,0,,0,
1523959888.064,,0.000000e+000,3.999939e+001,-2.234843e-004,0.000000e+000,3,9.916973e-001,0.000000e+000,,,,,,,,,,,,,,32,1,4.000000e+000,1.029968e-003,0.000000e+000,0,,0,
1523959900.349,,0.000000e+000,3.999887e+001,-2.235648e-004,0.000000e+000,3,9.915640e-001,0.000000e+000,,,,,,,,,,,,,,32,1,4.000000e+000,2.067566e-003,0.000000e+000,0,,0,
1523959914.039,,0.000000e+000,3.999887e+001,-2.236426e-004,0.000000e+000,3,9.916361e-001,0.000000e+000,,,,,,,,,,,,,,32,1,4.000000e+000,2.067566e-003,0.000000e+000,0,,0,
1523959927.002,,0.000000e+000,3.999784e+001,-2.236280e-004,0.000000e+000,3,9.915746e-001,0.000000e+000,,,,,,,,,,,,,,32,1,4.000000e+000,0.000000e+000,0.000000e+000,0,,0,
1523959939.657,,0.000000e+000,3.999939e+001,-2.236948e-004,0.000000e+000,3,9.915438e-001,0.000000e+000,,,,,,,,,,,,,,32,1,4.000000e+000,3.097534e-003,0.000000e+000,0,,0,
1523959953.332,,0.000000e+000,3.999888e+001,-2.237109e-004,0.000000e+000,3,9.916841e-001,0.000000e+000,,,,,,,,,,,,,,32,1,4.000000e+000,0.000000e+000,0.000000e+000,0,,0,
1523959966.055,,0.000000e+000,4.000042e+001,-2.237821e-004,0.000000e+000,3,9.914576e-001,0.000000e+000,,,,,,,,,,,,,,32,1,4.000000e+000,1.029968e-003,0.000000e+000,0,,0,
1523959978.768,,0.000000e+000,3.999836e+001,-2.238371e-004,0.000000e+000,3,9.915230e-001,0.000000e+000,,,,,,,,,,,,,,32,1,4.000000e+000,1.037598e-003,0.000000e+000,0,,0,
1523959991.200,,0.000000e+000,3.999836e+001,-2.238774e-004,0.000000e+000,3,9.916672e-001,0.000000e+000,,,,,,,,,,,,,,32,1,4.000000e+000,1.037598e-003,0.000000e+000,0,,0,
1523960004.701,,0.000000e+000,3.999836e+001,-2.239106e-004,0.000000e+000,3,9.915980e-001,0.000000e+000,,,,,,,,,,,,,,32,1,4.000000e+000,1.037598e-003,0.000000e+000,0,,0,
1523960017.056,,0.000000e+000,3.999836e+001,-2.240021e-004,0.000000e+000,3,9.914498e-001,0.000000e+000,,,,,,,,,,,,,,32,1,4.000000e+000,1.037598e-003,0.000000e+000,0,,0,
1523960030.169,,0.000000e+000,3.999681e+001,-2.238081e-004,0.000000e+000,3,9.913217e-001,0.000000e+000,,,,,,,,,,,,,,32,1,4.000000e+000,4.138947e-003,0.000000e+000,0,,0,
1523960043.586,,0.000000e+000,3.999991e+001,-2.239792e-004,0.000000e+000,3,9.918450e-001,0.000000e+000,,,,,,,,,,,,,,32,1,4.000000e+000,0.000000e+000,0.000000e+000,0,,0,
1523960056.111,,0.000000e+000,3.999836e+001,-2.240987e-004,0.000000e+000,3,9.914373e-001,0.000000e+000,,,,,,,,,,,,,,32,1,4.000000e+000,1.037598e-003,0.000000e+000,0,,0,
1523960068.954,,0.000000e+000,3.999939e+001,-2.240592e-004,0.000000e+000,3,9.915466e-001,0.000000e+000,,,,,,,,,,,,,,32,1,4.000000e+000,1.029968e-003,0.000000e+000,0,,0,
1523960081.464,,0.000000e+000,3.999887e+001,-2.241220e-004,0.000000e+000,3,9.915861e-001,0.000000e+000,,,,,,,,,,,,,,32,1,4.000000e+000,2.067566e-003,0.000000e+000,0,,0,
1523960094.709,,0.000000e+000,4.000197e+001,-2.242031e-004,0.000000e+000,3,9.917826e-001,0.000000e+000,,,,,,,,,,,,,,32,1,4.000000e+000,2.059937e-003,0.000000e+000,0,,0,
1523960106.487,,0.000000e+000,3.999887e+001,-2.242490e-004,0.000000e+000,3,9.916696e-001,0.000000e+000,,,,,,,,,,,,,,32,1,4.000000e+000,4.127502e-003,0.000000e+000,0,,0,
1523960119.467,,0.000000e+000,3.999939e+001,-2.243116e-004,0.000000e+000,3,9.915606e-001,0.000000e+000,,,,,,,,,,,,,,32,1,4.000000e+000,1.029968e-003,0.000000e+000,0,,0,
1523960131.968,,0.000000e+000,3.999888e+001,-2.243385e-004,0.000000e+000,3,9.917021e-001,0.000000e+000,,,,,,,,,,,,,,32,1,4.000000e+000,0.000000e+000,0.000000e+000,0,,0,
1523960144.925,,0.000000e+000,3.999784e+001,-2.243701e-004,0.000000e+000,3,9.915775e-001,0.000000e+000,,,,,,,,,,,,,,32,1,4.000000e+000,0.000000e+000,0.000000e+000,0,,0,
1523960157.435,,0.000000e+000,3.999784e+001,-2.244206e-004,0.000000e+000,3,9.917022e-001,0.000000e+000,,,,,,,,,,,,,,32,1,4.000000e+000,0.000000e+000,0.000000e+000,0,,0,
1523960169.788,,0.000000e+000,3.999733e+001,-2.244867e-004,0.000000e+000,3,9.913764e-001,0.000000e+000,,,,,,,,,,,,,,32,1,4.000000e+000,1.029968e-003,0.000000e+000,0,,0,
1523960183.156,,0.000000e+000,3.999887e+001,-2.245462e-004,0.000000e+000,3,9.915249e-001,0.000000e+000,,,,,,,,,,,,,,32,1,4.000000e+000,2.067566e-003,0.000000e+000,0,,0,
1523960195.566,,0.000000e+000,3.999939e+001,-2.245527e-004,0.000000e+000,3,9.916644e-001,0.000000e+000,,,,,,,,,,,,,,32,1,4.000000e+000,1.029968e-003,0.000000e+000,0,,0,
1523960207.576,,0.000000e+000,3.999991e+001,-2.246642e-004,0.000000e+000,3,9.916560e-001,0.000000e+000,,,,,,,,,,,,,,32,1,4.000000e+000,0.000000e+000,0.000000e+000,0,,0,
1523960220.146,,0.000000e+000,4.000042e+001,-2.246165e-004,0.000000e+000,3,9.916264e-001,0.000000e+000,,,,,,,,,,,,,,32,1,4.000000e+000,3.089905e-003,0.000000e+000,0,,0,
1523960232.406,,0.000000e+000,3.999991e+001,-2.246889e-004,0.000000e+000,3,9.916890e-001,0.000000e+000,,,,,,,,,,,,,,32,1,4.000000e+000,0.000000e+000,0.000000e+000,0,,0,
1523960244.654,,0.000000e+000,3.999939e+001,-2.247012e-004,0.000000e+000,3,9.916926e-001,0.000000e+000,,,,,,,,,,,,,,32,1,4.000000e+000,1.029968e-003,0.000000e+000,0,,0,
1523960256.709,,0.000000e+000,3.999888e+001,-2.247836e-004,0.000000e+000,3,9.915977e-001,0.000000e+000,,,,,,,,,,,,,,32,1,4.000000e+000,0.000000e+000,0.000000e+000,0,,0,
1523960269.229,,0.000000e+000,3.999836e+001,-2.247813e-004,0.000000e+000,3,9.915840e-001,0.000000e+000,,,,,,,,,,,,,,32,1,4.000000e+000,1.037598e-003,0.000000e+000,0,,0,
1523960281.757,,0.000000e+000,3.999784e+001,-2.248285e-004,0.000000e+000,3,9.914504e-001,0.000000e+000,,,,,,,,,,,,,,32,1,4.000000e+000,0.000000e+000,0.000000e+000,0,,0,
1523960294.830,,0.000000e+000,4.000042e+001,-2.248807e-004,0.000000e+000,3,9.914594e-001,0.000000e+000,,,,,,,,,,,,,,32,1,4.000000e+000,1.029968e-003,0.000000e+000,0,,0,
1523960307.240,,0.000000e+000,3.999681e+001,-2.249103e-004,0.000000e+000,3,9.916835e-001,0.000000e+000,,,,,,,,,,,,,,32,1,4.000000e+000,0.000000e+000,0.000000e+000,0,,0,
1523960319.803,,0.000000e+000,3.999784e+001,-2.249427e-004,0.000000e+000,3,9.915765e-001,0.000000e+000,,,,,,,,,,,,,,32,1,4.000000e+000,2.067566e-003,0.000000e+000,0,,0,
1523960333.050,,0.000000e+000,3.999836e+001,-2.249796e-004,0.000000e+000,3,9.916384e-001,0.000000e+000,,,,,,,,,,,,,,32,1,4.000000e+000,3.097534e-003,0.000000e+000,0,,0,
1523960345.483,,0.000000e+000,3.999939e+001,-2.249991e-004,0.000000e+000,3,9.917334e-001,0.000000e+000,,,,,,,,,,,,,,32,1,4.000000e+000,1.029968e-003,0.000000e+000,0,,0,
1523960357.636,,0.000000e+000,3.999888e+001,-2.251471e-004,0.000000e+000,3,9.917178e-001,0.000000e+000,,,,,,,,,,,,,,32,1,4.000000e+000,0.000000e+000,0.000000e+000,0,,0,
1523960369.793,,0.000000e+000,3.999784e+001,-2.251220e-004,0.000000e+000,3,9.916171e-001,0.000000e+000,,,,,,,,,,,,,,32,1,4.000000e+000,2.067566e-003,0.000000e+000,0,,0,
1523960381.849,,0.000000e+000,3.999681e+001,-2.251692e-004,0.000000e+000,3,9.915788e-001,0.000000e+000,,,,,,,,,,,,,,32,1,4.000000e+000,0.000000e+000,0.000000e+000,0,,0,
1523960394.971,,0.000000e+000,3.999629e+001,-2.252014e-004,0.000000e+000,3,9.916342e-001,0.000000e+000,,,,,,,,,,,,,,32,1,4.000000e+000,1.041412e-003,0.000000e+000,0,,0,
1523960407.371,,0.000000e+000,3.999732e+001,-2.252165e-004,0.000000e+000,3,9.916586e-001,0.000000e+000,,,,,,,,,,,,,,32,1,4.000000e+000,3.108978e-003,0.000000e+000,0,,0,
1523960420.412,,0.000000e+000,3.999939e+001,-2.252151e-004,0.000000e+000,3,9.915770e-001,0.000000e+000,,,,,,,,,,,,,,32,1,4.000000e+000,1.029968e-003,0.000000e+000,0,,0,
1523960433.824,,0.000000e+000,3.999888e+001,-2.252589e-004,0.000000e+000,3,9.916820e-001,0.000000e+000,,,,,,,,,,,,,,32,1,4.000000e+000,0.000000e+000,0.000000e+000,0,,0,
1523960446.477,,0.000000e+000,3.999888e+001,-2.253406e-004,0.000000e+000,3,9.916149e-001,0.000000e+000,,,,,,,,,,,,,,32,1,4.000000e+000,0.000000e+000,0.000000e+000,0,,0,
1523960459.280,,0.000000e+000,3.999836e+001,-2.253110e-004,0.000000e+000,3,9.914751e-001,0.000000e+000,,,,,,,,,,,,,,32,1,4.000000e+000,1.037598e-003,0.000000e+000,0,,0,
1523960471.872,,0.000000e+000,3.999887e+001,-2.253545e-004,0.000000e+000,3,9.916520e-001,0.000000e+000,,,,,,,,,,,,,,32,1,4.000000e+000,4.127502e-003,0.000000e+000,0,,0,
1523960484.250,,0.000000e+000,3.999836e+001,-2.254140e-004,0.000000e+000,3,9.914542e-001,0.000000e+000,,,,,,,,,,,,,,32,1,4.000000e+000,1.037598e-003,0.000000e+000,0,,0,
1523960497.653,,0.000000e+000,3.999888e+001,-2.254588e-004,0.000000e+000,3,9.916868e-001,0.000000e+000,,,,,,,,,,,,,,32,1,4.000000e+000,0.000000e+000,0.000000e+000,0,,0,
1523960510.883,,0.000000e+000,3.999939e+001,-2.255044e-004,0.000000e+000,3,9.916105e-001,0.000000e+000,,,,,,,,,,,,,,32,1,4.000000e+000,1.029968e-003,0.000000e+000,0,,0,
1523960523.348,,0.000000e+000,3.999939e+001,-2.255257e-004,0.000000e+000,3,9.915927e-001,0.000000e+000,,,,,,,,,,,,,,32,1,4.000000e+000,1.029968e-003,0.000000e+000,0,,0,
1523960536.593,,0.000000e+000,3.999887e+001,-2.255381e-004,0.000000e+000,3,9.915185e-001,0.000000e+000,,,,,,,,,,,,,,32,1,4.000000e+000,2.067566e-003,0.000000e+000,0,,0,
1523960549.066,,0.000000e+000,3.999887e+001,-2.256116e-004,0.000000e+000,3,9.916420e-001,0.000000e+000,,,,,,,,,,,,,,32,1,4.000000e+000,2.067566e-003,0.000000e+000,0,,0,
1523960562.154,,0.000000e+000,3.999887e+001,-2.256259e-004,0.000000e+000,3,9.916474e-001,0.000000e+000,,,,,,,,,,,,,,32,1,4.000000e+000,2.067566e-003,0.000000e+000,0,,0,
1523960574.776,,0.000000e+000,3.999784e+001,-2.256836e-004,0.000000e+000,3,9.914125e-001,0.000000e+000,,,,,,,,,,,,,,32,1,4.000000e+000,0.000000e+000,0.000000e+000,0,,0,
1523960588.399,,0.000000e+000,3.999887e+001,-2.256900e-004,0.000000e+000,3,9.915844e-001,0.000000e+000,,,,,,,,,,,,,,32,1,4.000000e+000,2.067566e-003,0.000000e+000,0,,0,
1523960600.729,,0.000000e+000,3.999836e+001,-2.257345e-004,0.000000e+000,3,9.916559e-001,0.000000e+000,,,,,,,,,,,,,,32,1,4.000000e+000,1.037598e-003,0.000000e+000,0,,0,
1523960613.065,,0.000000e+000,3.999939e+001,-2.257982e-004,0.000000e+000,3,9.916619e-001,0.000000e+000,,,,,,,,,,,,,,32,1,4.000000e+000,1.029968e-003,0.000000e+000,0,,0,
1523960626.177,,0.000000e+000,3.999836e+001,-2.257635e-004,0.000000e+000,3,9.916750e-001,0.000000e+000,,,,,,,,,,,,,,32,1,4.000000e+000,1.037598e-003,0.000000e+000,0,,0,
1523960639.072,,0.000000e+000,3.999888e+001,-2.257914e-004,0.000000e+000,3,9.915569e-001,0.000000e+000,,,,,,,,,,,,,,32,1,4.000000e+000,0.000000e+000,0.000000e+000,0,,0,
1523960652.105,,0.000000e+000,3.999888e+001,-2.259052e-004,0.000000e+000,3,9.916537e-001,0.000000e+000,,,,,,,,,,,,,,32,1,4.000000e+000,0.000000e+000,0.000000e+000,0,,0,
1523960664.723,,0.000000e+000,3.999784e+001,-2.258920e-004,0.000000e+000,3,9.915351e-001,0.000000e+000,,,,,,,,,,,,,,32,1,4.000000e+000,2.067566e-003,0.000000e+000,0,,0,
1523960677.620,,0.000000e+000,3.999939e+001,-2.259156e-004,0.000000e+000,3,9.915885e-001,0.000000e+000,,,,,,,,,,,,,,32,1,4.000000e+000,1.029968e-003,0.000000e+000,0,,0,
1523960691.098,,0.000000e+000,3.999888e+001,-2.259492e-004,0.000000e+000,3,9.916926e-001,0.000000e+000,,,,,,,,,,,,,,32,1,4.000000e+000,0.000000e+000,0.000000e+000,0,,0,
1523960702.886,,0.000000e+000,3.999991e+001,-2.260304e-004,0.000000e+000,3,9.916611e-001,0.000000e+000,,,,,,,,,,,,,,32,1,4.000000e+000,0.000000e+000,0.000000e+000,0,,0,
1523960716.044,,0.000000e+000,3.999939e+001,-2.260674e-004,0.000000e+000,3,9.916008e-001,0.000000e+000,,,,,,,,,,,,,,32,1,4.000000e+000,1.029968e-003,0.000000e+000,0,,0,
1523960729.186,,0.000000e+000,3.999836e+001,-2.260633e-004,0.000000e+000,3,9.915860e-001,0.000000e+000,,,,,,,,,,,,,,32,1,4.000000e+000,1.037598e-003,0.000000e+000,0,,0,
1523960741.531,,0.000000e+000,3.999939e+001,-2.260913e-004,0.000000e+000,3,9.916446e-001,0.000000e+000,,,,,,,,,,,,,,32,1,4.000000e+000,1.029968e-003,0.000000e+000,0,,0,
1523960753.654,,0.000000e+000,3.999939e+001,-2.261623e-004,0.000000e+000,3,9.916289e-001,0.000000e+000,,,,,,,,,,,,,,32,1,4.000000e+000,1.029968e-003,0.000000e+000,0,,0,
1523960765.842,,0.000000e+000,3.999836e+001,-2.261952e-004,0.000000e+000,3,9.916599e-001,0.000000e+000,,,,,,,,,,,,,,32,1,4.000000e+000,1.037598e-003,0.000000e+000,0,,0,
1523960777.962,,0.000000e+000,3.999939e+001,-2.262457e-004,0.000000e+000,3,9.916003e-001,0.000000e+000,,,,,,,,,,,,,,32,1,4.000000e+000,1.029968e-003,0.000000e+000,0,,0,
1523960791.115,,0.000000e+000,3.999888e+001,-2.262398e-004,0.000000e+000,3,9.916857e-001,0.000000e+000,,,,,,,,,,,,,,32,1,4.000000e+000,0.000000e+000,0.000000e+000,0,,0,
1523960803.295,,0.000000e+000,3.999836e+001,-2.262789e-004,0.000000e+000,3,9.916589e-001,0.000000e+000,,,,,,,,,,,,,,32,1,4.000000e+000,1.037598e-003,0.000000e+000,0,,0,
1523960815.325,,0.000000e+000,3.999733e+001,-2.263150e-004,0.000000e+000,3,9.916304e-001,0.000000e+000,,,,,,,,,,,,,,32,1,4.000000e+000,1.029968e-003,0.000000e+000,0,,0,
1523960828.403,,0.000000e+000,3.999629e+001,-2.262955e-004,0.000000e+000,3,9.916561e-001,0.000000e+000,,,,,,,,,,,,,,32,1,4.000000e+000,1.041412e-003,0.000000e+000,0,,0,
1523960840.753,,0.000000e+000,3.999732e+001,-2.263749e-004,0.000000e+000,3,9.916212e-001,0.000000e+000,,,,,,,,,,,,,,32,1,4.000000e+000,3.108978e-003,0.000000e+000,0,,0,
1523960852.938,,0.000000e+000,3.999939e+001,-2.263912e-004,0.000000e+000,3,9.916608e-001,0.000000e+000,,,,,,,,,,,,,,32,1,4.000000e+000,3.097534e-003,0.000000e+000,0,,0,
1523960865.066,,0.000000e+000,3.999733e+001,-2.264618e-004,0.000000e+000,3,9.917305e-001,0.000000e+000,,,,,,,,,,,,,,32,1,4.000000e+000,1.029968e-003,0.000000e+000,0,,0,