File: Experimental Raw Data/MFn1 Acquisition/MFn1_VRMac_37K_1500s.dc.dat
[Header]
TITLE,MPMS DC Measurement
BYAPP,MPMS Measurement,2.1,Summary
FILEOPENTIME, 1524209799.799000 4/20/2018, 1:36:39 AM

INFO, APPNAME, MPMS MultiVu Application, Revision 1.61,  Build 082

INFO, NAME, MFn1
INFO, WEIGHT, 1.000
INFO, AREA, 1.000
INFO, LENGTH, 1.000
INFO, SHAPE, 0
INFO, COMMENT,
INFO, SEQUENCE FILE: VRMac_37K_1500s_VRMde_35K.seq


INFO, BACKGROUND DATA FILE:, None


STARTUPAXIS,X,4,LINEAR,AUTO,0.000000,0.000000
STARTUPAXIS,Y1,5,LINEAR,AUTO,0.000000,0.000000


STARTUPGROUP,Longitudinal
FIELDGROUP,Longitudinal,1,2,3,4,5,6,7,8,9,15,16,17,18,27,28
FIELDGROUP,Transverse,1,2,3,4,10,11,12,13,14,19,20,21,22,27,28

PLOT_APPEARANCE,ALL,HORZ_GRID_ON,VERT_GRID_ON,MARKERS_AND_LINES

[Data]
Time,Comment,Field (Oe),Temperature (K),Long Moment (emu),Long Scan Std Dev,Long Algorithm,Long Reg Fit,Long Percent Error (%),Trans Moment (emu),Trans Scan Std Dev,Trans Algorithm,Trans Reg Fit,Trans Percent Error (%),Long Moment [w/o ABS] (emu),Long Scan Std Dev [w/o ABS],Long Reg Fit [w/o ABS],Long Percent Error [w/o ABS] (%),Trans Moment [w/o ABS] (emu),Trans Scan Std Dev [w/o ABS],Trans Reg Fit [w/o ABS],Trans Percent Error [w/o ABS] (%),Points per Scan,Scans per Measurement,Scan Length (cm),Delta Temp (K),Rot Position (deg),Error,EC Comp. Running,Using ABS,
1524209799.797,,0.000000e+000,3.699917e+001,-1.852329e-004,0.000000e+000,3,9.923975e-001,0.000000e+000,,,,,,,,,,,,,,32,1,4.000000e+000,1.758575e-003,0.000000e+000,0,,0,
1524209812.239,,0.000000e+000,3.700049e+001,-1.865852e-004,0.000000e+000,3,9.925655e-001,0.000000e+000,,,,,,,,,,,,,,32,1,4.000000e+000,8.811951e-004,0.000000e+000,0,,0,
1524209825.077,,0.000000e+000,3.700005e+001,-1.876577e-004,0.000000e+000,3,9.926906e-001,0.000000e+000,,,,,,,,,,,,,,32,1,4.000000e+000,0.000000e+000,0.000000e+000,0,,0,
1524209837.542,,0.000000e+000,3.700049e+001,-1.885438e-004,0.000000e+000,3,9.926221e-001,0.000000e+000,,,,,,,,,,,,,,32,1,4.000000e+000,8.811951e-004,0.000000e+000,0,,0,
1524209849.602,,0.000000e+000,3.700005e+001,-1.892559e-004,0.000000e+000,3,9.927720e-001,0.000000e+000,,,,,,,,,,,,,,32,1,4.000000e+000,0.000000e+000,0.000000e+000,0,,0,
1524209862.477,,0.000000e+000,3.700005e+001,-1.899151e-004,0.000000e+000,3,9.927167e-001,0.000000e+000,,,,,,,,,,,,,,32,1,4.000000e+000,1.762390e-003,0.000000e+000,0,,0,
1524209874.538,,0.000000e+000,3.699917e+001,-1.905851e-004,0.000000e+000,3,9.926971e-001,0.000000e+000,,,,,,,,,,,,,,32,1,4.000000e+000,0.000000e+000,0.000000e+000,0,,0,
1524209887.088,,0.000000e+000,3.700005e+001,-1.910873e-004,0.000000e+000,3,9.927436e-001,0.000000e+000,,,,,,,,,,,,,,32,1,4.000000e+000,1.762390e-003,0.000000e+000,0,,0,
1524209899.581,,0.000000e+000,3.700049e+001,-1.915594e-004,0.000000e+000,3,9.927562e-001,0.000000e+000,,,,,,,,,,,,,,32,1,4.000000e+000,8.811951e-004,0.000000e+000,0,,0,
1524209912.588,,0.000000e+000,3.699917e+001,-1.919963e-004,0.000000e+000,3,9.927855e-001,0.000000e+000,,,,,,,,,,,,,,32,1,4.000000e+000,1.758575e-003,0.000000e+000,0,,0,
1524209924.788,,0.000000e+000,3.699961e+001,-1.923928e-004,0.000000e+000,3,9.927964e-001,0.000000e+000,,,,,,,,,,,,,,32,1,4.000000e+000,8.811951e-004,0.000000e+000,0,,0,
1524209937.256,,0.000000e+000,3.699829e+001,-1.927618e-004,0.000000e+000,3,9.929199e-001,0.000000e+000,,,,,,,,,,,,,,32,1,4.000000e+000,1.747131e-003,0.000000e+000,0,,0,
1524209949.726,,0.000000e+000,3.699829e+001,-1.931446e-004,0.000000e+000,3,9.929979e-001,0.000000e+000,,,,,,,,,,,,,,32,1,4.000000e+000,1.747131e-003,0.000000e+000,0,,0,
1524209962.016,,0.000000e+000,3.699961e+001,-1.934459e-004,0.000000e+000,3,9.929681e-001,0.000000e+000,,,,,,,,,,,,,,32,1,4.000000e+000,4.386902e-003,0.000000e+000,0,,0,
1524209974.324,,0.000000e+000,3.699741e+001,-1.937469e-004,0.000000e+000,3,9.929013e-001,0.000000e+000,,,,,,,,,,,,,,32,1,4.000000e+000,3.509521e-003,0.000000e+000,0,,0,
1524209987.217,,0.000000e+000,3.699873e+001,-1.940801e-004,0.000000e+000,3,9.930985e-001,0.000000e+000,,,,,,,,,,,,,,32,1,4.000000e+000,8.773804e-004,0.000000e+000,0,,0,
1524209999.897,,0.000000e+000,3.699873e+001,-1.943607e-004,0.000000e+000,3,9.929779e-001,0.000000e+000,,,,,,,,,,,,,,32,1,4.000000e+000,4.390717e-003,0.000000e+000,0,,0,
1524210012.325,,0.000000e+000,3.699829e+001,-1.946601e-004,0.000000e+000,3,9.928554e-001,0.000000e+000,,,,,,,,,,,,,,32,1,4.000000e+000,1.747131e-003,0.000000e+000,0,,0,
1524210024.757,,0.000000e+000,3.699917e+001,-1.949150e-004,0.000000e+000,3,9.927858e-001,0.000000e+000,,,,,,,,,,,,,,32,1,4.000000e+000,1.758575e-003,0.000000e+000,0,,0,
1524210037.285,,0.000000e+000,3.700005e+001,-1.951526e-004,0.000000e+000,3,9.929515e-001,0.000000e+000,,,,,,,,,,,,,,32,1,4.000000e+000,3.517151e-003,0.000000e+000,0,,0,
1524210049.735,,0.000000e+000,3.699873e+001,-1.954067e-004,0.000000e+000,3,9.929011e-001,0.000000e+000,,,,,,,,,,,,,,32,1,4.000000e+000,2.628326e-003,0.000000e+000,0,,0,
1524210062.120,,0.000000e+000,3.699873e+001,-1.956067e-004,0.000000e+000,3,9.928455e-001,0.000000e+000,,,,,,,,,,,,,,32,1,4.000000e+000,2.628326e-003,0.000000e+000,0,,0,
1524210074.623,,0.000000e+000,3.699741e+001,-1.958403e-004,0.000000e+000,3,9.928023e-001,0.000000e+000,,,,,,,,,,,,,,32,1,4.000000e+000,1.750946e-003,0.000000e+000,0,,0,
1524210087.168,,0.000000e+000,3.699917e+001,-1.960175e-004,0.000000e+000,3,9.927554e-001,0.000000e+000,,,,,,,,,,,,,,32,1,4.000000e+000,1.758575e-003,0.000000e+000,0,,0,
1524210100.273,,0.000000e+000,3.699786e+001,-1.962365e-004,0.000000e+000,3,9.928678e-001,0.000000e+000,,,,,,,,,,,,,,32,1,4.000000e+000,8.697510e-004,0.000000e+000,0,,0,
1524210113.199,,0.000000e+000,3.699873e+001,-1.963929e-004,0.000000e+000,3,9.926227e-001,0.000000e+000,,,,,,,,,,,,,,32,1,4.000000e+000,2.628326e-003,0.000000e+000,0,,0,
1524210126.016,,0.000000e+000,3.699786e+001,-1.966048e-004,0.000000e+000,3,9.926965e-001,0.000000e+000,,,,,,,,,,,,,,32,1,4.000000e+000,4.390717e-003,0.000000e+000,0,,0,
1524210139.089,,0.000000e+000,3.699786e+001,-1.968410e-004,0.000000e+000,3,9.928858e-001,0.000000e+000,,,,,,,,,,,,,,32,1,4.000000e+000,8.697510e-004,0.000000e+000,0,,0,
1524210151.564,,0.000000e+000,3.700005e+001,-1.970303e-004,0.000000e+000,3,9.929100e-001,0.000000e+000,,,,,,,,,,,,,,32,1,4.000000e+000,3.517151e-003,0.000000e+000,0,,0,
1524210163.414,,0.000000e+000,3.700137e+001,-1.971586e-004,0.000000e+000,3,9.929438e-001,0.000000e+000,,,,,,,,,,,,,,32,1,4.000000e+000,8.773804e-004,0.000000e+000,0,,0,
1524210176.487,,0.000000e+000,3.700137e+001,-1.973210e-004,0.000000e+000,3,9.929036e-001,0.000000e+000,,,,,,,,,,,,,,32,1,4.000000e+000,2.639771e-003,0.000000e+000,0,,0,
1524210188.567,,0.000000e+000,3.700093e+001,-1.974828e-004,0.000000e+000,3,9.927993e-001,0.000000e+000,,,,,,,,,,,,,,32,1,4.000000e+000,3.520966e-003,0.000000e+000,0,,0,
1524210200.872,,0.000000e+000,3.699567e+001,-1.976573e-004,0.000000e+000,3,9.927702e-001,0.000000e+000,,,,,,,,,,,,,,32,1,4.000000e+000,3.509521e-003,0.000000e+000,0,,0,
1524210213.298,,0.000000e+000,3.699873e+001,-1.977899e-004,0.000000e+000,3,9.927944e-001,0.000000e+000,,,,,,,,,,,,,,32,1,4.000000e+000,8.773804e-004,0.000000e+000,0,,0,
1524210226.325,,0.000000e+000,3.699697e+001,-1.979632e-004,0.000000e+000,3,9.928237e-001,0.000000e+000,,,,,,,,,,,,,,32,1,4.000000e+000,2.632141e-003,0.000000e+000,0,,0,
1524210238.778,,0.000000e+000,3.699917e+001,-1.981396e-004,0.000000e+000,3,9.928682e-001,0.000000e+000,,,,,,,,,,,,,,32,1,4.000000e+000,1.758575e-003,0.000000e+000,0,,0,
1524210251.258,,0.000000e+000,3.700093e+001,-1.983121e-004,0.000000e+000,3,9.929287e-001,0.000000e+000,,,,,,,,,,,,,,32,1,4.000000e+000,1.758575e-003,0.000000e+000,0,,0,
1524210263.118,,0.000000e+000,3.699961e+001,-1.983850e-004,0.000000e+000,3,9.928916e-001,0.000000e+000,,,,,,,,,,,,,,32,1,4.000000e+000,4.386902e-003,0.000000e+000,0,,0,
1524210275.564,,0.000000e+000,3.699918e+001,-1.985311e-004,0.000000e+000,3,9.928588e-001,0.000000e+000,,,,,,,,,,,,,,32,1,4.000000e+000,5.268097e-003,0.000000e+000,0,,0,
1524210288.601,,0.000000e+000,3.699610e+001,-1.986859e-004,0.000000e+000,3,9.927738e-001,0.000000e+000,,,,,,,,,,,,,,32,1,4.000000e+000,2.639771e-003,0.000000e+000,0,,0,
1524210301.091,,0.000000e+000,3.699698e+001,-1.988049e-004,0.000000e+000,3,9.928738e-001,0.000000e+000,,,,,,,,,,,,,,32,1,4.000000e+000,8.811951e-004,0.000000e+000,0,,0,
1524210313.529,,0.000000e+000,3.699741e+001,-1.989407e-004,0.000000e+000,3,9.929042e-001,0.000000e+000,,,,,,,,,,,,,,32,1,4.000000e+000,1.750946e-003,0.000000e+000,0,,0,
1524210325.409,,0.000000e+000,3.699829e+001,-1.990538e-004,0.000000e+000,3,9.928555e-001,0.000000e+000,,,,,,,,,,,,,,32,1,4.000000e+000,0.000000e+000,0.000000e+000,0,,0,
1524210337.894,,0.000000e+000,3.699829e+001,-1.991606e-004,0.000000e+000,3,9.928887e-001,0.000000e+000,,,,,,,,,,,,,,32,1,4.000000e+000,0.000000e+000,0.000000e+000,0,,0,
1524210350.357,,0.000000e+000,3.699697e+001,-1.992729e-004,0.000000e+000,3,9.928806e-001,0.000000e+000,,,,,,,,,,,,,,32,1,4.000000e+000,2.632141e-003,0.000000e+000,0,,0,
1524210362.822,,0.000000e+000,3.699654e+001,-1.993571e-004,0.000000e+000,3,9.928123e-001,0.000000e+000,,,,,,,,,,,,,,32,1,4.000000e+000,1.762390e-003,0.000000e+000,0,,0,
1524210375.290,,0.000000e+000,3.699786e+001,-1.995050e-004,0.000000e+000,3,9.929636e-001,0.000000e+000,,,,,,,,,,,,,,32,1,4.000000e+000,2.628326e-003,0.000000e+000,0,,0,
1524210387.770,,0.000000e+000,3.699829e+001,-1.996158e-004,0.000000e+000,3,9.928329e-001,0.000000e+000,,,,,,,,,,,,,,32,1,4.000000e+000,3.509521e-003,0.000000e+000,0,,0,
1524210400.185,,0.000000e+000,3.699741e+001,-1.997267e-004,0.000000e+000,3,9.927626e-001,0.000000e+000,,,,,,,,,,,,,,32,1,4.000000e+000,1.750946e-003,0.000000e+000,0,,0,
1524210413.206,,0.000000e+000,3.699961e+001,-1.998521e-004,0.000000e+000,3,9.929387e-001,0.000000e+000,,,,,,,,,,,,,,32,1,4.000000e+000,8.811951e-004,0.000000e+000,0,,0,
1524210425.103,,0.000000e+000,3.699786e+001,-1.999617e-004,0.000000e+000,3,9.928432e-001,0.000000e+000,,,,,,,,,,,,,,32,1,4.000000e+000,2.628326e-003,0.000000e+000,0,,0,
1524210437.206,,0.000000e+000,3.699917e+001,-2.000743e-004,0.000000e+000,3,9.930267e-001,0.000000e+000,,,,,,,,,,,,,,32,1,4.000000e+000,0.000000e+000,0.000000e+000,0,,0,
1524210450.604,,0.000000e+000,3.699829e+001,-2.001375e-004,0.000000e+000,3,9.928536e-001,0.000000e+000,,,,,,,,,,,,,,32,1,4.000000e+000,1.747131e-003,0.000000e+000,0,,0,
1524210463.041,,0.000000e+000,3.699873e+001,-2.002411e-004,0.000000e+000,3,9.929130e-001,0.000000e+000,,,,,,,,,,,,,,32,1,4.000000e+000,2.628326e-003,0.000000e+000,0,,0,
1524210475.521,,0.000000e+000,3.699610e+001,-2.003542e-004,0.000000e+000,3,9.928205e-001,0.000000e+000,,,,,,,,,,,,,,32,1,4.000000e+000,6.137848e-003,0.000000e+000,0,,0,
1524210487.982,,0.000000e+000,3.699435e+001,-2.004592e-004,0.000000e+000,3,9.928195e-001,0.000000e+000,,,,,,,,,,,,,,32,1,4.000000e+000,2.628326e-003,0.000000e+000,0,,0,
1524210499.859,,0.000000e+000,3.699873e+001,-2.006138e-004,0.000000e+000,3,9.927948e-001,0.000000e+000,,,,,,,,,,,,,,32,1,4.000000e+000,2.628326e-003,0.000000e+000,0,,0,
1524210512.355,,0.000000e+000,3.699698e+001,-2.006474e-004,0.000000e+000,3,9.929760e-001,0.000000e+000,,,,,,,,,,,,,,32,1,4.000000e+000,8.811951e-004,0.000000e+000,0,,0,
1524210525.372,,0.000000e+000,3.699829e+001,-2.007689e-004,0.000000e+000,3,9.928899e-001,0.000000e+000,,,,,,,,,,,,,,32,1,4.000000e+000,1.747131e-003,0.000000e+000,0,,0,
1524210537.487,,0.000000e+000,3.700049e+001,-2.008266e-004,0.000000e+000,3,9.929270e-001,0.000000e+000,,,,,,,,,,,,,,32,1,4.000000e+000,2.639771e-003,0.000000e+000,0,,0,
1524210549.705,,0.000000e+000,3.700005e+001,-2.009163e-004,0.000000e+000,3,9.928833e-001,0.000000e+000,,,,,,,,,,,,,,32,1,4.000000e+000,3.517151e-003,0.000000e+000,0,,0,
1524210562.748,,0.000000e+000,3.699786e+001,-2.010075e-004,0.000000e+000,3,9.929954e-001,0.000000e+000,,,,,,,,,,,,,,32,1,4.000000e+000,8.697510e-004,0.000000e+000,0,,0,
1524210575.215,,0.000000e+000,3.699742e+001,-2.011227e-004,0.000000e+000,3,9.928988e-001,0.000000e+000,,,,,,,,,,,,,,32,1,4.000000e+000,0.000000e+000,0.000000e+000,0,,0,
1524210587.638,,0.000000e+000,3.699829e+001,-2.011950e-004,0.000000e+000,3,9.928660e-001,0.000000e+000,,,,,,,,,,,,,,32,1,4.000000e+000,1.747131e-003,0.000000e+000,0,,0,
1524210599.541,,0.000000e+000,3.699829e+001,-2.013000e-004,0.000000e+000,3,9.929467e-001,0.000000e+000,,,,,,,,,,,,,,32,1,4.000000e+000,1.747131e-003,0.000000e+000,0,,0,
1524210611.999,,0.000000e+000,3.699829e+001,-2.013684e-004,0.000000e+000,3,9.928939e-001,0.000000e+000,,,,,,,,,,,,,,32,1,4.000000e+000,0.000000e+000,0.000000e+000,0,,0,
1524210624.476,,0.000000e+000,3.699741e+001,-2.014538e-004,0.000000e+000,3,9.928899e-001,0.000000e+000,,,,,,,,,,,,,,32,1,4.000000e+000,1.750946e-003,0.000000e+000,0,,0,
1524210636.944,,0.000000e+000,3.699654e+001,-2.015453e-004,0.000000e+000,3,9.929525e-001,0.000000e+000,,,,,,,,,,,,,,32,1,4.000000e+000,0.000000e+000,0.000000e+000,0,,0,
1524210649.619,,0.000000e+000,3.699829e+001,-2.015991e-004,0.000000e+000,3,9.929130e-001,0.000000e+000,,,,,,,,,,,,,,32,1,4.000000e+000,1.747131e-003,0.000000e+000,0,,0,
1524210661.844,,0.000000e+000,3.699873e+001,-2.016882e-004,0.000000e+000,3,9.929050e-001,0.000000e+000,,,,,,,,,,,,,,32,1,4.000000e+000,8.773804e-004,0.000000e+000,0,,0,
1524210674.884,,0.000000e+000,3.699786e+001,-2.017563e-004,0.000000e+000,3,9.928973e-001,0.000000e+000,,,,,,,,,,,,,,32,1,4.000000e+000,2.628326e-003,0.000000e+000,0,,0,
1524210687.330,,0.000000e+000,3.699873e+001,-2.018635e-004,0.000000e+000,3,9.928973e-001,0.000000e+000,,,,,,,,,,,,,,32,1,4.000000e+000,8.773804e-004,0.000000e+000,0,,0,
1524210699.825,,0.000000e+000,3.699741e+001,-2.019439e-004,0.000000e+000,3,9.928343e-001,0.000000e+000,,,,,,,,,,,,,,32,1,4.000000e+000,5.268097e-003,0.000000e+000,0,,0,
1524210712.242,,0.000000e+000,3.699786e+001,-2.020230e-004,0.000000e+000,3,9.928504e-001,0.000000e+000,,,,,,,,,,,,,,32,1,4.000000e+000,6.149292e-003,0.000000e+000,0,,0,
1524210724.738,,0.000000e+000,3.699873e+001,-2.020872e-004,0.000000e+000,3,9.929708e-001,0.000000e+000,,,,,,,,,,,,,,32,1,4.000000e+000,4.390717e-003,0.000000e+000,0,,0,
1524210737.395,,0.000000e+000,3.699829e+001,-2.020996e-004,0.000000e+000,3,9.928758e-001,0.000000e+000,,,,,,,,,,,,,,32,1,4.000000e+000,1.747131e-003,0.000000e+000,0,,0,
1524210749.946,,0.000000e+000,3.700049e+001,-2.022015e-004,0.000000e+000,3,9.929669e-001,0.000000e+000,,,,,,,,,,,,,,32,1,4.000000e+000,2.639771e-003,0.000000e+000,0,,0,
1524210762.723,,0.000000e+000,3.699610e+001,-2.022326e-004,0.000000e+000,3,9.930932e-001,0.000000e+000,,,,,,,,,,,,,,32,1,4.000000e+000,8.811951e-004,0.000000e+000,0,,0,
1524210775.468,,0.000000e+000,3.699829e+001,-2.023437e-004,0.000000e+000,3,9.929359e-001,0.000000e+000,,,,,,,,,,,,,,32,1,4.000000e+000,1.747131e-003,0.000000e+000,0,,0,
1524210788.046,,0.000000e+000,3.699697e+001,-2.024136e-004,0.000000e+000,3,9.928907e-001,0.000000e+000,,,,,,,,,,,,,,32,1,4.000000e+000,4.386902e-003,0.000000e+000,0,,0,
1524210800.509,,0.000000e+000,3.699697e+001,-2.024869e-004,0.000000e+000,3,9.929644e-001,0.000000e+000,,,,,,,,,,,,,,32,1,4.000000e+000,4.386902e-003,0.000000e+000,0,,0,
1524210812.864,,0.000000e+000,3.699654e+001,-2.025762e-004,0.000000e+000,3,9.929314e-001,0.000000e+000,,,,,,,,,,,,,,32,1,4.000000e+000,0.000000e+000,0.000000e+000,0,,0,
1524210825.412,,0.000000e+000,3.699698e+001,-2.026284e-004,0.000000e+000,3,9.930053e-001,0.000000e+000,,,,,,,,,,,,,,32,1,4.000000e+000,8.811951e-004,0.000000e+000,0,,0,
1524210837.812,,0.000000e+000,3.699698e+001,-2.027009e-004,0.000000e+000,3,9.929773e-001,0.000000e+000,,,,,,,,,,,,,,32,1,4.000000e+000,8.811951e-004,0.000000e+000,0,,0,
1524210850.247,,0.000000e+000,3.699654e+001,-2.027543e-004,0.000000e+000,3,9.930251e-001,0.000000e+000,,,,,,,,,,,,,,32,1,4.000000e+000,0.000000e+000,0.000000e+000,0,,0,
1524210862.677,,0.000000e+000,3.699435e+001,-2.028123e-004,0.000000e+000,3,9.930165e-001,0.000000e+000,,,,,,,,,,,,,,32,1,4.000000e+000,8.697510e-004,0.000000e+000,0,,0,
1524210875.187,,0.000000e+000,3.699522e+001,-2.028950e-004,0.000000e+000,3,9.929351e-001,0.000000e+000,,,,,,,,,,,,,,32,1,4.000000e+000,8.773804e-004,0.000000e+000,0,,0,
1524210887.753,,0.000000e+000,3.699697e+001,-2.029506e-004,0.000000e+000,3,9.928566e-001,0.000000e+000,,,,,,,,,,,,,,32,1,4.000000e+000,2.632141e-003,0.000000e+000,0,,0,
1524210900.105,,0.000000e+000,3.699786e+001,-2.030042e-004,0.000000e+000,3,9.929491e-001,0.000000e+000,,,,,,,,,,,,,,32,1,4.000000e+000,8.697510e-004,0.000000e+000,0,,0,
1524210912.543,,0.000000e+000,3.699829e+001,-2.030943e-004,0.000000e+000,3,9.930532e-001,0.000000e+000,,,,,,,,,,,,,,32,1,4.000000e+000,1.747131e-003,0.000000e+000,0,,0,
1524210924.971,,0.000000e+000,3.699347e+001,-2.031668e-004,0.000000e+000,3,9.929792e-001,0.000000e+000,,,,,,,,,,,,,,32,1,4.000000e+000,8.811951e-004,0.000000e+000,0,,0,
1524210937.618,,0.000000e+000,3.699654e+001,-2.031701e-004,0.000000e+000,3,9.929676e-001,0.000000e+000,,,,,,,,,,,,,,32,1,4.000000e+000,5.256653e-003,0.000000e+000,0,,0,
1524210949.988,,0.000000e+000,3.699917e+001,-2.032496e-004,0.000000e+000,3,9.929507e-001,0.000000e+000,,,,,,,,,,,,,,32,1,4.000000e+000,0.000000e+000,0.000000e+000,0,,0,
1524210962.536,,0.000000e+000,3.699741e+001,-2.032980e-004,0.000000e+000,3,9.929900e-001,0.000000e+000,,,,,,,,,,,,,,32,1,4.000000e+000,3.509521e-003,0.000000e+000,0,,0,
1524210974.881,,0.000000e+000,3.699654e+001,-2.034109e-004,0.000000e+000,3,9.929162e-001,0.000000e+000,,,,,,,,,,,,,,32,1,4.000000e+000,1.762390e-003,0.000000e+000,0,,0,
1524210987.299,,0.000000e+000,3.700005e+001,-2.034254e-004,0.000000e+000,3,9.929756e-001,0.000000e+000,,,,,,,,,,,,,,32,1,4.000000e+000,3.517151e-003,0.000000e+000,0,,0,
1524210999.929,,0.000000e+000,3.700093e+001,-2.035159e-004,0.000000e+000,3,9.928812e-001,0.000000e+000,,,,,,,,,,,,,,32,1,4.000000e+000,1.758575e-003,0.000000e+000,0,,0,
1524211012.327,,0.000000e+000,3.699786e+001,-2.035863e-004,0.000000e+000,3,9.929517e-001,0.000000e+000,,,,,,,,,,,,,,32,1,4.000000e+000,8.697510e-004,0.000000e+000,0,,0,
1524211024.739,,0.000000e+000,3.699786e+001,-2.036235e-004,0.000000e+000,3,9.929664e-001,0.000000e+000,,,,,,,,,,,,,,32,1,4.000000e+000,8.697510e-004,0.000000e+000,0,,0,
1524211037.175,,0.000000e+000,3.699435e+001,-2.036726e-004,0.000000e+000,3,9.930612e-001,0.000000e+000,,,,,,,,,,,,,,32,1,4.000000e+000,8.697510e-004,0.000000e+000,0,,0,
1524211049.607,,0.000000e+000,3.699435e+001,-2.037377e-004,0.000000e+000,3,9.930718e-001,0.000000e+000,,,,,,,,,,,,,,32,1,4.000000e+000,8.697510e-004,0.000000e+000,0,,0,
1524211062.233,,0.000000e+000,3.699786e+001,-2.037785e-004,0.000000e+000,3,9.930780e-001,0.000000e+000,,,,,,,,,,,,,,32,1,4.000000e+000,6.149292e-003,0.000000e+000,0,,0,
1524211074.573,,0.000000e+000,3.699786e+001,-2.038426e-004,0.000000e+000,3,9.930034e-001,0.000000e+000,,,,,,,,,,,,,,32,1,4.000000e+000,2.628326e-003,0.000000e+000,0,,0,
1524211087.155,,0.000000e+000,3.699961e+001,-2.038814e-004,0.000000e+000,3,9.928555e-001,0.000000e+000,,,,,,,,,,,,,,32,1,4.000000e+000,8.811951e-004,0.000000e+000,0,,0,
1524211099.451,,0.000000e+000,3.699786e+001,-2.039467e-004,0.000000e+000,3,9.929163e-001,0.000000e+000,,,,,,,,,,,,,,32,1,4.000000e+000,8.697510e-004,0.000000e+000,0,,0,
1524211111.916,,0.000000e+000,3.699829e+001,-2.039867e-004,0.000000e+000,3,9.929892e-001,0.000000e+000,,,,,,,,,,,,,,32,1,4.000000e+000,0.000000e+000,0.000000e+000,0,,0,
1524211124.411,,0.000000e+000,3.699786e+001,-2.040499e-004,0.000000e+000,3,9.929847e-001,0.000000e+000,,,,,,,,,,,,,,32,1,4.000000e+000,4.390717e-003,0.000000e+000,0,,0,