File: Experimental Raw Data/TC04-12-01K TRMac VRMde/TC04-12-01K_TRMac_57K_0.04Kmin_VRMde_55K.dc.dat
[Header]
TITLE,MPMS DC Measurement
BYAPP,MPMS Measurement,2.1,Summary
FILEOPENTIME, 1524490308.219000 4/23/2018, 7:31:48 AM

INFO, APPNAME, MPMS MultiVu Application, Revision 1.61,  Build 082

INFO, NAME, TC04-12-01K
INFO, WEIGHT, 1.000
INFO, AREA, 1.000
INFO, LENGTH, 1.000
INFO, SHAPE, 0
INFO, COMMENT,
INFO, SEQUENCE FILE: TRMac_57K_0.04Kmin_VRMde_55K.seq


INFO, BACKGROUND DATA FILE:, None


STARTUPAXIS,X,4,LINEAR,AUTO,0.000000,0.000000
STARTUPAXIS,Y1,5,LINEAR,AUTO,0.000000,0.000000


STARTUPGROUP,Longitudinal
FIELDGROUP,Longitudinal,1,2,3,4,5,6,7,8,9,15,16,17,18,27,28
FIELDGROUP,Transverse,1,2,3,4,10,11,12,13,14,19,20,21,22,27,28

PLOT_APPEARANCE,ALL,HORZ_GRID_ON,VERT_GRID_ON,MARKERS_AND_LINES

[Data]
Time,Comment,Field (Oe),Temperature (K),Long Moment (emu),Long Scan Std Dev,Long Algorithm,Long Reg Fit,Long Percent Error (%),Trans Moment (emu),Trans Scan Std Dev,Trans Algorithm,Trans Reg Fit,Trans Percent Error (%),Long Moment [w/o ABS] (emu),Long Scan Std Dev [w/o ABS],Long Reg Fit [w/o ABS],Long Percent Error [w/o ABS] (%),Trans Moment [w/o ABS] (emu),Trans Scan Std Dev [w/o ABS],Trans Reg Fit [w/o ABS],Trans Percent Error [w/o ABS] (%),Points per Scan,Scans per Measurement,Scan Length (cm),Delta Temp (K),Rot Position (deg),Error,EC Comp. Running,Using ABS,
1524490308.219,,0.000000e+000,5.498196e+001,-9.579332e-006,0.000000e+000,3,9.606841e-001,0.000000e+000,,,,,,,,,,,,,,32,1,4.000000e+000,1.445770e-002,0.000000e+000,0,,0,
1524490347.299,,0.000000e+000,5.499511e+001,-7.162740e-006,0.000000e+000,3,9.429263e-001,0.000000e+000,,,,,,,,,,,,,,32,1,4.000000e+000,1.319885e-003,0.000000e+000,0,,0,
1524490384.989,,0.000000e+000,5.499051e+001,-5.856699e-006,0.000000e+000,3,9.415005e-001,0.000000e+000,,,,,,,,,,,,,,32,1,4.000000e+000,2.632141e-003,0.000000e+000,0,,0,
1524490422.280,,0.000000e+000,5.499709e+001,-5.096894e-006,0.000000e+000,3,9.308060e-001,0.000000e+000,,,,,,,,,,,,,,32,1,4.000000e+000,1.052856e-002,0.000000e+000,0,,0,
1524490460.760,,0.000000e+000,5.499248e+001,-4.351185e-006,0.000000e+000,3,9.158814e-001,0.000000e+000,,,,,,,,,,,,,,32,1,4.000000e+000,3.940582e-003,0.000000e+000,0,,0,
1524490498.650,,0.000000e+000,5.500037e+001,-3.790104e-006,0.000000e+000,3,9.247797e-001,0.000000e+000,,,,,,,,,,,,,,32,1,4.000000e+000,1.319885e-003,0.000000e+000,0,,0,
1524490537.270,,0.000000e+000,5.500037e+001,-3.385064e-006,0.000000e+000,3,8.913077e-001,0.000000e+000,,,,,,,,,,,,,,32,1,4.000000e+000,3.959656e-003,0.000000e+000,0,,0,
1524490575.020,,0.000000e+000,5.499511e+001,-3.160794e-006,0.000000e+000,3,8.565695e-001,0.000000e+000,,,,,,,,,,,,,,32,1,4.000000e+000,3.940582e-003,0.000000e+000,0,,0,
1524490638.570,,0.000000e+000,5.499577e+001,-2.670147e-006,0.000000e+000,3,8.529032e-001,0.000000e+000,,,,,,,,,,,,,,32,1,4.000000e+000,5.249023e-003,0.000000e+000,0,,0,
1524490676.270,,0.000000e+000,5.499775e+001,-2.499682e-006,0.000000e+000,3,8.133165e-001,0.000000e+000,,,,,,,,,,,,,,32,1,4.000000e+000,9.208679e-003,0.000000e+000,0,,0,
1524490713.930,,0.000000e+000,5.500169e+001,-2.380698e-006,0.000000e+000,3,7.703100e-001,0.000000e+000,,,,,,,,,,,,,,32,1,4.000000e+000,3.959656e-003,0.000000e+000,0,,0,
1524490751.300,,0.000000e+000,5.499971e+001,-2.252598e-006,0.000000e+000,3,7.636359e-001,0.000000e+000,,,,,,,,,,,,,,32,1,4.000000e+000,0.000000e+000,0.000000e+000,0,,0,
1524490791.040,,0.000000e+000,5.499906e+001,-6.746342e-007,0.000000e+000,2,0.000000e+000,0.000000e+000,,,,,,,,,,,,,,32,1,4.000000e+000,9.220123e-003,0.000000e+000,0,,0,
1524490833.516,,0.000000e+000,5.500169e+001,-4.287517e-007,0.000000e+000,2,0.000000e+000,0.000000e+000,,,,,,,,,,,,,,32,1,4.000000e+000,1.319885e-003,0.000000e+000,0,,0,
1524490874.450,,0.000000e+000,5.500169e+001,-2.969298e-007,0.000000e+000,2,0.000000e+000,0.000000e+000,,,,,,,,,,,,,,32,1,4.000000e+000,1.319885e-003,0.000000e+000,0,,0,
1524490911.650,,0.000000e+000,5.499577e+001,2.214893e-006,0.000000e+000,3,6.721417e-001,0.000000e+000,,,,,,,,,,,,,,32,1,4.000000e+000,1.052094e-002,0.000000e+000,0,,0,
1524490949.490,,0.000000e+000,5.500300e+001,-2.433108e-006,0.000000e+000,3,6.980139e-001,0.000000e+000,,,,,,,,,,,,,,32,1,4.000000e+000,3.940582e-003,0.000000e+000,0,,0,
1524490987.510,,0.000000e+000,5.499905e+001,-2.219305e-006,0.000000e+000,3,7.028556e-001,0.000000e+000,,,,,,,,,,,,,,32,1,4.000000e+000,1.319885e-003,0.000000e+000,0,,0,
1524491028.524,,0.000000e+000,5.499445e+001,3.334379e-007,0.000000e+000,2,0.000000e+000,0.000000e+000,,,,,,,,,,,,,,32,1,4.000000e+000,0.000000e+000,0.000000e+000,0,,0,
1524491072.010,,0.000000e+000,5.499577e+001,5.236203e-007,0.000000e+000,2,0.000000e+000,0.000000e+000,,,,,,,,,,,,,,32,1,4.000000e+000,1.316071e-002,0.000000e+000,0,,0,
1524491112.834,,0.000000e+000,5.499773e+001,2.251811e-006,0.000000e+000,3,7.499971e-001,0.000000e+000,,,,,,,,,,,,,,32,1,4.000000e+000,1.308441e-003,0.000000e+000,0,,0,
1524491153.909,,0.000000e+000,5.499577e+001,6.804906e-007,0.000000e+000,2,0.000000e+000,0.000000e+000,,,,,,,,,,,,,,32,1,4.000000e+000,2.632141e-003,0.000000e+000,0,,0,
1524491190.749,,0.000000e+000,5.499380e+001,2.372851e-006,0.000000e+000,3,7.399742e-001,0.000000e+000,,,,,,,,,,,,,,32,1,4.000000e+000,6.572723e-003,0.000000e+000,0,,0,
1524491228.689,,0.000000e+000,5.499511e+001,2.191404e-006,0.000000e+000,3,7.276570e-001,0.000000e+000,,,,,,,,,,,,,,32,1,4.000000e+000,1.972198e-002,0.000000e+000,0,,0,
1524491280.079,,0.000000e+000,5.499248e+001,2.451716e-006,0.000000e+000,3,7.650932e-001,0.000000e+000,,,,,,,,,,,,,,32,1,4.000000e+000,3.940582e-003,0.000000e+000,0,,0,
1524491317.929,,0.000000e+000,5.499971e+001,2.434107e-006,0.000000e+000,3,7.710711e-001,0.000000e+000,,,,,,,,,,,,,,32,1,4.000000e+000,2.639771e-003,0.000000e+000,0,,0,
1524491356.199,,0.000000e+000,5.499708e+001,2.317932e-006,0.000000e+000,3,8.054056e-001,0.000000e+000,,,,,,,,,,,,,,32,1,4.000000e+000,0.000000e+000,0.000000e+000,0,,0,
1524491393.519,,0.000000e+000,5.499577e+001,2.416474e-006,0.000000e+000,3,7.700868e-001,0.000000e+000,,,,,,,,,,,,,,32,1,4.000000e+000,2.632141e-003,0.000000e+000,0,,0,
1524491431.819,,0.000000e+000,5.500103e+001,2.382872e-006,0.000000e+000,3,8.088959e-001,0.000000e+000,,,,,,,,,,,,,,32,1,4.000000e+000,5.279541e-003,0.000000e+000,0,,0,
1524491469.109,,0.000000e+000,5.499971e+001,2.421016e-006,0.000000e+000,3,7.678128e-001,0.000000e+000,,,,,,,,,,,,,,32,1,4.000000e+000,2.639771e-003,0.000000e+000,0,,0,
1524491507.409,,0.000000e+000,5.499905e+001,2.515233e-006,0.000000e+000,3,8.234664e-001,0.000000e+000,,,,,,,,,,,,,,32,1,4.000000e+000,1.319885e-003,0.000000e+000,0,,0,
1524491544.699,,0.000000e+000,5.499313e+001,2.476445e-006,0.000000e+000,3,8.066716e-001,0.000000e+000,,,,,,,,,,,,,,32,1,4.000000e+000,1.050949e-002,0.000000e+000,0,,0,
1524491582.509,,0.000000e+000,5.499971e+001,2.598813e-006,0.000000e+000,3,8.195252e-001,0.000000e+000,,,,,,,,,,,,,,32,1,4.000000e+000,2.639771e-003,0.000000e+000,0,,0,
1524491620.529,,0.000000e+000,5.500103e+001,2.806245e-006,0.000000e+000,3,8.021002e-001,0.000000e+000,,,,,,,,,,,,,,32,1,4.000000e+000,0.000000e+000,0.000000e+000,0,,0,
1524491683.249,,0.000000e+000,5.499840e+001,2.699682e-006,0.000000e+000,3,8.268373e-001,0.000000e+000,,,,,,,,,,,,,,32,1,4.000000e+000,5.260468e-003,0.000000e+000,0,,0,
1524491720.539,,0.000000e+000,5.499905e+001,2.778600e-006,0.000000e+000,3,8.285927e-001,0.000000e+000,,,,,,,,,,,,,,32,1,4.000000e+000,1.182938e-002,0.000000e+000,0,,0,
1524491758.559,,0.000000e+000,5.500169e+001,2.788669e-006,0.000000e+000,3,8.279474e-001,0.000000e+000,,,,,,,,,,,,,,32,1,4.000000e+000,1.319885e-003,0.000000e+000,0,,0,
1524491796.139,,0.000000e+000,5.499773e+001,2.830355e-006,0.000000e+000,3,8.254117e-001,0.000000e+000,,,,,,,,,,,,,,32,1,4.000000e+000,1.308441e-003,0.000000e+000,0,,0,
1524491833.980,,0.000000e+000,5.499971e+001,2.785641e-006,0.000000e+000,3,8.468412e-001,0.000000e+000,,,,,,,,,,,,,,32,1,4.000000e+000,2.639771e-003,0.000000e+000,0,,0,
1524491871.910,,0.000000e+000,5.499906e+001,2.752387e-006,0.000000e+000,3,8.321771e-001,0.000000e+000,,,,,,,,,,,,,,32,1,4.000000e+000,9.220123e-003,0.000000e+000,0,,0,
1524491909.580,,0.000000e+000,5.499774e+001,2.813342e-006,0.000000e+000,3,8.670856e-001,0.000000e+000,,,,,,,,,,,,,,32,1,4.000000e+000,3.940582e-003,0.000000e+000,0,,0,
1524491946.550,,0.000000e+000,5.500037e+001,2.881937e-006,0.000000e+000,3,8.697678e-001,0.000000e+000,,,,,,,,,,,,,,32,1,4.000000e+000,9.201050e-003,0.000000e+000,0,,0,
1524491984.960,,0.000000e+000,5.499708e+001,2.870107e-006,0.000000e+000,3,8.732560e-001,0.000000e+000,,,,,,,,,,,,,,32,1,4.000000e+000,0.000000e+000,0.000000e+000,0,,0,
1524492022.770,,0.000000e+000,5.500301e+001,3.002740e-006,0.000000e+000,3,8.754671e-001,0.000000e+000,,,,,,,,,,,,,,32,1,4.000000e+000,1.319885e-003,0.000000e+000,0,,0,
1524492060.030,,0.000000e+000,5.499972e+001,3.007354e-006,0.000000e+000,3,8.815321e-001,0.000000e+000,,,,,,,,,,,,,,32,1,4.000000e+000,7.900238e-003,0.000000e+000,0,,0,
1524492097.920,,0.000000e+000,5.500037e+001,3.097618e-006,0.000000e+000,3,8.684595e-001,0.000000e+000,,,,,,,,,,,,,,32,1,4.000000e+000,6.587982e-003,0.000000e+000,0,,0,
1524492136.440,,0.000000e+000,5.499051e+001,3.031669e-006,0.000000e+000,3,8.511522e-001,0.000000e+000,,,,,,,,,,,,,,32,1,4.000000e+000,2.632141e-003,0.000000e+000,0,,0,
1524492174.320,,0.000000e+000,5.500103e+001,3.010412e-006,0.000000e+000,3,8.692496e-001,0.000000e+000,,,,,,,,,,,,,,32,1,4.000000e+000,0.000000e+000,0.000000e+000,0,,0,
1524492225.470,,0.000000e+000,5.499774e+001,3.155797e-006,0.000000e+000,3,8.514518e-001,0.000000e+000,,,,,,,,,,,,,,32,1,4.000000e+000,3.940582e-003,0.000000e+000,0,,0,
1524492263.140,,0.000000e+000,5.500498e+001,3.164437e-006,0.000000e+000,3,8.313525e-001,0.000000e+000,,,,,,,,,,,,,,32,1,4.000000e+000,5.260468e-003,0.000000e+000,0,,0,
1524492300.970,,0.000000e+000,5.499905e+001,3.131805e-006,0.000000e+000,3,8.494539e-001,0.000000e+000,,,,,,,,,,,,,,32,1,4.000000e+000,1.319885e-003,0.000000e+000,0,,0,
1524492338.140,,0.000000e+000,5.499840e+001,3.290734e-006,0.000000e+000,3,8.318522e-001,0.000000e+000,,,,,,,,,,,,,,32,1,4.000000e+000,1.842117e-002,0.000000e+000,0,,0,
1524492376.130,,0.000000e+000,5.499708e+001,3.267182e-006,0.000000e+000,3,8.548253e-001,0.000000e+000,,,,,,,,,,,,,,32,1,4.000000e+000,0.000000e+000,0.000000e+000,0,,0,
1524492414.060,,0.000000e+000,5.499972e+001,3.315823e-006,0.000000e+000,3,8.485943e-001,0.000000e+000,,,,,,,,,,,,,,32,1,4.000000e+000,1.314926e-002,0.000000e+000,0,,0,
1524492452.140,,0.000000e+000,5.499445e+001,3.365106e-006,0.000000e+000,3,8.282762e-001,0.000000e+000,,,,,,,,,,,,,,32,1,4.000000e+000,5.260468e-003,0.000000e+000,0,,0,
1524492490.810,,0.000000e+000,5.500432e+001,3.462903e-006,0.000000e+000,3,8.563964e-001,0.000000e+000,,,,,,,,,,,,,,32,1,4.000000e+000,3.940582e-003,0.000000e+000,0,,0,
1524492527.950,,0.000000e+000,5.499971e+001,3.342238e-006,0.000000e+000,3,8.580196e-001,0.000000e+000,,,,,,,,,,,,,,32,1,4.000000e+000,1.052094e-002,0.000000e+000,0,,0,
1524492565.091,,0.000000e+000,5.499971e+001,3.470879e-006,0.000000e+000,3,8.442562e-001,0.000000e+000,,,,,,,,,,,,,,32,1,4.000000e+000,0.000000e+000,0.000000e+000,0,,0,
1524492603.641,,0.000000e+000,5.500103e+001,3.405942e-006,0.000000e+000,3,8.678603e-001,0.000000e+000,,,,,,,,,,,,,,32,1,4.000000e+000,1.052094e-002,0.000000e+000,0,,0,
1524492641.141,,0.000000e+000,5.500037e+001,3.469198e-006,0.000000e+000,3,8.664700e-001,0.000000e+000,,,,,,,,,,,,,,32,1,4.000000e+000,1.319885e-003,0.000000e+000,0,,0,
1524492679.111,,0.000000e+000,5.499839e+001,3.459259e-006,0.000000e+000,3,8.650849e-001,0.000000e+000,,,,,,,,,,,,,,32,1,4.000000e+000,0.000000e+000,0.000000e+000,0,,0,
1524492716.591,,0.000000e+000,5.500103e+001,3.536424e-006,0.000000e+000,3,8.586141e-001,0.000000e+000,,,,,,,,,,,,,,32,1,4.000000e+000,7.888794e-003,0.000000e+000,0,,0,
1524492754.721,,0.000000e+000,5.500300e+001,3.558134e-006,0.000000e+000,3,8.750149e-001,0.000000e+000,,,,,,,,,,,,,,32,1,4.000000e+000,6.580353e-003,0.000000e+000,0,,0,
1524492792.691,,0.000000e+000,5.499839e+001,3.488228e-006,0.000000e+000,3,8.784462e-001,0.000000e+000,,,,,,,,,,,,,,32,1,4.000000e+000,0.000000e+000,0.000000e+000,0,,0,
1524492830.111,,0.000000e+000,5.499577e+001,3.634078e-006,0.000000e+000,3,8.609704e-001,0.000000e+000,,,,,,,,,,,,,,32,1,4.000000e+000,5.249023e-003,0.000000e+000,0,,0,
1524492868.091,,0.000000e+000,5.499643e+001,3.730536e-006,0.000000e+000,3,8.823325e-001,0.000000e+000,,,,,,,,,,,,,,32,1,4.000000e+000,6.568909e-003,0.000000e+000,0,,0,
1524492905.745,,0.000000e+000,5.499643e+001,3.662088e-006,0.000000e+000,3,8.618714e-001,0.000000e+000,,,,,,,,,,,,,,32,1,4.000000e+000,1.312256e-003,0.000000e+000,0,,0,
1524492943.731,,0.000000e+000,5.500103e+001,3.679624e-006,0.000000e+000,3,8.727995e-001,0.000000e+000,,,,,,,,,,,,,,32,1,4.000000e+000,2.639771e-003,0.000000e+000,0,,0,
1524492981.281,,0.000000e+000,5.499774e+001,3.671549e-006,0.000000e+000,3,8.649030e-001,0.000000e+000,,,,,,,,,,,,,,32,1,4.000000e+000,3.940582e-003,0.000000e+000,0,,0,
1524493019.313,,0.000000e+000,5.500037e+001,3.701682e-006,0.000000e+000,3,8.770126e-001,0.000000e+000,,,,,,,,,,,,,,32,1,4.000000e+000,3.959656e-003,0.000000e+000,0,,0,
1524493056.893,,0.000000e+000,5.499708e+001,3.753687e-006,0.000000e+000,3,8.632407e-001,0.000000e+000,,,,,,,,,,,,,,32,1,4.000000e+000,2.620697e-003,0.000000e+000,0,,0,
1524493094.923,,0.000000e+000,5.499313e+001,3.743662e-006,0.000000e+000,3,8.784811e-001,0.000000e+000,,,,,,,,,,,,,,32,1,4.000000e+000,2.628326e-003,0.000000e+000,0,,0,
1524493145.833,,0.000000e+000,5.499709e+001,3.726110e-006,0.000000e+000,3,8.707131e-001,0.000000e+000,,,,,,,,,,,,,,32,1,4.000000e+000,7.888794e-003,0.000000e+000,0,,0,
1524493184.363,,0.000000e+000,5.499643e+001,3.691128e-006,0.000000e+000,3,8.778639e-001,0.000000e+000,,,,,,,,,,,,,,32,1,4.000000e+000,6.568909e-003,0.000000e+000,0,,0,
1524493221.903,,0.000000e+000,5.500037e+001,3.811693e-006,0.000000e+000,3,8.668210e-001,0.000000e+000,,,,,,,,,,,,,,32,1,4.000000e+000,3.959656e-003,0.000000e+000,0,,0,
1524493260.154,,0.000000e+000,5.499971e+001,3.714823e-006,0.000000e+000,3,8.720397e-001,0.000000e+000,,,,,,,,,,,,,,32,1,4.000000e+000,0.000000e+000,0.000000e+000,0,,0,
1524493297.994,,0.000000e+000,5.500037e+001,3.740121e-006,0.000000e+000,3,8.686776e-001,0.000000e+000,,,,,,,,,,,,,,32,1,4.000000e+000,9.201050e-003,0.000000e+000,0,,0,
1524493335.634,,0.000000e+000,5.500761e+001,3.779212e-006,0.000000e+000,3,8.677098e-001,0.000000e+000,,,,,,,,,,,,,,32,1,4.000000e+000,1.316071e-002,0.000000e+000,0,,0,
1524493373.874,,0.000000e+000,5.499840e+001,3.708506e-006,0.000000e+000,3,8.788080e-001,0.000000e+000,,,,,,,,,,,,,,32,1,4.000000e+000,1.842117e-002,0.000000e+000,0,,0,
1524493411.934,,0.000000e+000,5.500037e+001,3.839642e-006,0.000000e+000,3,8.622001e-001,0.000000e+000,,,,,,,,,,,,,,32,1,4.000000e+000,6.587982e-003,0.000000e+000,0,,0,
1524493449.824,,0.000000e+000,5.500235e+001,3.866616e-006,0.000000e+000,3,8.809742e-001,0.000000e+000,,,,,,,,,,,,,,32,1,4.000000e+000,2.639771e-003,0.000000e+000,0,,0,
1524493487.574,,0.000000e+000,5.499840e+001,3.716444e-006,0.000000e+000,3,8.660750e-001,0.000000e+000,,,,,,,,,,,,,,32,1,4.000000e+000,2.628326e-003,0.000000e+000,0,,0,
1524493524.714,,0.000000e+000,5.499642e+001,3.845146e-006,0.000000e+000,3,8.923196e-001,0.000000e+000,,,,,,,,,,,,,,32,1,4.000000e+000,3.940582e-003,0.000000e+000,0,,0,
1524493562.024,,0.000000e+000,5.499643e+001,3.876710e-006,0.000000e+000,3,8.815380e-001,0.000000e+000,,,,,,,,,,,,,,32,1,4.000000e+000,6.568909e-003,0.000000e+000,0,,0,
1524493600.084,,0.000000e+000,5.499642e+001,3.811550e-006,0.000000e+000,3,8.920630e-001,0.000000e+000,,,,,,,,,,,,,,32,1,4.000000e+000,3.940582e-003,0.000000e+000,0,,0,
1524493637.204,,0.000000e+000,5.500365e+001,3.778163e-006,0.000000e+000,3,8.705147e-001,0.000000e+000,,,,,,,,,,,,,,32,1,4.000000e+000,1.052856e-002,0.000000e+000,0,,0,
1524493674.964,,0.000000e+000,5.500037e+001,3.770510e-006,0.000000e+000,3,8.711142e-001,0.000000e+000,,,,,,,,,,,,,,32,1,4.000000e+000,6.587982e-003,0.000000e+000,0,,0,
1524493713.634,,0.000000e+000,5.500301e+001,3.637372e-006,0.000000e+000,3,8.786427e-001,0.000000e+000,,,,,,,,,,,,,,32,1,4.000000e+000,1.319885e-003,0.000000e+000,0,,0,
1524493751.284,,0.000000e+000,5.499972e+001,3.689735e-006,0.000000e+000,3,8.757970e-001,0.000000e+000,,,,,,,,,,,,,,32,1,4.000000e+000,5.268097e-003,0.000000e+000,0,,0,
1524493789.594,,0.000000e+000,5.500103e+001,3.766631e-006,0.000000e+000,3,8.725255e-001,0.000000e+000,,,,,,,,,,,,,,32,1,4.000000e+000,5.279541e-003,0.000000e+000,0,,0,
1524493827.404,,0.000000e+000,5.500431e+001,3.786964e-006,0.000000e+000,3,8.929486e-001,0.000000e+000,,,,,,,,,,,,,,32,1,4.000000e+000,1.184845e-002,0.000000e+000,0,,0,
1524493865.094,,0.000000e+000,5.499512e+001,3.701163e-006,0.000000e+000,3,8.703681e-001,0.000000e+000,,,,,,,,,,,,,,32,1,4.000000e+000,1.446915e-002,0.000000e+000,0,,0,
1524493902.994,,0.000000e+000,5.499905e+001,3.639422e-006,0.000000e+000,3,8.709869e-001,0.000000e+000,,,,,,,,,,,,,,32,1,4.000000e+000,3.948212e-003,0.000000e+000,0,,0,
1524493940.544,,0.000000e+000,5.499445e+001,3.675486e-006,0.000000e+000,3,8.801155e-001,0.000000e+000,,,,,,,,,,,,,,32,1,4.000000e+000,7.881165e-003,0.000000e+000,0,,0,
1524493977.675,,0.000000e+000,5.499643e+001,3.722700e-006,0.000000e+000,3,8.823618e-001,0.000000e+000,,,,,,,,,,,,,,32,1,4.000000e+000,1.312256e-003,0.000000e+000,0,,0,
1524494015.365,,0.000000e+000,5.499971e+001,3.813660e-006,0.000000e+000,3,9.058222e-001,0.000000e+000,,,,,,,,,,,,,,32,1,4.000000e+000,0.000000e+000,0.000000e+000,0,,0,
1524494066.335,,0.000000e+000,5.500037e+001,4.077975e-006,0.000000e+000,3,9.118533e-001,0.000000e+000,,,,,,,,,,,,,,32,1,4.000000e+000,1.319885e-003,0.000000e+000,0,,0,
1524494103.875,,0.000000e+000,5.499775e+001,3.886214e-006,0.000000e+000,3,9.129543e-001,0.000000e+000,,,,,,,,,,,,,,32,1,4.000000e+000,9.208679e-003,0.000000e+000,0,,0,
1524494141.465,,0.000000e+000,5.500366e+001,3.741736e-006,0.000000e+000,3,8.983893e-001,0.000000e+000,,,,,,,,,,,,,,32,1,4.000000e+000,7.900238e-003,0.000000e+000,0,,0,
1524494179.745,,0.000000e+000,5.499971e+001,3.715749e-006,0.000000e+000,3,8.901483e-001,0.000000e+000,,,,,,,,,,,,,,32,1,4.000000e+000,1.052094e-002,0.000000e+000,0,,0,
1524494217.405,,0.000000e+000,5.499773e+001,3.805513e-006,0.000000e+000,3,8.836274e-001,0.000000e+000,,,,,,,,,,,,,,32,1,4.000000e+000,1.308441e-003,0.000000e+000,0,,0,
1524494254.985,,0.000000e+000,5.499709e+001,3.803071e-006,0.000000e+000,3,8.921894e-001,0.000000e+000,,,,,,,,,,,,,,32,1,4.000000e+000,7.888794e-003,0.000000e+000,0,,0,
1524494292.105,,0.000000e+000,5.500037e+001,3.739776e-006,0.000000e+000,3,8.900094e-001,0.000000e+000,,,,,,,,,,,,,,32,1,4.000000e+000,1.319885e-003,0.000000e+000,0,,0,
1524494329.285,,0.000000e+000,5.500037e+001,3.748324e-006,0.000000e+000,3,8.858483e-001,0.000000e+000,,,,,,,,,,,,,,32,1,4.000000e+000,6.587982e-003,0.000000e+000,0,,0,
1524494367.085,,0.000000e+000,5.499445e+001,3.806456e-006,0.000000e+000,3,8.769388e-001,0.000000e+000,,,,,,,,,,,,,,32,1,4.000000e+000,1.314926e-002,0.000000e+000,0,,0,
1524494405.165,,0.000000e+000,5.499839e+001,3.846626e-006,0.000000e+000,3,8.829176e-001,0.000000e+000,,,,,,,,,,,,,,32,1,4.000000e+000,0.000000e+000,0.000000e+000,0,,0,
1524494443.145,,0.000000e+000,5.499971e+001,3.989998e-006,0.000000e+000,3,8.817441e-001,0.000000e+000,,,,,,,,,,,,,,32,1,4.000000e+000,2.639771e-003,0.000000e+000,0,,0,
1524494481.045,,0.000000e+000,5.500234e+001,3.944403e-006,0.000000e+000,3,9.010173e-001,0.000000e+000,,,,,,,,,,,,,,32,1,4.000000e+000,7.900238e-003,0.000000e+000,0,,0,
1524494518.955,,0.000000e+000,5.499840e+001,4.032869e-006,0.000000e+000,3,9.042001e-001,0.000000e+000,,,,,,,,,,,,,,32,1,4.000000e+000,2.628326e-003,0.000000e+000,0,,0,
1524494557.845,,0.000000e+000,5.499775e+001,4.028883e-006,0.000000e+000,3,8.971562e-001,0.000000e+000,,,,,,,,,,,,,,32,1,4.000000e+000,9.208679e-003,0.000000e+000,0,,0,
1524494596.555,,0.000000e+000,5.500037e+001,4.116605e-006,0.000000e+000,3,9.003564e-001,0.000000e+000,,,,,,,,,,,,,,32,1,4.000000e+000,1.319885e-003,0.000000e+000,0,,0,
1524494634.325,,0.000000e+000,5.499972e+001,4.162625e-006,0.000000e+000,3,9.201156e-001,0.000000e+000,,,,,,,,,,,,,,32,1,4.000000e+000,7.900238e-003,0.000000e+000,0,,0,
1524494672.015,,0.000000e+000,5.499839e+001,4.078682e-006,0.000000e+000,3,8.907980e-001,0.000000e+000,,,,,,,,,,,,,,32,1,4.000000e+000,0.000000e+000,0.000000e+000,0,,0,
1524494710.106,,0.000000e+000,5.499905e+001,4.108452e-006,0.000000e+000,3,9.059882e-001,0.000000e+000,,,,,,,,,,,,,,32,1,4.000000e+000,3.948212e-003,0.000000e+000,0,,0,
1524494747.656,,0.000000e+000,5.499445e+001,4.178425e-006,0.000000e+000,3,8.953126e-001,0.000000e+000,,,,,,,,,,,,,,32,1,4.000000e+000,5.260468e-003,0.000000e+000,0,,0,
1524494785.726,,0.000000e+000,5.499511e+001,4.115155e-006,0.000000e+000,3,9.048521e-001,0.000000e+000,,,,,,,,,,,,,,32,1,4.000000e+000,1.184082e-002,0.000000e+000,0,,0,
1524494823.366,,0.000000e+000,5.499708e+001,4.127803e-006,0.000000e+000,3,8.911249e-001,0.000000e+000,,,,,,,,,,,,,,32,1,4.000000e+000,2.620697e-003,0.000000e+000,0,,0,
1524494861.216,,0.000000e+000,5.500629e+001,4.145676e-006,0.000000e+000,3,9.109292e-001,0.000000e+000,,,,,,,,,,,,,,32,1,4.000000e+000,2.639771e-003,0.000000e+000,0,,0,
1524494898.966,,0.000000e+000,5.499905e+001,4.129578e-006,0.000000e+000,3,9.004436e-001,0.000000e+000,,,,,,,,,,,,,,32,1,4.000000e+000,3.948212e-003,0.000000e+000,0,,0,
1524494951.516,,0.000000e+000,5.500037e+001,4.200900e-006,0.000000e+000,3,9.136767e-001,0.000000e+000,,,,,,,,,,,,,,32,1,4.000000e+000,3.959656e-003,0.000000e+000,0,,0,
1524494989.316,,0.000000e+000,5.499708e+001,4.152835e-006,0.000000e+000,3,8.916924e-001,0.000000e+000,,,,,,,,,,,,,,32,1,4.000000e+000,2.620697e-003,0.000000e+000,0,,0,
1524495027.716,,0.000000e+000,5.500037e+001,4.193075e-006,0.000000e+000,3,8.885334e-001,0.000000e+000,,,,,,,,,,,,,,32,1,4.000000e+000,3.959656e-003,0.000000e+000,0,,0,
1524495065.676,,0.000000e+000,5.499840e+001,4.102949e-006,0.000000e+000,3,8.927147e-001,0.000000e+000,,,,,,,,,,,,,,32,1,4.000000e+000,2.628326e-003,0.000000e+000,0,,0,
1524495103.206,,0.000000e+000,5.500103e+001,4.125606e-006,0.000000e+000,3,8.924225e-001,0.000000e+000,,,,,,,,,,,,,,32,1,4.000000e+000,2.639771e-003,0.000000e+000,0,,0,
1524495140.226,,0.000000e+000,5.499577e+001,4.153612e-006,0.000000e+000,3,8.913727e-001,0.000000e+000,,,,,,,,,,,,,,32,1,4.000000e+000,1.316071e-002,0.000000e+000,0,,0,
1524495177.566,,0.000000e+000,5.499511e+001,4.111487e-006,0.000000e+000,3,9.064077e-001,0.000000e+000,,,,,,,,,,,,,,32,1,4.000000e+000,9.201050e-003,0.000000e+000,0,,0,
1524495215.476,,0.000000e+000,5.499905e+001,4.159608e-006,0.000000e+000,3,8.979594e-001,0.000000e+000,,,,,,,,,,,,,,32,1,4.000000e+000,1.319885e-003,0.000000e+000,0,,0,
1524495252.376,,0.000000e+000,5.499445e+001,4.177008e-006,0.000000e+000,3,8.959539e-001,0.000000e+000,,,,,,,,,,,,,,32,1,4.000000e+000,1.052094e-002,0.000000e+000,0,,0,
1524495290.026,,0.000000e+000,5.499774e+001,4.199492e-006,0.000000e+000,3,8.973926e-001,0.000000e+000,,,,,,,,,,,,,,32,1,4.000000e+000,3.940582e-003,0.000000e+000,0,,0,
1524495328.016,,0.000000e+000,5.499774e+001,4.091027e-006,0.000000e+000,3,8.905399e-001,0.000000e+000,,,,,,,,,,,,,,32,1,4.000000e+000,3.940582e-003,0.000000e+000,0,,0,
1524495365.846,,0.000000e+000,5.499708e+001,4.199583e-006,0.000000e+000,3,8.897086e-001,0.000000e+000,,,,,,,,,,,,,,32,1,4.000000e+000,2.620697e-003,0.000000e+000,0,,0,
1524495403.827,,0.000000e+000,5.500235e+001,4.213280e-006,0.000000e+000,3,9.063379e-001,0.000000e+000,,,,,,,,,,,,,,32,1,4.000000e+000,2.639771e-003,0.000000e+000,0,,0,
1524495440.997,,0.000000e+000,5.500103e+001,4.221768e-006,0.000000e+000,3,8.868065e-001,0.000000e+000,,,,,,,,,,,,,,32,1,4.000000e+000,7.888794e-003,0.000000e+000,0,,0,
1524495478.527,,0.000000e+000,5.500234e+001,4.229300e-006,0.000000e+000,3,8.882304e-001,0.000000e+000,,,,,,,,,,,,,,32,1,4.000000e+000,5.260468e-003,0.000000e+000,0,,0,
1524495516.327,,0.000000e+000,5.499840e+001,4.136097e-006,0.000000e+000,3,8.915788e-001,0.000000e+000,,,,,,,,,,,,,,32,1,4.000000e+000,7.900238e-003,0.000000e+000,0,,0,
1524495554.477,,0.000000e+000,5.499840e+001,4.225157e-006,0.000000e+000,3,8.900321e-001,0.000000e+000,,,,,,,,,,,,,,32,1,4.000000e+000,7.900238e-003,0.000000e+000,0,,0,
1524495592.107,,0.000000e+000,5.499445e+001,4.164072e-006,0.000000e+000,3,8.947440e-001,0.000000e+000,,,,,,,,,,,,,,32,1,4.000000e+000,7.881165e-003,0.000000e+000,0,,0,
1524495630.277,,0.000000e+000,5.499445e+001,4.195080e-006,0.000000e+000,3,8.995475e-001,0.000000e+000,,,,,,,,,,,,,,32,1,4.000000e+000,2.628326e-003,0.000000e+000,0,,0,
1524495667.827,,0.000000e+000,5.499183e+001,4.273933e-006,0.000000e+000,3,8.976241e-001,0.000000e+000,,,,,,,,,,,,,,32,1,4.000000e+000,7.888794e-003,0.000000e+000,0,,0,
1524495705.157,,0.000000e+000,5.499905e+001,4.169924e-006,0.000000e+000,3,9.063903e-001,0.000000e+000,,,,,,,,,,,,,,32,1,4.000000e+000,3.948212e-003,0.000000e+000,0,,0,
1524495743.077,,0.000000e+000,5.500037e+001,4.219496e-006,0.000000e+000,3,9.054253e-001,0.000000e+000,,,,,,,,,,,,,,32,1,4.000000e+000,6.587982e-003,0.000000e+000,0,,0,
1524495781.007,,0.000000e+000,5.499905e+001,4.346938e-006,0.000000e+000,3,9.012136e-001,0.000000e+000,,,,,,,,,,,,,,32,1,4.000000e+000,3.948212e-003,0.000000e+000,0,,0,
1524495818.597,,0.000000e+000,5.499972e+001,4.266708e-006,0.000000e+000,3,8.894557e-001,0.000000e+000,,,,,,,,,,,,,,32,1,4.000000e+000,5.268097e-003,0.000000e+000,0,,0,
1524495870.267,,0.000000e+000,5.499248e+001,4.343178e-006,0.000000e+000,3,9.484528e-001,0.000000e+000,,,,,,,,,,,,,,32,1,4.000000e+000,1.319885e-003,0.000000e+000,0,,0,
1524495907.427,,0.000000e+000,5.499972e+001,4.290154e-006,0.000000e+000,3,8.886046e-001,0.000000e+000,,,,,,,,,,,,,,32,1,4.000000e+000,7.900238e-003,0.000000e+000,0,,0,
1524495945.887,,0.000000e+000,5.499511e+001,4.208654e-006,0.000000e+000,3,9.032207e-001,0.000000e+000,,,,,,,,,,,,,,32,1,4.000000e+000,6.568909e-003,0.000000e+000,0,,0,
1524495983.237,,0.000000e+000,5.499905e+001,4.371864e-006,0.000000e+000,3,8.924204e-001,0.000000e+000,,,,,,,,,,,,,,32,1,4.000000e+000,1.182938e-002,0.000000e+000,0,,0,
1524496020.447,,0.000000e+000,5.499971e+001,4.242603e-006,0.000000e+000,3,9.197971e-001,0.000000e+000,,,,,,,,,,,,,,32,1,4.000000e+000,2.639771e-003,0.000000e+000,0,,0,
1524496058.127,,0.000000e+000,5.499905e+001,4.308954e-006,0.000000e+000,3,8.978623e-001,0.000000e+000,,,,,,,,,,,,,,32,1,4.000000e+000,1.319885e-003,0.000000e+000,0,,0,
1524496096.087,,0.000000e+000,5.499906e+001,4.281589e-006,0.000000e+000,3,9.166846e-001,0.000000e+000,,,,,,,,,,,,,,32,1,4.000000e+000,9.220123e-003,0.000000e+000,0,,0,
1524496133.628,,0.000000e+000,5.499642e+001,4.329228e-006,0.000000e+000,3,9.026747e-001,0.000000e+000,,,,,,,,,,,,,,32,1,4.000000e+000,3.940582e-003,0.000000e+000,0,,0,
1524496196.848,,0.000000e+000,5.500037e+001,4.309221e-006,0.000000e+000,3,9.141817e-001,0.000000e+000,,,,,,,,,,,,,,32,1,4.000000e+000,9.201050e-003,0.000000e+000,0,,0,
1524496234.448,,0.000000e+000,5.500103e+001,4.369804e-006,0.000000e+000,3,9.014501e-001,0.000000e+000,,,,,,,,,,,,,,32,1,4.000000e+000,7.888794e-003,0.000000e+000,0,,0,
1524496271.868,,0.000000e+000,5.499313e+001,4.307219e-006,0.000000e+000,3,9.132450e-001,0.000000e+000,,,,,,,,,,,,,,32,1,4.000000e+000,7.892609e-003,0.000000e+000,0,,0,
1524496309.538,,0.000000e+000,5.499840e+001,4.335908e-006,0.000000e+000,3,9.041136e-001,0.000000e+000,,,,,,,,,,,,,,32,1,4.000000e+000,2.628326e-003,0.000000e+000,0,,0,
1524496347.488,,0.000000e+000,5.499971e+001,4.330124e-006,0.000000e+000,3,9.059708e-001,0.000000e+000,,,,,,,,,,,,,,32,1,4.000000e+000,0.000000e+000,0.000000e+000,0,,0,
1524496384.658,,0.000000e+000,5.499709e+001,4.297216e-006,0.000000e+000,3,9.008511e-001,0.000000e+000,,,,,,,,,,,,,,32,1,4.000000e+000,7.888794e-003,0.000000e+000,0,,0,
1524496422.598,,0.000000e+000,5.500103e+001,4.306170e-006,0.000000e+000,3,9.066921e-001,0.000000e+000,,,,,,,,,,,,,,32,1,4.000000e+000,7.888794e-003,0.000000e+000,0,,0,
1524496460.218,,0.000000e+000,5.500037e+001,4.319853e-006,0.000000e+000,3,9.054073e-001,0.000000e+000,,,,,,,,,,,,,,32,1,4.000000e+000,6.587982e-003,0.000000e+000,0,,0,
1524496498.228,,0.000000e+000,5.500103e+001,4.307219e-006,0.000000e+000,3,9.153352e-001,0.000000e+000,,,,,,,,,,,,,,32,1,4.000000e+000,7.888794e-003,0.000000e+000,0,,0,
1524496535.888,,0.000000e+000,5.500037e+001,4.338667e-006,0.000000e+000,3,9.033383e-001,0.000000e+000,,,,,,,,,,,,,,32,1,4.000000e+000,1.319885e-003,0.000000e+000,0,,0,
1524496573.918,,0.000000e+000,5.499183e+001,4.329825e-006,0.000000e+000,3,9.170241e-001,0.000000e+000,,,,,,,,,,,,,,32,1,4.000000e+000,2.632141e-003,0.000000e+000,0,,0,
1524496611.518,,0.000000e+000,5.500497e+001,4.320985e-006,0.000000e+000,3,9.035468e-001,0.000000e+000,,,,,,,,,,,,,,32,1,4.000000e+000,1.052856e-002,0.000000e+000,0,,0,
1524496649.208,,0.000000e+000,5.499708e+001,4.342590e-006,0.000000e+000,3,9.123425e-001,0.000000e+000,,,,,,,,,,,,,,32,1,4.000000e+000,2.620697e-003,0.000000e+000,0,,0,
1524496687.368,,0.000000e+000,5.499905e+001,4.372329e-006,0.000000e+000,3,9.277920e-001,0.000000e+000,,,,,,,,,,,,,,32,1,4.000000e+000,1.319885e-003,0.000000e+000,0,,0,
1524496725.288,,0.000000e+000,5.499774e+001,4.344622e-006,0.000000e+000,3,9.024425e-001,0.000000e+000,,,,,,,,,,,,,,32,1,4.000000e+000,6.580353e-003,0.000000e+000,0,,0,
1524496762.418,,0.000000e+000,5.499905e+001,4.319156e-006,0.000000e+000,3,9.209881e-001,0.000000e+000,,,,,,,,,,,,,,32,1,4.000000e+000,1.319885e-003,0.000000e+000,0,,0,
1524496838.809,,0.000000e+000,5.499905e+001,4.402954e-006,0.000000e+000,3,9.424558e-001,0.000000e+000,,,,,,,,,,,,,,32,1,4.000000e+000,3.948212e-003,0.000000e+000,0,,0,
1524496876.499,,0.000000e+000,5.498919e+001,4.351046e-006,0.000000e+000,3,9.044201e-001,0.000000e+000,,,,,,,,,,,,,,32,1,4.000000e+000,5.260468e-003,0.000000e+000,0,,0,
1524496914.159,,0.000000e+000,5.499905e+001,4.310353e-006,0.000000e+000,3,9.244545e-001,0.000000e+000,,,,,,,,,,,,,,32,1,4.000000e+000,3.948212e-003,0.000000e+000,0,,0,
1524496951.559,,0.000000e+000,5.500366e+001,4.340057e-006,0.000000e+000,3,9.018853e-001,0.000000e+000,,,,,,,,,,,,,,32,1,4.000000e+000,1.315689e-002,0.000000e+000,0,,0,
1524496989.419,,0.000000e+000,5.499905e+001,4.421179e-006,0.000000e+000,3,9.376429e-001,0.000000e+000,,,,,,,,,,,,,,32,1,4.000000e+000,1.446915e-002,0.000000e+000,0,,0,
1524497026.889,,0.000000e+000,5.499905e+001,4.376414e-006,0.000000e+000,3,9.078305e-001,0.000000e+000,,,,,,,,,,,,,,32,1,4.000000e+000,2.499008e-002,0.000000e+000,0,,0,
1524497064.909,,0.000000e+000,5.499840e+001,4.373592e-006,0.000000e+000,3,9.115428e-001,0.000000e+000,,,,,,,,,,,,,,32,1,4.000000e+000,5.260468e-003,0.000000e+000,0,,0,
1524497102.539,,0.000000e+000,5.500432e+001,4.435659e-006,0.000000e+000,3,9.051696e-001,0.000000e+000,,,,,,,,,,,,,,32,1,4.000000e+000,6.580353e-003,0.000000e+000,0,,0,
1524497139.859,,0.000000e+000,5.499773e+001,4.440089e-006,0.000000e+000,3,9.135476e-001,0.000000e+000,,,,,,,,,,,,,,32,1,4.000000e+000,1.308441e-003,0.000000e+000,0,,0,
1524497177.239,,0.000000e+000,5.499774e+001,4.415846e-006,0.000000e+000,3,9.176565e-001,0.000000e+000,,,,,,,,,,,,,,32,1,4.000000e+000,6.580353e-003,0.000000e+000,0,,0,
1524497215.259,,0.000000e+000,5.499577e+001,4.414128e-006,0.000000e+000,3,8.987765e-001,0.000000e+000,,,,,,,,,,,,,,32,1,4.000000e+000,1.316071e-002,0.000000e+000,0,,0,
1524497253.229,,0.000000e+000,5.500037e+001,4.338425e-006,0.000000e+000,3,9.065049e-001,0.000000e+000,,,,,,,,,,,,,,32,1,4.000000e+000,3.959656e-003,0.000000e+000,0,,0,
1524497290.959,,0.000000e+000,5.499511e+001,4.360681e-006,0.000000e+000,3,9.004194e-001,0.000000e+000,,,,,,,,,,,,,,32,1,4.000000e+000,6.568909e-003,0.000000e+000,0,,0,
1524497328.849,,0.000000e+000,5.499905e+001,4.363867e-006,0.000000e+000,3,9.176769e-001,0.000000e+000,,,,,,,,,,,,,,32,1,4.000000e+000,1.319885e-003,0.000000e+000,0,,0,
1524497366.619,,0.000000e+000,5.500235e+001,4.387419e-006,0.000000e+000,3,8.979892e-001,0.000000e+000,,,,,,,,,,,,,,32,1,4.000000e+000,2.639771e-003,0.000000e+000,0,,0,
1524497404.589,,0.000000e+000,5.499774e+001,4.392670e-006,0.000000e+000,3,9.155845e-001,0.000000e+000,,,,,,,,,,,,,,32,1,4.000000e+000,3.940582e-003,0.000000e+000,0,,0,
1524497442.489,,0.000000e+000,5.499774e+001,4.350594e-006,0.000000e+000,3,9.108744e-001,0.000000e+000,,,,,,,,,,,,,,32,1,4.000000e+000,3.940582e-003,0.000000e+000,0,,0,
1524497479.959,,0.000000e+000,5.500037e+001,4.456173e-006,0.000000e+000,3,9.022045e-001,0.000000e+000,,,,,,,,,,,,,,32,1,4.000000e+000,3.959656e-003,0.000000e+000,0,,0,
1524497518.469,,0.000000e+000,5.499774e+001,4.360805e-006,0.000000e+000,3,9.235138e-001,0.000000e+000,,,,,,,,,,,,,,32,1,4.000000e+000,1.446152e-002,0.000000e+000,0,,0,
1524497555.820,,0.000000e+000,5.499445e+001,4.425675e-006,0.000000e+000,3,8.996068e-001,0.000000e+000,,,,,,,,,,,,,,32,1,4.000000e+000,5.260468e-003,0.000000e+000,0,,0,
1524497593.640,,0.000000e+000,5.499708e+001,4.485430e-006,0.000000e+000,3,8.959028e-001,0.000000e+000,,,,,,,,,,,,,,32,1,4.000000e+000,0.000000e+000,0.000000e+000,0,,0,
1524497631.700,,0.000000e+000,5.499773e+001,4.403052e-006,0.000000e+000,3,9.128550e-001,0.000000e+000,,,,,,,,,,,,,,32,1,4.000000e+000,1.308441e-003,0.000000e+000,0,,0,
1524497669.600,,0.000000e+000,5.500234e+001,4.468250e-006,0.000000e+000,3,9.041880e-001,0.000000e+000,,,,,,,,,,,,,,32,1,4.000000e+000,5.260468e-003,0.000000e+000,0,,0,
1524497707.230,,0.000000e+000,5.500103e+001,4.422620e-006,0.000000e+000,3,9.123086e-001,0.000000e+000,,,,,,,,,,,,,,32,1,4.000000e+000,2.639771e-003,0.000000e+000,0,,0,
1524497758.880,,0.000000e+000,5.499643e+001,4.546788e-006,0.000000e+000,3,9.150511e-001,0.000000e+000,,,,,,,,,,,,,,32,1,4.000000e+000,1.312256e-003,0.000000e+000,0,,0,
1524497797.810,,0.000000e+000,5.499773e+001,4.417805e-006,0.000000e+000,3,9.156600e-001,0.000000e+000,,,,,,,,,,,,,,32,1,4.000000e+000,1.308441e-003,0.000000e+000,0,,0,
1524497835.340,,0.000000e+000,5.499708e+001,4.452272e-006,0.000000e+000,3,9.076566e-001,0.000000e+000,,,,,,,,,,,,,,32,1,4.000000e+000,2.620697e-003,0.000000e+000,0,,0,
1524497873.260,,0.000000e+000,5.499380e+001,4.456739e-006,0.000000e+000,3,9.176260e-001,0.000000e+000,,,,,,,,,,,,,,32,1,4.000000e+000,1.308441e-003,0.000000e+000,0,,0,
1524497911.140,,0.000000e+000,5.499445e+001,4.435118e-006,0.000000e+000,3,9.182377e-001,0.000000e+000,,,,,,,,,,,,,,32,1,4.000000e+000,2.628326e-003,0.000000e+000,0,,0,
1524497948.890,,0.000000e+000,5.499380e+001,4.512115e-006,0.000000e+000,3,9.293576e-001,0.000000e+000,,,,,,,,,,,,,,32,1,4.000000e+000,6.572723e-003,0.000000e+000,0,,0,
1524497986.090,,0.000000e+000,5.500103e+001,4.435903e-006,0.000000e+000,3,9.002790e-001,0.000000e+000,,,,,,,,,,,,,,32,1,4.000000e+000,2.639771e-003,0.000000e+000,0,,0,
1524498023.990,,0.000000e+000,5.499774e+001,4.455678e-006,0.000000e+000,3,9.204883e-001,0.000000e+000,,,,,,,,,,,,,,32,1,4.000000e+000,3.940582e-003,0.000000e+000,0,,0,
1524498061.290,,0.000000e+000,5.499905e+001,4.447636e-006,0.000000e+000,3,9.167464e-001,0.000000e+000,,,,,,,,,,,,,,32,1,4.000000e+000,1.182938e-002,0.000000e+000,0,,0,
1524498099.780,,0.000000e+000,5.500300e+001,4.460432e-006,0.000000e+000,3,9.047679e-001,0.000000e+000,,,,,,,,,,,,,,32,1,4.000000e+000,3.940582e-003,0.000000e+000,0,,0,
1524498138.360,,0.000000e+000,5.499379e+001,4.437603e-006,0.000000e+000,3,9.170720e-001,0.000000e+000,,,,,,,,,,,,,,32,1,4.000000e+000,9.201050e-003,0.000000e+000,0,,0,
1524498176.210,,0.000000e+000,5.499905e+001,4.486852e-006,0.000000e+000,3,9.071265e-001,0.000000e+000,,,,,,,,,,,,,,32,1,4.000000e+000,1.182938e-002,0.000000e+000,0,,0,
1524498214.050,,0.000000e+000,5.499511e+001,4.483876e-006,0.000000e+000,3,9.148921e-001,0.000000e+000,,,,,,,,,,,,,,32,1,4.000000e+000,6.568909e-003,0.000000e+000,0,,0,
1524498251.140,,0.000000e+000,5.499643e+001,4.460657e-006,0.000000e+000,3,9.104468e-001,0.000000e+000,,,,,,,,,,,,,,32,1,4.000000e+000,1.312256e-003,0.000000e+000,0,,0,
1524498288.481,,0.000000e+000,5.500169e+001,4.414791e-006,0.000000e+000,3,9.221256e-001,0.000000e+000,,,,,,,,,,,,,,32,1,4.000000e+000,1.184082e-002,0.000000e+000,0,,0,
1524498326.371,,0.000000e+000,5.499445e+001,4.531409e-006,0.000000e+000,3,9.122040e-001,0.000000e+000,,,,,,,,,,,,,,32,1,4.000000e+000,2.628326e-003,0.000000e+000,0,,0,
1524498364.241,,0.000000e+000,5.499839e+001,4.522084e-006,0.000000e+000,3,9.088938e-001,0.000000e+000,,,,,,,,,,,,,,32,1,4.000000e+000,0.000000e+000,0.000000e+000,0,,0,
1524498402.721,,0.000000e+000,5.499380e+001,4.457926e-006,0.000000e+000,3,9.167899e-001,0.000000e+000,,,,,,,,,,,,,,32,1,4.000000e+000,6.572723e-003,0.000000e+000,0,,0,
1524498440.401,,0.000000e+000,5.500169e+001,4.484105e-006,0.000000e+000,3,9.117637e-001,0.000000e+000,,,,,,,,,,,,,,32,1,4.000000e+000,1.319885e-003,0.000000e+000,0,,0,
1524498478.511,,0.000000e+000,5.499182e+001,4.495696e-006,0.000000e+000,3,9.004560e-001,0.000000e+000,,,,,,,,,,,,,,32,1,4.000000e+000,0.000000e+000,0.000000e+000,0,,0,
1524498516.611,,0.000000e+000,5.500037e+001,4.440955e-006,0.000000e+000,3,9.088311e-001,0.000000e+000,,,,,,,,,,,,,,32,1,4.000000e+000,1.319885e-003,0.000000e+000,0,,0,
1524498554.261,,0.000000e+000,5.499642e+001,4.494101e-006,0.000000e+000,3,9.109047e-001,0.000000e+000,,,,,,,,,,,,,,32,1,4.000000e+000,3.940582e-003,0.000000e+000,0,,0,
1524498592.241,,0.000000e+000,5.499708e+001,4.568774e-006,0.000000e+000,3,9.215955e-001,0.000000e+000,,,,,,,,,,,,,,32,1,4.000000e+000,2.620697e-003,0.000000e+000,0,,0,
1524498629.891,,0.000000e+000,5.500300e+001,4.526006e-006,0.000000e+000,3,9.221597e-001,0.000000e+000,,,,,,,,,,,,,,32,1,4.000000e+000,9.220123e-003,0.000000e+000,0,,0,
1524498680.441,,0.000000e+000,5.499905e+001,4.547293e-006,0.000000e+000,3,9.391232e-001,0.000000e+000,,,,,,,,,,,,,,32,1,4.000000e+000,1.319885e-003,0.000000e+000,0,,0,
1524498718.451,,0.000000e+000,5.499577e+001,4.494071e-006,0.000000e+000,3,9.044408e-001,0.000000e+000,,,,,,,,,,,,,,32,1,4.000000e+000,7.888794e-003,0.000000e+000,0,,0,
1524498756.421,,0.000000e+000,5.499313e+001,4.479303e-006,0.000000e+000,3,9.228497e-001,0.000000e+000,,,,,,,,,,,,,,32,1,4.000000e+000,7.892609e-003,0.000000e+000,0,,0,
1524498794.381,,0.000000e+000,5.499773e+001,4.524670e-006,0.000000e+000,3,9.194484e-001,0.000000e+000,,,,,,,,,,,,,,32,1,4.000000e+000,1.308441e-003,0.000000e+000,0,,0,
1524498832.301,,0.000000e+000,5.500169e+001,4.527771e-006,0.000000e+000,3,9.187297e-001,0.000000e+000,,,,,,,,,,,,,,32,1,4.000000e+000,3.959656e-003,0.000000e+000,0,,0,
1524498869.931,,0.000000e+000,5.499643e+001,4.526073e-006,0.000000e+000,3,9.028389e-001,0.000000e+000,,,,,,,,,,,,,,32,1,4.000000e+000,1.184082e-002,0.000000e+000,0,,0,
1524498907.941,,0.000000e+000,5.500432e+001,4.558303e-006,0.000000e+000,3,9.201357e-001,0.000000e+000,,,,,,,,,,,,,,32,1,4.000000e+000,6.580353e-003,0.000000e+000,0,,0,
1524498945.561,,0.000000e+000,5.499774e+001,4.478961e-006,0.000000e+000,3,8.987197e-001,0.000000e+000,,,,,,,,,,,,,,32,1,4.000000e+000,3.940582e-003,0.000000e+000,0,,0,
1524498983.572,,0.000000e+000,5.500300e+001,4.495538e-006,0.000000e+000,3,9.199386e-001,0.000000e+000,,,,,,,,,,,,,,32,1,4.000000e+000,3.940582e-003,0.000000e+000,0,,0,
1524499021.172,,0.000000e+000,5.499445e+001,4.592639e-006,0.000000e+000,3,9.108512e-001,0.000000e+000,,,,,,,,,,,,,,32,1,4.000000e+000,2.628326e-003,0.000000e+000,0,,0,
1524499059.192,,0.000000e+000,5.500103e+001,4.480591e-006,0.000000e+000,3,9.157040e-001,0.000000e+000,,,,,,,,,,,,,,32,1,4.000000e+000,0.000000e+000,0.000000e+000,0,,0,
1524499096.832,,0.000000e+000,5.500037e+001,4.477860e-006,0.000000e+000,3,8.995516e-001,0.000000e+000,,,,,,,,,,,,,,32,1,4.000000e+000,1.319885e-003,0.000000e+000,0,,0,
1524499134.772,,0.000000e+000,5.499774e+001,4.501793e-006,0.000000e+000,3,9.200280e-001,0.000000e+000,,,,,,,,,,,,,,32,1,4.000000e+000,6.580353e-003,0.000000e+000,0,,0,
1524499172.782,,0.000000e+000,5.499643e+001,4.535178e-006,0.000000e+000,3,9.267892e-001,0.000000e+000,,,,,,,,,,,,,,32,1,4.000000e+000,1.312256e-003,0.000000e+000,0,,0,
1524499210.792,,0.000000e+000,5.499840e+001,4.558981e-006,0.000000e+000,3,9.028492e-001,0.000000e+000,,,,,,,,,,,,,,32,1,4.000000e+000,5.260468e-003,0.000000e+000,0,,0,
1524499248.162,,0.000000e+000,5.500037e+001,4.534262e-006,0.000000e+000,3,9.157686e-001,0.000000e+000,,,,,,,,,,,,,,32,1,4.000000e+000,3.959656e-003,0.000000e+000,0,,0,
1524499285.062,,0.000000e+000,5.499642e+001,4.511926e-006,0.000000e+000,3,9.124095e-001,0.000000e+000,,,,,,,,,,,,,,32,1,4.000000e+000,3.940582e-003,0.000000e+000,0,,0,
1524499322.812,,0.000000e+000,5.499577e+001,4.510111e-006,0.000000e+000,3,9.138672e-001,0.000000e+000,,,,,,,,,,,,,,32,1,4.000000e+000,0.000000e+000,0.000000e+000,0,,0,
1524499360.062,,0.000000e+000,5.498919e+001,4.522945e-006,0.000000e+000,3,9.113827e-001,0.000000e+000,,,,,,,,,,,,,,32,1,4.000000e+000,0.000000e+000,0.000000e+000,0,,0,
1524499397.992,,0.000000e+000,5.500169e+001,4.568740e-006,0.000000e+000,3,9.040210e-001,0.000000e+000,,,,,,,,,,,,,,32,1,4.000000e+000,3.959656e-003,0.000000e+000,0,,0,
1524499435.712,,0.000000e+000,5.500037e+001,4.529875e-006,0.000000e+000,3,9.176918e-001,0.000000e+000,,,,,,,,,,,,,,32,1,4.000000e+000,9.201050e-003,0.000000e+000,0,,0,
1524499473.252,,0.000000e+000,5.499840e+001,4.511839e-006,0.000000e+000,3,9.099787e-001,0.000000e+000,,,,,,,,,,,,,,32,1,4.000000e+000,5.260468e-003,0.000000e+000,0,,0,
1524499510.562,,0.000000e+000,5.500235e+001,4.467503e-006,0.000000e+000,3,9.245355e-001,0.000000e+000,,,,,,,,,,,,,,32,1,4.000000e+000,0.000000e+000,0.000000e+000,0,,0,
1524499548.142,,0.000000e+000,5.499643e+001,4.559623e-006,0.000000e+000,3,9.007512e-001,0.000000e+000,,,,,,,,,,,,,,32,1,4.000000e+000,1.184082e-002,0.000000e+000,0,,0,
1524499599.202,,0.000000e+000,5.500366e+001,4.588152e-006,0.000000e+000,3,9.446613e-001,0.000000e+000,,,,,,,,,,,,,,32,1,4.000000e+000,7.900238e-003,0.000000e+000,0,,0,
1524499637.212,,0.000000e+000,5.500169e+001,4.494826e-006,0.000000e+000,3,9.294137e-001,0.000000e+000,,,,,,,,,,,,,,32,1,4.000000e+000,1.319885e-003,0.000000e+000,0,,0,
1524499674.312,,0.000000e+000,5.499971e+001,4.486926e-006,0.000000e+000,3,9.227218e-001,0.000000e+000,,,,,,,,,,,,,,32,1,4.000000e+000,1.052094e-002,0.000000e+000,0,,0,
1524499711.873,,0.000000e+000,5.500037e+001,4.534950e-006,0.000000e+000,3,9.148575e-001,0.000000e+000,,,,,,,,,,,,,,32,1,4.000000e+000,1.319885e-003,0.000000e+000,0,,0,
1524499749.763,,0.000000e+000,5.500169e+001,4.595317e-006,0.000000e+000,3,9.142432e-001,0.000000e+000,,,,,,,,,,,,,,32,1,4.000000e+000,1.709747e-002,0.000000e+000,0,,0,
1524499787.673,,0.000000e+000,5.499972e+001,4.471329e-006,0.000000e+000,3,9.109089e-001,0.000000e+000,,,,,,,,,,,,,,32,1,4.000000e+000,5.268097e-003,0.000000e+000,0,,0,
1524499825.033,,0.000000e+000,5.499905e+001,4.580173e-006,0.000000e+000,3,9.365607e-001,0.000000e+000,,,,,,,,,,,,,,32,1,4.000000e+000,1.319885e-003,0.000000e+000,0,,0,
1524499863.263,,0.000000e+000,5.499511e+001,4.535249e-006,0.000000e+000,3,9.159738e-001,0.000000e+000,,,,,,,,,,,,,,32,1,4.000000e+000,1.319885e-003,0.000000e+000,0,,0,
1524499900.363,,0.000000e+000,5.499905e+001,4.632958e-006,0.000000e+000,3,9.102634e-001,0.000000e+000,,,,,,,,,,,,,,32,1,4.000000e+000,1.319885e-003,0.000000e+000,0,,0,
1524499937.983,,0.000000e+000,5.500367e+001,4.661839e-006,0.000000e+000,3,9.210373e-001,0.000000e+000,,,,,,,,,,,,,,32,1,4.000000e+000,0.000000e+000,0.000000e+000,0,,0,
1524499975.883,,0.000000e+000,5.500037e+001,4.601400e-006,0.000000e+000,3,9.188535e-001,0.000000e+000,,,,,,,,,,,,,,32,1,4.000000e+000,1.184082e-002,0.000000e+000,0,,0,
1524500013.923,,0.000000e+000,5.499577e+001,4.550948e-006,0.000000e+000,3,9.099333e-001,0.000000e+000,,,,,,,,,,,,,,32,1,4.000000e+000,7.888794e-003,0.000000e+000,0,,0,
1524500051.913,,0.000000e+000,5.500103e+001,4.525645e-006,0.000000e+000,3,9.210199e-001,0.000000e+000,,,,,,,,,,,,,,32,1,4.000000e+000,2.639771e-003,0.000000e+000,0,,0,
1524500089.623,,0.000000e+000,5.499840e+001,4.585207e-006,0.000000e+000,3,9.105206e-001,0.000000e+000,,,,,,,,,,,,,,32,1,4.000000e+000,2.628326e-003,0.000000e+000,0,,0,
1524500127.553,,0.000000e+000,5.500169e+001,4.601905e-006,0.000000e+000,3,9.291981e-001,0.000000e+000,,,,,,,,,,,,,,32,1,4.000000e+000,1.319885e-003,0.000000e+000,0,,0,
1524500165.243,,0.000000e+000,5.499906e+001,4.618757e-006,0.000000e+000,3,9.080651e-001,0.000000e+000,,,,,,,,,,,,,,32,1,4.000000e+000,9.220123e-003,0.000000e+000,0,,0,
1524500203.143,,0.000000e+000,5.499840e+001,4.583530e-006,0.000000e+000,3,9.201829e-001,0.000000e+000,,,,,,,,,,,,,,32,1,4.000000e+000,7.900238e-003,0.000000e+000,0,,0,
1524500240.813,,0.000000e+000,5.499906e+001,4.569707e-006,0.000000e+000,3,9.092746e-001,0.000000e+000,,,,,,,,,,,,,,32,1,4.000000e+000,6.580353e-003,0.000000e+000,0,,0,
1524500278.763,,0.000000e+000,5.499775e+001,4.570676e-006,0.000000e+000,3,9.213252e-001,0.000000e+000,,,,,,,,,,,,,,32,1,4.000000e+000,9.208679e-003,0.000000e+000,0,,0,
1524500316.333,,0.000000e+000,5.499248e+001,4.556808e-006,0.000000e+000,3,9.298670e-001,0.000000e+000,,,,,,,,,,,,,,32,1,4.000000e+000,1.182938e-002,0.000000e+000,0,,0,
1524500354.373,,0.000000e+000,5.500563e+001,4.598076e-006,0.000000e+000,3,9.323405e-001,0.000000e+000,,,,,,,,,,,,,,32,1,4.000000e+000,6.568909e-003,0.000000e+000,0,,0,
1524500392.543,,0.000000e+000,5.499840e+001,4.430704e-006,0.000000e+000,3,9.161418e-001,0.000000e+000,,,,,,,,,,,,,,32,1,4.000000e+000,5.260468e-003,0.000000e+000,0,,0,
1524500430.124,,0.000000e+000,5.499577e+001,4.592783e-006,0.000000e+000,3,9.142771e-001,0.000000e+000,,,,,,,,,,,,,,32,1,4.000000e+000,2.632141e-003,0.000000e+000,0,,0,
1524500468.084,,0.000000e+000,5.499511e+001,4.472632e-006,0.000000e+000,3,9.227882e-001,0.000000e+000,,,,,,,,,,,,,,32,1,4.000000e+000,6.568909e-003,0.000000e+000,0,,0,
1524500519.434,,0.000000e+000,5.499709e+001,4.709176e-006,0.000000e+000,3,9.289421e-001,0.000000e+000,,,,,,,,,,,,,,32,1,4.000000e+000,1.316071e-002,0.000000e+000,0,,0,
1524500557.394,,0.000000e+000,5.499248e+001,4.563020e-006,0.000000e+000,3,9.078246e-001,0.000000e+000,,,,,,,,,,,,,,32,1,4.000000e+000,6.580353e-003,0.000000e+000,0,,0,
1524500595.134,,0.000000e+000,5.500037e+001,4.587247e-006,0.000000e+000,3,9.069647e-001,0.000000e+000,,,,,,,,,,,,,,32,1,4.000000e+000,6.587982e-003,0.000000e+000,0,,0,
1524500633.024,,0.000000e+000,5.499642e+001,4.530943e-006,0.000000e+000,3,9.010316e-001,0.000000e+000,,,,,,,,,,,,,,32,1,4.000000e+000,3.940582e-003,0.000000e+000,0,,0,
1524500670.854,,0.000000e+000,5.500169e+001,4.668565e-006,0.000000e+000,3,9.133731e-001,0.000000e+000,,,,,,,,,,,,,,32,1,4.000000e+000,3.959656e-003,0.000000e+000,0,,0,
1524500708.654,,0.000000e+000,5.499642e+001,4.567365e-006,0.000000e+000,3,9.191123e-001,0.000000e+000,,,,,,,,,,,,,,32,1,4.000000e+000,3.940582e-003,0.000000e+000,0,,0,
1524500746.444,,0.000000e+000,5.499709e+001,4.644636e-006,0.000000e+000,3,9.115520e-001,0.000000e+000,,,,,,,,,,,,,,32,1,4.000000e+000,7.888794e-003,0.000000e+000,0,,0,
1524500784.404,,0.000000e+000,5.499972e+001,4.630887e-006,0.000000e+000,3,9.200886e-001,0.000000e+000,,,,,,,,,,,,,,32,1,4.000000e+000,5.268097e-003,0.000000e+000,0,,0,
1524500822.094,,0.000000e+000,5.499905e+001,4.598414e-006,0.000000e+000,3,9.124442e-001,0.000000e+000,,,,,,,,,,,,,,32,1,4.000000e+000,1.446915e-002,0.000000e+000,0,,0,
1524500859.814,,0.000000e+000,5.499577e+001,4.608807e-006,0.000000e+000,3,9.261882e-001,0.000000e+000,,,,,,,,,,,,,,32,1,4.000000e+000,0.000000e+000,0.000000e+000,0,,0,
1524500897.514,,0.000000e+000,5.499182e+001,4.573655e-006,0.000000e+000,3,9.113285e-001,0.000000e+000,,,,,,,,,,,,,,32,1,4.000000e+000,0.000000e+000,0.000000e+000,0,,0,
1524500934.954,,0.000000e+000,5.499839e+001,4.577963e-006,0.000000e+000,3,9.135686e-001,0.000000e+000,,,,,,,,,,,,,,32,1,4.000000e+000,0.000000e+000,0.000000e+000,0,,0,
1524500972.974,,0.000000e+000,5.499774e+001,4.561332e-006,0.000000e+000,3,9.218516e-001,0.000000e+000,,,,,,,,,,,,,,32,1,4.000000e+000,6.580353e-003,0.000000e+000,0,,0,
1524501010.004,,0.000000e+000,5.500103e+001,4.678817e-006,0.000000e+000,3,9.098562e-001,0.000000e+000,,,,,,,,,,,,,,32,1,4.000000e+000,3.157043e-002,0.000000e+000,0,,0,
1524501047.724,,0.000000e+000,5.499971e+001,4.613229e-006,0.000000e+000,3,9.168095e-001,0.000000e+000,,,,,,,,,,,,,,32,1,4.000000e+000,0.000000e+000,0.000000e+000,0,,0,
1524501085.454,,0.000000e+000,5.499971e+001,4.578508e-006,0.000000e+000,3,9.006739e-001,0.000000e+000,,,,,,,,,,,,,,32,1,4.000000e+000,1.052094e-002,0.000000e+000,0,,0,
1524501123.315,,0.000000e+000,5.499775e+001,4.587334e-006,0.000000e+000,3,9.199070e-001,0.000000e+000,,,,,,,,,,,,,,32,1,4.000000e+000,9.208679e-003,0.000000e+000,0,,0,
1524501161.045,,0.000000e+000,5.499577e+001,4.571080e-006,0.000000e+000,3,9.057266e-001,0.000000e+000,,,,,,,,,,,,,,32,1,4.000000e+000,5.249023e-003,0.000000e+000,0,,0,
1524501199.505,,0.000000e+000,5.499906e+001,4.633090e-006,0.000000e+000,3,9.180709e-001,0.000000e+000,,,,,,,,,,,,,,32,1,4.000000e+000,9.220123e-003,0.000000e+000,0,,0,
1524501237.165,,0.000000e+000,5.500432e+001,4.549980e-006,0.000000e+000,3,9.147617e-001,0.000000e+000,,,,,,,,,,,,,,32,1,4.000000e+000,6.580353e-003,0.000000e+000,0,,0,
1524501274.675,,0.000000e+000,5.499117e+001,4.578433e-006,0.000000e+000,3,9.101850e-001,0.000000e+000,,,,,,,,,,,,,,32,1,4.000000e+000,1.312256e-003,0.000000e+000,0,,0,
1524501312.415,,0.000000e+000,5.499972e+001,4.682540e-006,0.000000e+000,3,9.399944e-001,0.000000e+000,,,,,,,,,,,,,,32,1,4.000000e+000,5.268097e-003,0.000000e+000,0,,0,
1524501350.405,,0.000000e+000,5.500432e+001,4.601868e-006,0.000000e+000,3,9.119600e-001,0.000000e+000,,,,,,,,,,,,,,32,1,4.000000e+000,1.300812e-003,0.000000e+000,0,,0,
1524501388.305,,0.000000e+000,5.500366e+001,4.640131e-006,0.000000e+000,3,9.089252e-001,0.000000e+000,,,,,,,,,,,,,,32,1,4.000000e+000,1.578140e-002,0.000000e+000,0,,0,
1524501413.655,,0.000000e+000,5.499445e+001,4.714488e-006,0.000000e+000,3,9.122425e-001,0.000000e+000,,,,,,,,,,,,,,32,1,4.000000e+000,5.260468e-003,0.000000e+000,0,,0,