File: Experimental Raw Data/TC04-12-01K TRMac VRMde/TC04-12-01K_TRMac_57K_0.06Kmin_VRMde_55K.dc.dat
[Header]
TITLE,MPMS DC Measurement
BYAPP,MPMS Measurement,2.1,Summary
FILEOPENTIME, 1524687525.945000 4/25/2018, 2:18:45 PM

INFO, APPNAME, MPMS MultiVu Application, Revision 1.61,  Build 082

INFO, NAME, TC04-12-01K
INFO, WEIGHT, 1.000
INFO, AREA, 1.000
INFO, LENGTH, 1.000
INFO, SHAPE, 0
INFO, COMMENT,
INFO, SEQUENCE FILE: TRMac_57K_0.06Kmin_VRMde_55K.seq


INFO, BACKGROUND DATA FILE:, None


STARTUPAXIS,X,4,LINEAR,AUTO,0.000000,0.000000
STARTUPAXIS,Y1,5,LINEAR,AUTO,0.000000,0.000000


STARTUPGROUP,Longitudinal
FIELDGROUP,Longitudinal,1,2,3,4,5,6,7,8,9,15,16,17,18,27,28
FIELDGROUP,Transverse,1,2,3,4,10,11,12,13,14,19,20,21,22,27,28

PLOT_APPEARANCE,ALL,HORZ_GRID_ON,VERT_GRID_ON,MARKERS_AND_LINES

[Data]
Time,Comment,Field (Oe),Temperature (K),Long Moment (emu),Long Scan Std Dev,Long Algorithm,Long Reg Fit,Long Percent Error (%),Trans Moment (emu),Trans Scan Std Dev,Trans Algorithm,Trans Reg Fit,Trans Percent Error (%),Long Moment [w/o ABS] (emu),Long Scan Std Dev [w/o ABS],Long Reg Fit [w/o ABS],Long Percent Error [w/o ABS] (%),Trans Moment [w/o ABS] (emu),Trans Scan Std Dev [w/o ABS],Trans Reg Fit [w/o ABS],Trans Percent Error [w/o ABS] (%),Points per Scan,Scans per Measurement,Scan Length (cm),Delta Temp (K),Rot Position (deg),Error,EC Comp. Running,Using ABS,
1524687525.945,,0.000000e+000,5.498920e+001,8.213769e-006,0.000000e+000,3,7.884965e-001,0.000000e+000,,,,,,,,,,,,,,32,1,4.000000e+000,2.628326e-003,0.000000e+000,0,,0,
1524687551.225,,0.000000e+000,5.498788e+001,6.728844e-006,0.000000e+000,3,7.804571e-001,0.000000e+000,,,,,,,,,,,,,,32,1,4.000000e+000,1.052094e-002,0.000000e+000,0,,0,
1524687576.835,,0.000000e+000,5.499773e+001,5.762422e-006,0.000000e+000,3,7.638348e-001,0.000000e+000,,,,,,,,,,,,,,32,1,4.000000e+000,1.308441e-003,0.000000e+000,0,,0,
1524687602.505,,0.000000e+000,5.498920e+001,5.260179e-006,0.000000e+000,3,7.814883e-001,0.000000e+000,,,,,,,,,,,,,,32,1,4.000000e+000,2.103043e-002,0.000000e+000,0,,0,
1524687628.025,,0.000000e+000,5.499643e+001,4.709477e-006,0.000000e+000,3,7.794442e-001,0.000000e+000,,,,,,,,,,,,,,32,1,4.000000e+000,1.708984e-002,0.000000e+000,0,,0,
1524687653.375,,0.000000e+000,5.499774e+001,4.323339e-006,0.000000e+000,3,7.469504e-001,0.000000e+000,,,,,,,,,,,,,,32,1,4.000000e+000,6.580353e-003,0.000000e+000,0,,0,
1524687678.595,,0.000000e+000,5.499773e+001,4.023198e-006,0.000000e+000,3,7.464904e-001,0.000000e+000,,,,,,,,,,,,,,32,1,4.000000e+000,1.308441e-003,0.000000e+000,0,,0,
1524687703.825,,0.000000e+000,5.500103e+001,3.846059e-006,0.000000e+000,3,7.424279e-001,0.000000e+000,,,,,,,,,,,,,,32,1,4.000000e+000,1.052094e-002,0.000000e+000,0,,0,
1524687729.035,,0.000000e+000,5.499774e+001,3.670675e-006,0.000000e+000,3,7.251668e-001,0.000000e+000,,,,,,,,,,,,,,32,1,4.000000e+000,3.940582e-003,0.000000e+000,0,,0,
1524687754.405,,0.000000e+000,5.500300e+001,8.395257e-005,0.000000e+000,3,3.932046e-001,0.000000e+000,,,,,,,,,,,,,,32,1,4.000000e+000,1.183701e-002,0.000000e+000,0,,0,
1524687779.735,,0.000000e+000,5.500563e+001,3.317755e-006,0.000000e+000,3,7.222167e-001,0.000000e+000,,,,,,,,,,,,,,32,1,4.000000e+000,1.184082e-002,0.000000e+000,0,,0,
1524687804.675,,0.000000e+000,5.499905e+001,3.200042e-006,0.000000e+000,3,7.155972e-001,0.000000e+000,,,,,,,,,,,,,,32,1,4.000000e+000,1.319885e-003,0.000000e+000,0,,0,
1524687829.915,,0.000000e+000,5.499708e+001,3.040725e-006,0.000000e+000,3,7.118152e-001,0.000000e+000,,,,,,,,,,,,,,32,1,4.000000e+000,2.620697e-003,0.000000e+000,0,,0,
1524687855.375,,0.000000e+000,5.500300e+001,2.892660e-006,0.000000e+000,3,6.743510e-001,0.000000e+000,,,,,,,,,,,,,,32,1,4.000000e+000,6.580353e-003,0.000000e+000,0,,0,
1524687880.665,,0.000000e+000,5.499708e+001,2.748287e-006,0.000000e+000,3,6.810564e-001,0.000000e+000,,,,,,,,,,,,,,32,1,4.000000e+000,5.260468e-003,0.000000e+000,0,,0,
1524687906.805,,0.000000e+000,5.500301e+001,2.575681e-006,0.000000e+000,3,6.912961e-001,0.000000e+000,,,,,,,,,,,,,,32,1,4.000000e+000,1.319885e-003,0.000000e+000,0,,0,
1524687957.295,,0.000000e+000,5.499643e+001,2.472162e-006,0.000000e+000,3,6.916427e-001,0.000000e+000,,,,,,,,,,,,,,32,1,4.000000e+000,6.568909e-003,0.000000e+000,0,,0,
1524687982.735,,0.000000e+000,5.499971e+001,2.425612e-006,0.000000e+000,3,6.978204e-001,0.000000e+000,,,,,,,,,,,,,,32,1,4.000000e+000,0.000000e+000,0.000000e+000,0,,0,
1524688007.735,,0.000000e+000,5.499905e+001,2.327893e-006,0.000000e+000,3,6.805291e-001,0.000000e+000,,,,,,,,,,,,,,32,1,4.000000e+000,1.319885e-003,0.000000e+000,0,,0,
1524688032.915,,0.000000e+000,5.499643e+001,2.218564e-006,0.000000e+000,3,6.589477e-001,0.000000e+000,,,,,,,,,,,,,,32,1,4.000000e+000,1.312256e-003,0.000000e+000,0,,0,
1524688057.785,,0.000000e+000,5.499905e+001,2.199298e-006,0.000000e+000,3,6.641902e-001,0.000000e+000,,,,,,,,,,,,,,32,1,4.000000e+000,3.948212e-003,0.000000e+000,0,,0,
1524688083.395,,0.000000e+000,5.499577e+001,2.114707e-006,0.000000e+000,3,6.318719e-001,0.000000e+000,,,,,,,,,,,,,,32,1,4.000000e+000,2.632141e-003,0.000000e+000,0,,0,
1524688108.106,,0.000000e+000,5.499511e+001,2.084410e-006,0.000000e+000,3,6.234410e-001,0.000000e+000,,,,,,,,,,,,,,32,1,4.000000e+000,3.940582e-003,0.000000e+000,0,,0,
1524688132.996,,0.000000e+000,5.499971e+001,2.062826e-006,0.000000e+000,3,6.267120e-001,0.000000e+000,,,,,,,,,,,,,,32,1,4.000000e+000,2.639771e-003,0.000000e+000,0,,0,
1524688158.746,,0.000000e+000,5.499840e+001,1.953038e-006,0.000000e+000,3,5.761948e-001,0.000000e+000,,,,,,,,,,,,,,32,1,4.000000e+000,2.628326e-003,0.000000e+000,0,,0,
1524688183.766,,0.000000e+000,5.499511e+001,1.924184e-006,0.000000e+000,3,5.555625e-001,0.000000e+000,,,,,,,,,,,,,,32,1,4.000000e+000,3.940582e-003,0.000000e+000,0,,0,
1524688209.836,,0.000000e+000,5.499840e+001,1.762198e-006,0.000000e+000,3,5.856195e-001,0.000000e+000,,,,,,,,,,,,,,32,1,4.000000e+000,5.260468e-003,0.000000e+000,0,,0,
1524688235.346,,0.000000e+000,5.500235e+001,1.760133e-006,0.000000e+000,3,5.652978e-001,0.000000e+000,,,,,,,,,,,,,,32,1,4.000000e+000,0.000000e+000,0.000000e+000,0,,0,
1524688260.606,,0.000000e+000,5.499708e+001,1.772179e-006,0.000000e+000,3,5.914288e-001,0.000000e+000,,,,,,,,,,,,,,32,1,4.000000e+000,0.000000e+000,0.000000e+000,0,,0,
1524688285.856,,0.000000e+000,5.499839e+001,1.671612e-006,0.000000e+000,3,5.413954e-001,0.000000e+000,,,,,,,,,,,,,,32,1,4.000000e+000,0.000000e+000,0.000000e+000,0,,0,
1524688311.076,,0.000000e+000,5.499840e+001,1.634626e-006,0.000000e+000,3,5.420265e-001,0.000000e+000,,,,,,,,,,,,,,32,1,4.000000e+000,2.628326e-003,0.000000e+000,0,,0,
1524688336.346,,0.000000e+000,5.499577e+001,1.613483e-006,0.000000e+000,3,5.115780e-001,0.000000e+000,,,,,,,,,,,,,,32,1,4.000000e+000,5.249023e-003,0.000000e+000,0,,0,
1524688361.086,,0.000000e+000,5.499971e+001,1.616284e-006,0.000000e+000,3,5.735708e-001,0.000000e+000,,,,,,,,,,,,,,32,1,4.000000e+000,2.639771e-003,0.000000e+000,0,,0,
1524688386.536,,0.000000e+000,5.499774e+001,1.562675e-006,0.000000e+000,3,4.998130e-001,0.000000e+000,,,,,,,,,,,,,,32,1,4.000000e+000,3.940582e-003,0.000000e+000,0,,0,
1524688412.186,,0.000000e+000,5.499511e+001,1.555441e-006,0.000000e+000,3,4.926221e-001,0.000000e+000,,,,,,,,,,,,,,32,1,4.000000e+000,9.201050e-003,0.000000e+000,0,,0,
1524688438.586,,0.000000e+000,5.499445e+001,1.477019e-006,0.000000e+000,3,4.921931e-001,0.000000e+000,,,,,,,,,,,,,,32,1,4.000000e+000,2.628326e-003,0.000000e+000,0,,0,
1524688464.056,,0.000000e+000,5.499971e+001,1.568653e-006,0.000000e+000,3,5.092583e-001,0.000000e+000,,,,,,,,,,,,,,32,1,4.000000e+000,2.639771e-003,0.000000e+000,0,,0,
1524688489.186,,0.000000e+000,5.499182e+001,1.542439e-006,0.000000e+000,3,5.135744e-001,0.000000e+000,,,,,,,,,,,,,,32,1,4.000000e+000,5.260468e-003,0.000000e+000,0,,0,
1524688514.506,,0.000000e+000,5.499708e+001,1.476221e-006,0.000000e+000,3,4.637146e-001,0.000000e+000,,,,,,,,,,,,,,32,1,4.000000e+000,2.620697e-003,0.000000e+000,0,,0,
1524688539.656,,0.000000e+000,5.499905e+001,1.472067e-006,0.000000e+000,3,5.320566e-001,0.000000e+000,,,,,,,,,,,,,,32,1,4.000000e+000,3.948212e-003,0.000000e+000,0,,0,
1524688564.286,,0.000000e+000,5.499905e+001,1.478277e-006,0.000000e+000,3,5.045723e-001,0.000000e+000,,,,,,,,,,,,,,32,1,4.000000e+000,1.319885e-003,0.000000e+000,0,,0,
1524688589.396,,0.000000e+000,5.500168e+001,1.470305e-006,0.000000e+000,3,5.017483e-001,0.000000e+000,,,,,,,,,,,,,,32,1,4.000000e+000,6.580353e-003,0.000000e+000,0,,0,
1524688614.526,,0.000000e+000,5.499906e+001,1.404542e-006,0.000000e+000,3,4.309973e-001,0.000000e+000,,,,,,,,,,,,,,32,1,4.000000e+000,6.580353e-003,0.000000e+000,0,,0,
1524688639.806,,0.000000e+000,5.500563e+001,1.315217e-006,0.000000e+000,3,3.976489e-001,0.000000e+000,,,,,,,,,,,,,,32,1,4.000000e+000,1.184082e-002,0.000000e+000,0,,0,
1524688665.066,,0.000000e+000,5.499643e+001,1.257572e-006,0.000000e+000,3,4.065339e-001,0.000000e+000,,,,,,,,,,,,,,32,1,4.000000e+000,1.312256e-003,0.000000e+000,0,,0,
1524688690.206,,0.000000e+000,5.499773e+001,1.293592e-006,0.000000e+000,3,4.115092e-001,0.000000e+000,,,,,,,,,,,,,,32,1,4.000000e+000,1.308441e-003,0.000000e+000,0,,0,
1524688715.416,,0.000000e+000,5.499773e+001,1.308615e-006,0.000000e+000,3,4.276709e-001,0.000000e+000,,,,,,,,,,,,,,32,1,4.000000e+000,1.308441e-003,0.000000e+000,0,,0,
1524688740.576,,0.000000e+000,5.499051e+001,1.272159e-006,0.000000e+000,3,4.308765e-001,0.000000e+000,,,,,,,,,,,,,,32,1,4.000000e+000,5.260468e-003,0.000000e+000,0,,0,
1524688765.776,,0.000000e+000,5.499182e+001,1.248685e-006,0.000000e+000,3,4.049355e-001,0.000000e+000,,,,,,,,,,,,,,32,1,4.000000e+000,1.314163e-002,0.000000e+000,0,,0,
1524688790.896,,0.000000e+000,5.499774e+001,1.213030e-006,0.000000e+000,3,3.819720e-001,0.000000e+000,,,,,,,,,,,,,,32,1,4.000000e+000,6.580353e-003,0.000000e+000,0,,0,
1524688815.907,,0.000000e+000,5.499906e+001,1.180782e-006,0.000000e+000,3,4.582478e-001,0.000000e+000,,,,,,,,,,,,,,32,1,4.000000e+000,9.220123e-003,0.000000e+000,0,,0,
1524688841.287,,0.000000e+000,5.499905e+001,1.211708e-006,0.000000e+000,3,3.814146e-001,0.000000e+000,,,,,,,,,,,,,,32,1,4.000000e+000,1.319885e-003,0.000000e+000,0,,0,
1524688866.107,,0.000000e+000,5.499511e+001,1.293961e-006,0.000000e+000,3,4.136546e-001,0.000000e+000,,,,,,,,,,,,,,32,1,4.000000e+000,3.940582e-003,0.000000e+000,0,,0,
1524688891.717,,0.000000e+000,5.500103e+001,1.267952e-006,0.000000e+000,3,4.029103e-001,0.000000e+000,,,,,,,,,,,,,,32,1,4.000000e+000,1.316071e-002,0.000000e+000,0,,0,
1524688916.757,,0.000000e+000,5.499774e+001,1.226744e-006,0.000000e+000,3,4.363668e-001,0.000000e+000,,,,,,,,,,,,,,32,1,4.000000e+000,6.580353e-003,0.000000e+000,0,,0,
1524688941.967,,0.000000e+000,5.499773e+001,1.227753e-006,0.000000e+000,3,4.139768e-001,0.000000e+000,,,,,,,,,,,,,,32,1,4.000000e+000,1.308441e-003,0.000000e+000,0,,0,
1524688966.637,,0.000000e+000,5.499380e+001,1.232741e-006,0.000000e+000,3,4.119545e-001,0.000000e+000,,,,,,,,,,,,,,32,1,4.000000e+000,1.308441e-003,0.000000e+000,0,,0,
1524688991.857,,0.000000e+000,5.499708e+001,1.270360e-006,0.000000e+000,3,3.795561e-001,0.000000e+000,,,,,,,,,,,,,,32,1,4.000000e+000,2.620697e-003,0.000000e+000,0,,0,
1524689017.027,,0.000000e+000,5.500103e+001,1.247058e-006,0.000000e+000,3,2.915286e-001,0.000000e+000,,,,,,,,,,,,,,32,1,4.000000e+000,0.000000e+000,0.000000e+000,0,,0,
1524689042.667,,0.000000e+000,5.500037e+001,1.151371e-006,0.000000e+000,3,2.407121e-001,0.000000e+000,,,,,,,,,,,,,,32,1,4.000000e+000,1.319885e-003,0.000000e+000,0,,0,
1524689067.727,,0.000000e+000,5.499840e+001,1.196670e-006,0.000000e+000,3,3.023864e-001,0.000000e+000,,,,,,,,,,,,,,32,1,4.000000e+000,2.628326e-003,0.000000e+000,0,,0,
1524689093.387,,0.000000e+000,5.499906e+001,1.016582e-006,0.000000e+000,3,1.455103e-001,0.000000e+000,,,,,,,,,,,,,,32,1,4.000000e+000,6.580353e-003,0.000000e+000,0,,0,
1524689144.077,,0.000000e+000,5.498919e+001,1.224891e-006,0.000000e+000,3,3.053191e-001,0.000000e+000,,,,,,,,,,,,,,32,1,4.000000e+000,5.260468e-003,0.000000e+000,0,,0,
1524689169.447,,0.000000e+000,5.500235e+001,1.166315e-006,0.000000e+000,3,3.064732e-001,0.000000e+000,,,,,,,,,,,,,,32,1,4.000000e+000,2.639771e-003,0.000000e+000,0,,0,
1524689194.637,,0.000000e+000,5.499840e+001,1.169472e-006,0.000000e+000,3,3.552123e-001,0.000000e+000,,,,,,,,,,,,,,32,1,4.000000e+000,7.900238e-003,0.000000e+000,0,,0,
1524689219.917,,0.000000e+000,5.500432e+001,1.146090e-006,0.000000e+000,3,3.559126e-001,0.000000e+000,,,,,,,,,,,,,,32,1,4.000000e+000,1.300812e-003,0.000000e+000,0,,0,
1524689245.097,,0.000000e+000,5.500037e+001,1.753885e-007,0.000000e+000,3,0.000000e+000,0.000000e+000,,,,,,,,,,,,,,32,1,4.000000e+000,1.319885e-003,0.000000e+000,0,,0,
1524689270.317,,0.000000e+000,5.499972e+001,9.217054e-007,0.000000e+000,3,0.000000e+000,0.000000e+000,,,,,,,,,,,,,,32,1,4.000000e+000,5.268097e-003,0.000000e+000,0,,0,
1524689295.547,,0.000000e+000,5.499183e+001,-4.333758e-007,0.000000e+000,3,0.000000e+000,0.000000e+000,,,,,,,,,,,,,,32,1,4.000000e+000,7.888794e-003,0.000000e+000,0,,0,
1524689320.777,,0.000000e+000,5.499577e+001,-2.712935e-007,0.000000e+000,3,0.000000e+000,0.000000e+000,,,,,,,,,,,,,,32,1,4.000000e+000,1.578903e-002,0.000000e+000,0,,0,
1524689347.977,,0.000000e+000,5.499643e+001,3.178957e-007,0.000000e+000,2,0.000000e+000,0.000000e+000,,,,,,,,,,,,,,32,1,4.000000e+000,1.312256e-003,0.000000e+000,0,,0,
1524689373.679,,0.000000e+000,5.499971e+001,1.147068e-007,0.000000e+000,3,0.000000e+000,0.000000e+000,,,,,,,,,,,,,,32,1,4.000000e+000,1.052094e-002,0.000000e+000,0,,0,
1524689399.189,,0.000000e+000,5.499708e+001,9.155962e-007,0.000000e+000,3,2.212340e-001,0.000000e+000,,,,,,,,,,,,,,32,1,4.000000e+000,0.000000e+000,0.000000e+000,0,,0,
1524689428.723,,0.000000e+000,5.499709e+001,3.054199e-007,0.000000e+000,2,0.000000e+000,0.000000e+000,,,,,,,,,,,,,,32,1,4.000000e+000,1.052856e-002,0.000000e+000,0,,0,
1524689458.047,,0.000000e+000,5.499577e+001,2.712881e-007,0.000000e+000,2,0.000000e+000,0.000000e+000,,,,,,,,,,,,,,32,1,4.000000e+000,5.249023e-003,0.000000e+000,0,,0,
1524689486.251,,0.000000e+000,5.499971e+001,2.468445e-007,0.000000e+000,2,0.000000e+000,0.000000e+000,,,,,,,,,,,,,,32,1,4.000000e+000,0.000000e+000,0.000000e+000,0,,0,
1524689512.864,,0.000000e+000,5.499577e+001,3.009026e-007,0.000000e+000,2,0.000000e+000,0.000000e+000,,,,,,,,,,,,,,32,1,4.000000e+000,5.249023e-003,0.000000e+000,0,,0,
1524689540.388,,0.000000e+000,5.499511e+001,2.682720e-007,0.000000e+000,2,0.000000e+000,0.000000e+000,,,,,,,,,,,,,,32,1,4.000000e+000,9.201050e-003,0.000000e+000,0,,0,
1524689568.602,,0.000000e+000,5.499511e+001,2.229937e-007,0.000000e+000,2,0.000000e+000,0.000000e+000,,,,,,,,,,,,,,32,1,4.000000e+000,6.568909e-003,0.000000e+000,0,,0,
1524689596.686,,0.000000e+000,5.499773e+001,2.192974e-007,0.000000e+000,2,0.000000e+000,0.000000e+000,,,,,,,,,,,,,,32,1,4.000000e+000,1.308441e-003,0.000000e+000,0,,0,
1524689621.466,,0.000000e+000,5.499906e+001,-1.858823e-006,0.000000e+000,3,8.241578e-001,0.000000e+000,,,,,,,,,,,,,,32,1,4.000000e+000,9.220123e-003,0.000000e+000,0,,0,
1524689650.740,,0.000000e+000,5.499840e+001,2.325655e-007,0.000000e+000,2,0.000000e+000,0.000000e+000,,,,,,,,,,,,,,32,1,4.000000e+000,7.900238e-003,0.000000e+000,0,,0,
1524689677.562,,0.000000e+000,5.499643e+001,-1.749668e-006,0.000000e+000,3,8.054499e-001,0.000000e+000,,,,,,,,,,,,,,32,1,4.000000e+000,1.312256e-003,0.000000e+000,0,,0,
1524689705.696,,0.000000e+000,5.499248e+001,3.071325e-007,0.000000e+000,2,0.000000e+000,0.000000e+000,,,,,,,,,,,,,,32,1,4.000000e+000,3.940582e-003,0.000000e+000,0,,0,
1524689730.366,,0.000000e+000,5.499511e+001,-1.705624e-006,0.000000e+000,3,8.099674e-001,0.000000e+000,,,,,,,,,,,,,,32,1,4.000000e+000,1.319885e-003,0.000000e+000,0,,0,
1524689757.628,,0.000000e+000,5.499773e+001,4.366736e-008,0.000000e+000,2,0.000000e+000,0.000000e+000,,,,,,,,,,,,,,32,1,4.000000e+000,1.308441e-003,0.000000e+000,0,,0,
1524689782.098,,0.000000e+000,5.500498e+001,-1.791905e-006,0.000000e+000,3,8.317202e-001,0.000000e+000,,,,,,,,,,,,,,32,1,4.000000e+000,5.260468e-003,0.000000e+000,0,,0,
1524689808.620,,0.000000e+000,5.499840e+001,-1.796282e-006,0.000000e+000,3,8.028039e-001,0.000000e+000,,,,,,,,,,,,,,32,1,4.000000e+000,5.260468e-003,0.000000e+000,0,,0,
1524689836.642,,0.000000e+000,5.499840e+001,2.117889e-007,0.000000e+000,2,0.000000e+000,0.000000e+000,,,,,,,,,,,,,,32,1,4.000000e+000,2.628326e-003,0.000000e+000,0,,0,
1524689864.806,,0.000000e+000,5.499774e+001,2.217645e-007,0.000000e+000,2,0.000000e+000,0.000000e+000,,,,,,,,,,,,,,32,1,4.000000e+000,3.940582e-003,0.000000e+000,0,,0,
1524689889.516,,0.000000e+000,5.498919e+001,-1.684238e-006,0.000000e+000,3,8.103329e-001,0.000000e+000,,,,,,,,,,,,,,32,1,4.000000e+000,0.000000e+000,0.000000e+000,0,,0,
1524689915.126,,0.000000e+000,5.498853e+001,-1.417813e-006,0.000000e+000,3,4.030217e-001,0.000000e+000,,,,,,,,,,,,,,32,1,4.000000e+000,1.182938e-002,0.000000e+000,0,,0,
1524689942.178,,0.000000e+000,5.499116e+001,1.788126e-007,0.000000e+000,2,0.000000e+000,0.000000e+000,,,,,,,,,,,,,,32,1,4.000000e+000,1.446152e-002,0.000000e+000,0,,0,
1524689968.900,,0.000000e+000,5.499971e+001,3.605198e-008,0.000000e+000,2,0.000000e+000,0.000000e+000,,,,,,,,,,,,,,32,1,4.000000e+000,2.639771e-003,0.000000e+000,0,,0,
1524689997.174,,0.000000e+000,5.500432e+001,4.274069e-008,0.000000e+000,2,0.000000e+000,0.000000e+000,,,,,,,,,,,,,,32,1,4.000000e+000,3.940582e-003,0.000000e+000,0,,0,
1524690025.568,,0.000000e+000,5.499642e+001,3.677453e-008,0.000000e+000,2,0.000000e+000,0.000000e+000,,,,,,,,,,,,,,32,1,4.000000e+000,3.940582e-003,0.000000e+000,0,,0,
1524690052.180,,0.000000e+000,5.499577e+001,-8.502352e-009,0.000000e+000,2,0.000000e+000,0.000000e+000,,,,,,,,,,,,,,32,1,4.000000e+000,5.249023e-003,0.000000e+000,0,,0,
1524690078.962,,0.000000e+000,5.499314e+001,1.908128e-007,0.000000e+000,2,0.000000e+000,0.000000e+000,,,,,,,,,,,,,,32,1,4.000000e+000,1.578140e-002,0.000000e+000,0,,0,
1524690105.634,,0.000000e+000,5.499708e+001,-1.556072e-006,0.000000e+000,3,8.069025e-001,0.000000e+000,,,,,,,,,,,,,,32,1,4.000000e+000,5.260468e-003,0.000000e+000,0,,0,
1524690130.374,,0.000000e+000,5.499117e+001,7.663768e-007,0.000000e+000,3,0.000000e+000,0.000000e+000,,,,,,,,,,,,,,32,1,4.000000e+000,1.312256e-003,0.000000e+000,0,,0,
1524690158.036,,0.000000e+000,5.499643e+001,9.435526e-007,0.000000e+000,3,1.626279e-001,0.000000e+000,,,,,,,,,,,,,,32,1,4.000000e+000,9.208679e-003,0.000000e+000,0,,0,
1524690183.576,,0.000000e+000,5.499773e+001,-1.628778e-006,0.000000e+000,3,8.039893e-001,0.000000e+000,,,,,,,,,,,,,,32,1,4.000000e+000,1.308441e-003,0.000000e+000,0,,0,
1524690208.966,,0.000000e+000,5.499972e+001,1.002778e-006,0.000000e+000,3,1.673499e-001,0.000000e+000,,,,,,,,,,,,,,32,1,4.000000e+000,5.268097e-003,0.000000e+000,0,,0,
1524690234.207,,0.000000e+000,5.499709e+001,8.719489e-007,0.000000e+000,3,0.000000e+000,0.000000e+000,,,,,,,,,,,,,,32,1,4.000000e+000,1.316071e-002,0.000000e+000,0,,0,
1524690261.219,,0.000000e+000,5.499972e+001,5.286028e-008,0.000000e+000,2,0.000000e+000,0.000000e+000,,,,,,,,,,,,,,32,1,4.000000e+000,5.268097e-003,0.000000e+000,0,,0,
1524690286.049,,0.000000e+000,5.499971e+001,-1.437428e-006,0.000000e+000,3,7.799813e-001,0.000000e+000,,,,,,,,,,,,,,32,1,4.000000e+000,2.639771e-003,0.000000e+000,0,,0,
1524690313.371,,0.000000e+000,5.499577e+001,1.048950e-006,0.000000e+000,3,2.461701e-001,0.000000e+000,,,,,,,,,,,,,,32,1,4.000000e+000,5.249023e-003,0.000000e+000,0,,0,
1524690340.543,,0.000000e+000,5.499642e+001,4.378279e-008,0.000000e+000,2,0.000000e+000,0.000000e+000,,,,,,,,,,,,,,32,1,4.000000e+000,3.940582e-003,0.000000e+000,0,,0,
1524690368.777,,0.000000e+000,5.499248e+001,-3.407536e-008,0.000000e+000,2,0.000000e+000,0.000000e+000,,,,,,,,,,,,,,32,1,4.000000e+000,1.319885e-003,0.000000e+000,0,,0,
1524690396.611,,0.000000e+000,5.499773e+001,-7.544892e-008,0.000000e+000,2,0.000000e+000,0.000000e+000,,,,,,,,,,,,,,32,1,4.000000e+000,1.308441e-003,0.000000e+000,0,,0,
1524690425.585,,0.000000e+000,5.499314e+001,-4.192298e-008,0.000000e+000,2,0.000000e+000,0.000000e+000,,,,,,,,,,,,,,32,1,4.000000e+000,5.260468e-003,0.000000e+000,0,,0,
1524690452.757,,0.000000e+000,5.499643e+001,-4.916453e-008,0.000000e+000,2,0.000000e+000,0.000000e+000,,,,,,,,,,,,,,32,1,4.000000e+000,1.312256e-003,0.000000e+000,0,,0,
1524690477.987,,0.000000e+000,5.500234e+001,1.007696e-006,0.000000e+000,3,9.178724e-002,0.000000e+000,,,,,,,,,,,,,,32,1,4.000000e+000,7.900238e-003,0.000000e+000,0,,0,
1524690507.041,,0.000000e+000,5.499906e+001,-6.674508e-008,0.000000e+000,2,0.000000e+000,0.000000e+000,,,,,,,,,,,,,,32,1,4.000000e+000,6.580353e-003,0.000000e+000,0,,0,
1524690531.321,,0.000000e+000,5.499708e+001,1.015367e-006,0.000000e+000,3,1.354293e-001,0.000000e+000,,,,,,,,,,,,,,32,1,4.000000e+000,0.000000e+000,0.000000e+000,0,,0,
1524690558.073,,0.000000e+000,5.499840e+001,1.177455e-006,0.000000e+000,3,2.546499e-001,0.000000e+000,,,,,,,,,,,,,,32,1,4.000000e+000,5.260468e-003,0.000000e+000,0,,0,
1524690586.617,,0.000000e+000,5.500169e+001,-3.951999e-008,0.000000e+000,2,0.000000e+000,0.000000e+000,,,,,,,,,,,,,,32,1,4.000000e+000,3.959656e-003,0.000000e+000,0,,0,
1524690612.227,,0.000000e+000,5.499971e+001,1.174152e-006,0.000000e+000,3,2.682086e-001,0.000000e+000,,,,,,,,,,,,,,32,1,4.000000e+000,2.639771e-003,0.000000e+000,0,,0,
1524690638.329,,0.000000e+000,5.499577e+001,1.003545e-006,0.000000e+000,3,4.446090e-002,0.000000e+000,,,,,,,,,,,,,,32,1,4.000000e+000,5.249023e-003,0.000000e+000,0,,0,
1524690663.849,,0.000000e+000,5.500169e+001,9.891190e-007,0.000000e+000,3,1.817464e-002,0.000000e+000,,,,,,,,,,,,,,32,1,4.000000e+000,3.959656e-003,0.000000e+000,0,,0,
1524690690.951,,0.000000e+000,5.499840e+001,-9.840222e-009,0.000000e+000,2,0.000000e+000,0.000000e+000,,,,,,,,,,,,,,32,1,4.000000e+000,2.628326e-003,0.000000e+000,0,,0,
1524690718.133,,0.000000e+000,5.499905e+001,9.716190e-007,0.000000e+000,3,0.000000e+000,0.000000e+000,,,,,,,,,,,,,,32,1,4.000000e+000,1.319885e-003,0.000000e+000,0,,0,
1524690745.965,,0.000000e+000,5.499511e+001,-5.824517e-008,0.000000e+000,2,0.000000e+000,0.000000e+000,,,,,,,,,,,,,,32,1,4.000000e+000,1.319885e-003,0.000000e+000,0,,0,
1524690772.757,,0.000000e+000,5.500168e+001,1.074173e-006,0.000000e+000,3,1.027818e-001,0.000000e+000,,,,,,,,,,,,,,32,1,4.000000e+000,6.580353e-003,0.000000e+000,0,,0,
1524690798.007,,0.000000e+000,5.500037e+001,1.026103e-006,0.000000e+000,3,1.435326e-001,0.000000e+000,,,,,,,,,,,,,,32,1,4.000000e+000,1.319885e-003,0.000000e+000,0,,0,
1524690825.129,,0.000000e+000,5.499577e+001,-5.145073e-008,0.000000e+000,2,0.000000e+000,0.000000e+000,,,,,,,,,,,,,,32,1,4.000000e+000,2.632141e-003,0.000000e+000,0,,0,
1524690850.861,,0.000000e+000,5.499511e+001,1.210088e-006,0.000000e+000,3,2.506453e-001,0.000000e+000,,,,,,,,,,,,,,32,1,4.000000e+000,1.319885e-003,0.000000e+000,0,,0,
1524690877.413,,0.000000e+000,5.499971e+001,9.989118e-007,0.000000e+000,3,1.783478e-002,0.000000e+000,,,,,,,,,,,,,,32,1,4.000000e+000,0.000000e+000,0.000000e+000,0,,0,
1524690902.703,,0.000000e+000,5.499905e+001,1.008837e-006,0.000000e+000,3,1.090982e-001,0.000000e+000,,,,,,,,,,,,,,32,1,4.000000e+000,1.319885e-003,0.000000e+000,0,,0,
1524690927.973,,0.000000e+000,5.499905e+001,1.016861e-006,0.000000e+000,3,1.540536e-001,0.000000e+000,,,,,,,,,,,,,,32,1,4.000000e+000,1.319885e-003,0.000000e+000,0,,0,
1524690955.116,,0.000000e+000,5.499511e+001,-5.842557e-008,0.000000e+000,2,0.000000e+000,0.000000e+000,,,,,,,,,,,,,,32,1,4.000000e+000,3.940582e-003,0.000000e+000,0,,0,
1524690979.686,,0.000000e+000,5.499248e+001,1.092937e-006,0.000000e+000,3,2.464005e-001,0.000000e+000,,,,,,,,,,,,,,32,1,4.000000e+000,1.182938e-002,0.000000e+000,0,,0,
1524691004.986,,0.000000e+000,5.499642e+001,1.064040e-006,0.000000e+000,3,1.122034e-001,0.000000e+000,,,,,,,,,,,,,,32,1,4.000000e+000,3.940582e-003,0.000000e+000,0,,0,
1524691032.218,,0.000000e+000,5.499642e+001,-6.630411e-008,0.000000e+000,2,0.000000e+000,0.000000e+000,,,,,,,,,,,,,,32,1,4.000000e+000,3.940582e-003,0.000000e+000,0,,0,
1524691056.698,,0.000000e+000,5.499971e+001,1.039276e-006,0.000000e+000,3,1.524512e-001,0.000000e+000,,,,,,,,,,,,,,32,1,4.000000e+000,2.639771e-003,0.000000e+000,0,,0,
1524691081.828,,0.000000e+000,5.499117e+001,8.683995e-007,0.000000e+000,3,5.763215e-002,0.000000e+000,,,,,,,,,,,,,,32,1,4.000000e+000,1.312256e-003,0.000000e+000,0,,0,
1524691108.370,,0.000000e+000,5.499248e+001,1.026878e-006,0.000000e+000,3,1.344337e-001,0.000000e+000,,,,,,,,,,,,,,32,1,4.000000e+000,1.710129e-002,0.000000e+000,0,,0,
1524691133.640,,0.000000e+000,5.499971e+001,9.941119e-007,0.000000e+000,3,1.660156e-001,0.000000e+000,,,,,,,,,,,,,,32,1,4.000000e+000,0.000000e+000,0.000000e+000,0,,0,
1524691158.850,,0.000000e+000,5.499906e+001,1.041002e-006,0.000000e+000,3,1.793111e-001,0.000000e+000,,,,,,,,,,,,,,32,1,4.000000e+000,6.580353e-003,0.000000e+000,0,,0,
1524691184.070,,0.000000e+000,5.499840e+001,1.066941e-006,0.000000e+000,3,1.742881e-001,0.000000e+000,,,,,,,,,,,,,,32,1,4.000000e+000,2.628326e-003,0.000000e+000,0,,0,
1524691209.280,,0.000000e+000,5.499774e+001,1.091616e-006,0.000000e+000,3,2.037173e-001,0.000000e+000,,,,,,,,,,,,,,32,1,4.000000e+000,6.580353e-003,0.000000e+000,0,,0,
1524691234.500,,0.000000e+000,5.500169e+001,1.107437e-006,0.000000e+000,3,2.042113e-001,0.000000e+000,,,,,,,,,,,,,,32,1,4.000000e+000,9.208679e-003,0.000000e+000,0,,0,
1524691259.730,,0.000000e+000,5.500300e+001,1.079871e-006,0.000000e+000,3,2.052882e-001,0.000000e+000,,,,,,,,,,,,,,32,1,4.000000e+000,3.940582e-003,0.000000e+000,0,,0,
1524691284.970,,0.000000e+000,5.500103e+001,9.894434e-007,0.000000e+000,3,1.026265e-001,0.000000e+000,,,,,,,,,,,,,,32,1,4.000000e+000,0.000000e+000,0.000000e+000,0,,0,
1524691310.160,,0.000000e+000,5.500235e+001,1.064595e-006,0.000000e+000,3,1.849826e-001,0.000000e+000,,,,,,,,,,,,,,32,1,4.000000e+000,2.639771e-003,0.000000e+000,0,,0,
1524691335.410,,0.000000e+000,5.500037e+001,1.060343e-006,0.000000e+000,3,2.020869e-001,0.000000e+000,,,,,,,,,,,,,,32,1,4.000000e+000,6.587982e-003,0.000000e+000,0,,0,
1524691360.600,,0.000000e+000,5.499708e+001,1.060093e-006,0.000000e+000,3,1.466947e-001,0.000000e+000,,,,,,,,,,,,,,32,1,4.000000e+000,0.000000e+000,0.000000e+000,0,,0,
1524691385.810,,0.000000e+000,5.499839e+001,1.096280e-006,0.000000e+000,3,2.056278e-001,0.000000e+000,,,,,,,,,,,,,,32,1,4.000000e+000,0.000000e+000,0.000000e+000,0,,0,
1524691411.050,,0.000000e+000,5.499774e+001,1.076135e-006,0.000000e+000,3,1.839872e-001,0.000000e+000,,,,,,,,,,,,,,32,1,4.000000e+000,3.940582e-003,0.000000e+000,0,,0,
1524691436.230,,0.000000e+000,5.499643e+001,1.132343e-006,0.000000e+000,3,2.039779e-001,0.000000e+000,,,,,,,,,,,,,,32,1,4.000000e+000,1.312256e-003,0.000000e+000,0,,0,
1524691461.480,,0.000000e+000,5.499971e+001,1.121285e-006,0.000000e+000,3,2.349054e-001,0.000000e+000,,,,,,,,,,,,,,32,1,4.000000e+000,2.639771e-003,0.000000e+000,0,,0,
1524691486.690,,0.000000e+000,5.499840e+001,1.087957e-006,0.000000e+000,3,1.815450e-001,0.000000e+000,,,,,,,,,,,,,,32,1,4.000000e+000,2.628326e-003,0.000000e+000,0,,0,
1524691511.860,,0.000000e+000,5.499774e+001,1.095917e-006,0.000000e+000,3,1.854535e-001,0.000000e+000,,,,,,,,,,,,,,32,1,4.000000e+000,3.940582e-003,0.000000e+000,0,,0,
1524691536.720,,0.000000e+000,5.500037e+001,1.062030e-006,0.000000e+000,3,2.482689e-001,0.000000e+000,,,,,,,,,,,,,,32,1,4.000000e+000,6.587982e-003,0.000000e+000,0,,0,
1524691561.750,,0.000000e+000,5.499577e+001,1.043732e-006,0.000000e+000,3,1.471725e-001,0.000000e+000,,,,,,,,,,,,,,32,1,4.000000e+000,1.052094e-002,0.000000e+000,0,,0,
1524691586.420,,0.000000e+000,5.499708e+001,1.056841e-006,0.000000e+000,3,2.370837e-001,0.000000e+000,,,,,,,,,,,,,,32,1,4.000000e+000,0.000000e+000,0.000000e+000,0,,0,
1524691611.650,,0.000000e+000,5.499840e+001,1.098049e-006,0.000000e+000,3,1.636663e-001,0.000000e+000,,,,,,,,,,,,,,32,1,4.000000e+000,2.628326e-003,0.000000e+000,0,,0,
1524691636.880,,0.000000e+000,5.500169e+001,1.109000e-006,0.000000e+000,3,2.139444e-001,0.000000e+000,,,,,,,,,,,,,,32,1,4.000000e+000,1.319885e-003,0.000000e+000,0,,0,
1524691662.001,,0.000000e+000,5.499445e+001,1.098131e-006,0.000000e+000,3,2.281145e-001,0.000000e+000,,,,,,,,,,,,,,32,1,4.000000e+000,2.628326e-003,0.000000e+000,0,,0,
1524691687.311,,0.000000e+000,5.499445e+001,1.069557e-006,0.000000e+000,3,1.434530e-001,0.000000e+000,,,,,,,,,,,,,,32,1,4.000000e+000,2.628326e-003,0.000000e+000,0,,0,
1524691711.941,,0.000000e+000,5.499642e+001,1.076902e-006,0.000000e+000,3,2.614401e-001,0.000000e+000,,,,,,,,,,,,,,32,1,4.000000e+000,3.940582e-003,0.000000e+000,0,,0,
1524691737.231,,0.000000e+000,5.500037e+001,1.032994e-006,0.000000e+000,3,2.105068e-001,0.000000e+000,,,,,,,,,,,,,,32,1,4.000000e+000,1.319885e-003,0.000000e+000,0,,0,
1524691762.431,,0.000000e+000,5.500366e+001,1.027271e-006,0.000000e+000,3,1.718245e-001,0.000000e+000,,,,,,,,,,,,,,32,1,4.000000e+000,1.578140e-002,0.000000e+000,0,,0,
1524691789.641,,0.000000e+000,5.499971e+001,-2.740510e-007,0.000000e+000,2,0.000000e+000,0.000000e+000,,,,,,,,,,,,,,32,1,4.000000e+000,2.639771e-003,0.000000e+000,0,,0,
1524691818.325,,0.000000e+000,5.499643e+001,-2.517179e-007,0.000000e+000,2,0.000000e+000,0.000000e+000,,,,,,,,,,,,,,32,1,4.000000e+000,1.312256e-003,0.000000e+000,0,,0,
1524691843.015,,0.000000e+000,5.499708e+001,1.088829e-006,0.000000e+000,3,2.117017e-001,0.000000e+000,,,,,,,,,,,,,,32,1,4.000000e+000,5.260468e-003,0.000000e+000,0,,0,
1524691868.215,,0.000000e+000,5.499708e+001,1.122957e-006,0.000000e+000,3,2.629986e-001,0.000000e+000,,,,,,,,,,,,,,32,1,4.000000e+000,5.260468e-003,0.000000e+000,0,,0,
1524691893.325,,0.000000e+000,5.500169e+001,1.046518e-006,0.000000e+000,3,1.254243e-001,0.000000e+000,,,,,,,,,,,,,,32,1,4.000000e+000,1.319885e-003,0.000000e+000,0,,0,
1524691922.319,,0.000000e+000,5.499380e+001,-2.644129e-007,0.000000e+000,2,0.000000e+000,0.000000e+000,,,,,,,,,,,,,,32,1,4.000000e+000,3.948212e-003,0.000000e+000,0,,0,
1524691948.621,,0.000000e+000,5.499840e+001,1.019463e-006,0.000000e+000,3,1.163769e-001,0.000000e+000,,,,,,,,,,,,,,32,1,4.000000e+000,2.628326e-003,0.000000e+000,0,,0,
1524691976.965,,0.000000e+000,5.499577e+001,-2.909970e-007,0.000000e+000,2,0.000000e+000,0.000000e+000,,,,,,,,,,,,,,32,1,4.000000e+000,2.632141e-003,0.000000e+000,0,,0,
1524692005.309,,0.000000e+000,5.499906e+001,-2.824321e-007,0.000000e+000,2,0.000000e+000,0.000000e+000,,,,,,,,,,,,,,32,1,4.000000e+000,6.580353e-003,0.000000e+000,0,,0,
1524692033.573,,0.000000e+000,5.500234e+001,-2.715574e-007,0.000000e+000,2,0.000000e+000,0.000000e+000,,,,,,,,,,,,,,32,1,4.000000e+000,1.314926e-002,0.000000e+000,0,,0,
1524692062.107,,0.000000e+000,5.499511e+001,-3.541312e-007,0.000000e+000,2,0.000000e+000,0.000000e+000,,,,,,,,,,,,,,32,1,4.000000e+000,3.940582e-003,0.000000e+000,0,,0,
1524692090.191,,0.000000e+000,5.499248e+001,-2.951288e-007,0.000000e+000,2,0.000000e+000,0.000000e+000,,,,,,,,,,,,,,32,1,4.000000e+000,3.940582e-003,0.000000e+000,0,,0,
1524692116.953,,0.000000e+000,5.499380e+001,1.182124e-006,0.000000e+000,3,1.942544e-001,0.000000e+000,,,,,,,,,,,,,,32,1,4.000000e+000,1.308441e-003,0.000000e+000,0,,0,
1524692142.755,,0.000000e+000,5.499577e+001,1.014416e-006,0.000000e+000,3,7.219029e-002,0.000000e+000,,,,,,,,,,,,,,32,1,4.000000e+000,7.888794e-003,0.000000e+000,0,,0,
1524692171.479,,0.000000e+000,5.500103e+001,-3.460531e-007,0.000000e+000,2,0.000000e+000,0.000000e+000,,,,,,,,,,,,,,32,1,4.000000e+000,5.279541e-003,0.000000e+000,0,,0,
1524692200.533,,0.000000e+000,5.499773e+001,-3.480424e-007,0.000000e+000,2,0.000000e+000,0.000000e+000,,,,,,,,,,,,,,32,1,4.000000e+000,1.308441e-003,0.000000e+000,0,,0,
1524692228.577,,0.000000e+000,5.500037e+001,-2.804231e-007,0.000000e+000,2,0.000000e+000,0.000000e+000,,,,,,,,,,,,,,32,1,4.000000e+000,3.959656e-003,0.000000e+000,0,,0,
1524692257.081,,0.000000e+000,5.500169e+001,-3.312891e-007,0.000000e+000,2,0.000000e+000,0.000000e+000,,,,,,,,,,,,,,32,1,4.000000e+000,1.319885e-003,0.000000e+000,0,,0,
1524692271.463,,0.000000e+000,5.499905e+001,-3.478965e-007,0.000000e+000,2,0.000000e+000,0.000000e+000,,,,,,,,,,,,,,32,1,4.000000e+000,1.319885e-003,0.000000e+000,0,,0,