File: Experimental Raw Data/MFn1 TRM linear/MFn1_TRMac_37K_0.04Kmin_VRMde_35K.dc.dat
[Header]
TITLE,MPMS DC Measurement
BYAPP,MPMS Measurement,2.1,Summary
FILEOPENTIME, 1524388844.895000 4/22/2018, 3:20:44 AM

INFO, APPNAME, MPMS MultiVu Application, Revision 1.61,  Build 082

INFO, NAME, MFn1
INFO, WEIGHT, 1.000
INFO, AREA, 1.000
INFO, LENGTH, 1.000
INFO, SHAPE, 0
INFO, COMMENT,
INFO, SEQUENCE FILE: TRMac_37K_0.04Kmin_VRMde_35K.seq


INFO, BACKGROUND DATA FILE:, None


STARTUPAXIS,X,4,LINEAR,AUTO,0.000000,0.000000
STARTUPAXIS,Y1,5,LINEAR,AUTO,0.000000,0.000000


STARTUPGROUP,Longitudinal
FIELDGROUP,Longitudinal,1,2,3,4,5,6,7,8,9,15,16,17,18,27,28
FIELDGROUP,Transverse,1,2,3,4,10,11,12,13,14,19,20,21,22,27,28

PLOT_APPEARANCE,ALL,HORZ_GRID_ON,VERT_GRID_ON,MARKERS_AND_LINES

[Data]
Time,Comment,Field (Oe),Temperature (K),Long Moment (emu),Long Scan Std Dev,Long Algorithm,Long Reg Fit,Long Percent Error (%),Trans Moment (emu),Trans Scan Std Dev,Trans Algorithm,Trans Reg Fit,Trans Percent Error (%),Long Moment [w/o ABS] (emu),Long Scan Std Dev [w/o ABS],Long Reg Fit [w/o ABS],Long Percent Error [w/o ABS] (%),Trans Moment [w/o ABS] (emu),Trans Scan Std Dev [w/o ABS],Trans Reg Fit [w/o ABS],Trans Percent Error [w/o ABS] (%),Points per Scan,Scans per Measurement,Scan Length (cm),Delta Temp (K),Rot Position (deg),Error,EC Comp. Running,Using ABS,
1524388844.892,,0.000000e+000,3.499480e+001,-2.808512e-005,0.000000e+000,2,9.712227e-001,0.000000e+000,,,,,,,,,,,,,,32,1,4.000000e+000,4.692078e-003,0.000000e+000,0,,0,
1524388882.935,,0.000000e+000,3.499793e+001,-2.640540e-005,0.000000e+000,2,9.704720e-001,0.000000e+000,,,,,,,,,,,,,,32,1,4.000000e+000,1.567841e-003,0.000000e+000,0,,0,
1524388920.833,,0.000000e+000,3.499833e+001,-2.518063e-005,0.000000e+000,2,9.674642e-001,0.000000e+000,,,,,,,,,,,,,,32,1,4.000000e+000,7.781982e-004,0.000000e+000,0,,0,
1524388959.009,,0.000000e+000,3.499872e+001,-2.414550e-005,0.000000e+000,2,9.658993e-001,0.000000e+000,,,,,,,,,,,,,,32,1,4.000000e+000,0.000000e+000,0.000000e+000,0,,0,
1524388997.062,,0.000000e+000,3.499911e+001,-2.330777e-005,0.000000e+000,2,9.649498e-001,0.000000e+000,,,,,,,,,,,,,,32,1,4.000000e+000,7.820129e-004,0.000000e+000,0,,0,
1524389035.207,,0.000000e+000,3.499559e+001,-2.257253e-005,0.000000e+000,2,9.622270e-001,0.000000e+000,,,,,,,,,,,,,,32,1,4.000000e+000,6.259918e-003,0.000000e+000,0,,0,
1524389072.673,,0.000000e+000,3.499754e+001,-2.197885e-005,0.000000e+000,2,9.625616e-001,0.000000e+000,,,,,,,,,,,,,,32,1,4.000000e+000,7.896423e-004,0.000000e+000,0,,0,
1524389110.739,,0.000000e+000,3.499911e+001,-2.137603e-005,0.000000e+000,2,9.613222e-001,0.000000e+000,,,,,,,,,,,,,,32,1,4.000000e+000,7.820129e-004,0.000000e+000,0,,0,
1524389148.949,,0.000000e+000,3.499911e+001,-2.094951e-005,0.000000e+000,2,9.585059e-001,0.000000e+000,,,,,,,,,,,,,,32,1,4.000000e+000,2.338409e-003,0.000000e+000,0,,0,
1524389187.175,,0.000000e+000,3.499793e+001,-2.051835e-005,0.000000e+000,2,9.601863e-001,0.000000e+000,,,,,,,,,,,,,,32,1,4.000000e+000,1.567841e-003,0.000000e+000,0,,0,
1524389224.850,,0.000000e+000,3.499715e+001,-2.011686e-005,0.000000e+000,2,9.592580e-001,0.000000e+000,,,,,,,,,,,,,,32,1,4.000000e+000,3.128052e-003,0.000000e+000,0,,0,
1524389263.361,,0.000000e+000,3.499833e+001,-1.977055e-005,0.000000e+000,2,9.579671e-001,0.000000e+000,,,,,,,,,,,,,,32,1,4.000000e+000,7.781982e-004,0.000000e+000,0,,0,
1524389301.416,,0.000000e+000,3.499833e+001,-1.937257e-005,0.000000e+000,2,9.570479e-001,0.000000e+000,,,,,,,,,,,,,,32,1,4.000000e+000,2.349854e-003,0.000000e+000,0,,0,
1524389338.904,,0.000000e+000,3.499872e+001,-1.908098e-005,0.000000e+000,2,9.570143e-001,0.000000e+000,,,,,,,,,,,,,,32,1,4.000000e+000,0.000000e+000,0.000000e+000,0,,0,
1524389376.485,,0.000000e+000,3.499833e+001,-1.880887e-005,0.000000e+000,2,9.570580e-001,0.000000e+000,,,,,,,,,,,,,,32,1,4.000000e+000,7.781982e-004,0.000000e+000,0,,0,
1524389413.651,,0.000000e+000,3.499872e+001,-1.852044e-005,0.000000e+000,2,9.562253e-001,0.000000e+000,,,,,,,,,,,,,,32,1,4.000000e+000,0.000000e+000,0.000000e+000,0,,0,
1524389451.681,,0.000000e+000,3.499872e+001,-1.824741e-005,0.000000e+000,2,9.549994e-001,0.000000e+000,,,,,,,,,,,,,,32,1,4.000000e+000,0.000000e+000,0.000000e+000,0,,0,
1524389489.774,,0.000000e+000,3.499833e+001,-1.799191e-005,0.000000e+000,2,9.553515e-001,0.000000e+000,,,,,,,,,,,,,,32,1,4.000000e+000,7.781982e-004,0.000000e+000,0,,0,
1524389527.807,,0.000000e+000,3.499833e+001,-1.772493e-005,0.000000e+000,2,9.551436e-001,0.000000e+000,,,,,,,,,,,,,,32,1,4.000000e+000,7.781982e-004,0.000000e+000,0,,0,
1524389565.893,,0.000000e+000,3.499911e+001,-1.754884e-005,0.000000e+000,2,9.523975e-001,0.000000e+000,,,,,,,,,,,,,,32,1,4.000000e+000,7.820129e-004,0.000000e+000,0,,0,
1524389603.781,,0.000000e+000,3.499833e+001,-1.731453e-005,0.000000e+000,2,9.554140e-001,0.000000e+000,,,,,,,,,,,,,,32,1,4.000000e+000,7.781982e-004,0.000000e+000,0,,0,
1524389641.971,,0.000000e+000,3.499911e+001,-1.711895e-005,0.000000e+000,2,9.524797e-001,0.000000e+000,,,,,,,,,,,,,,32,1,4.000000e+000,7.820129e-004,0.000000e+000,0,,0,
1524389680.440,,0.000000e+000,3.499872e+001,-1.687075e-005,0.000000e+000,2,9.519076e-001,0.000000e+000,,,,,,,,,,,,,,32,1,4.000000e+000,1.560211e-003,0.000000e+000,0,,0,
1524389718.485,,0.000000e+000,3.499989e+001,-1.667512e-005,0.000000e+000,2,9.507267e-001,0.000000e+000,,,,,,,,,,,,,,32,1,4.000000e+000,7.781982e-004,0.000000e+000,0,,0,
1524389756.433,,0.000000e+000,3.500028e+001,-1.649828e-005,0.000000e+000,2,9.508926e-001,0.000000e+000,,,,,,,,,,,,,,32,1,4.000000e+000,3.120422e-003,0.000000e+000,0,,0,
1524389793.934,,0.000000e+000,3.499754e+001,-1.633217e-005,0.000000e+000,2,9.503710e-001,0.000000e+000,,,,,,,,,,,,,,32,1,4.000000e+000,7.896423e-004,0.000000e+000,0,,0,
1524389831.782,,0.000000e+000,3.499833e+001,-1.615782e-005,0.000000e+000,2,9.514007e-001,0.000000e+000,,,,,,,,,,,,,,32,1,4.000000e+000,7.781982e-004,0.000000e+000,0,,0,
1524389869.970,,0.000000e+000,3.499833e+001,-1.599658e-005,0.000000e+000,2,9.492853e-001,0.000000e+000,,,,,,,,,,,,,,32,1,4.000000e+000,2.349854e-003,0.000000e+000,0,,0,
1524389908.120,,0.000000e+000,3.499911e+001,-1.582912e-005,0.000000e+000,2,9.502894e-001,0.000000e+000,,,,,,,,,,,,,,32,1,4.000000e+000,7.820129e-004,0.000000e+000,0,,0,
1524389946.186,,0.000000e+000,3.499950e+001,-1.566364e-005,0.000000e+000,2,9.481164e-001,0.000000e+000,,,,,,,,,,,,,,32,1,4.000000e+000,3.120422e-003,0.000000e+000,0,,0,
1524389983.764,,0.000000e+000,3.499989e+001,-1.556477e-005,0.000000e+000,2,9.482141e-001,0.000000e+000,,,,,,,,,,,,,,32,1,4.000000e+000,2.342224e-003,0.000000e+000,0,,0,
1524390022.107,,0.000000e+000,3.499950e+001,-1.539015e-005,0.000000e+000,2,9.482248e-001,0.000000e+000,,,,,,,,,,,,,,32,1,4.000000e+000,1.560211e-003,0.000000e+000,0,,0,
1524390059.253,,0.000000e+000,3.499950e+001,-1.527839e-005,0.000000e+000,2,9.463919e-001,0.000000e+000,,,,,,,,,,,,,,32,1,4.000000e+000,0.000000e+000,0.000000e+000,0,,0,
1524390097.421,,0.000000e+000,3.499872e+001,-1.509086e-005,0.000000e+000,2,9.462764e-001,0.000000e+000,,,,,,,,,,,,,,32,1,4.000000e+000,0.000000e+000,0.000000e+000,0,,0,
1524390135.489,,0.000000e+000,3.499911e+001,-1.493020e-005,0.000000e+000,2,9.449098e-001,0.000000e+000,,,,,,,,,,,,,,32,1,4.000000e+000,7.820129e-004,0.000000e+000,0,,0,
1524390173.377,,0.000000e+000,3.499793e+001,-1.485140e-005,0.000000e+000,2,9.452496e-001,0.000000e+000,,,,,,,,,,,,,,32,1,4.000000e+000,1.567841e-003,0.000000e+000,0,,0,
1524390211.602,,0.000000e+000,3.499911e+001,-1.476613e-005,0.000000e+000,2,9.456747e-001,0.000000e+000,,,,,,,,,,,,,,32,1,4.000000e+000,7.820129e-004,0.000000e+000,0,,0,
1524390249.708,,0.000000e+000,3.499989e+001,-1.462009e-005,0.000000e+000,2,9.444413e-001,0.000000e+000,,,,,,,,,,,,,,32,1,4.000000e+000,7.781982e-004,0.000000e+000,0,,0,
1524390287.861,,0.000000e+000,3.499872e+001,-1.447634e-005,0.000000e+000,2,9.451789e-001,0.000000e+000,,,,,,,,,,,,,,32,1,4.000000e+000,1.560211e-003,0.000000e+000,0,,0,
1524390326.079,,0.000000e+000,3.499794e+001,-1.435171e-005,0.000000e+000,2,9.467316e-001,0.000000e+000,,,,,,,,,,,,,,32,1,4.000000e+000,0.000000e+000,0.000000e+000,0,,0,
1524390363.510,,0.000000e+000,3.499911e+001,-1.424316e-005,0.000000e+000,2,9.433234e-001,0.000000e+000,,,,,,,,,,,,,,32,1,4.000000e+000,7.820129e-004,0.000000e+000,0,,0,
1524390401.725,,0.000000e+000,3.499950e+001,-1.412811e-005,0.000000e+000,2,9.445118e-001,0.000000e+000,,,,,,,,,,,,,,32,1,4.000000e+000,3.120422e-003,0.000000e+000,0,,0,
1524390439.326,,0.000000e+000,3.499872e+001,-1.408250e-005,0.000000e+000,2,9.448820e-001,0.000000e+000,,,,,,,,,,,,,,32,1,4.000000e+000,1.560211e-003,0.000000e+000,0,,0,
1524390477.389,,0.000000e+000,3.499754e+001,-1.394888e-005,0.000000e+000,2,9.439400e-001,0.000000e+000,,,,,,,,,,,,,,32,1,4.000000e+000,7.896423e-004,0.000000e+000,0,,0,
1524390515.477,,0.000000e+000,3.499833e+001,-1.384279e-005,0.000000e+000,2,9.446217e-001,0.000000e+000,,,,,,,,,,,,,,32,1,4.000000e+000,7.781982e-004,0.000000e+000,0,,0,
1524390553.560,,0.000000e+000,3.499989e+001,-1.376207e-005,0.000000e+000,2,9.429671e-001,0.000000e+000,,,,,,,,,,,,,,32,1,4.000000e+000,7.781982e-004,0.000000e+000,0,,0,
1524390591.378,,0.000000e+000,3.499911e+001,-1.366718e-005,0.000000e+000,2,9.437227e-001,0.000000e+000,,,,,,,,,,,,,,32,1,4.000000e+000,3.910065e-003,0.000000e+000,0,,0,
1524390628.883,,0.000000e+000,3.499793e+001,-1.357272e-005,0.000000e+000,2,9.419798e-001,0.000000e+000,,,,,,,,,,,,,,32,1,4.000000e+000,4.688263e-003,0.000000e+000,0,,0,
1524390667.011,,0.000000e+000,3.499833e+001,-1.344930e-005,0.000000e+000,2,9.407913e-001,0.000000e+000,,,,,,,,,,,,,,32,1,4.000000e+000,7.781982e-004,0.000000e+000,0,,0,
1524390705.027,,0.000000e+000,3.499911e+001,-1.335979e-005,0.000000e+000,2,9.408029e-001,0.000000e+000,,,,,,,,,,,,,,32,1,4.000000e+000,7.820129e-004,0.000000e+000,0,,0,
1524390743.128,,0.000000e+000,3.499793e+001,-1.325344e-005,0.000000e+000,2,9.398468e-001,0.000000e+000,,,,,,,,,,,,,,32,1,4.000000e+000,3.131866e-003,0.000000e+000,0,,0,
1524390781.208,,0.000000e+000,3.499833e+001,-1.316077e-005,0.000000e+000,2,9.397358e-001,0.000000e+000,,,,,,,,,,,,,,32,1,4.000000e+000,7.781982e-004,0.000000e+000,0,,0,
1524390819.276,,0.000000e+000,3.499715e+001,-1.311044e-005,0.000000e+000,2,9.397542e-001,0.000000e+000,,,,,,,,,,,,,,32,1,4.000000e+000,0.000000e+000,0.000000e+000,0,,0,
1524390857.897,,0.000000e+000,3.499872e+001,-1.303032e-005,0.000000e+000,2,9.395453e-001,0.000000e+000,,,,,,,,,,,,,,32,1,4.000000e+000,1.560211e-003,0.000000e+000,0,,0,
1524390895.395,,0.000000e+000,3.499989e+001,-1.294314e-005,0.000000e+000,2,9.382691e-001,0.000000e+000,,,,,,,,,,,,,,32,1,4.000000e+000,2.342224e-003,0.000000e+000,0,,0,
1524390933.438,,0.000000e+000,3.499911e+001,-1.280751e-005,0.000000e+000,2,9.390581e-001,0.000000e+000,,,,,,,,,,,,,,32,1,4.000000e+000,7.820129e-004,0.000000e+000,0,,0,
1524390971.201,,0.000000e+000,3.499637e+001,-1.279332e-005,0.000000e+000,2,9.369320e-001,0.000000e+000,,,,,,,,,,,,,,32,1,4.000000e+000,0.000000e+000,0.000000e+000,0,,0,
1524391009.089,,0.000000e+000,3.499833e+001,-1.269451e-005,0.000000e+000,2,9.389662e-001,0.000000e+000,,,,,,,,,,,,,,32,1,4.000000e+000,7.781982e-004,0.000000e+000,0,,0,
1524391046.925,,0.000000e+000,3.499872e+001,-1.257672e-005,0.000000e+000,2,9.350860e-001,0.000000e+000,,,,,,,,,,,,,,32,1,4.000000e+000,0.000000e+000,0.000000e+000,0,,0,
1524391083.803,,0.000000e+000,3.499872e+001,-1.250803e-005,0.000000e+000,2,9.379461e-001,0.000000e+000,,,,,,,,,,,,,,32,1,4.000000e+000,1.560211e-003,0.000000e+000,0,,0,
1524391122.768,,0.000000e+000,3.499872e+001,-1.240598e-005,0.000000e+000,2,9.371634e-001,0.000000e+000,,,,,,,,,,,,,,32,1,4.000000e+000,0.000000e+000,0.000000e+000,0,,0,
1524391161.399,,0.000000e+000,3.499872e+001,-1.233987e-005,0.000000e+000,2,9.364614e-001,0.000000e+000,,,,,,,,,,,,,,32,1,4.000000e+000,0.000000e+000,0.000000e+000,0,,0,
1524391198.147,,0.000000e+000,3.499872e+001,-1.229370e-005,0.000000e+000,2,9.346607e-001,0.000000e+000,,,,,,,,,,,,,,32,1,4.000000e+000,1.560211e-003,0.000000e+000,0,,0,
1524391236.422,,0.000000e+000,3.499833e+001,-1.224700e-005,0.000000e+000,2,9.360200e-001,0.000000e+000,,,,,,,,,,,,,,32,1,4.000000e+000,7.781982e-004,0.000000e+000,0,,0,
1524391274.203,,0.000000e+000,3.499833e+001,-1.213945e-005,0.000000e+000,2,9.341656e-001,0.000000e+000,,,,,,,,,,,,,,32,1,4.000000e+000,7.781982e-004,0.000000e+000,0,,0,
1524391312.098,,0.000000e+000,3.499715e+001,-1.204287e-005,0.000000e+000,2,9.339890e-001,0.000000e+000,,,,,,,,,,,,,,32,1,4.000000e+000,3.128052e-003,0.000000e+000,0,,0,
1524391349.284,,0.000000e+000,3.500028e+001,-1.199105e-005,0.000000e+000,2,9.356111e-001,0.000000e+000,,,,,,,,,,,,,,32,1,4.000000e+000,3.120422e-003,0.000000e+000,0,,0,
1524391386.917,,0.000000e+000,3.499754e+001,-1.194062e-005,0.000000e+000,2,9.334137e-001,0.000000e+000,,,,,,,,,,,,,,32,1,4.000000e+000,2.349854e-003,0.000000e+000,0,,0,
1524391424.988,,0.000000e+000,3.499950e+001,-1.186948e-005,0.000000e+000,2,9.357610e-001,0.000000e+000,,,,,,,,,,,,,,32,1,4.000000e+000,1.560211e-003,0.000000e+000,0,,0,
1524391463.456,,0.000000e+000,3.499794e+001,-1.181590e-005,0.000000e+000,2,9.352023e-001,0.000000e+000,,,,,,,,,,,,,,32,1,4.000000e+000,0.000000e+000,0.000000e+000,0,,0,
1524391501.469,,0.000000e+000,3.499911e+001,-1.168000e-005,0.000000e+000,2,9.320574e-001,0.000000e+000,,,,,,,,,,,,,,32,1,4.000000e+000,2.338409e-003,0.000000e+000,0,,0,
1524391540.652,,0.000000e+000,3.499872e+001,-1.162497e-005,0.000000e+000,2,9.327149e-001,0.000000e+000,,,,,,,,,,,,,,32,1,4.000000e+000,1.560211e-003,0.000000e+000,0,,0,
1524391578.787,,0.000000e+000,3.499872e+001,-1.158470e-005,0.000000e+000,2,9.303648e-001,0.000000e+000,,,,,,,,,,,,,,32,1,4.000000e+000,0.000000e+000,0.000000e+000,0,,0,
1524391616.938,,0.000000e+000,3.499833e+001,-1.152261e-005,0.000000e+000,2,9.336056e-001,0.000000e+000,,,,,,,,,,,,,,32,1,4.000000e+000,7.781982e-004,0.000000e+000,0,,0,
1524391655.016,,0.000000e+000,3.499989e+001,-1.147850e-005,0.000000e+000,2,9.341641e-001,0.000000e+000,,,,,,,,,,,,,,32,1,4.000000e+000,2.342224e-003,0.000000e+000,0,,0,
1524391693.092,,0.000000e+000,3.499872e+001,-1.141805e-005,0.000000e+000,2,9.323331e-001,0.000000e+000,,,,,,,,,,,,,,32,1,4.000000e+000,1.560211e-003,0.000000e+000,0,,0,
1524391730.760,,0.000000e+000,3.499833e+001,-1.134531e-005,0.000000e+000,2,9.318789e-001,0.000000e+000,,,,,,,,,,,,,,32,1,4.000000e+000,7.781982e-004,0.000000e+000,0,,0,
1524391768.658,,0.000000e+000,3.499911e+001,-1.132804e-005,0.000000e+000,2,9.319152e-001,0.000000e+000,,,,,,,,,,,,,,32,1,4.000000e+000,7.820129e-004,0.000000e+000,0,,0,
1524391806.811,,0.000000e+000,3.499950e+001,-1.125357e-005,0.000000e+000,2,9.294806e-001,0.000000e+000,,,,,,,,,,,,,,32,1,4.000000e+000,1.560211e-003,0.000000e+000,0,,0,
1524391844.821,,0.000000e+000,3.499872e+001,-1.115922e-005,0.000000e+000,2,9.295052e-001,0.000000e+000,,,,,,,,,,,,,,32,1,4.000000e+000,1.560211e-003,0.000000e+000,0,,0,
1524391883.157,,0.000000e+000,3.499911e+001,-1.113354e-005,0.000000e+000,2,9.297414e-001,0.000000e+000,,,,,,,,,,,,,,32,1,4.000000e+000,7.820129e-004,0.000000e+000,0,,0,
1524391921.217,,0.000000e+000,3.499911e+001,-1.105094e-005,0.000000e+000,2,9.295224e-001,0.000000e+000,,,,,,,,,,,,,,32,1,4.000000e+000,7.820129e-004,0.000000e+000,0,,0,
1524391959.430,,0.000000e+000,3.499989e+001,-1.099791e-005,0.000000e+000,2,9.312424e-001,0.000000e+000,,,,,,,,,,,,,,32,1,4.000000e+000,2.342224e-003,0.000000e+000,0,,0,
1524391997.131,,0.000000e+000,3.499911e+001,-1.095822e-005,0.000000e+000,2,9.281675e-001,0.000000e+000,,,,,,,,,,,,,,32,1,4.000000e+000,7.820129e-004,0.000000e+000,0,,0,
1524392035.491,,0.000000e+000,3.499950e+001,-1.090832e-005,0.000000e+000,2,9.288421e-001,0.000000e+000,,,,,,,,,,,,,,32,1,4.000000e+000,1.560211e-003,0.000000e+000,0,,0,
1524392073.092,,0.000000e+000,3.499872e+001,-1.084839e-005,0.000000e+000,2,9.283614e-001,0.000000e+000,,,,,,,,,,,,,,32,1,4.000000e+000,1.560211e-003,0.000000e+000,0,,0,
1524392111.190,,0.000000e+000,3.499872e+001,-1.078846e-005,0.000000e+000,2,9.270415e-001,0.000000e+000,,,,,,,,,,,,,,32,1,4.000000e+000,0.000000e+000,0.000000e+000,0,,0,
1524392148.593,,0.000000e+000,3.500145e+001,-1.071330e-005,0.000000e+000,2,9.294201e-001,0.000000e+000,,,,,,,,,,,,,,32,1,4.000000e+000,5.470276e-003,0.000000e+000,0,,0,
1524392186.491,,0.000000e+000,3.499989e+001,-1.067223e-005,0.000000e+000,2,9.255316e-001,0.000000e+000,,,,,,,,,,,,,,32,1,4.000000e+000,2.342224e-003,0.000000e+000,0,,0,
1524392224.614,,0.000000e+000,3.499911e+001,-1.065092e-005,0.000000e+000,2,9.267081e-001,0.000000e+000,,,,,,,,,,,,,,32,1,4.000000e+000,7.820129e-004,0.000000e+000,0,,0,
1524392262.682,,0.000000e+000,3.499677e+001,-1.058533e-005,0.000000e+000,2,9.286338e-001,0.000000e+000,,,,,,,,,,,,,,32,1,4.000000e+000,3.910065e-003,0.000000e+000,0,,0,
1524392300.735,,0.000000e+000,3.499872e+001,-1.053601e-005,0.000000e+000,2,9.251106e-001,0.000000e+000,,,,,,,,,,,,,,32,1,4.000000e+000,0.000000e+000,0.000000e+000,0,,0,
1524392338.804,,0.000000e+000,3.499911e+001,-1.044356e-005,0.000000e+000,2,9.264801e-001,0.000000e+000,,,,,,,,,,,,,,32,1,4.000000e+000,7.820129e-004,0.000000e+000,0,,0,
1524392376.467,,0.000000e+000,3.499911e+001,-1.043243e-005,0.000000e+000,2,9.263379e-001,0.000000e+000,,,,,,,,,,,,,,32,1,4.000000e+000,7.820129e-004,0.000000e+000,0,,0,
1524392414.447,,0.000000e+000,3.499872e+001,-1.038291e-005,0.000000e+000,2,9.249421e-001,0.000000e+000,,,,,,,,,,,,,,32,1,4.000000e+000,1.560211e-003,0.000000e+000,0,,0,
1524392452.093,,0.000000e+000,3.499989e+001,-1.031722e-005,0.000000e+000,2,9.248253e-001,0.000000e+000,,,,,,,,,,,,,,32,1,4.000000e+000,7.781982e-004,0.000000e+000,0,,0,
1524392489.481,,0.000000e+000,3.499911e+001,-1.031332e-005,0.000000e+000,2,9.259086e-001,0.000000e+000,,,,,,,,,,,,,,32,1,4.000000e+000,7.820129e-004,0.000000e+000,0,,0,
1524392527.344,,0.000000e+000,3.499950e+001,-1.023184e-005,0.000000e+000,2,9.278120e-001,0.000000e+000,,,,,,,,,,,,,,32,1,4.000000e+000,0.000000e+000,0.000000e+000,0,,0,
1524392564.822,,0.000000e+000,3.499950e+001,-1.017444e-005,0.000000e+000,2,9.230474e-001,0.000000e+000,,,,,,,,,,,,,,32,1,4.000000e+000,1.560211e-003,0.000000e+000,0,,0,
1524392602.912,,0.000000e+000,3.499872e+001,-1.014573e-005,0.000000e+000,2,9.224566e-001,0.000000e+000,,,,,,,,,,,,,,32,1,4.000000e+000,1.560211e-003,0.000000e+000,0,,0,
1524392640.635,,0.000000e+000,3.499911e+001,-1.011358e-005,0.000000e+000,2,9.242460e-001,0.000000e+000,,,,,,,,,,,,,,32,1,4.000000e+000,7.820129e-004,0.000000e+000,0,,0,
1524392679.611,,0.000000e+000,3.499911e+001,-1.007516e-005,0.000000e+000,2,9.225895e-001,0.000000e+000,,,,,,,,,,,,,,32,1,4.000000e+000,7.820129e-004,0.000000e+000,0,,0,
1524392716.754,,0.000000e+000,3.499950e+001,-1.003126e-005,0.000000e+000,2,9.226646e-001,0.000000e+000,,,,,,,,,,,,,,32,1,4.000000e+000,0.000000e+000,0.000000e+000,0,,0,
1524392754.010,,0.000000e+000,3.499833e+001,-9.955808e-006,0.000000e+000,2,9.200878e-001,0.000000e+000,,,,,,,,,,,,,,32,1,4.000000e+000,7.781982e-004,0.000000e+000,0,,0,
1524392792.135,,0.000000e+000,3.499872e+001,-9.902285e-006,0.000000e+000,2,9.215845e-001,0.000000e+000,,,,,,,,,,,,,,32,1,4.000000e+000,1.560211e-003,0.000000e+000,0,,0,
1524392829.878,,0.000000e+000,3.499989e+001,-9.856990e-006,0.000000e+000,2,9.208184e-001,0.000000e+000,,,,,,,,,,,,,,32,1,4.000000e+000,2.342224e-003,0.000000e+000,0,,0,
1524392868.341,,0.000000e+000,3.499950e+001,-9.802616e-006,0.000000e+000,2,9.215385e-001,0.000000e+000,,,,,,,,,,,,,,32,1,4.000000e+000,1.560211e-003,0.000000e+000,0,,0,
1524392907.134,,0.000000e+000,3.499989e+001,-9.795657e-006,0.000000e+000,2,9.221564e-001,0.000000e+000,,,,,,,,,,,,,,32,1,4.000000e+000,7.781982e-004,0.000000e+000,0,,0,
1524392945.212,,0.000000e+000,3.499911e+001,-9.726573e-006,0.000000e+000,2,9.250697e-001,0.000000e+000,,,,,,,,,,,,,,32,1,4.000000e+000,7.820129e-004,0.000000e+000,0,,0,
1524392983.365,,0.000000e+000,3.499950e+001,-9.703795e-006,0.000000e+000,2,9.207221e-001,0.000000e+000,,,,,,,,,,,,,,32,1,4.000000e+000,3.120422e-003,0.000000e+000,0,,0,
1524393021.429,,0.000000e+000,3.499911e+001,-9.666579e-006,0.000000e+000,2,9.196004e-001,0.000000e+000,,,,,,,,,,,,,,32,1,4.000000e+000,7.820129e-004,0.000000e+000,0,,0,
1524393059.497,,0.000000e+000,3.499911e+001,-9.624250e-006,0.000000e+000,2,9.210250e-001,0.000000e+000,,,,,,,,,,,,,,32,1,4.000000e+000,7.820129e-004,0.000000e+000,0,,0,
1524393097.510,,0.000000e+000,3.499911e+001,-9.600096e-006,0.000000e+000,2,9.203597e-001,0.000000e+000,,,,,,,,,,,,,,32,1,4.000000e+000,7.820129e-004,0.000000e+000,0,,0,
1524393135.655,,0.000000e+000,3.499911e+001,-9.555147e-006,0.000000e+000,2,9.210586e-001,0.000000e+000,,,,,,,,,,,,,,32,1,4.000000e+000,7.820129e-004,0.000000e+000,0,,0,
1524393173.671,,0.000000e+000,3.499950e+001,-9.479126e-006,0.000000e+000,2,9.186782e-001,0.000000e+000,,,,,,,,,,,,,,32,1,4.000000e+000,1.560211e-003,0.000000e+000,0,,0,
1524393211.796,,0.000000e+000,3.499872e+001,-9.462095e-006,0.000000e+000,2,9.192025e-001,0.000000e+000,,,,,,,,,,,,,,32,1,4.000000e+000,1.560211e-003,0.000000e+000,0,,0,
1524393249.862,,0.000000e+000,3.499794e+001,-9.409970e-006,0.000000e+000,2,9.191679e-001,0.000000e+000,,,,,,,,,,,,,,32,1,4.000000e+000,0.000000e+000,0.000000e+000,0,,0,
1524393287.445,,0.000000e+000,3.499833e+001,-9.384828e-006,0.000000e+000,2,9.168258e-001,0.000000e+000,,,,,,,,,,,,,,32,1,4.000000e+000,7.781982e-004,0.000000e+000,0,,0,
1524393325.023,,0.000000e+000,3.499989e+001,-9.336234e-006,0.000000e+000,2,9.202773e-001,0.000000e+000,,,,,,,,,,,,,,32,1,4.000000e+000,7.781982e-004,0.000000e+000,0,,0,
1524393363.108,,0.000000e+000,3.499872e+001,-9.308776e-006,0.000000e+000,2,9.196029e-001,0.000000e+000,,,,,,,,,,,,,,32,1,4.000000e+000,0.000000e+000,0.000000e+000,0,,0,
1524393400.529,,0.000000e+000,3.499989e+001,-9.273559e-006,0.000000e+000,2,9.163819e-001,0.000000e+000,,,,,,,,,,,,,,32,1,4.000000e+000,7.781982e-004,0.000000e+000,0,,0,
1524393438.482,,0.000000e+000,3.499872e+001,-9.225796e-006,0.000000e+000,2,9.166067e-001,0.000000e+000,,,,,,,,,,,,,,32,1,4.000000e+000,1.560211e-003,0.000000e+000,0,,0,
1524393476.560,,0.000000e+000,3.499872e+001,-9.188129e-006,0.000000e+000,2,9.130806e-001,0.000000e+000,,,,,,,,,,,,,,32,1,4.000000e+000,0.000000e+000,0.000000e+000,0,,0,
1524393514.616,,0.000000e+000,3.499911e+001,-9.170478e-006,0.000000e+000,2,9.150545e-001,0.000000e+000,,,,,,,,,,,,,,32,1,4.000000e+000,7.820129e-004,0.000000e+000,0,,0,
1524393552.701,,0.000000e+000,3.499950e+001,-9.110073e-006,0.000000e+000,2,9.151770e-001,0.000000e+000,,,,,,,,,,,,,,32,1,4.000000e+000,0.000000e+000,0.000000e+000,0,,0,
1524393590.304,,0.000000e+000,3.499950e+001,-9.058690e-006,0.000000e+000,2,9.139965e-001,0.000000e+000,,,,,,,,,,,,,,32,1,4.000000e+000,1.560211e-003,0.000000e+000,0,,0,
1524393628.240,,0.000000e+000,3.499950e+001,-9.065199e-006,0.000000e+000,2,9.158168e-001,0.000000e+000,,,,,,,,,,,,,,32,1,4.000000e+000,0.000000e+000,0.000000e+000,0,,0,
1524393666.143,,0.000000e+000,3.499676e+001,-9.010617e-006,0.000000e+000,2,9.122930e-001,0.000000e+000,,,,,,,,,,,,,,32,1,4.000000e+000,7.038116e-003,0.000000e+000,0,,0,
1524393704.469,,0.000000e+000,3.499754e+001,-8.972967e-006,0.000000e+000,2,9.134062e-001,0.000000e+000,,,,,,,,,,,,,,32,1,4.000000e+000,7.896423e-004,0.000000e+000,0,,0,
1524393742.659,,0.000000e+000,3.499911e+001,-8.954232e-006,0.000000e+000,2,9.168150e-001,0.000000e+000,,,,,,,,,,,,,,32,1,4.000000e+000,7.820129e-004,0.000000e+000,0,,0,
1524393780.552,,0.000000e+000,3.500028e+001,-8.904397e-006,0.000000e+000,2,9.125825e-001,0.000000e+000,,,,,,,,,,,,,,32,1,4.000000e+000,0.000000e+000,0.000000e+000,0,,0,
1524393818.598,,0.000000e+000,3.499872e+001,-8.888674e-006,0.000000e+000,2,9.138514e-001,0.000000e+000,,,,,,,,,,,,,,32,1,4.000000e+000,0.000000e+000,0.000000e+000,0,,0,
1524393856.663,,0.000000e+000,3.499950e+001,-8.850782e-006,0.000000e+000,2,9.129218e-001,0.000000e+000,,,,,,,,,,,,,,32,1,4.000000e+000,0.000000e+000,0.000000e+000,0,,0,
1524393894.879,,0.000000e+000,3.499871e+001,-8.823868e-006,0.000000e+000,2,9.129812e-001,0.000000e+000,,,,,,,,,,,,,,32,1,4.000000e+000,3.128052e-003,0.000000e+000,0,,0,
1524393932.897,,0.000000e+000,3.499872e+001,-8.790058e-006,0.000000e+000,2,9.126849e-001,0.000000e+000,,,,,,,,,,,,,,32,1,4.000000e+000,1.560211e-003,0.000000e+000,0,,0,
1524393970.372,,0.000000e+000,3.499950e+001,-8.742356e-006,0.000000e+000,2,9.123392e-001,0.000000e+000,,,,,,,,,,,,,,32,1,4.000000e+000,0.000000e+000,0.000000e+000,0,,0,
1524394008.438,,0.000000e+000,3.499911e+001,-8.677735e-006,0.000000e+000,2,9.103538e-001,0.000000e+000,,,,,,,,,,,,,,32,1,4.000000e+000,7.820129e-004,0.000000e+000,0,,0,
1524394046.443,,0.000000e+000,3.499950e+001,-8.705078e-006,0.000000e+000,2,9.137714e-001,0.000000e+000,,,,,,,,,,,,,,32,1,4.000000e+000,1.560211e-003,0.000000e+000,0,,0,
1524394085.304,,0.000000e+000,3.499950e+001,-8.663502e-006,0.000000e+000,2,9.120107e-001,0.000000e+000,,,,,,,,,,,,,,32,1,4.000000e+000,1.560211e-003,0.000000e+000,0,,0,
1524394124.057,,0.000000e+000,3.499950e+001,-8.620225e-006,0.000000e+000,2,9.082322e-001,0.000000e+000,,,,,,,,,,,,,,32,1,4.000000e+000,1.560211e-003,0.000000e+000,0,,0,
1524394161.333,,0.000000e+000,3.499911e+001,-8.564707e-006,0.000000e+000,2,9.083556e-001,0.000000e+000,,,,,,,,,,,,,,32,1,4.000000e+000,7.820129e-004,0.000000e+000,0,,0,
1524394200.116,,0.000000e+000,3.500146e+001,-8.580535e-006,0.000000e+000,2,9.062450e-001,0.000000e+000,,,,,,,,,,,,,,32,1,4.000000e+000,3.910065e-003,0.000000e+000,0,,0,
1524394238.151,,0.000000e+000,3.499833e+001,-8.500941e-006,0.000000e+000,2,9.092796e-001,0.000000e+000,,,,,,,,,,,,,,32,1,4.000000e+000,2.349854e-003,0.000000e+000,0,,0,
1524394276.232,,0.000000e+000,3.499950e+001,-8.471969e-006,0.000000e+000,2,9.056798e-001,0.000000e+000,,,,,,,,,,,,,,32,1,4.000000e+000,1.560211e-003,0.000000e+000,0,,0,
1524394314.262,,0.000000e+000,3.499950e+001,-8.454155e-006,0.000000e+000,2,9.046730e-001,0.000000e+000,,,,,,,,,,,,,,32,1,4.000000e+000,0.000000e+000,0.000000e+000,0,,0,
1524394352.051,,0.000000e+000,3.499754e+001,-8.406968e-006,0.000000e+000,2,9.111441e-001,0.000000e+000,,,,,,,,,,,,,,32,1,4.000000e+000,2.349854e-003,0.000000e+000,0,,0,
1524394390.269,,0.000000e+000,3.499950e+001,-8.371665e-006,0.000000e+000,2,9.090553e-001,0.000000e+000,,,,,,,,,,,,,,32,1,4.000000e+000,0.000000e+000,0.000000e+000,0,,0,
1524394428.109,,0.000000e+000,3.499833e+001,-8.368535e-006,0.000000e+000,2,9.066465e-001,0.000000e+000,,,,,,,,,,,,,,32,1,4.000000e+000,7.781982e-004,0.000000e+000,0,,0,
1524394466.722,,0.000000e+000,3.499950e+001,-8.341619e-006,0.000000e+000,2,9.098499e-001,0.000000e+000,,,,,,,,,,,,,,32,1,4.000000e+000,1.560211e-003,0.000000e+000,0,,0,
1524394503.728,,0.000000e+000,3.499911e+001,-8.318107e-006,0.000000e+000,2,9.053680e-001,0.000000e+000,,,,,,,,,,,,,,32,1,4.000000e+000,7.820129e-004,0.000000e+000,0,,0,
1524394541.761,,0.000000e+000,3.499989e+001,-8.279798e-006,0.000000e+000,2,9.066780e-001,0.000000e+000,,,,,,,,,,,,,,32,1,4.000000e+000,7.781982e-004,0.000000e+000,0,,0,
1524394578.951,,0.000000e+000,3.500028e+001,-8.210191e-006,0.000000e+000,2,9.061268e-001,0.000000e+000,,,,,,,,,,,,,,32,1,4.000000e+000,4.688263e-003,0.000000e+000,0,,0,
1524394616.569,,0.000000e+000,3.499872e+001,-8.226943e-006,0.000000e+000,2,9.070348e-001,0.000000e+000,,,,,,,,,,,,,,32,1,4.000000e+000,1.560211e-003,0.000000e+000,0,,0,
1524394654.632,,0.000000e+000,3.499950e+001,-8.197637e-006,0.000000e+000,2,9.077375e-001,0.000000e+000,,,,,,,,,,,,,,32,1,4.000000e+000,1.560211e-003,0.000000e+000,0,,0,
1524394692.635,,0.000000e+000,3.499950e+001,-8.172853e-006,0.000000e+000,2,9.093969e-001,0.000000e+000,,,,,,,,,,,,,,32,1,4.000000e+000,1.560211e-003,0.000000e+000,0,,0,
1524394730.769,,0.000000e+000,3.499911e+001,-8.119754e-006,0.000000e+000,2,9.062713e-001,0.000000e+000,,,,,,,,,,,,,,32,1,4.000000e+000,2.338409e-003,0.000000e+000,0,,0,
1524394768.869,,0.000000e+000,3.499872e+001,-8.087840e-006,0.000000e+000,2,9.071394e-001,0.000000e+000,,,,,,,,,,,,,,32,1,4.000000e+000,0.000000e+000,0.000000e+000,0,,0,
1524394806.967,,0.000000e+000,3.499872e+001,-8.033880e-006,0.000000e+000,2,9.040518e-001,0.000000e+000,,,,,,,,,,,,,,32,1,4.000000e+000,0.000000e+000,0.000000e+000,0,,0,
1524394845.308,,0.000000e+000,3.499911e+001,-8.060050e-006,0.000000e+000,2,9.086940e-001,0.000000e+000,,,,,,,,,,,,,,32,1,4.000000e+000,7.820129e-004,0.000000e+000,0,,0,
1524394883.283,,0.000000e+000,3.499950e+001,-7.986268e-006,0.000000e+000,2,9.057851e-001,0.000000e+000,,,,,,,,,,,,,,32,1,4.000000e+000,1.560211e-003,0.000000e+000,0,,0,
1524394921.224,,0.000000e+000,3.500146e+001,-7.953959e-006,0.000000e+000,2,8.984074e-001,0.000000e+000,,,,,,,,,,,,,,32,1,4.000000e+000,3.910065e-003,0.000000e+000,0,,0,
1524394959.267,,0.000000e+000,3.499833e+001,-7.939398e-006,0.000000e+000,2,9.016965e-001,0.000000e+000,,,,,,,,,,,,,,32,1,4.000000e+000,2.349854e-003,0.000000e+000,0,,0,
1524394997.268,,0.000000e+000,3.500028e+001,-7.906227e-006,0.000000e+000,2,9.002038e-001,0.000000e+000,,,,,,,,,,,,,,32,1,4.000000e+000,0.000000e+000,0.000000e+000,0,,0,
1524395036.341,,0.000000e+000,3.499989e+001,-7.861211e-006,0.000000e+000,2,9.027295e-001,0.000000e+000,,,,,,,,,,,,,,32,1,4.000000e+000,2.342224e-003,0.000000e+000,0,,0,
1524395074.469,,0.000000e+000,3.499911e+001,-7.884346e-006,0.000000e+000,2,9.053127e-001,0.000000e+000,,,,,,,,,,,,,,32,1,4.000000e+000,2.338409e-003,0.000000e+000,0,,0,
1524395112.527,,0.000000e+000,3.499794e+001,-7.830864e-006,0.000000e+000,2,9.044827e-001,0.000000e+000,,,,,,,,,,,,,,32,1,4.000000e+000,0.000000e+000,0.000000e+000,0,,0,
1524395150.600,,0.000000e+000,3.500028e+001,-7.784013e-006,0.000000e+000,2,9.023674e-001,0.000000e+000,,,,,,,,,,,,,,32,1,4.000000e+000,0.000000e+000,0.000000e+000,0,,0,
1524395188.935,,0.000000e+000,3.499950e+001,-7.777261e-006,0.000000e+000,2,9.007123e-001,0.000000e+000,,,,,,,,,,,,,,32,1,4.000000e+000,1.560211e-003,0.000000e+000,0,,0,
1524395227.623,,0.000000e+000,3.499715e+001,-7.724047e-006,0.000000e+000,2,8.975720e-001,0.000000e+000,,,,,,,,,,,,,,32,1,4.000000e+000,3.128052e-003,0.000000e+000,0,,0,
1524395266.269,,0.000000e+000,3.499989e+001,-7.699983e-006,0.000000e+000,2,9.004146e-001,0.000000e+000,,,,,,,,,,,,,,32,1,4.000000e+000,2.342224e-003,0.000000e+000,0,,0,
1524395303.282,,0.000000e+000,3.499989e+001,-7.717775e-006,0.000000e+000,2,9.003208e-001,0.000000e+000,,,,,,,,,,,,,,32,1,4.000000e+000,7.781982e-004,0.000000e+000,0,,0,
1524395341.437,,0.000000e+000,3.499989e+001,-7.660848e-006,0.000000e+000,2,8.991305e-001,0.000000e+000,,,,,,,,,,,,,,32,1,4.000000e+000,7.781982e-004,0.000000e+000,0,,0,
1524395379.368,,0.000000e+000,3.499989e+001,-7.640853e-006,0.000000e+000,2,8.990042e-001,0.000000e+000,,,,,,,,,,,,,,32,1,4.000000e+000,2.342224e-003,0.000000e+000,0,,0,
1524395417.419,,0.000000e+000,3.499989e+001,-7.576933e-006,0.000000e+000,2,9.001454e-001,0.000000e+000,,,,,,,,,,,,,,32,1,4.000000e+000,7.781982e-004,0.000000e+000,0,,0,
1524395455.524,,0.000000e+000,3.499833e+001,-7.575552e-006,0.000000e+000,2,8.982288e-001,0.000000e+000,,,,,,,,,,,,,,32,1,4.000000e+000,7.781982e-004,0.000000e+000,0,,0,
1524395493.570,,0.000000e+000,3.499872e+001,-7.543180e-006,0.000000e+000,2,8.975851e-001,0.000000e+000,,,,,,,,,,,,,,32,1,4.000000e+000,1.560211e-003,0.000000e+000,0,,0,
1524395531.693,,0.000000e+000,3.499872e+001,-7.519310e-006,0.000000e+000,2,8.957326e-001,0.000000e+000,,,,,,,,,,,,,,32,1,4.000000e+000,0.000000e+000,0.000000e+000,0,,0,
1524395569.201,,0.000000e+000,3.499950e+001,-7.512866e-006,0.000000e+000,2,8.977624e-001,0.000000e+000,,,,,,,,,,,,,,32,1,4.000000e+000,0.000000e+000,0.000000e+000,0,,0,
1524395607.284,,0.000000e+000,3.499911e+001,-7.465710e-006,0.000000e+000,2,8.975571e-001,0.000000e+000,,,,,,,,,,,,,,32,1,4.000000e+000,7.820129e-004,0.000000e+000,0,,0,
1524395645.335,,0.000000e+000,3.499872e+001,-7.449619e-006,0.000000e+000,2,8.959327e-001,0.000000e+000,,,,,,,,,,,,,,32,1,4.000000e+000,0.000000e+000,0.000000e+000,0,,0,
1524395683.180,,0.000000e+000,3.499793e+001,-7.461677e-006,0.000000e+000,2,8.975993e-001,0.000000e+000,,,,,,,,,,,,,,32,1,4.000000e+000,1.567841e-003,0.000000e+000,0,,0,
1524395720.913,,0.000000e+000,3.499754e+001,-7.398719e-006,0.000000e+000,2,8.964598e-001,0.000000e+000,,,,,,,,,,,,,,32,1,4.000000e+000,2.349854e-003,0.000000e+000,0,,0,
1524395758.689,,0.000000e+000,3.499872e+001,-7.357389e-006,0.000000e+000,2,8.980872e-001,0.000000e+000,,,,,,,,,,,,,,32,1,4.000000e+000,0.000000e+000,0.000000e+000,0,,0,
1524395796.869,,0.000000e+000,3.500146e+001,-7.314905e-006,0.000000e+000,2,8.972021e-001,0.000000e+000,,,,,,,,,,,,,,32,1,4.000000e+000,3.910065e-003,0.000000e+000,0,,0,
1524395835.657,,0.000000e+000,3.499872e+001,-7.308986e-006,0.000000e+000,2,8.947408e-001,0.000000e+000,,,,,,,,,,,,,,32,1,4.000000e+000,1.560211e-003,0.000000e+000,0,,0,
1524395873.260,,0.000000e+000,3.499989e+001,-7.330449e-006,0.000000e+000,2,8.966479e-001,0.000000e+000,,,,,,,,,,,,,,32,1,4.000000e+000,7.781982e-004,0.000000e+000,0,,0,
1524395911.353,,0.000000e+000,3.499871e+001,-7.296651e-006,0.000000e+000,2,8.989658e-001,0.000000e+000,,,,,,,,,,,,,,32,1,4.000000e+000,3.128052e-003,0.000000e+000,0,,0,
1524395949.381,,0.000000e+000,3.499989e+001,-7.248604e-006,0.000000e+000,2,8.937663e-001,0.000000e+000,,,,,,,,,,,,,,32,1,4.000000e+000,7.781982e-004,0.000000e+000,0,,0,
1524395987.507,,0.000000e+000,3.499833e+001,-7.206486e-006,0.000000e+000,2,8.918355e-001,0.000000e+000,,,,,,,,,,,,,,32,1,4.000000e+000,7.781982e-004,0.000000e+000,0,,0,
1524396025.530,,0.000000e+000,3.500067e+001,-7.198263e-006,0.000000e+000,2,8.925383e-001,0.000000e+000,,,,,,,,,,,,,,32,1,4.000000e+000,2.338409e-003,0.000000e+000,0,,0,
1524396063.381,,0.000000e+000,3.499872e+001,-7.173486e-006,0.000000e+000,2,8.913140e-001,0.000000e+000,,,,,,,,,,,,,,32,1,4.000000e+000,0.000000e+000,0.000000e+000,0,,0,
1524396101.091,,0.000000e+000,3.499950e+001,-7.153964e-006,0.000000e+000,2,8.947439e-001,0.000000e+000,,,,,,,,,,,,,,32,1,4.000000e+000,1.560211e-003,0.000000e+000,0,,0,
1524396139.119,,0.000000e+000,3.499911e+001,-7.147361e-006,0.000000e+000,2,8.919123e-001,0.000000e+000,,,,,,,,,,,,,,32,1,4.000000e+000,7.820129e-004,0.000000e+000,0,,0,
1524396177.092,,0.000000e+000,3.499911e+001,-7.085346e-006,0.000000e+000,2,8.936298e-001,0.000000e+000,,,,,,,,,,,,,,32,1,4.000000e+000,7.820129e-004,0.000000e+000,0,,0,
1524396215.160,,0.000000e+000,3.499911e+001,-7.060571e-006,0.000000e+000,2,8.934956e-001,0.000000e+000,,,,,,,,,,,,,,32,1,4.000000e+000,2.338409e-003,0.000000e+000,0,,0,
1524396252.443,,0.000000e+000,3.499638e+001,-7.017368e-006,0.000000e+000,2,8.886244e-001,0.000000e+000,,,,,,,,,,,,,,32,1,4.000000e+000,4.688263e-003,0.000000e+000,0,,0,
1524396290.766,,0.000000e+000,3.499872e+001,-7.032149e-006,0.000000e+000,2,8.900442e-001,0.000000e+000,,,,,,,,,,,,,,32,1,4.000000e+000,1.560211e-003,0.000000e+000,0,,0,
1524396329.627,,0.000000e+000,3.499833e+001,-7.041863e-006,0.000000e+000,2,8.919547e-001,0.000000e+000,,,,,,,,,,,,,,32,1,4.000000e+000,7.781982e-004,0.000000e+000,0,,0,
1524396367.840,,0.000000e+000,3.499872e+001,-6.979790e-006,0.000000e+000,2,8.890443e-001,0.000000e+000,,,,,,,,,,,,,,32,1,4.000000e+000,1.560211e-003,0.000000e+000,0,,0,
1524396405.901,,0.000000e+000,3.499950e+001,-6.962203e-006,0.000000e+000,2,8.938568e-001,0.000000e+000,,,,,,,,,,,,,,32,1,4.000000e+000,1.560211e-003,0.000000e+000,0,,0,
1524396443.981,,0.000000e+000,3.499950e+001,-6.939074e-006,0.000000e+000,2,8.895997e-001,0.000000e+000,,,,,,,,,,,,,,32,1,4.000000e+000,0.000000e+000,0.000000e+000,0,,0,
1524396482.122,,0.000000e+000,3.499911e+001,-6.932317e-006,0.000000e+000,2,8.907397e-001,0.000000e+000,,,,,,,,,,,,,,32,1,4.000000e+000,7.820129e-004,0.000000e+000,0,,0,
1524396520.187,,0.000000e+000,3.499950e+001,-6.911433e-006,0.000000e+000,2,8.921629e-001,0.000000e+000,,,,,,,,,,,,,,32,1,4.000000e+000,0.000000e+000,0.000000e+000,0,,0,
1524396558.198,,0.000000e+000,3.499911e+001,-6.886989e-006,0.000000e+000,2,8.888220e-001,0.000000e+000,,,,,,,,,,,,,,32,1,4.000000e+000,2.338409e-003,0.000000e+000,0,,0,
1524396596.326,,0.000000e+000,3.499989e+001,-6.840974e-006,0.000000e+000,2,8.877762e-001,0.000000e+000,,,,,,,,,,,,,,32,1,4.000000e+000,2.342224e-003,0.000000e+000,0,,0,
1524396634.404,,0.000000e+000,3.499872e+001,-6.818472e-006,0.000000e+000,2,8.860165e-001,0.000000e+000,,,,,,,,,,,,,,32,1,4.000000e+000,0.000000e+000,0.000000e+000,0,,0,
1524396672.459,,0.000000e+000,3.499911e+001,-6.811831e-006,0.000000e+000,2,8.878853e-001,0.000000e+000,,,,,,,,,,,,,,32,1,4.000000e+000,7.820129e-004,0.000000e+000,0,,0,
1524396710.520,,0.000000e+000,3.499911e+001,-6.791930e-006,0.000000e+000,2,8.895112e-001,0.000000e+000,,,,,,,,,,,,,,32,1,4.000000e+000,7.820129e-004,0.000000e+000,0,,0,
1524396749.013,,0.000000e+000,3.499833e+001,-6.767495e-006,0.000000e+000,2,8.840026e-001,0.000000e+000,,,,,,,,,,,,,,32,1,4.000000e+000,7.781982e-004,0.000000e+000,0,,0,
1524396786.601,,0.000000e+000,3.499950e+001,-6.744532e-006,0.000000e+000,2,8.863180e-001,0.000000e+000,,,,,,,,,,,,,,32,1,4.000000e+000,0.000000e+000,0.000000e+000,0,,0,
1524396824.522,,0.000000e+000,3.499950e+001,-6.752351e-006,0.000000e+000,2,8.894317e-001,0.000000e+000,,,,,,,,,,,,,,32,1,4.000000e+000,0.000000e+000,0.000000e+000,0,,0,
1524396862.832,,0.000000e+000,3.499872e+001,-6.702629e-006,0.000000e+000,2,8.845943e-001,0.000000e+000,,,,,,,,,,,,,,32,1,4.000000e+000,1.560211e-003,0.000000e+000,0,,0,
1524396901.028,,0.000000e+000,3.500028e+001,-6.693583e-006,0.000000e+000,2,8.906749e-001,0.000000e+000,,,,,,,,,,,,,,32,1,4.000000e+000,1.560211e-003,0.000000e+000,0,,0,
1524396939.158,,0.000000e+000,3.499872e+001,-6.686319e-006,0.000000e+000,2,8.834507e-001,0.000000e+000,,,,,,,,,,,,,,32,1,4.000000e+000,0.000000e+000,0.000000e+000,0,,0,
1524396977.797,,0.000000e+000,3.499872e+001,-6.648131e-006,0.000000e+000,2,8.849521e-001,0.000000e+000,,,,,,,,,,,,,,32,1,4.000000e+000,0.000000e+000,0.000000e+000,0,,0,
1524397015.860,,0.000000e+000,3.499911e+001,-6.640058e-006,0.000000e+000,2,8.834376e-001,0.000000e+000,,,,,,,,,,,,,,32,1,4.000000e+000,7.820129e-004,0.000000e+000,0,,0,
1524397053.323,,0.000000e+000,3.499833e+001,-6.632667e-006,0.000000e+000,2,8.803873e-001,0.000000e+000,,,,,,,,,,,,,,32,1,4.000000e+000,7.781982e-004,0.000000e+000,0,,0,
1524397092.473,,0.000000e+000,3.499911e+001,-6.587957e-006,0.000000e+000,2,8.816737e-001,0.000000e+000,,,,,,,,,,,,,,32,1,4.000000e+000,7.820129e-004,0.000000e+000,0,,0,
1524397130.571,,0.000000e+000,3.499989e+001,-6.572348e-006,0.000000e+000,2,8.822842e-001,0.000000e+000,,,,,,,,,,,,,,32,1,4.000000e+000,7.781982e-004,0.000000e+000,0,,0,
1524397168.462,,0.000000e+000,3.500028e+001,-6.537207e-006,0.000000e+000,2,8.811774e-001,0.000000e+000,,,,,,,,,,,,,,32,1,4.000000e+000,1.560211e-003,0.000000e+000,0,,0,
1524397206.590,,0.000000e+000,3.499911e+001,-6.486446e-006,0.000000e+000,2,8.863141e-001,0.000000e+000,,,,,,,,,,,,,,32,1,4.000000e+000,7.820129e-004,0.000000e+000,0,,0,
1524397243.918,,0.000000e+000,3.499950e+001,-6.530855e-006,0.000000e+000,2,8.835548e-001,0.000000e+000,,,,,,,,,,,,,,32,1,4.000000e+000,0.000000e+000,0.000000e+000,0,,0,
1524397282.434,,0.000000e+000,3.499911e+001,-6.498340e-006,0.000000e+000,2,8.803135e-001,0.000000e+000,,,,,,,,,,,,,,32,1,4.000000e+000,7.820129e-004,0.000000e+000,0,,0,
1524397320.327,,0.000000e+000,3.499911e+001,-6.493013e-006,0.000000e+000,2,8.831203e-001,0.000000e+000,,,,,,,,,,,,,,32,1,4.000000e+000,7.820129e-004,0.000000e+000,0,,0,
1524397358.897,,0.000000e+000,3.499794e+001,-6.467243e-006,0.000000e+000,2,8.784204e-001,0.000000e+000,,,,,,,,,,,,,,32,1,4.000000e+000,0.000000e+000,0.000000e+000,0,,0,
1524397396.978,,0.000000e+000,3.500146e+001,-6.432866e-006,0.000000e+000,2,8.827846e-001,0.000000e+000,,,,,,,,,,,,,,32,1,4.000000e+000,3.910065e-003,0.000000e+000,0,,0,
1524397435.558,,0.000000e+000,3.499950e+001,-6.411361e-006,0.000000e+000,2,8.780003e-001,0.000000e+000,,,,,,,,,,,,,,32,1,4.000000e+000,1.560211e-003,0.000000e+000,0,,0,
1524397473.109,,0.000000e+000,3.499833e+001,-6.402373e-006,0.000000e+000,2,8.786370e-001,0.000000e+000,,,,,,,,,,,,,,32,1,4.000000e+000,7.781982e-004,0.000000e+000,0,,0,
1524397511.904,,0.000000e+000,3.499911e+001,-6.413015e-006,0.000000e+000,2,8.822975e-001,0.000000e+000,,,,,,,,,,,,,,32,1,4.000000e+000,7.820129e-004,0.000000e+000,0,,0,
1524397550.255,,0.000000e+000,3.499989e+001,-6.347317e-006,0.000000e+000,2,8.791819e-001,0.000000e+000,,,,,,,,,,,,,,32,1,4.000000e+000,7.781982e-004,0.000000e+000,0,,0,
1524397588.333,,0.000000e+000,3.499833e+001,-6.334010e-006,0.000000e+000,2,8.786886e-001,0.000000e+000,,,,,,,,,,,,,,32,1,4.000000e+000,7.781982e-004,0.000000e+000,0,,0,
1524397627.531,,0.000000e+000,3.499911e+001,-6.301321e-006,0.000000e+000,2,8.770313e-001,0.000000e+000,,,,,,,,,,,,,,32,1,4.000000e+000,7.820129e-004,0.000000e+000,0,,0,
1524397665.732,,0.000000e+000,3.499950e+001,-6.264141e-006,0.000000e+000,2,8.740839e-001,0.000000e+000,,,,,,,,,,,,,,32,1,4.000000e+000,0.000000e+000,0.000000e+000,0,,0,
1524397703.775,,0.000000e+000,3.499872e+001,-6.296503e-006,0.000000e+000,2,8.786325e-001,0.000000e+000,,,,,,,,,,,,,,32,1,4.000000e+000,1.560211e-003,0.000000e+000,0,,0,
1524397741.843,,0.000000e+000,3.499950e+001,-6.282375e-006,0.000000e+000,2,8.780225e-001,0.000000e+000,,,,,,,,,,,,,,32,1,4.000000e+000,0.000000e+000,0.000000e+000,0,,0,
1524397779.831,,0.000000e+000,3.499911e+001,-6.251445e-006,0.000000e+000,2,8.799978e-001,0.000000e+000,,,,,,,,,,,,,,32,1,4.000000e+000,7.820129e-004,0.000000e+000,0,,0,
1524397818.289,,0.000000e+000,3.500106e+001,-6.199803e-006,0.000000e+000,2,8.723506e-001,0.000000e+000,,,,,,,,,,,,,,32,1,4.000000e+000,3.128052e-003,0.000000e+000,0,,0,
1524397856.819,,0.000000e+000,3.500028e+001,-6.182210e-006,0.000000e+000,2,8.728923e-001,0.000000e+000,,,,,,,,,,,,,,32,1,4.000000e+000,0.000000e+000,0.000000e+000,0,,0,
1524397894.875,,0.000000e+000,3.499989e+001,-6.200845e-006,0.000000e+000,2,8.768123e-001,0.000000e+000,,,,,,,,,,,,,,32,1,4.000000e+000,7.781982e-004,0.000000e+000,0,,0,
1524397932.396,,0.000000e+000,3.499989e+001,-6.191950e-006,0.000000e+000,2,8.756796e-001,0.000000e+000,,,,,,,,,,,,,,32,1,4.000000e+000,2.342224e-003,0.000000e+000,0,,0,
1524397970.451,,0.000000e+000,3.500067e+001,-6.176659e-006,0.000000e+000,2,8.722621e-001,0.000000e+000,,,,,,,,,,,,,,32,1,4.000000e+000,7.820129e-004,0.000000e+000,0,,0,
1524398008.834,,0.000000e+000,3.499911e+001,-6.135748e-006,0.000000e+000,2,8.741654e-001,0.000000e+000,,,,,,,,,,,,,,32,1,4.000000e+000,7.820129e-004,0.000000e+000,0,,0,
1524398046.895,,0.000000e+000,3.499911e+001,-6.176691e-006,0.000000e+000,2,8.736237e-001,0.000000e+000,,,,,,,,,,,,,,32,1,4.000000e+000,7.820129e-004,0.000000e+000,0,,0,
1524398083.903,,0.000000e+000,3.500106e+001,-6.114079e-006,0.000000e+000,2,8.707421e-001,0.000000e+000,,,,,,,,,,,,,,32,1,4.000000e+000,4.692078e-003,0.000000e+000,0,,0,
1524398121.256,,0.000000e+000,3.499872e+001,-6.095329e-006,0.000000e+000,2,8.747775e-001,0.000000e+000,,,,,,,,,,,,,,32,1,4.000000e+000,0.000000e+000,0.000000e+000,0,,0,
1524398159.249,,0.000000e+000,3.499911e+001,-6.086532e-006,0.000000e+000,2,8.749183e-001,0.000000e+000,,,,,,,,,,,,,,32,1,4.000000e+000,7.820129e-004,0.000000e+000,0,,0,
1524398197.674,,0.000000e+000,3.499950e+001,-6.055158e-006,0.000000e+000,2,8.704859e-001,0.000000e+000,,,,,,,,,,,,,,32,1,4.000000e+000,1.560211e-003,0.000000e+000,0,,0,
1524398234.965,,0.000000e+000,3.499989e+001,-6.027572e-006,0.000000e+000,2,8.787552e-001,0.000000e+000,,,,,,,,,,,,,,32,1,4.000000e+000,2.342224e-003,0.000000e+000,0,,0,
1524398273.081,,0.000000e+000,3.500028e+001,-6.025668e-006,0.000000e+000,2,8.723594e-001,0.000000e+000,,,,,,,,,,,,,,32,1,4.000000e+000,3.120422e-003,0.000000e+000,0,,0,
1524398311.379,,0.000000e+000,3.499833e+001,-6.051826e-006,0.000000e+000,2,8.749684e-001,0.000000e+000,,,,,,,,,,,,,,32,1,4.000000e+000,2.349854e-003,0.000000e+000,0,,0,
1524398349.262,,0.000000e+000,3.499989e+001,-6.002982e-006,0.000000e+000,2,8.693377e-001,0.000000e+000,,,,,,,,,,,,,,32,1,4.000000e+000,7.781982e-004,0.000000e+000,0,,0,
1524398387.580,,0.000000e+000,3.499911e+001,-5.978250e-006,0.000000e+000,2,8.702700e-001,0.000000e+000,,,,,,,,,,,,,,32,1,4.000000e+000,7.820129e-004,0.000000e+000,0,,0,
1524398425.115,,0.000000e+000,3.499950e+001,-5.938061e-006,0.000000e+000,2,8.675072e-001,0.000000e+000,,,,,,,,,,,,,,32,1,4.000000e+000,0.000000e+000,0.000000e+000,0,,0,
1524398463.173,,0.000000e+000,3.499950e+001,-5.944661e-006,0.000000e+000,2,8.689087e-001,0.000000e+000,,,,,,,,,,,,,,32,1,4.000000e+000,0.000000e+000,0.000000e+000,0,,0,
1524398501.229,,0.000000e+000,3.499950e+001,-5.951729e-006,0.000000e+000,2,8.678300e-001,0.000000e+000,,,,,,,,,,,,,,32,1,4.000000e+000,0.000000e+000,0.000000e+000,0,,0,
1524398539.242,,0.000000e+000,3.499872e+001,-5.918268e-006,0.000000e+000,2,8.696851e-001,0.000000e+000,,,,,,,,,,,,,,32,1,4.000000e+000,1.560211e-003,0.000000e+000,0,,0,
1524398577.077,,0.000000e+000,3.499950e+001,-5.950272e-006,0.000000e+000,2,8.716868e-001,0.000000e+000,,,,,,,,,,,,,,32,1,4.000000e+000,0.000000e+000,0.000000e+000,0,,0,
1524398614.621,,0.000000e+000,3.500028e+001,-5.888421e-006,0.000000e+000,2,8.671420e-001,0.000000e+000,,,,,,,,,,,,,,32,1,4.000000e+000,1.560211e-003,0.000000e+000,0,,0,
1524398652.334,,0.000000e+000,3.499872e+001,-5.871105e-006,0.000000e+000,2,8.690774e-001,0.000000e+000,,,,,,,,,,,,,,32,1,4.000000e+000,0.000000e+000,0.000000e+000,0,,0,
1524398690.252,,0.000000e+000,3.500067e+001,-5.841776e-006,0.000000e+000,2,8.625869e-001,0.000000e+000,,,,,,,,,,,,,,32,1,4.000000e+000,7.820129e-004,0.000000e+000,0,,0,
1524398728.665,,0.000000e+000,3.499950e+001,-5.837755e-006,0.000000e+000,2,8.684735e-001,0.000000e+000,,,,,,,,,,,,,,32,1,4.000000e+000,1.560211e-003,0.000000e+000,0,,0,
1524398766.583,,0.000000e+000,3.499911e+001,-5.824233e-006,0.000000e+000,2,8.662439e-001,0.000000e+000,,,,,,,,,,,,,,32,1,4.000000e+000,7.820129e-004,0.000000e+000,0,,0,
1524398804.668,,0.000000e+000,3.499950e+001,-5.818308e-006,0.000000e+000,2,8.664109e-001,0.000000e+000,,,,,,,,,,,,,,32,1,4.000000e+000,0.000000e+000,0.000000e+000,0,,0,
1524398842.719,,0.000000e+000,3.499989e+001,-5.779563e-006,0.000000e+000,2,8.658409e-001,0.000000e+000,,,,,,,,,,,,,,32,1,4.000000e+000,7.781982e-004,0.000000e+000,0,,0,
1524398880.272,,0.000000e+000,3.499989e+001,-5.784001e-006,0.000000e+000,2,8.622581e-001,0.000000e+000,,,,,,,,,,,,,,32,1,4.000000e+000,7.781982e-004,0.000000e+000,0,,0,
1524398918.238,,0.000000e+000,3.499950e+001,-5.739260e-006,0.000000e+000,2,8.656544e-001,0.000000e+000,,,,,,,,,,,,,,32,1,4.000000e+000,1.560211e-003,0.000000e+000,0,,0,
1524398956.556,,0.000000e+000,3.500224e+001,-5.722590e-006,0.000000e+000,2,8.661421e-001,0.000000e+000,,,,,,,,,,,,,,32,1,4.000000e+000,7.041931e-003,0.000000e+000,0,,0,
1524398994.399,,0.000000e+000,3.500106e+001,-5.717425e-006,0.000000e+000,2,8.635357e-001,0.000000e+000,,,,,,,,,,,,,,32,1,4.000000e+000,0.000000e+000,0.000000e+000,0,,0,
1524399032.464,,0.000000e+000,3.499950e+001,-5.736018e-006,0.000000e+000,2,8.665695e-001,0.000000e+000,,,,,,,,,,,,,,32,1,4.000000e+000,1.560211e-003,0.000000e+000,0,,0,
1524399070.602,,0.000000e+000,3.499911e+001,-5.728803e-006,0.000000e+000,2,8.639219e-001,0.000000e+000,,,,,,,,,,,,,,32,1,4.000000e+000,7.820129e-004,0.000000e+000,0,,0,
1524399107.955,,0.000000e+000,3.499950e+001,-5.661284e-006,0.000000e+000,2,8.640277e-001,0.000000e+000,,,,,,,,,,,,,,32,1,4.000000e+000,0.000000e+000,0.000000e+000,0,,0,
1524399145.886,,0.000000e+000,3.500067e+001,-5.679763e-006,0.000000e+000,2,8.550469e-001,0.000000e+000,,,,,,,,,,,,,,32,1,4.000000e+000,2.338409e-003,0.000000e+000,0,,0,
1524399184.276,,0.000000e+000,3.499989e+001,-5.632428e-006,0.000000e+000,2,8.663394e-001,0.000000e+000,,,,,,,,,,,,,,32,1,4.000000e+000,7.781982e-004,0.000000e+000,0,,0,
1524399222.412,,0.000000e+000,3.499911e+001,-5.610795e-006,0.000000e+000,2,8.613070e-001,0.000000e+000,,,,,,,,,,,,,,32,1,4.000000e+000,7.820129e-004,0.000000e+000,0,,0,
1524399259.807,,0.000000e+000,3.499833e+001,-5.617735e-006,0.000000e+000,2,8.624465e-001,0.000000e+000,,,,,,,,,,,,,,32,1,4.000000e+000,7.781982e-004,0.000000e+000,0,,0,
1524399297.886,,0.000000e+000,3.499911e+001,-5.634193e-006,0.000000e+000,2,8.583646e-001,0.000000e+000,,,,,,,,,,,,,,32,1,4.000000e+000,7.820129e-004,0.000000e+000,0,,0,
1524399335.429,,0.000000e+000,3.499911e+001,-5.588204e-006,0.000000e+000,2,8.616514e-001,0.000000e+000,,,,,,,,,,,,,,32,1,4.000000e+000,7.820129e-004,0.000000e+000,0,,0,
1524399372.817,,0.000000e+000,3.499911e+001,-5.565128e-006,0.000000e+000,2,8.588545e-001,0.000000e+000,,,,,,,,,,,,,,32,1,4.000000e+000,2.338409e-003,0.000000e+000,0,,0,
1524399410.895,,0.000000e+000,3.499989e+001,-5.562783e-006,0.000000e+000,2,8.620744e-001,0.000000e+000,,,,,,,,,,,,,,32,1,4.000000e+000,7.781982e-004,0.000000e+000,0,,0,
1524399448.913,,0.000000e+000,3.499989e+001,-5.503776e-006,0.000000e+000,2,8.587399e-001,0.000000e+000,,,,,,,,,,,,,,32,1,4.000000e+000,2.342224e-003,0.000000e+000,0,,0,
1524399487.111,,0.000000e+000,3.499872e+001,-5.504946e-006,0.000000e+000,2,8.574654e-001,0.000000e+000,,,,,,,,,,,,,,32,1,4.000000e+000,0.000000e+000,0.000000e+000,0,,0,
1524399499.834,,0.000000e+000,3.499872e+001,-5.511072e-006,0.000000e+000,2,8.564060e-001,0.000000e+000,,,,,,,,,,,,,,32,1,4.000000e+000,0.000000e+000,0.000000e+000,0,,0,