File: Experimental Raw Data/MFn1 VRM/Iterative Regression/Acquisition/MFn1_VRMac_37K_6000s.dc.dat
[Header]
TITLE,MPMS DC Measurement
BYAPP,MPMS Measurement,2.1,Summary
FILEOPENTIME, 1524168711.746000 4/19/2018, 2:11:51 PM

INFO, APPNAME, MPMS MultiVu Application, Revision 1.61,  Build 082

INFO, NAME, MFn1
INFO, WEIGHT, 1.000
INFO, AREA, 1.000
INFO, LENGTH, 1.000
INFO, SHAPE, 0
INFO, COMMENT,
INFO, SEQUENCE FILE: VRMac_37K_6000s_VRMde_35K.seq


INFO, BACKGROUND DATA FILE:, None


STARTUPAXIS,X,4,LINEAR,AUTO,0.000000,0.000000
STARTUPAXIS,Y1,5,LINEAR,AUTO,0.000000,0.000000


STARTUPGROUP,Longitudinal
FIELDGROUP,Longitudinal,1,2,3,4,5,6,7,8,9,15,16,17,18,27,28
FIELDGROUP,Transverse,1,2,3,4,10,11,12,13,14,19,20,21,22,27,28

PLOT_APPEARANCE,ALL,HORZ_GRID_ON,VERT_GRID_ON,MARKERS_AND_LINES

[Data]
Time,Comment,Field (Oe),Temperature (K),Long Moment (emu),Long Scan Std Dev,Long Algorithm,Long Reg Fit,Long Percent Error (%),Trans Moment (emu),Trans Scan Std Dev,Trans Algorithm,Trans Reg Fit,Trans Percent Error (%),Long Moment [w/o ABS] (emu),Long Scan Std Dev [w/o ABS],Long Reg Fit [w/o ABS],Long Percent Error [w/o ABS] (%),Trans Moment [w/o ABS] (emu),Trans Scan Std Dev [w/o ABS],Trans Reg Fit [w/o ABS],Trans Percent Error [w/o ABS] (%),Points per Scan,Scans per Measurement,Scan Length (cm),Delta Temp (K),Rot Position (deg),Error,EC Comp. Running,Using ABS,
1524168711.743,,0.000000e+000,3.699522e+001,-1.804603e-004,0.000000e+000,3,9.921954e-001,0.000000e+000,,,,,,,,,,,,,,32,1,4.000000e+000,8.773804e-004,0.000000e+000,0,,0,
1524168737.211,,0.000000e+000,3.699786e+001,-1.854076e-004,0.000000e+000,3,9.927198e-001,0.000000e+000,,,,,,,,,,,,,,32,1,4.000000e+000,8.697510e-004,0.000000e+000,0,,0,
1524168762.169,,0.000000e+000,3.700005e+001,-1.878930e-004,0.000000e+000,3,9.926935e-001,0.000000e+000,,,,,,,,,,,,,,32,1,4.000000e+000,0.000000e+000,0.000000e+000,0,,0,
1524168787.099,,0.000000e+000,3.700005e+001,-1.895411e-004,0.000000e+000,3,9.926764e-001,0.000000e+000,,,,,,,,,,,,,,32,1,4.000000e+000,1.762390e-003,0.000000e+000,0,,0,
1524168812.040,,0.000000e+000,3.699917e+001,-1.907370e-004,0.000000e+000,3,9.926518e-001,0.000000e+000,,,,,,,,,,,,,,32,1,4.000000e+000,0.000000e+000,0.000000e+000,0,,0,
1524168836.963,,0.000000e+000,3.699917e+001,-1.917709e-004,0.000000e+000,3,9.927428e-001,0.000000e+000,,,,,,,,,,,,,,32,1,4.000000e+000,0.000000e+000,0.000000e+000,0,,0,
1524168861.940,,0.000000e+000,3.699873e+001,-1.927093e-004,0.000000e+000,3,9.927875e-001,0.000000e+000,,,,,,,,,,,,,,32,1,4.000000e+000,2.628326e-003,0.000000e+000,0,,0,
1524168886.876,,0.000000e+000,3.699873e+001,-1.934629e-004,0.000000e+000,3,9.928958e-001,0.000000e+000,,,,,,,,,,,,,,32,1,4.000000e+000,8.773804e-004,0.000000e+000,0,,0,
1524168911.419,,0.000000e+000,3.699873e+001,-1.941939e-004,0.000000e+000,3,9.928894e-001,0.000000e+000,,,,,,,,,,,,,,32,1,4.000000e+000,8.773804e-004,0.000000e+000,0,,0,
1524168936.589,,0.000000e+000,3.699786e+001,-1.946905e-004,0.000000e+000,3,9.929293e-001,0.000000e+000,,,,,,,,,,,,,,32,1,4.000000e+000,8.697510e-004,0.000000e+000,0,,0,
1524168961.669,,0.000000e+000,3.699873e+001,-1.952312e-004,0.000000e+000,3,9.926587e-001,0.000000e+000,,,,,,,,,,,,,,32,1,4.000000e+000,2.628326e-003,0.000000e+000,0,,0,
1524168986.287,,0.000000e+000,3.699829e+001,-1.957606e-004,0.000000e+000,3,9.929211e-001,0.000000e+000,,,,,,,,,,,,,,32,1,4.000000e+000,0.000000e+000,0.000000e+000,0,,0,
1524169011.220,,0.000000e+000,3.699829e+001,-1.961563e-004,0.000000e+000,3,9.928430e-001,0.000000e+000,,,,,,,,,,,,,,32,1,4.000000e+000,0.000000e+000,0.000000e+000,0,,0,
1524169036.090,,0.000000e+000,3.699786e+001,-1.965803e-004,0.000000e+000,3,9.928052e-001,0.000000e+000,,,,,,,,,,,,,,32,1,4.000000e+000,8.697510e-004,0.000000e+000,0,,0,
1524169061.468,,0.000000e+000,3.699829e+001,-1.968817e-004,0.000000e+000,3,9.927861e-001,0.000000e+000,,,,,,,,,,,,,,32,1,4.000000e+000,1.747131e-003,0.000000e+000,0,,0,
1524169085.996,,0.000000e+000,3.699742e+001,-1.973706e-004,0.000000e+000,3,9.928689e-001,0.000000e+000,,,,,,,,,,,,,,32,1,4.000000e+000,0.000000e+000,0.000000e+000,0,,0,
1524169111.024,,0.000000e+000,3.699917e+001,-1.977102e-004,0.000000e+000,3,9.928812e-001,0.000000e+000,,,,,,,,,,,,,,32,1,4.000000e+000,1.758575e-003,0.000000e+000,0,,0,
1524169135.729,,0.000000e+000,3.699741e+001,-1.979847e-004,0.000000e+000,3,9.928467e-001,0.000000e+000,,,,,,,,,,,,,,32,1,4.000000e+000,1.750946e-003,0.000000e+000,0,,0,
1524169160.727,,0.000000e+000,3.699698e+001,-1.983245e-004,0.000000e+000,3,9.930627e-001,0.000000e+000,,,,,,,,,,,,,,32,1,4.000000e+000,8.811951e-004,0.000000e+000,0,,0,
1524169185.658,,0.000000e+000,3.699741e+001,-1.986440e-004,0.000000e+000,3,9.928946e-001,0.000000e+000,,,,,,,,,,,,,,32,1,4.000000e+000,1.750946e-003,0.000000e+000,0,,0,
1524169210.483,,0.000000e+000,3.699786e+001,-1.989344e-004,0.000000e+000,3,9.930291e-001,0.000000e+000,,,,,,,,,,,,,,32,1,4.000000e+000,8.697510e-004,0.000000e+000,0,,0,
1524169235.553,,0.000000e+000,3.699829e+001,-1.991930e-004,0.000000e+000,3,9.929650e-001,0.000000e+000,,,,,,,,,,,,,,32,1,4.000000e+000,0.000000e+000,0.000000e+000,0,,0,
1524169260.579,,0.000000e+000,3.699961e+001,-1.993775e-004,0.000000e+000,3,9.928194e-001,0.000000e+000,,,,,,,,,,,,,,32,1,4.000000e+000,8.811951e-004,0.000000e+000,0,,0,
1524169285.822,,0.000000e+000,3.699786e+001,-1.996245e-004,0.000000e+000,3,9.928963e-001,0.000000e+000,,,,,,,,,,,,,,32,1,4.000000e+000,8.697510e-004,0.000000e+000,0,,0,
1524169310.369,,0.000000e+000,3.699829e+001,-1.998980e-004,0.000000e+000,3,9.929032e-001,0.000000e+000,,,,,,,,,,,,,,32,1,4.000000e+000,0.000000e+000,0.000000e+000,0,,0,
1524169334.987,,0.000000e+000,3.699742e+001,-2.001173e-004,0.000000e+000,3,9.930636e-001,0.000000e+000,,,,,,,,,,,,,,32,1,4.000000e+000,0.000000e+000,0.000000e+000,0,,0,
1524169359.785,,0.000000e+000,3.699391e+001,-2.003330e-004,0.000000e+000,3,9.930010e-001,0.000000e+000,,,,,,,,,,,,,,32,1,4.000000e+000,0.000000e+000,0.000000e+000,0,,0,
1524169384.816,,0.000000e+000,3.699697e+001,-2.005360e-004,0.000000e+000,3,9.928921e-001,0.000000e+000,,,,,,,,,,,,,,32,1,4.000000e+000,2.632141e-003,0.000000e+000,0,,0,
1524169409.666,,0.000000e+000,3.699610e+001,-2.006994e-004,0.000000e+000,3,9.930516e-001,0.000000e+000,,,,,,,,,,,,,,32,1,4.000000e+000,2.639771e-003,0.000000e+000,0,,0,
1524169434.574,,0.000000e+000,3.699479e+001,-2.009226e-004,0.000000e+000,3,9.929065e-001,0.000000e+000,,,,,,,,,,,,,,32,1,4.000000e+000,1.747131e-003,0.000000e+000,0,,0,
1524169459.507,,0.000000e+000,3.699873e+001,-2.011206e-004,0.000000e+000,3,9.931249e-001,0.000000e+000,,,,,,,,,,,,,,32,1,4.000000e+000,2.628326e-003,0.000000e+000,0,,0,
1524169484.445,,0.000000e+000,3.699741e+001,-2.013053e-004,0.000000e+000,3,9.929983e-001,0.000000e+000,,,,,,,,,,,,,,32,1,4.000000e+000,5.268097e-003,0.000000e+000,0,,0,
1524169509.435,,0.000000e+000,3.699610e+001,-2.014730e-004,0.000000e+000,3,9.929451e-001,0.000000e+000,,,,,,,,,,,,,,32,1,4.000000e+000,8.811951e-004,0.000000e+000,0,,0,
1524169534.300,,0.000000e+000,3.699786e+001,-2.016884e-004,0.000000e+000,3,9.930229e-001,0.000000e+000,,,,,,,,,,,,,,32,1,4.000000e+000,2.628326e-003,0.000000e+000,0,,0,
1524169559.228,,0.000000e+000,3.700093e+001,-2.018401e-004,0.000000e+000,3,9.930799e-001,0.000000e+000,,,,,,,,,,,,,,32,1,4.000000e+000,0.000000e+000,0.000000e+000,0,,0,
1524169584.226,,0.000000e+000,3.699698e+001,-2.020133e-004,0.000000e+000,3,9.929470e-001,0.000000e+000,,,,,,,,,,,,,,32,1,4.000000e+000,8.811951e-004,0.000000e+000,0,,0,
1524169609.089,,0.000000e+000,3.699918e+001,-2.021490e-004,0.000000e+000,3,9.930659e-001,0.000000e+000,,,,,,,,,,,,,,32,1,4.000000e+000,5.268097e-003,0.000000e+000,0,,0,
1524169634.104,,0.000000e+000,3.700005e+001,-2.023013e-004,0.000000e+000,3,9.930057e-001,0.000000e+000,,,,,,,,,,,,,,32,1,4.000000e+000,3.517151e-003,0.000000e+000,0,,0,
1524169658.937,,0.000000e+000,3.700005e+001,-2.024384e-004,0.000000e+000,3,9.931633e-001,0.000000e+000,,,,,,,,,,,,,,32,1,4.000000e+000,3.517151e-003,0.000000e+000,0,,0,
1524169683.880,,0.000000e+000,3.700181e+001,-2.025983e-004,0.000000e+000,3,9.930357e-001,0.000000e+000,,,,,,,,,,,,,,32,1,4.000000e+000,0.000000e+000,0.000000e+000,0,,0,
1524169708.798,,0.000000e+000,3.699873e+001,-2.027572e-004,0.000000e+000,3,9.933558e-001,0.000000e+000,,,,,,,,,,,,,,32,1,4.000000e+000,6.149292e-003,0.000000e+000,0,,0,
1524169733.746,,0.000000e+000,3.699742e+001,-2.029139e-004,0.000000e+000,3,9.930639e-001,0.000000e+000,,,,,,,,,,,,,,32,1,4.000000e+000,0.000000e+000,0.000000e+000,0,,0,
1524169758.753,,0.000000e+000,3.699786e+001,-2.029782e-004,0.000000e+000,3,9.929814e-001,0.000000e+000,,,,,,,,,,,,,,32,1,4.000000e+000,4.390717e-003,0.000000e+000,0,,0,
1524169783.624,,0.000000e+000,3.699829e+001,-2.031333e-004,0.000000e+000,3,9.928920e-001,0.000000e+000,,,,,,,,,,,,,,32,1,4.000000e+000,1.747131e-003,0.000000e+000,0,,0,
1524169808.549,,0.000000e+000,3.699786e+001,-2.032527e-004,0.000000e+000,3,9.931337e-001,0.000000e+000,,,,,,,,,,,,,,32,1,4.000000e+000,7.896423e-003,0.000000e+000,0,,0,
1524169833.482,,0.000000e+000,3.699698e+001,-2.034164e-004,0.000000e+000,3,9.930426e-001,0.000000e+000,,,,,,,,,,,,,,32,1,4.000000e+000,8.811951e-004,0.000000e+000,0,,0,
1524169858.562,,0.000000e+000,3.699391e+001,-2.035013e-004,0.000000e+000,3,9.931223e-001,0.000000e+000,,,,,,,,,,,,,,32,1,4.000000e+000,0.000000e+000,0.000000e+000,0,,0,
1524169884.528,,0.000000e+000,3.699873e+001,-2.037075e-004,0.000000e+000,3,9.930406e-001,0.000000e+000,,,,,,,,,,,,,,32,1,4.000000e+000,7.907867e-003,0.000000e+000,0,,0,
1524169909.461,,0.000000e+000,3.699873e+001,-2.038173e-004,0.000000e+000,3,9.929848e-001,0.000000e+000,,,,,,,,,,,,,,32,1,4.000000e+000,8.773804e-004,0.000000e+000,0,,0,
1524169933.841,,0.000000e+000,3.699435e+001,-2.039368e-004,0.000000e+000,3,9.929131e-001,0.000000e+000,,,,,,,,,,,,,,32,1,4.000000e+000,8.697510e-004,0.000000e+000,0,,0,
1524169959.326,,0.000000e+000,3.699610e+001,-2.040700e-004,0.000000e+000,3,9.931196e-001,0.000000e+000,,,,,,,,,,,,,,32,1,4.000000e+000,4.379272e-003,0.000000e+000,0,,0,
1524169984.262,,0.000000e+000,3.699829e+001,-2.041613e-004,0.000000e+000,3,9.930141e-001,0.000000e+000,,,,,,,,,,,,,,32,1,4.000000e+000,5.271912e-003,0.000000e+000,0,,0,
1524170009.195,,0.000000e+000,3.699961e+001,-2.042883e-004,0.000000e+000,3,9.929973e-001,0.000000e+000,,,,,,,,,,,,,,32,1,4.000000e+000,8.811951e-004,0.000000e+000,0,,0,
1524170034.373,,0.000000e+000,3.699961e+001,-2.043813e-004,0.000000e+000,3,9.932150e-001,0.000000e+000,,,,,,,,,,,,,,32,1,4.000000e+000,4.386902e-003,0.000000e+000,0,,0,
1524170059.685,,0.000000e+000,3.699829e+001,-2.044741e-004,0.000000e+000,3,9.932252e-001,0.000000e+000,,,,,,,,,,,,,,32,1,4.000000e+000,1.747131e-003,0.000000e+000,0,,0,
1524170084.901,,0.000000e+000,3.699390e+001,-2.045801e-004,0.000000e+000,3,9.930238e-001,0.000000e+000,,,,,,,,,,,,,,32,1,4.000000e+000,1.750946e-003,0.000000e+000,0,,0,
1524170109.876,,0.000000e+000,3.699741e+001,-2.047400e-004,0.000000e+000,3,9.931538e-001,0.000000e+000,,,,,,,,,,,,,,32,1,4.000000e+000,5.268097e-003,0.000000e+000,0,,0,
1524170134.789,,0.000000e+000,3.699786e+001,-2.047972e-004,0.000000e+000,3,9.930363e-001,0.000000e+000,,,,,,,,,,,,,,32,1,4.000000e+000,8.697510e-004,0.000000e+000,0,,0,
1524170159.707,,0.000000e+000,3.699829e+001,-2.049488e-004,0.000000e+000,3,9.931093e-001,0.000000e+000,,,,,,,,,,,,,,32,1,4.000000e+000,1.747131e-003,0.000000e+000,0,,0,
1524170185.817,,0.000000e+000,3.699697e+001,-2.050022e-004,0.000000e+000,3,9.929754e-001,0.000000e+000,,,,,,,,,,,,,,32,1,4.000000e+000,4.386902e-003,0.000000e+000,0,,0,
1524170210.750,,0.000000e+000,3.699918e+001,-2.051226e-004,0.000000e+000,3,9.930558e-001,0.000000e+000,,,,,,,,,,,,,,32,1,4.000000e+000,3.509521e-003,0.000000e+000,0,,0,
1524170235.691,,0.000000e+000,3.699654e+001,-2.052270e-004,0.000000e+000,3,9.930369e-001,0.000000e+000,,,,,,,,,,,,,,32,1,4.000000e+000,0.000000e+000,0.000000e+000,0,,0,
1524170260.638,,0.000000e+000,3.699698e+001,-2.053080e-004,0.000000e+000,3,9.931041e-001,0.000000e+000,,,,,,,,,,,,,,32,1,4.000000e+000,8.811951e-004,0.000000e+000,0,,0,
1524170284.974,,0.000000e+000,3.699741e+001,-2.054103e-004,0.000000e+000,3,9.930295e-001,0.000000e+000,,,,,,,,,,,,,,32,1,4.000000e+000,3.509521e-003,0.000000e+000,0,,0,
1524170309.952,,0.000000e+000,3.699918e+001,-2.055213e-004,0.000000e+000,3,9.930545e-001,0.000000e+000,,,,,,,,,,,,,,32,1,4.000000e+000,3.509521e-003,0.000000e+000,0,,0,
1524170334.844,,0.000000e+000,3.699873e+001,-2.056152e-004,0.000000e+000,3,9.931015e-001,0.000000e+000,,,,,,,,,,,,,,32,1,4.000000e+000,2.628326e-003,0.000000e+000,0,,0,
1524170360.395,,0.000000e+000,3.700005e+001,-2.057160e-004,0.000000e+000,3,9.931197e-001,0.000000e+000,,,,,,,,,,,,,,32,1,4.000000e+000,5.268097e-003,0.000000e+000,0,,0,
1524170385.320,,0.000000e+000,3.699961e+001,-2.057854e-004,0.000000e+000,3,9.930338e-001,0.000000e+000,,,,,,,,,,,,,,32,1,4.000000e+000,8.811951e-004,0.000000e+000,0,,0,
1524170410.248,,0.000000e+000,3.699829e+001,-2.058905e-004,0.000000e+000,3,9.930451e-001,0.000000e+000,,,,,,,,,,,,,,32,1,4.000000e+000,1.747131e-003,0.000000e+000,0,,0,
1524170435.518,,0.000000e+000,3.699873e+001,-2.058562e-004,0.000000e+000,3,9.929142e-001,0.000000e+000,,,,,,,,,,,,,,32,1,4.000000e+000,2.628326e-003,0.000000e+000,0,,0,
1524170460.814,,0.000000e+000,3.699741e+001,-2.059999e-004,0.000000e+000,3,9.932234e-001,0.000000e+000,,,,,,,,,,,,,,32,1,4.000000e+000,1.750946e-003,0.000000e+000,0,,0,
1524170485.964,,0.000000e+000,3.699698e+001,-2.060985e-004,0.000000e+000,3,9.931561e-001,0.000000e+000,,,,,,,,,,,,,,32,1,4.000000e+000,8.811951e-004,0.000000e+000,0,,0,
1524170510.882,,0.000000e+000,3.699873e+001,-2.061831e-004,0.000000e+000,3,9.931372e-001,0.000000e+000,,,,,,,,,,,,,,32,1,4.000000e+000,2.628326e-003,0.000000e+000,0,,0,
1524170535.840,,0.000000e+000,3.699829e+001,-2.063006e-004,0.000000e+000,3,9.930659e-001,0.000000e+000,,,,,,,,,,,,,,32,1,4.000000e+000,5.271912e-003,0.000000e+000,0,,0,
1524170560.805,,0.000000e+000,3.699786e+001,-2.063345e-004,0.000000e+000,3,9.930995e-001,0.000000e+000,,,,,,,,,,,,,,32,1,4.000000e+000,2.628326e-003,0.000000e+000,0,,0,
1524170585.668,,0.000000e+000,3.699566e+001,-2.064578e-004,0.000000e+000,3,9.930155e-001,0.000000e+000,,,,,,,,,,,,,,32,1,4.000000e+000,1.758575e-003,0.000000e+000,0,,0,
1524170610.666,,0.000000e+000,3.699654e+001,-2.064907e-004,0.000000e+000,3,9.930146e-001,0.000000e+000,,,,,,,,,,,,,,32,1,4.000000e+000,3.509521e-003,0.000000e+000,0,,0,
1524170635.579,,0.000000e+000,3.699786e+001,-2.065899e-004,0.000000e+000,3,9.929965e-001,0.000000e+000,,,,,,,,,,,,,,32,1,4.000000e+000,2.628326e-003,0.000000e+000,0,,0,
1524170660.489,,0.000000e+000,3.699566e+001,-2.066541e-004,0.000000e+000,3,9.931189e-001,0.000000e+000,,,,,,,,,,,,,,32,1,4.000000e+000,1.758575e-003,0.000000e+000,0,,0,
1524170685.440,,0.000000e+000,3.699786e+001,-2.067531e-004,0.000000e+000,3,9.930767e-001,0.000000e+000,,,,,,,,,,,,,,32,1,4.000000e+000,8.697510e-004,0.000000e+000,0,,0,
1524170710.340,,0.000000e+000,3.699654e+001,-2.068066e-004,0.000000e+000,3,9.931464e-001,0.000000e+000,,,,,,,,,,,,,,32,1,4.000000e+000,0.000000e+000,0.000000e+000,0,,0,
1524170735.350,,0.000000e+000,3.699741e+001,-2.068959e-004,0.000000e+000,3,9.931612e-001,0.000000e+000,,,,,,,,,,,,,,32,1,4.000000e+000,3.509521e-003,0.000000e+000,0,,0,
1524170760.196,,0.000000e+000,3.699961e+001,-2.069439e-004,0.000000e+000,3,9.931421e-001,0.000000e+000,,,,,,,,,,,,,,32,1,4.000000e+000,8.811951e-004,0.000000e+000,0,,0,
1524170785.159,,0.000000e+000,3.699786e+001,-2.070606e-004,0.000000e+000,3,9.931417e-001,0.000000e+000,,,,,,,,,,,,,,32,1,4.000000e+000,2.628326e-003,0.000000e+000,0,,0,
1524170810.409,,0.000000e+000,3.699829e+001,-2.071264e-004,0.000000e+000,3,9.932016e-001,0.000000e+000,,,,,,,,,,,,,,32,1,4.000000e+000,0.000000e+000,0.000000e+000,0,,0,
1524170835.274,,0.000000e+000,3.699829e+001,-2.071920e-004,0.000000e+000,3,9.932495e-001,0.000000e+000,,,,,,,,,,,,,,32,1,4.000000e+000,1.747131e-003,0.000000e+000,0,,0,
1524170860.380,,0.000000e+000,3.699829e+001,-2.072323e-004,0.000000e+000,3,9.932410e-001,0.000000e+000,,,,,,,,,,,,,,32,1,4.000000e+000,0.000000e+000,0.000000e+000,0,,0,
1524170885.788,,0.000000e+000,3.700137e+001,-2.072859e-004,0.000000e+000,3,9.929712e-001,0.000000e+000,,,,,,,,,,,,,,32,1,4.000000e+000,4.390717e-003,0.000000e+000,0,,0,
1524170910.878,,0.000000e+000,3.699873e+001,-2.073856e-004,0.000000e+000,3,9.931883e-001,0.000000e+000,,,,,,,,,,,,,,32,1,4.000000e+000,8.773804e-004,0.000000e+000,0,,0,
1524170935.896,,0.000000e+000,3.699873e+001,-2.075047e-004,0.000000e+000,3,9.932032e-001,0.000000e+000,,,,,,,,,,,,,,32,1,4.000000e+000,8.773804e-004,0.000000e+000,0,,0,
1524170961.401,,0.000000e+000,3.700049e+001,-2.075043e-004,0.000000e+000,3,9.931761e-001,0.000000e+000,,,,,,,,,,,,,,32,1,4.000000e+000,8.811951e-004,0.000000e+000,0,,0,
1524170986.569,,0.000000e+000,3.699741e+001,-2.076838e-004,0.000000e+000,3,9.932578e-001,0.000000e+000,,,,,,,,,,,,,,32,1,4.000000e+000,1.750946e-003,0.000000e+000,0,,0,
1524171011.567,,0.000000e+000,3.699697e+001,-2.075458e-004,0.000000e+000,3,9.931713e-001,0.000000e+000,,,,,,,,,,,,,,32,1,4.000000e+000,4.386902e-003,0.000000e+000,0,,0,
1524171038.310,,0.000000e+000,3.700180e+001,-2.078102e-004,0.000000e+000,3,9.926015e-001,0.000000e+000,,,,,,,,,,,,,,32,1,4.000000e+000,5.271912e-003,0.000000e+000,0,,0,
1524171063.225,,0.000000e+000,3.699917e+001,-2.078176e-004,0.000000e+000,3,9.931573e-001,0.000000e+000,,,,,,,,,,,,,,32,1,4.000000e+000,1.758575e-003,0.000000e+000,0,,0,
1524171087.588,,0.000000e+000,3.699961e+001,-2.077315e-004,0.000000e+000,3,9.929730e-001,0.000000e+000,,,,,,,,,,,,,,32,1,4.000000e+000,2.639771e-003,0.000000e+000,0,,0,
1524171113.118,,0.000000e+000,3.699918e+001,-2.079617e-004,0.000000e+000,3,9.932860e-001,0.000000e+000,,,,,,,,,,,,,,32,1,4.000000e+000,5.268097e-003,0.000000e+000,0,,0,
1524171137.461,,0.000000e+000,3.699829e+001,-2.080328e-004,0.000000e+000,3,9.930313e-001,0.000000e+000,,,,,,,,,,,,,,32,1,4.000000e+000,1.747131e-003,0.000000e+000,0,,0,
1524171162.964,,0.000000e+000,3.699567e+001,-2.080723e-004,0.000000e+000,3,9.931294e-001,0.000000e+000,,,,,,,,,,,,,,32,1,4.000000e+000,3.509521e-003,0.000000e+000,0,,0,
1524171187.902,,0.000000e+000,3.699741e+001,-2.079944e-004,0.000000e+000,3,9.928496e-001,0.000000e+000,,,,,,,,,,,,,,32,1,4.000000e+000,3.509521e-003,0.000000e+000,0,,0,
1524171212.272,,0.000000e+000,3.699786e+001,-2.082211e-004,0.000000e+000,3,9.931247e-001,0.000000e+000,,,,,,,,,,,,,,32,1,4.000000e+000,8.697510e-004,0.000000e+000,0,,0,
1524171237.203,,0.000000e+000,3.700049e+001,-2.082729e-004,0.000000e+000,3,9.928626e-001,0.000000e+000,,,,,,,,,,,,,,32,1,4.000000e+000,2.639771e-003,0.000000e+000,0,,0,
1524171262.148,,0.000000e+000,3.699917e+001,-2.083567e-004,0.000000e+000,3,9.932320e-001,0.000000e+000,,,,,,,,,,,,,,32,1,4.000000e+000,1.758575e-003,0.000000e+000,0,,0,
1524171287.318,,0.000000e+000,3.700093e+001,-2.083669e-004,0.000000e+000,3,9.930410e-001,0.000000e+000,,,,,,,,,,,,,,32,1,4.000000e+000,3.520966e-003,0.000000e+000,0,,0,
1524171312.589,,0.000000e+000,3.700005e+001,-2.084376e-004,0.000000e+000,3,9.930774e-001,0.000000e+000,,,,,,,,,,,,,,32,1,4.000000e+000,5.268097e-003,0.000000e+000,0,,0,
1524171336.942,,0.000000e+000,3.700049e+001,-2.086250e-004,0.000000e+000,3,9.933874e-001,0.000000e+000,,,,,,,,,,,,,,32,1,4.000000e+000,2.639771e-003,0.000000e+000,0,,0,
1524171361.902,,0.000000e+000,3.699829e+001,-2.085727e-004,0.000000e+000,3,9.931819e-001,0.000000e+000,,,,,,,,,,,,,,32,1,4.000000e+000,1.747131e-003,0.000000e+000,0,,0,
1524171387.435,,0.000000e+000,3.699961e+001,-2.086615e-004,0.000000e+000,3,9.932340e-001,0.000000e+000,,,,,,,,,,,,,,32,1,4.000000e+000,8.811951e-004,0.000000e+000,0,,0,
1524171412.630,,0.000000e+000,3.699918e+001,-2.085149e-004,0.000000e+000,3,9.932461e-001,0.000000e+000,,,,,,,,,,,,,,32,1,4.000000e+000,7.030487e-003,0.000000e+000,0,,0,
1524171438.458,,0.000000e+000,3.699829e+001,-2.087097e-004,0.000000e+000,3,9.933065e-001,0.000000e+000,,,,,,,,,,,,,,32,1,4.000000e+000,1.747131e-003,0.000000e+000,0,,0,
1524171463.169,,0.000000e+000,3.699741e+001,-2.087624e-004,0.000000e+000,3,9.932007e-001,0.000000e+000,,,,,,,,,,,,,,32,1,4.000000e+000,1.750946e-003,0.000000e+000,0,,0,
1524171488.189,,0.000000e+000,3.699741e+001,-2.088228e-004,0.000000e+000,3,9.931872e-001,0.000000e+000,,,,,,,,,,,,,,32,1,4.000000e+000,3.509521e-003,0.000000e+000,0,,0,
1524171512.974,,0.000000e+000,3.699917e+001,-2.089399e-004,0.000000e+000,3,9.932026e-001,0.000000e+000,,,,,,,,,,,,,,32,1,4.000000e+000,0.000000e+000,0.000000e+000,0,,0,
1524171537.910,,0.000000e+000,3.699829e+001,-2.088262e-004,0.000000e+000,3,9.932343e-001,0.000000e+000,,,,,,,,,,,,,,32,1,4.000000e+000,1.747131e-003,0.000000e+000,0,,0,
1524171562.838,,0.000000e+000,3.699961e+001,-2.090207e-004,0.000000e+000,3,9.930909e-001,0.000000e+000,,,,,,,,,,,,,,32,1,4.000000e+000,8.811951e-004,0.000000e+000,0,,0,
1524171587.815,,0.000000e+000,3.699610e+001,-2.090826e-004,0.000000e+000,3,9.931849e-001,0.000000e+000,,,,,,,,,,,,,,32,1,4.000000e+000,4.379272e-003,0.000000e+000,0,,0,
1524171612.698,,0.000000e+000,3.699873e+001,-2.090959e-004,0.000000e+000,3,9.931195e-001,0.000000e+000,,,,,,,,,,,,,,32,1,4.000000e+000,8.773804e-004,0.000000e+000,0,,0,
1524171637.691,,0.000000e+000,3.700225e+001,-2.091526e-004,0.000000e+000,3,9.931452e-001,0.000000e+000,,,,,,,,,,,,,,32,1,4.000000e+000,8.811951e-004,0.000000e+000,0,,0,
1524171662.876,,0.000000e+000,3.699829e+001,-2.091596e-004,0.000000e+000,3,9.933368e-001,0.000000e+000,,,,,,,,,,,,,,32,1,4.000000e+000,0.000000e+000,0.000000e+000,0,,0,
1524171688.014,,0.000000e+000,3.699961e+001,-2.092286e-004,0.000000e+000,3,9.931425e-001,0.000000e+000,,,,,,,,,,,,,,32,1,4.000000e+000,8.811951e-004,0.000000e+000,0,,0,
1524171713.490,,0.000000e+000,3.699917e+001,-2.093196e-004,0.000000e+000,3,9.931031e-001,0.000000e+000,,,,,,,,,,,,,,32,1,4.000000e+000,0.000000e+000,0.000000e+000,0,,0,
1524171738.400,,0.000000e+000,3.699961e+001,-2.094142e-004,0.000000e+000,3,9.931611e-001,0.000000e+000,,,,,,,,,,,,,,32,1,4.000000e+000,8.811951e-004,0.000000e+000,0,,0,
1524171763.290,,0.000000e+000,3.699873e+001,-2.094034e-004,0.000000e+000,3,9.932106e-001,0.000000e+000,,,,,,,,,,,,,,32,1,4.000000e+000,8.773804e-004,0.000000e+000,0,,0,
1524171788.226,,0.000000e+000,3.699873e+001,-2.094712e-004,0.000000e+000,3,9.931542e-001,0.000000e+000,,,,,,,,,,,,,,32,1,4.000000e+000,8.773804e-004,0.000000e+000,0,,0,
1524171813.059,,0.000000e+000,3.699917e+001,-2.095181e-004,0.000000e+000,3,9.932030e-001,0.000000e+000,,,,,,,,,,,,,,32,1,4.000000e+000,0.000000e+000,0.000000e+000,0,,0,
1524171838.776,,0.000000e+000,3.699873e+001,-2.095656e-004,0.000000e+000,3,9.932048e-001,0.000000e+000,,,,,,,,,,,,,,32,1,4.000000e+000,8.773804e-004,0.000000e+000,0,,0,
1524171863.707,,0.000000e+000,3.699829e+001,-2.096336e-004,0.000000e+000,3,9.933208e-001,0.000000e+000,,,,,,,,,,,,,,32,1,4.000000e+000,3.509521e-003,0.000000e+000,0,,0,
1524171888.750,,0.000000e+000,3.699829e+001,-2.096105e-004,0.000000e+000,3,9.931416e-001,0.000000e+000,,,,,,,,,,,,,,32,1,4.000000e+000,1.747131e-003,0.000000e+000,0,,0,
1524171913.700,,0.000000e+000,3.699786e+001,-2.096920e-004,0.000000e+000,3,9.932193e-001,0.000000e+000,,,,,,,,,,,,,,32,1,4.000000e+000,4.390717e-003,0.000000e+000,0,,0,
1524171939.948,,0.000000e+000,3.699873e+001,-2.097534e-004,0.000000e+000,3,9.932457e-001,0.000000e+000,,,,,,,,,,,,,,32,1,4.000000e+000,8.773804e-004,0.000000e+000,0,,0,
1524171964.803,,0.000000e+000,3.699917e+001,-2.098184e-004,0.000000e+000,3,9.930975e-001,0.000000e+000,,,,,,,,,,,,,,32,1,4.000000e+000,0.000000e+000,0.000000e+000,0,,0,
1524171989.829,,0.000000e+000,3.699829e+001,-2.098575e-004,0.000000e+000,3,9.931355e-001,0.000000e+000,,,,,,,,,,,,,,32,1,4.000000e+000,1.747131e-003,0.000000e+000,0,,0,
1524172014.649,,0.000000e+000,3.699829e+001,-2.098539e-004,0.000000e+000,3,9.930479e-001,0.000000e+000,,,,,,,,,,,,,,32,1,4.000000e+000,0.000000e+000,0.000000e+000,0,,0,
1524172039.790,,0.000000e+000,3.700093e+001,-2.100113e-004,0.000000e+000,3,9.930616e-001,0.000000e+000,,,,,,,,,,,,,,32,1,4.000000e+000,1.758575e-003,0.000000e+000,0,,0,
1524172064.315,,0.000000e+000,3.699917e+001,-2.099331e-004,0.000000e+000,3,9.930563e-001,0.000000e+000,,,,,,,,,,,,,,32,1,4.000000e+000,1.758575e-003,0.000000e+000,0,,0,
1524172090.230,,0.000000e+000,3.700137e+001,-2.100079e-004,0.000000e+000,3,9.931971e-001,0.000000e+000,,,,,,,,,,,,,,32,1,4.000000e+000,2.639771e-003,0.000000e+000,0,,0,
1524172115.386,,0.000000e+000,3.699961e+001,-2.101623e-004,0.000000e+000,3,9.932257e-001,0.000000e+000,,,,,,,,,,,,,,32,1,4.000000e+000,8.811951e-004,0.000000e+000,0,,0,
1524172140.334,,0.000000e+000,3.699917e+001,-2.102345e-004,0.000000e+000,3,9.934805e-001,0.000000e+000,,,,,,,,,,,,,,32,1,4.000000e+000,0.000000e+000,0.000000e+000,0,,0,
1524172165.525,,0.000000e+000,3.699786e+001,-2.100588e-004,0.000000e+000,3,9.930780e-001,0.000000e+000,,,,,,,,,,,,,,32,1,4.000000e+000,8.697510e-004,0.000000e+000,0,,0,
1524172191.587,,0.000000e+000,3.699610e+001,-2.100694e-004,0.000000e+000,3,9.930618e-001,0.000000e+000,,,,,,,,,,,,,,32,1,4.000000e+000,2.639771e-003,0.000000e+000,0,,0,
1524172216.565,,0.000000e+000,3.699829e+001,-2.102879e-004,0.000000e+000,3,9.932080e-001,0.000000e+000,,,,,,,,,,,,,,32,1,4.000000e+000,3.509521e-003,0.000000e+000,0,,0,
1524172241.465,,0.000000e+000,3.699961e+001,-2.103022e-004,0.000000e+000,3,9.930793e-001,0.000000e+000,,,,,,,,,,,,,,32,1,4.000000e+000,8.811951e-004,0.000000e+000,0,,0,
1524172266.998,,0.000000e+000,3.700005e+001,-2.103833e-004,0.000000e+000,3,9.932483e-001,0.000000e+000,,,,,,,,,,,,,,32,1,4.000000e+000,1.762390e-003,0.000000e+000,0,,0,
1524172291.951,,0.000000e+000,3.700005e+001,-2.104018e-004,0.000000e+000,3,9.929766e-001,0.000000e+000,,,,,,,,,,,,,,32,1,4.000000e+000,0.000000e+000,0.000000e+000,0,,0,
1524172316.309,,0.000000e+000,3.700049e+001,-2.104538e-004,0.000000e+000,3,9.931931e-001,0.000000e+000,,,,,,,,,,,,,,32,1,4.000000e+000,8.811951e-004,0.000000e+000,0,,0,
1524172342.054,,0.000000e+000,3.699786e+001,-2.105418e-004,0.000000e+000,3,9.934077e-001,0.000000e+000,,,,,,,,,,,,,,32,1,4.000000e+000,4.390717e-003,0.000000e+000,0,,0,
1524172367.135,,0.000000e+000,3.699918e+001,-2.103360e-004,0.000000e+000,3,9.932457e-001,0.000000e+000,,,,,,,,,,,,,,32,1,4.000000e+000,5.268097e-003,0.000000e+000,0,,0,
1524172392.603,,0.000000e+000,3.699741e+001,-2.106083e-004,0.000000e+000,3,9.932031e-001,0.000000e+000,,,,,,,,,,,,,,32,1,4.000000e+000,1.750946e-003,0.000000e+000,0,,0,
1524172417.533,,0.000000e+000,3.700225e+001,-2.106564e-004,0.000000e+000,3,9.931831e-001,0.000000e+000,,,,,,,,,,,,,,32,1,4.000000e+000,8.811951e-004,0.000000e+000,0,,0,
1524172442.543,,0.000000e+000,3.699786e+001,-2.106530e-004,0.000000e+000,3,9.930400e-001,0.000000e+000,,,,,,,,,,,,,,32,1,4.000000e+000,8.697510e-004,0.000000e+000,0,,0,
1524172467.409,,0.000000e+000,3.699566e+001,-2.105925e-004,0.000000e+000,3,9.930099e-001,0.000000e+000,,,,,,,,,,,,,,32,1,4.000000e+000,0.000000e+000,0.000000e+000,0,,0,
1524172492.497,,0.000000e+000,3.700005e+001,-2.108534e-004,0.000000e+000,3,9.932573e-001,0.000000e+000,,,,,,,,,,,,,,32,1,4.000000e+000,5.268097e-003,0.000000e+000,0,,0,
1524172517.354,,0.000000e+000,3.699961e+001,-2.108032e-004,0.000000e+000,3,9.928070e-001,0.000000e+000,,,,,,,,,,,,,,32,1,4.000000e+000,8.811951e-004,0.000000e+000,0,,0,
1524172542.217,,0.000000e+000,3.700093e+001,-2.108677e-004,0.000000e+000,3,9.931437e-001,0.000000e+000,,,,,,,,,,,,,,32,1,4.000000e+000,1.758575e-003,0.000000e+000,0,,0,
1524172567.283,,0.000000e+000,3.699829e+001,-2.108344e-004,0.000000e+000,3,9.930783e-001,0.000000e+000,,,,,,,,,,,,,,32,1,4.000000e+000,0.000000e+000,0.000000e+000,0,,0,
1524172592.128,,0.000000e+000,3.699961e+001,-2.109060e-004,0.000000e+000,3,9.931697e-001,0.000000e+000,,,,,,,,,,,,,,32,1,4.000000e+000,2.639771e-003,0.000000e+000,0,,0,
1524172617.038,,0.000000e+000,3.699698e+001,-2.109997e-004,0.000000e+000,3,9.930567e-001,0.000000e+000,,,,,,,,,,,,,,32,1,4.000000e+000,8.811951e-004,0.000000e+000,0,,0,
1524172642.019,,0.000000e+000,3.700093e+001,-2.110319e-004,0.000000e+000,3,9.933349e-001,0.000000e+000,,,,,,,,,,,,,,32,1,4.000000e+000,1.758575e-003,0.000000e+000,0,,0,
1524172666.904,,0.000000e+000,3.699829e+001,-2.109944e-004,0.000000e+000,3,9.931900e-001,0.000000e+000,,,,,,,,,,,,,,32,1,4.000000e+000,0.000000e+000,0.000000e+000,0,,0,
1524172693.027,,0.000000e+000,3.699741e+001,-2.110343e-004,0.000000e+000,3,9.929441e-001,0.000000e+000,,,,,,,,,,,,,,32,1,4.000000e+000,1.750946e-003,0.000000e+000,0,,0,
1524172717.387,,0.000000e+000,3.700049e+001,-2.111264e-004,0.000000e+000,3,9.933399e-001,0.000000e+000,,,,,,,,,,,,,,32,1,4.000000e+000,4.398346e-003,0.000000e+000,0,,0,
1524172742.385,,0.000000e+000,3.700137e+001,-2.111533e-004,0.000000e+000,3,9.931300e-001,0.000000e+000,,,,,,,,,,,,,,32,1,4.000000e+000,8.773804e-004,0.000000e+000,0,,0,
1524172767.866,,0.000000e+000,3.699873e+001,-2.111764e-004,0.000000e+000,3,9.931654e-001,0.000000e+000,,,,,,,,,,,,,,32,1,4.000000e+000,2.628326e-003,0.000000e+000,0,,0,
1524172793.126,,0.000000e+000,3.699697e+001,-2.112446e-004,0.000000e+000,3,9.930960e-001,0.000000e+000,,,,,,,,,,,,,,32,1,4.000000e+000,2.632141e-003,0.000000e+000,0,,0,
1524172818.614,,0.000000e+000,3.699873e+001,-2.113074e-004,0.000000e+000,3,9.932130e-001,0.000000e+000,,,,,,,,,,,,,,32,1,4.000000e+000,8.773804e-004,0.000000e+000,0,,0,
1524172843.514,,0.000000e+000,3.699478e+001,-2.111549e-004,0.000000e+000,3,9.932383e-001,0.000000e+000,,,,,,,,,,,,,,32,1,4.000000e+000,0.000000e+000,0.000000e+000,0,,0,
1524172868.525,,0.000000e+000,3.699654e+001,-2.112924e-004,0.000000e+000,3,9.931608e-001,0.000000e+000,,,,,,,,,,,,,,32,1,4.000000e+000,1.762390e-003,0.000000e+000,0,,0,
1524172893.405,,0.000000e+000,3.699829e+001,-2.113475e-004,0.000000e+000,3,9.930436e-001,0.000000e+000,,,,,,,,,,,,,,32,1,4.000000e+000,3.509521e-003,0.000000e+000,0,,0,
1524172918.415,,0.000000e+000,3.700005e+001,-2.113936e-004,0.000000e+000,3,9.931016e-001,0.000000e+000,,,,,,,,,,,,,,32,1,4.000000e+000,1.762390e-003,0.000000e+000,0,,0,
1524172943.286,,0.000000e+000,3.699829e+001,-2.115510e-004,0.000000e+000,3,9.927643e-001,0.000000e+000,,,,,,,,,,,,,,32,1,4.000000e+000,3.509521e-003,0.000000e+000,0,,0,
1524172968.224,,0.000000e+000,3.699873e+001,-2.115862e-004,0.000000e+000,3,9.934080e-001,0.000000e+000,,,,,,,,,,,,,,32,1,4.000000e+000,2.628326e-003,0.000000e+000,0,,0,
1524172993.289,,0.000000e+000,3.699697e+001,-2.115578e-004,0.000000e+000,3,9.931147e-001,0.000000e+000,,,,,,,,,,,,,,32,1,4.000000e+000,4.386902e-003,0.000000e+000,0,,0,
1524173018.232,,0.000000e+000,3.699786e+001,-2.116030e-004,0.000000e+000,3,9.929926e-001,0.000000e+000,,,,,,,,,,,,,,32,1,4.000000e+000,8.697510e-004,0.000000e+000,0,,0,
1524173043.155,,0.000000e+000,3.699873e+001,-2.115777e-004,0.000000e+000,3,9.932689e-001,0.000000e+000,,,,,,,,,,,,,,32,1,4.000000e+000,8.773804e-004,0.000000e+000,0,,0,
1524173068.105,,0.000000e+000,3.699918e+001,-2.116233e-004,0.000000e+000,3,9.931941e-001,0.000000e+000,,,,,,,,,,,,,,32,1,4.000000e+000,3.509521e-003,0.000000e+000,0,,0,
1524173092.895,,0.000000e+000,3.699873e+001,-2.116455e-004,0.000000e+000,3,9.931195e-001,0.000000e+000,,,,,,,,,,,,,,32,1,4.000000e+000,6.149292e-003,0.000000e+000,0,,0,
1524173118.113,,0.000000e+000,3.699741e+001,-2.117829e-004,0.000000e+000,3,9.930678e-001,0.000000e+000,,,,,,,,,,,,,,32,1,4.000000e+000,1.750946e-003,0.000000e+000,0,,0,
1524173143.789,,0.000000e+000,3.700005e+001,-2.117516e-004,0.000000e+000,3,9.930882e-001,0.000000e+000,,,,,,,,,,,,,,32,1,4.000000e+000,1.762390e-003,0.000000e+000,0,,0,
1524173168.744,,0.000000e+000,3.699829e+001,-2.117540e-004,0.000000e+000,3,9.930164e-001,0.000000e+000,,,,,,,,,,,,,,32,1,4.000000e+000,1.747131e-003,0.000000e+000,0,,0,
1524173194.039,,0.000000e+000,3.700093e+001,-2.116574e-004,0.000000e+000,3,9.930834e-001,0.000000e+000,,,,,,,,,,,,,,32,1,4.000000e+000,3.520966e-003,0.000000e+000,0,,0,
1524173219.172,,0.000000e+000,3.699786e+001,-2.118409e-004,0.000000e+000,3,9.930376e-001,0.000000e+000,,,,,,,,,,,,,,32,1,4.000000e+000,4.390717e-003,0.000000e+000,0,,0,
1524173243.523,,0.000000e+000,3.699873e+001,-2.118813e-004,0.000000e+000,3,9.931328e-001,0.000000e+000,,,,,,,,,,,,,,32,1,4.000000e+000,8.773804e-004,0.000000e+000,0,,0,
1524173269.583,,0.000000e+000,3.699741e+001,-2.119462e-004,0.000000e+000,3,9.930456e-001,0.000000e+000,,,,,,,,,,,,,,32,1,4.000000e+000,1.750946e-003,0.000000e+000,0,,0,
1524173295.408,,0.000000e+000,3.699961e+001,-2.119440e-004,0.000000e+000,3,9.931268e-001,0.000000e+000,,,,,,,,,,,,,,32,1,4.000000e+000,2.639771e-003,0.000000e+000,0,,0,
1524173320.741,,0.000000e+000,3.699786e+001,-2.120086e-004,0.000000e+000,3,9.930639e-001,0.000000e+000,,,,,,,,,,,,,,32,1,4.000000e+000,2.628326e-003,0.000000e+000,0,,0,
1524173345.202,,0.000000e+000,3.699917e+001,-2.120759e-004,0.000000e+000,3,9.932572e-001,0.000000e+000,,,,,,,,,,,,,,32,1,4.000000e+000,0.000000e+000,0.000000e+000,0,,0,
1524173370.272,,0.000000e+000,3.699786e+001,-2.120585e-004,0.000000e+000,3,9.932189e-001,0.000000e+000,,,,,,,,,,,,,,32,1,4.000000e+000,8.697510e-004,0.000000e+000,0,,0,
1524173395.180,,0.000000e+000,3.699654e+001,-2.121034e-004,0.000000e+000,3,9.930928e-001,0.000000e+000,,,,,,,,,,,,,,32,1,4.000000e+000,1.762390e-003,0.000000e+000,0,,0,
1524173420.093,,0.000000e+000,3.699829e+001,-2.121682e-004,0.000000e+000,3,9.932691e-001,0.000000e+000,,,,,,,,,,,,,,32,1,4.000000e+000,3.509521e-003,0.000000e+000,0,,0,
1524173445.406,,0.000000e+000,3.699829e+001,-2.121730e-004,0.000000e+000,3,9.931979e-001,0.000000e+000,,,,,,,,,,,,,,32,1,4.000000e+000,1.747131e-003,0.000000e+000,0,,0,
1524173469.889,,0.000000e+000,3.699829e+001,-2.122033e-004,0.000000e+000,3,9.931583e-001,0.000000e+000,,,,,,,,,,,,,,32,1,4.000000e+000,0.000000e+000,0.000000e+000,0,,0,
1524173495.254,,0.000000e+000,3.699917e+001,-2.123340e-004,0.000000e+000,3,9.933557e-001,0.000000e+000,,,,,,,,,,,,,,32,1,4.000000e+000,1.758575e-003,0.000000e+000,0,,0,
1524173519.842,,0.000000e+000,3.699917e+001,-2.122312e-004,0.000000e+000,3,9.931530e-001,0.000000e+000,,,,,,,,,,,,,,32,1,4.000000e+000,0.000000e+000,0.000000e+000,0,,0,
1524173544.775,,0.000000e+000,3.699918e+001,-2.122822e-004,0.000000e+000,3,9.931024e-001,0.000000e+000,,,,,,,,,,,,,,32,1,4.000000e+000,7.030487e-003,0.000000e+000,0,,0,
1524173569.725,,0.000000e+000,3.699698e+001,-2.123157e-004,0.000000e+000,3,9.929896e-001,0.000000e+000,,,,,,,,,,,,,,32,1,4.000000e+000,8.811951e-004,0.000000e+000,0,,0,
1524173594.673,,0.000000e+000,3.699873e+001,-2.123690e-004,0.000000e+000,3,9.929988e-001,0.000000e+000,,,,,,,,,,,,,,32,1,4.000000e+000,7.907867e-003,0.000000e+000,0,,0,
1524173619.633,,0.000000e+000,3.699829e+001,-2.123889e-004,0.000000e+000,3,9.930948e-001,0.000000e+000,,,,,,,,,,,,,,32,1,4.000000e+000,7.026672e-003,0.000000e+000,0,,0,
1524173644.526,,0.000000e+000,3.699786e+001,-2.123111e-004,0.000000e+000,3,9.930778e-001,0.000000e+000,,,,,,,,,,,,,,32,1,4.000000e+000,8.697510e-004,0.000000e+000,0,,0,
1524173670.066,,0.000000e+000,3.700093e+001,-2.124113e-004,0.000000e+000,3,9.931554e-001,0.000000e+000,,,,,,,,,,,,,,32,1,4.000000e+000,3.520966e-003,0.000000e+000,0,,0,
1524173694.987,,0.000000e+000,3.699697e+001,-2.124968e-004,0.000000e+000,3,9.930870e-001,0.000000e+000,,,,,,,,,,,,,,32,1,4.000000e+000,2.632141e-003,0.000000e+000,0,,0,
1524173719.337,,0.000000e+000,3.700093e+001,-2.125233e-004,0.000000e+000,3,9.934868e-001,0.000000e+000,,,,,,,,,,,,,,32,1,4.000000e+000,1.758575e-003,0.000000e+000,0,,0,
1524173744.865,,0.000000e+000,3.700093e+001,-2.125508e-004,0.000000e+000,3,9.933340e-001,0.000000e+000,,,,,,,,,,,,,,32,1,4.000000e+000,1.758575e-003,0.000000e+000,0,,0,
1524173769.780,,0.000000e+000,3.699829e+001,-2.126173e-004,0.000000e+000,3,9.933739e-001,0.000000e+000,,,,,,,,,,,,,,32,1,4.000000e+000,5.271912e-003,0.000000e+000,0,,0,
1524173794.708,,0.000000e+000,3.700137e+001,-2.126250e-004,0.000000e+000,3,9.932084e-001,0.000000e+000,,,,,,,,,,,,,,32,1,4.000000e+000,8.773804e-004,0.000000e+000,0,,0,
1524173819.654,,0.000000e+000,3.699961e+001,-2.126026e-004,0.000000e+000,3,9.932676e-001,0.000000e+000,,,,,,,,,,,,,,32,1,4.000000e+000,8.811951e-004,0.000000e+000,0,,0,
1524173844.606,,0.000000e+000,3.700049e+001,-2.125458e-004,0.000000e+000,3,9.932515e-001,0.000000e+000,,,,,,,,,,,,,,32,1,4.000000e+000,4.398346e-003,0.000000e+000,0,,0,
1524173869.747,,0.000000e+000,3.700049e+001,-2.127019e-004,0.000000e+000,3,9.932802e-001,0.000000e+000,,,,,,,,,,,,,,32,1,4.000000e+000,8.811951e-004,0.000000e+000,0,,0,
1524173895.307,,0.000000e+000,3.699829e+001,-2.127432e-004,0.000000e+000,3,9.932545e-001,0.000000e+000,,,,,,,,,,,,,,32,1,4.000000e+000,1.747131e-003,0.000000e+000,0,,0,
1524173920.465,,0.000000e+000,3.700225e+001,-2.127951e-004,0.000000e+000,3,9.933274e-001,0.000000e+000,,,,,,,,,,,,,,32,1,4.000000e+000,8.811951e-004,0.000000e+000,0,,0,
1524173945.215,,0.000000e+000,3.699917e+001,-2.128158e-004,0.000000e+000,3,9.932334e-001,0.000000e+000,,,,,,,,,,,,,,32,1,4.000000e+000,1.758575e-003,0.000000e+000,0,,0,
1524173970.318,,0.000000e+000,3.700093e+001,-2.129112e-004,0.000000e+000,3,9.933570e-001,0.000000e+000,,,,,,,,,,,,,,32,1,4.000000e+000,3.520966e-003,0.000000e+000,0,,0,
1524173982.681,,0.000000e+000,3.700181e+001,-2.128059e-004,0.000000e+000,3,9.931007e-001,0.000000e+000,,,,,,,,,,,,,,32,1,4.000000e+000,1.758575e-003,0.000000e+000,0,,0,