File: Experimental Raw Data/MFn1 VRM/Iterative Regression/Acquisition/MFn1_VRMac_37K_3000s.dc.dat
[Header]
TITLE,MPMS DC Measurement
BYAPP,MPMS Measurement,2.1,Summary
FILEOPENTIME, 1524190531.051000 4/19/2018, 8:15:31 PM

INFO, APPNAME, MPMS MultiVu Application, Revision 1.61,  Build 082

INFO, NAME, MFn1
INFO, WEIGHT, 1.000
INFO, AREA, 1.000
INFO, LENGTH, 1.000
INFO, SHAPE, 0
INFO, COMMENT,
INFO, SEQUENCE FILE: VRMac_37K_3000s_VRMde_35K.seq


INFO, BACKGROUND DATA FILE:, None


STARTUPAXIS,X,4,LINEAR,AUTO,0.000000,0.000000
STARTUPAXIS,Y1,5,LINEAR,AUTO,0.000000,0.000000


STARTUPGROUP,Longitudinal
FIELDGROUP,Longitudinal,1,2,3,4,5,6,7,8,9,15,16,17,18,27,28
FIELDGROUP,Transverse,1,2,3,4,10,11,12,13,14,19,20,21,22,27,28

PLOT_APPEARANCE,ALL,HORZ_GRID_ON,VERT_GRID_ON,MARKERS_AND_LINES

[Data]
Time,Comment,Field (Oe),Temperature (K),Long Moment (emu),Long Scan Std Dev,Long Algorithm,Long Reg Fit,Long Percent Error (%),Trans Moment (emu),Trans Scan Std Dev,Trans Algorithm,Trans Reg Fit,Trans Percent Error (%),Long Moment [w/o ABS] (emu),Long Scan Std Dev [w/o ABS],Long Reg Fit [w/o ABS],Long Percent Error [w/o ABS] (%),Trans Moment [w/o ABS] (emu),Trans Scan Std Dev [w/o ABS],Trans Reg Fit [w/o ABS],Trans Percent Error [w/o ABS] (%),Points per Scan,Scans per Measurement,Scan Length (cm),Delta Temp (K),Rot Position (deg),Error,EC Comp. Running,Using ABS,
1524190531.049,,0.000000e+000,3.699918e+001,-1.849694e-004,0.000000e+000,3,9.924775e-001,0.000000e+000,,,,,,,,,,,,,,32,1,4.000000e+000,3.509521e-003,0.000000e+000,0,,0,
1524190543.469,,0.000000e+000,3.700093e+001,-1.863407e-004,0.000000e+000,3,9.925616e-001,0.000000e+000,,,,,,,,,,,,,,32,1,4.000000e+000,0.000000e+000,0.000000e+000,0,,0,
1524190556.114,,0.000000e+000,3.700181e+001,-1.874174e-004,0.000000e+000,3,9.926861e-001,0.000000e+000,,,,,,,,,,,,,,32,1,4.000000e+000,1.758575e-003,0.000000e+000,0,,0,
1524190568.979,,0.000000e+000,3.700225e+001,-1.883918e-004,0.000000e+000,3,9.927642e-001,0.000000e+000,,,,,,,,,,,,,,32,1,4.000000e+000,8.811951e-004,0.000000e+000,0,,0,
1524190581.517,,0.000000e+000,3.700181e+001,-1.891035e-004,0.000000e+000,3,9.926127e-001,0.000000e+000,,,,,,,,,,,,,,32,1,4.000000e+000,1.758575e-003,0.000000e+000,0,,0,
1524190593.970,,0.000000e+000,3.699961e+001,-1.897933e-004,0.000000e+000,3,9.926287e-001,0.000000e+000,,,,,,,,,,,,,,32,1,4.000000e+000,8.811951e-004,0.000000e+000,0,,0,
1524190606.640,,0.000000e+000,3.699961e+001,-1.903548e-004,0.000000e+000,3,9.927086e-001,0.000000e+000,,,,,,,,,,,,,,32,1,4.000000e+000,8.811951e-004,0.000000e+000,0,,0,
1524190619.578,,0.000000e+000,3.699961e+001,-1.909388e-004,0.000000e+000,3,9.926429e-001,0.000000e+000,,,,,,,,,,,,,,32,1,4.000000e+000,8.811951e-004,0.000000e+000,0,,0,
1524190632.040,,0.000000e+000,3.699961e+001,-1.913580e-004,0.000000e+000,3,9.928420e-001,0.000000e+000,,,,,,,,,,,,,,32,1,4.000000e+000,2.639771e-003,0.000000e+000,0,,0,
1524190644.503,,0.000000e+000,3.699917e+001,-1.918375e-004,0.000000e+000,3,9.928126e-001,0.000000e+000,,,,,,,,,,,,,,32,1,4.000000e+000,1.758575e-003,0.000000e+000,0,,0,
1524190656.991,,0.000000e+000,3.699786e+001,-1.922756e-004,0.000000e+000,3,9.927280e-001,0.000000e+000,,,,,,,,,,,,,,32,1,4.000000e+000,8.697510e-004,0.000000e+000,0,,0,
1524190669.426,,0.000000e+000,3.699873e+001,-1.926486e-004,0.000000e+000,3,9.927750e-001,0.000000e+000,,,,,,,,,,,,,,32,1,4.000000e+000,2.628326e-003,0.000000e+000,0,,0,
1524190681.916,,0.000000e+000,3.699873e+001,-1.929992e-004,0.000000e+000,3,9.926288e-001,0.000000e+000,,,,,,,,,,,,,,32,1,4.000000e+000,2.628326e-003,0.000000e+000,0,,0,
1524190694.574,,0.000000e+000,3.699786e+001,-1.933429e-004,0.000000e+000,3,9.927254e-001,0.000000e+000,,,,,,,,,,,,,,32,1,4.000000e+000,2.628326e-003,0.000000e+000,0,,0,
1524190707.124,,0.000000e+000,3.699961e+001,-1.936864e-004,0.000000e+000,3,9.927495e-001,0.000000e+000,,,,,,,,,,,,,,32,1,4.000000e+000,8.811951e-004,0.000000e+000,0,,0,
1524190719.657,,0.000000e+000,3.699917e+001,-1.939716e-004,0.000000e+000,3,9.927879e-001,0.000000e+000,,,,,,,,,,,,,,32,1,4.000000e+000,1.758575e-003,0.000000e+000,0,,0,
1524190732.347,,0.000000e+000,3.699829e+001,-1.942370e-004,0.000000e+000,3,9.928607e-001,0.000000e+000,,,,,,,,,,,,,,32,1,4.000000e+000,1.747131e-003,0.000000e+000,0,,0,
1524190745.244,,0.000000e+000,3.699961e+001,-1.944924e-004,0.000000e+000,3,9.928044e-001,0.000000e+000,,,,,,,,,,,,,,32,1,4.000000e+000,8.811951e-004,0.000000e+000,0,,0,
1524190757.592,,0.000000e+000,3.699917e+001,-1.948280e-004,0.000000e+000,3,9.929287e-001,0.000000e+000,,,,,,,,,,,,,,32,1,4.000000e+000,1.758575e-003,0.000000e+000,0,,0,
1524190770.035,,0.000000e+000,3.699697e+001,-1.950188e-004,0.000000e+000,3,9.929227e-001,0.000000e+000,,,,,,,,,,,,,,32,1,4.000000e+000,4.386902e-003,0.000000e+000,0,,0,
1524190782.582,,0.000000e+000,3.699741e+001,-1.952567e-004,0.000000e+000,3,9.928146e-001,0.000000e+000,,,,,,,,,,,,,,32,1,4.000000e+000,5.268097e-003,0.000000e+000,0,,0,
1524190794.988,,0.000000e+000,3.699741e+001,-1.954816e-004,0.000000e+000,3,9.927003e-001,0.000000e+000,,,,,,,,,,,,,,32,1,4.000000e+000,1.750946e-003,0.000000e+000,0,,0,
1524190807.400,,0.000000e+000,3.699741e+001,-1.957098e-004,0.000000e+000,3,9.927865e-001,0.000000e+000,,,,,,,,,,,,,,32,1,4.000000e+000,1.750946e-003,0.000000e+000,0,,0,
1524190819.886,,0.000000e+000,3.699829e+001,-1.959115e-004,0.000000e+000,3,9.928318e-001,0.000000e+000,,,,,,,,,,,,,,32,1,4.000000e+000,5.271912e-003,0.000000e+000,0,,0,
1524190832.396,,0.000000e+000,3.700005e+001,-1.961184e-004,0.000000e+000,3,9.929046e-001,0.000000e+000,,,,,,,,,,,,,,32,1,4.000000e+000,1.762390e-003,0.000000e+000,0,,0,
1524190844.816,,0.000000e+000,3.699786e+001,-1.963073e-004,0.000000e+000,3,9.928914e-001,0.000000e+000,,,,,,,,,,,,,,32,1,4.000000e+000,2.628326e-003,0.000000e+000,0,,0,
1524190857.276,,0.000000e+000,3.699829e+001,-1.964535e-004,0.000000e+000,3,9.929775e-001,0.000000e+000,,,,,,,,,,,,,,32,1,4.000000e+000,0.000000e+000,0.000000e+000,0,,0,
1524190869.744,,0.000000e+000,3.699697e+001,-1.966554e-004,0.000000e+000,3,9.929516e-001,0.000000e+000,,,,,,,,,,,,,,32,1,4.000000e+000,2.632141e-003,0.000000e+000,0,,0,
1524190882.191,,0.000000e+000,3.699654e+001,-1.968594e-004,0.000000e+000,3,9.928365e-001,0.000000e+000,,,,,,,,,,,,,,32,1,4.000000e+000,3.509521e-003,0.000000e+000,0,,0,
1524190894.674,,0.000000e+000,3.699654e+001,-1.970537e-004,0.000000e+000,3,9.927951e-001,0.000000e+000,,,,,,,,,,,,,,32,1,4.000000e+000,3.509521e-003,0.000000e+000,0,,0,
1524190907.202,,0.000000e+000,3.699786e+001,-1.971863e-004,0.000000e+000,3,9.927946e-001,0.000000e+000,,,,,,,,,,,,,,32,1,4.000000e+000,4.390717e-003,0.000000e+000,0,,0,
1524190919.607,,0.000000e+000,3.699786e+001,-1.973710e-004,0.000000e+000,3,9.927677e-001,0.000000e+000,,,,,,,,,,,,,,32,1,4.000000e+000,4.390717e-003,0.000000e+000,0,,0,
1524190932.052,,0.000000e+000,3.699918e+001,-1.975109e-004,0.000000e+000,3,9.928777e-001,0.000000e+000,,,,,,,,,,,,,,32,1,4.000000e+000,7.030487e-003,0.000000e+000,0,,0,
1524190944.652,,0.000000e+000,3.699654e+001,-1.976139e-004,0.000000e+000,3,9.928282e-001,0.000000e+000,,,,,,,,,,,,,,32,1,4.000000e+000,1.762390e-003,0.000000e+000,0,,0,
1524190956.995,,0.000000e+000,3.699742e+001,-1.978209e-004,0.000000e+000,3,9.929254e-001,0.000000e+000,,,,,,,,,,,,,,32,1,4.000000e+000,0.000000e+000,0.000000e+000,0,,0,
1524190969.633,,0.000000e+000,3.699873e+001,-1.979639e-004,0.000000e+000,3,9.929785e-001,0.000000e+000,,,,,,,,,,,,,,32,1,4.000000e+000,8.773804e-004,0.000000e+000,0,,0,
1524190983.303,,0.000000e+000,3.699829e+001,-1.980727e-004,0.000000e+000,3,9.928149e-001,0.000000e+000,,,,,,,,,,,,,,32,1,4.000000e+000,0.000000e+000,0.000000e+000,0,,0,
1524190995.758,,0.000000e+000,3.699786e+001,-1.982738e-004,0.000000e+000,3,9.927108e-001,0.000000e+000,,,,,,,,,,,,,,32,1,4.000000e+000,8.697510e-004,0.000000e+000,0,,0,
1524191008.228,,0.000000e+000,3.699829e+001,-1.983970e-004,0.000000e+000,3,9.928515e-001,0.000000e+000,,,,,,,,,,,,,,32,1,4.000000e+000,1.747131e-003,0.000000e+000,0,,0,
1524191020.099,,0.000000e+000,3.699873e+001,-1.985396e-004,0.000000e+000,3,9.929505e-001,0.000000e+000,,,,,,,,,,,,,,32,1,4.000000e+000,8.773804e-004,0.000000e+000,0,,0,
1524191033.156,,0.000000e+000,3.699786e+001,-1.986734e-004,0.000000e+000,3,9.928666e-001,0.000000e+000,,,,,,,,,,,,,,32,1,4.000000e+000,8.697510e-004,0.000000e+000,0,,0,
1524191045.624,,0.000000e+000,3.699917e+001,-1.987903e-004,0.000000e+000,3,9.928598e-001,0.000000e+000,,,,,,,,,,,,,,32,1,4.000000e+000,0.000000e+000,0.000000e+000,0,,0,
1524191058.089,,0.000000e+000,3.699786e+001,-1.989013e-004,0.000000e+000,3,9.928381e-001,0.000000e+000,,,,,,,,,,,,,,32,1,4.000000e+000,8.697510e-004,0.000000e+000,0,,0,
1524191069.972,,0.000000e+000,3.699873e+001,-1.990093e-004,0.000000e+000,3,9.929842e-001,0.000000e+000,,,,,,,,,,,,,,32,1,4.000000e+000,2.628326e-003,0.000000e+000,0,,0,
1524191082.439,,0.000000e+000,3.699918e+001,-1.991505e-004,0.000000e+000,3,9.929417e-001,0.000000e+000,,,,,,,,,,,,,,32,1,4.000000e+000,3.509521e-003,0.000000e+000,0,,0,
1524191094.877,,0.000000e+000,3.699829e+001,-1.992547e-004,0.000000e+000,3,9.927547e-001,0.000000e+000,,,,,,,,,,,,,,32,1,4.000000e+000,1.747131e-003,0.000000e+000,0,,0,
1524191107.952,,0.000000e+000,3.699917e+001,-1.993553e-004,0.000000e+000,3,9.928070e-001,0.000000e+000,,,,,,,,,,,,,,32,1,4.000000e+000,0.000000e+000,0.000000e+000,0,,0,
1524191120.428,,0.000000e+000,3.699829e+001,-1.994862e-004,0.000000e+000,3,9.927428e-001,0.000000e+000,,,,,,,,,,,,,,32,1,4.000000e+000,0.000000e+000,0.000000e+000,0,,0,
1524191132.883,,0.000000e+000,3.699829e+001,-1.995497e-004,0.000000e+000,3,9.929184e-001,0.000000e+000,,,,,,,,,,,,,,32,1,4.000000e+000,0.000000e+000,0.000000e+000,0,,0,
1524191145.313,,0.000000e+000,3.699786e+001,-1.997461e-004,0.000000e+000,3,9.928914e-001,0.000000e+000,,,,,,,,,,,,,,32,1,4.000000e+000,2.628326e-003,0.000000e+000,0,,0,
1524191157.806,,0.000000e+000,3.699742e+001,-1.998177e-004,0.000000e+000,3,9.929024e-001,0.000000e+000,,,,,,,,,,,,,,32,1,4.000000e+000,0.000000e+000,0.000000e+000,0,,0,
1524191170.271,,0.000000e+000,3.699786e+001,-1.999168e-004,0.000000e+000,3,9.929051e-001,0.000000e+000,,,,,,,,,,,,,,32,1,4.000000e+000,2.628326e-003,0.000000e+000,0,,0,
1524191182.736,,0.000000e+000,3.699786e+001,-2.000275e-004,0.000000e+000,3,9.928429e-001,0.000000e+000,,,,,,,,,,,,,,32,1,4.000000e+000,2.628326e-003,0.000000e+000,0,,0,
1524191195.199,,0.000000e+000,3.699786e+001,-2.001432e-004,0.000000e+000,3,9.928267e-001,0.000000e+000,,,,,,,,,,,,,,32,1,4.000000e+000,2.628326e-003,0.000000e+000,0,,0,
1524191207.634,,0.000000e+000,3.699917e+001,-2.002440e-004,0.000000e+000,3,9.930066e-001,0.000000e+000,,,,,,,,,,,,,,32,1,4.000000e+000,0.000000e+000,0.000000e+000,0,,0,
1524191219.511,,0.000000e+000,3.699786e+001,-2.003398e-004,0.000000e+000,3,9.928399e-001,0.000000e+000,,,,,,,,,,,,,,32,1,4.000000e+000,2.628326e-003,0.000000e+000,0,,0,
1524191232.022,,0.000000e+000,3.699829e+001,-2.004278e-004,0.000000e+000,3,9.929971e-001,0.000000e+000,,,,,,,,,,,,,,32,1,4.000000e+000,1.747131e-003,0.000000e+000,0,,0,
1524191244.772,,0.000000e+000,3.699742e+001,-2.005686e-004,0.000000e+000,3,9.931095e-001,0.000000e+000,,,,,,,,,,,,,,32,1,4.000000e+000,0.000000e+000,0.000000e+000,0,,0,
1524191257.472,,0.000000e+000,3.699654e+001,-2.006178e-004,0.000000e+000,3,9.930522e-001,0.000000e+000,,,,,,,,,,,,,,32,1,4.000000e+000,3.509521e-003,0.000000e+000,0,,0,
1524191269.302,,0.000000e+000,3.699654e+001,-2.007273e-004,0.000000e+000,3,9.930048e-001,0.000000e+000,,,,,,,,,,,,,,32,1,4.000000e+000,0.000000e+000,0.000000e+000,0,,0,
1524191281.817,,0.000000e+000,3.700005e+001,-2.008021e-004,0.000000e+000,3,9.928700e-001,0.000000e+000,,,,,,,,,,,,,,32,1,4.000000e+000,0.000000e+000,0.000000e+000,0,,0,
1524191294.980,,0.000000e+000,3.699917e+001,-2.008713e-004,0.000000e+000,3,9.929196e-001,0.000000e+000,,,,,,,,,,,,,,32,1,4.000000e+000,1.758575e-003,0.000000e+000,0,,0,
1524191307.600,,0.000000e+000,3.699786e+001,-2.009871e-004,0.000000e+000,3,9.929941e-001,0.000000e+000,,,,,,,,,,,,,,32,1,4.000000e+000,8.697510e-004,0.000000e+000,0,,0,
1524191320.098,,0.000000e+000,3.699829e+001,-2.010990e-004,0.000000e+000,3,9.927129e-001,0.000000e+000,,,,,,,,,,,,,,32,1,4.000000e+000,1.747131e-003,0.000000e+000,0,,0,
1524191333.038,,0.000000e+000,3.699786e+001,-2.011253e-004,0.000000e+000,3,9.930713e-001,0.000000e+000,,,,,,,,,,,,,,32,1,4.000000e+000,2.628326e-003,0.000000e+000,0,,0,
1524191345.421,,0.000000e+000,3.699917e+001,-2.012520e-004,0.000000e+000,3,9.930006e-001,0.000000e+000,,,,,,,,,,,,,,32,1,4.000000e+000,1.758575e-003,0.000000e+000,0,,0,
1524191357.891,,0.000000e+000,3.699873e+001,-2.013038e-004,0.000000e+000,3,9.930117e-001,0.000000e+000,,,,,,,,,,,,,,32,1,4.000000e+000,8.773804e-004,0.000000e+000,0,,0,
1524191370.334,,0.000000e+000,3.699786e+001,-2.013594e-004,0.000000e+000,3,9.930446e-001,0.000000e+000,,,,,,,,,,,,,,32,1,4.000000e+000,8.697510e-004,0.000000e+000,0,,0,
1524191382.581,,0.000000e+000,3.699873e+001,-2.015020e-004,0.000000e+000,3,9.929505e-001,0.000000e+000,,,,,,,,,,,,,,32,1,4.000000e+000,8.773804e-004,0.000000e+000,0,,0,
1524191395.366,,0.000000e+000,3.699873e+001,-2.015840e-004,0.000000e+000,3,9.929863e-001,0.000000e+000,,,,,,,,,,,,,,32,1,4.000000e+000,8.773804e-004,0.000000e+000,0,,0,
1524191407.569,,0.000000e+000,3.699786e+001,-2.016522e-004,0.000000e+000,3,9.929835e-001,0.000000e+000,,,,,,,,,,,,,,32,1,4.000000e+000,8.697510e-004,0.000000e+000,0,,0,
1524191420.314,,0.000000e+000,3.699829e+001,-2.017571e-004,0.000000e+000,3,9.932837e-001,0.000000e+000,,,,,,,,,,,,,,32,1,4.000000e+000,0.000000e+000,0.000000e+000,0,,0,
1524191432.472,,0.000000e+000,3.699786e+001,-2.018086e-004,0.000000e+000,3,9.929906e-001,0.000000e+000,,,,,,,,,,,,,,32,1,4.000000e+000,8.697510e-004,0.000000e+000,0,,0,
1524191444.842,,0.000000e+000,3.699786e+001,-2.018724e-004,0.000000e+000,3,9.931066e-001,0.000000e+000,,,,,,,,,,,,,,32,1,4.000000e+000,8.697510e-004,0.000000e+000,0,,0,
1524191457.440,,0.000000e+000,3.699786e+001,-2.019638e-004,0.000000e+000,3,9.929548e-001,0.000000e+000,,,,,,,,,,,,,,32,1,4.000000e+000,8.697510e-004,0.000000e+000,0,,0,
1524191469.773,,0.000000e+000,3.699873e+001,-2.020564e-004,0.000000e+000,3,9.930562e-001,0.000000e+000,,,,,,,,,,,,,,32,1,4.000000e+000,8.773804e-004,0.000000e+000,0,,0,
1524191482.548,,0.000000e+000,3.699741e+001,-2.021307e-004,0.000000e+000,3,9.931961e-001,0.000000e+000,,,,,,,,,,,,,,32,1,4.000000e+000,1.750946e-003,0.000000e+000,0,,0,
1524191495.060,,0.000000e+000,3.699873e+001,-2.022002e-004,0.000000e+000,3,9.930422e-001,0.000000e+000,,,,,,,,,,,,,,32,1,4.000000e+000,8.773804e-004,0.000000e+000,0,,0,
1524191507.153,,0.000000e+000,3.699873e+001,-2.022353e-004,0.000000e+000,3,9.929847e-001,0.000000e+000,,,,,,,,,,,,,,32,1,4.000000e+000,8.773804e-004,0.000000e+000,0,,0,
1524191519.718,,0.000000e+000,3.699786e+001,-2.023122e-004,0.000000e+000,3,9.930422e-001,0.000000e+000,,,,,,,,,,,,,,32,1,4.000000e+000,8.697510e-004,0.000000e+000,0,,0,
1524191532.149,,0.000000e+000,3.699786e+001,-2.023882e-004,0.000000e+000,3,9.930103e-001,0.000000e+000,,,,,,,,,,,,,,32,1,4.000000e+000,8.697510e-004,0.000000e+000,0,,0,
1524191544.341,,0.000000e+000,3.699829e+001,-2.024421e-004,0.000000e+000,3,9.931204e-001,0.000000e+000,,,,,,,,,,,,,,32,1,4.000000e+000,0.000000e+000,0.000000e+000,0,,0,
1524191557.074,,0.000000e+000,3.699786e+001,-2.024979e-004,0.000000e+000,3,9.929769e-001,0.000000e+000,,,,,,,,,,,,,,32,1,4.000000e+000,8.697510e-004,0.000000e+000,0,,0,
1524191569.892,,0.000000e+000,3.699917e+001,-2.025494e-004,0.000000e+000,3,9.931290e-001,0.000000e+000,,,,,,,,,,,,,,32,1,4.000000e+000,1.758575e-003,0.000000e+000,0,,0,
1524191582.234,,0.000000e+000,3.699917e+001,-2.026660e-004,0.000000e+000,3,9.930882e-001,0.000000e+000,,,,,,,,,,,,,,32,1,4.000000e+000,0.000000e+000,0.000000e+000,0,,0,
1524191594.457,,0.000000e+000,3.699829e+001,-2.027157e-004,0.000000e+000,3,9.931113e-001,0.000000e+000,,,,,,,,,,,,,,32,1,4.000000e+000,0.000000e+000,0.000000e+000,0,,0,
1524191607.060,,0.000000e+000,3.699829e+001,-2.027731e-004,0.000000e+000,3,9.929968e-001,0.000000e+000,,,,,,,,,,,,,,32,1,4.000000e+000,0.000000e+000,0.000000e+000,0,,0,
1524191619.420,,0.000000e+000,3.699829e+001,-2.028543e-004,0.000000e+000,3,9.929410e-001,0.000000e+000,,,,,,,,,,,,,,32,1,4.000000e+000,0.000000e+000,0.000000e+000,0,,0,
1524191631.855,,0.000000e+000,3.699786e+001,-2.029373e-004,0.000000e+000,3,9.930702e-001,0.000000e+000,,,,,,,,,,,,,,32,1,4.000000e+000,8.697510e-004,0.000000e+000,0,,0,
1524191644.473,,0.000000e+000,3.699873e+001,-2.029680e-004,0.000000e+000,3,9.930461e-001,0.000000e+000,,,,,,,,,,,,,,32,1,4.000000e+000,8.773804e-004,0.000000e+000,0,,0,
1524191657.008,,0.000000e+000,3.699873e+001,-2.030473e-004,0.000000e+000,3,9.931155e-001,0.000000e+000,,,,,,,,,,,,,,32,1,4.000000e+000,8.773804e-004,0.000000e+000,0,,0,
1524191669.228,,0.000000e+000,3.699829e+001,-2.031405e-004,0.000000e+000,3,9.931381e-001,0.000000e+000,,,,,,,,,,,,,,32,1,4.000000e+000,0.000000e+000,0.000000e+000,0,,0,
1524191682.146,,0.000000e+000,3.699917e+001,-2.031437e-004,0.000000e+000,3,9.930122e-001,0.000000e+000,,,,,,,,,,,,,,32,1,4.000000e+000,1.758575e-003,0.000000e+000,0,,0,
1524191695.493,,0.000000e+000,3.700137e+001,-2.032229e-004,0.000000e+000,3,9.928955e-001,0.000000e+000,,,,,,,,,,,,,,32,1,4.000000e+000,8.773804e-004,0.000000e+000,0,,0,
1524191707.984,,0.000000e+000,3.700005e+001,-2.033689e-004,0.000000e+000,3,9.930682e-001,0.000000e+000,,,,,,,,,,,,,,32,1,4.000000e+000,5.268097e-003,0.000000e+000,0,,0,
1524191720.416,,0.000000e+000,3.700225e+001,-2.033446e-004,0.000000e+000,3,9.929557e-001,0.000000e+000,,,,,,,,,,,,,,32,1,4.000000e+000,8.811951e-004,0.000000e+000,0,,0,
1524191732.301,,0.000000e+000,3.699873e+001,-2.034178e-004,0.000000e+000,3,9.930393e-001,0.000000e+000,,,,,,,,,,,,,,32,1,4.000000e+000,2.628326e-003,0.000000e+000,0,,0,
1524191745.357,,0.000000e+000,3.699961e+001,-2.034696e-004,0.000000e+000,3,9.929064e-001,0.000000e+000,,,,,,,,,,,,,,32,1,4.000000e+000,8.811951e-004,0.000000e+000,0,,0,
1524191757.232,,0.000000e+000,3.699873e+001,-2.035425e-004,0.000000e+000,3,9.929633e-001,0.000000e+000,,,,,,,,,,,,,,32,1,4.000000e+000,2.628326e-003,0.000000e+000,0,,0,
1524191769.667,,0.000000e+000,3.699742e+001,-2.035737e-004,0.000000e+000,3,9.930344e-001,0.000000e+000,,,,,,,,,,,,,,32,1,4.000000e+000,0.000000e+000,0.000000e+000,0,,0,
1524191782.717,,0.000000e+000,3.700181e+001,-2.036294e-004,0.000000e+000,3,9.929715e-001,0.000000e+000,,,,,,,,,,,,,,32,1,4.000000e+000,0.000000e+000,0.000000e+000,0,,0,
1524191795.217,,0.000000e+000,3.699918e+001,-2.036937e-004,0.000000e+000,3,9.929780e-001,0.000000e+000,,,,,,,,,,,,,,32,1,4.000000e+000,7.030487e-003,0.000000e+000,0,,0,
1524191807.630,,0.000000e+000,3.700093e+001,-2.037208e-004,0.000000e+000,3,9.928542e-001,0.000000e+000,,,,,,,,,,,,,,32,1,4.000000e+000,3.520966e-003,0.000000e+000,0,,0,
1524191820.115,,0.000000e+000,3.699742e+001,-2.038122e-004,0.000000e+000,3,9.929744e-001,0.000000e+000,,,,,,,,,,,,,,32,1,4.000000e+000,7.019043e-003,0.000000e+000,0,,0,
1524191832.555,,0.000000e+000,3.699435e+001,-2.038855e-004,0.000000e+000,3,9.930762e-001,0.000000e+000,,,,,,,,,,,,,,32,1,4.000000e+000,8.697510e-004,0.000000e+000,0,,0,
1524191845.043,,0.000000e+000,3.699741e+001,-2.039534e-004,0.000000e+000,3,9.930018e-001,0.000000e+000,,,,,,,,,,,,,,32,1,4.000000e+000,1.750946e-003,0.000000e+000,0,,0,
1524191856.918,,0.000000e+000,3.699829e+001,-2.039681e-004,0.000000e+000,3,9.930882e-001,0.000000e+000,,,,,,,,,,,,,,32,1,4.000000e+000,3.509521e-003,0.000000e+000,0,,0,
1524191869.953,,0.000000e+000,3.699918e+001,-2.040314e-004,0.000000e+000,3,9.929686e-001,0.000000e+000,,,,,,,,,,,,,,32,1,4.000000e+000,5.268097e-003,0.000000e+000,0,,0,
1524191882.439,,0.000000e+000,3.699829e+001,-2.041025e-004,0.000000e+000,3,9.930322e-001,0.000000e+000,,,,,,,,,,,,,,32,1,4.000000e+000,1.747131e-003,0.000000e+000,0,,0,
1524191894.316,,0.000000e+000,3.699786e+001,-2.040647e-004,0.000000e+000,3,9.929749e-001,0.000000e+000,,,,,,,,,,,,,,32,1,4.000000e+000,2.628326e-003,0.000000e+000,0,,0,
1524191906.989,,0.000000e+000,3.699829e+001,-2.041307e-004,0.000000e+000,3,9.929613e-001,0.000000e+000,,,,,,,,,,,,,,32,1,4.000000e+000,1.747131e-003,0.000000e+000,0,,0,
1524191919.279,,0.000000e+000,3.699873e+001,-2.042461e-004,0.000000e+000,3,9.930406e-001,0.000000e+000,,,,,,,,,,,,,,32,1,4.000000e+000,8.773804e-004,0.000000e+000,0,,0,
1524191931.714,,0.000000e+000,3.699829e+001,-2.042662e-004,0.000000e+000,3,9.930382e-001,0.000000e+000,,,,,,,,,,,,,,32,1,4.000000e+000,0.000000e+000,0.000000e+000,0,,0,
1524191944.165,,0.000000e+000,3.699873e+001,-2.043132e-004,0.000000e+000,3,9.929554e-001,0.000000e+000,,,,,,,,,,,,,,32,1,4.000000e+000,8.773804e-004,0.000000e+000,0,,0,
1524191957.190,,0.000000e+000,3.699654e+001,-2.043252e-004,0.000000e+000,3,9.930634e-001,0.000000e+000,,,,,,,,,,,,,,32,1,4.000000e+000,5.256653e-003,0.000000e+000,0,,0,
1524191969.670,,0.000000e+000,3.699873e+001,-2.044392e-004,0.000000e+000,3,9.930064e-001,0.000000e+000,,,,,,,,,,,,,,32,1,4.000000e+000,4.390717e-003,0.000000e+000,0,,0,
1524191982.120,,0.000000e+000,3.699698e+001,-2.044715e-004,0.000000e+000,3,9.929230e-001,0.000000e+000,,,,,,,,,,,,,,32,1,4.000000e+000,8.811951e-004,0.000000e+000,0,,0,
1524191994.595,,0.000000e+000,3.699917e+001,-2.045320e-004,0.000000e+000,3,9.928802e-001,0.000000e+000,,,,,,,,,,,,,,32,1,4.000000e+000,0.000000e+000,0.000000e+000,0,,0,
1524192006.468,,0.000000e+000,3.700049e+001,-2.045878e-004,0.000000e+000,3,9.929764e-001,0.000000e+000,,,,,,,,,,,,,,32,1,4.000000e+000,2.639771e-003,0.000000e+000,0,,0,
1524192018.916,,0.000000e+000,3.699829e+001,-2.045937e-004,0.000000e+000,3,9.930484e-001,0.000000e+000,,,,,,,,,,,,,,32,1,4.000000e+000,1.747131e-003,0.000000e+000,0,,0,
1524192031.433,,0.000000e+000,3.700005e+001,-2.046953e-004,0.000000e+000,3,9.930152e-001,0.000000e+000,,,,,,,,,,,,,,32,1,4.000000e+000,1.762390e-003,0.000000e+000,0,,0,
1524192043.896,,0.000000e+000,3.699786e+001,-2.047725e-004,0.000000e+000,3,9.931116e-001,0.000000e+000,,,,,,,,,,,,,,32,1,4.000000e+000,2.628326e-003,0.000000e+000,0,,0,
1524192056.879,,0.000000e+000,3.699741e+001,-2.047835e-004,0.000000e+000,3,9.930686e-001,0.000000e+000,,,,,,,,,,,,,,32,1,4.000000e+000,3.509521e-003,0.000000e+000,0,,0,
1524192069.366,,0.000000e+000,3.699522e+001,-2.048634e-004,0.000000e+000,3,9.930775e-001,0.000000e+000,,,,,,,,,,,,,,32,1,4.000000e+000,8.773804e-004,0.000000e+000,0,,0,
1524192081.807,,0.000000e+000,3.699917e+001,-2.049065e-004,0.000000e+000,3,9.930731e-001,0.000000e+000,,,,,,,,,,,,,,32,1,4.000000e+000,0.000000e+000,0.000000e+000,0,,0,
1524192094.299,,0.000000e+000,3.700005e+001,-2.049676e-004,0.000000e+000,3,9.929054e-001,0.000000e+000,,,,,,,,,,,,,,32,1,4.000000e+000,3.517151e-003,0.000000e+000,0,,0,
1524192106.774,,0.000000e+000,3.699741e+001,-2.049929e-004,0.000000e+000,3,9.929529e-001,0.000000e+000,,,,,,,,,,,,,,32,1,4.000000e+000,1.750946e-003,0.000000e+000,0,,0,
1524192119.210,,0.000000e+000,3.700093e+001,-2.050644e-004,0.000000e+000,3,9.930024e-001,0.000000e+000,,,,,,,,,,,,,,32,1,4.000000e+000,0.000000e+000,0.000000e+000,0,,0,
1524192131.090,,0.000000e+000,3.700137e+001,-2.050825e-004,0.000000e+000,3,9.930170e-001,0.000000e+000,,,,,,,,,,,,,,32,1,4.000000e+000,8.773804e-004,0.000000e+000,0,,0,
1524192143.587,,0.000000e+000,3.700005e+001,-2.050971e-004,0.000000e+000,3,9.930115e-001,0.000000e+000,,,,,,,,,,,,,,32,1,4.000000e+000,3.517151e-003,0.000000e+000,0,,0,
1524192156.068,,0.000000e+000,3.700181e+001,-2.051621e-004,0.000000e+000,3,9.931020e-001,0.000000e+000,,,,,,,,,,,,,,32,1,4.000000e+000,0.000000e+000,0.000000e+000,0,,0,
1524192168.520,,0.000000e+000,3.699697e+001,-2.051778e-004,0.000000e+000,3,9.930510e-001,0.000000e+000,,,,,,,,,,,,,,32,1,4.000000e+000,2.632141e-003,0.000000e+000,0,,0,
1524192180.966,,0.000000e+000,3.699786e+001,-2.052550e-004,0.000000e+000,3,9.929963e-001,0.000000e+000,,,,,,,,,,,,,,32,1,4.000000e+000,8.697510e-004,0.000000e+000,0,,0,
1524192193.416,,0.000000e+000,3.699829e+001,-2.052797e-004,0.000000e+000,3,9.929163e-001,0.000000e+000,,,,,,,,,,,,,,32,1,4.000000e+000,1.747131e-003,0.000000e+000,0,,0,
1524192206.461,,0.000000e+000,3.699873e+001,-2.053443e-004,0.000000e+000,3,9.929786e-001,0.000000e+000,,,,,,,,,,,,,,32,1,4.000000e+000,4.390717e-003,0.000000e+000,0,,0,
1524192218.931,,0.000000e+000,3.699654e+001,-2.053958e-004,0.000000e+000,3,9.930201e-001,0.000000e+000,,,,,,,,,,,,,,32,1,4.000000e+000,0.000000e+000,0.000000e+000,0,,0,
1524192231.399,,0.000000e+000,3.699786e+001,-2.054316e-004,0.000000e+000,3,9.929428e-001,0.000000e+000,,,,,,,,,,,,,,32,1,4.000000e+000,4.390717e-003,0.000000e+000,0,,0,
1524192243.839,,0.000000e+000,3.699654e+001,-2.054963e-004,0.000000e+000,3,9.930094e-001,0.000000e+000,,,,,,,,,,,,,,32,1,4.000000e+000,1.762390e-003,0.000000e+000,0,,0,
1524192256.324,,0.000000e+000,3.699697e+001,-2.055381e-004,0.000000e+000,3,9.929956e-001,0.000000e+000,,,,,,,,,,,,,,32,1,4.000000e+000,4.386902e-003,0.000000e+000,0,,0,
1524192268.794,,0.000000e+000,3.699741e+001,-2.055791e-004,0.000000e+000,3,9.931471e-001,0.000000e+000,,,,,,,,,,,,,,32,1,4.000000e+000,5.268097e-003,0.000000e+000,0,,0,
1524192281.470,,0.000000e+000,3.700049e+001,-2.056017e-004,0.000000e+000,3,9.931529e-001,0.000000e+000,,,,,,,,,,,,,,32,1,4.000000e+000,8.811951e-004,0.000000e+000,0,,0,
1524192294.022,,0.000000e+000,3.699829e+001,-2.056457e-004,0.000000e+000,3,9.930237e-001,0.000000e+000,,,,,,,,,,,,,,32,1,4.000000e+000,0.000000e+000,0.000000e+000,0,,0,
1524192306.502,,0.000000e+000,3.699873e+001,-2.056639e-004,0.000000e+000,3,9.930526e-001,0.000000e+000,,,,,,,,,,,,,,32,1,4.000000e+000,8.773804e-004,0.000000e+000,0,,0,
1524192319.473,,0.000000e+000,3.699741e+001,-2.056292e-004,0.000000e+000,3,9.931070e-001,0.000000e+000,,,,,,,,,,,,,,32,1,4.000000e+000,1.750946e-003,0.000000e+000,0,,0,
1524192332.128,,0.000000e+000,3.699741e+001,-2.057465e-004,0.000000e+000,3,9.932255e-001,0.000000e+000,,,,,,,,,,,,,,32,1,4.000000e+000,1.750946e-003,0.000000e+000,0,,0,
1524192344.503,,0.000000e+000,3.699918e+001,-2.057776e-004,0.000000e+000,3,9.930289e-001,0.000000e+000,,,,,,,,,,,,,,32,1,4.000000e+000,5.268097e-003,0.000000e+000,0,,0,
1524192357.133,,0.000000e+000,3.700093e+001,-2.057968e-004,0.000000e+000,3,9.929638e-001,0.000000e+000,,,,,,,,,,,,,,32,1,4.000000e+000,1.758575e-003,0.000000e+000,0,,0,
1524192369.861,,0.000000e+000,3.699873e+001,-2.058434e-004,0.000000e+000,3,9.931485e-001,0.000000e+000,,,,,,,,,,,,,,32,1,4.000000e+000,8.773804e-004,0.000000e+000,0,,0,
1524192381.984,,0.000000e+000,3.699873e+001,-2.058735e-004,0.000000e+000,3,9.929846e-001,0.000000e+000,,,,,,,,,,,,,,32,1,4.000000e+000,2.628326e-003,0.000000e+000,0,,0,
1524192395.401,,0.000000e+000,3.699873e+001,-2.059136e-004,0.000000e+000,3,9.930094e-001,0.000000e+000,,,,,,,,,,,,,,32,1,4.000000e+000,8.773804e-004,0.000000e+000,0,,0,
1524192407.866,,0.000000e+000,3.700092e+001,-2.059554e-004,0.000000e+000,3,9.929805e-001,0.000000e+000,,,,,,,,,,,,,,32,1,4.000000e+000,5.268097e-003,0.000000e+000,0,,0,
1524192420.334,,0.000000e+000,3.700137e+001,-2.060354e-004,0.000000e+000,3,9.930752e-001,0.000000e+000,,,,,,,,,,,,,,32,1,4.000000e+000,8.773804e-004,0.000000e+000,0,,0,
1524192432.802,,0.000000e+000,3.700005e+001,-2.060601e-004,0.000000e+000,3,9.930992e-001,0.000000e+000,,,,,,,,,,,,,,32,1,4.000000e+000,1.762390e-003,0.000000e+000,0,,0,
1524192445.262,,0.000000e+000,3.700181e+001,-2.060924e-004,0.000000e+000,3,9.931443e-001,0.000000e+000,,,,,,,,,,,,,,32,1,4.000000e+000,1.758575e-003,0.000000e+000,0,,0,
1524192457.882,,0.000000e+000,3.700049e+001,-2.061440e-004,0.000000e+000,3,9.931780e-001,0.000000e+000,,,,,,,,,,,,,,32,1,4.000000e+000,2.639771e-003,0.000000e+000,0,,0,
1524192469.967,,0.000000e+000,3.699917e+001,-2.061690e-004,0.000000e+000,3,9.929263e-001,0.000000e+000,,,,,,,,,,,,,,32,1,4.000000e+000,0.000000e+000,0.000000e+000,0,,0,
1524192482.422,,0.000000e+000,3.699917e+001,-2.062345e-004,0.000000e+000,3,9.929485e-001,0.000000e+000,,,,,,,,,,,,,,32,1,4.000000e+000,0.000000e+000,0.000000e+000,0,,0,
1524192494.893,,0.000000e+000,3.699961e+001,-2.062868e-004,0.000000e+000,3,9.929712e-001,0.000000e+000,,,,,,,,,,,,,,32,1,4.000000e+000,8.811951e-004,0.000000e+000,0,,0,
1524192507.353,,0.000000e+000,3.699917e+001,-2.062807e-004,0.000000e+000,3,9.929994e-001,0.000000e+000,,,,,,,,,,,,,,32,1,4.000000e+000,0.000000e+000,0.000000e+000,0,,0,
1524192519.818,,0.000000e+000,3.699961e+001,-2.063401e-004,0.000000e+000,3,9.930038e-001,0.000000e+000,,,,,,,,,,,,,,32,1,4.000000e+000,8.811951e-004,0.000000e+000,0,,0,
1524192532.296,,0.000000e+000,3.699873e+001,-2.063379e-004,0.000000e+000,3,9.929942e-001,0.000000e+000,,,,,,,,,,,,,,32,1,4.000000e+000,8.773804e-004,0.000000e+000,0,,0,
1524192544.743,,0.000000e+000,3.699961e+001,-2.064100e-004,0.000000e+000,3,9.929934e-001,0.000000e+000,,,,,,,,,,,,,,32,1,4.000000e+000,8.811951e-004,0.000000e+000,0,,0,
1524192557.554,,0.000000e+000,3.699917e+001,-2.064327e-004,0.000000e+000,3,9.929743e-001,0.000000e+000,,,,,,,,,,,,,,32,1,4.000000e+000,1.758575e-003,0.000000e+000,0,,0,
1524192570.234,,0.000000e+000,3.699873e+001,-2.064287e-004,0.000000e+000,3,9.931482e-001,0.000000e+000,,,,,,,,,,,,,,32,1,4.000000e+000,4.390717e-003,0.000000e+000,0,,0,
1524192582.804,,0.000000e+000,3.699829e+001,-2.064670e-004,0.000000e+000,3,9.931214e-001,0.000000e+000,,,,,,,,,,,,,,32,1,4.000000e+000,1.747131e-003,0.000000e+000,0,,0,
1524192595.557,,0.000000e+000,3.700093e+001,-2.064984e-004,0.000000e+000,3,9.931114e-001,0.000000e+000,,,,,,,,,,,,,,32,1,4.000000e+000,1.758575e-003,0.000000e+000,0,,0,
1524192608.324,,0.000000e+000,3.699918e+001,-2.065415e-004,0.000000e+000,3,9.929999e-001,0.000000e+000,,,,,,,,,,,,,,32,1,4.000000e+000,3.509521e-003,0.000000e+000,0,,0,
1524192620.757,,0.000000e+000,3.699786e+001,-2.065778e-004,0.000000e+000,3,9.930380e-001,0.000000e+000,,,,,,,,,,,,,,32,1,4.000000e+000,4.390717e-003,0.000000e+000,0,,0,
1524192633.385,,0.000000e+000,3.699829e+001,-2.066349e-004,0.000000e+000,3,9.931286e-001,0.000000e+000,,,,,,,,,,,,,,32,1,4.000000e+000,3.509521e-003,0.000000e+000,0,,0,
1524192645.850,,0.000000e+000,3.699873e+001,-2.066776e-004,0.000000e+000,3,9.930696e-001,0.000000e+000,,,,,,,,,,,,,,32,1,4.000000e+000,4.390717e-003,0.000000e+000,0,,0,
1524192658.250,,0.000000e+000,3.699873e+001,-2.066700e-004,0.000000e+000,3,9.931276e-001,0.000000e+000,,,,,,,,,,,,,,32,1,4.000000e+000,4.390717e-003,0.000000e+000,0,,0,
1524192670.630,,0.000000e+000,3.700093e+001,-2.067340e-004,0.000000e+000,3,9.931251e-001,0.000000e+000,,,,,,,,,,,,,,32,1,4.000000e+000,0.000000e+000,0.000000e+000,0,,0,
1524192683.098,,0.000000e+000,3.700005e+001,-2.067688e-004,0.000000e+000,3,9.930289e-001,0.000000e+000,,,,,,,,,,,,,,32,1,4.000000e+000,5.268097e-003,0.000000e+000,0,,0,
1524192695.578,,0.000000e+000,3.700005e+001,-2.067802e-004,0.000000e+000,3,9.929454e-001,0.000000e+000,,,,,,,,,,,,,,32,1,4.000000e+000,5.268097e-003,0.000000e+000,0,,0,
1524192708.041,,0.000000e+000,3.700005e+001,-2.068583e-004,0.000000e+000,3,9.929776e-001,0.000000e+000,,,,,,,,,,,,,,32,1,4.000000e+000,5.268097e-003,0.000000e+000,0,,0,
1524192720.588,,0.000000e+000,3.700093e+001,-2.068567e-004,0.000000e+000,3,9.930774e-001,0.000000e+000,,,,,,,,,,,,,,32,1,4.000000e+000,3.520966e-003,0.000000e+000,0,,0,
1524192732.989,,0.000000e+000,3.699917e+001,-2.069030e-004,0.000000e+000,3,9.930183e-001,0.000000e+000,,,,,,,,,,,,,,32,1,4.000000e+000,0.000000e+000,0.000000e+000,0,,0,
1524192745.454,,0.000000e+000,3.700137e+001,-2.069147e-004,0.000000e+000,3,9.930492e-001,0.000000e+000,,,,,,,,,,,,,,32,1,4.000000e+000,2.639771e-003,0.000000e+000,0,,0,
1524192757.869,,0.000000e+000,3.699918e+001,-2.069446e-004,0.000000e+000,3,9.930772e-001,0.000000e+000,,,,,,,,,,,,,,32,1,4.000000e+000,7.030487e-003,0.000000e+000,0,,0,
1524192770.369,,0.000000e+000,3.699961e+001,-2.069868e-004,0.000000e+000,3,9.931455e-001,0.000000e+000,,,,,,,,,,,,,,32,1,4.000000e+000,2.639771e-003,0.000000e+000,0,,0,
1524192782.904,,0.000000e+000,3.699741e+001,-2.069884e-004,0.000000e+000,3,9.930198e-001,0.000000e+000,,,,,,,,,,,,,,32,1,4.000000e+000,1.750946e-003,0.000000e+000,0,,0,
1524192795.302,,0.000000e+000,3.699786e+001,-2.070398e-004,0.000000e+000,3,9.930446e-001,0.000000e+000,,,,,,,,,,,,,,32,1,4.000000e+000,2.628326e-003,0.000000e+000,0,,0,
1524192807.750,,0.000000e+000,3.699961e+001,-2.070851e-004,0.000000e+000,3,9.930916e-001,0.000000e+000,,,,,,,,,,,,,,32,1,4.000000e+000,8.811951e-004,0.000000e+000,0,,0,
1524192820.230,,0.000000e+000,3.699873e+001,-2.071219e-004,0.000000e+000,3,9.930401e-001,0.000000e+000,,,,,,,,,,,,,,32,1,4.000000e+000,2.628326e-003,0.000000e+000,0,,0,
1524192832.710,,0.000000e+000,3.700093e+001,-2.071746e-004,0.000000e+000,3,9.930727e-001,0.000000e+000,,,,,,,,,,,,,,32,1,4.000000e+000,1.758575e-003,0.000000e+000,0,,0,
1524192845.393,,0.000000e+000,3.700049e+001,-2.071763e-004,0.000000e+000,3,9.932273e-001,0.000000e+000,,,,,,,,,,,,,,32,1,4.000000e+000,2.639771e-003,0.000000e+000,0,,0,
1524192857.645,,0.000000e+000,3.699917e+001,-2.072325e-004,0.000000e+000,3,9.932801e-001,0.000000e+000,,,,,,,,,,,,,,32,1,4.000000e+000,0.000000e+000,0.000000e+000,0,,0,
1524192870.233,,0.000000e+000,3.699917e+001,-2.072798e-004,0.000000e+000,3,9.931732e-001,0.000000e+000,,,,,,,,,,,,,,32,1,4.000000e+000,0.000000e+000,0.000000e+000,0,,0,
1524192882.696,,0.000000e+000,3.699786e+001,-2.073062e-004,0.000000e+000,3,9.931591e-001,0.000000e+000,,,,,,,,,,,,,,32,1,4.000000e+000,2.628326e-003,0.000000e+000,0,,0,
1524192895.049,,0.000000e+000,3.699873e+001,-2.073461e-004,0.000000e+000,3,9.929740e-001,0.000000e+000,,,,,,,,,,,,,,32,1,4.000000e+000,2.628326e-003,0.000000e+000,0,,0,
1524192907.576,,0.000000e+000,3.699961e+001,-2.073479e-004,0.000000e+000,3,9.929939e-001,0.000000e+000,,,,,,,,,,,,,,32,1,4.000000e+000,8.811951e-004,0.000000e+000,0,,0,
1524192919.951,,0.000000e+000,3.699918e+001,-2.073970e-004,0.000000e+000,3,9.930403e-001,0.000000e+000,,,,,,,,,,,,,,32,1,4.000000e+000,5.268097e-003,0.000000e+000,0,,0,
1524192932.449,,0.000000e+000,3.699961e+001,-2.074031e-004,0.000000e+000,3,9.930336e-001,0.000000e+000,,,,,,,,,,,,,,32,1,4.000000e+000,4.386902e-003,0.000000e+000,0,,0,
1524192945.022,,0.000000e+000,3.700225e+001,-2.074379e-004,0.000000e+000,3,9.930592e-001,0.000000e+000,,,,,,,,,,,,,,32,1,4.000000e+000,8.811951e-004,0.000000e+000,0,,0,
1524192957.362,,0.000000e+000,3.700005e+001,-2.074622e-004,0.000000e+000,3,9.930280e-001,0.000000e+000,,,,,,,,,,,,,,32,1,4.000000e+000,3.517151e-003,0.000000e+000,0,,0,
1524192969.912,,0.000000e+000,3.699873e+001,-2.074937e-004,0.000000e+000,3,9.930544e-001,0.000000e+000,,,,,,,,,,,,,,32,1,4.000000e+000,8.773804e-004,0.000000e+000,0,,0,
1524192982.327,,0.000000e+000,3.699873e+001,-2.075271e-004,0.000000e+000,3,9.930189e-001,0.000000e+000,,,,,,,,,,,,,,32,1,4.000000e+000,8.773804e-004,0.000000e+000,0,,0,
1524192994.725,,0.000000e+000,3.699741e+001,-2.075754e-004,0.000000e+000,3,9.930111e-001,0.000000e+000,,,,,,,,,,,,,,32,1,4.000000e+000,1.750946e-003,0.000000e+000,0,,0,
1524193007.175,,0.000000e+000,3.699654e+001,-2.076079e-004,0.000000e+000,3,9.930336e-001,0.000000e+000,,,,,,,,,,,,,,32,1,4.000000e+000,3.509521e-003,0.000000e+000,0,,0,
1524193019.705,,0.000000e+000,3.699741e+001,-2.076502e-004,0.000000e+000,3,9.931126e-001,0.000000e+000,,,,,,,,,,,,,,32,1,4.000000e+000,1.750946e-003,0.000000e+000,0,,0,
1524193032.121,,0.000000e+000,3.699873e+001,-2.076697e-004,0.000000e+000,3,9.930729e-001,0.000000e+000,,,,,,,,,,,,,,32,1,4.000000e+000,4.390717e-003,0.000000e+000,0,,0,
1524193044.606,,0.000000e+000,3.699961e+001,-2.076267e-004,0.000000e+000,3,9.930833e-001,0.000000e+000,,,,,,,,,,,,,,32,1,4.000000e+000,2.639771e-003,0.000000e+000,0,,0,
1524193057.086,,0.000000e+000,3.699829e+001,-2.076954e-004,0.000000e+000,3,9.930655e-001,0.000000e+000,,,,,,,,,,,,,,32,1,4.000000e+000,0.000000e+000,0.000000e+000,0,,0,
1524193069.674,,0.000000e+000,3.700181e+001,-2.077425e-004,0.000000e+000,3,9.931059e-001,0.000000e+000,,,,,,,,,,,,,,32,1,4.000000e+000,1.758575e-003,0.000000e+000,0,,0,
1524193082.014,,0.000000e+000,3.700093e+001,-2.077786e-004,0.000000e+000,3,9.930324e-001,0.000000e+000,,,,,,,,,,,,,,32,1,4.000000e+000,0.000000e+000,0.000000e+000,0,,0,
1524193094.546,,0.000000e+000,3.699829e+001,-2.077886e-004,0.000000e+000,3,9.929588e-001,0.000000e+000,,,,,,,,,,,,,,32,1,4.000000e+000,1.747131e-003,0.000000e+000,0,,0,
1524193107.012,,0.000000e+000,3.699917e+001,-2.078278e-004,0.000000e+000,3,9.930362e-001,0.000000e+000,,,,,,,,,,,,,,32,1,4.000000e+000,0.000000e+000,0.000000e+000,0,,0,
1524193119.397,,0.000000e+000,3.699961e+001,-2.078615e-004,0.000000e+000,3,9.930618e-001,0.000000e+000,,,,,,,,,,,,,,32,1,4.000000e+000,8.811951e-004,0.000000e+000,0,,0,
1524193131.862,,0.000000e+000,3.699873e+001,-2.078818e-004,0.000000e+000,3,9.930876e-001,0.000000e+000,,,,,,,,,,,,,,32,1,4.000000e+000,8.773804e-004,0.000000e+000,0,,0,
1524193144.307,,0.000000e+000,3.699873e+001,-2.078867e-004,0.000000e+000,3,9.930634e-001,0.000000e+000,,,,,,,,,,,,,,32,1,4.000000e+000,8.773804e-004,0.000000e+000,0,,0,
1524193156.875,,0.000000e+000,3.699961e+001,-2.079240e-004,0.000000e+000,3,9.931065e-001,0.000000e+000,,,,,,,,,,,,,,32,1,4.000000e+000,4.386902e-003,0.000000e+000,0,,0,
1524193169.240,,0.000000e+000,3.699829e+001,-2.079869e-004,0.000000e+000,3,9.930822e-001,0.000000e+000,,,,,,,,,,,,,,32,1,4.000000e+000,1.747131e-003,0.000000e+000,0,,0,