File: Experimental Raw Data/MFn1 VRM/Iterative Regression/Acquisition/MFn1_VRMac_34K_12000s.dc.dat
[Header]
TITLE,MPMS DC Measurement
BYAPP,MPMS Measurement,2.1,Summary
FILEOPENTIME, 1524227870.047000 4/20/2018, 6:37:50 AM

INFO, APPNAME, MPMS MultiVu Application, Revision 1.61,  Build 082

INFO, NAME, MFn1
INFO, WEIGHT, 1.000
INFO, AREA, 1.000
INFO, LENGTH, 1.000
INFO, SHAPE, 0
INFO, COMMENT,
INFO, SEQUENCE FILE: VRMac_34K_12000s_VRMde_35K.seq


INFO, BACKGROUND DATA FILE:, None


STARTUPAXIS,X,4,LINEAR,AUTO,0.000000,0.000000
STARTUPAXIS,Y1,5,LINEAR,AUTO,0.000000,0.000000


STARTUPGROUP,Longitudinal
FIELDGROUP,Longitudinal,1,2,3,4,5,6,7,8,9,15,16,17,18,27,28
FIELDGROUP,Transverse,1,2,3,4,10,11,12,13,14,19,20,21,22,27,28

PLOT_APPEARANCE,ALL,HORZ_GRID_ON,VERT_GRID_ON,MARKERS_AND_LINES

[Data]
Time,Comment,Field (Oe),Temperature (K),Long Moment (emu),Long Scan Std Dev,Long Algorithm,Long Reg Fit,Long Percent Error (%),Trans Moment (emu),Trans Scan Std Dev,Trans Algorithm,Trans Reg Fit,Trans Percent Error (%),Long Moment [w/o ABS] (emu),Long Scan Std Dev [w/o ABS],Long Reg Fit [w/o ABS],Long Percent Error [w/o ABS] (%),Trans Moment [w/o ABS] (emu),Trans Scan Std Dev [w/o ABS],Trans Reg Fit [w/o ABS],Trans Percent Error [w/o ABS] (%),Points per Scan,Scans per Measurement,Scan Length (cm),Delta Temp (K),Rot Position (deg),Error,EC Comp. Running,Using ABS,
1524227870.044,,0.000000e+000,3.399789e+001,-1.697189e-004,0.000000e+000,3,9.924738e-001,0.000000e+000,,,,,,,,,,,,,,32,1,4.000000e+000,2.948761e-003,0.000000e+000,0,,0,
1524227908.655,,0.000000e+000,3.399899e+001,-1.754822e-004,0.000000e+000,3,9.927346e-001,0.000000e+000,,,,,,,,,,,,,,32,1,4.000000e+000,2.212524e-003,0.000000e+000,0,,0,
1524227948.135,,0.000000e+000,3.399973e+001,-1.780366e-004,0.000000e+000,3,9.928735e-001,0.000000e+000,,,,,,,,,,,,,,32,1,4.000000e+000,7.324219e-004,0.000000e+000,0,,0,
1524227984.856,,0.000000e+000,3.399862e+001,-1.795971e-004,0.000000e+000,3,9.928082e-001,0.000000e+000,,,,,,,,,,,,,,32,1,4.000000e+000,0.000000e+000,0.000000e+000,0,,0,
1524228022.786,,0.000000e+000,3.399862e+001,-1.808117e-004,0.000000e+000,3,9.930511e-001,0.000000e+000,,,,,,,,,,,,,,32,1,4.000000e+000,1.480103e-003,0.000000e+000,0,,0,
1524228061.192,,0.000000e+000,3.399825e+001,-1.816829e-004,0.000000e+000,3,9.925695e-001,0.000000e+000,,,,,,,,,,,,,,32,1,4.000000e+000,2.220154e-003,0.000000e+000,0,,0,
1524228099.130,,0.000000e+000,3.399788e+001,-1.825224e-004,0.000000e+000,3,9.928958e-001,0.000000e+000,,,,,,,,,,,,,,32,1,4.000000e+000,1.480103e-003,0.000000e+000,0,,0,
1524228137.396,,0.000000e+000,3.399825e+001,-1.833051e-004,0.000000e+000,3,9.930908e-001,0.000000e+000,,,,,,,,,,,,,,32,1,4.000000e+000,2.220154e-003,0.000000e+000,0,,0,
1524228175.831,,0.000000e+000,3.399751e+001,-1.838905e-004,0.000000e+000,3,9.930033e-001,0.000000e+000,,,,,,,,,,,,,,32,1,4.000000e+000,7.400513e-004,0.000000e+000,0,,0,
1524228214.182,,0.000000e+000,3.399862e+001,-1.844915e-004,0.000000e+000,3,9.929126e-001,0.000000e+000,,,,,,,,,,,,,,32,1,4.000000e+000,1.480103e-003,0.000000e+000,0,,0,
1524228251.725,,0.000000e+000,3.399899e+001,-1.849325e-004,0.000000e+000,3,9.929594e-001,0.000000e+000,,,,,,,,,,,,,,32,1,4.000000e+000,7.400513e-004,0.000000e+000,0,,0,
1524228289.718,,0.000000e+000,3.399825e+001,-1.854047e-004,0.000000e+000,3,9.929582e-001,0.000000e+000,,,,,,,,,,,,,,32,1,4.000000e+000,7.400513e-004,0.000000e+000,0,,0,
1524228326.566,,0.000000e+000,3.399899e+001,-1.858071e-004,0.000000e+000,3,9.931677e-001,0.000000e+000,,,,,,,,,,,,,,32,1,4.000000e+000,7.400513e-004,0.000000e+000,0,,0,
1524228364.521,,0.000000e+000,3.399862e+001,-1.861563e-004,0.000000e+000,3,9.930897e-001,0.000000e+000,,,,,,,,,,,,,,32,1,4.000000e+000,1.480103e-003,0.000000e+000,0,,0,
1524228402.107,,0.000000e+000,3.399751e+001,-1.865609e-004,0.000000e+000,3,9.930028e-001,0.000000e+000,,,,,,,,,,,,,,32,1,4.000000e+000,2.208710e-003,0.000000e+000,0,,0,
1524228440.543,,0.000000e+000,3.399825e+001,-1.868973e-004,0.000000e+000,3,9.930139e-001,0.000000e+000,,,,,,,,,,,,,,32,1,4.000000e+000,2.220154e-003,0.000000e+000,0,,0,
1524228478.833,,0.000000e+000,3.399862e+001,-1.871928e-004,0.000000e+000,3,9.930499e-001,0.000000e+000,,,,,,,,,,,,,,32,1,4.000000e+000,1.480103e-003,0.000000e+000,0,,0,
1524228516.261,,0.000000e+000,3.400009e+001,-1.874814e-004,0.000000e+000,3,9.930459e-001,0.000000e+000,,,,,,,,,,,,,,32,1,4.000000e+000,2.941132e-003,0.000000e+000,0,,0,
1524228554.232,,0.000000e+000,3.399751e+001,-1.878084e-004,0.000000e+000,3,9.931932e-001,0.000000e+000,,,,,,,,,,,,,,32,1,4.000000e+000,2.208710e-003,0.000000e+000,0,,0,
1524228592.657,,0.000000e+000,3.399788e+001,-1.880379e-004,0.000000e+000,3,9.931101e-001,0.000000e+000,,,,,,,,,,,,,,32,1,4.000000e+000,1.480103e-003,0.000000e+000,0,,0,
1524228631.198,,0.000000e+000,3.399825e+001,-1.883159e-004,0.000000e+000,3,9.930925e-001,0.000000e+000,,,,,,,,,,,,,,32,1,4.000000e+000,7.400513e-004,0.000000e+000,0,,0,
1524228669.301,,0.000000e+000,3.399899e+001,-1.885817e-004,0.000000e+000,3,9.930867e-001,0.000000e+000,,,,,,,,,,,,,,32,1,4.000000e+000,7.400513e-004,0.000000e+000,0,,0,
1524228707.209,,0.000000e+000,3.399899e+001,-1.887817e-004,0.000000e+000,3,9.931805e-001,0.000000e+000,,,,,,,,,,,,,,32,1,4.000000e+000,7.400513e-004,0.000000e+000,0,,0,
1524228745.977,,0.000000e+000,3.399825e+001,-1.890348e-004,0.000000e+000,3,9.931966e-001,0.000000e+000,,,,,,,,,,,,,,32,1,4.000000e+000,7.400513e-004,0.000000e+000,0,,0,
1524228783.460,,0.000000e+000,3.399825e+001,-1.892331e-004,0.000000e+000,3,9.932470e-001,0.000000e+000,,,,,,,,,,,,,,32,1,4.000000e+000,7.400513e-004,0.000000e+000,0,,0,
1524228821.698,,0.000000e+000,3.399862e+001,-1.894638e-004,0.000000e+000,3,9.931391e-001,0.000000e+000,,,,,,,,,,,,,,32,1,4.000000e+000,1.480103e-003,0.000000e+000,0,,0,
1524228859.931,,0.000000e+000,3.399935e+001,-1.896566e-004,0.000000e+000,3,9.931023e-001,0.000000e+000,,,,,,,,,,,,,,32,1,4.000000e+000,2.941132e-003,0.000000e+000,0,,0,
1524228897.917,,0.000000e+000,3.399825e+001,-1.898451e-004,0.000000e+000,3,9.931864e-001,0.000000e+000,,,,,,,,,,,,,,32,1,4.000000e+000,7.400513e-004,0.000000e+000,0,,0,
1524228935.922,,0.000000e+000,3.399973e+001,-1.900310e-004,0.000000e+000,3,9.931685e-001,0.000000e+000,,,,,,,,,,,,,,32,1,4.000000e+000,7.324219e-004,0.000000e+000,0,,0,
1524228973.958,,0.000000e+000,3.399936e+001,-1.902026e-004,0.000000e+000,3,9.933934e-001,0.000000e+000,,,,,,,,,,,,,,32,1,4.000000e+000,1.472473e-003,0.000000e+000,0,,0,
1524229012.238,,0.000000e+000,3.399789e+001,-1.903566e-004,0.000000e+000,3,9.931191e-001,0.000000e+000,,,,,,,,,,,,,,32,1,4.000000e+000,2.948761e-003,0.000000e+000,0,,0,
1524229050.384,,0.000000e+000,3.399825e+001,-1.905642e-004,0.000000e+000,3,9.931698e-001,0.000000e+000,,,,,,,,,,,,,,32,1,4.000000e+000,7.400513e-004,0.000000e+000,0,,0,
1524229088.205,,0.000000e+000,3.399714e+001,-1.906844e-004,0.000000e+000,3,9.932617e-001,0.000000e+000,,,,,,,,,,,,,,32,1,4.000000e+000,0.000000e+000,0.000000e+000,0,,0,
1524229125.743,,0.000000e+000,3.399935e+001,-1.908715e-004,0.000000e+000,3,9.931791e-001,0.000000e+000,,,,,,,,,,,,,,32,1,4.000000e+000,2.941132e-003,0.000000e+000,0,,0,
1524229163.556,,0.000000e+000,3.399825e+001,-1.910223e-004,0.000000e+000,3,9.932556e-001,0.000000e+000,,,,,,,,,,,,,,32,1,4.000000e+000,7.400513e-004,0.000000e+000,0,,0,
1524229201.774,,0.000000e+000,3.399899e+001,-1.911640e-004,0.000000e+000,3,9.930503e-001,0.000000e+000,,,,,,,,,,,,,,32,1,4.000000e+000,7.400513e-004,0.000000e+000,0,,0,
1524229239.222,,0.000000e+000,3.399862e+001,-1.913189e-004,0.000000e+000,3,9.932328e-001,0.000000e+000,,,,,,,,,,,,,,32,1,4.000000e+000,0.000000e+000,0.000000e+000,0,,0,
1524229276.970,,0.000000e+000,3.399899e+001,-1.914825e-004,0.000000e+000,3,9.929979e-001,0.000000e+000,,,,,,,,,,,,,,32,1,4.000000e+000,2.212524e-003,0.000000e+000,0,,0,
1524229314.795,,0.000000e+000,3.399862e+001,-1.915812e-004,0.000000e+000,3,9.931351e-001,0.000000e+000,,,,,,,,,,,,,,32,1,4.000000e+000,0.000000e+000,0.000000e+000,0,,0,
1524229352.863,,0.000000e+000,3.399899e+001,-1.917586e-004,0.000000e+000,3,9.931339e-001,0.000000e+000,,,,,,,,,,,,,,32,1,4.000000e+000,7.400513e-004,0.000000e+000,0,,0,
1524229390.774,,0.000000e+000,3.399862e+001,-1.918897e-004,0.000000e+000,3,9.932916e-001,0.000000e+000,,,,,,,,,,,,,,32,1,4.000000e+000,1.480103e-003,0.000000e+000,0,,0,
1524229430.095,,0.000000e+000,3.399899e+001,-1.920946e-004,0.000000e+000,3,9.931414e-001,0.000000e+000,,,,,,,,,,,,,,32,1,4.000000e+000,7.400513e-004,0.000000e+000,0,,0,
1524229467.413,,0.000000e+000,3.399825e+001,-1.921569e-004,0.000000e+000,3,9.930574e-001,0.000000e+000,,,,,,,,,,,,,,32,1,4.000000e+000,2.220154e-003,0.000000e+000,0,,0,
1524229505.553,,0.000000e+000,3.399825e+001,-1.922536e-004,0.000000e+000,3,9.930844e-001,0.000000e+000,,,,,,,,,,,,,,32,1,4.000000e+000,7.400513e-004,0.000000e+000,0,,0,
1524229543.246,,0.000000e+000,3.399825e+001,-1.923770e-004,0.000000e+000,3,9.934098e-001,0.000000e+000,,,,,,,,,,,,,,32,1,4.000000e+000,7.400513e-004,0.000000e+000,0,,0,
1524229581.999,,0.000000e+000,3.399751e+001,-1.925228e-004,0.000000e+000,3,9.932621e-001,0.000000e+000,,,,,,,,,,,,,,32,1,4.000000e+000,2.208710e-003,0.000000e+000,0,,0,
1524229620.250,,0.000000e+000,3.399899e+001,-1.926289e-004,0.000000e+000,3,9.930201e-001,0.000000e+000,,,,,,,,,,,,,,32,1,4.000000e+000,7.400513e-004,0.000000e+000,0,,0,
1524229658.025,,0.000000e+000,3.399899e+001,-1.927003e-004,0.000000e+000,3,9.931052e-001,0.000000e+000,,,,,,,,,,,,,,32,1,4.000000e+000,7.400513e-004,0.000000e+000,0,,0,
1524229696.203,,0.000000e+000,3.399862e+001,-1.928128e-004,0.000000e+000,3,9.932046e-001,0.000000e+000,,,,,,,,,,,,,,32,1,4.000000e+000,0.000000e+000,0.000000e+000,0,,0,
1524229734.174,,0.000000e+000,3.399825e+001,-1.929769e-004,0.000000e+000,3,9.931922e-001,0.000000e+000,,,,,,,,,,,,,,32,1,4.000000e+000,7.400513e-004,0.000000e+000,0,,0,
1524229772.545,,0.000000e+000,3.400009e+001,-1.930625e-004,0.000000e+000,3,9.930990e-001,0.000000e+000,,,,,,,,,,,,,,32,1,4.000000e+000,1.461029e-003,0.000000e+000,0,,0,
1524229810.450,,0.000000e+000,3.399862e+001,-1.931896e-004,0.000000e+000,3,9.932165e-001,0.000000e+000,,,,,,,,,,,,,,32,1,4.000000e+000,1.480103e-003,0.000000e+000,0,,0,
1524229849.526,,0.000000e+000,3.399751e+001,-1.932940e-004,0.000000e+000,3,9.931854e-001,0.000000e+000,,,,,,,,,,,,,,32,1,4.000000e+000,7.400513e-004,0.000000e+000,0,,0,
1524229887.954,,0.000000e+000,3.399862e+001,-1.933873e-004,0.000000e+000,3,9.932308e-001,0.000000e+000,,,,,,,,,,,,,,32,1,4.000000e+000,1.480103e-003,0.000000e+000,0,,0,
1524229925.527,,0.000000e+000,3.399936e+001,-1.935061e-004,0.000000e+000,3,9.932737e-001,0.000000e+000,,,,,,,,,,,,,,32,1,4.000000e+000,0.000000e+000,0.000000e+000,0,,0,
1524229964.192,,0.000000e+000,3.399899e+001,-1.935995e-004,0.000000e+000,3,9.932121e-001,0.000000e+000,,,,,,,,,,,,,,32,1,4.000000e+000,2.212524e-003,0.000000e+000,0,,0,
1524230001.873,,0.000000e+000,3.399935e+001,-1.936688e-004,0.000000e+000,3,9.933699e-001,0.000000e+000,,,,,,,,,,,,,,32,1,4.000000e+000,2.941132e-003,0.000000e+000,0,,0,
1524230040.516,,0.000000e+000,3.399862e+001,-1.937722e-004,0.000000e+000,3,9.931709e-001,0.000000e+000,,,,,,,,,,,,,,32,1,4.000000e+000,1.480103e-003,0.000000e+000,0,,0,
1524230078.789,,0.000000e+000,3.399936e+001,-1.938919e-004,0.000000e+000,3,9.931836e-001,0.000000e+000,,,,,,,,,,,,,,32,1,4.000000e+000,0.000000e+000,0.000000e+000,0,,0,
1524230117.252,,0.000000e+000,3.399862e+001,-1.939940e-004,0.000000e+000,3,9.931043e-001,0.000000e+000,,,,,,,,,,,,,,32,1,4.000000e+000,0.000000e+000,0.000000e+000,0,,0,
1524230156.283,,0.000000e+000,3.399862e+001,-1.940677e-004,0.000000e+000,3,9.932371e-001,0.000000e+000,,,,,,,,,,,,,,32,1,4.000000e+000,2.952576e-003,0.000000e+000,0,,0,
1524230193.503,,0.000000e+000,3.399862e+001,-1.941555e-004,0.000000e+000,3,9.933909e-001,0.000000e+000,,,,,,,,,,,,,,32,1,4.000000e+000,1.480103e-003,0.000000e+000,0,,0,
1524230231.974,,0.000000e+000,3.399604e+001,-1.943002e-004,0.000000e+000,3,9.932961e-001,0.000000e+000,,,,,,,,,,,,,,32,1,4.000000e+000,6.629944e-003,0.000000e+000,0,,0,
1524230269.959,,0.000000e+000,3.399715e+001,-1.942908e-004,0.000000e+000,3,9.933917e-001,0.000000e+000,,,,,,,,,,,,,,32,1,4.000000e+000,2.948761e-003,0.000000e+000,0,,0,
1524230308.315,,0.000000e+000,3.399936e+001,-1.944165e-004,0.000000e+000,3,9.933415e-001,0.000000e+000,,,,,,,,,,,,,,32,1,4.000000e+000,1.472473e-003,0.000000e+000,0,,0,
1524230346.901,,0.000000e+000,3.399973e+001,-1.945267e-004,0.000000e+000,3,9.931232e-001,0.000000e+000,,,,,,,,,,,,,,32,1,4.000000e+000,7.324219e-004,0.000000e+000,0,,0,
1524230385.294,,0.000000e+000,3.399862e+001,-1.946917e-004,0.000000e+000,3,9.933965e-001,0.000000e+000,,,,,,,,,,,,,,32,1,4.000000e+000,1.480103e-003,0.000000e+000,0,,0,
1524230424.077,,0.000000e+000,3.399899e+001,-1.947326e-004,0.000000e+000,3,9.932938e-001,0.000000e+000,,,,,,,,,,,,,,32,1,4.000000e+000,7.400513e-004,0.000000e+000,0,,0,
1524230461.850,,0.000000e+000,3.399862e+001,-1.947839e-004,0.000000e+000,3,9.932789e-001,0.000000e+000,,,,,,,,,,,,,,32,1,4.000000e+000,0.000000e+000,0.000000e+000,0,,0,
1524230500.443,,0.000000e+000,3.399899e+001,-1.948512e-004,0.000000e+000,3,9.931920e-001,0.000000e+000,,,,,,,,,,,,,,32,1,4.000000e+000,7.400513e-004,0.000000e+000,0,,0,
1524230538.263,,0.000000e+000,3.399936e+001,-1.949400e-004,0.000000e+000,3,9.931428e-001,0.000000e+000,,,,,,,,,,,,,,32,1,4.000000e+000,0.000000e+000,0.000000e+000,0,,0,
1524230577.054,,0.000000e+000,3.400009e+001,-1.950439e-004,0.000000e+000,3,9.931917e-001,0.000000e+000,,,,,,,,,,,,,,32,1,4.000000e+000,1.461029e-003,0.000000e+000,0,,0,
1524230614.119,,0.000000e+000,3.399973e+001,-1.951061e-004,0.000000e+000,3,9.932973e-001,0.000000e+000,,,,,,,,,,,,,,32,1,4.000000e+000,7.324219e-004,0.000000e+000,0,,0,
1524230651.812,,0.000000e+000,3.399899e+001,-1.951877e-004,0.000000e+000,3,9.932829e-001,0.000000e+000,,,,,,,,,,,,,,32,1,4.000000e+000,7.400513e-004,0.000000e+000,0,,0,
1524230690.218,,0.000000e+000,3.399899e+001,-1.952523e-004,0.000000e+000,3,9.931973e-001,0.000000e+000,,,,,,,,,,,,,,32,1,4.000000e+000,2.212524e-003,0.000000e+000,0,,0,
1524230728.159,,0.000000e+000,3.399936e+001,-1.953183e-004,0.000000e+000,3,9.931548e-001,0.000000e+000,,,,,,,,,,,,,,32,1,4.000000e+000,0.000000e+000,0.000000e+000,0,,0,
1524230766.369,,0.000000e+000,3.399973e+001,-1.953991e-004,0.000000e+000,3,9.932250e-001,0.000000e+000,,,,,,,,,,,,,,32,1,4.000000e+000,7.324219e-004,0.000000e+000,0,,0,
1524230804.702,,0.000000e+000,3.399936e+001,-1.954274e-004,0.000000e+000,3,9.933170e-001,0.000000e+000,,,,,,,,,,,,,,32,1,4.000000e+000,1.472473e-003,0.000000e+000,0,,0,
1524230843.178,,0.000000e+000,3.399936e+001,-1.955715e-004,0.000000e+000,3,9.932756e-001,0.000000e+000,,,,,,,,,,,,,,32,1,4.000000e+000,1.472473e-003,0.000000e+000,0,,0,
1524230881.431,,0.000000e+000,3.400009e+001,-1.955958e-004,0.000000e+000,3,9.932635e-001,0.000000e+000,,,,,,,,,,,,,,32,1,4.000000e+000,1.461029e-003,0.000000e+000,0,,0,
1524230919.792,,0.000000e+000,3.399973e+001,-1.956577e-004,0.000000e+000,3,9.932265e-001,0.000000e+000,,,,,,,,,,,,,,32,1,4.000000e+000,7.324219e-004,0.000000e+000,0,,0,
1524230958.090,,0.000000e+000,3.399715e+001,-1.957285e-004,0.000000e+000,3,9.932303e-001,0.000000e+000,,,,,,,,,,,,,,32,1,4.000000e+000,1.468658e-003,0.000000e+000,0,,0,
1524230996.150,,0.000000e+000,3.399788e+001,-1.958561e-004,0.000000e+000,3,9.933718e-001,0.000000e+000,,,,,,,,,,,,,,32,1,4.000000e+000,1.480103e-003,0.000000e+000,0,,0,
1524231033.928,,0.000000e+000,3.399788e+001,-1.959183e-004,0.000000e+000,3,9.931815e-001,0.000000e+000,,,,,,,,,,,,,,32,1,4.000000e+000,1.480103e-003,0.000000e+000,0,,0,
1524231071.371,,0.000000e+000,3.400046e+001,-1.959534e-004,0.000000e+000,3,9.932227e-001,0.000000e+000,,,,,,,,,,,,,,32,1,4.000000e+000,2.201080e-003,0.000000e+000,0,,0,
1524231109.757,,0.000000e+000,3.399936e+001,-1.959931e-004,0.000000e+000,3,9.934022e-001,0.000000e+000,,,,,,,,,,,,,,32,1,4.000000e+000,0.000000e+000,0.000000e+000,0,,0,
1524231147.805,,0.000000e+000,3.399936e+001,-1.960589e-004,0.000000e+000,3,9.931542e-001,0.000000e+000,,,,,,,,,,,,,,32,1,4.000000e+000,1.472473e-003,0.000000e+000,0,,0,
1524231186.030,,0.000000e+000,3.399825e+001,-1.961872e-004,0.000000e+000,3,9.932076e-001,0.000000e+000,,,,,,,,,,,,,,32,1,4.000000e+000,7.400513e-004,0.000000e+000,0,,0,
1524231224.468,,0.000000e+000,3.399973e+001,-1.962089e-004,0.000000e+000,3,9.933646e-001,0.000000e+000,,,,,,,,,,,,,,32,1,4.000000e+000,7.324219e-004,0.000000e+000,0,,0,
1524231262.644,,0.000000e+000,3.399899e+001,-1.962292e-004,0.000000e+000,3,9.932993e-001,0.000000e+000,,,,,,,,,,,,,,32,1,4.000000e+000,7.400513e-004,0.000000e+000,0,,0,
1524231300.850,,0.000000e+000,3.399973e+001,-1.963466e-004,0.000000e+000,3,9.932348e-001,0.000000e+000,,,,,,,,,,,,,,32,1,4.000000e+000,7.324219e-004,0.000000e+000,0,,0,
1524231339.041,,0.000000e+000,3.399862e+001,-1.963590e-004,0.000000e+000,3,9.933141e-001,0.000000e+000,,,,,,,,,,,,,,32,1,4.000000e+000,1.480103e-003,0.000000e+000,0,,0,
1524231377.547,,0.000000e+000,3.399936e+001,-1.964636e-004,0.000000e+000,3,9.931592e-001,0.000000e+000,,,,,,,,,,,,,,32,1,4.000000e+000,0.000000e+000,0.000000e+000,0,,0,
1524231415.577,,0.000000e+000,3.399899e+001,-1.965004e-004,0.000000e+000,3,9.932730e-001,0.000000e+000,,,,,,,,,,,,,,32,1,4.000000e+000,7.400513e-004,0.000000e+000,0,,0,
1524231454.038,,0.000000e+000,3.399825e+001,-1.965550e-004,0.000000e+000,3,9.931204e-001,0.000000e+000,,,,,,,,,,,,,,32,1,4.000000e+000,2.220154e-003,0.000000e+000,0,,0,
1524231492.436,,0.000000e+000,3.399862e+001,-1.966090e-004,0.000000e+000,3,9.930561e-001,0.000000e+000,,,,,,,,,,,,,,32,1,4.000000e+000,1.480103e-003,0.000000e+000,0,,0,
1524231530.569,,0.000000e+000,3.399862e+001,-1.966584e-004,0.000000e+000,3,9.932015e-001,0.000000e+000,,,,,,,,,,,,,,32,1,4.000000e+000,0.000000e+000,0.000000e+000,0,,0,
1524231569.110,,0.000000e+000,3.399825e+001,-1.967542e-004,0.000000e+000,3,9.931862e-001,0.000000e+000,,,,,,,,,,,,,,32,1,4.000000e+000,7.400513e-004,0.000000e+000,0,,0,
1524231607.100,,0.000000e+000,3.399972e+001,-1.968421e-004,0.000000e+000,3,9.931800e-001,0.000000e+000,,,,,,,,,,,,,,32,1,4.000000e+000,2.201080e-003,0.000000e+000,0,,0,
1524231645.328,,0.000000e+000,3.399936e+001,-1.968674e-004,0.000000e+000,3,9.933192e-001,0.000000e+000,,,,,,,,,,,,,,32,1,4.000000e+000,1.472473e-003,0.000000e+000,0,,0,
1524231683.044,,0.000000e+000,3.399899e+001,-1.969293e-004,0.000000e+000,3,9.931735e-001,0.000000e+000,,,,,,,,,,,,,,32,1,4.000000e+000,7.400513e-004,0.000000e+000,0,,0,
1524231721.097,,0.000000e+000,3.399899e+001,-1.969479e-004,0.000000e+000,3,9.932628e-001,0.000000e+000,,,,,,,,,,,,,,32,1,4.000000e+000,7.400513e-004,0.000000e+000,0,,0,
1524231759.212,,0.000000e+000,3.399899e+001,-1.970081e-004,0.000000e+000,3,9.933001e-001,0.000000e+000,,,,,,,,,,,,,,32,1,4.000000e+000,2.212524e-003,0.000000e+000,0,,0,
1524231797.125,,0.000000e+000,3.399936e+001,-1.970684e-004,0.000000e+000,3,9.932995e-001,0.000000e+000,,,,,,,,,,,,,,32,1,4.000000e+000,1.472473e-003,0.000000e+000,0,,0,
1524231834.871,,0.000000e+000,3.399862e+001,-1.971663e-004,0.000000e+000,3,9.933026e-001,0.000000e+000,,,,,,,,,,,,,,32,1,4.000000e+000,1.480103e-003,0.000000e+000,0,,0,
1524231873.324,,0.000000e+000,3.399899e+001,-1.972481e-004,0.000000e+000,3,9.931186e-001,0.000000e+000,,,,,,,,,,,,,,32,1,4.000000e+000,7.400513e-004,0.000000e+000,0,,0,
1524231912.239,,0.000000e+000,3.400009e+001,-1.972297e-004,0.000000e+000,3,9.932740e-001,0.000000e+000,,,,,,,,,,,,,,32,1,4.000000e+000,2.941132e-003,0.000000e+000,0,,0,
1524231950.553,,0.000000e+000,3.399936e+001,-1.973466e-004,0.000000e+000,3,9.932552e-001,0.000000e+000,,,,,,,,,,,,,,32,1,4.000000e+000,1.472473e-003,0.000000e+000,0,,0,
1524231988.901,,0.000000e+000,3.399973e+001,-1.973907e-004,0.000000e+000,3,9.932153e-001,0.000000e+000,,,,,,,,,,,,,,32,1,4.000000e+000,7.324219e-004,0.000000e+000,0,,0,
1524232026.771,,0.000000e+000,3.399788e+001,-1.974077e-004,0.000000e+000,3,9.934142e-001,0.000000e+000,,,,,,,,,,,,,,32,1,4.000000e+000,1.480103e-003,0.000000e+000,0,,0,
1524232064.929,,0.000000e+000,3.399899e+001,-1.974854e-004,0.000000e+000,3,9.932099e-001,0.000000e+000,,,,,,,,,,,,,,32,1,4.000000e+000,7.400513e-004,0.000000e+000,0,,0,
1524232102.895,,0.000000e+000,3.399862e+001,-1.975189e-004,0.000000e+000,3,9.932328e-001,0.000000e+000,,,,,,,,,,,,,,32,1,4.000000e+000,1.480103e-003,0.000000e+000,0,,0,
1524232141.930,,0.000000e+000,3.399899e+001,-1.975780e-004,0.000000e+000,3,9.931831e-001,0.000000e+000,,,,,,,,,,,,,,32,1,4.000000e+000,7.400513e-004,0.000000e+000,0,,0,
1524232180.266,,0.000000e+000,3.399936e+001,-1.975932e-004,0.000000e+000,3,9.932601e-001,0.000000e+000,,,,,,,,,,,,,,32,1,4.000000e+000,0.000000e+000,0.000000e+000,0,,0,
1524232218.364,,0.000000e+000,3.399973e+001,-1.976746e-004,0.000000e+000,3,9.932123e-001,0.000000e+000,,,,,,,,,,,,,,32,1,4.000000e+000,7.324219e-004,0.000000e+000,0,,0,
1524232256.620,,0.000000e+000,3.400009e+001,-1.977303e-004,0.000000e+000,3,9.932693e-001,0.000000e+000,,,,,,,,,,,,,,32,1,4.000000e+000,0.000000e+000,0.000000e+000,0,,0,
1524232294.993,,0.000000e+000,3.399899e+001,-1.977735e-004,0.000000e+000,3,9.933172e-001,0.000000e+000,,,,,,,,,,,,,,32,1,4.000000e+000,7.400513e-004,0.000000e+000,0,,0,
1524232333.433,,0.000000e+000,3.399899e+001,-1.977851e-004,0.000000e+000,3,9.932286e-001,0.000000e+000,,,,,,,,,,,,,,32,1,4.000000e+000,2.212524e-003,0.000000e+000,0,,0,
1524232371.896,,0.000000e+000,3.399825e+001,-1.978500e-004,0.000000e+000,3,9.931731e-001,0.000000e+000,,,,,,,,,,,,,,32,1,4.000000e+000,7.400513e-004,0.000000e+000,0,,0,
1524232410.389,,0.000000e+000,3.399899e+001,-1.979257e-004,0.000000e+000,3,9.932655e-001,0.000000e+000,,,,,,,,,,,,,,32,1,4.000000e+000,2.212524e-003,0.000000e+000,0,,0,
1524232448.995,,0.000000e+000,3.399862e+001,-1.979545e-004,0.000000e+000,3,9.932637e-001,0.000000e+000,,,,,,,,,,,,,,32,1,4.000000e+000,0.000000e+000,0.000000e+000,0,,0,
1524232486.770,,0.000000e+000,3.399862e+001,-1.980039e-004,0.000000e+000,3,9.931656e-001,0.000000e+000,,,,,,,,,,,,,,32,1,4.000000e+000,0.000000e+000,0.000000e+000,0,,0,
1524232526.021,,0.000000e+000,3.399789e+001,-1.980120e-004,0.000000e+000,3,9.932194e-001,0.000000e+000,,,,,,,,,,,,,,32,1,4.000000e+000,2.948761e-003,0.000000e+000,0,,0,
1524232562.842,,0.000000e+000,3.399825e+001,-1.980826e-004,0.000000e+000,3,9.932922e-001,0.000000e+000,,,,,,,,,,,,,,32,1,4.000000e+000,2.220154e-003,0.000000e+000,0,,0,
1524232601.102,,0.000000e+000,3.399936e+001,-1.981265e-004,0.000000e+000,3,9.933073e-001,0.000000e+000,,,,,,,,,,,,,,32,1,4.000000e+000,1.472473e-003,0.000000e+000,0,,0,
1524232639.650,,0.000000e+000,3.399751e+001,-1.981932e-004,0.000000e+000,3,9.933775e-001,0.000000e+000,,,,,,,,,,,,,,32,1,4.000000e+000,2.208710e-003,0.000000e+000,0,,0,
1524232677.208,,0.000000e+000,3.399899e+001,-1.982491e-004,0.000000e+000,3,9.932311e-001,0.000000e+000,,,,,,,,,,,,,,32,1,4.000000e+000,7.400513e-004,0.000000e+000,0,,0,
1524232715.371,,0.000000e+000,3.399862e+001,-1.982480e-004,0.000000e+000,3,9.932845e-001,0.000000e+000,,,,,,,,,,,,,,32,1,4.000000e+000,1.480103e-003,0.000000e+000,0,,0,
1524232753.907,,0.000000e+000,3.399973e+001,-1.982963e-004,0.000000e+000,3,9.932784e-001,0.000000e+000,,,,,,,,,,,,,,32,1,4.000000e+000,7.324219e-004,0.000000e+000,0,,0,
1524232791.732,,0.000000e+000,3.399936e+001,-1.983657e-004,0.000000e+000,3,9.932822e-001,0.000000e+000,,,,,,,,,,,,,,32,1,4.000000e+000,1.472473e-003,0.000000e+000,0,,0,
1524232829.948,,0.000000e+000,3.399973e+001,-1.983979e-004,0.000000e+000,3,9.935039e-001,0.000000e+000,,,,,,,,,,,,,,32,1,4.000000e+000,7.324219e-004,0.000000e+000,0,,0,
1524232868.046,,0.000000e+000,3.399936e+001,-1.984312e-004,0.000000e+000,3,9.932303e-001,0.000000e+000,,,,,,,,,,,,,,32,1,4.000000e+000,0.000000e+000,0.000000e+000,0,,0,
1524232906.363,,0.000000e+000,3.400046e+001,-1.984401e-004,0.000000e+000,3,9.931175e-001,0.000000e+000,,,,,,,,,,,,,,32,1,4.000000e+000,2.201080e-003,0.000000e+000,0,,0,
1524232944.118,,0.000000e+000,3.399973e+001,-1.984946e-004,0.000000e+000,3,9.933894e-001,0.000000e+000,,,,,,,,,,,,,,32,1,4.000000e+000,7.324219e-004,0.000000e+000,0,,0,
1524232982.589,,0.000000e+000,3.399899e+001,-1.985353e-004,0.000000e+000,3,9.933039e-001,0.000000e+000,,,,,,,,,,,,,,32,1,4.000000e+000,7.400513e-004,0.000000e+000,0,,0,
1524233020.494,,0.000000e+000,3.400009e+001,-1.985602e-004,0.000000e+000,3,9.933851e-001,0.000000e+000,,,,,,,,,,,,,,32,1,4.000000e+000,4.421234e-003,0.000000e+000,0,,0,
1524233058.977,,0.000000e+000,3.399936e+001,-1.986549e-004,0.000000e+000,3,9.935598e-001,0.000000e+000,,,,,,,,,,,,,,32,1,4.000000e+000,0.000000e+000,0.000000e+000,0,,0,
1524233098.345,,0.000000e+000,3.399862e+001,-1.987040e-004,0.000000e+000,3,9.932494e-001,0.000000e+000,,,,,,,,,,,,,,32,1,4.000000e+000,0.000000e+000,0.000000e+000,0,,0,
1524233136.723,,0.000000e+000,3.399973e+001,-1.987379e-004,0.000000e+000,3,9.932089e-001,0.000000e+000,,,,,,,,,,,,,,32,1,4.000000e+000,7.324219e-004,0.000000e+000,0,,0,
1524233175.162,,0.000000e+000,3.399899e+001,-1.987837e-004,0.000000e+000,3,9.932216e-001,0.000000e+000,,,,,,,,,,,,,,32,1,4.000000e+000,7.400513e-004,0.000000e+000,0,,0,
1524233213.520,,0.000000e+000,3.399973e+001,-1.988418e-004,0.000000e+000,3,9.933614e-001,0.000000e+000,,,,,,,,,,,,,,32,1,4.000000e+000,7.324219e-004,0.000000e+000,0,,0,
1524233251.573,,0.000000e+000,3.399973e+001,-1.988855e-004,0.000000e+000,3,9.933206e-001,0.000000e+000,,,,,,,,,,,,,,32,1,4.000000e+000,7.324219e-004,0.000000e+000,0,,0,
1524233289.996,,0.000000e+000,3.399899e+001,-1.989373e-004,0.000000e+000,3,9.931926e-001,0.000000e+000,,,,,,,,,,,,,,32,1,4.000000e+000,7.400513e-004,0.000000e+000,0,,0,
1524233327.296,,0.000000e+000,3.399936e+001,-1.989766e-004,0.000000e+000,3,9.933267e-001,0.000000e+000,,,,,,,,,,,,,,32,1,4.000000e+000,1.472473e-003,0.000000e+000,0,,0,
1524233365.849,,0.000000e+000,3.399899e+001,-1.989699e-004,0.000000e+000,3,9.933909e-001,0.000000e+000,,,,,,,,,,,,,,32,1,4.000000e+000,7.400513e-004,0.000000e+000,0,,0,
1524233403.352,,0.000000e+000,3.399862e+001,-1.989908e-004,0.000000e+000,3,9.932848e-001,0.000000e+000,,,,,,,,,,,,,,32,1,4.000000e+000,1.480103e-003,0.000000e+000,0,,0,
1524233441.575,,0.000000e+000,3.399936e+001,-1.990786e-004,0.000000e+000,3,9.932610e-001,0.000000e+000,,,,,,,,,,,,,,32,1,4.000000e+000,0.000000e+000,0.000000e+000,0,,0,
1524233479.784,,0.000000e+000,3.399751e+001,-1.991127e-004,0.000000e+000,3,9.933546e-001,0.000000e+000,,,,,,,,,,,,,,32,1,4.000000e+000,3.688812e-003,0.000000e+000,0,,0,
1524233518.207,,0.000000e+000,3.400156e+001,-1.991585e-004,0.000000e+000,3,9.933941e-001,0.000000e+000,,,,,,,,,,,,,,32,1,4.000000e+000,5.889893e-003,0.000000e+000,0,,0,
1524233556.370,,0.000000e+000,3.399899e+001,-1.991886e-004,0.000000e+000,3,9.932718e-001,0.000000e+000,,,,,,,,,,,,,,32,1,4.000000e+000,7.400513e-004,0.000000e+000,0,,0,
1524233594.303,,0.000000e+000,3.399973e+001,-1.992313e-004,0.000000e+000,3,9.931994e-001,0.000000e+000,,,,,,,,,,,,,,32,1,4.000000e+000,7.324219e-004,0.000000e+000,0,,0,
1524233632.321,,0.000000e+000,3.399604e+001,-1.992427e-004,0.000000e+000,3,9.932739e-001,0.000000e+000,,,,,,,,,,,,,,32,1,4.000000e+000,5.149841e-003,0.000000e+000,0,,0,
1524233670.619,,0.000000e+000,3.399936e+001,-1.992868e-004,0.000000e+000,3,9.932413e-001,0.000000e+000,,,,,,,,,,,,,,32,1,4.000000e+000,0.000000e+000,0.000000e+000,0,,0,
1524233708.772,,0.000000e+000,3.399936e+001,-1.993228e-004,0.000000e+000,3,9.933670e-001,0.000000e+000,,,,,,,,,,,,,,32,1,4.000000e+000,0.000000e+000,0.000000e+000,0,,0,
1524233747.012,,0.000000e+000,3.399973e+001,-1.993692e-004,0.000000e+000,3,9.932515e-001,0.000000e+000,,,,,,,,,,,,,,32,1,4.000000e+000,7.324219e-004,0.000000e+000,0,,0,
1524233785.113,,0.000000e+000,3.399715e+001,-1.993920e-004,0.000000e+000,3,9.933666e-001,0.000000e+000,,,,,,,,,,,,,,32,1,4.000000e+000,1.468658e-003,0.000000e+000,0,,0,
1524233823.361,,0.000000e+000,3.399862e+001,-1.994189e-004,0.000000e+000,3,9.931913e-001,0.000000e+000,,,,,,,,,,,,,,32,1,4.000000e+000,2.952576e-003,0.000000e+000,0,,0,
1524233861.777,,0.000000e+000,3.399862e+001,-1.994689e-004,0.000000e+000,3,9.933007e-001,0.000000e+000,,,,,,,,,,,,,,32,1,4.000000e+000,1.480103e-003,0.000000e+000,0,,0,
1524233900.027,,0.000000e+000,3.399899e+001,-1.995263e-004,0.000000e+000,3,9.932056e-001,0.000000e+000,,,,,,,,,,,,,,32,1,4.000000e+000,7.400513e-004,0.000000e+000,0,,0,
1524233938.170,,0.000000e+000,3.399862e+001,-1.995632e-004,0.000000e+000,3,9.933023e-001,0.000000e+000,,,,,,,,,,,,,,32,1,4.000000e+000,0.000000e+000,0.000000e+000,0,,0,
1524233976.536,,0.000000e+000,3.399862e+001,-1.995885e-004,0.000000e+000,3,9.931967e-001,0.000000e+000,,,,,,,,,,,,,,32,1,4.000000e+000,1.480103e-003,0.000000e+000,0,,0,
1524234015.166,,0.000000e+000,3.399936e+001,-1.996081e-004,0.000000e+000,3,9.931937e-001,0.000000e+000,,,,,,,,,,,,,,32,1,4.000000e+000,1.472473e-003,0.000000e+000,0,,0,
1524234052.757,,0.000000e+000,3.400046e+001,-1.996629e-004,0.000000e+000,3,9.933789e-001,0.000000e+000,,,,,,,,,,,,,,32,1,4.000000e+000,7.286072e-004,0.000000e+000,0,,0,
1524234091.177,,0.000000e+000,3.399899e+001,-1.996904e-004,0.000000e+000,3,9.932310e-001,0.000000e+000,,,,,,,,,,,,,,32,1,4.000000e+000,7.400513e-004,0.000000e+000,0,,0,
1524234129.966,,0.000000e+000,3.399862e+001,-1.997077e-004,0.000000e+000,3,9.932718e-001,0.000000e+000,,,,,,,,,,,,,,32,1,4.000000e+000,0.000000e+000,0.000000e+000,0,,0,
1524234167.576,,0.000000e+000,3.399899e+001,-1.997157e-004,0.000000e+000,3,9.932852e-001,0.000000e+000,,,,,,,,,,,,,,32,1,4.000000e+000,7.400513e-004,0.000000e+000,0,,0,
1524234204.912,,0.000000e+000,3.399899e+001,-1.997813e-004,0.000000e+000,3,9.932501e-001,0.000000e+000,,,,,,,,,,,,,,32,1,4.000000e+000,7.400513e-004,0.000000e+000,0,,0,
1524234243.447,,0.000000e+000,3.399825e+001,-1.998571e-004,0.000000e+000,3,9.932975e-001,0.000000e+000,,,,,,,,,,,,,,32,1,4.000000e+000,2.220154e-003,0.000000e+000,0,,0,
1524234281.318,,0.000000e+000,3.399862e+001,-1.998969e-004,0.000000e+000,3,9.930597e-001,0.000000e+000,,,,,,,,,,,,,,32,1,4.000000e+000,1.480103e-003,0.000000e+000,0,,0,
1524234318.991,,0.000000e+000,3.400009e+001,-1.998601e-004,0.000000e+000,3,9.931508e-001,0.000000e+000,,,,,,,,,,,,,,32,1,4.000000e+000,1.461029e-003,0.000000e+000,0,,0,
1524234357.254,,0.000000e+000,3.399973e+001,-1.999382e-004,0.000000e+000,3,9.930946e-001,0.000000e+000,,,,,,,,,,,,,,32,1,4.000000e+000,7.324219e-004,0.000000e+000,0,,0,
1524234395.259,,0.000000e+000,3.400009e+001,-1.999385e-004,0.000000e+000,3,9.932004e-001,0.000000e+000,,,,,,,,,,,,,,32,1,4.000000e+000,1.461029e-003,0.000000e+000,0,,0,
1524234434.272,,0.000000e+000,3.400046e+001,-2.000095e-004,0.000000e+000,3,9.933137e-001,0.000000e+000,,,,,,,,,,,,,,32,1,4.000000e+000,2.201080e-003,0.000000e+000,0,,0,
1524234472.511,,0.000000e+000,3.399899e+001,-2.000010e-004,0.000000e+000,3,9.932784e-001,0.000000e+000,,,,,,,,,,,,,,32,1,4.000000e+000,7.400513e-004,0.000000e+000,0,,0,
1524234510.166,,0.000000e+000,3.399899e+001,-2.000748e-004,0.000000e+000,3,9.931095e-001,0.000000e+000,,,,,,,,,,,,,,32,1,4.000000e+000,7.400513e-004,0.000000e+000,0,,0,
1524234548.069,,0.000000e+000,3.399936e+001,-2.001137e-004,0.000000e+000,3,9.930680e-001,0.000000e+000,,,,,,,,,,,,,,32,1,4.000000e+000,1.472473e-003,0.000000e+000,0,,0,
1524234586.097,,0.000000e+000,3.399641e+001,-2.001352e-004,0.000000e+000,3,9.933072e-001,0.000000e+000,,,,,,,,,,,,,,32,1,4.000000e+000,5.889893e-003,0.000000e+000,0,,0,
1524234624.695,,0.000000e+000,3.399789e+001,-2.001337e-004,0.000000e+000,3,9.933290e-001,0.000000e+000,,,,,,,,,,,,,,32,1,4.000000e+000,2.948761e-003,0.000000e+000,0,,0,
1524234662.261,,0.000000e+000,3.399862e+001,-2.002169e-004,0.000000e+000,3,9.933345e-001,0.000000e+000,,,,,,,,,,,,,,32,1,4.000000e+000,1.480103e-003,0.000000e+000,0,,0,
1524234700.401,,0.000000e+000,3.399862e+001,-2.002338e-004,0.000000e+000,3,9.932086e-001,0.000000e+000,,,,,,,,,,,,,,32,1,4.000000e+000,1.480103e-003,0.000000e+000,0,,0,
1524234738.574,,0.000000e+000,3.399862e+001,-2.002416e-004,0.000000e+000,3,9.933022e-001,0.000000e+000,,,,,,,,,,,,,,32,1,4.000000e+000,0.000000e+000,0.000000e+000,0,,0,
1524234776.748,,0.000000e+000,3.399936e+001,-2.002451e-004,0.000000e+000,3,9.932520e-001,0.000000e+000,,,,,,,,,,,,,,32,1,4.000000e+000,0.000000e+000,0.000000e+000,0,,0,
1524234814.971,,0.000000e+000,3.399899e+001,-2.003166e-004,0.000000e+000,3,9.931813e-001,0.000000e+000,,,,,,,,,,,,,,32,1,4.000000e+000,7.400513e-004,0.000000e+000,0,,0,
1524234853.299,,0.000000e+000,3.399973e+001,-2.003109e-004,0.000000e+000,3,9.932685e-001,0.000000e+000,,,,,,,,,,,,,,32,1,4.000000e+000,7.324219e-004,0.000000e+000,0,,0,
1524234891.329,,0.000000e+000,3.400046e+001,-2.004601e-004,0.000000e+000,3,9.931807e-001,0.000000e+000,,,,,,,,,,,,,,32,1,4.000000e+000,7.286072e-004,0.000000e+000,0,,0,
1524234928.782,,0.000000e+000,3.399862e+001,-2.004050e-004,0.000000e+000,3,9.931418e-001,0.000000e+000,,,,,,,,,,,,,,32,1,4.000000e+000,1.480103e-003,0.000000e+000,0,,0,
1524234967.215,,0.000000e+000,3.399825e+001,-2.004576e-004,0.000000e+000,3,9.931690e-001,0.000000e+000,,,,,,,,,,,,,,32,1,4.000000e+000,7.400513e-004,0.000000e+000,0,,0,
1524235006.121,,0.000000e+000,3.399862e+001,-2.004706e-004,0.000000e+000,3,9.933363e-001,0.000000e+000,,,,,,,,,,,,,,32,1,4.000000e+000,0.000000e+000,0.000000e+000,0,,0,
1524235044.499,,0.000000e+000,3.399936e+001,-2.005680e-004,0.000000e+000,3,9.932099e-001,0.000000e+000,,,,,,,,,,,,,,32,1,4.000000e+000,0.000000e+000,0.000000e+000,0,,0,
1524235082.997,,0.000000e+000,3.399973e+001,-2.004269e-004,0.000000e+000,3,9.932961e-001,0.000000e+000,,,,,,,,,,,,,,32,1,4.000000e+000,7.324219e-004,0.000000e+000,0,,0,
1524235121.568,,0.000000e+000,3.399973e+001,-2.005822e-004,0.000000e+000,3,9.932168e-001,0.000000e+000,,,,,,,,,,,,,,32,1,4.000000e+000,7.324219e-004,0.000000e+000,0,,0,
1524235159.693,,0.000000e+000,3.399936e+001,-2.006678e-004,0.000000e+000,3,9.931845e-001,0.000000e+000,,,,,,,,,,,,,,32,1,4.000000e+000,0.000000e+000,0.000000e+000,0,,0,
1524235197.551,,0.000000e+000,3.399825e+001,-2.006271e-004,0.000000e+000,3,9.932297e-001,0.000000e+000,,,,,,,,,,,,,,32,1,4.000000e+000,2.220154e-003,0.000000e+000,0,,0,
1524235236.034,,0.000000e+000,3.399973e+001,-2.006092e-004,0.000000e+000,3,9.933636e-001,0.000000e+000,,,,,,,,,,,,,,32,1,4.000000e+000,7.324219e-004,0.000000e+000,0,,0,
1524235273.922,,0.000000e+000,3.399936e+001,-2.006624e-004,0.000000e+000,3,9.935220e-001,0.000000e+000,,,,,,,,,,,,,,32,1,4.000000e+000,0.000000e+000,0.000000e+000,0,,0,
1524235312.395,,0.000000e+000,3.399825e+001,-2.007017e-004,0.000000e+000,3,9.931905e-001,0.000000e+000,,,,,,,,,,,,,,32,1,4.000000e+000,7.400513e-004,0.000000e+000,0,,0,
1524235350.461,,0.000000e+000,3.399825e+001,-2.007228e-004,0.000000e+000,3,9.932066e-001,0.000000e+000,,,,,,,,,,,,,,32,1,4.000000e+000,7.400513e-004,0.000000e+000,0,,0,
1524235388.847,,0.000000e+000,3.399973e+001,-2.007291e-004,0.000000e+000,3,9.931984e-001,0.000000e+000,,,,,,,,,,,,,,32,1,4.000000e+000,7.324219e-004,0.000000e+000,0,,0,
1524235427.565,,0.000000e+000,3.400009e+001,-2.007871e-004,0.000000e+000,3,9.931261e-001,0.000000e+000,,,,,,,,,,,,,,32,1,4.000000e+000,0.000000e+000,0.000000e+000,0,,0,
1524235465.383,,0.000000e+000,3.399973e+001,-2.008820e-004,0.000000e+000,3,9.932556e-001,0.000000e+000,,,,,,,,,,,,,,32,1,4.000000e+000,7.324219e-004,0.000000e+000,0,,0,
1524235503.486,,0.000000e+000,3.399862e+001,-2.008437e-004,0.000000e+000,3,9.933048e-001,0.000000e+000,,,,,,,,,,,,,,32,1,4.000000e+000,1.480103e-003,0.000000e+000,0,,0,
1524235541.729,,0.000000e+000,3.399936e+001,-2.008760e-004,0.000000e+000,3,9.931972e-001,0.000000e+000,,,,,,,,,,,,,,32,1,4.000000e+000,0.000000e+000,0.000000e+000,0,,0,
1524235579.867,,0.000000e+000,3.399862e+001,-2.008321e-004,0.000000e+000,3,9.933267e-001,0.000000e+000,,,,,,,,,,,,,,32,1,4.000000e+000,0.000000e+000,0.000000e+000,0,,0,
1524235617.490,,0.000000e+000,3.399862e+001,-2.009703e-004,0.000000e+000,3,9.931874e-001,0.000000e+000,,,,,,,,,,,,,,32,1,4.000000e+000,0.000000e+000,0.000000e+000,0,,0,
1524235655.688,,0.000000e+000,3.399862e+001,-2.009712e-004,0.000000e+000,3,9.931194e-001,0.000000e+000,,,,,,,,,,,,,,32,1,4.000000e+000,0.000000e+000,0.000000e+000,0,,0,
1524235694.216,,0.000000e+000,3.400009e+001,-2.009459e-004,0.000000e+000,3,9.933771e-001,0.000000e+000,,,,,,,,,,,,,,32,1,4.000000e+000,1.461029e-003,0.000000e+000,0,,0,
1524235732.344,,0.000000e+000,3.399751e+001,-2.010214e-004,0.000000e+000,3,9.932384e-001,0.000000e+000,,,,,,,,,,,,,,32,1,4.000000e+000,7.400513e-004,0.000000e+000,0,,0,
1524235770.400,,0.000000e+000,3.399899e+001,-2.010427e-004,0.000000e+000,3,9.932983e-001,0.000000e+000,,,,,,,,,,,,,,32,1,4.000000e+000,7.400513e-004,0.000000e+000,0,,0,
1524235808.610,,0.000000e+000,3.400046e+001,-2.011075e-004,0.000000e+000,3,9.933777e-001,0.000000e+000,,,,,,,,,,,,,,32,1,4.000000e+000,3.681183e-003,0.000000e+000,0,,0,
1524235846.646,,0.000000e+000,3.399899e+001,-2.010878e-004,0.000000e+000,3,9.933180e-001,0.000000e+000,,,,,,,,,,,,,,32,1,4.000000e+000,7.400513e-004,0.000000e+000,0,,0,
1524235885.099,,0.000000e+000,3.399973e+001,-2.011434e-004,0.000000e+000,3,9.934305e-001,0.000000e+000,,,,,,,,,,,,,,32,1,4.000000e+000,7.324219e-004,0.000000e+000,0,,0,
1524235923.564,,0.000000e+000,3.399862e+001,-2.011697e-004,0.000000e+000,3,9.933071e-001,0.000000e+000,,,,,,,,,,,,,,32,1,4.000000e+000,0.000000e+000,0.000000e+000,0,,0,
1524235961.717,,0.000000e+000,3.399899e+001,-2.012244e-004,0.000000e+000,3,9.932792e-001,0.000000e+000,,,,,,,,,,,,,,32,1,4.000000e+000,7.400513e-004,0.000000e+000,0,,0,
1524236000.215,,0.000000e+000,3.399715e+001,-2.011910e-004,0.000000e+000,3,9.932873e-001,0.000000e+000,,,,,,,,,,,,,,32,1,4.000000e+000,4.428864e-003,0.000000e+000,0,,0,
1524236038.131,,0.000000e+000,3.399751e+001,-2.012037e-004,0.000000e+000,3,9.932686e-001,0.000000e+000,,,,,,,,,,,,,,32,1,4.000000e+000,2.208710e-003,0.000000e+000,0,,0,
1524236076.277,,0.000000e+000,3.399862e+001,-2.012836e-004,0.000000e+000,3,9.934078e-001,0.000000e+000,,,,,,,,,,,,,,32,1,4.000000e+000,1.480103e-003,0.000000e+000,0,,0,
1524236114.120,,0.000000e+000,3.399862e+001,-2.012948e-004,0.000000e+000,3,9.932199e-001,0.000000e+000,,,,,,,,,,,,,,32,1,4.000000e+000,1.480103e-003,0.000000e+000,0,,0,
1524236152.065,,0.000000e+000,3.399936e+001,-2.013346e-004,0.000000e+000,3,9.931265e-001,0.000000e+000,,,,,,,,,,,,,,32,1,4.000000e+000,1.472473e-003,0.000000e+000,0,,0,
1524236189.903,,0.000000e+000,3.399862e+001,-2.013260e-004,0.000000e+000,3,9.931031e-001,0.000000e+000,,,,,,,,,,,,,,32,1,4.000000e+000,1.480103e-003,0.000000e+000,0,,0,
1524236227.896,,0.000000e+000,3.399825e+001,-2.013451e-004,0.000000e+000,3,9.932335e-001,0.000000e+000,,,,,,,,,,,,,,32,1,4.000000e+000,7.400513e-004,0.000000e+000,0,,0,
1524236266.269,,0.000000e+000,3.400046e+001,-2.013948e-004,0.000000e+000,3,9.932210e-001,0.000000e+000,,,,,,,,,,,,,,32,1,4.000000e+000,7.286072e-004,0.000000e+000,0,,0,
1524236304.438,,0.000000e+000,3.399862e+001,-2.013927e-004,0.000000e+000,3,9.934292e-001,0.000000e+000,,,,,,,,,,,,,,32,1,4.000000e+000,1.480103e-003,0.000000e+000,0,,0,
1524236342.811,,0.000000e+000,3.400156e+001,-2.014802e-004,0.000000e+000,3,9.933568e-001,0.000000e+000,,,,,,,,,,,,,,32,1,4.000000e+000,2.948761e-003,0.000000e+000,0,,0,
1524236380.586,,0.000000e+000,3.399899e+001,-2.014601e-004,0.000000e+000,3,9.933586e-001,0.000000e+000,,,,,,,,,,,,,,32,1,4.000000e+000,7.400513e-004,0.000000e+000,0,,0,
1524236418.502,,0.000000e+000,3.399936e+001,-2.014745e-004,0.000000e+000,3,9.932334e-001,0.000000e+000,,,,,,,,,,,,,,32,1,4.000000e+000,0.000000e+000,0.000000e+000,0,,0,
1524236456.397,,0.000000e+000,3.399936e+001,-2.016400e-004,0.000000e+000,3,9.933516e-001,0.000000e+000,,,,,,,,,,,,,,32,1,4.000000e+000,0.000000e+000,0.000000e+000,0,,0,
1524236493.445,,0.000000e+000,3.399936e+001,-2.016115e-004,0.000000e+000,3,9.933197e-001,0.000000e+000,,,,,,,,,,,,,,32,1,4.000000e+000,0.000000e+000,0.000000e+000,0,,0,
1524236531.836,,0.000000e+000,3.399973e+001,-2.015600e-004,0.000000e+000,3,9.929535e-001,0.000000e+000,,,,,,,,,,,,,,32,1,4.000000e+000,7.324219e-004,0.000000e+000,0,,0,
1524236570.154,,0.000000e+000,3.399899e+001,-2.015999e-004,0.000000e+000,3,9.935918e-001,0.000000e+000,,,,,,,,,,,,,,32,1,4.000000e+000,7.400513e-004,0.000000e+000,0,,0,
1524236608.612,,0.000000e+000,3.399936e+001,-2.016484e-004,0.000000e+000,3,9.930761e-001,0.000000e+000,,,,,,,,,,,,,,32,1,4.000000e+000,0.000000e+000,0.000000e+000,0,,0,
1524236647.217,,0.000000e+000,3.399973e+001,-2.016535e-004,0.000000e+000,3,9.931914e-001,0.000000e+000,,,,,,,,,,,,,,32,1,4.000000e+000,7.324219e-004,0.000000e+000,0,,0,
1524236684.943,,0.000000e+000,3.399936e+001,-2.016736e-004,0.000000e+000,3,9.933235e-001,0.000000e+000,,,,,,,,,,,,,,32,1,4.000000e+000,1.472473e-003,0.000000e+000,0,,0,
1524236722.816,,0.000000e+000,3.399936e+001,-2.017218e-004,0.000000e+000,3,9.933441e-001,0.000000e+000,,,,,,,,,,,,,,32,1,4.000000e+000,1.472473e-003,0.000000e+000,0,,0,
1524236760.557,,0.000000e+000,3.400156e+001,-2.017596e-004,0.000000e+000,3,9.933109e-001,0.000000e+000,,,,,,,,,,,,,,32,1,4.000000e+000,4.409790e-003,0.000000e+000,0,,0,
1524236798.752,,0.000000e+000,3.399973e+001,-2.017770e-004,0.000000e+000,3,9.930915e-001,0.000000e+000,,,,,,,,,,,,,,32,1,4.000000e+000,7.324219e-004,0.000000e+000,0,,0,
1524236837.328,,0.000000e+000,3.399936e+001,-2.017858e-004,0.000000e+000,3,9.932585e-001,0.000000e+000,,,,,,,,,,,,,,32,1,4.000000e+000,0.000000e+000,0.000000e+000,0,,0,
1524236875.163,,0.000000e+000,3.400009e+001,-2.018078e-004,0.000000e+000,3,9.932340e-001,0.000000e+000,,,,,,,,,,,,,,32,1,4.000000e+000,2.941132e-003,0.000000e+000,0,,0,
1524236913.346,,0.000000e+000,3.399936e+001,-2.018380e-004,0.000000e+000,3,9.932964e-001,0.000000e+000,,,,,,,,,,,,,,32,1,4.000000e+000,0.000000e+000,0.000000e+000,0,,0,
1524236951.779,,0.000000e+000,3.399936e+001,-2.017704e-004,0.000000e+000,3,9.931802e-001,0.000000e+000,,,,,,,,,,,,,,32,1,4.000000e+000,0.000000e+000,0.000000e+000,0,,0,
1524236990.815,,0.000000e+000,3.399862e+001,-2.018178e-004,0.000000e+000,3,9.933076e-001,0.000000e+000,,,,,,,,,,,,,,32,1,4.000000e+000,2.952576e-003,0.000000e+000,0,,0,
1524237029.063,,0.000000e+000,3.399862e+001,-2.019242e-004,0.000000e+000,3,9.935736e-001,0.000000e+000,,,,,,,,,,,,,,32,1,4.000000e+000,1.480103e-003,0.000000e+000,0,,0,
1524237067.701,,0.000000e+000,3.399936e+001,-2.019385e-004,0.000000e+000,3,9.929543e-001,0.000000e+000,,,,,,,,,,,,,,32,1,4.000000e+000,0.000000e+000,0.000000e+000,0,,0,
1524237104.604,,0.000000e+000,3.399899e+001,-2.019757e-004,0.000000e+000,3,9.932158e-001,0.000000e+000,,,,,,,,,,,,,,32,1,4.000000e+000,7.400513e-004,0.000000e+000,0,,0,
1524237142.712,,0.000000e+000,3.399899e+001,-2.019805e-004,0.000000e+000,3,9.932290e-001,0.000000e+000,,,,,,,,,,,,,,32,1,4.000000e+000,7.400513e-004,0.000000e+000,0,,0,
1524237180.953,,0.000000e+000,3.400009e+001,-2.019994e-004,0.000000e+000,3,9.933061e-001,0.000000e+000,,,,,,,,,,,,,,32,1,4.000000e+000,2.941132e-003,0.000000e+000,0,,0,
1524237219.113,,0.000000e+000,3.399899e+001,-2.020165e-004,0.000000e+000,3,9.930608e-001,0.000000e+000,,,,,,,,,,,,,,32,1,4.000000e+000,2.212524e-003,0.000000e+000,0,,0,
1524237258.889,,0.000000e+000,3.399936e+001,-2.020431e-004,0.000000e+000,3,9.932524e-001,0.000000e+000,,,,,,,,,,,,,,32,1,4.000000e+000,1.472473e-003,0.000000e+000,0,,0,
1524237297.507,,0.000000e+000,3.399899e+001,-2.021267e-004,0.000000e+000,3,9.930763e-001,0.000000e+000,,,,,,,,,,,,,,32,1,4.000000e+000,7.400513e-004,0.000000e+000,0,,0,
1524237335.528,,0.000000e+000,3.399973e+001,-2.020611e-004,0.000000e+000,3,9.933522e-001,0.000000e+000,,,,,,,,,,,,,,32,1,4.000000e+000,7.324219e-004,0.000000e+000,0,,0,
1524237373.398,,0.000000e+000,3.399751e+001,-2.020262e-004,0.000000e+000,3,9.927847e-001,0.000000e+000,,,,,,,,,,,,,,32,1,4.000000e+000,6.618500e-003,0.000000e+000,0,,0,
1524237411.121,,0.000000e+000,3.399862e+001,-2.021832e-004,0.000000e+000,3,9.933701e-001,0.000000e+000,,,,,,,,,,,,,,32,1,4.000000e+000,1.480103e-003,0.000000e+000,0,,0,
1524237449.559,,0.000000e+000,3.399973e+001,-2.021337e-004,0.000000e+000,3,9.934990e-001,0.000000e+000,,,,,,,,,,,,,,32,1,4.000000e+000,7.324219e-004,0.000000e+000,0,,0,
1524237488.012,,0.000000e+000,3.400193e+001,-2.022059e-004,0.000000e+000,3,9.934594e-001,0.000000e+000,,,,,,,,,,,,,,32,1,4.000000e+000,5.149841e-003,0.000000e+000,0,,0,
1524237526.808,,0.000000e+000,3.399899e+001,-2.022698e-004,0.000000e+000,3,9.933190e-001,0.000000e+000,,,,,,,,,,,,,,32,1,4.000000e+000,7.400513e-004,0.000000e+000,0,,0,
1524237564.521,,0.000000e+000,3.399899e+001,-2.022402e-004,0.000000e+000,3,9.932367e-001,0.000000e+000,,,,,,,,,,,,,,32,1,4.000000e+000,7.400513e-004,0.000000e+000,0,,0,
1524237602.844,,0.000000e+000,3.399899e+001,-2.022572e-004,0.000000e+000,3,9.932959e-001,0.000000e+000,,,,,,,,,,,,,,32,1,4.000000e+000,7.400513e-004,0.000000e+000,0,,0,
1524237641.300,,0.000000e+000,3.399936e+001,-2.022510e-004,0.000000e+000,3,9.932708e-001,0.000000e+000,,,,,,,,,,,,,,32,1,4.000000e+000,0.000000e+000,0.000000e+000,0,,0,
1524237679.840,,0.000000e+000,3.399973e+001,-2.023251e-004,0.000000e+000,3,9.932387e-001,0.000000e+000,,,,,,,,,,,,,,32,1,4.000000e+000,7.324219e-004,0.000000e+000,0,,0,
1524237717.336,,0.000000e+000,3.400193e+001,-2.023265e-004,0.000000e+000,3,9.932474e-001,0.000000e+000,,,,,,,,,,,,,,32,1,4.000000e+000,5.149841e-003,0.000000e+000,0,,0,
1524237755.059,,0.000000e+000,3.399936e+001,-2.023359e-004,0.000000e+000,3,9.933037e-001,0.000000e+000,,,,,,,,,,,,,,32,1,4.000000e+000,0.000000e+000,0.000000e+000,0,,0,
1524237793.232,,0.000000e+000,3.399825e+001,-2.023427e-004,0.000000e+000,3,9.932769e-001,0.000000e+000,,,,,,,,,,,,,,32,1,4.000000e+000,2.220154e-003,0.000000e+000,0,,0,
1524237831.190,,0.000000e+000,3.399936e+001,-2.023590e-004,0.000000e+000,3,9.933686e-001,0.000000e+000,,,,,,,,,,,,,,32,1,4.000000e+000,1.472473e-003,0.000000e+000,0,,0,
1524237869.658,,0.000000e+000,3.400046e+001,-2.024385e-004,0.000000e+000,3,9.932923e-001,0.000000e+000,,,,,,,,,,,,,,32,1,4.000000e+000,7.286072e-004,0.000000e+000,0,,0,
1524237907.718,,0.000000e+000,3.399936e+001,-2.024198e-004,0.000000e+000,3,9.932185e-001,0.000000e+000,,,,,,,,,,,,,,32,1,4.000000e+000,1.472473e-003,0.000000e+000,0,,0,
1524237945.894,,0.000000e+000,3.399972e+001,-2.024845e-004,0.000000e+000,3,9.930612e-001,0.000000e+000,,,,,,,,,,,,,,32,1,4.000000e+000,2.201080e-003,0.000000e+000,0,,0,
1524237984.100,,0.000000e+000,3.399973e+001,-2.024549e-004,0.000000e+000,3,9.931667e-001,0.000000e+000,,,,,,,,,,,,,,32,1,4.000000e+000,7.324219e-004,0.000000e+000,0,,0,
1524238021.835,,0.000000e+000,3.400082e+001,-2.024847e-004,0.000000e+000,3,9.932991e-001,0.000000e+000,,,,,,,,,,,,,,32,1,4.000000e+000,1.468658e-003,0.000000e+000,0,,0,
1524238060.168,,0.000000e+000,3.400082e+001,-2.024811e-004,0.000000e+000,3,9.933178e-001,0.000000e+000,,,,,,,,,,,,,,32,1,4.000000e+000,1.468658e-003,0.000000e+000,0,,0,
1524238098.456,,0.000000e+000,3.399973e+001,-2.025464e-004,0.000000e+000,3,9.931953e-001,0.000000e+000,,,,,,,,,,,,,,32,1,4.000000e+000,7.324219e-004,0.000000e+000,0,,0,
1524238136.704,,0.000000e+000,3.399789e+001,-2.025575e-004,0.000000e+000,3,9.932846e-001,0.000000e+000,,,,,,,,,,,,,,32,1,4.000000e+000,2.948761e-003,0.000000e+000,0,,0,
1524238174.020,,0.000000e+000,3.399899e+001,-2.026554e-004,0.000000e+000,3,9.931102e-001,0.000000e+000,,,,,,,,,,,,,,32,1,4.000000e+000,7.400513e-004,0.000000e+000,0,,0,
1524238211.268,,0.000000e+000,3.400083e+001,-2.026285e-004,0.000000e+000,3,9.931329e-001,0.000000e+000,,,,,,,,,,,,,,32,1,4.000000e+000,2.941132e-003,0.000000e+000,0,,0,
1524238249.641,,0.000000e+000,3.399789e+001,-2.026109e-004,0.000000e+000,3,9.933217e-001,0.000000e+000,,,,,,,,,,,,,,32,1,4.000000e+000,2.948761e-003,0.000000e+000,0,,0,
1524238288.507,,0.000000e+000,3.399898e+001,-2.026733e-004,0.000000e+000,3,9.933125e-001,0.000000e+000,,,,,,,,,,,,,,32,1,4.000000e+000,3.681183e-003,0.000000e+000,0,,0,
1524238325.995,,0.000000e+000,3.399899e+001,-2.026760e-004,0.000000e+000,3,9.932694e-001,0.000000e+000,,,,,,,,,,,,,,32,1,4.000000e+000,7.400513e-004,0.000000e+000,0,,0,
1524238363.608,,0.000000e+000,3.399789e+001,-2.027327e-004,0.000000e+000,3,9.931884e-001,0.000000e+000,,,,,,,,,,,,,,32,1,4.000000e+000,2.948761e-003,0.000000e+000,0,,0,
1524238401.878,,0.000000e+000,3.399936e+001,-2.027105e-004,0.000000e+000,3,9.932308e-001,0.000000e+000,,,,,,,,,,,,,,32,1,4.000000e+000,1.472473e-003,0.000000e+000,0,,0,
1524238440.099,,0.000000e+000,3.399899e+001,-2.026865e-004,0.000000e+000,3,9.931731e-001,0.000000e+000,,,,,,,,,,,,,,32,1,4.000000e+000,7.400513e-004,0.000000e+000,0,,0,
1524238478.342,,0.000000e+000,3.399862e+001,-2.027190e-004,0.000000e+000,3,9.932156e-001,0.000000e+000,,,,,,,,,,,,,,32,1,4.000000e+000,1.480103e-003,0.000000e+000,0,,0,
1524238516.025,,0.000000e+000,3.399936e+001,-2.028118e-004,0.000000e+000,3,9.932514e-001,0.000000e+000,,,,,,,,,,,,,,32,1,4.000000e+000,0.000000e+000,0.000000e+000,0,,0,
1524238554.125,,0.000000e+000,3.399936e+001,-2.027525e-004,0.000000e+000,3,9.933724e-001,0.000000e+000,,,,,,,,,,,,,,32,1,4.000000e+000,1.472473e-003,0.000000e+000,0,,0,
1524238579.706,,0.000000e+000,3.399936e+001,-2.028054e-004,0.000000e+000,3,9.931738e-001,0.000000e+000,,,,,,,,,,,,,,32,1,4.000000e+000,0.000000e+000,0.000000e+000,0,,0,