File: Experimental Raw Data/MFn1 VRM/Iterative Regression/Acquisition/MFn1_VRMac_35K_12000s.dc.dat
[Header]
TITLE,MPMS DC Measurement
BYAPP,MPMS Measurement,2.1,Summary
FILEOPENTIME, 1523990910.296000 4/17/2018, 12:48:30 PM

INFO, APPNAME, MPMS MultiVu Application, Revision 1.61,  Build 082

INFO, NAME, MFn1
INFO, WEIGHT, 1.000
INFO, AREA, 1.000
INFO, LENGTH, 1.000
INFO, SHAPE, 0
INFO, COMMENT,
INFO, SEQUENCE FILE: VRMac_35K_12000s_VRMde_35K.seq


INFO, BACKGROUND DATA FILE:, None


STARTUPAXIS,X,4,LINEAR,AUTO,0.000000,0.000000
STARTUPAXIS,Y1,5,LINEAR,AUTO,0.000000,0.000000


STARTUPGROUP,Longitudinal
FIELDGROUP,Longitudinal,1,2,3,4,5,6,7,8,9,15,16,17,18,27,28
FIELDGROUP,Transverse,1,2,3,4,10,11,12,13,14,19,20,21,22,27,28

PLOT_APPEARANCE,ALL,HORZ_GRID_ON,VERT_GRID_ON,MARKERS_AND_LINES

[Data]
Time,Comment,Field (Oe),Temperature (K),Long Moment (emu),Long Scan Std Dev,Long Algorithm,Long Reg Fit,Long Percent Error (%),Trans Moment (emu),Trans Scan Std Dev,Trans Algorithm,Trans Reg Fit,Trans Percent Error (%),Long Moment [w/o ABS] (emu),Long Scan Std Dev [w/o ABS],Long Reg Fit [w/o ABS],Long Percent Error [w/o ABS] (%),Trans Moment [w/o ABS] (emu),Trans Scan Std Dev [w/o ABS],Trans Reg Fit [w/o ABS],Trans Percent Error [w/o ABS] (%),Points per Scan,Scans per Measurement,Scan Length (cm),Delta Temp (K),Rot Position (deg),Error,EC Comp. Running,Using ABS,
1523990910.293,,0.000000e+000,3.499715e+001,-1.766844e-004,0.000000e+000,3,9.916984e-001,0.000000e+000,,,,,,,,,,,,,,32,1,4.000000e+000,1.571655e-003,0.000000e+000,0,,0,
1523990948.276,,0.000000e+000,3.499989e+001,-1.825072e-004,0.000000e+000,3,9.919130e-001,0.000000e+000,,,,,,,,,,,,,,32,1,4.000000e+000,7.781982e-004,0.000000e+000,0,,0,
1523990985.669,,0.000000e+000,3.499950e+001,-1.849096e-004,0.000000e+000,3,9.926730e-001,0.000000e+000,,,,,,,,,,,,,,32,1,4.000000e+000,1.560211e-003,0.000000e+000,0,,0,
1523991023.862,,0.000000e+000,3.499833e+001,-1.865786e-004,0.000000e+000,3,9.921151e-001,0.000000e+000,,,,,,,,,,,,,,32,1,4.000000e+000,7.781982e-004,0.000000e+000,0,,0,
1523991061.183,,0.000000e+000,3.500028e+001,-1.877980e-004,0.000000e+000,3,9.925909e-001,0.000000e+000,,,,,,,,,,,,,,32,1,4.000000e+000,0.000000e+000,0.000000e+000,0,,0,
1523991099.203,,0.000000e+000,3.499911e+001,-1.888011e-004,0.000000e+000,3,9.925563e-001,0.000000e+000,,,,,,,,,,,,,,32,1,4.000000e+000,7.820129e-004,0.000000e+000,0,,0,
1523991137.359,,0.000000e+000,3.499872e+001,-1.896208e-004,0.000000e+000,3,9.923172e-001,0.000000e+000,,,,,,,,,,,,,,32,1,4.000000e+000,0.000000e+000,0.000000e+000,0,,0,
1523991175.522,,0.000000e+000,3.499872e+001,-1.903271e-004,0.000000e+000,3,9.926057e-001,0.000000e+000,,,,,,,,,,,,,,32,1,4.000000e+000,1.560211e-003,0.000000e+000,0,,0,
1523991213.468,,0.000000e+000,3.499989e+001,-1.909866e-004,0.000000e+000,3,9.926568e-001,0.000000e+000,,,,,,,,,,,,,,32,1,4.000000e+000,7.781982e-004,0.000000e+000,0,,0,
1523991251.481,,0.000000e+000,3.499793e+001,-1.915636e-004,0.000000e+000,3,9.927155e-001,0.000000e+000,,,,,,,,,,,,,,32,1,4.000000e+000,1.567841e-003,0.000000e+000,0,,0,
1523991288.936,,0.000000e+000,3.499754e+001,-1.920779e-004,0.000000e+000,3,9.928318e-001,0.000000e+000,,,,,,,,,,,,,,32,1,4.000000e+000,2.349854e-003,0.000000e+000,0,,0,
1523991327.009,,0.000000e+000,3.499872e+001,-1.925680e-004,0.000000e+000,3,9.929705e-001,0.000000e+000,,,,,,,,,,,,,,32,1,4.000000e+000,0.000000e+000,0.000000e+000,0,,0,
1523991364.982,,0.000000e+000,3.499950e+001,-1.929196e-004,0.000000e+000,3,9.927695e-001,0.000000e+000,,,,,,,,,,,,,,32,1,4.000000e+000,0.000000e+000,0.000000e+000,0,,0,
1523991402.678,,0.000000e+000,3.499872e+001,-1.933326e-004,0.000000e+000,3,9.928519e-001,0.000000e+000,,,,,,,,,,,,,,32,1,4.000000e+000,0.000000e+000,0.000000e+000,0,,0,
1523991440.028,,0.000000e+000,3.499833e+001,-1.937321e-004,0.000000e+000,3,9.927533e-001,0.000000e+000,,,,,,,,,,,,,,32,1,4.000000e+000,7.781982e-004,0.000000e+000,0,,0,
1523991478.089,,0.000000e+000,3.499872e+001,-1.940213e-004,0.000000e+000,3,9.928048e-001,0.000000e+000,,,,,,,,,,,,,,32,1,4.000000e+000,0.000000e+000,0.000000e+000,0,,0,
1523991516.467,,0.000000e+000,3.499793e+001,-1.943724e-004,0.000000e+000,3,9.928057e-001,0.000000e+000,,,,,,,,,,,,,,32,1,4.000000e+000,1.567841e-003,0.000000e+000,0,,0,
1523991555.000,,0.000000e+000,3.499872e+001,-1.946983e-004,0.000000e+000,3,9.927973e-001,0.000000e+000,,,,,,,,,,,,,,32,1,4.000000e+000,1.560211e-003,0.000000e+000,0,,0,
1523991593.671,,0.000000e+000,3.499872e+001,-1.949773e-004,0.000000e+000,3,9.928378e-001,0.000000e+000,,,,,,,,,,,,,,32,1,4.000000e+000,0.000000e+000,0.000000e+000,0,,0,
1523991630.634,,0.000000e+000,3.499872e+001,-1.952401e-004,0.000000e+000,3,9.927286e-001,0.000000e+000,,,,,,,,,,,,,,32,1,4.000000e+000,0.000000e+000,0.000000e+000,0,,0,
1523991668.474,,0.000000e+000,3.499833e+001,-1.954236e-004,0.000000e+000,3,9.927288e-001,0.000000e+000,,,,,,,,,,,,,,32,1,4.000000e+000,7.781982e-004,0.000000e+000,0,,0,
1523991707.305,,0.000000e+000,3.499833e+001,-1.957943e-004,0.000000e+000,3,9.929520e-001,0.000000e+000,,,,,,,,,,,,,,32,1,4.000000e+000,7.781982e-004,0.000000e+000,0,,0,
1523991744.500,,0.000000e+000,3.500145e+001,-1.960096e-004,0.000000e+000,3,9.927146e-001,0.000000e+000,,,,,,,,,,,,,,32,1,4.000000e+000,7.781982e-004,0.000000e+000,0,,0,
1523991782.338,,0.000000e+000,3.499871e+001,-1.962502e-004,0.000000e+000,3,9.928855e-001,0.000000e+000,,,,,,,,,,,,,,32,1,4.000000e+000,3.128052e-003,0.000000e+000,0,,0,
1523991820.454,,0.000000e+000,3.499793e+001,-1.964371e-004,0.000000e+000,3,9.927838e-001,0.000000e+000,,,,,,,,,,,,,,32,1,4.000000e+000,1.567841e-003,0.000000e+000,0,,0,
1523991858.525,,0.000000e+000,3.499793e+001,-1.966722e-004,0.000000e+000,3,9.928424e-001,0.000000e+000,,,,,,,,,,,,,,32,1,4.000000e+000,1.567841e-003,0.000000e+000,0,,0,
1523991896.575,,0.000000e+000,3.499911e+001,-1.968599e-004,0.000000e+000,3,9.929376e-001,0.000000e+000,,,,,,,,,,,,,,32,1,4.000000e+000,2.338409e-003,0.000000e+000,0,,0,
1523991934.708,,0.000000e+000,3.499754e+001,-1.970765e-004,0.000000e+000,3,9.927366e-001,0.000000e+000,,,,,,,,,,,,,,32,1,4.000000e+000,2.349854e-003,0.000000e+000,0,,0,
1523991972.674,,0.000000e+000,3.499677e+001,-1.972353e-004,0.000000e+000,3,9.927852e-001,0.000000e+000,,,,,,,,,,,,,,32,1,4.000000e+000,2.349854e-003,0.000000e+000,0,,0,
1523992010.772,,0.000000e+000,3.499872e+001,-1.974061e-004,0.000000e+000,3,9.929571e-001,0.000000e+000,,,,,,,,,,,,,,32,1,4.000000e+000,1.560211e-003,0.000000e+000,0,,0,
1523992048.840,,0.000000e+000,3.499793e+001,-1.977019e-004,0.000000e+000,3,9.929371e-001,0.000000e+000,,,,,,,,,,,,,,32,1,4.000000e+000,1.567841e-003,0.000000e+000,0,,0,
1523992086.908,,0.000000e+000,3.499833e+001,-1.977708e-004,0.000000e+000,3,9.928575e-001,0.000000e+000,,,,,,,,,,,,,,32,1,4.000000e+000,7.781982e-004,0.000000e+000,0,,0,
1523992124.726,,0.000000e+000,3.499911e+001,-1.979514e-004,0.000000e+000,3,9.927936e-001,0.000000e+000,,,,,,,,,,,,,,32,1,4.000000e+000,7.820129e-004,0.000000e+000,0,,0,
1523992163.001,,0.000000e+000,3.499833e+001,-1.981419e-004,0.000000e+000,3,9.929832e-001,0.000000e+000,,,,,,,,,,,,,,32,1,4.000000e+000,7.781982e-004,0.000000e+000,0,,0,
1523992200.774,,0.000000e+000,3.499872e+001,-1.983254e-004,0.000000e+000,3,9.929485e-001,0.000000e+000,,,,,,,,,,,,,,32,1,4.000000e+000,1.560211e-003,0.000000e+000,0,,0,
1523992238.655,,0.000000e+000,3.499833e+001,-1.984331e-004,0.000000e+000,3,9.928832e-001,0.000000e+000,,,,,,,,,,,,,,32,1,4.000000e+000,7.781982e-004,0.000000e+000,0,,0,
1523992276.658,,0.000000e+000,3.499950e+001,-1.985504e-004,0.000000e+000,3,9.929019e-001,0.000000e+000,,,,,,,,,,,,,,32,1,4.000000e+000,1.560211e-003,0.000000e+000,0,,0,
1523992314.424,,0.000000e+000,3.499833e+001,-1.987218e-004,0.000000e+000,3,9.929156e-001,0.000000e+000,,,,,,,,,,,,,,32,1,4.000000e+000,7.781982e-004,0.000000e+000,0,,0,
1523992353.389,,0.000000e+000,3.499911e+001,-1.988688e-004,0.000000e+000,3,9.929467e-001,0.000000e+000,,,,,,,,,,,,,,32,1,4.000000e+000,7.820129e-004,0.000000e+000,0,,0,
1523992390.860,,0.000000e+000,3.499911e+001,-1.990350e-004,0.000000e+000,3,9.929199e-001,0.000000e+000,,,,,,,,,,,,,,32,1,4.000000e+000,7.820129e-004,0.000000e+000,0,,0,
1523992428.928,,0.000000e+000,3.499833e+001,-1.991721e-004,0.000000e+000,3,9.929155e-001,0.000000e+000,,,,,,,,,,,,,,32,1,4.000000e+000,2.349854e-003,0.000000e+000,0,,0,
1523992466.736,,0.000000e+000,3.499989e+001,-1.992975e-004,0.000000e+000,3,9.929630e-001,0.000000e+000,,,,,,,,,,,,,,32,1,4.000000e+000,3.898621e-003,0.000000e+000,0,,0,
1523992504.614,,0.000000e+000,3.499872e+001,-1.994104e-004,0.000000e+000,3,9.928769e-001,0.000000e+000,,,,,,,,,,,,,,32,1,4.000000e+000,0.000000e+000,0.000000e+000,0,,0,
1523992542.685,,0.000000e+000,3.499793e+001,-1.995386e-004,0.000000e+000,3,9.928899e-001,0.000000e+000,,,,,,,,,,,,,,32,1,4.000000e+000,3.131866e-003,0.000000e+000,0,,0,
1523992580.750,,0.000000e+000,3.499793e+001,-1.996738e-004,0.000000e+000,3,9.929104e-001,0.000000e+000,,,,,,,,,,,,,,32,1,4.000000e+000,1.567841e-003,0.000000e+000,0,,0,
1523992618.793,,0.000000e+000,3.499872e+001,-1.997969e-004,0.000000e+000,3,9.930245e-001,0.000000e+000,,,,,,,,,,,,,,32,1,4.000000e+000,1.560211e-003,0.000000e+000,0,,0,
1523992656.904,,0.000000e+000,3.499793e+001,-1.999138e-004,0.000000e+000,3,9.928954e-001,0.000000e+000,,,,,,,,,,,,,,32,1,4.000000e+000,1.567841e-003,0.000000e+000,0,,0,
1523992694.934,,0.000000e+000,3.499872e+001,-1.999913e-004,0.000000e+000,3,9.928859e-001,0.000000e+000,,,,,,,,,,,,,,32,1,4.000000e+000,0.000000e+000,0.000000e+000,0,,0,
1523992733.015,,0.000000e+000,3.499833e+001,-2.001234e-004,0.000000e+000,3,9.928415e-001,0.000000e+000,,,,,,,,,,,,,,32,1,4.000000e+000,2.349854e-003,0.000000e+000,0,,0,
1523992771.098,,0.000000e+000,3.499872e+001,-2.002821e-004,0.000000e+000,3,9.929632e-001,0.000000e+000,,,,,,,,,,,,,,32,1,4.000000e+000,0.000000e+000,0.000000e+000,0,,0,
1523992808.836,,0.000000e+000,3.499871e+001,-2.004181e-004,0.000000e+000,3,9.931874e-001,0.000000e+000,,,,,,,,,,,,,,32,1,4.000000e+000,3.128052e-003,0.000000e+000,0,,0,
1523992846.599,,0.000000e+000,3.499833e+001,-2.004283e-004,0.000000e+000,3,9.929752e-001,0.000000e+000,,,,,,,,,,,,,,32,1,4.000000e+000,2.349854e-003,0.000000e+000,0,,0,
1523992884.885,,0.000000e+000,3.499911e+001,-2.005016e-004,0.000000e+000,3,9.928488e-001,0.000000e+000,,,,,,,,,,,,,,32,1,4.000000e+000,7.820129e-004,0.000000e+000,0,,0,
1523992921.910,,0.000000e+000,3.499911e+001,-2.006922e-004,0.000000e+000,3,9.929605e-001,0.000000e+000,,,,,,,,,,,,,,32,1,4.000000e+000,7.820129e-004,0.000000e+000,0,,0,
1523992960.013,,0.000000e+000,3.499833e+001,-2.007896e-004,0.000000e+000,3,9.929689e-001,0.000000e+000,,,,,,,,,,,,,,32,1,4.000000e+000,7.781982e-004,0.000000e+000,0,,0,
1523992997.881,,0.000000e+000,3.499950e+001,-2.008615e-004,0.000000e+000,3,9.928398e-001,0.000000e+000,,,,,,,,,,,,,,32,1,4.000000e+000,0.000000e+000,0.000000e+000,0,,0,
1523993035.944,,0.000000e+000,3.499833e+001,-2.009708e-004,0.000000e+000,3,9.928434e-001,0.000000e+000,,,,,,,,,,,,,,32,1,4.000000e+000,7.781982e-004,0.000000e+000,0,,0,
1523993073.475,,0.000000e+000,3.499911e+001,-2.010593e-004,0.000000e+000,3,9.928468e-001,0.000000e+000,,,,,,,,,,,,,,32,1,4.000000e+000,2.338409e-003,0.000000e+000,0,,0,
1523993111.150,,0.000000e+000,3.499833e+001,-2.011803e-004,0.000000e+000,3,9.928678e-001,0.000000e+000,,,,,,,,,,,,,,32,1,4.000000e+000,7.781982e-004,0.000000e+000,0,,0,
1523993148.661,,0.000000e+000,3.499872e+001,-2.012433e-004,0.000000e+000,3,9.928699e-001,0.000000e+000,,,,,,,,,,,,,,32,1,4.000000e+000,1.560211e-003,0.000000e+000,0,,0,
1523993186.407,,0.000000e+000,3.499872e+001,-2.013496e-004,0.000000e+000,3,9.929227e-001,0.000000e+000,,,,,,,,,,,,,,32,1,4.000000e+000,0.000000e+000,0.000000e+000,0,,0,
1523993224.385,,0.000000e+000,3.499833e+001,-2.014405e-004,0.000000e+000,3,9.930225e-001,0.000000e+000,,,,,,,,,,,,,,32,1,4.000000e+000,7.781982e-004,0.000000e+000,0,,0,
1523993262.005,,0.000000e+000,3.499911e+001,-2.015324e-004,0.000000e+000,3,9.929553e-001,0.000000e+000,,,,,,,,,,,,,,32,1,4.000000e+000,7.820129e-004,0.000000e+000,0,,0,
1523993300.238,,0.000000e+000,3.499872e+001,-2.016328e-004,0.000000e+000,3,9.928480e-001,0.000000e+000,,,,,,,,,,,,,,32,1,4.000000e+000,0.000000e+000,0.000000e+000,0,,0,
1523993338.304,,0.000000e+000,3.499911e+001,-2.016931e-004,0.000000e+000,3,9.929467e-001,0.000000e+000,,,,,,,,,,,,,,32,1,4.000000e+000,7.820129e-004,0.000000e+000,0,,0,
1523993376.419,,0.000000e+000,3.499754e+001,-2.018271e-004,0.000000e+000,3,9.931821e-001,0.000000e+000,,,,,,,,,,,,,,32,1,4.000000e+000,7.896423e-004,0.000000e+000,0,,0,
1523993414.415,,0.000000e+000,3.499911e+001,-2.019294e-004,0.000000e+000,3,9.931047e-001,0.000000e+000,,,,,,,,,,,,,,32,1,4.000000e+000,7.820129e-004,0.000000e+000,0,,0,
1523993452.665,,0.000000e+000,3.499911e+001,-2.018868e-004,0.000000e+000,3,9.928572e-001,0.000000e+000,,,,,,,,,,,,,,32,1,4.000000e+000,7.820129e-004,0.000000e+000,0,,0,
1523993491.483,,0.000000e+000,3.499872e+001,-2.019957e-004,0.000000e+000,3,9.928954e-001,0.000000e+000,,,,,,,,,,,,,,32,1,4.000000e+000,0.000000e+000,0.000000e+000,0,,0,
1523993529.629,,0.000000e+000,3.499872e+001,-2.021741e-004,0.000000e+000,3,9.928705e-001,0.000000e+000,,,,,,,,,,,,,,32,1,4.000000e+000,0.000000e+000,0.000000e+000,0,,0,
1523993567.485,,0.000000e+000,3.499872e+001,-2.022416e-004,0.000000e+000,3,9.930366e-001,0.000000e+000,,,,,,,,,,,,,,32,1,4.000000e+000,0.000000e+000,0.000000e+000,0,,0,
1523993605.433,,0.000000e+000,3.499872e+001,-2.022700e-004,0.000000e+000,3,9.930651e-001,0.000000e+000,,,,,,,,,,,,,,32,1,4.000000e+000,1.560211e-003,0.000000e+000,0,,0,
1523993643.343,,0.000000e+000,3.499872e+001,-2.023603e-004,0.000000e+000,3,9.926987e-001,0.000000e+000,,,,,,,,,,,,,,32,1,4.000000e+000,0.000000e+000,0.000000e+000,0,,0,
1523993681.326,,0.000000e+000,3.499872e+001,-2.024589e-004,0.000000e+000,3,9.930060e-001,0.000000e+000,,,,,,,,,,,,,,32,1,4.000000e+000,0.000000e+000,0.000000e+000,0,,0,
1523993719.392,,0.000000e+000,3.499794e+001,-2.024885e-004,0.000000e+000,3,9.930047e-001,0.000000e+000,,,,,,,,,,,,,,32,1,4.000000e+000,0.000000e+000,0.000000e+000,0,,0,
1523993757.255,,0.000000e+000,3.499715e+001,-2.025949e-004,0.000000e+000,3,9.927583e-001,0.000000e+000,,,,,,,,,,,,,,32,1,4.000000e+000,0.000000e+000,0.000000e+000,0,,0,
1523993794.348,,0.000000e+000,3.499793e+001,-2.026823e-004,0.000000e+000,3,9.929736e-001,0.000000e+000,,,,,,,,,,,,,,32,1,4.000000e+000,1.567841e-003,0.000000e+000,0,,0,
1523993832.434,,0.000000e+000,3.499872e+001,-2.027606e-004,0.000000e+000,3,9.930292e-001,0.000000e+000,,,,,,,,,,,,,,32,1,4.000000e+000,0.000000e+000,0.000000e+000,0,,0,
1523993870.534,,0.000000e+000,3.499950e+001,-2.028565e-004,0.000000e+000,3,9.930449e-001,0.000000e+000,,,,,,,,,,,,,,32,1,4.000000e+000,0.000000e+000,0.000000e+000,0,,0,
1523993908.595,,0.000000e+000,3.499950e+001,-2.028944e-004,0.000000e+000,3,9.929464e-001,0.000000e+000,,,,,,,,,,,,,,32,1,4.000000e+000,0.000000e+000,0.000000e+000,0,,0,
1523993946.653,,0.000000e+000,3.499911e+001,-2.029802e-004,0.000000e+000,3,9.929504e-001,0.000000e+000,,,,,,,,,,,,,,32,1,4.000000e+000,7.820129e-004,0.000000e+000,0,,0,
1523993984.728,,0.000000e+000,3.499911e+001,-2.030780e-004,0.000000e+000,3,9.931465e-001,0.000000e+000,,,,,,,,,,,,,,32,1,4.000000e+000,7.820129e-004,0.000000e+000,0,,0,
1523994022.556,,0.000000e+000,3.499950e+001,-2.031539e-004,0.000000e+000,3,9.928657e-001,0.000000e+000,,,,,,,,,,,,,,32,1,4.000000e+000,0.000000e+000,0.000000e+000,0,,0,
1523994060.214,,0.000000e+000,3.499833e+001,-2.031151e-004,0.000000e+000,3,9.930022e-001,0.000000e+000,,,,,,,,,,,,,,32,1,4.000000e+000,7.781982e-004,0.000000e+000,0,,0,
1523994098.315,,0.000000e+000,3.499989e+001,-2.032936e-004,0.000000e+000,3,9.929291e-001,0.000000e+000,,,,,,,,,,,,,,32,1,4.000000e+000,7.781982e-004,0.000000e+000,0,,0,
1523994136.365,,0.000000e+000,3.499872e+001,-2.033137e-004,0.000000e+000,3,9.932118e-001,0.000000e+000,,,,,,,,,,,,,,32,1,4.000000e+000,0.000000e+000,0.000000e+000,0,,0,
1523994174.448,,0.000000e+000,3.499989e+001,-2.033330e-004,0.000000e+000,3,9.930441e-001,0.000000e+000,,,,,,,,,,,,,,32,1,4.000000e+000,7.781982e-004,0.000000e+000,0,,0,
1523994211.714,,0.000000e+000,3.499794e+001,-2.034392e-004,0.000000e+000,3,9.930879e-001,0.000000e+000,,,,,,,,,,,,,,32,1,4.000000e+000,0.000000e+000,0.000000e+000,0,,0,
1523994250.205,,0.000000e+000,3.499989e+001,-2.035015e-004,0.000000e+000,3,9.929473e-001,0.000000e+000,,,,,,,,,,,,,,32,1,4.000000e+000,7.781982e-004,0.000000e+000,0,,0,
1523994288.238,,0.000000e+000,3.499950e+001,-2.035293e-004,0.000000e+000,3,9.930295e-001,0.000000e+000,,,,,,,,,,,,,,32,1,4.000000e+000,0.000000e+000,0.000000e+000,0,,0,
1523994326.318,,0.000000e+000,3.499872e+001,-2.035714e-004,0.000000e+000,3,9.930329e-001,0.000000e+000,,,,,,,,,,,,,,32,1,4.000000e+000,1.560211e-003,0.000000e+000,0,,0,
1523994364.821,,0.000000e+000,3.499950e+001,-2.037368e-004,0.000000e+000,3,9.928977e-001,0.000000e+000,,,,,,,,,,,,,,32,1,4.000000e+000,0.000000e+000,0.000000e+000,0,,0,
1523994402.269,,0.000000e+000,3.499833e+001,-2.037506e-004,0.000000e+000,3,9.929496e-001,0.000000e+000,,,,,,,,,,,,,,32,1,4.000000e+000,2.349854e-003,0.000000e+000,0,,0,
1523994440.412,,0.000000e+000,3.499989e+001,-2.037940e-004,0.000000e+000,3,9.928955e-001,0.000000e+000,,,,,,,,,,,,,,32,1,4.000000e+000,2.342224e-003,0.000000e+000,0,,0,
1523994478.260,,0.000000e+000,3.500067e+001,-2.039030e-004,0.000000e+000,3,9.928513e-001,0.000000e+000,,,,,,,,,,,,,,32,1,4.000000e+000,2.338409e-003,0.000000e+000,0,,0,
1523994515.816,,0.000000e+000,3.499989e+001,-2.039580e-004,0.000000e+000,3,9.930269e-001,0.000000e+000,,,,,,,,,,,,,,32,1,4.000000e+000,7.781982e-004,0.000000e+000,0,,0,
1523994553.494,,0.000000e+000,3.499872e+001,-2.039706e-004,0.000000e+000,3,9.930777e-001,0.000000e+000,,,,,,,,,,,,,,32,1,4.000000e+000,0.000000e+000,0.000000e+000,0,,0,
1523994591.657,,0.000000e+000,3.499989e+001,-2.041324e-004,0.000000e+000,3,9.930466e-001,0.000000e+000,,,,,,,,,,,,,,32,1,4.000000e+000,7.781982e-004,0.000000e+000,0,,0,
1523994629.890,,0.000000e+000,3.499911e+001,-2.040644e-004,0.000000e+000,3,9.931918e-001,0.000000e+000,,,,,,,,,,,,,,32,1,4.000000e+000,7.820129e-004,0.000000e+000,0,,0,
1523994668.261,,0.000000e+000,3.499833e+001,-2.041693e-004,0.000000e+000,3,9.927984e-001,0.000000e+000,,,,,,,,,,,,,,32,1,4.000000e+000,7.781982e-004,0.000000e+000,0,,0,
1523994705.926,,0.000000e+000,3.499872e+001,-2.042312e-004,0.000000e+000,3,9.931037e-001,0.000000e+000,,,,,,,,,,,,,,32,1,4.000000e+000,1.560211e-003,0.000000e+000,0,,0,
1523994743.712,,0.000000e+000,3.499793e+001,-2.042716e-004,0.000000e+000,3,9.930598e-001,0.000000e+000,,,,,,,,,,,,,,32,1,4.000000e+000,3.131866e-003,0.000000e+000,0,,0,
1523994782.217,,0.000000e+000,3.499872e+001,-2.043838e-004,0.000000e+000,3,9.929936e-001,0.000000e+000,,,,,,,,,,,,,,32,1,4.000000e+000,0.000000e+000,0.000000e+000,0,,0,
1523994819.320,,0.000000e+000,3.500145e+001,-2.044117e-004,0.000000e+000,3,9.930329e-001,0.000000e+000,,,,,,,,,,,,,,32,1,4.000000e+000,5.470276e-003,0.000000e+000,0,,0,
1523994857.291,,0.000000e+000,3.500028e+001,-2.044571e-004,0.000000e+000,3,9.930478e-001,0.000000e+000,,,,,,,,,,,,,,32,1,4.000000e+000,1.560211e-003,0.000000e+000,0,,0,
1523994895.782,,0.000000e+000,3.500067e+001,-2.044979e-004,0.000000e+000,3,9.931049e-001,0.000000e+000,,,,,,,,,,,,,,32,1,4.000000e+000,2.338409e-003,0.000000e+000,0,,0,
1523994934.217,,0.000000e+000,3.499911e+001,-2.045445e-004,0.000000e+000,3,9.931493e-001,0.000000e+000,,,,,,,,,,,,,,32,1,4.000000e+000,7.820129e-004,0.000000e+000,0,,0,
1523994972.418,,0.000000e+000,3.499793e+001,-2.046306e-004,0.000000e+000,3,9.931016e-001,0.000000e+000,,,,,,,,,,,,,,32,1,4.000000e+000,3.131866e-003,0.000000e+000,0,,0,
1523995010.028,,0.000000e+000,3.499911e+001,-2.046923e-004,0.000000e+000,3,9.929381e-001,0.000000e+000,,,,,,,,,,,,,,32,1,4.000000e+000,7.820129e-004,0.000000e+000,0,,0,
1523995048.064,,0.000000e+000,3.499911e+001,-2.047772e-004,0.000000e+000,3,9.929568e-001,0.000000e+000,,,,,,,,,,,,,,32,1,4.000000e+000,7.820129e-004,0.000000e+000,0,,0,
1523995086.124,,0.000000e+000,3.499989e+001,-2.048266e-004,0.000000e+000,3,9.928540e-001,0.000000e+000,,,,,,,,,,,,,,32,1,4.000000e+000,7.781982e-004,0.000000e+000,0,,0,
1523995124.222,,0.000000e+000,3.499911e+001,-2.048778e-004,0.000000e+000,3,9.929661e-001,0.000000e+000,,,,,,,,,,,,,,32,1,4.000000e+000,7.820129e-004,0.000000e+000,0,,0,
1523995162.226,,0.000000e+000,3.499872e+001,-2.049135e-004,0.000000e+000,3,9.927803e-001,0.000000e+000,,,,,,,,,,,,,,32,1,4.000000e+000,0.000000e+000,0.000000e+000,0,,0,
1523995200.251,,0.000000e+000,3.499911e+001,-2.048948e-004,0.000000e+000,3,9.930298e-001,0.000000e+000,,,,,,,,,,,,,,32,1,4.000000e+000,7.820129e-004,0.000000e+000,0,,0,
1523995238.209,,0.000000e+000,3.499911e+001,-2.050205e-004,0.000000e+000,3,9.929590e-001,0.000000e+000,,,,,,,,,,,,,,32,1,4.000000e+000,7.820129e-004,0.000000e+000,0,,0,
1523995276.957,,0.000000e+000,3.500067e+001,-2.050456e-004,0.000000e+000,3,9.929753e-001,0.000000e+000,,,,,,,,,,,,,,32,1,4.000000e+000,3.910065e-003,0.000000e+000,0,,0,
1523995315.010,,0.000000e+000,3.499872e+001,-2.051166e-004,0.000000e+000,3,9.931214e-001,0.000000e+000,,,,,,,,,,,,,,32,1,4.000000e+000,0.000000e+000,0.000000e+000,0,,0,
1523995353.098,,0.000000e+000,3.500067e+001,-2.051229e-004,0.000000e+000,3,9.930999e-001,0.000000e+000,,,,,,,,,,,,,,32,1,4.000000e+000,2.338409e-003,0.000000e+000,0,,0,
1523995391.186,,0.000000e+000,3.500145e+001,-2.051997e-004,0.000000e+000,3,9.930344e-001,0.000000e+000,,,,,,,,,,,,,,32,1,4.000000e+000,5.470276e-003,0.000000e+000,0,,0,
1523995429.234,,0.000000e+000,3.499833e+001,-2.052517e-004,0.000000e+000,3,9.930239e-001,0.000000e+000,,,,,,,,,,,,,,32,1,4.000000e+000,2.349854e-003,0.000000e+000,0,,0,
1523995467.480,,0.000000e+000,3.499911e+001,-2.053518e-004,0.000000e+000,3,9.929398e-001,0.000000e+000,,,,,,,,,,,,,,32,1,4.000000e+000,7.820129e-004,0.000000e+000,0,,0,
1523995505.225,,0.000000e+000,3.499872e+001,-2.053548e-004,0.000000e+000,3,9.930563e-001,0.000000e+000,,,,,,,,,,,,,,32,1,4.000000e+000,0.000000e+000,0.000000e+000,0,,0,
1523995543.116,,0.000000e+000,3.499950e+001,-2.053925e-004,0.000000e+000,3,9.930307e-001,0.000000e+000,,,,,,,,,,,,,,32,1,4.000000e+000,1.560211e-003,0.000000e+000,0,,0,
1523995581.172,,0.000000e+000,3.499833e+001,-2.054309e-004,0.000000e+000,3,9.928591e-001,0.000000e+000,,,,,,,,,,,,,,32,1,4.000000e+000,7.781982e-004,0.000000e+000,0,,0,
1523995619.762,,0.000000e+000,3.499794e+001,-2.054979e-004,0.000000e+000,3,9.932281e-001,0.000000e+000,,,,,,,,,,,,,,32,1,4.000000e+000,0.000000e+000,0.000000e+000,0,,0,
1523995656.903,,0.000000e+000,3.500028e+001,-2.055821e-004,0.000000e+000,3,9.929463e-001,0.000000e+000,,,,,,,,,,,,,,32,1,4.000000e+000,3.120422e-003,0.000000e+000,0,,0,
1523995694.841,,0.000000e+000,3.499950e+001,-2.056378e-004,0.000000e+000,3,9.931428e-001,0.000000e+000,,,,,,,,,,,,,,32,1,4.000000e+000,0.000000e+000,0.000000e+000,0,,0,
1523995732.876,,0.000000e+000,3.499950e+001,-2.055686e-004,0.000000e+000,3,9.929009e-001,0.000000e+000,,,,,,,,,,,,,,32,1,4.000000e+000,1.560211e-003,0.000000e+000,0,,0,
1523995770.237,,0.000000e+000,3.499911e+001,-2.056653e-004,0.000000e+000,3,9.927496e-001,0.000000e+000,,,,,,,,,,,,,,32,1,4.000000e+000,7.820129e-004,0.000000e+000,0,,0,
1523995808.352,,0.000000e+000,3.499872e+001,-2.057242e-004,0.000000e+000,3,9.931390e-001,0.000000e+000,,,,,,,,,,,,,,32,1,4.000000e+000,1.560211e-003,0.000000e+000,0,,0,
1523995846.506,,0.000000e+000,3.499793e+001,-2.057384e-004,0.000000e+000,3,9.931294e-001,0.000000e+000,,,,,,,,,,,,,,32,1,4.000000e+000,1.567841e-003,0.000000e+000,0,,0,
1523995884.556,,0.000000e+000,3.499950e+001,-2.058739e-004,0.000000e+000,3,9.929705e-001,0.000000e+000,,,,,,,,,,,,,,32,1,4.000000e+000,1.560211e-003,0.000000e+000,0,,0,
1523995922.617,,0.000000e+000,3.499911e+001,-2.058911e-004,0.000000e+000,3,9.929897e-001,0.000000e+000,,,,,,,,,,,,,,32,1,4.000000e+000,7.820129e-004,0.000000e+000,0,,0,
1523995960.692,,0.000000e+000,3.499911e+001,-2.059318e-004,0.000000e+000,3,9.929541e-001,0.000000e+000,,,,,,,,,,,,,,32,1,4.000000e+000,7.820129e-004,0.000000e+000,0,,0,
1523995998.663,,0.000000e+000,3.499989e+001,-2.059607e-004,0.000000e+000,3,9.929541e-001,0.000000e+000,,,,,,,,,,,,,,32,1,4.000000e+000,7.781982e-004,0.000000e+000,0,,0,
1523996036.008,,0.000000e+000,3.499872e+001,-2.060159e-004,0.000000e+000,3,9.929981e-001,0.000000e+000,,,,,,,,,,,,,,32,1,4.000000e+000,1.560211e-003,0.000000e+000,0,,0,
1523996073.734,,0.000000e+000,3.499911e+001,-2.060575e-004,0.000000e+000,3,9.931023e-001,0.000000e+000,,,,,,,,,,,,,,32,1,4.000000e+000,7.820129e-004,0.000000e+000,0,,0,
1523996111.582,,0.000000e+000,3.499911e+001,-2.060928e-004,0.000000e+000,3,9.930715e-001,0.000000e+000,,,,,,,,,,,,,,32,1,4.000000e+000,7.820129e-004,0.000000e+000,0,,0,
1523996149.400,,0.000000e+000,3.499950e+001,-2.061423e-004,0.000000e+000,3,9.930284e-001,0.000000e+000,,,,,,,,,,,,,,32,1,4.000000e+000,1.560211e-003,0.000000e+000,0,,0,
1523996187.480,,0.000000e+000,3.499989e+001,-2.061955e-004,0.000000e+000,3,9.931290e-001,0.000000e+000,,,,,,,,,,,,,,32,1,4.000000e+000,7.781982e-004,0.000000e+000,0,,0,
1523996226.564,,0.000000e+000,3.499911e+001,-2.062637e-004,0.000000e+000,3,9.928035e-001,0.000000e+000,,,,,,,,,,,,,,32,1,4.000000e+000,7.820129e-004,0.000000e+000,0,,0,
1523996263.397,,0.000000e+000,3.499872e+001,-2.061620e-004,0.000000e+000,3,9.929490e-001,0.000000e+000,,,,,,,,,,,,,,32,1,4.000000e+000,0.000000e+000,0.000000e+000,0,,0,
1523996301.640,,0.000000e+000,3.500028e+001,-2.063048e-004,0.000000e+000,3,9.929827e-001,0.000000e+000,,,,,,,,,,,,,,32,1,4.000000e+000,1.560211e-003,0.000000e+000,0,,0,
1523996339.625,,0.000000e+000,3.499872e+001,-2.063490e-004,0.000000e+000,3,9.929938e-001,0.000000e+000,,,,,,,,,,,,,,32,1,4.000000e+000,0.000000e+000,0.000000e+000,0,,0,
1523996377.123,,0.000000e+000,3.499872e+001,-2.063577e-004,0.000000e+000,3,9.931193e-001,0.000000e+000,,,,,,,,,,,,,,32,1,4.000000e+000,0.000000e+000,0.000000e+000,0,,0,
1523996415.101,,0.000000e+000,3.499950e+001,-2.063950e-004,0.000000e+000,3,9.931032e-001,0.000000e+000,,,,,,,,,,,,,,32,1,4.000000e+000,1.560211e-003,0.000000e+000,0,,0,
1523996453.224,,0.000000e+000,3.499872e+001,-2.064265e-004,0.000000e+000,3,9.932427e-001,0.000000e+000,,,,,,,,,,,,,,32,1,4.000000e+000,1.560211e-003,0.000000e+000,0,,0,
1523996490.873,,0.000000e+000,3.499793e+001,-2.065376e-004,0.000000e+000,3,9.930734e-001,0.000000e+000,,,,,,,,,,,,,,32,1,4.000000e+000,1.567841e-003,0.000000e+000,0,,0,
1523996529.081,,0.000000e+000,3.499950e+001,-2.065271e-004,0.000000e+000,3,9.929062e-001,0.000000e+000,,,,,,,,,,,,,,32,1,4.000000e+000,0.000000e+000,0.000000e+000,0,,0,
1523996567.146,,0.000000e+000,3.499872e+001,-2.065918e-004,0.000000e+000,3,9.929692e-001,0.000000e+000,,,,,,,,,,,,,,32,1,4.000000e+000,0.000000e+000,0.000000e+000,0,,0,
1523996604.742,,0.000000e+000,3.499911e+001,-2.066137e-004,0.000000e+000,3,9.929114e-001,0.000000e+000,,,,,,,,,,,,,,32,1,4.000000e+000,7.820129e-004,0.000000e+000,0,,0,
1523996643.265,,0.000000e+000,3.499911e+001,-2.066772e-004,0.000000e+000,3,9.928915e-001,0.000000e+000,,,,,,,,,,,,,,32,1,4.000000e+000,7.820129e-004,0.000000e+000,0,,0,
1523996680.955,,0.000000e+000,3.499911e+001,-2.066891e-004,0.000000e+000,3,9.930342e-001,0.000000e+000,,,,,,,,,,,,,,32,1,4.000000e+000,2.338409e-003,0.000000e+000,0,,0,
1523996718.806,,0.000000e+000,3.499833e+001,-2.067755e-004,0.000000e+000,3,9.928595e-001,0.000000e+000,,,,,,,,,,,,,,32,1,4.000000e+000,7.781982e-004,0.000000e+000,0,,0,
1523996756.974,,0.000000e+000,3.499950e+001,-2.067066e-004,0.000000e+000,3,9.929553e-001,0.000000e+000,,,,,,,,,,,,,,32,1,4.000000e+000,1.560211e-003,0.000000e+000,0,,0,
1523996795.497,,0.000000e+000,3.499950e+001,-2.068159e-004,0.000000e+000,3,9.928955e-001,0.000000e+000,,,,,,,,,,,,,,32,1,4.000000e+000,1.560211e-003,0.000000e+000,0,,0,
1523996833.570,,0.000000e+000,3.499950e+001,-2.068628e-004,0.000000e+000,3,9.930154e-001,0.000000e+000,,,,,,,,,,,,,,32,1,4.000000e+000,1.560211e-003,0.000000e+000,0,,0,
1523996871.613,,0.000000e+000,3.499950e+001,-2.068856e-004,0.000000e+000,3,9.928792e-001,0.000000e+000,,,,,,,,,,,,,,32,1,4.000000e+000,1.560211e-003,0.000000e+000,0,,0,
1523996909.521,,0.000000e+000,3.499872e+001,-2.069275e-004,0.000000e+000,3,9.929449e-001,0.000000e+000,,,,,,,,,,,,,,32,1,4.000000e+000,0.000000e+000,0.000000e+000,0,,0,
1523996948.094,,0.000000e+000,3.499950e+001,-2.069490e-004,0.000000e+000,3,9.930842e-001,0.000000e+000,,,,,,,,,,,,,,32,1,4.000000e+000,0.000000e+000,0.000000e+000,0,,0,
1523996986.137,,0.000000e+000,3.499911e+001,-2.069804e-004,0.000000e+000,3,9.930071e-001,0.000000e+000,,,,,,,,,,,,,,32,1,4.000000e+000,7.820129e-004,0.000000e+000,0,,0,
1523997023.328,,0.000000e+000,3.499911e+001,-2.070440e-004,0.000000e+000,3,9.930861e-001,0.000000e+000,,,,,,,,,,,,,,32,1,4.000000e+000,7.820129e-004,0.000000e+000,0,,0,
1523997061.381,,0.000000e+000,3.499872e+001,-2.070567e-004,0.000000e+000,3,9.929751e-001,0.000000e+000,,,,,,,,,,,,,,32,1,4.000000e+000,0.000000e+000,0.000000e+000,0,,0,
1523997099.661,,0.000000e+000,3.499950e+001,-2.070911e-004,0.000000e+000,3,9.929054e-001,0.000000e+000,,,,,,,,,,,,,,32,1,4.000000e+000,0.000000e+000,0.000000e+000,0,,0,
1523997137.062,,0.000000e+000,3.499872e+001,-2.071440e-004,0.000000e+000,3,9.931156e-001,0.000000e+000,,,,,,,,,,,,,,32,1,4.000000e+000,1.560211e-003,0.000000e+000,0,,0,
1523997175.123,,0.000000e+000,3.499950e+001,-2.072089e-004,0.000000e+000,3,9.929981e-001,0.000000e+000,,,,,,,,,,,,,,32,1,4.000000e+000,1.560211e-003,0.000000e+000,0,,0,
1523997213.093,,0.000000e+000,3.499989e+001,-2.072713e-004,0.000000e+000,3,9.930688e-001,0.000000e+000,,,,,,,,,,,,,,32,1,4.000000e+000,7.781982e-004,0.000000e+000,0,,0,
1523997251.211,,0.000000e+000,3.499911e+001,-2.072702e-004,0.000000e+000,3,9.931003e-001,0.000000e+000,,,,,,,,,,,,,,32,1,4.000000e+000,7.820129e-004,0.000000e+000,0,,0,
1523997289.219,,0.000000e+000,3.499833e+001,-2.073231e-004,0.000000e+000,3,9.930484e-001,0.000000e+000,,,,,,,,,,,,,,32,1,4.000000e+000,7.781982e-004,0.000000e+000,0,,0,
1523997326.847,,0.000000e+000,3.500106e+001,-2.073383e-004,0.000000e+000,3,9.928993e-001,0.000000e+000,,,,,,,,,,,,,,32,1,4.000000e+000,1.560211e-003,0.000000e+000,0,,0,
1523997364.895,,0.000000e+000,3.499989e+001,-2.073465e-004,0.000000e+000,3,9.929501e-001,0.000000e+000,,,,,,,,,,,,,,32,1,4.000000e+000,7.781982e-004,0.000000e+000,0,,0,
1523997402.931,,0.000000e+000,3.499872e+001,-2.074778e-004,0.000000e+000,3,9.928257e-001,0.000000e+000,,,,,,,,,,,,,,32,1,4.000000e+000,1.560211e-003,0.000000e+000,0,,0,
1523997441.446,,0.000000e+000,3.499911e+001,-2.074214e-004,0.000000e+000,3,9.932269e-001,0.000000e+000,,,,,,,,,,,,,,32,1,4.000000e+000,7.820129e-004,0.000000e+000,0,,0,
1523997478.994,,0.000000e+000,3.499989e+001,-2.074587e-004,0.000000e+000,3,9.929525e-001,0.000000e+000,,,,,,,,,,,,,,32,1,4.000000e+000,7.781982e-004,0.000000e+000,0,,0,
1523997517.045,,0.000000e+000,3.499872e+001,-2.074814e-004,0.000000e+000,3,9.928839e-001,0.000000e+000,,,,,,,,,,,,,,32,1,4.000000e+000,0.000000e+000,0.000000e+000,0,,0,
1523997555.203,,0.000000e+000,3.499950e+001,-2.075072e-004,0.000000e+000,3,9.929758e-001,0.000000e+000,,,,,,,,,,,,,,32,1,4.000000e+000,0.000000e+000,0.000000e+000,0,,0,
1523997593.514,,0.000000e+000,3.499950e+001,-2.075509e-004,0.000000e+000,3,9.930637e-001,0.000000e+000,,,,,,,,,,,,,,32,1,4.000000e+000,0.000000e+000,0.000000e+000,0,,0,
1523997630.784,,0.000000e+000,3.499950e+001,-2.076082e-004,0.000000e+000,3,9.929778e-001,0.000000e+000,,,,,,,,,,,,,,32,1,4.000000e+000,0.000000e+000,0.000000e+000,0,,0,
1523997668.845,,0.000000e+000,3.499911e+001,-2.076582e-004,0.000000e+000,3,9.931157e-001,0.000000e+000,,,,,,,,,,,,,,32,1,4.000000e+000,7.820129e-004,0.000000e+000,0,,0,
1523997706.903,,0.000000e+000,3.499872e+001,-2.076486e-004,0.000000e+000,3,9.928937e-001,0.000000e+000,,,,,,,,,,,,,,32,1,4.000000e+000,0.000000e+000,0.000000e+000,0,,0,
1523997744.866,,0.000000e+000,3.499872e+001,-2.076897e-004,0.000000e+000,3,9.930450e-001,0.000000e+000,,,,,,,,,,,,,,32,1,4.000000e+000,0.000000e+000,0.000000e+000,0,,0,
1523997782.916,,0.000000e+000,3.499911e+001,-2.077323e-004,0.000000e+000,3,9.930350e-001,0.000000e+000,,,,,,,,,,,,,,32,1,4.000000e+000,7.820129e-004,0.000000e+000,0,,0,
1523997821.495,,0.000000e+000,3.499950e+001,-2.077475e-004,0.000000e+000,3,9.930533e-001,0.000000e+000,,,,,,,,,,,,,,32,1,4.000000e+000,0.000000e+000,0.000000e+000,0,,0,
1523997859.433,,0.000000e+000,3.499911e+001,-2.078012e-004,0.000000e+000,3,9.931092e-001,0.000000e+000,,,,,,,,,,,,,,32,1,4.000000e+000,7.820129e-004,0.000000e+000,0,,0,
1523997898.106,,0.000000e+000,3.499715e+001,-2.078250e-004,0.000000e+000,3,9.929922e-001,0.000000e+000,,,,,,,,,,,,,,32,1,4.000000e+000,3.128052e-003,0.000000e+000,0,,0,
1523997936.029,,0.000000e+000,3.499911e+001,-2.078749e-004,0.000000e+000,3,9.930115e-001,0.000000e+000,,,,,,,,,,,,,,32,1,4.000000e+000,7.820129e-004,0.000000e+000,0,,0,
1523997973.557,,0.000000e+000,3.499833e+001,-2.078585e-004,0.000000e+000,3,9.929365e-001,0.000000e+000,,,,,,,,,,,,,,32,1,4.000000e+000,2.349854e-003,0.000000e+000,0,,0,
1523998011.150,,0.000000e+000,3.499950e+001,-2.079643e-004,0.000000e+000,3,9.929487e-001,0.000000e+000,,,,,,,,,,,,,,32,1,4.000000e+000,1.560211e-003,0.000000e+000,0,,0,
1523998049.178,,0.000000e+000,3.499833e+001,-2.079592e-004,0.000000e+000,3,9.930786e-001,0.000000e+000,,,,,,,,,,,,,,32,1,4.000000e+000,7.781982e-004,0.000000e+000,0,,0,
1523998087.328,,0.000000e+000,3.499793e+001,-2.079961e-004,0.000000e+000,3,9.930341e-001,0.000000e+000,,,,,,,,,,,,,,32,1,4.000000e+000,1.567841e-003,0.000000e+000,0,,0,
1523998125.274,,0.000000e+000,3.499950e+001,-2.080456e-004,0.000000e+000,3,9.930620e-001,0.000000e+000,,,,,,,,,,,,,,32,1,4.000000e+000,0.000000e+000,0.000000e+000,0,,0,
1523998164.145,,0.000000e+000,3.499950e+001,-2.080479e-004,0.000000e+000,3,9.930094e-001,0.000000e+000,,,,,,,,,,,,,,32,1,4.000000e+000,1.560211e-003,0.000000e+000,0,,0,
1523998202.387,,0.000000e+000,3.500028e+001,-2.080382e-004,0.000000e+000,3,9.930542e-001,0.000000e+000,,,,,,,,,,,,,,32,1,4.000000e+000,1.560211e-003,0.000000e+000,0,,0,
1523998240.401,,0.000000e+000,3.499911e+001,-2.081229e-004,0.000000e+000,3,9.931025e-001,0.000000e+000,,,,,,,,,,,,,,32,1,4.000000e+000,7.820129e-004,0.000000e+000,0,,0,
1523998278.609,,0.000000e+000,3.499911e+001,-2.081433e-004,0.000000e+000,3,9.930682e-001,0.000000e+000,,,,,,,,,,,,,,32,1,4.000000e+000,7.820129e-004,0.000000e+000,0,,0,
1523998317.444,,0.000000e+000,3.499911e+001,-2.082135e-004,0.000000e+000,3,9.927911e-001,0.000000e+000,,,,,,,,,,,,,,32,1,4.000000e+000,7.820129e-004,0.000000e+000,0,,0,
1523998355.420,,0.000000e+000,3.499950e+001,-2.082094e-004,0.000000e+000,3,9.930276e-001,0.000000e+000,,,,,,,,,,,,,,32,1,4.000000e+000,0.000000e+000,0.000000e+000,0,,0,
1523998393.753,,0.000000e+000,3.499911e+001,-2.082043e-004,0.000000e+000,3,9.931210e-001,0.000000e+000,,,,,,,,,,,,,,32,1,4.000000e+000,7.820129e-004,0.000000e+000,0,,0,
1523998431.761,,0.000000e+000,3.500067e+001,-2.082010e-004,0.000000e+000,3,9.930097e-001,0.000000e+000,,,,,,,,,,,,,,32,1,4.000000e+000,7.820129e-004,0.000000e+000,0,,0,
1523998469.572,,0.000000e+000,3.499950e+001,-2.082733e-004,0.000000e+000,3,9.933096e-001,0.000000e+000,,,,,,,,,,,,,,32,1,4.000000e+000,0.000000e+000,0.000000e+000,0,,0,
1523998507.212,,0.000000e+000,3.499872e+001,-2.083267e-004,0.000000e+000,3,9.930694e-001,0.000000e+000,,,,,,,,,,,,,,32,1,4.000000e+000,0.000000e+000,0.000000e+000,0,,0,
1523998545.285,,0.000000e+000,3.499911e+001,-2.083842e-004,0.000000e+000,3,9.930287e-001,0.000000e+000,,,,,,,,,,,,,,32,1,4.000000e+000,7.820129e-004,0.000000e+000,0,,0,
1523998583.338,,0.000000e+000,3.499989e+001,-2.083712e-004,0.000000e+000,3,9.930687e-001,0.000000e+000,,,,,,,,,,,,,,32,1,4.000000e+000,7.781982e-004,0.000000e+000,0,,0,
1523998621.851,,0.000000e+000,3.499950e+001,-2.083868e-004,0.000000e+000,3,9.929922e-001,0.000000e+000,,,,,,,,,,,,,,32,1,4.000000e+000,0.000000e+000,0.000000e+000,0,,0,
1523998660.274,,0.000000e+000,3.499911e+001,-2.084682e-004,0.000000e+000,3,9.930995e-001,0.000000e+000,,,,,,,,,,,,,,32,1,4.000000e+000,7.820129e-004,0.000000e+000,0,,0,
1523998698.272,,0.000000e+000,3.499911e+001,-2.084531e-004,0.000000e+000,3,9.930587e-001,0.000000e+000,,,,,,,,,,,,,,32,1,4.000000e+000,7.820129e-004,0.000000e+000,0,,0,
1523998736.135,,0.000000e+000,3.499872e+001,-2.084992e-004,0.000000e+000,3,9.929110e-001,0.000000e+000,,,,,,,,,,,,,,32,1,4.000000e+000,1.560211e-003,0.000000e+000,0,,0,
1523998774.996,,0.000000e+000,3.499989e+001,-2.086021e-004,0.000000e+000,3,9.930127e-001,0.000000e+000,,,,,,,,,,,,,,32,1,4.000000e+000,7.781982e-004,0.000000e+000,0,,0,
1523998812.254,,0.000000e+000,3.499950e+001,-2.085520e-004,0.000000e+000,3,9.928817e-001,0.000000e+000,,,,,,,,,,,,,,32,1,4.000000e+000,1.560211e-003,0.000000e+000,0,,0,
1523998850.047,,0.000000e+000,3.499989e+001,-2.085755e-004,0.000000e+000,3,9.929720e-001,0.000000e+000,,,,,,,,,,,,,,32,1,4.000000e+000,7.781982e-004,0.000000e+000,0,,0,
1523998888.028,,0.000000e+000,3.499911e+001,-2.085860e-004,0.000000e+000,3,9.930331e-001,0.000000e+000,,,,,,,,,,,,,,32,1,4.000000e+000,7.820129e-004,0.000000e+000,0,,0,
1523998925.801,,0.000000e+000,3.499911e+001,-2.086786e-004,0.000000e+000,3,9.930117e-001,0.000000e+000,,,,,,,,,,,,,,32,1,4.000000e+000,7.820129e-004,0.000000e+000,0,,0,
1523998964.884,,0.000000e+000,3.499989e+001,-2.086983e-004,0.000000e+000,3,9.929841e-001,0.000000e+000,,,,,,,,,,,,,,32,1,4.000000e+000,7.781982e-004,0.000000e+000,0,,0,
1523999003.347,,0.000000e+000,3.499911e+001,-2.086672e-004,0.000000e+000,3,9.930097e-001,0.000000e+000,,,,,,,,,,,,,,32,1,4.000000e+000,7.820129e-004,0.000000e+000,0,,0,
1523999041.270,,0.000000e+000,3.499833e+001,-2.086970e-004,0.000000e+000,3,9.929270e-001,0.000000e+000,,,,,,,,,,,,,,32,1,4.000000e+000,2.349854e-003,0.000000e+000,0,,0,
1523999079.205,,0.000000e+000,3.499871e+001,-2.087277e-004,0.000000e+000,3,9.927805e-001,0.000000e+000,,,,,,,,,,,,,,32,1,4.000000e+000,3.128052e-003,0.000000e+000,0,,0,
1523999117.606,,0.000000e+000,3.499989e+001,-2.087826e-004,0.000000e+000,3,9.928669e-001,0.000000e+000,,,,,,,,,,,,,,32,1,4.000000e+000,7.781982e-004,0.000000e+000,0,,0,
1523999155.587,,0.000000e+000,3.499911e+001,-2.087989e-004,0.000000e+000,3,9.929997e-001,0.000000e+000,,,,,,,,,,,,,,32,1,4.000000e+000,7.820129e-004,0.000000e+000,0,,0,
1523999193.620,,0.000000e+000,3.499950e+001,-2.088311e-004,0.000000e+000,3,9.930470e-001,0.000000e+000,,,,,,,,,,,,,,32,1,4.000000e+000,0.000000e+000,0.000000e+000,0,,0,
1523999231.710,,0.000000e+000,3.499989e+001,-2.088399e-004,0.000000e+000,3,9.928897e-001,0.000000e+000,,,,,,,,,,,,,,32,1,4.000000e+000,7.781982e-004,0.000000e+000,0,,0,
1523999270.301,,0.000000e+000,3.499872e+001,-2.089013e-004,0.000000e+000,3,9.931399e-001,0.000000e+000,,,,,,,,,,,,,,32,1,4.000000e+000,0.000000e+000,0.000000e+000,0,,0,
1523999307.821,,0.000000e+000,3.499911e+001,-2.088886e-004,0.000000e+000,3,9.929104e-001,0.000000e+000,,,,,,,,,,,,,,32,1,4.000000e+000,7.820129e-004,0.000000e+000,0,,0,
1523999345.879,,0.000000e+000,3.499794e+001,-2.089679e-004,0.000000e+000,3,9.929591e-001,0.000000e+000,,,,,,,,,,,,,,32,1,4.000000e+000,0.000000e+000,0.000000e+000,0,,0,
1523999383.917,,0.000000e+000,3.499911e+001,-2.089473e-004,0.000000e+000,3,9.930083e-001,0.000000e+000,,,,,,,,,,,,,,32,1,4.000000e+000,7.820129e-004,0.000000e+000,0,,0,
1523999421.963,,0.000000e+000,3.499872e+001,-2.089921e-004,0.000000e+000,3,9.930344e-001,0.000000e+000,,,,,,,,,,,,,,32,1,4.000000e+000,1.560211e-003,0.000000e+000,0,,0,
1523999460.064,,0.000000e+000,3.499872e+001,-2.090316e-004,0.000000e+000,3,9.930395e-001,0.000000e+000,,,,,,,,,,,,,,32,1,4.000000e+000,1.560211e-003,0.000000e+000,0,,0,
1523999498.112,,0.000000e+000,3.499911e+001,-2.090610e-004,0.000000e+000,3,9.930481e-001,0.000000e+000,,,,,,,,,,,,,,32,1,4.000000e+000,7.820129e-004,0.000000e+000,0,,0,
1523999536.160,,0.000000e+000,3.499989e+001,-2.091716e-004,0.000000e+000,3,9.932269e-001,0.000000e+000,,,,,,,,,,,,,,32,1,4.000000e+000,7.781982e-004,0.000000e+000,0,,0,
1523999574.228,,0.000000e+000,3.499950e+001,-2.091553e-004,0.000000e+000,3,9.930013e-001,0.000000e+000,,,,,,,,,,,,,,32,1,4.000000e+000,1.560211e-003,0.000000e+000,0,,0,
1523999612.311,,0.000000e+000,3.499911e+001,-2.091236e-004,0.000000e+000,3,9.929805e-001,0.000000e+000,,,,,,,,,,,,,,32,1,4.000000e+000,7.820129e-004,0.000000e+000,0,,0,
1523999650.904,,0.000000e+000,3.499872e+001,-2.091459e-004,0.000000e+000,3,9.929976e-001,0.000000e+000,,,,,,,,,,,,,,32,1,4.000000e+000,0.000000e+000,0.000000e+000,0,,0,
1523999688.574,,0.000000e+000,3.499911e+001,-2.092021e-004,0.000000e+000,3,9.930040e-001,0.000000e+000,,,,,,,,,,,,,,32,1,4.000000e+000,7.820129e-004,0.000000e+000,0,,0,
1523999725.790,,0.000000e+000,3.499872e+001,-2.092017e-004,0.000000e+000,3,9.929572e-001,0.000000e+000,,,,,,,,,,,,,,32,1,4.000000e+000,0.000000e+000,0.000000e+000,0,,0,
1523999763.200,,0.000000e+000,3.499911e+001,-2.092588e-004,0.000000e+000,3,9.930022e-001,0.000000e+000,,,,,,,,,,,,,,32,1,4.000000e+000,7.820129e-004,0.000000e+000,0,,0,
1523999800.501,,0.000000e+000,3.499911e+001,-2.092525e-004,0.000000e+000,3,9.931067e-001,0.000000e+000,,,,,,,,,,,,,,32,1,4.000000e+000,7.820129e-004,0.000000e+000,0,,0,
1523999838.522,,0.000000e+000,3.499950e+001,-2.092402e-004,0.000000e+000,3,9.930553e-001,0.000000e+000,,,,,,,,,,,,,,32,1,4.000000e+000,0.000000e+000,0.000000e+000,0,,0,
1523999876.587,,0.000000e+000,3.499950e+001,-2.093309e-004,0.000000e+000,3,9.929879e-001,0.000000e+000,,,,,,,,,,,,,,32,1,4.000000e+000,1.560211e-003,0.000000e+000,0,,0,
1523999915.203,,0.000000e+000,3.499950e+001,-2.093563e-004,0.000000e+000,3,9.930115e-001,0.000000e+000,,,,,,,,,,,,,,32,1,4.000000e+000,1.560211e-003,0.000000e+000,0,,0,
1523999952.656,,0.000000e+000,3.499872e+001,-2.093647e-004,0.000000e+000,3,9.929134e-001,0.000000e+000,,,,,,,,,,,,,,32,1,4.000000e+000,0.000000e+000,0.000000e+000,0,,0,
1523999990.231,,0.000000e+000,3.499677e+001,-2.093706e-004,0.000000e+000,3,9.929889e-001,0.000000e+000,,,,,,,,,,,,,,32,1,4.000000e+000,2.349854e-003,0.000000e+000,0,,0,
1524000028.302,,0.000000e+000,3.499911e+001,-2.094051e-004,0.000000e+000,3,9.930146e-001,0.000000e+000,,,,,,,,,,,,,,32,1,4.000000e+000,7.820129e-004,0.000000e+000,0,,0,
1524000066.365,,0.000000e+000,3.499872e+001,-2.094211e-004,0.000000e+000,3,9.930047e-001,0.000000e+000,,,,,,,,,,,,,,32,1,4.000000e+000,0.000000e+000,0.000000e+000,0,,0,
1524000105.158,,0.000000e+000,3.499872e+001,-2.094567e-004,0.000000e+000,3,9.929078e-001,0.000000e+000,,,,,,,,,,,,,,32,1,4.000000e+000,0.000000e+000,0.000000e+000,0,,0,
1524000143.634,,0.000000e+000,3.499872e+001,-2.094793e-004,0.000000e+000,3,9.930616e-001,0.000000e+000,,,,,,,,,,,,,,32,1,4.000000e+000,0.000000e+000,0.000000e+000,0,,0,
1524000180.767,,0.000000e+000,3.499950e+001,-2.094918e-004,0.000000e+000,3,9.929419e-001,0.000000e+000,,,,,,,,,,,,,,32,1,4.000000e+000,0.000000e+000,0.000000e+000,0,,0,
1524000219.300,,0.000000e+000,3.499989e+001,-2.095270e-004,0.000000e+000,3,9.931765e-001,0.000000e+000,,,,,,,,,,,,,,32,1,4.000000e+000,7.781982e-004,0.000000e+000,0,,0,
1524000257.315,,0.000000e+000,3.499872e+001,-2.095695e-004,0.000000e+000,3,9.929525e-001,0.000000e+000,,,,,,,,,,,,,,32,1,4.000000e+000,0.000000e+000,0.000000e+000,0,,0,
1524000294.708,,0.000000e+000,3.499872e+001,-2.095899e-004,0.000000e+000,3,9.930701e-001,0.000000e+000,,,,,,,,,,,,,,32,1,4.000000e+000,0.000000e+000,0.000000e+000,0,,0,
1524000332.241,,0.000000e+000,3.499911e+001,-2.095885e-004,0.000000e+000,3,9.928007e-001,0.000000e+000,,,,,,,,,,,,,,32,1,4.000000e+000,7.820129e-004,0.000000e+000,0,,0,
1524000369.769,,0.000000e+000,3.499950e+001,-2.095764e-004,0.000000e+000,3,9.930490e-001,0.000000e+000,,,,,,,,,,,,,,32,1,4.000000e+000,0.000000e+000,0.000000e+000,0,,0,
1524000408.315,,0.000000e+000,3.499911e+001,-2.095929e-004,0.000000e+000,3,9.929474e-001,0.000000e+000,,,,,,,,,,,,,,32,1,4.000000e+000,7.820129e-004,0.000000e+000,0,,0,
1524000446.338,,0.000000e+000,3.499950e+001,-2.097049e-004,0.000000e+000,3,9.929935e-001,0.000000e+000,,,,,,,,,,,,,,32,1,4.000000e+000,0.000000e+000,0.000000e+000,0,,0,
1524000484.059,,0.000000e+000,3.499989e+001,-2.097075e-004,0.000000e+000,3,9.929798e-001,0.000000e+000,,,,,,,,,,,,,,32,1,4.000000e+000,7.781982e-004,0.000000e+000,0,,0,
1524000521.944,,0.000000e+000,3.499911e+001,-2.096962e-004,0.000000e+000,3,9.930659e-001,0.000000e+000,,,,,,,,,,,,,,32,1,4.000000e+000,7.820129e-004,0.000000e+000,0,,0,
1524000559.995,,0.000000e+000,3.499950e+001,-2.097461e-004,0.000000e+000,3,9.929878e-001,0.000000e+000,,,,,,,,,,,,,,32,1,4.000000e+000,0.000000e+000,0.000000e+000,0,,0,
1524000598.063,,0.000000e+000,3.500028e+001,-2.097485e-004,0.000000e+000,3,9.928446e-001,0.000000e+000,,,,,,,,,,,,,,32,1,4.000000e+000,1.560211e-003,0.000000e+000,0,,0,
1524000636.278,,0.000000e+000,3.500028e+001,-2.097528e-004,0.000000e+000,3,9.928672e-001,0.000000e+000,,,,,,,,,,,,,,32,1,4.000000e+000,1.560211e-003,0.000000e+000,0,,0,
1524000674.166,,0.000000e+000,3.499950e+001,-2.097817e-004,0.000000e+000,3,9.930398e-001,0.000000e+000,,,,,,,,,,,,,,32,1,4.000000e+000,0.000000e+000,0.000000e+000,0,,0,
1524000712.247,,0.000000e+000,3.499950e+001,-2.098182e-004,0.000000e+000,3,9.931906e-001,0.000000e+000,,,,,,,,,,,,,,32,1,4.000000e+000,1.560211e-003,0.000000e+000,0,,0,
1524000750.295,,0.000000e+000,3.499911e+001,-2.098402e-004,0.000000e+000,3,9.929388e-001,0.000000e+000,,,,,,,,,,,,,,32,1,4.000000e+000,7.820129e-004,0.000000e+000,0,,0,
1524000788.380,,0.000000e+000,3.499911e+001,-2.098307e-004,0.000000e+000,3,9.929435e-001,0.000000e+000,,,,,,,,,,,,,,32,1,4.000000e+000,7.820129e-004,0.000000e+000,0,,0,
1524000826.414,,0.000000e+000,3.499833e+001,-2.098738e-004,0.000000e+000,3,9.930118e-001,0.000000e+000,,,,,,,,,,,,,,32,1,4.000000e+000,7.781982e-004,0.000000e+000,0,,0,
1524000864.569,,0.000000e+000,3.499989e+001,-2.098919e-004,0.000000e+000,3,9.929225e-001,0.000000e+000,,,,,,,,,,,,,,32,1,4.000000e+000,7.781982e-004,0.000000e+000,0,,0,
1524000902.525,,0.000000e+000,3.499989e+001,-2.099210e-004,0.000000e+000,3,9.929472e-001,0.000000e+000,,,,,,,,,,,,,,32,1,4.000000e+000,7.781982e-004,0.000000e+000,0,,0,
1524000940.543,,0.000000e+000,3.499989e+001,-2.099391e-004,0.000000e+000,3,9.930429e-001,0.000000e+000,,,,,,,,,,,,,,32,1,4.000000e+000,7.781982e-004,0.000000e+000,0,,0,
1524000978.636,,0.000000e+000,3.499833e+001,-2.099523e-004,0.000000e+000,3,9.929714e-001,0.000000e+000,,,,,,,,,,,,,,32,1,4.000000e+000,7.781982e-004,0.000000e+000,0,,0,
1524001016.146,,0.000000e+000,3.500106e+001,-2.099364e-004,0.000000e+000,3,9.930718e-001,0.000000e+000,,,,,,,,,,,,,,32,1,4.000000e+000,1.560211e-003,0.000000e+000,0,,0,
1524001054.129,,0.000000e+000,3.499950e+001,-2.100128e-004,0.000000e+000,3,9.931361e-001,0.000000e+000,,,,,,,,,,,,,,32,1,4.000000e+000,0.000000e+000,0.000000e+000,0,,0,
1524001092.197,,0.000000e+000,3.499833e+001,-2.100085e-004,0.000000e+000,3,9.930607e-001,0.000000e+000,,,,,,,,,,,,,,32,1,4.000000e+000,7.781982e-004,0.000000e+000,0,,0,
1524001130.203,,0.000000e+000,3.499950e+001,-2.100262e-004,0.000000e+000,3,9.930269e-001,0.000000e+000,,,,,,,,,,,,,,32,1,4.000000e+000,1.560211e-003,0.000000e+000,0,,0,
1524001167.969,,0.000000e+000,3.499793e+001,-2.100610e-004,0.000000e+000,3,9.931412e-001,0.000000e+000,,,,,,,,,,,,,,32,1,4.000000e+000,3.131866e-003,0.000000e+000,0,,0,
1524001205.542,,0.000000e+000,3.499911e+001,-2.101038e-004,0.000000e+000,3,9.929789e-001,0.000000e+000,,,,,,,,,,,,,,32,1,4.000000e+000,7.820129e-004,0.000000e+000,0,,0,
1524001243.175,,0.000000e+000,3.499833e+001,-2.101085e-004,0.000000e+000,3,9.929326e-001,0.000000e+000,,,,,,,,,,,,,,32,1,4.000000e+000,7.781982e-004,0.000000e+000,0,,0,
1524001281.528,,0.000000e+000,3.499871e+001,-2.101056e-004,0.000000e+000,3,9.930129e-001,0.000000e+000,,,,,,,,,,,,,,32,1,4.000000e+000,3.128052e-003,0.000000e+000,0,,0,
1524001319.848,,0.000000e+000,3.499911e+001,-2.101455e-004,0.000000e+000,3,9.932884e-001,0.000000e+000,,,,,,,,,,,,,,32,1,4.000000e+000,7.820129e-004,0.000000e+000,0,,0,
1524001357.904,,0.000000e+000,3.499950e+001,-2.101990e-004,0.000000e+000,3,9.929528e-001,0.000000e+000,,,,,,,,,,,,,,32,1,4.000000e+000,0.000000e+000,0.000000e+000,0,,0,
1524001395.837,,0.000000e+000,3.499950e+001,-2.101856e-004,0.000000e+000,3,9.930341e-001,0.000000e+000,,,,,,,,,,,,,,32,1,4.000000e+000,1.560211e-003,0.000000e+000,0,,0,
1524001434.832,,0.000000e+000,3.499872e+001,-2.101825e-004,0.000000e+000,3,9.931307e-001,0.000000e+000,,,,,,,,,,,,,,32,1,4.000000e+000,1.560211e-003,0.000000e+000,0,,0,
1524001473.686,,0.000000e+000,3.499911e+001,-2.102329e-004,0.000000e+000,3,9.930161e-001,0.000000e+000,,,,,,,,,,,,,,32,1,4.000000e+000,7.820129e-004,0.000000e+000,0,,0,
1524001511.724,,0.000000e+000,3.499833e+001,-2.102442e-004,0.000000e+000,3,9.929947e-001,0.000000e+000,,,,,,,,,,,,,,32,1,4.000000e+000,7.781982e-004,0.000000e+000,0,,0,
1524001550.559,,0.000000e+000,3.499989e+001,-2.102848e-004,0.000000e+000,3,9.930342e-001,0.000000e+000,,,,,,,,,,,,,,32,1,4.000000e+000,7.781982e-004,0.000000e+000,0,,0,
1524001562.649,,0.000000e+000,3.499833e+001,-2.102879e-004,0.000000e+000,3,9.929707e-001,0.000000e+000,,,,,,,,,,,,,,32,1,4.000000e+000,7.781982e-004,0.000000e+000,0,,0,