File: Experimental Raw Data/MFn1 VRM/Iterative Regression/Acquisition/MFn1_VRMac_33K_12000s.dc.dat
[Header]
TITLE,MPMS DC Measurement
BYAPP,MPMS Measurement,2.1,Summary
FILEOPENTIME, 1524100600.965000 4/18/2018, 7:16:40 PM

INFO, APPNAME, MPMS MultiVu Application, Revision 1.61,  Build 082

INFO, NAME, MFn1
INFO, WEIGHT, 1.000
INFO, AREA, 1.000
INFO, LENGTH, 1.000
INFO, SHAPE, 0
INFO, COMMENT,
INFO, SEQUENCE FILE: VRMac_33K_12000s_VRMde_35K.seq


INFO, BACKGROUND DATA FILE:, None


STARTUPAXIS,X,4,LINEAR,AUTO,0.000000,0.000000
STARTUPAXIS,Y1,5,LINEAR,AUTO,0.000000,0.000000


STARTUPGROUP,Longitudinal
FIELDGROUP,Longitudinal,1,2,3,4,5,6,7,8,9,15,16,17,18,27,28
FIELDGROUP,Transverse,1,2,3,4,10,11,12,13,14,19,20,21,22,27,28

PLOT_APPEARANCE,ALL,HORZ_GRID_ON,VERT_GRID_ON,MARKERS_AND_LINES

[Data]
Time,Comment,Field (Oe),Temperature (K),Long Moment (emu),Long Scan Std Dev,Long Algorithm,Long Reg Fit,Long Percent Error (%),Trans Moment (emu),Trans Scan Std Dev,Trans Algorithm,Trans Reg Fit,Trans Percent Error (%),Long Moment [w/o ABS] (emu),Long Scan Std Dev [w/o ABS],Long Reg Fit [w/o ABS],Long Percent Error [w/o ABS] (%),Trans Moment [w/o ABS] (emu),Trans Scan Std Dev [w/o ABS],Trans Reg Fit [w/o ABS],Trans Percent Error [w/o ABS] (%),Points per Scan,Scans per Measurement,Scan Length (cm),Delta Temp (K),Rot Position (deg),Error,EC Comp. Running,Using ABS,
1524100600.963,,0.000000e+000,3.299750e+001,-1.690720e-004,0.000000e+000,3,9.917974e-001,0.000000e+000,,,,,,,,,,,,,,32,1,4.000000e+000,1.392365e-003,0.000000e+000,0,,0,
1524100638.738,,0.000000e+000,3.299957e+001,-1.747502e-004,0.000000e+000,3,9.922639e-001,0.000000e+000,,,,,,,,,,,,,,32,1,4.000000e+000,1.380920e-003,0.000000e+000,0,,0,
1524100676.214,,0.000000e+000,3.300026e+001,-1.771291e-004,0.000000e+000,3,9.924702e-001,0.000000e+000,,,,,,,,,,,,,,32,1,4.000000e+000,0.000000e+000,0.000000e+000,0,,0,
1524100714.257,,0.000000e+000,3.299854e+001,-1.787011e-004,0.000000e+000,3,9.925517e-001,0.000000e+000,,,,,,,,,,,,,,32,1,4.000000e+000,6.866455e-004,0.000000e+000,0,,0,
1524100752.612,,0.000000e+000,3.299785e+001,-1.798945e-004,0.000000e+000,3,9.927589e-001,0.000000e+000,,,,,,,,,,,,,,32,1,4.000000e+000,6.904602e-004,0.000000e+000,0,,0,
1524100790.466,,0.000000e+000,3.299957e+001,-1.808382e-004,0.000000e+000,3,9.926779e-001,0.000000e+000,,,,,,,,,,,,,,32,1,4.000000e+000,2.758026e-003,0.000000e+000,0,,0,
1524100828.434,,0.000000e+000,3.299785e+001,-1.815865e-004,0.000000e+000,3,9.924179e-001,0.000000e+000,,,,,,,,,,,,,,32,1,4.000000e+000,6.904602e-004,0.000000e+000,0,,0,
1524100867.279,,0.000000e+000,3.299819e+001,-1.822691e-004,0.000000e+000,3,9.928568e-001,0.000000e+000,,,,,,,,,,,,,,32,1,4.000000e+000,0.000000e+000,0.000000e+000,0,,0,
1524100904.472,,0.000000e+000,3.299854e+001,-1.829536e-004,0.000000e+000,3,9.927993e-001,0.000000e+000,,,,,,,,,,,,,,32,1,4.000000e+000,2.067566e-003,0.000000e+000,0,,0,
1524100942.975,,0.000000e+000,3.299750e+001,-1.834267e-004,0.000000e+000,3,9.928514e-001,0.000000e+000,,,,,,,,,,,,,,32,1,4.000000e+000,1.392365e-003,0.000000e+000,0,,0,
1524100981.043,,0.000000e+000,3.299785e+001,-1.839590e-004,0.000000e+000,3,9.927943e-001,0.000000e+000,,,,,,,,,,,,,,32,1,4.000000e+000,6.904602e-004,0.000000e+000,0,,0,
1524101017.786,,0.000000e+000,3.299819e+001,-1.843725e-004,0.000000e+000,3,9.926383e-001,0.000000e+000,,,,,,,,,,,,,,32,1,4.000000e+000,1.377106e-003,0.000000e+000,0,,0,
1524101056.082,,0.000000e+000,3.299922e+001,-1.847153e-004,0.000000e+000,3,9.926169e-001,0.000000e+000,,,,,,,,,,,,,,32,1,4.000000e+000,6.904602e-004,0.000000e+000,0,,0,
1524101094.640,,0.000000e+000,3.299750e+001,-1.851192e-004,0.000000e+000,3,9.926625e-001,0.000000e+000,,,,,,,,,,,,,,32,1,4.000000e+000,2.758026e-003,0.000000e+000,0,,0,
1524101132.556,,0.000000e+000,3.299785e+001,-1.854685e-004,0.000000e+000,3,9.927856e-001,0.000000e+000,,,,,,,,,,,,,,32,1,4.000000e+000,6.904602e-004,0.000000e+000,0,,0,
1524101170.869,,0.000000e+000,3.299785e+001,-1.857891e-004,0.000000e+000,3,9.929671e-001,0.000000e+000,,,,,,,,,,,,,,32,1,4.000000e+000,6.904602e-004,0.000000e+000,0,,0,
1524101208.464,,0.000000e+000,3.299784e+001,-1.861669e-004,0.000000e+000,3,9.926109e-001,0.000000e+000,,,,,,,,,,,,,,32,1,4.000000e+000,2.079010e-003,0.000000e+000,0,,0,
1524101245.750,,0.000000e+000,3.299957e+001,-1.864375e-004,0.000000e+000,3,9.927171e-001,0.000000e+000,,,,,,,,,,,,,,32,1,4.000000e+000,2.758026e-003,0.000000e+000,0,,0,
1524101283.033,,0.000000e+000,3.299819e+001,-1.866895e-004,0.000000e+000,3,9.928836e-001,0.000000e+000,,,,,,,,,,,,,,32,1,4.000000e+000,1.377106e-003,0.000000e+000,0,,0,
1524101321.086,,0.000000e+000,3.299750e+001,-1.869518e-004,0.000000e+000,3,9.927934e-001,0.000000e+000,,,,,,,,,,,,,,32,1,4.000000e+000,1.392365e-003,0.000000e+000,0,,0,
1524101359.471,,0.000000e+000,3.299992e+001,-1.871963e-004,0.000000e+000,3,9.927862e-001,0.000000e+000,,,,,,,,,,,,,,32,1,4.000000e+000,3.459930e-003,0.000000e+000,0,,0,
1524101396.774,,0.000000e+000,3.299750e+001,-1.874531e-004,0.000000e+000,3,9.925742e-001,0.000000e+000,,,,,,,,,,,,,,32,1,4.000000e+000,1.392365e-003,0.000000e+000,0,,0,
1524101434.550,,0.000000e+000,3.299750e+001,-1.876446e-004,0.000000e+000,3,9.929309e-001,0.000000e+000,,,,,,,,,,,,,,32,1,4.000000e+000,1.392365e-003,0.000000e+000,0,,0,
1524101471.446,,0.000000e+000,3.299819e+001,-1.878084e-004,0.000000e+000,3,9.929828e-001,0.000000e+000,,,,,,,,,,,,,,32,1,4.000000e+000,0.000000e+000,0.000000e+000,0,,0,
1524101508.549,,0.000000e+000,3.299819e+001,-1.881289e-004,0.000000e+000,3,9.927607e-001,0.000000e+000,,,,,,,,,,,,,,32,1,4.000000e+000,1.377106e-003,0.000000e+000,0,,0,
1524101546.439,,0.000000e+000,3.299992e+001,-1.883262e-004,0.000000e+000,3,9.930506e-001,0.000000e+000,,,,,,,,,,,,,,32,1,4.000000e+000,2.071381e-003,0.000000e+000,0,,0,
1524101585.202,,0.000000e+000,3.299819e+001,-1.885220e-004,0.000000e+000,3,9.928912e-001,0.000000e+000,,,,,,,,,,,,,,32,1,4.000000e+000,1.377106e-003,0.000000e+000,0,,0,
1524101623.420,,0.000000e+000,3.299854e+001,-1.887020e-004,0.000000e+000,3,9.929294e-001,0.000000e+000,,,,,,,,,,,,,,32,1,4.000000e+000,6.866455e-004,0.000000e+000,0,,0,
1524101660.558,,0.000000e+000,3.299854e+001,-1.888752e-004,0.000000e+000,3,9.925877e-001,0.000000e+000,,,,,,,,,,,,,,32,1,4.000000e+000,6.866455e-004,0.000000e+000,0,,0,
1524101698.969,,0.000000e+000,3.299854e+001,-1.890501e-004,0.000000e+000,3,9.926851e-001,0.000000e+000,,,,,,,,,,,,,,32,1,4.000000e+000,6.866455e-004,0.000000e+000,0,,0,
1524101736.117,,0.000000e+000,3.299715e+001,-1.892609e-004,0.000000e+000,3,9.927892e-001,0.000000e+000,,,,,,,,,,,,,,32,1,4.000000e+000,7.019043e-004,0.000000e+000,0,,0,
1524101773.465,,0.000000e+000,3.299750e+001,-1.894559e-004,0.000000e+000,3,9.928191e-001,0.000000e+000,,,,,,,,,,,,,,32,1,4.000000e+000,2.758026e-003,0.000000e+000,0,,0,
1524101811.221,,0.000000e+000,3.299854e+001,-1.895672e-004,0.000000e+000,3,9.928538e-001,0.000000e+000,,,,,,,,,,,,,,32,1,4.000000e+000,6.866455e-004,0.000000e+000,0,,0,
1524101848.539,,0.000000e+000,3.299888e+001,-1.896706e-004,0.000000e+000,3,9.927285e-001,0.000000e+000,,,,,,,,,,,,,,32,1,4.000000e+000,0.000000e+000,0.000000e+000,0,,0,
1524101886.384,,0.000000e+000,3.299715e+001,-1.898088e-004,0.000000e+000,3,9.926948e-001,0.000000e+000,,,,,,,,,,,,,,32,1,4.000000e+000,2.071381e-003,0.000000e+000,0,,0,
1524101924.232,,0.000000e+000,3.299888e+001,-1.899756e-004,0.000000e+000,3,9.930243e-001,0.000000e+000,,,,,,,,,,,,,,32,1,4.000000e+000,0.000000e+000,0.000000e+000,0,,0,
1524101962.770,,0.000000e+000,3.299923e+001,-1.901443e-004,0.000000e+000,3,9.927126e-001,0.000000e+000,,,,,,,,,,,,,,32,1,4.000000e+000,2.067566e-003,0.000000e+000,0,,0,
1524102001.068,,0.000000e+000,3.299715e+001,-1.903367e-004,0.000000e+000,3,9.927920e-001,0.000000e+000,,,,,,,,,,,,,,32,1,4.000000e+000,3.459930e-003,0.000000e+000,0,,0,
1524102039.351,,0.000000e+000,3.299854e+001,-1.903816e-004,0.000000e+000,3,9.928446e-001,0.000000e+000,,,,,,,,,,,,,,32,1,4.000000e+000,6.866455e-004,0.000000e+000,0,,0,
1524102077.339,,0.000000e+000,3.299785e+001,-1.905425e-004,0.000000e+000,3,9.929138e-001,0.000000e+000,,,,,,,,,,,,,,32,1,4.000000e+000,6.904602e-004,0.000000e+000,0,,0,
1524102114.742,,0.000000e+000,3.299785e+001,-1.906522e-004,0.000000e+000,3,9.929752e-001,0.000000e+000,,,,,,,,,,,,,,32,1,4.000000e+000,6.904602e-004,0.000000e+000,0,,0,
1524102152.383,,0.000000e+000,3.299819e+001,-1.908530e-004,0.000000e+000,3,9.928962e-001,0.000000e+000,,,,,,,,,,,,,,32,1,4.000000e+000,0.000000e+000,0.000000e+000,0,,0,
1524102189.791,,0.000000e+000,3.299888e+001,-1.908766e-004,0.000000e+000,3,9.929764e-001,0.000000e+000,,,,,,,,,,,,,,32,1,4.000000e+000,0.000000e+000,0.000000e+000,0,,0,
1524102226.729,,0.000000e+000,3.299784e+001,-1.910414e-004,0.000000e+000,3,9.927241e-001,0.000000e+000,,,,,,,,,,,,,,32,1,4.000000e+000,2.079010e-003,0.000000e+000,0,,0,
1524102264.787,,0.000000e+000,3.299819e+001,-1.911504e-004,0.000000e+000,3,9.930040e-001,0.000000e+000,,,,,,,,,,,,,,32,1,4.000000e+000,1.377106e-003,0.000000e+000,0,,0,
1524102301.723,,0.000000e+000,3.299680e+001,-1.912587e-004,0.000000e+000,3,9.928104e-001,0.000000e+000,,,,,,,,,,,,,,32,1,4.000000e+000,0.000000e+000,0.000000e+000,0,,0,
1524102339.988,,0.000000e+000,3.299819e+001,-1.913861e-004,0.000000e+000,3,9.930100e-001,0.000000e+000,,,,,,,,,,,,,,32,1,4.000000e+000,0.000000e+000,0.000000e+000,0,,0,
1524102378.656,,0.000000e+000,3.299923e+001,-1.915051e-004,0.000000e+000,3,9.930580e-001,0.000000e+000,,,,,,,,,,,,,,32,1,4.000000e+000,2.067566e-003,0.000000e+000,0,,0,
1524102417.309,,0.000000e+000,3.299957e+001,-1.916501e-004,0.000000e+000,3,9.929343e-001,0.000000e+000,,,,,,,,,,,,,,32,1,4.000000e+000,0.000000e+000,0.000000e+000,0,,0,
1524102454.500,,0.000000e+000,3.299819e+001,-1.917077e-004,0.000000e+000,3,9.928653e-001,0.000000e+000,,,,,,,,,,,,,,32,1,4.000000e+000,0.000000e+000,0.000000e+000,0,,0,
1524102492.371,,0.000000e+000,3.299854e+001,-1.919016e-004,0.000000e+000,3,9.930857e-001,0.000000e+000,,,,,,,,,,,,,,32,1,4.000000e+000,6.866455e-004,0.000000e+000,0,,0,
1524102529.489,,0.000000e+000,3.299957e+001,-1.919146e-004,0.000000e+000,3,9.928430e-001,0.000000e+000,,,,,,,,,,,,,,32,1,4.000000e+000,1.380920e-003,0.000000e+000,0,,0,
1524102592.622,,0.000000e+000,3.299819e+001,-1.920571e-004,0.000000e+000,3,9.927198e-001,0.000000e+000,,,,,,,,,,,,,,32,1,4.000000e+000,0.000000e+000,0.000000e+000,0,,0,
1524102629.943,,0.000000e+000,3.299715e+001,-1.921204e-004,0.000000e+000,3,9.928508e-001,0.000000e+000,,,,,,,,,,,,,,32,1,4.000000e+000,7.019043e-004,0.000000e+000,0,,0,
1524102667.361,,0.000000e+000,3.299992e+001,-1.922461e-004,0.000000e+000,3,9.928408e-001,0.000000e+000,,,,,,,,,,,,,,32,1,4.000000e+000,6.904602e-004,0.000000e+000,0,,0,
1524102705.104,,0.000000e+000,3.299992e+001,-1.923468e-004,0.000000e+000,3,9.928917e-001,0.000000e+000,,,,,,,,,,,,,,32,1,4.000000e+000,2.071381e-003,0.000000e+000,0,,0,
1524102742.244,,0.000000e+000,3.299922e+001,-1.924264e-004,0.000000e+000,3,9.929289e-001,0.000000e+000,,,,,,,,,,,,,,32,1,4.000000e+000,6.904602e-004,0.000000e+000,0,,0,
1524102779.677,,0.000000e+000,3.299922e+001,-1.925220e-004,0.000000e+000,3,9.929811e-001,0.000000e+000,,,,,,,,,,,,,,32,1,4.000000e+000,6.904602e-004,0.000000e+000,0,,0,
1524102817.065,,0.000000e+000,3.299922e+001,-1.926095e-004,0.000000e+000,3,9.930518e-001,0.000000e+000,,,,,,,,,,,,,,32,1,4.000000e+000,6.904602e-004,0.000000e+000,0,,0,
1524102855.941,,0.000000e+000,3.299680e+001,-1.926594e-004,0.000000e+000,3,9.931210e-001,0.000000e+000,,,,,,,,,,,,,,32,1,4.000000e+000,5.527496e-003,0.000000e+000,0,,0,
1524102894.804,,0.000000e+000,3.300095e+001,-1.927551e-004,0.000000e+000,3,9.930470e-001,0.000000e+000,,,,,,,,,,,,,,32,1,4.000000e+000,4.150391e-003,0.000000e+000,0,,0,
1524102933.484,,0.000000e+000,3.299819e+001,-1.929067e-004,0.000000e+000,3,9.927915e-001,0.000000e+000,,,,,,,,,,,,,,32,1,4.000000e+000,1.377106e-003,0.000000e+000,0,,0,
1524102970.635,,0.000000e+000,3.299888e+001,-1.929669e-004,0.000000e+000,3,9.928721e-001,0.000000e+000,,,,,,,,,,,,,,32,1,4.000000e+000,0.000000e+000,0.000000e+000,0,,0,
1524103008.046,,0.000000e+000,3.299888e+001,-1.930596e-004,0.000000e+000,3,9.927199e-001,0.000000e+000,,,,,,,,,,,,,,32,1,4.000000e+000,0.000000e+000,0.000000e+000,0,,0,
1524103046.009,,0.000000e+000,3.300130e+001,-1.931047e-004,0.000000e+000,3,9.930375e-001,0.000000e+000,,,,,,,,,,,,,,32,1,4.000000e+000,2.079010e-003,0.000000e+000,0,,0,
1524103084.682,,0.000000e+000,3.299922e+001,-1.932288e-004,0.000000e+000,3,9.930029e-001,0.000000e+000,,,,,,,,,,,,,,32,1,4.000000e+000,6.904602e-004,0.000000e+000,0,,0,
1524103121.805,,0.000000e+000,3.299784e+001,-1.933121e-004,0.000000e+000,3,9.928066e-001,0.000000e+000,,,,,,,,,,,,,,32,1,4.000000e+000,2.079010e-003,0.000000e+000,0,,0,
1524103160.220,,0.000000e+000,3.299577e+001,-1.933765e-004,0.000000e+000,3,9.930341e-001,0.000000e+000,,,,,,,,,,,,,,32,1,4.000000e+000,4.840851e-003,0.000000e+000,0,,0,
1524103196.808,,0.000000e+000,3.299922e+001,-1.934770e-004,0.000000e+000,3,9.928796e-001,0.000000e+000,,,,,,,,,,,,,,32,1,4.000000e+000,6.904602e-004,0.000000e+000,0,,0,
1524103234.959,,0.000000e+000,3.299854e+001,-1.935374e-004,0.000000e+000,3,9.928444e-001,0.000000e+000,,,,,,,,,,,,,,32,1,4.000000e+000,6.866455e-004,0.000000e+000,0,,0,
1524103273.592,,0.000000e+000,3.299888e+001,-1.935768e-004,0.000000e+000,3,9.929792e-001,0.000000e+000,,,,,,,,,,,,,,32,1,4.000000e+000,1.377106e-003,0.000000e+000,0,,0,
1524103311.898,,0.000000e+000,3.299888e+001,-1.936525e-004,0.000000e+000,3,9.928041e-001,0.000000e+000,,,,,,,,,,,,,,32,1,4.000000e+000,0.000000e+000,0.000000e+000,0,,0,
1524103349.326,,0.000000e+000,3.299888e+001,-1.937508e-004,0.000000e+000,3,9.929711e-001,0.000000e+000,,,,,,,,,,,,,,32,1,4.000000e+000,0.000000e+000,0.000000e+000,0,,0,
1524103386.734,,0.000000e+000,3.299819e+001,-1.938002e-004,0.000000e+000,3,9.931542e-001,0.000000e+000,,,,,,,,,,,,,,32,1,4.000000e+000,0.000000e+000,0.000000e+000,0,,0,
1524103423.687,,0.000000e+000,3.299819e+001,-1.938913e-004,0.000000e+000,3,9.927663e-001,0.000000e+000,,,,,,,,,,,,,,32,1,4.000000e+000,0.000000e+000,0.000000e+000,0,,0,
1524103461.070,,0.000000e+000,3.299957e+001,-1.939768e-004,0.000000e+000,3,9.927874e-001,0.000000e+000,,,,,,,,,,,,,,32,1,4.000000e+000,1.380920e-003,0.000000e+000,0,,0,
1524103498.840,,0.000000e+000,3.299818e+001,-1.939734e-004,0.000000e+000,3,9.927477e-001,0.000000e+000,,,,,,,,,,,,,,32,1,4.000000e+000,2.769470e-003,0.000000e+000,0,,0,
1524103536.136,,0.000000e+000,3.299922e+001,-1.941052e-004,0.000000e+000,3,9.929364e-001,0.000000e+000,,,,,,,,,,,,,,32,1,4.000000e+000,6.904602e-004,0.000000e+000,0,,0,
1524103573.796,,0.000000e+000,3.300061e+001,-1.941587e-004,0.000000e+000,3,9.929959e-001,0.000000e+000,,,,,,,,,,,,,,32,1,4.000000e+000,2.082825e-003,0.000000e+000,0,,0,
1524103612.372,,0.000000e+000,3.299854e+001,-1.942279e-004,0.000000e+000,3,9.929774e-001,0.000000e+000,,,,,,,,,,,,,,32,1,4.000000e+000,6.866455e-004,0.000000e+000,0,,0,
1524103650.912,,0.000000e+000,3.299785e+001,-1.942658e-004,0.000000e+000,3,9.927784e-001,0.000000e+000,,,,,,,,,,,,,,32,1,4.000000e+000,6.904602e-004,0.000000e+000,0,,0,
1524103688.413,,0.000000e+000,3.299922e+001,-1.943647e-004,0.000000e+000,3,9.928803e-001,0.000000e+000,,,,,,,,,,,,,,32,1,4.000000e+000,6.904602e-004,0.000000e+000,0,,0,
1524103725.919,,0.000000e+000,3.299992e+001,-1.944313e-004,0.000000e+000,3,9.929129e-001,0.000000e+000,,,,,,,,,,,,,,32,1,4.000000e+000,6.904602e-004,0.000000e+000,0,,0,
1524103764.022,,0.000000e+000,3.300061e+001,-1.945338e-004,0.000000e+000,3,9.930713e-001,0.000000e+000,,,,,,,,,,,,,,32,1,4.000000e+000,4.837036e-003,0.000000e+000,0,,0,
1524103802.147,,0.000000e+000,3.299819e+001,-1.945518e-004,0.000000e+000,3,9.929895e-001,0.000000e+000,,,,,,,,,,,,,,32,1,4.000000e+000,1.377106e-003,0.000000e+000,0,,0,
1524103841.220,,0.000000e+000,3.299750e+001,-1.946049e-004,0.000000e+000,3,9.929238e-001,0.000000e+000,,,,,,,,,,,,,,32,1,4.000000e+000,2.758026e-003,0.000000e+000,0,,0,
1524103879.416,,0.000000e+000,3.300130e+001,-1.946502e-004,0.000000e+000,3,9.928942e-001,0.000000e+000,,,,,,,,,,,,,,32,1,4.000000e+000,7.019043e-004,0.000000e+000,0,,0,
1524103916.836,,0.000000e+000,3.299854e+001,-1.947468e-004,0.000000e+000,3,9.928952e-001,0.000000e+000,,,,,,,,,,,,,,32,1,4.000000e+000,6.866455e-004,0.000000e+000,0,,0,
1524103954.222,,0.000000e+000,3.299957e+001,-1.947873e-004,0.000000e+000,3,9.931412e-001,0.000000e+000,,,,,,,,,,,,,,32,1,4.000000e+000,0.000000e+000,0.000000e+000,0,,0,
1524103991.833,,0.000000e+000,3.299922e+001,-1.948806e-004,0.000000e+000,3,9.929344e-001,0.000000e+000,,,,,,,,,,,,,,32,1,4.000000e+000,6.904602e-004,0.000000e+000,0,,0,
1524104029.946,,0.000000e+000,3.299957e+001,-1.948974e-004,0.000000e+000,3,9.928922e-001,0.000000e+000,,,,,,,,,,,,,,32,1,4.000000e+000,0.000000e+000,0.000000e+000,0,,0,
1524104067.521,,0.000000e+000,3.299888e+001,-1.949827e-004,0.000000e+000,3,9.929824e-001,0.000000e+000,,,,,,,,,,,,,,32,1,4.000000e+000,0.000000e+000,0.000000e+000,0,,0,
1524104105.067,,0.000000e+000,3.299888e+001,-1.949980e-004,0.000000e+000,3,9.927517e-001,0.000000e+000,,,,,,,,,,,,,,32,1,4.000000e+000,0.000000e+000,0.000000e+000,0,,0,
1524104143.217,,0.000000e+000,3.299922e+001,-1.950656e-004,0.000000e+000,3,9.930606e-001,0.000000e+000,,,,,,,,,,,,,,32,1,4.000000e+000,6.904602e-004,0.000000e+000,0,,0,
1524104181.885,,0.000000e+000,3.299922e+001,-1.951699e-004,0.000000e+000,3,9.930850e-001,0.000000e+000,,,,,,,,,,,,,,32,1,4.000000e+000,6.904602e-004,0.000000e+000,0,,0,
1524104218.816,,0.000000e+000,3.299922e+001,-1.951989e-004,0.000000e+000,3,9.929200e-001,0.000000e+000,,,,,,,,,,,,,,32,1,4.000000e+000,6.904602e-004,0.000000e+000,0,,0,
1524104257.484,,0.000000e+000,3.299888e+001,-1.952880e-004,0.000000e+000,3,9.928187e-001,0.000000e+000,,,,,,,,,,,,,,32,1,4.000000e+000,0.000000e+000,0.000000e+000,0,,0,
1524104294.667,,0.000000e+000,3.299922e+001,-1.953187e-004,0.000000e+000,3,9.928512e-001,0.000000e+000,,,,,,,,,,,,,,32,1,4.000000e+000,6.904602e-004,0.000000e+000,0,,0,
1524104333.305,,0.000000e+000,3.300095e+001,-1.953458e-004,0.000000e+000,3,9.930105e-001,0.000000e+000,,,,,,,,,,,,,,32,1,4.000000e+000,4.150391e-003,0.000000e+000,0,,0,
1524104370.288,,0.000000e+000,3.299957e+001,-1.954706e-004,0.000000e+000,3,9.928647e-001,0.000000e+000,,,,,,,,,,,,,,32,1,4.000000e+000,2.758026e-003,0.000000e+000,0,,0,
1524104408.246,,0.000000e+000,3.299819e+001,-1.955045e-004,0.000000e+000,3,9.930623e-001,0.000000e+000,,,,,,,,,,,,,,32,1,4.000000e+000,1.377106e-003,0.000000e+000,0,,0,
1524104446.679,,0.000000e+000,3.299922e+001,-1.955669e-004,0.000000e+000,3,9.932088e-001,0.000000e+000,,,,,,,,,,,,,,32,1,4.000000e+000,6.904602e-004,0.000000e+000,0,,0,
1524104485.347,,0.000000e+000,3.299922e+001,-1.956316e-004,0.000000e+000,3,9.929934e-001,0.000000e+000,,,,,,,,,,,,,,32,1,4.000000e+000,6.904602e-004,0.000000e+000,0,,0,
1524104522.480,,0.000000e+000,3.299957e+001,-1.956824e-004,0.000000e+000,3,9.928200e-001,0.000000e+000,,,,,,,,,,,,,,32,1,4.000000e+000,1.380920e-003,0.000000e+000,0,,0,
1524104561.343,,0.000000e+000,3.299957e+001,-1.957030e-004,0.000000e+000,3,9.930548e-001,0.000000e+000,,,,,,,,,,,,,,32,1,4.000000e+000,2.758026e-003,0.000000e+000,0,,0,
1524104599.906,,0.000000e+000,3.299922e+001,-1.958004e-004,0.000000e+000,3,9.927490e-001,0.000000e+000,,,,,,,,,,,,,,32,1,4.000000e+000,6.904602e-004,0.000000e+000,0,,0,
1524104638.042,,0.000000e+000,3.299888e+001,-1.958560e-004,0.000000e+000,3,9.929214e-001,0.000000e+000,,,,,,,,,,,,,,32,1,4.000000e+000,0.000000e+000,0.000000e+000,0,,0,
1524104674.818,,0.000000e+000,3.299888e+001,-1.958746e-004,0.000000e+000,3,9.928362e-001,0.000000e+000,,,,,,,,,,,,,,32,1,4.000000e+000,0.000000e+000,0.000000e+000,0,,0,
1524104713.026,,0.000000e+000,3.299888e+001,-1.958777e-004,0.000000e+000,3,9.928797e-001,0.000000e+000,,,,,,,,,,,,,,32,1,4.000000e+000,0.000000e+000,0.000000e+000,0,,0,
1524104751.324,,0.000000e+000,3.299923e+001,-1.959460e-004,0.000000e+000,3,9.929338e-001,0.000000e+000,,,,,,,,,,,,,,32,1,4.000000e+000,2.067566e-003,0.000000e+000,0,,0,
1524104789.069,,0.000000e+000,3.299785e+001,-1.960365e-004,0.000000e+000,3,9.930188e-001,0.000000e+000,,,,,,,,,,,,,,32,1,4.000000e+000,6.904602e-004,0.000000e+000,0,,0,
1524104827.965,,0.000000e+000,3.299922e+001,-1.960985e-004,0.000000e+000,3,9.927927e-001,0.000000e+000,,,,,,,,,,,,,,32,1,4.000000e+000,6.904602e-004,0.000000e+000,0,,0,
1524104866.800,,0.000000e+000,3.299992e+001,-1.960882e-004,0.000000e+000,3,9.931766e-001,0.000000e+000,,,,,,,,,,,,,,32,1,4.000000e+000,2.071381e-003,0.000000e+000,0,,0,
1524104903.873,,0.000000e+000,3.299819e+001,-1.961649e-004,0.000000e+000,3,9.928274e-001,0.000000e+000,,,,,,,,,,,,,,32,1,4.000000e+000,1.377106e-003,0.000000e+000,0,,0,
1524104941.881,,0.000000e+000,3.299888e+001,-1.962104e-004,0.000000e+000,3,9.929917e-001,0.000000e+000,,,,,,,,,,,,,,32,1,4.000000e+000,0.000000e+000,0.000000e+000,0,,0,
1524104979.734,,0.000000e+000,3.299888e+001,-1.962596e-004,0.000000e+000,3,9.929873e-001,0.000000e+000,,,,,,,,,,,,,,32,1,4.000000e+000,1.377106e-003,0.000000e+000,0,,0,
1524105017.528,,0.000000e+000,3.299854e+001,-1.963093e-004,0.000000e+000,3,9.929257e-001,0.000000e+000,,,,,,,,,,,,,,32,1,4.000000e+000,6.866455e-004,0.000000e+000,0,,0,
1524105054.736,,0.000000e+000,3.299922e+001,-1.963323e-004,0.000000e+000,3,9.931089e-001,0.000000e+000,,,,,,,,,,,,,,32,1,4.000000e+000,6.904602e-004,0.000000e+000,0,,0,
1524105092.384,,0.000000e+000,3.299957e+001,-1.964045e-004,0.000000e+000,3,9.928860e-001,0.000000e+000,,,,,,,,,,,,,,32,1,4.000000e+000,0.000000e+000,0.000000e+000,0,,0,
1524105129.654,,0.000000e+000,3.299577e+001,-1.964572e-004,0.000000e+000,3,9.930158e-001,0.000000e+000,,,,,,,,,,,,,,32,1,4.000000e+000,4.840851e-003,0.000000e+000,0,,0,
1524105167.690,,0.000000e+000,3.299888e+001,-1.965093e-004,0.000000e+000,3,9.929405e-001,0.000000e+000,,,,,,,,,,,,,,32,1,4.000000e+000,1.377106e-003,0.000000e+000,0,,0,
1524105205.135,,0.000000e+000,3.299785e+001,-1.965542e-004,0.000000e+000,3,9.928732e-001,0.000000e+000,,,,,,,,,,,,,,32,1,4.000000e+000,6.904602e-004,0.000000e+000,0,,0,
1524105243.113,,0.000000e+000,3.299957e+001,-1.965261e-004,0.000000e+000,3,9.928714e-001,0.000000e+000,,,,,,,,,,,,,,32,1,4.000000e+000,0.000000e+000,0.000000e+000,0,,0,
1524105281.356,,0.000000e+000,3.299888e+001,-1.966243e-004,0.000000e+000,3,9.930545e-001,0.000000e+000,,,,,,,,,,,,,,32,1,4.000000e+000,0.000000e+000,0.000000e+000,0,,0,
1524105318.289,,0.000000e+000,3.299854e+001,-1.966425e-004,0.000000e+000,3,9.930516e-001,0.000000e+000,,,,,,,,,,,,,,32,1,4.000000e+000,6.866455e-004,0.000000e+000,0,,0,
1524105355.910,,0.000000e+000,3.299922e+001,-1.967325e-004,0.000000e+000,3,9.927823e-001,0.000000e+000,,,,,,,,,,,,,,32,1,4.000000e+000,6.904602e-004,0.000000e+000,0,,0,
1524105393.901,,0.000000e+000,3.299680e+001,-1.967041e-004,0.000000e+000,3,9.931144e-001,0.000000e+000,,,,,,,,,,,,,,32,1,4.000000e+000,4.146576e-003,0.000000e+000,0,,0,
1524105432.456,,0.000000e+000,3.299784e+001,-1.968052e-004,0.000000e+000,3,9.928265e-001,0.000000e+000,,,,,,,,,,,,,,32,1,4.000000e+000,2.079010e-003,0.000000e+000,0,,0,
1524105471.139,,0.000000e+000,3.299957e+001,-1.968023e-004,0.000000e+000,3,9.930611e-001,0.000000e+000,,,,,,,,,,,,,,32,1,4.000000e+000,0.000000e+000,0.000000e+000,0,,0,
1524105508.967,,0.000000e+000,3.299854e+001,-1.968475e-004,0.000000e+000,3,9.932273e-001,0.000000e+000,,,,,,,,,,,,,,32,1,4.000000e+000,6.866455e-004,0.000000e+000,0,,0,
1524105547.303,,0.000000e+000,3.299992e+001,-1.968724e-004,0.000000e+000,3,9.930516e-001,0.000000e+000,,,,,,,,,,,,,,32,1,4.000000e+000,6.904602e-004,0.000000e+000,0,,0,
1524105585.633,,0.000000e+000,3.299854e+001,-1.969564e-004,0.000000e+000,3,9.930826e-001,0.000000e+000,,,,,,,,,,,,,,32,1,4.000000e+000,2.067566e-003,0.000000e+000,0,,0,
1524105624.154,,0.000000e+000,3.299957e+001,-1.969660e-004,0.000000e+000,3,9.929984e-001,0.000000e+000,,,,,,,,,,,,,,32,1,4.000000e+000,0.000000e+000,0.000000e+000,0,,0,
1524105662.322,,0.000000e+000,3.299888e+001,-1.970152e-004,0.000000e+000,3,9.931344e-001,0.000000e+000,,,,,,,,,,,,,,32,1,4.000000e+000,1.377106e-003,0.000000e+000,0,,0,
1524105699.945,,0.000000e+000,3.299854e+001,-1.970170e-004,0.000000e+000,3,9.928234e-001,0.000000e+000,,,,,,,,,,,,,,32,1,4.000000e+000,6.866455e-004,0.000000e+000,0,,0,
1524105737.733,,0.000000e+000,3.299957e+001,-1.970887e-004,0.000000e+000,3,9.929327e-001,0.000000e+000,,,,,,,,,,,,,,32,1,4.000000e+000,1.380920e-003,0.000000e+000,0,,0,
1524105774.664,,0.000000e+000,3.299957e+001,-1.971285e-004,0.000000e+000,3,9.932356e-001,0.000000e+000,,,,,,,,,,,,,,32,1,4.000000e+000,0.000000e+000,0.000000e+000,0,,0,
1524105812.324,,0.000000e+000,3.299922e+001,-1.972374e-004,0.000000e+000,3,9.928650e-001,0.000000e+000,,,,,,,,,,,,,,32,1,4.000000e+000,6.904602e-004,0.000000e+000,0,,0,
1524105850.270,,0.000000e+000,3.299923e+001,-1.971980e-004,0.000000e+000,3,9.930369e-001,0.000000e+000,,,,,,,,,,,,,,32,1,4.000000e+000,2.067566e-003,0.000000e+000,0,,0,
1524105887.415,,0.000000e+000,3.299922e+001,-1.973380e-004,0.000000e+000,3,9.930763e-001,0.000000e+000,,,,,,,,,,,,,,32,1,4.000000e+000,6.904602e-004,0.000000e+000,0,,0,
1524105924.973,,0.000000e+000,3.299922e+001,-1.972836e-004,0.000000e+000,3,9.928625e-001,0.000000e+000,,,,,,,,,,,,,,32,1,4.000000e+000,6.904602e-004,0.000000e+000,0,,0,
1524105963.956,,0.000000e+000,3.299923e+001,-1.973255e-004,0.000000e+000,3,9.929677e-001,0.000000e+000,,,,,,,,,,,,,,32,1,4.000000e+000,2.067566e-003,0.000000e+000,0,,0,
1524106002.442,,0.000000e+000,3.299819e+001,-1.973504e-004,0.000000e+000,3,9.930480e-001,0.000000e+000,,,,,,,,,,,,,,32,1,4.000000e+000,0.000000e+000,0.000000e+000,0,,0,
1524106040.650,,0.000000e+000,3.299888e+001,-1.974158e-004,0.000000e+000,3,9.928454e-001,0.000000e+000,,,,,,,,,,,,,,32,1,4.000000e+000,1.377106e-003,0.000000e+000,0,,0,
1524106078.173,,0.000000e+000,3.299922e+001,-1.974568e-004,0.000000e+000,3,9.929094e-001,0.000000e+000,,,,,,,,,,,,,,32,1,4.000000e+000,6.904602e-004,0.000000e+000,0,,0,
1524106116.274,,0.000000e+000,3.299922e+001,-1.974878e-004,0.000000e+000,3,9.929842e-001,0.000000e+000,,,,,,,,,,,,,,32,1,4.000000e+000,6.904602e-004,0.000000e+000,0,,0,
1524106154.129,,0.000000e+000,3.299888e+001,-1.975548e-004,0.000000e+000,3,9.929342e-001,0.000000e+000,,,,,,,,,,,,,,32,1,4.000000e+000,0.000000e+000,0.000000e+000,0,,0,
1524106192.102,,0.000000e+000,3.299612e+001,-1.975550e-004,0.000000e+000,3,9.931157e-001,0.000000e+000,,,,,,,,,,,,,,32,1,4.000000e+000,4.150391e-003,0.000000e+000,0,,0,
1524106230.978,,0.000000e+000,3.299992e+001,-1.976000e-004,0.000000e+000,3,9.930988e-001,0.000000e+000,,,,,,,,,,,,,,32,1,4.000000e+000,2.071381e-003,0.000000e+000,0,,0,
1524106268.621,,0.000000e+000,3.299957e+001,-1.976675e-004,0.000000e+000,3,9.927776e-001,0.000000e+000,,,,,,,,,,,,,,32,1,4.000000e+000,0.000000e+000,0.000000e+000,0,,0,
1524106306.376,,0.000000e+000,3.299957e+001,-1.976829e-004,0.000000e+000,3,9.929249e-001,0.000000e+000,,,,,,,,,,,,,,32,1,4.000000e+000,1.380920e-003,0.000000e+000,0,,0,
1524106343.302,,0.000000e+000,3.299957e+001,-1.976790e-004,0.000000e+000,3,9.930928e-001,0.000000e+000,,,,,,,,,,,,,,32,1,4.000000e+000,1.380920e-003,0.000000e+000,0,,0,
1524106380.958,,0.000000e+000,3.299888e+001,-1.977987e-004,0.000000e+000,3,9.927989e-001,0.000000e+000,,,,,,,,,,,,,,32,1,4.000000e+000,0.000000e+000,0.000000e+000,0,,0,
1524106418.898,,0.000000e+000,3.300164e+001,-1.977402e-004,0.000000e+000,3,9.931310e-001,0.000000e+000,,,,,,,,,,,,,,32,1,4.000000e+000,5.531311e-003,0.000000e+000,0,,0,
1524106456.026,,0.000000e+000,3.299992e+001,-1.978578e-004,0.000000e+000,3,9.929197e-001,0.000000e+000,,,,,,,,,,,,,,32,1,4.000000e+000,6.904602e-004,0.000000e+000,0,,0,
1524106493.984,,0.000000e+000,3.299957e+001,-1.978239e-004,0.000000e+000,3,9.930013e-001,0.000000e+000,,,,,,,,,,,,,,32,1,4.000000e+000,0.000000e+000,0.000000e+000,0,,0,
1524106532.755,,0.000000e+000,3.299957e+001,-1.978513e-004,0.000000e+000,3,9.930870e-001,0.000000e+000,,,,,,,,,,,,,,32,1,4.000000e+000,0.000000e+000,0.000000e+000,0,,0,
1524106571.198,,0.000000e+000,3.300130e+001,-1.979552e-004,0.000000e+000,3,9.930969e-001,0.000000e+000,,,,,,,,,,,,,,32,1,4.000000e+000,3.459930e-003,0.000000e+000,0,,0,
1524106608.151,,0.000000e+000,3.299854e+001,-1.979671e-004,0.000000e+000,3,9.929770e-001,0.000000e+000,,,,,,,,,,,,,,32,1,4.000000e+000,6.866455e-004,0.000000e+000,0,,0,
1524106646.794,,0.000000e+000,3.300027e+001,-1.980003e-004,0.000000e+000,3,9.931390e-001,0.000000e+000,,,,,,,,,,,,,,32,1,4.000000e+000,2.773285e-003,0.000000e+000,0,,0,
1524106684.490,,0.000000e+000,3.299992e+001,-1.980577e-004,0.000000e+000,3,9.929910e-001,0.000000e+000,,,,,,,,,,,,,,32,1,4.000000e+000,6.904602e-004,0.000000e+000,0,,0,
1524106722.273,,0.000000e+000,3.299854e+001,-1.980947e-004,0.000000e+000,3,9.929307e-001,0.000000e+000,,,,,,,,,,,,,,32,1,4.000000e+000,6.866455e-004,0.000000e+000,0,,0,
1524106759.996,,0.000000e+000,3.299888e+001,-1.981142e-004,0.000000e+000,3,9.929415e-001,0.000000e+000,,,,,,,,,,,,,,32,1,4.000000e+000,0.000000e+000,0.000000e+000,0,,0,
1524106797.114,,0.000000e+000,3.299854e+001,-1.981625e-004,0.000000e+000,3,9.930286e-001,0.000000e+000,,,,,,,,,,,,,,32,1,4.000000e+000,2.067566e-003,0.000000e+000,0,,0,
1524106835.542,,0.000000e+000,3.299888e+001,-1.981808e-004,0.000000e+000,3,9.931126e-001,0.000000e+000,,,,,,,,,,,,,,32,1,4.000000e+000,1.377106e-003,0.000000e+000,0,,0,
1524106872.917,,0.000000e+000,3.299922e+001,-1.982158e-004,0.000000e+000,3,9.929442e-001,0.000000e+000,,,,,,,,,,,,,,32,1,4.000000e+000,6.904602e-004,0.000000e+000,0,,0,
1524106910.578,,0.000000e+000,3.299854e+001,-1.982445e-004,0.000000e+000,3,9.928796e-001,0.000000e+000,,,,,,,,,,,,,,32,1,4.000000e+000,6.866455e-004,0.000000e+000,0,,0,
1524106948.553,,0.000000e+000,3.300164e+001,-1.982822e-004,0.000000e+000,3,9.928755e-001,0.000000e+000,,,,,,,,,,,,,,32,1,4.000000e+000,2.769470e-003,0.000000e+000,0,,0,
1524106986.119,,0.000000e+000,3.299785e+001,-1.983310e-004,0.000000e+000,3,9.929292e-001,0.000000e+000,,,,,,,,,,,,,,32,1,4.000000e+000,6.904602e-004,0.000000e+000,0,,0,
1524107024.279,,0.000000e+000,3.299992e+001,-1.983008e-004,0.000000e+000,3,9.932762e-001,0.000000e+000,,,,,,,,,,,,,,32,1,4.000000e+000,6.904602e-004,0.000000e+000,0,,0,
1524107061.930,,0.000000e+000,3.299992e+001,-1.983762e-004,0.000000e+000,3,9.928039e-001,0.000000e+000,,,,,,,,,,,,,,32,1,4.000000e+000,6.904602e-004,0.000000e+000,0,,0,
1524107099.891,,0.000000e+000,3.299888e+001,-1.983866e-004,0.000000e+000,3,9.930516e-001,0.000000e+000,,,,,,,,,,,,,,32,1,4.000000e+000,0.000000e+000,0.000000e+000,0,,0,
1524107138.424,,0.000000e+000,3.299784e+001,-1.984189e-004,0.000000e+000,3,9.929858e-001,0.000000e+000,,,,,,,,,,,,,,32,1,4.000000e+000,2.079010e-003,0.000000e+000,0,,0,
1524107176.859,,0.000000e+000,3.299922e+001,-1.984794e-004,0.000000e+000,3,9.932202e-001,0.000000e+000,,,,,,,,,,,,,,32,1,4.000000e+000,6.904602e-004,0.000000e+000,0,,0,
1524107213.495,,0.000000e+000,3.299888e+001,-1.984925e-004,0.000000e+000,3,9.929809e-001,0.000000e+000,,,,,,,,,,,,,,32,1,4.000000e+000,0.000000e+000,0.000000e+000,0,,0,
1524107252.038,,0.000000e+000,3.299888e+001,-1.985155e-004,0.000000e+000,3,9.929571e-001,0.000000e+000,,,,,,,,,,,,,,32,1,4.000000e+000,1.377106e-003,0.000000e+000,0,,0,
1524107290.483,,0.000000e+000,3.299854e+001,-1.985616e-004,0.000000e+000,3,9.930832e-001,0.000000e+000,,,,,,,,,,,,,,32,1,4.000000e+000,6.866455e-004,0.000000e+000,0,,0,
1524107328.624,,0.000000e+000,3.299785e+001,-1.985640e-004,0.000000e+000,3,9.931209e-001,0.000000e+000,,,,,,,,,,,,,,32,1,4.000000e+000,6.904602e-004,0.000000e+000,0,,0,
1524107365.572,,0.000000e+000,3.299992e+001,-1.986598e-004,0.000000e+000,3,9.928262e-001,0.000000e+000,,,,,,,,,,,,,,32,1,4.000000e+000,6.904602e-004,0.000000e+000,0,,0,
1524107403.438,,0.000000e+000,3.300026e+001,-1.986510e-004,0.000000e+000,3,9.929370e-001,0.000000e+000,,,,,,,,,,,,,,32,1,4.000000e+000,0.000000e+000,0.000000e+000,0,,0,
1524107440.898,,0.000000e+000,3.299922e+001,-1.986748e-004,0.000000e+000,3,9.929629e-001,0.000000e+000,,,,,,,,,,,,,,32,1,4.000000e+000,6.904602e-004,0.000000e+000,0,,0,
1524107479.141,,0.000000e+000,3.299922e+001,-1.987336e-004,0.000000e+000,3,9.930745e-001,0.000000e+000,,,,,,,,,,,,,,32,1,4.000000e+000,6.904602e-004,0.000000e+000,0,,0,
1524107515.952,,0.000000e+000,3.299854e+001,-1.987436e-004,0.000000e+000,3,9.929737e-001,0.000000e+000,,,,,,,,,,,,,,32,1,4.000000e+000,6.866455e-004,0.000000e+000,0,,0,
1524107554.280,,0.000000e+000,3.299785e+001,-1.987232e-004,0.000000e+000,3,9.929823e-001,0.000000e+000,,,,,,,,,,,,,,32,1,4.000000e+000,6.904602e-004,0.000000e+000,0,,0,
1524107593.148,,0.000000e+000,3.300026e+001,-1.987800e-004,0.000000e+000,3,9.929386e-001,0.000000e+000,,,,,,,,,,,,,,32,1,4.000000e+000,1.380920e-003,0.000000e+000,0,,0,
1524107631.063,,0.000000e+000,3.299922e+001,-1.988352e-004,0.000000e+000,3,9.930918e-001,0.000000e+000,,,,,,,,,,,,,,32,1,4.000000e+000,6.904602e-004,0.000000e+000,0,,0,
1524107667.991,,0.000000e+000,3.299922e+001,-1.988303e-004,0.000000e+000,3,9.930836e-001,0.000000e+000,,,,,,,,,,,,,,32,1,4.000000e+000,6.904602e-004,0.000000e+000,0,,0,
1524107705.617,,0.000000e+000,3.299957e+001,-1.988975e-004,0.000000e+000,3,9.928635e-001,0.000000e+000,,,,,,,,,,,,,,32,1,4.000000e+000,0.000000e+000,0.000000e+000,0,,0,
1524107744.440,,0.000000e+000,3.299888e+001,-1.989616e-004,0.000000e+000,3,9.928957e-001,0.000000e+000,,,,,,,,,,,,,,32,1,4.000000e+000,1.377106e-003,0.000000e+000,0,,0,
1524107781.388,,0.000000e+000,3.299888e+001,-1.989129e-004,0.000000e+000,3,9.930229e-001,0.000000e+000,,,,,,,,,,,,,,32,1,4.000000e+000,0.000000e+000,0.000000e+000,0,,0,
1524107818.356,,0.000000e+000,3.300027e+001,-1.989799e-004,0.000000e+000,3,9.930445e-001,0.000000e+000,,,,,,,,,,,,,,32,1,4.000000e+000,2.773285e-003,0.000000e+000,0,,0,
1524107856.289,,0.000000e+000,3.299888e+001,-1.990237e-004,0.000000e+000,3,9.929021e-001,0.000000e+000,,,,,,,,,,,,,,32,1,4.000000e+000,0.000000e+000,0.000000e+000,0,,0,
1524107893.882,,0.000000e+000,3.299957e+001,-1.990173e-004,0.000000e+000,3,9.928787e-001,0.000000e+000,,,,,,,,,,,,,,32,1,4.000000e+000,1.380920e-003,0.000000e+000,0,,0,
1524107932.033,,0.000000e+000,3.299922e+001,-1.990391e-004,0.000000e+000,3,9.930767e-001,0.000000e+000,,,,,,,,,,,,,,32,1,4.000000e+000,6.904602e-004,0.000000e+000,0,,0,
1524107970.041,,0.000000e+000,3.299854e+001,-1.990754e-004,0.000000e+000,3,9.928591e-001,0.000000e+000,,,,,,,,,,,,,,32,1,4.000000e+000,6.866455e-004,0.000000e+000,0,,0,
1524108007.909,,0.000000e+000,3.299888e+001,-1.991664e-004,0.000000e+000,3,9.930317e-001,0.000000e+000,,,,,,,,,,,,,,32,1,4.000000e+000,1.377106e-003,0.000000e+000,0,,0,
1524108045.882,,0.000000e+000,3.299888e+001,-1.991220e-004,0.000000e+000,3,9.929520e-001,0.000000e+000,,,,,,,,,,,,,,32,1,4.000000e+000,1.377106e-003,0.000000e+000,0,,0,
1524108084.103,,0.000000e+000,3.299888e+001,-1.991698e-004,0.000000e+000,3,9.929094e-001,0.000000e+000,,,,,,,,,,,,,,32,1,4.000000e+000,1.377106e-003,0.000000e+000,0,,0,
1524108121.293,,0.000000e+000,3.299854e+001,-1.992277e-004,0.000000e+000,3,9.929432e-001,0.000000e+000,,,,,,,,,,,,,,32,1,4.000000e+000,6.866455e-004,0.000000e+000,0,,0,
1524108158.936,,0.000000e+000,3.299957e+001,-1.992191e-004,0.000000e+000,3,9.928730e-001,0.000000e+000,,,,,,,,,,,,,,32,1,4.000000e+000,0.000000e+000,0.000000e+000,0,,0,
1524108196.119,,0.000000e+000,3.299992e+001,-1.992478e-004,0.000000e+000,3,9.931254e-001,0.000000e+000,,,,,,,,,,,,,,32,1,4.000000e+000,6.904602e-004,0.000000e+000,0,,0,
1524108233.755,,0.000000e+000,3.299888e+001,-1.992901e-004,0.000000e+000,3,9.929536e-001,0.000000e+000,,,,,,,,,,,,,,32,1,4.000000e+000,1.377106e-003,0.000000e+000,0,,0,
1524108271.520,,0.000000e+000,3.299922e+001,-1.992945e-004,0.000000e+000,3,9.929090e-001,0.000000e+000,,,,,,,,,,,,,,32,1,4.000000e+000,6.904602e-004,0.000000e+000,0,,0,
1524108308.631,,0.000000e+000,3.299992e+001,-1.993434e-004,0.000000e+000,3,9.930521e-001,0.000000e+000,,,,,,,,,,,,,,32,1,4.000000e+000,6.904602e-004,0.000000e+000,0,,0,
1524108346.944,,0.000000e+000,3.299957e+001,-1.992813e-004,0.000000e+000,3,9.928097e-001,0.000000e+000,,,,,,,,,,,,,,32,1,4.000000e+000,1.380920e-003,0.000000e+000,0,,0,
1524108385.149,,0.000000e+000,3.299922e+001,-1.993666e-004,0.000000e+000,3,9.931033e-001,0.000000e+000,,,,,,,,,,,,,,32,1,4.000000e+000,6.904602e-004,0.000000e+000,0,,0,
1524108423.480,,0.000000e+000,3.299922e+001,-1.994082e-004,0.000000e+000,3,9.931230e-001,0.000000e+000,,,,,,,,,,,,,,32,1,4.000000e+000,6.904602e-004,0.000000e+000,0,,0,
1524108461.783,,0.000000e+000,3.299888e+001,-1.994327e-004,0.000000e+000,3,9.929126e-001,0.000000e+000,,,,,,,,,,,,,,32,1,4.000000e+000,1.377106e-003,0.000000e+000,0,,0,
1524108500.374,,0.000000e+000,3.299957e+001,-1.994429e-004,0.000000e+000,3,9.929669e-001,0.000000e+000,,,,,,,,,,,,,,32,1,4.000000e+000,0.000000e+000,0.000000e+000,0,,0,
1524108538.684,,0.000000e+000,3.299888e+001,-1.994391e-004,0.000000e+000,3,9.929700e-001,0.000000e+000,,,,,,,,,,,,,,32,1,4.000000e+000,1.377106e-003,0.000000e+000,0,,0,
1524108577.292,,0.000000e+000,3.299992e+001,-1.995141e-004,0.000000e+000,3,9.930160e-001,0.000000e+000,,,,,,,,,,,,,,32,1,4.000000e+000,6.904602e-004,0.000000e+000,0,,0,
1524108615.483,,0.000000e+000,3.300061e+001,-1.995317e-004,0.000000e+000,3,9.930736e-001,0.000000e+000,,,,,,,,,,,,,,32,1,4.000000e+000,2.082825e-003,0.000000e+000,0,,0,
1524108654.113,,0.000000e+000,3.299819e+001,-1.995226e-004,0.000000e+000,3,9.929668e-001,0.000000e+000,,,,,,,,,,,,,,32,1,4.000000e+000,1.377106e-003,0.000000e+000,0,,0,
1524108692.439,,0.000000e+000,3.300026e+001,-1.995141e-004,0.000000e+000,3,9.930657e-001,0.000000e+000,,,,,,,,,,,,,,32,1,4.000000e+000,1.380920e-003,0.000000e+000,0,,0,
1524108730.072,,0.000000e+000,3.299992e+001,-1.995967e-004,0.000000e+000,3,9.928530e-001,0.000000e+000,,,,,,,,,,,,,,32,1,4.000000e+000,6.904602e-004,0.000000e+000,0,,0,
1524108767.383,,0.000000e+000,3.299922e+001,-1.996411e-004,0.000000e+000,3,9.929215e-001,0.000000e+000,,,,,,,,,,,,,,32,1,4.000000e+000,6.904602e-004,0.000000e+000,0,,0,
1524108804.486,,0.000000e+000,3.299750e+001,-1.996709e-004,0.000000e+000,3,9.928647e-001,0.000000e+000,,,,,,,,,,,,,,32,1,4.000000e+000,0.000000e+000,0.000000e+000,0,,0,
1524108842.834,,0.000000e+000,3.299854e+001,-1.997466e-004,0.000000e+000,3,9.929695e-001,0.000000e+000,,,,,,,,,,,,,,32,1,4.000000e+000,6.866455e-004,0.000000e+000,0,,0,
1524108881.242,,0.000000e+000,3.300027e+001,-1.996807e-004,0.000000e+000,3,9.927932e-001,0.000000e+000,,,,,,,,,,,,,,32,1,4.000000e+000,2.773285e-003,0.000000e+000,0,,0,
1524108918.572,,0.000000e+000,3.299957e+001,-1.997335e-004,0.000000e+000,3,9.928234e-001,0.000000e+000,,,,,,,,,,,,,,32,1,4.000000e+000,1.380920e-003,0.000000e+000,0,,0,
1524108956.333,,0.000000e+000,3.299854e+001,-1.997491e-004,0.000000e+000,3,9.930158e-001,0.000000e+000,,,,,,,,,,,,,,32,1,4.000000e+000,6.866455e-004,0.000000e+000,0,,0,
1524108993.276,,0.000000e+000,3.299922e+001,-1.997651e-004,0.000000e+000,3,9.931831e-001,0.000000e+000,,,,,,,,,,,,,,32,1,4.000000e+000,6.904602e-004,0.000000e+000,0,,0,
1524109031.684,,0.000000e+000,3.299922e+001,-1.998120e-004,0.000000e+000,3,9.930580e-001,0.000000e+000,,,,,,,,,,,,,,32,1,4.000000e+000,6.904602e-004,0.000000e+000,0,,0,
1524109070.227,,0.000000e+000,3.299957e+001,-1.998352e-004,0.000000e+000,3,9.928988e-001,0.000000e+000,,,,,,,,,,,,,,32,1,4.000000e+000,1.380920e-003,0.000000e+000,0,,0,
1524109108.548,,0.000000e+000,3.299819e+001,-1.998796e-004,0.000000e+000,3,9.928290e-001,0.000000e+000,,,,,,,,,,,,,,32,1,4.000000e+000,1.377106e-003,0.000000e+000,0,,0,
1524109146.983,,0.000000e+000,3.299957e+001,-1.998747e-004,0.000000e+000,3,9.930082e-001,0.000000e+000,,,,,,,,,,,,,,32,1,4.000000e+000,0.000000e+000,0.000000e+000,0,,0,
1524109183.924,,0.000000e+000,3.299819e+001,-1.998778e-004,0.000000e+000,3,9.930822e-001,0.000000e+000,,,,,,,,,,,,,,32,1,4.000000e+000,0.000000e+000,0.000000e+000,0,,0,
1524109222.589,,0.000000e+000,3.299957e+001,-1.999493e-004,0.000000e+000,3,9.931507e-001,0.000000e+000,,,,,,,,,,,,,,32,1,4.000000e+000,0.000000e+000,0.000000e+000,0,,0,
1524109259.230,,0.000000e+000,3.299819e+001,-1.999496e-004,0.000000e+000,3,9.929936e-001,0.000000e+000,,,,,,,,,,,,,,32,1,4.000000e+000,1.377106e-003,0.000000e+000,0,,0,
1524109297.658,,0.000000e+000,3.299854e+001,-1.999727e-004,0.000000e+000,3,9.930762e-001,0.000000e+000,,,,,,,,,,,,,,32,1,4.000000e+000,2.067566e-003,0.000000e+000,0,,0,
1524109334.616,,0.000000e+000,3.299957e+001,-1.999589e-004,0.000000e+000,3,9.932277e-001,0.000000e+000,,,,,,,,,,,,,,32,1,4.000000e+000,0.000000e+000,0.000000e+000,0,,0,
1524109372.951,,0.000000e+000,3.299992e+001,-2.000029e-004,0.000000e+000,3,9.931137e-001,0.000000e+000,,,,,,,,,,,,,,32,1,4.000000e+000,6.904602e-004,0.000000e+000,0,,0,
1524109410.780,,0.000000e+000,3.300061e+001,-2.000693e-004,0.000000e+000,3,9.930810e-001,0.000000e+000,,,,,,,,,,,,,,32,1,4.000000e+000,2.082825e-003,0.000000e+000,0,,0,
1524109448.403,,0.000000e+000,3.299854e+001,-2.000791e-004,0.000000e+000,3,9.929637e-001,0.000000e+000,,,,,,,,,,,,,,32,1,4.000000e+000,6.866455e-004,0.000000e+000,0,,0,
1524109486.061,,0.000000e+000,3.300026e+001,-2.001133e-004,0.000000e+000,3,9.929610e-001,0.000000e+000,,,,,,,,,,,,,,32,1,4.000000e+000,0.000000e+000,0.000000e+000,0,,0,
1524109524.224,,0.000000e+000,3.299957e+001,-2.001109e-004,0.000000e+000,3,9.929762e-001,0.000000e+000,,,,,,,,,,,,,,32,1,4.000000e+000,1.380920e-003,0.000000e+000,0,,0,
1524109561.804,,0.000000e+000,3.299957e+001,-2.001301e-004,0.000000e+000,3,9.929776e-001,0.000000e+000,,,,,,,,,,,,,,32,1,4.000000e+000,0.000000e+000,0.000000e+000,0,,0,
1524109599.917,,0.000000e+000,3.299888e+001,-2.000890e-004,0.000000e+000,3,9.928002e-001,0.000000e+000,,,,,,,,,,,,,,32,1,4.000000e+000,0.000000e+000,0.000000e+000,0,,0,
1524109638.215,,0.000000e+000,3.299888e+001,-2.001698e-004,0.000000e+000,3,9.932418e-001,0.000000e+000,,,,,,,,,,,,,,32,1,4.000000e+000,0.000000e+000,0.000000e+000,0,,0,
1524109675.808,,0.000000e+000,3.299957e+001,-2.002163e-004,0.000000e+000,3,9.928228e-001,0.000000e+000,,,,,,,,,,,,,,32,1,4.000000e+000,1.380920e-003,0.000000e+000,0,,0,
1524109713.466,,0.000000e+000,3.299888e+001,-2.002137e-004,0.000000e+000,3,9.929958e-001,0.000000e+000,,,,,,,,,,,,,,32,1,4.000000e+000,0.000000e+000,0.000000e+000,0,,0,
1524109752.844,,0.000000e+000,3.299992e+001,-2.002056e-004,0.000000e+000,3,9.930654e-001,0.000000e+000,,,,,,,,,,,,,,32,1,4.000000e+000,6.904602e-004,0.000000e+000,0,,0,
1524109790.455,,0.000000e+000,3.299957e+001,-2.002288e-004,0.000000e+000,3,9.931951e-001,0.000000e+000,,,,,,,,,,,,,,32,1,4.000000e+000,0.000000e+000,0.000000e+000,0,,0,
1524109828.111,,0.000000e+000,3.299922e+001,-2.003195e-004,0.000000e+000,3,9.928079e-001,0.000000e+000,,,,,,,,,,,,,,32,1,4.000000e+000,6.904602e-004,0.000000e+000,0,,0,
1524109865.391,,0.000000e+000,3.299922e+001,-2.003230e-004,0.000000e+000,3,9.929671e-001,0.000000e+000,,,,,,,,,,,,,,32,1,4.000000e+000,6.904602e-004,0.000000e+000,0,,0,
1524109902.964,,0.000000e+000,3.299992e+001,-2.003318e-004,0.000000e+000,3,9.929717e-001,0.000000e+000,,,,,,,,,,,,,,32,1,4.000000e+000,6.904602e-004,0.000000e+000,0,,0,
1524109940.770,,0.000000e+000,3.299957e+001,-2.003892e-004,0.000000e+000,3,9.928904e-001,0.000000e+000,,,,,,,,,,,,,,32,1,4.000000e+000,0.000000e+000,0.000000e+000,0,,0,
1524109979.873,,0.000000e+000,3.299922e+001,-2.003676e-004,0.000000e+000,3,9.930328e-001,0.000000e+000,,,,,,,,,,,,,,32,1,4.000000e+000,6.904602e-004,0.000000e+000,0,,0,
1524110017.478,,0.000000e+000,3.300061e+001,-2.004338e-004,0.000000e+000,3,9.931217e-001,0.000000e+000,,,,,,,,,,,,,,32,1,4.000000e+000,2.082825e-003,0.000000e+000,0,,0,
1524110055.624,,0.000000e+000,3.300164e+001,-2.004323e-004,0.000000e+000,3,9.932401e-001,0.000000e+000,,,,,,,,,,,,,,32,1,4.000000e+000,5.531311e-003,0.000000e+000,0,,0,
1524110094.220,,0.000000e+000,3.299854e+001,-2.004699e-004,0.000000e+000,3,9.930449e-001,0.000000e+000,,,,,,,,,,,,,,32,1,4.000000e+000,6.866455e-004,0.000000e+000,0,,0,
1524110132.815,,0.000000e+000,3.299922e+001,-2.004529e-004,0.000000e+000,3,9.930320e-001,0.000000e+000,,,,,,,,,,,,,,32,1,4.000000e+000,6.904602e-004,0.000000e+000,0,,0,
1524110171.618,,0.000000e+000,3.299992e+001,-2.004688e-004,0.000000e+000,3,9.929838e-001,0.000000e+000,,,,,,,,,,,,,,32,1,4.000000e+000,6.904602e-004,0.000000e+000,0,,0,
1524110209.226,,0.000000e+000,3.299957e+001,-2.005348e-004,0.000000e+000,3,9.929097e-001,0.000000e+000,,,,,,,,,,,,,,32,1,4.000000e+000,1.380920e-003,0.000000e+000,0,,0,
1524110247.912,,0.000000e+000,3.300164e+001,-2.005274e-004,0.000000e+000,3,9.933138e-001,0.000000e+000,,,,,,,,,,,,,,32,1,4.000000e+000,2.769470e-003,0.000000e+000,0,,0,
1524110286.790,,0.000000e+000,3.299750e+001,-2.005316e-004,0.000000e+000,3,9.930854e-001,0.000000e+000,,,,,,,,,,,,,,32,1,4.000000e+000,2.758026e-003,0.000000e+000,0,,0,
1524110325.678,,0.000000e+000,3.300095e+001,-2.005439e-004,0.000000e+000,3,9.932021e-001,0.000000e+000,,,,,,,,,,,,,,32,1,4.000000e+000,2.769470e-003,0.000000e+000,0,,0,
1524110363.898,,0.000000e+000,3.299957e+001,-2.005809e-004,0.000000e+000,3,9.930997e-001,0.000000e+000,,,,,,,,,,,,,,32,1,4.000000e+000,0.000000e+000,0.000000e+000,0,,0,
1524110401.506,,0.000000e+000,3.300026e+001,-2.006346e-004,0.000000e+000,3,9.928988e-001,0.000000e+000,,,,,,,,,,,,,,32,1,4.000000e+000,1.380920e-003,0.000000e+000,0,,0,
1524110439.652,,0.000000e+000,3.299854e+001,-2.006367e-004,0.000000e+000,3,9.931360e-001,0.000000e+000,,,,,,,,,,,,,,32,1,4.000000e+000,6.866455e-004,0.000000e+000,0,,0,
1524110476.645,,0.000000e+000,3.299888e+001,-2.006874e-004,0.000000e+000,3,9.930641e-001,0.000000e+000,,,,,,,,,,,,,,32,1,4.000000e+000,1.377106e-003,0.000000e+000,0,,0,
1524110514.941,,0.000000e+000,3.299888e+001,-2.007094e-004,0.000000e+000,3,9.929422e-001,0.000000e+000,,,,,,,,,,,,,,32,1,4.000000e+000,1.377106e-003,0.000000e+000,0,,0,
1524110553.319,,0.000000e+000,3.299888e+001,-2.006721e-004,0.000000e+000,3,9.929819e-001,0.000000e+000,,,,,,,,,,,,,,32,1,4.000000e+000,1.377106e-003,0.000000e+000,0,,0,
1524110591.649,,0.000000e+000,3.299854e+001,-2.007115e-004,0.000000e+000,3,9.929364e-001,0.000000e+000,,,,,,,,,,,,,,32,1,4.000000e+000,6.866455e-004,0.000000e+000,0,,0,
1524110630.115,,0.000000e+000,3.300026e+001,-2.007541e-004,0.000000e+000,3,9.931230e-001,0.000000e+000,,,,,,,,,,,,,,32,1,4.000000e+000,1.380920e-003,0.000000e+000,0,,0,
1524110668.658,,0.000000e+000,3.299854e+001,-2.008308e-004,0.000000e+000,3,9.929627e-001,0.000000e+000,,,,,,,,,,,,,,32,1,4.000000e+000,6.866455e-004,0.000000e+000,0,,0,
1524110706.406,,0.000000e+000,3.299922e+001,-2.008387e-004,0.000000e+000,3,9.929541e-001,0.000000e+000,,,,,,,,,,,,,,32,1,4.000000e+000,6.904602e-004,0.000000e+000,0,,0,
1524110744.904,,0.000000e+000,3.299957e+001,-2.008204e-004,0.000000e+000,3,9.931153e-001,0.000000e+000,,,,,,,,,,,,,,32,1,4.000000e+000,1.380920e-003,0.000000e+000,0,,0,
1524110782.870,,0.000000e+000,3.299888e+001,-2.008552e-004,0.000000e+000,3,9.930068e-001,0.000000e+000,,,,,,,,,,,,,,32,1,4.000000e+000,0.000000e+000,0.000000e+000,0,,0,
1524110821.240,,0.000000e+000,3.299957e+001,-2.008774e-004,0.000000e+000,3,9.928740e-001,0.000000e+000,,,,,,,,,,,,,,32,1,4.000000e+000,0.000000e+000,0.000000e+000,0,,0,
1524110858.493,,0.000000e+000,3.299922e+001,-2.009118e-004,0.000000e+000,3,9.931089e-001,0.000000e+000,,,,,,,,,,,,,,32,1,4.000000e+000,6.904602e-004,0.000000e+000,0,,0,
1524110897.504,,0.000000e+000,3.299888e+001,-2.008931e-004,0.000000e+000,3,9.929342e-001,0.000000e+000,,,,,,,,,,,,,,32,1,4.000000e+000,2.758026e-003,0.000000e+000,0,,0,
1524110935.317,,0.000000e+000,3.299922e+001,-2.009780e-004,0.000000e+000,3,9.931008e-001,0.000000e+000,,,,,,,,,,,,,,32,1,4.000000e+000,6.904602e-004,0.000000e+000,0,,0,
1524110974.022,,0.000000e+000,3.299888e+001,-2.009466e-004,0.000000e+000,3,9.931598e-001,0.000000e+000,,,,,,,,,,,,,,32,1,4.000000e+000,0.000000e+000,0.000000e+000,0,,0,
1524111012.143,,0.000000e+000,3.299992e+001,-2.009701e-004,0.000000e+000,3,9.931321e-001,0.000000e+000,,,,,,,,,,,,,,32,1,4.000000e+000,6.904602e-004,0.000000e+000,0,,0,
1524111049.066,,0.000000e+000,3.299922e+001,-2.010195e-004,0.000000e+000,3,9.929341e-001,0.000000e+000,,,,,,,,,,,,,,32,1,4.000000e+000,6.904602e-004,0.000000e+000,0,,0,
1524111086.509,,0.000000e+000,3.299854e+001,-2.010267e-004,0.000000e+000,3,9.928975e-001,0.000000e+000,,,,,,,,,,,,,,32,1,4.000000e+000,6.866455e-004,0.000000e+000,0,,0,
1524111124.557,,0.000000e+000,3.299854e+001,-2.010772e-004,0.000000e+000,3,9.929209e-001,0.000000e+000,,,,,,,,,,,,,,32,1,4.000000e+000,6.866455e-004,0.000000e+000,0,,0,
1524111162.805,,0.000000e+000,3.299957e+001,-2.010628e-004,0.000000e+000,3,9.930632e-001,0.000000e+000,,,,,,,,,,,,,,32,1,4.000000e+000,1.380920e-003,0.000000e+000,0,,0,
1524111201.281,,0.000000e+000,3.299749e+001,-2.010969e-004,0.000000e+000,3,9.931452e-001,0.000000e+000,,,,,,,,,,,,,,32,1,4.000000e+000,4.150391e-003,0.000000e+000,0,,0,
1524111239.609,,0.000000e+000,3.299957e+001,-2.011349e-004,0.000000e+000,3,9.930843e-001,0.000000e+000,,,,,,,,,,,,,,32,1,4.000000e+000,1.380920e-003,0.000000e+000,0,,0,
1524111252.617,,0.000000e+000,3.299888e+001,-2.010999e-004,0.000000e+000,3,9.930144e-001,0.000000e+000,,,,,,,,,,,,,,32,1,4.000000e+000,0.000000e+000,0.000000e+000,0,,0,