File: Experimental Raw Data/MFn1 VRM/Iterative Regression/Acquisition/MFn1_VRMac_35K_6000s.dc.dat
[Header]
TITLE,MPMS DC Measurement
BYAPP,MPMS Measurement,2.1,Summary
FILEOPENTIME, 1524018385.549000 4/17/2018, 8:26:25 PM

INFO, APPNAME, MPMS MultiVu Application, Revision 1.61,  Build 082

INFO, NAME, MFn1
INFO, WEIGHT, 1.000
INFO, AREA, 1.000
INFO, LENGTH, 1.000
INFO, SHAPE, 0
INFO, COMMENT,
INFO, SEQUENCE FILE: VRMac_35K_6000s_VRMde_35K.seq


INFO, BACKGROUND DATA FILE:, None


STARTUPAXIS,X,4,LINEAR,AUTO,0.000000,0.000000
STARTUPAXIS,Y1,5,LINEAR,AUTO,0.000000,0.000000


STARTUPGROUP,Longitudinal
FIELDGROUP,Longitudinal,1,2,3,4,5,6,7,8,9,15,16,17,18,27,28
FIELDGROUP,Transverse,1,2,3,4,10,11,12,13,14,19,20,21,22,27,28

PLOT_APPEARANCE,ALL,HORZ_GRID_ON,VERT_GRID_ON,MARKERS_AND_LINES

[Data]
Time,Comment,Field (Oe),Temperature (K),Long Moment (emu),Long Scan Std Dev,Long Algorithm,Long Reg Fit,Long Percent Error (%),Trans Moment (emu),Trans Scan Std Dev,Trans Algorithm,Trans Reg Fit,Trans Percent Error (%),Long Moment [w/o ABS] (emu),Long Scan Std Dev [w/o ABS],Long Reg Fit [w/o ABS],Long Percent Error [w/o ABS] (%),Trans Moment [w/o ABS] (emu),Trans Scan Std Dev [w/o ABS],Trans Reg Fit [w/o ABS],Trans Percent Error [w/o ABS] (%),Points per Scan,Scans per Measurement,Scan Length (cm),Delta Temp (K),Rot Position (deg),Error,EC Comp. Running,Using ABS,
1524018385.541,,0.000000e+000,3.500067e+001,-1.776909e-004,0.000000e+000,3,9.916915e-001,0.000000e+000,,,,,,,,,,,,,,32,1,4.000000e+000,7.820129e-004,0.000000e+000,0,,0,
1524018411.187,,0.000000e+000,3.500028e+001,-1.800155e-004,0.000000e+000,3,9.920928e-001,0.000000e+000,,,,,,,,,,,,,,32,1,4.000000e+000,0.000000e+000,0.000000e+000,0,,0,
1524018435.984,,0.000000e+000,3.499989e+001,-1.815626e-004,0.000000e+000,3,9.922342e-001,0.000000e+000,,,,,,,,,,,,,,32,1,4.000000e+000,7.781982e-004,0.000000e+000,0,,0,
1524018460.922,,0.000000e+000,3.499989e+001,-1.826314e-004,0.000000e+000,3,9.923478e-001,0.000000e+000,,,,,,,,,,,,,,32,1,4.000000e+000,7.781982e-004,0.000000e+000,0,,0,
1524018485.653,,0.000000e+000,3.499833e+001,-1.834553e-004,0.000000e+000,3,9.920954e-001,0.000000e+000,,,,,,,,,,,,,,32,1,4.000000e+000,7.781982e-004,0.000000e+000,0,,0,
1524018510.733,,0.000000e+000,3.500028e+001,-1.843948e-004,0.000000e+000,3,9.925276e-001,0.000000e+000,,,,,,,,,,,,,,32,1,4.000000e+000,3.120422e-003,0.000000e+000,0,,0,
1524018536.436,,0.000000e+000,3.499833e+001,-1.849928e-004,0.000000e+000,3,9.921052e-001,0.000000e+000,,,,,,,,,,,,,,32,1,4.000000e+000,7.781982e-004,0.000000e+000,0,,0,
1524018561.224,,0.000000e+000,3.499872e+001,-1.856848e-004,0.000000e+000,3,9.924659e-001,0.000000e+000,,,,,,,,,,,,,,32,1,4.000000e+000,0.000000e+000,0.000000e+000,0,,0,
1524018586.642,,0.000000e+000,3.499833e+001,-1.861862e-004,0.000000e+000,3,9.922037e-001,0.000000e+000,,,,,,,,,,,,,,32,1,4.000000e+000,7.781982e-004,0.000000e+000,0,,0,
1524018612.060,,0.000000e+000,3.499833e+001,-1.866897e-004,0.000000e+000,3,9.921900e-001,0.000000e+000,,,,,,,,,,,,,,32,1,4.000000e+000,7.781982e-004,0.000000e+000,0,,0,
1524018637.855,,0.000000e+000,3.499833e+001,-1.871533e-004,0.000000e+000,3,9.922670e-001,0.000000e+000,,,,,,,,,,,,,,32,1,4.000000e+000,7.781982e-004,0.000000e+000,0,,0,
1524018663.150,,0.000000e+000,3.499872e+001,-1.875481e-004,0.000000e+000,3,9.924849e-001,0.000000e+000,,,,,,,,,,,,,,32,1,4.000000e+000,1.560211e-003,0.000000e+000,0,,0,
1524018688.023,,0.000000e+000,3.499911e+001,-1.878641e-004,0.000000e+000,3,9.922194e-001,0.000000e+000,,,,,,,,,,,,,,32,1,4.000000e+000,7.820129e-004,0.000000e+000,0,,0,
1524018713.466,,0.000000e+000,3.499872e+001,-1.882930e-004,0.000000e+000,3,9.925511e-001,0.000000e+000,,,,,,,,,,,,,,32,1,4.000000e+000,0.000000e+000,0.000000e+000,0,,0,
1524018738.119,,0.000000e+000,3.499754e+001,-1.886392e-004,0.000000e+000,3,9.924488e-001,0.000000e+000,,,,,,,,,,,,,,32,1,4.000000e+000,7.896423e-004,0.000000e+000,0,,0,
1524018763.909,,0.000000e+000,3.499911e+001,-1.889473e-004,0.000000e+000,3,9.924483e-001,0.000000e+000,,,,,,,,,,,,,,32,1,4.000000e+000,7.820129e-004,0.000000e+000,0,,0,
1524018789.560,,0.000000e+000,3.499715e+001,-1.892121e-004,0.000000e+000,3,9.923136e-001,0.000000e+000,,,,,,,,,,,,,,32,1,4.000000e+000,3.128052e-003,0.000000e+000,0,,0,
1524018815.055,,0.000000e+000,3.499833e+001,-1.894450e-004,0.000000e+000,3,9.923493e-001,0.000000e+000,,,,,,,,,,,,,,32,1,4.000000e+000,7.781982e-004,0.000000e+000,0,,0,
1524018840.455,,0.000000e+000,3.499793e+001,-1.897809e-004,0.000000e+000,3,9.922614e-001,0.000000e+000,,,,,,,,,,,,,,32,1,4.000000e+000,1.567841e-003,0.000000e+000,0,,0,
1524018866.898,,0.000000e+000,3.499754e+001,-1.900281e-004,0.000000e+000,3,9.924511e-001,0.000000e+000,,,,,,,,,,,,,,32,1,4.000000e+000,7.896423e-004,0.000000e+000,0,,0,
1524018892.366,,0.000000e+000,3.499793e+001,-1.903041e-004,0.000000e+000,3,9.923344e-001,0.000000e+000,,,,,,,,,,,,,,32,1,4.000000e+000,1.567841e-003,0.000000e+000,0,,0,
1524018917.872,,0.000000e+000,3.499872e+001,-1.905480e-004,0.000000e+000,3,9.925396e-001,0.000000e+000,,,,,,,,,,,,,,32,1,4.000000e+000,1.560211e-003,0.000000e+000,0,,0,
1524018943.172,,0.000000e+000,3.499793e+001,-1.907670e-004,0.000000e+000,3,9.923858e-001,0.000000e+000,,,,,,,,,,,,,,32,1,4.000000e+000,1.567841e-003,0.000000e+000,0,,0,
1524018968.635,,0.000000e+000,3.499794e+001,-1.909317e-004,0.000000e+000,3,9.924085e-001,0.000000e+000,,,,,,,,,,,,,,32,1,4.000000e+000,0.000000e+000,0.000000e+000,0,,0,
1524018994.005,,0.000000e+000,3.499833e+001,-1.911678e-004,0.000000e+000,3,9.924216e-001,0.000000e+000,,,,,,,,,,,,,,32,1,4.000000e+000,7.781982e-004,0.000000e+000,0,,0,
1524019019.380,,0.000000e+000,3.499833e+001,-1.913730e-004,0.000000e+000,3,9.924264e-001,0.000000e+000,,,,,,,,,,,,,,32,1,4.000000e+000,7.781982e-004,0.000000e+000,0,,0,
1524019045.031,,0.000000e+000,3.499872e+001,-1.915918e-004,0.000000e+000,3,9.924759e-001,0.000000e+000,,,,,,,,,,,,,,32,1,4.000000e+000,0.000000e+000,0.000000e+000,0,,0,
1524019070.219,,0.000000e+000,3.499911e+001,-1.917273e-004,0.000000e+000,3,9.924611e-001,0.000000e+000,,,,,,,,,,,,,,32,1,4.000000e+000,2.338409e-003,0.000000e+000,0,,0,
1524019095.874,,0.000000e+000,3.499872e+001,-1.919301e-004,0.000000e+000,3,9.924027e-001,0.000000e+000,,,,,,,,,,,,,,32,1,4.000000e+000,0.000000e+000,0.000000e+000,0,,0,
1524019121.195,,0.000000e+000,3.499872e+001,-1.921328e-004,0.000000e+000,3,9.924600e-001,0.000000e+000,,,,,,,,,,,,,,32,1,4.000000e+000,0.000000e+000,0.000000e+000,0,,0,
1524019146.572,,0.000000e+000,3.499833e+001,-1.922829e-004,0.000000e+000,3,9.924936e-001,0.000000e+000,,,,,,,,,,,,,,32,1,4.000000e+000,7.781982e-004,0.000000e+000,0,,0,
1524019171.988,,0.000000e+000,3.499833e+001,-1.924349e-004,0.000000e+000,3,9.923753e-001,0.000000e+000,,,,,,,,,,,,,,32,1,4.000000e+000,2.349854e-003,0.000000e+000,0,,0,
1524019197.316,,0.000000e+000,3.499872e+001,-1.926063e-004,0.000000e+000,3,9.924539e-001,0.000000e+000,,,,,,,,,,,,,,32,1,4.000000e+000,1.560211e-003,0.000000e+000,0,,0,
1524019222.726,,0.000000e+000,3.499872e+001,-1.927567e-004,0.000000e+000,3,9.924332e-001,0.000000e+000,,,,,,,,,,,,,,32,1,4.000000e+000,0.000000e+000,0.000000e+000,0,,0,
1524019247.451,,0.000000e+000,3.499793e+001,-1.929059e-004,0.000000e+000,3,9.924926e-001,0.000000e+000,,,,,,,,,,,,,,32,1,4.000000e+000,3.131866e-003,0.000000e+000,0,,0,
1524019272.677,,0.000000e+000,3.499754e+001,-1.930455e-004,0.000000e+000,3,9.924958e-001,0.000000e+000,,,,,,,,,,,,,,32,1,4.000000e+000,2.349854e-003,0.000000e+000,0,,0,
1524019297.720,,0.000000e+000,3.499715e+001,-1.932534e-004,0.000000e+000,3,9.925627e-001,0.000000e+000,,,,,,,,,,,,,,32,1,4.000000e+000,1.571655e-003,0.000000e+000,0,,0,
1524019323.085,,0.000000e+000,3.499754e+001,-1.933531e-004,0.000000e+000,3,9.926662e-001,0.000000e+000,,,,,,,,,,,,,,32,1,4.000000e+000,7.896423e-004,0.000000e+000,0,,0,
1524019348.323,,0.000000e+000,3.499793e+001,-1.934575e-004,0.000000e+000,3,9.924213e-001,0.000000e+000,,,,,,,,,,,,,,32,1,4.000000e+000,1.567841e-003,0.000000e+000,0,,0,
1524019373.053,,0.000000e+000,3.499911e+001,-1.936007e-004,0.000000e+000,3,9.925210e-001,0.000000e+000,,,,,,,,,,,,,,32,1,4.000000e+000,7.820129e-004,0.000000e+000,0,,0,
1524019398.409,,0.000000e+000,3.499872e+001,-1.937106e-004,0.000000e+000,3,9.925528e-001,0.000000e+000,,,,,,,,,,,,,,32,1,4.000000e+000,1.560211e-003,0.000000e+000,0,,0,
1524019423.791,,0.000000e+000,3.499872e+001,-1.938661e-004,0.000000e+000,3,9.924968e-001,0.000000e+000,,,,,,,,,,,,,,32,1,4.000000e+000,1.560211e-003,0.000000e+000,0,,0,
1524019449.189,,0.000000e+000,3.499833e+001,-1.939976e-004,0.000000e+000,3,9.924266e-001,0.000000e+000,,,,,,,,,,,,,,32,1,4.000000e+000,7.781982e-004,0.000000e+000,0,,0,
1524019474.130,,0.000000e+000,3.499911e+001,-1.940960e-004,0.000000e+000,3,9.925498e-001,0.000000e+000,,,,,,,,,,,,,,32,1,4.000000e+000,7.820129e-004,0.000000e+000,0,,0,
1524019499.415,,0.000000e+000,3.499872e+001,-1.942592e-004,0.000000e+000,3,9.924163e-001,0.000000e+000,,,,,,,,,,,,,,32,1,4.000000e+000,0.000000e+000,0.000000e+000,0,,0,
1524019524.860,,0.000000e+000,3.499911e+001,-1.943139e-004,0.000000e+000,3,9.925067e-001,0.000000e+000,,,,,,,,,,,,,,32,1,4.000000e+000,7.820129e-004,0.000000e+000,0,,0,
1524019550.233,,0.000000e+000,3.499833e+001,-1.944371e-004,0.000000e+000,3,9.925218e-001,0.000000e+000,,,,,,,,,,,,,,32,1,4.000000e+000,7.781982e-004,0.000000e+000,0,,0,
1524019575.556,,0.000000e+000,3.499911e+001,-1.945534e-004,0.000000e+000,3,9.925197e-001,0.000000e+000,,,,,,,,,,,,,,32,1,4.000000e+000,7.820129e-004,0.000000e+000,0,,0,
1524019600.554,,0.000000e+000,3.499793e+001,-1.946908e-004,0.000000e+000,3,9.924049e-001,0.000000e+000,,,,,,,,,,,,,,32,1,4.000000e+000,1.567841e-003,0.000000e+000,0,,0,
1524019625.862,,0.000000e+000,3.499754e+001,-1.947995e-004,0.000000e+000,3,9.924017e-001,0.000000e+000,,,,,,,,,,,,,,32,1,4.000000e+000,2.349854e-003,0.000000e+000,0,,0,
1524019651.177,,0.000000e+000,3.499833e+001,-1.948840e-004,0.000000e+000,3,9.925096e-001,0.000000e+000,,,,,,,,,,,,,,32,1,4.000000e+000,2.349854e-003,0.000000e+000,0,,0,
1524019676.640,,0.000000e+000,3.499833e+001,-1.949852e-004,0.000000e+000,3,9.925864e-001,0.000000e+000,,,,,,,,,,,,,,32,1,4.000000e+000,7.781982e-004,0.000000e+000,0,,0,
1524019701.928,,0.000000e+000,3.499872e+001,-1.952228e-004,0.000000e+000,3,9.920505e-001,0.000000e+000,,,,,,,,,,,,,,32,1,4.000000e+000,1.560211e-003,0.000000e+000,0,,0,
1524019727.373,,0.000000e+000,3.499911e+001,-1.952032e-004,0.000000e+000,3,9.925123e-001,0.000000e+000,,,,,,,,,,,,,,32,1,4.000000e+000,7.820129e-004,0.000000e+000,0,,0,
1524019753.011,,0.000000e+000,3.499872e+001,-1.952969e-004,0.000000e+000,3,9.926994e-001,0.000000e+000,,,,,,,,,,,,,,32,1,4.000000e+000,0.000000e+000,0.000000e+000,0,,0,
1524019777.632,,0.000000e+000,3.499872e+001,-1.953795e-004,0.000000e+000,3,9.924968e-001,0.000000e+000,,,,,,,,,,,,,,32,1,4.000000e+000,1.560211e-003,0.000000e+000,0,,0,
1524019803.004,,0.000000e+000,3.499911e+001,-1.954809e-004,0.000000e+000,3,9.924742e-001,0.000000e+000,,,,,,,,,,,,,,32,1,4.000000e+000,7.820129e-004,0.000000e+000,0,,0,
1524019828.380,,0.000000e+000,3.499911e+001,-1.955759e-004,0.000000e+000,3,9.924837e-001,0.000000e+000,,,,,,,,,,,,,,32,1,4.000000e+000,7.820129e-004,0.000000e+000,0,,0,
1524019853.530,,0.000000e+000,3.499950e+001,-1.956893e-004,0.000000e+000,3,9.925119e-001,0.000000e+000,,,,,,,,,,,,,,32,1,4.000000e+000,1.560211e-003,0.000000e+000,0,,0,
1524019878.298,,0.000000e+000,3.499950e+001,-1.957642e-004,0.000000e+000,3,9.925886e-001,0.000000e+000,,,,,,,,,,,,,,32,1,4.000000e+000,1.560211e-003,0.000000e+000,0,,0,
1524019904.358,,0.000000e+000,3.499833e+001,-1.958527e-004,0.000000e+000,3,9.924725e-001,0.000000e+000,,,,,,,,,,,,,,32,1,4.000000e+000,7.781982e-004,0.000000e+000,0,,0,
1524019929.779,,0.000000e+000,3.499911e+001,-1.960510e-004,0.000000e+000,3,9.924210e-001,0.000000e+000,,,,,,,,,,,,,,32,1,4.000000e+000,7.820129e-004,0.000000e+000,0,,0,
1524019954.767,,0.000000e+000,3.499872e+001,-1.960313e-004,0.000000e+000,3,9.925491e-001,0.000000e+000,,,,,,,,,,,,,,32,1,4.000000e+000,0.000000e+000,0.000000e+000,0,,0,
1524019980.552,,0.000000e+000,3.499833e+001,-1.961244e-004,0.000000e+000,3,9.925312e-001,0.000000e+000,,,,,,,,,,,,,,32,1,4.000000e+000,7.781982e-004,0.000000e+000,0,,0,
1524020005.475,,0.000000e+000,3.499833e+001,-1.961511e-004,0.000000e+000,3,9.925289e-001,0.000000e+000,,,,,,,,,,,,,,32,1,4.000000e+000,7.781982e-004,0.000000e+000,0,,0,
1524020030.880,,0.000000e+000,3.499754e+001,-1.962572e-004,0.000000e+000,3,9.925382e-001,0.000000e+000,,,,,,,,,,,,,,32,1,4.000000e+000,7.896423e-004,0.000000e+000,0,,0,
1524020056.701,,0.000000e+000,3.499872e+001,-1.963469e-004,0.000000e+000,3,9.926951e-001,0.000000e+000,,,,,,,,,,,,,,32,1,4.000000e+000,0.000000e+000,0.000000e+000,0,,0,
1524020081.534,,0.000000e+000,3.499911e+001,-1.964875e-004,0.000000e+000,3,9.926492e-001,0.000000e+000,,,,,,,,,,,,,,32,1,4.000000e+000,2.338409e-003,0.000000e+000,0,,0,
1524020106.912,,0.000000e+000,3.499872e+001,-1.965229e-004,0.000000e+000,3,9.924052e-001,0.000000e+000,,,,,,,,,,,,,,32,1,4.000000e+000,1.560211e-003,0.000000e+000,0,,0,
1524020132.647,,0.000000e+000,3.499833e+001,-1.966159e-004,0.000000e+000,3,9.925510e-001,0.000000e+000,,,,,,,,,,,,,,32,1,4.000000e+000,7.781982e-004,0.000000e+000,0,,0,
1524020158.065,,0.000000e+000,3.499872e+001,-1.966569e-004,0.000000e+000,3,9.927332e-001,0.000000e+000,,,,,,,,,,,,,,32,1,4.000000e+000,0.000000e+000,0.000000e+000,0,,0,
1524020184.000,,0.000000e+000,3.499911e+001,-1.967241e-004,0.000000e+000,3,9.926707e-001,0.000000e+000,,,,,,,,,,,,,,32,1,4.000000e+000,7.820129e-004,0.000000e+000,0,,0,
1524020209.571,,0.000000e+000,3.499793e+001,-1.968404e-004,0.000000e+000,3,9.926310e-001,0.000000e+000,,,,,,,,,,,,,,32,1,4.000000e+000,1.567841e-003,0.000000e+000,0,,0,
1524020234.198,,0.000000e+000,3.499911e+001,-1.969200e-004,0.000000e+000,3,9.923853e-001,0.000000e+000,,,,,,,,,,,,,,32,1,4.000000e+000,7.820129e-004,0.000000e+000,0,,0,
1524020258.809,,0.000000e+000,3.499872e+001,-1.969603e-004,0.000000e+000,3,9.926049e-001,0.000000e+000,,,,,,,,,,,,,,32,1,4.000000e+000,1.560211e-003,0.000000e+000,0,,0,
1524020283.932,,0.000000e+000,3.499715e+001,-1.970427e-004,0.000000e+000,3,9.927395e-001,0.000000e+000,,,,,,,,,,,,,,32,1,4.000000e+000,4.692078e-003,0.000000e+000,0,,0,
1524020309.777,,0.000000e+000,3.499872e+001,-1.971023e-004,0.000000e+000,3,9.924806e-001,0.000000e+000,,,,,,,,,,,,,,32,1,4.000000e+000,0.000000e+000,0.000000e+000,0,,0,
1524020335.710,,0.000000e+000,3.499872e+001,-1.971783e-004,0.000000e+000,3,9.926228e-001,0.000000e+000,,,,,,,,,,,,,,32,1,4.000000e+000,1.560211e-003,0.000000e+000,0,,0,
1524020359.783,,0.000000e+000,3.499833e+001,-1.972537e-004,0.000000e+000,3,9.924678e-001,0.000000e+000,,,,,,,,,,,,,,32,1,4.000000e+000,7.781982e-004,0.000000e+000,0,,0,
1524020385.063,,0.000000e+000,3.499911e+001,-1.973067e-004,0.000000e+000,3,9.925613e-001,0.000000e+000,,,,,,,,,,,,,,32,1,4.000000e+000,7.820129e-004,0.000000e+000,0,,0,
1524020411.436,,0.000000e+000,3.499911e+001,-1.973798e-004,0.000000e+000,3,9.925680e-001,0.000000e+000,,,,,,,,,,,,,,32,1,4.000000e+000,7.820129e-004,0.000000e+000,0,,0,
1524020436.861,,0.000000e+000,3.499872e+001,-1.974763e-004,0.000000e+000,3,9.925913e-001,0.000000e+000,,,,,,,,,,,,,,32,1,4.000000e+000,0.000000e+000,0.000000e+000,0,,0,
1524020462.524,,0.000000e+000,3.499833e+001,-1.975372e-004,0.000000e+000,3,9.927346e-001,0.000000e+000,,,,,,,,,,,,,,32,1,4.000000e+000,7.781982e-004,0.000000e+000,0,,0,
1524020487.915,,0.000000e+000,3.499715e+001,-1.976327e-004,0.000000e+000,3,9.929070e-001,0.000000e+000,,,,,,,,,,,,,,32,1,4.000000e+000,1.571655e-003,0.000000e+000,0,,0,
1524020513.247,,0.000000e+000,3.499911e+001,-1.976400e-004,0.000000e+000,3,9.926546e-001,0.000000e+000,,,,,,,,,,,,,,32,1,4.000000e+000,7.820129e-004,0.000000e+000,0,,0,
1524020538.295,,0.000000e+000,3.499872e+001,-1.976805e-004,0.000000e+000,3,9.925883e-001,0.000000e+000,,,,,,,,,,,,,,32,1,4.000000e+000,1.560211e-003,0.000000e+000,0,,0,
1524020563.548,,0.000000e+000,3.499872e+001,-1.977855e-004,0.000000e+000,3,9.927215e-001,0.000000e+000,,,,,,,,,,,,,,32,1,4.000000e+000,0.000000e+000,0.000000e+000,0,,0,
1524020588.924,,0.000000e+000,3.499794e+001,-1.978154e-004,0.000000e+000,3,9.927309e-001,0.000000e+000,,,,,,,,,,,,,,32,1,4.000000e+000,0.000000e+000,0.000000e+000,0,,0,
1524020614.379,,0.000000e+000,3.499989e+001,-1.978891e-004,0.000000e+000,3,9.925877e-001,0.000000e+000,,,,,,,,,,,,,,32,1,4.000000e+000,7.781982e-004,0.000000e+000,0,,0,
1524020639.492,,0.000000e+000,3.499872e+001,-1.980464e-004,0.000000e+000,3,9.925150e-001,0.000000e+000,,,,,,,,,,,,,,32,1,4.000000e+000,0.000000e+000,0.000000e+000,0,,0,
1524020663.987,,0.000000e+000,3.499871e+001,-1.980403e-004,0.000000e+000,3,9.926842e-001,0.000000e+000,,,,,,,,,,,,,,32,1,4.000000e+000,4.692078e-003,0.000000e+000,0,,0,
1524020689.153,,0.000000e+000,3.499911e+001,-1.980819e-004,0.000000e+000,3,9.928713e-001,0.000000e+000,,,,,,,,,,,,,,32,1,4.000000e+000,7.820129e-004,0.000000e+000,0,,0,
1524020714.093,,0.000000e+000,3.499715e+001,-1.981592e-004,0.000000e+000,3,9.924808e-001,0.000000e+000,,,,,,,,,,,,,,32,1,4.000000e+000,1.571655e-003,0.000000e+000,0,,0,
1524020739.448,,0.000000e+000,3.499911e+001,-1.982230e-004,0.000000e+000,3,9.925095e-001,0.000000e+000,,,,,,,,,,,,,,32,1,4.000000e+000,7.820129e-004,0.000000e+000,0,,0,
1524020764.824,,0.000000e+000,3.499872e+001,-1.982789e-004,0.000000e+000,3,9.925803e-001,0.000000e+000,,,,,,,,,,,,,,32,1,4.000000e+000,1.560211e-003,0.000000e+000,0,,0,
1524020790.234,,0.000000e+000,3.499911e+001,-1.983268e-004,0.000000e+000,3,9.926124e-001,0.000000e+000,,,,,,,,,,,,,,32,1,4.000000e+000,7.820129e-004,0.000000e+000,0,,0,
1524020815.592,,0.000000e+000,3.499754e+001,-1.984312e-004,0.000000e+000,3,9.927016e-001,0.000000e+000,,,,,,,,,,,,,,32,1,4.000000e+000,7.896423e-004,0.000000e+000,0,,0,
1524020840.992,,0.000000e+000,3.499950e+001,-1.984525e-004,0.000000e+000,3,9.925410e-001,0.000000e+000,,,,,,,,,,,,,,32,1,4.000000e+000,1.560211e-003,0.000000e+000,0,,0,
1524020866.825,,0.000000e+000,3.499872e+001,-1.984932e-004,0.000000e+000,3,9.928576e-001,0.000000e+000,,,,,,,,,,,,,,32,1,4.000000e+000,0.000000e+000,0.000000e+000,0,,0,
1524020891.741,,0.000000e+000,3.499911e+001,-1.985881e-004,0.000000e+000,3,9.925886e-001,0.000000e+000,,,,,,,,,,,,,,32,1,4.000000e+000,7.820129e-004,0.000000e+000,0,,0,
1524020917.141,,0.000000e+000,3.499793e+001,-1.986175e-004,0.000000e+000,3,9.925939e-001,0.000000e+000,,,,,,,,,,,,,,32,1,4.000000e+000,1.567841e-003,0.000000e+000,0,,0,
1524020942.974,,0.000000e+000,3.499872e+001,-1.986851e-004,0.000000e+000,3,9.924874e-001,0.000000e+000,,,,,,,,,,,,,,32,1,4.000000e+000,1.560211e-003,0.000000e+000,0,,0,
1524020967.912,,0.000000e+000,3.499911e+001,-1.987208e-004,0.000000e+000,3,9.925663e-001,0.000000e+000,,,,,,,,,,,,,,32,1,4.000000e+000,7.820129e-004,0.000000e+000,0,,0,
1524020993.299,,0.000000e+000,3.499754e+001,-1.987771e-004,0.000000e+000,3,9.923550e-001,0.000000e+000,,,,,,,,,,,,,,32,1,4.000000e+000,2.349854e-003,0.000000e+000,0,,0,
1524021018.662,,0.000000e+000,3.499833e+001,-1.988468e-004,0.000000e+000,3,9.925237e-001,0.000000e+000,,,,,,,,,,,,,,32,1,4.000000e+000,7.781982e-004,0.000000e+000,0,,0,
1524021044.530,,0.000000e+000,3.499911e+001,-1.987529e-004,0.000000e+000,3,9.925944e-001,0.000000e+000,,,,,,,,,,,,,,32,1,4.000000e+000,7.820129e-004,0.000000e+000,0,,0,
1524021069.436,,0.000000e+000,3.499911e+001,-1.989711e-004,0.000000e+000,3,9.925694e-001,0.000000e+000,,,,,,,,,,,,,,32,1,4.000000e+000,7.820129e-004,0.000000e+000,0,,0,
1524021094.813,,0.000000e+000,3.499950e+001,-1.989981e-004,0.000000e+000,3,9.927729e-001,0.000000e+000,,,,,,,,,,,,,,32,1,4.000000e+000,1.560211e-003,0.000000e+000,0,,0,
1524021120.126,,0.000000e+000,3.499833e+001,-1.990623e-004,0.000000e+000,3,9.925688e-001,0.000000e+000,,,,,,,,,,,,,,32,1,4.000000e+000,2.349854e-003,0.000000e+000,0,,0,
1524021145.227,,0.000000e+000,3.500028e+001,-1.990988e-004,0.000000e+000,3,9.927070e-001,0.000000e+000,,,,,,,,,,,,,,32,1,4.000000e+000,0.000000e+000,0.000000e+000,0,,0,
1524021170.452,,0.000000e+000,3.499872e+001,-1.991982e-004,0.000000e+000,3,9.926670e-001,0.000000e+000,,,,,,,,,,,,,,32,1,4.000000e+000,0.000000e+000,0.000000e+000,0,,0,
1524021195.832,,0.000000e+000,3.499833e+001,-1.992006e-004,0.000000e+000,3,9.926364e-001,0.000000e+000,,,,,,,,,,,,,,32,1,4.000000e+000,7.781982e-004,0.000000e+000,0,,0,
1524021221.683,,0.000000e+000,3.499950e+001,-1.992521e-004,0.000000e+000,3,9.926608e-001,0.000000e+000,,,,,,,,,,,,,,32,1,4.000000e+000,0.000000e+000,0.000000e+000,0,,0,
1524021246.588,,0.000000e+000,3.499911e+001,-1.992999e-004,0.000000e+000,3,9.925931e-001,0.000000e+000,,,,,,,,,,,,,,32,1,4.000000e+000,7.820129e-004,0.000000e+000,0,,0,
1524021271.341,,0.000000e+000,3.499911e+001,-1.994809e-004,0.000000e+000,3,9.927244e-001,0.000000e+000,,,,,,,,,,,,,,32,1,4.000000e+000,2.338409e-003,0.000000e+000,0,,0,
1524021296.596,,0.000000e+000,3.499872e+001,-1.993972e-004,0.000000e+000,3,9.926382e-001,0.000000e+000,,,,,,,,,,,,,,32,1,4.000000e+000,1.560211e-003,0.000000e+000,0,,0,
1524021321.954,,0.000000e+000,3.499950e+001,-1.994699e-004,0.000000e+000,3,9.925165e-001,0.000000e+000,,,,,,,,,,,,,,32,1,4.000000e+000,0.000000e+000,0.000000e+000,0,,0,
1524021347.342,,0.000000e+000,3.499950e+001,-1.995539e-004,0.000000e+000,3,9.926083e-001,0.000000e+000,,,,,,,,,,,,,,32,1,4.000000e+000,0.000000e+000,0.000000e+000,0,,0,
1524021372.728,,0.000000e+000,3.499950e+001,-1.995514e-004,0.000000e+000,3,9.925463e-001,0.000000e+000,,,,,,,,,,,,,,32,1,4.000000e+000,0.000000e+000,0.000000e+000,0,,0,
1524021398.058,,0.000000e+000,3.499911e+001,-1.995791e-004,0.000000e+000,3,9.926234e-001,0.000000e+000,,,,,,,,,,,,,,32,1,4.000000e+000,7.820129e-004,0.000000e+000,0,,0,
1524021423.481,,0.000000e+000,3.499950e+001,-1.995862e-004,0.000000e+000,3,9.926074e-001,0.000000e+000,,,,,,,,,,,,,,32,1,4.000000e+000,0.000000e+000,0.000000e+000,0,,0,
1524021448.831,,0.000000e+000,3.499911e+001,-1.996948e-004,0.000000e+000,3,9.926615e-001,0.000000e+000,,,,,,,,,,,,,,32,1,4.000000e+000,7.820129e-004,0.000000e+000,0,,0,
1524021474.357,,0.000000e+000,3.499872e+001,-1.997656e-004,0.000000e+000,3,9.925119e-001,0.000000e+000,,,,,,,,,,,,,,32,1,4.000000e+000,0.000000e+000,0.000000e+000,0,,0,
1524021499.617,,0.000000e+000,3.499872e+001,-1.997943e-004,0.000000e+000,3,9.926254e-001,0.000000e+000,,,,,,,,,,,,,,32,1,4.000000e+000,1.560211e-003,0.000000e+000,0,,0,
1524021524.735,,0.000000e+000,3.499833e+001,-1.998410e-004,0.000000e+000,3,9.925802e-001,0.000000e+000,,,,,,,,,,,,,,32,1,4.000000e+000,7.781982e-004,0.000000e+000,0,,0,
1524021549.443,,0.000000e+000,3.499989e+001,-1.998928e-004,0.000000e+000,3,9.926828e-001,0.000000e+000,,,,,,,,,,,,,,32,1,4.000000e+000,3.898621e-003,0.000000e+000,0,,0,
1524021574.873,,0.000000e+000,3.499911e+001,-1.998984e-004,0.000000e+000,3,9.926684e-001,0.000000e+000,,,,,,,,,,,,,,32,1,4.000000e+000,7.820129e-004,0.000000e+000,0,,0,
1524021599.788,,0.000000e+000,3.499911e+001,-1.999826e-004,0.000000e+000,3,9.926123e-001,0.000000e+000,,,,,,,,,,,,,,32,1,4.000000e+000,7.820129e-004,0.000000e+000,0,,0,
1524021625.599,,0.000000e+000,3.499911e+001,-2.000173e-004,0.000000e+000,3,9.924886e-001,0.000000e+000,,,,,,,,,,,,,,32,1,4.000000e+000,7.820129e-004,0.000000e+000,0,,0,
1524021650.307,,0.000000e+000,3.499911e+001,-2.000635e-004,0.000000e+000,3,9.925774e-001,0.000000e+000,,,,,,,,,,,,,,32,1,4.000000e+000,7.820129e-004,0.000000e+000,0,,0,
1524021675.074,,0.000000e+000,3.499950e+001,-2.000954e-004,0.000000e+000,3,9.925345e-001,0.000000e+000,,,,,,,,,,,,,,32,1,4.000000e+000,0.000000e+000,0.000000e+000,0,,0,
1524021700.495,,0.000000e+000,3.499911e+001,-2.001578e-004,0.000000e+000,3,9.926719e-001,0.000000e+000,,,,,,,,,,,,,,32,1,4.000000e+000,7.820129e-004,0.000000e+000,0,,0,
1524021725.820,,0.000000e+000,3.499911e+001,-2.002093e-004,0.000000e+000,3,9.925693e-001,0.000000e+000,,,,,,,,,,,,,,32,1,4.000000e+000,7.820129e-004,0.000000e+000,0,,0,
1524021751.233,,0.000000e+000,3.499911e+001,-2.002411e-004,0.000000e+000,3,9.925267e-001,0.000000e+000,,,,,,,,,,,,,,32,1,4.000000e+000,7.820129e-004,0.000000e+000,0,,0,
1524021776.578,,0.000000e+000,3.499872e+001,-2.002614e-004,0.000000e+000,3,9.925289e-001,0.000000e+000,,,,,,,,,,,,,,32,1,4.000000e+000,1.560211e-003,0.000000e+000,0,,0,
1524021801.964,,0.000000e+000,3.499950e+001,-2.003049e-004,0.000000e+000,3,9.926975e-001,0.000000e+000,,,,,,,,,,,,,,32,1,4.000000e+000,1.560211e-003,0.000000e+000,0,,0,
1524021827.344,,0.000000e+000,3.499872e+001,-2.003479e-004,0.000000e+000,3,9.926116e-001,0.000000e+000,,,,,,,,,,,,,,32,1,4.000000e+000,0.000000e+000,0.000000e+000,0,,0,
1524021852.685,,0.000000e+000,3.499833e+001,-2.004239e-004,0.000000e+000,3,9.925959e-001,0.000000e+000,,,,,,,,,,,,,,32,1,4.000000e+000,7.781982e-004,0.000000e+000,0,,0,
1524021878.057,,0.000000e+000,3.499833e+001,-2.004577e-004,0.000000e+000,3,9.926645e-001,0.000000e+000,,,,,,,,,,,,,,32,1,4.000000e+000,2.349854e-003,0.000000e+000,0,,0,
1524021903.400,,0.000000e+000,3.499989e+001,-2.005018e-004,0.000000e+000,3,9.926622e-001,0.000000e+000,,,,,,,,,,,,,,32,1,4.000000e+000,7.781982e-004,0.000000e+000,0,,0,
1524021928.771,,0.000000e+000,3.499950e+001,-2.006002e-004,0.000000e+000,3,9.925954e-001,0.000000e+000,,,,,,,,,,,,,,32,1,4.000000e+000,1.560211e-003,0.000000e+000,0,,0,
1524021954.146,,0.000000e+000,3.499833e+001,-2.006167e-004,0.000000e+000,3,9.925920e-001,0.000000e+000,,,,,,,,,,,,,,32,1,4.000000e+000,7.781982e-004,0.000000e+000,0,,0,
1524021979.526,,0.000000e+000,3.499872e+001,-2.006445e-004,0.000000e+000,3,9.926479e-001,0.000000e+000,,,,,,,,,,,,,,32,1,4.000000e+000,1.560211e-003,0.000000e+000,0,,0,
1524022004.909,,0.000000e+000,3.499911e+001,-2.006649e-004,0.000000e+000,3,9.926355e-001,0.000000e+000,,,,,,,,,,,,,,32,1,4.000000e+000,7.820129e-004,0.000000e+000,0,,0,
1524022030.127,,0.000000e+000,3.499989e+001,-2.006864e-004,0.000000e+000,3,9.925185e-001,0.000000e+000,,,,,,,,,,,,,,32,1,4.000000e+000,7.781982e-004,0.000000e+000,0,,0,
1524022055.175,,0.000000e+000,3.499911e+001,-2.007449e-004,0.000000e+000,3,9.925424e-001,0.000000e+000,,,,,,,,,,,,,,32,1,4.000000e+000,7.820129e-004,0.000000e+000,0,,0,
1524022080.535,,0.000000e+000,3.500028e+001,-2.008023e-004,0.000000e+000,3,9.926950e-001,0.000000e+000,,,,,,,,,,,,,,32,1,4.000000e+000,1.560211e-003,0.000000e+000,0,,0,
1524022105.891,,0.000000e+000,3.499989e+001,-2.008342e-004,0.000000e+000,3,9.927163e-001,0.000000e+000,,,,,,,,,,,,,,32,1,4.000000e+000,7.781982e-004,0.000000e+000,0,,0,
1524022131.296,,0.000000e+000,3.499989e+001,-2.008391e-004,0.000000e+000,3,9.925613e-001,0.000000e+000,,,,,,,,,,,,,,32,1,4.000000e+000,7.781982e-004,0.000000e+000,0,,0,
1524022156.632,,0.000000e+000,3.499911e+001,-2.008887e-004,0.000000e+000,3,9.925930e-001,0.000000e+000,,,,,,,,,,,,,,32,1,4.000000e+000,2.338409e-003,0.000000e+000,0,,0,
1524022182.094,,0.000000e+000,3.499833e+001,-2.009137e-004,0.000000e+000,3,9.925757e-001,0.000000e+000,,,,,,,,,,,,,,32,1,4.000000e+000,7.781982e-004,0.000000e+000,0,,0,
1524022206.985,,0.000000e+000,3.499911e+001,-2.009290e-004,0.000000e+000,3,9.927048e-001,0.000000e+000,,,,,,,,,,,,,,32,1,4.000000e+000,7.820129e-004,0.000000e+000,0,,0,
1524022232.015,,0.000000e+000,3.499911e+001,-2.009837e-004,0.000000e+000,3,9.927581e-001,0.000000e+000,,,,,,,,,,,,,,32,1,4.000000e+000,7.820129e-004,0.000000e+000,0,,0,
1524022256.728,,0.000000e+000,3.500106e+001,-2.010524e-004,0.000000e+000,3,9.926284e-001,0.000000e+000,,,,,,,,,,,,,,32,1,4.000000e+000,3.128052e-003,0.000000e+000,0,,0,
1524022281.433,,0.000000e+000,3.499950e+001,-2.010909e-004,0.000000e+000,3,9.925937e-001,0.000000e+000,,,,,,,,,,,,,,32,1,4.000000e+000,0.000000e+000,0.000000e+000,0,,0,
1524022306.214,,0.000000e+000,3.499872e+001,-2.011273e-004,0.000000e+000,3,9.926708e-001,0.000000e+000,,,,,,,,,,,,,,32,1,4.000000e+000,1.560211e-003,0.000000e+000,0,,0,
1524022331.589,,0.000000e+000,3.499950e+001,-2.011520e-004,0.000000e+000,3,9.926052e-001,0.000000e+000,,,,,,,,,,,,,,32,1,4.000000e+000,0.000000e+000,0.000000e+000,0,,0,
1524022356.972,,0.000000e+000,3.499793e+001,-2.011654e-004,0.000000e+000,3,9.925932e-001,0.000000e+000,,,,,,,,,,,,,,32,1,4.000000e+000,1.567841e-003,0.000000e+000,0,,0,
1524022382.372,,0.000000e+000,3.499911e+001,-2.012316e-004,0.000000e+000,3,9.926969e-001,0.000000e+000,,,,,,,,,,,,,,32,1,4.000000e+000,7.820129e-004,0.000000e+000,0,,0,
1524022407.518,,0.000000e+000,3.499989e+001,-2.012594e-004,0.000000e+000,3,9.925814e-001,0.000000e+000,,,,,,,,,,,,,,32,1,4.000000e+000,7.781982e-004,0.000000e+000,0,,0,
1524022433.053,,0.000000e+000,3.499911e+001,-2.012759e-004,0.000000e+000,3,9.926834e-001,0.000000e+000,,,,,,,,,,,,,,32,1,4.000000e+000,7.820129e-004,0.000000e+000,0,,0,
1524022458.421,,0.000000e+000,3.499872e+001,-2.013734e-004,0.000000e+000,3,9.926325e-001,0.000000e+000,,,,,,,,,,,,,,32,1,4.000000e+000,1.560211e-003,0.000000e+000,0,,0,
1524022484.394,,0.000000e+000,3.499833e+001,-2.014171e-004,0.000000e+000,3,9.926413e-001,0.000000e+000,,,,,,,,,,,,,,32,1,4.000000e+000,7.781982e-004,0.000000e+000,0,,0,
1524022509.782,,0.000000e+000,3.499872e+001,-2.014682e-004,0.000000e+000,3,9.928361e-001,0.000000e+000,,,,,,,,,,,,,,32,1,4.000000e+000,1.560211e-003,0.000000e+000,0,,0,
1524022534.252,,0.000000e+000,3.500028e+001,-2.014673e-004,0.000000e+000,3,9.925244e-001,0.000000e+000,,,,,,,,,,,,,,32,1,4.000000e+000,1.560211e-003,0.000000e+000,0,,0,
1524022559.447,,0.000000e+000,3.499911e+001,-2.014833e-004,0.000000e+000,3,9.927111e-001,0.000000e+000,,,,,,,,,,,,,,32,1,4.000000e+000,7.820129e-004,0.000000e+000,0,,0,
1524022584.955,,0.000000e+000,3.499950e+001,-2.015044e-004,0.000000e+000,3,9.925288e-001,0.000000e+000,,,,,,,,,,,,,,32,1,4.000000e+000,1.560211e-003,0.000000e+000,0,,0,
1524022610.201,,0.000000e+000,3.499911e+001,-2.015460e-004,0.000000e+000,3,9.926891e-001,0.000000e+000,,,,,,,,,,,,,,32,1,4.000000e+000,7.820129e-004,0.000000e+000,0,,0,
1524022635.619,,0.000000e+000,3.499872e+001,-2.015765e-004,0.000000e+000,3,9.925967e-001,0.000000e+000,,,,,,,,,,,,,,32,1,4.000000e+000,1.560211e-003,0.000000e+000,0,,0,
1524022660.939,,0.000000e+000,3.499950e+001,-2.016256e-004,0.000000e+000,3,9.926047e-001,0.000000e+000,,,,,,,,,,,,,,32,1,4.000000e+000,0.000000e+000,0.000000e+000,0,,0,
1524022686.299,,0.000000e+000,3.499911e+001,-2.016697e-004,0.000000e+000,3,9.927054e-001,0.000000e+000,,,,,,,,,,,,,,32,1,4.000000e+000,7.820129e-004,0.000000e+000,0,,0,
1524022711.622,,0.000000e+000,3.500028e+001,-2.016851e-004,0.000000e+000,3,9.927123e-001,0.000000e+000,,,,,,,,,,,,,,32,1,4.000000e+000,1.560211e-003,0.000000e+000,0,,0,
1524022737.090,,0.000000e+000,3.499950e+001,-2.016756e-004,0.000000e+000,3,9.924734e-001,0.000000e+000,,,,,,,,,,,,,,32,1,4.000000e+000,0.000000e+000,0.000000e+000,0,,0,
1524022762.405,,0.000000e+000,3.499871e+001,-2.017422e-004,0.000000e+000,3,9.926390e-001,0.000000e+000,,,,,,,,,,,,,,32,1,4.000000e+000,3.128052e-003,0.000000e+000,0,,0,
1524022787.773,,0.000000e+000,3.499872e+001,-2.017486e-004,0.000000e+000,3,9.925609e-001,0.000000e+000,,,,,,,,,,,,,,32,1,4.000000e+000,1.560211e-003,0.000000e+000,0,,0,
1524022813.106,,0.000000e+000,3.499911e+001,-2.017862e-004,0.000000e+000,3,9.926614e-001,0.000000e+000,,,,,,,,,,,,,,32,1,4.000000e+000,7.820129e-004,0.000000e+000,0,,0,
1524022838.484,,0.000000e+000,3.499872e+001,-2.018497e-004,0.000000e+000,3,9.928263e-001,0.000000e+000,,,,,,,,,,,,,,32,1,4.000000e+000,0.000000e+000,0.000000e+000,0,,0,
1524022863.892,,0.000000e+000,3.499872e+001,-2.018914e-004,0.000000e+000,3,9.926436e-001,0.000000e+000,,,,,,,,,,,,,,32,1,4.000000e+000,1.560211e-003,0.000000e+000,0,,0,
1524022888.765,,0.000000e+000,3.499715e+001,-2.019117e-004,0.000000e+000,3,9.926181e-001,0.000000e+000,,,,,,,,,,,,,,32,1,4.000000e+000,1.571655e-003,0.000000e+000,0,,0,
1524022914.105,,0.000000e+000,3.499950e+001,-2.019380e-004,0.000000e+000,3,9.927492e-001,0.000000e+000,,,,,,,,,,,,,,32,1,4.000000e+000,1.560211e-003,0.000000e+000,0,,0,
1524022939.486,,0.000000e+000,3.499950e+001,-2.019838e-004,0.000000e+000,3,9.926428e-001,0.000000e+000,,,,,,,,,,,,,,32,1,4.000000e+000,1.560211e-003,0.000000e+000,0,,0,
1524022964.856,,0.000000e+000,3.499989e+001,-2.020232e-004,0.000000e+000,3,9.926195e-001,0.000000e+000,,,,,,,,,,,,,,32,1,4.000000e+000,7.781982e-004,0.000000e+000,0,,0,
1524022990.171,,0.000000e+000,3.499950e+001,-2.020514e-004,0.000000e+000,3,9.926498e-001,0.000000e+000,,,,,,,,,,,,,,32,1,4.000000e+000,0.000000e+000,0.000000e+000,0,,0,
1524023015.062,,0.000000e+000,3.499950e+001,-2.020474e-004,0.000000e+000,3,9.925822e-001,0.000000e+000,,,,,,,,,,,,,,32,1,4.000000e+000,1.560211e-003,0.000000e+000,0,,0,
1524023040.449,,0.000000e+000,3.499911e+001,-2.021400e-004,0.000000e+000,3,9.927436e-001,0.000000e+000,,,,,,,,,,,,,,32,1,4.000000e+000,7.820129e-004,0.000000e+000,0,,0,
1524023065.922,,0.000000e+000,3.499872e+001,-2.021470e-004,0.000000e+000,3,9.927867e-001,0.000000e+000,,,,,,,,,,,,,,32,1,4.000000e+000,1.560211e-003,0.000000e+000,0,,0,
1524023091.720,,0.000000e+000,3.499911e+001,-2.021654e-004,0.000000e+000,3,9.927294e-001,0.000000e+000,,,,,,,,,,,,,,32,1,4.000000e+000,7.820129e-004,0.000000e+000,0,,0,
1524023116.558,,0.000000e+000,3.499793e+001,-2.021862e-004,0.000000e+000,3,9.925667e-001,0.000000e+000,,,,,,,,,,,,,,32,1,4.000000e+000,1.567841e-003,0.000000e+000,0,,0,
1524023141.929,,0.000000e+000,3.499833e+001,-2.022288e-004,0.000000e+000,3,9.926027e-001,0.000000e+000,,,,,,,,,,,,,,32,1,4.000000e+000,7.781982e-004,0.000000e+000,0,,0,
1524023167.296,,0.000000e+000,3.499911e+001,-2.022695e-004,0.000000e+000,3,9.927806e-001,0.000000e+000,,,,,,,,,,,,,,32,1,4.000000e+000,7.820129e-004,0.000000e+000,0,,0,
1524023193.212,,0.000000e+000,3.499950e+001,-2.023114e-004,0.000000e+000,3,9.927050e-001,0.000000e+000,,,,,,,,,,,,,,32,1,4.000000e+000,0.000000e+000,0.000000e+000,0,,0,
1524023217.697,,0.000000e+000,3.499872e+001,-2.023034e-004,0.000000e+000,3,9.926796e-001,0.000000e+000,,,,,,,,,,,,,,32,1,4.000000e+000,0.000000e+000,0.000000e+000,0,,0,
1524023243.367,,0.000000e+000,3.499872e+001,-2.023499e-004,0.000000e+000,3,9.926962e-001,0.000000e+000,,,,,,,,,,,,,,32,1,4.000000e+000,0.000000e+000,0.000000e+000,0,,0,
1524023268.528,,0.000000e+000,3.499911e+001,-2.024186e-004,0.000000e+000,3,9.925953e-001,0.000000e+000,,,,,,,,,,,,,,32,1,4.000000e+000,7.820129e-004,0.000000e+000,0,,0,
1524023294.171,,0.000000e+000,3.499911e+001,-2.025146e-004,0.000000e+000,3,9.923650e-001,0.000000e+000,,,,,,,,,,,,,,32,1,4.000000e+000,7.820129e-004,0.000000e+000,0,,0,
1524023319.001,,0.000000e+000,3.499872e+001,-2.024293e-004,0.000000e+000,3,9.927134e-001,0.000000e+000,,,,,,,,,,,,,,32,1,4.000000e+000,0.000000e+000,0.000000e+000,0,,0,
1524023344.316,,0.000000e+000,3.499911e+001,-2.024758e-004,0.000000e+000,3,9.925498e-001,0.000000e+000,,,,,,,,,,,,,,32,1,4.000000e+000,7.820129e-004,0.000000e+000,0,,0,
1524023369.439,,0.000000e+000,3.500028e+001,-2.025462e-004,0.000000e+000,3,9.925593e-001,0.000000e+000,,,,,,,,,,,,,,32,1,4.000000e+000,1.560211e-003,0.000000e+000,0,,0,
1524023394.307,,0.000000e+000,3.499793e+001,-2.025426e-004,0.000000e+000,3,9.925846e-001,0.000000e+000,,,,,,,,,,,,,,32,1,4.000000e+000,1.567841e-003,0.000000e+000,0,,0,
1524023419.628,,0.000000e+000,3.499872e+001,-2.025569e-004,0.000000e+000,3,9.927682e-001,0.000000e+000,,,,,,,,,,,,,,32,1,4.000000e+000,0.000000e+000,0.000000e+000,0,,0,
1524023445.295,,0.000000e+000,3.499911e+001,-2.025990e-004,0.000000e+000,3,9.927104e-001,0.000000e+000,,,,,,,,,,,,,,32,1,4.000000e+000,7.820129e-004,0.000000e+000,0,,0,
1524023470.348,,0.000000e+000,3.500028e+001,-2.026427e-004,0.000000e+000,3,9.925655e-001,0.000000e+000,,,,,,,,,,,,,,32,1,4.000000e+000,0.000000e+000,0.000000e+000,0,,0,
1524023495.536,,0.000000e+000,3.499911e+001,-2.026663e-004,0.000000e+000,3,9.926655e-001,0.000000e+000,,,,,,,,,,,,,,32,1,4.000000e+000,7.820129e-004,0.000000e+000,0,,0,
1524023520.959,,0.000000e+000,3.499950e+001,-2.027080e-004,0.000000e+000,3,9.922737e-001,0.000000e+000,,,,,,,,,,,,,,32,1,4.000000e+000,1.560211e-003,0.000000e+000,0,,0,
1524023546.297,,0.000000e+000,3.499872e+001,-2.026985e-004,0.000000e+000,3,9.926136e-001,0.000000e+000,,,,,,,,,,,,,,32,1,4.000000e+000,0.000000e+000,0.000000e+000,0,,0,
1524023571.825,,0.000000e+000,3.499950e+001,-2.027411e-004,0.000000e+000,3,9.925010e-001,0.000000e+000,,,,,,,,,,,,,,32,1,4.000000e+000,0.000000e+000,0.000000e+000,0,,0,
1524023596.815,,0.000000e+000,3.499911e+001,-2.027946e-004,0.000000e+000,3,9.925641e-001,0.000000e+000,,,,,,,,,,,,,,32,1,4.000000e+000,7.820129e-004,0.000000e+000,0,,0,
1524023622.961,,0.000000e+000,3.499911e+001,-2.028111e-004,0.000000e+000,3,9.927024e-001,0.000000e+000,,,,,,,,,,,,,,32,1,4.000000e+000,7.820129e-004,0.000000e+000,0,,0,
1524023648.411,,0.000000e+000,3.499989e+001,-2.028163e-004,0.000000e+000,3,9.926198e-001,0.000000e+000,,,,,,,,,,,,,,32,1,4.000000e+000,7.781982e-004,0.000000e+000,0,,0,
1524023673.834,,0.000000e+000,3.499989e+001,-2.028862e-004,0.000000e+000,3,9.926757e-001,0.000000e+000,,,,,,,,,,,,,,32,1,4.000000e+000,7.781982e-004,0.000000e+000,0,,0,
1524023699.222,,0.000000e+000,3.499950e+001,-2.029215e-004,0.000000e+000,3,9.927635e-001,0.000000e+000,,,,,,,,,,,,,,32,1,4.000000e+000,1.560211e-003,0.000000e+000,0,,0,
1524023712.394,,0.000000e+000,3.499989e+001,-2.028779e-004,0.000000e+000,3,9.926919e-001,0.000000e+000,,,,,,,,,,,,,,32,1,4.000000e+000,7.781982e-004,0.000000e+000,0,,0,