File: Experimental Raw Data/TC04-12-01K VRMac VRMde/Iterative Regression/TC04-12-01K_VRMac_53K_6000s.dc.dat
[Header]
TITLE,MPMS DC Measurement
BYAPP,MPMS Measurement,2.1,Summary
FILEOPENTIME, 1524203413.471000 4/19/2018, 11:50:13 PM

INFO, APPNAME, MPMS MultiVu Application, Revision 1.61,  Build 082

INFO, NAME, TC04-12-01K
INFO, WEIGHT, 1.000
INFO, AREA, 1.000
INFO, LENGTH, 1.000
INFO, SHAPE, 0
INFO, COMMENT,
INFO, SEQUENCE FILE: VRMac_53K_6000s_VRMde_55K.seq


INFO, BACKGROUND DATA FILE:, None


STARTUPAXIS,X,4,LINEAR,AUTO,0.000000,0.000000
STARTUPAXIS,Y1,5,LINEAR,AUTO,0.000000,0.000000


STARTUPGROUP,Longitudinal
FIELDGROUP,Longitudinal,1,2,3,4,5,6,7,8,9,15,16,17,18,27,28
FIELDGROUP,Transverse,1,2,3,4,10,11,12,13,14,19,20,21,22,27,28

PLOT_APPEARANCE,ALL,HORZ_GRID_ON,VERT_GRID_ON,MARKERS_AND_LINES

[Data]
Time,Comment,Field (Oe),Temperature (K),Long Moment (emu),Long Scan Std Dev,Long Algorithm,Long Reg Fit,Long Percent Error (%),Trans Moment (emu),Trans Scan Std Dev,Trans Algorithm,Trans Reg Fit,Trans Percent Error (%),Long Moment [w/o ABS] (emu),Long Scan Std Dev [w/o ABS],Long Reg Fit [w/o ABS],Long Percent Error [w/o ABS] (%),Trans Moment [w/o ABS] (emu),Trans Scan Std Dev [w/o ABS],Trans Reg Fit [w/o ABS],Trans Percent Error [w/o ABS] (%),Points per Scan,Scans per Measurement,Scan Length (cm),Delta Temp (K),Rot Position (deg),Error,EC Comp. Running,Using ABS,
1524203413.471,,0.000000e+000,5.303983e+001,-5.133819e-005,0.000000e+000,3,9.708238e-001,0.000000e+000,,,,,,,,,,,,,,32,1,4.000000e+000,7.400513e-003,0.000000e+000,0,,0,
1524203438.561,,0.000000e+000,5.301826e+001,-5.515406e-005,0.000000e+000,3,9.712542e-001,0.000000e+000,,,,,,,,,,,,,,32,1,4.000000e+000,8.640289e-003,0.000000e+000,0,,0,
1524203464.221,,0.000000e+000,5.301332e+001,-5.706933e-005,0.000000e+000,3,9.713976e-001,0.000000e+000,,,,,,,,,,,,,,32,1,4.000000e+000,1.228333e-003,0.000000e+000,0,,0,
1524203489.071,,0.000000e+000,5.300717e+001,-5.842445e-005,0.000000e+000,3,9.704567e-001,0.000000e+000,,,,,,,,,,,,,,32,1,4.000000e+000,1.848221e-002,0.000000e+000,0,,0,
1524203514.591,,0.000000e+000,5.300040e+001,-5.951770e-005,0.000000e+000,3,9.716895e-001,0.000000e+000,,,,,,,,,,,,,,32,1,4.000000e+000,2.468109e-003,0.000000e+000,0,,0,
1524203539.611,,0.000000e+000,5.300533e+001,-6.016546e-005,0.000000e+000,3,9.705491e-001,0.000000e+000,,,,,,,,,,,,,,32,1,4.000000e+000,4.928589e-003,0.000000e+000,0,,0,
1524203565.941,,0.000000e+000,5.300162e+001,-6.096003e-005,0.000000e+000,3,9.721491e-001,0.000000e+000,,,,,,,,,,,,,,32,1,4.000000e+000,4.920959e-003,0.000000e+000,0,,0,
1524203591.461,,0.000000e+000,5.300101e+001,-6.148568e-005,0.000000e+000,3,9.731768e-001,0.000000e+000,,,,,,,,,,,,,,32,1,4.000000e+000,3.700256e-003,0.000000e+000,0,,0,
1524203616.661,,0.000000e+000,5.300040e+001,-6.191300e-005,0.000000e+000,3,9.722230e-001,0.000000e+000,,,,,,,,,,,,,,32,1,4.000000e+000,2.468109e-003,0.000000e+000,0,,0,
1524203641.631,,0.000000e+000,5.299363e+001,-6.233717e-005,0.000000e+000,3,9.716653e-001,0.000000e+000,,,,,,,,,,,,,,32,1,4.000000e+000,1.228333e-003,0.000000e+000,0,,0,
1524203667.101,,0.000000e+000,5.299854e+001,-6.273071e-005,0.000000e+000,3,9.727229e-001,0.000000e+000,,,,,,,,,,,,,,32,1,4.000000e+000,1.232147e-003,0.000000e+000,0,,0,
1524203692.581,,0.000000e+000,5.299855e+001,-6.315371e-005,0.000000e+000,3,9.713523e-001,0.000000e+000,,,,,,,,,,,,,,32,1,4.000000e+000,3.700256e-003,0.000000e+000,0,,0,
1524203717.551,,0.000000e+000,5.299855e+001,-6.352806e-005,0.000000e+000,3,9.716497e-001,0.000000e+000,,,,,,,,,,,,,,32,1,4.000000e+000,3.700256e-003,0.000000e+000,0,,0,
1524203743.721,,0.000000e+000,5.299670e+001,-6.381430e-005,0.000000e+000,3,9.714556e-001,0.000000e+000,,,,,,,,,,,,,,32,1,4.000000e+000,2.449036e-003,0.000000e+000,0,,0,
1524203768.871,,0.000000e+000,5.299916e+001,-6.410152e-005,0.000000e+000,3,9.703982e-001,0.000000e+000,,,,,,,,,,,,,,32,1,4.000000e+000,0.000000e+000,0.000000e+000,0,,0,
1524203793.651,,0.000000e+000,5.299486e+001,-6.429799e-005,0.000000e+000,3,9.712548e-001,0.000000e+000,,,,,,,,,,,,,,32,1,4.000000e+000,8.609772e-003,0.000000e+000,0,,0,
1524203818.991,,0.000000e+000,5.299794e+001,-6.456656e-005,0.000000e+000,3,9.700013e-001,0.000000e+000,,,,,,,,,,,,,,32,1,4.000000e+000,9.849548e-003,0.000000e+000,0,,0,
1524203844.751,,0.000000e+000,5.299424e+001,-6.482130e-005,0.000000e+000,3,9.725886e-001,0.000000e+000,,,,,,,,,,,,,,32,1,4.000000e+000,4.920959e-003,0.000000e+000,0,,0,
1524203869.901,,0.000000e+000,5.299363e+001,-6.507374e-005,0.000000e+000,3,9.733395e-001,0.000000e+000,,,,,,,,,,,,,,32,1,4.000000e+000,1.228333e-003,0.000000e+000,0,,0,
1524203894.901,,0.000000e+000,5.299916e+001,-6.528126e-005,0.000000e+000,3,9.730048e-001,0.000000e+000,,,,,,,,,,,,,,32,1,4.000000e+000,2.471924e-003,0.000000e+000,0,,0,
1524203919.681,,0.000000e+000,5.299486e+001,-6.557964e-005,0.000000e+000,3,9.729928e-001,0.000000e+000,,,,,,,,,,,,,,32,1,4.000000e+000,3.688812e-003,0.000000e+000,0,,0,
1524203944.081,,0.000000e+000,5.300163e+001,-6.565761e-005,0.000000e+000,3,9.713832e-001,0.000000e+000,,,,,,,,,,,,,,32,1,4.000000e+000,9.849548e-003,0.000000e+000,0,,0,
1524203969.681,,0.000000e+000,5.299732e+001,-6.585872e-005,0.000000e+000,3,9.729423e-001,0.000000e+000,,,,,,,,,,,,,,32,1,4.000000e+000,6.160736e-003,0.000000e+000,0,,0,
1524203995.851,,0.000000e+000,5.299486e+001,-6.605520e-005,0.000000e+000,3,9.720059e-001,0.000000e+000,,,,,,,,,,,,,,32,1,4.000000e+000,1.353836e-002,0.000000e+000,0,,0,
1524204021.131,,0.000000e+000,5.299485e+001,-6.612634e-005,0.000000e+000,3,9.714658e-001,0.000000e+000,,,,,,,,,,,,,,32,1,4.000000e+000,6.149292e-003,0.000000e+000,0,,0,
1524204046.601,,0.000000e+000,5.299425e+001,-6.632196e-005,0.000000e+000,3,9.709637e-001,0.000000e+000,,,,,,,,,,,,,,32,1,4.000000e+000,2.468109e-003,0.000000e+000,0,,0,
1524204072.131,,0.000000e+000,5.299978e+001,-6.648307e-005,0.000000e+000,3,9.707506e-001,0.000000e+000,,,,,,,,,,,,,,32,1,4.000000e+000,3.700256e-003,0.000000e+000,0,,0,
1524204097.511,,0.000000e+000,5.299732e+001,-6.666181e-005,0.000000e+000,3,9.712681e-001,0.000000e+000,,,,,,,,,,,,,,32,1,4.000000e+000,3.681183e-003,0.000000e+000,0,,0,
1524204122.662,,0.000000e+000,5.299609e+001,-6.675615e-005,0.000000e+000,3,9.708512e-001,0.000000e+000,,,,,,,,,,,,,,32,1,4.000000e+000,1.220703e-003,0.000000e+000,0,,0,
1524204147.642,,0.000000e+000,5.299916e+001,-6.688349e-005,0.000000e+000,3,9.704410e-001,0.000000e+000,,,,,,,,,,,,,,32,1,4.000000e+000,2.471924e-003,0.000000e+000,0,,0,
1524204172.492,,0.000000e+000,5.300040e+001,-6.705631e-005,0.000000e+000,3,9.705428e-001,0.000000e+000,,,,,,,,,,,,,,32,1,4.000000e+000,1.477814e-002,0.000000e+000,0,,0,
1524204198.062,,0.000000e+000,5.299731e+001,-6.715519e-005,0.000000e+000,3,9.709539e-001,0.000000e+000,,,,,,,,,,,,,,32,1,4.000000e+000,1.228333e-003,0.000000e+000,0,,0,
1524204223.282,,0.000000e+000,5.299731e+001,-6.728522e-005,0.000000e+000,3,9.723879e-001,0.000000e+000,,,,,,,,,,,,,,32,1,4.000000e+000,1.228333e-003,0.000000e+000,0,,0,
1524204248.802,,0.000000e+000,5.300101e+001,-6.744683e-005,0.000000e+000,3,9.731014e-001,0.000000e+000,,,,,,,,,,,,,,32,1,4.000000e+000,3.700256e-003,0.000000e+000,0,,0,
1524204273.242,,0.000000e+000,5.299978e+001,-6.754864e-005,0.000000e+000,3,9.722320e-001,0.000000e+000,,,,,,,,,,,,,,32,1,4.000000e+000,3.700256e-003,0.000000e+000,0,,0,
1524204298.072,,0.000000e+000,5.299978e+001,-6.767992e-005,0.000000e+000,3,9.711509e-001,0.000000e+000,,,,,,,,,,,,,,32,1,4.000000e+000,1.239777e-003,0.000000e+000,0,,0,
1524204323.462,,0.000000e+000,5.299855e+001,-6.774814e-005,0.000000e+000,3,9.712561e-001,0.000000e+000,,,,,,,,,,,,,,32,1,4.000000e+000,3.700256e-003,0.000000e+000,0,,0,
1524204348.772,,0.000000e+000,5.299609e+001,-6.795787e-005,0.000000e+000,3,9.727913e-001,0.000000e+000,,,,,,,,,,,,,,32,1,4.000000e+000,1.220703e-003,0.000000e+000,0,,0,
1524204373.532,,0.000000e+000,5.300040e+001,-6.797627e-005,0.000000e+000,3,9.729407e-001,0.000000e+000,,,,,,,,,,,,,,32,1,4.000000e+000,0.000000e+000,0.000000e+000,0,,0,
1524204398.752,,0.000000e+000,5.299731e+001,-6.813282e-005,0.000000e+000,3,9.719424e-001,0.000000e+000,,,,,,,,,,,,,,32,1,4.000000e+000,1.228333e-003,0.000000e+000,0,,0,
1524204424.502,,0.000000e+000,5.300101e+001,-6.821177e-005,0.000000e+000,3,9.721167e-001,0.000000e+000,,,,,,,,,,,,,,32,1,4.000000e+000,1.228333e-003,0.000000e+000,0,,0,
1524204449.762,,0.000000e+000,5.299855e+001,-6.831370e-005,0.000000e+000,3,9.718967e-001,0.000000e+000,,,,,,,,,,,,,,32,1,4.000000e+000,3.700256e-003,0.000000e+000,0,,0,
1524204475.182,,0.000000e+000,5.299978e+001,-6.839837e-005,0.000000e+000,3,9.720910e-001,0.000000e+000,,,,,,,,,,,,,,32,1,4.000000e+000,8.602142e-003,0.000000e+000,0,,0,
1524204500.842,,0.000000e+000,5.299854e+001,-6.851715e-005,0.000000e+000,3,9.716228e-001,0.000000e+000,,,,,,,,,,,,,,32,1,4.000000e+000,1.232147e-003,0.000000e+000,0,,0,
1524204526.332,,0.000000e+000,5.299978e+001,-6.858550e-005,0.000000e+000,3,9.722916e-001,0.000000e+000,,,,,,,,,,,,,,32,1,4.000000e+000,6.160736e-003,0.000000e+000,0,,0,
1524204551.322,,0.000000e+000,5.299731e+001,-6.867491e-005,0.000000e+000,3,9.722007e-001,0.000000e+000,,,,,,,,,,,,,,32,1,4.000000e+000,1.228333e-003,0.000000e+000,0,,0,
1524204576.842,,0.000000e+000,5.299978e+001,-6.882416e-005,0.000000e+000,3,9.732851e-001,0.000000e+000,,,,,,,,,,,,,,32,1,4.000000e+000,3.700256e-003,0.000000e+000,0,,0,
1524204601.852,,0.000000e+000,5.299363e+001,-6.890106e-005,0.000000e+000,3,9.734197e-001,0.000000e+000,,,,,,,,,,,,,,32,1,4.000000e+000,1.107025e-002,0.000000e+000,0,,0,
1524204627.542,,0.000000e+000,5.299916e+001,-6.899821e-005,0.000000e+000,3,9.729053e-001,0.000000e+000,,,,,,,,,,,,,,32,1,4.000000e+000,9.841919e-003,0.000000e+000,0,,0,
1524204652.322,,0.000000e+000,5.299978e+001,-6.908360e-005,0.000000e+000,3,9.731794e-001,0.000000e+000,,,,,,,,,,,,,,32,1,4.000000e+000,3.700256e-003,0.000000e+000,0,,0,
1524204677.172,,0.000000e+000,5.300408e+001,-6.913024e-005,0.000000e+000,3,9.726941e-001,0.000000e+000,,,,,,,,,,,,,,32,1,4.000000e+000,0.000000e+000,0.000000e+000,0,,0,
1524204703.542,,0.000000e+000,5.299670e+001,-6.927066e-005,0.000000e+000,3,9.724461e-001,0.000000e+000,,,,,,,,,,,,,,32,1,4.000000e+000,2.449036e-003,0.000000e+000,0,,0,
1524204728.482,,0.000000e+000,5.300409e+001,-6.930758e-005,0.000000e+000,3,9.721557e-001,0.000000e+000,,,,,,,,,,,,,,32,1,4.000000e+000,1.232147e-002,0.000000e+000,0,,0,
1524204753.642,,0.000000e+000,5.299609e+001,-6.938865e-005,0.000000e+000,3,9.720305e-001,0.000000e+000,,,,,,,,,,,,,,32,1,4.000000e+000,1.220703e-003,0.000000e+000,0,,0,
1524204778.342,,0.000000e+000,5.299609e+001,-6.940030e-005,0.000000e+000,3,9.725310e-001,0.000000e+000,,,,,,,,,,,,,,32,1,4.000000e+000,1.220703e-003,0.000000e+000,0,,0,
1524204803.332,,0.000000e+000,5.299978e+001,-6.947971e-005,0.000000e+000,3,9.719793e-001,0.000000e+000,,,,,,,,,,,,,,32,1,4.000000e+000,1.108170e-002,0.000000e+000,0,,0,
1524204828.302,,0.000000e+000,5.300163e+001,-6.953971e-005,0.000000e+000,3,9.719667e-001,0.000000e+000,,,,,,,,,,,,,,32,1,4.000000e+000,7.392883e-003,0.000000e+000,0,,0,
1524204853.383,,0.000000e+000,5.300040e+001,-6.964722e-005,0.000000e+000,3,9.720992e-001,0.000000e+000,,,,,,,,,,,,,,32,1,4.000000e+000,1.231003e-002,0.000000e+000,0,,0,
1524204878.233,,0.000000e+000,5.299978e+001,-6.974170e-005,0.000000e+000,3,9.720069e-001,0.000000e+000,,,,,,,,,,,,,,32,1,4.000000e+000,1.353836e-002,0.000000e+000,0,,0,
1524204903.233,,0.000000e+000,5.299055e+001,-6.977336e-005,0.000000e+000,3,9.727255e-001,0.000000e+000,,,,,,,,,,,,,,32,1,4.000000e+000,1.231003e-002,0.000000e+000,0,,0,
1524204928.213,,0.000000e+000,5.299670e+001,-6.988527e-005,0.000000e+000,3,9.722311e-001,0.000000e+000,,,,,,,,,,,,,,32,1,4.000000e+000,9.849548e-003,0.000000e+000,0,,0,
1524204953.183,,0.000000e+000,5.299239e+001,-6.990335e-005,0.000000e+000,3,9.721249e-001,0.000000e+000,,,,,,,,,,,,,,32,1,4.000000e+000,3.688812e-003,0.000000e+000,0,,0,
1524204978.133,,0.000000e+000,5.300348e+001,-6.998734e-005,0.000000e+000,3,9.718569e-001,0.000000e+000,,,,,,,,,,,,,,32,1,4.000000e+000,1.109314e-002,0.000000e+000,0,,0,
1524205003.103,,0.000000e+000,5.300594e+001,-7.006719e-005,0.000000e+000,3,9.722128e-001,0.000000e+000,,,,,,,,,,,,,,32,1,4.000000e+000,1.228333e-003,0.000000e+000,0,,0,
1524205028.073,,0.000000e+000,5.299547e+001,-7.008242e-005,0.000000e+000,3,9.719452e-001,0.000000e+000,,,,,,,,,,,,,,32,1,4.000000e+000,1.723099e-002,0.000000e+000,0,,0,
1524205053.063,,0.000000e+000,5.299793e+001,-7.016315e-005,0.000000e+000,3,9.718650e-001,0.000000e+000,,,,,,,,,,,,,,32,1,4.000000e+000,0.000000e+000,0.000000e+000,0,,0,
1524205078.023,,0.000000e+000,5.299731e+001,-7.022142e-005,0.000000e+000,3,9.714068e-001,0.000000e+000,,,,,,,,,,,,,,32,1,4.000000e+000,1.228333e-003,0.000000e+000,0,,0,
1524205103.023,,0.000000e+000,5.299609e+001,-7.031109e-005,0.000000e+000,3,9.717168e-001,0.000000e+000,,,,,,,,,,,,,,32,1,4.000000e+000,6.149292e-003,0.000000e+000,0,,0,
1524205127.993,,0.000000e+000,5.299731e+001,-7.037385e-005,0.000000e+000,3,9.720978e-001,0.000000e+000,,,,,,,,,,,,,,32,1,4.000000e+000,1.228333e-003,0.000000e+000,0,,0,
1524205152.943,,0.000000e+000,5.299239e+001,-7.040938e-005,0.000000e+000,3,9.717382e-001,0.000000e+000,,,,,,,,,,,,,,32,1,4.000000e+000,1.232147e-003,0.000000e+000,0,,0,
1524205178.103,,0.000000e+000,5.299916e+001,-7.043792e-005,0.000000e+000,3,9.721499e-001,0.000000e+000,,,,,,,,,,,,,,32,1,4.000000e+000,2.471924e-003,0.000000e+000,0,,0,
1524205203.283,,0.000000e+000,5.299486e+001,-7.049762e-005,0.000000e+000,3,9.712763e-001,0.000000e+000,,,,,,,,,,,,,,32,1,4.000000e+000,1.108170e-002,0.000000e+000,0,,0,
1524205228.233,,0.000000e+000,5.300285e+001,-7.048422e-005,0.000000e+000,3,9.715476e-001,0.000000e+000,,,,,,,,,,,,,,32,1,4.000000e+000,2.452850e-003,0.000000e+000,0,,0,
1524205253.163,,0.000000e+000,5.299486e+001,-7.059189e-005,0.000000e+000,3,9.717907e-001,0.000000e+000,,,,,,,,,,,,,,32,1,4.000000e+000,1.239777e-003,0.000000e+000,0,,0,
1524205278.653,,0.000000e+000,5.299486e+001,-7.060619e-005,0.000000e+000,3,9.710774e-001,0.000000e+000,,,,,,,,,,,,,,32,1,4.000000e+000,1.108170e-002,0.000000e+000,0,,0,
1524205303.933,,0.000000e+000,5.299793e+001,-7.076823e-005,0.000000e+000,3,9.708662e-001,0.000000e+000,,,,,,,,,,,,,,32,1,4.000000e+000,1.230240e-002,0.000000e+000,0,,0,
1524205328.513,,0.000000e+000,5.299731e+001,-7.080047e-005,0.000000e+000,3,9.710500e-001,0.000000e+000,,,,,,,,,,,,,,32,1,4.000000e+000,1.228333e-003,0.000000e+000,0,,0,
1524205353.433,,0.000000e+000,5.299794e+001,-7.084369e-005,0.000000e+000,3,9.713675e-001,0.000000e+000,,,,,,,,,,,,,,32,1,4.000000e+000,4.920959e-003,0.000000e+000,0,,0,
1524205378.313,,0.000000e+000,5.300040e+001,-7.087705e-005,0.000000e+000,3,9.711759e-001,0.000000e+000,,,,,,,,,,,,,,32,1,4.000000e+000,2.468109e-003,0.000000e+000,0,,0,
1524205403.603,,0.000000e+000,5.299854e+001,-7.093964e-005,0.000000e+000,3,9.710469e-001,0.000000e+000,,,,,,,,,,,,,,32,1,4.000000e+000,1.232147e-003,0.000000e+000,0,,0,
1524205428.703,,0.000000e+000,5.299486e+001,-7.097125e-005,0.000000e+000,3,9.717671e-001,0.000000e+000,,,,,,,,,,,,,,32,1,4.000000e+000,3.688812e-003,0.000000e+000,0,,0,
1524205454.213,,0.000000e+000,5.299855e+001,-7.098490e-005,0.000000e+000,3,9.715067e-001,0.000000e+000,,,,,,,,,,,,,,32,1,4.000000e+000,6.149292e-003,0.000000e+000,0,,0,
1524205479.273,,0.000000e+000,5.299978e+001,-7.107703e-005,0.000000e+000,3,9.730638e-001,0.000000e+000,,,,,,,,,,,,,,32,1,4.000000e+000,1.108170e-002,0.000000e+000,0,,0,
1524205504.213,,0.000000e+000,5.299732e+001,-7.115948e-005,0.000000e+000,3,9.726827e-001,0.000000e+000,,,,,,,,,,,,,,32,1,4.000000e+000,3.681183e-003,0.000000e+000,0,,0,
1524205529.173,,0.000000e+000,5.299547e+001,-7.124859e-005,0.000000e+000,3,9.725615e-001,0.000000e+000,,,,,,,,,,,,,,32,1,4.000000e+000,4.917145e-003,0.000000e+000,0,,0,
1524205554.154,,0.000000e+000,5.299793e+001,-7.128325e-005,0.000000e+000,3,9.720265e-001,0.000000e+000,,,,,,,,,,,,,,32,1,4.000000e+000,2.460480e-003,0.000000e+000,0,,0,
1524205579.264,,0.000000e+000,5.299855e+001,-7.128075e-005,0.000000e+000,3,9.728391e-001,0.000000e+000,,,,,,,,,,,,,,32,1,4.000000e+000,6.149292e-003,0.000000e+000,0,,0,
1524205604.164,,0.000000e+000,5.299854e+001,-7.136544e-005,0.000000e+000,3,9.728783e-001,0.000000e+000,,,,,,,,,,,,,,32,1,4.000000e+000,1.232147e-003,0.000000e+000,0,,0,
1524205629.134,,0.000000e+000,5.299547e+001,-7.139928e-005,0.000000e+000,3,9.723613e-001,0.000000e+000,,,,,,,,,,,,,,32,1,4.000000e+000,2.460480e-003,0.000000e+000,0,,0,
1524205654.104,,0.000000e+000,5.299916e+001,-7.145879e-005,0.000000e+000,3,9.721871e-001,0.000000e+000,,,,,,,,,,,,,,32,1,4.000000e+000,0.000000e+000,0.000000e+000,0,,0,
1524205679.154,,0.000000e+000,5.299916e+001,-7.149816e-005,0.000000e+000,3,9.730752e-001,0.000000e+000,,,,,,,,,,,,,,32,1,4.000000e+000,0.000000e+000,0.000000e+000,0,,0,
1524205704.124,,0.000000e+000,5.299486e+001,-7.159894e-005,0.000000e+000,3,9.725406e-001,0.000000e+000,,,,,,,,,,,,,,32,1,4.000000e+000,1.239777e-003,0.000000e+000,0,,0,
1524205729.094,,0.000000e+000,5.300040e+001,-7.156008e-005,0.000000e+000,3,9.724787e-001,0.000000e+000,,,,,,,,,,,,,,32,1,4.000000e+000,2.468109e-003,0.000000e+000,0,,0,
1524205754.144,,0.000000e+000,5.299854e+001,-7.164011e-005,0.000000e+000,3,9.729314e-001,0.000000e+000,,,,,,,,,,,,,,32,1,4.000000e+000,1.232147e-003,0.000000e+000,0,,0,
1524205779.734,,0.000000e+000,5.299916e+001,-7.169351e-005,0.000000e+000,3,9.726084e-001,0.000000e+000,,,,,,,,,,,,,,32,1,4.000000e+000,0.000000e+000,0.000000e+000,0,,0,
1524205804.714,,0.000000e+000,5.299916e+001,-7.179553e-005,0.000000e+000,3,9.736845e-001,0.000000e+000,,,,,,,,,,,,,,32,1,4.000000e+000,2.471924e-003,0.000000e+000,0,,0,
1524205829.904,,0.000000e+000,5.299117e+001,-7.175692e-005,0.000000e+000,3,9.724657e-001,0.000000e+000,,,,,,,,,,,,,,32,1,4.000000e+000,8.628845e-003,0.000000e+000,0,,0,
1524205854.884,,0.000000e+000,5.299793e+001,-7.176521e-005,0.000000e+000,3,9.727121e-001,0.000000e+000,,,,,,,,,,,,,,32,1,4.000000e+000,0.000000e+000,0.000000e+000,0,,0,
1524205880.814,,0.000000e+000,5.299855e+001,-7.185214e-005,0.000000e+000,3,9.726874e-001,0.000000e+000,,,,,,,,,,,,,,32,1,4.000000e+000,3.700256e-003,0.000000e+000,0,,0,
1524205906.214,,0.000000e+000,5.299547e+001,-7.185213e-005,0.000000e+000,3,9.718797e-001,0.000000e+000,,,,,,,,,,,,,,32,1,4.000000e+000,2.460480e-003,0.000000e+000,0,,0,
1524205931.774,,0.000000e+000,5.300224e+001,-7.185786e-005,0.000000e+000,3,9.720983e-001,0.000000e+000,,,,,,,,,,,,,,32,1,4.000000e+000,6.160736e-003,0.000000e+000,0,,0,
1524205956.764,,0.000000e+000,5.299731e+001,-7.191506e-005,0.000000e+000,3,9.717125e-001,0.000000e+000,,,,,,,,,,,,,,32,1,4.000000e+000,1.228333e-003,0.000000e+000,0,,0,
1524205982.444,,0.000000e+000,5.300162e+001,-7.196718e-005,0.000000e+000,3,9.716058e-001,0.000000e+000,,,,,,,,,,,,,,32,1,4.000000e+000,4.920959e-003,0.000000e+000,0,,0,
1524206008.134,,0.000000e+000,5.300224e+001,-7.192333e-005,0.000000e+000,3,9.726524e-001,0.000000e+000,,,,,,,,,,,,,,32,1,4.000000e+000,8.621216e-003,0.000000e+000,0,,0,
1524206033.244,,0.000000e+000,5.299793e+001,-7.204677e-005,0.000000e+000,3,9.713909e-001,0.000000e+000,,,,,,,,,,,,,,32,1,4.000000e+000,0.000000e+000,0.000000e+000,0,,0,
1524206058.544,,0.000000e+000,5.299916e+001,-7.212400e-005,0.000000e+000,3,9.733875e-001,0.000000e+000,,,,,,,,,,,,,,32,1,4.000000e+000,4.928589e-003,0.000000e+000,0,,0,
1524206084.104,,0.000000e+000,5.299732e+001,-7.217548e-005,0.000000e+000,3,9.724758e-001,0.000000e+000,,,,,,,,,,,,,,32,1,4.000000e+000,3.681183e-003,0.000000e+000,0,,0,
1524206109.494,,0.000000e+000,5.299486e+001,-7.212687e-005,0.000000e+000,3,9.715372e-001,0.000000e+000,,,,,,,,,,,,,,32,1,4.000000e+000,1.239777e-003,0.000000e+000,0,,0,
1524206134.374,,0.000000e+000,5.300410e+001,-7.217463e-005,0.000000e+000,3,9.718002e-001,0.000000e+000,,,,,,,,,,,,,,32,1,4.000000e+000,7.389069e-003,0.000000e+000,0,,0,
1524206159.364,,0.000000e+000,5.299609e+001,-7.221311e-005,0.000000e+000,3,9.715891e-001,0.000000e+000,,,,,,,,,,,,,,32,1,4.000000e+000,8.621216e-003,0.000000e+000,0,,0,
1524206185.264,,0.000000e+000,5.299486e+001,-7.223657e-005,0.000000e+000,3,9.708167e-001,0.000000e+000,,,,,,,,,,,,,,32,1,4.000000e+000,3.688812e-003,0.000000e+000,0,,0,
1524206210.314,,0.000000e+000,5.299978e+001,-7.227687e-005,0.000000e+000,3,9.706720e-001,0.000000e+000,,,,,,,,,,,,,,32,1,4.000000e+000,1.239777e-003,0.000000e+000,0,,0,
1524206235.404,,0.000000e+000,5.299731e+001,-7.229311e-005,0.000000e+000,3,9.713492e-001,0.000000e+000,,,,,,,,,,,,,,32,1,4.000000e+000,1.228333e-003,0.000000e+000,0,,0,
1524206260.405,,0.000000e+000,5.299916e+001,-7.236860e-005,0.000000e+000,3,9.709402e-001,0.000000e+000,,,,,,,,,,,,,,32,1,4.000000e+000,4.928589e-003,0.000000e+000,0,,0,
1524206285.355,,0.000000e+000,5.299916e+001,-7.243765e-005,0.000000e+000,3,9.711964e-001,0.000000e+000,,,,,,,,,,,,,,32,1,4.000000e+000,4.928589e-003,0.000000e+000,0,,0,
1524206310.335,,0.000000e+000,5.299547e+001,-7.243528e-005,0.000000e+000,3,9.716108e-001,0.000000e+000,,,,,,,,,,,,,,32,1,4.000000e+000,2.460480e-003,0.000000e+000,0,,0,
1524206335.405,,0.000000e+000,5.299978e+001,-7.241491e-005,0.000000e+000,3,9.719452e-001,0.000000e+000,,,,,,,,,,,,,,32,1,4.000000e+000,1.108170e-002,0.000000e+000,0,,0,
1524206360.515,,0.000000e+000,5.299731e+001,-7.252566e-005,0.000000e+000,3,9.718785e-001,0.000000e+000,,,,,,,,,,,,,,32,1,4.000000e+000,1.228333e-003,0.000000e+000,0,,0,
1524206385.425,,0.000000e+000,5.299424e+001,-7.250571e-005,0.000000e+000,3,9.705364e-001,0.000000e+000,,,,,,,,,,,,,,32,1,4.000000e+000,1.477814e-002,0.000000e+000,0,,0,
1524206410.745,,0.000000e+000,5.299978e+001,-7.256655e-005,0.000000e+000,3,9.710507e-001,0.000000e+000,,,,,,,,,,,,,,32,1,4.000000e+000,8.602142e-003,0.000000e+000,0,,0,
1524206435.855,,0.000000e+000,5.300039e+001,-7.259876e-005,0.000000e+000,3,9.727252e-001,0.000000e+000,,,,,,,,,,,,,,32,1,4.000000e+000,7.381439e-003,0.000000e+000,0,,0,
1524206460.985,,0.000000e+000,5.299855e+001,-7.256816e-005,0.000000e+000,3,9.717081e-001,0.000000e+000,,,,,,,,,,,,,,32,1,4.000000e+000,8.621216e-003,0.000000e+000,0,,0,
1524206485.825,,0.000000e+000,5.299855e+001,-7.262859e-005,0.000000e+000,3,9.715008e-001,0.000000e+000,,,,,,,,,,,,,,32,1,4.000000e+000,3.700256e-003,0.000000e+000,0,,0,
1524206510.975,,0.000000e+000,5.299916e+001,-7.274427e-005,0.000000e+000,3,9.719388e-001,0.000000e+000,,,,,,,,,,,,,,32,1,4.000000e+000,2.471924e-003,0.000000e+000,0,,0,
1524206536.215,,0.000000e+000,5.299854e+001,-7.268157e-005,0.000000e+000,3,9.711376e-001,0.000000e+000,,,,,,,,,,,,,,32,1,4.000000e+000,1.232147e-003,0.000000e+000,0,,0,
1524206562.005,,0.000000e+000,5.300040e+001,-7.275752e-005,0.000000e+000,3,9.723792e-001,0.000000e+000,,,,,,,,,,,,,,32,1,4.000000e+000,2.468109e-003,0.000000e+000,0,,0,
1524206586.455,,0.000000e+000,5.300040e+001,-7.277689e-005,0.000000e+000,3,9.718346e-001,0.000000e+000,,,,,,,,,,,,,,32,1,4.000000e+000,2.468109e-003,0.000000e+000,0,,0,
1524206611.475,,0.000000e+000,5.299916e+001,-7.279594e-005,0.000000e+000,3,9.716269e-001,0.000000e+000,,,,,,,,,,,,,,32,1,4.000000e+000,2.471924e-003,0.000000e+000,0,,0,
1524206637.115,,0.000000e+000,5.299609e+001,-7.294373e-005,0.000000e+000,3,9.716750e-001,0.000000e+000,,,,,,,,,,,,,,32,1,4.000000e+000,6.149292e-003,0.000000e+000,0,,0,
1524206662.085,,0.000000e+000,5.300101e+001,-7.293368e-005,0.000000e+000,3,9.716318e-001,0.000000e+000,,,,,,,,,,,,,,32,1,4.000000e+000,1.228333e-003,0.000000e+000,0,,0,
1524206687.205,,0.000000e+000,5.299670e+001,-7.297348e-005,0.000000e+000,3,9.721701e-001,0.000000e+000,,,,,,,,,,,,,,32,1,4.000000e+000,0.000000e+000,0.000000e+000,0,,0,
1524206712.395,,0.000000e+000,5.300040e+001,-7.299576e-005,0.000000e+000,3,9.725225e-001,0.000000e+000,,,,,,,,,,,,,,32,1,4.000000e+000,4.932404e-003,0.000000e+000,0,,0,
1524206737.295,,0.000000e+000,5.299978e+001,-7.296566e-005,0.000000e+000,3,9.715360e-001,0.000000e+000,,,,,,,,,,,,,,32,1,4.000000e+000,6.160736e-003,0.000000e+000,0,,0,
1524206762.865,,0.000000e+000,5.299793e+001,-7.302119e-005,0.000000e+000,3,9.711119e-001,0.000000e+000,,,,,,,,,,,,,,32,1,4.000000e+000,0.000000e+000,0.000000e+000,0,,0,
1524206787.805,,0.000000e+000,5.299794e+001,-7.301484e-005,0.000000e+000,3,9.718324e-001,0.000000e+000,,,,,,,,,,,,,,32,1,4.000000e+000,9.849548e-003,0.000000e+000,0,,0,
1524206812.915,,0.000000e+000,5.300101e+001,-7.303647e-005,0.000000e+000,3,9.716487e-001,0.000000e+000,,,,,,,,,,,,,,32,1,4.000000e+000,1.228333e-003,0.000000e+000,0,,0,
1524206837.775,,0.000000e+000,5.300224e+001,-7.309786e-005,0.000000e+000,3,9.712641e-001,0.000000e+000,,,,,,,,,,,,,,32,1,4.000000e+000,6.160736e-003,0.000000e+000,0,,0,
1524206862.735,,0.000000e+000,5.299732e+001,-7.309621e-005,0.000000e+000,3,9.716047e-001,0.000000e+000,,,,,,,,,,,,,,32,1,4.000000e+000,3.681183e-003,0.000000e+000,0,,0,
1524206887.715,,0.000000e+000,5.299978e+001,-7.316883e-005,0.000000e+000,3,9.718643e-001,0.000000e+000,,,,,,,,,,,,,,32,1,4.000000e+000,1.353836e-002,0.000000e+000,0,,0,
1524206912.825,,0.000000e+000,5.299547e+001,-7.320328e-005,0.000000e+000,3,9.718102e-001,0.000000e+000,,,,,,,,,,,,,,32,1,4.000000e+000,7.381439e-003,0.000000e+000,0,,0,
1524206937.665,,0.000000e+000,5.300533e+001,-7.318224e-005,0.000000e+000,3,9.715156e-001,0.000000e+000,,,,,,,,,,,,,,32,1,4.000000e+000,9.849548e-003,0.000000e+000,0,,0,
1524206962.645,,0.000000e+000,5.299547e+001,-7.322552e-005,0.000000e+000,3,9.718791e-001,0.000000e+000,,,,,,,,,,,,,,32,1,4.000000e+000,2.460480e-003,0.000000e+000,0,,0,
1524206988.326,,0.000000e+000,5.299609e+001,-7.323093e-005,0.000000e+000,3,9.727772e-001,0.000000e+000,,,,,,,,,,,,,,32,1,4.000000e+000,1.220703e-003,0.000000e+000,0,,0,
1524207013.296,,0.000000e+000,5.300163e+001,-7.329835e-005,0.000000e+000,3,9.726305e-001,0.000000e+000,,,,,,,,,,,,,,32,1,4.000000e+000,7.392883e-003,0.000000e+000,0,,0,
1524207038.276,,0.000000e+000,5.299609e+001,-7.333545e-005,0.000000e+000,3,9.725653e-001,0.000000e+000,,,,,,,,,,,,,,32,1,4.000000e+000,3.688812e-003,0.000000e+000,0,,0,
1524207063.476,,0.000000e+000,5.299793e+001,-7.329183e-005,0.000000e+000,3,9.724417e-001,0.000000e+000,,,,,,,,,,,,,,32,1,4.000000e+000,7.389069e-003,0.000000e+000,0,,0,
1524207088.346,,0.000000e+000,5.299670e+001,-7.339141e-005,0.000000e+000,3,9.723353e-001,0.000000e+000,,,,,,,,,,,,,,32,1,4.000000e+000,0.000000e+000,0.000000e+000,0,,0,
1524207113.586,,0.000000e+000,5.299609e+001,-7.345404e-005,0.000000e+000,3,9.720321e-001,0.000000e+000,,,,,,,,,,,,,,32,1,4.000000e+000,3.688812e-003,0.000000e+000,0,,0,
1524207138.836,,0.000000e+000,5.299978e+001,-7.345201e-005,0.000000e+000,3,9.718559e-001,0.000000e+000,,,,,,,,,,,,,,32,1,4.000000e+000,8.602142e-003,0.000000e+000,0,,0,
1524207163.696,,0.000000e+000,5.299978e+001,-7.342637e-005,0.000000e+000,3,9.717174e-001,0.000000e+000,,,,,,,,,,,,,,32,1,4.000000e+000,6.160736e-003,0.000000e+000,0,,0,
1524207188.386,,0.000000e+000,5.299917e+001,-7.350776e-005,0.000000e+000,3,9.719799e-001,0.000000e+000,,,,,,,,,,,,,,32,1,4.000000e+000,1.231003e-002,0.000000e+000,0,,0,
1524207213.916,,0.000000e+000,5.299547e+001,-7.350339e-005,0.000000e+000,3,9.716920e-001,0.000000e+000,,,,,,,,,,,,,,32,1,4.000000e+000,4.917145e-003,0.000000e+000,0,,0,
1524207238.916,,0.000000e+000,5.300286e+001,-7.348901e-005,0.000000e+000,3,9.715591e-001,0.000000e+000,,,,,,,,,,,,,,32,1,4.000000e+000,0.000000e+000,0.000000e+000,0,,0,
1524207263.926,,0.000000e+000,5.300162e+001,-7.351466e-005,0.000000e+000,3,9.717567e-001,0.000000e+000,,,,,,,,,,,,,,32,1,4.000000e+000,4.920959e-003,0.000000e+000,0,,0,
1524207288.836,,0.000000e+000,5.299793e+001,-7.352630e-005,0.000000e+000,3,9.717117e-001,0.000000e+000,,,,,,,,,,,,,,32,1,4.000000e+000,1.230240e-002,0.000000e+000,0,,0,
1524207314.176,,0.000000e+000,5.299486e+001,-7.360469e-005,0.000000e+000,3,9.722256e-001,0.000000e+000,,,,,,,,,,,,,,32,1,4.000000e+000,8.609772e-003,0.000000e+000,0,,0,
1524207339.466,,0.000000e+000,5.299793e+001,-7.356660e-005,0.000000e+000,3,9.712173e-001,0.000000e+000,,,,,,,,,,,,,,32,1,4.000000e+000,2.460480e-003,0.000000e+000,0,,0,
1524207364.906,,0.000000e+000,5.299670e+001,-7.357003e-005,0.000000e+000,3,9.709950e-001,0.000000e+000,,,,,,,,,,,,,,32,1,4.000000e+000,7.389069e-003,0.000000e+000,0,,0,
1524207390.206,,0.000000e+000,5.300101e+001,-7.373429e-005,0.000000e+000,3,9.714139e-001,0.000000e+000,,,,,,,,,,,,,,32,1,4.000000e+000,1.228333e-003,0.000000e+000,0,,0,
1524207415.366,,0.000000e+000,5.300409e+001,-7.367633e-005,0.000000e+000,3,9.711375e-001,0.000000e+000,,,,,,,,,,,,,,32,1,4.000000e+000,4.920959e-003,0.000000e+000,0,,0,
1524207440.456,,0.000000e+000,5.299609e+001,-7.371121e-005,0.000000e+000,3,9.709901e-001,0.000000e+000,,,,,,,,,,,,,,32,1,4.000000e+000,6.149292e-003,0.000000e+000,0,,0,
1524207465.556,,0.000000e+000,5.300101e+001,-7.371668e-005,0.000000e+000,3,9.716264e-001,0.000000e+000,,,,,,,,,,,,,,32,1,4.000000e+000,1.228333e-003,0.000000e+000,0,,0,
1524207490.556,,0.000000e+000,5.299978e+001,-7.379305e-005,0.000000e+000,3,9.714226e-001,0.000000e+000,,,,,,,,,,,,,,32,1,4.000000e+000,8.602142e-003,0.000000e+000,0,,0,
1524207515.356,,0.000000e+000,5.299916e+001,-7.383369e-005,0.000000e+000,3,9.713975e-001,0.000000e+000,,,,,,,,,,,,,,32,1,4.000000e+000,4.928589e-003,0.000000e+000,0,,0,
1524207540.556,,0.000000e+000,5.299793e+001,-7.384944e-005,0.000000e+000,3,9.722015e-001,0.000000e+000,,,,,,,,,,,,,,32,1,4.000000e+000,0.000000e+000,0.000000e+000,0,,0,
1524207565.746,,0.000000e+000,5.300101e+001,-7.383112e-005,0.000000e+000,3,9.714850e-001,0.000000e+000,,,,,,,,,,,,,,32,1,4.000000e+000,1.228333e-003,0.000000e+000,0,,0,
1524207592.256,,0.000000e+000,5.299732e+001,-7.395553e-005,0.000000e+000,3,9.722892e-001,0.000000e+000,,,,,,,,,,,,,,32,1,4.000000e+000,3.681183e-003,0.000000e+000,0,,0,
1524207618.176,,0.000000e+000,5.300348e+001,-7.386690e-005,0.000000e+000,3,9.719424e-001,0.000000e+000,,,,,,,,,,,,,,32,1,4.000000e+000,6.149292e-003,0.000000e+000,0,,0,
1524207643.776,,0.000000e+000,5.299670e+001,-7.393650e-005,0.000000e+000,3,9.726859e-001,0.000000e+000,,,,,,,,,,,,,,32,1,4.000000e+000,4.920959e-003,0.000000e+000,0,,0,
1524207668.756,,0.000000e+000,5.299978e+001,-7.391880e-005,0.000000e+000,3,9.727130e-001,0.000000e+000,,,,,,,,,,,,,,32,1,4.000000e+000,6.160736e-003,0.000000e+000,0,,0,
1524207693.727,,0.000000e+000,5.300040e+001,-7.399420e-005,0.000000e+000,3,9.728601e-001,0.000000e+000,,,,,,,,,,,,,,32,1,4.000000e+000,2.468109e-003,0.000000e+000,0,,0,
1524207718.707,,0.000000e+000,5.299793e+001,-7.400150e-005,0.000000e+000,3,9.720634e-001,0.000000e+000,,,,,,,,,,,,,,32,1,4.000000e+000,0.000000e+000,0.000000e+000,0,,0,
1524207743.557,,0.000000e+000,5.299670e+001,-7.402066e-005,0.000000e+000,3,9.716563e-001,0.000000e+000,,,,,,,,,,,,,,32,1,4.000000e+000,7.389069e-003,0.000000e+000,0,,0,
1524207768.487,,0.000000e+000,5.300286e+001,-7.409547e-005,0.000000e+000,3,9.715593e-001,0.000000e+000,,,,,,,,,,,,,,32,1,4.000000e+000,0.000000e+000,0.000000e+000,0,,0,
1524207793.627,,0.000000e+000,5.299548e+001,-7.412246e-005,0.000000e+000,3,9.715637e-001,0.000000e+000,,,,,,,,,,,,,,32,1,4.000000e+000,9.849548e-003,0.000000e+000,0,,0,
1524207818.457,,0.000000e+000,5.299670e+001,-7.403342e-005,0.000000e+000,3,9.717504e-001,0.000000e+000,,,,,,,,,,,,,,32,1,4.000000e+000,0.000000e+000,0.000000e+000,0,,0,
1524207844.027,,0.000000e+000,5.300101e+001,-7.410167e-005,0.000000e+000,3,9.713792e-001,0.000000e+000,,,,,,,,,,,,,,32,1,4.000000e+000,3.700256e-003,0.000000e+000,0,,0,
1524207869.007,,0.000000e+000,5.300163e+001,-7.413004e-005,0.000000e+000,3,9.718207e-001,0.000000e+000,,,,,,,,,,,,,,32,1,4.000000e+000,9.849548e-003,0.000000e+000,0,,0,
1524207893.987,,0.000000e+000,5.299916e+001,-7.415514e-005,0.000000e+000,3,9.717107e-001,0.000000e+000,,,,,,,,,,,,,,32,1,4.000000e+000,2.471924e-003,0.000000e+000,0,,0,
1524207918.957,,0.000000e+000,5.299978e+001,-7.415457e-005,0.000000e+000,3,9.719809e-001,0.000000e+000,,,,,,,,,,,,,,32,1,4.000000e+000,1.239777e-003,0.000000e+000,0,,0,
1524207943.937,,0.000000e+000,5.300224e+001,-7.418593e-005,0.000000e+000,3,9.714253e-001,0.000000e+000,,,,,,,,,,,,,,32,1,4.000000e+000,1.232147e-003,0.000000e+000,0,,0,
1524207968.907,,0.000000e+000,5.299301e+001,-7.423349e-005,0.000000e+000,3,9.712728e-001,0.000000e+000,,,,,,,,,,,,,,32,1,4.000000e+000,7.381439e-003,0.000000e+000,0,,0,
1524207993.887,,0.000000e+000,5.299731e+001,-7.422845e-005,0.000000e+000,3,9.716791e-001,0.000000e+000,,,,,,,,,,,,,,32,1,4.000000e+000,1.228333e-003,0.000000e+000,0,,0,
1524208018.867,,0.000000e+000,5.300409e+001,-7.423660e-005,0.000000e+000,3,9.717955e-001,0.000000e+000,,,,,,,,,,,,,,32,1,4.000000e+000,9.860992e-003,0.000000e+000,0,,0,
1524208043.837,,0.000000e+000,5.299916e+001,-7.425423e-005,0.000000e+000,3,9.717977e-001,0.000000e+000,,,,,,,,,,,,,,32,1,4.000000e+000,2.471924e-003,0.000000e+000,0,,0,
1524208068.217,,0.000000e+000,5.299916e+001,-7.429624e-005,0.000000e+000,3,9.712653e-001,0.000000e+000,,,,,,,,,,,,,,32,1,4.000000e+000,0.000000e+000,0.000000e+000,0,,0,
1524208093.777,,0.000000e+000,5.299793e+001,-7.431009e-005,0.000000e+000,3,9.716792e-001,0.000000e+000,,,,,,,,,,,,,,32,1,4.000000e+000,0.000000e+000,0.000000e+000,0,,0,
1524208118.747,,0.000000e+000,5.299855e+001,-7.433150e-005,0.000000e+000,3,9.715496e-001,0.000000e+000,,,,,,,,,,,,,,32,1,4.000000e+000,8.621216e-003,0.000000e+000,0,,0,
1524208143.737,,0.000000e+000,5.300163e+001,-7.434608e-005,0.000000e+000,3,9.715847e-001,0.000000e+000,,,,,,,,,,,,,,32,1,4.000000e+000,2.460480e-003,0.000000e+000,0,,0,
1524208168.697,,0.000000e+000,5.299855e+001,-7.440503e-005,0.000000e+000,3,9.712099e-001,0.000000e+000,,,,,,,,,,,,,,32,1,4.000000e+000,3.700256e-003,0.000000e+000,0,,0,
1524208193.787,,0.000000e+000,5.299793e+001,-7.440450e-005,0.000000e+000,3,9.708248e-001,0.000000e+000,,,,,,,,,,,,,,32,1,4.000000e+000,7.389069e-003,0.000000e+000,0,,0,
1524208219.247,,0.000000e+000,5.300040e+001,-7.441494e-005,0.000000e+000,3,9.708717e-001,0.000000e+000,,,,,,,,,,,,,,32,1,4.000000e+000,0.000000e+000,0.000000e+000,0,,0,
1524208244.557,,0.000000e+000,5.299363e+001,-7.445188e-005,0.000000e+000,3,9.705558e-001,0.000000e+000,,,,,,,,,,,,,,32,1,4.000000e+000,3.700256e-003,0.000000e+000,0,,0,
1524208269.647,,0.000000e+000,5.299793e+001,-7.449065e-005,0.000000e+000,3,9.710980e-001,0.000000e+000,,,,,,,,,,,,,,32,1,4.000000e+000,2.460480e-003,0.000000e+000,0,,0,
1524208294.687,,0.000000e+000,5.299670e+001,-7.453964e-005,0.000000e+000,3,9.716678e-001,0.000000e+000,,,,,,,,,,,,,,32,1,4.000000e+000,4.920959e-003,0.000000e+000,0,,0,
1524208320.647,,0.000000e+000,5.300285e+001,-7.458458e-005,0.000000e+000,3,9.734703e-001,0.000000e+000,,,,,,,,,,,,,,32,1,4.000000e+000,7.389069e-003,0.000000e+000,0,,0,
1524208345.627,,0.000000e+000,5.299854e+001,-7.462237e-005,0.000000e+000,3,9.723178e-001,0.000000e+000,,,,,,,,,,,,,,32,1,4.000000e+000,1.232147e-003,0.000000e+000,0,,0,
1524208370.627,,0.000000e+000,5.300040e+001,-7.456848e-005,0.000000e+000,3,9.717433e-001,0.000000e+000,,,,,,,,,,,,,,32,1,4.000000e+000,1.231003e-002,0.000000e+000,0,,0,
1524208395.707,,0.000000e+000,5.300224e+001,-7.462004e-005,0.000000e+000,3,9.712800e-001,0.000000e+000,,,,,,,,,,,,,,32,1,4.000000e+000,6.160736e-003,0.000000e+000,0,,0,
1524208421.328,,0.000000e+000,5.299793e+001,-7.463353e-005,0.000000e+000,3,9.720343e-001,0.000000e+000,,,,,,,,,,,,,,32,1,4.000000e+000,0.000000e+000,0.000000e+000,0,,0,
1524208446.298,,0.000000e+000,5.299978e+001,-7.459286e-005,0.000000e+000,3,9.726216e-001,0.000000e+000,,,,,,,,,,,,,,32,1,4.000000e+000,1.239777e-003,0.000000e+000,0,,0,
1524208471.288,,0.000000e+000,5.299731e+001,-7.459937e-005,0.000000e+000,3,9.725516e-001,0.000000e+000,,,,,,,,,,,,,,32,1,4.000000e+000,1.228333e-003,0.000000e+000,0,,0,
1524208496.188,,0.000000e+000,5.299670e+001,-7.466568e-005,0.000000e+000,3,9.715413e-001,0.000000e+000,,,,,,,,,,,,,,32,1,4.000000e+000,4.920959e-003,0.000000e+000,0,,0,
1524208521.178,,0.000000e+000,5.299670e+001,-7.470351e-005,0.000000e+000,3,9.717118e-001,0.000000e+000,,,,,,,,,,,,,,32,1,4.000000e+000,0.000000e+000,0.000000e+000,0,,0,
1524208546.118,,0.000000e+000,5.299855e+001,-7.472961e-005,0.000000e+000,3,9.714013e-001,0.000000e+000,,,,,,,,,,,,,,32,1,4.000000e+000,3.700256e-003,0.000000e+000,0,,0,
1524208571.108,,0.000000e+000,5.299670e+001,-7.466395e-005,0.000000e+000,3,9.715087e-001,0.000000e+000,,,,,,,,,,,,,,32,1,4.000000e+000,2.449036e-003,0.000000e+000,0,,0,
1524208596.328,,0.000000e+000,5.299794e+001,-7.474738e-005,0.000000e+000,3,9.718756e-001,0.000000e+000,,,,,,,,,,,,,,32,1,4.000000e+000,4.920959e-003,0.000000e+000,0,,0,
1524208621.618,,0.000000e+000,5.299855e+001,-7.473588e-005,0.000000e+000,3,9.714071e-001,0.000000e+000,,,,,,,,,,,,,,32,1,4.000000e+000,8.621216e-003,0.000000e+000,0,,0,
1524208646.828,,0.000000e+000,5.299916e+001,-7.476041e-005,0.000000e+000,3,9.712533e-001,0.000000e+000,,,,,,,,,,,,,,32,1,4.000000e+000,2.471924e-003,0.000000e+000,0,,0,
1524208671.978,,0.000000e+000,5.299732e+001,-7.476209e-005,0.000000e+000,3,9.714785e-001,0.000000e+000,,,,,,,,,,,,,,32,1,4.000000e+000,8.617401e-003,0.000000e+000,0,,0,
1524208697.098,,0.000000e+000,5.299732e+001,-7.480435e-005,0.000000e+000,3,9.726136e-001,0.000000e+000,,,,,,,,,,,,,,32,1,4.000000e+000,3.681183e-003,0.000000e+000,0,,0,
1524208709.908,,0.000000e+000,5.299731e+001,-7.483746e-005,0.000000e+000,3,9.720371e-001,0.000000e+000,,,,,,,,,,,,,,32,1,4.000000e+000,1.228333e-003,0.000000e+000,0,,0,