File: Experimental Raw Data/TC04-12-01K VRMac VRMde/Iterative Regression/TC04-12-01K_VRMac_55K_3000s.dc.dat
[Header]
TITLE,MPMS DC Measurement
BYAPP,MPMS Measurement,2.1,Summary
FILEOPENTIME, 1524068079.387000 4/18/2018, 10:14:39 AM

INFO, APPNAME, MPMS MultiVu Application, Revision 1.61,  Build 082

INFO, NAME, TC04-12-01K
INFO, WEIGHT, 1.000
INFO, AREA, 1.000
INFO, LENGTH, 1.000
INFO, SHAPE, 0
INFO, COMMENT,
INFO, SEQUENCE FILE: VRMac_55K_3000s_VRMde_55K.seq


INFO, BACKGROUND DATA FILE:, None


STARTUPAXIS,X,4,LINEAR,AUTO,0.000000,0.000000
STARTUPAXIS,Y1,5,LINEAR,AUTO,0.000000,0.000000


STARTUPGROUP,Longitudinal
FIELDGROUP,Longitudinal,1,2,3,4,5,6,7,8,9,15,16,17,18,27,28
FIELDGROUP,Transverse,1,2,3,4,10,11,12,13,14,19,20,21,22,27,28

PLOT_APPEARANCE,ALL,HORZ_GRID_ON,VERT_GRID_ON,MARKERS_AND_LINES

[Data]
Time,Comment,Field (Oe),Temperature (K),Long Moment (emu),Long Scan Std Dev,Long Algorithm,Long Reg Fit,Long Percent Error (%),Trans Moment (emu),Trans Scan Std Dev,Trans Algorithm,Trans Reg Fit,Trans Percent Error (%),Long Moment [w/o ABS] (emu),Long Scan Std Dev [w/o ABS],Long Reg Fit [w/o ABS],Long Percent Error [w/o ABS] (%),Trans Moment [w/o ABS] (emu),Trans Scan Std Dev [w/o ABS],Trans Reg Fit [w/o ABS],Trans Percent Error [w/o ABS] (%),Points per Scan,Scans per Measurement,Scan Length (cm),Delta Temp (K),Rot Position (deg),Error,EC Comp. Running,Using ABS,
1524068079.387,,0.000000e+000,5.506820e+001,-5.429789e-005,0.000000e+000,3,9.750988e-001,0.000000e+000,,,,,,,,,,,,,,32,1,4.000000e+000,1.581955e-002,0.000000e+000,0,,0,
1524068091.727,,0.000000e+000,5.504580e+001,-5.646090e-005,0.000000e+000,3,9.733250e-001,0.000000e+000,,,,,,,,,,,,,,32,1,4.000000e+000,5.271912e-003,0.000000e+000,0,,0,
1524068104.157,,0.000000e+000,5.504184e+001,-5.807700e-005,0.000000e+000,3,9.743243e-001,0.000000e+000,,,,,,,,,,,,,,32,1,4.000000e+000,2.639771e-003,0.000000e+000,0,,0,
1524068141.297,,0.000000e+000,5.501945e+001,-6.070584e-005,0.000000e+000,3,9.729860e-001,0.000000e+000,,,,,,,,,,,,,,32,1,4.000000e+000,1.052856e-002,0.000000e+000,0,,0,
1524068153.627,,0.000000e+000,5.500958e+001,-6.141739e-005,0.000000e+000,3,9.740575e-001,0.000000e+000,,,,,,,,,,,,,,32,1,4.000000e+000,1.319885e-003,0.000000e+000,0,,0,
1524068165.967,,0.000000e+000,5.501089e+001,-6.181499e-005,0.000000e+000,3,9.738955e-001,0.000000e+000,,,,,,,,,,,,,,32,1,4.000000e+000,1.312256e-003,0.000000e+000,0,,0,
1524068178.447,,0.000000e+000,5.500892e+001,-6.234260e-005,0.000000e+000,3,9.745172e-001,0.000000e+000,,,,,,,,,,,,,,32,1,4.000000e+000,5.260468e-003,0.000000e+000,0,,0,
1524068191.617,,0.000000e+000,5.500432e+001,-6.273421e-005,0.000000e+000,3,9.736063e-001,0.000000e+000,,,,,,,,,,,,,,32,1,4.000000e+000,3.940582e-003,0.000000e+000,0,,0,
1524068204.427,,0.000000e+000,5.500432e+001,-6.322295e-005,0.000000e+000,3,9.739186e-001,0.000000e+000,,,,,,,,,,,,,,32,1,4.000000e+000,1.300812e-003,0.000000e+000,0,,0,
1524068216.877,,0.000000e+000,5.500168e+001,-6.356670e-005,0.000000e+000,3,9.735475e-001,0.000000e+000,,,,,,,,,,,,,,32,1,4.000000e+000,6.580353e-003,0.000000e+000,0,,0,
1524068229.677,,0.000000e+000,5.499972e+001,-6.390196e-005,0.000000e+000,3,9.742566e-001,0.000000e+000,,,,,,,,,,,,,,32,1,4.000000e+000,5.268097e-003,0.000000e+000,0,,0,
1524068242.057,,0.000000e+000,5.500235e+001,-6.417881e-005,0.000000e+000,3,9.749799e-001,0.000000e+000,,,,,,,,,,,,,,32,1,4.000000e+000,1.052856e-002,0.000000e+000,0,,0,
1524068254.847,,0.000000e+000,5.500037e+001,-6.444780e-005,0.000000e+000,3,9.741648e-001,0.000000e+000,,,,,,,,,,,,,,32,1,4.000000e+000,1.319885e-003,0.000000e+000,0,,0,
1524068267.187,,0.000000e+000,5.500432e+001,-6.473751e-005,0.000000e+000,3,9.738813e-001,0.000000e+000,,,,,,,,,,,,,,32,1,4.000000e+000,1.300812e-003,0.000000e+000,0,,0,
1524068279.957,,0.000000e+000,5.499906e+001,-6.494066e-005,0.000000e+000,3,9.736289e-001,0.000000e+000,,,,,,,,,,,,,,32,1,4.000000e+000,9.220123e-003,0.000000e+000,0,,0,
1524068292.967,,0.000000e+000,5.500103e+001,-6.524005e-005,0.000000e+000,3,9.750255e-001,0.000000e+000,,,,,,,,,,,,,,32,1,4.000000e+000,2.639771e-003,0.000000e+000,0,,0,
1524068305.507,,0.000000e+000,5.499841e+001,-6.541714e-005,0.000000e+000,3,9.730258e-001,0.000000e+000,,,,,,,,,,,,,,32,1,4.000000e+000,1.052856e-002,0.000000e+000,0,,0,
1524068318.387,,0.000000e+000,5.499840e+001,-6.560502e-005,0.000000e+000,3,9.744261e-001,0.000000e+000,,,,,,,,,,,,,,32,1,4.000000e+000,5.260468e-003,0.000000e+000,0,,0,
1524068330.867,,0.000000e+000,5.499445e+001,-6.578559e-005,0.000000e+000,3,9.738426e-001,0.000000e+000,,,,,,,,,,,,,,32,1,4.000000e+000,1.052094e-002,0.000000e+000,0,,0,
1524068343.607,,0.000000e+000,5.499905e+001,-6.592427e-005,0.000000e+000,3,9.739660e-001,0.000000e+000,,,,,,,,,,,,,,32,1,4.000000e+000,1.319885e-003,0.000000e+000,0,,0,
1524068356.007,,0.000000e+000,5.500695e+001,-6.613899e-005,0.000000e+000,3,9.734284e-001,0.000000e+000,,,,,,,,,,,,,,32,1,4.000000e+000,1.184082e-002,0.000000e+000,0,,0,
1524068368.817,,0.000000e+000,5.499972e+001,-6.633180e-005,0.000000e+000,3,9.740595e-001,0.000000e+000,,,,,,,,,,,,,,32,1,4.000000e+000,7.900238e-003,0.000000e+000,0,,0,
1524068381.197,,0.000000e+000,5.499840e+001,-6.654139e-005,0.000000e+000,3,9.734069e-001,0.000000e+000,,,,,,,,,,,,,,32,1,4.000000e+000,7.900238e-003,0.000000e+000,0,,0,
1524068394.017,,0.000000e+000,5.500300e+001,-6.665508e-005,0.000000e+000,3,9.748935e-001,0.000000e+000,,,,,,,,,,,,,,32,1,4.000000e+000,6.580353e-003,0.000000e+000,0,,0,
1524068406.397,,0.000000e+000,5.500037e+001,-6.683063e-005,0.000000e+000,3,9.736282e-001,0.000000e+000,,,,,,,,,,,,,,32,1,4.000000e+000,1.184082e-002,0.000000e+000,0,,0,
1524068419.257,,0.000000e+000,5.499905e+001,-6.698640e-005,0.000000e+000,3,9.744354e-001,0.000000e+000,,,,,,,,,,,,,,32,1,4.000000e+000,3.948212e-003,0.000000e+000,0,,0,
1524068431.628,,0.000000e+000,5.500103e+001,-6.717652e-005,0.000000e+000,3,9.738415e-001,0.000000e+000,,,,,,,,,,,,,,32,1,4.000000e+000,7.888794e-003,0.000000e+000,0,,0,
1524068444.428,,0.000000e+000,5.499905e+001,-6.726455e-005,0.000000e+000,3,9.748805e-001,0.000000e+000,,,,,,,,,,,,,,32,1,4.000000e+000,1.319885e-003,0.000000e+000,0,,0,
1524068456.818,,0.000000e+000,5.500169e+001,-6.742019e-005,0.000000e+000,3,9.737493e-001,0.000000e+000,,,,,,,,,,,,,,32,1,4.000000e+000,3.959656e-003,0.000000e+000,0,,0,
1524068469.638,,0.000000e+000,5.499905e+001,-6.752965e-005,0.000000e+000,3,9.744473e-001,0.000000e+000,,,,,,,,,,,,,,32,1,4.000000e+000,3.948212e-003,0.000000e+000,0,,0,
1524068482.008,,0.000000e+000,5.500367e+001,-6.768582e-005,0.000000e+000,3,9.736221e-001,0.000000e+000,,,,,,,,,,,,,,32,1,4.000000e+000,0.000000e+000,0.000000e+000,0,,0,
1524068494.848,,0.000000e+000,5.500103e+001,-6.776920e-005,0.000000e+000,3,9.743030e-001,0.000000e+000,,,,,,,,,,,,,,32,1,4.000000e+000,1.052094e-002,0.000000e+000,0,,0,
1524068507.238,,0.000000e+000,5.499905e+001,-6.788847e-005,0.000000e+000,3,9.741636e-001,0.000000e+000,,,,,,,,,,,,,,32,1,4.000000e+000,1.319885e-003,0.000000e+000,0,,0,
1524068520.058,,0.000000e+000,5.499905e+001,-6.796990e-005,0.000000e+000,3,9.750280e-001,0.000000e+000,,,,,,,,,,,,,,32,1,4.000000e+000,3.948212e-003,0.000000e+000,0,,0,
1524068532.448,,0.000000e+000,5.499840e+001,-6.815797e-005,0.000000e+000,3,9.748142e-001,0.000000e+000,,,,,,,,,,,,,,32,1,4.000000e+000,2.628326e-003,0.000000e+000,0,,0,
1524068545.278,,0.000000e+000,5.499642e+001,-6.825080e-005,0.000000e+000,3,9.749408e-001,0.000000e+000,,,,,,,,,,,,,,32,1,4.000000e+000,3.940582e-003,0.000000e+000,0,,0,
1524068557.668,,0.000000e+000,5.499380e+001,-6.834019e-005,0.000000e+000,3,9.740058e-001,0.000000e+000,,,,,,,,,,,,,,32,1,4.000000e+000,1.308441e-003,0.000000e+000,0,,0,
1524068570.488,,0.000000e+000,5.500168e+001,-6.843733e-005,0.000000e+000,3,9.747574e-001,0.000000e+000,,,,,,,,,,,,,,32,1,4.000000e+000,6.580353e-003,0.000000e+000,0,,0,
1524068582.918,,0.000000e+000,5.499906e+001,-6.850310e-005,0.000000e+000,3,9.738279e-001,0.000000e+000,,,,,,,,,,,,,,32,1,4.000000e+000,9.220123e-003,0.000000e+000,0,,0,
1524068595.698,,0.000000e+000,5.499840e+001,-6.863231e-005,0.000000e+000,3,9.746147e-001,0.000000e+000,,,,,,,,,,,,,,32,1,4.000000e+000,2.628326e-003,0.000000e+000,0,,0,
1524068608.108,,0.000000e+000,5.499774e+001,-6.871674e-005,0.000000e+000,3,9.735580e-001,0.000000e+000,,,,,,,,,,,,,,32,1,4.000000e+000,3.940582e-003,0.000000e+000,0,,0,
1524068620.888,,0.000000e+000,5.499445e+001,-6.884796e-005,0.000000e+000,3,9.747866e-001,0.000000e+000,,,,,,,,,,,,,,32,1,4.000000e+000,2.628326e-003,0.000000e+000,0,,0,
1524068633.278,,0.000000e+000,5.499380e+001,-6.888912e-005,0.000000e+000,3,9.738134e-001,0.000000e+000,,,,,,,,,,,,,,32,1,4.000000e+000,6.572723e-003,0.000000e+000,0,,0,
1524068646.068,,0.000000e+000,5.499905e+001,-6.898343e-005,0.000000e+000,3,9.749294e-001,0.000000e+000,,,,,,,,,,,,,,32,1,4.000000e+000,1.319885e-003,0.000000e+000,0,,0,
1524068658.428,,0.000000e+000,5.499642e+001,-6.910077e-005,0.000000e+000,3,9.739787e-001,0.000000e+000,,,,,,,,,,,,,,32,1,4.000000e+000,3.940582e-003,0.000000e+000,0,,0,
1524068671.308,,0.000000e+000,5.499642e+001,-6.916690e-005,0.000000e+000,3,9.741942e-001,0.000000e+000,,,,,,,,,,,,,,32,1,4.000000e+000,3.940582e-003,0.000000e+000,0,,0,
1524068683.708,,0.000000e+000,5.500366e+001,-6.922230e-005,0.000000e+000,3,9.746506e-001,0.000000e+000,,,,,,,,,,,,,,32,1,4.000000e+000,7.900238e-003,0.000000e+000,0,,0,
1524068696.478,,0.000000e+000,5.500103e+001,-6.936383e-005,0.000000e+000,3,9.750412e-001,0.000000e+000,,,,,,,,,,,,,,32,1,4.000000e+000,7.888794e-003,0.000000e+000,0,,0,
1524068708.868,,0.000000e+000,5.499643e+001,-6.944210e-005,0.000000e+000,3,9.742800e-001,0.000000e+000,,,,,,,,,,,,,,32,1,4.000000e+000,1.184082e-002,0.000000e+000,0,,0,
1524068721.688,,0.000000e+000,5.499971e+001,-6.948461e-005,0.000000e+000,3,9.750112e-001,0.000000e+000,,,,,,,,,,,,,,32,1,4.000000e+000,2.639771e-003,0.000000e+000,0,,0,
1524068734.058,,0.000000e+000,5.499380e+001,-6.958801e-005,0.000000e+000,3,9.740875e-001,0.000000e+000,,,,,,,,,,,,,,32,1,4.000000e+000,6.572723e-003,0.000000e+000,0,,0,
1524068746.668,,0.000000e+000,5.500103e+001,-6.958115e-005,0.000000e+000,3,9.751914e-001,0.000000e+000,,,,,,,,,,,,,,32,1,4.000000e+000,5.279541e-003,0.000000e+000,0,,0,
1524068758.818,,0.000000e+000,5.499840e+001,-6.967098e-005,0.000000e+000,3,9.737965e-001,0.000000e+000,,,,,,,,,,,,,,32,1,4.000000e+000,5.260468e-003,0.000000e+000,0,,0,
1524068771.568,,0.000000e+000,5.499971e+001,-6.982534e-005,0.000000e+000,3,9.740863e-001,0.000000e+000,,,,,,,,,,,,,,32,1,4.000000e+000,2.639771e-003,0.000000e+000,0,,0,
1524068784.208,,0.000000e+000,5.500037e+001,-6.990280e-005,0.000000e+000,3,9.748762e-001,0.000000e+000,,,,,,,,,,,,,,32,1,4.000000e+000,3.959656e-003,0.000000e+000,0,,0,
1524068796.558,,0.000000e+000,5.499906e+001,-6.991583e-005,0.000000e+000,3,9.744368e-001,0.000000e+000,,,,,,,,,,,,,,32,1,4.000000e+000,6.580353e-003,0.000000e+000,0,,0,
1524068809.058,,0.000000e+000,5.500169e+001,-7.000481e-005,0.000000e+000,3,9.757285e-001,0.000000e+000,,,,,,,,,,,,,,32,1,4.000000e+000,1.184082e-002,0.000000e+000,0,,0,
1524068821.418,,0.000000e+000,5.499773e+001,-7.002689e-005,0.000000e+000,3,9.752684e-001,0.000000e+000,,,,,,,,,,,,,,32,1,4.000000e+000,1.308441e-003,0.000000e+000,0,,0,
1524068833.498,,0.000000e+000,5.500037e+001,-7.013276e-005,0.000000e+000,3,9.752311e-001,0.000000e+000,,,,,,,,,,,,,,32,1,4.000000e+000,3.959656e-003,0.000000e+000,0,,0,
1524068846.178,,0.000000e+000,5.499971e+001,-7.016728e-005,0.000000e+000,3,9.760956e-001,0.000000e+000,,,,,,,,,,,,,,32,1,4.000000e+000,2.639771e-003,0.000000e+000,0,,0,
1524068858.708,,0.000000e+000,5.500168e+001,-7.028454e-005,0.000000e+000,3,9.750144e-001,0.000000e+000,,,,,,,,,,,,,,32,1,4.000000e+000,6.580353e-003,0.000000e+000,0,,0,
1524068871.408,,0.000000e+000,5.500037e+001,-7.031907e-005,0.000000e+000,3,9.746426e-001,0.000000e+000,,,,,,,,,,,,,,32,1,4.000000e+000,1.319885e-003,0.000000e+000,0,,0,
1524068883.928,,0.000000e+000,5.499313e+001,-7.050738e-005,0.000000e+000,3,9.760647e-001,0.000000e+000,,,,,,,,,,,,,,32,1,4.000000e+000,1.050949e-002,0.000000e+000,0,,0,
1524068896.998,,0.000000e+000,5.499313e+001,-7.043198e-005,0.000000e+000,3,9.744281e-001,0.000000e+000,,,,,,,,,,,,,,32,1,4.000000e+000,1.050949e-002,0.000000e+000,0,,0,
1524068910.258,,0.000000e+000,5.499905e+001,-7.054581e-005,0.000000e+000,3,9.754032e-001,0.000000e+000,,,,,,,,,,,,,,32,1,4.000000e+000,1.319885e-003,0.000000e+000,0,,0,
1524068922.538,,0.000000e+000,5.499577e+001,-7.058833e-005,0.000000e+000,3,9.757118e-001,0.000000e+000,,,,,,,,,,,,,,32,1,4.000000e+000,1.052094e-002,0.000000e+000,0,,0,
1524068935.338,,0.000000e+000,5.499511e+001,-7.066439e-005,0.000000e+000,3,9.748329e-001,0.000000e+000,,,,,,,,,,,,,,32,1,4.000000e+000,1.319885e-003,0.000000e+000,0,,0,
1524068947.718,,0.000000e+000,5.499709e+001,-7.066783e-005,0.000000e+000,3,9.738314e-001,0.000000e+000,,,,,,,,,,,,,,32,1,4.000000e+000,1.052856e-002,0.000000e+000,0,,0,
1524068960.518,,0.000000e+000,5.499905e+001,-7.069030e-005,0.000000e+000,3,9.749705e-001,0.000000e+000,,,,,,,,,,,,,,32,1,4.000000e+000,3.948212e-003,0.000000e+000,0,,0,
1524068972.908,,0.000000e+000,5.500037e+001,-7.080060e-005,0.000000e+000,3,9.740350e-001,0.000000e+000,,,,,,,,,,,,,,32,1,4.000000e+000,1.319885e-003,0.000000e+000,0,,0,
1524068985.758,,0.000000e+000,5.499840e+001,-7.085190e-005,0.000000e+000,3,9.748172e-001,0.000000e+000,,,,,,,,,,,,,,32,1,4.000000e+000,5.260468e-003,0.000000e+000,0,,0,
1524068998.168,,0.000000e+000,5.499445e+001,-7.090698e-005,0.000000e+000,3,9.743336e-001,0.000000e+000,,,,,,,,,,,,,,32,1,4.000000e+000,2.628326e-003,0.000000e+000,0,,0,
1524069010.948,,0.000000e+000,5.499773e+001,-7.102536e-005,0.000000e+000,3,9.747947e-001,0.000000e+000,,,,,,,,,,,,,,32,1,4.000000e+000,1.308441e-003,0.000000e+000,0,,0,
1524069023.338,,0.000000e+000,5.499773e+001,-7.105662e-005,0.000000e+000,3,9.742588e-001,0.000000e+000,,,,,,,,,,,,,,32,1,4.000000e+000,1.308441e-003,0.000000e+000,0,,0,
1524069036.128,,0.000000e+000,5.499840e+001,-7.109798e-005,0.000000e+000,3,9.749735e-001,0.000000e+000,,,,,,,,,,,,,,32,1,4.000000e+000,2.628326e-003,0.000000e+000,0,,0,
1524069048.498,,0.000000e+000,5.500037e+001,-7.117722e-005,0.000000e+000,3,9.737809e-001,0.000000e+000,,,,,,,,,,,,,,32,1,4.000000e+000,6.587982e-003,0.000000e+000,0,,0,
1524069061.358,,0.000000e+000,5.500235e+001,-7.119309e-005,0.000000e+000,3,9.751765e-001,0.000000e+000,,,,,,,,,,,,,,32,1,4.000000e+000,2.639771e-003,0.000000e+000,0,,0,
1524069073.788,,0.000000e+000,5.500103e+001,-7.128873e-005,0.000000e+000,3,9.734955e-001,0.000000e+000,,,,,,,,,,,,,,32,1,4.000000e+000,5.279541e-003,0.000000e+000,0,,0,
1524069086.558,,0.000000e+000,5.500103e+001,-7.132068e-005,0.000000e+000,3,9.747447e-001,0.000000e+000,,,,,,,,,,,,,,32,1,4.000000e+000,5.279541e-003,0.000000e+000,0,,0,
1524069099.018,,0.000000e+000,5.500300e+001,-7.133345e-005,0.000000e+000,3,9.739991e-001,0.000000e+000,,,,,,,,,,,,,,32,1,4.000000e+000,9.220123e-003,0.000000e+000,0,,0,
1524069111.728,,0.000000e+000,5.500169e+001,-7.139597e-005,0.000000e+000,3,9.748052e-001,0.000000e+000,,,,,,,,,,,,,,32,1,4.000000e+000,1.319885e-003,0.000000e+000,0,,0,
1524069124.108,,0.000000e+000,5.500301e+001,-7.141422e-005,0.000000e+000,3,9.737830e-001,0.000000e+000,,,,,,,,,,,,,,32,1,4.000000e+000,1.319885e-003,0.000000e+000,0,,0,
1524069136.958,,0.000000e+000,5.499642e+001,-7.150467e-005,0.000000e+000,3,9.747967e-001,0.000000e+000,,,,,,,,,,,,,,32,1,4.000000e+000,3.940582e-003,0.000000e+000,0,,0,
1524069149.399,,0.000000e+000,5.500366e+001,-7.147875e-005,0.000000e+000,3,9.743750e-001,0.000000e+000,,,,,,,,,,,,,,32,1,4.000000e+000,2.620697e-003,0.000000e+000,0,,0,
1524069162.139,,0.000000e+000,5.499511e+001,-7.158690e-005,0.000000e+000,3,9.746194e-001,0.000000e+000,,,,,,,,,,,,,,32,1,4.000000e+000,1.319885e-003,0.000000e+000,0,,0,
1524069174.539,,0.000000e+000,5.499248e+001,-7.158012e-005,0.000000e+000,3,9.742714e-001,0.000000e+000,,,,,,,,,,,,,,32,1,4.000000e+000,1.319885e-003,0.000000e+000,0,,0,
1524069187.379,,0.000000e+000,5.499906e+001,-7.165456e-005,0.000000e+000,3,9.747742e-001,0.000000e+000,,,,,,,,,,,,,,32,1,4.000000e+000,6.580353e-003,0.000000e+000,0,,0,
1524069199.769,,0.000000e+000,5.499972e+001,-7.172330e-005,0.000000e+000,3,9.744484e-001,0.000000e+000,,,,,,,,,,,,,,32,1,4.000000e+000,5.268097e-003,0.000000e+000,0,,0,
1524069212.559,,0.000000e+000,5.500234e+001,-7.172627e-005,0.000000e+000,3,9.751885e-001,0.000000e+000,,,,,,,,,,,,,,32,1,4.000000e+000,1.578903e-002,0.000000e+000,0,,0,
1524069224.969,,0.000000e+000,5.500234e+001,-7.182841e-005,0.000000e+000,3,9.741318e-001,0.000000e+000,,,,,,,,,,,,,,32,1,4.000000e+000,1.578903e-002,0.000000e+000,0,,0,
1524069237.769,,0.000000e+000,5.500169e+001,-7.186985e-005,0.000000e+000,3,9.744794e-001,0.000000e+000,,,,,,,,,,,,,,32,1,4.000000e+000,3.959656e-003,0.000000e+000,0,,0,
1524069250.149,,0.000000e+000,5.499840e+001,-7.187392e-005,0.000000e+000,3,9.740577e-001,0.000000e+000,,,,,,,,,,,,,,32,1,4.000000e+000,2.628326e-003,0.000000e+000,0,,0,
1524069262.979,,0.000000e+000,5.500366e+001,-7.194487e-005,0.000000e+000,3,9.751205e-001,0.000000e+000,,,,,,,,,,,,,,32,1,4.000000e+000,2.620697e-003,0.000000e+000,0,,0,
1524069275.359,,0.000000e+000,5.499643e+001,-7.198520e-005,0.000000e+000,3,9.742700e-001,0.000000e+000,,,,,,,,,,,,,,32,1,4.000000e+000,9.208679e-003,0.000000e+000,0,,0,
1524069288.209,,0.000000e+000,5.499840e+001,-7.202299e-005,0.000000e+000,3,9.747103e-001,0.000000e+000,,,,,,,,,,,,,,32,1,4.000000e+000,2.628326e-003,0.000000e+000,0,,0,
1524069300.619,,0.000000e+000,5.500235e+001,-7.203264e-005,0.000000e+000,3,9.743043e-001,0.000000e+000,,,,,,,,,,,,,,32,1,4.000000e+000,1.052856e-002,0.000000e+000,0,,0,
1524069313.399,,0.000000e+000,5.499971e+001,-7.212181e-005,0.000000e+000,3,9.748660e-001,0.000000e+000,,,,,,,,,,,,,,32,1,4.000000e+000,2.639771e-003,0.000000e+000,0,,0,
1524069325.839,,0.000000e+000,5.499708e+001,-7.207961e-005,0.000000e+000,3,9.746255e-001,0.000000e+000,,,,,,,,,,,,,,32,1,4.000000e+000,5.260468e-003,0.000000e+000,0,,0,
1524069338.629,,0.000000e+000,5.500037e+001,-7.217146e-005,0.000000e+000,3,9.751627e-001,0.000000e+000,,,,,,,,,,,,,,32,1,4.000000e+000,3.959656e-003,0.000000e+000,0,,0,
1524069351.009,,0.000000e+000,5.499972e+001,-7.217351e-005,0.000000e+000,3,9.739658e-001,0.000000e+000,,,,,,,,,,,,,,32,1,4.000000e+000,7.900238e-003,0.000000e+000,0,,0,
1524069363.829,,0.000000e+000,5.499708e+001,-7.221613e-005,0.000000e+000,3,9.744616e-001,0.000000e+000,,,,,,,,,,,,,,32,1,4.000000e+000,5.260468e-003,0.000000e+000,0,,0,
1524069376.249,,0.000000e+000,5.499773e+001,-7.230781e-005,0.000000e+000,3,9.742349e-001,0.000000e+000,,,,,,,,,,,,,,32,1,4.000000e+000,1.308441e-003,0.000000e+000,0,,0,
1524069389.009,,0.000000e+000,5.499577e+001,-7.236242e-005,0.000000e+000,3,9.750599e-001,0.000000e+000,,,,,,,,,,,,,,32,1,4.000000e+000,2.632141e-003,0.000000e+000,0,,0,
1524069401.399,,0.000000e+000,5.500432e+001,-7.234714e-005,0.000000e+000,3,9.742569e-001,0.000000e+000,,,,,,,,,,,,,,32,1,4.000000e+000,3.940582e-003,0.000000e+000,0,,0,
1524069414.239,,0.000000e+000,5.499773e+001,-7.240765e-005,0.000000e+000,3,9.752045e-001,0.000000e+000,,,,,,,,,,,,,,32,1,4.000000e+000,1.308441e-003,0.000000e+000,0,,0,
1524069426.619,,0.000000e+000,5.499839e+001,-7.245237e-005,0.000000e+000,3,9.747197e-001,0.000000e+000,,,,,,,,,,,,,,32,1,4.000000e+000,0.000000e+000,0.000000e+000,0,,0,
1524069439.419,,0.000000e+000,5.499840e+001,-7.252146e-005,0.000000e+000,3,9.750833e-001,0.000000e+000,,,,,,,,,,,,,,32,1,4.000000e+000,5.260468e-003,0.000000e+000,0,,0,
1524069451.789,,0.000000e+000,5.499643e+001,-7.248218e-005,0.000000e+000,3,9.744431e-001,0.000000e+000,,,,,,,,,,,,,,32,1,4.000000e+000,1.184082e-002,0.000000e+000,0,,0,
1524069464.639,,0.000000e+000,5.499577e+001,-7.256351e-005,0.000000e+000,3,9.749013e-001,0.000000e+000,,,,,,,,,,,,,,32,1,4.000000e+000,2.632141e-003,0.000000e+000,0,,0,
1524069477.029,,0.000000e+000,5.499906e+001,-7.261089e-005,0.000000e+000,3,9.742090e-001,0.000000e+000,,,,,,,,,,,,,,32,1,4.000000e+000,9.220123e-003,0.000000e+000,0,,0,
1524069489.869,,0.000000e+000,5.499577e+001,-7.270106e-005,0.000000e+000,3,9.750540e-001,0.000000e+000,,,,,,,,,,,,,,32,1,4.000000e+000,5.249023e-003,0.000000e+000,0,,0,
1524069502.249,,0.000000e+000,5.499380e+001,-7.269115e-005,0.000000e+000,3,9.741495e-001,0.000000e+000,,,,,,,,,,,,,,32,1,4.000000e+000,6.572723e-003,0.000000e+000,0,,0,
1524069515.009,,0.000000e+000,5.499773e+001,-7.270772e-005,0.000000e+000,3,9.755144e-001,0.000000e+000,,,,,,,,,,,,,,32,1,4.000000e+000,1.308441e-003,0.000000e+000,0,,0,
1524069527.439,,0.000000e+000,5.500432e+001,-7.271807e-005,0.000000e+000,3,9.745108e-001,0.000000e+000,,,,,,,,,,,,,,32,1,4.000000e+000,6.580353e-003,0.000000e+000,0,,0,
1524069540.259,,0.000000e+000,5.499511e+001,-7.275610e-005,0.000000e+000,3,9.752463e-001,0.000000e+000,,,,,,,,,,,,,,32,1,4.000000e+000,3.940582e-003,0.000000e+000,0,,0,
1524069552.649,,0.000000e+000,5.499445e+001,-7.282339e-005,0.000000e+000,3,9.740762e-001,0.000000e+000,,,,,,,,,,,,,,32,1,4.000000e+000,0.000000e+000,0.000000e+000,0,,0,
1524069565.489,,0.000000e+000,5.499972e+001,-7.283366e-005,0.000000e+000,3,9.749753e-001,0.000000e+000,,,,,,,,,,,,,,32,1,4.000000e+000,5.268097e-003,0.000000e+000,0,,0,
1524069577.859,,0.000000e+000,5.499972e+001,-7.285493e-005,0.000000e+000,3,9.741958e-001,0.000000e+000,,,,,,,,,,,,,,32,1,4.000000e+000,1.314926e-002,0.000000e+000,0,,0,
1524069590.489,,0.000000e+000,5.499248e+001,-7.289819e-005,0.000000e+000,3,9.749938e-001,0.000000e+000,,,,,,,,,,,,,,32,1,4.000000e+000,6.580353e-003,0.000000e+000,0,,0,
1524069602.779,,0.000000e+000,5.499971e+001,-7.295726e-005,0.000000e+000,3,9.746495e-001,0.000000e+000,,,,,,,,,,,,,,32,1,4.000000e+000,1.052094e-002,0.000000e+000,0,,0,
1524069615.329,,0.000000e+000,5.499643e+001,-7.291829e-005,0.000000e+000,3,9.750485e-001,0.000000e+000,,,,,,,,,,,,,,32,1,4.000000e+000,1.312256e-003,0.000000e+000,0,,0,
1524069627.789,,0.000000e+000,5.499380e+001,-7.300408e-005,0.000000e+000,3,9.739454e-001,0.000000e+000,,,,,,,,,,,,,,32,1,4.000000e+000,1.308441e-003,0.000000e+000,0,,0,
1524069640.529,,0.000000e+000,5.499774e+001,-7.303342e-005,0.000000e+000,3,9.753738e-001,0.000000e+000,,,,,,,,,,,,,,32,1,4.000000e+000,3.940582e-003,0.000000e+000,0,,0,
1524069652.999,,0.000000e+000,5.499905e+001,-7.312289e-005,0.000000e+000,3,9.741810e-001,0.000000e+000,,,,,,,,,,,,,,32,1,4.000000e+000,1.319885e-003,0.000000e+000,0,,0,
1524069665.739,,0.000000e+000,5.500103e+001,-7.306826e-005,0.000000e+000,3,9.745008e-001,0.000000e+000,,,,,,,,,,,,,,32,1,4.000000e+000,0.000000e+000,0.000000e+000,0,,0,
1524069678.169,,0.000000e+000,5.499839e+001,-7.306388e-005,0.000000e+000,3,9.743903e-001,0.000000e+000,,,,,,,,,,,,,,32,1,4.000000e+000,0.000000e+000,0.000000e+000,0,,0,
1524069690.729,,0.000000e+000,5.500037e+001,-7.319650e-005,0.000000e+000,3,9.759195e-001,0.000000e+000,,,,,,,,,,,,,,32,1,4.000000e+000,3.959656e-003,0.000000e+000,0,,0,
1524069703.019,,0.000000e+000,5.499445e+001,-7.328291e-005,0.000000e+000,3,9.743578e-001,0.000000e+000,,,,,,,,,,,,,,32,1,4.000000e+000,2.628326e-003,0.000000e+000,0,,0,
1524069715.599,,0.000000e+000,5.500037e+001,-7.320585e-005,0.000000e+000,3,9.750766e-001,0.000000e+000,,,,,,,,,,,,,,32,1,4.000000e+000,3.959656e-003,0.000000e+000,0,,0,
1524069728.059,,0.000000e+000,5.500169e+001,-7.329637e-005,0.000000e+000,3,9.746214e-001,0.000000e+000,,,,,,,,,,,,,,32,1,4.000000e+000,1.319885e-003,0.000000e+000,0,,0,
1524069740.819,,0.000000e+000,5.499709e+001,-7.323781e-005,0.000000e+000,3,9.754524e-001,0.000000e+000,,,,,,,,,,,,,,32,1,4.000000e+000,7.888794e-003,0.000000e+000,0,,0,
1524069753.499,,0.000000e+000,5.499445e+001,-7.332516e-005,0.000000e+000,3,9.759239e-001,0.000000e+000,,,,,,,,,,,,,,32,1,4.000000e+000,1.578903e-002,0.000000e+000,0,,0,
1524069766.209,,0.000000e+000,5.499314e+001,-7.333871e-005,0.000000e+000,3,9.752016e-001,0.000000e+000,,,,,,,,,,,,,,32,1,4.000000e+000,5.260468e-003,0.000000e+000,0,,0,
1524069778.689,,0.000000e+000,5.499445e+001,-7.342712e-005,0.000000e+000,3,9.755026e-001,0.000000e+000,,,,,,,,,,,,,,32,1,4.000000e+000,7.881165e-003,0.000000e+000,0,,0,
1524069791.409,,0.000000e+000,5.499445e+001,-7.344608e-005,0.000000e+000,3,9.746560e-001,0.000000e+000,,,,,,,,,,,,,,32,1,4.000000e+000,2.628326e-003,0.000000e+000,0,,0,
1524069804.419,,0.000000e+000,5.499643e+001,-7.349291e-005,0.000000e+000,3,9.765903e-001,0.000000e+000,,,,,,,,,,,,,,32,1,4.000000e+000,1.708984e-002,0.000000e+000,0,,0,
1524069817.279,,0.000000e+000,5.500037e+001,-7.343630e-005,0.000000e+000,3,9.748440e-001,0.000000e+000,,,,,,,,,,,,,,32,1,4.000000e+000,9.201050e-003,0.000000e+000,0,,0,
1524069830.099,,0.000000e+000,5.499577e+001,-7.353727e-005,0.000000e+000,3,9.745753e-001,0.000000e+000,,,,,,,,,,,,,,32,1,4.000000e+000,0.000000e+000,0.000000e+000,0,,0,
1524069842.229,,0.000000e+000,5.499511e+001,-7.358602e-005,0.000000e+000,3,9.749851e-001,0.000000e+000,,,,,,,,,,,,,,32,1,4.000000e+000,1.319885e-003,0.000000e+000,0,,0,
1524069854.590,,0.000000e+000,5.499905e+001,-7.354626e-005,0.000000e+000,3,9.757837e-001,0.000000e+000,,,,,,,,,,,,,,32,1,4.000000e+000,3.948212e-003,0.000000e+000,0,,0,
1524069867.480,,0.000000e+000,5.500235e+001,-7.357905e-005,0.000000e+000,3,9.746078e-001,0.000000e+000,,,,,,,,,,,,,,32,1,4.000000e+000,1.052856e-002,0.000000e+000,0,,0,
1524069880.000,,0.000000e+000,5.500234e+001,-7.359266e-005,0.000000e+000,3,9.749628e-001,0.000000e+000,,,,,,,,,,,,,,32,1,4.000000e+000,7.900238e-003,0.000000e+000,0,,0,
1524069892.430,,0.000000e+000,5.499775e+001,-7.374329e-005,0.000000e+000,3,9.752972e-001,0.000000e+000,,,,,,,,,,,,,,32,1,4.000000e+000,9.208679e-003,0.000000e+000,0,,0,
1524069905.160,,0.000000e+000,5.499643e+001,-7.370828e-005,0.000000e+000,3,9.756770e-001,0.000000e+000,,,,,,,,,,,,,,32,1,4.000000e+000,6.568909e-003,0.000000e+000,0,,0,
1524069918.450,,0.000000e+000,5.500169e+001,-7.373613e-005,0.000000e+000,3,9.756610e-001,0.000000e+000,,,,,,,,,,,,,,32,1,4.000000e+000,9.208679e-003,0.000000e+000,0,,0,
1524069930.560,,0.000000e+000,5.499445e+001,-7.372828e-005,0.000000e+000,3,9.752201e-001,0.000000e+000,,,,,,,,,,,,,,32,1,4.000000e+000,5.260468e-003,0.000000e+000,0,,0,
1524069943.330,,0.000000e+000,5.499840e+001,-7.382046e-005,0.000000e+000,3,9.756945e-001,0.000000e+000,,,,,,,,,,,,,,32,1,4.000000e+000,2.628326e-003,0.000000e+000,0,,0,
1524069956.510,,0.000000e+000,5.499511e+001,-7.373444e-005,0.000000e+000,3,9.746055e-001,0.000000e+000,,,,,,,,,,,,,,32,1,4.000000e+000,3.940582e-003,0.000000e+000,0,,0,
1524069969.660,,0.000000e+000,5.500103e+001,-7.374412e-005,0.000000e+000,3,9.744863e-001,0.000000e+000,,,,,,,,,,,,,,32,1,4.000000e+000,1.577759e-002,0.000000e+000,0,,0,
1524069982.010,,0.000000e+000,5.499971e+001,-7.380934e-005,0.000000e+000,3,9.751567e-001,0.000000e+000,,,,,,,,,,,,,,32,1,4.000000e+000,0.000000e+000,0.000000e+000,0,,0,
1524069994.770,,0.000000e+000,5.499577e+001,-7.385123e-005,0.000000e+000,3,9.741780e-001,0.000000e+000,,,,,,,,,,,,,,32,1,4.000000e+000,2.632141e-003,0.000000e+000,0,,0,
1524070007.710,,0.000000e+000,5.499773e+001,-7.395298e-005,0.000000e+000,3,9.753823e-001,0.000000e+000,,,,,,,,,,,,,,32,1,4.000000e+000,1.308441e-003,0.000000e+000,0,,0,
1524070020.250,,0.000000e+000,5.500037e+001,-7.396232e-005,0.000000e+000,3,9.742818e-001,0.000000e+000,,,,,,,,,,,,,,32,1,4.000000e+000,1.319885e-003,0.000000e+000,0,,0,
1524070033.000,,0.000000e+000,5.499971e+001,-7.396698e-005,0.000000e+000,3,9.758022e-001,0.000000e+000,,,,,,,,,,,,,,32,1,4.000000e+000,2.639771e-003,0.000000e+000,0,,0,
1524070045.320,,0.000000e+000,5.499511e+001,-7.400572e-005,0.000000e+000,3,9.743352e-001,0.000000e+000,,,,,,,,,,,,,,32,1,4.000000e+000,1.319885e-003,0.000000e+000,0,,0,
1524070058.090,,0.000000e+000,5.499905e+001,-7.398470e-005,0.000000e+000,3,9.748679e-001,0.000000e+000,,,,,,,,,,,,,,32,1,4.000000e+000,3.948212e-003,0.000000e+000,0,,0,
1524070070.320,,0.000000e+000,5.499971e+001,-7.395025e-005,0.000000e+000,3,9.743435e-001,0.000000e+000,,,,,,,,,,,,,,32,1,4.000000e+000,2.639771e-003,0.000000e+000,0,,0,
1524070082.750,,0.000000e+000,5.499643e+001,-7.408149e-005,0.000000e+000,3,9.750341e-001,0.000000e+000,,,,,,,,,,,,,,32,1,4.000000e+000,9.208679e-003,0.000000e+000,0,,0,
1524070095.230,,0.000000e+000,5.499445e+001,-7.410009e-005,0.000000e+000,3,9.740526e-001,0.000000e+000,,,,,,,,,,,,,,32,1,4.000000e+000,5.260468e-003,0.000000e+000,0,,0,
1524070107.960,,0.000000e+000,5.500103e+001,-7.408364e-005,0.000000e+000,3,9.750975e-001,0.000000e+000,,,,,,,,,,,,,,32,1,4.000000e+000,7.888794e-003,0.000000e+000,0,,0,
1524070120.340,,0.000000e+000,5.499643e+001,-7.415154e-005,0.000000e+000,3,9.760699e-001,0.000000e+000,,,,,,,,,,,,,,32,1,4.000000e+000,6.568909e-003,0.000000e+000,0,,0,
1524070133.190,,0.000000e+000,5.499840e+001,-7.412972e-005,0.000000e+000,3,9.751019e-001,0.000000e+000,,,,,,,,,,,,,,32,1,4.000000e+000,5.260468e-003,0.000000e+000,0,,0,
1524070145.330,,0.000000e+000,5.500235e+001,-7.421937e-005,0.000000e+000,3,9.748111e-001,0.000000e+000,,,,,,,,,,,,,,32,1,4.000000e+000,0.000000e+000,0.000000e+000,0,,0,
1524070157.810,,0.000000e+000,5.499708e+001,-7.422776e-005,0.000000e+000,3,9.750348e-001,0.000000e+000,,,,,,,,,,,,,,32,1,4.000000e+000,0.000000e+000,0.000000e+000,0,,0,
1524070170.280,,0.000000e+000,5.500037e+001,-7.421985e-005,0.000000e+000,3,9.742763e-001,0.000000e+000,,,,,,,,,,,,,,32,1,4.000000e+000,1.319885e-003,0.000000e+000,0,,0,
1524070183.030,,0.000000e+000,5.499840e+001,-7.422461e-005,0.000000e+000,3,9.750071e-001,0.000000e+000,,,,,,,,,,,,,,32,1,4.000000e+000,2.628326e-003,0.000000e+000,0,,0,
1524070195.170,,0.000000e+000,5.499577e+001,-7.428914e-005,0.000000e+000,3,9.753491e-001,0.000000e+000,,,,,,,,,,,,,,32,1,4.000000e+000,0.000000e+000,0.000000e+000,0,,0,
1524070207.830,,0.000000e+000,5.500169e+001,-7.425438e-005,0.000000e+000,3,9.758494e-001,0.000000e+000,,,,,,,,,,,,,,32,1,4.000000e+000,3.959656e-003,0.000000e+000,0,,0,
1524070220.380,,0.000000e+000,5.499773e+001,-7.431263e-005,0.000000e+000,3,9.761705e-001,0.000000e+000,,,,,,,,,,,,,,32,1,4.000000e+000,1.308441e-003,0.000000e+000,0,,0,
1524070233.060,,0.000000e+000,5.499708e+001,-7.430951e-005,0.000000e+000,3,9.753059e-001,0.000000e+000,,,,,,,,,,,,,,32,1,4.000000e+000,2.620697e-003,0.000000e+000,0,,0,
1524070246.110,,0.000000e+000,5.499248e+001,-7.446533e-005,0.000000e+000,3,9.764284e-001,0.000000e+000,,,,,,,,,,,,,,32,1,4.000000e+000,1.319885e-003,0.000000e+000,0,,0,
1524070258.610,,0.000000e+000,5.499182e+001,-7.440645e-005,0.000000e+000,3,9.742059e-001,0.000000e+000,,,,,,,,,,,,,,32,1,4.000000e+000,0.000000e+000,0.000000e+000,0,,0,
1524070271.200,,0.000000e+000,5.499380e+001,-7.440460e-005,0.000000e+000,3,9.757404e-001,0.000000e+000,,,,,,,,,,,,,,32,1,4.000000e+000,3.948212e-003,0.000000e+000,0,,0,
1524070283.670,,0.000000e+000,5.499643e+001,-7.446862e-005,0.000000e+000,3,9.737435e-001,0.000000e+000,,,,,,,,,,,,,,32,1,4.000000e+000,1.312256e-003,0.000000e+000,0,,0,
1524070296.500,,0.000000e+000,5.500103e+001,-7.449553e-005,0.000000e+000,3,9.748542e-001,0.000000e+000,,,,,,,,,,,,,,32,1,4.000000e+000,7.888794e-003,0.000000e+000,0,,0,
1524070309.100,,0.000000e+000,5.500761e+001,-7.442787e-005,0.000000e+000,3,9.740508e-001,0.000000e+000,,,,,,,,,,,,,,32,1,4.000000e+000,5.268097e-003,0.000000e+000,0,,0,
1524070321.970,,0.000000e+000,5.500234e+001,-7.453815e-005,0.000000e+000,3,9.748468e-001,0.000000e+000,,,,,,,,,,,,,,32,1,4.000000e+000,1.578903e-002,0.000000e+000,0,,0,
1524070334.520,,0.000000e+000,5.499906e+001,-7.452522e-005,0.000000e+000,3,9.745006e-001,0.000000e+000,,,,,,,,,,,,,,32,1,4.000000e+000,9.220123e-003,0.000000e+000,0,,0,
1524070347.180,,0.000000e+000,5.499972e+001,-7.448089e-005,0.000000e+000,3,9.750673e-001,0.000000e+000,,,,,,,,,,,,,,32,1,4.000000e+000,7.900238e-003,0.000000e+000,0,,0,
1524070359.720,,0.000000e+000,5.499511e+001,-7.455728e-005,0.000000e+000,3,9.742482e-001,0.000000e+000,,,,,,,,,,,,,,32,1,4.000000e+000,1.319885e-003,0.000000e+000,0,,0,
1524070374.410,,0.000000e+000,5.499445e+001,5.411141e-005,0.000000e+000,2,0.000000e+000,0.000000e+000,,,,,,,,,,,,,,32,1,4.000000e+000,2.628326e-003,0.000000e+000,0,,0,
1524070386.370,,0.000000e+000,5.500037e+001,-7.467796e-005,0.000000e+000,3,9.757522e-001,0.000000e+000,,,,,,,,,,,,,,32,1,4.000000e+000,3.959656e-003,0.000000e+000,0,,0,
1524070399.100,,0.000000e+000,5.500103e+001,-7.458146e-005,0.000000e+000,3,9.747111e-001,0.000000e+000,,,,,,,,,,,,,,32,1,4.000000e+000,1.316071e-002,0.000000e+000,0,,0,
1524070411.840,,0.000000e+000,5.499511e+001,-7.466753e-005,0.000000e+000,3,9.758019e-001,0.000000e+000,,,,,,,,,,,,,,32,1,4.000000e+000,9.201050e-003,0.000000e+000,0,,0,
1524070424.440,,0.000000e+000,5.499971e+001,-7.459095e-005,0.000000e+000,3,9.743549e-001,0.000000e+000,,,,,,,,,,,,,,32,1,4.000000e+000,0.000000e+000,0.000000e+000,0,,0,
1524070436.810,,0.000000e+000,5.499971e+001,-7.463701e-005,0.000000e+000,3,9.745523e-001,0.000000e+000,,,,,,,,,,,,,,32,1,4.000000e+000,0.000000e+000,0.000000e+000,0,,0,
1524070449.780,,0.000000e+000,5.500037e+001,-7.464194e-005,0.000000e+000,3,9.734783e-001,0.000000e+000,,,,,,,,,,,,,,32,1,4.000000e+000,1.319885e-003,0.000000e+000,0,,0,
1524070462.470,,0.000000e+000,5.499841e+001,-7.464969e-005,0.000000e+000,3,9.744985e-001,0.000000e+000,,,,,,,,,,,,,,32,1,4.000000e+000,1.052856e-002,0.000000e+000,0,,0,
1524070474.590,,0.000000e+000,5.499971e+001,-7.471697e-005,0.000000e+000,3,9.747024e-001,0.000000e+000,,,,,,,,,,,,,,32,1,4.000000e+000,0.000000e+000,0.000000e+000,0,,0,
1524070486.950,,0.000000e+000,5.499905e+001,-7.474202e-005,0.000000e+000,3,9.743034e-001,0.000000e+000,,,,,,,,,,,,,,32,1,4.000000e+000,3.948212e-003,0.000000e+000,0,,0,
1524070499.290,,0.000000e+000,5.500103e+001,-7.473059e-005,0.000000e+000,3,9.739597e-001,0.000000e+000,,,,,,,,,,,,,,32,1,4.000000e+000,1.316071e-002,0.000000e+000,0,,0,
1524070511.810,,0.000000e+000,5.499708e+001,-7.470891e-005,0.000000e+000,3,9.743276e-001,0.000000e+000,,,,,,,,,,,,,,32,1,4.000000e+000,5.260468e-003,0.000000e+000,0,,0,
1524070524.270,,0.000000e+000,5.499905e+001,-7.477154e-005,0.000000e+000,3,9.729975e-001,0.000000e+000,,,,,,,,,,,,,,32,1,4.000000e+000,3.948212e-003,0.000000e+000,0,,0,
1524070537.040,,0.000000e+000,5.499971e+001,-7.478399e-005,0.000000e+000,3,9.742736e-001,0.000000e+000,,,,,,,,,,,,,,32,1,4.000000e+000,2.639771e-003,0.000000e+000,0,,0,
1524070549.890,,0.000000e+000,5.499445e+001,-7.478364e-005,0.000000e+000,3,9.743739e-001,0.000000e+000,,,,,,,,,,,,,,32,1,4.000000e+000,0.000000e+000,0.000000e+000,0,,0,
1524070562.400,,0.000000e+000,5.500037e+001,-7.484687e-005,0.000000e+000,3,9.743304e-001,0.000000e+000,,,,,,,,,,,,,,32,1,4.000000e+000,1.446915e-002,0.000000e+000,0,,0,
1524070575.481,,0.000000e+000,5.498919e+001,-7.491105e-005,0.000000e+000,3,9.742979e-001,0.000000e+000,,,,,,,,,,,,,,32,1,4.000000e+000,5.260468e-003,0.000000e+000,0,,0,
1524070587.411,,0.000000e+000,5.499905e+001,-7.482646e-005,0.000000e+000,3,9.739999e-001,0.000000e+000,,,,,,,,,,,,,,32,1,4.000000e+000,1.446915e-002,0.000000e+000,0,,0,
1524070600.651,,0.000000e+000,5.499051e+001,-7.491009e-005,0.000000e+000,3,9.744167e-001,0.000000e+000,,,,,,,,,,,,,,32,1,4.000000e+000,2.632141e-003,0.000000e+000,0,,0,
1524070613.121,,0.000000e+000,5.499445e+001,-7.489538e-005,0.000000e+000,3,9.738321e-001,0.000000e+000,,,,,,,,,,,,,,32,1,4.000000e+000,5.260468e-003,0.000000e+000,0,,0,
1524070626.161,,0.000000e+000,5.499445e+001,-7.496580e-005,0.000000e+000,3,9.741972e-001,0.000000e+000,,,,,,,,,,,,,,32,1,4.000000e+000,2.628326e-003,0.000000e+000,0,,0,
1524070638.761,,0.000000e+000,5.499906e+001,-7.493474e-005,0.000000e+000,3,9.737307e-001,0.000000e+000,,,,,,,,,,,,,,32,1,4.000000e+000,6.580353e-003,0.000000e+000,0,,0,
1524070651.501,,0.000000e+000,5.500037e+001,-7.494978e-005,0.000000e+000,3,9.747601e-001,0.000000e+000,,,,,,,,,,,,,,32,1,4.000000e+000,6.587982e-003,0.000000e+000,0,,0,
1524070663.881,,0.000000e+000,5.500169e+001,-7.497484e-005,0.000000e+000,3,9.735166e-001,0.000000e+000,,,,,,,,,,,,,,32,1,4.000000e+000,1.184082e-002,0.000000e+000,0,,0,
1524070676.701,,0.000000e+000,5.499972e+001,-7.499883e-005,0.000000e+000,3,9.740339e-001,0.000000e+000,,,,,,,,,,,,,,32,1,4.000000e+000,7.900238e-003,0.000000e+000,0,,0,
1524070689.141,,0.000000e+000,5.500235e+001,-1.532174e-004,0.000000e+000,3,6.372837e-001,0.000000e+000,,,,,,,,,,,,,,32,1,4.000000e+000,2.639771e-003,0.000000e+000,0,,0,
1524070701.941,,0.000000e+000,5.500235e+001,-7.501646e-005,0.000000e+000,3,9.741384e-001,0.000000e+000,,,,,,,,,,,,,,32,1,4.000000e+000,1.052856e-002,0.000000e+000,0,,0,
1524070714.301,,0.000000e+000,5.500300e+001,-7.505923e-005,0.000000e+000,3,9.735342e-001,0.000000e+000,,,,,,,,,,,,,,32,1,4.000000e+000,9.220123e-003,0.000000e+000,0,,0,
1524070727.121,,0.000000e+000,5.500103e+001,-7.509180e-005,0.000000e+000,3,9.743202e-001,0.000000e+000,,,,,,,,,,,,,,32,1,4.000000e+000,5.279541e-003,0.000000e+000,0,,0,
1524070739.371,,0.000000e+000,5.499643e+001,-7.507992e-005,0.000000e+000,3,9.740966e-001,0.000000e+000,,,,,,,,,,,,,,32,1,4.000000e+000,9.208679e-003,0.000000e+000,0,,0,
1524070752.051,,0.000000e+000,5.500037e+001,-7.510318e-005,0.000000e+000,3,9.745421e-001,0.000000e+000,,,,,,,,,,,,,,32,1,4.000000e+000,3.959656e-003,0.000000e+000,0,,0,
1524070764.591,,0.000000e+000,5.499248e+001,-7.506990e-005,0.000000e+000,3,9.736088e-001,0.000000e+000,,,,,,,,,,,,,,32,1,4.000000e+000,1.319885e-003,0.000000e+000,0,,0,
1524070777.561,,0.000000e+000,5.499840e+001,-7.507388e-005,0.000000e+000,3,9.745472e-001,0.000000e+000,,,,,,,,,,,,,,32,1,4.000000e+000,2.628326e-003,0.000000e+000,0,,0,
1524070789.681,,0.000000e+000,5.499445e+001,-7.511089e-005,0.000000e+000,3,9.742650e-001,0.000000e+000,,,,,,,,,,,,,,32,1,4.000000e+000,2.628326e-003,0.000000e+000,0,,0,