File: Experimental Raw Data/TC04-12-01K VRMac VRMde/Iterative Regression/TC04-12-01K_VRMac_53K_6000s_VRMde_55K.dc.dat
[Header]
TITLE,MPMS DC Measurement
BYAPP,MPMS Measurement,2.1,Summary
FILEOPENTIME, 1524208739.938000 4/20/2018, 1:18:59 AM

INFO, APPNAME, MPMS MultiVu Application, Revision 1.61,  Build 082

INFO, NAME, TC04-12-01K
INFO, WEIGHT, 1.000
INFO, AREA, 1.000
INFO, LENGTH, 1.000
INFO, SHAPE, 0
INFO, COMMENT,
INFO, SEQUENCE FILE: VRMac_53K_6000s_VRMde_55K.seq


INFO, BACKGROUND DATA FILE:, None


STARTUPAXIS,X,4,LINEAR,AUTO,0.000000,0.000000
STARTUPAXIS,Y1,5,LINEAR,AUTO,0.000000,0.000000


STARTUPGROUP,Longitudinal
FIELDGROUP,Longitudinal,1,2,3,4,5,6,7,8,9,15,16,17,18,27,28
FIELDGROUP,Transverse,1,2,3,4,10,11,12,13,14,19,20,21,22,27,28

PLOT_APPEARANCE,ALL,HORZ_GRID_ON,VERT_GRID_ON,MARKERS_AND_LINES

[Data]
Time,Comment,Field (Oe),Temperature (K),Long Moment (emu),Long Scan Std Dev,Long Algorithm,Long Reg Fit,Long Percent Error (%),Trans Moment (emu),Trans Scan Std Dev,Trans Algorithm,Trans Reg Fit,Trans Percent Error (%),Long Moment [w/o ABS] (emu),Long Scan Std Dev [w/o ABS],Long Reg Fit [w/o ABS],Long Percent Error [w/o ABS] (%),Trans Moment [w/o ABS] (emu),Trans Scan Std Dev [w/o ABS],Trans Reg Fit [w/o ABS],Trans Percent Error [w/o ABS] (%),Points per Scan,Scans per Measurement,Scan Length (cm),Delta Temp (K),Rot Position (deg),Error,EC Comp. Running,Using ABS,
1524208739.938,,0.000000e+000,5.322804e+001,-1.636835e-005,0.000000e+000,3,9.623227e-001,0.000000e+000,,,,,,,,,,,,,,32,1,4.000000e+000,4.429893e-001,0.000000e+000,0,,0,
1524208779.698,,0.000000e+000,5.486079e+001,-1.150275e-005,0.000000e+000,3,9.620615e-001,0.000000e+000,,,,,,,,,,,,,,32,1,4.000000e+000,2.278824e-001,0.000000e+000,0,,0,
1524208817.498,,0.000000e+000,5.508139e+001,-8.726598e-006,0.000000e+000,3,9.440012e-001,0.000000e+000,,,,,,,,,,,,,,32,1,4.000000e+000,2.639771e-003,0.000000e+000,0,,0,
1524208855.258,,0.000000e+000,5.504382e+001,-7.024464e-006,0.000000e+000,3,9.438289e-001,0.000000e+000,,,,,,,,,,,,,,32,1,4.000000e+000,2.503967e-002,0.000000e+000,0,,0,
1524208892.278,,0.000000e+000,5.501485e+001,-6.020838e-006,0.000000e+000,3,9.326947e-001,0.000000e+000,,,,,,,,,,,,,,32,1,4.000000e+000,1.448059e-002,0.000000e+000,0,,0,
1524208930.568,,0.000000e+000,5.500365e+001,-5.234038e-006,0.000000e+000,3,9.361951e-001,0.000000e+000,,,,,,,,,,,,,,32,1,4.000000e+000,1.052856e-002,0.000000e+000,0,,0,
1524208968.178,,0.000000e+000,5.499906e+001,-4.606350e-006,0.000000e+000,3,9.248239e-001,0.000000e+000,,,,,,,,,,,,,,32,1,4.000000e+000,6.580353e-003,0.000000e+000,0,,0,
1524209006.118,,0.000000e+000,5.499708e+001,-4.112103e-006,0.000000e+000,3,9.037719e-001,0.000000e+000,,,,,,,,,,,,,,32,1,4.000000e+000,2.620697e-003,0.000000e+000,0,,0,
1524209044.588,,0.000000e+000,5.499839e+001,-3.754849e-006,0.000000e+000,3,9.067433e-001,0.000000e+000,,,,,,,,,,,,,,32,1,4.000000e+000,0.000000e+000,0.000000e+000,0,,0,
1524209081.968,,0.000000e+000,5.500103e+001,-3.373359e-006,0.000000e+000,3,9.096724e-001,0.000000e+000,,,,,,,,,,,,,,32,1,4.000000e+000,2.639771e-003,0.000000e+000,0,,0,
1524209119.349,,0.000000e+000,5.499905e+001,-3.283500e-006,0.000000e+000,3,8.751029e-001,0.000000e+000,,,,,,,,,,,,,,32,1,4.000000e+000,3.948212e-003,0.000000e+000,0,,0,
1524209157.039,,0.000000e+000,5.499708e+001,-2.928465e-006,0.000000e+000,3,8.696408e-001,0.000000e+000,,,,,,,,,,,,,,32,1,4.000000e+000,0.000000e+000,0.000000e+000,0,,0,
1524209194.419,,0.000000e+000,5.499774e+001,-2.836184e-006,0.000000e+000,3,8.656105e-001,0.000000e+000,,,,,,,,,,,,,,32,1,4.000000e+000,6.580353e-003,0.000000e+000,0,,0,
1524209232.729,,0.000000e+000,5.499905e+001,-2.574605e-006,0.000000e+000,3,8.526478e-001,0.000000e+000,,,,,,,,,,,,,,32,1,4.000000e+000,1.319885e-003,0.000000e+000,0,,0,
1524209270.959,,0.000000e+000,5.499905e+001,-2.477893e-006,0.000000e+000,3,8.299400e-001,0.000000e+000,,,,,,,,,,,,,,32,1,4.000000e+000,1.319885e-003,0.000000e+000,0,,0,
1524209308.729,,0.000000e+000,5.499773e+001,-2.490410e-006,0.000000e+000,3,8.089542e-001,0.000000e+000,,,,,,,,,,,,,,32,1,4.000000e+000,1.308441e-003,0.000000e+000,0,,0,
1524209349.741,,0.000000e+000,5.499445e+001,-6.478563e-007,0.000000e+000,2,0.000000e+000,0.000000e+000,,,,,,,,,,,,,,32,1,4.000000e+000,2.628326e-003,0.000000e+000,0,,0,
1524209392.267,,0.000000e+000,5.499380e+001,-4.601794e-007,0.000000e+000,2,0.000000e+000,0.000000e+000,,,,,,,,,,,,,,32,1,4.000000e+000,6.572723e-003,0.000000e+000,0,,0,
1524209432.681,,0.000000e+000,5.499840e+001,2.285209e-006,0.000000e+000,3,6.588875e-001,0.000000e+000,,,,,,,,,,,,,,32,1,4.000000e+000,7.900238e-003,0.000000e+000,0,,0,
1524209469.891,,0.000000e+000,5.500169e+001,2.191107e-006,0.000000e+000,3,6.182920e-001,0.000000e+000,,,,,,,,,,,,,,32,1,4.000000e+000,9.208679e-003,0.000000e+000,0,,0,
1524209507.391,,0.000000e+000,5.499906e+001,-2.262843e-006,0.000000e+000,3,7.644318e-001,0.000000e+000,,,,,,,,,,,,,,32,1,4.000000e+000,6.580353e-003,0.000000e+000,0,,0,
1524209547.273,,0.000000e+000,5.499445e+001,-2.198507e-006,0.000000e+000,3,7.358861e-001,0.000000e+000,,,,,,,,,,,,,,32,1,4.000000e+000,0.000000e+000,0.000000e+000,0,,0,
1524209585.363,,0.000000e+000,5.499905e+001,-2.237953e-006,0.000000e+000,3,7.339052e-001,0.000000e+000,,,,,,,,,,,,,,32,1,4.000000e+000,1.319885e-003,0.000000e+000,0,,0,
1524209628.159,,0.000000e+000,5.499905e+001,4.300469e-007,0.000000e+000,2,0.000000e+000,0.000000e+000,,,,,,,,,,,,,,32,1,4.000000e+000,1.319885e-003,0.000000e+000,0,,0,
1524209670.105,,0.000000e+000,5.499774e+001,5.796275e-007,0.000000e+000,2,0.000000e+000,0.000000e+000,,,,,,,,,,,,,,32,1,4.000000e+000,3.940582e-003,0.000000e+000,0,,0,
1524209711.319,,0.000000e+000,5.498919e+001,6.175726e-007,0.000000e+000,2,0.000000e+000,0.000000e+000,,,,,,,,,,,,,,32,1,4.000000e+000,5.260468e-003,0.000000e+000,0,,0,
1524209749.771,,0.000000e+000,5.499972e+001,2.033503e-006,0.000000e+000,3,7.164418e-001,0.000000e+000,,,,,,,,,,,,,,32,1,4.000000e+000,7.900238e-003,0.000000e+000,0,,0,
1524209787.661,,0.000000e+000,5.499511e+001,2.090073e-006,0.000000e+000,3,6.870800e-001,0.000000e+000,,,,,,,,,,,,,,32,1,4.000000e+000,3.940582e-003,0.000000e+000,0,,0,
1524209825.461,,0.000000e+000,5.499445e+001,2.137996e-006,0.000000e+000,3,7.187569e-001,0.000000e+000,,,,,,,,,,,,,,32,1,4.000000e+000,5.260468e-003,0.000000e+000,0,,0,
1524209863.282,,0.000000e+000,5.499774e+001,2.198234e-006,0.000000e+000,3,7.076483e-001,0.000000e+000,,,,,,,,,,,,,,32,1,4.000000e+000,3.940582e-003,0.000000e+000,0,,0,
1524209901.122,,0.000000e+000,5.499445e+001,2.120810e-006,0.000000e+000,3,7.335819e-001,0.000000e+000,,,,,,,,,,,,,,32,1,4.000000e+000,5.260468e-003,0.000000e+000,0,,0,
1524209938.822,,0.000000e+000,5.500103e+001,2.236211e-006,0.000000e+000,3,7.456491e-001,0.000000e+000,,,,,,,,,,,,,,32,1,4.000000e+000,7.888794e-003,0.000000e+000,0,,0,
1524209976.642,,0.000000e+000,5.499839e+001,2.126767e-006,0.000000e+000,3,7.488845e-001,0.000000e+000,,,,,,,,,,,,,,32,1,4.000000e+000,0.000000e+000,0.000000e+000,0,,0,
1524210014.012,,0.000000e+000,5.499971e+001,2.230170e-006,0.000000e+000,3,7.426653e-001,0.000000e+000,,,,,,,,,,,,,,32,1,4.000000e+000,2.639771e-003,0.000000e+000,0,,0,
1524210051.382,,0.000000e+000,5.499117e+001,2.186207e-006,0.000000e+000,3,7.641845e-001,0.000000e+000,,,,,,,,,,,,,,32,1,4.000000e+000,1.183319e-002,0.000000e+000,0,,0,
1524210088.742,,0.000000e+000,5.499971e+001,2.281240e-006,0.000000e+000,3,7.518234e-001,0.000000e+000,,,,,,,,,,,,,,32,1,4.000000e+000,0.000000e+000,0.000000e+000,0,,0,
1524210127.302,,0.000000e+000,5.499773e+001,2.386156e-006,0.000000e+000,3,7.560006e-001,0.000000e+000,,,,,,,,,,,,,,32,1,4.000000e+000,1.308441e-003,0.000000e+000,0,,0,
1524210165.272,,0.000000e+000,5.500103e+001,2.335883e-006,0.000000e+000,3,7.741555e-001,0.000000e+000,,,,,,,,,,,,,,32,1,4.000000e+000,7.888794e-003,0.000000e+000,0,,0,
1524210202.832,,0.000000e+000,5.499839e+001,2.438406e-006,0.000000e+000,3,7.631252e-001,0.000000e+000,,,,,,,,,,,,,,32,1,4.000000e+000,0.000000e+000,0.000000e+000,0,,0,
1524210241.002,,0.000000e+000,5.499708e+001,2.400305e-006,0.000000e+000,3,7.853935e-001,0.000000e+000,,,,,,,,,,,,,,32,1,4.000000e+000,5.260468e-003,0.000000e+000,0,,0,
1524210278.842,,0.000000e+000,5.499708e+001,2.437095e-006,0.000000e+000,3,7.871130e-001,0.000000e+000,,,,,,,,,,,,,,32,1,4.000000e+000,5.260468e-003,0.000000e+000,0,,0,
1524210316.102,,0.000000e+000,5.499773e+001,2.459097e-006,0.000000e+000,3,7.851002e-001,0.000000e+000,,,,,,,,,,,,,,32,1,4.000000e+000,1.308441e-003,0.000000e+000,0,,0,
1524210353.512,,0.000000e+000,5.500169e+001,2.576254e-006,0.000000e+000,3,7.878508e-001,0.000000e+000,,,,,,,,,,,,,,32,1,4.000000e+000,9.208679e-003,0.000000e+000,0,,0,
1524210391.842,,0.000000e+000,5.500235e+001,2.470318e-006,0.000000e+000,3,7.993618e-001,0.000000e+000,,,,,,,,,,,,,,32,1,4.000000e+000,1.052856e-002,0.000000e+000,0,,0,
1524210429.622,,0.000000e+000,5.499905e+001,2.574616e-006,0.000000e+000,3,8.135808e-001,0.000000e+000,,,,,,,,,,,,,,32,1,4.000000e+000,3.948212e-003,0.000000e+000,0,,0,
1524210466.822,,0.000000e+000,5.500103e+001,2.595346e-006,0.000000e+000,3,8.307747e-001,0.000000e+000,,,,,,,,,,,,,,32,1,4.000000e+000,1.052094e-002,0.000000e+000,0,,0,
1524210505.412,,0.000000e+000,5.500037e+001,2.522717e-006,0.000000e+000,3,8.255937e-001,0.000000e+000,,,,,,,,,,,,,,32,1,4.000000e+000,1.184082e-002,0.000000e+000,0,,0,
1524210542.772,,0.000000e+000,5.499972e+001,2.683572e-006,0.000000e+000,3,8.081206e-001,0.000000e+000,,,,,,,,,,,,,,32,1,4.000000e+000,1.578903e-002,0.000000e+000,0,,0,
1524210581.413,,0.000000e+000,5.499773e+001,2.660600e-006,0.000000e+000,3,8.324801e-001,0.000000e+000,,,,,,,,,,,,,,32,1,4.000000e+000,1.308441e-003,0.000000e+000,0,,0,
1524210619.353,,0.000000e+000,5.500103e+001,2.639146e-006,0.000000e+000,3,8.413219e-001,0.000000e+000,,,,,,,,,,,,,,32,1,4.000000e+000,1.841736e-002,0.000000e+000,0,,0,
1524210657.153,,0.000000e+000,5.499117e+001,2.678741e-006,0.000000e+000,3,8.136364e-001,0.000000e+000,,,,,,,,,,,,,,32,1,4.000000e+000,1.708984e-002,0.000000e+000,0,,0,
1524210695.023,,0.000000e+000,5.500037e+001,2.702640e-006,0.000000e+000,3,8.370304e-001,0.000000e+000,,,,,,,,,,,,,,32,1,4.000000e+000,9.201050e-003,0.000000e+000,0,,0,
1524210732.373,,0.000000e+000,5.499117e+001,2.769409e-006,0.000000e+000,3,8.274577e-001,0.000000e+000,,,,,,,,,,,,,,32,1,4.000000e+000,3.952026e-003,0.000000e+000,0,,0,
1524210770.103,,0.000000e+000,5.500103e+001,2.764823e-006,0.000000e+000,3,8.410407e-001,0.000000e+000,,,,,,,,,,,,,,32,1,4.000000e+000,0.000000e+000,0.000000e+000,0,,0,
1524210807.843,,0.000000e+000,5.499708e+001,2.724702e-006,0.000000e+000,3,8.246351e-001,0.000000e+000,,,,,,,,,,,,,,32,1,4.000000e+000,5.260468e-003,0.000000e+000,0,,0,
1524210845.733,,0.000000e+000,5.498985e+001,2.800095e-006,0.000000e+000,3,8.443785e-001,0.000000e+000,,,,,,,,,,,,,,32,1,4.000000e+000,1.319885e-003,0.000000e+000,0,,0,
1524210883.473,,0.000000e+000,5.499773e+001,2.745235e-006,0.000000e+000,3,8.351800e-001,0.000000e+000,,,,,,,,,,,,,,32,1,4.000000e+000,1.308441e-003,0.000000e+000,0,,0,
1524210921.353,,0.000000e+000,5.499708e+001,2.854403e-006,0.000000e+000,3,8.509763e-001,0.000000e+000,,,,,,,,,,,,,,32,1,4.000000e+000,5.260468e-003,0.000000e+000,0,,0,
1524210959.093,,0.000000e+000,5.499511e+001,2.904164e-006,0.000000e+000,3,8.315928e-001,0.000000e+000,,,,,,,,,,,,,,32,1,4.000000e+000,3.940582e-003,0.000000e+000,0,,0,
1524210996.983,,0.000000e+000,5.500169e+001,2.873397e-006,0.000000e+000,3,8.515213e-001,0.000000e+000,,,,,,,,,,,,,,32,1,4.000000e+000,1.319885e-003,0.000000e+000,0,,0,
1524211034.713,,0.000000e+000,5.500235e+001,2.927745e-006,0.000000e+000,3,8.317178e-001,0.000000e+000,,,,,,,,,,,,,,32,1,4.000000e+000,2.639771e-003,0.000000e+000,0,,0,
1524211072.603,,0.000000e+000,5.500103e+001,2.887448e-006,0.000000e+000,3,8.530903e-001,0.000000e+000,,,,,,,,,,,,,,32,1,4.000000e+000,2.639771e-003,0.000000e+000,0,,0,
1524211110.353,,0.000000e+000,5.499248e+001,2.965314e-006,0.000000e+000,3,8.364838e-001,0.000000e+000,,,,,,,,,,,,,,32,1,4.000000e+000,1.182938e-002,0.000000e+000,0,,0,
1524211148.223,,0.000000e+000,5.499445e+001,2.958779e-006,0.000000e+000,3,8.595795e-001,0.000000e+000,,,,,,,,,,,,,,32,1,4.000000e+000,2.628326e-003,0.000000e+000,0,,0,
1524211186.003,,0.000000e+000,5.499905e+001,3.046361e-006,0.000000e+000,3,8.432660e-001,0.000000e+000,,,,,,,,,,,,,,32,1,4.000000e+000,1.319885e-003,0.000000e+000,0,,0,
1524211223.853,,0.000000e+000,5.499905e+001,2.966404e-006,0.000000e+000,3,8.585933e-001,0.000000e+000,,,,,,,,,,,,,,32,1,4.000000e+000,1.182938e-002,0.000000e+000,0,,0,
1524211261.594,,0.000000e+000,5.499840e+001,3.055862e-006,0.000000e+000,3,8.400258e-001,0.000000e+000,,,,,,,,,,,,,,32,1,4.000000e+000,5.260468e-003,0.000000e+000,0,,0,
1524211299.284,,0.000000e+000,5.500103e+001,3.005747e-006,0.000000e+000,3,8.705411e-001,0.000000e+000,,,,,,,,,,,,,,32,1,4.000000e+000,1.052094e-002,0.000000e+000,0,,0,
1524211336.824,,0.000000e+000,5.499577e+001,3.029731e-006,0.000000e+000,3,8.483019e-001,0.000000e+000,,,,,,,,,,,,,,32,1,4.000000e+000,2.632141e-003,0.000000e+000,0,,0,
1524211374.374,,0.000000e+000,5.499643e+001,3.067247e-006,0.000000e+000,3,8.579805e-001,0.000000e+000,,,,,,,,,,,,,,32,1,4.000000e+000,6.568909e-003,0.000000e+000,0,,0,
1524211411.524,,0.000000e+000,5.499840e+001,3.112488e-006,0.000000e+000,3,8.819599e-001,0.000000e+000,,,,,,,,,,,,,,32,1,4.000000e+000,7.900238e-003,0.000000e+000,0,,0,
1524211448.554,,0.000000e+000,5.500301e+001,3.167823e-006,0.000000e+000,3,8.617787e-001,0.000000e+000,,,,,,,,,,,,,,32,1,4.000000e+000,1.319885e-003,0.000000e+000,0,,0,
1524211486.054,,0.000000e+000,5.499840e+001,3.118970e-006,0.000000e+000,3,8.720809e-001,0.000000e+000,,,,,,,,,,,,,,32,1,4.000000e+000,2.628326e-003,0.000000e+000,0,,0,
1524211523.684,,0.000000e+000,5.499643e+001,3.203140e-006,0.000000e+000,3,8.584501e-001,0.000000e+000,,,,,,,,,,,,,,32,1,4.000000e+000,1.312256e-003,0.000000e+000,0,,0,
1524211561.694,,0.000000e+000,5.499774e+001,3.114989e-006,0.000000e+000,3,8.714212e-001,0.000000e+000,,,,,,,,,,,,,,32,1,4.000000e+000,1.446152e-002,0.000000e+000,0,,0,
1524211598.704,,0.000000e+000,5.499840e+001,3.213529e-006,0.000000e+000,3,8.667135e-001,0.000000e+000,,,,,,,,,,,,,,32,1,4.000000e+000,5.260468e-003,0.000000e+000,0,,0,
1524211636.204,,0.000000e+000,5.500037e+001,3.170544e-006,0.000000e+000,3,8.832693e-001,0.000000e+000,,,,,,,,,,,,,,32,1,4.000000e+000,3.959656e-003,0.000000e+000,0,,0,
1524211673.834,,0.000000e+000,5.500234e+001,3.257278e-006,0.000000e+000,3,8.872355e-001,0.000000e+000,,,,,,,,,,,,,,32,1,4.000000e+000,5.260468e-003,0.000000e+000,0,,0,
1524211711.284,,0.000000e+000,5.499839e+001,3.097477e-006,0.000000e+000,3,8.662498e-001,0.000000e+000,,,,,,,,,,,,,,32,1,4.000000e+000,0.000000e+000,0.000000e+000,0,,0,
1524211748.404,,0.000000e+000,5.499905e+001,3.222600e-006,0.000000e+000,3,8.670271e-001,0.000000e+000,,,,,,,,,,,,,,32,1,4.000000e+000,3.948212e-003,0.000000e+000,0,,0,
1524211786.954,,0.000000e+000,5.499905e+001,3.210056e-006,0.000000e+000,3,8.671959e-001,0.000000e+000,,,,,,,,,,,,,,32,1,4.000000e+000,1.319885e-003,0.000000e+000,0,,0,
1524211825.444,,0.000000e+000,5.499577e+001,3.187237e-006,0.000000e+000,3,8.783865e-001,0.000000e+000,,,,,,,,,,,,,,32,1,4.000000e+000,5.249023e-003,0.000000e+000,0,,0,
1524211862.664,,0.000000e+000,5.499775e+001,3.276645e-006,0.000000e+000,3,8.752149e-001,0.000000e+000,,,,,,,,,,,,,,32,1,4.000000e+000,9.208679e-003,0.000000e+000,0,,0,
1524211901.354,,0.000000e+000,5.500037e+001,3.326419e-006,0.000000e+000,3,8.734440e-001,0.000000e+000,,,,,,,,,,,,,,32,1,4.000000e+000,6.587982e-003,0.000000e+000,0,,0,
1524211939.274,,0.000000e+000,5.499971e+001,3.239089e-006,0.000000e+000,3,8.732802e-001,0.000000e+000,,,,,,,,,,,,,,32,1,4.000000e+000,0.000000e+000,0.000000e+000,0,,0,
1524211976.925,,0.000000e+000,5.499905e+001,3.321336e-006,0.000000e+000,3,8.647913e-001,0.000000e+000,,,,,,,,,,,,,,32,1,4.000000e+000,3.948212e-003,0.000000e+000,0,,0,
1524212014.905,,0.000000e+000,5.499841e+001,3.266280e-006,0.000000e+000,3,8.760885e-001,0.000000e+000,,,,,,,,,,,,,,32,1,4.000000e+000,1.052856e-002,0.000000e+000,0,,0,
1524212052.535,,0.000000e+000,5.500103e+001,3.333513e-006,0.000000e+000,3,8.697911e-001,0.000000e+000,,,,,,,,,,,,,,32,1,4.000000e+000,1.316071e-002,0.000000e+000,0,,0,
1524212090.555,,0.000000e+000,5.500037e+001,3.295166e-006,0.000000e+000,3,8.828254e-001,0.000000e+000,,,,,,,,,,,,,,32,1,4.000000e+000,1.319885e-003,0.000000e+000,0,,0,
1524212128.165,,0.000000e+000,5.499248e+001,3.298177e-006,0.000000e+000,3,8.621461e-001,0.000000e+000,,,,,,,,,,,,,,32,1,4.000000e+000,3.940582e-003,0.000000e+000,0,,0,
1524212166.165,,0.000000e+000,5.499905e+001,3.348742e-006,0.000000e+000,3,8.844358e-001,0.000000e+000,,,,,,,,,,,,,,32,1,4.000000e+000,1.319885e-003,0.000000e+000,0,,0,
1524212203.755,,0.000000e+000,5.499117e+001,3.377094e-006,0.000000e+000,3,8.701361e-001,0.000000e+000,,,,,,,,,,,,,,32,1,4.000000e+000,1.312256e-003,0.000000e+000,0,,0,
1524212241.805,,0.000000e+000,5.499708e+001,3.318374e-006,0.000000e+000,3,8.848551e-001,0.000000e+000,,,,,,,,,,,,,,32,1,4.000000e+000,0.000000e+000,0.000000e+000,0,,0,
1524212279.435,,0.000000e+000,5.499972e+001,3.382267e-006,0.000000e+000,3,8.700609e-001,0.000000e+000,,,,,,,,,,,,,,32,1,4.000000e+000,5.268097e-003,0.000000e+000,0,,0,
1524212317.435,,0.000000e+000,5.499906e+001,3.298749e-006,0.000000e+000,3,8.873432e-001,0.000000e+000,,,,,,,,,,,,,,32,1,4.000000e+000,6.580353e-003,0.000000e+000,0,,0,
1524212355.015,,0.000000e+000,5.499709e+001,3.460981e-006,0.000000e+000,3,8.754795e-001,0.000000e+000,,,,,,,,,,,,,,32,1,4.000000e+000,1.316071e-002,0.000000e+000,0,,0,
1524212393.065,,0.000000e+000,5.500103e+001,3.317014e-006,0.000000e+000,3,8.816844e-001,0.000000e+000,,,,,,,,,,,,,,32,1,4.000000e+000,5.279541e-003,0.000000e+000,0,,0,
1524212430.485,,0.000000e+000,5.500037e+001,3.455839e-006,0.000000e+000,3,8.732793e-001,0.000000e+000,,,,,,,,,,,,,,32,1,4.000000e+000,6.587982e-003,0.000000e+000,0,,0,
1524212468.695,,0.000000e+000,5.499971e+001,3.468512e-006,0.000000e+000,3,8.912860e-001,0.000000e+000,,,,,,,,,,,,,,32,1,4.000000e+000,2.639771e-003,0.000000e+000,0,,0,
1524212506.445,,0.000000e+000,5.499840e+001,3.417192e-006,0.000000e+000,3,8.991898e-001,0.000000e+000,,,,,,,,,,,,,,32,1,4.000000e+000,1.314926e-002,0.000000e+000,0,,0,
1524212544.705,,0.000000e+000,5.499905e+001,3.483586e-006,0.000000e+000,3,8.674974e-001,0.000000e+000,,,,,,,,,,,,,,32,1,4.000000e+000,1.319885e-003,0.000000e+000,0,,0,
1524212582.695,,0.000000e+000,5.499380e+001,3.417209e-006,0.000000e+000,3,8.830944e-001,0.000000e+000,,,,,,,,,,,,,,32,1,4.000000e+000,1.308441e-003,0.000000e+000,0,,0,
1524212620.295,,0.000000e+000,5.499972e+001,3.516119e-006,0.000000e+000,3,9.024391e-001,0.000000e+000,,,,,,,,,,,,,,32,1,4.000000e+000,5.268097e-003,0.000000e+000,0,,0,
1524212658.305,,0.000000e+000,5.499642e+001,3.469971e-006,0.000000e+000,3,8.880540e-001,0.000000e+000,,,,,,,,,,,,,,32,1,4.000000e+000,3.940582e-003,0.000000e+000,0,,0,
1524212696.156,,0.000000e+000,5.499577e+001,3.455502e-006,0.000000e+000,3,9.026908e-001,0.000000e+000,,,,,,,,,,,,,,32,1,4.000000e+000,0.000000e+000,0.000000e+000,0,,0,
1524212733.336,,0.000000e+000,5.499708e+001,3.454712e-006,0.000000e+000,3,8.797971e-001,0.000000e+000,,,,,,,,,,,,,,32,1,4.000000e+000,5.260468e-003,0.000000e+000,0,,0,
1524212770.656,,0.000000e+000,5.500037e+001,3.512938e-006,0.000000e+000,3,8.936741e-001,0.000000e+000,,,,,,,,,,,,,,32,1,4.000000e+000,3.959656e-003,0.000000e+000,0,,0,
1524212808.496,,0.000000e+000,5.499642e+001,3.460219e-006,0.000000e+000,3,9.069231e-001,0.000000e+000,,,,,,,,,,,,,,32,1,4.000000e+000,3.940582e-003,0.000000e+000,0,,0,
1524212846.116,,0.000000e+000,5.499905e+001,3.500705e-006,0.000000e+000,3,8.721651e-001,0.000000e+000,,,,,,,,,,,,,,32,1,4.000000e+000,1.319885e-003,0.000000e+000,0,,0,
1524212884.066,,0.000000e+000,5.499642e+001,3.452531e-006,0.000000e+000,3,8.868116e-001,0.000000e+000,,,,,,,,,,,,,,32,1,4.000000e+000,3.940582e-003,0.000000e+000,0,,0,
1524212921.676,,0.000000e+000,5.499643e+001,3.512375e-006,0.000000e+000,3,9.020067e-001,0.000000e+000,,,,,,,,,,,,,,32,1,4.000000e+000,9.208679e-003,0.000000e+000,0,,0,
1524212959.116,,0.000000e+000,5.500103e+001,3.515910e-006,0.000000e+000,3,9.014202e-001,0.000000e+000,,,,,,,,,,,,,,32,1,4.000000e+000,2.639771e-003,0.000000e+000,0,,0,
1524212996.816,,0.000000e+000,5.499840e+001,3.548987e-006,0.000000e+000,3,8.762940e-001,0.000000e+000,,,,,,,,,,,,,,32,1,4.000000e+000,2.628326e-003,0.000000e+000,0,,0,
1524213034.796,,0.000000e+000,5.499906e+001,3.504657e-006,0.000000e+000,3,8.882040e-001,0.000000e+000,,,,,,,,,,,,,,32,1,4.000000e+000,6.580353e-003,0.000000e+000,0,,0,
1524213072.886,,0.000000e+000,5.499906e+001,3.463833e-006,0.000000e+000,3,8.900532e-001,0.000000e+000,,,,,,,,,,,,,,32,1,4.000000e+000,6.580353e-003,0.000000e+000,0,,0,
1524213110.766,,0.000000e+000,5.500168e+001,3.541555e-006,0.000000e+000,3,8.812841e-001,0.000000e+000,,,,,,,,,,,,,,32,1,4.000000e+000,6.580353e-003,0.000000e+000,0,,0,
1524213148.326,,0.000000e+000,5.500564e+001,3.506608e-006,0.000000e+000,3,8.858022e-001,0.000000e+000,,,,,,,,,,,,,,32,1,4.000000e+000,3.940582e-003,0.000000e+000,0,,0,
1524213185.866,,0.000000e+000,5.499643e+001,3.534900e-006,0.000000e+000,3,8.797604e-001,0.000000e+000,,,,,,,,,,,,,,32,1,4.000000e+000,6.568909e-003,0.000000e+000,0,,0,
1524213223.286,,0.000000e+000,5.499971e+001,3.508274e-006,0.000000e+000,3,8.892226e-001,0.000000e+000,,,,,,,,,,,,,,32,1,4.000000e+000,2.639771e-003,0.000000e+000,0,,0,
1524213261.376,,0.000000e+000,5.500301e+001,3.592176e-006,0.000000e+000,3,8.703511e-001,0.000000e+000,,,,,,,,,,,,,,32,1,4.000000e+000,1.319885e-003,0.000000e+000,0,,0,
1524213299.796,,0.000000e+000,5.499248e+001,3.572615e-006,0.000000e+000,3,8.771039e-001,0.000000e+000,,,,,,,,,,,,,,32,1,4.000000e+000,3.940582e-003,0.000000e+000,0,,0,
1524213337.826,,0.000000e+000,5.500103e+001,3.599295e-006,0.000000e+000,3,8.977958e-001,0.000000e+000,,,,,,,,,,,,,,32,1,4.000000e+000,0.000000e+000,0.000000e+000,0,,0,
1524213375.546,,0.000000e+000,5.499906e+001,3.615612e-006,0.000000e+000,3,8.774680e-001,0.000000e+000,,,,,,,,,,,,,,32,1,4.000000e+000,6.580353e-003,0.000000e+000,0,,0,
1524213413.457,,0.000000e+000,5.499577e+001,3.590527e-006,0.000000e+000,3,9.058465e-001,0.000000e+000,,,,,,,,,,,,,,32,1,4.000000e+000,2.632141e-003,0.000000e+000,0,,0,
1524213450.767,,0.000000e+000,5.499511e+001,3.627158e-006,0.000000e+000,3,8.823937e-001,0.000000e+000,,,,,,,,,,,,,,32,1,4.000000e+000,1.319885e-003,0.000000e+000,0,,0,
1524213488.577,,0.000000e+000,5.499248e+001,3.564220e-006,0.000000e+000,3,8.925739e-001,0.000000e+000,,,,,,,,,,,,,,32,1,4.000000e+000,1.319885e-003,0.000000e+000,0,,0,
1524213525.867,,0.000000e+000,5.499774e+001,3.592677e-006,0.000000e+000,3,8.788970e-001,0.000000e+000,,,,,,,,,,,,,,32,1,4.000000e+000,3.940582e-003,0.000000e+000,0,,0,
1524213563.867,,0.000000e+000,5.499314e+001,3.611253e-006,0.000000e+000,3,8.881343e-001,0.000000e+000,,,,,,,,,,,,,,32,1,4.000000e+000,5.260468e-003,0.000000e+000,0,,0,
1524213601.707,,0.000000e+000,5.499511e+001,3.533641e-006,0.000000e+000,3,8.942528e-001,0.000000e+000,,,,,,,,,,,,,,32,1,4.000000e+000,3.940582e-003,0.000000e+000,0,,0,
1524213640.027,,0.000000e+000,5.499445e+001,3.651892e-006,0.000000e+000,3,8.901424e-001,0.000000e+000,,,,,,,,,,,,,,32,1,4.000000e+000,1.052094e-002,0.000000e+000,0,,0,
1524213678.327,,0.000000e+000,5.499511e+001,3.585782e-006,0.000000e+000,3,8.947765e-001,0.000000e+000,,,,,,,,,,,,,,32,1,4.000000e+000,1.319885e-003,0.000000e+000,0,,0,
1524213717.077,,0.000000e+000,5.499905e+001,3.605933e-006,0.000000e+000,3,8.991979e-001,0.000000e+000,,,,,,,,,,,,,,32,1,4.000000e+000,3.948212e-003,0.000000e+000,0,,0,
1524213754.757,,0.000000e+000,5.500366e+001,3.662610e-006,0.000000e+000,3,8.804761e-001,0.000000e+000,,,,,,,,,,,,,,32,1,4.000000e+000,5.260468e-003,0.000000e+000,0,,0,
1524213792.707,,0.000000e+000,5.499380e+001,3.695356e-006,0.000000e+000,3,8.938093e-001,0.000000e+000,,,,,,,,,,,,,,32,1,4.000000e+000,3.948212e-003,0.000000e+000,0,,0,
1524213830.597,,0.000000e+000,5.500169e+001,3.708525e-006,0.000000e+000,3,9.115376e-001,0.000000e+000,,,,,,,,,,,,,,32,1,4.000000e+000,1.709747e-002,0.000000e+000,0,,0,
1524213867.797,,0.000000e+000,5.499313e+001,3.634194e-006,0.000000e+000,3,8.970103e-001,0.000000e+000,,,,,,,,,,,,,,32,1,4.000000e+000,1.050949e-002,0.000000e+000,0,,0,
1524213905.347,,0.000000e+000,5.499577e+001,3.656441e-006,0.000000e+000,3,8.916108e-001,0.000000e+000,,,,,,,,,,,,,,32,1,4.000000e+000,5.249023e-003,0.000000e+000,0,,0,
1524213943.677,,0.000000e+000,5.499708e+001,3.637276e-006,0.000000e+000,3,8.816131e-001,0.000000e+000,,,,,,,,,,,,,,32,1,4.000000e+000,2.620697e-003,0.000000e+000,0,,0,
1524213981.237,,0.000000e+000,5.500037e+001,3.651890e-006,0.000000e+000,3,8.969078e-001,0.000000e+000,,,,,,,,,,,,,,32,1,4.000000e+000,3.959656e-003,0.000000e+000,0,,0,
1524214018.427,,0.000000e+000,5.499840e+001,3.713540e-006,0.000000e+000,3,8.840732e-001,0.000000e+000,,,,,,,,,,,,,,32,1,4.000000e+000,2.628326e-003,0.000000e+000,0,,0,
1524214056.317,,0.000000e+000,5.500037e+001,3.684530e-006,0.000000e+000,3,8.948069e-001,0.000000e+000,,,,,,,,,,,,,,32,1,4.000000e+000,9.201050e-003,0.000000e+000,0,,0,
1524214093.627,,0.000000e+000,5.500366e+001,3.710724e-006,0.000000e+000,3,8.837408e-001,0.000000e+000,,,,,,,,,,,,,,32,1,4.000000e+000,1.578140e-002,0.000000e+000,0,,0,
1524214131.608,,0.000000e+000,5.499905e+001,3.657879e-006,0.000000e+000,3,9.184375e-001,0.000000e+000,,,,,,,,,,,,,,32,1,4.000000e+000,1.319885e-003,0.000000e+000,0,,0,
1524214170.038,,0.000000e+000,5.499709e+001,3.723024e-006,0.000000e+000,3,9.068211e-001,0.000000e+000,,,,,,,,,,,,,,32,1,4.000000e+000,7.888794e-003,0.000000e+000,0,,0,
1524214207.898,,0.000000e+000,5.499972e+001,3.796694e-006,0.000000e+000,3,9.089532e-001,0.000000e+000,,,,,,,,,,,,,,32,1,4.000000e+000,5.268097e-003,0.000000e+000,0,,0,
1524214245.898,,0.000000e+000,5.499511e+001,3.714906e-006,0.000000e+000,3,9.148434e-001,0.000000e+000,,,,,,,,,,,,,,32,1,4.000000e+000,6.568909e-003,0.000000e+000,0,,0,
1524214283.268,,0.000000e+000,5.500103e+001,3.758854e-006,0.000000e+000,3,8.917623e-001,0.000000e+000,,,,,,,,,,,,,,32,1,4.000000e+000,1.052094e-002,0.000000e+000,0,,0,
1524214320.938,,0.000000e+000,5.499643e+001,3.704202e-006,0.000000e+000,3,8.909622e-001,0.000000e+000,,,,,,,,,,,,,,32,1,4.000000e+000,9.208679e-003,0.000000e+000,0,,0,
1524214359.098,,0.000000e+000,5.500300e+001,3.683485e-006,0.000000e+000,3,9.021704e-001,0.000000e+000,,,,,,,,,,,,,,32,1,4.000000e+000,1.710129e-002,0.000000e+000,0,,0,
1524214397.068,,0.000000e+000,5.499840e+001,3.756752e-006,0.000000e+000,3,8.944887e-001,0.000000e+000,,,,,,,,,,,,,,32,1,4.000000e+000,5.260468e-003,0.000000e+000,0,,0,
1524214434.418,,0.000000e+000,5.500168e+001,3.699163e-006,0.000000e+000,3,9.102570e-001,0.000000e+000,,,,,,,,,,,,,,32,1,4.000000e+000,6.580353e-003,0.000000e+000,0,,0,
1524214472.118,,0.000000e+000,5.499906e+001,3.772822e-006,0.000000e+000,3,8.932694e-001,0.000000e+000,,,,,,,,,,,,,,32,1,4.000000e+000,6.580353e-003,0.000000e+000,0,,0,
1524214509.998,,0.000000e+000,5.499511e+001,3.702046e-006,0.000000e+000,3,8.995304e-001,0.000000e+000,,,,,,,,,,,,,,32,1,4.000000e+000,3.940582e-003,0.000000e+000,0,,0,
1524214547.698,,0.000000e+000,5.499840e+001,3.759259e-006,0.000000e+000,3,8.865198e-001,0.000000e+000,,,,,,,,,,,,,,32,1,4.000000e+000,2.628326e-003,0.000000e+000,0,,0,
1524214585.608,,0.000000e+000,5.499840e+001,3.760118e-006,0.000000e+000,3,9.002061e-001,0.000000e+000,,,,,,,,,,,,,,32,1,4.000000e+000,5.260468e-003,0.000000e+000,0,,0,
1524214622.888,,0.000000e+000,5.499709e+001,3.819450e-006,0.000000e+000,3,9.237431e-001,0.000000e+000,,,,,,,,,,,,,,32,1,4.000000e+000,7.888794e-003,0.000000e+000,0,,0,
1524214661.038,,0.000000e+000,5.499972e+001,3.790523e-006,0.000000e+000,3,8.892658e-001,0.000000e+000,,,,,,,,,,,,,,32,1,4.000000e+000,7.900238e-003,0.000000e+000,0,,0,
1524214698.788,,0.000000e+000,5.499380e+001,3.769469e-006,0.000000e+000,3,9.021452e-001,0.000000e+000,,,,,,,,,,,,,,32,1,4.000000e+000,3.948212e-003,0.000000e+000,0,,0,
1524214736.538,,0.000000e+000,5.499972e+001,3.789389e-006,0.000000e+000,3,8.905855e-001,0.000000e+000,,,,,,,,,,,,,,32,1,4.000000e+000,5.268097e-003,0.000000e+000,0,,0,
1524214774.388,,0.000000e+000,5.499117e+001,3.722034e-006,0.000000e+000,3,8.970931e-001,0.000000e+000,,,,,,,,,,,,,,32,1,4.000000e+000,3.952026e-003,0.000000e+000,0,,0,
1524214812.118,,0.000000e+000,5.499708e+001,3.738341e-006,0.000000e+000,3,8.861620e-001,0.000000e+000,,,,,,,,,,,,,,32,1,4.000000e+000,5.260468e-003,0.000000e+000,0,,0,
1524214849.989,,0.000000e+000,5.499445e+001,3.765905e-006,0.000000e+000,3,8.984598e-001,0.000000e+000,,,,,,,,,,,,,,32,1,4.000000e+000,0.000000e+000,0.000000e+000,0,,0,
1524214887.739,,0.000000e+000,5.500498e+001,3.843177e-006,0.000000e+000,3,8.899859e-001,0.000000e+000,,,,,,,,,,,,,,32,1,4.000000e+000,2.620697e-003,0.000000e+000,0,,0,
1524214925.589,,0.000000e+000,5.499773e+001,3.737715e-006,0.000000e+000,3,9.029202e-001,0.000000e+000,,,,,,,,,,,,,,32,1,4.000000e+000,1.308441e-003,0.000000e+000,0,,0,
1524214963.329,,0.000000e+000,5.500037e+001,3.817239e-006,0.000000e+000,3,8.833259e-001,0.000000e+000,,,,,,,,,,,,,,32,1,4.000000e+000,1.446915e-002,0.000000e+000,0,,0,
1524215001.189,,0.000000e+000,5.499577e+001,3.774142e-006,0.000000e+000,3,9.027193e-001,0.000000e+000,,,,,,,,,,,,,,32,1,4.000000e+000,0.000000e+000,0.000000e+000,0,,0,
1524215038.929,,0.000000e+000,5.499577e+001,3.805831e-006,0.000000e+000,3,8.884320e-001,0.000000e+000,,,,,,,,,,,,,,32,1,4.000000e+000,1.316071e-002,0.000000e+000,0,,0,
1524215076.789,,0.000000e+000,5.499577e+001,3.691458e-006,0.000000e+000,3,9.050013e-001,0.000000e+000,,,,,,,,,,,,,,32,1,4.000000e+000,7.888794e-003,0.000000e+000,0,,0,
1524215114.539,,0.000000e+000,5.499511e+001,3.853519e-006,0.000000e+000,3,8.941965e-001,0.000000e+000,,,,,,,,,,,,,,32,1,4.000000e+000,3.940582e-003,0.000000e+000,0,,0,
1524215152.409,,0.000000e+000,5.499905e+001,3.690008e-006,0.000000e+000,3,9.032730e-001,0.000000e+000,,,,,,,,,,,,,,32,1,4.000000e+000,1.319885e-003,0.000000e+000,0,,0,
1524215190.139,,0.000000e+000,5.500037e+001,3.827603e-006,0.000000e+000,3,8.915788e-001,0.000000e+000,,,,,,,,,,,,,,32,1,4.000000e+000,9.201050e-003,0.000000e+000,0,,0,
1524215228.029,,0.000000e+000,5.500037e+001,3.708712e-006,0.000000e+000,3,9.123747e-001,0.000000e+000,,,,,,,,,,,,,,32,1,4.000000e+000,1.319885e-003,0.000000e+000,0,,0,
1524215265.799,,0.000000e+000,5.500366e+001,3.857768e-006,0.000000e+000,3,8.895288e-001,0.000000e+000,,,,,,,,,,,,,,32,1,4.000000e+000,5.260468e-003,0.000000e+000,0,,0,
1524215303.659,,0.000000e+000,5.499775e+001,3.754423e-006,0.000000e+000,3,8.936782e-001,0.000000e+000,,,,,,,,,,,,,,32,1,4.000000e+000,9.208679e-003,0.000000e+000,0,,0,
1524215341.399,,0.000000e+000,5.500037e+001,3.826052e-006,0.000000e+000,3,9.007860e-001,0.000000e+000,,,,,,,,,,,,,,32,1,4.000000e+000,1.319885e-003,0.000000e+000,0,,0,
1524215379.289,,0.000000e+000,5.500037e+001,3.752227e-006,0.000000e+000,3,9.130933e-001,0.000000e+000,,,,,,,,,,,,,,32,1,4.000000e+000,6.587982e-003,0.000000e+000,0,,0,
1524215417.039,,0.000000e+000,5.500037e+001,3.792793e-006,0.000000e+000,3,8.862523e-001,0.000000e+000,,,,,,,,,,,,,,32,1,4.000000e+000,6.587982e-003,0.000000e+000,0,,0,
1524215454.919,,0.000000e+000,5.500234e+001,3.752295e-006,0.000000e+000,3,8.996032e-001,0.000000e+000,,,,,,,,,,,,,,32,1,4.000000e+000,5.260468e-003,0.000000e+000,0,,0,
1524215492.649,,0.000000e+000,5.500169e+001,3.804032e-006,0.000000e+000,3,8.908628e-001,0.000000e+000,,,,,,,,,,,,,,32,1,4.000000e+000,1.319885e-003,0.000000e+000,0,,0,
1524215530.539,,0.000000e+000,5.499445e+001,3.760431e-006,0.000000e+000,3,9.074611e-001,0.000000e+000,,,,,,,,,,,,,,32,1,4.000000e+000,0.000000e+000,0.000000e+000,0,,0,
1524215568.270,,0.000000e+000,5.499577e+001,3.816961e-006,0.000000e+000,3,8.903820e-001,0.000000e+000,,,,,,,,,,,,,,32,1,4.000000e+000,2.632141e-003,0.000000e+000,0,,0,
1524215606.140,,0.000000e+000,5.499708e+001,3.785838e-006,0.000000e+000,3,9.085733e-001,0.000000e+000,,,,,,,,,,,,,,32,1,4.000000e+000,5.260468e-003,0.000000e+000,0,,0,
1524215643.870,,0.000000e+000,5.500235e+001,3.856747e-006,0.000000e+000,3,8.912413e-001,0.000000e+000,,,,,,,,,,,,,,32,1,4.000000e+000,2.639771e-003,0.000000e+000,0,,0,
1524215681.750,,0.000000e+000,5.500235e+001,3.836877e-006,0.000000e+000,3,9.031617e-001,0.000000e+000,,,,,,,,,,,,,,32,1,4.000000e+000,1.052856e-002,0.000000e+000,0,,0,
1524215719.470,,0.000000e+000,5.500301e+001,3.892437e-006,0.000000e+000,3,8.970466e-001,0.000000e+000,,,,,,,,,,,,,,32,1,4.000000e+000,1.319885e-003,0.000000e+000,0,,0,
1524215757.360,,0.000000e+000,5.499051e+001,3.847303e-006,0.000000e+000,3,9.033490e-001,0.000000e+000,,,,,,,,,,,,,,32,1,4.000000e+000,0.000000e+000,0.000000e+000,0,,0,
1524215795.080,,0.000000e+000,5.499117e+001,3.838889e-006,0.000000e+000,3,8.925874e-001,0.000000e+000,,,,,,,,,,,,,,32,1,4.000000e+000,9.208679e-003,0.000000e+000,0,,0,
1524215832.960,,0.000000e+000,5.499971e+001,3.844587e-006,0.000000e+000,3,9.071399e-001,0.000000e+000,,,,,,,,,,,,,,32,1,4.000000e+000,1.052094e-002,0.000000e+000,0,,0,
1524215870.710,,0.000000e+000,5.499774e+001,3.872682e-006,0.000000e+000,3,8.899142e-001,0.000000e+000,,,,,,,,,,,,,,32,1,4.000000e+000,3.940582e-003,0.000000e+000,0,,0,
1524215908.570,,0.000000e+000,5.499972e+001,3.868051e-006,0.000000e+000,3,9.087376e-001,0.000000e+000,,,,,,,,,,,,,,32,1,4.000000e+000,5.268097e-003,0.000000e+000,0,,0,
1524215946.300,,0.000000e+000,5.499773e+001,3.893084e-006,0.000000e+000,3,8.959150e-001,0.000000e+000,,,,,,,,,,,,,,32,1,4.000000e+000,1.308441e-003,0.000000e+000,0,,0,
1524215984.170,,0.000000e+000,5.499905e+001,3.850959e-006,0.000000e+000,3,9.037315e-001,0.000000e+000,,,,,,,,,,,,,,32,1,4.000000e+000,3.948212e-003,0.000000e+000,0,,0,
1524216021.850,,0.000000e+000,5.499512e+001,3.910008e-006,0.000000e+000,3,8.953256e-001,0.000000e+000,,,,,,,,,,,,,,32,1,4.000000e+000,1.446915e-002,0.000000e+000,0,,0,
1524216059.870,,0.000000e+000,5.499642e+001,3.937683e-006,0.000000e+000,3,9.046453e-001,0.000000e+000,,,,,,,,,,,,,,32,1,4.000000e+000,3.940582e-003,0.000000e+000,0,,0,
1524216097.940,,0.000000e+000,5.499313e+001,3.880165e-006,0.000000e+000,3,9.005239e-001,0.000000e+000,,,,,,,,,,,,,,32,1,4.000000e+000,1.314926e-002,0.000000e+000,0,,0,
1524216136.010,,0.000000e+000,5.499577e+001,3.935855e-006,0.000000e+000,3,8.915978e-001,0.000000e+000,,,,,,,,,,,,,,32,1,4.000000e+000,0.000000e+000,0.000000e+000,0,,0,
1524216173.740,,0.000000e+000,5.499839e+001,3.826659e-006,0.000000e+000,3,9.091530e-001,0.000000e+000,,,,,,,,,,,,,,32,1,4.000000e+000,0.000000e+000,0.000000e+000,0,,0,
1524216211.550,,0.000000e+000,5.499840e+001,3.976195e-006,0.000000e+000,3,9.154748e-001,0.000000e+000,,,,,,,,,,,,,,32,1,4.000000e+000,5.260468e-003,0.000000e+000,0,,0,
1524216249.800,,0.000000e+000,5.499643e+001,3.919527e-006,0.000000e+000,3,8.992482e-001,0.000000e+000,,,,,,,,,,,,,,32,1,4.000000e+000,6.568909e-003,0.000000e+000,0,,0,
1524216287.701,,0.000000e+000,5.499577e+001,3.919235e-006,0.000000e+000,3,9.059479e-001,0.000000e+000,,,,,,,,,,,,,,32,1,4.000000e+000,5.249023e-003,0.000000e+000,0,,0,
1524216325.091,,0.000000e+000,5.499840e+001,3.990188e-006,0.000000e+000,3,9.004014e-001,0.000000e+000,,,,,,,,,,,,,,32,1,4.000000e+000,2.628326e-003,0.000000e+000,0,,0,
1524216362.831,,0.000000e+000,5.500432e+001,3.905912e-006,0.000000e+000,3,9.011847e-001,0.000000e+000,,,,,,,,,,,,,,32,1,4.000000e+000,1.446915e-002,0.000000e+000,0,,0,
1524216401.191,,0.000000e+000,5.499248e+001,3.891701e-006,0.000000e+000,3,9.093645e-001,0.000000e+000,,,,,,,,,,,,,,32,1,4.000000e+000,1.319885e-003,0.000000e+000,0,,0,
1524216438.651,,0.000000e+000,5.499971e+001,3.972078e-006,0.000000e+000,3,8.940542e-001,0.000000e+000,,,,,,,,,,,,,,32,1,4.000000e+000,0.000000e+000,0.000000e+000,0,,0,
1524216476.371,,0.000000e+000,5.500037e+001,3.947017e-006,0.000000e+000,3,9.102250e-001,0.000000e+000,,,,,,,,,,,,,,32,1,4.000000e+000,6.587982e-003,0.000000e+000,0,,0,
1524216513.741,,0.000000e+000,5.500168e+001,3.992265e-006,0.000000e+000,3,8.929366e-001,0.000000e+000,,,,,,,,,,,,,,32,1,4.000000e+000,6.580353e-003,0.000000e+000,0,,0,
1524216551.191,,0.000000e+000,5.499445e+001,3.899623e-006,0.000000e+000,3,9.070117e-001,0.000000e+000,,,,,,,,,,,,,,32,1,4.000000e+000,5.260468e-003,0.000000e+000,0,,0,
1524216588.961,,0.000000e+000,5.499773e+001,3.963461e-006,0.000000e+000,3,8.897498e-001,0.000000e+000,,,,,,,,,,,,,,32,1,4.000000e+000,1.308441e-003,0.000000e+000,0,,0,
1524216626.791,,0.000000e+000,5.499643e+001,3.915898e-006,0.000000e+000,3,9.078597e-001,0.000000e+000,,,,,,,,,,,,,,32,1,4.000000e+000,1.312256e-003,0.000000e+000,0,,0,
1524216664.521,,0.000000e+000,5.499511e+001,3.931505e-006,0.000000e+000,3,8.965082e-001,0.000000e+000,,,,,,,,,,,,,,32,1,4.000000e+000,6.568909e-003,0.000000e+000,0,,0,
1524216702.391,,0.000000e+000,5.499774e+001,3.920105e-006,0.000000e+000,3,8.996996e-001,0.000000e+000,,,,,,,,,,,,,,32,1,4.000000e+000,6.580353e-003,0.000000e+000,0,,0,
1524216740.131,,0.000000e+000,5.500169e+001,3.962026e-006,0.000000e+000,3,8.975683e-001,0.000000e+000,,,,,,,,,,,,,,32,1,4.000000e+000,1.319885e-003,0.000000e+000,0,,0,
1524216777.991,,0.000000e+000,5.499905e+001,3.926886e-006,0.000000e+000,3,9.029112e-001,0.000000e+000,,,,,,,,,,,,,,32,1,4.000000e+000,1.182938e-002,0.000000e+000,0,,0,
1524216816.431,,0.000000e+000,5.500431e+001,3.998280e-006,0.000000e+000,3,8.928039e-001,0.000000e+000,,,,,,,,,,,,,,32,1,4.000000e+000,9.208679e-003,0.000000e+000,0,,0,
1524216853.941,,0.000000e+000,5.499971e+001,3.981600e-006,0.000000e+000,3,9.229124e-001,0.000000e+000,,,,,,,,,,,,,,32,1,4.000000e+000,0.000000e+000,0.000000e+000,0,,0,
1524216891.731,,0.000000e+000,5.500169e+001,3.940345e-006,0.000000e+000,3,8.978838e-001,0.000000e+000,,,,,,,,,,,,,,32,1,4.000000e+000,3.959656e-003,0.000000e+000,0,,0,
1524216930.401,,0.000000e+000,5.499314e+001,4.018443e-006,0.000000e+000,3,9.187340e-001,0.000000e+000,,,,,,,,,,,,,,32,1,4.000000e+000,0.000000e+000,0.000000e+000,0,,0,
1524216968.341,,0.000000e+000,5.499839e+001,3.961381e-006,0.000000e+000,3,9.124784e-001,0.000000e+000,,,,,,,,,,,,,,32,1,4.000000e+000,0.000000e+000,0.000000e+000,0,,0,
1524217005.892,,0.000000e+000,5.499445e+001,3.948975e-006,0.000000e+000,3,8.983040e-001,0.000000e+000,,,,,,,,,,,,,,32,1,4.000000e+000,2.628326e-003,0.000000e+000,0,,0,
1524217043.982,,0.000000e+000,5.499773e+001,3.909725e-006,0.000000e+000,3,9.069306e-001,0.000000e+000,,,,,,,,,,,,,,32,1,4.000000e+000,1.308441e-003,0.000000e+000,0,,0,
1524217081.522,,0.000000e+000,5.500037e+001,3.944539e-006,0.000000e+000,3,8.914338e-001,0.000000e+000,,,,,,,,,,,,,,32,1,4.000000e+000,6.587982e-003,0.000000e+000,0,,0,
1524217119.532,,0.000000e+000,5.499511e+001,3.948855e-006,0.000000e+000,3,9.071915e-001,0.000000e+000,,,,,,,,,,,,,,32,1,4.000000e+000,6.568909e-003,0.000000e+000,0,,0,
1524217157.142,,0.000000e+000,5.500300e+001,4.000560e-006,0.000000e+000,3,8.894317e-001,0.000000e+000,,,,,,,,,,,,,,32,1,4.000000e+000,3.940582e-003,0.000000e+000,0,,0,
1524217195.162,,0.000000e+000,5.499643e+001,3.955232e-006,0.000000e+000,3,9.067070e-001,0.000000e+000,,,,,,,,,,,,,,32,1,4.000000e+000,1.312256e-003,0.000000e+000,0,,0,
1524217232.722,,0.000000e+000,5.499445e+001,3.925924e-006,0.000000e+000,3,8.930494e-001,0.000000e+000,,,,,,,,,,,,,,32,1,4.000000e+000,2.628326e-003,0.000000e+000,0,,0,
1524217270.772,,0.000000e+000,5.499642e+001,3.941111e-006,0.000000e+000,3,9.090801e-001,0.000000e+000,,,,,,,,,,,,,,32,1,4.000000e+000,3.940582e-003,0.000000e+000,0,,0,
1524217308.382,,0.000000e+000,5.499313e+001,3.948690e-006,0.000000e+000,3,8.897039e-001,0.000000e+000,,,,,,,,,,,,,,32,1,4.000000e+000,7.892609e-003,0.000000e+000,0,,0,
1524217346.262,,0.000000e+000,5.499905e+001,3.981893e-006,0.000000e+000,3,9.119219e-001,0.000000e+000,,,,,,,,,,,,,,32,1,4.000000e+000,3.948212e-003,0.000000e+000,0,,0,
1524217384.022,,0.000000e+000,5.499577e+001,4.029833e-006,0.000000e+000,3,8.985192e-001,0.000000e+000,,,,,,,,,,,,,,32,1,4.000000e+000,2.632141e-003,0.000000e+000,0,,0,
1524217421.942,,0.000000e+000,5.499971e+001,3.994513e-006,0.000000e+000,3,8.944941e-001,0.000000e+000,,,,,,,,,,,,,,32,1,4.000000e+000,0.000000e+000,0.000000e+000,0,,0,
1524217459.952,,0.000000e+000,5.499774e+001,3.981566e-006,0.000000e+000,3,9.318526e-001,0.000000e+000,,,,,,,,,,,,,,32,1,4.000000e+000,3.940582e-003,0.000000e+000,0,,0,
1524217497.392,,0.000000e+000,5.500103e+001,4.044984e-006,0.000000e+000,3,8.939055e-001,0.000000e+000,,,,,,,,,,,,,,32,1,4.000000e+000,2.639771e-003,0.000000e+000,0,,0,
1524217535.172,,0.000000e+000,5.499577e+001,3.904853e-006,0.000000e+000,3,9.091909e-001,0.000000e+000,,,,,,,,,,,,,,32,1,4.000000e+000,1.316071e-002,0.000000e+000,0,,0,
1524217573.072,,0.000000e+000,5.499971e+001,4.093334e-006,0.000000e+000,3,8.870953e-001,0.000000e+000,,,,,,,,,,,,,,32,1,4.000000e+000,2.639771e-003,0.000000e+000,0,,0,
1524217610.822,,0.000000e+000,5.499445e+001,4.038453e-006,0.000000e+000,3,9.057956e-001,0.000000e+000,,,,,,,,,,,,,,32,1,4.000000e+000,0.000000e+000,0.000000e+000,0,,0,
1524217648.562,,0.000000e+000,5.500234e+001,3.940702e-006,0.000000e+000,3,9.082977e-001,0.000000e+000,,,,,,,,,,,,,,32,1,4.000000e+000,5.260468e-003,0.000000e+000,0,,0,
1524217686.302,,0.000000e+000,5.499248e+001,4.062723e-006,0.000000e+000,3,8.957474e-001,0.000000e+000,,,,,,,,,,,,,,32,1,4.000000e+000,3.940582e-003,0.000000e+000,0,,0,
1524217724.233,,0.000000e+000,5.500103e+001,3.960783e-006,0.000000e+000,3,9.100189e-001,0.000000e+000,,,,,,,,,,,,,,32,1,4.000000e+000,7.888794e-003,0.000000e+000,0,,0,
1524217762.323,,0.000000e+000,5.499774e+001,3.934887e-006,0.000000e+000,3,9.063946e-001,0.000000e+000,,,,,,,,,,,,,,32,1,4.000000e+000,6.580353e-003,0.000000e+000,0,,0,
1524217799.853,,0.000000e+000,5.499709e+001,4.063813e-006,0.000000e+000,3,9.092008e-001,0.000000e+000,,,,,,,,,,,,,,32,1,4.000000e+000,1.316071e-002,0.000000e+000,0,,0,
1524217837.373,,0.000000e+000,5.499774e+001,3.968970e-006,0.000000e+000,3,9.077826e-001,0.000000e+000,,,,,,,,,,,,,,32,1,4.000000e+000,3.940582e-003,0.000000e+000,0,,0,
1524217875.483,,0.000000e+000,5.500103e+001,4.056975e-006,0.000000e+000,3,8.925299e-001,0.000000e+000,,,,,,,,,,,,,,32,1,4.000000e+000,2.639771e-003,0.000000e+000,0,,0,
1524217913.413,,0.000000e+000,5.499774e+001,3.991290e-006,0.000000e+000,3,9.103301e-001,0.000000e+000,,,,,,,,,,,,,,32,1,4.000000e+000,6.580353e-003,0.000000e+000,0,,0,
1524217951.123,,0.000000e+000,5.500037e+001,4.087009e-006,0.000000e+000,3,9.004633e-001,0.000000e+000,,,,,,,,,,,,,,32,1,4.000000e+000,3.959656e-003,0.000000e+000,0,,0,
1524217989.033,,0.000000e+000,5.499906e+001,4.053943e-006,0.000000e+000,3,9.188285e-001,0.000000e+000,,,,,,,,,,,,,,32,1,4.000000e+000,6.580353e-003,0.000000e+000,0,,0,
1524218026.663,,0.000000e+000,5.499840e+001,4.074655e-006,0.000000e+000,3,9.011925e-001,0.000000e+000,,,,,,,,,,,,,,32,1,4.000000e+000,2.628326e-003,0.000000e+000,0,,0,
1524218064.683,,0.000000e+000,5.499840e+001,3.974630e-006,0.000000e+000,3,9.265141e-001,0.000000e+000,,,,,,,,,,,,,,32,1,4.000000e+000,1.314926e-002,0.000000e+000,0,,0,
1524218102.463,,0.000000e+000,5.499708e+001,4.018289e-006,0.000000e+000,3,9.084555e-001,0.000000e+000,,,,,,,,,,,,,,32,1,4.000000e+000,2.620697e-003,0.000000e+000,0,,0,
1524218140.553,,0.000000e+000,5.499708e+001,4.071088e-006,0.000000e+000,3,9.013821e-001,0.000000e+000,,,,,,,,,,,,,,32,1,4.000000e+000,0.000000e+000,0.000000e+000,0,,0,
1524218178.613,,0.000000e+000,5.500037e+001,4.014848e-006,0.000000e+000,3,9.078207e-001,0.000000e+000,,,,,,,,,,,,,,32,1,4.000000e+000,3.959656e-003,0.000000e+000,0,,0,
1524218215.723,,0.000000e+000,5.499379e+001,4.085455e-006,0.000000e+000,3,9.004963e-001,0.000000e+000,,,,,,,,,,,,,,32,1,4.000000e+000,9.201050e-003,0.000000e+000,0,,0,
1524218253.443,,0.000000e+000,5.499380e+001,3.989308e-006,0.000000e+000,3,9.056883e-001,0.000000e+000,,,,,,,,,,,,,,32,1,4.000000e+000,1.308441e-003,0.000000e+000,0,,0,
1524218291.313,,0.000000e+000,5.500168e+001,3.949052e-006,0.000000e+000,3,8.982432e-001,0.000000e+000,,,,,,,,,,,,,,32,1,4.000000e+000,6.580353e-003,0.000000e+000,0,,0,
1524218329.043,,0.000000e+000,5.500169e+001,3.956794e-006,0.000000e+000,3,9.070185e-001,0.000000e+000,,,,,,,,,,,,,,32,1,4.000000e+000,1.319885e-003,0.000000e+000,0,,0,
1524218366.383,,0.000000e+000,5.499248e+001,4.019027e-006,0.000000e+000,3,9.097612e-001,0.000000e+000,,,,,,,,,,,,,,32,1,4.000000e+000,1.319885e-003,0.000000e+000,0,,0,
1524218404.164,,0.000000e+000,5.500037e+001,3.966798e-006,0.000000e+000,3,9.070583e-001,0.000000e+000,,,,,,,,,,,,,,32,1,4.000000e+000,9.201050e-003,0.000000e+000,0,,0,
1524218442.094,,0.000000e+000,5.499773e+001,4.035875e-006,0.000000e+000,3,9.048320e-001,0.000000e+000,,,,,,,,,,,,,,32,1,4.000000e+000,1.308441e-003,0.000000e+000,0,,0,
1524218479.824,,0.000000e+000,5.499511e+001,4.029502e-006,0.000000e+000,3,9.103683e-001,0.000000e+000,,,,,,,,,,,,,,32,1,4.000000e+000,3.940582e-003,0.000000e+000,0,,0,
1524218517.894,,0.000000e+000,5.499380e+001,3.945897e-006,0.000000e+000,3,8.996961e-001,0.000000e+000,,,,,,,,,,,,,,32,1,4.000000e+000,1.446915e-002,0.000000e+000,0,,0,
1524218555.734,,0.000000e+000,5.499577e+001,3.993034e-006,0.000000e+000,3,9.057953e-001,0.000000e+000,,,,,,,,,,,,,,32,1,4.000000e+000,0.000000e+000,0.000000e+000,0,,0,
1524218594.094,,0.000000e+000,5.499643e+001,3.960331e-006,0.000000e+000,3,9.073033e-001,0.000000e+000,,,,,,,,,,,,,,32,1,4.000000e+000,1.312256e-003,0.000000e+000,0,,0,
1524218632.634,,0.000000e+000,5.499840e+001,3.922005e-006,0.000000e+000,3,9.106146e-001,0.000000e+000,,,,,,,,,,,,,,32,1,4.000000e+000,5.260468e-003,0.000000e+000,0,,0,
1524218670.404,,0.000000e+000,5.499775e+001,3.965717e-006,0.000000e+000,3,8.974720e-001,0.000000e+000,,,,,,,,,,,,,,32,1,4.000000e+000,9.208679e-003,0.000000e+000,0,,0,
1524218708.444,,0.000000e+000,5.499708e+001,3.987810e-006,0.000000e+000,3,9.109574e-001,0.000000e+000,,,,,,,,,,,,,,32,1,4.000000e+000,5.260468e-003,0.000000e+000,0,,0,
1524218745.634,,0.000000e+000,5.499445e+001,3.994238e-006,0.000000e+000,3,9.063681e-001,0.000000e+000,,,,,,,,,,,,,,32,1,4.000000e+000,0.000000e+000,0.000000e+000,0,,0,
1524218782.584,,0.000000e+000,5.500103e+001,3.976136e-006,0.000000e+000,3,9.026703e-001,0.000000e+000,,,,,,,,,,,,,,32,1,4.000000e+000,5.279541e-003,0.000000e+000,0,,0,
1524218821.444,,0.000000e+000,5.499840e+001,3.956552e-006,0.000000e+000,3,9.116545e-001,0.000000e+000,,,,,,,,,,,,,,32,1,4.000000e+000,1.314926e-002,0.000000e+000,0,,0,
1524218859.174,,0.000000e+000,5.499971e+001,3.978887e-006,0.000000e+000,3,9.053182e-001,0.000000e+000,,,,,,,,,,,,,,32,1,4.000000e+000,2.639771e-003,0.000000e+000,0,,0,
1524218897.284,,0.000000e+000,5.499511e+001,4.038388e-006,0.000000e+000,3,8.953670e-001,0.000000e+000,,,,,,,,,,,,,,32,1,4.000000e+000,3.940582e-003,0.000000e+000,0,,0,
1524218935.034,,0.000000e+000,5.500037e+001,4.011037e-006,0.000000e+000,3,9.099780e-001,0.000000e+000,,,,,,,,,,,,,,32,1,4.000000e+000,3.959656e-003,0.000000e+000,0,,0,
1524218972.344,,0.000000e+000,5.499840e+001,4.054185e-006,0.000000e+000,3,8.994067e-001,0.000000e+000,,,,,,,,,,,,,,32,1,4.000000e+000,5.260468e-003,0.000000e+000,0,,0,
1524219010.304,,0.000000e+000,5.500366e+001,3.996929e-006,0.000000e+000,3,9.063346e-001,0.000000e+000,,,,,,,,,,,,,,32,1,4.000000e+000,2.620697e-003,0.000000e+000,0,,0,
1524219047.904,,0.000000e+000,5.500169e+001,4.080061e-006,0.000000e+000,3,9.046569e-001,0.000000e+000,,,,,,,,,,,,,,32,1,4.000000e+000,3.959656e-003,0.000000e+000,0,,0,
1524219085.884,,0.000000e+000,5.499906e+001,4.026461e-006,0.000000e+000,3,9.157102e-001,0.000000e+000,,,,,,,,,,,,,,32,1,4.000000e+000,6.580353e-003,0.000000e+000,0,,0,
1524219123.465,,0.000000e+000,5.499445e+001,4.042390e-006,0.000000e+000,3,9.032724e-001,0.000000e+000,,,,,,,,,,,,,,32,1,4.000000e+000,0.000000e+000,0.000000e+000,0,,0,
1524219161.545,,0.000000e+000,5.499182e+001,3.999409e-006,0.000000e+000,3,9.162709e-001,0.000000e+000,,,,,,,,,,,,,,32,1,4.000000e+000,5.260468e-003,0.000000e+000,0,,0,
1524219200.015,,0.000000e+000,5.500367e+001,4.073939e-006,0.000000e+000,3,9.251799e-001,0.000000e+000,,,,,,,,,,,,,,32,1,4.000000e+000,0.000000e+000,0.000000e+000,0,,0,
1524219237.135,,0.000000e+000,5.500103e+001,4.072566e-006,0.000000e+000,3,8.971960e-001,0.000000e+000,,,,,,,,,,,,,,32,1,4.000000e+000,1.052094e-002,0.000000e+000,0,,0,
1524219274.915,,0.000000e+000,5.500497e+001,4.041092e-006,0.000000e+000,3,9.246395e-001,0.000000e+000,,,,,,,,,,,,,,32,1,4.000000e+000,7.888794e-003,0.000000e+000,0,,0,
1524219312.545,,0.000000e+000,5.500629e+001,4.124954e-006,0.000000e+000,3,9.003444e-001,0.000000e+000,,,,,,,,,,,,,,32,1,4.000000e+000,0.000000e+000,0.000000e+000,0,,0,
1524219350.145,,0.000000e+000,5.499774e+001,4.063098e-006,0.000000e+000,3,9.267753e-001,0.000000e+000,,,,,,,,,,,,,,32,1,4.000000e+000,3.940582e-003,0.000000e+000,0,,0,
1524219388.055,,0.000000e+000,5.499577e+001,3.974199e-006,0.000000e+000,3,9.198829e-001,0.000000e+000,,,,,,,,,,,,,,32,1,4.000000e+000,1.316071e-002,0.000000e+000,0,,0,
1524219425.955,,0.000000e+000,5.499972e+001,4.067002e-006,0.000000e+000,3,9.025027e-001,0.000000e+000,,,,,,,,,,,,,,32,1,4.000000e+000,5.268097e-003,0.000000e+000,0,,0,
1524219463.695,,0.000000e+000,5.500300e+001,4.054526e-006,0.000000e+000,3,9.187120e-001,0.000000e+000,,,,,,,,,,,,,,32,1,4.000000e+000,6.580353e-003,0.000000e+000,0,,0,
1524219501.025,,0.000000e+000,5.499905e+001,4.027849e-006,0.000000e+000,3,8.986998e-001,0.000000e+000,,,,,,,,,,,,,,32,1,4.000000e+000,1.319885e-003,0.000000e+000,0,,0,
1524219538.955,,0.000000e+000,5.499774e+001,4.050970e-006,0.000000e+000,3,9.152488e-001,0.000000e+000,,,,,,,,,,,,,,32,1,4.000000e+000,3.940582e-003,0.000000e+000,0,,0,
1524219576.065,,0.000000e+000,5.499708e+001,4.053001e-006,0.000000e+000,3,9.005818e-001,0.000000e+000,,,,,,,,,,,,,,32,1,4.000000e+000,0.000000e+000,0.000000e+000,0,,0,
1524219613.435,,0.000000e+000,5.499708e+001,4.071498e-006,0.000000e+000,3,9.149860e-001,0.000000e+000,,,,,,,,,,,,,,32,1,4.000000e+000,2.620697e-003,0.000000e+000,0,,0,