File: Experimental Raw Data/TC04-12-01K VRMac VRMde/Iterative Regression/TC04-12-01K_VRMac_57K_12000s.dc.dat
[Header]
TITLE,MPMS DC Measurement
BYAPP,MPMS Measurement,2.1,Summary
FILEOPENTIME, 1524145026.515000 4/19/2018, 7:37:06 AM

INFO, APPNAME, MPMS MultiVu Application, Revision 1.61,  Build 082

INFO, NAME, TC04-12-01K
INFO, WEIGHT, 1.000
INFO, AREA, 1.000
INFO, LENGTH, 1.000
INFO, SHAPE, 0
INFO, COMMENT,
INFO, SEQUENCE FILE: VRMac_57K_12000s_VRMde_55K.seq


INFO, BACKGROUND DATA FILE:, None


STARTUPAXIS,X,4,LINEAR,AUTO,0.000000,0.000000
STARTUPAXIS,Y1,5,LINEAR,AUTO,0.000000,0.000000


STARTUPGROUP,Longitudinal
FIELDGROUP,Longitudinal,1,2,3,4,5,6,7,8,9,15,16,17,18,27,28
FIELDGROUP,Transverse,1,2,3,4,10,11,12,13,14,19,20,21,22,27,28

PLOT_APPEARANCE,ALL,HORZ_GRID_ON,VERT_GRID_ON,MARKERS_AND_LINES

[Data]
Time,Comment,Field (Oe),Temperature (K),Long Moment (emu),Long Scan Std Dev,Long Algorithm,Long Reg Fit,Long Percent Error (%),Trans Moment (emu),Trans Scan Std Dev,Trans Algorithm,Trans Reg Fit,Trans Percent Error (%),Long Moment [w/o ABS] (emu),Long Scan Std Dev [w/o ABS],Long Reg Fit [w/o ABS],Long Percent Error [w/o ABS] (%),Trans Moment [w/o ABS] (emu),Trans Scan Std Dev [w/o ABS],Trans Reg Fit [w/o ABS],Trans Percent Error [w/o ABS] (%),Points per Scan,Scans per Measurement,Scan Length (cm),Delta Temp (K),Rot Position (deg),Error,EC Comp. Running,Using ABS,
1524145026.515,,0.000000e+000,5.708520e+001,-5.568166e-005,0.000000e+000,3,9.750847e-001,0.000000e+000,,,,,,,,,,,,,,32,1,4.000000e+000,1.546097e-002,0.000000e+000,0,,0,
1524145064.825,,0.000000e+000,5.704095e+001,-6.085266e-005,0.000000e+000,3,9.716746e-001,0.000000e+000,,,,,,,,,,,,,,32,1,4.000000e+000,2.811432e-003,0.000000e+000,0,,0,
1524145128.545,,0.000000e+000,5.700446e+001,-6.413558e-005,0.000000e+000,3,9.735725e-001,0.000000e+000,,,,,,,,,,,,,,32,1,4.000000e+000,2.811432e-003,0.000000e+000,0,,0,
1524145190.695,,0.000000e+000,5.700097e+001,-6.588375e-005,0.000000e+000,3,9.722765e-001,0.000000e+000,,,,,,,,,,,,,,32,1,4.000000e+000,1.411438e-003,0.000000e+000,0,,0,
1524145227.535,,0.000000e+000,5.699676e+001,-6.664961e-005,0.000000e+000,3,9.733022e-001,0.000000e+000,,,,,,,,,,,,,,32,1,4.000000e+000,1.399994e-003,0.000000e+000,0,,0,
1524145264.765,,0.000000e+000,5.700307e+001,-6.727413e-005,0.000000e+000,3,9.729808e-001,0.000000e+000,,,,,,,,,,,,,,32,1,4.000000e+000,1.121902e-002,0.000000e+000,0,,0,
1524145302.355,,0.000000e+000,5.699045e+001,-6.781574e-005,0.000000e+000,3,9.730991e-001,0.000000e+000,,,,,,,,,,,,,,32,1,4.000000e+000,0.000000e+000,0.000000e+000,0,,0,
1524145339.885,,0.000000e+000,5.699746e+001,-6.837468e-005,0.000000e+000,3,9.734792e-001,0.000000e+000,,,,,,,,,,,,,,32,1,4.000000e+000,2.799988e-003,0.000000e+000,0,,0,
1524145377.325,,0.000000e+000,5.699185e+001,-6.878648e-005,0.000000e+000,3,9.740291e-001,0.000000e+000,,,,,,,,,,,,,,32,1,4.000000e+000,2.799988e-003,0.000000e+000,0,,0,
1524145414.515,,0.000000e+000,5.699886e+001,-6.911356e-005,0.000000e+000,3,9.719219e-001,0.000000e+000,,,,,,,,,,,,,,32,1,4.000000e+000,5.611420e-003,0.000000e+000,0,,0,
1524145452.905,,0.000000e+000,5.699255e+001,-6.945424e-005,0.000000e+000,3,9.736396e-001,0.000000e+000,,,,,,,,,,,,,,32,1,4.000000e+000,1.392365e-003,0.000000e+000,0,,0,
1524145491.225,,0.000000e+000,5.699816e+001,-6.983952e-005,0.000000e+000,3,9.733357e-001,0.000000e+000,,,,,,,,,,,,,,32,1,4.000000e+000,1.399994e-003,0.000000e+000,0,,0,
1524145528.815,,0.000000e+000,5.699535e+001,-7.014782e-005,0.000000e+000,3,9.727082e-001,0.000000e+000,,,,,,,,,,,,,,32,1,4.000000e+000,1.407623e-003,0.000000e+000,0,,0,
1524145566.306,,0.000000e+000,5.699535e+001,-7.042383e-005,0.000000e+000,3,9.735159e-001,0.000000e+000,,,,,,,,,,,,,,32,1,4.000000e+000,1.407623e-003,0.000000e+000,0,,0,
1524145604.116,,0.000000e+000,5.699535e+001,-7.059143e-005,0.000000e+000,3,9.732593e-001,0.000000e+000,,,,,,,,,,,,,,32,1,4.000000e+000,4.207611e-003,0.000000e+000,0,,0,
1524145641.516,,0.000000e+000,5.699606e+001,-7.092353e-005,0.000000e+000,3,9.731135e-001,0.000000e+000,,,,,,,,,,,,,,32,1,4.000000e+000,2.807617e-003,0.000000e+000,0,,0,
1524145678.746,,0.000000e+000,5.699816e+001,-7.118965e-005,0.000000e+000,3,9.744073e-001,0.000000e+000,,,,,,,,,,,,,,32,1,4.000000e+000,1.399994e-003,0.000000e+000,0,,0,
1524145716.226,,0.000000e+000,5.699116e+001,-7.131694e-005,0.000000e+000,3,9.741845e-001,0.000000e+000,,,,,,,,,,,,,,32,1,4.000000e+000,1.407623e-003,0.000000e+000,0,,0,
1524145754.116,,0.000000e+000,5.699535e+001,-7.158822e-005,0.000000e+000,3,9.740838e-001,0.000000e+000,,,,,,,,,,,,,,32,1,4.000000e+000,4.207611e-003,0.000000e+000,0,,0,
1524145791.616,,0.000000e+000,5.699536e+001,-7.175410e-005,0.000000e+000,3,9.733033e-001,0.000000e+000,,,,,,,,,,,,,,32,1,4.000000e+000,6.999969e-003,0.000000e+000,0,,0,
1524145829.166,,0.000000e+000,5.699535e+001,-7.191260e-005,0.000000e+000,3,9.720317e-001,0.000000e+000,,,,,,,,,,,,,,32,1,4.000000e+000,1.407623e-003,0.000000e+000,0,,0,
1524145867.526,,0.000000e+000,5.699746e+001,-7.206549e-005,0.000000e+000,3,9.727195e-001,0.000000e+000,,,,,,,,,,,,,,32,1,4.000000e+000,0.000000e+000,0.000000e+000,0,,0,
1524145905.516,,0.000000e+000,5.699255e+001,-7.226461e-005,0.000000e+000,3,9.736171e-001,0.000000e+000,,,,,,,,,,,,,,32,1,4.000000e+000,7.019043e-003,0.000000e+000,0,,0,
1524145943.496,,0.000000e+000,5.699606e+001,-7.237877e-005,0.000000e+000,3,9.723529e-001,0.000000e+000,,,,,,,,,,,,,,32,1,4.000000e+000,8.399963e-003,0.000000e+000,0,,0,
1524145981.306,,0.000000e+000,5.700377e+001,-7.255596e-005,0.000000e+000,3,9.733475e-001,0.000000e+000,,,,,,,,,,,,,,32,1,4.000000e+000,4.199982e-003,0.000000e+000,0,,0,
1524146043.896,,0.000000e+000,5.699956e+001,-7.278722e-005,0.000000e+000,3,9.744859e-001,0.000000e+000,,,,,,,,,,,,,,32,1,4.000000e+000,6.999969e-003,0.000000e+000,0,,0,
1524146081.726,,0.000000e+000,5.699255e+001,-7.293125e-005,0.000000e+000,3,9.732721e-001,0.000000e+000,,,,,,,,,,,,,,32,1,4.000000e+000,9.807587e-003,0.000000e+000,0,,0,
1524146118.872,,0.000000e+000,5.699886e+001,-7.307037e-005,0.000000e+000,3,9.743341e-001,0.000000e+000,,,,,,,,,,,,,,32,1,4.000000e+000,0.000000e+000,0.000000e+000,0,,0,
1524146157.072,,0.000000e+000,5.699325e+001,-7.315690e-005,0.000000e+000,3,9.731529e-001,0.000000e+000,,,,,,,,,,,,,,32,1,4.000000e+000,1.401901e-002,0.000000e+000,0,,0,
1524146194.134,,0.000000e+000,5.699184e+001,-7.334457e-005,0.000000e+000,3,9.723642e-001,0.000000e+000,,,,,,,,,,,,,,32,1,4.000000e+000,5.611420e-003,0.000000e+000,0,,0,
1524146232.344,,0.000000e+000,5.699956e+001,-7.351510e-005,0.000000e+000,3,9.742573e-001,0.000000e+000,,,,,,,,,,,,,,32,1,4.000000e+000,9.819031e-003,0.000000e+000,0,,0,
1524146269.844,,0.000000e+000,5.699746e+001,-7.352018e-005,0.000000e+000,3,9.728467e-001,0.000000e+000,,,,,,,,,,,,,,32,1,4.000000e+000,8.419037e-003,0.000000e+000,0,,0,
1524146307.725,,0.000000e+000,5.699535e+001,-7.367614e-005,0.000000e+000,3,9.733200e-001,0.000000e+000,,,,,,,,,,,,,,32,1,4.000000e+000,1.407623e-003,0.000000e+000,0,,0,
1524146345.175,,0.000000e+000,5.699606e+001,-7.385336e-005,0.000000e+000,3,9.746442e-001,0.000000e+000,,,,,,,,,,,,,,32,1,4.000000e+000,0.000000e+000,0.000000e+000,0,,0,
1524146382.215,,0.000000e+000,5.700237e+001,-7.388352e-005,0.000000e+000,3,9.734992e-001,0.000000e+000,,,,,,,,,,,,,,32,1,4.000000e+000,1.388550e-003,0.000000e+000,0,,0,
1524146420.645,,0.000000e+000,5.699676e+001,-7.397661e-005,0.000000e+000,3,9.740949e-001,0.000000e+000,,,,,,,,,,,,,,32,1,4.000000e+000,1.399994e-003,0.000000e+000,0,,0,
1524146458.455,,0.000000e+000,5.699886e+001,-7.409739e-005,0.000000e+000,3,9.739039e-001,0.000000e+000,,,,,,,,,,,,,,32,1,4.000000e+000,1.682663e-002,0.000000e+000,0,,0,
1524146495.905,,0.000000e+000,5.700166e+001,-7.419804e-005,0.000000e+000,3,9.737930e-001,0.000000e+000,,,,,,,,,,,,,,32,1,4.000000e+000,8.411407e-003,0.000000e+000,0,,0,
1524146533.785,,0.000000e+000,5.699956e+001,-7.431257e-005,0.000000e+000,3,9.731867e-001,0.000000e+000,,,,,,,,,,,,,,32,1,4.000000e+000,1.399994e-003,0.000000e+000,0,,0,
1524146572.155,,0.000000e+000,5.699535e+001,-7.444980e-005,0.000000e+000,3,9.735187e-001,0.000000e+000,,,,,,,,,,,,,,32,1,4.000000e+000,4.207611e-003,0.000000e+000,0,,0,
1524146610.485,,0.000000e+000,5.699886e+001,-7.448083e-005,0.000000e+000,3,9.732985e-001,0.000000e+000,,,,,,,,,,,,,,32,1,4.000000e+000,2.799988e-003,0.000000e+000,0,,0,
1524146648.125,,0.000000e+000,5.699535e+001,-7.453447e-005,0.000000e+000,3,9.739438e-001,0.000000e+000,,,,,,,,,,,,,,32,1,4.000000e+000,4.207611e-003,0.000000e+000,0,,0,
1524146685.785,,0.000000e+000,5.699676e+001,-7.469431e-005,0.000000e+000,3,9.732077e-001,0.000000e+000,,,,,,,,,,,,,,32,1,4.000000e+000,7.007599e-003,0.000000e+000,0,,0,
1524146723.855,,0.000000e+000,5.699466e+001,-7.472448e-005,0.000000e+000,3,9.731488e-001,0.000000e+000,,,,,,,,,,,,,,32,1,4.000000e+000,8.407593e-003,0.000000e+000,0,,0,
1524146761.265,,0.000000e+000,5.700026e+001,-7.482304e-005,0.000000e+000,3,9.752630e-001,0.000000e+000,,,,,,,,,,,,,,32,1,4.000000e+000,2.243805e-002,0.000000e+000,0,,0,
1524146799.565,,0.000000e+000,5.699746e+001,-7.489262e-005,0.000000e+000,3,9.737135e-001,0.000000e+000,,,,,,,,,,,,,,32,1,4.000000e+000,2.799988e-003,0.000000e+000,0,,0,
1524146836.985,,0.000000e+000,5.698975e+001,-7.504681e-005,0.000000e+000,3,9.736461e-001,0.000000e+000,,,,,,,,,,,,,,32,1,4.000000e+000,7.011414e-003,0.000000e+000,0,,0,
1524146875.465,,0.000000e+000,5.699395e+001,-7.494035e-005,0.000000e+000,3,9.731687e-001,0.000000e+000,,,,,,,,,,,,,,32,1,4.000000e+000,1.399994e-003,0.000000e+000,0,,0,
1524146913.265,,0.000000e+000,5.700026e+001,-7.513816e-005,0.000000e+000,3,9.740342e-001,0.000000e+000,,,,,,,,,,,,,,32,1,4.000000e+000,0.000000e+000,0.000000e+000,0,,0,
1524146951.195,,0.000000e+000,5.699886e+001,-7.521192e-005,0.000000e+000,3,9.732600e-001,0.000000e+000,,,,,,,,,,,,,,32,1,4.000000e+000,0.000000e+000,0.000000e+000,0,,0,
1524146988.946,,0.000000e+000,5.699535e+001,-7.535095e-005,0.000000e+000,3,9.750893e-001,0.000000e+000,,,,,,,,,,,,,,32,1,4.000000e+000,4.207611e-003,0.000000e+000,0,,0,
1524147026.766,,0.000000e+000,5.699886e+001,-7.544174e-005,0.000000e+000,3,9.741560e-001,0.000000e+000,,,,,,,,,,,,,,32,1,4.000000e+000,1.121902e-002,0.000000e+000,0,,0,
1524147064.116,,0.000000e+000,5.699606e+001,-7.548174e-005,0.000000e+000,3,9.749370e-001,0.000000e+000,,,,,,,,,,,,,,32,1,4.000000e+000,2.807617e-003,0.000000e+000,0,,0,
1524147102.186,,0.000000e+000,5.700166e+001,-7.556773e-005,0.000000e+000,3,9.755458e-001,0.000000e+000,,,,,,,,,,,,,,32,1,4.000000e+000,2.799988e-003,0.000000e+000,0,,0,
1524147140.226,,0.000000e+000,5.699535e+001,-7.561545e-005,0.000000e+000,3,9.734212e-001,0.000000e+000,,,,,,,,,,,,,,32,1,4.000000e+000,1.263046e-002,0.000000e+000,0,,0,
1524147178.096,,0.000000e+000,5.699535e+001,-7.570010e-005,0.000000e+000,3,9.743096e-001,0.000000e+000,,,,,,,,,,,,,,32,1,4.000000e+000,4.207611e-003,0.000000e+000,0,,0,
1524147215.786,,0.000000e+000,5.699746e+001,-7.569988e-005,0.000000e+000,3,9.732209e-001,0.000000e+000,,,,,,,,,,,,,,32,1,4.000000e+000,1.683044e-002,0.000000e+000,0,,0,
1524147254.826,,0.000000e+000,5.699535e+001,-7.575894e-005,0.000000e+000,3,9.740928e-001,0.000000e+000,,,,,,,,,,,,,,32,1,4.000000e+000,1.407623e-003,0.000000e+000,0,,0,
1524147292.216,,0.000000e+000,5.699676e+001,-7.584035e-005,0.000000e+000,3,9.730514e-001,0.000000e+000,,,,,,,,,,,,,,32,1,4.000000e+000,1.399994e-003,0.000000e+000,0,,0,
1524147329.816,,0.000000e+000,5.699746e+001,-7.593427e-005,0.000000e+000,3,9.747204e-001,0.000000e+000,,,,,,,,,,,,,,32,1,4.000000e+000,5.607605e-003,0.000000e+000,0,,0,
1524147368.806,,0.000000e+000,5.699815e+001,-7.605751e-005,0.000000e+000,3,9.748199e-001,0.000000e+000,,,,,,,,,,,,,,32,1,4.000000e+000,9.807587e-003,0.000000e+000,0,,0,
1524147406.376,,0.000000e+000,5.700027e+001,-7.611027e-005,0.000000e+000,3,9.734392e-001,0.000000e+000,,,,,,,,,,,,,,32,1,4.000000e+000,2.811432e-003,0.000000e+000,0,,0,
1524147443.976,,0.000000e+000,5.699816e+001,-7.604402e-005,0.000000e+000,3,9.733968e-001,0.000000e+000,,,,,,,,,,,,,,32,1,4.000000e+000,1.399994e-003,0.000000e+000,0,,0,
1524147481.306,,0.000000e+000,5.699676e+001,-7.618166e-005,0.000000e+000,3,9.747490e-001,0.000000e+000,,,,,,,,,,,,,,32,1,4.000000e+000,1.399994e-003,0.000000e+000,0,,0,
1524147518.976,,0.000000e+000,5.699606e+001,-7.623959e-005,0.000000e+000,3,9.734540e-001,0.000000e+000,,,,,,,,,,,,,,32,1,4.000000e+000,2.807617e-003,0.000000e+000,0,,0,
1524147557.736,,0.000000e+000,5.699466e+001,-7.628169e-005,0.000000e+000,3,9.737909e-001,0.000000e+000,,,,,,,,,,,,,,32,1,4.000000e+000,2.807617e-003,0.000000e+000,0,,0,
1524147595.026,,0.000000e+000,5.699886e+001,-7.636291e-005,0.000000e+000,3,9.748615e-001,0.000000e+000,,,,,,,,,,,,,,32,1,4.000000e+000,2.799988e-003,0.000000e+000,0,,0,
1524147632.446,,0.000000e+000,5.699746e+001,-7.633572e-005,0.000000e+000,3,9.744617e-001,0.000000e+000,,,,,,,,,,,,,,32,1,4.000000e+000,8.419037e-003,0.000000e+000,0,,0,
1524147670.046,,0.000000e+000,5.699466e+001,-7.640952e-005,0.000000e+000,3,9.738165e-001,0.000000e+000,,,,,,,,,,,,,,32,1,4.000000e+000,8.407593e-003,0.000000e+000,0,,0,
1524147707.397,,0.000000e+000,5.699746e+001,-7.656851e-005,0.000000e+000,3,9.744750e-001,0.000000e+000,,,,,,,,,,,,,,32,1,4.000000e+000,5.607605e-003,0.000000e+000,0,,0,
1524147745.367,,0.000000e+000,5.699816e+001,-7.649304e-005,0.000000e+000,3,9.748554e-001,0.000000e+000,,,,,,,,,,,,,,32,1,4.000000e+000,4.199982e-003,0.000000e+000,0,,0,
1524147782.947,,0.000000e+000,5.699677e+001,-7.669596e-005,0.000000e+000,3,9.743224e-001,0.000000e+000,,,,,,,,,,,,,,32,1,4.000000e+000,9.811401e-003,0.000000e+000,0,,0,
1524147820.257,,0.000000e+000,5.699956e+001,-7.662215e-005,0.000000e+000,3,9.739386e-001,0.000000e+000,,,,,,,,,,,,,,32,1,4.000000e+000,1.399994e-003,0.000000e+000,0,,0,
1524147858.047,,0.000000e+000,5.699186e+001,-7.671468e-005,0.000000e+000,3,9.742399e-001,0.000000e+000,,,,,,,,,,,,,,32,1,4.000000e+000,8.407593e-003,0.000000e+000,0,,0,
1524147895.667,,0.000000e+000,5.699886e+001,-7.671430e-005,0.000000e+000,3,9.733309e-001,0.000000e+000,,,,,,,,,,,,,,32,1,4.000000e+000,5.611420e-003,0.000000e+000,0,,0,
1524147933.957,,0.000000e+000,5.699816e+001,-7.681957e-005,0.000000e+000,3,9.742455e-001,0.000000e+000,,,,,,,,,,,,,,32,1,4.000000e+000,1.399994e-003,0.000000e+000,0,,0,
1524147971.607,,0.000000e+000,5.699466e+001,-7.684649e-005,0.000000e+000,3,9.731427e-001,0.000000e+000,,,,,,,,,,,,,,32,1,4.000000e+000,8.407593e-003,0.000000e+000,0,,0,
1524148009.437,,0.000000e+000,5.700166e+001,-7.689519e-005,0.000000e+000,3,9.737571e-001,0.000000e+000,,,,,,,,,,,,,,32,1,4.000000e+000,8.411407e-003,0.000000e+000,0,,0,
1524148046.677,,0.000000e+000,5.699676e+001,-7.706117e-005,0.000000e+000,3,9.753304e-001,0.000000e+000,,,,,,,,,,,,,,32,1,4.000000e+000,1.399994e-003,0.000000e+000,0,,0,
1524148084.177,,0.000000e+000,5.699816e+001,-7.699360e-005,0.000000e+000,3,9.746597e-001,0.000000e+000,,,,,,,,,,,,,,32,1,4.000000e+000,4.199982e-003,0.000000e+000,0,,0,
1524148121.947,,0.000000e+000,5.700377e+001,-7.705851e-005,0.000000e+000,3,9.741413e-001,0.000000e+000,,,,,,,,,,,,,,32,1,4.000000e+000,7.019043e-003,0.000000e+000,0,,0,
1524148159.637,,0.000000e+000,5.699606e+001,-7.709879e-005,0.000000e+000,3,9.741918e-001,0.000000e+000,,,,,,,,,,,,,,32,1,4.000000e+000,8.399963e-003,0.000000e+000,0,,0,
1524148197.247,,0.000000e+000,5.699396e+001,-7.720551e-005,0.000000e+000,3,9.746283e-001,0.000000e+000,,,,,,,,,,,,,,32,1,4.000000e+000,7.007599e-003,0.000000e+000,0,,0,
1524148234.737,,0.000000e+000,5.699465e+001,-7.718344e-005,0.000000e+000,3,9.734865e-001,0.000000e+000,,,,,,,,,,,,,,32,1,4.000000e+000,1.681900e-002,0.000000e+000,0,,0,
1524148272.897,,0.000000e+000,5.700096e+001,-7.720525e-005,0.000000e+000,3,9.743634e-001,0.000000e+000,,,,,,,,,,,,,,32,1,4.000000e+000,4.199982e-003,0.000000e+000,0,,0,
1524148311.157,,0.000000e+000,5.699606e+001,-7.724294e-005,0.000000e+000,3,9.735418e-001,0.000000e+000,,,,,,,,,,,,,,32,1,4.000000e+000,0.000000e+000,0.000000e+000,0,,0,
1524148349.337,,0.000000e+000,5.699606e+001,-7.734337e-005,0.000000e+000,3,9.743941e-001,0.000000e+000,,,,,,,,,,,,,,32,1,4.000000e+000,5.607605e-003,0.000000e+000,0,,0,
1524148386.567,,0.000000e+000,5.700377e+001,-7.741898e-005,0.000000e+000,3,9.734789e-001,0.000000e+000,,,,,,,,,,,,,,32,1,4.000000e+000,7.019043e-003,0.000000e+000,0,,0,
1524148424.478,,0.000000e+000,5.699957e+001,-7.747759e-005,0.000000e+000,3,9.742813e-001,0.000000e+000,,,,,,,,,,,,,,32,1,4.000000e+000,4.211426e-003,0.000000e+000,0,,0,
1524148462.508,,0.000000e+000,5.700096e+001,-7.741201e-005,0.000000e+000,3,9.736739e-001,0.000000e+000,,,,,,,,,,,,,,32,1,4.000000e+000,4.199982e-003,0.000000e+000,0,,0,
1524148500.628,,0.000000e+000,5.700027e+001,-7.748359e-005,0.000000e+000,3,9.734964e-001,0.000000e+000,,,,,,,,,,,,,,32,1,4.000000e+000,2.811432e-003,0.000000e+000,0,,0,
1524148538.948,,0.000000e+000,5.700026e+001,-7.754556e-005,0.000000e+000,3,9.748509e-001,0.000000e+000,,,,,,,,,,,,,,32,1,4.000000e+000,5.599976e-003,0.000000e+000,0,,0,
1524148576.778,,0.000000e+000,5.699535e+001,-7.757042e-005,0.000000e+000,3,9.742064e-001,0.000000e+000,,,,,,,,,,,,,,32,1,4.000000e+000,4.207611e-003,0.000000e+000,0,,0,
1524148614.348,,0.000000e+000,5.699886e+001,-7.763752e-005,0.000000e+000,3,9.746035e-001,0.000000e+000,,,,,,,,,,,,,,32,1,4.000000e+000,2.799988e-003,0.000000e+000,0,,0,
1524148651.988,,0.000000e+000,5.699535e+001,-7.772775e-005,0.000000e+000,3,9.742265e-001,0.000000e+000,,,,,,,,,,,,,,32,1,4.000000e+000,1.407623e-003,0.000000e+000,0,,0,
1524148689.828,,0.000000e+000,5.699886e+001,-7.775542e-005,0.000000e+000,3,9.743873e-001,0.000000e+000,,,,,,,,,,,,,,32,1,4.000000e+000,0.000000e+000,0.000000e+000,0,,0,
1524148727.738,,0.000000e+000,5.699886e+001,-7.776092e-005,0.000000e+000,3,9.745418e-001,0.000000e+000,,,,,,,,,,,,,,32,1,4.000000e+000,0.000000e+000,0.000000e+000,0,,0,
1524148765.278,,0.000000e+000,5.699396e+001,-7.783939e-005,0.000000e+000,3,9.752600e-001,0.000000e+000,,,,,,,,,,,,,,32,1,4.000000e+000,7.007599e-003,0.000000e+000,0,,0,
1524148803.078,,0.000000e+000,5.699326e+001,-7.778229e-005,0.000000e+000,3,9.730106e-001,0.000000e+000,,,,,,,,,,,,,,32,1,4.000000e+000,5.607605e-003,0.000000e+000,0,,0,
1524148840.828,,0.000000e+000,5.699676e+001,-7.793350e-005,0.000000e+000,3,9.743336e-001,0.000000e+000,,,,,,,,,,,,,,32,1,4.000000e+000,4.207611e-003,0.000000e+000,0,,0,
1524148879.598,,0.000000e+000,5.700377e+001,-7.789161e-005,0.000000e+000,3,9.746784e-001,0.000000e+000,,,,,,,,,,,,,,32,1,4.000000e+000,4.199982e-003,0.000000e+000,0,,0,
1524148916.828,,0.000000e+000,5.699676e+001,-7.797442e-005,0.000000e+000,3,9.740148e-001,0.000000e+000,,,,,,,,,,,,,,32,1,4.000000e+000,1.399994e-003,0.000000e+000,0,,0,
1524148954.978,,0.000000e+000,5.700027e+001,-7.804530e-005,0.000000e+000,3,9.743882e-001,0.000000e+000,,,,,,,,,,,,,,32,1,4.000000e+000,2.811432e-003,0.000000e+000,0,,0,
1524148993.398,,0.000000e+000,5.700517e+001,-7.799583e-005,0.000000e+000,3,9.735174e-001,0.000000e+000,,,,,,,,,,,,,,32,1,4.000000e+000,4.219055e-003,0.000000e+000,0,,0,
1524149030.768,,0.000000e+000,5.699606e+001,-7.815444e-005,0.000000e+000,3,9.739402e-001,0.000000e+000,,,,,,,,,,,,,,32,1,4.000000e+000,0.000000e+000,0.000000e+000,0,,0,
1524149068.868,,0.000000e+000,5.699746e+001,-7.808428e-005,0.000000e+000,3,9.743305e-001,0.000000e+000,,,,,,,,,,,,,,32,1,4.000000e+000,5.607605e-003,0.000000e+000,0,,0,
1524149106.428,,0.000000e+000,5.700166e+001,-7.808480e-005,0.000000e+000,3,9.738622e-001,0.000000e+000,,,,,,,,,,,,,,32,1,4.000000e+000,5.611420e-003,0.000000e+000,0,,0,
1524149144.579,,0.000000e+000,5.699535e+001,-7.817677e-005,0.000000e+000,3,9.737973e-001,0.000000e+000,,,,,,,,,,,,,,32,1,4.000000e+000,9.807587e-003,0.000000e+000,0,,0,
1524149182.579,,0.000000e+000,5.699466e+001,-7.824755e-005,0.000000e+000,3,9.735957e-001,0.000000e+000,,,,,,,,,,,,,,32,1,4.000000e+000,8.407593e-003,0.000000e+000,0,,0,
1524149219.949,,0.000000e+000,5.699886e+001,-7.825350e-005,0.000000e+000,3,9.746899e-001,0.000000e+000,,,,,,,,,,,,,,32,1,4.000000e+000,1.682663e-002,0.000000e+000,0,,0,
1524149257.209,,0.000000e+000,5.699746e+001,-7.829293e-005,0.000000e+000,3,9.739919e-001,0.000000e+000,,,,,,,,,,,,,,32,1,4.000000e+000,0.000000e+000,0.000000e+000,0,,0,
1524149295.299,,0.000000e+000,5.699396e+001,-7.829752e-005,0.000000e+000,3,9.742795e-001,0.000000e+000,,,,,,,,,,,,,,32,1,4.000000e+000,7.007599e-003,0.000000e+000,0,,0,
1524149332.459,,0.000000e+000,5.699606e+001,-7.835316e-005,0.000000e+000,3,9.740262e-001,0.000000e+000,,,,,,,,,,,,,,32,1,4.000000e+000,2.807617e-003,0.000000e+000,0,,0,
1524149370.279,,0.000000e+000,5.699466e+001,-7.839517e-005,0.000000e+000,3,9.742512e-001,0.000000e+000,,,,,,,,,,,,,,32,1,4.000000e+000,2.807617e-003,0.000000e+000,0,,0,
1524149408.189,,0.000000e+000,5.699956e+001,-7.846095e-005,0.000000e+000,3,9.748461e-001,0.000000e+000,,,,,,,,,,,,,,32,1,4.000000e+000,1.261902e-002,0.000000e+000,0,,0,
1524149445.719,,0.000000e+000,5.699957e+001,-7.841676e-005,0.000000e+000,3,9.740289e-001,0.000000e+000,,,,,,,,,,,,,,32,1,4.000000e+000,4.211426e-003,0.000000e+000,0,,0,
1524149482.839,,0.000000e+000,5.699886e+001,-7.846078e-005,0.000000e+000,3,9.730774e-001,0.000000e+000,,,,,,,,,,,,,,32,1,4.000000e+000,2.799988e-003,0.000000e+000,0,,0,
1524149521.339,,0.000000e+000,5.700237e+001,-7.844526e-005,0.000000e+000,3,9.744235e-001,0.000000e+000,,,,,,,,,,,,,,32,1,4.000000e+000,4.211426e-003,0.000000e+000,0,,0,
1524149559.669,,0.000000e+000,5.700097e+001,-7.860437e-005,0.000000e+000,3,9.743873e-001,0.000000e+000,,,,,,,,,,,,,,32,1,4.000000e+000,1.411438e-003,0.000000e+000,0,,0,
1524149597.259,,0.000000e+000,5.699676e+001,-7.855628e-005,0.000000e+000,3,9.737031e-001,0.000000e+000,,,,,,,,,,,,,,32,1,4.000000e+000,1.399994e-003,0.000000e+000,0,,0,
1524149634.699,,0.000000e+000,5.699396e+001,-7.865299e-005,0.000000e+000,3,9.744222e-001,0.000000e+000,,,,,,,,,,,,,,32,1,4.000000e+000,7.007599e-003,0.000000e+000,0,,0,
1524149673.509,,0.000000e+000,5.700587e+001,-7.867988e-005,0.000000e+000,3,9.737448e-001,0.000000e+000,,,,,,,,,,,,,,32,1,4.000000e+000,0.000000e+000,0.000000e+000,0,,0,
1524149712.639,,0.000000e+000,5.699676e+001,-7.863213e-005,0.000000e+000,3,9.737286e-001,0.000000e+000,,,,,,,,,,,,,,32,1,4.000000e+000,4.207611e-003,0.000000e+000,0,,0,
1524149750.539,,0.000000e+000,5.700166e+001,-7.873974e-005,0.000000e+000,3,9.753643e-001,0.000000e+000,,,,,,,,,,,,,,32,1,4.000000e+000,8.411407e-003,0.000000e+000,0,,0,
1524149787.549,,0.000000e+000,5.699326e+001,-7.864078e-005,0.000000e+000,3,9.742150e-001,0.000000e+000,,,,,,,,,,,,,,32,1,4.000000e+000,2.792358e-003,0.000000e+000,0,,0,
1524149824.989,,0.000000e+000,5.700167e+001,-7.877761e-005,0.000000e+000,3,9.746508e-001,0.000000e+000,,,,,,,,,,,,,,32,1,4.000000e+000,0.000000e+000,0.000000e+000,0,,0,
1524149862.580,,0.000000e+000,5.700026e+001,-7.878883e-005,0.000000e+000,3,9.735052e-001,0.000000e+000,,,,,,,,,,,,,,32,1,4.000000e+000,5.599976e-003,0.000000e+000,0,,0,
1524149901.370,,0.000000e+000,5.700237e+001,-7.886142e-005,0.000000e+000,3,9.742969e-001,0.000000e+000,,,,,,,,,,,,,,32,1,4.000000e+000,1.261902e-002,0.000000e+000,0,,0,
1524149939.190,,0.000000e+000,5.700026e+001,-7.890525e-005,0.000000e+000,3,9.741902e-001,0.000000e+000,,,,,,,,,,,,,,32,1,4.000000e+000,5.599976e-003,0.000000e+000,0,,0,
1524149976.970,,0.000000e+000,5.699746e+001,-7.882501e-005,0.000000e+000,3,9.740671e-001,0.000000e+000,,,,,,,,,,,,,,32,1,4.000000e+000,2.799988e-003,0.000000e+000,0,,0,
1524150014.900,,0.000000e+000,5.699676e+001,-7.894965e-005,0.000000e+000,3,9.735742e-001,0.000000e+000,,,,,,,,,,,,,,32,1,4.000000e+000,7.007599e-003,0.000000e+000,0,,0,
1524150052.880,,0.000000e+000,5.699886e+001,-7.894087e-005,0.000000e+000,3,9.741252e-001,0.000000e+000,,,,,,,,,,,,,,32,1,4.000000e+000,2.799988e-003,0.000000e+000,0,,0,
1524150091.020,,0.000000e+000,5.699676e+001,-7.889186e-005,0.000000e+000,3,9.739490e-001,0.000000e+000,,,,,,,,,,,,,,32,1,4.000000e+000,1.399994e-003,0.000000e+000,0,,0,
1524150129.330,,0.000000e+000,5.698975e+001,-7.902577e-005,0.000000e+000,3,9.741591e-001,0.000000e+000,,,,,,,,,,,,,,32,1,4.000000e+000,1.541901e-002,0.000000e+000,0,,0,
1524150167.670,,0.000000e+000,5.699886e+001,-7.903245e-005,0.000000e+000,3,9.739943e-001,0.000000e+000,,,,,,,,,,,,,,32,1,4.000000e+000,0.000000e+000,0.000000e+000,0,,0,
1524150205.480,,0.000000e+000,5.700446e+001,-7.900071e-005,0.000000e+000,3,9.735228e-001,0.000000e+000,,,,,,,,,,,,,,32,1,4.000000e+000,2.811432e-003,0.000000e+000,0,,0,
1524150243.040,,0.000000e+000,5.699956e+001,-7.913884e-005,0.000000e+000,3,9.756587e-001,0.000000e+000,,,,,,,,,,,,,,32,1,4.000000e+000,6.999969e-003,0.000000e+000,0,,0,
1524150280.750,,0.000000e+000,5.699815e+001,-7.908442e-005,0.000000e+000,3,9.733985e-001,0.000000e+000,,,,,,,,,,,,,,32,1,4.000000e+000,9.807587e-003,0.000000e+000,0,,0,
1524150317.920,,0.000000e+000,5.699606e+001,-7.905193e-005,0.000000e+000,3,9.746158e-001,0.000000e+000,,,,,,,,,,,,,,32,1,4.000000e+000,2.807617e-003,0.000000e+000,0,,0,
1524150355.860,,0.000000e+000,5.699465e+001,-7.905887e-005,0.000000e+000,3,9.743348e-001,0.000000e+000,,,,,,,,,,,,,,32,1,4.000000e+000,0.000000e+000,0.000000e+000,0,,0,
1524150393.490,,0.000000e+000,5.699746e+001,-7.917990e-005,0.000000e+000,3,9.747174e-001,0.000000e+000,,,,,,,,,,,,,,32,1,4.000000e+000,2.799988e-003,0.000000e+000,0,,0,
1524150430.960,,0.000000e+000,5.700307e+001,-7.916391e-005,0.000000e+000,3,9.734432e-001,0.000000e+000,,,,,,,,,,,,,,32,1,4.000000e+000,2.799988e-003,0.000000e+000,0,,0,
1524150469.140,,0.000000e+000,5.699957e+001,-7.925937e-005,0.000000e+000,3,9.748971e-001,0.000000e+000,,,,,,,,,,,,,,32,1,4.000000e+000,4.211426e-003,0.000000e+000,0,,0,
1524150506.570,,0.000000e+000,5.699746e+001,-7.922964e-005,0.000000e+000,3,9.751108e-001,0.000000e+000,,,,,,,,,,,,,,32,1,4.000000e+000,8.419037e-003,0.000000e+000,0,,0,
1524150545.020,,0.000000e+000,5.699886e+001,-7.923858e-005,0.000000e+000,3,9.741209e-001,0.000000e+000,,,,,,,,,,,,,,32,1,4.000000e+000,2.799988e-003,0.000000e+000,0,,0,
1524150583.231,,0.000000e+000,5.700097e+001,-7.931798e-005,0.000000e+000,3,9.745712e-001,0.000000e+000,,,,,,,,,,,,,,32,1,4.000000e+000,9.811401e-003,0.000000e+000,0,,0,
1524150620.401,,0.000000e+000,5.699886e+001,-7.933356e-005,0.000000e+000,3,9.743815e-001,0.000000e+000,,,,,,,,,,,,,,32,1,4.000000e+000,0.000000e+000,0.000000e+000,0,,0,
1524150658.461,,0.000000e+000,5.699606e+001,-7.934877e-005,0.000000e+000,3,9.746775e-001,0.000000e+000,,,,,,,,,,,,,,32,1,4.000000e+000,5.607605e-003,0.000000e+000,0,,0,
1524150695.591,,0.000000e+000,5.700097e+001,-7.936000e-005,0.000000e+000,3,9.750463e-001,0.000000e+000,,,,,,,,,,,,,,32,1,4.000000e+000,7.011414e-003,0.000000e+000,0,,0,
1524150732.801,,0.000000e+000,5.699465e+001,-7.940435e-005,0.000000e+000,3,9.744712e-001,0.000000e+000,,,,,,,,,,,,,,32,1,4.000000e+000,1.121902e-002,0.000000e+000,0,,0,
1524150770.941,,0.000000e+000,5.699816e+001,-7.935548e-005,0.000000e+000,3,9.741195e-001,0.000000e+000,,,,,,,,,,,,,,32,1,4.000000e+000,1.399994e-003,0.000000e+000,0,,0,
1524150808.861,,0.000000e+000,5.699536e+001,-7.946085e-005,0.000000e+000,3,9.746584e-001,0.000000e+000,,,,,,,,,,,,,,32,1,4.000000e+000,6.999969e-003,0.000000e+000,0,,0,
1524150847.131,,0.000000e+000,5.699255e+001,-7.948400e-005,0.000000e+000,3,9.752257e-001,0.000000e+000,,,,,,,,,,,,,,32,1,4.000000e+000,4.199982e-003,0.000000e+000,0,,0,
1524150885.171,,0.000000e+000,5.699186e+001,-7.960968e-005,0.000000e+000,3,9.748318e-001,0.000000e+000,,,,,,,,,,,,,,32,1,4.000000e+000,8.407593e-003,0.000000e+000,0,,0,
1524150923.951,,0.000000e+000,5.699535e+001,-7.947338e-005,0.000000e+000,3,9.740084e-001,0.000000e+000,,,,,,,,,,,,,,32,1,4.000000e+000,9.807587e-003,0.000000e+000,0,,0,
1524150961.721,,0.000000e+000,5.699816e+001,-7.947686e-005,0.000000e+000,3,9.745005e-001,0.000000e+000,,,,,,,,,,,,,,32,1,4.000000e+000,1.399994e-003,0.000000e+000,0,,0,
1524150998.651,,0.000000e+000,5.700096e+001,-7.957796e-005,0.000000e+000,3,9.749904e-001,0.000000e+000,,,,,,,,,,,,,,32,1,4.000000e+000,4.199982e-003,0.000000e+000,0,,0,
1524151036.231,,0.000000e+000,5.699815e+001,-7.954101e-005,0.000000e+000,3,9.740643e-001,0.000000e+000,,,,,,,,,,,,,,32,1,4.000000e+000,9.807587e-003,0.000000e+000,0,,0,
1524151073.831,,0.000000e+000,5.699886e+001,-7.957953e-005,0.000000e+000,3,9.738638e-001,0.000000e+000,,,,,,,,,,,,,,32,1,4.000000e+000,5.611420e-003,0.000000e+000,0,,0,
1524151111.881,,0.000000e+000,5.699816e+001,-7.970862e-005,0.000000e+000,3,9.740267e-001,0.000000e+000,,,,,,,,,,,,,,32,1,4.000000e+000,1.399994e-003,0.000000e+000,0,,0,
1524151150.201,,0.000000e+000,5.700026e+001,-7.960398e-005,0.000000e+000,3,9.735100e-001,0.000000e+000,,,,,,,,,,,,,,32,1,4.000000e+000,0.000000e+000,0.000000e+000,0,,0,
1524151189.201,,0.000000e+000,5.699535e+001,-7.972938e-005,0.000000e+000,3,9.746107e-001,0.000000e+000,,,,,,,,,,,,,,32,1,4.000000e+000,1.407623e-003,0.000000e+000,0,,0,
1524151227.201,,0.000000e+000,5.699746e+001,-7.963990e-005,0.000000e+000,3,9.744721e-001,0.000000e+000,,,,,,,,,,,,,,32,1,4.000000e+000,0.000000e+000,0.000000e+000,0,,0,
1524151265.461,,0.000000e+000,5.699676e+001,-7.972401e-005,0.000000e+000,3,9.737499e-001,0.000000e+000,,,,,,,,,,,,,,32,1,4.000000e+000,1.399994e-003,0.000000e+000,0,,0,
1524151304.052,,0.000000e+000,5.699886e+001,-7.969964e-005,0.000000e+000,3,9.744771e-001,0.000000e+000,,,,,,,,,,,,,,32,1,4.000000e+000,1.121902e-002,0.000000e+000,0,,0,
1524151341.342,,0.000000e+000,5.700097e+001,-7.978048e-005,0.000000e+000,3,9.752176e-001,0.000000e+000,,,,,,,,,,,,,,32,1,4.000000e+000,1.411438e-003,0.000000e+000,0,,0,
1524151378.972,,0.000000e+000,5.700166e+001,-7.980003e-005,0.000000e+000,3,9.738572e-001,0.000000e+000,,,,,,,,,,,,,,32,1,4.000000e+000,5.611420e-003,0.000000e+000,0,,0,
1524151416.622,,0.000000e+000,5.699886e+001,-7.986849e-005,0.000000e+000,3,9.745564e-001,0.000000e+000,,,,,,,,,,,,,,32,1,4.000000e+000,0.000000e+000,0.000000e+000,0,,0,
1524151453.792,,0.000000e+000,5.699746e+001,-7.984442e-005,0.000000e+000,3,9.738992e-001,0.000000e+000,,,,,,,,,,,,,,32,1,4.000000e+000,0.000000e+000,0.000000e+000,0,,0,
1524151491.462,,0.000000e+000,5.699746e+001,-7.990776e-005,0.000000e+000,3,9.741927e-001,0.000000e+000,,,,,,,,,,,,,,32,1,4.000000e+000,2.799988e-003,0.000000e+000,0,,0,
1524151530.082,,0.000000e+000,5.700097e+001,-7.990655e-005,0.000000e+000,3,9.733465e-001,0.000000e+000,,,,,,,,,,,,,,32,1,4.000000e+000,7.011414e-003,0.000000e+000,0,,0,
1524151567.812,,0.000000e+000,5.700097e+001,-7.993128e-005,0.000000e+000,3,9.736999e-001,0.000000e+000,,,,,,,,,,,,,,32,1,4.000000e+000,1.411438e-003,0.000000e+000,0,,0,
1524151605.632,,0.000000e+000,5.699746e+001,-7.992478e-005,0.000000e+000,3,9.740917e-001,0.000000e+000,,,,,,,,,,,,,,32,1,4.000000e+000,2.799988e-003,0.000000e+000,0,,0,
1524151643.382,,0.000000e+000,5.700026e+001,-7.997888e-005,0.000000e+000,3,9.753678e-001,0.000000e+000,,,,,,,,,,,,,,32,1,4.000000e+000,0.000000e+000,0.000000e+000,0,,0,
1524151680.792,,0.000000e+000,5.699746e+001,-7.997459e-005,0.000000e+000,3,9.753742e-001,0.000000e+000,,,,,,,,,,,,,,32,1,4.000000e+000,2.799988e-003,0.000000e+000,0,,0,
1524151718.162,,0.000000e+000,5.700237e+001,-7.997041e-005,0.000000e+000,3,9.738702e-001,0.000000e+000,,,,,,,,,,,,,,32,1,4.000000e+000,1.388550e-003,0.000000e+000,0,,0,
1524151755.772,,0.000000e+000,5.699606e+001,-7.998948e-005,0.000000e+000,3,9.742990e-001,0.000000e+000,,,,,,,,,,,,,,32,1,4.000000e+000,1.121902e-002,0.000000e+000,0,,0,
1524151793.602,,0.000000e+000,5.699536e+001,-8.007623e-005,0.000000e+000,3,9.734609e-001,0.000000e+000,,,,,,,,,,,,,,32,1,4.000000e+000,6.999969e-003,0.000000e+000,0,,0,
1524151831.132,,0.000000e+000,5.699746e+001,-8.003175e-005,0.000000e+000,3,9.755647e-001,0.000000e+000,,,,,,,,,,,,,,32,1,4.000000e+000,2.799988e-003,0.000000e+000,0,,0,
1524151869.442,,0.000000e+000,5.699886e+001,-8.012958e-005,0.000000e+000,3,9.746454e-001,0.000000e+000,,,,,,,,,,,,,,32,1,4.000000e+000,8.407593e-003,0.000000e+000,0,,0,
1524151906.822,,0.000000e+000,5.700307e+001,-8.003115e-005,0.000000e+000,3,9.741260e-001,0.000000e+000,,,,,,,,,,,,,,32,1,4.000000e+000,5.611420e-003,0.000000e+000,0,,0,
1524151945.032,,0.000000e+000,5.700166e+001,-8.012739e-005,0.000000e+000,3,9.743103e-001,0.000000e+000,,,,,,,,,,,,,,32,1,4.000000e+000,5.611420e-003,0.000000e+000,0,,0,
1524151983.302,,0.000000e+000,5.700377e+001,-8.014059e-005,0.000000e+000,3,9.741670e-001,0.000000e+000,,,,,,,,,,,,,,32,1,4.000000e+000,4.199982e-003,0.000000e+000,0,,0,
1524152021.573,,0.000000e+000,5.699535e+001,-8.014763e-005,0.000000e+000,3,9.741057e-001,0.000000e+000,,,,,,,,,,,,,,32,1,4.000000e+000,1.407623e-003,0.000000e+000,0,,0,
1524152059.163,,0.000000e+000,5.700166e+001,-8.017116e-005,0.000000e+000,3,9.737479e-001,0.000000e+000,,,,,,,,,,,,,,32,1,4.000000e+000,2.799988e-003,0.000000e+000,0,,0,
1524152097.503,,0.000000e+000,5.699606e+001,-8.018460e-005,0.000000e+000,3,9.743440e-001,0.000000e+000,,,,,,,,,,,,,,32,1,4.000000e+000,8.399963e-003,0.000000e+000,0,,0,
1524152135.473,,0.000000e+000,5.699886e+001,-8.027726e-005,0.000000e+000,3,9.751222e-001,0.000000e+000,,,,,,,,,,,,,,32,1,4.000000e+000,2.799988e-003,0.000000e+000,0,,0,
1524152173.013,,0.000000e+000,5.699535e+001,-8.022120e-005,0.000000e+000,3,9.736634e-001,0.000000e+000,,,,,,,,,,,,,,32,1,4.000000e+000,1.407623e-003,0.000000e+000,0,,0,
1524152211.063,,0.000000e+000,5.699957e+001,-8.028780e-005,0.000000e+000,3,9.742502e-001,0.000000e+000,,,,,,,,,,,,,,32,1,4.000000e+000,4.211426e-003,0.000000e+000,0,,0,
1524152248.973,,0.000000e+000,5.699606e+001,-8.026550e-005,0.000000e+000,3,9.733737e-001,0.000000e+000,,,,,,,,,,,,,,32,1,4.000000e+000,5.607605e-003,0.000000e+000,0,,0,
1524152287.833,,0.000000e+000,5.700447e+001,-8.034238e-005,0.000000e+000,3,9.747588e-001,0.000000e+000,,,,,,,,,,,,,,32,1,4.000000e+000,2.243805e-002,0.000000e+000,0,,0,
1524152325.383,,0.000000e+000,5.699746e+001,-8.027400e-005,0.000000e+000,3,9.739235e-001,0.000000e+000,,,,,,,,,,,,,,32,1,4.000000e+000,5.607605e-003,0.000000e+000,0,,0,
1524152363.253,,0.000000e+000,5.699746e+001,-8.032809e-005,0.000000e+000,3,9.744617e-001,0.000000e+000,,,,,,,,,,,,,,32,1,4.000000e+000,2.799988e-003,0.000000e+000,0,,0,
1524152400.513,,0.000000e+000,5.699816e+001,-8.039212e-005,0.000000e+000,3,9.754108e-001,0.000000e+000,,,,,,,,,,,,,,32,1,4.000000e+000,4.199982e-003,0.000000e+000,0,,0,
1524152438.003,,0.000000e+000,5.699816e+001,-8.034972e-005,0.000000e+000,3,9.744443e-001,0.000000e+000,,,,,,,,,,,,,,32,1,4.000000e+000,4.199982e-003,0.000000e+000,0,,0,
1524152475.623,,0.000000e+000,5.700307e+001,-8.033404e-005,0.000000e+000,3,9.734635e-001,0.000000e+000,,,,,,,,,,,,,,32,1,4.000000e+000,1.121902e-002,0.000000e+000,0,,0,
1524152514.353,,0.000000e+000,5.699886e+001,-8.038889e-005,0.000000e+000,3,9.744278e-001,0.000000e+000,,,,,,,,,,,,,,32,1,4.000000e+000,0.000000e+000,0.000000e+000,0,,0,
1524152552.333,,0.000000e+000,5.700166e+001,-8.044912e-005,0.000000e+000,3,9.741846e-001,0.000000e+000,,,,,,,,,,,,,,32,1,4.000000e+000,8.411407e-003,0.000000e+000,0,,0,
1524152589.593,,0.000000e+000,5.699676e+001,-8.041698e-005,0.000000e+000,3,9.739400e-001,0.000000e+000,,,,,,,,,,,,,,32,1,4.000000e+000,4.207611e-003,0.000000e+000,0,,0,
1524152627.963,,0.000000e+000,5.699816e+001,-8.046600e-005,0.000000e+000,3,9.744816e-001,0.000000e+000,,,,,,,,,,,,,,32,1,4.000000e+000,1.399994e-003,0.000000e+000,0,,0,
1524152666.233,,0.000000e+000,5.700658e+001,-8.041840e-005,0.000000e+000,3,9.741451e-001,0.000000e+000,,,,,,,,,,,,,,32,1,4.000000e+000,1.543045e-002,0.000000e+000,0,,0,
1524152704.724,,0.000000e+000,5.699396e+001,-8.052600e-005,0.000000e+000,3,9.739258e-001,0.000000e+000,,,,,,,,,,,,,,32,1,4.000000e+000,7.007599e-003,0.000000e+000,0,,0,
1524152742.734,,0.000000e+000,5.700097e+001,-8.049430e-005,0.000000e+000,3,9.745277e-001,0.000000e+000,,,,,,,,,,,,,,32,1,4.000000e+000,7.011414e-003,0.000000e+000,0,,0,
1524152780.644,,0.000000e+000,5.699466e+001,-8.051082e-005,0.000000e+000,3,9.742652e-001,0.000000e+000,,,,,,,,,,,,,,32,1,4.000000e+000,5.599976e-003,0.000000e+000,0,,0,
1524152818.454,,0.000000e+000,5.699535e+001,-8.054123e-005,0.000000e+000,3,9.740808e-001,0.000000e+000,,,,,,,,,,,,,,32,1,4.000000e+000,4.207611e-003,0.000000e+000,0,,0,
1524152856.244,,0.000000e+000,5.699886e+001,-8.055604e-005,0.000000e+000,3,9.745631e-001,0.000000e+000,,,,,,,,,,,,,,32,1,4.000000e+000,2.799988e-003,0.000000e+000,0,,0,
1524152893.554,,0.000000e+000,5.699886e+001,-8.050889e-005,0.000000e+000,3,9.742913e-001,0.000000e+000,,,,,,,,,,,,,,32,1,4.000000e+000,2.799988e-003,0.000000e+000,0,,0,
1524152930.864,,0.000000e+000,5.699746e+001,-8.058854e-005,0.000000e+000,3,9.739044e-001,0.000000e+000,,,,,,,,,,,,,,32,1,4.000000e+000,2.799988e-003,0.000000e+000,0,,0,
1524152969.194,,0.000000e+000,5.699886e+001,-8.050581e-005,0.000000e+000,3,9.743177e-001,0.000000e+000,,,,,,,,,,,,,,32,1,4.000000e+000,2.799988e-003,0.000000e+000,0,,0,
1524153007.384,,0.000000e+000,5.699676e+001,-8.062932e-005,0.000000e+000,3,9.748638e-001,0.000000e+000,,,,,,,,,,,,,,32,1,4.000000e+000,4.207611e-003,0.000000e+000,0,,0,
1524153045.134,,0.000000e+000,5.700096e+001,-8.066156e-005,0.000000e+000,3,9.742950e-001,0.000000e+000,,,,,,,,,,,,,,32,1,4.000000e+000,4.199982e-003,0.000000e+000,0,,0,
1524153082.834,,0.000000e+000,5.699325e+001,-8.066123e-005,0.000000e+000,3,9.737525e-001,0.000000e+000,,,,,,,,,,,,,,32,1,4.000000e+000,8.419037e-003,0.000000e+000,0,,0,
1524153121.004,,0.000000e+000,5.699326e+001,-8.062709e-005,0.000000e+000,3,9.744460e-001,0.000000e+000,,,,,,,,,,,,,,32,1,4.000000e+000,1.120758e-002,0.000000e+000,0,,0,
1524153159.114,,0.000000e+000,5.700027e+001,-8.071950e-005,0.000000e+000,3,9.748662e-001,0.000000e+000,,,,,,,,,,,,,,32,1,4.000000e+000,2.811432e-003,0.000000e+000,0,,0,
1524153197.364,,0.000000e+000,5.699956e+001,-8.074383e-005,0.000000e+000,3,9.741424e-001,0.000000e+000,,,,,,,,,,,,,,32,1,4.000000e+000,6.999969e-003,0.000000e+000,0,,0,
1524153235.534,,0.000000e+000,5.699535e+001,-8.076498e-005,0.000000e+000,3,9.741183e-001,0.000000e+000,,,,,,,,,,,,,,32,1,4.000000e+000,4.207611e-003,0.000000e+000,0,,0,
1524153273.474,,0.000000e+000,5.699886e+001,-8.074054e-005,0.000000e+000,3,9.741538e-001,0.000000e+000,,,,,,,,,,,,,,32,1,4.000000e+000,0.000000e+000,0.000000e+000,0,,0,
1524153311.444,,0.000000e+000,5.699676e+001,-8.079397e-005,0.000000e+000,3,9.747760e-001,0.000000e+000,,,,,,,,,,,,,,32,1,4.000000e+000,7.007599e-003,0.000000e+000,0,,0,
1524153348.964,,0.000000e+000,5.699465e+001,-8.081235e-005,0.000000e+000,3,9.743769e-001,0.000000e+000,,,,,,,,,,,,,,32,1,4.000000e+000,1.121902e-002,0.000000e+000,0,,0,
1524153386.714,,0.000000e+000,5.699886e+001,-8.076940e-005,0.000000e+000,3,9.742409e-001,0.000000e+000,,,,,,,,,,,,,,32,1,4.000000e+000,5.611420e-003,0.000000e+000,0,,0,
1524153424.785,,0.000000e+000,5.699886e+001,-8.085444e-005,0.000000e+000,3,9.744198e-001,0.000000e+000,,,,,,,,,,,,,,32,1,4.000000e+000,0.000000e+000,0.000000e+000,0,,0,
1524153463.475,,0.000000e+000,5.699396e+001,-8.086197e-005,0.000000e+000,3,9.742597e-001,0.000000e+000,,,,,,,,,,,,,,32,1,4.000000e+000,4.199982e-003,0.000000e+000,0,,0,
1524153501.245,,0.000000e+000,5.699816e+001,-8.089533e-005,0.000000e+000,3,9.744710e-001,0.000000e+000,,,,,,,,,,,,,,32,1,4.000000e+000,4.199982e-003,0.000000e+000,0,,0,
1524153539.405,,0.000000e+000,5.699465e+001,-8.085710e-005,0.000000e+000,3,9.745609e-001,0.000000e+000,,,,,,,,,,,,,,32,1,4.000000e+000,1.121902e-002,0.000000e+000,0,,0,
1524153578.045,,0.000000e+000,5.699956e+001,-8.093524e-005,0.000000e+000,3,9.747777e-001,0.000000e+000,,,,,,,,,,,,,,32,1,4.000000e+000,1.399994e-003,0.000000e+000,0,,0,
1524153616.085,,0.000000e+000,5.699746e+001,-8.087236e-005,0.000000e+000,3,9.746629e-001,0.000000e+000,,,,,,,,,,,,,,32,1,4.000000e+000,8.419037e-003,0.000000e+000,0,,0,
1524153653.895,,0.000000e+000,5.699676e+001,-8.088734e-005,0.000000e+000,3,9.749449e-001,0.000000e+000,,,,,,,,,,,,,,32,1,4.000000e+000,1.399994e-003,0.000000e+000,0,,0,
1524153691.285,,0.000000e+000,5.699957e+001,-8.095685e-005,0.000000e+000,3,9.740742e-001,0.000000e+000,,,,,,,,,,,,,,32,1,4.000000e+000,4.211426e-003,0.000000e+000,0,,0,
1524153729.565,,0.000000e+000,5.699956e+001,-8.091710e-005,0.000000e+000,3,9.747393e-001,0.000000e+000,,,,,,,,,,,,,,32,1,4.000000e+000,6.999969e-003,0.000000e+000,0,,0,
1524153766.935,,0.000000e+000,5.699466e+001,-8.093511e-005,0.000000e+000,3,9.738474e-001,0.000000e+000,,,,,,,,,,,,,,32,1,4.000000e+000,8.407593e-003,0.000000e+000,0,,0,
1524153804.975,,0.000000e+000,5.699816e+001,-8.098589e-005,0.000000e+000,3,9.737411e-001,0.000000e+000,,,,,,,,,,,,,,32,1,4.000000e+000,4.199982e-003,0.000000e+000,0,,0,
1524153843.025,,0.000000e+000,5.699466e+001,-8.093897e-005,0.000000e+000,3,9.744330e-001,0.000000e+000,,,,,,,,,,,,,,32,1,4.000000e+000,5.599976e-003,0.000000e+000,0,,0,
1524153881.435,,0.000000e+000,5.699677e+001,-8.100180e-005,0.000000e+000,3,9.743414e-001,0.000000e+000,,,,,,,,,,,,,,32,1,4.000000e+000,9.811401e-003,0.000000e+000,0,,0,
1524153918.955,,0.000000e+000,5.699255e+001,-8.103961e-005,0.000000e+000,3,9.736213e-001,0.000000e+000,,,,,,,,,,,,,,32,1,4.000000e+000,1.392365e-003,0.000000e+000,0,,0,
1524153956.595,,0.000000e+000,5.699816e+001,-8.106347e-005,0.000000e+000,3,9.744388e-001,0.000000e+000,,,,,,,,,,,,,,32,1,4.000000e+000,1.399994e-003,0.000000e+000,0,,0,
1524153994.705,,0.000000e+000,5.699816e+001,-8.107447e-005,0.000000e+000,3,9.754686e-001,0.000000e+000,,,,,,,,,,,,,,32,1,4.000000e+000,1.399994e-003,0.000000e+000,0,,0,
1524154033.135,,0.000000e+000,5.700026e+001,-8.102573e-005,0.000000e+000,3,9.744990e-001,0.000000e+000,,,,,,,,,,,,,,32,1,4.000000e+000,5.599976e-003,0.000000e+000,0,,0,
1524154071.385,,0.000000e+000,5.699886e+001,-8.107741e-005,0.000000e+000,3,9.742072e-001,0.000000e+000,,,,,,,,,,,,,,32,1,4.000000e+000,0.000000e+000,0.000000e+000,0,,0,
1524154133.806,,0.000000e+000,5.698905e+001,-8.105850e-005,0.000000e+000,3,9.744868e-001,0.000000e+000,,,,,,,,,,,,,,32,1,4.000000e+000,2.799988e-003,0.000000e+000,0,,0,
1524154171.286,,0.000000e+000,5.700097e+001,-8.110186e-005,0.000000e+000,3,9.744545e-001,0.000000e+000,,,,,,,,,,,,,,32,1,4.000000e+000,1.411438e-003,0.000000e+000,0,,0,
1524154208.296,,0.000000e+000,5.699957e+001,-8.110702e-005,0.000000e+000,3,9.749586e-001,0.000000e+000,,,,,,,,,,,,,,32,1,4.000000e+000,4.211426e-003,0.000000e+000,0,,0,
1524154245.616,,0.000000e+000,5.700027e+001,-8.121318e-005,0.000000e+000,3,9.751040e-001,0.000000e+000,,,,,,,,,,,,,,32,1,4.000000e+000,1.962662e-002,0.000000e+000,0,,0,
1524154282.946,,0.000000e+000,5.699465e+001,-8.113648e-005,0.000000e+000,3,9.744007e-001,0.000000e+000,,,,,,,,,,,,,,32,1,4.000000e+000,1.681900e-002,0.000000e+000,0,,0,
1524154321.126,,0.000000e+000,5.700097e+001,-8.114317e-005,0.000000e+000,3,9.742239e-001,0.000000e+000,,,,,,,,,,,,,,32,1,4.000000e+000,7.011414e-003,0.000000e+000,0,,0,
1524154358.976,,0.000000e+000,5.700517e+001,-8.116942e-005,0.000000e+000,3,9.748258e-001,0.000000e+000,,,,,,,,,,,,,,32,1,4.000000e+000,1.399994e-003,0.000000e+000,0,,0,
1524154396.606,,0.000000e+000,5.699816e+001,-8.118427e-005,0.000000e+000,3,9.747700e-001,0.000000e+000,,,,,,,,,,,,,,32,1,4.000000e+000,1.541901e-002,0.000000e+000,0,,0,
1524154434.226,,0.000000e+000,5.699676e+001,-8.119986e-005,0.000000e+000,3,9.737667e-001,0.000000e+000,,,,,,,,,,,,,,32,1,4.000000e+000,7.007599e-003,0.000000e+000,0,,0,
1524154471.656,,0.000000e+000,5.700377e+001,-8.126013e-005,0.000000e+000,3,9.737014e-001,0.000000e+000,,,,,,,,,,,,,,32,1,4.000000e+000,9.819031e-003,0.000000e+000,0,,0,
1524154508.976,,0.000000e+000,5.700377e+001,-8.119526e-005,0.000000e+000,3,9.738005e-001,0.000000e+000,,,,,,,,,,,,,,32,1,4.000000e+000,7.019043e-003,0.000000e+000,0,,0,
1524154547.436,,0.000000e+000,5.700658e+001,-8.125020e-005,0.000000e+000,3,9.746621e-001,0.000000e+000,,,,,,,,,,,,,,32,1,4.000000e+000,1.407623e-003,0.000000e+000,0,,0,
1524154585.336,,0.000000e+000,5.699676e+001,-8.126375e-005,0.000000e+000,3,9.743031e-001,0.000000e+000,,,,,,,,,,,,,,32,1,4.000000e+000,1.399994e-003,0.000000e+000,0,,0,
1524154623.746,,0.000000e+000,5.700307e+001,-8.129426e-005,0.000000e+000,3,9.744075e-001,0.000000e+000,,,,,,,,,,,,,,32,1,4.000000e+000,2.799988e-003,0.000000e+000,0,,0,
1524154660.986,,0.000000e+000,5.700097e+001,-8.131930e-005,0.000000e+000,3,9.756589e-001,0.000000e+000,,,,,,,,,,,,,,32,1,4.000000e+000,1.411438e-003,0.000000e+000,0,,0,
1524154698.976,,0.000000e+000,5.699816e+001,-8.133562e-005,0.000000e+000,3,9.750395e-001,0.000000e+000,,,,,,,,,,,,,,32,1,4.000000e+000,4.199982e-003,0.000000e+000,0,,0,
1524154736.146,,0.000000e+000,5.699115e+001,-8.131390e-005,0.000000e+000,3,9.738626e-001,0.000000e+000,,,,,,,,,,,,,,32,1,4.000000e+000,9.819031e-003,0.000000e+000,0,,0,
1524154774.196,,0.000000e+000,5.699815e+001,-8.132889e-005,0.000000e+000,3,9.744185e-001,0.000000e+000,,,,,,,,,,,,,,32,1,4.000000e+000,9.807587e-003,0.000000e+000,0,,0,
1524154812.296,,0.000000e+000,5.699676e+001,-8.145948e-005,0.000000e+000,3,9.745557e-001,0.000000e+000,,,,,,,,,,,,,,32,1,4.000000e+000,4.207611e-003,0.000000e+000,0,,0,
1524154850.117,,0.000000e+000,5.699676e+001,-8.136167e-005,0.000000e+000,3,9.731854e-001,0.000000e+000,,,,,,,,,,,,,,32,1,4.000000e+000,4.207611e-003,0.000000e+000,0,,0,
1524154888.017,,0.000000e+000,5.699886e+001,-8.142091e-005,0.000000e+000,3,9.745085e-001,0.000000e+000,,,,,,,,,,,,,,32,1,4.000000e+000,1.401138e-002,0.000000e+000,0,,0,
1524154926.697,,0.000000e+000,5.700097e+001,-8.143810e-005,0.000000e+000,3,9.740338e-001,0.000000e+000,,,,,,,,,,,,,,32,1,4.000000e+000,7.011414e-003,0.000000e+000,0,,0,
1524154965.007,,0.000000e+000,5.699746e+001,-8.140312e-005,0.000000e+000,3,9.742257e-001,0.000000e+000,,,,,,,,,,,,,,32,1,4.000000e+000,2.799988e-003,0.000000e+000,0,,0,
1524155002.397,,0.000000e+000,5.699956e+001,-8.138590e-005,0.000000e+000,3,9.738485e-001,0.000000e+000,,,,,,,,,,,,,,32,1,4.000000e+000,1.261902e-002,0.000000e+000,0,,0,
1524155040.067,,0.000000e+000,5.700166e+001,-8.140650e-005,0.000000e+000,3,9.746222e-001,0.000000e+000,,,,,,,,,,,,,,32,1,4.000000e+000,5.611420e-003,0.000000e+000,0,,0,
1524155077.807,,0.000000e+000,5.699676e+001,-8.151940e-005,0.000000e+000,3,9.746867e-001,0.000000e+000,,,,,,,,,,,,,,32,1,4.000000e+000,1.399994e-003,0.000000e+000,0,,0,
1524155115.087,,0.000000e+000,5.700027e+001,-8.152708e-005,0.000000e+000,3,9.733258e-001,0.000000e+000,,,,,,,,,,,,,,32,1,4.000000e+000,2.811432e-003,0.000000e+000,0,,0,
1524155152.587,,0.000000e+000,5.699957e+001,-4.832412e-006,0.000000e+000,3,0.000000e+000,0.000000e+000,,,,,,,,,,,,,,32,1,4.000000e+000,4.211426e-003,0.000000e+000,0,,0,
1524155190.727,,0.000000e+000,5.700307e+001,-8.158185e-005,0.000000e+000,3,9.743707e-001,0.000000e+000,,,,,,,,,,,,,,32,1,4.000000e+000,5.611420e-003,0.000000e+000,0,,0,
1524155228.387,,0.000000e+000,5.699326e+001,-8.155894e-005,0.000000e+000,3,9.745322e-001,0.000000e+000,,,,,,,,,,,,,,32,1,4.000000e+000,2.792358e-003,0.000000e+000,0,,0,
1524155267.097,,0.000000e+000,5.700026e+001,-8.153379e-005,0.000000e+000,3,9.744077e-001,0.000000e+000,,,,,,,,,,,,,,32,1,4.000000e+000,0.000000e+000,0.000000e+000,0,,0,
1524155305.027,,0.000000e+000,5.699746e+001,-8.157302e-005,0.000000e+000,3,9.745193e-001,0.000000e+000,,,,,,,,,,,,,,32,1,4.000000e+000,2.799988e-003,0.000000e+000,0,,0,
1524155343.137,,0.000000e+000,5.699255e+001,-8.151781e-005,0.000000e+000,3,9.734840e-001,0.000000e+000,,,,,,,,,,,,,,32,1,4.000000e+000,1.392365e-003,0.000000e+000,0,,0,
1524155380.977,,0.000000e+000,5.700096e+001,-8.157226e-005,0.000000e+000,3,9.742512e-001,0.000000e+000,,,,,,,,,,,,,,32,1,4.000000e+000,4.199982e-003,0.000000e+000,0,,0,
1524155418.127,,0.000000e+000,5.699606e+001,-8.169012e-005,0.000000e+000,3,9.734648e-001,0.000000e+000,,,,,,,,,,,,,,32,1,4.000000e+000,0.000000e+000,0.000000e+000,0,,0,
1524155455.437,,0.000000e+000,5.699676e+001,-8.152715e-005,0.000000e+000,3,9.745702e-001,0.000000e+000,,,,,,,,,,,,,,32,1,4.000000e+000,4.207611e-003,0.000000e+000,0,,0,
1524155492.607,,0.000000e+000,5.699886e+001,-8.162401e-005,0.000000e+000,3,9.736800e-001,0.000000e+000,,,,,,,,,,,,,,32,1,4.000000e+000,0.000000e+000,0.000000e+000,0,,0,
1524155530.887,,0.000000e+000,5.699466e+001,-8.163883e-005,0.000000e+000,3,9.745892e-001,0.000000e+000,,,,,,,,,,,,,,32,1,4.000000e+000,1.401901e-002,0.000000e+000,0,,0,
1524155569.018,,0.000000e+000,5.699255e+001,-8.166674e-005,0.000000e+000,3,9.738901e-001,0.000000e+000,,,,,,,,,,,,,,32,1,4.000000e+000,9.807587e-003,0.000000e+000,0,,0,
1524155606.738,,0.000000e+000,5.699395e+001,-8.159031e-005,0.000000e+000,3,9.739851e-001,0.000000e+000,,,,,,,,,,,,,,32,1,4.000000e+000,1.399994e-003,0.000000e+000,0,,0,
1524155644.758,,0.000000e+000,5.699606e+001,-8.165308e-005,0.000000e+000,3,9.742088e-001,0.000000e+000,,,,,,,,,,,,,,32,1,4.000000e+000,8.399963e-003,0.000000e+000,0,,0,
1524155682.428,,0.000000e+000,5.699886e+001,-8.167300e-005,0.000000e+000,3,9.735199e-001,0.000000e+000,,,,,,,,,,,,,,32,1,4.000000e+000,0.000000e+000,0.000000e+000,0,,0,
1524155720.718,,0.000000e+000,5.699255e+001,-8.170636e-005,0.000000e+000,3,9.741024e-001,0.000000e+000,,,,,,,,,,,,,,32,1,4.000000e+000,1.261902e-002,0.000000e+000,0,,0,
1524155758.298,,0.000000e+000,5.699746e+001,-8.169595e-005,0.000000e+000,3,9.753406e-001,0.000000e+000,,,,,,,,,,,,,,32,1,4.000000e+000,2.799988e-003,0.000000e+000,0,,0,
1524155795.508,,0.000000e+000,5.699606e+001,-8.166859e-005,0.000000e+000,3,9.746019e-001,0.000000e+000,,,,,,,,,,,,,,32,1,4.000000e+000,8.399963e-003,0.000000e+000,0,,0,
1524155833.508,,0.000000e+000,5.699957e+001,-8.178421e-005,0.000000e+000,3,9.752184e-001,0.000000e+000,,,,,,,,,,,,,,32,1,4.000000e+000,4.211426e-003,0.000000e+000,0,,0,
1524155858.258,,0.000000e+000,5.699466e+001,-8.172673e-005,0.000000e+000,3,9.743895e-001,0.000000e+000,,,,,,,,,,,,,,32,1,4.000000e+000,2.807617e-003,0.000000e+000,0,,0,