File: Experimental Raw Data/TC04-12-01K VRMac VRMde/Iterative Regression/TC04-12-01K_VRMac_55K_12000s_VRMde_55K.dc.dat
[Header]
TITLE,MPMS DC Measurement
BYAPP,MPMS Measurement,2.1,Summary
FILEOPENTIME, 1524026515.674000 4/17/2018, 10:41:55 PM

INFO, APPNAME, MPMS MultiVu Application, Revision 1.61,  Build 082

INFO, NAME, TC04-12-01K
INFO, WEIGHT, 1.000
INFO, AREA, 1.000
INFO, LENGTH, 1.000
INFO, SHAPE, 0
INFO, COMMENT,
INFO, SEQUENCE FILE: VRMac_55K_12000s_VRMde_55K.seq


INFO, BACKGROUND DATA FILE:, None


STARTUPAXIS,X,4,LINEAR,AUTO,0.000000,0.000000
STARTUPAXIS,Y1,5,LINEAR,AUTO,0.000000,0.000000


STARTUPGROUP,Longitudinal
FIELDGROUP,Longitudinal,1,2,3,4,5,6,7,8,9,15,16,17,18,27,28
FIELDGROUP,Transverse,1,2,3,4,10,11,12,13,14,19,20,21,22,27,28

PLOT_APPEARANCE,ALL,HORZ_GRID_ON,VERT_GRID_ON,MARKERS_AND_LINES

[Data]
Time,Comment,Field (Oe),Temperature (K),Long Moment (emu),Long Scan Std Dev,Long Algorithm,Long Reg Fit,Long Percent Error (%),Trans Moment (emu),Trans Scan Std Dev,Trans Algorithm,Trans Reg Fit,Trans Percent Error (%),Long Moment [w/o ABS] (emu),Long Scan Std Dev [w/o ABS],Long Reg Fit [w/o ABS],Long Percent Error [w/o ABS] (%),Trans Moment [w/o ABS] (emu),Trans Scan Std Dev [w/o ABS],Trans Reg Fit [w/o ABS],Trans Percent Error [w/o ABS] (%),Points per Scan,Scans per Measurement,Scan Length (cm),Delta Temp (K),Rot Position (deg),Error,EC Comp. Running,Using ABS,
1524026515.674,,0.000000e+000,5.500169e+001,-2.050540e-005,0.000000e+000,3,9.651595e-001,0.000000e+000,,,,,,,,,,,,,,32,1,4.000000e+000,1.319885e-003,0.000000e+000,0,,0,
1524026553.174,,0.000000e+000,5.499773e+001,-1.679491e-005,0.000000e+000,3,9.683629e-001,0.000000e+000,,,,,,,,,,,,,,32,1,4.000000e+000,1.308441e-003,0.000000e+000,0,,0,
1524026590.744,,0.000000e+000,5.499708e+001,-1.493744e-005,0.000000e+000,3,9.621221e-001,0.000000e+000,,,,,,,,,,,,,,32,1,4.000000e+000,0.000000e+000,0.000000e+000,0,,0,
1524026628.874,,0.000000e+000,5.499248e+001,-1.362363e-005,0.000000e+000,3,9.613067e-001,0.000000e+000,,,,,,,,,,,,,,32,1,4.000000e+000,1.710129e-002,0.000000e+000,0,,0,
1524026666.804,,0.000000e+000,5.499775e+001,-1.260153e-005,0.000000e+000,3,9.650415e-001,0.000000e+000,,,,,,,,,,,,,,32,1,4.000000e+000,9.208679e-003,0.000000e+000,0,,0,
1524026704.644,,0.000000e+000,5.500037e+001,-1.198597e-005,0.000000e+000,3,9.648567e-001,0.000000e+000,,,,,,,,,,,,,,32,1,4.000000e+000,1.319885e-003,0.000000e+000,0,,0,
1524026742.414,,0.000000e+000,5.500300e+001,-1.129449e-005,0.000000e+000,3,9.673493e-001,0.000000e+000,,,,,,,,,,,,,,32,1,4.000000e+000,3.940582e-003,0.000000e+000,0,,0,
1524026780.184,,0.000000e+000,5.499774e+001,-1.082161e-005,0.000000e+000,3,9.627774e-001,0.000000e+000,,,,,,,,,,,,,,32,1,4.000000e+000,3.940582e-003,0.000000e+000,0,,0,
1524026817.434,,0.000000e+000,5.499709e+001,-1.025309e-005,0.000000e+000,3,9.626044e-001,0.000000e+000,,,,,,,,,,,,,,32,1,4.000000e+000,1.840973e-002,0.000000e+000,0,,0,
1524026854.824,,0.000000e+000,5.499840e+001,-9.962060e-006,0.000000e+000,3,9.661483e-001,0.000000e+000,,,,,,,,,,,,,,32,1,4.000000e+000,5.260468e-003,0.000000e+000,0,,0,
1524026893.324,,0.000000e+000,5.499906e+001,-9.522260e-006,0.000000e+000,3,9.521082e-001,0.000000e+000,,,,,,,,,,,,,,32,1,4.000000e+000,9.220123e-003,0.000000e+000,0,,0,
1524026931.344,,0.000000e+000,5.499840e+001,-9.160492e-006,0.000000e+000,3,9.562805e-001,0.000000e+000,,,,,,,,,,,,,,32,1,4.000000e+000,2.628326e-003,0.000000e+000,0,,0,
1524026969.264,,0.000000e+000,5.500826e+001,-8.869853e-006,0.000000e+000,3,9.534185e-001,0.000000e+000,,,,,,,,,,,,,,32,1,4.000000e+000,1.710892e-002,0.000000e+000,0,,0,
1524027006.744,,0.000000e+000,5.499905e+001,-8.588503e-006,0.000000e+000,3,9.512046e-001,0.000000e+000,,,,,,,,,,,,,,32,1,4.000000e+000,1.319885e-003,0.000000e+000,0,,0,
1524027044.465,,0.000000e+000,5.500169e+001,-8.345130e-006,0.000000e+000,3,9.579090e-001,0.000000e+000,,,,,,,,,,,,,,32,1,4.000000e+000,3.959656e-003,0.000000e+000,0,,0,
1524027082.175,,0.000000e+000,5.500169e+001,-8.082527e-006,0.000000e+000,3,9.495422e-001,0.000000e+000,,,,,,,,,,,,,,32,1,4.000000e+000,1.184082e-002,0.000000e+000,0,,0,
1524027120.025,,0.000000e+000,5.499971e+001,-7.898338e-006,0.000000e+000,3,9.509017e-001,0.000000e+000,,,,,,,,,,,,,,32,1,4.000000e+000,0.000000e+000,0.000000e+000,0,,0,
1524027157.755,,0.000000e+000,5.499248e+001,-7.655166e-006,0.000000e+000,3,9.486332e-001,0.000000e+000,,,,,,,,,,,,,,32,1,4.000000e+000,1.319885e-003,0.000000e+000,0,,0,
1524027195.605,,0.000000e+000,5.500037e+001,-7.470996e-006,0.000000e+000,3,9.494504e-001,0.000000e+000,,,,,,,,,,,,,,32,1,4.000000e+000,9.201050e-003,0.000000e+000,0,,0,
1524027233.335,,0.000000e+000,5.499708e+001,-7.269933e-006,0.000000e+000,3,9.457117e-001,0.000000e+000,,,,,,,,,,,,,,32,1,4.000000e+000,2.620697e-003,0.000000e+000,0,,0,
1524027271.195,,0.000000e+000,5.499774e+001,-7.119833e-006,0.000000e+000,3,9.495748e-001,0.000000e+000,,,,,,,,,,,,,,32,1,4.000000e+000,6.580353e-003,0.000000e+000,0,,0,
1524027308.915,,0.000000e+000,5.499773e+001,-6.961390e-006,0.000000e+000,3,9.412670e-001,0.000000e+000,,,,,,,,,,,,,,32,1,4.000000e+000,1.308441e-003,0.000000e+000,0,,0,
1524027346.775,,0.000000e+000,5.500169e+001,-6.742308e-006,0.000000e+000,3,9.492474e-001,0.000000e+000,,,,,,,,,,,,,,32,1,4.000000e+000,3.959656e-003,0.000000e+000,0,,0,
1524027384.525,,0.000000e+000,5.499577e+001,-6.641347e-006,0.000000e+000,3,9.389901e-001,0.000000e+000,,,,,,,,,,,,,,32,1,4.000000e+000,2.632141e-003,0.000000e+000,0,,0,
1524027421.665,,0.000000e+000,5.499971e+001,-6.618693e-006,0.000000e+000,3,9.475558e-001,0.000000e+000,,,,,,,,,,,,,,32,1,4.000000e+000,2.639771e-003,0.000000e+000,0,,0,
1524027459.605,,0.000000e+000,5.499840e+001,-6.317676e-006,0.000000e+000,3,9.322671e-001,0.000000e+000,,,,,,,,,,,,,,32,1,4.000000e+000,5.260468e-003,0.000000e+000,0,,0,
1524027497.465,,0.000000e+000,5.500103e+001,-6.266567e-006,0.000000e+000,3,9.429622e-001,0.000000e+000,,,,,,,,,,,,,,32,1,4.000000e+000,5.279541e-003,0.000000e+000,0,,0,
1524027535.305,,0.000000e+000,5.499840e+001,-6.137539e-006,0.000000e+000,3,9.439315e-001,0.000000e+000,,,,,,,,,,,,,,32,1,4.000000e+000,2.628326e-003,0.000000e+000,0,,0,
1524027573.235,,0.000000e+000,5.500103e+001,-5.967043e-006,0.000000e+000,3,9.492437e-001,0.000000e+000,,,,,,,,,,,,,,32,1,4.000000e+000,5.279541e-003,0.000000e+000,0,,0,
1524027610.675,,0.000000e+000,5.500168e+001,-5.932812e-006,0.000000e+000,3,9.499519e-001,0.000000e+000,,,,,,,,,,,,,,32,1,4.000000e+000,6.580353e-003,0.000000e+000,0,,0,
1524027649.405,,0.000000e+000,5.499577e+001,-5.780801e-006,0.000000e+000,3,9.387515e-001,0.000000e+000,,,,,,,,,,,,,,32,1,4.000000e+000,2.632141e-003,0.000000e+000,0,,0,
1524027687.675,,0.000000e+000,5.499445e+001,-5.683166e-006,0.000000e+000,3,9.388751e-001,0.000000e+000,,,,,,,,,,,,,,32,1,4.000000e+000,2.628326e-003,0.000000e+000,0,,0,
1524027724.985,,0.000000e+000,5.499905e+001,-5.665671e-006,0.000000e+000,3,9.480980e-001,0.000000e+000,,,,,,,,,,,,,,32,1,4.000000e+000,3.948212e-003,0.000000e+000,0,,0,
1524027762.146,,0.000000e+000,5.499972e+001,-5.500287e-006,0.000000e+000,3,9.465637e-001,0.000000e+000,,,,,,,,,,,,,,32,1,4.000000e+000,7.900238e-003,0.000000e+000,0,,0,
1524027799.716,,0.000000e+000,5.500037e+001,-5.382886e-006,0.000000e+000,3,9.344039e-001,0.000000e+000,,,,,,,,,,,,,,32,1,4.000000e+000,3.959656e-003,0.000000e+000,0,,0,
1524027837.756,,0.000000e+000,5.499775e+001,-5.281629e-006,0.000000e+000,3,9.397528e-001,0.000000e+000,,,,,,,,,,,,,,32,1,4.000000e+000,9.208679e-003,0.000000e+000,0,,0,
1524027875.276,,0.000000e+000,5.500234e+001,-5.227266e-006,0.000000e+000,3,9.266322e-001,0.000000e+000,,,,,,,,,,,,,,32,1,4.000000e+000,1.314926e-002,0.000000e+000,0,,0,
1524027913.946,,0.000000e+000,5.499971e+001,-5.157038e-006,0.000000e+000,3,9.268678e-001,0.000000e+000,,,,,,,,,,,,,,32,1,4.000000e+000,0.000000e+000,0.000000e+000,0,,0,
1524027951.836,,0.000000e+000,5.500037e+001,-5.026315e-006,0.000000e+000,3,9.335063e-001,0.000000e+000,,,,,,,,,,,,,,32,1,4.000000e+000,9.201050e-003,0.000000e+000,0,,0,
1524027989.756,,0.000000e+000,5.500037e+001,-5.024054e-006,0.000000e+000,3,9.277772e-001,0.000000e+000,,,,,,,,,,,,,,32,1,4.000000e+000,3.959656e-003,0.000000e+000,0,,0,
1524028028.266,,0.000000e+000,5.499773e+001,-4.913608e-006,0.000000e+000,3,9.284277e-001,0.000000e+000,,,,,,,,,,,,,,32,1,4.000000e+000,1.308441e-003,0.000000e+000,0,,0,
1524028066.106,,0.000000e+000,5.499905e+001,-4.787903e-006,0.000000e+000,3,9.362106e-001,0.000000e+000,,,,,,,,,,,,,,32,1,4.000000e+000,1.972961e-002,0.000000e+000,0,,0,
1524028103.866,,0.000000e+000,5.499577e+001,-4.782908e-006,0.000000e+000,3,9.237511e-001,0.000000e+000,,,,,,,,,,,,,,32,1,4.000000e+000,7.888794e-003,0.000000e+000,0,,0,
1524028141.706,,0.000000e+000,5.499971e+001,-4.692174e-006,0.000000e+000,3,9.324475e-001,0.000000e+000,,,,,,,,,,,,,,32,1,4.000000e+000,2.639771e-003,0.000000e+000,0,,0,
1524028179.326,,0.000000e+000,5.500235e+001,-4.616661e-006,0.000000e+000,3,9.269090e-001,0.000000e+000,,,,,,,,,,,,,,32,1,4.000000e+000,0.000000e+000,0.000000e+000,0,,0,
1524028217.316,,0.000000e+000,5.499708e+001,-4.546581e-006,0.000000e+000,3,9.271820e-001,0.000000e+000,,,,,,,,,,,,,,32,1,4.000000e+000,1.578140e-002,0.000000e+000,0,,0,
1524028254.886,,0.000000e+000,5.499972e+001,-4.499766e-006,0.000000e+000,3,9.198406e-001,0.000000e+000,,,,,,,,,,,,,,32,1,4.000000e+000,5.268097e-003,0.000000e+000,0,,0,
1524028292.896,,0.000000e+000,5.499577e+001,-4.397176e-006,0.000000e+000,3,9.298118e-001,0.000000e+000,,,,,,,,,,,,,,32,1,4.000000e+000,2.632141e-003,0.000000e+000,0,,0,
1524028330.726,,0.000000e+000,5.499840e+001,-4.405562e-006,0.000000e+000,3,9.086670e-001,0.000000e+000,,,,,,,,,,,,,,32,1,4.000000e+000,5.260468e-003,0.000000e+000,0,,0,
1524028368.186,,0.000000e+000,5.499840e+001,-4.319845e-006,0.000000e+000,3,9.039964e-001,0.000000e+000,,,,,,,,,,,,,,32,1,4.000000e+000,5.260468e-003,0.000000e+000,0,,0,
1524028405.866,,0.000000e+000,5.500235e+001,-4.340286e-006,0.000000e+000,3,9.079624e-001,0.000000e+000,,,,,,,,,,,,,,32,1,4.000000e+000,2.639771e-003,0.000000e+000,0,,0,
1524028443.436,,0.000000e+000,5.500431e+001,-4.216428e-006,0.000000e+000,3,9.187769e-001,0.000000e+000,,,,,,,,,,,,,,32,1,4.000000e+000,1.184845e-002,0.000000e+000,0,,0,
1524028481.597,,0.000000e+000,5.500235e+001,-4.187699e-006,0.000000e+000,3,9.051293e-001,0.000000e+000,,,,,,,,,,,,,,32,1,4.000000e+000,2.639771e-003,0.000000e+000,0,,0,
1524028519.357,,0.000000e+000,5.500366e+001,-4.122546e-006,0.000000e+000,3,9.061658e-001,0.000000e+000,,,,,,,,,,,,,,32,1,4.000000e+000,2.620697e-003,0.000000e+000,0,,0,
1524028557.977,,0.000000e+000,5.499708e+001,-4.027040e-006,0.000000e+000,3,9.258867e-001,0.000000e+000,,,,,,,,,,,,,,32,1,4.000000e+000,2.620697e-003,0.000000e+000,0,,0,
1524028596.037,,0.000000e+000,5.499906e+001,-4.028460e-006,0.000000e+000,3,9.081433e-001,0.000000e+000,,,,,,,,,,,,,,32,1,4.000000e+000,6.580353e-003,0.000000e+000,0,,0,
1524028633.947,,0.000000e+000,5.500037e+001,-3.960780e-006,0.000000e+000,3,9.146243e-001,0.000000e+000,,,,,,,,,,,,,,32,1,4.000000e+000,3.959656e-003,0.000000e+000,0,,0,
1524028671.877,,0.000000e+000,5.499643e+001,-3.901093e-006,0.000000e+000,3,9.070325e-001,0.000000e+000,,,,,,,,,,,,,,32,1,4.000000e+000,1.184082e-002,0.000000e+000,0,,0,
1524028709.987,,0.000000e+000,5.499708e+001,-3.906036e-006,0.000000e+000,3,9.053192e-001,0.000000e+000,,,,,,,,,,,,,,32,1,4.000000e+000,5.260468e-003,0.000000e+000,0,,0,
1524028747.387,,0.000000e+000,5.499971e+001,-3.855911e-006,0.000000e+000,3,9.110194e-001,0.000000e+000,,,,,,,,,,,,,,32,1,4.000000e+000,2.639771e-003,0.000000e+000,0,,0,
1524028785.707,,0.000000e+000,5.500498e+001,-3.749835e-006,0.000000e+000,3,9.009563e-001,0.000000e+000,,,,,,,,,,,,,,32,1,4.000000e+000,2.620697e-003,0.000000e+000,0,,0,
1524028824.077,,0.000000e+000,5.500366e+001,-3.766428e-006,0.000000e+000,3,8.923398e-001,0.000000e+000,,,,,,,,,,,,,,32,1,4.000000e+000,1.842117e-002,0.000000e+000,0,,0,
1524028862.157,,0.000000e+000,5.500234e+001,-3.753032e-006,0.000000e+000,3,8.970158e-001,0.000000e+000,,,,,,,,,,,,,,32,1,4.000000e+000,7.900238e-003,0.000000e+000,0,,0,
1524028900.207,,0.000000e+000,5.499643e+001,-3.662272e-006,0.000000e+000,3,9.043553e-001,0.000000e+000,,,,,,,,,,,,,,32,1,4.000000e+000,1.312256e-003,0.000000e+000,0,,0,
1524028938.367,,0.000000e+000,5.500103e+001,-3.648161e-006,0.000000e+000,3,8.842151e-001,0.000000e+000,,,,,,,,,,,,,,32,1,4.000000e+000,0.000000e+000,0.000000e+000,0,,0,
1524028977.057,,0.000000e+000,5.499971e+001,-3.755076e-006,0.000000e+000,3,8.979614e-001,0.000000e+000,,,,,,,,,,,,,,32,1,4.000000e+000,0.000000e+000,0.000000e+000,0,,0,
1524029014.957,,0.000000e+000,5.500037e+001,-3.602973e-006,0.000000e+000,3,8.965680e-001,0.000000e+000,,,,,,,,,,,,,,32,1,4.000000e+000,1.319885e-003,0.000000e+000,0,,0,
1524029053.597,,0.000000e+000,5.499773e+001,-3.531645e-006,0.000000e+000,3,8.957588e-001,0.000000e+000,,,,,,,,,,,,,,32,1,4.000000e+000,1.308441e-003,0.000000e+000,0,,0,
1524029090.707,,0.000000e+000,5.499839e+001,-3.592453e-006,0.000000e+000,3,8.989365e-001,0.000000e+000,,,,,,,,,,,,,,32,1,4.000000e+000,0.000000e+000,0.000000e+000,0,,0,
1524029128.617,,0.000000e+000,5.500169e+001,-3.481472e-006,0.000000e+000,3,9.040405e-001,0.000000e+000,,,,,,,,,,,,,,32,1,4.000000e+000,3.959656e-003,0.000000e+000,0,,0,
1524029166.268,,0.000000e+000,5.499643e+001,-3.481599e-006,0.000000e+000,3,8.874413e-001,0.000000e+000,,,,,,,,,,,,,,32,1,4.000000e+000,1.312256e-003,0.000000e+000,0,,0,
1524029203.478,,0.000000e+000,5.499906e+001,-3.493973e-006,0.000000e+000,3,8.829340e-001,0.000000e+000,,,,,,,,,,,,,,32,1,4.000000e+000,9.220123e-003,0.000000e+000,0,,0,
1524029241.448,,0.000000e+000,5.499577e+001,-3.346378e-006,0.000000e+000,3,8.756683e-001,0.000000e+000,,,,,,,,,,,,,,32,1,4.000000e+000,0.000000e+000,0.000000e+000,0,,0,
1524029279.078,,0.000000e+000,5.500103e+001,-3.410090e-006,0.000000e+000,3,8.714521e-001,0.000000e+000,,,,,,,,,,,,,,32,1,4.000000e+000,0.000000e+000,0.000000e+000,0,,0,
1524029317.048,,0.000000e+000,5.500103e+001,-3.383221e-006,0.000000e+000,3,8.832126e-001,0.000000e+000,,,,,,,,,,,,,,32,1,4.000000e+000,7.888794e-003,0.000000e+000,0,,0,
1524029354.648,,0.000000e+000,5.500037e+001,-3.377877e-006,0.000000e+000,3,8.817009e-001,0.000000e+000,,,,,,,,,,,,,,32,1,4.000000e+000,1.184082e-002,0.000000e+000,0,,0,
1524029392.648,,0.000000e+000,5.500037e+001,-3.248853e-006,0.000000e+000,3,8.853664e-001,0.000000e+000,,,,,,,,,,,,,,32,1,4.000000e+000,9.201050e-003,0.000000e+000,0,,0,
1524029430.178,,0.000000e+000,5.500169e+001,-3.297714e-006,0.000000e+000,3,8.729682e-001,0.000000e+000,,,,,,,,,,,,,,32,1,4.000000e+000,9.208679e-003,0.000000e+000,0,,0,
1524029468.198,,0.000000e+000,5.499773e+001,-3.239945e-006,0.000000e+000,3,8.830581e-001,0.000000e+000,,,,,,,,,,,,,,32,1,4.000000e+000,1.308441e-003,0.000000e+000,0,,0,
1524029505.778,,0.000000e+000,5.500366e+001,-3.238312e-006,0.000000e+000,3,8.652886e-001,0.000000e+000,,,,,,,,,,,,,,32,1,4.000000e+000,2.620697e-003,0.000000e+000,0,,0,
1524029543.778,,0.000000e+000,5.500498e+001,-3.182683e-006,0.000000e+000,3,8.696089e-001,0.000000e+000,,,,,,,,,,,,,,32,1,4.000000e+000,2.620697e-003,0.000000e+000,0,,0,
1524029581.398,,0.000000e+000,5.499905e+001,-3.176473e-006,0.000000e+000,3,8.736144e-001,0.000000e+000,,,,,,,,,,,,,,32,1,4.000000e+000,3.948212e-003,0.000000e+000,0,,0,
1524029619.358,,0.000000e+000,5.499642e+001,-3.092867e-006,0.000000e+000,3,8.810037e-001,0.000000e+000,,,,,,,,,,,,,,32,1,4.000000e+000,3.940582e-003,0.000000e+000,0,,0,
1524029657.178,,0.000000e+000,5.499511e+001,-3.072754e-006,0.000000e+000,3,8.614099e-001,0.000000e+000,,,,,,,,,,,,,,32,1,4.000000e+000,1.184082e-002,0.000000e+000,0,,0,
1524029695.158,,0.000000e+000,5.499840e+001,-3.124722e-006,0.000000e+000,3,8.632977e-001,0.000000e+000,,,,,,,,,,,,,,32,1,4.000000e+000,2.628326e-003,0.000000e+000,0,,0,
1524029732.708,,0.000000e+000,5.500037e+001,-3.075211e-006,0.000000e+000,3,8.676497e-001,0.000000e+000,,,,,,,,,,,,,,32,1,4.000000e+000,1.319885e-003,0.000000e+000,0,,0,
1524029772.048,,0.000000e+000,5.499314e+001,-3.014872e-006,0.000000e+000,3,8.738220e-001,0.000000e+000,,,,,,,,,,,,,,32,1,4.000000e+000,1.578140e-002,0.000000e+000,0,,0,
1524029809.518,,0.000000e+000,5.499379e+001,-3.109130e-006,0.000000e+000,3,8.494220e-001,0.000000e+000,,,,,,,,,,,,,,32,1,4.000000e+000,9.201050e-003,0.000000e+000,0,,0,
1524029847.098,,0.000000e+000,5.499905e+001,-3.037131e-006,0.000000e+000,3,8.616551e-001,0.000000e+000,,,,,,,,,,,,,,32,1,4.000000e+000,3.948212e-003,0.000000e+000,0,,0,
1524029885.039,,0.000000e+000,5.500037e+001,-2.939689e-006,0.000000e+000,3,8.573893e-001,0.000000e+000,,,,,,,,,,,,,,32,1,4.000000e+000,9.201050e-003,0.000000e+000,0,,0,
1524029922.369,,0.000000e+000,5.500300e+001,-3.032550e-006,0.000000e+000,3,8.393062e-001,0.000000e+000,,,,,,,,,,,,,,32,1,4.000000e+000,3.940582e-003,0.000000e+000,0,,0,
1524029960.029,,0.000000e+000,5.499971e+001,-2.902851e-006,0.000000e+000,3,8.548720e-001,0.000000e+000,,,,,,,,,,,,,,32,1,4.000000e+000,2.639771e-003,0.000000e+000,0,,0,
1524029997.119,,0.000000e+000,5.499708e+001,-3.003658e-006,0.000000e+000,3,8.593605e-001,0.000000e+000,,,,,,,,,,,,,,32,1,4.000000e+000,2.620697e-003,0.000000e+000,0,,0,
1524030034.519,,0.000000e+000,5.500037e+001,-2.872586e-006,0.000000e+000,3,8.599357e-001,0.000000e+000,,,,,,,,,,,,,,32,1,4.000000e+000,3.959656e-003,0.000000e+000,0,,0,
1524030072.179,,0.000000e+000,5.499708e+001,-2.945090e-006,0.000000e+000,3,8.314729e-001,0.000000e+000,,,,,,,,,,,,,,32,1,4.000000e+000,2.620697e-003,0.000000e+000,0,,0,
1524030110.359,,0.000000e+000,5.499643e+001,-2.914203e-006,0.000000e+000,3,8.426162e-001,0.000000e+000,,,,,,,,,,,,,,32,1,4.000000e+000,9.208679e-003,0.000000e+000,0,,0,
1524030148.409,,0.000000e+000,5.499971e+001,-2.866565e-006,0.000000e+000,3,8.514324e-001,0.000000e+000,,,,,,,,,,,,,,32,1,4.000000e+000,2.639771e-003,0.000000e+000,0,,0,
1524030186.139,,0.000000e+000,5.499773e+001,-2.876543e-006,0.000000e+000,3,8.314850e-001,0.000000e+000,,,,,,,,,,,,,,32,1,4.000000e+000,1.308441e-003,0.000000e+000,0,,0,
1524030224.029,,0.000000e+000,5.500103e+001,-2.823884e-006,0.000000e+000,3,8.413169e-001,0.000000e+000,,,,,,,,,,,,,,32,1,4.000000e+000,5.279541e-003,0.000000e+000,0,,0,
1524030261.619,,0.000000e+000,5.499708e+001,-2.853460e-006,0.000000e+000,3,8.240960e-001,0.000000e+000,,,,,,,,,,,,,,32,1,4.000000e+000,0.000000e+000,0.000000e+000,0,,0,
1524030299.649,,0.000000e+000,5.500432e+001,-2.779829e-006,0.000000e+000,3,8.361526e-001,0.000000e+000,,,,,,,,,,,,,,32,1,4.000000e+000,1.300812e-003,0.000000e+000,0,,0,
1524030337.249,,0.000000e+000,5.499511e+001,-2.862734e-006,0.000000e+000,3,8.303263e-001,0.000000e+000,,,,,,,,,,,,,,32,1,4.000000e+000,9.201050e-003,0.000000e+000,0,,0,
1524030375.719,,0.000000e+000,5.499445e+001,-2.891570e-006,0.000000e+000,3,8.356180e-001,0.000000e+000,,,,,,,,,,,,,,32,1,4.000000e+000,5.260468e-003,0.000000e+000,0,,0,
1524030413.539,,0.000000e+000,5.499905e+001,-2.736997e-006,0.000000e+000,3,8.392584e-001,0.000000e+000,,,,,,,,,,,,,,32,1,4.000000e+000,3.948212e-003,0.000000e+000,0,,0,
1524030451.139,,0.000000e+000,5.499906e+001,-2.814055e-006,0.000000e+000,3,8.194541e-001,0.000000e+000,,,,,,,,,,,,,,32,1,4.000000e+000,6.580353e-003,0.000000e+000,0,,0,
1524030489.289,,0.000000e+000,5.500037e+001,-2.770309e-006,0.000000e+000,3,8.325429e-001,0.000000e+000,,,,,,,,,,,,,,32,1,4.000000e+000,6.587982e-003,0.000000e+000,0,,0,
1524030528.169,,0.000000e+000,5.499972e+001,-2.752921e-006,0.000000e+000,3,8.159868e-001,0.000000e+000,,,,,,,,,,,,,,32,1,4.000000e+000,1.314926e-002,0.000000e+000,0,,0,
1524030565.909,,0.000000e+000,5.500234e+001,-2.806764e-006,0.000000e+000,3,8.012905e-001,0.000000e+000,,,,,,,,,,,,,,32,1,4.000000e+000,5.260468e-003,0.000000e+000,0,,0,
1524030604.610,,0.000000e+000,5.499839e+001,-2.784601e-006,0.000000e+000,3,7.997804e-001,0.000000e+000,,,,,,,,,,,,,,32,1,4.000000e+000,0.000000e+000,0.000000e+000,0,,0,
1524030642.280,,0.000000e+000,5.499774e+001,-2.719721e-006,0.000000e+000,3,8.059404e-001,0.000000e+000,,,,,,,,,,,,,,32,1,4.000000e+000,6.580353e-003,0.000000e+000,0,,0,
1524030679.610,,0.000000e+000,5.500037e+001,-2.770143e-006,0.000000e+000,3,8.086733e-001,0.000000e+000,,,,,,,,,,,,,,32,1,4.000000e+000,1.319885e-003,0.000000e+000,0,,0,
1524030717.540,,0.000000e+000,5.499577e+001,-2.682079e-006,0.000000e+000,3,8.214651e-001,0.000000e+000,,,,,,,,,,,,,,32,1,4.000000e+000,2.632141e-003,0.000000e+000,0,,0,
1524030754.890,,0.000000e+000,5.499840e+001,-2.778809e-006,0.000000e+000,3,7.886022e-001,0.000000e+000,,,,,,,,,,,,,,32,1,4.000000e+000,5.260468e-003,0.000000e+000,0,,0,
1524030793.090,,0.000000e+000,5.499774e+001,-2.767277e-006,0.000000e+000,3,8.103671e-001,0.000000e+000,,,,,,,,,,,,,,32,1,4.000000e+000,3.940582e-003,0.000000e+000,0,,0,
1524030831.250,,0.000000e+000,5.499905e+001,-2.625535e-006,0.000000e+000,3,8.175173e-001,0.000000e+000,,,,,,,,,,,,,,32,1,4.000000e+000,3.948212e-003,0.000000e+000,0,,0,
1524030868.580,,0.000000e+000,5.499248e+001,-2.755668e-006,0.000000e+000,3,7.786607e-001,0.000000e+000,,,,,,,,,,,,,,32,1,4.000000e+000,1.319885e-003,0.000000e+000,0,,0,
1524030906.900,,0.000000e+000,5.500563e+001,-2.760392e-006,0.000000e+000,3,8.146371e-001,0.000000e+000,,,,,,,,,,,,,,32,1,4.000000e+000,9.208679e-003,0.000000e+000,0,,0,
1524030946.110,,0.000000e+000,5.500169e+001,-2.814739e-006,0.000000e+000,3,7.276675e-001,0.000000e+000,,,,,,,,,,,,,,32,1,4.000000e+000,1.319885e-003,0.000000e+000,0,,0,
1524030984.990,,0.000000e+000,5.499643e+001,-2.628905e-006,0.000000e+000,3,8.017145e-001,0.000000e+000,,,,,,,,,,,,,,32,1,4.000000e+000,1.312256e-003,0.000000e+000,0,,0,
1524031024.522,,0.000000e+000,5.500431e+001,-8.370719e-007,0.000000e+000,2,0.000000e+000,0.000000e+000,,,,,,,,,,,,,,32,1,4.000000e+000,1.184845e-002,0.000000e+000,0,,0,
1524031067.368,,0.000000e+000,5.499840e+001,-7.812741e-007,0.000000e+000,2,0.000000e+000,0.000000e+000,,,,,,,,,,,,,,32,1,4.000000e+000,2.628326e-003,0.000000e+000,0,,0,
1524031110.704,,0.000000e+000,5.499249e+001,-7.300701e-007,0.000000e+000,2,0.000000e+000,0.000000e+000,,,,,,,,,,,,,,32,1,4.000000e+000,1.972961e-002,0.000000e+000,0,,0,
1524031152.450,,0.000000e+000,5.499905e+001,-6.755538e-007,0.000000e+000,2,0.000000e+000,0.000000e+000,,,,,,,,,,,,,,32,1,4.000000e+000,3.948212e-003,0.000000e+000,0,,0,
1524031195.136,,0.000000e+000,5.499445e+001,-6.644223e-007,0.000000e+000,2,0.000000e+000,0.000000e+000,,,,,,,,,,,,,,32,1,4.000000e+000,5.260468e-003,0.000000e+000,0,,0,
1524031238.352,,0.000000e+000,5.500366e+001,-6.357035e-007,0.000000e+000,2,0.000000e+000,0.000000e+000,,,,,,,,,,,,,,32,1,4.000000e+000,2.620697e-003,0.000000e+000,0,,0,
1524031280.418,,0.000000e+000,5.500103e+001,-5.969821e-007,0.000000e+000,2,0.000000e+000,0.000000e+000,,,,,,,,,,,,,,32,1,4.000000e+000,5.279541e-003,0.000000e+000,0,,0,
1524031323.835,,0.000000e+000,5.500301e+001,-6.256163e-007,0.000000e+000,2,0.000000e+000,0.000000e+000,,,,,,,,,,,,,,32,1,4.000000e+000,1.319885e-003,0.000000e+000,0,,0,
1524031366.021,,0.000000e+000,5.499511e+001,-5.671253e-007,0.000000e+000,2,0.000000e+000,0.000000e+000,,,,,,,,,,,,,,32,1,4.000000e+000,3.940582e-003,0.000000e+000,0,,0,
1524031408.667,,0.000000e+000,5.499511e+001,-5.603995e-007,0.000000e+000,2,0.000000e+000,0.000000e+000,,,,,,,,,,,,,,32,1,4.000000e+000,1.319885e-003,0.000000e+000,0,,0,
1524031450.963,,0.000000e+000,5.499183e+001,-5.168512e-007,0.000000e+000,2,0.000000e+000,0.000000e+000,,,,,,,,,,,,,,32,1,4.000000e+000,2.632141e-003,0.000000e+000,0,,0,
1524031493.679,,0.000000e+000,5.499774e+001,-4.984965e-007,0.000000e+000,2,0.000000e+000,0.000000e+000,,,,,,,,,,,,,,32,1,4.000000e+000,3.940582e-003,0.000000e+000,0,,0,
1524031536.665,,0.000000e+000,5.499577e+001,-4.781778e-007,0.000000e+000,2,0.000000e+000,0.000000e+000,,,,,,,,,,,,,,32,1,4.000000e+000,7.888794e-003,0.000000e+000,0,,0,
1524031578.161,,0.000000e+000,5.499774e+001,-3.701061e-007,0.000000e+000,2,0.000000e+000,0.000000e+000,,,,,,,,,,,,,,32,1,4.000000e+000,3.940582e-003,0.000000e+000,0,,0,
1524031621.296,,0.000000e+000,5.499774e+001,-4.084866e-007,0.000000e+000,2,0.000000e+000,0.000000e+000,,,,,,,,,,,,,,32,1,4.000000e+000,3.940582e-003,0.000000e+000,0,,0,
1524031663.092,,0.000000e+000,5.500300e+001,-4.392051e-007,0.000000e+000,2,0.000000e+000,0.000000e+000,,,,,,,,,,,,,,32,1,4.000000e+000,3.940582e-003,0.000000e+000,0,,0,
1524031704.168,,0.000000e+000,5.500235e+001,-4.269729e-007,0.000000e+000,2,0.000000e+000,0.000000e+000,,,,,,,,,,,,,,32,1,4.000000e+000,2.639771e-003,0.000000e+000,0,,0,
1524031746.174,,0.000000e+000,5.499971e+001,-3.689923e-007,0.000000e+000,2,0.000000e+000,0.000000e+000,,,,,,,,,,,,,,32,1,4.000000e+000,1.052094e-002,0.000000e+000,0,,0,
1524031786.598,,0.000000e+000,5.500037e+001,-3.509970e-007,0.000000e+000,2,0.000000e+000,0.000000e+000,,,,,,,,,,,,,,32,1,4.000000e+000,3.959656e-003,0.000000e+000,0,,0,
1524031825.130,,0.000000e+000,5.500103e+001,2.728853e-006,0.000000e+000,3,6.598427e-001,0.000000e+000,,,,,,,,,,,,,,32,1,4.000000e+000,5.279541e-003,0.000000e+000,0,,0,
1524031864.162,,0.000000e+000,5.499972e+001,2.721391e-006,0.000000e+000,3,6.587240e-001,0.000000e+000,,,,,,,,,,,,,,32,1,4.000000e+000,5.268097e-003,0.000000e+000,0,,0,
1524031906.828,,0.000000e+000,5.499972e+001,-3.416599e-007,0.000000e+000,2,0.000000e+000,0.000000e+000,,,,,,,,,,,,,,32,1,4.000000e+000,5.268097e-003,0.000000e+000,0,,0,
1524031945.670,,0.000000e+000,5.499774e+001,2.582529e-006,0.000000e+000,3,6.459677e-001,0.000000e+000,,,,,,,,,,,,,,32,1,4.000000e+000,3.940582e-003,0.000000e+000,0,,0,
1524031984.972,,0.000000e+000,5.500300e+001,2.562316e-006,0.000000e+000,3,6.894817e-001,0.000000e+000,,,,,,,,,,,,,,32,1,4.000000e+000,9.220123e-003,0.000000e+000,0,,0,
1524032022.583,,0.000000e+000,5.499972e+001,2.657417e-006,0.000000e+000,3,6.400895e-001,0.000000e+000,,,,,,,,,,,,,,32,1,4.000000e+000,5.268097e-003,0.000000e+000,0,,0,
1524032060.573,,0.000000e+000,5.499577e+001,2.574613e-006,0.000000e+000,3,6.457539e-001,0.000000e+000,,,,,,,,,,,,,,32,1,4.000000e+000,5.249023e-003,0.000000e+000,0,,0,
1524032098.233,,0.000000e+000,5.499511e+001,2.584247e-006,0.000000e+000,3,6.445857e-001,0.000000e+000,,,,,,,,,,,,,,32,1,4.000000e+000,3.940582e-003,0.000000e+000,0,,0,
1524032136.153,,0.000000e+000,5.500169e+001,2.574480e-006,0.000000e+000,3,6.407550e-001,0.000000e+000,,,,,,,,,,,,,,32,1,4.000000e+000,9.208679e-003,0.000000e+000,0,,0,
1524032173.543,,0.000000e+000,5.499643e+001,2.699771e-006,0.000000e+000,3,6.556312e-001,0.000000e+000,,,,,,,,,,,,,,32,1,4.000000e+000,1.448059e-002,0.000000e+000,0,,0,
1524032211.303,,0.000000e+000,5.499708e+001,2.496081e-006,0.000000e+000,3,6.487176e-001,0.000000e+000,,,,,,,,,,,,,,32,1,4.000000e+000,0.000000e+000,0.000000e+000,0,,0,
1524032249.843,,0.000000e+000,5.499642e+001,2.546476e-006,0.000000e+000,3,6.656047e-001,0.000000e+000,,,,,,,,,,,,,,32,1,4.000000e+000,3.940582e-003,0.000000e+000,0,,0,
1524032287.163,,0.000000e+000,5.500037e+001,2.602647e-006,0.000000e+000,3,6.477502e-001,0.000000e+000,,,,,,,,,,,,,,32,1,4.000000e+000,1.319885e-003,0.000000e+000,0,,0,
1524032324.573,,0.000000e+000,5.499511e+001,2.532936e-006,0.000000e+000,3,6.627043e-001,0.000000e+000,,,,,,,,,,,,,,32,1,4.000000e+000,1.319885e-003,0.000000e+000,0,,0,
1524032362.253,,0.000000e+000,5.500037e+001,2.606007e-006,0.000000e+000,3,6.446115e-001,0.000000e+000,,,,,,,,,,,,,,32,1,4.000000e+000,6.587982e-003,0.000000e+000,0,,0,
1524032400.083,,0.000000e+000,5.500103e+001,2.454785e-006,0.000000e+000,3,6.360007e-001,0.000000e+000,,,,,,,,,,,,,,32,1,4.000000e+000,2.639771e-003,0.000000e+000,0,,0,
1524032438.393,,0.000000e+000,5.499905e+001,2.534453e-006,0.000000e+000,3,6.880798e-001,0.000000e+000,,,,,,,,,,,,,,32,1,4.000000e+000,1.319885e-003,0.000000e+000,0,,0,
1524032478.113,,0.000000e+000,5.499511e+001,2.475840e-006,0.000000e+000,3,6.732199e-001,0.000000e+000,,,,,,,,,,,,,,32,1,4.000000e+000,3.940582e-003,0.000000e+000,0,,0,
1524032515.623,,0.000000e+000,5.500169e+001,2.530612e-006,0.000000e+000,3,6.446787e-001,0.000000e+000,,,,,,,,,,,,,,32,1,4.000000e+000,1.319885e-003,0.000000e+000,0,,0,
1524032554.603,,0.000000e+000,5.499642e+001,2.460840e-006,0.000000e+000,3,6.316904e-001,0.000000e+000,,,,,,,,,,,,,,32,1,4.000000e+000,3.940582e-003,0.000000e+000,0,,0,
1524032596.137,,0.000000e+000,5.500169e+001,-7.676147e-008,0.000000e+000,2,0.000000e+000,0.000000e+000,,,,,,,,,,,,,,32,1,4.000000e+000,1.319885e-003,0.000000e+000,0,,0,
1524032637.111,,0.000000e+000,5.500169e+001,-3.779196e-008,0.000000e+000,2,0.000000e+000,0.000000e+000,,,,,,,,,,,,,,32,1,4.000000e+000,3.959656e-003,0.000000e+000,0,,0,
1524032675.433,,0.000000e+000,5.500037e+001,2.448085e-006,0.000000e+000,3,6.785653e-001,0.000000e+000,,,,,,,,,,,,,,32,1,4.000000e+000,9.201050e-003,0.000000e+000,0,,0,
1524032714.775,,0.000000e+000,5.500168e+001,2.468240e-006,0.000000e+000,3,6.458702e-001,0.000000e+000,,,,,,,,,,,,,,32,1,4.000000e+000,6.580353e-003,0.000000e+000,0,,0,
1524032754.148,,0.000000e+000,5.499971e+001,-6.061477e-008,0.000000e+000,2,0.000000e+000,0.000000e+000,,,,,,,,,,,,,,32,1,4.000000e+000,2.639771e-003,0.000000e+000,0,,0,
1524032797.824,,0.000000e+000,5.499906e+001,7.882542e-008,0.000000e+000,2,0.000000e+000,0.000000e+000,,,,,,,,,,,,,,32,1,4.000000e+000,9.220123e-003,0.000000e+000,0,,0,
1524032837.316,,0.000000e+000,5.500366e+001,-2.643668e-006,0.000000e+000,3,7.193037e-001,0.000000e+000,,,,,,,,,,,,,,32,1,4.000000e+000,1.578140e-002,0.000000e+000,0,,0,
1524032877.840,,0.000000e+000,5.499709e+001,-2.706487e-006,0.000000e+000,3,7.305942e-001,0.000000e+000,,,,,,,,,,,,,,32,1,4.000000e+000,7.888794e-003,0.000000e+000,0,,0,
1524032917.602,,0.000000e+000,5.499642e+001,3.978113e-008,0.000000e+000,2,0.000000e+000,0.000000e+000,,,,,,,,,,,,,,32,1,4.000000e+000,3.940582e-003,0.000000e+000,0,,0,
1524032957.244,,0.000000e+000,5.499971e+001,6.645035e-008,0.000000e+000,2,0.000000e+000,0.000000e+000,,,,,,,,,,,,,,32,1,4.000000e+000,2.639771e-003,0.000000e+000,0,,0,
1524032995.616,,0.000000e+000,5.500103e+001,-2.718399e-006,0.000000e+000,3,7.254640e-001,0.000000e+000,,,,,,,,,,,,,,32,1,4.000000e+000,2.639771e-003,0.000000e+000,0,,0,
1524033034.978,,0.000000e+000,5.499643e+001,-2.725123e-006,0.000000e+000,3,7.256406e-001,0.000000e+000,,,,,,,,,,,,,,32,1,4.000000e+000,1.184082e-002,0.000000e+000,0,,0,
1524033072.828,,0.000000e+000,5.500432e+001,-2.593267e-006,0.000000e+000,3,7.383626e-001,0.000000e+000,,,,,,,,,,,,,,32,1,4.000000e+000,3.940582e-003,0.000000e+000,0,,0,
1524033112.830,,0.000000e+000,5.499773e+001,6.605541e-008,0.000000e+000,2,0.000000e+000,0.000000e+000,,,,,,,,,,,,,,32,1,4.000000e+000,1.308441e-003,0.000000e+000,0,,0,
1524033150.540,,0.000000e+000,5.500301e+001,-2.421672e-006,0.000000e+000,3,6.970989e-001,0.000000e+000,,,,,,,,,,,,,,32,1,4.000000e+000,1.319885e-003,0.000000e+000,0,,0,
1524033189.080,,0.000000e+000,5.499773e+001,-2.726912e-006,0.000000e+000,3,7.248227e-001,0.000000e+000,,,,,,,,,,,,,,32,1,4.000000e+000,1.308441e-003,0.000000e+000,0,,0,
1524033226.590,,0.000000e+000,5.499380e+001,-2.541320e-006,0.000000e+000,3,7.444065e-001,0.000000e+000,,,,,,,,,,,,,,32,1,4.000000e+000,1.182938e-002,0.000000e+000,0,,0,
1524033265.240,,0.000000e+000,5.499971e+001,-2.468157e-006,0.000000e+000,3,7.096234e-001,0.000000e+000,,,,,,,,,,,,,,32,1,4.000000e+000,2.639771e-003,0.000000e+000,0,,0,
1524033303.000,,0.000000e+000,5.499511e+001,-2.612512e-006,0.000000e+000,3,7.209033e-001,0.000000e+000,,,,,,,,,,,,,,32,1,4.000000e+000,1.319885e-003,0.000000e+000,0,,0,
1524033341.010,,0.000000e+000,5.499840e+001,-2.686230e-006,0.000000e+000,3,7.121549e-001,0.000000e+000,,,,,,,,,,,,,,32,1,4.000000e+000,5.260468e-003,0.000000e+000,0,,0,
1524033379.410,,0.000000e+000,5.500037e+001,-2.668462e-006,0.000000e+000,3,7.584145e-001,0.000000e+000,,,,,,,,,,,,,,32,1,4.000000e+000,9.201050e-003,0.000000e+000,0,,0,
1524033417.620,,0.000000e+000,5.499709e+001,-2.454599e-006,0.000000e+000,3,6.881986e-001,0.000000e+000,,,,,,,,,,,,,,32,1,4.000000e+000,7.888794e-003,0.000000e+000,0,,0,
1524033455.571,,0.000000e+000,5.500037e+001,-2.685295e-006,0.000000e+000,3,7.238935e-001,0.000000e+000,,,,,,,,,,,,,,32,1,4.000000e+000,6.587982e-003,0.000000e+000,0,,0,
1524033494.001,,0.000000e+000,5.499642e+001,-2.623145e-006,0.000000e+000,3,7.341084e-001,0.000000e+000,,,,,,,,,,,,,,32,1,4.000000e+000,3.940582e-003,0.000000e+000,0,,0,
1524033530.841,,0.000000e+000,5.499773e+001,-2.720855e-006,0.000000e+000,3,7.128518e-001,0.000000e+000,,,,,,,,,,,,,,32,1,4.000000e+000,1.308441e-003,0.000000e+000,0,,0,
1524033568.311,,0.000000e+000,5.499774e+001,-2.578503e-006,0.000000e+000,3,7.196735e-001,0.000000e+000,,,,,,,,,,,,,,32,1,4.000000e+000,1.446152e-002,0.000000e+000,0,,0,
1524033607.521,,0.000000e+000,5.500037e+001,-2.603317e-006,0.000000e+000,3,7.312188e-001,0.000000e+000,,,,,,,,,,,,,,32,1,4.000000e+000,1.446915e-002,0.000000e+000,0,,0,
1524033646.663,,0.000000e+000,5.499643e+001,3.157414e-007,0.000000e+000,2,0.000000e+000,0.000000e+000,,,,,,,,,,,,,,32,1,4.000000e+000,1.312256e-003,0.000000e+000,0,,0,
1524033689.339,,0.000000e+000,5.499840e+001,3.473270e-007,0.000000e+000,2,0.000000e+000,0.000000e+000,,,,,,,,,,,,,,32,1,4.000000e+000,2.628326e-003,0.000000e+000,0,,0,
1524033732.435,,0.000000e+000,5.499905e+001,3.473899e-007,0.000000e+000,2,0.000000e+000,0.000000e+000,,,,,,,,,,,,,,32,1,4.000000e+000,1.319885e-003,0.000000e+000,0,,0,
1524033775.201,,0.000000e+000,5.499905e+001,4.258308e-007,0.000000e+000,2,0.000000e+000,0.000000e+000,,,,,,,,,,,,,,32,1,4.000000e+000,1.319885e-003,0.000000e+000,0,,0,
1524033817.237,,0.000000e+000,5.499971e+001,4.187387e-007,0.000000e+000,2,0.000000e+000,0.000000e+000,,,,,,,,,,,,,,32,1,4.000000e+000,0.000000e+000,0.000000e+000,0,,0,
1524033860.433,,0.000000e+000,5.499708e+001,4.626379e-007,0.000000e+000,2,0.000000e+000,0.000000e+000,,,,,,,,,,,,,,32,1,4.000000e+000,5.260468e-003,0.000000e+000,0,,0,
1524033901.879,,0.000000e+000,5.500103e+001,4.528283e-007,0.000000e+000,2,0.000000e+000,0.000000e+000,,,,,,,,,,,,,,32,1,4.000000e+000,2.639771e-003,0.000000e+000,0,,0,
1524033945.125,,0.000000e+000,5.500234e+001,4.065211e-007,0.000000e+000,2,0.000000e+000,0.000000e+000,,,,,,,,,,,,,,32,1,4.000000e+000,5.260468e-003,0.000000e+000,0,,0,
1524033988.271,,0.000000e+000,5.500037e+001,4.472872e-007,0.000000e+000,2,0.000000e+000,0.000000e+000,,,,,,,,,,,,,,32,1,4.000000e+000,6.587982e-003,0.000000e+000,0,,0,
1524034030.457,,0.000000e+000,5.499774e+001,4.939195e-007,0.000000e+000,2,0.000000e+000,0.000000e+000,,,,,,,,,,,,,,32,1,4.000000e+000,3.940582e-003,0.000000e+000,0,,0,
1524034073.593,,0.000000e+000,5.500367e+001,4.900508e-007,0.000000e+000,2,0.000000e+000,0.000000e+000,,,,,,,,,,,,,,32,1,4.000000e+000,0.000000e+000,0.000000e+000,0,,0,
1524034116.179,,0.000000e+000,5.499643e+001,5.161901e-007,0.000000e+000,2,0.000000e+000,0.000000e+000,,,,,,,,,,,,,,32,1,4.000000e+000,6.568909e-003,0.000000e+000,0,,0,
1524034158.296,,0.000000e+000,5.499708e+001,5.500543e-007,0.000000e+000,2,0.000000e+000,0.000000e+000,,,,,,,,,,,,,,32,1,4.000000e+000,1.578140e-002,0.000000e+000,0,,0,
1524034201.072,,0.000000e+000,5.499905e+001,5.335092e-007,0.000000e+000,2,0.000000e+000,0.000000e+000,,,,,,,,,,,,,,32,1,4.000000e+000,1.182938e-002,0.000000e+000,0,,0,
1524034243.398,,0.000000e+000,5.499511e+001,5.628979e-007,0.000000e+000,2,0.000000e+000,0.000000e+000,,,,,,,,,,,,,,32,1,4.000000e+000,9.201050e-003,0.000000e+000,0,,0,
1524034286.434,,0.000000e+000,5.499906e+001,5.634033e-007,0.000000e+000,2,0.000000e+000,0.000000e+000,,,,,,,,,,,,,,32,1,4.000000e+000,6.580353e-003,0.000000e+000,0,,0,
1524034328.540,,0.000000e+000,5.499577e+001,5.696022e-007,0.000000e+000,2,0.000000e+000,0.000000e+000,,,,,,,,,,,,,,32,1,4.000000e+000,5.249023e-003,0.000000e+000,0,,0,
1524034371.346,,0.000000e+000,5.500629e+001,5.949356e-007,0.000000e+000,2,0.000000e+000,0.000000e+000,,,,,,,,,,,,,,32,1,4.000000e+000,5.249023e-003,0.000000e+000,0,,0,
1524034413.722,,0.000000e+000,5.499313e+001,6.189518e-007,0.000000e+000,2,0.000000e+000,0.000000e+000,,,,,,,,,,,,,,32,1,4.000000e+000,1.050949e-002,0.000000e+000,0,,0,
1524034456.478,,0.000000e+000,5.499972e+001,6.573931e-007,0.000000e+000,2,0.000000e+000,0.000000e+000,,,,,,,,,,,,,,32,1,4.000000e+000,5.268097e-003,0.000000e+000,0,,0,
1524034499.974,,0.000000e+000,5.499511e+001,6.188093e-007,0.000000e+000,2,0.000000e+000,0.000000e+000,,,,,,,,,,,,,,32,1,4.000000e+000,1.319885e-003,0.000000e+000,0,,0,
1524034542.810,,0.000000e+000,5.500103e+001,6.604446e-007,0.000000e+000,2,0.000000e+000,0.000000e+000,,,,,,,,,,,,,,32,1,4.000000e+000,0.000000e+000,0.000000e+000,0,,0,
1524034585.846,,0.000000e+000,5.499971e+001,7.024499e-007,0.000000e+000,2,0.000000e+000,0.000000e+000,,,,,,,,,,,,,,32,1,4.000000e+000,2.639771e-003,0.000000e+000,0,,0,
1524034628.482,,0.000000e+000,5.499248e+001,6.493771e-007,0.000000e+000,2,0.000000e+000,0.000000e+000,,,,,,,,,,,,,,32,1,4.000000e+000,9.201050e-003,0.000000e+000,0,,0,
1524034671.028,,0.000000e+000,5.500037e+001,6.751360e-007,0.000000e+000,2,0.000000e+000,0.000000e+000,,,,,,,,,,,,,,32,1,4.000000e+000,1.319885e-003,0.000000e+000,0,,0,
1524034714.644,,0.000000e+000,5.499445e+001,7.041725e-007,0.000000e+000,2,0.000000e+000,0.000000e+000,,,,,,,,,,,,,,32,1,4.000000e+000,5.260468e-003,0.000000e+000,0,,0,
1524034754.458,,0.000000e+000,5.500037e+001,2.429610e-006,0.000000e+000,3,6.961632e-001,0.000000e+000,,,,,,,,,,,,,,32,1,4.000000e+000,1.319885e-003,0.000000e+000,0,,0,
1524034798.804,,0.000000e+000,5.499380e+001,7.199212e-007,0.000000e+000,2,0.000000e+000,0.000000e+000,,,,,,,,,,,,,,32,1,4.000000e+000,6.572723e-003,0.000000e+000,0,,0,
1524034838.798,,0.000000e+000,5.499511e+001,2.419513e-006,0.000000e+000,3,7.128308e-001,0.000000e+000,,,,,,,,,,,,,,32,1,4.000000e+000,3.940582e-003,0.000000e+000,0,,0,
1524034881.875,,0.000000e+000,5.500169e+001,7.356692e-007,0.000000e+000,2,0.000000e+000,0.000000e+000,,,,,,,,,,,,,,32,1,4.000000e+000,3.959656e-003,0.000000e+000,0,,0,
1524034921.027,,0.000000e+000,5.499709e+001,-2.128187e-006,0.000000e+000,3,3.554862e-001,0.000000e+000,,,,,,,,,,,,,,32,1,4.000000e+000,7.888794e-003,0.000000e+000,0,,0,
1524034961.611,,0.000000e+000,5.499971e+001,2.414770e-006,0.000000e+000,3,7.188724e-001,0.000000e+000,,,,,,,,,,,,,,32,1,4.000000e+000,0.000000e+000,0.000000e+000,0,,0,
1524035002.355,,0.000000e+000,5.499708e+001,2.524913e-006,0.000000e+000,3,7.118558e-001,0.000000e+000,,,,,,,,,,,,,,32,1,4.000000e+000,2.620697e-003,0.000000e+000,0,,0,
1524035043.809,,0.000000e+000,5.499313e+001,7.641961e-007,0.000000e+000,2,0.000000e+000,0.000000e+000,,,,,,,,,,,,,,32,1,4.000000e+000,7.892609e-003,0.000000e+000,0,,0,
1524035085.223,,0.000000e+000,5.499511e+001,7.734718e-007,0.000000e+000,2,0.000000e+000,0.000000e+000,,,,,,,,,,,,,,32,1,4.000000e+000,9.201050e-003,0.000000e+000,0,,0,
1524035124.535,,0.000000e+000,5.500629e+001,7.338024e-007,0.000000e+000,2,0.000000e+000,0.000000e+000,,,,,,,,,,,,,,32,1,4.000000e+000,2.639771e-003,0.000000e+000,0,,0,
1524035164.117,,0.000000e+000,5.500301e+001,7.297489e-007,0.000000e+000,2,0.000000e+000,0.000000e+000,,,,,,,,,,,,,,32,1,4.000000e+000,1.319885e-003,0.000000e+000,0,,0,
1524035203.359,,0.000000e+000,5.499971e+001,7.435613e-007,0.000000e+000,2,0.000000e+000,0.000000e+000,,,,,,,,,,,,,,32,1,4.000000e+000,0.000000e+000,0.000000e+000,0,,0,
1524035241.459,,0.000000e+000,5.500037e+001,2.528300e-006,0.000000e+000,3,7.162369e-001,0.000000e+000,,,,,,,,,,,,,,32,1,4.000000e+000,3.959656e-003,0.000000e+000,0,,0,
1524035280.381,,0.000000e+000,5.500629e+001,2.533381e-006,0.000000e+000,3,7.195700e-001,0.000000e+000,,,,,,,,,,,,,,32,1,4.000000e+000,7.888794e-003,0.000000e+000,0,,0,
1524035317.611,,0.000000e+000,5.499577e+001,2.388816e-006,0.000000e+000,3,7.399941e-001,0.000000e+000,,,,,,,,,,,,,,32,1,4.000000e+000,2.632141e-003,0.000000e+000,0,,0,
1524035358.745,,0.000000e+000,5.499972e+001,7.498104e-007,0.000000e+000,2,0.000000e+000,0.000000e+000,,,,,,,,,,,,,,32,1,4.000000e+000,1.314926e-002,0.000000e+000,0,,0,
1524035398.947,,0.000000e+000,5.500037e+001,2.413404e-006,0.000000e+000,3,7.065580e-001,0.000000e+000,,,,,,,,,,,,,,32,1,4.000000e+000,3.959656e-003,0.000000e+000,0,,0,
1524035441.371,,0.000000e+000,5.499905e+001,7.692226e-007,0.000000e+000,2,0.000000e+000,0.000000e+000,,,,,,,,,,,,,,32,1,4.000000e+000,1.319885e-003,0.000000e+000,0,,0,
1524035478.661,,0.000000e+000,5.500037e+001,2.495377e-006,0.000000e+000,3,7.322152e-001,0.000000e+000,,,,,,,,,,,,,,32,1,4.000000e+000,1.319885e-003,0.000000e+000,0,,0,
1524035515.951,,0.000000e+000,5.500366e+001,2.368989e-006,0.000000e+000,3,7.203817e-001,0.000000e+000,,,,,,,,,,,,,,32,1,4.000000e+000,2.620697e-003,0.000000e+000,0,,0,
1524035553.471,,0.000000e+000,5.499841e+001,2.437548e-006,0.000000e+000,3,7.171012e-001,0.000000e+000,,,,,,,,,,,,,,32,1,4.000000e+000,1.052856e-002,0.000000e+000,0,,0,
1524035591.482,,0.000000e+000,5.499840e+001,2.381919e-006,0.000000e+000,3,7.554604e-001,0.000000e+000,,,,,,,,,,,,,,32,1,4.000000e+000,2.628326e-003,0.000000e+000,0,,0,
1524035629.112,,0.000000e+000,5.499971e+001,2.396806e-006,0.000000e+000,3,7.165061e-001,0.000000e+000,,,,,,,,,,,,,,32,1,4.000000e+000,2.639771e-003,0.000000e+000,0,,0,
1524035667.112,,0.000000e+000,5.500301e+001,2.371875e-006,0.000000e+000,3,7.190644e-001,0.000000e+000,,,,,,,,,,,,,,32,1,4.000000e+000,1.446915e-002,0.000000e+000,0,,0,
1524035704.742,,0.000000e+000,5.499906e+001,2.393776e-006,0.000000e+000,3,7.201263e-001,0.000000e+000,,,,,,,,,,,,,,32,1,4.000000e+000,6.580353e-003,0.000000e+000,0,,0,
1524035742.722,,0.000000e+000,5.499905e+001,2.303975e-006,0.000000e+000,3,7.216929e-001,0.000000e+000,,,,,,,,,,,,,,32,1,4.000000e+000,3.948212e-003,0.000000e+000,0,,0,
1524035780.362,,0.000000e+000,5.500301e+001,2.461632e-006,0.000000e+000,3,7.241766e-001,0.000000e+000,,,,,,,,,,,,,,32,1,4.000000e+000,1.319885e-003,0.000000e+000,0,,0,
1524035818.302,,0.000000e+000,5.500037e+001,2.360329e-006,0.000000e+000,3,7.200580e-001,0.000000e+000,,,,,,,,,,,,,,32,1,4.000000e+000,9.201050e-003,0.000000e+000,0,,0,
1524035855.922,,0.000000e+000,5.499380e+001,2.403728e-006,0.000000e+000,3,7.066652e-001,0.000000e+000,,,,,,,,,,,,,,32,1,4.000000e+000,6.572723e-003,0.000000e+000,0,,0,
1524035893.942,,0.000000e+000,5.500103e+001,2.342791e-006,0.000000e+000,3,7.291729e-001,0.000000e+000,,,,,,,,,,,,,,32,1,4.000000e+000,0.000000e+000,0.000000e+000,0,,0,
1524035931.952,,0.000000e+000,5.499380e+001,2.397192e-006,0.000000e+000,3,7.402861e-001,0.000000e+000,,,,,,,,,,,,,,32,1,4.000000e+000,3.948212e-003,0.000000e+000,0,,0,
1524035970.362,,0.000000e+000,5.500497e+001,2.418612e-006,0.000000e+000,3,7.150846e-001,0.000000e+000,,,,,,,,,,,,,,32,1,4.000000e+000,0.000000e+000,0.000000e+000,0,,0,
1524036007.832,,0.000000e+000,5.500365e+001,2.338664e-006,0.000000e+000,3,7.423663e-001,0.000000e+000,,,,,,,,,,,,,,32,1,4.000000e+000,1.052856e-002,0.000000e+000,0,,0,
1524036045.392,,0.000000e+000,5.499708e+001,2.439330e-006,0.000000e+000,3,7.182776e-001,0.000000e+000,,,,,,,,,,,,,,32,1,4.000000e+000,2.620697e-003,0.000000e+000,0,,0,
1524036083.962,,0.000000e+000,5.500037e+001,2.333643e-006,0.000000e+000,3,7.387054e-001,0.000000e+000,,,,,,,,,,,,,,32,1,4.000000e+000,3.959656e-003,0.000000e+000,0,,0,
1524036120.812,,0.000000e+000,5.500497e+001,2.507377e-006,0.000000e+000,3,7.233750e-001,0.000000e+000,,,,,,,,,,,,,,32,1,4.000000e+000,7.888794e-003,0.000000e+000,0,,0,
1524036157.942,,0.000000e+000,5.499446e+001,2.355745e-006,0.000000e+000,3,7.562048e-001,0.000000e+000,,,,,,,,,,,,,,32,1,4.000000e+000,1.842117e-002,0.000000e+000,0,,0,
1524036195.722,,0.000000e+000,5.499577e+001,2.373692e-006,0.000000e+000,3,7.201383e-001,0.000000e+000,,,,,,,,,,,,,,32,1,4.000000e+000,2.632141e-003,0.000000e+000,0,,0,
1524036233.312,,0.000000e+000,5.499511e+001,2.394682e-006,0.000000e+000,3,7.498034e-001,0.000000e+000,,,,,,,,,,,,,,32,1,4.000000e+000,3.940582e-003,0.000000e+000,0,,0,
1524036271.172,,0.000000e+000,5.499511e+001,2.411775e-006,0.000000e+000,3,7.304720e-001,0.000000e+000,,,,,,,,,,,,,,32,1,4.000000e+000,6.568909e-003,0.000000e+000,0,,0,
1524036308.903,,0.000000e+000,5.500103e+001,2.402918e-006,0.000000e+000,3,7.396663e-001,0.000000e+000,,,,,,,,,,,,,,32,1,4.000000e+000,2.639771e-003,0.000000e+000,0,,0,
1524036346.243,,0.000000e+000,5.500367e+001,2.403198e-006,0.000000e+000,3,7.338814e-001,0.000000e+000,,,,,,,,,,,,,,32,1,4.000000e+000,0.000000e+000,0.000000e+000,0,,0,
1524036384.503,,0.000000e+000,5.500037e+001,2.422506e-006,0.000000e+000,3,7.350212e-001,0.000000e+000,,,,,,,,,,,,,,32,1,4.000000e+000,1.319885e-003,0.000000e+000,0,,0,
1524036422.263,,0.000000e+000,5.499642e+001,2.405872e-006,0.000000e+000,3,7.489316e-001,0.000000e+000,,,,,,,,,,,,,,32,1,4.000000e+000,3.940582e-003,0.000000e+000,0,,0,
1524036460.103,,0.000000e+000,5.500695e+001,2.405856e-006,0.000000e+000,3,7.569351e-001,0.000000e+000,,,,,,,,,,,,,,32,1,4.000000e+000,6.568909e-003,0.000000e+000,0,,0,
1524036497.873,,0.000000e+000,5.500497e+001,2.411314e-006,0.000000e+000,3,7.362088e-001,0.000000e+000,,,,,,,,,,,,,,32,1,4.000000e+000,0.000000e+000,0.000000e+000,0,,0,
1524036535.703,,0.000000e+000,5.499905e+001,2.375560e-006,0.000000e+000,3,7.519816e-001,0.000000e+000,,,,,,,,,,,,,,32,1,4.000000e+000,1.182938e-002,0.000000e+000,0,,0,
1524036573.483,,0.000000e+000,5.500497e+001,2.425092e-006,0.000000e+000,3,7.480536e-001,0.000000e+000,,,,,,,,,,,,,,32,1,4.000000e+000,1.052856e-002,0.000000e+000,0,,0,
1524036611.313,,0.000000e+000,5.499774e+001,2.454114e-006,0.000000e+000,3,7.660537e-001,0.000000e+000,,,,,,,,,,,,,,32,1,4.000000e+000,3.940582e-003,0.000000e+000,0,,0,
1524036649.023,,0.000000e+000,5.500169e+001,2.455568e-006,0.000000e+000,3,7.403231e-001,0.000000e+000,,,,,,,,,,,,,,32,1,4.000000e+000,1.184082e-002,0.000000e+000,0,,0,
1524036686.893,,0.000000e+000,5.500235e+001,2.483115e-006,0.000000e+000,3,7.618541e-001,0.000000e+000,,,,,,,,,,,,,,32,1,4.000000e+000,2.639771e-003,0.000000e+000,0,,0,
1524036724.703,,0.000000e+000,5.499511e+001,2.396677e-006,0.000000e+000,3,7.379625e-001,0.000000e+000,,,,,,,,,,,,,,32,1,4.000000e+000,1.319885e-003,0.000000e+000,0,,0,
1524036762.713,,0.000000e+000,5.500563e+001,2.469466e-006,0.000000e+000,3,7.459732e-001,0.000000e+000,,,,,,,,,,,,,,32,1,4.000000e+000,6.568909e-003,0.000000e+000,0,,0,
1524036800.343,,0.000000e+000,5.500037e+001,2.568044e-006,0.000000e+000,3,7.286877e-001,0.000000e+000,,,,,,,,,,,,,,32,1,4.000000e+000,3.959656e-003,0.000000e+000,0,,0,
1524036838.363,,0.000000e+000,5.500497e+001,2.530038e-006,0.000000e+000,3,7.693418e-001,0.000000e+000,,,,,,,,,,,,,,32,1,4.000000e+000,1.052856e-002,0.000000e+000,0,,0,
1524036875.983,,0.000000e+000,5.499708e+001,2.520782e-006,0.000000e+000,3,7.449113e-001,0.000000e+000,,,,,,,,,,,,,,32,1,4.000000e+000,5.260468e-003,0.000000e+000,0,,0,
1524036913.863,,0.000000e+000,5.499577e+001,2.429696e-006,0.000000e+000,3,7.422410e-001,0.000000e+000,,,,,,,,,,,,,,32,1,4.000000e+000,7.888794e-003,0.000000e+000,0,,0,
1524036951.003,,0.000000e+000,5.499773e+001,2.507219e-006,0.000000e+000,3,7.475861e-001,0.000000e+000,,,,,,,,,,,,,,32,1,4.000000e+000,1.308441e-003,0.000000e+000,0,,0,
1524036989.133,,0.000000e+000,5.500234e+001,2.517678e-006,0.000000e+000,3,7.455392e-001,0.000000e+000,,,,,,,,,,,,,,32,1,4.000000e+000,5.260468e-003,0.000000e+000,0,,0,
1524037027.284,,0.000000e+000,5.499905e+001,2.406292e-006,0.000000e+000,3,7.575737e-001,0.000000e+000,,,,,,,,,,,,,,32,1,4.000000e+000,3.948212e-003,0.000000e+000,0,,0,
1524037065.134,,0.000000e+000,5.499971e+001,2.591345e-006,0.000000e+000,3,7.476335e-001,0.000000e+000,,,,,,,,,,,,,,32,1,4.000000e+000,0.000000e+000,0.000000e+000,0,,0,
1524037102.874,,0.000000e+000,5.500366e+001,2.450203e-006,0.000000e+000,3,7.477505e-001,0.000000e+000,,,,,,,,,,,,,,32,1,4.000000e+000,2.620697e-003,0.000000e+000,0,,0,
1524037141.744,,0.000000e+000,5.499577e+001,2.404690e-006,0.000000e+000,3,7.602566e-001,0.000000e+000,,,,,,,,,,,,,,32,1,4.000000e+000,2.632141e-003,0.000000e+000,0,,0,
1524037179.214,,0.000000e+000,5.500301e+001,2.565417e-006,0.000000e+000,3,7.327765e-001,0.000000e+000,,,,,,,,,,,,,,32,1,4.000000e+000,1.319885e-003,0.000000e+000,0,,0,
1524037217.274,,0.000000e+000,5.499905e+001,2.455624e-006,0.000000e+000,3,7.579463e-001,0.000000e+000,,,,,,,,,,,,,,32,1,4.000000e+000,3.948212e-003,0.000000e+000,0,,0,
1524037254.434,,0.000000e+000,5.500103e+001,2.517578e-006,0.000000e+000,3,7.465286e-001,0.000000e+000,,,,,,,,,,,,,,32,1,4.000000e+000,2.104187e-002,0.000000e+000,0,,0,
1524037292.184,,0.000000e+000,5.500037e+001,2.515187e-006,0.000000e+000,3,7.544712e-001,0.000000e+000,,,,,,,,,,,,,,32,1,4.000000e+000,1.319885e-003,0.000000e+000,0,,0,
1524037330.034,,0.000000e+000,5.500037e+001,2.588140e-006,0.000000e+000,3,7.616820e-001,0.000000e+000,,,,,,,,,,,,,,32,1,4.000000e+000,1.319885e-003,0.000000e+000,0,,0,
1524037367.764,,0.000000e+000,5.499774e+001,2.531896e-006,0.000000e+000,3,7.592371e-001,0.000000e+000,,,,,,,,,,,,,,32,1,4.000000e+000,6.580353e-003,0.000000e+000,0,,0,
1524037405.614,,0.000000e+000,5.499708e+001,2.556209e-006,0.000000e+000,3,7.446631e-001,0.000000e+000,,,,,,,,,,,,,,32,1,4.000000e+000,2.620697e-003,0.000000e+000,0,,0,
1524037443.334,,0.000000e+000,5.499643e+001,2.531808e-006,0.000000e+000,3,7.632213e-001,0.000000e+000,,,,,,,,,,,,,,32,1,4.000000e+000,6.568909e-003,0.000000e+000,0,,0,
1524037481.194,,0.000000e+000,5.500366e+001,2.560541e-006,0.000000e+000,3,7.498831e-001,0.000000e+000,,,,,,,,,,,,,,32,1,4.000000e+000,7.900238e-003,0.000000e+000,0,,0,
1524037518.924,,0.000000e+000,5.499577e+001,2.441888e-006,0.000000e+000,3,7.619845e-001,0.000000e+000,,,,,,,,,,,,,,32,1,4.000000e+000,7.888794e-003,0.000000e+000,0,,0,
1524037557.394,,0.000000e+000,5.500103e+001,2.426841e-006,0.000000e+000,3,7.400922e-001,0.000000e+000,,,,,,,,,,,,,,32,1,4.000000e+000,0.000000e+000,0.000000e+000,0,,0,
1524037595.134,,0.000000e+000,5.499905e+001,2.540490e-006,0.000000e+000,3,7.361516e-001,0.000000e+000,,,,,,,,,,,,,,32,1,4.000000e+000,1.319885e-003,0.000000e+000,0,,0,
1524037632.874,,0.000000e+000,5.500103e+001,2.449530e-006,0.000000e+000,3,7.664769e-001,0.000000e+000,,,,,,,,,,,,,,32,1,4.000000e+000,0.000000e+000,0.000000e+000,0,,0,