File: Experimental Raw Data/TC04-12-01K VRMac VRMde/Iterative Regression/TC04-12-01K_VRMac_57K_3000s_VRMde_55K.dc.dat
[Header]
TITLE,MPMS DC Measurement
BYAPP,MPMS Measurement,2.1,Summary
FILEOPENTIME, 1524184488.448000 4/19/2018, 6:34:48 PM

INFO, APPNAME, MPMS MultiVu Application, Revision 1.61,  Build 082

INFO, NAME, TC04-12-01K
INFO, WEIGHT, 1.000
INFO, AREA, 1.000
INFO, LENGTH, 1.000
INFO, SHAPE, 0
INFO, COMMENT,
INFO, SEQUENCE FILE: VRMac_57K_3000s_VRMde_55K.seq


INFO, BACKGROUND DATA FILE:, None


STARTUPAXIS,X,4,LINEAR,AUTO,0.000000,0.000000
STARTUPAXIS,Y1,5,LINEAR,AUTO,0.000000,0.000000


STARTUPGROUP,Longitudinal
FIELDGROUP,Longitudinal,1,2,3,4,5,6,7,8,9,15,16,17,18,27,28
FIELDGROUP,Transverse,1,2,3,4,10,11,12,13,14,19,20,21,22,27,28

PLOT_APPEARANCE,ALL,HORZ_GRID_ON,VERT_GRID_ON,MARKERS_AND_LINES

[Data]
Time,Comment,Field (Oe),Temperature (K),Long Moment (emu),Long Scan Std Dev,Long Algorithm,Long Reg Fit,Long Percent Error (%),Trans Moment (emu),Trans Scan Std Dev,Trans Algorithm,Trans Reg Fit,Trans Percent Error (%),Long Moment [w/o ABS] (emu),Long Scan Std Dev [w/o ABS],Long Reg Fit [w/o ABS],Long Percent Error [w/o ABS] (%),Trans Moment [w/o ABS] (emu),Trans Scan Std Dev [w/o ABS],Trans Reg Fit [w/o ABS],Trans Percent Error [w/o ABS] (%),Points per Scan,Scans per Measurement,Scan Length (cm),Delta Temp (K),Rot Position (deg),Error,EC Comp. Running,Using ABS,
1524184488.448,,0.000000e+000,5.698625e+001,-1.460314e-005,0.000000e+000,3,9.633987e-001,0.000000e+000,,,,,,,,,,,,,,32,1,4.000000e+000,3.084183e-002,0.000000e+000,0,,0,
1524184527.918,,0.000000e+000,5.681713e+001,-1.085422e-005,0.000000e+000,3,9.534187e-001,0.000000e+000,,,,,,,,,,,,,,32,1,4.000000e+000,7.528687e-002,0.000000e+000,0,,0,
1524184565.378,,0.000000e+000,5.634676e+001,-9.287923e-006,0.000000e+000,3,9.552895e-001,0.000000e+000,,,,,,,,,,,,,,32,1,4.000000e+000,1.867981e-001,0.000000e+000,0,,0,
1524184603.978,,0.000000e+000,5.559029e+001,-8.411297e-006,0.000000e+000,3,9.556491e-001,0.000000e+000,,,,,,,,,,,,,,32,1,4.000000e+000,2.373199e-001,0.000000e+000,0,,0,
1524185485.801,,0.000000e+000,5.501221e+001,-4.746963e-006,0.000000e+000,3,9.339778e-001,0.000000e+000,,,,,,,,,,,,,,32,1,4.000000e+000,1.319885e-003,0.000000e+000,0,,0,
1524185523.101,,0.000000e+000,5.499840e+001,-4.451166e-006,0.000000e+000,3,9.413707e-001,0.000000e+000,,,,,,,,,,,,,,32,1,4.000000e+000,5.260468e-003,0.000000e+000,0,,0,
1524185560.882,,0.000000e+000,5.499445e+001,-4.362140e-006,0.000000e+000,3,9.248914e-001,0.000000e+000,,,,,,,,,,,,,,32,1,4.000000e+000,2.628326e-003,0.000000e+000,0,,0,
1524185598.402,,0.000000e+000,5.500037e+001,-4.131833e-006,0.000000e+000,3,9.207765e-001,0.000000e+000,,,,,,,,,,,,,,32,1,4.000000e+000,9.201050e-003,0.000000e+000,0,,0,
1524185636.552,,0.000000e+000,5.499511e+001,-3.999726e-006,0.000000e+000,3,9.171181e-001,0.000000e+000,,,,,,,,,,,,,,32,1,4.000000e+000,9.201050e-003,0.000000e+000,0,,0,
1524185674.212,,0.000000e+000,5.500300e+001,-4.056725e-006,0.000000e+000,3,9.154708e-001,0.000000e+000,,,,,,,,,,,,,,32,1,4.000000e+000,9.220123e-003,0.000000e+000,0,,0,
1524185712.172,,0.000000e+000,5.500235e+001,-3.936951e-006,0.000000e+000,3,9.162139e-001,0.000000e+000,,,,,,,,,,,,,,32,1,4.000000e+000,2.639771e-003,0.000000e+000,0,,0,
1524185749.632,,0.000000e+000,5.499380e+001,-3.939204e-006,0.000000e+000,3,9.106461e-001,0.000000e+000,,,,,,,,,,,,,,32,1,4.000000e+000,1.308441e-003,0.000000e+000,0,,0,
1524185787.272,,0.000000e+000,5.499972e+001,-3.759365e-006,0.000000e+000,3,9.197997e-001,0.000000e+000,,,,,,,,,,,,,,32,1,4.000000e+000,7.900238e-003,0.000000e+000,0,,0,
1524185824.952,,0.000000e+000,5.500234e+001,-3.728785e-006,0.000000e+000,3,9.025151e-001,0.000000e+000,,,,,,,,,,,,,,32,1,4.000000e+000,1.578903e-002,0.000000e+000,0,,0,
1524185862.752,,0.000000e+000,5.499709e+001,-3.624698e-006,0.000000e+000,3,9.143242e-001,0.000000e+000,,,,,,,,,,,,,,32,1,4.000000e+000,1.052856e-002,0.000000e+000,0,,0,
1524185899.732,,0.000000e+000,5.500234e+001,-3.591623e-006,0.000000e+000,3,8.860062e-001,0.000000e+000,,,,,,,,,,,,,,32,1,4.000000e+000,7.900238e-003,0.000000e+000,0,,0,
1524185937.682,,0.000000e+000,5.499840e+001,-3.551808e-006,0.000000e+000,3,8.955716e-001,0.000000e+000,,,,,,,,,,,,,,32,1,4.000000e+000,2.628326e-003,0.000000e+000,0,,0,
1524185975.882,,0.000000e+000,5.499577e+001,-3.433367e-006,0.000000e+000,3,9.022819e-001,0.000000e+000,,,,,,,,,,,,,,32,1,4.000000e+000,2.632141e-003,0.000000e+000,0,,0,
1524186013.362,,0.000000e+000,5.499839e+001,-3.497699e-006,0.000000e+000,3,8.959654e-001,0.000000e+000,,,,,,,,,,,,,,32,1,4.000000e+000,0.000000e+000,0.000000e+000,0,,0,
1524186051.102,,0.000000e+000,5.499577e+001,-3.302360e-006,0.000000e+000,3,8.943892e-001,0.000000e+000,,,,,,,,,,,,,,32,1,4.000000e+000,2.632141e-003,0.000000e+000,0,,0,
1524186089.342,,0.000000e+000,5.499905e+001,-3.295406e-006,0.000000e+000,3,8.973557e-001,0.000000e+000,,,,,,,,,,,,,,32,1,4.000000e+000,1.319885e-003,0.000000e+000,0,,0,
1524186127.062,,0.000000e+000,5.500629e+001,-3.376957e-006,0.000000e+000,3,8.751186e-001,0.000000e+000,,,,,,,,,,,,,,32,1,4.000000e+000,0.000000e+000,0.000000e+000,0,,0,
1524186164.442,,0.000000e+000,5.499511e+001,-3.215314e-006,0.000000e+000,3,8.870968e-001,0.000000e+000,,,,,,,,,,,,,,32,1,4.000000e+000,9.201050e-003,0.000000e+000,0,,0,
1524186202.212,,0.000000e+000,5.500169e+001,-3.201645e-006,0.000000e+000,3,8.694609e-001,0.000000e+000,,,,,,,,,,,,,,32,1,4.000000e+000,9.208679e-003,0.000000e+000,0,,0,
1524186240.132,,0.000000e+000,5.500103e+001,-3.103238e-006,0.000000e+000,3,8.914636e-001,0.000000e+000,,,,,,,,,,,,,,32,1,4.000000e+000,0.000000e+000,0.000000e+000,0,,0,
1524186277.743,,0.000000e+000,5.500037e+001,-3.066261e-006,0.000000e+000,3,8.722311e-001,0.000000e+000,,,,,,,,,,,,,,32,1,4.000000e+000,1.319885e-003,0.000000e+000,0,,0,
1524186315.783,,0.000000e+000,5.499511e+001,-3.015460e-006,0.000000e+000,3,8.666536e-001,0.000000e+000,,,,,,,,,,,,,,32,1,4.000000e+000,3.940582e-003,0.000000e+000,0,,0,
1524186353.453,,0.000000e+000,5.499773e+001,-3.029715e-006,0.000000e+000,3,8.622720e-001,0.000000e+000,,,,,,,,,,,,,,32,1,4.000000e+000,1.308441e-003,0.000000e+000,0,,0,
1524186391.173,,0.000000e+000,5.499971e+001,-2.924364e-006,0.000000e+000,3,8.734734e-001,0.000000e+000,,,,,,,,,,,,,,32,1,4.000000e+000,2.639771e-003,0.000000e+000,0,,0,
1524186428.573,,0.000000e+000,5.499577e+001,-2.998571e-006,0.000000e+000,3,8.657267e-001,0.000000e+000,,,,,,,,,,,,,,32,1,4.000000e+000,0.000000e+000,0.000000e+000,0,,0,
1524186466.523,,0.000000e+000,5.499708e+001,-2.866095e-006,0.000000e+000,3,8.716902e-001,0.000000e+000,,,,,,,,,,,,,,32,1,4.000000e+000,2.620697e-003,0.000000e+000,0,,0,
1524186503.703,,0.000000e+000,5.499708e+001,-2.964869e-006,0.000000e+000,3,8.595245e-001,0.000000e+000,,,,,,,,,,,,,,32,1,4.000000e+000,5.260468e-003,0.000000e+000,0,,0,
1524186542.223,,0.000000e+000,5.499773e+001,-2.851722e-006,0.000000e+000,3,8.611441e-001,0.000000e+000,,,,,,,,,,,,,,32,1,4.000000e+000,1.308441e-003,0.000000e+000,0,,0,
1524186580.563,,0.000000e+000,5.499511e+001,-2.784923e-006,0.000000e+000,3,8.554346e-001,0.000000e+000,,,,,,,,,,,,,,32,1,4.000000e+000,9.201050e-003,0.000000e+000,0,,0,
1524186618.233,,0.000000e+000,5.499380e+001,-2.842364e-006,0.000000e+000,3,8.588865e-001,0.000000e+000,,,,,,,,,,,,,,32,1,4.000000e+000,1.308441e-003,0.000000e+000,0,,0,
1524186656.223,,0.000000e+000,5.499577e+001,-2.720811e-006,0.000000e+000,3,8.414648e-001,0.000000e+000,,,,,,,,,,,,,,32,1,4.000000e+000,5.249023e-003,0.000000e+000,0,,0,
1524186693.973,,0.000000e+000,5.499840e+001,-2.781684e-006,0.000000e+000,3,8.361585e-001,0.000000e+000,,,,,,,,,,,,,,32,1,4.000000e+000,1.578140e-002,0.000000e+000,0,,0,
1524186731.903,,0.000000e+000,5.499839e+001,-2.685776e-006,0.000000e+000,3,8.421449e-001,0.000000e+000,,,,,,,,,,,,,,32,1,4.000000e+000,0.000000e+000,0.000000e+000,0,,0,
1524186769.483,,0.000000e+000,5.499511e+001,-2.698794e-006,0.000000e+000,3,8.273523e-001,0.000000e+000,,,,,,,,,,,,,,32,1,4.000000e+000,3.940582e-003,0.000000e+000,0,,0,
1524186806.943,,0.000000e+000,5.499445e+001,-2.590773e-006,0.000000e+000,3,8.356509e-001,0.000000e+000,,,,,,,,,,,,,,32,1,4.000000e+000,7.881165e-003,0.000000e+000,0,,0,
1524186844.433,,0.000000e+000,5.499840e+001,-2.694412e-006,0.000000e+000,3,8.222627e-001,0.000000e+000,,,,,,,,,,,,,,32,1,4.000000e+000,2.628326e-003,0.000000e+000,0,,0,
1524186882.253,,0.000000e+000,5.499709e+001,-2.584532e-006,0.000000e+000,3,8.410766e-001,0.000000e+000,,,,,,,,,,,,,,32,1,4.000000e+000,7.888794e-003,0.000000e+000,0,,0,
1524186920.433,,0.000000e+000,5.499577e+001,-2.516390e-006,0.000000e+000,3,8.264322e-001,0.000000e+000,,,,,,,,,,,,,,32,1,4.000000e+000,5.249023e-003,0.000000e+000,0,,0,
1524186957.583,,0.000000e+000,5.499577e+001,-2.597564e-006,0.000000e+000,3,8.273557e-001,0.000000e+000,,,,,,,,,,,,,,32,1,4.000000e+000,7.888794e-003,0.000000e+000,0,,0,
1524186995.054,,0.000000e+000,5.500169e+001,-2.506819e-006,0.000000e+000,3,8.143877e-001,0.000000e+000,,,,,,,,,,,,,,32,1,4.000000e+000,1.319885e-003,0.000000e+000,0,,0,
1524187032.374,,0.000000e+000,5.499642e+001,-2.688416e-006,0.000000e+000,3,8.024393e-001,0.000000e+000,,,,,,,,,,,,,,32,1,4.000000e+000,3.940582e-003,0.000000e+000,0,,0,
1524187069.854,,0.000000e+000,5.499511e+001,-2.599962e-006,0.000000e+000,3,8.194559e-001,0.000000e+000,,,,,,,,,,,,,,32,1,4.000000e+000,1.319885e-003,0.000000e+000,0,,0,
1524187107.854,,0.000000e+000,5.499511e+001,-2.534676e-006,0.000000e+000,3,8.054658e-001,0.000000e+000,,,,,,,,,,,,,,32,1,4.000000e+000,1.319885e-003,0.000000e+000,0,,0,
1524187150.238,,0.000000e+000,5.499182e+001,-7.932574e-007,0.000000e+000,2,0.000000e+000,0.000000e+000,,,,,,,,,,,,,,32,1,4.000000e+000,5.260468e-003,0.000000e+000,0,,0,
1524187193.374,,0.000000e+000,5.499905e+001,-6.985002e-007,0.000000e+000,2,0.000000e+000,0.000000e+000,,,,,,,,,,,,,,32,1,4.000000e+000,3.948212e-003,0.000000e+000,0,,0,
1524187234.368,,0.000000e+000,5.500037e+001,-7.223201e-007,0.000000e+000,2,0.000000e+000,0.000000e+000,,,,,,,,,,,,,,32,1,4.000000e+000,9.201050e-003,0.000000e+000,0,,0,
1524187277.864,,0.000000e+000,5.500168e+001,-6.175387e-007,0.000000e+000,2,0.000000e+000,0.000000e+000,,,,,,,,,,,,,,32,1,4.000000e+000,6.580353e-003,0.000000e+000,0,,0,
1524187320.090,,0.000000e+000,5.499709e+001,-5.822127e-007,0.000000e+000,2,0.000000e+000,0.000000e+000,,,,,,,,,,,,,,32,1,4.000000e+000,7.888794e-003,0.000000e+000,0,,0,
1524187362.556,,0.000000e+000,5.499577e+001,-5.420865e-007,0.000000e+000,2,0.000000e+000,0.000000e+000,,,,,,,,,,,,,,32,1,4.000000e+000,2.632141e-003,0.000000e+000,0,,0,
1524187405.582,,0.000000e+000,5.499709e+001,-5.615118e-007,0.000000e+000,2,0.000000e+000,0.000000e+000,,,,,,,,,,,,,,32,1,4.000000e+000,1.052856e-002,0.000000e+000,0,,0,
1524187448.348,,0.000000e+000,5.499971e+001,-4.412127e-007,0.000000e+000,2,0.000000e+000,0.000000e+000,,,,,,,,,,,,,,32,1,4.000000e+000,2.639771e-003,0.000000e+000,0,,0,
1524187491.044,,0.000000e+000,5.499314e+001,-4.158603e-007,0.000000e+000,2,0.000000e+000,0.000000e+000,,,,,,,,,,,,,,32,1,4.000000e+000,5.260468e-003,0.000000e+000,0,,0,
1524187535.140,,0.000000e+000,5.499643e+001,-4.042868e-007,0.000000e+000,2,0.000000e+000,0.000000e+000,,,,,,,,,,,,,,32,1,4.000000e+000,1.312256e-003,0.000000e+000,0,,0,
1524187578.026,,0.000000e+000,5.499511e+001,-3.900064e-007,0.000000e+000,2,0.000000e+000,0.000000e+000,,,,,,,,,,,,,,32,1,4.000000e+000,1.319885e-003,0.000000e+000,0,,0,
1524187618.560,,0.000000e+000,5.500103e+001,-3.685390e-007,0.000000e+000,2,0.000000e+000,0.000000e+000,,,,,,,,,,,,,,32,1,4.000000e+000,1.316071e-002,0.000000e+000,0,,0,
1524187659.424,,0.000000e+000,5.499972e+001,-3.245836e-007,0.000000e+000,2,0.000000e+000,0.000000e+000,,,,,,,,,,,,,,32,1,4.000000e+000,5.268097e-003,0.000000e+000,0,,0,
1524187696.445,,0.000000e+000,5.499840e+001,2.383518e-006,0.000000e+000,3,6.357783e-001,0.000000e+000,,,,,,,,,,,,,,32,1,4.000000e+000,7.900238e-003,0.000000e+000,0,,0,
1524187737.589,,0.000000e+000,5.499380e+001,-3.615782e-007,0.000000e+000,2,0.000000e+000,0.000000e+000,,,,,,,,,,,,,,32,1,4.000000e+000,6.572723e-003,0.000000e+000,0,,0,
1524187775.229,,0.000000e+000,5.499643e+001,2.407294e-006,0.000000e+000,3,6.524220e-001,0.000000e+000,,,,,,,,,,,,,,32,1,4.000000e+000,6.568909e-003,0.000000e+000,0,,0,
1524187813.099,,0.000000e+000,5.499380e+001,2.397764e-006,0.000000e+000,3,6.136404e-001,0.000000e+000,,,,,,,,,,,,,,32,1,4.000000e+000,1.182938e-002,0.000000e+000,0,,0,
1524187851.089,,0.000000e+000,5.499445e+001,2.324192e-006,0.000000e+000,3,6.085877e-001,0.000000e+000,,,,,,,,,,,,,,32,1,4.000000e+000,0.000000e+000,0.000000e+000,0,,0,
1524187889.869,,0.000000e+000,5.499972e+001,2.370588e-006,0.000000e+000,3,6.539570e-001,0.000000e+000,,,,,,,,,,,,,,32,1,4.000000e+000,5.268097e-003,0.000000e+000,0,,0,
1524187927.489,,0.000000e+000,5.500037e+001,2.431807e-006,0.000000e+000,3,6.305325e-001,0.000000e+000,,,,,,,,,,,,,,32,1,4.000000e+000,6.587982e-003,0.000000e+000,0,,0,
1524187965.439,,0.000000e+000,5.499708e+001,2.398583e-006,0.000000e+000,3,6.644325e-001,0.000000e+000,,,,,,,,,,,,,,32,1,4.000000e+000,2.620697e-003,0.000000e+000,0,,0,
1524188007.735,,0.000000e+000,5.499577e+001,-6.454492e-008,0.000000e+000,2,0.000000e+000,0.000000e+000,,,,,,,,,,,,,,32,1,4.000000e+000,0.000000e+000,0.000000e+000,0,,0,
1524188051.601,,0.000000e+000,5.499773e+001,-5.165180e-008,0.000000e+000,2,0.000000e+000,0.000000e+000,,,,,,,,,,,,,,32,1,4.000000e+000,1.308441e-003,0.000000e+000,0,,0,
1524188090.143,,0.000000e+000,5.499841e+001,2.310295e-006,0.000000e+000,3,6.165656e-001,0.000000e+000,,,,,,,,,,,,,,32,1,4.000000e+000,1.052856e-002,0.000000e+000,0,,0,
1524188127.823,,0.000000e+000,5.499905e+001,-2.409814e-006,0.000000e+000,3,7.494799e-001,0.000000e+000,,,,,,,,,,,,,,32,1,4.000000e+000,3.948212e-003,0.000000e+000,0,,0,
1524188169.317,,0.000000e+000,5.500432e+001,3.689244e-008,0.000000e+000,2,0.000000e+000,0.000000e+000,,,,,,,,,,,,,,32,1,4.000000e+000,1.300812e-003,0.000000e+000,0,,0,
1524188209.721,,0.000000e+000,5.499905e+001,6.231888e-008,0.000000e+000,2,0.000000e+000,0.000000e+000,,,,,,,,,,,,,,32,1,4.000000e+000,1.319885e-003,0.000000e+000,0,,0,
1524188248.343,,0.000000e+000,5.499643e+001,7.387453e-008,0.000000e+000,2,0.000000e+000,0.000000e+000,,,,,,,,,,,,,,32,1,4.000000e+000,6.568909e-003,0.000000e+000,0,,0,
1524188285.023,,0.000000e+000,5.499642e+001,-2.412689e-006,0.000000e+000,3,7.557589e-001,0.000000e+000,,,,,,,,,,,,,,32,1,4.000000e+000,3.940582e-003,0.000000e+000,0,,0,
1524188324.475,,0.000000e+000,5.500563e+001,-2.368005e-006,0.000000e+000,3,7.364045e-001,0.000000e+000,,,,,,,,,,,,,,32,1,4.000000e+000,1.319885e-003,0.000000e+000,0,,0,
1524188363.777,,0.000000e+000,5.499642e+001,-2.204685e-006,0.000000e+000,3,7.449861e-001,0.000000e+000,,,,,,,,,,,,,,32,1,4.000000e+000,3.940582e-003,0.000000e+000,0,,0,
1524188401.487,,0.000000e+000,5.500301e+001,-2.250266e-006,0.000000e+000,3,7.412599e-001,0.000000e+000,,,,,,,,,,,,,,32,1,4.000000e+000,1.446915e-002,0.000000e+000,0,,0,
1524188439.078,,0.000000e+000,5.499577e+001,-2.255547e-006,0.000000e+000,3,7.480962e-001,0.000000e+000,,,,,,,,,,,,,,32,1,4.000000e+000,1.316071e-002,0.000000e+000,0,,0,
1524188477.088,,0.000000e+000,5.500366e+001,-2.198587e-006,0.000000e+000,3,7.483944e-001,0.000000e+000,,,,,,,,,,,,,,32,1,4.000000e+000,7.900238e-003,0.000000e+000,0,,0,
1524188514.708,,0.000000e+000,5.500037e+001,-2.347506e-006,0.000000e+000,3,7.368721e-001,0.000000e+000,,,,,,,,,,,,,,32,1,4.000000e+000,3.959656e-003,0.000000e+000,0,,0,
1524188552.788,,0.000000e+000,5.499511e+001,-2.236663e-006,0.000000e+000,3,7.380762e-001,0.000000e+000,,,,,,,,,,,,,,32,1,4.000000e+000,3.940582e-003,0.000000e+000,0,,0,
1524188590.678,,0.000000e+000,5.499248e+001,-2.364098e-006,0.000000e+000,3,7.476557e-001,0.000000e+000,,,,,,,,,,,,,,32,1,4.000000e+000,3.940582e-003,0.000000e+000,0,,0,
1524188628.488,,0.000000e+000,5.499905e+001,-2.362626e-006,0.000000e+000,3,7.601489e-001,0.000000e+000,,,,,,,,,,,,,,32,1,4.000000e+000,1.319885e-003,0.000000e+000,0,,0,
1524188665.798,,0.000000e+000,5.500103e+001,-2.491599e-006,0.000000e+000,3,7.477037e-001,0.000000e+000,,,,,,,,,,,,,,32,1,4.000000e+000,2.639771e-003,0.000000e+000,0,,0,
1524188706.850,,0.000000e+000,5.500235e+001,2.933868e-007,0.000000e+000,2,0.000000e+000,0.000000e+000,,,,,,,,,,,,,,32,1,4.000000e+000,1.052856e-002,0.000000e+000,0,,0,
1524188750.246,,0.000000e+000,5.500234e+001,3.113709e-007,0.000000e+000,2,0.000000e+000,0.000000e+000,,,,,,,,,,,,,,32,1,4.000000e+000,5.260468e-003,0.000000e+000,0,,0,
1524188793.102,,0.000000e+000,5.499775e+001,3.000751e-007,0.000000e+000,2,0.000000e+000,0.000000e+000,,,,,,,,,,,,,,32,1,4.000000e+000,9.208679e-003,0.000000e+000,0,,0,
1524188835.878,,0.000000e+000,5.499840e+001,4.495936e-007,0.000000e+000,2,0.000000e+000,0.000000e+000,,,,,,,,,,,,,,32,1,4.000000e+000,7.900238e-003,0.000000e+000,0,,0,
1524188878.074,,0.000000e+000,5.499643e+001,4.166156e-007,0.000000e+000,2,0.000000e+000,0.000000e+000,,,,,,,,,,,,,,32,1,4.000000e+000,1.312256e-003,0.000000e+000,0,,0,
1524188920.170,,0.000000e+000,5.499248e+001,4.391504e-007,0.000000e+000,2,0.000000e+000,0.000000e+000,,,,,,,,,,,,,,32,1,4.000000e+000,3.940582e-003,0.000000e+000,0,,0,
1524188963.266,,0.000000e+000,5.500169e+001,5.121398e-007,0.000000e+000,2,0.000000e+000,0.000000e+000,,,,,,,,,,,,,,32,1,4.000000e+000,3.959656e-003,0.000000e+000,0,,0,
1524189006.122,,0.000000e+000,5.499380e+001,4.995832e-007,0.000000e+000,2,0.000000e+000,0.000000e+000,,,,,,,,,,,,,,32,1,4.000000e+000,1.446915e-002,0.000000e+000,0,,0,
1524189048.288,,0.000000e+000,5.499775e+001,5.514676e-007,0.000000e+000,2,0.000000e+000,0.000000e+000,,,,,,,,,,,,,,32,1,4.000000e+000,9.208679e-003,0.000000e+000,0,,0,
1524189091.114,,0.000000e+000,5.499972e+001,5.001013e-007,0.000000e+000,2,0.000000e+000,0.000000e+000,,,,,,,,,,,,,,32,1,4.000000e+000,5.268097e-003,0.000000e+000,0,,0,
1524189133.791,,0.000000e+000,5.499840e+001,6.178685e-007,0.000000e+000,2,0.000000e+000,0.000000e+000,,,,,,,,,,,,,,32,1,4.000000e+000,2.628326e-003,0.000000e+000,0,,0,
1524189176.897,,0.000000e+000,5.499642e+001,6.194727e-007,0.000000e+000,2,0.000000e+000,0.000000e+000,,,,,,,,,,,,,,32,1,4.000000e+000,3.940582e-003,0.000000e+000,0,,0,
1524189217.161,,0.000000e+000,5.500367e+001,-1.932375e-006,0.000000e+000,3,2.594577e-001,0.000000e+000,,,,,,,,,,,,,,32,1,4.000000e+000,0.000000e+000,0.000000e+000,0,,0,
1524189260.027,,0.000000e+000,5.500365e+001,7.389969e-007,0.000000e+000,2,0.000000e+000,0.000000e+000,,,,,,,,,,,,,,32,1,4.000000e+000,1.052856e-002,0.000000e+000,0,,0,
1524189302.683,,0.000000e+000,5.499708e+001,7.064006e-007,0.000000e+000,2,0.000000e+000,0.000000e+000,,,,,,,,,,,,,,32,1,4.000000e+000,2.620697e-003,0.000000e+000,0,,0,
1524189343.247,,0.000000e+000,5.499972e+001,-1.140119e-006,0.000000e+000,3,0.000000e+000,0.000000e+000,,,,,,,,,,,,,,32,1,4.000000e+000,5.268097e-003,0.000000e+000,0,,0,
1524189384.331,,0.000000e+000,5.499971e+001,7.031860e-007,0.000000e+000,2,0.000000e+000,0.000000e+000,,,,,,,,,,,,,,32,1,4.000000e+000,2.639771e-003,0.000000e+000,0,,0,
1524189424.885,,0.000000e+000,5.499840e+001,-1.996395e-006,0.000000e+000,3,3.063523e-001,0.000000e+000,,,,,,,,,,,,,,32,1,4.000000e+000,5.260468e-003,0.000000e+000,0,,0,
1524189463.847,,0.000000e+000,5.499774e+001,2.251830e-006,0.000000e+000,3,7.298226e-001,0.000000e+000,,,,,,,,,,,,,,32,1,4.000000e+000,3.940582e-003,0.000000e+000,0,,0,
1524189506.873,,0.000000e+000,5.499972e+001,7.460397e-007,0.000000e+000,2,0.000000e+000,0.000000e+000,,,,,,,,,,,,,,32,1,4.000000e+000,5.268097e-003,0.000000e+000,0,,0,
1524189545.185,,0.000000e+000,5.500103e+001,2.467221e-006,0.000000e+000,3,6.592464e-001,0.000000e+000,,,,,,,,,,,,,,32,1,4.000000e+000,7.888794e-003,0.000000e+000,0,,0,
1524189586.739,,0.000000e+000,5.499971e+001,7.096124e-007,0.000000e+000,2,0.000000e+000,0.000000e+000,,,,,,,,,,,,,,32,1,4.000000e+000,2.639771e-003,0.000000e+000,0,,0,
1524189625.631,,0.000000e+000,5.500037e+001,2.272298e-006,0.000000e+000,3,7.208690e-001,0.000000e+000,,,,,,,,,,,,,,32,1,4.000000e+000,1.319885e-003,0.000000e+000,0,,0,
1524189663.101,,0.000000e+000,5.499905e+001,2.298535e-006,0.000000e+000,3,6.945103e-001,0.000000e+000,,,,,,,,,,,,,,32,1,4.000000e+000,1.319885e-003,0.000000e+000,0,,0,
1524189701.041,,0.000000e+000,5.499971e+001,2.264808e-006,0.000000e+000,3,7.126791e-001,0.000000e+000,,,,,,,,,,,,,,32,1,4.000000e+000,0.000000e+000,0.000000e+000,0,,0,
1524189738.781,,0.000000e+000,5.499840e+001,2.311584e-006,0.000000e+000,3,6.969949e-001,0.000000e+000,,,,,,,,,,,,,,32,1,4.000000e+000,2.628326e-003,0.000000e+000,0,,0,
1524189776.741,,0.000000e+000,5.499839e+001,2.192924e-006,0.000000e+000,3,7.361881e-001,0.000000e+000,,,,,,,,,,,,,,32,1,4.000000e+000,0.000000e+000,0.000000e+000,0,,0,
1524189814.471,,0.000000e+000,5.499971e+001,2.270448e-006,0.000000e+000,3,7.229056e-001,0.000000e+000,,,,,,,,,,,,,,32,1,4.000000e+000,0.000000e+000,0.000000e+000,0,,0,
1524189852.412,,0.000000e+000,5.499773e+001,2.182702e-006,0.000000e+000,3,7.309762e-001,0.000000e+000,,,,,,,,,,,,,,32,1,4.000000e+000,1.308441e-003,0.000000e+000,0,,0,
1524189890.302,,0.000000e+000,5.500103e+001,2.350856e-006,0.000000e+000,3,7.297944e-001,0.000000e+000,,,,,,,,,,,,,,32,1,4.000000e+000,5.279541e-003,0.000000e+000,0,,0,
1524189928.242,,0.000000e+000,5.499511e+001,2.195874e-006,0.000000e+000,3,6.907157e-001,0.000000e+000,,,,,,,,,,,,,,32,1,4.000000e+000,6.568909e-003,0.000000e+000,0,,0,
1524189965.302,,0.000000e+000,5.499906e+001,2.342112e-006,0.000000e+000,3,7.078245e-001,0.000000e+000,,,,,,,,,,,,,,32,1,4.000000e+000,6.580353e-003,0.000000e+000,0,,0,
1524190003.122,,0.000000e+000,5.499972e+001,2.267220e-006,0.000000e+000,3,7.477020e-001,0.000000e+000,,,,,,,,,,,,,,32,1,4.000000e+000,5.268097e-003,0.000000e+000,0,,0,
1524190040.742,,0.000000e+000,5.499773e+001,2.285757e-006,0.000000e+000,3,7.108946e-001,0.000000e+000,,,,,,,,,,,,,,32,1,4.000000e+000,1.308441e-003,0.000000e+000,0,,0,
1524190078.872,,0.000000e+000,5.500169e+001,2.248214e-006,0.000000e+000,3,7.328410e-001,0.000000e+000,,,,,,,,,,,,,,32,1,4.000000e+000,1.184082e-002,0.000000e+000,0,,0,
1524190116.542,,0.000000e+000,5.500498e+001,2.279186e-006,0.000000e+000,3,7.052274e-001,0.000000e+000,,,,,,,,,,,,,,32,1,4.000000e+000,2.620697e-003,0.000000e+000,0,,0,
1524190154.572,,0.000000e+000,5.499773e+001,2.235480e-006,0.000000e+000,3,7.214047e-001,0.000000e+000,,,,,,,,,,,,,,32,1,4.000000e+000,1.308441e-003,0.000000e+000,0,,0,
1524190192.182,,0.000000e+000,5.500103e+001,2.294773e-006,0.000000e+000,3,7.112061e-001,0.000000e+000,,,,,,,,,,,,,,32,1,4.000000e+000,1.841736e-002,0.000000e+000,0,,0,
1524190230.242,,0.000000e+000,5.499577e+001,2.246234e-006,0.000000e+000,3,7.259911e-001,0.000000e+000,,,,,,,,,,,,,,32,1,4.000000e+000,5.249023e-003,0.000000e+000,0,,0,
1524190267.932,,0.000000e+000,5.499840e+001,2.305854e-006,0.000000e+000,3,7.269093e-001,0.000000e+000,,,,,,,,,,,,,,32,1,4.000000e+000,2.628326e-003,0.000000e+000,0,,0,
1524190305.832,,0.000000e+000,5.499839e+001,2.306095e-006,0.000000e+000,3,7.315758e-001,0.000000e+000,,,,,,,,,,,,,,32,1,4.000000e+000,0.000000e+000,0.000000e+000,0,,0,
1524190343.582,,0.000000e+000,5.500234e+001,2.383916e-006,0.000000e+000,3,7.265875e-001,0.000000e+000,,,,,,,,,,,,,,32,1,4.000000e+000,5.260468e-003,0.000000e+000,0,,0,
1524190382.012,,0.000000e+000,5.499971e+001,2.271792e-006,0.000000e+000,3,7.194552e-001,0.000000e+000,,,,,,,,,,,,,,32,1,4.000000e+000,2.639771e-003,0.000000e+000,0,,0,
1524190419.882,,0.000000e+000,5.499380e+001,2.295679e-006,0.000000e+000,3,7.477888e-001,0.000000e+000,,,,,,,,,,,,,,32,1,4.000000e+000,6.572723e-003,0.000000e+000,0,,0,
1524190457.842,,0.000000e+000,5.499642e+001,2.344393e-006,0.000000e+000,3,7.587931e-001,0.000000e+000,,,,,,,,,,,,,,32,1,4.000000e+000,3.940582e-003,0.000000e+000,0,,0,
1524190496.072,,0.000000e+000,5.499774e+001,2.309722e-006,0.000000e+000,3,7.423793e-001,0.000000e+000,,,,,,,,,,,,,,32,1,4.000000e+000,3.940582e-003,0.000000e+000,0,,0,
1524190533.842,,0.000000e+000,5.499643e+001,2.307093e-006,0.000000e+000,3,7.312671e-001,0.000000e+000,,,,,,,,,,,,,,32,1,4.000000e+000,9.208679e-003,0.000000e+000,0,,0,
1524190571.223,,0.000000e+000,5.499971e+001,2.402576e-006,0.000000e+000,3,7.394087e-001,0.000000e+000,,,,,,,,,,,,,,32,1,4.000000e+000,2.639771e-003,0.000000e+000,0,,0,
1524190608.643,,0.000000e+000,5.499708e+001,2.350300e-006,0.000000e+000,3,7.636607e-001,0.000000e+000,,,,,,,,,,,,,,32,1,4.000000e+000,5.260468e-003,0.000000e+000,0,,0,
1524190645.743,,0.000000e+000,5.500037e+001,2.369761e-006,0.000000e+000,3,7.250038e-001,0.000000e+000,,,,,,,,,,,,,,32,1,4.000000e+000,3.959656e-003,0.000000e+000,0,,0,
1524190683.573,,0.000000e+000,5.499972e+001,2.322228e-006,0.000000e+000,3,7.360273e-001,0.000000e+000,,,,,,,,,,,,,,32,1,4.000000e+000,5.268097e-003,0.000000e+000,0,,0,
1524190721.703,,0.000000e+000,5.499511e+001,2.410176e-006,0.000000e+000,3,7.618372e-001,0.000000e+000,,,,,,,,,,,,,,32,1,4.000000e+000,1.319885e-003,0.000000e+000,0,,0,
1524190759.673,,0.000000e+000,5.499906e+001,2.371166e-006,0.000000e+000,3,7.237090e-001,0.000000e+000,,,,,,,,,,,,,,32,1,4.000000e+000,9.220123e-003,0.000000e+000,0,,0,
1524190797.833,,0.000000e+000,5.500037e+001,2.207627e-006,0.000000e+000,3,7.245635e-001,0.000000e+000,,,,,,,,,,,,,,32,1,4.000000e+000,9.201050e-003,0.000000e+000,0,,0,
1524190834.683,,0.000000e+000,5.499709e+001,2.358462e-006,0.000000e+000,3,7.262126e-001,0.000000e+000,,,,,,,,,,,,,,32,1,4.000000e+000,7.888794e-003,0.000000e+000,0,,0,
1524190872.623,,0.000000e+000,5.499511e+001,2.289317e-006,0.000000e+000,3,7.433583e-001,0.000000e+000,,,,,,,,,,,,,,32,1,4.000000e+000,3.940582e-003,0.000000e+000,0,,0,
1524190910.243,,0.000000e+000,5.500497e+001,2.412673e-006,0.000000e+000,3,7.589943e-001,0.000000e+000,,,,,,,,,,,,,,32,1,4.000000e+000,1.578903e-002,0.000000e+000,0,,0,
1524190947.723,,0.000000e+000,5.500103e+001,2.349836e-006,0.000000e+000,3,7.311193e-001,0.000000e+000,,,,,,,,,,,,,,32,1,4.000000e+000,2.639771e-003,0.000000e+000,0,,0,
1524190985.933,,0.000000e+000,5.500431e+001,2.375581e-006,0.000000e+000,3,7.670450e-001,0.000000e+000,,,,,,,,,,,,,,32,1,4.000000e+000,1.184845e-002,0.000000e+000,0,,0,
1524191023.433,,0.000000e+000,5.499511e+001,2.399880e-006,0.000000e+000,3,7.371700e-001,0.000000e+000,,,,,,,,,,,,,,32,1,4.000000e+000,3.940582e-003,0.000000e+000,0,,0,
1524191060.513,,0.000000e+000,5.499905e+001,2.344677e-006,0.000000e+000,3,7.505229e-001,0.000000e+000,,,,,,,,,,,,,,32,1,4.000000e+000,3.948212e-003,0.000000e+000,0,,0,
1524191097.693,,0.000000e+000,5.499905e+001,2.432187e-006,0.000000e+000,3,7.314371e-001,0.000000e+000,,,,,,,,,,,,,,32,1,4.000000e+000,1.319885e-003,0.000000e+000,0,,0,
1524191135.663,,0.000000e+000,5.500037e+001,2.427700e-006,0.000000e+000,3,7.652144e-001,0.000000e+000,,,,,,,,,,,,,,32,1,4.000000e+000,1.319885e-003,0.000000e+000,0,,0,
1524191172.833,,0.000000e+000,5.500169e+001,2.497813e-006,0.000000e+000,3,7.371964e-001,0.000000e+000,,,,,,,,,,,,,,32,1,4.000000e+000,3.959656e-003,0.000000e+000,0,,0,
1524191210.203,,0.000000e+000,5.499774e+001,2.379545e-006,0.000000e+000,3,7.503180e-001,0.000000e+000,,,,,,,,,,,,,,32,1,4.000000e+000,6.580353e-003,0.000000e+000,0,,0,
1524191247.853,,0.000000e+000,5.500168e+001,2.451292e-006,0.000000e+000,3,7.395440e-001,0.000000e+000,,,,,,,,,,,,,,32,1,4.000000e+000,6.580353e-003,0.000000e+000,0,,0,
1524191285.794,,0.000000e+000,5.499841e+001,2.422667e-006,0.000000e+000,3,7.585199e-001,0.000000e+000,,,,,,,,,,,,,,32,1,4.000000e+000,1.052856e-002,0.000000e+000,0,,0,
1524191323.524,,0.000000e+000,5.499577e+001,2.499537e-006,0.000000e+000,3,7.342598e-001,0.000000e+000,,,,,,,,,,,,,,32,1,4.000000e+000,1.052094e-002,0.000000e+000,0,,0,
1524191361.524,,0.000000e+000,5.499445e+001,2.349875e-006,0.000000e+000,3,7.651581e-001,0.000000e+000,,,,,,,,,,,,,,32,1,4.000000e+000,5.260468e-003,0.000000e+000,0,,0,
1524191399.044,,0.000000e+000,5.500103e+001,2.442626e-006,0.000000e+000,3,7.639654e-001,0.000000e+000,,,,,,,,,,,,,,32,1,4.000000e+000,7.888794e-003,0.000000e+000,0,,0,
1524191436.674,,0.000000e+000,5.499511e+001,2.388289e-006,0.000000e+000,3,7.544022e-001,0.000000e+000,,,,,,,,,,,,,,32,1,4.000000e+000,6.568909e-003,0.000000e+000,0,,0,
1524191474.314,,0.000000e+000,5.499905e+001,2.484305e-006,0.000000e+000,3,7.748608e-001,0.000000e+000,,,,,,,,,,,,,,32,1,4.000000e+000,1.319885e-003,0.000000e+000,0,,0,
1524191511.774,,0.000000e+000,5.499642e+001,2.383867e-006,0.000000e+000,3,7.471301e-001,0.000000e+000,,,,,,,,,,,,,,32,1,4.000000e+000,3.940582e-003,0.000000e+000,0,,0,
1524191549.664,,0.000000e+000,5.500301e+001,2.533066e-006,0.000000e+000,3,7.752054e-001,0.000000e+000,,,,,,,,,,,,,,32,1,4.000000e+000,1.319885e-003,0.000000e+000,0,,0,
1524191586.764,,0.000000e+000,5.499773e+001,2.403551e-006,0.000000e+000,3,7.601013e-001,0.000000e+000,,,,,,,,,,,,,,32,1,4.000000e+000,1.308441e-003,0.000000e+000,0,,0,
1524191625.274,,0.000000e+000,5.499971e+001,2.479044e-006,0.000000e+000,3,7.759426e-001,0.000000e+000,,,,,,,,,,,,,,32,1,4.000000e+000,2.639771e-003,0.000000e+000,0,,0,
1524191663.024,,0.000000e+000,5.499511e+001,2.582480e-006,0.000000e+000,3,7.632688e-001,0.000000e+000,,,,,,,,,,,,,,32,1,4.000000e+000,1.184082e-002,0.000000e+000,0,,0,
1524191700.374,,0.000000e+000,5.500037e+001,2.476191e-006,0.000000e+000,3,7.803887e-001,0.000000e+000,,,,,,,,,,,,,,32,1,4.000000e+000,3.959656e-003,0.000000e+000,0,,0,
1524191738.304,,0.000000e+000,5.499971e+001,2.603505e-006,0.000000e+000,3,7.805703e-001,0.000000e+000,,,,,,,,,,,,,,32,1,4.000000e+000,2.639771e-003,0.000000e+000,0,,0,
1524191776.224,,0.000000e+000,5.499905e+001,2.526107e-006,0.000000e+000,3,7.775171e-001,0.000000e+000,,,,,,,,,,,,,,32,1,4.000000e+000,1.319885e-003,0.000000e+000,0,,0,
1524191814.024,,0.000000e+000,5.499642e+001,2.488129e-006,0.000000e+000,3,7.789557e-001,0.000000e+000,,,,,,,,,,,,,,32,1,4.000000e+000,3.940582e-003,0.000000e+000,0,,0,
1524191851.874,,0.000000e+000,5.499183e+001,2.489129e-006,0.000000e+000,3,7.732451e-001,0.000000e+000,,,,,,,,,,,,,,32,1,4.000000e+000,7.888794e-003,0.000000e+000,0,,0,
1524191890.174,,0.000000e+000,5.499577e+001,2.411190e-006,0.000000e+000,3,8.054515e-001,0.000000e+000,,,,,,,,,,,,,,32,1,4.000000e+000,7.888794e-003,0.000000e+000,0,,0,
1524191928.624,,0.000000e+000,5.499708e+001,2.572783e-006,0.000000e+000,3,7.587671e-001,0.000000e+000,,,,,,,,,,,,,,32,1,4.000000e+000,2.620697e-003,0.000000e+000,0,,0,
1524191966.734,,0.000000e+000,5.499642e+001,2.538484e-006,0.000000e+000,3,7.613895e-001,0.000000e+000,,,,,,,,,,,,,,32,1,4.000000e+000,3.940582e-003,0.000000e+000,0,,0,
1524192004.875,,0.000000e+000,5.499708e+001,2.529181e-006,0.000000e+000,3,7.821018e-001,0.000000e+000,,,,,,,,,,,,,,32,1,4.000000e+000,5.260468e-003,0.000000e+000,0,,0,
1524192042.475,,0.000000e+000,5.499511e+001,2.603184e-006,0.000000e+000,3,7.730789e-001,0.000000e+000,,,,,,,,,,,,,,32,1,4.000000e+000,1.184082e-002,0.000000e+000,0,,0,
1524192080.345,,0.000000e+000,5.499774e+001,2.520601e-006,0.000000e+000,3,7.918127e-001,0.000000e+000,,,,,,,,,,,,,,32,1,4.000000e+000,3.940582e-003,0.000000e+000,0,,0,
1524192117.745,,0.000000e+000,5.500169e+001,2.591951e-006,0.000000e+000,3,7.685830e-001,0.000000e+000,,,,,,,,,,,,,,32,1,4.000000e+000,1.319885e-003,0.000000e+000,0,,0,
1524192156.265,,0.000000e+000,5.499643e+001,2.543840e-006,0.000000e+000,3,7.791967e-001,0.000000e+000,,,,,,,,,,,,,,32,1,4.000000e+000,6.568909e-003,0.000000e+000,0,,0,
1524192193.955,,0.000000e+000,5.499905e+001,2.497575e-006,0.000000e+000,3,7.931573e-001,0.000000e+000,,,,,,,,,,,,,,32,1,4.000000e+000,1.319885e-003,0.000000e+000,0,,0,
1524192231.345,,0.000000e+000,5.500234e+001,2.612319e-006,0.000000e+000,3,7.950166e-001,0.000000e+000,,,,,,,,,,,,,,32,1,4.000000e+000,7.900238e-003,0.000000e+000,0,,0,
1524192269.005,,0.000000e+000,5.499839e+001,2.501928e-006,0.000000e+000,3,7.784235e-001,0.000000e+000,,,,,,,,,,,,,,32,1,4.000000e+000,0.000000e+000,0.000000e+000,0,,0,
1524192306.545,,0.000000e+000,5.499314e+001,2.603055e-006,0.000000e+000,3,7.738159e-001,0.000000e+000,,,,,,,,,,,,,,32,1,4.000000e+000,5.260468e-003,0.000000e+000,0,,0,
1524192344.065,,0.000000e+000,5.500169e+001,2.563291e-006,0.000000e+000,3,7.841392e-001,0.000000e+000,,,,,,,,,,,,,,32,1,4.000000e+000,1.319885e-003,0.000000e+000,0,,0,
1524192382.035,,0.000000e+000,5.499972e+001,2.512302e-006,0.000000e+000,3,7.930154e-001,0.000000e+000,,,,,,,,,,,,,,32,1,4.000000e+000,7.900238e-003,0.000000e+000,0,,0,
1524192419.775,,0.000000e+000,5.500103e+001,2.641074e-006,0.000000e+000,3,7.710621e-001,0.000000e+000,,,,,,,,,,,,,,32,1,4.000000e+000,1.052094e-002,0.000000e+000,0,,0,
1524192458.125,,0.000000e+000,5.499840e+001,2.547082e-006,0.000000e+000,3,7.953374e-001,0.000000e+000,,,,,,,,,,,,,,32,1,4.000000e+000,2.628326e-003,0.000000e+000,0,,0,
1524192495.935,,0.000000e+000,5.499445e+001,2.623855e-006,0.000000e+000,3,8.078426e-001,0.000000e+000,,,,,,,,,,,,,,32,1,4.000000e+000,7.881165e-003,0.000000e+000,0,,0,
1524192533.945,,0.000000e+000,5.499905e+001,2.560806e-006,0.000000e+000,3,7.752382e-001,0.000000e+000,,,,,,,,,,,,,,32,1,4.000000e+000,3.948212e-003,0.000000e+000,0,,0,
1524192572.265,,0.000000e+000,5.500168e+001,2.550245e-006,0.000000e+000,3,7.950388e-001,0.000000e+000,,,,,,,,,,,,,,32,1,4.000000e+000,6.580353e-003,0.000000e+000,0,,0,
1524192609.755,,0.000000e+000,5.499708e+001,2.517867e-006,0.000000e+000,3,7.790336e-001,0.000000e+000,,,,,,,,,,,,,,32,1,4.000000e+000,2.620697e-003,0.000000e+000,0,,0,
1524192649.455,,0.000000e+000,5.499971e+001,2.609906e-006,0.000000e+000,3,7.932834e-001,0.000000e+000,,,,,,,,,,,,,,32,1,4.000000e+000,2.639771e-003,0.000000e+000,0,,0,
1524192687.805,,0.000000e+000,5.499511e+001,2.495839e-006,0.000000e+000,3,7.882329e-001,0.000000e+000,,,,,,,,,,,,,,32,1,4.000000e+000,1.319885e-003,0.000000e+000,0,,0,
1524192725.866,,0.000000e+000,5.500037e+001,2.591556e-006,0.000000e+000,3,7.826253e-001,0.000000e+000,,,,,,,,,,,,,,32,1,4.000000e+000,3.959656e-003,0.000000e+000,0,,0,
1524192763.766,,0.000000e+000,5.499313e+001,2.610691e-006,0.000000e+000,3,7.946334e-001,0.000000e+000,,,,,,,,,,,,,,32,1,4.000000e+000,2.628326e-003,0.000000e+000,0,,0,
1524192802.426,,0.000000e+000,5.498853e+001,2.531433e-006,0.000000e+000,3,7.942782e-001,0.000000e+000,,,,,,,,,,,,,,32,1,4.000000e+000,9.212494e-003,0.000000e+000,0,,0,
1524192840.306,,0.000000e+000,5.499511e+001,2.552847e-006,0.000000e+000,3,8.094528e-001,0.000000e+000,,,,,,,,,,,,,,32,1,4.000000e+000,1.319885e-003,0.000000e+000,0,,0,
1524192878.566,,0.000000e+000,5.499774e+001,2.583914e-006,0.000000e+000,3,7.717651e-001,0.000000e+000,,,,,,,,,,,,,,32,1,4.000000e+000,3.940582e-003,0.000000e+000,0,,0,
1524192916.456,,0.000000e+000,5.499577e+001,2.643017e-006,0.000000e+000,3,8.060989e-001,0.000000e+000,,,,,,,,,,,,,,32,1,4.000000e+000,2.632141e-003,0.000000e+000,0,,0,
1524192955.086,,0.000000e+000,5.500300e+001,2.630648e-006,0.000000e+000,3,8.113776e-001,0.000000e+000,,,,,,,,,,,,,,32,1,4.000000e+000,1.183701e-002,0.000000e+000,0,,0,
1524192993.496,,0.000000e+000,5.500300e+001,2.701484e-006,0.000000e+000,3,7.879592e-001,0.000000e+000,,,,,,,,,,,,,,32,1,4.000000e+000,6.580353e-003,0.000000e+000,0,,0,
1524193031.106,,0.000000e+000,5.499906e+001,2.610621e-006,0.000000e+000,3,7.925410e-001,0.000000e+000,,,,,,,,,,,,,,32,1,4.000000e+000,6.580353e-003,0.000000e+000,0,,0,
1524193068.376,,0.000000e+000,5.499642e+001,2.698297e-006,0.000000e+000,3,8.113918e-001,0.000000e+000,,,,,,,,,,,,,,32,1,4.000000e+000,3.940582e-003,0.000000e+000,0,,0,
1524193106.326,,0.000000e+000,5.499511e+001,2.589797e-006,0.000000e+000,3,7.912489e-001,0.000000e+000,,,,,,,,,,,,,,32,1,4.000000e+000,3.940582e-003,0.000000e+000,0,,0,
1524193144.276,,0.000000e+000,5.500037e+001,2.610363e-006,0.000000e+000,3,7.963957e-001,0.000000e+000,,,,,,,,,,,,,,32,1,4.000000e+000,9.201050e-003,0.000000e+000,0,,0,
1524193182.666,,0.000000e+000,5.499380e+001,2.645733e-006,0.000000e+000,3,7.888432e-001,0.000000e+000,,,,,,,,,,,,,,32,1,4.000000e+000,1.308441e-003,0.000000e+000,0,,0,
1524193220.116,,0.000000e+000,5.499774e+001,2.556577e-006,0.000000e+000,3,8.123775e-001,0.000000e+000,,,,,,,,,,,,,,32,1,4.000000e+000,3.940582e-003,0.000000e+000,0,,0,
1524193257.766,,0.000000e+000,5.499577e+001,2.634575e-006,0.000000e+000,3,7.710875e-001,0.000000e+000,,,,,,,,,,,,,,32,1,4.000000e+000,5.249023e-003,0.000000e+000,0,,0,
1524193295.836,,0.000000e+000,5.499906e+001,2.654680e-006,0.000000e+000,3,8.069245e-001,0.000000e+000,,,,,,,,,,,,,,32,1,4.000000e+000,6.580353e-003,0.000000e+000,0,,0,
1524193333.496,,0.000000e+000,5.499248e+001,2.676072e-006,0.000000e+000,3,7.874399e-001,0.000000e+000,,,,,,,,,,,,,,32,1,4.000000e+000,1.182938e-002,0.000000e+000,0,,0,
1524193371.496,,0.000000e+000,5.499905e+001,2.679180e-006,0.000000e+000,3,8.034031e-001,0.000000e+000,,,,,,,,,,,,,,32,1,4.000000e+000,1.319885e-003,0.000000e+000,0,,0,
1524193409.167,,0.000000e+000,5.499840e+001,2.679037e-006,0.000000e+000,3,7.937759e-001,0.000000e+000,,,,,,,,,,,,,,32,1,4.000000e+000,1.578140e-002,0.000000e+000,0,,0,
1524193447.197,,0.000000e+000,5.500563e+001,2.637601e-006,0.000000e+000,3,7.917006e-001,0.000000e+000,,,,,,,,,,,,,,32,1,4.000000e+000,1.319885e-003,0.000000e+000,0,,0,
1524193484.347,,0.000000e+000,5.499708e+001,2.713947e-006,0.000000e+000,3,7.916328e-001,0.000000e+000,,,,,,,,,,,,,,32,1,4.000000e+000,0.000000e+000,0.000000e+000,0,,0,
1524193522.257,,0.000000e+000,5.500103e+001,2.622130e-006,0.000000e+000,3,8.026916e-001,0.000000e+000,,,,,,,,,,,,,,32,1,4.000000e+000,2.639771e-003,0.000000e+000,0,,0,
1524193559.927,,0.000000e+000,5.500695e+001,2.723744e-006,0.000000e+000,3,7.845223e-001,0.000000e+000,,,,,,,,,,,,,,32,1,4.000000e+000,9.201050e-003,0.000000e+000,0,,0,
1524193597.317,,0.000000e+000,5.499708e+001,2.645455e-006,0.000000e+000,3,8.134839e-001,0.000000e+000,,,,,,,,,,,,,,32,1,4.000000e+000,5.260468e-003,0.000000e+000,0,,0,
1524193634.377,,0.000000e+000,5.499445e+001,2.719534e-006,0.000000e+000,3,8.037258e-001,0.000000e+000,,,,,,,,,,,,,,32,1,4.000000e+000,0.000000e+000,0.000000e+000,0,,0,
1524193672.107,,0.000000e+000,5.500103e+001,2.665556e-006,0.000000e+000,3,8.150314e-001,0.000000e+000,,,,,,,,,,,,,,32,1,4.000000e+000,7.888794e-003,0.000000e+000,0,,0,
1524193709.927,,0.000000e+000,5.499773e+001,2.707761e-006,0.000000e+000,3,8.133502e-001,0.000000e+000,,,,,,,,,,,,,,32,1,4.000000e+000,1.308441e-003,0.000000e+000,0,,0,
1524193747.747,,0.000000e+000,5.499971e+001,2.712699e-006,0.000000e+000,3,8.055004e-001,0.000000e+000,,,,,,,,,,,,,,32,1,4.000000e+000,0.000000e+000,0.000000e+000,0,,0,
1524193785.567,,0.000000e+000,5.499380e+001,2.699647e-006,0.000000e+000,3,8.075021e-001,0.000000e+000,,,,,,,,,,,,,,32,1,4.000000e+000,1.308441e-003,0.000000e+000,0,,0,
1524193822.737,,0.000000e+000,5.499577e+001,2.748242e-006,0.000000e+000,3,8.339438e-001,0.000000e+000,,,,,,,,,,,,,,32,1,4.000000e+000,5.249023e-003,0.000000e+000,0,,0,
1524193861.037,,0.000000e+000,5.499971e+001,2.708871e-006,0.000000e+000,3,8.253867e-001,0.000000e+000,,,,,,,,,,,,,,32,1,4.000000e+000,1.840973e-002,0.000000e+000,0,,0,
1524193898.077,,0.000000e+000,5.499840e+001,2.747503e-006,0.000000e+000,3,7.974211e-001,0.000000e+000,,,,,,,,,,,,,,32,1,4.000000e+000,2.628326e-003,0.000000e+000,0,,0,
1524193935.947,,0.000000e+000,5.499577e+001,2.666390e-006,0.000000e+000,3,8.093404e-001,0.000000e+000,,,,,,,,,,,,,,32,1,4.000000e+000,0.000000e+000,0.000000e+000,0,,0,
1524193973.447,,0.000000e+000,5.499971e+001,2.839086e-006,0.000000e+000,3,8.112441e-001,0.000000e+000,,,,,,,,,,,,,,32,1,4.000000e+000,0.000000e+000,0.000000e+000,0,,0,
1524194010.737,,0.000000e+000,5.499642e+001,2.701513e-006,0.000000e+000,3,8.142844e-001,0.000000e+000,,,,,,,,,,,,,,32,1,4.000000e+000,3.940582e-003,0.000000e+000,0,,0,
1524194048.117,,0.000000e+000,5.499380e+001,2.787680e-006,0.000000e+000,3,8.092507e-001,0.000000e+000,,,,,,,,,,,,,,32,1,4.000000e+000,3.948212e-003,0.000000e+000,0,,0,
1524194086.347,,0.000000e+000,5.500498e+001,2.746134e-006,0.000000e+000,3,8.037925e-001,0.000000e+000,,,,,,,,,,,,,,32,1,4.000000e+000,2.620697e-003,0.000000e+000,0,,0,
1524194125.448,,0.000000e+000,5.499774e+001,2.756917e-006,0.000000e+000,3,8.226160e-001,0.000000e+000,,,,,,,,,,,,,,32,1,4.000000e+000,3.940582e-003,0.000000e+000,0,,0,
1524194163.248,,0.000000e+000,5.500103e+001,2.714193e-006,0.000000e+000,3,8.336301e-001,0.000000e+000,,,,,,,,,,,,,,32,1,4.000000e+000,5.279541e-003,0.000000e+000,0,,0,
1524194200.718,,0.000000e+000,5.499577e+001,2.729017e-006,0.000000e+000,3,8.102481e-001,0.000000e+000,,,,,,,,,,,,,,32,1,4.000000e+000,1.578903e-002,0.000000e+000,0,,0,
1524194238.428,,0.000000e+000,5.499906e+001,2.727133e-006,0.000000e+000,3,8.227836e-001,0.000000e+000,,,,,,,,,,,,,,32,1,4.000000e+000,6.580353e-003,0.000000e+000,0,,0,
1524194276.468,,0.000000e+000,5.499775e+001,2.762300e-006,0.000000e+000,3,8.014614e-001,0.000000e+000,,,,,,,,,,,,,,32,1,4.000000e+000,1.184845e-002,0.000000e+000,0,,0,
1524194314.218,,0.000000e+000,5.500234e+001,2.767966e-006,0.000000e+000,3,8.313329e-001,0.000000e+000,,,,,,,,,,,,,,32,1,4.000000e+000,5.260468e-003,0.000000e+000,0,,0,
1524194351.558,,0.000000e+000,5.500300e+001,2.837364e-006,0.000000e+000,3,8.136166e-001,0.000000e+000,,,,,,,,,,,,,,32,1,4.000000e+000,6.580353e-003,0.000000e+000,0,,0,
1524194389.328,,0.000000e+000,5.499380e+001,2.757675e-006,0.000000e+000,3,8.298277e-001,0.000000e+000,,,,,,,,,,,,,,32,1,4.000000e+000,3.948212e-003,0.000000e+000,0,,0,
1524194427.078,,0.000000e+000,5.499774e+001,2.778292e-006,0.000000e+000,3,8.083171e-001,0.000000e+000,,,,,,,,,,,,,,32,1,4.000000e+000,6.580353e-003,0.000000e+000,0,,0,
1524194464.988,,0.000000e+000,5.499774e+001,2.644369e-006,0.000000e+000,3,8.271105e-001,0.000000e+000,,,,,,,,,,,,,,32,1,4.000000e+000,6.580353e-003,0.000000e+000,0,,0,
1524194502.778,,0.000000e+000,5.500037e+001,2.802780e-006,0.000000e+000,3,8.255870e-001,0.000000e+000,,,,,,,,,,,,,,32,1,4.000000e+000,1.319885e-003,0.000000e+000,0,,0,
1524194540.638,,0.000000e+000,5.500300e+001,2.671509e-006,0.000000e+000,3,8.323662e-001,0.000000e+000,,,,,,,,,,,,,,32,1,4.000000e+000,1.183701e-002,0.000000e+000,0,,0,
1524194578.548,,0.000000e+000,5.500365e+001,2.826172e-006,0.000000e+000,3,8.037319e-001,0.000000e+000,,,,,,,,,,,,,,32,1,4.000000e+000,1.052856e-002,0.000000e+000,0,,0,
1524194615.978,,0.000000e+000,5.500037e+001,2.731540e-006,0.000000e+000,3,8.383025e-001,0.000000e+000,,,,,,,,,,,,,,32,1,4.000000e+000,1.319885e-003,0.000000e+000,0,,0,
1524194653.368,,0.000000e+000,5.500037e+001,2.844641e-006,0.000000e+000,3,8.217342e-001,0.000000e+000,,,,,,,,,,,,,,32,1,4.000000e+000,6.587982e-003,0.000000e+000,0,,0,
1524194691.278,,0.000000e+000,5.500168e+001,2.759043e-006,0.000000e+000,3,8.255944e-001,0.000000e+000,,,,,,,,,,,,,,32,1,4.000000e+000,6.580353e-003,0.000000e+000,0,,0,
1524194729.238,,0.000000e+000,5.500037e+001,2.733360e-006,0.000000e+000,3,8.337896e-001,0.000000e+000,,,,,,,,,,,,,,32,1,4.000000e+000,6.587982e-003,0.000000e+000,0,,0,
1524194767.228,,0.000000e+000,5.499971e+001,2.838777e-006,0.000000e+000,3,8.052170e-001,0.000000e+000,,,,,,,,,,,,,,32,1,4.000000e+000,2.639771e-003,0.000000e+000,0,,0,
1524194804.608,,0.000000e+000,5.499313e+001,2.682161e-006,0.000000e+000,3,8.452152e-001,0.000000e+000,,,,,,,,,,,,,,32,1,4.000000e+000,1.050949e-002,0.000000e+000,0,,0,
1524194842.239,,0.000000e+000,5.499708e+001,2.837519e-006,0.000000e+000,3,8.181979e-001,0.000000e+000,,,,,,,,,,,,,,32,1,4.000000e+000,2.620697e-003,0.000000e+000,0,,0,
1524194879.789,,0.000000e+000,5.498788e+001,2.730237e-006,0.000000e+000,3,8.324017e-001,0.000000e+000,,,,,,,,,,,,,,32,1,4.000000e+000,1.052094e-002,0.000000e+000,0,,0,
1524194917.299,,0.000000e+000,5.499905e+001,2.817987e-006,0.000000e+000,3,8.222477e-001,0.000000e+000,,,,,,,,,,,,,,32,1,4.000000e+000,3.948212e-003,0.000000e+000,0,,0,
1524194954.899,,0.000000e+000,5.499577e+001,2.796968e-006,0.000000e+000,3,8.306960e-001,0.000000e+000,,,,,,,,,,,,,,32,1,4.000000e+000,2.632141e-003,0.000000e+000,0,,0,
1524194992.889,,0.000000e+000,5.499577e+001,2.825511e-006,0.000000e+000,3,8.380464e-001,0.000000e+000,,,,,,,,,,,,,,32,1,4.000000e+000,2.104187e-002,0.000000e+000,0,,0,
1524195030.779,,0.000000e+000,5.499380e+001,2.774435e-006,0.000000e+000,3,8.384871e-001,0.000000e+000,,,,,,,,,,,,,,32,1,4.000000e+000,1.308441e-003,0.000000e+000,0,,0,
1524195068.529,,0.000000e+000,5.500300e+001,2.852446e-006,0.000000e+000,3,8.309624e-001,0.000000e+000,,,,,,,,,,,,,,32,1,4.000000e+000,6.580353e-003,0.000000e+000,0,,0,
1524195106.439,,0.000000e+000,5.499445e+001,2.763625e-006,0.000000e+000,3,8.415899e-001,0.000000e+000,,,,,,,,,,,,,,32,1,4.000000e+000,2.628326e-003,0.000000e+000,0,,0,
1524195144.239,,0.000000e+000,5.499773e+001,2.856365e-006,0.000000e+000,3,8.262027e-001,0.000000e+000,,,,,,,,,,,,,,32,1,4.000000e+000,1.308441e-003,0.000000e+000,0,,0,
1524195182.099,,0.000000e+000,5.499709e+001,2.766042e-006,0.000000e+000,3,8.376114e-001,0.000000e+000,,,,,,,,,,,,,,32,1,4.000000e+000,1.316071e-002,0.000000e+000,0,,0,
1524195219.859,,0.000000e+000,5.499905e+001,2.831486e-006,0.000000e+000,3,8.322703e-001,0.000000e+000,,,,,,,,,,,,,,32,1,4.000000e+000,3.948212e-003,0.000000e+000,0,,0,
1524195257.769,,0.000000e+000,5.499511e+001,2.791374e-006,0.000000e+000,3,8.446340e-001,0.000000e+000,,,,,,,,,,,,,,32,1,4.000000e+000,3.940582e-003,0.000000e+000,0,,0,
1524195295.459,,0.000000e+000,5.499314e+001,2.870018e-006,0.000000e+000,3,8.245072e-001,0.000000e+000,,,,,,,,,,,,,,32,1,4.000000e+000,0.000000e+000,0.000000e+000,0,,0,
1524195333.129,,0.000000e+000,5.499840e+001,2.781529e-006,0.000000e+000,3,8.303996e-001,0.000000e+000,,,,,,,,,,,,,,32,1,4.000000e+000,2.628326e-003,0.000000e+000,0,,0,
1524195370.399,,0.000000e+000,5.500300e+001,2.920008e-006,0.000000e+000,3,8.371990e-001,0.000000e+000,,,,,,,,,,,,,,32,1,4.000000e+000,1.183701e-002,0.000000e+000,0,,0,
1524195408.239,,0.000000e+000,5.499840e+001,2.804396e-006,0.000000e+000,3,8.352379e-001,0.000000e+000,,,,,,,,,,,,,,32,1,4.000000e+000,2.628326e-003,0.000000e+000,0,,0,
1524195445.859,,0.000000e+000,5.500563e+001,2.895148e-006,0.000000e+000,3,8.298814e-001,0.000000e+000,,,,,,,,,,,,,,32,1,4.000000e+000,1.319885e-003,0.000000e+000,0,,0,
1524195483.889,,0.000000e+000,5.499906e+001,2.806605e-006,0.000000e+000,3,8.335112e-001,0.000000e+000,,,,,,,,,,,,,,32,1,4.000000e+000,6.580353e-003,0.000000e+000,0,,0,
1524195521.519,,0.000000e+000,5.500037e+001,2.867749e-006,0.000000e+000,3,8.214108e-001,0.000000e+000,,,,,,,,,,,,,,32,1,4.000000e+000,6.587982e-003,0.000000e+000,0,,0,
1524195559.420,,0.000000e+000,5.500234e+001,2.898497e-006,0.000000e+000,3,8.456973e-001,0.000000e+000,,,,,,,,,,,,,,32,1,4.000000e+000,5.260468e-003,0.000000e+000,0,,0,
1524195597.130,,0.000000e+000,5.499445e+001,2.860943e-006,0.000000e+000,3,8.187454e-001,0.000000e+000,,,,,,,,,,,,,,32,1,4.000000e+000,1.052094e-002,0.000000e+000,0,,0,
1524195635.180,,0.000000e+000,5.499773e+001,2.812649e-006,0.000000e+000,3,8.277891e-001,0.000000e+000,,,,,,,,,,,,,,32,1,4.000000e+000,1.308441e-003,0.000000e+000,0,,0,
1524195672.830,,0.000000e+000,5.499380e+001,2.886510e-006,0.000000e+000,3,8.272625e-001,0.000000e+000,,,,,,,,,,,,,,32,1,4.000000e+000,1.710129e-002,0.000000e+000,0,,0,
1524195710.860,,0.000000e+000,5.499643e+001,2.854001e-006,0.000000e+000,3,8.351579e-001,0.000000e+000,,,,,,,,,,,,,,32,1,4.000000e+000,1.184082e-002,0.000000e+000,0,,0,
1524195748.430,,0.000000e+000,5.499445e+001,2.981873e-006,0.000000e+000,3,8.179790e-001,0.000000e+000,,,,,,,,,,,,,,32,1,4.000000e+000,2.628326e-003,0.000000e+000,0,,0,
1524195785.910,,0.000000e+000,5.499905e+001,2.882926e-006,0.000000e+000,3,8.205403e-001,0.000000e+000,,,,,,,,,,,,,,32,1,4.000000e+000,1.319885e-003,0.000000e+000,0,,0,
1524195824.870,,0.000000e+000,5.500234e+001,2.887650e-006,0.000000e+000,3,8.392161e-001,0.000000e+000,,,,,,,,,,,,,,32,1,4.000000e+000,5.260468e-003,0.000000e+000,0,,0,
1524195862.240,,0.000000e+000,5.499840e+001,2.927708e-006,0.000000e+000,3,8.532190e-001,0.000000e+000,,,,,,,,,,,,,,32,1,4.000000e+000,2.628326e-003,0.000000e+000,0,,0,
1524195899.360,,0.000000e+000,5.499774e+001,2.889010e-006,0.000000e+000,3,8.323771e-001,0.000000e+000,,,,,,,,,,,,,,32,1,4.000000e+000,6.580353e-003,0.000000e+000,0,,0,
1524195937.000,,0.000000e+000,5.499775e+001,2.857246e-006,0.000000e+000,3,8.464271e-001,0.000000e+000,,,,,,,,,,,,,,32,1,4.000000e+000,1.184845e-002,0.000000e+000,0,,0,
1524195974.880,,0.000000e+000,5.499840e+001,2.951221e-006,0.000000e+000,3,8.195000e-001,0.000000e+000,,,,,,,,,,,,,,32,1,4.000000e+000,2.628326e-003,0.000000e+000,0,,0,
1524196012.880,,0.000000e+000,5.499774e+001,2.868372e-006,0.000000e+000,3,8.383359e-001,0.000000e+000,,,,,,,,,,,,,,32,1,4.000000e+000,6.580353e-003,0.000000e+000,0,,0,
1524196049.910,,0.000000e+000,5.499182e+001,2.930457e-006,0.000000e+000,3,8.286585e-001,0.000000e+000,,,,,,,,,,,,,,32,1,4.000000e+000,5.260468e-003,0.000000e+000,0,,0,
1524196088.160,,0.000000e+000,5.500103e+001,2.857808e-006,0.000000e+000,3,8.451625e-001,0.000000e+000,,,,,,,,,,,,,,32,1,4.000000e+000,2.639771e-003,0.000000e+000,0,,0,
1524196125.710,,0.000000e+000,5.499511e+001,2.906111e-006,0.000000e+000,3,8.257499e-001,0.000000e+000,,,,,,,,,,,,,,32,1,4.000000e+000,3.940582e-003,0.000000e+000,0,,0,
1524196163.090,,0.000000e+000,5.499248e+001,2.834855e-006,0.000000e+000,3,8.480473e-001,0.000000e+000,,,,,,,,,,,,,,32,1,4.000000e+000,6.580353e-003,0.000000e+000,0,,0,
1524196201.040,,0.000000e+000,5.499840e+001,2.949723e-006,0.000000e+000,3,8.329172e-001,0.000000e+000,,,,,,,,,,,,,,32,1,4.000000e+000,7.900238e-003,0.000000e+000,0,,0,
1524196238.420,,0.000000e+000,5.499774e+001,2.864296e-006,0.000000e+000,3,8.369737e-001,0.000000e+000,,,,,,,,,,,,,,32,1,4.000000e+000,6.580353e-003,0.000000e+000,0,,0,
1524196276.741,,0.000000e+000,5.500103e+001,2.897415e-006,0.000000e+000,3,8.374378e-001,0.000000e+000,,,,,,,,,,,,,,32,1,4.000000e+000,2.639771e-003,0.000000e+000,0,,0,
1524196314.241,,0.000000e+000,5.499905e+001,2.941328e-006,0.000000e+000,3,8.334003e-001,0.000000e+000,,,,,,,,,,,,,,32,1,4.000000e+000,1.319885e-003,0.000000e+000,0,,0,
1524196326.981,,0.000000e+000,5.499445e+001,2.901096e-006,0.000000e+000,3,8.565472e-001,0.000000e+000,,,,,,,,,,,,,,32,1,4.000000e+000,7.881165e-003,0.000000e+000,0,,0,