File: Experimental Raw Data/TC04-12-01K Adjusting Iterative/TC04-12-01K_TRMac_56K_0.16Kmin_VRMde_55K.dc.dat
[Header]
TITLE,MPMS DC Measurement
BYAPP,MPMS Measurement,2.1,Summary
FILEOPENTIME, 1524430347.419000 4/22/2018, 2:52:27 PM

INFO, APPNAME, MPMS MultiVu Application, Revision 1.61,  Build 082

INFO, NAME, TC04-12-01K
INFO, WEIGHT, 1.000
INFO, AREA, 1.000
INFO, LENGTH, 1.000
INFO, SHAPE, 0
INFO, COMMENT,
INFO, SEQUENCE FILE: TRMac_56K_0.16Kmin_VRMde_55K.seq


INFO, BACKGROUND DATA FILE:, None


STARTUPAXIS,X,4,LINEAR,AUTO,0.000000,0.000000
STARTUPAXIS,Y1,5,LINEAR,AUTO,0.000000,0.000000


STARTUPGROUP,Longitudinal
FIELDGROUP,Longitudinal,1,2,3,4,5,6,7,8,9,15,16,17,18,27,28
FIELDGROUP,Transverse,1,2,3,4,10,11,12,13,14,19,20,21,22,27,28

PLOT_APPEARANCE,ALL,HORZ_GRID_ON,VERT_GRID_ON,MARKERS_AND_LINES

[Data]
Time,Comment,Field (Oe),Temperature (K),Long Moment (emu),Long Scan Std Dev,Long Algorithm,Long Reg Fit,Long Percent Error (%),Trans Moment (emu),Trans Scan Std Dev,Trans Algorithm,Trans Reg Fit,Trans Percent Error (%),Long Moment [w/o ABS] (emu),Long Scan Std Dev [w/o ABS],Long Reg Fit [w/o ABS],Long Percent Error [w/o ABS] (%),Trans Moment [w/o ABS] (emu),Trans Scan Std Dev [w/o ABS],Trans Reg Fit [w/o ABS],Trans Percent Error [w/o ABS] (%),Points per Scan,Scans per Measurement,Scan Length (cm),Delta Temp (K),Rot Position (deg),Error,EC Comp. Running,Using ABS,
1524430347.419,,0.000000e+000,5.498919e+001,-6.297394e-006,0.000000e+000,3,9.617029e-001,0.000000e+000,,,,,,,,,,,,,,32,1,4.000000e+000,5.260468e-003,0.000000e+000,0,,0,
1524430385.469,,0.000000e+000,5.499445e+001,-3.669954e-006,0.000000e+000,3,9.060485e-001,0.000000e+000,,,,,,,,,,,,,,32,1,4.000000e+000,5.260468e-003,0.000000e+000,0,,0,
1524430423.450,,0.000000e+000,5.499445e+001,-2.537625e-006,0.000000e+000,3,8.553368e-001,0.000000e+000,,,,,,,,,,,,,,32,1,4.000000e+000,2.628326e-003,0.000000e+000,0,,0,
1524430461.030,,0.000000e+000,5.499445e+001,-2.220090e-006,0.000000e+000,3,7.598693e-001,0.000000e+000,,,,,,,,,,,,,,32,1,4.000000e+000,2.628326e-003,0.000000e+000,0,,0,
1524430503.202,,0.000000e+000,5.499511e+001,-6.587547e-009,0.000000e+000,2,0.000000e+000,0.000000e+000,,,,,,,,,,,,,,32,1,4.000000e+000,1.319885e-003,0.000000e+000,0,,0,
1524430545.828,,0.000000e+000,5.499445e+001,5.963631e-007,0.000000e+000,2,0.000000e+000,0.000000e+000,,,,,,,,,,,,,,32,1,4.000000e+000,1.052094e-002,0.000000e+000,0,,0,
1524430584.358,,0.000000e+000,5.500103e+001,2.216925e-006,0.000000e+000,3,7.427894e-001,0.000000e+000,,,,,,,,,,,,,,32,1,4.000000e+000,2.639771e-003,0.000000e+000,0,,0,
1524430622.108,,0.000000e+000,5.500365e+001,2.337566e-006,0.000000e+000,3,7.905404e-001,0.000000e+000,,,,,,,,,,,,,,32,1,4.000000e+000,1.052856e-002,0.000000e+000,0,,0,
1524430659.438,,0.000000e+000,5.499773e+001,2.542865e-006,0.000000e+000,3,7.962481e-001,0.000000e+000,,,,,,,,,,,,,,32,1,4.000000e+000,1.308441e-003,0.000000e+000,0,,0,
1524430698.078,,0.000000e+000,5.499972e+001,2.624375e-006,0.000000e+000,3,8.292361e-001,0.000000e+000,,,,,,,,,,,,,,32,1,4.000000e+000,1.578903e-002,0.000000e+000,0,,0,
1524430735.348,,0.000000e+000,5.500037e+001,2.786754e-006,0.000000e+000,3,8.306156e-001,0.000000e+000,,,,,,,,,,,,,,32,1,4.000000e+000,3.959656e-003,0.000000e+000,0,,0,
1524430772.728,,0.000000e+000,5.500169e+001,2.867989e-006,0.000000e+000,3,8.579535e-001,0.000000e+000,,,,,,,,,,,,,,32,1,4.000000e+000,1.319885e-003,0.000000e+000,0,,0,
1524430810.468,,0.000000e+000,5.499906e+001,2.982294e-006,0.000000e+000,3,8.498216e-001,0.000000e+000,,,,,,,,,,,,,,32,1,4.000000e+000,9.220123e-003,0.000000e+000,0,,0,
1524430848.318,,0.000000e+000,5.498919e+001,3.029001e-006,0.000000e+000,3,8.581496e-001,0.000000e+000,,,,,,,,,,,,,,32,1,4.000000e+000,5.260468e-003,0.000000e+000,0,,0,
1524430886.188,,0.000000e+000,5.499971e+001,3.190740e-006,0.000000e+000,3,8.646802e-001,0.000000e+000,,,,,,,,,,,,,,32,1,4.000000e+000,2.639771e-003,0.000000e+000,0,,0,
1524430925.058,,0.000000e+000,5.500366e+001,3.231851e-006,0.000000e+000,3,8.923159e-001,0.000000e+000,,,,,,,,,,,,,,32,1,4.000000e+000,2.620697e-003,0.000000e+000,0,,0,
1524430962.758,,0.000000e+000,5.499380e+001,3.260684e-006,0.000000e+000,3,8.910066e-001,0.000000e+000,,,,,,,,,,,,,,32,1,4.000000e+000,1.308441e-003,0.000000e+000,0,,0,
1524431000.548,,0.000000e+000,5.499774e+001,3.368202e-006,0.000000e+000,3,8.697041e-001,0.000000e+000,,,,,,,,,,,,,,32,1,4.000000e+000,6.580353e-003,0.000000e+000,0,,0,
1524431038.428,,0.000000e+000,5.500563e+001,3.343632e-006,0.000000e+000,3,8.913251e-001,0.000000e+000,,,,,,,,,,,,,,32,1,4.000000e+000,9.208679e-003,0.000000e+000,0,,0,
1524431076.138,,0.000000e+000,5.499709e+001,3.498280e-006,0.000000e+000,3,8.761038e-001,0.000000e+000,,,,,,,,,,,,,,32,1,4.000000e+000,1.316071e-002,0.000000e+000,0,,0,
1524431114.028,,0.000000e+000,5.500169e+001,3.500565e-006,0.000000e+000,3,8.857701e-001,0.000000e+000,,,,,,,,,,,,,,32,1,4.000000e+000,1.319885e-003,0.000000e+000,0,,0,
1524431151.729,,0.000000e+000,5.499643e+001,3.639017e-006,0.000000e+000,3,8.832220e-001,0.000000e+000,,,,,,,,,,,,,,32,1,4.000000e+000,6.568909e-003,0.000000e+000,0,,0,
1524431189.609,,0.000000e+000,5.499841e+001,3.617920e-006,0.000000e+000,3,8.923189e-001,0.000000e+000,,,,,,,,,,,,,,32,1,4.000000e+000,1.052856e-002,0.000000e+000,0,,0,
1524431227.119,,0.000000e+000,5.499840e+001,3.702114e-006,0.000000e+000,3,8.880497e-001,0.000000e+000,,,,,,,,,,,,,,32,1,4.000000e+000,5.260468e-003,0.000000e+000,0,,0,
1524431278.359,,0.000000e+000,5.499577e+001,3.726863e-006,0.000000e+000,3,9.123468e-001,0.000000e+000,,,,,,,,,,,,,,32,1,4.000000e+000,7.888794e-003,0.000000e+000,0,,0,
1524431316.809,,0.000000e+000,5.500103e+001,3.825192e-006,0.000000e+000,3,8.785018e-001,0.000000e+000,,,,,,,,,,,,,,32,1,4.000000e+000,5.279541e-003,0.000000e+000,0,,0,
1524431354.739,,0.000000e+000,5.499511e+001,3.978335e-006,0.000000e+000,3,8.948314e-001,0.000000e+000,,,,,,,,,,,,,,32,1,4.000000e+000,1.319885e-003,0.000000e+000,0,,0,
1524431392.379,,0.000000e+000,5.499905e+001,3.941043e-006,0.000000e+000,3,8.879130e-001,0.000000e+000,,,,,,,,,,,,,,32,1,4.000000e+000,1.182938e-002,0.000000e+000,0,,0,
1524431430.299,,0.000000e+000,5.500169e+001,4.042254e-006,0.000000e+000,3,9.018162e-001,0.000000e+000,,,,,,,,,,,,,,32,1,4.000000e+000,1.709747e-002,0.000000e+000,0,,0,
1524431468.139,,0.000000e+000,5.500103e+001,3.942517e-006,0.000000e+000,3,8.977007e-001,0.000000e+000,,,,,,,,,,,,,,32,1,4.000000e+000,2.639771e-003,0.000000e+000,0,,0,
1524431505.209,,0.000000e+000,5.499445e+001,4.040509e-006,0.000000e+000,3,8.900335e-001,0.000000e+000,,,,,,,,,,,,,,32,1,4.000000e+000,5.260468e-003,0.000000e+000,0,,0,
1524431543.659,,0.000000e+000,5.499905e+001,4.128766e-006,0.000000e+000,3,9.048082e-001,0.000000e+000,,,,,,,,,,,,,,32,1,4.000000e+000,3.948212e-003,0.000000e+000,0,,0,
1524431580.769,,0.000000e+000,5.498919e+001,4.067356e-006,0.000000e+000,3,8.884773e-001,0.000000e+000,,,,,,,,,,,,,,32,1,4.000000e+000,0.000000e+000,0.000000e+000,0,,0,
1524431618.709,,0.000000e+000,5.499643e+001,4.169841e-006,0.000000e+000,3,8.876222e-001,0.000000e+000,,,,,,,,,,,,,,32,1,4.000000e+000,1.312256e-003,0.000000e+000,0,,0,
1524431657.239,,0.000000e+000,5.500169e+001,4.125875e-006,0.000000e+000,3,8.985454e-001,0.000000e+000,,,,,,,,,,,,,,32,1,4.000000e+000,3.959656e-003,0.000000e+000,0,,0,
1524431694.709,,0.000000e+000,5.499577e+001,4.186611e-006,0.000000e+000,3,8.971998e-001,0.000000e+000,,,,,,,,,,,,,,32,1,4.000000e+000,2.632141e-003,0.000000e+000,0,,0,
1524431732.729,,0.000000e+000,5.499314e+001,4.188657e-006,0.000000e+000,3,9.065001e-001,0.000000e+000,,,,,,,,,,,,,,32,1,4.000000e+000,0.000000e+000,0.000000e+000,0,,0,
1524431770.569,,0.000000e+000,5.500169e+001,4.212906e-006,0.000000e+000,3,8.929439e-001,0.000000e+000,,,,,,,,,,,,,,32,1,4.000000e+000,3.959656e-003,0.000000e+000,0,,0,
1524431809.079,,0.000000e+000,5.499445e+001,4.210386e-006,0.000000e+000,3,8.924976e-001,0.000000e+000,,,,,,,,,,,,,,32,1,4.000000e+000,1.052094e-002,0.000000e+000,0,,0,
1524431847.120,,0.000000e+000,5.499577e+001,4.209736e-006,0.000000e+000,3,9.078631e-001,0.000000e+000,,,,,,,,,,,,,,32,1,4.000000e+000,7.888794e-003,0.000000e+000,0,,0,
1524431885.060,,0.000000e+000,5.499577e+001,4.234479e-006,0.000000e+000,3,8.961056e-001,0.000000e+000,,,,,,,,,,,,,,32,1,4.000000e+000,0.000000e+000,0.000000e+000,0,,0,
1524431923.560,,0.000000e+000,5.499248e+001,4.318497e-006,0.000000e+000,3,8.878005e-001,0.000000e+000,,,,,,,,,,,,,,32,1,4.000000e+000,6.580353e-003,0.000000e+000,0,,0,
1524431961.250,,0.000000e+000,5.499774e+001,4.276130e-006,0.000000e+000,3,9.097729e-001,0.000000e+000,,,,,,,,,,,,,,32,1,4.000000e+000,3.940582e-003,0.000000e+000,0,,0,
1524431998.880,,0.000000e+000,5.499577e+001,4.294141e-006,0.000000e+000,3,8.947874e-001,0.000000e+000,,,,,,,,,,,,,,32,1,4.000000e+000,5.249023e-003,0.000000e+000,0,,0,
1524432036.560,,0.000000e+000,5.499905e+001,4.364392e-006,0.000000e+000,3,9.046670e-001,0.000000e+000,,,,,,,,,,,,,,32,1,4.000000e+000,1.319885e-003,0.000000e+000,0,,0,
1524432074.290,,0.000000e+000,5.499314e+001,4.288068e-006,0.000000e+000,3,9.021464e-001,0.000000e+000,,,,,,,,,,,,,,32,1,4.000000e+000,5.260468e-003,0.000000e+000,0,,0,
1524432112.710,,0.000000e+000,5.498920e+001,4.340949e-006,0.000000e+000,3,9.144778e-001,0.000000e+000,,,,,,,,,,,,,,32,1,4.000000e+000,2.628326e-003,0.000000e+000,0,,0,
1524432150.910,,0.000000e+000,5.499380e+001,4.401571e-006,0.000000e+000,3,8.892198e-001,0.000000e+000,,,,,,,,,,,,,,32,1,4.000000e+000,3.948212e-003,0.000000e+000,0,,0,
1524432203.740,,0.000000e+000,5.499445e+001,4.485504e-006,0.000000e+000,3,9.390660e-001,0.000000e+000,,,,,,,,,,,,,,32,1,4.000000e+000,2.367020e-002,0.000000e+000,0,,0,
1524432240.930,,0.000000e+000,5.499708e+001,4.438226e-006,0.000000e+000,3,9.108666e-001,0.000000e+000,,,,,,,,,,,,,,32,1,4.000000e+000,2.620697e-003,0.000000e+000,0,,0,
1524432278.410,,0.000000e+000,5.500103e+001,4.430481e-006,0.000000e+000,3,8.997476e-001,0.000000e+000,,,,,,,,,,,,,,32,1,4.000000e+000,2.639771e-003,0.000000e+000,0,,0,
1524432316.650,,0.000000e+000,5.500301e+001,4.470530e-006,0.000000e+000,3,9.187665e-001,0.000000e+000,,,,,,,,,,,,,,32,1,4.000000e+000,1.319885e-003,0.000000e+000,0,,0,
1524432354.760,,0.000000e+000,5.499183e+001,4.444026e-006,0.000000e+000,3,9.117743e-001,0.000000e+000,,,,,,,,,,,,,,32,1,4.000000e+000,2.368927e-002,0.000000e+000,0,,0,
1524432392.600,,0.000000e+000,5.499708e+001,4.480113e-006,0.000000e+000,3,9.034346e-001,0.000000e+000,,,,,,,,,,,,,,32,1,4.000000e+000,2.620697e-003,0.000000e+000,0,,0,
1524432430.030,,0.000000e+000,5.499643e+001,4.473482e-006,0.000000e+000,3,9.125140e-001,0.000000e+000,,,,,,,,,,,,,,32,1,4.000000e+000,1.312256e-003,0.000000e+000,0,,0,
1524432467.880,,0.000000e+000,5.499445e+001,4.461248e-006,0.000000e+000,3,9.064665e-001,0.000000e+000,,,,,,,,,,,,,,32,1,4.000000e+000,5.260468e-003,0.000000e+000,0,,0,
1524432505.930,,0.000000e+000,5.499840e+001,4.503466e-006,0.000000e+000,3,8.946283e-001,0.000000e+000,,,,,,,,,,,,,,32,1,4.000000e+000,5.260468e-003,0.000000e+000,0,,0,
1524432543.520,,0.000000e+000,5.499380e+001,4.466539e-006,0.000000e+000,3,9.108796e-001,0.000000e+000,,,,,,,,,,,,,,32,1,4.000000e+000,1.308441e-003,0.000000e+000,0,,0,
1524432581.691,,0.000000e+000,5.499905e+001,4.477011e-006,0.000000e+000,3,9.051211e-001,0.000000e+000,,,,,,,,,,,,,,32,1,4.000000e+000,1.319885e-003,0.000000e+000,0,,0,
1524432619.571,,0.000000e+000,5.499971e+001,4.509452e-006,0.000000e+000,3,9.116465e-001,0.000000e+000,,,,,,,,,,,,,,32,1,4.000000e+000,2.639771e-003,0.000000e+000,0,,0,
1524432657.791,,0.000000e+000,5.499248e+001,4.473780e-006,0.000000e+000,3,9.047779e-001,0.000000e+000,,,,,,,,,,,,,,32,1,4.000000e+000,9.201050e-003,0.000000e+000,0,,0,
1524432695.471,,0.000000e+000,5.499511e+001,4.579756e-006,0.000000e+000,3,9.007958e-001,0.000000e+000,,,,,,,,,,,,,,32,1,4.000000e+000,3.940582e-003,0.000000e+000,0,,0,
1524432733.541,,0.000000e+000,5.500037e+001,4.527710e-006,0.000000e+000,3,9.093193e-001,0.000000e+000,,,,,,,,,,,,,,32,1,4.000000e+000,1.319885e-003,0.000000e+000,0,,0,
1524432771.161,,0.000000e+000,5.499773e+001,4.597538e-006,0.000000e+000,3,9.026557e-001,0.000000e+000,,,,,,,,,,,,,,32,1,4.000000e+000,1.308441e-003,0.000000e+000,0,,0,
1524432809.091,,0.000000e+000,5.500037e+001,4.561149e-006,0.000000e+000,3,9.101210e-001,0.000000e+000,,,,,,,,,,,,,,32,1,4.000000e+000,3.959656e-003,0.000000e+000,0,,0,
1524432846.731,,0.000000e+000,5.499906e+001,4.523245e-006,0.000000e+000,3,9.128909e-001,0.000000e+000,,,,,,,,,,,,,,32,1,4.000000e+000,9.220123e-003,0.000000e+000,0,,0,
1524432884.501,,0.000000e+000,5.499972e+001,4.623342e-006,0.000000e+000,3,9.094383e-001,0.000000e+000,,,,,,,,,,,,,,32,1,4.000000e+000,5.268097e-003,0.000000e+000,0,,0,
1524432922.531,,0.000000e+000,5.499906e+001,4.569851e-006,0.000000e+000,3,9.170604e-001,0.000000e+000,,,,,,,,,,,,,,32,1,4.000000e+000,9.220123e-003,0.000000e+000,0,,0,
1524432960.141,,0.000000e+000,5.500432e+001,4.584433e-006,0.000000e+000,3,9.080102e-001,0.000000e+000,,,,,,,,,,,,,,32,1,4.000000e+000,3.940582e-003,0.000000e+000,0,,0,
1524432998.101,,0.000000e+000,5.499708e+001,4.573194e-006,0.000000e+000,3,9.215697e-001,0.000000e+000,,,,,,,,,,,,,,32,1,4.000000e+000,2.620697e-003,0.000000e+000,0,,0,
1524433035.271,,0.000000e+000,5.499773e+001,4.581407e-006,0.000000e+000,3,9.176363e-001,0.000000e+000,,,,,,,,,,,,,,32,1,4.000000e+000,1.308441e-003,0.000000e+000,0,,0,
1524433073.191,,0.000000e+000,5.499972e+001,4.612319e-006,0.000000e+000,3,9.150057e-001,0.000000e+000,,,,,,,,,,,,,,32,1,4.000000e+000,7.900238e-003,0.000000e+000,0,,0,
1524433123.651,,0.000000e+000,5.500301e+001,4.642866e-006,0.000000e+000,3,9.399069e-001,0.000000e+000,,,,,,,,,,,,,,32,1,4.000000e+000,1.319885e-003,0.000000e+000,0,,0,
1524433161.111,,0.000000e+000,5.499709e+001,4.597172e-006,0.000000e+000,3,9.154190e-001,0.000000e+000,,,,,,,,,,,,,,32,1,4.000000e+000,7.888794e-003,0.000000e+000,0,,0,
1524433199.621,,0.000000e+000,5.500037e+001,4.567118e-006,0.000000e+000,3,9.052301e-001,0.000000e+000,,,,,,,,,,,,,,32,1,4.000000e+000,3.959656e-003,0.000000e+000,0,,0,
1524433237.431,,0.000000e+000,5.500300e+001,4.538737e-006,0.000000e+000,3,9.202651e-001,0.000000e+000,,,,,,,,,,,,,,32,1,4.000000e+000,6.580353e-003,0.000000e+000,0,,0,
1524433275.182,,0.000000e+000,5.500169e+001,4.565107e-006,0.000000e+000,3,9.118978e-001,0.000000e+000,,,,,,,,,,,,,,32,1,4.000000e+000,1.319885e-003,0.000000e+000,0,,0,
1524433312.562,,0.000000e+000,5.499511e+001,4.579724e-006,0.000000e+000,3,9.218579e-001,0.000000e+000,,,,,,,,,,,,,,32,1,4.000000e+000,6.568909e-003,0.000000e+000,0,,0,
1524433350.242,,0.000000e+000,5.500103e+001,4.597108e-006,0.000000e+000,3,9.156573e-001,0.000000e+000,,,,,,,,,,,,,,32,1,4.000000e+000,0.000000e+000,0.000000e+000,0,,0,
1524433387.972,,0.000000e+000,5.499511e+001,4.583590e-006,0.000000e+000,3,9.268068e-001,0.000000e+000,,,,,,,,,,,,,,32,1,4.000000e+000,1.319885e-003,0.000000e+000,0,,0,
1524433425.302,,0.000000e+000,5.499577e+001,4.585877e-006,0.000000e+000,3,9.071052e-001,0.000000e+000,,,,,,,,,,,,,,32,1,4.000000e+000,7.888794e-003,0.000000e+000,0,,0,
1524433462.812,,0.000000e+000,5.499972e+001,4.581329e-006,0.000000e+000,3,9.110996e-001,0.000000e+000,,,,,,,,,,,,,,32,1,4.000000e+000,7.900238e-003,0.000000e+000,0,,0,
1524433500.792,,0.000000e+000,5.499840e+001,4.603235e-006,0.000000e+000,3,9.185057e-001,0.000000e+000,,,,,,,,,,,,,,32,1,4.000000e+000,5.260468e-003,0.000000e+000,0,,0,
1524433538.562,,0.000000e+000,5.500169e+001,4.666497e-006,0.000000e+000,3,9.119909e-001,0.000000e+000,,,,,,,,,,,,,,32,1,4.000000e+000,3.959656e-003,0.000000e+000,0,,0,
1524433576.792,,0.000000e+000,5.499906e+001,4.624149e-006,0.000000e+000,3,9.275737e-001,0.000000e+000,,,,,,,,,,,,,,32,1,4.000000e+000,6.580353e-003,0.000000e+000,0,,0,
1524433614.312,,0.000000e+000,5.499380e+001,4.639250e-006,0.000000e+000,3,9.116665e-001,0.000000e+000,,,,,,,,,,,,,,32,1,4.000000e+000,1.308441e-003,0.000000e+000,0,,0,
1524433652.262,,0.000000e+000,5.499577e+001,4.610009e-006,0.000000e+000,3,9.181753e-001,0.000000e+000,,,,,,,,,,,,,,32,1,4.000000e+000,2.632141e-003,0.000000e+000,0,,0,
1524433689.122,,0.000000e+000,5.500037e+001,4.644044e-006,0.000000e+000,3,9.103298e-001,0.000000e+000,,,,,,,,,,,,,,32,1,4.000000e+000,1.319885e-003,0.000000e+000,0,,0,
1524433726.742,,0.000000e+000,5.500366e+001,4.556761e-006,0.000000e+000,3,9.294729e-001,0.000000e+000,,,,,,,,,,,,,,32,1,4.000000e+000,2.620697e-003,0.000000e+000,0,,0,
1524433764.152,,0.000000e+000,5.499643e+001,4.605816e-006,0.000000e+000,3,9.074924e-001,0.000000e+000,,,,,,,,,,,,,,32,1,4.000000e+000,1.312256e-003,0.000000e+000,0,,0,
1524433801.892,,0.000000e+000,5.499773e+001,4.612595e-006,0.000000e+000,3,9.044483e-001,0.000000e+000,,,,,,,,,,,,,,32,1,4.000000e+000,1.308441e-003,0.000000e+000,0,,0,
1524433839.092,,0.000000e+000,5.499117e+001,4.589765e-006,0.000000e+000,3,9.221768e-001,0.000000e+000,,,,,,,,,,,,,,32,1,4.000000e+000,9.208679e-003,0.000000e+000,0,,0,
1524433876.862,,0.000000e+000,5.499774e+001,4.653265e-006,0.000000e+000,3,9.198161e-001,0.000000e+000,,,,,,,,,,,,,,32,1,4.000000e+000,3.940582e-003,0.000000e+000,0,,0,
1524433913.932,,0.000000e+000,5.499905e+001,4.640933e-006,0.000000e+000,3,9.092785e-001,0.000000e+000,,,,,,,,,,,,,,32,1,4.000000e+000,1.319885e-003,0.000000e+000,0,,0,
1524433951.922,,0.000000e+000,5.499643e+001,4.641780e-006,0.000000e+000,3,9.160993e-001,0.000000e+000,,,,,,,,,,,,,,32,1,4.000000e+000,1.312256e-003,0.000000e+000,0,,0,
1524433990.413,,0.000000e+000,5.499314e+001,4.598903e-006,0.000000e+000,3,9.201615e-001,0.000000e+000,,,,,,,,,,,,,,32,1,4.000000e+000,2.104950e-002,0.000000e+000,0,,0,
1524434041.133,,0.000000e+000,5.499774e+001,4.632296e-006,0.000000e+000,3,9.231457e-001,0.000000e+000,,,,,,,,,,,,,,32,1,4.000000e+000,6.580353e-003,0.000000e+000,0,,0,
1524434078.773,,0.000000e+000,5.500037e+001,4.592920e-006,0.000000e+000,3,9.189730e-001,0.000000e+000,,,,,,,,,,,,,,32,1,4.000000e+000,1.319885e-003,0.000000e+000,0,,0,
1524434116.743,,0.000000e+000,5.499775e+001,4.671807e-006,0.000000e+000,3,9.197642e-001,0.000000e+000,,,,,,,,,,,,,,32,1,4.000000e+000,1.184845e-002,0.000000e+000,0,,0,
1524434154.533,,0.000000e+000,5.499577e+001,4.697495e-006,0.000000e+000,3,9.235147e-001,0.000000e+000,,,,,,,,,,,,,,32,1,4.000000e+000,5.249023e-003,0.000000e+000,0,,0,
1524434192.323,,0.000000e+000,5.500037e+001,4.684149e-006,0.000000e+000,3,9.121450e-001,0.000000e+000,,,,,,,,,,,,,,32,1,4.000000e+000,3.959656e-003,0.000000e+000,0,,0,
1524434230.253,,0.000000e+000,5.500498e+001,4.610576e-006,0.000000e+000,3,9.199246e-001,0.000000e+000,,,,,,,,,,,,,,32,1,4.000000e+000,5.260468e-003,0.000000e+000,0,,0,
1524434267.653,,0.000000e+000,5.499774e+001,4.675240e-006,0.000000e+000,3,9.181496e-001,0.000000e+000,,,,,,,,,,,,,,32,1,4.000000e+000,3.940582e-003,0.000000e+000,0,,0,
1524434305.243,,0.000000e+000,5.499051e+001,4.669640e-006,0.000000e+000,3,9.233480e-001,0.000000e+000,,,,,,,,,,,,,,32,1,4.000000e+000,1.052094e-002,0.000000e+000,0,,0,
1524434343.183,,0.000000e+000,5.499775e+001,4.694578e-006,0.000000e+000,3,9.168415e-001,0.000000e+000,,,,,,,,,,,,,,32,1,4.000000e+000,9.208679e-003,0.000000e+000,0,,0,
1524434381.033,,0.000000e+000,5.499774e+001,4.650613e-006,0.000000e+000,3,9.110090e-001,0.000000e+000,,,,,,,,,,,,,,32,1,4.000000e+000,6.580353e-003,0.000000e+000,0,,0,
1524434419.383,,0.000000e+000,5.499643e+001,4.661695e-006,0.000000e+000,3,9.236951e-001,0.000000e+000,,,,,,,,,,,,,,32,1,4.000000e+000,1.312256e-003,0.000000e+000,0,,0,
1524434456.793,,0.000000e+000,5.499577e+001,4.667515e-006,0.000000e+000,3,9.188871e-001,0.000000e+000,,,,,,,,,,,,,,32,1,4.000000e+000,2.632141e-003,0.000000e+000,0,,0,
1524434494.643,,0.000000e+000,5.499774e+001,4.729087e-006,0.000000e+000,3,9.333789e-001,0.000000e+000,,,,,,,,,,,,,,32,1,4.000000e+000,3.940582e-003,0.000000e+000,0,,0,
1524434531.923,,0.000000e+000,5.499840e+001,4.677597e-006,0.000000e+000,3,9.144635e-001,0.000000e+000,,,,,,,,,,,,,,32,1,4.000000e+000,2.628326e-003,0.000000e+000,0,,0,
1524434569.863,,0.000000e+000,5.500103e+001,4.710029e-006,0.000000e+000,3,9.268101e-001,0.000000e+000,,,,,,,,,,,,,,32,1,4.000000e+000,7.888794e-003,0.000000e+000,0,,0,
1524434607.493,,0.000000e+000,5.500168e+001,4.705408e-006,0.000000e+000,3,9.128351e-001,0.000000e+000,,,,,,,,,,,,,,32,1,4.000000e+000,6.580353e-003,0.000000e+000,0,,0,
1524434644.903,,0.000000e+000,5.500300e+001,4.680382e-006,0.000000e+000,3,9.372097e-001,0.000000e+000,,,,,,,,,,,,,,32,1,4.000000e+000,6.580353e-003,0.000000e+000,0,,0,
1524434682.203,,0.000000e+000,5.500498e+001,4.681821e-006,0.000000e+000,3,9.117384e-001,0.000000e+000,,,,,,,,,,,,,,32,1,4.000000e+000,5.260468e-003,0.000000e+000,0,,0,
1524434720.144,,0.000000e+000,5.500300e+001,4.738234e-006,0.000000e+000,3,9.169599e-001,0.000000e+000,,,,,,,,,,,,,,32,1,4.000000e+000,1.710129e-002,0.000000e+000,0,,0,
1524434758.404,,0.000000e+000,5.500037e+001,4.607300e-006,0.000000e+000,3,9.242702e-001,0.000000e+000,,,,,,,,,,,,,,32,1,4.000000e+000,1.319885e-003,0.000000e+000,0,,0,
1524434795.934,,0.000000e+000,5.499905e+001,4.700019e-006,0.000000e+000,3,9.101762e-001,0.000000e+000,,,,,,,,,,,,,,32,1,4.000000e+000,3.948212e-003,0.000000e+000,0,,0,
1524434833.464,,0.000000e+000,5.498985e+001,4.629816e-006,0.000000e+000,3,9.232810e-001,0.000000e+000,,,,,,,,,,,,,,32,1,4.000000e+000,9.201050e-003,0.000000e+000,0,,0,
1524434870.994,,0.000000e+000,5.499183e+001,4.714132e-006,0.000000e+000,3,9.161450e-001,0.000000e+000,,,,,,,,,,,,,,32,1,4.000000e+000,7.888794e-003,0.000000e+000,0,,0,
1524434908.494,,0.000000e+000,5.499577e+001,4.656312e-006,0.000000e+000,3,9.180749e-001,0.000000e+000,,,,,,,,,,,,,,32,1,4.000000e+000,7.888794e-003,0.000000e+000,0,,0,
1524434959.094,,0.000000e+000,5.499709e+001,4.691971e-006,0.000000e+000,3,9.266591e-001,0.000000e+000,,,,,,,,,,,,,,32,1,4.000000e+000,7.888794e-003,0.000000e+000,0,,0,
1524434996.824,,0.000000e+000,5.500103e+001,4.715343e-006,0.000000e+000,3,9.088556e-001,0.000000e+000,,,,,,,,,,,,,,32,1,4.000000e+000,2.639771e-003,0.000000e+000,0,,0,
1524435034.694,,0.000000e+000,5.499511e+001,4.700281e-006,0.000000e+000,3,9.211622e-001,0.000000e+000,,,,,,,,,,,,,,32,1,4.000000e+000,9.201050e-003,0.000000e+000,0,,0,
1524435072.424,,0.000000e+000,5.499445e+001,4.742421e-006,0.000000e+000,3,9.065663e-001,0.000000e+000,,,,,,,,,,,,,,32,1,4.000000e+000,0.000000e+000,0.000000e+000,0,,0,
1524435110.294,,0.000000e+000,5.500235e+001,4.706305e-006,0.000000e+000,3,9.197644e-001,0.000000e+000,,,,,,,,,,,,,,32,1,4.000000e+000,0.000000e+000,0.000000e+000,0,,0,
1524435148.074,,0.000000e+000,5.500037e+001,4.711720e-006,0.000000e+000,3,9.091145e-001,0.000000e+000,,,,,,,,,,,,,,32,1,4.000000e+000,6.587982e-003,0.000000e+000,0,,0,
1524435185.894,,0.000000e+000,5.499577e+001,4.674844e-006,0.000000e+000,3,9.242679e-001,0.000000e+000,,,,,,,,,,,,,,32,1,4.000000e+000,1.316071e-002,0.000000e+000,0,,0,
1524435223.614,,0.000000e+000,5.499380e+001,4.700849e-006,0.000000e+000,3,9.072632e-001,0.000000e+000,,,,,,,,,,,,,,32,1,4.000000e+000,6.572723e-003,0.000000e+000,0,,0,
1524435261.494,,0.000000e+000,5.499248e+001,4.685831e-006,0.000000e+000,3,9.241104e-001,0.000000e+000,,,,,,,,,,,,,,32,1,4.000000e+000,1.182938e-002,0.000000e+000,0,,0,
1524435299.234,,0.000000e+000,5.500168e+001,4.737273e-006,0.000000e+000,3,9.161096e-001,0.000000e+000,,,,,,,,,,,,,,32,1,4.000000e+000,6.580353e-003,0.000000e+000,0,,0,
1524435337.104,,0.000000e+000,5.500037e+001,4.718863e-006,0.000000e+000,3,9.224618e-001,0.000000e+000,,,,,,,,,,,,,,32,1,4.000000e+000,1.319885e-003,0.000000e+000,0,,0,
1524435375.154,,0.000000e+000,5.499971e+001,4.709516e-006,0.000000e+000,3,9.059262e-001,0.000000e+000,,,,,,,,,,,,,,32,1,4.000000e+000,0.000000e+000,0.000000e+000,0,,0,
1524435412.945,,0.000000e+000,5.499971e+001,4.721281e-006,0.000000e+000,3,9.256647e-001,0.000000e+000,,,,,,,,,,,,,,32,1,4.000000e+000,1.052094e-002,0.000000e+000,0,,0,
1524435450.295,,0.000000e+000,5.499906e+001,4.730171e-006,0.000000e+000,3,9.199494e-001,0.000000e+000,,,,,,,,,,,,,,32,1,4.000000e+000,6.580353e-003,0.000000e+000,0,,0,
1524435488.035,,0.000000e+000,5.500103e+001,4.747080e-006,0.000000e+000,3,9.147217e-001,0.000000e+000,,,,,,,,,,,,,,32,1,4.000000e+000,2.639771e-003,0.000000e+000,0,,0,
1524435525.895,,0.000000e+000,5.499708e+001,4.660436e-006,0.000000e+000,3,9.281095e-001,0.000000e+000,,,,,,,,,,,,,,32,1,4.000000e+000,5.260468e-003,0.000000e+000,0,,0,
1524435563.275,,0.000000e+000,5.499708e+001,4.724951e-006,0.000000e+000,3,9.120879e-001,0.000000e+000,,,,,,,,,,,,,,32,1,4.000000e+000,2.620697e-003,0.000000e+000,0,,0,
1524435601.425,,0.000000e+000,5.499577e+001,4.694434e-006,0.000000e+000,3,9.219433e-001,0.000000e+000,,,,,,,,,,,,,,32,1,4.000000e+000,7.888794e-003,0.000000e+000,0,,0,
1524435639.325,,0.000000e+000,5.500169e+001,4.734236e-006,0.000000e+000,3,9.201456e-001,0.000000e+000,,,,,,,,,,,,,,32,1,4.000000e+000,1.184082e-002,0.000000e+000,0,,0,
1524435676.485,,0.000000e+000,5.499445e+001,4.723693e-006,0.000000e+000,3,9.276845e-001,0.000000e+000,,,,,,,,,,,,,,32,1,4.000000e+000,7.881165e-003,0.000000e+000,0,,0,
1524435713.935,,0.000000e+000,5.499972e+001,4.761009e-006,0.000000e+000,3,9.174225e-001,0.000000e+000,,,,,,,,,,,,,,32,1,4.000000e+000,7.900238e-003,0.000000e+000,0,,0,
1524435751.995,,0.000000e+000,5.499445e+001,4.767737e-006,0.000000e+000,3,9.328299e-001,0.000000e+000,,,,,,,,,,,,,,32,1,4.000000e+000,1.314926e-002,0.000000e+000,0,,0,
1524435789.705,,0.000000e+000,5.499643e+001,4.710023e-006,0.000000e+000,3,9.175987e-001,0.000000e+000,,,,,,,,,,,,,,32,1,4.000000e+000,1.312256e-003,0.000000e+000,0,,0,
1524435827.745,,0.000000e+000,5.499313e+001,4.731786e-006,0.000000e+000,3,9.204231e-001,0.000000e+000,,,,,,,,,,,,,,32,1,4.000000e+000,7.892609e-003,0.000000e+000,0,,0,
1524435878.385,,0.000000e+000,5.499445e+001,4.797754e-006,0.000000e+000,3,9.397125e-001,0.000000e+000,,,,,,,,,,,,,,32,1,4.000000e+000,2.628326e-003,0.000000e+000,0,,0,
1524435916.235,,0.000000e+000,5.499379e+001,4.690245e-006,0.000000e+000,3,9.283967e-001,0.000000e+000,,,,,,,,,,,,,,32,1,4.000000e+000,9.201050e-003,0.000000e+000,0,,0,
1524435953.525,,0.000000e+000,5.499774e+001,4.743010e-006,0.000000e+000,3,9.109390e-001,0.000000e+000,,,,,,,,,,,,,,32,1,4.000000e+000,2.235794e-002,0.000000e+000,0,,0,
1524435991.525,,0.000000e+000,5.500103e+001,4.695451e-006,0.000000e+000,3,9.285797e-001,0.000000e+000,,,,,,,,,,,,,,32,1,4.000000e+000,1.052094e-002,0.000000e+000,0,,0,
1524436029.235,,0.000000e+000,5.499577e+001,4.749088e-006,0.000000e+000,3,9.181340e-001,0.000000e+000,,,,,,,,,,,,,,32,1,4.000000e+000,2.632141e-003,0.000000e+000,0,,0,
1524436066.755,,0.000000e+000,5.499708e+001,4.801322e-006,0.000000e+000,3,9.260783e-001,0.000000e+000,,,,,,,,,,,,,,32,1,4.000000e+000,2.620697e-003,0.000000e+000,0,,0,
1524436104.675,,0.000000e+000,5.499248e+001,4.799487e-006,0.000000e+000,3,9.262252e-001,0.000000e+000,,,,,,,,,,,,,,32,1,4.000000e+000,6.580353e-003,0.000000e+000,0,,0,
1524436142.616,,0.000000e+000,5.499905e+001,4.786991e-006,0.000000e+000,3,9.150398e-001,0.000000e+000,,,,,,,,,,,,,,32,1,4.000000e+000,1.182938e-002,0.000000e+000,0,,0,
1524436180.606,,0.000000e+000,5.499972e+001,4.811854e-006,0.000000e+000,3,9.159838e-001,0.000000e+000,,,,,,,,,,,,,,32,1,4.000000e+000,1.578903e-002,0.000000e+000,0,,0,
1524436218.616,,0.000000e+000,5.499775e+001,4.731301e-006,0.000000e+000,3,9.326999e-001,0.000000e+000,,,,,,,,,,,,,,32,1,4.000000e+000,9.208679e-003,0.000000e+000,0,,0,
1524436256.146,,0.000000e+000,5.499511e+001,4.798218e-006,0.000000e+000,3,9.167044e-001,0.000000e+000,,,,,,,,,,,,,,32,1,4.000000e+000,1.319885e-003,0.000000e+000,0,,0,
1524436293.456,,0.000000e+000,5.500366e+001,4.713677e-006,0.000000e+000,3,9.224769e-001,0.000000e+000,,,,,,,,,,,,,,32,1,4.000000e+000,2.620697e-003,0.000000e+000,0,,0,
1524436331.156,,0.000000e+000,5.499905e+001,4.757600e-006,0.000000e+000,3,9.213359e-001,0.000000e+000,,,,,,,,,,,,,,32,1,4.000000e+000,3.948212e-003,0.000000e+000,0,,0,
1524436368.536,,0.000000e+000,5.500432e+001,4.786182e-006,0.000000e+000,3,9.328544e-001,0.000000e+000,,,,,,,,,,,,,,32,1,4.000000e+000,1.710129e-002,0.000000e+000,0,,0,
1524436406.176,,0.000000e+000,5.499839e+001,4.750809e-006,0.000000e+000,3,9.149374e-001,0.000000e+000,,,,,,,,,,,,,,32,1,4.000000e+000,0.000000e+000,0.000000e+000,0,,0,
1524436443.926,,0.000000e+000,5.499774e+001,4.765491e-006,0.000000e+000,3,9.144814e-001,0.000000e+000,,,,,,,,,,,,,,32,1,4.000000e+000,3.940582e-003,0.000000e+000,0,,0,
1524436482.296,,0.000000e+000,5.499380e+001,4.776502e-006,0.000000e+000,3,9.065729e-001,0.000000e+000,,,,,,,,,,,,,,32,1,4.000000e+000,6.572723e-003,0.000000e+000,0,,0,
1524436520.176,,0.000000e+000,5.499774e+001,4.764611e-006,0.000000e+000,3,9.162824e-001,0.000000e+000,,,,,,,,,,,,,,32,1,4.000000e+000,1.446152e-002,0.000000e+000,0,,0,
1524436557.896,,0.000000e+000,5.500169e+001,4.686116e-006,0.000000e+000,3,9.240976e-001,0.000000e+000,,,,,,,,,,,,,,32,1,4.000000e+000,9.208679e-003,0.000000e+000,0,,0,
1524436596.616,,0.000000e+000,5.499905e+001,4.728273e-006,0.000000e+000,3,9.141057e-001,0.000000e+000,,,,,,,,,,,,,,32,1,4.000000e+000,3.948212e-003,0.000000e+000,0,,0,
1524436634.666,,0.000000e+000,5.500564e+001,4.759110e-006,0.000000e+000,3,9.206675e-001,0.000000e+000,,,,,,,,,,,,,,32,1,4.000000e+000,3.940582e-003,0.000000e+000,0,,0,
1524436672.436,,0.000000e+000,5.499577e+001,4.685063e-006,0.000000e+000,3,9.176828e-001,0.000000e+000,,,,,,,,,,,,,,32,1,4.000000e+000,7.888794e-003,0.000000e+000,0,,0,
1524436710.286,,0.000000e+000,5.500037e+001,4.758586e-006,0.000000e+000,3,9.175524e-001,0.000000e+000,,,,,,,,,,,,,,32,1,4.000000e+000,1.319885e-003,0.000000e+000,0,,0,
1524436748.046,,0.000000e+000,5.499643e+001,4.736469e-006,0.000000e+000,3,9.197050e-001,0.000000e+000,,,,,,,,,,,,,,32,1,4.000000e+000,6.568909e-003,0.000000e+000,0,,0,
1524436800.386,,0.000000e+000,5.500235e+001,4.722749e-006,0.000000e+000,3,9.148164e-001,0.000000e+000,,,,,,,,,,,,,,32,1,4.000000e+000,0.000000e+000,0.000000e+000,0,,0,
1524436838.147,,0.000000e+000,5.499839e+001,4.747447e-006,0.000000e+000,3,9.313693e-001,0.000000e+000,,,,,,,,,,,,,,32,1,4.000000e+000,0.000000e+000,0.000000e+000,0,,0,
1524436875.817,,0.000000e+000,5.499774e+001,4.782149e-006,0.000000e+000,3,9.232834e-001,0.000000e+000,,,,,,,,,,,,,,32,1,4.000000e+000,3.940582e-003,0.000000e+000,0,,0,
1524436913.767,,0.000000e+000,5.500103e+001,4.736601e-006,0.000000e+000,3,9.222184e-001,0.000000e+000,,,,,,,,,,,,,,32,1,4.000000e+000,7.888794e-003,0.000000e+000,0,,0,
1524436951.477,,0.000000e+000,5.499840e+001,4.742156e-006,0.000000e+000,3,9.228797e-001,0.000000e+000,,,,,,,,,,,,,,32,1,4.000000e+000,1.578140e-002,0.000000e+000,0,,0,
1524436988.837,,0.000000e+000,5.499511e+001,4.777851e-006,0.000000e+000,3,9.278836e-001,0.000000e+000,,,,,,,,,,,,,,32,1,4.000000e+000,1.319885e-003,0.000000e+000,0,,0,
1524437026.537,,0.000000e+000,5.500103e+001,4.792490e-006,0.000000e+000,3,9.210432e-001,0.000000e+000,,,,,,,,,,,,,,32,1,4.000000e+000,2.639771e-003,0.000000e+000,0,,0,
1524437064.267,,0.000000e+000,5.499905e+001,4.740124e-006,0.000000e+000,3,9.260833e-001,0.000000e+000,,,,,,,,,,,,,,32,1,4.000000e+000,3.948212e-003,0.000000e+000,0,,0,
1524437101.587,,0.000000e+000,5.499577e+001,4.768146e-006,0.000000e+000,3,9.145174e-001,0.000000e+000,,,,,,,,,,,,,,32,1,4.000000e+000,2.632141e-003,0.000000e+000,0,,0,
1524437139.677,,0.000000e+000,5.499971e+001,4.834895e-006,0.000000e+000,3,9.290746e-001,0.000000e+000,,,,,,,,,,,,,,32,1,4.000000e+000,2.639771e-003,0.000000e+000,0,,0,
1524437177.737,,0.000000e+000,5.499773e+001,4.755506e-006,0.000000e+000,3,9.347255e-001,0.000000e+000,,,,,,,,,,,,,,32,1,4.000000e+000,1.308441e-003,0.000000e+000,0,,0,
1524437215.577,,0.000000e+000,5.499840e+001,4.706968e-006,0.000000e+000,3,9.127573e-001,0.000000e+000,,,,,,,,,,,,,,32,1,4.000000e+000,2.628326e-003,0.000000e+000,0,,0,
1524437254.057,,0.000000e+000,5.499774e+001,4.722094e-006,0.000000e+000,3,9.151120e-001,0.000000e+000,,,,,,,,,,,,,,32,1,4.000000e+000,3.940582e-003,0.000000e+000,0,,0,
1524437291.867,,0.000000e+000,5.499314e+001,4.703389e-006,0.000000e+000,3,9.204944e-001,0.000000e+000,,,,,,,,,,,,,,32,1,4.000000e+000,1.578140e-002,0.000000e+000,0,,0,
1524437329.817,,0.000000e+000,5.500037e+001,4.668234e-006,0.000000e+000,3,9.177837e-001,0.000000e+000,,,,,,,,,,,,,,32,1,4.000000e+000,1.319885e-003,0.000000e+000,0,,0,
1524437368.007,,0.000000e+000,5.500235e+001,4.737177e-006,0.000000e+000,3,9.039627e-001,0.000000e+000,,,,,,,,,,,,,,32,1,4.000000e+000,2.639771e-003,0.000000e+000,0,,0,
1524437406.417,,0.000000e+000,5.499840e+001,4.751957e-006,0.000000e+000,3,9.207154e-001,0.000000e+000,,,,,,,,,,,,,,32,1,4.000000e+000,7.900238e-003,0.000000e+000,0,,0,
1524437443.567,,0.000000e+000,5.499511e+001,4.751974e-006,0.000000e+000,3,9.100558e-001,0.000000e+000,,,,,,,,,,,,,,32,1,4.000000e+000,1.184082e-002,0.000000e+000,0,,0,
1524437481.877,,0.000000e+000,5.499577e+001,4.771992e-006,0.000000e+000,3,9.185634e-001,0.000000e+000,,,,,,,,,,,,,,32,1,4.000000e+000,1.052094e-002,0.000000e+000,0,,0,
1524437520.437,,0.000000e+000,5.500168e+001,4.784368e-006,0.000000e+000,3,9.250811e-001,0.000000e+000,,,,,,,,,,,,,,32,1,4.000000e+000,6.580353e-003,0.000000e+000,0,,0,
1524437558.098,,0.000000e+000,5.500761e+001,4.751004e-006,0.000000e+000,3,9.068606e-001,0.000000e+000,,,,,,,,,,,,,,32,1,4.000000e+000,1.052094e-002,0.000000e+000,0,,0,
1524437596.038,,0.000000e+000,5.499971e+001,4.786544e-006,0.000000e+000,3,9.393564e-001,0.000000e+000,,,,,,,,,,,,,,32,1,4.000000e+000,2.639771e-003,0.000000e+000,0,,0,
1524437633.448,,0.000000e+000,5.499774e+001,4.793655e-006,0.000000e+000,3,9.149263e-001,0.000000e+000,,,,,,,,,,,,,,32,1,4.000000e+000,3.940582e-003,0.000000e+000,0,,0,
1524437671.148,,0.000000e+000,5.499841e+001,4.752209e-006,0.000000e+000,3,9.211192e-001,0.000000e+000,,,,,,,,,,,,,,32,1,4.000000e+000,1.052856e-002,0.000000e+000,0,,0,
1524437722.348,,0.000000e+000,5.500103e+001,4.703936e-006,0.000000e+000,3,9.124578e-001,0.000000e+000,,,,,,,,,,,,,,32,1,4.000000e+000,5.279541e-003,0.000000e+000,0,,0,
1524437761.028,,0.000000e+000,5.500037e+001,4.811222e-006,0.000000e+000,3,9.097511e-001,0.000000e+000,,,,,,,,,,,,,,32,1,4.000000e+000,1.319885e-003,0.000000e+000,0,,0,
1524437799.198,,0.000000e+000,5.499840e+001,4.718752e-006,0.000000e+000,3,9.214957e-001,0.000000e+000,,,,,,,,,,,,,,32,1,4.000000e+000,2.628326e-003,0.000000e+000,0,,0,
1524437836.258,,0.000000e+000,5.499708e+001,4.739058e-006,0.000000e+000,3,9.157256e-001,0.000000e+000,,,,,,,,,,,,,,32,1,4.000000e+000,2.620697e-003,0.000000e+000,0,,0,
1524437874.028,,0.000000e+000,5.500366e+001,4.646979e-006,0.000000e+000,3,9.154326e-001,0.000000e+000,,,,,,,,,,,,,,32,1,4.000000e+000,2.620697e-003,0.000000e+000,0,,0,
1524437911.858,,0.000000e+000,5.499380e+001,4.695946e-006,0.000000e+000,3,9.156897e-001,0.000000e+000,,,,,,,,,,,,,,32,1,4.000000e+000,6.572723e-003,0.000000e+000,0,,0,
1524437950.168,,0.000000e+000,5.499708e+001,4.725108e-006,0.000000e+000,3,9.203730e-001,0.000000e+000,,,,,,,,,,,,,,32,1,4.000000e+000,2.620697e-003,0.000000e+000,0,,0,
1524437986.878,,0.000000e+000,5.500432e+001,4.739825e-006,0.000000e+000,3,9.299160e-001,0.000000e+000,,,,,,,,,,,,,,32,1,4.000000e+000,3.940582e-003,0.000000e+000,0,,0,
1524438024.038,,0.000000e+000,5.499577e+001,4.725259e-006,0.000000e+000,3,9.173977e-001,0.000000e+000,,,,,,,,,,,,,,32,1,4.000000e+000,5.249023e-003,0.000000e+000,0,,0,
1524438061.858,,0.000000e+000,5.500168e+001,4.787305e-006,0.000000e+000,3,9.272904e-001,0.000000e+000,,,,,,,,,,,,,,32,1,4.000000e+000,6.580353e-003,0.000000e+000,0,,0,
1524438099.548,,0.000000e+000,5.500301e+001,4.754116e-006,0.000000e+000,3,9.100484e-001,0.000000e+000,,,,,,,,,,,,,,32,1,4.000000e+000,1.319885e-003,0.000000e+000,0,,0,
1524438137.278,,0.000000e+000,5.500103e+001,4.756864e-006,0.000000e+000,3,9.281714e-001,0.000000e+000,,,,,,,,,,,,,,32,1,4.000000e+000,2.639771e-003,0.000000e+000,0,,0,
1524438174.788,,0.000000e+000,5.500498e+001,4.737558e-006,0.000000e+000,3,9.184866e-001,0.000000e+000,,,,,,,,,,,,,,32,1,4.000000e+000,5.260468e-003,0.000000e+000,0,,0,
1524438213.028,,0.000000e+000,5.500169e+001,4.759579e-006,0.000000e+000,3,9.022223e-001,0.000000e+000,,,,,,,,,,,,,,32,1,4.000000e+000,3.959656e-003,0.000000e+000,0,,0,
1524438250.868,,0.000000e+000,5.500037e+001,4.740948e-006,0.000000e+000,3,9.201015e-001,0.000000e+000,,,,,,,,,,,,,,32,1,4.000000e+000,9.201050e-003,0.000000e+000,0,,0,
1524438288.569,,0.000000e+000,5.499708e+001,4.745405e-006,0.000000e+000,3,9.148462e-001,0.000000e+000,,,,,,,,,,,,,,32,1,4.000000e+000,2.620697e-003,0.000000e+000,0,,0,
1524438326.539,,0.000000e+000,5.500037e+001,4.684966e-006,0.000000e+000,3,9.203871e-001,0.000000e+000,,,,,,,,,,,,,,32,1,4.000000e+000,9.201050e-003,0.000000e+000,0,,0,
1524438364.199,,0.000000e+000,5.499841e+001,4.714719e-006,0.000000e+000,3,9.151760e-001,0.000000e+000,,,,,,,,,,,,,,32,1,4.000000e+000,1.052856e-002,0.000000e+000,0,,0,
1524438402.199,,0.000000e+000,5.500103e+001,4.705379e-006,0.000000e+000,3,9.195603e-001,0.000000e+000,,,,,,,,,,,,,,32,1,4.000000e+000,0.000000e+000,0.000000e+000,0,,0,
1524438439.789,,0.000000e+000,5.500366e+001,4.757399e-006,0.000000e+000,3,9.131281e-001,0.000000e+000,,,,,,,,,,,,,,32,1,4.000000e+000,7.900238e-003,0.000000e+000,0,,0,
1524438477.829,,0.000000e+000,5.500300e+001,4.712032e-006,0.000000e+000,3,9.238188e-001,0.000000e+000,,,,,,,,,,,,,,32,1,4.000000e+000,9.220123e-003,0.000000e+000,0,,0,
1524438515.469,,0.000000e+000,5.499905e+001,4.722583e-006,0.000000e+000,3,9.135084e-001,0.000000e+000,,,,,,,,,,,,,,32,1,4.000000e+000,1.319885e-003,0.000000e+000,0,,0,
1524438552.859,,0.000000e+000,5.499972e+001,4.702922e-006,0.000000e+000,3,9.215288e-001,0.000000e+000,,,,,,,,,,,,,,32,1,4.000000e+000,7.900238e-003,0.000000e+000,0,,0,
1524438590.139,,0.000000e+000,5.499773e+001,4.764733e-006,0.000000e+000,3,9.072983e-001,0.000000e+000,,,,,,,,,,,,,,32,1,4.000000e+000,1.308441e-003,0.000000e+000,0,,0,
1524438641.799,,0.000000e+000,5.499051e+001,4.597092e-006,0.000000e+000,3,9.124025e-001,0.000000e+000,,,,,,,,,,,,,,32,1,4.000000e+000,2.632141e-003,0.000000e+000,0,,0,
1524438679.779,,0.000000e+000,5.500366e+001,4.754957e-006,0.000000e+000,3,9.031304e-001,0.000000e+000,,,,,,,,,,,,,,32,1,4.000000e+000,5.260468e-003,0.000000e+000,0,,0,
1524438717.599,,0.000000e+000,5.500103e+001,4.691554e-006,0.000000e+000,3,9.153799e-001,0.000000e+000,,,,,,,,,,,,,,32,1,4.000000e+000,5.279541e-003,0.000000e+000,0,,0,
1524438755.479,,0.000000e+000,5.499512e+001,4.682516e-006,0.000000e+000,3,9.127584e-001,0.000000e+000,,,,,,,,,,,,,,32,1,4.000000e+000,1.446915e-002,0.000000e+000,0,,0,
1524438793.479,,0.000000e+000,5.500366e+001,4.745083e-006,0.000000e+000,3,9.200063e-001,0.000000e+000,,,,,,,,,,,,,,32,1,4.000000e+000,2.620697e-003,0.000000e+000,0,,0,
1524438830.569,,0.000000e+000,5.500563e+001,4.786444e-006,0.000000e+000,3,9.048972e-001,0.000000e+000,,,,,,,,,,,,,,32,1,4.000000e+000,9.208679e-003,0.000000e+000,0,,0,
1524438868.129,,0.000000e+000,5.499708e+001,4.734767e-006,0.000000e+000,3,9.250122e-001,0.000000e+000,,,,,,,,,,,,,,32,1,4.000000e+000,0.000000e+000,0.000000e+000,0,,0,
1524438905.729,,0.000000e+000,5.499445e+001,4.741129e-006,0.000000e+000,3,9.172608e-001,0.000000e+000,,,,,,,,,,,,,,32,1,4.000000e+000,0.000000e+000,0.000000e+000,0,,0,
1524438943.619,,0.000000e+000,5.499905e+001,4.761454e-006,0.000000e+000,3,9.228262e-001,0.000000e+000,,,,,,,,,,,,,,32,1,4.000000e+000,1.319885e-003,0.000000e+000,0,,0,
1524438981.190,,0.000000e+000,5.499773e+001,4.807534e-006,0.000000e+000,3,9.231484e-001,0.000000e+000,,,,,,,,,,,,,,32,1,4.000000e+000,1.308441e-003,0.000000e+000,0,,0,
1524439019.400,,0.000000e+000,5.499774e+001,4.731429e-006,0.000000e+000,3,9.156967e-001,0.000000e+000,,,,,,,,,,,,,,32,1,4.000000e+000,6.580353e-003,0.000000e+000,0,,0,
1524439057.370,,0.000000e+000,5.499577e+001,4.721868e-006,0.000000e+000,3,9.161741e-001,0.000000e+000,,,,,,,,,,,,,,32,1,4.000000e+000,0.000000e+000,0.000000e+000,0,,0,
1524439095.550,,0.000000e+000,5.499182e+001,4.697139e-006,0.000000e+000,3,9.150355e-001,0.000000e+000,,,,,,,,,,,,,,32,1,4.000000e+000,0.000000e+000,0.000000e+000,0,,0,
1524439132.840,,0.000000e+000,5.499116e+001,4.709401e-006,0.000000e+000,3,9.087232e-001,0.000000e+000,,,,,,,,,,,,,,32,1,4.000000e+000,1.446152e-002,0.000000e+000,0,,0,
1524439170.690,,0.000000e+000,5.499445e+001,4.662915e-006,0.000000e+000,3,9.228042e-001,0.000000e+000,,,,,,,,,,,,,,32,1,4.000000e+000,0.000000e+000,0.000000e+000,0,,0,
1524439208.100,,0.000000e+000,5.499774e+001,4.793519e-006,0.000000e+000,3,9.109520e-001,0.000000e+000,,,,,,,,,,,,,,32,1,4.000000e+000,6.580353e-003,0.000000e+000,0,,0,
1524439246.380,,0.000000e+000,5.499774e+001,4.774344e-006,0.000000e+000,3,9.198687e-001,0.000000e+000,,,,,,,,,,,,,,32,1,4.000000e+000,6.580353e-003,0.000000e+000,0,,0,
1524439283.690,,0.000000e+000,5.499774e+001,4.708042e-006,0.000000e+000,3,9.259211e-001,0.000000e+000,,,,,,,,,,,,,,32,1,4.000000e+000,3.940582e-003,0.000000e+000,0,,0,
1524439321.540,,0.000000e+000,5.499511e+001,4.784238e-006,0.000000e+000,3,9.121556e-001,0.000000e+000,,,,,,,,,,,,,,32,1,4.000000e+000,1.319885e-003,0.000000e+000,0,,0,
1524439358.910,,0.000000e+000,5.499511e+001,4.748081e-006,0.000000e+000,3,9.243330e-001,0.000000e+000,,,,,,,,,,,,,,32,1,4.000000e+000,1.184082e-002,0.000000e+000,0,,0,
1524439397.140,,0.000000e+000,5.500103e+001,4.726542e-006,0.000000e+000,3,9.179252e-001,0.000000e+000,,,,,,,,,,,,,,32,1,4.000000e+000,2.639771e-003,0.000000e+000,0,,0,
1524439434.830,,0.000000e+000,5.500103e+001,4.809769e-006,0.000000e+000,3,9.155647e-001,0.000000e+000,,,,,,,,,,,,,,32,1,4.000000e+000,2.639771e-003,0.000000e+000,0,,0,
1524439472.440,,0.000000e+000,5.499577e+001,4.783997e-006,0.000000e+000,3,9.217677e-001,0.000000e+000,,,,,,,,,,,,,,32,1,4.000000e+000,2.632141e-003,0.000000e+000,0,,0,
1524439510.300,,0.000000e+000,5.499248e+001,4.726995e-006,0.000000e+000,3,9.299679e-001,0.000000e+000,,,,,,,,,,,,,,32,1,4.000000e+000,3.940582e-003,0.000000e+000,0,,0,
1524439560.720,,0.000000e+000,5.499906e+001,4.768794e-006,0.000000e+000,3,9.265272e-001,0.000000e+000,,,,,,,,,,,,,,32,1,4.000000e+000,9.220123e-003,0.000000e+000,0,,0,
1524439597.940,,0.000000e+000,5.499971e+001,4.781115e-006,0.000000e+000,3,9.319155e-001,0.000000e+000,,,,,,,,,,,,,,32,1,4.000000e+000,2.639771e-003,0.000000e+000,0,,0,
1524439635.220,,0.000000e+000,5.499643e+001,4.805229e-006,0.000000e+000,3,9.348550e-001,0.000000e+000,,,,,,,,,,,,,,32,1,4.000000e+000,6.568909e-003,0.000000e+000,0,,0,
1524439673.050,,0.000000e+000,5.500235e+001,4.780450e-006,0.000000e+000,3,9.209688e-001,0.000000e+000,,,,,,,,,,,,,,32,1,4.000000e+000,1.052856e-002,0.000000e+000,0,,0,
1524439710.551,,0.000000e+000,5.500301e+001,4.797670e-006,0.000000e+000,3,9.245853e-001,0.000000e+000,,,,,,,,,,,,,,32,1,4.000000e+000,1.319885e-003,0.000000e+000,0,,0,
1524439748.871,,0.000000e+000,5.499511e+001,4.794706e-006,0.000000e+000,3,9.105662e-001,0.000000e+000,,,,,,,,,,,,,,32,1,4.000000e+000,1.319885e-003,0.000000e+000,0,,0,
1524439786.671,,0.000000e+000,5.499971e+001,4.745997e-006,0.000000e+000,3,9.235489e-001,0.000000e+000,,,,,,,,,,,,,,32,1,4.000000e+000,0.000000e+000,0.000000e+000,0,,0,
1524439824.281,,0.000000e+000,5.499314e+001,4.724189e-006,0.000000e+000,3,9.282627e-001,0.000000e+000,,,,,,,,,,,,,,32,1,4.000000e+000,0.000000e+000,0.000000e+000,0,,0,
1524439862.711,,0.000000e+000,5.499774e+001,4.747159e-006,0.000000e+000,3,9.174229e-001,0.000000e+000,,,,,,,,,,,,,,32,1,4.000000e+000,3.940582e-003,0.000000e+000,0,,0,
1524439901.371,,0.000000e+000,5.500169e+001,4.772179e-006,0.000000e+000,3,9.112959e-001,0.000000e+000,,,,,,,,,,,,,,32,1,4.000000e+000,1.319885e-003,0.000000e+000,0,,0,
1524439939.201,,0.000000e+000,5.499379e+001,4.766819e-006,0.000000e+000,3,9.184431e-001,0.000000e+000,,,,,,,,,,,,,,32,1,4.000000e+000,9.201050e-003,0.000000e+000,0,,0,
1524439976.611,,0.000000e+000,5.500563e+001,4.796313e-006,0.000000e+000,3,9.149863e-001,0.000000e+000,,,,,,,,,,,,,,32,1,4.000000e+000,1.184082e-002,0.000000e+000,0,,0,
1524440014.841,,0.000000e+000,5.499643e+001,4.761089e-006,0.000000e+000,3,9.211833e-001,0.000000e+000,,,,,,,,,,,,,,32,1,4.000000e+000,9.208679e-003,0.000000e+000,0,,0,
1524440052.681,,0.000000e+000,5.499708e+001,4.713962e-006,0.000000e+000,3,9.265312e-001,0.000000e+000,,,,,,,,,,,,,,32,1,4.000000e+000,0.000000e+000,0.000000e+000,0,,0,
1524440090.811,,0.000000e+000,5.499445e+001,4.767211e-006,0.000000e+000,3,9.333967e-001,0.000000e+000,,,,,,,,,,,,,,32,1,4.000000e+000,5.260468e-003,0.000000e+000,0,,0,
1524440128.961,,0.000000e+000,5.499380e+001,4.721141e-006,0.000000e+000,3,9.228712e-001,0.000000e+000,,,,,,,,,,,,,,32,1,4.000000e+000,6.572723e-003,0.000000e+000,0,,0,
1524440166.611,,0.000000e+000,5.500037e+001,4.792394e-006,0.000000e+000,3,9.213594e-001,0.000000e+000,,,,,,,,,,,,,,32,1,4.000000e+000,1.319885e-003,0.000000e+000,0,,0,
1524440204.521,,0.000000e+000,5.499117e+001,4.816387e-006,0.000000e+000,3,9.272661e-001,0.000000e+000,,,,,,,,,,,,,,32,1,4.000000e+000,3.952026e-003,0.000000e+000,0,,0,
1524440242.861,,0.000000e+000,5.500300e+001,4.707200e-006,0.000000e+000,3,9.260786e-001,0.000000e+000,,,,,,,,,,,,,,32,1,4.000000e+000,9.220123e-003,0.000000e+000,0,,0,
1524440280.731,,0.000000e+000,5.499905e+001,4.736707e-006,0.000000e+000,3,9.259576e-001,0.000000e+000,,,,,,,,,,,,,,32,1,4.000000e+000,1.319885e-003,0.000000e+000,0,,0,
1524440318.661,,0.000000e+000,5.499380e+001,4.737496e-006,0.000000e+000,3,9.122713e-001,0.000000e+000,,,,,,,,,,,,,,32,1,4.000000e+000,3.948212e-003,0.000000e+000,0,,0,
1524440357.001,,0.000000e+000,5.500169e+001,4.746821e-006,0.000000e+000,3,9.254721e-001,0.000000e+000,,,,,,,,,,,,,,32,1,4.000000e+000,1.319885e-003,0.000000e+000,0,,0,
1524440394.851,,0.000000e+000,5.500037e+001,4.758313e-006,0.000000e+000,3,9.148456e-001,0.000000e+000,,,,,,,,,,,,,,32,1,4.000000e+000,9.201050e-003,0.000000e+000,0,,0,
1524440432.122,,0.000000e+000,5.500169e+001,4.778045e-006,0.000000e+000,3,9.214488e-001,0.000000e+000,,,,,,,,,,,,,,32,1,4.000000e+000,1.184082e-002,0.000000e+000,0,,0,
1524440483.342,,0.000000e+000,5.499643e+001,4.817823e-006,0.000000e+000,3,9.218527e-001,0.000000e+000,,,,,,,,,,,,,,32,1,4.000000e+000,1.312256e-003,0.000000e+000,0,,0,
1524440521.252,,0.000000e+000,5.499905e+001,4.816516e-006,0.000000e+000,3,9.293854e-001,0.000000e+000,,,,,,,,,,,,,,32,1,4.000000e+000,1.319885e-003,0.000000e+000,0,,0,
1524440558.872,,0.000000e+000,5.499511e+001,4.862214e-006,0.000000e+000,3,9.241075e-001,0.000000e+000,,,,,,,,,,,,,,32,1,4.000000e+000,6.568909e-003,0.000000e+000,0,,0,
1524440596.822,,0.000000e+000,5.499511e+001,4.836565e-006,0.000000e+000,3,9.231689e-001,0.000000e+000,,,,,,,,,,,,,,32,1,4.000000e+000,3.940582e-003,0.000000e+000,0,,0,
1524440634.412,,0.000000e+000,5.500300e+001,4.850841e-006,0.000000e+000,3,9.234205e-001,0.000000e+000,,,,,,,,,,,,,,32,1,4.000000e+000,3.940582e-003,0.000000e+000,0,,0,
1524440672.452,,0.000000e+000,5.500037e+001,4.821538e-006,0.000000e+000,3,9.254549e-001,0.000000e+000,,,,,,,,,,,,,,32,1,4.000000e+000,3.959656e-003,0.000000e+000,0,,0,
1524440710.052,,0.000000e+000,5.499708e+001,4.815175e-006,0.000000e+000,3,9.159834e-001,0.000000e+000,,,,,,,,,,,,,,32,1,4.000000e+000,1.578140e-002,0.000000e+000,0,,0,
1524440748.082,,0.000000e+000,5.499840e+001,4.812702e-006,0.000000e+000,3,9.223568e-001,0.000000e+000,,,,,,,,,,,,,,32,1,4.000000e+000,2.628326e-003,0.000000e+000,0,,0,
1524440785.682,,0.000000e+000,5.499775e+001,4.864516e-006,0.000000e+000,3,9.182206e-001,0.000000e+000,,,,,,,,,,,,,,32,1,4.000000e+000,9.208679e-003,0.000000e+000,0,,0,
1524440823.662,,0.000000e+000,5.499380e+001,4.809498e-006,0.000000e+000,3,9.255827e-001,0.000000e+000,,,,,,,,,,,,,,32,1,4.000000e+000,1.308441e-003,0.000000e+000,0,,0,
1524440861.412,,0.000000e+000,5.500037e+001,4.861173e-006,0.000000e+000,3,9.177296e-001,0.000000e+000,,,,,,,,,,,,,,32,1,4.000000e+000,6.587982e-003,0.000000e+000,0,,0,
1524440899.282,,0.000000e+000,5.499511e+001,4.788862e-006,0.000000e+000,3,9.217452e-001,0.000000e+000,,,,,,,,,,,,,,32,1,4.000000e+000,6.568909e-003,0.000000e+000,0,,0,
1524440936.892,,0.000000e+000,5.500432e+001,4.809530e-006,0.000000e+000,3,9.139398e-001,0.000000e+000,,,,,,,,,,,,,,32,1,4.000000e+000,3.940582e-003,0.000000e+000,0,,0,
1524440974.932,,0.000000e+000,5.499972e+001,4.803494e-006,0.000000e+000,3,9.211392e-001,0.000000e+000,,,,,,,,,,,,,,32,1,4.000000e+000,7.900238e-003,0.000000e+000,0,,0,
1524441012.322,,0.000000e+000,5.499708e+001,4.841359e-006,0.000000e+000,3,9.120699e-001,0.000000e+000,,,,,,,,,,,,,,32,1,4.000000e+000,5.260468e-003,0.000000e+000,0,,0,
1524441050.092,,0.000000e+000,5.500235e+001,4.861354e-006,0.000000e+000,3,9.180751e-001,0.000000e+000,,,,,,,,,,,,,,32,1,4.000000e+000,2.639771e-003,0.000000e+000,0,,0,
1524441088.062,,0.000000e+000,5.499905e+001,4.807373e-006,0.000000e+000,3,9.212672e-001,0.000000e+000,,,,,,,,,,,,,,32,1,4.000000e+000,1.319885e-003,0.000000e+000,0,,0,
1524441125.573,,0.000000e+000,5.499445e+001,4.827094e-006,0.000000e+000,3,9.120426e-001,0.000000e+000,,,,,,,,,,,,,,32,1,4.000000e+000,7.881165e-003,0.000000e+000,0,,0,
1524441162.813,,0.000000e+000,5.499775e+001,4.797921e-006,0.000000e+000,3,9.256289e-001,0.000000e+000,,,,,,,,,,,,,,32,1,4.000000e+000,9.208679e-003,0.000000e+000,0,,0,
1524441200.433,,0.000000e+000,5.499774e+001,4.825393e-006,0.000000e+000,3,9.092734e-001,0.000000e+000,,,,,,,,,,,,,,32,1,4.000000e+000,6.580353e-003,0.000000e+000,0,,0,
1524441239.263,,0.000000e+000,5.499643e+001,4.801164e-006,0.000000e+000,3,9.108632e-001,0.000000e+000,,,,,,,,,,,,,,32,1,4.000000e+000,1.312256e-003,0.000000e+000,0,,0,
1524441276.693,,0.000000e+000,5.500235e+001,4.770912e-006,0.000000e+000,3,9.215758e-001,0.000000e+000,,,,,,,,,,,,,,32,1,4.000000e+000,0.000000e+000,0.000000e+000,0,,0,
1524441313.863,,0.000000e+000,5.499182e+001,4.804347e-006,0.000000e+000,3,9.117792e-001,0.000000e+000,,,,,,,,,,,,,,32,1,4.000000e+000,1.314163e-002,0.000000e+000,0,,0,
1524441351.813,,0.000000e+000,5.498985e+001,4.768455e-006,0.000000e+000,3,9.260465e-001,0.000000e+000,,,,,,,,,,,,,,32,1,4.000000e+000,1.184082e-002,0.000000e+000,0,,0,