File: Experimental Raw Data/TC04-12-01K Adjusting Iterative/TC04-12-01K_TRMac_56K_0.04Kmin_VRMde_55K.dc.dat
[Header]
TITLE,MPMS DC Measurement
BYAPP,MPMS Measurement,2.1,Summary
FILEOPENTIME, 1524400819.090000 4/22/2018, 6:40:19 AM

INFO, APPNAME, MPMS MultiVu Application, Revision 1.61,  Build 082

INFO, NAME, TC04-12-01K
INFO, WEIGHT, 1.000
INFO, AREA, 1.000
INFO, LENGTH, 1.000
INFO, SHAPE, 0
INFO, COMMENT,
INFO, SEQUENCE FILE: TRMac_56K_0.04Kmin_VRMde_55K.seq


INFO, BACKGROUND DATA FILE:, None


STARTUPAXIS,X,4,LINEAR,AUTO,0.000000,0.000000
STARTUPAXIS,Y1,5,LINEAR,AUTO,0.000000,0.000000


STARTUPGROUP,Longitudinal
FIELDGROUP,Longitudinal,1,2,3,4,5,6,7,8,9,15,16,17,18,27,28
FIELDGROUP,Transverse,1,2,3,4,10,11,12,13,14,19,20,21,22,27,28

PLOT_APPEARANCE,ALL,HORZ_GRID_ON,VERT_GRID_ON,MARKERS_AND_LINES

[Data]
Time,Comment,Field (Oe),Temperature (K),Long Moment (emu),Long Scan Std Dev,Long Algorithm,Long Reg Fit,Long Percent Error (%),Trans Moment (emu),Trans Scan Std Dev,Trans Algorithm,Trans Reg Fit,Trans Percent Error (%),Long Moment [w/o ABS] (emu),Long Scan Std Dev [w/o ABS],Long Reg Fit [w/o ABS],Long Percent Error [w/o ABS] (%),Trans Moment [w/o ABS] (emu),Trans Scan Std Dev [w/o ABS],Trans Reg Fit [w/o ABS],Trans Percent Error [w/o ABS] (%),Points per Scan,Scans per Measurement,Scan Length (cm),Delta Temp (K),Rot Position (deg),Error,EC Comp. Running,Using ABS,
1524400819.090,,0.000000e+000,5.499248e+001,-7.006835e-006,0.000000e+000,2,8.306298e-001,0.000000e+000,,,,,,,,,,,,,,32,1,4.000000e+000,3.940582e-003,0.000000e+000,0,,0,
1524400858.200,,0.000000e+000,5.499051e+001,-3.502937e-006,0.000000e+000,2,5.965034e-001,0.000000e+000,,,,,,,,,,,,,,32,1,4.000000e+000,1.052094e-002,0.000000e+000,0,,0,
1524400895.620,,0.000000e+000,5.500366e+001,-1.899813e-006,0.000000e+000,2,2.463188e-001,0.000000e+000,,,,,,,,,,,,,,32,1,4.000000e+000,7.900238e-003,0.000000e+000,0,,0,
1524400932.990,,0.000000e+000,5.498919e+001,-9.119435e-007,0.000000e+000,2,0.000000e+000,0.000000e+000,,,,,,,,,,,,,,32,1,4.000000e+000,1.052094e-002,0.000000e+000,0,,0,
1524400970.500,,0.000000e+000,5.499380e+001,-2.666110e-007,0.000000e+000,2,0.000000e+000,0.000000e+000,,,,,,,,,,,,,,32,1,4.000000e+000,3.948212e-003,0.000000e+000,0,,0,
1524401009.210,,0.000000e+000,5.500037e+001,2.647907e-007,0.000000e+000,2,0.000000e+000,0.000000e+000,,,,,,,,,,,,,,32,1,4.000000e+000,6.587982e-003,0.000000e+000,0,,0,
1524401046.920,,0.000000e+000,5.500037e+001,6.255507e-007,0.000000e+000,2,0.000000e+000,0.000000e+000,,,,,,,,,,,,,,32,1,4.000000e+000,6.587982e-003,0.000000e+000,0,,0,
1524401084.750,,0.000000e+000,5.500169e+001,9.103248e-007,0.000000e+000,2,0.000000e+000,0.000000e+000,,,,,,,,,,,,,,32,1,4.000000e+000,1.319885e-003,0.000000e+000,0,,0,
1524401122.040,,0.000000e+000,5.499774e+001,1.209074e-006,0.000000e+000,2,0.000000e+000,0.000000e+000,,,,,,,,,,,,,,32,1,4.000000e+000,3.940582e-003,0.000000e+000,0,,0,
1524401160.501,,0.000000e+000,5.499380e+001,1.396966e-006,0.000000e+000,2,0.000000e+000,0.000000e+000,,,,,,,,,,,,,,32,1,4.000000e+000,1.182938e-002,0.000000e+000,0,,0,
1524401197.961,,0.000000e+000,5.498788e+001,1.633184e-006,0.000000e+000,2,1.364518e-001,0.000000e+000,,,,,,,,,,,,,,32,1,4.000000e+000,7.892609e-003,0.000000e+000,0,,0,
1524401235.821,,0.000000e+000,5.499314e+001,1.813057e-006,0.000000e+000,2,2.283168e-001,0.000000e+000,,,,,,,,,,,,,,32,1,4.000000e+000,0.000000e+000,0.000000e+000,0,,0,
1524401273.561,,0.000000e+000,5.500301e+001,1.984391e-006,0.000000e+000,2,2.691430e-001,0.000000e+000,,,,,,,,,,,,,,32,1,4.000000e+000,1.319885e-003,0.000000e+000,0,,0,
1524401311.461,,0.000000e+000,5.499708e+001,2.089473e-006,0.000000e+000,2,3.105281e-001,0.000000e+000,,,,,,,,,,,,,,32,1,4.000000e+000,2.620697e-003,0.000000e+000,0,,0,
1524401349.221,,0.000000e+000,5.499708e+001,2.264857e-006,0.000000e+000,2,3.562439e-001,0.000000e+000,,,,,,,,,,,,,,32,1,4.000000e+000,2.620697e-003,0.000000e+000,0,,0,
1524401387.101,,0.000000e+000,5.499248e+001,2.359220e-006,0.000000e+000,2,3.962663e-001,0.000000e+000,,,,,,,,,,,,,,32,1,4.000000e+000,6.580353e-003,0.000000e+000,0,,0,
1524401424.861,,0.000000e+000,5.499906e+001,2.496664e-006,0.000000e+000,2,4.050338e-001,0.000000e+000,,,,,,,,,,,,,,32,1,4.000000e+000,6.580353e-003,0.000000e+000,0,,0,
1524401462.741,,0.000000e+000,5.499380e+001,2.505915e-006,0.000000e+000,2,4.227796e-001,0.000000e+000,,,,,,,,,,,,,,32,1,4.000000e+000,1.308441e-003,0.000000e+000,0,,0,
1524401500.491,,0.000000e+000,5.499183e+001,2.581046e-006,0.000000e+000,2,4.373557e-001,0.000000e+000,,,,,,,,,,,,,,32,1,4.000000e+000,2.632141e-003,0.000000e+000,0,,0,
1524401538.391,,0.000000e+000,5.500037e+001,2.652615e-006,0.000000e+000,2,4.596975e-001,0.000000e+000,,,,,,,,,,,,,,32,1,4.000000e+000,1.446915e-002,0.000000e+000,0,,0,
1524401576.161,,0.000000e+000,5.499773e+001,2.735367e-006,0.000000e+000,2,4.724804e-001,0.000000e+000,,,,,,,,,,,,,,32,1,4.000000e+000,1.308441e-003,0.000000e+000,0,,0,
1524401614.041,,0.000000e+000,5.499511e+001,2.763370e-006,0.000000e+000,2,4.698466e-001,0.000000e+000,,,,,,,,,,,,,,32,1,4.000000e+000,1.319885e-003,0.000000e+000,0,,0,
1524401651.411,,0.000000e+000,5.499774e+001,2.862026e-006,0.000000e+000,2,4.807886e-001,0.000000e+000,,,,,,,,,,,,,,32,1,4.000000e+000,6.580353e-003,0.000000e+000,0,,0,
1524401688.831,,0.000000e+000,5.500497e+001,2.903909e-006,0.000000e+000,2,5.194649e-001,0.000000e+000,,,,,,,,,,,,,,32,1,4.000000e+000,0.000000e+000,0.000000e+000,0,,0,
1524401726.161,,0.000000e+000,5.499905e+001,2.930804e-006,0.000000e+000,2,4.825252e-001,0.000000e+000,,,,,,,,,,,,,,32,1,4.000000e+000,1.319885e-003,0.000000e+000,0,,0,
1524401763.931,,0.000000e+000,5.498985e+001,2.968849e-006,0.000000e+000,2,5.270534e-001,0.000000e+000,,,,,,,,,,,,,,32,1,4.000000e+000,6.580353e-003,0.000000e+000,0,,0,
1524401801.511,,0.000000e+000,5.500300e+001,2.990177e-006,0.000000e+000,2,5.080937e-001,0.000000e+000,,,,,,,,,,,,,,32,1,4.000000e+000,9.220123e-003,0.000000e+000,0,,0,
1524401839.622,,0.000000e+000,5.499511e+001,3.035857e-006,0.000000e+000,2,5.235720e-001,0.000000e+000,,,,,,,,,,,,,,32,1,4.000000e+000,1.319885e-003,0.000000e+000,0,,0,
1524401876.702,,0.000000e+000,5.499643e+001,3.069511e-006,0.000000e+000,2,5.133570e-001,0.000000e+000,,,,,,,,,,,,,,32,1,4.000000e+000,6.568909e-003,0.000000e+000,0,,0,
1524401914.712,,0.000000e+000,5.499511e+001,3.099608e-006,0.000000e+000,2,5.503696e-001,0.000000e+000,,,,,,,,,,,,,,32,1,4.000000e+000,3.940582e-003,0.000000e+000,0,,0,
1524401951.812,,0.000000e+000,5.499380e+001,3.116835e-006,0.000000e+000,2,5.327125e-001,0.000000e+000,,,,,,,,,,,,,,32,1,4.000000e+000,1.308441e-003,0.000000e+000,0,,0,
1524401989.792,,0.000000e+000,5.499445e+001,3.118701e-006,0.000000e+000,2,5.454100e-001,0.000000e+000,,,,,,,,,,,,,,32,1,4.000000e+000,2.628326e-003,0.000000e+000,0,,0,
1524402027.392,,0.000000e+000,5.499445e+001,3.201525e-006,0.000000e+000,2,5.330493e-001,0.000000e+000,,,,,,,,,,,,,,32,1,4.000000e+000,1.314926e-002,0.000000e+000,0,,0,
1524402065.462,,0.000000e+000,5.499773e+001,3.133486e-006,0.000000e+000,2,5.444010e-001,0.000000e+000,,,,,,,,,,,,,,32,1,4.000000e+000,1.308441e-003,0.000000e+000,0,,0,
1524402102.882,,0.000000e+000,5.499577e+001,3.268755e-006,0.000000e+000,2,5.445378e-001,0.000000e+000,,,,,,,,,,,,,,32,1,4.000000e+000,2.632141e-003,0.000000e+000,0,,0,
1524402141.012,,0.000000e+000,5.499182e+001,3.196450e-006,0.000000e+000,2,5.573345e-001,0.000000e+000,,,,,,,,,,,,,,32,1,4.000000e+000,0.000000e+000,0.000000e+000,0,,0,
1524402178.242,,0.000000e+000,5.500301e+001,3.252429e-006,0.000000e+000,2,5.388306e-001,0.000000e+000,,,,,,,,,,,,,,32,1,4.000000e+000,1.319885e-003,0.000000e+000,0,,0,
1524402216.152,,0.000000e+000,5.499380e+001,3.229600e-006,0.000000e+000,2,5.509738e-001,0.000000e+000,,,,,,,,,,,,,,32,1,4.000000e+000,1.308441e-003,0.000000e+000,0,,0,
1524402253.792,,0.000000e+000,5.500037e+001,3.382165e-006,0.000000e+000,2,5.691817e-001,0.000000e+000,,,,,,,,,,,,,,32,1,4.000000e+000,1.319885e-003,0.000000e+000,0,,0,
1524402291.582,,0.000000e+000,5.499577e+001,3.302203e-006,0.000000e+000,2,5.587854e-001,0.000000e+000,,,,,,,,,,,,,,32,1,4.000000e+000,2.632141e-003,0.000000e+000,0,,0,
1524402329.412,,0.000000e+000,5.500103e+001,3.335410e-006,0.000000e+000,2,5.483327e-001,0.000000e+000,,,,,,,,,,,,,,32,1,4.000000e+000,5.279541e-003,0.000000e+000,0,,0,
1524402367.472,,0.000000e+000,5.499840e+001,3.260746e-006,0.000000e+000,2,5.656654e-001,0.000000e+000,,,,,,,,,,,,,,32,1,4.000000e+000,2.628326e-003,0.000000e+000,0,,0,
1524402405.892,,0.000000e+000,5.500564e+001,3.305905e-006,0.000000e+000,2,5.645936e-001,0.000000e+000,,,,,,,,,,,,,,32,1,4.000000e+000,3.940582e-003,0.000000e+000,0,,0,
1524402443.482,,0.000000e+000,5.499379e+001,3.388526e-006,0.000000e+000,2,5.790759e-001,0.000000e+000,,,,,,,,,,,,,,32,1,4.000000e+000,9.201050e-003,0.000000e+000,0,,0,
1524402480.392,,0.000000e+000,5.500169e+001,3.371791e-006,0.000000e+000,2,5.421416e-001,0.000000e+000,,,,,,,,,,,,,,32,1,4.000000e+000,3.959656e-003,0.000000e+000,0,,0,
1524402518.872,,0.000000e+000,5.499445e+001,3.426959e-006,0.000000e+000,2,5.747370e-001,0.000000e+000,,,,,,,,,,,,,,32,1,4.000000e+000,0.000000e+000,0.000000e+000,0,,0,
1524402556.723,,0.000000e+000,5.499511e+001,3.342176e-006,0.000000e+000,2,5.498397e-001,0.000000e+000,,,,,,,,,,,,,,32,1,4.000000e+000,6.568909e-003,0.000000e+000,0,,0,
1524402594.533,,0.000000e+000,5.499971e+001,3.400758e-006,0.000000e+000,2,5.741277e-001,0.000000e+000,,,,,,,,,,,,,,32,1,4.000000e+000,0.000000e+000,0.000000e+000,0,,0,
1524402631.543,,0.000000e+000,5.499380e+001,3.463100e-006,0.000000e+000,2,5.646437e-001,0.000000e+000,,,,,,,,,,,,,,32,1,4.000000e+000,6.572723e-003,0.000000e+000,0,,0,
1524402669.043,,0.000000e+000,5.499511e+001,3.438533e-006,0.000000e+000,2,5.631166e-001,0.000000e+000,,,,,,,,,,,,,,32,1,4.000000e+000,6.568909e-003,0.000000e+000,0,,0,
1524402706.243,,0.000000e+000,5.500169e+001,3.447978e-006,0.000000e+000,2,5.675852e-001,0.000000e+000,,,,,,,,,,,,,,32,1,4.000000e+000,1.319885e-003,0.000000e+000,0,,0,
1524402744.053,,0.000000e+000,5.499445e+001,3.494068e-006,0.000000e+000,2,5.948675e-001,0.000000e+000,,,,,,,,,,,,,,32,1,4.000000e+000,2.628326e-003,0.000000e+000,0,,0,
1524402782.493,,0.000000e+000,5.500037e+001,3.473958e-006,0.000000e+000,2,5.856053e-001,0.000000e+000,,,,,,,,,,,,,,32,1,4.000000e+000,1.184082e-002,0.000000e+000,0,,0,
1524402820.053,,0.000000e+000,5.499643e+001,3.553779e-006,0.000000e+000,2,5.892019e-001,0.000000e+000,,,,,,,,,,,,,,32,1,4.000000e+000,1.312256e-003,0.000000e+000,0,,0,
1524402858.023,,0.000000e+000,5.499380e+001,3.490673e-006,0.000000e+000,2,5.860630e-001,0.000000e+000,,,,,,,,,,,,,,32,1,4.000000e+000,3.948212e-003,0.000000e+000,0,,0,
1524402895.673,,0.000000e+000,5.500169e+001,3.569239e-006,0.000000e+000,2,5.957676e-001,0.000000e+000,,,,,,,,,,,,,,32,1,4.000000e+000,1.319885e-003,0.000000e+000,0,,0,
1524402933.663,,0.000000e+000,5.499511e+001,3.527892e-006,0.000000e+000,2,5.874687e-001,0.000000e+000,,,,,,,,,,,,,,32,1,4.000000e+000,3.940582e-003,0.000000e+000,0,,0,
1524402971.433,,0.000000e+000,5.499708e+001,3.550748e-006,0.000000e+000,2,5.799082e-001,0.000000e+000,,,,,,,,,,,,,,32,1,4.000000e+000,2.620697e-003,0.000000e+000,0,,0,
1524403009.353,,0.000000e+000,5.499972e+001,3.574638e-006,0.000000e+000,2,5.947801e-001,0.000000e+000,,,,,,,,,,,,,,32,1,4.000000e+000,7.900238e-003,0.000000e+000,0,,0,
1524403046.983,,0.000000e+000,5.499905e+001,3.586867e-006,0.000000e+000,2,5.858048e-001,0.000000e+000,,,,,,,,,,,,,,32,1,4.000000e+000,1.319885e-003,0.000000e+000,0,,0,
1524403084.953,,0.000000e+000,5.499577e+001,3.544477e-006,0.000000e+000,2,5.920168e-001,0.000000e+000,,,,,,,,,,,,,,32,1,4.000000e+000,2.632141e-003,0.000000e+000,0,,0,
1524403122.853,,0.000000e+000,5.499708e+001,3.576184e-006,0.000000e+000,2,5.689702e-001,0.000000e+000,,,,,,,,,,,,,,32,1,4.000000e+000,2.620697e-003,0.000000e+000,0,,0,
1524403160.983,,0.000000e+000,5.499709e+001,3.599657e-006,0.000000e+000,2,5.892735e-001,0.000000e+000,,,,,,,,,,,,,,32,1,4.000000e+000,1.052856e-002,0.000000e+000,0,,0,
1524403198.393,,0.000000e+000,5.499774e+001,3.608809e-006,0.000000e+000,2,6.005085e-001,0.000000e+000,,,,,,,,,,,,,,32,1,4.000000e+000,6.580353e-003,0.000000e+000,0,,0,
1524403235.793,,0.000000e+000,5.499840e+001,3.633180e-006,0.000000e+000,2,5.917258e-001,0.000000e+000,,,,,,,,,,,,,,32,1,4.000000e+000,5.260468e-003,0.000000e+000,0,,0,
1524403273.704,,0.000000e+000,5.500300e+001,3.606560e-006,0.000000e+000,2,6.002604e-001,0.000000e+000,,,,,,,,,,,,,,32,1,4.000000e+000,9.220123e-003,0.000000e+000,0,,0,
1524403311.994,,0.000000e+000,5.499445e+001,3.517548e-006,0.000000e+000,2,5.809054e-001,0.000000e+000,,,,,,,,,,,,,,32,1,4.000000e+000,5.260468e-003,0.000000e+000,0,,0,
1524403349.534,,0.000000e+000,5.500432e+001,3.576155e-006,0.000000e+000,2,5.930005e-001,0.000000e+000,,,,,,,,,,,,,,32,1,4.000000e+000,3.940582e-003,0.000000e+000,0,,0,
1524403387.564,,0.000000e+000,5.500037e+001,3.641612e-006,0.000000e+000,2,6.055428e-001,0.000000e+000,,,,,,,,,,,,,,32,1,4.000000e+000,6.587982e-003,0.000000e+000,0,,0,
1524403425.184,,0.000000e+000,5.499577e+001,3.710966e-006,0.000000e+000,2,5.899752e-001,0.000000e+000,,,,,,,,,,,,,,32,1,4.000000e+000,2.632141e-003,0.000000e+000,0,,0,
1524403463.184,,0.000000e+000,5.499971e+001,3.617364e-006,0.000000e+000,2,5.991647e-001,0.000000e+000,,,,,,,,,,,,,,32,1,4.000000e+000,2.639771e-003,0.000000e+000,0,,0,
1524403500.834,,0.000000e+000,5.499643e+001,3.629649e-006,0.000000e+000,2,5.937570e-001,0.000000e+000,,,,,,,,,,,,,,32,1,4.000000e+000,1.312256e-003,0.000000e+000,0,,0,
1524403538.814,,0.000000e+000,5.499380e+001,3.649244e-006,0.000000e+000,2,5.962553e-001,0.000000e+000,,,,,,,,,,,,,,32,1,4.000000e+000,6.572723e-003,0.000000e+000,0,,0,
1524403576.414,,0.000000e+000,5.500037e+001,3.679890e-006,0.000000e+000,2,5.950964e-001,0.000000e+000,,,,,,,,,,,,,,32,1,4.000000e+000,3.959656e-003,0.000000e+000,0,,0,
1524403614.274,,0.000000e+000,5.499511e+001,3.691448e-006,0.000000e+000,2,6.174059e-001,0.000000e+000,,,,,,,,,,,,,,32,1,4.000000e+000,6.568909e-003,0.000000e+000,0,,0,
1524403652.084,,0.000000e+000,5.500497e+001,3.670060e-006,0.000000e+000,2,5.895398e-001,0.000000e+000,,,,,,,,,,,,,,32,1,4.000000e+000,0.000000e+000,0.000000e+000,0,,0,
1524403690.144,,0.000000e+000,5.500235e+001,3.652231e-006,0.000000e+000,2,5.993062e-001,0.000000e+000,,,,,,,,,,,,,,32,1,4.000000e+000,1.840973e-002,0.000000e+000,0,,0,
1524403727.754,,0.000000e+000,5.500366e+001,3.694530e-006,0.000000e+000,2,5.979983e-001,0.000000e+000,,,,,,,,,,,,,,32,1,4.000000e+000,2.620697e-003,0.000000e+000,0,,0,
1524403765.764,,0.000000e+000,5.500169e+001,3.691430e-006,0.000000e+000,2,6.095949e-001,0.000000e+000,,,,,,,,,,,,,,32,1,4.000000e+000,1.319885e-003,0.000000e+000,0,,0,
1524403803.364,,0.000000e+000,5.500037e+001,3.711125e-006,0.000000e+000,2,6.000788e-001,0.000000e+000,,,,,,,,,,,,,,32,1,4.000000e+000,1.446915e-002,0.000000e+000,0,,0,
1524403841.384,,0.000000e+000,5.500037e+001,3.655907e-006,0.000000e+000,2,5.986755e-001,0.000000e+000,,,,,,,,,,,,,,32,1,4.000000e+000,1.319885e-003,0.000000e+000,0,,0,
1524403878.974,,0.000000e+000,5.499774e+001,3.674369e-006,0.000000e+000,2,5.889676e-001,0.000000e+000,,,,,,,,,,,,,,32,1,4.000000e+000,3.940582e-003,0.000000e+000,0,,0,
1524403917.164,,0.000000e+000,5.500366e+001,3.776405e-006,0.000000e+000,2,6.167755e-001,0.000000e+000,,,,,,,,,,,,,,32,1,4.000000e+000,5.260468e-003,0.000000e+000,0,,0,
1524403954.604,,0.000000e+000,5.500169e+001,3.728154e-006,0.000000e+000,2,5.971279e-001,0.000000e+000,,,,,,,,,,,,,,32,1,4.000000e+000,1.446915e-002,0.000000e+000,0,,0,
1524403992.765,,0.000000e+000,5.500235e+001,3.743252e-006,0.000000e+000,2,6.103836e-001,0.000000e+000,,,,,,,,,,,,,,32,1,4.000000e+000,2.639771e-003,0.000000e+000,0,,0,
1524404030.655,,0.000000e+000,5.499117e+001,3.663903e-006,0.000000e+000,2,5.745035e-001,0.000000e+000,,,,,,,,,,,,,,32,1,4.000000e+000,3.952026e-003,0.000000e+000,0,,0,
1524404068.575,,0.000000e+000,5.499642e+001,3.688968e-006,0.000000e+000,2,5.976243e-001,0.000000e+000,,,,,,,,,,,,,,32,1,4.000000e+000,3.940582e-003,0.000000e+000,0,,0,
1524404106.445,,0.000000e+000,5.499380e+001,3.667846e-006,0.000000e+000,2,5.940776e-001,0.000000e+000,,,,,,,,,,,,,,32,1,4.000000e+000,1.308441e-003,0.000000e+000,0,,0,
1524404144.415,,0.000000e+000,5.499511e+001,3.733687e-006,0.000000e+000,2,5.879993e-001,0.000000e+000,,,,,,,,,,,,,,32,1,4.000000e+000,6.568909e-003,0.000000e+000,0,,0,
1524404182.235,,0.000000e+000,5.499643e+001,3.698618e-006,0.000000e+000,2,6.040412e-001,0.000000e+000,,,,,,,,,,,,,,32,1,4.000000e+000,1.312256e-003,0.000000e+000,0,,0,
1524404220.005,,0.000000e+000,5.499117e+001,3.778139e-006,0.000000e+000,2,5.906149e-001,0.000000e+000,,,,,,,,,,,,,,32,1,4.000000e+000,6.568909e-003,0.000000e+000,0,,0,
1524404257.955,,0.000000e+000,5.499971e+001,3.632921e-006,0.000000e+000,2,6.074130e-001,0.000000e+000,,,,,,,,,,,,,,32,1,4.000000e+000,0.000000e+000,0.000000e+000,0,,0,
1524404295.595,,0.000000e+000,5.500103e+001,3.762350e-006,0.000000e+000,2,5.990338e-001,0.000000e+000,,,,,,,,,,,,,,32,1,4.000000e+000,5.279541e-003,0.000000e+000,0,,0,
1524404333.635,,0.000000e+000,5.499774e+001,3.725024e-006,0.000000e+000,2,6.085390e-001,0.000000e+000,,,,,,,,,,,,,,32,1,4.000000e+000,6.580353e-003,0.000000e+000,0,,0,
1524404371.205,,0.000000e+000,5.500431e+001,3.726260e-006,0.000000e+000,2,5.986080e-001,0.000000e+000,,,,,,,,,,,,,,32,1,4.000000e+000,9.208679e-003,0.000000e+000,0,,0,
1524404409.255,,0.000000e+000,5.499972e+001,3.781312e-006,0.000000e+000,2,6.160414e-001,0.000000e+000,,,,,,,,,,,,,,32,1,4.000000e+000,7.900238e-003,0.000000e+000,0,,0,
1524404446.805,,0.000000e+000,5.499708e+001,3.752216e-006,0.000000e+000,2,5.872682e-001,0.000000e+000,,,,,,,,,,,,,,32,1,4.000000e+000,2.620697e-003,0.000000e+000,0,,0,
1524404484.865,,0.000000e+000,5.500037e+001,3.690868e-006,0.000000e+000,2,5.994189e-001,0.000000e+000,,,,,,,,,,,,,,32,1,4.000000e+000,1.184082e-002,0.000000e+000,0,,0,
1524404522.455,,0.000000e+000,5.499380e+001,3.734385e-006,0.000000e+000,2,5.893409e-001,0.000000e+000,,,,,,,,,,,,,,32,1,4.000000e+000,2.235031e-002,0.000000e+000,0,,0,
1524404560.825,,0.000000e+000,5.500301e+001,3.712958e-006,0.000000e+000,2,5.868435e-001,0.000000e+000,,,,,,,,,,,,,,32,1,4.000000e+000,1.972961e-002,0.000000e+000,0,,0,
1524404598.915,,0.000000e+000,5.499708e+001,3.772953e-006,0.000000e+000,2,6.078738e-001,0.000000e+000,,,,,,,,,,,,,,32,1,4.000000e+000,5.260468e-003,0.000000e+000,0,,0,
1524404636.005,,0.000000e+000,5.499380e+001,3.794737e-006,0.000000e+000,2,5.991488e-001,0.000000e+000,,,,,,,,,,,,,,32,1,4.000000e+000,1.308441e-003,0.000000e+000,0,,0,
1524404673.885,,0.000000e+000,5.499905e+001,3.796441e-006,0.000000e+000,2,6.095588e-001,0.000000e+000,,,,,,,,,,,,,,32,1,4.000000e+000,1.319885e-003,0.000000e+000,0,,0,
1524404712.346,,0.000000e+000,5.500169e+001,3.791022e-006,0.000000e+000,2,6.150979e-001,0.000000e+000,,,,,,,,,,,,,,32,1,4.000000e+000,3.959656e-003,0.000000e+000,0,,0,
1524404749.996,,0.000000e+000,5.499314e+001,3.776412e-006,0.000000e+000,2,5.956668e-001,0.000000e+000,,,,,,,,,,,,,,32,1,4.000000e+000,0.000000e+000,0.000000e+000,0,,0,
1524404788.036,,0.000000e+000,5.499708e+001,3.779446e-006,0.000000e+000,2,6.122820e-001,0.000000e+000,,,,,,,,,,,,,,32,1,4.000000e+000,5.260468e-003,0.000000e+000,0,,0,
1524404825.646,,0.000000e+000,5.500366e+001,3.839918e-006,0.000000e+000,2,6.009695e-001,0.000000e+000,,,,,,,,,,,,,,32,1,4.000000e+000,5.260468e-003,0.000000e+000,0,,0,
1524404864.046,,0.000000e+000,5.499380e+001,3.882947e-006,0.000000e+000,2,6.048249e-001,0.000000e+000,,,,,,,,,,,,,,32,1,4.000000e+000,6.572723e-003,0.000000e+000,0,,0,
1524404902.316,,0.000000e+000,5.500301e+001,3.859277e-006,0.000000e+000,2,6.093259e-001,0.000000e+000,,,,,,,,,,,,,,32,1,4.000000e+000,1.319885e-003,0.000000e+000,0,,0,
1524404939.636,,0.000000e+000,5.499708e+001,3.862577e-006,0.000000e+000,2,5.884438e-001,0.000000e+000,,,,,,,,,,,,,,32,1,4.000000e+000,0.000000e+000,0.000000e+000,0,,0,
1524404978.196,,0.000000e+000,5.499380e+001,3.755484e-006,0.000000e+000,2,5.948042e-001,0.000000e+000,,,,,,,,,,,,,,32,1,4.000000e+000,1.308441e-003,0.000000e+000,0,,0,
1524405016.136,,0.000000e+000,5.499577e+001,3.818870e-006,0.000000e+000,2,6.105334e-001,0.000000e+000,,,,,,,,,,,,,,32,1,4.000000e+000,0.000000e+000,0.000000e+000,0,,0,
1524405053.496,,0.000000e+000,5.499840e+001,3.862121e-006,0.000000e+000,2,5.961885e-001,0.000000e+000,,,,,,,,,,,,,,32,1,4.000000e+000,7.900238e-003,0.000000e+000,0,,0,
1524405091.136,,0.000000e+000,5.499773e+001,3.825103e-006,0.000000e+000,2,6.166524e-001,0.000000e+000,,,,,,,,,,,,,,32,1,4.000000e+000,1.308441e-003,0.000000e+000,0,,0,
1524405128.986,,0.000000e+000,5.499511e+001,3.762423e-006,0.000000e+000,2,5.807032e-001,0.000000e+000,,,,,,,,,,,,,,32,1,4.000000e+000,9.201050e-003,0.000000e+000,0,,0,
1524405166.396,,0.000000e+000,5.499971e+001,3.839884e-006,0.000000e+000,2,6.071481e-001,0.000000e+000,,,,,,,,,,,,,,32,1,4.000000e+000,2.639771e-003,0.000000e+000,0,,0,
1524405204.946,,0.000000e+000,5.499971e+001,3.782015e-006,0.000000e+000,2,6.082659e-001,0.000000e+000,,,,,,,,,,,,,,32,1,4.000000e+000,0.000000e+000,0.000000e+000,0,,0,
1524405242.696,,0.000000e+000,5.499643e+001,3.867275e-006,0.000000e+000,2,5.987235e-001,0.000000e+000,,,,,,,,,,,,,,32,1,4.000000e+000,9.208679e-003,0.000000e+000,0,,0,
1524405280.606,,0.000000e+000,5.499905e+001,3.816247e-006,0.000000e+000,2,6.106427e-001,0.000000e+000,,,,,,,,,,,,,,32,1,4.000000e+000,3.948212e-003,0.000000e+000,0,,0,
1524405318.356,,0.000000e+000,5.500103e+001,3.893818e-006,0.000000e+000,2,6.133501e-001,0.000000e+000,,,,,,,,,,,,,,32,1,4.000000e+000,5.279541e-003,0.000000e+000,0,,0,
1524405356.266,,0.000000e+000,5.500629e+001,3.808427e-006,0.000000e+000,2,6.062621e-001,0.000000e+000,,,,,,,,,,,,,,32,1,4.000000e+000,5.249023e-003,0.000000e+000,0,,0,
1524405394.016,,0.000000e+000,5.499117e+001,3.890178e-006,0.000000e+000,2,6.041068e-001,0.000000e+000,,,,,,,,,,,,,,32,1,4.000000e+000,3.952026e-003,0.000000e+000,0,,0,
1524405431.927,,0.000000e+000,5.499906e+001,3.855873e-006,0.000000e+000,2,6.094505e-001,0.000000e+000,,,,,,,,,,,,,,32,1,4.000000e+000,9.220123e-003,0.000000e+000,0,,0,
1524405469.867,,0.000000e+000,5.499051e+001,3.824209e-006,0.000000e+000,2,5.859734e-001,0.000000e+000,,,,,,,,,,,,,,32,1,4.000000e+000,5.260468e-003,0.000000e+000,0,,0,
1524405507.857,,0.000000e+000,5.499972e+001,3.855659e-006,0.000000e+000,2,6.166691e-001,0.000000e+000,,,,,,,,,,,,,,32,1,4.000000e+000,5.268097e-003,0.000000e+000,0,,0,
1524405545.177,,0.000000e+000,5.499577e+001,3.869550e-006,0.000000e+000,2,5.999627e-001,0.000000e+000,,,,,,,,,,,,,,32,1,4.000000e+000,1.052094e-002,0.000000e+000,0,,0,
1524405582.387,,0.000000e+000,5.499708e+001,3.899366e-006,0.000000e+000,2,6.244723e-001,0.000000e+000,,,,,,,,,,,,,,32,1,4.000000e+000,0.000000e+000,0.000000e+000,0,,0,
1524405619.527,,0.000000e+000,5.500037e+001,3.883101e-006,0.000000e+000,2,5.956531e-001,0.000000e+000,,,,,,,,,,,,,,32,1,4.000000e+000,1.319885e-003,0.000000e+000,0,,0,
1524405657.457,,0.000000e+000,5.499906e+001,3.867850e-006,0.000000e+000,2,6.129604e-001,0.000000e+000,,,,,,,,,,,,,,32,1,4.000000e+000,9.220123e-003,0.000000e+000,0,,0,
1524405695.527,,0.000000e+000,5.500103e+001,3.844429e-006,0.000000e+000,2,5.921702e-001,0.000000e+000,,,,,,,,,,,,,,32,1,4.000000e+000,2.639771e-003,0.000000e+000,0,,0,
1524405732.797,,0.000000e+000,5.500300e+001,3.861890e-006,0.000000e+000,2,6.112022e-001,0.000000e+000,,,,,,,,,,,,,,32,1,4.000000e+000,9.220123e-003,0.000000e+000,0,,0,
1524405771.107,,0.000000e+000,5.499906e+001,3.847101e-006,0.000000e+000,2,6.223359e-001,0.000000e+000,,,,,,,,,,,,,,32,1,4.000000e+000,6.580353e-003,0.000000e+000,0,,0,
1524405809.347,,0.000000e+000,5.499314e+001,3.877302e-006,0.000000e+000,2,5.986751e-001,0.000000e+000,,,,,,,,,,,,,,32,1,4.000000e+000,5.260468e-003,0.000000e+000,0,,0,
1524405847.497,,0.000000e+000,5.499511e+001,3.926249e-006,0.000000e+000,2,5.953349e-001,0.000000e+000,,,,,,,,,,,,,,32,1,4.000000e+000,3.940582e-003,0.000000e+000,0,,0,
1524405885.637,,0.000000e+000,5.499905e+001,3.855054e-006,0.000000e+000,2,6.115854e-001,0.000000e+000,,,,,,,,,,,,,,32,1,4.000000e+000,1.319885e-003,0.000000e+000,0,,0,
1524405922.637,,0.000000e+000,5.499774e+001,3.814170e-006,0.000000e+000,2,5.886077e-001,0.000000e+000,,,,,,,,,,,,,,32,1,4.000000e+000,3.940582e-003,0.000000e+000,0,,0,
1524405959.677,,0.000000e+000,5.499905e+001,3.848207e-006,0.000000e+000,2,6.076431e-001,0.000000e+000,,,,,,,,,,,,,,32,1,4.000000e+000,3.948212e-003,0.000000e+000,0,,0,
1524405997.797,,0.000000e+000,5.500563e+001,3.822991e-006,0.000000e+000,2,5.859195e-001,0.000000e+000,,,,,,,,,,,,,,32,1,4.000000e+000,1.319885e-003,0.000000e+000,0,,0,
1524406035.767,,0.000000e+000,5.499708e+001,3.919932e-006,0.000000e+000,2,6.127161e-001,0.000000e+000,,,,,,,,,,,,,,32,1,4.000000e+000,2.620697e-003,0.000000e+000,0,,0,
1524406073.737,,0.000000e+000,5.499773e+001,3.879328e-006,0.000000e+000,2,6.116179e-001,0.000000e+000,,,,,,,,,,,,,,32,1,4.000000e+000,1.308441e-003,0.000000e+000,0,,0,
1524406111.317,,0.000000e+000,5.500037e+001,3.857154e-006,0.000000e+000,2,5.980847e-001,0.000000e+000,,,,,,,,,,,,,,32,1,4.000000e+000,3.959656e-003,0.000000e+000,0,,0,
1524406149.188,,0.000000e+000,5.499248e+001,3.842519e-006,0.000000e+000,2,6.181897e-001,0.000000e+000,,,,,,,,,,,,,,32,1,4.000000e+000,1.182938e-002,0.000000e+000,0,,0,
1524406186.298,,0.000000e+000,5.499708e+001,3.874924e-006,0.000000e+000,2,5.965980e-001,0.000000e+000,,,,,,,,,,,,,,32,1,4.000000e+000,0.000000e+000,0.000000e+000,0,,0,
1524406223.958,,0.000000e+000,5.499708e+001,3.890060e-006,0.000000e+000,2,6.070421e-001,0.000000e+000,,,,,,,,,,,,,,32,1,4.000000e+000,0.000000e+000,0.000000e+000,0,,0,
1524406261.558,,0.000000e+000,5.500564e+001,3.894874e-006,0.000000e+000,2,5.993443e-001,0.000000e+000,,,,,,,,,,,,,,32,1,4.000000e+000,3.940582e-003,0.000000e+000,0,,0,
1524406299.638,,0.000000e+000,5.499773e+001,3.855287e-006,0.000000e+000,2,6.059679e-001,0.000000e+000,,,,,,,,,,,,,,32,1,4.000000e+000,1.308441e-003,0.000000e+000,0,,0,
1524406337.258,,0.000000e+000,5.499643e+001,3.890645e-006,0.000000e+000,2,5.948057e-001,0.000000e+000,,,,,,,,,,,,,,32,1,4.000000e+000,9.208679e-003,0.000000e+000,0,,0,
1524406375.258,,0.000000e+000,5.499774e+001,3.871371e-006,0.000000e+000,2,6.158758e-001,0.000000e+000,,,,,,,,,,,,,,32,1,4.000000e+000,3.940582e-003,0.000000e+000,0,,0,
1524406412.938,,0.000000e+000,5.500300e+001,3.916753e-006,0.000000e+000,2,6.137969e-001,0.000000e+000,,,,,,,,,,,,,,32,1,4.000000e+000,1.183701e-002,0.000000e+000,0,,0,
1524406450.918,,0.000000e+000,5.499445e+001,3.864140e-006,0.000000e+000,2,6.062722e-001,0.000000e+000,,,,,,,,,,,,,,32,1,4.000000e+000,5.260468e-003,0.000000e+000,0,,0,
1524406488.498,,0.000000e+000,5.499313e+001,3.886906e-006,0.000000e+000,2,5.918653e-001,0.000000e+000,,,,,,,,,,,,,,32,1,4.000000e+000,7.892609e-003,0.000000e+000,0,,0,
1524406525.648,,0.000000e+000,5.499708e+001,3.837903e-006,0.000000e+000,2,6.064854e-001,0.000000e+000,,,,,,,,,,,,,,32,1,4.000000e+000,2.620697e-003,0.000000e+000,0,,0,
1524406564.398,,0.000000e+000,5.500366e+001,3.875130e-006,0.000000e+000,2,6.084607e-001,0.000000e+000,,,,,,,,,,,,,,32,1,4.000000e+000,5.260468e-003,0.000000e+000,0,,0,
1524406601.418,,0.000000e+000,5.500629e+001,3.894564e-006,0.000000e+000,2,6.075625e-001,0.000000e+000,,,,,,,,,,,,,,32,1,4.000000e+000,0.000000e+000,0.000000e+000,0,,0,
1524406639.288,,0.000000e+000,5.499642e+001,3.863606e-006,0.000000e+000,2,6.093984e-001,0.000000e+000,,,,,,,,,,,,,,32,1,4.000000e+000,3.940582e-003,0.000000e+000,0,,0,
1524406677.028,,0.000000e+000,5.499577e+001,3.859237e-006,0.000000e+000,2,6.005720e-001,0.000000e+000,,,,,,,,,,,,,,32,1,4.000000e+000,5.249023e-003,0.000000e+000,0,,0,
1524406714.938,,0.000000e+000,5.499117e+001,3.857524e-006,0.000000e+000,2,6.089681e-001,0.000000e+000,,,,,,,,,,,,,,32,1,4.000000e+000,1.183319e-002,0.000000e+000,0,,0,
1524406752.698,,0.000000e+000,5.499116e+001,3.870876e-006,0.000000e+000,2,6.010994e-001,0.000000e+000,,,,,,,,,,,,,,32,1,4.000000e+000,1.446152e-002,0.000000e+000,0,,0,
1524406790.818,,0.000000e+000,5.499643e+001,3.888641e-006,0.000000e+000,2,6.219610e-001,0.000000e+000,,,,,,,,,,,,,,32,1,4.000000e+000,6.568909e-003,0.000000e+000,0,,0,
1524406827.838,,0.000000e+000,5.499248e+001,3.945132e-006,0.000000e+000,2,6.080685e-001,0.000000e+000,,,,,,,,,,,,,,32,1,4.000000e+000,9.201050e-003,0.000000e+000,0,,0,
1524406865.709,,0.000000e+000,5.499577e+001,3.878106e-006,0.000000e+000,2,6.051047e-001,0.000000e+000,,,,,,,,,,,,,,32,1,4.000000e+000,5.249023e-003,0.000000e+000,0,,0,
1524406903.469,,0.000000e+000,5.499051e+001,3.861283e-006,0.000000e+000,2,6.095224e-001,0.000000e+000,,,,,,,,,,,,,,32,1,4.000000e+000,1.576996e-002,0.000000e+000,0,,0,
1524406941.389,,0.000000e+000,5.500037e+001,3.877430e-006,0.000000e+000,2,6.142318e-001,0.000000e+000,,,,,,,,,,,,,,32,1,4.000000e+000,1.319885e-003,0.000000e+000,0,,0,
1524406979.169,,0.000000e+000,5.499643e+001,3.907164e-006,0.000000e+000,2,6.009980e-001,0.000000e+000,,,,,,,,,,,,,,32,1,4.000000e+000,6.568909e-003,0.000000e+000,0,,0,
1524407017.039,,0.000000e+000,5.500432e+001,3.710036e-006,0.000000e+000,2,6.020973e-001,0.000000e+000,,,,,,,,,,,,,,32,1,4.000000e+000,3.940582e-003,0.000000e+000,0,,0,
1524407054.809,,0.000000e+000,5.500037e+001,3.935986e-006,0.000000e+000,2,6.074070e-001,0.000000e+000,,,,,,,,,,,,,,32,1,4.000000e+000,1.319885e-003,0.000000e+000,0,,0,
1524407092.689,,0.000000e+000,5.499642e+001,3.748736e-006,0.000000e+000,2,6.095212e-001,0.000000e+000,,,,,,,,,,,,,,32,1,4.000000e+000,3.940582e-003,0.000000e+000,0,,0,
1524407130.449,,0.000000e+000,5.499643e+001,3.890103e-006,0.000000e+000,2,6.095482e-001,0.000000e+000,,,,,,,,,,,,,,32,1,4.000000e+000,1.312256e-003,0.000000e+000,0,,0,
1524407168.349,,0.000000e+000,5.499708e+001,3.766733e-006,0.000000e+000,2,6.089156e-001,0.000000e+000,,,,,,,,,,,,,,32,1,4.000000e+000,2.620697e-003,0.000000e+000,0,,0,
1524407206.109,,0.000000e+000,5.500103e+001,3.974252e-006,0.000000e+000,2,6.135433e-001,0.000000e+000,,,,,,,,,,,,,,32,1,4.000000e+000,2.639771e-003,0.000000e+000,0,,0,
1524407244.019,,0.000000e+000,5.500366e+001,3.760862e-006,0.000000e+000,2,6.110555e-001,0.000000e+000,,,,,,,,,,,,,,32,1,4.000000e+000,2.620697e-003,0.000000e+000,0,,0,
1524407281.769,,0.000000e+000,5.499182e+001,3.880336e-006,0.000000e+000,2,5.940897e-001,0.000000e+000,,,,,,,,,,,,,,32,1,4.000000e+000,5.260468e-003,0.000000e+000,0,,0,
1524407319.679,,0.000000e+000,5.499774e+001,3.742963e-006,0.000000e+000,2,6.110318e-001,0.000000e+000,,,,,,,,,,,,,,32,1,4.000000e+000,3.940582e-003,0.000000e+000,0,,0,
1524407357.049,,0.000000e+000,5.499709e+001,3.925369e-006,0.000000e+000,2,6.122138e-001,0.000000e+000,,,,,,,,,,,,,,32,1,4.000000e+000,1.316071e-002,0.000000e+000,0,,0,
1524407394.639,,0.000000e+000,5.499313e+001,3.771728e-006,0.000000e+000,2,5.923242e-001,0.000000e+000,,,,,,,,,,,,,,32,1,4.000000e+000,2.628326e-003,0.000000e+000,0,,0,
1524407432.239,,0.000000e+000,5.499906e+001,3.882364e-006,0.000000e+000,2,6.152665e-001,0.000000e+000,,,,,,,,,,,,,,32,1,4.000000e+000,9.220123e-003,0.000000e+000,0,,0,
1524407469.159,,0.000000e+000,5.499906e+001,3.873695e-006,0.000000e+000,2,5.763512e-001,0.000000e+000,,,,,,,,,,,,,,32,1,4.000000e+000,6.580353e-003,0.000000e+000,0,,0,
1524407507.209,,0.000000e+000,5.499905e+001,3.893792e-006,0.000000e+000,2,6.241158e-001,0.000000e+000,,,,,,,,,,,,,,32,1,4.000000e+000,1.319885e-003,0.000000e+000,0,,0,
1524407545.019,,0.000000e+000,5.499445e+001,3.856066e-006,0.000000e+000,2,6.050414e-001,0.000000e+000,,,,,,,,,,,,,,32,1,4.000000e+000,2.628326e-003,0.000000e+000,0,,0,
1524407582.840,,0.000000e+000,5.500037e+001,3.835123e-006,0.000000e+000,2,5.872901e-001,0.000000e+000,,,,,,,,,,,,,,32,1,4.000000e+000,6.587982e-003,0.000000e+000,0,,0,
1524407620.910,,0.000000e+000,5.500234e+001,3.910553e-006,0.000000e+000,2,6.197500e-001,0.000000e+000,,,,,,,,,,,,,,32,1,4.000000e+000,5.260468e-003,0.000000e+000,0,,0,
1524407657.740,,0.000000e+000,5.499248e+001,3.823494e-006,0.000000e+000,2,5.830192e-001,0.000000e+000,,,,,,,,,,,,,,32,1,4.000000e+000,1.710129e-002,0.000000e+000,0,,0,
1524407695.650,,0.000000e+000,5.500168e+001,3.886240e-006,0.000000e+000,2,6.069083e-001,0.000000e+000,,,,,,,,,,,,,,32,1,4.000000e+000,6.580353e-003,0.000000e+000,0,,0,
1524407733.530,,0.000000e+000,5.499511e+001,3.872898e-006,0.000000e+000,2,6.029661e-001,0.000000e+000,,,,,,,,,,,,,,32,1,4.000000e+000,1.184082e-002,0.000000e+000,0,,0,
1524407770.780,,0.000000e+000,5.499380e+001,3.847530e-006,0.000000e+000,2,5.858574e-001,0.000000e+000,,,,,,,,,,,,,,32,1,4.000000e+000,1.446915e-002,0.000000e+000,0,,0,
1524407808.280,,0.000000e+000,5.499972e+001,3.906650e-006,0.000000e+000,2,6.181468e-001,0.000000e+000,,,,,,,,,,,,,,32,1,4.000000e+000,5.268097e-003,0.000000e+000,0,,0,
1524407846.150,,0.000000e+000,5.499445e+001,3.867030e-006,0.000000e+000,2,5.938660e-001,0.000000e+000,,,,,,,,,,,,,,32,1,4.000000e+000,0.000000e+000,0.000000e+000,0,,0,
1524407883.150,,0.000000e+000,5.499511e+001,3.872828e-006,0.000000e+000,2,6.120146e-001,0.000000e+000,,,,,,,,,,,,,,32,1,4.000000e+000,3.940582e-003,0.000000e+000,0,,0,
1524407920.760,,0.000000e+000,5.499774e+001,3.846975e-006,0.000000e+000,2,5.813572e-001,0.000000e+000,,,,,,,,,,,,,,32,1,4.000000e+000,3.940582e-003,0.000000e+000,0,,0,
1524407958.940,,0.000000e+000,5.499972e+001,3.860000e-006,0.000000e+000,2,6.042346e-001,0.000000e+000,,,,,,,,,,,,,,32,1,4.000000e+000,1.314926e-002,0.000000e+000,0,,0,
1524407996.910,,0.000000e+000,5.499905e+001,3.865413e-006,0.000000e+000,2,6.105682e-001,0.000000e+000,,,,,,,,,,,,,,32,1,4.000000e+000,3.948212e-003,0.000000e+000,0,,0,
1524408033.810,,0.000000e+000,5.499313e+001,3.832582e-006,0.000000e+000,2,5.969332e-001,0.000000e+000,,,,,,,,,,,,,,32,1,4.000000e+000,2.628326e-003,0.000000e+000,0,,0,
1524408071.760,,0.000000e+000,5.499380e+001,3.861152e-006,0.000000e+000,2,6.116315e-001,0.000000e+000,,,,,,,,,,,,,,32,1,4.000000e+000,1.446915e-002,0.000000e+000,0,,0,
1524408110.360,,0.000000e+000,5.500234e+001,3.850510e-006,0.000000e+000,2,6.163846e-001,0.000000e+000,,,,,,,,,,,,,,32,1,4.000000e+000,7.900238e-003,0.000000e+000,0,,0,
1524408148.070,,0.000000e+000,5.499511e+001,3.885174e-006,0.000000e+000,2,5.965176e-001,0.000000e+000,,,,,,,,,,,,,,32,1,4.000000e+000,6.568909e-003,0.000000e+000,0,,0,
1524408186.040,,0.000000e+000,5.500103e+001,3.784431e-006,0.000000e+000,2,6.025342e-001,0.000000e+000,,,,,,,,,,,,,,32,1,4.000000e+000,1.316071e-002,0.000000e+000,0,,0,
1524408223.520,,0.000000e+000,5.499445e+001,3.810954e-006,0.000000e+000,2,5.993960e-001,0.000000e+000,,,,,,,,,,,,,,32,1,4.000000e+000,7.881165e-003,0.000000e+000,0,,0,
1524408261.610,,0.000000e+000,5.500103e+001,3.862329e-006,0.000000e+000,2,5.964067e-001,0.000000e+000,,,,,,,,,,,,,,32,1,4.000000e+000,5.279541e-003,0.000000e+000,0,,0,
1524408300.021,,0.000000e+000,5.499840e+001,3.848469e-006,0.000000e+000,2,6.209301e-001,0.000000e+000,,,,,,,,,,,,,,32,1,4.000000e+000,5.260468e-003,0.000000e+000,0,,0,
1524408337.841,,0.000000e+000,5.499380e+001,3.834738e-006,0.000000e+000,2,5.955489e-001,0.000000e+000,,,,,,,,,,,,,,32,1,4.000000e+000,1.308441e-003,0.000000e+000,0,,0,
1524408376.071,,0.000000e+000,5.500037e+001,3.816416e-006,0.000000e+000,2,6.028996e-001,0.000000e+000,,,,,,,,,,,,,,32,1,4.000000e+000,3.959656e-003,0.000000e+000,0,,0,
1524408414.241,,0.000000e+000,5.499445e+001,3.814054e-006,0.000000e+000,2,6.255758e-001,0.000000e+000,,,,,,,,,,,,,,32,1,4.000000e+000,5.260468e-003,0.000000e+000,0,,0,
1524408452.081,,0.000000e+000,5.500103e+001,3.888802e-006,0.000000e+000,2,5.965579e-001,0.000000e+000,,,,,,,,,,,,,,32,1,4.000000e+000,1.052094e-002,0.000000e+000,0,,0,
1524408489.391,,0.000000e+000,5.499840e+001,3.840739e-006,0.000000e+000,2,6.123798e-001,0.000000e+000,,,,,,,,,,,,,,32,1,4.000000e+000,2.628326e-003,0.000000e+000,0,,0,
1524408527.011,,0.000000e+000,5.499445e+001,3.855404e-006,0.000000e+000,2,6.011903e-001,0.000000e+000,,,,,,,,,,,,,,32,1,4.000000e+000,5.260468e-003,0.000000e+000,0,,0,
1524408565.101,,0.000000e+000,5.499643e+001,3.819885e-006,0.000000e+000,2,6.259154e-001,0.000000e+000,,,,,,,,,,,,,,32,1,4.000000e+000,6.568909e-003,0.000000e+000,0,,0,
1524408603.151,,0.000000e+000,5.500432e+001,3.822417e-006,0.000000e+000,2,6.038259e-001,0.000000e+000,,,,,,,,,,,,,,32,1,4.000000e+000,3.940582e-003,0.000000e+000,0,,0,
1524408640.341,,0.000000e+000,5.500169e+001,3.812664e-006,0.000000e+000,2,5.996381e-001,0.000000e+000,,,,,,,,,,,,,,32,1,4.000000e+000,1.184082e-002,0.000000e+000,0,,0,
1524408678.191,,0.000000e+000,5.499380e+001,3.727798e-006,0.000000e+000,2,5.872939e-001,0.000000e+000,,,,,,,,,,,,,,32,1,4.000000e+000,6.572723e-003,0.000000e+000,0,,0,
1524408716.151,,0.000000e+000,5.499709e+001,3.744658e-006,0.000000e+000,2,6.042092e-001,0.000000e+000,,,,,,,,,,,,,,32,1,4.000000e+000,7.888794e-003,0.000000e+000,0,,0,
1524408754.351,,0.000000e+000,5.500235e+001,3.787467e-006,0.000000e+000,2,6.051480e-001,0.000000e+000,,,,,,,,,,,,,,32,1,4.000000e+000,0.000000e+000,0.000000e+000,0,,0,
1524408791.681,,0.000000e+000,5.499708e+001,3.747620e-006,0.000000e+000,2,5.959687e-001,0.000000e+000,,,,,,,,,,,,,,32,1,4.000000e+000,5.260468e-003,0.000000e+000,0,,0,
1524408829.531,,0.000000e+000,5.499708e+001,3.741108e-006,0.000000e+000,2,5.883758e-001,0.000000e+000,,,,,,,,,,,,,,32,1,4.000000e+000,2.620697e-003,0.000000e+000,0,,0,
1524408867.561,,0.000000e+000,5.500235e+001,3.785887e-006,0.000000e+000,2,6.023382e-001,0.000000e+000,,,,,,,,,,,,,,32,1,4.000000e+000,1.052856e-002,0.000000e+000,0,,0,
1524408905.211,,0.000000e+000,5.499380e+001,3.704610e-006,0.000000e+000,2,5.928405e-001,0.000000e+000,,,,,,,,,,,,,,32,1,4.000000e+000,1.182938e-002,0.000000e+000,0,,0,
1524408942.791,,0.000000e+000,5.499313e+001,3.763340e-006,0.000000e+000,2,6.030597e-001,0.000000e+000,,,,,,,,,,,,,,32,1,4.000000e+000,2.628326e-003,0.000000e+000,0,,0,
1524408980.351,,0.000000e+000,5.499905e+001,3.802748e-006,0.000000e+000,2,5.896596e-001,0.000000e+000,,,,,,,,,,,,,,32,1,4.000000e+000,1.319885e-003,0.000000e+000,0,,0,
1524409018.162,,0.000000e+000,5.499445e+001,3.801820e-006,0.000000e+000,2,6.104409e-001,0.000000e+000,,,,,,,,,,,,,,32,1,4.000000e+000,5.260468e-003,0.000000e+000,0,,0,
1524409057.082,,0.000000e+000,5.500037e+001,3.870937e-006,0.000000e+000,2,6.218377e-001,0.000000e+000,,,,,,,,,,,,,,32,1,4.000000e+000,6.587982e-003,0.000000e+000,0,,0,
1524409095.112,,0.000000e+000,5.499773e+001,3.729388e-006,0.000000e+000,2,5.989360e-001,0.000000e+000,,,,,,,,,,,,,,32,1,4.000000e+000,1.308441e-003,0.000000e+000,0,,0,
1524409133.082,,0.000000e+000,5.500169e+001,3.812115e-006,0.000000e+000,2,5.951254e-001,0.000000e+000,,,,,,,,,,,,,,32,1,4.000000e+000,9.208679e-003,0.000000e+000,0,,0,
1524409170.972,,0.000000e+000,5.499840e+001,3.822810e-006,0.000000e+000,2,6.017163e-001,0.000000e+000,,,,,,,,,,,,,,32,1,4.000000e+000,2.628326e-003,0.000000e+000,0,,0,
1524409208.142,,0.000000e+000,5.499971e+001,3.805714e-006,0.000000e+000,2,5.833255e-001,0.000000e+000,,,,,,,,,,,,,,32,1,4.000000e+000,0.000000e+000,0.000000e+000,0,,0,
1524409246.052,,0.000000e+000,5.499577e+001,3.839296e-006,0.000000e+000,2,6.188645e-001,0.000000e+000,,,,,,,,,,,,,,32,1,4.000000e+000,7.888794e-003,0.000000e+000,0,,0,
1524409284.452,,0.000000e+000,5.499445e+001,3.772586e-006,0.000000e+000,2,6.244137e-001,0.000000e+000,,,,,,,,,,,,,,32,1,4.000000e+000,2.628326e-003,0.000000e+000,0,,0,
1524409321.802,,0.000000e+000,5.499248e+001,3.813014e-006,0.000000e+000,2,5.809428e-001,0.000000e+000,,,,,,,,,,,,,,32,1,4.000000e+000,1.182938e-002,0.000000e+000,0,,0,
1524409359.612,,0.000000e+000,5.499380e+001,3.801665e-006,0.000000e+000,2,6.019319e-001,0.000000e+000,,,,,,,,,,,,,,32,1,4.000000e+000,6.572723e-003,0.000000e+000,0,,0,
1524409397.132,,0.000000e+000,5.499972e+001,3.798754e-006,0.000000e+000,2,5.892987e-001,0.000000e+000,,,,,,,,,,,,,,32,1,4.000000e+000,1.314926e-002,0.000000e+000,0,,0,
1524409434.502,,0.000000e+000,5.500761e+001,3.848947e-006,0.000000e+000,2,6.239601e-001,0.000000e+000,,,,,,,,,,,,,,32,1,4.000000e+000,7.881165e-003,0.000000e+000,0,,0,
1524409473.282,,0.000000e+000,5.500103e+001,3.760621e-006,0.000000e+000,2,6.069024e-001,0.000000e+000,,,,,,,,,,,,,,32,1,4.000000e+000,2.639771e-003,0.000000e+000,0,,0,
1524409510.742,,0.000000e+000,5.500103e+001,3.784561e-006,0.000000e+000,2,5.921533e-001,0.000000e+000,,,,,,,,,,,,,,32,1,4.000000e+000,1.316071e-002,0.000000e+000,0,,0,
1524409548.272,,0.000000e+000,5.499774e+001,3.802622e-006,0.000000e+000,2,6.174740e-001,0.000000e+000,,,,,,,,,,,,,,32,1,4.000000e+000,3.940582e-003,0.000000e+000,0,,0,
1524409586.412,,0.000000e+000,5.499840e+001,3.809816e-006,0.000000e+000,2,6.006065e-001,0.000000e+000,,,,,,,,,,,,,,32,1,4.000000e+000,2.628326e-003,0.000000e+000,0,,0,
1524409624.312,,0.000000e+000,5.499840e+001,3.831104e-006,0.000000e+000,2,5.902223e-001,0.000000e+000,,,,,,,,,,,,,,32,1,4.000000e+000,7.900238e-003,0.000000e+000,0,,0,
1524409662.062,,0.000000e+000,5.499841e+001,3.853435e-006,0.000000e+000,2,6.176078e-001,0.000000e+000,,,,,,,,,,,,,,32,1,4.000000e+000,1.052856e-002,0.000000e+000,0,,0,
1524409699.513,,0.000000e+000,5.500235e+001,3.852576e-006,0.000000e+000,2,5.838416e-001,0.000000e+000,,,,,,,,,,,,,,32,1,4.000000e+000,0.000000e+000,0.000000e+000,0,,0,
1524409737.673,,0.000000e+000,5.499840e+001,3.815420e-006,0.000000e+000,2,6.104822e-001,0.000000e+000,,,,,,,,,,,,,,32,1,4.000000e+000,1.578140e-002,0.000000e+000,0,,0,
1524409774.803,,0.000000e+000,5.499774e+001,3.755269e-006,0.000000e+000,2,6.104523e-001,0.000000e+000,,,,,,,,,,,,,,32,1,4.000000e+000,6.580353e-003,0.000000e+000,0,,0,
1524409812.903,,0.000000e+000,5.499840e+001,3.788703e-006,0.000000e+000,2,5.912313e-001,0.000000e+000,,,,,,,,,,,,,,32,1,4.000000e+000,2.628326e-003,0.000000e+000,0,,0,
1524409850.973,,0.000000e+000,5.499972e+001,3.840385e-006,0.000000e+000,2,6.174264e-001,0.000000e+000,,,,,,,,,,,,,,32,1,4.000000e+000,1.578903e-002,0.000000e+000,0,,0,
1524409888.583,,0.000000e+000,5.499182e+001,3.903502e-006,0.000000e+000,2,5.999507e-001,0.000000e+000,,,,,,,,,,,,,,32,1,4.000000e+000,1.052094e-002,0.000000e+000,0,,0,
1524409926.623,,0.000000e+000,5.499643e+001,3.835310e-006,0.000000e+000,2,6.109515e-001,0.000000e+000,,,,,,,,,,,,,,32,1,4.000000e+000,1.312256e-003,0.000000e+000,0,,0,
1524409964.273,,0.000000e+000,5.499775e+001,3.831960e-006,0.000000e+000,2,6.035045e-001,0.000000e+000,,,,,,,,,,,,,,32,1,4.000000e+000,1.184845e-002,0.000000e+000,0,,0,
1524410002.303,,0.000000e+000,5.499905e+001,3.831802e-006,0.000000e+000,2,6.152507e-001,0.000000e+000,,,,,,,,,,,,,,32,1,4.000000e+000,1.319885e-003,0.000000e+000,0,,0,
1524410039.923,,0.000000e+000,5.499905e+001,3.844623e-006,0.000000e+000,2,6.018121e-001,0.000000e+000,,,,,,,,,,,,,,32,1,4.000000e+000,3.948212e-003,0.000000e+000,0,,0,
1524410077.973,,0.000000e+000,5.500037e+001,3.834914e-006,0.000000e+000,2,6.097945e-001,0.000000e+000,,,,,,,,,,,,,,32,1,4.000000e+000,1.446915e-002,0.000000e+000,0,,0,
1524410115.593,,0.000000e+000,5.499906e+001,3.828261e-006,0.000000e+000,2,5.943859e-001,0.000000e+000,,,,,,,,,,,,,,32,1,4.000000e+000,6.580353e-003,0.000000e+000,0,,0,
1524410153.643,,0.000000e+000,5.499445e+001,3.839677e-006,0.000000e+000,2,6.139751e-001,0.000000e+000,,,,,,,,,,,,,,32,1,4.000000e+000,2.628326e-003,0.000000e+000,0,,0,
1524410190.803,,0.000000e+000,5.500235e+001,3.851928e-006,0.000000e+000,2,5.988311e-001,0.000000e+000,,,,,,,,,,,,,,32,1,4.000000e+000,1.052856e-002,0.000000e+000,0,,0,
1524410228.783,,0.000000e+000,5.500497e+001,3.840049e-006,0.000000e+000,2,6.194007e-001,0.000000e+000,,,,,,,,,,,,,,32,1,4.000000e+000,1.578903e-002,0.000000e+000,0,,0,
1524410266.413,,0.000000e+000,5.500168e+001,3.816898e-006,0.000000e+000,2,5.949277e-001,0.000000e+000,,,,,,,,,,,,,,32,1,4.000000e+000,6.580353e-003,0.000000e+000,0,,0,
1524410304.373,,0.000000e+000,5.499642e+001,3.826597e-006,0.000000e+000,2,6.255198e-001,0.000000e+000,,,,,,,,,,,,,,32,1,4.000000e+000,3.940582e-003,0.000000e+000,0,,0,
1524410342.233,,0.000000e+000,5.498920e+001,3.705387e-006,0.000000e+000,2,5.885438e-001,0.000000e+000,,,,,,,,,,,,,,32,1,4.000000e+000,2.628326e-003,0.000000e+000,0,,0,
1524410380.163,,0.000000e+000,5.499774e+001,3.831801e-006,0.000000e+000,2,6.106009e-001,0.000000e+000,,,,,,,,,,,,,,32,1,4.000000e+000,6.580353e-003,0.000000e+000,0,,0,
1524410417.514,,0.000000e+000,5.499248e+001,3.796318e-006,0.000000e+000,2,5.895685e-001,0.000000e+000,,,,,,,,,,,,,,32,1,4.000000e+000,3.940582e-003,0.000000e+000,0,,0,
1524410455.284,,0.000000e+000,5.499445e+001,3.832206e-006,0.000000e+000,2,6.148243e-001,0.000000e+000,,,,,,,,,,,,,,32,1,4.000000e+000,1.052094e-002,0.000000e+000,0,,0,
1524410492.984,,0.000000e+000,5.498985e+001,3.810623e-006,0.000000e+000,2,6.043902e-001,0.000000e+000,,,,,,,,,,,,,,32,1,4.000000e+000,6.580353e-003,0.000000e+000,0,,0,
1524410530.754,,0.000000e+000,5.499840e+001,3.844385e-006,0.000000e+000,2,6.069790e-001,0.000000e+000,,,,,,,,,,,,,,32,1,4.000000e+000,5.260468e-003,0.000000e+000,0,,0,
1524410568.804,,0.000000e+000,5.499445e+001,3.847864e-006,0.000000e+000,2,6.096196e-001,0.000000e+000,,,,,,,,,,,,,,32,1,4.000000e+000,5.260468e-003,0.000000e+000,0,,0,
1524410606.634,,0.000000e+000,5.500629e+001,3.788788e-006,0.000000e+000,2,5.887020e-001,0.000000e+000,,,,,,,,,,,,,,32,1,4.000000e+000,5.249023e-003,0.000000e+000,0,,0,
1524410644.604,,0.000000e+000,5.499380e+001,3.821530e-006,0.000000e+000,2,6.160790e-001,0.000000e+000,,,,,,,,,,,,,,32,1,4.000000e+000,3.948212e-003,0.000000e+000,0,,0,
1524410682.964,,0.000000e+000,5.499905e+001,3.769356e-006,0.000000e+000,2,5.945790e-001,0.000000e+000,,,,,,,,,,,,,,32,1,4.000000e+000,1.319885e-003,0.000000e+000,0,,0,
1524410720.304,,0.000000e+000,5.500037e+001,3.829712e-006,0.000000e+000,2,6.085008e-001,0.000000e+000,,,,,,,,,,,,,,32,1,4.000000e+000,1.319885e-003,0.000000e+000,0,,0,
1524410758.124,,0.000000e+000,5.500103e+001,3.755060e-006,0.000000e+000,2,5.985845e-001,0.000000e+000,,,,,,,,,,,,,,32,1,4.000000e+000,0.000000e+000,0.000000e+000,0,,0,
1524410795.414,,0.000000e+000,5.499773e+001,3.801673e-006,0.000000e+000,2,6.083105e-001,0.000000e+000,,,,,,,,,,,,,,32,1,4.000000e+000,1.308441e-003,0.000000e+000,0,,0,
1524410833.184,,0.000000e+000,5.499840e+001,3.759472e-006,0.000000e+000,2,6.133035e-001,0.000000e+000,,,,,,,,,,,,,,32,1,4.000000e+000,2.628326e-003,0.000000e+000,0,,0,
1524410896.034,,0.000000e+000,5.499839e+001,3.828302e-006,0.000000e+000,2,5.777882e-001,0.000000e+000,,,,,,,,,,,,,,32,1,4.000000e+000,0.000000e+000,0.000000e+000,0,,0,
1524410933.924,,0.000000e+000,5.499840e+001,3.770387e-006,0.000000e+000,2,6.103291e-001,0.000000e+000,,,,,,,,,,,,,,32,1,4.000000e+000,2.628326e-003,0.000000e+000,0,,0,
1524410971.104,,0.000000e+000,5.499774e+001,3.808142e-006,0.000000e+000,2,6.053479e-001,0.000000e+000,,,,,,,,,,,,,,32,1,4.000000e+000,6.580353e-003,0.000000e+000,0,,0,
1524411009.074,,0.000000e+000,5.499774e+001,3.832894e-006,0.000000e+000,2,6.156565e-001,0.000000e+000,,,,,,,,,,,,,,32,1,4.000000e+000,1.446152e-002,0.000000e+000,0,,0,
1524411047.274,,0.000000e+000,5.500103e+001,3.784560e-006,0.000000e+000,2,6.058918e-001,0.000000e+000,,,,,,,,,,,,,,32,1,4.000000e+000,2.639771e-003,0.000000e+000,0,,0,
1524411085.354,,0.000000e+000,5.499971e+001,3.826523e-006,0.000000e+000,2,5.906454e-001,0.000000e+000,,,,,,,,,,,,,,32,1,4.000000e+000,0.000000e+000,0.000000e+000,0,,0,
1524411123.204,,0.000000e+000,5.499511e+001,3.766156e-006,0.000000e+000,2,6.069991e-001,0.000000e+000,,,,,,,,,,,,,,32,1,4.000000e+000,3.940582e-003,0.000000e+000,0,,0,
1524411186.755,,0.000000e+000,5.500234e+001,3.723061e-006,0.000000e+000,2,6.028368e-001,0.000000e+000,,,,,,,,,,,,,,32,1,4.000000e+000,1.314926e-002,0.000000e+000,0,,0,
1524411199.125,,0.000000e+000,5.499248e+001,3.797112e-006,0.000000e+000,2,5.957497e-001,0.000000e+000,,,,,,,,,,,,,,32,1,4.000000e+000,3.940582e-003,0.000000e+000,0,,0,