File: Experimental Raw Data/MFn1 VRM/Iterative Regression/MFn1_VRMac_37K_1500s_VRMde_35K.dc.dat
[Header]
TITLE,MPMS DC Measurement
BYAPP,MPMS Measurement,2.1,Summary
FILEOPENTIME, 1524211150.974000 4/20/2018, 1:59:10 AM

INFO, APPNAME, MPMS MultiVu Application, Revision 1.61,  Build 082

INFO, NAME, MFn1
INFO, WEIGHT, 1.000
INFO, AREA, 1.000
INFO, LENGTH, 1.000
INFO, SHAPE, 0
INFO, COMMENT,
INFO, SEQUENCE FILE: VRMac_37K_1500s_VRMde_35K.seq


INFO, BACKGROUND DATA FILE:, None


STARTUPAXIS,X,4,LINEAR,AUTO,0.000000,0.000000
STARTUPAXIS,Y1,5,LINEAR,AUTO,0.000000,0.000000


STARTUPGROUP,Longitudinal
FIELDGROUP,Longitudinal,1,2,3,4,5,6,7,8,9,15,16,17,18,27,28
FIELDGROUP,Transverse,1,2,3,4,10,11,12,13,14,19,20,21,22,27,28

PLOT_APPEARANCE,ALL,HORZ_GRID_ON,VERT_GRID_ON,MARKERS_AND_LINES

[Data]
Time,Comment,Field (Oe),Temperature (K),Long Moment (emu),Long Scan Std Dev,Long Algorithm,Long Reg Fit,Long Percent Error (%),Trans Moment (emu),Trans Scan Std Dev,Trans Algorithm,Trans Reg Fit,Trans Percent Error (%),Long Moment [w/o ABS] (emu),Long Scan Std Dev [w/o ABS],Long Reg Fit [w/o ABS],Long Percent Error [w/o ABS] (%),Trans Moment [w/o ABS] (emu),Trans Scan Std Dev [w/o ABS],Trans Reg Fit [w/o ABS],Trans Percent Error [w/o ABS] (%),Points per Scan,Scans per Measurement,Scan Length (cm),Delta Temp (K),Rot Position (deg),Error,EC Comp. Running,Using ABS,
1524211150.971,,0.000000e+000,3.694840e+001,-1.914952e-005,0.000000e+000,3,9.596089e-001,0.000000e+000,,,,,,,,,,,,,,32,1,4.000000e+000,1.068192e-001,0.000000e+000,0,,0,
1524211191.362,,0.000000e+000,3.445115e+001,-1.599856e-005,0.000000e+000,3,9.507050e-001,0.000000e+000,,,,,,,,,,,,,,32,1,4.000000e+000,4.752388e-001,0.000000e+000,0,,0,
1524211229.315,,0.000000e+000,3.495693e+001,-1.534733e-005,0.000000e+000,3,9.422345e-001,0.000000e+000,,,,,,,,,,,,,,32,1,4.000000e+000,3.667068e-002,0.000000e+000,0,,0,
1524211267.588,,0.000000e+000,3.499989e+001,-1.463153e-005,0.000000e+000,3,9.399042e-001,0.000000e+000,,,,,,,,,,,,,,32,1,4.000000e+000,2.342224e-003,0.000000e+000,0,,0,
1524211305.024,,0.000000e+000,3.499872e+001,-1.406323e-005,0.000000e+000,3,9.347335e-001,0.000000e+000,,,,,,,,,,,,,,32,1,4.000000e+000,1.560211e-003,0.000000e+000,0,,0,
1524211342.662,,0.000000e+000,3.499872e+001,-1.351438e-005,0.000000e+000,3,9.338165e-001,0.000000e+000,,,,,,,,,,,,,,32,1,4.000000e+000,1.560211e-003,0.000000e+000,0,,0,
1524211380.797,,0.000000e+000,3.499950e+001,-1.306922e-005,0.000000e+000,3,9.294775e-001,0.000000e+000,,,,,,,,,,,,,,32,1,4.000000e+000,0.000000e+000,0.000000e+000,0,,0,
1524211419.380,,0.000000e+000,3.499871e+001,-1.269729e-005,0.000000e+000,3,9.275239e-001,0.000000e+000,,,,,,,,,,,,,,32,1,4.000000e+000,3.128052e-003,0.000000e+000,0,,0,
1524211457.518,,0.000000e+000,3.499950e+001,-1.231944e-005,0.000000e+000,3,9.269674e-001,0.000000e+000,,,,,,,,,,,,,,32,1,4.000000e+000,1.560211e-003,0.000000e+000,0,,0,
1524211495.709,,0.000000e+000,3.499989e+001,-1.196793e-005,0.000000e+000,3,9.230799e-001,0.000000e+000,,,,,,,,,,,,,,32,1,4.000000e+000,2.342224e-003,0.000000e+000,0,,0,
1524211534.609,,0.000000e+000,3.499833e+001,-1.167141e-005,0.000000e+000,3,9.226432e-001,0.000000e+000,,,,,,,,,,,,,,32,1,4.000000e+000,7.781982e-004,0.000000e+000,0,,0,
1524211571.835,,0.000000e+000,3.499950e+001,-1.133689e-005,0.000000e+000,3,9.195091e-001,0.000000e+000,,,,,,,,,,,,,,32,1,4.000000e+000,1.560211e-003,0.000000e+000,0,,0,
1524211610.003,,0.000000e+000,3.499950e+001,-1.108228e-005,0.000000e+000,3,9.170868e-001,0.000000e+000,,,,,,,,,,,,,,32,1,4.000000e+000,1.560211e-003,0.000000e+000,0,,0,
1524211647.946,,0.000000e+000,3.499833e+001,-1.085306e-005,0.000000e+000,3,9.156719e-001,0.000000e+000,,,,,,,,,,,,,,32,1,4.000000e+000,2.349854e-003,0.000000e+000,0,,0,
1524211686.102,,0.000000e+000,3.499911e+001,-1.059328e-005,0.000000e+000,3,9.147532e-001,0.000000e+000,,,,,,,,,,,,,,32,1,4.000000e+000,7.820129e-004,0.000000e+000,0,,0,
1524211723.745,,0.000000e+000,3.499950e+001,-1.036972e-005,0.000000e+000,3,9.091908e-001,0.000000e+000,,,,,,,,,,,,,,32,1,4.000000e+000,1.560211e-003,0.000000e+000,0,,0,
1524211761.893,,0.000000e+000,3.499794e+001,-1.010140e-005,0.000000e+000,3,9.075202e-001,0.000000e+000,,,,,,,,,,,,,,32,1,4.000000e+000,0.000000e+000,0.000000e+000,0,,0,
1524211799.908,,0.000000e+000,3.499754e+001,-9.930855e-006,0.000000e+000,3,9.057207e-001,0.000000e+000,,,,,,,,,,,,,,32,1,4.000000e+000,2.349854e-003,0.000000e+000,0,,0,
1524211838.159,,0.000000e+000,3.499872e+001,-9.730645e-006,0.000000e+000,3,9.051350e-001,0.000000e+000,,,,,,,,,,,,,,32,1,4.000000e+000,0.000000e+000,0.000000e+000,0,,0,
1524211876.357,,0.000000e+000,3.499872e+001,-9.562764e-006,0.000000e+000,3,9.047517e-001,0.000000e+000,,,,,,,,,,,,,,32,1,4.000000e+000,1.560211e-003,0.000000e+000,0,,0,
1524211914.670,,0.000000e+000,3.499872e+001,-9.375812e-006,0.000000e+000,3,9.024562e-001,0.000000e+000,,,,,,,,,,,,,,32,1,4.000000e+000,1.560211e-003,0.000000e+000,0,,0,
1524211952.668,,0.000000e+000,3.499754e+001,-9.208070e-006,0.000000e+000,3,9.008701e-001,0.000000e+000,,,,,,,,,,,,,,32,1,4.000000e+000,7.896423e-004,0.000000e+000,0,,0,
1524211990.819,,0.000000e+000,3.499950e+001,-9.030086e-006,0.000000e+000,3,8.987288e-001,0.000000e+000,,,,,,,,,,,,,,32,1,4.000000e+000,1.560211e-003,0.000000e+000,0,,0,
1524212029.449,,0.000000e+000,3.499637e+001,-8.890081e-006,0.000000e+000,3,8.962811e-001,0.000000e+000,,,,,,,,,,,,,,32,1,4.000000e+000,0.000000e+000,0.000000e+000,0,,0,
1524212067.120,,0.000000e+000,3.499950e+001,-8.770964e-006,0.000000e+000,3,8.995814e-001,0.000000e+000,,,,,,,,,,,,,,32,1,4.000000e+000,0.000000e+000,0.000000e+000,0,,0,
1524212104.618,,0.000000e+000,3.499793e+001,-8.616674e-006,0.000000e+000,3,8.922885e-001,0.000000e+000,,,,,,,,,,,,,,32,1,4.000000e+000,1.567841e-003,0.000000e+000,0,,0,
1524212142.301,,0.000000e+000,3.499872e+001,-8.481269e-006,0.000000e+000,3,8.922387e-001,0.000000e+000,,,,,,,,,,,,,,32,1,4.000000e+000,0.000000e+000,0.000000e+000,0,,0,
1524212180.489,,0.000000e+000,3.499833e+001,-8.327185e-006,0.000000e+000,3,8.934154e-001,0.000000e+000,,,,,,,,,,,,,,32,1,4.000000e+000,7.781982e-004,0.000000e+000,0,,0,
1524212218.392,,0.000000e+000,3.499911e+001,-8.216341e-006,0.000000e+000,3,8.880523e-001,0.000000e+000,,,,,,,,,,,,,,32,1,4.000000e+000,7.820129e-004,0.000000e+000,0,,0,
1524212256.293,,0.000000e+000,3.499911e+001,-8.074962e-006,0.000000e+000,3,8.854834e-001,0.000000e+000,,,,,,,,,,,,,,32,1,4.000000e+000,7.820129e-004,0.000000e+000,0,,0,
1524212294.316,,0.000000e+000,3.499989e+001,-7.990468e-006,0.000000e+000,3,8.879035e-001,0.000000e+000,,,,,,,,,,,,,,32,1,4.000000e+000,7.781982e-004,0.000000e+000,0,,0,
1524212332.451,,0.000000e+000,3.499638e+001,-7.867610e-006,0.000000e+000,3,8.840684e-001,0.000000e+000,,,,,,,,,,,,,,32,1,4.000000e+000,4.688263e-003,0.000000e+000,0,,0,
1524212370.612,,0.000000e+000,3.499911e+001,-7.744306e-006,0.000000e+000,3,8.829712e-001,0.000000e+000,,,,,,,,,,,,,,32,1,4.000000e+000,7.820129e-004,0.000000e+000,0,,0,
1524212408.605,,0.000000e+000,3.499833e+001,-7.651252e-006,0.000000e+000,3,8.792270e-001,0.000000e+000,,,,,,,,,,,,,,32,1,4.000000e+000,2.349854e-003,0.000000e+000,0,,0,
1524212446.145,,0.000000e+000,3.500028e+001,-7.545538e-006,0.000000e+000,3,8.775210e-001,0.000000e+000,,,,,,,,,,,,,,32,1,4.000000e+000,3.120422e-003,0.000000e+000,0,,0,
1524212483.816,,0.000000e+000,3.499833e+001,-7.458545e-006,0.000000e+000,3,8.812146e-001,0.000000e+000,,,,,,,,,,,,,,32,1,4.000000e+000,7.781982e-004,0.000000e+000,0,,0,
1524212521.169,,0.000000e+000,3.499793e+001,-7.354644e-006,0.000000e+000,3,8.738859e-001,0.000000e+000,,,,,,,,,,,,,,32,1,4.000000e+000,3.131866e-003,0.000000e+000,0,,0,
1524212559.317,,0.000000e+000,3.499911e+001,-7.275540e-006,0.000000e+000,3,8.756959e-001,0.000000e+000,,,,,,,,,,,,,,32,1,4.000000e+000,7.820129e-004,0.000000e+000,0,,0,
1524212597.463,,0.000000e+000,3.499872e+001,-7.153442e-006,0.000000e+000,3,8.747851e-001,0.000000e+000,,,,,,,,,,,,,,32,1,4.000000e+000,1.560211e-003,0.000000e+000,0,,0,
1524212636.281,,0.000000e+000,3.499950e+001,-7.058822e-006,0.000000e+000,3,8.693643e-001,0.000000e+000,,,,,,,,,,,,,,32,1,4.000000e+000,0.000000e+000,0.000000e+000,0,,0,
1524212674.486,,0.000000e+000,3.499911e+001,-6.996966e-006,0.000000e+000,3,8.758470e-001,0.000000e+000,,,,,,,,,,,,,,32,1,4.000000e+000,2.338409e-003,0.000000e+000,0,,0,
1524212712.647,,0.000000e+000,3.499872e+001,-6.914605e-006,0.000000e+000,3,8.700894e-001,0.000000e+000,,,,,,,,,,,,,,32,1,4.000000e+000,1.560211e-003,0.000000e+000,0,,0,
1524212750.352,,0.000000e+000,3.499833e+001,-6.860690e-006,0.000000e+000,3,8.664016e-001,0.000000e+000,,,,,,,,,,,,,,32,1,4.000000e+000,7.781982e-004,0.000000e+000,0,,0,
1524212788.955,,0.000000e+000,3.499833e+001,-6.699035e-006,0.000000e+000,3,8.629891e-001,0.000000e+000,,,,,,,,,,,,,,32,1,4.000000e+000,7.781982e-004,0.000000e+000,0,,0,
1524212827.096,,0.000000e+000,3.499872e+001,-6.647056e-006,0.000000e+000,3,8.651902e-001,0.000000e+000,,,,,,,,,,,,,,32,1,4.000000e+000,0.000000e+000,0.000000e+000,0,,0,
1524212865.251,,0.000000e+000,3.499911e+001,-6.561273e-006,0.000000e+000,3,8.634610e-001,0.000000e+000,,,,,,,,,,,,,,32,1,4.000000e+000,7.820129e-004,0.000000e+000,0,,0,
1524212902.845,,0.000000e+000,3.499872e+001,-6.544639e-006,0.000000e+000,3,8.652046e-001,0.000000e+000,,,,,,,,,,,,,,32,1,4.000000e+000,0.000000e+000,0.000000e+000,0,,0,
1524212940.995,,0.000000e+000,3.499950e+001,-6.439074e-006,0.000000e+000,3,8.583057e-001,0.000000e+000,,,,,,,,,,,,,,32,1,4.000000e+000,0.000000e+000,0.000000e+000,0,,0,
1524212979.151,,0.000000e+000,3.499911e+001,-6.341841e-006,0.000000e+000,3,8.541206e-001,0.000000e+000,,,,,,,,,,,,,,32,1,4.000000e+000,7.820129e-004,0.000000e+000,0,,0,
1524213017.334,,0.000000e+000,3.499833e+001,-6.283989e-006,0.000000e+000,3,8.557804e-001,0.000000e+000,,,,,,,,,,,,,,32,1,4.000000e+000,7.781982e-004,0.000000e+000,0,,0,
1524213055.022,,0.000000e+000,3.499950e+001,-6.219839e-006,0.000000e+000,3,8.546937e-001,0.000000e+000,,,,,,,,,,,,,,32,1,4.000000e+000,1.560211e-003,0.000000e+000,0,,0,
1524213093.647,,0.000000e+000,3.499950e+001,-6.130412e-006,0.000000e+000,3,8.538507e-001,0.000000e+000,,,,,,,,,,,,,,32,1,4.000000e+000,1.560211e-003,0.000000e+000,0,,0,
1524213131.328,,0.000000e+000,3.499754e+001,-6.143095e-006,0.000000e+000,3,8.533231e-001,0.000000e+000,,,,,,,,,,,,,,32,1,4.000000e+000,7.896423e-004,0.000000e+000,0,,0,
1524213168.961,,0.000000e+000,3.500028e+001,-6.005809e-006,0.000000e+000,3,8.496537e-001,0.000000e+000,,,,,,,,,,,,,,32,1,4.000000e+000,1.560211e-003,0.000000e+000,0,,0,
1524213206.814,,0.000000e+000,3.499911e+001,-5.939931e-006,0.000000e+000,3,8.469685e-001,0.000000e+000,,,,,,,,,,,,,,32,1,4.000000e+000,7.820129e-004,0.000000e+000,0,,0,
1524213244.930,,0.000000e+000,3.499911e+001,-5.894560e-006,0.000000e+000,3,8.453571e-001,0.000000e+000,,,,,,,,,,,,,,32,1,4.000000e+000,7.820129e-004,0.000000e+000,0,,0,
1524213282.585,,0.000000e+000,3.499872e+001,-5.813663e-006,0.000000e+000,3,8.417806e-001,0.000000e+000,,,,,,,,,,,,,,32,1,4.000000e+000,0.000000e+000,0.000000e+000,0,,0,
1524213320.911,,0.000000e+000,3.499911e+001,-5.750765e-006,0.000000e+000,3,8.367667e-001,0.000000e+000,,,,,,,,,,,,,,32,1,4.000000e+000,7.820129e-004,0.000000e+000,0,,0,
1524213359.941,,0.000000e+000,3.499833e+001,-5.687844e-006,0.000000e+000,3,8.435838e-001,0.000000e+000,,,,,,,,,,,,,,32,1,4.000000e+000,2.349854e-003,0.000000e+000,0,,0,
1524213397.064,,0.000000e+000,3.499950e+001,-5.656475e-006,0.000000e+000,3,8.482267e-001,0.000000e+000,,,,,,,,,,,,,,32,1,4.000000e+000,3.120422e-003,0.000000e+000,0,,0,
1524213434.932,,0.000000e+000,3.499911e+001,-5.598624e-006,0.000000e+000,3,8.362278e-001,0.000000e+000,,,,,,,,,,,,,,32,1,4.000000e+000,7.820129e-004,0.000000e+000,0,,0,
1524213473.065,,0.000000e+000,3.499911e+001,-5.554003e-006,0.000000e+000,3,8.366017e-001,0.000000e+000,,,,,,,,,,,,,,32,1,4.000000e+000,7.820129e-004,0.000000e+000,0,,0,
1524213511.246,,0.000000e+000,3.499754e+001,-5.501348e-006,0.000000e+000,3,8.343495e-001,0.000000e+000,,,,,,,,,,,,,,32,1,4.000000e+000,7.896423e-004,0.000000e+000,0,,0,
1524213549.374,,0.000000e+000,3.500028e+001,-5.428258e-006,0.000000e+000,3,8.297092e-001,0.000000e+000,,,,,,,,,,,,,,32,1,4.000000e+000,0.000000e+000,0.000000e+000,0,,0,
1524213587.822,,0.000000e+000,3.499833e+001,-5.395821e-006,0.000000e+000,3,8.333742e-001,0.000000e+000,,,,,,,,,,,,,,32,1,4.000000e+000,2.349854e-003,0.000000e+000,0,,0,
1524213625.938,,0.000000e+000,3.499911e+001,-5.337844e-006,0.000000e+000,3,8.318839e-001,0.000000e+000,,,,,,,,,,,,,,32,1,4.000000e+000,7.820129e-004,0.000000e+000,0,,0,
1524213663.238,,0.000000e+000,3.499950e+001,-5.264887e-006,0.000000e+000,3,8.239086e-001,0.000000e+000,,,,,,,,,,,,,,32,1,4.000000e+000,0.000000e+000,0.000000e+000,0,,0,
1524213700.984,,0.000000e+000,3.499950e+001,-5.226362e-006,0.000000e+000,3,8.261653e-001,0.000000e+000,,,,,,,,,,,,,,32,1,4.000000e+000,1.560211e-003,0.000000e+000,0,,0,
1524213739.149,,0.000000e+000,3.499833e+001,-5.182607e-006,0.000000e+000,3,8.221211e-001,0.000000e+000,,,,,,,,,,,,,,32,1,4.000000e+000,7.781982e-004,0.000000e+000,0,,0,
1524213777.315,,0.000000e+000,3.499872e+001,-5.141832e-006,0.000000e+000,3,8.240410e-001,0.000000e+000,,,,,,,,,,,,,,32,1,4.000000e+000,1.560211e-003,0.000000e+000,0,,0,
1524213815.463,,0.000000e+000,3.499911e+001,-5.062093e-006,0.000000e+000,3,8.223939e-001,0.000000e+000,,,,,,,,,,,,,,32,1,4.000000e+000,7.820129e-004,0.000000e+000,0,,0,
1524213853.564,,0.000000e+000,3.499833e+001,-5.013150e-006,0.000000e+000,3,8.159565e-001,0.000000e+000,,,,,,,,,,,,,,32,1,4.000000e+000,7.781982e-004,0.000000e+000,0,,0,
1524213891.202,,0.000000e+000,3.499911e+001,-5.019401e-006,0.000000e+000,3,8.213392e-001,0.000000e+000,,,,,,,,,,,,,,32,1,4.000000e+000,7.820129e-004,0.000000e+000,0,,0,
1524213928.105,,0.000000e+000,3.499833e+001,-4.938952e-006,0.000000e+000,3,8.112518e-001,0.000000e+000,,,,,,,,,,,,,,32,1,4.000000e+000,7.781982e-004,0.000000e+000,0,,0,
1524213966.238,,0.000000e+000,3.499950e+001,-4.913071e-006,0.000000e+000,3,8.184904e-001,0.000000e+000,,,,,,,,,,,,,,32,1,4.000000e+000,0.000000e+000,0.000000e+000,0,,0,
1524214004.311,,0.000000e+000,3.499911e+001,-4.853535e-006,0.000000e+000,3,8.145634e-001,0.000000e+000,,,,,,,,,,,,,,32,1,4.000000e+000,7.820129e-004,0.000000e+000,0,,0,
1524214042.519,,0.000000e+000,3.499911e+001,-4.812990e-006,0.000000e+000,3,8.133239e-001,0.000000e+000,,,,,,,,,,,,,,32,1,4.000000e+000,7.820129e-004,0.000000e+000,0,,0,
1524214080.674,,0.000000e+000,3.499872e+001,-4.780007e-006,0.000000e+000,3,8.114474e-001,0.000000e+000,,,,,,,,,,,,,,32,1,4.000000e+000,0.000000e+000,0.000000e+000,0,,0,
1524214118.745,,0.000000e+000,3.499911e+001,-4.736895e-006,0.000000e+000,3,8.118554e-001,0.000000e+000,,,,,,,,,,,,,,32,1,4.000000e+000,7.820129e-004,0.000000e+000,0,,0,
1524214156.886,,0.000000e+000,3.499911e+001,-4.692828e-006,0.000000e+000,3,8.032380e-001,0.000000e+000,,,,,,,,,,,,,,32,1,4.000000e+000,7.820129e-004,0.000000e+000,0,,0,
1524214195.101,,0.000000e+000,3.499872e+001,-4.670111e-006,0.000000e+000,3,8.081106e-001,0.000000e+000,,,,,,,,,,,,,,32,1,4.000000e+000,1.560211e-003,0.000000e+000,0,,0,
1524214233.517,,0.000000e+000,3.499950e+001,-4.592941e-006,0.000000e+000,3,8.085380e-001,0.000000e+000,,,,,,,,,,,,,,32,1,4.000000e+000,0.000000e+000,0.000000e+000,0,,0,
1524214271.550,,0.000000e+000,3.499872e+001,-4.562349e-006,0.000000e+000,3,7.997046e-001,0.000000e+000,,,,,,,,,,,,,,32,1,4.000000e+000,0.000000e+000,0.000000e+000,0,,0,
1524214309.578,,0.000000e+000,3.499950e+001,-4.526743e-006,0.000000e+000,3,7.961180e-001,0.000000e+000,,,,,,,,,,,,,,32,1,4.000000e+000,1.560211e-003,0.000000e+000,0,,0,
1524214348.066,,0.000000e+000,3.499793e+001,-4.501252e-006,0.000000e+000,3,7.953122e-001,0.000000e+000,,,,,,,,,,,,,,32,1,4.000000e+000,3.131866e-003,0.000000e+000,0,,0,
1524214386.111,,0.000000e+000,3.499911e+001,-4.462252e-006,0.000000e+000,3,7.950743e-001,0.000000e+000,,,,,,,,,,,,,,32,1,4.000000e+000,7.820129e-004,0.000000e+000,0,,0,
1524214423.782,,0.000000e+000,3.499989e+001,-4.429794e-006,0.000000e+000,3,7.984717e-001,0.000000e+000,,,,,,,,,,,,,,32,1,4.000000e+000,7.781982e-004,0.000000e+000,0,,0,
1524214461.900,,0.000000e+000,3.499911e+001,-4.379730e-006,0.000000e+000,3,7.899821e-001,0.000000e+000,,,,,,,,,,,,,,32,1,4.000000e+000,2.338409e-003,0.000000e+000,0,,0,
1524214500.146,,0.000000e+000,3.499793e+001,-4.369042e-006,0.000000e+000,3,7.975769e-001,0.000000e+000,,,,,,,,,,,,,,32,1,4.000000e+000,1.567841e-003,0.000000e+000,0,,0,
1524214538.231,,0.000000e+000,3.499989e+001,-4.325260e-006,0.000000e+000,3,7.870528e-001,0.000000e+000,,,,,,,,,,,,,,32,1,4.000000e+000,2.342224e-003,0.000000e+000,0,,0,
1524214575.967,,0.000000e+000,3.499754e+001,-4.303854e-006,0.000000e+000,3,7.813554e-001,0.000000e+000,,,,,,,,,,,,,,32,1,4.000000e+000,7.896423e-004,0.000000e+000,0,,0,
1524214613.727,,0.000000e+000,3.500185e+001,-4.267526e-006,0.000000e+000,3,7.949342e-001,0.000000e+000,,,,,,,,,,,,,,32,1,4.000000e+000,4.688263e-003,0.000000e+000,0,,0,
1524214651.853,,0.000000e+000,3.499872e+001,-4.216828e-006,0.000000e+000,3,7.813252e-001,0.000000e+000,,,,,,,,,,,,,,32,1,4.000000e+000,0.000000e+000,0.000000e+000,0,,0,
1524214689.991,,0.000000e+000,3.500028e+001,-4.182883e-006,0.000000e+000,3,7.848547e-001,0.000000e+000,,,,,,,,,,,,,,32,1,4.000000e+000,1.560211e-003,0.000000e+000,0,,0,
1524214728.136,,0.000000e+000,3.499833e+001,-4.147962e-006,0.000000e+000,3,7.774035e-001,0.000000e+000,,,,,,,,,,,,,,32,1,4.000000e+000,2.349854e-003,0.000000e+000,0,,0,
1524214767.307,,0.000000e+000,3.499950e+001,-4.094350e-006,0.000000e+000,3,7.791109e-001,0.000000e+000,,,,,,,,,,,,,,32,1,4.000000e+000,0.000000e+000,0.000000e+000,0,,0,
1524214805.838,,0.000000e+000,3.499989e+001,-4.038447e-006,0.000000e+000,3,7.768254e-001,0.000000e+000,,,,,,,,,,,,,,32,1,4.000000e+000,7.781982e-004,0.000000e+000,0,,0,
1524214843.928,,0.000000e+000,3.499911e+001,-4.018073e-006,0.000000e+000,3,7.655236e-001,0.000000e+000,,,,,,,,,,,,,,32,1,4.000000e+000,7.820129e-004,0.000000e+000,0,,0,
1524214882.069,,0.000000e+000,3.499989e+001,-4.025298e-006,0.000000e+000,3,7.752746e-001,0.000000e+000,,,,,,,,,,,,,,32,1,4.000000e+000,7.781982e-004,0.000000e+000,0,,0,
1524214919.722,,0.000000e+000,3.499911e+001,-3.981638e-006,0.000000e+000,3,7.733718e-001,0.000000e+000,,,,,,,,,,,,,,32,1,4.000000e+000,7.820129e-004,0.000000e+000,0,,0,
1524214957.460,,0.000000e+000,3.499911e+001,-3.967556e-006,0.000000e+000,3,7.660046e-001,0.000000e+000,,,,,,,,,,,,,,32,1,4.000000e+000,7.820129e-004,0.000000e+000,0,,0,
1524214995.625,,0.000000e+000,3.499872e+001,-3.863640e-006,0.000000e+000,3,7.671874e-001,0.000000e+000,,,,,,,,,,,,,,32,1,4.000000e+000,1.560211e-003,0.000000e+000,0,,0,
1524215034.688,,0.000000e+000,3.499911e+001,-3.864403e-006,0.000000e+000,3,7.659057e-001,0.000000e+000,,,,,,,,,,,,,,32,1,4.000000e+000,7.820129e-004,0.000000e+000,0,,0,
1524215071.726,,0.000000e+000,3.499950e+001,-3.868601e-006,0.000000e+000,3,7.615722e-001,0.000000e+000,,,,,,,,,,,,,,32,1,4.000000e+000,1.560211e-003,0.000000e+000,0,,0,
1524215109.794,,0.000000e+000,3.499911e+001,-3.840917e-006,0.000000e+000,3,7.591826e-001,0.000000e+000,,,,,,,,,,,,,,32,1,4.000000e+000,2.338409e-003,0.000000e+000,0,,0,
1524215146.708,,0.000000e+000,3.499793e+001,-3.850952e-006,0.000000e+000,3,7.630275e-001,0.000000e+000,,,,,,,,,,,,,,32,1,4.000000e+000,3.131866e-003,0.000000e+000,0,,0,
1524215184.848,,0.000000e+000,3.499872e+001,-3.789597e-006,0.000000e+000,3,7.600434e-001,0.000000e+000,,,,,,,,,,,,,,32,1,4.000000e+000,0.000000e+000,0.000000e+000,0,,0,
1524215223.474,,0.000000e+000,3.499872e+001,-3.762980e-006,0.000000e+000,3,7.583714e-001,0.000000e+000,,,,,,,,,,,,,,32,1,4.000000e+000,1.560211e-003,0.000000e+000,0,,0,
1524215261.554,,0.000000e+000,3.499989e+001,-3.756216e-006,0.000000e+000,3,7.630038e-001,0.000000e+000,,,,,,,,,,,,,,32,1,4.000000e+000,7.781982e-004,0.000000e+000,0,,0,
1524215299.572,,0.000000e+000,3.499872e+001,-3.692284e-006,0.000000e+000,3,7.670699e-001,0.000000e+000,,,,,,,,,,,,,,32,1,4.000000e+000,1.560211e-003,0.000000e+000,0,,0,
1524215337.378,,0.000000e+000,3.499989e+001,-3.662878e-006,0.000000e+000,3,7.582408e-001,0.000000e+000,,,,,,,,,,,,,,32,1,4.000000e+000,2.342224e-003,0.000000e+000,0,,0,
1524215375.366,,0.000000e+000,3.499911e+001,-3.659424e-006,0.000000e+000,3,7.497826e-001,0.000000e+000,,,,,,,,,,,,,,32,1,4.000000e+000,7.820129e-004,0.000000e+000,0,,0,
1524215412.936,,0.000000e+000,3.499754e+001,-3.574411e-006,0.000000e+000,3,7.481444e-001,0.000000e+000,,,,,,,,,,,,,,32,1,4.000000e+000,7.896423e-004,0.000000e+000,0,,0,
1524215450.437,,0.000000e+000,3.499872e+001,-3.549784e-006,0.000000e+000,3,7.394373e-001,0.000000e+000,,,,,,,,,,,,,,32,1,4.000000e+000,1.560211e-003,0.000000e+000,0,,0,
1524215488.483,,0.000000e+000,3.499989e+001,-3.547065e-006,0.000000e+000,3,7.390085e-001,0.000000e+000,,,,,,,,,,,,,,32,1,4.000000e+000,2.342224e-003,0.000000e+000,0,,0,
1524215526.636,,0.000000e+000,3.499950e+001,-3.532022e-006,0.000000e+000,3,7.461665e-001,0.000000e+000,,,,,,,,,,,,,,32,1,4.000000e+000,1.560211e-003,0.000000e+000,0,,0,
1524215565.124,,0.000000e+000,3.499872e+001,-3.497222e-006,0.000000e+000,3,7.421826e-001,0.000000e+000,,,,,,,,,,,,,,32,1,4.000000e+000,1.560211e-003,0.000000e+000,0,,0,
1524215602.257,,0.000000e+000,3.499950e+001,-3.446647e-006,0.000000e+000,3,7.278149e-001,0.000000e+000,,,,,,,,,,,,,,32,1,4.000000e+000,1.560211e-003,0.000000e+000,0,,0,
1524215639.737,,0.000000e+000,3.500106e+001,-3.474218e-006,0.000000e+000,3,7.406627e-001,0.000000e+000,,,,,,,,,,,,,,32,1,4.000000e+000,4.692078e-003,0.000000e+000,0,,0,
1524215676.945,,0.000000e+000,3.499911e+001,-3.463439e-006,0.000000e+000,3,7.413785e-001,0.000000e+000,,,,,,,,,,,,,,32,1,4.000000e+000,7.820129e-004,0.000000e+000,0,,0,
1524215714.298,,0.000000e+000,3.499950e+001,-3.391501e-006,0.000000e+000,3,7.266390e-001,0.000000e+000,,,,,,,,,,,,,,32,1,4.000000e+000,1.560211e-003,0.000000e+000,0,,0,
1524215752.204,,0.000000e+000,3.499989e+001,-3.399662e-006,0.000000e+000,3,7.335522e-001,0.000000e+000,,,,,,,,,,,,,,32,1,4.000000e+000,7.781982e-004,0.000000e+000,0,,0,
1524215790.352,,0.000000e+000,3.500028e+001,-3.350524e-006,0.000000e+000,3,7.215768e-001,0.000000e+000,,,,,,,,,,,,,,32,1,4.000000e+000,1.560211e-003,0.000000e+000,0,,0,
1524215828.040,,0.000000e+000,3.499950e+001,-3.255160e-006,0.000000e+000,3,7.141529e-001,0.000000e+000,,,,,,,,,,,,,,32,1,4.000000e+000,1.560211e-003,0.000000e+000,0,,0,
1524215865.591,,0.000000e+000,3.499950e+001,-3.305144e-006,0.000000e+000,3,7.268093e-001,0.000000e+000,,,,,,,,,,,,,,32,1,4.000000e+000,1.560211e-003,0.000000e+000,0,,0,
1524215903.726,,0.000000e+000,3.499911e+001,-3.332278e-006,0.000000e+000,3,7.309775e-001,0.000000e+000,,,,,,,,,,,,,,32,1,4.000000e+000,7.820129e-004,0.000000e+000,0,,0,
1524215941.449,,0.000000e+000,3.499872e+001,-3.288823e-006,0.000000e+000,3,7.305407e-001,0.000000e+000,,,,,,,,,,,,,,32,1,4.000000e+000,1.560211e-003,0.000000e+000,0,,0,
1524215980.305,,0.000000e+000,3.499911e+001,-3.243223e-006,0.000000e+000,3,7.182927e-001,0.000000e+000,,,,,,,,,,,,,,32,1,4.000000e+000,7.820129e-004,0.000000e+000,0,,0,
1524216017.730,,0.000000e+000,3.499794e+001,-3.248861e-006,0.000000e+000,3,7.225918e-001,0.000000e+000,,,,,,,,,,,,,,32,1,4.000000e+000,0.000000e+000,0.000000e+000,0,,0,
1524216055.811,,0.000000e+000,3.499872e+001,-3.186937e-006,0.000000e+000,3,7.120959e-001,0.000000e+000,,,,,,,,,,,,,,32,1,4.000000e+000,0.000000e+000,0.000000e+000,0,,0,
1524216093.954,,0.000000e+000,3.499950e+001,-3.194333e-006,0.000000e+000,3,7.161350e-001,0.000000e+000,,,,,,,,,,,,,,32,1,4.000000e+000,3.120422e-003,0.000000e+000,0,,0,
1524216132.097,,0.000000e+000,3.499911e+001,-3.188743e-006,0.000000e+000,3,7.238510e-001,0.000000e+000,,,,,,,,,,,,,,32,1,4.000000e+000,7.820129e-004,0.000000e+000,0,,0,
1524216170.253,,0.000000e+000,3.499911e+001,-3.145262e-006,0.000000e+000,3,7.101861e-001,0.000000e+000,,,,,,,,,,,,,,32,1,4.000000e+000,7.820129e-004,0.000000e+000,0,,0,
1524216208.378,,0.000000e+000,3.499911e+001,-3.115381e-006,0.000000e+000,3,7.112501e-001,0.000000e+000,,,,,,,,,,,,,,32,1,4.000000e+000,7.820129e-004,0.000000e+000,0,,0,
1524216246.536,,0.000000e+000,3.499872e+001,-3.154700e-006,0.000000e+000,3,7.093572e-001,0.000000e+000,,,,,,,,,,,,,,32,1,4.000000e+000,1.560211e-003,0.000000e+000,0,,0,
1524216284.919,,0.000000e+000,3.499989e+001,-3.024189e-006,0.000000e+000,3,7.141704e-001,0.000000e+000,,,,,,,,,,,,,,32,1,4.000000e+000,7.781982e-004,0.000000e+000,0,,0,
1524216323.160,,0.000000e+000,3.499872e+001,-3.060881e-006,0.000000e+000,3,6.989064e-001,0.000000e+000,,,,,,,,,,,,,,32,1,4.000000e+000,1.560211e-003,0.000000e+000,0,,0,
1524216361.838,,0.000000e+000,3.499754e+001,-3.036566e-006,0.000000e+000,3,6.978992e-001,0.000000e+000,,,,,,,,,,,,,,32,1,4.000000e+000,2.349854e-003,0.000000e+000,0,,0,
1524216399.771,,0.000000e+000,3.499872e+001,-3.007670e-006,0.000000e+000,3,6.949573e-001,0.000000e+000,,,,,,,,,,,,,,32,1,4.000000e+000,1.560211e-003,0.000000e+000,0,,0,
1524216437.354,,0.000000e+000,3.499833e+001,-2.851921e-006,0.000000e+000,3,6.710284e-001,0.000000e+000,,,,,,,,,,,,,,32,1,4.000000e+000,2.349854e-003,0.000000e+000,0,,0,
1524216475.399,,0.000000e+000,3.499950e+001,-2.986460e-006,0.000000e+000,3,6.849155e-001,0.000000e+000,,,,,,,,,,,,,,32,1,4.000000e+000,0.000000e+000,0.000000e+000,0,,0,
1524216515.090,,0.000000e+000,3.499833e+001,-2.939465e-006,0.000000e+000,3,6.881917e-001,0.000000e+000,,,,,,,,,,,,,,32,1,4.000000e+000,7.781982e-004,0.000000e+000,0,,0,
1524216553.076,,0.000000e+000,3.499911e+001,-2.981640e-006,0.000000e+000,3,7.065110e-001,0.000000e+000,,,,,,,,,,,,,,32,1,4.000000e+000,7.820129e-004,0.000000e+000,0,,0,
1524216591.114,,0.000000e+000,3.499989e+001,-2.909069e-006,0.000000e+000,3,6.876474e-001,0.000000e+000,,,,,,,,,,,,,,32,1,4.000000e+000,7.781982e-004,0.000000e+000,0,,0,
1524216629.289,,0.000000e+000,3.499793e+001,-2.869578e-006,0.000000e+000,3,6.777380e-001,0.000000e+000,,,,,,,,,,,,,,32,1,4.000000e+000,4.688263e-003,0.000000e+000,0,,0,
1524216667.210,,0.000000e+000,3.500146e+001,-2.841334e-006,0.000000e+000,3,6.779580e-001,0.000000e+000,,,,,,,,,,,,,,32,1,4.000000e+000,3.910065e-003,0.000000e+000,0,,0,
1524216705.283,,0.000000e+000,3.500028e+001,-2.779017e-006,0.000000e+000,3,6.600721e-001,0.000000e+000,,,,,,,,,,,,,,32,1,4.000000e+000,0.000000e+000,0.000000e+000,0,,0,
1524216744.531,,0.000000e+000,3.499833e+001,-2.814857e-006,0.000000e+000,3,6.901208e-001,0.000000e+000,,,,,,,,,,,,,,32,1,4.000000e+000,7.781982e-004,0.000000e+000,0,,0,
1524216782.679,,0.000000e+000,3.499911e+001,-2.878420e-006,0.000000e+000,3,6.985255e-001,0.000000e+000,,,,,,,,,,,,,,32,1,4.000000e+000,7.820129e-004,0.000000e+000,0,,0,
1524216820.732,,0.000000e+000,3.499872e+001,-2.853895e-006,0.000000e+000,3,6.778725e-001,0.000000e+000,,,,,,,,,,,,,,32,1,4.000000e+000,0.000000e+000,0.000000e+000,0,,0,
1524216858.865,,0.000000e+000,3.500028e+001,-2.738152e-006,0.000000e+000,3,6.469482e-001,0.000000e+000,,,,,,,,,,,,,,32,1,4.000000e+000,0.000000e+000,0.000000e+000,0,,0,
1524216897.018,,0.000000e+000,3.499950e+001,-2.766278e-006,0.000000e+000,3,6.614222e-001,0.000000e+000,,,,,,,,,,,,,,32,1,4.000000e+000,0.000000e+000,0.000000e+000,0,,0,
1524216935.154,,0.000000e+000,3.499950e+001,-2.772331e-006,0.000000e+000,3,6.799925e-001,0.000000e+000,,,,,,,,,,,,,,32,1,4.000000e+000,0.000000e+000,0.000000e+000,0,,0,
1524216973.309,,0.000000e+000,3.499911e+001,-2.783469e-006,0.000000e+000,3,6.591054e-001,0.000000e+000,,,,,,,,,,,,,,32,1,4.000000e+000,7.820129e-004,0.000000e+000,0,,0,
1524217011.427,,0.000000e+000,3.499872e+001,-2.739911e-006,0.000000e+000,3,6.560099e-001,0.000000e+000,,,,,,,,,,,,,,32,1,4.000000e+000,0.000000e+000,0.000000e+000,0,,0,
1524217049.525,,0.000000e+000,3.499911e+001,-2.718969e-006,0.000000e+000,3,6.605036e-001,0.000000e+000,,,,,,,,,,,,,,32,1,4.000000e+000,7.820129e-004,0.000000e+000,0,,0,
1524217087.231,,0.000000e+000,3.499911e+001,-2.728348e-006,0.000000e+000,3,6.716275e-001,0.000000e+000,,,,,,,,,,,,,,32,1,4.000000e+000,7.820129e-004,0.000000e+000,0,,0,
1524217125.352,,0.000000e+000,3.499950e+001,-2.714605e-006,0.000000e+000,3,6.758244e-001,0.000000e+000,,,,,,,,,,,,,,32,1,4.000000e+000,1.560211e-003,0.000000e+000,0,,0,
1524217163.820,,0.000000e+000,3.499950e+001,-2.633433e-006,0.000000e+000,3,6.450822e-001,0.000000e+000,,,,,,,,,,,,,,32,1,4.000000e+000,0.000000e+000,0.000000e+000,0,,0,
1524217201.543,,0.000000e+000,3.499950e+001,-2.677953e-006,0.000000e+000,3,6.630588e-001,0.000000e+000,,,,,,,,,,,,,,32,1,4.000000e+000,0.000000e+000,0.000000e+000,0,,0,
1524217239.926,,0.000000e+000,3.499911e+001,-2.612695e-006,0.000000e+000,3,6.483786e-001,0.000000e+000,,,,,,,,,,,,,,32,1,4.000000e+000,7.820129e-004,0.000000e+000,0,,0,
1524217277.819,,0.000000e+000,3.499793e+001,-2.581702e-006,0.000000e+000,3,6.477361e-001,0.000000e+000,,,,,,,,,,,,,,32,1,4.000000e+000,1.567841e-003,0.000000e+000,0,,0,
1524217315.712,,0.000000e+000,3.499911e+001,-2.649513e-006,0.000000e+000,3,6.623540e-001,0.000000e+000,,,,,,,,,,,,,,32,1,4.000000e+000,7.820129e-004,0.000000e+000,0,,0,
1524217353.935,,0.000000e+000,3.499950e+001,-2.495370e-006,0.000000e+000,3,6.636419e-001,0.000000e+000,,,,,,,,,,,,,,32,1,4.000000e+000,1.560211e-003,0.000000e+000,0,,0,
1524217393.073,,0.000000e+000,3.499989e+001,-2.536174e-006,0.000000e+000,3,6.440044e-001,0.000000e+000,,,,,,,,,,,,,,32,1,4.000000e+000,7.781982e-004,0.000000e+000,0,,0,
1524217430.519,,0.000000e+000,3.499833e+001,-2.547605e-006,0.000000e+000,3,6.304077e-001,0.000000e+000,,,,,,,,,,,,,,32,1,4.000000e+000,7.781982e-004,0.000000e+000,0,,0,
1524217468.914,,0.000000e+000,3.499950e+001,-2.518645e-006,0.000000e+000,3,6.470373e-001,0.000000e+000,,,,,,,,,,,,,,32,1,4.000000e+000,0.000000e+000,0.000000e+000,0,,0,
1524217506.735,,0.000000e+000,3.499754e+001,-2.496764e-006,0.000000e+000,3,6.207103e-001,0.000000e+000,,,,,,,,,,,,,,32,1,4.000000e+000,7.896423e-004,0.000000e+000,0,,0,
1524217544.753,,0.000000e+000,3.499911e+001,-2.465579e-006,0.000000e+000,3,6.368051e-001,0.000000e+000,,,,,,,,,,,,,,32,1,4.000000e+000,7.820129e-004,0.000000e+000,0,,0,
1524217582.463,,0.000000e+000,3.499911e+001,-2.469674e-006,0.000000e+000,3,6.157620e-001,0.000000e+000,,,,,,,,,,,,,,32,1,4.000000e+000,7.820129e-004,0.000000e+000,0,,0,
1524217620.219,,0.000000e+000,3.499911e+001,-2.401709e-006,0.000000e+000,3,6.224526e-001,0.000000e+000,,,,,,,,,,,,,,32,1,4.000000e+000,7.820129e-004,0.000000e+000,0,,0,
1524217658.344,,0.000000e+000,3.499911e+001,-2.478851e-006,0.000000e+000,3,6.314946e-001,0.000000e+000,,,,,,,,,,,,,,32,1,4.000000e+000,7.820129e-004,0.000000e+000,0,,0,
1524217696.070,,0.000000e+000,3.500028e+001,-2.432812e-006,0.000000e+000,3,6.199468e-001,0.000000e+000,,,,,,,,,,,,,,32,1,4.000000e+000,1.560211e-003,0.000000e+000,0,,0,
1524217733.843,,0.000000e+000,3.499911e+001,-2.381680e-006,0.000000e+000,3,6.097268e-001,0.000000e+000,,,,,,,,,,,,,,32,1,4.000000e+000,7.820129e-004,0.000000e+000,0,,0,
1524217771.478,,0.000000e+000,3.499989e+001,-2.366194e-006,0.000000e+000,3,6.243497e-001,0.000000e+000,,,,,,,,,,,,,,32,1,4.000000e+000,7.781982e-004,0.000000e+000,0,,0,
1524217809.607,,0.000000e+000,3.499950e+001,-2.365952e-006,0.000000e+000,3,6.116371e-001,0.000000e+000,,,,,,,,,,,,,,32,1,4.000000e+000,0.000000e+000,0.000000e+000,0,,0,
1524217848.030,,0.000000e+000,3.500028e+001,-2.353353e-006,0.000000e+000,3,5.855414e-001,0.000000e+000,,,,,,,,,,,,,,32,1,4.000000e+000,1.560211e-003,0.000000e+000,0,,0,
1524217885.805,,0.000000e+000,3.499989e+001,-2.304025e-006,0.000000e+000,3,6.074039e-001,0.000000e+000,,,,,,,,,,,,,,32,1,4.000000e+000,2.342224e-003,0.000000e+000,0,,0,
1524217923.451,,0.000000e+000,3.499872e+001,-2.320795e-006,0.000000e+000,3,5.731221e-001,0.000000e+000,,,,,,,,,,,,,,32,1,4.000000e+000,0.000000e+000,0.000000e+000,0,,0,
1524217961.584,,0.000000e+000,3.499950e+001,-2.326616e-006,0.000000e+000,3,6.205552e-001,0.000000e+000,,,,,,,,,,,,,,32,1,4.000000e+000,0.000000e+000,0.000000e+000,0,,0,
1524218000.187,,0.000000e+000,3.499989e+001,-2.247858e-006,0.000000e+000,3,5.676984e-001,0.000000e+000,,,,,,,,,,,,,,32,1,4.000000e+000,2.342224e-003,0.000000e+000,0,,0,
1524218037.775,,0.000000e+000,3.499833e+001,-2.295439e-006,0.000000e+000,3,5.959911e-001,0.000000e+000,,,,,,,,,,,,,,32,1,4.000000e+000,7.781982e-004,0.000000e+000,0,,0,
1524218075.526,,0.000000e+000,3.499989e+001,-2.210627e-006,0.000000e+000,3,5.905660e-001,0.000000e+000,,,,,,,,,,,,,,32,1,4.000000e+000,7.781982e-004,0.000000e+000,0,,0,
1524218114.049,,0.000000e+000,3.499950e+001,-2.286037e-006,0.000000e+000,3,6.023692e-001,0.000000e+000,,,,,,,,,,,,,,32,1,4.000000e+000,0.000000e+000,0.000000e+000,0,,0,
1524218152.184,,0.000000e+000,3.499872e+001,-2.308844e-006,0.000000e+000,3,6.110843e-001,0.000000e+000,,,,,,,,,,,,,,32,1,4.000000e+000,1.560211e-003,0.000000e+000,0,,0,
1524218189.670,,0.000000e+000,3.499911e+001,-2.272152e-006,0.000000e+000,3,6.069893e-001,0.000000e+000,,,,,,,,,,,,,,32,1,4.000000e+000,7.820129e-004,0.000000e+000,0,,0,
1524218227.208,,0.000000e+000,3.499950e+001,-2.216893e-006,0.000000e+000,3,5.877871e-001,0.000000e+000,,,,,,,,,,,,,,32,1,4.000000e+000,0.000000e+000,0.000000e+000,0,,0,
1524218265.371,,0.000000e+000,3.499950e+001,-2.206080e-006,0.000000e+000,3,5.847993e-001,0.000000e+000,,,,,,,,,,,,,,32,1,4.000000e+000,0.000000e+000,0.000000e+000,0,,0,
1524218303.544,,0.000000e+000,3.499872e+001,-2.178827e-006,0.000000e+000,3,5.754150e-001,0.000000e+000,,,,,,,,,,,,,,32,1,4.000000e+000,0.000000e+000,0.000000e+000,0,,0,
1524218341.659,,0.000000e+000,3.499911e+001,-2.167351e-006,0.000000e+000,3,5.844170e-001,0.000000e+000,,,,,,,,,,,,,,32,1,4.000000e+000,7.820129e-004,0.000000e+000,0,,0,
1524218379.330,,0.000000e+000,3.499872e+001,-2.143882e-006,0.000000e+000,3,5.679915e-001,0.000000e+000,,,,,,,,,,,,,,32,1,4.000000e+000,0.000000e+000,0.000000e+000,0,,0,
1524218417.418,,0.000000e+000,3.500028e+001,-2.135839e-006,0.000000e+000,3,5.578450e-001,0.000000e+000,,,,,,,,,,,,,,32,1,4.000000e+000,1.560211e-003,0.000000e+000,0,,0,
1524218455.564,,0.000000e+000,3.499989e+001,-2.114809e-006,0.000000e+000,3,5.593816e-001,0.000000e+000,,,,,,,,,,,,,,32,1,4.000000e+000,7.781982e-004,0.000000e+000,0,,0,
1524218493.562,,0.000000e+000,3.499950e+001,-2.152449e-006,0.000000e+000,3,5.754941e-001,0.000000e+000,,,,,,,,,,,,,,32,1,4.000000e+000,0.000000e+000,0.000000e+000,0,,0,
1524218531.822,,0.000000e+000,3.499872e+001,-2.175281e-006,0.000000e+000,3,5.833873e-001,0.000000e+000,,,,,,,,,,,,,,32,1,4.000000e+000,1.560211e-003,0.000000e+000,0,,0,
1524218569.965,,0.000000e+000,3.499989e+001,-2.126518e-006,0.000000e+000,3,5.783483e-001,0.000000e+000,,,,,,,,,,,,,,32,1,4.000000e+000,7.781982e-004,0.000000e+000,0,,0,
1524218608.106,,0.000000e+000,3.499872e+001,-2.106913e-006,0.000000e+000,3,5.606367e-001,0.000000e+000,,,,,,,,,,,,,,32,1,4.000000e+000,1.560211e-003,0.000000e+000,0,,0,
1524218646.229,,0.000000e+000,3.499950e+001,-2.090988e-006,0.000000e+000,3,5.591767e-001,0.000000e+000,,,,,,,,,,,,,,32,1,4.000000e+000,1.560211e-003,0.000000e+000,0,,0,
1524218684.137,,0.000000e+000,3.499833e+001,-2.066314e-006,0.000000e+000,3,5.603311e-001,0.000000e+000,,,,,,,,,,,,,,32,1,4.000000e+000,2.349854e-003,0.000000e+000,0,,0,
1524218722.165,,0.000000e+000,3.499911e+001,-2.056900e-006,0.000000e+000,3,5.446062e-001,0.000000e+000,,,,,,,,,,,,,,32,1,4.000000e+000,7.820129e-004,0.000000e+000,0,,0,
1524218760.158,,0.000000e+000,3.499950e+001,-2.090737e-006,0.000000e+000,3,5.784423e-001,0.000000e+000,,,,,,,,,,,,,,32,1,4.000000e+000,0.000000e+000,0.000000e+000,0,,0,
1524218798.269,,0.000000e+000,3.499911e+001,-2.048608e-006,0.000000e+000,3,5.558300e-001,0.000000e+000,,,,,,,,,,,,,,32,1,4.000000e+000,7.820129e-004,0.000000e+000,0,,0,
1524218836.042,,0.000000e+000,3.499950e+001,-1.995117e-006,0.000000e+000,3,5.388671e-001,0.000000e+000,,,,,,,,,,,,,,32,1,4.000000e+000,0.000000e+000,0.000000e+000,0,,0,
1524218873.910,,0.000000e+000,3.499911e+001,-1.970768e-006,0.000000e+000,3,5.465630e-001,0.000000e+000,,,,,,,,,,,,,,32,1,4.000000e+000,7.820129e-004,0.000000e+000,0,,0,
1524218911.858,,0.000000e+000,3.499989e+001,-1.967976e-006,0.000000e+000,3,5.257220e-001,0.000000e+000,,,,,,,,,,,,,,32,1,4.000000e+000,7.781982e-004,0.000000e+000,0,,0,
1524218949.776,,0.000000e+000,3.500067e+001,-1.948281e-006,0.000000e+000,3,5.354864e-001,0.000000e+000,,,,,,,,,,,,,,32,1,4.000000e+000,7.820129e-004,0.000000e+000,0,,0,
1524218987.854,,0.000000e+000,3.499989e+001,-1.953761e-006,0.000000e+000,3,5.431777e-001,0.000000e+000,,,,,,,,,,,,,,32,1,4.000000e+000,2.342224e-003,0.000000e+000,0,,0,
1524219026.542,,0.000000e+000,3.499911e+001,-1.984264e-006,0.000000e+000,3,5.394112e-001,0.000000e+000,,,,,,,,,,,,,,32,1,4.000000e+000,7.820129e-004,0.000000e+000,0,,0,
1524219063.630,,0.000000e+000,3.499911e+001,-1.972400e-006,0.000000e+000,3,5.402640e-001,0.000000e+000,,,,,,,,,,,,,,32,1,4.000000e+000,7.820129e-004,0.000000e+000,0,,0,
1524219101.250,,0.000000e+000,3.499872e+001,-1.944015e-006,0.000000e+000,3,5.273696e-001,0.000000e+000,,,,,,,,,,,,,,32,1,4.000000e+000,1.560211e-003,0.000000e+000,0,,0,
1524219139.839,,0.000000e+000,3.500067e+001,-1.944004e-006,0.000000e+000,3,5.260355e-001,0.000000e+000,,,,,,,,,,,,,,32,1,4.000000e+000,7.820129e-004,0.000000e+000,0,,0,
1524219177.997,,0.000000e+000,3.499833e+001,-1.941321e-006,0.000000e+000,3,5.377377e-001,0.000000e+000,,,,,,,,,,,,,,32,1,4.000000e+000,7.781982e-004,0.000000e+000,0,,0,
1524219217.352,,0.000000e+000,3.499911e+001,-1.863615e-006,0.000000e+000,3,5.228641e-001,0.000000e+000,,,,,,,,,,,,,,32,1,4.000000e+000,7.820129e-004,0.000000e+000,0,,0,
1524219255.325,,0.000000e+000,3.499833e+001,-1.925796e-006,0.000000e+000,3,5.405754e-001,0.000000e+000,,,,,,,,,,,,,,32,1,4.000000e+000,2.349854e-003,0.000000e+000,0,,0,
1524219293.243,,0.000000e+000,3.499871e+001,-1.902447e-006,0.000000e+000,3,4.653029e-001,0.000000e+000,,,,,,,,,,,,,,32,1,4.000000e+000,6.248474e-003,0.000000e+000,0,,0,
1524219331.729,,0.000000e+000,3.500106e+001,-1.920264e-006,0.000000e+000,3,4.956201e-001,0.000000e+000,,,,,,,,,,,,,,32,1,4.000000e+000,3.128052e-003,0.000000e+000,0,,0,
1524219370.362,,0.000000e+000,3.499872e+001,-1.883171e-006,0.000000e+000,3,5.259125e-001,0.000000e+000,,,,,,,,,,,,,,32,1,4.000000e+000,1.560211e-003,0.000000e+000,0,,0,
1524219408.500,,0.000000e+000,3.499911e+001,-1.837571e-006,0.000000e+000,3,5.105240e-001,0.000000e+000,,,,,,,,,,,,,,32,1,4.000000e+000,7.820129e-004,0.000000e+000,0,,0,
1524219446.628,,0.000000e+000,3.499950e+001,-1.917369e-006,0.000000e+000,3,5.327342e-001,0.000000e+000,,,,,,,,,,,,,,32,1,4.000000e+000,0.000000e+000,0.000000e+000,0,,0,
1524219485.306,,0.000000e+000,3.499950e+001,-1.837453e-006,0.000000e+000,3,5.051172e-001,0.000000e+000,,,,,,,,,,,,,,32,1,4.000000e+000,1.560211e-003,0.000000e+000,0,,0,
1524219523.439,,0.000000e+000,3.499911e+001,-1.792129e-006,0.000000e+000,3,4.766234e-001,0.000000e+000,,,,,,,,,,,,,,32,1,4.000000e+000,7.820129e-004,0.000000e+000,0,,0,
1524219561.572,,0.000000e+000,3.500067e+001,-1.771728e-006,0.000000e+000,3,4.728729e-001,0.000000e+000,,,,,,,,,,,,,,32,1,4.000000e+000,7.820129e-004,0.000000e+000,0,,0,
1524219599.433,,0.000000e+000,3.499950e+001,-1.824834e-006,0.000000e+000,3,5.071285e-001,0.000000e+000,,,,,,,,,,,,,,32,1,4.000000e+000,0.000000e+000,0.000000e+000,0,,0,
1524219637.453,,0.000000e+000,3.500028e+001,-1.802161e-006,0.000000e+000,3,4.914193e-001,0.000000e+000,,,,,,,,,,,,,,32,1,4.000000e+000,1.560211e-003,0.000000e+000,0,,0,
1524219675.586,,0.000000e+000,3.500067e+001,-1.834794e-006,0.000000e+000,3,5.016325e-001,0.000000e+000,,,,,,,,,,,,,,32,1,4.000000e+000,7.820129e-004,0.000000e+000,0,,0,
1524219712.930,,0.000000e+000,3.499989e+001,-1.816482e-006,0.000000e+000,3,5.025302e-001,0.000000e+000,,,,,,,,,,,,,,32,1,4.000000e+000,7.781982e-004,0.000000e+000,0,,0,
1524219750.857,,0.000000e+000,3.499872e+001,-1.825193e-006,0.000000e+000,3,5.017849e-001,0.000000e+000,,,,,,,,,,,,,,32,1,4.000000e+000,0.000000e+000,0.000000e+000,0,,0,
1524219788.888,,0.000000e+000,3.499911e+001,-1.747368e-006,0.000000e+000,3,4.490675e-001,0.000000e+000,,,,,,,,,,,,,,32,1,4.000000e+000,7.820129e-004,0.000000e+000,0,,0,
1524219825.759,,0.000000e+000,3.499871e+001,-1.778604e-006,0.000000e+000,3,4.847001e-001,0.000000e+000,,,,,,,,,,,,,,32,1,4.000000e+000,3.128052e-003,0.000000e+000,0,,0,
1524219863.872,,0.000000e+000,3.499754e+001,-1.769228e-006,0.000000e+000,3,4.826307e-001,0.000000e+000,,,,,,,,,,,,,,32,1,4.000000e+000,7.896423e-004,0.000000e+000,0,,0,
1524219901.480,,0.000000e+000,3.500028e+001,-1.716575e-006,0.000000e+000,3,4.159660e-001,0.000000e+000,,,,,,,,,,,,,,32,1,4.000000e+000,1.560211e-003,0.000000e+000,0,,0,
1524219939.555,,0.000000e+000,3.499754e+001,-1.736812e-006,0.000000e+000,3,4.598066e-001,0.000000e+000,,,,,,,,,,,,,,32,1,4.000000e+000,3.910065e-003,0.000000e+000,0,,0,
1524219977.563,,0.000000e+000,3.499754e+001,-1.766979e-006,0.000000e+000,3,4.887235e-001,0.000000e+000,,,,,,,,,,,,,,32,1,4.000000e+000,3.910065e-003,0.000000e+000,0,,0,
1524220015.456,,0.000000e+000,3.499989e+001,-1.714061e-006,0.000000e+000,3,4.383905e-001,0.000000e+000,,,,,,,,,,,,,,32,1,4.000000e+000,7.781982e-004,0.000000e+000,0,,0,
1524220053.087,,0.000000e+000,3.499911e+001,-1.725235e-006,0.000000e+000,3,4.822506e-001,0.000000e+000,,,,,,,,,,,,,,32,1,4.000000e+000,7.820129e-004,0.000000e+000,0,,0,
1524220091.420,,0.000000e+000,3.500145e+001,-1.677564e-006,0.000000e+000,3,4.471208e-001,0.000000e+000,,,,,,,,,,,,,,32,1,4.000000e+000,2.349854e-003,0.000000e+000,0,,0,
1524220128.866,,0.000000e+000,3.499872e+001,-1.711636e-006,0.000000e+000,3,4.646667e-001,0.000000e+000,,,,,,,,,,,,,,32,1,4.000000e+000,0.000000e+000,0.000000e+000,0,,0,
1524220167.014,,0.000000e+000,3.499950e+001,-1.712160e-006,0.000000e+000,3,4.647779e-001,0.000000e+000,,,,,,,,,,,,,,32,1,4.000000e+000,0.000000e+000,0.000000e+000,0,,0,
1524220205.044,,0.000000e+000,3.499950e+001,-1.667566e-006,0.000000e+000,3,4.383562e-001,0.000000e+000,,,,,,,,,,,,,,32,1,4.000000e+000,0.000000e+000,0.000000e+000,0,,0,
1524220242.725,,0.000000e+000,3.499989e+001,-1.662315e-006,0.000000e+000,3,4.354644e-001,0.000000e+000,,,,,,,,,,,,,,32,1,4.000000e+000,7.781982e-004,0.000000e+000,0,,0,
1524220280.860,,0.000000e+000,3.499950e+001,-1.645283e-006,0.000000e+000,3,4.547888e-001,0.000000e+000,,,,,,,,,,,,,,32,1,4.000000e+000,1.560211e-003,0.000000e+000,0,,0,
1524220318.993,,0.000000e+000,3.499911e+001,-1.662863e-006,0.000000e+000,3,4.358335e-001,0.000000e+000,,,,,,,,,,,,,,32,1,4.000000e+000,7.820129e-004,0.000000e+000,0,,0,
1524220357.606,,0.000000e+000,3.499911e+001,-1.680253e-006,0.000000e+000,3,4.678964e-001,0.000000e+000,,,,,,,,,,,,,,32,1,4.000000e+000,7.820129e-004,0.000000e+000,0,,0,
1524220395.472,,0.000000e+000,3.499950e+001,-1.628565e-006,0.000000e+000,3,4.369940e-001,0.000000e+000,,,,,,,,,,,,,,32,1,4.000000e+000,0.000000e+000,0.000000e+000,0,,0,
1524220433.537,,0.000000e+000,3.499989e+001,-1.655062e-006,0.000000e+000,3,4.153415e-001,0.000000e+000,,,,,,,,,,,,,,32,1,4.000000e+000,7.781982e-004,0.000000e+000,0,,0,
1524220471.443,,0.000000e+000,3.499911e+001,-1.558388e-006,0.000000e+000,3,4.221618e-001,0.000000e+000,,,,,,,,,,,,,,32,1,4.000000e+000,7.820129e-004,0.000000e+000,0,,0,
1524220509.114,,0.000000e+000,3.500028e+001,-1.614774e-006,0.000000e+000,3,4.499902e-001,0.000000e+000,,,,,,,,,,,,,,32,1,4.000000e+000,1.560211e-003,0.000000e+000,0,,0,
1524220547.219,,0.000000e+000,3.499950e+001,-1.607074e-006,0.000000e+000,3,4.223560e-001,0.000000e+000,,,,,,,,,,,,,,32,1,4.000000e+000,0.000000e+000,0.000000e+000,0,,0,
1524220585.357,,0.000000e+000,3.499911e+001,-1.576635e-006,0.000000e+000,3,4.259405e-001,0.000000e+000,,,,,,,,,,,,,,32,1,4.000000e+000,7.820129e-004,0.000000e+000,0,,0,
1524220623.405,,0.000000e+000,3.499989e+001,-1.610104e-006,0.000000e+000,3,4.456940e-001,0.000000e+000,,,,,,,,,,,,,,32,1,4.000000e+000,7.781982e-004,0.000000e+000,0,,0,
1524220661.108,,0.000000e+000,3.499911e+001,-1.591580e-006,0.000000e+000,3,4.166092e-001,0.000000e+000,,,,,,,,,,,,,,32,1,4.000000e+000,7.820129e-004,0.000000e+000,0,,0,
1524220699.707,,0.000000e+000,3.499950e+001,-1.525686e-006,0.000000e+000,3,4.132372e-001,0.000000e+000,,,,,,,,,,,,,,32,1,4.000000e+000,0.000000e+000,0.000000e+000,0,,0,
1524220737.555,,0.000000e+000,3.499911e+001,-1.549630e-006,0.000000e+000,3,4.117188e-001,0.000000e+000,,,,,,,,,,,,,,32,1,4.000000e+000,7.820129e-004,0.000000e+000,0,,0,
1524220775.488,,0.000000e+000,3.500028e+001,-1.579045e-006,0.000000e+000,3,4.335189e-001,0.000000e+000,,,,,,,,,,,,,,32,1,4.000000e+000,3.120422e-003,0.000000e+000,0,,0,
1524220813.933,,0.000000e+000,3.499872e+001,-1.532096e-006,0.000000e+000,3,3.874860e-001,0.000000e+000,,,,,,,,,,,,,,32,1,4.000000e+000,0.000000e+000,0.000000e+000,0,,0,
1524220851.639,,0.000000e+000,3.499950e+001,-1.508615e-006,0.000000e+000,3,4.005136e-001,0.000000e+000,,,,,,,,,,,,,,32,1,4.000000e+000,0.000000e+000,0.000000e+000,0,,0,
1524220889.777,,0.000000e+000,3.499911e+001,-1.500820e-006,0.000000e+000,3,4.166299e-001,0.000000e+000,,,,,,,,,,,,,,32,1,4.000000e+000,7.820129e-004,0.000000e+000,0,,0,
1524220928.325,,0.000000e+000,3.499911e+001,-1.483030e-006,0.000000e+000,3,3.599887e-001,0.000000e+000,,,,,,,,,,,,,,32,1,4.000000e+000,7.820129e-004,0.000000e+000,0,,0,
1524220966.050,,0.000000e+000,3.499989e+001,-1.489141e-006,0.000000e+000,3,3.868119e-001,0.000000e+000,,,,,,,,,,,,,,32,1,4.000000e+000,3.898621e-003,0.000000e+000,0,,0,
1524221003.721,,0.000000e+000,3.499911e+001,-1.483996e-006,0.000000e+000,3,3.986119e-001,0.000000e+000,,,,,,,,,,,,,,32,1,4.000000e+000,7.820129e-004,0.000000e+000,0,,0,
1524221041.766,,0.000000e+000,3.499950e+001,-1.490671e-006,0.000000e+000,3,3.866792e-001,0.000000e+000,,,,,,,,,,,,,,32,1,4.000000e+000,0.000000e+000,0.000000e+000,0,,0,
1524221079.880,,0.000000e+000,3.499833e+001,-1.462504e-006,0.000000e+000,3,3.664633e-001,0.000000e+000,,,,,,,,,,,,,,32,1,4.000000e+000,7.781982e-004,0.000000e+000,0,,0,
1524221118.270,,0.000000e+000,3.499950e+001,-1.415885e-006,0.000000e+000,3,3.509283e-001,0.000000e+000,,,,,,,,,,,,,,32,1,4.000000e+000,1.560211e-003,0.000000e+000,0,,0,
1524221156.523,,0.000000e+000,3.499833e+001,-1.416264e-006,0.000000e+000,3,3.278764e-001,0.000000e+000,,,,,,,,,,,,,,32,1,4.000000e+000,2.349854e-003,0.000000e+000,0,,0,
1524221194.526,,0.000000e+000,3.499872e+001,-1.440222e-006,0.000000e+000,3,3.705199e-001,0.000000e+000,,,,,,,,,,,,,,32,1,4.000000e+000,1.560211e-003,0.000000e+000,0,,0,
1524221232.517,,0.000000e+000,3.499677e+001,-1.400373e-006,0.000000e+000,3,3.436960e-001,0.000000e+000,,,,,,,,,,,,,,32,1,4.000000e+000,5.470276e-003,0.000000e+000,0,,0,
1524221270.295,,0.000000e+000,3.499833e+001,-1.390939e-006,0.000000e+000,3,3.381143e-001,0.000000e+000,,,,,,,,,,,,,,32,1,4.000000e+000,7.781982e-004,0.000000e+000,0,,0,
1524221308.283,,0.000000e+000,3.499833e+001,-1.348933e-006,0.000000e+000,3,3.296547e-001,0.000000e+000,,,,,,,,,,,,,,32,1,4.000000e+000,7.781982e-004,0.000000e+000,0,,0,
1524221345.996,,0.000000e+000,3.499950e+001,-1.412551e-006,0.000000e+000,3,3.437950e-001,0.000000e+000,,,,,,,,,,,,,,32,1,4.000000e+000,1.560211e-003,0.000000e+000,0,,0,
1524221383.982,,0.000000e+000,3.499950e+001,-1.373804e-006,0.000000e+000,3,3.216208e-001,0.000000e+000,,,,,,,,,,,,,,32,1,4.000000e+000,0.000000e+000,0.000000e+000,0,,0,
1524221421.775,,0.000000e+000,3.499911e+001,-1.376555e-006,0.000000e+000,3,3.492827e-001,0.000000e+000,,,,,,,,,,,,,,32,1,4.000000e+000,7.820129e-004,0.000000e+000,0,,0,
1524221458.840,,0.000000e+000,3.499989e+001,-1.376546e-006,0.000000e+000,3,3.145893e-001,0.000000e+000,,,,,,,,,,,,,,32,1,4.000000e+000,2.342224e-003,0.000000e+000,0,,0,
1524221496.163,,0.000000e+000,3.499950e+001,-1.391950e-006,0.000000e+000,3,3.487552e-001,0.000000e+000,,,,,,,,,,,,,,32,1,4.000000e+000,1.560211e-003,0.000000e+000,0,,0,
1524221533.474,,0.000000e+000,3.499911e+001,-1.352705e-006,0.000000e+000,3,2.924106e-001,0.000000e+000,,,,,,,,,,,,,,32,1,4.000000e+000,7.820129e-004,0.000000e+000,0,,0,
1524221571.364,,0.000000e+000,3.499872e+001,-1.334869e-006,0.000000e+000,3,3.088721e-001,0.000000e+000,,,,,,,,,,,,,,32,1,4.000000e+000,0.000000e+000,0.000000e+000,0,,0,
1524221609.750,,0.000000e+000,3.499911e+001,-1.313881e-006,0.000000e+000,3,3.052908e-001,0.000000e+000,,,,,,,,,,,,,,32,1,4.000000e+000,7.820129e-004,0.000000e+000,0,,0,
1524221648.160,,0.000000e+000,3.499911e+001,-1.357041e-006,0.000000e+000,3,3.481548e-001,0.000000e+000,,,,,,,,,,,,,,32,1,4.000000e+000,7.820129e-004,0.000000e+000,0,,0,
1524221686.091,,0.000000e+000,3.499833e+001,-1.320326e-006,0.000000e+000,3,2.906141e-001,0.000000e+000,,,,,,,,,,,,,,32,1,4.000000e+000,7.781982e-004,0.000000e+000,0,,0,
1524221724.212,,0.000000e+000,3.499989e+001,-1.314872e-006,0.000000e+000,3,2.949908e-001,0.000000e+000,,,,,,,,,,,,,,32,1,4.000000e+000,7.781982e-004,0.000000e+000,0,,0,
1524221762.092,,0.000000e+000,3.499950e+001,-1.295706e-006,0.000000e+000,3,2.599177e-001,0.000000e+000,,,,,,,,,,,,,,32,1,4.000000e+000,0.000000e+000,0.000000e+000,0,,0,
1524221799.978,,0.000000e+000,3.499911e+001,-1.320391e-006,0.000000e+000,3,3.159406e-001,0.000000e+000,,,,,,,,,,,,,,32,1,4.000000e+000,7.820129e-004,0.000000e+000,0,,0,
1524221838.661,,0.000000e+000,3.499794e+001,-1.314594e-006,0.000000e+000,3,3.051285e-001,0.000000e+000,,,,,,,,,,,,,,32,1,4.000000e+000,0.000000e+000,0.000000e+000,0,,0,
1524221876.239,,0.000000e+000,3.499950e+001,-1.266769e-006,0.000000e+000,3,2.769237e-001,0.000000e+000,,,,,,,,,,,,,,32,1,4.000000e+000,0.000000e+000,0.000000e+000,0,,0,
1524221913.867,,0.000000e+000,3.499872e+001,-1.205098e-006,0.000000e+000,3,2.142954e-001,0.000000e+000,,,,,,,,,,,,,,32,1,4.000000e+000,0.000000e+000,0.000000e+000,0,,0,