File: Experimental Raw Data/MFn1 VRM/Iterative Regression/MFn1_VRMac_33K_12000s_VRMde_35K.dc.dat
[Header]
TITLE,MPMS DC Measurement
BYAPP,MPMS Measurement,2.1,Summary
FILEOPENTIME, 1524111391.466000 4/18/2018, 10:16:31 PM

INFO, APPNAME, MPMS MultiVu Application, Revision 1.61,  Build 082

INFO, NAME, MFn1
INFO, WEIGHT, 1.000
INFO, AREA, 1.000
INFO, LENGTH, 1.000
INFO, SHAPE, 0
INFO, COMMENT,
INFO, SEQUENCE FILE: VRMac_33K_12000s_VRMde_35K.seq


INFO, BACKGROUND DATA FILE:, None


STARTUPAXIS,X,4,LINEAR,AUTO,0.000000,0.000000
STARTUPAXIS,Y1,5,LINEAR,AUTO,0.000000,0.000000


STARTUPGROUP,Longitudinal
FIELDGROUP,Longitudinal,1,2,3,4,5,6,7,8,9,15,16,17,18,27,28
FIELDGROUP,Transverse,1,2,3,4,10,11,12,13,14,19,20,21,22,27,28

PLOT_APPEARANCE,ALL,HORZ_GRID_ON,VERT_GRID_ON,MARKERS_AND_LINES

[Data]
Time,Comment,Field (Oe),Temperature (K),Long Moment (emu),Long Scan Std Dev,Long Algorithm,Long Reg Fit,Long Percent Error (%),Trans Moment (emu),Trans Scan Std Dev,Trans Algorithm,Trans Reg Fit,Trans Percent Error (%),Long Moment [w/o ABS] (emu),Long Scan Std Dev [w/o ABS],Long Reg Fit [w/o ABS],Long Percent Error [w/o ABS] (%),Trans Moment [w/o ABS] (emu),Trans Scan Std Dev [w/o ABS],Trans Reg Fit [w/o ABS],Trans Percent Error [w/o ABS] (%),Points per Scan,Scans per Measurement,Scan Length (cm),Delta Temp (K),Rot Position (deg),Error,EC Comp. Running,Using ABS,
1524111391.464,,0.000000e+000,3.500106e+001,-1.581296e-005,0.000000e+000,3,9.435334e-001,0.000000e+000,,,,,,,,,,,,,,32,1,4.000000e+000,1.560211e-003,0.000000e+000,0,,0,
1524111428.782,,0.000000e+000,3.500106e+001,-1.456561e-005,0.000000e+000,3,9.365838e-001,0.000000e+000,,,,,,,,,,,,,,32,1,4.000000e+000,3.128052e-003,0.000000e+000,0,,0,
1524111466.767,,0.000000e+000,3.499989e+001,-1.341044e-005,0.000000e+000,3,9.347957e-001,0.000000e+000,,,,,,,,,,,,,,32,1,4.000000e+000,7.781982e-004,0.000000e+000,0,,0,
1524111505.335,,0.000000e+000,3.499872e+001,-1.253693e-005,0.000000e+000,3,9.222981e-001,0.000000e+000,,,,,,,,,,,,,,32,1,4.000000e+000,0.000000e+000,0.000000e+000,0,,0,
1524111543.461,,0.000000e+000,3.499911e+001,-1.193518e-005,0.000000e+000,3,9.254075e-001,0.000000e+000,,,,,,,,,,,,,,32,1,4.000000e+000,7.820129e-004,0.000000e+000,0,,0,
1524111582.376,,0.000000e+000,3.499950e+001,-1.126738e-005,0.000000e+000,3,9.172053e-001,0.000000e+000,,,,,,,,,,,,,,32,1,4.000000e+000,0.000000e+000,0.000000e+000,0,,0,
1524111619.574,,0.000000e+000,3.499833e+001,-1.078068e-005,0.000000e+000,3,9.172170e-001,0.000000e+000,,,,,,,,,,,,,,32,1,4.000000e+000,2.349854e-003,0.000000e+000,0,,0,
1524111657.475,,0.000000e+000,3.499950e+001,-1.036457e-005,0.000000e+000,3,9.149683e-001,0.000000e+000,,,,,,,,,,,,,,32,1,4.000000e+000,0.000000e+000,0.000000e+000,0,,0,
1524111696.195,,0.000000e+000,3.500028e+001,-9.858005e-006,0.000000e+000,3,9.062482e-001,0.000000e+000,,,,,,,,,,,,,,32,1,4.000000e+000,1.560211e-003,0.000000e+000,0,,0,
1524111733.241,,0.000000e+000,3.499911e+001,-9.430988e-006,0.000000e+000,3,8.949134e-001,0.000000e+000,,,,,,,,,,,,,,32,1,4.000000e+000,7.820129e-004,0.000000e+000,0,,0,
1524111771.989,,0.000000e+000,3.499911e+001,-9.144629e-006,0.000000e+000,3,9.048088e-001,0.000000e+000,,,,,,,,,,,,,,32,1,4.000000e+000,7.820129e-004,0.000000e+000,0,,0,
1524111810.502,,0.000000e+000,3.499833e+001,-8.932362e-006,0.000000e+000,3,8.941957e-001,0.000000e+000,,,,,,,,,,,,,,32,1,4.000000e+000,7.781982e-004,0.000000e+000,0,,0,
1524111848.290,,0.000000e+000,3.499950e+001,-8.626243e-006,0.000000e+000,3,8.911723e-001,0.000000e+000,,,,,,,,,,,,,,32,1,4.000000e+000,0.000000e+000,0.000000e+000,0,,0,
1524111886.431,,0.000000e+000,3.499872e+001,-8.358721e-006,0.000000e+000,3,8.940195e-001,0.000000e+000,,,,,,,,,,,,,,32,1,4.000000e+000,1.560211e-003,0.000000e+000,0,,0,
1524111924.776,,0.000000e+000,3.499950e+001,-8.024968e-006,0.000000e+000,3,8.848878e-001,0.000000e+000,,,,,,,,,,,,,,32,1,4.000000e+000,0.000000e+000,0.000000e+000,0,,0,
1524111962.209,,0.000000e+000,3.499911e+001,-7.895640e-006,0.000000e+000,3,8.870019e-001,0.000000e+000,,,,,,,,,,,,,,32,1,4.000000e+000,7.820129e-004,0.000000e+000,0,,0,
1524112000.315,,0.000000e+000,3.500028e+001,-7.758048e-006,0.000000e+000,3,8.776439e-001,0.000000e+000,,,,,,,,,,,,,,32,1,4.000000e+000,1.560211e-003,0.000000e+000,0,,0,
1524112038.403,,0.000000e+000,3.499911e+001,-7.428083e-006,0.000000e+000,3,8.733507e-001,0.000000e+000,,,,,,,,,,,,,,32,1,4.000000e+000,7.820129e-004,0.000000e+000,0,,0,
1524112076.919,,0.000000e+000,3.499833e+001,-7.350348e-006,0.000000e+000,3,8.776150e-001,0.000000e+000,,,,,,,,,,,,,,32,1,4.000000e+000,2.349854e-003,0.000000e+000,0,,0,
1524112114.847,,0.000000e+000,3.499911e+001,-7.130338e-006,0.000000e+000,3,8.706988e-001,0.000000e+000,,,,,,,,,,,,,,32,1,4.000000e+000,7.820129e-004,0.000000e+000,0,,0,
1524112152.817,,0.000000e+000,3.499911e+001,-6.932337e-006,0.000000e+000,3,8.643174e-001,0.000000e+000,,,,,,,,,,,,,,32,1,4.000000e+000,7.820129e-004,0.000000e+000,0,,0,
1524112191.145,,0.000000e+000,3.499911e+001,-6.804752e-006,0.000000e+000,3,8.639050e-001,0.000000e+000,,,,,,,,,,,,,,32,1,4.000000e+000,7.820129e-004,0.000000e+000,0,,0,
1524112229.853,,0.000000e+000,3.499950e+001,-6.624811e-006,0.000000e+000,3,8.524630e-001,0.000000e+000,,,,,,,,,,,,,,32,1,4.000000e+000,0.000000e+000,0.000000e+000,0,,0,
1524112268.351,,0.000000e+000,3.499911e+001,-6.529932e-006,0.000000e+000,3,8.545065e-001,0.000000e+000,,,,,,,,,,,,,,32,1,4.000000e+000,7.820129e-004,0.000000e+000,0,,0,
1524112306.067,,0.000000e+000,3.499872e+001,-6.327089e-006,0.000000e+000,3,8.489970e-001,0.000000e+000,,,,,,,,,,,,,,32,1,4.000000e+000,1.560211e-003,0.000000e+000,0,,0,
1524112344.695,,0.000000e+000,3.499911e+001,-6.294300e-006,0.000000e+000,3,8.543406e-001,0.000000e+000,,,,,,,,,,,,,,32,1,4.000000e+000,7.820129e-004,0.000000e+000,0,,0,
1524112382.453,,0.000000e+000,3.499754e+001,-6.133863e-006,0.000000e+000,3,8.537829e-001,0.000000e+000,,,,,,,,,,,,,,32,1,4.000000e+000,3.910065e-003,0.000000e+000,0,,0,
1524112419.541,,0.000000e+000,3.500028e+001,-6.112356e-006,0.000000e+000,3,8.515983e-001,0.000000e+000,,,,,,,,,,,,,,32,1,4.000000e+000,3.120422e-003,0.000000e+000,0,,0,
1524112457.227,,0.000000e+000,3.499911e+001,-5.936365e-006,0.000000e+000,3,8.543084e-001,0.000000e+000,,,,,,,,,,,,,,32,1,4.000000e+000,7.820129e-004,0.000000e+000,0,,0,
1524112495.335,,0.000000e+000,3.499950e+001,-5.899902e-006,0.000000e+000,3,8.385298e-001,0.000000e+000,,,,,,,,,,,,,,32,1,4.000000e+000,0.000000e+000,0.000000e+000,0,,0,
1524112534.288,,0.000000e+000,3.499989e+001,-5.718270e-006,0.000000e+000,3,8.381376e-001,0.000000e+000,,,,,,,,,,,,,,32,1,4.000000e+000,7.781982e-004,0.000000e+000,0,,0,
1524112573.536,,0.000000e+000,3.499911e+001,-5.733012e-006,0.000000e+000,3,8.418239e-001,0.000000e+000,,,,,,,,,,,,,,32,1,4.000000e+000,7.820129e-004,0.000000e+000,0,,0,
1524112611.806,,0.000000e+000,3.499911e+001,-5.624343e-006,0.000000e+000,3,8.357836e-001,0.000000e+000,,,,,,,,,,,,,,32,1,4.000000e+000,7.820129e-004,0.000000e+000,0,,0,
1524112650.287,,0.000000e+000,3.500028e+001,-5.420146e-006,0.000000e+000,3,8.202651e-001,0.000000e+000,,,,,,,,,,,,,,32,1,4.000000e+000,1.560211e-003,0.000000e+000,0,,0,
1524112688.248,,0.000000e+000,3.499911e+001,-5.369653e-006,0.000000e+000,3,8.215453e-001,0.000000e+000,,,,,,,,,,,,,,32,1,4.000000e+000,2.338409e-003,0.000000e+000,0,,0,
1524112726.366,,0.000000e+000,3.499872e+001,-5.213734e-006,0.000000e+000,3,8.225706e-001,0.000000e+000,,,,,,,,,,,,,,32,1,4.000000e+000,1.560211e-003,0.000000e+000,0,,0,
1524112763.994,,0.000000e+000,3.499950e+001,-5.242751e-006,0.000000e+000,3,8.213372e-001,0.000000e+000,,,,,,,,,,,,,,32,1,4.000000e+000,0.000000e+000,0.000000e+000,0,,0,
1524112801.822,,0.000000e+000,3.499989e+001,-5.166036e-006,0.000000e+000,3,8.190965e-001,0.000000e+000,,,,,,,,,,,,,,32,1,4.000000e+000,7.781982e-004,0.000000e+000,0,,0,
1524112839.920,,0.000000e+000,3.499950e+001,-5.029357e-006,0.000000e+000,3,8.118844e-001,0.000000e+000,,,,,,,,,,,,,,32,1,4.000000e+000,1.560211e-003,0.000000e+000,0,,0,
1524112877.848,,0.000000e+000,3.499911e+001,-5.033107e-006,0.000000e+000,3,8.169428e-001,0.000000e+000,,,,,,,,,,,,,,32,1,4.000000e+000,7.820129e-004,0.000000e+000,0,,0,
1524112916.523,,0.000000e+000,3.499989e+001,-4.944332e-006,0.000000e+000,3,8.070900e-001,0.000000e+000,,,,,,,,,,,,,,32,1,4.000000e+000,7.781982e-004,0.000000e+000,0,,0,
1524112953.764,,0.000000e+000,3.499911e+001,-4.885821e-006,0.000000e+000,3,8.096926e-001,0.000000e+000,,,,,,,,,,,,,,32,1,4.000000e+000,7.820129e-004,0.000000e+000,0,,0,
1524112991.765,,0.000000e+000,3.499911e+001,-4.852757e-006,0.000000e+000,3,8.124572e-001,0.000000e+000,,,,,,,,,,,,,,32,1,4.000000e+000,7.820129e-004,0.000000e+000,0,,0,
1524113029.563,,0.000000e+000,3.499833e+001,-4.788592e-006,0.000000e+000,3,8.130747e-001,0.000000e+000,,,,,,,,,,,,,,32,1,4.000000e+000,7.781982e-004,0.000000e+000,0,,0,
1524113067.913,,0.000000e+000,3.499911e+001,-4.671155e-006,0.000000e+000,3,8.020865e-001,0.000000e+000,,,,,,,,,,,,,,32,1,4.000000e+000,2.338409e-003,0.000000e+000,0,,0,
1524113106.611,,0.000000e+000,3.499794e+001,-4.601315e-006,0.000000e+000,3,7.943599e-001,0.000000e+000,,,,,,,,,,,,,,32,1,4.000000e+000,0.000000e+000,0.000000e+000,0,,0,
1524113144.247,,0.000000e+000,3.499872e+001,-4.612414e-006,0.000000e+000,3,7.925600e-001,0.000000e+000,,,,,,,,,,,,,,32,1,4.000000e+000,1.560211e-003,0.000000e+000,0,,0,
1524113181.317,,0.000000e+000,3.499950e+001,-4.528160e-006,0.000000e+000,3,7.982028e-001,0.000000e+000,,,,,,,,,,,,,,32,1,4.000000e+000,0.000000e+000,0.000000e+000,0,,0,
1524113219.403,,0.000000e+000,3.499833e+001,-4.483956e-006,0.000000e+000,3,7.882465e-001,0.000000e+000,,,,,,,,,,,,,,32,1,4.000000e+000,2.349854e-003,0.000000e+000,0,,0,
1524113257.268,,0.000000e+000,3.499793e+001,-4.400048e-006,0.000000e+000,3,7.952226e-001,0.000000e+000,,,,,,,,,,,,,,32,1,4.000000e+000,3.131866e-003,0.000000e+000,0,,0,
1524113295.429,,0.000000e+000,3.500028e+001,-4.436017e-006,0.000000e+000,3,7.788569e-001,0.000000e+000,,,,,,,,,,,,,,32,1,4.000000e+000,1.560211e-003,0.000000e+000,0,,0,
1524113332.455,,0.000000e+000,3.500145e+001,-4.268749e-006,0.000000e+000,3,7.716925e-001,0.000000e+000,,,,,,,,,,,,,,32,1,4.000000e+000,7.781982e-004,0.000000e+000,0,,0,
1524113370.500,,0.000000e+000,3.499950e+001,-4.287443e-006,0.000000e+000,3,7.935275e-001,0.000000e+000,,,,,,,,,,,,,,32,1,4.000000e+000,0.000000e+000,0.000000e+000,0,,0,
1524113408.773,,0.000000e+000,3.499911e+001,-4.225925e-006,0.000000e+000,3,7.930152e-001,0.000000e+000,,,,,,,,,,,,,,32,1,4.000000e+000,7.820129e-004,0.000000e+000,0,,0,
1524113446.231,,0.000000e+000,3.499911e+001,-4.164409e-006,0.000000e+000,3,7.700592e-001,0.000000e+000,,,,,,,,,,,,,,32,1,4.000000e+000,7.820129e-004,0.000000e+000,0,,0,
1524113484.349,,0.000000e+000,3.499911e+001,-4.137988e-006,0.000000e+000,3,7.816009e-001,0.000000e+000,,,,,,,,,,,,,,32,1,4.000000e+000,7.820129e-004,0.000000e+000,0,,0,
1524113522.460,,0.000000e+000,3.499872e+001,-4.133318e-006,0.000000e+000,3,7.859795e-001,0.000000e+000,,,,,,,,,,,,,,32,1,4.000000e+000,0.000000e+000,0.000000e+000,0,,0,
1524113560.590,,0.000000e+000,3.499950e+001,-4.049272e-006,0.000000e+000,3,7.714039e-001,0.000000e+000,,,,,,,,,,,,,,32,1,4.000000e+000,0.000000e+000,0.000000e+000,0,,0,
1524113598.716,,0.000000e+000,3.499911e+001,-4.077463e-006,0.000000e+000,3,7.801294e-001,0.000000e+000,,,,,,,,,,,,,,32,1,4.000000e+000,7.820129e-004,0.000000e+000,0,,0,
1524113636.867,,0.000000e+000,3.499950e+001,-3.987127e-006,0.000000e+000,3,7.750508e-001,0.000000e+000,,,,,,,,,,,,,,32,1,4.000000e+000,1.560211e-003,0.000000e+000,0,,0,
1524113675.397,,0.000000e+000,3.499950e+001,-3.940519e-006,0.000000e+000,3,7.627042e-001,0.000000e+000,,,,,,,,,,,,,,32,1,4.000000e+000,0.000000e+000,0.000000e+000,0,,0,
1524113713.090,,0.000000e+000,3.499793e+001,-3.906243e-006,0.000000e+000,3,7.616243e-001,0.000000e+000,,,,,,,,,,,,,,32,1,4.000000e+000,1.567841e-003,0.000000e+000,0,,0,
1524113751.076,,0.000000e+000,3.499911e+001,-3.864987e-006,0.000000e+000,3,7.539547e-001,0.000000e+000,,,,,,,,,,,,,,32,1,4.000000e+000,7.820129e-004,0.000000e+000,0,,0,
1524113789.274,,0.000000e+000,3.499911e+001,-3.842987e-006,0.000000e+000,3,7.649714e-001,0.000000e+000,,,,,,,,,,,,,,32,1,4.000000e+000,2.338409e-003,0.000000e+000,0,,0,
1524113827.314,,0.000000e+000,3.499950e+001,-3.787617e-006,0.000000e+000,3,7.592662e-001,0.000000e+000,,,,,,,,,,,,,,32,1,4.000000e+000,0.000000e+000,0.000000e+000,0,,0,
1524113865.527,,0.000000e+000,3.499911e+001,-3.764196e-006,0.000000e+000,3,7.525783e-001,0.000000e+000,,,,,,,,,,,,,,32,1,4.000000e+000,7.820129e-004,0.000000e+000,0,,0,
1524113903.920,,0.000000e+000,3.499950e+001,-3.661764e-006,0.000000e+000,3,7.412662e-001,0.000000e+000,,,,,,,,,,,,,,32,1,4.000000e+000,1.560211e-003,0.000000e+000,0,,0,
1524113942.271,,0.000000e+000,3.499872e+001,-3.692820e-006,0.000000e+000,3,7.470341e-001,0.000000e+000,,,,,,,,,,,,,,32,1,4.000000e+000,1.560211e-003,0.000000e+000,0,,0,
1524113980.187,,0.000000e+000,3.499950e+001,-3.683876e-006,0.000000e+000,3,7.480407e-001,0.000000e+000,,,,,,,,,,,,,,32,1,4.000000e+000,0.000000e+000,0.000000e+000,0,,0,
1524114017.882,,0.000000e+000,3.499872e+001,-3.641942e-006,0.000000e+000,3,7.542191e-001,0.000000e+000,,,,,,,,,,,,,,32,1,4.000000e+000,0.000000e+000,0.000000e+000,0,,0,
1524114055.853,,0.000000e+000,3.499989e+001,-3.649849e-006,0.000000e+000,3,7.335550e-001,0.000000e+000,,,,,,,,,,,,,,32,1,4.000000e+000,7.781982e-004,0.000000e+000,0,,0,
1524114093.338,,0.000000e+000,3.499911e+001,-3.521354e-006,0.000000e+000,3,7.350600e-001,0.000000e+000,,,,,,,,,,,,,,32,1,4.000000e+000,2.338409e-003,0.000000e+000,0,,0,
1524114130.789,,0.000000e+000,3.499989e+001,-3.500767e-006,0.000000e+000,3,7.373999e-001,0.000000e+000,,,,,,,,,,,,,,32,1,4.000000e+000,7.781982e-004,0.000000e+000,0,,0,
1524114168.899,,0.000000e+000,3.499872e+001,-3.534921e-006,0.000000e+000,3,7.407712e-001,0.000000e+000,,,,,,,,,,,,,,32,1,4.000000e+000,0.000000e+000,0.000000e+000,0,,0,
1524114206.950,,0.000000e+000,3.499950e+001,-3.490601e-006,0.000000e+000,3,7.376580e-001,0.000000e+000,,,,,,,,,,,,,,32,1,4.000000e+000,0.000000e+000,0.000000e+000,0,,0,
1524114245.413,,0.000000e+000,3.499950e+001,-3.443635e-006,0.000000e+000,3,7.116128e-001,0.000000e+000,,,,,,,,,,,,,,32,1,4.000000e+000,1.560211e-003,0.000000e+000,0,,0,
1524114283.376,,0.000000e+000,3.500028e+001,-3.379813e-006,0.000000e+000,3,7.099919e-001,0.000000e+000,,,,,,,,,,,,,,32,1,4.000000e+000,1.560211e-003,0.000000e+000,0,,0,
1524114322.137,,0.000000e+000,3.499833e+001,-3.371346e-006,0.000000e+000,3,7.220173e-001,0.000000e+000,,,,,,,,,,,,,,32,1,4.000000e+000,2.349854e-003,0.000000e+000,0,,0,
1524114360.305,,0.000000e+000,3.499950e+001,-3.348368e-006,0.000000e+000,3,7.208892e-001,0.000000e+000,,,,,,,,,,,,,,32,1,4.000000e+000,1.560211e-003,0.000000e+000,0,,0,
1524114397.923,,0.000000e+000,3.499872e+001,-3.381294e-006,0.000000e+000,3,7.267890e-001,0.000000e+000,,,,,,,,,,,,,,32,1,4.000000e+000,1.560211e-003,0.000000e+000,0,,0,
1524114436.573,,0.000000e+000,3.499833e+001,-3.313477e-006,0.000000e+000,3,7.217277e-001,0.000000e+000,,,,,,,,,,,,,,32,1,4.000000e+000,7.781982e-004,0.000000e+000,0,,0,
1524114475.751,,0.000000e+000,3.499950e+001,-3.254335e-006,0.000000e+000,3,7.138501e-001,0.000000e+000,,,,,,,,,,,,,,32,1,4.000000e+000,1.560211e-003,0.000000e+000,0,,0,
1524114514.222,,0.000000e+000,3.499950e+001,-3.287870e-006,0.000000e+000,3,7.181275e-001,0.000000e+000,,,,,,,,,,,,,,32,1,4.000000e+000,0.000000e+000,0.000000e+000,0,,0,
1524114552.175,,0.000000e+000,3.499872e+001,-3.234595e-006,0.000000e+000,3,7.110528e-001,0.000000e+000,,,,,,,,,,,,,,32,1,4.000000e+000,1.560211e-003,0.000000e+000,0,,0,
1524114590.475,,0.000000e+000,3.499950e+001,-3.213288e-006,0.000000e+000,3,7.094104e-001,0.000000e+000,,,,,,,,,,,,,,32,1,4.000000e+000,0.000000e+000,0.000000e+000,0,,0,
1524114628.606,,0.000000e+000,3.499872e+001,-3.171097e-006,0.000000e+000,3,7.069841e-001,0.000000e+000,,,,,,,,,,,,,,32,1,4.000000e+000,0.000000e+000,0.000000e+000,0,,0,
1524114666.644,,0.000000e+000,3.500185e+001,-3.143295e-006,0.000000e+000,3,7.083802e-001,0.000000e+000,,,,,,,,,,,,,,32,1,4.000000e+000,4.688263e-003,0.000000e+000,0,,0,
1524114704.795,,0.000000e+000,3.499950e+001,-3.136952e-006,0.000000e+000,3,7.018892e-001,0.000000e+000,,,,,,,,,,,,,,32,1,4.000000e+000,0.000000e+000,0.000000e+000,0,,0,
1524114743.093,,0.000000e+000,3.499754e+001,-3.052672e-006,0.000000e+000,3,6.850971e-001,0.000000e+000,,,,,,,,,,,,,,32,1,4.000000e+000,7.896423e-004,0.000000e+000,0,,0,
1524114780.991,,0.000000e+000,3.499872e+001,-3.098401e-006,0.000000e+000,3,6.886541e-001,0.000000e+000,,,,,,,,,,,,,,32,1,4.000000e+000,0.000000e+000,0.000000e+000,0,,0,
1524114819.319,,0.000000e+000,3.499559e+001,-3.072042e-006,0.000000e+000,3,6.880642e-001,0.000000e+000,,,,,,,,,,,,,,32,1,4.000000e+000,4.699707e-003,0.000000e+000,0,,0,
1524114857.779,,0.000000e+000,3.499989e+001,-3.002763e-006,0.000000e+000,3,6.860996e-001,0.000000e+000,,,,,,,,,,,,,,32,1,4.000000e+000,7.781982e-004,0.000000e+000,0,,0,
1524114895.930,,0.000000e+000,3.499989e+001,-2.999895e-006,0.000000e+000,3,6.812552e-001,0.000000e+000,,,,,,,,,,,,,,32,1,4.000000e+000,7.781982e-004,0.000000e+000,0,,0,
1524114934.183,,0.000000e+000,3.499872e+001,-2.980691e-006,0.000000e+000,3,6.869110e-001,0.000000e+000,,,,,,,,,,,,,,32,1,4.000000e+000,1.560211e-003,0.000000e+000,0,,0,
1524114973.114,,0.000000e+000,3.499911e+001,-2.977345e-006,0.000000e+000,3,6.815798e-001,0.000000e+000,,,,,,,,,,,,,,32,1,4.000000e+000,7.820129e-004,0.000000e+000,0,,0,
1524115011.242,,0.000000e+000,3.499950e+001,-2.992324e-006,0.000000e+000,3,6.873508e-001,0.000000e+000,,,,,,,,,,,,,,32,1,4.000000e+000,3.120422e-003,0.000000e+000,0,,0,
1524115049.350,,0.000000e+000,3.499950e+001,-2.951174e-006,0.000000e+000,3,6.868234e-001,0.000000e+000,,,,,,,,,,,,,,32,1,4.000000e+000,1.560211e-003,0.000000e+000,0,,0,
1524115087.480,,0.000000e+000,3.499793e+001,-2.951862e-006,0.000000e+000,3,6.772304e-001,0.000000e+000,,,,,,,,,,,,,,32,1,4.000000e+000,1.567841e-003,0.000000e+000,0,,0,
1524115125.163,,0.000000e+000,3.499989e+001,-2.860801e-006,0.000000e+000,3,6.693417e-001,0.000000e+000,,,,,,,,,,,,,,32,1,4.000000e+000,7.781982e-004,0.000000e+000,0,,0,
1524115163.316,,0.000000e+000,3.499793e+001,-2.845635e-006,0.000000e+000,3,6.735189e-001,0.000000e+000,,,,,,,,,,,,,,32,1,4.000000e+000,1.567841e-003,0.000000e+000,0,,0,
1524115201.447,,0.000000e+000,3.499911e+001,-2.871670e-006,0.000000e+000,3,6.771109e-001,0.000000e+000,,,,,,,,,,,,,,32,1,4.000000e+000,7.820129e-004,0.000000e+000,0,,0,
1524115239.513,,0.000000e+000,3.499950e+001,-2.841262e-006,0.000000e+000,3,6.807163e-001,0.000000e+000,,,,,,,,,,,,,,32,1,4.000000e+000,0.000000e+000,0.000000e+000,0,,0,
1524115277.688,,0.000000e+000,3.499950e+001,-2.830960e-006,0.000000e+000,3,6.720093e-001,0.000000e+000,,,,,,,,,,,,,,32,1,4.000000e+000,0.000000e+000,0.000000e+000,0,,0,
1524115315.744,,0.000000e+000,3.499950e+001,-2.833265e-006,0.000000e+000,3,6.707845e-001,0.000000e+000,,,,,,,,,,,,,,32,1,4.000000e+000,1.560211e-003,0.000000e+000,0,,0,
1524115353.892,,0.000000e+000,3.499911e+001,-2.789941e-006,0.000000e+000,3,6.686456e-001,0.000000e+000,,,,,,,,,,,,,,32,1,4.000000e+000,7.820129e-004,0.000000e+000,0,,0,
1524115391.655,,0.000000e+000,3.499911e+001,-2.798248e-006,0.000000e+000,3,6.644488e-001,0.000000e+000,,,,,,,,,,,,,,32,1,4.000000e+000,7.820129e-004,0.000000e+000,0,,0,
1524115429.903,,0.000000e+000,3.499989e+001,-2.795809e-006,0.000000e+000,3,6.640997e-001,0.000000e+000,,,,,,,,,,,,,,32,1,4.000000e+000,7.781982e-004,0.000000e+000,0,,0,
1524115467.701,,0.000000e+000,3.499911e+001,-2.745056e-006,0.000000e+000,3,6.492196e-001,0.000000e+000,,,,,,,,,,,,,,32,1,4.000000e+000,7.820129e-004,0.000000e+000,0,,0,
1524115506.014,,0.000000e+000,3.499872e+001,-2.722720e-006,0.000000e+000,3,6.494214e-001,0.000000e+000,,,,,,,,,,,,,,32,1,4.000000e+000,0.000000e+000,0.000000e+000,0,,0,
1524115544.007,,0.000000e+000,3.499989e+001,-2.711076e-006,0.000000e+000,3,6.534802e-001,0.000000e+000,,,,,,,,,,,,,,32,1,4.000000e+000,7.781982e-004,0.000000e+000,0,,0,
1524115581.830,,0.000000e+000,3.499989e+001,-2.707548e-006,0.000000e+000,3,6.551356e-001,0.000000e+000,,,,,,,,,,,,,,32,1,4.000000e+000,7.781982e-004,0.000000e+000,0,,0,
1524115619.583,,0.000000e+000,3.499950e+001,-2.683091e-006,0.000000e+000,3,6.623335e-001,0.000000e+000,,,,,,,,,,,,,,32,1,4.000000e+000,0.000000e+000,0.000000e+000,0,,0,
1524115657.234,,0.000000e+000,3.499950e+001,-2.639582e-006,0.000000e+000,3,6.443011e-001,0.000000e+000,,,,,,,,,,,,,,32,1,4.000000e+000,0.000000e+000,0.000000e+000,0,,0,
1524115695.237,,0.000000e+000,3.499872e+001,-2.628157e-006,0.000000e+000,3,6.244234e-001,0.000000e+000,,,,,,,,,,,,,,32,1,4.000000e+000,1.560211e-003,0.000000e+000,0,,0,
1524115733.625,,0.000000e+000,3.499911e+001,-2.650670e-006,0.000000e+000,3,6.525635e-001,0.000000e+000,,,,,,,,,,,,,,32,1,4.000000e+000,7.820129e-004,0.000000e+000,0,,0,
1524115771.715,,0.000000e+000,3.499911e+001,-2.603492e-006,0.000000e+000,3,6.534421e-001,0.000000e+000,,,,,,,,,,,,,,32,1,4.000000e+000,7.820129e-004,0.000000e+000,0,,0,
1524115808.921,,0.000000e+000,3.499715e+001,-2.591646e-006,0.000000e+000,3,6.316316e-001,0.000000e+000,,,,,,,,,,,,,,32,1,4.000000e+000,4.692078e-003,0.000000e+000,0,,0,
1524115847.119,,0.000000e+000,3.500067e+001,-2.632298e-006,0.000000e+000,3,6.550400e-001,0.000000e+000,,,,,,,,,,,,,,32,1,4.000000e+000,7.820129e-004,0.000000e+000,0,,0,
1524115884.529,,0.000000e+000,3.499911e+001,-2.556295e-006,0.000000e+000,3,6.210330e-001,0.000000e+000,,,,,,,,,,,,,,32,1,4.000000e+000,7.820129e-004,0.000000e+000,0,,0,
1524115922.648,,0.000000e+000,3.499872e+001,-2.524144e-006,0.000000e+000,3,6.260762e-001,0.000000e+000,,,,,,,,,,,,,,32,1,4.000000e+000,1.560211e-003,0.000000e+000,0,,0,
1524115961.771,,0.000000e+000,3.499950e+001,-2.527198e-006,0.000000e+000,3,6.327770e-001,0.000000e+000,,,,,,,,,,,,,,32,1,4.000000e+000,0.000000e+000,0.000000e+000,0,,0,
1524115999.319,,0.000000e+000,3.499989e+001,-2.530581e-006,0.000000e+000,3,6.285327e-001,0.000000e+000,,,,,,,,,,,,,,32,1,4.000000e+000,7.781982e-004,0.000000e+000,0,,0,
1524116037.199,,0.000000e+000,3.499911e+001,-2.534123e-006,0.000000e+000,3,6.358960e-001,0.000000e+000,,,,,,,,,,,,,,32,1,4.000000e+000,7.820129e-004,0.000000e+000,0,,0,
1524116075.075,,0.000000e+000,3.499872e+001,-2.514111e-006,0.000000e+000,3,6.272265e-001,0.000000e+000,,,,,,,,,,,,,,32,1,4.000000e+000,0.000000e+000,0.000000e+000,0,,0,
1524116112.918,,0.000000e+000,3.500028e+001,-2.501140e-006,0.000000e+000,3,6.118742e-001,0.000000e+000,,,,,,,,,,,,,,32,1,4.000000e+000,1.560211e-003,0.000000e+000,0,,0,
1524116151.866,,0.000000e+000,3.499911e+001,-2.509894e-006,0.000000e+000,3,6.369634e-001,0.000000e+000,,,,,,,,,,,,,,32,1,4.000000e+000,7.820129e-004,0.000000e+000,0,,0,
1524116190.066,,0.000000e+000,3.499872e+001,-2.470762e-006,0.000000e+000,3,6.186378e-001,0.000000e+000,,,,,,,,,,,,,,32,1,4.000000e+000,1.560211e-003,0.000000e+000,0,,0,
1524116228.304,,0.000000e+000,3.499989e+001,-2.455637e-006,0.000000e+000,3,6.210065e-001,0.000000e+000,,,,,,,,,,,,,,32,1,4.000000e+000,7.781982e-004,0.000000e+000,0,,0,
1524116266.408,,0.000000e+000,3.499911e+001,-2.481398e-006,0.000000e+000,3,6.320015e-001,0.000000e+000,,,,,,,,,,,,,,32,1,4.000000e+000,7.820129e-004,0.000000e+000,0,,0,
1524116304.538,,0.000000e+000,3.499911e+001,-2.458059e-006,0.000000e+000,3,6.219702e-001,0.000000e+000,,,,,,,,,,,,,,32,1,4.000000e+000,7.820129e-004,0.000000e+000,0,,0,
1524116342.601,,0.000000e+000,3.499989e+001,-2.416599e-006,0.000000e+000,3,6.162859e-001,0.000000e+000,,,,,,,,,,,,,,32,1,4.000000e+000,7.781982e-004,0.000000e+000,0,,0,
1524116380.654,,0.000000e+000,3.499989e+001,-2.414151e-006,0.000000e+000,3,6.047419e-001,0.000000e+000,,,,,,,,,,,,,,32,1,4.000000e+000,7.781982e-004,0.000000e+000,0,,0,
1524116419.012,,0.000000e+000,3.499989e+001,-2.501966e-006,0.000000e+000,3,6.187798e-001,0.000000e+000,,,,,,,,,,,,,,32,1,4.000000e+000,7.781982e-004,0.000000e+000,0,,0,
1524116457.310,,0.000000e+000,3.499911e+001,-2.416709e-006,0.000000e+000,3,6.234776e-001,0.000000e+000,,,,,,,,,,,,,,32,1,4.000000e+000,7.820129e-004,0.000000e+000,0,,0,
1524116495.858,,0.000000e+000,3.499911e+001,-2.398989e-006,0.000000e+000,3,5.970836e-001,0.000000e+000,,,,,,,,,,,,,,32,1,4.000000e+000,3.910065e-003,0.000000e+000,0,,0,
1524116533.962,,0.000000e+000,3.499989e+001,-2.362626e-006,0.000000e+000,3,6.039472e-001,0.000000e+000,,,,,,,,,,,,,,32,1,4.000000e+000,2.342224e-003,0.000000e+000,0,,0,
1524116571.795,,0.000000e+000,3.499833e+001,-2.351312e-006,0.000000e+000,3,6.048486e-001,0.000000e+000,,,,,,,,,,,,,,32,1,4.000000e+000,2.349854e-003,0.000000e+000,0,,0,
1524116609.303,,0.000000e+000,3.500067e+001,-2.403622e-006,0.000000e+000,3,6.119953e-001,0.000000e+000,,,,,,,,,,,,,,32,1,4.000000e+000,7.820129e-004,0.000000e+000,0,,0,
1524116647.286,,0.000000e+000,3.499950e+001,-2.351413e-006,0.000000e+000,3,6.038236e-001,0.000000e+000,,,,,,,,,,,,,,32,1,4.000000e+000,1.560211e-003,0.000000e+000,0,,0,
1524116685.214,,0.000000e+000,3.500028e+001,-2.299462e-006,0.000000e+000,3,5.726433e-001,0.000000e+000,,,,,,,,,,,,,,32,1,4.000000e+000,3.120422e-003,0.000000e+000,0,,0,
1524116722.822,,0.000000e+000,3.499872e+001,-2.342935e-006,0.000000e+000,3,5.975631e-001,0.000000e+000,,,,,,,,,,,,,,32,1,4.000000e+000,1.560211e-003,0.000000e+000,0,,0,
1524116761.402,,0.000000e+000,3.499872e+001,-2.317174e-006,0.000000e+000,3,5.962047e-001,0.000000e+000,,,,,,,,,,,,,,32,1,4.000000e+000,1.560211e-003,0.000000e+000,0,,0,
1524116799.778,,0.000000e+000,3.499989e+001,-2.265601e-006,0.000000e+000,3,5.805789e-001,0.000000e+000,,,,,,,,,,,,,,32,1,4.000000e+000,7.781982e-004,0.000000e+000,0,,0,
1524116837.196,,0.000000e+000,3.499872e+001,-2.270579e-006,0.000000e+000,3,5.883008e-001,0.000000e+000,,,,,,,,,,,,,,32,1,4.000000e+000,0.000000e+000,0.000000e+000,0,,0,
1524116875.304,,0.000000e+000,3.499872e+001,-2.287009e-006,0.000000e+000,3,6.031461e-001,0.000000e+000,,,,,,,,,,,,,,32,1,4.000000e+000,0.000000e+000,0.000000e+000,0,,0,
1524116913.340,,0.000000e+000,3.499872e+001,-2.338741e-006,0.000000e+000,3,6.031355e-001,0.000000e+000,,,,,,,,,,,,,,32,1,4.000000e+000,0.000000e+000,0.000000e+000,0,,0,
1524116951.980,,0.000000e+000,3.499911e+001,-2.285995e-006,0.000000e+000,3,5.802067e-001,0.000000e+000,,,,,,,,,,,,,,32,1,4.000000e+000,7.820129e-004,0.000000e+000,0,,0,
1524116990.358,,0.000000e+000,3.499950e+001,-2.258108e-006,0.000000e+000,3,5.693085e-001,0.000000e+000,,,,,,,,,,,,,,32,1,4.000000e+000,0.000000e+000,0.000000e+000,0,,0,
1524117028.466,,0.000000e+000,3.499833e+001,-2.211732e-006,0.000000e+000,3,5.704920e-001,0.000000e+000,,,,,,,,,,,,,,32,1,4.000000e+000,7.781982e-004,0.000000e+000,0,,0,
1524117066.547,,0.000000e+000,3.499872e+001,-2.213056e-006,0.000000e+000,3,5.784986e-001,0.000000e+000,,,,,,,,,,,,,,32,1,4.000000e+000,0.000000e+000,0.000000e+000,0,,0,
1524117104.355,,0.000000e+000,3.499871e+001,-2.227835e-006,0.000000e+000,3,5.750280e-001,0.000000e+000,,,,,,,,,,,,,,32,1,4.000000e+000,3.128052e-003,0.000000e+000,0,,0,
1524117141.783,,0.000000e+000,3.499950e+001,-2.223670e-006,0.000000e+000,3,5.780587e-001,0.000000e+000,,,,,,,,,,,,,,32,1,4.000000e+000,0.000000e+000,0.000000e+000,0,,0,
1524117180.516,,0.000000e+000,3.499871e+001,-2.217828e-006,0.000000e+000,3,5.762899e-001,0.000000e+000,,,,,,,,,,,,,,32,1,4.000000e+000,4.692078e-003,0.000000e+000,0,,0,
1524117218.939,,0.000000e+000,3.500028e+001,-2.198801e-006,0.000000e+000,3,5.590824e-001,0.000000e+000,,,,,,,,,,,,,,32,1,4.000000e+000,1.560211e-003,0.000000e+000,0,,0,
1524117256.510,,0.000000e+000,3.500185e+001,-2.202403e-006,0.000000e+000,3,5.765483e-001,0.000000e+000,,,,,,,,,,,,,,32,1,4.000000e+000,4.688263e-003,0.000000e+000,0,,0,
1524117294.473,,0.000000e+000,3.499911e+001,-2.214286e-006,0.000000e+000,3,5.947622e-001,0.000000e+000,,,,,,,,,,,,,,32,1,4.000000e+000,7.820129e-004,0.000000e+000,0,,0,
1524117331.991,,0.000000e+000,3.499989e+001,-2.242558e-006,0.000000e+000,3,5.693297e-001,0.000000e+000,,,,,,,,,,,,,,32,1,4.000000e+000,7.781982e-004,0.000000e+000,0,,0,
1524117370.169,,0.000000e+000,3.499989e+001,-2.138456e-006,0.000000e+000,3,5.648056e-001,0.000000e+000,,,,,,,,,,,,,,32,1,4.000000e+000,7.781982e-004,0.000000e+000,0,,0,
1524117408.644,,0.000000e+000,3.499872e+001,-2.178081e-006,0.000000e+000,3,5.537082e-001,0.000000e+000,,,,,,,,,,,,,,32,1,4.000000e+000,1.560211e-003,0.000000e+000,0,,0,
1524117446.585,,0.000000e+000,3.499754e+001,-2.193395e-006,0.000000e+000,3,5.832496e-001,0.000000e+000,,,,,,,,,,,,,,32,1,4.000000e+000,7.896423e-004,0.000000e+000,0,,0,
1524117484.428,,0.000000e+000,3.499911e+001,-2.157102e-006,0.000000e+000,3,5.559961e-001,0.000000e+000,,,,,,,,,,,,,,32,1,4.000000e+000,7.820129e-004,0.000000e+000,0,,0,
1524117522.176,,0.000000e+000,3.499872e+001,-2.152709e-006,0.000000e+000,3,5.605865e-001,0.000000e+000,,,,,,,,,,,,,,32,1,4.000000e+000,0.000000e+000,0.000000e+000,0,,0,
1524117560.324,,0.000000e+000,3.499911e+001,-2.179209e-006,0.000000e+000,3,5.820284e-001,0.000000e+000,,,,,,,,,,,,,,32,1,4.000000e+000,7.820129e-004,0.000000e+000,0,,0,
1524117598.220,,0.000000e+000,3.499989e+001,-2.145664e-006,0.000000e+000,3,5.663158e-001,0.000000e+000,,,,,,,,,,,,,,32,1,4.000000e+000,7.781982e-004,0.000000e+000,0,,0,
1524117636.385,,0.000000e+000,3.499989e+001,-2.123953e-006,0.000000e+000,3,5.569897e-001,0.000000e+000,,,,,,,,,,,,,,32,1,4.000000e+000,7.781982e-004,0.000000e+000,0,,0,
1524117674.456,,0.000000e+000,3.499911e+001,-2.137993e-006,0.000000e+000,3,5.692661e-001,0.000000e+000,,,,,,,,,,,,,,32,1,4.000000e+000,7.820129e-004,0.000000e+000,0,,0,
1524117712.616,,0.000000e+000,3.499833e+001,-2.099908e-006,0.000000e+000,3,5.569966e-001,0.000000e+000,,,,,,,,,,,,,,32,1,4.000000e+000,7.781982e-004,0.000000e+000,0,,0,
1524117750.684,,0.000000e+000,3.499950e+001,-2.079147e-006,0.000000e+000,3,5.549834e-001,0.000000e+000,,,,,,,,,,,,,,32,1,4.000000e+000,1.560211e-003,0.000000e+000,0,,0,
1524117789.895,,0.000000e+000,3.499833e+001,-2.030505e-006,0.000000e+000,3,5.340457e-001,0.000000e+000,,,,,,,,,,,,,,32,1,4.000000e+000,7.781982e-004,0.000000e+000,0,,0,
1524117827.928,,0.000000e+000,3.500028e+001,-2.057420e-006,0.000000e+000,3,5.229674e-001,0.000000e+000,,,,,,,,,,,,,,32,1,4.000000e+000,1.560211e-003,0.000000e+000,0,,0,
1524117865.254,,0.000000e+000,3.499871e+001,-2.106729e-006,0.000000e+000,3,5.775571e-001,0.000000e+000,,,,,,,,,,,,,,32,1,4.000000e+000,4.692078e-003,0.000000e+000,0,,0,
1524117903.459,,0.000000e+000,3.499872e+001,-2.076567e-006,0.000000e+000,3,5.631083e-001,0.000000e+000,,,,,,,,,,,,,,32,1,4.000000e+000,0.000000e+000,0.000000e+000,0,,0,
1524117941.527,,0.000000e+000,3.499911e+001,-2.061367e-006,0.000000e+000,3,5.431313e-001,0.000000e+000,,,,,,,,,,,,,,32,1,4.000000e+000,7.820129e-004,0.000000e+000,0,,0,
1524117979.203,,0.000000e+000,3.499911e+001,-2.055978e-006,0.000000e+000,3,5.497612e-001,0.000000e+000,,,,,,,,,,,,,,32,1,4.000000e+000,7.820129e-004,0.000000e+000,0,,0,
1524118017.796,,0.000000e+000,3.499872e+001,-2.011499e-006,0.000000e+000,3,5.319309e-001,0.000000e+000,,,,,,,,,,,,,,32,1,4.000000e+000,0.000000e+000,0.000000e+000,0,,0,
1524118055.899,,0.000000e+000,3.499872e+001,-2.042112e-006,0.000000e+000,3,5.426178e-001,0.000000e+000,,,,,,,,,,,,,,32,1,4.000000e+000,0.000000e+000,0.000000e+000,0,,0,
1524118094.272,,0.000000e+000,3.499989e+001,-2.009692e-006,0.000000e+000,3,5.337960e-001,0.000000e+000,,,,,,,,,,,,,,32,1,4.000000e+000,7.781982e-004,0.000000e+000,0,,0,
1524118132.055,,0.000000e+000,3.499871e+001,-1.994433e-006,0.000000e+000,3,5.206266e-001,0.000000e+000,,,,,,,,,,,,,,32,1,4.000000e+000,3.128052e-003,0.000000e+000,0,,0,
1524118170.103,,0.000000e+000,3.499911e+001,-1.967834e-006,0.000000e+000,3,5.273098e-001,0.000000e+000,,,,,,,,,,,,,,32,1,4.000000e+000,7.820129e-004,0.000000e+000,0,,0,
1524118208.731,,0.000000e+000,3.499911e+001,-1.993783e-006,0.000000e+000,3,5.311000e-001,0.000000e+000,,,,,,,,,,,,,,32,1,4.000000e+000,2.338409e-003,0.000000e+000,0,,0,
1524118246.604,,0.000000e+000,3.499989e+001,-1.985445e-006,0.000000e+000,3,5.179887e-001,0.000000e+000,,,,,,,,,,,,,,32,1,4.000000e+000,2.342224e-003,0.000000e+000,0,,0,
1524118284.477,,0.000000e+000,3.499950e+001,-2.008676e-006,0.000000e+000,3,5.364048e-001,0.000000e+000,,,,,,,,,,,,,,32,1,4.000000e+000,0.000000e+000,0.000000e+000,0,,0,
1524118321.703,,0.000000e+000,3.499911e+001,-1.966117e-006,0.000000e+000,3,5.146286e-001,0.000000e+000,,,,,,,,,,,,,,32,1,4.000000e+000,7.820129e-004,0.000000e+000,0,,0,
1524118359.613,,0.000000e+000,3.499872e+001,-1.956345e-006,0.000000e+000,3,5.253452e-001,0.000000e+000,,,,,,,,,,,,,,32,1,4.000000e+000,0.000000e+000,0.000000e+000,0,,0,
1524118397.779,,0.000000e+000,3.499911e+001,-1.944811e-006,0.000000e+000,3,5.214061e-001,0.000000e+000,,,,,,,,,,,,,,32,1,4.000000e+000,7.820129e-004,0.000000e+000,0,,0,
1524118435.862,,0.000000e+000,3.499989e+001,-1.949055e-006,0.000000e+000,3,5.185128e-001,0.000000e+000,,,,,,,,,,,,,,32,1,4.000000e+000,7.781982e-004,0.000000e+000,0,,0,
1524118474.125,,0.000000e+000,3.499989e+001,-1.940039e-006,0.000000e+000,3,5.309197e-001,0.000000e+000,,,,,,,,,,,,,,32,1,4.000000e+000,7.781982e-004,0.000000e+000,0,,0,
1524118512.146,,0.000000e+000,3.499872e+001,-1.961122e-006,0.000000e+000,3,5.290709e-001,0.000000e+000,,,,,,,,,,,,,,32,1,4.000000e+000,0.000000e+000,0.000000e+000,0,,0,
1524118551.019,,0.000000e+000,3.499833e+001,-1.947939e-006,0.000000e+000,3,5.212592e-001,0.000000e+000,,,,,,,,,,,,,,32,1,4.000000e+000,7.781982e-004,0.000000e+000,0,,0,
1524118589.092,,0.000000e+000,3.499950e+001,-1.919166e-006,0.000000e+000,3,5.191103e-001,0.000000e+000,,,,,,,,,,,,,,32,1,4.000000e+000,0.000000e+000,0.000000e+000,0,,0,
1524118627.530,,0.000000e+000,3.499989e+001,-1.955236e-006,0.000000e+000,3,5.282707e-001,0.000000e+000,,,,,,,,,,,,,,32,1,4.000000e+000,7.781982e-004,0.000000e+000,0,,0,
1524118664.980,,0.000000e+000,3.499911e+001,-1.915014e-006,0.000000e+000,3,5.142326e-001,0.000000e+000,,,,,,,,,,,,,,32,1,4.000000e+000,7.820129e-004,0.000000e+000,0,,0,
1524118703.176,,0.000000e+000,3.499872e+001,-1.902705e-006,0.000000e+000,3,5.076767e-001,0.000000e+000,,,,,,,,,,,,,,32,1,4.000000e+000,1.560211e-003,0.000000e+000,0,,0,
1524118740.624,,0.000000e+000,3.499872e+001,-1.937565e-006,0.000000e+000,3,5.199516e-001,0.000000e+000,,,,,,,,,,,,,,32,1,4.000000e+000,1.560211e-003,0.000000e+000,0,,0,
1524118778.764,,0.000000e+000,3.499911e+001,-1.878005e-006,0.000000e+000,3,5.095751e-001,0.000000e+000,,,,,,,,,,,,,,32,1,4.000000e+000,7.820129e-004,0.000000e+000,0,,0,
1524118816.878,,0.000000e+000,3.499911e+001,-1.841315e-006,0.000000e+000,3,4.746270e-001,0.000000e+000,,,,,,,,,,,,,,32,1,4.000000e+000,7.820129e-004,0.000000e+000,0,,0,
1524118855.438,,0.000000e+000,3.499833e+001,-1.912161e-006,0.000000e+000,3,5.116112e-001,0.000000e+000,,,,,,,,,,,,,,32,1,4.000000e+000,7.781982e-004,0.000000e+000,0,,0,
1524118893.136,,0.000000e+000,3.499950e+001,-1.892016e-006,0.000000e+000,3,5.176859e-001,0.000000e+000,,,,,,,,,,,,,,32,1,4.000000e+000,0.000000e+000,0.000000e+000,0,,0,
1524118931.247,,0.000000e+000,3.499950e+001,-1.895475e-006,0.000000e+000,3,5.048462e-001,0.000000e+000,,,,,,,,,,,,,,32,1,4.000000e+000,0.000000e+000,0.000000e+000,0,,0,
1524118969.340,,0.000000e+000,3.499833e+001,-1.860850e-006,0.000000e+000,3,5.084773e-001,0.000000e+000,,,,,,,,,,,,,,32,1,4.000000e+000,7.781982e-004,0.000000e+000,0,,0,
1524119007.470,,0.000000e+000,3.499911e+001,-1.840453e-006,0.000000e+000,3,4.970732e-001,0.000000e+000,,,,,,,,,,,,,,32,1,4.000000e+000,7.820129e-004,0.000000e+000,0,,0,
1524119046.008,,0.000000e+000,3.499833e+001,-1.838901e-006,0.000000e+000,3,4.697309e-001,0.000000e+000,,,,,,,,,,,,,,32,1,4.000000e+000,7.781982e-004,0.000000e+000,0,,0,
1524119083.906,,0.000000e+000,3.499911e+001,-1.850544e-006,0.000000e+000,3,5.083278e-001,0.000000e+000,,,,,,,,,,,,,,32,1,4.000000e+000,7.820129e-004,0.000000e+000,0,,0,
1524119122.052,,0.000000e+000,3.499833e+001,-1.855952e-006,0.000000e+000,3,4.925677e-001,0.000000e+000,,,,,,,,,,,,,,32,1,4.000000e+000,2.349854e-003,0.000000e+000,0,,0,
1524119159.772,,0.000000e+000,3.499911e+001,-1.799900e-006,0.000000e+000,3,4.584952e-001,0.000000e+000,,,,,,,,,,,,,,32,1,4.000000e+000,2.338409e-003,0.000000e+000,0,,0,
1524119197.496,,0.000000e+000,3.499911e+001,-1.813688e-006,0.000000e+000,3,4.944458e-001,0.000000e+000,,,,,,,,,,,,,,32,1,4.000000e+000,7.820129e-004,0.000000e+000,0,,0,
1524119235.281,,0.000000e+000,3.499950e+001,-1.791265e-006,0.000000e+000,3,4.778741e-001,0.000000e+000,,,,,,,,,,,,,,32,1,4.000000e+000,0.000000e+000,0.000000e+000,0,,0,
1524119273.769,,0.000000e+000,3.499950e+001,-1.838015e-006,0.000000e+000,3,4.957504e-001,0.000000e+000,,,,,,,,,,,,,,32,1,4.000000e+000,0.000000e+000,0.000000e+000,0,,0,
1524119311.442,,0.000000e+000,3.499950e+001,-1.817162e-006,0.000000e+000,3,4.918759e-001,0.000000e+000,,,,,,,,,,,,,,32,1,4.000000e+000,0.000000e+000,0.000000e+000,0,,0,
1524119349.495,,0.000000e+000,3.500106e+001,-1.818344e-006,0.000000e+000,3,4.754693e-001,0.000000e+000,,,,,,,,,,,,,,32,1,4.000000e+000,3.128052e-003,0.000000e+000,0,,0,
1524119387.133,,0.000000e+000,3.499872e+001,-1.784914e-006,0.000000e+000,3,4.850721e-001,0.000000e+000,,,,,,,,,,,,,,32,1,4.000000e+000,0.000000e+000,0.000000e+000,0,,0,
1524119425.201,,0.000000e+000,3.499989e+001,-1.824091e-006,0.000000e+000,3,5.036979e-001,0.000000e+000,,,,,,,,,,,,,,32,1,4.000000e+000,7.781982e-004,0.000000e+000,0,,0,
1524119463.312,,0.000000e+000,3.499950e+001,-1.790065e-006,0.000000e+000,3,4.867269e-001,0.000000e+000,,,,,,,,,,,,,,32,1,4.000000e+000,0.000000e+000,0.000000e+000,0,,0,
1524119500.990,,0.000000e+000,3.499950e+001,-1.810424e-006,0.000000e+000,3,4.938081e-001,0.000000e+000,,,,,,,,,,,,,,32,1,4.000000e+000,0.000000e+000,0.000000e+000,0,,0,
1524119539.141,,0.000000e+000,3.499911e+001,-1.825663e-006,0.000000e+000,3,4.985393e-001,0.000000e+000,,,,,,,,,,,,,,32,1,4.000000e+000,7.820129e-004,0.000000e+000,0,,0,
1524119577.696,,0.000000e+000,3.499950e+001,-1.775174e-006,0.000000e+000,3,4.798653e-001,0.000000e+000,,,,,,,,,,,,,,32,1,4.000000e+000,0.000000e+000,0.000000e+000,0,,0,
1524119615.274,,0.000000e+000,3.499989e+001,-1.760872e-006,0.000000e+000,3,4.691114e-001,0.000000e+000,,,,,,,,,,,,,,32,1,4.000000e+000,7.781982e-004,0.000000e+000,0,,0,
1524119653.762,,0.000000e+000,3.499989e+001,-1.748994e-006,0.000000e+000,3,4.409053e-001,0.000000e+000,,,,,,,,,,,,,,32,1,4.000000e+000,7.781982e-004,0.000000e+000,0,,0,
1524119691.875,,0.000000e+000,3.499950e+001,-1.732673e-006,0.000000e+000,3,4.439514e-001,0.000000e+000,,,,,,,,,,,,,,32,1,4.000000e+000,0.000000e+000,0.000000e+000,0,,0,
1524119729.658,,0.000000e+000,3.499950e+001,-1.762892e-006,0.000000e+000,3,4.646060e-001,0.000000e+000,,,,,,,,,,,,,,32,1,4.000000e+000,0.000000e+000,0.000000e+000,0,,0,
1524119766.891,,0.000000e+000,3.499715e+001,-1.722468e-006,0.000000e+000,3,4.474051e-001,0.000000e+000,,,,,,,,,,,,,,32,1,4.000000e+000,1.571655e-003,0.000000e+000,0,,0,
1524119805.592,,0.000000e+000,3.499872e+001,-1.703578e-006,0.000000e+000,3,4.549004e-001,0.000000e+000,,,,,,,,,,,,,,32,1,4.000000e+000,0.000000e+000,0.000000e+000,0,,0,
1524119843.763,,0.000000e+000,3.499754e+001,-1.699233e-006,0.000000e+000,3,4.348285e-001,0.000000e+000,,,,,,,,,,,,,,32,1,4.000000e+000,7.030487e-003,0.000000e+000,0,,0,
1524119881.081,,0.000000e+000,3.499872e+001,-1.755929e-006,0.000000e+000,3,4.563784e-001,0.000000e+000,,,,,,,,,,,,,,32,1,4.000000e+000,1.560211e-003,0.000000e+000,0,,0,
1524119919.449,,0.000000e+000,3.499950e+001,-1.728613e-006,0.000000e+000,3,4.579577e-001,0.000000e+000,,,,,,,,,,,,,,32,1,4.000000e+000,0.000000e+000,0.000000e+000,0,,0,
1524119957.592,,0.000000e+000,3.499911e+001,-1.706668e-006,0.000000e+000,3,4.430343e-001,0.000000e+000,,,,,,,,,,,,,,32,1,4.000000e+000,7.820129e-004,0.000000e+000,0,,0,
1524119995.532,,0.000000e+000,3.499794e+001,-1.688744e-006,0.000000e+000,3,4.335551e-001,0.000000e+000,,,,,,,,,,,,,,32,1,4.000000e+000,0.000000e+000,0.000000e+000,0,,0,
1524120033.700,,0.000000e+000,3.499911e+001,-1.735422e-006,0.000000e+000,3,4.699177e-001,0.000000e+000,,,,,,,,,,,,,,32,1,4.000000e+000,7.820129e-004,0.000000e+000,0,,0,
1524120071.846,,0.000000e+000,3.499911e+001,-1.711945e-006,0.000000e+000,3,4.415911e-001,0.000000e+000,,,,,,,,,,,,,,32,1,4.000000e+000,7.820129e-004,0.000000e+000,0,,0,
1524120109.979,,0.000000e+000,3.499911e+001,-1.685142e-006,0.000000e+000,3,4.485930e-001,0.000000e+000,,,,,,,,,,,,,,32,1,4.000000e+000,2.338409e-003,0.000000e+000,0,,0,
1524120148.072,,0.000000e+000,3.499911e+001,-1.708872e-006,0.000000e+000,3,4.286853e-001,0.000000e+000,,,,,,,,,,,,,,32,1,4.000000e+000,7.820129e-004,0.000000e+000,0,,0,
1524120186.083,,0.000000e+000,3.499754e+001,-1.717150e-006,0.000000e+000,3,4.549788e-001,0.000000e+000,,,,,,,,,,,,,,32,1,4.000000e+000,2.349854e-003,0.000000e+000,0,,0,
1524120223.656,,0.000000e+000,3.499598e+001,-1.662138e-006,0.000000e+000,3,4.167673e-001,0.000000e+000,,,,,,,,,,,,,,32,1,4.000000e+000,8.598328e-003,0.000000e+000,0,,0,
1524120261.901,,0.000000e+000,3.499872e+001,-1.708449e-006,0.000000e+000,3,4.457799e-001,0.000000e+000,,,,,,,,,,,,,,32,1,4.000000e+000,1.560211e-003,0.000000e+000,0,,0,
1524120299.777,,0.000000e+000,3.499950e+001,-1.683600e-006,0.000000e+000,3,4.349535e-001,0.000000e+000,,,,,,,,,,,,,,32,1,4.000000e+000,0.000000e+000,0.000000e+000,0,,0,
1524120338.455,,0.000000e+000,3.499950e+001,-1.703762e-006,0.000000e+000,3,4.521661e-001,0.000000e+000,,,,,,,,,,,,,,32,1,4.000000e+000,0.000000e+000,0.000000e+000,0,,0,
1524120376.110,,0.000000e+000,3.499989e+001,-1.626743e-006,0.000000e+000,3,4.270191e-001,0.000000e+000,,,,,,,,,,,,,,32,1,4.000000e+000,7.781982e-004,0.000000e+000,0,,0,
1524120414.108,,0.000000e+000,3.499950e+001,-1.651660e-006,0.000000e+000,3,4.414304e-001,0.000000e+000,,,,,,,,,,,,,,32,1,4.000000e+000,1.560211e-003,0.000000e+000,0,,0,
1524120453.764,,0.000000e+000,3.499833e+001,-1.659536e-006,0.000000e+000,3,4.367135e-001,0.000000e+000,,,,,,,,,,,,,,32,1,4.000000e+000,7.781982e-004,0.000000e+000,0,,0,
1524120491.425,,0.000000e+000,3.499911e+001,-1.685903e-006,0.000000e+000,3,4.586231e-001,0.000000e+000,,,,,,,,,,,,,,32,1,4.000000e+000,7.820129e-004,0.000000e+000,0,,0,
1524120529.288,,0.000000e+000,3.499833e+001,-1.699718e-006,0.000000e+000,3,4.698825e-001,0.000000e+000,,,,,,,,,,,,,,32,1,4.000000e+000,7.781982e-004,0.000000e+000,0,,0,
1524120566.456,,0.000000e+000,3.499872e+001,-1.632241e-006,0.000000e+000,3,4.239826e-001,0.000000e+000,,,,,,,,,,,,,,32,1,4.000000e+000,0.000000e+000,0.000000e+000,0,,0,
1524120604.576,,0.000000e+000,3.499872e+001,-1.600573e-006,0.000000e+000,3,4.178936e-001,0.000000e+000,,,,,,,,,,,,,,32,1,4.000000e+000,0.000000e+000,0.000000e+000,0,,0,
1524120642.817,,0.000000e+000,3.499950e+001,-1.734249e-006,0.000000e+000,3,4.684837e-001,0.000000e+000,,,,,,,,,,,,,,32,1,4.000000e+000,0.000000e+000,0.000000e+000,0,,0,
1524120680.717,,0.000000e+000,3.499989e+001,-1.692707e-006,0.000000e+000,3,4.674866e-001,0.000000e+000,,,,,,,,,,,,,,32,1,4.000000e+000,7.781982e-004,0.000000e+000,0,,0,
1524120718.840,,0.000000e+000,3.499950e+001,-1.705051e-006,0.000000e+000,3,4.474313e-001,0.000000e+000,,,,,,,,,,,,,,32,1,4.000000e+000,3.120422e-003,0.000000e+000,0,,0,
1524120756.959,,0.000000e+000,3.500028e+001,-1.624629e-006,0.000000e+000,3,4.025345e-001,0.000000e+000,,,,,,,,,,,,,,32,1,4.000000e+000,0.000000e+000,0.000000e+000,0,,0,
1524120795.144,,0.000000e+000,3.499872e+001,-1.630076e-006,0.000000e+000,3,4.323934e-001,0.000000e+000,,,,,,,,,,,,,,32,1,4.000000e+000,1.560211e-003,0.000000e+000,0,,0,
1524120833.202,,0.000000e+000,3.499911e+001,-1.610275e-006,0.000000e+000,3,4.123166e-001,0.000000e+000,,,,,,,,,,,,,,32,1,4.000000e+000,2.338409e-003,0.000000e+000,0,,0,
1524120871.313,,0.000000e+000,3.499833e+001,-1.642216e-006,0.000000e+000,3,4.047066e-001,0.000000e+000,,,,,,,,,,,,,,32,1,4.000000e+000,7.781982e-004,0.000000e+000,0,,0,
1524120909.438,,0.000000e+000,3.499833e+001,-1.609697e-006,0.000000e+000,3,4.001430e-001,0.000000e+000,,,,,,,,,,,,,,32,1,4.000000e+000,7.781982e-004,0.000000e+000,0,,0,
1524120948.024,,0.000000e+000,3.499872e+001,-1.651659e-006,0.000000e+000,3,4.487758e-001,0.000000e+000,,,,,,,,,,,,,,32,1,4.000000e+000,0.000000e+000,0.000000e+000,0,,0,
1524120986.627,,0.000000e+000,3.499950e+001,-1.627068e-006,0.000000e+000,3,3.994262e-001,0.000000e+000,,,,,,,,,,,,,,32,1,4.000000e+000,0.000000e+000,0.000000e+000,0,,0,
1524121024.957,,0.000000e+000,3.499989e+001,-1.566086e-006,0.000000e+000,3,4.013580e-001,0.000000e+000,,,,,,,,,,,,,,32,1,4.000000e+000,7.781982e-004,0.000000e+000,0,,0,
1524121062.745,,0.000000e+000,3.499715e+001,-1.576268e-006,0.000000e+000,3,4.038828e-001,0.000000e+000,,,,,,,,,,,,,,32,1,4.000000e+000,4.692078e-003,0.000000e+000,0,,0,
1524121100.809,,0.000000e+000,3.499989e+001,-1.613918e-006,0.000000e+000,3,4.212058e-001,0.000000e+000,,,,,,,,,,,,,,32,1,4.000000e+000,7.781982e-004,0.000000e+000,0,,0,
1524121139.992,,0.000000e+000,3.499911e+001,-1.613186e-006,0.000000e+000,3,4.302113e-001,0.000000e+000,,,,,,,,,,,,,,32,1,4.000000e+000,2.338409e-003,0.000000e+000,0,,0,
1524121177.512,,0.000000e+000,3.499911e+001,-1.652004e-006,0.000000e+000,3,4.171921e-001,0.000000e+000,,,,,,,,,,,,,,32,1,4.000000e+000,7.820129e-004,0.000000e+000,0,,0,
1524121215.128,,0.000000e+000,3.499989e+001,-1.623987e-006,0.000000e+000,3,4.167815e-001,0.000000e+000,,,,,,,,,,,,,,32,1,4.000000e+000,7.781982e-004,0.000000e+000,0,,0,
1524121253.283,,0.000000e+000,3.499989e+001,-1.644904e-006,0.000000e+000,3,4.051332e-001,0.000000e+000,,,,,,,,,,,,,,32,1,4.000000e+000,7.781982e-004,0.000000e+000,0,,0,
1524121291.379,,0.000000e+000,3.499872e+001,-1.656189e-006,0.000000e+000,3,4.264042e-001,0.000000e+000,,,,,,,,,,,,,,32,1,4.000000e+000,0.000000e+000,0.000000e+000,0,,0,
1524121330.294,,0.000000e+000,3.499989e+001,-1.606085e-006,0.000000e+000,3,4.339376e-001,0.000000e+000,,,,,,,,,,,,,,32,1,4.000000e+000,7.781982e-004,0.000000e+000,0,,0,
1524121368.417,,0.000000e+000,3.499833e+001,-1.576708e-006,0.000000e+000,3,4.066042e-001,0.000000e+000,,,,,,,,,,,,,,32,1,4.000000e+000,7.781982e-004,0.000000e+000,0,,0,
1524121406.446,,0.000000e+000,3.499872e+001,-1.596855e-006,0.000000e+000,3,4.223677e-001,0.000000e+000,,,,,,,,,,,,,,32,1,4.000000e+000,1.560211e-003,0.000000e+000,0,,0,
1524121444.639,,0.000000e+000,3.499950e+001,-1.557717e-006,0.000000e+000,3,3.892660e-001,0.000000e+000,,,,,,,,,,,,,,32,1,4.000000e+000,0.000000e+000,0.000000e+000,0,,0,
1524121482.752,,0.000000e+000,3.499872e+001,-1.539319e-006,0.000000e+000,3,3.789515e-001,0.000000e+000,,,,,,,,,,,,,,32,1,4.000000e+000,0.000000e+000,0.000000e+000,0,,0,
1524121520.545,,0.000000e+000,3.499911e+001,-1.571651e-006,0.000000e+000,3,3.914629e-001,0.000000e+000,,,,,,,,,,,,,,32,1,4.000000e+000,7.820129e-004,0.000000e+000,0,,0,
1524121558.658,,0.000000e+000,3.499872e+001,-1.562428e-006,0.000000e+000,3,3.956741e-001,0.000000e+000,,,,,,,,,,,,,,32,1,4.000000e+000,0.000000e+000,0.000000e+000,0,,0,
1524121596.491,,0.000000e+000,3.499872e+001,-1.562884e-006,0.000000e+000,3,4.106686e-001,0.000000e+000,,,,,,,,,,,,,,32,1,4.000000e+000,0.000000e+000,0.000000e+000,0,,0,
1524121634.854,,0.000000e+000,3.499950e+001,-1.573570e-006,0.000000e+000,3,4.016412e-001,0.000000e+000,,,,,,,,,,,,,,32,1,4.000000e+000,0.000000e+000,0.000000e+000,0,,0,
1524121672.857,,0.000000e+000,3.499911e+001,-1.599621e-006,0.000000e+000,3,3.968213e-001,0.000000e+000,,,,,,,,,,,,,,32,1,4.000000e+000,7.820129e-004,0.000000e+000,0,,0,
1524121710.932,,0.000000e+000,3.499911e+001,-1.580876e-006,0.000000e+000,3,3.660246e-001,0.000000e+000,,,,,,,,,,,,,,32,1,4.000000e+000,2.338409e-003,0.000000e+000,0,,0,
1524121748.456,,0.000000e+000,3.499872e+001,-1.572101e-006,0.000000e+000,3,3.935809e-001,0.000000e+000,,,,,,,,,,,,,,32,1,4.000000e+000,0.000000e+000,0.000000e+000,0,,0,
1524121786.129,,0.000000e+000,3.499950e+001,-1.589047e-006,0.000000e+000,3,4.292399e-001,0.000000e+000,,,,,,,,,,,,,,32,1,4.000000e+000,1.560211e-003,0.000000e+000,0,,0,
1524121824.252,,0.000000e+000,3.499989e+001,-1.554190e-006,0.000000e+000,3,4.057889e-001,0.000000e+000,,,,,,,,,,,,,,32,1,4.000000e+000,7.781982e-004,0.000000e+000,0,,0,
1524121862.370,,0.000000e+000,3.500028e+001,-1.572937e-006,0.000000e+000,3,4.074087e-001,0.000000e+000,,,,,,,,,,,,,,32,1,4.000000e+000,0.000000e+000,0.000000e+000,0,,0,
1524121900.390,,0.000000e+000,3.499950e+001,-1.558239e-006,0.000000e+000,3,4.015576e-001,0.000000e+000,,,,,,,,,,,,,,32,1,4.000000e+000,0.000000e+000,0.000000e+000,0,,0,
1524121939.041,,0.000000e+000,3.499911e+001,-1.517911e-006,0.000000e+000,3,3.861437e-001,0.000000e+000,,,,,,,,,,,,,,32,1,4.000000e+000,7.820129e-004,0.000000e+000,0,,0,
1524121977.569,,0.000000e+000,3.499911e+001,-1.519085e-006,0.000000e+000,3,3.811174e-001,0.000000e+000,,,,,,,,,,,,,,32,1,4.000000e+000,7.820129e-004,0.000000e+000,0,,0,
1524122015.219,,0.000000e+000,3.500028e+001,-1.543172e-006,0.000000e+000,3,3.958077e-001,0.000000e+000,,,,,,,,,,,,,,32,1,4.000000e+000,3.120422e-003,0.000000e+000,0,,0,
1524122053.225,,0.000000e+000,3.499911e+001,-1.479495e-006,0.000000e+000,3,3.181790e-001,0.000000e+000,,,,,,,,,,,,,,32,1,4.000000e+000,7.820129e-004,0.000000e+000,0,,0,
1524122091.213,,0.000000e+000,3.500028e+001,-1.520247e-006,0.000000e+000,3,3.629780e-001,0.000000e+000,,,,,,,,,,,,,,32,1,4.000000e+000,0.000000e+000,0.000000e+000,0,,0,
1524122129.306,,0.000000e+000,3.499950e+001,-1.517966e-006,0.000000e+000,3,3.908738e-001,0.000000e+000,,,,,,,,,,,,,,32,1,4.000000e+000,0.000000e+000,0.000000e+000,0,,0,
1524122167.239,,0.000000e+000,3.499872e+001,-1.508055e-006,0.000000e+000,3,3.849895e-001,0.000000e+000,,,,,,,,,,,,,,32,1,4.000000e+000,0.000000e+000,0.000000e+000,0,,0,
1524122192.650,,0.000000e+000,3.499911e+001,-1.547479e-006,0.000000e+000,3,4.169387e-001,0.000000e+000,,,,,,,,,,,,,,32,1,4.000000e+000,7.820129e-004,0.000000e+000,0,,0,