File: Experimental Raw Data/MFn1 VRM/Iterative Regression/MFn1_VRMac_37K_6000s_VRMde_35K.dc.dat
[Header]
TITLE,MPMS DC Measurement
BYAPP,MPMS Measurement,2.1,Summary
FILEOPENTIME, 1524174010.349000 4/19/2018, 3:40:10 PM

INFO, APPNAME, MPMS MultiVu Application, Revision 1.61,  Build 082

INFO, NAME, MFn1
INFO, WEIGHT, 1.000
INFO, AREA, 1.000
INFO, LENGTH, 1.000
INFO, SHAPE, 0
INFO, COMMENT,
INFO, SEQUENCE FILE: VRMac_37K_6000s_VRMde_35K.seq


INFO, BACKGROUND DATA FILE:, None


STARTUPAXIS,X,4,LINEAR,AUTO,0.000000,0.000000
STARTUPAXIS,Y1,5,LINEAR,AUTO,0.000000,0.000000


STARTUPGROUP,Longitudinal
FIELDGROUP,Longitudinal,1,2,3,4,5,6,7,8,9,15,16,17,18,27,28
FIELDGROUP,Transverse,1,2,3,4,10,11,12,13,14,19,20,21,22,27,28

PLOT_APPEARANCE,ALL,HORZ_GRID_ON,VERT_GRID_ON,MARKERS_AND_LINES

[Data]
Time,Comment,Field (Oe),Temperature (K),Long Moment (emu),Long Scan Std Dev,Long Algorithm,Long Reg Fit,Long Percent Error (%),Trans Moment (emu),Trans Scan Std Dev,Trans Algorithm,Trans Reg Fit,Trans Percent Error (%),Long Moment [w/o ABS] (emu),Long Scan Std Dev [w/o ABS],Long Reg Fit [w/o ABS],Long Percent Error [w/o ABS] (%),Trans Moment [w/o ABS] (emu),Trans Scan Std Dev [w/o ABS],Trans Reg Fit [w/o ABS],Trans Percent Error [w/o ABS] (%),Points per Scan,Scans per Measurement,Scan Length (cm),Delta Temp (K),Rot Position (deg),Error,EC Comp. Running,Using ABS,
1524174010.349,,0.000000e+000,3.688057e+001,-2.772863e-005,0.000000e+000,3,9.687782e-001,0.000000e+000,,,,,,,,,,,,,,32,1,4.000000e+000,2.424774e-001,0.000000e+000,0,,0,
1524174051.740,,0.000000e+000,3.426025e+001,-2.514430e-005,0.000000e+000,3,9.620557e-001,0.000000e+000,,,,,,,,,,,,,,32,1,4.000000e+000,2.318916e-001,0.000000e+000,0,,0,
1524174090.763,,0.000000e+000,3.496786e+001,-2.436213e-005,0.000000e+000,3,9.608769e-001,0.000000e+000,,,,,,,,,,,,,,32,1,4.000000e+000,2.264023e-002,0.000000e+000,0,,0,
1524174129.148,,0.000000e+000,3.499911e+001,-2.374511e-005,0.000000e+000,3,9.620158e-001,0.000000e+000,,,,,,,,,,,,,,32,1,4.000000e+000,2.338409e-003,0.000000e+000,0,,0,
1524174167.034,,0.000000e+000,3.499715e+001,-2.316611e-005,0.000000e+000,3,9.594578e-001,0.000000e+000,,,,,,,,,,,,,,32,1,4.000000e+000,1.571655e-003,0.000000e+000,0,,0,
1524174204.587,,0.000000e+000,3.499715e+001,-2.258370e-005,0.000000e+000,3,9.590320e-001,0.000000e+000,,,,,,,,,,,,,,32,1,4.000000e+000,6.248474e-003,0.000000e+000,0,,0,
1524174242.475,,0.000000e+000,3.499754e+001,-2.211211e-005,0.000000e+000,3,9.580538e-001,0.000000e+000,,,,,,,,,,,,,,32,1,4.000000e+000,2.349854e-003,0.000000e+000,0,,0,
1524174279.970,,0.000000e+000,3.500067e+001,-2.163169e-005,0.000000e+000,3,9.557937e-001,0.000000e+000,,,,,,,,,,,,,,32,1,4.000000e+000,7.820129e-004,0.000000e+000,0,,0,
1524174318.441,,0.000000e+000,3.499911e+001,-2.124466e-005,0.000000e+000,3,9.565923e-001,0.000000e+000,,,,,,,,,,,,,,32,1,4.000000e+000,7.820129e-004,0.000000e+000,0,,0,
1524174356.579,,0.000000e+000,3.499872e+001,-2.092239e-005,0.000000e+000,3,9.556886e-001,0.000000e+000,,,,,,,,,,,,,,32,1,4.000000e+000,0.000000e+000,0.000000e+000,0,,0,
1524174395.067,,0.000000e+000,3.499989e+001,-2.054986e-005,0.000000e+000,3,9.539570e-001,0.000000e+000,,,,,,,,,,,,,,32,1,4.000000e+000,7.781982e-004,0.000000e+000,0,,0,
1524174433.218,,0.000000e+000,3.499950e+001,-2.028188e-005,0.000000e+000,3,9.556964e-001,0.000000e+000,,,,,,,,,,,,,,32,1,4.000000e+000,0.000000e+000,0.000000e+000,0,,0,
1524174471.206,,0.000000e+000,3.499793e+001,-1.979447e-005,0.000000e+000,3,9.517340e-001,0.000000e+000,,,,,,,,,,,,,,32,1,4.000000e+000,3.131866e-003,0.000000e+000,0,,0,
1524174508.764,,0.000000e+000,3.499989e+001,-1.968577e-005,0.000000e+000,3,9.458157e-001,0.000000e+000,,,,,,,,,,,,,,32,1,4.000000e+000,2.342224e-003,0.000000e+000,0,,0,
1524174546.219,,0.000000e+000,3.499911e+001,-1.939287e-005,0.000000e+000,3,9.521484e-001,0.000000e+000,,,,,,,,,,,,,,32,1,4.000000e+000,2.338409e-003,0.000000e+000,0,,0,
1524174584.315,,0.000000e+000,3.499872e+001,-1.906449e-005,0.000000e+000,3,9.527364e-001,0.000000e+000,,,,,,,,,,,,,,32,1,4.000000e+000,0.000000e+000,0.000000e+000,0,,0,
1524174622.885,,0.000000e+000,3.499989e+001,-1.894164e-005,0.000000e+000,3,9.507190e-001,0.000000e+000,,,,,,,,,,,,,,32,1,4.000000e+000,7.781982e-004,0.000000e+000,0,,0,
1524174660.546,,0.000000e+000,3.499911e+001,-1.871439e-005,0.000000e+000,3,9.511735e-001,0.000000e+000,,,,,,,,,,,,,,32,1,4.000000e+000,7.820129e-004,0.000000e+000,0,,0,
1524174699.372,,0.000000e+000,3.499950e+001,-1.844678e-005,0.000000e+000,3,9.503074e-001,0.000000e+000,,,,,,,,,,,,,,32,1,4.000000e+000,1.560211e-003,0.000000e+000,0,,0,
1524174736.775,,0.000000e+000,3.499872e+001,-1.834060e-005,0.000000e+000,3,9.480551e-001,0.000000e+000,,,,,,,,,,,,,,32,1,4.000000e+000,0.000000e+000,0.000000e+000,0,,0,
1524174775.285,,0.000000e+000,3.499911e+001,-1.814402e-005,0.000000e+000,3,9.498854e-001,0.000000e+000,,,,,,,,,,,,,,32,1,4.000000e+000,7.820129e-004,0.000000e+000,0,,0,
1524174812.488,,0.000000e+000,3.499911e+001,-1.801153e-005,0.000000e+000,3,9.498731e-001,0.000000e+000,,,,,,,,,,,,,,32,1,4.000000e+000,7.820129e-004,0.000000e+000,0,,0,
1524174850.596,,0.000000e+000,3.499911e+001,-1.783007e-005,0.000000e+000,3,9.441545e-001,0.000000e+000,,,,,,,,,,,,,,32,1,4.000000e+000,7.820129e-004,0.000000e+000,0,,0,
1524174889.139,,0.000000e+000,3.499872e+001,-1.754091e-005,0.000000e+000,3,9.454900e-001,0.000000e+000,,,,,,,,,,,,,,32,1,4.000000e+000,0.000000e+000,0.000000e+000,0,,0,
1524174926.835,,0.000000e+000,3.499911e+001,-1.743741e-005,0.000000e+000,3,9.494613e-001,0.000000e+000,,,,,,,,,,,,,,32,1,4.000000e+000,7.820129e-004,0.000000e+000,0,,0,
1524174965.810,,0.000000e+000,3.499950e+001,-1.724784e-005,0.000000e+000,3,9.470767e-001,0.000000e+000,,,,,,,,,,,,,,32,1,4.000000e+000,0.000000e+000,0.000000e+000,0,,0,
1524175003.583,,0.000000e+000,3.499950e+001,-1.708427e-005,0.000000e+000,3,9.450751e-001,0.000000e+000,,,,,,,,,,,,,,32,1,4.000000e+000,0.000000e+000,0.000000e+000,0,,0,
1524175040.654,,0.000000e+000,3.500028e+001,-1.697574e-005,0.000000e+000,3,9.446258e-001,0.000000e+000,,,,,,,,,,,,,,32,1,4.000000e+000,1.560211e-003,0.000000e+000,0,,0,
1524175078.692,,0.000000e+000,3.499872e+001,-1.684335e-005,0.000000e+000,3,9.448783e-001,0.000000e+000,,,,,,,,,,,,,,32,1,4.000000e+000,0.000000e+000,0.000000e+000,0,,0,
1524175116.400,,0.000000e+000,3.499950e+001,-1.664444e-005,0.000000e+000,3,9.444648e-001,0.000000e+000,,,,,,,,,,,,,,32,1,4.000000e+000,0.000000e+000,0.000000e+000,0,,0,
1524175154.573,,0.000000e+000,3.499989e+001,-1.653904e-005,0.000000e+000,3,9.421906e-001,0.000000e+000,,,,,,,,,,,,,,32,1,4.000000e+000,7.781982e-004,0.000000e+000,0,,0,
1524175192.636,,0.000000e+000,3.499911e+001,-1.639343e-005,0.000000e+000,3,9.431054e-001,0.000000e+000,,,,,,,,,,,,,,32,1,4.000000e+000,7.820129e-004,0.000000e+000,0,,0,
1524175231.232,,0.000000e+000,3.499911e+001,-1.632749e-005,0.000000e+000,3,9.464287e-001,0.000000e+000,,,,,,,,,,,,,,32,1,4.000000e+000,7.820129e-004,0.000000e+000,0,,0,
1524175269.327,,0.000000e+000,3.499872e+001,-1.598909e-005,0.000000e+000,3,9.435948e-001,0.000000e+000,,,,,,,,,,,,,,32,1,4.000000e+000,1.560211e-003,0.000000e+000,0,,0,
1524175307.810,,0.000000e+000,3.499715e+001,-1.609065e-005,0.000000e+000,3,9.367655e-001,0.000000e+000,,,,,,,,,,,,,,32,1,4.000000e+000,3.128052e-003,0.000000e+000,0,,0,
1524175345.909,,0.000000e+000,3.499911e+001,-1.591357e-005,0.000000e+000,3,9.431788e-001,0.000000e+000,,,,,,,,,,,,,,32,1,4.000000e+000,7.820129e-004,0.000000e+000,0,,0,
1524175392.487,,0.000000e+000,3.500028e+001,-1.566416e-005,0.000000e+000,3,9.352791e-001,0.000000e+000,,,,,,,,,,,,,,32,1,4.000000e+000,1.560211e-003,0.000000e+000,0,,0,
1524175430.400,,0.000000e+000,3.499872e+001,-1.560207e-005,0.000000e+000,3,9.438024e-001,0.000000e+000,,,,,,,,,,,,,,32,1,4.000000e+000,1.560211e-003,0.000000e+000,0,,0,
1524175468.235,,0.000000e+000,3.499950e+001,-1.559892e-005,0.000000e+000,3,9.392276e-001,0.000000e+000,,,,,,,,,,,,,,32,1,4.000000e+000,0.000000e+000,0.000000e+000,0,,0,
1524175506.483,,0.000000e+000,3.499911e+001,-1.547394e-005,0.000000e+000,3,9.407756e-001,0.000000e+000,,,,,,,,,,,,,,32,1,4.000000e+000,2.338409e-003,0.000000e+000,0,,0,
1524175544.504,,0.000000e+000,3.499911e+001,-1.531477e-005,0.000000e+000,3,9.404290e-001,0.000000e+000,,,,,,,,,,,,,,32,1,4.000000e+000,7.820129e-004,0.000000e+000,0,,0,
1524175582.102,,0.000000e+000,3.499950e+001,-1.526133e-005,0.000000e+000,3,9.352069e-001,0.000000e+000,,,,,,,,,,,,,,32,1,4.000000e+000,0.000000e+000,0.000000e+000,0,,0,
1524175620.258,,0.000000e+000,3.499989e+001,-1.518424e-005,0.000000e+000,3,9.370762e-001,0.000000e+000,,,,,,,,,,,,,,32,1,4.000000e+000,7.781982e-004,0.000000e+000,0,,0,
1524175658.353,,0.000000e+000,3.499989e+001,-1.513618e-005,0.000000e+000,3,9.336136e-001,0.000000e+000,,,,,,,,,,,,,,32,1,4.000000e+000,7.781982e-004,0.000000e+000,0,,0,
1524175696.481,,0.000000e+000,3.499872e+001,-1.482906e-005,0.000000e+000,3,9.337861e-001,0.000000e+000,,,,,,,,,,,,,,32,1,4.000000e+000,0.000000e+000,0.000000e+000,0,,0,
1524175734.564,,0.000000e+000,3.499872e+001,-1.499144e-005,0.000000e+000,3,9.372100e-001,0.000000e+000,,,,,,,,,,,,,,32,1,4.000000e+000,1.560211e-003,0.000000e+000,0,,0,
1524175772.695,,0.000000e+000,3.499872e+001,-1.472826e-005,0.000000e+000,3,9.358474e-001,0.000000e+000,,,,,,,,,,,,,,32,1,4.000000e+000,0.000000e+000,0.000000e+000,0,,0,
1524175810.815,,0.000000e+000,3.499911e+001,-1.472642e-005,0.000000e+000,3,9.450831e-001,0.000000e+000,,,,,,,,,,,,,,32,1,4.000000e+000,7.820129e-004,0.000000e+000,0,,0,
1524175848.911,,0.000000e+000,3.499833e+001,-1.452498e-005,0.000000e+000,3,9.380615e-001,0.000000e+000,,,,,,,,,,,,,,32,1,4.000000e+000,7.781982e-004,0.000000e+000,0,,0,
1524175887.091,,0.000000e+000,3.499911e+001,-1.445876e-005,0.000000e+000,3,9.335619e-001,0.000000e+000,,,,,,,,,,,,,,32,1,4.000000e+000,7.820129e-004,0.000000e+000,0,,0,
1524175925.777,,0.000000e+000,3.499950e+001,-1.431577e-005,0.000000e+000,3,9.344420e-001,0.000000e+000,,,,,,,,,,,,,,32,1,4.000000e+000,1.560211e-003,0.000000e+000,0,,0,
1524175962.770,,0.000000e+000,3.499950e+001,-1.438649e-005,0.000000e+000,3,9.333950e-001,0.000000e+000,,,,,,,,,,,,,,32,1,4.000000e+000,1.560211e-003,0.000000e+000,0,,0,
1524176000.953,,0.000000e+000,3.499911e+001,-1.427709e-005,0.000000e+000,3,9.315552e-001,0.000000e+000,,,,,,,,,,,,,,32,1,4.000000e+000,7.820129e-004,0.000000e+000,0,,0,
1524176038.556,,0.000000e+000,3.499911e+001,-1.424214e-005,0.000000e+000,3,9.360303e-001,0.000000e+000,,,,,,,,,,,,,,32,1,4.000000e+000,7.820129e-004,0.000000e+000,0,,0,
1524176077.724,,0.000000e+000,3.499950e+001,-1.415176e-005,0.000000e+000,3,9.314798e-001,0.000000e+000,,,,,,,,,,,,,,32,1,4.000000e+000,0.000000e+000,0.000000e+000,0,,0,
1524176114.765,,0.000000e+000,3.500028e+001,-1.415044e-005,0.000000e+000,3,9.357846e-001,0.000000e+000,,,,,,,,,,,,,,32,1,4.000000e+000,0.000000e+000,0.000000e+000,0,,0,
1524176152.860,,0.000000e+000,3.500067e+001,-1.390149e-005,0.000000e+000,3,9.351055e-001,0.000000e+000,,,,,,,,,,,,,,32,1,4.000000e+000,7.820129e-004,0.000000e+000,0,,0,
1524176190.636,,0.000000e+000,3.499911e+001,-1.404061e-005,0.000000e+000,3,9.410154e-001,0.000000e+000,,,,,,,,,,,,,,32,1,4.000000e+000,7.820129e-004,0.000000e+000,0,,0,
1524176228.589,,0.000000e+000,3.499950e+001,-1.387276e-005,0.000000e+000,3,9.349805e-001,0.000000e+000,,,,,,,,,,,,,,32,1,4.000000e+000,0.000000e+000,0.000000e+000,0,,0,
1524176266.495,,0.000000e+000,3.499911e+001,-1.374295e-005,0.000000e+000,3,9.268543e-001,0.000000e+000,,,,,,,,,,,,,,32,1,4.000000e+000,7.820129e-004,0.000000e+000,0,,0,
1524176304.338,,0.000000e+000,3.499911e+001,-1.373787e-005,0.000000e+000,3,9.295192e-001,0.000000e+000,,,,,,,,,,,,,,32,1,4.000000e+000,7.820129e-004,0.000000e+000,0,,0,
1524176342.446,,0.000000e+000,3.499989e+001,-1.358808e-005,0.000000e+000,3,9.316584e-001,0.000000e+000,,,,,,,,,,,,,,32,1,4.000000e+000,2.342224e-003,0.000000e+000,0,,0,
1524176380.211,,0.000000e+000,3.499950e+001,-1.355485e-005,0.000000e+000,3,9.298937e-001,0.000000e+000,,,,,,,,,,,,,,32,1,4.000000e+000,0.000000e+000,0.000000e+000,0,,0,
1524176418.552,,0.000000e+000,3.499833e+001,-1.351299e-005,0.000000e+000,3,9.290586e-001,0.000000e+000,,,,,,,,,,,,,,32,1,4.000000e+000,2.349854e-003,0.000000e+000,0,,0,
1524176456.822,,0.000000e+000,3.499950e+001,-1.337241e-005,0.000000e+000,3,9.322859e-001,0.000000e+000,,,,,,,,,,,,,,32,1,4.000000e+000,1.560211e-003,0.000000e+000,0,,0,
1524176494.378,,0.000000e+000,3.499989e+001,-1.342898e-005,0.000000e+000,3,9.308482e-001,0.000000e+000,,,,,,,,,,,,,,32,1,4.000000e+000,7.781982e-004,0.000000e+000,0,,0,
1524176532.291,,0.000000e+000,3.499911e+001,-1.319841e-005,0.000000e+000,3,9.290044e-001,0.000000e+000,,,,,,,,,,,,,,32,1,4.000000e+000,7.820129e-004,0.000000e+000,0,,0,
1524176571.176,,0.000000e+000,3.499872e+001,-1.317267e-005,0.000000e+000,3,9.315208e-001,0.000000e+000,,,,,,,,,,,,,,32,1,4.000000e+000,0.000000e+000,0.000000e+000,0,,0,
1524176608.290,,0.000000e+000,3.499911e+001,-1.318188e-005,0.000000e+000,3,9.318498e-001,0.000000e+000,,,,,,,,,,,,,,32,1,4.000000e+000,7.820129e-004,0.000000e+000,0,,0,
1524176645.715,,0.000000e+000,3.499872e+001,-1.311879e-005,0.000000e+000,3,9.259099e-001,0.000000e+000,,,,,,,,,,,,,,32,1,4.000000e+000,1.560211e-003,0.000000e+000,0,,0,
1524176683.733,,0.000000e+000,3.499989e+001,-1.299849e-005,0.000000e+000,3,9.284973e-001,0.000000e+000,,,,,,,,,,,,,,32,1,4.000000e+000,7.781982e-004,0.000000e+000,0,,0,
1524176721.931,,0.000000e+000,3.499950e+001,-1.302385e-005,0.000000e+000,3,9.286949e-001,0.000000e+000,,,,,,,,,,,,,,32,1,4.000000e+000,0.000000e+000,0.000000e+000,0,,0,
1524176760.284,,0.000000e+000,3.499950e+001,-1.290999e-005,0.000000e+000,3,9.312836e-001,0.000000e+000,,,,,,,,,,,,,,32,1,4.000000e+000,1.560211e-003,0.000000e+000,0,,0,
1524176797.877,,0.000000e+000,3.499872e+001,-1.274227e-005,0.000000e+000,3,9.286049e-001,0.000000e+000,,,,,,,,,,,,,,32,1,4.000000e+000,0.000000e+000,0.000000e+000,0,,0,
1524176836.010,,0.000000e+000,3.499911e+001,-1.275187e-005,0.000000e+000,3,9.370473e-001,0.000000e+000,,,,,,,,,,,,,,32,1,4.000000e+000,7.820129e-004,0.000000e+000,0,,0,
1524176873.888,,0.000000e+000,3.499911e+001,-1.285298e-005,0.000000e+000,3,9.230223e-001,0.000000e+000,,,,,,,,,,,,,,32,1,4.000000e+000,7.820129e-004,0.000000e+000,0,,0,
1524176911.972,,0.000000e+000,3.499793e+001,-1.267700e-005,0.000000e+000,3,9.290799e-001,0.000000e+000,,,,,,,,,,,,,,32,1,4.000000e+000,3.131866e-003,0.000000e+000,0,,0,
1524176950.302,,0.000000e+000,3.499950e+001,-1.263034e-005,0.000000e+000,3,9.310141e-001,0.000000e+000,,,,,,,,,,,,,,32,1,4.000000e+000,6.259918e-003,0.000000e+000,0,,0,
1524176988.650,,0.000000e+000,3.499872e+001,-1.262590e-005,0.000000e+000,3,9.230399e-001,0.000000e+000,,,,,,,,,,,,,,32,1,4.000000e+000,1.560211e-003,0.000000e+000,0,,0,
1524177026.791,,0.000000e+000,3.499911e+001,-1.255749e-005,0.000000e+000,3,9.243792e-001,0.000000e+000,,,,,,,,,,,,,,32,1,4.000000e+000,7.820129e-004,0.000000e+000,0,,0,
1524177065.061,,0.000000e+000,3.499950e+001,-1.255421e-005,0.000000e+000,3,9.243022e-001,0.000000e+000,,,,,,,,,,,,,,32,1,4.000000e+000,0.000000e+000,0.000000e+000,0,,0,
1524177103.249,,0.000000e+000,3.499950e+001,-1.245721e-005,0.000000e+000,3,9.329400e-001,0.000000e+000,,,,,,,,,,,,,,32,1,4.000000e+000,1.560211e-003,0.000000e+000,0,,0,
1524177141.282,,0.000000e+000,3.500028e+001,-1.246798e-005,0.000000e+000,3,9.218047e-001,0.000000e+000,,,,,,,,,,,,,,32,1,4.000000e+000,1.560211e-003,0.000000e+000,0,,0,
1524177179.103,,0.000000e+000,3.499833e+001,-1.229525e-005,0.000000e+000,3,9.252340e-001,0.000000e+000,,,,,,,,,,,,,,32,1,4.000000e+000,7.781982e-004,0.000000e+000,0,,0,
1524177216.958,,0.000000e+000,3.500028e+001,-1.233233e-005,0.000000e+000,3,9.226764e-001,0.000000e+000,,,,,,,,,,,,,,32,1,4.000000e+000,6.259918e-003,0.000000e+000,0,,0,
1524177255.579,,0.000000e+000,3.499911e+001,-1.237282e-005,0.000000e+000,3,9.241355e-001,0.000000e+000,,,,,,,,,,,,,,32,1,4.000000e+000,7.820129e-004,0.000000e+000,0,,0,
1524177292.825,,0.000000e+000,3.499989e+001,-1.218574e-005,0.000000e+000,3,9.221745e-001,0.000000e+000,,,,,,,,,,,,,,32,1,4.000000e+000,7.781982e-004,0.000000e+000,0,,0,
1524177330.778,,0.000000e+000,3.499833e+001,-1.204649e-005,0.000000e+000,3,9.267473e-001,0.000000e+000,,,,,,,,,,,,,,32,1,4.000000e+000,7.781982e-004,0.000000e+000,0,,0,
1524177368.863,,0.000000e+000,3.499833e+001,-1.202658e-005,0.000000e+000,3,9.194300e-001,0.000000e+000,,,,,,,,,,,,,,32,1,4.000000e+000,7.781982e-004,0.000000e+000,0,,0,
1524177406.671,,0.000000e+000,3.499872e+001,-1.197465e-005,0.000000e+000,3,9.224307e-001,0.000000e+000,,,,,,,,,,,,,,32,1,4.000000e+000,1.560211e-003,0.000000e+000,0,,0,
1524177445.679,,0.000000e+000,3.499715e+001,-1.200858e-005,0.000000e+000,3,9.221199e-001,0.000000e+000,,,,,,,,,,,,,,32,1,4.000000e+000,1.571655e-003,0.000000e+000,0,,0,
1524177483.810,,0.000000e+000,3.499911e+001,-1.191832e-005,0.000000e+000,3,9.240258e-001,0.000000e+000,,,,,,,,,,,,,,32,1,4.000000e+000,7.820129e-004,0.000000e+000,0,,0,
1524177522.608,,0.000000e+000,3.499833e+001,-1.192280e-005,0.000000e+000,3,9.261565e-001,0.000000e+000,,,,,,,,,,,,,,32,1,4.000000e+000,7.781982e-004,0.000000e+000,0,,0,
1524177560.784,,0.000000e+000,3.499833e+001,-1.178255e-005,0.000000e+000,3,9.233155e-001,0.000000e+000,,,,,,,,,,,,,,32,1,4.000000e+000,7.781982e-004,0.000000e+000,0,,0,
1524177598.907,,0.000000e+000,3.499872e+001,-1.179758e-005,0.000000e+000,3,9.245973e-001,0.000000e+000,,,,,,,,,,,,,,32,1,4.000000e+000,0.000000e+000,0.000000e+000,0,,0,
1524177637.027,,0.000000e+000,3.499872e+001,-1.174645e-005,0.000000e+000,3,9.266342e-001,0.000000e+000,,,,,,,,,,,,,,32,1,4.000000e+000,0.000000e+000,0.000000e+000,0,,0,
1524177675.665,,0.000000e+000,3.499911e+001,-1.149702e-005,0.000000e+000,3,9.193531e-001,0.000000e+000,,,,,,,,,,,,,,32,1,4.000000e+000,7.820129e-004,0.000000e+000,0,,0,
1524177713.643,,0.000000e+000,3.499911e+001,-1.163785e-005,0.000000e+000,3,9.114836e-001,0.000000e+000,,,,,,,,,,,,,,32,1,4.000000e+000,2.338409e-003,0.000000e+000,0,,0,
1524177751.779,,0.000000e+000,3.499793e+001,-1.151504e-005,0.000000e+000,3,9.219694e-001,0.000000e+000,,,,,,,,,,,,,,32,1,4.000000e+000,1.567841e-003,0.000000e+000,0,,0,
1524177789.882,,0.000000e+000,3.499911e+001,-1.150305e-005,0.000000e+000,3,9.185160e-001,0.000000e+000,,,,,,,,,,,,,,32,1,4.000000e+000,7.820129e-004,0.000000e+000,0,,0,
1524177827.497,,0.000000e+000,3.499950e+001,-1.144649e-005,0.000000e+000,3,9.221345e-001,0.000000e+000,,,,,,,,,,,,,,32,1,4.000000e+000,0.000000e+000,0.000000e+000,0,,0,
1524177865.613,,0.000000e+000,3.499911e+001,-1.145137e-005,0.000000e+000,3,9.194630e-001,0.000000e+000,,,,,,,,,,,,,,32,1,4.000000e+000,7.820129e-004,0.000000e+000,0,,0,
1524177903.346,,0.000000e+000,3.499872e+001,-1.141050e-005,0.000000e+000,3,9.198855e-001,0.000000e+000,,,,,,,,,,,,,,32,1,4.000000e+000,1.560211e-003,0.000000e+000,0,,0,
1524177941.434,,0.000000e+000,3.499872e+001,-1.127869e-005,0.000000e+000,3,9.198818e-001,0.000000e+000,,,,,,,,,,,,,,32,1,4.000000e+000,0.000000e+000,0.000000e+000,0,,0,
1524177979.420,,0.000000e+000,3.499989e+001,-1.143590e-005,0.000000e+000,3,9.164047e-001,0.000000e+000,,,,,,,,,,,,,,32,1,4.000000e+000,7.781982e-004,0.000000e+000,0,,0,
1524178017.483,,0.000000e+000,3.499911e+001,-1.137836e-005,0.000000e+000,3,9.258000e-001,0.000000e+000,,,,,,,,,,,,,,32,1,4.000000e+000,7.820129e-004,0.000000e+000,0,,0,
1524178055.611,,0.000000e+000,3.499793e+001,-1.107514e-005,0.000000e+000,3,9.167862e-001,0.000000e+000,,,,,,,,,,,,,,32,1,4.000000e+000,3.131866e-003,0.000000e+000,0,,0,
1524178094.416,,0.000000e+000,3.499911e+001,-1.123770e-005,0.000000e+000,3,9.159708e-001,0.000000e+000,,,,,,,,,,,,,,32,1,4.000000e+000,7.820129e-004,0.000000e+000,0,,0,
1524178133.024,,0.000000e+000,3.499872e+001,-1.109832e-005,0.000000e+000,3,9.210626e-001,0.000000e+000,,,,,,,,,,,,,,32,1,4.000000e+000,1.560211e-003,0.000000e+000,0,,0,
1524178170.978,,0.000000e+000,3.499950e+001,-1.109022e-005,0.000000e+000,3,9.153868e-001,0.000000e+000,,,,,,,,,,,,,,32,1,4.000000e+000,0.000000e+000,0.000000e+000,0,,0,
1524178209.591,,0.000000e+000,3.499911e+001,-1.094168e-005,0.000000e+000,3,9.157969e-001,0.000000e+000,,,,,,,,,,,,,,32,1,4.000000e+000,7.820129e-004,0.000000e+000,0,,0,
1524178247.066,,0.000000e+000,3.499911e+001,-1.103688e-005,0.000000e+000,3,9.171638e-001,0.000000e+000,,,,,,,,,,,,,,32,1,4.000000e+000,7.820129e-004,0.000000e+000,0,,0,
1524178285.184,,0.000000e+000,3.500028e+001,-1.092176e-005,0.000000e+000,3,9.161639e-001,0.000000e+000,,,,,,,,,,,,,,32,1,4.000000e+000,4.688263e-003,0.000000e+000,0,,0,
1524178322.810,,0.000000e+000,3.499833e+001,-1.086875e-005,0.000000e+000,3,9.146410e-001,0.000000e+000,,,,,,,,,,,,,,32,1,4.000000e+000,7.781982e-004,0.000000e+000,0,,0,
1524178360.918,,0.000000e+000,3.499794e+001,-1.091063e-005,0.000000e+000,3,9.149225e-001,0.000000e+000,,,,,,,,,,,,,,32,1,4.000000e+000,0.000000e+000,0.000000e+000,0,,0,
1524178399.281,,0.000000e+000,3.499833e+001,-1.092932e-005,0.000000e+000,3,9.191895e-001,0.000000e+000,,,,,,,,,,,,,,32,1,4.000000e+000,7.781982e-004,0.000000e+000,0,,0,
1524178437.386,,0.000000e+000,3.499911e+001,-1.087747e-005,0.000000e+000,3,9.165804e-001,0.000000e+000,,,,,,,,,,,,,,32,1,4.000000e+000,7.820129e-004,0.000000e+000,0,,0,
1524178475.897,,0.000000e+000,3.499872e+001,-1.076760e-005,0.000000e+000,3,9.145514e-001,0.000000e+000,,,,,,,,,,,,,,32,1,4.000000e+000,1.560211e-003,0.000000e+000,0,,0,
1524178512.932,,0.000000e+000,3.499833e+001,-1.076498e-005,0.000000e+000,3,9.133040e-001,0.000000e+000,,,,,,,,,,,,,,32,1,4.000000e+000,7.781982e-004,0.000000e+000,0,,0,
1524178551.598,,0.000000e+000,3.499950e+001,-1.065276e-005,0.000000e+000,3,9.128231e-001,0.000000e+000,,,,,,,,,,,,,,32,1,4.000000e+000,0.000000e+000,0.000000e+000,0,,0,
1524178588.914,,0.000000e+000,3.499911e+001,-1.068678e-005,0.000000e+000,3,9.099270e-001,0.000000e+000,,,,,,,,,,,,,,32,1,4.000000e+000,7.820129e-004,0.000000e+000,0,,0,
1524178626.514,,0.000000e+000,3.499872e+001,-1.062366e-005,0.000000e+000,3,9.086871e-001,0.000000e+000,,,,,,,,,,,,,,32,1,4.000000e+000,0.000000e+000,0.000000e+000,0,,0,
1524178664.275,,0.000000e+000,3.499989e+001,-1.054551e-005,0.000000e+000,3,9.150186e-001,0.000000e+000,,,,,,,,,,,,,,32,1,4.000000e+000,7.781982e-004,0.000000e+000,0,,0,
1524178701.630,,0.000000e+000,3.499911e+001,-1.055004e-005,0.000000e+000,3,9.125040e-001,0.000000e+000,,,,,,,,,,,,,,32,1,4.000000e+000,7.820129e-004,0.000000e+000,0,,0,
1524178739.643,,0.000000e+000,3.499911e+001,-1.049632e-005,0.000000e+000,3,9.162384e-001,0.000000e+000,,,,,,,,,,,,,,32,1,4.000000e+000,7.820129e-004,0.000000e+000,0,,0,
1524178778.291,,0.000000e+000,3.499911e+001,-1.048423e-005,0.000000e+000,3,9.096978e-001,0.000000e+000,,,,,,,,,,,,,,32,1,4.000000e+000,7.820129e-004,0.000000e+000,0,,0,
1524178816.829,,0.000000e+000,3.499950e+001,-1.043656e-005,0.000000e+000,3,9.148932e-001,0.000000e+000,,,,,,,,,,,,,,32,1,4.000000e+000,3.120422e-003,0.000000e+000,0,,0,
1524178855.318,,0.000000e+000,3.499911e+001,-1.033796e-005,0.000000e+000,3,9.093935e-001,0.000000e+000,,,,,,,,,,,,,,32,1,4.000000e+000,7.820129e-004,0.000000e+000,0,,0,
1524178893.911,,0.000000e+000,3.499950e+001,-1.035143e-005,0.000000e+000,3,9.096719e-001,0.000000e+000,,,,,,,,,,,,,,32,1,4.000000e+000,1.560211e-003,0.000000e+000,0,,0,
1524178932.699,,0.000000e+000,3.500067e+001,-1.033012e-005,0.000000e+000,3,9.138868e-001,0.000000e+000,,,,,,,,,,,,,,32,1,4.000000e+000,2.338409e-003,0.000000e+000,0,,0,
1524178970.999,,0.000000e+000,3.499950e+001,-1.024286e-005,0.000000e+000,3,9.106637e-001,0.000000e+000,,,,,,,,,,,,,,32,1,4.000000e+000,0.000000e+000,0.000000e+000,0,,0,
1524179009.165,,0.000000e+000,3.499911e+001,-1.026253e-005,0.000000e+000,3,9.016289e-001,0.000000e+000,,,,,,,,,,,,,,32,1,4.000000e+000,7.820129e-004,0.000000e+000,0,,0,
1524179047.248,,0.000000e+000,3.499989e+001,-1.028095e-005,0.000000e+000,3,9.074660e-001,0.000000e+000,,,,,,,,,,,,,,32,1,4.000000e+000,7.781982e-004,0.000000e+000,0,,0,
1524179085.306,,0.000000e+000,3.499989e+001,-1.017194e-005,0.000000e+000,3,9.094371e-001,0.000000e+000,,,,,,,,,,,,,,32,1,4.000000e+000,7.781982e-004,0.000000e+000,0,,0,
1524179123.409,,0.000000e+000,3.499911e+001,-1.014090e-005,0.000000e+000,3,9.074538e-001,0.000000e+000,,,,,,,,,,,,,,32,1,4.000000e+000,2.338409e-003,0.000000e+000,0,,0,
1524179161.530,,0.000000e+000,3.499950e+001,-1.012132e-005,0.000000e+000,3,9.096195e-001,0.000000e+000,,,,,,,,,,,,,,32,1,4.000000e+000,0.000000e+000,0.000000e+000,0,,0,
1524179200.003,,0.000000e+000,3.500028e+001,-1.001842e-005,0.000000e+000,3,9.073787e-001,0.000000e+000,,,,,,,,,,,,,,32,1,4.000000e+000,1.560211e-003,0.000000e+000,0,,0,
1524179238.598,,0.000000e+000,3.499872e+001,-1.002655e-005,0.000000e+000,3,9.077125e-001,0.000000e+000,,,,,,,,,,,,,,32,1,4.000000e+000,1.560211e-003,0.000000e+000,0,,0,
1524179276.236,,0.000000e+000,3.500028e+001,-9.974619e-006,0.000000e+000,3,9.075401e-001,0.000000e+000,,,,,,,,,,,,,,32,1,4.000000e+000,0.000000e+000,0.000000e+000,0,,0,
1524179314.672,,0.000000e+000,3.499950e+001,-9.951270e-006,0.000000e+000,3,9.050338e-001,0.000000e+000,,,,,,,,,,,,,,32,1,4.000000e+000,3.120422e-003,0.000000e+000,0,,0,
1524179352.982,,0.000000e+000,3.500028e+001,-9.931732e-006,0.000000e+000,3,9.055815e-001,0.000000e+000,,,,,,,,,,,,,,32,1,4.000000e+000,0.000000e+000,0.000000e+000,0,,0,
1524179390.780,,0.000000e+000,3.499872e+001,-9.901818e-006,0.000000e+000,3,9.066566e-001,0.000000e+000,,,,,,,,,,,,,,32,1,4.000000e+000,0.000000e+000,0.000000e+000,0,,0,
1524179428.893,,0.000000e+000,3.499911e+001,-9.899857e-006,0.000000e+000,3,9.084666e-001,0.000000e+000,,,,,,,,,,,,,,32,1,4.000000e+000,7.820129e-004,0.000000e+000,0,,0,
1524179467.014,,0.000000e+000,3.499911e+001,-9.882242e-006,0.000000e+000,3,9.071859e-001,0.000000e+000,,,,,,,,,,,,,,32,1,4.000000e+000,7.820129e-004,0.000000e+000,0,,0,
1524179505.107,,0.000000e+000,3.499950e+001,-9.860510e-006,0.000000e+000,3,9.051126e-001,0.000000e+000,,,,,,,,,,,,,,32,1,4.000000e+000,0.000000e+000,0.000000e+000,0,,0,
1524179543.110,,0.000000e+000,3.499872e+001,-9.761745e-006,0.000000e+000,3,9.071533e-001,0.000000e+000,,,,,,,,,,,,,,32,1,4.000000e+000,0.000000e+000,0.000000e+000,0,,0,
1524179581.483,,0.000000e+000,3.499950e+001,-9.720554e-006,0.000000e+000,3,9.021058e-001,0.000000e+000,,,,,,,,,,,,,,32,1,4.000000e+000,0.000000e+000,0.000000e+000,0,,0,
1524179619.616,,0.000000e+000,3.499989e+001,-9.656418e-006,0.000000e+000,3,9.117620e-001,0.000000e+000,,,,,,,,,,,,,,32,1,4.000000e+000,7.781982e-004,0.000000e+000,0,,0,
1524179657.714,,0.000000e+000,3.499911e+001,-9.783239e-006,0.000000e+000,3,9.075339e-001,0.000000e+000,,,,,,,,,,,,,,32,1,4.000000e+000,7.820129e-004,0.000000e+000,0,,0,
1524179695.775,,0.000000e+000,3.499911e+001,-9.616251e-006,0.000000e+000,3,9.082308e-001,0.000000e+000,,,,,,,,,,,,,,32,1,4.000000e+000,7.820129e-004,0.000000e+000,0,,0,
1524179733.948,,0.000000e+000,3.499911e+001,-9.591697e-006,0.000000e+000,3,8.976098e-001,0.000000e+000,,,,,,,,,,,,,,32,1,4.000000e+000,7.820129e-004,0.000000e+000,0,,0,
1524179771.896,,0.000000e+000,3.499911e+001,-9.609762e-006,0.000000e+000,3,9.011952e-001,0.000000e+000,,,,,,,,,,,,,,32,1,4.000000e+000,7.820129e-004,0.000000e+000,0,,0,
1524179809.947,,0.000000e+000,3.499872e+001,-9.570309e-006,0.000000e+000,3,8.996632e-001,0.000000e+000,,,,,,,,,,,,,,32,1,4.000000e+000,0.000000e+000,0.000000e+000,0,,0,
1524179847.820,,0.000000e+000,3.499989e+001,-9.528833e-006,0.000000e+000,3,9.002852e-001,0.000000e+000,,,,,,,,,,,,,,32,1,4.000000e+000,2.342224e-003,0.000000e+000,0,,0,
1524179886.395,,0.000000e+000,3.499911e+001,-9.512481e-006,0.000000e+000,3,9.056747e-001,0.000000e+000,,,,,,,,,,,,,,32,1,4.000000e+000,7.820129e-004,0.000000e+000,0,,0,
1524179925.253,,0.000000e+000,3.499911e+001,-9.497502e-006,0.000000e+000,3,9.026738e-001,0.000000e+000,,,,,,,,,,,,,,32,1,4.000000e+000,7.820129e-004,0.000000e+000,0,,0,
1524179963.349,,0.000000e+000,3.499950e+001,-9.449430e-006,0.000000e+000,3,9.049789e-001,0.000000e+000,,,,,,,,,,,,,,32,1,4.000000e+000,1.560211e-003,0.000000e+000,0,,0,
1524180001.454,,0.000000e+000,3.499911e+001,-9.414625e-006,0.000000e+000,3,9.011070e-001,0.000000e+000,,,,,,,,,,,,,,32,1,4.000000e+000,7.820129e-004,0.000000e+000,0,,0,
1524180039.605,,0.000000e+000,3.499989e+001,-9.407730e-006,0.000000e+000,3,9.039910e-001,0.000000e+000,,,,,,,,,,,,,,32,1,4.000000e+000,7.781982e-004,0.000000e+000,0,,0,
1524180077.733,,0.000000e+000,3.499911e+001,-9.417271e-006,0.000000e+000,3,9.066473e-001,0.000000e+000,,,,,,,,,,,,,,32,1,4.000000e+000,7.820129e-004,0.000000e+000,0,,0,
1524180115.913,,0.000000e+000,3.499989e+001,-9.401311e-006,0.000000e+000,3,9.033646e-001,0.000000e+000,,,,,,,,,,,,,,32,1,4.000000e+000,7.781982e-004,0.000000e+000,0,,0,
1524180154.247,,0.000000e+000,3.499989e+001,-9.316157e-006,0.000000e+000,3,8.925340e-001,0.000000e+000,,,,,,,,,,,,,,32,1,4.000000e+000,7.781982e-004,0.000000e+000,0,,0,
1524180193.070,,0.000000e+000,3.499950e+001,-9.227716e-006,0.000000e+000,3,8.994065e-001,0.000000e+000,,,,,,,,,,,,,,32,1,4.000000e+000,0.000000e+000,0.000000e+000,0,,0,
1524180231.595,,0.000000e+000,3.500224e+001,-9.248227e-006,0.000000e+000,3,8.957369e-001,0.000000e+000,,,,,,,,,,,,,,32,1,4.000000e+000,7.896423e-004,0.000000e+000,0,,0,
1524180269.936,,0.000000e+000,3.499754e+001,-9.294189e-006,0.000000e+000,3,8.996705e-001,0.000000e+000,,,,,,,,,,,,,,32,1,4.000000e+000,3.910065e-003,0.000000e+000,0,,0,
1524180308.269,,0.000000e+000,3.499793e+001,-9.313197e-006,0.000000e+000,3,9.050154e-001,0.000000e+000,,,,,,,,,,,,,,32,1,4.000000e+000,1.567841e-003,0.000000e+000,0,,0,
1524180345.859,,0.000000e+000,3.499911e+001,-9.216440e-006,0.000000e+000,3,9.026622e-001,0.000000e+000,,,,,,,,,,,,,,32,1,4.000000e+000,7.820129e-004,0.000000e+000,0,,0,
1524180383.982,,0.000000e+000,3.499950e+001,-9.198853e-006,0.000000e+000,3,8.943660e-001,0.000000e+000,,,,,,,,,,,,,,32,1,4.000000e+000,0.000000e+000,0.000000e+000,0,,0,
1524180422.138,,0.000000e+000,3.499950e+001,-9.141843e-006,0.000000e+000,3,8.929008e-001,0.000000e+000,,,,,,,,,,,,,,32,1,4.000000e+000,0.000000e+000,0.000000e+000,0,,0,
1524180460.209,,0.000000e+000,3.499872e+001,-9.155485e-006,0.000000e+000,3,9.046794e-001,0.000000e+000,,,,,,,,,,,,,,32,1,4.000000e+000,0.000000e+000,0.000000e+000,0,,0,
1524180498.302,,0.000000e+000,3.499989e+001,-9.208125e-006,0.000000e+000,3,9.014729e-001,0.000000e+000,,,,,,,,,,,,,,32,1,4.000000e+000,7.781982e-004,0.000000e+000,0,,0,
1524180536.145,,0.000000e+000,3.499911e+001,-9.139224e-006,0.000000e+000,3,8.984133e-001,0.000000e+000,,,,,,,,,,,,,,32,1,4.000000e+000,7.820129e-004,0.000000e+000,0,,0,
1524180574.000,,0.000000e+000,3.499872e+001,-9.052889e-006,0.000000e+000,3,8.955334e-001,0.000000e+000,,,,,,,,,,,,,,32,1,4.000000e+000,1.560211e-003,0.000000e+000,0,,0,
1524180611.193,,0.000000e+000,3.499833e+001,-9.015572e-006,0.000000e+000,3,8.944055e-001,0.000000e+000,,,,,,,,,,,,,,32,1,4.000000e+000,7.781982e-004,0.000000e+000,0,,0,
1524180648.864,,0.000000e+000,3.499950e+001,-9.076839e-006,0.000000e+000,3,8.975480e-001,0.000000e+000,,,,,,,,,,,,,,32,1,4.000000e+000,0.000000e+000,0.000000e+000,0,,0,
1524180687.819,,0.000000e+000,3.499794e+001,-8.920790e-006,0.000000e+000,3,8.996771e-001,0.000000e+000,,,,,,,,,,,,,,32,1,4.000000e+000,0.000000e+000,0.000000e+000,0,,0,
1524180725.747,,0.000000e+000,3.499911e+001,-8.982531e-006,0.000000e+000,3,8.950799e-001,0.000000e+000,,,,,,,,,,,,,,32,1,4.000000e+000,7.820129e-004,0.000000e+000,0,,0,
1524180763.333,,0.000000e+000,3.499950e+001,-8.887831e-006,0.000000e+000,3,8.939263e-001,0.000000e+000,,,,,,,,,,,,,,32,1,4.000000e+000,0.000000e+000,0.000000e+000,0,,0,
1524180801.471,,0.000000e+000,3.499832e+001,-8.894753e-006,0.000000e+000,3,9.032022e-001,0.000000e+000,,,,,,,,,,,,,,32,1,4.000000e+000,3.910065e-003,0.000000e+000,0,,0,
1524180839.204,,0.000000e+000,3.499911e+001,-8.845625e-006,0.000000e+000,3,8.941911e-001,0.000000e+000,,,,,,,,,,,,,,32,1,4.000000e+000,7.820129e-004,0.000000e+000,0,,0,
1524180877.810,,0.000000e+000,3.499911e+001,-8.855955e-006,0.000000e+000,3,8.986711e-001,0.000000e+000,,,,,,,,,,,,,,32,1,4.000000e+000,7.820129e-004,0.000000e+000,0,,0,
1524180915.363,,0.000000e+000,3.499872e+001,-8.859001e-006,0.000000e+000,3,8.934670e-001,0.000000e+000,,,,,,,,,,,,,,32,1,4.000000e+000,0.000000e+000,0.000000e+000,0,,0,
1524180953.476,,0.000000e+000,3.499950e+001,-8.833264e-006,0.000000e+000,3,8.946415e-001,0.000000e+000,,,,,,,,,,,,,,32,1,4.000000e+000,0.000000e+000,0.000000e+000,0,,0,
1524180991.559,,0.000000e+000,3.499989e+001,-8.829407e-006,0.000000e+000,3,8.931568e-001,0.000000e+000,,,,,,,,,,,,,,32,1,4.000000e+000,7.781982e-004,0.000000e+000,0,,0,
1524181029.687,,0.000000e+000,3.499950e+001,-8.793803e-006,0.000000e+000,3,8.970627e-001,0.000000e+000,,,,,,,,,,,,,,32,1,4.000000e+000,0.000000e+000,0.000000e+000,0,,0,
1524181067.177,,0.000000e+000,3.500106e+001,-8.761469e-006,0.000000e+000,3,8.938105e-001,0.000000e+000,,,,,,,,,,,,,,32,1,4.000000e+000,1.560211e-003,0.000000e+000,0,,0,
1524181105.268,,0.000000e+000,3.499754e+001,-8.706627e-006,0.000000e+000,3,8.938721e-001,0.000000e+000,,,,,,,,,,,,,,32,1,4.000000e+000,3.910065e-003,0.000000e+000,0,,0,
1524181143.329,,0.000000e+000,3.499950e+001,-8.635262e-006,0.000000e+000,3,8.921582e-001,0.000000e+000,,,,,,,,,,,,,,32,1,4.000000e+000,0.000000e+000,0.000000e+000,0,,0,
1524181181.457,,0.000000e+000,3.500185e+001,-8.652206e-006,0.000000e+000,3,8.945057e-001,0.000000e+000,,,,,,,,,,,,,,32,1,4.000000e+000,4.688263e-003,0.000000e+000,0,,0,
1524181219.670,,0.000000e+000,3.500106e+001,-8.598957e-006,0.000000e+000,3,8.885903e-001,0.000000e+000,,,,,,,,,,,,,,32,1,4.000000e+000,1.560211e-003,0.000000e+000,0,,0,
1524181257.780,,0.000000e+000,3.499950e+001,-8.640739e-006,0.000000e+000,3,8.933758e-001,0.000000e+000,,,,,,,,,,,,,,32,1,4.000000e+000,1.560211e-003,0.000000e+000,0,,0,
1524181295.603,,0.000000e+000,3.499871e+001,-8.567788e-006,0.000000e+000,3,8.920712e-001,0.000000e+000,,,,,,,,,,,,,,32,1,4.000000e+000,3.128052e-003,0.000000e+000,0,,0,
1524181334.626,,0.000000e+000,3.499872e+001,-8.595092e-006,0.000000e+000,3,8.940732e-001,0.000000e+000,,,,,,,,,,,,,,32,1,4.000000e+000,0.000000e+000,0.000000e+000,0,,0,
1524181372.577,,0.000000e+000,3.499911e+001,-8.574297e-006,0.000000e+000,3,8.891490e-001,0.000000e+000,,,,,,,,,,,,,,32,1,4.000000e+000,7.820129e-004,0.000000e+000,0,,0,
1524181409.722,,0.000000e+000,3.499871e+001,-8.542138e-006,0.000000e+000,3,8.896176e-001,0.000000e+000,,,,,,,,,,,,,,32,1,4.000000e+000,3.128052e-003,0.000000e+000,0,,0,
1524181447.561,,0.000000e+000,3.499833e+001,-8.508918e-006,0.000000e+000,3,8.884142e-001,0.000000e+000,,,,,,,,,,,,,,32,1,4.000000e+000,2.349854e-003,0.000000e+000,0,,0,
1524181485.904,,0.000000e+000,3.500106e+001,-8.411561e-006,0.000000e+000,3,8.843527e-001,0.000000e+000,,,,,,,,,,,,,,32,1,4.000000e+000,3.128052e-003,0.000000e+000,0,,0,
1524181524.009,,0.000000e+000,3.499911e+001,-8.477912e-006,0.000000e+000,3,8.938625e-001,0.000000e+000,,,,,,,,,,,,,,32,1,4.000000e+000,7.820129e-004,0.000000e+000,0,,0,
1524181561.465,,0.000000e+000,3.499989e+001,-8.440569e-006,0.000000e+000,3,8.863437e-001,0.000000e+000,,,,,,,,,,,,,,32,1,4.000000e+000,7.781982e-004,0.000000e+000,0,,0,
1524181599.175,,0.000000e+000,3.500067e+001,-8.405800e-006,0.000000e+000,3,8.866764e-001,0.000000e+000,,,,,,,,,,,,,,32,1,4.000000e+000,2.338409e-003,0.000000e+000,0,,0,
1524181637.818,,0.000000e+000,3.500028e+001,-8.379870e-006,0.000000e+000,3,8.914853e-001,0.000000e+000,,,,,,,,,,,,,,32,1,4.000000e+000,1.560211e-003,0.000000e+000,0,,0,
1524181674.924,,0.000000e+000,3.499911e+001,-8.387737e-006,0.000000e+000,3,8.885036e-001,0.000000e+000,,,,,,,,,,,,,,32,1,4.000000e+000,2.338409e-003,0.000000e+000,0,,0,
1524181712.904,,0.000000e+000,3.499950e+001,-8.361763e-006,0.000000e+000,3,8.924655e-001,0.000000e+000,,,,,,,,,,,,,,32,1,4.000000e+000,1.560211e-003,0.000000e+000,0,,0,
1524181750.670,,0.000000e+000,3.499989e+001,-8.304105e-006,0.000000e+000,3,8.813648e-001,0.000000e+000,,,,,,,,,,,,,,32,1,4.000000e+000,7.781982e-004,0.000000e+000,0,,0,
1524181788.648,,0.000000e+000,3.499989e+001,-8.347174e-006,0.000000e+000,3,8.853756e-001,0.000000e+000,,,,,,,,,,,,,,32,1,4.000000e+000,7.781982e-004,0.000000e+000,0,,0,
1524181826.761,,0.000000e+000,3.499989e+001,-8.366495e-006,0.000000e+000,3,8.884164e-001,0.000000e+000,,,,,,,,,,,,,,32,1,4.000000e+000,7.781982e-004,0.000000e+000,0,,0,
1524181864.854,,0.000000e+000,3.499950e+001,-8.295489e-006,0.000000e+000,3,8.884392e-001,0.000000e+000,,,,,,,,,,,,,,32,1,4.000000e+000,1.560211e-003,0.000000e+000,0,,0,
1524181902.615,,0.000000e+000,3.499872e+001,-8.243501e-006,0.000000e+000,3,8.886027e-001,0.000000e+000,,,,,,,,,,,,,,32,1,4.000000e+000,1.560211e-003,0.000000e+000,0,,0,
1524181942.008,,0.000000e+000,3.499833e+001,-8.226212e-006,0.000000e+000,3,8.874925e-001,0.000000e+000,,,,,,,,,,,,,,32,1,4.000000e+000,7.781982e-004,0.000000e+000,0,,0,
1524181979.201,,0.000000e+000,3.499793e+001,-8.234497e-006,0.000000e+000,3,8.885531e-001,0.000000e+000,,,,,,,,,,,,,,32,1,4.000000e+000,1.567841e-003,0.000000e+000,0,,0,
1524182016.889,,0.000000e+000,3.499833e+001,-8.249088e-006,0.000000e+000,3,8.897643e-001,0.000000e+000,,,,,,,,,,,,,,32,1,4.000000e+000,7.781982e-004,0.000000e+000,0,,0,
1524182054.557,,0.000000e+000,3.500067e+001,-8.185882e-006,0.000000e+000,3,8.883522e-001,0.000000e+000,,,,,,,,,,,,,,32,1,4.000000e+000,7.820129e-004,0.000000e+000,0,,0,
1524182093.150,,0.000000e+000,3.500028e+001,-8.190333e-006,0.000000e+000,3,8.904483e-001,0.000000e+000,,,,,,,,,,,,,,32,1,4.000000e+000,0.000000e+000,0.000000e+000,0,,0,
1524182131.246,,0.000000e+000,3.499911e+001,-8.030121e-006,0.000000e+000,3,8.875633e-001,0.000000e+000,,,,,,,,,,,,,,32,1,4.000000e+000,7.820129e-004,0.000000e+000,0,,0,
1524182168.884,,0.000000e+000,3.500067e+001,-8.170720e-006,0.000000e+000,3,8.920883e-001,0.000000e+000,,,,,,,,,,,,,,32,1,4.000000e+000,2.338409e-003,0.000000e+000,0,,0,
1524182207.667,,0.000000e+000,3.499872e+001,-8.112339e-006,0.000000e+000,3,8.791053e-001,0.000000e+000,,,,,,,,,,,,,,32,1,4.000000e+000,0.000000e+000,0.000000e+000,0,,0,
1524182245.762,,0.000000e+000,3.499950e+001,-8.063223e-006,0.000000e+000,3,8.863788e-001,0.000000e+000,,,,,,,,,,,,,,32,1,4.000000e+000,0.000000e+000,0.000000e+000,0,,0,
1524182283.198,,0.000000e+000,3.499793e+001,-8.117178e-006,0.000000e+000,3,8.774940e-001,0.000000e+000,,,,,,,,,,,,,,32,1,4.000000e+000,3.131866e-003,0.000000e+000,0,,0,
1524182321.243,,0.000000e+000,3.499872e+001,-8.070694e-006,0.000000e+000,3,8.824828e-001,0.000000e+000,,,,,,,,,,,,,,32,1,4.000000e+000,1.560211e-003,0.000000e+000,0,,0,
1524182359.344,,0.000000e+000,3.499950e+001,-8.045333e-006,0.000000e+000,3,8.855819e-001,0.000000e+000,,,,,,,,,,,,,,32,1,4.000000e+000,1.560211e-003,0.000000e+000,0,,0,
1524182397.459,,0.000000e+000,3.499793e+001,-8.034001e-006,0.000000e+000,3,8.834975e-001,0.000000e+000,,,,,,,,,,,,,,32,1,4.000000e+000,1.567841e-003,0.000000e+000,0,,0,
1524182435.125,,0.000000e+000,3.499950e+001,-8.051396e-006,0.000000e+000,3,8.878771e-001,0.000000e+000,,,,,,,,,,,,,,32,1,4.000000e+000,0.000000e+000,0.000000e+000,0,,0,
1524182472.573,,0.000000e+000,3.499950e+001,-8.041780e-006,0.000000e+000,3,8.885306e-001,0.000000e+000,,,,,,,,,,,,,,32,1,4.000000e+000,0.000000e+000,0.000000e+000,0,,0,
1524182511.114,,0.000000e+000,3.499872e+001,-7.994676e-006,0.000000e+000,3,8.879533e-001,0.000000e+000,,,,,,,,,,,,,,32,1,4.000000e+000,0.000000e+000,0.000000e+000,0,,0,
1524182548.434,,0.000000e+000,3.500067e+001,-7.951400e-006,0.000000e+000,3,8.802450e-001,0.000000e+000,,,,,,,,,,,,,,32,1,4.000000e+000,7.820129e-004,0.000000e+000,0,,0,
1524182586.717,,0.000000e+000,3.499911e+001,-7.970603e-006,0.000000e+000,3,8.798965e-001,0.000000e+000,,,,,,,,,,,,,,32,1,4.000000e+000,7.820129e-004,0.000000e+000,0,,0,
1524182624.568,,0.000000e+000,3.499950e+001,-7.877479e-006,0.000000e+000,3,8.878009e-001,0.000000e+000,,,,,,,,,,,,,,32,1,4.000000e+000,1.560211e-003,0.000000e+000,0,,0,
1524182662.421,,0.000000e+000,3.500067e+001,-7.879926e-006,0.000000e+000,3,8.840996e-001,0.000000e+000,,,,,,,,,,,,,,32,1,4.000000e+000,2.338409e-003,0.000000e+000,0,,0,
1524182700.554,,0.000000e+000,3.499871e+001,-7.855399e-006,0.000000e+000,3,8.823866e-001,0.000000e+000,,,,,,,,,,,,,,32,1,4.000000e+000,3.128052e-003,0.000000e+000,0,,0,
1524182738.667,,0.000000e+000,3.499833e+001,-7.917411e-006,0.000000e+000,3,8.877139e-001,0.000000e+000,,,,,,,,,,,,,,32,1,4.000000e+000,7.781982e-004,0.000000e+000,0,,0,
1524182776.723,,0.000000e+000,3.499950e+001,-7.875856e-006,0.000000e+000,3,8.716847e-001,0.000000e+000,,,,,,,,,,,,,,32,1,4.000000e+000,3.120422e-003,0.000000e+000,0,,0,
1524182814.836,,0.000000e+000,3.499911e+001,-7.807002e-006,0.000000e+000,3,8.826748e-001,0.000000e+000,,,,,,,,,,,,,,32,1,4.000000e+000,7.820129e-004,0.000000e+000,0,,0,
1524182853.091,,0.000000e+000,3.499872e+001,-7.853864e-006,0.000000e+000,3,8.883067e-001,0.000000e+000,,,,,,,,,,,,,,32,1,4.000000e+000,0.000000e+000,0.000000e+000,0,,0,
1524182890.544,,0.000000e+000,3.500028e+001,-7.753826e-006,0.000000e+000,3,8.808569e-001,0.000000e+000,,,,,,,,,,,,,,32,1,4.000000e+000,4.688263e-003,0.000000e+000,0,,0,
1524182928.645,,0.000000e+000,3.500028e+001,-7.734247e-006,0.000000e+000,3,8.754153e-001,0.000000e+000,,,,,,,,,,,,,,32,1,4.000000e+000,3.120422e-003,0.000000e+000,0,,0,
1524182966.413,,0.000000e+000,3.499872e+001,-7.753431e-006,0.000000e+000,3,8.773053e-001,0.000000e+000,,,,,,,,,,,,,,32,1,4.000000e+000,0.000000e+000,0.000000e+000,0,,0,
1524183004.113,,0.000000e+000,3.499911e+001,-7.744867e-006,0.000000e+000,3,8.871236e-001,0.000000e+000,,,,,,,,,,,,,,32,1,4.000000e+000,7.820129e-004,0.000000e+000,0,,0,
1524183042.076,,0.000000e+000,3.499911e+001,-7.772963e-006,0.000000e+000,3,8.781112e-001,0.000000e+000,,,,,,,,,,,,,,32,1,4.000000e+000,7.820129e-004,0.000000e+000,0,,0,
1524183080.555,,0.000000e+000,3.499989e+001,-7.722938e-006,0.000000e+000,3,8.793924e-001,0.000000e+000,,,,,,,,,,,,,,32,1,4.000000e+000,7.781982e-004,0.000000e+000,0,,0,
1524183118.678,,0.000000e+000,3.499950e+001,-7.717487e-006,0.000000e+000,3,8.808461e-001,0.000000e+000,,,,,,,,,,,,,,32,1,4.000000e+000,0.000000e+000,0.000000e+000,0,,0,
1524183157.841,,0.000000e+000,3.499911e+001,-7.725820e-006,0.000000e+000,3,8.832293e-001,0.000000e+000,,,,,,,,,,,,,,32,1,4.000000e+000,7.820129e-004,0.000000e+000,0,,0,
1524183196.076,,0.000000e+000,3.499911e+001,-7.673899e-006,0.000000e+000,3,8.862823e-001,0.000000e+000,,,,,,,,,,,,,,32,1,4.000000e+000,7.820129e-004,0.000000e+000,0,,0,
1524183234.272,,0.000000e+000,3.499911e+001,-7.660945e-006,0.000000e+000,3,8.819703e-001,0.000000e+000,,,,,,,,,,,,,,32,1,4.000000e+000,7.820129e-004,0.000000e+000,0,,0,
1524183271.937,,0.000000e+000,3.500185e+001,-7.631142e-006,0.000000e+000,3,8.783885e-001,0.000000e+000,,,,,,,,,,,,,,32,1,4.000000e+000,3.131866e-003,0.000000e+000,0,,0,
1524183309.880,,0.000000e+000,3.500028e+001,-7.615855e-006,0.000000e+000,3,8.827432e-001,0.000000e+000,,,,,,,,,,,,,,32,1,4.000000e+000,0.000000e+000,0.000000e+000,0,,0,
1524183347.578,,0.000000e+000,3.499911e+001,-7.575756e-006,0.000000e+000,3,8.774076e-001,0.000000e+000,,,,,,,,,,,,,,32,1,4.000000e+000,7.820129e-004,0.000000e+000,0,,0,
1524183386.339,,0.000000e+000,3.499911e+001,-7.605038e-006,0.000000e+000,3,8.828402e-001,0.000000e+000,,,,,,,,,,,,,,32,1,4.000000e+000,7.820129e-004,0.000000e+000,0,,0,
1524183423.755,,0.000000e+000,3.499989e+001,-7.544095e-006,0.000000e+000,3,8.772920e-001,0.000000e+000,,,,,,,,,,,,,,32,1,4.000000e+000,7.781982e-004,0.000000e+000,0,,0,
1524183461.855,,0.000000e+000,3.499911e+001,-7.420612e-006,0.000000e+000,3,8.752679e-001,0.000000e+000,,,,,,,,,,,,,,32,1,4.000000e+000,7.820129e-004,0.000000e+000,0,,0,
1524183499.963,,0.000000e+000,3.499872e+001,-7.562880e-006,0.000000e+000,3,8.823699e-001,0.000000e+000,,,,,,,,,,,,,,32,1,4.000000e+000,1.560211e-003,0.000000e+000,0,,0,
1524183538.079,,0.000000e+000,3.499950e+001,-7.504472e-006,0.000000e+000,3,8.750890e-001,0.000000e+000,,,,,,,,,,,,,,32,1,4.000000e+000,1.560211e-003,0.000000e+000,0,,0,
1524183576.082,,0.000000e+000,3.499872e+001,-7.526670e-006,0.000000e+000,3,8.753425e-001,0.000000e+000,,,,,,,,,,,,,,32,1,4.000000e+000,0.000000e+000,0.000000e+000,0,,0,
1524183613.900,,0.000000e+000,3.499989e+001,-7.485288e-006,0.000000e+000,3,8.845000e-001,0.000000e+000,,,,,,,,,,,,,,32,1,4.000000e+000,7.781982e-004,0.000000e+000,0,,0,
1524183652.000,,0.000000e+000,3.499872e+001,-7.429653e-006,0.000000e+000,3,8.747122e-001,0.000000e+000,,,,,,,,,,,,,,32,1,4.000000e+000,0.000000e+000,0.000000e+000,0,,0,
1524183689.613,,0.000000e+000,3.499872e+001,-7.397554e-006,0.000000e+000,3,8.735549e-001,0.000000e+000,,,,,,,,,,,,,,32,1,4.000000e+000,0.000000e+000,0.000000e+000,0,,0,
1524183727.562,,0.000000e+000,3.499950e+001,-7.452446e-006,0.000000e+000,3,8.682764e-001,0.000000e+000,,,,,,,,,,,,,,32,1,4.000000e+000,1.560211e-003,0.000000e+000,0,,0,
1524183765.680,,0.000000e+000,3.499872e+001,-7.450985e-006,0.000000e+000,3,8.758810e-001,0.000000e+000,,,,,,,,,,,,,,32,1,4.000000e+000,0.000000e+000,0.000000e+000,0,,0,
1524183803.680,,0.000000e+000,3.499911e+001,-7.366801e-006,0.000000e+000,3,8.769360e-001,0.000000e+000,,,,,,,,,,,,,,32,1,4.000000e+000,2.338409e-003,0.000000e+000,0,,0,
1524183842.356,,0.000000e+000,3.499872e+001,-7.355820e-006,0.000000e+000,3,8.732655e-001,0.000000e+000,,,,,,,,,,,,,,32,1,4.000000e+000,0.000000e+000,0.000000e+000,0,,0,
1524183879.996,,0.000000e+000,3.499911e+001,-7.393683e-006,0.000000e+000,3,8.808824e-001,0.000000e+000,,,,,,,,,,,,,,32,1,4.000000e+000,7.820129e-004,0.000000e+000,0,,0,
1524183917.999,,0.000000e+000,3.499872e+001,-7.325759e-006,0.000000e+000,3,8.756585e-001,0.000000e+000,,,,,,,,,,,,,,32,1,4.000000e+000,1.560211e-003,0.000000e+000,0,,0,
1524183956.622,,0.000000e+000,3.499950e+001,-7.293459e-006,0.000000e+000,3,8.725082e-001,0.000000e+000,,,,,,,,,,,,,,32,1,4.000000e+000,0.000000e+000,0.000000e+000,0,,0,
1524183994.993,,0.000000e+000,3.499794e+001,-7.334113e-006,0.000000e+000,3,8.681760e-001,0.000000e+000,,,,,,,,,,,,,,32,1,4.000000e+000,0.000000e+000,0.000000e+000,0,,0,
1524184033.383,,0.000000e+000,3.499677e+001,-7.242320e-006,0.000000e+000,3,8.747644e-001,0.000000e+000,,,,,,,,,,,,,,32,1,4.000000e+000,5.470276e-003,0.000000e+000,0,,0,
1524184071.314,,0.000000e+000,3.500028e+001,-7.261581e-006,0.000000e+000,3,8.663817e-001,0.000000e+000,,,,,,,,,,,,,,32,1,4.000000e+000,1.560211e-003,0.000000e+000,0,,0,
1524184109.505,,0.000000e+000,3.499950e+001,-7.313080e-006,0.000000e+000,3,8.784425e-001,0.000000e+000,,,,,,,,,,,,,,32,1,4.000000e+000,1.560211e-003,0.000000e+000,0,,0,
1524184147.655,,0.000000e+000,3.500028e+001,-7.272936e-006,0.000000e+000,3,8.800025e-001,0.000000e+000,,,,,,,,,,,,,,32,1,4.000000e+000,1.560211e-003,0.000000e+000,0,,0,
1524184185.618,,0.000000e+000,3.499950e+001,-7.266999e-006,0.000000e+000,3,8.785976e-001,0.000000e+000,,,,,,,,,,,,,,32,1,4.000000e+000,0.000000e+000,0.000000e+000,0,,0,
1524184224.391,,0.000000e+000,3.499950e+001,-7.182672e-006,0.000000e+000,3,8.724166e-001,0.000000e+000,,,,,,,,,,,,,,32,1,4.000000e+000,0.000000e+000,0.000000e+000,0,,0,
1524184262.612,,0.000000e+000,3.499911e+001,-7.211613e-006,0.000000e+000,3,8.737673e-001,0.000000e+000,,,,,,,,,,,,,,32,1,4.000000e+000,7.820129e-004,0.000000e+000,0,,0,
1524184300.657,,0.000000e+000,3.499950e+001,-7.184837e-006,0.000000e+000,3,8.721016e-001,0.000000e+000,,,,,,,,,,,,,,32,1,4.000000e+000,1.560211e-003,0.000000e+000,0,,0,
1524184338.750,,0.000000e+000,3.499872e+001,-7.194681e-006,0.000000e+000,3,8.742312e-001,0.000000e+000,,,,,,,,,,,,,,32,1,4.000000e+000,0.000000e+000,0.000000e+000,0,,0,
1524184376.921,,0.000000e+000,3.499911e+001,-7.167699e-006,0.000000e+000,3,8.738079e-001,0.000000e+000,,,,,,,,,,,,,,32,1,4.000000e+000,7.820129e-004,0.000000e+000,0,,0,
1524184414.987,,0.000000e+000,3.499872e+001,-7.157382e-006,0.000000e+000,3,8.729877e-001,0.000000e+000,,,,,,,,,,,,,,32,1,4.000000e+000,1.560211e-003,0.000000e+000,0,,0,
1524184453.075,,0.000000e+000,3.499872e+001,-7.129174e-006,0.000000e+000,3,8.728191e-001,0.000000e+000,,,,,,,,,,,,,,32,1,4.000000e+000,0.000000e+000,0.000000e+000,0,,0,
1524184491.530,,0.000000e+000,3.499950e+001,-7.115631e-006,0.000000e+000,3,8.704273e-001,0.000000e+000,,,,,,,,,,,,,,32,1,4.000000e+000,1.560211e-003,0.000000e+000,0,,0,
1524184528.858,,0.000000e+000,3.499989e+001,-7.155490e-006,0.000000e+000,3,8.740042e-001,0.000000e+000,,,,,,,,,,,,,,32,1,4.000000e+000,7.781982e-004,0.000000e+000,0,,0,
1524184566.854,,0.000000e+000,3.500028e+001,-7.073428e-006,0.000000e+000,3,8.685521e-001,0.000000e+000,,,,,,,,,,,,,,32,1,4.000000e+000,0.000000e+000,0.000000e+000,0,,0,
1524184605.229,,0.000000e+000,3.499950e+001,-7.106174e-006,0.000000e+000,3,8.689673e-001,0.000000e+000,,,,,,,,,,,,,,32,1,4.000000e+000,1.560211e-003,0.000000e+000,0,,0,
1524184642.647,,0.000000e+000,3.499989e+001,-7.080986e-006,0.000000e+000,3,8.694504e-001,0.000000e+000,,,,,,,,,,,,,,32,1,4.000000e+000,7.781982e-004,0.000000e+000,0,,0,
1524184681.325,,0.000000e+000,3.499989e+001,-7.047960e-006,0.000000e+000,3,8.665028e-001,0.000000e+000,,,,,,,,,,,,,,32,1,4.000000e+000,2.342224e-003,0.000000e+000,0,,0,
1524184719.526,,0.000000e+000,3.499911e+001,-7.036056e-006,0.000000e+000,3,8.685345e-001,0.000000e+000,,,,,,,,,,,,,,32,1,4.000000e+000,7.820129e-004,0.000000e+000,0,,0,
1524184757.777,,0.000000e+000,3.499950e+001,-6.980581e-006,0.000000e+000,3,8.644308e-001,0.000000e+000,,,,,,,,,,,,,,32,1,4.000000e+000,1.560211e-003,0.000000e+000,0,,0,
1524184783.152,,0.000000e+000,3.499872e+001,-7.078265e-006,0.000000e+000,3,8.697093e-001,0.000000e+000,,,,,,,,,,,,,,32,1,4.000000e+000,0.000000e+000,0.000000e+000,0,,0,