File: Experimental Raw Data/MFn1 VRM/Iterative Regression/MFn1_VRMac_33K_3000s_VRMde_35K.dc.dat
[Header]
TITLE,MPMS DC Measurement
BYAPP,MPMS Measurement,2.1,Summary
FILEOPENTIME, 1524152521.764000 4/19/2018, 9:42:01 AM

INFO, APPNAME, MPMS MultiVu Application, Revision 1.61,  Build 082

INFO, NAME, MFn1
INFO, WEIGHT, 1.000
INFO, AREA, 1.000
INFO, LENGTH, 1.000
INFO, SHAPE, 0
INFO, COMMENT,
INFO, SEQUENCE FILE: VRMac_33K_3000s_VRMde_35K.seq


INFO, BACKGROUND DATA FILE:, None


STARTUPAXIS,X,4,LINEAR,AUTO,0.000000,0.000000
STARTUPAXIS,Y1,5,LINEAR,AUTO,0.000000,0.000000


STARTUPGROUP,Longitudinal
FIELDGROUP,Longitudinal,1,2,3,4,5,6,7,8,9,15,16,17,18,27,28
FIELDGROUP,Transverse,1,2,3,4,10,11,12,13,14,19,20,21,22,27,28

PLOT_APPEARANCE,ALL,HORZ_GRID_ON,VERT_GRID_ON,MARKERS_AND_LINES

[Data]
Time,Comment,Field (Oe),Temperature (K),Long Moment (emu),Long Scan Std Dev,Long Algorithm,Long Reg Fit,Long Percent Error (%),Trans Moment (emu),Trans Scan Std Dev,Trans Algorithm,Trans Reg Fit,Trans Percent Error (%),Long Moment [w/o ABS] (emu),Long Scan Std Dev [w/o ABS],Long Reg Fit [w/o ABS],Long Percent Error [w/o ABS] (%),Trans Moment [w/o ABS] (emu),Trans Scan Std Dev [w/o ABS],Trans Reg Fit [w/o ABS],Trans Percent Error [w/o ABS] (%),Points per Scan,Scans per Measurement,Scan Length (cm),Delta Temp (K),Rot Position (deg),Error,EC Comp. Running,Using ABS,
1524152521.761,,0.000000e+000,3.318956e+001,-2.000759e-005,0.000000e+000,3,9.631699e-001,0.000000e+000,,,,,,,,,,,,,,32,1,4.000000e+000,3.744507e-001,0.000000e+000,0,,0,
1524152558.932,,0.000000e+000,3.483173e+001,-1.284389e-005,0.000000e+000,3,9.345432e-001,0.000000e+000,,,,,,,,,,,,,,32,1,4.000000e+000,2.059708e-001,0.000000e+000,0,,0,
1524152616.993,,0.000000e+000,3.500497e+001,-7.177540e-006,0.000000e+000,3,8.742381e-001,0.000000e+000,,,,,,,,,,,,,,32,1,4.000000e+000,7.827759e-003,0.000000e+000,0,,0,
1524152654.801,,0.000000e+000,3.499833e+001,-5.672742e-006,0.000000e+000,3,8.463461e-001,0.000000e+000,,,,,,,,,,,,,,32,1,4.000000e+000,7.781982e-004,0.000000e+000,0,,0,
1524152692.646,,0.000000e+000,3.499989e+001,-4.691992e-006,0.000000e+000,3,8.085581e-001,0.000000e+000,,,,,,,,,,,,,,32,1,4.000000e+000,7.781982e-004,0.000000e+000,0,,0,
1524152729.952,,0.000000e+000,3.499911e+001,-3.991421e-006,0.000000e+000,3,7.755465e-001,0.000000e+000,,,,,,,,,,,,,,32,1,4.000000e+000,7.820129e-004,0.000000e+000,0,,0,
1524152767.837,,0.000000e+000,3.500106e+001,-3.210463e-006,0.000000e+000,3,7.058946e-001,0.000000e+000,,,,,,,,,,,,,,32,1,4.000000e+000,3.128052e-003,0.000000e+000,0,,0,
1524152805.715,,0.000000e+000,3.499911e+001,-2.904882e-006,0.000000e+000,3,6.901941e-001,0.000000e+000,,,,,,,,,,,,,,32,1,4.000000e+000,7.820129e-004,0.000000e+000,0,,0,
1524152842.941,,0.000000e+000,3.499833e+001,-2.492224e-006,0.000000e+000,3,6.490626e-001,0.000000e+000,,,,,,,,,,,,,,32,1,4.000000e+000,2.349854e-003,0.000000e+000,0,,0,
1524152881.009,,0.000000e+000,3.499872e+001,-2.166728e-006,0.000000e+000,3,6.015637e-001,0.000000e+000,,,,,,,,,,,,,,32,1,4.000000e+000,1.560211e-003,0.000000e+000,0,,0,
1524152919.102,,0.000000e+000,3.499911e+001,-1.853653e-006,0.000000e+000,3,5.170704e-001,0.000000e+000,,,,,,,,,,,,,,32,1,4.000000e+000,7.820129e-004,0.000000e+000,0,,0,
1524152957.637,,0.000000e+000,3.499911e+001,-1.645609e-006,0.000000e+000,3,4.624950e-001,0.000000e+000,,,,,,,,,,,,,,32,1,4.000000e+000,7.820129e-004,0.000000e+000,0,,0,
1524152995.251,,0.000000e+000,3.499911e+001,-1.453172e-006,0.000000e+000,3,3.873350e-001,0.000000e+000,,,,,,,,,,,,,,32,1,4.000000e+000,7.820129e-004,0.000000e+000,0,,0,
1524153033.319,,0.000000e+000,3.499793e+001,-1.264153e-006,0.000000e+000,3,2.715179e-001,0.000000e+000,,,,,,,,,,,,,,32,1,4.000000e+000,1.567841e-003,0.000000e+000,0,,0,
1524153071.312,,0.000000e+000,3.499911e+001,-1.107865e-006,0.000000e+000,3,1.973144e-001,0.000000e+000,,,,,,,,,,,,,,32,1,4.000000e+000,7.820129e-004,0.000000e+000,0,,0,
1524153109.762,,0.000000e+000,3.499950e+001,-9.370962e-007,0.000000e+000,3,0.000000e+000,0.000000e+000,,,,,,,,,,,,,,32,1,4.000000e+000,0.000000e+000,0.000000e+000,0,,0,
1524153147.858,,0.000000e+000,3.499677e+001,-7.532402e-007,0.000000e+000,3,0.000000e+000,0.000000e+000,,,,,,,,,,,,,,32,1,4.000000e+000,2.349854e-003,0.000000e+000,0,,0,
1524153185.431,,0.000000e+000,3.499872e+001,-6.766565e-007,0.000000e+000,3,0.000000e+000,0.000000e+000,,,,,,,,,,,,,,32,1,4.000000e+000,1.560211e-003,0.000000e+000,0,,0,
1524153224.246,,0.000000e+000,3.500067e+001,-5.889702e-007,0.000000e+000,3,0.000000e+000,0.000000e+000,,,,,,,,,,,,,,32,1,4.000000e+000,7.820129e-004,0.000000e+000,0,,0,
1524153262.580,,0.000000e+000,3.499793e+001,-4.883445e-007,0.000000e+000,3,0.000000e+000,0.000000e+000,,,,,,,,,,,,,,32,1,4.000000e+000,1.567841e-003,0.000000e+000,0,,0,
1524153301.223,,0.000000e+000,3.499872e+001,-3.229487e-007,0.000000e+000,3,0.000000e+000,0.000000e+000,,,,,,,,,,,,,,32,1,4.000000e+000,0.000000e+000,0.000000e+000,0,,0,
1524153340.634,,0.000000e+000,3.499715e+001,-2.196458e-007,0.000000e+000,2,0.000000e+000,0.000000e+000,,,,,,,,,,,,,,32,1,4.000000e+000,3.128052e-003,0.000000e+000,0,,0,
1524153380.805,,0.000000e+000,3.499833e+001,-2.280149e-007,0.000000e+000,2,0.000000e+000,0.000000e+000,,,,,,,,,,,,,,32,1,4.000000e+000,7.781982e-004,0.000000e+000,0,,0,
1524153419.959,,0.000000e+000,3.499911e+001,3.352411e-008,0.000000e+000,3,0.000000e+000,0.000000e+000,,,,,,,,,,,,,,32,1,4.000000e+000,7.820129e-004,0.000000e+000,0,,0,
1524153460.100,,0.000000e+000,3.499833e+001,1.001733e-008,0.000000e+000,3,0.000000e+000,0.000000e+000,,,,,,,,,,,,,,32,1,4.000000e+000,7.781982e-004,0.000000e+000,0,,0,
1524153498.043,,0.000000e+000,3.499911e+001,-1.326115e-008,0.000000e+000,3,0.000000e+000,0.000000e+000,,,,,,,,,,,,,,32,1,4.000000e+000,7.820129e-004,0.000000e+000,0,,0,
1524153535.246,,0.000000e+000,3.499950e+001,8.514132e-008,0.000000e+000,3,0.000000e+000,0.000000e+000,,,,,,,,,,,,,,32,1,4.000000e+000,1.560211e-003,0.000000e+000,0,,0,
1524153573.024,,0.000000e+000,3.500106e+001,8.004332e-007,0.000000e+000,3,0.000000e+000,0.000000e+000,,,,,,,,,,,,,,32,1,4.000000e+000,0.000000e+000,0.000000e+000,0,,0,
1524153613.068,,0.000000e+000,3.499793e+001,6.905177e-008,0.000000e+000,2,0.000000e+000,0.000000e+000,,,,,,,,,,,,,,32,1,4.000000e+000,1.567841e-003,0.000000e+000,0,,0,
1524153651.271,,0.000000e+000,3.499833e+001,6.605023e-008,0.000000e+000,3,0.000000e+000,0.000000e+000,,,,,,,,,,,,,,32,1,4.000000e+000,2.349854e-003,0.000000e+000,0,,0,
1524153694.706,,0.000000e+000,3.499872e+001,2.302207e-007,0.000000e+000,2,0.000000e+000,0.000000e+000,,,,,,,,,,,,,,32,1,4.000000e+000,0.000000e+000,0.000000e+000,0,,0,
1524153733.727,,0.000000e+000,3.499950e+001,-2.311089e-007,0.000000e+000,3,0.000000e+000,0.000000e+000,,,,,,,,,,,,,,32,1,4.000000e+000,1.560211e-003,0.000000e+000,0,,0,
1524153773.065,,0.000000e+000,3.499989e+001,-2.525501e-007,0.000000e+000,3,0.000000e+000,0.000000e+000,,,,,,,,,,,,,,32,1,4.000000e+000,7.781982e-004,0.000000e+000,0,,0,
1524153810.986,,0.000000e+000,3.499911e+001,-2.366473e-007,0.000000e+000,3,0.000000e+000,0.000000e+000,,,,,,,,,,,,,,32,1,4.000000e+000,7.820129e-004,0.000000e+000,0,,0,
1524153850.740,,0.000000e+000,3.499950e+001,3.931584e-007,0.000000e+000,2,0.000000e+000,0.000000e+000,,,,,,,,,,,,,,32,1,4.000000e+000,1.560211e-003,0.000000e+000,0,,0,
1524153893.419,,0.000000e+000,3.499833e+001,4.927791e-007,0.000000e+000,2,0.000000e+000,0.000000e+000,,,,,,,,,,,,,,32,1,4.000000e+000,7.781982e-004,0.000000e+000,0,,0,
1524153936.164,,0.000000e+000,3.499950e+001,4.885151e-007,0.000000e+000,2,0.000000e+000,0.000000e+000,,,,,,,,,,,,,,32,1,4.000000e+000,0.000000e+000,0.000000e+000,0,,0,
1524153978.138,,0.000000e+000,3.499950e+001,1.112096e-006,0.000000e+000,3,2.039221e-001,0.000000e+000,,,,,,,,,,,,,,32,1,4.000000e+000,0.000000e+000,0.000000e+000,0,,0,
1524154020.070,,0.000000e+000,3.499872e+001,1.125850e-006,0.000000e+000,3,1.489438e-001,0.000000e+000,,,,,,,,,,,,,,32,1,4.000000e+000,0.000000e+000,0.000000e+000,0,,0,
1524154057.983,,0.000000e+000,3.499833e+001,1.028920e-006,0.000000e+000,3,1.083236e-001,0.000000e+000,,,,,,,,,,,,,,32,1,4.000000e+000,7.781982e-004,0.000000e+000,0,,0,
1524154095.686,,0.000000e+000,3.499715e+001,1.141400e-006,0.000000e+000,3,1.649370e-001,0.000000e+000,,,,,,,,,,,,,,32,1,4.000000e+000,3.128052e-003,0.000000e+000,0,,0,
1524154135.539,,0.000000e+000,3.500028e+001,1.287301e-006,0.000000e+000,3,3.079649e-001,0.000000e+000,,,,,,,,,,,,,,32,1,4.000000e+000,3.120422e-003,0.000000e+000,0,,0,
1524154173.135,,0.000000e+000,3.499950e+001,1.198100e-006,0.000000e+000,3,2.465613e-001,0.000000e+000,,,,,,,,,,,,,,32,1,4.000000e+000,0.000000e+000,0.000000e+000,0,,0,
1524154211.320,,0.000000e+000,3.499911e+001,1.253200e-006,0.000000e+000,3,2.897274e-001,0.000000e+000,,,,,,,,,,,,,,32,1,4.000000e+000,7.820129e-004,0.000000e+000,0,,0,
1524154249.383,,0.000000e+000,3.499911e+001,1.223391e-006,0.000000e+000,3,2.748313e-001,0.000000e+000,,,,,,,,,,,,,,32,1,4.000000e+000,7.820129e-004,0.000000e+000,0,,0,
1524154286.941,,0.000000e+000,3.499911e+001,1.228596e-006,0.000000e+000,3,2.341033e-001,0.000000e+000,,,,,,,,,,,,,,32,1,4.000000e+000,2.338409e-003,0.000000e+000,0,,0,
1524154325.540,,0.000000e+000,3.499872e+001,1.371139e-006,0.000000e+000,3,3.405131e-001,0.000000e+000,,,,,,,,,,,,,,32,1,4.000000e+000,0.000000e+000,0.000000e+000,0,,0,
1524154362.545,,0.000000e+000,3.499872e+001,1.228480e-006,0.000000e+000,3,2.899470e-001,0.000000e+000,,,,,,,,,,,,,,32,1,4.000000e+000,0.000000e+000,0.000000e+000,0,,0,
1524154400.261,,0.000000e+000,3.499911e+001,1.312133e-006,0.000000e+000,3,3.287590e-001,0.000000e+000,,,,,,,,,,,,,,32,1,4.000000e+000,7.820129e-004,0.000000e+000,0,,0,
1524154438.224,,0.000000e+000,3.499911e+001,1.319868e-006,0.000000e+000,3,3.018823e-001,0.000000e+000,,,,,,,,,,,,,,32,1,4.000000e+000,7.820129e-004,0.000000e+000,0,,0,
1524154476.784,,0.000000e+000,3.499911e+001,1.304465e-006,0.000000e+000,3,3.030784e-001,0.000000e+000,,,,,,,,,,,,,,32,1,4.000000e+000,7.820129e-004,0.000000e+000,0,,0,
1524154515.022,,0.000000e+000,3.499872e+001,1.394597e-006,0.000000e+000,3,3.664278e-001,0.000000e+000,,,,,,,,,,,,,,32,1,4.000000e+000,0.000000e+000,0.000000e+000,0,,0,
1524154553.080,,0.000000e+000,3.499950e+001,1.358288e-006,0.000000e+000,3,3.370371e-001,0.000000e+000,,,,,,,,,,,,,,32,1,4.000000e+000,1.560211e-003,0.000000e+000,0,,0,
1524154591.226,,0.000000e+000,3.499950e+001,1.301852e-006,0.000000e+000,3,2.924904e-001,0.000000e+000,,,,,,,,,,,,,,32,1,4.000000e+000,0.000000e+000,0.000000e+000,0,,0,
1524154628.814,,0.000000e+000,3.499911e+001,1.408908e-006,0.000000e+000,3,3.685751e-001,0.000000e+000,,,,,,,,,,,,,,32,1,4.000000e+000,7.820129e-004,0.000000e+000,0,,0,
1524154666.787,,0.000000e+000,3.499911e+001,1.383918e-006,0.000000e+000,3,3.618242e-001,0.000000e+000,,,,,,,,,,,,,,32,1,4.000000e+000,7.820129e-004,0.000000e+000,0,,0,
1524154705.408,,0.000000e+000,3.499911e+001,1.484078e-006,0.000000e+000,3,3.831295e-001,0.000000e+000,,,,,,,,,,,,,,32,1,4.000000e+000,7.820129e-004,0.000000e+000,0,,0,
1524154743.866,,0.000000e+000,3.499793e+001,1.471991e-006,0.000000e+000,3,3.955049e-001,0.000000e+000,,,,,,,,,,,,,,32,1,4.000000e+000,1.567841e-003,0.000000e+000,0,,0,
1524154781.389,,0.000000e+000,3.499833e+001,1.463663e-006,0.000000e+000,3,3.799399e-001,0.000000e+000,,,,,,,,,,,,,,32,1,4.000000e+000,2.349854e-003,0.000000e+000,0,,0,
1524154819.117,,0.000000e+000,3.500145e+001,1.482909e-006,0.000000e+000,3,4.014479e-001,0.000000e+000,,,,,,,,,,,,,,32,1,4.000000e+000,2.349854e-003,0.000000e+000,0,,0,
1524154856.650,,0.000000e+000,3.499950e+001,1.453294e-006,0.000000e+000,3,3.505783e-001,0.000000e+000,,,,,,,,,,,,,,32,1,4.000000e+000,1.560211e-003,0.000000e+000,0,,0,
1524154894.778,,0.000000e+000,3.499911e+001,1.523606e-006,0.000000e+000,3,4.434051e-001,0.000000e+000,,,,,,,,,,,,,,32,1,4.000000e+000,7.820129e-004,0.000000e+000,0,,0,
1524154932.781,,0.000000e+000,3.499872e+001,1.535538e-006,0.000000e+000,3,4.035917e-001,0.000000e+000,,,,,,,,,,,,,,32,1,4.000000e+000,0.000000e+000,0.000000e+000,0,,0,
1524154970.962,,0.000000e+000,3.499950e+001,1.518261e-006,0.000000e+000,3,4.251069e-001,0.000000e+000,,,,,,,,,,,,,,32,1,4.000000e+000,0.000000e+000,0.000000e+000,0,,0,
1524155009.317,,0.000000e+000,3.499911e+001,1.479470e-006,0.000000e+000,3,3.842974e-001,0.000000e+000,,,,,,,,,,,,,,32,1,4.000000e+000,7.820129e-004,0.000000e+000,0,,0,
1524155047.415,,0.000000e+000,3.499950e+001,1.504959e-006,0.000000e+000,3,3.944129e-001,0.000000e+000,,,,,,,,,,,,,,32,1,4.000000e+000,1.560211e-003,0.000000e+000,0,,0,
1524155085.953,,0.000000e+000,3.499872e+001,1.537502e-006,0.000000e+000,3,4.359791e-001,0.000000e+000,,,,,,,,,,,,,,32,1,4.000000e+000,0.000000e+000,0.000000e+000,0,,0,
1524155124.699,,0.000000e+000,3.499833e+001,1.584085e-006,0.000000e+000,3,4.287021e-001,0.000000e+000,,,,,,,,,,,,,,32,1,4.000000e+000,7.781982e-004,0.000000e+000,0,,0,
1524155163.102,,0.000000e+000,3.499950e+001,1.582456e-006,0.000000e+000,3,4.346712e-001,0.000000e+000,,,,,,,,,,,,,,32,1,4.000000e+000,3.120422e-003,0.000000e+000,0,,0,
1524155201.157,,0.000000e+000,3.499911e+001,1.585540e-006,0.000000e+000,3,4.510312e-001,0.000000e+000,,,,,,,,,,,,,,32,1,4.000000e+000,7.820129e-004,0.000000e+000,0,,0,
1524155239.301,,0.000000e+000,3.499872e+001,1.586298e-006,0.000000e+000,3,4.250625e-001,0.000000e+000,,,,,,,,,,,,,,32,1,4.000000e+000,1.560211e-003,0.000000e+000,0,,0,
1524155277.211,,0.000000e+000,3.499833e+001,1.557414e-006,0.000000e+000,3,4.010871e-001,0.000000e+000,,,,,,,,,,,,,,32,1,4.000000e+000,7.781982e-004,0.000000e+000,0,,0,
1524155315.564,,0.000000e+000,3.499950e+001,1.639954e-006,0.000000e+000,3,4.430084e-001,0.000000e+000,,,,,,,,,,,,,,32,1,4.000000e+000,0.000000e+000,0.000000e+000,0,,0,
1524155353.630,,0.000000e+000,3.499911e+001,1.520731e-006,0.000000e+000,3,4.088467e-001,0.000000e+000,,,,,,,,,,,,,,32,1,4.000000e+000,7.820129e-004,0.000000e+000,0,,0,
1524155391.700,,0.000000e+000,3.499911e+001,1.623676e-006,0.000000e+000,3,4.676720e-001,0.000000e+000,,,,,,,,,,,,,,32,1,4.000000e+000,7.820129e-004,0.000000e+000,0,,0,
1524155429.763,,0.000000e+000,3.499989e+001,1.642887e-006,0.000000e+000,3,4.538508e-001,0.000000e+000,,,,,,,,,,,,,,32,1,4.000000e+000,7.781982e-004,0.000000e+000,0,,0,
1524155467.871,,0.000000e+000,3.499950e+001,1.682216e-006,0.000000e+000,3,4.622930e-001,0.000000e+000,,,,,,,,,,,,,,32,1,4.000000e+000,0.000000e+000,0.000000e+000,0,,0,
1524155505.929,,0.000000e+000,3.499911e+001,1.694852e-006,0.000000e+000,3,4.761858e-001,0.000000e+000,,,,,,,,,,,,,,32,1,4.000000e+000,7.820129e-004,0.000000e+000,0,,0,
1524155543.460,,0.000000e+000,3.499911e+001,1.708291e-006,0.000000e+000,3,4.867956e-001,0.000000e+000,,,,,,,,,,,,,,32,1,4.000000e+000,7.820129e-004,0.000000e+000,0,,0,
1524155581.535,,0.000000e+000,3.499950e+001,1.638308e-006,0.000000e+000,3,4.538835e-001,0.000000e+000,,,,,,,,,,,,,,32,1,4.000000e+000,0.000000e+000,0.000000e+000,0,,0,
1524155619.651,,0.000000e+000,3.500028e+001,1.673015e-006,0.000000e+000,3,4.659360e-001,0.000000e+000,,,,,,,,,,,,,,32,1,4.000000e+000,1.560211e-003,0.000000e+000,0,,0,
1524155657.684,,0.000000e+000,3.500028e+001,1.689485e-006,0.000000e+000,3,4.523097e-001,0.000000e+000,,,,,,,,,,,,,,32,1,4.000000e+000,1.560211e-003,0.000000e+000,0,,0,
1524155695.552,,0.000000e+000,3.499833e+001,1.757551e-006,0.000000e+000,3,4.720014e-001,0.000000e+000,,,,,,,,,,,,,,32,1,4.000000e+000,7.781982e-004,0.000000e+000,0,,0,
1524155733.103,,0.000000e+000,3.499872e+001,1.730306e-006,0.000000e+000,3,4.676460e-001,0.000000e+000,,,,,,,,,,,,,,32,1,4.000000e+000,1.560211e-003,0.000000e+000,0,,0,
1524155770.851,,0.000000e+000,3.499911e+001,1.726750e-006,0.000000e+000,3,5.225245e-001,0.000000e+000,,,,,,,,,,,,,,32,1,4.000000e+000,7.820129e-004,0.000000e+000,0,,0,
1524155808.734,,0.000000e+000,3.500106e+001,1.704405e-006,0.000000e+000,3,4.469154e-001,0.000000e+000,,,,,,,,,,,,,,32,1,4.000000e+000,1.560211e-003,0.000000e+000,0,,0,
1524155846.597,,0.000000e+000,3.499871e+001,1.716458e-006,0.000000e+000,3,4.899465e-001,0.000000e+000,,,,,,,,,,,,,,32,1,4.000000e+000,3.128052e-003,0.000000e+000,0,,0,
1524155884.653,,0.000000e+000,3.499871e+001,1.721155e-006,0.000000e+000,3,4.530169e-001,0.000000e+000,,,,,,,,,,,,,,32,1,4.000000e+000,3.128052e-003,0.000000e+000,0,,0,
1524155922.516,,0.000000e+000,3.499833e+001,1.712276e-006,0.000000e+000,3,4.665624e-001,0.000000e+000,,,,,,,,,,,,,,32,1,4.000000e+000,2.349854e-003,0.000000e+000,0,,0,
1524155960.514,,0.000000e+000,3.499950e+001,1.693105e-006,0.000000e+000,3,4.593000e-001,0.000000e+000,,,,,,,,,,,,,,32,1,4.000000e+000,3.120422e-003,0.000000e+000,0,,0,
1524155998.479,,0.000000e+000,3.499950e+001,1.776308e-006,0.000000e+000,3,5.245036e-001,0.000000e+000,,,,,,,,,,,,,,32,1,4.000000e+000,0.000000e+000,0.000000e+000,0,,0,
1524156037.020,,0.000000e+000,3.499872e+001,1.813669e-006,0.000000e+000,3,4.887917e-001,0.000000e+000,,,,,,,,,,,,,,32,1,4.000000e+000,1.560211e-003,0.000000e+000,0,,0,
1524156074.590,,0.000000e+000,3.499794e+001,1.732298e-006,0.000000e+000,3,5.002222e-001,0.000000e+000,,,,,,,,,,,,,,32,1,4.000000e+000,0.000000e+000,0.000000e+000,0,,0,
1524156112.413,,0.000000e+000,3.500067e+001,1.781659e-006,0.000000e+000,3,4.821350e-001,0.000000e+000,,,,,,,,,,,,,,32,1,4.000000e+000,7.820129e-004,0.000000e+000,0,,0,
1524156149.829,,0.000000e+000,3.499833e+001,1.784982e-006,0.000000e+000,3,4.683675e-001,0.000000e+000,,,,,,,,,,,,,,32,1,4.000000e+000,7.781982e-004,0.000000e+000,0,,0,
1524156187.732,,0.000000e+000,3.500028e+001,1.798435e-006,0.000000e+000,3,5.030264e-001,0.000000e+000,,,,,,,,,,,,,,32,1,4.000000e+000,0.000000e+000,0.000000e+000,0,,0,
1524156225.730,,0.000000e+000,3.499911e+001,1.780189e-006,0.000000e+000,3,5.007051e-001,0.000000e+000,,,,,,,,,,,,,,32,1,4.000000e+000,7.820129e-004,0.000000e+000,0,,0,
1524156263.410,,0.000000e+000,3.499950e+001,1.691455e-006,0.000000e+000,3,4.931799e-001,0.000000e+000,,,,,,,,,,,,,,32,1,4.000000e+000,0.000000e+000,0.000000e+000,0,,0,
1524156301.511,,0.000000e+000,3.499872e+001,1.720041e-006,0.000000e+000,3,4.513736e-001,0.000000e+000,,,,,,,,,,,,,,32,1,4.000000e+000,0.000000e+000,0.000000e+000,0,,0,
1524156338.502,,0.000000e+000,3.499911e+001,1.780728e-006,0.000000e+000,3,5.136794e-001,0.000000e+000,,,,,,,,,,,,,,32,1,4.000000e+000,7.820129e-004,0.000000e+000,0,,0,
1524156376.455,,0.000000e+000,3.499911e+001,1.759735e-006,0.000000e+000,3,4.973212e-001,0.000000e+000,,,,,,,,,,,,,,32,1,4.000000e+000,7.820129e-004,0.000000e+000,0,,0,
1524156414.523,,0.000000e+000,3.499989e+001,1.749463e-006,0.000000e+000,3,4.812497e-001,0.000000e+000,,,,,,,,,,,,,,32,1,4.000000e+000,7.781982e-004,0.000000e+000,0,,0,
1524156452.063,,0.000000e+000,3.499872e+001,1.766629e-006,0.000000e+000,3,4.691845e-001,0.000000e+000,,,,,,,,,,,,,,32,1,4.000000e+000,0.000000e+000,0.000000e+000,0,,0,
1524156490.129,,0.000000e+000,3.499911e+001,1.783598e-006,0.000000e+000,3,5.214043e-001,0.000000e+000,,,,,,,,,,,,,,32,1,4.000000e+000,7.820129e-004,0.000000e+000,0,,0,
1524156528.177,,0.000000e+000,3.499950e+001,1.846064e-006,0.000000e+000,3,5.162498e-001,0.000000e+000,,,,,,,,,,,,,,32,1,4.000000e+000,1.560211e-003,0.000000e+000,0,,0,
1524156566.845,,0.000000e+000,3.499911e+001,1.834020e-006,0.000000e+000,3,4.820169e-001,0.000000e+000,,,,,,,,,,,,,,32,1,4.000000e+000,7.820129e-004,0.000000e+000,0,,0,
1524156603.838,,0.000000e+000,3.499911e+001,1.806948e-006,0.000000e+000,3,4.683816e-001,0.000000e+000,,,,,,,,,,,,,,32,1,4.000000e+000,7.820129e-004,0.000000e+000,0,,0,
1524156641.931,,0.000000e+000,3.499950e+001,1.814979e-006,0.000000e+000,3,4.998496e-001,0.000000e+000,,,,,,,,,,,,,,32,1,4.000000e+000,1.560211e-003,0.000000e+000,0,,0,
1524156680.102,,0.000000e+000,3.500028e+001,1.769767e-006,0.000000e+000,3,4.835601e-001,0.000000e+000,,,,,,,,,,,,,,32,1,4.000000e+000,1.560211e-003,0.000000e+000,0,,0,
1524156718.172,,0.000000e+000,3.499911e+001,1.811329e-006,0.000000e+000,3,4.976421e-001,0.000000e+000,,,,,,,,,,,,,,32,1,4.000000e+000,7.820129e-004,0.000000e+000,0,,0,
1524156756.170,,0.000000e+000,3.499872e+001,1.848648e-006,0.000000e+000,3,5.304912e-001,0.000000e+000,,,,,,,,,,,,,,32,1,4.000000e+000,0.000000e+000,0.000000e+000,0,,0,
1524156794.183,,0.000000e+000,3.499872e+001,1.886665e-006,0.000000e+000,3,5.512138e-001,0.000000e+000,,,,,,,,,,,,,,32,1,4.000000e+000,1.560211e-003,0.000000e+000,0,,0,
1524156832.326,,0.000000e+000,3.499793e+001,1.786684e-006,0.000000e+000,3,5.156226e-001,0.000000e+000,,,,,,,,,,,,,,32,1,4.000000e+000,3.131866e-003,0.000000e+000,0,,0,
1524156869.849,,0.000000e+000,3.499872e+001,1.814248e-006,0.000000e+000,3,4.950435e-001,0.000000e+000,,,,,,,,,,,,,,32,1,4.000000e+000,0.000000e+000,0.000000e+000,0,,0,
1524156907.952,,0.000000e+000,3.499872e+001,1.809577e-006,0.000000e+000,3,4.852076e-001,0.000000e+000,,,,,,,,,,,,,,32,1,4.000000e+000,1.560211e-003,0.000000e+000,0,,0,
1524156946.050,,0.000000e+000,3.499911e+001,1.932078e-006,0.000000e+000,3,5.605769e-001,0.000000e+000,,,,,,,,,,,,,,32,1,4.000000e+000,7.820129e-004,0.000000e+000,0,,0,
1524156983.104,,0.000000e+000,3.499911e+001,1.791679e-006,0.000000e+000,3,4.854605e-001,0.000000e+000,,,,,,,,,,,,,,32,1,4.000000e+000,7.820129e-004,0.000000e+000,0,,0,
1524157020.982,,0.000000e+000,3.499715e+001,1.894099e-006,0.000000e+000,3,5.259831e-001,0.000000e+000,,,,,,,,,,,,,,32,1,4.000000e+000,3.128052e-003,0.000000e+000,0,,0,
1524157058.290,,0.000000e+000,3.499950e+001,1.860503e-006,0.000000e+000,3,5.185078e-001,0.000000e+000,,,,,,,,,,,,,,32,1,4.000000e+000,1.560211e-003,0.000000e+000,0,,0,
1524157096.813,,0.000000e+000,3.500263e+001,1.873298e-006,0.000000e+000,3,5.029548e-001,0.000000e+000,,,,,,,,,,,,,,32,1,4.000000e+000,4.699707e-003,0.000000e+000,0,,0,
1524157134.886,,0.000000e+000,3.499872e+001,1.873523e-006,0.000000e+000,3,5.151784e-001,0.000000e+000,,,,,,,,,,,,,,32,1,4.000000e+000,1.560211e-003,0.000000e+000,0,,0,
1524157172.696,,0.000000e+000,3.499950e+001,1.993368e-006,0.000000e+000,3,5.387488e-001,0.000000e+000,,,,,,,,,,,,,,32,1,4.000000e+000,0.000000e+000,0.000000e+000,0,,0,
1524157210.807,,0.000000e+000,3.499871e+001,1.936508e-006,0.000000e+000,3,5.422661e-001,0.000000e+000,,,,,,,,,,,,,,32,1,4.000000e+000,3.128052e-003,0.000000e+000,0,,0,
1524157249.090,,0.000000e+000,3.499872e+001,1.863313e-006,0.000000e+000,3,5.203524e-001,0.000000e+000,,,,,,,,,,,,,,32,1,4.000000e+000,0.000000e+000,0.000000e+000,0,,0,
1524157287.616,,0.000000e+000,3.500067e+001,1.888067e-006,0.000000e+000,3,5.326120e-001,0.000000e+000,,,,,,,,,,,,,,32,1,4.000000e+000,2.338409e-003,0.000000e+000,0,,0,
1524157325.649,,0.000000e+000,3.499872e+001,1.890669e-006,0.000000e+000,3,5.257931e-001,0.000000e+000,,,,,,,,,,,,,,32,1,4.000000e+000,0.000000e+000,0.000000e+000,0,,0,
1524157363.704,,0.000000e+000,3.499950e+001,1.926083e-006,0.000000e+000,3,5.341550e-001,0.000000e+000,,,,,,,,,,,,,,32,1,4.000000e+000,0.000000e+000,0.000000e+000,0,,0,
1524157402.387,,0.000000e+000,3.499911e+001,1.896698e-006,0.000000e+000,3,5.383957e-001,0.000000e+000,,,,,,,,,,,,,,32,1,4.000000e+000,7.820129e-004,0.000000e+000,0,,0,
1524157439.890,,0.000000e+000,3.499520e+001,1.905096e-006,0.000000e+000,3,5.477821e-001,0.000000e+000,,,,,,,,,,,,,,32,1,4.000000e+000,7.820129e-004,0.000000e+000,0,,0,
1524157477.751,,0.000000e+000,3.499872e+001,1.967585e-006,0.000000e+000,3,5.478593e-001,0.000000e+000,,,,,,,,,,,,,,32,1,4.000000e+000,0.000000e+000,0.000000e+000,0,,0,
1524157515.764,,0.000000e+000,3.499950e+001,1.846505e-006,0.000000e+000,3,5.414333e-001,0.000000e+000,,,,,,,,,,,,,,32,1,4.000000e+000,1.560211e-003,0.000000e+000,0,,0,
1524157553.912,,0.000000e+000,3.499950e+001,1.927172e-006,0.000000e+000,3,5.747578e-001,0.000000e+000,,,,,,,,,,,,,,32,1,4.000000e+000,0.000000e+000,0.000000e+000,0,,0,
1524157591.912,,0.000000e+000,3.499950e+001,1.889695e-006,0.000000e+000,3,5.165108e-001,0.000000e+000,,,,,,,,,,,,,,32,1,4.000000e+000,0.000000e+000,0.000000e+000,0,,0,
1524157629.795,,0.000000e+000,3.500106e+001,1.873770e-006,0.000000e+000,3,5.469986e-001,0.000000e+000,,,,,,,,,,,,,,32,1,4.000000e+000,4.692078e-003,0.000000e+000,0,,0,
1524157667.549,,0.000000e+000,3.499872e+001,1.849897e-006,0.000000e+000,3,5.162960e-001,0.000000e+000,,,,,,,,,,,,,,32,1,4.000000e+000,1.560211e-003,0.000000e+000,0,,0,
1524157705.399,,0.000000e+000,3.500028e+001,1.916183e-006,0.000000e+000,3,5.225971e-001,0.000000e+000,,,,,,,,,,,,,,32,1,4.000000e+000,4.688263e-003,0.000000e+000,0,,0,
1524157743.985,,0.000000e+000,3.499911e+001,1.883149e-006,0.000000e+000,3,5.411698e-001,0.000000e+000,,,,,,,,,,,,,,32,1,4.000000e+000,7.820129e-004,0.000000e+000,0,,0,
1524157781.695,,0.000000e+000,3.499911e+001,1.902750e-006,0.000000e+000,3,5.454223e-001,0.000000e+000,,,,,,,,,,,,,,32,1,4.000000e+000,7.820129e-004,0.000000e+000,0,,0,
1524157819.126,,0.000000e+000,3.499911e+001,1.853895e-006,0.000000e+000,3,5.382761e-001,0.000000e+000,,,,,,,,,,,,,,32,1,4.000000e+000,7.820129e-004,0.000000e+000,0,,0,
1524157857.521,,0.000000e+000,3.499793e+001,1.928729e-006,0.000000e+000,3,5.531659e-001,0.000000e+000,,,,,,,,,,,,,,32,1,4.000000e+000,3.131866e-003,0.000000e+000,0,,0,
1524157895.564,,0.000000e+000,3.499911e+001,1.873529e-006,0.000000e+000,3,5.251248e-001,0.000000e+000,,,,,,,,,,,,,,32,1,4.000000e+000,7.820129e-004,0.000000e+000,0,,0,
1524157933.518,,0.000000e+000,3.499872e+001,1.925016e-006,0.000000e+000,3,5.263577e-001,0.000000e+000,,,,,,,,,,,,,,32,1,4.000000e+000,0.000000e+000,0.000000e+000,0,,0,
1524157971.328,,0.000000e+000,3.499911e+001,1.961743e-006,0.000000e+000,3,5.643743e-001,0.000000e+000,,,,,,,,,,,,,,32,1,4.000000e+000,7.820129e-004,0.000000e+000,0,,0,
1524158009.414,,0.000000e+000,3.499950e+001,1.942607e-006,0.000000e+000,3,5.386651e-001,0.000000e+000,,,,,,,,,,,,,,32,1,4.000000e+000,0.000000e+000,0.000000e+000,0,,0,
1524158047.374,,0.000000e+000,3.499871e+001,1.912197e-006,0.000000e+000,3,5.632036e-001,0.000000e+000,,,,,,,,,,,,,,32,1,4.000000e+000,3.128052e-003,0.000000e+000,0,,0,
1524158084.917,,0.000000e+000,3.499598e+001,2.018746e-006,0.000000e+000,3,5.582861e-001,0.000000e+000,,,,,,,,,,,,,,32,1,4.000000e+000,5.477905e-003,0.000000e+000,0,,0,
1524158124.305,,0.000000e+000,3.500185e+001,1.878735e-006,0.000000e+000,3,5.615920e-001,0.000000e+000,,,,,,,,,,,,,,32,1,4.000000e+000,6.259918e-003,0.000000e+000,0,,0,
1524158162.668,,0.000000e+000,3.499950e+001,1.909902e-006,0.000000e+000,3,5.342744e-001,0.000000e+000,,,,,,,,,,,,,,32,1,4.000000e+000,1.560211e-003,0.000000e+000,0,,0,
1524158200.979,,0.000000e+000,3.499950e+001,1.912430e-006,0.000000e+000,3,5.277756e-001,0.000000e+000,,,,,,,,,,,,,,32,1,4.000000e+000,0.000000e+000,0.000000e+000,0,,0,
1524158238.702,,0.000000e+000,3.500028e+001,1.914148e-006,0.000000e+000,3,5.322549e-001,0.000000e+000,,,,,,,,,,,,,,32,1,4.000000e+000,1.560211e-003,0.000000e+000,0,,0,
1524158277.055,,0.000000e+000,3.499754e+001,1.932028e-006,0.000000e+000,3,5.344111e-001,0.000000e+000,,,,,,,,,,,,,,32,1,4.000000e+000,2.349854e-003,0.000000e+000,0,,0,
1524158315.116,,0.000000e+000,3.499911e+001,1.859900e-006,0.000000e+000,3,5.440114e-001,0.000000e+000,,,,,,,,,,,,,,32,1,4.000000e+000,7.820129e-004,0.000000e+000,0,,0,
1524158353.186,,0.000000e+000,3.499950e+001,1.882776e-006,0.000000e+000,3,5.278882e-001,0.000000e+000,,,,,,,,,,,,,,32,1,4.000000e+000,0.000000e+000,0.000000e+000,0,,0,
1524158391.282,,0.000000e+000,3.499989e+001,2.001331e-006,0.000000e+000,3,5.138065e-001,0.000000e+000,,,,,,,,,,,,,,32,1,4.000000e+000,7.781982e-004,0.000000e+000,0,,0,
1524158429.817,,0.000000e+000,3.499950e+001,1.946586e-006,0.000000e+000,3,5.420027e-001,0.000000e+000,,,,,,,,,,,,,,32,1,4.000000e+000,0.000000e+000,0.000000e+000,0,,0,
1524158467.630,,0.000000e+000,3.499911e+001,1.946135e-006,0.000000e+000,3,5.293415e-001,0.000000e+000,,,,,,,,,,,,,,32,1,4.000000e+000,7.820129e-004,0.000000e+000,0,,0,
1524158505.353,,0.000000e+000,3.499950e+001,1.926560e-006,0.000000e+000,3,5.160975e-001,0.000000e+000,,,,,,,,,,,,,,32,1,4.000000e+000,1.560211e-003,0.000000e+000,0,,0,
1524158543.264,,0.000000e+000,3.499911e+001,1.944015e-006,0.000000e+000,3,5.415379e-001,0.000000e+000,,,,,,,,,,,,,,32,1,4.000000e+000,7.820129e-004,0.000000e+000,0,,0,
1524158581.367,,0.000000e+000,3.499872e+001,2.004124e-006,0.000000e+000,3,5.356857e-001,0.000000e+000,,,,,,,,,,,,,,32,1,4.000000e+000,0.000000e+000,0.000000e+000,0,,0,
1524158619.253,,0.000000e+000,3.500185e+001,2.002028e-006,0.000000e+000,3,5.381960e-001,0.000000e+000,,,,,,,,,,,,,,32,1,4.000000e+000,4.688263e-003,0.000000e+000,0,,0,
1524158657.003,,0.000000e+000,3.500067e+001,1.968237e-006,0.000000e+000,3,5.908169e-001,0.000000e+000,,,,,,,,,,,,,,32,1,4.000000e+000,2.338409e-003,0.000000e+000,0,,0,
1524158693.739,,0.000000e+000,3.499911e+001,1.943957e-006,0.000000e+000,3,5.487293e-001,0.000000e+000,,,,,,,,,,,,,,32,1,4.000000e+000,7.820129e-004,0.000000e+000,0,,0,
1524158731.694,,0.000000e+000,3.499989e+001,1.980851e-006,0.000000e+000,3,5.396411e-001,0.000000e+000,,,,,,,,,,,,,,32,1,4.000000e+000,7.781982e-004,0.000000e+000,0,,0,
1524158769.740,,0.000000e+000,3.499950e+001,1.935093e-006,0.000000e+000,3,5.328403e-001,0.000000e+000,,,,,,,,,,,,,,32,1,4.000000e+000,0.000000e+000,0.000000e+000,0,,0,
1524158807.215,,0.000000e+000,3.499833e+001,1.937658e-006,0.000000e+000,3,5.260938e-001,0.000000e+000,,,,,,,,,,,,,,32,1,4.000000e+000,2.349854e-003,0.000000e+000,0,,0,
1524158844.586,,0.000000e+000,3.499911e+001,1.908035e-006,0.000000e+000,3,5.390901e-001,0.000000e+000,,,,,,,,,,,,,,32,1,4.000000e+000,7.820129e-004,0.000000e+000,0,,0,
1524158882.671,,0.000000e+000,3.500028e+001,1.935458e-006,0.000000e+000,3,5.450944e-001,0.000000e+000,,,,,,,,,,,,,,32,1,4.000000e+000,1.560211e-003,0.000000e+000,0,,0,
1524158921.467,,0.000000e+000,3.499911e+001,2.014199e-006,0.000000e+000,3,5.626660e-001,0.000000e+000,,,,,,,,,,,,,,32,1,4.000000e+000,7.820129e-004,0.000000e+000,0,,0,
1524158958.828,,0.000000e+000,3.499950e+001,2.071478e-006,0.000000e+000,3,5.870879e-001,0.000000e+000,,,,,,,,,,,,,,32,1,4.000000e+000,0.000000e+000,0.000000e+000,0,,0,
1524158996.921,,0.000000e+000,3.499872e+001,1.976381e-006,0.000000e+000,3,5.615780e-001,0.000000e+000,,,,,,,,,,,,,,32,1,4.000000e+000,0.000000e+000,0.000000e+000,0,,0,
1524159034.236,,0.000000e+000,3.499872e+001,1.927258e-006,0.000000e+000,3,5.264496e-001,0.000000e+000,,,,,,,,,,,,,,32,1,4.000000e+000,0.000000e+000,0.000000e+000,0,,0,
1524159072.207,,0.000000e+000,3.499833e+001,1.973205e-006,0.000000e+000,3,5.407715e-001,0.000000e+000,,,,,,,,,,,,,,32,1,4.000000e+000,2.349854e-003,0.000000e+000,0,,0,
1524159109.877,,0.000000e+000,3.499872e+001,1.964462e-006,0.000000e+000,3,5.452326e-001,0.000000e+000,,,,,,,,,,,,,,32,1,4.000000e+000,0.000000e+000,0.000000e+000,0,,0,
1524159147.298,,0.000000e+000,3.499833e+001,1.991878e-006,0.000000e+000,3,5.367776e-001,0.000000e+000,,,,,,,,,,,,,,32,1,4.000000e+000,7.781982e-004,0.000000e+000,0,,0,
1524159184.708,,0.000000e+000,3.499950e+001,1.958588e-006,0.000000e+000,3,5.611234e-001,0.000000e+000,,,,,,,,,,,,,,32,1,4.000000e+000,0.000000e+000,0.000000e+000,0,,0,
1524159222.791,,0.000000e+000,3.499950e+001,1.937591e-006,0.000000e+000,3,5.586826e-001,0.000000e+000,,,,,,,,,,,,,,32,1,4.000000e+000,0.000000e+000,0.000000e+000,0,,0,
1524159260.842,,0.000000e+000,3.499872e+001,1.971059e-006,0.000000e+000,3,5.604928e-001,0.000000e+000,,,,,,,,,,,,,,32,1,4.000000e+000,0.000000e+000,0.000000e+000,0,,0,
1524159298.850,,0.000000e+000,3.499950e+001,1.977132e-006,0.000000e+000,3,5.516239e-001,0.000000e+000,,,,,,,,,,,,,,32,1,4.000000e+000,0.000000e+000,0.000000e+000,0,,0,
1524159337.431,,0.000000e+000,3.499950e+001,1.957173e-006,0.000000e+000,3,5.360246e-001,0.000000e+000,,,,,,,,,,,,,,32,1,4.000000e+000,0.000000e+000,0.000000e+000,0,,0,
1524159375.281,,0.000000e+000,3.499872e+001,1.994407e-006,0.000000e+000,3,5.543154e-001,0.000000e+000,,,,,,,,,,,,,,32,1,4.000000e+000,0.000000e+000,0.000000e+000,0,,0,
1524159413.342,,0.000000e+000,3.499911e+001,2.025520e-006,0.000000e+000,3,5.575497e-001,0.000000e+000,,,,,,,,,,,,,,32,1,4.000000e+000,7.820129e-004,0.000000e+000,0,,0,
1524159451.562,,0.000000e+000,3.499911e+001,1.978541e-006,0.000000e+000,3,5.516732e-001,0.000000e+000,,,,,,,,,,,,,,32,1,4.000000e+000,7.820129e-004,0.000000e+000,0,,0,
1524159489.645,,0.000000e+000,3.499911e+001,1.984238e-006,0.000000e+000,3,5.532789e-001,0.000000e+000,,,,,,,,,,,,,,32,1,4.000000e+000,7.820129e-004,0.000000e+000,0,,0,
1524159527.741,,0.000000e+000,3.499989e+001,1.985058e-006,0.000000e+000,3,5.466451e-001,0.000000e+000,,,,,,,,,,,,,,32,1,4.000000e+000,7.781982e-004,0.000000e+000,0,,0,
1524159565.829,,0.000000e+000,3.499911e+001,1.941347e-006,0.000000e+000,3,5.483040e-001,0.000000e+000,,,,,,,,,,,,,,32,1,4.000000e+000,7.820129e-004,0.000000e+000,0,,0,
1524159603.910,,0.000000e+000,3.499911e+001,1.993412e-006,0.000000e+000,3,5.579835e-001,0.000000e+000,,,,,,,,,,,,,,32,1,4.000000e+000,7.820129e-004,0.000000e+000,0,,0,
1524159642.013,,0.000000e+000,3.499911e+001,2.017883e-006,0.000000e+000,3,5.435324e-001,0.000000e+000,,,,,,,,,,,,,,32,1,4.000000e+000,7.820129e-004,0.000000e+000,0,,0,
1524159680.648,,0.000000e+000,3.499911e+001,2.001929e-006,0.000000e+000,3,5.583997e-001,0.000000e+000,,,,,,,,,,,,,,32,1,4.000000e+000,7.820129e-004,0.000000e+000,0,,0,
1524159718.726,,0.000000e+000,3.499950e+001,1.927197e-006,0.000000e+000,3,5.421078e-001,0.000000e+000,,,,,,,,,,,,,,32,1,4.000000e+000,0.000000e+000,0.000000e+000,0,,0,
1524159755.687,,0.000000e+000,3.499950e+001,1.957869e-006,0.000000e+000,3,5.464775e-001,0.000000e+000,,,,,,,,,,,,,,32,1,4.000000e+000,1.560211e-003,0.000000e+000,0,,0,
1524159793.807,,0.000000e+000,3.499793e+001,2.044282e-006,0.000000e+000,3,5.660074e-001,0.000000e+000,,,,,,,,,,,,,,32,1,4.000000e+000,1.567841e-003,0.000000e+000,0,,0,
1524159831.908,,0.000000e+000,3.499989e+001,1.952718e-006,0.000000e+000,3,5.536679e-001,0.000000e+000,,,,,,,,,,,,,,32,1,4.000000e+000,7.781982e-004,0.000000e+000,0,,0,
1524159870.523,,0.000000e+000,3.499911e+001,2.007009e-006,0.000000e+000,3,5.747022e-001,0.000000e+000,,,,,,,,,,,,,,32,1,4.000000e+000,7.820129e-004,0.000000e+000,0,,0,
1524159908.089,,0.000000e+000,3.499989e+001,1.985588e-006,0.000000e+000,3,5.514910e-001,0.000000e+000,,,,,,,,,,,,,,32,1,4.000000e+000,3.898621e-003,0.000000e+000,0,,0,
1524159946.130,,0.000000e+000,3.499872e+001,1.980069e-006,0.000000e+000,3,5.321685e-001,0.000000e+000,,,,,,,,,,,,,,32,1,4.000000e+000,0.000000e+000,0.000000e+000,0,,0,
1524159984.760,,0.000000e+000,3.499911e+001,2.026384e-006,0.000000e+000,3,5.681300e-001,0.000000e+000,,,,,,,,,,,,,,32,1,4.000000e+000,7.820129e-004,0.000000e+000,0,,0,
1524160022.873,,0.000000e+000,3.499872e+001,2.015174e-006,0.000000e+000,3,5.476921e-001,0.000000e+000,,,,,,,,,,,,,,32,1,4.000000e+000,0.000000e+000,0.000000e+000,0,,0,
1524160061.499,,0.000000e+000,3.499911e+001,2.062609e-006,0.000000e+000,3,5.661461e-001,0.000000e+000,,,,,,,,,,,,,,32,1,4.000000e+000,7.820129e-004,0.000000e+000,0,,0,
1524160099.544,,0.000000e+000,3.499872e+001,2.085681e-006,0.000000e+000,3,5.811811e-001,0.000000e+000,,,,,,,,,,,,,,32,1,4.000000e+000,1.560211e-003,0.000000e+000,0,,0,
1524160137.510,,0.000000e+000,3.499950e+001,2.019715e-006,0.000000e+000,3,5.669289e-001,0.000000e+000,,,,,,,,,,,,,,32,1,4.000000e+000,0.000000e+000,0.000000e+000,0,,0,
1524160175.618,,0.000000e+000,3.499754e+001,2.060162e-006,0.000000e+000,3,5.648146e-001,0.000000e+000,,,,,,,,,,,,,,32,1,4.000000e+000,2.349854e-003,0.000000e+000,0,,0,
1524160213.713,,0.000000e+000,3.500185e+001,2.021627e-006,0.000000e+000,3,5.615155e-001,0.000000e+000,,,,,,,,,,,,,,32,1,4.000000e+000,4.688263e-003,0.000000e+000,0,,0,
1524160251.642,,0.000000e+000,3.499911e+001,1.997178e-006,0.000000e+000,3,5.393909e-001,0.000000e+000,,,,,,,,,,,,,,32,1,4.000000e+000,7.820129e-004,0.000000e+000,0,,0,
1524160290.650,,0.000000e+000,3.500028e+001,2.039985e-006,0.000000e+000,3,5.592988e-001,0.000000e+000,,,,,,,,,,,,,,32,1,4.000000e+000,0.000000e+000,0.000000e+000,0,,0,
1524160328.038,,0.000000e+000,3.499950e+001,2.001938e-006,0.000000e+000,3,5.502019e-001,0.000000e+000,,,,,,,,,,,,,,32,1,4.000000e+000,0.000000e+000,0.000000e+000,0,,0,
1524160366.158,,0.000000e+000,3.499989e+001,2.058342e-006,0.000000e+000,3,5.626228e-001,0.000000e+000,,,,,,,,,,,,,,32,1,4.000000e+000,2.342224e-003,0.000000e+000,0,,0,
1524160404.256,,0.000000e+000,3.499872e+001,2.019811e-006,0.000000e+000,3,5.595888e-001,0.000000e+000,,,,,,,,,,,,,,32,1,4.000000e+000,0.000000e+000,0.000000e+000,0,,0,
1524160442.944,,0.000000e+000,3.499872e+001,1.980256e-006,0.000000e+000,3,5.509116e-001,0.000000e+000,,,,,,,,,,,,,,32,1,4.000000e+000,0.000000e+000,0.000000e+000,0,,0,
1524160481.145,,0.000000e+000,3.499911e+001,2.003923e-006,0.000000e+000,3,5.696817e-001,0.000000e+000,,,,,,,,,,,,,,32,1,4.000000e+000,7.820129e-004,0.000000e+000,0,,0,
1524160519.163,,0.000000e+000,3.499872e+001,2.012222e-006,0.000000e+000,3,5.495877e-001,0.000000e+000,,,,,,,,,,,,,,32,1,4.000000e+000,0.000000e+000,0.000000e+000,0,,0,
1524160557.314,,0.000000e+000,3.499911e+001,2.046289e-006,0.000000e+000,3,5.657253e-001,0.000000e+000,,,,,,,,,,,,,,32,1,4.000000e+000,7.820129e-004,0.000000e+000,0,,0,
1524160595.409,,0.000000e+000,3.499794e+001,2.028596e-006,0.000000e+000,3,5.575193e-001,0.000000e+000,,,,,,,,,,,,,,32,1,4.000000e+000,0.000000e+000,0.000000e+000,0,,0,
1524160633.785,,0.000000e+000,3.499833e+001,2.091671e-006,0.000000e+000,3,5.571844e-001,0.000000e+000,,,,,,,,,,,,,,32,1,4.000000e+000,7.781982e-004,0.000000e+000,0,,0,
1524160671.870,,0.000000e+000,3.499911e+001,2.025428e-006,0.000000e+000,3,5.602053e-001,0.000000e+000,,,,,,,,,,,,,,32,1,4.000000e+000,7.820129e-004,0.000000e+000,0,,0,
1524160709.641,,0.000000e+000,3.500067e+001,2.012136e-006,0.000000e+000,3,5.451599e-001,0.000000e+000,,,,,,,,,,,,,,32,1,4.000000e+000,2.338409e-003,0.000000e+000,0,,0,
1524160747.991,,0.000000e+000,3.499989e+001,2.007833e-006,0.000000e+000,3,5.501408e-001,0.000000e+000,,,,,,,,,,,,,,32,1,4.000000e+000,7.781982e-004,0.000000e+000,0,,0,
1524160786.039,,0.000000e+000,3.499872e+001,2.036013e-006,0.000000e+000,3,5.610822e-001,0.000000e+000,,,,,,,,,,,,,,32,1,4.000000e+000,0.000000e+000,0.000000e+000,0,,0,
1524160825.225,,0.000000e+000,3.499950e+001,2.023162e-006,0.000000e+000,3,5.457855e-001,0.000000e+000,,,,,,,,,,,,,,32,1,4.000000e+000,1.560211e-003,0.000000e+000,0,,0,
1524160863.300,,0.000000e+000,3.499911e+001,2.042324e-006,0.000000e+000,3,5.589648e-001,0.000000e+000,,,,,,,,,,,,,,32,1,4.000000e+000,7.820129e-004,0.000000e+000,0,,0,
1524160901.534,,0.000000e+000,3.499872e+001,2.041975e-006,0.000000e+000,3,5.800878e-001,0.000000e+000,,,,,,,,,,,,,,32,1,4.000000e+000,0.000000e+000,0.000000e+000,0,,0,
1524160940.512,,0.000000e+000,3.499793e+001,2.287821e-006,0.000000e+000,3,5.808814e-001,0.000000e+000,,,,,,,,,,,,,,32,1,4.000000e+000,1.567841e-003,0.000000e+000,0,,0,
1524160977.535,,0.000000e+000,3.499833e+001,2.088100e-006,0.000000e+000,3,5.712275e-001,0.000000e+000,,,,,,,,,,,,,,32,1,4.000000e+000,7.781982e-004,0.000000e+000,0,,0,
1524161015.593,,0.000000e+000,3.499872e+001,2.082514e-006,0.000000e+000,3,5.585693e-001,0.000000e+000,,,,,,,,,,,,,,32,1,4.000000e+000,0.000000e+000,0.000000e+000,0,,0,
1524161053.813,,0.000000e+000,3.499872e+001,2.079639e-006,0.000000e+000,3,5.752637e-001,0.000000e+000,,,,,,,,,,,,,,32,1,4.000000e+000,0.000000e+000,0.000000e+000,0,,0,
1524161091.764,,0.000000e+000,3.499677e+001,2.042384e-006,0.000000e+000,3,5.764549e-001,0.000000e+000,,,,,,,,,,,,,,32,1,4.000000e+000,5.470276e-003,0.000000e+000,0,,0,
1524161129.959,,0.000000e+000,3.499911e+001,2.062861e-006,0.000000e+000,3,5.678281e-001,0.000000e+000,,,,,,,,,,,,,,32,1,4.000000e+000,3.910065e-003,0.000000e+000,0,,0,
1524161167.955,,0.000000e+000,3.499911e+001,2.058199e-006,0.000000e+000,3,5.680578e-001,0.000000e+000,,,,,,,,,,,,,,32,1,4.000000e+000,7.820129e-004,0.000000e+000,0,,0,
1524161205.453,,0.000000e+000,3.499911e+001,2.092425e-006,0.000000e+000,3,5.779826e-001,0.000000e+000,,,,,,,,,,,,,,32,1,4.000000e+000,7.820129e-004,0.000000e+000,0,,0,
1524161243.569,,0.000000e+000,3.500028e+001,2.121589e-006,0.000000e+000,3,5.813468e-001,0.000000e+000,,,,,,,,,,,,,,32,1,4.000000e+000,0.000000e+000,0.000000e+000,0,,0,
1524161281.677,,0.000000e+000,3.499872e+001,2.092077e-006,0.000000e+000,3,5.808880e-001,0.000000e+000,,,,,,,,,,,,,,32,1,4.000000e+000,0.000000e+000,0.000000e+000,0,,0,
1524161319.700,,0.000000e+000,3.499911e+001,2.064853e-006,0.000000e+000,3,5.696412e-001,0.000000e+000,,,,,,,,,,,,,,32,1,4.000000e+000,7.820129e-004,0.000000e+000,0,,0,
1524161357.055,,0.000000e+000,3.499989e+001,2.068926e-006,0.000000e+000,3,5.655863e-001,0.000000e+000,,,,,,,,,,,,,,32,1,4.000000e+000,7.781982e-004,0.000000e+000,0,,0,
1524161394.783,,0.000000e+000,3.499872e+001,2.109037e-006,0.000000e+000,3,5.714021e-001,0.000000e+000,,,,,,,,,,,,,,32,1,4.000000e+000,1.560211e-003,0.000000e+000,0,,0,
1524161432.676,,0.000000e+000,3.499950e+001,2.113401e-006,0.000000e+000,3,5.779644e-001,0.000000e+000,,,,,,,,,,,,,,32,1,4.000000e+000,1.560211e-003,0.000000e+000,0,,0,
1524161470.692,,0.000000e+000,3.499950e+001,2.056054e-006,0.000000e+000,3,5.617013e-001,0.000000e+000,,,,,,,,,,,,,,32,1,4.000000e+000,1.560211e-003,0.000000e+000,0,,0,
1524161508.567,,0.000000e+000,3.500067e+001,2.036332e-006,0.000000e+000,3,5.705390e-001,0.000000e+000,,,,,,,,,,,,,,32,1,4.000000e+000,7.820129e-004,0.000000e+000,0,,0,
1524161546.416,,0.000000e+000,3.499872e+001,2.061041e-006,0.000000e+000,3,5.704767e-001,0.000000e+000,,,,,,,,,,,,,,32,1,4.000000e+000,1.560211e-003,0.000000e+000,0,,0,
1524161584.344,,0.000000e+000,3.499911e+001,2.039844e-006,0.000000e+000,3,5.666692e-001,0.000000e+000,,,,,,,,,,,,,,32,1,4.000000e+000,7.820129e-004,0.000000e+000,0,,0,
1524161622.799,,0.000000e+000,3.499872e+001,2.117739e-006,0.000000e+000,3,5.754619e-001,0.000000e+000,,,,,,,,,,,,,,32,1,4.000000e+000,1.560211e-003,0.000000e+000,0,,0,
1524161660.305,,0.000000e+000,3.499989e+001,2.058475e-006,0.000000e+000,3,5.701674e-001,0.000000e+000,,,,,,,,,,,,,,32,1,4.000000e+000,7.781982e-004,0.000000e+000,0,,0,
1524161698.393,,0.000000e+000,3.500028e+001,2.003244e-006,0.000000e+000,3,5.466182e-001,0.000000e+000,,,,,,,,,,,,,,32,1,4.000000e+000,0.000000e+000,0.000000e+000,0,,0,
1524161736.483,,0.000000e+000,3.500028e+001,2.050578e-006,0.000000e+000,3,5.871573e-001,0.000000e+000,,,,,,,,,,,,,,32,1,4.000000e+000,1.560211e-003,0.000000e+000,0,,0,
1524161774.094,,0.000000e+000,3.499950e+001,2.036320e-006,0.000000e+000,3,5.703943e-001,0.000000e+000,,,,,,,,,,,,,,32,1,4.000000e+000,1.560211e-003,0.000000e+000,0,,0,
1524161811.889,,0.000000e+000,3.500067e+001,2.065686e-006,0.000000e+000,3,5.589419e-001,0.000000e+000,,,,,,,,,,,,,,32,1,4.000000e+000,2.338409e-003,0.000000e+000,0,,0,
1524161850.207,,0.000000e+000,3.499911e+001,2.070524e-006,0.000000e+000,3,5.640675e-001,0.000000e+000,,,,,,,,,,,,,,32,1,4.000000e+000,7.820129e-004,0.000000e+000,0,,0,
1524161888.096,,0.000000e+000,3.499950e+001,2.037374e-006,0.000000e+000,3,5.690576e-001,0.000000e+000,,,,,,,,,,,,,,32,1,4.000000e+000,0.000000e+000,0.000000e+000,0,,0,
1524161925.896,,0.000000e+000,3.499911e+001,2.046917e-006,0.000000e+000,3,5.500405e-001,0.000000e+000,,,,,,,,,,,,,,32,1,4.000000e+000,7.820129e-004,0.000000e+000,0,,0,
1524161963.997,,0.000000e+000,3.499950e+001,2.055954e-006,0.000000e+000,3,5.630130e-001,0.000000e+000,,,,,,,,,,,,,,32,1,4.000000e+000,0.000000e+000,0.000000e+000,0,,0,
1524162002.087,,0.000000e+000,3.499950e+001,2.050679e-006,0.000000e+000,3,5.684398e-001,0.000000e+000,,,,,,,,,,,,,,32,1,4.000000e+000,0.000000e+000,0.000000e+000,0,,0,
1524162040.280,,0.000000e+000,3.499950e+001,2.061491e-006,0.000000e+000,3,5.660343e-001,0.000000e+000,,,,,,,,,,,,,,32,1,4.000000e+000,0.000000e+000,0.000000e+000,0,,0,
1524162078.223,,0.000000e+000,3.499911e+001,2.049502e-006,0.000000e+000,3,5.680658e-001,0.000000e+000,,,,,,,,,,,,,,32,1,4.000000e+000,7.820129e-004,0.000000e+000,0,,0,
1524162116.429,,0.000000e+000,3.499911e+001,2.046763e-006,0.000000e+000,3,5.739682e-001,0.000000e+000,,,,,,,,,,,,,,32,1,4.000000e+000,7.820129e-004,0.000000e+000,0,,0,
1524162154.402,,0.000000e+000,3.499950e+001,2.055649e-006,0.000000e+000,3,5.673239e-001,0.000000e+000,,,,,,,,,,,,,,32,1,4.000000e+000,0.000000e+000,0.000000e+000,0,,0,
1524162192.295,,0.000000e+000,3.499950e+001,2.042528e-006,0.000000e+000,3,5.488492e-001,0.000000e+000,,,,,,,,,,,,,,32,1,4.000000e+000,1.560211e-003,0.000000e+000,0,,0,
1524162230.118,,0.000000e+000,3.499989e+001,2.072693e-006,0.000000e+000,3,5.603316e-001,0.000000e+000,,,,,,,,,,,,,,32,1,4.000000e+000,7.781982e-004,0.000000e+000,0,,0,
1524162267.499,,0.000000e+000,3.499911e+001,1.992970e-006,0.000000e+000,3,5.678000e-001,0.000000e+000,,,,,,,,,,,,,,32,1,4.000000e+000,7.820129e-004,0.000000e+000,0,,0,
1524162305.587,,0.000000e+000,3.499950e+001,2.089115e-006,0.000000e+000,3,5.823248e-001,0.000000e+000,,,,,,,,,,,,,,32,1,4.000000e+000,0.000000e+000,0.000000e+000,0,,0,
1524162343.680,,0.000000e+000,3.499833e+001,2.044811e-006,0.000000e+000,3,5.540417e-001,0.000000e+000,,,,,,,,,,,,,,32,1,4.000000e+000,7.781982e-004,0.000000e+000,0,,0,
1524162381.783,,0.000000e+000,3.499911e+001,2.079553e-006,0.000000e+000,3,5.575967e-001,0.000000e+000,,,,,,,,,,,,,,32,1,4.000000e+000,2.338409e-003,0.000000e+000,0,,0,
1524162419.926,,0.000000e+000,3.499950e+001,2.111627e-006,0.000000e+000,3,5.840564e-001,0.000000e+000,,,,,,,,,,,,,,32,1,4.000000e+000,0.000000e+000,0.000000e+000,0,,0,
1524162458.629,,0.000000e+000,3.500067e+001,2.042187e-006,0.000000e+000,3,5.629665e-001,0.000000e+000,,,,,,,,,,,,,,32,1,4.000000e+000,7.820129e-004,0.000000e+000,0,,0,
1524162495.579,,0.000000e+000,3.499989e+001,2.041145e-006,0.000000e+000,3,5.618061e-001,0.000000e+000,,,,,,,,,,,,,,32,1,4.000000e+000,7.781982e-004,0.000000e+000,0,,0,
1524162533.665,,0.000000e+000,3.499872e+001,2.036067e-006,0.000000e+000,3,5.650477e-001,0.000000e+000,,,,,,,,,,,,,,32,1,4.000000e+000,0.000000e+000,0.000000e+000,0,,0,
1524162571.736,,0.000000e+000,3.499833e+001,2.048156e-006,0.000000e+000,3,5.596192e-001,0.000000e+000,,,,,,,,,,,,,,32,1,4.000000e+000,2.349854e-003,0.000000e+000,0,,0,
1524162610.419,,0.000000e+000,3.499989e+001,2.034865e-006,0.000000e+000,3,5.674456e-001,0.000000e+000,,,,,,,,,,,,,,32,1,4.000000e+000,7.781982e-004,0.000000e+000,0,,0,
1524162647.392,,0.000000e+000,3.499911e+001,2.052270e-006,0.000000e+000,3,5.718738e-001,0.000000e+000,,,,,,,,,,,,,,32,1,4.000000e+000,7.820129e-004,0.000000e+000,0,,0,
1524162685.487,,0.000000e+000,3.499950e+001,2.019758e-006,0.000000e+000,3,5.622536e-001,0.000000e+000,,,,,,,,,,,,,,32,1,4.000000e+000,0.000000e+000,0.000000e+000,0,,0,
1524162723.673,,0.000000e+000,3.499911e+001,2.010139e-006,0.000000e+000,3,5.421272e-001,0.000000e+000,,,,,,,,,,,,,,32,1,4.000000e+000,7.820129e-004,0.000000e+000,0,,0,
1524162761.641,,0.000000e+000,3.499872e+001,1.969938e-006,0.000000e+000,3,5.578030e-001,0.000000e+000,,,,,,,,,,,,,,32,1,4.000000e+000,1.560211e-003,0.000000e+000,0,,0,
1524162800.314,,0.000000e+000,3.499911e+001,2.022067e-006,0.000000e+000,3,5.621292e-001,0.000000e+000,,,,,,,,,,,,,,32,1,4.000000e+000,7.820129e-004,0.000000e+000,0,,0,
1524162837.302,,0.000000e+000,3.499872e+001,2.041198e-006,0.000000e+000,3,5.849633e-001,0.000000e+000,,,,,,,,,,,,,,32,1,4.000000e+000,1.560211e-003,0.000000e+000,0,,0,
1524162875.390,,0.000000e+000,3.499911e+001,2.038240e-006,0.000000e+000,3,5.593851e-001,0.000000e+000,,,,,,,,,,,,,,32,1,4.000000e+000,7.820129e-004,0.000000e+000,0,,0,
1524162913.433,,0.000000e+000,3.499872e+001,2.075543e-006,0.000000e+000,3,5.702069e-001,0.000000e+000,,,,,,,,,,,,,,32,1,4.000000e+000,1.560211e-003,0.000000e+000,0,,0,
1524162951.036,,0.000000e+000,3.500106e+001,2.079840e-006,0.000000e+000,3,5.772036e-001,0.000000e+000,,,,,,,,,,,,,,32,1,4.000000e+000,1.560211e-003,0.000000e+000,0,,0,
1524162989.032,,0.000000e+000,3.499989e+001,2.101139e-006,0.000000e+000,3,5.726782e-001,0.000000e+000,,,,,,,,,,,,,,32,1,4.000000e+000,2.342224e-003,0.000000e+000,0,,0,
1524163026.907,,0.000000e+000,3.499872e+001,2.105626e-006,0.000000e+000,3,5.637443e-001,0.000000e+000,,,,,,,,,,,,,,32,1,4.000000e+000,0.000000e+000,0.000000e+000,0,,0,
1524163064.805,,0.000000e+000,3.499989e+001,2.122074e-006,0.000000e+000,3,5.749010e-001,0.000000e+000,,,,,,,,,,,,,,32,1,4.000000e+000,7.781982e-004,0.000000e+000,0,,0,
1524163104.136,,0.000000e+000,3.499911e+001,1.982995e-006,0.000000e+000,3,5.554644e-001,0.000000e+000,,,,,,,,,,,,,,32,1,4.000000e+000,7.820129e-004,0.000000e+000,0,,0,
1524163142.921,,0.000000e+000,3.499911e+001,2.076315e-006,0.000000e+000,3,5.616668e-001,0.000000e+000,,,,,,,,,,,,,,32,1,4.000000e+000,7.820129e-004,0.000000e+000,0,,0,
1524163181.022,,0.000000e+000,3.499872e+001,2.059830e-006,0.000000e+000,3,5.635477e-001,0.000000e+000,,,,,,,,,,,,,,32,1,4.000000e+000,0.000000e+000,0.000000e+000,0,,0,
1524163218.558,,0.000000e+000,3.500067e+001,2.096085e-006,0.000000e+000,3,5.682144e-001,0.000000e+000,,,,,,,,,,,,,,32,1,4.000000e+000,7.820129e-004,0.000000e+000,0,,0,
1524163256.418,,0.000000e+000,3.500146e+001,2.102688e-006,0.000000e+000,3,5.765385e-001,0.000000e+000,,,,,,,,,,,,,,32,1,4.000000e+000,3.910065e-003,0.000000e+000,0,,0,
1524163294.484,,0.000000e+000,3.499911e+001,2.028585e-006,0.000000e+000,3,5.778064e-001,0.000000e+000,,,,,,,,,,,,,,32,1,4.000000e+000,7.820129e-004,0.000000e+000,0,,0,
1524163332.107,,0.000000e+000,3.499872e+001,1.971708e-006,0.000000e+000,3,5.554417e-001,0.000000e+000,,,,,,,,,,,,,,32,1,4.000000e+000,1.560211e-003,0.000000e+000,0,,0,
1524163370.125,,0.000000e+000,3.499794e+001,2.094774e-006,0.000000e+000,3,5.827143e-001,0.000000e+000,,,,,,,,,,,,,,32,1,4.000000e+000,0.000000e+000,0.000000e+000,0,,0,
1524163407.943,,0.000000e+000,3.500028e+001,2.055171e-006,0.000000e+000,3,5.738191e-001,0.000000e+000,,,,,,,,,,,,,,32,1,4.000000e+000,0.000000e+000,0.000000e+000,0,,0,
1524163446.173,,0.000000e+000,3.499911e+001,2.052896e-006,0.000000e+000,3,5.626405e-001,0.000000e+000,,,,,,,,,,,,,,32,1,4.000000e+000,2.338409e-003,0.000000e+000,0,,0,
1524163471.669,,0.000000e+000,3.499911e+001,2.037057e-006,0.000000e+000,3,5.632755e-001,0.000000e+000,,,,,,,,,,,,,,32,1,4.000000e+000,7.820129e-004,0.000000e+000,0,,0,