File: Experimental Raw Data/MFn1 VRM/Iterative Regression/MFn1_VRMac_34K_12000s_VRMde_35K.dc.dat
[Header]
TITLE,MPMS DC Measurement
BYAPP,MPMS Measurement,2.1,Summary
FILEOPENTIME, 1524238693.770000 4/20/2018, 9:38:13 AM

INFO, APPNAME, MPMS MultiVu Application, Revision 1.61,  Build 082

INFO, NAME, MFn1
INFO, WEIGHT, 1.000
INFO, AREA, 1.000
INFO, LENGTH, 1.000
INFO, SHAPE, 0
INFO, COMMENT,
INFO, SEQUENCE FILE: VRMac_34K_12000s_VRMde_35K.seq


INFO, BACKGROUND DATA FILE:, None


STARTUPAXIS,X,4,LINEAR,AUTO,0.000000,0.000000
STARTUPAXIS,Y1,5,LINEAR,AUTO,0.000000,0.000000


STARTUPGROUP,Longitudinal
FIELDGROUP,Longitudinal,1,2,3,4,5,6,7,8,9,15,16,17,18,27,28
FIELDGROUP,Transverse,1,2,3,4,10,11,12,13,14,19,20,21,22,27,28

PLOT_APPEARANCE,ALL,HORZ_GRID_ON,VERT_GRID_ON,MARKERS_AND_LINES

[Data]
Time,Comment,Field (Oe),Temperature (K),Long Moment (emu),Long Scan Std Dev,Long Algorithm,Long Reg Fit,Long Percent Error (%),Trans Moment (emu),Trans Scan Std Dev,Trans Algorithm,Trans Reg Fit,Trans Percent Error (%),Long Moment [w/o ABS] (emu),Long Scan Std Dev [w/o ABS],Long Reg Fit [w/o ABS],Long Percent Error [w/o ABS] (%),Trans Moment [w/o ABS] (emu),Trans Scan Std Dev [w/o ABS],Trans Reg Fit [w/o ABS],Trans Percent Error [w/o ABS] (%),Points per Scan,Scans per Measurement,Scan Length (cm),Delta Temp (K),Rot Position (deg),Error,EC Comp. Running,Using ABS,
1524238693.767,,0.000000e+000,3.500419e+001,-1.797918e-005,0.000000e+000,3,9.494333e-001,0.000000e+000,,,,,,,,,,,,,,32,1,4.000000e+000,4.699707e-003,0.000000e+000,0,,0,
1524238732.456,,0.000000e+000,3.500262e+001,-1.652885e-005,0.000000e+000,3,9.454147e-001,0.000000e+000,,,,,,,,,,,,,,32,1,4.000000e+000,3.128052e-003,0.000000e+000,0,,0,
1524238770.534,,0.000000e+000,3.500028e+001,-1.559096e-005,0.000000e+000,3,9.373559e-001,0.000000e+000,,,,,,,,,,,,,,32,1,4.000000e+000,1.560211e-003,0.000000e+000,0,,0,
1524238808.369,,0.000000e+000,3.500028e+001,-1.463560e-005,0.000000e+000,3,9.345407e-001,0.000000e+000,,,,,,,,,,,,,,32,1,4.000000e+000,0.000000e+000,0.000000e+000,0,,0,
1524238846.025,,0.000000e+000,3.499989e+001,-1.385423e-005,0.000000e+000,3,9.354952e-001,0.000000e+000,,,,,,,,,,,,,,32,1,4.000000e+000,7.781982e-004,0.000000e+000,0,,0,
1524238884.863,,0.000000e+000,3.499911e+001,-1.322395e-005,0.000000e+000,3,9.277995e-001,0.000000e+000,,,,,,,,,,,,,,32,1,4.000000e+000,7.820129e-004,0.000000e+000,0,,0,
1524238923.183,,0.000000e+000,3.500067e+001,-1.258777e-005,0.000000e+000,3,9.247429e-001,0.000000e+000,,,,,,,,,,,,,,32,1,4.000000e+000,2.338409e-003,0.000000e+000,0,,0,
1524238961.591,,0.000000e+000,3.500028e+001,-1.208089e-005,0.000000e+000,3,9.179352e-001,0.000000e+000,,,,,,,,,,,,,,32,1,4.000000e+000,0.000000e+000,0.000000e+000,0,,0,
1524239000.230,,0.000000e+000,3.499872e+001,-1.166958e-005,0.000000e+000,3,9.242328e-001,0.000000e+000,,,,,,,,,,,,,,32,1,4.000000e+000,0.000000e+000,0.000000e+000,0,,0,
1524239037.413,,0.000000e+000,3.499872e+001,-1.133144e-005,0.000000e+000,3,9.165323e-001,0.000000e+000,,,,,,,,,,,,,,32,1,4.000000e+000,0.000000e+000,0.000000e+000,0,,0,
1524239075.463,,0.000000e+000,3.499950e+001,-1.089795e-005,0.000000e+000,3,9.121858e-001,0.000000e+000,,,,,,,,,,,,,,32,1,4.000000e+000,0.000000e+000,0.000000e+000,0,,0,
1524239113.579,,0.000000e+000,3.499989e+001,-1.060887e-005,0.000000e+000,3,9.174964e-001,0.000000e+000,,,,,,,,,,,,,,32,1,4.000000e+000,2.342224e-003,0.000000e+000,0,,0,
1524239151.419,,0.000000e+000,3.499950e+001,-1.022880e-005,0.000000e+000,3,9.080958e-001,0.000000e+000,,,,,,,,,,,,,,32,1,4.000000e+000,1.560211e-003,0.000000e+000,0,,0,
1524239190.025,,0.000000e+000,3.499872e+001,-9.958960e-006,0.000000e+000,3,9.016519e-001,0.000000e+000,,,,,,,,,,,,,,32,1,4.000000e+000,1.560211e-003,0.000000e+000,0,,0,
1524239227.313,,0.000000e+000,3.499911e+001,-9.663345e-006,0.000000e+000,3,9.052098e-001,0.000000e+000,,,,,,,,,,,,,,32,1,4.000000e+000,7.820129e-004,0.000000e+000,0,,0,
1524239266.243,,0.000000e+000,3.499871e+001,-9.452054e-006,0.000000e+000,3,9.019093e-001,0.000000e+000,,,,,,,,,,,,,,32,1,4.000000e+000,3.128052e-003,0.000000e+000,0,,0,
1524239304.426,,0.000000e+000,3.499911e+001,-9.185228e-006,0.000000e+000,3,8.958381e-001,0.000000e+000,,,,,,,,,,,,,,32,1,4.000000e+000,7.820129e-004,0.000000e+000,0,,0,
1524239342.284,,0.000000e+000,3.499989e+001,-8.905353e-006,0.000000e+000,3,8.919113e-001,0.000000e+000,,,,,,,,,,,,,,32,1,4.000000e+000,7.781982e-004,0.000000e+000,0,,0,
1524239380.328,,0.000000e+000,3.499911e+001,-8.728642e-006,0.000000e+000,3,8.933564e-001,0.000000e+000,,,,,,,,,,,,,,32,1,4.000000e+000,7.820129e-004,0.000000e+000,0,,0,
1524239417.366,,0.000000e+000,3.499911e+001,-8.581428e-006,0.000000e+000,3,8.880903e-001,0.000000e+000,,,,,,,,,,,,,,32,1,4.000000e+000,7.820129e-004,0.000000e+000,0,,0,
1524239455.354,,0.000000e+000,3.499911e+001,-8.379338e-006,0.000000e+000,3,8.898326e-001,0.000000e+000,,,,,,,,,,,,,,32,1,4.000000e+000,7.820129e-004,0.000000e+000,0,,0,
1524239492.964,,0.000000e+000,3.499911e+001,-8.103022e-006,0.000000e+000,3,8.922164e-001,0.000000e+000,,,,,,,,,,,,,,32,1,4.000000e+000,7.820129e-004,0.000000e+000,0,,0,
1524239532.070,,0.000000e+000,3.499911e+001,-8.010076e-006,0.000000e+000,3,8.819635e-001,0.000000e+000,,,,,,,,,,,,,,32,1,4.000000e+000,7.820129e-004,0.000000e+000,0,,0,
1524239569.598,,0.000000e+000,3.499911e+001,-7.827015e-006,0.000000e+000,3,8.869087e-001,0.000000e+000,,,,,,,,,,,,,,32,1,4.000000e+000,7.820129e-004,0.000000e+000,0,,0,
1524239607.113,,0.000000e+000,3.499950e+001,-7.663942e-006,0.000000e+000,3,8.782066e-001,0.000000e+000,,,,,,,,,,,,,,32,1,4.000000e+000,0.000000e+000,0.000000e+000,0,,0,
1524239644.539,,0.000000e+000,3.499872e+001,-7.452754e-006,0.000000e+000,3,8.729295e-001,0.000000e+000,,,,,,,,,,,,,,32,1,4.000000e+000,0.000000e+000,0.000000e+000,0,,0,
1524239682.352,,0.000000e+000,3.499872e+001,-7.386984e-006,0.000000e+000,3,8.733041e-001,0.000000e+000,,,,,,,,,,,,,,32,1,4.000000e+000,0.000000e+000,0.000000e+000,0,,0,
1524239719.843,,0.000000e+000,3.499911e+001,-7.212391e-006,0.000000e+000,3,8.760468e-001,0.000000e+000,,,,,,,,,,,,,,32,1,4.000000e+000,7.820129e-004,0.000000e+000,0,,0,
1524239757.913,,0.000000e+000,3.499950e+001,-7.083361e-006,0.000000e+000,3,8.760703e-001,0.000000e+000,,,,,,,,,,,,,,32,1,4.000000e+000,1.560211e-003,0.000000e+000,0,,0,
1524239796.391,,0.000000e+000,3.499989e+001,-6.925819e-006,0.000000e+000,3,8.684019e-001,0.000000e+000,,,,,,,,,,,,,,32,1,4.000000e+000,7.781982e-004,0.000000e+000,0,,0,
1524239834.302,,0.000000e+000,3.499833e+001,-6.778821e-006,0.000000e+000,3,8.590202e-001,0.000000e+000,,,,,,,,,,,,,,32,1,4.000000e+000,7.781982e-004,0.000000e+000,0,,0,
1524239872.482,,0.000000e+000,3.499833e+001,-6.708904e-006,0.000000e+000,3,8.610875e-001,0.000000e+000,,,,,,,,,,,,,,32,1,4.000000e+000,7.781982e-004,0.000000e+000,0,,0,
1524239910.518,,0.000000e+000,3.499872e+001,-6.539046e-006,0.000000e+000,3,8.554485e-001,0.000000e+000,,,,,,,,,,,,,,32,1,4.000000e+000,1.560211e-003,0.000000e+000,0,,0,
1524239948.571,,0.000000e+000,3.499911e+001,-6.482023e-006,0.000000e+000,3,8.541496e-001,0.000000e+000,,,,,,,,,,,,,,32,1,4.000000e+000,2.338409e-003,0.000000e+000,0,,0,
1524239986.306,,0.000000e+000,3.499911e+001,-6.341264e-006,0.000000e+000,3,8.548010e-001,0.000000e+000,,,,,,,,,,,,,,32,1,4.000000e+000,2.338409e-003,0.000000e+000,0,,0,
1524240024.167,,0.000000e+000,3.499989e+001,-6.232436e-006,0.000000e+000,3,8.513132e-001,0.000000e+000,,,,,,,,,,,,,,32,1,4.000000e+000,7.781982e-004,0.000000e+000,0,,0,
1524240062.260,,0.000000e+000,3.499989e+001,-6.105669e-006,0.000000e+000,3,8.445033e-001,0.000000e+000,,,,,,,,,,,,,,32,1,4.000000e+000,7.781982e-004,0.000000e+000,0,,0,
1524240100.273,,0.000000e+000,3.499793e+001,-5.946406e-006,0.000000e+000,3,8.413243e-001,0.000000e+000,,,,,,,,,,,,,,32,1,4.000000e+000,1.567841e-003,0.000000e+000,0,,0,
1524240138.364,,0.000000e+000,3.499950e+001,-5.948412e-006,0.000000e+000,3,8.457882e-001,0.000000e+000,,,,,,,,,,,,,,32,1,4.000000e+000,1.560211e-003,0.000000e+000,0,,0,
1524240176.414,,0.000000e+000,3.499754e+001,-5.829534e-006,0.000000e+000,3,8.402646e-001,0.000000e+000,,,,,,,,,,,,,,32,1,4.000000e+000,2.349854e-003,0.000000e+000,0,,0,
1524240214.462,,0.000000e+000,3.499950e+001,-5.738019e-006,0.000000e+000,3,8.406239e-001,0.000000e+000,,,,,,,,,,,,,,32,1,4.000000e+000,1.560211e-003,0.000000e+000,0,,0,
1524240252.508,,0.000000e+000,3.499950e+001,-5.653376e-006,0.000000e+000,3,8.349860e-001,0.000000e+000,,,,,,,,,,,,,,32,1,4.000000e+000,1.560211e-003,0.000000e+000,0,,0,
1524240290.046,,0.000000e+000,3.499872e+001,-5.576147e-006,0.000000e+000,3,8.258830e-001,0.000000e+000,,,,,,,,,,,,,,32,1,4.000000e+000,0.000000e+000,0.000000e+000,0,,0,
1524240328.142,,0.000000e+000,3.499911e+001,-5.433795e-006,0.000000e+000,3,8.229839e-001,0.000000e+000,,,,,,,,,,,,,,32,1,4.000000e+000,2.338409e-003,0.000000e+000,0,,0,
1524240366.227,,0.000000e+000,3.499911e+001,-5.370852e-006,0.000000e+000,3,8.250188e-001,0.000000e+000,,,,,,,,,,,,,,32,1,4.000000e+000,7.820129e-004,0.000000e+000,0,,0,
1524240405.308,,0.000000e+000,3.499872e+001,-5.331026e-006,0.000000e+000,3,8.258358e-001,0.000000e+000,,,,,,,,,,,,,,32,1,4.000000e+000,0.000000e+000,0.000000e+000,0,,0,
1524240442.798,,0.000000e+000,3.499950e+001,-5.264784e-006,0.000000e+000,3,8.396372e-001,0.000000e+000,,,,,,,,,,,,,,32,1,4.000000e+000,0.000000e+000,0.000000e+000,0,,0,
1524240480.926,,0.000000e+000,3.499911e+001,-5.249995e-006,0.000000e+000,3,8.271739e-001,0.000000e+000,,,,,,,,,,,,,,32,1,4.000000e+000,7.820129e-004,0.000000e+000,0,,0,
1524240519.232,,0.000000e+000,3.499950e+001,-5.178563e-006,0.000000e+000,3,8.250233e-001,0.000000e+000,,,,,,,,,,,,,,32,1,4.000000e+000,1.560211e-003,0.000000e+000,0,,0,
1524240557.760,,0.000000e+000,3.499911e+001,-5.092665e-006,0.000000e+000,3,8.125689e-001,0.000000e+000,,,,,,,,,,,,,,32,1,4.000000e+000,7.820129e-004,0.000000e+000,0,,0,
1524240595.090,,0.000000e+000,3.499911e+001,-4.926863e-006,0.000000e+000,3,8.022941e-001,0.000000e+000,,,,,,,,,,,,,,32,1,4.000000e+000,7.820129e-004,0.000000e+000,0,,0,
1524240632.771,,0.000000e+000,3.499833e+001,-4.865106e-006,0.000000e+000,3,8.177782e-001,0.000000e+000,,,,,,,,,,,,,,32,1,4.000000e+000,7.781982e-004,0.000000e+000,0,,0,
1524240670.912,,0.000000e+000,3.499911e+001,-4.836801e-006,0.000000e+000,3,8.127745e-001,0.000000e+000,,,,,,,,,,,,,,32,1,4.000000e+000,7.820129e-004,0.000000e+000,0,,0,
1524240708.882,,0.000000e+000,3.499872e+001,-4.751693e-006,0.000000e+000,3,8.042799e-001,0.000000e+000,,,,,,,,,,,,,,32,1,4.000000e+000,0.000000e+000,0.000000e+000,0,,0,
1524240747.345,,0.000000e+000,3.499911e+001,-4.815030e-006,0.000000e+000,3,8.068790e-001,0.000000e+000,,,,,,,,,,,,,,32,1,4.000000e+000,7.820129e-004,0.000000e+000,0,,0,
1524240784.943,,0.000000e+000,3.499911e+001,-4.688558e-006,0.000000e+000,3,8.122048e-001,0.000000e+000,,,,,,,,,,,,,,32,1,4.000000e+000,7.820129e-004,0.000000e+000,0,,0,
1524240822.676,,0.000000e+000,3.499950e+001,-4.703525e-006,0.000000e+000,3,8.157669e-001,0.000000e+000,,,,,,,,,,,,,,32,1,4.000000e+000,1.560211e-003,0.000000e+000,0,,0,
1524240861.184,,0.000000e+000,3.499872e+001,-4.495114e-006,0.000000e+000,3,7.791181e-001,0.000000e+000,,,,,,,,,,,,,,32,1,4.000000e+000,1.560211e-003,0.000000e+000,0,,0,
1524240898.815,,0.000000e+000,3.499872e+001,-4.505341e-006,0.000000e+000,3,7.927687e-001,0.000000e+000,,,,,,,,,,,,,,32,1,4.000000e+000,0.000000e+000,0.000000e+000,0,,0,
1524240936.858,,0.000000e+000,3.499872e+001,-4.345818e-006,0.000000e+000,3,7.909562e-001,0.000000e+000,,,,,,,,,,,,,,32,1,4.000000e+000,0.000000e+000,0.000000e+000,0,,0,
1524240974.894,,0.000000e+000,3.499911e+001,-4.297619e-006,0.000000e+000,3,7.841930e-001,0.000000e+000,,,,,,,,,,,,,,32,1,4.000000e+000,7.820129e-004,0.000000e+000,0,,0,
1524241012.969,,0.000000e+000,3.499989e+001,-4.337908e-006,0.000000e+000,3,7.817736e-001,0.000000e+000,,,,,,,,,,,,,,32,1,4.000000e+000,7.781982e-004,0.000000e+000,0,,0,
1524241050.972,,0.000000e+000,3.499911e+001,-4.302299e-006,0.000000e+000,3,7.818604e-001,0.000000e+000,,,,,,,,,,,,,,32,1,4.000000e+000,7.820129e-004,0.000000e+000,0,,0,
1524241088.510,,0.000000e+000,3.499989e+001,-4.251397e-006,0.000000e+000,3,7.900824e-001,0.000000e+000,,,,,,,,,,,,,,32,1,4.000000e+000,7.781982e-004,0.000000e+000,0,,0,
1524241126.891,,0.000000e+000,3.499950e+001,-4.114619e-006,0.000000e+000,3,7.740629e-001,0.000000e+000,,,,,,,,,,,,,,32,1,4.000000e+000,0.000000e+000,0.000000e+000,0,,0,
1524241164.846,,0.000000e+000,3.499989e+001,-4.148199e-006,0.000000e+000,3,7.786722e-001,0.000000e+000,,,,,,,,,,,,,,32,1,4.000000e+000,7.781982e-004,0.000000e+000,0,,0,
1524241202.909,,0.000000e+000,3.499598e+001,-3.989045e-006,0.000000e+000,3,7.623993e-001,0.000000e+000,,,,,,,,,,,,,,32,1,4.000000e+000,5.477905e-003,0.000000e+000,0,,0,
1524241241.042,,0.000000e+000,3.499754e+001,-4.029857e-006,0.000000e+000,3,7.791986e-001,0.000000e+000,,,,,,,,,,,,,,32,1,4.000000e+000,3.910065e-003,0.000000e+000,0,,0,
1524241279.028,,0.000000e+000,3.499911e+001,-3.908141e-006,0.000000e+000,3,7.607199e-001,0.000000e+000,,,,,,,,,,,,,,32,1,4.000000e+000,7.820129e-004,0.000000e+000,0,,0,
1524241317.099,,0.000000e+000,3.499911e+001,-3.950137e-006,0.000000e+000,3,7.621499e-001,0.000000e+000,,,,,,,,,,,,,,32,1,4.000000e+000,7.820129e-004,0.000000e+000,0,,0,
1524241355.307,,0.000000e+000,3.499950e+001,-3.945118e-006,0.000000e+000,3,7.718032e-001,0.000000e+000,,,,,,,,,,,,,,32,1,4.000000e+000,0.000000e+000,0.000000e+000,0,,0,
1524241393.327,,0.000000e+000,3.499793e+001,-3.838961e-006,0.000000e+000,3,7.680440e-001,0.000000e+000,,,,,,,,,,,,,,32,1,4.000000e+000,1.567841e-003,0.000000e+000,0,,0,
1524241431.410,,0.000000e+000,3.499911e+001,-3.801892e-006,0.000000e+000,3,7.606059e-001,0.000000e+000,,,,,,,,,,,,,,32,1,4.000000e+000,7.820129e-004,0.000000e+000,0,,0,
1524241469.446,,0.000000e+000,3.499872e+001,-3.767489e-006,0.000000e+000,3,7.589573e-001,0.000000e+000,,,,,,,,,,,,,,32,1,4.000000e+000,0.000000e+000,0.000000e+000,0,,0,
1524241507.264,,0.000000e+000,3.499833e+001,-3.735996e-006,0.000000e+000,3,7.520601e-001,0.000000e+000,,,,,,,,,,,,,,32,1,4.000000e+000,2.349854e-003,0.000000e+000,0,,0,
1524241545.579,,0.000000e+000,3.499950e+001,-3.653491e-006,0.000000e+000,3,7.496529e-001,0.000000e+000,,,,,,,,,,,,,,32,1,4.000000e+000,0.000000e+000,0.000000e+000,0,,0,
1524241584.242,,0.000000e+000,3.499989e+001,-3.616648e-006,0.000000e+000,3,7.356278e-001,0.000000e+000,,,,,,,,,,,,,,32,1,4.000000e+000,7.781982e-004,0.000000e+000,0,,0,
1524241621.700,,0.000000e+000,3.499911e+001,-3.620464e-006,0.000000e+000,3,7.437263e-001,0.000000e+000,,,,,,,,,,,,,,32,1,4.000000e+000,7.820129e-004,0.000000e+000,0,,0,
1524241659.764,,0.000000e+000,3.499950e+001,-3.618693e-006,0.000000e+000,3,7.291992e-001,0.000000e+000,,,,,,,,,,,,,,32,1,4.000000e+000,0.000000e+000,0.000000e+000,0,,0,
1524241698.642,,0.000000e+000,3.499950e+001,-3.478077e-006,0.000000e+000,3,7.404926e-001,0.000000e+000,,,,,,,,,,,,,,32,1,4.000000e+000,1.560211e-003,0.000000e+000,0,,0,
1524241736.630,,0.000000e+000,3.499989e+001,-3.460188e-006,0.000000e+000,3,7.328329e-001,0.000000e+000,,,,,,,,,,,,,,32,1,4.000000e+000,7.781982e-004,0.000000e+000,0,,0,
1524241774.540,,0.000000e+000,3.499989e+001,-3.389474e-006,0.000000e+000,3,7.100590e-001,0.000000e+000,,,,,,,,,,,,,,32,1,4.000000e+000,7.781982e-004,0.000000e+000,0,,0,
1524241812.678,,0.000000e+000,3.499872e+001,-3.366442e-006,0.000000e+000,3,7.113793e-001,0.000000e+000,,,,,,,,,,,,,,32,1,4.000000e+000,1.560211e-003,0.000000e+000,0,,0,
1524241851.389,,0.000000e+000,3.499832e+001,-3.310462e-006,0.000000e+000,3,7.304378e-001,0.000000e+000,,,,,,,,,,,,,,32,1,4.000000e+000,3.910065e-003,0.000000e+000,0,,0,
1524241889.294,,0.000000e+000,3.499872e+001,-3.321846e-006,0.000000e+000,3,7.197801e-001,0.000000e+000,,,,,,,,,,,,,,32,1,4.000000e+000,0.000000e+000,0.000000e+000,0,,0,
1524241927.315,,0.000000e+000,3.499911e+001,-3.247545e-006,0.000000e+000,3,7.051948e-001,0.000000e+000,,,,,,,,,,,,,,32,1,4.000000e+000,7.820129e-004,0.000000e+000,0,,0,
1524241965.233,,0.000000e+000,3.499559e+001,-3.201376e-006,0.000000e+000,3,7.003063e-001,0.000000e+000,,,,,,,,,,,,,,32,1,4.000000e+000,4.699707e-003,0.000000e+000,0,,0,
1524242003.049,,0.000000e+000,3.500145e+001,-3.162269e-006,0.000000e+000,3,6.969472e-001,0.000000e+000,,,,,,,,,,,,,,32,1,4.000000e+000,5.470276e-003,0.000000e+000,0,,0,
1524242040.149,,0.000000e+000,3.499950e+001,-3.081056e-006,0.000000e+000,3,6.953068e-001,0.000000e+000,,,,,,,,,,,,,,32,1,4.000000e+000,0.000000e+000,0.000000e+000,0,,0,
1524242078.212,,0.000000e+000,3.499911e+001,-3.017311e-006,0.000000e+000,3,6.989287e-001,0.000000e+000,,,,,,,,,,,,,,32,1,4.000000e+000,7.820129e-004,0.000000e+000,0,,0,
1524242116.208,,0.000000e+000,3.499950e+001,-3.018929e-006,0.000000e+000,3,6.911402e-001,0.000000e+000,,,,,,,,,,,,,,32,1,4.000000e+000,0.000000e+000,0.000000e+000,0,,0,
1524242154.041,,0.000000e+000,3.499911e+001,-2.983367e-006,0.000000e+000,3,6.944512e-001,0.000000e+000,,,,,,,,,,,,,,32,1,4.000000e+000,7.820129e-004,0.000000e+000,0,,0,
1524242191.521,,0.000000e+000,3.499715e+001,-2.901267e-006,0.000000e+000,3,6.924857e-001,0.000000e+000,,,,,,,,,,,,,,32,1,4.000000e+000,1.571655e-003,0.000000e+000,0,,0,
1524242229.902,,0.000000e+000,3.499989e+001,-2.880246e-006,0.000000e+000,3,6.727183e-001,0.000000e+000,,,,,,,,,,,,,,32,1,4.000000e+000,7.781982e-004,0.000000e+000,0,,0,
1524242267.620,,0.000000e+000,3.499833e+001,-2.878191e-006,0.000000e+000,3,6.782476e-001,0.000000e+000,,,,,,,,,,,,,,32,1,4.000000e+000,7.781982e-004,0.000000e+000,0,,0,
1524242305.566,,0.000000e+000,3.499754e+001,-2.878103e-006,0.000000e+000,3,6.754543e-001,0.000000e+000,,,,,,,,,,,,,,32,1,4.000000e+000,3.910065e-003,0.000000e+000,0,,0,
1524242342.856,,0.000000e+000,3.499989e+001,-2.899954e-006,0.000000e+000,3,6.694495e-001,0.000000e+000,,,,,,,,,,,,,,32,1,4.000000e+000,7.781982e-004,0.000000e+000,0,,0,
1524242380.484,,0.000000e+000,3.500028e+001,-2.803293e-006,0.000000e+000,3,6.512643e-001,0.000000e+000,,,,,,,,,,,,,,32,1,4.000000e+000,3.120422e-003,0.000000e+000,0,,0,
1524242419.247,,0.000000e+000,3.499872e+001,-2.801009e-006,0.000000e+000,3,6.462005e-001,0.000000e+000,,,,,,,,,,,,,,32,1,4.000000e+000,1.560211e-003,0.000000e+000,0,,0,
1524242457.485,,0.000000e+000,3.499872e+001,-2.795462e-006,0.000000e+000,3,6.524163e-001,0.000000e+000,,,,,,,,,,,,,,32,1,4.000000e+000,1.560211e-003,0.000000e+000,0,,0,
1524242495.546,,0.000000e+000,3.499911e+001,-2.735646e-006,0.000000e+000,3,6.445618e-001,0.000000e+000,,,,,,,,,,,,,,32,1,4.000000e+000,7.820129e-004,0.000000e+000,0,,0,
1524242533.316,,0.000000e+000,3.499911e+001,-2.798681e-006,0.000000e+000,3,6.554800e-001,0.000000e+000,,,,,,,,,,,,,,32,1,4.000000e+000,7.820129e-004,0.000000e+000,0,,0,
1524242572.799,,0.000000e+000,3.499872e+001,-2.689660e-006,0.000000e+000,3,6.474386e-001,0.000000e+000,,,,,,,,,,,,,,32,1,4.000000e+000,0.000000e+000,0.000000e+000,0,,0,
1524242611.332,,0.000000e+000,3.499989e+001,-2.613605e-006,0.000000e+000,3,6.440082e-001,0.000000e+000,,,,,,,,,,,,,,32,1,4.000000e+000,7.781982e-004,0.000000e+000,0,,0,
1524242648.901,,0.000000e+000,3.499793e+001,-2.648596e-006,0.000000e+000,3,6.440783e-001,0.000000e+000,,,,,,,,,,,,,,32,1,4.000000e+000,1.567841e-003,0.000000e+000,0,,0,
1524242686.744,,0.000000e+000,3.499794e+001,-2.650982e-006,0.000000e+000,3,6.368659e-001,0.000000e+000,,,,,,,,,,,,,,32,1,4.000000e+000,0.000000e+000,0.000000e+000,0,,0,
1524242724.792,,0.000000e+000,3.499872e+001,-2.603144e-006,0.000000e+000,3,6.115071e-001,0.000000e+000,,,,,,,,,,,,,,32,1,4.000000e+000,0.000000e+000,0.000000e+000,0,,0,
1524242762.627,,0.000000e+000,3.500028e+001,-2.551541e-006,0.000000e+000,3,6.166338e-001,0.000000e+000,,,,,,,,,,,,,,32,1,4.000000e+000,0.000000e+000,0.000000e+000,0,,0,
1524242800.500,,0.000000e+000,3.499872e+001,-2.524843e-006,0.000000e+000,3,6.249457e-001,0.000000e+000,,,,,,,,,,,,,,32,1,4.000000e+000,0.000000e+000,0.000000e+000,0,,0,
1524242838.783,,0.000000e+000,3.500028e+001,-2.501713e-006,0.000000e+000,3,6.108614e-001,0.000000e+000,,,,,,,,,,,,,,32,1,4.000000e+000,4.688263e-003,0.000000e+000,0,,0,
1524242877.309,,0.000000e+000,3.499950e+001,-2.490586e-006,0.000000e+000,3,6.494439e-001,0.000000e+000,,,,,,,,,,,,,,32,1,4.000000e+000,0.000000e+000,0.000000e+000,0,,0,
1524242914.952,,0.000000e+000,3.500028e+001,-2.490315e-006,0.000000e+000,3,6.324224e-001,0.000000e+000,,,,,,,,,,,,,,32,1,4.000000e+000,1.560211e-003,0.000000e+000,0,,0,
1524242952.888,,0.000000e+000,3.499871e+001,-2.422584e-006,0.000000e+000,3,6.244812e-001,0.000000e+000,,,,,,,,,,,,,,32,1,4.000000e+000,3.128052e-003,0.000000e+000,0,,0,
1524242990.493,,0.000000e+000,3.500028e+001,-2.347300e-006,0.000000e+000,3,5.999690e-001,0.000000e+000,,,,,,,,,,,,,,32,1,4.000000e+000,1.560211e-003,0.000000e+000,0,,0,
1524243028.531,,0.000000e+000,3.499871e+001,-2.401725e-006,0.000000e+000,3,6.056273e-001,0.000000e+000,,,,,,,,,,,,,,32,1,4.000000e+000,3.128052e-003,0.000000e+000,0,,0,
1524243066.469,,0.000000e+000,3.499911e+001,-2.316914e-006,0.000000e+000,3,6.004829e-001,0.000000e+000,,,,,,,,,,,,,,32,1,4.000000e+000,7.820129e-004,0.000000e+000,0,,0,
1524243103.942,,0.000000e+000,3.499911e+001,-2.349260e-006,0.000000e+000,3,5.922945e-001,0.000000e+000,,,,,,,,,,,,,,32,1,4.000000e+000,7.820129e-004,0.000000e+000,0,,0,
1524243141.440,,0.000000e+000,3.499950e+001,-2.279179e-006,0.000000e+000,3,5.878301e-001,0.000000e+000,,,,,,,,,,,,,,32,1,4.000000e+000,1.560211e-003,0.000000e+000,0,,0,
1524243179.413,,0.000000e+000,3.499950e+001,-2.302520e-006,0.000000e+000,3,5.942574e-001,0.000000e+000,,,,,,,,,,,,,,32,1,4.000000e+000,1.560211e-003,0.000000e+000,0,,0,
1524243217.909,,0.000000e+000,3.499989e+001,-2.286336e-006,0.000000e+000,3,5.978448e-001,0.000000e+000,,,,,,,,,,,,,,32,1,4.000000e+000,7.781982e-004,0.000000e+000,0,,0,
1524243255.999,,0.000000e+000,3.499950e+001,-2.299160e-006,0.000000e+000,3,5.848633e-001,0.000000e+000,,,,,,,,,,,,,,32,1,4.000000e+000,0.000000e+000,0.000000e+000,0,,0,
1524243293.622,,0.000000e+000,3.499950e+001,-2.212929e-006,0.000000e+000,3,5.883893e-001,0.000000e+000,,,,,,,,,,,,,,32,1,4.000000e+000,0.000000e+000,0.000000e+000,0,,0,
1524243331.998,,0.000000e+000,3.499911e+001,-2.242241e-006,0.000000e+000,3,5.814114e-001,0.000000e+000,,,,,,,,,,,,,,32,1,4.000000e+000,7.820129e-004,0.000000e+000,0,,0,
1524243370.621,,0.000000e+000,3.499715e+001,-2.207352e-006,0.000000e+000,3,5.864028e-001,0.000000e+000,,,,,,,,,,,,,,32,1,4.000000e+000,3.128052e-003,0.000000e+000,0,,0,
1524243408.579,,0.000000e+000,3.499911e+001,-2.160022e-006,0.000000e+000,3,5.644431e-001,0.000000e+000,,,,,,,,,,,,,,32,1,4.000000e+000,7.820129e-004,0.000000e+000,0,,0,
1524243446.630,,0.000000e+000,3.499950e+001,-2.150094e-006,0.000000e+000,3,5.621201e-001,0.000000e+000,,,,,,,,,,,,,,32,1,4.000000e+000,0.000000e+000,0.000000e+000,0,,0,
1524243484.733,,0.000000e+000,3.499911e+001,-2.127397e-006,0.000000e+000,3,5.631636e-001,0.000000e+000,,,,,,,,,,,,,,32,1,4.000000e+000,7.820129e-004,0.000000e+000,0,,0,
1524243522.271,,0.000000e+000,3.499872e+001,-2.093674e-006,0.000000e+000,3,5.405917e-001,0.000000e+000,,,,,,,,,,,,,,32,1,4.000000e+000,1.560211e-003,0.000000e+000,0,,0,
1524243560.184,,0.000000e+000,3.499872e+001,-2.036078e-006,0.000000e+000,3,5.325822e-001,0.000000e+000,,,,,,,,,,,,,,32,1,4.000000e+000,1.560211e-003,0.000000e+000,0,,0,
1524243598.152,,0.000000e+000,3.499793e+001,-2.015413e-006,0.000000e+000,3,5.579956e-001,0.000000e+000,,,,,,,,,,,,,,32,1,4.000000e+000,1.567841e-003,0.000000e+000,0,,0,
1524243636.470,,0.000000e+000,3.499911e+001,-2.022038e-006,0.000000e+000,3,5.248013e-001,0.000000e+000,,,,,,,,,,,,,,32,1,4.000000e+000,7.820129e-004,0.000000e+000,0,,0,
1524243673.638,,0.000000e+000,3.500028e+001,-2.066249e-006,0.000000e+000,3,5.631814e-001,0.000000e+000,,,,,,,,,,,,,,32,1,4.000000e+000,0.000000e+000,0.000000e+000,0,,0,
1524243711.891,,0.000000e+000,3.499911e+001,-1.940775e-006,0.000000e+000,3,4.981874e-001,0.000000e+000,,,,,,,,,,,,,,32,1,4.000000e+000,7.820129e-004,0.000000e+000,0,,0,
1524243749.989,,0.000000e+000,3.499911e+001,-1.972533e-006,0.000000e+000,3,5.037026e-001,0.000000e+000,,,,,,,,,,,,,,32,1,4.000000e+000,7.820129e-004,0.000000e+000,0,,0,
1524243787.807,,0.000000e+000,3.499872e+001,-1.947727e-006,0.000000e+000,3,5.243848e-001,0.000000e+000,,,,,,,,,,,,,,32,1,4.000000e+000,0.000000e+000,0.000000e+000,0,,0,
1524243825.500,,0.000000e+000,3.499950e+001,-1.911742e-006,0.000000e+000,3,5.286133e-001,0.000000e+000,,,,,,,,,,,,,,32,1,4.000000e+000,0.000000e+000,0.000000e+000,0,,0,
1524243863.523,,0.000000e+000,3.499950e+001,-1.981197e-006,0.000000e+000,3,5.401252e-001,0.000000e+000,,,,,,,,,,,,,,32,1,4.000000e+000,0.000000e+000,0.000000e+000,0,,0,
1524243901.571,,0.000000e+000,3.499950e+001,-1.896668e-006,0.000000e+000,3,4.916566e-001,0.000000e+000,,,,,,,,,,,,,,32,1,4.000000e+000,0.000000e+000,0.000000e+000,0,,0,
1524243939.617,,0.000000e+000,3.499872e+001,-1.995784e-006,0.000000e+000,3,5.393220e-001,0.000000e+000,,,,,,,,,,,,,,32,1,4.000000e+000,0.000000e+000,0.000000e+000,0,,0,
1524243977.688,,0.000000e+000,3.499989e+001,-1.923764e-006,0.000000e+000,3,5.069155e-001,0.000000e+000,,,,,,,,,,,,,,32,1,4.000000e+000,7.781982e-004,0.000000e+000,0,,0,
1524244016.173,,0.000000e+000,3.499872e+001,-1.754295e-006,0.000000e+000,3,4.591498e-001,0.000000e+000,,,,,,,,,,,,,,32,1,4.000000e+000,0.000000e+000,0.000000e+000,0,,0,
1524244054.024,,0.000000e+000,3.499989e+001,-1.868896e-006,0.000000e+000,3,5.054029e-001,0.000000e+000,,,,,,,,,,,,,,32,1,4.000000e+000,2.342224e-003,0.000000e+000,0,,0,
1524244092.087,,0.000000e+000,3.500028e+001,-1.855270e-006,0.000000e+000,3,4.948692e-001,0.000000e+000,,,,,,,,,,,,,,32,1,4.000000e+000,0.000000e+000,0.000000e+000,0,,0,
1524244129.807,,0.000000e+000,3.499911e+001,-1.804944e-006,0.000000e+000,3,4.904242e-001,0.000000e+000,,,,,,,,,,,,,,32,1,4.000000e+000,2.338409e-003,0.000000e+000,0,,0,
1524244167.673,,0.000000e+000,3.499950e+001,-1.742403e-006,0.000000e+000,3,4.474273e-001,0.000000e+000,,,,,,,,,,,,,,32,1,4.000000e+000,0.000000e+000,0.000000e+000,0,,0,
1524244205.958,,0.000000e+000,3.499872e+001,-1.691473e-006,0.000000e+000,3,4.472961e-001,0.000000e+000,,,,,,,,,,,,,,32,1,4.000000e+000,0.000000e+000,0.000000e+000,0,,0,
1524244243.959,,0.000000e+000,3.500067e+001,-1.664506e-006,0.000000e+000,3,4.030031e-001,0.000000e+000,,,,,,,,,,,,,,32,1,4.000000e+000,2.338409e-003,0.000000e+000,0,,0,
1524244281.810,,0.000000e+000,3.499911e+001,-1.715219e-006,0.000000e+000,3,4.441998e-001,0.000000e+000,,,,,,,,,,,,,,32,1,4.000000e+000,7.820129e-004,0.000000e+000,0,,0,
1524244319.860,,0.000000e+000,3.500028e+001,-1.676141e-006,0.000000e+000,3,4.283533e-001,0.000000e+000,,,,,,,,,,,,,,32,1,4.000000e+000,1.560211e-003,0.000000e+000,0,,0,
1524244358.598,,0.000000e+000,3.499950e+001,-1.674462e-006,0.000000e+000,3,4.337757e-001,0.000000e+000,,,,,,,,,,,,,,32,1,4.000000e+000,0.000000e+000,0.000000e+000,0,,0,
1524244396.789,,0.000000e+000,3.499950e+001,-1.649398e-006,0.000000e+000,3,4.053693e-001,0.000000e+000,,,,,,,,,,,,,,32,1,4.000000e+000,0.000000e+000,0.000000e+000,0,,0,
1524244434.752,,0.000000e+000,3.499911e+001,-1.712006e-006,0.000000e+000,3,4.547847e-001,0.000000e+000,,,,,,,,,,,,,,32,1,4.000000e+000,7.820129e-004,0.000000e+000,0,,0,
1524244472.497,,0.000000e+000,3.499950e+001,-1.655655e-006,0.000000e+000,3,4.513273e-001,0.000000e+000,,,,,,,,,,,,,,32,1,4.000000e+000,0.000000e+000,0.000000e+000,0,,0,
1524244511.440,,0.000000e+000,3.499911e+001,-1.649363e-006,0.000000e+000,3,4.120891e-001,0.000000e+000,,,,,,,,,,,,,,32,1,4.000000e+000,2.338409e-003,0.000000e+000,0,,0,
1524244548.398,,0.000000e+000,3.499833e+001,-1.654886e-006,0.000000e+000,3,4.184213e-001,0.000000e+000,,,,,,,,,,,,,,32,1,4.000000e+000,7.781982e-004,0.000000e+000,0,,0,
1524244586.494,,0.000000e+000,3.500067e+001,-1.628788e-006,0.000000e+000,3,4.283455e-001,0.000000e+000,,,,,,,,,,,,,,32,1,4.000000e+000,3.910065e-003,0.000000e+000,0,,0,
1524244624.022,,0.000000e+000,3.500028e+001,-1.579643e-006,0.000000e+000,3,3.765580e-001,0.000000e+000,,,,,,,,,,,,,,32,1,4.000000e+000,0.000000e+000,0.000000e+000,0,,0,
1524244661.980,,0.000000e+000,3.499911e+001,-1.559648e-006,0.000000e+000,3,3.906288e-001,0.000000e+000,,,,,,,,,,,,,,32,1,4.000000e+000,7.820129e-004,0.000000e+000,0,,0,
1524244699.898,,0.000000e+000,3.499833e+001,-1.578751e-006,0.000000e+000,3,4.037461e-001,0.000000e+000,,,,,,,,,,,,,,32,1,4.000000e+000,2.349854e-003,0.000000e+000,0,,0,
1524244738.276,,0.000000e+000,3.499872e+001,-1.547751e-006,0.000000e+000,3,3.817491e-001,0.000000e+000,,,,,,,,,,,,,,32,1,4.000000e+000,0.000000e+000,0.000000e+000,0,,0,
1524244776.222,,0.000000e+000,3.499950e+001,-1.558043e-006,0.000000e+000,3,3.907632e-001,0.000000e+000,,,,,,,,,,,,,,32,1,4.000000e+000,0.000000e+000,0.000000e+000,0,,0,
1524244814.987,,0.000000e+000,3.499950e+001,-1.472002e-006,0.000000e+000,3,3.920759e-001,0.000000e+000,,,,,,,,,,,,,,32,1,4.000000e+000,0.000000e+000,0.000000e+000,0,,0,
1524244853.150,,0.000000e+000,3.499950e+001,-1.529521e-006,0.000000e+000,3,3.832740e-001,0.000000e+000,,,,,,,,,,,,,,32,1,4.000000e+000,0.000000e+000,0.000000e+000,0,,0,
1524244891.578,,0.000000e+000,3.499832e+001,-1.521406e-006,0.000000e+000,3,3.649253e-001,0.000000e+000,,,,,,,,,,,,,,32,1,4.000000e+000,3.910065e-003,0.000000e+000,0,,0,
1524244930.139,,0.000000e+000,3.499989e+001,-1.509960e-006,0.000000e+000,3,3.656660e-001,0.000000e+000,,,,,,,,,,,,,,32,1,4.000000e+000,2.342224e-003,0.000000e+000,0,,0,
1524244968.445,,0.000000e+000,3.499950e+001,-1.480438e-006,0.000000e+000,3,3.726358e-001,0.000000e+000,,,,,,,,,,,,,,32,1,4.000000e+000,0.000000e+000,0.000000e+000,0,,0,
1524245005.998,,0.000000e+000,3.499950e+001,-1.504156e-006,0.000000e+000,3,3.781911e-001,0.000000e+000,,,,,,,,,,,,,,32,1,4.000000e+000,1.560211e-003,0.000000e+000,0,,0,
1524245043.418,,0.000000e+000,3.499950e+001,-1.420903e-006,0.000000e+000,3,3.331148e-001,0.000000e+000,,,,,,,,,,,,,,32,1,4.000000e+000,1.560211e-003,0.000000e+000,0,,0,
1524245081.304,,0.000000e+000,3.499989e+001,-1.453089e-006,0.000000e+000,3,3.366337e-001,0.000000e+000,,,,,,,,,,,,,,32,1,4.000000e+000,7.781982e-004,0.000000e+000,0,,0,
1524245119.394,,0.000000e+000,3.499872e+001,-1.403776e-006,0.000000e+000,3,3.312338e-001,0.000000e+000,,,,,,,,,,,,,,32,1,4.000000e+000,0.000000e+000,0.000000e+000,0,,0,
1524245157.447,,0.000000e+000,3.499911e+001,-1.411487e-006,0.000000e+000,3,3.060142e-001,0.000000e+000,,,,,,,,,,,,,,32,1,4.000000e+000,7.820129e-004,0.000000e+000,0,,0,
1524245195.528,,0.000000e+000,3.499872e+001,-1.366784e-006,0.000000e+000,3,3.230232e-001,0.000000e+000,,,,,,,,,,,,,,32,1,4.000000e+000,1.560211e-003,0.000000e+000,0,,0,
1524245232.933,,0.000000e+000,3.499950e+001,-1.336375e-006,0.000000e+000,3,2.950867e-001,0.000000e+000,,,,,,,,,,,,,,32,1,4.000000e+000,1.560211e-003,0.000000e+000,0,,0,
1524245271.024,,0.000000e+000,3.499950e+001,-1.315911e-006,0.000000e+000,3,2.733993e-001,0.000000e+000,,,,,,,,,,,,,,32,1,4.000000e+000,0.000000e+000,0.000000e+000,0,,0,
1524245309.232,,0.000000e+000,3.499872e+001,-1.397251e-006,0.000000e+000,3,3.584180e-001,0.000000e+000,,,,,,,,,,,,,,32,1,4.000000e+000,1.560211e-003,0.000000e+000,0,,0,
1524245347.738,,0.000000e+000,3.499911e+001,-1.327795e-006,0.000000e+000,3,2.741111e-001,0.000000e+000,,,,,,,,,,,,,,32,1,4.000000e+000,2.338409e-003,0.000000e+000,0,,0,
1524245385.186,,0.000000e+000,3.499911e+001,-1.324109e-006,0.000000e+000,3,2.978626e-001,0.000000e+000,,,,,,,,,,,,,,32,1,4.000000e+000,2.338409e-003,0.000000e+000,0,,0,
1524245423.661,,0.000000e+000,3.499989e+001,-1.291215e-006,0.000000e+000,3,2.811697e-001,0.000000e+000,,,,,,,,,,,,,,32,1,4.000000e+000,2.342224e-003,0.000000e+000,0,,0,
1524245460.642,,0.000000e+000,3.499872e+001,-1.331903e-006,0.000000e+000,3,2.765325e-001,0.000000e+000,,,,,,,,,,,,,,32,1,4.000000e+000,1.560211e-003,0.000000e+000,0,,0,
1524245498.322,,0.000000e+000,3.499911e+001,-1.272363e-006,0.000000e+000,3,2.480160e-001,0.000000e+000,,,,,,,,,,,,,,32,1,4.000000e+000,7.820129e-004,0.000000e+000,0,,0,
1524245536.438,,0.000000e+000,3.499872e+001,-1.310232e-006,0.000000e+000,3,3.050456e-001,0.000000e+000,,,,,,,,,,,,,,32,1,4.000000e+000,0.000000e+000,0.000000e+000,0,,0,
1524245574.448,,0.000000e+000,3.499872e+001,-1.256149e-006,0.000000e+000,3,2.273872e-001,0.000000e+000,,,,,,,,,,,,,,32,1,4.000000e+000,0.000000e+000,0.000000e+000,0,,0,
1524245612.709,,0.000000e+000,3.499989e+001,-1.254217e-006,0.000000e+000,3,2.584884e-001,0.000000e+000,,,,,,,,,,,,,,32,1,4.000000e+000,7.781982e-004,0.000000e+000,0,,0,
1524245650.282,,0.000000e+000,3.499911e+001,-1.252719e-006,0.000000e+000,3,2.565422e-001,0.000000e+000,,,,,,,,,,,,,,32,1,4.000000e+000,7.820129e-004,0.000000e+000,0,,0,
1524245688.333,,0.000000e+000,3.500028e+001,-1.260866e-006,0.000000e+000,3,2.562818e-001,0.000000e+000,,,,,,,,,,,,,,32,1,4.000000e+000,3.120422e-003,0.000000e+000,0,,0,
1524245726.358,,0.000000e+000,3.499950e+001,-1.257800e-006,0.000000e+000,3,2.653480e-001,0.000000e+000,,,,,,,,,,,,,,32,1,4.000000e+000,0.000000e+000,0.000000e+000,0,,0,
1524245764.816,,0.000000e+000,3.499872e+001,-1.223583e-006,0.000000e+000,3,2.139530e-001,0.000000e+000,,,,,,,,,,,,,,32,1,4.000000e+000,0.000000e+000,0.000000e+000,0,,0,
1524245802.712,,0.000000e+000,3.499872e+001,-1.175076e-006,0.000000e+000,3,1.566451e-001,0.000000e+000,,,,,,,,,,,,,,32,1,4.000000e+000,0.000000e+000,0.000000e+000,0,,0,
1524245840.230,,0.000000e+000,3.499911e+001,-1.169844e-006,0.000000e+000,3,2.123601e-001,0.000000e+000,,,,,,,,,,,,,,32,1,4.000000e+000,7.820129e-004,0.000000e+000,0,,0,
1524245878.600,,0.000000e+000,3.499950e+001,-1.216730e-006,0.000000e+000,3,2.383322e-001,0.000000e+000,,,,,,,,,,,,,,32,1,4.000000e+000,0.000000e+000,0.000000e+000,0,,0,
1524245917.013,,0.000000e+000,3.499950e+001,-1.194128e-006,0.000000e+000,3,2.500092e-001,0.000000e+000,,,,,,,,,,,,,,32,1,4.000000e+000,0.000000e+000,0.000000e+000,0,,0,
1524245955.009,,0.000000e+000,3.499989e+001,-1.164996e-006,0.000000e+000,3,1.743256e-001,0.000000e+000,,,,,,,,,,,,,,32,1,4.000000e+000,7.781982e-004,0.000000e+000,0,,0,
1524245992.662,,0.000000e+000,3.499911e+001,-1.177161e-006,0.000000e+000,3,1.493369e-001,0.000000e+000,,,,,,,,,,,,,,32,1,4.000000e+000,7.820129e-004,0.000000e+000,0,,0,
1524246030.725,,0.000000e+000,3.500067e+001,-1.119233e-006,0.000000e+000,3,1.292349e-001,0.000000e+000,,,,,,,,,,,,,,32,1,4.000000e+000,7.820129e-004,0.000000e+000,0,,0,
1524246068.566,,0.000000e+000,3.499833e+001,-1.073352e-006,0.000000e+000,3,8.751754e-002,0.000000e+000,,,,,,,,,,,,,,32,1,4.000000e+000,2.349854e-003,0.000000e+000,0,,0,
1524246106.636,,0.000000e+000,3.499989e+001,-1.129347e-006,0.000000e+000,3,1.575020e-001,0.000000e+000,,,,,,,,,,,,,,32,1,4.000000e+000,7.781982e-004,0.000000e+000,0,,0,
1524246145.009,,0.000000e+000,3.499872e+001,-1.134905e-006,0.000000e+000,3,1.742605e-001,0.000000e+000,,,,,,,,,,,,,,32,1,4.000000e+000,1.560211e-003,0.000000e+000,0,,0,
1524246182.705,,0.000000e+000,3.499950e+001,-1.081822e-006,0.000000e+000,3,1.208221e-001,0.000000e+000,,,,,,,,,,,,,,32,1,4.000000e+000,0.000000e+000,0.000000e+000,0,,0,
1524246220.660,,0.000000e+000,3.499833e+001,-1.109134e-006,0.000000e+000,3,1.447067e-001,0.000000e+000,,,,,,,,,,,,,,32,1,4.000000e+000,7.781982e-004,0.000000e+000,0,,0,
1524246258.246,,0.000000e+000,3.499950e+001,-1.034836e-006,0.000000e+000,3,5.319124e-002,0.000000e+000,,,,,,,,,,,,,,32,1,4.000000e+000,0.000000e+000,0.000000e+000,0,,0,
1524246297.044,,0.000000e+000,3.499911e+001,-1.082106e-006,0.000000e+000,3,1.144939e-001,0.000000e+000,,,,,,,,,,,,,,32,1,4.000000e+000,7.820129e-004,0.000000e+000,0,,0,
1524246335.077,,0.000000e+000,3.499872e+001,-1.036521e-006,0.000000e+000,3,8.918840e-002,0.000000e+000,,,,,,,,,,,,,,32,1,4.000000e+000,1.560211e-003,0.000000e+000,0,,0,
1524246373.138,,0.000000e+000,3.499989e+001,-1.057562e-006,0.000000e+000,3,9.869884e-002,0.000000e+000,,,,,,,,,,,,,,32,1,4.000000e+000,7.781982e-004,0.000000e+000,0,,0,
1524246411.198,,0.000000e+000,3.499833e+001,-1.031151e-006,0.000000e+000,3,8.749259e-002,0.000000e+000,,,,,,,,,,,,,,32,1,4.000000e+000,7.781982e-004,0.000000e+000,0,,0,
1524246449.271,,0.000000e+000,3.499911e+001,-1.024194e-006,0.000000e+000,3,5.758501e-002,0.000000e+000,,,,,,,,,,,,,,32,1,4.000000e+000,7.820129e-004,0.000000e+000,0,,0,
1524246487.347,,0.000000e+000,3.499833e+001,-1.046107e-006,0.000000e+000,3,7.610010e-002,0.000000e+000,,,,,,,,,,,,,,32,1,4.000000e+000,7.781982e-004,0.000000e+000,0,,0,
1524246525.192,,0.000000e+000,3.499950e+001,-1.008281e-006,0.000000e+000,3,5.178596e-002,0.000000e+000,,,,,,,,,,,,,,32,1,4.000000e+000,3.120422e-003,0.000000e+000,0,,0,
1524246564.021,,0.000000e+000,3.499833e+001,-9.857109e-007,0.000000e+000,3,2.019663e-002,0.000000e+000,,,,,,,,,,,,,,32,1,4.000000e+000,7.781982e-004,0.000000e+000,0,,0,
1524246602.114,,0.000000e+000,3.499911e+001,-9.808595e-007,0.000000e+000,3,1.986339e-002,0.000000e+000,,,,,,,,,,,,,,32,1,4.000000e+000,7.820129e-004,0.000000e+000,0,,0,
1524246640.139,,0.000000e+000,3.499833e+001,-9.611911e-007,0.000000e+000,3,0.000000e+000,0.000000e+000,,,,,,,,,,,,,,32,1,4.000000e+000,7.781982e-004,0.000000e+000,0,,0,
1524246678.265,,0.000000e+000,3.499989e+001,-9.690523e-007,0.000000e+000,3,3.516294e-003,0.000000e+000,,,,,,,,,,,,,,32,1,4.000000e+000,7.781982e-004,0.000000e+000,0,,0,
1524246715.870,,0.000000e+000,3.499950e+001,-9.744932e-007,0.000000e+000,3,2.761834e-002,0.000000e+000,,,,,,,,,,,,,,32,1,4.000000e+000,1.560211e-003,0.000000e+000,0,,0,
1524246753.086,,0.000000e+000,3.499911e+001,-9.524753e-007,0.000000e+000,3,0.000000e+000,0.000000e+000,,,,,,,,,,,,,,32,1,4.000000e+000,7.820129e-004,0.000000e+000,0,,0,
1524246791.639,,0.000000e+000,3.499911e+001,-9.411507e-007,0.000000e+000,3,0.000000e+000,0.000000e+000,,,,,,,,,,,,,,32,1,4.000000e+000,7.820129e-004,0.000000e+000,0,,0,
1524246829.507,,0.000000e+000,3.499911e+001,-9.055539e-007,0.000000e+000,3,0.000000e+000,0.000000e+000,,,,,,,,,,,,,,32,1,4.000000e+000,7.820129e-004,0.000000e+000,0,,0,
1524246867.715,,0.000000e+000,3.499872e+001,-8.623466e-007,0.000000e+000,3,0.000000e+000,0.000000e+000,,,,,,,,,,,,,,32,1,4.000000e+000,0.000000e+000,0.000000e+000,0,,0,
1524246905.721,,0.000000e+000,3.499911e+001,-9.349264e-007,0.000000e+000,3,0.000000e+000,0.000000e+000,,,,,,,,,,,,,,32,1,4.000000e+000,7.820129e-004,0.000000e+000,0,,0,
1524246943.889,,0.000000e+000,3.500106e+001,-8.858061e-007,0.000000e+000,3,0.000000e+000,0.000000e+000,,,,,,,,,,,,,,32,1,4.000000e+000,0.000000e+000,0.000000e+000,0,,0,
1524246981.397,,0.000000e+000,3.499872e+001,-9.079382e-007,0.000000e+000,3,0.000000e+000,0.000000e+000,,,,,,,,,,,,,,32,1,4.000000e+000,0.000000e+000,0.000000e+000,0,,0,
1524247018.950,,0.000000e+000,3.499950e+001,-8.421508e-007,0.000000e+000,3,0.000000e+000,0.000000e+000,,,,,,,,,,,,,,32,1,4.000000e+000,0.000000e+000,0.000000e+000,0,,0,
1524247057.775,,0.000000e+000,3.499911e+001,-9.014066e-007,0.000000e+000,3,0.000000e+000,0.000000e+000,,,,,,,,,,,,,,32,1,4.000000e+000,7.820129e-004,0.000000e+000,0,,0,
1524247095.838,,0.000000e+000,3.499950e+001,-8.940189e-007,0.000000e+000,3,0.000000e+000,0.000000e+000,,,,,,,,,,,,,,32,1,4.000000e+000,0.000000e+000,0.000000e+000,0,,0,
1524247133.104,,0.000000e+000,3.499989e+001,-8.468149e-007,0.000000e+000,3,0.000000e+000,0.000000e+000,,,,,,,,,,,,,,32,1,4.000000e+000,7.781982e-004,0.000000e+000,0,,0,
1524247170.782,,0.000000e+000,3.499950e+001,-8.409464e-007,0.000000e+000,3,0.000000e+000,0.000000e+000,,,,,,,,,,,,,,32,1,4.000000e+000,0.000000e+000,0.000000e+000,0,,0,
1524247208.265,,0.000000e+000,3.499950e+001,-8.592501e-007,0.000000e+000,3,0.000000e+000,0.000000e+000,,,,,,,,,,,,,,32,1,4.000000e+000,0.000000e+000,0.000000e+000,0,,0,
1524247245.721,,0.000000e+000,3.499950e+001,-8.374462e-007,0.000000e+000,3,0.000000e+000,0.000000e+000,,,,,,,,,,,,,,32,1,4.000000e+000,1.560211e-003,0.000000e+000,0,,0,
1524247283.031,,0.000000e+000,3.499989e+001,-8.417356e-007,0.000000e+000,3,0.000000e+000,0.000000e+000,,,,,,,,,,,,,,32,1,4.000000e+000,2.342224e-003,0.000000e+000,0,,0,
1524247321.049,,0.000000e+000,3.499872e+001,-8.332329e-007,0.000000e+000,3,0.000000e+000,0.000000e+000,,,,,,,,,,,,,,32,1,4.000000e+000,1.560211e-003,0.000000e+000,0,,0,
1524247359.545,,0.000000e+000,3.499989e+001,-8.384915e-007,0.000000e+000,3,0.000000e+000,0.000000e+000,,,,,,,,,,,,,,32,1,4.000000e+000,7.781982e-004,0.000000e+000,0,,0,
1524247398.140,,0.000000e+000,3.499833e+001,-8.088332e-007,0.000000e+000,3,0.000000e+000,0.000000e+000,,,,,,,,,,,,,,32,1,4.000000e+000,7.781982e-004,0.000000e+000,0,,0,
1524247435.228,,0.000000e+000,3.499950e+001,-8.102845e-007,0.000000e+000,3,0.000000e+000,0.000000e+000,,,,,,,,,,,,,,32,1,4.000000e+000,0.000000e+000,0.000000e+000,0,,0,
1524247473.296,,0.000000e+000,3.499950e+001,-7.991990e-007,0.000000e+000,3,0.000000e+000,0.000000e+000,,,,,,,,,,,,,,32,1,4.000000e+000,1.560211e-003,0.000000e+000,0,,0,
1524247513.157,,0.000000e+000,3.499833e+001,-8.258417e-007,0.000000e+000,3,0.000000e+000,0.000000e+000,,,,,,,,,,,,,,32,1,4.000000e+000,2.349854e-003,0.000000e+000,0,,0,
1524247550.405,,0.000000e+000,3.499950e+001,-8.288547e-007,0.000000e+000,3,0.000000e+000,0.000000e+000,,,,,,,,,,,,,,32,1,4.000000e+000,0.000000e+000,0.000000e+000,0,,0,
1524247587.321,,0.000000e+000,3.499911e+001,-8.381842e-007,0.000000e+000,3,0.000000e+000,0.000000e+000,,,,,,,,,,,,,,32,1,4.000000e+000,7.820129e-004,0.000000e+000,0,,0,
1524247625.464,,0.000000e+000,3.499911e+001,-7.984526e-007,0.000000e+000,3,0.000000e+000,0.000000e+000,,,,,,,,,,,,,,32,1,4.000000e+000,7.820129e-004,0.000000e+000,0,,0,
1524247662.854,,0.000000e+000,3.499950e+001,-7.313536e-007,0.000000e+000,3,0.000000e+000,0.000000e+000,,,,,,,,,,,,,,32,1,4.000000e+000,3.120422e-003,0.000000e+000,0,,0,
1524247700.887,,0.000000e+000,3.499911e+001,-7.639482e-007,0.000000e+000,3,0.000000e+000,0.000000e+000,,,,,,,,,,,,,,32,1,4.000000e+000,7.820129e-004,0.000000e+000,0,,0,
1524247739.133,,0.000000e+000,3.499833e+001,-8.220778e-007,0.000000e+000,3,0.000000e+000,0.000000e+000,,,,,,,,,,,,,,32,1,4.000000e+000,7.781982e-004,0.000000e+000,0,,0,
1524247777.083,,0.000000e+000,3.499833e+001,-7.354812e-007,0.000000e+000,3,0.000000e+000,0.000000e+000,,,,,,,,,,,,,,32,1,4.000000e+000,7.781982e-004,0.000000e+000,0,,0,
1524247814.939,,0.000000e+000,3.499911e+001,-7.396875e-007,0.000000e+000,3,0.000000e+000,0.000000e+000,,,,,,,,,,,,,,32,1,4.000000e+000,7.820129e-004,0.000000e+000,0,,0,
1524247853.219,,0.000000e+000,3.499911e+001,-7.297019e-007,0.000000e+000,3,0.000000e+000,0.000000e+000,,,,,,,,,,,,,,32,1,4.000000e+000,7.820129e-004,0.000000e+000,0,,0,
1524247891.075,,0.000000e+000,3.499911e+001,-6.274458e-007,0.000000e+000,3,0.000000e+000,0.000000e+000,,,,,,,,,,,,,,32,1,4.000000e+000,7.820129e-004,0.000000e+000,0,,0,
1524247927.728,,0.000000e+000,3.499872e+001,-7.643986e-007,0.000000e+000,3,0.000000e+000,0.000000e+000,,,,,,,,,,,,,,32,1,4.000000e+000,0.000000e+000,0.000000e+000,0,,0,
1524247965.769,,0.000000e+000,3.499793e+001,-7.728325e-007,0.000000e+000,3,0.000000e+000,0.000000e+000,,,,,,,,,,,,,,32,1,4.000000e+000,1.567841e-003,0.000000e+000,0,,0,
1524248003.832,,0.000000e+000,3.499872e+001,-6.960709e-007,0.000000e+000,3,0.000000e+000,0.000000e+000,,,,,,,,,,,,,,32,1,4.000000e+000,1.560211e-003,0.000000e+000,0,,0,
1524248041.290,,0.000000e+000,3.499833e+001,-7.130363e-007,0.000000e+000,3,0.000000e+000,0.000000e+000,,,,,,,,,,,,,,32,1,4.000000e+000,7.781982e-004,0.000000e+000,0,,0,
1524248079.348,,0.000000e+000,3.499872e+001,-7.295071e-007,0.000000e+000,3,0.000000e+000,0.000000e+000,,,,,,,,,,,,,,32,1,4.000000e+000,1.560211e-003,0.000000e+000,0,,0,
1524248118.106,,0.000000e+000,3.499989e+001,-7.058498e-007,0.000000e+000,3,0.000000e+000,0.000000e+000,,,,,,,,,,,,,,32,1,4.000000e+000,2.342224e-003,0.000000e+000,0,,0,
1524248156.269,,0.000000e+000,3.499911e+001,-7.086758e-007,0.000000e+000,3,0.000000e+000,0.000000e+000,,,,,,,,,,,,,,32,1,4.000000e+000,7.820129e-004,0.000000e+000,0,,0,
1524248194.259,,0.000000e+000,3.499950e+001,-6.676373e-007,0.000000e+000,3,0.000000e+000,0.000000e+000,,,,,,,,,,,,,,32,1,4.000000e+000,0.000000e+000,0.000000e+000,0,,0,
1524248232.292,,0.000000e+000,3.499989e+001,-6.893446e-007,0.000000e+000,3,0.000000e+000,0.000000e+000,,,,,,,,,,,,,,32,1,4.000000e+000,7.781982e-004,0.000000e+000,0,,0,
1524248271.158,,0.000000e+000,3.500185e+001,-6.312756e-007,0.000000e+000,3,0.000000e+000,0.000000e+000,,,,,,,,,,,,,,32,1,4.000000e+000,4.688263e-003,0.000000e+000,0,,0,
1524248309.776,,0.000000e+000,3.499911e+001,-6.125681e-007,0.000000e+000,3,0.000000e+000,0.000000e+000,,,,,,,,,,,,,,32,1,4.000000e+000,7.820129e-004,0.000000e+000,0,,0,
1524248348.704,,0.000000e+000,3.499989e+001,-6.559181e-007,0.000000e+000,3,0.000000e+000,0.000000e+000,,,,,,,,,,,,,,32,1,4.000000e+000,7.781982e-004,0.000000e+000,0,,0,
1524248387.197,,0.000000e+000,3.499950e+001,-6.484223e-007,0.000000e+000,3,0.000000e+000,0.000000e+000,,,,,,,,,,,,,,32,1,4.000000e+000,0.000000e+000,0.000000e+000,0,,0,
1524248424.318,,0.000000e+000,3.500028e+001,-6.966732e-007,0.000000e+000,3,0.000000e+000,0.000000e+000,,,,,,,,,,,,,,32,1,4.000000e+000,1.560211e-003,0.000000e+000,0,,0,
1524248462.833,,0.000000e+000,3.499872e+001,-6.478008e-007,0.000000e+000,3,0.000000e+000,0.000000e+000,,,,,,,,,,,,,,32,1,4.000000e+000,1.560211e-003,0.000000e+000,0,,0,
1524248500.919,,0.000000e+000,3.499950e+001,-6.327322e-007,0.000000e+000,3,0.000000e+000,0.000000e+000,,,,,,,,,,,,,,32,1,4.000000e+000,0.000000e+000,0.000000e+000,0,,0,
1524248538.502,,0.000000e+000,3.499872e+001,-6.270524e-007,0.000000e+000,3,0.000000e+000,0.000000e+000,,,,,,,,,,,,,,32,1,4.000000e+000,1.560211e-003,0.000000e+000,0,,0,
1524248576.503,,0.000000e+000,3.499872e+001,-6.361620e-007,0.000000e+000,3,0.000000e+000,0.000000e+000,,,,,,,,,,,,,,32,1,4.000000e+000,0.000000e+000,0.000000e+000,0,,0,
1524248614.596,,0.000000e+000,3.499950e+001,-6.023752e-007,0.000000e+000,3,0.000000e+000,0.000000e+000,,,,,,,,,,,,,,32,1,4.000000e+000,1.560211e-003,0.000000e+000,0,,0,
1524248652.599,,0.000000e+000,3.499911e+001,-5.074315e-007,0.000000e+000,3,0.000000e+000,0.000000e+000,,,,,,,,,,,,,,32,1,4.000000e+000,7.820129e-004,0.000000e+000,0,,0,
1524248690.664,,0.000000e+000,3.499911e+001,-6.169682e-007,0.000000e+000,3,0.000000e+000,0.000000e+000,,,,,,,,,,,,,,32,1,4.000000e+000,7.820129e-004,0.000000e+000,0,,0,
1524248728.730,,0.000000e+000,3.499950e+001,-6.211594e-007,0.000000e+000,3,0.000000e+000,0.000000e+000,,,,,,,,,,,,,,32,1,4.000000e+000,0.000000e+000,0.000000e+000,0,,0,
1524248766.865,,0.000000e+000,3.499989e+001,-5.755143e-007,0.000000e+000,3,0.000000e+000,0.000000e+000,,,,,,,,,,,,,,32,1,4.000000e+000,7.781982e-004,0.000000e+000,0,,0,
1524248804.413,,0.000000e+000,3.499989e+001,-5.703130e-007,0.000000e+000,3,0.000000e+000,0.000000e+000,,,,,,,,,,,,,,32,1,4.000000e+000,7.781982e-004,0.000000e+000,0,,0,
1524248842.939,,0.000000e+000,3.499950e+001,-5.624890e-007,0.000000e+000,3,0.000000e+000,0.000000e+000,,,,,,,,,,,,,,32,1,4.000000e+000,0.000000e+000,0.000000e+000,0,,0,
1524248881.002,,0.000000e+000,3.499989e+001,-5.959382e-007,0.000000e+000,3,0.000000e+000,0.000000e+000,,,,,,,,,,,,,,32,1,4.000000e+000,7.781982e-004,0.000000e+000,0,,0,
1524248919.100,,0.000000e+000,3.499911e+001,-5.919669e-007,0.000000e+000,3,0.000000e+000,0.000000e+000,,,,,,,,,,,,,,32,1,4.000000e+000,7.820129e-004,0.000000e+000,0,,0,
1524248956.683,,0.000000e+000,3.499950e+001,-5.891491e-007,0.000000e+000,3,0.000000e+000,0.000000e+000,,,,,,,,,,,,,,32,1,4.000000e+000,0.000000e+000,0.000000e+000,0,,0,
1524248994.744,,0.000000e+000,3.499833e+001,-5.611484e-007,0.000000e+000,3,0.000000e+000,0.000000e+000,,,,,,,,,,,,,,32,1,4.000000e+000,7.781982e-004,0.000000e+000,0,,0,
1524249032.792,,0.000000e+000,3.499911e+001,-4.462687e-007,0.000000e+000,3,0.000000e+000,0.000000e+000,,,,,,,,,,,,,,32,1,4.000000e+000,7.820129e-004,0.000000e+000,0,,0,
1524249070.340,,0.000000e+000,3.499833e+001,-4.564978e-007,0.000000e+000,3,0.000000e+000,0.000000e+000,,,,,,,,,,,,,,32,1,4.000000e+000,7.781982e-004,0.000000e+000,0,,0,
1524249108.428,,0.000000e+000,3.499950e+001,-4.030128e-007,0.000000e+000,3,0.000000e+000,0.000000e+000,,,,,,,,,,,,,,32,1,4.000000e+000,0.000000e+000,0.000000e+000,0,,0,
1524249146.463,,0.000000e+000,3.499989e+001,-5.203813e-007,0.000000e+000,3,0.000000e+000,0.000000e+000,,,,,,,,,,,,,,32,1,4.000000e+000,7.781982e-004,0.000000e+000,0,,0,
1524249184.521,,0.000000e+000,3.500067e+001,-4.897983e-007,0.000000e+000,3,0.000000e+000,0.000000e+000,,,,,,,,,,,,,,32,1,4.000000e+000,3.910065e-003,0.000000e+000,0,,0,
1524249222.895,,0.000000e+000,3.499911e+001,-4.364888e-007,0.000000e+000,3,0.000000e+000,0.000000e+000,,,,,,,,,,,,,,32,1,4.000000e+000,7.820129e-004,0.000000e+000,0,,0,
1524249261.098,,0.000000e+000,3.499872e+001,-4.884984e-007,0.000000e+000,3,0.000000e+000,0.000000e+000,,,,,,,,,,,,,,32,1,4.000000e+000,0.000000e+000,0.000000e+000,0,,0,
1524249299.171,,0.000000e+000,3.499872e+001,-3.173011e-007,0.000000e+000,3,0.000000e+000,0.000000e+000,,,,,,,,,,,,,,32,1,4.000000e+000,0.000000e+000,0.000000e+000,0,,0,
1524249336.779,,0.000000e+000,3.499950e+001,7.969404e-007,0.000000e+000,3,0.000000e+000,0.000000e+000,,,,,,,,,,,,,,32,1,4.000000e+000,0.000000e+000,0.000000e+000,0,,0,
1524249374.852,,0.000000e+000,3.499793e+001,-4.515604e-007,0.000000e+000,3,0.000000e+000,0.000000e+000,,,,,,,,,,,,,,32,1,4.000000e+000,1.567841e-003,0.000000e+000,0,,0,
1524249412.925,,0.000000e+000,3.499911e+001,-5.251138e-007,0.000000e+000,3,0.000000e+000,0.000000e+000,,,,,,,,,,,,,,32,1,4.000000e+000,7.820129e-004,0.000000e+000,0,,0,
1524249451.455,,0.000000e+000,3.500028e+001,-3.331894e-007,0.000000e+000,3,0.000000e+000,0.000000e+000,,,,,,,,,,,,,,32,1,4.000000e+000,1.560211e-003,0.000000e+000,0,,0,
1524249489.038,,0.000000e+000,3.499989e+001,-3.476522e-007,0.000000e+000,3,0.000000e+000,0.000000e+000,,,,,,,,,,,,,,32,1,4.000000e+000,7.781982e-004,0.000000e+000,0,,0,
1524249514.366,,0.000000e+000,3.499872e+001,-1.198368e-007,0.000000e+000,3,0.000000e+000,0.000000e+000,,,,,,,,,,,,,,32,1,4.000000e+000,0.000000e+000,0.000000e+000,0,,0,