File: Experimental Raw Data/MFn1 VRM/Iterative Regression/MFn1_VRMac_40K_12000s_VRMde_40K_12000s.dc.dat
[Header]
TITLE,MPMS DC Measurement
BYAPP,MPMS Measurement,2.1,Summary
FILEOPENTIME, 1523919102.216000 4/16/2018, 4:51:42 PM

INFO, APPNAME, MPMS MultiVu Application, Revision 1.61,  Build 082

INFO, NAME, MFn1
INFO, WEIGHT, 1.000
INFO, AREA, 1.000
INFO, LENGTH, 1.000
INFO, SHAPE, 0
INFO, COMMENT,
INFO, SEQUENCE FILE: VRMac_40K_12000s_VRMde_40K_12000s.seq


INFO, BACKGROUND DATA FILE:, None


STARTUPAXIS,X,4,LINEAR,AUTO,0.000000,0.000000
STARTUPAXIS,Y1,5,LINEAR,AUTO,0.000000,0.000000


STARTUPGROUP,Longitudinal
FIELDGROUP,Longitudinal,1,2,3,4,5,6,7,8,9,15,16,17,18,27,28
FIELDGROUP,Transverse,1,2,3,4,10,11,12,13,14,19,20,21,22,27,28

PLOT_APPEARANCE,ALL,HORZ_GRID_ON,VERT_GRID_ON,MARKERS_AND_LINES

[Data]
Time,Comment,Field (Oe),Temperature (K),Long Moment (emu),Long Scan Std Dev,Long Algorithm,Long Reg Fit,Long Percent Error (%),Trans Moment (emu),Trans Scan Std Dev,Trans Algorithm,Trans Reg Fit,Trans Percent Error (%),Long Moment [w/o ABS] (emu),Long Scan Std Dev [w/o ABS],Long Reg Fit [w/o ABS],Long Percent Error [w/o ABS] (%),Trans Moment [w/o ABS] (emu),Trans Scan Std Dev [w/o ABS],Trans Reg Fit [w/o ABS],Trans Percent Error [w/o ABS] (%),Points per Scan,Scans per Measurement,Scan Length (cm),Delta Temp (K),Rot Position (deg),Error,EC Comp. Running,Using ABS,
1523919102.214,,0.000000e+000,4.000042e+001,-2.854214e-005,0.000000e+000,3,9.713777e-001,0.000000e+000,,,,,,,,,,,,,,32,1,4.000000e+000,1.029968e-003,0.000000e+000,0,,0,
1523919153.692,,0.000000e+000,3.999939e+001,-2.401431e-005,0.000000e+000,3,9.655408e-001,0.000000e+000,,,,,,,,,,,,,,32,1,4.000000e+000,3.097534e-003,0.000000e+000,0,,0,
1523919203.885,,0.000000e+000,3.999887e+001,-2.181276e-005,0.000000e+000,3,9.621086e-001,0.000000e+000,,,,,,,,,,,,,,32,1,4.000000e+000,2.067566e-003,0.000000e+000,0,,0,
1523919252.861,,0.000000e+000,4.000042e+001,-2.025149e-005,0.000000e+000,3,9.591110e-001,0.000000e+000,,,,,,,,,,,,,,32,1,4.000000e+000,1.029968e-003,0.000000e+000,0,,0,
1523919303.224,,0.000000e+000,4.000042e+001,-1.906649e-005,0.000000e+000,3,9.587854e-001,0.000000e+000,,,,,,,,,,,,,,32,1,4.000000e+000,1.029968e-003,0.000000e+000,0,,0,
1523919353.350,,0.000000e+000,3.999939e+001,-1.814381e-005,0.000000e+000,3,9.507124e-001,0.000000e+000,,,,,,,,,,,,,,32,1,4.000000e+000,1.029968e-003,0.000000e+000,0,,0,
1523919403.886,,0.000000e+000,3.999732e+001,-1.725431e-005,0.000000e+000,3,9.523199e-001,0.000000e+000,,,,,,,,,,,,,,32,1,4.000000e+000,3.108978e-003,0.000000e+000,0,,0,
1523919455.402,,0.000000e+000,3.999888e+001,-1.650048e-005,0.000000e+000,3,9.521227e-001,0.000000e+000,,,,,,,,,,,,,,32,1,4.000000e+000,0.000000e+000,0.000000e+000,0,,0,
1523919505.825,,0.000000e+000,3.999836e+001,-1.592182e-005,0.000000e+000,3,9.470336e-001,0.000000e+000,,,,,,,,,,,,,,32,1,4.000000e+000,3.097534e-003,0.000000e+000,0,,0,
1523919557.631,,0.000000e+000,4.000145e+001,-1.535925e-005,0.000000e+000,3,9.453286e-001,0.000000e+000,,,,,,,,,,,,,,32,1,4.000000e+000,3.089905e-003,0.000000e+000,0,,0,
1523919607.881,,0.000000e+000,3.999939e+001,-1.484529e-005,0.000000e+000,3,9.417004e-001,0.000000e+000,,,,,,,,,,,,,,32,1,4.000000e+000,1.029968e-003,0.000000e+000,0,,0,
1523919658.400,,0.000000e+000,4.000094e+001,-1.431726e-005,0.000000e+000,3,9.376490e-001,0.000000e+000,,,,,,,,,,,,,,32,1,4.000000e+000,0.000000e+000,0.000000e+000,0,,0,
1523919710.860,,0.000000e+000,3.999784e+001,-1.394861e-005,0.000000e+000,3,9.392025e-001,0.000000e+000,,,,,,,,,,,,,,32,1,4.000000e+000,2.067566e-003,0.000000e+000,0,,0,
1523919762.306,,0.000000e+000,3.999939e+001,-1.358012e-005,0.000000e+000,3,9.370770e-001,0.000000e+000,,,,,,,,,,,,,,32,1,4.000000e+000,1.029968e-003,0.000000e+000,0,,0,
1523919813.914,,0.000000e+000,3.999939e+001,-1.323570e-005,0.000000e+000,3,9.383578e-001,0.000000e+000,,,,,,,,,,,,,,32,1,4.000000e+000,5.157471e-003,0.000000e+000,0,,0,
1523919865.025,,0.000000e+000,3.999991e+001,-1.292399e-005,0.000000e+000,3,9.353029e-001,0.000000e+000,,,,,,,,,,,,,,32,1,4.000000e+000,0.000000e+000,0.000000e+000,0,,0,
1523919914.651,,0.000000e+000,3.999784e+001,-1.263763e-005,0.000000e+000,3,9.305161e-001,0.000000e+000,,,,,,,,,,,,,,32,1,4.000000e+000,4.138947e-003,0.000000e+000,0,,0,
1523919963.176,,0.000000e+000,3.999939e+001,-1.235757e-005,0.000000e+000,3,9.322852e-001,0.000000e+000,,,,,,,,,,,,,,32,1,4.000000e+000,1.029968e-003,0.000000e+000,0,,0,
1523920015.250,,0.000000e+000,3.999991e+001,-1.202346e-005,0.000000e+000,3,9.282014e-001,0.000000e+000,,,,,,,,,,,,,,32,1,4.000000e+000,2.059937e-003,0.000000e+000,0,,0,
1523920066.648,,0.000000e+000,3.999991e+001,-1.175808e-005,0.000000e+000,3,9.280031e-001,0.000000e+000,,,,,,,,,,,,,,32,1,4.000000e+000,2.059937e-003,0.000000e+000,0,,0,
1523920118.099,,0.000000e+000,4.000042e+001,-1.159363e-005,0.000000e+000,3,9.249776e-001,0.000000e+000,,,,,,,,,,,,,,32,1,4.000000e+000,1.029968e-003,0.000000e+000,0,,0,
1523920170.085,,0.000000e+000,3.999887e+001,-1.128685e-005,0.000000e+000,3,9.234735e-001,0.000000e+000,,,,,,,,,,,,,,32,1,4.000000e+000,4.127502e-003,0.000000e+000,0,,0,
1523920220.698,,0.000000e+000,3.999887e+001,-1.107130e-005,0.000000e+000,3,9.211114e-001,0.000000e+000,,,,,,,,,,,,,,32,1,4.000000e+000,2.067566e-003,0.000000e+000,0,,0,
1523920271.829,,0.000000e+000,3.999887e+001,-1.080128e-005,0.000000e+000,3,9.194742e-001,0.000000e+000,,,,,,,,,,,,,,32,1,4.000000e+000,2.067566e-003,0.000000e+000,0,,0,
1523920323.674,,0.000000e+000,3.999732e+001,-1.062295e-005,0.000000e+000,3,9.160109e-001,0.000000e+000,,,,,,,,,,,,,,32,1,4.000000e+000,3.108978e-003,0.000000e+000,0,,0,
1523920374.498,,0.000000e+000,3.999526e+001,-1.044429e-005,0.000000e+000,3,9.212021e-001,0.000000e+000,,,,,,,,,,,,,,32,1,4.000000e+000,5.161285e-003,0.000000e+000,0,,0,
1523920425.818,,0.000000e+000,3.999888e+001,-1.025639e-005,0.000000e+000,3,9.162271e-001,0.000000e+000,,,,,,,,,,,,,,32,1,4.000000e+000,0.000000e+000,0.000000e+000,0,,0,
1523920478.397,,0.000000e+000,3.999991e+001,-1.008139e-005,0.000000e+000,3,9.185854e-001,0.000000e+000,,,,,,,,,,,,,,32,1,4.000000e+000,2.059937e-003,0.000000e+000,0,,0,
1523920529.187,,0.000000e+000,4.000042e+001,-9.896873e-006,0.000000e+000,3,9.096041e-001,0.000000e+000,,,,,,,,,,,,,,32,1,4.000000e+000,1.029968e-003,0.000000e+000,0,,0,
1523920579.363,,0.000000e+000,4.000145e+001,-9.757931e-006,0.000000e+000,3,9.113721e-001,0.000000e+000,,,,,,,,,,,,,,32,1,4.000000e+000,3.089905e-003,0.000000e+000,0,,0,
1523920629.019,,0.000000e+000,3.999991e+001,-9.608126e-006,0.000000e+000,3,9.105412e-001,0.000000e+000,,,,,,,,,,,,,,32,1,4.000000e+000,2.059937e-003,0.000000e+000,0,,0,
1523920677.562,,0.000000e+000,3.999888e+001,-9.391307e-006,0.000000e+000,3,9.071344e-001,0.000000e+000,,,,,,,,,,,,,,32,1,4.000000e+000,0.000000e+000,0.000000e+000,0,,0,
1523920727.410,,0.000000e+000,3.999939e+001,-9.293892e-006,0.000000e+000,3,9.065335e-001,0.000000e+000,,,,,,,,,,,,,,32,1,4.000000e+000,3.097534e-003,0.000000e+000,0,,0,
1523920779.168,,0.000000e+000,3.999836e+001,-9.136205e-006,0.000000e+000,3,9.032256e-001,0.000000e+000,,,,,,,,,,,,,,32,1,4.000000e+000,3.097534e-003,0.000000e+000,0,,0,
1523920830.384,,0.000000e+000,3.999887e+001,-9.000230e-006,0.000000e+000,3,9.037225e-001,0.000000e+000,,,,,,,,,,,,,,32,1,4.000000e+000,2.067566e-003,0.000000e+000,0,,0,
1523920879.410,,0.000000e+000,3.999939e+001,-8.880955e-006,0.000000e+000,3,9.023085e-001,0.000000e+000,,,,,,,,,,,,,,32,1,4.000000e+000,3.097534e-003,0.000000e+000,0,,0,
1523920931.133,,0.000000e+000,3.999991e+001,-8.758949e-006,0.000000e+000,3,8.972493e-001,0.000000e+000,,,,,,,,,,,,,,32,1,4.000000e+000,0.000000e+000,0.000000e+000,0,,0,
1523920982.539,,0.000000e+000,3.999887e+001,-8.626623e-006,0.000000e+000,3,8.990000e-001,0.000000e+000,,,,,,,,,,,,,,32,1,4.000000e+000,2.067566e-003,0.000000e+000,0,,0,
1523921033.160,,0.000000e+000,4.000042e+001,-8.492460e-006,0.000000e+000,3,8.918815e-001,0.000000e+000,,,,,,,,,,,,,,32,1,4.000000e+000,1.029968e-003,0.000000e+000,0,,0,
1523921083.460,,0.000000e+000,3.999991e+001,-8.340549e-006,0.000000e+000,3,8.963996e-001,0.000000e+000,,,,,,,,,,,,,,32,1,4.000000e+000,0.000000e+000,0.000000e+000,0,,0,
1523921133.081,,0.000000e+000,4.000042e+001,-8.282340e-006,0.000000e+000,3,8.926429e-001,0.000000e+000,,,,,,,,,,,,,,32,1,4.000000e+000,3.089905e-003,0.000000e+000,0,,0,
1523921183.354,,0.000000e+000,3.999836e+001,-8.173457e-006,0.000000e+000,3,8.910314e-001,0.000000e+000,,,,,,,,,,,,,,32,1,4.000000e+000,1.037598e-003,0.000000e+000,0,,0,
1523921234.728,,0.000000e+000,3.999836e+001,-8.001986e-006,0.000000e+000,3,8.838557e-001,0.000000e+000,,,,,,,,,,,,,,32,1,4.000000e+000,3.097534e-003,0.000000e+000,0,,0,
1523921284.603,,0.000000e+000,3.999733e+001,-7.944399e-006,0.000000e+000,3,8.876877e-001,0.000000e+000,,,,,,,,,,,,,,32,1,4.000000e+000,1.029968e-003,0.000000e+000,0,,0,
1523921333.422,,0.000000e+000,3.999888e+001,-7.854237e-006,0.000000e+000,3,8.877173e-001,0.000000e+000,,,,,,,,,,,,,,32,1,4.000000e+000,0.000000e+000,0.000000e+000,0,,0,
1523921384.910,,0.000000e+000,4.000042e+001,-7.719157e-006,0.000000e+000,3,8.846338e-001,0.000000e+000,,,,,,,,,,,,,,32,1,4.000000e+000,1.029968e-003,0.000000e+000,0,,0,
1523921434.268,,0.000000e+000,3.999784e+001,-7.632436e-006,0.000000e+000,3,8.857403e-001,0.000000e+000,,,,,,,,,,,,,,32,1,4.000000e+000,0.000000e+000,0.000000e+000,0,,0,
1523921484.079,,0.000000e+000,3.999888e+001,-7.541653e-006,0.000000e+000,3,8.826202e-001,0.000000e+000,,,,,,,,,,,,,,32,1,4.000000e+000,0.000000e+000,0.000000e+000,0,,0,
1523921535.420,,0.000000e+000,3.999784e+001,-7.428930e-006,0.000000e+000,3,8.809090e-001,0.000000e+000,,,,,,,,,,,,,,32,1,4.000000e+000,2.067566e-003,0.000000e+000,0,,0,
1523921586.148,,0.000000e+000,3.999888e+001,-7.361165e-006,0.000000e+000,3,8.802364e-001,0.000000e+000,,,,,,,,,,,,,,32,1,4.000000e+000,0.000000e+000,0.000000e+000,0,,0,
1523921638.471,,0.000000e+000,4.000145e+001,-7.236440e-006,0.000000e+000,3,8.713755e-001,0.000000e+000,,,,,,,,,,,,,,32,1,4.000000e+000,3.089905e-003,0.000000e+000,0,,0,
1523921688.944,,0.000000e+000,3.999887e+001,-7.143170e-006,0.000000e+000,3,8.684256e-001,0.000000e+000,,,,,,,,,,,,,,32,1,4.000000e+000,2.067566e-003,0.000000e+000,0,,0,
1523921739.620,,0.000000e+000,4.000094e+001,-7.059170e-006,0.000000e+000,3,8.712733e-001,0.000000e+000,,,,,,,,,,,,,,32,1,4.000000e+000,4.119873e-003,0.000000e+000,0,,0,
1523921791.126,,0.000000e+000,3.999887e+001,-6.992600e-006,0.000000e+000,3,8.713967e-001,0.000000e+000,,,,,,,,,,,,,,32,1,4.000000e+000,2.067566e-003,0.000000e+000,0,,0,
1523921844.054,,0.000000e+000,3.999939e+001,-6.945184e-006,0.000000e+000,3,8.707617e-001,0.000000e+000,,,,,,,,,,,,,,32,1,4.000000e+000,1.029968e-003,0.000000e+000,0,,0,
1523921895.565,,0.000000e+000,3.999991e+001,-6.806293e-006,0.000000e+000,3,8.620844e-001,0.000000e+000,,,,,,,,,,,,,,32,1,4.000000e+000,0.000000e+000,0.000000e+000,0,,0,
1523921946.276,,0.000000e+000,3.999939e+001,-6.771493e-006,0.000000e+000,3,8.656825e-001,0.000000e+000,,,,,,,,,,,,,,32,1,4.000000e+000,1.029968e-003,0.000000e+000,0,,0,
1523921996.619,,0.000000e+000,3.999732e+001,-6.651322e-006,0.000000e+000,3,8.593020e-001,0.000000e+000,,,,,,,,,,,,,,32,1,4.000000e+000,3.108978e-003,0.000000e+000,0,,0,
1523922047.387,,0.000000e+000,3.999887e+001,-6.611681e-006,0.000000e+000,3,8.624076e-001,0.000000e+000,,,,,,,,,,,,,,32,1,4.000000e+000,2.067566e-003,0.000000e+000,0,,0,
1523922098.915,,0.000000e+000,3.999888e+001,-6.500848e-006,0.000000e+000,3,8.581471e-001,0.000000e+000,,,,,,,,,,,,,,32,1,4.000000e+000,0.000000e+000,0.000000e+000,0,,0,
1523922150.409,,0.000000e+000,3.999888e+001,-6.454023e-006,0.000000e+000,3,8.572533e-001,0.000000e+000,,,,,,,,,,,,,,32,1,4.000000e+000,0.000000e+000,0.000000e+000,0,,0,
1523922200.322,,0.000000e+000,3.999888e+001,-6.416803e-006,0.000000e+000,3,8.553616e-001,0.000000e+000,,,,,,,,,,,,,,32,1,4.000000e+000,0.000000e+000,0.000000e+000,0,,0,
1523922253.025,,0.000000e+000,3.999784e+001,-6.295381e-006,0.000000e+000,3,8.484562e-001,0.000000e+000,,,,,,,,,,,,,,32,1,4.000000e+000,0.000000e+000,0.000000e+000,0,,0,
1523922302.958,,0.000000e+000,3.999888e+001,-6.252377e-006,0.000000e+000,3,8.487381e-001,0.000000e+000,,,,,,,,,,,,,,32,1,4.000000e+000,0.000000e+000,0.000000e+000,0,,0,
1523922353.389,,0.000000e+000,4.000094e+001,-6.202219e-006,0.000000e+000,3,8.551873e-001,0.000000e+000,,,,,,,,,,,,,,32,1,4.000000e+000,0.000000e+000,0.000000e+000,0,,0,
1523922402.667,,0.000000e+000,3.999784e+001,-6.167568e-006,0.000000e+000,3,8.547238e-001,0.000000e+000,,,,,,,,,,,,,,32,1,4.000000e+000,2.067566e-003,0.000000e+000,0,,0,
1523922454.218,,0.000000e+000,3.999888e+001,-6.018437e-006,0.000000e+000,3,8.463464e-001,0.000000e+000,,,,,,,,,,,,,,32,1,4.000000e+000,0.000000e+000,0.000000e+000,0,,0,
1523922503.659,,0.000000e+000,3.999836e+001,-5.975201e-006,0.000000e+000,3,8.409414e-001,0.000000e+000,,,,,,,,,,,,,,32,1,4.000000e+000,1.037598e-003,0.000000e+000,0,,0,
1523922554.972,,0.000000e+000,3.999888e+001,-5.910112e-006,0.000000e+000,3,8.367687e-001,0.000000e+000,,,,,,,,,,,,,,32,1,4.000000e+000,0.000000e+000,0.000000e+000,0,,0,
1523922605.543,,0.000000e+000,3.999888e+001,-5.936149e-006,0.000000e+000,3,8.408530e-001,0.000000e+000,,,,,,,,,,,,,,32,1,4.000000e+000,0.000000e+000,0.000000e+000,0,,0,
1523922656.168,,0.000000e+000,3.999939e+001,-5.811282e-006,0.000000e+000,3,8.325079e-001,0.000000e+000,,,,,,,,,,,,,,32,1,4.000000e+000,1.029968e-003,0.000000e+000,0,,0,
1523922707.514,,0.000000e+000,3.999939e+001,-5.757542e-006,0.000000e+000,3,8.360671e-001,0.000000e+000,,,,,,,,,,,,,,32,1,4.000000e+000,1.029968e-003,0.000000e+000,0,,0,
1523922758.893,,0.000000e+000,3.999939e+001,-5.683037e-006,0.000000e+000,3,8.280417e-001,0.000000e+000,,,,,,,,,,,,,,32,1,4.000000e+000,1.029968e-003,0.000000e+000,0,,0,
1523922809.583,,0.000000e+000,3.999939e+001,-5.648454e-006,0.000000e+000,3,8.348166e-001,0.000000e+000,,,,,,,,,,,,,,32,1,4.000000e+000,1.029968e-003,0.000000e+000,0,,0,
1523922858.139,,0.000000e+000,3.999991e+001,-5.633035e-006,0.000000e+000,3,8.308598e-001,0.000000e+000,,,,,,,,,,,,,,32,1,4.000000e+000,0.000000e+000,0.000000e+000,0,,0,
1523922909.902,,0.000000e+000,3.999784e+001,-5.483733e-006,0.000000e+000,3,8.277817e-001,0.000000e+000,,,,,,,,,,,,,,32,1,4.000000e+000,0.000000e+000,0.000000e+000,0,,0,
1523922961.286,,0.000000e+000,4.000094e+001,-5.487922e-006,0.000000e+000,3,8.248734e-001,0.000000e+000,,,,,,,,,,,,,,32,1,4.000000e+000,0.000000e+000,0.000000e+000,0,,0,
1523923012.866,,0.000000e+000,3.999888e+001,-5.434645e-006,0.000000e+000,3,8.288716e-001,0.000000e+000,,,,,,,,,,,,,,32,1,4.000000e+000,0.000000e+000,0.000000e+000,0,,0,
1523923064.222,,0.000000e+000,4.000248e+001,-5.434051e-006,0.000000e+000,3,8.249013e-001,0.000000e+000,,,,,,,,,,,,,,32,1,4.000000e+000,1.029968e-003,0.000000e+000,0,,0,
1523923115.013,,0.000000e+000,3.999835e+001,-5.328389e-006,0.000000e+000,3,8.193634e-001,0.000000e+000,,,,,,,,,,,,,,32,1,4.000000e+000,5.168915e-003,0.000000e+000,0,,0,
1523923165.821,,0.000000e+000,3.999836e+001,-5.306479e-006,0.000000e+000,3,8.166117e-001,0.000000e+000,,,,,,,,,,,,,,32,1,4.000000e+000,1.037598e-003,0.000000e+000,0,,0,
1523923216.744,,0.000000e+000,3.999680e+001,-5.226021e-006,0.000000e+000,3,8.210731e-001,0.000000e+000,,,,,,,,,,,,,,32,1,4.000000e+000,2.071381e-003,0.000000e+000,0,,0,
1523923268.127,,0.000000e+000,3.999991e+001,-5.231112e-006,0.000000e+000,3,8.124747e-001,0.000000e+000,,,,,,,,,,,,,,32,1,4.000000e+000,2.059937e-003,0.000000e+000,0,,0,
1523923319.116,,0.000000e+000,4.000042e+001,-5.147256e-006,0.000000e+000,3,8.083625e-001,0.000000e+000,,,,,,,,,,,,,,32,1,4.000000e+000,1.029968e-003,0.000000e+000,0,,0,
1523923369.904,,0.000000e+000,4.000094e+001,-5.132410e-006,0.000000e+000,3,8.124056e-001,0.000000e+000,,,,,,,,,,,,,,32,1,4.000000e+000,2.059937e-003,0.000000e+000,0,,0,
1523923419.850,,0.000000e+000,4.000042e+001,-5.070519e-006,0.000000e+000,3,8.021349e-001,0.000000e+000,,,,,,,,,,,,,,32,1,4.000000e+000,1.029968e-003,0.000000e+000,0,,0,
1523923471.075,,0.000000e+000,3.999888e+001,-5.062589e-006,0.000000e+000,3,8.018333e-001,0.000000e+000,,,,,,,,,,,,,,32,1,4.000000e+000,0.000000e+000,0.000000e+000,0,,0,
1523923521.889,,0.000000e+000,3.999836e+001,-4.996360e-006,0.000000e+000,3,8.113160e-001,0.000000e+000,,,,,,,,,,,,,,32,1,4.000000e+000,3.097534e-003,0.000000e+000,0,,0,
1523923571.777,,0.000000e+000,3.999887e+001,-4.942210e-006,0.000000e+000,3,8.013442e-001,0.000000e+000,,,,,,,,,,,,,,32,1,4.000000e+000,2.067566e-003,0.000000e+000,0,,0,
1523923623.210,,0.000000e+000,3.999939e+001,-4.904227e-006,0.000000e+000,3,8.084387e-001,0.000000e+000,,,,,,,,,,,,,,32,1,4.000000e+000,1.029968e-003,0.000000e+000,0,,0,
1523923674.629,,0.000000e+000,4.000094e+001,-4.868482e-006,0.000000e+000,3,7.966589e-001,0.000000e+000,,,,,,,,,,,,,,32,1,4.000000e+000,6.198883e-003,0.000000e+000,0,,0,
1523923723.919,,0.000000e+000,3.999888e+001,-4.835105e-006,0.000000e+000,3,8.032571e-001,0.000000e+000,,,,,,,,,,,,,,32,1,4.000000e+000,0.000000e+000,0.000000e+000,0,,0,
1523923775.210,,0.000000e+000,3.999991e+001,-4.816445e-006,0.000000e+000,3,7.989643e-001,0.000000e+000,,,,,,,,,,,,,,32,1,4.000000e+000,0.000000e+000,0.000000e+000,0,,0,
1523923826.088,,0.000000e+000,3.999991e+001,-4.735208e-006,0.000000e+000,3,7.801608e-001,0.000000e+000,,,,,,,,,,,,,,32,1,4.000000e+000,2.059937e-003,0.000000e+000,0,,0,
1523923877.091,,0.000000e+000,3.999939e+001,-4.746330e-006,0.000000e+000,3,7.957367e-001,0.000000e+000,,,,,,,,,,,,,,32,1,4.000000e+000,1.029968e-003,0.000000e+000,0,,0,
1523923927.515,,0.000000e+000,3.999939e+001,-4.626355e-006,0.000000e+000,3,7.776189e-001,0.000000e+000,,,,,,,,,,,,,,32,1,4.000000e+000,1.029968e-003,0.000000e+000,0,,0,
1523923979.893,,0.000000e+000,4.000145e+001,-4.642977e-006,0.000000e+000,3,7.857981e-001,0.000000e+000,,,,,,,,,,,,,,32,1,4.000000e+000,1.029968e-003,0.000000e+000,0,,0,
1523924029.336,,0.000000e+000,3.999836e+001,-4.600814e-006,0.000000e+000,3,7.945961e-001,0.000000e+000,,,,,,,,,,,,,,32,1,4.000000e+000,1.037598e-003,0.000000e+000,0,,0,
1523924079.792,,0.000000e+000,3.999836e+001,-4.547973e-006,0.000000e+000,3,7.723625e-001,0.000000e+000,,,,,,,,,,,,,,32,1,4.000000e+000,3.097534e-003,0.000000e+000,0,,0,
1523924130.118,,0.000000e+000,3.999991e+001,-4.562521e-006,0.000000e+000,3,7.832090e-001,0.000000e+000,,,,,,,,,,,,,,32,1,4.000000e+000,0.000000e+000,0.000000e+000,0,,0,
1523924182.118,,0.000000e+000,3.999784e+001,-4.529166e-006,0.000000e+000,3,7.715576e-001,0.000000e+000,,,,,,,,,,,,,,32,1,4.000000e+000,2.067566e-003,0.000000e+000,0,,0,
1523924232.982,,0.000000e+000,3.999888e+001,-4.493470e-006,0.000000e+000,3,7.783969e-001,0.000000e+000,,,,,,,,,,,,,,32,1,4.000000e+000,0.000000e+000,0.000000e+000,0,,0,
1523924284.227,,0.000000e+000,4.000042e+001,-4.422187e-006,0.000000e+000,3,7.746427e-001,0.000000e+000,,,,,,,,,,,,,,32,1,4.000000e+000,1.029968e-003,0.000000e+000,0,,0,
1523924336.196,,0.000000e+000,4.000042e+001,-4.368849e-006,0.000000e+000,3,7.597454e-001,0.000000e+000,,,,,,,,,,,,,,32,1,4.000000e+000,5.157471e-003,0.000000e+000,0,,0,
1523924386.134,,0.000000e+000,3.999991e+001,-4.438352e-006,0.000000e+000,3,7.763625e-001,0.000000e+000,,,,,,,,,,,,,,32,1,4.000000e+000,0.000000e+000,0.000000e+000,0,,0,
1523924436.820,,0.000000e+000,3.999939e+001,-4.339321e-006,0.000000e+000,3,7.586701e-001,0.000000e+000,,,,,,,,,,,,,,32,1,4.000000e+000,1.029968e-003,0.000000e+000,0,,0,
1523924489.365,,0.000000e+000,3.999888e+001,-4.318219e-006,0.000000e+000,3,7.643086e-001,0.000000e+000,,,,,,,,,,,,,,32,1,4.000000e+000,0.000000e+000,0.000000e+000,0,,0,
1523924539.786,,0.000000e+000,3.999887e+001,-4.245760e-006,0.000000e+000,3,7.493916e-001,0.000000e+000,,,,,,,,,,,,,,32,1,4.000000e+000,2.067566e-003,0.000000e+000,0,,0,
1523924590.687,,0.000000e+000,3.999629e+001,-4.276042e-006,0.000000e+000,3,7.623444e-001,0.000000e+000,,,,,,,,,,,,,,32,1,4.000000e+000,5.168915e-003,0.000000e+000,0,,0,
1523924640.320,,0.000000e+000,3.999784e+001,-4.226302e-006,0.000000e+000,3,7.679797e-001,0.000000e+000,,,,,,,,,,,,,,32,1,4.000000e+000,4.138947e-003,0.000000e+000,0,,0,
1523924690.701,,0.000000e+000,3.999784e+001,-4.209032e-006,0.000000e+000,3,7.508615e-001,0.000000e+000,,,,,,,,,,,,,,32,1,4.000000e+000,0.000000e+000,0.000000e+000,0,,0,
1523924740.732,,0.000000e+000,3.999836e+001,-4.174658e-006,0.000000e+000,3,7.568621e-001,0.000000e+000,,,,,,,,,,,,,,32,1,4.000000e+000,1.037598e-003,0.000000e+000,0,,0,
1523924791.047,,0.000000e+000,3.999991e+001,-4.177120e-006,0.000000e+000,3,7.551796e-001,0.000000e+000,,,,,,,,,,,,,,32,1,4.000000e+000,2.059937e-003,0.000000e+000,0,,0,
1523924842.171,,0.000000e+000,4.000042e+001,-4.138444e-006,0.000000e+000,3,7.516208e-001,0.000000e+000,,,,,,,,,,,,,,32,1,4.000000e+000,1.029968e-003,0.000000e+000,0,,0,
1523924891.734,,0.000000e+000,3.999990e+001,-4.104393e-006,0.000000e+000,3,7.433338e-001,0.000000e+000,,,,,,,,,,,,,,32,1,4.000000e+000,4.127502e-003,0.000000e+000,0,,0,
1523924942.470,,0.000000e+000,3.999888e+001,-4.059846e-006,0.000000e+000,3,7.454228e-001,0.000000e+000,,,,,,,,,,,,,,32,1,4.000000e+000,0.000000e+000,0.000000e+000,0,,0,
1523924993.995,,0.000000e+000,3.999990e+001,-4.088951e-006,0.000000e+000,3,7.454336e-001,0.000000e+000,,,,,,,,,,,,,,32,1,4.000000e+000,4.127502e-003,0.000000e+000,0,,0,
1523925044.334,,0.000000e+000,3.999991e+001,-4.031772e-006,0.000000e+000,3,7.346812e-001,0.000000e+000,,,,,,,,,,,,,,32,1,4.000000e+000,0.000000e+000,0.000000e+000,0,,0,
1523925096.059,,0.000000e+000,3.999836e+001,-4.017273e-006,0.000000e+000,3,7.316861e-001,0.000000e+000,,,,,,,,,,,,,,32,1,4.000000e+000,1.037598e-003,0.000000e+000,0,,0,
1523925147.213,,0.000000e+000,3.999991e+001,-3.967515e-006,0.000000e+000,3,7.334640e-001,0.000000e+000,,,,,,,,,,,,,,32,1,4.000000e+000,0.000000e+000,0.000000e+000,0,,0,
1523925197.361,,0.000000e+000,4.000042e+001,-4.053091e-006,0.000000e+000,3,7.445801e-001,0.000000e+000,,,,,,,,,,,,,,32,1,4.000000e+000,1.029968e-003,0.000000e+000,0,,0,
1523925247.432,,0.000000e+000,3.999939e+001,-3.943219e-006,0.000000e+000,3,7.273165e-001,0.000000e+000,,,,,,,,,,,,,,32,1,4.000000e+000,1.029968e-003,0.000000e+000,0,,0,
1523925298.870,,0.000000e+000,3.999732e+001,-3.922421e-006,0.000000e+000,3,7.236491e-001,0.000000e+000,,,,,,,,,,,,,,32,1,4.000000e+000,3.108978e-003,0.000000e+000,0,,0,
1523925349.268,,0.000000e+000,3.999939e+001,-3.893927e-006,0.000000e+000,3,7.286152e-001,0.000000e+000,,,,,,,,,,,,,,32,1,4.000000e+000,3.097534e-003,0.000000e+000,0,,0,
1523925400.079,,0.000000e+000,3.999784e+001,-3.966321e-006,0.000000e+000,3,7.289141e-001,0.000000e+000,,,,,,,,,,,,,,32,1,4.000000e+000,4.138947e-003,0.000000e+000,0,,0,
1523925450.080,,0.000000e+000,3.999939e+001,-3.857358e-006,0.000000e+000,3,7.329518e-001,0.000000e+000,,,,,,,,,,,,,,32,1,4.000000e+000,5.157471e-003,0.000000e+000,0,,0,
1523925498.963,,0.000000e+000,4.000094e+001,-3.810118e-006,0.000000e+000,3,7.103710e-001,0.000000e+000,,,,,,,,,,,,,,32,1,4.000000e+000,6.198883e-003,0.000000e+000,0,,0,
1523925551.009,,0.000000e+000,3.999939e+001,-3.807027e-006,0.000000e+000,3,7.155070e-001,0.000000e+000,,,,,,,,,,,,,,32,1,4.000000e+000,1.029968e-003,0.000000e+000,0,,0,
1523925601.202,,0.000000e+000,4.000042e+001,-3.810835e-006,0.000000e+000,3,7.220665e-001,0.000000e+000,,,,,,,,,,,,,,32,1,4.000000e+000,1.029968e-003,0.000000e+000,0,,0,
1523925652.100,,0.000000e+000,3.999836e+001,-3.758212e-006,0.000000e+000,3,7.135051e-001,0.000000e+000,,,,,,,,,,,,,,32,1,4.000000e+000,3.097534e-003,0.000000e+000,0,,0,
1523925702.373,,0.000000e+000,3.999784e+001,-3.774706e-006,0.000000e+000,3,7.121846e-001,0.000000e+000,,,,,,,,,,,,,,32,1,4.000000e+000,2.067566e-003,0.000000e+000,0,,0,
1523925753.021,,0.000000e+000,4.000042e+001,-3.696329e-006,0.000000e+000,3,6.932704e-001,0.000000e+000,,,,,,,,,,,,,,32,1,4.000000e+000,1.029968e-003,0.000000e+000,0,,0,
1523925804.552,,0.000000e+000,3.999836e+001,-3.735612e-006,0.000000e+000,3,7.133272e-001,0.000000e+000,,,,,,,,,,,,,,32,1,4.000000e+000,1.037598e-003,0.000000e+000,0,,0,
1523925855.730,,0.000000e+000,4.000042e+001,-3.697812e-006,0.000000e+000,3,7.170404e-001,0.000000e+000,,,,,,,,,,,,,,32,1,4.000000e+000,1.029968e-003,0.000000e+000,0,,0,
1523925907.071,,0.000000e+000,4.000094e+001,-3.706906e-006,0.000000e+000,3,7.068713e-001,0.000000e+000,,,,,,,,,,,,,,32,1,4.000000e+000,2.059937e-003,0.000000e+000,0,,0,
1523925957.082,,0.000000e+000,3.999836e+001,-3.629985e-006,0.000000e+000,3,7.004034e-001,0.000000e+000,,,,,,,,,,,,,,32,1,4.000000e+000,1.037598e-003,0.000000e+000,0,,0,
1523926009.078,,0.000000e+000,3.999991e+001,-3.647297e-006,0.000000e+000,3,6.900645e-001,0.000000e+000,,,,,,,,,,,,,,32,1,4.000000e+000,2.059937e-003,0.000000e+000,0,,0,
1523926059.061,,0.000000e+000,4.000145e+001,-3.615351e-006,0.000000e+000,3,7.076407e-001,0.000000e+000,,,,,,,,,,,,,,32,1,4.000000e+000,3.089905e-003,0.000000e+000,0,,0,
1523926108.699,,0.000000e+000,3.999784e+001,-3.619152e-006,0.000000e+000,3,6.957350e-001,0.000000e+000,,,,,,,,,,,,,,32,1,4.000000e+000,4.138947e-003,0.000000e+000,0,,0,
1523926157.857,,0.000000e+000,3.999939e+001,-3.556984e-006,0.000000e+000,3,6.969789e-001,0.000000e+000,,,,,,,,,,,,,,32,1,4.000000e+000,1.029968e-003,0.000000e+000,0,,0,
1523926208.486,,0.000000e+000,4.000145e+001,-3.564401e-006,0.000000e+000,3,6.827285e-001,0.000000e+000,,,,,,,,,,,,,,32,1,4.000000e+000,1.029968e-003,0.000000e+000,0,,0,
1523926260.186,,0.000000e+000,3.999836e+001,-3.548173e-006,0.000000e+000,3,6.853073e-001,0.000000e+000,,,,,,,,,,,,,,32,1,4.000000e+000,1.037598e-003,0.000000e+000,0,,0,
1523926310.502,,0.000000e+000,3.999887e+001,-3.517340e-006,0.000000e+000,3,6.738707e-001,0.000000e+000,,,,,,,,,,,,,,32,1,4.000000e+000,2.067566e-003,0.000000e+000,0,,0,
1523926361.005,,0.000000e+000,3.999888e+001,-3.548706e-006,0.000000e+000,3,6.888708e-001,0.000000e+000,,,,,,,,,,,,,,32,1,4.000000e+000,0.000000e+000,0.000000e+000,0,,0,
1523926410.664,,0.000000e+000,3.999680e+001,-3.512998e-006,0.000000e+000,3,6.658471e-001,0.000000e+000,,,,,,,,,,,,,,32,1,4.000000e+000,2.071381e-003,0.000000e+000,0,,0,
1523926461.142,,0.000000e+000,3.999939e+001,-3.493418e-006,0.000000e+000,3,6.703613e-001,0.000000e+000,,,,,,,,,,,,,,32,1,4.000000e+000,1.029968e-003,0.000000e+000,0,,0,
1523926513.063,,0.000000e+000,3.999888e+001,-3.494412e-006,0.000000e+000,3,6.726457e-001,0.000000e+000,,,,,,,,,,,,,,32,1,4.000000e+000,0.000000e+000,0.000000e+000,0,,0,
1523926564.293,,0.000000e+000,3.999888e+001,-3.450351e-006,0.000000e+000,3,6.610333e-001,0.000000e+000,,,,,,,,,,,,,,32,1,4.000000e+000,0.000000e+000,0.000000e+000,0,,0,
1523926615.084,,0.000000e+000,3.999991e+001,-3.458228e-006,0.000000e+000,3,6.600726e-001,0.000000e+000,,,,,,,,,,,,,,32,1,4.000000e+000,2.059937e-003,0.000000e+000,0,,0,
1523926665.195,,0.000000e+000,3.999577e+001,-3.454086e-006,0.000000e+000,3,6.696795e-001,0.000000e+000,,,,,,,,,,,,,,32,1,4.000000e+000,8.270264e-003,0.000000e+000,0,,0,
1523926715.386,,0.000000e+000,3.999991e+001,-3.450222e-006,0.000000e+000,3,6.615890e-001,0.000000e+000,,,,,,,,,,,,,,32,1,4.000000e+000,2.059937e-003,0.000000e+000,0,,0,
1523926766.601,,0.000000e+000,3.999939e+001,-3.415697e-006,0.000000e+000,3,6.644117e-001,0.000000e+000,,,,,,,,,,,,,,32,1,4.000000e+000,3.097534e-003,0.000000e+000,0,,0,
1523926817.972,,0.000000e+000,3.999732e+001,-3.440580e-006,0.000000e+000,3,6.663837e-001,0.000000e+000,,,,,,,,,,,,,,32,1,4.000000e+000,3.108978e-003,0.000000e+000,0,,0,
1523926867.408,,0.000000e+000,3.999888e+001,-3.393689e-006,0.000000e+000,3,6.625035e-001,0.000000e+000,,,,,,,,,,,,,,32,1,4.000000e+000,0.000000e+000,0.000000e+000,0,,0,
1523926917.916,,0.000000e+000,3.999887e+001,-3.383289e-006,0.000000e+000,3,6.516450e-001,0.000000e+000,,,,,,,,,,,,,,32,1,4.000000e+000,4.127502e-003,0.000000e+000,0,,0,
1523926968.954,,0.000000e+000,3.999991e+001,-3.371578e-006,0.000000e+000,3,6.460048e-001,0.000000e+000,,,,,,,,,,,,,,32,1,4.000000e+000,0.000000e+000,0.000000e+000,0,,0,
1523927019.705,,0.000000e+000,3.999991e+001,-3.365756e-006,0.000000e+000,3,6.384407e-001,0.000000e+000,,,,,,,,,,,,,,32,1,4.000000e+000,0.000000e+000,0.000000e+000,0,,0,
1523927071.033,,0.000000e+000,3.999888e+001,-3.369896e-006,0.000000e+000,3,6.623310e-001,0.000000e+000,,,,,,,,,,,,,,32,1,4.000000e+000,0.000000e+000,0.000000e+000,0,,0,
1523927121.999,,0.000000e+000,3.999784e+001,-3.356499e-006,0.000000e+000,3,6.602544e-001,0.000000e+000,,,,,,,,,,,,,,32,1,4.000000e+000,2.067566e-003,0.000000e+000,0,,0,
1523927170.880,,0.000000e+000,3.999888e+001,-3.352071e-006,0.000000e+000,3,6.617387e-001,0.000000e+000,,,,,,,,,,,,,,32,1,4.000000e+000,0.000000e+000,0.000000e+000,0,,0,
1523927220.115,,0.000000e+000,3.999836e+001,-3.333423e-006,0.000000e+000,3,6.504308e-001,0.000000e+000,,,,,,,,,,,,,,32,1,4.000000e+000,1.037598e-003,0.000000e+000,0,,0,
1523927272.319,,0.000000e+000,3.999784e+001,-3.356114e-006,0.000000e+000,3,6.551347e-001,0.000000e+000,,,,,,,,,,,,,,32,1,4.000000e+000,2.067566e-003,0.000000e+000,0,,0,
1523927324.757,,0.000000e+000,3.999939e+001,-3.305487e-006,0.000000e+000,3,6.384630e-001,0.000000e+000,,,,,,,,,,,,,,32,1,4.000000e+000,1.029968e-003,0.000000e+000,0,,0,
1523927376.255,,0.000000e+000,3.999836e+001,-3.295028e-006,0.000000e+000,3,6.476307e-001,0.000000e+000,,,,,,,,,,,,,,32,1,4.000000e+000,1.037598e-003,0.000000e+000,0,,0,
1523927427.121,,0.000000e+000,3.999939e+001,-3.301564e-006,0.000000e+000,3,6.188129e-001,0.000000e+000,,,,,,,,,,,,,,32,1,4.000000e+000,1.029968e-003,0.000000e+000,0,,0,
1523927478.312,,0.000000e+000,3.999887e+001,-3.280309e-006,0.000000e+000,3,6.400231e-001,0.000000e+000,,,,,,,,,,,,,,32,1,4.000000e+000,4.127502e-003,0.000000e+000,0,,0,
1523927531.073,,0.000000e+000,3.999836e+001,-3.304057e-006,0.000000e+000,3,6.339467e-001,0.000000e+000,,,,,,,,,,,,,,32,1,4.000000e+000,3.097534e-003,0.000000e+000,0,,0,
1523927581.073,,0.000000e+000,3.999836e+001,-3.218008e-006,0.000000e+000,3,6.327324e-001,0.000000e+000,,,,,,,,,,,,,,32,1,4.000000e+000,1.037598e-003,0.000000e+000,0,,0,
1523927633.567,,0.000000e+000,3.999629e+001,-3.293427e-006,0.000000e+000,3,6.416603e-001,0.000000e+000,,,,,,,,,,,,,,32,1,4.000000e+000,7.228851e-003,0.000000e+000,0,,0,
1523927684.350,,0.000000e+000,3.999733e+001,-3.277417e-006,0.000000e+000,3,6.381468e-001,0.000000e+000,,,,,,,,,,,,,,32,1,4.000000e+000,1.029968e-003,0.000000e+000,0,,0,
1523927733.011,,0.000000e+000,3.999939e+001,-3.261692e-006,0.000000e+000,3,6.291714e-001,0.000000e+000,,,,,,,,,,,,,,32,1,4.000000e+000,1.029968e-003,0.000000e+000,0,,0,
1523927782.884,,0.000000e+000,4.000145e+001,-3.237388e-006,0.000000e+000,3,6.315179e-001,0.000000e+000,,,,,,,,,,,,,,32,1,4.000000e+000,3.089905e-003,0.000000e+000,0,,0,
1523927832.664,,0.000000e+000,3.999784e+001,-3.183660e-006,0.000000e+000,3,6.155422e-001,0.000000e+000,,,,,,,,,,,,,,32,1,4.000000e+000,2.067566e-003,0.000000e+000,0,,0,
1523927883.998,,0.000000e+000,3.999836e+001,-3.242556e-006,0.000000e+000,3,6.312596e-001,0.000000e+000,,,,,,,,,,,,,,32,1,4.000000e+000,1.037598e-003,0.000000e+000,0,,0,
1523927934.978,,0.000000e+000,3.999836e+001,-3.220890e-006,0.000000e+000,3,6.186492e-001,0.000000e+000,,,,,,,,,,,,,,32,1,4.000000e+000,3.097534e-003,0.000000e+000,0,,0,
1523927984.652,,0.000000e+000,3.999887e+001,-3.238021e-006,0.000000e+000,3,6.204034e-001,0.000000e+000,,,,,,,,,,,,,,32,1,4.000000e+000,2.067566e-003,0.000000e+000,0,,0,
1523928035.680,,0.000000e+000,3.999939e+001,-3.265502e-006,0.000000e+000,3,6.280292e-001,0.000000e+000,,,,,,,,,,,,,,32,1,4.000000e+000,1.029968e-003,0.000000e+000,0,,0,
1523928086.638,,0.000000e+000,3.999888e+001,-3.236930e-006,0.000000e+000,3,6.253384e-001,0.000000e+000,,,,,,,,,,,,,,32,1,4.000000e+000,0.000000e+000,0.000000e+000,0,,0,
1523928136.284,,0.000000e+000,3.999888e+001,-3.187658e-006,0.000000e+000,3,6.168799e-001,0.000000e+000,,,,,,,,,,,,,,32,1,4.000000e+000,0.000000e+000,0.000000e+000,0,,0,
1523928185.780,,0.000000e+000,3.999990e+001,-3.212521e-006,0.000000e+000,3,6.272793e-001,0.000000e+000,,,,,,,,,,,,,,32,1,4.000000e+000,4.127502e-003,0.000000e+000,0,,0,
1523928236.610,,0.000000e+000,3.999784e+001,-3.270815e-006,0.000000e+000,3,6.165741e-001,0.000000e+000,,,,,,,,,,,,,,32,1,4.000000e+000,2.067566e-003,0.000000e+000,0,,0,
1523928286.259,,0.000000e+000,3.999991e+001,-3.202237e-006,0.000000e+000,3,6.213221e-001,0.000000e+000,,,,,,,,,,,,,,32,1,4.000000e+000,2.059937e-003,0.000000e+000,0,,0,
1523928335.664,,0.000000e+000,3.999629e+001,-3.207895e-006,0.000000e+000,3,6.011655e-001,0.000000e+000,,,,,,,,,,,,,,32,1,4.000000e+000,7.228851e-003,0.000000e+000,0,,0,
1523928386.058,,0.000000e+000,4.000042e+001,-3.191017e-006,0.000000e+000,3,5.997300e-001,0.000000e+000,,,,,,,,,,,,,,32,1,4.000000e+000,1.029968e-003,0.000000e+000,0,,0,
1523928435.923,,0.000000e+000,3.999991e+001,-3.246608e-006,0.000000e+000,3,5.838603e-001,0.000000e+000,,,,,,,,,,,,,,32,1,4.000000e+000,2.059937e-003,0.000000e+000,0,,0,
1523928487.552,,0.000000e+000,4.000094e+001,-3.204867e-006,0.000000e+000,3,5.909433e-001,0.000000e+000,,,,,,,,,,,,,,32,1,4.000000e+000,2.059937e-003,0.000000e+000,0,,0,
1523928541.596,,0.000000e+000,3.999835e+001,-9.974672e-007,0.000000e+000,2,0.000000e+000,0.000000e+000,,,,,,,,,,,,,,32,1,4.000000e+000,5.168915e-003,0.000000e+000,0,,0,
1523928600.552,,0.000000e+000,4.000094e+001,-8.573724e-007,0.000000e+000,2,0.000000e+000,0.000000e+000,,,,,,,,,,,,,,32,1,4.000000e+000,2.059937e-003,0.000000e+000,0,,0,
1523928657.430,,0.000000e+000,3.999836e+001,-8.532463e-007,0.000000e+000,2,0.000000e+000,0.000000e+000,,,,,,,,,,,,,,32,1,4.000000e+000,3.097534e-003,0.000000e+000,0,,0,
1523928714.527,,0.000000e+000,4.000145e+001,-7.889763e-007,0.000000e+000,2,0.000000e+000,0.000000e+000,,,,,,,,,,,,,,32,1,4.000000e+000,1.029968e-003,0.000000e+000,0,,0,
1523928771.760,,0.000000e+000,4.000042e+001,-7.963651e-007,0.000000e+000,2,0.000000e+000,0.000000e+000,,,,,,,,,,,,,,32,1,4.000000e+000,5.157471e-003,0.000000e+000,0,,0,
1523928829.048,,0.000000e+000,3.999836e+001,-7.702160e-007,0.000000e+000,2,0.000000e+000,0.000000e+000,,,,,,,,,,,,,,32,1,4.000000e+000,3.097534e-003,0.000000e+000,0,,0,
1523928886.331,,0.000000e+000,3.999939e+001,-7.411904e-007,0.000000e+000,2,0.000000e+000,0.000000e+000,,,,,,,,,,,,,,32,1,4.000000e+000,1.029968e-003,0.000000e+000,0,,0,
1523928942.588,,0.000000e+000,3.999836e+001,-7.328890e-007,0.000000e+000,2,0.000000e+000,0.000000e+000,,,,,,,,,,,,,,32,1,4.000000e+000,3.097534e-003,0.000000e+000,0,,0,
1523929001.458,,0.000000e+000,4.000042e+001,-6.699611e-007,0.000000e+000,2,0.000000e+000,0.000000e+000,,,,,,,,,,,,,,32,1,4.000000e+000,1.029968e-003,0.000000e+000,0,,0,
1523929059.039,,0.000000e+000,4.000042e+001,-6.728782e-007,0.000000e+000,2,0.000000e+000,0.000000e+000,,,,,,,,,,,,,,32,1,4.000000e+000,1.029968e-003,0.000000e+000,0,,0,
1523929116.571,,0.000000e+000,3.999887e+001,-6.804394e-007,0.000000e+000,2,0.000000e+000,0.000000e+000,,,,,,,,,,,,,,32,1,4.000000e+000,4.127502e-003,0.000000e+000,0,,0,
1523929174.898,,0.000000e+000,3.999939e+001,-6.084028e-007,0.000000e+000,2,0.000000e+000,0.000000e+000,,,,,,,,,,,,,,32,1,4.000000e+000,1.029968e-003,0.000000e+000,0,,0,
1523929231.236,,0.000000e+000,3.999835e+001,-6.215873e-007,0.000000e+000,2,0.000000e+000,0.000000e+000,,,,,,,,,,,,,,32,1,4.000000e+000,5.168915e-003,0.000000e+000,0,,0,
1523929288.076,,0.000000e+000,3.999939e+001,-5.732230e-007,0.000000e+000,2,0.000000e+000,0.000000e+000,,,,,,,,,,,,,,32,1,4.000000e+000,1.029968e-003,0.000000e+000,0,,0,
1523929346.223,,0.000000e+000,3.999991e+001,-5.286321e-007,0.000000e+000,2,0.000000e+000,0.000000e+000,,,,,,,,,,,,,,32,1,4.000000e+000,2.059937e-003,0.000000e+000,0,,0,
1523929404.304,,0.000000e+000,3.999887e+001,-5.493221e-007,0.000000e+000,2,0.000000e+000,0.000000e+000,,,,,,,,,,,,,,32,1,4.000000e+000,2.067566e-003,0.000000e+000,0,,0,
1523929461.884,,0.000000e+000,3.999732e+001,-4.802513e-007,0.000000e+000,2,0.000000e+000,0.000000e+000,,,,,,,,,,,,,,32,1,4.000000e+000,3.108978e-003,0.000000e+000,0,,0,
1523929519.104,,0.000000e+000,3.999887e+001,-4.982400e-007,0.000000e+000,2,0.000000e+000,0.000000e+000,,,,,,,,,,,,,,32,1,4.000000e+000,2.067566e-003,0.000000e+000,0,,0,
1523929576.182,,0.000000e+000,4.000042e+001,-4.738411e-007,0.000000e+000,2,0.000000e+000,0.000000e+000,,,,,,,,,,,,,,32,1,4.000000e+000,3.089905e-003,0.000000e+000,0,,0,
1523929634.650,,0.000000e+000,3.999784e+001,-4.401815e-007,0.000000e+000,2,0.000000e+000,0.000000e+000,,,,,,,,,,,,,,32,1,4.000000e+000,0.000000e+000,0.000000e+000,0,,0,
1523929692.000,,0.000000e+000,3.999887e+001,-4.586916e-007,0.000000e+000,2,0.000000e+000,0.000000e+000,,,,,,,,,,,,,,32,1,4.000000e+000,2.067566e-003,0.000000e+000,0,,0,
1523929750.467,,0.000000e+000,3.999836e+001,-4.198097e-007,0.000000e+000,2,0.000000e+000,0.000000e+000,,,,,,,,,,,,,,32,1,4.000000e+000,1.037598e-003,0.000000e+000,0,,0,
1523929806.212,,0.000000e+000,3.999991e+001,3.705972e-006,0.000000e+000,3,7.228727e-001,0.000000e+000,,,,,,,,,,,,,,32,1,4.000000e+000,2.059937e-003,0.000000e+000,0,,0,
1523929861.916,,0.000000e+000,3.999784e+001,-4.148679e-007,0.000000e+000,2,0.000000e+000,0.000000e+000,,,,,,,,,,,,,,32,1,4.000000e+000,4.138947e-003,0.000000e+000,0,,0,
1523929915.348,,0.000000e+000,3.999991e+001,-4.151016e-007,0.000000e+000,2,0.000000e+000,0.000000e+000,,,,,,,,,,,,,,32,1,4.000000e+000,0.000000e+000,0.000000e+000,0,,0,
1523929968.887,,0.000000e+000,3.999991e+001,-4.485020e-007,0.000000e+000,2,0.000000e+000,0.000000e+000,,,,,,,,,,,,,,32,1,4.000000e+000,0.000000e+000,0.000000e+000,0,,0,
1523930021.018,,0.000000e+000,3.999939e+001,3.694774e-006,0.000000e+000,3,7.214795e-001,0.000000e+000,,,,,,,,,,,,,,32,1,4.000000e+000,1.029968e-003,0.000000e+000,0,,0,
1523930072.717,,0.000000e+000,4.000042e+001,3.663286e-006,0.000000e+000,3,7.254345e-001,0.000000e+000,,,,,,,,,,,,,,32,1,4.000000e+000,1.029968e-003,0.000000e+000,0,,0,
1523930124.113,,0.000000e+000,3.999991e+001,3.636851e-006,0.000000e+000,3,7.289996e-001,0.000000e+000,,,,,,,,,,,,,,32,1,4.000000e+000,2.059937e-003,0.000000e+000,0,,0,
1523930177.097,,0.000000e+000,3.999991e+001,3.669085e-006,0.000000e+000,3,7.305033e-001,0.000000e+000,,,,,,,,,,,,,,32,1,4.000000e+000,0.000000e+000,0.000000e+000,0,,0,
1523930226.740,,0.000000e+000,3.999836e+001,3.700313e-006,0.000000e+000,3,7.271332e-001,0.000000e+000,,,,,,,,,,,,,,32,1,4.000000e+000,1.037598e-003,0.000000e+000,0,,0,
1523930278.181,,0.000000e+000,4.000042e+001,3.661981e-006,0.000000e+000,3,7.361673e-001,0.000000e+000,,,,,,,,,,,,,,32,1,4.000000e+000,1.029968e-003,0.000000e+000,0,,0,
1523930328.077,,0.000000e+000,4.000145e+001,3.646923e-006,0.000000e+000,3,7.277429e-001,0.000000e+000,,,,,,,,,,,,,,32,1,4.000000e+000,3.089905e-003,0.000000e+000,0,,0,
1523930377.007,,0.000000e+000,4.000042e+001,3.636629e-006,0.000000e+000,3,7.261910e-001,0.000000e+000,,,,,,,,,,,,,,32,1,4.000000e+000,3.089905e-003,0.000000e+000,0,,0,
1523930427.121,,0.000000e+000,3.999836e+001,3.679485e-006,0.000000e+000,3,7.244055e-001,0.000000e+000,,,,,,,,,,,,,,32,1,4.000000e+000,1.037598e-003,0.000000e+000,0,,0,
1523930478.631,,0.000000e+000,3.999836e+001,3.693892e-006,0.000000e+000,3,7.222121e-001,0.000000e+000,,,,,,,,,,,,,,32,1,4.000000e+000,1.037598e-003,0.000000e+000,0,,0,
1523930529.870,,0.000000e+000,3.999784e+001,3.678026e-006,0.000000e+000,3,7.238699e-001,0.000000e+000,,,,,,,,,,,,,,32,1,4.000000e+000,2.067566e-003,0.000000e+000,0,,0,
1523930580.393,,0.000000e+000,3.999836e+001,3.674459e-006,0.000000e+000,3,7.322096e-001,0.000000e+000,,,,,,,,,,,,,,32,1,4.000000e+000,1.037598e-003,0.000000e+000,0,,0,
1523930630.816,,0.000000e+000,3.999939e+001,3.663645e-006,0.000000e+000,3,7.225035e-001,0.000000e+000,,,,,,,,,,,,,,32,1,4.000000e+000,1.029968e-003,0.000000e+000,0,,0,
1523930681.164,,0.000000e+000,3.999939e+001,3.657055e-006,0.000000e+000,3,7.262689e-001,0.000000e+000,,,,,,,,,,,,,,32,1,4.000000e+000,1.029968e-003,0.000000e+000,0,,0,
1523930733.900,,0.000000e+000,3.999836e+001,3.641871e-006,0.000000e+000,3,7.299334e-001,0.000000e+000,,,,,,,,,,,,,,32,1,4.000000e+000,1.037598e-003,0.000000e+000,0,,0,
1523930784.301,,0.000000e+000,3.999939e+001,3.692106e-006,0.000000e+000,3,7.334144e-001,0.000000e+000,,,,,,,,,,,,,,32,1,4.000000e+000,1.029968e-003,0.000000e+000,0,,0,