File: Experimental Raw Data/MFn1 VRM/Iterative Regression/MFn1_VRMac_35K_1500s_VRMde_35K.dc.dat
[Header]
TITLE,MPMS DC Measurement
BYAPP,MPMS Measurement,2.1,Summary
FILEOPENTIME, 1524061121.707000 4/18/2018, 8:18:41 AM

INFO, APPNAME, MPMS MultiVu Application, Revision 1.61,  Build 082

INFO, NAME, MFn1
INFO, WEIGHT, 1.000
INFO, AREA, 1.000
INFO, LENGTH, 1.000
INFO, SHAPE, 0
INFO, COMMENT,
INFO, SEQUENCE FILE: VRMac_35K_1500s_VRMde_35K.seq


INFO, BACKGROUND DATA FILE:, None


STARTUPAXIS,X,4,LINEAR,AUTO,0.000000,0.000000
STARTUPAXIS,Y1,5,LINEAR,AUTO,0.000000,0.000000


STARTUPGROUP,Longitudinal
FIELDGROUP,Longitudinal,1,2,3,4,5,6,7,8,9,15,16,17,18,27,28
FIELDGROUP,Transverse,1,2,3,4,10,11,12,13,14,19,20,21,22,27,28

PLOT_APPEARANCE,ALL,HORZ_GRID_ON,VERT_GRID_ON,MARKERS_AND_LINES

[Data]
Time,Comment,Field (Oe),Temperature (K),Long Moment (emu),Long Scan Std Dev,Long Algorithm,Long Reg Fit,Long Percent Error (%),Trans Moment (emu),Trans Scan Std Dev,Trans Algorithm,Trans Reg Fit,Trans Percent Error (%),Long Moment [w/o ABS] (emu),Long Scan Std Dev [w/o ABS],Long Reg Fit [w/o ABS],Long Percent Error [w/o ABS] (%),Trans Moment [w/o ABS] (emu),Trans Scan Std Dev [w/o ABS],Trans Reg Fit [w/o ABS],Trans Percent Error [w/o ABS] (%),Points per Scan,Scans per Measurement,Scan Length (cm),Delta Temp (K),Rot Position (deg),Error,EC Comp. Running,Using ABS,
1524061121.684,,0.000000e+000,3.499637e+001,-1.589391e-005,0.000000e+000,3,9.465141e-001,0.000000e+000,,,,,,,,,,,,,,32,1,4.000000e+000,1.560211e-003,0.000000e+000,0,,0,
1524061159.102,,0.000000e+000,3.499833e+001,-1.252406e-005,0.000000e+000,3,9.293137e-001,0.000000e+000,,,,,,,,,,,,,,32,1,4.000000e+000,7.781982e-004,0.000000e+000,0,,0,
1524061197.173,,0.000000e+000,3.499833e+001,-1.065981e-005,0.000000e+000,3,9.135152e-001,0.000000e+000,,,,,,,,,,,,,,32,1,4.000000e+000,7.781982e-004,0.000000e+000,0,,0,
1524061235.171,,0.000000e+000,3.499833e+001,-9.383993e-006,0.000000e+000,3,9.051777e-001,0.000000e+000,,,,,,,,,,,,,,32,1,4.000000e+000,7.781982e-004,0.000000e+000,0,,0,
1524061273.202,,0.000000e+000,3.499872e+001,-8.453692e-006,0.000000e+000,3,8.944159e-001,0.000000e+000,,,,,,,,,,,,,,32,1,4.000000e+000,1.560211e-003,0.000000e+000,0,,0,
1524061311.157,,0.000000e+000,3.499754e+001,-7.683174e-006,0.000000e+000,3,8.853342e-001,0.000000e+000,,,,,,,,,,,,,,32,1,4.000000e+000,7.896423e-004,0.000000e+000,0,,0,
1524061348.998,,0.000000e+000,3.499872e+001,-7.047536e-006,0.000000e+000,3,8.749997e-001,0.000000e+000,,,,,,,,,,,,,,32,1,4.000000e+000,1.560211e-003,0.000000e+000,0,,0,
1524061387.194,,0.000000e+000,3.499754e+001,-6.512697e-006,0.000000e+000,3,8.579805e-001,0.000000e+000,,,,,,,,,,,,,,32,1,4.000000e+000,7.896423e-004,0.000000e+000,0,,0,
1524061425.005,,0.000000e+000,3.499754e+001,-6.053232e-006,0.000000e+000,3,8.540279e-001,0.000000e+000,,,,,,,,,,,,,,32,1,4.000000e+000,7.896423e-004,0.000000e+000,0,,0,
1524061462.871,,0.000000e+000,3.499754e+001,-5.593792e-006,0.000000e+000,3,8.355117e-001,0.000000e+000,,,,,,,,,,,,,,32,1,4.000000e+000,2.349854e-003,0.000000e+000,0,,0,
1524061500.837,,0.000000e+000,3.499833e+001,-5.327831e-006,0.000000e+000,3,8.293343e-001,0.000000e+000,,,,,,,,,,,,,,32,1,4.000000e+000,7.781982e-004,0.000000e+000,0,,0,
1524061538.830,,0.000000e+000,3.499754e+001,-4.964868e-006,0.000000e+000,3,8.198192e-001,0.000000e+000,,,,,,,,,,,,,,32,1,4.000000e+000,2.349854e-003,0.000000e+000,0,,0,
1524061577.593,,0.000000e+000,3.499793e+001,-4.663336e-006,0.000000e+000,3,8.079236e-001,0.000000e+000,,,,,,,,,,,,,,32,1,4.000000e+000,1.567841e-003,0.000000e+000,0,,0,
1524061615.341,,0.000000e+000,3.499872e+001,-4.444466e-006,0.000000e+000,3,8.054070e-001,0.000000e+000,,,,,,,,,,,,,,32,1,4.000000e+000,1.560211e-003,0.000000e+000,0,,0,
1524061653.962,,0.000000e+000,3.499911e+001,-4.181995e-006,0.000000e+000,3,7.871506e-001,0.000000e+000,,,,,,,,,,,,,,32,1,4.000000e+000,2.338409e-003,0.000000e+000,0,,0,
1524061692.795,,0.000000e+000,3.499872e+001,-3.927223e-006,0.000000e+000,3,7.686622e-001,0.000000e+000,,,,,,,,,,,,,,32,1,4.000000e+000,0.000000e+000,0.000000e+000,0,,0,
1524061730.338,,0.000000e+000,3.499833e+001,-3.680325e-006,0.000000e+000,3,7.531154e-001,0.000000e+000,,,,,,,,,,,,,,32,1,4.000000e+000,7.781982e-004,0.000000e+000,0,,0,
1524061768.393,,0.000000e+000,3.499754e+001,-3.516568e-006,0.000000e+000,3,7.454946e-001,0.000000e+000,,,,,,,,,,,,,,32,1,4.000000e+000,2.349854e-003,0.000000e+000,0,,0,
1524061806.461,,0.000000e+000,3.499754e+001,-3.403320e-006,0.000000e+000,3,7.370278e-001,0.000000e+000,,,,,,,,,,,,,,32,1,4.000000e+000,2.349854e-003,0.000000e+000,0,,0,
1524061844.572,,0.000000e+000,3.499950e+001,-3.222186e-006,0.000000e+000,3,7.242232e-001,0.000000e+000,,,,,,,,,,,,,,32,1,4.000000e+000,1.560211e-003,0.000000e+000,0,,0,
1524061881.983,,0.000000e+000,3.499833e+001,-3.008121e-006,0.000000e+000,3,6.998349e-001,0.000000e+000,,,,,,,,,,,,,,32,1,4.000000e+000,7.781982e-004,0.000000e+000,0,,0,
1524061919.583,,0.000000e+000,3.499872e+001,-2.930474e-006,0.000000e+000,3,6.935830e-001,0.000000e+000,,,,,,,,,,,,,,32,1,4.000000e+000,1.560211e-003,0.000000e+000,0,,0,
1524061957.699,,0.000000e+000,3.499950e+001,-2.810656e-006,0.000000e+000,3,6.811399e-001,0.000000e+000,,,,,,,,,,,,,,32,1,4.000000e+000,0.000000e+000,0.000000e+000,0,,0,
1524061996.199,,0.000000e+000,3.499833e+001,-2.691642e-006,0.000000e+000,3,6.629774e-001,0.000000e+000,,,,,,,,,,,,,,32,1,4.000000e+000,7.781982e-004,0.000000e+000,0,,0,
1524062033.815,,0.000000e+000,3.499911e+001,-2.565489e-006,0.000000e+000,3,6.577943e-001,0.000000e+000,,,,,,,,,,,,,,32,1,4.000000e+000,7.820129e-004,0.000000e+000,0,,0,
1524062071.858,,0.000000e+000,3.499794e+001,-2.409761e-006,0.000000e+000,3,6.367169e-001,0.000000e+000,,,,,,,,,,,,,,32,1,4.000000e+000,0.000000e+000,0.000000e+000,0,,0,
1524062110.393,,0.000000e+000,3.499872e+001,-2.323314e-006,0.000000e+000,3,6.209664e-001,0.000000e+000,,,,,,,,,,,,,,32,1,4.000000e+000,0.000000e+000,0.000000e+000,0,,0,
1524062148.449,,0.000000e+000,3.499872e+001,-2.240979e-006,0.000000e+000,3,6.093158e-001,0.000000e+000,,,,,,,,,,,,,,32,1,4.000000e+000,0.000000e+000,0.000000e+000,0,,0,
1524062186.062,,0.000000e+000,3.499950e+001,-2.126334e-006,0.000000e+000,3,5.961465e-001,0.000000e+000,,,,,,,,,,,,,,32,1,4.000000e+000,1.560211e-003,0.000000e+000,0,,0,
1524062224.570,,0.000000e+000,3.499754e+001,-2.057626e-006,0.000000e+000,3,5.604537e-001,0.000000e+000,,,,,,,,,,,,,,32,1,4.000000e+000,7.896423e-004,0.000000e+000,0,,0,
1524062262.196,,0.000000e+000,3.499911e+001,-1.914322e-006,0.000000e+000,3,5.260748e-001,0.000000e+000,,,,,,,,,,,,,,32,1,4.000000e+000,7.820129e-004,0.000000e+000,0,,0,
1524062300.266,,0.000000e+000,3.499872e+001,-1.855945e-006,0.000000e+000,3,5.175952e-001,0.000000e+000,,,,,,,,,,,,,,32,1,4.000000e+000,0.000000e+000,0.000000e+000,0,,0,
1524062338.307,,0.000000e+000,3.499872e+001,-1.767430e-006,0.000000e+000,3,4.814287e-001,0.000000e+000,,,,,,,,,,,,,,32,1,4.000000e+000,0.000000e+000,0.000000e+000,0,,0,
1524062376.332,,0.000000e+000,3.499911e+001,-1.863875e-006,0.000000e+000,3,5.135284e-001,0.000000e+000,,,,,,,,,,,,,,32,1,4.000000e+000,7.820129e-004,0.000000e+000,0,,0,
1524062414.415,,0.000000e+000,3.499950e+001,-1.651460e-006,0.000000e+000,3,4.592529e-001,0.000000e+000,,,,,,,,,,,,,,32,1,4.000000e+000,0.000000e+000,0.000000e+000,0,,0,
1524062452.558,,0.000000e+000,3.499871e+001,-1.512466e-006,0.000000e+000,3,4.223707e-001,0.000000e+000,,,,,,,,,,,,,,32,1,4.000000e+000,3.128052e-003,0.000000e+000,0,,0,
1524062491.004,,0.000000e+000,3.499794e+001,-1.469448e-006,0.000000e+000,3,4.121677e-001,0.000000e+000,,,,,,,,,,,,,,32,1,4.000000e+000,0.000000e+000,0.000000e+000,0,,0,
1524062529.047,,0.000000e+000,3.499989e+001,-1.409331e-006,0.000000e+000,3,3.406936e-001,0.000000e+000,,,,,,,,,,,,,,32,1,4.000000e+000,2.342224e-003,0.000000e+000,0,,0,
1524062567.290,,0.000000e+000,3.499833e+001,-1.342279e-006,0.000000e+000,3,3.159263e-001,0.000000e+000,,,,,,,,,,,,,,32,1,4.000000e+000,7.781982e-004,0.000000e+000,0,,0,
1524062605.118,,0.000000e+000,3.499833e+001,-1.361511e-006,0.000000e+000,3,3.219028e-001,0.000000e+000,,,,,,,,,,,,,,32,1,4.000000e+000,2.349854e-003,0.000000e+000,0,,0,
1524062643.131,,0.000000e+000,3.499911e+001,-1.235693e-006,0.000000e+000,3,2.688869e-001,0.000000e+000,,,,,,,,,,,,,,32,1,4.000000e+000,7.820129e-004,0.000000e+000,0,,0,
1524062681.319,,0.000000e+000,3.499793e+001,-1.196258e-006,0.000000e+000,3,2.471646e-001,0.000000e+000,,,,,,,,,,,,,,32,1,4.000000e+000,3.131866e-003,0.000000e+000,0,,0,
1524062719.287,,0.000000e+000,3.499793e+001,-1.179941e-006,0.000000e+000,3,2.205814e-001,0.000000e+000,,,,,,,,,,,,,,32,1,4.000000e+000,1.567841e-003,0.000000e+000,0,,0,
1524062757.040,,0.000000e+000,3.499872e+001,-1.101275e-006,0.000000e+000,3,2.001559e-001,0.000000e+000,,,,,,,,,,,,,,32,1,4.000000e+000,0.000000e+000,0.000000e+000,0,,0,
1524062795.408,,0.000000e+000,3.499833e+001,-1.041690e-006,0.000000e+000,3,1.453607e-001,0.000000e+000,,,,,,,,,,,,,,32,1,4.000000e+000,7.781982e-004,0.000000e+000,0,,0,
1524062834.072,,0.000000e+000,3.499833e+001,-1.004565e-006,0.000000e+000,3,9.271459e-002,0.000000e+000,,,,,,,,,,,,,,32,1,4.000000e+000,7.781982e-004,0.000000e+000,0,,0,
1524062872.602,,0.000000e+000,3.499911e+001,-9.498309e-007,0.000000e+000,3,8.083199e-002,0.000000e+000,,,,,,,,,,,,,,32,1,4.000000e+000,2.338409e-003,0.000000e+000,0,,0,
1524062909.798,,0.000000e+000,3.499872e+001,-9.281562e-007,0.000000e+000,3,4.501390e-002,0.000000e+000,,,,,,,,,,,,,,32,1,4.000000e+000,0.000000e+000,0.000000e+000,0,,0,
1524062947.473,,0.000000e+000,3.499793e+001,-8.741199e-007,0.000000e+000,3,0.000000e+000,0.000000e+000,,,,,,,,,,,,,,32,1,4.000000e+000,3.131866e-003,0.000000e+000,0,,0,
1524062985.491,,0.000000e+000,3.499989e+001,-8.271825e-007,0.000000e+000,3,0.000000e+000,0.000000e+000,,,,,,,,,,,,,,32,1,4.000000e+000,2.342224e-003,0.000000e+000,0,,0,
1524063023.329,,0.000000e+000,3.499950e+001,-7.947569e-007,0.000000e+000,3,0.000000e+000,0.000000e+000,,,,,,,,,,,,,,32,1,4.000000e+000,0.000000e+000,0.000000e+000,0,,0,
1524063060.862,,0.000000e+000,3.499793e+001,-6.991293e-007,0.000000e+000,3,0.000000e+000,0.000000e+000,,,,,,,,,,,,,,32,1,4.000000e+000,1.567841e-003,0.000000e+000,0,,0,
1524063098.890,,0.000000e+000,3.499754e+001,-6.893174e-007,0.000000e+000,3,0.000000e+000,0.000000e+000,,,,,,,,,,,,,,32,1,4.000000e+000,2.349854e-003,0.000000e+000,0,,0,
1524063137.011,,0.000000e+000,3.499911e+001,-6.763469e-007,0.000000e+000,3,0.000000e+000,0.000000e+000,,,,,,,,,,,,,,32,1,4.000000e+000,7.820129e-004,0.000000e+000,0,,0,
1524063174.489,,0.000000e+000,3.499911e+001,-6.305758e-007,0.000000e+000,3,0.000000e+000,0.000000e+000,,,,,,,,,,,,,,32,1,4.000000e+000,7.820129e-004,0.000000e+000,0,,0,
1524063212.100,,0.000000e+000,3.499793e+001,-5.792980e-007,0.000000e+000,3,0.000000e+000,0.000000e+000,,,,,,,,,,,,,,32,1,4.000000e+000,1.567841e-003,0.000000e+000,0,,0,
1524063250.133,,0.000000e+000,3.499911e+001,-3.853946e-007,0.000000e+000,3,0.000000e+000,0.000000e+000,,,,,,,,,,,,,,32,1,4.000000e+000,7.820129e-004,0.000000e+000,0,,0,
1524063287.903,,0.000000e+000,3.499911e+001,-5.478349e-007,0.000000e+000,3,0.000000e+000,0.000000e+000,,,,,,,,,,,,,,32,1,4.000000e+000,7.820129e-004,0.000000e+000,0,,0,
1524063326.864,,0.000000e+000,3.499833e+001,-1.458931e-007,0.000000e+000,3,0.000000e+000,0.000000e+000,,,,,,,,,,,,,,32,1,4.000000e+000,7.781982e-004,0.000000e+000,0,,0,
1524063363.877,,0.000000e+000,3.499872e+001,3.301741e-007,0.000000e+000,3,0.000000e+000,0.000000e+000,,,,,,,,,,,,,,32,1,4.000000e+000,0.000000e+000,0.000000e+000,0,,0,
1524063401.950,,0.000000e+000,3.499911e+001,5.962862e-007,0.000000e+000,3,0.000000e+000,0.000000e+000,,,,,,,,,,,,,,32,1,4.000000e+000,7.820129e-004,0.000000e+000,0,,0,
1524063439.993,,0.000000e+000,3.499989e+001,2.409548e-007,0.000000e+000,3,0.000000e+000,0.000000e+000,,,,,,,,,,,,,,32,1,4.000000e+000,7.781982e-004,0.000000e+000,0,,0,
1524063478.113,,0.000000e+000,3.499872e+001,6.670524e-007,0.000000e+000,3,0.000000e+000,0.000000e+000,,,,,,,,,,,,,,32,1,4.000000e+000,0.000000e+000,0.000000e+000,0,,0,
1524063516.147,,0.000000e+000,3.499911e+001,7.086994e-007,0.000000e+000,3,0.000000e+000,0.000000e+000,,,,,,,,,,,,,,32,1,4.000000e+000,7.820129e-004,0.000000e+000,0,,0,
1524063554.245,,0.000000e+000,3.499989e+001,7.308720e-007,0.000000e+000,3,0.000000e+000,0.000000e+000,,,,,,,,,,,,,,32,1,4.000000e+000,7.781982e-004,0.000000e+000,0,,0,
1524063592.300,,0.000000e+000,3.499911e+001,6.829206e-007,0.000000e+000,3,0.000000e+000,0.000000e+000,,,,,,,,,,,,,,32,1,4.000000e+000,7.820129e-004,0.000000e+000,0,,0,
1524063631.742,,0.000000e+000,3.499950e+001,-2.954795e-007,0.000000e+000,2,0.000000e+000,0.000000e+000,,,,,,,,,,,,,,32,1,4.000000e+000,0.000000e+000,0.000000e+000,0,,0,
1524063675.421,,0.000000e+000,3.499989e+001,-1.738145e-007,0.000000e+000,2,0.000000e+000,0.000000e+000,,,,,,,,,,,,,,32,1,4.000000e+000,2.342224e-003,0.000000e+000,0,,0,
1524063715.140,,0.000000e+000,3.499872e+001,-2.486356e-007,0.000000e+000,2,0.000000e+000,0.000000e+000,,,,,,,,,,,,,,32,1,4.000000e+000,0.000000e+000,0.000000e+000,0,,0,
1524063757.820,,0.000000e+000,3.500067e+001,-1.946895e-007,0.000000e+000,2,0.000000e+000,0.000000e+000,,,,,,,,,,,,,,32,1,4.000000e+000,2.338409e-003,0.000000e+000,0,,0,
1524063796.188,,0.000000e+000,3.499911e+001,6.255752e-007,0.000000e+000,3,0.000000e+000,0.000000e+000,,,,,,,,,,,,,,32,1,4.000000e+000,7.820129e-004,0.000000e+000,0,,0,
1524063838.585,,0.000000e+000,3.500028e+001,-1.718493e-007,0.000000e+000,2,0.000000e+000,0.000000e+000,,,,,,,,,,,,,,32,1,4.000000e+000,1.560211e-003,0.000000e+000,0,,0,
1524063878.241,,0.000000e+000,3.499872e+001,5.891756e-007,0.000000e+000,3,0.000000e+000,0.000000e+000,,,,,,,,,,,,,,32,1,4.000000e+000,0.000000e+000,0.000000e+000,0,,0,
1524063918.347,,0.000000e+000,3.499638e+001,-1.289121e-007,0.000000e+000,2,0.000000e+000,0.000000e+000,,,,,,,,,,,,,,32,1,4.000000e+000,4.688263e-003,0.000000e+000,0,,0,
1524063958.403,,0.000000e+000,3.500067e+001,3.418983e-008,0.000000e+000,3,0.000000e+000,0.000000e+000,,,,,,,,,,,,,,32,1,4.000000e+000,2.338409e-003,0.000000e+000,0,,0,
1524063997.742,,0.000000e+000,3.499833e+001,-2.237859e-007,0.000000e+000,3,0.000000e+000,0.000000e+000,,,,,,,,,,,,,,32,1,4.000000e+000,7.781982e-004,0.000000e+000,0,,0,
1524064039.003,,0.000000e+000,3.499833e+001,-1.520434e-009,0.000000e+000,3,0.000000e+000,0.000000e+000,,,,,,,,,,,,,,32,1,4.000000e+000,7.781982e-004,0.000000e+000,0,,0,
1524064077.069,,0.000000e+000,3.500106e+001,-3.801469e-009,0.000000e+000,3,0.000000e+000,0.000000e+000,,,,,,,,,,,,,,32,1,4.000000e+000,4.692078e-003,0.000000e+000,0,,0,
1524064115.154,,0.000000e+000,3.499950e+001,-2.090671e-009,0.000000e+000,3,0.000000e+000,0.000000e+000,,,,,,,,,,,,,,32,1,4.000000e+000,3.120422e-003,0.000000e+000,0,,0,
1524064153.625,,0.000000e+000,3.499911e+001,1.224353e-009,0.000000e+000,3,0.000000e+000,0.000000e+000,,,,,,,,,,,,,,32,1,4.000000e+000,7.820129e-004,0.000000e+000,0,,0,
1524064191.878,,0.000000e+000,3.499872e+001,6.621760e-009,0.000000e+000,3,0.000000e+000,0.000000e+000,,,,,,,,,,,,,,32,1,4.000000e+000,0.000000e+000,0.000000e+000,0,,0,
1524064229.936,,0.000000e+000,3.499911e+001,-5.349113e-011,0.000000e+000,3,0.000000e+000,0.000000e+000,,,,,,,,,,,,,,32,1,4.000000e+000,2.338409e-003,0.000000e+000,0,,0,
1524064267.709,,0.000000e+000,3.499911e+001,2.495199e-008,0.000000e+000,3,0.000000e+000,0.000000e+000,,,,,,,,,,,,,,32,1,4.000000e+000,7.820129e-004,0.000000e+000,0,,0,
1524064305.175,,0.000000e+000,3.499872e+001,1.733696e-008,0.000000e+000,3,0.000000e+000,0.000000e+000,,,,,,,,,,,,,,32,1,4.000000e+000,1.560211e-003,0.000000e+000,0,,0,
1524064342.693,,0.000000e+000,3.499754e+001,2.711226e-008,0.000000e+000,3,0.000000e+000,0.000000e+000,,,,,,,,,,,,,,32,1,4.000000e+000,2.349854e-003,0.000000e+000,0,,0,
1524064381.031,,0.000000e+000,3.499989e+001,-1.300701e-009,0.000000e+000,3,0.000000e+000,0.000000e+000,,,,,,,,,,,,,,32,1,4.000000e+000,7.781982e-004,0.000000e+000,0,,0,
1524064418.849,,0.000000e+000,3.499911e+001,1.658230e-008,0.000000e+000,3,0.000000e+000,0.000000e+000,,,,,,,,,,,,,,32,1,4.000000e+000,7.820129e-004,0.000000e+000,0,,0,
1524064456.342,,0.000000e+000,3.499872e+001,4.006036e-008,0.000000e+000,3,0.000000e+000,0.000000e+000,,,,,,,,,,,,,,32,1,4.000000e+000,0.000000e+000,0.000000e+000,0,,0,
1524064494.450,,0.000000e+000,3.499911e+001,6.489199e-008,0.000000e+000,3,0.000000e+000,0.000000e+000,,,,,,,,,,,,,,32,1,4.000000e+000,7.820129e-004,0.000000e+000,0,,0,
1524064532.493,,0.000000e+000,3.499950e+001,1.326352e-007,0.000000e+000,3,0.000000e+000,0.000000e+000,,,,,,,,,,,,,,32,1,4.000000e+000,1.560211e-003,0.000000e+000,0,,0,
1524064572.032,,0.000000e+000,3.500067e+001,6.092211e-008,0.000000e+000,3,0.000000e+000,0.000000e+000,,,,,,,,,,,,,,32,1,4.000000e+000,2.338409e-003,0.000000e+000,0,,0,
1524064611.481,,0.000000e+000,3.499911e+001,6.620650e-007,0.000000e+000,3,0.000000e+000,0.000000e+000,,,,,,,,,,,,,,32,1,4.000000e+000,7.820129e-004,0.000000e+000,0,,0,
1524064651.499,,0.000000e+000,3.499872e+001,5.213708e-008,0.000000e+000,3,0.000000e+000,0.000000e+000,,,,,,,,,,,,,,32,1,4.000000e+000,1.560211e-003,0.000000e+000,0,,0,
1524064692.686,,0.000000e+000,3.499989e+001,2.140820e-007,0.000000e+000,2,0.000000e+000,0.000000e+000,,,,,,,,,,,,,,32,1,4.000000e+000,2.342224e-003,0.000000e+000,0,,0,
1524064733.545,,0.000000e+000,3.499911e+001,2.599402e-007,0.000000e+000,2,0.000000e+000,0.000000e+000,,,,,,,,,,,,,,32,1,4.000000e+000,7.820129e-004,0.000000e+000,0,,0,
1524064776.794,,0.000000e+000,3.499911e+001,2.679214e-007,0.000000e+000,2,0.000000e+000,0.000000e+000,,,,,,,,,,,,,,32,1,4.000000e+000,2.338409e-003,0.000000e+000,0,,0,
1524064818.928,,0.000000e+000,3.499989e+001,2.880652e-007,0.000000e+000,2,0.000000e+000,0.000000e+000,,,,,,,,,,,,,,32,1,4.000000e+000,7.781982e-004,0.000000e+000,0,,0,
1524064861.107,,0.000000e+000,3.499871e+001,2.455620e-007,0.000000e+000,2,0.000000e+000,0.000000e+000,,,,,,,,,,,,,,32,1,4.000000e+000,3.128052e-003,0.000000e+000,0,,0,
1524064902.778,,0.000000e+000,3.499793e+001,2.800684e-007,0.000000e+000,2,0.000000e+000,0.000000e+000,,,,,,,,,,,,,,32,1,4.000000e+000,1.567841e-003,0.000000e+000,0,,0,
1524064942.600,,0.000000e+000,3.499872e+001,-2.195106e-007,0.000000e+000,3,0.000000e+000,0.000000e+000,,,,,,,,,,,,,,32,1,4.000000e+000,0.000000e+000,0.000000e+000,0,,0,
1524064980.668,,0.000000e+000,3.499872e+001,5.712171e-007,0.000000e+000,3,0.000000e+000,0.000000e+000,,,,,,,,,,,,,,32,1,4.000000e+000,0.000000e+000,0.000000e+000,0,,0,
1524065022.117,,0.000000e+000,3.499833e+001,2.715054e-007,0.000000e+000,2,0.000000e+000,0.000000e+000,,,,,,,,,,,,,,32,1,4.000000e+000,7.781982e-004,0.000000e+000,0,,0,
1524065061.363,,0.000000e+000,3.499911e+001,-2.855386e-007,0.000000e+000,3,0.000000e+000,0.000000e+000,,,,,,,,,,,,,,32,1,4.000000e+000,7.820129e-004,0.000000e+000,0,,0,
1524065099.846,,0.000000e+000,3.499872e+001,-2.816967e-007,0.000000e+000,3,0.000000e+000,0.000000e+000,,,,,,,,,,,,,,32,1,4.000000e+000,1.560211e-003,0.000000e+000,0,,0,
1524065139.772,,0.000000e+000,3.499989e+001,3.521021e-007,0.000000e+000,2,0.000000e+000,0.000000e+000,,,,,,,,,,,,,,32,1,4.000000e+000,2.342224e-003,0.000000e+000,0,,0,
1524065179.596,,0.000000e+000,3.499833e+001,3.838759e-007,0.000000e+000,2,0.000000e+000,0.000000e+000,,,,,,,,,,,,,,32,1,4.000000e+000,7.781982e-004,0.000000e+000,0,,0,
1524065222.143,,0.000000e+000,3.499911e+001,3.962157e-007,0.000000e+000,2,0.000000e+000,0.000000e+000,,,,,,,,,,,,,,32,1,4.000000e+000,7.820129e-004,0.000000e+000,0,,0,
1524065264.788,,0.000000e+000,3.499950e+001,4.158632e-007,0.000000e+000,2,0.000000e+000,0.000000e+000,,,,,,,,,,,,,,32,1,4.000000e+000,0.000000e+000,0.000000e+000,0,,0,
1524065306.710,,0.000000e+000,3.499989e+001,4.015195e-007,0.000000e+000,2,0.000000e+000,0.000000e+000,,,,,,,,,,,,,,32,1,4.000000e+000,2.342224e-003,0.000000e+000,0,,0,
1524065348.487,,0.000000e+000,3.499833e+001,4.660488e-007,0.000000e+000,2,0.000000e+000,0.000000e+000,,,,,,,,,,,,,,32,1,4.000000e+000,7.781982e-004,0.000000e+000,0,,0,
1524065389.346,,0.000000e+000,3.499911e+001,4.212113e-007,0.000000e+000,2,0.000000e+000,0.000000e+000,,,,,,,,,,,,,,32,1,4.000000e+000,7.820129e-004,0.000000e+000,0,,0,
1524065430.464,,0.000000e+000,3.499911e+001,4.646733e-007,0.000000e+000,2,0.000000e+000,0.000000e+000,,,,,,,,,,,,,,32,1,4.000000e+000,7.820129e-004,0.000000e+000,0,,0,
1524065470.618,,0.000000e+000,3.499950e+001,4.147820e-007,0.000000e+000,2,0.000000e+000,0.000000e+000,,,,,,,,,,,,,,32,1,4.000000e+000,0.000000e+000,0.000000e+000,0,,0,
1524065510.007,,0.000000e+000,3.499872e+001,8.707059e-007,0.000000e+000,3,0.000000e+000,0.000000e+000,,,,,,,,,,,,,,32,1,4.000000e+000,1.560211e-003,0.000000e+000,0,,0,
1524065549.501,,0.000000e+000,3.499872e+001,-1.218041e-006,0.000000e+000,3,3.010150e-001,0.000000e+000,,,,,,,,,,,,,,32,1,4.000000e+000,0.000000e+000,0.000000e+000,0,,0,
1524065591.082,,0.000000e+000,3.499911e+001,4.336023e-007,0.000000e+000,2,0.000000e+000,0.000000e+000,,,,,,,,,,,,,,32,1,4.000000e+000,7.820129e-004,0.000000e+000,0,,0,
1524065629.989,,0.000000e+000,3.499872e+001,8.749961e-007,0.000000e+000,3,0.000000e+000,0.000000e+000,,,,,,,,,,,,,,32,1,4.000000e+000,0.000000e+000,0.000000e+000,0,,0,
1524065671.143,,0.000000e+000,3.499833e+001,4.463630e-007,0.000000e+000,2,0.000000e+000,0.000000e+000,,,,,,,,,,,,,,32,1,4.000000e+000,7.781982e-004,0.000000e+000,0,,0,
1524065710.416,,0.000000e+000,3.499989e+001,8.778130e-007,0.000000e+000,3,0.000000e+000,0.000000e+000,,,,,,,,,,,,,,32,1,4.000000e+000,7.781982e-004,0.000000e+000,0,,0,
1524065750.504,,0.000000e+000,3.499950e+001,4.719338e-007,0.000000e+000,2,0.000000e+000,0.000000e+000,,,,,,,,,,,,,,32,1,4.000000e+000,1.560211e-003,0.000000e+000,0,,0,
1524065788.212,,0.000000e+000,3.499911e+001,8.176275e-007,0.000000e+000,3,0.000000e+000,0.000000e+000,,,,,,,,,,,,,,32,1,4.000000e+000,7.820129e-004,0.000000e+000,0,,0,
1524065826.720,,0.000000e+000,3.499872e+001,8.768164e-007,0.000000e+000,3,0.000000e+000,0.000000e+000,,,,,,,,,,,,,,32,1,4.000000e+000,0.000000e+000,0.000000e+000,0,,0,
1524065864.813,,0.000000e+000,3.499833e+001,8.816780e-007,0.000000e+000,3,0.000000e+000,0.000000e+000,,,,,,,,,,,,,,32,1,4.000000e+000,7.781982e-004,0.000000e+000,0,,0,
1524065904.207,,0.000000e+000,3.499950e+001,4.733240e-007,0.000000e+000,2,0.000000e+000,0.000000e+000,,,,,,,,,,,,,,32,1,4.000000e+000,0.000000e+000,0.000000e+000,0,,0,
1524065941.900,,0.000000e+000,3.499911e+001,8.644508e-007,0.000000e+000,3,0.000000e+000,0.000000e+000,,,,,,,,,,,,,,32,1,4.000000e+000,7.820129e-004,0.000000e+000,0,,0,
1524065982.081,,0.000000e+000,3.499989e+001,4.469389e-007,0.000000e+000,2,0.000000e+000,0.000000e+000,,,,,,,,,,,,,,32,1,4.000000e+000,7.781982e-004,0.000000e+000,0,,0,
1524066019.476,,0.000000e+000,3.499872e+001,9.449268e-007,0.000000e+000,3,0.000000e+000,0.000000e+000,,,,,,,,,,,,,,32,1,4.000000e+000,1.560211e-003,0.000000e+000,0,,0,
1524066057.582,,0.000000e+000,3.499872e+001,9.877846e-007,0.000000e+000,3,2.520704e-002,0.000000e+000,,,,,,,,,,,,,,32,1,4.000000e+000,0.000000e+000,0.000000e+000,0,,0,
1524066095.472,,0.000000e+000,3.499989e+001,9.740525e-007,0.000000e+000,3,1.543667e-002,0.000000e+000,,,,,,,,,,,,,,32,1,4.000000e+000,7.781982e-004,0.000000e+000,0,,0,
1524066133.195,,0.000000e+000,3.499754e+001,1.011124e-006,0.000000e+000,3,8.924223e-002,0.000000e+000,,,,,,,,,,,,,,32,1,4.000000e+000,3.910065e-003,0.000000e+000,0,,0,
1524066171.081,,0.000000e+000,3.499872e+001,1.022549e-006,0.000000e+000,3,4.662306e-002,0.000000e+000,,,,,,,,,,,,,,32,1,4.000000e+000,0.000000e+000,0.000000e+000,0,,0,
1524066208.602,,0.000000e+000,3.499833e+001,1.046767e-006,0.000000e+000,3,1.103647e-001,0.000000e+000,,,,,,,,,,,,,,32,1,4.000000e+000,7.781982e-004,0.000000e+000,0,,0,
1524066246.662,,0.000000e+000,3.499911e+001,1.020416e-006,0.000000e+000,3,9.793929e-002,0.000000e+000,,,,,,,,,,,,,,32,1,4.000000e+000,7.820129e-004,0.000000e+000,0,,0,
1524066284.285,,0.000000e+000,3.499872e+001,1.002219e-006,0.000000e+000,3,8.445606e-002,0.000000e+000,,,,,,,,,,,,,,32,1,4.000000e+000,0.000000e+000,0.000000e+000,0,,0,
1524066323.687,,0.000000e+000,3.499989e+001,1.054933e-006,0.000000e+000,3,1.178251e-001,0.000000e+000,,,,,,,,,,,,,,32,1,4.000000e+000,7.781982e-004,0.000000e+000,0,,0,
1524066361.872,,0.000000e+000,3.499989e+001,9.990110e-007,0.000000e+000,3,6.890264e-002,0.000000e+000,,,,,,,,,,,,,,32,1,4.000000e+000,7.781982e-004,0.000000e+000,0,,0,
1524066399.098,,0.000000e+000,3.499950e+001,1.008242e-006,0.000000e+000,3,5.363762e-002,0.000000e+000,,,,,,,,,,,,,,32,1,4.000000e+000,0.000000e+000,0.000000e+000,0,,0,
1524066437.061,,0.000000e+000,3.499911e+001,1.023475e-006,0.000000e+000,3,5.369317e-002,0.000000e+000,,,,,,,,,,,,,,32,1,4.000000e+000,7.820129e-004,0.000000e+000,0,,0,
1524066474.721,,0.000000e+000,3.499911e+001,1.067945e-006,0.000000e+000,3,1.059439e-001,0.000000e+000,,,,,,,,,,,,,,32,1,4.000000e+000,7.820129e-004,0.000000e+000,0,,0,
1524066513.097,,0.000000e+000,3.499911e+001,1.049394e-006,0.000000e+000,3,1.119538e-001,0.000000e+000,,,,,,,,,,,,,,32,1,4.000000e+000,7.820129e-004,0.000000e+000,0,,0,
1524066550.708,,0.000000e+000,3.499911e+001,1.043816e-006,0.000000e+000,3,1.242300e-001,0.000000e+000,,,,,,,,,,,,,,32,1,4.000000e+000,2.338409e-003,0.000000e+000,0,,0,
1524066589.283,,0.000000e+000,3.499833e+001,1.101467e-006,0.000000e+000,3,1.563458e-001,0.000000e+000,,,,,,,,,,,,,,32,1,4.000000e+000,7.781982e-004,0.000000e+000,0,,0,
1524066628.214,,0.000000e+000,3.499911e+001,1.105753e-006,0.000000e+000,3,1.531100e-001,0.000000e+000,,,,,,,,,,,,,,32,1,4.000000e+000,7.820129e-004,0.000000e+000,0,,0,
1524066666.189,,0.000000e+000,3.499911e+001,1.077645e-006,0.000000e+000,3,1.508389e-001,0.000000e+000,,,,,,,,,,,,,,32,1,4.000000e+000,7.820129e-004,0.000000e+000,0,,0,
1524066704.290,,0.000000e+000,3.499754e+001,1.083223e-006,0.000000e+000,3,1.227257e-001,0.000000e+000,,,,,,,,,,,,,,32,1,4.000000e+000,2.349854e-003,0.000000e+000,0,,0,
1524066742.078,,0.000000e+000,3.499754e+001,1.155427e-006,0.000000e+000,3,1.849717e-001,0.000000e+000,,,,,,,,,,,,,,32,1,4.000000e+000,3.910065e-003,0.000000e+000,0,,0,
1524066780.036,,0.000000e+000,3.500028e+001,1.118963e-006,0.000000e+000,3,1.480666e-001,0.000000e+000,,,,,,,,,,,,,,32,1,4.000000e+000,0.000000e+000,0.000000e+000,0,,0,
1524066818.137,,0.000000e+000,3.499989e+001,1.153760e-006,0.000000e+000,3,1.889587e-001,0.000000e+000,,,,,,,,,,,,,,32,1,4.000000e+000,7.781982e-004,0.000000e+000,0,,0,
1524066856.235,,0.000000e+000,3.499911e+001,1.141203e-006,0.000000e+000,3,1.833118e-001,0.000000e+000,,,,,,,,,,,,,,32,1,4.000000e+000,7.820129e-004,0.000000e+000,0,,0,
1524066895.053,,0.000000e+000,3.499833e+001,1.126535e-006,0.000000e+000,3,1.642053e-001,0.000000e+000,,,,,,,,,,,,,,32,1,4.000000e+000,7.781982e-004,0.000000e+000,0,,0,
1524066933.191,,0.000000e+000,3.499833e+001,1.114484e-006,0.000000e+000,3,1.822762e-001,0.000000e+000,,,,,,,,,,,,,,32,1,4.000000e+000,7.781982e-004,0.000000e+000,0,,0,
1524066971.701,,0.000000e+000,3.499911e+001,1.137727e-006,0.000000e+000,3,2.046090e-001,0.000000e+000,,,,,,,,,,,,,,32,1,4.000000e+000,2.338409e-003,0.000000e+000,0,,0,
1524067009.644,,0.000000e+000,3.499911e+001,1.184778e-006,0.000000e+000,3,1.947910e-001,0.000000e+000,,,,,,,,,,,,,,32,1,4.000000e+000,7.820129e-004,0.000000e+000,0,,0,
1524067048.235,,0.000000e+000,3.499911e+001,1.163141e-006,0.000000e+000,3,2.047344e-001,0.000000e+000,,,,,,,,,,,,,,32,1,4.000000e+000,7.820129e-004,0.000000e+000,0,,0,
1524067086.910,,0.000000e+000,3.499911e+001,1.181635e-006,0.000000e+000,3,2.186153e-001,0.000000e+000,,,,,,,,,,,,,,32,1,4.000000e+000,7.820129e-004,0.000000e+000,0,,0,
1524067125.136,,0.000000e+000,3.500028e+001,1.143467e-006,0.000000e+000,3,2.166297e-001,0.000000e+000,,,,,,,,,,,,,,32,1,4.000000e+000,0.000000e+000,0.000000e+000,0,,0,
1524067163.589,,0.000000e+000,3.499793e+001,1.196354e-006,0.000000e+000,3,2.072239e-001,0.000000e+000,,,,,,,,,,,,,,32,1,4.000000e+000,4.688263e-003,0.000000e+000,0,,0,
1524067201.402,,0.000000e+000,3.499911e+001,1.217905e-006,0.000000e+000,3,2.270555e-001,0.000000e+000,,,,,,,,,,,,,,32,1,4.000000e+000,7.820129e-004,0.000000e+000,0,,0,
1524067239.375,,0.000000e+000,3.499872e+001,1.179803e-006,0.000000e+000,3,2.351124e-001,0.000000e+000,,,,,,,,,,,,,,32,1,4.000000e+000,0.000000e+000,0.000000e+000,0,,0,
1524067276.908,,0.000000e+000,3.499872e+001,1.245262e-006,0.000000e+000,3,3.093296e-001,0.000000e+000,,,,,,,,,,,,,,32,1,4.000000e+000,0.000000e+000,0.000000e+000,0,,0,
1524067315.359,,0.000000e+000,3.499911e+001,1.204516e-006,0.000000e+000,3,2.032235e-001,0.000000e+000,,,,,,,,,,,,,,32,1,4.000000e+000,7.820129e-004,0.000000e+000,0,,0,
1524067353.612,,0.000000e+000,3.499950e+001,1.074954e-006,0.000000e+000,3,1.358160e-001,0.000000e+000,,,,,,,,,,,,,,32,1,4.000000e+000,0.000000e+000,0.000000e+000,0,,0,
1524067391.710,,0.000000e+000,3.499911e+001,1.161273e-006,0.000000e+000,3,1.895809e-001,0.000000e+000,,,,,,,,,,,,,,32,1,4.000000e+000,7.820129e-004,0.000000e+000,0,,0,
1524067429.811,,0.000000e+000,3.499950e+001,1.194738e-006,0.000000e+000,3,2.262651e-001,0.000000e+000,,,,,,,,,,,,,,32,1,4.000000e+000,0.000000e+000,0.000000e+000,0,,0,
1524067467.684,,0.000000e+000,3.499911e+001,1.142638e-006,0.000000e+000,3,1.900555e-001,0.000000e+000,,,,,,,,,,,,,,32,1,4.000000e+000,7.820129e-004,0.000000e+000,0,,0,
1524067505.189,,0.000000e+000,3.499833e+001,1.134510e-006,0.000000e+000,3,1.369226e-001,0.000000e+000,,,,,,,,,,,,,,32,1,4.000000e+000,7.781982e-004,0.000000e+000,0,,0,
1524067543.797,,0.000000e+000,3.499872e+001,1.159148e-006,0.000000e+000,3,2.034715e-001,0.000000e+000,,,,,,,,,,,,,,32,1,4.000000e+000,0.000000e+000,0.000000e+000,0,,0,
1524067581.883,,0.000000e+000,3.499911e+001,1.099905e-006,0.000000e+000,3,1.415832e-001,0.000000e+000,,,,,,,,,,,,,,32,1,4.000000e+000,7.820129e-004,0.000000e+000,0,,0,
1524067619.651,,0.000000e+000,3.499911e+001,1.215839e-006,0.000000e+000,3,2.405661e-001,0.000000e+000,,,,,,,,,,,,,,32,1,4.000000e+000,3.910065e-003,0.000000e+000,0,,0,
1524067657.521,,0.000000e+000,3.499950e+001,1.254361e-006,0.000000e+000,3,3.092284e-001,0.000000e+000,,,,,,,,,,,,,,32,1,4.000000e+000,1.560211e-003,0.000000e+000,0,,0,
1524067695.059,,0.000000e+000,3.499950e+001,1.197082e-006,0.000000e+000,3,2.447523e-001,0.000000e+000,,,,,,,,,,,,,,32,1,4.000000e+000,1.560211e-003,0.000000e+000,0,,0,
1524067732.612,,0.000000e+000,3.499911e+001,1.190275e-006,0.000000e+000,3,2.760232e-001,0.000000e+000,,,,,,,,,,,,,,32,1,4.000000e+000,7.820129e-004,0.000000e+000,0,,0,
1524067770.685,,0.000000e+000,3.499833e+001,1.217281e-006,0.000000e+000,3,2.519203e-001,0.000000e+000,,,,,,,,,,,,,,32,1,4.000000e+000,7.781982e-004,0.000000e+000,0,,0,
1524067808.896,,0.000000e+000,3.499833e+001,1.214413e-006,0.000000e+000,3,1.794058e-001,0.000000e+000,,,,,,,,,,,,,,32,1,4.000000e+000,7.781982e-004,0.000000e+000,0,,0,
1524067846.699,,0.000000e+000,3.499950e+001,1.188640e-006,0.000000e+000,3,2.201579e-001,0.000000e+000,,,,,,,,,,,,,,32,1,4.000000e+000,0.000000e+000,0.000000e+000,0,,0,
1524067885.177,,0.000000e+000,3.499676e+001,1.165498e-006,0.000000e+000,3,1.759171e-001,0.000000e+000,,,,,,,,,,,,,,32,1,4.000000e+000,7.820129e-004,0.000000e+000,0,,0,
1524067922.833,,0.000000e+000,3.500028e+001,1.235421e-006,0.000000e+000,3,2.367692e-001,0.000000e+000,,,,,,,,,,,,,,32,1,4.000000e+000,0.000000e+000,0.000000e+000,0,,0,
1524067960.818,,0.000000e+000,3.499833e+001,1.160396e-006,0.000000e+000,3,2.207344e-001,0.000000e+000,,,,,,,,,,,,,,32,1,4.000000e+000,2.349854e-003,0.000000e+000,0,,0,
1524067998.481,,0.000000e+000,3.499872e+001,1.213868e-006,0.000000e+000,3,2.085377e-001,0.000000e+000,,,,,,,,,,,,,,32,1,4.000000e+000,1.560211e-003,0.000000e+000,0,,0,
1524068036.049,,0.000000e+000,3.499833e+001,1.253625e-006,0.000000e+000,3,2.447616e-001,0.000000e+000,,,,,,,,,,,,,,32,1,4.000000e+000,2.349854e-003,0.000000e+000,0,,0,
1524068074.125,,0.000000e+000,3.499989e+001,1.272696e-006,0.000000e+000,3,2.699513e-001,0.000000e+000,,,,,,,,,,,,,,32,1,4.000000e+000,7.781982e-004,0.000000e+000,0,,0,
1524068112.201,,0.000000e+000,3.499911e+001,1.272081e-006,0.000000e+000,3,2.923908e-001,0.000000e+000,,,,,,,,,,,,,,32,1,4.000000e+000,7.820129e-004,0.000000e+000,0,,0,
1524068150.229,,0.000000e+000,3.500106e+001,1.279538e-006,0.000000e+000,3,2.671282e-001,0.000000e+000,,,,,,,,,,,,,,32,1,4.000000e+000,4.692078e-003,0.000000e+000,0,,0,
1524068188.452,,0.000000e+000,3.499911e+001,1.308692e-006,0.000000e+000,3,2.906983e-001,0.000000e+000,,,,,,,,,,,,,,32,1,4.000000e+000,7.820129e-004,0.000000e+000,0,,0,
1524068227.085,,0.000000e+000,3.499872e+001,1.236278e-006,0.000000e+000,3,2.549423e-001,0.000000e+000,,,,,,,,,,,,,,32,1,4.000000e+000,0.000000e+000,0.000000e+000,0,,0,
1524068264.575,,0.000000e+000,3.499872e+001,1.230071e-006,0.000000e+000,3,2.612001e-001,0.000000e+000,,,,,,,,,,,,,,32,1,4.000000e+000,0.000000e+000,0.000000e+000,0,,0,
1524068302.358,,0.000000e+000,3.499911e+001,1.210724e-006,0.000000e+000,3,2.309849e-001,0.000000e+000,,,,,,,,,,,,,,32,1,4.000000e+000,7.820129e-004,0.000000e+000,0,,0,
1524068341.314,,0.000000e+000,3.499911e+001,1.272776e-006,0.000000e+000,3,3.143043e-001,0.000000e+000,,,,,,,,,,,,,,32,1,4.000000e+000,7.820129e-004,0.000000e+000,0,,0,
1524068379.582,,0.000000e+000,3.499911e+001,1.285135e-006,0.000000e+000,3,2.902159e-001,0.000000e+000,,,,,,,,,,,,,,32,1,4.000000e+000,7.820129e-004,0.000000e+000,0,,0,
1524068417.680,,0.000000e+000,3.499950e+001,1.262335e-006,0.000000e+000,3,2.678363e-001,0.000000e+000,,,,,,,,,,,,,,32,1,4.000000e+000,0.000000e+000,0.000000e+000,0,,0,
1524068455.678,,0.000000e+000,3.499911e+001,1.260516e-006,0.000000e+000,3,2.507009e-001,0.000000e+000,,,,,,,,,,,,,,32,1,4.000000e+000,7.820129e-004,0.000000e+000,0,,0,
1524068493.859,,0.000000e+000,3.499950e+001,1.310143e-006,0.000000e+000,3,3.013915e-001,0.000000e+000,,,,,,,,,,,,,,32,1,4.000000e+000,0.000000e+000,0.000000e+000,0,,0,
1524068531.907,,0.000000e+000,3.499872e+001,1.282470e-006,0.000000e+000,3,2.745627e-001,0.000000e+000,,,,,,,,,,,,,,32,1,4.000000e+000,1.560211e-003,0.000000e+000,0,,0,
1524068569.980,,0.000000e+000,3.499911e+001,1.270723e-006,0.000000e+000,3,2.989643e-001,0.000000e+000,,,,,,,,,,,,,,32,1,4.000000e+000,7.820129e-004,0.000000e+000,0,,0,
1524068608.003,,0.000000e+000,3.499950e+001,1.276277e-006,0.000000e+000,3,2.705551e-001,0.000000e+000,,,,,,,,,,,,,,32,1,4.000000e+000,0.000000e+000,0.000000e+000,0,,0,
1524068646.148,,0.000000e+000,3.499872e+001,1.276405e-006,0.000000e+000,3,2.871886e-001,0.000000e+000,,,,,,,,,,,,,,32,1,4.000000e+000,1.560211e-003,0.000000e+000,0,,0,
1524068683.716,,0.000000e+000,3.499911e+001,1.277793e-006,0.000000e+000,3,2.881148e-001,0.000000e+000,,,,,,,,,,,,,,32,1,4.000000e+000,7.820129e-004,0.000000e+000,0,,0,
1524068722.252,,0.000000e+000,3.499989e+001,1.326172e-006,0.000000e+000,3,2.992803e-001,0.000000e+000,,,,,,,,,,,,,,32,1,4.000000e+000,7.781982e-004,0.000000e+000,0,,0,
1524068759.863,,0.000000e+000,3.499911e+001,1.317456e-006,0.000000e+000,3,3.033547e-001,0.000000e+000,,,,,,,,,,,,,,32,1,4.000000e+000,7.820129e-004,0.000000e+000,0,,0,
1524068798.021,,0.000000e+000,3.499950e+001,1.293820e-006,0.000000e+000,3,2.970576e-001,0.000000e+000,,,,,,,,,,,,,,32,1,4.000000e+000,0.000000e+000,0.000000e+000,0,,0,
1524068836.006,,0.000000e+000,3.499911e+001,1.300242e-006,0.000000e+000,3,3.002492e-001,0.000000e+000,,,,,,,,,,,,,,32,1,4.000000e+000,7.820129e-004,0.000000e+000,0,,0,
1524068874.512,,0.000000e+000,3.499950e+001,1.251523e-006,0.000000e+000,3,2.719794e-001,0.000000e+000,,,,,,,,,,,,,,32,1,4.000000e+000,0.000000e+000,0.000000e+000,0,,0,
1524068912.157,,0.000000e+000,3.499872e+001,1.297839e-006,0.000000e+000,3,2.896227e-001,0.000000e+000,,,,,,,,,,,,,,32,1,4.000000e+000,0.000000e+000,0.000000e+000,0,,0,
1524068950.723,,0.000000e+000,3.499950e+001,1.277461e-006,0.000000e+000,3,2.729941e-001,0.000000e+000,,,,,,,,,,,,,,32,1,4.000000e+000,0.000000e+000,0.000000e+000,0,,0,
1524068988.766,,0.000000e+000,3.499872e+001,1.336221e-006,0.000000e+000,3,3.154608e-001,0.000000e+000,,,,,,,,,,,,,,32,1,4.000000e+000,0.000000e+000,0.000000e+000,0,,0,
1524069026.409,,0.000000e+000,3.499950e+001,1.332411e-006,0.000000e+000,3,3.107988e-001,0.000000e+000,,,,,,,,,,,,,,32,1,4.000000e+000,0.000000e+000,0.000000e+000,0,,0,
1524069064.914,,0.000000e+000,3.499911e+001,1.292943e-006,0.000000e+000,3,2.920545e-001,0.000000e+000,,,,,,,,,,,,,,32,1,4.000000e+000,7.820129e-004,0.000000e+000,0,,0,
1524069102.560,,0.000000e+000,3.499950e+001,1.323872e-006,0.000000e+000,3,3.140613e-001,0.000000e+000,,,,,,,,,,,,,,32,1,4.000000e+000,0.000000e+000,0.000000e+000,0,,0,
1524069141.091,,0.000000e+000,3.499950e+001,1.307467e-006,0.000000e+000,3,3.109496e-001,0.000000e+000,,,,,,,,,,,,,,32,1,4.000000e+000,0.000000e+000,0.000000e+000,0,,0,
1524069178.719,,0.000000e+000,3.499911e+001,1.328890e-006,0.000000e+000,3,3.285895e-001,0.000000e+000,,,,,,,,,,,,,,32,1,4.000000e+000,7.820129e-004,0.000000e+000,0,,0,
1524069216.797,,0.000000e+000,3.499989e+001,1.303444e-006,0.000000e+000,3,2.793363e-001,0.000000e+000,,,,,,,,,,,,,,32,1,4.000000e+000,7.781982e-004,0.000000e+000,0,,0,
1524069255.302,,0.000000e+000,3.499950e+001,1.310455e-006,0.000000e+000,3,3.168437e-001,0.000000e+000,,,,,,,,,,,,,,32,1,4.000000e+000,0.000000e+000,0.000000e+000,0,,0,
1524069293.373,,0.000000e+000,3.500028e+001,1.357889e-006,0.000000e+000,3,3.236603e-001,0.000000e+000,,,,,,,,,,,,,,32,1,4.000000e+000,1.560211e-003,0.000000e+000,0,,0,
1524069331.506,,0.000000e+000,3.499989e+001,1.400349e-006,0.000000e+000,3,3.297039e-001,0.000000e+000,,,,,,,,,,,,,,32,1,4.000000e+000,7.781982e-004,0.000000e+000,0,,0,
1524069369.576,,0.000000e+000,3.499950e+001,1.327594e-006,0.000000e+000,3,3.296245e-001,0.000000e+000,,,,,,,,,,,,,,32,1,4.000000e+000,0.000000e+000,0.000000e+000,0,,0,
1524069407.677,,0.000000e+000,3.499833e+001,1.335521e-006,0.000000e+000,3,3.208516e-001,0.000000e+000,,,,,,,,,,,,,,32,1,4.000000e+000,7.781982e-004,0.000000e+000,0,,0,
1524069445.180,,0.000000e+000,3.499872e+001,1.280571e-006,0.000000e+000,3,3.115361e-001,0.000000e+000,,,,,,,,,,,,,,32,1,4.000000e+000,1.560211e-003,0.000000e+000,0,,0,
1524069483.328,,0.000000e+000,3.499950e+001,1.345853e-006,0.000000e+000,3,3.189929e-001,0.000000e+000,,,,,,,,,,,,,,32,1,4.000000e+000,0.000000e+000,0.000000e+000,0,,0,
1524069521.414,,0.000000e+000,3.499911e+001,1.358337e-006,0.000000e+000,3,3.340424e-001,0.000000e+000,,,,,,,,,,,,,,32,1,4.000000e+000,7.820129e-004,0.000000e+000,0,,0,
1524069558.999,,0.000000e+000,3.499754e+001,1.339810e-006,0.000000e+000,3,3.296690e-001,0.000000e+000,,,,,,,,,,,,,,32,1,4.000000e+000,2.349854e-003,0.000000e+000,0,,0,
1524069596.990,,0.000000e+000,3.499911e+001,1.350867e-006,0.000000e+000,3,3.308122e-001,0.000000e+000,,,,,,,,,,,,,,32,1,4.000000e+000,7.820129e-004,0.000000e+000,0,,0,
1524069635.140,,0.000000e+000,3.499872e+001,1.370211e-006,0.000000e+000,3,3.377069e-001,0.000000e+000,,,,,,,,,,,,,,32,1,4.000000e+000,0.000000e+000,0.000000e+000,0,,0,
1524069673.223,,0.000000e+000,3.499950e+001,1.313165e-006,0.000000e+000,3,3.031225e-001,0.000000e+000,,,,,,,,,,,,,,32,1,4.000000e+000,0.000000e+000,0.000000e+000,0,,0,
1524069711.504,,0.000000e+000,3.499833e+001,1.371797e-006,0.000000e+000,3,3.367870e-001,0.000000e+000,,,,,,,,,,,,,,32,1,4.000000e+000,7.781982e-004,0.000000e+000,0,,0,
1524069749.297,,0.000000e+000,3.499950e+001,1.363007e-006,0.000000e+000,3,3.416112e-001,0.000000e+000,,,,,,,,,,,,,,32,1,4.000000e+000,0.000000e+000,0.000000e+000,0,,0,
1524069787.403,,0.000000e+000,3.499872e+001,1.374135e-006,0.000000e+000,3,3.712254e-001,0.000000e+000,,,,,,,,,,,,,,32,1,4.000000e+000,0.000000e+000,0.000000e+000,0,,0,
1524069825.703,,0.000000e+000,3.499872e+001,1.383090e-006,0.000000e+000,3,3.154905e-001,0.000000e+000,,,,,,,,,,,,,,32,1,4.000000e+000,0.000000e+000,0.000000e+000,0,,0,
1524069863.771,,0.000000e+000,3.500145e+001,1.396609e-006,0.000000e+000,3,3.379065e-001,0.000000e+000,,,,,,,,,,,,,,32,1,4.000000e+000,5.470276e-003,0.000000e+000,0,,0,
1524069901.754,,0.000000e+000,3.499989e+001,1.420398e-006,0.000000e+000,3,3.386776e-001,0.000000e+000,,,,,,,,,,,,,,32,1,4.000000e+000,7.781982e-004,0.000000e+000,0,,0,
1524069940.220,,0.000000e+000,3.499989e+001,1.391143e-006,0.000000e+000,3,3.517120e-001,0.000000e+000,,,,,,,,,,,,,,32,1,4.000000e+000,2.342224e-003,0.000000e+000,0,,0,
1524069977.515,,0.000000e+000,3.499950e+001,1.377142e-006,0.000000e+000,3,3.162016e-001,0.000000e+000,,,,,,,,,,,,,,32,1,4.000000e+000,3.120422e-003,0.000000e+000,0,,0,
1524070014.661,,0.000000e+000,3.500067e+001,1.374406e-006,0.000000e+000,3,3.354094e-001,0.000000e+000,,,,,,,,,,,,,,32,1,4.000000e+000,7.820129e-004,0.000000e+000,0,,0,
1524070052.174,,0.000000e+000,3.499911e+001,1.386810e-006,0.000000e+000,3,3.363442e-001,0.000000e+000,,,,,,,,,,,,,,32,1,4.000000e+000,7.820129e-004,0.000000e+000,0,,0,
1524070090.297,,0.000000e+000,3.499950e+001,1.409416e-006,0.000000e+000,3,3.654061e-001,0.000000e+000,,,,,,,,,,,,,,32,1,4.000000e+000,1.560211e-003,0.000000e+000,0,,0,
1524070128.358,,0.000000e+000,3.500028e+001,1.403650e-006,0.000000e+000,3,3.542379e-001,0.000000e+000,,,,,,,,,,,,,,32,1,4.000000e+000,1.560211e-003,0.000000e+000,0,,0,
1524070165.933,,0.000000e+000,3.499833e+001,1.420890e-006,0.000000e+000,3,3.465610e-001,0.000000e+000,,,,,,,,,,,,,,32,1,4.000000e+000,7.781982e-004,0.000000e+000,0,,0,
1524070203.884,,0.000000e+000,3.499833e+001,1.410902e-006,0.000000e+000,3,3.871719e-001,0.000000e+000,,,,,,,,,,,,,,32,1,4.000000e+000,7.781982e-004,0.000000e+000,0,,0,
1524070241.989,,0.000000e+000,3.499872e+001,1.383940e-006,0.000000e+000,3,3.492730e-001,0.000000e+000,,,,,,,,,,,,,,32,1,4.000000e+000,0.000000e+000,0.000000e+000,0,,0,
1524070280.055,,0.000000e+000,3.499950e+001,1.478991e-006,0.000000e+000,3,3.784985e-001,0.000000e+000,,,,,,,,,,,,,,32,1,4.000000e+000,0.000000e+000,0.000000e+000,0,,0,
1524070317.615,,0.000000e+000,3.499833e+001,1.500012e-006,0.000000e+000,3,3.817525e-001,0.000000e+000,,,,,,,,,,,,,,32,1,4.000000e+000,7.781982e-004,0.000000e+000,0,,0,
1524070355.321,,0.000000e+000,3.499950e+001,1.430951e-006,0.000000e+000,3,3.476013e-001,0.000000e+000,,,,,,,,,,,,,,32,1,4.000000e+000,1.560211e-003,0.000000e+000,0,,0,
1524070393.221,,0.000000e+000,3.499911e+001,1.420720e-006,0.000000e+000,3,3.558872e-001,0.000000e+000,,,,,,,,,,,,,,32,1,4.000000e+000,7.820129e-004,0.000000e+000,0,,0,
1524070431.115,,0.000000e+000,3.499911e+001,1.391621e-006,0.000000e+000,3,3.326625e-001,0.000000e+000,,,,,,,,,,,,,,32,1,4.000000e+000,7.820129e-004,0.000000e+000,0,,0,
1524070469.175,,0.000000e+000,3.499872e+001,1.372434e-006,0.000000e+000,3,3.373440e-001,0.000000e+000,,,,,,,,,,,,,,32,1,4.000000e+000,0.000000e+000,0.000000e+000,0,,0,
1524070506.818,,0.000000e+000,3.499950e+001,1.391663e-006,0.000000e+000,3,3.464278e-001,0.000000e+000,,,,,,,,,,,,,,32,1,4.000000e+000,1.560211e-003,0.000000e+000,0,,0,
1524070544.899,,0.000000e+000,3.499833e+001,1.394444e-006,0.000000e+000,3,3.706135e-001,0.000000e+000,,,,,,,,,,,,,,32,1,4.000000e+000,7.781982e-004,0.000000e+000,0,,0,
1524070582.954,,0.000000e+000,3.499911e+001,1.439046e-006,0.000000e+000,3,3.771915e-001,0.000000e+000,,,,,,,,,,,,,,32,1,4.000000e+000,7.820129e-004,0.000000e+000,0,,0,
1524070620.997,,0.000000e+000,3.499911e+001,1.400626e-006,0.000000e+000,3,3.510580e-001,0.000000e+000,,,,,,,,,,,,,,32,1,4.000000e+000,7.820129e-004,0.000000e+000,0,,0,
1524070659.085,,0.000000e+000,3.499872e+001,1.425752e-006,0.000000e+000,3,3.807519e-001,0.000000e+000,,,,,,,,,,,,,,32,1,4.000000e+000,0.000000e+000,0.000000e+000,0,,0,
1524070697.183,,0.000000e+000,3.499911e+001,1.373244e-006,0.000000e+000,3,3.443108e-001,0.000000e+000,,,,,,,,,,,,,,32,1,4.000000e+000,7.820129e-004,0.000000e+000,0,,0,
1524070734.836,,0.000000e+000,3.499911e+001,1.480923e-006,0.000000e+000,3,4.007614e-001,0.000000e+000,,,,,,,,,,,,,,32,1,4.000000e+000,7.820129e-004,0.000000e+000,0,,0,
1524070772.920,,0.000000e+000,3.499911e+001,1.355715e-006,0.000000e+000,3,3.618439e-001,0.000000e+000,,,,,,,,,,,,,,32,1,4.000000e+000,7.820129e-004,0.000000e+000,0,,0,
1524070811.445,,0.000000e+000,3.499950e+001,1.452935e-006,0.000000e+000,3,3.859321e-001,0.000000e+000,,,,,,,,,,,,,,32,1,4.000000e+000,1.560211e-003,0.000000e+000,0,,0,
1524070849.223,,0.000000e+000,3.499833e+001,1.449679e-006,0.000000e+000,3,3.547669e-001,0.000000e+000,,,,,,,,,,,,,,32,1,4.000000e+000,7.781982e-004,0.000000e+000,0,,0,
1524070886.636,,0.000000e+000,3.499950e+001,1.420187e-006,0.000000e+000,3,3.693126e-001,0.000000e+000,,,,,,,,,,,,,,32,1,4.000000e+000,1.560211e-003,0.000000e+000,0,,0,
1524070924.712,,0.000000e+000,3.499989e+001,1.399516e-006,0.000000e+000,3,3.703476e-001,0.000000e+000,,,,,,,,,,,,,,32,1,4.000000e+000,7.781982e-004,0.000000e+000,0,,0,
1524070962.795,,0.000000e+000,3.499950e+001,1.417755e-006,0.000000e+000,3,3.653108e-001,0.000000e+000,,,,,,,,,,,,,,32,1,4.000000e+000,1.560211e-003,0.000000e+000,0,,0,
1524071000.805,,0.000000e+000,3.499911e+001,1.425086e-006,0.000000e+000,3,3.906469e-001,0.000000e+000,,,,,,,,,,,,,,32,1,4.000000e+000,7.820129e-004,0.000000e+000,0,,0,
1524071039.266,,0.000000e+000,3.499989e+001,1.506353e-006,0.000000e+000,3,3.477725e-001,0.000000e+000,,,,,,,,,,,,,,32,1,4.000000e+000,7.781982e-004,0.000000e+000,0,,0,
1524071077.844,,0.000000e+000,3.499950e+001,1.436856e-006,0.000000e+000,3,3.481126e-001,0.000000e+000,,,,,,,,,,,,,,32,1,4.000000e+000,1.560211e-003,0.000000e+000,0,,0,
1524071116.690,,0.000000e+000,3.499911e+001,1.447156e-006,0.000000e+000,3,3.879163e-001,0.000000e+000,,,,,,,,,,,,,,32,1,4.000000e+000,2.338409e-003,0.000000e+000,0,,0,
1524071154.775,,0.000000e+000,3.499950e+001,1.461142e-006,0.000000e+000,3,3.842280e-001,0.000000e+000,,,,,,,,,,,,,,32,1,4.000000e+000,0.000000e+000,0.000000e+000,0,,0,
1524071192.808,,0.000000e+000,3.499950e+001,1.456583e-006,0.000000e+000,3,3.746434e-001,0.000000e+000,,,,,,,,,,,,,,32,1,4.000000e+000,0.000000e+000,0.000000e+000,0,,0,
1524071230.949,,0.000000e+000,3.499950e+001,1.456652e-006,0.000000e+000,3,3.812167e-001,0.000000e+000,,,,,,,,,,,,,,32,1,4.000000e+000,1.560211e-003,0.000000e+000,0,,0,
1524071269.434,,0.000000e+000,3.499872e+001,1.450288e-006,0.000000e+000,3,3.806922e-001,0.000000e+000,,,,,,,,,,,,,,32,1,4.000000e+000,0.000000e+000,0.000000e+000,0,,0,
1524071306.615,,0.000000e+000,3.499950e+001,1.425799e-006,0.000000e+000,3,3.768615e-001,0.000000e+000,,,,,,,,,,,,,,32,1,4.000000e+000,1.560211e-003,0.000000e+000,0,,0,
1524071345.090,,0.000000e+000,3.499950e+001,1.455809e-006,0.000000e+000,3,3.775593e-001,0.000000e+000,,,,,,,,,,,,,,32,1,4.000000e+000,1.560211e-003,0.000000e+000,0,,0,
1524071383.066,,0.000000e+000,3.499911e+001,1.485457e-006,0.000000e+000,3,3.735487e-001,0.000000e+000,,,,,,,,,,,,,,32,1,4.000000e+000,7.820129e-004,0.000000e+000,0,,0,
1524071421.034,,0.000000e+000,3.499872e+001,1.469160e-006,0.000000e+000,3,3.765570e-001,0.000000e+000,,,,,,,,,,,,,,32,1,4.000000e+000,0.000000e+000,0.000000e+000,0,,0,
1524071458.562,,0.000000e+000,3.499911e+001,1.448361e-006,0.000000e+000,3,3.407733e-001,0.000000e+000,,,,,,,,,,,,,,32,1,4.000000e+000,7.820129e-004,0.000000e+000,0,,0,
1524071496.428,,0.000000e+000,3.499989e+001,1.516112e-006,0.000000e+000,3,3.984645e-001,0.000000e+000,,,,,,,,,,,,,,32,1,4.000000e+000,7.781982e-004,0.000000e+000,0,,0,
1524071534.401,,0.000000e+000,3.499950e+001,1.527732e-006,0.000000e+000,3,3.844274e-001,0.000000e+000,,,,,,,,,,,,,,32,1,4.000000e+000,1.560211e-003,0.000000e+000,0,,0,
1524071573.471,,0.000000e+000,3.499872e+001,1.477561e-006,0.000000e+000,3,3.960418e-001,0.000000e+000,,,,,,,,,,,,,,32,1,4.000000e+000,0.000000e+000,0.000000e+000,0,,0,
1524071610.967,,0.000000e+000,3.499833e+001,1.420730e-006,0.000000e+000,3,3.605982e-001,0.000000e+000,,,,,,,,,,,,,,32,1,4.000000e+000,2.349854e-003,0.000000e+000,0,,0,
1524071648.562,,0.000000e+000,3.499872e+001,1.445055e-006,0.000000e+000,3,3.756371e-001,0.000000e+000,,,,,,,,,,,,,,32,1,4.000000e+000,1.560211e-003,0.000000e+000,0,,0,
1524071686.613,,0.000000e+000,3.499833e+001,1.485109e-006,0.000000e+000,3,3.937558e-001,0.000000e+000,,,,,,,,,,,,,,32,1,4.000000e+000,2.349854e-003,0.000000e+000,0,,0,
1524071724.726,,0.000000e+000,3.499872e+001,1.518519e-006,0.000000e+000,3,3.908474e-001,0.000000e+000,,,,,,,,,,,,,,32,1,4.000000e+000,1.560211e-003,0.000000e+000,0,,0,
1524071762.192,,0.000000e+000,3.499872e+001,1.491785e-006,0.000000e+000,3,3.930753e-001,0.000000e+000,,,,,,,,,,,,,,32,1,4.000000e+000,1.560211e-003,0.000000e+000,0,,0,
1524071800.237,,0.000000e+000,3.499794e+001,1.512898e-006,0.000000e+000,3,3.964586e-001,0.000000e+000,,,,,,,,,,,,,,32,1,4.000000e+000,0.000000e+000,0.000000e+000,0,,0,
1524071838.185,,0.000000e+000,3.499833e+001,1.555680e-006,0.000000e+000,3,3.950582e-001,0.000000e+000,,,,,,,,,,,,,,32,1,4.000000e+000,7.781982e-004,0.000000e+000,0,,0,
1524071876.028,,0.000000e+000,3.499911e+001,1.488687e-006,0.000000e+000,3,3.717184e-001,0.000000e+000,,,,,,,,,,,,,,32,1,4.000000e+000,7.820129e-004,0.000000e+000,0,,0,
1524071913.756,,0.000000e+000,3.499911e+001,1.492441e-006,0.000000e+000,3,3.881273e-001,0.000000e+000,,,,,,,,,,,,,,32,1,4.000000e+000,7.820129e-004,0.000000e+000,0,,0,
1524071951.399,,0.000000e+000,3.499989e+001,1.501384e-006,0.000000e+000,3,3.900873e-001,0.000000e+000,,,,,,,,,,,,,,32,1,4.000000e+000,7.781982e-004,0.000000e+000,0,,0,
1524071989.930,,0.000000e+000,3.499950e+001,1.491622e-006,0.000000e+000,3,4.000899e-001,0.000000e+000,,,,,,,,,,,,,,32,1,4.000000e+000,0.000000e+000,0.000000e+000,0,,0,
1524072028.020,,0.000000e+000,3.499911e+001,1.520380e-006,0.000000e+000,3,4.015288e-001,0.000000e+000,,,,,,,,,,,,,,32,1,4.000000e+000,7.820129e-004,0.000000e+000,0,,0,
1524072066.101,,0.000000e+000,3.499911e+001,1.528585e-006,0.000000e+000,3,3.911783e-001,0.000000e+000,,,,,,,,,,,,,,32,1,4.000000e+000,7.820129e-004,0.000000e+000,0,,0,
1524072104.399,,0.000000e+000,3.500067e+001,1.519071e-006,0.000000e+000,3,3.874112e-001,0.000000e+000,,,,,,,,,,,,,,32,1,4.000000e+000,3.910065e-003,0.000000e+000,0,,0,
1524072129.837,,0.000000e+000,3.499911e+001,1.563594e-006,0.000000e+000,3,4.196749e-001,0.000000e+000,,,,,,,,,,,,,,32,1,4.000000e+000,7.820129e-004,0.000000e+000,0,,0,