File: Experimental Raw Data/MFn1 VRM/Iterative Regression/MFn1_VRMac_40K_6000s_3000s_VRMde_40K.dc.dat
[Header]
TITLE,MPMS DC Measurement
BYAPP,MPMS Measurement,2.1,Summary
FILEOPENTIME, 1523939557.961000 4/16/2018, 10:32:37 PM

INFO, APPNAME, MPMS MultiVu Application, Revision 1.61,  Build 082

INFO, NAME, MFn1
INFO, WEIGHT, 1.000
INFO, AREA, 1.000
INFO, LENGTH, 1.000
INFO, SHAPE, 0
INFO, COMMENT,
INFO, SEQUENCE FILE: VRMac_40K_6000s_3000s_VRMde_40K.seq


INFO, BACKGROUND DATA FILE:, None


STARTUPAXIS,X,4,LINEAR,AUTO,0.000000,0.000000
STARTUPAXIS,Y1,5,LINEAR,AUTO,0.000000,0.000000


STARTUPGROUP,Longitudinal
FIELDGROUP,Longitudinal,1,2,3,4,5,6,7,8,9,15,16,17,18,27,28
FIELDGROUP,Transverse,1,2,3,4,10,11,12,13,14,19,20,21,22,27,28

PLOT_APPEARANCE,ALL,HORZ_GRID_ON,VERT_GRID_ON,MARKERS_AND_LINES

[Data]
Time,Comment,Field (Oe),Temperature (K),Long Moment (emu),Long Scan Std Dev,Long Algorithm,Long Reg Fit,Long Percent Error (%),Trans Moment (emu),Trans Scan Std Dev,Trans Algorithm,Trans Reg Fit,Trans Percent Error (%),Long Moment [w/o ABS] (emu),Long Scan Std Dev [w/o ABS],Long Reg Fit [w/o ABS],Long Percent Error [w/o ABS] (%),Trans Moment [w/o ABS] (emu),Trans Scan Std Dev [w/o ABS],Trans Reg Fit [w/o ABS],Trans Percent Error [w/o ABS] (%),Points per Scan,Scans per Measurement,Scan Length (cm),Delta Temp (K),Rot Position (deg),Error,EC Comp. Running,Using ABS,
1523939557.958,,0.000000e+000,3.999577e+001,-1.977921e-004,0.000000e+000,3,9.900588e-001,0.000000e+000,,,,,,,,,,,,,,32,1,4.000000e+000,4.131317e-003,0.000000e+000,0,,0,
1523939634.052,,0.000000e+000,3.999991e+001,-2.074615e-004,0.000000e+000,3,9.909592e-001,0.000000e+000,,,,,,,,,,,,,,32,1,4.000000e+000,2.059937e-003,0.000000e+000,0,,0,
1523939710.813,,0.000000e+000,3.999836e+001,-2.109241e-004,0.000000e+000,3,9.912137e-001,0.000000e+000,,,,,,,,,,,,,,32,1,4.000000e+000,1.037598e-003,0.000000e+000,0,,0,
1523939787.784,,0.000000e+000,3.999836e+001,-2.130798e-004,0.000000e+000,3,9.911311e-001,0.000000e+000,,,,,,,,,,,,,,32,1,4.000000e+000,1.037598e-003,0.000000e+000,0,,0,
1523939863.858,,0.000000e+000,3.999733e+001,-2.147642e-004,0.000000e+000,3,9.914047e-001,0.000000e+000,,,,,,,,,,,,,,32,1,4.000000e+000,1.029968e-003,0.000000e+000,0,,0,
1523939937.841,,0.000000e+000,3.999991e+001,-2.159740e-004,0.000000e+000,3,9.914419e-001,0.000000e+000,,,,,,,,,,,,,,32,1,4.000000e+000,0.000000e+000,0.000000e+000,0,,0,
1523940014.777,,0.000000e+000,3.999939e+001,-2.169316e-004,0.000000e+000,3,9.914798e-001,0.000000e+000,,,,,,,,,,,,,,32,1,4.000000e+000,1.029968e-003,0.000000e+000,0,,0,
1523940090.471,,0.000000e+000,3.999887e+001,-2.178730e-004,0.000000e+000,3,9.914250e-001,0.000000e+000,,,,,,,,,,,,,,32,1,4.000000e+000,2.067566e-003,0.000000e+000,0,,0,
1523940167.577,,0.000000e+000,3.999888e+001,-2.187199e-004,0.000000e+000,3,9.914508e-001,0.000000e+000,,,,,,,,,,,,,,32,1,4.000000e+000,0.000000e+000,0.000000e+000,0,,0,
1523940243.571,,0.000000e+000,3.999991e+001,-2.193875e-004,0.000000e+000,3,9.912754e-001,0.000000e+000,,,,,,,,,,,,,,32,1,4.000000e+000,2.059937e-003,0.000000e+000,0,,0,
1523940319.984,,0.000000e+000,3.999939e+001,-2.199679e-004,0.000000e+000,3,9.915268e-001,0.000000e+000,,,,,,,,,,,,,,32,1,4.000000e+000,1.029968e-003,0.000000e+000,0,,0,
1523940395.508,,0.000000e+000,3.999836e+001,-2.205745e-004,0.000000e+000,3,9.913480e-001,0.000000e+000,,,,,,,,,,,,,,32,1,4.000000e+000,1.037598e-003,0.000000e+000,0,,0,
1523940471.404,,0.000000e+000,4.000094e+001,-2.211154e-004,0.000000e+000,3,9.914505e-001,0.000000e+000,,,,,,,,,,,,,,32,1,4.000000e+000,4.119873e-003,0.000000e+000,0,,0,
1523940545.378,,0.000000e+000,3.999680e+001,-2.216416e-004,0.000000e+000,3,9.913449e-001,0.000000e+000,,,,,,,,,,,,,,32,1,4.000000e+000,2.071381e-003,0.000000e+000,0,,0,
1523940622.506,,0.000000e+000,3.999939e+001,-2.219462e-004,0.000000e+000,3,9.915681e-001,0.000000e+000,,,,,,,,,,,,,,32,1,4.000000e+000,3.097534e-003,0.000000e+000,0,,0,
1523940699.265,,0.000000e+000,3.999733e+001,-2.224975e-004,0.000000e+000,3,9.915983e-001,0.000000e+000,,,,,,,,,,,,,,32,1,4.000000e+000,1.029968e-003,0.000000e+000,0,,0,
1523940773.708,,0.000000e+000,3.999784e+001,-2.228875e-004,0.000000e+000,3,9.913753e-001,0.000000e+000,,,,,,,,,,,,,,32,1,4.000000e+000,0.000000e+000,0.000000e+000,0,,0,
1523940849.694,,0.000000e+000,4.000042e+001,-2.232829e-004,0.000000e+000,3,9.915427e-001,0.000000e+000,,,,,,,,,,,,,,32,1,4.000000e+000,3.089905e-003,0.000000e+000,0,,0,
1523940926.186,,0.000000e+000,3.999939e+001,-2.236200e-004,0.000000e+000,3,9.913606e-001,0.000000e+000,,,,,,,,,,,,,,32,1,4.000000e+000,1.029968e-003,0.000000e+000,0,,0,
1523941003.787,,0.000000e+000,3.999784e+001,-2.239604e-004,0.000000e+000,3,9.915781e-001,0.000000e+000,,,,,,,,,,,,,,32,1,4.000000e+000,0.000000e+000,0.000000e+000,0,,0,
1523941081.283,,0.000000e+000,3.999991e+001,-2.242855e-004,0.000000e+000,3,9.916157e-001,0.000000e+000,,,,,,,,,,,,,,32,1,4.000000e+000,0.000000e+000,0.000000e+000,0,,0,
1523941156.354,,0.000000e+000,3.999784e+001,-2.245717e-004,0.000000e+000,3,9.913543e-001,0.000000e+000,,,,,,,,,,,,,,32,1,4.000000e+000,2.067566e-003,0.000000e+000,0,,0,
1523941232.548,,0.000000e+000,3.999990e+001,-2.249442e-004,0.000000e+000,3,9.915546e-001,0.000000e+000,,,,,,,,,,,,,,32,1,4.000000e+000,6.187439e-003,0.000000e+000,0,,0,
1523941309.914,,0.000000e+000,3.999784e+001,-2.251353e-004,0.000000e+000,3,9.914949e-001,0.000000e+000,,,,,,,,,,,,,,32,1,4.000000e+000,2.067566e-003,0.000000e+000,0,,0,
1523941386.732,,0.000000e+000,3.999733e+001,-2.254348e-004,0.000000e+000,3,9.915429e-001,0.000000e+000,,,,,,,,,,,,,,32,1,4.000000e+000,1.029968e-003,0.000000e+000,0,,0,
1523941461.989,,0.000000e+000,3.999939e+001,-2.257255e-004,0.000000e+000,3,9.914203e-001,0.000000e+000,,,,,,,,,,,,,,32,1,4.000000e+000,3.097534e-003,0.000000e+000,0,,0,
1523941538.777,,0.000000e+000,3.999836e+001,-2.259785e-004,0.000000e+000,3,9.915441e-001,0.000000e+000,,,,,,,,,,,,,,32,1,4.000000e+000,1.037598e-003,0.000000e+000,0,,0,
1523941615.908,,0.000000e+000,3.999888e+001,-2.261955e-004,0.000000e+000,3,9.916266e-001,0.000000e+000,,,,,,,,,,,,,,32,1,4.000000e+000,0.000000e+000,0.000000e+000,0,,0,
1523941692.417,,0.000000e+000,3.999836e+001,-2.264270e-004,0.000000e+000,3,9.916486e-001,0.000000e+000,,,,,,,,,,,,,,32,1,4.000000e+000,3.097534e-003,0.000000e+000,0,,0,
1523941769.298,,0.000000e+000,3.999939e+001,-2.266598e-004,0.000000e+000,3,9.914626e-001,0.000000e+000,,,,,,,,,,,,,,32,1,4.000000e+000,1.029968e-003,0.000000e+000,0,,0,
1523941846.292,,0.000000e+000,3.999836e+001,-2.268524e-004,0.000000e+000,3,9.915321e-001,0.000000e+000,,,,,,,,,,,,,,32,1,4.000000e+000,1.037598e-003,0.000000e+000,0,,0,
1523941921.925,,0.000000e+000,3.999991e+001,-2.271244e-004,0.000000e+000,3,9.916528e-001,0.000000e+000,,,,,,,,,,,,,,32,1,4.000000e+000,2.059937e-003,0.000000e+000,0,,0,
1523941997.919,,0.000000e+000,4.000094e+001,-2.272999e-004,0.000000e+000,3,9.915633e-001,0.000000e+000,,,,,,,,,,,,,,32,1,4.000000e+000,2.059937e-003,0.000000e+000,0,,0,
1523942072.710,,0.000000e+000,3.999887e+001,-2.275284e-004,0.000000e+000,3,9.913499e-001,0.000000e+000,,,,,,,,,,,,,,32,1,4.000000e+000,6.198883e-003,0.000000e+000,0,,0,
1523942149.174,,0.000000e+000,4.000042e+001,-2.276332e-004,0.000000e+000,3,9.914268e-001,0.000000e+000,,,,,,,,,,,,,,32,1,4.000000e+000,1.029968e-003,0.000000e+000,0,,0,
1523942224.665,,0.000000e+000,3.999784e+001,-2.278342e-004,0.000000e+000,3,9.914640e-001,0.000000e+000,,,,,,,,,,,,,,32,1,4.000000e+000,2.067566e-003,0.000000e+000,0,,0,
1523942301.068,,0.000000e+000,3.999887e+001,-2.280295e-004,0.000000e+000,3,9.916126e-001,0.000000e+000,,,,,,,,,,,,,,32,1,4.000000e+000,6.198883e-003,0.000000e+000,0,,0,
1523942377.417,,0.000000e+000,3.999887e+001,-2.281947e-004,0.000000e+000,3,9.914102e-001,0.000000e+000,,,,,,,,,,,,,,32,1,4.000000e+000,2.067566e-003,0.000000e+000,0,,0,
1523942453.346,,0.000000e+000,3.999887e+001,-2.284125e-004,0.000000e+000,3,9.915892e-001,0.000000e+000,,,,,,,,,,,,,,32,1,4.000000e+000,2.067566e-003,0.000000e+000,0,,0,
1523942529.402,,0.000000e+000,3.999939e+001,-2.286270e-004,0.000000e+000,3,9.915519e-001,0.000000e+000,,,,,,,,,,,,,,32,1,4.000000e+000,1.029968e-003,0.000000e+000,0,,0,
1523942607.130,,0.000000e+000,3.999888e+001,-2.287681e-004,0.000000e+000,3,9.916613e-001,0.000000e+000,,,,,,,,,,,,,,32,1,4.000000e+000,0.000000e+000,0.000000e+000,0,,0,
1523942683.866,,0.000000e+000,3.999836e+001,-2.289191e-004,0.000000e+000,3,9.914392e-001,0.000000e+000,,,,,,,,,,,,,,32,1,4.000000e+000,1.037598e-003,0.000000e+000,0,,0,
1523942760.740,,0.000000e+000,3.999732e+001,-2.290502e-004,0.000000e+000,3,9.914016e-001,0.000000e+000,,,,,,,,,,,,,,32,1,4.000000e+000,3.108978e-003,0.000000e+000,0,,0,
1523942836.414,,0.000000e+000,3.999887e+001,-2.291881e-004,0.000000e+000,3,9.914511e-001,0.000000e+000,,,,,,,,,,,,,,32,1,4.000000e+000,2.067566e-003,0.000000e+000,0,,0,
1523942911.510,,0.000000e+000,3.999990e+001,-2.294262e-004,0.000000e+000,3,9.916957e-001,0.000000e+000,,,,,,,,,,,,,,32,1,4.000000e+000,4.127502e-003,0.000000e+000,0,,0,
1523942987.646,,0.000000e+000,3.999836e+001,-2.295629e-004,0.000000e+000,3,9.915906e-001,0.000000e+000,,,,,,,,,,,,,,32,1,4.000000e+000,1.037598e-003,0.000000e+000,0,,0,
1523943063.897,,0.000000e+000,3.999888e+001,-2.295848e-004,0.000000e+000,3,9.914953e-001,0.000000e+000,,,,,,,,,,,,,,32,1,4.000000e+000,0.000000e+000,0.000000e+000,0,,0,
1523943140.616,,0.000000e+000,3.999888e+001,-2.297730e-004,0.000000e+000,3,9.915869e-001,0.000000e+000,,,,,,,,,,,,,,32,1,4.000000e+000,0.000000e+000,0.000000e+000,0,,0,
1523943216.139,,0.000000e+000,3.999939e+001,-2.299396e-004,0.000000e+000,3,9.914614e-001,0.000000e+000,,,,,,,,,,,,,,32,1,4.000000e+000,3.097534e-003,0.000000e+000,0,,0,
1523943291.643,,0.000000e+000,3.999991e+001,-2.300690e-004,0.000000e+000,3,9.915577e-001,0.000000e+000,,,,,,,,,,,,,,32,1,4.000000e+000,2.059937e-003,0.000000e+000,0,,0,
1523943366.179,,0.000000e+000,3.999836e+001,-2.302481e-004,0.000000e+000,3,9.914650e-001,0.000000e+000,,,,,,,,,,,,,,32,1,4.000000e+000,3.097534e-003,0.000000e+000,0,,0,
1523943442.373,,0.000000e+000,3.999939e+001,-2.303217e-004,0.000000e+000,3,9.915613e-001,0.000000e+000,,,,,,,,,,,,,,32,1,4.000000e+000,1.029968e-003,0.000000e+000,0,,0,
1523943518.316,,0.000000e+000,3.999784e+001,-2.304789e-004,0.000000e+000,3,9.915776e-001,0.000000e+000,,,,,,,,,,,,,,32,1,4.000000e+000,0.000000e+000,0.000000e+000,0,,0,
1523943592.587,,0.000000e+000,4.000042e+001,-2.306132e-004,0.000000e+000,3,9.914382e-001,0.000000e+000,,,,,,,,,,,,,,32,1,4.000000e+000,1.029968e-003,0.000000e+000,0,,0,
1523943667.413,,0.000000e+000,3.999939e+001,-2.306856e-004,0.000000e+000,3,9.915314e-001,0.000000e+000,,,,,,,,,,,,,,32,1,4.000000e+000,1.029968e-003,0.000000e+000,0,,0,
1523943743.877,,0.000000e+000,3.999784e+001,-2.308261e-004,0.000000e+000,3,9.914174e-001,0.000000e+000,,,,,,,,,,,,,,32,1,4.000000e+000,2.067566e-003,0.000000e+000,0,,0,
1523943821.423,,0.000000e+000,3.999939e+001,-2.309867e-004,0.000000e+000,3,9.914293e-001,0.000000e+000,,,,,,,,,,,,,,32,1,4.000000e+000,1.029968e-003,0.000000e+000,0,,0,
1523943898.259,,0.000000e+000,3.999887e+001,-2.310415e-004,0.000000e+000,3,9.915043e-001,0.000000e+000,,,,,,,,,,,,,,32,1,4.000000e+000,2.067566e-003,0.000000e+000,0,,0,
1523943974.210,,0.000000e+000,3.999887e+001,-2.312114e-004,0.000000e+000,3,9.915311e-001,0.000000e+000,,,,,,,,,,,,,,32,1,4.000000e+000,2.067566e-003,0.000000e+000,0,,0,
1523944050.586,,0.000000e+000,3.999680e+001,-2.312569e-004,0.000000e+000,3,9.914843e-001,0.000000e+000,,,,,,,,,,,,,,32,1,4.000000e+000,2.071381e-003,0.000000e+000,0,,0,
1523944125.580,,0.000000e+000,3.999991e+001,-2.314181e-004,0.000000e+000,3,9.916208e-001,0.000000e+000,,,,,,,,,,,,,,32,1,4.000000e+000,2.059937e-003,0.000000e+000,0,,0,
1523944199.386,,0.000000e+000,3.999888e+001,-2.315489e-004,0.000000e+000,3,9.915857e-001,0.000000e+000,,,,,,,,,,,,,,32,1,4.000000e+000,0.000000e+000,0.000000e+000,0,,0,
1523944273.375,,0.000000e+000,3.999939e+001,-2.316461e-004,0.000000e+000,3,9.916845e-001,0.000000e+000,,,,,,,,,,,,,,32,1,4.000000e+000,1.029968e-003,0.000000e+000,0,,0,
1523944350.913,,0.000000e+000,3.999887e+001,-2.317406e-004,0.000000e+000,3,9.915336e-001,0.000000e+000,,,,,,,,,,,,,,32,1,4.000000e+000,2.067566e-003,0.000000e+000,0,,0,
1523944428.400,,0.000000e+000,3.999939e+001,-2.318393e-004,0.000000e+000,3,9.915474e-001,0.000000e+000,,,,,,,,,,,,,,32,1,4.000000e+000,1.029968e-003,0.000000e+000,0,,0,
1523944504.563,,0.000000e+000,3.999784e+001,-2.319083e-004,0.000000e+000,3,9.914215e-001,0.000000e+000,,,,,,,,,,,,,,32,1,4.000000e+000,2.067566e-003,0.000000e+000,0,,0,
1523944579.787,,0.000000e+000,3.999887e+001,-2.320463e-004,0.000000e+000,3,9.915395e-001,0.000000e+000,,,,,,,,,,,,,,32,1,4.000000e+000,2.067566e-003,0.000000e+000,0,,0,
1523944657.208,,0.000000e+000,4.000042e+001,-2.321275e-004,0.000000e+000,3,9.914688e-001,0.000000e+000,,,,,,,,,,,,,,32,1,4.000000e+000,1.029968e-003,0.000000e+000,0,,0,
1523944735.672,,0.000000e+000,3.999732e+001,-2.322558e-004,0.000000e+000,3,9.915484e-001,0.000000e+000,,,,,,,,,,,,,,32,1,4.000000e+000,3.108978e-003,0.000000e+000,0,,0,
1523944812.495,,0.000000e+000,3.999991e+001,-2.323529e-004,0.000000e+000,3,9.915679e-001,0.000000e+000,,,,,,,,,,,,,,32,1,4.000000e+000,0.000000e+000,0.000000e+000,0,,0,
1523944889.014,,0.000000e+000,3.999939e+001,-2.324263e-004,0.000000e+000,3,9.914752e-001,0.000000e+000,,,,,,,,,,,,,,32,1,4.000000e+000,1.029968e-003,0.000000e+000,0,,0,
1523944978.823,,0.000000e+000,3.999990e+001,-3.091917e-005,0.000000e+000,3,9.660558e-001,0.000000e+000,,,,,,,,,,,,,,32,1,4.000000e+000,4.127502e-003,0.000000e+000,0,,0,
1523945054.824,,0.000000e+000,3.999732e+001,-2.713468e-005,0.000000e+000,3,9.586573e-001,0.000000e+000,,,,,,,,,,,,,,32,1,4.000000e+000,5.168915e-003,0.000000e+000,0,,0,
1523945140.973,,0.000000e+000,3.999991e+001,-2.478873e-005,0.000000e+000,3,9.560570e-001,0.000000e+000,,,,,,,,,,,,,,32,1,4.000000e+000,2.059937e-003,0.000000e+000,0,,0,
1523945216.209,,0.000000e+000,3.999680e+001,-2.333077e-005,0.000000e+000,3,9.508267e-001,0.000000e+000,,,,,,,,,,,,,,32,1,4.000000e+000,2.071381e-003,0.000000e+000,0,,0,
1523945293.802,,0.000000e+000,4.000042e+001,-2.214189e-005,0.000000e+000,3,9.496950e-001,0.000000e+000,,,,,,,,,,,,,,32,1,4.000000e+000,3.089905e-003,0.000000e+000,0,,0,
1523945370.298,,0.000000e+000,3.999888e+001,-2.122554e-005,0.000000e+000,3,9.457891e-001,0.000000e+000,,,,,,,,,,,,,,32,1,4.000000e+000,0.000000e+000,0.000000e+000,0,,0,
1523945445.542,,0.000000e+000,4.000042e+001,-2.048130e-005,0.000000e+000,3,9.443562e-001,0.000000e+000,,,,,,,,,,,,,,32,1,4.000000e+000,1.029968e-003,0.000000e+000,0,,0,
1523945521.963,,0.000000e+000,3.999888e+001,-1.972036e-005,0.000000e+000,3,9.433412e-001,0.000000e+000,,,,,,,,,,,,,,32,1,4.000000e+000,0.000000e+000,0.000000e+000,0,,0,
1523945601.794,,0.000000e+000,4.000042e+001,-1.913001e-005,0.000000e+000,3,9.421678e-001,0.000000e+000,,,,,,,,,,,,,,32,1,4.000000e+000,3.089905e-003,0.000000e+000,0,,0,
1523945676.913,,0.000000e+000,3.999732e+001,-1.866406e-005,0.000000e+000,3,9.414357e-001,0.000000e+000,,,,,,,,,,,,,,32,1,4.000000e+000,3.108978e-003,0.000000e+000,0,,0,
1523945754.781,,0.000000e+000,3.999991e+001,-1.809938e-005,0.000000e+000,3,9.367498e-001,0.000000e+000,,,,,,,,,,,,,,32,1,4.000000e+000,2.059937e-003,0.000000e+000,0,,0,
1523945831.035,,0.000000e+000,3.999991e+001,-1.771365e-005,0.000000e+000,3,9.354928e-001,0.000000e+000,,,,,,,,,,,,,,32,1,4.000000e+000,2.059937e-003,0.000000e+000,0,,0,
1523945908.104,,0.000000e+000,3.999836e+001,-1.731117e-005,0.000000e+000,3,9.373366e-001,0.000000e+000,,,,,,,,,,,,,,32,1,4.000000e+000,1.037598e-003,0.000000e+000,0,,0,
1523945982.830,,0.000000e+000,4.000198e+001,-1.693584e-005,0.000000e+000,3,9.332070e-001,0.000000e+000,,,,,,,,,,,,,,32,1,4.000000e+000,4.131317e-003,0.000000e+000,0,,0,
1523946060.491,,0.000000e+000,3.999733e+001,-1.656818e-005,0.000000e+000,3,9.317783e-001,0.000000e+000,,,,,,,,,,,,,,32,1,4.000000e+000,1.029968e-003,0.000000e+000,0,,0,
1523946136.855,,0.000000e+000,3.999939e+001,-1.631210e-005,0.000000e+000,3,9.311928e-001,0.000000e+000,,,,,,,,,,,,,,32,1,4.000000e+000,1.029968e-003,0.000000e+000,0,,0,
1523946213.356,,0.000000e+000,3.999784e+001,-1.599778e-005,0.000000e+000,3,9.294865e-001,0.000000e+000,,,,,,,,,,,,,,32,1,4.000000e+000,2.067566e-003,0.000000e+000,0,,0,
1523946288.307,,0.000000e+000,4.000042e+001,-1.576346e-005,0.000000e+000,3,9.299021e-001,0.000000e+000,,,,,,,,,,,,,,32,1,4.000000e+000,3.089905e-003,0.000000e+000,0,,0,
1523946364.930,,0.000000e+000,4.000145e+001,-1.552760e-005,0.000000e+000,3,9.283224e-001,0.000000e+000,,,,,,,,,,,,,,32,1,4.000000e+000,3.089905e-003,0.000000e+000,0,,0,
1523946441.552,,0.000000e+000,3.999939e+001,-1.526376e-005,0.000000e+000,3,9.270087e-001,0.000000e+000,,,,,,,,,,,,,,32,1,4.000000e+000,1.029968e-003,0.000000e+000,0,,0,
1523946518.538,,0.000000e+000,3.999991e+001,-1.506631e-005,0.000000e+000,3,9.275187e-001,0.000000e+000,,,,,,,,,,,,,,32,1,4.000000e+000,0.000000e+000,0.000000e+000,0,,0,
1523946596.286,,0.000000e+000,3.999888e+001,-1.486604e-005,0.000000e+000,3,9.254966e-001,0.000000e+000,,,,,,,,,,,,,,32,1,4.000000e+000,0.000000e+000,0.000000e+000,0,,0,
1523946673.670,,0.000000e+000,3.999887e+001,-1.463704e-005,0.000000e+000,3,9.233868e-001,0.000000e+000,,,,,,,,,,,,,,32,1,4.000000e+000,2.067566e-003,0.000000e+000,0,,0,
1523946749.946,,0.000000e+000,3.999784e+001,-1.440669e-005,0.000000e+000,3,9.231620e-001,0.000000e+000,,,,,,,,,,,,,,32,1,4.000000e+000,4.138947e-003,0.000000e+000,0,,0,
1523946825.132,,0.000000e+000,3.999939e+001,-1.421369e-005,0.000000e+000,3,9.227326e-001,0.000000e+000,,,,,,,,,,,,,,32,1,4.000000e+000,1.029968e-003,0.000000e+000,0,,0,
1523946901.171,,0.000000e+000,3.999888e+001,-1.405339e-005,0.000000e+000,3,9.194248e-001,0.000000e+000,,,,,,,,,,,,,,32,1,4.000000e+000,0.000000e+000,0.000000e+000,0,,0,
1523946977.094,,0.000000e+000,3.999888e+001,-1.387745e-005,0.000000e+000,3,9.189304e-001,0.000000e+000,,,,,,,,,,,,,,32,1,4.000000e+000,0.000000e+000,0.000000e+000,0,,0,
1523947053.498,,0.000000e+000,4.000042e+001,-1.371950e-005,0.000000e+000,3,9.172562e-001,0.000000e+000,,,,,,,,,,,,,,32,1,4.000000e+000,3.089905e-003,0.000000e+000,0,,0,
1523947129.894,,0.000000e+000,3.999836e+001,-1.353030e-005,0.000000e+000,3,9.176629e-001,0.000000e+000,,,,,,,,,,,,,,32,1,4.000000e+000,3.097534e-003,0.000000e+000,0,,0,
1523947206.175,,0.000000e+000,4.000042e+001,-1.340481e-005,0.000000e+000,3,9.170347e-001,0.000000e+000,,,,,,,,,,,,,,32,1,4.000000e+000,1.029968e-003,0.000000e+000,0,,0,
1523947282.116,,0.000000e+000,3.999939e+001,-1.327041e-005,0.000000e+000,3,9.152798e-001,0.000000e+000,,,,,,,,,,,,,,32,1,4.000000e+000,1.029968e-003,0.000000e+000,0,,0,
1523947358.493,,0.000000e+000,3.999836e+001,-1.315349e-005,0.000000e+000,3,9.161202e-001,0.000000e+000,,,,,,,,,,,,,,32,1,4.000000e+000,1.037598e-003,0.000000e+000,0,,0,
1523947433.746,,0.000000e+000,3.999990e+001,-1.299367e-005,0.000000e+000,3,9.143636e-001,0.000000e+000,,,,,,,,,,,,,,32,1,4.000000e+000,6.187439e-003,0.000000e+000,0,,0,
1523947510.872,,0.000000e+000,3.999990e+001,-1.288790e-005,0.000000e+000,3,9.156101e-001,0.000000e+000,,,,,,,,,,,,,,32,1,4.000000e+000,4.127502e-003,0.000000e+000,0,,0,
1523947586.916,,0.000000e+000,3.999888e+001,-1.280061e-005,0.000000e+000,3,9.166359e-001,0.000000e+000,,,,,,,,,,,,,,32,1,4.000000e+000,0.000000e+000,0.000000e+000,0,,0,
1523947663.292,,0.000000e+000,3.999888e+001,-1.265749e-005,0.000000e+000,3,9.127336e-001,0.000000e+000,,,,,,,,,,,,,,32,1,4.000000e+000,0.000000e+000,0.000000e+000,0,,0,
1523947738.753,,0.000000e+000,3.999939e+001,-1.255810e-005,0.000000e+000,3,9.142195e-001,0.000000e+000,,,,,,,,,,,,,,32,1,4.000000e+000,3.097534e-003,0.000000e+000,0,,0,
1523947815.097,,0.000000e+000,3.999733e+001,-1.242455e-005,0.000000e+000,3,9.101521e-001,0.000000e+000,,,,,,,,,,,,,,32,1,4.000000e+000,1.029968e-003,0.000000e+000,0,,0,
1523947891.545,,0.000000e+000,3.999939e+001,-1.232132e-005,0.000000e+000,3,9.096066e-001,0.000000e+000,,,,,,,,,,,,,,32,1,4.000000e+000,1.029968e-003,0.000000e+000,0,,0,
1523947967.947,,0.000000e+000,3.999888e+001,-1.222051e-005,0.000000e+000,3,9.076369e-001,0.000000e+000,,,,,,,,,,,,,,32,1,4.000000e+000,0.000000e+000,0.000000e+000,0,,0,
1523948045.693,,0.000000e+000,3.999887e+001,-1.211047e-005,0.000000e+000,3,9.099404e-001,0.000000e+000,,,,,,,,,,,,,,32,1,4.000000e+000,2.067566e-003,0.000000e+000,0,,0,
1523948119.916,,0.000000e+000,3.999888e+001,-1.200819e-005,0.000000e+000,3,9.088510e-001,0.000000e+000,,,,,,,,,,,,,,32,1,4.000000e+000,0.000000e+000,0.000000e+000,0,,0,
1523948193.897,,0.000000e+000,3.999836e+001,-1.196976e-005,0.000000e+000,3,9.088449e-001,0.000000e+000,,,,,,,,,,,,,,32,1,4.000000e+000,1.037598e-003,0.000000e+000,0,,0,
1523948269.898,,0.000000e+000,3.999836e+001,-1.193334e-005,0.000000e+000,3,9.089684e-001,0.000000e+000,,,,,,,,,,,,,,32,1,4.000000e+000,3.097534e-003,0.000000e+000,0,,0,
1523948344.969,,0.000000e+000,3.999939e+001,-1.174104e-005,0.000000e+000,3,9.049056e-001,0.000000e+000,,,,,,,,,,,,,,32,1,4.000000e+000,1.029968e-003,0.000000e+000,0,,0,
1523948422.098,,0.000000e+000,3.999836e+001,-1.167074e-005,0.000000e+000,3,9.049635e-001,0.000000e+000,,,,,,,,,,,,,,32,1,4.000000e+000,1.037598e-003,0.000000e+000,0,,0,
1523948497.612,,0.000000e+000,3.999629e+001,-1.163935e-005,0.000000e+000,3,9.052612e-001,0.000000e+000,,,,,,,,,,,,,,32,1,4.000000e+000,7.228851e-003,0.000000e+000,0,,0,
1523948573.243,,0.000000e+000,4.000146e+001,-1.150877e-005,0.000000e+000,3,9.052148e-001,0.000000e+000,,,,,,,,,,,,,,32,1,4.000000e+000,5.161285e-003,0.000000e+000,0,,0,
1523948651.132,,0.000000e+000,3.999836e+001,-1.147819e-005,0.000000e+000,3,9.010701e-001,0.000000e+000,,,,,,,,,,,,,,32,1,4.000000e+000,1.037598e-003,0.000000e+000,0,,0,
1523948727.130,,0.000000e+000,3.999680e+001,-1.136646e-005,0.000000e+000,3,9.041486e-001,0.000000e+000,,,,,,,,,,,,,,32,1,4.000000e+000,2.071381e-003,0.000000e+000,0,,0,
1523948801.709,,0.000000e+000,3.999939e+001,-1.131927e-005,0.000000e+000,3,9.037068e-001,0.000000e+000,,,,,,,,,,,,,,32,1,4.000000e+000,1.029968e-003,0.000000e+000,0,,0,
1523948876.925,,0.000000e+000,4.000042e+001,-1.124523e-005,0.000000e+000,3,9.013745e-001,0.000000e+000,,,,,,,,,,,,,,32,1,4.000000e+000,1.029968e-003,0.000000e+000,0,,0,
1523948954.388,,0.000000e+000,3.999836e+001,-1.111854e-005,0.000000e+000,3,9.025153e-001,0.000000e+000,,,,,,,,,,,,,,32,1,4.000000e+000,1.037598e-003,0.000000e+000,0,,0,
1523949029.512,,0.000000e+000,3.999991e+001,-1.110866e-005,0.000000e+000,3,9.013583e-001,0.000000e+000,,,,,,,,,,,,,,32,1,4.000000e+000,0.000000e+000,0.000000e+000,0,,0,
1523949106.188,,0.000000e+000,4.000094e+001,-1.105016e-005,0.000000e+000,3,8.983321e-001,0.000000e+000,,,,,,,,,,,,,,32,1,4.000000e+000,6.198883e-003,0.000000e+000,0,,0,
1523949183.237,,0.000000e+000,3.999836e+001,-1.098271e-005,0.000000e+000,3,8.968754e-001,0.000000e+000,,,,,,,,,,,,,,32,1,4.000000e+000,1.037598e-003,0.000000e+000,0,,0,
1523949260.311,,0.000000e+000,3.999939e+001,-1.093052e-005,0.000000e+000,3,9.016616e-001,0.000000e+000,,,,,,,,,,,,,,32,1,4.000000e+000,1.029968e-003,0.000000e+000,0,,0,
1523949336.264,,0.000000e+000,3.999991e+001,-1.083913e-005,0.000000e+000,3,9.002269e-001,0.000000e+000,,,,,,,,,,,,,,32,1,4.000000e+000,2.059937e-003,0.000000e+000,0,,0,
1523949410.528,,0.000000e+000,3.999888e+001,-1.077562e-005,0.000000e+000,3,8.994383e-001,0.000000e+000,,,,,,,,,,,,,,32,1,4.000000e+000,0.000000e+000,0.000000e+000,0,,0,
1523949484.476,,0.000000e+000,3.999888e+001,-1.074850e-005,0.000000e+000,3,8.980117e-001,0.000000e+000,,,,,,,,,,,,,,32,1,4.000000e+000,0.000000e+000,0.000000e+000,0,,0,
1523949559.372,,0.000000e+000,3.999991e+001,-1.067015e-005,0.000000e+000,3,8.950806e-001,0.000000e+000,,,,,,,,,,,,,,32,1,4.000000e+000,0.000000e+000,0.000000e+000,0,,0,
1523949635.253,,0.000000e+000,3.999991e+001,-1.059014e-005,0.000000e+000,3,8.984233e-001,0.000000e+000,,,,,,,,,,,,,,32,1,4.000000e+000,2.059937e-003,0.000000e+000,0,,0,
1523949711.210,,0.000000e+000,3.999836e+001,-1.055335e-005,0.000000e+000,3,8.960511e-001,0.000000e+000,,,,,,,,,,,,,,32,1,4.000000e+000,1.037598e-003,0.000000e+000,0,,0,
1523949788.248,,0.000000e+000,3.999680e+001,-1.050519e-005,0.000000e+000,3,8.926440e-001,0.000000e+000,,,,,,,,,,,,,,32,1,4.000000e+000,2.071381e-003,0.000000e+000,0,,0,
1523949863.389,,0.000000e+000,4.000145e+001,-1.046944e-005,0.000000e+000,3,8.968287e-001,0.000000e+000,,,,,,,,,,,,,,32,1,4.000000e+000,1.029968e-003,0.000000e+000,0,,0,
1523949938.998,,0.000000e+000,3.999888e+001,-1.040239e-005,0.000000e+000,3,8.922536e-001,0.000000e+000,,,,,,,,,,,,,,32,1,4.000000e+000,0.000000e+000,0.000000e+000,0,,0,
1523950016.629,,0.000000e+000,3.999888e+001,-1.035174e-005,0.000000e+000,3,8.958935e-001,0.000000e+000,,,,,,,,,,,,,,32,1,4.000000e+000,0.000000e+000,0.000000e+000,0,,0,
1523950093.853,,0.000000e+000,3.999939e+001,-1.030683e-005,0.000000e+000,3,8.934261e-001,0.000000e+000,,,,,,,,,,,,,,32,1,4.000000e+000,1.029968e-003,0.000000e+000,0,,0,
1523950170.326,,0.000000e+000,3.999939e+001,-1.023008e-005,0.000000e+000,3,8.908080e-001,0.000000e+000,,,,,,,,,,,,,,32,1,4.000000e+000,1.029968e-003,0.000000e+000,0,,0,
1523950246.265,,0.000000e+000,3.999991e+001,-1.020751e-005,0.000000e+000,3,8.937171e-001,0.000000e+000,,,,,,,,,,,,,,32,1,4.000000e+000,0.000000e+000,0.000000e+000,0,,0,
1523950324.126,,0.000000e+000,3.999939e+001,-1.015344e-005,0.000000e+000,3,8.935186e-001,0.000000e+000,,,,,,,,,,,,,,32,1,4.000000e+000,3.097534e-003,0.000000e+000,0,,0,
1523950399.197,,0.000000e+000,3.999784e+001,-1.009878e-005,0.000000e+000,3,8.919932e-001,0.000000e+000,,,,,,,,,,,,,,32,1,4.000000e+000,0.000000e+000,0.000000e+000,0,,0,
1523950477.496,,0.000000e+000,4.000042e+001,-1.004658e-005,0.000000e+000,3,8.897805e-001,0.000000e+000,,,,,,,,,,,,,,32,1,4.000000e+000,3.089905e-003,0.000000e+000,0,,0,
1523950554.207,,0.000000e+000,3.999836e+001,-1.003414e-005,0.000000e+000,3,8.933980e-001,0.000000e+000,,,,,,,,,,,,,,32,1,4.000000e+000,1.037598e-003,0.000000e+000,0,,0,
1523950629.736,,0.000000e+000,3.999991e+001,-9.993794e-006,0.000000e+000,3,8.910253e-001,0.000000e+000,,,,,,,,,,,,,,32,1,4.000000e+000,2.059937e-003,0.000000e+000,0,,0,
1523950704.629,,0.000000e+000,3.999939e+001,-9.969327e-006,0.000000e+000,3,8.911693e-001,0.000000e+000,,,,,,,,,,,,,,32,1,4.000000e+000,1.029968e-003,0.000000e+000,0,,0,
1523950781.093,,0.000000e+000,3.999835e+001,-9.857572e-006,0.000000e+000,3,8.921992e-001,0.000000e+000,,,,,,,,,,,,,,32,1,4.000000e+000,5.168915e-003,0.000000e+000,0,,0,
1523950854.789,,0.000000e+000,3.999939e+001,-9.865082e-006,0.000000e+000,3,8.898386e-001,0.000000e+000,,,,,,,,,,,,,,32,1,4.000000e+000,1.029968e-003,0.000000e+000,0,,0,
1523950931.837,,0.000000e+000,4.000042e+001,-9.796450e-006,0.000000e+000,3,8.870912e-001,0.000000e+000,,,,,,,,,,,,,,32,1,4.000000e+000,1.029968e-003,0.000000e+000,0,,0,
1523951007.666,,0.000000e+000,3.999939e+001,-9.773261e-006,0.000000e+000,3,8.896290e-001,0.000000e+000,,,,,,,,,,,,,,32,1,4.000000e+000,1.029968e-003,0.000000e+000,0,,0,
1523951084.305,,0.000000e+000,3.999939e+001,-9.714679e-006,0.000000e+000,3,8.899320e-001,0.000000e+000,,,,,,,,,,,,,,32,1,4.000000e+000,1.029968e-003,0.000000e+000,0,,0,
1523951159.361,,0.000000e+000,3.999939e+001,-9.703597e-006,0.000000e+000,3,8.876806e-001,0.000000e+000,,,,,,,,,,,,,,32,1,4.000000e+000,1.029968e-003,0.000000e+000,0,,0,
1523951236.279,,0.000000e+000,3.999887e+001,-9.647872e-006,0.000000e+000,3,8.862635e-001,0.000000e+000,,,,,,,,,,,,,,32,1,4.000000e+000,2.067566e-003,0.000000e+000,0,,0,
1523951313.398,,0.000000e+000,3.999784e+001,-9.577973e-006,0.000000e+000,3,8.822789e-001,0.000000e+000,,,,,,,,,,,,,,32,1,4.000000e+000,4.138947e-003,0.000000e+000,0,,0,
1523951389.927,,0.000000e+000,4.000249e+001,-9.527543e-006,0.000000e+000,3,8.828806e-001,0.000000e+000,,,,,,,,,,,,,,32,1,4.000000e+000,5.161285e-003,0.000000e+000,0,,0,
1523951466.203,,0.000000e+000,3.999888e+001,-9.554446e-006,0.000000e+000,3,8.865558e-001,0.000000e+000,,,,,,,,,,,,,,32,1,4.000000e+000,0.000000e+000,0.000000e+000,0,,0,
1523951543.309,,0.000000e+000,3.999939e+001,-9.469812e-006,0.000000e+000,3,8.839635e-001,0.000000e+000,,,,,,,,,,,,,,32,1,4.000000e+000,1.029968e-003,0.000000e+000,0,,0,
1523951618.805,,0.000000e+000,4.000094e+001,-9.441726e-006,0.000000e+000,3,8.835938e-001,0.000000e+000,,,,,,,,,,,,,,32,1,4.000000e+000,4.119873e-003,0.000000e+000,0,,0,
1523951694.824,,0.000000e+000,3.999939e+001,-9.442021e-006,0.000000e+000,3,8.867437e-001,0.000000e+000,,,,,,,,,,,,,,32,1,4.000000e+000,1.029968e-003,0.000000e+000,0,,0,
1523951770.195,,0.000000e+000,4.000042e+001,-9.407252e-006,0.000000e+000,3,8.860992e-001,0.000000e+000,,,,,,,,,,,,,,32,1,4.000000e+000,3.089905e-003,0.000000e+000,0,,0,
1523951846.293,,0.000000e+000,3.999836e+001,-9.357796e-006,0.000000e+000,3,8.797675e-001,0.000000e+000,,,,,,,,,,,,,,32,1,4.000000e+000,1.037598e-003,0.000000e+000,0,,0,
1523951923.025,,0.000000e+000,3.999939e+001,-9.323105e-006,0.000000e+000,3,8.800478e-001,0.000000e+000,,,,,,,,,,,,,,32,1,4.000000e+000,1.029968e-003,0.000000e+000,0,,0,
1523952000.616,,0.000000e+000,3.999888e+001,-9.271746e-006,0.000000e+000,3,8.820292e-001,0.000000e+000,,,,,,,,,,,,,,32,1,4.000000e+000,0.000000e+000,0.000000e+000,0,,0,
1523952077.152,,0.000000e+000,4.000198e+001,-9.254438e-006,0.000000e+000,3,8.764926e-001,0.000000e+000,,,,,,,,,,,,,,32,1,4.000000e+000,6.191254e-003,0.000000e+000,0,,0,
1523952152.298,,0.000000e+000,3.999888e+001,-9.237257e-006,0.000000e+000,3,8.830046e-001,0.000000e+000,,,,,,,,,,,,,,32,1,4.000000e+000,0.000000e+000,0.000000e+000,0,,0,
1523952227.889,,0.000000e+000,4.000042e+001,-9.164506e-006,0.000000e+000,3,8.765398e-001,0.000000e+000,,,,,,,,,,,,,,32,1,4.000000e+000,1.029968e-003,0.000000e+000,0,,0,
1523952303.005,,0.000000e+000,3.999526e+001,-9.226187e-006,0.000000e+000,3,8.807200e-001,0.000000e+000,,,,,,,,,,,,,,32,1,4.000000e+000,3.101349e-003,0.000000e+000,0,,0,
1523952379.541,,0.000000e+000,3.999680e+001,-9.125361e-006,0.000000e+000,3,8.800258e-001,0.000000e+000,,,,,,,,,,,,,,32,1,4.000000e+000,2.071381e-003,0.000000e+000,0,,0,
1523952457.352,,0.000000e+000,3.999784e+001,-9.125448e-006,0.000000e+000,3,8.793181e-001,0.000000e+000,,,,,,,,,,,,,,32,1,4.000000e+000,2.067566e-003,0.000000e+000,0,,0,
1523952534.011,,0.000000e+000,3.999784e+001,-9.095815e-006,0.000000e+000,3,8.776020e-001,0.000000e+000,,,,,,,,,,,,,,32,1,4.000000e+000,2.067566e-003,0.000000e+000,0,,0,
1523952609.992,,0.000000e+000,3.999991e+001,-9.050552e-006,0.000000e+000,3,8.803189e-001,0.000000e+000,,,,,,,,,,,,,,32,1,4.000000e+000,0.000000e+000,0.000000e+000,0,,0,
1523952688.033,,0.000000e+000,3.999939e+001,-9.019506e-006,0.000000e+000,3,8.799214e-001,0.000000e+000,,,,,,,,,,,,,,32,1,4.000000e+000,1.029968e-003,0.000000e+000,0,,0,
1523952764.169,,0.000000e+000,3.999939e+001,-9.009304e-006,0.000000e+000,3,8.764665e-001,0.000000e+000,,,,,,,,,,,,,,32,1,4.000000e+000,1.029968e-003,0.000000e+000,0,,0,
1523952839.565,,0.000000e+000,3.999836e+001,-8.993859e-006,0.000000e+000,3,8.818536e-001,0.000000e+000,,,,,,,,,,,,,,32,1,4.000000e+000,1.037598e-003,0.000000e+000,0,,0,
1523952914.939,,0.000000e+000,3.999887e+001,-8.940456e-006,0.000000e+000,3,8.762389e-001,0.000000e+000,,,,,,,,,,,,,,32,1,4.000000e+000,2.067566e-003,0.000000e+000,0,,0,
1523958220.874,,0.000000e+000,3.999991e+001,-2.038262e-004,0.000000e+000,3,9.910141e-001,0.000000e+000,,,,,,,,,,,,,,32,1,4.000000e+000,2.059937e-003,0.000000e+000,0,,0,
1523958295.681,,0.000000e+000,4.000094e+001,-2.080583e-004,0.000000e+000,3,9.910961e-001,0.000000e+000,,,,,,,,,,,,,,32,1,4.000000e+000,0.000000e+000,0.000000e+000,0,,0,
1523958373.657,,0.000000e+000,3.999681e+001,-2.105773e-004,0.000000e+000,3,9.911366e-001,0.000000e+000,,,,,,,,,,,,,,32,1,4.000000e+000,4.138947e-003,0.000000e+000,0,,0,
1523958449.040,,0.000000e+000,3.999836e+001,-2.125761e-004,0.000000e+000,3,9.914293e-001,0.000000e+000,,,,,,,,,,,,,,32,1,4.000000e+000,1.037598e-003,0.000000e+000,0,,0,
1523958525.199,,0.000000e+000,3.999526e+001,-2.138207e-004,0.000000e+000,3,9.915383e-001,0.000000e+000,,,,,,,,,,,,,,32,1,4.000000e+000,5.161285e-003,0.000000e+000,0,,0,
1523958602.335,,0.000000e+000,3.999887e+001,-2.149439e-004,0.000000e+000,3,9.912042e-001,0.000000e+000,,,,,,,,,,,,,,32,1,4.000000e+000,2.067566e-003,0.000000e+000,0,,0,
1523958677.306,,0.000000e+000,3.999680e+001,-2.159515e-004,0.000000e+000,3,9.914717e-001,0.000000e+000,,,,,,,,,,,,,,32,1,4.000000e+000,2.071381e-003,0.000000e+000,0,,0,
1523958751.547,,0.000000e+000,3.999836e+001,-2.167746e-004,0.000000e+000,3,9.913526e-001,0.000000e+000,,,,,,,,,,,,,,32,1,4.000000e+000,1.037598e-003,0.000000e+000,0,,0,
1523958827.418,,0.000000e+000,3.999784e+001,-2.174411e-004,0.000000e+000,3,9.915984e-001,0.000000e+000,,,,,,,,,,,,,,32,1,4.000000e+000,2.067566e-003,0.000000e+000,0,,0,
1523958901.684,,0.000000e+000,3.999887e+001,-2.181080e-004,0.000000e+000,3,9.916603e-001,0.000000e+000,,,,,,,,,,,,,,32,1,4.000000e+000,2.067566e-003,0.000000e+000,0,,0,
1523958977.813,,0.000000e+000,3.999732e+001,-2.188039e-004,0.000000e+000,3,9.915455e-001,0.000000e+000,,,,,,,,,,,,,,32,1,4.000000e+000,3.108978e-003,0.000000e+000,0,,0,
1523959052.434,,0.000000e+000,3.999733e+001,-2.193096e-004,0.000000e+000,3,9.916740e-001,0.000000e+000,,,,,,,,,,,,,,32,1,4.000000e+000,1.029968e-003,0.000000e+000,0,,0,
1523959128.463,,0.000000e+000,3.999836e+001,-2.197997e-004,0.000000e+000,3,9.915940e-001,0.000000e+000,,,,,,,,,,,,,,32,1,4.000000e+000,1.037598e-003,0.000000e+000,0,,0,
1523959204.051,,0.000000e+000,3.999888e+001,-2.202896e-004,0.000000e+000,3,9.915732e-001,0.000000e+000,,,,,,,,,,,,,,32,1,4.000000e+000,0.000000e+000,0.000000e+000,0,,0,
1523959281.287,,0.000000e+000,3.999836e+001,-2.207184e-004,0.000000e+000,3,9.917412e-001,0.000000e+000,,,,,,,,,,,,,,32,1,4.000000e+000,1.037598e-003,0.000000e+000,0,,0,
1523959355.714,,0.000000e+000,3.999836e+001,-2.210796e-004,0.000000e+000,3,9.915268e-001,0.000000e+000,,,,,,,,,,,,,,32,1,4.000000e+000,1.037598e-003,0.000000e+000,0,,0,
1523959429.407,,0.000000e+000,3.999680e+001,-2.214781e-004,0.000000e+000,3,9.916070e-001,0.000000e+000,,,,,,,,,,,,,,32,1,4.000000e+000,2.071381e-003,0.000000e+000,0,,0,
1523959505.858,,0.000000e+000,3.999836e+001,-2.218780e-004,0.000000e+000,3,9.915854e-001,0.000000e+000,,,,,,,,,,,,,,32,1,4.000000e+000,1.037598e-003,0.000000e+000,0,,0,
1523959581.887,,0.000000e+000,3.999991e+001,-2.222608e-004,0.000000e+000,3,9.916098e-001,0.000000e+000,,,,,,,,,,,,,,32,1,4.000000e+000,2.059937e-003,0.000000e+000,0,,0,
1523959657.180,,0.000000e+000,3.999784e+001,-2.225525e-004,0.000000e+000,3,9.914379e-001,0.000000e+000,,,,,,,,,,,,,,32,1,4.000000e+000,0.000000e+000,0.000000e+000,0,,0,
1523959735.269,,0.000000e+000,3.999887e+001,-2.228812e-004,0.000000e+000,3,9.915796e-001,0.000000e+000,,,,,,,,,,,,,,32,1,4.000000e+000,2.067566e-003,0.000000e+000,0,,0,
1523959811.245,,0.000000e+000,3.999836e+001,-2.231900e-004,0.000000e+000,3,9.916564e-001,0.000000e+000,,,,,,,,,,,,,,32,1,4.000000e+000,1.037598e-003,0.000000e+000,0,,0,
1523959888.064,,0.000000e+000,3.999939e+001,-2.234843e-004,0.000000e+000,3,9.916973e-001,0.000000e+000,,,,,,,,,,,,,,32,1,4.000000e+000,1.029968e-003,0.000000e+000,0,,0,
1523959966.055,,0.000000e+000,4.000042e+001,-2.237821e-004,0.000000e+000,3,9.914576e-001,0.000000e+000,,,,,,,,,,,,,,32,1,4.000000e+000,1.029968e-003,0.000000e+000,0,,0,
1523960043.586,,0.000000e+000,3.999991e+001,-2.239792e-004,0.000000e+000,3,9.918450e-001,0.000000e+000,,,,,,,,,,,,,,32,1,4.000000e+000,0.000000e+000,0.000000e+000,0,,0,
1523960119.467,,0.000000e+000,3.999939e+001,-2.243116e-004,0.000000e+000,3,9.915606e-001,0.000000e+000,,,,,,,,,,,,,,32,1,4.000000e+000,1.029968e-003,0.000000e+000,0,,0,
1523960195.566,,0.000000e+000,3.999939e+001,-2.245527e-004,0.000000e+000,3,9.916644e-001,0.000000e+000,,,,,,,,,,,,,,32,1,4.000000e+000,1.029968e-003,0.000000e+000,0,,0,
1523960269.229,,0.000000e+000,3.999836e+001,-2.247813e-004,0.000000e+000,3,9.915840e-001,0.000000e+000,,,,,,,,,,,,,,32,1,4.000000e+000,1.037598e-003,0.000000e+000,0,,0,
1523960345.483,,0.000000e+000,3.999939e+001,-2.249991e-004,0.000000e+000,3,9.917334e-001,0.000000e+000,,,,,,,,,,,,,,32,1,4.000000e+000,1.029968e-003,0.000000e+000,0,,0,
1523960420.412,,0.000000e+000,3.999939e+001,-2.252151e-004,0.000000e+000,3,9.915770e-001,0.000000e+000,,,,,,,,,,,,,,32,1,4.000000e+000,1.029968e-003,0.000000e+000,0,,0,
1523960497.653,,0.000000e+000,3.999888e+001,-2.254588e-004,0.000000e+000,3,9.916868e-001,0.000000e+000,,,,,,,,,,,,,,32,1,4.000000e+000,0.000000e+000,0.000000e+000,0,,0,
1523960574.776,,0.000000e+000,3.999784e+001,-2.256836e-004,0.000000e+000,3,9.914125e-001,0.000000e+000,,,,,,,,,,,,,,32,1,4.000000e+000,0.000000e+000,0.000000e+000,0,,0,
1523960652.105,,0.000000e+000,3.999888e+001,-2.259052e-004,0.000000e+000,3,9.916537e-001,0.000000e+000,,,,,,,,,,,,,,32,1,4.000000e+000,0.000000e+000,0.000000e+000,0,,0,
1523960729.186,,0.000000e+000,3.999836e+001,-2.260633e-004,0.000000e+000,3,9.915860e-001,0.000000e+000,,,,,,,,,,,,,,32,1,4.000000e+000,1.037598e-003,0.000000e+000,0,,0,
1523960803.295,,0.000000e+000,3.999836e+001,-2.262789e-004,0.000000e+000,3,9.916589e-001,0.000000e+000,,,,,,,,,,,,,,32,1,4.000000e+000,1.037598e-003,0.000000e+000,0,,0,
1523960902.286,,0.000000e+000,3.999939e+001,-2.843910e-005,0.000000e+000,3,9.626737e-001,0.000000e+000,,,,,,,,,,,,,,32,1,4.000000e+000,1.029968e-003,0.000000e+000,0,,0,
1523960978.252,,0.000000e+000,3.999784e+001,-2.213467e-005,0.000000e+000,3,9.503342e-001,0.000000e+000,,,,,,,,,,,,,,32,1,4.000000e+000,0.000000e+000,0.000000e+000,0,,0,
1523961051.361,,0.000000e+000,3.999836e+001,-1.943970e-005,0.000000e+000,3,9.433773e-001,0.000000e+000,,,,,,,,,,,,,,32,1,4.000000e+000,1.037598e-003,0.000000e+000,0,,0,
1523961127.952,,0.000000e+000,4.000042e+001,-1.764867e-005,0.000000e+000,3,9.367750e-001,0.000000e+000,,,,,,,,,,,,,,32,1,4.000000e+000,1.029968e-003,0.000000e+000,0,,0,
1523961204.173,,0.000000e+000,3.999887e+001,-1.640280e-005,0.000000e+000,3,9.320646e-001,0.000000e+000,,,,,,,,,,,,,,32,1,4.000000e+000,4.127502e-003,0.000000e+000,0,,0,
1523961281.414,,0.000000e+000,4.000042e+001,-1.530665e-005,0.000000e+000,3,9.280558e-001,0.000000e+000,,,,,,,,,,,,,,32,1,4.000000e+000,1.029968e-003,0.000000e+000,0,,0,
1523961356.390,,0.000000e+000,3.999939e+001,-1.452697e-005,0.000000e+000,3,9.245751e-001,0.000000e+000,,,,,,,,,,,,,,32,1,4.000000e+000,1.029968e-003,0.000000e+000,0,,0,
1523961431.667,,0.000000e+000,3.999784e+001,-1.385607e-005,0.000000e+000,3,9.229444e-001,0.000000e+000,,,,,,,,,,,,,,32,1,4.000000e+000,2.067566e-003,0.000000e+000,0,,0,
1523961508.228,,0.000000e+000,3.999836e+001,-1.325314e-005,0.000000e+000,3,9.171354e-001,0.000000e+000,,,,,,,,,,,,,,32,1,4.000000e+000,1.037598e-003,0.000000e+000,0,,0,
1523961585.141,,0.000000e+000,3.999939e+001,-1.271937e-005,0.000000e+000,3,9.119400e-001,0.000000e+000,,,,,,,,,,,,,,32,1,4.000000e+000,5.157471e-003,0.000000e+000,0,,0,
1523961660.252,,0.000000e+000,3.999939e+001,-1.229438e-005,0.000000e+000,3,9.091534e-001,0.000000e+000,,,,,,,,,,,,,,32,1,4.000000e+000,3.097534e-003,0.000000e+000,0,,0,
1523961737.278,,0.000000e+000,3.999939e+001,-1.193610e-005,0.000000e+000,3,9.077568e-001,0.000000e+000,,,,,,,,,,,,,,32,1,4.000000e+000,3.097534e-003,0.000000e+000,0,,0,
1523961813.835,,0.000000e+000,3.999991e+001,-1.146114e-005,0.000000e+000,3,9.037763e-001,0.000000e+000,,,,,,,,,,,,,,32,1,4.000000e+000,0.000000e+000,0.000000e+000,0,,0,
1523961891.553,,0.000000e+000,3.999836e+001,-1.110923e-005,0.000000e+000,3,9.021910e-001,0.000000e+000,,,,,,,,,,,,,,32,1,4.000000e+000,1.037598e-003,0.000000e+000,0,,0,
1523961966.769,,0.000000e+000,3.999888e+001,-1.083080e-005,0.000000e+000,3,8.993582e-001,0.000000e+000,,,,,,,,,,,,,,32,1,4.000000e+000,0.000000e+000,0.000000e+000,0,,0,
1523962042.271,,0.000000e+000,3.999836e+001,-1.054026e-005,0.000000e+000,3,8.930647e-001,0.000000e+000,,,,,,,,,,,,,,32,1,4.000000e+000,1.037598e-003,0.000000e+000,0,,0,
1523962118.969,,0.000000e+000,3.999888e+001,-1.029975e-005,0.000000e+000,3,8.933293e-001,0.000000e+000,,,,,,,,,,,,,,32,1,4.000000e+000,0.000000e+000,0.000000e+000,0,,0,
1523962195.528,,0.000000e+000,3.999836e+001,-1.005636e-005,0.000000e+000,3,8.938665e-001,0.000000e+000,,,,,,,,,,,,,,32,1,4.000000e+000,1.037598e-003,0.000000e+000,0,,0,
1523962271.634,,0.000000e+000,3.999733e+001,-9.815252e-006,0.000000e+000,3,8.892871e-001,0.000000e+000,,,,,,,,,,,,,,32,1,4.000000e+000,1.029968e-003,0.000000e+000,0,,0,
1523962348.605,,0.000000e+000,3.999990e+001,-9.633695e-006,0.000000e+000,3,8.873747e-001,0.000000e+000,,,,,,,,,,,,,,32,1,4.000000e+000,4.127502e-003,0.000000e+000,0,,0,
1523962423.541,,0.000000e+000,3.999939e+001,-9.457102e-006,0.000000e+000,3,8.841087e-001,0.000000e+000,,,,,,,,,,,,,,32,1,4.000000e+000,1.029968e-003,0.000000e+000,0,,0,
1523962497.062,,0.000000e+000,3.999784e+001,-9.268860e-006,0.000000e+000,3,8.825189e-001,0.000000e+000,,,,,,,,,,,,,,32,1,4.000000e+000,0.000000e+000,0.000000e+000,0,,0,
1523962573.771,,0.000000e+000,3.999990e+001,-9.093732e-006,0.000000e+000,3,8.787476e-001,0.000000e+000,,,,,,,,,,,,,,32,1,4.000000e+000,4.127502e-003,0.000000e+000,0,,0,
1523962649.439,,0.000000e+000,3.999991e+001,-8.945506e-006,0.000000e+000,3,8.773527e-001,0.000000e+000,,,,,,,,,,,,,,32,1,4.000000e+000,0.000000e+000,0.000000e+000,0,,0,
1523962724.443,,0.000000e+000,3.999836e+001,-8.774007e-006,0.000000e+000,3,8.733090e-001,0.000000e+000,,,,,,,,,,,,,,32,1,4.000000e+000,1.037598e-003,0.000000e+000,0,,0,
1523962800.549,,0.000000e+000,3.999836e+001,-8.669877e-006,0.000000e+000,3,8.758403e-001,0.000000e+000,,,,,,,,,,,,,,32,1,4.000000e+000,3.097534e-003,0.000000e+000,0,,0,
1523962876.990,,0.000000e+000,3.999733e+001,-8.480216e-006,0.000000e+000,3,8.690012e-001,0.000000e+000,,,,,,,,,,,,,,32,1,4.000000e+000,1.029968e-003,0.000000e+000,0,,0,
1523962954.231,,0.000000e+000,3.999939e+001,-8.443079e-006,0.000000e+000,3,8.711706e-001,0.000000e+000,,,,,,,,,,,,,,32,1,4.000000e+000,1.029968e-003,0.000000e+000,0,,0,
1523963029.677,,0.000000e+000,3.999887e+001,-8.280808e-006,0.000000e+000,3,8.690520e-001,0.000000e+000,,,,,,,,,,,,,,32,1,4.000000e+000,2.067566e-003,0.000000e+000,0,,0,
1523963107.379,,0.000000e+000,3.999836e+001,-8.114683e-006,0.000000e+000,3,8.632634e-001,0.000000e+000,,,,,,,,,,,,,,32,1,4.000000e+000,1.037598e-003,0.000000e+000,0,,0,
1523963184.232,,0.000000e+000,3.999888e+001,-8.078574e-006,0.000000e+000,3,8.688195e-001,0.000000e+000,,,,,,,,,,,,,,32,1,4.000000e+000,0.000000e+000,0.000000e+000,0,,0,
1523963260.543,,0.000000e+000,3.999887e+001,-7.942685e-006,0.000000e+000,3,8.625061e-001,0.000000e+000,,,,,,,,,,,,,,32,1,4.000000e+000,2.067566e-003,0.000000e+000,0,,0,
1523963335.889,,0.000000e+000,3.999939e+001,-7.861789e-006,0.000000e+000,3,8.583962e-001,0.000000e+000,,,,,,,,,,,,,,32,1,4.000000e+000,1.029968e-003,0.000000e+000,0,,0,
1523963413.216,,0.000000e+000,3.999939e+001,-7.765870e-006,0.000000e+000,3,8.545269e-001,0.000000e+000,,,,,,,,,,,,,,32,1,4.000000e+000,1.029968e-003,0.000000e+000,0,,0,
1523963488.252,,0.000000e+000,3.999939e+001,-7.671608e-006,0.000000e+000,3,8.626584e-001,0.000000e+000,,,,,,,,,,,,,,32,1,4.000000e+000,1.029968e-003,0.000000e+000,0,,0,
1523963563.798,,0.000000e+000,3.999784e+001,-7.558814e-006,0.000000e+000,3,8.609015e-001,0.000000e+000,,,,,,,,,,,,,,32,1,4.000000e+000,2.067566e-003,0.000000e+000,0,,0,
1523963641.524,,0.000000e+000,3.999990e+001,-7.458461e-006,0.000000e+000,3,8.517241e-001,0.000000e+000,,,,,,,,,,,,,,32,1,4.000000e+000,4.127502e-003,0.000000e+000,0,,0,
1523963716.563,,0.000000e+000,4.000042e+001,-7.384786e-006,0.000000e+000,3,8.527492e-001,0.000000e+000,,,,,,,,,,,,,,32,1,4.000000e+000,1.029968e-003,0.000000e+000,0,,0,
1523963792.534,,0.000000e+000,3.999939e+001,-7.308886e-006,0.000000e+000,3,8.516169e-001,0.000000e+000,,,,,,,,,,,,,,32,1,4.000000e+000,1.029968e-003,0.000000e+000,0,,0,
1523963870.897,,0.000000e+000,3.999991e+001,-7.221538e-006,0.000000e+000,3,8.466502e-001,0.000000e+000,,,,,,,,,,,,,,32,1,4.000000e+000,0.000000e+000,0.000000e+000,0,,0,
1523963947.116,,0.000000e+000,3.999577e+001,-7.178254e-006,0.000000e+000,3,8.486192e-001,0.000000e+000,,,,,,,,,,,,,,32,1,4.000000e+000,8.270264e-003,0.000000e+000,0,,0,
1523964023.890,,0.000000e+000,4.000042e+001,-7.052884e-006,0.000000e+000,3,8.459454e-001,0.000000e+000,,,,,,,,,,,,,,32,1,4.000000e+000,1.029968e-003,0.000000e+000,0,,0,
1523964101.771,,0.000000e+000,3.999887e+001,-6.969370e-006,0.000000e+000,3,8.478808e-001,0.000000e+000,,,,,,,,,,,,,,32,1,4.000000e+000,2.067566e-003,0.000000e+000,0,,0,
1523964178.629,,0.000000e+000,3.999939e+001,-6.941374e-006,0.000000e+000,3,8.417256e-001,0.000000e+000,,,,,,,,,,,,,,32,1,4.000000e+000,3.097534e-003,0.000000e+000,0,,0,
1523964254.463,,0.000000e+000,3.999888e+001,-6.870028e-006,0.000000e+000,3,8.365428e-001,0.000000e+000,,,,,,,,,,,,,,32,1,4.000000e+000,0.000000e+000,0.000000e+000,0,,0,
1523964331.617,,0.000000e+000,4.000198e+001,-6.779292e-006,0.000000e+000,3,8.380768e-001,0.000000e+000,,,,,,,,,,,,,,32,1,4.000000e+000,6.191254e-003,0.000000e+000,0,,0,
1523964410.195,,0.000000e+000,3.999939e+001,-6.727634e-006,0.000000e+000,3,8.390557e-001,0.000000e+000,,,,,,,,,,,,,,32,1,4.000000e+000,1.029968e-003,0.000000e+000,0,,0,
1523964486.946,,0.000000e+000,3.999939e+001,-6.694060e-006,0.000000e+000,3,8.390387e-001,0.000000e+000,,,,,,,,,,,,,,32,1,4.000000e+000,1.029968e-003,0.000000e+000,0,,0,
1523964563.582,,0.000000e+000,4.000042e+001,-6.637528e-006,0.000000e+000,3,8.368748e-001,0.000000e+000,,,,,,,,,,,,,,32,1,4.000000e+000,3.089905e-003,0.000000e+000,0,,0,
1523964639.464,,0.000000e+000,4.000042e+001,-6.621024e-006,0.000000e+000,3,8.398111e-001,0.000000e+000,,,,,,,,,,,,,,32,1,4.000000e+000,3.089905e-003,0.000000e+000,0,,0,
1523964715.725,,0.000000e+000,3.999887e+001,-6.493223e-006,0.000000e+000,3,8.294765e-001,0.000000e+000,,,,,,,,,,,,,,32,1,4.000000e+000,2.067566e-003,0.000000e+000,0,,0,
1523964789.451,,0.000000e+000,3.999888e+001,-6.558514e-006,0.000000e+000,3,8.395296e-001,0.000000e+000,,,,,,,,,,,,,,32,1,4.000000e+000,0.000000e+000,0.000000e+000,0,,0,
1523964866.322,,0.000000e+000,3.999939e+001,-6.450957e-006,0.000000e+000,3,8.304723e-001,0.000000e+000,,,,,,,,,,,,,,32,1,4.000000e+000,1.029968e-003,0.000000e+000,0,,0,
1523964942.433,,0.000000e+000,3.999939e+001,-6.407029e-006,0.000000e+000,3,8.341737e-001,0.000000e+000,,,,,,,,,,,,,,32,1,4.000000e+000,1.029968e-003,0.000000e+000,0,,0,
1523965017.847,,0.000000e+000,3.999991e+001,-6.365655e-006,0.000000e+000,3,8.296970e-001,0.000000e+000,,,,,,,,,,,,,,32,1,4.000000e+000,2.059937e-003,0.000000e+000,0,,0,
1523965095.125,,0.000000e+000,3.999991e+001,-6.359153e-006,0.000000e+000,3,8.297452e-001,0.000000e+000,,,,,,,,,,,,,,32,1,4.000000e+000,2.059937e-003,0.000000e+000,0,,0,
1523965172.486,,0.000000e+000,3.999939e+001,-6.270546e-006,0.000000e+000,3,8.257053e-001,0.000000e+000,,,,,,,,,,,,,,32,1,4.000000e+000,1.029968e-003,0.000000e+000,0,,0,
1523965248.333,,0.000000e+000,3.999939e+001,-6.283746e-006,0.000000e+000,3,8.291490e-001,0.000000e+000,,,,,,,,,,,,,,32,1,4.000000e+000,3.097534e-003,0.000000e+000,0,,0,
1523965325.221,,0.000000e+000,3.999991e+001,-6.208941e-006,0.000000e+000,3,8.214037e-001,0.000000e+000,,,,,,,,,,,,,,32,1,4.000000e+000,0.000000e+000,0.000000e+000,0,,0,
1523965401.985,,0.000000e+000,3.999887e+001,-6.180597e-006,0.000000e+000,3,8.251326e-001,0.000000e+000,,,,,,,,,,,,,,32,1,4.000000e+000,2.067566e-003,0.000000e+000,0,,0,
1523965479.543,,0.000000e+000,3.999732e+001,-6.143279e-006,0.000000e+000,3,8.178334e-001,0.000000e+000,,,,,,,,,,,,,,32,1,4.000000e+000,5.168915e-003,0.000000e+000,0,,0,
1523965555.197,,0.000000e+000,3.999836e+001,-6.084646e-006,0.000000e+000,3,8.213106e-001,0.000000e+000,,,,,,,,,,,,,,32,1,4.000000e+000,3.097534e-003,0.000000e+000,0,,0,
1523965631.628,,0.000000e+000,3.999732e+001,-6.073118e-006,0.000000e+000,3,8.213075e-001,0.000000e+000,,,,,,,,,,,,,,32,1,4.000000e+000,3.108978e-003,0.000000e+000,0,,0,
1523965706.387,,0.000000e+000,3.999887e+001,-6.114309e-006,0.000000e+000,3,8.275464e-001,0.000000e+000,,,,,,,,,,,,,,32,1,4.000000e+000,2.067566e-003,0.000000e+000,0,,0,
1523965783.470,,0.000000e+000,3.999836e+001,-6.009483e-006,0.000000e+000,3,8.201205e-001,0.000000e+000,,,,,,,,,,,,,,32,1,4.000000e+000,3.097534e-003,0.000000e+000,0,,0,
1523965861.181,,0.000000e+000,3.999888e+001,-6.018220e-006,0.000000e+000,3,8.163091e-001,0.000000e+000,,,,,,,,,,,,,,32,1,4.000000e+000,0.000000e+000,0.000000e+000,0,,0,
1523965938.155,,0.000000e+000,3.999784e+001,-5.960444e-006,0.000000e+000,3,8.139222e-001,0.000000e+000,,,,,,,,,,,,,,32,1,4.000000e+000,0.000000e+000,0.000000e+000,0,,0,
1523966014.894,,0.000000e+000,4.000042e+001,-5.924758e-006,0.000000e+000,3,8.167112e-001,0.000000e+000,,,,,,,,,,,,,,32,1,4.000000e+000,1.029968e-003,0.000000e+000,0,,0,
1523966090.495,,0.000000e+000,3.999991e+001,-5.934842e-006,0.000000e+000,3,8.094937e-001,0.000000e+000,,,,,,,,,,,,,,32,1,4.000000e+000,0.000000e+000,0.000000e+000,0,,0,
1523966165.949,,0.000000e+000,3.999835e+001,-5.915863e-006,0.000000e+000,3,8.175162e-001,0.000000e+000,,,,,,,,,,,,,,32,1,4.000000e+000,5.168915e-003,0.000000e+000,0,,0,
1523966240.465,,0.000000e+000,3.999939e+001,-5.888523e-006,0.000000e+000,3,8.177379e-001,0.000000e+000,,,,,,,,,,,,,,32,1,4.000000e+000,1.029968e-003,0.000000e+000,0,,0,
1523966253.520,,0.000000e+000,3.999888e+001,-5.877243e-006,0.000000e+000,3,8.222540e-001,0.000000e+000,,,,,,,,,,,,,,32,1,4.000000e+000,0.000000e+000,0.000000e+000,0,,0,