File: Experimental Raw Data/MFn1 VRM/Iterative Regression/MFn1_VRMac_35K_12000s_VRMde_35K.dc.dat
[Header]
TITLE,MPMS DC Measurement
BYAPP,MPMS Measurement,2.1,Summary
FILEOPENTIME, 1524001588.020000 4/17/2018, 3:46:28 PM

INFO, APPNAME, MPMS MultiVu Application, Revision 1.61,  Build 082

INFO, NAME, MFn1
INFO, WEIGHT, 1.000
INFO, AREA, 1.000
INFO, LENGTH, 1.000
INFO, SHAPE, 0
INFO, COMMENT,
INFO, SEQUENCE FILE: VRMac_35K_12000s_VRMde_35K.seq


INFO, BACKGROUND DATA FILE:, None


STARTUPAXIS,X,4,LINEAR,AUTO,0.000000,0.000000
STARTUPAXIS,Y1,5,LINEAR,AUTO,0.000000,0.000000


STARTUPGROUP,Longitudinal
FIELDGROUP,Longitudinal,1,2,3,4,5,6,7,8,9,15,16,17,18,27,28
FIELDGROUP,Transverse,1,2,3,4,10,11,12,13,14,19,20,21,22,27,28

PLOT_APPEARANCE,ALL,HORZ_GRID_ON,VERT_GRID_ON,MARKERS_AND_LINES

[Data]
Time,Comment,Field (Oe),Temperature (K),Long Moment (emu),Long Scan Std Dev,Long Algorithm,Long Reg Fit,Long Percent Error (%),Trans Moment (emu),Trans Scan Std Dev,Trans Algorithm,Trans Reg Fit,Trans Percent Error (%),Long Moment [w/o ABS] (emu),Long Scan Std Dev [w/o ABS],Long Reg Fit [w/o ABS],Long Percent Error [w/o ABS] (%),Trans Moment [w/o ABS] (emu),Trans Scan Std Dev [w/o ABS],Trans Reg Fit [w/o ABS],Trans Percent Error [w/o ABS] (%),Points per Scan,Scans per Measurement,Scan Length (cm),Delta Temp (K),Rot Position (deg),Error,EC Comp. Running,Using ABS,
1524001588.017,,0.000000e+000,3.499989e+001,-3.265131e-005,0.000000e+000,3,9.758497e-001,0.000000e+000,,,,,,,,,,,,,,32,1,4.000000e+000,2.342224e-003,0.000000e+000,0,,0,
1524001625.615,,0.000000e+000,3.499872e+001,-2.809584e-005,0.000000e+000,3,9.675055e-001,0.000000e+000,,,,,,,,,,,,,,32,1,4.000000e+000,0.000000e+000,0.000000e+000,0,,0,
1524001676.086,,0.000000e+000,3.500028e+001,-2.529112e-005,0.000000e+000,3,9.633018e-001,0.000000e+000,,,,,,,,,,,,,,32,1,4.000000e+000,3.120422e-003,0.000000e+000,0,,0,
1524001714.449,,0.000000e+000,3.499911e+001,-2.396191e-005,0.000000e+000,3,9.628359e-001,0.000000e+000,,,,,,,,,,,,,,32,1,4.000000e+000,7.820129e-004,0.000000e+000,0,,0,
1524001752.022,,0.000000e+000,3.499911e+001,-2.289374e-005,0.000000e+000,3,9.596870e-001,0.000000e+000,,,,,,,,,,,,,,32,1,4.000000e+000,7.820129e-004,0.000000e+000,0,,0,
1524001790.265,,0.000000e+000,3.499911e+001,-2.203499e-005,0.000000e+000,3,9.584050e-001,0.000000e+000,,,,,,,,,,,,,,32,1,4.000000e+000,7.820129e-004,0.000000e+000,0,,0,
1524001828.101,,0.000000e+000,3.499833e+001,-2.146961e-005,0.000000e+000,3,9.588816e-001,0.000000e+000,,,,,,,,,,,,,,32,1,4.000000e+000,7.781982e-004,0.000000e+000,0,,0,
1524001866.349,,0.000000e+000,3.499872e+001,-2.068816e-005,0.000000e+000,3,9.578409e-001,0.000000e+000,,,,,,,,,,,,,,32,1,4.000000e+000,0.000000e+000,0.000000e+000,0,,0,
1524001904.727,,0.000000e+000,3.499872e+001,-2.014836e-005,0.000000e+000,3,9.548357e-001,0.000000e+000,,,,,,,,,,,,,,32,1,4.000000e+000,0.000000e+000,0.000000e+000,0,,0,
1524001942.370,,0.000000e+000,3.499911e+001,-1.966221e-005,0.000000e+000,3,9.549775e-001,0.000000e+000,,,,,,,,,,,,,,32,1,4.000000e+000,7.820129e-004,0.000000e+000,0,,0,
1524001981.103,,0.000000e+000,3.500067e+001,-1.915813e-005,0.000000e+000,3,9.515215e-001,0.000000e+000,,,,,,,,,,,,,,32,1,4.000000e+000,7.820129e-004,0.000000e+000,0,,0,
1524002019.804,,0.000000e+000,3.499989e+001,-1.879937e-005,0.000000e+000,3,9.514048e-001,0.000000e+000,,,,,,,,,,,,,,32,1,4.000000e+000,7.781982e-004,0.000000e+000,0,,0,
1524002057.882,,0.000000e+000,3.499911e+001,-1.836806e-005,0.000000e+000,3,9.500108e-001,0.000000e+000,,,,,,,,,,,,,,32,1,4.000000e+000,7.820129e-004,0.000000e+000,0,,0,
1524002095.917,,0.000000e+000,3.499950e+001,-1.804407e-005,0.000000e+000,3,9.492748e-001,0.000000e+000,,,,,,,,,,,,,,32,1,4.000000e+000,0.000000e+000,0.000000e+000,0,,0,
1524002133.700,,0.000000e+000,3.499911e+001,-1.770936e-005,0.000000e+000,3,9.471464e-001,0.000000e+000,,,,,,,,,,,,,,32,1,4.000000e+000,7.820129e-004,0.000000e+000,0,,0,
1524002172.551,,0.000000e+000,3.499911e+001,-1.743473e-005,0.000000e+000,3,9.494253e-001,0.000000e+000,,,,,,,,,,,,,,32,1,4.000000e+000,7.820129e-004,0.000000e+000,0,,0,
1524002210.981,,0.000000e+000,3.499872e+001,-1.714394e-005,0.000000e+000,3,9.466550e-001,0.000000e+000,,,,,,,,,,,,,,32,1,4.000000e+000,0.000000e+000,0.000000e+000,0,,0,
1524002249.084,,0.000000e+000,3.499950e+001,-1.689680e-005,0.000000e+000,3,9.438778e-001,0.000000e+000,,,,,,,,,,,,,,32,1,4.000000e+000,1.560211e-003,0.000000e+000,0,,0,
1524002286.895,,0.000000e+000,3.499950e+001,-1.667306e-005,0.000000e+000,3,9.449118e-001,0.000000e+000,,,,,,,,,,,,,,32,1,4.000000e+000,0.000000e+000,0.000000e+000,0,,0,
1524002324.518,,0.000000e+000,3.499793e+001,-1.644864e-005,0.000000e+000,3,9.480580e-001,0.000000e+000,,,,,,,,,,,,,,32,1,4.000000e+000,4.688263e-003,0.000000e+000,0,,0,
1524002362.241,,0.000000e+000,3.499950e+001,-1.621367e-005,0.000000e+000,3,9.440723e-001,0.000000e+000,,,,,,,,,,,,,,32,1,4.000000e+000,0.000000e+000,0.000000e+000,0,,0,
1524002400.252,,0.000000e+000,3.499833e+001,-1.603646e-005,0.000000e+000,3,9.432456e-001,0.000000e+000,,,,,,,,,,,,,,32,1,4.000000e+000,7.781982e-004,0.000000e+000,0,,0,
1524002438.195,,0.000000e+000,3.499872e+001,-1.582342e-005,0.000000e+000,3,9.458180e-001,0.000000e+000,,,,,,,,,,,,,,32,1,4.000000e+000,0.000000e+000,0.000000e+000,0,,0,
1524002476.343,,0.000000e+000,3.499950e+001,-1.558827e-005,0.000000e+000,3,9.427434e-001,0.000000e+000,,,,,,,,,,,,,,32,1,4.000000e+000,0.000000e+000,0.000000e+000,0,,0,
1524002514.436,,0.000000e+000,3.499989e+001,-1.542606e-005,0.000000e+000,3,9.419761e-001,0.000000e+000,,,,,,,,,,,,,,32,1,4.000000e+000,7.781982e-004,0.000000e+000,0,,0,
1524002552.386,,0.000000e+000,3.499950e+001,-1.520997e-005,0.000000e+000,3,9.402645e-001,0.000000e+000,,,,,,,,,,,,,,32,1,4.000000e+000,0.000000e+000,0.000000e+000,0,,0,
1524002590.512,,0.000000e+000,3.499911e+001,-1.506560e-005,0.000000e+000,3,9.394544e-001,0.000000e+000,,,,,,,,,,,,,,32,1,4.000000e+000,7.820129e-004,0.000000e+000,0,,0,
1524002628.575,,0.000000e+000,3.499950e+001,-1.490290e-005,0.000000e+000,3,9.392206e-001,0.000000e+000,,,,,,,,,,,,,,32,1,4.000000e+000,1.560211e-003,0.000000e+000,0,,0,
1524002666.188,,0.000000e+000,3.499989e+001,-1.472136e-005,0.000000e+000,3,9.407802e-001,0.000000e+000,,,,,,,,,,,,,,32,1,4.000000e+000,7.781982e-004,0.000000e+000,0,,0,
1524002704.619,,0.000000e+000,3.499911e+001,-1.460521e-005,0.000000e+000,3,9.373682e-001,0.000000e+000,,,,,,,,,,,,,,32,1,4.000000e+000,7.820129e-004,0.000000e+000,0,,0,
1524002742.702,,0.000000e+000,3.499911e+001,-1.443811e-005,0.000000e+000,3,9.368308e-001,0.000000e+000,,,,,,,,,,,,,,32,1,4.000000e+000,7.820129e-004,0.000000e+000,0,,0,
1524002780.305,,0.000000e+000,3.499833e+001,-1.436528e-005,0.000000e+000,3,9.367837e-001,0.000000e+000,,,,,,,,,,,,,,32,1,4.000000e+000,7.781982e-004,0.000000e+000,0,,0,
1524002818.405,,0.000000e+000,3.499989e+001,-1.413972e-005,0.000000e+000,3,9.368888e-001,0.000000e+000,,,,,,,,,,,,,,32,1,4.000000e+000,7.781982e-004,0.000000e+000,0,,0,
1524002856.793,,0.000000e+000,3.499911e+001,-1.400096e-005,0.000000e+000,3,9.360296e-001,0.000000e+000,,,,,,,,,,,,,,32,1,4.000000e+000,7.820129e-004,0.000000e+000,0,,0,
1524002893.296,,0.000000e+000,3.499872e+001,-1.389184e-005,0.000000e+000,3,9.352544e-001,0.000000e+000,,,,,,,,,,,,,,32,1,4.000000e+000,1.560211e-003,0.000000e+000,0,,0,
1524002931.339,,0.000000e+000,3.499871e+001,-1.370965e-005,0.000000e+000,3,9.367735e-001,0.000000e+000,,,,,,,,,,,,,,32,1,4.000000e+000,3.128052e-003,0.000000e+000,0,,0,
1524002969.217,,0.000000e+000,3.499950e+001,-1.364093e-005,0.000000e+000,3,9.342366e-001,0.000000e+000,,,,,,,,,,,,,,32,1,4.000000e+000,1.560211e-003,0.000000e+000,0,,0,
1524003006.826,,0.000000e+000,3.500028e+001,-1.353754e-005,0.000000e+000,3,9.340985e-001,0.000000e+000,,,,,,,,,,,,,,32,1,4.000000e+000,3.120422e-003,0.000000e+000,0,,0,
1524003044.864,,0.000000e+000,3.499833e+001,-1.340712e-005,0.000000e+000,3,9.322573e-001,0.000000e+000,,,,,,,,,,,,,,32,1,4.000000e+000,2.349854e-003,0.000000e+000,0,,0,
1524003084.062,,0.000000e+000,3.499911e+001,-1.328966e-005,0.000000e+000,3,9.329617e-001,0.000000e+000,,,,,,,,,,,,,,32,1,4.000000e+000,7.820129e-004,0.000000e+000,0,,0,
1524003122.175,,0.000000e+000,3.499911e+001,-1.317390e-005,0.000000e+000,3,9.314348e-001,0.000000e+000,,,,,,,,,,,,,,32,1,4.000000e+000,7.820129e-004,0.000000e+000,0,,0,
1524003160.228,,0.000000e+000,3.499950e+001,-1.308085e-005,0.000000e+000,3,9.328762e-001,0.000000e+000,,,,,,,,,,,,,,32,1,4.000000e+000,1.560211e-003,0.000000e+000,0,,0,
1524003197.931,,0.000000e+000,3.500106e+001,-1.299860e-005,0.000000e+000,3,9.296207e-001,0.000000e+000,,,,,,,,,,,,,,32,1,4.000000e+000,3.128052e-003,0.000000e+000,0,,0,
1524003235.819,,0.000000e+000,3.499950e+001,-1.289677e-005,0.000000e+000,3,9.324127e-001,0.000000e+000,,,,,,,,,,,,,,32,1,4.000000e+000,0.000000e+000,0.000000e+000,0,,0,
1524003273.927,,0.000000e+000,3.499872e+001,-1.277909e-005,0.000000e+000,3,9.300358e-001,0.000000e+000,,,,,,,,,,,,,,32,1,4.000000e+000,0.000000e+000,0.000000e+000,0,,0,
1524003311.940,,0.000000e+000,3.499950e+001,-1.267025e-005,0.000000e+000,3,9.291711e-001,0.000000e+000,,,,,,,,,,,,,,32,1,4.000000e+000,0.000000e+000,0.000000e+000,0,,0,
1524003350.811,,0.000000e+000,3.499872e+001,-1.257672e-005,0.000000e+000,3,9.274523e-001,0.000000e+000,,,,,,,,,,,,,,32,1,4.000000e+000,1.560211e-003,0.000000e+000,0,,0,
1524003388.831,,0.000000e+000,3.499911e+001,-1.250090e-005,0.000000e+000,3,9.276114e-001,0.000000e+000,,,,,,,,,,,,,,32,1,4.000000e+000,7.820129e-004,0.000000e+000,0,,0,
1524003426.984,,0.000000e+000,3.499950e+001,-1.240213e-005,0.000000e+000,3,9.292808e-001,0.000000e+000,,,,,,,,,,,,,,32,1,4.000000e+000,0.000000e+000,0.000000e+000,0,,0,
1524003464.540,,0.000000e+000,3.500106e+001,-1.230249e-005,0.000000e+000,3,9.251835e-001,0.000000e+000,,,,,,,,,,,,,,32,1,4.000000e+000,1.560211e-003,0.000000e+000,0,,0,
1524003502.603,,0.000000e+000,3.499950e+001,-1.224513e-005,0.000000e+000,3,9.254807e-001,0.000000e+000,,,,,,,,,,,,,,32,1,4.000000e+000,1.560211e-003,0.000000e+000,0,,0,
1524003541.811,,0.000000e+000,3.499872e+001,-1.213104e-005,0.000000e+000,3,9.264644e-001,0.000000e+000,,,,,,,,,,,,,,32,1,4.000000e+000,0.000000e+000,0.000000e+000,0,,0,
1524003579.996,,0.000000e+000,3.499911e+001,-1.207249e-005,0.000000e+000,3,9.221687e-001,0.000000e+000,,,,,,,,,,,,,,32,1,4.000000e+000,7.820129e-004,0.000000e+000,0,,0,
1524003618.282,,0.000000e+000,3.499989e+001,-1.194000e-005,0.000000e+000,3,9.200553e-001,0.000000e+000,,,,,,,,,,,,,,32,1,4.000000e+000,7.781982e-004,0.000000e+000,0,,0,
1524003655.595,,0.000000e+000,3.499911e+001,-1.188770e-005,0.000000e+000,3,9.250920e-001,0.000000e+000,,,,,,,,,,,,,,32,1,4.000000e+000,7.820129e-004,0.000000e+000,0,,0,
1524003694.081,,0.000000e+000,3.499950e+001,-1.169712e-005,0.000000e+000,3,9.249807e-001,0.000000e+000,,,,,,,,,,,,,,32,1,4.000000e+000,0.000000e+000,0.000000e+000,0,,0,
1524003732.409,,0.000000e+000,3.499872e+001,-1.174857e-005,0.000000e+000,3,9.238252e-001,0.000000e+000,,,,,,,,,,,,,,32,1,4.000000e+000,0.000000e+000,0.000000e+000,0,,0,
1524003769.809,,0.000000e+000,3.499950e+001,-1.169387e-005,0.000000e+000,3,9.264036e-001,0.000000e+000,,,,,,,,,,,,,,32,1,4.000000e+000,0.000000e+000,0.000000e+000,0,,0,
1524003807.832,,0.000000e+000,3.499989e+001,-1.163492e-005,0.000000e+000,3,9.172927e-001,0.000000e+000,,,,,,,,,,,,,,32,1,4.000000e+000,7.781982e-004,0.000000e+000,0,,0,
1524003845.663,,0.000000e+000,3.499989e+001,-1.137174e-005,0.000000e+000,3,9.209961e-001,0.000000e+000,,,,,,,,,,,,,,32,1,4.000000e+000,7.781982e-004,0.000000e+000,0,,0,
1524003883.166,,0.000000e+000,3.499950e+001,-1.147293e-005,0.000000e+000,3,9.181971e-001,0.000000e+000,,,,,,,,,,,,,,32,1,4.000000e+000,0.000000e+000,0.000000e+000,0,,0,
1524003921.264,,0.000000e+000,3.499950e+001,-1.145721e-005,0.000000e+000,3,9.213412e-001,0.000000e+000,,,,,,,,,,,,,,32,1,4.000000e+000,1.560211e-003,0.000000e+000,0,,0,
1524003959.335,,0.000000e+000,3.499950e+001,-1.136834e-005,0.000000e+000,3,9.173226e-001,0.000000e+000,,,,,,,,,,,,,,32,1,4.000000e+000,0.000000e+000,0.000000e+000,0,,0,
1524003997.348,,0.000000e+000,3.500028e+001,-1.115843e-005,0.000000e+000,3,9.156510e-001,0.000000e+000,,,,,,,,,,,,,,32,1,4.000000e+000,0.000000e+000,0.000000e+000,0,,0,
1524004035.436,,0.000000e+000,3.499872e+001,-1.104154e-005,0.000000e+000,3,9.193014e-001,0.000000e+000,,,,,,,,,,,,,,32,1,4.000000e+000,0.000000e+000,0.000000e+000,0,,0,
1524004073.449,,0.000000e+000,3.499911e+001,-1.114856e-005,0.000000e+000,3,9.206412e-001,0.000000e+000,,,,,,,,,,,,,,32,1,4.000000e+000,7.820129e-004,0.000000e+000,0,,0,
1524004111.537,,0.000000e+000,3.499989e+001,-1.101848e-005,0.000000e+000,3,9.179007e-001,0.000000e+000,,,,,,,,,,,,,,32,1,4.000000e+000,7.781982e-004,0.000000e+000,0,,0,
1524004148.955,,0.000000e+000,3.499911e+001,-1.096633e-005,0.000000e+000,3,9.173767e-001,0.000000e+000,,,,,,,,,,,,,,32,1,4.000000e+000,7.820129e-004,0.000000e+000,0,,0,
1524004186.318,,0.000000e+000,3.499950e+001,-1.084119e-005,0.000000e+000,3,9.161927e-001,0.000000e+000,,,,,,,,,,,,,,32,1,4.000000e+000,0.000000e+000,0.000000e+000,0,,0,
1524004224.376,,0.000000e+000,3.499911e+001,-1.086400e-005,0.000000e+000,3,9.198546e-001,0.000000e+000,,,,,,,,,,,,,,32,1,4.000000e+000,7.820129e-004,0.000000e+000,0,,0,
1524004262.431,,0.000000e+000,3.499950e+001,-1.082070e-005,0.000000e+000,3,9.164993e-001,0.000000e+000,,,,,,,,,,,,,,32,1,4.000000e+000,0.000000e+000,0.000000e+000,0,,0,
1524004300.882,,0.000000e+000,3.499911e+001,-1.067319e-005,0.000000e+000,3,9.114541e-001,0.000000e+000,,,,,,,,,,,,,,32,1,4.000000e+000,7.820129e-004,0.000000e+000,0,,0,
1524004338.018,,0.000000e+000,3.499950e+001,-1.070180e-005,0.000000e+000,3,9.169894e-001,0.000000e+000,,,,,,,,,,,,,,32,1,4.000000e+000,0.000000e+000,0.000000e+000,0,,0,
1524004376.761,,0.000000e+000,3.499989e+001,-1.063636e-005,0.000000e+000,3,9.164690e-001,0.000000e+000,,,,,,,,,,,,,,32,1,4.000000e+000,2.342224e-003,0.000000e+000,0,,0,
1524004414.814,,0.000000e+000,3.500067e+001,-1.062784e-005,0.000000e+000,3,9.105254e-001,0.000000e+000,,,,,,,,,,,,,,32,1,4.000000e+000,3.910065e-003,0.000000e+000,0,,0,
1524004452.647,,0.000000e+000,3.499872e+001,-1.051685e-005,0.000000e+000,3,9.136781e-001,0.000000e+000,,,,,,,,,,,,,,32,1,4.000000e+000,0.000000e+000,0.000000e+000,0,,0,
1524004490.717,,0.000000e+000,3.499989e+001,-1.058355e-005,0.000000e+000,3,9.116389e-001,0.000000e+000,,,,,,,,,,,,,,32,1,4.000000e+000,7.781982e-004,0.000000e+000,0,,0,
1524004528.760,,0.000000e+000,3.499872e+001,-1.043090e-005,0.000000e+000,3,9.145312e-001,0.000000e+000,,,,,,,,,,,,,,32,1,4.000000e+000,0.000000e+000,0.000000e+000,0,,0,
1524004566.353,,0.000000e+000,3.499911e+001,-1.038089e-005,0.000000e+000,3,9.179139e-001,0.000000e+000,,,,,,,,,,,,,,32,1,4.000000e+000,7.820129e-004,0.000000e+000,0,,0,
1524004603.642,,0.000000e+000,3.499833e+001,-1.028493e-005,0.000000e+000,3,9.111708e-001,0.000000e+000,,,,,,,,,,,,,,32,1,4.000000e+000,7.781982e-004,0.000000e+000,0,,0,
1524004641.697,,0.000000e+000,3.499872e+001,-1.024239e-005,0.000000e+000,3,9.127923e-001,0.000000e+000,,,,,,,,,,,,,,32,1,4.000000e+000,0.000000e+000,0.000000e+000,0,,0,
1524004680.305,,0.000000e+000,3.499872e+001,-1.018963e-005,0.000000e+000,3,9.071508e-001,0.000000e+000,,,,,,,,,,,,,,32,1,4.000000e+000,0.000000e+000,0.000000e+000,0,,0,
1524004717.301,,0.000000e+000,3.499950e+001,-1.015690e-005,0.000000e+000,3,9.111790e-001,0.000000e+000,,,,,,,,,,,,,,32,1,4.000000e+000,0.000000e+000,0.000000e+000,0,,0,
1524004755.366,,0.000000e+000,3.499872e+001,-1.009745e-005,0.000000e+000,3,9.136481e-001,0.000000e+000,,,,,,,,,,,,,,32,1,4.000000e+000,0.000000e+000,0.000000e+000,0,,0,
1524004793.389,,0.000000e+000,3.499950e+001,-1.003642e-005,0.000000e+000,3,9.117622e-001,0.000000e+000,,,,,,,,,,,,,,32,1,4.000000e+000,0.000000e+000,0.000000e+000,0,,0,
1524004831.407,,0.000000e+000,3.499950e+001,-1.004992e-005,0.000000e+000,3,9.135135e-001,0.000000e+000,,,,,,,,,,,,,,32,1,4.000000e+000,1.560211e-003,0.000000e+000,0,,0,
1524004869.000,,0.000000e+000,3.499950e+001,-9.965214e-006,0.000000e+000,3,9.144549e-001,0.000000e+000,,,,,,,,,,,,,,32,1,4.000000e+000,0.000000e+000,0.000000e+000,0,,0,
1524004907.601,,0.000000e+000,3.499872e+001,-9.964792e-006,0.000000e+000,3,9.158357e-001,0.000000e+000,,,,,,,,,,,,,,32,1,4.000000e+000,0.000000e+000,0.000000e+000,0,,0,
1524004945.051,,0.000000e+000,3.499950e+001,-9.868014e-006,0.000000e+000,3,9.098598e-001,0.000000e+000,,,,,,,,,,,,,,32,1,4.000000e+000,1.560211e-003,0.000000e+000,0,,0,
1524004982.819,,0.000000e+000,3.499950e+001,-9.791176e-006,0.000000e+000,3,9.092827e-001,0.000000e+000,,,,,,,,,,,,,,32,1,4.000000e+000,0.000000e+000,0.000000e+000,0,,0,
1524005021.848,,0.000000e+000,3.499872e+001,-9.605784e-006,0.000000e+000,3,9.062189e-001,0.000000e+000,,,,,,,,,,,,,,32,1,4.000000e+000,0.000000e+000,0.000000e+000,0,,0,
1524005060.358,,0.000000e+000,3.499950e+001,-9.714302e-006,0.000000e+000,3,9.048163e-001,0.000000e+000,,,,,,,,,,,,,,32,1,4.000000e+000,0.000000e+000,0.000000e+000,0,,0,
1524005098.859,,0.000000e+000,3.499833e+001,-9.725822e-006,0.000000e+000,3,9.089806e-001,0.000000e+000,,,,,,,,,,,,,,32,1,4.000000e+000,2.349854e-003,0.000000e+000,0,,0,
1524005137.034,,0.000000e+000,3.499911e+001,-9.615391e-006,0.000000e+000,3,9.049851e-001,0.000000e+000,,,,,,,,,,,,,,32,1,4.000000e+000,7.820129e-004,0.000000e+000,0,,0,
1524005175.597,,0.000000e+000,3.499911e+001,-9.415286e-006,0.000000e+000,3,9.041226e-001,0.000000e+000,,,,,,,,,,,,,,32,1,4.000000e+000,7.820129e-004,0.000000e+000,0,,0,
1524005213.768,,0.000000e+000,3.499872e+001,-9.530005e-006,0.000000e+000,3,9.064194e-001,0.000000e+000,,,,,,,,,,,,,,32,1,4.000000e+000,0.000000e+000,0.000000e+000,0,,0,
1524005252.059,,0.000000e+000,3.499794e+001,-9.484752e-006,0.000000e+000,3,9.052691e-001,0.000000e+000,,,,,,,,,,,,,,32,1,4.000000e+000,0.000000e+000,0.000000e+000,0,,0,
1524005290.032,,0.000000e+000,3.499911e+001,-9.418557e-006,0.000000e+000,3,9.015235e-001,0.000000e+000,,,,,,,,,,,,,,32,1,4.000000e+000,7.820129e-004,0.000000e+000,0,,0,
1524005328.090,,0.000000e+000,3.499989e+001,-9.400776e-006,0.000000e+000,3,9.018087e-001,0.000000e+000,,,,,,,,,,,,,,32,1,4.000000e+000,7.781982e-004,0.000000e+000,0,,0,
1524005366.313,,0.000000e+000,3.499911e+001,-9.356972e-006,0.000000e+000,3,9.034392e-001,0.000000e+000,,,,,,,,,,,,,,32,1,4.000000e+000,7.820129e-004,0.000000e+000,0,,0,
1524005404.081,,0.000000e+000,3.499989e+001,-9.410703e-006,0.000000e+000,3,9.082930e-001,0.000000e+000,,,,,,,,,,,,,,32,1,4.000000e+000,7.781982e-004,0.000000e+000,0,,0,
1524005441.971,,0.000000e+000,3.499911e+001,-9.308807e-006,0.000000e+000,3,9.006889e-001,0.000000e+000,,,,,,,,,,,,,,32,1,4.000000e+000,7.820129e-004,0.000000e+000,0,,0,
1524005479.972,,0.000000e+000,3.500028e+001,-9.278125e-006,0.000000e+000,3,9.066645e-001,0.000000e+000,,,,,,,,,,,,,,32,1,4.000000e+000,1.560211e-003,0.000000e+000,0,,0,
1524005518.067,,0.000000e+000,3.499754e+001,-9.227972e-006,0.000000e+000,3,9.027946e-001,0.000000e+000,,,,,,,,,,,,,,32,1,4.000000e+000,2.349854e-003,0.000000e+000,0,,0,
1524005556.125,,0.000000e+000,3.500028e+001,-9.190027e-006,0.000000e+000,3,9.022380e-001,0.000000e+000,,,,,,,,,,,,,,32,1,4.000000e+000,3.120422e-003,0.000000e+000,0,,0,
1524005593.506,,0.000000e+000,3.500067e+001,-9.159572e-006,0.000000e+000,3,9.018620e-001,0.000000e+000,,,,,,,,,,,,,,32,1,4.000000e+000,2.338409e-003,0.000000e+000,0,,0,
1524005630.797,,0.000000e+000,3.499989e+001,-9.164472e-006,0.000000e+000,3,9.008408e-001,0.000000e+000,,,,,,,,,,,,,,32,1,4.000000e+000,2.342224e-003,0.000000e+000,0,,0,
1524005668.930,,0.000000e+000,3.499911e+001,-9.099973e-006,0.000000e+000,3,9.079959e-001,0.000000e+000,,,,,,,,,,,,,,32,1,4.000000e+000,7.820129e-004,0.000000e+000,0,,0,
1524005706.930,,0.000000e+000,3.499950e+001,-9.148619e-006,0.000000e+000,3,8.924988e-001,0.000000e+000,,,,,,,,,,,,,,32,1,4.000000e+000,1.560211e-003,0.000000e+000,0,,0,
1524005744.968,,0.000000e+000,3.499950e+001,-8.864143e-006,0.000000e+000,3,8.980918e-001,0.000000e+000,,,,,,,,,,,,,,32,1,4.000000e+000,1.560211e-003,0.000000e+000,0,,0,
1524005783.284,,0.000000e+000,3.499872e+001,-8.980496e-006,0.000000e+000,3,8.946307e-001,0.000000e+000,,,,,,,,,,,,,,32,1,4.000000e+000,0.000000e+000,0.000000e+000,0,,0,
1524005821.189,,0.000000e+000,3.499950e+001,-8.978655e-006,0.000000e+000,3,8.998149e-001,0.000000e+000,,,,,,,,,,,,,,32,1,4.000000e+000,0.000000e+000,0.000000e+000,0,,0,
1524005859.215,,0.000000e+000,3.499833e+001,-8.883683e-006,0.000000e+000,3,8.947114e-001,0.000000e+000,,,,,,,,,,,,,,32,1,4.000000e+000,7.781982e-004,0.000000e+000,0,,0,
1524005897.501,,0.000000e+000,3.499950e+001,-8.886574e-006,0.000000e+000,3,8.990483e-001,0.000000e+000,,,,,,,,,,,,,,32,1,4.000000e+000,0.000000e+000,0.000000e+000,0,,0,
1524005935.886,,0.000000e+000,3.499989e+001,-8.888004e-006,0.000000e+000,3,8.993317e-001,0.000000e+000,,,,,,,,,,,,,,32,1,4.000000e+000,7.781982e-004,0.000000e+000,0,,0,
1524005973.674,,0.000000e+000,3.499911e+001,-8.831748e-006,0.000000e+000,3,8.998060e-001,0.000000e+000,,,,,,,,,,,,,,32,1,4.000000e+000,7.820129e-004,0.000000e+000,0,,0,
1524006012.145,,0.000000e+000,3.499950e+001,-8.727236e-006,0.000000e+000,3,8.948367e-001,0.000000e+000,,,,,,,,,,,,,,32,1,4.000000e+000,1.560211e-003,0.000000e+000,0,,0,
1524006050.205,,0.000000e+000,3.499872e+001,-8.733238e-006,0.000000e+000,3,8.920844e-001,0.000000e+000,,,,,,,,,,,,,,32,1,4.000000e+000,0.000000e+000,0.000000e+000,0,,0,
1524006088.738,,0.000000e+000,3.499950e+001,-8.652695e-006,0.000000e+000,3,8.954490e-001,0.000000e+000,,,,,,,,,,,,,,32,1,4.000000e+000,0.000000e+000,0.000000e+000,0,,0,
1524006125.996,,0.000000e+000,3.499911e+001,-8.670150e-006,0.000000e+000,3,8.938144e-001,0.000000e+000,,,,,,,,,,,,,,32,1,4.000000e+000,7.820129e-004,0.000000e+000,0,,0,
1524006164.757,,0.000000e+000,3.499989e+001,-8.648605e-006,0.000000e+000,3,8.982076e-001,0.000000e+000,,,,,,,,,,,,,,32,1,4.000000e+000,7.781982e-004,0.000000e+000,0,,0,
1524006202.567,,0.000000e+000,3.499950e+001,-8.627778e-006,0.000000e+000,3,8.952350e-001,0.000000e+000,,,,,,,,,,,,,,32,1,4.000000e+000,0.000000e+000,0.000000e+000,0,,0,
1524006240.233,,0.000000e+000,3.499872e+001,-8.610364e-006,0.000000e+000,3,8.920629e-001,0.000000e+000,,,,,,,,,,,,,,32,1,4.000000e+000,1.560211e-003,0.000000e+000,0,,0,
1524006278.254,,0.000000e+000,3.499911e+001,-8.566128e-006,0.000000e+000,3,8.952728e-001,0.000000e+000,,,,,,,,,,,,,,32,1,4.000000e+000,7.820129e-004,0.000000e+000,0,,0,
1524006315.907,,0.000000e+000,3.499872e+001,-8.532427e-006,0.000000e+000,3,8.917740e-001,0.000000e+000,,,,,,,,,,,,,,32,1,4.000000e+000,0.000000e+000,0.000000e+000,0,,0,
1524006353.697,,0.000000e+000,3.499989e+001,-8.468359e-006,0.000000e+000,3,8.898208e-001,0.000000e+000,,,,,,,,,,,,,,32,1,4.000000e+000,7.781982e-004,0.000000e+000,0,,0,
1524006391.375,,0.000000e+000,3.500028e+001,-8.433907e-006,0.000000e+000,3,8.908670e-001,0.000000e+000,,,,,,,,,,,,,,32,1,4.000000e+000,3.120422e-003,0.000000e+000,0,,0,
1524006428.976,,0.000000e+000,3.499989e+001,-8.528854e-006,0.000000e+000,3,9.005615e-001,0.000000e+000,,,,,,,,,,,,,,32,1,4.000000e+000,7.781982e-004,0.000000e+000,0,,0,
1524006467.031,,0.000000e+000,3.499911e+001,-8.490930e-006,0.000000e+000,3,8.924407e-001,0.000000e+000,,,,,,,,,,,,,,32,1,4.000000e+000,7.820129e-004,0.000000e+000,0,,0,
1524006505.097,,0.000000e+000,3.499911e+001,-8.390281e-006,0.000000e+000,3,8.879821e-001,0.000000e+000,,,,,,,,,,,,,,32,1,4.000000e+000,7.820129e-004,0.000000e+000,0,,0,
1524006543.137,,0.000000e+000,3.499872e+001,-8.255675e-006,0.000000e+000,3,8.870219e-001,0.000000e+000,,,,,,,,,,,,,,32,1,4.000000e+000,1.560211e-003,0.000000e+000,0,,0,
1524006581.193,,0.000000e+000,3.499833e+001,-8.155741e-006,0.000000e+000,3,8.905558e-001,0.000000e+000,,,,,,,,,,,,,,32,1,4.000000e+000,2.349854e-003,0.000000e+000,0,,0,
1524006619.251,,0.000000e+000,3.499950e+001,-8.195681e-006,0.000000e+000,3,8.936591e-001,0.000000e+000,,,,,,,,,,,,,,32,1,4.000000e+000,0.000000e+000,0.000000e+000,0,,0,
1524006657.792,,0.000000e+000,3.499950e+001,-8.189485e-006,0.000000e+000,3,8.848741e-001,0.000000e+000,,,,,,,,,,,,,,32,1,4.000000e+000,3.120422e-003,0.000000e+000,0,,0,
1524006695.375,,0.000000e+000,3.499911e+001,-8.240568e-006,0.000000e+000,3,8.807392e-001,0.000000e+000,,,,,,,,,,,,,,32,1,4.000000e+000,7.820129e-004,0.000000e+000,0,,0,
1524006733.693,,0.000000e+000,3.499989e+001,-8.240055e-006,0.000000e+000,3,8.937441e-001,0.000000e+000,,,,,,,,,,,,,,32,1,4.000000e+000,7.781982e-004,0.000000e+000,0,,0,
1524006772.301,,0.000000e+000,3.499989e+001,-8.191408e-006,0.000000e+000,3,8.941697e-001,0.000000e+000,,,,,,,,,,,,,,32,1,4.000000e+000,7.781982e-004,0.000000e+000,0,,0,
1524006810.129,,0.000000e+000,3.499950e+001,-8.153987e-006,0.000000e+000,3,8.961049e-001,0.000000e+000,,,,,,,,,,,,,,32,1,4.000000e+000,0.000000e+000,0.000000e+000,0,,0,
1524006847.872,,0.000000e+000,3.499950e+001,-8.115145e-006,0.000000e+000,3,8.872690e-001,0.000000e+000,,,,,,,,,,,,,,32,1,4.000000e+000,0.000000e+000,0.000000e+000,0,,0,
1524006885.900,,0.000000e+000,3.500028e+001,-8.083594e-006,0.000000e+000,3,8.879092e-001,0.000000e+000,,,,,,,,,,,,,,32,1,4.000000e+000,0.000000e+000,0.000000e+000,0,,0,
1524006923.993,,0.000000e+000,3.499833e+001,-8.057257e-006,0.000000e+000,3,8.882618e-001,0.000000e+000,,,,,,,,,,,,,,32,1,4.000000e+000,7.781982e-004,0.000000e+000,0,,0,
1524006962.034,,0.000000e+000,3.499833e+001,-8.048301e-006,0.000000e+000,3,8.856953e-001,0.000000e+000,,,,,,,,,,,,,,32,1,4.000000e+000,7.781982e-004,0.000000e+000,0,,0,
1524007000.057,,0.000000e+000,3.499911e+001,-8.004299e-006,0.000000e+000,3,8.882311e-001,0.000000e+000,,,,,,,,,,,,,,32,1,4.000000e+000,7.820129e-004,0.000000e+000,0,,0,
1524007038.252,,0.000000e+000,3.499872e+001,-7.980288e-006,0.000000e+000,3,8.827301e-001,0.000000e+000,,,,,,,,,,,,,,32,1,4.000000e+000,0.000000e+000,0.000000e+000,0,,0,
1524007075.580,,0.000000e+000,3.499950e+001,-7.942586e-006,0.000000e+000,3,8.826336e-001,0.000000e+000,,,,,,,,,,,,,,32,1,4.000000e+000,0.000000e+000,0.000000e+000,0,,0,
1524007113.683,,0.000000e+000,3.500028e+001,-7.915972e-006,0.000000e+000,3,8.874520e-001,0.000000e+000,,,,,,,,,,,,,,32,1,4.000000e+000,1.560211e-003,0.000000e+000,0,,0,
1524007151.441,,0.000000e+000,3.499833e+001,-7.914882e-006,0.000000e+000,3,8.852109e-001,0.000000e+000,,,,,,,,,,,,,,32,1,4.000000e+000,7.781982e-004,0.000000e+000,0,,0,
1524007189.269,,0.000000e+000,3.499911e+001,-7.885806e-006,0.000000e+000,3,8.864556e-001,0.000000e+000,,,,,,,,,,,,,,32,1,4.000000e+000,7.820129e-004,0.000000e+000,0,,0,
1524007227.480,,0.000000e+000,3.499911e+001,-7.856869e-006,0.000000e+000,3,8.860696e-001,0.000000e+000,,,,,,,,,,,,,,32,1,4.000000e+000,3.910065e-003,0.000000e+000,0,,0,
1524007265.438,,0.000000e+000,3.499950e+001,-7.844222e-006,0.000000e+000,3,8.828428e-001,0.000000e+000,,,,,,,,,,,,,,32,1,4.000000e+000,0.000000e+000,0.000000e+000,0,,0,
1524007303.464,,0.000000e+000,3.499950e+001,-7.796195e-006,0.000000e+000,3,8.853439e-001,0.000000e+000,,,,,,,,,,,,,,32,1,4.000000e+000,1.560211e-003,0.000000e+000,0,,0,
1524007341.517,,0.000000e+000,3.499989e+001,-7.797134e-006,0.000000e+000,3,8.841074e-001,0.000000e+000,,,,,,,,,,,,,,32,1,4.000000e+000,7.781982e-004,0.000000e+000,0,,0,
1524007379.597,,0.000000e+000,3.499871e+001,-7.748084e-006,0.000000e+000,3,8.811322e-001,0.000000e+000,,,,,,,,,,,,,,32,1,4.000000e+000,3.128052e-003,0.000000e+000,0,,0,
1524007417.660,,0.000000e+000,3.499911e+001,-7.723362e-006,0.000000e+000,3,8.818651e-001,0.000000e+000,,,,,,,,,,,,,,32,1,4.000000e+000,7.820129e-004,0.000000e+000,0,,0,
1524007455.713,,0.000000e+000,3.499911e+001,-7.734899e-006,0.000000e+000,3,8.821362e-001,0.000000e+000,,,,,,,,,,,,,,32,1,4.000000e+000,7.820129e-004,0.000000e+000,0,,0,
1524007494.291,,0.000000e+000,3.499911e+001,-7.668279e-006,0.000000e+000,3,8.814895e-001,0.000000e+000,,,,,,,,,,,,,,32,1,4.000000e+000,7.820129e-004,0.000000e+000,0,,0,
1524007531.772,,0.000000e+000,3.500028e+001,-7.662740e-006,0.000000e+000,3,8.824091e-001,0.000000e+000,,,,,,,,,,,,,,32,1,4.000000e+000,1.560211e-003,0.000000e+000,0,,0,
1524007569.880,,0.000000e+000,3.499911e+001,-7.674405e-006,0.000000e+000,3,8.842712e-001,0.000000e+000,,,,,,,,,,,,,,32,1,4.000000e+000,2.338409e-003,0.000000e+000,0,,0,
1524007607.401,,0.000000e+000,3.499911e+001,-7.645788e-006,0.000000e+000,3,8.797662e-001,0.000000e+000,,,,,,,,,,,,,,32,1,4.000000e+000,7.820129e-004,0.000000e+000,0,,0,
1524007645.411,,0.000000e+000,3.499911e+001,-7.590095e-006,0.000000e+000,3,8.799145e-001,0.000000e+000,,,,,,,,,,,,,,32,1,4.000000e+000,7.820129e-004,0.000000e+000,0,,0,
1524007683.497,,0.000000e+000,3.499950e+001,-7.586844e-006,0.000000e+000,3,8.820938e-001,0.000000e+000,,,,,,,,,,,,,,32,1,4.000000e+000,0.000000e+000,0.000000e+000,0,,0,
1524007721.555,,0.000000e+000,3.499872e+001,-7.631972e-006,0.000000e+000,3,8.845795e-001,0.000000e+000,,,,,,,,,,,,,,32,1,4.000000e+000,0.000000e+000,0.000000e+000,0,,0,
1524007759.623,,0.000000e+000,3.499989e+001,-7.549163e-006,0.000000e+000,3,8.725200e-001,0.000000e+000,,,,,,,,,,,,,,32,1,4.000000e+000,7.781982e-004,0.000000e+000,0,,0,
1524007797.751,,0.000000e+000,3.499872e+001,-7.410638e-006,0.000000e+000,3,8.754691e-001,0.000000e+000,,,,,,,,,,,,,,32,1,4.000000e+000,1.560211e-003,0.000000e+000,0,,0,
1524007835.734,,0.000000e+000,3.499911e+001,-7.340138e-006,0.000000e+000,3,8.800756e-001,0.000000e+000,,,,,,,,,,,,,,32,1,4.000000e+000,7.820129e-004,0.000000e+000,0,,0,
1524007873.764,,0.000000e+000,3.499950e+001,-7.409646e-006,0.000000e+000,3,8.761663e-001,0.000000e+000,,,,,,,,,,,,,,32,1,4.000000e+000,0.000000e+000,0.000000e+000,0,,0,
1524007911.835,,0.000000e+000,3.499950e+001,-7.486579e-006,0.000000e+000,3,8.665866e-001,0.000000e+000,,,,,,,,,,,,,,32,1,4.000000e+000,0.000000e+000,0.000000e+000,0,,0,
1524007949.508,,0.000000e+000,3.500067e+001,-7.451200e-006,0.000000e+000,3,8.833371e-001,0.000000e+000,,,,,,,,,,,,,,32,1,4.000000e+000,2.338409e-003,0.000000e+000,0,,0,
1524007987.414,,0.000000e+000,3.499872e+001,-7.419427e-006,0.000000e+000,3,8.817490e-001,0.000000e+000,,,,,,,,,,,,,,32,1,4.000000e+000,0.000000e+000,0.000000e+000,0,,0,
1524008025.434,,0.000000e+000,3.500028e+001,-7.380117e-006,0.000000e+000,3,8.761043e-001,0.000000e+000,,,,,,,,,,,,,,32,1,4.000000e+000,0.000000e+000,0.000000e+000,0,,0,
1524008063.472,,0.000000e+000,3.499911e+001,-7.374940e-006,0.000000e+000,3,8.741443e-001,0.000000e+000,,,,,,,,,,,,,,32,1,4.000000e+000,7.820129e-004,0.000000e+000,0,,0,
1524008101.528,,0.000000e+000,3.499911e+001,-7.352615e-006,0.000000e+000,3,8.762026e-001,0.000000e+000,,,,,,,,,,,,,,32,1,4.000000e+000,7.820129e-004,0.000000e+000,0,,0,
1524008139.351,,0.000000e+000,3.499911e+001,-7.340898e-006,0.000000e+000,3,8.760244e-001,0.000000e+000,,,,,,,,,,,,,,32,1,4.000000e+000,7.820129e-004,0.000000e+000,0,,0,
1524008177.126,,0.000000e+000,3.499911e+001,-7.308934e-006,0.000000e+000,3,8.752618e-001,0.000000e+000,,,,,,,,,,,,,,32,1,4.000000e+000,7.820129e-004,0.000000e+000,0,,0,
1524008215.194,,0.000000e+000,3.499989e+001,-7.303276e-006,0.000000e+000,3,8.727841e-001,0.000000e+000,,,,,,,,,,,,,,32,1,4.000000e+000,7.781982e-004,0.000000e+000,0,,0,
1524008253.265,,0.000000e+000,3.499911e+001,-7.271041e-006,0.000000e+000,3,8.750836e-001,0.000000e+000,,,,,,,,,,,,,,32,1,4.000000e+000,7.820129e-004,0.000000e+000,0,,0,
1524008291.256,,0.000000e+000,3.499872e+001,-7.210324e-006,0.000000e+000,3,8.707834e-001,0.000000e+000,,,,,,,,,,,,,,32,1,4.000000e+000,0.000000e+000,0.000000e+000,0,,0,
1524008329.319,,0.000000e+000,3.499911e+001,-7.219908e-006,0.000000e+000,3,8.738187e-001,0.000000e+000,,,,,,,,,,,,,,32,1,4.000000e+000,7.820129e-004,0.000000e+000,0,,0,
1524008366.904,,0.000000e+000,3.499911e+001,-7.192184e-006,0.000000e+000,3,8.728724e-001,0.000000e+000,,,,,,,,,,,,,,32,1,4.000000e+000,7.820129e-004,0.000000e+000,0,,0,
1524008404.952,,0.000000e+000,3.499911e+001,-7.059532e-006,0.000000e+000,3,8.672983e-001,0.000000e+000,,,,,,,,,,,,,,32,1,4.000000e+000,7.820129e-004,0.000000e+000,0,,0,
1524008442.983,,0.000000e+000,3.499911e+001,-7.184104e-006,0.000000e+000,3,8.732652e-001,0.000000e+000,,,,,,,,,,,,,,32,1,4.000000e+000,7.820129e-004,0.000000e+000,0,,0,
1524008480.413,,0.000000e+000,3.499833e+001,-7.121636e-006,0.000000e+000,3,8.678895e-001,0.000000e+000,,,,,,,,,,,,,,32,1,4.000000e+000,2.349854e-003,0.000000e+000,0,,0,
1524008518.584,,0.000000e+000,3.499911e+001,-7.086124e-006,0.000000e+000,3,8.703635e-001,0.000000e+000,,,,,,,,,,,,,,32,1,4.000000e+000,7.820129e-004,0.000000e+000,0,,0,
1524008556.484,,0.000000e+000,3.499911e+001,-7.056814e-006,0.000000e+000,3,8.692799e-001,0.000000e+000,,,,,,,,,,,,,,32,1,4.000000e+000,7.820129e-004,0.000000e+000,0,,0,
1524008594.698,,0.000000e+000,3.499911e+001,-7.092543e-006,0.000000e+000,3,8.723110e-001,0.000000e+000,,,,,,,,,,,,,,32,1,4.000000e+000,7.820129e-004,0.000000e+000,0,,0,
1524008632.753,,0.000000e+000,3.499950e+001,-7.105639e-006,0.000000e+000,3,8.737550e-001,0.000000e+000,,,,,,,,,,,,,,32,1,4.000000e+000,0.000000e+000,0.000000e+000,0,,0,
1524008670.526,,0.000000e+000,3.499989e+001,-7.098946e-006,0.000000e+000,3,8.661445e-001,0.000000e+000,,,,,,,,,,,,,,32,1,4.000000e+000,7.781982e-004,0.000000e+000,0,,0,
1524008708.364,,0.000000e+000,3.499911e+001,-6.984908e-006,0.000000e+000,3,8.674036e-001,0.000000e+000,,,,,,,,,,,,,,32,1,4.000000e+000,7.820129e-004,0.000000e+000,0,,0,
1524008746.360,,0.000000e+000,3.499872e+001,-7.022791e-006,0.000000e+000,3,8.753352e-001,0.000000e+000,,,,,,,,,,,,,,32,1,4.000000e+000,1.560211e-003,0.000000e+000,0,,0,
1524008784.905,,0.000000e+000,3.499950e+001,-7.056455e-006,0.000000e+000,3,8.679341e-001,0.000000e+000,,,,,,,,,,,,,,32,1,4.000000e+000,0.000000e+000,0.000000e+000,0,,0,
1524008822.501,,0.000000e+000,3.499872e+001,-6.815215e-006,0.000000e+000,3,8.649973e-001,0.000000e+000,,,,,,,,,,,,,,32,1,4.000000e+000,1.560211e-003,0.000000e+000,0,,0,
1524008860.551,,0.000000e+000,3.499911e+001,-6.819816e-006,0.000000e+000,3,8.679135e-001,0.000000e+000,,,,,,,,,,,,,,32,1,4.000000e+000,7.820129e-004,0.000000e+000,0,,0,
1524008898.352,,0.000000e+000,3.499911e+001,-6.941341e-006,0.000000e+000,3,8.608890e-001,0.000000e+000,,,,,,,,,,,,,,32,1,4.000000e+000,7.820129e-004,0.000000e+000,0,,0,
1524008936.848,,0.000000e+000,3.500028e+001,-6.940989e-006,0.000000e+000,3,8.569514e-001,0.000000e+000,,,,,,,,,,,,,,32,1,4.000000e+000,0.000000e+000,0.000000e+000,0,,0,
1524008974.711,,0.000000e+000,3.500067e+001,-6.953113e-006,0.000000e+000,3,8.764499e-001,0.000000e+000,,,,,,,,,,,,,,32,1,4.000000e+000,2.338409e-003,0.000000e+000,0,,0,
1524009012.786,,0.000000e+000,3.500028e+001,-6.875347e-006,0.000000e+000,3,8.730667e-001,0.000000e+000,,,,,,,,,,,,,,32,1,4.000000e+000,0.000000e+000,0.000000e+000,0,,0,
1524009050.827,,0.000000e+000,3.499950e+001,-6.851492e-006,0.000000e+000,3,8.672357e-001,0.000000e+000,,,,,,,,,,,,,,32,1,4.000000e+000,1.560211e-003,0.000000e+000,0,,0,
1524009088.892,,0.000000e+000,3.500028e+001,-6.837671e-006,0.000000e+000,3,8.670606e-001,0.000000e+000,,,,,,,,,,,,,,32,1,4.000000e+000,0.000000e+000,0.000000e+000,0,,0,
1524009126.675,,0.000000e+000,3.499911e+001,-6.814263e-006,0.000000e+000,3,8.622926e-001,0.000000e+000,,,,,,,,,,,,,,32,1,4.000000e+000,2.338409e-003,0.000000e+000,0,,0,
1524009164.481,,0.000000e+000,3.499989e+001,-6.749787e-006,0.000000e+000,3,8.597541e-001,0.000000e+000,,,,,,,,,,,,,,32,1,4.000000e+000,7.781982e-004,0.000000e+000,0,,0,
1524009202.446,,0.000000e+000,3.499911e+001,-6.749331e-006,0.000000e+000,3,8.595036e-001,0.000000e+000,,,,,,,,,,,,,,32,1,4.000000e+000,7.820129e-004,0.000000e+000,0,,0,
1524009240.235,,0.000000e+000,3.499950e+001,-6.737186e-006,0.000000e+000,3,8.647320e-001,0.000000e+000,,,,,,,,,,,,,,32,1,4.000000e+000,0.000000e+000,0.000000e+000,0,,0,
1524009277.853,,0.000000e+000,3.499950e+001,-6.755002e-006,0.000000e+000,3,8.650680e-001,0.000000e+000,,,,,,,,,,,,,,32,1,4.000000e+000,1.560211e-003,0.000000e+000,0,,0,
1524009316.356,,0.000000e+000,3.499911e+001,-6.755582e-006,0.000000e+000,3,8.652827e-001,0.000000e+000,,,,,,,,,,,,,,32,1,4.000000e+000,7.820129e-004,0.000000e+000,0,,0,
1524009353.946,,0.000000e+000,3.500028e+001,-6.774305e-006,0.000000e+000,3,8.625738e-001,0.000000e+000,,,,,,,,,,,,,,32,1,4.000000e+000,1.560211e-003,0.000000e+000,0,,0,
1524009392.484,,0.000000e+000,3.500028e+001,-6.682750e-006,0.000000e+000,3,8.625636e-001,0.000000e+000,,,,,,,,,,,,,,32,1,4.000000e+000,0.000000e+000,0.000000e+000,0,,0,
1524009430.060,,0.000000e+000,3.499911e+001,-6.724040e-006,0.000000e+000,3,8.680366e-001,0.000000e+000,,,,,,,,,,,,,,32,1,4.000000e+000,7.820129e-004,0.000000e+000,0,,0,
1524009468.125,,0.000000e+000,3.500067e+001,-6.711510e-006,0.000000e+000,3,8.634445e-001,0.000000e+000,,,,,,,,,,,,,,32,1,4.000000e+000,7.820129e-004,0.000000e+000,0,,0,
1524009506.191,,0.000000e+000,3.499989e+001,-6.683997e-006,0.000000e+000,3,8.641997e-001,0.000000e+000,,,,,,,,,,,,,,32,1,4.000000e+000,2.342224e-003,0.000000e+000,0,,0,
1524009544.251,,0.000000e+000,3.500067e+001,-6.684552e-006,0.000000e+000,3,8.677967e-001,0.000000e+000,,,,,,,,,,,,,,32,1,4.000000e+000,2.338409e-003,0.000000e+000,0,,0,
1524009582.747,,0.000000e+000,3.499911e+001,-6.670829e-006,0.000000e+000,3,8.622842e-001,0.000000e+000,,,,,,,,,,,,,,32,1,4.000000e+000,7.820129e-004,0.000000e+000,0,,0,
1524009620.273,,0.000000e+000,3.499872e+001,-6.667301e-006,0.000000e+000,3,8.661949e-001,0.000000e+000,,,,,,,,,,,,,,32,1,4.000000e+000,1.560211e-003,0.000000e+000,0,,0,
1524009658.336,,0.000000e+000,3.499989e+001,-6.598026e-006,0.000000e+000,3,8.636421e-001,0.000000e+000,,,,,,,,,,,,,,32,1,4.000000e+000,7.781982e-004,0.000000e+000,0,,0,
1524009696.461,,0.000000e+000,3.499950e+001,-6.677794e-006,0.000000e+000,3,8.717865e-001,0.000000e+000,,,,,,,,,,,,,,32,1,4.000000e+000,1.560211e-003,0.000000e+000,0,,0,
1524009734.782,,0.000000e+000,3.499872e+001,-6.558924e-006,0.000000e+000,3,8.543025e-001,0.000000e+000,,,,,,,,,,,,,,32,1,4.000000e+000,1.560211e-003,0.000000e+000,0,,0,
1524009772.062,,0.000000e+000,3.499950e+001,-6.414039e-006,0.000000e+000,3,8.605142e-001,0.000000e+000,,,,,,,,,,,,,,32,1,4.000000e+000,0.000000e+000,0.000000e+000,0,,0,
1524009810.560,,0.000000e+000,3.499872e+001,-6.536662e-006,0.000000e+000,3,8.561237e-001,0.000000e+000,,,,,,,,,,,,,,32,1,4.000000e+000,0.000000e+000,0.000000e+000,0,,0,
1524009848.186,,0.000000e+000,3.499950e+001,-6.620075e-006,0.000000e+000,3,8.586976e-001,0.000000e+000,,,,,,,,,,,,,,32,1,4.000000e+000,0.000000e+000,0.000000e+000,0,,0,
1524009886.892,,0.000000e+000,3.499872e+001,-6.554211e-006,0.000000e+000,3,8.659281e-001,0.000000e+000,,,,,,,,,,,,,,32,1,4.000000e+000,1.560211e-003,0.000000e+000,0,,0,
1524009924.292,,0.000000e+000,3.499872e+001,-6.467378e-006,0.000000e+000,3,8.632143e-001,0.000000e+000,,,,,,,,,,,,,,32,1,4.000000e+000,0.000000e+000,0.000000e+000,0,,0,
1524009963.010,,0.000000e+000,3.499950e+001,-6.450919e-006,0.000000e+000,3,8.573164e-001,0.000000e+000,,,,,,,,,,,,,,32,1,4.000000e+000,0.000000e+000,0.000000e+000,0,,0,
1524010000.553,,0.000000e+000,3.499911e+001,-6.454706e-006,0.000000e+000,3,8.538735e-001,0.000000e+000,,,,,,,,,,,,,,32,1,4.000000e+000,7.820129e-004,0.000000e+000,0,,0,
1524010038.764,,0.000000e+000,3.499911e+001,-6.407747e-006,0.000000e+000,3,8.544239e-001,0.000000e+000,,,,,,,,,,,,,,32,1,4.000000e+000,7.820129e-004,0.000000e+000,0,,0,
1524010077.294,,0.000000e+000,3.499833e+001,-6.408629e-006,0.000000e+000,3,8.591918e-001,0.000000e+000,,,,,,,,,,,,,,32,1,4.000000e+000,7.781982e-004,0.000000e+000,0,,0,
1524010115.395,,0.000000e+000,3.499911e+001,-6.428725e-006,0.000000e+000,3,8.598821e-001,0.000000e+000,,,,,,,,,,,,,,32,1,4.000000e+000,7.820129e-004,0.000000e+000,0,,0,
1524010152.683,,0.000000e+000,3.499911e+001,-6.409042e-006,0.000000e+000,3,8.567086e-001,0.000000e+000,,,,,,,,,,,,,,32,1,4.000000e+000,7.820129e-004,0.000000e+000,0,,0,
1524010190.446,,0.000000e+000,3.499950e+001,-6.344568e-006,0.000000e+000,3,8.525736e-001,0.000000e+000,,,,,,,,,,,,,,32,1,4.000000e+000,0.000000e+000,0.000000e+000,0,,0,
1524010228.341,,0.000000e+000,3.500185e+001,-6.365802e-006,0.000000e+000,3,8.555679e-001,0.000000e+000,,,,,,,,,,,,,,32,1,4.000000e+000,4.688263e-003,0.000000e+000,0,,0,
1524010266.532,,0.000000e+000,3.499871e+001,-6.361476e-006,0.000000e+000,3,8.577571e-001,0.000000e+000,,,,,,,,,,,,,,32,1,4.000000e+000,3.128052e-003,0.000000e+000,0,,0,
1524010304.605,,0.000000e+000,3.499872e+001,-6.368628e-006,0.000000e+000,3,8.578518e-001,0.000000e+000,,,,,,,,,,,,,,32,1,4.000000e+000,1.560211e-003,0.000000e+000,0,,0,
1524010341.998,,0.000000e+000,3.499989e+001,-6.348351e-006,0.000000e+000,3,8.605815e-001,0.000000e+000,,,,,,,,,,,,,,32,1,4.000000e+000,2.342224e-003,0.000000e+000,0,,0,
1524010380.069,,0.000000e+000,3.499911e+001,-6.274990e-006,0.000000e+000,3,8.556026e-001,0.000000e+000,,,,,,,,,,,,,,32,1,4.000000e+000,7.820129e-004,0.000000e+000,0,,0,
1524010418.169,,0.000000e+000,3.499950e+001,-6.321210e-006,0.000000e+000,3,8.566091e-001,0.000000e+000,,,,,,,,,,,,,,32,1,4.000000e+000,0.000000e+000,0.000000e+000,0,,0,
1524010456.030,,0.000000e+000,3.499989e+001,-6.282253e-006,0.000000e+000,3,8.534117e-001,0.000000e+000,,,,,,,,,,,,,,32,1,4.000000e+000,2.342224e-003,0.000000e+000,0,,0,
1524010494.115,,0.000000e+000,3.499950e+001,-6.303108e-006,0.000000e+000,3,8.545772e-001,0.000000e+000,,,,,,,,,,,,,,32,1,4.000000e+000,3.120422e-003,0.000000e+000,0,,0,
1524010531.741,,0.000000e+000,3.499911e+001,-6.246378e-006,0.000000e+000,3,8.539341e-001,0.000000e+000,,,,,,,,,,,,,,32,1,4.000000e+000,7.820129e-004,0.000000e+000,0,,0,
1524010569.697,,0.000000e+000,3.500067e+001,-6.233505e-006,0.000000e+000,3,8.494405e-001,0.000000e+000,,,,,,,,,,,,,,32,1,4.000000e+000,2.338409e-003,0.000000e+000,0,,0,
1524010607.792,,0.000000e+000,3.500067e+001,-6.240125e-006,0.000000e+000,3,8.520139e-001,0.000000e+000,,,,,,,,,,,,,,32,1,4.000000e+000,2.338409e-003,0.000000e+000,0,,0,
1524010646.013,,0.000000e+000,3.499794e+001,-6.225966e-006,0.000000e+000,3,8.560689e-001,0.000000e+000,,,,,,,,,,,,,,32,1,4.000000e+000,0.000000e+000,0.000000e+000,0,,0,
1524010684.671,,0.000000e+000,3.499911e+001,-6.229065e-006,0.000000e+000,3,8.540348e-001,0.000000e+000,,,,,,,,,,,,,,32,1,4.000000e+000,7.820129e-004,0.000000e+000,0,,0,
1524010722.834,,0.000000e+000,3.499872e+001,-6.207477e-006,0.000000e+000,3,8.557258e-001,0.000000e+000,,,,,,,,,,,,,,32,1,4.000000e+000,0.000000e+000,0.000000e+000,0,,0,
1524010761.257,,0.000000e+000,3.499950e+001,-6.164745e-006,0.000000e+000,3,8.526130e-001,0.000000e+000,,,,,,,,,,,,,,32,1,4.000000e+000,1.560211e-003,0.000000e+000,0,,0,
1524010798.555,,0.000000e+000,3.499950e+001,-6.159582e-006,0.000000e+000,3,8.518775e-001,0.000000e+000,,,,,,,,,,,,,,32,1,4.000000e+000,0.000000e+000,0.000000e+000,0,,0,
1524010835.820,,0.000000e+000,3.499911e+001,-6.195675e-006,0.000000e+000,3,8.547088e-001,0.000000e+000,,,,,,,,,,,,,,32,1,4.000000e+000,7.820129e-004,0.000000e+000,0,,0,
1524010873.868,,0.000000e+000,3.499950e+001,-6.152361e-006,0.000000e+000,3,8.576008e-001,0.000000e+000,,,,,,,,,,,,,,32,1,4.000000e+000,1.560211e-003,0.000000e+000,0,,0,
1524010911.909,,0.000000e+000,3.499950e+001,-6.136029e-006,0.000000e+000,3,8.512678e-001,0.000000e+000,,,,,,,,,,,,,,32,1,4.000000e+000,0.000000e+000,0.000000e+000,0,,0,
1524010949.977,,0.000000e+000,3.499911e+001,-6.113749e-006,0.000000e+000,3,8.537913e-001,0.000000e+000,,,,,,,,,,,,,,32,1,4.000000e+000,7.820129e-004,0.000000e+000,0,,0,
1524010988.588,,0.000000e+000,3.499911e+001,-6.099539e-006,0.000000e+000,3,8.522997e-001,0.000000e+000,,,,,,,,,,,,,,32,1,4.000000e+000,7.820129e-004,0.000000e+000,0,,0,
1524011026.088,,0.000000e+000,3.499794e+001,-6.121430e-006,0.000000e+000,3,8.520352e-001,0.000000e+000,,,,,,,,,,,,,,32,1,4.000000e+000,0.000000e+000,0.000000e+000,0,,0,
1524011063.796,,0.000000e+000,3.499989e+001,-6.008628e-006,0.000000e+000,3,8.602070e-001,0.000000e+000,,,,,,,,,,,,,,32,1,4.000000e+000,7.781982e-004,0.000000e+000,0,,0,
1524011102.159,,0.000000e+000,3.499911e+001,-6.095473e-006,0.000000e+000,3,8.515560e-001,0.000000e+000,,,,,,,,,,,,,,32,1,4.000000e+000,7.820129e-004,0.000000e+000,0,,0,
1524011139.785,,0.000000e+000,3.499950e+001,-6.055669e-006,0.000000e+000,3,8.513119e-001,0.000000e+000,,,,,,,,,,,,,,32,1,4.000000e+000,0.000000e+000,0.000000e+000,0,,0,
1524011177.815,,0.000000e+000,3.499872e+001,-6.063167e-006,0.000000e+000,3,8.514499e-001,0.000000e+000,,,,,,,,,,,,,,32,1,4.000000e+000,0.000000e+000,0.000000e+000,0,,0,
1524011215.264,,0.000000e+000,3.499871e+001,-6.017834e-006,0.000000e+000,3,8.481936e-001,0.000000e+000,,,,,,,,,,,,,,32,1,4.000000e+000,3.128052e-003,0.000000e+000,0,,0,
1524011253.637,,0.000000e+000,3.499833e+001,-6.049056e-006,0.000000e+000,3,8.507834e-001,0.000000e+000,,,,,,,,,,,,,,32,1,4.000000e+000,7.781982e-004,0.000000e+000,0,,0,
1524011290.695,,0.000000e+000,3.500106e+001,-6.001576e-006,0.000000e+000,3,8.426836e-001,0.000000e+000,,,,,,,,,,,,,,32,1,4.000000e+000,4.692078e-003,0.000000e+000,0,,0,
1524011329.520,,0.000000e+000,3.499950e+001,-5.985758e-006,0.000000e+000,3,8.469757e-001,0.000000e+000,,,,,,,,,,,,,,32,1,4.000000e+000,1.560211e-003,0.000000e+000,0,,0,
1524011366.976,,0.000000e+000,3.499911e+001,-5.943899e-006,0.000000e+000,3,8.491032e-001,0.000000e+000,,,,,,,,,,,,,,32,1,4.000000e+000,7.820129e-004,0.000000e+000,0,,0,
1524011405.036,,0.000000e+000,3.499911e+001,-5.986584e-006,0.000000e+000,3,8.501050e-001,0.000000e+000,,,,,,,,,,,,,,32,1,4.000000e+000,7.820129e-004,0.000000e+000,0,,0,
1524011443.454,,0.000000e+000,3.499950e+001,-6.037946e-006,0.000000e+000,3,8.527241e-001,0.000000e+000,,,,,,,,,,,,,,32,1,4.000000e+000,0.000000e+000,0.000000e+000,0,,0,
1524011480.655,,0.000000e+000,3.499950e+001,-5.985347e-006,0.000000e+000,3,8.521860e-001,0.000000e+000,,,,,,,,,,,,,,32,1,4.000000e+000,0.000000e+000,0.000000e+000,0,,0,
1524011518.068,,0.000000e+000,3.499950e+001,-5.938345e-006,0.000000e+000,3,8.435291e-001,0.000000e+000,,,,,,,,,,,,,,32,1,4.000000e+000,1.560211e-003,0.000000e+000,0,,0,
1524011555.441,,0.000000e+000,3.499911e+001,-5.935718e-006,0.000000e+000,3,8.504032e-001,0.000000e+000,,,,,,,,,,,,,,32,1,4.000000e+000,7.820129e-004,0.000000e+000,0,,0,
1524011593.987,,0.000000e+000,3.499911e+001,-5.891225e-006,0.000000e+000,3,8.463350e-001,0.000000e+000,,,,,,,,,,,,,,32,1,4.000000e+000,7.820129e-004,0.000000e+000,0,,0,
1524011631.477,,0.000000e+000,3.499872e+001,-5.899011e-006,0.000000e+000,3,8.456811e-001,0.000000e+000,,,,,,,,,,,,,,32,1,4.000000e+000,0.000000e+000,0.000000e+000,0,,0,
1524011669.875,,0.000000e+000,3.499911e+001,-5.888602e-006,0.000000e+000,3,8.528383e-001,0.000000e+000,,,,,,,,,,,,,,32,1,4.000000e+000,7.820129e-004,0.000000e+000,0,,0,
1524011707.396,,0.000000e+000,3.499911e+001,-5.856761e-006,0.000000e+000,3,8.426668e-001,0.000000e+000,,,,,,,,,,,,,,32,1,4.000000e+000,7.820129e-004,0.000000e+000,0,,0,
1524011745.884,,0.000000e+000,3.499950e+001,-5.844811e-006,0.000000e+000,3,8.451324e-001,0.000000e+000,,,,,,,,,,,,,,32,1,4.000000e+000,1.560211e-003,0.000000e+000,0,,0,
1524011783.962,,0.000000e+000,3.499911e+001,-5.830794e-006,0.000000e+000,3,8.458076e-001,0.000000e+000,,,,,,,,,,,,,,32,1,4.000000e+000,2.338409e-003,0.000000e+000,0,,0,
1524011821.995,,0.000000e+000,3.499950e+001,-5.844425e-006,0.000000e+000,3,8.410543e-001,0.000000e+000,,,,,,,,,,,,,,32,1,4.000000e+000,0.000000e+000,0.000000e+000,0,,0,
1524011860.235,,0.000000e+000,3.499911e+001,-5.902830e-006,0.000000e+000,3,8.501379e-001,0.000000e+000,,,,,,,,,,,,,,32,1,4.000000e+000,2.338409e-003,0.000000e+000,0,,0,
1524011898.511,,0.000000e+000,3.499872e+001,-5.754143e-006,0.000000e+000,3,8.349283e-001,0.000000e+000,,,,,,,,,,,,,,32,1,4.000000e+000,0.000000e+000,0.000000e+000,0,,0,
1524011936.724,,0.000000e+000,3.500028e+001,-5.789887e-006,0.000000e+000,3,8.441814e-001,0.000000e+000,,,,,,,,,,,,,,32,1,4.000000e+000,1.560211e-003,0.000000e+000,0,,0,
1524011974.790,,0.000000e+000,3.499950e+001,-5.752916e-006,0.000000e+000,3,8.426767e-001,0.000000e+000,,,,,,,,,,,,,,32,1,4.000000e+000,0.000000e+000,0.000000e+000,0,,0,
1524012012.858,,0.000000e+000,3.499911e+001,-5.738071e-006,0.000000e+000,3,8.382440e-001,0.000000e+000,,,,,,,,,,,,,,32,1,4.000000e+000,7.820129e-004,0.000000e+000,0,,0,
1524012050.726,,0.000000e+000,3.499872e+001,-5.713214e-006,0.000000e+000,3,8.368344e-001,0.000000e+000,,,,,,,,,,,,,,32,1,4.000000e+000,0.000000e+000,0.000000e+000,0,,0,
1524012089.436,,0.000000e+000,3.499911e+001,-5.681679e-006,0.000000e+000,3,8.367092e-001,0.000000e+000,,,,,,,,,,,,,,32,1,4.000000e+000,7.820129e-004,0.000000e+000,0,,0,
1524012127.319,,0.000000e+000,3.499989e+001,-5.716861e-006,0.000000e+000,3,8.388070e-001,0.000000e+000,,,,,,,,,,,,,,32,1,4.000000e+000,7.781982e-004,0.000000e+000,0,,0,
1524012165.375,,0.000000e+000,3.499872e+001,-5.712928e-006,0.000000e+000,3,8.417069e-001,0.000000e+000,,,,,,,,,,,,,,32,1,4.000000e+000,0.000000e+000,0.000000e+000,0,,0,
1524012203.248,,0.000000e+000,3.499911e+001,-5.699724e-006,0.000000e+000,3,8.399072e-001,0.000000e+000,,,,,,,,,,,,,,32,1,4.000000e+000,7.820129e-004,0.000000e+000,0,,0,
1524012241.324,,0.000000e+000,3.499833e+001,-5.689343e-006,0.000000e+000,3,8.381150e-001,0.000000e+000,,,,,,,,,,,,,,32,1,4.000000e+000,7.781982e-004,0.000000e+000,0,,0,
1524012279.384,,0.000000e+000,3.499989e+001,-5.750379e-006,0.000000e+000,3,8.520275e-001,0.000000e+000,,,,,,,,,,,,,,32,1,4.000000e+000,2.342224e-003,0.000000e+000,0,,0,
1524012317.957,,0.000000e+000,3.499911e+001,-5.670278e-006,0.000000e+000,3,8.350280e-001,0.000000e+000,,,,,,,,,,,,,,32,1,4.000000e+000,7.820129e-004,0.000000e+000,0,,0,
1524012355.495,,0.000000e+000,3.499911e+001,-5.648596e-006,0.000000e+000,3,8.399287e-001,0.000000e+000,,,,,,,,,,,,,,32,1,4.000000e+000,7.820129e-004,0.000000e+000,0,,0,
1524012368.135,,0.000000e+000,3.499871e+001,-5.648131e-006,0.000000e+000,3,8.412716e-001,0.000000e+000,,,,,,,,,,,,,,32,1,4.000000e+000,3.128052e-003,0.000000e+000,0,,0,