File: Experimental Raw Data/MFn1 VRM/Iterative Regression/MFn1_VRMac_35K_400s_VRMde_35K.dc.dat
[Header]
TITLE,MPMS DC Measurement
BYAPP,MPMS Measurement,2.1,Summary
FILEOPENTIME, 1524091415.506000 4/18/2018, 4:43:35 PM

INFO, APPNAME, MPMS MultiVu Application, Revision 1.61,  Build 082

INFO, NAME, MFn1
INFO, WEIGHT, 1.000
INFO, AREA, 1.000
INFO, LENGTH, 1.000
INFO, SHAPE, 0
INFO, COMMENT,
INFO, SEQUENCE FILE: VRMac_35K_400s_VRMde_35K.seq


INFO, BACKGROUND DATA FILE:, None


STARTUPAXIS,X,4,LINEAR,AUTO,0.000000,0.000000
STARTUPAXIS,Y1,5,LINEAR,AUTO,0.000000,0.000000


STARTUPGROUP,Longitudinal
FIELDGROUP,Longitudinal,1,2,3,4,5,6,7,8,9,15,16,17,18,27,28
FIELDGROUP,Transverse,1,2,3,4,10,11,12,13,14,19,20,21,22,27,28

PLOT_APPEARANCE,ALL,HORZ_GRID_ON,VERT_GRID_ON,MARKERS_AND_LINES

[Data]
Time,Comment,Field (Oe),Temperature (K),Long Moment (emu),Long Scan Std Dev,Long Algorithm,Long Reg Fit,Long Percent Error (%),Trans Moment (emu),Trans Scan Std Dev,Trans Algorithm,Trans Reg Fit,Trans Percent Error (%),Long Moment [w/o ABS] (emu),Long Scan Std Dev [w/o ABS],Long Reg Fit [w/o ABS],Long Percent Error [w/o ABS] (%),Trans Moment [w/o ABS] (emu),Trans Scan Std Dev [w/o ABS],Trans Reg Fit [w/o ABS],Trans Percent Error [w/o ABS] (%),Points per Scan,Scans per Measurement,Scan Length (cm),Delta Temp (K),Rot Position (deg),Error,EC Comp. Running,Using ABS,
1524091415.503,,0.000000e+000,3.499637e+001,-9.286367e-006,0.000000e+000,3,9.060753e-001,0.000000e+000,,,,,,,,,,,,,,32,1,4.000000e+000,1.560211e-003,0.000000e+000,0,,0,
1524091428.189,,0.000000e+000,3.499677e+001,-7.963567e-006,0.000000e+000,3,8.903735e-001,0.000000e+000,,,,,,,,,,,,,,32,1,4.000000e+000,2.349854e-003,0.000000e+000,0,,0,
1524091440.871,,0.000000e+000,3.499793e+001,-6.923745e-006,0.000000e+000,3,8.738443e-001,0.000000e+000,,,,,,,,,,,,,,32,1,4.000000e+000,1.567841e-003,0.000000e+000,0,,0,
1524091453.564,,0.000000e+000,3.499715e+001,-6.206855e-006,0.000000e+000,3,8.576424e-001,0.000000e+000,,,,,,,,,,,,,,32,1,4.000000e+000,0.000000e+000,0.000000e+000,0,,0,
1524091466.507,,0.000000e+000,3.499833e+001,-5.507371e-006,0.000000e+000,3,8.357144e-001,0.000000e+000,,,,,,,,,,,,,,32,1,4.000000e+000,2.349854e-003,0.000000e+000,0,,0,
1524091479.094,,0.000000e+000,3.499872e+001,-5.004917e-006,0.000000e+000,3,8.237892e-001,0.000000e+000,,,,,,,,,,,,,,32,1,4.000000e+000,0.000000e+000,0.000000e+000,0,,0,
1524091491.725,,0.000000e+000,3.499833e+001,-4.587130e-006,0.000000e+000,3,8.048855e-001,0.000000e+000,,,,,,,,,,,,,,32,1,4.000000e+000,7.781982e-004,0.000000e+000,0,,0,
1524091504.462,,0.000000e+000,3.499911e+001,-4.219930e-006,0.000000e+000,3,7.873420e-001,0.000000e+000,,,,,,,,,,,,,,32,1,4.000000e+000,7.820129e-004,0.000000e+000,0,,0,
1524091517.150,,0.000000e+000,3.499911e+001,-3.809720e-006,0.000000e+000,3,7.627186e-001,0.000000e+000,,,,,,,,,,,,,,32,1,4.000000e+000,7.820129e-004,0.000000e+000,0,,0,
1524091529.860,,0.000000e+000,3.499793e+001,-3.541854e-006,0.000000e+000,3,7.486498e-001,0.000000e+000,,,,,,,,,,,,,,32,1,4.000000e+000,1.567841e-003,0.000000e+000,0,,0,
1524091542.488,,0.000000e+000,3.499833e+001,-3.329022e-006,0.000000e+000,3,7.360387e-001,0.000000e+000,,,,,,,,,,,,,,32,1,4.000000e+000,7.781982e-004,0.000000e+000,0,,0,
1524091555.210,,0.000000e+000,3.499872e+001,-3.000659e-006,0.000000e+000,3,6.981072e-001,0.000000e+000,,,,,,,,,,,,,,32,1,4.000000e+000,1.560211e-003,0.000000e+000,0,,0,
1524091567.878,,0.000000e+000,3.499793e+001,-2.789596e-006,0.000000e+000,3,6.819847e-001,0.000000e+000,,,,,,,,,,,,,,32,1,4.000000e+000,1.567841e-003,0.000000e+000,0,,0,
1524091580.606,,0.000000e+000,3.499793e+001,-2.606340e-006,0.000000e+000,3,6.592103e-001,0.000000e+000,,,,,,,,,,,,,,32,1,4.000000e+000,1.567841e-003,0.000000e+000,0,,0,
1524091593.269,,0.000000e+000,3.499833e+001,-2.429978e-006,0.000000e+000,3,6.314039e-001,0.000000e+000,,,,,,,,,,,,,,32,1,4.000000e+000,7.781982e-004,0.000000e+000,0,,0,
1524091605.931,,0.000000e+000,3.499833e+001,-2.178523e-006,0.000000e+000,3,5.666852e-001,0.000000e+000,,,,,,,,,,,,,,32,1,4.000000e+000,2.349854e-003,0.000000e+000,0,,0,
1524091619.181,,0.000000e+000,3.499754e+001,-2.116024e-006,0.000000e+000,3,5.720702e-001,0.000000e+000,,,,,,,,,,,,,,32,1,4.000000e+000,7.896423e-004,0.000000e+000,0,,0,
1524091631.309,,0.000000e+000,3.499793e+001,-1.973400e-006,0.000000e+000,3,5.442690e-001,0.000000e+000,,,,,,,,,,,,,,32,1,4.000000e+000,1.567841e-003,0.000000e+000,0,,0,
1524091644.007,,0.000000e+000,3.499833e+001,-1.742786e-006,0.000000e+000,3,4.661674e-001,0.000000e+000,,,,,,,,,,,,,,32,1,4.000000e+000,7.781982e-004,0.000000e+000,0,,0,
1524091656.709,,0.000000e+000,3.499833e+001,-1.647660e-006,0.000000e+000,3,4.469480e-001,0.000000e+000,,,,,,,,,,,,,,32,1,4.000000e+000,7.781982e-004,0.000000e+000,0,,0,
1524091669.372,,0.000000e+000,3.499754e+001,-1.590922e-006,0.000000e+000,3,4.331692e-001,0.000000e+000,,,,,,,,,,,,,,32,1,4.000000e+000,2.349854e-003,0.000000e+000,0,,0,
1524091682.060,,0.000000e+000,3.499872e+001,-1.442495e-006,0.000000e+000,3,3.832610e-001,0.000000e+000,,,,,,,,,,,,,,32,1,4.000000e+000,0.000000e+000,0.000000e+000,0,,0,
1524091694.725,,0.000000e+000,3.499833e+001,-1.341256e-006,0.000000e+000,3,3.051905e-001,0.000000e+000,,,,,,,,,,,,,,32,1,4.000000e+000,7.781982e-004,0.000000e+000,0,,0,
1524091707.438,,0.000000e+000,3.499911e+001,-1.240747e-006,0.000000e+000,3,2.471241e-001,0.000000e+000,,,,,,,,,,,,,,32,1,4.000000e+000,7.820129e-004,0.000000e+000,0,,0,
1524091719.890,,0.000000e+000,3.499872e+001,-1.182593e-006,0.000000e+000,3,2.054938e-001,0.000000e+000,,,,,,,,,,,,,,32,1,4.000000e+000,1.560211e-003,0.000000e+000,0,,0,
1524091732.756,,0.000000e+000,3.499872e+001,-1.080840e-006,0.000000e+000,3,1.605029e-001,0.000000e+000,,,,,,,,,,,,,,32,1,4.000000e+000,0.000000e+000,0.000000e+000,0,,0,
1524091745.436,,0.000000e+000,3.499833e+001,-1.000335e-006,0.000000e+000,3,9.540696e-002,0.000000e+000,,,,,,,,,,,,,,32,1,4.000000e+000,7.781982e-004,0.000000e+000,0,,0,
1524091758.186,,0.000000e+000,3.499794e+001,-9.572991e-007,0.000000e+000,3,3.268957e-002,0.000000e+000,,,,,,,,,,,,,,32,1,4.000000e+000,0.000000e+000,0.000000e+000,0,,0,
1524091770.924,,0.000000e+000,3.500028e+001,-8.109482e-007,0.000000e+000,3,0.000000e+000,0.000000e+000,,,,,,,,,,,,,,32,1,4.000000e+000,3.120422e-003,0.000000e+000,0,,0,
1524091783.681,,0.000000e+000,3.500028e+001,-7.905937e-007,0.000000e+000,3,0.000000e+000,0.000000e+000,,,,,,,,,,,,,,32,1,4.000000e+000,3.120422e-003,0.000000e+000,0,,0,
1524091796.377,,0.000000e+000,3.499793e+001,-6.697315e-007,0.000000e+000,3,0.000000e+000,0.000000e+000,,,,,,,,,,,,,,32,1,4.000000e+000,1.567841e-003,0.000000e+000,0,,0,
1524091809.524,,0.000000e+000,3.499754e+001,-6.492755e-007,0.000000e+000,3,0.000000e+000,0.000000e+000,,,,,,,,,,,,,,32,1,4.000000e+000,7.896423e-004,0.000000e+000,0,,0,
1524091821.644,,0.000000e+000,3.499794e+001,-6.032923e-007,0.000000e+000,3,0.000000e+000,0.000000e+000,,,,,,,,,,,,,,32,1,4.000000e+000,0.000000e+000,0.000000e+000,0,,0,
1524091834.457,,0.000000e+000,3.499794e+001,-5.418378e-007,0.000000e+000,3,0.000000e+000,0.000000e+000,,,,,,,,,,,,,,32,1,4.000000e+000,0.000000e+000,0.000000e+000,0,,0,
1524091846.870,,0.000000e+000,3.499833e+001,-4.735537e-007,0.000000e+000,3,0.000000e+000,0.000000e+000,,,,,,,,,,,,,,32,1,4.000000e+000,7.781982e-004,0.000000e+000,0,,0,
1524091859.290,,0.000000e+000,3.499989e+001,-4.052322e-007,0.000000e+000,3,0.000000e+000,0.000000e+000,,,,,,,,,,,,,,32,1,4.000000e+000,3.898621e-003,0.000000e+000,0,,0,
1524091871.998,,0.000000e+000,3.499833e+001,8.649599e-007,0.000000e+000,3,5.380563e-003,0.000000e+000,,,,,,,,,,,,,,32,1,4.000000e+000,7.781982e-004,0.000000e+000,0,,0,
1524091884.260,,0.000000e+000,3.499833e+001,-4.214910e-007,0.000000e+000,3,0.000000e+000,0.000000e+000,,,,,,,,,,,,,,32,1,4.000000e+000,7.781982e-004,0.000000e+000,0,,0,
1524091896.921,,0.000000e+000,3.499794e+001,-4.154748e-007,0.000000e+000,3,0.000000e+000,0.000000e+000,,,,,,,,,,,,,,32,1,4.000000e+000,0.000000e+000,0.000000e+000,0,,0,
1524091909.598,,0.000000e+000,3.499794e+001,7.667055e-007,0.000000e+000,3,0.000000e+000,0.000000e+000,,,,,,,,,,,,,,32,1,4.000000e+000,0.000000e+000,0.000000e+000,0,,0,
1524091922.271,,0.000000e+000,3.499833e+001,6.859126e-007,0.000000e+000,3,0.000000e+000,0.000000e+000,,,,,,,,,,,,,,32,1,4.000000e+000,7.781982e-004,0.000000e+000,0,,0,
1524091936.982,,0.000000e+000,3.499833e+001,-1.922382e-007,0.000000e+000,2,0.000000e+000,0.000000e+000,,,,,,,,,,,,,,32,1,4.000000e+000,7.781982e-004,0.000000e+000,0,,0,
1524091951.005,,0.000000e+000,3.500028e+001,-1.317143e-007,0.000000e+000,2,0.000000e+000,0.000000e+000,,,,,,,,,,,,,,32,1,4.000000e+000,1.560211e-003,0.000000e+000,0,,0,
1524091963.243,,0.000000e+000,3.499989e+001,8.292955e-007,0.000000e+000,3,0.000000e+000,0.000000e+000,,,,,,,,,,,,,,32,1,4.000000e+000,2.342224e-003,0.000000e+000,0,,0,
1524091977.981,,0.000000e+000,3.499872e+001,-4.109570e-008,0.000000e+000,2,0.000000e+000,0.000000e+000,,,,,,,,,,,,,,32,1,4.000000e+000,0.000000e+000,0.000000e+000,0,,0,
1524091989.921,,0.000000e+000,3.499793e+001,8.406026e-007,0.000000e+000,3,0.000000e+000,0.000000e+000,,,,,,,,,,,,,,32,1,4.000000e+000,1.567841e-003,0.000000e+000,0,,0,
1524092004.657,,0.000000e+000,3.499833e+001,-3.434016e-008,0.000000e+000,2,0.000000e+000,0.000000e+000,,,,,,,,,,,,,,32,1,4.000000e+000,7.781982e-004,0.000000e+000,0,,0,
1524092016.637,,0.000000e+000,3.499989e+001,-1.853566e-007,0.000000e+000,3,0.000000e+000,0.000000e+000,,,,,,,,,,,,,,32,1,4.000000e+000,7.781982e-004,0.000000e+000,0,,0,
1524092029.307,,0.000000e+000,3.499754e+001,-6.463782e-007,0.000000e+000,3,0.000000e+000,0.000000e+000,,,,,,,,,,,,,,32,1,4.000000e+000,7.896423e-004,0.000000e+000,0,,0,
1524092044.001,,0.000000e+000,3.499871e+001,9.470456e-008,0.000000e+000,2,0.000000e+000,0.000000e+000,,,,,,,,,,,,,,32,1,4.000000e+000,3.128052e-003,0.000000e+000,0,,0,
1524092056.333,,0.000000e+000,3.499911e+001,7.196371e-007,0.000000e+000,3,0.000000e+000,0.000000e+000,,,,,,,,,,,,,,32,1,4.000000e+000,2.338409e-003,0.000000e+000,0,,0,
1524092068.831,,0.000000e+000,3.499833e+001,8.998185e-007,0.000000e+000,3,1.932581e-002,0.000000e+000,,,,,,,,,,,,,,32,1,4.000000e+000,7.781982e-004,0.000000e+000,0,,0,
1524092081.574,,0.000000e+000,3.499872e+001,8.927744e-007,0.000000e+000,3,3.206761e-002,0.000000e+000,,,,,,,,,,,,,,32,1,4.000000e+000,0.000000e+000,0.000000e+000,0,,0,
1524092096.229,,0.000000e+000,3.499833e+001,1.706876e-007,0.000000e+000,2,0.000000e+000,0.000000e+000,,,,,,,,,,,,,,32,1,4.000000e+000,7.781982e-004,0.000000e+000,0,,0,
1524092110.268,,0.000000e+000,3.499754e+001,2.584830e-007,0.000000e+000,2,0.000000e+000,0.000000e+000,,,,,,,,,,,,,,32,1,4.000000e+000,7.896423e-004,0.000000e+000,0,,0,
1524092124.046,,0.000000e+000,3.499872e+001,2.683000e-007,0.000000e+000,2,0.000000e+000,0.000000e+000,,,,,,,,,,,,,,32,1,4.000000e+000,0.000000e+000,0.000000e+000,0,,0,
1524092136.298,,0.000000e+000,3.499754e+001,-2.731189e-007,0.000000e+000,3,0.000000e+000,0.000000e+000,,,,,,,,,,,,,,32,1,4.000000e+000,2.349854e-003,0.000000e+000,0,,0,
1524092148.961,,0.000000e+000,3.499793e+001,-2.777518e-007,0.000000e+000,3,0.000000e+000,0.000000e+000,,,,,,,,,,,,,,32,1,4.000000e+000,1.567841e-003,0.000000e+000,0,,0,
1524092161.639,,0.000000e+000,3.499872e+001,-3.318793e-007,0.000000e+000,3,0.000000e+000,0.000000e+000,,,,,,,,,,,,,,32,1,4.000000e+000,0.000000e+000,0.000000e+000,0,,0,
1524092176.225,,0.000000e+000,3.499833e+001,4.134238e-007,0.000000e+000,2,0.000000e+000,0.000000e+000,,,,,,,,,,,,,,32,1,4.000000e+000,7.781982e-004,0.000000e+000,0,,0,
1524092188.237,,0.000000e+000,3.499793e+001,-3.734367e-007,0.000000e+000,3,0.000000e+000,0.000000e+000,,,,,,,,,,,,,,32,1,4.000000e+000,3.131866e-003,0.000000e+000,0,,0,
1524092202.888,,0.000000e+000,3.499872e+001,3.560068e-007,0.000000e+000,2,0.000000e+000,0.000000e+000,,,,,,,,,,,,,,32,1,4.000000e+000,1.560211e-003,0.000000e+000,0,,0,
1524092216.896,,0.000000e+000,3.499989e+001,4.393660e-007,0.000000e+000,2,0.000000e+000,0.000000e+000,,,,,,,,,,,,,,32,1,4.000000e+000,7.781982e-004,0.000000e+000,0,,0,
1524092231.089,,0.000000e+000,3.499950e+001,4.552928e-007,0.000000e+000,2,0.000000e+000,0.000000e+000,,,,,,,,,,,,,,32,1,4.000000e+000,1.560211e-003,0.000000e+000,0,,0,
1524092245.180,,0.000000e+000,3.499950e+001,5.031010e-007,0.000000e+000,2,0.000000e+000,0.000000e+000,,,,,,,,,,,,,,32,1,4.000000e+000,0.000000e+000,0.000000e+000,0,,0,
1524092259.172,,0.000000e+000,3.499950e+001,5.123143e-007,0.000000e+000,2,0.000000e+000,0.000000e+000,,,,,,,,,,,,,,32,1,4.000000e+000,1.560211e-003,0.000000e+000,0,,0,
1524092271.740,,0.000000e+000,3.499950e+001,1.202031e-006,0.000000e+000,3,2.461973e-001,0.000000e+000,,,,,,,,,,,,,,32,1,4.000000e+000,1.560211e-003,0.000000e+000,0,,0,
1524092284.013,,0.000000e+000,3.499637e+001,1.070882e-006,0.000000e+000,3,8.413977e-002,0.000000e+000,,,,,,,,,,,,,,32,1,4.000000e+000,1.560211e-003,0.000000e+000,0,,0,
1524092296.328,,0.000000e+000,3.499754e+001,1.225076e-006,0.000000e+000,3,2.254016e-001,0.000000e+000,,,,,,,,,,,,,,32,1,4.000000e+000,7.896423e-004,0.000000e+000,0,,0,
1524092309.376,,0.000000e+000,3.499794e+001,1.222812e-006,0.000000e+000,3,2.596444e-001,0.000000e+000,,,,,,,,,,,,,,32,1,4.000000e+000,0.000000e+000,0.000000e+000,0,,0,
1524092322.108,,0.000000e+000,3.499872e+001,1.206717e-006,0.000000e+000,3,2.423818e-001,0.000000e+000,,,,,,,,,,,,,,32,1,4.000000e+000,1.560211e-003,0.000000e+000,0,,0,
1524092334.798,,0.000000e+000,3.499872e+001,1.246962e-006,0.000000e+000,3,2.569900e-001,0.000000e+000,,,,,,,,,,,,,,32,1,4.000000e+000,0.000000e+000,0.000000e+000,0,,0,
1524092347.481,,0.000000e+000,3.500067e+001,1.280728e-006,0.000000e+000,3,2.579237e-001,0.000000e+000,,,,,,,,,,,,,,32,1,4.000000e+000,2.338409e-003,0.000000e+000,0,,0,
1524092360.181,,0.000000e+000,3.499637e+001,1.261088e-006,0.000000e+000,3,2.644020e-001,0.000000e+000,,,,,,,,,,,,,,32,1,4.000000e+000,6.259918e-003,0.000000e+000,0,,0,
1524092372.719,,0.000000e+000,3.499911e+001,1.287472e-006,0.000000e+000,3,2.846414e-001,0.000000e+000,,,,,,,,,,,,,,32,1,4.000000e+000,7.820129e-004,0.000000e+000,0,,0,
1524092385.002,,0.000000e+000,3.499911e+001,1.274459e-006,0.000000e+000,3,2.643919e-001,0.000000e+000,,,,,,,,,,,,,,32,1,4.000000e+000,3.910065e-003,0.000000e+000,0,,0,
1524092397.454,,0.000000e+000,3.500028e+001,1.239069e-006,0.000000e+000,3,2.706810e-001,0.000000e+000,,,,,,,,,,,,,,32,1,4.000000e+000,1.560211e-003,0.000000e+000,0,,0,
1524092410.182,,0.000000e+000,3.499911e+001,1.306704e-006,0.000000e+000,3,3.239033e-001,0.000000e+000,,,,,,,,,,,,,,32,1,4.000000e+000,7.820129e-004,0.000000e+000,0,,0,
1524092422.375,,0.000000e+000,3.499872e+001,1.340602e-006,0.000000e+000,3,3.898036e-001,0.000000e+000,,,,,,,,,,,,,,32,1,4.000000e+000,0.000000e+000,0.000000e+000,0,,0,
1524092434.830,,0.000000e+000,3.499833e+001,1.314249e-006,0.000000e+000,3,3.288078e-001,0.000000e+000,,,,,,,,,,,,,,32,1,4.000000e+000,7.781982e-004,0.000000e+000,0,,0,
1524092446.963,,0.000000e+000,3.499794e+001,1.286156e-006,0.000000e+000,3,2.981522e-001,0.000000e+000,,,,,,,,,,,,,,32,1,4.000000e+000,0.000000e+000,0.000000e+000,0,,0,
1524092459.640,,0.000000e+000,3.499833e+001,1.266723e-006,0.000000e+000,3,3.063771e-001,0.000000e+000,,,,,,,,,,,,,,32,1,4.000000e+000,7.781982e-004,0.000000e+000,0,,0,
1524092472.360,,0.000000e+000,3.499833e+001,1.282248e-006,0.000000e+000,3,3.106390e-001,0.000000e+000,,,,,,,,,,,,,,32,1,4.000000e+000,7.781982e-004,0.000000e+000,0,,0,
1524092484.801,,0.000000e+000,3.499794e+001,1.312330e-006,0.000000e+000,3,3.168828e-001,0.000000e+000,,,,,,,,,,,,,,32,1,4.000000e+000,0.000000e+000,0.000000e+000,0,,0,
1524092497.096,,0.000000e+000,3.499911e+001,1.305870e-006,0.000000e+000,3,3.080356e-001,0.000000e+000,,,,,,,,,,,,,,32,1,4.000000e+000,7.820129e-004,0.000000e+000,0,,0,
1524092509.759,,0.000000e+000,3.499872e+001,1.365461e-006,0.000000e+000,3,3.524733e-001,0.000000e+000,,,,,,,,,,,,,,32,1,4.000000e+000,0.000000e+000,0.000000e+000,0,,0,
1524092522.351,,0.000000e+000,3.499794e+001,1.428001e-006,0.000000e+000,3,3.316956e-001,0.000000e+000,,,,,,,,,,,,,,32,1,4.000000e+000,0.000000e+000,0.000000e+000,0,,0,
1524092534.619,,0.000000e+000,3.499833e+001,1.528007e-006,0.000000e+000,3,3.970549e-001,0.000000e+000,,,,,,,,,,,,,,32,1,4.000000e+000,7.781982e-004,0.000000e+000,0,,0,
1524092547.079,,0.000000e+000,3.499833e+001,1.420988e-006,0.000000e+000,3,3.785231e-001,0.000000e+000,,,,,,,,,,,,,,32,1,4.000000e+000,7.781982e-004,0.000000e+000,0,,0,
1524092560.044,,0.000000e+000,3.499833e+001,1.403239e-006,0.000000e+000,3,3.469916e-001,0.000000e+000,,,,,,,,,,,,,,32,1,4.000000e+000,7.781982e-004,0.000000e+000,0,,0,
1524092572.032,,0.000000e+000,3.499872e+001,1.369355e-006,0.000000e+000,3,3.274687e-001,0.000000e+000,,,,,,,,,,,,,,32,1,4.000000e+000,0.000000e+000,0.000000e+000,0,,0,
1524092584.707,,0.000000e+000,3.499911e+001,1.426399e-006,0.000000e+000,3,3.958448e-001,0.000000e+000,,,,,,,,,,,,,,32,1,4.000000e+000,7.820129e-004,0.000000e+000,0,,0,
1524092597.397,,0.000000e+000,3.499872e+001,1.440856e-006,0.000000e+000,3,3.968128e-001,0.000000e+000,,,,,,,,,,,,,,32,1,4.000000e+000,1.560211e-003,0.000000e+000,0,,0,
1524092609.990,,0.000000e+000,3.499872e+001,1.401288e-006,0.000000e+000,3,3.857192e-001,0.000000e+000,,,,,,,,,,,,,,32,1,4.000000e+000,0.000000e+000,0.000000e+000,0,,0,
1524092622.508,,0.000000e+000,3.499793e+001,1.486982e-006,0.000000e+000,3,3.761840e-001,0.000000e+000,,,,,,,,,,,,,,32,1,4.000000e+000,3.131866e-003,0.000000e+000,0,,0,
1524092635.305,,0.000000e+000,3.499989e+001,1.549064e-006,0.000000e+000,3,4.053082e-001,0.000000e+000,,,,,,,,,,,,,,32,1,4.000000e+000,3.898621e-003,0.000000e+000,0,,0,
1524092647.841,,0.000000e+000,3.499911e+001,1.444931e-006,0.000000e+000,3,3.138142e-001,0.000000e+000,,,,,,,,,,,,,,32,1,4.000000e+000,7.820129e-004,0.000000e+000,0,,0,
1524092660.503,,0.000000e+000,3.499833e+001,1.533243e-006,0.000000e+000,3,4.498580e-001,0.000000e+000,,,,,,,,,,,,,,32,1,4.000000e+000,7.781982e-004,0.000000e+000,0,,0,
1524092673.166,,0.000000e+000,3.499833e+001,1.511991e-006,0.000000e+000,3,3.953528e-001,0.000000e+000,,,,,,,,,,,,,,32,1,4.000000e+000,7.781982e-004,0.000000e+000,0,,0,
1524092685.856,,0.000000e+000,3.499794e+001,1.473503e-006,0.000000e+000,3,4.004487e-001,0.000000e+000,,,,,,,,,,,,,,32,1,4.000000e+000,0.000000e+000,0.000000e+000,0,,0,
1524092698.571,,0.000000e+000,3.499833e+001,1.577584e-006,0.000000e+000,3,4.316135e-001,0.000000e+000,,,,,,,,,,,,,,32,1,4.000000e+000,7.781982e-004,0.000000e+000,0,,0,
1524092711.084,,0.000000e+000,3.499793e+001,1.554633e-006,0.000000e+000,3,4.080738e-001,0.000000e+000,,,,,,,,,,,,,,32,1,4.000000e+000,1.567841e-003,0.000000e+000,0,,0,
1524092723.654,,0.000000e+000,3.499754e+001,1.603245e-006,0.000000e+000,3,4.613454e-001,0.000000e+000,,,,,,,,,,,,,,32,1,4.000000e+000,7.896423e-004,0.000000e+000,0,,0,
1524092735.984,,0.000000e+000,3.499833e+001,1.479252e-006,0.000000e+000,3,3.801965e-001,0.000000e+000,,,,,,,,,,,,,,32,1,4.000000e+000,7.781982e-004,0.000000e+000,0,,0,
1524092748.647,,0.000000e+000,3.499950e+001,1.558012e-006,0.000000e+000,3,4.188079e-001,0.000000e+000,,,,,,,,,,,,,,32,1,4.000000e+000,0.000000e+000,0.000000e+000,0,,0,
1524092761.325,,0.000000e+000,3.499833e+001,1.559880e-006,0.000000e+000,3,4.375321e-001,0.000000e+000,,,,,,,,,,,,,,32,1,4.000000e+000,7.781982e-004,0.000000e+000,0,,0,
1524092774.010,,0.000000e+000,3.499793e+001,1.556371e-006,0.000000e+000,3,4.287842e-001,0.000000e+000,,,,,,,,,,,,,,32,1,4.000000e+000,1.567841e-003,0.000000e+000,0,,0,
1524092787.250,,0.000000e+000,3.499793e+001,1.573521e-006,0.000000e+000,3,4.433931e-001,0.000000e+000,,,,,,,,,,,,,,32,1,4.000000e+000,1.567841e-003,0.000000e+000,0,,0,
1524092799.810,,0.000000e+000,3.499754e+001,1.570543e-006,0.000000e+000,3,3.826584e-001,0.000000e+000,,,,,,,,,,,,,,32,1,4.000000e+000,7.896423e-004,0.000000e+000,0,,0,
1524092812.485,,0.000000e+000,3.499872e+001,1.567962e-006,0.000000e+000,3,4.439143e-001,0.000000e+000,,,,,,,,,,,,,,32,1,4.000000e+000,0.000000e+000,0.000000e+000,0,,0,
1524092824.446,,0.000000e+000,3.499872e+001,1.520047e-006,0.000000e+000,3,4.173031e-001,0.000000e+000,,,,,,,,,,,,,,32,1,4.000000e+000,0.000000e+000,0.000000e+000,0,,0,
1524092837.606,,0.000000e+000,3.499950e+001,1.549603e-006,0.000000e+000,3,3.905435e-001,0.000000e+000,,,,,,,,,,,,,,32,1,4.000000e+000,1.560211e-003,0.000000e+000,0,,0,
1524092850.181,,0.000000e+000,3.499833e+001,1.564030e-006,0.000000e+000,3,4.276472e-001,0.000000e+000,,,,,,,,,,,,,,32,1,4.000000e+000,7.781982e-004,0.000000e+000,0,,0,
1524092862.871,,0.000000e+000,3.499794e+001,1.596052e-006,0.000000e+000,3,4.259186e-001,0.000000e+000,,,,,,,,,,,,,,32,1,4.000000e+000,0.000000e+000,0.000000e+000,0,,0,
1524092875.574,,0.000000e+000,3.499911e+001,1.663369e-006,0.000000e+000,3,4.589000e-001,0.000000e+000,,,,,,,,,,,,,,32,1,4.000000e+000,2.338409e-003,0.000000e+000,0,,0,
1524092888.267,,0.000000e+000,3.499871e+001,1.592195e-006,0.000000e+000,3,4.306298e-001,0.000000e+000,,,,,,,,,,,,,,32,1,4.000000e+000,3.128052e-003,0.000000e+000,0,,0,
1524092901.024,,0.000000e+000,3.499794e+001,1.637871e-006,0.000000e+000,3,4.603277e-001,0.000000e+000,,,,,,,,,,,,,,32,1,4.000000e+000,0.000000e+000,0.000000e+000,0,,0,
1524092913.644,,0.000000e+000,3.499950e+001,1.660335e-006,0.000000e+000,3,4.698523e-001,0.000000e+000,,,,,,,,,,,,,,32,1,4.000000e+000,1.560211e-003,0.000000e+000,0,,0,
1524092926.340,,0.000000e+000,3.499833e+001,1.657056e-006,0.000000e+000,3,4.679669e-001,0.000000e+000,,,,,,,,,,,,,,32,1,4.000000e+000,2.349854e-003,0.000000e+000,0,,0,
1524092939.087,,0.000000e+000,3.499833e+001,1.649672e-006,0.000000e+000,3,4.528534e-001,0.000000e+000,,,,,,,,,,,,,,32,1,4.000000e+000,2.349854e-003,0.000000e+000,0,,0,
1524092951.740,,0.000000e+000,3.499872e+001,1.594645e-006,0.000000e+000,3,3.991407e-001,0.000000e+000,,,,,,,,,,,,,,32,1,4.000000e+000,1.560211e-003,0.000000e+000,0,,0,
1524092965.060,,0.000000e+000,3.499872e+001,1.637336e-006,0.000000e+000,3,4.480285e-001,0.000000e+000,,,,,,,,,,,,,,32,1,4.000000e+000,1.560211e-003,0.000000e+000,0,,0,
1524092977.400,,0.000000e+000,3.499911e+001,1.576533e-006,0.000000e+000,3,4.719992e-001,0.000000e+000,,,,,,,,,,,,,,32,1,4.000000e+000,2.338409e-003,0.000000e+000,0,,0,
1524092990.298,,0.000000e+000,3.499833e+001,1.653142e-006,0.000000e+000,3,4.777350e-001,0.000000e+000,,,,,,,,,,,,,,32,1,4.000000e+000,7.781982e-004,0.000000e+000,0,,0,
1524093002.726,,0.000000e+000,3.499911e+001,1.651264e-006,0.000000e+000,3,4.682728e-001,0.000000e+000,,,,,,,,,,,,,,32,1,4.000000e+000,2.338409e-003,0.000000e+000,0,,0,
1524093014.821,,0.000000e+000,3.499911e+001,1.715049e-006,0.000000e+000,3,4.764498e-001,0.000000e+000,,,,,,,,,,,,,,32,1,4.000000e+000,7.820129e-004,0.000000e+000,0,,0,
1524093027.404,,0.000000e+000,3.499833e+001,1.673495e-006,0.000000e+000,3,4.680582e-001,0.000000e+000,,,,,,,,,,,,,,32,1,4.000000e+000,7.781982e-004,0.000000e+000,0,,0,
1524093040.631,,0.000000e+000,3.500067e+001,1.648113e-006,0.000000e+000,3,4.734365e-001,0.000000e+000,,,,,,,,,,,,,,32,1,4.000000e+000,2.338409e-003,0.000000e+000,0,,0,
1524093053.032,,0.000000e+000,3.499872e+001,1.727961e-006,0.000000e+000,3,4.680787e-001,0.000000e+000,,,,,,,,,,,,,,32,1,4.000000e+000,1.560211e-003,0.000000e+000,0,,0,
1524093065.919,,0.000000e+000,3.499911e+001,1.693510e-006,0.000000e+000,3,4.847620e-001,0.000000e+000,,,,,,,,,,,,,,32,1,4.000000e+000,7.820129e-004,0.000000e+000,0,,0,
1524093077.997,,0.000000e+000,3.499833e+001,1.729510e-006,0.000000e+000,3,4.950457e-001,0.000000e+000,,,,,,,,,,,,,,32,1,4.000000e+000,7.781982e-004,0.000000e+000,0,,0,
1524093090.352,,0.000000e+000,3.499872e+001,1.659583e-006,0.000000e+000,3,4.556223e-001,0.000000e+000,,,,,,,,,,,,,,32,1,4.000000e+000,0.000000e+000,0.000000e+000,0,,0,
1524093102.810,,0.000000e+000,3.499833e+001,1.735451e-006,0.000000e+000,3,4.580331e-001,0.000000e+000,,,,,,,,,,,,,,32,1,4.000000e+000,2.349854e-003,0.000000e+000,0,,0,
1524093115.055,,0.000000e+000,3.499833e+001,1.717683e-006,0.000000e+000,3,4.817297e-001,0.000000e+000,,,,,,,,,,,,,,32,1,4.000000e+000,7.781982e-004,0.000000e+000,0,,0,
1524093127.610,,0.000000e+000,3.499833e+001,1.772135e-006,0.000000e+000,3,5.034909e-001,0.000000e+000,,,,,,,,,,,,,,32,1,4.000000e+000,7.781982e-004,0.000000e+000,0,,0,
1524093140.298,,0.000000e+000,3.499794e+001,1.772725e-006,0.000000e+000,3,4.904899e-001,0.000000e+000,,,,,,,,,,,,,,32,1,4.000000e+000,0.000000e+000,0.000000e+000,0,,0,
1524093153.005,,0.000000e+000,3.499794e+001,1.752906e-006,0.000000e+000,3,4.890065e-001,0.000000e+000,,,,,,,,,,,,,,32,1,4.000000e+000,0.000000e+000,0.000000e+000,0,,0,
1524093166.483,,0.000000e+000,3.499794e+001,1.760036e-006,0.000000e+000,3,4.969802e-001,0.000000e+000,,,,,,,,,,,,,,32,1,4.000000e+000,0.000000e+000,0.000000e+000,0,,0,
1524093179.116,,0.000000e+000,3.499872e+001,1.702363e-006,0.000000e+000,3,4.840017e-001,0.000000e+000,,,,,,,,,,,,,,32,1,4.000000e+000,0.000000e+000,0.000000e+000,0,,0,
1524093191.791,,0.000000e+000,3.499794e+001,1.719601e-006,0.000000e+000,3,4.719888e-001,0.000000e+000,,,,,,,,,,,,,,32,1,4.000000e+000,0.000000e+000,0.000000e+000,0,,0,
1524093204.471,,0.000000e+000,3.499911e+001,1.739035e-006,0.000000e+000,3,4.817747e-001,0.000000e+000,,,,,,,,,,,,,,32,1,4.000000e+000,7.820129e-004,0.000000e+000,0,,0,
1524093217.166,,0.000000e+000,3.499793e+001,1.772288e-006,0.000000e+000,3,4.903205e-001,0.000000e+000,,,,,,,,,,,,,,32,1,4.000000e+000,1.567841e-003,0.000000e+000,0,,0,
1524093229.809,,0.000000e+000,3.499911e+001,1.758587e-006,0.000000e+000,3,5.038840e-001,0.000000e+000,,,,,,,,,,,,,,32,1,4.000000e+000,7.820129e-004,0.000000e+000,0,,0,
1524093242.292,,0.000000e+000,3.499911e+001,1.822157e-006,0.000000e+000,3,4.916943e-001,0.000000e+000,,,,,,,,,,,,,,32,1,4.000000e+000,7.820129e-004,0.000000e+000,0,,0,
1524093254.977,,0.000000e+000,3.499794e+001,1.755998e-006,0.000000e+000,3,4.543627e-001,0.000000e+000,,,,,,,,,,,,,,32,1,4.000000e+000,0.000000e+000,0.000000e+000,0,,0,
1524093267.682,,0.000000e+000,3.499833e+001,1.780353e-006,0.000000e+000,3,4.945744e-001,0.000000e+000,,,,,,,,,,,,,,32,1,4.000000e+000,7.781982e-004,0.000000e+000,0,,0,
1524093280.177,,0.000000e+000,3.499950e+001,1.757362e-006,0.000000e+000,3,4.649074e-001,0.000000e+000,,,,,,,,,,,,,,32,1,4.000000e+000,1.560211e-003,0.000000e+000,0,,0,
1524093292.755,,0.000000e+000,3.499598e+001,1.761483e-006,0.000000e+000,3,4.929913e-001,0.000000e+000,,,,,,,,,,,,,,32,1,4.000000e+000,7.041931e-003,0.000000e+000,0,,0,
1524093306.070,,0.000000e+000,3.499872e+001,1.863984e-006,0.000000e+000,3,5.209830e-001,0.000000e+000,,,,,,,,,,,,,,32,1,4.000000e+000,0.000000e+000,0.000000e+000,0,,0,
1524093318.655,,0.000000e+000,3.499872e+001,1.794641e-006,0.000000e+000,3,5.146685e-001,0.000000e+000,,,,,,,,,,,,,,32,1,4.000000e+000,0.000000e+000,0.000000e+000,0,,0,
1524093331.091,,0.000000e+000,3.499872e+001,1.888637e-006,0.000000e+000,3,5.300664e-001,0.000000e+000,,,,,,,,,,,,,,32,1,4.000000e+000,0.000000e+000,0.000000e+000,0,,0,
1524093343.808,,0.000000e+000,3.499911e+001,1.819599e-006,0.000000e+000,3,5.071211e-001,0.000000e+000,,,,,,,,,,,,,,32,1,4.000000e+000,7.820129e-004,0.000000e+000,0,,0,
1524093356.098,,0.000000e+000,3.499911e+001,1.850513e-006,0.000000e+000,3,4.977468e-001,0.000000e+000,,,,,,,,,,,,,,32,1,4.000000e+000,7.820129e-004,0.000000e+000,0,,0,
1524093368.654,,0.000000e+000,3.499911e+001,1.757036e-006,0.000000e+000,3,4.821506e-001,0.000000e+000,,,,,,,,,,,,,,32,1,4.000000e+000,2.338409e-003,0.000000e+000,0,,0,
1524093382.081,,0.000000e+000,3.499911e+001,1.834660e-006,0.000000e+000,3,5.126584e-001,0.000000e+000,,,,,,,,,,,,,,32,1,4.000000e+000,7.820129e-004,0.000000e+000,0,,0,
1524093394.774,,0.000000e+000,3.499911e+001,1.843720e-006,0.000000e+000,3,5.194142e-001,0.000000e+000,,,,,,,,,,,,,,32,1,4.000000e+000,7.820129e-004,0.000000e+000,0,,0,
1524093407.664,,0.000000e+000,3.499911e+001,1.788602e-006,0.000000e+000,3,5.156503e-001,0.000000e+000,,,,,,,,,,,,,,32,1,4.000000e+000,7.820129e-004,0.000000e+000,0,,0,
1524093420.354,,0.000000e+000,3.499911e+001,1.785339e-006,0.000000e+000,3,4.910181e-001,0.000000e+000,,,,,,,,,,,,,,32,1,4.000000e+000,7.820129e-004,0.000000e+000,0,,0,
1524093433.005,,0.000000e+000,3.499950e+001,1.742887e-006,0.000000e+000,3,4.981734e-001,0.000000e+000,,,,,,,,,,,,,,32,1,4.000000e+000,0.000000e+000,0.000000e+000,0,,0,
1524093445.602,,0.000000e+000,3.499911e+001,1.824462e-006,0.000000e+000,3,4.888020e-001,0.000000e+000,,,,,,,,,,,,,,32,1,4.000000e+000,7.820129e-004,0.000000e+000,0,,0,
1524093457.885,,0.000000e+000,3.499872e+001,1.778662e-006,0.000000e+000,3,4.954850e-001,0.000000e+000,,,,,,,,,,,,,,32,1,4.000000e+000,0.000000e+000,0.000000e+000,0,,0,
1524093470.548,,0.000000e+000,3.499911e+001,1.860520e-006,0.000000e+000,3,5.101610e-001,0.000000e+000,,,,,,,,,,,,,,32,1,4.000000e+000,7.820129e-004,0.000000e+000,0,,0,
1524093483.045,,0.000000e+000,3.499911e+001,1.817959e-006,0.000000e+000,3,5.091224e-001,0.000000e+000,,,,,,,,,,,,,,32,1,4.000000e+000,7.820129e-004,0.000000e+000,0,,0,
1524093495.748,,0.000000e+000,3.499833e+001,1.876487e-006,0.000000e+000,3,5.252486e-001,0.000000e+000,,,,,,,,,,,,,,32,1,4.000000e+000,7.781982e-004,0.000000e+000,0,,0,
1524093508.421,,0.000000e+000,3.499794e+001,1.886071e-006,0.000000e+000,3,5.148011e-001,0.000000e+000,,,,,,,,,,,,,,32,1,4.000000e+000,0.000000e+000,0.000000e+000,0,,0,
1524093521.108,,0.000000e+000,3.499794e+001,1.893110e-006,0.000000e+000,3,5.225459e-001,0.000000e+000,,,,,,,,,,,,,,32,1,4.000000e+000,0.000000e+000,0.000000e+000,0,,0,
1524093533.799,,0.000000e+000,3.499833e+001,1.933536e-006,0.000000e+000,3,5.291653e-001,0.000000e+000,,,,,,,,,,,,,,32,1,4.000000e+000,7.781982e-004,0.000000e+000,0,,0,
1524093546.634,,0.000000e+000,3.499872e+001,1.836260e-006,0.000000e+000,3,5.239693e-001,0.000000e+000,,,,,,,,,,,,,,32,1,4.000000e+000,0.000000e+000,0.000000e+000,0,,0,
1524093559.386,,0.000000e+000,3.499872e+001,1.971750e-006,0.000000e+000,3,5.385187e-001,0.000000e+000,,,,,,,,,,,,,,32,1,4.000000e+000,0.000000e+000,0.000000e+000,0,,0,
1524093572.057,,0.000000e+000,3.499911e+001,1.858865e-006,0.000000e+000,3,5.145363e-001,0.000000e+000,,,,,,,,,,,,,,32,1,4.000000e+000,7.820129e-004,0.000000e+000,0,,0,
1524093584.747,,0.000000e+000,3.499911e+001,1.892457e-006,0.000000e+000,3,5.368944e-001,0.000000e+000,,,,,,,,,,,,,,32,1,4.000000e+000,7.820129e-004,0.000000e+000,0,,0,
1524093597.407,,0.000000e+000,3.499793e+001,1.893985e-006,0.000000e+000,3,5.234852e-001,0.000000e+000,,,,,,,,,,,,,,32,1,4.000000e+000,1.567841e-003,0.000000e+000,0,,0,
1524093610.062,,0.000000e+000,3.499754e+001,1.884599e-006,0.000000e+000,3,5.129085e-001,0.000000e+000,,,,,,,,,,,,,,32,1,4.000000e+000,7.896423e-004,0.000000e+000,0,,0,
1524093622.795,,0.000000e+000,3.499794e+001,1.886358e-006,0.000000e+000,3,5.223996e-001,0.000000e+000,,,,,,,,,,,,,,32,1,4.000000e+000,0.000000e+000,0.000000e+000,0,,0,
1524093635.595,,0.000000e+000,3.499833e+001,1.930146e-006,0.000000e+000,3,5.400403e-001,0.000000e+000,,,,,,,,,,,,,,32,1,4.000000e+000,7.781982e-004,0.000000e+000,0,,0,
1524093648.370,,0.000000e+000,3.499989e+001,1.877835e-006,0.000000e+000,3,5.225934e-001,0.000000e+000,,,,,,,,,,,,,,32,1,4.000000e+000,7.781982e-004,0.000000e+000,0,,0,
1524093661.065,,0.000000e+000,3.499715e+001,1.880176e-006,0.000000e+000,3,5.345838e-001,0.000000e+000,,,,,,,,,,,,,,32,1,4.000000e+000,0.000000e+000,0.000000e+000,0,,0,
1524093673.778,,0.000000e+000,3.499833e+001,1.911511e-006,0.000000e+000,3,5.342878e-001,0.000000e+000,,,,,,,,,,,,,,32,1,4.000000e+000,2.349854e-003,0.000000e+000,0,,0,
1524093686.551,,0.000000e+000,3.500028e+001,1.872216e-006,0.000000e+000,3,5.208626e-001,0.000000e+000,,,,,,,,,,,,,,32,1,4.000000e+000,0.000000e+000,0.000000e+000,0,,0,
1524093699.171,,0.000000e+000,3.499793e+001,1.825826e-006,0.000000e+000,3,5.265257e-001,0.000000e+000,,,,,,,,,,,,,,32,1,4.000000e+000,4.688263e-003,0.000000e+000,0,,0,
1524093712.624,,0.000000e+000,3.499911e+001,1.934328e-006,0.000000e+000,3,5.366715e-001,0.000000e+000,,,,,,,,,,,,,,32,1,4.000000e+000,7.820129e-004,0.000000e+000,0,,0,
1524093725.324,,0.000000e+000,3.499872e+001,1.831034e-006,0.000000e+000,3,5.435565e-001,0.000000e+000,,,,,,,,,,,,,,32,1,4.000000e+000,0.000000e+000,0.000000e+000,0,,0,
1524093738.007,,0.000000e+000,3.500028e+001,1.914768e-006,0.000000e+000,3,5.312756e-001,0.000000e+000,,,,,,,,,,,,,,32,1,4.000000e+000,1.560211e-003,0.000000e+000,0,,0,
1524093750.704,,0.000000e+000,3.499794e+001,1.975138e-006,0.000000e+000,3,5.607174e-001,0.000000e+000,,,,,,,,,,,,,,32,1,4.000000e+000,0.000000e+000,0.000000e+000,0,,0,
1524093763.399,,0.000000e+000,3.499989e+001,1.927918e-006,0.000000e+000,3,5.422674e-001,0.000000e+000,,,,,,,,,,,,,,32,1,4.000000e+000,7.781982e-004,0.000000e+000,0,,0,
1524093776.087,,0.000000e+000,3.500067e+001,1.849011e-006,0.000000e+000,3,4.819335e-001,0.000000e+000,,,,,,,,,,,,,,32,1,4.000000e+000,2.338409e-003,0.000000e+000,0,,0,
1524093788.772,,0.000000e+000,3.499911e+001,1.920832e-006,0.000000e+000,3,5.504839e-001,0.000000e+000,,,,,,,,,,,,,,32,1,4.000000e+000,7.820129e-004,0.000000e+000,0,,0,
1524093801.468,,0.000000e+000,3.499950e+001,1.936237e-006,0.000000e+000,3,5.474482e-001,0.000000e+000,,,,,,,,,,,,,,32,1,4.000000e+000,1.560211e-003,0.000000e+000,0,,0,
1524093814.155,,0.000000e+000,3.499754e+001,1.946610e-006,0.000000e+000,3,5.590957e-001,0.000000e+000,,,,,,,,,,,,,,32,1,4.000000e+000,7.896423e-004,0.000000e+000,0,,0,
1524093826.903,,0.000000e+000,3.499911e+001,1.899760e-006,0.000000e+000,3,5.297993e-001,0.000000e+000,,,,,,,,,,,,,,32,1,4.000000e+000,7.820129e-004,0.000000e+000,0,,0,
1524093839.181,,0.000000e+000,3.499715e+001,1.872125e-006,0.000000e+000,3,5.266600e-001,0.000000e+000,,,,,,,,,,,,,,32,1,4.000000e+000,3.128052e-003,0.000000e+000,0,,0,
1524093852.213,,0.000000e+000,3.499950e+001,1.906474e-006,0.000000e+000,3,5.313858e-001,0.000000e+000,,,,,,,,,,,,,,32,1,4.000000e+000,1.560211e-003,0.000000e+000,0,,0,
1524093864.683,,0.000000e+000,3.499754e+001,1.967264e-006,0.000000e+000,3,5.514255e-001,0.000000e+000,,,,,,,,,,,,,,32,1,4.000000e+000,2.349854e-003,0.000000e+000,0,,0,
1524093876.726,,0.000000e+000,3.499911e+001,1.906628e-006,0.000000e+000,3,5.291961e-001,0.000000e+000,,,,,,,,,,,,,,32,1,4.000000e+000,7.820129e-004,0.000000e+000,0,,0,
1524093889.499,,0.000000e+000,3.499872e+001,1.933384e-006,0.000000e+000,3,5.519076e-001,0.000000e+000,,,,,,,,,,,,,,32,1,4.000000e+000,0.000000e+000,0.000000e+000,0,,0,
1524093901.969,,0.000000e+000,3.500067e+001,1.912055e-006,0.000000e+000,3,5.465955e-001,0.000000e+000,,,,,,,,,,,,,,32,1,4.000000e+000,3.910065e-003,0.000000e+000,0,,0,
1524093914.679,,0.000000e+000,3.500067e+001,1.922949e-006,0.000000e+000,3,5.451647e-001,0.000000e+000,,,,,,,,,,,,,,32,1,4.000000e+000,7.820129e-004,0.000000e+000,0,,0,
1524093927.092,,0.000000e+000,3.499989e+001,1.917373e-006,0.000000e+000,3,5.303041e-001,0.000000e+000,,,,,,,,,,,,,,32,1,4.000000e+000,2.342224e-003,0.000000e+000,0,,0,
1524093939.789,,0.000000e+000,3.499872e+001,1.935951e-006,0.000000e+000,3,5.475428e-001,0.000000e+000,,,,,,,,,,,,,,32,1,4.000000e+000,0.000000e+000,0.000000e+000,0,,0,
1524093952.415,,0.000000e+000,3.499911e+001,1.963233e-006,0.000000e+000,3,5.233409e-001,0.000000e+000,,,,,,,,,,,,,,32,1,4.000000e+000,7.820129e-004,0.000000e+000,0,,0,
1524093964.880,,0.000000e+000,3.499754e+001,1.985905e-006,0.000000e+000,3,5.788603e-001,0.000000e+000,,,,,,,,,,,,,,32,1,4.000000e+000,3.910065e-003,0.000000e+000,0,,0,
1524093977.578,,0.000000e+000,3.499715e+001,1.961744e-006,0.000000e+000,3,5.556919e-001,0.000000e+000,,,,,,,,,,,,,,32,1,4.000000e+000,3.128052e-003,0.000000e+000,0,,0,
1524093990.240,,0.000000e+000,3.499950e+001,1.952310e-006,0.000000e+000,3,5.379546e-001,0.000000e+000,,,,,,,,,,,,,,32,1,4.000000e+000,1.560211e-003,0.000000e+000,0,,0,
1524094002.758,,0.000000e+000,3.499872e+001,1.960799e-006,0.000000e+000,3,5.415937e-001,0.000000e+000,,,,,,,,,,,,,,32,1,4.000000e+000,1.560211e-003,0.000000e+000,0,,0,
1524094015.336,,0.000000e+000,3.499833e+001,2.018125e-006,0.000000e+000,3,5.742931e-001,0.000000e+000,,,,,,,,,,,,,,32,1,4.000000e+000,2.349854e-003,0.000000e+000,0,,0,
1524094027.796,,0.000000e+000,3.499871e+001,1.948152e-006,0.000000e+000,3,5.483543e-001,0.000000e+000,,,,,,,,,,,,,,32,1,4.000000e+000,3.128052e-003,0.000000e+000,0,,0,
1524094040.508,,0.000000e+000,3.499872e+001,1.988633e-006,0.000000e+000,3,5.676125e-001,0.000000e+000,,,,,,,,,,,,,,32,1,4.000000e+000,7.820129e-003,0.000000e+000,0,,0,
1524094053.981,,0.000000e+000,3.499793e+001,2.063447e-006,0.000000e+000,3,5.430313e-001,0.000000e+000,,,,,,,,,,,,,,32,1,4.000000e+000,1.567841e-003,0.000000e+000,0,,0,
1524094066.689,,0.000000e+000,3.499638e+001,1.951209e-006,0.000000e+000,3,5.370713e-001,0.000000e+000,,,,,,,,,,,,,,32,1,4.000000e+000,4.688263e-003,0.000000e+000,0,,0,
1524094079.362,,0.000000e+000,3.499833e+001,1.901947e-006,0.000000e+000,3,5.188022e-001,0.000000e+000,,,,,,,,,,,,,,32,1,4.000000e+000,5.470276e-003,0.000000e+000,0,,0,
1524094092.054,,0.000000e+000,3.500146e+001,1.951998e-006,0.000000e+000,3,5.382434e-001,0.000000e+000,,,,,,,,,,,,,,32,1,4.000000e+000,3.910065e-003,0.000000e+000,0,,0,
1524094104.622,,0.000000e+000,3.499950e+001,1.898871e-006,0.000000e+000,3,5.235851e-001,0.000000e+000,,,,,,,,,,,,,,32,1,4.000000e+000,4.688263e-003,0.000000e+000,0,,0,
1524094117.762,,0.000000e+000,3.499872e+001,2.015102e-006,0.000000e+000,3,5.585970e-001,0.000000e+000,,,,,,,,,,,,,,32,1,4.000000e+000,1.560211e-003,0.000000e+000,0,,0,
1524094130.515,,0.000000e+000,3.499911e+001,2.019612e-006,0.000000e+000,3,5.492468e-001,0.000000e+000,,,,,,,,,,,,,,32,1,4.000000e+000,7.820129e-004,0.000000e+000,0,,0,
1524094143.207,,0.000000e+000,3.499989e+001,1.944561e-006,0.000000e+000,3,5.528041e-001,0.000000e+000,,,,,,,,,,,,,,32,1,4.000000e+000,7.781982e-004,0.000000e+000,0,,0,
1524094156.295,,0.000000e+000,3.499793e+001,2.006609e-006,0.000000e+000,3,5.630525e-001,0.000000e+000,,,,,,,,,,,,,,32,1,4.000000e+000,1.567841e-003,0.000000e+000,0,,0,
1524094168.748,,0.000000e+000,3.499989e+001,1.980100e-006,0.000000e+000,3,5.481671e-001,0.000000e+000,,,,,,,,,,,,,,32,1,4.000000e+000,7.781982e-004,0.000000e+000,0,,0,
1524094181.363,,0.000000e+000,3.500028e+001,2.009913e-006,0.000000e+000,3,5.555794e-001,0.000000e+000,,,,,,,,,,,,,,32,1,4.000000e+000,1.560211e-003,0.000000e+000,0,,0,
1524094194.071,,0.000000e+000,3.499676e+001,1.988578e-006,0.000000e+000,3,5.531646e-001,0.000000e+000,,,,,,,,,,,,,,32,1,4.000000e+000,7.820129e-004,0.000000e+000,0,,0,
1524094206.548,,0.000000e+000,3.499871e+001,1.929674e-006,0.000000e+000,3,5.576643e-001,0.000000e+000,,,,,,,,,,,,,,32,1,4.000000e+000,4.692078e-003,0.000000e+000,0,,0,
1524094219.249,,0.000000e+000,3.499754e+001,1.983493e-006,0.000000e+000,3,5.567295e-001,0.000000e+000,,,,,,,,,,,,,,32,1,4.000000e+000,7.030487e-003,0.000000e+000,0,,0,
1524094232.196,,0.000000e+000,3.499638e+001,1.962911e-006,0.000000e+000,3,5.251243e-001,0.000000e+000,,,,,,,,,,,,,,32,1,4.000000e+000,4.688263e-003,0.000000e+000,0,,0,
1524094244.909,,0.000000e+000,3.499950e+001,2.027668e-006,0.000000e+000,3,5.564954e-001,0.000000e+000,,,,,,,,,,,,,,32,1,4.000000e+000,1.560211e-003,0.000000e+000,0,,0,
1524094257.699,,0.000000e+000,3.499833e+001,2.025257e-006,0.000000e+000,3,5.559177e-001,0.000000e+000,,,,,,,,,,,,,,32,1,4.000000e+000,7.781982e-004,0.000000e+000,0,,0,
1524094270.262,,0.000000e+000,3.499794e+001,1.987818e-006,0.000000e+000,3,5.439240e-001,0.000000e+000,,,,,,,,,,,,,,32,1,4.000000e+000,0.000000e+000,0.000000e+000,0,,0,
1524094283.190,,0.000000e+000,3.499872e+001,1.984944e-006,0.000000e+000,3,5.523224e-001,0.000000e+000,,,,,,,,,,,,,,32,1,4.000000e+000,0.000000e+000,0.000000e+000,0,,0,
1524094295.642,,0.000000e+000,3.499911e+001,1.994421e-006,0.000000e+000,3,5.605895e-001,0.000000e+000,,,,,,,,,,,,,,32,1,4.000000e+000,7.820129e-004,0.000000e+000,0,,0,
1524094308.562,,0.000000e+000,3.499950e+001,2.039407e-006,0.000000e+000,3,5.508226e-001,0.000000e+000,,,,,,,,,,,,,,32,1,4.000000e+000,0.000000e+000,0.000000e+000,0,,0,
1524094321.025,,0.000000e+000,3.499794e+001,2.014696e-006,0.000000e+000,3,5.596339e-001,0.000000e+000,,,,,,,,,,,,,,32,1,4.000000e+000,0.000000e+000,0.000000e+000,0,,0,
1524094333.720,,0.000000e+000,3.499833e+001,2.136054e-006,0.000000e+000,3,5.937291e-001,0.000000e+000,,,,,,,,,,,,,,32,1,4.000000e+000,7.781982e-004,0.000000e+000,0,,0,
1524094346.633,,0.000000e+000,3.499872e+001,2.003937e-006,0.000000e+000,3,5.530577e-001,0.000000e+000,,,,,,,,,,,,,,32,1,4.000000e+000,0.000000e+000,0.000000e+000,0,,0,
1524094359.226,,0.000000e+000,3.499872e+001,2.041139e-006,0.000000e+000,3,5.616679e-001,0.000000e+000,,,,,,,,,,,,,,32,1,4.000000e+000,1.560211e-003,0.000000e+000,0,,0,
1524094371.791,,0.000000e+000,3.499872e+001,2.046995e-006,0.000000e+000,3,5.652133e-001,0.000000e+000,,,,,,,,,,,,,,32,1,4.000000e+000,0.000000e+000,0.000000e+000,0,,0,
1524094384.491,,0.000000e+000,3.499911e+001,1.989467e-006,0.000000e+000,3,5.497643e-001,0.000000e+000,,,,,,,,,,,,,,32,1,4.000000e+000,7.820129e-004,0.000000e+000,0,,0,
1524094397.476,,0.000000e+000,3.499911e+001,1.979039e-006,0.000000e+000,3,5.368664e-001,0.000000e+000,,,,,,,,,,,,,,32,1,4.000000e+000,7.820129e-004,0.000000e+000,0,,0,
1524094410.296,,0.000000e+000,3.499872e+001,1.999529e-006,0.000000e+000,3,5.518377e-001,0.000000e+000,,,,,,,,,,,,,,32,1,4.000000e+000,1.560211e-003,0.000000e+000,0,,0,
1524094422.937,,0.000000e+000,3.499872e+001,2.021290e-006,0.000000e+000,3,5.619817e-001,0.000000e+000,,,,,,,,,,,,,,32,1,4.000000e+000,0.000000e+000,0.000000e+000,0,,0,
1524094435.857,,0.000000e+000,3.499872e+001,2.038191e-006,0.000000e+000,3,5.605837e-001,0.000000e+000,,,,,,,,,,,,,,32,1,4.000000e+000,0.000000e+000,0.000000e+000,0,,0,
1524094448.862,,0.000000e+000,3.499950e+001,1.965959e-006,0.000000e+000,3,5.456340e-001,0.000000e+000,,,,,,,,,,,,,,32,1,4.000000e+000,1.560211e-003,0.000000e+000,0,,0,
1524094461.562,,0.000000e+000,3.499833e+001,2.000914e-006,0.000000e+000,3,5.616716e-001,0.000000e+000,,,,,,,,,,,,,,32,1,4.000000e+000,7.781982e-004,0.000000e+000,0,,0,
1524094474.622,,0.000000e+000,3.499794e+001,2.015209e-006,0.000000e+000,3,5.588565e-001,0.000000e+000,,,,,,,,,,,,,,32,1,4.000000e+000,0.000000e+000,0.000000e+000,0,,0,
1524094487.073,,0.000000e+000,3.499911e+001,2.008698e-006,0.000000e+000,3,5.424628e-001,0.000000e+000,,,,,,,,,,,,,,32,1,4.000000e+000,7.820129e-004,0.000000e+000,0,,0,
1524094499.180,,0.000000e+000,3.499911e+001,1.970717e-006,0.000000e+000,3,5.268553e-001,0.000000e+000,,,,,,,,,,,,,,32,1,4.000000e+000,7.820129e-004,0.000000e+000,0,,0,
1524094511.925,,0.000000e+000,3.499950e+001,2.056787e-006,0.000000e+000,3,5.632463e-001,0.000000e+000,,,,,,,,,,,,,,32,1,4.000000e+000,0.000000e+000,0.000000e+000,0,,0,
1524094524.621,,0.000000e+000,3.499950e+001,2.047862e-006,0.000000e+000,3,5.638029e-001,0.000000e+000,,,,,,,,,,,,,,32,1,4.000000e+000,0.000000e+000,0.000000e+000,0,,0,
1524094537.033,,0.000000e+000,3.499872e+001,2.110613e-006,0.000000e+000,3,5.680517e-001,0.000000e+000,,,,,,,,,,,,,,32,1,4.000000e+000,1.560211e-003,0.000000e+000,0,,0,
1524094549.581,,0.000000e+000,3.499833e+001,2.050144e-006,0.000000e+000,3,5.649385e-001,0.000000e+000,,,,,,,,,,,,,,32,1,4.000000e+000,7.781982e-004,0.000000e+000,0,,0,
1524094562.544,,0.000000e+000,3.499833e+001,2.066256e-006,0.000000e+000,3,5.628033e-001,0.000000e+000,,,,,,,,,,,,,,32,1,4.000000e+000,7.781982e-004,0.000000e+000,0,,0,
1524094575.219,,0.000000e+000,3.499911e+001,2.014245e-006,0.000000e+000,3,5.626148e-001,0.000000e+000,,,,,,,,,,,,,,32,1,4.000000e+000,3.910065e-003,0.000000e+000,0,,0,
1524094587.949,,0.000000e+000,3.499872e+001,1.974233e-006,0.000000e+000,3,5.525716e-001,0.000000e+000,,,,,,,,,,,,,,32,1,4.000000e+000,1.560211e-003,0.000000e+000,0,,0,
1524094601.097,,0.000000e+000,3.499989e+001,2.050386e-006,0.000000e+000,3,5.861625e-001,0.000000e+000,,,,,,,,,,,,,,32,1,4.000000e+000,7.781982e-004,0.000000e+000,0,,0,
1524094613.864,,0.000000e+000,3.499950e+001,2.079156e-006,0.000000e+000,3,5.670089e-001,0.000000e+000,,,,,,,,,,,,,,32,1,4.000000e+000,1.560211e-003,0.000000e+000,0,,0,
1524094626.420,,0.000000e+000,3.499950e+001,2.004012e-006,0.000000e+000,3,5.591225e-001,0.000000e+000,,,,,,,,,,,,,,32,1,4.000000e+000,1.560211e-003,0.000000e+000,0,,0,
1524094638.967,,0.000000e+000,3.499715e+001,2.027994e-006,0.000000e+000,3,5.387899e-001,0.000000e+000,,,,,,,,,,,,,,32,1,4.000000e+000,6.248474e-003,0.000000e+000,0,,0,
1524094651.867,,0.000000e+000,3.499872e+001,2.049886e-006,0.000000e+000,3,5.619903e-001,0.000000e+000,,,,,,,,,,,,,,32,1,4.000000e+000,1.560211e-003,0.000000e+000,0,,0,
1524094664.590,,0.000000e+000,3.499872e+001,2.047560e-006,0.000000e+000,3,5.601468e-001,0.000000e+000,,,,,,,,,,,,,,32,1,4.000000e+000,0.000000e+000,0.000000e+000,0,,0,
1524094677.050,,0.000000e+000,3.499950e+001,2.122024e-006,0.000000e+000,3,5.665948e-001,0.000000e+000,,,,,,,,,,,,,,32,1,4.000000e+000,0.000000e+000,0.000000e+000,0,,0,
1524094690.515,,0.000000e+000,3.500028e+001,2.055910e-006,0.000000e+000,3,5.704731e-001,0.000000e+000,,,,,,,,,,,,,,32,1,4.000000e+000,3.120422e-003,0.000000e+000,0,,0,
1524094702.323,,0.000000e+000,3.499911e+001,2.025092e-006,0.000000e+000,3,5.636551e-001,0.000000e+000,,,,,,,,,,,,,,32,1,4.000000e+000,7.820129e-004,0.000000e+000,0,,0,
1524094715.901,,0.000000e+000,3.499872e+001,2.003827e-006,0.000000e+000,3,5.609564e-001,0.000000e+000,,,,,,,,,,,,,,32,1,4.000000e+000,0.000000e+000,0.000000e+000,0,,0,
1524094728.006,,0.000000e+000,3.499950e+001,1.988198e-006,0.000000e+000,3,5.551850e-001,0.000000e+000,,,,,,,,,,,,,,32,1,4.000000e+000,0.000000e+000,0.000000e+000,0,,0,
1524094740.696,,0.000000e+000,3.499911e+001,2.069617e-006,0.000000e+000,3,5.656980e-001,0.000000e+000,,,,,,,,,,,,,,32,1,4.000000e+000,7.820129e-004,0.000000e+000,0,,0,
1524094753.166,,0.000000e+000,3.500106e+001,2.078818e-006,0.000000e+000,3,5.802885e-001,0.000000e+000,,,,,,,,,,,,,,32,1,4.000000e+000,4.692078e-003,0.000000e+000,0,,0,
1524094765.592,,0.000000e+000,3.499715e+001,2.068187e-006,0.000000e+000,3,5.694770e-001,0.000000e+000,,,,,,,,,,,,,,32,1,4.000000e+000,4.692078e-003,0.000000e+000,0,,0,
1524094778.287,,0.000000e+000,3.499911e+001,2.069654e-006,0.000000e+000,3,5.666838e-001,0.000000e+000,,,,,,,,,,,,,,32,1,4.000000e+000,7.820129e-004,0.000000e+000,0,,0,
1524094790.999,,0.000000e+000,3.499911e+001,2.055018e-006,0.000000e+000,3,5.656141e-001,0.000000e+000,,,,,,,,,,,,,,32,1,4.000000e+000,7.820129e-004,0.000000e+000,0,,0,
1524094803.807,,0.000000e+000,3.499911e+001,2.087987e-006,0.000000e+000,3,5.771755e-001,0.000000e+000,,,,,,,,,,,,,,32,1,4.000000e+000,7.820129e-004,0.000000e+000,0,,0,
1524094816.320,,0.000000e+000,3.499872e+001,2.077476e-006,0.000000e+000,3,5.759082e-001,0.000000e+000,,,,,,,,,,,,,,32,1,4.000000e+000,0.000000e+000,0.000000e+000,0,,0,
1524094829.047,,0.000000e+000,3.499833e+001,2.081512e-006,0.000000e+000,3,5.746412e-001,0.000000e+000,,,,,,,,,,,,,,32,1,4.000000e+000,7.781982e-004,0.000000e+000,0,,0,
1524094841.743,,0.000000e+000,3.499872e+001,2.079736e-006,0.000000e+000,3,5.688689e-001,0.000000e+000,,,,,,,,,,,,,,32,1,4.000000e+000,0.000000e+000,0.000000e+000,0,,0,
1524094854.483,,0.000000e+000,3.499911e+001,2.059138e-006,0.000000e+000,3,5.339018e-001,0.000000e+000,,,,,,,,,,,,,,32,1,4.000000e+000,7.820129e-004,0.000000e+000,0,,0,
1524094867.126,,0.000000e+000,3.499872e+001,2.094175e-006,0.000000e+000,3,5.920596e-001,0.000000e+000,,,,,,,,,,,,,,32,1,4.000000e+000,0.000000e+000,0.000000e+000,0,,0,
1524094879.838,,0.000000e+000,3.499872e+001,2.060821e-006,0.000000e+000,3,5.753544e-001,0.000000e+000,,,,,,,,,,,,,,32,1,4.000000e+000,1.560211e-003,0.000000e+000,0,,0,
1524094892.518,,0.000000e+000,3.499911e+001,2.062580e-006,0.000000e+000,3,5.662837e-001,0.000000e+000,,,,,,,,,,,,,,32,1,4.000000e+000,7.820129e-004,0.000000e+000,0,,0,
1524094905.764,,0.000000e+000,3.499911e+001,2.069220e-006,0.000000e+000,3,5.722349e-001,0.000000e+000,,,,,,,,,,,,,,32,1,4.000000e+000,7.820129e-004,0.000000e+000,0,,0,
1524094917.561,,0.000000e+000,3.499989e+001,2.053402e-006,0.000000e+000,3,5.684072e-001,0.000000e+000,,,,,,,,,,,,,,32,1,4.000000e+000,7.781982e-004,0.000000e+000,0,,0,
1524094931.129,,0.000000e+000,3.499872e+001,2.111782e-006,0.000000e+000,3,5.795177e-001,0.000000e+000,,,,,,,,,,,,,,32,1,4.000000e+000,1.560211e-003,0.000000e+000,0,,0,
1524094942.964,,0.000000e+000,3.499872e+001,2.041415e-006,0.000000e+000,3,5.817088e-001,0.000000e+000,,,,,,,,,,,,,,32,1,4.000000e+000,1.560211e-003,0.000000e+000,0,,0,
1524094955.434,,0.000000e+000,3.499950e+001,2.091867e-006,0.000000e+000,3,5.665084e-001,0.000000e+000,,,,,,,,,,,,,,32,1,4.000000e+000,1.560211e-003,0.000000e+000,0,,0,
1524094968.107,,0.000000e+000,3.499833e+001,2.106504e-006,0.000000e+000,3,5.821372e-001,0.000000e+000,,,,,,,,,,,,,,32,1,4.000000e+000,7.781982e-004,0.000000e+000,0,,0,
1524094980.807,,0.000000e+000,3.499911e+001,2.083862e-006,0.000000e+000,3,5.695779e-001,0.000000e+000,,,,,,,,,,,,,,32,1,4.000000e+000,7.820129e-004,0.000000e+000,0,,0,
1524094993.535,,0.000000e+000,3.499833e+001,2.080035e-006,0.000000e+000,3,5.688351e-001,0.000000e+000,,,,,,,,,,,,,,32,1,4.000000e+000,7.781982e-004,0.000000e+000,0,,0,
1524095006.220,,0.000000e+000,3.500028e+001,2.115517e-006,0.000000e+000,3,5.900852e-001,0.000000e+000,,,,,,,,,,,,,,32,1,4.000000e+000,1.560211e-003,0.000000e+000,0,,0,
1524095018.923,,0.000000e+000,3.499911e+001,2.073375e-006,0.000000e+000,3,5.707167e-001,0.000000e+000,,,,,,,,,,,,,,32,1,4.000000e+000,7.820129e-004,0.000000e+000,0,,0,
1524095031.568,,0.000000e+000,3.499833e+001,2.098140e-006,0.000000e+000,3,5.872874e-001,0.000000e+000,,,,,,,,,,,,,,32,1,4.000000e+000,2.349854e-003,0.000000e+000,0,,0,
1524095044.298,,0.000000e+000,3.499872e+001,2.153992e-006,0.000000e+000,3,5.917387e-001,0.000000e+000,,,,,,,,,,,,,,32,1,4.000000e+000,1.560211e-003,0.000000e+000,0,,0,