File: Experimental Raw Data/MFn1 VRM/Adjusting Iterative/MFn1_VRMac_34K_3000s_VRMde_35K.dc.dat
[Header]
TITLE,MPMS DC Measurement
BYAPP,MPMS Measurement,2.1,Summary
FILEOPENTIME, 1524282205.215000 4/20/2018, 9:43:25 PM

INFO, APPNAME, MPMS MultiVu Application, Revision 1.61,  Build 082

INFO, NAME, MFn1
INFO, WEIGHT, 1.000
INFO, AREA, 1.000
INFO, LENGTH, 1.000
INFO, SHAPE, 0
INFO, COMMENT,
INFO, SEQUENCE FILE: VRMac_34K_3000s_VRMde_35K.seq


INFO, BACKGROUND DATA FILE:, None


STARTUPAXIS,X,4,LINEAR,AUTO,0.000000,0.000000
STARTUPAXIS,Y1,5,LINEAR,AUTO,0.000000,0.000000


STARTUPGROUP,Longitudinal
FIELDGROUP,Longitudinal,1,2,3,4,5,6,7,8,9,15,16,17,18,27,28
FIELDGROUP,Transverse,1,2,3,4,10,11,12,13,14,19,20,21,22,27,28

PLOT_APPEARANCE,ALL,HORZ_GRID_ON,VERT_GRID_ON,MARKERS_AND_LINES

[Data]
Time,Comment,Field (Oe),Temperature (K),Long Moment (emu),Long Scan Std Dev,Long Algorithm,Long Reg Fit,Long Percent Error (%),Trans Moment (emu),Trans Scan Std Dev,Trans Algorithm,Trans Reg Fit,Trans Percent Error (%),Long Moment [w/o ABS] (emu),Long Scan Std Dev [w/o ABS],Long Reg Fit [w/o ABS],Long Percent Error [w/o ABS] (%),Trans Moment [w/o ABS] (emu),Trans Scan Std Dev [w/o ABS],Trans Reg Fit [w/o ABS],Trans Percent Error [w/o ABS] (%),Points per Scan,Scans per Measurement,Scan Length (cm),Delta Temp (K),Rot Position (deg),Error,EC Comp. Running,Using ABS,
1524454493.750,,0.000000e+000,3.500341e+001,-4.000306e-006,0.000000e+000,3,8.191724e-001,0.000000e+000,,,,,,,,,,,,,,32,1,4.000000e+000,3.139496e-003,0.000000e+000,0,,0,
1524454531.043,,0.000000e+000,3.500106e+001,-2.725357e-006,0.000000e+000,3,7.376059e-001,0.000000e+000,,,,,,,,,,,,,,32,1,4.000000e+000,1.560211e-003,0.000000e+000,0,,0,
1524454569.053,,0.000000e+000,3.500106e+001,-1.769541e-006,0.000000e+000,3,5.933437e-001,0.000000e+000,,,,,,,,,,,,,,32,1,4.000000e+000,6.248474e-003,0.000000e+000,0,,0,
1524454606.839,,0.000000e+000,3.499950e+001,-9.902153e-007,0.000000e+000,3,2.549441e-001,0.000000e+000,,,,,,,,,,,,,,32,1,4.000000e+000,1.560211e-003,0.000000e+000,0,,0,
1524454646.890,,0.000000e+000,3.499950e+001,-1.740668e-007,0.000000e+000,2,0.000000e+000,0.000000e+000,,,,,,,,,,,,,,32,1,4.000000e+000,0.000000e+000,0.000000e+000,0,,0,
1524454687.252,,0.000000e+000,3.500028e+001,9.001523e-007,0.000000e+000,3,2.612524e-001,0.000000e+000,,,,,,,,,,,,,,32,1,4.000000e+000,1.560211e-003,0.000000e+000,0,,0,
1524454725.547,,0.000000e+000,3.499833e+001,1.226306e-006,0.000000e+000,3,4.283585e-001,0.000000e+000,,,,,,,,,,,,,,32,1,4.000000e+000,7.781982e-004,0.000000e+000,0,,0,
1524454764.303,,0.000000e+000,3.499911e+001,1.580769e-006,0.000000e+000,3,5.641879e-001,0.000000e+000,,,,,,,,,,,,,,32,1,4.000000e+000,7.820129e-004,0.000000e+000,0,,0,
1524454802.561,,0.000000e+000,3.499950e+001,1.877781e-006,0.000000e+000,3,6.486601e-001,0.000000e+000,,,,,,,,,,,,,,32,1,4.000000e+000,1.560211e-003,0.000000e+000,0,,0,
1524454840.614,,0.000000e+000,3.499833e+001,2.194927e-006,0.000000e+000,3,6.870090e-001,0.000000e+000,,,,,,,,,,,,,,32,1,4.000000e+000,2.349854e-003,0.000000e+000,0,,0,
1524454878.787,,0.000000e+000,3.499833e+001,2.440651e-006,0.000000e+000,3,7.251852e-001,0.000000e+000,,,,,,,,,,,,,,32,1,4.000000e+000,7.781982e-004,0.000000e+000,0,,0,
1524454916.850,,0.000000e+000,3.499911e+001,2.786117e-006,0.000000e+000,3,7.551204e-001,0.000000e+000,,,,,,,,,,,,,,32,1,4.000000e+000,7.820129e-004,0.000000e+000,0,,0,
1524454954.916,,0.000000e+000,3.499911e+001,2.942935e-006,0.000000e+000,3,7.811146e-001,0.000000e+000,,,,,,,,,,,,,,32,1,4.000000e+000,7.820129e-004,0.000000e+000,0,,0,
1524454992.929,,0.000000e+000,3.499872e+001,3.247623e-006,0.000000e+000,3,7.792978e-001,0.000000e+000,,,,,,,,,,,,,,32,1,4.000000e+000,1.560211e-003,0.000000e+000,0,,0,
1524455031.062,,0.000000e+000,3.499872e+001,3.423235e-006,0.000000e+000,3,7.996888e-001,0.000000e+000,,,,,,,,,,,,,,32,1,4.000000e+000,0.000000e+000,0.000000e+000,0,,0,
1524455069.072,,0.000000e+000,3.499911e+001,3.602449e-006,0.000000e+000,3,8.132551e-001,0.000000e+000,,,,,,,,,,,,,,32,1,4.000000e+000,7.820129e-004,0.000000e+000,0,,0,
1524455107.213,,0.000000e+000,3.499950e+001,3.757769e-006,0.000000e+000,3,8.159595e-001,0.000000e+000,,,,,,,,,,,,,,32,1,4.000000e+000,0.000000e+000,0.000000e+000,0,,0,
1524455145.304,,0.000000e+000,3.499950e+001,3.959100e-006,0.000000e+000,3,8.308047e-001,0.000000e+000,,,,,,,,,,,,,,32,1,4.000000e+000,1.560211e-003,0.000000e+000,0,,0,
1524455183.249,,0.000000e+000,3.499872e+001,4.048777e-006,0.000000e+000,3,8.363482e-001,0.000000e+000,,,,,,,,,,,,,,32,1,4.000000e+000,1.560211e-003,0.000000e+000,0,,0,
1524455220.910,,0.000000e+000,3.499950e+001,4.212771e-006,0.000000e+000,3,8.337544e-001,0.000000e+000,,,,,,,,,,,,,,32,1,4.000000e+000,1.560211e-003,0.000000e+000,0,,0,
1524455259.410,,0.000000e+000,3.499911e+001,4.349005e-006,0.000000e+000,3,8.494913e-001,0.000000e+000,,,,,,,,,,,,,,32,1,4.000000e+000,7.820129e-004,0.000000e+000,0,,0,
1524455297.371,,0.000000e+000,3.500028e+001,4.518079e-006,0.000000e+000,3,8.458436e-001,0.000000e+000,,,,,,,,,,,,,,32,1,4.000000e+000,1.560211e-003,0.000000e+000,0,,0,
1524455335.359,,0.000000e+000,3.499833e+001,4.594233e-006,0.000000e+000,3,8.574375e-001,0.000000e+000,,,,,,,,,,,,,,32,1,4.000000e+000,7.781982e-004,0.000000e+000,0,,0,
1524455373.489,,0.000000e+000,3.499794e+001,4.708856e-006,0.000000e+000,3,8.546818e-001,0.000000e+000,,,,,,,,,,,,,,32,1,4.000000e+000,0.000000e+000,0.000000e+000,0,,0,
1524455425.493,,0.000000e+000,3.499950e+001,4.876913e-006,0.000000e+000,3,8.757292e-001,0.000000e+000,,,,,,,,,,,,,,32,1,4.000000e+000,0.000000e+000,0.000000e+000,0,,0,
1524455463.913,,0.000000e+000,3.499794e+001,4.933111e-006,0.000000e+000,3,8.721535e-001,0.000000e+000,,,,,,,,,,,,,,32,1,4.000000e+000,0.000000e+000,0.000000e+000,0,,0,
1524455501.861,,0.000000e+000,3.499833e+001,5.030967e-006,0.000000e+000,3,8.729213e-001,0.000000e+000,,,,,,,,,,,,,,32,1,4.000000e+000,7.781982e-004,0.000000e+000,0,,0,
1524455539.957,,0.000000e+000,3.499911e+001,5.116659e-006,0.000000e+000,3,8.809617e-001,0.000000e+000,,,,,,,,,,,,,,32,1,4.000000e+000,7.820129e-004,0.000000e+000,0,,0,
1524455577.360,,0.000000e+000,3.499950e+001,5.160274e-006,0.000000e+000,3,8.806932e-001,0.000000e+000,,,,,,,,,,,,,,32,1,4.000000e+000,0.000000e+000,0.000000e+000,0,,0,
1524455615.420,,0.000000e+000,3.499833e+001,5.282636e-006,0.000000e+000,3,8.804772e-001,0.000000e+000,,,,,,,,,,,,,,32,1,4.000000e+000,2.349854e-003,0.000000e+000,0,,0,
1524455653.939,,0.000000e+000,3.499911e+001,5.311823e-006,0.000000e+000,3,8.755061e-001,0.000000e+000,,,,,,,,,,,,,,32,1,4.000000e+000,7.820129e-004,0.000000e+000,0,,0,
1524455691.997,,0.000000e+000,3.499911e+001,5.441432e-006,0.000000e+000,3,8.819855e-001,0.000000e+000,,,,,,,,,,,,,,32,1,4.000000e+000,7.820129e-004,0.000000e+000,0,,0,
1524455730.050,,0.000000e+000,3.499911e+001,5.531355e-006,0.000000e+000,3,8.871486e-001,0.000000e+000,,,,,,,,,,,,,,32,1,4.000000e+000,7.820129e-004,0.000000e+000,0,,0,
1524455768.405,,0.000000e+000,3.499677e+001,5.592398e-006,0.000000e+000,3,8.840634e-001,0.000000e+000,,,,,,,,,,,,,,32,1,4.000000e+000,3.910065e-003,0.000000e+000,0,,0,
1524455806.276,,0.000000e+000,3.499872e+001,5.579793e-006,0.000000e+000,3,8.806727e-001,0.000000e+000,,,,,,,,,,,,,,32,1,4.000000e+000,1.560211e-003,0.000000e+000,0,,0,
1524455844.604,,0.000000e+000,3.499950e+001,5.696677e-006,0.000000e+000,3,8.865774e-001,0.000000e+000,,,,,,,,,,,,,,32,1,4.000000e+000,0.000000e+000,0.000000e+000,0,,0,
1524455883.424,,0.000000e+000,3.499833e+001,5.735952e-006,0.000000e+000,3,8.901531e-001,0.000000e+000,,,,,,,,,,,,,,32,1,4.000000e+000,2.349854e-003,0.000000e+000,0,,0,
1524455921.490,,0.000000e+000,3.499872e+001,5.714052e-006,0.000000e+000,3,8.901580e-001,0.000000e+000,,,,,,,,,,,,,,32,1,4.000000e+000,0.000000e+000,0.000000e+000,0,,0,
1524455959.573,,0.000000e+000,3.499872e+001,5.838688e-006,0.000000e+000,3,8.961533e-001,0.000000e+000,,,,,,,,,,,,,,32,1,4.000000e+000,1.560211e-003,0.000000e+000,0,,0,
1524455997.704,,0.000000e+000,3.500028e+001,5.906189e-006,0.000000e+000,3,8.923313e-001,0.000000e+000,,,,,,,,,,,,,,32,1,4.000000e+000,1.560211e-003,0.000000e+000,0,,0,
1524456035.772,,0.000000e+000,3.499989e+001,5.949835e-006,0.000000e+000,3,8.948157e-001,0.000000e+000,,,,,,,,,,,,,,32,1,4.000000e+000,2.342224e-003,0.000000e+000,0,,0,
1524456073.790,,0.000000e+000,3.499833e+001,5.942315e-006,0.000000e+000,3,8.993006e-001,0.000000e+000,,,,,,,,,,,,,,32,1,4.000000e+000,7.781982e-004,0.000000e+000,0,,0,
1524456111.920,,0.000000e+000,3.499950e+001,6.032573e-006,0.000000e+000,3,8.952687e-001,0.000000e+000,,,,,,,,,,,,,,32,1,4.000000e+000,1.560211e-003,0.000000e+000,0,,0,
1524456150.011,,0.000000e+000,3.499911e+001,6.092729e-006,0.000000e+000,3,8.987900e-001,0.000000e+000,,,,,,,,,,,,,,32,1,4.000000e+000,7.820129e-004,0.000000e+000,0,,0,
1524456188.074,,0.000000e+000,3.499950e+001,6.114167e-006,0.000000e+000,3,8.953782e-001,0.000000e+000,,,,,,,,,,,,,,32,1,4.000000e+000,1.560211e-003,0.000000e+000,0,,0,
1524456226.142,,0.000000e+000,3.499911e+001,6.160988e-006,0.000000e+000,3,9.030173e-001,0.000000e+000,,,,,,,,,,,,,,32,1,4.000000e+000,7.820129e-004,0.000000e+000,0,,0,
1524456264.520,,0.000000e+000,3.499481e+001,6.099017e-006,0.000000e+000,3,8.955860e-001,0.000000e+000,,,,,,,,,,,,,,32,1,4.000000e+000,7.820129e-003,0.000000e+000,0,,0,
1524456303.671,,0.000000e+000,3.499911e+001,6.241613e-006,0.000000e+000,3,8.948925e-001,0.000000e+000,,,,,,,,,,,,,,32,1,4.000000e+000,7.820129e-004,0.000000e+000,0,,0,
1524456355.114,,0.000000e+000,3.499872e+001,6.294986e-006,0.000000e+000,3,9.037047e-001,0.000000e+000,,,,,,,,,,,,,,32,1,4.000000e+000,0.000000e+000,0.000000e+000,0,,0,
1524456392.744,,0.000000e+000,3.499989e+001,6.365621e-006,0.000000e+000,3,8.989979e-001,0.000000e+000,,,,,,,,,,,,,,32,1,4.000000e+000,2.342224e-003,0.000000e+000,0,,0,
1524456430.782,,0.000000e+000,3.499872e+001,6.353047e-006,0.000000e+000,3,8.993907e-001,0.000000e+000,,,,,,,,,,,,,,32,1,4.000000e+000,0.000000e+000,0.000000e+000,0,,0,
1524456468.833,,0.000000e+000,3.499911e+001,6.398363e-006,0.000000e+000,3,8.997420e-001,0.000000e+000,,,,,,,,,,,,,,32,1,4.000000e+000,7.820129e-004,0.000000e+000,0,,0,
1524456507.776,,0.000000e+000,3.499911e+001,6.455169e-006,0.000000e+000,3,9.014003e-001,0.000000e+000,,,,,,,,,,,,,,32,1,4.000000e+000,7.820129e-004,0.000000e+000,0,,0,
1524456545.644,,0.000000e+000,3.499950e+001,6.465001e-006,0.000000e+000,3,9.007582e-001,0.000000e+000,,,,,,,,,,,,,,32,1,4.000000e+000,0.000000e+000,0.000000e+000,0,,0,
1524456583.865,,0.000000e+000,3.499950e+001,6.454713e-006,0.000000e+000,3,8.946326e-001,0.000000e+000,,,,,,,,,,,,,,32,1,4.000000e+000,1.560211e-003,0.000000e+000,0,,0,
1524456622.013,,0.000000e+000,3.499793e+001,6.497199e-006,0.000000e+000,3,9.016722e-001,0.000000e+000,,,,,,,,,,,,,,32,1,4.000000e+000,3.131866e-003,0.000000e+000,0,,0,
1524456659.966,,0.000000e+000,3.499872e+001,6.551938e-006,0.000000e+000,3,9.012222e-001,0.000000e+000,,,,,,,,,,,,,,32,1,4.000000e+000,0.000000e+000,0.000000e+000,0,,0,
1524456697.476,,0.000000e+000,3.499911e+001,6.559638e-006,0.000000e+000,3,8.970264e-001,0.000000e+000,,,,,,,,,,,,,,32,1,4.000000e+000,7.820129e-004,0.000000e+000,0,,0,
1524456735.594,,0.000000e+000,3.499950e+001,6.637798e-006,0.000000e+000,3,9.020565e-001,0.000000e+000,,,,,,,,,,,,,,32,1,4.000000e+000,1.560211e-003,0.000000e+000,0,,0,
1524456773.150,,0.000000e+000,3.499950e+001,6.663453e-006,0.000000e+000,3,8.973994e-001,0.000000e+000,,,,,,,,,,,,,,32,1,4.000000e+000,0.000000e+000,0.000000e+000,0,,0,
1524456811.348,,0.000000e+000,3.499911e+001,6.596868e-006,0.000000e+000,3,9.034643e-001,0.000000e+000,,,,,,,,,,,,,,32,1,4.000000e+000,7.820129e-004,0.000000e+000,0,,0,
1524456849.799,,0.000000e+000,3.499832e+001,6.629658e-006,0.000000e+000,3,9.077330e-001,0.000000e+000,,,,,,,,,,,,,,32,1,4.000000e+000,3.910065e-003,0.000000e+000,0,,0,
1524456886.667,,0.000000e+000,3.499871e+001,6.719462e-006,0.000000e+000,3,9.035898e-001,0.000000e+000,,,,,,,,,,,,,,32,1,4.000000e+000,3.128052e-003,0.000000e+000,0,,0,
1524456924.860,,0.000000e+000,3.499950e+001,6.748795e-006,0.000000e+000,3,9.073544e-001,0.000000e+000,,,,,,,,,,,,,,32,1,4.000000e+000,0.000000e+000,0.000000e+000,0,,0,
1524456962.803,,0.000000e+000,3.499950e+001,6.775372e-006,0.000000e+000,3,9.060993e-001,0.000000e+000,,,,,,,,,,,,,,32,1,4.000000e+000,0.000000e+000,0.000000e+000,0,,0,
1524457000.841,,0.000000e+000,3.499911e+001,6.824325e-006,0.000000e+000,3,9.086477e-001,0.000000e+000,,,,,,,,,,,,,,32,1,4.000000e+000,7.820129e-004,0.000000e+000,0,,0,
1524457038.954,,0.000000e+000,3.500028e+001,6.811872e-006,0.000000e+000,3,9.056503e-001,0.000000e+000,,,,,,,,,,,,,,32,1,4.000000e+000,0.000000e+000,0.000000e+000,0,,0,
1524457076.954,,0.000000e+000,3.500028e+001,6.821076e-006,0.000000e+000,3,9.022484e-001,0.000000e+000,,,,,,,,,,,,,,32,1,4.000000e+000,0.000000e+000,0.000000e+000,0,,0,
1524457115.068,,0.000000e+000,3.499793e+001,6.894226e-006,0.000000e+000,3,9.059085e-001,0.000000e+000,,,,,,,,,,,,,,32,1,4.000000e+000,1.567841e-003,0.000000e+000,0,,0,
1524457153.201,,0.000000e+000,3.499911e+001,6.877394e-006,0.000000e+000,3,9.050916e-001,0.000000e+000,,,,,,,,,,,,,,32,1,4.000000e+000,7.820129e-004,0.000000e+000,0,,0,
1524457191.274,,0.000000e+000,3.499950e+001,6.826892e-006,0.000000e+000,3,9.024626e-001,0.000000e+000,,,,,,,,,,,,,,32,1,4.000000e+000,0.000000e+000,0.000000e+000,0,,0,
1524457242.817,,0.000000e+000,3.499872e+001,6.945137e-006,0.000000e+000,3,9.128368e-001,0.000000e+000,,,,,,,,,,,,,,32,1,4.000000e+000,0.000000e+000,0.000000e+000,0,,0,
1524457281.310,,0.000000e+000,3.499872e+001,6.953529e-006,0.000000e+000,3,9.083151e-001,0.000000e+000,,,,,,,,,,,,,,32,1,4.000000e+000,1.560211e-003,0.000000e+000,0,,0,
1524457319.420,,0.000000e+000,3.499950e+001,6.996034e-006,0.000000e+000,3,9.083287e-001,0.000000e+000,,,,,,,,,,,,,,32,1,4.000000e+000,0.000000e+000,0.000000e+000,0,,0,
1524457357.451,,0.000000e+000,3.499833e+001,6.950381e-006,0.000000e+000,3,9.098101e-001,0.000000e+000,,,,,,,,,,,,,,32,1,4.000000e+000,7.781982e-004,0.000000e+000,0,,0,
1524457395.069,,0.000000e+000,3.499872e+001,6.947882e-006,0.000000e+000,3,9.116941e-001,0.000000e+000,,,,,,,,,,,,,,32,1,4.000000e+000,1.560211e-003,0.000000e+000,0,,0,
1524457433.115,,0.000000e+000,3.499950e+001,7.038872e-006,0.000000e+000,3,9.090576e-001,0.000000e+000,,,,,,,,,,,,,,32,1,4.000000e+000,0.000000e+000,0.000000e+000,0,,0,
1524457471.193,,0.000000e+000,3.499950e+001,6.971586e-006,0.000000e+000,3,9.080616e-001,0.000000e+000,,,,,,,,,,,,,,32,1,4.000000e+000,0.000000e+000,0.000000e+000,0,,0,
1524457509.713,,0.000000e+000,3.499911e+001,7.066086e-006,0.000000e+000,3,9.080659e-001,0.000000e+000,,,,,,,,,,,,,,32,1,4.000000e+000,7.820129e-004,0.000000e+000,0,,0,
1524457547.754,,0.000000e+000,3.499911e+001,7.096469e-006,0.000000e+000,3,9.137458e-001,0.000000e+000,,,,,,,,,,,,,,32,1,4.000000e+000,7.820129e-004,0.000000e+000,0,,0,
1524457586.017,,0.000000e+000,3.499872e+001,7.132479e-006,0.000000e+000,3,9.167963e-001,0.000000e+000,,,,,,,,,,,,,,32,1,4.000000e+000,0.000000e+000,0.000000e+000,0,,0,
1524457623.277,,0.000000e+000,3.499833e+001,7.090513e-006,0.000000e+000,3,9.098768e-001,0.000000e+000,,,,,,,,,,,,,,32,1,4.000000e+000,7.781982e-004,0.000000e+000,0,,0,
1524457661.275,,0.000000e+000,3.499911e+001,7.012802e-006,0.000000e+000,3,9.073243e-001,0.000000e+000,,,,,,,,,,,,,,32,1,4.000000e+000,7.820129e-004,0.000000e+000,0,,0,
1524457699.719,,0.000000e+000,3.499832e+001,7.127959e-006,0.000000e+000,3,9.053961e-001,0.000000e+000,,,,,,,,,,,,,,32,1,4.000000e+000,3.910065e-003,0.000000e+000,0,,0,
1524457736.837,,0.000000e+000,3.500145e+001,7.110021e-006,0.000000e+000,3,9.064136e-001,0.000000e+000,,,,,,,,,,,,,,32,1,4.000000e+000,7.781982e-004,0.000000e+000,0,,0,
1524457774.922,,0.000000e+000,3.499911e+001,7.233124e-006,0.000000e+000,3,9.105100e-001,0.000000e+000,,,,,,,,,,,,,,32,1,4.000000e+000,7.820129e-004,0.000000e+000,0,,0,
1524457813.988,,0.000000e+000,3.499793e+001,7.208497e-006,0.000000e+000,3,9.094332e-001,0.000000e+000,,,,,,,,,,,,,,32,1,4.000000e+000,3.131866e-003,0.000000e+000,0,,0,
1524457851.711,,0.000000e+000,3.499950e+001,7.179086e-006,0.000000e+000,3,9.119836e-001,0.000000e+000,,,,,,,,,,,,,,32,1,4.000000e+000,1.560211e-003,0.000000e+000,0,,0,
1524457889.809,,0.000000e+000,3.499911e+001,7.138585e-006,0.000000e+000,3,9.073424e-001,0.000000e+000,,,,,,,,,,,,,,32,1,4.000000e+000,2.338409e-003,0.000000e+000,0,,0,
1524457927.699,,0.000000e+000,3.499911e+001,7.217445e-006,0.000000e+000,3,9.109408e-001,0.000000e+000,,,,,,,,,,,,,,32,1,4.000000e+000,7.820129e-004,0.000000e+000,0,,0,
1524457965.712,,0.000000e+000,3.499950e+001,7.230740e-006,0.000000e+000,3,9.105045e-001,0.000000e+000,,,,,,,,,,,,,,32,1,4.000000e+000,0.000000e+000,0.000000e+000,0,,0,
1524458003.818,,0.000000e+000,3.499872e+001,7.242895e-006,0.000000e+000,3,9.107919e-001,0.000000e+000,,,,,,,,,,,,,,32,1,4.000000e+000,1.560211e-003,0.000000e+000,0,,0,
1524458041.984,,0.000000e+000,3.499950e+001,7.266129e-006,0.000000e+000,3,9.098067e-001,0.000000e+000,,,,,,,,,,,,,,32,1,4.000000e+000,1.560211e-003,0.000000e+000,0,,0,
1524458079.934,,0.000000e+000,3.500106e+001,7.236354e-006,0.000000e+000,3,9.057155e-001,0.000000e+000,,,,,,,,,,,,,,32,1,4.000000e+000,3.128052e-003,0.000000e+000,0,,0,
1524458117.987,,0.000000e+000,3.499833e+001,7.349972e-006,0.000000e+000,3,9.124745e-001,0.000000e+000,,,,,,,,,,,,,,32,1,4.000000e+000,2.349854e-003,0.000000e+000,0,,0,
1524458170.240,,0.000000e+000,3.499989e+001,7.262302e-006,0.000000e+000,3,9.082935e-001,0.000000e+000,,,,,,,,,,,,,,32,1,4.000000e+000,2.342224e-003,0.000000e+000,0,,0,
1524458208.248,,0.000000e+000,3.499989e+001,7.264048e-006,0.000000e+000,3,9.113623e-001,0.000000e+000,,,,,,,,,,,,,,32,1,4.000000e+000,7.781982e-004,0.000000e+000,0,,0,
1524458246.454,,0.000000e+000,3.499911e+001,7.258500e-006,0.000000e+000,3,9.112462e-001,0.000000e+000,,,,,,,,,,,,,,32,1,4.000000e+000,7.820129e-004,0.000000e+000,0,,0,
1524458284.490,,0.000000e+000,3.499989e+001,7.330910e-006,0.000000e+000,3,9.106553e-001,0.000000e+000,,,,,,,,,,,,,,32,1,4.000000e+000,7.781982e-004,0.000000e+000,0,,0,
1524458322.590,,0.000000e+000,3.499872e+001,7.343928e-006,0.000000e+000,3,9.101528e-001,0.000000e+000,,,,,,,,,,,,,,32,1,4.000000e+000,1.560211e-003,0.000000e+000,0,,0,
1524458361.368,,0.000000e+000,3.499911e+001,7.341188e-006,0.000000e+000,3,9.105528e-001,0.000000e+000,,,,,,,,,,,,,,32,1,4.000000e+000,7.820129e-004,0.000000e+000,0,,0,
1524458399.434,,0.000000e+000,3.499911e+001,7.379228e-006,0.000000e+000,3,9.152865e-001,0.000000e+000,,,,,,,,,,,,,,32,1,4.000000e+000,7.820129e-004,0.000000e+000,0,,0,
1524458437.504,,0.000000e+000,3.499833e+001,7.359061e-006,0.000000e+000,3,9.135700e-001,0.000000e+000,,,,,,,,,,,,,,32,1,4.000000e+000,2.349854e-003,0.000000e+000,0,,0,
1524458475.505,,0.000000e+000,3.499950e+001,7.365092e-006,0.000000e+000,3,9.085426e-001,0.000000e+000,,,,,,,,,,,,,,32,1,4.000000e+000,0.000000e+000,0.000000e+000,0,,0,
1524458513.620,,0.000000e+000,3.499911e+001,7.375411e-006,0.000000e+000,3,9.130979e-001,0.000000e+000,,,,,,,,,,,,,,32,1,4.000000e+000,7.820129e-004,0.000000e+000,0,,0,
1524458551.611,,0.000000e+000,3.499872e+001,7.408486e-006,0.000000e+000,3,9.158318e-001,0.000000e+000,,,,,,,,,,,,,,32,1,4.000000e+000,0.000000e+000,0.000000e+000,0,,0,
1524458589.762,,0.000000e+000,3.499950e+001,7.382014e-006,0.000000e+000,3,9.125730e-001,0.000000e+000,,,,,,,,,,,,,,32,1,4.000000e+000,0.000000e+000,0.000000e+000,0,,0,
1524458627.835,,0.000000e+000,3.499911e+001,7.396408e-006,0.000000e+000,3,9.132140e-001,0.000000e+000,,,,,,,,,,,,,,32,1,4.000000e+000,7.820129e-004,0.000000e+000,0,,0,
1524458665.140,,0.000000e+000,3.499950e+001,7.413599e-006,0.000000e+000,3,9.138060e-001,0.000000e+000,,,,,,,,,,,,,,32,1,4.000000e+000,3.120422e-003,0.000000e+000,0,,0,
1524458702.623,,0.000000e+000,3.499950e+001,7.428786e-006,0.000000e+000,3,9.095876e-001,0.000000e+000,,,,,,,,,,,,,,32,1,4.000000e+000,0.000000e+000,0.000000e+000,0,,0,
1524458740.679,,0.000000e+000,3.499989e+001,7.404671e-006,0.000000e+000,3,9.122904e-001,0.000000e+000,,,,,,,,,,,,,,32,1,4.000000e+000,7.781982e-004,0.000000e+000,0,,0,
1524458779.319,,0.000000e+000,3.499833e+001,7.457524e-006,0.000000e+000,3,9.139169e-001,0.000000e+000,,,,,,,,,,,,,,32,1,4.000000e+000,7.781982e-004,0.000000e+000,0,,0,
1524458816.807,,0.000000e+000,3.499950e+001,7.441371e-006,0.000000e+000,3,9.144190e-001,0.000000e+000,,,,,,,,,,,,,,32,1,4.000000e+000,0.000000e+000,0.000000e+000,0,,0,
1524458855.250,,0.000000e+000,3.499911e+001,7.452486e-006,0.000000e+000,3,9.115692e-001,0.000000e+000,,,,,,,,,,,,,,32,1,4.000000e+000,7.820129e-004,0.000000e+000,0,,0,
1524458893.141,,0.000000e+000,3.499950e+001,7.446083e-006,0.000000e+000,3,9.158654e-001,0.000000e+000,,,,,,,,,,,,,,32,1,4.000000e+000,1.560211e-003,0.000000e+000,0,,0,
1524458931.269,,0.000000e+000,3.499911e+001,7.504122e-006,0.000000e+000,3,9.147915e-001,0.000000e+000,,,,,,,,,,,,,,32,1,4.000000e+000,7.820129e-004,0.000000e+000,0,,0,
1524458969.257,,0.000000e+000,3.499989e+001,7.491839e-006,0.000000e+000,3,9.158976e-001,0.000000e+000,,,,,,,,,,,,,,32,1,4.000000e+000,7.781982e-004,0.000000e+000,0,,0,
1524459007.388,,0.000000e+000,3.499950e+001,7.501028e-006,0.000000e+000,3,9.109617e-001,0.000000e+000,,,,,,,,,,,,,,32,1,4.000000e+000,0.000000e+000,0.000000e+000,0,,0,
1524459045.853,,0.000000e+000,3.499911e+001,7.525242e-006,0.000000e+000,3,9.181721e-001,0.000000e+000,,,,,,,,,,,,,,32,1,4.000000e+000,7.820129e-004,0.000000e+000,0,,0,
1524459097.027,,0.000000e+000,3.499872e+001,7.561109e-006,0.000000e+000,3,9.130847e-001,0.000000e+000,,,,,,,,,,,,,,32,1,4.000000e+000,1.560211e-003,0.000000e+000,0,,0,
1524459135.105,,0.000000e+000,3.499754e+001,7.463841e-006,0.000000e+000,3,9.100621e-001,0.000000e+000,,,,,,,,,,,,,,32,1,4.000000e+000,2.349854e-003,0.000000e+000,0,,0,
1524459173.235,,0.000000e+000,3.500028e+001,7.480947e-006,0.000000e+000,3,9.150589e-001,0.000000e+000,,,,,,,,,,,,,,32,1,4.000000e+000,1.560211e-003,0.000000e+000,0,,0,
1524459210.551,,0.000000e+000,3.499794e+001,7.572037e-006,0.000000e+000,3,9.117650e-001,0.000000e+000,,,,,,,,,,,,,,32,1,4.000000e+000,0.000000e+000,0.000000e+000,0,,0,
1524459248.064,,0.000000e+000,3.499833e+001,7.519219e-006,0.000000e+000,3,9.146113e-001,0.000000e+000,,,,,,,,,,,,,,32,1,4.000000e+000,7.781982e-004,0.000000e+000,0,,0,
1524459286.262,,0.000000e+000,3.500185e+001,7.517130e-006,0.000000e+000,3,9.118916e-001,0.000000e+000,,,,,,,,,,,,,,32,1,4.000000e+000,4.688263e-003,0.000000e+000,0,,0,
1524459324.090,,0.000000e+000,3.499559e+001,7.571906e-006,0.000000e+000,3,9.130048e-001,0.000000e+000,,,,,,,,,,,,,,32,1,4.000000e+000,6.259918e-003,0.000000e+000,0,,0,
1524459362.148,,0.000000e+000,3.499911e+001,7.580635e-006,0.000000e+000,3,9.096351e-001,0.000000e+000,,,,,,,,,,,,,,32,1,4.000000e+000,7.820129e-004,0.000000e+000,0,,0,
1524459400.211,,0.000000e+000,3.499911e+001,7.526749e-006,0.000000e+000,3,9.122432e-001,0.000000e+000,,,,,,,,,,,,,,32,1,4.000000e+000,7.820129e-004,0.000000e+000,0,,0,
1524459438.549,,0.000000e+000,3.499950e+001,7.561096e-006,0.000000e+000,3,9.133223e-001,0.000000e+000,,,,,,,,,,,,,,32,1,4.000000e+000,1.560211e-003,0.000000e+000,0,,0,
1524459476.815,,0.000000e+000,3.499833e+001,7.584824e-006,0.000000e+000,3,9.164494e-001,0.000000e+000,,,,,,,,,,,,,,32,1,4.000000e+000,7.781982e-004,0.000000e+000,0,,0,
1524459514.673,,0.000000e+000,3.499989e+001,7.582337e-006,0.000000e+000,3,9.159575e-001,0.000000e+000,,,,,,,,,,,,,,32,1,4.000000e+000,7.781982e-004,0.000000e+000,0,,0,
1524459552.693,,0.000000e+000,3.499872e+001,7.682126e-006,0.000000e+000,3,9.145762e-001,0.000000e+000,,,,,,,,,,,,,,32,1,4.000000e+000,0.000000e+000,0.000000e+000,0,,0,
1524459591.571,,0.000000e+000,3.499911e+001,7.534845e-006,0.000000e+000,3,9.096982e-001,0.000000e+000,,,,,,,,,,,,,,32,1,4.000000e+000,7.820129e-004,0.000000e+000,0,,0,
1524459629.857,,0.000000e+000,3.500028e+001,7.651552e-006,0.000000e+000,3,9.118215e-001,0.000000e+000,,,,,,,,,,,,,,32,1,4.000000e+000,1.560211e-003,0.000000e+000,0,,0,
1524459667.897,,0.000000e+000,3.499950e+001,7.590021e-006,0.000000e+000,3,9.100568e-001,0.000000e+000,,,,,,,,,,,,,,32,1,4.000000e+000,0.000000e+000,0.000000e+000,0,,0,
1524459705.960,,0.000000e+000,3.499950e+001,7.625069e-006,0.000000e+000,3,9.012839e-001,0.000000e+000,,,,,,,,,,,,,,32,1,4.000000e+000,1.560211e-003,0.000000e+000,0,,0,
1524459744.629,,0.000000e+000,3.499833e+001,7.659527e-006,0.000000e+000,3,9.122556e-001,0.000000e+000,,,,,,,,,,,,,,32,1,4.000000e+000,2.349854e-003,0.000000e+000,0,,0,
1524459782.107,,0.000000e+000,3.499793e+001,7.667015e-006,0.000000e+000,3,9.107193e-001,0.000000e+000,,,,,,,,,,,,,,32,1,4.000000e+000,1.567841e-003,0.000000e+000,0,,0,
1524459819.822,,0.000000e+000,3.499872e+001,7.635575e-006,0.000000e+000,3,9.120712e-001,0.000000e+000,,,,,,,,,,,,,,32,1,4.000000e+000,0.000000e+000,0.000000e+000,0,,0,
1524459857.838,,0.000000e+000,3.499950e+001,7.639614e-006,0.000000e+000,3,9.123634e-001,0.000000e+000,,,,,,,,,,,,,,32,1,4.000000e+000,0.000000e+000,0.000000e+000,0,,0,
1524459895.748,,0.000000e+000,3.499911e+001,7.583542e-006,0.000000e+000,3,9.124194e-001,0.000000e+000,,,,,,,,,,,,,,32,1,4.000000e+000,7.820129e-004,0.000000e+000,0,,0,
1524459933.819,,0.000000e+000,3.499950e+001,7.694138e-006,0.000000e+000,3,9.082722e-001,0.000000e+000,,,,,,,,,,,,,,32,1,4.000000e+000,0.000000e+000,0.000000e+000,0,,0,
1524459971.327,,0.000000e+000,3.499989e+001,7.718768e-006,0.000000e+000,3,9.104127e-001,0.000000e+000,,,,,,,,,,,,,,32,1,4.000000e+000,7.781982e-004,0.000000e+000,0,,0,
1524460022.880,,0.000000e+000,3.499793e+001,7.720487e-006,0.000000e+000,3,9.187048e-001,0.000000e+000,,,,,,,,,,,,,,32,1,4.000000e+000,1.567841e-003,0.000000e+000,0,,0,
1524460060.946,,0.000000e+000,3.499989e+001,7.636384e-006,0.000000e+000,3,9.158304e-001,0.000000e+000,,,,,,,,,,,,,,32,1,4.000000e+000,7.781982e-004,0.000000e+000,0,,0,
1524460099.009,,0.000000e+000,3.499872e+001,7.728532e-006,0.000000e+000,3,9.173241e-001,0.000000e+000,,,,,,,,,,,,,,32,1,4.000000e+000,1.560211e-003,0.000000e+000,0,,0,
1524460136.992,,0.000000e+000,3.499989e+001,7.727660e-006,0.000000e+000,3,9.136264e-001,0.000000e+000,,,,,,,,,,,,,,32,1,4.000000e+000,7.781982e-004,0.000000e+000,0,,0,
1524460175.132,,0.000000e+000,3.499911e+001,7.705470e-006,0.000000e+000,3,9.175174e-001,0.000000e+000,,,,,,,,,,,,,,32,1,4.000000e+000,7.820129e-004,0.000000e+000,0,,0,
1524460213.473,,0.000000e+000,3.499989e+001,7.757034e-006,0.000000e+000,3,9.148849e-001,0.000000e+000,,,,,,,,,,,,,,32,1,4.000000e+000,7.781982e-004,0.000000e+000,0,,0,
1524460251.571,,0.000000e+000,3.499950e+001,7.652322e-006,0.000000e+000,3,9.094492e-001,0.000000e+000,,,,,,,,,,,,,,32,1,4.000000e+000,0.000000e+000,0.000000e+000,0,,0,
1524460289.254,,0.000000e+000,3.499872e+001,7.764493e-006,0.000000e+000,3,9.144598e-001,0.000000e+000,,,,,,,,,,,,,,32,1,4.000000e+000,0.000000e+000,0.000000e+000,0,,0,
1524460326.882,,0.000000e+000,3.499950e+001,7.785809e-006,0.000000e+000,3,9.145139e-001,0.000000e+000,,,,,,,,,,,,,,32,1,4.000000e+000,0.000000e+000,0.000000e+000,0,,0,
1524460364.940,,0.000000e+000,3.499911e+001,7.712909e-006,0.000000e+000,3,9.164891e-001,0.000000e+000,,,,,,,,,,,,,,32,1,4.000000e+000,7.820129e-004,0.000000e+000,0,,0,
1524460403.463,,0.000000e+000,3.499872e+001,7.767813e-006,0.000000e+000,3,9.138882e-001,0.000000e+000,,,,,,,,,,,,,,32,1,4.000000e+000,0.000000e+000,0.000000e+000,0,,0,
1524460441.386,,0.000000e+000,3.499911e+001,7.708328e-006,0.000000e+000,3,9.156909e-001,0.000000e+000,,,,,,,,,,,,,,32,1,4.000000e+000,7.820129e-004,0.000000e+000,0,,0,
1524460479.149,,0.000000e+000,3.499950e+001,7.806564e-006,0.000000e+000,3,9.163675e-001,0.000000e+000,,,,,,,,,,,,,,32,1,4.000000e+000,0.000000e+000,0.000000e+000,0,,0,
1524460517.652,,0.000000e+000,3.499911e+001,7.743726e-006,0.000000e+000,3,9.143576e-001,0.000000e+000,,,,,,,,,,,,,,32,1,4.000000e+000,7.820129e-004,0.000000e+000,0,,0,
1524460555.273,,0.000000e+000,3.499989e+001,7.789931e-006,0.000000e+000,3,9.168463e-001,0.000000e+000,,,,,,,,,,,,,,32,1,4.000000e+000,7.781982e-004,0.000000e+000,0,,0,
1524460593.401,,0.000000e+000,3.499950e+001,7.715622e-006,0.000000e+000,3,9.154061e-001,0.000000e+000,,,,,,,,,,,,,,32,1,4.000000e+000,0.000000e+000,0.000000e+000,0,,0,
1524460630.619,,0.000000e+000,3.499911e+001,7.743880e-006,0.000000e+000,3,9.119163e-001,0.000000e+000,,,,,,,,,,,,,,32,1,4.000000e+000,7.820129e-004,0.000000e+000,0,,0,
1524460668.685,,0.000000e+000,3.499911e+001,7.711303e-006,0.000000e+000,3,9.134325e-001,0.000000e+000,,,,,,,,,,,,,,32,1,4.000000e+000,7.820129e-004,0.000000e+000,0,,0,
1524460706.763,,0.000000e+000,3.499911e+001,7.761431e-006,0.000000e+000,3,9.068041e-001,0.000000e+000,,,,,,,,,,,,,,32,1,4.000000e+000,7.820129e-004,0.000000e+000,0,,0,
1524460744.788,,0.000000e+000,3.499989e+001,7.769206e-006,0.000000e+000,3,9.097807e-001,0.000000e+000,,,,,,,,,,,,,,32,1,4.000000e+000,7.781982e-004,0.000000e+000,0,,0,
1524460782.871,,0.000000e+000,3.499911e+001,7.707563e-006,0.000000e+000,3,9.153203e-001,0.000000e+000,,,,,,,,,,,,,,32,1,4.000000e+000,7.820129e-004,0.000000e+000,0,,0,
1524460821.482,,0.000000e+000,3.499911e+001,7.783037e-006,0.000000e+000,3,9.118146e-001,0.000000e+000,,,,,,,,,,,,,,32,1,4.000000e+000,7.820129e-004,0.000000e+000,0,,0,
1524460859.010,,0.000000e+000,3.499950e+001,7.798483e-006,0.000000e+000,3,9.115998e-001,0.000000e+000,,,,,,,,,,,,,,32,1,4.000000e+000,0.000000e+000,0.000000e+000,0,,0,
1524460897.080,,0.000000e+000,3.500028e+001,7.796864e-006,0.000000e+000,3,9.146578e-001,0.000000e+000,,,,,,,,,,,,,,32,1,4.000000e+000,0.000000e+000,0.000000e+000,0,,0,
1524460948.041,,0.000000e+000,3.499833e+001,7.784648e-006,0.000000e+000,3,9.168183e-001,0.000000e+000,,,,,,,,,,,,,,32,1,4.000000e+000,7.781982e-004,0.000000e+000,0,,0,
1524460986.572,,0.000000e+000,3.500067e+001,7.771242e-006,0.000000e+000,3,9.160574e-001,0.000000e+000,,,,,,,,,,,,,,32,1,4.000000e+000,3.910065e-003,0.000000e+000,0,,0,
1524461024.632,,0.000000e+000,3.499911e+001,7.824093e-006,0.000000e+000,3,9.177738e-001,0.000000e+000,,,,,,,,,,,,,,32,1,4.000000e+000,7.820129e-004,0.000000e+000,0,,0,
1524461062.223,,0.000000e+000,3.499950e+001,7.771845e-006,0.000000e+000,3,9.237057e-001,0.000000e+000,,,,,,,,,,,,,,32,1,4.000000e+000,0.000000e+000,0.000000e+000,0,,0,
1524461100.691,,0.000000e+000,3.499950e+001,7.853653e-006,0.000000e+000,3,9.163516e-001,0.000000e+000,,,,,,,,,,,,,,32,1,4.000000e+000,0.000000e+000,0.000000e+000,0,,0,
1524461137.844,,0.000000e+000,3.499911e+001,7.840509e-006,0.000000e+000,3,9.167264e-001,0.000000e+000,,,,,,,,,,,,,,32,1,4.000000e+000,7.820129e-004,0.000000e+000,0,,0,
1524461175.775,,0.000000e+000,3.499950e+001,7.770045e-006,0.000000e+000,3,9.192265e-001,0.000000e+000,,,,,,,,,,,,,,32,1,4.000000e+000,0.000000e+000,0.000000e+000,0,,0,
1524461214.095,,0.000000e+000,3.499950e+001,7.852072e-006,0.000000e+000,3,9.167010e-001,0.000000e+000,,,,,,,,,,,,,,32,1,4.000000e+000,0.000000e+000,0.000000e+000,0,,0,
1524461252.291,,0.000000e+000,3.499989e+001,7.834200e-006,0.000000e+000,3,9.077548e-001,0.000000e+000,,,,,,,,,,,,,,32,1,4.000000e+000,7.781982e-004,0.000000e+000,0,,0,
1524461290.211,,0.000000e+000,3.499911e+001,7.860590e-006,0.000000e+000,3,9.160959e-001,0.000000e+000,,,,,,,,,,,,,,32,1,4.000000e+000,7.820129e-004,0.000000e+000,0,,0,
1524461328.587,,0.000000e+000,3.499833e+001,7.858933e-006,0.000000e+000,3,9.170436e-001,0.000000e+000,,,,,,,,,,,,,,32,1,4.000000e+000,7.781982e-004,0.000000e+000,0,,0,
1524461367.770,,0.000000e+000,3.499872e+001,7.849472e-006,0.000000e+000,3,9.144574e-001,0.000000e+000,,,,,,,,,,,,,,32,1,4.000000e+000,0.000000e+000,0.000000e+000,0,,0,
1524461405.813,,0.000000e+000,3.499989e+001,7.828678e-006,0.000000e+000,3,9.163669e-001,0.000000e+000,,,,,,,,,,,,,,32,1,4.000000e+000,7.781982e-004,0.000000e+000,0,,0,
1524461444.073,,0.000000e+000,3.499911e+001,7.846050e-006,0.000000e+000,3,9.153876e-001,0.000000e+000,,,,,,,,,,,,,,32,1,4.000000e+000,7.820129e-004,0.000000e+000,0,,0,
1524461482.239,,0.000000e+000,3.499911e+001,7.881881e-006,0.000000e+000,3,9.175255e-001,0.000000e+000,,,,,,,,,,,,,,32,1,4.000000e+000,7.820129e-004,0.000000e+000,0,,0,
1524461520.192,,0.000000e+000,3.499950e+001,7.908749e-006,0.000000e+000,3,9.193009e-001,0.000000e+000,,,,,,,,,,,,,,32,1,4.000000e+000,0.000000e+000,0.000000e+000,0,,0,
1524461558.325,,0.000000e+000,3.499989e+001,7.869712e-006,0.000000e+000,3,9.109293e-001,0.000000e+000,,,,,,,,,,,,,,32,1,4.000000e+000,7.781982e-004,0.000000e+000,0,,0,
1524461596.358,,0.000000e+000,3.499950e+001,7.860926e-006,0.000000e+000,3,9.121943e-001,0.000000e+000,,,,,,,,,,,,,,32,1,4.000000e+000,1.560211e-003,0.000000e+000,0,,0,
1524461634.189,,0.000000e+000,3.499872e+001,7.876773e-006,0.000000e+000,3,9.101570e-001,0.000000e+000,,,,,,,,,,,,,,32,1,4.000000e+000,0.000000e+000,0.000000e+000,0,,0,
1524461672.144,,0.000000e+000,3.499872e+001,7.845735e-006,0.000000e+000,3,9.133983e-001,0.000000e+000,,,,,,,,,,,,,,32,1,4.000000e+000,1.560211e-003,0.000000e+000,0,,0,
1524461710.217,,0.000000e+000,3.499872e+001,7.883330e-006,0.000000e+000,3,9.147450e-001,0.000000e+000,,,,,,,,,,,,,,32,1,4.000000e+000,0.000000e+000,0.000000e+000,0,,0,
1524461749.298,,0.000000e+000,3.499911e+001,7.894387e-006,0.000000e+000,3,9.119558e-001,0.000000e+000,,,,,,,,,,,,,,32,1,4.000000e+000,7.820129e-004,0.000000e+000,0,,0,
1524461787.446,,0.000000e+000,3.499872e+001,7.874040e-006,0.000000e+000,3,9.149108e-001,0.000000e+000,,,,,,,,,,,,,,32,1,4.000000e+000,0.000000e+000,0.000000e+000,0,,0,
1524461825.514,,0.000000e+000,3.499989e+001,7.889773e-006,0.000000e+000,3,9.222573e-001,0.000000e+000,,,,,,,,,,,,,,32,1,4.000000e+000,7.781982e-004,0.000000e+000,0,,0,
1524461877.572,,0.000000e+000,3.499989e+001,7.899818e-006,0.000000e+000,3,9.122085e-001,0.000000e+000,,,,,,,,,,,,,,32,1,4.000000e+000,7.781982e-004,0.000000e+000,0,,0,
1524461915.115,,0.000000e+000,3.499872e+001,7.944260e-006,0.000000e+000,3,9.133378e-001,0.000000e+000,,,,,,,,,,,,,,32,1,4.000000e+000,0.000000e+000,0.000000e+000,0,,0,
1524461952.881,,0.000000e+000,3.499833e+001,7.889605e-006,0.000000e+000,3,9.174805e-001,0.000000e+000,,,,,,,,,,,,,,32,1,4.000000e+000,7.781982e-004,0.000000e+000,0,,0,
1524461990.246,,0.000000e+000,3.499911e+001,7.943665e-006,0.000000e+000,3,9.141330e-001,0.000000e+000,,,,,,,,,,,,,,32,1,4.000000e+000,7.820129e-004,0.000000e+000,0,,0,
1524462028.824,,0.000000e+000,3.499950e+001,7.905968e-006,0.000000e+000,3,9.150346e-001,0.000000e+000,,,,,,,,,,,,,,32,1,4.000000e+000,0.000000e+000,0.000000e+000,0,,0,
1524462065.778,,0.000000e+000,3.499911e+001,7.898178e-006,0.000000e+000,3,9.153734e-001,0.000000e+000,,,,,,,,,,,,,,32,1,4.000000e+000,7.820129e-004,0.000000e+000,0,,0,
1524462102.978,,0.000000e+000,3.499950e+001,7.957714e-006,0.000000e+000,3,9.165227e-001,0.000000e+000,,,,,,,,,,,,,,32,1,4.000000e+000,1.560211e-003,0.000000e+000,0,,0,
1524462141.049,,0.000000e+000,3.499950e+001,7.954545e-006,0.000000e+000,3,9.190997e-001,0.000000e+000,,,,,,,,,,,,,,32,1,4.000000e+000,1.560211e-003,0.000000e+000,0,,0,
1524462179.109,,0.000000e+000,3.499911e+001,7.928334e-006,0.000000e+000,3,9.191413e-001,0.000000e+000,,,,,,,,,,,,,,32,1,4.000000e+000,7.820129e-004,0.000000e+000,0,,0,
1524462216.082,,0.000000e+000,3.499833e+001,7.935503e-006,0.000000e+000,3,9.175348e-001,0.000000e+000,,,,,,,,,,,,,,32,1,4.000000e+000,7.781982e-004,0.000000e+000,0,,0,
1524462254.015,,0.000000e+000,3.499911e+001,7.972084e-006,0.000000e+000,3,9.156145e-001,0.000000e+000,,,,,,,,,,,,,,32,1,4.000000e+000,7.820129e-004,0.000000e+000,0,,0,
1524462291.393,,0.000000e+000,3.499950e+001,7.948018e-006,0.000000e+000,3,9.135016e-001,0.000000e+000,,,,,,,,,,,,,,32,1,4.000000e+000,0.000000e+000,0.000000e+000,0,,0,
1524462329.509,,0.000000e+000,3.499872e+001,7.957327e-006,0.000000e+000,3,9.158880e-001,0.000000e+000,,,,,,,,,,,,,,32,1,4.000000e+000,1.560211e-003,0.000000e+000,0,,0,
1524462367.660,,0.000000e+000,3.499911e+001,8.015430e-006,0.000000e+000,3,9.204314e-001,0.000000e+000,,,,,,,,,,,,,,32,1,4.000000e+000,7.820129e-004,0.000000e+000,0,,0,
1524462405.205,,0.000000e+000,3.499871e+001,7.965608e-006,0.000000e+000,3,9.191694e-001,0.000000e+000,,,,,,,,,,,,,,32,1,4.000000e+000,3.128052e-003,0.000000e+000,0,,0,
1524462443.143,,0.000000e+000,3.499911e+001,7.961467e-006,0.000000e+000,3,9.155852e-001,0.000000e+000,,,,,,,,,,,,,,32,1,4.000000e+000,7.820129e-004,0.000000e+000,0,,0,
1524462481.204,,0.000000e+000,3.500067e+001,7.994853e-006,0.000000e+000,3,9.201167e-001,0.000000e+000,,,,,,,,,,,,,,32,1,4.000000e+000,7.820129e-004,0.000000e+000,0,,0,
1524462519.339,,0.000000e+000,3.499872e+001,7.972628e-006,0.000000e+000,3,9.165952e-001,0.000000e+000,,,,,,,,,,,,,,32,1,4.000000e+000,1.560211e-003,0.000000e+000,0,,0,
1524462556.530,,0.000000e+000,3.499833e+001,7.979849e-006,0.000000e+000,3,9.173202e-001,0.000000e+000,,,,,,,,,,,,,,32,1,4.000000e+000,7.781982e-004,0.000000e+000,0,,0,
1524462594.155,,0.000000e+000,3.499911e+001,7.959882e-006,0.000000e+000,3,9.184756e-001,0.000000e+000,,,,,,,,,,,,,,32,1,4.000000e+000,7.820129e-004,0.000000e+000,0,,0,
1524462632.196,,0.000000e+000,3.499950e+001,7.948037e-006,0.000000e+000,3,9.175954e-001,0.000000e+000,,,,,,,,,,,,,,32,1,4.000000e+000,0.000000e+000,0.000000e+000,0,,0,
1524462670.169,,0.000000e+000,3.499950e+001,7.975905e-006,0.000000e+000,3,9.194115e-001,0.000000e+000,,,,,,,,,,,,,,32,1,4.000000e+000,0.000000e+000,0.000000e+000,0,,0,
1524462708.222,,0.000000e+000,3.499950e+001,7.983230e-006,0.000000e+000,3,9.197282e-001,0.000000e+000,,,,,,,,,,,,,,32,1,4.000000e+000,1.560211e-003,0.000000e+000,0,,0,
1524462746.680,,0.000000e+000,3.499989e+001,8.004733e-006,0.000000e+000,3,9.152450e-001,0.000000e+000,,,,,,,,,,,,,,32,1,4.000000e+000,7.781982e-004,0.000000e+000,0,,0,
1524462797.698,,0.000000e+000,3.499950e+001,8.015603e-006,0.000000e+000,3,9.153889e-001,0.000000e+000,,,,,,,,,,,,,,32,1,4.000000e+000,1.560211e-003,0.000000e+000,0,,0,
1524462835.636,,0.000000e+000,3.499833e+001,7.990285e-006,0.000000e+000,3,9.190778e-001,0.000000e+000,,,,,,,,,,,,,,32,1,4.000000e+000,7.781982e-004,0.000000e+000,0,,0,
1524462875.199,,0.000000e+000,3.499950e+001,8.011441e-006,0.000000e+000,3,9.188958e-001,0.000000e+000,,,,,,,,,,,,,,32,1,4.000000e+000,1.560211e-003,0.000000e+000,0,,0,
1524462913.115,,0.000000e+000,3.499911e+001,8.034190e-006,0.000000e+000,3,9.185817e-001,0.000000e+000,,,,,,,,,,,,,,32,1,4.000000e+000,2.338409e-003,0.000000e+000,0,,0,
1524462951.126,,0.000000e+000,3.499833e+001,8.048991e-006,0.000000e+000,3,9.244232e-001,0.000000e+000,,,,,,,,,,,,,,32,1,4.000000e+000,7.781982e-004,0.000000e+000,0,,0,
1524462988.694,,0.000000e+000,3.499950e+001,7.995580e-006,0.000000e+000,3,9.208701e-001,0.000000e+000,,,,,,,,,,,,,,32,1,4.000000e+000,0.000000e+000,0.000000e+000,0,,0,
1524463026.119,,0.000000e+000,3.499950e+001,8.004989e-006,0.000000e+000,3,9.205018e-001,0.000000e+000,,,,,,,,,,,,,,32,1,4.000000e+000,1.560211e-003,0.000000e+000,0,,0,
1524463064.077,,0.000000e+000,3.499833e+001,8.039894e-006,0.000000e+000,3,9.191324e-001,0.000000e+000,,,,,,,,,,,,,,32,1,4.000000e+000,7.781982e-004,0.000000e+000,0,,0,
1524463102.138,,0.000000e+000,3.499950e+001,8.059495e-006,0.000000e+000,3,9.208658e-001,0.000000e+000,,,,,,,,,,,,,,32,1,4.000000e+000,0.000000e+000,0.000000e+000,0,,0,
1524463139.746,,0.000000e+000,3.499911e+001,8.030882e-006,0.000000e+000,3,9.191419e-001,0.000000e+000,,,,,,,,,,,,,,32,1,4.000000e+000,7.820129e-004,0.000000e+000,0,,0,
1524463178.614,,0.000000e+000,3.499872e+001,8.029391e-006,0.000000e+000,3,9.249566e-001,0.000000e+000,,,,,,,,,,,,,,32,1,4.000000e+000,0.000000e+000,0.000000e+000,0,,0,
1524463216.535,,0.000000e+000,3.499754e+001,8.059337e-006,0.000000e+000,3,9.198257e-001,0.000000e+000,,,,,,,,,,,,,,32,1,4.000000e+000,7.896423e-004,0.000000e+000,0,,0,
1524463254.605,,0.000000e+000,3.499794e+001,8.018114e-006,0.000000e+000,3,9.221948e-001,0.000000e+000,,,,,,,,,,,,,,32,1,4.000000e+000,0.000000e+000,0.000000e+000,0,,0,
1524463292.446,,0.000000e+000,3.499833e+001,8.067683e-006,0.000000e+000,3,9.183403e-001,0.000000e+000,,,,,,,,,,,,,,32,1,4.000000e+000,7.781982e-004,0.000000e+000,0,,0,
1524463330.166,,0.000000e+000,3.500028e+001,8.044415e-006,0.000000e+000,3,9.187829e-001,0.000000e+000,,,,,,,,,,,,,,32,1,4.000000e+000,1.560211e-003,0.000000e+000,0,,0,
1524463368.064,,0.000000e+000,3.500185e+001,8.010130e-006,0.000000e+000,3,9.210533e-001,0.000000e+000,,,,,,,,,,,,,,32,1,4.000000e+000,3.131866e-003,0.000000e+000,0,,0,
1524463406.515,,0.000000e+000,3.499871e+001,8.038167e-006,0.000000e+000,3,9.216903e-001,0.000000e+000,,,,,,,,,,,,,,32,1,4.000000e+000,3.128052e-003,0.000000e+000,0,,0,
1524463445.145,,0.000000e+000,3.499872e+001,8.046856e-006,0.000000e+000,3,9.224816e-001,0.000000e+000,,,,,,,,,,,,,,32,1,4.000000e+000,1.560211e-003,0.000000e+000,0,,0,
1524463483.333,,0.000000e+000,3.499950e+001,8.059500e-006,0.000000e+000,3,9.209644e-001,0.000000e+000,,,,,,,,,,,,,,32,1,4.000000e+000,1.560211e-003,0.000000e+000,0,,0,
1524463521.651,,0.000000e+000,3.499950e+001,8.085896e-006,0.000000e+000,3,9.132957e-001,0.000000e+000,,,,,,,,,,,,,,32,1,4.000000e+000,0.000000e+000,0.000000e+000,0,,0,
1524463559.544,,0.000000e+000,3.499833e+001,8.024578e-006,0.000000e+000,3,9.222243e-001,0.000000e+000,,,,,,,,,,,,,,32,1,4.000000e+000,2.349854e-003,0.000000e+000,0,,0,
1524463597.675,,0.000000e+000,3.499950e+001,8.051968e-006,0.000000e+000,3,9.217947e-001,0.000000e+000,,,,,,,,,,,,,,32,1,4.000000e+000,1.560211e-003,0.000000e+000,0,,0,
1524463635.536,,0.000000e+000,3.500185e+001,7.979584e-006,0.000000e+000,3,9.109656e-001,0.000000e+000,,,,,,,,,,,,,,32,1,4.000000e+000,4.688263e-003,0.000000e+000,0,,0,
1524463673.391,,0.000000e+000,3.500028e+001,8.054648e-006,0.000000e+000,3,9.189165e-001,0.000000e+000,,,,,,,,,,,,,,32,1,4.000000e+000,1.560211e-003,0.000000e+000,0,,0,
1524463725.289,,0.000000e+000,3.499989e+001,8.091036e-006,0.000000e+000,3,9.187591e-001,0.000000e+000,,,,,,,,,,,,,,32,1,4.000000e+000,7.781982e-004,0.000000e+000,0,,0,
1524463763.450,,0.000000e+000,3.499911e+001,8.062188e-006,0.000000e+000,3,9.194685e-001,0.000000e+000,,,,,,,,,,,,,,32,1,4.000000e+000,7.820129e-004,0.000000e+000,0,,0,
1524463801.523,,0.000000e+000,3.499989e+001,8.054701e-006,0.000000e+000,3,9.186172e-001,0.000000e+000,,,,,,,,,,,,,,32,1,4.000000e+000,7.781982e-004,0.000000e+000,0,,0,
1524463839.504,,0.000000e+000,3.499872e+001,8.056179e-006,0.000000e+000,3,9.235393e-001,0.000000e+000,,,,,,,,,,,,,,32,1,4.000000e+000,1.560211e-003,0.000000e+000,0,,0,
1524463877.562,,0.000000e+000,3.499950e+001,8.075923e-006,0.000000e+000,3,9.184289e-001,0.000000e+000,,,,,,,,,,,,,,32,1,4.000000e+000,1.560211e-003,0.000000e+000,0,,0,
1524463916.102,,0.000000e+000,3.499911e+001,8.093752e-006,0.000000e+000,3,9.205015e-001,0.000000e+000,,,,,,,,,,,,,,32,1,4.000000e+000,7.820129e-004,0.000000e+000,0,,0,
1524463953.900,,0.000000e+000,3.500067e+001,8.094568e-006,0.000000e+000,3,9.191100e-001,0.000000e+000,,,,,,,,,,,,,,32,1,4.000000e+000,2.338409e-003,0.000000e+000,0,,0,
1524463991.998,,0.000000e+000,3.499911e+001,8.043608e-006,0.000000e+000,3,9.223166e-001,0.000000e+000,,,,,,,,,,,,,,32,1,4.000000e+000,7.820129e-004,0.000000e+000,0,,0,
1524464030.059,,0.000000e+000,3.499677e+001,8.061606e-006,0.000000e+000,3,9.193234e-001,0.000000e+000,,,,,,,,,,,,,,32,1,4.000000e+000,3.910065e-003,0.000000e+000,0,,0,
1524464068.512,,0.000000e+000,3.499950e+001,8.101167e-006,0.000000e+000,3,9.220718e-001,0.000000e+000,,,,,,,,,,,,,,32,1,4.000000e+000,0.000000e+000,0.000000e+000,0,,0,
1524464105.793,,0.000000e+000,3.499911e+001,8.128884e-006,0.000000e+000,3,9.200972e-001,0.000000e+000,,,,,,,,,,,,,,32,1,4.000000e+000,7.820129e-004,0.000000e+000,0,,0,
1524464144.081,,0.000000e+000,3.499872e+001,8.088012e-006,0.000000e+000,3,9.205906e-001,0.000000e+000,,,,,,,,,,,,,,32,1,4.000000e+000,1.560211e-003,0.000000e+000,0,,0,
1524464181.909,,0.000000e+000,3.499989e+001,8.038496e-006,0.000000e+000,3,9.195357e-001,0.000000e+000,,,,,,,,,,,,,,32,1,4.000000e+000,7.781982e-004,0.000000e+000,0,,0,
1524464219.939,,0.000000e+000,3.499950e+001,8.047654e-006,0.000000e+000,3,9.184217e-001,0.000000e+000,,,,,,,,,,,,,,32,1,4.000000e+000,0.000000e+000,0.000000e+000,0,,0,
1524464258.717,,0.000000e+000,3.499911e+001,8.122457e-006,0.000000e+000,3,9.237884e-001,0.000000e+000,,,,,,,,,,,,,,32,1,4.000000e+000,7.820129e-004,0.000000e+000,0,,0,
1524464297.098,,0.000000e+000,3.499950e+001,8.102507e-006,0.000000e+000,3,9.208587e-001,0.000000e+000,,,,,,,,,,,,,,32,1,4.000000e+000,0.000000e+000,0.000000e+000,0,,0,
1524464334.656,,0.000000e+000,3.499989e+001,8.088568e-006,0.000000e+000,3,9.206986e-001,0.000000e+000,,,,,,,,,,,,,,32,1,4.000000e+000,7.781982e-004,0.000000e+000,0,,0,
1524464372.756,,0.000000e+000,3.499911e+001,8.089981e-006,0.000000e+000,3,9.193327e-001,0.000000e+000,,,,,,,,,,,,,,32,1,4.000000e+000,7.820129e-004,0.000000e+000,0,,0,
1524464411.527,,0.000000e+000,3.499950e+001,8.093987e-006,0.000000e+000,3,9.219131e-001,0.000000e+000,,,,,,,,,,,,,,32,1,4.000000e+000,0.000000e+000,0.000000e+000,0,,0,
1524464449.600,,0.000000e+000,3.499872e+001,8.071795e-006,0.000000e+000,3,9.245179e-001,0.000000e+000,,,,,,,,,,,,,,32,1,4.000000e+000,1.560211e-003,0.000000e+000,0,,0,
1524464487.678,,0.000000e+000,3.499911e+001,8.104985e-006,0.000000e+000,3,9.221424e-001,0.000000e+000,,,,,,,,,,,,,,32,1,4.000000e+000,7.820129e-004,0.000000e+000,0,,0,
1524464525.711,,0.000000e+000,3.499950e+001,8.097822e-006,0.000000e+000,3,9.189454e-001,0.000000e+000,,,,,,,,,,,,,,32,1,4.000000e+000,0.000000e+000,0.000000e+000,0,,0,
1524464564.257,,0.000000e+000,3.499989e+001,8.062459e-006,0.000000e+000,3,9.233723e-001,0.000000e+000,,,,,,,,,,,,,,32,1,4.000000e+000,7.781982e-004,0.000000e+000,0,,0,
1524464601.847,,0.000000e+000,3.499911e+001,7.971159e-006,0.000000e+000,3,9.175085e-001,0.000000e+000,,,,,,,,,,,,,,32,1,4.000000e+000,7.820129e-004,0.000000e+000,0,,0,
1524464653.458,,0.000000e+000,3.500028e+001,8.140982e-006,0.000000e+000,3,9.207203e-001,0.000000e+000,,,,,,,,,,,,,,32,1,4.000000e+000,0.000000e+000,0.000000e+000,0,,0,
1524464691.369,,0.000000e+000,3.499872e+001,8.115641e-006,0.000000e+000,3,9.214091e-001,0.000000e+000,,,,,,,,,,,,,,32,1,4.000000e+000,0.000000e+000,0.000000e+000,0,,0,
1524464728.872,,0.000000e+000,3.499872e+001,8.085760e-006,0.000000e+000,3,9.205950e-001,0.000000e+000,,,,,,,,,,,,,,32,1,4.000000e+000,0.000000e+000,0.000000e+000,0,,0,
1524464766.725,,0.000000e+000,3.499950e+001,8.073014e-006,0.000000e+000,3,9.246156e-001,0.000000e+000,,,,,,,,,,,,,,32,1,4.000000e+000,0.000000e+000,0.000000e+000,0,,0,
1524464804.738,,0.000000e+000,3.499911e+001,8.084636e-006,0.000000e+000,3,9.216075e-001,0.000000e+000,,,,,,,,,,,,,,32,1,4.000000e+000,7.820129e-004,0.000000e+000,0,,0,
1524464842.131,,0.000000e+000,3.499989e+001,8.101661e-006,0.000000e+000,3,9.235987e-001,0.000000e+000,,,,,,,,,,,,,,32,1,4.000000e+000,7.781982e-004,0.000000e+000,0,,0,
1524464879.634,,0.000000e+000,3.499950e+001,8.115130e-006,0.000000e+000,3,9.188343e-001,0.000000e+000,,,,,,,,,,,,,,32,1,4.000000e+000,0.000000e+000,0.000000e+000,0,,0,
1524464917.694,,0.000000e+000,3.499911e+001,8.102100e-006,0.000000e+000,3,9.205141e-001,0.000000e+000,,,,,,,,,,,,,,32,1,4.000000e+000,7.820129e-004,0.000000e+000,0,,0,
1524464955.857,,0.000000e+000,3.500028e+001,8.104739e-006,0.000000e+000,3,9.182239e-001,0.000000e+000,,,,,,,,,,,,,,32,1,4.000000e+000,1.560211e-003,0.000000e+000,0,,0,
1524464993.231,,0.000000e+000,3.499950e+001,8.105697e-006,0.000000e+000,3,9.182893e-001,0.000000e+000,,,,,,,,,,,,,,32,1,4.000000e+000,0.000000e+000,0.000000e+000,0,,0,
1524465031.236,,0.000000e+000,3.499872e+001,8.116775e-006,0.000000e+000,3,9.203016e-001,0.000000e+000,,,,,,,,,,,,,,32,1,4.000000e+000,1.560211e-003,0.000000e+000,0,,0,
1524465068.649,,0.000000e+000,3.499911e+001,8.108930e-006,0.000000e+000,3,9.223478e-001,0.000000e+000,,,,,,,,,,,,,,32,1,4.000000e+000,7.820129e-004,0.000000e+000,0,,0,
1524465106.750,,0.000000e+000,3.499911e+001,8.089913e-006,0.000000e+000,3,9.208202e-001,0.000000e+000,,,,,,,,,,,,,,32,1,4.000000e+000,7.820129e-004,0.000000e+000,0,,0,
1524465145.860,,0.000000e+000,3.499911e+001,8.103524e-006,0.000000e+000,3,9.202290e-001,0.000000e+000,,,,,,,,,,,,,,32,1,4.000000e+000,7.820129e-004,0.000000e+000,0,,0,
1524465183.623,,0.000000e+000,3.499911e+001,8.097219e-006,0.000000e+000,3,9.175208e-001,0.000000e+000,,,,,,,,,,,,,,32,1,4.000000e+000,7.820129e-004,0.000000e+000,0,,0,
1524465222.241,,0.000000e+000,3.499950e+001,8.126827e-006,0.000000e+000,3,9.215009e-001,0.000000e+000,,,,,,,,,,,,,,32,1,4.000000e+000,0.000000e+000,0.000000e+000,0,,0,
1524465260.662,,0.000000e+000,3.499911e+001,8.111992e-006,0.000000e+000,3,9.207542e-001,0.000000e+000,,,,,,,,,,,,,,32,1,4.000000e+000,7.820129e-004,0.000000e+000,0,,0,
1524465298.720,,0.000000e+000,3.499832e+001,8.127900e-006,0.000000e+000,3,9.198041e-001,0.000000e+000,,,,,,,,,,,,,,32,1,4.000000e+000,3.910065e-003,0.000000e+000,0,,0,
1524465336.828,,0.000000e+000,3.499872e+001,8.111281e-006,0.000000e+000,3,9.218958e-001,0.000000e+000,,,,,,,,,,,,,,32,1,4.000000e+000,0.000000e+000,0.000000e+000,0,,0,
1524465374.879,,0.000000e+000,3.500067e+001,8.090081e-006,0.000000e+000,3,9.180300e-001,0.000000e+000,,,,,,,,,,,,,,32,1,4.000000e+000,2.338409e-003,0.000000e+000,0,,0,
1524465412.932,,0.000000e+000,3.499950e+001,8.128044e-006,0.000000e+000,3,9.189950e-001,0.000000e+000,,,,,,,,,,,,,,32,1,4.000000e+000,0.000000e+000,0.000000e+000,0,,0,
1524465450.995,,0.000000e+000,3.500067e+001,8.081184e-006,0.000000e+000,3,9.181256e-001,0.000000e+000,,,,,,,,,,,,,,32,1,4.000000e+000,2.338409e-003,0.000000e+000,0,,0,
1524465488.905,,0.000000e+000,3.499833e+001,8.247300e-006,0.000000e+000,3,9.165332e-001,0.000000e+000,,,,,,,,,,,,,,32,1,4.000000e+000,2.349854e-003,0.000000e+000,0,,0,
1524465527.498,,0.000000e+000,3.499950e+001,8.136300e-006,0.000000e+000,3,9.252837e-001,0.000000e+000,,,,,,,,,,,,,,32,1,4.000000e+000,0.000000e+000,0.000000e+000,0,,0,
1524465540.171,,0.000000e+000,3.499872e+001,8.060070e-006,0.000000e+000,3,9.197462e-001,0.000000e+000,,,,,,,,,,,,,,32,1,4.000000e+000,1.560211e-003,0.000000e+000,0,,0,