File: Experimental Raw Data/MFn1 VRM/Adjusting Iterative/MFn1_VRMac_36K_3000s_VRMde_35K.dc.dat
[Header]
TITLE,MPMS DC Measurement
BYAPP,MPMS Measurement,2.1,Summary
FILEOPENTIME, 1524301131.885000 4/21/2018, 2:58:51 AM

INFO, APPNAME, MPMS MultiVu Application, Revision 1.61,  Build 082

INFO, NAME, MFn1
INFO, WEIGHT, 1.000
INFO, AREA, 1.000
INFO, LENGTH, 1.000
INFO, SHAPE, 0
INFO, COMMENT,
INFO, SEQUENCE FILE: VRMac_36K_3000s_VRMde_35K.seq


INFO, BACKGROUND DATA FILE:, None


STARTUPAXIS,X,4,LINEAR,AUTO,0.000000,0.000000
STARTUPAXIS,Y1,5,LINEAR,AUTO,0.000000,0.000000


STARTUPGROUP,Longitudinal
FIELDGROUP,Longitudinal,1,2,3,4,5,6,7,8,9,15,16,17,18,27,28
FIELDGROUP,Transverse,1,2,3,4,10,11,12,13,14,19,20,21,22,27,28

PLOT_APPEARANCE,ALL,HORZ_GRID_ON,VERT_GRID_ON,MARKERS_AND_LINES

[Data]
Time,Comment,Field (Oe),Temperature (K),Long Moment (emu),Long Scan Std Dev,Long Algorithm,Long Reg Fit,Long Percent Error (%),Trans Moment (emu),Trans Scan Std Dev,Trans Algorithm,Trans Reg Fit,Trans Percent Error (%),Long Moment [w/o ABS] (emu),Long Scan Std Dev [w/o ABS],Long Reg Fit [w/o ABS],Long Percent Error [w/o ABS] (%),Trans Moment [w/o ABS] (emu),Trans Scan Std Dev [w/o ABS],Trans Reg Fit [w/o ABS],Trans Percent Error [w/o ABS] (%),Points per Scan,Scans per Measurement,Scan Length (cm),Delta Temp (K),Rot Position (deg),Error,EC Comp. Running,Using ABS,
1524474280.822,,0.000000e+000,3.500341e+001,-1.036639e-005,0.000000e+000,3,9.329690e-001,0.000000e+000,,,,,,,,,,,,,,32,1,4.000000e+000,1.560211e-003,0.000000e+000,0,,0,
1524474317.987,,0.000000e+000,3.500380e+001,-9.689177e-006,0.000000e+000,3,9.272534e-001,0.000000e+000,,,,,,,,,,,,,,32,1,4.000000e+000,7.781982e-004,0.000000e+000,0,,0,
1524474355.978,,0.000000e+000,3.500145e+001,-9.037753e-006,0.000000e+000,3,9.256300e-001,0.000000e+000,,,,,,,,,,,,,,32,1,4.000000e+000,7.781982e-004,0.000000e+000,0,,0,
1524474394.013,,0.000000e+000,3.499950e+001,-8.410044e-006,0.000000e+000,3,9.126686e-001,0.000000e+000,,,,,,,,,,,,,,32,1,4.000000e+000,0.000000e+000,0.000000e+000,0,,0,
1524474432.029,,0.000000e+000,3.499950e+001,-7.836751e-006,0.000000e+000,3,9.090374e-001,0.000000e+000,,,,,,,,,,,,,,32,1,4.000000e+000,0.000000e+000,0.000000e+000,0,,0,
1524474469.875,,0.000000e+000,3.499833e+001,-7.357739e-006,0.000000e+000,3,8.983577e-001,0.000000e+000,,,,,,,,,,,,,,32,1,4.000000e+000,7.781982e-004,0.000000e+000,0,,0,
1524474507.818,,0.000000e+000,3.499989e+001,-6.898790e-006,0.000000e+000,3,8.975298e-001,0.000000e+000,,,,,,,,,,,,,,32,1,4.000000e+000,7.781982e-004,0.000000e+000,0,,0,
1524474547.473,,0.000000e+000,3.499754e+001,-6.545707e-006,0.000000e+000,3,8.940394e-001,0.000000e+000,,,,,,,,,,,,,,32,1,4.000000e+000,2.349854e-003,0.000000e+000,0,,0,
1524474585.484,,0.000000e+000,3.499911e+001,-6.158224e-006,0.000000e+000,3,8.885424e-001,0.000000e+000,,,,,,,,,,,,,,32,1,4.000000e+000,7.820129e-004,0.000000e+000,0,,0,
1524474623.537,,0.000000e+000,3.499911e+001,-5.751411e-006,0.000000e+000,3,8.755642e-001,0.000000e+000,,,,,,,,,,,,,,32,1,4.000000e+000,7.820129e-004,0.000000e+000,0,,0,
1524474661.655,,0.000000e+000,3.499950e+001,-5.411574e-006,0.000000e+000,3,8.640235e-001,0.000000e+000,,,,,,,,,,,,,,32,1,4.000000e+000,0.000000e+000,0.000000e+000,0,,0,
1524474699.428,,0.000000e+000,3.499872e+001,-5.096505e-006,0.000000e+000,3,8.696722e-001,0.000000e+000,,,,,,,,,,,,,,32,1,4.000000e+000,0.000000e+000,0.000000e+000,0,,0,
1524474737.186,,0.000000e+000,3.499950e+001,-4.904730e-006,0.000000e+000,3,8.609700e-001,0.000000e+000,,,,,,,,,,,,,,32,1,4.000000e+000,0.000000e+000,0.000000e+000,0,,0,
1524474775.659,,0.000000e+000,3.499911e+001,-4.608121e-006,0.000000e+000,3,8.470255e-001,0.000000e+000,,,,,,,,,,,,,,32,1,4.000000e+000,7.820129e-004,0.000000e+000,0,,0,
1524474813.397,,0.000000e+000,3.499989e+001,-4.414173e-006,0.000000e+000,3,8.422992e-001,0.000000e+000,,,,,,,,,,,,,,32,1,4.000000e+000,7.781982e-004,0.000000e+000,0,,0,
1524474852.153,,0.000000e+000,3.499793e+001,-4.162218e-006,0.000000e+000,3,8.163394e-001,0.000000e+000,,,,,,,,,,,,,,32,1,4.000000e+000,1.567841e-003,0.000000e+000,0,,0,
1524474890.896,,0.000000e+000,3.499950e+001,-3.918410e-006,0.000000e+000,3,8.287920e-001,0.000000e+000,,,,,,,,,,,,,,32,1,4.000000e+000,1.560211e-003,0.000000e+000,0,,0,
1524474928.221,,0.000000e+000,3.499950e+001,-3.741812e-006,0.000000e+000,3,7.936621e-001,0.000000e+000,,,,,,,,,,,,,,32,1,4.000000e+000,0.000000e+000,0.000000e+000,0,,0,
1524474966.207,,0.000000e+000,3.499872e+001,-3.534093e-006,0.000000e+000,3,7.931933e-001,0.000000e+000,,,,,,,,,,,,,,32,1,4.000000e+000,0.000000e+000,0.000000e+000,0,,0,
1524475004.325,,0.000000e+000,3.499950e+001,-3.422548e-006,0.000000e+000,3,7.923284e-001,0.000000e+000,,,,,,,,,,,,,,32,1,4.000000e+000,1.560211e-003,0.000000e+000,0,,0,
1524475042.730,,0.000000e+000,3.499794e+001,-3.178103e-006,0.000000e+000,3,7.800778e-001,0.000000e+000,,,,,,,,,,,,,,32,1,4.000000e+000,0.000000e+000,0.000000e+000,0,,0,
1524475081.659,,0.000000e+000,3.499911e+001,-3.082220e-006,0.000000e+000,3,7.811847e-001,0.000000e+000,,,,,,,,,,,,,,32,1,4.000000e+000,7.820129e-004,0.000000e+000,0,,0,
1524475119.674,,0.000000e+000,3.499911e+001,-2.906803e-006,0.000000e+000,3,7.667848e-001,0.000000e+000,,,,,,,,,,,,,,32,1,4.000000e+000,7.820129e-004,0.000000e+000,0,,0,
1524475157.870,,0.000000e+000,3.499911e+001,-2.758186e-006,0.000000e+000,3,7.427697e-001,0.000000e+000,,,,,,,,,,,,,,32,1,4.000000e+000,7.820129e-004,0.000000e+000,0,,0,
1524475209.238,,0.000000e+000,3.499911e+001,-2.399794e-006,0.000000e+000,3,6.669226e-001,0.000000e+000,,,,,,,,,,,,,,32,1,4.000000e+000,7.820129e-004,0.000000e+000,0,,0,
1524475247.204,,0.000000e+000,3.499833e+001,-2.361274e-006,0.000000e+000,3,6.759760e-001,0.000000e+000,,,,,,,,,,,,,,32,1,4.000000e+000,7.781982e-004,0.000000e+000,0,,0,
1524475285.187,,0.000000e+000,3.499911e+001,-2.181662e-006,0.000000e+000,3,6.288976e-001,0.000000e+000,,,,,,,,,,,,,,32,1,4.000000e+000,7.820129e-004,0.000000e+000,0,,0,
1524475323.155,,0.000000e+000,3.499793e+001,-2.054279e-006,0.000000e+000,3,5.725592e-001,0.000000e+000,,,,,,,,,,,,,,32,1,4.000000e+000,3.131866e-003,0.000000e+000,0,,0,
1524475361.058,,0.000000e+000,3.499911e+001,-1.982844e-006,0.000000e+000,3,6.021903e-001,0.000000e+000,,,,,,,,,,,,,,32,1,4.000000e+000,7.820129e-004,0.000000e+000,0,,0,
1524475399.416,,0.000000e+000,3.499950e+001,-1.872862e-006,0.000000e+000,3,5.874116e-001,0.000000e+000,,,,,,,,,,,,,,32,1,4.000000e+000,0.000000e+000,0.000000e+000,0,,0,
1524475437.611,,0.000000e+000,3.499911e+001,-1.757909e-006,0.000000e+000,3,5.379052e-001,0.000000e+000,,,,,,,,,,,,,,32,1,4.000000e+000,7.820129e-004,0.000000e+000,0,,0,
1524475476.479,,0.000000e+000,3.500067e+001,-1.626083e-006,0.000000e+000,3,4.978118e-001,0.000000e+000,,,,,,,,,,,,,,32,1,4.000000e+000,7.820129e-004,0.000000e+000,0,,0,
1524475515.305,,0.000000e+000,3.499989e+001,-1.549527e-006,0.000000e+000,3,4.473234e-001,0.000000e+000,,,,,,,,,,,,,,32,1,4.000000e+000,2.342224e-003,0.000000e+000,0,,0,
1524475552.940,,0.000000e+000,3.499911e+001,-1.481259e-006,0.000000e+000,3,4.698738e-001,0.000000e+000,,,,,,,,,,,,,,32,1,4.000000e+000,2.338409e-003,0.000000e+000,0,,0,
1524475590.954,,0.000000e+000,3.499950e+001,-1.281166e-006,0.000000e+000,3,3.681890e-001,0.000000e+000,,,,,,,,,,,,,,32,1,4.000000e+000,0.000000e+000,0.000000e+000,0,,0,
1524475629.159,,0.000000e+000,3.499793e+001,-1.222546e-006,0.000000e+000,3,3.449443e-001,0.000000e+000,,,,,,,,,,,,,,32,1,4.000000e+000,1.567841e-003,0.000000e+000,0,,0,
1524475666.757,,0.000000e+000,3.500028e+001,-1.119933e-006,0.000000e+000,3,2.904412e-001,0.000000e+000,,,,,,,,,,,,,,32,1,4.000000e+000,1.560211e-003,0.000000e+000,0,,0,
1524475704.910,,0.000000e+000,3.499950e+001,-1.000475e-006,0.000000e+000,3,2.232841e-001,0.000000e+000,,,,,,,,,,,,,,32,1,4.000000e+000,0.000000e+000,0.000000e+000,0,,0,
1524475744.021,,0.000000e+000,3.499950e+001,-9.819979e-007,0.000000e+000,3,2.035941e-001,0.000000e+000,,,,,,,,,,,,,,32,1,4.000000e+000,1.560211e-003,0.000000e+000,0,,0,
1524475781.231,,0.000000e+000,3.499911e+001,-9.085836e-007,0.000000e+000,3,1.860038e-001,0.000000e+000,,,,,,,,,,,,,,32,1,4.000000e+000,7.820129e-004,0.000000e+000,0,,0,
1524475820.237,,0.000000e+000,3.499833e+001,-8.896162e-007,0.000000e+000,3,1.205286e-001,0.000000e+000,,,,,,,,,,,,,,32,1,4.000000e+000,7.781982e-004,0.000000e+000,0,,0,
1524475856.767,,0.000000e+000,3.500028e+001,-7.080575e-007,0.000000e+000,3,0.000000e+000,0.000000e+000,,,,,,,,,,,,,,32,1,4.000000e+000,1.560211e-003,0.000000e+000,0,,0,
1524475894.825,,0.000000e+000,3.499950e+001,-6.731755e-007,0.000000e+000,3,0.000000e+000,0.000000e+000,,,,,,,,,,,,,,32,1,4.000000e+000,0.000000e+000,0.000000e+000,0,,0,
1524475932.571,,0.000000e+000,3.499833e+001,-5.716482e-007,0.000000e+000,3,0.000000e+000,0.000000e+000,,,,,,,,,,,,,,32,1,4.000000e+000,7.781982e-004,0.000000e+000,0,,0,
1524475970.959,,0.000000e+000,3.499911e+001,-4.743232e-007,0.000000e+000,3,0.000000e+000,0.000000e+000,,,,,,,,,,,,,,32,1,4.000000e+000,7.820129e-004,0.000000e+000,0,,0,
1524476008.862,,0.000000e+000,3.499911e+001,7.527889e-007,0.000000e+000,3,0.000000e+000,0.000000e+000,,,,,,,,,,,,,,32,1,4.000000e+000,7.820129e-004,0.000000e+000,0,,0,
1524476047.248,,0.000000e+000,3.499911e+001,5.281965e-007,0.000000e+000,3,0.000000e+000,0.000000e+000,,,,,,,,,,,,,,32,1,4.000000e+000,7.820129e-004,0.000000e+000,0,,0,
1524476087.339,,0.000000e+000,3.499911e+001,-1.854529e-007,0.000000e+000,2,0.000000e+000,0.000000e+000,,,,,,,,,,,,,,32,1,4.000000e+000,7.820129e-004,0.000000e+000,0,,0,
1524476141.735,,0.000000e+000,3.499989e+001,1.654196e-007,0.000000e+000,2,0.000000e+000,0.000000e+000,,,,,,,,,,,,,,32,1,4.000000e+000,2.342224e-003,0.000000e+000,0,,0,
1524476179.241,,0.000000e+000,3.499911e+001,-1.560194e-006,0.000000e+000,3,7.020675e-001,0.000000e+000,,,,,,,,,,,,,,32,1,4.000000e+000,2.338409e-003,0.000000e+000,0,,0,
1524476217.686,,0.000000e+000,3.499911e+001,-1.726285e-006,0.000000e+000,3,7.212245e-001,0.000000e+000,,,,,,,,,,,,,,32,1,4.000000e+000,7.820129e-004,0.000000e+000,0,,0,
1524476256.109,,0.000000e+000,3.499872e+001,-1.778831e-006,0.000000e+000,3,7.907581e-001,0.000000e+000,,,,,,,,,,,,,,32,1,4.000000e+000,0.000000e+000,0.000000e+000,0,,0,
1524476294.215,,0.000000e+000,3.499950e+001,-1.815656e-006,0.000000e+000,3,7.922407e-001,0.000000e+000,,,,,,,,,,,,,,32,1,4.000000e+000,0.000000e+000,0.000000e+000,0,,0,
1524476332.470,,0.000000e+000,3.499872e+001,-1.897841e-006,0.000000e+000,3,7.919014e-001,0.000000e+000,,,,,,,,,,,,,,32,1,4.000000e+000,0.000000e+000,0.000000e+000,0,,0,
1524476373.369,,0.000000e+000,3.499989e+001,3.894716e-008,0.000000e+000,2,0.000000e+000,0.000000e+000,,,,,,,,,,,,,,32,1,4.000000e+000,2.342224e-003,0.000000e+000,0,,0,
1524476412.778,,0.000000e+000,3.499872e+001,6.385699e-008,0.000000e+000,2,0.000000e+000,0.000000e+000,,,,,,,,,,,,,,32,1,4.000000e+000,0.000000e+000,0.000000e+000,0,,0,
1524476452.465,,0.000000e+000,3.499950e+001,-2.156812e-006,0.000000e+000,3,8.370244e-001,0.000000e+000,,,,,,,,,,,,,,32,1,4.000000e+000,1.560211e-003,0.000000e+000,0,,0,
1524476490.690,,0.000000e+000,3.499872e+001,1.766522e-006,0.000000e+000,3,5.166043e-001,0.000000e+000,,,,,,,,,,,,,,32,1,4.000000e+000,0.000000e+000,0.000000e+000,0,,0,
1524476533.706,,0.000000e+000,3.499872e+001,-4.962492e-008,0.000000e+000,2,0.000000e+000,0.000000e+000,,,,,,,,,,,,,,32,1,4.000000e+000,1.560211e-003,0.000000e+000,0,,0,
1524476572.937,,0.000000e+000,3.499950e+001,-2.299414e-006,0.000000e+000,3,8.186634e-001,0.000000e+000,,,,,,,,,,,,,,32,1,4.000000e+000,1.560211e-003,0.000000e+000,0,,0,
1524476610.898,,0.000000e+000,3.499911e+001,-2.348512e-006,0.000000e+000,3,8.282276e-001,0.000000e+000,,,,,,,,,,,,,,32,1,4.000000e+000,7.820129e-004,0.000000e+000,0,,0,
1524476649.836,,0.000000e+000,3.500028e+001,-2.399985e-006,0.000000e+000,3,8.174372e-001,0.000000e+000,,,,,,,,,,,,,,32,1,4.000000e+000,3.120422e-003,0.000000e+000,0,,0,
1524476693.985,,0.000000e+000,3.499911e+001,5.121848e-008,0.000000e+000,2,0.000000e+000,0.000000e+000,,,,,,,,,,,,,,32,1,4.000000e+000,7.820129e-004,0.000000e+000,0,,0,
1524476733.844,,0.000000e+000,3.499833e+001,2.138672e-006,0.000000e+000,3,6.048064e-001,0.000000e+000,,,,,,,,,,,,,,32,1,4.000000e+000,7.781982e-004,0.000000e+000,0,,0,
1524476774.760,,0.000000e+000,3.499950e+001,-2.645704e-006,0.000000e+000,3,8.322152e-001,0.000000e+000,,,,,,,,,,,,,,32,1,4.000000e+000,3.120422e-003,0.000000e+000,0,,0,
1524476817.644,,0.000000e+000,3.499950e+001,4.995991e-008,0.000000e+000,2,0.000000e+000,0.000000e+000,,,,,,,,,,,,,,32,1,4.000000e+000,0.000000e+000,0.000000e+000,0,,0,
1524476858.359,,0.000000e+000,3.499754e+001,3.972763e-008,0.000000e+000,2,0.000000e+000,0.000000e+000,,,,,,,,,,,,,,32,1,4.000000e+000,2.349854e-003,0.000000e+000,0,,0,
1524476895.487,,0.000000e+000,3.499950e+001,2.371657e-006,0.000000e+000,3,6.395838e-001,0.000000e+000,,,,,,,,,,,,,,32,1,4.000000e+000,0.000000e+000,0.000000e+000,0,,0,
1524476937.091,,0.000000e+000,3.500106e+001,-5.679181e-008,0.000000e+000,2,0.000000e+000,0.000000e+000,,,,,,,,,,,,,,32,1,4.000000e+000,0.000000e+000,0.000000e+000,0,,0,
1524476980.633,,0.000000e+000,3.499989e+001,-5.191038e-008,0.000000e+000,2,0.000000e+000,0.000000e+000,,,,,,,,,,,,,,32,1,4.000000e+000,2.342224e-003,0.000000e+000,0,,0,
1524477021.070,,0.000000e+000,3.499872e+001,8.480566e-008,0.000000e+000,2,0.000000e+000,0.000000e+000,,,,,,,,,,,,,,32,1,4.000000e+000,1.560211e-003,0.000000e+000,0,,0,
1524477059.736,,0.000000e+000,3.499833e+001,2.386976e-006,0.000000e+000,3,4.384722e-001,0.000000e+000,,,,,,,,,,,,,,32,1,4.000000e+000,7.781982e-004,0.000000e+000,0,,0,
1524477112.812,,0.000000e+000,3.499950e+001,-6.138506e-009,0.000000e+000,2,0.000000e+000,0.000000e+000,,,,,,,,,,,,,,32,1,4.000000e+000,1.560211e-003,0.000000e+000,0,,0,
1524477153.348,,0.000000e+000,3.499833e+001,-2.889853e-006,0.000000e+000,3,7.982301e-001,0.000000e+000,,,,,,,,,,,,,,32,1,4.000000e+000,7.781982e-004,0.000000e+000,0,,0,
1524477191.319,,0.000000e+000,3.499833e+001,-2.955235e-006,0.000000e+000,3,8.009605e-001,0.000000e+000,,,,,,,,,,,,,,32,1,4.000000e+000,2.349854e-003,0.000000e+000,0,,0,
1524477231.195,,0.000000e+000,3.499911e+001,-2.990564e-006,0.000000e+000,3,7.963586e-001,0.000000e+000,,,,,,,,,,,,,,32,1,4.000000e+000,7.820129e-004,0.000000e+000,0,,0,
1524477275.069,,0.000000e+000,3.500106e+001,-3.738482e-008,0.000000e+000,2,0.000000e+000,0.000000e+000,,,,,,,,,,,,,,32,1,4.000000e+000,3.128052e-003,0.000000e+000,0,,0,
1524477312.637,,0.000000e+000,3.500028e+001,-3.055571e-006,0.000000e+000,3,7.895246e-001,0.000000e+000,,,,,,,,,,,,,,32,1,4.000000e+000,1.560211e-003,0.000000e+000,0,,0,
1524477350.740,,0.000000e+000,3.499872e+001,-3.035920e-006,0.000000e+000,3,7.805101e-001,0.000000e+000,,,,,,,,,,,,,,32,1,4.000000e+000,1.560211e-003,0.000000e+000,0,,0,
1524477389.253,,0.000000e+000,3.499754e+001,-3.121179e-006,0.000000e+000,3,7.904811e-001,0.000000e+000,,,,,,,,,,,,,,32,1,4.000000e+000,2.349854e-003,0.000000e+000,0,,0,
1524477426.659,,0.000000e+000,3.499833e+001,-3.103516e-006,0.000000e+000,3,7.818635e-001,0.000000e+000,,,,,,,,,,,,,,32,1,4.000000e+000,7.781982e-004,0.000000e+000,0,,0,
1524477466.967,,0.000000e+000,3.499911e+001,-5.430320e-008,0.000000e+000,2,0.000000e+000,0.000000e+000,,,,,,,,,,,,,,32,1,4.000000e+000,7.820129e-004,0.000000e+000,0,,0,
1524477504.598,,0.000000e+000,3.499950e+001,3.108207e-006,0.000000e+000,3,7.435035e-001,0.000000e+000,,,,,,,,,,,,,,32,1,4.000000e+000,0.000000e+000,0.000000e+000,0,,0,
1524477544.470,,0.000000e+000,3.499950e+001,-3.269033e-006,0.000000e+000,3,7.804494e-001,0.000000e+000,,,,,,,,,,,,,,32,1,4.000000e+000,3.120422e-003,0.000000e+000,0,,0,
1524477584.469,,0.000000e+000,3.499911e+001,-1.005734e-008,0.000000e+000,2,0.000000e+000,0.000000e+000,,,,,,,,,,,,,,32,1,4.000000e+000,7.820129e-004,0.000000e+000,0,,0,
1524477626.431,,0.000000e+000,3.499833e+001,-6.003337e-008,0.000000e+000,2,0.000000e+000,0.000000e+000,,,,,,,,,,,,,,32,1,4.000000e+000,7.781982e-004,0.000000e+000,0,,0,
1524477666.213,,0.000000e+000,3.499833e+001,-4.914761e-008,0.000000e+000,2,0.000000e+000,0.000000e+000,,,,,,,,,,,,,,32,1,4.000000e+000,2.349854e-003,0.000000e+000,0,,0,
1524477705.219,,0.000000e+000,3.499833e+001,-3.417070e-006,0.000000e+000,3,7.699015e-001,0.000000e+000,,,,,,,,,,,,,,32,1,4.000000e+000,7.781982e-004,0.000000e+000,0,,0,
1524477744.960,,0.000000e+000,3.499911e+001,-7.875089e-008,0.000000e+000,2,0.000000e+000,0.000000e+000,,,,,,,,,,,,,,32,1,4.000000e+000,7.820129e-004,0.000000e+000,0,,0,
1524477785.519,,0.000000e+000,3.499911e+001,-4.716114e-008,0.000000e+000,2,0.000000e+000,0.000000e+000,,,,,,,,,,,,,,32,1,4.000000e+000,7.820129e-004,0.000000e+000,0,,0,
1524477827.003,,0.000000e+000,3.499911e+001,-4.403801e-008,0.000000e+000,2,0.000000e+000,0.000000e+000,,,,,,,,,,,,,,32,1,4.000000e+000,7.820129e-004,0.000000e+000,0,,0,
1524477867.547,,0.000000e+000,3.500028e+001,-3.479880e-006,0.000000e+000,3,7.581111e-001,0.000000e+000,,,,,,,,,,,,,,32,1,4.000000e+000,0.000000e+000,0.000000e+000,0,,0,
1524477910.104,,0.000000e+000,3.499950e+001,-4.468349e-008,0.000000e+000,2,0.000000e+000,0.000000e+000,,,,,,,,,,,,,,32,1,4.000000e+000,1.560211e-003,0.000000e+000,0,,0,
1524477950.713,,0.000000e+000,3.499911e+001,-3.603541e-006,0.000000e+000,3,7.607426e-001,0.000000e+000,,,,,,,,,,,,,,32,1,4.000000e+000,7.820129e-004,0.000000e+000,0,,0,
1524477993.688,,0.000000e+000,3.499950e+001,-4.862080e-008,0.000000e+000,2,0.000000e+000,0.000000e+000,,,,,,,,,,,,,,32,1,4.000000e+000,0.000000e+000,0.000000e+000,0,,0,
1524478034.452,,0.000000e+000,3.499911e+001,-6.035153e-008,0.000000e+000,2,0.000000e+000,0.000000e+000,,,,,,,,,,,,,,32,1,4.000000e+000,7.820129e-004,0.000000e+000,0,,0,
1524478089.912,,0.000000e+000,3.499911e+001,-4.762857e-008,0.000000e+000,2,0.000000e+000,0.000000e+000,,,,,,,,,,,,,,32,1,4.000000e+000,7.820129e-004,0.000000e+000,0,,0,
1524478130.943,,0.000000e+000,3.499950e+001,-3.728653e-006,0.000000e+000,3,7.501948e-001,0.000000e+000,,,,,,,,,,,,,,32,1,4.000000e+000,1.560211e-003,0.000000e+000,0,,0,
1524478173.282,,0.000000e+000,3.499989e+001,-3.785520e-006,0.000000e+000,3,7.558480e-001,0.000000e+000,,,,,,,,,,,,,,32,1,4.000000e+000,7.781982e-004,0.000000e+000,0,,0,
1524478215.727,,0.000000e+000,3.499950e+001,-5.445624e-008,0.000000e+000,2,0.000000e+000,0.000000e+000,,,,,,,,,,,,,,32,1,4.000000e+000,1.560211e-003,0.000000e+000,0,,0,
1524478258.051,,0.000000e+000,3.499833e+001,-6.365971e-008,0.000000e+000,2,0.000000e+000,0.000000e+000,,,,,,,,,,,,,,32,1,4.000000e+000,7.781982e-004,0.000000e+000,0,,0,
1524478301.263,,0.000000e+000,3.499950e+001,-8.575405e-008,0.000000e+000,2,0.000000e+000,0.000000e+000,,,,,,,,,,,,,,32,1,4.000000e+000,0.000000e+000,0.000000e+000,0,,0,
1524478343.132,,0.000000e+000,3.500106e+001,-8.037387e-008,0.000000e+000,2,0.000000e+000,0.000000e+000,,,,,,,,,,,,,,32,1,4.000000e+000,3.128052e-003,0.000000e+000,0,,0,
1524478381.090,,0.000000e+000,3.499989e+001,-3.943934e-006,0.000000e+000,3,7.514994e-001,0.000000e+000,,,,,,,,,,,,,,32,1,4.000000e+000,7.781982e-004,0.000000e+000,0,,0,
1524478422.127,,0.000000e+000,3.499950e+001,-9.612513e-008,0.000000e+000,2,0.000000e+000,0.000000e+000,,,,,,,,,,,,,,32,1,4.000000e+000,3.120422e-003,0.000000e+000,0,,0,
1524478464.281,,0.000000e+000,3.499950e+001,-7.008356e-008,0.000000e+000,2,0.000000e+000,0.000000e+000,,,,,,,,,,,,,,32,1,4.000000e+000,1.560211e-003,0.000000e+000,0,,0,
1524478504.820,,0.000000e+000,3.500028e+001,-3.935450e-006,0.000000e+000,3,7.338519e-001,0.000000e+000,,,,,,,,,,,,,,32,1,4.000000e+000,3.120422e-003,0.000000e+000,0,,0,
1524478546.852,,0.000000e+000,3.499911e+001,-7.063660e-008,0.000000e+000,2,0.000000e+000,0.000000e+000,,,,,,,,,,,,,,32,1,4.000000e+000,2.338409e-003,0.000000e+000,0,,0,
1524478589.428,,0.000000e+000,3.499989e+001,-9.204129e-008,0.000000e+000,2,0.000000e+000,0.000000e+000,,,,,,,,,,,,,,32,1,4.000000e+000,7.781982e-004,0.000000e+000,0,,0,
1524478631.530,,0.000000e+000,3.499872e+001,-1.048691e-007,0.000000e+000,2,0.000000e+000,0.000000e+000,,,,,,,,,,,,,,32,1,4.000000e+000,1.560211e-003,0.000000e+000,0,,0,
1524478674.069,,0.000000e+000,3.499950e+001,-6.886610e-008,0.000000e+000,2,0.000000e+000,0.000000e+000,,,,,,,,,,,,,,32,1,4.000000e+000,0.000000e+000,0.000000e+000,0,,0,
1524478716.206,,0.000000e+000,3.500028e+001,-9.032352e-008,0.000000e+000,2,0.000000e+000,0.000000e+000,,,,,,,,,,,,,,32,1,4.000000e+000,0.000000e+000,0.000000e+000,0,,0,
1524478756.862,,0.000000e+000,3.499989e+001,-9.779674e-008,0.000000e+000,2,0.000000e+000,0.000000e+000,,,,,,,,,,,,,,32,1,4.000000e+000,7.781982e-004,0.000000e+000,0,,0,
1524478796.036,,0.000000e+000,3.499872e+001,-6.917104e-008,0.000000e+000,2,0.000000e+000,0.000000e+000,,,,,,,,,,,,,,32,1,4.000000e+000,0.000000e+000,0.000000e+000,0,,0,
1524478836.417,,0.000000e+000,3.499794e+001,-4.126660e-006,0.000000e+000,3,7.247411e-001,0.000000e+000,,,,,,,,,,,,,,32,1,4.000000e+000,0.000000e+000,0.000000e+000,0,,0,
1524478877.616,,0.000000e+000,3.499950e+001,-4.082242e-006,0.000000e+000,3,7.126965e-001,0.000000e+000,,,,,,,,,,,,,,32,1,4.000000e+000,1.560211e-003,0.000000e+000,0,,0,
1524478920.381,,0.000000e+000,3.499793e+001,-6.732817e-008,0.000000e+000,2,0.000000e+000,0.000000e+000,,,,,,,,,,,,,,32,1,4.000000e+000,1.567841e-003,0.000000e+000,0,,0,
1524478963.328,,0.000000e+000,3.500028e+001,-7.226227e-008,0.000000e+000,2,0.000000e+000,0.000000e+000,,,,,,,,,,,,,,32,1,4.000000e+000,1.560211e-003,0.000000e+000,0,,0,
1524479003.267,,0.000000e+000,3.499950e+001,-1.080879e-007,0.000000e+000,2,0.000000e+000,0.000000e+000,,,,,,,,,,,,,,32,1,4.000000e+000,0.000000e+000,0.000000e+000,0,,0,
1524479045.525,,0.000000e+000,3.500028e+001,-5.476264e-008,0.000000e+000,2,0.000000e+000,0.000000e+000,,,,,,,,,,,,,,32,1,4.000000e+000,0.000000e+000,0.000000e+000,0,,0,
1524479100.435,,0.000000e+000,3.499950e+001,4.534755e-006,0.000000e+000,3,8.172425e-001,0.000000e+000,,,,,,,,,,,,,,32,1,4.000000e+000,1.560211e-003,0.000000e+000,0,,0,
1524479143.072,,0.000000e+000,3.499911e+001,-6.385368e-008,0.000000e+000,2,0.000000e+000,0.000000e+000,,,,,,,,,,,,,,32,1,4.000000e+000,7.820129e-004,0.000000e+000,0,,0,
1524479182.366,,0.000000e+000,3.499833e+001,-4.318441e-006,0.000000e+000,3,7.221409e-001,0.000000e+000,,,,,,,,,,,,,,32,1,4.000000e+000,7.781982e-004,0.000000e+000,0,,0,
1524479221.217,,0.000000e+000,3.499872e+001,4.626026e-006,0.000000e+000,3,8.136029e-001,0.000000e+000,,,,,,,,,,,,,,32,1,4.000000e+000,1.560211e-003,0.000000e+000,0,,0,
1524479263.912,,0.000000e+000,3.499872e+001,-1.322657e-007,0.000000e+000,2,0.000000e+000,0.000000e+000,,,,,,,,,,,,,,32,1,4.000000e+000,1.560211e-003,0.000000e+000,0,,0,
1524479304.598,,0.000000e+000,3.499989e+001,-6.593947e-008,0.000000e+000,2,0.000000e+000,0.000000e+000,,,,,,,,,,,,,,32,1,4.000000e+000,2.342224e-003,0.000000e+000,0,,0,
1524479346.905,,0.000000e+000,3.499833e+001,-9.749770e-008,0.000000e+000,2,0.000000e+000,0.000000e+000,,,,,,,,,,,,,,32,1,4.000000e+000,7.781982e-004,0.000000e+000,0,,0,
1524479389.600,,0.000000e+000,3.499950e+001,-9.981112e-008,0.000000e+000,2,0.000000e+000,0.000000e+000,,,,,,,,,,,,,,32,1,4.000000e+000,1.560211e-003,0.000000e+000,0,,0,
1524479433.155,,0.000000e+000,3.499989e+001,-1.188854e-007,0.000000e+000,2,0.000000e+000,0.000000e+000,,,,,,,,,,,,,,32,1,4.000000e+000,7.781982e-004,0.000000e+000,0,,0,
1524479474.229,,0.000000e+000,3.499794e+001,-1.375849e-007,0.000000e+000,2,0.000000e+000,0.000000e+000,,,,,,,,,,,,,,32,1,4.000000e+000,0.000000e+000,0.000000e+000,0,,0,
1524479517.302,,0.000000e+000,3.499833e+001,-1.307600e-007,0.000000e+000,2,0.000000e+000,0.000000e+000,,,,,,,,,,,,,,32,1,4.000000e+000,7.781982e-004,0.000000e+000,0,,0,
1524479561.014,,0.000000e+000,3.500028e+001,-9.914321e-008,0.000000e+000,2,0.000000e+000,0.000000e+000,,,,,,,,,,,,,,32,1,4.000000e+000,3.120422e-003,0.000000e+000,0,,0,
1524479601.943,,0.000000e+000,3.499911e+001,4.881549e-006,0.000000e+000,3,8.261989e-001,0.000000e+000,,,,,,,,,,,,,,32,1,4.000000e+000,7.820129e-004,0.000000e+000,0,,0,
1524479644.148,,0.000000e+000,3.499754e+001,-1.212337e-007,0.000000e+000,2,0.000000e+000,0.000000e+000,,,,,,,,,,,,,,32,1,4.000000e+000,7.896423e-004,0.000000e+000,0,,0,
1524479684.909,,0.000000e+000,3.499872e+001,-7.922531e-008,0.000000e+000,2,0.000000e+000,0.000000e+000,,,,,,,,,,,,,,32,1,4.000000e+000,1.560211e-003,0.000000e+000,0,,0,
1524479725.363,,0.000000e+000,3.500028e+001,-7.435926e-008,0.000000e+000,2,0.000000e+000,0.000000e+000,,,,,,,,,,,,,,32,1,4.000000e+000,0.000000e+000,0.000000e+000,0,,0,
1524479765.565,,0.000000e+000,3.499989e+001,4.981704e-006,0.000000e+000,3,8.223482e-001,0.000000e+000,,,,,,,,,,,,,,32,1,4.000000e+000,7.781982e-004,0.000000e+000,0,,0,
1524479806.829,,0.000000e+000,3.499911e+001,-1.296610e-007,0.000000e+000,2,0.000000e+000,0.000000e+000,,,,,,,,,,,,,,32,1,4.000000e+000,7.820129e-004,0.000000e+000,0,,0,
1524479847.376,,0.000000e+000,3.500067e+001,4.967997e-006,0.000000e+000,3,8.292679e-001,0.000000e+000,,,,,,,,,,,,,,32,1,4.000000e+000,3.910065e-003,0.000000e+000,0,,0,
1524479886.804,,0.000000e+000,3.499833e+001,-9.914270e-008,0.000000e+000,2,0.000000e+000,0.000000e+000,,,,,,,,,,,,,,32,1,4.000000e+000,7.781982e-004,0.000000e+000,0,,0,
1524479929.614,,0.000000e+000,3.500028e+001,-1.263072e-007,0.000000e+000,2,0.000000e+000,0.000000e+000,,,,,,,,,,,,,,32,1,4.000000e+000,4.688263e-003,0.000000e+000,0,,0,
1524479972.798,,0.000000e+000,3.500028e+001,-1.130053e-007,0.000000e+000,2,0.000000e+000,0.000000e+000,,,,,,,,,,,,,,32,1,4.000000e+000,3.120422e-003,0.000000e+000,0,,0,
1524480013.808,,0.000000e+000,3.499793e+001,-1.219959e-007,0.000000e+000,2,0.000000e+000,0.000000e+000,,,,,,,,,,,,,,32,1,4.000000e+000,1.567841e-003,0.000000e+000,0,,0,
1524480054.494,,0.000000e+000,3.500106e+001,-1.070006e-007,0.000000e+000,2,0.000000e+000,0.000000e+000,,,,,,,,,,,,,,32,1,4.000000e+000,4.692078e-003,0.000000e+000,0,,0,
1524480111.184,,0.000000e+000,3.499872e+001,-1.437602e-007,0.000000e+000,2,0.000000e+000,0.000000e+000,,,,,,,,,,,,,,32,1,4.000000e+000,0.000000e+000,0.000000e+000,0,,0,
1524480151.590,,0.000000e+000,3.500185e+001,5.126253e-006,0.000000e+000,3,8.286242e-001,0.000000e+000,,,,,,,,,,,,,,32,1,4.000000e+000,4.688263e-003,0.000000e+000,0,,0,
1524480190.954,,0.000000e+000,3.499911e+001,5.134956e-006,0.000000e+000,3,8.378201e-001,0.000000e+000,,,,,,,,,,,,,,32,1,4.000000e+000,7.820129e-004,0.000000e+000,0,,0,
1524480232.652,,0.000000e+000,3.499872e+001,-6.675007e-008,0.000000e+000,2,0.000000e+000,0.000000e+000,,,,,,,,,,,,,,32,1,4.000000e+000,0.000000e+000,0.000000e+000,0,,0,
1524480275.371,,0.000000e+000,3.499911e+001,-1.398868e-007,0.000000e+000,2,0.000000e+000,0.000000e+000,,,,,,,,,,,,,,32,1,4.000000e+000,7.820129e-004,0.000000e+000,0,,0,
1524480315.950,,0.000000e+000,3.500106e+001,-1.184200e-007,0.000000e+000,2,0.000000e+000,0.000000e+000,,,,,,,,,,,,,,32,1,4.000000e+000,1.560211e-003,0.000000e+000,0,,0,
1524480356.887,,0.000000e+000,3.499989e+001,5.249293e-006,0.000000e+000,3,8.417545e-001,0.000000e+000,,,,,,,,,,,,,,32,1,4.000000e+000,3.898621e-003,0.000000e+000,0,,0,
1524480400.582,,0.000000e+000,3.499989e+001,-9.530683e-008,0.000000e+000,2,0.000000e+000,0.000000e+000,,,,,,,,,,,,,,32,1,4.000000e+000,7.781982e-004,0.000000e+000,0,,0,
1524480441.653,,0.000000e+000,3.499950e+001,-1.385603e-007,0.000000e+000,2,0.000000e+000,0.000000e+000,,,,,,,,,,,,,,32,1,4.000000e+000,1.560211e-003,0.000000e+000,0,,0,
1524480482.045,,0.000000e+000,3.499911e+001,5.337831e-006,0.000000e+000,3,8.341951e-001,0.000000e+000,,,,,,,,,,,,,,32,1,4.000000e+000,7.820129e-004,0.000000e+000,0,,0,
1524480524.807,,0.000000e+000,3.499989e+001,-1.228542e-007,0.000000e+000,2,0.000000e+000,0.000000e+000,,,,,,,,,,,,,,32,1,4.000000e+000,3.898621e-003,0.000000e+000,0,,0,
1524480566.846,,0.000000e+000,3.499872e+001,-1.117259e-007,0.000000e+000,2,0.000000e+000,0.000000e+000,,,,,,,,,,,,,,32,1,4.000000e+000,1.560211e-003,0.000000e+000,0,,0,
1524480607.905,,0.000000e+000,3.500028e+001,-1.145399e-007,0.000000e+000,2,0.000000e+000,0.000000e+000,,,,,,,,,,,,,,32,1,4.000000e+000,1.560211e-003,0.000000e+000,0,,0,
1524480648.672,,0.000000e+000,3.500028e+001,-1.152598e-007,0.000000e+000,2,0.000000e+000,0.000000e+000,,,,,,,,,,,,,,32,1,4.000000e+000,3.120422e-003,0.000000e+000,0,,0,
1524480688.093,,0.000000e+000,3.499911e+001,5.337610e-006,0.000000e+000,3,8.278303e-001,0.000000e+000,,,,,,,,,,,,,,32,1,4.000000e+000,7.820129e-004,0.000000e+000,0,,0,
1524480729.047,,0.000000e+000,3.499833e+001,-8.036596e-008,0.000000e+000,2,0.000000e+000,0.000000e+000,,,,,,,,,,,,,,32,1,4.000000e+000,7.781982e-004,0.000000e+000,0,,0,
1524480771.486,,0.000000e+000,3.500067e+001,-1.230215e-007,0.000000e+000,2,0.000000e+000,0.000000e+000,,,,,,,,,,,,,,32,1,4.000000e+000,7.820129e-004,0.000000e+000,0,,0,
1524480812.522,,0.000000e+000,3.500028e+001,5.499189e-006,0.000000e+000,3,8.411133e-001,0.000000e+000,,,,,,,,,,,,,,32,1,4.000000e+000,1.560211e-003,0.000000e+000,0,,0,
1524480853.416,,0.000000e+000,3.500106e+001,5.541401e-006,0.000000e+000,3,8.474408e-001,0.000000e+000,,,,,,,,,,,,,,32,1,4.000000e+000,1.560211e-003,0.000000e+000,0,,0,
1524480895.052,,0.000000e+000,3.499989e+001,5.395397e-006,0.000000e+000,3,8.342735e-001,0.000000e+000,,,,,,,,,,,,,,32,1,4.000000e+000,7.781982e-004,0.000000e+000,0,,0,
1524480935.860,,0.000000e+000,3.499989e+001,5.440046e-006,0.000000e+000,3,8.421735e-001,0.000000e+000,,,,,,,,,,,,,,32,1,4.000000e+000,2.342224e-003,0.000000e+000,0,,0,
1524480979.562,,0.000000e+000,3.499950e+001,-1.057786e-007,0.000000e+000,2,0.000000e+000,0.000000e+000,,,,,,,,,,,,,,32,1,4.000000e+000,0.000000e+000,0.000000e+000,0,,0,
1524481021.699,,0.000000e+000,3.499872e+001,-1.112908e-007,0.000000e+000,2,0.000000e+000,0.000000e+000,,,,,,,,,,,,,,32,1,4.000000e+000,0.000000e+000,0.000000e+000,0,,0,
1524481064.039,,0.000000e+000,3.499872e+001,-1.185639e-007,0.000000e+000,2,0.000000e+000,0.000000e+000,,,,,,,,,,,,,,32,1,4.000000e+000,0.000000e+000,0.000000e+000,0,,0,
1524481120.056,,0.000000e+000,3.500106e+001,-1.243969e-007,0.000000e+000,2,0.000000e+000,0.000000e+000,,,,,,,,,,,,,,32,1,4.000000e+000,4.692078e-003,0.000000e+000,0,,0,
1524481161.180,,0.000000e+000,3.499754e+001,-1.135894e-007,0.000000e+000,2,0.000000e+000,0.000000e+000,,,,,,,,,,,,,,32,1,4.000000e+000,7.896423e-004,0.000000e+000,0,,0,
1524481202.491,,0.000000e+000,3.499833e+001,-1.322312e-007,0.000000e+000,2,0.000000e+000,0.000000e+000,,,,,,,,,,,,,,32,1,4.000000e+000,7.781982e-004,0.000000e+000,0,,0,
1524481244.811,,0.000000e+000,3.500028e+001,-1.114950e-007,0.000000e+000,2,0.000000e+000,0.000000e+000,,,,,,,,,,,,,,32,1,4.000000e+000,4.688263e-003,0.000000e+000,0,,0,
1524481288.496,,0.000000e+000,3.499833e+001,-1.172991e-007,0.000000e+000,2,0.000000e+000,0.000000e+000,,,,,,,,,,,,,,32,1,4.000000e+000,7.781982e-004,0.000000e+000,0,,0,
1524481330.830,,0.000000e+000,3.499833e+001,-1.231032e-007,0.000000e+000,2,0.000000e+000,0.000000e+000,,,,,,,,,,,,,,32,1,4.000000e+000,2.349854e-003,0.000000e+000,0,,0,
1524481373.275,,0.000000e+000,3.499950e+001,-1.532473e-007,0.000000e+000,2,0.000000e+000,0.000000e+000,,,,,,,,,,,,,,32,1,4.000000e+000,0.000000e+000,0.000000e+000,0,,0,
1524481415.122,,0.000000e+000,3.499989e+001,-1.221394e-007,0.000000e+000,2,0.000000e+000,0.000000e+000,,,,,,,,,,,,,,32,1,4.000000e+000,7.781982e-004,0.000000e+000,0,,0,
1524481458.364,,0.000000e+000,3.500028e+001,-1.449194e-007,0.000000e+000,2,0.000000e+000,0.000000e+000,,,,,,,,,,,,,,32,1,4.000000e+000,1.560211e-003,0.000000e+000,0,,0,
1524481497.745,,0.000000e+000,3.499989e+001,5.686139e-006,0.000000e+000,3,8.410753e-001,0.000000e+000,,,,,,,,,,,,,,32,1,4.000000e+000,7.781982e-004,0.000000e+000,0,,0,
1524481540.102,,0.000000e+000,3.500106e+001,5.689257e-006,0.000000e+000,3,8.444161e-001,0.000000e+000,,,,,,,,,,,,,,32,1,4.000000e+000,3.128052e-003,0.000000e+000,0,,0,
1524481582.426,,0.000000e+000,3.500028e+001,5.806767e-006,0.000000e+000,3,8.506705e-001,0.000000e+000,,,,,,,,,,,,,,32,1,4.000000e+000,1.560211e-003,0.000000e+000,0,,0,
1524481624.770,,0.000000e+000,3.499989e+001,5.656659e-006,0.000000e+000,3,8.427532e-001,0.000000e+000,,,,,,,,,,,,,,32,1,4.000000e+000,2.342224e-003,0.000000e+000,0,,0,
1524481669.104,,0.000000e+000,3.499989e+001,-1.109563e-007,0.000000e+000,2,0.000000e+000,0.000000e+000,,,,,,,,,,,,,,32,1,4.000000e+000,3.898621e-003,0.000000e+000,0,,0,
1524481711.679,,0.000000e+000,3.500028e+001,-1.683676e-007,0.000000e+000,2,0.000000e+000,0.000000e+000,,,,,,,,,,,,,,32,1,4.000000e+000,1.560211e-003,0.000000e+000,0,,0,
1524481753.796,,0.000000e+000,3.500067e+001,-1.241115e-007,0.000000e+000,2,0.000000e+000,0.000000e+000,,,,,,,,,,,,,,32,1,4.000000e+000,2.338409e-003,0.000000e+000,0,,0,
1524481796.337,,0.000000e+000,3.499989e+001,-9.515519e-008,0.000000e+000,2,0.000000e+000,0.000000e+000,,,,,,,,,,,,,,32,1,4.000000e+000,2.342224e-003,0.000000e+000,0,,0,
1524481839.317,,0.000000e+000,3.499989e+001,-1.503810e-007,0.000000e+000,2,0.000000e+000,0.000000e+000,,,,,,,,,,,,,,32,1,4.000000e+000,7.781982e-004,0.000000e+000,0,,0,
1524481882.934,,0.000000e+000,3.500028e+001,-1.074363e-007,0.000000e+000,2,0.000000e+000,0.000000e+000,,,,,,,,,,,,,,32,1,4.000000e+000,3.120422e-003,0.000000e+000,0,,0,
1524481925.494,,0.000000e+000,3.500106e+001,-1.290471e-007,0.000000e+000,2,0.000000e+000,0.000000e+000,,,,,,,,,,,,,,32,1,4.000000e+000,0.000000e+000,0.000000e+000,0,,0,
1524481969.701,,0.000000e+000,3.500028e+001,-1.459754e-007,0.000000e+000,2,0.000000e+000,0.000000e+000,,,,,,,,,,,,,,32,1,4.000000e+000,3.120422e-003,0.000000e+000,0,,0,
1524482010.540,,0.000000e+000,3.500028e+001,-1.451962e-007,0.000000e+000,2,0.000000e+000,0.000000e+000,,,,,,,,,,,,,,32,1,4.000000e+000,3.120422e-003,0.000000e+000,0,,0,
1524482051.234,,0.000000e+000,3.499910e+001,5.974351e-006,0.000000e+000,3,8.533180e-001,0.000000e+000,,,,,,,,,,,,,,32,1,4.000000e+000,5.470276e-003,0.000000e+000,0,,0,
1524482094.081,,0.000000e+000,3.499911e+001,-1.182937e-007,0.000000e+000,2,0.000000e+000,0.000000e+000,,,,,,,,,,,,,,32,1,4.000000e+000,7.820129e-004,0.000000e+000,0,,0,
1524482151.788,,0.000000e+000,3.499872e+001,-1.593314e-007,0.000000e+000,2,0.000000e+000,0.000000e+000,,,,,,,,,,,,,,32,1,4.000000e+000,1.560211e-003,0.000000e+000,0,,0,
1524482193.420,,0.000000e+000,3.499989e+001,-1.423171e-007,0.000000e+000,2,0.000000e+000,0.000000e+000,,,,,,,,,,,,,,32,1,4.000000e+000,7.781982e-004,0.000000e+000,0,,0,
1524482235.931,,0.000000e+000,3.499911e+001,-1.247800e-007,0.000000e+000,2,0.000000e+000,0.000000e+000,,,,,,,,,,,,,,32,1,4.000000e+000,7.820129e-004,0.000000e+000,0,,0,
1524482276.120,,0.000000e+000,3.499833e+001,-1.143277e-007,0.000000e+000,2,0.000000e+000,0.000000e+000,,,,,,,,,,,,,,32,1,4.000000e+000,7.781982e-004,0.000000e+000,0,,0,
1524482320.157,,0.000000e+000,3.499872e+001,-1.188965e-007,0.000000e+000,2,0.000000e+000,0.000000e+000,,,,,,,,,,,,,,32,1,4.000000e+000,1.560211e-003,0.000000e+000,0,,0,
1524482362.937,,0.000000e+000,3.500028e+001,-1.586863e-007,0.000000e+000,2,0.000000e+000,0.000000e+000,,,,,,,,,,,,,,32,1,4.000000e+000,1.560211e-003,0.000000e+000,0,,0,
1524482405.632,,0.000000e+000,3.500028e+001,-1.549024e-007,0.000000e+000,2,0.000000e+000,0.000000e+000,,,,,,,,,,,,,,32,1,4.000000e+000,3.120422e-003,0.000000e+000,0,,0,
1524482447.456,,0.000000e+000,3.500106e+001,-1.321699e-007,0.000000e+000,2,0.000000e+000,0.000000e+000,,,,,,,,,,,,,,32,1,4.000000e+000,1.560211e-003,0.000000e+000,0,,0,
1524482489.843,,0.000000e+000,3.500028e+001,-1.010030e-007,0.000000e+000,2,0.000000e+000,0.000000e+000,,,,,,,,,,,,,,32,1,4.000000e+000,1.560211e-003,0.000000e+000,0,,0,
1524482532.646,,0.000000e+000,3.500028e+001,-1.281535e-007,0.000000e+000,2,0.000000e+000,0.000000e+000,,,,,,,,,,,,,,32,1,4.000000e+000,1.560211e-003,0.000000e+000,0,,0,
1524482574.483,,0.000000e+000,3.499872e+001,-1.386412e-007,0.000000e+000,2,0.000000e+000,0.000000e+000,,,,,,,,,,,,,,32,1,4.000000e+000,0.000000e+000,0.000000e+000,0,,0,
1524482616.857,,0.000000e+000,3.499989e+001,-1.331999e-007,0.000000e+000,2,0.000000e+000,0.000000e+000,,,,,,,,,,,,,,32,1,4.000000e+000,7.781982e-004,0.000000e+000,0,,0,
1524482659.292,,0.000000e+000,3.499715e+001,-1.602073e-007,0.000000e+000,2,0.000000e+000,0.000000e+000,,,,,,,,,,,,,,32,1,4.000000e+000,4.692078e-003,0.000000e+000,0,,0,
1524482702.737,,0.000000e+000,3.500028e+001,-9.851846e-008,0.000000e+000,2,0.000000e+000,0.000000e+000,,,,,,,,,,,,,,32,1,4.000000e+000,1.560211e-003,0.000000e+000,0,,0,
1524482745.289,,0.000000e+000,3.500028e+001,-1.067230e-007,0.000000e+000,2,0.000000e+000,0.000000e+000,,,,,,,,,,,,,,32,1,4.000000e+000,3.120422e-003,0.000000e+000,0,,0,
1524482789.533,,0.000000e+000,3.500146e+001,-1.647543e-007,0.000000e+000,2,0.000000e+000,0.000000e+000,,,,,,,,,,,,,,32,1,4.000000e+000,3.910065e-003,0.000000e+000,0,,0,
1524482832.731,,0.000000e+000,3.500028e+001,-1.391390e-007,0.000000e+000,2,0.000000e+000,0.000000e+000,,,,,,,,,,,,,,32,1,4.000000e+000,3.120422e-003,0.000000e+000,0,,0,
1524482874.215,,0.000000e+000,3.499911e+001,-1.442096e-007,0.000000e+000,2,0.000000e+000,0.000000e+000,,,,,,,,,,,,,,32,1,4.000000e+000,7.820129e-004,0.000000e+000,0,,0,
1524482915.439,,0.000000e+000,3.500028e+001,-1.308529e-007,0.000000e+000,2,0.000000e+000,0.000000e+000,,,,,,,,,,,,,,32,1,4.000000e+000,3.120422e-003,0.000000e+000,0,,0,
1524482958.573,,0.000000e+000,3.499911e+001,-1.367691e-007,0.000000e+000,2,0.000000e+000,0.000000e+000,,,,,,,,,,,,,,32,1,4.000000e+000,7.820129e-004,0.000000e+000,0,,0,
1524483000.918,,0.000000e+000,3.500224e+001,-1.120328e-007,0.000000e+000,2,0.000000e+000,0.000000e+000,,,,,,,,,,,,,,32,1,4.000000e+000,7.896423e-004,0.000000e+000,0,,0,
1524483044.673,,0.000000e+000,3.500028e+001,-1.819857e-007,0.000000e+000,2,0.000000e+000,0.000000e+000,,,,,,,,,,,,,,32,1,4.000000e+000,3.120422e-003,0.000000e+000,0,,0,
1524483087.009,,0.000000e+000,3.499950e+001,-9.685652e-008,0.000000e+000,2,0.000000e+000,0.000000e+000,,,,,,,,,,,,,,32,1,4.000000e+000,0.000000e+000,0.000000e+000,0,,0,
1524483128.728,,0.000000e+000,3.500028e+001,-1.583520e-007,0.000000e+000,2,0.000000e+000,0.000000e+000,,,,,,,,,,,,,,32,1,4.000000e+000,3.120422e-003,0.000000e+000,0,,0,
1524483186.526,,0.000000e+000,3.499989e+001,-9.765026e-008,0.000000e+000,2,0.000000e+000,0.000000e+000,,,,,,,,,,,,,,32,1,4.000000e+000,3.898621e-003,0.000000e+000,0,,0,
1524483229.941,,0.000000e+000,3.499989e+001,-1.369081e-007,0.000000e+000,2,0.000000e+000,0.000000e+000,,,,,,,,,,,,,,32,1,4.000000e+000,2.342224e-003,0.000000e+000,0,,0,
1524483273.093,,0.000000e+000,3.499872e+001,-1.460620e-007,0.000000e+000,2,0.000000e+000,0.000000e+000,,,,,,,,,,,,,,32,1,4.000000e+000,1.560211e-003,0.000000e+000,0,,0,
1524483317.535,,0.000000e+000,3.499833e+001,-1.366842e-007,0.000000e+000,2,0.000000e+000,0.000000e+000,,,,,,,,,,,,,,32,1,4.000000e+000,7.781982e-004,0.000000e+000,0,,0,
1524483361.405,,0.000000e+000,3.499989e+001,-1.445380e-007,0.000000e+000,2,0.000000e+000,0.000000e+000,,,,,,,,,,,,,,32,1,4.000000e+000,2.342224e-003,0.000000e+000,0,,0,
1524483404.549,,0.000000e+000,3.499911e+001,-1.162259e-007,0.000000e+000,2,0.000000e+000,0.000000e+000,,,,,,,,,,,,,,32,1,4.000000e+000,7.820129e-004,0.000000e+000,0,,0,
1524483448.204,,0.000000e+000,3.500067e+001,-1.446964e-007,0.000000e+000,2,0.000000e+000,0.000000e+000,,,,,,,,,,,,,,32,1,4.000000e+000,7.820129e-004,0.000000e+000,0,,0,
1524483491.271,,0.000000e+000,3.499911e+001,-1.688686e-007,0.000000e+000,2,0.000000e+000,0.000000e+000,,,,,,,,,,,,,,32,1,4.000000e+000,7.820129e-004,0.000000e+000,0,,0,
1524483534.146,,0.000000e+000,3.499989e+001,-1.445290e-007,0.000000e+000,2,0.000000e+000,0.000000e+000,,,,,,,,,,,,,,32,1,4.000000e+000,3.898621e-003,0.000000e+000,0,,0,
1524483576.340,,0.000000e+000,3.499989e+001,-1.270733e-007,0.000000e+000,2,0.000000e+000,0.000000e+000,,,,,,,,,,,,,,32,1,4.000000e+000,2.342224e-003,0.000000e+000,0,,0,
1524483618.320,,0.000000e+000,3.499872e+001,-1.130753e-007,0.000000e+000,2,0.000000e+000,0.000000e+000,,,,,,,,,,,,,,32,1,4.000000e+000,0.000000e+000,0.000000e+000,0,,0,
1524483659.519,,0.000000e+000,3.499989e+001,-1.357987e-007,0.000000e+000,2,0.000000e+000,0.000000e+000,,,,,,,,,,,,,,32,1,4.000000e+000,2.342224e-003,0.000000e+000,0,,0,
1524483702.421,,0.000000e+000,3.499872e+001,-1.466767e-007,0.000000e+000,2,0.000000e+000,0.000000e+000,,,,,,,,,,,,,,32,1,4.000000e+000,0.000000e+000,0.000000e+000,0,,0,
1524483744.758,,0.000000e+000,3.499950e+001,-1.652265e-007,0.000000e+000,2,0.000000e+000,0.000000e+000,,,,,,,,,,,,,,32,1,4.000000e+000,0.000000e+000,0.000000e+000,0,,0,
1524483787.344,,0.000000e+000,3.500028e+001,-1.327155e-007,0.000000e+000,2,0.000000e+000,0.000000e+000,,,,,,,,,,,,,,32,1,4.000000e+000,3.120422e-003,0.000000e+000,0,,0,
1524483829.809,,0.000000e+000,3.500067e+001,-1.246812e-007,0.000000e+000,2,0.000000e+000,0.000000e+000,,,,,,,,,,,,,,32,1,4.000000e+000,7.820129e-004,0.000000e+000,0,,0,
1524483873.941,,0.000000e+000,3.500106e+001,-1.203577e-007,0.000000e+000,2,0.000000e+000,0.000000e+000,,,,,,,,,,,,,,32,1,4.000000e+000,1.560211e-003,0.000000e+000,0,,0,
1524483917.203,,0.000000e+000,3.499989e+001,-1.466603e-007,0.000000e+000,2,0.000000e+000,0.000000e+000,,,,,,,,,,,,,,32,1,4.000000e+000,3.898621e-003,0.000000e+000,0,,0,
1524483960.708,,0.000000e+000,3.499989e+001,-1.659813e-007,0.000000e+000,2,0.000000e+000,0.000000e+000,,,,,,,,,,,,,,32,1,4.000000e+000,7.781982e-004,0.000000e+000,0,,0,
1524484000.493,,0.000000e+000,3.499872e+001,-1.611778e-007,0.000000e+000,2,0.000000e+000,0.000000e+000,,,,,,,,,,,,,,32,1,4.000000e+000,0.000000e+000,0.000000e+000,0,,0,
1524484042.127,,0.000000e+000,3.499989e+001,-1.679052e-007,0.000000e+000,2,0.000000e+000,0.000000e+000,,,,,,,,,,,,,,32,1,4.000000e+000,2.342224e-003,0.000000e+000,0,,0,
1524484083.704,,0.000000e+000,3.499950e+001,-1.231038e-007,0.000000e+000,2,0.000000e+000,0.000000e+000,,,,,,,,,,,,,,32,1,4.000000e+000,1.560211e-003,0.000000e+000,0,,0,
1524484126.757,,0.000000e+000,3.499989e+001,-1.353423e-007,0.000000e+000,2,0.000000e+000,0.000000e+000,,,,,,,,,,,,,,32,1,4.000000e+000,2.342224e-003,0.000000e+000,0,,0,
1524484169.016,,0.000000e+000,3.500028e+001,-1.303304e-007,0.000000e+000,2,0.000000e+000,0.000000e+000,,,,,,,,,,,,,,32,1,4.000000e+000,1.560211e-003,0.000000e+000,0,,0,
1524484226.224,,0.000000e+000,3.500028e+001,-1.407490e-007,0.000000e+000,2,0.000000e+000,0.000000e+000,,,,,,,,,,,,,,32,1,4.000000e+000,3.120422e-003,0.000000e+000,0,,0,
1524484269.254,,0.000000e+000,3.500067e+001,-1.321016e-007,0.000000e+000,2,0.000000e+000,0.000000e+000,,,,,,,,,,,,,,32,1,4.000000e+000,2.338409e-003,0.000000e+000,0,,0,
1524484311.620,,0.000000e+000,3.499911e+001,-1.485813e-007,0.000000e+000,2,0.000000e+000,0.000000e+000,,,,,,,,,,,,,,32,1,4.000000e+000,7.820129e-004,0.000000e+000,0,,0,
1524484353.927,,0.000000e+000,3.499911e+001,-1.485474e-007,0.000000e+000,2,0.000000e+000,0.000000e+000,,,,,,,,,,,,,,32,1,4.000000e+000,7.820129e-004,0.000000e+000,0,,0,
1524484396.294,,0.000000e+000,3.500028e+001,-1.700469e-007,0.000000e+000,2,0.000000e+000,0.000000e+000,,,,,,,,,,,,,,32,1,4.000000e+000,3.120422e-003,0.000000e+000,0,,0,
1524484438.842,,0.000000e+000,3.500028e+001,-1.432139e-007,0.000000e+000,2,0.000000e+000,0.000000e+000,,,,,,,,,,,,,,32,1,4.000000e+000,3.120422e-003,0.000000e+000,0,,0,
1524484481.804,,0.000000e+000,3.499989e+001,-1.397639e-007,0.000000e+000,2,0.000000e+000,0.000000e+000,,,,,,,,,,,,,,32,1,4.000000e+000,2.342224e-003,0.000000e+000,0,,0,
1524484524.106,,0.000000e+000,3.499989e+001,-1.340520e-007,0.000000e+000,2,0.000000e+000,0.000000e+000,,,,,,,,,,,,,,32,1,4.000000e+000,3.898621e-003,0.000000e+000,0,,0,
1524484566.450,,0.000000e+000,3.500067e+001,-1.606244e-007,0.000000e+000,2,0.000000e+000,0.000000e+000,,,,,,,,,,,,,,32,1,4.000000e+000,2.338409e-003,0.000000e+000,0,,0,
1524484608.783,,0.000000e+000,3.499989e+001,-1.852339e-007,0.000000e+000,2,0.000000e+000,0.000000e+000,,,,,,,,,,,,,,32,1,4.000000e+000,7.781982e-004,0.000000e+000,0,,0,
1524484651.767,,0.000000e+000,3.500067e+001,-1.707770e-007,0.000000e+000,2,0.000000e+000,0.000000e+000,,,,,,,,,,,,,,32,1,4.000000e+000,7.820129e-004,0.000000e+000,0,,0,
1524484694.214,,0.000000e+000,3.499989e+001,-1.466734e-007,0.000000e+000,2,0.000000e+000,0.000000e+000,,,,,,,,,,,,,,32,1,4.000000e+000,3.898621e-003,0.000000e+000,0,,0,
1524484736.802,,0.000000e+000,3.500028e+001,-9.209980e-008,0.000000e+000,2,0.000000e+000,0.000000e+000,,,,,,,,,,,,,,32,1,4.000000e+000,3.120422e-003,0.000000e+000,0,,0,
1524484780.306,,0.000000e+000,3.499989e+001,-1.216689e-007,0.000000e+000,2,0.000000e+000,0.000000e+000,,,,,,,,,,,,,,32,1,4.000000e+000,7.781982e-004,0.000000e+000,0,,0,
1524484823.073,,0.000000e+000,3.500067e+001,-1.471111e-007,0.000000e+000,2,0.000000e+000,0.000000e+000,,,,,,,,,,,,,,32,1,4.000000e+000,2.338409e-003,0.000000e+000,0,,0,
1524484865.455,,0.000000e+000,3.499911e+001,-1.641687e-007,0.000000e+000,2,0.000000e+000,0.000000e+000,,,,,,,,,,,,,,32,1,4.000000e+000,7.820129e-004,0.000000e+000,0,,0,
1524484908.355,,0.000000e+000,3.499989e+001,-1.401534e-007,0.000000e+000,2,0.000000e+000,0.000000e+000,,,,,,,,,,,,,,32,1,4.000000e+000,2.342224e-003,0.000000e+000,0,,0,
1524484950.706,,0.000000e+000,3.499911e+001,-1.291063e-007,0.000000e+000,2,0.000000e+000,0.000000e+000,,,,,,,,,,,,,,32,1,4.000000e+000,2.338409e-003,0.000000e+000,0,,0,
1524484994.309,,0.000000e+000,3.500146e+001,-1.386708e-007,0.000000e+000,2,0.000000e+000,0.000000e+000,,,,,,,,,,,,,,32,1,4.000000e+000,3.910065e-003,0.000000e+000,0,,0,
1524485037.024,,0.000000e+000,3.499950e+001,-1.758303e-007,0.000000e+000,2,0.000000e+000,0.000000e+000,,,,,,,,,,,,,,32,1,4.000000e+000,3.120422e-003,0.000000e+000,0,,0,
1524485079.204,,0.000000e+000,3.499872e+001,-1.719320e-007,0.000000e+000,2,0.000000e+000,0.000000e+000,,,,,,,,,,,,,,32,1,4.000000e+000,0.000000e+000,0.000000e+000,0,,0,
1524485120.596,,0.000000e+000,3.499911e+001,-1.426344e-007,0.000000e+000,2,0.000000e+000,0.000000e+000,,,,,,,,,,,,,,32,1,4.000000e+000,7.820129e-004,0.000000e+000,0,,0,
1524485162.013,,0.000000e+000,3.500028e+001,-1.080438e-007,0.000000e+000,2,0.000000e+000,0.000000e+000,,,,,,,,,,,,,,32,1,4.000000e+000,4.688263e-003,0.000000e+000,0,,0,
1524485203.900,,0.000000e+000,3.500067e+001,-1.453020e-007,0.000000e+000,2,0.000000e+000,0.000000e+000,,,,,,,,,,,,,,32,1,4.000000e+000,2.338409e-003,0.000000e+000,0,,0,
1524485260.560,,0.000000e+000,3.499989e+001,-1.474262e-007,0.000000e+000,2,0.000000e+000,0.000000e+000,,,,,,,,,,,,,,32,1,4.000000e+000,3.898621e-003,0.000000e+000,0,,0,
1524485303.005,,0.000000e+000,3.499989e+001,-1.287097e-007,0.000000e+000,2,0.000000e+000,0.000000e+000,,,,,,,,,,,,,,32,1,4.000000e+000,7.781982e-004,0.000000e+000,0,,0,
1524485344.533,,0.000000e+000,3.499989e+001,-1.679788e-007,0.000000e+000,2,0.000000e+000,0.000000e+000,,,,,,,,,,,,,,32,1,4.000000e+000,2.342224e-003,0.000000e+000,0,,0,
1524485387.683,,0.000000e+000,3.500028e+001,-1.769287e-007,0.000000e+000,2,0.000000e+000,0.000000e+000,,,,,,,,,,,,,,32,1,4.000000e+000,3.120422e-003,0.000000e+000,0,,0,
1524485432.143,,0.000000e+000,3.499950e+001,-1.320776e-007,0.000000e+000,2,0.000000e+000,0.000000e+000,,,,,,,,,,,,,,32,1,4.000000e+000,0.000000e+000,0.000000e+000,0,,0,
1524485474.467,,0.000000e+000,3.499989e+001,-1.039103e-007,0.000000e+000,2,0.000000e+000,0.000000e+000,,,,,,,,,,,,,,32,1,4.000000e+000,7.781982e-004,0.000000e+000,0,,0,
1524485516.809,,0.000000e+000,3.499793e+001,-1.575772e-007,0.000000e+000,2,0.000000e+000,0.000000e+000,,,,,,,,,,,,,,32,1,4.000000e+000,1.567841e-003,0.000000e+000,0,,0,
1524485560.440,,0.000000e+000,3.499950e+001,-1.024001e-007,0.000000e+000,2,0.000000e+000,0.000000e+000,,,,,,,,,,,,,,32,1,4.000000e+000,0.000000e+000,0.000000e+000,0,,0,
1524485602.965,,0.000000e+000,3.499833e+001,-1.640265e-007,0.000000e+000,2,0.000000e+000,0.000000e+000,,,,,,,,,,,,,,32,1,4.000000e+000,2.349854e-003,0.000000e+000,0,,0,
1524485644.771,,0.000000e+000,3.500028e+001,-2.022964e-007,0.000000e+000,2,0.000000e+000,0.000000e+000,,,,,,,,,,,,,,32,1,4.000000e+000,3.120422e-003,0.000000e+000,0,,0,
1524485688.051,,0.000000e+000,3.500067e+001,-1.176732e-007,0.000000e+000,2,0.000000e+000,0.000000e+000,,,,,,,,,,,,,,32,1,4.000000e+000,2.338409e-003,0.000000e+000,0,,0,
1524485728.202,,0.000000e+000,3.499833e+001,-1.744700e-007,0.000000e+000,2,0.000000e+000,0.000000e+000,,,,,,,,,,,,,,32,1,4.000000e+000,2.349854e-003,0.000000e+000,0,,0,
1524485771.319,,0.000000e+000,3.500145e+001,-1.553131e-007,0.000000e+000,2,0.000000e+000,0.000000e+000,,,,,,,,,,,,,,32,1,4.000000e+000,2.349854e-003,0.000000e+000,0,,0,
1524485810.564,,0.000000e+000,3.499989e+001,6.939597e-006,0.000000e+000,3,8.812629e-001,0.000000e+000,,,,,,,,,,,,,,32,1,4.000000e+000,3.898621e-003,0.000000e+000,0,,0,
1524485853.174,,0.000000e+000,3.500067e+001,-1.215246e-007,0.000000e+000,2,0.000000e+000,0.000000e+000,,,,,,,,,,,,,,32,1,4.000000e+000,7.820129e-004,0.000000e+000,0,,0,
1524485895.388,,0.000000e+000,3.500028e+001,-1.919662e-007,0.000000e+000,2,0.000000e+000,0.000000e+000,,,,,,,,,,,,,,32,1,4.000000e+000,1.560211e-003,0.000000e+000,0,,0,
1524485938.538,,0.000000e+000,3.499950e+001,-1.744078e-007,0.000000e+000,2,0.000000e+000,0.000000e+000,,,,,,,,,,,,,,32,1,4.000000e+000,0.000000e+000,0.000000e+000,0,,0,
1524485979.050,,0.000000e+000,3.499989e+001,-1.593355e-007,0.000000e+000,2,0.000000e+000,0.000000e+000,,,,,,,,,,,,,,32,1,4.000000e+000,3.898621e-003,0.000000e+000,0,,0,
1524486019.646,,0.000000e+000,3.499871e+001,-1.653076e-007,0.000000e+000,2,0.000000e+000,0.000000e+000,,,,,,,,,,,,,,32,1,4.000000e+000,4.692078e-003,0.000000e+000,0,,0,
1524486061.778,,0.000000e+000,3.499911e+001,-1.960698e-007,0.000000e+000,2,0.000000e+000,0.000000e+000,,,,,,,,,,,,,,32,1,4.000000e+000,7.820129e-004,0.000000e+000,0,,0,
1524486102.063,,0.000000e+000,3.500067e+001,6.906334e-006,0.000000e+000,3,8.848853e-001,0.000000e+000,,,,,,,,,,,,,,32,1,4.000000e+000,2.338409e-003,0.000000e+000,0,,0,
1524486145.252,,0.000000e+000,3.500067e+001,-1.715951e-007,0.000000e+000,2,0.000000e+000,0.000000e+000,,,,,,,,,,,,,,32,1,4.000000e+000,2.338409e-003,0.000000e+000,0,,0,
1524486187.504,,0.000000e+000,3.500028e+001,-1.863230e-007,0.000000e+000,2,0.000000e+000,0.000000e+000,,,,,,,,,,,,,,32,1,4.000000e+000,1.560211e-003,0.000000e+000,0,,0,
1524486228.553,,0.000000e+000,3.500067e+001,6.997686e-006,0.000000e+000,3,8.715025e-001,0.000000e+000,,,,,,,,,,,,,,32,1,4.000000e+000,7.820129e-004,0.000000e+000,0,,0,
1524486257.402,,0.000000e+000,3.499989e+001,-1.322936e-007,0.000000e+000,2,0.000000e+000,0.000000e+000,,,,,,,,,,,,,,32,1,4.000000e+000,7.781982e-004,0.000000e+000,0,,0,