File: Experimental Raw Data/MFn1 VRM/Adjusting Iterative/MFn1_VRMac_36K_6000s_VRMde_35K.dc.dat
[Header]
TITLE,MPMS DC Measurement
BYAPP,MPMS Measurement,2.1,Summary
FILEOPENTIME, 1524322486.883000 4/21/2018, 8:54:46 AM

INFO, APPNAME, MPMS MultiVu Application, Revision 1.61,  Build 082

INFO, NAME, MFn1
INFO, WEIGHT, 1.000
INFO, AREA, 1.000
INFO, LENGTH, 1.000
INFO, SHAPE, 0
INFO, COMMENT,
INFO, SEQUENCE FILE: VRMac_36K_6000s_VRMde_35K.seq


INFO, BACKGROUND DATA FILE:, None


STARTUPAXIS,X,4,LINEAR,AUTO,0.000000,0.000000
STARTUPAXIS,Y1,5,LINEAR,AUTO,0.000000,0.000000


STARTUPGROUP,Longitudinal
FIELDGROUP,Longitudinal,1,2,3,4,5,6,7,8,9,15,16,17,18,27,28
FIELDGROUP,Transverse,1,2,3,4,10,11,12,13,14,19,20,21,22,27,28

PLOT_APPEARANCE,ALL,HORZ_GRID_ON,VERT_GRID_ON,MARKERS_AND_LINES

[Data]
Time,Comment,Field (Oe),Temperature (K),Long Moment (emu),Long Scan Std Dev,Long Algorithm,Long Reg Fit,Long Percent Error (%),Trans Moment (emu),Trans Scan Std Dev,Trans Algorithm,Trans Reg Fit,Trans Percent Error (%),Long Moment [w/o ABS] (emu),Long Scan Std Dev [w/o ABS],Long Reg Fit [w/o ABS],Long Percent Error [w/o ABS] (%),Trans Moment [w/o ABS] (emu),Trans Scan Std Dev [w/o ABS],Trans Reg Fit [w/o ABS],Trans Percent Error [w/o ABS] (%),Points per Scan,Scans per Measurement,Scan Length (cm),Delta Temp (K),Rot Position (deg),Error,EC Comp. Running,Using ABS,
1524497597.619,,0.000000e+000,3.499833e+001,4.268599e-006,0.000000e+000,3,8.385296e-001,0.000000e+000,,,,,,,,,,,,,,32,1,4.000000e+000,7.781982e-004,0.000000e+000,0,,0,
1524497635.700,,0.000000e+000,3.500106e+001,4.943046e-006,0.000000e+000,3,8.619497e-001,0.000000e+000,,,,,,,,,,,,,,32,1,4.000000e+000,3.128052e-003,0.000000e+000,0,,0,
1524497674.173,,0.000000e+000,3.500028e+001,5.718817e-006,0.000000e+000,3,8.813888e-001,0.000000e+000,,,,,,,,,,,,,,32,1,4.000000e+000,0.000000e+000,0.000000e+000,0,,0,
1524497712.198,,0.000000e+000,3.500106e+001,6.295058e-006,0.000000e+000,3,8.934557e-001,0.000000e+000,,,,,,,,,,,,,,32,1,4.000000e+000,1.560211e-003,0.000000e+000,0,,0,
1524497750.244,,0.000000e+000,3.500028e+001,6.823739e-006,0.000000e+000,3,9.071913e-001,0.000000e+000,,,,,,,,,,,,,,32,1,4.000000e+000,1.560211e-003,0.000000e+000,0,,0,
1524497788.320,,0.000000e+000,3.499950e+001,7.323020e-006,0.000000e+000,3,9.149855e-001,0.000000e+000,,,,,,,,,,,,,,32,1,4.000000e+000,1.560211e-003,0.000000e+000,0,,0,
1524497825.595,,0.000000e+000,3.499950e+001,7.796419e-006,0.000000e+000,3,9.111259e-001,0.000000e+000,,,,,,,,,,,,,,32,1,4.000000e+000,0.000000e+000,0.000000e+000,0,,0,
1524497863.038,,0.000000e+000,3.499950e+001,8.153704e-006,0.000000e+000,3,9.150516e-001,0.000000e+000,,,,,,,,,,,,,,32,1,4.000000e+000,1.560211e-003,0.000000e+000,0,,0,
1524497900.639,,0.000000e+000,3.499950e+001,8.550381e-006,0.000000e+000,3,9.229141e-001,0.000000e+000,,,,,,,,,,,,,,32,1,4.000000e+000,1.560211e-003,0.000000e+000,0,,0,
1524497938.599,,0.000000e+000,3.499872e+001,8.863239e-006,0.000000e+000,3,9.225445e-001,0.000000e+000,,,,,,,,,,,,,,32,1,4.000000e+000,0.000000e+000,0.000000e+000,0,,0,
1524497976.635,,0.000000e+000,3.499989e+001,9.168642e-006,0.000000e+000,3,9.298670e-001,0.000000e+000,,,,,,,,,,,,,,32,1,4.000000e+000,7.781982e-004,0.000000e+000,0,,0,
1524498014.645,,0.000000e+000,3.499989e+001,9.580759e-006,0.000000e+000,3,9.323872e-001,0.000000e+000,,,,,,,,,,,,,,32,1,4.000000e+000,7.781982e-004,0.000000e+000,0,,0,
1524498052.701,,0.000000e+000,3.499833e+001,9.816227e-006,0.000000e+000,3,9.305989e-001,0.000000e+000,,,,,,,,,,,,,,32,1,4.000000e+000,7.781982e-004,0.000000e+000,0,,0,
1524498090.251,,0.000000e+000,3.499950e+001,1.002524e-005,0.000000e+000,3,9.325192e-001,0.000000e+000,,,,,,,,,,,,,,32,1,4.000000e+000,0.000000e+000,0.000000e+000,0,,0,
1524498128.352,,0.000000e+000,3.499989e+001,1.030536e-005,0.000000e+000,3,9.315265e-001,0.000000e+000,,,,,,,,,,,,,,32,1,4.000000e+000,7.781982e-004,0.000000e+000,0,,0,
1524498166.363,,0.000000e+000,3.499833e+001,1.055180e-005,0.000000e+000,3,9.332737e-001,0.000000e+000,,,,,,,,,,,,,,32,1,4.000000e+000,7.781982e-004,0.000000e+000,0,,0,
1524498204.428,,0.000000e+000,3.499872e+001,1.076242e-005,0.000000e+000,3,9.394636e-001,0.000000e+000,,,,,,,,,,,,,,32,1,4.000000e+000,1.560211e-003,0.000000e+000,0,,0,
1524498242.551,,0.000000e+000,3.499872e+001,1.100305e-005,0.000000e+000,3,9.389779e-001,0.000000e+000,,,,,,,,,,,,,,32,1,4.000000e+000,1.560211e-003,0.000000e+000,0,,0,
1524498280.074,,0.000000e+000,3.499911e+001,1.125381e-005,0.000000e+000,3,9.413378e-001,0.000000e+000,,,,,,,,,,,,,,32,1,4.000000e+000,7.820129e-004,0.000000e+000,0,,0,
1524498318.272,,0.000000e+000,3.499911e+001,1.137301e-005,0.000000e+000,3,9.400287e-001,0.000000e+000,,,,,,,,,,,,,,32,1,4.000000e+000,7.820129e-004,0.000000e+000,0,,0,
1524498356.140,,0.000000e+000,3.499833e+001,1.160465e-005,0.000000e+000,3,9.408851e-001,0.000000e+000,,,,,,,,,,,,,,32,1,4.000000e+000,7.781982e-004,0.000000e+000,0,,0,
1524498394.233,,0.000000e+000,3.499950e+001,1.179206e-005,0.000000e+000,3,9.410477e-001,0.000000e+000,,,,,,,,,,,,,,32,1,4.000000e+000,0.000000e+000,0.000000e+000,0,,0,
1524498432.269,,0.000000e+000,3.499911e+001,1.192801e-005,0.000000e+000,3,9.437942e-001,0.000000e+000,,,,,,,,,,,,,,32,1,4.000000e+000,7.820129e-004,0.000000e+000,0,,0,
1524498470.100,,0.000000e+000,3.499950e+001,1.212428e-005,0.000000e+000,3,9.379213e-001,0.000000e+000,,,,,,,,,,,,,,32,1,4.000000e+000,0.000000e+000,0.000000e+000,0,,0,
1524498521.848,,0.000000e+000,3.499950e+001,1.231443e-005,0.000000e+000,3,9.459789e-001,0.000000e+000,,,,,,,,,,,,,,32,1,4.000000e+000,1.560211e-003,0.000000e+000,0,,0,
1524498559.398,,0.000000e+000,3.500028e+001,1.244145e-005,0.000000e+000,3,9.426543e-001,0.000000e+000,,,,,,,,,,,,,,32,1,4.000000e+000,1.560211e-003,0.000000e+000,0,,0,
1524498597.926,,0.000000e+000,3.499872e+001,1.259168e-005,0.000000e+000,3,9.460078e-001,0.000000e+000,,,,,,,,,,,,,,32,1,4.000000e+000,0.000000e+000,0.000000e+000,0,,0,
1524498635.514,,0.000000e+000,3.499950e+001,1.270136e-005,0.000000e+000,3,9.459317e-001,0.000000e+000,,,,,,,,,,,,,,32,1,4.000000e+000,0.000000e+000,0.000000e+000,0,,0,
1524498673.570,,0.000000e+000,3.499989e+001,1.288844e-005,0.000000e+000,3,9.484790e-001,0.000000e+000,,,,,,,,,,,,,,32,1,4.000000e+000,7.781982e-004,0.000000e+000,0,,0,
1524498711.621,,0.000000e+000,3.499911e+001,1.307829e-005,0.000000e+000,3,9.490911e-001,0.000000e+000,,,,,,,,,,,,,,32,1,4.000000e+000,7.820129e-004,0.000000e+000,0,,0,
1524498749.364,,0.000000e+000,3.499911e+001,1.313805e-005,0.000000e+000,3,9.491456e-001,0.000000e+000,,,,,,,,,,,,,,32,1,4.000000e+000,7.820129e-004,0.000000e+000,0,,0,
1524498786.917,,0.000000e+000,3.499911e+001,1.330140e-005,0.000000e+000,3,9.450362e-001,0.000000e+000,,,,,,,,,,,,,,32,1,4.000000e+000,7.820129e-004,0.000000e+000,0,,0,
1524498824.467,,0.000000e+000,3.499872e+001,1.329390e-005,0.000000e+000,3,9.506454e-001,0.000000e+000,,,,,,,,,,,,,,32,1,4.000000e+000,0.000000e+000,0.000000e+000,0,,0,
1524498861.663,,0.000000e+000,3.499872e+001,1.351344e-005,0.000000e+000,3,9.463942e-001,0.000000e+000,,,,,,,,,,,,,,32,1,4.000000e+000,1.560211e-003,0.000000e+000,0,,0,
1524498900.111,,0.000000e+000,3.499911e+001,1.362697e-005,0.000000e+000,3,9.502206e-001,0.000000e+000,,,,,,,,,,,,,,32,1,4.000000e+000,7.820129e-004,0.000000e+000,0,,0,
1524498938.156,,0.000000e+000,3.499833e+001,1.375330e-005,0.000000e+000,3,9.488456e-001,0.000000e+000,,,,,,,,,,,,,,32,1,4.000000e+000,7.781982e-004,0.000000e+000,0,,0,
1524498975.877,,0.000000e+000,3.499911e+001,1.384748e-005,0.000000e+000,3,9.504737e-001,0.000000e+000,,,,,,,,,,,,,,32,1,4.000000e+000,7.820129e-004,0.000000e+000,0,,0,
1524499013.945,,0.000000e+000,3.500067e+001,1.403214e-005,0.000000e+000,3,9.509844e-001,0.000000e+000,,,,,,,,,,,,,,32,1,4.000000e+000,2.338409e-003,0.000000e+000,0,,0,
1524499051.428,,0.000000e+000,3.499950e+001,1.407471e-005,0.000000e+000,3,9.510353e-001,0.000000e+000,,,,,,,,,,,,,,32,1,4.000000e+000,0.000000e+000,0.000000e+000,0,,0,
1524499090.041,,0.000000e+000,3.499989e+001,1.415653e-005,0.000000e+000,3,9.520541e-001,0.000000e+000,,,,,,,,,,,,,,32,1,4.000000e+000,7.781982e-004,0.000000e+000,0,,0,
1524499128.307,,0.000000e+000,3.499872e+001,1.429167e-005,0.000000e+000,3,9.517621e-001,0.000000e+000,,,,,,,,,,,,,,32,1,4.000000e+000,0.000000e+000,0.000000e+000,0,,0,
1524499166.367,,0.000000e+000,3.499911e+001,1.434923e-005,0.000000e+000,3,9.535491e-001,0.000000e+000,,,,,,,,,,,,,,32,1,4.000000e+000,7.820129e-004,0.000000e+000,0,,0,
1524499204.440,,0.000000e+000,3.499950e+001,1.441533e-005,0.000000e+000,3,9.533728e-001,0.000000e+000,,,,,,,,,,,,,,32,1,4.000000e+000,0.000000e+000,0.000000e+000,0,,0,
1524499242.138,,0.000000e+000,3.499989e+001,1.455198e-005,0.000000e+000,3,9.511684e-001,0.000000e+000,,,,,,,,,,,,,,32,1,4.000000e+000,7.781982e-004,0.000000e+000,0,,0,
1524499280.174,,0.000000e+000,3.499950e+001,1.459462e-005,0.000000e+000,3,9.522202e-001,0.000000e+000,,,,,,,,,,,,,,32,1,4.000000e+000,0.000000e+000,0.000000e+000,0,,0,
1524499318.207,,0.000000e+000,3.499989e+001,1.471391e-005,0.000000e+000,3,9.519941e-001,0.000000e+000,,,,,,,,,,,,,,32,1,4.000000e+000,7.781982e-004,0.000000e+000,0,,0,
1524499356.275,,0.000000e+000,3.499911e+001,1.480196e-005,0.000000e+000,3,9.520470e-001,0.000000e+000,,,,,,,,,,,,,,32,1,4.000000e+000,7.820129e-004,0.000000e+000,0,,0,
1524499394.376,,0.000000e+000,3.499950e+001,1.492610e-005,0.000000e+000,3,9.520769e-001,0.000000e+000,,,,,,,,,,,,,,32,1,4.000000e+000,1.560211e-003,0.000000e+000,0,,0,
1524499445.776,,0.000000e+000,3.499950e+001,1.493761e-005,0.000000e+000,3,9.535683e-001,0.000000e+000,,,,,,,,,,,,,,32,1,4.000000e+000,0.000000e+000,0.000000e+000,0,,0,
1524499483.392,,0.000000e+000,3.499989e+001,1.502753e-005,0.000000e+000,3,9.555992e-001,0.000000e+000,,,,,,,,,,,,,,32,1,4.000000e+000,2.342224e-003,0.000000e+000,0,,0,
1524499520.687,,0.000000e+000,3.499989e+001,1.512430e-005,0.000000e+000,3,9.550990e-001,0.000000e+000,,,,,,,,,,,,,,32,1,4.000000e+000,7.781982e-004,0.000000e+000,0,,0,
1524499559.376,,0.000000e+000,3.499793e+001,1.523665e-005,0.000000e+000,3,9.534171e-001,0.000000e+000,,,,,,,,,,,,,,32,1,4.000000e+000,1.567841e-003,0.000000e+000,0,,0,
1524499597.564,,0.000000e+000,3.499989e+001,1.535524e-005,0.000000e+000,3,9.558291e-001,0.000000e+000,,,,,,,,,,,,,,32,1,4.000000e+000,2.342224e-003,0.000000e+000,0,,0,
1524499635.617,,0.000000e+000,3.499950e+001,1.539541e-005,0.000000e+000,3,9.543138e-001,0.000000e+000,,,,,,,,,,,,,,32,1,4.000000e+000,1.560211e-003,0.000000e+000,0,,0,
1524499673.345,,0.000000e+000,3.499872e+001,1.543665e-005,0.000000e+000,3,9.542664e-001,0.000000e+000,,,,,,,,,,,,,,32,1,4.000000e+000,1.560211e-003,0.000000e+000,0,,0,
1524499711.440,,0.000000e+000,3.499872e+001,1.552434e-005,0.000000e+000,3,9.564313e-001,0.000000e+000,,,,,,,,,,,,,,32,1,4.000000e+000,0.000000e+000,0.000000e+000,0,,0,
1524499749.446,,0.000000e+000,3.499872e+001,1.555556e-005,0.000000e+000,3,9.543959e-001,0.000000e+000,,,,,,,,,,,,,,32,1,4.000000e+000,1.560211e-003,0.000000e+000,0,,0,
1524499787.529,,0.000000e+000,3.499872e+001,1.559243e-005,0.000000e+000,3,9.582840e-001,0.000000e+000,,,,,,,,,,,,,,32,1,4.000000e+000,0.000000e+000,0.000000e+000,0,,0,
1524499825.779,,0.000000e+000,3.500067e+001,1.571353e-005,0.000000e+000,3,9.563165e-001,0.000000e+000,,,,,,,,,,,,,,32,1,4.000000e+000,7.820129e-004,0.000000e+000,0,,0,
1524499864.662,,0.000000e+000,3.499950e+001,1.573097e-005,0.000000e+000,3,9.546298e-001,0.000000e+000,,,,,,,,,,,,,,32,1,4.000000e+000,0.000000e+000,0.000000e+000,0,,0,
1524499902.493,,0.000000e+000,3.499872e+001,1.579496e-005,0.000000e+000,3,9.565346e-001,0.000000e+000,,,,,,,,,,,,,,32,1,4.000000e+000,0.000000e+000,0.000000e+000,0,,0,
1524499940.141,,0.000000e+000,3.500263e+001,1.591492e-005,0.000000e+000,3,9.547350e-001,0.000000e+000,,,,,,,,,,,,,,32,1,4.000000e+000,6.259918e-003,0.000000e+000,0,,0,
1524499978.414,,0.000000e+000,3.499950e+001,1.584845e-005,0.000000e+000,3,9.567308e-001,0.000000e+000,,,,,,,,,,,,,,32,1,4.000000e+000,0.000000e+000,0.000000e+000,0,,0,
1524500016.197,,0.000000e+000,3.499911e+001,1.601111e-005,0.000000e+000,3,9.574042e-001,0.000000e+000,,,,,,,,,,,,,,32,1,4.000000e+000,7.820129e-004,0.000000e+000,0,,0,
1524500054.018,,0.000000e+000,3.499911e+001,1.605575e-005,0.000000e+000,3,9.545022e-001,0.000000e+000,,,,,,,,,,,,,,32,1,4.000000e+000,7.820129e-004,0.000000e+000,0,,0,
1524500092.056,,0.000000e+000,3.499911e+001,1.613784e-005,0.000000e+000,3,9.576548e-001,0.000000e+000,,,,,,,,,,,,,,32,1,4.000000e+000,7.820129e-004,0.000000e+000,0,,0,
1524500130.119,,0.000000e+000,3.499872e+001,1.620044e-005,0.000000e+000,3,9.573336e-001,0.000000e+000,,,,,,,,,,,,,,32,1,4.000000e+000,0.000000e+000,0.000000e+000,0,,0,
1524500167.659,,0.000000e+000,3.499950e+001,1.625890e-005,0.000000e+000,3,9.529651e-001,0.000000e+000,,,,,,,,,,,,,,32,1,4.000000e+000,0.000000e+000,0.000000e+000,0,,0,
1524500205.785,,0.000000e+000,3.499872e+001,1.635960e-005,0.000000e+000,3,9.552231e-001,0.000000e+000,,,,,,,,,,,,,,32,1,4.000000e+000,1.560211e-003,0.000000e+000,0,,0,
1524500243.836,,0.000000e+000,3.500067e+001,1.624145e-005,0.000000e+000,3,9.534839e-001,0.000000e+000,,,,,,,,,,,,,,32,1,4.000000e+000,3.910065e-003,0.000000e+000,0,,0,
1524500281.241,,0.000000e+000,3.500028e+001,1.639404e-005,0.000000e+000,3,9.590417e-001,0.000000e+000,,,,,,,,,,,,,,32,1,4.000000e+000,3.120422e-003,0.000000e+000,0,,0,
1524500332.132,,0.000000e+000,3.499911e+001,1.653995e-005,0.000000e+000,3,9.592019e-001,0.000000e+000,,,,,,,,,,,,,,32,1,4.000000e+000,7.820129e-004,0.000000e+000,0,,0,
1524500370.170,,0.000000e+000,3.499950e+001,1.649451e-005,0.000000e+000,3,9.603764e-001,0.000000e+000,,,,,,,,,,,,,,32,1,4.000000e+000,1.560211e-003,0.000000e+000,0,,0,
1524500408.706,,0.000000e+000,3.499872e+001,1.666512e-005,0.000000e+000,3,9.575644e-001,0.000000e+000,,,,,,,,,,,,,,32,1,4.000000e+000,1.560211e-003,0.000000e+000,0,,0,
1524500446.784,,0.000000e+000,3.499911e+001,1.652834e-005,0.000000e+000,3,9.572550e-001,0.000000e+000,,,,,,,,,,,,,,32,1,4.000000e+000,7.820129e-004,0.000000e+000,0,,0,
1524500485.577,,0.000000e+000,3.499872e+001,1.665710e-005,0.000000e+000,3,9.582752e-001,0.000000e+000,,,,,,,,,,,,,,32,1,4.000000e+000,0.000000e+000,0.000000e+000,0,,0,
1524500523.707,,0.000000e+000,3.499911e+001,1.673924e-005,0.000000e+000,3,9.584962e-001,0.000000e+000,,,,,,,,,,,,,,32,1,4.000000e+000,7.820129e-004,0.000000e+000,0,,0,
1524500561.775,,0.000000e+000,3.499833e+001,1.686012e-005,0.000000e+000,3,9.584013e-001,0.000000e+000,,,,,,,,,,,,,,32,1,4.000000e+000,7.781982e-004,0.000000e+000,0,,0,
1524500600.083,,0.000000e+000,3.499989e+001,1.686156e-005,0.000000e+000,3,9.609223e-001,0.000000e+000,,,,,,,,,,,,,,32,1,4.000000e+000,7.781982e-004,0.000000e+000,0,,0,
1524500638.209,,0.000000e+000,3.499950e+001,1.682450e-005,0.000000e+000,3,9.566275e-001,0.000000e+000,,,,,,,,,,,,,,32,1,4.000000e+000,1.560211e-003,0.000000e+000,0,,0,
1524500676.724,,0.000000e+000,3.499872e+001,1.695882e-005,0.000000e+000,3,9.612136e-001,0.000000e+000,,,,,,,,,,,,,,32,1,4.000000e+000,1.560211e-003,0.000000e+000,0,,0,
1524500714.785,,0.000000e+000,3.499950e+001,1.704204e-005,0.000000e+000,3,9.598846e-001,0.000000e+000,,,,,,,,,,,,,,32,1,4.000000e+000,1.560211e-003,0.000000e+000,0,,0,
1524500752.348,,0.000000e+000,3.499911e+001,1.704209e-005,0.000000e+000,3,9.591324e-001,0.000000e+000,,,,,,,,,,,,,,32,1,4.000000e+000,2.338409e-003,0.000000e+000,0,,0,
1524500790.554,,0.000000e+000,3.500185e+001,1.706442e-005,0.000000e+000,3,9.605474e-001,0.000000e+000,,,,,,,,,,,,,,32,1,4.000000e+000,1.567841e-003,0.000000e+000,0,,0,
1524500828.489,,0.000000e+000,3.499911e+001,1.718708e-005,0.000000e+000,3,9.557365e-001,0.000000e+000,,,,,,,,,,,,,,32,1,4.000000e+000,7.820129e-004,0.000000e+000,0,,0,
1524500866.562,,0.000000e+000,3.500028e+001,1.720512e-005,0.000000e+000,3,9.589696e-001,0.000000e+000,,,,,,,,,,,,,,32,1,4.000000e+000,0.000000e+000,0.000000e+000,0,,0,
1524500904.573,,0.000000e+000,3.499872e+001,1.716746e-005,0.000000e+000,3,9.597476e-001,0.000000e+000,,,,,,,,,,,,,,32,1,4.000000e+000,0.000000e+000,0.000000e+000,0,,0,
1524500942.638,,0.000000e+000,3.500028e+001,1.728470e-005,0.000000e+000,3,9.592013e-001,0.000000e+000,,,,,,,,,,,,,,32,1,4.000000e+000,0.000000e+000,0.000000e+000,0,,0,
1524500980.751,,0.000000e+000,3.499793e+001,1.731317e-005,0.000000e+000,3,9.583007e-001,0.000000e+000,,,,,,,,,,,,,,32,1,4.000000e+000,1.567841e-003,0.000000e+000,0,,0,
1524501018.757,,0.000000e+000,3.499989e+001,1.736582e-005,0.000000e+000,3,9.586113e-001,0.000000e+000,,,,,,,,,,,,,,32,1,4.000000e+000,7.781982e-004,0.000000e+000,0,,0,
1524501056.868,,0.000000e+000,3.499989e+001,1.738417e-005,0.000000e+000,3,9.594418e-001,0.000000e+000,,,,,,,,,,,,,,32,1,4.000000e+000,7.781982e-004,0.000000e+000,0,,0,
1524501094.926,,0.000000e+000,3.499911e+001,1.735756e-005,0.000000e+000,3,9.591331e-001,0.000000e+000,,,,,,,,,,,,,,32,1,4.000000e+000,7.820129e-004,0.000000e+000,0,,0,
1524501132.941,,0.000000e+000,3.499989e+001,1.745178e-005,0.000000e+000,3,9.583246e-001,0.000000e+000,,,,,,,,,,,,,,32,1,4.000000e+000,7.781982e-004,0.000000e+000,0,,0,
1524501171.622,,0.000000e+000,3.499911e+001,1.752094e-005,0.000000e+000,3,9.585618e-001,0.000000e+000,,,,,,,,,,,,,,32,1,4.000000e+000,7.820129e-004,0.000000e+000,0,,0,
1524501208.452,,0.000000e+000,3.499989e+001,1.755238e-005,0.000000e+000,3,9.604760e-001,0.000000e+000,,,,,,,,,,,,,,32,1,4.000000e+000,2.342224e-003,0.000000e+000,0,,0,
1524501259.820,,0.000000e+000,3.499872e+001,1.756933e-005,0.000000e+000,3,9.619839e-001,0.000000e+000,,,,,,,,,,,,,,32,1,4.000000e+000,1.560211e-003,0.000000e+000,0,,0,
1524501297.919,,0.000000e+000,3.499911e+001,1.764988e-005,0.000000e+000,3,9.630537e-001,0.000000e+000,,,,,,,,,,,,,,32,1,4.000000e+000,2.338409e-003,0.000000e+000,0,,0,
1524501335.959,,0.000000e+000,3.499950e+001,1.768130e-005,0.000000e+000,3,9.602412e-001,0.000000e+000,,,,,,,,,,,,,,32,1,4.000000e+000,1.560211e-003,0.000000e+000,0,,0,
1524501374.002,,0.000000e+000,3.499989e+001,1.765404e-005,0.000000e+000,3,9.583488e-001,0.000000e+000,,,,,,,,,,,,,,32,1,4.000000e+000,7.781982e-004,0.000000e+000,0,,0,
1524501412.095,,0.000000e+000,3.499872e+001,1.773701e-005,0.000000e+000,3,9.606901e-001,0.000000e+000,,,,,,,,,,,,,,32,1,4.000000e+000,0.000000e+000,0.000000e+000,0,,0,
1524501450.126,,0.000000e+000,3.500028e+001,1.775327e-005,0.000000e+000,3,9.611813e-001,0.000000e+000,,,,,,,,,,,,,,32,1,4.000000e+000,1.560211e-003,0.000000e+000,0,,0,
1524501488.366,,0.000000e+000,3.499989e+001,1.784931e-005,0.000000e+000,3,9.603183e-001,0.000000e+000,,,,,,,,,,,,,,32,1,4.000000e+000,2.342224e-003,0.000000e+000,0,,0,
1524501526.292,,0.000000e+000,3.500067e+001,1.781189e-005,0.000000e+000,3,9.601093e-001,0.000000e+000,,,,,,,,,,,,,,32,1,4.000000e+000,2.338409e-003,0.000000e+000,0,,0,
1524501564.325,,0.000000e+000,3.499793e+001,1.787953e-005,0.000000e+000,3,9.620637e-001,0.000000e+000,,,,,,,,,,,,,,32,1,4.000000e+000,3.131866e-003,0.000000e+000,0,,0,
1524501602.408,,0.000000e+000,3.499793e+001,1.789985e-005,0.000000e+000,3,9.633847e-001,0.000000e+000,,,,,,,,,,,,,,32,1,4.000000e+000,3.131866e-003,0.000000e+000,0,,0,
1524501640.474,,0.000000e+000,3.499872e+001,1.790892e-005,0.000000e+000,3,9.628448e-001,0.000000e+000,,,,,,,,,,,,,,32,1,4.000000e+000,1.560211e-003,0.000000e+000,0,,0,
1524501678.577,,0.000000e+000,3.499950e+001,1.798494e-005,0.000000e+000,3,9.638807e-001,0.000000e+000,,,,,,,,,,,,,,32,1,4.000000e+000,1.560211e-003,0.000000e+000,0,,0,
1524501716.585,,0.000000e+000,3.499872e+001,1.806842e-005,0.000000e+000,3,9.596964e-001,0.000000e+000,,,,,,,,,,,,,,32,1,4.000000e+000,1.560211e-003,0.000000e+000,0,,0,
1524501754.613,,0.000000e+000,3.499793e+001,1.810695e-005,0.000000e+000,3,9.618397e-001,0.000000e+000,,,,,,,,,,,,,,32,1,4.000000e+000,1.567841e-003,0.000000e+000,0,,0,
1524501792.713,,0.000000e+000,3.499832e+001,1.810743e-005,0.000000e+000,3,9.627199e-001,0.000000e+000,,,,,,,,,,,,,,32,1,4.000000e+000,3.910065e-003,0.000000e+000,0,,0,
1524501830.761,,0.000000e+000,3.499872e+001,1.811544e-005,0.000000e+000,3,9.620169e-001,0.000000e+000,,,,,,,,,,,,,,32,1,4.000000e+000,0.000000e+000,0.000000e+000,0,,0,
1524501868.799,,0.000000e+000,3.500145e+001,1.816506e-005,0.000000e+000,3,9.626764e-001,0.000000e+000,,,,,,,,,,,,,,32,1,4.000000e+000,2.349854e-003,0.000000e+000,0,,0,
1524501907.020,,0.000000e+000,3.499911e+001,1.811890e-005,0.000000e+000,3,9.612798e-001,0.000000e+000,,,,,,,,,,,,,,32,1,4.000000e+000,2.338409e-003,0.000000e+000,0,,0,
1524501944.476,,0.000000e+000,3.499911e+001,1.829502e-005,0.000000e+000,3,9.607155e-001,0.000000e+000,,,,,,,,,,,,,,32,1,4.000000e+000,2.338409e-003,0.000000e+000,0,,0,
1524501982.486,,0.000000e+000,3.499950e+001,1.828707e-005,0.000000e+000,3,9.623392e-001,0.000000e+000,,,,,,,,,,,,,,32,1,4.000000e+000,0.000000e+000,0.000000e+000,0,,0,
1524502020.157,,0.000000e+000,3.499871e+001,1.829626e-005,0.000000e+000,3,9.621991e-001,0.000000e+000,,,,,,,,,,,,,,32,1,4.000000e+000,3.128052e-003,0.000000e+000,0,,0,
1524502057.785,,0.000000e+000,3.499794e+001,1.828313e-005,0.000000e+000,3,9.630257e-001,0.000000e+000,,,,,,,,,,,,,,32,1,4.000000e+000,0.000000e+000,0.000000e+000,0,,0,
1524502095.820,,0.000000e+000,3.499911e+001,1.831027e-005,0.000000e+000,3,9.620506e-001,0.000000e+000,,,,,,,,,,,,,,32,1,4.000000e+000,7.820129e-004,0.000000e+000,0,,0,
1524502147.046,,0.000000e+000,3.500028e+001,1.839827e-005,0.000000e+000,3,9.621931e-001,0.000000e+000,,,,,,,,,,,,,,32,1,4.000000e+000,0.000000e+000,0.000000e+000,0,,0,
1524502184.554,,0.000000e+000,3.499872e+001,1.837393e-005,0.000000e+000,3,9.633597e-001,0.000000e+000,,,,,,,,,,,,,,32,1,4.000000e+000,1.560211e-003,0.000000e+000,0,,0,
1524502222.680,,0.000000e+000,3.499989e+001,1.836513e-005,0.000000e+000,3,9.618182e-001,0.000000e+000,,,,,,,,,,,,,,32,1,4.000000e+000,7.781982e-004,0.000000e+000,0,,0,
1524502260.740,,0.000000e+000,3.499911e+001,1.852674e-005,0.000000e+000,3,9.625093e-001,0.000000e+000,,,,,,,,,,,,,,32,1,4.000000e+000,7.820129e-004,0.000000e+000,0,,0,
1524502298.793,,0.000000e+000,3.499989e+001,1.848433e-005,0.000000e+000,3,9.624434e-001,0.000000e+000,,,,,,,,,,,,,,32,1,4.000000e+000,7.781982e-004,0.000000e+000,0,,0,
1524502336.776,,0.000000e+000,3.499989e+001,1.855980e-005,0.000000e+000,3,9.644018e-001,0.000000e+000,,,,,,,,,,,,,,32,1,4.000000e+000,2.342224e-003,0.000000e+000,0,,0,
1524502374.849,,0.000000e+000,3.499872e+001,1.857541e-005,0.000000e+000,3,9.614714e-001,0.000000e+000,,,,,,,,,,,,,,32,1,4.000000e+000,0.000000e+000,0.000000e+000,0,,0,
1524502412.907,,0.000000e+000,3.499950e+001,1.859455e-005,0.000000e+000,3,9.649110e-001,0.000000e+000,,,,,,,,,,,,,,32,1,4.000000e+000,0.000000e+000,0.000000e+000,0,,0,
1524502450.970,,0.000000e+000,3.499911e+001,1.854591e-005,0.000000e+000,3,9.619399e-001,0.000000e+000,,,,,,,,,,,,,,32,1,4.000000e+000,7.820129e-004,0.000000e+000,0,,0,
1524502489.026,,0.000000e+000,3.499833e+001,1.863567e-005,0.000000e+000,3,9.648479e-001,0.000000e+000,,,,,,,,,,,,,,32,1,4.000000e+000,2.349854e-003,0.000000e+000,0,,0,
1524502527.442,,0.000000e+000,3.499950e+001,1.867020e-005,0.000000e+000,3,9.613434e-001,0.000000e+000,,,,,,,,,,,,,,32,1,4.000000e+000,1.560211e-003,0.000000e+000,0,,0,
1524502565.555,,0.000000e+000,3.499950e+001,1.868916e-005,0.000000e+000,3,9.628059e-001,0.000000e+000,,,,,,,,,,,,,,32,1,4.000000e+000,0.000000e+000,0.000000e+000,0,,0,
1524502604.730,,0.000000e+000,3.499872e+001,1.869653e-005,0.000000e+000,3,9.628465e-001,0.000000e+000,,,,,,,,,,,,,,32,1,4.000000e+000,0.000000e+000,0.000000e+000,0,,0,
1524502642.838,,0.000000e+000,3.499872e+001,1.871095e-005,0.000000e+000,3,9.637534e-001,0.000000e+000,,,,,,,,,,,,,,32,1,4.000000e+000,0.000000e+000,0.000000e+000,0,,0,
1524502680.904,,0.000000e+000,3.499950e+001,1.874117e-005,0.000000e+000,3,9.645046e-001,0.000000e+000,,,,,,,,,,,,,,32,1,4.000000e+000,1.560211e-003,0.000000e+000,0,,0,
1524502718.952,,0.000000e+000,3.499911e+001,1.872242e-005,0.000000e+000,3,9.648346e-001,0.000000e+000,,,,,,,,,,,,,,32,1,4.000000e+000,7.820129e-004,0.000000e+000,0,,0,
1524502757.397,,0.000000e+000,3.500028e+001,1.884400e-005,0.000000e+000,3,9.632047e-001,0.000000e+000,,,,,,,,,,,,,,32,1,4.000000e+000,0.000000e+000,0.000000e+000,0,,0,
1524502795.433,,0.000000e+000,3.499872e+001,1.888545e-005,0.000000e+000,3,9.635098e-001,0.000000e+000,,,,,,,,,,,,,,32,1,4.000000e+000,0.000000e+000,0.000000e+000,0,,0,
1524502833.519,,0.000000e+000,3.499911e+001,1.889665e-005,0.000000e+000,3,9.635730e-001,0.000000e+000,,,,,,,,,,,,,,32,1,4.000000e+000,7.820129e-004,0.000000e+000,0,,0,
1524502872.662,,0.000000e+000,3.499950e+001,1.884058e-005,0.000000e+000,3,9.634043e-001,0.000000e+000,,,,,,,,,,,,,,32,1,4.000000e+000,0.000000e+000,0.000000e+000,0,,0,
1524502910.117,,0.000000e+000,3.499950e+001,1.894815e-005,0.000000e+000,3,9.656318e-001,0.000000e+000,,,,,,,,,,,,,,32,1,4.000000e+000,1.560211e-003,0.000000e+000,0,,0,
1524502948.178,,0.000000e+000,3.499911e+001,1.892783e-005,0.000000e+000,3,9.638444e-001,0.000000e+000,,,,,,,,,,,,,,32,1,4.000000e+000,7.820129e-004,0.000000e+000,0,,0,
1524502987.321,,0.000000e+000,3.499793e+001,1.897810e-005,0.000000e+000,3,9.652876e-001,0.000000e+000,,,,,,,,,,,,,,32,1,4.000000e+000,1.567841e-003,0.000000e+000,0,,0,
1524503038.682,,0.000000e+000,3.499950e+001,1.901444e-005,0.000000e+000,3,9.636415e-001,0.000000e+000,,,,,,,,,,,,,,32,1,4.000000e+000,1.560211e-003,0.000000e+000,0,,0,
1524503076.102,,0.000000e+000,3.499911e+001,1.902398e-005,0.000000e+000,3,9.647269e-001,0.000000e+000,,,,,,,,,,,,,,32,1,4.000000e+000,7.820129e-004,0.000000e+000,0,,0,
1524503114.660,,0.000000e+000,3.499833e+001,1.905216e-005,0.000000e+000,3,9.634448e-001,0.000000e+000,,,,,,,,,,,,,,32,1,4.000000e+000,7.781982e-004,0.000000e+000,0,,0,
1524503152.416,,0.000000e+000,3.500028e+001,1.912375e-005,0.000000e+000,3,9.638549e-001,0.000000e+000,,,,,,,,,,,,,,32,1,4.000000e+000,1.560211e-003,0.000000e+000,0,,0,
1524503190.774,,0.000000e+000,3.499950e+001,1.906127e-005,0.000000e+000,3,9.635959e-001,0.000000e+000,,,,,,,,,,,,,,32,1,4.000000e+000,0.000000e+000,0.000000e+000,0,,0,
1524503228.547,,0.000000e+000,3.500028e+001,1.909835e-005,0.000000e+000,3,9.627730e-001,0.000000e+000,,,,,,,,,,,,,,32,1,4.000000e+000,0.000000e+000,0.000000e+000,0,,0,
1524503266.412,,0.000000e+000,3.499872e+001,1.908810e-005,0.000000e+000,3,9.630114e-001,0.000000e+000,,,,,,,,,,,,,,32,1,4.000000e+000,0.000000e+000,0.000000e+000,0,,0,
1524503304.460,,0.000000e+000,3.499911e+001,1.911715e-005,0.000000e+000,3,9.656054e-001,0.000000e+000,,,,,,,,,,,,,,32,1,4.000000e+000,7.820129e-004,0.000000e+000,0,,0,
1524503342.524,,0.000000e+000,3.499754e+001,1.917460e-005,0.000000e+000,3,9.639633e-001,0.000000e+000,,,,,,,,,,,,,,32,1,4.000000e+000,7.896423e-004,0.000000e+000,0,,0,
1524503380.217,,0.000000e+000,3.499950e+001,1.918478e-005,0.000000e+000,3,9.641322e-001,0.000000e+000,,,,,,,,,,,,,,32,1,4.000000e+000,0.000000e+000,0.000000e+000,0,,0,
1524503418.587,,0.000000e+000,3.499911e+001,1.923599e-005,0.000000e+000,3,9.627071e-001,0.000000e+000,,,,,,,,,,,,,,32,1,4.000000e+000,7.820129e-004,0.000000e+000,0,,0,
1524503456.140,,0.000000e+000,3.499872e+001,1.927520e-005,0.000000e+000,3,9.640041e-001,0.000000e+000,,,,,,,,,,,,,,32,1,4.000000e+000,0.000000e+000,0.000000e+000,0,,0,
1524503494.208,,0.000000e+000,3.499872e+001,1.926711e-005,0.000000e+000,3,9.650560e-001,0.000000e+000,,,,,,,,,,,,,,32,1,4.000000e+000,1.560211e-003,0.000000e+000,0,,0,
1524503532.281,,0.000000e+000,3.499911e+001,1.928515e-005,0.000000e+000,3,9.641511e-001,0.000000e+000,,,,,,,,,,,,,,32,1,4.000000e+000,7.820129e-004,0.000000e+000,0,,0,
1524503570.314,,0.000000e+000,3.499989e+001,1.932241e-005,0.000000e+000,3,9.656160e-001,0.000000e+000,,,,,,,,,,,,,,32,1,4.000000e+000,7.781982e-004,0.000000e+000,0,,0,
1524503607.510,,0.000000e+000,3.499950e+001,1.937164e-005,0.000000e+000,3,9.634206e-001,0.000000e+000,,,,,,,,,,,,,,32,1,4.000000e+000,0.000000e+000,0.000000e+000,0,,0,
1524503645.786,,0.000000e+000,3.499793e+001,1.939749e-005,0.000000e+000,3,9.645367e-001,0.000000e+000,,,,,,,,,,,,,,32,1,4.000000e+000,1.567841e-003,0.000000e+000,0,,0,
1524503683.831,,0.000000e+000,3.500146e+001,1.932402e-005,0.000000e+000,3,9.663044e-001,0.000000e+000,,,,,,,,,,,,,,32,1,4.000000e+000,3.910065e-003,0.000000e+000,0,,0,
1524503721.802,,0.000000e+000,3.499989e+001,1.942718e-005,0.000000e+000,3,9.623564e-001,0.000000e+000,,,,,,,,,,,,,,32,1,4.000000e+000,7.781982e-004,0.000000e+000,0,,0,
1524503760.135,,0.000000e+000,3.499950e+001,1.944905e-005,0.000000e+000,3,9.655011e-001,0.000000e+000,,,,,,,,,,,,,,32,1,4.000000e+000,0.000000e+000,0.000000e+000,0,,0,
1524503797.508,,0.000000e+000,3.499950e+001,1.945881e-005,0.000000e+000,3,9.654549e-001,0.000000e+000,,,,,,,,,,,,,,32,1,4.000000e+000,0.000000e+000,0.000000e+000,0,,0,
1524503836.208,,0.000000e+000,3.499950e+001,1.947610e-005,0.000000e+000,3,9.636022e-001,0.000000e+000,,,,,,,,,,,,,,32,1,4.000000e+000,1.560211e-003,0.000000e+000,0,,0,
1524503874.246,,0.000000e+000,3.499950e+001,1.949157e-005,0.000000e+000,3,9.654073e-001,0.000000e+000,,,,,,,,,,,,,,32,1,4.000000e+000,0.000000e+000,0.000000e+000,0,,0,
1524503911.802,,0.000000e+000,3.499950e+001,1.951060e-005,0.000000e+000,3,9.648757e-001,0.000000e+000,,,,,,,,,,,,,,32,1,4.000000e+000,0.000000e+000,0.000000e+000,0,,0,
1524503963.250,,0.000000e+000,3.499911e+001,1.957983e-005,0.000000e+000,3,9.654540e-001,0.000000e+000,,,,,,,,,,,,,,32,1,4.000000e+000,7.820129e-004,0.000000e+000,0,,0,
1524504001.298,,0.000000e+000,3.499911e+001,1.958053e-005,0.000000e+000,3,9.634628e-001,0.000000e+000,,,,,,,,,,,,,,32,1,4.000000e+000,7.820129e-004,0.000000e+000,0,,0,
1524504039.444,,0.000000e+000,3.499989e+001,1.958588e-005,0.000000e+000,3,9.652780e-001,0.000000e+000,,,,,,,,,,,,,,32,1,4.000000e+000,7.781982e-004,0.000000e+000,0,,0,
1524504077.509,,0.000000e+000,3.499911e+001,1.961752e-005,0.000000e+000,3,9.641384e-001,0.000000e+000,,,,,,,,,,,,,,32,1,4.000000e+000,7.820129e-004,0.000000e+000,0,,0,
1524504115.497,,0.000000e+000,3.499872e+001,1.968306e-005,0.000000e+000,3,9.630634e-001,0.000000e+000,,,,,,,,,,,,,,32,1,4.000000e+000,1.560211e-003,0.000000e+000,0,,0,
1524504153.628,,0.000000e+000,3.499911e+001,1.960097e-005,0.000000e+000,3,9.648235e-001,0.000000e+000,,,,,,,,,,,,,,32,1,4.000000e+000,7.820129e-004,0.000000e+000,0,,0,
1524504191.619,,0.000000e+000,3.499950e+001,1.966917e-005,0.000000e+000,3,9.656346e-001,0.000000e+000,,,,,,,,,,,,,,32,1,4.000000e+000,0.000000e+000,0.000000e+000,0,,0,
1524504229.682,,0.000000e+000,3.499950e+001,1.966892e-005,0.000000e+000,3,9.665089e-001,0.000000e+000,,,,,,,,,,,,,,32,1,4.000000e+000,0.000000e+000,0.000000e+000,0,,0,
1524504267.762,,0.000000e+000,3.499911e+001,1.967742e-005,0.000000e+000,3,9.665316e-001,0.000000e+000,,,,,,,,,,,,,,32,1,4.000000e+000,7.820129e-004,0.000000e+000,0,,0,
1524504305.878,,0.000000e+000,3.499911e+001,1.971104e-005,0.000000e+000,3,9.648001e-001,0.000000e+000,,,,,,,,,,,,,,32,1,4.000000e+000,7.820129e-004,0.000000e+000,0,,0,
1524504343.931,,0.000000e+000,3.499911e+001,1.976414e-005,0.000000e+000,3,9.654749e-001,0.000000e+000,,,,,,,,,,,,,,32,1,4.000000e+000,7.820129e-004,0.000000e+000,0,,0,
1524504382.004,,0.000000e+000,3.499911e+001,1.977859e-005,0.000000e+000,3,9.655448e-001,0.000000e+000,,,,,,,,,,,,,,32,1,4.000000e+000,7.820129e-004,0.000000e+000,0,,0,
1524504419.597,,0.000000e+000,3.499950e+001,1.975408e-005,0.000000e+000,3,9.645666e-001,0.000000e+000,,,,,,,,,,,,,,32,1,4.000000e+000,0.000000e+000,0.000000e+000,0,,0,
1524504457.527,,0.000000e+000,3.499911e+001,1.989868e-005,0.000000e+000,3,9.655170e-001,0.000000e+000,,,,,,,,,,,,,,32,1,4.000000e+000,7.820129e-004,0.000000e+000,0,,0,
1524504495.605,,0.000000e+000,3.499872e+001,1.978537e-005,0.000000e+000,3,9.662610e-001,0.000000e+000,,,,,,,,,,,,,,32,1,4.000000e+000,1.560211e-003,0.000000e+000,0,,0,
1524504533.674,,0.000000e+000,3.499872e+001,1.981910e-005,0.000000e+000,3,9.661570e-001,0.000000e+000,,,,,,,,,,,,,,32,1,4.000000e+000,1.560211e-003,0.000000e+000,0,,0,
1524504571.292,,0.000000e+000,3.499950e+001,1.986536e-005,0.000000e+000,3,9.656057e-001,0.000000e+000,,,,,,,,,,,,,,32,1,4.000000e+000,1.560211e-003,0.000000e+000,0,,0,
1524504609.805,,0.000000e+000,3.499911e+001,1.987267e-005,0.000000e+000,3,9.649630e-001,0.000000e+000,,,,,,,,,,,,,,32,1,4.000000e+000,7.820129e-004,0.000000e+000,0,,0,
1524504647.423,,0.000000e+000,3.499911e+001,1.983444e-005,0.000000e+000,3,9.655941e-001,0.000000e+000,,,,,,,,,,,,,,32,1,4.000000e+000,7.820129e-004,0.000000e+000,0,,0,
1524504685.386,,0.000000e+000,3.499950e+001,1.989636e-005,0.000000e+000,3,9.659550e-001,0.000000e+000,,,,,,,,,,,,,,32,1,4.000000e+000,0.000000e+000,0.000000e+000,0,,0,
1524504723.301,,0.000000e+000,3.499950e+001,1.995080e-005,0.000000e+000,3,9.665273e-001,0.000000e+000,,,,,,,,,,,,,,32,1,4.000000e+000,1.560211e-003,0.000000e+000,0,,0,
1524504761.944,,0.000000e+000,3.499872e+001,1.996838e-005,0.000000e+000,3,9.665477e-001,0.000000e+000,,,,,,,,,,,,,,32,1,4.000000e+000,0.000000e+000,0.000000e+000,0,,0,
1524504799.967,,0.000000e+000,3.499911e+001,2.000402e-005,0.000000e+000,3,9.648103e-001,0.000000e+000,,,,,,,,,,,,,,32,1,4.000000e+000,7.820129e-004,0.000000e+000,0,,0,
1524504851.448,,0.000000e+000,3.499872e+001,1.997994e-005,0.000000e+000,3,9.671279e-001,0.000000e+000,,,,,,,,,,,,,,32,1,4.000000e+000,0.000000e+000,0.000000e+000,0,,0,
1524504889.424,,0.000000e+000,3.500028e+001,1.999805e-005,0.000000e+000,3,9.661272e-001,0.000000e+000,,,,,,,,,,,,,,32,1,4.000000e+000,0.000000e+000,0.000000e+000,0,,0,
1524504927.524,,0.000000e+000,3.499989e+001,2.001180e-005,0.000000e+000,3,9.679232e-001,0.000000e+000,,,,,,,,,,,,,,32,1,4.000000e+000,7.781982e-004,0.000000e+000,0,,0,
1524504965.935,,0.000000e+000,3.499950e+001,2.008782e-005,0.000000e+000,3,9.682280e-001,0.000000e+000,,,,,,,,,,,,,,32,1,4.000000e+000,0.000000e+000,0.000000e+000,0,,0,
1524505004.035,,0.000000e+000,3.499989e+001,2.010506e-005,0.000000e+000,3,9.657863e-001,0.000000e+000,,,,,,,,,,,,,,32,1,4.000000e+000,2.342224e-003,0.000000e+000,0,,0,
1524505041.941,,0.000000e+000,3.500028e+001,2.007499e-005,0.000000e+000,3,9.657700e-001,0.000000e+000,,,,,,,,,,,,,,32,1,4.000000e+000,0.000000e+000,0.000000e+000,0,,0,
1524505079.994,,0.000000e+000,3.499989e+001,2.011069e-005,0.000000e+000,3,9.663085e-001,0.000000e+000,,,,,,,,,,,,,,32,1,4.000000e+000,7.781982e-004,0.000000e+000,0,,0,
1524505118.190,,0.000000e+000,3.499950e+001,2.012874e-005,0.000000e+000,3,9.654773e-001,0.000000e+000,,,,,,,,,,,,,,32,1,4.000000e+000,0.000000e+000,0.000000e+000,0,,0,
1524505156.230,,0.000000e+000,3.499833e+001,2.012999e-005,0.000000e+000,3,9.659677e-001,0.000000e+000,,,,,,,,,,,,,,32,1,4.000000e+000,7.781982e-004,0.000000e+000,0,,0,
1524505194.443,,0.000000e+000,3.499989e+001,2.014479e-005,0.000000e+000,3,9.656126e-001,0.000000e+000,,,,,,,,,,,,,,32,1,4.000000e+000,7.781982e-004,0.000000e+000,0,,0,
1524505232.404,,0.000000e+000,3.499989e+001,2.015324e-005,0.000000e+000,3,9.662408e-001,0.000000e+000,,,,,,,,,,,,,,32,1,4.000000e+000,7.781982e-004,0.000000e+000,0,,0,
1524505270.424,,0.000000e+000,3.499911e+001,2.013868e-005,0.000000e+000,3,9.680613e-001,0.000000e+000,,,,,,,,,,,,,,32,1,4.000000e+000,7.820129e-004,0.000000e+000,0,,0,
1524505308.527,,0.000000e+000,3.499911e+001,2.015173e-005,0.000000e+000,3,9.692307e-001,0.000000e+000,,,,,,,,,,,,,,32,1,4.000000e+000,7.820129e-004,0.000000e+000,0,,0,
1524505346.593,,0.000000e+000,3.499911e+001,2.029143e-005,0.000000e+000,3,9.649397e-001,0.000000e+000,,,,,,,,,,,,,,32,1,4.000000e+000,7.820129e-004,0.000000e+000,0,,0,
1524505384.676,,0.000000e+000,3.499911e+001,2.023562e-005,0.000000e+000,3,9.650511e-001,0.000000e+000,,,,,,,,,,,,,,32,1,4.000000e+000,7.820129e-004,0.000000e+000,0,,0,
1524505422.724,,0.000000e+000,3.499911e+001,2.020025e-005,0.000000e+000,3,9.670420e-001,0.000000e+000,,,,,,,,,,,,,,32,1,4.000000e+000,7.820129e-004,0.000000e+000,0,,0,
1524505460.782,,0.000000e+000,3.499833e+001,2.023431e-005,0.000000e+000,3,9.676883e-001,0.000000e+000,,,,,,,,,,,,,,32,1,4.000000e+000,7.781982e-004,0.000000e+000,0,,0,
1524505498.850,,0.000000e+000,3.499950e+001,2.025802e-005,0.000000e+000,3,9.654794e-001,0.000000e+000,,,,,,,,,,,,,,32,1,4.000000e+000,0.000000e+000,0.000000e+000,0,,0,
1524505537.448,,0.000000e+000,3.499911e+001,2.028833e-005,0.000000e+000,3,9.662423e-001,0.000000e+000,,,,,,,,,,,,,,32,1,4.000000e+000,7.820129e-004,0.000000e+000,0,,0,
1524505575.051,,0.000000e+000,3.499950e+001,2.029226e-005,0.000000e+000,3,9.667816e-001,0.000000e+000,,,,,,,,,,,,,,32,1,4.000000e+000,0.000000e+000,0.000000e+000,0,,0,
1524505613.034,,0.000000e+000,3.499872e+001,2.026765e-005,0.000000e+000,3,9.674779e-001,0.000000e+000,,,,,,,,,,,,,,32,1,4.000000e+000,0.000000e+000,0.000000e+000,0,,0,
1524505651.105,,0.000000e+000,3.499989e+001,2.036083e-005,0.000000e+000,3,9.676442e-001,0.000000e+000,,,,,,,,,,,,,,32,1,4.000000e+000,7.781982e-004,0.000000e+000,0,,0,
1524505689.168,,0.000000e+000,3.499911e+001,2.032597e-005,0.000000e+000,3,9.664895e-001,0.000000e+000,,,,,,,,,,,,,,32,1,4.000000e+000,7.820129e-004,0.000000e+000,0,,0,
1524505727.749,,0.000000e+000,3.499911e+001,2.030406e-005,0.000000e+000,3,9.654704e-001,0.000000e+000,,,,,,,,,,,,,,32,1,4.000000e+000,7.820129e-004,0.000000e+000,0,,0,
1524505778.724,,0.000000e+000,3.499911e+001,2.042311e-005,0.000000e+000,3,9.682621e-001,0.000000e+000,,,,,,,,,,,,,,32,1,4.000000e+000,7.820129e-004,0.000000e+000,0,,0,
1524505816.737,,0.000000e+000,3.499833e+001,2.035212e-005,0.000000e+000,3,9.659014e-001,0.000000e+000,,,,,,,,,,,,,,32,1,4.000000e+000,7.781982e-004,0.000000e+000,0,,0,
1524505854.803,,0.000000e+000,3.499872e+001,2.036764e-005,0.000000e+000,3,9.660529e-001,0.000000e+000,,,,,,,,,,,,,,32,1,4.000000e+000,1.560211e-003,0.000000e+000,0,,0,
1524505892.783,,0.000000e+000,3.499950e+001,2.044157e-005,0.000000e+000,3,9.664694e-001,0.000000e+000,,,,,,,,,,,,,,32,1,4.000000e+000,0.000000e+000,0.000000e+000,0,,0,
1524505930.851,,0.000000e+000,3.499989e+001,2.035657e-005,0.000000e+000,3,9.653785e-001,0.000000e+000,,,,,,,,,,,,,,32,1,4.000000e+000,7.781982e-004,0.000000e+000,0,,0,
1524505969.775,,0.000000e+000,3.499989e+001,2.044419e-005,0.000000e+000,3,9.661388e-001,0.000000e+000,,,,,,,,,,,,,,32,1,4.000000e+000,7.781982e-004,0.000000e+000,0,,0,
1524506008.428,,0.000000e+000,3.499833e+001,2.041480e-005,0.000000e+000,3,9.694466e-001,0.000000e+000,,,,,,,,,,,,,,32,1,4.000000e+000,7.781982e-004,0.000000e+000,0,,0,
1524506046.453,,0.000000e+000,3.499833e+001,2.043348e-005,0.000000e+000,3,9.649307e-001,0.000000e+000,,,,,,,,,,,,,,32,1,4.000000e+000,7.781982e-004,0.000000e+000,0,,0,
1524506083.934,,0.000000e+000,3.499950e+001,2.042597e-005,0.000000e+000,3,9.669301e-001,0.000000e+000,,,,,,,,,,,,,,32,1,4.000000e+000,1.560211e-003,0.000000e+000,0,,0,
1524506122.597,,0.000000e+000,3.499833e+001,2.047463e-005,0.000000e+000,3,9.654440e-001,0.000000e+000,,,,,,,,,,,,,,32,1,4.000000e+000,7.781982e-004,0.000000e+000,0,,0,
1524506159.585,,0.000000e+000,3.499989e+001,2.039633e-005,0.000000e+000,3,9.681293e-001,0.000000e+000,,,,,,,,,,,,,,32,1,4.000000e+000,7.781982e-004,0.000000e+000,0,,0,
1524506197.648,,0.000000e+000,3.499950e+001,2.048330e-005,0.000000e+000,3,9.646524e-001,0.000000e+000,,,,,,,,,,,,,,32,1,4.000000e+000,0.000000e+000,0.000000e+000,0,,0,
1524506235.689,,0.000000e+000,3.499989e+001,2.045907e-005,0.000000e+000,3,9.676331e-001,0.000000e+000,,,,,,,,,,,,,,32,1,4.000000e+000,7.781982e-004,0.000000e+000,0,,0,
1524506273.497,,0.000000e+000,3.499911e+001,2.059003e-005,0.000000e+000,3,9.659159e-001,0.000000e+000,,,,,,,,,,,,,,32,1,4.000000e+000,7.820129e-004,0.000000e+000,0,,0,
1524506311.760,,0.000000e+000,3.499911e+001,2.050694e-005,0.000000e+000,3,9.706420e-001,0.000000e+000,,,,,,,,,,,,,,32,1,4.000000e+000,7.820129e-004,0.000000e+000,0,,0,
1524506349.805,,0.000000e+000,3.499911e+001,2.059444e-005,0.000000e+000,3,9.673570e-001,0.000000e+000,,,,,,,,,,,,,,32,1,4.000000e+000,7.820129e-004,0.000000e+000,0,,0,
1524506387.868,,0.000000e+000,3.499950e+001,2.061177e-005,0.000000e+000,3,9.638943e-001,0.000000e+000,,,,,,,,,,,,,,32,1,4.000000e+000,0.000000e+000,0.000000e+000,0,,0,
1524506425.419,,0.000000e+000,3.499833e+001,2.058903e-005,0.000000e+000,3,9.666962e-001,0.000000e+000,,,,,,,,,,,,,,32,1,4.000000e+000,2.349854e-003,0.000000e+000,0,,0,
1524506463.504,,0.000000e+000,3.499950e+001,2.063881e-005,0.000000e+000,3,9.644573e-001,0.000000e+000,,,,,,,,,,,,,,32,1,4.000000e+000,1.560211e-003,0.000000e+000,0,,0,
1524506501.317,,0.000000e+000,3.500028e+001,2.057708e-005,0.000000e+000,3,9.681126e-001,0.000000e+000,,,,,,,,,,,,,,32,1,4.000000e+000,1.560211e-003,0.000000e+000,0,,0,
1524506539.045,,0.000000e+000,3.499911e+001,2.063742e-005,0.000000e+000,3,9.680184e-001,0.000000e+000,,,,,,,,,,,,,,32,1,4.000000e+000,7.820129e-004,0.000000e+000,0,,0,
1524506577.016,,0.000000e+000,3.499872e+001,2.065587e-005,0.000000e+000,3,9.677674e-001,0.000000e+000,,,,,,,,,,,,,,32,1,4.000000e+000,0.000000e+000,0.000000e+000,0,,0,
1524506615.074,,0.000000e+000,3.499911e+001,2.069983e-005,0.000000e+000,3,9.680684e-001,0.000000e+000,,,,,,,,,,,,,,32,1,4.000000e+000,7.820129e-004,0.000000e+000,0,,0,
1524506653.280,,0.000000e+000,3.499832e+001,2.065923e-005,0.000000e+000,3,9.674421e-001,0.000000e+000,,,,,,,,,,,,,,32,1,4.000000e+000,3.910065e-003,0.000000e+000,0,,0,
1524506704.800,,0.000000e+000,3.499911e+001,2.061754e-005,0.000000e+000,3,9.671442e-001,0.000000e+000,,,,,,,,,,,,,,32,1,4.000000e+000,7.820129e-004,0.000000e+000,0,,0,
1524506742.841,,0.000000e+000,3.499989e+001,2.070254e-005,0.000000e+000,3,9.640057e-001,0.000000e+000,,,,,,,,,,,,,,32,1,4.000000e+000,7.781982e-004,0.000000e+000,0,,0,
1524506780.811,,0.000000e+000,3.499950e+001,2.068958e-005,0.000000e+000,3,9.711909e-001,0.000000e+000,,,,,,,,,,,,,,32,1,4.000000e+000,0.000000e+000,0.000000e+000,0,,0,
1524506818.950,,0.000000e+000,3.499950e+001,2.065951e-005,0.000000e+000,3,9.696155e-001,0.000000e+000,,,,,,,,,,,,,,32,1,4.000000e+000,0.000000e+000,0.000000e+000,0,,0,
1524506857.015,,0.000000e+000,3.499911e+001,2.066239e-005,0.000000e+000,3,9.681242e-001,0.000000e+000,,,,,,,,,,,,,,32,1,4.000000e+000,7.820129e-004,0.000000e+000,0,,0,
1524506895.808,,0.000000e+000,3.499950e+001,2.069003e-005,0.000000e+000,3,9.668394e-001,0.000000e+000,,,,,,,,,,,,,,32,1,4.000000e+000,1.560211e-003,0.000000e+000,0,,0,
1524506933.816,,0.000000e+000,3.499911e+001,2.075042e-005,0.000000e+000,3,9.688107e-001,0.000000e+000,,,,,,,,,,,,,,32,1,4.000000e+000,7.820129e-004,0.000000e+000,0,,0,
1524506972.004,,0.000000e+000,3.499950e+001,2.077334e-005,0.000000e+000,3,9.668984e-001,0.000000e+000,,,,,,,,,,,,,,32,1,4.000000e+000,0.000000e+000,0.000000e+000,0,,0,
1524507009.735,,0.000000e+000,3.499989e+001,2.074433e-005,0.000000e+000,3,9.682981e-001,0.000000e+000,,,,,,,,,,,,,,32,1,4.000000e+000,7.781982e-004,0.000000e+000,0,,0,
1524507048.898,,0.000000e+000,3.499911e+001,2.073929e-005,0.000000e+000,3,9.661145e-001,0.000000e+000,,,,,,,,,,,,,,32,1,4.000000e+000,7.820129e-004,0.000000e+000,0,,0,
1524507086.896,,0.000000e+000,3.499989e+001,2.074608e-005,0.000000e+000,3,9.658054e-001,0.000000e+000,,,,,,,,,,,,,,32,1,4.000000e+000,7.781982e-004,0.000000e+000,0,,0,
1524507124.509,,0.000000e+000,3.499950e+001,2.084337e-005,0.000000e+000,3,9.650559e-001,0.000000e+000,,,,,,,,,,,,,,32,1,4.000000e+000,0.000000e+000,0.000000e+000,0,,0,
1524507162.555,,0.000000e+000,3.499833e+001,2.080760e-005,0.000000e+000,3,9.670178e-001,0.000000e+000,,,,,,,,,,,,,,32,1,4.000000e+000,7.781982e-004,0.000000e+000,0,,0,
1524507201.075,,0.000000e+000,3.499911e+001,2.074474e-005,0.000000e+000,3,9.670156e-001,0.000000e+000,,,,,,,,,,,,,,32,1,4.000000e+000,7.820129e-004,0.000000e+000,0,,0,
1524507238.681,,0.000000e+000,3.499911e+001,2.085854e-005,0.000000e+000,3,9.688570e-001,0.000000e+000,,,,,,,,,,,,,,32,1,4.000000e+000,7.820129e-004,0.000000e+000,0,,0,
1524507277.201,,0.000000e+000,3.499911e+001,2.084529e-005,0.000000e+000,3,9.668788e-001,0.000000e+000,,,,,,,,,,,,,,32,1,4.000000e+000,7.820129e-004,0.000000e+000,0,,0,
1524507314.709,,0.000000e+000,3.499989e+001,2.084953e-005,0.000000e+000,3,9.663721e-001,0.000000e+000,,,,,,,,,,,,,,32,1,4.000000e+000,7.781982e-004,0.000000e+000,0,,0,
1524507353.095,,0.000000e+000,3.499872e+001,2.087404e-005,0.000000e+000,3,9.678575e-001,0.000000e+000,,,,,,,,,,,,,,32,1,4.000000e+000,1.560211e-003,0.000000e+000,0,,0,
1524507391.335,,0.000000e+000,3.499911e+001,2.094044e-005,0.000000e+000,3,9.680042e-001,0.000000e+000,,,,,,,,,,,,,,32,1,4.000000e+000,7.820129e-004,0.000000e+000,0,,0,
1524507429.251,,0.000000e+000,3.499950e+001,2.090651e-005,0.000000e+000,3,9.668574e-001,0.000000e+000,,,,,,,,,,,,,,32,1,4.000000e+000,0.000000e+000,0.000000e+000,0,,0,
1524507467.794,,0.000000e+000,3.499950e+001,2.092584e-005,0.000000e+000,3,9.667140e-001,0.000000e+000,,,,,,,,,,,,,,32,1,4.000000e+000,0.000000e+000,0.000000e+000,0,,0,
1524507505.845,,0.000000e+000,3.500028e+001,2.090793e-005,0.000000e+000,3,9.680903e-001,0.000000e+000,,,,,,,,,,,,,,32,1,4.000000e+000,0.000000e+000,0.000000e+000,0,,0,
1524507543.405,,0.000000e+000,3.499872e+001,2.101671e-005,0.000000e+000,3,9.685664e-001,0.000000e+000,,,,,,,,,,,,,,32,1,4.000000e+000,0.000000e+000,0.000000e+000,0,,0,
1524507581.503,,0.000000e+000,3.499950e+001,2.094468e-005,0.000000e+000,3,9.675574e-001,0.000000e+000,,,,,,,,,,,,,,32,1,4.000000e+000,0.000000e+000,0.000000e+000,0,,0,
1524507633.011,,0.000000e+000,3.499911e+001,2.094452e-005,0.000000e+000,3,9.689163e-001,0.000000e+000,,,,,,,,,,,,,,32,1,4.000000e+000,7.820129e-004,0.000000e+000,0,,0,
1524507671.057,,0.000000e+000,3.499989e+001,2.095066e-005,0.000000e+000,3,9.673958e-001,0.000000e+000,,,,,,,,,,,,,,32,1,4.000000e+000,7.781982e-004,0.000000e+000,0,,0,
1524507709.558,,0.000000e+000,3.499950e+001,2.097911e-005,0.000000e+000,3,9.680718e-001,0.000000e+000,,,,,,,,,,,,,,32,1,4.000000e+000,0.000000e+000,0.000000e+000,0,,0,
1524507747.171,,0.000000e+000,3.499872e+001,2.097099e-005,0.000000e+000,3,9.691659e-001,0.000000e+000,,,,,,,,,,,,,,32,1,4.000000e+000,0.000000e+000,0.000000e+000,0,,0,
1524507785.239,,0.000000e+000,3.499989e+001,2.094871e-005,0.000000e+000,3,9.654790e-001,0.000000e+000,,,,,,,,,,,,,,32,1,4.000000e+000,7.781982e-004,0.000000e+000,0,,0,
1524507823.207,,0.000000e+000,3.499911e+001,2.096964e-005,0.000000e+000,3,9.671886e-001,0.000000e+000,,,,,,,,,,,,,,32,1,4.000000e+000,7.820129e-004,0.000000e+000,0,,0,
1524507860.897,,0.000000e+000,3.499950e+001,2.098625e-005,0.000000e+000,3,9.656346e-001,0.000000e+000,,,,,,,,,,,,,,32,1,4.000000e+000,0.000000e+000,0.000000e+000,0,,0,
1524507899.318,,0.000000e+000,3.499872e+001,2.103068e-005,0.000000e+000,3,9.682943e-001,0.000000e+000,,,,,,,,,,,,,,32,1,4.000000e+000,0.000000e+000,0.000000e+000,0,,0,
1524507936.921,,0.000000e+000,3.499989e+001,2.100530e-005,0.000000e+000,3,9.661190e-001,0.000000e+000,,,,,,,,,,,,,,32,1,4.000000e+000,7.781982e-004,0.000000e+000,0,,0,
1524507975.034,,0.000000e+000,3.499950e+001,2.106773e-005,0.000000e+000,3,9.688012e-001,0.000000e+000,,,,,,,,,,,,,,32,1,4.000000e+000,0.000000e+000,0.000000e+000,0,,0,
1524508012.417,,0.000000e+000,3.500028e+001,2.103516e-005,0.000000e+000,3,9.699461e-001,0.000000e+000,,,,,,,,,,,,,,32,1,4.000000e+000,1.560211e-003,0.000000e+000,0,,0,
1524508050.433,,0.000000e+000,3.499950e+001,2.105466e-005,0.000000e+000,3,9.664411e-001,0.000000e+000,,,,,,,,,,,,,,32,1,4.000000e+000,3.120422e-003,0.000000e+000,0,,0,
1524508088.353,,0.000000e+000,3.499950e+001,2.102886e-005,0.000000e+000,3,9.665698e-001,0.000000e+000,,,,,,,,,,,,,,32,1,4.000000e+000,1.560211e-003,0.000000e+000,0,,0,
1524508125.964,,0.000000e+000,3.499989e+001,2.112166e-005,0.000000e+000,3,9.685026e-001,0.000000e+000,,,,,,,,,,,,,,32,1,4.000000e+000,2.342224e-003,0.000000e+000,0,,0,
1524508163.957,,0.000000e+000,3.499872e+001,2.111213e-005,0.000000e+000,3,9.681270e-001,0.000000e+000,,,,,,,,,,,,,,32,1,4.000000e+000,1.560211e-003,0.000000e+000,0,,0,
1524508202.042,,0.000000e+000,3.499872e+001,2.111086e-005,0.000000e+000,3,9.665970e-001,0.000000e+000,,,,,,,,,,,,,,32,1,4.000000e+000,1.560211e-003,0.000000e+000,0,,0,
1524508241.290,,0.000000e+000,3.499911e+001,2.110207e-005,0.000000e+000,3,9.675128e-001,0.000000e+000,,,,,,,,,,,,,,32,1,4.000000e+000,7.820129e-004,0.000000e+000,0,,0,
1524508279.408,,0.000000e+000,3.499872e+001,2.110527e-005,0.000000e+000,3,9.669008e-001,0.000000e+000,,,,,,,,,,,,,,32,1,4.000000e+000,1.560211e-003,0.000000e+000,0,,0,
1524508317.462,,0.000000e+000,3.499950e+001,2.109176e-005,0.000000e+000,3,9.669181e-001,0.000000e+000,,,,,,,,,,,,,,32,1,4.000000e+000,1.560211e-003,0.000000e+000,0,,0,
1524508355.465,,0.000000e+000,3.499989e+001,2.109213e-005,0.000000e+000,3,9.688618e-001,0.000000e+000,,,,,,,,,,,,,,32,1,4.000000e+000,7.781982e-004,0.000000e+000,0,,0,
1524508393.068,,0.000000e+000,3.499833e+001,2.120986e-005,0.000000e+000,3,9.679098e-001,0.000000e+000,,,,,,,,,,,,,,32,1,4.000000e+000,7.781982e-004,0.000000e+000,0,,0,
1524508431.046,,0.000000e+000,3.499989e+001,2.114580e-005,0.000000e+000,3,9.679691e-001,0.000000e+000,,,,,,,,,,,,,,32,1,4.000000e+000,7.781982e-004,0.000000e+000,0,,0,
1524508469.084,,0.000000e+000,3.499989e+001,2.118600e-005,0.000000e+000,3,9.666660e-001,0.000000e+000,,,,,,,,,,,,,,32,1,4.000000e+000,7.781982e-004,0.000000e+000,0,,0,
1524508507.637,,0.000000e+000,3.499950e+001,2.126619e-005,0.000000e+000,3,9.691613e-001,0.000000e+000,,,,,,,,,,,,,,32,1,4.000000e+000,0.000000e+000,0.000000e+000,0,,0,