File: Experimental Raw Data/MFn1 VRM/Adjusting Iterative/MFn1_VRMac_34K_6000s_VRMde_35K.dc.dat
[Header]
TITLE,MPMS DC Measurement
BYAPP,MPMS Measurement,2.1,Summary
FILEOPENTIME, 1524263121.777000 4/20/2018, 4:25:21 PM

INFO, APPNAME, MPMS MultiVu Application, Revision 1.61,  Build 082

INFO, NAME, MFn1
INFO, WEIGHT, 1.000
INFO, AREA, 1.000
INFO, LENGTH, 1.000
INFO, SHAPE, 0
INFO, COMMENT,
INFO, SEQUENCE FILE: VRMac_34K_6000s_VRMde_35K.seq


INFO, BACKGROUND DATA FILE:, None


STARTUPAXIS,X,4,LINEAR,AUTO,0.000000,0.000000
STARTUPAXIS,Y1,5,LINEAR,AUTO,0.000000,0.000000


STARTUPGROUP,Longitudinal
FIELDGROUP,Longitudinal,1,2,3,4,5,6,7,8,9,15,16,17,18,27,28
FIELDGROUP,Transverse,1,2,3,4,10,11,12,13,14,19,20,21,22,27,28

PLOT_APPEARANCE,ALL,HORZ_GRID_ON,VERT_GRID_ON,MARKERS_AND_LINES

[Data]
Time,Comment,Field (Oe),Temperature (K),Long Moment (emu),Long Scan Std Dev,Long Algorithm,Long Reg Fit,Long Percent Error (%),Trans Moment (emu),Trans Scan Std Dev,Trans Algorithm,Trans Reg Fit,Trans Percent Error (%),Long Moment [w/o ABS] (emu),Long Scan Std Dev [w/o ABS],Long Reg Fit [w/o ABS],Long Percent Error [w/o ABS] (%),Trans Moment [w/o ABS] (emu),Trans Scan Std Dev [w/o ABS],Trans Reg Fit [w/o ABS],Trans Percent Error [w/o ABS] (%),Points per Scan,Scans per Measurement,Scan Length (cm),Delta Temp (K),Rot Position (deg),Error,EC Comp. Running,Using ABS,
1524434639.394,,0.000000e+000,3.500420e+001,-8.594120e-006,0.000000e+000,3,9.183959e-001,0.000000e+000,,,,,,,,,,,,,,32,1,4.000000e+000,1.567841e-003,0.000000e+000,0,,0,
1524434677.957,,0.000000e+000,3.500145e+001,-7.236259e-006,0.000000e+000,3,9.070360e-001,0.000000e+000,,,,,,,,,,,,,,32,1,4.000000e+000,2.349854e-003,0.000000e+000,0,,0,
1524434716.007,,0.000000e+000,3.499989e+001,-6.155438e-006,0.000000e+000,3,8.841596e-001,0.000000e+000,,,,,,,,,,,,,,32,1,4.000000e+000,7.781982e-004,0.000000e+000,0,,0,
1524434754.110,,0.000000e+000,3.500028e+001,-5.335045e-006,0.000000e+000,3,8.660623e-001,0.000000e+000,,,,,,,,,,,,,,32,1,4.000000e+000,0.000000e+000,0.000000e+000,0,,0,
1524434792.181,,0.000000e+000,3.499989e+001,-4.595344e-006,0.000000e+000,3,8.512068e-001,0.000000e+000,,,,,,,,,,,,,,32,1,4.000000e+000,2.342224e-003,0.000000e+000,0,,0,
1524434829.532,,0.000000e+000,3.499911e+001,-3.998122e-006,0.000000e+000,3,8.247035e-001,0.000000e+000,,,,,,,,,,,,,,32,1,4.000000e+000,2.338409e-003,0.000000e+000,0,,0,
1524434867.947,,0.000000e+000,3.500146e+001,-3.473908e-006,0.000000e+000,3,8.063951e-001,0.000000e+000,,,,,,,,,,,,,,32,1,4.000000e+000,3.910065e-003,0.000000e+000,0,,0,
1524434905.900,,0.000000e+000,3.499911e+001,-3.012992e-006,0.000000e+000,3,7.636894e-001,0.000000e+000,,,,,,,,,,,,,,32,1,4.000000e+000,7.820129e-004,0.000000e+000,0,,0,
1524434943.953,,0.000000e+000,3.499911e+001,-2.529250e-006,0.000000e+000,3,7.386326e-001,0.000000e+000,,,,,,,,,,,,,,32,1,4.000000e+000,7.820129e-004,0.000000e+000,0,,0,
1524434981.739,,0.000000e+000,3.499911e+001,-2.239608e-006,0.000000e+000,3,6.748178e-001,0.000000e+000,,,,,,,,,,,,,,32,1,4.000000e+000,7.820129e-004,0.000000e+000,0,,0,
1524435019.247,,0.000000e+000,3.499872e+001,-1.872610e-006,0.000000e+000,3,6.076986e-001,0.000000e+000,,,,,,,,,,,,,,32,1,4.000000e+000,0.000000e+000,0.000000e+000,0,,0,
1524435056.960,,0.000000e+000,3.499989e+001,-1.559080e-006,0.000000e+000,3,5.201138e-001,0.000000e+000,,,,,,,,,,,,,,32,1,4.000000e+000,2.342224e-003,0.000000e+000,0,,0,
1524435095.055,,0.000000e+000,3.499872e+001,-1.304574e-006,0.000000e+000,3,4.565093e-001,0.000000e+000,,,,,,,,,,,,,,32,1,4.000000e+000,1.560211e-003,0.000000e+000,0,,0,
1524435132.813,,0.000000e+000,3.499911e+001,-1.070960e-006,0.000000e+000,3,3.412414e-001,0.000000e+000,,,,,,,,,,,,,,32,1,4.000000e+000,7.820129e-004,0.000000e+000,0,,0,
1524435170.749,,0.000000e+000,3.499872e+001,-9.089012e-007,0.000000e+000,3,1.628171e-001,0.000000e+000,,,,,,,,,,,,,,32,1,4.000000e+000,1.560211e-003,0.000000e+000,0,,0,
1524435208.257,,0.000000e+000,3.499989e+001,-7.323943e-007,0.000000e+000,3,0.000000e+000,0.000000e+000,,,,,,,,,,,,,,32,1,4.000000e+000,7.781982e-004,0.000000e+000,0,,0,
1524435246.478,,0.000000e+000,3.499950e+001,5.847426e-007,0.000000e+000,3,0.000000e+000,0.000000e+000,,,,,,,,,,,,,,32,1,4.000000e+000,0.000000e+000,0.000000e+000,0,,0,
1524435286.409,,0.000000e+000,3.499872e+001,6.899693e-007,0.000000e+000,3,0.000000e+000,0.000000e+000,,,,,,,,,,,,,,32,1,4.000000e+000,0.000000e+000,0.000000e+000,0,,0,
1524435325.608,,0.000000e+000,3.499833e+001,-2.405822e-007,0.000000e+000,3,0.000000e+000,0.000000e+000,,,,,,,,,,,,,,32,1,4.000000e+000,2.349854e-003,0.000000e+000,0,,0,
1524435366.573,,0.000000e+000,3.499989e+001,9.696794e-007,0.000000e+000,3,3.677154e-001,0.000000e+000,,,,,,,,,,,,,,32,1,4.000000e+000,7.781982e-004,0.000000e+000,0,,0,
1524435405.957,,0.000000e+000,3.499872e+001,9.807783e-007,0.000000e+000,3,3.530734e-001,0.000000e+000,,,,,,,,,,,,,,32,1,4.000000e+000,1.560211e-003,0.000000e+000,0,,0,
1524435444.052,,0.000000e+000,3.499872e+001,1.060081e-006,0.000000e+000,3,3.742983e-001,0.000000e+000,,,,,,,,,,,,,,32,1,4.000000e+000,1.560211e-003,0.000000e+000,0,,0,
1524435482.053,,0.000000e+000,3.500028e+001,1.137564e-006,0.000000e+000,3,4.330505e-001,0.000000e+000,,,,,,,,,,,,,,32,1,4.000000e+000,0.000000e+000,0.000000e+000,0,,0,
1524435520.046,,0.000000e+000,3.499794e+001,1.259295e-006,0.000000e+000,3,4.658680e-001,0.000000e+000,,,,,,,,,,,,,,32,1,4.000000e+000,0.000000e+000,0.000000e+000,0,,0,
1524435571.444,,0.000000e+000,3.500028e+001,1.238710e-006,0.000000e+000,3,5.089307e-001,0.000000e+000,,,,,,,,,,,,,,32,1,4.000000e+000,0.000000e+000,0.000000e+000,0,,0,
1524435609.515,,0.000000e+000,3.499989e+001,1.403237e-006,0.000000e+000,3,5.472533e-001,0.000000e+000,,,,,,,,,,,,,,32,1,4.000000e+000,7.781982e-004,0.000000e+000,0,,0,
1524435647.478,,0.000000e+000,3.499833e+001,1.553208e-006,0.000000e+000,3,5.581272e-001,0.000000e+000,,,,,,,,,,,,,,32,1,4.000000e+000,2.349854e-003,0.000000e+000,0,,0,
1524435684.488,,0.000000e+000,3.499950e+001,1.564863e-006,0.000000e+000,3,5.141278e-001,0.000000e+000,,,,,,,,,,,,,,32,1,4.000000e+000,0.000000e+000,0.000000e+000,0,,0,
1524435721.814,,0.000000e+000,3.499872e+001,1.764064e-006,0.000000e+000,3,6.350059e-001,0.000000e+000,,,,,,,,,,,,,,32,1,4.000000e+000,0.000000e+000,0.000000e+000,0,,0,
1524435759.222,,0.000000e+000,3.499833e+001,1.840161e-006,0.000000e+000,3,6.346438e-001,0.000000e+000,,,,,,,,,,,,,,32,1,4.000000e+000,2.349854e-003,0.000000e+000,0,,0,
1524435797.500,,0.000000e+000,3.499833e+001,1.973360e-006,0.000000e+000,3,6.701269e-001,0.000000e+000,,,,,,,,,,,,,,32,1,4.000000e+000,7.781982e-004,0.000000e+000,0,,0,
1524435835.603,,0.000000e+000,3.499793e+001,2.062866e-006,0.000000e+000,3,6.780776e-001,0.000000e+000,,,,,,,,,,,,,,32,1,4.000000e+000,1.567841e-003,0.000000e+000,0,,0,
1524435874.466,,0.000000e+000,3.499989e+001,2.248970e-006,0.000000e+000,3,6.783966e-001,0.000000e+000,,,,,,,,,,,,,,32,1,4.000000e+000,2.342224e-003,0.000000e+000,0,,0,
1524435912.809,,0.000000e+000,3.499872e+001,2.218198e-006,0.000000e+000,3,6.923127e-001,0.000000e+000,,,,,,,,,,,,,,32,1,4.000000e+000,1.560211e-003,0.000000e+000,0,,0,
1524435951.062,,0.000000e+000,3.499833e+001,2.296804e-006,0.000000e+000,3,7.242599e-001,0.000000e+000,,,,,,,,,,,,,,32,1,4.000000e+000,7.781982e-004,0.000000e+000,0,,0,
1524435989.680,,0.000000e+000,3.499989e+001,2.400142e-006,0.000000e+000,3,7.276930e-001,0.000000e+000,,,,,,,,,,,,,,32,1,4.000000e+000,7.781982e-004,0.000000e+000,0,,0,
1524436028.051,,0.000000e+000,3.499950e+001,2.480308e-006,0.000000e+000,3,7.341769e-001,0.000000e+000,,,,,,,,,,,,,,32,1,4.000000e+000,0.000000e+000,0.000000e+000,0,,0,
1524436066.129,,0.000000e+000,3.499911e+001,2.545496e-006,0.000000e+000,3,7.424251e-001,0.000000e+000,,,,,,,,,,,,,,32,1,4.000000e+000,3.910065e-003,0.000000e+000,0,,0,
1524436104.367,,0.000000e+000,3.499754e+001,2.615545e-006,0.000000e+000,3,7.494929e-001,0.000000e+000,,,,,,,,,,,,,,32,1,4.000000e+000,7.896423e-004,0.000000e+000,0,,0,
1524436142.610,,0.000000e+000,3.499872e+001,2.687103e-006,0.000000e+000,3,7.624341e-001,0.000000e+000,,,,,,,,,,,,,,32,1,4.000000e+000,1.560211e-003,0.000000e+000,0,,0,
1524436181.078,,0.000000e+000,3.499911e+001,2.792594e-006,0.000000e+000,3,7.558959e-001,0.000000e+000,,,,,,,,,,,,,,32,1,4.000000e+000,7.820129e-004,0.000000e+000,0,,0,
1524436218.711,,0.000000e+000,3.500028e+001,2.857227e-006,0.000000e+000,3,7.726822e-001,0.000000e+000,,,,,,,,,,,,,,32,1,4.000000e+000,1.560211e-003,0.000000e+000,0,,0,
1524436256.849,,0.000000e+000,3.499911e+001,2.910609e-006,0.000000e+000,3,7.777178e-001,0.000000e+000,,,,,,,,,,,,,,32,1,4.000000e+000,7.820129e-004,0.000000e+000,0,,0,
1524436294.920,,0.000000e+000,3.499872e+001,3.041985e-006,0.000000e+000,3,7.854139e-001,0.000000e+000,,,,,,,,,,,,,,32,1,4.000000e+000,0.000000e+000,0.000000e+000,0,,0,
1524436332.678,,0.000000e+000,3.499911e+001,2.975426e-006,0.000000e+000,3,7.793165e-001,0.000000e+000,,,,,,,,,,,,,,32,1,4.000000e+000,7.820129e-004,0.000000e+000,0,,0,
1524436372.189,,0.000000e+000,3.499872e+001,3.144142e-006,0.000000e+000,3,7.946615e-001,0.000000e+000,,,,,,,,,,,,,,32,1,4.000000e+000,1.560211e-003,0.000000e+000,0,,0,
1524436410.209,,0.000000e+000,3.499989e+001,3.206787e-006,0.000000e+000,3,7.940747e-001,0.000000e+000,,,,,,,,,,,,,,32,1,4.000000e+000,7.781982e-004,0.000000e+000,0,,0,
1524436448.257,,0.000000e+000,3.499872e+001,3.270012e-006,0.000000e+000,3,8.016420e-001,0.000000e+000,,,,,,,,,,,,,,32,1,4.000000e+000,1.560211e-003,0.000000e+000,0,,0,
1524436499.533,,0.000000e+000,3.499950e+001,3.502312e-006,0.000000e+000,3,8.250206e-001,0.000000e+000,,,,,,,,,,,,,,32,1,4.000000e+000,1.560211e-003,0.000000e+000,0,,0,
1524436538.623,,0.000000e+000,3.499950e+001,3.433533e-006,0.000000e+000,3,8.207431e-001,0.000000e+000,,,,,,,,,,,,,,32,1,4.000000e+000,0.000000e+000,0.000000e+000,0,,0,
1524436576.417,,0.000000e+000,3.500185e+001,3.482004e-006,0.000000e+000,3,8.161833e-001,0.000000e+000,,,,,,,,,,,,,,32,1,4.000000e+000,6.259918e-003,0.000000e+000,0,,0,
1524436614.365,,0.000000e+000,3.499950e+001,3.419034e-006,0.000000e+000,3,8.219539e-001,0.000000e+000,,,,,,,,,,,,,,32,1,4.000000e+000,1.560211e-003,0.000000e+000,0,,0,
1524436652.330,,0.000000e+000,3.499833e+001,3.570601e-006,0.000000e+000,3,8.192663e-001,0.000000e+000,,,,,,,,,,,,,,32,1,4.000000e+000,7.781982e-004,0.000000e+000,0,,0,
1524436690.378,,0.000000e+000,3.499754e+001,3.614584e-006,0.000000e+000,3,8.266323e-001,0.000000e+000,,,,,,,,,,,,,,32,1,4.000000e+000,2.349854e-003,0.000000e+000,0,,0,
1524436728.454,,0.000000e+000,3.500106e+001,3.607323e-006,0.000000e+000,3,8.158772e-001,0.000000e+000,,,,,,,,,,,,,,32,1,4.000000e+000,0.000000e+000,0.000000e+000,0,,0,
1524436766.494,,0.000000e+000,3.499950e+001,3.680974e-006,0.000000e+000,3,8.318666e-001,0.000000e+000,,,,,,,,,,,,,,32,1,4.000000e+000,0.000000e+000,0.000000e+000,0,,0,
1524436804.512,,0.000000e+000,3.499872e+001,3.713256e-006,0.000000e+000,3,8.295202e-001,0.000000e+000,,,,,,,,,,,,,,32,1,4.000000e+000,0.000000e+000,0.000000e+000,0,,0,
1524436842.103,,0.000000e+000,3.499833e+001,3.764642e-006,0.000000e+000,3,8.303542e-001,0.000000e+000,,,,,,,,,,,,,,32,1,4.000000e+000,2.349854e-003,0.000000e+000,0,,0,
1524436880.171,,0.000000e+000,3.499872e+001,3.847674e-006,0.000000e+000,3,8.361779e-001,0.000000e+000,,,,,,,,,,,,,,32,1,4.000000e+000,0.000000e+000,0.000000e+000,0,,0,
1524436918.089,,0.000000e+000,3.500106e+001,3.850505e-006,0.000000e+000,3,8.395240e-001,0.000000e+000,,,,,,,,,,,,,,32,1,4.000000e+000,3.128052e-003,0.000000e+000,0,,0,
1524436956.107,,0.000000e+000,3.499950e+001,3.904872e-006,0.000000e+000,3,8.352279e-001,0.000000e+000,,,,,,,,,,,,,,32,1,4.000000e+000,1.560211e-003,0.000000e+000,0,,0,
1524436993.650,,0.000000e+000,3.500028e+001,3.936275e-006,0.000000e+000,3,8.458126e-001,0.000000e+000,,,,,,,,,,,,,,32,1,4.000000e+000,4.688263e-003,0.000000e+000,0,,0,
1524437031.653,,0.000000e+000,3.499911e+001,3.965485e-006,0.000000e+000,3,8.313410e-001,0.000000e+000,,,,,,,,,,,,,,32,1,4.000000e+000,3.910065e-003,0.000000e+000,0,,0,
1524437069.684,,0.000000e+000,3.499872e+001,4.008009e-006,0.000000e+000,3,8.407855e-001,0.000000e+000,,,,,,,,,,,,,,32,1,4.000000e+000,1.560211e-003,0.000000e+000,0,,0,
1524437107.752,,0.000000e+000,3.499872e+001,4.041078e-006,0.000000e+000,3,8.416978e-001,0.000000e+000,,,,,,,,,,,,,,32,1,4.000000e+000,1.560211e-003,0.000000e+000,0,,0,
1524437145.672,,0.000000e+000,3.499950e+001,4.017843e-006,0.000000e+000,3,8.467199e-001,0.000000e+000,,,,,,,,,,,,,,32,1,4.000000e+000,1.560211e-003,0.000000e+000,0,,0,
1524437182.578,,0.000000e+000,3.499911e+001,4.126393e-006,0.000000e+000,3,8.503463e-001,0.000000e+000,,,,,,,,,,,,,,32,1,4.000000e+000,7.820129e-004,0.000000e+000,0,,0,
1524437220.743,,0.000000e+000,3.499950e+001,4.117283e-006,0.000000e+000,3,8.502247e-001,0.000000e+000,,,,,,,,,,,,,,32,1,4.000000e+000,0.000000e+000,0.000000e+000,0,,0,
1524437257.834,,0.000000e+000,3.499911e+001,4.214238e-006,0.000000e+000,3,8.511798e-001,0.000000e+000,,,,,,,,,,,,,,32,1,4.000000e+000,7.820129e-004,0.000000e+000,0,,0,
1524437295.665,,0.000000e+000,3.499950e+001,4.212661e-006,0.000000e+000,3,8.498654e-001,0.000000e+000,,,,,,,,,,,,,,32,1,4.000000e+000,0.000000e+000,0.000000e+000,0,,0,
1524437333.163,,0.000000e+000,3.499911e+001,4.228345e-006,0.000000e+000,3,8.510920e-001,0.000000e+000,,,,,,,,,,,,,,32,1,4.000000e+000,7.820129e-004,0.000000e+000,0,,0,
1524437384.181,,0.000000e+000,3.499911e+001,4.294776e-006,0.000000e+000,3,8.554520e-001,0.000000e+000,,,,,,,,,,,,,,32,1,4.000000e+000,7.820129e-004,0.000000e+000,0,,0,
1524437422.657,,0.000000e+000,3.499872e+001,4.327866e-006,0.000000e+000,3,8.541189e-001,0.000000e+000,,,,,,,,,,,,,,32,1,4.000000e+000,0.000000e+000,0.000000e+000,0,,0,
1524437460.255,,0.000000e+000,3.499911e+001,4.367830e-006,0.000000e+000,3,8.610755e-001,0.000000e+000,,,,,,,,,,,,,,32,1,4.000000e+000,7.820129e-004,0.000000e+000,0,,0,
1524437497.863,,0.000000e+000,3.499989e+001,4.384985e-006,0.000000e+000,3,8.606902e-001,0.000000e+000,,,,,,,,,,,,,,32,1,4.000000e+000,7.781982e-004,0.000000e+000,0,,0,
1524437535.111,,0.000000e+000,3.499911e+001,4.400997e-006,0.000000e+000,3,8.520523e-001,0.000000e+000,,,,,,,,,,,,,,32,1,4.000000e+000,7.820129e-004,0.000000e+000,0,,0,
1524437572.721,,0.000000e+000,3.499950e+001,4.474458e-006,0.000000e+000,3,8.570772e-001,0.000000e+000,,,,,,,,,,,,,,32,1,4.000000e+000,1.560211e-003,0.000000e+000,0,,0,
1524437611.937,,0.000000e+000,3.499911e+001,4.491132e-006,0.000000e+000,3,8.583858e-001,0.000000e+000,,,,,,,,,,,,,,32,1,4.000000e+000,7.820129e-004,0.000000e+000,0,,0,
1524437650.770,,0.000000e+000,3.500028e+001,4.532383e-006,0.000000e+000,3,8.660296e-001,0.000000e+000,,,,,,,,,,,,,,32,1,4.000000e+000,1.560211e-003,0.000000e+000,0,,0,
1524437688.930,,0.000000e+000,3.499911e+001,4.568633e-006,0.000000e+000,3,8.567419e-001,0.000000e+000,,,,,,,,,,,,,,32,1,4.000000e+000,7.820129e-004,0.000000e+000,0,,0,
1524437727.006,,0.000000e+000,3.499911e+001,4.472074e-006,0.000000e+000,3,8.632848e-001,0.000000e+000,,,,,,,,,,,,,,32,1,4.000000e+000,7.820129e-004,0.000000e+000,0,,0,
1524437765.764,,0.000000e+000,3.499911e+001,4.572045e-006,0.000000e+000,3,8.615013e-001,0.000000e+000,,,,,,,,,,,,,,32,1,4.000000e+000,7.820129e-004,0.000000e+000,0,,0,
1524437803.960,,0.000000e+000,3.499872e+001,4.598123e-006,0.000000e+000,3,8.568775e-001,0.000000e+000,,,,,,,,,,,,,,32,1,4.000000e+000,1.560211e-003,0.000000e+000,0,,0,
1524437841.993,,0.000000e+000,3.499872e+001,4.628655e-006,0.000000e+000,3,8.637457e-001,0.000000e+000,,,,,,,,,,,,,,32,1,4.000000e+000,1.560211e-003,0.000000e+000,0,,0,
1524437879.991,,0.000000e+000,3.499833e+001,4.673535e-006,0.000000e+000,3,8.713325e-001,0.000000e+000,,,,,,,,,,,,,,32,1,4.000000e+000,7.781982e-004,0.000000e+000,0,,0,
1524437918.061,,0.000000e+000,3.500028e+001,4.672044e-006,0.000000e+000,3,8.679999e-001,0.000000e+000,,,,,,,,,,,,,,32,1,4.000000e+000,1.560211e-003,0.000000e+000,0,,0,
1524437956.184,,0.000000e+000,3.499950e+001,4.693337e-006,0.000000e+000,3,8.646104e-001,0.000000e+000,,,,,,,,,,,,,,32,1,4.000000e+000,0.000000e+000,0.000000e+000,0,,0,
1524437994.175,,0.000000e+000,3.499871e+001,4.765297e-006,0.000000e+000,3,8.660963e-001,0.000000e+000,,,,,,,,,,,,,,32,1,4.000000e+000,3.128052e-003,0.000000e+000,0,,0,
1524438032.313,,0.000000e+000,3.499950e+001,4.755433e-006,0.000000e+000,3,8.665956e-001,0.000000e+000,,,,,,,,,,,,,,32,1,4.000000e+000,0.000000e+000,0.000000e+000,0,,0,
1524438070.301,,0.000000e+000,3.499833e+001,4.757012e-006,0.000000e+000,3,8.684883e-001,0.000000e+000,,,,,,,,,,,,,,32,1,4.000000e+000,7.781982e-004,0.000000e+000,0,,0,
1524438108.444,,0.000000e+000,3.499911e+001,4.806252e-006,0.000000e+000,3,8.701104e-001,0.000000e+000,,,,,,,,,,,,,,32,1,4.000000e+000,7.820129e-004,0.000000e+000,0,,0,
1524438146.507,,0.000000e+000,3.500028e+001,4.842052e-006,0.000000e+000,3,8.638608e-001,0.000000e+000,,,,,,,,,,,,,,32,1,4.000000e+000,0.000000e+000,0.000000e+000,0,,0,
1524438184.978,,0.000000e+000,3.499872e+001,4.857235e-006,0.000000e+000,3,8.650194e-001,0.000000e+000,,,,,,,,,,,,,,32,1,4.000000e+000,0.000000e+000,0.000000e+000,0,,0,
1524438222.941,,0.000000e+000,3.499989e+001,4.867857e-006,0.000000e+000,3,8.678331e-001,0.000000e+000,,,,,,,,,,,,,,32,1,4.000000e+000,7.781982e-004,0.000000e+000,0,,0,
1524438274.262,,0.000000e+000,3.500185e+001,4.960127e-006,0.000000e+000,3,8.723521e-001,0.000000e+000,,,,,,,,,,,,,,32,1,4.000000e+000,4.688263e-003,0.000000e+000,0,,0,
1524438312.280,,0.000000e+000,3.499911e+001,4.881611e-006,0.000000e+000,3,8.679903e-001,0.000000e+000,,,,,,,,,,,,,,32,1,4.000000e+000,7.820129e-004,0.000000e+000,0,,0,
1524438350.348,,0.000000e+000,3.499950e+001,4.890955e-006,0.000000e+000,3,8.692770e-001,0.000000e+000,,,,,,,,,,,,,,32,1,4.000000e+000,0.000000e+000,0.000000e+000,0,,0,
1524438388.363,,0.000000e+000,3.499950e+001,4.931004e-006,0.000000e+000,3,8.666654e-001,0.000000e+000,,,,,,,,,,,,,,32,1,4.000000e+000,0.000000e+000,0.000000e+000,0,,0,
1524438427.001,,0.000000e+000,3.499950e+001,4.987244e-006,0.000000e+000,3,8.697781e-001,0.000000e+000,,,,,,,,,,,,,,32,1,4.000000e+000,0.000000e+000,0.000000e+000,0,,0,
1524438464.754,,0.000000e+000,3.499911e+001,5.023936e-006,0.000000e+000,3,8.837799e-001,0.000000e+000,,,,,,,,,,,,,,32,1,4.000000e+000,7.820129e-004,0.000000e+000,0,,0,
1524438503.265,,0.000000e+000,3.499872e+001,5.003206e-006,0.000000e+000,3,8.755335e-001,0.000000e+000,,,,,,,,,,,,,,32,1,4.000000e+000,0.000000e+000,0.000000e+000,0,,0,
1524438541.535,,0.000000e+000,3.499911e+001,5.035317e-006,0.000000e+000,3,8.788459e-001,0.000000e+000,,,,,,,,,,,,,,32,1,4.000000e+000,7.820129e-004,0.000000e+000,0,,0,
1524438578.958,,0.000000e+000,3.500106e+001,5.036735e-006,0.000000e+000,3,8.736629e-001,0.000000e+000,,,,,,,,,,,,,,32,1,4.000000e+000,1.560211e-003,0.000000e+000,0,,0,
1524438617.474,,0.000000e+000,3.499911e+001,5.048445e-006,0.000000e+000,3,8.764473e-001,0.000000e+000,,,,,,,,,,,,,,32,1,4.000000e+000,7.820129e-004,0.000000e+000,0,,0,
1524438654.430,,0.000000e+000,3.499911e+001,5.027626e-006,0.000000e+000,3,8.767440e-001,0.000000e+000,,,,,,,,,,,,,,32,1,4.000000e+000,7.820129e-004,0.000000e+000,0,,0,
1524438692.365,,0.000000e+000,3.499715e+001,5.093050e-006,0.000000e+000,3,8.726353e-001,0.000000e+000,,,,,,,,,,,,,,32,1,4.000000e+000,3.128052e-003,0.000000e+000,0,,0,
1524438730.418,,0.000000e+000,3.499989e+001,5.083240e-006,0.000000e+000,3,8.749723e-001,0.000000e+000,,,,,,,,,,,,,,32,1,4.000000e+000,7.781982e-004,0.000000e+000,0,,0,
1524438768.101,,0.000000e+000,3.499911e+001,5.065877e-006,0.000000e+000,3,8.726222e-001,0.000000e+000,,,,,,,,,,,,,,32,1,4.000000e+000,7.820129e-004,0.000000e+000,0,,0,
1524438805.364,,0.000000e+000,3.499872e+001,5.146704e-006,0.000000e+000,3,8.795655e-001,0.000000e+000,,,,,,,,,,,,,,32,1,4.000000e+000,1.560211e-003,0.000000e+000,0,,0,
1524438843.175,,0.000000e+000,3.499911e+001,5.216901e-006,0.000000e+000,3,8.795560e-001,0.000000e+000,,,,,,,,,,,,,,32,1,4.000000e+000,7.820129e-004,0.000000e+000,0,,0,
1524438881.445,,0.000000e+000,3.500106e+001,5.210914e-006,0.000000e+000,3,8.768615e-001,0.000000e+000,,,,,,,,,,,,,,32,1,4.000000e+000,1.560211e-003,0.000000e+000,0,,0,
1524438919.519,,0.000000e+000,3.499950e+001,5.205489e-006,0.000000e+000,3,8.778340e-001,0.000000e+000,,,,,,,,,,,,,,32,1,4.000000e+000,0.000000e+000,0.000000e+000,0,,0,
1524438956.824,,0.000000e+000,3.499833e+001,5.170823e-006,0.000000e+000,3,8.792912e-001,0.000000e+000,,,,,,,,,,,,,,32,1,4.000000e+000,2.349854e-003,0.000000e+000,0,,0,
1524438994.430,,0.000000e+000,3.499872e+001,5.196588e-006,0.000000e+000,3,8.808194e-001,0.000000e+000,,,,,,,,,,,,,,32,1,4.000000e+000,0.000000e+000,0.000000e+000,0,,0,
1524439032.505,,0.000000e+000,3.499989e+001,5.226152e-006,0.000000e+000,3,8.822246e-001,0.000000e+000,,,,,,,,,,,,,,32,1,4.000000e+000,7.781982e-004,0.000000e+000,0,,0,
1524439070.558,,0.000000e+000,3.499872e+001,5.234623e-006,0.000000e+000,3,8.807606e-001,0.000000e+000,,,,,,,,,,,,,,32,1,4.000000e+000,1.560211e-003,0.000000e+000,0,,0,
1524439108.531,,0.000000e+000,3.499950e+001,5.285500e-006,0.000000e+000,3,8.781062e-001,0.000000e+000,,,,,,,,,,,,,,32,1,4.000000e+000,0.000000e+000,0.000000e+000,0,,0,
1524439146.597,,0.000000e+000,3.499989e+001,5.271225e-006,0.000000e+000,3,8.829442e-001,0.000000e+000,,,,,,,,,,,,,,32,1,4.000000e+000,7.781982e-004,0.000000e+000,0,,0,
1524439198.010,,0.000000e+000,3.499989e+001,5.273980e-006,0.000000e+000,3,8.718808e-001,0.000000e+000,,,,,,,,,,,,,,32,1,4.000000e+000,7.781982e-004,0.000000e+000,0,,0,
1524439235.801,,0.000000e+000,3.499872e+001,5.344344e-006,0.000000e+000,3,8.802727e-001,0.000000e+000,,,,,,,,,,,,,,32,1,4.000000e+000,1.560211e-003,0.000000e+000,0,,0,
1524439274.304,,0.000000e+000,3.499911e+001,5.358470e-006,0.000000e+000,3,8.860601e-001,0.000000e+000,,,,,,,,,,,,,,32,1,4.000000e+000,7.820129e-004,0.000000e+000,0,,0,
1524439312.127,,0.000000e+000,3.499833e+001,5.286062e-006,0.000000e+000,3,8.826292e-001,0.000000e+000,,,,,,,,,,,,,,32,1,4.000000e+000,2.349854e-003,0.000000e+000,0,,0,
1524439349.060,,0.000000e+000,3.499872e+001,5.305468e-006,0.000000e+000,3,8.842162e-001,0.000000e+000,,,,,,,,,,,,,,32,1,4.000000e+000,1.560211e-003,0.000000e+000,0,,0,
1524439387.495,,0.000000e+000,3.499872e+001,5.455800e-006,0.000000e+000,3,8.774061e-001,0.000000e+000,,,,,,,,,,,,,,32,1,4.000000e+000,1.560211e-003,0.000000e+000,0,,0,
1524439425.571,,0.000000e+000,3.499950e+001,5.414079e-006,0.000000e+000,3,8.739578e-001,0.000000e+000,,,,,,,,,,,,,,32,1,4.000000e+000,0.000000e+000,0.000000e+000,0,,0,
1524439463.596,,0.000000e+000,3.499911e+001,5.451542e-006,0.000000e+000,3,8.838952e-001,0.000000e+000,,,,,,,,,,,,,,32,1,4.000000e+000,7.820129e-004,0.000000e+000,0,,0,
1524439501.517,,0.000000e+000,3.500028e+001,5.439725e-006,0.000000e+000,3,8.848668e-001,0.000000e+000,,,,,,,,,,,,,,32,1,4.000000e+000,3.120422e-003,0.000000e+000,0,,0,
1524439538.893,,0.000000e+000,3.499950e+001,5.424550e-006,0.000000e+000,3,8.879770e-001,0.000000e+000,,,,,,,,,,,,,,32,1,4.000000e+000,1.560211e-003,0.000000e+000,0,,0,
1524439577.266,,0.000000e+000,3.500106e+001,5.475732e-006,0.000000e+000,3,8.865180e-001,0.000000e+000,,,,,,,,,,,,,,32,1,4.000000e+000,1.560211e-003,0.000000e+000,0,,0,
1524439615.054,,0.000000e+000,3.499872e+001,5.457430e-006,0.000000e+000,3,8.805158e-001,0.000000e+000,,,,,,,,,,,,,,32,1,4.000000e+000,0.000000e+000,0.000000e+000,0,,0,
1524439653.064,,0.000000e+000,3.499950e+001,5.425179e-006,0.000000e+000,3,8.845187e-001,0.000000e+000,,,,,,,,,,,,,,32,1,4.000000e+000,1.560211e-003,0.000000e+000,0,,0,
1524439691.045,,0.000000e+000,3.499833e+001,5.469547e-006,0.000000e+000,3,8.843253e-001,0.000000e+000,,,,,,,,,,,,,,32,1,4.000000e+000,2.349854e-003,0.000000e+000,0,,0,
1524439729.118,,0.000000e+000,3.499793e+001,5.470002e-006,0.000000e+000,3,8.874928e-001,0.000000e+000,,,,,,,,,,,,,,32,1,4.000000e+000,1.567841e-003,0.000000e+000,0,,0,
1524439767.178,,0.000000e+000,3.499950e+001,5.428296e-006,0.000000e+000,3,8.860537e-001,0.000000e+000,,,,,,,,,,,,,,32,1,4.000000e+000,1.560211e-003,0.000000e+000,0,,0,
1524439804.816,,0.000000e+000,3.499833e+001,5.478030e-006,0.000000e+000,3,8.874288e-001,0.000000e+000,,,,,,,,,,,,,,32,1,4.000000e+000,7.781982e-004,0.000000e+000,0,,0,
1524439842.867,,0.000000e+000,3.499833e+001,5.497940e-006,0.000000e+000,3,8.857380e-001,0.000000e+000,,,,,,,,,,,,,,32,1,4.000000e+000,7.781982e-004,0.000000e+000,0,,0,
1524439881.300,,0.000000e+000,3.499911e+001,5.521191e-006,0.000000e+000,3,8.845165e-001,0.000000e+000,,,,,,,,,,,,,,32,1,4.000000e+000,7.820129e-004,0.000000e+000,0,,0,
1524439918.443,,0.000000e+000,3.499950e+001,5.476363e-006,0.000000e+000,3,8.866740e-001,0.000000e+000,,,,,,,,,,,,,,32,1,4.000000e+000,0.000000e+000,0.000000e+000,0,,0,
1524439956.909,,0.000000e+000,3.499989e+001,5.589586e-006,0.000000e+000,3,8.894953e-001,0.000000e+000,,,,,,,,,,,,,,32,1,4.000000e+000,7.781982e-004,0.000000e+000,0,,0,
1524439994.057,,0.000000e+000,3.499911e+001,5.603453e-006,0.000000e+000,3,8.887615e-001,0.000000e+000,,,,,,,,,,,,,,32,1,4.000000e+000,7.820129e-004,0.000000e+000,0,,0,
1524440032.475,,0.000000e+000,3.499911e+001,5.576313e-006,0.000000e+000,3,8.887122e-001,0.000000e+000,,,,,,,,,,,,,,32,1,4.000000e+000,2.338409e-003,0.000000e+000,0,,0,
1524440069.618,,0.000000e+000,3.499871e+001,5.539567e-006,0.000000e+000,3,8.863294e-001,0.000000e+000,,,,,,,,,,,,,,32,1,4.000000e+000,3.128052e-003,0.000000e+000,0,,0,
1524440121.206,,0.000000e+000,3.499911e+001,5.630138e-006,0.000000e+000,3,8.836118e-001,0.000000e+000,,,,,,,,,,,,,,32,1,4.000000e+000,7.820129e-004,0.000000e+000,0,,0,
1524440159.242,,0.000000e+000,3.499989e+001,5.650179e-006,0.000000e+000,3,8.878982e-001,0.000000e+000,,,,,,,,,,,,,,32,1,4.000000e+000,7.781982e-004,0.000000e+000,0,,0,
1524440196.562,,0.000000e+000,3.499911e+001,5.696458e-006,0.000000e+000,3,8.819953e-001,0.000000e+000,,,,,,,,,,,,,,32,1,4.000000e+000,7.820129e-004,0.000000e+000,0,,0,
1524440234.525,,0.000000e+000,3.499911e+001,5.663332e-006,0.000000e+000,3,8.862666e-001,0.000000e+000,,,,,,,,,,,,,,32,1,4.000000e+000,7.820129e-004,0.000000e+000,0,,0,
1524440272.571,,0.000000e+000,3.499950e+001,5.616237e-006,0.000000e+000,3,8.835319e-001,0.000000e+000,,,,,,,,,,,,,,32,1,4.000000e+000,0.000000e+000,0.000000e+000,0,,0,
1524440310.829,,0.000000e+000,3.499989e+001,5.657541e-006,0.000000e+000,3,8.807606e-001,0.000000e+000,,,,,,,,,,,,,,32,1,4.000000e+000,7.781982e-004,0.000000e+000,0,,0,
1524440348.194,,0.000000e+000,3.499950e+001,5.675620e-006,0.000000e+000,3,8.894392e-001,0.000000e+000,,,,,,,,,,,,,,32,1,4.000000e+000,1.560211e-003,0.000000e+000,0,,0,
1524440386.242,,0.000000e+000,3.499872e+001,5.669202e-006,0.000000e+000,3,8.867147e-001,0.000000e+000,,,,,,,,,,,,,,32,1,4.000000e+000,1.560211e-003,0.000000e+000,0,,0,
1524440424.731,,0.000000e+000,3.499911e+001,5.679638e-006,0.000000e+000,3,8.940949e-001,0.000000e+000,,,,,,,,,,,,,,32,1,4.000000e+000,7.820129e-004,0.000000e+000,0,,0,
1524440462.441,,0.000000e+000,3.499950e+001,5.680050e-006,0.000000e+000,3,8.900554e-001,0.000000e+000,,,,,,,,,,,,,,32,1,4.000000e+000,0.000000e+000,0.000000e+000,0,,0,
1524440500.419,,0.000000e+000,3.499911e+001,5.698875e-006,0.000000e+000,3,8.915587e-001,0.000000e+000,,,,,,,,,,,,,,32,1,4.000000e+000,7.820129e-004,0.000000e+000,0,,0,
1524440538.795,,0.000000e+000,3.499872e+001,5.699117e-006,0.000000e+000,3,8.896512e-001,0.000000e+000,,,,,,,,,,,,,,32,1,4.000000e+000,1.560211e-003,0.000000e+000,0,,0,
1524440577.195,,0.000000e+000,3.499989e+001,5.704692e-006,0.000000e+000,3,8.914913e-001,0.000000e+000,,,,,,,,,,,,,,32,1,4.000000e+000,7.781982e-004,0.000000e+000,0,,0,
1524440615.316,,0.000000e+000,3.500028e+001,5.726978e-006,0.000000e+000,3,8.891881e-001,0.000000e+000,,,,,,,,,,,,,,32,1,4.000000e+000,0.000000e+000,0.000000e+000,0,,0,
1524440653.166,,0.000000e+000,3.499911e+001,5.763751e-006,0.000000e+000,3,8.834971e-001,0.000000e+000,,,,,,,,,,,,,,32,1,4.000000e+000,7.820129e-004,0.000000e+000,0,,0,
1524440691.724,,0.000000e+000,3.500224e+001,5.791734e-006,0.000000e+000,3,8.923645e-001,0.000000e+000,,,,,,,,,,,,,,32,1,4.000000e+000,7.896423e-004,0.000000e+000,0,,0,
1524440729.573,,0.000000e+000,3.499833e+001,5.742502e-006,0.000000e+000,3,8.839728e-001,0.000000e+000,,,,,,,,,,,,,,32,1,4.000000e+000,2.349854e-003,0.000000e+000,0,,0,
1524440767.633,,0.000000e+000,3.499950e+001,5.769516e-006,0.000000e+000,3,8.873022e-001,0.000000e+000,,,,,,,,,,,,,,32,1,4.000000e+000,0.000000e+000,0.000000e+000,0,,0,
1524440805.689,,0.000000e+000,3.499911e+001,5.737443e-006,0.000000e+000,3,8.869333e-001,0.000000e+000,,,,,,,,,,,,,,32,1,4.000000e+000,7.820129e-004,0.000000e+000,0,,0,
1524440843.719,,0.000000e+000,3.500028e+001,5.796825e-006,0.000000e+000,3,8.889760e-001,0.000000e+000,,,,,,,,,,,,,,32,1,4.000000e+000,4.688263e-003,0.000000e+000,0,,0,
1524440882.615,,0.000000e+000,3.499911e+001,5.790463e-006,0.000000e+000,3,8.911565e-001,0.000000e+000,,,,,,,,,,,,,,32,1,4.000000e+000,7.820129e-004,0.000000e+000,0,,0,
1524440920.553,,0.000000e+000,3.499911e+001,5.765598e-006,0.000000e+000,3,8.927589e-001,0.000000e+000,,,,,,,,,,,,,,32,1,4.000000e+000,7.820129e-004,0.000000e+000,0,,0,
1524440958.711,,0.000000e+000,3.500028e+001,5.824551e-006,0.000000e+000,3,8.910742e-001,0.000000e+000,,,,,,,,,,,,,,32,1,4.000000e+000,0.000000e+000,0.000000e+000,0,,0,
1524440996.739,,0.000000e+000,3.499872e+001,5.803061e-006,0.000000e+000,3,8.915858e-001,0.000000e+000,,,,,,,,,,,,,,32,1,4.000000e+000,1.560211e-003,0.000000e+000,0,,0,
1524441048.287,,0.000000e+000,3.499872e+001,5.828329e-006,0.000000e+000,3,8.902977e-001,0.000000e+000,,,,,,,,,,,,,,32,1,4.000000e+000,0.000000e+000,0.000000e+000,0,,0,
1524441085.583,,0.000000e+000,3.499989e+001,5.810885e-006,0.000000e+000,3,8.873746e-001,0.000000e+000,,,,,,,,,,,,,,32,1,4.000000e+000,2.342224e-003,0.000000e+000,0,,0,
1524441122.998,,0.000000e+000,3.499950e+001,5.810577e-006,0.000000e+000,3,8.825712e-001,0.000000e+000,,,,,,,,,,,,,,32,1,4.000000e+000,0.000000e+000,0.000000e+000,0,,0,
1524441160.536,,0.000000e+000,3.499833e+001,5.753377e-006,0.000000e+000,3,8.891047e-001,0.000000e+000,,,,,,,,,,,,,,32,1,4.000000e+000,7.781982e-004,0.000000e+000,0,,0,
1524441198.152,,0.000000e+000,3.499950e+001,5.879830e-006,0.000000e+000,3,8.959280e-001,0.000000e+000,,,,,,,,,,,,,,32,1,4.000000e+000,0.000000e+000,0.000000e+000,0,,0,
1524441236.627,,0.000000e+000,3.499911e+001,5.840690e-006,0.000000e+000,3,8.973466e-001,0.000000e+000,,,,,,,,,,,,,,32,1,4.000000e+000,7.820129e-004,0.000000e+000,0,,0,
1524441274.260,,0.000000e+000,3.499950e+001,5.862967e-006,0.000000e+000,3,8.916956e-001,0.000000e+000,,,,,,,,,,,,,,32,1,4.000000e+000,0.000000e+000,0.000000e+000,0,,0,
1524441312.771,,0.000000e+000,3.499911e+001,5.881482e-006,0.000000e+000,3,8.976638e-001,0.000000e+000,,,,,,,,,,,,,,32,1,4.000000e+000,7.820129e-004,0.000000e+000,0,,0,
1524441350.382,,0.000000e+000,3.499950e+001,5.852748e-006,0.000000e+000,3,8.937348e-001,0.000000e+000,,,,,,,,,,,,,,32,1,4.000000e+000,0.000000e+000,0.000000e+000,0,,0,
1524441388.400,,0.000000e+000,3.499872e+001,5.910073e-006,0.000000e+000,3,8.895516e-001,0.000000e+000,,,,,,,,,,,,,,32,1,4.000000e+000,1.560211e-003,0.000000e+000,0,,0,
1524441426.920,,0.000000e+000,3.499950e+001,5.936804e-006,0.000000e+000,3,8.958357e-001,0.000000e+000,,,,,,,,,,,,,,32,1,4.000000e+000,0.000000e+000,0.000000e+000,0,,0,
1524441464.998,,0.000000e+000,3.499950e+001,5.947422e-006,0.000000e+000,3,8.951753e-001,0.000000e+000,,,,,,,,,,,,,,32,1,4.000000e+000,0.000000e+000,0.000000e+000,0,,0,
1524441503.334,,0.000000e+000,3.499793e+001,5.906775e-006,0.000000e+000,3,8.991246e-001,0.000000e+000,,,,,,,,,,,,,,32,1,4.000000e+000,3.131866e-003,0.000000e+000,0,,0,
1524441541.212,,0.000000e+000,3.499950e+001,5.973797e-006,0.000000e+000,3,8.943906e-001,0.000000e+000,,,,,,,,,,,,,,32,1,4.000000e+000,0.000000e+000,0.000000e+000,0,,0,
1524441578.920,,0.000000e+000,3.499989e+001,5.935182e-006,0.000000e+000,3,8.900294e-001,0.000000e+000,,,,,,,,,,,,,,32,1,4.000000e+000,7.781982e-004,0.000000e+000,0,,0,
1524441616.923,,0.000000e+000,3.500028e+001,5.974790e-006,0.000000e+000,3,8.946668e-001,0.000000e+000,,,,,,,,,,,,,,32,1,4.000000e+000,0.000000e+000,0.000000e+000,0,,0,
1524441655.026,,0.000000e+000,3.499950e+001,5.968971e-006,0.000000e+000,3,8.924173e-001,0.000000e+000,,,,,,,,,,,,,,32,1,4.000000e+000,0.000000e+000,0.000000e+000,0,,0,
1524441693.169,,0.000000e+000,3.499950e+001,5.953251e-006,0.000000e+000,3,8.943756e-001,0.000000e+000,,,,,,,,,,,,,,32,1,4.000000e+000,1.560211e-003,0.000000e+000,0,,0,
1524441731.180,,0.000000e+000,3.499911e+001,6.003315e-006,0.000000e+000,3,8.907816e-001,0.000000e+000,,,,,,,,,,,,,,32,1,4.000000e+000,3.910065e-003,0.000000e+000,0,,0,
1524441768.905,,0.000000e+000,3.499950e+001,5.953167e-006,0.000000e+000,3,8.947825e-001,0.000000e+000,,,,,,,,,,,,,,32,1,4.000000e+000,0.000000e+000,0.000000e+000,0,,0,
1524441806.818,,0.000000e+000,3.499872e+001,6.002285e-006,0.000000e+000,3,8.923950e-001,0.000000e+000,,,,,,,,,,,,,,32,1,4.000000e+000,1.560211e-003,0.000000e+000,0,,0,
1524441844.899,,0.000000e+000,3.499989e+001,5.979046e-006,0.000000e+000,3,8.905062e-001,0.000000e+000,,,,,,,,,,,,,,32,1,4.000000e+000,7.781982e-004,0.000000e+000,0,,0,
1524441882.917,,0.000000e+000,3.500106e+001,5.964529e-006,0.000000e+000,3,8.878806e-001,0.000000e+000,,,,,,,,,,,,,,32,1,4.000000e+000,3.128052e-003,0.000000e+000,0,,0,
1524441920.750,,0.000000e+000,3.499833e+001,5.960143e-006,0.000000e+000,3,8.877901e-001,0.000000e+000,,,,,,,,,,,,,,32,1,4.000000e+000,2.349854e-003,0.000000e+000,0,,0,
1524441971.683,,0.000000e+000,3.499872e+001,6.035711e-006,0.000000e+000,3,8.873072e-001,0.000000e+000,,,,,,,,,,,,,,32,1,4.000000e+000,0.000000e+000,0.000000e+000,0,,0,
1524442008.881,,0.000000e+000,3.499989e+001,6.037835e-006,0.000000e+000,3,8.944476e-001,0.000000e+000,,,,,,,,,,,,,,32,1,4.000000e+000,5.477905e-003,0.000000e+000,0,,0,
1524442046.509,,0.000000e+000,3.499950e+001,6.049176e-006,0.000000e+000,3,8.922839e-001,0.000000e+000,,,,,,,,,,,,,,32,1,4.000000e+000,1.560211e-003,0.000000e+000,0,,0,
1524442084.565,,0.000000e+000,3.499989e+001,5.999231e-006,0.000000e+000,3,8.953376e-001,0.000000e+000,,,,,,,,,,,,,,32,1,4.000000e+000,2.342224e-003,0.000000e+000,0,,0,
1524442123.000,,0.000000e+000,3.499950e+001,6.034949e-006,0.000000e+000,3,8.977697e-001,0.000000e+000,,,,,,,,,,,,,,32,1,4.000000e+000,0.000000e+000,0.000000e+000,0,,0,
1524442160.136,,0.000000e+000,3.499872e+001,5.988273e-006,0.000000e+000,3,8.916129e-001,0.000000e+000,,,,,,,,,,,,,,32,1,4.000000e+000,0.000000e+000,0.000000e+000,0,,0,
1524442198.169,,0.000000e+000,3.500028e+001,6.045379e-006,0.000000e+000,3,8.934348e-001,0.000000e+000,,,,,,,,,,,,,,32,1,4.000000e+000,0.000000e+000,0.000000e+000,0,,0,
1524442236.152,,0.000000e+000,3.499950e+001,6.097192e-006,0.000000e+000,3,8.997501e-001,0.000000e+000,,,,,,,,,,,,,,32,1,4.000000e+000,1.560211e-003,0.000000e+000,0,,0,
1524442275.163,,0.000000e+000,3.499950e+001,6.067786e-006,0.000000e+000,3,8.955146e-001,0.000000e+000,,,,,,,,,,,,,,32,1,4.000000e+000,1.560211e-003,0.000000e+000,0,,0,
1524442313.038,,0.000000e+000,3.499989e+001,6.082091e-006,0.000000e+000,3,8.970649e-001,0.000000e+000,,,,,,,,,,,,,,32,1,4.000000e+000,7.781982e-004,0.000000e+000,0,,0,
1524442350.989,,0.000000e+000,3.499911e+001,6.120401e-006,0.000000e+000,3,8.943207e-001,0.000000e+000,,,,,,,,,,,,,,32,1,4.000000e+000,7.820129e-004,0.000000e+000,0,,0,
1524442389.319,,0.000000e+000,3.499754e+001,6.117678e-006,0.000000e+000,3,8.935328e-001,0.000000e+000,,,,,,,,,,,,,,32,1,4.000000e+000,3.910065e-003,0.000000e+000,0,,0,
1524442427.810,,0.000000e+000,3.499950e+001,6.084528e-006,0.000000e+000,3,8.968644e-001,0.000000e+000,,,,,,,,,,,,,,32,1,4.000000e+000,0.000000e+000,0.000000e+000,0,,0,
1524442465.073,,0.000000e+000,3.499950e+001,6.063274e-006,0.000000e+000,3,8.905464e-001,0.000000e+000,,,,,,,,,,,,,,32,1,4.000000e+000,1.560211e-003,0.000000e+000,0,,0,
1524442502.919,,0.000000e+000,3.499911e+001,6.077696e-006,0.000000e+000,3,8.950235e-001,0.000000e+000,,,,,,,,,,,,,,32,1,4.000000e+000,7.820129e-004,0.000000e+000,0,,0,
1524442540.529,,0.000000e+000,3.499715e+001,6.144639e-006,0.000000e+000,3,8.996152e-001,0.000000e+000,,,,,,,,,,,,,,32,1,4.000000e+000,0.000000e+000,0.000000e+000,0,,0,
1524442578.530,,0.000000e+000,3.499911e+001,6.125130e-006,0.000000e+000,3,8.907804e-001,0.000000e+000,,,,,,,,,,,,,,32,1,4.000000e+000,7.820129e-004,0.000000e+000,0,,0,
1524442616.205,,0.000000e+000,3.499950e+001,6.152664e-006,0.000000e+000,3,9.009668e-001,0.000000e+000,,,,,,,,,,,,,,32,1,4.000000e+000,0.000000e+000,0.000000e+000,0,,0,
1524442654.366,,0.000000e+000,3.499911e+001,6.151816e-006,0.000000e+000,3,8.894333e-001,0.000000e+000,,,,,,,,,,,,,,32,1,4.000000e+000,7.820129e-004,0.000000e+000,0,,0,
1524442692.204,,0.000000e+000,3.499833e+001,6.171479e-006,0.000000e+000,3,9.000428e-001,0.000000e+000,,,,,,,,,,,,,,32,1,4.000000e+000,2.349854e-003,0.000000e+000,0,,0,
1524442731.394,,0.000000e+000,3.499989e+001,6.162620e-006,0.000000e+000,3,8.959196e-001,0.000000e+000,,,,,,,,,,,,,,32,1,4.000000e+000,7.781982e-004,0.000000e+000,0,,0,
1524442769.877,,0.000000e+000,3.499950e+001,6.158553e-006,0.000000e+000,3,8.903045e-001,0.000000e+000,,,,,,,,,,,,,,32,1,4.000000e+000,0.000000e+000,0.000000e+000,0,,0,
1524442809.206,,0.000000e+000,3.499911e+001,6.176005e-006,0.000000e+000,3,8.970264e-001,0.000000e+000,,,,,,,,,,,,,,32,1,4.000000e+000,2.338409e-003,0.000000e+000,0,,0,
1524442860.631,,0.000000e+000,3.499872e+001,6.203933e-006,0.000000e+000,3,8.982658e-001,0.000000e+000,,,,,,,,,,,,,,32,1,4.000000e+000,0.000000e+000,0.000000e+000,0,,0,
1524442898.857,,0.000000e+000,3.499911e+001,6.200017e-006,0.000000e+000,3,8.946136e-001,0.000000e+000,,,,,,,,,,,,,,32,1,4.000000e+000,7.820129e-004,0.000000e+000,0,,0,
1524442936.895,,0.000000e+000,3.500106e+001,6.211951e-006,0.000000e+000,3,8.915359e-001,0.000000e+000,,,,,,,,,,,,,,32,1,4.000000e+000,1.560211e-003,0.000000e+000,0,,0,
1524442975.075,,0.000000e+000,3.500106e+001,6.234763e-006,0.000000e+000,3,8.974574e-001,0.000000e+000,,,,,,,,,,,,,,32,1,4.000000e+000,1.560211e-003,0.000000e+000,0,,0,
1524443013.011,,0.000000e+000,3.499872e+001,6.218515e-006,0.000000e+000,3,8.986238e-001,0.000000e+000,,,,,,,,,,,,,,32,1,4.000000e+000,1.560211e-003,0.000000e+000,0,,0,
1524443051.029,,0.000000e+000,3.499911e+001,6.187548e-006,0.000000e+000,3,8.914624e-001,0.000000e+000,,,,,,,,,,,,,,32,1,4.000000e+000,2.338409e-003,0.000000e+000,0,,0,
1524443089.117,,0.000000e+000,3.499794e+001,6.192154e-006,0.000000e+000,3,8.972027e-001,0.000000e+000,,,,,,,,,,,,,,32,1,4.000000e+000,0.000000e+000,0.000000e+000,0,,0,
1524443127.188,,0.000000e+000,3.499911e+001,6.188099e-006,0.000000e+000,3,8.977222e-001,0.000000e+000,,,,,,,,,,,,,,32,1,4.000000e+000,7.820129e-004,0.000000e+000,0,,0,
1524443165.016,,0.000000e+000,3.500106e+001,6.222521e-006,0.000000e+000,3,8.921311e-001,0.000000e+000,,,,,,,,,,,,,,32,1,4.000000e+000,1.560211e-003,0.000000e+000,0,,0,
1524443204.004,,0.000000e+000,3.499833e+001,6.217907e-006,0.000000e+000,3,9.002727e-001,0.000000e+000,,,,,,,,,,,,,,32,1,4.000000e+000,7.781982e-004,0.000000e+000,0,,0,
1524443242.452,,0.000000e+000,3.500145e+001,6.193764e-006,0.000000e+000,3,8.969961e-001,0.000000e+000,,,,,,,,,,,,,,32,1,4.000000e+000,7.781982e-004,0.000000e+000,0,,0,
1524443281.045,,0.000000e+000,3.499872e+001,6.243025e-006,0.000000e+000,3,9.011049e-001,0.000000e+000,,,,,,,,,,,,,,32,1,4.000000e+000,0.000000e+000,0.000000e+000,0,,0,
1524443319.090,,0.000000e+000,3.499872e+001,6.217031e-006,0.000000e+000,3,9.017623e-001,0.000000e+000,,,,,,,,,,,,,,32,1,4.000000e+000,0.000000e+000,0.000000e+000,0,,0,
1524443356.541,,0.000000e+000,3.499989e+001,6.216096e-006,0.000000e+000,3,8.933207e-001,0.000000e+000,,,,,,,,,,,,,,32,1,4.000000e+000,7.781982e-004,0.000000e+000,0,,0,
1524443394.814,,0.000000e+000,3.499911e+001,6.197454e-006,0.000000e+000,3,9.001944e-001,0.000000e+000,,,,,,,,,,,,,,32,1,4.000000e+000,7.820129e-004,0.000000e+000,0,,0,
1524443432.855,,0.000000e+000,3.499833e+001,6.259129e-006,0.000000e+000,3,8.995531e-001,0.000000e+000,,,,,,,,,,,,,,32,1,4.000000e+000,7.781982e-004,0.000000e+000,0,,0,
1524443471.305,,0.000000e+000,3.499911e+001,6.247792e-006,0.000000e+000,3,8.969539e-001,0.000000e+000,,,,,,,,,,,,,,32,1,4.000000e+000,7.820129e-004,0.000000e+000,0,,0,
1524443509.838,,0.000000e+000,3.499950e+001,6.262823e-006,0.000000e+000,3,8.968263e-001,0.000000e+000,,,,,,,,,,,,,,32,1,4.000000e+000,0.000000e+000,0.000000e+000,0,,0,
1524443548.584,,0.000000e+000,3.499950e+001,6.254057e-006,0.000000e+000,3,8.948483e-001,0.000000e+000,,,,,,,,,,,,,,32,1,4.000000e+000,0.000000e+000,0.000000e+000,0,,0,
1524443586.952,,0.000000e+000,3.499911e+001,6.262526e-006,0.000000e+000,3,9.011028e-001,0.000000e+000,,,,,,,,,,,,,,32,1,4.000000e+000,7.820129e-004,0.000000e+000,0,,0,
1524443625.015,,0.000000e+000,3.500224e+001,6.308565e-006,0.000000e+000,3,9.002557e-001,0.000000e+000,,,,,,,,,,,,,,32,1,4.000000e+000,5.477905e-003,0.000000e+000,0,,0,
1524443663.151,,0.000000e+000,3.499950e+001,6.295335e-006,0.000000e+000,3,8.950136e-001,0.000000e+000,,,,,,,,,,,,,,32,1,4.000000e+000,0.000000e+000,0.000000e+000,0,,0,
1524443701.864,,0.000000e+000,3.499833e+001,6.281776e-006,0.000000e+000,3,8.981545e-001,0.000000e+000,,,,,,,,,,,,,,32,1,4.000000e+000,7.781982e-004,0.000000e+000,0,,0,
1524443740.044,,0.000000e+000,3.499911e+001,6.290494e-006,0.000000e+000,3,8.980609e-001,0.000000e+000,,,,,,,,,,,,,,32,1,4.000000e+000,7.820129e-004,0.000000e+000,0,,0,
1524443791.540,,0.000000e+000,3.499872e+001,6.319879e-006,0.000000e+000,3,8.996133e-001,0.000000e+000,,,,,,,,,,,,,,32,1,4.000000e+000,0.000000e+000,0.000000e+000,0,,0,
1524443829.575,,0.000000e+000,3.499793e+001,6.332090e-006,0.000000e+000,3,8.973330e-001,0.000000e+000,,,,,,,,,,,,,,32,1,4.000000e+000,1.567841e-003,0.000000e+000,0,,0,
1524443867.614,,0.000000e+000,3.499950e+001,6.316901e-006,0.000000e+000,3,8.978224e-001,0.000000e+000,,,,,,,,,,,,,,32,1,4.000000e+000,0.000000e+000,0.000000e+000,0,,0,
1524443905.837,,0.000000e+000,3.499833e+001,6.330523e-006,0.000000e+000,3,8.980962e-001,0.000000e+000,,,,,,,,,,,,,,32,1,4.000000e+000,2.349854e-003,0.000000e+000,0,,0,
1524443943.860,,0.000000e+000,3.499950e+001,6.313060e-006,0.000000e+000,3,8.958001e-001,0.000000e+000,,,,,,,,,,,,,,32,1,4.000000e+000,1.560211e-003,0.000000e+000,0,,0,
1524443981.908,,0.000000e+000,3.499950e+001,6.332521e-006,0.000000e+000,3,8.986334e-001,0.000000e+000,,,,,,,,,,,,,,32,1,4.000000e+000,0.000000e+000,0.000000e+000,0,,0,
1524444019.976,,0.000000e+000,3.499950e+001,6.325306e-006,0.000000e+000,3,8.979399e-001,0.000000e+000,,,,,,,,,,,,,,32,1,4.000000e+000,0.000000e+000,0.000000e+000,0,,0,
1524444058.076,,0.000000e+000,3.499911e+001,6.327653e-006,0.000000e+000,3,8.958279e-001,0.000000e+000,,,,,,,,,,,,,,32,1,4.000000e+000,7.820129e-004,0.000000e+000,0,,0,
1524444096.107,,0.000000e+000,3.499989e+001,6.335557e-006,0.000000e+000,3,8.965572e-001,0.000000e+000,,,,,,,,,,,,,,32,1,4.000000e+000,7.781982e-004,0.000000e+000,0,,0,
1524444134.165,,0.000000e+000,3.499911e+001,6.346998e-006,0.000000e+000,3,8.957623e-001,0.000000e+000,,,,,,,,,,,,,,32,1,4.000000e+000,7.820129e-004,0.000000e+000,0,,0,
1524444172.248,,0.000000e+000,3.499989e+001,6.354832e-006,0.000000e+000,3,8.972173e-001,0.000000e+000,,,,,,,,,,,,,,32,1,4.000000e+000,7.781982e-004,0.000000e+000,0,,0,
1524444210.051,,0.000000e+000,3.499911e+001,6.360578e-006,0.000000e+000,3,8.995956e-001,0.000000e+000,,,,,,,,,,,,,,32,1,4.000000e+000,2.338409e-003,0.000000e+000,0,,0,
1524444247.829,,0.000000e+000,3.499911e+001,6.399227e-006,0.000000e+000,3,8.961046e-001,0.000000e+000,,,,,,,,,,,,,,32,1,4.000000e+000,7.820129e-004,0.000000e+000,0,,0,
1524444285.915,,0.000000e+000,3.499872e+001,6.381088e-006,0.000000e+000,3,9.014974e-001,0.000000e+000,,,,,,,,,,,,,,32,1,4.000000e+000,1.560211e-003,0.000000e+000,0,,0,
1524444324.443,,0.000000e+000,3.499911e+001,6.393070e-006,0.000000e+000,3,8.981956e-001,0.000000e+000,,,,,,,,,,,,,,32,1,4.000000e+000,7.820129e-004,0.000000e+000,0,,0,
1524444362.138,,0.000000e+000,3.499872e+001,6.369403e-006,0.000000e+000,3,9.011407e-001,0.000000e+000,,,,,,,,,,,,,,32,1,4.000000e+000,0.000000e+000,0.000000e+000,0,,0,
1524444399.719,,0.000000e+000,3.499911e+001,6.417903e-006,0.000000e+000,3,8.998581e-001,0.000000e+000,,,,,,,,,,,,,,32,1,4.000000e+000,7.820129e-004,0.000000e+000,0,,0,
1524444439.292,,0.000000e+000,3.499872e+001,6.413393e-006,0.000000e+000,3,8.975365e-001,0.000000e+000,,,,,,,,,,,,,,32,1,4.000000e+000,1.560211e-003,0.000000e+000,0,,0,
1524444476.520,,0.000000e+000,3.500028e+001,6.380717e-006,0.000000e+000,3,9.006374e-001,0.000000e+000,,,,,,,,,,,,,,32,1,4.000000e+000,0.000000e+000,0.000000e+000,0,,0,
1524444514.506,,0.000000e+000,3.499911e+001,6.375181e-006,0.000000e+000,3,9.044915e-001,0.000000e+000,,,,,,,,,,,,,,32,1,4.000000e+000,7.820129e-004,0.000000e+000,0,,0,
1524444552.569,,0.000000e+000,3.499950e+001,6.353047e-006,0.000000e+000,3,8.974488e-001,0.000000e+000,,,,,,,,,,,,,,32,1,4.000000e+000,0.000000e+000,0.000000e+000,0,,0,
1524444590.644,,0.000000e+000,3.499872e+001,6.386005e-006,0.000000e+000,3,9.007415e-001,0.000000e+000,,,,,,,,,,,,,,32,1,4.000000e+000,0.000000e+000,0.000000e+000,0,,0,
1524444629.137,,0.000000e+000,3.499911e+001,6.390972e-006,0.000000e+000,3,9.021253e-001,0.000000e+000,,,,,,,,,,,,,,32,1,4.000000e+000,7.820129e-004,0.000000e+000,0,,0,
1524444680.125,,0.000000e+000,3.499950e+001,6.431645e-006,0.000000e+000,3,9.024436e-001,0.000000e+000,,,,,,,,,,,,,,32,1,4.000000e+000,0.000000e+000,0.000000e+000,0,,0,
1524444717.469,,0.000000e+000,3.499950e+001,6.389066e-006,0.000000e+000,3,8.967623e-001,0.000000e+000,,,,,,,,,,,,,,32,1,4.000000e+000,0.000000e+000,0.000000e+000,0,,0,
1524444755.374,,0.000000e+000,3.500067e+001,6.495947e-006,0.000000e+000,3,8.983396e-001,0.000000e+000,,,,,,,,,,,,,,32,1,4.000000e+000,2.338409e-003,0.000000e+000,0,,0,
1524444793.080,,0.000000e+000,3.499872e+001,6.424570e-006,0.000000e+000,3,9.038083e-001,0.000000e+000,,,,,,,,,,,,,,32,1,4.000000e+000,0.000000e+000,0.000000e+000,0,,0,
1524444831.165,,0.000000e+000,3.499950e+001,6.444235e-006,0.000000e+000,3,8.982849e-001,0.000000e+000,,,,,,,,,,,,,,32,1,4.000000e+000,1.560211e-003,0.000000e+000,0,,0,
1524444869.686,,0.000000e+000,3.499872e+001,6.422084e-006,0.000000e+000,3,9.035724e-001,0.000000e+000,,,,,,,,,,,,,,32,1,4.000000e+000,0.000000e+000,0.000000e+000,0,,0,
1524444907.724,,0.000000e+000,3.499793e+001,6.423651e-006,0.000000e+000,3,9.003487e-001,0.000000e+000,,,,,,,,,,,,,,32,1,4.000000e+000,3.131866e-003,0.000000e+000,0,,0,
1524444945.249,,0.000000e+000,3.499950e+001,6.406878e-006,0.000000e+000,3,9.010356e-001,0.000000e+000,,,,,,,,,,,,,,32,1,4.000000e+000,0.000000e+000,0.000000e+000,0,,0,
1524444983.310,,0.000000e+000,3.499950e+001,6.450092e-006,0.000000e+000,3,9.045659e-001,0.000000e+000,,,,,,,,,,,,,,32,1,4.000000e+000,1.560211e-003,0.000000e+000,0,,0,
1524445021.393,,0.000000e+000,3.499911e+001,6.453152e-006,0.000000e+000,3,9.034357e-001,0.000000e+000,,,,,,,,,,,,,,32,1,4.000000e+000,2.338409e-003,0.000000e+000,0,,0,
1524445059.789,,0.000000e+000,3.499833e+001,6.465136e-006,0.000000e+000,3,9.020681e-001,0.000000e+000,,,,,,,,,,,,,,32,1,4.000000e+000,2.349854e-003,0.000000e+000,0,,0,
1524445097.727,,0.000000e+000,3.499911e+001,6.463064e-006,0.000000e+000,3,9.030786e-001,0.000000e+000,,,,,,,,,,,,,,32,1,4.000000e+000,7.820129e-004,0.000000e+000,0,,0,
1524445135.217,,0.000000e+000,3.499833e+001,6.460397e-006,0.000000e+000,3,9.003656e-001,0.000000e+000,,,,,,,,,,,,,,32,1,4.000000e+000,2.349854e-003,0.000000e+000,0,,0,
1524445173.195,,0.000000e+000,3.499989e+001,6.478423e-006,0.000000e+000,3,9.027483e-001,0.000000e+000,,,,,,,,,,,,,,32,1,4.000000e+000,7.781982e-004,0.000000e+000,0,,0,
1524445210.446,,0.000000e+000,3.499872e+001,6.476445e-006,0.000000e+000,3,8.982986e-001,0.000000e+000,,,,,,,,,,,,,,32,1,4.000000e+000,0.000000e+000,0.000000e+000,0,,0,
1524445248.556,,0.000000e+000,3.499911e+001,6.497877e-006,0.000000e+000,3,8.976874e-001,0.000000e+000,,,,,,,,,,,,,,32,1,4.000000e+000,7.820129e-004,0.000000e+000,0,,0,
1524445286.624,,0.000000e+000,3.499950e+001,6.479502e-006,0.000000e+000,3,8.974429e-001,0.000000e+000,,,,,,,,,,,,,,32,1,4.000000e+000,0.000000e+000,0.000000e+000,0,,0,
1524445324.645,,0.000000e+000,3.499911e+001,6.465166e-006,0.000000e+000,3,8.973430e-001,0.000000e+000,,,,,,,,,,,,,,32,1,4.000000e+000,7.820129e-004,0.000000e+000,0,,0,
1524445362.825,,0.000000e+000,3.499911e+001,6.500732e-006,0.000000e+000,3,8.994010e-001,0.000000e+000,,,,,,,,,,,,,,32,1,4.000000e+000,7.820129e-004,0.000000e+000,0,,0,
1524445400.886,,0.000000e+000,3.499950e+001,6.486418e-006,0.000000e+000,3,9.023069e-001,0.000000e+000,,,,,,,,,,,,,,32,1,4.000000e+000,0.000000e+000,0.000000e+000,0,,0,
1524445438.862,,0.000000e+000,3.499911e+001,6.478848e-006,0.000000e+000,3,8.971757e-001,0.000000e+000,,,,,,,,,,,,,,32,1,4.000000e+000,7.820129e-004,0.000000e+000,0,,0,
1524445476.897,,0.000000e+000,3.499950e+001,6.455868e-006,0.000000e+000,3,8.987761e-001,0.000000e+000,,,,,,,,,,,,,,32,1,4.000000e+000,0.000000e+000,0.000000e+000,0,,0,
1524445514.998,,0.000000e+000,3.499911e+001,6.488165e-006,0.000000e+000,3,9.012996e-001,0.000000e+000,,,,,,,,,,,,,,32,1,4.000000e+000,7.820129e-004,0.000000e+000,0,,0,
1524445553.033,,0.000000e+000,3.499950e+001,6.501935e-006,0.000000e+000,3,9.006627e-001,0.000000e+000,,,,,,,,,,,,,,32,1,4.000000e+000,1.560211e-003,0.000000e+000,0,,0,
1524445578.404,,0.000000e+000,3.499989e+001,6.508218e-006,0.000000e+000,3,9.009981e-001,0.000000e+000,,,,,,,,,,,,,,32,1,4.000000e+000,7.781982e-004,0.000000e+000,0,,0,